{"op":"mcm","clk":"5346195403","pt":1646178339833,"mc":[{"id":"1.195453751","marketDefinition":{"bspMarket":false,"turnInPlayEnabled":false,"persistenceEnabled":false,"marketBaseRate":7.0,"eventId":"31272494","eventTypeId":"4339","numberOfWinners":1,"bettingType":"ODDS","marketType":"QUINELLA","marketTime":"2022-03-02T09:11:00.000Z","suspendTime":"2022-03-02T09:11:00.000Z","bspReconciled":false,"complete":true,"inPlay":false,"crossMatching":false,"runnersVoidable":false,"numberOfActiveRunners":21,"betDelay":0,"status":"OPEN","runners":[{"status":"ACTIVE","sortPriority":1,"id":522741,"name":"1 - 2 / 2 - 1"},{"status":"ACTIVE","sortPriority":2,"id":522742,"name":"1 - 3 / 3 - 1"},{"status":"ACTIVE","sortPriority":3,"id":522743,"name":"1 - 4 / 4 - 1"},{"status":"ACTIVE","sortPriority":4,"id":7607472,"name":"1 - 5 / 5 - 1"},{"status":"ACTIVE","sortPriority":5,"id":522745,"name":"1 - 6 / 6 - 1"},{"status":"ACTIVE","sortPriority":6,"id":3805731,"name":"1 - 8 / 8 - 1"},{"status":"ACTIVE","sortPriority":7,"id":522746,"name":"2 - 3 / 3 - 2"},{"status":"ACTIVE","sortPriority":8,"id":522747,"name":"2 - 4 / 4 - 2"},{"status":"ACTIVE","sortPriority":9,"id":522748,"name":"2 - 5 / 5 - 2"},{"status":"ACTIVE","sortPriority":10,"id":522749,"name":"2 - 6 / 6 - 2"},{"status":"ACTIVE","sortPriority":11,"id":3805740,"name":"2 - 8 / 8 - 2"},{"status":"ACTIVE","sortPriority":12,"id":522750,"name":"3 - 4 / 4 - 3"},{"status":"ACTIVE","sortPriority":13,"id":522751,"name":"3 - 5 / 5 - 3"},{"status":"ACTIVE","sortPriority":14,"id":522752,"name":"3 - 6 / 6 - 3"},{"status":"ACTIVE","sortPriority":15,"id":3805747,"name":"3 - 8 / 8 - 3"},{"status":"ACTIVE","sortPriority":16,"id":522754,"name":"4 - 5 / 5 - 4"},{"status":"ACTIVE","sortPriority":17,"id":522753,"name":"4 - 6 / 6 - 4"},{"status":"ACTIVE","sortPriority":18,"id":3805762,"name":"4 - 8 / 8 - 4"},{"status":"ACTIVE","sortPriority":19,"id":522755,"name":"5 - 6 / 6 - 5"},{"status":"ACTIVE","sortPriority":20,"id":3805772,"name":"5 - 8 / 8 - 5"},{"status":"ACTIVE","sortPriority":21,"id":3805784,"name":"6 - 8 / 8 - 6"}],"regulators":["MR_INT"],"venue":"Traralgon","countryCode":"AU","discountAllowed":true,"timezone":"Australia/Sydney","openDate":"2022-03-02T08:31:00.000Z","version":4382480611,"name":"Quinella","eventName":"Traralgon (AUS) 2nd Mar"},"rc":[],"con":true,"img":false}]}
{"op":"mcm","clk":"5346200440","pt":1646178438338,"mc":[{"id":"1.195453751","rc":[{"atb":[[2.82,109.65],[2.32,201.57],[2.52,131.29]],"id":3805784},{"atb":[[22,9.5],[13.5,15.96],[9.4,31.67]],"id":522750},{"atb":[[17,16.63],[48,4.24],[24,8.67]],"id":522751},{"atb":[[4.6,55.43],[6.2,38.37],[3.8,95.02]],"id":522752},{"atb":[[4.4,78.25],[7.8,29.34],[5.4,45.35]],"id":3805747},{"atb":[[4.4,78.25],[7.8,29.34],[5.4,45.35]],"id":522753},{"atb":[[5.1,64.89],[9.2,24.33],[6.2,38.37]],"id":3805762},{"atb":[[65,3.11],[19,14.78],[28,7.39]],"id":522754},{"atb":[[19.5,10.78],[12,18.14],[8.8,34.11]],"id":522755},{"atb":[[9.6,23.2],[5.3,61.87],[6.6,35.63]],"id":3805740},{"atb":[[24,8.67],[9.8,30.23],[14.5,14.78]],"id":3805772}],"con":true,"img":false}]}
{"op":"mcm","clk":"5346200445","pt":1646178438495,"mc":[{"id":"1.195453751","rc":[{"atb":[[9.6,30.94],[23,9.06],[14,15.35]],"id":522746},{"atb":[[16,13.3],[11,26.6],[27,7.67]],"id":522747},{"atb":[[70,2.89],[19.5,14.38],[29,7.12]],"id":522748},{"atb":[[8,28.5],[4.5,76.02],[5.5,44.34]],"id":522749},{"atb":[[22,9.5],[13.5,15.96],[9.4,31.67]],"id":3805731},{"atb":[[18.5,15.2],[27,7.67],[60,3.38]],"id":522741},{"atb":[[16.5,17.16],[46,4.43],[23,9.06]],"id":522742},{"atb":[[18,15.65],[26,7.98],[55,3.69]],"id":522743},{"atb":[[340,0.58],[190,1.05],[95,2.83]],"id":7607472},{"atb":[[18.5,11.4],[11,19.95],[8.4,35.95]],"id":522745}],"con":true,"img":false}]}
{"op":"mcm","clk":"5346401303","pt":1646182002775,"mc":[{"id":"1.195453751","marketDefinition":{"bspMarket":false,"turnInPlayEnabled":false,"persistenceEnabled":false,"marketBaseRate":7.0,"eventId":"31272494","eventTypeId":"4339","numberOfWinners":1,"bettingType":"ODDS","marketType":"QUINELLA","marketTime":"2022-03-02T09:11:00.000Z","suspendTime":"2022-03-02T09:11:00.000Z","bspReconciled":false,"complete":true,"inPlay":false,"crossMatching":false,"runnersVoidable":false,"numberOfActiveRunners":21,"betDelay":0,"status":"OPEN","runners":[{"status":"ACTIVE","sortPriority":1,"id":522741,"name":"1 - 2 / 2 - 1"},{"status":"ACTIVE","sortPriority":2,"id":522742,"name":"1 - 3 / 3 - 1"},{"status":"ACTIVE","sortPriority":3,"id":522743,"name":"1 - 4 / 4 - 1"},{"status":"ACTIVE","sortPriority":4,"id":7607472,"name":"1 - 5 / 5 - 1"},{"status":"ACTIVE","sortPriority":5,"id":522745,"name":"1 - 6 / 6 - 1"},{"status":"ACTIVE","sortPriority":6,"id":3805731,"name":"1 - 8 / 8 - 1"},{"status":"ACTIVE","sortPriority":7,"id":522746,"name":"2 - 3 / 3 - 2"},{"status":"ACTIVE","sortPriority":8,"id":522747,"name":"2 - 4 / 4 - 2"},{"status":"ACTIVE","sortPriority":9,"id":522748,"name":"2 - 5 / 5 - 2"},{"status":"ACTIVE","sortPriority":10,"id":522749,"name":"2 - 6 / 6 - 2"},{"status":"ACTIVE","sortPriority":11,"id":3805740,"name":"2 - 8 / 8 - 2"},{"status":"ACTIVE","sortPriority":12,"id":522750,"name":"3 - 4 / 4 - 3"},{"status":"ACTIVE","sortPriority":13,"id":522751,"name":"3 - 5 / 5 - 3"},{"status":"ACTIVE","sortPriority":14,"id":522752,"name":"3 - 6 / 6 - 3"},{"status":"ACTIVE","sortPriority":15,"id":3805747,"name":"3 - 8 / 8 - 3"},{"status":"ACTIVE","sortPriority":16,"id":522754,"name":"4 - 5 / 5 - 4"},{"status":"ACTIVE","sortPriority":17,"id":522753,"name":"4 - 6 / 6 - 4"},{"status":"ACTIVE","sortPriority":18,"id":3805762,"name":"4 - 8 / 8 - 4"},{"status":"ACTIVE","sortPriority":19,"id":522755,"name":"5 - 6 / 6 - 5"},{"status":"ACTIVE","sortPriority":20,"id":3805772,"name":"5 - 8 / 8 - 5"},{"status":"ACTIVE","sortPriority":21,"id":3805784,"name":"6 - 8 / 8 - 6"}],"regulators":["MR_INT"],"venue":"Traralgon","countryCode":"AU","discountAllowed":true,"timezone":"Australia/Sydney","openDate":"2022-03-02T08:31:00.000Z","version":4382480611,"name":"Quinella","eventName":"Traralgon (AUS) 2nd Mar"},"rc":[{"atb":[[2.82,109.66],[2.32,201.6],[2.52,131.3]],"id":3805784},{"atb":[[4.4,78.26],[7.8,29.34],[5.4,45.36]],"id":3805747},{"atb":[[65,3.11],[19,14.78],[28,7.39]],"id":522754},{"atb":[[19.5,10.79],[12,18.14],[8.8,34.11]],"id":522755},{"atb":[[9.6,30.94],[23,9.07],[14,15.35]],"id":522746},{"atb":[[16,13.3],[11,26.61],[27,7.67]],"id":522747},{"atb":[[70,2.89],[19.5,14.38],[29,7.12]],"id":522748},{"atb":[[8,28.51],[4.5,76.03],[5.5,44.35]],"id":522749},{"atb":[[22,9.5],[13.5,15.96],[9.4,31.68]],"id":522750},{"atb":[[17,16.63],[48,4.24],[24,8.67]],"id":522751},{"atb":[[22,9.5],[13.5,15.96],[9.4,31.68]],"id":3805731},{"atb":[[4.6,55.43],[6.2,38.38],[3.8,95.04]],"id":522752},{"atb":[[5.1,64.9],[9.2,24.34],[6.2,38.38]],"id":3805762},{"atb":[[4.4,78.26],[7.8,29.34],[5.4,45.36]],"id":522753},{"atb":[[18.5,15.2],[27,7.67],[60,3.38]],"id":522741},{"atb":[[16.5,17.17],[46,4.43],[23,9.07]],"id":522742},{"atb":[[18,15.65],[26,7.98],[55,3.69]],"id":522743},{"atb":[[9.6,23.2],[5.3,61.88],[6.6,35.63]],"id":3805740},{"atb":[[24,8.67],[9.8,30.24],[14.5,14.78]],"id":3805772},{"atb":[[340,0.58],[190,1.05],[95,2.83]],"id":7607472},{"atb":[[18.5,11.4],[11,19.95],[8.4,35.95]],"id":522745}],"con":true,"img":true}]}
{"op":"mcm","clk":"5346767664","pt":1646187402720,"mc":[{"id":"1.195453751","marketDefinition":{"bspMarket":false,"turnInPlayEnabled":false,"persistenceEnabled":false,"marketBaseRate":7.0,"eventId":"31272494","eventTypeId":"4339","numberOfWinners":1,"bettingType":"ODDS","marketType":"QUINELLA","marketTime":"2022-03-02T09:11:00.000Z","suspendTime":"2022-03-02T09:11:00.000Z","bspReconciled":false,"complete":true,"inPlay":false,"crossMatching":false,"runnersVoidable":false,"numberOfActiveRunners":21,"betDelay":0,"status":"OPEN","runners":[{"status":"ACTIVE","sortPriority":1,"id":522741,"name":"1 - 2 / 2 - 1"},{"status":"ACTIVE","sortPriority":2,"id":522742,"name":"1 - 3 / 3 - 1"},{"status":"ACTIVE","sortPriority":3,"id":522743,"name":"1 - 4 / 4 - 1"},{"status":"ACTIVE","sortPriority":4,"id":7607472,"name":"1 - 5 / 5 - 1"},{"status":"ACTIVE","sortPriority":5,"id":522745,"name":"1 - 6 / 6 - 1"},{"status":"ACTIVE","sortPriority":6,"id":3805731,"name":"1 - 8 / 8 - 1"},{"status":"ACTIVE","sortPriority":7,"id":522746,"name":"2 - 3 / 3 - 2"},{"status":"ACTIVE","sortPriority":8,"id":522747,"name":"2 - 4 / 4 - 2"},{"status":"ACTIVE","sortPriority":9,"id":522748,"name":"2 - 5 / 5 - 2"},{"status":"ACTIVE","sortPriority":10,"id":522749,"name":"2 - 6 / 6 - 2"},{"status":"ACTIVE","sortPriority":11,"id":3805740,"name":"2 - 8 / 8 - 2"},{"status":"ACTIVE","sortPriority":12,"id":522750,"name":"3 - 4 / 4 - 3"},{"status":"ACTIVE","sortPriority":13,"id":522751,"name":"3 - 5 / 5 - 3"},{"status":"ACTIVE","sortPriority":14,"id":522752,"name":"3 - 6 / 6 - 3"},{"status":"ACTIVE","sortPriority":15,"id":3805747,"name":"3 - 8 / 8 - 3"},{"status":"ACTIVE","sortPriority":16,"id":522754,"name":"4 - 5 / 5 - 4"},{"status":"ACTIVE","sortPriority":17,"id":522753,"name":"4 - 6 / 6 - 4"},{"status":"ACTIVE","sortPriority":18,"id":3805762,"name":"4 - 8 / 8 - 4"},{"status":"ACTIVE","sortPriority":19,"id":522755,"name":"5 - 6 / 6 - 5"},{"status":"ACTIVE","sortPriority":20,"id":3805772,"name":"5 - 8 / 8 - 5"},{"status":"ACTIVE","sortPriority":21,"id":3805784,"name":"6 - 8 / 8 - 6"}],"regulators":["MR_INT"],"venue":"Traralgon","countryCode":"AU","discountAllowed":true,"timezone":"Australia/Sydney","openDate":"2022-03-02T08:31:00.000Z","version":4382480611,"name":"Quinella","eventName":"Traralgon (AUS) 2nd Mar"},"rc":[{"atb":[[2.82,109.83],[2.32,201.91],[2.52,131.51]],"id":3805784},{"atb":[[4.4,78.39],[7.8,29.39],[5.4,45.43]],"id":3805747},{"atb":[[65,3.12],[19,14.8],[28,7.4]],"id":522754},{"atb":[[19.5,10.8],[12,18.17],[8.8,34.17]],"id":522755},{"atb":[[9.6,30.99],[23,9.08],[14,15.37]],"id":522746},{"atb":[[16,13.32],[11,26.65],[27,7.68]],"id":522747},{"atb":[[70,2.89],[19.5,14.4],[29,7.13]],"id":522748},{"atb":[[8,28.55],[4.5,76.15],[5.5,44.42]],"id":522749},{"atb":[[22,9.52],[13.5,15.99],[9.4,31.73]],"id":522750},{"atb":[[17,16.65],[48,4.25],[24,8.69]],"id":522751},{"atb":[[22,9.52],[13.5,15.99],[9.4,31.73]],"id":3805731},{"atb":[[4.6,55.52],[6.2,38.44],[3.8,95.19]],"id":522752},{"atb":[[5.1,65],[9.2,24.37],[6.2,38.44]],"id":3805762},{"atb":[[4.4,78.39],[7.8,29.39],[5.4,45.43]],"id":522753},{"atb":[[18.5,15.22],[27,7.68],[60,3.38]],"id":522741},{"atb":[[16.5,17.19],[46,4.44],[23,9.08]],"id":522742},{"atb":[[18,15.67],[26,7.99],[55,3.7]],"id":522743},{"atb":[[9.6,23.24],[5.3,61.98],[6.6,35.69]],"id":3805740},{"atb":[[24,8.69],[9.8,30.29],[14.5,14.8]],"id":3805772},{"atb":[[340,0.58],[190,1.05],[95,2.83]],"id":7607472},{"atb":[[18.5,11.42],[11,19.99],[8.4,36.01]],"id":522745}],"con":true,"img":true}]}
{"op":"mcm","clk":"5347092228","pt":1646192802701,"mc":[{"id":"1.195453751","marketDefinition":{"bspMarket":false,"turnInPlayEnabled":false,"persistenceEnabled":false,"marketBaseRate":7.0,"eventId":"31272494","eventTypeId":"4339","numberOfWinners":1,"bettingType":"ODDS","marketType":"QUINELLA","marketTime":"2022-03-02T09:11:00.000Z","suspendTime":"2022-03-02T09:11:00.000Z","bspReconciled":false,"complete":true,"inPlay":false,"crossMatching":false,"runnersVoidable":false,"numberOfActiveRunners":21,"betDelay":0,"status":"OPEN","runners":[{"status":"ACTIVE","sortPriority":1,"id":522741,"name":"1 - 2 / 2 - 1"},{"status":"ACTIVE","sortPriority":2,"id":522742,"name":"1 - 3 / 3 - 1"},{"status":"ACTIVE","sortPriority":3,"id":522743,"name":"1 - 4 / 4 - 1"},{"status":"ACTIVE","sortPriority":4,"id":7607472,"name":"1 - 5 / 5 - 1"},{"status":"ACTIVE","sortPriority":5,"id":522745,"name":"1 - 6 / 6 - 1"},{"status":"ACTIVE","sortPriority":6,"id":3805731,"name":"1 - 8 / 8 - 1"},{"status":"ACTIVE","sortPriority":7,"id":522746,"name":"2 - 3 / 3 - 2"},{"status":"ACTIVE","sortPriority":8,"id":522747,"name":"2 - 4 / 4 - 2"},{"status":"ACTIVE","sortPriority":9,"id":522748,"name":"2 - 5 / 5 - 2"},{"status":"ACTIVE","sortPriority":10,"id":522749,"name":"2 - 6 / 6 - 2"},{"status":"ACTIVE","sortPriority":11,"id":3805740,"name":"2 - 8 / 8 - 2"},{"status":"ACTIVE","sortPriority":12,"id":522750,"name":"3 - 4 / 4 - 3"},{"status":"ACTIVE","sortPriority":13,"id":522751,"name":"3 - 5 / 5 - 3"},{"status":"ACTIVE","sortPriority":14,"id":522752,"name":"3 - 6 / 6 - 3"},{"status":"ACTIVE","sortPriority":15,"id":3805747,"name":"3 - 8 / 8 - 3"},{"status":"ACTIVE","sortPriority":16,"id":522754,"name":"4 - 5 / 5 - 4"},{"status":"ACTIVE","sortPriority":17,"id":522753,"name":"4 - 6 / 6 - 4"},{"status":"ACTIVE","sortPriority":18,"id":3805762,"name":"4 - 8 / 8 - 4"},{"status":"ACTIVE","sortPriority":19,"id":522755,"name":"5 - 6 / 6 - 5"},{"status":"ACTIVE","sortPriority":20,"id":3805772,"name":"5 - 8 / 8 - 5"},{"status":"ACTIVE","sortPriority":21,"id":3805784,"name":"6 - 8 / 8 - 6"}],"regulators":["MR_INT"],"venue":"Traralgon","countryCode":"AU","discountAllowed":true,"timezone":"Australia/Sydney","openDate":"2022-03-02T08:31:00.000Z","version":4382480611,"name":"Quinella","eventName":"Traralgon (AUS) 2nd Mar"},"rc":[{"atb":[[2.82,110.02],[2.32,202.26],[2.52,131.73]],"id":3805784},{"atb":[[4.4,78.52],[7.8,29.44],[5.4,45.51]],"id":3805747},{"atb":[[65,3.12],[19,14.83],[28,7.41]],"id":522754},{"atb":[[19.5,10.82],[12,18.2],[8.8,34.23]],"id":522755},{"atb":[[9.6,31.04],[23,9.09],[14,15.4]],"id":522746},{"atb":[[16,13.34],[11,26.69],[27,7.7]],"id":522747},{"atb":[[70,2.9],[19.5,14.43],[29,7.14]],"id":522748},{"atb":[[8,28.6],[4.5,76.28],[5.5,44.49]],"id":522749},{"atb":[[22,9.53],[13.5,16.02],[9.4,31.78]],"id":522750},{"atb":[[17,16.68],[48,4.26],[24,8.7]],"id":522751},{"atb":[[22,9.53],[13.5,16.02],[9.4,31.78]],"id":3805731},{"atb":[[4.6,55.62],[6.2,38.5],[3.8,95.35]],"id":522752},{"atb":[[5.1,65.11],[9.2,24.42],[6.2,38.5]],"id":3805762},{"atb":[[4.4,78.52],[7.8,29.44],[5.4,45.51]],"id":522753},{"atb":[[18.5,15.25],[27,7.7],[60,3.39]],"id":522741},{"atb":[[16.5,17.22],[46,4.45],[23,9.09]],"id":522742},{"atb":[[18,15.7],[26,8],[55,3.7]],"id":522743},{"atb":[[9.6,23.28],[5.3,62.08],[6.6,35.75]],"id":3805740},{"atb":[[24,8.7],[9.8,30.34],[14.5,14.83]],"id":3805772},{"atb":[[340,0.58],[190,1.05],[95,2.84]],"id":7607472},{"atb":[[18.5,11.44],[11,20.02],[8.4,36.07]],"id":522745}],"con":true,"img":true}]}
{"op":"mcm","clk":"5347381101","pt":1646198202719,"mc":[{"id":"1.195453751","marketDefinition":{"bspMarket":false,"turnInPlayEnabled":false,"persistenceEnabled":false,"marketBaseRate":7.0,"eventId":"31272494","eventTypeId":"4339","numberOfWinners":1,"bettingType":"ODDS","marketType":"QUINELLA","marketTime":"2022-03-02T09:11:00.000Z","suspendTime":"2022-03-02T09:11:00.000Z","bspReconciled":false,"complete":true,"inPlay":false,"crossMatching":false,"runnersVoidable":false,"numberOfActiveRunners":21,"betDelay":0,"status":"OPEN","runners":[{"status":"ACTIVE","sortPriority":1,"id":522741,"name":"1 - 2 / 2 - 1"},{"status":"ACTIVE","sortPriority":2,"id":522742,"name":"1 - 3 / 3 - 1"},{"status":"ACTIVE","sortPriority":3,"id":522743,"name":"1 - 4 / 4 - 1"},{"status":"ACTIVE","sortPriority":4,"id":7607472,"name":"1 - 5 / 5 - 1"},{"status":"ACTIVE","sortPriority":5,"id":522745,"name":"1 - 6 / 6 - 1"},{"status":"ACTIVE","sortPriority":6,"id":3805731,"name":"1 - 8 / 8 - 1"},{"status":"ACTIVE","sortPriority":7,"id":522746,"name":"2 - 3 / 3 - 2"},{"status":"ACTIVE","sortPriority":8,"id":522747,"name":"2 - 4 / 4 - 2"},{"status":"ACTIVE","sortPriority":9,"id":522748,"name":"2 - 5 / 5 - 2"},{"status":"ACTIVE","sortPriority":10,"id":522749,"name":"2 - 6 / 6 - 2"},{"status":"ACTIVE","sortPriority":11,"id":3805740,"name":"2 - 8 / 8 - 2"},{"status":"ACTIVE","sortPriority":12,"id":522750,"name":"3 - 4 / 4 - 3"},{"status":"ACTIVE","sortPriority":13,"id":522751,"name":"3 - 5 / 5 - 3"},{"status":"ACTIVE","sortPriority":14,"id":522752,"name":"3 - 6 / 6 - 3"},{"status":"ACTIVE","sortPriority":15,"id":3805747,"name":"3 - 8 / 8 - 3"},{"status":"ACTIVE","sortPriority":16,"id":522754,"name":"4 - 5 / 5 - 4"},{"status":"ACTIVE","sortPriority":17,"id":522753,"name":"4 - 6 / 6 - 4"},{"status":"ACTIVE","sortPriority":18,"id":3805762,"name":"4 - 8 / 8 - 4"},{"status":"ACTIVE","sortPriority":19,"id":522755,"name":"5 - 6 / 6 - 5"},{"status":"ACTIVE","sortPriority":20,"id":3805772,"name":"5 - 8 / 8 - 5"},{"status":"ACTIVE","sortPriority":21,"id":3805784,"name":"6 - 8 / 8 - 6"}],"regulators":["MR_INT"],"venue":"Traralgon","countryCode":"AU","discountAllowed":true,"timezone":"Australia/Sydney","openDate":"2022-03-02T08:31:00.000Z","version":4382480611,"name":"Quinella","eventName":"Traralgon (AUS) 2nd Mar"},"rc":[{"atb":[[2.82,109.98],[2.32,202.18],[2.52,131.68]],"id":3805784},{"atb":[[4.4,78.49],[7.8,29.43],[5.4,45.49]],"id":3805747},{"atb":[[65,3.12],[19,14.82],[28,7.41]],"id":522754},{"atb":[[19.5,10.82],[12,18.19],[8.8,34.21]],"id":522755},{"atb":[[9.6,31.03],[23,9.09],[14,15.39]],"id":522746},{"atb":[[16,13.34],[11,26.68],[27,7.69]],"id":522747},{"atb":[[70,2.89],[19.5,14.42],[29,7.14]],"id":522748},{"atb":[[8,28.59],[4.5,76.25],[5.5,44.48]],"id":522749},{"atb":[[22,9.53],[13.5,16.01],[9.4,31.77]],"id":522750},{"atb":[[17,16.68],[48,4.25],[24,8.7]],"id":522751},{"atb":[[22,9.53],[13.5,16.01],[9.4,31.77]],"id":3805731},{"atb":[[4.6,55.59],[6.2,38.49],[3.8,95.31]],"id":522752},{"atb":[[5.1,65.09],[9.2,24.41],[6.2,38.49]],"id":3805762},{"atb":[[4.4,78.49],[7.8,29.43],[5.4,45.49]],"id":522753},{"atb":[[18.5,15.24],[27,7.69],[60,3.39]],"id":522741},{"atb":[[16.5,17.22],[46,4.44],[23,9.09]],"id":522742},{"atb":[[18,15.69],[26,8],[55,3.7]],"id":522743},{"atb":[[9.6,23.27],[5.3,62.06],[6.6,35.74]],"id":3805740},{"atb":[[24,8.7],[9.8,30.33],[14.5,14.82]],"id":3805772},{"atb":[[340,0.58],[190,1.05],[95,2.83]],"id":7607472},{"atb":[[18.5,11.43],[11,20.01],[8.4,36.06]],"id":522745}],"con":true,"img":true}]}
{"op":"mcm","clk":"5347433891","pt":1646199293761,"mc":[{"id":"1.195453751","rc":[{"atb":[[2.82,109.98],[2.32,202.18],[2.52,131.68]],"id":3805784},{"atb":[[4.4,78.49],[7.8,29.43],[5.4,45.49]],"id":3805747},{"atb":[[65,3.12],[19,14.82],[28,7.41]],"id":522754},{"atb":[[19.5,10.82],[12,18.19],[8.8,34.21]],"id":522755},{"atb":[[9.6,31.03],[23,9.09],[14,15.39]],"id":522746},{"atb":[[16,13.34],[11,26.68],[27,7.69]],"id":522747},{"atb":[[70,2.89],[19.5,14.42],[29,7.14]],"id":522748},{"atb":[[8,28.59],[4.5,76.25],[5.5,44.48]],"id":522749},{"atb":[[22,9.53],[13.5,16.01],[9.4,31.77]],"id":522750},{"atb":[[17,16.68],[48,4.25],[24,8.7]],"id":522751},{"atb":[[22,9.53],[13.5,16.01],[9.4,31.77]],"id":3805731},{"atb":[[4.6,55.59],[6.2,38.49],[3.8,95.31]],"id":522752},{"atb":[[5.1,65.09],[9.2,24.41],[6.2,38.49]],"id":3805762},{"atb":[[4.4,78.49],[7.8,29.43],[5.4,45.49]],"id":522753},{"atb":[[18.5,15.24],[27,7.69],[60,3.39]],"id":522741},{"atb":[[16.5,17.22],[46,4.44],[23,9.09]],"id":522742},{"atb":[[18,15.69],[26,8],[55,3.7]],"id":522743},{"atb":[[9.6,23.27],[5.3,62.06],[6.6,35.74]],"id":3805740},{"atb":[[24,8.7],[9.8,30.33],[14.5,14.82]],"id":3805772},{"atb":[[340,0],[190,0],[95,0]],"id":7607472},{"atb":[[18.5,11.43],[11,20.01],[8.4,36.06]],"id":522745}],"con":true,"img":false}]}
{"op":"mcm","clk":"5347433897","pt":1646199293861,"mc":[{"id":"1.195453751","rc":[{"atb":[[2.82,0],[2.32,0],[2.52,0]],"id":3805784},{"atb":[[4.4,0],[7.8,0],[5.4,0]],"id":3805747},{"atb":[[65,0],[19,0],[28,0]],"id":522754},{"atb":[[19.5,0],[12,0],[8.8,0]],"id":522755},{"atb":[[9.6,0],[23,0],[14,0]],"id":522746},{"atb":[[16,0],[11,0],[27,0]],"id":522747},{"atb":[[70,0],[19.5,0],[29,0]],"id":522748},{"atb":[[8,0],[4.5,0],[5.5,0]],"id":522749},{"atb":[[22,0],[13.5,0],[9.4,0]],"id":522750},{"atb":[[17,0],[48,0],[24,0]],"id":522751},{"atb":[[22,0],[13.5,0],[9.4,0]],"id":3805731},{"atb":[[4.6,0],[6.2,0],[3.8,0]],"id":522752},{"atb":[[5.1,0],[9.2,0],[6.2,0]],"id":3805762},{"atb":[[4.4,0],[7.8,0],[5.4,0]],"id":522753},{"atb":[[18.5,0],[27,0],[60,0]],"id":522741},{"atb":[[16.5,0],[46,0],[23,0]],"id":522742},{"atb":[[18,0],[26,0],[55,0]],"id":522743},{"atb":[[9.6,0],[5.3,0],[6.6,0]],"id":3805740},{"atb":[[24,0],[9.8,0],[14.5,0]],"id":3805772},{"atb":[[18.5,0],[11,0],[8.4,0]],"id":522745}],"con":true,"img":false}]}
{"op":"mcm","clk":"5347434503","pt":1646199305807,"mc":[{"id":"1.195453751","rc":[{"atb":[[2.3,153.97],[2.6,125.1],[2.1,242.62]],"id":3805784},{"atb":[[7.2,32.28],[5.1,48.81],[4.1,86.09]],"id":3805747},{"atb":[[34,8.08],[170,1.18],[60,3.39]],"id":522754},{"atb":[[9.6,31.03],[23,9.09],[14,15.39]],"id":522755},{"atb":[[9.6,31.03],[23,9.09],[14,15.39]],"id":522746},{"atb":[[36,5.71],[19,11.12],[14,20.52]],"id":522747},{"atb":[[42,4.88],[26,10.67],[110,1.83]],"id":522748},{"atb":[[8,28.59],[4.5,76.25],[5.5,44.48]],"id":522749},{"atb":[[16,13.34],[11,26.68],[27,7.69]],"id":522750},{"atb":[[18.5,15.24],[27,7.69],[60,3.39]],"id":522751},{"atb":[[24,8.7],[9.8,30.33],[14.5,14.82]],"id":3805731},{"atb":[[4,66.72],[5.5,44.48],[3.5,106.75]],"id":522752},{"atb":[[8,28.59],[6,53.37],[12.5,17.4]],"id":3805762},{"atb":[[5.1,65.09],[9.2,24.41],[6.2,38.49]],"id":522753},{"atb":[[32,6.45],[80,2.53],[21,13.34]],"id":522741},{"atb":[[17,16.68],[48,4.25],[24,8.7]],"id":522742},{"atb":[[42,4.88],[26,10.67],[110,1.83]],"id":522743},{"atb":[[16,13.34],[11,26.68],[27,7.69]],"id":3805772},{"atb":[[6.4,37.06],[5.2,63.54],[9.4,23.82]],"id":3805740},{"atb":[[610,0.32],[360,0.74],[460,0.43]],"id":7607472},{"atb":[[19.5,10.82],[12,18.19],[8.8,34.21]],"id":522745}],"con":true,"img":false}]}
{"op":"mcm","clk":"5347437013","pt":1646199353165,"mc":[{"id":"1.195453751","rc":[{"atb":[[2.3,0],[2.6,0],[2.1,0]],"id":3805784},{"atb":[[7.2,0],[5.1,0],[4.1,0]],"id":3805747},{"atb":[[34,0],[170,0],[60,0]],"id":522754},{"atb":[[9.6,0],[23,0],[14,0]],"id":522755},{"atb":[[9.6,0],[23,0],[14,0]],"id":522746},{"atb":[[36,0],[19,0],[14,0]],"id":522747},{"atb":[[42,0],[26,0],[110,0]],"id":522748},{"atb":[[8,0],[4.5,0],[5.5,0]],"id":522749},{"atb":[[16,0],[11,0],[27,0]],"id":522750},{"atb":[[18.5,0],[27,0],[60,0]],"id":522751},{"atb":[[24,0],[9.8,0],[14.5,0]],"id":3805731},{"atb":[[4,0],[5.5,0],[3.5,0]],"id":522752},{"atb":[[8,0],[6,0],[12.5,0]],"id":3805762},{"atb":[[5.1,0],[9.2,0],[6.2,0]],"id":522753},{"atb":[[32,0],[80,0],[21,0]],"id":522741},{"atb":[[17,0],[48,0],[24,0]],"id":522742},{"atb":[[42,0],[26,0],[110,0]],"id":522743},{"atb":[[6.4,0],[5.2,0],[9.4,0]],"id":3805740},{"atb":[[16,0],[11,0],[27,0]],"id":3805772},{"atb":[[610,0],[360,0],[460,0]],"id":7607472},{"atb":[[19.5,0],[12,0],[8.8,0]],"id":522745}],"con":true,"img":false}]}
{"op":"mcm","clk":"5347437671","pt":1646199365587,"mc":[{"id":"1.195453751","rc":[{"atb":[[2.3,153.97],[2.6,125.1],[2.1,242.62]],"id":3805784},{"atb":[[7.2,32.28],[5.1,48.81],[4.1,86.09]],"id":3805747},{"atb":[[34,8.08],[170,1.18],[60,3.39]],"id":522754},{"atb":[[9.6,31.03],[23,9.09],[14,15.39]],"id":522755},{"atb":[[9.6,31.03],[23,9.09],[14,15.39]],"id":522746},{"atb":[[36,5.71],[19,11.12],[14,20.52]],"id":522747},{"atb":[[42,4.88],[26,10.67],[110,1.83]],"id":522748},{"atb":[[8,28.59],[4.5,76.25],[5.5,44.48]],"id":522749},{"atb":[[16,13.34],[11,26.68],[27,7.69]],"id":522750},{"atb":[[18.5,15.24],[27,7.69],[60,3.39]],"id":522751},{"atb":[[24,8.7],[9.8,30.33],[14.5,14.82]],"id":3805731},{"atb":[[4,66.72],[5.5,44.48],[3.5,106.75]],"id":522752},{"atb":[[8,28.59],[6,53.37],[12.5,17.4]],"id":3805762},{"atb":[[5.1,65.09],[9.2,24.41],[6.2,38.49]],"id":522753},{"atb":[[32,6.45],[80,2.53],[21,13.34]],"id":522741},{"atb":[[17,16.68],[48,4.25],[24,8.7]],"id":522742},{"atb":[[42,4.88],[26,10.67],[110,1.83]],"id":522743},{"atb":[[16,13.34],[11,26.68],[27,7.69]],"id":3805772},{"atb":[[6.4,37.06],[5.2,63.54],[9.4,23.82]],"id":3805740},{"atb":[[610,0.32],[360,0.74],[460,0.43]],"id":7607472},{"atb":[[19.5,10.82],[12,18.19],[8.8,34.21]],"id":522745}],"con":true,"img":false}]}
{"op":"mcm","clk":"5347674974","pt":1646205060456,"mc":[{"id":"1.195453751","rc":[{"atb":[[2.82,3.27],[2.92,2.72],[2.3,153.93],[2.6,125.07],[2.1,242.55]],"id":3805784},{"atb":[[7.2,32.27],[5.1,48.8],[4.1,86.06],[7.6,2.72],[6.6,3.27]],"id":3805747},{"atb":[[34,8.08],[170,1.18],[42,3.27],[55,2.72],[60,3.38]],"id":522754},{"atb":[[9.6,31.02],[17,2.72],[23,9.09],[14,15.39],[14.5,3.27]],"id":522755},{"atb":[[9.6,31.02],[18,2.72],[23,9.09],[14,15.39],[15.5,3.27]],"id":522746},{"atb":[[36,5.71],[19,11.11],[20,3.27],[25,2.72],[14,20.52]],"id":522747},{"atb":[[34,3.27],[42,4.87],[44,2.72],[26,10.67],[110,1.83]],"id":522748},{"atb":[[8,28.58],[4.5,76.23],[5.5,44.47],[5.2,3.27],[5.7,2.72]],"id":522749},{"atb":[[16,13.34],[18,3.27],[21,2.72],[11,26.68],[27,7.69]],"id":522750},{"atb":[[18.5,15.24],[36,2.72],[27,7.69],[28,3.27],[60,3.38]],"id":522751},{"atb":[[17.5,2.72],[24,8.7],[9.8,30.32],[14.5,14.82],[15,3.27]],"id":3805731},{"atb":[[4,66.7],[6.4,2.72],[5.5,44.47],[5.7,3.27],[3.5,106.72]],"id":522752},{"atb":[[8,28.58],[6,53.36],[12,2.72],[12.5,17.4],[9.8,3.27]],"id":3805762},{"atb":[[5.1,65.07],[9,3.27],[9.2,24.4],[10,2.72],[6.2,38.48]],"id":522753},{"atb":[[32,6.45],[80,2.53],[40,2.72],[21,13.34],[30,3.27]],"id":522741},{"atb":[[32,2.72],[17,16.67],[48,4.25],[24,8.7],[26,3.27]],"id":522742},{"atb":[[36,3.27],[42,4.87],[46,2.72],[26,10.67],[110,1.83]],"id":522743},{"atb":[[6.4,37.05],[5.2,63.52],[9.8,2.72],[8.8,3.27],[9.4,23.82]],"id":3805740},{"atb":[[16,13.34],[16.5,3.27],[19,2.72],[11,26.68],[27,7.69]],"id":3805772},{"atb":[[80,2.72],[360,0.74],[55,3.27],[460,0.43]],"id":7607472},{"atb":[[19.5,10.81],[12,18.19],[12.5,3.27],[8.8,34.2],[15,2.72]],"id":522745}],"con":true,"img":false}]}
{"op":"mcm","clk":"5347694557","pt":1646205608793,"mc":[{"id":"1.195453751","rc":[{"atb":[[20,0],[25,0]],"id":522747},{"atb":[[18,0],[21,0]],"id":522750},{"atb":[[6.4,0],[5.7,0]],"id":522752}],"con":true,"img":false}]}
{"op":"mcm","clk":"5347694562","pt":1646205608899,"mc":[{"id":"1.195453751","rc":[{"atb":[[7.6,0],[6.6,0]],"id":3805747},{"atb":[[42,0],[55,0]],"id":522754},{"atb":[[17,0],[14.5,0]],"id":522755},{"atb":[[18,0],[15.5,0]],"id":522746},{"atb":[[34,0],[44,0]],"id":522748},{"atb":[[17.5,0],[15,0]],"id":3805731},{"atb":[[9,0],[10,0]],"id":522753},{"atb":[[32,0],[26,0]],"id":522742},{"atb":[[36,0],[46,0]],"id":522743},{"atb":[[12.5,0],[15,0]],"id":522745}],"con":true,"img":false}]}
{"op":"mcm","clk":"5347694596","pt":1646205609464,"mc":[{"id":"1.195453751","rc":[{"atb":[[20,3.27],[25,2.72]],"id":522747},{"atb":[[18,3.27],[21,2.72]],"id":522750},{"atb":[[6.4,2.72],[5.7,3.27]],"id":522752}],"con":true,"img":false}]}
{"op":"mcm","clk":"5347694602","pt":1646205609570,"mc":[{"id":"1.195453751","rc":[{"atb":[[7.6,2.72],[6.6,3.27]],"id":3805747},{"atb":[[42,3.27],[55,2.72]],"id":522754},{"atb":[[17,2.72],[14.5,3.27]],"id":522755},{"atb":[[18,2.72],[15.5,3.27]],"id":522746},{"atb":[[34,3.27],[44,2.72]],"id":522748},{"atb":[[17.5,2.72],[15,3.27]],"id":3805731},{"atb":[[9,3.27],[10,2.72]],"id":522753},{"atb":[[32,2.72],[26,3.27]],"id":522742},{"atb":[[36,3.27],[46,2.72]],"id":522743},{"atb":[[12.5,3.27],[15,2.72]],"id":522745}],"con":true,"img":false}]}
{"op":"mcm","clk":"5347714864","pt":1646206155732,"mc":[{"id":"1.195453751","rc":[{"atb":[[2.82,0],[2.92,0]],"id":3805784},{"atb":[[5.2,0],[5.7,0]],"id":522749}],"con":true,"img":false}]}
{"op":"mcm","clk":"5347714892","pt":1646206156449,"mc":[{"id":"1.195453751","rc":[{"atb":[[2.82,2.72],[2.72,3.27]],"id":3805784}],"con":true,"img":false}]}
{"op":"mcm","clk":"5347714897","pt":1646206156706,"mc":[{"id":"1.195453751","rc":[{"atb":[[5.9,2.72],[5.4,3.27]],"id":522749}],"con":true,"img":false}]}
{"op":"mcm","clk":"5347715570","pt":1646206173674,"mc":[{"id":"1.195453751","rc":[{"atb":[[2.82,0],[2.72,0]],"id":3805784}],"con":true,"img":false}]}
{"op":"mcm","clk":"5347715588","pt":1646206173934,"mc":[{"id":"1.195453751","rc":[{"atb":[[5.9,0],[5.4,0]],"id":522749}],"con":true,"img":false}]}
{"op":"mcm","clk":"5347715608","pt":1646206174348,"mc":[{"id":"1.195453751","rc":[{"atb":[[2.82,3.27],[2.92,2.72]],"id":3805784}],"con":true,"img":false}]}
{"op":"mcm","clk":"5347715625","pt":1646206174659,"mc":[{"id":"1.195453751","rc":[{"atb":[[5.2,3.27],[5.7,2.72]],"id":522749}],"con":true,"img":false}]}
{"op":"mcm","clk":"5347741054","pt":1646206836114,"mc":[{"id":"1.195453751","rc":[{"atb":[[2.82,0],[2.92,0]],"id":3805784}],"con":true,"img":false}]}
{"op":"mcm","clk":"5347741066","pt":1646206836421,"mc":[{"id":"1.195453751","rc":[{"atb":[[5.2,0],[5.7,0]],"id":522749}],"con":true,"img":false}]}
{"op":"mcm","clk":"5347741084","pt":1646206836781,"mc":[{"id":"1.195453751","rc":[{"atb":[[2.92,3.27],[3.05,2.72]],"id":3805784}],"con":true,"img":false}]}
{"op":"mcm","clk":"5347741102","pt":1646206837090,"mc":[{"id":"1.195453751","rc":[{"atb":[[5.8,2.72],[5.3,3.27]],"id":522749}],"con":true,"img":false}]}
{"op":"mcm","clk":"5347767161","pt":1646207385280,"mc":[{"id":"1.195453751","rc":[{"atb":[[5.8,0],[5.3,0]],"id":522749}],"con":true,"img":false}]}
{"op":"mcm","clk":"5347767202","pt":1646207386161,"mc":[{"id":"1.195453751","rc":[{"atb":[[5.5,47.74],[6,2.72]],"id":522749}],"con":true,"img":false}]}
{"op":"mcm","clk":"5347769547","pt":1646207433716,"mc":[{"id":"1.195453751","rc":[{"atb":[[5.5,44.47],[6,0]],"id":522749}],"con":true,"img":false}]}
{"op":"mcm","clk":"5347769596","pt":1646207434634,"mc":[{"id":"1.195453751","rc":[{"atb":[[5.8,2.72],[5.3,3.27]],"id":522749}],"con":true,"img":false}]}
{"op":"mcm","clk":"5347810914","pt":1646208335719,"mc":[{"id":"1.195453751","rc":[{"atb":[[5.8,0],[5.3,0]],"id":522749}],"con":true,"img":false}]}
{"op":"mcm","clk":"5347810962","pt":1646208336742,"mc":[{"id":"1.195453751","rc":[{"atb":[[4.9,3.27],[5.4,2.72]],"id":522749}],"con":true,"img":false}]}
{"op":"mcm","clk":"5347825168","pt":1646208663519,"mc":[{"id":"1.195453751","rc":[{"atb":[[1.94,106.38]],"id":3805784},{"atl":[[270,2]],"id":3805784},{"atb":[[16,6.56]],"id":522748},{"atb":[[7,15.4]],"id":522750},{"atl":[[850,2]],"id":522750},{"atb":[[25,3.28]],"id":3805731},{"atb":[[2.8,55.56]],"id":522752},{"atl":[[360,2]],"id":522752}],"con":true,"img":false}]}
{"op":"mcm","clk":"5347825171","pt":1646208663623,"mc":[{"id":"1.195453751","rc":[{"atb":[[3.4,41.67]],"id":3805747},{"atl":[[430,2]],"id":3805747},{"atb":[[26,4]],"id":522754},{"atb":[[7.2,16.13]],"id":522755},{"atl":[[780,2]],"id":522755},{"atb":[[4.1,18.18]],"id":522746},{"atl":[[510,2]],"id":522746},{"atb":[[6,11.44]],"id":522747},{"atl":[[660,2]],"id":522747},{"atb":[[2.38,57.18]],"id":522749},{"atl":[[360,2]],"id":522749},{"atb":[[21,5]],"id":522751},{"atb":[[5.3,23.26]],"id":3805762},{"atl":[[560,2]],"id":3805762},{"atb":[[3.5,40]],"id":522753},{"atl":[[450,2]],"id":522753},{"atb":[[21,18.34]],"id":522741},{"atb":[[12.5,8.52]],"id":522742},{"atb":[[21,5]],"id":522743},{"atb":[[3,47.64]],"id":3805740},{"atl":[[320,2]],"id":3805740},{"atb":[[2.78,15.4]],"id":3805772},{"atl":[[1000,2]],"id":3805772},{"atb":[[21,2]],"id":7607472},{"atb":[[4.7,21.64]],"id":522745},{"atl":[[1000,2]],"id":522745}],"con":true,"img":false}]}
{"op":"mcm","clk":"5347825187","pt":1646208663932,"mc":[{"id":"1.195453751","rc":[{"atb":[[9.8,0],[8.8,0]],"id":3805740}],"con":true,"img":false}]}
{"op":"mcm","clk":"5347825225","pt":1646208664645,"mc":[{"id":"1.195453751","rc":[{"atb":[[9.6,2.72],[8.6,3.27]],"id":3805740}],"con":true,"img":false}]}
{"op":"mcm","clk":"5347826723","pt":1646208700599,"mc":[{"id":"1.195453751","rc":[{"atl":[[830,2],[850,0]],"id":522750},{"atb":[[2.8,0],[2.94,51.55]],"id":522752}],"con":true,"img":false}]}
{"op":"mcm","clk":"5347826728","pt":1646208700703,"mc":[{"id":"1.195453751","rc":[{"atl":[[420,2]],"id":3805747},{"atl":[[500,2]],"id":522746}],"con":true,"img":false}]}
{"op":"mcm","clk":"5347826737","pt":1646208700806,"mc":[{"id":"1.195453751","rc":[{"atl":[[430,0]],"id":3805747},{"atl":[[510,0]],"id":522746},{"atb":[[2.38,0],[2.52,57.18]],"id":522749},{"atl":[[540,2],[560,0]],"id":3805762},{"atl":[[440,2],[450,0]],"id":522753},{"atl":[[310,2],[320,0]],"id":3805740}],"con":true,"img":false}]}
{"op":"mcm","clk":"5347827772","pt":1646208723284,"mc":[{"id":"1.195453751","rc":[{"atb":[[1.99,101.01]],"id":3805784}],"con":true,"img":false}]}
{"op":"mcm","clk":"5347827776","pt":1646208723386,"mc":[{"id":"1.195453751","rc":[{"atb":[[1.94,0]],"id":3805784},{"atl":[[750,2],[780,0]],"id":522755},{"atl":[[640,2]],"id":522747}],"con":true,"img":false}]}
{"op":"mcm","clk":"5347827781","pt":1646208723498,"mc":[{"id":"1.195453751","rc":[{"atl":[[660,0]],"id":522747}],"con":true,"img":false}]}
{"op":"mcm","clk":"5347828429","pt":1646208737321,"mc":[{"id":"1.195453751","rc":[{"atl":[[830,0],[820,2]],"id":522750}],"con":true,"img":false}]}
{"op":"mcm","clk":"5347828437","pt":1646208737426,"mc":[{"id":"1.195453751","rc":[{"atl":[[490,2],[500,0]],"id":522746}],"con":true,"img":false}]}
{"op":"mcm","clk":"5347830875","pt":1646208787685,"mc":[{"id":"1.195453751","rc":[{"atl":[[270,0],[75,2]],"id":3805784},{"atl":[[620,2],[640,0]],"id":522747},{"atb":[[16,0],[24,4.35]],"id":522748},{"atl":[[85,2],[360,0]],"id":522749},{"atb":[[21,0],[27,11.54]],"id":522751},{"atl":[[360,0],[230,2]],"id":522752},{"atb":[[3.5,0],[3.9,34.48]],"id":522753},{"atl":[[430,2],[440,0]],"id":522753},{"atb":[[12.5,0],[15,7.14]],"id":522742},{"atb":[[21,0],[29,3.57]],"id":522743},{"atb":[[3.35,42.55],[3,0]],"id":3805740},{"atl":[[300,2],[310,0]],"id":3805740},{"atb":[[2.78,0],[5.4,15.4]],"id":3805772},{"atb":[[21,0],[30,2]],"id":7607472},{"atb":[[5.9,20.41],[4.7,0]],"id":522745}],"con":true,"img":false}]}
{"op":"mcm","clk":"5347833657","pt":1646208843332,"mc":[{"id":"1.195453751","rc":[{"atb":[[2.8,55.56],[2.94,0]],"id":522752}],"con":true,"img":false}]}
{"op":"mcm","clk":"5347852539","pt":1646209029811,"mc":[{"id":"1.195453751","rc":[{"atb":[[9.6,0],[8.6,0]],"id":3805740}],"con":true,"img":false}]}
{"op":"mcm","clk":"5347852580","pt":1646209030592,"mc":[{"id":"1.195453751","rc":[{"atb":[[9.8,2.72]],"id":3805740}],"con":true,"img":false}]}
{"op":"mcm","clk":"5347852587","pt":1646209030697,"mc":[{"id":"1.195453751","rc":[{"atb":[[8.8,3.27]],"id":3805740}],"con":true,"img":false}]}
{"op":"mcm","clk":"5347869338","pt":1646209335793,"mc":[{"id":"1.195453751","rc":[{"atl":[[490,0],[480,2]],"id":522746},{"atl":[[620,0],[610,2]],"id":522747},{"atl":[[760,2],[820,0]],"id":522750},{"atl":[[220,2],[230,0]],"id":522752},{"atl":[[430,0],[420,2]],"id":522753}],"con":true,"img":false}]}
{"op":"mcm","clk":"5347869357","pt":1646209336152,"mc":[{"id":"1.195453751","rc":[{"atb":[[4.9,0],[5.4,0]],"id":522749}],"con":true,"img":false}]}
{"op":"mcm","clk":"5347869404","pt":1646209336879,"mc":[{"id":"1.195453751","rc":[{"atb":[[5,3.27],[5.5,47.19]],"id":522749}],"con":true,"img":false}]}
{"op":"mcm","clk":"5347877865","pt":1646209516188,"mc":[{"id":"1.195453751","rc":[{"atb":[[2.52,0],[2.62,61.73]],"id":522749}],"con":true,"img":false}]}
{"op":"mcm","clk":"5347883857","pt":1646209636252,"mc":[{"id":"1.195453751","rc":[{"atb":[[2.5,66.67],[2.62,0]],"id":522749}],"con":true,"img":false}]}
{"op":"mcm","clk":"5347886859","pt":1646209695236,"mc":[{"id":"1.195453751","rc":[{"atb":[[2.5,0],[2.62,61.73]],"id":522749},{"atb":[[2.8,0],[2.9,52.63]],"id":522752}],"con":true,"img":false}]}
{"op":"mcm","clk":"5347886886","pt":1646209695502,"mc":[{"id":"1.195453751","rc":[{"atb":[[5,0],[5.5,44.47]],"id":522749}],"con":true,"img":false}]}
{"op":"mcm","clk":"5347886932","pt":1646209696229,"mc":[{"id":"1.195453751","rc":[{"atb":[[5.6,2.72],[5.1,3.27]],"id":522749}],"con":true,"img":false}]}
{"op":"mcm","clk":"5347890168","pt":1646209760650,"mc":[{"id":"1.195453751","rc":[{"atl":[[1000,2]],"id":522748}],"con":true,"img":false}]}
{"op":"mcm","clk":"5347890885","pt":1646209775773,"mc":[{"id":"1.195453751","rc":[{"atl":[[1000,0]],"id":522748}],"con":true,"img":false}]}
{"op":"mcm","clk":"5347893888","pt":1646209835170,"mc":[{"id":"1.195453751","rc":[{"atl":[[470,2],[480,0]],"id":522746}],"con":true,"img":false}]}
{"op":"mcm","clk":"5347894859","pt":1646209855289,"mc":[{"id":"1.195453751","rc":[{"atl":[[760,0],[750,2]],"id":522750}],"con":true,"img":false}]}
{"op":"mcm","clk":"5347895757","pt":1646209873727,"mc":[{"id":"1.195453751","rc":[{"atb":[[9.8,0],[8.8,0]],"id":3805740}],"con":true,"img":false}]}
{"op":"mcm","clk":"5347895786","pt":1646209874397,"mc":[{"id":"1.195453751","rc":[{"atb":[[9.6,2.72],[8.6,3.27]],"id":3805740}],"con":true,"img":false}]}
{"op":"mcm","clk":"5347895889","pt":1646209876519,"mc":[{"id":"1.195453751","rc":[{"atb":[[6,0],[7,11.44]],"id":522747},{"atl":[[300,0],[290,2]],"id":3805740}],"con":true,"img":false}]}
{"op":"mcm","clk":"5347896082","pt":1646209880032,"mc":[{"id":"1.195453751","rc":[{"atl":[[65,2],[75,0]],"id":3805784}],"con":true,"img":false}]}
{"op":"mcm","clk":"5347897272","pt":1646209907589,"mc":[{"id":"1.195453751","rc":[{"atb":[[2.24,80.65],[1.99,0]],"id":3805784},{"atb":[[7.2,0],[11.5,9.52]],"id":522755},{"atb":[[4.1,0],[3.65,24.48]],"id":522746},{"atl":[[430,2],[470,0]],"id":522746},{"atb":[[5.7,16.84],[7,0]],"id":522747},{"atl":[[550,2],[610,0]],"id":522747},{"atb":[[2.62,0],[2.76,56.82]],"id":522749},{"atl":[[590,2],[750,0]],"id":522750},{"atl":[[210,2],[220,0]],"id":522752},{"atb":[[5.3,0],[4.4,29.41]],"id":3805762},{"atl":[[540,0],[520,2]],"id":3805762},{"atl":[[400,2],[420,0]],"id":522753},{"atl":[[270,2],[290,0]],"id":3805740},{"atl":[[1000,0]],"id":522745}],"con":true,"img":false}]}
{"op":"mcm","clk":"5347897280","pt":1646209907736,"mc":[{"id":"1.195453751","rc":[{"atl":[[530,2]],"id":522747}],"con":true,"img":false}]}
{"op":"mcm","clk":"5347897283","pt":1646209907839,"mc":[{"id":"1.195453751","rc":[{"atl":[[550,0]],"id":522747}],"con":true,"img":false}]}
{"op":"mcm","clk":"5347897300","pt":1646209908252,"mc":[{"id":"1.195453751","rc":[{"atb":[[18,0],[15.5,0]],"id":522746},{"atb":[[9.6,0],[8.6,0]],"id":3805740}],"con":true,"img":false}]}
{"op":"mcm","clk":"5347897337","pt":1646209908921,"mc":[{"id":"1.195453751","rc":[{"atb":[[8.4,3.27],[9.4,26.55]],"id":3805740}],"con":true,"img":false}]}
{"op":"mcm","clk":"5347897349","pt":1646209909228,"mc":[{"id":"1.195453751","rc":[{"atb":[[13,3.27],[15.5,2.72]],"id":522746}],"con":true,"img":false}]}
{"op":"mcm","clk":"5347898262","pt":1646209932264,"mc":[{"id":"1.195453751","rc":[{"atb":[[3.9,24.48],[3.65,0]],"id":522746},{"atl":[[430,0],[420,2]],"id":522746},{"atl":[[570,2],[590,0]],"id":522750},{"atl":[[180,2],[210,0]],"id":522752},{"atl":[[520,0],[510,2]],"id":3805762},{"atl":[[380,2],[400,0]],"id":522753}],"con":true,"img":false}]}
{"op":"mcm","clk":"5347899359","pt":1646209958481,"mc":[{"id":"1.195453751","rc":[{"atb":[[5.6,0],[5.1,0]],"id":522749}],"con":true,"img":false}]}
{"op":"mcm","clk":"5347899397","pt":1646209959200,"mc":[{"id":"1.195453751","rc":[{"atb":[[5.7,2.72]],"id":522749}],"con":true,"img":false}]}
{"op":"mcm","clk":"5347899412","pt":1646209959510,"mc":[{"id":"1.195453751","rc":[{"atb":[[5.2,3.27]],"id":522749}],"con":true,"img":false}]}
{"op":"mcm","clk":"5347902245","pt":1646210027540,"mc":[{"id":"1.195453751","rc":[{"atl":[[420,0]],"id":522746},{"atb":[[2.76,0]],"id":522749},{"atl":[[570,0],[590,2]],"id":522750},{"atl":[[180,0],[210,2]],"id":522752},{"atl":[[510,0]],"id":3805762},{"atl":[[400,2]],"id":522753}],"con":true,"img":false}]}
{"op":"mcm","clk":"5347902251","pt":1646210027598,"mc":[{"id":"1.195453751","rc":[{"atl":[[430,2]],"id":522746},{"atb":[[2.64,60.98]],"id":522749},{"atl":[[520,2]],"id":3805762},{"atl":[[380,0]],"id":522753}],"con":true,"img":false}]}
{"op":"mcm","clk":"5347919314","pt":1646210463233,"mc":[{"id":"1.195453751","rc":[{"atb":[[6.4,16.84],[5.7,0]],"id":522747},{"atb":[[2.9,0],[3,50]],"id":522752},{"atl":[[200,2],[210,0]],"id":522752},{"atl":[[520,0],[510,2]],"id":3805762},{"atl":[[270,0],[250,2]],"id":3805740}],"con":true,"img":false}]}
{"op":"mcm","clk":"5347919322","pt":1646210463285,"mc":[{"id":"1.195453751","rc":[{"atb":[[2.64,0],[2.76,56.82]],"id":522749}],"con":true,"img":false}]}
{"op":"mcm","clk":"5347919334","pt":1646210463495,"mc":[{"id":"1.195453751","rc":[{"atb":[[13,0],[15.5,0]],"id":522746},{"atb":[[5.2,0],[5.7,0]],"id":522749}],"con":true,"img":false}]}
{"op":"mcm","clk":"5347919340","pt":1646210463595,"mc":[{"id":"1.195453751","rc":[{"atb":[[8.4,0],[9.4,23.82]],"id":3805740}],"con":true,"img":false}]}
{"op":"mcm","clk":"5347919369","pt":1646210464310,"mc":[{"id":"1.195453751","rc":[{"atb":[[16,2.72],[13.5,3.27]],"id":522746},{"atb":[[5.6,2.72],[5.1,3.27]],"id":522749},{"atb":[[8,3.27],[9,2.72]],"id":3805740}],"con":true,"img":false}]}
{"op":"mcm","clk":"5347920183","pt":1646210486954,"mc":[{"id":"1.195453751","rc":[{"atl":[[430,0],[420,2]],"id":522746}],"con":true,"img":false}]}
{"op":"mcm","clk":"5347924130","pt":1646210583266,"mc":[{"id":"1.195453751","rc":[{"atb":[[2.64,60.98],[2.76,0]],"id":522749},{"atb":[[2.86,53.76],[3,0]],"id":522752}],"con":true,"img":false}]}
{"op":"mcm","clk":"5347947159","pt":1646211065124,"mc":[{"id":"1.195453751","rc":[{"atl":[[60,2]],"id":3805784},{"atb":[[29,0]],"id":522743}],"con":true,"img":false}]}
{"op":"mcm","clk":"5347947163","pt":1646211065226,"mc":[{"id":"1.195453751","rc":[{"atl":[[65,0]],"id":3805784},{"atb":[[2.52,65.79],[2.64,0]],"id":522749},{"atb":[[21,5]],"id":522743}],"con":true,"img":false}]}
{"op":"mcm","clk":"5347952079","pt":1646211162085,"mc":[{"id":"1.195453751","rc":[{"atb":[[2.52,0],[2.84,54.35]],"id":522749},{"atl":[[590,0],[580,2]],"id":522750},{"atb":[[2.86,0],[2.98,50.51]],"id":522752},{"atl":[[390,2],[400,0]],"id":522753}],"con":true,"img":false}]}
{"op":"mcm","clk":"5347952091","pt":1646211162348,"mc":[{"id":"1.195453751","rc":[{"atb":[[5.6,0],[5.1,0]],"id":522749},{"atb":[[8,0],[9,0]],"id":3805740}],"con":true,"img":false}]}
{"op":"mcm","clk":"5347952125","pt":1646211163072,"mc":[{"id":"1.195453751","rc":[{"atb":[[5.9,2.72],[5.4,3.27]],"id":522749},{"atb":[[9.2,2.72],[8.2,3.27]],"id":3805740}],"con":true,"img":false}]}
{"op":"mcm","clk":"5347955854","pt":1646211243180,"mc":[{"id":"1.195453751","rc":[{"atb":[[2.64,60.98],[2.84,0]],"id":522749}],"con":true,"img":false}]}
{"op":"mcm","clk":"5347955898","pt":1646211243899,"mc":[{"id":"1.195453751","rc":[{"atb":[[5.9,0],[5.4,0]],"id":522749},{"atb":[[9.2,0],[8.2,0]],"id":3805740}],"con":true,"img":false}]}
{"op":"mcm","clk":"5347955957","pt":1646211244878,"mc":[{"id":"1.195453751","rc":[{"atb":[[5.6,2.72],[5.1,3.27]],"id":522749},{"atb":[[8,3.27],[9,2.72]],"id":3805740}],"con":true,"img":false}]}
{"op":"mcm","clk":"5347958944","pt":1646211302175,"mc":[{"id":"1.195453751","rc":[{"atb":[[20,0],[25,0]],"id":522747},{"atb":[[18,0],[21,0]],"id":522750},{"atb":[[36,0],[28,0]],"id":522751},{"atb":[[6.4,0],[5.7,0]],"id":522752},{"atb":[[32,0],[26,0]],"id":522742},{"atb":[[16.5,0],[19,0]],"id":3805772},{"atb":[[80,0],[55,0]],"id":7607472}],"con":true,"img":false}]}
{"op":"mcm","clk":"5347958960","pt":1646211302434,"mc":[{"id":"1.195453751","rc":[{"atb":[[7.6,0],[6.6,0]],"id":3805747}],"con":true,"img":false}]}
{"op":"mcm","clk":"5347958982","pt":1646211302846,"mc":[{"id":"1.195453751","rc":[{"atb":[[21,3.27],[26,2.72]],"id":522747},{"atb":[[18.5,3.27],[22,2.72]],"id":522750},{"atb":[[38,2.72],[29,3.27]],"id":522751},{"atb":[[34,2.72],[27,3.27]],"id":522742},{"atb":[[17,3.27],[19.5,2.72]],"id":3805772},{"atb":[[85,2.72],[60,3.27]],"id":7607472}],"con":true,"img":false}]}
{"op":"mcm","clk":"5347958988","pt":1646211302949,"mc":[{"id":"1.195453751","rc":[{"atb":[[6.8,2.72],[5.9,3.27]],"id":522752}],"con":true,"img":false}]}
{"op":"mcm","clk":"5347959002","pt":1646211303156,"mc":[{"id":"1.195453751","rc":[{"atb":[[8,2.72],[7,3.27]],"id":3805747}],"con":true,"img":false}]}
{"op":"mcm","clk":"5347959120","pt":1646211305479,"mc":[{"id":"1.195453751","rc":[{"atb":[[2.24,0],[2.5,66.67]],"id":3805784},{"atl":[[65,2],[60,0]],"id":3805784},{"atb":[[3.7,37.04],[3.4,0]],"id":3805747},{"atb":[[11.5,0]],"id":522755},{"atl":[[750,0]],"id":522755},{"atb":[[4.3,24.48],[3.9,0]],"id":522746},{"atb":[[6.4,0]],"id":522747},{"atl":[[530,0]],"id":522747},{"atl":[[1000,2]],"id":522748},{"atb":[[2.64,0]],"id":522749},{"atl":[[1000,2]],"id":3805731},{"atl":[[470,2],[510,0]],"id":3805762},{"atb":[[3.9,0],[3.5,40]],"id":522753},{"atl":[[330,2],[390,0]],"id":522753},{"atb":[[3.35,0],[3.75,36.36]],"id":3805740},{"atl":[[890,2]],"id":522745}],"con":true,"img":false}]}
{"op":"mcm","clk":"5347959124","pt":1646211305583,"mc":[{"id":"1.195453751","rc":[{"atb":[[34,11.11],[26,0]],"id":522754},{"atl":[[1000,2]],"id":522754},{"atb":[[7.2,16.13]],"id":522755},{"atl":[[660,2]],"id":522755},{"atl":[[410,2],[420,0]],"id":522746},{"atb":[[5.4,16.84]],"id":522747},{"atl":[[510,2]],"id":522747},{"atb":[[2.94,51.55]],"id":522749},{"atb":[[7,0],[5.9,20.41]],"id":522750},{"atl":[[530,2],[580,0]],"id":522750},{"atl":[[1000,2]],"id":522751},{"atb":[[3.35,42.55],[2.98,0]],"id":522752},{"atl":[[880,2],[1000,0]],"id":3805772}],"con":true,"img":false}]}
{"op":"mcm","clk":"5347959130","pt":1646211305683,"mc":[{"id":"1.195453751","rc":[{"atl":[[910,2],[1000,0]],"id":522748},{"atl":[[810,2],[890,0]],"id":522745}],"con":true,"img":false}]}
{"op":"mcm","clk":"5347959136","pt":1646211305785,"mc":[{"id":"1.195453751","rc":[{"atb":[[7.2,0],[8.8,12.82]],"id":522755},{"atl":[[620,2],[660,0]],"id":522755},{"atb":[[6.4,16.84],[5.4,0]],"id":522747},{"atl":[[480,2],[510,0]],"id":522747},{"atb":[[3.3,43.48],[2.94,0]],"id":522749},{"atb":[[7.2,16.13],[5.9,0]],"id":522750},{"atl":[[530,0],[500,2]],"id":522750},{"atl":[[940,2],[1000,0]],"id":522751}],"con":true,"img":false}]}
{"op":"mcm","clk":"5347959150","pt":1646211306042,"mc":[{"id":"1.195453751","rc":[{"atb":[[16,0],[13.5,0]],"id":522746}],"con":true,"img":false}]}
{"op":"mcm","clk":"5347959188","pt":1646211306865,"mc":[{"id":"1.195453751","rc":[{"atb":[[16.5,2.72],[14,18.66]],"id":522746}],"con":true,"img":false}]}
{"op":"mcm","clk":"5347959261","pt":1646211308565,"mc":[{"id":"1.195453751","rc":[{"atb":[[21,0]],"id":522747}],"con":true,"img":false}]}
{"op":"mcm","clk":"5347959272","pt":1646211308872,"mc":[{"id":"1.195453751","rc":[{"atb":[[26,0]],"id":522747}],"con":true,"img":false}]}
{"op":"mcm","clk":"5347959298","pt":1646211309284,"mc":[{"id":"1.195453751","rc":[{"atb":[[20,3.27]],"id":522747}],"con":true,"img":false}]}
{"op":"mcm","clk":"5347959311","pt":1646211309591,"mc":[{"id":"1.195453751","rc":[{"atb":[[25,2.72]],"id":522747}],"con":true,"img":false}]}
{"op":"mcm","clk":"5347959597","pt":1646211316203,"mc":[{"id":"1.195453751","rc":[{"atb":[[2.5,0],[2.62,61.73]],"id":3805784},{"atl":[[65,0],[60,2]],"id":3805784},{"atb":[[3.7,0]],"id":3805747},{"atb":[[4.3,0],[5.1,24.39]],"id":522746},{"atb":[[4,33.33],[3.5,0]],"id":522753},{"atl":[[310,2],[330,0]],"id":522753},{"atb":[[4.3,30.3],[3.75,0]],"id":3805740}],"con":true,"img":false}]}
{"op":"mcm","clk":"5347959601","pt":1646211316309,"mc":[{"id":"1.195453751","rc":[{"atb":[[4.2,31.25]],"id":3805747},{"atl":[[800,2],[880,0]],"id":3805772}],"con":true,"img":false}]}
{"op":"mcm","clk":"5347960557","pt":1646211338788,"mc":[{"id":"1.195453751","rc":[{"atb":[[34,0],[44,0]],"id":522748},{"atb":[[40,0],[30,0]],"id":522741},{"atb":[[12.5,0],[15,0]],"id":522745}],"con":true,"img":false}]}
{"op":"mcm","clk":"5347960591","pt":1646211339516,"mc":[{"id":"1.195453751","rc":[{"atb":[[38,3.27],[48,2.72]],"id":522748},{"atb":[[32,9.73],[42,2.72]],"id":522741},{"atb":[[13,3.27],[15.5,2.72]],"id":522745}],"con":true,"img":false}]}
{"op":"mcm","clk":"5347960675","pt":1646211341014,"mc":[{"id":"1.195453751","rc":[{"atl":[[590,2],[620,0]],"id":522755},{"atl":[[470,2],[480,0]],"id":522747},{"atl":[[880,2],[910,0]],"id":522748},{"atl":[[490,2],[500,0]],"id":522750},{"atl":[[910,2],[940,0]],"id":522751},{"atl":[[300,2],[310,0]],"id":522753},{"atl":[[760,2],[800,0]],"id":3805772}],"con":true,"img":false}]}
{"op":"mcm","clk":"5347960703","pt":1646211341632,"mc":[{"id":"1.195453751","rc":[{"atb":[[20,0],[25,0]],"id":522747}],"con":true,"img":false}]}
{"op":"mcm","clk":"5347960739","pt":1646211342406,"mc":[{"id":"1.195453751","rc":[{"atb":[[19.5,3.27],[24,2.72]],"id":522747}],"con":true,"img":false}]}
{"op":"mcm","clk":"5347961102","pt":1646211352134,"mc":[{"id":"1.195453751","rc":[{"atb":[[5.6,0],[5.1,0]],"id":522749},{"atb":[[8,0],[9,0]],"id":3805740}],"con":true,"img":false}]}
{"op":"mcm","clk":"5347961135","pt":1646211352804,"mc":[{"id":"1.195453751","rc":[{"atb":[[6.4,2.72],[5.7,3.27]],"id":522749},{"atb":[[9.2,3.27],[10.5,2.72]],"id":3805740}],"con":true,"img":false}]}
{"op":"mcm","clk":"5347962414","pt":1646211380280,"mc":[{"id":"1.195453751","rc":[{"atl":[[300,0],[290,2]],"id":522753}],"con":true,"img":false}]}
{"op":"mcm","clk":"5347962474","pt":1646211381357,"mc":[{"id":"1.195453751","rc":[{"atl":[[80,2],[85,0]],"id":522749}],"con":true,"img":false}]}
{"op":"mcm","clk":"5347962861","pt":1646211390275,"mc":[{"id":"1.195453751","rc":[{"atb":[[9.2,0],[10.5,0]],"id":3805740}],"con":true,"img":false}]}
{"op":"mcm","clk":"5347962900","pt":1646211391000,"mc":[{"id":"1.195453751","rc":[{"atb":[[9,3.27],[10,2.72]],"id":3805740}],"con":true,"img":false}]}
{"op":"mcm","clk":"5347963727","pt":1646211407916,"mc":[{"id":"1.195453751","rc":[{"atb":[[14,15.39]],"id":522746}],"con":true,"img":false}]}
{"op":"mcm","clk":"5347963743","pt":1646211408226,"mc":[{"id":"1.195453751","rc":[{"atb":[[16.5,0]],"id":522746}],"con":true,"img":false}]}
{"op":"mcm","clk":"5347963758","pt":1646211408590,"mc":[{"id":"1.195453751","rc":[{"atb":[[14.5,3.27]],"id":522746}],"con":true,"img":false}]}
{"op":"mcm","clk":"5347963778","pt":1646211409000,"mc":[{"id":"1.195453751","rc":[{"atb":[[17,2.72]],"id":522746}],"con":true,"img":false}]}
{"op":"mcm","clk":"5347963912","pt":1646211411626,"mc":[{"id":"1.195453751","rc":[{"atl":[[410,0],[400,2]],"id":522746},{"atl":[[910,0],[900,2]],"id":522751}],"con":true,"img":false}]}
{"op":"mcm","clk":"5347963959","pt":1646211412301,"mc":[{"id":"1.195453751","rc":[{"atb":[[14.5,0]],"id":522746}],"con":true,"img":false}]}
{"op":"mcm","clk":"5347964018","pt":1646211413337,"mc":[{"id":"1.195453751","rc":[{"atb":[[14,18.66]],"id":522746}],"con":true,"img":false}]}
{"op":"mcm","clk":"5347964085","pt":1646211414789,"mc":[{"id":"1.195453751","rc":[{"atb":[[17,0]],"id":522746}],"con":true,"img":false}]}
{"op":"mcm","clk":"5347964127","pt":1646211415469,"mc":[{"id":"1.195453751","rc":[{"atb":[[16.5,2.72]],"id":522746}],"con":true,"img":false}]}
{"op":"mcm","clk":"5347964233","pt":1646211417272,"mc":[{"id":"1.195453751","rc":[{"atb":[[2.92,0],[3.05,0]],"id":3805784},{"atb":[[9,0],[10,0]],"id":3805740}],"con":true,"img":false}]}
{"op":"mcm","clk":"5347964281","pt":1646211417994,"mc":[{"id":"1.195453751","rc":[{"atb":[[3.1,2.72],[2.94,3.27]],"id":3805784},{"atb":[[9.8,2.72],[8.8,3.27]],"id":3805740}],"con":true,"img":false}]}
{"op":"mcm","clk":"5347964290","pt":1646211418198,"mc":[{"id":"1.195453751","rc":[{"atb":[[2.82,54.95],[2.62,0]],"id":3805784}],"con":true,"img":false}]}
{"op":"mcm","clk":"5347964361","pt":1646211419440,"mc":[{"id":"1.195453751","rc":[{"atb":[[2.3,0],[2.6,0],[2.1,0]],"id":3805784},{"atb":[[7.2,0],[5.1,0],[4.1,0]],"id":3805747},{"atb":[[34,3.03],[170,0],[60,0]],"id":522754},{"atb":[[9.6,0],[23,0],[14,0]],"id":522755},{"atb":[[9.6,0],[23,0],[14,3.27]],"id":522746},{"atb":[[36,0],[19,0],[14,0]],"id":522747},{"atb":[[42,0],[26,0],[110,0]],"id":522748},{"atb":[[8,0],[4.5,0],[5.5,0]],"id":522749},{"atb":[[16,0],[11,0],[27,0]],"id":522750},{"atb":[[18.5,0],[27,3.85],[60,0]],"id":522751},{"atb":[[24,0],[9.8,0],[14.5,0]],"id":3805731},{"atb":[[4,0],[5.5,0],[3.5,0]],"id":522752},{"atb":[[8,0],[6,0],[12.5,0]],"id":3805762},{"atb":[[5.1,0],[9.2,0],[6.2,0]],"id":522753},{"atb":[[32,3.27],[80,0],[21,5]],"id":522741},{"atb":[[17,0],[48,0],[24,0]],"id":522742},{"atb":[[42,0],[26,0],[110,0]],"id":522743},{"atb":[[6.4,0],[5.2,0],[9.4,0]],"id":3805740},{"atb":[[16,0],[11,0],[27,0]],"id":3805772},{"atb":[[610,0],[360,0],[460,0]],"id":7607472},{"atb":[[19.5,0],[12,0],[8.8,0]],"id":522745}],"con":true,"img":false}]}
{"op":"mcm","clk":"5347964372","pt":1646211419597,"mc":[{"id":"1.195453751","rc":[{"atb":[[23,4.55],[27,0]],"id":522751},{"atb":[[25,0],[15,9.28]],"id":3805731}],"con":true,"img":false}]}
{"op":"mcm","clk":"5347964544","pt":1646211422704,"mc":[{"id":"1.195453751","rc":[{"atb":[[2.3,102.62],[1.85,313.89],[1.95,280.85]],"id":3805784},{"atb":[[5.1,32.53],[3.55,104.63],[3.05,130.15]],"id":3805747},{"atb":[[16,17.78],[22,12.7],[60,2.25]],"id":522754},{"atb":[[5.8,55.58],[7.6,40.42],[14,10.26]],"id":522755},{"atb":[[5.8,55.58],[7.6,40.42],[14,13.53]],"id":522746},{"atb":[[9.6,31.02],[19,7.41],[7.6,40.42]],"id":522747},{"atb":[[18,15.69],[42,3.25],[13,22.23]],"id":522748},{"atb":[[5.5,29.64],[3.25,118.58],[3.75,97.02]],"id":522749},{"atb":[[16,8.89],[6.4,49.41],[8.4,36.05]],"id":522750},{"atb":[[27,5.13],[13.5,21.34],[9.4,31.76]],"id":522751},{"atb":[[7.8,39.23],[14.5,9.87],[5.9,54.45]],"id":3805731},{"atb":[[4,44.47],[2.8,148.23],[3,133.4]],"id":522752},{"atb":[[8,19.05],[4,88.93],[5,66.7]],"id":3805762},{"atb":[[6.2,25.65],[4.1,86.06],[3.55,104.63]],"id":522753},{"atb":[[32,7.57],[10.5,28.08],[15.5,18.4]],"id":522741},{"atb":[[24,5.8],[12,24.25],[8.8,34.2]],"id":522742},{"atb":[[18,15.69],[42,3.25],[13,22.23]],"id":522743},{"atb":[[16,8.89],[6.4,49.41],[8.4,36.05]],"id":3805772},{"atb":[[3.6,102.62],[6.4,24.7],[4.2,83.37]],"id":3805740},{"atb":[[260,1.03],[160,1.67],[460,0.28]],"id":7607472},{"atb":[[12,12.12],[6.8,46],[5.4,60.63]],"id":522745}],"con":true,"img":false}]}
{"op":"mcm","clk":"5347964747","pt":1646211426385,"mc":[{"id":"1.195453751","rc":[{"atl":[[50,2],[60,0]],"id":3805784},{"atl":[[430,2],[470,0]],"id":3805762},{"atb":[[21,0],[14.5,7.41]],"id":522741},{"atb":[[19.5,5.41],[15,0]],"id":522742},{"atb":[[6.4,67.93],[5.4,0]],"id":3805772},{"atb":[[40,2.56],[30,0]],"id":7607472}],"con":true,"img":false}]}
{"op":"mcm","clk":"5347965929","pt":1646211449748,"mc":[{"id":"1.195453751","rc":[{"atb":[[8,0],[7,0]],"id":3805747}],"con":true,"img":false}]}
{"op":"mcm","clk":"5347965938","pt":1646211449950,"mc":[{"id":"1.195453751","rc":[{"atb":[[36,0],[46,0]],"id":522743}],"con":true,"img":false}]}
{"op":"mcm","clk":"5347965973","pt":1646211450633,"mc":[{"id":"1.195453751","rc":[{"atb":[[7.2,3.27],[8.2,2.72]],"id":3805747},{"atb":[[38,3.27],[48,2.72]],"id":522743}],"con":true,"img":false}]}
{"op":"mcm","clk":"5347968291","pt":1646211507913,"mc":[{"id":"1.195453751","rc":[{"atb":[[9.8,0]],"id":3805740}],"con":true,"img":false}]}
{"op":"mcm","clk":"5347968309","pt":1646211508326,"mc":[{"id":"1.195453751","rc":[{"atb":[[8.8,0]],"id":3805740}],"con":true,"img":false}]}
{"op":"mcm","clk":"5347968325","pt":1646211508627,"mc":[{"id":"1.195453751","rc":[{"atb":[[10,2.72]],"id":3805740}],"con":true,"img":false}]}
{"op":"mcm","clk":"5347968347","pt":1646211509117,"mc":[{"id":"1.195453751","rc":[{"atb":[[9,3.27]],"id":3805740}],"con":true,"img":false}]}
{"op":"mcm","clk":"5347968583","pt":1646211516363,"mc":[{"id":"1.195453751","rc":[{"atb":[[7.2,0],[6,20]],"id":522750}],"con":true,"img":false}]}
{"op":"mcm","clk":"5347968611","pt":1646211516938,"mc":[{"id":"1.195453751","rc":[{"atb":[[19.5,0],[24,0]],"id":522747},{"atb":[[6.4,0],[5.7,0]],"id":522749}],"con":true,"img":false}]}
{"op":"mcm","clk":"5347968634","pt":1646211517647,"mc":[{"id":"1.195453751","rc":[{"atb":[[20,3.27],[25,2.72]],"id":522747},{"atb":[[5.8,3.27],[6.6,2.72]],"id":522749}],"con":true,"img":false}]}
{"op":"mcm","clk":"5347968710","pt":1646211519554,"mc":[{"id":"1.195453751","rc":[{"atl":[[890,2],[900,0]],"id":522751}],"con":true,"img":false}]}
{"op":"mcm","clk":"5347968729","pt":1646211520069,"mc":[{"id":"1.195453751","rc":[{"atb":[[16.5,0],[14,10.26]],"id":522746}],"con":true,"img":false}]}
{"op":"mcm","clk":"5347968762","pt":1646211520748,"mc":[{"id":"1.195453751","rc":[{"atb":[[16,2.72],[13.5,3.27]],"id":522746}],"con":true,"img":false}]}
{"op":"mcm","clk":"5347969058","pt":1646211527171,"mc":[{"id":"1.195453751","rc":[{"atb":[[5.8,0],[6.6,0]],"id":522749}],"con":true,"img":false}]}
{"op":"mcm","clk":"5347969100","pt":1646211527947,"mc":[{"id":"1.195453751","rc":[{"atb":[[6.4,2.72],[5.7,3.27]],"id":522749}],"con":true,"img":false}]}
{"op":"mcm","clk":"5347975312","pt":1646211660647,"mc":[{"id":"1.195453751","rc":[{"atb":[[2.3,102.45],[3.1,2.72],[1.85,313.4],[1.95,280.41],[2.94,3.26]],"id":3805784},{"atb":[[7.2,3.26],[5.1,41.41],[8.2,11.65],[3.55,104.46],[3.05,129.94]],"id":3805747},{"atl":[[410,0.38],[440,2.79]],"id":3805747},{"atb":[[16,17.76],[42,10.68],[85,9.9],[22,12.68],[55,2.72],[110,4.95],[60,2.25]],"id":522754},{"atb":[[17,2.72],[5.8,55.49],[7.6,40.36],[14,10.24],[14.5,3.26]],"id":522755},{"atb":[[16,2.72],[5.8,55.49],[7.6,40.36],[13.5,3.26],[14,10.24]],"id":522746},{"atl":[[390,0.4],[420,2.92]],"id":522746},{"atb":[[9.6,30.97],[19,7.4],[20,3.26],[7.6,40.36],[25,2.72]],"id":522747},{"atb":[[18,15.66],[38,3.26],[42,3.24],[48,2.72],[50,3.23],[13,22.19]],"id":522748},{"atl":[[870,0.17]],"id":522748},{"atb":[[6.4,2.72],[5.5,29.59],[3.25,118.39],[5.7,3.26],[3.75,96.87]],"id":522749},{"atb":[[16,8.87],[18.5,3.26],[6.4,49.33],[22,2.72],[8.4,35.99]],"id":522750},{"atb":[[38,2.72],[80,4.95],[40,4.06],[27,5.12],[13.5,21.3],[29,3.26],[60,9.9],[9.4,31.71]],"id":522751},{"atl":[[160,4.95],[880,0.17]],"id":522751},{"atb":[[17.5,2.72],[7.8,39.17],[14.5,27.72],[5.9,54.36],[15,9.27]],"id":3805731},{"atb":[[4,44.4],[2.8,147.99],[6.8,2.72],[3,133.19],[5.9,3.26]],"id":522752},{"atb":[[8,19.02],[4,88.79],[5,66.59],[12,2.72],[9.8,3.26]],"id":3805762},{"atb":[[9,3.26],[10,2.72],[6.2,25.61],[4.1,85.93],[3.55,104.46]],"id":522753},{"atb":[[32,7.56],[42,2.72],[10.5,28.03],[15.5,18.37]],"id":522741},{"atb":[[34,2.72],[24,5.79],[12,24.21],[27,3.26],[8.8,34.15]],"id":522742},{"atb":[[18,15.66],[38,3.26],[42,3.24],[48,2.72],[13,22.19]],"id":522743},{"atb":[[3.6,102.45],[9,3.26],[6.4,24.66],[10,2.72],[4.2,83.24]],"id":3805740},{"atb":[[16,8.87],[17,3.26],[19.5,2.72],[6.4,67.85],[8.4,35.99]],"id":3805772},{"atb":[[260,1.03],[160,4.73],[85,2.72],[460,0.28],[60,3.26]],"id":7607472},{"atb":[[38,4.95],[12,12.1],[6.8,45.93],[13,3.26],[30,9.9],[15.5,2.72],[5.4,60.54]],"id":522745},{"atl":[[120,4.95]],"id":522745}],"con":true,"img":false}]}
{"op":"mcm","clk":"5347975317","pt":1646211660703,"mc":[{"id":"1.195453751","rc":[{"atb":[[2.82,63.88],[3.1,11.65],[3.7,4.95],[3.5,9.9]],"id":3805784},{"atl":[[6.8,4.95],[7.6,9.9],[48,3.37],[60,8.93]],"id":3805784},{"atb":[[10,4.95],[9.2,9.9]],"id":3805747},{"atl":[[16.5,4.95],[18.5,9.9]],"id":3805747},{"atb":[[65,2.47]],"id":522754},{"atl":[[990,0.15]],"id":522754},{"atb":[[17.5,8.93],[26,9.9],[14,19.17],[30,4.95]],"id":522755},{"atl":[[580,0.27],[610,2.01],[80,9.9],[60,4.95]],"id":522755},{"atb":[[11.5,4.95],[9.8,9.9]],"id":522746},{"atl":[[38,9.9],[30,4.95]],"id":522746},{"atb":[[17.5,4.95],[15.5,9.9]],"id":522747},{"atl":[[75,9.9],[55,4.95],[460,0.34],[490,2.5]],"id":522747},{"atb":[[65,9.9],[38,12.15],[85,4.95]],"id":522748},{"atl":[[190,4.95],[900,1.35]],"id":522748},{"atb":[[5.6,4.95],[5.5,38.53],[5.2,9.9]],"id":522749},{"atl":[[9.6,4.95],[75,2.14],[11,9.9],[90,8.93]],"id":522749},{"atb":[[16,22.76],[14,9.9]],"id":522750},{"atl":[[46,4.95],[60,9.9],[480,0.33],[510,2.4]],"id":522750},{"atb":[[27,14.05]],"id":522751},{"atl":[[910,1.34]],"id":522751},{"atb":[[18,9.32],[42,9.9],[50,4.95]],"id":3805731},{"atl":[[230,4.95],[990,0.15]],"id":3805731},{"atb":[[4,53.33],[6.4,4.95],[5.8,9.9]],"id":522752},{"atl":[[10.5,9.9],[190,0.83],[220,5.59],[9.4,4.95]],"id":522752},{"atb":[[8,27.95],[10,9.9],[12,16.61]],"id":3805762},{"atl":[[22,4.95],[26,9.9],[420,0.37],[450,2.73]],"id":3805762},{"atb":[[6.2,34.54],[7.6,9.9],[8.4,4.95]],"id":522753},{"atl":[[280,0.56],[310,3.96],[13.5,4.95],[15.5,9.9]],"id":522753},{"atb":[[140,4.95],[44,3.68],[100,9.9],[15.5,40.9]],"id":522741},{"atl":[[1000,0.15]],"id":522741},{"atb":[[36,4.52],[90,9.9],[24,15.54],[120,4.95]],"id":522742},{"atl":[[1000,0.15]],"id":522742},{"atb":[[38,12.93],[160,4.95],[50,3.23],[120,9.9]],"id":522743},{"atl":[[1000,0.15]],"id":522743},{"atb":[[8,9.9],[6.4,33.59],[8.8,4.95]],"id":3805740},{"atl":[[16,9.9],[270,4.55],[14,4.95],[240,0.66]],"id":3805740},{"atb":[[16,17.81],[36,9.9],[20,8.34],[44,4.95]],"id":3805772},{"atl":[[750,0.21],[780,1.56],[100,4.95]],"id":3805772},{"atb":[[160,9.68],[120,9.9]],"id":7607472},{"atb":[[16,8.93],[12,21.04]],"id":522745},{"atl":[[800,0.19],[830,1.47]],"id":522745}],"con":true,"img":false}]}
{"op":"mcm","clk":"5347975324","pt":1646211660806,"mc":[{"id":"1.195453751","rc":[{"atl":[[420,0],[430,2]],"id":3805747},{"atl":[[400,0],[410,2]],"id":522746},{"atl":[[890,0],[510,2]],"id":522751},{"atl":[[810,0],[420,2]],"id":522745}],"con":true,"img":false}]}
{"op":"mcm","clk":"5347975330","pt":1646211660916,"mc":[{"id":"1.195453751","rc":[{"atb":[[2.82,8.93],[3,50]],"id":3805784},{"atl":[[10.5,10.53],[50,0]],"id":3805784},{"atl":[[590,0],[210,2]],"id":522755},{"atl":[[85,2],[470,0]],"id":522747},{"atl":[[880,0],[500,2]],"id":522748},{"atl":[[80,0],[13,8.33]],"id":522749},{"atl":[[100,2],[490,0]],"id":522750},{"atb":[[28,3.7],[15,3.26]],"id":3805731},{"atl":[[740,2],[1000,0]],"id":3805731},{"atl":[[200,0],[25,4.17]],"id":522752},{"atl":[[70,2],[430,0]],"id":3805762},{"atl":[[290,0],[29,3.57]],"id":522753},{"atl":[[760,0],[380,2]],"id":3805772},{"atl":[[29,3.57],[250,0]],"id":3805740}],"con":true,"img":false}]}
{"op":"mcm","clk":"5347975348","pt":1646211661220,"mc":[{"id":"1.195453751","rc":[{"atl":[[870,2.17],[500,0]],"id":522748},{"atl":[[380,0],[750,2.21]],"id":3805772}],"con":true,"img":false}]}
{"op":"mcm","clk":"5347975357","pt":1646211661375,"mc":[{"id":"1.195453751","rc":[{"atl":[[1000,1.22]],"id":3805731}],"con":true,"img":false}]}
{"op":"mcm","clk":"5347975374","pt":1646211661686,"mc":[{"id":"1.195453751","rc":[{"atb":[[5.3,23.26],[4.2,0]],"id":3805747},{"atb":[[34,0],[48,2.13]],"id":522754},{"atb":[[11.5,9.52],[8.8,0]],"id":522755},{"atb":[[5.1,0],[5.8,76.32]],"id":522746},{"atb":[[6.4,0],[8.8,12.82]],"id":522747},{"atb":[[32,3.23],[24,0]],"id":522748},{"atb":[[4,33.33],[3.3,0]],"id":522749},{"atb":[[8,14.29],[6,0]],"id":522750},{"atb":[[32,3.23],[23,0]],"id":522751},{"atb":[[4,86.66],[3.35,0]],"id":522752},{"atb":[[6.2,19.23],[4.4,0]],"id":3805762},{"atb":[[4,0],[4.8,26.32]],"id":522753},{"atl":[[1000,2.15]],"id":522741},{"atl":[[1000,2.15]],"id":522742},{"atb":[[4.3,0],[5.5,22.22]],"id":3805740}],"con":true,"img":false}]}
{"op":"mcm","clk":"5347975582","pt":1646211665911,"mc":[{"id":"1.195453751","rc":[{"atb":[[20,0],[25,0]],"id":522747},{"atl":[[800,2],[510,0]],"id":522751},{"atl":[[22,0],[23,4.95],[26,0],[27,9.9]],"id":3805762},{"atl":[[730,2],[420,0]],"id":522745}],"con":true,"img":false}]}
{"op":"mcm","clk":"5347975586","pt":1646211666015,"mc":[{"id":"1.195453751","rc":[{"atl":[[740,0],[980,2]],"id":3805731}],"con":true,"img":false}]}
{"op":"mcm","clk":"5347975618","pt":1646211666478,"mc":[{"id":"1.195453751","rc":[{"atb":[[15.5,28.26]],"id":522747}],"con":true,"img":false}]}
{"op":"mcm","clk":"5347975641","pt":1646211666886,"mc":[{"id":"1.195453751","rc":[{"atb":[[17.5,14.56],[21,3.26],[26,2.72]],"id":522747}],"con":true,"img":false}]}
{"op":"mcm","clk":"5347975680","pt":1646211667505,"mc":[{"id":"1.195453751","rc":[{"atb":[[15.5,9.9]],"id":522747}],"con":true,"img":false}]}
{"op":"mcm","clk":"5347975719","pt":1646211668280,"mc":[{"id":"1.195453751","rc":[{"atl":[[800,2]],"id":522748},{"atl":[[700,2]],"id":3805772}],"con":true,"img":false}]}
{"op":"mcm","clk":"5347975727","pt":1646211668383,"mc":[{"id":"1.195453751","rc":[{"atl":[[870,0.17]],"id":522748},{"atl":[[750,0.21]],"id":3805772}],"con":true,"img":false}]}
{"op":"mcm","clk":"5347975741","pt":1646211668793,"mc":[{"id":"1.195453751","rc":[{"atb":[[4.8,0],[5.5,22.22]],"id":522753}],"con":true,"img":false}]}
{"op":"mcm","clk":"5347975883","pt":1646211671319,"mc":[{"id":"1.195453751","rc":[{"atb":[[80,4.95],[60,9.9]],"id":522748}],"con":true,"img":false}]}
{"op":"mcm","clk":"5347975896","pt":1646211671425,"mc":[{"id":"1.195453751","rc":[{"atb":[[65,0],[85,0]],"id":522748}],"con":true,"img":false}]}
{"op":"mcm","clk":"5347976077","pt":1646211674530,"mc":[{"id":"1.195453751","rc":[{"atl":[[190,0]],"id":522748}],"con":true,"img":false}]}
{"op":"mcm","clk":"5347976090","pt":1646211674838,"mc":[{"id":"1.195453751","rc":[{"atl":[[200,4.95]],"id":522748}],"con":true,"img":false}]}
{"op":"mcm","clk":"5347976116","pt":1646211675202,"mc":[{"id":"1.195453751","rc":[{"atl":[[160,0],[170,4.95]],"id":522751}],"con":true,"img":false}]}
{"op":"mcm","clk":"5347976124","pt":1646211675312,"mc":[{"id":"1.195453751","rc":[{"atl":[[800,0],[400,2]],"id":522751}],"con":true,"img":false}]}
{"op":"mcm","clk":"5347976172","pt":1646211676140,"mc":[{"id":"1.195453751","rc":[{"atb":[[4.8,26.32],[5.5,0]],"id":522753}],"con":true,"img":false}]}
{"op":"mcm","clk":"5347976182","pt":1646211676346,"mc":[{"id":"1.195453751","rc":[{"atb":[[5.1,32.48],[10,22.56],[8.2,33.74]],"id":3805747},{"atl":[[16.5,15.18],[410,3.48],[440,0]],"id":3805747},{"atb":[[65,9.85],[42,3.26]],"id":522754},{"atl":[[390,3.67],[420,0],[30,10.42]],"id":522746},{"atb":[[80,6.95]],"id":522748},{"atl":[[200,5.74]],"id":522748},{"atb":[[28,16.55],[14.5,9.86]],"id":3805731}],"con":true,"img":false}]}
{"op":"mcm","clk":"5347976185","pt":1646211676452,"mc":[{"id":"1.195453751","rc":[{"atb":[[2.82,0],[3.1,41.11],[3.7,34.41]],"id":3805784},{"atl":[[10.5,39.98],[6.8,32.29],[60,0]],"id":3805784},{"atb":[[110,6.4]],"id":522754},{"atb":[[17.5,29.56],[14,10.24],[30,10.42]],"id":522755},{"atl":[[610,0],[210,8.07],[60,7.64]],"id":522755},{"atl":[[85,14.21],[50,3.23],[490,0]],"id":522747},{"atb":[[38,3.26],[50,15.41]],"id":522748},{"atl":[[870,1.63]],"id":522748},{"atb":[[5.6,19.66],[5.5,29.59]],"id":522749},{"atl":[[9.6,19.66],[90,0]],"id":522749},{"atl":[[44,3.68],[100,14.21],[510,0]],"id":522750},{"atb":[[80,6.95],[40,17.47],[27,5.12]],"id":522751},{"atl":[[390,0.4],[910,0]],"id":522751},{"atb":[[55,2.93]],"id":3805731},{"atl":[[230,5.64]],"id":3805731},{"atb":[[4,77.73],[5.9,16.82]],"id":522752},{"atl":[[25,17.72],[220,0],[9.4,18.5]],"id":522752},{"atb":[[8,19.02],[9.8,25.35]],"id":3805762},{"atl":[[65,2.47],[70,20.22],[450,0]],"id":3805762},{"atb":[[6.2,25.61],[8.4,17.61]],"id":522753},{"atl":[[310,0],[13.5,17.61],[29,16.23]],"id":522753},{"atb":[[140,6.09],[15.5,18.37]],"id":522741},{"atb":[[130,1.23],[36,18.61],[24,5.79]],"id":522742},{"atb":[[38,3.26],[170,0.93],[50,15.41]],"id":522743},{"atb":[[16,8.87],[20,23.05],[44,8.64]],"id":3805772},{"atl":[[750,1.9],[780,0],[100,6.55]],"id":3805772},{"atb":[[6.4,24.66],[8.8,17.61]],"id":3805740},{"atl":[[270,0],[14,17.15],[29,16.23]],"id":3805740},{"atb":[[16,23.64],[40,4.06],[12,12.1]],"id":522745},{"atl":[[800,1.78],[830,0],[120,6.28]],"id":522745}],"con":true,"img":false}]}
{"op":"mcm","clk":"5347976191","pt":1646211676506,"mc":[{"id":"1.195453751","rc":[{"atl":[[410,0]],"id":522746},{"atb":[[21,0],[26,0]],"id":522747}],"con":true,"img":false}]}
{"op":"mcm","clk":"5347976194","pt":1646211676615,"mc":[{"id":"1.195453751","rc":[{"atb":[[3,0],[3.55,39.22]],"id":3805784},{"atl":[[10.5,29.45],[8.8,12.82]],"id":3805784},{"atl":[[85,2],[430,0]],"id":3805747},{"atl":[[44,2.33]],"id":522746},{"atl":[[65,2]],"id":522747},{"atl":[[80,2],[100,12.21]],"id":522750},{"atl":[[24,4.35],[29,12.66]],"id":522753},{"atl":[[23,4.55],[29,12.66]],"id":3805740}],"con":true,"img":false}]}
{"op":"mcm","clk":"5347976201","pt":1646211676711,"mc":[{"id":"1.195453751","rc":[{"atl":[[85,12.21]],"id":522747}],"con":true,"img":false}]}
{"op":"mcm","clk":"5347976211","pt":1646211677023,"mc":[{"id":"1.195453751","rc":[{"atb":[[8.2,24.81]],"id":3805747},{"atl":[[410,3.1]],"id":3805747},{"atl":[[390,3.26]],"id":522746},{"atb":[[50,12.17]],"id":522748},{"atl":[[870,1.45]],"id":522748},{"atl":[[990,1.43],[1000,0]],"id":3805731}],"con":true,"img":false}]}
{"op":"mcm","clk":"5347976218","pt":1646211677129,"mc":[{"id":"1.195453751","rc":[{"atb":[[3.1,32.18]],"id":3805784},{"atl":[[48,0]],"id":3805784},{"atb":[[65,7.37]],"id":522754},{"atb":[[17.5,20.62]],"id":522755},{"atl":[[580,0]],"id":522755},{"atl":[[460,0]],"id":522747},{"atl":[[75,0]],"id":522749},{"atl":[[480,0]],"id":522750},{"atb":[[40,13.4]],"id":522751},{"atl":[[880,0]],"id":522751},{"atb":[[18,0]],"id":3805731},{"atl":[[990,1.28]],"id":3805731},{"atl":[[420,0]],"id":3805762},{"atl":[[280,0]],"id":522753},{"atb":[[44,0]],"id":522741},{"atb":[[36,14.08]],"id":522742},{"atb":[[50,12.17]],"id":522743},{"atl":[[240,0]],"id":3805740},{"atb":[[20,14.71]],"id":3805772},{"atl":[[750,1.69]],"id":3805772},{"atb":[[16,14.71]],"id":522745}],"con":true,"img":false}]}
{"op":"mcm","clk":"5347976226","pt":1646211677231,"mc":[{"id":"1.195453751","rc":[{"atl":[[900,0]],"id":522748},{"atl":[[13,23.04]],"id":522749},{"atl":[[880,1.43]],"id":522751},{"atl":[[190,0]],"id":522752},{"atb":[[44,12.83]],"id":522741},{"atl":[[800,1.58]],"id":522745}],"con":true,"img":false}]}
{"op":"mcm","clk":"5347976232","pt":1646211677335,"mc":[{"id":"1.195453751","rc":[{"atb":[[19.5,3.26],[24,2.72]],"id":522747}],"con":true,"img":false}]}
{"op":"mcm","clk":"5347976501","pt":1646211681725,"mc":[{"id":"1.195453751","rc":[{"atb":[[3.55,0],[3.5,49.9]],"id":3805784}],"con":true,"img":false}]}
{"op":"mcm","clk":"5347977016","pt":1646211691635,"mc":[{"id":"1.195453751","rc":[{"atl":[[85,17.52],[410,0]],"id":3805747},{"atl":[[44,21.92],[390,0]],"id":522746}],"con":true,"img":false}]}
{"op":"mcm","clk":"5347977021","pt":1646211691737,"mc":[{"id":"1.195453751","rc":[{"atb":[[42,21.63],[28,3.7]],"id":3805731}],"con":true,"img":false}]}
{"op":"mcm","clk":"5347977025","pt":1646211691840,"mc":[{"id":"1.195453751","rc":[{"atl":[[10.5,0],[8.8,108.64]],"id":3805784},{"atl":[[65,11.67],[85,0]],"id":522747},{"atl":[[100,0],[60,22.74]],"id":522750},{"atl":[[170,5.89]],"id":522751},{"atl":[[65,22.78],[70,2],[23,12.15]],"id":3805762},{"atl":[[24,25.54],[29,0]],"id":522753},{"atb":[[36,0],[90,20.47]],"id":522742},{"atb":[[50,0],[120,18.66]],"id":522743},{"atl":[[23,26.04],[29,0]],"id":3805740},{"atb":[[16,0],[30,23.31]],"id":522745}],"con":true,"img":false}]}
{"op":"mcm","clk":"5347977033","pt":1646211691952,"mc":[{"id":"1.195453751","rc":[{"atb":[[3.1,79.8]],"id":3805784}],"con":true,"img":false}]}
{"op":"mcm","clk":"5347977041","pt":1646211692157,"mc":[{"id":"1.195453751","rc":[{"atb":[[3.5,9.9]],"id":3805784}],"con":true,"img":false}]}
{"op":"mcm","clk":"5347977069","pt":1646211692566,"mc":[{"id":"1.195453751","rc":[{"atl":[[390,0]],"id":522751}],"con":true,"img":false}]}
{"op":"mcm","clk":"5347977073","pt":1646211692613,"mc":[{"id":"1.195453751","rc":[{"atl":[[65,20.3]],"id":3805762}],"con":true,"img":false}]}
{"op":"mcm","clk":"5347977086","pt":1646211692931,"mc":[{"id":"1.195453751","rc":[{"atl":[[400,5.29],[880,0]],"id":522751}],"con":true,"img":false}]}
{"op":"mcm","clk":"5347977111","pt":1646211693340,"mc":[{"id":"1.195453751","rc":[{"atl":[[810,2]],"id":522751}],"con":true,"img":false}]}
{"op":"mcm","clk":"5347977116","pt":1646211693439,"mc":[{"id":"1.195453751","rc":[{"atl":[[400,3.29]],"id":522751}],"con":true,"img":false}]}
{"op":"mcm","clk":"5347977368","pt":1646211698554,"mc":[{"id":"1.195453751","rc":[{"atl":[[270,4.95]],"id":522754}],"con":true,"img":false}]}
{"op":"mcm","clk":"5347977379","pt":1646211698761,"mc":[{"id":"1.195453751","rc":[{"atl":[[650,2],[1000,0]],"id":522754}],"con":true,"img":false}]}
{"op":"mcm","clk":"5347977383","pt":1646211698969,"mc":[{"id":"1.195453751","rc":[{"atl":[[990,2.15]],"id":522754}],"con":true,"img":false}]}
{"op":"mcm","clk":"5347977388","pt":1646211699070,"mc":[{"id":"1.195453751","rc":[{"atl":[[650,0]],"id":522754}],"con":true,"img":false}]}
{"op":"mcm","clk":"5347977400","pt":1646211699276,"mc":[{"id":"1.195453751","rc":[{"atl":[[270,5.54],[1000,1.32]],"id":522754}],"con":true,"img":false}]}
{"op":"mcm","clk":"5347977433","pt":1646211699948,"mc":[{"id":"1.195453751","rc":[{"atl":[[990,2]],"id":522754}],"con":true,"img":false}]}
{"op":"mcm","clk":"5347977459","pt":1646211700566,"mc":[{"id":"1.195453751","rc":[{"atl":[[400,0],[810,3.65]],"id":522751}],"con":true,"img":false}]}
{"op":"mcm","clk":"5347977469","pt":1646211700778,"mc":[{"id":"1.195453751","rc":[{"atl":[[34,4.95],[38,0],[42,9.9],[30,0]],"id":522746},{"atb":[[55,0]],"id":3805731},{"atb":[[40,0]],"id":522745}],"con":true,"img":false}]}
{"op":"mcm","clk":"5347977475","pt":1646211700983,"mc":[{"id":"1.195453751","rc":[{"atl":[[9.6,4.95]],"id":522749}],"con":true,"img":false}]}
{"op":"mcm","clk":"5347977481","pt":1646211701036,"mc":[{"id":"1.195453751","rc":[{"atl":[[9.6,0],[11,0],[11.5,9.9],[9.8,4.95]],"id":522749}],"con":true,"img":false}]}
{"op":"mcm","clk":"5347977485","pt":1646211701188,"mc":[{"id":"1.195453751","rc":[{"atb":[[3.45,4.95],[3.7,0],[3.25,9.9],[3.5,0]],"id":3805784},{"atl":[[270,0]],"id":522754},{"atl":[[50,0]],"id":522747},{"atl":[[200,0],[230,4.95]],"id":522748},{"atl":[[65,9.9],[44,0],[46,0],[48,4.95],[60,12.83]],"id":522750},{"atl":[[170,0],[190,4.95]],"id":522751}],"con":true,"img":false}]}
{"op":"mcm","clk":"5347977489","pt":1646211701255,"mc":[{"id":"1.195453751","rc":[{"atl":[[810,2]],"id":522751},{"atb":[[42,9.9],[28,16.55]],"id":3805731},{"atb":[[30,9.9],[15.5,14.12]],"id":522745}],"con":true,"img":false}]}
{"op":"mcm","clk":"5347977493","pt":1646211701347,"mc":[{"id":"1.195453751","rc":[{"atb":[[3.1,32.18],[3.5,9.91]],"id":3805784},{"atl":[[800,0],[400,2]],"id":522748},{"atl":[[810,0],[410,2]],"id":522751}],"con":true,"img":false}]}
{"op":"mcm","clk":"5347977499","pt":1646211701454,"mc":[{"id":"1.195453751","rc":[{"atl":[[42,13.77]],"id":522746},{"atb":[[44,3.68]],"id":3805731},{"atb":[[32,5.11]],"id":522745}],"con":true,"img":false}]}
{"op":"mcm","clk":"5347977503","pt":1646211701556,"mc":[{"id":"1.195453751","rc":[{"atl":[[1000,0]],"id":522754},{"atl":[[65,2]],"id":522747},{"atl":[[65,30.63],[60,0]],"id":522750}],"con":true,"img":false}]}
{"op":"mcm","clk":"5347977508","pt":1646211701660,"mc":[{"id":"1.195453751","rc":[{"atb":[[5.8,55.49],[6.8,17.24]],"id":522746},{"atl":[[65,0],[70,2],[75,27.87]],"id":522747},{"atl":[[11,8.9]],"id":522749},{"atb":[[32,0],[40,15.96]],"id":522751},{"atl":[[1000,0.15]],"id":522741},{"atl":[[1000,0.15]],"id":522742}],"con":true,"img":false}]}
{"op":"mcm","clk":"5347977520","pt":1646211701866,"mc":[{"id":"1.195453751","rc":[{"atb":[[3.1,2.72],[3.25,39.36],[3.5,39.36]],"id":3805784},{"atl":[[990,2.15],[250,4.95]],"id":522754},{"atl":[[60,2.68]],"id":522747},{"atl":[[390,0.4]],"id":522748},{"atl":[[55,2.93]],"id":522750},{"atl":[[190,0],[400,0.39]],"id":522751}],"con":true,"img":false}]}
{"op":"mcm","clk":"5347977528","pt":1646211701972,"mc":[{"id":"1.195453751","rc":[{"atb":[[16,0],[13.5,0]],"id":522746}],"con":true,"img":false}]}
{"op":"mcm","clk":"5347977538","pt":1646211702179,"mc":[{"id":"1.195453751","rc":[{"atl":[[11.5,30.5],[13,8.33]],"id":522749},{"atb":[[28,3.7]],"id":3805731},{"atb":[[15.5,2.72]],"id":522745}],"con":true,"img":false}]}
{"op":"mcm","clk":"5347977542","pt":1646211702280,"mc":[{"id":"1.195453751","rc":[{"atl":[[400,5.36]],"id":522748}],"con":true,"img":false}]}
{"op":"mcm","clk":"5347977548","pt":1646211702333,"mc":[{"id":"1.195453751","rc":[{"atb":[[9.8,39.87]],"id":522746},{"atl":[[870,0]],"id":522748}],"con":true,"img":false}]}
{"op":"mcm","clk":"5347977569","pt":1646211702645,"mc":[{"id":"1.195453751","rc":[{"atl":[[260,4.95],[250,0]],"id":522754},{"atl":[[170,4.95]],"id":522751}],"con":true,"img":false}]}
{"op":"mcm","clk":"5347977574","pt":1646211702750,"mc":[{"id":"1.195453751","rc":[{"atb":[[17.5,2.72],[15,3.26]],"id":522746}],"con":true,"img":false}]}
{"op":"mcm","clk":"5347977602","pt":1646211703368,"mc":[{"id":"1.195453751","rc":[{"atb":[[9.8,9.9]],"id":522746}],"con":true,"img":false}]}
{"op":"mcm","clk":"5347977610","pt":1646211703472,"mc":[{"id":"1.195453751","rc":[{"atl":[[170,0],[180,4.95]],"id":522751}],"con":true,"img":false}]}
{"op":"mcm","clk":"5347977700","pt":1646211705283,"mc":[{"id":"1.195453751","rc":[{"atl":[[34,0],[36,4.95],[42,3.86],[44,31.83]],"id":522746}],"con":true,"img":false}]}
{"op":"mcm","clk":"5347977744","pt":1646211706100,"mc":[{"id":"1.195453751","rc":[{"atl":[[36,0],[44,21.92]],"id":522746}],"con":true,"img":false}]}
{"op":"mcm","clk":"5347977769","pt":1646211706466,"mc":[{"id":"1.195453751","rc":[{"atb":[[3.25,83.68],[3.5,29.45]],"id":3805784}],"con":true,"img":false}]}
{"op":"mcm","clk":"5347977787","pt":1646211706773,"mc":[{"id":"1.195453751","rc":[{"atl":[[44,2.33],[46,11.5]],"id":522746}],"con":true,"img":false}]}
{"op":"mcm","clk":"5347977791","pt":1646211706879,"mc":[{"id":"1.195453751","rc":[{"atl":[[34,4.95],[42,13.77]],"id":522746},{"atb":[[42,22.74]],"id":3805731}],"con":true,"img":false}]}
{"op":"mcm","clk":"5347977796","pt":1646211706980,"mc":[{"id":"1.195453751","rc":[{"atl":[[70,10.9],[75,9.9]],"id":522747},{"atl":[[390,0.4]],"id":522751},{"atb":[[30,24.86]],"id":522745}],"con":true,"img":false}]}
{"op":"mcm","clk":"5347977816","pt":1646211707445,"mc":[{"id":"1.195453751","rc":[{"atl":[[46,0]],"id":522746}],"con":true,"img":false}]}
{"op":"mcm","clk":"5347977839","pt":1646211707754,"mc":[{"id":"1.195453751","rc":[{"atl":[[400,0]],"id":522751}],"con":true,"img":false}]}
{"op":"mcm","clk":"5347977857","pt":1646211708064,"mc":[{"id":"1.195453751","rc":[{"atl":[[400,3.4]],"id":522751}],"con":true,"img":false}]}
{"op":"mcm","clk":"5347977979","pt":1646211710492,"mc":[{"id":"1.195453751","rc":[{"atl":[[34,0],[36,4.95],[42,3.86],[44,12.23]],"id":522746}],"con":true,"img":false}]}
{"op":"mcm","clk":"5347978110","pt":1646211714287,"mc":[{"id":"1.195453751","rc":[{"atl":[[280,4.93]],"id":522754}],"con":true,"img":false}]}
{"op":"mcm","clk":"5347978112","pt":1646211714388,"mc":[{"id":"1.195453751","rc":[{"atl":[[980,0.16]],"id":522754}],"con":true,"img":false}]}
{"op":"mcm","clk":"5347978113","pt":1646211714490,"mc":[{"id":"1.195453751","rc":[{"atl":[[690,2],[990,0.15]],"id":522754}],"con":true,"img":false}]}
{"op":"mcm","clk":"5347978142","pt":1646211715160,"mc":[{"id":"1.195453751","rc":[{"atl":[[990,0]],"id":522754}],"con":true,"img":false}]}
{"op":"mcm","clk":"5347978182","pt":1646211716396,"mc":[{"id":"1.195453751","rc":[{"atb":[[50,8.19]],"id":3805731},{"atb":[[36,4.95],[38,4.28],[29,9.9],[30,14.95]],"id":522745}],"con":true,"img":false}]}
{"op":"mcm","clk":"5347978193","pt":1646211716603,"mc":[{"id":"1.195453751","rc":[{"atl":[[9.8,22.97]],"id":522749}],"con":true,"img":false}]}
{"op":"mcm","clk":"5347978198","pt":1646211716704,"mc":[{"id":"1.195453751","rc":[{"atl":[[180,5.84]],"id":522751}],"con":true,"img":false}]}
{"op":"mcm","clk":"5347978203","pt":1646211716820,"mc":[{"id":"1.195453751","rc":[{"atl":[[260,5.56]],"id":522754},{"atl":[[50,3.23]],"id":522747},{"atl":[[220,0.72]],"id":522748},{"atl":[[46,3.52]],"id":522750},{"atb":[[32,18.82]],"id":522745}],"con":true,"img":false}]}
{"op":"mcm","clk":"5347978208","pt":1646211716871,"mc":[{"id":"1.195453751","rc":[{"atb":[[30,0]],"id":522745}],"con":true,"img":false}]}
{"op":"mcm","clk":"5347978223","pt":1646211717173,"mc":[{"id":"1.195453751","rc":[{"atl":[[60,12.36]],"id":522747},{"atl":[[390,3.96]],"id":522748},{"atb":[[32,13.71],[38,0]],"id":522745}],"con":true,"img":false}]}
{"op":"mcm","clk":"5347978227","pt":1646211717276,"mc":[{"id":"1.195453751","rc":[{"atl":[[70,2]],"id":522747},{"atl":[[400,2]],"id":522748},{"atl":[[11,0]],"id":522749},{"atl":[[55,13.03]],"id":522750},{"atb":[[44,0]],"id":3805731}],"con":true,"img":false}]}
{"op":"mcm","clk":"5347978234","pt":1646211717478,"mc":[{"id":"1.195453751","rc":[{"atl":[[65,9.9]],"id":522750}],"con":true,"img":false}]}
{"op":"mcm","clk":"5347978238","pt":1646211717591,"mc":[{"id":"1.195453751","rc":[{"atl":[[980,0]],"id":522754},{"atl":[[60,9.67]],"id":522747},{"atl":[[390,3.55]],"id":522748},{"atl":[[55,10.09]],"id":522750},{"atl":[[390,0]],"id":522751}],"con":true,"img":false}]}
{"op":"mcm","clk":"5347978249","pt":1646211717789,"mc":[{"id":"1.195453751","rc":[{"atl":[[11.5,9.9]],"id":522749}],"con":true,"img":false}]}
{"op":"mcm","clk":"5347978255","pt":1646211717893,"mc":[{"id":"1.195453751","rc":[{"atl":[[13,49.94]],"id":522749},{"atb":[[42,9.9],[28,17.59]],"id":3805731},{"atb":[[34,4.8]],"id":522745}],"con":true,"img":false}]}
{"op":"mcm","clk":"5347978265","pt":1646211718202,"mc":[{"id":"1.195453751","rc":[{"atl":[[400,0],[410,5.38]],"id":522751}],"con":true,"img":false}]}
{"op":"mcm","clk":"5347978294","pt":1646211718973,"mc":[{"id":"1.195453751","rc":[{"atl":[[410,2]],"id":522751}],"con":true,"img":false}]}
{"op":"mcm","clk":"5347978368","pt":1646211720629,"mc":[{"id":"1.195453751","rc":[{"atb":[[3.45,0],[3.7,4.95],[3.25,73.77],[3.5,39.36]],"id":3805784},{"atl":[[260,0.61],[250,4.95]],"id":522754},{"atb":[[11.5,0],[12,4.95],[9.8,0]],"id":522746},{"atl":[[65,9.9],[75,0],[48,4.95],[55,0]],"id":522747},{"atb":[[75,9.9],[80,2],[95,4.95],[60,0]],"id":522748},{"atb":[[16,17.81],[16.5,4.95],[14,0],[14.5,9.9]],"id":522750},{"atb":[[75,9.9],[80,2],[95,4.95],[60,0]],"id":522751},{"atb":[[6.4,0],[5.8,0],[6.6,4.95],[5.9,26.73]],"id":522752},{"atl":[[21,4.95],[23,7.2],[25,9.9],[27,0]],"id":3805762},{"atl":[[13,4.95],[13.5,12.66],[15,9.9],[15.5,0]],"id":522753},{"atb":[[150,4.95],[110,9.9]],"id":522741},{"atb":[[130,6.18],[90,10.56],[95,9.9],[120,0]],"id":522742},{"atb":[[36,0],[38,9.9],[44,3.68],[46,4.95]],"id":3805772}],"con":true,"img":false}]}
{"op":"mcm","clk":"5347978372","pt":1646211720685,"mc":[{"id":"1.195453751","rc":[{"atl":[[10.5,9.9],[11.5,0],[9.8,18.01],[9.4,4.95]],"id":522749},{"atb":[[140,1.13],[100,0]],"id":522741}],"con":true,"img":false}]}
{"op":"mcm","clk":"5347978376","pt":1646211720786,"mc":[{"id":"1.195453751","rc":[{"atb":[[3.4,41.67],[3.25,29.45]],"id":3805784}],"con":true,"img":false}]}
{"op":"mcm","clk":"5347978389","pt":1646211721097,"mc":[{"id":"1.195453751","rc":[{"atb":[[3.7,63.67]],"id":3805784},{"atl":[[36,9.48]],"id":522746},{"atb":[[75,22.55],[95,6.63],[50,0]],"id":522748},{"atb":[[16.5,17.54],[16,8.87]],"id":522750},{"atb":[[75,24.62],[40,2.56],[100,1.6]],"id":522751},{"atl":[[65,0],[20,7.22],[25,39.36]],"id":3805762},{"atl":[[24,4.35],[12.5,13.78],[15,31.99]],"id":522753},{"atb":[[150,6.01],[44,0],[110,22.65]],"id":522741},{"atb":[[38,22.74],[20,0],[48,3.37]],"id":3805772}],"con":true,"img":false}]}
{"op":"mcm","clk":"5347978404","pt":1646211721307,"mc":[{"id":"1.195453751","rc":[{"atb":[[3.4,148.16],[3.25,0]],"id":3805784},{"atl":[[7.2,9.9],[6.4,4.95],[6.8,27.33],[7.6,0]],"id":3805784},{"atl":[[180,4.95],[230,0]],"id":522748},{"atl":[[65,0],[44,4.95],[48,0],[55,20]],"id":522750}],"con":true,"img":false}]}
{"op":"mcm","clk":"5347978412","pt":1646211721510,"mc":[{"id":"1.195453751","rc":[{"atl":[[8,14.29],[8.8,95.82]],"id":3805784},{"atl":[[44,25.34]],"id":522746}],"con":true,"img":false}]}
{"op":"mcm","clk":"5347978429","pt":1646211721772,"mc":[{"id":"1.195453751","rc":[{"atl":[[7.2,109.04],[6.2,30.48],[8.8,0]],"id":3805784},{"atl":[[42,0]],"id":522746},{"atb":[[80,0]],"id":522748},{"atl":[[13.5,0]],"id":522753},{"atb":[[140,0]],"id":522741}],"con":true,"img":false}]}
{"op":"mcm","clk":"5347978435","pt":1646211721978,"mc":[{"id":"1.195453751","rc":[{"atb":[[3.5,9.9]],"id":3805784},{"atb":[[80,0]],"id":522751},{"atl":[[23,0]],"id":3805762},{"atb":[[44,0]],"id":3805772}],"con":true,"img":false}]}
{"op":"mcm","clk":"5347978463","pt":1646211722571,"mc":[{"id":"1.195453751","rc":[{"atl":[[6.8,0]],"id":3805784}],"con":true,"img":false}]}
{"op":"mcm","clk":"5347978486","pt":1646211722883,"mc":[{"id":"1.195453751","rc":[{"atl":[[200,7.03]],"id":522751}],"con":true,"img":false}]}
{"op":"mcm","clk":"5347978596","pt":1646211725413,"mc":[{"id":"1.195453751","rc":[{"atl":[[200,0],[410,5.44]],"id":522751}],"con":true,"img":false}]}
{"op":"mcm","clk":"5347978711","pt":1646211727581,"mc":[{"id":"1.195453751","rc":[{"atb":[[6.8,24.81]],"id":522752}],"con":true,"img":false}]}
{"op":"mcm","clk":"5347978742","pt":1646211728299,"mc":[{"id":"1.195453751","rc":[{"atb":[[75,9.9],[48,15.37]],"id":522748},{"atb":[[42,15.71],[110,9.9]],"id":522741}],"con":true,"img":false}]}
{"op":"mcm","clk":"5347978788","pt":1646211729279,"mc":[{"id":"1.195453751","rc":[{"atl":[[250,5.59]],"id":522754}],"con":true,"img":false}]}
{"op":"mcm","clk":"5347978798","pt":1646211729693,"mc":[{"id":"1.195453751","rc":[{"atl":[[180,0],[190,4.95]],"id":522748},{"atl":[[9.6,4.95],[10.5,0],[11,9.9],[9.4,0]],"id":522749},{"atb":[[36,0],[38,4.95],[29,0],[30,9.9]],"id":522745}],"con":true,"img":false}]}
{"op":"mcm","clk":"5347978810","pt":1646211730008,"mc":[{"id":"1.195453751","rc":[{"atl":[[260,0]],"id":522754}],"con":true,"img":false}]}
{"op":"mcm","clk":"5347978827","pt":1646211730514,"mc":[{"id":"1.195453751","rc":[{"atl":[[280,0],[690,4.06]],"id":522754}],"con":true,"img":false}]}
{"op":"mcm","clk":"5347978859","pt":1646211730980,"mc":[{"id":"1.195453751","rc":[{"atb":[[38,9.23]],"id":522745}],"con":true,"img":false}]}
{"op":"mcm","clk":"5347978866","pt":1646211731290,"mc":[{"id":"1.195453751","rc":[{"atl":[[690,2]],"id":522754}],"con":true,"img":false}]}
{"op":"mcm","clk":"5347978873","pt":1646211731393,"mc":[{"id":"1.195453751","rc":[{"atl":[[46,3.52]],"id":522747},{"atl":[[210,0.75]],"id":522748},{"atl":[[44,8.64]],"id":522750}],"con":true,"img":false}]}
{"op":"mcm","clk":"5347978884","pt":1646211731802,"mc":[{"id":"1.195453751","rc":[{"atb":[[34,0]],"id":522745}],"con":true,"img":false}]}
{"op":"mcm","clk":"5347978893","pt":1646211732010,"mc":[{"id":"1.195453751","rc":[{"atl":[[50,13.33]],"id":522747},{"atl":[[390,0],[220,7.23]],"id":522748}],"con":true,"img":false}]}
{"op":"mcm","clk":"5347978896","pt":1646211732112,"mc":[{"id":"1.195453751","rc":[{"atl":[[60,0]],"id":522747}],"con":true,"img":false}]}
{"op":"mcm","clk":"5347978899","pt":1646211732214,"mc":[{"id":"1.195453751","rc":[{"atl":[[50,10.09]],"id":522747},{"atl":[[220,6.5]],"id":522748},{"atl":[[46,0]],"id":522750},{"atb":[[32,0],[30,32.97]],"id":522745}],"con":true,"img":false}]}
{"op":"mcm","clk":"5347978907","pt":1646211732523,"mc":[{"id":"1.195453751","rc":[{"atl":[[11,31.99],[13,8.33]],"id":522749}],"con":true,"img":false}]}
{"op":"mcm","clk":"5347978913","pt":1646211732732,"mc":[{"id":"1.195453751","rc":[{"atl":[[80,19.7],[55,9.9]],"id":522750},{"atl":[[410,2],[200,7.17]],"id":522751}],"con":true,"img":false}]}
{"op":"mcm","clk":"5347978924","pt":1646211732984,"mc":[{"id":"1.195453751","rc":[{"atl":[[9.6,23.39]],"id":522749}],"con":true,"img":false}]}
{"op":"mcm","clk":"5347978949","pt":1646211733805,"mc":[{"id":"1.195453751","rc":[{"atl":[[9.8,0]],"id":522749}],"con":true,"img":false}]}
{"op":"mcm","clk":"5347979031","pt":1646211736028,"mc":[{"id":"1.195453751","rc":[{"atl":[[40,28.18],[44,12.23]],"id":522746}],"con":true,"img":false}]}
{"op":"mcm","clk":"5347979063","pt":1646211736910,"mc":[{"id":"1.195453751","rc":[{"atl":[[40,0]],"id":522746}],"con":true,"img":false}]}
{"op":"mcm","clk":"5347979145","pt":1646211739226,"mc":[{"id":"1.195453751","rc":[{"atb":[[30,9.9],[15.5,16.1]],"id":522745}],"con":true,"img":false}]}
{"op":"mcm","clk":"5347979166","pt":1646211739532,"mc":[{"id":"1.195453751","rc":[{"atl":[[13,49.94]],"id":522749}],"con":true,"img":false}]}
{"op":"mcm","clk":"5347979173","pt":1646211739640,"mc":[{"id":"1.195453751","rc":[{"atl":[[11,9.9]],"id":522749}],"con":true,"img":false}]}
{"op":"mcm","clk":"5347979185","pt":1646211739947,"mc":[{"id":"1.195453751","rc":[{"atl":[[200,0],[410,5.54]],"id":522751}],"con":true,"img":false}]}
{"op":"mcm","clk":"5347979246","pt":1646211741445,"mc":[{"id":"1.195453751","rc":[{"atb":[[24,0]],"id":522747}],"con":true,"img":false}]}
{"op":"mcm","clk":"5347979248","pt":1646211741545,"mc":[{"id":"1.195453751","rc":[{"atb":[[19.5,0]],"id":522747}],"con":true,"img":false}]}
{"op":"mcm","clk":"5347979261","pt":1646211741957,"mc":[{"id":"1.195453751","rc":[{"atb":[[17.5,32.91]],"id":522747}],"con":true,"img":false}]}
{"op":"mcm","clk":"5347979268","pt":1646211742168,"mc":[{"id":"1.195453751","rc":[{"atb":[[25,2.72]],"id":522747}],"con":true,"img":false}]}
{"op":"mcm","clk":"5347979278","pt":1646211742217,"mc":[{"id":"1.195453751","rc":[{"atb":[[20,3.26]],"id":522747}],"con":true,"img":false}]}
{"op":"mcm","clk":"5347979308","pt":1646211742937,"mc":[{"id":"1.195453751","rc":[{"atb":[[17.5,14.56]],"id":522747}],"con":true,"img":false}]}
{"op":"mcm","clk":"5347979371","pt":1646211745040,"mc":[{"id":"1.195453751","rc":[{"atl":[[270,5.43]],"id":522754}],"con":true,"img":false}]}
{"op":"mcm","clk":"5347979402","pt":1646211745759,"mc":[{"id":"1.195453751","rc":[{"atl":[[190,5.79]],"id":522748}],"con":true,"img":false}]}
{"op":"mcm","clk":"5347979438","pt":1646211746735,"mc":[{"id":"1.195453751","rc":[{"atl":[[210,0]],"id":522748}],"con":true,"img":false}]}
{"op":"mcm","clk":"5347979454","pt":1646211747048,"mc":[{"id":"1.195453751","rc":[{"atl":[[410,2],[200,7.37]],"id":522751}],"con":true,"img":false}]}
{"op":"mcm","clk":"5347979461","pt":1646211747352,"mc":[{"id":"1.195453751","rc":[{"atl":[[400,5.68],[220,0]],"id":522748}],"con":true,"img":false}]}
{"op":"mcm","clk":"5347979490","pt":1646211748168,"mc":[{"id":"1.195453751","rc":[{"atl":[[200,0]],"id":522751}],"con":true,"img":false}]}
{"op":"mcm","clk":"5347979570","pt":1646211750485,"mc":[{"id":"1.195453751","rc":[{"atl":[[40,28.18]],"id":522746}],"con":true,"img":false}]}
{"op":"mcm","clk":"5347979633","pt":1646211752040,"mc":[{"id":"1.195453751","rc":[{"atl":[[270,0],[690,4.15]],"id":522754}],"con":true,"img":false}]}
{"op":"mcm","clk":"5347979725","pt":1646211754370,"mc":[{"id":"1.195453751","rc":[{"atl":[[200,7.47]],"id":522751}],"con":true,"img":false}]}
{"op":"mcm","clk":"5347979853","pt":1646211757367,"mc":[{"id":"1.195453751","rc":[{"atl":[[40,0],[44,41.56]],"id":522746}],"con":true,"img":false}]}
{"op":"mcm","clk":"5347979867","pt":1646211757671,"mc":[{"id":"1.195453751","rc":[{"atl":[[65,11.9],[70,0]],"id":522747}],"con":true,"img":false}]}
{"op":"mcm","clk":"5347979875","pt":1646211757883,"mc":[{"id":"1.195453751","rc":[{"atl":[[690,2]],"id":522754},{"atb":[[32,4.95],[26,0],[27,9.9],[30,5.46]],"id":522755},{"atb":[[20,0],[25,0]],"id":522747},{"atb":[[6.8,2.72]],"id":522752},{"atl":[[150,9.9],[100,1.6],[110,4.95]],"id":3805772}],"con":true,"img":false}]}
{"op":"mcm","clk":"5347979880","pt":1646211757987,"mc":[{"id":"1.195453751","rc":[{"atb":[[8,0],[9,8.22],[8.2,9.9],[8.8,12.66]],"id":3805740}],"con":true,"img":false}]}
{"op":"mcm","clk":"5347979884","pt":1646211758086,"mc":[{"id":"1.195453751","rc":[{"atl":[[310,2],[700,0]],"id":3805772}],"con":true,"img":false}]}
{"op":"mcm","clk":"5347979890","pt":1646211758219,"mc":[{"id":"1.195453751","rc":[{"atl":[[44,12.23]],"id":522746}],"con":true,"img":false}]}
{"op":"mcm","clk":"5347979895","pt":1646211758291,"mc":[{"id":"1.195453751","rc":[{"atb":[[34,4.8]],"id":522755},{"atb":[[15.5,35.63]],"id":522747},{"atl":[[150,19.95],[750,0]],"id":3805772}],"con":true,"img":false}]}
{"op":"mcm","clk":"5347979901","pt":1646211758395,"mc":[{"id":"1.195453751","rc":[{"atb":[[17.5,0],[27,33.26]],"id":522755}],"con":true,"img":false}]}
{"op":"mcm","clk":"5347979915","pt":1646211758603,"mc":[{"id":"1.195453751","rc":[{"atb":[[19.5,3.26],[24,2.72]],"id":522747},{"atb":[[6.6,33.26]],"id":522752}],"con":true,"img":false}]}
{"op":"mcm","clk":"5347979925","pt":1646211758762,"mc":[{"id":"1.195453751","rc":[{"atb":[[3.7,0],[3.5,0]],"id":3805784},{"atl":[[14,4.95]],"id":3805740}],"con":true,"img":false}]}
{"op":"mcm","clk":"5347979931","pt":1646211758912,"mc":[{"id":"1.195453751","rc":[{"atb":[[3.2,9.9],[3.4,153.12]],"id":3805784},{"atl":[[250,0]],"id":522754},{"atl":[[65,2],[46,0],[48,0],[50,0],[60,4.95]],"id":522747},{"atl":[[260,4.95],[190,0],[400,2]],"id":522748},{"atl":[[70,9.9],[44,0],[50,4.95],[55,0]],"id":522750},{"atl":[[180,0],[230,4.95]],"id":522751},{"atb":[[75,4.95],[42,0],[50,3.23],[55,9.9]],"id":3805731},{"atl":[[16,0],[16.5,9.9],[14,0],[14.5,4.95]],"id":3805740}],"con":true,"img":false}]}
{"op":"mcm","clk":"5347979938","pt":1646211758971,"mc":[{"id":"1.195453751","rc":[{"atl":[[280,4.95]],"id":522754}],"con":true,"img":false}]}
{"op":"mcm","clk":"5347979945","pt":1646211759077,"mc":[{"id":"1.195453751","rc":[{"atb":[[30,0]],"id":522755},{"atb":[[15.5,9.9]],"id":522747}],"con":true,"img":false}]}
{"op":"mcm","clk":"5347979951","pt":1646211759178,"mc":[{"id":"1.195453751","rc":[{"atl":[[690,0],[720,2]],"id":522754}],"con":true,"img":false}]}
{"op":"mcm","clk":"5347979955","pt":1646211759280,"mc":[{"id":"1.195453751","rc":[{"atb":[[3.4,46.62],[2.94,55.94]],"id":3805784}],"con":true,"img":false}]}
{"op":"mcm","clk":"5347979961","pt":1646211759382,"mc":[{"id":"1.195453751","rc":[{"atb":[[3.1,50.34]],"id":3805784}],"con":true,"img":false}]}
{"op":"mcm","clk":"5347979966","pt":1646211759482,"mc":[{"id":"1.195453751","rc":[{"atb":[[3.4,57.62]],"id":3805784},{"atl":[[710,2.12]],"id":522754},{"atl":[[70,9.72]],"id":522747},{"atb":[[50,15.41],[28,3.7]],"id":3805731},{"atl":[[16.5,20.13]],"id":3805740}],"con":true,"img":false}]}
{"op":"mcm","clk":"5347979974","pt":1646211759590,"mc":[{"id":"1.195453751","rc":[{"atl":[[280,5.52]],"id":522754},{"atb":[[34,0]],"id":522755},{"atl":[[60,4.95]],"id":522755},{"atl":[[70,19.63],[50,4.95],[60,2.68]],"id":522747},{"atl":[[65,2.47]],"id":522750},{"atl":[[190,4.95],[200,8.26]],"id":522751},{"atb":[[75,0],[46,9.9],[55,0],[60,4.95]],"id":3805731}],"con":true,"img":false}]}
{"op":"mcm","clk":"5347979980","pt":1646211759687,"mc":[{"id":"1.195453751","rc":[{"atl":[[1000,0.15]],"id":522748}],"con":true,"img":false}]}
{"op":"mcm","clk":"5347979988","pt":1646211759787,"mc":[{"id":"1.195453751","rc":[{"atl":[[290,4.95]],"id":522754}],"con":true,"img":false}]}
{"op":"mcm","clk":"5347979992","pt":1646211759889,"mc":[{"id":"1.195453751","rc":[{"atl":[[280,0.56]],"id":522754},{"atl":[[400,0],[830,2]],"id":522748}],"con":true,"img":false}]}
{"op":"mcm","clk":"5347980000","pt":1646211759993,"mc":[{"id":"1.195453751","rc":[{"atl":[[70,22.12],[80,2]],"id":522750},{"atb":[[60,7.64]],"id":3805731}],"con":true,"img":false}]}
{"op":"mcm","clk":"5347980012","pt":1646211760302,"mc":[{"id":"1.195453751","rc":[{"atb":[[27,39.35]],"id":522755},{"atb":[[50,3.23]],"id":3805731}],"con":true,"img":false}]}
{"op":"mcm","clk":"5347980021","pt":1646211760465,"mc":[{"id":"1.195453751","rc":[{"atl":[[290,0]],"id":522754}],"con":true,"img":false}]}
{"op":"mcm","clk":"5347980029","pt":1646211760668,"mc":[{"id":"1.195453751","rc":[{"atl":[[280,5.52]],"id":522754}],"con":true,"img":false}]}
{"op":"mcm","clk":"5347980032","pt":1646211760772,"mc":[{"id":"1.195453751","rc":[{"atl":[[60,7.64]],"id":522755},{"atb":[[50,0]],"id":3805731}],"con":true,"img":false}]}
{"op":"mcm","clk":"5347980050","pt":1646211761182,"mc":[{"id":"1.195453751","rc":[{"atl":[[200,0.79],[230,11.53]],"id":522751}],"con":true,"img":false}]}
{"op":"mcm","clk":"5347980054","pt":1646211761285,"mc":[{"id":"1.195453751","rc":[{"atl":[[190,0],[200,5.74],[230,6.58]],"id":522751}],"con":true,"img":false}]}
{"op":"mcm","clk":"5347980059","pt":1646211761387,"mc":[{"id":"1.195453751","rc":[{"atl":[[1000,1.66]],"id":522748}],"con":true,"img":false}]}
{"op":"mcm","clk":"5347980073","pt":1646211761692,"mc":[{"id":"1.195453751","rc":[{"atl":[[410,0],[440,2]],"id":522751}],"con":true,"img":false}]}
{"op":"mcm","clk":"5347980106","pt":1646211762583,"mc":[{"id":"1.195453751","rc":[{"atl":[[280,0],[290,4.95]],"id":522754}],"con":true,"img":false}]}
{"op":"mcm","clk":"5347980121","pt":1646211762887,"mc":[{"id":"1.195453751","rc":[{"atl":[[65,0],[70,21.63]],"id":522747}],"con":true,"img":false}]}
{"op":"mcm","clk":"5347980143","pt":1646211763492,"mc":[{"id":"1.195453751","rc":[{"atl":[[290,5.5]],"id":522754}],"con":true,"img":false}]}
{"op":"mcm","clk":"5347980187","pt":1646211764584,"mc":[{"id":"1.195453751","rc":[{"atl":[[40,28.18]],"id":522746}],"con":true,"img":false}]}
{"op":"mcm","clk":"5347980215","pt":1646211765303,"mc":[{"id":"1.195453751","rc":[{"atb":[[17,26.07]],"id":522755}],"con":true,"img":false}]}
{"op":"mcm","clk":"5347980224","pt":1646211765406,"mc":[{"id":"1.195453751","rc":[{"atb":[[27,16]],"id":522755}],"con":true,"img":false}]}
{"op":"mcm","clk":"5347980259","pt":1646211766496,"mc":[{"id":"1.195453751","rc":[{"atl":[[710,0],[720,4.11]],"id":522754}],"con":true,"img":false}]}
{"op":"mcm","clk":"5347980331","pt":1646211768097,"mc":[{"id":"1.195453751","rc":[{"atl":[[440,5.48],[230,0]],"id":522751}],"con":true,"img":false}]}
{"op":"mcm","clk":"5347980458","pt":1646211771293,"mc":[{"id":"1.195453751","rc":[{"atl":[[40,0],[44,41.56]],"id":522746}],"con":true,"img":false}]}
{"op":"mcm","clk":"5347980505","pt":1646211772118,"mc":[{"id":"1.195453751","rc":[{"atb":[[32,10.06]],"id":522755}],"con":true,"img":false}]}
{"op":"mcm","clk":"5347980540","pt":1646211773008,"mc":[{"id":"1.195453751","rc":[{"atb":[[3.1,170.48]],"id":3805784},{"atb":[[27,9.9]],"id":522755}],"con":true,"img":false}]}
{"op":"mcm","clk":"5347980543","pt":1646211773107,"mc":[{"id":"1.195453751","rc":[{"atb":[[2.94,3.26]],"id":3805784}],"con":true,"img":false}]}
{"op":"mcm","clk":"5347980547","pt":1646211773208,"mc":[{"id":"1.195453751","rc":[{"atb":[[28,17.59]],"id":3805731}],"con":true,"img":false}]}
{"op":"mcm","clk":"5347980551","pt":1646211773315,"mc":[{"id":"1.195453751","rc":[{"atl":[[310,4.99],[720,2]],"id":522754},{"atl":[[48,3.37]],"id":522750},{"atl":[[14.5,16.69]],"id":3805740}],"con":true,"img":false}]}
{"op":"mcm","clk":"5347980563","pt":1646211773524,"mc":[{"id":"1.195453751","rc":[{"atl":[[50,8.19]],"id":522747},{"atl":[[250,0.63]],"id":522748}],"con":true,"img":false}]}
{"op":"mcm","clk":"5347980588","pt":1646211773893,"mc":[{"id":"1.195453751","rc":[{"atl":[[65,12.34],[70,9.9]],"id":522750}],"con":true,"img":false}]}
{"op":"mcm","clk":"5347980603","pt":1646211774103,"mc":[{"id":"1.195453751","rc":[{"atl":[[65,9.86]],"id":522750},{"atl":[[16.5,9.9]],"id":3805740}],"con":true,"img":false}]}
{"op":"mcm","clk":"5347980613","pt":1646211774310,"mc":[{"id":"1.195453751","rc":[{"atl":[[60,0]],"id":522747},{"atl":[[1000,1.5]],"id":522748}],"con":true,"img":false}]}
{"op":"mcm","clk":"5347980642","pt":1646211774950,"mc":[{"id":"1.195453751","rc":[{"atl":[[70,11.9],[60,21.99]],"id":522747},{"atl":[[440,2],[220,7.06]],"id":522751}],"con":true,"img":false}]}
{"op":"mcm","clk":"5347980647","pt":1646211775024,"mc":[{"id":"1.195453751","rc":[{"atl":[[830,3.86],[1000,0]],"id":522748}],"con":true,"img":false}]}
{"op":"mcm","clk":"5347980686","pt":1646211775598,"mc":[{"id":"1.195453751","rc":[{"atl":[[220,0]],"id":522751}],"con":true,"img":false}]}
{"op":"mcm","clk":"5347980789","pt":1646211777611,"mc":[{"id":"1.195453751","rc":[{"atb":[[3.6,4.95],[3.2,0]],"id":3805784},{"atl":[[280,4.95],[290,0.55]],"id":522754},{"atb":[[12,0],[12.5,4.95]],"id":522746},{"atb":[[75,0],[80,9.9],[95,1.68],[100,4.95]],"id":522748},{"atl":[[9.6,18.43],[9.2,4.95],[10,9.9],[11,0]],"id":522749},{"atl":[[190,4.95],[200,0.79]],"id":522751},{"atb":[[44,9.9],[46,0],[55,4.95],[60,0]],"id":3805731},{"atb":[[38,12.83],[40,9.9],[46,0],[48,8.32]],"id":3805772}],"con":true,"img":false}]}
{"op":"mcm","clk":"5347980799","pt":1646211777816,"mc":[{"id":"1.195453751","rc":[{"atb":[[3.1,122.86],[3.4,99.29]],"id":3805784}],"con":true,"img":false}]}
{"op":"mcm","clk":"5347980806","pt":1646211778019,"mc":[{"id":"1.195453751","rc":[{"atb":[[3.6,57.62],[3.2,45.45],[3.4,57.62]],"id":3805784},{"atb":[[80,23],[48,2.72],[100,6.55]],"id":522748},{"atl":[[9.2,24.29],[10,31.99],[13,8.33]],"id":522749},{"atl":[[190,5.79]],"id":522751}],"con":true,"img":false}]}
{"op":"mcm","clk":"5347980809","pt":1646211778121,"mc":[{"id":"1.195453751","rc":[{"atl":[[280,5.52]],"id":522754}],"con":true,"img":false}]}
{"op":"mcm","clk":"5347980816","pt":1646211778225,"mc":[{"id":"1.195453751","rc":[{"atl":[[40,28.18],[44,12.23]],"id":522746}],"con":true,"img":false}]}
{"op":"mcm","clk":"5347980823","pt":1646211778328,"mc":[{"id":"1.195453751","rc":[{"atl":[[260,0],[210,4.95]],"id":522748},{"atl":[[70,0],[46,4.95],[50,0],[60,9.9]],"id":522750},{"atb":[[75,14.71],[80,9.9],[95,0],[100,6.55]],"id":522751},{"atb":[[55,7.89]],"id":3805731}],"con":true,"img":false}]}
{"op":"mcm","clk":"5347980836","pt":1646211778485,"mc":[{"id":"1.195453751","rc":[{"atl":[[830,1.86],[430,2]],"id":522748}],"con":true,"img":false}]}
{"op":"mcm","clk":"5347980856","pt":1646211778946,"mc":[{"id":"1.195453751","rc":[{"atb":[[3.4,4.95]],"id":3805784},{"atl":[[290,0]],"id":522754},{"atb":[[95,0]],"id":522748},{"atl":[[9.6,0]],"id":522749},{"atl":[[200,0]],"id":522751}],"con":true,"img":false}]}
{"op":"mcm","clk":"5347980863","pt":1646211779105,"mc":[{"id":"1.195453751","rc":[{"atl":[[40,0]],"id":522746}],"con":true,"img":false}]}
{"op":"mcm","clk":"5347980912","pt":1646211780089,"mc":[{"id":"1.195453751","rc":[{"atl":[[310,0],[720,4.16]],"id":522754}],"con":true,"img":false}]}
{"op":"mcm","clk":"5347980938","pt":1646211780505,"mc":[{"id":"1.195453751","rc":[{"atl":[[65,9.9],[70,2],[48,4.95],[50,3.23]],"id":522747},{"atl":[[220,4.95]],"id":522748},{"atl":[[190,0]],"id":522751}],"con":true,"img":false}]}
{"op":"mcm","clk":"5347980944","pt":1646211780604,"mc":[{"id":"1.195453751","rc":[{"atl":[[210,0]],"id":522748}],"con":true,"img":false}]}
{"op":"mcm","clk":"5347980953","pt":1646211780806,"mc":[{"id":"1.195453751","rc":[{"atl":[[200,4.95]],"id":522751}],"con":true,"img":false}]}
{"op":"mcm","clk":"5347980974","pt":1646211781321,"mc":[{"id":"1.195453751","rc":[{"atl":[[1000,0.15]],"id":522751}],"con":true,"img":false}]}
{"op":"mcm","clk":"5347980983","pt":1646211781525,"mc":[{"id":"1.195453751","rc":[{"atl":[[840,2],[440,0]],"id":522751}],"con":true,"img":false}]}
{"op":"mcm","clk":"5347980998","pt":1646211781793,"mc":[{"id":"1.195453751","rc":[{"atl":[[220,7.15]],"id":522751}],"con":true,"img":false}]}
{"op":"mcm","clk":"5347981030","pt":1646211782422,"mc":[{"id":"1.195453751","rc":[{"atb":[[16.5,6.45]],"id":522754},{"atl":[[44,9.9],[50,2.04]],"id":522746},{"atb":[[6.8,63.17],[5.9,0]],"id":522745}],"con":true,"img":false}]}
{"op":"mcm","clk":"5347981037","pt":1646211782523,"mc":[{"id":"1.195453751","rc":[{"atb":[[48,0]],"id":522754}],"con":true,"img":false}]}
{"op":"mcm","clk":"5347981132","pt":1646211784527,"mc":[{"id":"1.195453751","rc":[{"atb":[[80,9.9],[48,14.12]],"id":522748}],"con":true,"img":false}]}
{"op":"mcm","clk":"5347981137","pt":1646211784637,"mc":[{"id":"1.195453751","rc":[{"atl":[[10,9.9],[13,49.94]],"id":522749}],"con":true,"img":false}]}
{"op":"mcm","clk":"5347981149","pt":1646211784847,"mc":[{"id":"1.195453751","rc":[{"atl":[[50,20.98]],"id":522746}],"con":true,"img":false}]}
{"op":"mcm","clk":"5347981191","pt":1646211785524,"mc":[{"id":"1.195453751","rc":[{"atl":[[320,4.95]],"id":522741}],"con":true,"img":false}]}
{"op":"mcm","clk":"5347981214","pt":1646211786041,"mc":[{"id":"1.195453751","rc":[{"atl":[[310,0.51]],"id":522741}],"con":true,"img":false}]}
{"op":"mcm","clk":"5347981222","pt":1646211786230,"mc":[{"id":"1.195453751","rc":[{"atb":[[32,9.9],[40,4.95]],"id":522745}],"con":true,"img":false}]}
{"op":"mcm","clk":"5347981225","pt":1646211786332,"mc":[{"id":"1.195453751","rc":[{"atb":[[38,4.28],[30,0]],"id":522745}],"con":true,"img":false}]}
{"op":"mcm","clk":"5347981242","pt":1646211786541,"mc":[{"id":"1.195453751","rc":[{"atb":[[3.2,158.32],[3.1,2.72]],"id":3805784},{"atl":[[1000,1.73]],"id":522741}],"con":true,"img":false}]}
{"op":"mcm","clk":"5347981248","pt":1646211786646,"mc":[{"id":"1.195453751","rc":[{"atb":[[32,26.6],[40,9.01],[15.5,2.72]],"id":522745}],"con":true,"img":false}]}
{"op":"mcm","clk":"5347981254","pt":1646211786712,"mc":[{"id":"1.195453751","rc":[{"atl":[[1000,1.58]],"id":522741}],"con":true,"img":false}]}
{"op":"mcm","clk":"5347981261","pt":1646211786804,"mc":[{"id":"1.195453751","rc":[{"atl":[[300,5.28],[720,2]],"id":522754},{"atl":[[44,3.68]],"id":522750}],"con":true,"img":false}]}
{"op":"mcm","clk":"5347981266","pt":1646211786931,"mc":[{"id":"1.195453751","rc":[{"atl":[[220,5.67]],"id":522748}],"con":true,"img":false}]}
{"op":"mcm","clk":"5347981272","pt":1646211787026,"mc":[{"id":"1.195453751","rc":[{"atl":[[48,8.32]],"id":522747}],"con":true,"img":false}]}
{"op":"mcm","clk":"5347981293","pt":1646211787337,"mc":[{"id":"1.195453751","rc":[{"atl":[[65,0],[48,13.86]],"id":522750}],"con":true,"img":false}]}
{"op":"mcm","clk":"5347981298","pt":1646211787433,"mc":[{"id":"1.195453751","rc":[{"atb":[[38,0]],"id":522745}],"con":true,"img":false}]}
{"op":"mcm","clk":"5347981312","pt":1646211787641,"mc":[{"id":"1.195453751","rc":[{"atl":[[48,10.49]],"id":522750}],"con":true,"img":false}]}
{"op":"mcm","clk":"5347981320","pt":1646211787747,"mc":[{"id":"1.195453751","rc":[{"atl":[[250,0]],"id":522748}],"con":true,"img":false}]}
{"op":"mcm","clk":"5347981328","pt":1646211787914,"mc":[{"id":"1.195453751","rc":[{"atl":[[50,0]],"id":522747}],"con":true,"img":false}]}
{"op":"mcm","clk":"5347981351","pt":1646211788326,"mc":[{"id":"1.195453751","rc":[{"atl":[[840,3.88],[220,0]],"id":522751}],"con":true,"img":false}]}
{"op":"mcm","clk":"5347981356","pt":1646211788428,"mc":[{"id":"1.195453751","rc":[{"atl":[[65,33.28],[60,0]],"id":522747}],"con":true,"img":false}]}
{"op":"mcm","clk":"5347981505","pt":1646211791323,"mc":[{"id":"1.195453751","rc":[{"atl":[[200,5.74]],"id":522751}],"con":true,"img":false}]}
{"op":"mcm","clk":"5347981572","pt":1646211792255,"mc":[{"id":"1.195453751","rc":[{"atl":[[1000,0]],"id":522751}],"con":true,"img":false}]}
{"op":"mcm","clk":"5347981641","pt":1646211793233,"mc":[{"id":"1.195453751","rc":[{"atl":[[300,0],[720,4.22]],"id":522754},{"atb":[[32,9.9],[15.5,16.1]],"id":522745}],"con":true,"img":false}]}
{"op":"mcm","clk":"5347981724","pt":1646211794875,"mc":[{"id":"1.195453751","rc":[{"atl":[[1000,1.6]],"id":522751}],"con":true,"img":false}]}
{"op":"mcm","clk":"5347981729","pt":1646211794931,"mc":[{"id":"1.195453751","rc":[{"atl":[[840,2]],"id":522751}],"con":true,"img":false}]}
{"op":"mcm","clk":"5347981739","pt":1646211795242,"mc":[{"id":"1.195453751","rc":[{"atl":[[65,9.9],[70,17.85]],"id":522747}],"con":true,"img":false}]}
{"op":"mcm","clk":"5347982003","pt":1646211800061,"mc":[{"id":"1.195453751","rc":[{"atl":[[300,5.41]],"id":522754}],"con":true,"img":false}]}
{"op":"mcm","clk":"5347982008","pt":1646211800165,"mc":[{"id":"1.195453751","rc":[{"atl":[[720,2]],"id":522754}],"con":true,"img":false}]}
{"op":"mcm","clk":"5347982047","pt":1646211800839,"mc":[{"id":"1.195453751","rc":[{"atl":[[300,0]],"id":522754}],"con":true,"img":false}]}
{"op":"mcm","clk":"5347982236","pt":1646211804444,"mc":[{"id":"1.195453751","rc":[{"atl":[[720,0],[820,2]],"id":522754},{"atl":[[430,0],[510,2]],"id":522748},{"atl":[[950,2]],"id":522751}],"con":true,"img":false}]}
{"op":"mcm","clk":"5347982241","pt":1646211804546,"mc":[{"id":"1.195453751","rc":[{"atl":[[840,0]],"id":522751}],"con":true,"img":false}]}
{"op":"mcm","clk":"5347982247","pt":1646211804755,"mc":[{"id":"1.195453751","rc":[{"atl":[[6.2,35.44],[7,9.9]],"id":3805784},{"atb":[[85,0],[90,9.9],[110,1.45],[120,4.95]],"id":522754},{"atl":[[65,4.95],[80,0],[85,9.9],[60,2.68]],"id":522755},{"atb":[[17.5,0],[14,39.06],[15,0]],"id":522746},{"atl":[[200,0.79],[210,4.95]],"id":522751},{"atl":[[260,4.95],[230,0.69]],"id":3805731},{"atb":[[6.8,30.06]],"id":522752},{"atl":[[20,12.17],[21,0],[24,9.9],[25,29.45]],"id":3805762},{"atb":[[9,0],[10,0],[8.4,4.95]],"id":522753},{"atb":[[150,1.06],[110,0]],"id":522741},{"atl":[[320,0]],"id":522741},{"atb":[[130,1.23],[140,4.95],[95,0],[100,9.9]],"id":522742},{"atl":[[150,10.04],[160,9.9],[110,0],[120,4.95]],"id":3805772},{"atl":[[130,4.95],[120,1.32]],"id":522745}],"con":true,"img":false}]}
{"op":"mcm","clk":"5347982251","pt":1646211804865,"mc":[{"id":"1.195453751","rc":[{"atl":[[7.2,99.13],[6.4,0]],"id":3805784},{"atb":[[7.8,4.95]],"id":522753},{"atl":[[12.5,18.74],[14.5,9.9]],"id":522753},{"atb":[[160,4.95],[120,9.9]],"id":522741}],"con":true,"img":false}]}
{"op":"mcm","clk":"5347982257","pt":1646211804960,"mc":[{"id":"1.195453751","rc":[{"atl":[[550,2],[950,1.71],[1000,0]],"id":522751},{"atl":[[690,2],[980,0]],"id":3805731},{"atb":[[7.6,0],[8.4,0]],"id":522753},{"atl":[[13,0],[15,22.08]],"id":522753},{"atl":[[730,0],[360,2]],"id":522745}],"con":true,"img":false}]}
{"op":"mcm","clk":"5347982268","pt":1646211805166,"mc":[{"id":"1.195453751","rc":[{"atl":[[7,77.31]],"id":3805784},{"atb":[[65,0],[90,24.62]],"id":522754},{"atl":[[210,2]],"id":522755},{"atl":[[980,1.66]],"id":3805731},{"atb":[[90,0],[100,19.09]],"id":522742},{"atl":[[730,2.23]],"id":522745}],"con":true,"img":false}]}
{"op":"mcm","clk":"5347982274","pt":1646211805270,"mc":[{"id":"1.195453751","rc":[{"atl":[[7.2,0]],"id":3805784},{"atb":[[130,1.23]],"id":522754},{"atl":[[85,29.21]],"id":522755},{"atb":[[14.5,11.74]],"id":522746},{"atl":[[990,0]],"id":3805731},{"atb":[[6.2,60.84]],"id":522753},{"atl":[[14.5,31.99],[15,0]],"id":522753},{"atb":[[32,12.26],[42,2.72],[170,0.93]],"id":522741},{"atl":[[1000,0]],"id":522741},{"atb":[[150,1.06]],"id":522742},{"atl":[[800,0]],"id":522745}],"con":true,"img":false}]}
{"op":"mcm","clk":"5347982284","pt":1646211805474,"mc":[{"id":"1.195453751","rc":[{"atb":[[16.5,3.26],[19,2.72]],"id":522746},{"atb":[[6.6,4.95]],"id":522752},{"atb":[[9.6,2.72],[8.6,3.26],[7.8,7.36]],"id":522753}],"con":true,"img":false}]}
{"op":"mcm","clk":"5347982292","pt":1646211805679,"mc":[{"id":"1.195453751","rc":[{"atb":[[7,9.9]],"id":522753}],"con":true,"img":false}]}
{"op":"mcm","clk":"5347982306","pt":1646211806071,"mc":[{"id":"1.195453751","rc":[{"atl":[[7,9.9]],"id":3805784},{"atb":[[110,0]],"id":522754},{"atb":[[32,7.56],[150,0]],"id":522741},{"atb":[[130,0]],"id":522742}],"con":true,"img":false}]}
{"op":"mcm","clk":"5347982418","pt":1646211807858,"mc":[{"id":"1.195453751","rc":[{"atl":[[550,4.98],[950,0]],"id":522751}],"con":true,"img":false}]}
{"op":"mcm","clk":"5347982497","pt":1646211809565,"mc":[{"id":"1.195453751","rc":[{"atl":[[830,3.86],[510,0]],"id":522748}],"con":true,"img":false}]}
{"op":"mcm","clk":"5347982533","pt":1646211810080,"mc":[{"id":"1.195453751","rc":[{"atl":[[830,2],[240,6.88]],"id":522748}],"con":true,"img":false}]}
{"op":"mcm","clk":"5347982539","pt":1646211810184,"mc":[{"id":"1.195453751","rc":[{"atl":[[830,0],[510,2]],"id":522748}],"con":true,"img":false}]}
{"op":"mcm","clk":"5347982579","pt":1646211810859,"mc":[{"id":"1.195453751","rc":[{"atl":[[240,0]],"id":522748}],"con":true,"img":false}]}
{"op":"mcm","clk":"5347982614","pt":1646211811472,"mc":[{"id":"1.195453751","rc":[{"atl":[[300,5.52]],"id":522754}],"con":true,"img":false}]}
{"op":"mcm","clk":"5347982618","pt":1646211811574,"mc":[{"id":"1.195453751","rc":[{"atl":[[24,21.75],[14.5,9.9]],"id":522753}],"con":true,"img":false}]}
{"op":"mcm","clk":"5347982650","pt":1646211812297,"mc":[{"id":"1.195453751","rc":[{"atb":[[19,30.78]],"id":522747}],"con":true,"img":false}]}
{"op":"mcm","clk":"5347982697","pt":1646211813073,"mc":[{"id":"1.195453751","rc":[{"atb":[[32,5.11],[34,4.95],[27,0],[28,9.9]],"id":522755}],"con":true,"img":false}]}
{"op":"mcm","clk":"5347982737","pt":1646211813594,"mc":[{"id":"1.195453751","rc":[{"atb":[[17,2.72],[36,4.52],[28,24.86]],"id":522755}],"con":true,"img":false}]}
{"op":"mcm","clk":"5347982763","pt":1646211813959,"mc":[{"id":"1.195453751","rc":[{"atb":[[44,0],[46,9.9],[55,2.93],[60,4.95]],"id":3805731}],"con":true,"img":false}]}
{"op":"mcm","clk":"5347982788","pt":1646211814370,"mc":[{"id":"1.195453751","rc":[{"atb":[[32,0]],"id":522755},{"atb":[[28,3.7],[60,7.64]],"id":3805731}],"con":true,"img":false}]}
{"op":"mcm","clk":"5347982792","pt":1646211814471,"mc":[{"id":"1.195453751","rc":[{"atb":[[19.5,0],[24,0]],"id":522747},{"atb":[[46,21.63]],"id":3805731}],"con":true,"img":false}]}
{"op":"mcm","clk":"5347982828","pt":1646211815088,"mc":[{"id":"1.195453751","rc":[{"atb":[[19,39.58]],"id":522747},{"atb":[[55,0]],"id":3805731}],"con":true,"img":false}]}
{"op":"mcm","clk":"5347982834","pt":1646211815189,"mc":[{"id":"1.195453751","rc":[{"atb":[[25,2.72]],"id":522747}],"con":true,"img":false}]}
{"op":"mcm","clk":"5347982846","pt":1646211815396,"mc":[{"id":"1.195453751","rc":[{"atb":[[20,3.26]],"id":522747}],"con":true,"img":false}]}
{"op":"mcm","clk":"5347982860","pt":1646211815761,"mc":[{"id":"1.195453751","rc":[{"atb":[[17.5,4.95]],"id":522747}],"con":true,"img":false}]}
{"op":"mcm","clk":"5347982966","pt":1646211817571,"mc":[{"id":"1.195453751","rc":[{"atb":[[14,10.24],[14.5,40.56]],"id":522746}],"con":true,"img":false}]}
{"op":"mcm","clk":"5347982978","pt":1646211817776,"mc":[{"id":"1.195453751","rc":[{"atl":[[300,0],[820,4.03]],"id":522754}],"con":true,"img":false}]}
{"op":"mcm","clk":"5347982980","pt":1646211817879,"mc":[{"id":"1.195453751","rc":[{"atl":[[220,0],[230,4.95]],"id":522748}],"con":true,"img":false}]}
{"op":"mcm","clk":"5347982986","pt":1646211817981,"mc":[{"id":"1.195453751","rc":[{"atb":[[3.1,0],[2.94,0]],"id":3805784},{"atl":[[8,88.2]],"id":3805784},{"atb":[[16.5,0],[19,0]],"id":522746},{"atl":[[690,4.41],[980,0]],"id":3805731},{"atb":[[9,4.95],[10,0]],"id":3805740},{"atl":[[360,6.64],[730,0]],"id":522745}],"con":true,"img":false}]}
{"op":"mcm","clk":"5347982990","pt":1646211818082,"mc":[{"id":"1.195453751","rc":[{"atb":[[6.2,25.61],[7.8,33.03]],"id":522753},{"atb":[[120,18.66]],"id":522741}],"con":true,"img":false}]}
{"op":"mcm","clk":"5347983006","pt":1646211818393,"mc":[{"id":"1.195453751","rc":[{"atb":[[9,24.76],[8.2,43.46],[8.8,0]],"id":3805740}],"con":true,"img":false}]}
{"op":"mcm","clk":"5347983021","pt":1646211818699,"mc":[{"id":"1.195453751","rc":[{"atb":[[3.15,2.72],[2.96,3.26]],"id":3805784},{"atb":[[16,3.26],[18.5,2.72]],"id":522746},{"atl":[[500,0.31]],"id":522748},{"atb":[[9.8,2.72],[8.8,3.26]],"id":3805740}],"con":true,"img":false}]}
{"op":"mcm","clk":"5347983109","pt":1646211820503,"mc":[{"id":"1.195453751","rc":[{"atb":[[19,16.2]],"id":522747}],"con":true,"img":false}]}
{"op":"mcm","clk":"5347983114","pt":1646211820606,"mc":[{"id":"1.195453751","rc":[{"atl":[[820,2]],"id":522754},{"atb":[[19,7.4]],"id":522747},{"atb":[[16.5,12.58],[17,4.95],[14.5,0]],"id":522750},{"atl":[[16.5,0],[16,9.9],[14,4.95],[14.5,11.74]],"id":3805740}],"con":true,"img":false}]}
{"op":"mcm","clk":"5347983118","pt":1646211820710,"mc":[{"id":"1.195453751","rc":[{"atb":[[46,9.9],[28,17.62]],"id":3805731}],"con":true,"img":false}]}
{"op":"mcm","clk":"5347983124","pt":1646211820815,"mc":[{"id":"1.195453751","rc":[{"atb":[[42,0],[55,0]],"id":522754},{"atb":[[17,0],[14.5,0]],"id":522755},{"atb":[[38,0],[29,0]],"id":522751},{"atb":[[17,0],[19.5,0]],"id":3805772},{"atb":[[85,0],[60,0]],"id":7607472}],"con":true,"img":false}]}
{"op":"mcm","clk":"5347983134","pt":1646211820970,"mc":[{"id":"1.195453751","rc":[{"atb":[[25,0]],"id":522747}],"con":true,"img":false}]}
{"op":"mcm","clk":"5347983138","pt":1646211821073,"mc":[{"id":"1.195453751","rc":[{"atb":[[20,0]],"id":522747},{"atb":[[16.5,0],[17,17.79]],"id":522750},{"atl":[[16,31.99],[23,4.55],[13.5,12.68]],"id":3805740}],"con":true,"img":false}]}
{"op":"mcm","clk":"5347983151","pt":1646211821281,"mc":[{"id":"1.195453751","rc":[{"atb":[[3.6,0],[3.35,9.9],[3.4,0],[3.55,4.95]],"id":3805784},{"atl":[[280,0],[340,4.95]],"id":522754},{"atl":[[290,4.95],[230,0]],"id":522748},{"atl":[[260,4.95],[200,0],[210,0]],"id":522751}],"con":true,"img":false}]}
{"op":"mcm","clk":"5347983159","pt":1646211821383,"mc":[{"id":"1.195453751","rc":[{"atb":[[3.2,112.87],[3.35,19.81]],"id":3805784},{"atl":[[720,2],[820,0]],"id":522754},{"atl":[[34,4.95],[36,4.52],[42,9.9],[44,0]],"id":522746}],"con":true,"img":false}]}
{"op":"mcm","clk":"5347983162","pt":1646211821487,"mc":[{"id":"1.195453751","rc":[{"atb":[[44,3.26],[60,4.98]],"id":522754},{"atb":[[18,2.72],[15.5,3.26]],"id":522755},{"atl":[[44,2.33],[50,18.94]],"id":522746},{"atb":[[40,5.28],[30,3.26]],"id":522751},{"atb":[[18,3.26],[21,2.72]],"id":3805772},{"atb":[[65,3.26],[90,2.72]],"id":7607472}],"con":true,"img":false}]}
{"op":"mcm","clk":"5347983168","pt":1646211821697,"mc":[{"id":"1.195453751","rc":[{"atl":[[70,4.95],[90,9.9],[60,0]],"id":522755},{"atb":[[24,2.72]],"id":522747},{"atl":[[550,2],[280,6.02]],"id":522751},{"atl":[[310,0]],"id":522741}],"con":true,"img":false}]}
{"op":"mcm","clk":"5347983172","pt":1646211821796,"mc":[{"id":"1.195453751","rc":[{"atl":[[65,0],[85,19.3]],"id":522755},{"atl":[[42,23.99],[50,0]],"id":522746},{"atb":[[17.5,14.56],[19.5,3.26]],"id":522747},{"atl":[[14.5,0]],"id":3805740}],"con":true,"img":false}]}
{"op":"mcm","clk":"5347983181","pt":1646211821903,"mc":[{"id":"1.195453751","rc":[{"atl":[[34,9.76]],"id":522746}],"con":true,"img":false}]}
{"op":"mcm","clk":"5347983184","pt":1646211822011,"mc":[{"id":"1.195453751","rc":[{"atb":[[3.35,31.99]],"id":3805784},{"atb":[[16.5,0],[29,3.57]],"id":522754},{"atl":[[280,4.95],[340,0],[710,0.22]],"id":522754},{"atb":[[11.5,0],[14.5,7.41]],"id":522755},{"atb":[[7.4,15.62],[8.8,0]],"id":522747},{"atl":[[70,15.85],[75,2]],"id":522747},{"atb":[[32,0],[44,2.33]],"id":522748},{"atb":[[4,0],[3.6,38.46]],"id":522749},{"atl":[[260,0],[540,0.29]],"id":522751},{"atb":[[11,10],[28,13.92]],"id":3805731},{"atl":[[34,3.03],[24,17.4]],"id":522753},{"atb":[[14.5,0],[30,3.45]],"id":522741},{"atb":[[19.5,0],[40,2.56]],"id":522742},{"atb":[[36,2.86],[21,0]],"id":522743},{"atb":[[5.5,0],[4.9,25.64]],"id":3805740},{"atb":[[6.4,49.33],[12.5,8.7]],"id":3805772},{"atb":[[40,0],[60,2]],"id":7607472},{"atb":[[8.2,13.89],[6.8,45.93]],"id":522745}],"con":true,"img":false}]}
{"op":"mcm","clk":"5347983191","pt":1646211822108,"mc":[{"id":"1.195453751","rc":[{"atb":[[2.06,94.34]],"id":3805784}],"con":true,"img":false}]}
{"op":"mcm","clk":"5347983195","pt":1646211822212,"mc":[{"id":"1.195453751","rc":[{"atl":[[85,0],[90,28.67]],"id":522755},{"atb":[[14.5,0]],"id":522746},{"atb":[[17.5,9.6],[17,4.95],[15.5,0]],"id":522747},{"atb":[[5.6,14.71],[6.4,0],[5.2,0],[5.7,0]],"id":522749},{"atl":[[20,7.22],[21,4.95],[24,0],[25,39.36]],"id":3805762},{"atb":[[8,4.95],[7.2,9.9],[7.8,28.07],[7,0]],"id":522753},{"atl":[[340,4.95]],"id":522741}],"con":true,"img":false}]}
{"op":"mcm","clk":"5347983207","pt":1646211822421,"mc":[{"id":"1.195453751","rc":[{"atl":[[70,7.25]],"id":522755},{"atl":[[1000,0.15]],"id":522741}],"con":true,"img":false}]}
{"op":"mcm","clk":"5347983221","pt":1646211822629,"mc":[{"id":"1.195453751","rc":[{"atl":[[36,0]],"id":522746},{"atb":[[5.6,32.16],[3.75,176.96]],"id":522749}],"con":true,"img":false}]}
{"op":"mcm","clk":"5347983230","pt":1646211822687,"mc":[{"id":"1.195453751","rc":[{"atb":[[5,9.9],[5.4,4.95]],"id":522749},{"atl":[[220,4.95]],"id":522751}],"con":true,"img":false}]}
{"op":"mcm","clk":"5347983234","pt":1646211822789,"mc":[{"id":"1.195453751","rc":[{"atl":[[510,5.3]],"id":522748}],"con":true,"img":false}]}
{"op":"mcm","clk":"5347983239","pt":1646211822892,"mc":[{"id":"1.195453751","rc":[{"atb":[[5.6,35.43],[6.2,2.72]],"id":522749}],"con":true,"img":false}]}
{"op":"mcm","clk":"5347983257","pt":1646211823301,"mc":[{"id":"1.195453751","rc":[{"atl":[[34,0],[42,14.08]],"id":522746}],"con":true,"img":false}]}
{"op":"mcm","clk":"5347983262","pt":1646211823406,"mc":[{"id":"1.195453751","rc":[{"atl":[[36,4.95],[44,12.23]],"id":522746}],"con":true,"img":false}]}
{"op":"mcm","clk":"5347983305","pt":1646211824079,"mc":[{"id":"1.195453751","rc":[{"atl":[[42,17.95]],"id":522746}],"con":true,"img":false}]}
{"op":"mcm","clk":"5347983310","pt":1646211824184,"mc":[{"id":"1.195453751","rc":[{"atl":[[720,4.34]],"id":522754}],"con":true,"img":false}]}
{"op":"mcm","clk":"5347983316","pt":1646211824387,"mc":[{"id":"1.195453751","rc":[{"atb":[[16,0],[18.5,0]],"id":522746},{"atb":[[9.8,0],[8.8,0]],"id":3805740}],"con":true,"img":false}]}
{"op":"mcm","clk":"5347983340","pt":1646211824799,"mc":[{"id":"1.195453751","rc":[{"atb":[[14,22.44]],"id":522746},{"atb":[[6.4,98.15],[8.2,9.9]],"id":3805740}],"con":true,"img":false}]}
{"op":"mcm","clk":"5347983355","pt":1646211825106,"mc":[{"id":"1.195453751","rc":[{"atb":[[18,2.72],[15.5,3.26]],"id":522746},{"atb":[[9.6,2.72],[8.6,3.26]],"id":3805740}],"con":true,"img":false}]}
{"op":"mcm","clk":"5347983424","pt":1646211826498,"mc":[{"id":"1.195453751","rc":[{"atl":[[720,2.34],[810,2]],"id":522754}],"con":true,"img":false}]}
{"op":"mcm","clk":"5347983432","pt":1646211826701,"mc":[{"id":"1.195453751","rc":[{"atl":[[44,9.9],[55,2]],"id":522746}],"con":true,"img":false}]}
{"op":"mcm","clk":"5347983491","pt":1646211827784,"mc":[{"id":"1.195453751","rc":[{"atl":[[540,3.44],[280,0]],"id":522751}],"con":true,"img":false}]}
{"op":"mcm","clk":"5347983497","pt":1646211827889,"mc":[{"id":"1.195453751","rc":[{"atl":[[42,3.86],[44,31.99]],"id":522746}],"con":true,"img":false}]}
{"op":"mcm","clk":"5347983513","pt":1646211828299,"mc":[{"id":"1.195453751","rc":[{"atl":[[210,10.12]],"id":522755}],"con":true,"img":false}]}
{"op":"mcm","clk":"5347983517","pt":1646211828405,"mc":[{"id":"1.195453751","rc":[{"atl":[[90,9.9]],"id":522755}],"con":true,"img":false}]}
{"op":"mcm","clk":"5347983627","pt":1646211830012,"mc":[{"id":"1.195453751","rc":[{"atb":[[17.5,0],[15,0]],"id":3805731},{"atb":[[6.8,27.33],[5.9,23.46]],"id":522752},{"atb":[[32,4.29],[42,0]],"id":522741},{"atb":[[34,0],[27,0]],"id":522742},{"atb":[[38,0],[48,0]],"id":522743},{"atb":[[13,0],[15.5,13.37]],"id":522745}],"con":true,"img":false}]}
{"op":"mcm","clk":"5347983642","pt":1646211830217,"mc":[{"id":"1.195453751","rc":[{"atb":[[14,35.54]],"id":522746}],"con":true,"img":false}]}
{"op":"mcm","clk":"5347983671","pt":1646211830737,"mc":[{"id":"1.195453751","rc":[{"atb":[[5.8,3.26],[6.6,7.67]],"id":522752},{"atb":[[8,27.04],[7.8,2.4]],"id":522753},{"atb":[[38,3.26],[48,2.72]],"id":522741},{"atb":[[44,3.26],[60,2.72]],"id":522743}],"con":true,"img":false}]}
{"op":"mcm","clk":"5347983676","pt":1646211830840,"mc":[{"id":"1.195453751","rc":[{"atb":[[16,3.26],[18.5,2.72]],"id":522745}],"con":true,"img":false}]}
{"op":"mcm","clk":"5347983683","pt":1646211830895,"mc":[{"id":"1.195453751","rc":[{"atb":[[18,3.26],[21,2.72]],"id":3805731},{"atb":[[32,3.26],[42,2.72]],"id":522742}],"con":true,"img":false}]}
{"op":"mcm","clk":"5347983693","pt":1646211831000,"mc":[{"id":"1.195453751","rc":[{"atb":[[8.6,29.47],[6.4,24.66]],"id":3805740}],"con":true,"img":false}]}
{"op":"mcm","clk":"5347983711","pt":1646211831206,"mc":[{"id":"1.195453751","rc":[{"atl":[[280,0.56]],"id":522748}],"con":true,"img":false}]}
{"op":"mcm","clk":"5347983716","pt":1646211831309,"mc":[{"id":"1.195453751","rc":[{"atb":[[18.5,19.96],[15.5,0]],"id":522745}],"con":true,"img":false}]}
{"op":"mcm","clk":"5347983743","pt":1646211831717,"mc":[{"id":"1.195453751","rc":[{"atb":[[3.45,9.9],[3.35,22.08],[3.55,0],[3.65,4.95]],"id":3805784},{"atb":[[80,0],[85,9.9],[100,1.6],[110,4.95]],"id":522748},{"atb":[[40,0],[44,9.9],[48,3.37],[55,4.95]],"id":3805772}],"con":true,"img":false}]}
{"op":"mcm","clk":"5347983765","pt":1646211832028,"mc":[{"id":"1.195453751","rc":[{"atl":[[500,0]],"id":522748}],"con":true,"img":false}]}
{"op":"mcm","clk":"5347983772","pt":1646211832132,"mc":[{"id":"1.195453751","rc":[{"atb":[[3.2,0]],"id":3805784},{"atb":[[85,19.64],[48,2.72],[120,1.32]],"id":522748},{"atb":[[18.5,0],[22,0]],"id":522750},{"atb":[[38,0],[44,24.62],[60,2.68]],"id":3805772},{"atb":[[9.6,0],[8.6,26.2]],"id":3805740}],"con":true,"img":false}]}
{"op":"mcm","clk":"5347983778","pt":1646211832235,"mc":[{"id":"1.195453751","rc":[{"atb":[[3.35,69.64]],"id":3805784}],"con":true,"img":false}]}
{"op":"mcm","clk":"5347983791","pt":1646211832398,"mc":[{"id":"1.195453751","rc":[{"atl":[[42,4.95],[46,0],[50,9.9],[60,0]],"id":522750},{"atb":[[80,0],[85,9.9],[100,1.6],[110,4.95]],"id":522751}],"con":true,"img":false}]}
{"op":"mcm","clk":"5347983800","pt":1646211832500,"mc":[{"id":"1.195453751","rc":[{"atl":[[290,0],[230,4.95]],"id":522748}],"con":true,"img":false}]}
{"op":"mcm","clk":"5347983808","pt":1646211832602,"mc":[{"id":"1.195453751","rc":[{"atb":[[17,14.86],[8.4,64.78]],"id":522750}],"con":true,"img":false}]}
{"op":"mcm","clk":"5347983824","pt":1646211832814,"mc":[{"id":"1.195453751","rc":[{"atb":[[100,0]],"id":522748},{"atb":[[19,3.26],[23,2.72]],"id":522750},{"atb":[[75,0],[85,22.37]],"id":522751},{"atb":[[48,0]],"id":3805772},{"atb":[[8.4,3.26],[9.4,2.72]],"id":3805740}],"con":true,"img":false}]}
{"op":"mcm","clk":"5347983830","pt":1646211832909,"mc":[{"id":"1.195453751","rc":[{"atl":[[42,8.82]],"id":522750},{"atb":[[120,1.32]],"id":522751}],"con":true,"img":false}]}
{"op":"mcm","clk":"5347983837","pt":1646211833013,"mc":[{"id":"1.195453751","rc":[{"atl":[[340,0]],"id":522741}],"con":true,"img":false}]}
{"op":"mcm","clk":"5347983856","pt":1646211833324,"mc":[{"id":"1.195453751","rc":[{"atb":[[9.4,21.59]],"id":3805740}],"con":true,"img":false}]}
{"op":"mcm","clk":"5347983862","pt":1646211833426,"mc":[{"id":"1.195453751","rc":[{"atb":[[8.4,35.99]],"id":522750}],"con":true,"img":false}]}
{"op":"mcm","clk":"5347983867","pt":1646211833531,"mc":[{"id":"1.195453751","rc":[{"atl":[[760,2]],"id":522754}],"con":true,"img":false}]}
{"op":"mcm","clk":"5347983871","pt":1646211833633,"mc":[{"id":"1.195453751","rc":[{"atl":[[810,0]],"id":522754},{"atb":[[17,33.45]],"id":522750}],"con":true,"img":false}]}
{"op":"mcm","clk":"5347983877","pt":1646211833738,"mc":[{"id":"1.195453751","rc":[{"atl":[[44,0]],"id":522750},{"atb":[[100,0]],"id":522751}],"con":true,"img":false}]}
{"op":"mcm","clk":"5347983886","pt":1646211833943,"mc":[{"id":"1.195453751","rc":[{"atl":[[540,0.29],[550,5.12]],"id":522751}],"con":true,"img":false}]}
{"op":"mcm","clk":"5347983897","pt":1646211834101,"mc":[{"id":"1.195453751","rc":[{"atb":[[9,4.95]],"id":3805740}],"con":true,"img":false}]}
{"op":"mcm","clk":"5347983903","pt":1646211834206,"mc":[{"id":"1.195453751","rc":[{"atl":[[48,0],[50,37.74]],"id":522750}],"con":true,"img":false}]}
{"op":"mcm","clk":"5347983915","pt":1646211834411,"mc":[{"id":"1.195453751","rc":[{"atb":[[3.65,64.78]],"id":3805784},{"atl":[[280,5.52]],"id":522754},{"atl":[[36,9.48]],"id":522746},{"atl":[[220,5.67]],"id":522751}],"con":true,"img":false}]}
{"op":"mcm","clk":"5347983920","pt":1646211834513,"mc":[{"id":"1.195453751","rc":[{"atl":[[46,4.95],[60,9.9]],"id":522747}],"con":true,"img":false}]}
{"op":"mcm","clk":"5347983924","pt":1646211834616,"mc":[{"id":"1.195453751","rc":[{"atl":[[65,0],[48,3.37]],"id":522747}],"con":true,"img":false}]}
{"op":"mcm","clk":"5347983929","pt":1646211834727,"mc":[{"id":"1.195453751","rc":[{"atl":[[70,17.85],[75,0]],"id":522747}],"con":true,"img":false}]}
{"op":"mcm","clk":"5347983950","pt":1646211835031,"mc":[{"id":"1.195453751","rc":[{"atl":[[46,8.47],[60,28.26]],"id":522747}],"con":true,"img":false}]}
{"op":"mcm","clk":"5347983955","pt":1646211835134,"mc":[{"id":"1.195453751","rc":[{"atb":[[3.35,47.56]],"id":3805784},{"atl":[[42,0]],"id":522746},{"atl":[[70,2]],"id":522747},{"atb":[[5.5,109.69],[3.75,96.87]],"id":522749},{"atl":[[540,0]],"id":522751}],"con":true,"img":false}]}
{"op":"mcm","clk":"5347983965","pt":1646211835239,"mc":[{"id":"1.195453751","rc":[{"atl":[[710,0]],"id":522754}],"con":true,"img":false}]}
{"op":"mcm","clk":"5347983998","pt":1646211835640,"mc":[{"id":"1.195453751","rc":[{"atl":[[44,9.9],[55,20.94]],"id":522746}],"con":true,"img":false}]}
{"op":"mcm","clk":"5347984002","pt":1646211835743,"mc":[{"id":"1.195453751","rc":[{"atl":[[720,0],[760,4.26]],"id":522754}],"con":true,"img":false}]}
{"op":"mcm","clk":"5347984007","pt":1646211835798,"mc":[{"id":"1.195453751","rc":[{"atl":[[48,0]],"id":522747}],"con":true,"img":false}]}
{"op":"mcm","clk":"5347984040","pt":1646211836518,"mc":[{"id":"1.195453751","rc":[{"atl":[[760,2]],"id":522754}],"con":true,"img":false}]}
{"op":"mcm","clk":"5347984049","pt":1646211836833,"mc":[{"id":"1.195453751","rc":[{"atl":[[300,5.76]],"id":522754}],"con":true,"img":false}]}
{"op":"mcm","clk":"5347984119","pt":1646211838110,"mc":[{"id":"1.195453751","rc":[{"atl":[[350,4.95]],"id":522741}],"con":true,"img":false}]}
{"op":"mcm","clk":"5347984135","pt":1646211838528,"mc":[{"id":"1.195453751","rc":[{"atl":[[340,0.46]],"id":522741}],"con":true,"img":false}]}
{"op":"mcm","clk":"5347984152","pt":1646211838933,"mc":[{"id":"1.195453751","rc":[{"atl":[[1000,1.88]],"id":522741}],"con":true,"img":false}]}
{"op":"mcm","clk":"5347984167","pt":1646211839244,"mc":[{"id":"1.195453751","rc":[{"atl":[[1000,1.72]],"id":522741}],"con":true,"img":false}]}
{"op":"mcm","clk":"5347984204","pt":1646211839918,"mc":[{"id":"1.195453751","rc":[{"atb":[[32,0],[40,4.06]],"id":522745}],"con":true,"img":false}]}
{"op":"mcm","clk":"5347984219","pt":1646211840123,"mc":[{"id":"1.195453751","rc":[{"atl":[[240,7.24]],"id":522751},{"atb":[[34,9.9],[42,4.95]],"id":522745}],"con":true,"img":false}]}
{"op":"mcm","clk":"5347984224","pt":1646211840237,"mc":[{"id":"1.195453751","rc":[{"atl":[[80,19.96],[50,9.9]],"id":522750},{"atl":[[550,2]],"id":522751}],"con":true,"img":false}]}
{"op":"mcm","clk":"5347984236","pt":1646211840433,"mc":[{"id":"1.195453751","rc":[{"atb":[[16,16.67]],"id":522745}],"con":true,"img":false}]}
{"op":"mcm","clk":"5347984241","pt":1646211840535,"mc":[{"id":"1.195453751","rc":[{"atb":[[18.5,2.72]],"id":522745}],"con":true,"img":false}]}
{"op":"mcm","clk":"5347984248","pt":1646211840645,"mc":[{"id":"1.195453751","rc":[{"atb":[[42,8.82]],"id":522745}],"con":true,"img":false}]}
{"op":"mcm","clk":"5347984259","pt":1646211840845,"mc":[{"id":"1.195453751","rc":[{"atl":[[240,0]],"id":522751}],"con":true,"img":false}]}
{"op":"mcm","clk":"5347984280","pt":1646211841103,"mc":[{"id":"1.195453751","rc":[{"atl":[[70,17.85]],"id":522747}],"con":true,"img":false}]}
{"op":"mcm","clk":"5347984288","pt":1646211841256,"mc":[{"id":"1.195453751","rc":[{"atl":[[60,9.9]],"id":522747},{"atb":[[16,3.26]],"id":522745}],"con":true,"img":false}]}
{"op":"mcm","clk":"5347984302","pt":1646211841516,"mc":[{"id":"1.195453751","rc":[{"atb":[[40,0]],"id":522745}],"con":true,"img":false}]}
{"op":"mcm","clk":"5347984314","pt":1646211841824,"mc":[{"id":"1.195453751","rc":[{"atl":[[300,0],[760,4.28]],"id":522754}],"con":true,"img":false}]}
{"op":"mcm","clk":"5347984365","pt":1646211842850,"mc":[{"id":"1.195453751","rc":[{"atl":[[760,2]],"id":522754}],"con":true,"img":false}]}
{"op":"mcm","clk":"5347984369","pt":1646211842953,"mc":[{"id":"1.195453751","rc":[{"atl":[[13.5,0]],"id":3805740},{"atb":[[34,0],[42,0]],"id":522745}],"con":true,"img":false}]}
{"op":"mcm","clk":"5347984376","pt":1646211843111,"mc":[{"id":"1.195453751","rc":[{"atl":[[340,5.42]],"id":522741},{"atb":[[32,9.9],[40,4.95]],"id":522745}],"con":true,"img":false}]}
{"op":"mcm","clk":"5347984379","pt":1646211843214,"mc":[{"id":"1.195453751","rc":[{"atl":[[350,0]],"id":522741}],"con":true,"img":false}]}
{"op":"mcm","clk":"5347984387","pt":1646211843418,"mc":[{"id":"1.195453751","rc":[{"atl":[[16,9.9],[23,44.01]],"id":3805740}],"con":true,"img":false}]}
{"op":"mcm","clk":"5347984390","pt":1646211843522,"mc":[{"id":"1.195453751","rc":[{"atl":[[230,5.64]],"id":522748}],"con":true,"img":false}]}
{"op":"mcm","clk":"5347984393","pt":1646211843628,"mc":[{"id":"1.195453751","rc":[{"atl":[[1000,0]],"id":522741},{"atb":[[18.5,17.43]],"id":522745}],"con":true,"img":false}]}
{"op":"mcm","clk":"5347984396","pt":1646211843730,"mc":[{"id":"1.195453751","rc":[{"atl":[[16,20.47]],"id":3805740},{"atb":[[19,8.8]],"id":522745}],"con":true,"img":false}]}
{"op":"mcm","clk":"5347984425","pt":1646211844343,"mc":[{"id":"1.195453751","rc":[{"atl":[[280,0]],"id":522748}],"con":true,"img":false}]}
{"op":"mcm","clk":"5347984433","pt":1646211844660,"mc":[{"id":"1.195453751","rc":[{"atb":[[32,0],[38,4.95],[40,0],[30,9.9]],"id":522745}],"con":true,"img":false}]}
{"op":"mcm","clk":"5347984449","pt":1646211844913,"mc":[{"id":"1.195453751","rc":[{"atl":[[510,2],[250,7]],"id":522748}],"con":true,"img":false}]}
{"op":"mcm","clk":"5347984453","pt":1646211845014,"mc":[{"id":"1.195453751","rc":[{"atl":[[450,2]],"id":522748}],"con":true,"img":false}]}
{"op":"mcm","clk":"5347984457","pt":1646211845115,"mc":[{"id":"1.195453751","rc":[{"atl":[[510,0]],"id":522748}],"con":true,"img":false}]}
{"op":"mcm","clk":"5347984488","pt":1646211845733,"mc":[{"id":"1.195453751","rc":[{"atl":[[250,0]],"id":522748}],"con":true,"img":false}]}
{"op":"mcm","clk":"5347984512","pt":1646211846244,"mc":[{"id":"1.195453751","rc":[{"atl":[[240,7.31]],"id":522751}],"con":true,"img":false}]}
{"op":"mcm","clk":"5347984553","pt":1646211846917,"mc":[{"id":"1.195453751","rc":[{"atl":[[10.5,9.9],[9.4,4.95]],"id":522749}],"con":true,"img":false}]}
{"op":"mcm","clk":"5347984559","pt":1646211847018,"mc":[{"id":"1.195453751","rc":[{"atl":[[9.2,0],[10,0],[12,9.09],[13,41.61]],"id":522749}],"con":true,"img":false}]}
{"op":"mcm","clk":"5347984579","pt":1646211847534,"mc":[{"id":"1.195453751","rc":[{"atl":[[10,50.83],[13,0]],"id":522749}],"con":true,"img":false}]}
{"op":"mcm","clk":"5347984589","pt":1646211847739,"mc":[{"id":"1.195453751","rc":[{"atl":[[10,60.73],[9.2,4.95],[10.5,0],[11.5,11.4],[9.4,0]],"id":522749}],"con":true,"img":false}]}
{"op":"mcm","clk":"5347984596","pt":1646211847942,"mc":[{"id":"1.195453751","rc":[{"atl":[[300,5.86]],"id":522754}],"con":true,"img":false}]}
{"op":"mcm","clk":"5347984654","pt":1646211849431,"mc":[{"id":"1.195453751","rc":[{"atl":[[210,4.95],[220,0.72]],"id":522751}],"con":true,"img":false}]}
{"op":"mcm","clk":"5347984676","pt":1646211849943,"mc":[{"id":"1.195453751","rc":[{"atl":[[200,0.79]],"id":522751}],"con":true,"img":false}]}
{"op":"mcm","clk":"5347984704","pt":1646211850456,"mc":[{"id":"1.195453751","rc":[{"atl":[[65,9.9],[46,0],[48,4.95],[60,0]],"id":522747}],"con":true,"img":false}]}
{"op":"mcm","clk":"5347984720","pt":1646211850764,"mc":[{"id":"1.195453751","rc":[{"atl":[[220,0]],"id":522751}],"con":true,"img":false}]}
{"op":"mcm","clk":"5347984738","pt":1646211851125,"mc":[{"id":"1.195453751","rc":[{"atl":[[65,12.38]],"id":522747}],"con":true,"img":false}]}
{"op":"mcm","clk":"5347984824","pt":1646211852770,"mc":[{"id":"1.195453751","rc":[{"atb":[[18.5,2.72],[19,26.05],[19.5,8.56]],"id":522745}],"con":true,"img":false}]}
{"op":"mcm","clk":"5347984856","pt":1646211853437,"mc":[{"id":"1.195453751","rc":[{"atl":[[10,9.9],[11.5,81.02]],"id":522749}],"con":true,"img":false}]}
{"op":"mcm","clk":"5347984864","pt":1646211853647,"mc":[{"id":"1.195453751","rc":[{"atb":[[19,17.24]],"id":522745}],"con":true,"img":false}]}
{"op":"mcm","clk":"5347984873","pt":1646211853847,"mc":[{"id":"1.195453751","rc":[{"atl":[[300,0],[760,4.33]],"id":522754}],"con":true,"img":false}]}
{"op":"mcm","clk":"5347984972","pt":1646211855850,"mc":[{"id":"1.195453751","rc":[{"atl":[[14,17.15]],"id":3805740},{"atb":[[38,9.23],[19.5,25.81],[19,0]],"id":522745}],"con":true,"img":false}]}
{"op":"mcm","clk":"5347985008","pt":1646211856564,"mc":[{"id":"1.195453751","rc":[{"atb":[[9.6,0],[8.6,0]],"id":522753},{"atl":[[16,9.9]],"id":3805740},{"atb":[[19.5,17.24]],"id":522745}],"con":true,"img":false}]}
{"op":"mcm","clk":"5347985027","pt":1646211857085,"mc":[{"id":"1.195453751","rc":[{"atl":[[250,7.13]],"id":522748},{"atb":[[8,27.6],[7.2,50.51]],"id":522753}],"con":true,"img":false}]}
{"op":"mcm","clk":"5347985046","pt":1646211857338,"mc":[{"id":"1.195453751","rc":[{"atb":[[9.8,2.72],[8.8,3.26]],"id":522753}],"con":true,"img":false}]}
{"op":"mcm","clk":"5347985072","pt":1646211857855,"mc":[{"id":"1.195453751","rc":[{"atb":[[7.8,0]],"id":522753}],"con":true,"img":false}]}
{"op":"mcm","clk":"5347985116","pt":1646211858572,"mc":[{"id":"1.195453751","rc":[{"atl":[[16,0],[14,0]],"id":3805740}],"con":true,"img":false}]}
{"op":"mcm","clk":"5347985127","pt":1646211858776,"mc":[{"id":"1.195453751","rc":[{"atl":[[16.5,9.9],[23,39.46],[24,4.35],[14.5,4.95]],"id":3805740}],"con":true,"img":false}]}
{"op":"mcm","clk":"5347985140","pt":1646211858981,"mc":[{"id":"1.195453751","rc":[{"atl":[[23,0],[25,71.04]],"id":3805740}],"con":true,"img":false}]}
{"op":"mcm","clk":"5347985156","pt":1646211859342,"mc":[{"id":"1.195453751","rc":[{"atl":[[16.5,20.13]],"id":3805740}],"con":true,"img":false}]}
{"op":"mcm","clk":"5347985161","pt":1646211859547,"mc":[{"id":"1.195453751","rc":[{"atl":[[230,0.69],[240,4.95]],"id":522748}],"con":true,"img":false}]}
{"op":"mcm","clk":"5347985163","pt":1646211859650,"mc":[{"id":"1.195453751","rc":[{"atl":[[230,0]],"id":522748}],"con":true,"img":false}]}
{"op":"mcm","clk":"5347985169","pt":1646211859855,"mc":[{"id":"1.195453751","rc":[{"atl":[[9.2,24.29]],"id":522749}],"con":true,"img":false}]}
{"op":"mcm","clk":"5347985172","pt":1646211859957,"mc":[{"id":"1.195453751","rc":[{"atl":[[300,5.97],[760,2]],"id":522754}],"con":true,"img":false}]}
{"op":"mcm","clk":"5347985192","pt":1646211860576,"mc":[{"id":"1.195453751","rc":[{"atl":[[240,5.61]],"id":522748}],"con":true,"img":false}]}
{"op":"mcm","clk":"5347985198","pt":1646211860677,"mc":[{"id":"1.195453751","rc":[{"atl":[[11.5,69.62]],"id":522749}],"con":true,"img":false}]}
{"op":"mcm","clk":"5347985213","pt":1646211860878,"mc":[{"id":"1.195453751","rc":[{"atl":[[300,0]],"id":522754}],"con":true,"img":false}]}
{"op":"mcm","clk":"5347985296","pt":1646211862272,"mc":[{"id":"1.195453751","rc":[{"atb":[[2.3,0],[1.85,0],[1.95,0]],"id":3805784},{"atb":[[5.1,0],[3.55,0],[3.05,0]],"id":3805747},{"atb":[[16,0],[22,0],[60,2.72]],"id":522754},{"atb":[[5.8,0],[7.6,0],[14,0]],"id":522755},{"atb":[[5.8,0],[7.6,0],[14,25.3]],"id":522746},{"atb":[[9.6,0],[19,0],[7.6,0]],"id":522747},{"atb":[[18,0],[42,0],[13,0]],"id":522748},{"atb":[[5.5,80.09],[3.25,0],[3.75,0]],"id":522749},{"atb":[[16,0],[6.4,0],[8.4,0]],"id":522750},{"atb":[[27,0],[13.5,0],[9.4,0]],"id":522751},{"atb":[[7.8,0],[14.5,0],[5.9,0]],"id":3805731},{"atb":[[4,33.33],[2.8,0],[3,0]],"id":522752},{"atb":[[8,0],[4,0],[5,0]],"id":3805762},{"atb":[[6.2,0],[4.1,0],[3.55,0]],"id":522753},{"atb":[[32,0],[10.5,0],[15.5,0]],"id":522741},{"atb":[[24,0],[12,0],[8.8,0]],"id":522742},{"atb":[[18,0],[42,0],[13,0]],"id":522743},{"atb":[[3.6,0],[6.4,0],[4.2,0]],"id":3805740},{"atb":[[16,0],[6.4,0],[8.4,0]],"id":3805772},{"atb":[[260,0],[160,8.01],[460,0]],"id":7607472},{"atb":[[12,0],[6.8,0],[5.4,0]],"id":522745}],"con":true,"img":false}]}
{"op":"mcm","clk":"5347985321","pt":1646211862790,"mc":[{"id":"1.195453751","rc":[{"atb":[[17.5,31.24]],"id":522747},{"atb":[[160,4.95],[170,0.93],[90,22.76]],"id":7607472}],"con":true,"img":false}]}
{"op":"mcm","clk":"5347985334","pt":1646211862953,"mc":[{"id":"1.195453751","rc":[{"atl":[[450,6],[250,0]],"id":522748}],"con":true,"img":false}]}
{"op":"mcm","clk":"5347985343","pt":1646211863157,"mc":[{"id":"1.195453751","rc":[{"atl":[[46,3.52]],"id":522747}],"con":true,"img":false}]}
{"op":"mcm","clk":"5347985369","pt":1646211863673,"mc":[{"id":"1.195453751","rc":[{"atl":[[65,24.97],[70,2]],"id":522747}],"con":true,"img":false}]}
{"op":"mcm","clk":"5347985387","pt":1646211863978,"mc":[{"id":"1.195453751","rc":[{"atl":[[65,22.49]],"id":522747}],"con":true,"img":false}]}
{"op":"mcm","clk":"5347985413","pt":1646211864390,"mc":[{"id":"1.195453751","rc":[{"atl":[[760,0],[820,2]],"id":522754}],"con":true,"img":false}]}
{"op":"mcm","clk":"5347985433","pt":1646211864800,"mc":[{"id":"1.195453751","rc":[{"atl":[[340,0.46],[350,4.95]],"id":522741}],"con":true,"img":false}]}
{"op":"mcm","clk":"5347985485","pt":1646211865780,"mc":[{"id":"1.195453751","rc":[{"atl":[[300,6.03]],"id":522754}],"con":true,"img":false}]}
{"op":"mcm","clk":"5347985507","pt":1646211866294,"mc":[{"id":"1.195453751","rc":[{"atb":[[65,4.95],[46,0],[48,9.9],[60,2.68]],"id":3805731}],"con":true,"img":false}]}
{"op":"mcm","clk":"5347985526","pt":1646211866756,"mc":[{"id":"1.195453751","rc":[{"atb":[[65,7.43],[48,23.83],[28,0]],"id":3805731}],"con":true,"img":false}]}
{"op":"mcm","clk":"5347985561","pt":1646211867476,"mc":[{"id":"1.195453751","rc":[{"atb":[[60,0]],"id":3805731}],"con":true,"img":false}]}
{"op":"mcm","clk":"5347985578","pt":1646211867783,"mc":[{"id":"1.195453751","rc":[{"atl":[[14.5,16.69]],"id":3805740}],"con":true,"img":false}]}
{"op":"mcm","clk":"5347985606","pt":1646211868603,"mc":[{"id":"1.195453751","rc":[{"atl":[[16.5,9.9]],"id":3805740}],"con":true,"img":false}]}
{"op":"mcm","clk":"5347985618","pt":1646211868916,"mc":[{"id":"1.195453751","rc":[{"atl":[[260,6.99],[450,2]],"id":522748},{"atb":[[8,68.21],[7.2,9.9]],"id":522753}],"con":true,"img":false}]}
{"op":"mcm","clk":"5347985622","pt":1646211869020,"mc":[{"id":"1.195453751","rc":[{"atb":[[2.3,102.45],[1.85,313.4],[1.95,280.41]],"id":3805784},{"atb":[[5.1,32.48],[3.55,104.46],[3.05,129.94]],"id":3805747},{"atb":[[16,17.76],[22,12.68],[60,4.98]],"id":522754},{"atb":[[5.8,55.49],[7.6,40.36],[14,10.24]],"id":522755},{"atb":[[5.8,55.49],[7.6,40.36],[14,35.54]],"id":522746},{"atb":[[9.6,30.97],[19,7.4],[7.6,40.36]],"id":522747},{"atb":[[18,15.66],[42,3.24],[13,22.19]],"id":522748},{"atb":[[5.5,109.69],[3.25,118.39],[3.75,96.87]],"id":522749},{"atb":[[16,8.87],[6.4,49.33],[8.4,35.99]],"id":522750},{"atb":[[27,5.12],[13.5,21.3],[9.4,31.71]],"id":522751},{"atb":[[7.8,39.17],[14.5,9.86],[5.9,54.36]],"id":3805731},{"atb":[[4,77.73],[2.8,147.99],[3,133.19]],"id":522752},{"atb":[[8,19.02],[4,88.79],[5,66.59]],"id":3805762},{"atb":[[6.2,25.61],[4.1,85.93],[3.55,104.46]],"id":522753},{"atb":[[32,4.29],[10.5,28.03],[15.5,18.37]],"id":522741},{"atb":[[24,5.79],[12,24.21],[8.8,34.15]],"id":522742},{"atb":[[18,15.66],[42,3.24],[13,22.19]],"id":522743},{"atb":[[3.6,102.45],[6.4,24.66],[4.2,83.24]],"id":3805740},{"atb":[[16,8.87],[6.4,49.33],[8.4,35.99]],"id":3805772},{"atb":[[260,1.03],[160,6.62],[460,0.28]],"id":7607472},{"atb":[[12,12.1],[6.8,45.93],[5.4,60.54]],"id":522745}],"con":true,"img":false}]}
{"op":"mcm","clk":"5347985653","pt":1646211869484,"mc":[{"id":"1.195453751","rc":[{"atb":[[17.5,9.6]],"id":522747}],"con":true,"img":false}]}
{"op":"mcm","clk":"5347985735","pt":1646211870879,"mc":[{"id":"1.195453751","rc":[{"atl":[[24,43.89]],"id":3805740}],"con":true,"img":false}]}
{"op":"mcm","clk":"5347985739","pt":1646211870981,"mc":[{"id":"1.195453751","rc":[{"atl":[[25,0]],"id":3805740}],"con":true,"img":false}]}
{"op":"mcm","clk":"5347985746","pt":1646211871091,"mc":[{"id":"1.195453751","rc":[{"atb":[[40,2.56],[30,0]],"id":522751},{"atb":[[65,0],[90,20.03]],"id":7607472}],"con":true,"img":false}]}
{"op":"mcm","clk":"5347985765","pt":1646211871493,"mc":[{"id":"1.195453751","rc":[{"atl":[[300,0],[820,4.21]],"id":522754}],"con":true,"img":false}]}
{"op":"mcm","clk":"5347985780","pt":1646211871802,"mc":[{"id":"1.195453751","rc":[{"atb":[[42,2.72]],"id":522751}],"con":true,"img":false}]}
{"op":"mcm","clk":"5347985787","pt":1646211871904,"mc":[{"id":"1.195453751","rc":[{"atb":[[32,3.26]],"id":522751},{"atb":[[120,12.63]],"id":7607472}],"con":true,"img":false}]}
{"op":"mcm","clk":"5347985808","pt":1646211872273,"mc":[{"id":"1.195453751","rc":[{"atl":[[820,2]],"id":522754}],"con":true,"img":false}]}
{"op":"mcm","clk":"5347985816","pt":1646211872476,"mc":[{"id":"1.195453751","rc":[{"atb":[[21,16.64],[48,9.9]],"id":3805731}],"con":true,"img":false}]}
{"op":"mcm","clk":"5347985839","pt":1646211872886,"mc":[{"id":"1.195453751","rc":[{"atb":[[19,0],[23,0]],"id":522750},{"atb":[[65,0],[46,9.9],[48,0],[60,4.95]],"id":3805731}],"con":true,"img":false}]}
{"op":"mcm","clk":"5347985864","pt":1646211873298,"mc":[{"id":"1.195453751","rc":[{"atb":[[17,14.86],[8.4,80.4]],"id":522750}],"con":true,"img":false}]}
{"op":"mcm","clk":"5347985880","pt":1646211873607,"mc":[{"id":"1.195453751","rc":[{"atb":[[18.5,3.26],[22,2.72]],"id":522750},{"atb":[[60,7.64]],"id":3805731}],"con":true,"img":false}]}
{"op":"mcm","clk":"5347985925","pt":1646211874478,"mc":[{"id":"1.195453751","rc":[{"atb":[[170,3.73],[90,0]],"id":7607472}],"con":true,"img":false}]}
{"op":"mcm","clk":"5347985929","pt":1646211874582,"mc":[{"id":"1.195453751","rc":[{"atl":[[260,0],[450,6.07]],"id":522748}],"con":true,"img":false}]}
{"op":"mcm","clk":"5347985949","pt":1646211874992,"mc":[{"id":"1.195453751","rc":[{"atb":[[85,3.26]],"id":7607472}],"con":true,"img":false}]}
{"op":"mcm","clk":"5347986026","pt":1646211876900,"mc":[{"id":"1.195453751","rc":[{"atb":[[18,0],[15.5,0]],"id":522755}],"con":true,"img":false}]}
{"op":"mcm","clk":"5347986057","pt":1646211877419,"mc":[{"id":"1.195453751","rc":[{"atl":[[300,6.14]],"id":522754}],"con":true,"img":false}]}
{"op":"mcm","clk":"5347986062","pt":1646211877623,"mc":[{"id":"1.195453751","rc":[{"atl":[[770,2],[820,0]],"id":522754},{"atb":[[16,3.26],[18.5,2.72]],"id":522755}],"con":true,"img":false}]}
{"op":"mcm","clk":"5347986166","pt":1646211880502,"mc":[{"id":"1.195453751","rc":[{"atl":[[260,7.12]],"id":522748}],"con":true,"img":false}]}
{"op":"mcm","clk":"5347986171","pt":1646211880607,"mc":[{"id":"1.195453751","rc":[{"atl":[[450,2]],"id":522748}],"con":true,"img":false}]}
{"op":"mcm","clk":"5347986182","pt":1646211880913,"mc":[{"id":"1.195453751","rc":[{"atl":[[6.2,30.48],[6,4.95],[6.8,9.9],[7,0]],"id":3805784},{"atl":[[280,0.56],[300,11.09]],"id":522754},{"atb":[[17,0],[18,4.95],[19.5,0],[19,19.99]],"id":522747},{"atb":[[17,9.9],[17.5,4.95]],"id":522750},{"atl":[[210,0]],"id":522751},{"atl":[[260,0],[240,4.95]],"id":3805731},{"atb":[[8,63.25],[7.2,0],[8.2,4.95],[7.4,9.9]],"id":522753},{"atl":[[350,0],[360,4.95]],"id":522741},{"atb":[[460,0.63]],"id":7607472}],"con":true,"img":false}]}
{"op":"mcm","clk":"5347986186","pt":1646211881016,"mc":[{"id":"1.195453751","rc":[{"atb":[[5,0],[5.5,114.64],[5.4,0]],"id":522749},{"atb":[[22,10.27]],"id":522750},{"atl":[[220,4.95]],"id":522751},{"atl":[[590,2],[690,2.41]],"id":3805731}],"con":true,"img":false}]}
{"op":"mcm","clk":"5347986193","pt":1646211881221,"mc":[{"id":"1.195453751","rc":[{"atl":[[260,0]],"id":522748}],"con":true,"img":false}]}
{"op":"mcm","clk":"5347986195","pt":1646211881323,"mc":[{"id":"1.195453751","rc":[{"atl":[[8,14.29],[6.8,69.95],[5.9,32.35]],"id":3805784},{"atl":[[550,5.36],[240,0]],"id":522751},{"atb":[[8,22.64],[8.2,27.04]],"id":522753}],"con":true,"img":false}]}
{"op":"mcm","clk":"5347986204","pt":1646211881529,"mc":[{"id":"1.195453751","rc":[{"atl":[[590,5.13],[690,0]],"id":3805731}],"con":true,"img":false}]}
{"op":"mcm","clk":"5347986208","pt":1646211881583,"mc":[{"id":"1.195453751","rc":[{"atb":[[20,3.26]],"id":522747}],"con":true,"img":false}]}
{"op":"mcm","clk":"5347986215","pt":1646211881688,"mc":[{"id":"1.195453751","rc":[{"atb":[[17,0]],"id":522750},{"atb":[[170,2.79],[460,0.28]],"id":7607472}],"con":true,"img":false}]}
{"op":"mcm","clk":"5347986229","pt":1646211881996,"mc":[{"id":"1.195453751","rc":[{"atl":[[34,4.95],[36,4.52],[42,9.9],[44,0]],"id":522746}],"con":true,"img":false}]}
{"op":"mcm","clk":"5347986233","pt":1646211882098,"mc":[{"id":"1.195453751","rc":[{"atl":[[6.2,0]],"id":3805784}],"con":true,"img":false}]}
{"op":"mcm","clk":"5347986247","pt":1646211882406,"mc":[{"id":"1.195453751","rc":[{"atl":[[34,9.76],[42,23.99]],"id":522746},{"atb":[[270,0.58]],"id":7607472}],"con":true,"img":false}]}
{"op":"mcm","clk":"5347986253","pt":1646211882509,"mc":[{"id":"1.195453751","rc":[{"atl":[[55,2]],"id":522746}],"con":true,"img":false}]}
{"op":"mcm","clk":"5347986258","pt":1646211882614,"mc":[{"id":"1.195453751","rc":[{"atl":[[770,0],[850,2]],"id":522754}],"con":true,"img":false}]}
{"op":"mcm","clk":"5347986288","pt":1646211883027,"mc":[{"id":"1.195453751","rc":[{"atl":[[300,4.95],[770,2.4]],"id":522754},{"atl":[[46,0]],"id":522747},{"atl":[[250,4.95]],"id":522748},{"atl":[[16.5,0],[17,9.9],[14.5,0],[15,4.95]],"id":3805740}],"con":true,"img":false}]}
{"op":"mcm","clk":"5347986290","pt":1646211883128,"mc":[{"id":"1.195453751","rc":[{"atl":[[34,4.8],[36,9.48],[42,14.08],[44,9.9]],"id":522746},{"atl":[[240,0]],"id":522748}],"con":true,"img":false}]}
{"op":"mcm","clk":"5347986295","pt":1646211883233,"mc":[{"id":"1.195453751","rc":[{"atb":[[3.45,0],[3.7,4.95],[3.5,9.9],[3.65,59.82]],"id":3805784},{"atl":[[34,0],[36,4.95]],"id":522746},{"atl":[[70,0],[75,2]],"id":522747}],"con":true,"img":false}]}
{"op":"mcm","clk":"5347986301","pt":1646211883335,"mc":[{"id":"1.195453751","rc":[{"atl":[[200,0]],"id":522751}],"con":true,"img":false}]}
{"op":"mcm","clk":"5347986307","pt":1646211883439,"mc":[{"id":"1.195453751","rc":[{"atl":[[280,0]],"id":522754},{"atl":[[65,9.9],[70,12.21]],"id":522747}],"con":true,"img":false}]}
{"op":"mcm","clk":"5347986319","pt":1646211883704,"mc":[{"id":"1.195453751","rc":[{"atb":[[3.35,0],[3.5,72.73]],"id":3805784},{"atl":[[300,0],[310,4.95]],"id":522754},{"atl":[[65,0],[70,22.12],[48,0],[50,4.95],[60,2.68]],"id":522747},{"atl":[[270,4.95],[250,0]],"id":522748},{"atl":[[17,0],[17.5,9.9],[23,7.2],[15,0],[15.5,4.95]],"id":3805740}],"con":true,"img":false}]}
{"op":"mcm","clk":"5347986323","pt":1646211883807,"mc":[{"id":"1.195453751","rc":[{"atl":[[440,0.35]],"id":522748},{"atl":[[40,4.95],[42,3.86],[48,9.9],[50,0]],"id":522750}],"con":true,"img":false}]}
{"op":"mcm","clk":"5347986330","pt":1646211883908,"mc":[{"id":"1.195453751","rc":[{"atb":[[3.45,9.9],[3.7,0],[3.5,62.82],[3.65,64.78]],"id":3805784},{"atl":[[42,17.95]],"id":522746}],"con":true,"img":false}]}
{"op":"mcm","clk":"5347986334","pt":1646211884011,"mc":[{"id":"1.195453751","rc":[{"atb":[[3.65,4.95]],"id":3805784},{"atl":[[230,4.95]],"id":522751}],"con":true,"img":false}]}
{"op":"mcm","clk":"5347986338","pt":1646211884116,"mc":[{"id":"1.195453751","rc":[{"atl":[[220,0.72]],"id":522751}],"con":true,"img":false}]}
{"op":"mcm","clk":"5347986345","pt":1646211884219,"mc":[{"id":"1.195453751","rc":[{"atl":[[300,0.52]],"id":522754},{"atl":[[23,32.63],[24,4.35]],"id":3805740}],"con":true,"img":false}]}
{"op":"mcm","clk":"5347986350","pt":1646211884322,"mc":[{"id":"1.195453751","rc":[{"atl":[[40,9.01],[80,2],[48,24.62]],"id":522750}],"con":true,"img":false}]}
{"op":"mcm","clk":"5347986355","pt":1646211884425,"mc":[{"id":"1.195453751","rc":[{"atl":[[310,0],[320,4.95]],"id":522754},{"atl":[[270,0],[280,4.95]],"id":522748}],"con":true,"img":false}]}
{"op":"mcm","clk":"5347986367","pt":1646211884631,"mc":[{"id":"1.195453751","rc":[{"atb":[[3.6,4.95],[3.4,9.9]],"id":3805784}],"con":true,"img":false}]}
{"op":"mcm","clk":"5347986373","pt":1646211884735,"mc":[{"id":"1.195453751","rc":[{"atb":[[3.45,0],[3.65,0]],"id":3805784}],"con":true,"img":false}]}
{"op":"mcm","clk":"5347986380","pt":1646211884839,"mc":[{"id":"1.195453751","rc":[{"atb":[[3.5,118.27]],"id":3805784},{"atb":[[17.5,19.66],[8.4,35.99]],"id":522750}],"con":true,"img":false}]}
{"op":"mcm","clk":"5347986394","pt":1646211884997,"mc":[{"id":"1.195453751","rc":[{"atb":[[6.6,2.72],[5.9,13.55]],"id":522752},{"atl":[[21,0],[22,4.95],[25,29.45],[26,9.9]],"id":3805762},{"atl":[[360,0],[370,4.95]],"id":522741}],"con":true,"img":false}]}
{"op":"mcm","clk":"5347986402","pt":1646211885100,"mc":[{"id":"1.195453751","rc":[{"atl":[[42,0]],"id":522750},{"atb":[[6.4,4.95],[5.8,13.17]],"id":522752}],"con":true,"img":false}]}
{"op":"mcm","clk":"5347986410","pt":1646211885202,"mc":[{"id":"1.195453751","rc":[{"atl":[[300,0],[320,0],[360,4.95]],"id":522754},{"atl":[[280,0],[310,4.95]],"id":522748},{"atl":[[40,0],[42,4.95],[48,14.71],[50,9.9]],"id":522750},{"atl":[[220,0],[230,0],[250,4.95]],"id":522751}],"con":true,"img":false}]}
{"op":"mcm","clk":"5347986418","pt":1646211885415,"mc":[{"id":"1.195453751","rc":[{"atb":[[3.6,0],[3.35,9.9],[3.4,0],[3.55,4.95]],"id":3805784},{"atl":[[70,12.21],[75,11.9],[50,0],[55,4.95]],"id":522747}],"con":true,"img":false}]}
{"op":"mcm","clk":"5347986422","pt":1646211885510,"mc":[{"id":"1.195453751","rc":[{"atb":[[6.4,46.01],[5.9,0]],"id":522752},{"atl":[[17.5,0],[17,9.9],[15,4.95],[15.5,0]],"id":3805740}],"con":true,"img":false}]}
{"op":"mcm","clk":"5347986439","pt":1646211885922,"mc":[{"id":"1.195453751","rc":[{"atl":[[760,0.2]],"id":522754},{"atl":[[46,3.52]],"id":522750},{"atl":[[540,0.29],[240,4.95],[250,0]],"id":522751},{"atb":[[260,2.78],[170,0]],"id":7607472}],"con":true,"img":false}]}
{"op":"mcm","clk":"5347986445","pt":1646211886028,"mc":[{"id":"1.195453751","rc":[{"atl":[[290,4.95],[310,0]],"id":522748}],"con":true,"img":false}]}
{"op":"mcm","clk":"5347986451","pt":1646211886131,"mc":[{"id":"1.195453751","rc":[{"atl":[[70,22.12],[75,2],[50,4.95],[55,0]],"id":522747},{"atl":[[450,6.14]],"id":522748}],"con":true,"img":false}]}
{"op":"mcm","clk":"5347986460","pt":1646211886242,"mc":[{"id":"1.195453751","rc":[{"atl":[[17.5,9.9],[15.5,4.95]],"id":3805740}],"con":true,"img":false}]}
{"op":"mcm","clk":"5347986467","pt":1646211886289,"mc":[{"id":"1.195453751","rc":[{"atl":[[17,0],[15,0]],"id":3805740}],"con":true,"img":false}]}
{"op":"mcm","clk":"5347986481","pt":1646211886606,"mc":[{"id":"1.195453751","rc":[{"atl":[[360,0],[370,4.95]],"id":522754}],"con":true,"img":false}]}
{"op":"mcm","clk":"5347986487","pt":1646211886709,"mc":[{"id":"1.195453751","rc":[{"atl":[[240,0],[250,4.95]],"id":522751}],"con":true,"img":false}]}
{"op":"mcm","clk":"5347986496","pt":1646211886806,"mc":[{"id":"1.195453751","rc":[{"atl":[[290,0],[300,4.95]],"id":522748}],"con":true,"img":false}]}
{"op":"mcm","clk":"5347986503","pt":1646211886913,"mc":[{"id":"1.195453751","rc":[{"atl":[[70,12.21],[75,11.9],[50,0],[55,4.95]],"id":522747}],"con":true,"img":false}]}
{"op":"mcm","clk":"5347986521","pt":1646211887215,"mc":[{"id":"1.195453751","rc":[{"atl":[[42,0],[44,4.95],[50,0]],"id":522750}],"con":true,"img":false}]}
{"op":"mcm","clk":"5347986527","pt":1646211887420,"mc":[{"id":"1.195453751","rc":[{"atl":[[370,0]],"id":522754}],"con":true,"img":false}]}
{"op":"mcm","clk":"5347986531","pt":1646211887526,"mc":[{"id":"1.195453751","rc":[{"atl":[[300,0],[310,4.95]],"id":522748}],"con":true,"img":false}]}
{"op":"mcm","clk":"5347986559","pt":1646211887938,"mc":[{"id":"1.195453751","rc":[{"atl":[[260,4.95],[250,0]],"id":522751}],"con":true,"img":false}]}
{"op":"mcm","clk":"5347986564","pt":1646211887991,"mc":[{"id":"1.195453751","rc":[{"atl":[[42,3.86],[44,31.99]],"id":522746},{"atl":[[55,9.9]],"id":522750}],"con":true,"img":false}]}
{"op":"mcm","clk":"5347986580","pt":1646211888299,"mc":[{"id":"1.195453751","rc":[{"atl":[[310,0],[320,4.95]],"id":522748}],"con":true,"img":false}]}
{"op":"mcm","clk":"5347986588","pt":1646211888507,"mc":[{"id":"1.195453751","rc":[{"atl":[[770,0],[850,4.19]],"id":522754}],"con":true,"img":false}]}
{"op":"mcm","clk":"5347986631","pt":1646211889227,"mc":[{"id":"1.195453751","rc":[{"atb":[[3.35,72.73],[3.5,55.45]],"id":3805784}],"con":true,"img":false}]}
{"op":"mcm","clk":"5347986663","pt":1646211889841,"mc":[{"id":"1.195453751","rc":[{"atl":[[850,2.19],[960,2]],"id":522754},{"atl":[[75,9.9],[80,2]],"id":522747},{"atl":[[560,2],[450,4.14]],"id":522748},{"atl":[[550,3.36],[630,2]],"id":522751},{"atl":[[590,3.13],[670,2]],"id":3805731}],"con":true,"img":false}]}
{"op":"mcm","clk":"5347986680","pt":1646211890098,"mc":[{"id":"1.195453751","rc":[{"atb":[[12.5,0],[13,4.95]],"id":522746},{"atb":[[85,9.73],[90,9.9],[110,0],[120,6.28]],"id":522748},{"atb":[[6.8,0]],"id":522752},{"atb":[[46,9.9],[60,7.64]],"id":3805772},{"atl":[[130,4.95]],"id":3805772}],"con":true,"img":false}]}
{"op":"mcm","clk":"5347986689","pt":1646211890201,"mc":[{"id":"1.195453751","rc":[{"atb":[[44,14.71],[55,0]],"id":3805772},{"atl":[[160,0],[120,0]],"id":3805772}],"con":true,"img":false}]}
{"op":"mcm","clk":"5347986713","pt":1646211890511,"mc":[{"id":"1.195453751","rc":[{"atb":[[44,0]],"id":3805772},{"atl":[[150,0]],"id":3805772}],"con":true,"img":false}]}
{"op":"mcm","clk":"5347986721","pt":1646211890614,"mc":[{"id":"1.195453751","rc":[{"atb":[[46,24.62]],"id":3805772}],"con":true,"img":false}]}
{"op":"mcm","clk":"5347986735","pt":1646211890816,"mc":[{"id":"1.195453751","rc":[{"atb":[[6.4,75.37]],"id":522752},{"atl":[[170,9.9]],"id":3805772}],"con":true,"img":false}]}
{"op":"mcm","clk":"5347986740","pt":1646211890918,"mc":[{"id":"1.195453751","rc":[{"atb":[[6.4,34.31],[5.8,59.1]],"id":522752},{"atl":[[310,8.06]],"id":3805772},{"atb":[[34,9.9],[38,4.28],[42,4.95],[30,0]],"id":522745}],"con":true,"img":false}]}
{"op":"mcm","clk":"5347986762","pt":1646211891329,"mc":[{"id":"1.195453751","rc":[{"atb":[[34,24.62],[19.5,0],[42,8.82]],"id":522745}],"con":true,"img":false}]}
{"op":"mcm","clk":"5347986798","pt":1646211892000,"mc":[{"id":"1.195453751","rc":[{"atb":[[38,0]],"id":522745}],"con":true,"img":false}]}
{"op":"mcm","clk":"5347986811","pt":1646211892307,"mc":[{"id":"1.195453751","rc":[{"atb":[[470,0.33]],"id":7607472}],"con":true,"img":false}]}
{"op":"mcm","clk":"5347986844","pt":1646211893025,"mc":[{"id":"1.195453751","rc":[{"atb":[[270,0]],"id":7607472}],"con":true,"img":false}]}
{"op":"mcm","clk":"5347986886","pt":1646211893802,"mc":[{"id":"1.195453751","rc":[{"atl":[[36,9.48]],"id":522746}],"con":true,"img":false}]}
{"op":"mcm","clk":"5347986893","pt":1646211893905,"mc":[{"id":"1.195453751","rc":[{"atl":[[850,0]],"id":522754}],"con":true,"img":false}]}
{"op":"mcm","clk":"5347986897","pt":1646211894008,"mc":[{"id":"1.195453751","rc":[{"atl":[[960,3.96]],"id":522754}],"con":true,"img":false}]}
{"op":"mcm","clk":"5347986930","pt":1646211894622,"mc":[{"id":"1.195453751","rc":[{"atl":[[42,0]],"id":522746}],"con":true,"img":false}]}
{"op":"mcm","clk":"5347986950","pt":1646211894931,"mc":[{"id":"1.195453751","rc":[{"atl":[[55,7.89]],"id":522747},{"atl":[[22,7.54]],"id":3805740}],"con":true,"img":false}]}
{"op":"mcm","clk":"5347986960","pt":1646211895137,"mc":[{"id":"1.195453751","rc":[{"atl":[[55,20.94]],"id":522746}],"con":true,"img":false}]}
{"op":"mcm","clk":"5347986967","pt":1646211895240,"mc":[{"id":"1.195453751","rc":[{"atl":[[44,9.9]],"id":522746},{"atl":[[310,0.51]],"id":522748}],"con":true,"img":false}]}
{"op":"mcm","clk":"5347986984","pt":1646211895549,"mc":[{"id":"1.195453751","rc":[{"atl":[[260,5.56]],"id":522751},{"atl":[[22,33.5],[23,7.2]],"id":3805740}],"con":true,"img":false}]}
{"op":"mcm","clk":"5347986987","pt":1646211895602,"mc":[{"id":"1.195453751","rc":[{"atl":[[44,8.64]],"id":522750}],"con":true,"img":false}]}
{"op":"mcm","clk":"5347986995","pt":1646211895810,"mc":[{"id":"1.195453751","rc":[{"atl":[[440,4.66]],"id":522748}],"con":true,"img":false}]}
{"op":"mcm","clk":"5347986999","pt":1646211895912,"mc":[{"id":"1.195453751","rc":[{"atl":[[60,0]],"id":522747},{"atl":[[450,0]],"id":522748},{"atl":[[23,0]],"id":3805740}],"con":true,"img":false}]}
{"op":"mcm","clk":"5347987006","pt":1646211896016,"mc":[{"id":"1.195453751","rc":[{"atl":[[440,4.3]],"id":522748},{"atb":[[21,21.43],[46,9.9]],"id":3805772}],"con":true,"img":false}]}
{"op":"mcm","clk":"5347987010","pt":1646211896121,"mc":[{"id":"1.195453751","rc":[{"atb":[[3.55,67.12]],"id":3805784}],"con":true,"img":false}]}
{"op":"mcm","clk":"5347987017","pt":1646211896323,"mc":[{"id":"1.195453751","rc":[{"atl":[[70,0],[75,35.22]],"id":522747},{"atl":[[46,0]],"id":522750},{"atl":[[540,0]],"id":522751}],"con":true,"img":false}]}
{"op":"mcm","clk":"5347987040","pt":1646211896734,"mc":[{"id":"1.195453751","rc":[{"atb":[[34,9.9],[18.5,19.96]],"id":522745}],"con":true,"img":false}]}
{"op":"mcm","clk":"5347987044","pt":1646211896843,"mc":[{"id":"1.195453751","rc":[{"atl":[[48,0],[55,39.9]],"id":522750},{"atl":[[550,0],[630,5]],"id":522751}],"con":true,"img":false}]}
{"op":"mcm","clk":"5347987051","pt":1646211897041,"mc":[{"id":"1.195453751","rc":[{"atb":[[3.5,0]],"id":3805784}],"con":true,"img":false}]}
{"op":"mcm","clk":"5347987078","pt":1646211897505,"mc":[{"id":"1.195453751","rc":[{"atb":[[3.35,9.9],[3.15,150.6]],"id":3805784},{"atl":[[630,2]],"id":522751}],"con":true,"img":false}]}
{"op":"mcm","clk":"5347987112","pt":1646211898428,"mc":[{"id":"1.195453751","rc":[{"atl":[[8.6,4.95],[9.2,19.33],[10,0],[9.4,9.9]],"id":522749}],"con":true,"img":false}]}
{"op":"mcm","clk":"5347987129","pt":1646211898942,"mc":[{"id":"1.195453751","rc":[{"atl":[[8.6,25.81],[11.5,0],[9.4,53.38]],"id":522749}],"con":true,"img":false}]}
{"op":"mcm","clk":"5347987163","pt":1646211899614,"mc":[{"id":"1.195453751","rc":[{"atl":[[9.2,0]],"id":522749}],"con":true,"img":false}]}
{"op":"mcm","clk":"5347987171","pt":1646211899921,"mc":[{"id":"1.195453751","rc":[{"atl":[[780,2.43],[960,2]],"id":522754}],"con":true,"img":false}]}
{"op":"mcm","clk":"5347987211","pt":1646211900746,"mc":[{"id":"1.195453751","rc":[{"atl":[[100,0]],"id":3805772}],"con":true,"img":false}]}
{"op":"mcm","clk":"5347987237","pt":1646211901420,"mc":[{"id":"1.195453751","rc":[{"atl":[[130,6.18]],"id":3805772}],"con":true,"img":false}]}
{"op":"mcm","clk":"5347987249","pt":1646211901732,"mc":[{"id":"1.195453751","rc":[{"atl":[[75,9.9],[80,18.58]],"id":522747}],"con":true,"img":false}]}
{"op":"mcm","clk":"5347987256","pt":1646211901937,"mc":[{"id":"1.195453751","rc":[{"atb":[[6.6,31.03]],"id":522752}],"con":true,"img":false}]}
{"op":"mcm","clk":"5347987264","pt":1646211902142,"mc":[{"id":"1.195453751","rc":[{"atl":[[80,25.94],[55,9.9]],"id":522750}],"con":true,"img":false}]}
{"op":"mcm","clk":"5347987267","pt":1646211902247,"mc":[{"id":"1.195453751","rc":[{"atb":[[2.06,0]],"id":3805784},{"atb":[[9.4,11.9]],"id":3805772}],"con":true,"img":false}]}
{"op":"mcm","clk":"5347987273","pt":1646211902349,"mc":[{"id":"1.195453751","rc":[{"atb":[[2.16,86.21]],"id":3805784},{"atb":[[40,0],[24,10.14]],"id":522742},{"atb":[[12.5,0]],"id":3805772}],"con":true,"img":false}]}
{"op":"mcm","clk":"5347987288","pt":1646211902714,"mc":[{"id":"1.195453751","rc":[{"atb":[[6.4,4.95]],"id":522752}],"con":true,"img":false}]}
{"op":"mcm","clk":"5347987386","pt":1646211904217,"mc":[{"id":"1.195453751","rc":[{"atl":[[12,100.14]],"id":522749}],"con":true,"img":false}]}
{"op":"mcm","clk":"5347987391","pt":1646211904320,"mc":[{"id":"1.195453751","rc":[{"atl":[[9.4,9.9]],"id":522749}],"con":true,"img":false}]}
{"op":"mcm","clk":"5347987449","pt":1646211905350,"mc":[{"id":"1.195453751","rc":[{"atl":[[780,0],[960,3.99]],"id":522754}],"con":true,"img":false}]}
{"op":"mcm","clk":"5347987479","pt":1646211906021,"mc":[{"id":"1.195453751","rc":[{"atl":[[15.5,15.88]],"id":3805740}],"con":true,"img":false}]}
{"op":"mcm","clk":"5347987522","pt":1646211907048,"mc":[{"id":"1.195453751","rc":[{"atl":[[22,25.95]],"id":3805740}],"con":true,"img":false}]}
{"op":"mcm","clk":"5347987569","pt":1646211907935,"mc":[{"id":"1.195453751","rc":[{"atl":[[280,6.88]],"id":522751}],"con":true,"img":false}]}
{"op":"mcm","clk":"5347987583","pt":1646211908236,"mc":[{"id":"1.195453751","rc":[{"atl":[[380,4.95]],"id":522754},{"atl":[[260,0.61],[250,4.95]],"id":522751}],"con":true,"img":false}]}
{"op":"mcm","clk":"5347987615","pt":1646211908850,"mc":[{"id":"1.195453751","rc":[{"atl":[[380,5.37]],"id":522754},{"atl":[[250,5.59]],"id":522751}],"con":true,"img":false}]}
{"op":"mcm","clk":"5347987619","pt":1646211908953,"mc":[{"id":"1.195453751","rc":[{"atl":[[260,5.56]],"id":522751}],"con":true,"img":false}]}
{"op":"mcm","clk":"5347987623","pt":1646211909057,"mc":[{"id":"1.195453751","rc":[{"atl":[[250,0.63]],"id":522751}],"con":true,"img":false}]}
{"op":"mcm","clk":"5347987644","pt":1646211909627,"mc":[{"id":"1.195453751","rc":[{"atl":[[760,0]],"id":522754},{"atl":[[260,4.95],[250,0]],"id":522751}],"con":true,"img":false}]}
{"op":"mcm","clk":"5347987674","pt":1646211910249,"mc":[{"id":"1.195453751","rc":[{"atl":[[960,2]],"id":522754}],"con":true,"img":false}]}
{"op":"mcm","clk":"5347987680","pt":1646211910346,"mc":[{"id":"1.195453751","rc":[{"atl":[[260,5.56]],"id":522751}],"con":true,"img":false}]}
{"op":"mcm","clk":"5347987805","pt":1646211912876,"mc":[{"id":"1.195453751","rc":[{"atb":[[3.35,0],[3.55,0],[3.5,4.95],[3.3,9.9]],"id":3805784},{"atl":[[380,0]],"id":522754},{"atl":[[310,0],[320,0],[340,4.95]],"id":522748},{"atl":[[260,0],[280,11.84]],"id":522751}],"con":true,"img":false}]}
{"op":"mcm","clk":"5347987819","pt":1646211913136,"mc":[{"id":"1.195453751","rc":[{"atl":[[280,4.95],[630,5.07]],"id":522751}],"con":true,"img":false}]}
{"op":"mcm","clk":"5347987833","pt":1646211913445,"mc":[{"id":"1.195453751","rc":[{"atl":[[980,1.97]],"id":522754},{"atl":[[560,5.46],[440,0]],"id":522748}],"con":true,"img":false}]}
{"op":"mcm","clk":"5347987838","pt":1646211913555,"mc":[{"id":"1.195453751","rc":[{"atb":[[3.45,4.95],[3.15,165.31],[3.25,9.9],[3.5,0],[3.3,0]],"id":3805784},{"atl":[[960,0],[980,3.97]],"id":522754},{"atl":[[620,0.25]],"id":522751}],"con":true,"img":false}]}
{"op":"mcm","clk":"5347987841","pt":1646211913650,"mc":[{"id":"1.195453751","rc":[{"atl":[[1000,0.15]],"id":522754},{"atl":[[430,0.37]],"id":522748}],"con":true,"img":false}]}
{"op":"mcm","clk":"5347987849","pt":1646211913857,"mc":[{"id":"1.195453751","rc":[{"atl":[[340,0],[350,4.95]],"id":522748},{"atl":[[280,0],[290,4.95],[630,2]],"id":522751}],"con":true,"img":false}]}
{"op":"mcm","clk":"5347987856","pt":1646211914061,"mc":[{"id":"1.195453751","rc":[{"atb":[[5.8,55.83],[6.6,28.31]],"id":522752},{"atb":[[9.8,0],[8.8,0]],"id":522753}],"con":true,"img":false}]}
{"op":"mcm","clk":"5347987860","pt":1646211914165,"mc":[{"id":"1.195453751","rc":[{"atl":[[370,4.95]],"id":522754}],"con":true,"img":false}]}
{"op":"mcm","clk":"5347987868","pt":1646211914269,"mc":[{"id":"1.195453751","rc":[{"atl":[[36,4.52],[38,4.95],[44,0],[46,9.9]],"id":522746}],"con":true,"img":false}]}
{"op":"mcm","clk":"5347987871","pt":1646211914372,"mc":[{"id":"1.195453751","rc":[{"atb":[[3.45,0],[3.25,0]],"id":3805784},{"atl":[[36,0]],"id":522746}],"con":true,"img":false}]}
{"op":"mcm","clk":"5347987874","pt":1646211914476,"mc":[{"id":"1.195453751","rc":[{"atl":[[44,0],[46,4.95],[55,0],[60,9.9]],"id":522750}],"con":true,"img":false}]}
{"op":"mcm","clk":"5347987878","pt":1646211914579,"mc":[{"id":"1.195453751","rc":[{"atb":[[8.2,26.97],[7.4,63.63]],"id":522753}],"con":true,"img":false}]}
{"op":"mcm","clk":"5347987886","pt":1646211914786,"mc":[{"id":"1.195453751","rc":[{"atb":[[2.3,254.52],[3.15,17.43]],"id":3805784},{"atl":[[46,23.99],[55,2]],"id":522746},{"atb":[[6.4,7.67],[5.7,3.26]],"id":522752},{"atb":[[9.6,2.72],[8.6,3.26]],"id":522753}],"con":true,"img":false}]}
{"op":"mcm","clk":"5347987900","pt":1646211915047,"mc":[{"id":"1.195453751","rc":[{"atb":[[3.5,4.95],[3.3,9.9]],"id":3805784},{"atl":[[370,0]],"id":522754},{"atl":[[50,3.23]],"id":522746}],"con":true,"img":false}]}
{"op":"mcm","clk":"5347987906","pt":1646211915149,"mc":[{"id":"1.195453751","rc":[{"atl":[[380,4.95]],"id":522754},{"atl":[[55,2.93]],"id":522750}],"con":true,"img":false}]}
{"op":"mcm","clk":"5347987919","pt":1646211915463,"mc":[{"id":"1.195453751","rc":[{"atb":[[8,0],[7.4,9.9]],"id":522753}],"con":true,"img":false}]}
{"op":"mcm","clk":"5347987939","pt":1646211915765,"mc":[{"id":"1.195453751","rc":[{"atl":[[80,2],[60,31.99]],"id":522750}],"con":true,"img":false}]}
{"op":"mcm","clk":"5347987958","pt":1646211916074,"mc":[{"id":"1.195453751","rc":[{"atb":[[3.45,4.95],[3.25,9.9],[3.5,0],[3.3,0]],"id":3805784},{"atl":[[38,0],[40,4.95],[46,14.08],[48,9.9]],"id":522746},{"atl":[[65,9.9],[46,0],[48,4.95],[60,22.08]],"id":522750},{"atb":[[80,4.95],[46,0]],"id":3805731},{"atb":[[32,9.9],[34,0],[40,4.95],[42,0]],"id":522745}],"con":true,"img":false}]}
{"op":"mcm","clk":"5347987970","pt":1646211916280,"mc":[{"id":"1.195453751","rc":[{"atl":[[80,0],[95,2]],"id":522750}],"con":true,"img":false}]}
{"op":"mcm","clk":"5347987982","pt":1646211916488,"mc":[{"id":"1.195453751","rc":[{"atb":[[10,17.61],[9.2,0],[10.5,4.95],[9.4,9.9]],"id":3805747},{"atb":[[85,12.46],[90,9.9],[110,0],[120,6.28]],"id":522751}],"con":true,"img":false}]}
{"op":"mcm","clk":"5347987995","pt":1646211916748,"mc":[{"id":"1.195453751","rc":[{"atb":[[3.45,0],[3.2,9.9],[3.4,4.95],[3.25,0]],"id":3805784},{"atb":[[80,0],[60,2.68]],"id":3805731},{"atb":[[34,4.8]],"id":522745}],"con":true,"img":false}]}
{"op":"mcm","clk":"5347988000","pt":1646211916852,"mc":[{"id":"1.195453751","rc":[{"atb":[[75,4.95],[55,9.9]],"id":3805731}],"con":true,"img":false}]}
{"op":"mcm","clk":"5347988002","pt":1646211916955,"mc":[{"id":"1.195453751","rc":[{"atb":[[8.2,2.72],[11,15.85],[9.4,47.2]],"id":3805747},{"atl":[[65,0],[48,0]],"id":522750}],"con":true,"img":false}]}
{"op":"mcm","clk":"5347988009","pt":1646211917059,"mc":[{"id":"1.195453751","rc":[{"atl":[[50,4.95]],"id":522750}],"con":true,"img":false}]}
{"op":"mcm","clk":"5347988015","pt":1646211917158,"mc":[{"id":"1.195453751","rc":[{"atb":[[65,2.47],[18,12.79],[21,2.72]],"id":3805731},{"atb":[[32,24.62],[18.5,2.72]],"id":522745}],"con":true,"img":false}]}
{"op":"mcm","clk":"5347988039","pt":1646211917774,"mc":[{"id":"1.195453751","rc":[{"atb":[[10,0]],"id":3805747}],"con":true,"img":false}]}
{"op":"mcm","clk":"5347988043","pt":1646211917877,"mc":[{"id":"1.195453751","rc":[{"atb":[[18,3.26]],"id":3805731}],"con":true,"img":false}]}
{"op":"mcm","clk":"5347988049","pt":1646211917979,"mc":[{"id":"1.195453751","rc":[{"atb":[[60,0]],"id":3805731}],"con":true,"img":false}]}
{"op":"mcm","clk":"5347988086","pt":1646211918752,"mc":[{"id":"1.195453751","rc":[{"atl":[[980,2],[1000,2.1]],"id":522754},{"atl":[[630,5.1]],"id":522751}],"con":true,"img":false}]}
{"op":"mcm","clk":"5347988096","pt":1646211918957,"mc":[{"id":"1.195453751","rc":[{"atb":[[3.2,0],[3.35,4.95],[3.4,0],[3.15,27.34]],"id":3805784},{"atl":[[40,0],[42,4.95],[48,0],[50,13.14]],"id":522746}],"con":true,"img":false}]}
{"op":"mcm","clk":"5347988100","pt":1646211919061,"mc":[{"id":"1.195453751","rc":[{"atl":[[290,0],[300,4.95]],"id":522751}],"con":true,"img":false}]}
{"op":"mcm","clk":"5347988109","pt":1646211919266,"mc":[{"id":"1.195453751","rc":[{"atl":[[390,4.95]],"id":522754}],"con":true,"img":false}]}
{"op":"mcm","clk":"5347988115","pt":1646211919370,"mc":[{"id":"1.195453751","rc":[{"atl":[[380,0]],"id":522754}],"con":true,"img":false}]}
{"op":"mcm","clk":"5347988142","pt":1646211919782,"mc":[{"id":"1.195453751","rc":[{"atl":[[300,0],[310,4.95]],"id":522751}],"con":true,"img":false}]}
{"op":"mcm","clk":"5347988145","pt":1646211919885,"mc":[{"id":"1.195453751","rc":[{"atl":[[390,5.36]],"id":522754},{"atl":[[610,0.26]],"id":522751}],"con":true,"img":false}]}
{"op":"mcm","clk":"5347988152","pt":1646211919986,"mc":[{"id":"1.195453751","rc":[{"atl":[[46,0],[50,40.04]],"id":522746}],"con":true,"img":false}]}
{"op":"mcm","clk":"5347988197","pt":1646211920660,"mc":[{"id":"1.195453751","rc":[{"atl":[[620,0]],"id":522751}],"con":true,"img":false}]}
{"op":"mcm","clk":"5347988205","pt":1646211920762,"mc":[{"id":"1.195453751","rc":[{"atl":[[1000,1.95]],"id":522754}],"con":true,"img":false}]}
{"op":"mcm","clk":"5347988226","pt":1646211921175,"mc":[{"id":"1.195453751","rc":[{"atl":[[600,0.26]],"id":522751},{"atl":[[310,6.06],[370,2]],"id":3805772}],"con":true,"img":false}]}
{"op":"mcm","clk":"5347988240","pt":1646211921478,"mc":[{"id":"1.195453751","rc":[{"atl":[[370,0],[380,4.95]],"id":522741}],"con":true,"img":false}]}
{"op":"mcm","clk":"5347988267","pt":1646211922048,"mc":[{"id":"1.195453751","rc":[{"atl":[[610,0]],"id":522751}],"con":true,"img":false}]}
{"op":"mcm","clk":"5347988300","pt":1646211922664,"mc":[{"id":"1.195453751","rc":[{"atl":[[390,0]],"id":522754}],"con":true,"img":false}]}
{"op":"mcm","clk":"5347988306","pt":1646211922768,"mc":[{"id":"1.195453751","rc":[{"atl":[[980,0],[1000,3.95]],"id":522754}],"con":true,"img":false}]}
{"op":"mcm","clk":"5347988327","pt":1646211923384,"mc":[{"id":"1.195453751","rc":[{"atl":[[1000,2]],"id":522754}],"con":true,"img":false}]}
{"op":"mcm","clk":"5347988330","pt":1646211923486,"mc":[{"id":"1.195453751","rc":[{"atl":[[990,0.15]],"id":522754}],"con":true,"img":false}]}
{"op":"mcm","clk":"5347988368","pt":1646211924156,"mc":[{"id":"1.195453751","rc":[{"atl":[[310,5.46]],"id":522751}],"con":true,"img":false}]}
{"op":"mcm","clk":"5347988377","pt":1646211924361,"mc":[{"id":"1.195453751","rc":[{"atl":[[420,0.37]],"id":522748}],"con":true,"img":false}]}
{"op":"mcm","clk":"5347988389","pt":1646211924880,"mc":[{"id":"1.195453751","rc":[{"atl":[[560,2],[430,4.96]],"id":522748}],"con":true,"img":false}]}
{"op":"mcm","clk":"5347988394","pt":1646211924984,"mc":[{"id":"1.195453751","rc":[{"atl":[[600,0]],"id":522751}],"con":true,"img":false}]}
{"op":"mcm","clk":"5347988400","pt":1646211925087,"mc":[{"id":"1.195453751","rc":[{"atl":[[50,13.14],[55,14.21]],"id":522746}],"con":true,"img":false}]}
{"op":"mcm","clk":"5347988405","pt":1646211925189,"mc":[{"id":"1.195453751","rc":[{"atl":[[430,4.59]],"id":522748},{"atb":[[8.2,67.57]],"id":522753}],"con":true,"img":false}]}
{"op":"mcm","clk":"5347988412","pt":1646211925396,"mc":[{"id":"1.195453751","rc":[{"atb":[[2.96,51.27]],"id":3805784},{"atl":[[390,4.95]],"id":522754}],"con":true,"img":false}]}
{"op":"mcm","clk":"5347988416","pt":1646211925452,"mc":[{"id":"1.195453751","rc":[{"atb":[[2.3,102.45]],"id":3805784},{"atl":[[630,2]],"id":522751}],"con":true,"img":false}]}
{"op":"mcm","clk":"5347988421","pt":1646211925557,"mc":[{"id":"1.195453751","rc":[{"atl":[[330,5.99]],"id":522751}],"con":true,"img":false}]}
{"op":"mcm","clk":"5347988425","pt":1646211925659,"mc":[{"id":"1.195453751","rc":[{"atl":[[40,4.06]],"id":522746},{"atl":[[9.6,9.9],[8.6,0],[8.8,4.95],[9.4,0]],"id":522749},{"atb":[[70,4.95],[75,0],[50,9.9],[55,0]],"id":3805731}],"con":true,"img":false}]}
{"op":"mcm","clk":"5347988428","pt":1646211925769,"mc":[{"id":"1.195453751","rc":[{"atl":[[1000,3.97]],"id":522754},{"atl":[[50,8.19]],"id":522750}],"con":true,"img":false}]}
{"op":"mcm","clk":"5347988432","pt":1646211925879,"mc":[{"id":"1.195453751","rc":[{"atb":[[3.35,72.41]],"id":3805784},{"atl":[[380,0.41]],"id":522754}],"con":true,"img":false}]}
{"op":"mcm","clk":"5347988450","pt":1646211926274,"mc":[{"id":"1.195453751","rc":[{"atb":[[3.35,67.46],[2.98,9.9]],"id":3805784},{"atl":[[390,0]],"id":522754},{"atl":[[50,3.23]],"id":522750},{"atl":[[310,0.51],[350,4.95]],"id":522751}],"con":true,"img":false}]}
{"op":"mcm","clk":"5347988456","pt":1646211926380,"mc":[{"id":"1.195453751","rc":[{"atl":[[42,0],[44,4.95],[50,3.23],[55,24.12]],"id":522746},{"atl":[[350,0],[360,4.95]],"id":522748},{"atl":[[9.4,11.4]],"id":522749},{"atl":[[75,9.9],[55,7.89]],"id":522750},{"atl":[[310,0]],"id":522751},{"atb":[[70,0],[50,0]],"id":3805731}],"con":true,"img":false}]}
{"op":"mcm","clk":"5347988460","pt":1646211926491,"mc":[{"id":"1.195453751","rc":[{"atl":[[40,0],[50,0]],"id":522746},{"atl":[[55,4.95]],"id":522750}],"con":true,"img":false}]}
{"op":"mcm","clk":"5347988474","pt":1646211926688,"mc":[{"id":"1.195453751","rc":[{"atb":[[3.15,12.63]],"id":3805784},{"atl":[[990,0]],"id":522754}],"con":true,"img":false}]}
{"op":"mcm","clk":"5347988477","pt":1646211926790,"mc":[{"id":"1.195453751","rc":[{"atl":[[9.6,41.58],[12,9.09]],"id":522749}],"con":true,"img":false}]}
{"op":"mcm","clk":"5347988486","pt":1646211926996,"mc":[{"id":"1.195453751","rc":[{"atl":[[340,4.95]],"id":522754}],"con":true,"img":false}]}
{"op":"mcm","clk":"5347988488","pt":1646211927101,"mc":[{"id":"1.195453751","rc":[{"atl":[[340,0.46]],"id":522751},{"atb":[[70,4.95],[50,9.9]],"id":3805731}],"con":true,"img":false}]}
{"op":"mcm","clk":"5347988503","pt":1646211927259,"mc":[{"id":"1.195453751","rc":[{"atl":[[50,3.23]],"id":522746}],"con":true,"img":false}]}
{"op":"mcm","clk":"5347988506","pt":1646211927360,"mc":[{"id":"1.195453751","rc":[{"atb":[[42,3.86]],"id":522745}],"con":true,"img":false}]}
{"op":"mcm","clk":"5347988522","pt":1646211927670,"mc":[{"id":"1.195453751","rc":[{"atl":[[340,0],[360,4.95]],"id":522754}],"con":true,"img":false}]}
{"op":"mcm","clk":"5347988527","pt":1646211927770,"mc":[{"id":"1.195453751","rc":[{"atb":[[75,2.14],[50,21.93]],"id":3805731}],"con":true,"img":false}]}
{"op":"mcm","clk":"5347988531","pt":1646211927873,"mc":[{"id":"1.195453751","rc":[{"atb":[[32,9.9],[34,19.31]],"id":522745}],"con":true,"img":false}]}
{"op":"mcm","clk":"5347988537","pt":1646211928080,"mc":[{"id":"1.195453751","rc":[{"atb":[[34,14.5]],"id":522745}],"con":true,"img":false}]}
{"op":"mcm","clk":"5347988550","pt":1646211928493,"mc":[{"id":"1.195453751","rc":[{"atb":[[65,0]],"id":3805731}],"con":true,"img":false}]}
{"op":"mcm","clk":"5347988599","pt":1646211929896,"mc":[{"id":"1.195453751","rc":[{"atb":[[17.5,14.71]],"id":522750}],"con":true,"img":false}]}
{"op":"mcm","clk":"5347988605","pt":1646211930000,"mc":[{"id":"1.195453751","rc":[{"atl":[[6,0],[6.8,60.04],[6.6,9.9],[5.9,37.3]],"id":3805784},{"atb":[[16,18.78],[18,4.95]],"id":522750}],"con":true,"img":false}]}
{"op":"mcm","clk":"5347988622","pt":1646211930369,"mc":[{"id":"1.195453751","rc":[{"atl":[[320,0.49]],"id":522751}],"con":true,"img":false}]}
{"op":"mcm","clk":"5347988625","pt":1646211930470,"mc":[{"id":"1.195453751","rc":[{"atb":[[17.5,0],[18,19.66]],"id":522750}],"con":true,"img":false}]}
{"op":"mcm","clk":"5347988635","pt":1646211930677,"mc":[{"id":"1.195453751","rc":[{"atl":[[330,0],[350,10.64]],"id":522751}],"con":true,"img":false}]}
{"op":"mcm","clk":"5347988644","pt":1646211930887,"mc":[{"id":"1.195453751","rc":[{"atl":[[36,4.95]],"id":522746}],"con":true,"img":false}]}
{"op":"mcm","clk":"5347988647","pt":1646211930990,"mc":[{"id":"1.195453751","rc":[{"atl":[[55,14.21]],"id":522746}],"con":true,"img":false}]}
{"op":"mcm","clk":"5347988650","pt":1646211931094,"mc":[{"id":"1.195453751","rc":[{"atl":[[340,0]],"id":522751}],"con":true,"img":false}]}
{"op":"mcm","clk":"5347988660","pt":1646211931356,"mc":[{"id":"1.195453751","rc":[{"atl":[[50,15.45]],"id":522746}],"con":true,"img":false}]}
{"op":"mcm","clk":"5347988661","pt":1646211931462,"mc":[{"id":"1.195453751","rc":[{"atl":[[360,0],[370,4.95]],"id":522754},{"atl":[[55,2]],"id":522746}],"con":true,"img":false}]}
{"op":"mcm","clk":"5347988676","pt":1646211931675,"mc":[{"id":"1.195453751","rc":[{"atl":[[36,0],[38,4.95],[44,0],[46,9.9]],"id":522746}],"con":true,"img":false}]}
{"op":"mcm","clk":"5347988689","pt":1646211931877,"mc":[{"id":"1.195453751","rc":[{"atl":[[370,5.38]],"id":522754}],"con":true,"img":false}]}
{"op":"mcm","clk":"5347988694","pt":1646211932083,"mc":[{"id":"1.195453751","rc":[{"atb":[[3.35,77.37],[3.15,2.72],[2.98,0],[3.55,4.95]],"id":3805784}],"con":true,"img":false}]}
{"op":"mcm","clk":"5347988714","pt":1646211932499,"mc":[{"id":"1.195453751","rc":[{"atl":[[38,0],[46,0]],"id":522746}],"con":true,"img":false}]}
{"op":"mcm","clk":"5347988724","pt":1646211932600,"mc":[{"id":"1.195453751","rc":[{"atl":[[380,0]],"id":522754},{"atl":[[75,0],[46,4.95],[55,0],[60,31.99]],"id":522750}],"con":true,"img":false}]}
{"op":"mcm","clk":"5347988756","pt":1646211933168,"mc":[{"id":"1.195453751","rc":[{"atl":[[1000,2]],"id":522754}],"con":true,"img":false}]}
{"op":"mcm","clk":"5347988760","pt":1646211933275,"mc":[{"id":"1.195453751","rc":[{"atl":[[36,4.95],[44,9.9]],"id":522746}],"con":true,"img":false}]}
{"op":"mcm","clk":"5347988796","pt":1646211934091,"mc":[{"id":"1.195453751","rc":[{"atl":[[370,4.95]],"id":522754}],"con":true,"img":false}]}
{"op":"mcm","clk":"5347988801","pt":1646211934194,"mc":[{"id":"1.195453751","rc":[{"atl":[[370,0],[380,4.95]],"id":522754}],"con":true,"img":false}]}
{"op":"mcm","clk":"5347988807","pt":1646211934296,"mc":[{"id":"1.195453751","rc":[{"atl":[[16,9.9],[17.5,0],[14,4.95],[15.5,10.93]],"id":3805740}],"con":true,"img":false}]}
{"op":"mcm","clk":"5347988811","pt":1646211934398,"mc":[{"id":"1.195453751","rc":[{"atl":[[910,2],[1000,0]],"id":522754}],"con":true,"img":false}]}
{"op":"mcm","clk":"5347988828","pt":1646211934708,"mc":[{"id":"1.195453751","rc":[{"atl":[[290,4.95],[360,0]],"id":522748},{"atl":[[14,17.15]],"id":3805740}],"con":true,"img":false}]}
{"op":"mcm","clk":"5347988833","pt":1646211934764,"mc":[{"id":"1.195453751","rc":[{"atl":[[410,0.38]],"id":522748},{"atl":[[16,40.88],[22,0]],"id":3805740}],"con":true,"img":false}]}
{"op":"mcm","clk":"5347988837","pt":1646211934865,"mc":[{"id":"1.195453751","rc":[{"atl":[[380,0],[390,4.95],[900,0.17]],"id":522754},{"atl":[[75,0],[46,4.95],[55,2.93],[60,9.9]],"id":522747}],"con":true,"img":false}]}
{"op":"mcm","clk":"5347988854","pt":1646211935277,"mc":[{"id":"1.195453751","rc":[{"atl":[[910,4.19]],"id":522754},{"atl":[[80,2],[46,8.47],[60,22.12]],"id":522747},{"atl":[[420,5.15],[430,0]],"id":522748}],"con":true,"img":false}]}
{"op":"mcm","clk":"5347988864","pt":1646211935496,"mc":[{"id":"1.195453751","rc":[{"atl":[[420,4.77]],"id":522748},{"atl":[[15.5,0]],"id":3805740}],"con":true,"img":false}]}
{"op":"mcm","clk":"5347988873","pt":1646211935788,"mc":[{"id":"1.195453751","rc":[{"atb":[[2.96,3.26]],"id":3805784},{"atl":[[630,5.18],[350,4.95]],"id":522751}],"con":true,"img":false}]}
{"op":"mcm","clk":"5347988879","pt":1646211935890,"mc":[{"id":"1.195453751","rc":[{"atb":[[3.15,72.9]],"id":3805784}],"con":true,"img":false}]}
{"op":"mcm","clk":"5347988881","pt":1646211935993,"mc":[{"id":"1.195453751","rc":[{"atl":[[55,0]],"id":522747}],"con":true,"img":false}]}
{"op":"mcm","clk":"5347988885","pt":1646211936097,"mc":[{"id":"1.195453751","rc":[{"atl":[[36,9.48]],"id":522746}],"con":true,"img":false}]}
{"op":"mcm","clk":"5347988890","pt":1646211936199,"mc":[{"id":"1.195453751","rc":[{"atl":[[46,8.47]],"id":522750}],"con":true,"img":false}]}
{"op":"mcm","clk":"5347988895","pt":1646211936304,"mc":[{"id":"1.195453751","rc":[{"atb":[[3.55,67.12]],"id":3805784}],"con":true,"img":false}]}
{"op":"mcm","clk":"5347988899","pt":1646211936405,"mc":[{"id":"1.195453751","rc":[{"atl":[[390,5.36]],"id":522754}],"con":true,"img":false}]}
{"op":"mcm","clk":"5347988905","pt":1646211936713,"mc":[{"id":"1.195453751","rc":[{"atb":[[130,6.18],[90,14.71],[95,9.9],[120,0]],"id":522754},{"atb":[[34,0],[36,9.48],[28,14.95],[29,9.9]],"id":522755}],"con":true,"img":false}]}
{"op":"mcm","clk":"5347988908","pt":1646211936766,"mc":[{"id":"1.195453751","rc":[{"atl":[[50,12.21]],"id":522746},{"atl":[[8.8,25.28]],"id":522749},{"atl":[[380,0],[370,4.95]],"id":522741}],"con":true,"img":false}]}
{"op":"mcm","clk":"5347988915","pt":1646211936979,"mc":[{"id":"1.195453751","rc":[{"atb":[[3.35,9.9]],"id":3805784},{"atl":[[50,0]],"id":522750}],"con":true,"img":false}]}
{"op":"mcm","clk":"5347988923","pt":1646211937078,"mc":[{"id":"1.195453751","rc":[{"atl":[[900,0]],"id":522754}],"con":true,"img":false}]}
{"op":"mcm","clk":"5347988934","pt":1646211937383,"mc":[{"id":"1.195453751","rc":[{"atl":[[95,23.21]],"id":522750}],"con":true,"img":false}]}
{"op":"mcm","clk":"5347988937","pt":1646211937484,"mc":[{"id":"1.195453751","rc":[{"atl":[[60,9.9]],"id":522750}],"con":true,"img":false}]}
{"op":"mcm","clk":"5347988939","pt":1646211937586,"mc":[{"id":"1.195453751","rc":[{"atl":[[910,2]],"id":522754},{"atl":[[9.4,0]],"id":522749}],"con":true,"img":false}]}
{"op":"mcm","clk":"5347988947","pt":1646211937895,"mc":[{"id":"1.195453751","rc":[{"atl":[[8,0],[7.6,15.15]],"id":3805784},{"atl":[[910,0],[1000,2]],"id":522754},{"atb":[[8,0],[9,12.5]],"id":522750}],"con":true,"img":false}]}
{"op":"mcm","clk":"5347988950","pt":1646211938101,"mc":[{"id":"1.195453751","rc":[{"atl":[[70,2.29],[75,4.95],[90,0],[95,9.9]],"id":522755},{"atb":[[5.6,32.16],[6.2,0],[5.5,109.69],[5.3,4.95],[4.9,9.9]],"id":522749},{"atl":[[9.6,9.9],[12,99.34]],"id":522749},{"atb":[[6.4,2.72],[5.8,45.92],[6.6,33.26],[5.9,9.9]],"id":522752}],"con":true,"img":false}]}
{"op":"mcm","clk":"5347988952","pt":1646211938205,"mc":[{"id":"1.195453751","rc":[{"atl":[[370,0],[380,4.95]],"id":522741}],"con":true,"img":false}]}
{"op":"mcm","clk":"5347988955","pt":1646211938411,"mc":[{"id":"1.195453751","rc":[{"atl":[[1000,4.01]],"id":522754}],"con":true,"img":false}]}
{"op":"mcm","clk":"5347988956","pt":1646211938514,"mc":[{"id":"1.195453751","rc":[{"atl":[[95,31.15]],"id":522755},{"atb":[[5.5,29.59],[5.3,90.34]],"id":522749},{"atb":[[5.8,0],[5.9,50.97]],"id":522752}],"con":true,"img":false}]}
{"op":"mcm","clk":"5347988958","pt":1646211938567,"mc":[{"id":"1.195453751","rc":[{"atl":[[210,2]],"id":522755},{"atl":[[46,0],[60,12.21]],"id":522747}],"con":true,"img":false}]}
{"op":"mcm","clk":"5347988962","pt":1646211938740,"mc":[{"id":"1.195453751","rc":[{"atl":[[65,9.9],[48,4.95]],"id":522747}],"con":true,"img":false}]}
{"op":"mcm","clk":"5347988966","pt":1646211938776,"mc":[{"id":"1.195453751","rc":[{"atl":[[1000,2.01]],"id":522754},{"atb":[[5.5,32.86],[6,2.72]],"id":522749},{"atl":[[710,2]],"id":522751},{"atb":[[65,4.95],[46,0],[48,9.9],[60,2.68]],"id":3805772}],"con":true,"img":false}]}
{"op":"mcm","clk":"5347988967","pt":1646211938882,"mc":[{"id":"1.195453751","rc":[{"atl":[[630,3.18]],"id":522751}],"con":true,"img":false}]}
{"op":"mcm","clk":"5347988979","pt":1646211939190,"mc":[{"id":"1.195453751","rc":[{"atl":[[1000,0]],"id":522754}],"con":true,"img":false}]}
{"op":"mcm","clk":"5347988983","pt":1646211939293,"mc":[{"id":"1.195453751","rc":[{"atb":[[70,2.29],[21,2.72],[48,28.13]],"id":3805772}],"con":true,"img":false}]}
{"op":"mcm","clk":"5347988991","pt":1646211939506,"mc":[{"id":"1.195453751","rc":[{"atl":[[55,2.93]],"id":522747},{"atb":[[32,0],[34,24.41],[40,0],[42,8.82]],"id":522745}],"con":true,"img":false}]}
{"op":"mcm","clk":"5347989006","pt":1646211939808,"mc":[{"id":"1.195453751","rc":[{"atl":[[16,9.9],[24,61.94]],"id":3805740}],"con":true,"img":false}]}
{"op":"mcm","clk":"5347989015","pt":1646211940013,"mc":[{"id":"1.195453751","rc":[{"atb":[[34,9.9],[18.5,19.96]],"id":522745}],"con":true,"img":false}]}
{"op":"mcm","clk":"5347989021","pt":1646211940118,"mc":[{"id":"1.195453751","rc":[{"atb":[[3.55,4.95]],"id":3805784},{"atb":[[60,0]],"id":3805772}],"con":true,"img":false}]}
{"op":"mcm","clk":"5347989026","pt":1646211940221,"mc":[{"id":"1.195453751","rc":[{"atb":[[3.35,0],[3.55,0],[3.5,4.95],[3.3,9.9]],"id":3805784},{"atl":[[290,0],[300,4.95]],"id":522748}],"con":true,"img":false}]}
{"op":"mcm","clk":"5347989060","pt":1646211940793,"mc":[{"id":"1.195453751","rc":[{"atb":[[3.3,31.99]],"id":3805784}],"con":true,"img":false}]}
{"op":"mcm","clk":"5347989142","pt":1646211942601,"mc":[{"id":"1.195453751","rc":[{"atl":[[390,0],[400,4.95]],"id":522754},{"atb":[[18,0],[18.5,4.95]],"id":522747}],"con":true,"img":false}]}
{"op":"mcm","clk":"5347989152","pt":1646211942805,"mc":[{"id":"1.195453751","rc":[{"atl":[[390,4.95]],"id":522741},{"atl":[[130,0],[140,4.95],[180,9.9]],"id":522745}],"con":true,"img":false}]}
{"op":"mcm","clk":"5347989157","pt":1646211942908,"mc":[{"id":"1.195453751","rc":[{"atl":[[380,0]],"id":522741}],"con":true,"img":false}]}
{"op":"mcm","clk":"5347989169","pt":1646211943217,"mc":[{"id":"1.195453751","rc":[{"atl":[[180,21.18]],"id":522745}],"con":true,"img":false}]}
{"op":"mcm","clk":"5347989172","pt":1646211943319,"mc":[{"id":"1.195453751","rc":[{"atl":[[400,5.35]],"id":522754},{"atl":[[360,2]],"id":522745}],"con":true,"img":false}]}
{"op":"mcm","clk":"5347989187","pt":1646211943784,"mc":[{"id":"1.195453751","rc":[{"atl":[[130,4.95],[140,0],[170,9.9],[180,11.28]],"id":522745}],"con":true,"img":false}]}
{"op":"mcm","clk":"5347989198","pt":1646211944195,"mc":[{"id":"1.195453751","rc":[{"atl":[[400,4.95],[410,4.95]],"id":522754}],"con":true,"img":false}]}
{"op":"mcm","clk":"5347989199","pt":1646211944299,"mc":[{"id":"1.195453751","rc":[{"atl":[[400,0]],"id":522754}],"con":true,"img":false}]}
{"op":"mcm","clk":"5347989222","pt":1646211944920,"mc":[{"id":"1.195453751","rc":[{"atl":[[410,5.34]],"id":522754}],"con":true,"img":false}]}
{"op":"mcm","clk":"5347989227","pt":1646211945124,"mc":[{"id":"1.195453751","rc":[{"atl":[[400,0.39]],"id":522748}],"con":true,"img":false}]}
{"op":"mcm","clk":"5347989238","pt":1646211945484,"mc":[{"id":"1.195453751","rc":[{"atl":[[410,0.38]],"id":522754},{"atl":[[46,3.52]],"id":522747}],"con":true,"img":false}]}
{"op":"mcm","clk":"5347989246","pt":1646211945690,"mc":[{"id":"1.195453751","rc":[{"atl":[[410,0]],"id":522754},{"atl":[[410,5.35],[420,0]],"id":522748}],"con":true,"img":false}]}
{"op":"mcm","clk":"5347989249","pt":1646211945794,"mc":[{"id":"1.195453751","rc":[{"atl":[[410,4.96]],"id":522748}],"con":true,"img":false}]}
{"op":"mcm","clk":"5347989257","pt":1646211946002,"mc":[{"id":"1.195453751","rc":[{"atl":[[55,13.03],[60,0]],"id":522747}],"con":true,"img":false}]}
{"op":"mcm","clk":"5347989268","pt":1646211946308,"mc":[{"id":"1.195453751","rc":[{"atl":[[55,10.09]],"id":522747}],"con":true,"img":false}]}
{"op":"mcm","clk":"5347989272","pt":1646211946514,"mc":[{"id":"1.195453751","rc":[{"atb":[[3.5,68.36]],"id":3805784},{"atl":[[1000,0.15]],"id":522754}],"con":true,"img":false}]}
{"op":"mcm","clk":"5347989277","pt":1646211946622,"mc":[{"id":"1.195453751","rc":[{"atl":[[9.6,0],[8.6,9.9],[8.8,20.32],[7.8,4.95]],"id":522749}],"con":true,"img":false}]}
{"op":"mcm","clk":"5347989302","pt":1646211947083,"mc":[{"id":"1.195453751","rc":[{"atl":[[7.8,28.26]],"id":522749}],"con":true,"img":false}]}
{"op":"mcm","clk":"5347989309","pt":1646211947290,"mc":[{"id":"1.195453751","rc":[{"atb":[[3.3,9.9]],"id":3805784},{"atl":[[380,4.95]],"id":522754},{"atl":[[9,9.9],[8.2,4.95]],"id":522749}],"con":true,"img":false}]}
{"op":"mcm","clk":"5347989311","pt":1646211947392,"mc":[{"id":"1.195453751","rc":[{"atl":[[8.6,0],[7.8,23.31]],"id":522749}],"con":true,"img":false}]}
{"op":"mcm","clk":"5347989332","pt":1646211947907,"mc":[{"id":"1.195453751","rc":[{"atl":[[8.8,0],[7.8,0]],"id":522749}],"con":true,"img":false}]}
{"op":"mcm","clk":"5347989349","pt":1646211948314,"mc":[{"id":"1.195453751","rc":[{"atl":[[12,9.09],[8.8,64.86]],"id":522749}],"con":true,"img":false}]}
{"op":"mcm","clk":"5347989363","pt":1646211948622,"mc":[{"id":"1.195453751","rc":[{"atb":[[5.5,95.41],[5.3,4.95]],"id":522749},{"atl":[[11.5,11.4]],"id":522749}],"con":true,"img":false}]}
{"op":"mcm","clk":"5347989387","pt":1646211949088,"mc":[{"id":"1.195453751","rc":[{"atl":[[8.8,0]],"id":522749}],"con":true,"img":false}]}
{"op":"mcm","clk":"5347989636","pt":1646211953326,"mc":[{"id":"1.195453751","rc":[{"atl":[[170,22.01],[180,0]],"id":522745}],"con":true,"img":false}]}
{"op":"mcm","clk":"5347989639","pt":1646211953431,"mc":[{"id":"1.195453751","rc":[{"atl":[[380,5.37]],"id":522754}],"con":true,"img":false}]}
{"op":"mcm","clk":"5347989663","pt":1646211954004,"mc":[{"id":"1.195453751","rc":[{"atb":[[2.3,0],[1.85,0],[1.95,0]],"id":3805784},{"atb":[[5.1,0],[3.55,0],[3.05,0]],"id":3805747},{"atb":[[16,0],[22,0],[60,2.72]],"id":522754},{"atb":[[5.8,0],[7.6,0],[14,0]],"id":522755},{"atb":[[5.8,0],[7.6,0],[14,25.3]],"id":522746},{"atb":[[9.6,0],[19,12.58],[7.6,0]],"id":522747},{"atb":[[18,0],[42,0],[13,0]],"id":522748},{"atb":[[5.5,65.81],[3.25,0],[3.75,0]],"id":522749},{"atb":[[16,9.9],[6.4,0],[8.4,0]],"id":522750},{"atb":[[27,0],[13.5,0],[9.4,0]],"id":522751},{"atb":[[7.8,0],[14.5,0],[5.9,0]],"id":3805731},{"atb":[[4,33.33],[2.8,0],[3,0]],"id":522752},{"atb":[[8,0],[4,0],[5,0]],"id":3805762},{"atb":[[6.2,0],[4.1,0],[3.55,0]],"id":522753},{"atb":[[32,0],[10.5,0],[15.5,0]],"id":522741},{"atb":[[24,4.35],[12,0],[8.8,0]],"id":522742},{"atb":[[18,0],[42,0],[13,0]],"id":522743},{"atb":[[16,0],[6.4,0],[8.4,0]],"id":3805772},{"atb":[[3.6,0],[6.4,0],[4.2,0]],"id":3805740},{"atb":[[260,1.75],[160,4.95],[460,0]],"id":7607472},{"atb":[[12,0],[6.8,0],[5.4,0]],"id":522745}],"con":true,"img":false}]}
{"op":"mcm","clk":"5347989673","pt":1646211954345,"mc":[{"id":"1.195453751","rc":[{"atl":[[1000,0]],"id":522754}],"con":true,"img":false}]}
{"op":"mcm","clk":"5347989676","pt":1646211954417,"mc":[{"id":"1.195453751","rc":[{"atb":[[260,0],[160,10.15]],"id":7607472}],"con":true,"img":false}]}
{"op":"mcm","clk":"5347989712","pt":1646211955193,"mc":[{"id":"1.195453751","rc":[{"atl":[[290,0.55]],"id":522748}],"con":true,"img":false}]}
{"op":"mcm","clk":"5347989740","pt":1646211955709,"mc":[{"id":"1.195453751","rc":[{"atl":[[400,5.55]],"id":522748}],"con":true,"img":false}]}
{"op":"mcm","clk":"5347989749","pt":1646211955812,"mc":[{"id":"1.195453751","rc":[{"atl":[[410,0]],"id":522748}],"con":true,"img":false}]}
{"op":"mcm","clk":"5347989751","pt":1646211955916,"mc":[{"id":"1.195453751","rc":[{"atl":[[380,0.41],[370,4.95]],"id":522754},{"atl":[[400,5.16]],"id":522748},{"atl":[[270,4.95],[350,0]],"id":522751}],"con":true,"img":false}]}
{"op":"mcm","clk":"5347989765","pt":1646211956324,"mc":[{"id":"1.195453751","rc":[{"atl":[[270,5.54]],"id":522751}],"con":true,"img":false}]}
{"op":"mcm","clk":"5347989771","pt":1646211956529,"mc":[{"id":"1.195453751","rc":[{"atl":[[380,0]],"id":522754}],"con":true,"img":false}]}
{"op":"mcm","clk":"5347989776","pt":1646211956633,"mc":[{"id":"1.195453751","rc":[{"atl":[[370,0],[390,4.95]],"id":522754},{"atl":[[270,0.58],[280,4.95]],"id":522751}],"con":true,"img":false}]}
{"op":"mcm","clk":"5347989797","pt":1646211957044,"mc":[{"id":"1.195453751","rc":[{"atl":[[270,0],[630,0],[320,6.46]],"id":522751}],"con":true,"img":false}]}
{"op":"mcm","clk":"5347989800","pt":1646211957097,"mc":[{"id":"1.195453751","rc":[{"atl":[[8.2,26.97]],"id":522749}],"con":true,"img":false}]}
{"op":"mcm","clk":"5347989812","pt":1646211957304,"mc":[{"id":"1.195453751","rc":[{"atl":[[390,0.4]],"id":522754},{"atl":[[290,0],[300,0],[310,4.95]],"id":522748}],"con":true,"img":false}]}
{"op":"mcm","clk":"5347989819","pt":1646211957405,"mc":[{"id":"1.195453751","rc":[{"atl":[[400,4.95]],"id":522754}],"con":true,"img":false}]}
{"op":"mcm","clk":"5347989837","pt":1646211957713,"mc":[{"id":"1.195453751","rc":[{"atl":[[280,5.52],[320,0]],"id":522751}],"con":true,"img":false}]}
{"op":"mcm","clk":"5347989842","pt":1646211957818,"mc":[{"id":"1.195453751","rc":[{"atl":[[11.5,0]],"id":522749}],"con":true,"img":false}]}
{"op":"mcm","clk":"5347989849","pt":1646211958024,"mc":[{"id":"1.195453751","rc":[{"atl":[[300,0.52]],"id":522748}],"con":true,"img":false}]}
{"op":"mcm","clk":"5347989854","pt":1646211958126,"mc":[{"id":"1.195453751","rc":[{"atl":[[390,0]],"id":522754}],"con":true,"img":false}]}
{"op":"mcm","clk":"5347989856","pt":1646211958226,"mc":[{"id":"1.195453751","rc":[{"atl":[[410,4.95]],"id":522754}],"con":true,"img":false}]}
{"op":"mcm","clk":"5347989859","pt":1646211958329,"mc":[{"id":"1.195453751","rc":[{"atl":[[400,0]],"id":522754},{"atl":[[12,63.9]],"id":522749}],"con":true,"img":false}]}
{"op":"mcm","clk":"5347989880","pt":1646211958841,"mc":[{"id":"1.195453751","rc":[{"atl":[[410,5.34]],"id":522754}],"con":true,"img":false}]}
{"op":"mcm","clk":"5347989902","pt":1646211959208,"mc":[{"id":"1.195453751","rc":[{"atl":[[410,0.38]],"id":522754},{"atb":[[160,4.95],[120,29.93]],"id":7607472}],"con":true,"img":false}]}
{"op":"mcm","clk":"5347989920","pt":1646211959622,"mc":[{"id":"1.195453751","rc":[{"atl":[[410,0]],"id":522754}],"con":true,"img":false}]}
{"op":"mcm","clk":"5347989973","pt":1646211960553,"mc":[{"id":"1.195453751","rc":[{"atl":[[1000,0.15]],"id":522754}],"con":true,"img":false}]}
{"op":"mcm","clk":"5347989976","pt":1646211960654,"mc":[{"id":"1.195453751","rc":[{"atb":[[2.16,0],[2.34,74.63]],"id":3805784},{"atb":[[9.2,12.2],[7.4,0]],"id":522747},{"atl":[[70,2],[80,0]],"id":522747},{"atb":[[36,0],[27,3.85]],"id":522743},{"atb":[[8.2,0],[9.4,11.9]],"id":522745}],"con":true,"img":false}]}
{"op":"mcm","clk":"5347989989","pt":1646211960811,"mc":[{"id":"1.195453751","rc":[{"atl":[[420,4.95]],"id":522754}],"con":true,"img":false}]}
{"op":"mcm","clk":"5347990053","pt":1646211961941,"mc":[{"id":"1.195453751","rc":[{"atl":[[420,0]],"id":522754},{"atl":[[300,0]],"id":522748},{"atl":[[280,0],[290,4.95]],"id":522751}],"con":true,"img":false}]}
{"op":"mcm","clk":"5347990072","pt":1646211962454,"mc":[{"id":"1.195453751","rc":[{"atb":[[3.45,9.9],[3.5,63.41],[3.3,0],[3.65,4.95]],"id":3805784},{"atl":[[560,5.7],[400,0]],"id":522748}],"con":true,"img":false}]}
{"op":"mcm","clk":"5347990082","pt":1646211962613,"mc":[{"id":"1.195453751","rc":[{"atl":[[310,5.46]],"id":522748},{"atl":[[700,0.22]],"id":522751}],"con":true,"img":false}]}
{"op":"mcm","clk":"5347990090","pt":1646211962816,"mc":[{"id":"1.195453751","rc":[{"atl":[[1000,2.15]],"id":522754},{"atl":[[65,11.9]],"id":522747}],"con":true,"img":false}]}
{"op":"mcm","clk":"5347990092","pt":1646211962918,"mc":[{"id":"1.195453751","rc":[{"atl":[[70,0]],"id":522747}],"con":true,"img":false}]}
{"op":"mcm","clk":"5347990095","pt":1646211963020,"mc":[{"id":"1.195453751","rc":[{"atb":[[3.45,80.09],[3.15,2.72],[3.65,64.78]],"id":3805784},{"atl":[[420,4.95]],"id":522754}],"con":true,"img":false}]}
{"op":"mcm","clk":"5347990101","pt":1646211963330,"mc":[{"id":"1.195453751","rc":[{"atl":[[560,2]],"id":522748},{"atb":[[90,4.95],[50,12.02]],"id":3805731}],"con":true,"img":false}]}
{"op":"mcm","clk":"5347990108","pt":1646211963432,"mc":[{"id":"1.195453751","rc":[{"atl":[[420,5.32]],"id":522754}],"con":true,"img":false}]}
{"op":"mcm","clk":"5347990128","pt":1646211963819,"mc":[{"id":"1.195453751","rc":[{"atb":[[3.5,0]],"id":3805784},{"atb":[[70,16.97],[90,6.73],[50,0]],"id":3805731}],"con":true,"img":false}]}
{"op":"mcm","clk":"5347990147","pt":1646211964230,"mc":[{"id":"1.195453751","rc":[{"atl":[[1000,2]],"id":522754}],"con":true,"img":false}]}
{"op":"mcm","clk":"5347990168","pt":1646211964640,"mc":[{"id":"1.195453751","rc":[{"atb":[[75,0]],"id":3805731}],"con":true,"img":false}]}
{"op":"mcm","clk":"5347990201","pt":1646211965257,"mc":[{"id":"1.195453751","rc":[{"atl":[[420,0]],"id":522754}],"con":true,"img":false}]}
{"op":"mcm","clk":"5347990211","pt":1646211965521,"mc":[{"id":"1.195453751","rc":[{"atl":[[330,6.29]],"id":522748}],"con":true,"img":false}]}
{"op":"mcm","clk":"5347990228","pt":1646211966034,"mc":[{"id":"1.195453751","rc":[{"atl":[[990,0.15]],"id":522754}],"con":true,"img":false}]}
{"op":"mcm","clk":"5347990234","pt":1646211966137,"mc":[{"id":"1.195453751","rc":[{"atl":[[290,5.5]],"id":522751}],"con":true,"img":false}]}
{"op":"mcm","clk":"5347990257","pt":1646211966650,"mc":[{"id":"1.195453751","rc":[{"atl":[[410,4.95]],"id":522754}],"con":true,"img":false}]}
{"op":"mcm","clk":"5347990264","pt":1646211966755,"mc":[{"id":"1.195453751","rc":[{"atl":[[310,0],[320,4.95]],"id":522748}],"con":true,"img":false}]}
{"op":"mcm","clk":"5347990269","pt":1646211966909,"mc":[{"id":"1.195453751","rc":[{"atl":[[700,0],[710,4.92]],"id":522751}],"con":true,"img":false}]}
{"op":"mcm","clk":"5347990284","pt":1646211967277,"mc":[{"id":"1.195453751","rc":[{"atb":[[2.36,97.93],[1.98,271.82],[1.88,302.71]],"id":3805784},{"atb":[[3.6,102.45],[3.1,126.85],[5.2,31.71]],"id":3805747},{"atb":[[65,2.08],[16.5,17.18],[23,12.1]],"id":522754},{"atl":[[410,5.34],[1000,4.07]],"id":522754},{"atb":[[5.8,55.49],[7.6,40.36],[14,10.24]],"id":522755},{"atb":[[5.6,57.91],[7.2,42.96],[13,16.05]],"id":522746},{"atb":[[7.2,42.96],[18,7.83],[9.2,44.68]],"id":522747},{"atb":[[17,16.64],[38,6.87],[12,24.21]],"id":522748},{"atl":[[560,5.7],[330,0]],"id":522748},{"atb":[[5.3,35.93],[3.15,123.9],[3.65,100.52]],"id":522749},{"atb":[[16,18.78],[6.4,49.33],[8.4,35.99]],"id":522750},{"atb":[[27,5.12],[13.5,21.3],[9.4,31.71]],"id":522751},{"atb":[[8,38.05],[6,53.27],[15,9.51]],"id":3805731},{"atb":[[2.82,146.36],[4.1,42.96],[3.05,129.94]],"id":522752},{"atb":[[5.1,64.97],[8.2,18.49],[4.1,85.93]],"id":3805762},{"atb":[[6.2,25.61],[4.1,85.93],[3.55,104.46]],"id":522753},{"atb":[[9.8,30.27],[29,4.75],[14.5,19.73]],"id":522741},{"atb":[[24,10.14],[12,24.21],[8.8,34.15]],"id":522742},{"atb":[[18.5,15.22],[44,6.36],[13.5,21.3]],"id":522743},{"atb":[[3.45,108.73],[3.95,90.29],[5.9,27.18]],"id":3805740},{"atb":[[16,8.87],[6.4,49.33],[8.4,35.99]],"id":3805772},{"atb":[[280,0.95],[180,1.48],[480,0.27]],"id":7607472},{"atb":[[12,12.1],[6.8,45.93],[5.4,60.54]],"id":522745}],"con":true,"img":false}]}
{"op":"mcm","clk":"5347990296","pt":1646211967536,"mc":[{"id":"1.195453751","rc":[{"atl":[[320,5.44]],"id":522748}],"con":true,"img":false}]}
{"op":"mcm","clk":"5347990305","pt":1646211967742,"mc":[{"id":"1.195453751","rc":[{"atb":[[3.45,9.9],[3.15,147.43]],"id":3805784},{"atl":[[9,0],[8.2,0]],"id":522749}],"con":true,"img":false}]}
{"op":"mcm","clk":"5347990311","pt":1646211967847,"mc":[{"id":"1.195453751","rc":[{"atl":[[9.2,9.9],[8.4,4.95]],"id":522749},{"atb":[[280,1.96],[120,12.63],[490,0.32]],"id":7607472}],"con":true,"img":false}]}
{"op":"mcm","clk":"5347990328","pt":1646211968159,"mc":[{"id":"1.195453751","rc":[{"atl":[[990,0]],"id":522754},{"atl":[[560,2]],"id":522748},{"atl":[[12,9.09],[13,142.79]],"id":522749}],"con":true,"img":false}]}
{"op":"mcm","clk":"5347990342","pt":1646211968468,"mc":[{"id":"1.195453751","rc":[{"atb":[[65,9.9],[70,12.02],[85,4.95],[90,0]],"id":3805731}],"con":true,"img":false}]}
{"op":"mcm","clk":"5347990350","pt":1646211968523,"mc":[{"id":"1.195453751","rc":[{"atl":[[11.5,11.4]],"id":522749},{"atb":[[70,0]],"id":3805731},{"atb":[[470,0]],"id":7607472}],"con":true,"img":false}]}
{"op":"mcm","clk":"5347990356","pt":1646211968629,"mc":[{"id":"1.195453751","rc":[{"atl":[[1000,2]],"id":522754},{"atb":[[21,14.74]],"id":3805731}],"con":true,"img":false}]}
{"op":"mcm","clk":"5347990370","pt":1646211968937,"mc":[{"id":"1.195453751","rc":[{"atb":[[280,0.95],[470,0.95]],"id":7607472}],"con":true,"img":false}]}
{"op":"mcm","clk":"5347990378","pt":1646211969146,"mc":[{"id":"1.195453751","rc":[{"atb":[[70,2.29]],"id":3805731}],"con":true,"img":false}]}
