{"op":"mcm","clk":"5346195393","pt":1646178339823,"mc":[{"id":"1.195453700","marketDefinition":{"bspMarket":false,"turnInPlayEnabled":false,"persistenceEnabled":false,"marketBaseRate":7.0,"eventId":"31272494","eventTypeId":"4339","numberOfWinners":1,"bettingType":"ODDS","marketType":"EXACTA","marketTime":"2022-03-02T08:31:00.000Z","suspendTime":"2022-03-02T08:31:00.000Z","bspReconciled":false,"complete":true,"inPlay":false,"crossMatching":false,"runnersVoidable":false,"numberOfActiveRunners":56,"betDelay":0,"status":"OPEN","runners":[{"status":"ACTIVE","sortPriority":1,"id":41419585,"name":"1 - 2"},{"status":"ACTIVE","sortPriority":2,"id":41419586,"name":"1 - 3"},{"status":"ACTIVE","sortPriority":3,"id":41419587,"name":"1 - 4"},{"status":"ACTIVE","sortPriority":4,"id":41419588,"name":"1 - 5"},{"status":"ACTIVE","sortPriority":5,"id":41419589,"name":"1 - 6"},{"status":"ACTIVE","sortPriority":6,"id":41419590,"name":"1 - 7"},{"status":"ACTIVE","sortPriority":7,"id":41419591,"name":"1 - 8"},{"status":"ACTIVE","sortPriority":8,"id":41419592,"name":"2 - 1"},{"status":"ACTIVE","sortPriority":9,"id":41419593,"name":"2 - 3"},{"status":"ACTIVE","sortPriority":10,"id":41419594,"name":"2 - 4"},{"status":"ACTIVE","sortPriority":11,"id":41419595,"name":"2 - 5"},{"status":"ACTIVE","sortPriority":12,"id":41419596,"name":"2 - 6"},{"status":"ACTIVE","sortPriority":13,"id":41419597,"name":"2 - 7"},{"status":"ACTIVE","sortPriority":14,"id":41419598,"name":"2 - 8"},{"status":"ACTIVE","sortPriority":15,"id":41419599,"name":"3 - 1"},{"status":"ACTIVE","sortPriority":16,"id":41419600,"name":"3 - 2"},{"status":"ACTIVE","sortPriority":17,"id":41419601,"name":"3 - 4"},{"status":"ACTIVE","sortPriority":18,"id":41419602,"name":"3 - 5"},{"status":"ACTIVE","sortPriority":19,"id":41419603,"name":"3 - 6"},{"status":"ACTIVE","sortPriority":20,"id":41419604,"name":"3 - 7"},{"status":"ACTIVE","sortPriority":21,"id":41419605,"name":"3 - 8"},{"status":"ACTIVE","sortPriority":22,"id":41419606,"name":"4 - 1"},{"status":"ACTIVE","sortPriority":23,"id":41419607,"name":"4 - 2"},{"status":"ACTIVE","sortPriority":24,"id":41419608,"name":"4 - 3"},{"status":"ACTIVE","sortPriority":25,"id":41419609,"name":"4 - 5"},{"status":"ACTIVE","sortPriority":26,"id":41419610,"name":"4 - 6"},{"status":"ACTIVE","sortPriority":27,"id":41419611,"name":"4 - 7"},{"status":"ACTIVE","sortPriority":28,"id":41419612,"name":"4 - 8"},{"status":"ACTIVE","sortPriority":29,"id":41419613,"name":"5 - 1"},{"status":"ACTIVE","sortPriority":30,"id":41419614,"name":"5 - 2"},{"status":"ACTIVE","sortPriority":31,"id":41419615,"name":"5 - 3"},{"status":"ACTIVE","sortPriority":32,"id":41419616,"name":"5 - 4"},{"status":"ACTIVE","sortPriority":33,"id":41419617,"name":"5 - 6"},{"status":"ACTIVE","sortPriority":34,"id":41419618,"name":"5 - 7"},{"status":"ACTIVE","sortPriority":35,"id":41419619,"name":"5 - 8"},{"status":"ACTIVE","sortPriority":36,"id":41419620,"name":"6 - 1"},{"status":"ACTIVE","sortPriority":37,"id":41419621,"name":"6 - 2"},{"status":"ACTIVE","sortPriority":38,"id":41419622,"name":"6 - 3"},{"status":"ACTIVE","sortPriority":39,"id":41419623,"name":"6 - 4"},{"status":"ACTIVE","sortPriority":40,"id":41419624,"name":"6 - 5"},{"status":"ACTIVE","sortPriority":41,"id":41419625,"name":"6 - 7"},{"status":"ACTIVE","sortPriority":42,"id":41419626,"name":"6 - 8"},{"status":"ACTIVE","sortPriority":43,"id":41419627,"name":"7 - 1"},{"status":"ACTIVE","sortPriority":44,"id":41419628,"name":"7 - 2"},{"status":"ACTIVE","sortPriority":45,"id":41419629,"name":"7 - 3"},{"status":"ACTIVE","sortPriority":46,"id":41419630,"name":"7 - 4"},{"status":"ACTIVE","sortPriority":47,"id":41419631,"name":"7 - 5"},{"status":"ACTIVE","sortPriority":48,"id":41419632,"name":"7 - 6"},{"status":"ACTIVE","sortPriority":49,"id":41419633,"name":"7 - 8"},{"status":"ACTIVE","sortPriority":50,"id":41419634,"name":"8 - 1"},{"status":"ACTIVE","sortPriority":51,"id":41419635,"name":"8 - 2"},{"status":"ACTIVE","sortPriority":52,"id":41419636,"name":"8 - 3"},{"status":"ACTIVE","sortPriority":53,"id":41419637,"name":"8 - 4"},{"status":"ACTIVE","sortPriority":54,"id":41419638,"name":"8 - 5"},{"status":"ACTIVE","sortPriority":55,"id":41419639,"name":"8 - 6"},{"status":"ACTIVE","sortPriority":56,"id":41419640,"name":"8 - 7"}],"regulators":["MR_INT"],"venue":"Traralgon","countryCode":"AU","discountAllowed":true,"timezone":"Australia/Sydney","openDate":"2022-03-02T08:31:00.000Z","version":4382480593,"name":"Exacta","eventName":"Traralgon (AUS) 2nd Mar"},"rc":[],"con":true,"img":false}]}
{"op":"mcm","clk":"5346203713","pt":1646178502733,"mc":[{"id":"1.195453700","rc":[{"atb":[[17,16.63],[48,4.24],[24,8.67]],"id":41419609},{"atb":[[65,3.11],[19,14.78],[28,7.39]],"id":41419607},{"atb":[[17,16.63],[48,4.24],[24,8.67]],"id":41419605},{"atb":[[16,17.74],[44,4.64],[22,9.5]],"id":41419603},{"atb":[[17.5,16.12],[50,4.07],[25,8.31]],"id":41419611},{"atb":[[65,3.11],[19,14.78],[28,7.39]],"id":41419593},{"atb":[[9.6,23.2],[5.3,61.87],[6.6,35.63]],"id":41419591},{"atb":[[5.7,42.46],[8.4,26.96],[4.7,71.91]],"id":41419589},{"atb":[[9.6,23.2],[5.3,61.87],[6.6,35.63]],"id":41419587},{"atb":[[17,16.63],[48,4.24],[24,8.67]],"id":41419601},{"atb":[[16,13.3],[7.4,41.57],[9.4,23.75]],"id":41419599},{"atb":[[70,2.89],[19.5,14.38],[29,7.12]],"id":41419597},{"atb":[[65,3.11],[19,14.78],[28,7.39]],"id":41419595},{"atb":[[17,16.63],[48,4.24],[24,8.67]],"id":41419608},{"atb":[[16,13.3],[7.4,41.57],[9.4,23.75]],"id":41419606},{"atb":[[17.5,16.12],[50,4.07],[25,8.31]],"id":41419604},{"atb":[[17,16.63],[48,4.24],[24,8.67]],"id":41419602},{"atb":[[6.2,51.17],[8.2,27.71],[13,16.63]],"id":41419585},{"atb":[[17,16.63],[48,4.24],[24,8.67]],"id":41419612},{"atb":[[16,17.74],[44,4.64],[22,9.5]],"id":41419610},{"atb":[[8.6,35.01],[19,11.08],[11.5,19]],"id":41419592},{"atb":[[10,22.17],[5.5,59.12],[7,33.26]],"id":41419590},{"atb":[[9.6,23.2],[5.3,61.87],[6.6,35.63]],"id":41419588},{"atb":[[9.6,23.2],[5.3,61.87],[6.6,35.63]],"id":41419586},{"atb":[[65,3.11],[19,14.78],[28,7.39]],"id":41419600},{"atb":[[65,3.11],[19,14.78],[28,7.39]],"id":41419598},{"atb":[[17.5,16.12],[50,4.07],[25,8.31]],"id":41419596},{"atb":[[65,3.11],[19,14.78],[28,7.39]],"id":41419594}],"con":true,"img":false}]}
{"op":"mcm","clk":"5346203715","pt":1646178502896,"mc":[{"id":"1.195453700","rc":[{"atb":[[17,16.63],[48,4.24],[24,8.67]],"id":41419638},{"atb":[[16,13.3],[7.4,41.57],[9.4,23.75]],"id":41419634},{"atb":[[16,17.74],[44,4.64],[22,9.5]],"id":41419617},{"atb":[[16,13.3],[7.4,41.57],[9.4,23.75]],"id":41419613},{"atb":[[42,4.86],[21,9.97],[15.5,18.35]],"id":41419622},{"atb":[[17.5,16.12],[50,4.07],[25,8.31]],"id":41419618},{"atb":[[17.5,16.12],[50,4.07],[25,8.31]],"id":41419630},{"atb":[[42,4.86],[21,9.97],[15.5,18.35]],"id":41419626},{"atb":[[16,17.74],[44,4.64],[22,9.5]],"id":41419639},{"atb":[[65,3.11],[19,14.78],[28,7.39]],"id":41419635},{"atb":[[65,3.11],[19,14.78],[28,7.39]],"id":41419614},{"atb":[[42,4.86],[21,9.97],[15.5,18.35]],"id":41419623},{"atb":[[17,16.63],[48,4.24],[24,8.67]],"id":41419619},{"atb":[[17.5,16.12],[50,4.07],[25,8.31]],"id":41419631},{"atb":[[16.5,12.87],[9.6,23.2],[7.6,40.31]],"id":41419627},{"atb":[[17.5,16.12],[50,4.07],[25,8.31]],"id":41419640},{"atb":[[17,16.63],[48,4.24],[24,8.67]],"id":41419636},{"atb":[[17,16.63],[48,4.24],[24,8.67]],"id":41419615},{"atb":[[42,4.86],[21,9.97],[15.5,18.35]],"id":41419624},{"atb":[[6.2,51.17],[8.2,27.71],[13,16.63]],"id":41419620},{"atb":[[16,17.74],[44,4.64],[22,9.5]],"id":41419632},{"atb":[[70,2.89],[19.5,14.38],[29,7.12]],"id":41419628},{"atb":[[17,16.63],[48,4.24],[24,8.67]],"id":41419637},{"atb":[[17,16.63],[48,4.24],[24,8.67]],"id":41419616},{"atb":[[16,17.74],[44,4.64],[22,9.5]],"id":41419625},{"atb":[[17,16.63],[48,4.24],[24,8.67]],"id":41419621},{"atb":[[17.5,16.12],[50,4.07],[25,8.31]],"id":41419633},{"atb":[[17.5,16.12],[50,4.07],[25,8.31]],"id":41419629}],"con":true,"img":false}]}
{"op":"mcm","clk":"5346401377","pt":1646182002779,"mc":[{"id":"1.195453700","marketDefinition":{"bspMarket":false,"turnInPlayEnabled":false,"persistenceEnabled":false,"marketBaseRate":7.0,"eventId":"31272494","eventTypeId":"4339","numberOfWinners":1,"bettingType":"ODDS","marketType":"EXACTA","marketTime":"2022-03-02T08:31:00.000Z","suspendTime":"2022-03-02T08:31:00.000Z","bspReconciled":false,"complete":true,"inPlay":false,"crossMatching":false,"runnersVoidable":false,"numberOfActiveRunners":56,"betDelay":0,"status":"OPEN","runners":[{"status":"ACTIVE","sortPriority":1,"id":41419585,"name":"1 - 2"},{"status":"ACTIVE","sortPriority":2,"id":41419586,"name":"1 - 3"},{"status":"ACTIVE","sortPriority":3,"id":41419587,"name":"1 - 4"},{"status":"ACTIVE","sortPriority":4,"id":41419588,"name":"1 - 5"},{"status":"ACTIVE","sortPriority":5,"id":41419589,"name":"1 - 6"},{"status":"ACTIVE","sortPriority":6,"id":41419590,"name":"1 - 7"},{"status":"ACTIVE","sortPriority":7,"id":41419591,"name":"1 - 8"},{"status":"ACTIVE","sortPriority":8,"id":41419592,"name":"2 - 1"},{"status":"ACTIVE","sortPriority":9,"id":41419593,"name":"2 - 3"},{"status":"ACTIVE","sortPriority":10,"id":41419594,"name":"2 - 4"},{"status":"ACTIVE","sortPriority":11,"id":41419595,"name":"2 - 5"},{"status":"ACTIVE","sortPriority":12,"id":41419596,"name":"2 - 6"},{"status":"ACTIVE","sortPriority":13,"id":41419597,"name":"2 - 7"},{"status":"ACTIVE","sortPriority":14,"id":41419598,"name":"2 - 8"},{"status":"ACTIVE","sortPriority":15,"id":41419599,"name":"3 - 1"},{"status":"ACTIVE","sortPriority":16,"id":41419600,"name":"3 - 2"},{"status":"ACTIVE","sortPriority":17,"id":41419601,"name":"3 - 4"},{"status":"ACTIVE","sortPriority":18,"id":41419602,"name":"3 - 5"},{"status":"ACTIVE","sortPriority":19,"id":41419603,"name":"3 - 6"},{"status":"ACTIVE","sortPriority":20,"id":41419604,"name":"3 - 7"},{"status":"ACTIVE","sortPriority":21,"id":41419605,"name":"3 - 8"},{"status":"ACTIVE","sortPriority":22,"id":41419606,"name":"4 - 1"},{"status":"ACTIVE","sortPriority":23,"id":41419607,"name":"4 - 2"},{"status":"ACTIVE","sortPriority":24,"id":41419608,"name":"4 - 3"},{"status":"ACTIVE","sortPriority":25,"id":41419609,"name":"4 - 5"},{"status":"ACTIVE","sortPriority":26,"id":41419610,"name":"4 - 6"},{"status":"ACTIVE","sortPriority":27,"id":41419611,"name":"4 - 7"},{"status":"ACTIVE","sortPriority":28,"id":41419612,"name":"4 - 8"},{"status":"ACTIVE","sortPriority":29,"id":41419613,"name":"5 - 1"},{"status":"ACTIVE","sortPriority":30,"id":41419614,"name":"5 - 2"},{"status":"ACTIVE","sortPriority":31,"id":41419615,"name":"5 - 3"},{"status":"ACTIVE","sortPriority":32,"id":41419616,"name":"5 - 4"},{"status":"ACTIVE","sortPriority":33,"id":41419617,"name":"5 - 6"},{"status":"ACTIVE","sortPriority":34,"id":41419618,"name":"5 - 7"},{"status":"ACTIVE","sortPriority":35,"id":41419619,"name":"5 - 8"},{"status":"ACTIVE","sortPriority":36,"id":41419620,"name":"6 - 1"},{"status":"ACTIVE","sortPriority":37,"id":41419621,"name":"6 - 2"},{"status":"ACTIVE","sortPriority":38,"id":41419622,"name":"6 - 3"},{"status":"ACTIVE","sortPriority":39,"id":41419623,"name":"6 - 4"},{"status":"ACTIVE","sortPriority":40,"id":41419624,"name":"6 - 5"},{"status":"ACTIVE","sortPriority":41,"id":41419625,"name":"6 - 7"},{"status":"ACTIVE","sortPriority":42,"id":41419626,"name":"6 - 8"},{"status":"ACTIVE","sortPriority":43,"id":41419627,"name":"7 - 1"},{"status":"ACTIVE","sortPriority":44,"id":41419628,"name":"7 - 2"},{"status":"ACTIVE","sortPriority":45,"id":41419629,"name":"7 - 3"},{"status":"ACTIVE","sortPriority":46,"id":41419630,"name":"7 - 4"},{"status":"ACTIVE","sortPriority":47,"id":41419631,"name":"7 - 5"},{"status":"ACTIVE","sortPriority":48,"id":41419632,"name":"7 - 6"},{"status":"ACTIVE","sortPriority":49,"id":41419633,"name":"7 - 8"},{"status":"ACTIVE","sortPriority":50,"id":41419634,"name":"8 - 1"},{"status":"ACTIVE","sortPriority":51,"id":41419635,"name":"8 - 2"},{"status":"ACTIVE","sortPriority":52,"id":41419636,"name":"8 - 3"},{"status":"ACTIVE","sortPriority":53,"id":41419637,"name":"8 - 4"},{"status":"ACTIVE","sortPriority":54,"id":41419638,"name":"8 - 5"},{"status":"ACTIVE","sortPriority":55,"id":41419639,"name":"8 - 6"},{"status":"ACTIVE","sortPriority":56,"id":41419640,"name":"8 - 7"}],"regulators":["MR_INT"],"venue":"Traralgon","countryCode":"AU","discountAllowed":true,"timezone":"Australia/Sydney","openDate":"2022-03-02T08:31:00.000Z","version":4382480593,"name":"Exacta","eventName":"Traralgon (AUS) 2nd Mar"},"rc":[{"atb":[[17,16.63],[48,4.24],[24,8.67]],"id":41419609},{"atb":[[17,16.63],[48,4.24],[24,8.67]],"id":41419638},{"atb":[[17,16.63],[48,4.24],[24,8.67]],"id":41419605},{"atb":[[16,13.3],[7.4,41.58],[9.4,23.75]],"id":41419634},{"atb":[[16,17.74],[44,4.64],[22,9.5]],"id":41419617},{"atb":[[16,13.3],[7.4,41.58],[9.4,23.75]],"id":41419613},{"atb":[[65,3.11],[19,14.78],[28,7.39]],"id":41419593},{"atb":[[42,4.86],[21,9.97],[15.5,18.35]],"id":41419622},{"atb":[[5.7,42.46],[8.4,26.97],[4.7,71.92]],"id":41419589},{"atb":[[17.5,16.12],[50,4.07],[25,8.31]],"id":41419618},{"atb":[[17,16.63],[48,4.24],[24,8.67]],"id":41419601},{"atb":[[17.5,16.12],[50,4.07],[25,8.31]],"id":41419630},{"atb":[[70,2.89],[19.5,14.38],[29,7.12]],"id":41419597},{"atb":[[42,4.86],[21,9.97],[15.5,18.35]],"id":41419626},{"atb":[[16,17.74],[44,4.64],[22,9.5]],"id":41419639},{"atb":[[16,13.3],[7.4,41.58],[9.4,23.75]],"id":41419606},{"atb":[[65,3.11],[19,14.78],[28,7.39]],"id":41419635},{"atb":[[17,16.63],[48,4.24],[24,8.67]],"id":41419602},{"atb":[[6.2,51.17],[8.2,27.72],[13,16.63]],"id":41419585},{"atb":[[65,3.11],[19,14.78],[28,7.39]],"id":41419614},{"atb":[[16,17.74],[44,4.64],[22,9.5]],"id":41419610},{"atb":[[42,4.86],[21,9.97],[15.5,18.35]],"id":41419623},{"atb":[[10,22.17],[5.5,59.13],[7,33.26]],"id":41419590},{"atb":[[17,16.63],[48,4.24],[24,8.67]],"id":41419619},{"atb":[[9.6,23.2],[5.3,61.88],[6.6,35.63]],"id":41419586},{"atb":[[17.5,16.12],[50,4.07],[25,8.31]],"id":41419631},{"atb":[[65,3.11],[19,14.78],[28,7.39]],"id":41419598},{"atb":[[16.5,12.87],[9.6,23.2],[7.6,40.32]],"id":41419627},{"atb":[[65,3.11],[19,14.78],[28,7.39]],"id":41419594},{"atb":[[17.5,16.12],[50,4.07],[25,8.31]],"id":41419640},{"atb":[[65,3.11],[19,14.78],[28,7.39]],"id":41419607},{"atb":[[17,16.63],[48,4.24],[24,8.67]],"id":41419636},{"atb":[[16,17.74],[44,4.64],[22,9.5]],"id":41419603},{"atb":[[17,16.63],[48,4.24],[24,8.67]],"id":41419615},{"atb":[[17.5,16.12],[50,4.07],[25,8.31]],"id":41419611},{"atb":[[42,4.86],[21,9.97],[15.5,18.35]],"id":41419624},{"atb":[[9.6,23.2],[5.3,61.88],[6.6,35.63]],"id":41419591},{"atb":[[6.2,51.17],[8.2,27.72],[13,16.63]],"id":41419620},{"atb":[[9.6,23.2],[5.3,61.88],[6.6,35.63]],"id":41419587},{"atb":[[16,17.74],[44,4.64],[22,9.5]],"id":41419632},{"atb":[[16,13.3],[7.4,41.58],[9.4,23.75]],"id":41419599},{"atb":[[70,2.89],[19.5,14.38],[29,7.12]],"id":41419628},{"atb":[[65,3.11],[19,14.78],[28,7.39]],"id":41419595},{"atb":[[17,16.63],[48,4.24],[24,8.67]],"id":41419608},{"atb":[[17,16.63],[48,4.24],[24,8.67]],"id":41419637},{"atb":[[17.5,16.12],[50,4.07],[25,8.31]],"id":41419604},{"atb":[[17,16.63],[48,4.24],[24,8.67]],"id":41419616},{"atb":[[17,16.63],[48,4.24],[24,8.67]],"id":41419612},{"atb":[[16,17.74],[44,4.64],[22,9.5]],"id":41419625},{"atb":[[8.6,35.01],[19,11.08],[11.5,19]],"id":41419592},{"atb":[[17,16.63],[48,4.24],[24,8.67]],"id":41419621},{"atb":[[9.6,23.2],[5.3,61.88],[6.6,35.63]],"id":41419588},{"atb":[[17.5,16.12],[50,4.07],[25,8.31]],"id":41419633},{"atb":[[65,3.11],[19,14.78],[28,7.39]],"id":41419600},{"atb":[[17.5,16.12],[50,4.07],[25,8.31]],"id":41419629},{"atb":[[17.5,16.12],[50,4.07],[25,8.31]],"id":41419596}],"con":true,"img":true}]}
{"op":"mcm","clk":"5346767737","pt":1646187402723,"mc":[{"id":"1.195453700","marketDefinition":{"bspMarket":false,"turnInPlayEnabled":false,"persistenceEnabled":false,"marketBaseRate":7.0,"eventId":"31272494","eventTypeId":"4339","numberOfWinners":1,"bettingType":"ODDS","marketType":"EXACTA","marketTime":"2022-03-02T08:31:00.000Z","suspendTime":"2022-03-02T08:31:00.000Z","bspReconciled":false,"complete":true,"inPlay":false,"crossMatching":false,"runnersVoidable":false,"numberOfActiveRunners":56,"betDelay":0,"status":"OPEN","runners":[{"status":"ACTIVE","sortPriority":1,"id":41419585,"name":"1 - 2"},{"status":"ACTIVE","sortPriority":2,"id":41419586,"name":"1 - 3"},{"status":"ACTIVE","sortPriority":3,"id":41419587,"name":"1 - 4"},{"status":"ACTIVE","sortPriority":4,"id":41419588,"name":"1 - 5"},{"status":"ACTIVE","sortPriority":5,"id":41419589,"name":"1 - 6"},{"status":"ACTIVE","sortPriority":6,"id":41419590,"name":"1 - 7"},{"status":"ACTIVE","sortPriority":7,"id":41419591,"name":"1 - 8"},{"status":"ACTIVE","sortPriority":8,"id":41419592,"name":"2 - 1"},{"status":"ACTIVE","sortPriority":9,"id":41419593,"name":"2 - 3"},{"status":"ACTIVE","sortPriority":10,"id":41419594,"name":"2 - 4"},{"status":"ACTIVE","sortPriority":11,"id":41419595,"name":"2 - 5"},{"status":"ACTIVE","sortPriority":12,"id":41419596,"name":"2 - 6"},{"status":"ACTIVE","sortPriority":13,"id":41419597,"name":"2 - 7"},{"status":"ACTIVE","sortPriority":14,"id":41419598,"name":"2 - 8"},{"status":"ACTIVE","sortPriority":15,"id":41419599,"name":"3 - 1"},{"status":"ACTIVE","sortPriority":16,"id":41419600,"name":"3 - 2"},{"status":"ACTIVE","sortPriority":17,"id":41419601,"name":"3 - 4"},{"status":"ACTIVE","sortPriority":18,"id":41419602,"name":"3 - 5"},{"status":"ACTIVE","sortPriority":19,"id":41419603,"name":"3 - 6"},{"status":"ACTIVE","sortPriority":20,"id":41419604,"name":"3 - 7"},{"status":"ACTIVE","sortPriority":21,"id":41419605,"name":"3 - 8"},{"status":"ACTIVE","sortPriority":22,"id":41419606,"name":"4 - 1"},{"status":"ACTIVE","sortPriority":23,"id":41419607,"name":"4 - 2"},{"status":"ACTIVE","sortPriority":24,"id":41419608,"name":"4 - 3"},{"status":"ACTIVE","sortPriority":25,"id":41419609,"name":"4 - 5"},{"status":"ACTIVE","sortPriority":26,"id":41419610,"name":"4 - 6"},{"status":"ACTIVE","sortPriority":27,"id":41419611,"name":"4 - 7"},{"status":"ACTIVE","sortPriority":28,"id":41419612,"name":"4 - 8"},{"status":"ACTIVE","sortPriority":29,"id":41419613,"name":"5 - 1"},{"status":"ACTIVE","sortPriority":30,"id":41419614,"name":"5 - 2"},{"status":"ACTIVE","sortPriority":31,"id":41419615,"name":"5 - 3"},{"status":"ACTIVE","sortPriority":32,"id":41419616,"name":"5 - 4"},{"status":"ACTIVE","sortPriority":33,"id":41419617,"name":"5 - 6"},{"status":"ACTIVE","sortPriority":34,"id":41419618,"name":"5 - 7"},{"status":"ACTIVE","sortPriority":35,"id":41419619,"name":"5 - 8"},{"status":"ACTIVE","sortPriority":36,"id":41419620,"name":"6 - 1"},{"status":"ACTIVE","sortPriority":37,"id":41419621,"name":"6 - 2"},{"status":"ACTIVE","sortPriority":38,"id":41419622,"name":"6 - 3"},{"status":"ACTIVE","sortPriority":39,"id":41419623,"name":"6 - 4"},{"status":"ACTIVE","sortPriority":40,"id":41419624,"name":"6 - 5"},{"status":"ACTIVE","sortPriority":41,"id":41419625,"name":"6 - 7"},{"status":"ACTIVE","sortPriority":42,"id":41419626,"name":"6 - 8"},{"status":"ACTIVE","sortPriority":43,"id":41419627,"name":"7 - 1"},{"status":"ACTIVE","sortPriority":44,"id":41419628,"name":"7 - 2"},{"status":"ACTIVE","sortPriority":45,"id":41419629,"name":"7 - 3"},{"status":"ACTIVE","sortPriority":46,"id":41419630,"name":"7 - 4"},{"status":"ACTIVE","sortPriority":47,"id":41419631,"name":"7 - 5"},{"status":"ACTIVE","sortPriority":48,"id":41419632,"name":"7 - 6"},{"status":"ACTIVE","sortPriority":49,"id":41419633,"name":"7 - 8"},{"status":"ACTIVE","sortPriority":50,"id":41419634,"name":"8 - 1"},{"status":"ACTIVE","sortPriority":51,"id":41419635,"name":"8 - 2"},{"status":"ACTIVE","sortPriority":52,"id":41419636,"name":"8 - 3"},{"status":"ACTIVE","sortPriority":53,"id":41419637,"name":"8 - 4"},{"status":"ACTIVE","sortPriority":54,"id":41419638,"name":"8 - 5"},{"status":"ACTIVE","sortPriority":55,"id":41419639,"name":"8 - 6"},{"status":"ACTIVE","sortPriority":56,"id":41419640,"name":"8 - 7"}],"regulators":["MR_INT"],"venue":"Traralgon","countryCode":"AU","discountAllowed":true,"timezone":"Australia/Sydney","openDate":"2022-03-02T08:31:00.000Z","version":4382480593,"name":"Exacta","eventName":"Traralgon (AUS) 2nd Mar"},"rc":[{"atb":[[17,16.65],[48,4.25],[24,8.69]],"id":41419609},{"atb":[[17,16.65],[48,4.25],[24,8.69]],"id":41419638},{"atb":[[17,16.65],[48,4.25],[24,8.69]],"id":41419605},{"atb":[[16,13.32],[7.4,41.64],[9.4,23.79]],"id":41419634},{"atb":[[16,17.77],[44,4.65],[22,9.52]],"id":41419617},{"atb":[[16,13.32],[7.4,41.64],[9.4,23.79]],"id":41419613},{"atb":[[65,3.12],[19,14.8],[28,7.4]],"id":41419593},{"atb":[[42,4.87],[21,9.99],[15.5,18.38]],"id":41419622},{"atb":[[5.7,42.53],[8.4,27.01],[4.7,72.03]],"id":41419589},{"atb":[[17.5,16.15],[50,4.07],[25,8.32]],"id":41419618},{"atb":[[17,16.65],[48,4.25],[24,8.69]],"id":41419601},{"atb":[[17.5,16.15],[50,4.07],[25,8.32]],"id":41419630},{"atb":[[70,2.89],[19.5,14.4],[29,7.13]],"id":41419597},{"atb":[[42,4.87],[21,9.99],[15.5,18.38]],"id":41419626},{"atb":[[16,17.77],[44,4.65],[22,9.52]],"id":41419639},{"atb":[[16,13.32],[7.4,41.64],[9.4,23.79]],"id":41419606},{"atb":[[65,3.12],[19,14.8],[28,7.4]],"id":41419635},{"atb":[[17,16.65],[48,4.25],[24,8.69]],"id":41419602},{"atb":[[6.2,51.25],[8.2,27.76],[13,16.65]],"id":41419585},{"atb":[[65,3.12],[19,14.8],[28,7.4]],"id":41419614},{"atb":[[16,17.77],[44,4.65],[22,9.52]],"id":41419610},{"atb":[[42,4.87],[21,9.99],[15.5,18.38]],"id":41419623},{"atb":[[10,22.2],[5.5,59.22],[7,33.31]],"id":41419590},{"atb":[[17,16.65],[48,4.25],[24,8.69]],"id":41419619},{"atb":[[9.6,23.24],[5.3,61.98],[6.6,35.69]],"id":41419586},{"atb":[[17.5,16.15],[50,4.07],[25,8.32]],"id":41419631},{"atb":[[65,3.12],[19,14.8],[28,7.4]],"id":41419598},{"atb":[[16.5,12.89],[9.6,23.24],[7.6,40.38]],"id":41419627},{"atb":[[65,3.12],[19,14.8],[28,7.4]],"id":41419594},{"atb":[[17.5,16.15],[50,4.07],[25,8.32]],"id":41419640},{"atb":[[65,3.12],[19,14.8],[28,7.4]],"id":41419607},{"atb":[[17,16.65],[48,4.25],[24,8.69]],"id":41419636},{"atb":[[16,17.77],[44,4.65],[22,9.52]],"id":41419603},{"atb":[[17,16.65],[48,4.25],[24,8.69]],"id":41419615},{"atb":[[17.5,16.15],[50,4.07],[25,8.32]],"id":41419611},{"atb":[[42,4.87],[21,9.99],[15.5,18.38]],"id":41419624},{"atb":[[9.6,23.24],[5.3,61.98],[6.6,35.69]],"id":41419591},{"atb":[[6.2,51.25],[8.2,27.76],[13,16.65]],"id":41419620},{"atb":[[9.6,23.24],[5.3,61.98],[6.6,35.69]],"id":41419587},{"atb":[[16,17.77],[44,4.65],[22,9.52]],"id":41419632},{"atb":[[16,13.32],[7.4,41.64],[9.4,23.79]],"id":41419599},{"atb":[[70,2.89],[19.5,14.4],[29,7.13]],"id":41419628},{"atb":[[65,3.12],[19,14.8],[28,7.4]],"id":41419595},{"atb":[[17,16.65],[48,4.25],[24,8.69]],"id":41419608},{"atb":[[17,16.65],[48,4.25],[24,8.69]],"id":41419637},{"atb":[[17.5,16.15],[50,4.07],[25,8.32]],"id":41419604},{"atb":[[17,16.65],[48,4.25],[24,8.69]],"id":41419616},{"atb":[[17,16.65],[48,4.25],[24,8.69]],"id":41419612},{"atb":[[16,17.77],[44,4.65],[22,9.52]],"id":41419625},{"atb":[[8.6,35.07],[19,11.1],[11.5,19.03]],"id":41419592},{"atb":[[17,16.65],[48,4.25],[24,8.69]],"id":41419621},{"atb":[[9.6,23.24],[5.3,61.98],[6.6,35.69]],"id":41419588},{"atb":[[17.5,16.15],[50,4.07],[25,8.32]],"id":41419633},{"atb":[[65,3.12],[19,14.8],[28,7.4]],"id":41419600},{"atb":[[17.5,16.15],[50,4.07],[25,8.32]],"id":41419629},{"atb":[[17.5,16.15],[50,4.07],[25,8.32]],"id":41419596}],"con":true,"img":true}]}
{"op":"mcm","clk":"5347092301","pt":1646192802704,"mc":[{"id":"1.195453700","marketDefinition":{"bspMarket":false,"turnInPlayEnabled":false,"persistenceEnabled":false,"marketBaseRate":7.0,"eventId":"31272494","eventTypeId":"4339","numberOfWinners":1,"bettingType":"ODDS","marketType":"EXACTA","marketTime":"2022-03-02T08:31:00.000Z","suspendTime":"2022-03-02T08:31:00.000Z","bspReconciled":false,"complete":true,"inPlay":false,"crossMatching":false,"runnersVoidable":false,"numberOfActiveRunners":56,"betDelay":0,"status":"OPEN","runners":[{"status":"ACTIVE","sortPriority":1,"id":41419585,"name":"1 - 2"},{"status":"ACTIVE","sortPriority":2,"id":41419586,"name":"1 - 3"},{"status":"ACTIVE","sortPriority":3,"id":41419587,"name":"1 - 4"},{"status":"ACTIVE","sortPriority":4,"id":41419588,"name":"1 - 5"},{"status":"ACTIVE","sortPriority":5,"id":41419589,"name":"1 - 6"},{"status":"ACTIVE","sortPriority":6,"id":41419590,"name":"1 - 7"},{"status":"ACTIVE","sortPriority":7,"id":41419591,"name":"1 - 8"},{"status":"ACTIVE","sortPriority":8,"id":41419592,"name":"2 - 1"},{"status":"ACTIVE","sortPriority":9,"id":41419593,"name":"2 - 3"},{"status":"ACTIVE","sortPriority":10,"id":41419594,"name":"2 - 4"},{"status":"ACTIVE","sortPriority":11,"id":41419595,"name":"2 - 5"},{"status":"ACTIVE","sortPriority":12,"id":41419596,"name":"2 - 6"},{"status":"ACTIVE","sortPriority":13,"id":41419597,"name":"2 - 7"},{"status":"ACTIVE","sortPriority":14,"id":41419598,"name":"2 - 8"},{"status":"ACTIVE","sortPriority":15,"id":41419599,"name":"3 - 1"},{"status":"ACTIVE","sortPriority":16,"id":41419600,"name":"3 - 2"},{"status":"ACTIVE","sortPriority":17,"id":41419601,"name":"3 - 4"},{"status":"ACTIVE","sortPriority":18,"id":41419602,"name":"3 - 5"},{"status":"ACTIVE","sortPriority":19,"id":41419603,"name":"3 - 6"},{"status":"ACTIVE","sortPriority":20,"id":41419604,"name":"3 - 7"},{"status":"ACTIVE","sortPriority":21,"id":41419605,"name":"3 - 8"},{"status":"ACTIVE","sortPriority":22,"id":41419606,"name":"4 - 1"},{"status":"ACTIVE","sortPriority":23,"id":41419607,"name":"4 - 2"},{"status":"ACTIVE","sortPriority":24,"id":41419608,"name":"4 - 3"},{"status":"ACTIVE","sortPriority":25,"id":41419609,"name":"4 - 5"},{"status":"ACTIVE","sortPriority":26,"id":41419610,"name":"4 - 6"},{"status":"ACTIVE","sortPriority":27,"id":41419611,"name":"4 - 7"},{"status":"ACTIVE","sortPriority":28,"id":41419612,"name":"4 - 8"},{"status":"ACTIVE","sortPriority":29,"id":41419613,"name":"5 - 1"},{"status":"ACTIVE","sortPriority":30,"id":41419614,"name":"5 - 2"},{"status":"ACTIVE","sortPriority":31,"id":41419615,"name":"5 - 3"},{"status":"ACTIVE","sortPriority":32,"id":41419616,"name":"5 - 4"},{"status":"ACTIVE","sortPriority":33,"id":41419617,"name":"5 - 6"},{"status":"ACTIVE","sortPriority":34,"id":41419618,"name":"5 - 7"},{"status":"ACTIVE","sortPriority":35,"id":41419619,"name":"5 - 8"},{"status":"ACTIVE","sortPriority":36,"id":41419620,"name":"6 - 1"},{"status":"ACTIVE","sortPriority":37,"id":41419621,"name":"6 - 2"},{"status":"ACTIVE","sortPriority":38,"id":41419622,"name":"6 - 3"},{"status":"ACTIVE","sortPriority":39,"id":41419623,"name":"6 - 4"},{"status":"ACTIVE","sortPriority":40,"id":41419624,"name":"6 - 5"},{"status":"ACTIVE","sortPriority":41,"id":41419625,"name":"6 - 7"},{"status":"ACTIVE","sortPriority":42,"id":41419626,"name":"6 - 8"},{"status":"ACTIVE","sortPriority":43,"id":41419627,"name":"7 - 1"},{"status":"ACTIVE","sortPriority":44,"id":41419628,"name":"7 - 2"},{"status":"ACTIVE","sortPriority":45,"id":41419629,"name":"7 - 3"},{"status":"ACTIVE","sortPriority":46,"id":41419630,"name":"7 - 4"},{"status":"ACTIVE","sortPriority":47,"id":41419631,"name":"7 - 5"},{"status":"ACTIVE","sortPriority":48,"id":41419632,"name":"7 - 6"},{"status":"ACTIVE","sortPriority":49,"id":41419633,"name":"7 - 8"},{"status":"ACTIVE","sortPriority":50,"id":41419634,"name":"8 - 1"},{"status":"ACTIVE","sortPriority":51,"id":41419635,"name":"8 - 2"},{"status":"ACTIVE","sortPriority":52,"id":41419636,"name":"8 - 3"},{"status":"ACTIVE","sortPriority":53,"id":41419637,"name":"8 - 4"},{"status":"ACTIVE","sortPriority":54,"id":41419638,"name":"8 - 5"},{"status":"ACTIVE","sortPriority":55,"id":41419639,"name":"8 - 6"},{"status":"ACTIVE","sortPriority":56,"id":41419640,"name":"8 - 7"}],"regulators":["MR_INT"],"venue":"Traralgon","countryCode":"AU","discountAllowed":true,"timezone":"Australia/Sydney","openDate":"2022-03-02T08:31:00.000Z","version":4382480593,"name":"Exacta","eventName":"Traralgon (AUS) 2nd Mar"},"rc":[{"atb":[[17,16.68],[48,4.26],[24,8.7]],"id":41419609},{"atb":[[17,16.68],[48,4.26],[24,8.7]],"id":41419638},{"atb":[[17,16.68],[48,4.26],[24,8.7]],"id":41419605},{"atb":[[16,13.34],[7.4,41.71],[9.4,23.83]],"id":41419634},{"atb":[[16,17.8],[44,4.65],[22,9.53]],"id":41419617},{"atb":[[16,13.34],[7.4,41.71],[9.4,23.83]],"id":41419613},{"atb":[[65,3.12],[19,14.83],[28,7.41]],"id":41419593},{"atb":[[42,4.88],[21,10.01],[15.5,18.41]],"id":41419622},{"atb":[[5.7,42.6],[8.4,27.05],[4.7,72.15]],"id":41419589},{"atb":[[17.5,16.17],[50,4.08],[25,8.34]],"id":41419618},{"atb":[[17,16.68],[48,4.26],[24,8.7]],"id":41419601},{"atb":[[17.5,16.17],[50,4.08],[25,8.34]],"id":41419630},{"atb":[[70,2.9],[19.5,14.43],[29,7.14]],"id":41419597},{"atb":[[42,4.88],[21,10.01],[15.5,18.41]],"id":41419626},{"atb":[[16,17.8],[44,4.65],[22,9.53]],"id":41419639},{"atb":[[16,13.34],[7.4,41.71],[9.4,23.83]],"id":41419606},{"atb":[[65,3.12],[19,14.83],[28,7.41]],"id":41419635},{"atb":[[17,16.68],[48,4.26],[24,8.7]],"id":41419602},{"atb":[[6.2,51.34],[8.2,27.81],[13,16.68]],"id":41419585},{"atb":[[65,3.12],[19,14.83],[28,7.41]],"id":41419614},{"atb":[[16,17.8],[44,4.65],[22,9.53]],"id":41419610},{"atb":[[42,4.88],[21,10.01],[15.5,18.41]],"id":41419623},{"atb":[[10,22.24],[5.5,59.32],[7,33.37]],"id":41419590},{"atb":[[17,16.68],[48,4.26],[24,8.7]],"id":41419619},{"atb":[[9.6,23.28],[5.3,62.08],[6.6,35.75]],"id":41419586},{"atb":[[17.5,16.17],[50,4.08],[25,8.34]],"id":41419631},{"atb":[[65,3.12],[19,14.83],[28,7.41]],"id":41419598},{"atb":[[16.5,12.91],[9.6,23.28],[7.6,40.45]],"id":41419627},{"atb":[[65,3.12],[19,14.83],[28,7.41]],"id":41419594},{"atb":[[17.5,16.17],[50,4.08],[25,8.34]],"id":41419640},{"atb":[[65,3.12],[19,14.83],[28,7.41]],"id":41419607},{"atb":[[17,16.68],[48,4.26],[24,8.7]],"id":41419636},{"atb":[[16,17.8],[44,4.65],[22,9.53]],"id":41419603},{"atb":[[17,16.68],[48,4.26],[24,8.7]],"id":41419615},{"atb":[[17.5,16.17],[50,4.08],[25,8.34]],"id":41419611},{"atb":[[42,4.88],[21,10.01],[15.5,18.41]],"id":41419624},{"atb":[[9.6,23.28],[5.3,62.08],[6.6,35.75]],"id":41419591},{"atb":[[6.2,51.34],[8.2,27.81],[13,16.68]],"id":41419620},{"atb":[[9.6,23.28],[5.3,62.08],[6.6,35.75]],"id":41419587},{"atb":[[16,17.8],[44,4.65],[22,9.53]],"id":41419632},{"atb":[[16,13.34],[7.4,41.71],[9.4,23.83]],"id":41419599},{"atb":[[70,2.9],[19.5,14.43],[29,7.14]],"id":41419628},{"atb":[[65,3.12],[19,14.83],[28,7.41]],"id":41419595},{"atb":[[17,16.68],[48,4.26],[24,8.7]],"id":41419608},{"atb":[[17,16.68],[48,4.26],[24,8.7]],"id":41419637},{"atb":[[17.5,16.17],[50,4.08],[25,8.34]],"id":41419604},{"atb":[[17,16.68],[48,4.26],[24,8.7]],"id":41419616},{"atb":[[17,16.68],[48,4.26],[24,8.7]],"id":41419612},{"atb":[[16,17.8],[44,4.65],[22,9.53]],"id":41419625},{"atb":[[8.6,35.13],[19,11.12],[11.5,19.06]],"id":41419592},{"atb":[[17,16.68],[48,4.26],[24,8.7]],"id":41419621},{"atb":[[9.6,23.28],[5.3,62.08],[6.6,35.75]],"id":41419588},{"atb":[[17.5,16.17],[50,4.08],[25,8.34]],"id":41419633},{"atb":[[65,3.12],[19,14.83],[28,7.41]],"id":41419600},{"atb":[[17.5,16.17],[50,4.08],[25,8.34]],"id":41419629},{"atb":[[17.5,16.17],[50,4.08],[25,8.34]],"id":41419596}],"con":true,"img":true}]}
{"op":"mcm","clk":"5347381173","pt":1646198202722,"mc":[{"id":"1.195453700","marketDefinition":{"bspMarket":false,"turnInPlayEnabled":false,"persistenceEnabled":false,"marketBaseRate":7.0,"eventId":"31272494","eventTypeId":"4339","numberOfWinners":1,"bettingType":"ODDS","marketType":"EXACTA","marketTime":"2022-03-02T08:31:00.000Z","suspendTime":"2022-03-02T08:31:00.000Z","bspReconciled":false,"complete":true,"inPlay":false,"crossMatching":false,"runnersVoidable":false,"numberOfActiveRunners":56,"betDelay":0,"status":"OPEN","runners":[{"status":"ACTIVE","sortPriority":1,"id":41419585,"name":"1 - 2"},{"status":"ACTIVE","sortPriority":2,"id":41419586,"name":"1 - 3"},{"status":"ACTIVE","sortPriority":3,"id":41419587,"name":"1 - 4"},{"status":"ACTIVE","sortPriority":4,"id":41419588,"name":"1 - 5"},{"status":"ACTIVE","sortPriority":5,"id":41419589,"name":"1 - 6"},{"status":"ACTIVE","sortPriority":6,"id":41419590,"name":"1 - 7"},{"status":"ACTIVE","sortPriority":7,"id":41419591,"name":"1 - 8"},{"status":"ACTIVE","sortPriority":8,"id":41419592,"name":"2 - 1"},{"status":"ACTIVE","sortPriority":9,"id":41419593,"name":"2 - 3"},{"status":"ACTIVE","sortPriority":10,"id":41419594,"name":"2 - 4"},{"status":"ACTIVE","sortPriority":11,"id":41419595,"name":"2 - 5"},{"status":"ACTIVE","sortPriority":12,"id":41419596,"name":"2 - 6"},{"status":"ACTIVE","sortPriority":13,"id":41419597,"name":"2 - 7"},{"status":"ACTIVE","sortPriority":14,"id":41419598,"name":"2 - 8"},{"status":"ACTIVE","sortPriority":15,"id":41419599,"name":"3 - 1"},{"status":"ACTIVE","sortPriority":16,"id":41419600,"name":"3 - 2"},{"status":"ACTIVE","sortPriority":17,"id":41419601,"name":"3 - 4"},{"status":"ACTIVE","sortPriority":18,"id":41419602,"name":"3 - 5"},{"status":"ACTIVE","sortPriority":19,"id":41419603,"name":"3 - 6"},{"status":"ACTIVE","sortPriority":20,"id":41419604,"name":"3 - 7"},{"status":"ACTIVE","sortPriority":21,"id":41419605,"name":"3 - 8"},{"status":"ACTIVE","sortPriority":22,"id":41419606,"name":"4 - 1"},{"status":"ACTIVE","sortPriority":23,"id":41419607,"name":"4 - 2"},{"status":"ACTIVE","sortPriority":24,"id":41419608,"name":"4 - 3"},{"status":"ACTIVE","sortPriority":25,"id":41419609,"name":"4 - 5"},{"status":"ACTIVE","sortPriority":26,"id":41419610,"name":"4 - 6"},{"status":"ACTIVE","sortPriority":27,"id":41419611,"name":"4 - 7"},{"status":"ACTIVE","sortPriority":28,"id":41419612,"name":"4 - 8"},{"status":"ACTIVE","sortPriority":29,"id":41419613,"name":"5 - 1"},{"status":"ACTIVE","sortPriority":30,"id":41419614,"name":"5 - 2"},{"status":"ACTIVE","sortPriority":31,"id":41419615,"name":"5 - 3"},{"status":"ACTIVE","sortPriority":32,"id":41419616,"name":"5 - 4"},{"status":"ACTIVE","sortPriority":33,"id":41419617,"name":"5 - 6"},{"status":"ACTIVE","sortPriority":34,"id":41419618,"name":"5 - 7"},{"status":"ACTIVE","sortPriority":35,"id":41419619,"name":"5 - 8"},{"status":"ACTIVE","sortPriority":36,"id":41419620,"name":"6 - 1"},{"status":"ACTIVE","sortPriority":37,"id":41419621,"name":"6 - 2"},{"status":"ACTIVE","sortPriority":38,"id":41419622,"name":"6 - 3"},{"status":"ACTIVE","sortPriority":39,"id":41419623,"name":"6 - 4"},{"status":"ACTIVE","sortPriority":40,"id":41419624,"name":"6 - 5"},{"status":"ACTIVE","sortPriority":41,"id":41419625,"name":"6 - 7"},{"status":"ACTIVE","sortPriority":42,"id":41419626,"name":"6 - 8"},{"status":"ACTIVE","sortPriority":43,"id":41419627,"name":"7 - 1"},{"status":"ACTIVE","sortPriority":44,"id":41419628,"name":"7 - 2"},{"status":"ACTIVE","sortPriority":45,"id":41419629,"name":"7 - 3"},{"status":"ACTIVE","sortPriority":46,"id":41419630,"name":"7 - 4"},{"status":"ACTIVE","sortPriority":47,"id":41419631,"name":"7 - 5"},{"status":"ACTIVE","sortPriority":48,"id":41419632,"name":"7 - 6"},{"status":"ACTIVE","sortPriority":49,"id":41419633,"name":"7 - 8"},{"status":"ACTIVE","sortPriority":50,"id":41419634,"name":"8 - 1"},{"status":"ACTIVE","sortPriority":51,"id":41419635,"name":"8 - 2"},{"status":"ACTIVE","sortPriority":52,"id":41419636,"name":"8 - 3"},{"status":"ACTIVE","sortPriority":53,"id":41419637,"name":"8 - 4"},{"status":"ACTIVE","sortPriority":54,"id":41419638,"name":"8 - 5"},{"status":"ACTIVE","sortPriority":55,"id":41419639,"name":"8 - 6"},{"status":"ACTIVE","sortPriority":56,"id":41419640,"name":"8 - 7"}],"regulators":["MR_INT"],"venue":"Traralgon","countryCode":"AU","discountAllowed":true,"timezone":"Australia/Sydney","openDate":"2022-03-02T08:31:00.000Z","version":4382480593,"name":"Exacta","eventName":"Traralgon (AUS) 2nd Mar"},"rc":[{"atb":[[17,16.68],[48,4.25],[24,8.7]],"id":41419609},{"atb":[[17,16.68],[48,4.25],[24,8.7]],"id":41419638},{"atb":[[17,16.68],[48,4.25],[24,8.7]],"id":41419605},{"atb":[[16,13.34],[7.4,41.7],[9.4,23.82]],"id":41419634},{"atb":[[16,17.79],[44,4.65],[22,9.53]],"id":41419617},{"atb":[[16,13.34],[7.4,41.7],[9.4,23.82]],"id":41419613},{"atb":[[65,3.12],[19,14.82],[28,7.41]],"id":41419593},{"atb":[[42,4.88],[21,10],[15.5,18.4]],"id":41419622},{"atb":[[5.7,42.58],[8.4,27.04],[4.7,72.13]],"id":41419589},{"atb":[[17.5,16.17],[50,4.08],[25,8.33]],"id":41419618},{"atb":[[17,16.68],[48,4.25],[24,8.7]],"id":41419601},{"atb":[[17.5,16.17],[50,4.08],[25,8.33]],"id":41419630},{"atb":[[70,2.89],[19.5,14.42],[29,7.14]],"id":41419597},{"atb":[[42,4.88],[21,10],[15.5,18.4]],"id":41419626},{"atb":[[16,17.79],[44,4.65],[22,9.53]],"id":41419639},{"atb":[[16,13.34],[7.4,41.7],[9.4,23.82]],"id":41419606},{"atb":[[65,3.12],[19,14.82],[28,7.41]],"id":41419635},{"atb":[[17,16.68],[48,4.25],[24,8.7]],"id":41419602},{"atb":[[6.2,51.32],[8.2,27.8],[13,16.68]],"id":41419585},{"atb":[[65,3.12],[19,14.82],[28,7.41]],"id":41419614},{"atb":[[16,17.79],[44,4.65],[22,9.53]],"id":41419610},{"atb":[[42,4.88],[21,10],[15.5,18.4]],"id":41419623},{"atb":[[10,22.23],[5.5,59.3],[7,33.36]],"id":41419590},{"atb":[[17,16.68],[48,4.25],[24,8.7]],"id":41419619},{"atb":[[9.6,23.27],[5.3,62.06],[6.6,35.74]],"id":41419586},{"atb":[[17.5,16.17],[50,4.08],[25,8.33]],"id":41419631},{"atb":[[65,3.12],[19,14.82],[28,7.41]],"id":41419598},{"atb":[[16.5,12.91],[9.6,23.27],[7.6,40.43]],"id":41419627},{"atb":[[65,3.12],[19,14.82],[28,7.41]],"id":41419594},{"atb":[[17.5,16.17],[50,4.08],[25,8.33]],"id":41419640},{"atb":[[65,3.12],[19,14.82],[28,7.41]],"id":41419607},{"atb":[[17,16.68],[48,4.25],[24,8.7]],"id":41419636},{"atb":[[16,17.79],[44,4.65],[22,9.53]],"id":41419603},{"atb":[[17,16.68],[48,4.25],[24,8.7]],"id":41419615},{"atb":[[17.5,16.17],[50,4.08],[25,8.33]],"id":41419611},{"atb":[[42,4.88],[21,10],[15.5,18.4]],"id":41419624},{"atb":[[9.6,23.27],[5.3,62.06],[6.6,35.74]],"id":41419591},{"atb":[[6.2,51.32],[8.2,27.8],[13,16.68]],"id":41419620},{"atb":[[9.6,23.27],[5.3,62.06],[6.6,35.74]],"id":41419587},{"atb":[[16,17.79],[44,4.65],[22,9.53]],"id":41419632},{"atb":[[16,13.34],[7.4,41.7],[9.4,23.82]],"id":41419599},{"atb":[[70,2.89],[19.5,14.42],[29,7.14]],"id":41419628},{"atb":[[65,3.12],[19,14.82],[28,7.41]],"id":41419595},{"atb":[[17,16.68],[48,4.25],[24,8.7]],"id":41419608},{"atb":[[17,16.68],[48,4.25],[24,8.7]],"id":41419637},{"atb":[[17.5,16.17],[50,4.08],[25,8.33]],"id":41419604},{"atb":[[17,16.68],[48,4.25],[24,8.7]],"id":41419616},{"atb":[[17,16.68],[48,4.25],[24,8.7]],"id":41419612},{"atb":[[16,17.79],[44,4.65],[22,9.53]],"id":41419625},{"atb":[[8.6,35.11],[19,11.12],[11.5,19.06]],"id":41419592},{"atb":[[17,16.68],[48,4.25],[24,8.7]],"id":41419621},{"atb":[[9.6,23.27],[5.3,62.06],[6.6,35.74]],"id":41419588},{"atb":[[17.5,16.17],[50,4.08],[25,8.33]],"id":41419633},{"atb":[[65,3.12],[19,14.82],[28,7.41]],"id":41419600},{"atb":[[17.5,16.17],[50,4.08],[25,8.33]],"id":41419629},{"atb":[[17.5,16.17],[50,4.08],[25,8.33]],"id":41419596}],"con":true,"img":true}]}
{"op":"mcm","clk":"5347580304","pt":1646202660464,"mc":[{"id":"1.195453700","rc":[{"atb":[[65,2.73],[17,16.68],[46,3.27],[48,4.25],[24,8.7]],"id":41419609},{"atb":[[65,2.73],[17,16.68],[46,3.27],[48,4.25],[24,8.7]],"id":41419638},{"atb":[[17,16.68],[44,3.27],[48,4.25],[24,8.7],[60,2.73]],"id":41419605},{"atb":[[16,13.34],[22,3.27],[7.4,41.7],[27,2.73],[9.4,23.82]],"id":41419634},{"atb":[[16,17.79],[44,7.93],[22,9.53],[60,2.73]],"id":41419617},{"atb":[[16,13.34],[22,3.27],[7.4,41.7],[27,2.73],[9.4,23.82]],"id":41419613},{"atb":[[65,3.12],[19,14.82],[80,2.73],[55,3.27],[28,7.41]],"id":41419593},{"atb":[[42,8.15],[21,10],[55,2.73],[15.5,18.4]],"id":41419622},{"atb":[[9,3.27],[10,2.73],[5.7,42.58],[8.4,27.04],[4.7,72.13]],"id":41419589},{"atb":[[65,2.73],[17.5,16.17],[46,3.27],[50,4.08],[25,8.33]],"id":41419618},{"atb":[[65,2.73],[17,16.68],[46,3.27],[48,4.25],[24,8.7]],"id":41419601},{"atb":[[65,2.73],[17.5,16.17],[46,3.27],[50,4.08],[25,8.33]],"id":41419630},{"atb":[[70,2.89],[19.5,14.42],[80,2.73],[55,3.27],[29,7.14]],"id":41419597},{"atb":[[42,4.88],[21,10],[44,3.27],[60,2.73],[15.5,18.4]],"id":41419626},{"atb":[[16,17.79],[44,7.93],[22,9.53],[60,2.73]],"id":41419639},{"atb":[[16,13.34],[20,3.27],[7.4,41.7],[25,2.73],[9.4,23.82]],"id":41419606},{"atb":[[65,3.12],[70,2.73],[19,14.82],[48,3.27],[28,7.41]],"id":41419635},{"atb":[[17,16.68],[44,3.27],[48,4.25],[24,8.7],[60,2.73]],"id":41419602},{"atb":[[10,3.27],[6.2,51.32],[8.2,27.8],[12.5,2.73],[13,16.68]],"id":41419585},{"atb":[[65,3.12],[70,2.73],[19,14.82],[48,3.27],[28,7.41]],"id":41419614},{"atb":[[16,17.79],[44,7.93],[22,9.53],[60,2.73]],"id":41419610},{"atb":[[42,4.88],[21,10],[44,3.27],[60,2.73],[15.5,18.4]],"id":41419623},{"atb":[[10,22.23],[5.5,59.3],[6.8,2.73],[7,33.36],[5.9,3.27]],"id":41419590},{"atb":[[17,16.68],[44,3.27],[48,4.25],[24,8.7],[60,2.73]],"id":41419619},{"atb":[[9.6,23.27],[5.3,62.06],[11,2.73],[6.6,35.74],[9.4,3.27]],"id":41419586},{"atb":[[65,2.73],[17.5,16.17],[46,3.27],[50,4.08],[25,8.33]],"id":41419631},{"atb":[[65,3.12],[19,14.82],[80,2.73],[55,3.27],[28,7.41]],"id":41419598},{"atb":[[16.5,16.18],[9.6,23.27],[19,2.73],[7.6,40.43]],"id":41419627},{"atb":[[65,3.12],[19,14.82],[80,2.73],[55,3.27],[28,7.41]],"id":41419594},{"atb":[[65,2.73],[17.5,16.17],[46,3.27],[50,4.08],[25,8.33]],"id":41419640},{"atb":[[65,3.12],[70,2.73],[19,14.82],[48,3.27],[28,7.41]],"id":41419607},{"atb":[[65,2.73],[17,16.68],[46,3.27],[48,4.25],[24,8.7]],"id":41419636},{"atb":[[16,17.79],[44,7.93],[22,9.53],[60,2.73]],"id":41419603},{"atb":[[17,16.68],[44,3.27],[48,4.25],[24,8.7],[60,2.73]],"id":41419615},{"atb":[[65,2.73],[17.5,16.17],[46,3.27],[50,4.08],[25,8.33]],"id":41419611},{"atb":[[42,4.88],[21,10],[15.5,18.4]],"id":41419624},{"atb":[[9.6,23.27],[5.3,62.06],[11,2.73],[6.6,35.74],[9.4,3.27]],"id":41419591},{"atb":[[19.5,3.27],[6.2,51.32],[8.2,27.8],[24,2.73],[13,16.68]],"id":41419620},{"atb":[[9.6,23.27],[5.3,62.06],[11,2.73],[6.6,35.74],[9.4,3.27]],"id":41419587},{"atb":[[16,17.79],[44,4.65],[22,9.53]],"id":41419632},{"atb":[[16,13.34],[22,3.27],[7.4,41.7],[27,2.73],[9.4,23.82]],"id":41419599},{"atb":[[70,2.89],[75,2.73],[19.5,14.42],[50,3.27],[29,7.14]],"id":41419628},{"atb":[[65,3.12],[19,14.82],[80,2.73],[55,3.27],[28,7.41]],"id":41419595},{"atb":[[65,2.73],[17,16.68],[46,3.27],[48,4.25],[24,8.7]],"id":41419608},{"atb":[[65,2.73],[17,16.68],[46,3.27],[48,4.25],[24,8.7]],"id":41419637},{"atb":[[17.5,16.17],[50,4.08],[25,8.33]],"id":41419604},{"atb":[[65,2.73],[17,16.68],[46,3.27],[48,4.25],[24,8.7]],"id":41419616},{"atb":[[65,2.73],[17,16.68],[46,3.27],[48,4.25],[24,8.7]],"id":41419612},{"atb":[[16,17.79],[44,7.93],[22,9.53],[60,2.73]],"id":41419625},{"atb":[[8.6,35.11],[19,11.12],[11.5,19.06],[25,3.27],[30,2.73]],"id":41419592},{"atb":[[65,2.73],[17,16.68],[46,3.27],[48,4.25],[24,8.7]],"id":41419621},{"atb":[[9.6,23.27],[5.3,62.06],[11,2.73],[6.6,35.74],[9.4,3.27]],"id":41419588},{"atb":[[65,2.73],[17.5,16.17],[46,3.27],[50,4.08],[25,8.33]],"id":41419633},{"atb":[[65,3.12],[70,2.73],[19,14.82],[48,3.27],[28,7.41]],"id":41419600},{"atb":[[65,2.73],[17.5,16.17],[46,3.27],[50,4.08],[25,8.33]],"id":41419629},{"atb":[[17.5,16.17],[75,2.73],[50,7.36],[25,8.33]],"id":41419596}],"con":true,"img":false}]}
{"op":"mcm","clk":"5347580313","pt":1646202660666,"mc":[{"id":"1.195453700","rc":[{"atb":[[42,8.15],[55,2.73]],"id":41419624},{"atb":[[65,2.73],[46,3.27]],"id":41419632},{"atb":[[65,2.73],[46,3.27]],"id":41419604}],"con":true,"img":false}]}
{"op":"mcm","clk":"5347583077","pt":1646202716341,"mc":[{"id":"1.195453700","rc":[{"atb":[[9,0],[10,0]],"id":41419589}],"con":true,"img":false}]}
{"op":"mcm","clk":"5347583103","pt":1646202717049,"mc":[{"id":"1.195453700","rc":[{"atb":[[9.6,2.73],[8.6,3.27]],"id":41419589}],"con":true,"img":false}]}
{"op":"mcm","clk":"5347603119","pt":1646203155290,"mc":[{"id":"1.195453700","rc":[{"atb":[[10,0],[12.5,0]],"id":41419585},{"atb":[[6.8,0],[5.9,0]],"id":41419590},{"atb":[[16.5,12.91],[19,0]],"id":41419627}],"con":true,"img":false}]}
{"op":"mcm","clk":"5347603148","pt":1646203156013,"mc":[{"id":"1.195453700","rc":[{"atb":[[12,2.73],[9.8,3.27]],"id":41419585},{"atb":[[5.6,3.27],[6.2,2.73]],"id":41419590},{"atb":[[16,3.27],[18.5,2.73]],"id":41419627}],"con":true,"img":false}]}
{"op":"mcm","clk":"5347632373","pt":1646203832196,"mc":[{"id":"1.195453700","rc":[{"atb":[[5.6,0]],"id":41419590}],"con":true,"img":false}]}
{"op":"mcm","clk":"5347632383","pt":1646203832457,"mc":[{"id":"1.195453700","rc":[{"atb":[[12,0],[9.8,0]],"id":41419585},{"atb":[[6.2,0]],"id":41419590},{"atb":[[16,0],[18.5,0]],"id":41419627}],"con":true,"img":false}]}
{"op":"mcm","clk":"5347632390","pt":1646203832861,"mc":[{"id":"1.195453700","rc":[{"atb":[[5.9,3.27]],"id":41419590}],"con":true,"img":false}]}
{"op":"mcm","clk":"5347632397","pt":1646203833168,"mc":[{"id":"1.195453700","rc":[{"atb":[[10,3.27],[12.5,2.73]],"id":41419585},{"atb":[[6.8,2.73]],"id":41419590},{"atb":[[16.5,16.18],[19,2.73]],"id":41419627}],"con":true,"img":false}]}
{"op":"mcm","clk":"5347655738","pt":1646204472457,"mc":[{"id":"1.195453700","rc":[{"atb":[[65,2.72],[17,16.67],[46,3.27],[48,4.25],[24,8.7]],"id":41419609},{"atb":[[65,2.72],[17,16.67],[46,3.27],[48,4.25],[24,8.7]],"id":41419638},{"atb":[[17,16.67],[44,3.27],[48,4.25],[24,8.7],[60,2.72]],"id":41419605},{"atb":[[16,13.34],[22,3.27],[7.4,41.69],[27,2.72],[9.4,23.82]],"id":41419634},{"atb":[[16,17.78],[44,7.93],[22,9.53],[60,2.72]],"id":41419617},{"atb":[[16,13.34],[22,3.27],[7.4,41.69],[27,2.72],[9.4,23.82]],"id":41419613},{"atb":[[65,3.12],[19,14.82],[80,2.72],[55,3.27],[28,7.41]],"id":41419593},{"atb":[[42,8.15],[21,10],[55,2.72],[15.5,18.4]],"id":41419622},{"atb":[[9.6,2.72],[8.6,3.27],[5.7,42.57],[8.4,27.04],[4.7,72.11]],"id":41419589},{"atb":[[65,2.72],[17.5,16.16],[46,3.27],[50,4.08],[25,8.33]],"id":41419618},{"atb":[[65,2.72],[17,16.67],[46,3.27],[48,4.25],[24,8.7]],"id":41419601},{"atb":[[65,2.72],[17.5,16.16],[46,3.27],[50,4.08],[25,8.33]],"id":41419630},{"atb":[[70,2.89],[19.5,14.42],[80,2.72],[55,3.27],[29,7.14]],"id":41419597},{"atb":[[42,4.87],[21,10],[44,3.27],[60,2.72],[15.5,18.4]],"id":41419626},{"atb":[[16,17.78],[44,7.93],[22,9.53],[60,2.72]],"id":41419639},{"atb":[[16,13.34],[20,0],[7.4,41.69],[25,0],[9.4,23.82]],"id":41419606},{"atb":[[65,3.12],[70,2.72],[19,14.82],[48,3.27],[28,7.41]],"id":41419635},{"atb":[[17,16.67],[44,3.27],[48,4.25],[24,8.7],[60,2.72]],"id":41419602},{"atb":[[10,0],[6.2,51.31],[8.2,27.79],[12.5,0],[13,16.67]],"id":41419585},{"atb":[[65,3.12],[70,2.72],[19,14.82],[48,3.27],[28,7.41]],"id":41419614},{"atb":[[16,17.78],[44,7.93],[22,9.53],[60,2.72]],"id":41419610},{"atb":[[42,4.87],[21,10],[44,3.27],[60,2.72],[15.5,18.4]],"id":41419623},{"atb":[[10,22.23],[5.5,59.29],[6.8,0],[7,33.35],[5.9,0]],"id":41419590},{"atb":[[17,16.67],[44,3.27],[48,4.25],[24,8.7],[60,2.72]],"id":41419619},{"atb":[[9.6,23.26],[11,2.72],[5.3,62.04],[6.6,35.73],[9.4,3.27]],"id":41419586},{"atb":[[65,2.72],[17.5,16.16],[46,3.27],[50,4.08],[25,8.33]],"id":41419631},{"atb":[[65,3.12],[19,14.82],[80,2.72],[55,3.27],[28,7.41]],"id":41419598},{"atb":[[16.5,12.9],[9.6,23.26],[19,0],[7.6,40.42]],"id":41419627},{"atb":[[65,3.12],[19,14.82],[80,2.72],[55,3.27],[28,7.41]],"id":41419594},{"atb":[[65,2.72],[17.5,16.16],[46,3.27],[50,4.08],[25,8.33]],"id":41419640},{"atb":[[65,3.12],[70,2.72],[19,14.82],[48,3.27],[28,7.41]],"id":41419607},{"atb":[[65,2.72],[17,16.67],[46,3.27],[48,4.25],[24,8.7]],"id":41419636},{"atb":[[16,17.78],[44,7.93],[22,9.53],[60,2.72]],"id":41419603},{"atb":[[17,16.67],[44,3.27],[48,4.25],[24,8.7],[60,2.72]],"id":41419615},{"atb":[[65,2.72],[17.5,16.16],[46,3.27],[50,4.08],[25,8.33]],"id":41419611},{"atb":[[42,8.15],[21,10],[55,2.72],[15.5,18.4]],"id":41419624},{"atb":[[9.6,23.26],[11,2.72],[5.3,62.04],[6.6,35.73],[9.4,3.27]],"id":41419591},{"atb":[[19.5,3.27],[6.2,51.31],[8.2,27.79],[24,2.72],[13,16.67]],"id":41419620},{"atb":[[9.6,23.26],[11,2.72],[5.3,62.04],[6.6,35.73],[9.4,3.27]],"id":41419587},{"atb":[[65,2.72],[16,17.78],[44,4.65],[22,9.53],[46,3.27]],"id":41419632},{"atb":[[16,13.34],[22,3.27],[7.4,41.69],[27,2.72],[9.4,23.82]],"id":41419599},{"atb":[[70,2.89],[75,2.72],[19.5,14.42],[50,3.27],[29,7.14]],"id":41419628},{"atb":[[65,3.12],[19,14.82],[80,2.72],[55,3.27],[28,7.41]],"id":41419595},{"atb":[[65,2.72],[17,16.67],[46,3.27],[48,4.25],[24,8.7]],"id":41419608},{"atb":[[65,2.72],[17,16.67],[46,3.27],[48,4.25],[24,8.7]],"id":41419637},{"atb":[[65,2.72],[17.5,16.16],[46,3.27],[50,4.08],[25,8.33]],"id":41419604},{"atb":[[65,2.72],[17,16.67],[46,3.27],[48,4.25],[24,8.7]],"id":41419616},{"atb":[[65,2.72],[17,16.67],[46,3.27],[48,4.25],[24,8.7]],"id":41419612},{"atb":[[16,17.78],[44,7.93],[22,9.53],[60,2.72]],"id":41419625},{"atb":[[8.6,35.1],[19,11.11],[11.5,19.05],[25,0],[30,0]],"id":41419592},{"atb":[[65,2.72],[17,16.67],[46,3.27],[48,4.25],[24,8.7]],"id":41419621},{"atb":[[9.6,23.26],[11,2.72],[5.3,62.04],[6.6,35.73],[9.4,3.27]],"id":41419588},{"atb":[[65,2.72],[17.5,16.16],[46,3.27],[50,4.08],[25,8.33]],"id":41419633},{"atb":[[65,3.12],[70,2.72],[19,14.82],[48,3.27],[28,7.41]],"id":41419600},{"atb":[[65,2.72],[17.5,16.16],[46,3.27],[50,4.08],[25,8.33]],"id":41419629},{"atb":[[17.5,16.16],[75,2.72],[50,7.35],[25,8.33]],"id":41419596}],"con":true,"img":false}]}
{"op":"mcm","clk":"5347655770","pt":1646204473130,"mc":[{"id":"1.195453700","rc":[{"atb":[[22,3.27],[27,2.72]],"id":41419606},{"atb":[[12,2.72],[9.8,3.27]],"id":41419585},{"atb":[[5.6,3.27],[6.2,2.72]],"id":41419590},{"atb":[[16,3.27],[18.5,2.72]],"id":41419627},{"atb":[[32,2.72],[26,3.27]],"id":41419592}],"con":true,"img":false}]}
{"op":"mcm","clk":"5347659164","pt":1646204553513,"mc":[{"id":"1.195453700","rc":[{"atb":[[32,0],[26,0]],"id":41419592}],"con":true,"img":false}]}
{"op":"mcm","clk":"5347659180","pt":1646204553747,"mc":[{"id":"1.195453700","rc":[{"atb":[[22,0],[27,0]],"id":41419606}],"con":true,"img":false}]}
{"op":"mcm","clk":"5347659202","pt":1646204554154,"mc":[{"id":"1.195453700","rc":[{"atb":[[25,3.27],[30,2.72]],"id":41419592}],"con":true,"img":false}]}
{"op":"mcm","clk":"5347659221","pt":1646204554462,"mc":[{"id":"1.195453700","rc":[{"atb":[[20,3.27],[25,2.72]],"id":41419606}],"con":true,"img":false}]}
{"op":"mcm","clk":"5347673670","pt":1646205017549,"mc":[{"id":"1.195453700","rc":[{"atb":[[5.6,0]],"id":41419590}],"con":true,"img":false}]}
{"op":"mcm","clk":"5347673673","pt":1646205017652,"mc":[{"id":"1.195453700","rc":[{"atb":[[12,0],[9.8,0]],"id":41419585},{"atb":[[6.2,0]],"id":41419590},{"atb":[[16,0],[18.5,0]],"id":41419627}],"con":true,"img":false}]}
{"op":"mcm","clk":"5347673692","pt":1646205018569,"mc":[{"id":"1.195453700","rc":[{"atb":[[10,3.27],[12.5,2.72]],"id":41419585},{"atb":[[6.8,2.72],[5.9,3.27]],"id":41419590},{"atb":[[16.5,16.18],[19,2.72]],"id":41419627}],"con":true,"img":false}]}
{"op":"mcm","clk":"5347694170","pt":1646205601594,"mc":[{"id":"1.195453700","rc":[{"atb":[[65,0],[44,3.27],[46,0],[60,2.72]],"id":41419601},{"atb":[[42,8.15],[44,0],[55,2.72],[60,0]],"id":41419626},{"atb":[[65,0],[46,0]],"id":41419612},{"atb":[[11,0],[9.4,0]],"id":41419588}],"con":true,"img":false}]}
{"op":"mcm","clk":"5347694178","pt":1646205601650,"mc":[{"id":"1.195453700","rc":[{"atb":[[10,0],[12.5,0]],"id":41419585},{"atb":[[44,4.65],[60,0]],"id":41419610},{"atb":[[6.8,0],[5.9,0]],"id":41419590},{"atb":[[80,0],[55,0]],"id":41419598},{"atb":[[65,0],[44,3.27],[46,0],[60,2.72]],"id":41419608},{"atb":[[65,0],[46,0]],"id":41419637}],"con":true,"img":false}]}
{"op":"mcm","clk":"5347694182","pt":1646205601754,"mc":[{"id":"1.195453700","rc":[{"atb":[[65,0],[44,3.27],[46,0],[60,2.72]],"id":41419638},{"atb":[[80,0],[55,0]],"id":41419593},{"atb":[[22,0],[27,0]],"id":41419599},{"atb":[[65,0],[46,0]],"id":41419629}],"con":true,"img":false}]}
{"op":"mcm","clk":"5347694191","pt":1646205601859,"mc":[{"id":"1.195453700","rc":[{"atb":[[65,0],[46,0]],"id":41419618},{"atb":[[65,0],[46,0]],"id":41419630},{"atb":[[11,0],[9.4,0]],"id":41419591},{"atb":[[18.5,3.27],[19.5,0],[22,2.72],[24,0]],"id":41419620}],"con":true,"img":false}]}
{"op":"mcm","clk":"5347694206","pt":1646205602071,"mc":[{"id":"1.195453700","rc":[{"atb":[[11,0],[9.4,0]],"id":41419586},{"atb":[[65,0],[46,0]],"id":41419611}],"con":true,"img":false}]}
{"op":"mcm","clk":"5347694213","pt":1646205602173,"mc":[{"id":"1.195453700","rc":[{"atb":[[44,0],[60,0]],"id":41419619},{"atb":[[44,4.65],[60,0]],"id":41419603},{"atb":[[42,4.87],[55,0]],"id":41419624},{"atb":[[65,0],[46,0]],"id":41419604},{"atb":[[65,0],[46,0]],"id":41419633},{"atb":[[70,2.72],[48,3.27]],"id":41419596}],"con":true,"img":false}]}
{"op":"mcm","clk":"5347694223","pt":1646205602285,"mc":[{"id":"1.195453700","rc":[{"atb":[[80,0],[55,0]],"id":41419597},{"atb":[[20,0],[25,0]],"id":41419606},{"atb":[[70,0],[48,0]],"id":41419614},{"atb":[[65,0],[46,0]],"id":41419631},{"atb":[[65,0],[44,3.27],[46,0],[60,2.72]],"id":41419616},{"atb":[[65,2.72],[46,3.27]],"id":41419612},{"atb":[[42,3.27],[44,4.65],[55,2.72],[60,0]],"id":41419625},{"atb":[[65,0],[46,0]],"id":41419621},{"atb":[[11,2.72],[9.4,3.27]],"id":41419588},{"atb":[[75,0],[50,4.08]],"id":41419596}],"con":true,"img":false}]}
{"op":"mcm","clk":"5347694232","pt":1646205602390,"mc":[{"id":"1.195453700","rc":[{"atb":[[70,0],[48,0]],"id":41419635},{"atb":[[10,3.27],[12.5,2.72]],"id":41419585},{"atb":[[44,7.93],[60,2.72]],"id":41419610},{"atb":[[6.8,2.72],[5.9,3.27]],"id":41419590},{"atb":[[80,2.72],[55,3.27]],"id":41419598},{"atb":[[16.5,12.9],[19,0]],"id":41419627},{"atb":[[80,0],[55,0]],"id":41419594},{"atb":[[65,0],[46,0]],"id":41419640},{"atb":[[70,0],[48,0]],"id":41419607},{"atb":[[65,0],[44,7.93],[46,0],[60,2.72]],"id":41419632},{"atb":[[65,2.72],[46,3.27]],"id":41419637}],"con":true,"img":false}]}
{"op":"mcm","clk":"5347694238","pt":1646205602493,"mc":[{"id":"1.195453700","rc":[{"atb":[[65,0],[44,3.27],[46,0],[60,2.72]],"id":41419609},{"atb":[[80,2.72],[55,3.27]],"id":41419593},{"atb":[[44,0],[60,0]],"id":41419602},{"atb":[[65,0],[44,3.27],[46,0],[60,2.72]],"id":41419636},{"atb":[[22,3.27],[27,2.72]],"id":41419599}],"con":true,"img":false}]}
{"op":"mcm","clk":"5347694246","pt":1646205602596,"mc":[{"id":"1.195453700","rc":[{"atb":[[65,2.72],[46,3.27]],"id":41419618},{"atb":[[65,2.72],[46,3.27]],"id":41419630},{"atb":[[42,8.15],[44,0],[55,2.72],[60,0]],"id":41419623},{"atb":[[11,2.72],[9.4,3.27]],"id":41419591},{"atb":[[65,2.72],[46,3.27]],"id":41419629}],"con":true,"img":false}]}
{"op":"mcm","clk":"5347694267","pt":1646205602849,"mc":[{"id":"1.195453700","rc":[{"atb":[[44,3.27],[60,2.72]],"id":41419619},{"atb":[[11,2.72],[9.4,3.27]],"id":41419586},{"atb":[[44,7.93],[60,2.72]],"id":41419603},{"atb":[[65,2.72],[46,3.27]],"id":41419611},{"atb":[[42,8.15],[55,2.72]],"id":41419624},{"atb":[[65,2.72],[46,3.27]],"id":41419604},{"atb":[[65,2.72],[46,3.27]],"id":41419633}],"con":true,"img":false}]}
{"op":"mcm","clk":"5347694277","pt":1646205602955,"mc":[{"id":"1.195453700","rc":[{"atb":[[70,2.72],[48,3.27]],"id":41419614},{"atb":[[65,2.72],[46,3.27]],"id":41419631}],"con":true,"img":false}]}
{"op":"mcm","clk":"5347694286","pt":1646205603065,"mc":[{"id":"1.195453700","rc":[{"atb":[[80,2.72],[55,3.27]],"id":41419597},{"atb":[[20,3.27],[25,2.72]],"id":41419606},{"atb":[[70,2.72],[48,3.27]],"id":41419635},{"atb":[[16.5,16.18],[19,2.72]],"id":41419627},{"atb":[[80,2.72],[55,3.27]],"id":41419594},{"atb":[[65,2.72],[46,3.27]],"id":41419640},{"atb":[[70,2.72],[48,3.27]],"id":41419607},{"atb":[[65,2.72],[46,3.27]],"id":41419621}],"con":true,"img":false}]}
{"op":"mcm","clk":"5347694290","pt":1646205603159,"mc":[{"id":"1.195453700","rc":[{"atb":[[44,3.27],[60,2.72]],"id":41419602}],"con":true,"img":false}]}
{"op":"mcm","clk":"5347698617","pt":1646205704905,"mc":[{"id":"1.195453700","rc":[{"atb":[[44,0],[60,0]],"id":41419605},{"atb":[[44,0],[60,0]],"id":41419601},{"atb":[[44,0],[60,0]],"id":41419619},{"atb":[[44,0],[60,0]],"id":41419615},{"atb":[[44,0],[60,0]],"id":41419608}],"con":true,"img":false}]}
{"op":"mcm","clk":"5347698628","pt":1646205705213,"mc":[{"id":"1.195453700","rc":[{"atb":[[44,0],[60,0]],"id":41419638}],"con":true,"img":false}]}
{"op":"mcm","clk":"5347698644","pt":1646205705623,"mc":[{"id":"1.195453700","rc":[{"atb":[[65,2.72],[46,3.27]],"id":41419605},{"atb":[[65,2.72],[46,3.27]],"id":41419601},{"atb":[[65,2.72],[46,3.27]],"id":41419619},{"atb":[[65,2.72],[46,3.27]],"id":41419615},{"atb":[[65,2.72],[46,3.27]],"id":41419608}],"con":true,"img":false}]}
{"op":"mcm","clk":"5347698668","pt":1646205706190,"mc":[{"id":"1.195453700","rc":[{"atb":[[65,2.72],[46,3.27]],"id":41419638}],"con":true,"img":false}]}
{"op":"mcm","clk":"5347704698","pt":1646205855298,"mc":[{"id":"1.195453700","rc":[{"atb":[[10,0],[12.5,0]],"id":41419585},{"atb":[[6.8,0],[5.9,0]],"id":41419590},{"atb":[[16.5,12.9],[19,0]],"id":41419627},{"atb":[[25,0],[30,0]],"id":41419592}],"con":true,"img":false}]}
{"op":"mcm","clk":"5347704737","pt":1646205856017,"mc":[{"id":"1.195453700","rc":[{"atb":[[5.6,3.27],[6.2,2.72]],"id":41419590}],"con":true,"img":false}]}
{"op":"mcm","clk":"5347704741","pt":1646205856120,"mc":[{"id":"1.195453700","rc":[{"atb":[[12,2.72],[9.8,3.27]],"id":41419585},{"atb":[[16,3.27],[18.5,2.72]],"id":41419627},{"atb":[[32,2.72],[26,3.27]],"id":41419592}],"con":true,"img":false}]}
{"op":"mcm","clk":"5347708075","pt":1646205933608,"mc":[{"id":"1.195453700","rc":[{"atb":[[32,0],[26,0]],"id":41419592}],"con":true,"img":false}]}
{"op":"mcm","clk":"5347708104","pt":1646205934279,"mc":[{"id":"1.195453700","rc":[{"atb":[[25,3.27],[30,2.72]],"id":41419592}],"con":true,"img":false}]}
{"op":"mcm","clk":"5347711062","pt":1646206033653,"mc":[{"id":"1.195453700","rc":[{"atb":[[48,0]],"id":41419596}],"con":true,"img":false}]}
{"op":"mcm","clk":"5347711076","pt":1646206033962,"mc":[{"id":"1.195453700","rc":[{"atb":[[44,0],[60,0]],"id":41419609},{"atb":[[44,0],[60,0]],"id":41419636},{"atb":[[44,0],[60,0]],"id":41419616},{"atb":[[70,0]],"id":41419596}],"con":true,"img":false}]}
{"op":"mcm","clk":"5347711087","pt":1646206034372,"mc":[{"id":"1.195453700","rc":[{"atb":[[50,7.35]],"id":41419596}],"con":true,"img":false}]}
{"op":"mcm","clk":"5347711097","pt":1646206034682,"mc":[{"id":"1.195453700","rc":[{"atb":[[65,2.72],[46,3.27]],"id":41419609},{"atb":[[44,0],[60,0]],"id":41419602},{"atb":[[65,2.72],[46,3.27]],"id":41419636},{"atb":[[65,2.72],[46,3.27]],"id":41419616},{"atb":[[75,2.72]],"id":41419596}],"con":true,"img":false}]}
{"op":"mcm","clk":"5347711128","pt":1646206035403,"mc":[{"id":"1.195453700","rc":[{"atb":[[65,2.72]],"id":41419602}],"con":true,"img":false}]}
{"op":"mcm","clk":"5347711145","pt":1646206035763,"mc":[{"id":"1.195453700","rc":[{"atb":[[46,3.27]],"id":41419602}],"con":true,"img":false}]}
{"op":"mcm","clk":"5347719613","pt":1646206262017,"mc":[{"id":"1.195453700","rc":[{"atb":[[6.2,0]],"id":41419590}],"con":true,"img":false}]}
{"op":"mcm","clk":"5347719636","pt":1646206262430,"mc":[{"id":"1.195453700","rc":[{"atb":[[12,0],[9.8,0]],"id":41419585},{"atb":[[5.6,0]],"id":41419590},{"atb":[[16,0],[18.5,0]],"id":41419627}],"con":true,"img":false}]}
{"op":"mcm","clk":"5347719654","pt":1646206262737,"mc":[{"id":"1.195453700","rc":[{"atb":[[6.8,2.72]],"id":41419590}],"con":true,"img":false}]}
{"op":"mcm","clk":"5347719691","pt":1646206263461,"mc":[{"id":"1.195453700","rc":[{"atb":[[10,3.27],[12.5,2.72]],"id":41419585},{"atb":[[5.9,3.27]],"id":41419590},{"atb":[[16.5,16.18],[19,2.72]],"id":41419627}],"con":true,"img":false}]}
{"op":"mcm","clk":"5347720146","pt":1646206272731,"mc":[{"id":"1.195453700","rc":[{"atb":[[22,4.76]],"id":41419609},{"atl":[[1000,2]],"id":41419609},{"atb":[[26,4]],"id":41419638},{"atb":[[21,5]],"id":41419605},{"atb":[[6.2,19.23]],"id":41419634},{"atl":[[620,2]],"id":41419634},{"atb":[[26,4]],"id":41419617},{"atb":[[5.5,22.22]],"id":41419613},{"atl":[[570,2]],"id":41419613},{"atb":[[21,5]],"id":41419593},{"atb":[[21,15]],"id":41419622},{"atb":[[3.8,35.71]],"id":41419589},{"atl":[[470,2]],"id":41419589},{"atb":[[10.5,8.16]],"id":41419618},{"atl":[[920,2]],"id":41419618},{"atb":[[27,3.85]],"id":41419601},{"atb":[[17,6.25]],"id":41419630},{"atl":[[1000,2]],"id":41419630},{"atb":[[10,6.56]],"id":41419597},{"atl":[[900,2]],"id":41419597},{"atb":[[26,4]],"id":41419626},{"atb":[[26,4]],"id":41419639},{"atb":[[4.7,26.68]],"id":41419606},{"atl":[[530,2]],"id":41419606},{"atb":[[26,4]],"id":41419635},{"atb":[[21,5]],"id":41419602},{"atb":[[3.45,33.36]],"id":41419585},{"atl":[[390,2]],"id":41419585},{"atb":[[25,4.17]],"id":41419614},{"atl":[[1000,2]],"id":41419614},{"atb":[[26,4]],"id":41419610},{"atl":[[1000,2]],"id":41419610},{"atb":[[21,15]],"id":41419623},{"atb":[[2.74,44.46]],"id":41419590},{"atl":[[170,2]],"id":41419590},{"atb":[[25,4.17]],"id":41419619},{"atl":[[1000,2]],"id":41419619},{"atb":[[5,25]],"id":41419586},{"atl":[[520,2]],"id":41419586},{"atb":[[14.5,7.41]],"id":41419631},{"atl":[[1000,2]],"id":41419631},{"atb":[[21,5]],"id":41419598},{"atl":[[1000,2]],"id":41419598},{"atb":[[3.9,34.48]],"id":41419627},{"atl":[[480,2]],"id":41419627},{"atb":[[21,5]],"id":41419594},{"atb":[[12.5,8.16]],"id":41419640},{"atl":[[980,2]],"id":41419640},{"atb":[[20,5.26]],"id":41419607},{"atl":[[1000,2]],"id":41419607},{"atb":[[28,3.7]],"id":41419636},{"atb":[[21,5]],"id":41419603},{"atb":[[27,3.85]],"id":41419615},{"atb":[[8,8.16]],"id":41419611},{"atl":[[840,2]],"id":41419611},{"atb":[[21,15]],"id":41419624},{"atb":[[3.45,40.82]],"id":41419591},{"atl":[[380,2]],"id":41419591},{"atb":[[6.8,17.24]],"id":41419620},{"atl":[[700,2]],"id":41419620},{"atb":[[3.7,37.04]],"id":41419587},{"atl":[[440,2]],"id":41419587},{"atb":[[17,6.25]],"id":41419632},{"atl":[[1000,2]],"id":41419632},{"atb":[[6.8,17.24]],"id":41419599},{"atl":[[700,2]],"id":41419599},{"atb":[[12,6.56]],"id":41419628},{"atl":[[970,2]],"id":41419628},{"atb":[[26,4]],"id":41419595},{"atl":[[1000,2]],"id":41419595},{"atb":[[27,3.85]],"id":41419608},{"atb":[[10.5,8.52]],"id":41419637},{"atb":[[22,4.76]],"id":41419604},{"atl":[[1000,2]],"id":41419604},{"atb":[[26,4]],"id":41419616},{"atb":[[10.5,8.52]],"id":41419612},{"atl":[[1000,2]],"id":41419612},{"atb":[[18,5.88]],"id":41419625},{"atl":[[1000,2]],"id":41419625},{"atb":[[5.3,22.24]],"id":41419592},{"atl":[[560,2]],"id":41419592},{"atb":[[27,3.85]],"id":41419621},{"atb":[[3.6,38.46]],"id":41419588},{"atl":[[420,2]],"id":41419588},{"atb":[[10,8.16]],"id":41419633},{"atl":[[910,2]],"id":41419633},{"atb":[[21,5]],"id":41419600},{"atb":[[26,4]],"id":41419629},{"atb":[[26,4]],"id":41419596}],"con":true,"img":false}]}
{"op":"mcm","clk":"5347734325","pt":1646206667725,"mc":[{"id":"1.195453700","rc":[{"atb":[[9.6,0],[8.6,0]],"id":41419589}],"con":true,"img":false}]}
{"op":"mcm","clk":"5347734335","pt":1646206668033,"mc":[{"id":"1.195453700","rc":[{"atb":[[18.5,0],[22,0]],"id":41419620}],"con":true,"img":false}]}
{"op":"mcm","clk":"5347734350","pt":1646206668446,"mc":[{"id":"1.195453700","rc":[{"atb":[[9.8,2.72],[8.8,3.27]],"id":41419589}],"con":true,"img":false}]}
{"op":"mcm","clk":"5347734367","pt":1646206668702,"mc":[{"id":"1.195453700","rc":[{"atb":[[19,3.27],[23,2.72]],"id":41419620}],"con":true,"img":false}]}
{"op":"mcm","clk":"5347734496","pt":1646206671944,"mc":[{"id":"1.195453700","rc":[{"atb":[[22,0],[27,0]],"id":41419634}],"con":true,"img":false}]}
{"op":"mcm","clk":"5347734505","pt":1646206672253,"mc":[{"id":"1.195453700","rc":[{"atb":[[22,0],[27,0]],"id":41419613},{"atb":[[10,0],[12.5,0]],"id":41419585},{"atb":[[22,0],[27,0]],"id":41419599}],"con":true,"img":false}]}
{"op":"mcm","clk":"5347734518","pt":1646206672612,"mc":[{"id":"1.195453700","rc":[{"atb":[[23,3.27],[28,2.72]],"id":41419634}],"con":true,"img":false}]}
{"op":"mcm","clk":"5347734532","pt":1646206672919,"mc":[{"id":"1.195453700","rc":[{"atb":[[23,3.27],[28,2.72]],"id":41419613}],"con":true,"img":false}]}
{"op":"mcm","clk":"5347734537","pt":1646206673022,"mc":[{"id":"1.195453700","rc":[{"atb":[[12,2.72],[9.8,3.27]],"id":41419585},{"atb":[[23,3.27],[28,2.72]],"id":41419599}],"con":true,"img":false}]}
{"op":"mcm","clk":"5347735054","pt":1646206685767,"mc":[{"id":"1.195453700","rc":[{"atl":[[450,2]],"id":41419589},{"atl":[[810,2],[900,0]],"id":41419597},{"atl":[[520,0]],"id":41419586},{"atb":[[3.9,0]],"id":41419627},{"atl":[[1000,2]],"id":41419594},{"atb":[[17.5,22.22],[12.5,0]],"id":41419640},{"atl":[[440,0]],"id":41419587},{"atb":[[17,0]],"id":41419632},{"atl":[[970,0]],"id":41419628},{"atb":[[18,0],[24,4.35]],"id":41419625},{"atl":[[520,2],[560,0]],"id":41419592},{"atl":[[410,2],[420,0]],"id":41419588}],"con":true,"img":false}]}
{"op":"mcm","clk":"5347735061","pt":1646206685872,"mc":[{"id":"1.195453700","rc":[{"atb":[[22,0],[28,3.7]],"id":41419609},{"atb":[[6.2,19.23],[5.5,0]],"id":41419613},{"atl":[[470,0]],"id":41419589},{"atb":[[10.5,0],[14,7.69]],"id":41419618},{"atb":[[17,0],[24,4.35]],"id":41419630},{"atb":[[4.7,0],[5.4,22.73]],"id":41419606},{"atl":[[320,2],[390,0]],"id":41419585},{"atl":[[1000,0]],"id":41419610},{"atb":[[2.74,0],[2.84,44.46]],"id":41419590},{"atl":[[150,2],[170,0]],"id":41419590},{"atl":[[510,2]],"id":41419586},{"atb":[[20,5.26],[14.5,0]],"id":41419631},{"atb":[[4.3,30.3]],"id":41419627},{"atb":[[8,0],[10.5,8.16]],"id":41419611},{"atl":[[360,2],[380,0]],"id":41419591},{"atl":[[430,2]],"id":41419587},{"atb":[[24,4.35]],"id":41419632},{"atl":[[920,2]],"id":41419628},{"atb":[[22,0],[27,3.85]],"id":41419604},{"atb":[[10,0],[13.5,8]],"id":41419633},{"atl":[[1000,2]],"id":41419596}],"con":true,"img":false}]}
{"op":"mcm","clk":"5347735067","pt":1646206686077,"mc":[{"id":"1.195453700","rc":[{"atb":[[80,0],[55,0]],"id":41419597},{"atb":[[20,0],[25,0]],"id":41419606},{"atb":[[6.8,0],[5.9,0]],"id":41419590}],"con":true,"img":false}]}
{"op":"mcm","clk":"5347735072","pt":1646206686179,"mc":[{"id":"1.195453700","rc":[{"atb":[[12,0],[9.8,0]],"id":41419585},{"atb":[[16.5,12.9],[19,0]],"id":41419627},{"atb":[[25,0],[30,0]],"id":41419592}],"con":true,"img":false}]}
{"op":"mcm","clk":"5347735102","pt":1646206686744,"mc":[{"id":"1.195453700","rc":[{"atb":[[5.8,3.27],[6.6,2.72]],"id":41419590}],"con":true,"img":false}]}
{"op":"mcm","clk":"5347735108","pt":1646206686848,"mc":[{"id":"1.195453700","rc":[{"atb":[[70,5.62],[48,3.27]],"id":41419597},{"atb":[[23,3.27],[28,2.72]],"id":41419606},{"atb":[[9,3.27],[10,2.72]],"id":41419585},{"atb":[[18,3.27],[21,2.72]],"id":41419627},{"atb":[[19.5,3.27],[24,2.72]],"id":41419592}],"con":true,"img":false}]}
{"op":"mcm","clk":"5347736359","pt":1646206713330,"mc":[{"id":"1.195453700","rc":[{"atb":[[3.6,0]],"id":41419588},{"atl":[[1000,0]],"id":41419596}],"con":true,"img":false}]}
{"op":"mcm","clk":"5347736362","pt":1646206713435,"mc":[{"id":"1.195453700","rc":[{"atl":[[620,0],[610,2]],"id":41419634},{"atl":[[570,0],[550,2]],"id":41419613},{"atb":[[14,0]],"id":41419618},{"atl":[[880,2],[920,0]],"id":41419618},{"atb":[[18.5,5.71],[24,0]],"id":41419630},{"atl":[[530,0],[520,2]],"id":41419606},{"atl":[[1000,2]],"id":41419610},{"atb":[[20,0],[15.5,6.9]],"id":41419631},{"atl":[[960,2],[1000,0]],"id":41419631},{"atl":[[470,2],[480,0]],"id":41419627},{"atb":[[17.5,16.16],[14,7.69]],"id":41419640},{"atl":[[930,2],[980,0]],"id":41419640},{"atb":[[10.5,0],[8.8,12.24]],"id":41419611},{"atl":[[800,2],[840,0]],"id":41419611},{"atl":[[670,2],[700,0]],"id":41419620},{"atb":[[3.95,33.9],[3.7,0]],"id":41419587},{"atb":[[19,5.56],[24,0]],"id":41419632},{"atl":[[700,0],[680,2]],"id":41419599},{"atl":[[1000,2]],"id":41419616},{"atb":[[24,0]],"id":41419625},{"atb":[[3.85,35.09]],"id":41419588},{"atb":[[13.5,0]],"id":41419633},{"atl":[[870,2],[910,0]],"id":41419633},{"atl":[[1000,2]],"id":41419629}],"con":true,"img":false}]}
{"op":"mcm","clk":"5347736367","pt":1646206713486,"mc":[{"id":"1.195453700","rc":[{"atb":[[11.5,9.52]],"id":41419618},{"atb":[[19.5,5.41]],"id":41419625},{"atb":[[11,10]],"id":41419633}],"con":true,"img":false}]}
{"op":"mcm","clk":"5347736373","pt":1646206713693,"mc":[{"id":"1.195453700","rc":[{"atb":[[18,0],[21,0]],"id":41419627}],"con":true,"img":false}]}
{"op":"mcm","clk":"5347736392","pt":1646206714002,"mc":[{"id":"1.195453700","rc":[{"atb":[[23,0],[28,0]],"id":41419606}],"con":true,"img":false}]}
{"op":"mcm","clk":"5347736416","pt":1646206714414,"mc":[{"id":"1.195453700","rc":[{"atb":[[16.5,16.18],[19,2.72]],"id":41419627}],"con":true,"img":false}]}
{"op":"mcm","clk":"5347736431","pt":1646206714723,"mc":[{"id":"1.195453700","rc":[{"atb":[[20,3.27],[25,2.72]],"id":41419606}],"con":true,"img":false}]}
{"op":"mcm","clk":"5347740951","pt":1646206833395,"mc":[{"id":"1.195453700","rc":[{"atb":[[22,4.76],[28,0]],"id":41419609},{"atb":[[6.2,0],[5.5,22.22]],"id":41419613},{"atb":[[5.4,0],[4.7,27.03]],"id":41419606},{"atl":[[1000,0]],"id":41419594},{"atb":[[27,0]],"id":41419604},{"atl":[[1000,0]],"id":41419616},{"atl":[[1000,0]],"id":41419629}],"con":true,"img":false}]}
{"op":"mcm","clk":"5347740955","pt":1646206833497,"mc":[{"id":"1.195453700","rc":[{"atb":[[22,4.76]],"id":41419604}],"con":true,"img":false}]}
{"op":"mcm","clk":"5347748214","pt":1646207010059,"mc":[{"id":"1.195453700","rc":[{"atb":[[9,0],[10,0]],"id":41419585},{"atb":[[6.6,0]],"id":41419590},{"atb":[[19.5,0],[24,0]],"id":41419592}],"con":true,"img":false}]}
{"op":"mcm","clk":"5347748218","pt":1646207010162,"mc":[{"id":"1.195453700","rc":[{"atb":[[5.8,0]],"id":41419590}],"con":true,"img":false}]}
{"op":"mcm","clk":"5347748243","pt":1646207010778,"mc":[{"id":"1.195453700","rc":[{"atb":[[6.8,2.72]],"id":41419590}],"con":true,"img":false}]}
{"op":"mcm","clk":"5347748258","pt":1646207011085,"mc":[{"id":"1.195453700","rc":[{"atb":[[12,2.72],[9.8,3.27]],"id":41419585}],"con":true,"img":false}]}
{"op":"mcm","clk":"5347748263","pt":1646207011188,"mc":[{"id":"1.195453700","rc":[{"atb":[[5.9,3.27]],"id":41419590},{"atb":[[25,3.27],[30,2.72]],"id":41419592}],"con":true,"img":false}]}
{"op":"mcm","clk":"5347753694","pt":1646207139581,"mc":[{"id":"1.195453700","rc":[{"atb":[[65,0],[46,0]],"id":41419630},{"atb":[[65,0],[46,0]],"id":41419631},{"atb":[[44,4.65],[60,0]],"id":41419632},{"atb":[[42,0],[55,0]],"id":41419625},{"atb":[[65,0],[46,0]],"id":41419633},{"atb":[[65,0],[46,0]],"id":41419629}],"con":true,"img":false}]}
{"op":"mcm","clk":"5347753754","pt":1646207140004,"mc":[{"id":"1.195453700","rc":[{"atb":[[17,6.25]],"id":41419632}],"con":true,"img":false}]}
{"op":"mcm","clk":"5347753778","pt":1646207140107,"mc":[{"id":"1.195453700","rc":[{"atb":[[19,0]],"id":41419632}],"con":true,"img":false}]}
{"op":"mcm","clk":"5347753798","pt":1646207140270,"mc":[{"id":"1.195453700","rc":[{"atb":[[70,2.72],[48,3.27]],"id":41419630},{"atb":[[65,2.72],[46,3.27]],"id":41419632},{"atb":[[44,7.93],[60,2.72]],"id":41419625},{"atb":[[70,2.72],[48,3.27]],"id":41419633},{"atb":[[70,2.72],[48,3.27]],"id":41419629}],"con":true,"img":false}]}
{"op":"mcm","clk":"5347753824","pt":1646207140477,"mc":[{"id":"1.195453700","rc":[{"atb":[[70,2.72],[48,3.27]],"id":41419631}],"con":true,"img":false}]}
{"op":"mcm","clk":"5347765710","pt":1646207353121,"mc":[{"id":"1.195453700","rc":[{"atb":[[22,0],[28,3.7]],"id":41419609},{"atb":[[6.2,19.23],[5.5,0]],"id":41419613},{"atb":[[11.5,0],[14,7.69]],"id":41419618},{"atb":[[18.5,0],[24,4.35]],"id":41419630},{"atb":[[4.7,0],[5.4,22.73]],"id":41419606},{"atl":[[1000,0]],"id":41419610},{"atb":[[20,5.26],[15.5,0]],"id":41419631},{"atl":[[1000,2]],"id":41419594},{"atb":[[17.5,22.22],[14,0]],"id":41419640},{"atb":[[10.5,10.53],[8.8,0]],"id":41419611},{"atb":[[17,0],[24,4.35]],"id":41419632},{"atb":[[22,0],[27,3.85]],"id":41419604},{"atb":[[19.5,0],[24,4.35]],"id":41419625},{"atb":[[11,0],[13.5,8]],"id":41419633},{"atl":[[1000,2]],"id":41419596}],"con":true,"img":false}]}
{"op":"mcm","clk":"5347765726","pt":1646207353418,"mc":[{"id":"1.195453700","rc":[{"atb":[[20,0],[25,0]],"id":41419606},{"atb":[[12,0],[9.8,0]],"id":41419585},{"atb":[[6.8,0],[5.9,0]],"id":41419590},{"atb":[[25,0],[30,0]],"id":41419592}],"con":true,"img":false}]}
{"op":"mcm","clk":"5347765765","pt":1646207354093,"mc":[{"id":"1.195453700","rc":[{"atb":[[9,3.27],[10,2.72]],"id":41419585},{"atb":[[5.8,3.27],[6.6,2.72]],"id":41419590},{"atb":[[19.5,3.27],[24,2.72]],"id":41419592}],"con":true,"img":false}]}
{"op":"mcm","clk":"5347765773","pt":1646207354300,"mc":[{"id":"1.195453700","rc":[{"atb":[[22,3.27],[27,2.72]],"id":41419606}],"con":true,"img":false}]}
{"op":"mcm","clk":"5347766631","pt":1646207373257,"mc":[{"id":"1.195453700","rc":[{"atb":[[14,0]],"id":41419618},{"atb":[[18.5,5.71],[24,0]],"id":41419630},{"atl":[[1000,2]],"id":41419610},{"atb":[[20,0],[15.5,6.9]],"id":41419631},{"atb":[[17.5,16.16],[14,7.69]],"id":41419640},{"atb":[[10.5,0],[8.8,12.42]],"id":41419611},{"atb":[[19,5.56],[24,0]],"id":41419632},{"atl":[[1000,2]],"id":41419616},{"atb":[[24,0]],"id":41419625},{"atb":[[13.5,0]],"id":41419633},{"atl":[[1000,2]],"id":41419629},{"atl":[[1000,0]],"id":41419596}],"con":true,"img":false}]}
{"op":"mcm","clk":"5347766643","pt":1646207373461,"mc":[{"id":"1.195453700","rc":[{"atb":[[11.5,8.16]],"id":41419618},{"atb":[[19.5,5.41]],"id":41419625},{"atb":[[11,8.16]],"id":41419633}],"con":true,"img":false}]}
{"op":"mcm","clk":"5347766660","pt":1646207373728,"mc":[{"id":"1.195453700","rc":[{"atb":[[22,0],[27,0]],"id":41419606}],"con":true,"img":false}]}
{"op":"mcm","clk":"5347766712","pt":1646207374754,"mc":[{"id":"1.195453700","rc":[{"atb":[[20,3.27],[25,2.72]],"id":41419606}],"con":true,"img":false}]}
{"op":"mcm","clk":"5347772693","pt":1646207493290,"mc":[{"id":"1.195453700","rc":[{"atb":[[22,4.76],[28,0]],"id":41419609},{"atb":[[6.2,0],[5.5,22.22]],"id":41419613},{"atb":[[5.4,0],[4.7,27.03]],"id":41419606},{"atl":[[1000,0]],"id":41419594},{"atb":[[27,0]],"id":41419604},{"atl":[[1000,0]],"id":41419616},{"atl":[[1000,0]],"id":41419629}],"con":true,"img":false}]}
{"op":"mcm","clk":"5347772704","pt":1646207493391,"mc":[{"id":"1.195453700","rc":[{"atb":[[22,4.76]],"id":41419604}],"con":true,"img":false}]}
{"op":"mcm","clk":"5347779228","pt":1646207610437,"mc":[{"id":"1.195453700","rc":[{"atb":[[10,0]],"id":41419585}],"con":true,"img":false}]}
{"op":"mcm","clk":"5347779256","pt":1646207610707,"mc":[{"id":"1.195453700","rc":[{"atb":[[9,0]],"id":41419585},{"atb":[[5.8,0],[6.6,0]],"id":41419590},{"atb":[[19.5,0],[24,0]],"id":41419592}],"con":true,"img":false}]}
{"op":"mcm","clk":"5347779295","pt":1646207611129,"mc":[{"id":"1.195453700","rc":[{"atb":[[12,2.72]],"id":41419585}],"con":true,"img":false}]}
{"op":"mcm","clk":"5347779336","pt":1646207611407,"mc":[{"id":"1.195453700","rc":[{"atb":[[9.8,3.27]],"id":41419585},{"atb":[[6.8,2.72],[5.9,3.27]],"id":41419590},{"atb":[[25,3.27],[30,2.72]],"id":41419592}],"con":true,"img":false}]}
{"op":"mcm","clk":"5347780732","pt":1646207636935,"mc":[{"id":"1.195453700","rc":[{"atb":[[21,0],[27,3.85]],"id":41419605},{"atb":[[21,0],[27,3.85]],"id":41419593},{"atb":[[21,10],[28,3.7]],"id":41419622},{"atb":[[18,5.88],[26,0]],"id":41419626},{"atb":[[21,0],[27,3.85]],"id":41419602},{"atb":[[21,10],[27,3.85]],"id":41419623},{"atb":[[21,0],[14.5,7.41]],"id":41419598},{"atb":[[21,0],[26,4]],"id":41419594},{"atb":[[21,0],[28,3.7]],"id":41419603},{"atb":[[21,10],[27,3.85]],"id":41419624},{"atb":[[10.5,0],[22,4.76]],"id":41419637},{"atb":[[22,0],[11,8.84]],"id":41419604},{"atb":[[19,5.56],[10.5,0]],"id":41419612},{"atb":[[21,0],[27,3.85]],"id":41419600},{"atb":[[11,8.08],[26,0]],"id":41419629}],"con":true,"img":false}]}
{"op":"mcm","clk":"5347799932","pt":1646208062075,"mc":[{"id":"1.195453700","rc":[{"atb":[[23,0],[28,0]],"id":41419613},{"atb":[[9.8,0],[8.8,0]],"id":41419589},{"atb":[[65,0],[46,0]],"id":41419618},{"atb":[[11,0],[9.4,0]],"id":41419591},{"atb":[[11,0],[9.4,0]],"id":41419587},{"atb":[[23,0],[28,0]],"id":41419599},{"atb":[[65,0],[46,0]],"id":41419604},{"atb":[[11,0],[9.4,0]],"id":41419588}],"con":true,"img":false}]}
{"op":"mcm","clk":"5347799935","pt":1646208062177,"mc":[{"id":"1.195453700","rc":[{"atb":[[11,0],[9.4,0]],"id":41419586}],"con":true,"img":false}]}
{"op":"mcm","clk":"5347799968","pt":1646208062796,"mc":[{"id":"1.195453700","rc":[{"atb":[[24,3.27],[29,2.72]],"id":41419613},{"atb":[[9,3.27],[10,2.72]],"id":41419589},{"atb":[[70,2.72],[48,3.27]],"id":41419618},{"atb":[[9.6,26.54],[11.5,2.72]],"id":41419591},{"atb":[[9.6,26.54],[11.5,2.72]],"id":41419587},{"atb":[[24,3.27],[29,2.72]],"id":41419599},{"atb":[[70,2.72],[48,3.27]],"id":41419604}],"con":true,"img":false}]}
{"op":"mcm","clk":"5347799975","pt":1646208062901,"mc":[{"id":"1.195453700","rc":[{"atb":[[9.6,26.54],[11.5,2.72]],"id":41419586},{"atb":[[9.6,26.54],[11.5,2.72]],"id":41419588}],"con":true,"img":false}]}
{"op":"mcm","clk":"5347800095","pt":1646208065952,"mc":[{"id":"1.195453700","rc":[{"atb":[[65,0],[46,0]],"id":41419609},{"atb":[[65,0],[46,0]],"id":41419601},{"atb":[[44,4.65],[60,0]],"id":41419610},{"atb":[[42,4.87],[55,0]],"id":41419623},{"atb":[[65,0],[46,0]],"id":41419616},{"atb":[[65,0],[46,0]],"id":41419612}],"con":true,"img":false}]}
{"op":"mcm","clk":"5347800105","pt":1646208066263,"mc":[{"id":"1.195453700","rc":[{"atb":[[65,0],[46,0]],"id":41419608}],"con":true,"img":false}]}
{"op":"mcm","clk":"5347800121","pt":1646208066674,"mc":[{"id":"1.195453700","rc":[{"atb":[[70,2.72],[48,7.53]],"id":41419609},{"atb":[[70,2.72],[48,7.53]],"id":41419601},{"atb":[[65,2.72],[46,3.27]],"id":41419610},{"atb":[[44,3.27],[60,2.72]],"id":41419623},{"atb":[[70,2.72],[48,7.53]],"id":41419616},{"atb":[[70,2.72],[48,7.53]],"id":41419612}],"con":true,"img":false}]}
{"op":"mcm","clk":"5347800131","pt":1646208066979,"mc":[{"id":"1.195453700","rc":[{"atb":[[70,2.72],[48,7.53]],"id":41419608}],"con":true,"img":false}]}
{"op":"mcm","clk":"5347800197","pt":1646208068582,"mc":[{"id":"1.195453700","rc":[{"atb":[[29,0]],"id":41419613}],"con":true,"img":false}]}
{"op":"mcm","clk":"5347800216","pt":1646208068892,"mc":[{"id":"1.195453700","rc":[{"atb":[[24,0]],"id":41419613}],"con":true,"img":false}]}
{"op":"mcm","clk":"5347800237","pt":1646208069304,"mc":[{"id":"1.195453700","rc":[{"atb":[[28,2.72]],"id":41419613}],"con":true,"img":false}]}
{"op":"mcm","clk":"5347800256","pt":1646208069563,"mc":[{"id":"1.195453700","rc":[{"atb":[[23,3.27]],"id":41419613}],"con":true,"img":false}]}
{"op":"mcm","clk":"5347802265","pt":1646208123259,"mc":[{"id":"1.195453700","rc":[{"atb":[[22,0],[27,3.85]],"id":41419609},{"atl":[[600,2],[610,0]],"id":41419634},{"atb":[[6.2,19.23],[5.5,0]],"id":41419613},{"atl":[[440,2],[450,0]],"id":41419589},{"atb":[[18.5,0],[22,4.76]],"id":41419630},{"atb":[[10,0],[13,8.33]],"id":41419597},{"atb":[[5.3,23.26],[4.7,0]],"id":41419606},{"atl":[[1000,0]],"id":41419610},{"atb":[[19,5.56],[15.5,0]],"id":41419631},{"atb":[[20,0],[27,3.85]],"id":41419607},{"atb":[[11,10],[8.8,0]],"id":41419611},{"atb":[[27,0],[30,3.45]],"id":41419624},{"atb":[[3.45,0],[3.7,37.04]],"id":41419591},{"atl":[[320,2],[360,0]],"id":41419591},{"atb":[[8,14.29],[6.8,0]],"id":41419620},{"atl":[[670,0],[660,2]],"id":41419620},{"atl":[[410,2],[430,0]],"id":41419587},{"atb":[[8.2,13.89],[6.8,0]],"id":41419599},{"atb":[[16,6.56],[12,0]],"id":41419628},{"atl":[[1000,0]],"id":41419595},{"atb":[[5.3,0],[6,20]],"id":41419592}],"con":true,"img":false}]}
{"op":"mcm","clk":"5347802276","pt":1646208123560,"mc":[{"id":"1.195453700","rc":[{"atb":[[20,0],[25,0]],"id":41419606},{"atb":[[6.8,0],[5.9,0]],"id":41419590},{"atb":[[9.6,23.26],[11.5,0]],"id":41419591}],"con":true,"img":false}]}
{"op":"mcm","clk":"5347802281","pt":1646208123662,"mc":[{"id":"1.195453700","rc":[{"atb":[[65,0],[46,0]],"id":41419611},{"atb":[[25,0],[30,0]],"id":41419592}],"con":true,"img":false}]}
{"op":"mcm","clk":"5347802309","pt":1646208124380,"mc":[{"id":"1.195453700","rc":[{"atb":[[22,3.27],[27,2.72]],"id":41419606},{"atb":[[5.6,3.27],[6.2,2.72]],"id":41419590},{"atb":[[70,2.72],[48,3.27]],"id":41419611},{"atb":[[11,2.72],[9.4,3.27]],"id":41419591},{"atb":[[32,2.72],[26,3.27]],"id":41419592}],"con":true,"img":false}]}
{"op":"mcm","clk":"5347807096","pt":1646208243206,"mc":[{"id":"1.195453700","rc":[{"atl":[[450,2]],"id":41419589},{"atl":[[1000,0]],"id":41419614},{"atb":[[3.85,0]],"id":41419588}],"con":true,"img":false}]}
{"op":"mcm","clk":"5347807099","pt":1646208243310,"mc":[{"id":"1.195453700","rc":[{"atl":[[600,0],[610,2]],"id":41419634},{"atl":[[440,0]],"id":41419589},{"atb":[[2.66,55.58],[2.84,0]],"id":41419590},{"atl":[[660,0],[670,2]],"id":41419620},{"atl":[[410,0],[420,2]],"id":41419587},{"atb":[[3.55,39.22]],"id":41419588}],"con":true,"img":false}]}
{"op":"mcm","clk":"5347807289","pt":1646208248494,"mc":[{"id":"1.195453700","rc":[{"atb":[[11.5,0]],"id":41419587}],"con":true,"img":false}]}
{"op":"mcm","clk":"5347807293","pt":1646208248597,"mc":[{"id":"1.195453700","rc":[{"atb":[[9.6,23.26]],"id":41419587}],"con":true,"img":false}]}
{"op":"mcm","clk":"5347807324","pt":1646208249215,"mc":[{"id":"1.195453700","rc":[{"atb":[[12,2.72]],"id":41419587}],"con":true,"img":false}]}
{"op":"mcm","clk":"5347807340","pt":1646208249628,"mc":[{"id":"1.195453700","rc":[{"atb":[[9.8,3.27]],"id":41419587}],"con":true,"img":false}]}
{"op":"mcm","clk":"5347807583","pt":1646208254311,"mc":[{"id":"1.195453700","rc":[{"atb":[[23,0]],"id":41419613}],"con":true,"img":false}]}
{"op":"mcm","clk":"5347807627","pt":1646208255038,"mc":[{"id":"1.195453700","rc":[{"atb":[[24,3.27]],"id":41419613}],"con":true,"img":false}]}
{"op":"mcm","clk":"5347810887","pt":1646208335251,"mc":[{"id":"1.195453700","rc":[{"atb":[[24,0]],"id":41419613}],"con":true,"img":false}]}
{"op":"mcm","clk":"5347810922","pt":1646208335922,"mc":[{"id":"1.195453700","rc":[{"atb":[[23,3.27]],"id":41419613}],"con":true,"img":false}]}
{"op":"mcm","clk":"5347820339","pt":1646208554783,"mc":[{"id":"1.195453700","rc":[{"atb":[[13,8.33]],"id":41419628},{"atl":[[1000,2]],"id":41419596}],"con":true,"img":false}]}
{"op":"mcm","clk":"5347820342","pt":1646208554891,"mc":[{"id":"1.195453700","rc":[{"atb":[[11.5,0],[14,7.69]],"id":41419618},{"atb":[[9,12.5],[13,0]],"id":41419597},{"atl":[[1000,2]],"id":41419614},{"atb":[[2.66,0],[2.84,54.35]],"id":41419590},{"atl":[[1000,2]],"id":41419594},{"atb":[[17.5,22.22],[14,0]],"id":41419640},{"atb":[[27,0]],"id":41419607},{"atb":[[19,0],[24,4.35]],"id":41419632},{"atb":[[16,0]],"id":41419628},{"atl":[[1000,2]],"id":41419595},{"atb":[[19.5,0],[24,4.35]],"id":41419625},{"atb":[[6,0],[4.9,25.64]],"id":41419592},{"atb":[[3.8,35.71],[3.55,0]],"id":41419588},{"atb":[[11,0],[13.5,8]],"id":41419633}],"con":true,"img":false}]}
{"op":"mcm","clk":"5347820346","pt":1646208554980,"mc":[{"id":"1.195453700","rc":[{"atb":[[22,4.76]],"id":41419607}],"con":true,"img":false}]}
{"op":"mcm","clk":"5347820350","pt":1646208555089,"mc":[{"id":"1.195453700","rc":[{"atb":[[12,0],[9.8,0]],"id":41419585},{"atb":[[5.6,0],[6.2,0]],"id":41419590},{"atb":[[32,0],[26,0]],"id":41419592}],"con":true,"img":false}]}
{"op":"mcm","clk":"5347820356","pt":1646208555204,"mc":[{"id":"1.195453700","rc":[{"atb":[[22,0],[27,0]],"id":41419606}],"con":true,"img":false}]}
{"op":"mcm","clk":"5347820388","pt":1646208555776,"mc":[{"id":"1.195453700","rc":[{"atb":[[19.5,3.27],[24,2.72]],"id":41419592}],"con":true,"img":false}]}
{"op":"mcm","clk":"5347820392","pt":1646208555882,"mc":[{"id":"1.195453700","rc":[{"atb":[[23,3.27],[28,2.72]],"id":41419606},{"atb":[[9,3.27],[10,2.72]],"id":41419585},{"atb":[[5.8,3.27],[6.6,2.72]],"id":41419590}],"con":true,"img":false}]}
{"op":"mcm","clk":"5347820504","pt":1646208559492,"mc":[{"id":"1.195453700","rc":[{"atb":[[23,0],[28,0]],"id":41419634},{"atb":[[65,0],[46,0]],"id":41419640},{"atb":[[65,0],[46,0]],"id":41419637}],"con":true,"img":false}]}
{"op":"mcm","clk":"5347820527","pt":1646208560204,"mc":[{"id":"1.195453700","rc":[{"atb":[[24,3.27],[29,2.72]],"id":41419634},{"atb":[[70,2.72],[48,3.27]],"id":41419640},{"atb":[[70,2.72],[48,7.53]],"id":41419637}],"con":true,"img":false}]}
{"op":"mcm","clk":"5347822999","pt":1646208615192,"mc":[{"id":"1.195453700","rc":[{"atb":[[9,0],[10,0]],"id":41419589},{"atb":[[9.6,23.26],[11.5,0]],"id":41419586},{"atb":[[9.6,23.26],[11.5,0]],"id":41419588}],"con":true,"img":false}]}
{"op":"mcm","clk":"5347823039","pt":1646208615866,"mc":[{"id":"1.195453700","rc":[{"atb":[[9.8,2.72],[8.8,3.27]],"id":41419589},{"atb":[[11,2.72],[9.4,3.27]],"id":41419586},{"atb":[[11,2.72],[9.4,3.27]],"id":41419588}],"con":true,"img":false}]}
{"op":"mcm","clk":"5347824569","pt":1646208649710,"mc":[{"id":"1.195453700","rc":[{"atb":[[18,0],[21,15]],"id":41419626},{"atb":[[17.5,6.06],[14.5,0]],"id":41419598},{"atl":[[870,2]],"id":41419628},{"atb":[[26,4]],"id":41419612},{"atl":[[520,0],[510,2]],"id":41419592}],"con":true,"img":false}]}
{"op":"mcm","clk":"5347824576","pt":1646208649812,"mc":[{"id":"1.195453700","rc":[{"atl":[[920,0]],"id":41419628},{"atb":[[19,0]],"id":41419612}],"con":true,"img":false}]}
{"op":"mcm","clk":"5347825678","pt":1646208674834,"mc":[{"id":"1.195453700","rc":[{"atb":[[2.72,55.58],[2.84,0]],"id":41419590},{"atl":[[1000,0]],"id":41419619}],"con":true,"img":false}]}
{"op":"mcm","clk":"5347835291","pt":1646208873297,"mc":[{"id":"1.195453700","rc":[{"atb":[[2.72,0],[2.84,54.35]],"id":41419590},{"atl":[[1000,2]],"id":41419619},{"atl":[[670,0],[660,2]],"id":41419620},{"atb":[[5.5,22.22],[4.9,0]],"id":41419592}],"con":true,"img":false}]}
{"op":"mcm","clk":"5347835306","pt":1646208873602,"mc":[{"id":"1.195453700","rc":[{"atb":[[23,0],[28,0]],"id":41419606},{"atb":[[9,0],[10,0]],"id":41419585},{"atb":[[19.5,0],[24,0]],"id":41419592}],"con":true,"img":false}]}
{"op":"mcm","clk":"5347835351","pt":1646208874280,"mc":[{"id":"1.195453700","rc":[{"atb":[[22,3.27],[27,2.72]],"id":41419606},{"atb":[[9.2,3.27],[10.5,2.72]],"id":41419585},{"atb":[[21,3.27],[26,2.72]],"id":41419592}],"con":true,"img":false}]}
{"op":"mcm","clk":"5347836656","pt":1646208900795,"mc":[{"id":"1.195453700","rc":[{"atb":[[11,0],[9.4,0]],"id":41419586},{"atb":[[11,0],[9.4,0]],"id":41419588}],"con":true,"img":false}]}
{"op":"mcm","clk":"5347836736","pt":1646208901808,"mc":[{"id":"1.195453700","rc":[{"atb":[[9.6,26.54],[11.5,2.72]],"id":41419586},{"atb":[[9.6,26.54],[11.5,2.72]],"id":41419588}],"con":true,"img":false}]}
{"op":"mcm","clk":"5347837890","pt":1646208921175,"mc":[{"id":"1.195453700","rc":[{"atb":[[70,0],[48,0]],"id":41419630},{"atb":[[70,0],[48,0]],"id":41419611}],"con":true,"img":false}]}
{"op":"mcm","clk":"5347837936","pt":1646208922055,"mc":[{"id":"1.195453700","rc":[{"atb":[[75,2.72],[50,7.35]],"id":41419630},{"atb":[[75,2.72],[50,7.35]],"id":41419611}],"con":true,"img":false}]}
{"op":"mcm","clk":"5347838651","pt":1646208934284,"mc":[{"id":"1.195453700","rc":[{"atb":[[12,0],[9.8,0]],"id":41419587}],"con":true,"img":false}]}
{"op":"mcm","clk":"5347838729","pt":1646208935272,"mc":[{"id":"1.195453700","rc":[{"atb":[[9.6,26.54],[11.5,2.72]],"id":41419587}],"con":true,"img":false}]}
{"op":"mcm","clk":"5347839085","pt":1646208941094,"mc":[{"id":"1.195453700","rc":[{"atb":[[75,0],[50,4.08]],"id":41419611}],"con":true,"img":false}]}
{"op":"mcm","clk":"5347839131","pt":1646208941769,"mc":[{"id":"1.195453700","rc":[{"atb":[[70,2.72],[48,3.27]],"id":41419611}],"con":true,"img":false}]}
{"op":"mcm","clk":"5347841999","pt":1646208993339,"mc":[{"id":"1.195453700","rc":[{"atb":[[2.72,55.58],[2.84,0]],"id":41419590}],"con":true,"img":false}]}
{"op":"mcm","clk":"5347851917","pt":1646209019514,"mc":[{"id":"1.195453700","rc":[{"atb":[[17,0],[48,3.27],[24,0]],"id":41419609},{"atb":[[17,0],[48,0],[24,0]],"id":41419638},{"atb":[[17,0],[48,0],[24,0]],"id":41419605},{"atb":[[16,0],[7.4,0],[9.4,0]],"id":41419634},{"atb":[[16,0],[44,3.27],[22,0]],"id":41419617},{"atb":[[16,0],[7.4,0],[9.4,0]],"id":41419613},{"atb":[[65,0],[19,0],[28,0]],"id":41419593},{"atb":[[42,3.27],[21,0],[15.5,0]],"id":41419622},{"atb":[[5.7,0],[8.4,0],[4.7,0]],"id":41419589},{"atb":[[17.5,0],[50,0],[25,0]],"id":41419618},{"atb":[[17,0],[48,3.27],[24,0]],"id":41419601},{"atb":[[17.5,0],[50,3.27],[25,0]],"id":41419630},{"atb":[[70,2.72],[19.5,0],[29,0]],"id":41419597},{"atb":[[42,3.27],[21,5],[15.5,0]],"id":41419626},{"atb":[[16,0],[44,3.27],[22,0]],"id":41419639},{"atb":[[16,0],[7.4,0],[9.4,0]],"id":41419606},{"atb":[[65,0],[19,0],[28,0]],"id":41419635},{"atb":[[17,0],[48,0],[24,0]],"id":41419602},{"atb":[[6.2,0],[8.2,0],[13,0]],"id":41419585},{"atb":[[65,0],[19,0],[28,0]],"id":41419614},{"atb":[[16,0],[44,0],[22,0]],"id":41419610},{"atb":[[42,0],[21,0],[15.5,0]],"id":41419623},{"atb":[[10,0],[5.5,0],[7,0]],"id":41419590},{"atb":[[17,0],[48,0],[24,0]],"id":41419619},{"atb":[[9.6,3.27],[5.3,0],[6.6,0]],"id":41419586},{"atb":[[17.5,0],[50,0],[25,0]],"id":41419631},{"atb":[[65,0],[19,0],[28,0]],"id":41419598},{"atb":[[16.5,3.27],[9.6,0],[7.6,0]],"id":41419627},{"atb":[[65,0],[19,0],[28,0]],"id":41419594},{"atb":[[17.5,6.06],[50,0],[25,0]],"id":41419640},{"atb":[[65,0],[19,0],[28,0]],"id":41419607},{"atb":[[17,0],[48,0],[24,0]],"id":41419636},{"atb":[[16,0],[44,3.27],[22,0]],"id":41419603},{"atb":[[17,0],[48,0],[24,0]],"id":41419615},{"atb":[[17.5,0],[50,0],[25,0]],"id":41419611},{"atb":[[42,3.27],[21,0],[15.5,0]],"id":41419624},{"atb":[[9.6,0],[5.3,0],[6.6,0]],"id":41419591},{"atb":[[6.2,0],[8.2,0],[13,0]],"id":41419620},{"atb":[[9.6,3.27],[5.3,0],[6.6,0]],"id":41419587},{"atb":[[16,0],[44,0],[22,0]],"id":41419632},{"atb":[[16,0],[7.4,0],[9.4,0]],"id":41419599},{"atb":[[70,0],[19.5,0],[29,0]],"id":41419628},{"atb":[[65,0],[19,0],[28,0]],"id":41419595},{"atb":[[17,0],[48,3.27],[24,0]],"id":41419608},{"atb":[[17,0],[48,3.27],[24,0]],"id":41419637},{"atb":[[17.5,0],[50,0],[25,0]],"id":41419604},{"atb":[[17,0],[48,3.27],[24,0]],"id":41419616},{"atb":[[17,0],[48,3.27],[24,0]],"id":41419612},{"atb":[[16,0],[44,3.27],[22,0]],"id":41419625},{"atb":[[8.6,0],[19,0],[11.5,0]],"id":41419592},{"atb":[[17,0],[48,0],[24,0]],"id":41419621},{"atb":[[9.6,3.27],[5.3,0],[6.6,0]],"id":41419588},{"atb":[[17.5,0],[50,0],[25,0]],"id":41419633},{"atb":[[65,0],[19,0],[28,0]],"id":41419600},{"atb":[[17.5,0],[50,0],[25,0]],"id":41419629},{"atb":[[17.5,0],[50,3.27],[25,0]],"id":41419596}],"con":true,"img":false}]}
{"op":"mcm","clk":"5347852148","pt":1646209023237,"mc":[{"id":"1.195453700","rc":[{"atb":[[24,5.8],[12,24.25],[8.8,34.2]],"id":41419609},{"atb":[[24,5.8],[12,24.25],[8.8,34.2]],"id":41419638},{"atb":[[24,5.8],[12,24.25],[8.8,34.2]],"id":41419605},{"atb":[[5.7,56.76],[9.4,15.88],[4.7,72.11]],"id":41419634},{"atb":[[22,6.35],[11,26.68],[8.4,36.05]],"id":41419617},{"atb":[[5.7,56.76],[9.4,15.88],[4.7,72.11]],"id":41419613},{"atb":[[9.6,31.02],[28,4.93],[14,20.52]],"id":41419593},{"atb":[[21,6.67],[10.5,28.08],[8.2,37.05]],"id":41419622},{"atb":[[3.85,93.61],[3.35,113.53],[5.7,28.38]],"id":41419589},{"atb":[[9,33.35],[25,5.55],[12.5,23.19]],"id":41419618},{"atb":[[24,5.8],[12,24.25],[8.8,34.2]],"id":41419601},{"atb":[[9,33.35],[25,5.55],[12.5,23.19]],"id":41419630},{"atb":[[9.8,30.32],[29,4.76],[14.5,19.76]],"id":41419597},{"atb":[[21,11.67],[10.5,28.08],[8.2,37.05]],"id":41419626},{"atb":[[22,6.35],[11,26.68],[8.4,36.05]],"id":41419639},{"atb":[[5.7,56.76],[9.4,15.88],[4.7,72.11]],"id":41419606},{"atb":[[9.6,31.02],[28,4.93],[14,20.52]],"id":41419635},{"atb":[[24,5.8],[12,24.25],[8.8,34.2]],"id":41419602},{"atb":[[5.1,65.07],[8.2,18.52],[4.1,86.06]],"id":41419585},{"atb":[[9.6,31.02],[28,4.93],[14,20.52]],"id":41419614},{"atb":[[22,6.35],[11,26.68],[8.4,36.05]],"id":41419610},{"atb":[[21,6.67],[10.5,28.08],[8.2,37.05]],"id":41419623},{"atb":[[4.5,76.23],[7,22.23],[3.75,97.02]],"id":41419590},{"atb":[[24,5.8],[12,24.25],[8.8,34.2]],"id":41419619},{"atb":[[4.3,80.85],[6.6,23.82],[3.65,100.68]],"id":41419586},{"atb":[[9,33.35],[25,5.55],[12.5,23.19]],"id":41419631},{"atb":[[9.6,31.02],[28,4.93],[14,20.52]],"id":41419598},{"atb":[[9.6,15.51],[4.8,70.21],[5.8,55.58]],"id":41419627},{"atb":[[9.6,31.02],[28,4.93],[14,20.52]],"id":41419594},{"atb":[[9,33.35],[25,5.55],[12.5,23.19]],"id":41419640},{"atb":[[9.6,31.02],[28,4.93],[14,20.52]],"id":41419607},{"atb":[[24,5.8],[12,24.25],[8.8,34.2]],"id":41419636},{"atb":[[22,6.35],[11,26.68],[8.4,36.05]],"id":41419603},{"atb":[[24,5.8],[12,24.25],[8.8,34.2]],"id":41419615},{"atb":[[9,33.35],[25,5.55],[12.5,23.19]],"id":41419611},{"atb":[[21,6.67],[10.5,28.08],[8.2,37.05]],"id":41419624},{"atb":[[4.3,80.85],[6.6,23.82],[3.65,100.68]],"id":41419591},{"atb":[[5.1,65.07],[8.2,18.52],[4.1,86.06]],"id":41419620},{"atb":[[4.3,80.85],[6.6,23.82],[3.65,100.68]],"id":41419587},{"atb":[[22,6.35],[11,26.68],[8.4,36.05]],"id":41419632},{"atb":[[5.7,56.76],[9.4,15.88],[4.7,72.11]],"id":41419599},{"atb":[[9.8,30.32],[29,4.76],[14.5,19.76]],"id":41419628},{"atb":[[9.6,31.02],[28,4.93],[14,20.52]],"id":41419595},{"atb":[[24,5.8],[12,24.25],[8.8,34.2]],"id":41419608},{"atb":[[24,5.8],[12,24.25],[8.8,34.2]],"id":41419637},{"atb":[[9,33.35],[25,5.55],[12.5,23.19]],"id":41419604},{"atb":[[24,5.8],[12,24.25],[8.8,34.2]],"id":41419616},{"atb":[[24,5.8],[12,24.25],[8.8,34.2]],"id":41419612},{"atb":[[22,6.35],[11,26.68],[8.4,36.05]],"id":41419625},{"atb":[[5.3,62.04],[11.5,12.7],[6.6,47.64]],"id":41419592},{"atb":[[24,5.8],[12,24.25],[8.8,34.2]],"id":41419621},{"atb":[[4.3,80.85],[6.6,23.82],[3.65,100.68]],"id":41419588},{"atb":[[9,33.35],[25,5.55],[12.5,23.19]],"id":41419633},{"atb":[[9.6,31.02],[28,4.93],[14,20.52]],"id":41419600},{"atb":[[9,33.35],[25,5.55],[12.5,23.19]],"id":41419629},{"atb":[[9,33.35],[25,5.55],[12.5,23.19]],"id":41419596}],"con":true,"img":false}]}
{"op":"mcm","clk":"5347854280","pt":1646209059154,"mc":[{"id":"1.195453700","rc":[{"atl":[[1000,0]],"id":41419609},{"atl":[[570,2],[610,0]],"id":41419634},{"atl":[[1000,2]],"id":41419617},{"atb":[[6.2,0]],"id":41419613},{"atl":[[410,2],[450,0]],"id":41419589},{"atb":[[20,5.26],[14,0]],"id":41419618},{"atl":[[1000,2]],"id":41419639},{"atb":[[5.3,0]],"id":41419606},{"atl":[[1000,2]],"id":41419610},{"atl":[[1000,2]],"id":41419623},{"atb":[[2.72,0]],"id":41419590},{"atl":[[1000,0]],"id":41419598},{"atb":[[11,0],[13.5,8]],"id":41419611},{"atb":[[3.7,0]],"id":41419591},{"atb":[[8,0]],"id":41419620},{"atl":[[660,0]],"id":41419620},{"atb":[[24,0]],"id":41419632},{"atl":[[1000,0]],"id":41419632},{"atl":[[870,0]],"id":41419628},{"atb":[[24,0]],"id":41419625},{"atl":[[1000,0]],"id":41419625},{"atl":[[490,2],[510,0]],"id":41419592},{"atb":[[4.1,32.26],[3.8,0]],"id":41419588},{"atb":[[26,0],[13,8.33]],"id":41419596},{"atl":[[920,2],[1000,0]],"id":41419596}],"con":true,"img":false}]}
{"op":"mcm","clk":"5347854283","pt":1646209059262,"mc":[{"id":"1.195453700","rc":[{"atl":[[1000,2]],"id":41419638},{"atb":[[6.2,0],[7.4,15.62]],"id":41419634},{"atb":[[7.4,15.62]],"id":41419613},{"atl":[[1000,2]],"id":41419593},{"atl":[[1000,2]],"id":41419622},{"atb":[[3.8,0],[4.4,29.41]],"id":41419589},{"atb":[[22,0],[15.5,6.9]],"id":41419630},{"atl":[[960,2],[1000,0]],"id":41419630},{"atb":[[9,0],[11.5,9.52]],"id":41419597},{"atl":[[750,2],[810,0]],"id":41419597},{"atb":[[17,6.25],[21,6.67]],"id":41419626},{"atl":[[980,2]],"id":41419626},{"atb":[[6,20]],"id":41419606},{"atl":[[1000,2]],"id":41419635},{"atb":[[3.45,0],[4.1,118.32]],"id":41419585},{"atb":[[3.35,42.55]],"id":41419590},{"atl":[[1000,0]],"id":41419619},{"atb":[[5.6,21.74],[5,0]],"id":41419586},{"atl":[[480,2],[510,0]],"id":41419586},{"atb":[[19,0],[23,4.55]],"id":41419631},{"atl":[[900,2],[960,0]],"id":41419631},{"atl":[[960,2]],"id":41419598},{"atb":[[4.3,0],[4.9,25.64]],"id":41419627},{"atl":[[450,2],[470,0]],"id":41419627},{"atb":[[26,0]],"id":41419594},{"atl":[[920,2],[1000,0]],"id":41419594},{"atb":[[17.5,0],[13,8.33]],"id":41419640},{"atl":[[920,2],[930,0]],"id":41419640},{"atb":[[22,0],[28,8.63]],"id":41419607},{"atl":[[930,2],[1000,0]],"id":41419607},{"atl":[[1000,2]],"id":41419624},{"atb":[[4,33.33]],"id":41419591},{"atb":[[5.1,89.46]],"id":41419620},{"atl":[[520,2]],"id":41419620},{"atb":[[5.1,24.39],[3.95,0]],"id":41419587},{"atl":[[410,2],[420,0]],"id":41419587},{"atb":[[11,36.68]],"id":41419632},{"atl":[[870,2]],"id":41419632},{"atb":[[9.6,11.63],[8.2,0]],"id":41419599},{"atl":[[650,2],[680,0]],"id":41419599},{"atl":[[800,2]],"id":41419628},{"atl":[[950,2],[1000,0]],"id":41419595},{"atl":[[1000,2]],"id":41419637},{"atl":[[940,2],[1000,0]],"id":41419604},{"atb":[[9.8,11.36]],"id":41419625},{"atl":[[840,2]],"id":41419625},{"atb":[[5.5,0],[6,20]],"id":41419592},{"atb":[[27,0],[14,7.69]],"id":41419621},{"atl":[[940,2]],"id":41419621},{"atl":[[790,2],[870,0]],"id":41419633},{"atl":[[1000,2]],"id":41419600},{"atl":[[1000,2]],"id":41419629}],"con":true,"img":false}]}
{"op":"mcm","clk":"5347854290","pt":1646209059365,"mc":[{"id":"1.195453700","rc":[{"atl":[[1000,2]],"id":41419609},{"atl":[[940,2],[1000,0]],"id":41419623}],"con":true,"img":false}]}
{"op":"mcm","clk":"5347854294","pt":1646209059467,"mc":[{"id":"1.195453700","rc":[{"atb":[[22,0],[27,0]],"id":41419606},{"atb":[[9.2,0],[10.5,0]],"id":41419585},{"atb":[[5.8,0],[6.6,0]],"id":41419590},{"atl":[[1000,2]],"id":41419619},{"atb":[[26,4]],"id":41419594},{"atb":[[75,0],[50,0]],"id":41419628},{"atb":[[21,0],[26,0]],"id":41419592}],"con":true,"img":false}]}
{"op":"mcm","clk":"5347854340","pt":1646209060150,"mc":[{"id":"1.195453700","rc":[{"atb":[[24,3.27],[29,2.72]],"id":41419606},{"atb":[[9.6,3.27],[11.5,2.72]],"id":41419585},{"atb":[[9.8,2.72],[8.8,3.27]],"id":41419590},{"atb":[[70,2.72],[48,3.27]],"id":41419628},{"atb":[[19,3.27],[23,2.72]],"id":41419592}],"con":true,"img":false}]}
{"op":"mcm","clk":"5347854614","pt":1646209064649,"mc":[{"id":"1.195453700","rc":[{"atl":[[940,0],[980,2]],"id":41419623},{"atl":[[780,2],[800,0]],"id":41419611},{"atl":[[990,2],[1000,0]],"id":41419612}],"con":true,"img":false}]}
{"op":"mcm","clk":"5347854690","pt":1646209066080,"mc":[{"id":"1.195453700","rc":[{"atb":[[19,0],[23,0]],"id":41419592}],"con":true,"img":false}]}
{"op":"mcm","clk":"5347854725","pt":1646209066755,"mc":[{"id":"1.195453700","rc":[{"atb":[[18.5,3.27]],"id":41419592}],"con":true,"img":false}]}
{"op":"mcm","clk":"5347854735","pt":1646209066960,"mc":[{"id":"1.195453700","rc":[{"atb":[[22,2.72]],"id":41419592}],"con":true,"img":false}]}
{"op":"mcm","clk":"5347854820","pt":1646209068359,"mc":[{"id":"1.195453700","rc":[{"atl":[[540,2],[570,0]],"id":41419634},{"atl":[[380,2],[410,0]],"id":41419589},{"atl":[[940,2],[1000,0]],"id":41419639},{"atb":[[17.5,6.06],[13.5,0]],"id":41419611},{"atl":[[460,2],[490,0]],"id":41419592},{"atb":[[16,6.67],[13,0]],"id":41419596},{"atl":[[830,2],[920,0]],"id":41419596}],"con":true,"img":false}]}
{"op":"mcm","clk":"5347854829","pt":1646209068461,"mc":[{"id":"1.195453700","rc":[{"atb":[[19,5.56],[15.5,0]],"id":41419630},{"atl":[[860,2]],"id":41419630},{"atb":[[6,0],[7,16.67]],"id":41419606},{"atb":[[3.8,35.71]],"id":41419590},{"atl":[[860,2],[960,0]],"id":41419598},{"atl":[[920,0],[910,2]],"id":41419594},{"atl":[[920,2],[930,0]],"id":41419607},{"atb":[[6.2,19.23]],"id":41419620},{"atl":[[510,2]],"id":41419620},{"atb":[[11,26.68],[13.5,8]],"id":41419632},{"atl":[[790,2],[870,0]],"id":41419632},{"atl":[[730,2],[800,0]],"id":41419628},{"atb":[[9.8,0],[13,8.33]],"id":41419625},{"atl":[[780,2],[840,0]],"id":41419625},{"atl":[[870,2],[940,0]],"id":41419621},{"atl":[[940,2],[1000,0]],"id":41419629}],"con":true,"img":false}]}
{"op":"mcm","clk":"5347854834","pt":1646209068564,"mc":[{"id":"1.195453700","rc":[{"atl":[[960,0]],"id":41419630},{"atb":[[17,0],[21,11.67]],"id":41419626},{"atl":[[900,2],[980,0]],"id":41419626},{"atl":[[940,2],[1000,0]],"id":41419635},{"atb":[[3.35,0]],"id":41419590},{"atb":[[16,6.67],[13,0]],"id":41419640},{"atl":[[830,2],[920,0]],"id":41419640},{"atb":[[4,0],[4.7,27.03]],"id":41419591},{"atb":[[5.1,65.07]],"id":41419620},{"atl":[[520,0]],"id":41419620},{"atl":[[600,2],[650,0]],"id":41419599},{"atb":[[19,5.56],[14,0]],"id":41419621}],"con":true,"img":false}]}
{"op":"mcm","clk":"5347855328","pt":1646209076767,"mc":[{"id":"1.195453700","rc":[{"atl":[[900,0]],"id":41419631},{"atl":[[990,0]],"id":41419612},{"atl":[[790,0]],"id":41419633}],"con":true,"img":false}]}
{"op":"mcm","clk":"5347855333","pt":1646209076862,"mc":[{"id":"1.195453700","rc":[{"atl":[[910,2]],"id":41419631},{"atl":[[980,2]],"id":41419612},{"atl":[[800,2]],"id":41419633}],"con":true,"img":false}]}
{"op":"mcm","clk":"5347856795","pt":1646209099036,"mc":[{"id":"1.195453700","rc":[{"atb":[[23,0]],"id":41419613},{"atb":[[19,0],[23,0]],"id":41419620}],"con":true,"img":false}]}
{"op":"mcm","clk":"5347856853","pt":1646209099906,"mc":[{"id":"1.195453700","rc":[{"atb":[[24,3.27]],"id":41419613},{"atb":[[18.5,3.27],[22,2.72]],"id":41419620}],"con":true,"img":false}]}
{"op":"mcm","clk":"5347856858","pt":1646209100008,"mc":[{"id":"1.195453700","rc":[{"atl":[[910,0],[900,2]],"id":41419631},{"atl":[[790,2],[800,0]],"id":41419633}],"con":true,"img":false}]}
{"op":"mcm","clk":"5347858029","pt":1646209118430,"mc":[{"id":"1.195453700","rc":[{"atb":[[9.2,12.2],[7.4,0]],"id":41419613},{"atl":[[380,0],[370,2]],"id":41419589},{"atl":[[860,0],[870,2]],"id":41419630},{"atl":[[940,0],[950,2]],"id":41419635},{"atl":[[480,0],[490,2]],"id":41419586},{"atl":[[890,2],[900,0]],"id":41419631},{"atl":[[830,0],[810,2]],"id":41419640},{"atl":[[410,0],[420,2]],"id":41419587},{"atl":[[790,0],[780,2]],"id":41419632},{"atl":[[600,0],[610,2]],"id":41419599},{"atl":[[950,0],[960,2]],"id":41419595},{"atl":[[790,0],[780,2]],"id":41419633}],"con":true,"img":false}]}
{"op":"mcm","clk":"5347858061","pt":1646209119133,"mc":[{"id":"1.195453700","rc":[{"atb":[[9.8,0],[8.8,0]],"id":41419590}],"con":true,"img":false}]}
{"op":"mcm","clk":"5347858112","pt":1646209119926,"mc":[{"id":"1.195453700","rc":[{"atb":[[8.4,3.27],[9.4,2.72]],"id":41419590}],"con":true,"img":false}]}
{"op":"mcm","clk":"5347858130","pt":1646209120346,"mc":[{"id":"1.195453700","rc":[{"atb":[[20,0],[25,9.72]],"id":41419618},{"atl":[[840,2],[880,0]],"id":41419618},{"atl":[[890,2]],"id":41419639},{"atb":[[5.4,22.73]],"id":41419627},{"atl":[[440,2]],"id":41419627},{"atl":[[870,2],[910,0]],"id":41419594},{"atl":[[870,2],[920,0]],"id":41419607},{"atb":[[16.5,6.45]],"id":41419604},{"atb":[[4.8,26.32]],"id":41419588},{"atb":[[16.5,6.45],[11,0]],"id":41419629},{"atb":[[18.5,5.71]],"id":41419596},{"atl":[[790,2]],"id":41419596}],"con":true,"img":false}]}
{"op":"mcm","clk":"5347858138","pt":1646209120441,"mc":[{"id":"1.195453700","rc":[{"atl":[[940,0]],"id":41419639},{"atb":[[4.9,0]],"id":41419627},{"atl":[[450,0]],"id":41419627},{"atb":[[11,0]],"id":41419604},{"atb":[[4.1,0]],"id":41419588},{"atb":[[16,0]],"id":41419596},{"atl":[[830,0]],"id":41419596}],"con":true,"img":false}]}
{"op":"mcm","clk":"5347858154","pt":1646209120753,"mc":[{"id":"1.195453700","rc":[{"atl":[[750,0],[760,2]],"id":41419597}],"con":true,"img":false}]}
{"op":"mcm","clk":"5347858484","pt":1646209126946,"mc":[{"id":"1.195453700","rc":[{"atl":[[490,0],[480,2]],"id":41419586}],"con":true,"img":false}]}
{"op":"mcm","clk":"5347858487","pt":1646209127049,"mc":[{"id":"1.195453700","rc":[{"atl":[[950,0],[940,2]],"id":41419635},{"atl":[[840,2],[890,0]],"id":41419631},{"atl":[[740,2],[780,0]],"id":41419632}],"con":true,"img":false}]}
{"op":"mcm","clk":"5347858570","pt":1646209128647,"mc":[{"id":"1.195453700","rc":[{"atl":[[880,2]],"id":41419639}],"con":true,"img":false}]}
{"op":"mcm","clk":"5347858578","pt":1646209128750,"mc":[{"id":"1.195453700","rc":[{"atl":[[890,0]],"id":41419639}],"con":true,"img":false}]}
{"op":"mcm","clk":"5347859379","pt":1646209144146,"mc":[{"id":"1.195453700","rc":[{"atl":[[810,0],[800,2]],"id":41419640}],"con":true,"img":false}]}
{"op":"mcm","clk":"5347859756","pt":1646209151789,"mc":[{"id":"1.195453700","rc":[{"atb":[[18.5,0]],"id":41419592}],"con":true,"img":false}]}
{"op":"mcm","clk":"5347859771","pt":1646209152100,"mc":[{"id":"1.195453700","rc":[{"atb":[[22,0]],"id":41419592}],"con":true,"img":false}]}
{"op":"mcm","clk":"5347859802","pt":1646209152617,"mc":[{"id":"1.195453700","rc":[{"atb":[[19,3.27]],"id":41419592}],"con":true,"img":false}]}
{"op":"mcm","clk":"5347859827","pt":1646209152981,"mc":[{"id":"1.195453700","rc":[{"atb":[[23,2.72]],"id":41419592}],"con":true,"img":false}]}
{"op":"mcm","clk":"5347861063","pt":1646209176438,"mc":[{"id":"1.195453700","rc":[{"atl":[[540,0],[530,2]],"id":41419634},{"atb":[[8,14.29],[9.2,0]],"id":41419613},{"atb":[[11.5,0],[14.5,27.17]],"id":41419597},{"atl":[[890,2],[900,0]],"id":41419626},{"atb":[[17.5,0],[24,4.35]],"id":41419598},{"atl":[[1000,2]],"id":41419603},{"atl":[[730,2],[740,0]],"id":41419632},{"atl":[[600,2],[610,0]],"id":41419599},{"atl":[[780,0],[770,2]],"id":41419633}],"con":true,"img":false}]}
{"op":"mcm","clk":"5347861319","pt":1646209181761,"mc":[{"id":"1.195453700","rc":[{"atb":[[18.5,0],[22,0]],"id":41419620}],"con":true,"img":false}]}
{"op":"mcm","clk":"5347861351","pt":1646209182437,"mc":[{"id":"1.195453700","rc":[{"atb":[[19,3.27],[23,2.72]],"id":41419620}],"con":true,"img":false}]}
{"op":"mcm","clk":"5347862586","pt":1646209207187,"mc":[{"id":"1.195453700","rc":[{"atb":[[9.6,0],[11.5,0]],"id":41419585}],"con":true,"img":false}]}
{"op":"mcm","clk":"5347862622","pt":1646209207908,"mc":[{"id":"1.195453700","rc":[{"atb":[[11,2.72],[9.4,3.27]],"id":41419585}],"con":true,"img":false}]}
{"op":"mcm","clk":"5347863209","pt":1646209219020,"mc":[{"id":"1.195453700","rc":[{"atl":[[860,2],[870,0]],"id":41419630},{"atl":[[880,0],[870,2]],"id":41419639},{"atl":[[980,0],[970,2]],"id":41419623},{"atl":[[430,2],[440,0]],"id":41419627},{"atl":[[790,2],[800,0]],"id":41419640}],"con":true,"img":false}]}
{"op":"mcm","clk":"5347863784","pt":1646209229123,"mc":[{"id":"1.195453700","rc":[{"atb":[[19,0]],"id":41419592}],"con":true,"img":false}]}
{"op":"mcm","clk":"5347863816","pt":1646209229638,"mc":[{"id":"1.195453700","rc":[{"atb":[[23,0]],"id":41419592}],"con":true,"img":false}]}
{"op":"mcm","clk":"5347863824","pt":1646209229795,"mc":[{"id":"1.195453700","rc":[{"atb":[[22,3.27]],"id":41419592}],"con":true,"img":false}]}
{"op":"mcm","clk":"5347863846","pt":1646209230311,"mc":[{"id":"1.195453700","rc":[{"atb":[[27,2.72]],"id":41419592}],"con":true,"img":false}]}
{"op":"mcm","clk":"5347863937","pt":1646209232321,"mc":[{"id":"1.195453700","rc":[{"atl":[[890,0],[900,2]],"id":41419626},{"atl":[[730,0],[740,2]],"id":41419632}],"con":true,"img":false}]}
{"op":"mcm","clk":"5347863953","pt":1646209232740,"mc":[{"id":"1.195453700","rc":[{"atb":[[8.4,0],[9.4,0]],"id":41419590}],"con":true,"img":false}]}
{"op":"mcm","clk":"5347863992","pt":1646209233510,"mc":[{"id":"1.195453700","rc":[{"atb":[[9.2,2.72],[8.2,3.27]],"id":41419590}],"con":true,"img":false}]}
{"op":"mcm","clk":"5347864487","pt":1646209242936,"mc":[{"id":"1.195453700","rc":[{"atl":[[1000,0]],"id":41419609},{"atl":[[890,2],[900,0]],"id":41419626},{"atb":[[17.5,0],[20,5.26]],"id":41419611},{"atl":[[730,2],[740,0]],"id":41419632}],"con":true,"img":false}]}
{"op":"mcm","clk":"5347864786","pt":1646209249731,"mc":[{"id":"1.195453700","rc":[{"atl":[[470,2],[480,0]],"id":41419586},{"atl":[[1000,0]],"id":41419603},{"atl":[[770,0],[780,2]],"id":41419633}],"con":true,"img":false}]}
{"op":"mcm","clk":"5347864815","pt":1646209250244,"mc":[{"id":"1.195453700","rc":[{"atb":[[9.2,0],[8.2,0]],"id":41419590},{"atb":[[22,0],[27,0]],"id":41419592}],"con":true,"img":false}]}
{"op":"mcm","clk":"5347864850","pt":1646209250962,"mc":[{"id":"1.195453700","rc":[{"atb":[[8,3.27],[9,2.72]],"id":41419590},{"atb":[[21,3.27],[26,2.72]],"id":41419592}],"con":true,"img":false}]}
{"op":"mcm","clk":"5347865070","pt":1646209254840,"mc":[{"id":"1.195453700","rc":[{"atl":[[1000,2]],"id":41419603}],"con":true,"img":false}]}
{"op":"mcm","clk":"5347865400","pt":1646209261064,"mc":[{"id":"1.195453700","rc":[{"atb":[[25,13.11]],"id":41419619},{"atb":[[30,12.39]],"id":41419624}],"con":true,"img":false}]}
{"op":"mcm","clk":"5347865404","pt":1646209261166,"mc":[{"id":"1.195453700","rc":[{"atb":[[140,4.96],[75,2.14],[100,9.92],[27,13.61]],"id":41419609},{"atl":[[1000,0.15]],"id":41419609},{"atb":[[140,4.96],[70,2.3],[100,9.92],[27,13.61]],"id":41419605},{"atl":[[1000,0.15]],"id":41419605},{"atb":[[18,9.92],[20,4.96],[9.4,24.01]],"id":41419634},{"atl":[[520,0.3],[550,2.23],[40,4.96],[48,9.92]],"id":41419634},{"atb":[[65,2.48],[85,9.92],[26,12.94],[110,4.96]],"id":41419617},{"atl":[[990,0.15]],"id":41419617},{"atb":[[85,1.88],[28,13.88]],"id":41419593},{"atl":[[990,0.15]],"id":41419593},{"atb":[[90,9.92],[28,12.64],[120,4.96],[60,2.69]],"id":41419622},{"atl":[[990,0.15]],"id":41419622},{"atb":[[9.2,4.96],[9.8,11.67],[5.7,37.33],[8.4,9.92]],"id":41419589},{"atl":[[17.5,9.92],[360,0.44],[390,3.16],[15.5,4.96]],"id":41419589},{"atb":[[70,5.03],[80,4.96],[25,18.67],[60,9.92]],"id":41419618},{"atl":[[180,4.96],[830,0.19],[860,1.42]],"id":41419618},{"atb":[[27,13.61]],"id":41419601},{"atb":[[75,4.87],[25,14.5]],"id":41419630},{"atl":[[850,0.18],[880,1.39]],"id":41419630},{"atb":[[44,9.92],[55,4.96],[29,13.71]],"id":41419597},{"atl":[[750,0.21],[780,1.57],[200,4.96]],"id":41419597},{"atb":[[65,9.92],[21,20.61],[85,4.96],[60,2.69]],"id":41419626},{"atl":[[160,4.96],[880,0.18],[910,1.34]],"id":41419626},{"atb":[[65,2.48],[70,9.92],[90,4.96],[26,12.94]],"id":41419639},{"atl":[[170,4.96],[860,0.18],[890,1.38]],"id":41419639},{"atb":[[85,9.92],[110,4.96],[28,13.88]],"id":41419614},{"atl":[[230,4.96]],"id":41419614},{"atb":[[70,2.3],[90,9.92],[26,12.94],[120,4.96]],"id":41419610},{"atl":[[230,4.96],[990,0.15]],"id":41419610},{"atb":[[65,2.48],[27,12.79]],"id":41419623},{"atl":[[960,0.16],[990,1.23]],"id":41419623},{"atb":[[70,2.3],[85,9.92],[110,4.96]],"id":41419619},{"atl":[[990,0.15]],"id":41419619},{"atb":[[70,5.03],[80,4.96],[25,14.5],[60,9.92]],"id":41419631},{"atl":[[200,4.96],[830,0.19],[860,1.42]],"id":41419631},{"atb":[[9.6,24.45]],"id":41419627},{"atl":[[450,2.73]],"id":41419627},{"atb":[[42,9.92],[50,4.96]],"id":41419640},{"atl":[[180,4.96]],"id":41419640},{"atb":[[75,12.06],[95,4.96],[28,17.58]],"id":41419607},{"atl":[[190,4.96],[860,0.18],[890,1.38]],"id":41419607},{"atb":[[130,4.96],[70,2.3],[95,9.92],[28,13.46]],"id":41419636},{"atl":[[1000,0.15]],"id":41419636},{"atb":[[65,2.48],[90,9.92],[120,4.96]],"id":41419603},{"atl":[[990,0.15]],"id":41419603},{"atb":[[140,4.96],[70,2.3],[100,9.92],[27,13.61]],"id":41419615},{"atl":[[1000,0.15]],"id":41419615},{"atb":[[70,5.03],[46,9.92],[25,14.5],[60,4.96]],"id":41419611},{"atl":[[770,0.2],[800,1.53],[220,4.96]],"id":41419611},{"atb":[[80,9.92],[100,4.96],[60,2.69]],"id":41419624},{"atl":[[210,4.96],[990,0.15]],"id":41419624},{"atb":[[17,4.96],[8.2,27.47],[15,9.92]],"id":41419620},{"atl":[[530,2.31],[36,4.96],[44,9.92],[500,0.31]],"id":41419620},{"atb":[[6.6,32.76]],"id":41419587},{"atl":[[440,2.8]],"id":41419587},{"atb":[[40,9.92],[22,15.3],[48,4.96]],"id":41419632},{"atl":[[720,0.21],[190,4.96],[750,1.63]],"id":41419632},{"atb":[[9.6,19.75],[26,9.92],[29,8.4],[30,4.96]],"id":41419599},{"atl":[[590,0.26],[620,1.98],[80,9.92],[60,4.96]],"id":41419599},{"atb":[[29,13.71]],"id":41419628},{"atl":[[720,0.21],[750,1.63]],"id":41419628},{"atb":[[75,2.14],[27,13.61]],"id":41419608},{"atl":[[1000,0.15]],"id":41419608},{"atb":[[75,2.14],[85,9.92],[24,14.74],[110,4.96]],"id":41419637},{"atl":[[240,4.96],[990,0.15]],"id":41419637},{"atb":[[80,9.92],[100,4.96]],"id":41419604},{"atl":[[210,4.96]],"id":41419604},{"atb":[[140,4.96],[75,2.14],[100,9.92],[26,13.76]],"id":41419616},{"atl":[[1000,0.15]],"id":41419616},{"atb":[[26,12.94]],"id":41419612},{"atl":[[1000,1.22]],"id":41419612},{"atb":[[40,9.92],[22,15.3],[48,4.96]],"id":41419625},{"atl":[[160,4.96],[800,1.53]],"id":41419625},{"atb":[[65,5.21],[24,14.74]],"id":41419621},{"atl":[[860,0.18],[890,1.38]],"id":41419621},{"atb":[[11.5,11.67]],"id":41419588},{"atl":[[400,0.39]],"id":41419588},{"atb":[[75,2.14],[25,14.5]],"id":41419629},{"atl":[[930,0.16],[960,1.27]],"id":41419629}],"con":true,"img":false}]}
{"op":"mcm","clk":"5347865411","pt":1646209261271,"mc":[{"id":"1.195453700","rc":[{"atb":[[26,12.94]],"id":41419638},{"atb":[[28,8.6],[9.4,24.83]],"id":41419613},{"atl":[[540,0.29],[570,2.15]],"id":41419613},{"atb":[[85,11.81],[110,4.96]],"id":41419593},{"atb":[[150,4.96],[75,2.14],[110,9.92]],"id":41419601},{"atl":[[1000,0.15]],"id":41419601},{"atb":[[75,9.83],[55,9.92]],"id":41419630},{"atl":[[230,4.96]],"id":41419630},{"atb":[[19,9.92],[22,4.96],[9.4,24.83]],"id":41419606},{"atl":[[65,9.92],[540,2.27],[48,4.96],[510,0.31]],"id":41419606},{"atb":[[75,2.14],[80,9.92],[100,4.96],[28,13.88]],"id":41419635},{"atl":[[180,4.96],[930,0.16],[960,1.27]],"id":41419635},{"atb":[[75,2.14]],"id":41419614},{"atl":[[990,0.15]],"id":41419614},{"atb":[[80,9.92],[100,4.96]],"id":41419623},{"atl":[[200,4.96]],"id":41419623},{"atl":[[140,1.14]],"id":41419590},{"atb":[[80,4.73],[28,13.88]],"id":41419598},{"atl":[[850,0.18],[880,1.39]],"id":41419598},{"atl":[[420,0.37]],"id":41419627},{"atb":[[80,4.73],[28,13.88]],"id":41419594},{"atl":[[860,0.18],[890,1.38]],"id":41419594},{"atb":[[25,14.5]],"id":41419640},{"atl":[[780,0.2],[810,1.51]],"id":41419640},{"atb":[[28,12.64]],"id":41419603},{"atb":[[8.6,9.92],[6.6,32.76],[9.4,8.23]],"id":41419591},{"atl":[[17.5,9.92],[310,0.51],[340,3.62],[15.5,4.96]],"id":41419591},{"atb":[[11.5,16.63],[9.8,9.92]],"id":41419587},{"atl":[[22,4.96],[410,0.38],[26,9.92]],"id":41419587},{"atb":[[36,9.92],[44,4.96]],"id":41419628},{"atl":[[220,4.96]],"id":41419628},{"atb":[[85,11.81],[110,4.96],[28,13.88]],"id":41419595},{"atl":[[220,4.96],[950,0.16],[980,1.25]],"id":41419595},{"atb":[[25,14.5]],"id":41419604},{"atl":[[960,1.27]],"id":41419604},{"atb":[[75,2.14]],"id":41419612},{"atl":[[970,0.16]],"id":41419612},{"atl":[[770,0.2]],"id":41419625},{"atb":[[75,4.96],[55,9.92]],"id":41419621},{"atl":[[150,4.96]],"id":41419621},{"atb":[[6.6,32.76]],"id":41419588},{"atl":[[430,2.86]],"id":41419588},{"atl":[[770,0.2]],"id":41419633},{"atb":[[80,9.92],[100,4.96]],"id":41419629},{"atl":[[220,4.96]],"id":41419629},{"atb":[[65,4.96],[75,4.87],[48,9.92],[25,14.5]],"id":41419596},{"atl":[[160,4.96],[780,0.2],[810,1.51]],"id":41419596}],"con":true,"img":false}]}
{"op":"mcm","clk":"5347865417","pt":1646209261374,"mc":[{"id":"1.195453700","rc":[{"atb":[[70,2.3],[85,9.92],[110,4.96]],"id":41419638},{"atl":[[990,0.15]],"id":41419638},{"atb":[[24,13.19],[28,13.56]],"id":41419613},{"atl":[[75,9.92],[55,4.96]],"id":41419613},{"atb":[[70,2.3],[150,4.96],[27,13.61],[110,9.92]],"id":41419602},{"atl":[[1000,0.15]],"id":41419602},{"atb":[[9.2,4.96],[8.2,27.47],[8.4,9.92]],"id":41419585},{"atl":[[16.5,9.92],[310,0.51],[340,3.62],[14.5,4.96]],"id":41419585},{"atb":[[7.2,4.96],[6.4,9.92],[7,31.17]],"id":41419590},{"atl":[[16.5,9.92],[170,7.25],[14.5,4.96]],"id":41419590},{"atb":[[11,9.92],[13,4.96],[6.6,32.76]],"id":41419586},{"atl":[[36,9.92],[29,4.96],[490,2.51]],"id":41419586},{"atb":[[75,4.96],[55,13.19]],"id":41419598},{"atl":[[170,4.96]],"id":41419598},{"atb":[[12.5,9.92],[14.5,4.96]],"id":41419627},{"atl":[[75,9.92],[55,4.96]],"id":41419627},{"atb":[[85,9.92],[110,4.96]],"id":41419594},{"atl":[[190,4.96]],"id":41419594},{"atl":[[600,2]],"id":41419607},{"atb":[[150,4.96],[110,9.92]],"id":41419608},{"atb":[[85,9.92],[110,4.96]],"id":41419612},{"atl":[[220,4.96]],"id":41419612},{"atb":[[11.5,16.63],[9.8,9.92]],"id":41419588},{"atl":[[22,4.96],[26,9.92]],"id":41419588},{"atb":[[36,9.92],[44,4.96],[25,14.5]],"id":41419633},{"atl":[[200,4.96],[800,1.53]],"id":41419633},{"atb":[[130,4.96],[75,2.14],[95,9.92],[28,13.88]],"id":41419600},{"atl":[[240,4.96],[990,0.15]],"id":41419600}],"con":true,"img":false}]}
{"op":"mcm","clk":"5347865421","pt":1646209261480,"mc":[{"id":"1.195453700","rc":[{"atb":[[36,2.86],[27,9.76]],"id":41419609},{"atb":[[34,3.03],[27,9.76]],"id":41419605},{"atl":[[530,0],[130,2]],"id":41419634},{"atb":[[34,3.03],[26,8.94]],"id":41419617},{"atl":[[550,0],[560,2]],"id":41419613},{"atb":[[34,3.03],[27,0]],"id":41419593},{"atl":[[370,0],[100,2]],"id":41419589},{"atl":[[840,0],[470,2]],"id":41419618},{"atb":[[36,2.86],[27,9.76]],"id":41419601},{"atl":[[860,0],[870,2]],"id":41419630},{"atl":[[760,0],[400,2]],"id":41419597},{"atl":[[890,0],[510,2]],"id":41419626},{"atb":[[32,3.23],[26,8.94]],"id":41419639},{"atl":[[870,0],[480,2]],"id":41419639},{"atl":[[520,0],[150,2]],"id":41419606},{"atb":[[32,3.23],[26,0]],"id":41419635},{"atl":[[540,2],[940,0]],"id":41419635},{"atb":[[34,3.03],[25,0]],"id":41419614},{"atl":[[780,2],[1000,0]],"id":41419614},{"atb":[[34,3.03],[26,8.94]],"id":41419610},{"atl":[[760,2],[1000,0]],"id":41419610},{"atl":[[970,0],[980,2]],"id":41419623},{"atb":[[34,3.03],[25,8.94]],"id":41419619},{"atb":[[11.5,11.67]],"id":41419586},{"atl":[[460,0.34]],"id":41419586},{"atl":[[840,0],[460,2]],"id":41419631},{"atl":[[860,0],[870,2]],"id":41419598},{"atl":[[430,0],[440,2]],"id":41419627},{"atl":[[870,0],[880,2]],"id":41419594},{"atl":[[790,0],[410,2]],"id":41419640},{"atl":[[870,0]],"id":41419607},{"atb":[[36,2.86],[28,9.76]],"id":41419636},{"atb":[[36,2.86],[27,9.76]],"id":41419615},{"atl":[[780,0],[480,2]],"id":41419611},{"atl":[[700,2],[1000,0]],"id":41419624},{"atl":[[38,2.7],[320,0]],"id":41419591},{"atl":[[110,2],[510,0]],"id":41419620},{"atl":[[420,0],[60,2]],"id":41419587},{"atl":[[350,2],[730,0]],"id":41419632},{"atl":[[600,0],[200,2]],"id":41419599},{"atl":[[730,0],[740,2]],"id":41419628},{"atb":[[34,3.03],[26,0]],"id":41419595},{"atl":[[710,2],[960,0]],"id":41419595},{"atb":[[36,2.86],[27,9.76]],"id":41419608},{"atb":[[34,3.03],[22,0]],"id":41419637},{"atl":[[810,2],[1000,0]],"id":41419637},{"atl":[[540,2],[940,0]],"id":41419604},{"atb":[[36,2.86],[26,9.76]],"id":41419616},{"atb":[[34,3.03],[26,8.94]],"id":41419612},{"atl":[[980,0],[1000,3.22]],"id":41419612},{"atl":[[780,0],[400,2]],"id":41419625},{"atb":[[16.5,9.92],[18.5,4.96],[11.5,21.65]],"id":41419592},{"atl":[[44,4.96],[55,9.92],[450,0.35],[480,2.56]],"id":41419592},{"atl":[[870,0],[880,2]],"id":41419621},{"atl":[[410,0],[420,2]],"id":41419588},{"atl":[[940,0],[950,2]],"id":41419629},{"atl":[[790,0],[480,2]],"id":41419596}],"con":true,"img":false}]}
{"op":"mcm","clk":"5347865427","pt":1646209261584,"mc":[{"id":"1.195453700","rc":[{"atb":[[34,3.03],[26,8.94]],"id":41419638},{"atb":[[36,2.86],[27,9.76]],"id":41419602},{"atl":[[36,2.86],[320,0]],"id":41419585},{"atl":[[150,0],[100,2]],"id":41419590},{"atl":[[85,2],[470,0]],"id":41419586},{"atb":[[32,3.23],[26,0]],"id":41419594},{"atl":[[780,0],[390,2]],"id":41419633},{"atb":[[34,3.03],[27,0]],"id":41419600},{"atl":[[880,2],[1000,0]],"id":41419600}],"con":true,"img":false}]}
{"op":"mcm","clk":"5347865433","pt":1646209261689,"mc":[{"id":"1.195453700","rc":[{"atl":[[560,0],[190,2]],"id":41419613},{"atl":[[830,2.19],[470,0]],"id":41419618},{"atl":[[870,0],[490,2]],"id":41419630},{"atl":[[750,2.21],[400,0]],"id":41419597},{"atl":[[880,2.18],[510,0]],"id":41419626},{"atl":[[860,2.18],[480,0]],"id":41419639},{"atl":[[780,0],[990,2.15]],"id":41419614},{"atl":[[760,0],[990,2.15]],"id":41419610},{"atl":[[640,2],[980,0]],"id":41419623},{"atl":[[830,2.19],[460,0]],"id":41419631},{"atl":[[870,0],[500,2]],"id":41419598},{"atl":[[70,2],[440,0]],"id":41419627},{"atl":[[590,2],[880,0]],"id":41419594},{"atl":[[780,2.2],[410,0]],"id":41419640},{"atl":[[770,2.2],[480,0]],"id":41419611},{"atl":[[700,0],[990,2.15]],"id":41419624},{"atl":[[350,0],[720,2.21]],"id":41419632},{"atl":[[350,2],[740,0]],"id":41419628},{"atl":[[710,0],[950,2.16]],"id":41419595},{"atl":[[810,0],[990,2.15]],"id":41419637},{"atl":[[540,0],[940,2]],"id":41419604},{"atl":[[730,2],[1000,1.22]],"id":41419612},{"atl":[[770,2.2],[400,0]],"id":41419625},{"atl":[[90,2],[460,0]],"id":41419592},{"atl":[[880,0],[490,2]],"id":41419621},{"atl":[[65,2],[420,0]],"id":41419588},{"atl":[[570,2],[950,0]],"id":41419629},{"atl":[[780,2.2]],"id":41419596}],"con":true,"img":false}]}
{"op":"mcm","clk":"5347865439","pt":1646209261791,"mc":[{"id":"1.195453700","rc":[{"atl":[[540,0],[930,2.16]],"id":41419635},{"atl":[[250,4.93]],"id":41419614},{"atl":[[1000,1.22]],"id":41419610},{"atl":[[1000,1.22]],"id":41419624},{"atl":[[1000,1.22]],"id":41419637},{"atl":[[480,0]],"id":41419596}],"con":true,"img":false}]}
{"op":"mcm","clk":"5347865447","pt":1646209261893,"mc":[{"id":"1.195453700","rc":[{"atl":[[850,2.18],[500,0]],"id":41419598},{"atb":[[75,2.14]],"id":41419604},{"atl":[[930,0.16]],"id":41419604},{"atl":[[860,2.18],[490,0]],"id":41419621}],"con":true,"img":false}]}
{"op":"mcm","clk":"5347865453","pt":1646209262001,"mc":[{"id":"1.195453700","rc":[{"atb":[[36,0],[50,2.04]],"id":41419609},{"atb":[[34,0],[50,2.04]],"id":41419605},{"atb":[[9.6,11.63],[7.4,0]],"id":41419634},{"atb":[[34,0],[48,2.13]],"id":41419617},{"atb":[[8,0],[9.6,11.63]],"id":41419613},{"atb":[[34,0],[48,2.13]],"id":41419593},{"atb":[[48,2.13],[28,8.94]],"id":41419622},{"atb":[[5.3,23.26],[4.4,0]],"id":41419589},{"atb":[[42,2.44]],"id":41419618},{"atb":[[36,0],[50,2.04]],"id":41419601},{"atb":[[19,0],[29,3.57]],"id":41419630},{"atb":[[20,5.26],[14.5,19.76]],"id":41419597},{"atb":[[32,3.23],[21,15.61]],"id":41419626},{"atb":[[32,0],[46,2.22]],"id":41419639},{"atb":[[10,11.11],[7,0]],"id":41419606},{"atb":[[32,0],[42,2.44]],"id":41419635},{"atb":[[5.1,89.46],[4.1,86.06]],"id":41419585},{"atb":[[34,0],[48,5.4]],"id":41419614},{"atb":[[34,0],[46,5.49]],"id":41419610},{"atb":[[46,2.22],[27,8.94]],"id":41419623},{"atb":[[3.8,0],[4.4,29.41]],"id":41419590},{"atb":[[34,0],[48,2.13]],"id":41419619},{"atb":[[5.6,0],[7,16.67]],"id":41419586},{"atb":[[38,2.7],[23,0]],"id":41419631},{"atb":[[7.4,15.62],[5.4,0]],"id":41419627},{"atb":[[44,2.33],[28,13.88]],"id":41419607},{"atb":[[36,0],[50,2.04]],"id":41419636},{"atb":[[50,2.04],[28,8.94]],"id":41419603},{"atb":[[36,0],[50,2.04]],"id":41419615},{"atb":[[20,0],[27,3.85]],"id":41419611},{"atb":[[6,20],[4.7,0]],"id":41419591},{"atb":[[6.2,0],[8.4,13.51]],"id":41419620},{"atb":[[5.1,0],[6,20]],"id":41419587},{"atb":[[22,20.06],[13.5,0]],"id":41419632},{"atb":[[9.6,8.12],[14,7.69]],"id":41419599},{"atb":[[22,4.76],[13,0]],"id":41419628},{"atb":[[34,0],[46,2.22]],"id":41419595},{"atb":[[36,0],[50,2.04]],"id":41419608},{"atb":[[36,0],[50,2.04]],"id":41419616},{"atb":[[19.5,5.41],[13,0]],"id":41419625},{"atb":[[9.2,12.2],[6,0]],"id":41419592},{"atb":[[19,0],[29,3.57]],"id":41419621},{"atb":[[4.8,0],[6,20]],"id":41419588},{"atl":[[1000,1.22]],"id":41419600},{"atb":[[18.5,0],[28,3.7]],"id":41419596}],"con":true,"img":false}]}
{"op":"mcm","clk":"5347865459","pt":1646209262061,"mc":[{"id":"1.195453700","rc":[{"atb":[[25,14.5]],"id":41419618}],"con":true,"img":false}]}
{"op":"mcm","clk":"5347865463","pt":1646209262163,"mc":[{"id":"1.195453700","rc":[{"atl":[[44,0],[55,0]],"id":41419592}],"con":true,"img":false}]}
{"op":"mcm","clk":"5347865467","pt":1646209262268,"mc":[{"id":"1.195453700","rc":[{"atl":[[46,4.96],[60,9.92]],"id":41419592}],"con":true,"img":false}]}
{"op":"mcm","clk":"5347865651","pt":1646209265466,"mc":[{"id":"1.195453700","rc":[{"atl":[[250,4.96]],"id":41419593}],"con":true,"img":false}]}
{"op":"mcm","clk":"5347865658","pt":1646209265568,"mc":[{"id":"1.195453700","rc":[{"atl":[[900,2]],"id":41419593}],"con":true,"img":false}]}
{"op":"mcm","clk":"5347865664","pt":1646209265695,"mc":[{"id":"1.195453700","rc":[{"atl":[[1000,0]],"id":41419593},{"atb":[[10.5,9.92],[11,0],[12.5,4.96],[13,0]],"id":41419586}],"con":true,"img":false}]}
{"op":"mcm","clk":"5347865667","pt":1646209265788,"mc":[{"id":"1.195453700","rc":[{"atb":[[150,0],[110,0]],"id":41419602}],"con":true,"img":false}]}
{"op":"mcm","clk":"5347865675","pt":1646209265892,"mc":[{"id":"1.195453700","rc":[{"atb":[[140,4.96],[100,9.92]],"id":41419602}],"con":true,"img":false}]}
{"op":"mcm","clk":"5347865682","pt":1646209265954,"mc":[{"id":"1.195453700","rc":[{"atl":[[1000,1.23]],"id":41419593}],"con":true,"img":false}]}
{"op":"mcm","clk":"5347865719","pt":1646209266570,"mc":[{"id":"1.195453700","rc":[{"atl":[[600,0],[860,2.18]],"id":41419607}],"con":true,"img":false}]}
{"op":"mcm","clk":"5347865724","pt":1646209266667,"mc":[{"id":"1.195453700","rc":[{"atl":[[390,0],[770,2.2]],"id":41419633},{"atl":[[880,0],[990,2.15]],"id":41419600}],"con":true,"img":false}]}
{"op":"mcm","clk":"5347865728","pt":1646209266776,"mc":[{"id":"1.195453700","rc":[{"atl":[[850,2.18],[490,0]],"id":41419630},{"atl":[[640,0],[960,2.16]],"id":41419623},{"atl":[[70,0],[75,11.92]],"id":41419627},{"atl":[[590,0],[860,2.18]],"id":41419594},{"atl":[[350,0],[720,2.21]],"id":41419628},{"atl":[[730,0]],"id":41419612},{"atl":[[570,0],[930,2.16]],"id":41419629}],"con":true,"img":false}]}
{"op":"mcm","clk":"5347865733","pt":1646209266880,"mc":[{"id":"1.195453700","rc":[{"atl":[[420,2.37]],"id":41419627},{"atl":[[970,2.16]],"id":41419612}],"con":true,"img":false}]}
{"op":"mcm","clk":"5347865741","pt":1646209266982,"mc":[{"id":"1.195453700","rc":[{"atl":[[75,9.92]],"id":41419627}],"con":true,"img":false}]}
{"op":"mcm","clk":"5347865844","pt":1646209268681,"mc":[{"id":"1.195453700","rc":[{"atb":[[34,0],[48,2.13]],"id":41419638},{"atb":[[32,0],[44,2.33]],"id":41419594},{"atb":[[34,0],[48,5.4]],"id":41419600}],"con":true,"img":false}]}
{"op":"mcm","clk":"5347865888","pt":1646209269462,"mc":[{"id":"1.195453700","rc":[{"atl":[[990,3.41],[250,0]],"id":41419614}],"con":true,"img":false}]}
{"op":"mcm","clk":"5347865915","pt":1646209269870,"mc":[{"id":"1.195453700","rc":[{"atl":[[200,0],[250,4.96]],"id":41419597},{"atl":[[16.5,0],[17,9.92],[14.5,0],[15,4.96]],"id":41419585},{"atl":[[170,0],[200,4.96]],"id":41419598},{"atl":[[190,0],[230,4.96]],"id":41419594},{"atl":[[190,0],[210,4.96]],"id":41419607},{"atl":[[220,0],[250,4.96]],"id":41419628},{"atl":[[80,9.92],[46,0]],"id":41419592},{"atl":[[150,0],[160,4.96]],"id":41419621},{"atl":[[160,0],[200,4.96]],"id":41419596}],"con":true,"img":false}]}
{"op":"mcm","clk":"5347865919","pt":1646209269973,"mc":[{"id":"1.195453700","rc":[{"atl":[[1000,0]],"id":41419638},{"atb":[[46,0],[50,2.04]],"id":41419639},{"atl":[[580,2],[860,0.18]],"id":41419594},{"atl":[[600,2]],"id":41419607},{"atb":[[130,4.96],[140,0],[95,9.92],[100,0]],"id":41419615},{"atl":[[720,0.21]],"id":41419628},{"atb":[[130,4.96],[140,0],[95,9.92],[100,0]],"id":41419616}],"con":true,"img":false}]}
{"op":"mcm","clk":"5347865921","pt":1646209270073,"mc":[{"id":"1.195453700","rc":[{"atl":[[750,0.21],[400,2]],"id":41419597},{"atl":[[850,0.18],[510,2]],"id":41419598},{"atl":[[860,0.18]],"id":41419607},{"atl":[[350,2]],"id":41419628},{"atl":[[860,0.18],[490,2]],"id":41419621},{"atl":[[780,0.2],[480,2]],"id":41419596}],"con":true,"img":false}]}
{"op":"mcm","clk":"5347865934","pt":1646209270277,"mc":[{"id":"1.195453700","rc":[{"atl":[[40,0],[42,4.96],[48,0],[50,9.92]],"id":41419634},{"atl":[[170,0],[180,4.96]],"id":41419639},{"atl":[[180,0],[190,4.96]],"id":41419635},{"atl":[[990,2.15]],"id":41419614}],"con":true,"img":false}]}
{"op":"mcm","clk":"5347865950","pt":1646209270482,"mc":[{"id":"1.195453700","rc":[{"atl":[[860,0.18],[500,2]],"id":41419639},{"atl":[[590,2],[930,0.16]],"id":41419635}],"con":true,"img":false}]}
{"op":"mcm","clk":"5347865955","pt":1646209270585,"mc":[{"id":"1.195453700","rc":[{"atl":[[210,4.96]],"id":41419597},{"atl":[[17,0],[15,0]],"id":41419585},{"atl":[[200,0]],"id":41419598},{"atl":[[250,0]],"id":41419628},{"atl":[[160,0]],"id":41419621}],"con":true,"img":false}]}
{"op":"mcm","clk":"5347865965","pt":1646209270688,"mc":[{"id":"1.195453700","rc":[{"atl":[[900,0],[990,2.15]],"id":41419593}],"con":true,"img":false}]}
{"op":"mcm","clk":"5347865980","pt":1646209270893,"mc":[{"id":"1.195453700","rc":[{"atb":[[130,0],[95,0]],"id":41419615},{"atb":[[130,0],[95,0]],"id":41419616}],"con":true,"img":false}]}
{"op":"mcm","clk":"5347866006","pt":1646209271264,"mc":[{"id":"1.195453700","rc":[{"atl":[[16.5,9.92],[14.5,4.96]],"id":41419585}],"con":true,"img":false}]}
{"op":"mcm","clk":"5347866012","pt":1646209271366,"mc":[{"id":"1.195453700","rc":[{"atl":[[170,4.96]],"id":41419598},{"atl":[[220,4.96]],"id":41419628},{"atl":[[150,4.96]],"id":41419621}],"con":true,"img":false}]}
{"op":"mcm","clk":"5347866025","pt":1646209271572,"mc":[{"id":"1.195453700","rc":[{"atb":[[140,4.96],[100,9.92]],"id":41419615},{"atb":[[140,4.96],[100,9.92]],"id":41419616}],"con":true,"img":false}]}
{"op":"mcm","clk":"5347866225","pt":1646209274900,"mc":[{"id":"1.195453700","rc":[{"atl":[[210,0],[220,4.96]],"id":41419604},{"atl":[[220,0],[230,4.96]],"id":41419629}],"con":true,"img":false}]}
{"op":"mcm","clk":"5347866240","pt":1646209275107,"mc":[{"id":"1.195453700","rc":[{"atl":[[1000,0]],"id":41419603},{"atl":[[540,2],[940,0]],"id":41419604},{"atl":[[560,2],[930,0.16]],"id":41419629}],"con":true,"img":false}]}
{"op":"mcm","clk":"5347866248","pt":1646209275172,"mc":[{"id":"1.195453700","rc":[{"atl":[[850,2.18],[510,0]],"id":41419598},{"atl":[[350,0],[720,2.21]],"id":41419628},{"atb":[[130,4.96],[140,0],[95,9.92],[100,0]],"id":41419616}],"con":true,"img":false}]}
{"op":"mcm","clk":"5347866256","pt":1646209275272,"mc":[{"id":"1.195453700","rc":[{"atl":[[860,2.18],[490,0]],"id":41419621}],"con":true,"img":false}]}
{"op":"mcm","clk":"5347866308","pt":1646209275980,"mc":[{"id":"1.195453700","rc":[{"atl":[[230,0]],"id":41419629}],"con":true,"img":false}]}
{"op":"mcm","clk":"5347866364","pt":1646209276909,"mc":[{"id":"1.195453700","rc":[{"atb":[[140,6.1],[75,12.72],[27,0]],"id":41419609},{"atb":[[140,6.1],[70,13.11],[27,0]],"id":41419605},{"atb":[[20,17.22],[9.4,15.88]],"id":41419634},{"atl":[[130,11.83],[550,0],[120,1.33]],"id":41419634},{"atb":[[65,9.86],[26,0],[110,6.41]],"id":41419617},{"atb":[[80,14.17],[110,6.41],[28,4.93]],"id":41419593},{"atl":[[250,5.6]],"id":41419593},{"atb":[[8.8,18.04],[5.7,28.38]],"id":41419589},{"atl":[[15.5,15.91]],"id":41419589},{"atb":[[80,6.97],[25,5.55]],"id":41419618},{"atl":[[180,5.85]],"id":41419618},{"atb":[[75,12.72],[27,0]],"id":41419601},{"atb":[[50,15.54],[25,5.55]],"id":41419630},{"atl":[[220,0.72]],"id":41419630},{"atb":[[48,15.54],[29,4.76]],"id":41419597},{"atl":[[780,0],[400,5.19],[200,0.79]],"id":41419597},{"atb":[[85,6.85],[21,6.67],[60,14.07]],"id":41419626},{"atl":[[160,5.96]],"id":41419626},{"atl":[[490,0.32]],"id":41419639},{"atb":[[75,16.91],[28,4.93]],"id":41419614},{"atb":[[70,13.11],[26,0],[120,6.29]],"id":41419610},{"atl":[[230,5.65]],"id":41419610},{"atb":[[65,13.55],[100,6.56],[27,0]],"id":41419623},{"atl":[[200,5.75]],"id":41419623},{"atb":[[70,9.15],[25,0],[110,6.41]],"id":41419619},{"atb":[[80,6.97],[25,5.55],[60,24.68]],"id":41419631},{"atl":[[200,5.75]],"id":41419631},{"atb":[[9.6,15.51],[14.5,17.22]],"id":41419627},{"atl":[[420,5.41],[450,0]],"id":41419627},{"atb":[[70,14.17],[95,6.64],[28,4.93]],"id":41419607},{"atl":[[590,0.26],[860,1.66],[890,0]],"id":41419607},{"atb":[[70,13.11],[140,1.14],[28,0]],"id":41419636},{"atb":[[120,6.29]],"id":41419603},{"atb":[[140,6.1]],"id":41419615},{"atb":[[48,15.54],[25,5.55]],"id":41419611},{"atl":[[210,0.75]],"id":41419611},{"atb":[[60,14.07],[30,3.45]],"id":41419624},{"atl":[[210,5.72]],"id":41419624},{"atb":[[17,17.22],[8.2,18.52]],"id":41419620},{"atl":[[530,0],[110,13.62]],"id":41419620},{"atb":[[9.6,25.42],[6.6,23.82]],"id":41419587},{"atl":[[440,0],[60,23.32]],"id":41419587},{"atl":[[190,5.8]],"id":41419632},{"atb":[[9.6,0],[26,29.81],[30,10.43]],"id":41419599},{"atl":[[620,0],[200,8.39],[60,7.65]],"id":41419599},{"atb":[[44,13.9],[29,4.76]],"id":41419628},{"atb":[[75,12.72],[27,0]],"id":41419608},{"atb":[[75,12.74],[24,5.8],[110,6.41]],"id":41419637},{"atl":[[240,5.62]],"id":41419637},{"atb":[[75,12.72],[80,0.24],[26,0]],"id":41419616},{"atb":[[75,12.74],[26,0]],"id":41419612},{"atb":[[44,12.22],[22,6.35]],"id":41419625},{"atb":[[75,7.1],[24,5.8],[55,24.68]],"id":41419621},{"atl":[[150,6.02]],"id":41419621},{"atl":[[22,12.52]],"id":41419588},{"atb":[[75,8.32],[25,5.55]],"id":41419629},{"atl":[[220,4.96]],"id":41419629}],"con":true,"img":false}]}
{"op":"mcm","clk":"5347866373","pt":1646209277014,"mc":[{"id":"1.195453700","rc":[{"atb":[[70,13.11],[26,0]],"id":41419638},{"atb":[[9.6,43.7],[9.4,15.88]],"id":41419613},{"atl":[[570,0],[190,8.73],[55,7.9]],"id":41419613},{"atb":[[28,0],[120,6.29],[60,10.69]],"id":41419622},{"atl":[[390,0],[100,14.79]],"id":41419589},{"atb":[[150,6.02]],"id":41419601},{"atb":[[65,13.55],[26,0]],"id":41419639},{"atl":[[860,1.66],[890,0]],"id":41419639},{"atb":[[22,17.22],[9.4,15.88]],"id":41419606},{"atl":[[540,0],[150,10.52],[48,8.34]],"id":41419606},{"atb":[[75,12.72],[100,6.56],[28,4.93]],"id":41419635},{"atl":[[580,0.27],[930,1.53],[960,0]],"id":41419635},{"atb":[[110,6.41]],"id":41419614},{"atl":[[230,5.65]],"id":41419614},{"atl":[[14.5,16.72]],"id":41419590},{"atb":[[55,27.63],[28,4.93]],"id":41419598},{"atl":[[170,5.9]],"id":41419598},{"atb":[[80,19.17],[110,6.41],[28,4.93]],"id":41419594},{"atl":[[570,0.27],[860,1.66],[890,0]],"id":41419594},{"atb":[[48,12.22]],"id":41419640},{"atl":[[180,5.85]],"id":41419640},{"atb":[[65,13.55],[28,0]],"id":41419603},{"atb":[[70,13.11],[27,0]],"id":41419615},{"atb":[[8.6,29.57],[6.6,23.82]],"id":41419591},{"atl":[[38,22.35],[340,0]],"id":41419591},{"atl":[[22,12.52]],"id":41419587},{"atb":[[22,11.11],[46,12.22]],"id":41419632},{"atl":[[220,5.68]],"id":41419628},{"atb":[[80,14.17],[110,6.41],[28,4.93]],"id":41419595},{"atl":[[220,5.68]],"id":41419595},{"atb":[[150,6.02]],"id":41419608},{"atb":[[75,12.72],[25,5.55]],"id":41419604},{"atl":[[930,1.53],[960,0]],"id":41419604},{"atb":[[110,6.41]],"id":41419612},{"atl":[[220,5.68]],"id":41419612},{"atl":[[160,5.96]],"id":41419625},{"atb":[[9.6,25.42],[6.6,23.82]],"id":41419588},{"atl":[[65,21.68],[430,0]],"id":41419588},{"atl":[[200,5.75]],"id":41419633},{"atb":[[100,6.56]],"id":41419629},{"atl":[[920,0.17]],"id":41419629},{"atb":[[50,15.4],[25,5.55]],"id":41419596},{"atl":[[780,1.83],[810,0],[470,0.33]],"id":41419596}],"con":true,"img":false}]}
{"op":"mcm","clk":"5347866376","pt":1646209277071,"mc":[{"id":"1.195453700","rc":[{"atb":[[120,1.33]],"id":41419638},{"atb":[[75,0.24],[27,0]],"id":41419602},{"atb":[[9.2,17.22],[8.2,18.52]],"id":41419585},{"atl":[[36,15.12],[340,0],[14.5,16.72]],"id":41419585},{"atb":[[7.2,17.22],[7,22.23]],"id":41419590},{"atl":[[170,0],[100,14.26]],"id":41419590},{"atb":[[10.5,32.07],[6.6,23.82]],"id":41419586},{"atl":[[85,17.05],[490,0]],"id":41419586},{"atb":[[44,13.9],[25,5.55]],"id":41419633},{"atb":[[130,6.19],[75,12.74],[28,4.93]],"id":41419600},{"atl":[[240,5.62]],"id":41419600}],"con":true,"img":false}]}
{"op":"mcm","clk":"5347866382","pt":1646209277175,"mc":[{"id":"1.195453700","rc":[{"atl":[[29,10.63]],"id":41419586},{"atb":[[18.5,17.22],[11.5,12.7]],"id":41419592},{"atl":[[55,2.94],[480,0]],"id":41419592}],"con":true,"img":false}]}
{"op":"mcm","clk":"5347866387","pt":1646209277277,"mc":[{"id":"1.195453700","rc":[{"atl":[[770,3.86],[800,0]],"id":41419611},{"atl":[[930,1.53],[960,0]],"id":41419629}],"con":true,"img":false}]}
{"op":"mcm","clk":"5347866393","pt":1646209277380,"mc":[{"id":"1.195453700","rc":[{"atl":[[850,3.68],[880,0]],"id":41419630}],"con":true,"img":false}]}
{"op":"mcm","clk":"5347866397","pt":1646209277481,"mc":[{"id":"1.195453700","rc":[{"atl":[[250,5.11]],"id":41419614},{"atb":[[12.5,18.77]],"id":41419586}],"con":true,"img":false}]}
{"op":"mcm","clk":"5347866403","pt":1646209277588,"mc":[{"id":"1.195453700","rc":[{"atb":[[75,10.58]],"id":41419609},{"atb":[[70,10.8]],"id":41419605},{"atl":[[520,0]],"id":41419634},{"atb":[[65,7.38]],"id":41419617},{"atb":[[85,9.92]],"id":41419593},{"atl":[[990,2]],"id":41419593},{"atl":[[360,0]],"id":41419589},{"atb":[[70,2.72]],"id":41419618},{"atl":[[830,2]],"id":41419618},{"atl":[[850,3.49]],"id":41419630},{"atl":[[750,0]],"id":41419597},{"atb":[[60,11.38]],"id":41419626},{"atl":[[770,2]],"id":41419614},{"atb":[[70,10.8]],"id":41419610},{"atl":[[990,2]],"id":41419610},{"atb":[[65,11.07]],"id":41419623},{"atl":[[960,2]],"id":41419623},{"atb":[[70,6.85]],"id":41419619},{"atb":[[70,2.72]],"id":41419631},{"atb":[[75,9.92]],"id":41419607},{"atl":[[860,1.47]],"id":41419607},{"atb":[[70,10.8]],"id":41419636},{"atb":[[65,11.07]],"id":41419603},{"atb":[[70,10.8]],"id":41419615},{"atl":[[770,3.65]],"id":41419611},{"atl":[[990,2]],"id":41419624},{"atb":[[29,2.72]],"id":41419599},{"atl":[[590,0]],"id":41419599},{"atl":[[990,2]],"id":41419637},{"atb":[[100,6.56]],"id":41419604},{"atl":[[210,0.75]],"id":41419604},{"atb":[[75,10.58]],"id":41419616},{"atb":[[65,2.72]],"id":41419621},{"atl":[[860,2]],"id":41419621},{"atl":[[400,0]],"id":41419588}],"con":true,"img":false}]}
{"op":"mcm","clk":"5347866408","pt":1646209277683,"mc":[{"id":"1.195453700","rc":[{"atb":[[60,24.68]],"id":41419618},{"atl":[[880,2]],"id":41419626},{"atb":[[90,6.74]],"id":41419639},{"atl":[[860,1.47]],"id":41419639},{"atl":[[990,0.15]],"id":41419614},{"atl":[[140,0]],"id":41419590},{"atl":[[830,2]],"id":41419631},{"atb":[[100,6.56]],"id":41419624},{"atl":[[720,2]],"id":41419632},{"atb":[[75,10.6]],"id":41419637},{"atl":[[970,2]],"id":41419612}],"con":true,"img":false}]}
{"op":"mcm","clk":"5347866412","pt":1646209277785,"mc":[{"id":"1.195453700","rc":[{"atl":[[540,0]],"id":41419613},{"atb":[[60,8]],"id":41419622},{"atb":[[75,10.58]],"id":41419601},{"atl":[[510,0]],"id":41419606},{"atb":[[75,10.58]],"id":41419635},{"atl":[[930,1.36]],"id":41419635},{"atb":[[75,14.76]],"id":41419614},{"atl":[[990,0]],"id":41419614},{"atl":[[850,2]],"id":41419598},{"atl":[[55,7.9]],"id":41419627},{"atb":[[80,17.16]],"id":41419594},{"atl":[[860,1.47]],"id":41419594},{"atb":[[25,5.55]],"id":41419640},{"atl":[[780,2]],"id":41419640},{"atl":[[410,0]],"id":41419587},{"atl":[[720,2]],"id":41419628},{"atb":[[85,9.92]],"id":41419595},{"atl":[[950,2]],"id":41419595},{"atb":[[75,10.58]],"id":41419608},{"atb":[[75,10.6]],"id":41419612},{"atl":[[770,2]],"id":41419625},{"atl":[[770,2]],"id":41419633},{"atb":[[75,6.17]],"id":41419629},{"atl":[[930,1.37]],"id":41419629},{"atl":[[780,1.63]],"id":41419596}],"con":true,"img":false}]}
{"op":"mcm","clk":"5347866418","pt":1646209277889,"mc":[{"id":"1.195453700","rc":[{"atb":[[70,10.8]],"id":41419638},{"atb":[[70,10.8]],"id":41419602},{"atl":[[310,0]],"id":41419585},{"atb":[[75,10.6]],"id":41419600},{"atl":[[990,2]],"id":41419600}],"con":true,"img":false}]}
{"op":"mcm","clk":"5347866424","pt":1646209277991,"mc":[{"id":"1.195453700","rc":[{"atl":[[460,0]],"id":41419586},{"atl":[[90,14.26],[450,0]],"id":41419592}],"con":true,"img":false}]}
{"op":"mcm","clk":"5347866442","pt":1646209278299,"mc":[{"id":"1.195453700","rc":[{"atb":[[11.5,2.72]],"id":41419586}],"con":true,"img":false}]}
{"op":"mcm","clk":"5347866454","pt":1646209278504,"mc":[{"id":"1.195453700","rc":[{"atl":[[930,1.36]],"id":41419604}],"con":true,"img":false}]}
{"op":"mcm","clk":"5347866460","pt":1646209278607,"mc":[{"id":"1.195453700","rc":[{"atb":[[65,11.07]],"id":41419639},{"atl":[[420,5.04]],"id":41419627},{"atb":[[60,11.38]],"id":41419624},{"atb":[[75,10.58]],"id":41419604}],"con":true,"img":false}]}
{"op":"mcm","clk":"5347866558","pt":1646209280202,"mc":[{"id":"1.195453700","rc":[{"atl":[[560,2],[500,0]],"id":41419639},{"atl":[[920,2.17]],"id":41419629}],"con":true,"img":false}]}
{"op":"mcm","clk":"5347866563","pt":1646209280303,"mc":[{"id":"1.195453700","rc":[{"atl":[[560,0]],"id":41419629}],"con":true,"img":false}]}
{"op":"mcm","clk":"5347866571","pt":1646209280509,"mc":[{"id":"1.195453700","rc":[{"atl":[[260,4.96]],"id":41419617},{"atl":[[260,4.96]],"id":41419622},{"atl":[[260,4.96]],"id":41419603},{"atl":[[260,4.96],[240,0.66]],"id":41419637}],"con":true,"img":false}]}
{"op":"mcm","clk":"5347866584","pt":1646209280672,"mc":[{"id":"1.195453700","rc":[{"atl":[[880,2],[1000,0]],"id":41419617},{"atl":[[930,2],[1000,0]],"id":41419622},{"atl":[[910,2],[990,0]],"id":41419637}],"con":true,"img":false}]}
{"op":"mcm","clk":"5347866595","pt":1646209280898,"mc":[{"id":"1.195453700","rc":[{"atl":[[1000,1.28]],"id":41419617}],"con":true,"img":false}]}
{"op":"mcm","clk":"5347866618","pt":1646209281283,"mc":[{"id":"1.195453700","rc":[{"atl":[[250,0.63]],"id":41419617},{"atl":[[250,0.63],[1000,1.28]],"id":41419622},{"atl":[[250,1.12]],"id":41419603},{"atl":[[990,1.29]],"id":41419637}],"con":true,"img":false}]}
{"op":"mcm","clk":"5347866623","pt":1646209281388,"mc":[{"id":"1.195453700","rc":[{"atl":[[1000,0]],"id":41419637}],"con":true,"img":false}]}
{"op":"mcm","clk":"5347866641","pt":1646209281698,"mc":[{"id":"1.195453700","rc":[{"atl":[[990,1.45]],"id":41419603}],"con":true,"img":false}]}
{"op":"mcm","clk":"5347866661","pt":1646209282103,"mc":[{"id":"1.195453700","rc":[{"atl":[[990,0]],"id":41419617},{"atl":[[990,0]],"id":41419622},{"atl":[[990,1.29]],"id":41419603}],"con":true,"img":false}]}
{"op":"mcm","clk":"5347866825","pt":1646209285002,"mc":[{"id":"1.195453700","rc":[{"atl":[[770,3.68],[250,0]],"id":41419614}],"con":true,"img":false}]}
{"op":"mcm","clk":"5347866865","pt":1646209285819,"mc":[{"id":"1.195453700","rc":[{"atl":[[770,2]],"id":41419614}],"con":true,"img":false}]}
{"op":"mcm","clk":"5347867157","pt":1646209291217,"mc":[{"id":"1.195453700","rc":[{"atb":[[130,4.96],[140,0],[95,9.92],[100,0]],"id":41419615},{"atl":[[36,9.49]],"id":41419620}],"con":true,"img":false}]}
{"op":"mcm","clk":"5347867211","pt":1646209292200,"mc":[{"id":"1.195453700","rc":[{"atb":[[75,0.24]],"id":41419615},{"atl":[[500,0]],"id":41419620}],"con":true,"img":false}]}
{"op":"mcm","clk":"5347867217","pt":1646209292302,"mc":[{"id":"1.195453700","rc":[{"atl":[[130,2],[120,12.35]],"id":41419634},{"atl":[[400,2],[250,10.24]],"id":41419597},{"atl":[[180,5.85]],"id":41419639},{"atl":[[580,4.27]],"id":41419594},{"atl":[[600,4.19],[210,5.72]],"id":41419607},{"atb":[[70,0],[95,19]],"id":41419636},{"atb":[[130,6.19],[75,0],[80,7.98]],"id":41419616}],"con":true,"img":false}]}
{"op":"mcm","clk":"5347867222","pt":1646209292403,"mc":[{"id":"1.195453700","rc":[{"atb":[[85,19.28]],"id":41419638},{"atl":[[860,0]],"id":41419639},{"atl":[[590,4.23],[190,5.8],[930,0]],"id":41419635},{"atl":[[860,0],[230,5.65]],"id":41419594},{"atl":[[860,0]],"id":41419607},{"atl":[[540,4.43],[930,0]],"id":41419604},{"atl":[[220,5.68]],"id":41419629},{"atl":[[190,0.84],[780,0],[480,4.75]],"id":41419596}],"con":true,"img":false}]}
{"op":"mcm","clk":"5347867227","pt":1646209292507,"mc":[{"id":"1.195453700","rc":[{"atb":[[150,1.06]],"id":41419602}],"con":true,"img":false}]}
{"op":"mcm","clk":"5347867237","pt":1646209292709,"mc":[{"id":"1.195453700","rc":[{"atb":[[70,0],[75,7.98]],"id":41419615}],"con":true,"img":false}]}
{"op":"mcm","clk":"5347867245","pt":1646209292915,"mc":[{"id":"1.195453700","rc":[{"atl":[[250,5.28]],"id":41419614}],"con":true,"img":false}]}
{"op":"mcm","clk":"5347867257","pt":1646209293114,"mc":[{"id":"1.195453700","rc":[{"atb":[[70,0]],"id":41419638},{"atl":[[560,4.35],[490,0]],"id":41419639},{"atl":[[580,0]],"id":41419635},{"atl":[[570,0]],"id":41419594},{"atl":[[590,0]],"id":41419607},{"atb":[[80,7.74]],"id":41419616},{"atl":[[920,2]],"id":41419629},{"atl":[[470,0]],"id":41419596}],"con":true,"img":false}]}
{"op":"mcm","clk":"5347867261","pt":1646209293217,"mc":[{"id":"1.195453700","rc":[{"atb":[[70,0],[75,0],[100,18.88]],"id":41419602}],"con":true,"img":false}]}
{"op":"mcm","clk":"5347867270","pt":1646209293422,"mc":[{"id":"1.195453700","rc":[{"atl":[[80,26.5],[90,2]],"id":41419592}],"con":true,"img":false}]}
{"op":"mcm","clk":"5347867398","pt":1646209296304,"mc":[{"id":"1.195453700","rc":[{"atl":[[880,3.5],[1000,0]],"id":41419617}],"con":true,"img":false}]}
{"op":"mcm","clk":"5347867413","pt":1646209296617,"mc":[{"id":"1.195453700","rc":[{"atl":[[930,3.42]],"id":41419622},{"atl":[[910,3.45],[990,0]],"id":41419637}],"con":true,"img":false}]}
{"op":"mcm","clk":"5347867420","pt":1646209296717,"mc":[{"id":"1.195453700","rc":[{"atl":[[1000,0]],"id":41419622}],"con":true,"img":false}]}
{"op":"mcm","clk":"5347867483","pt":1646209298006,"mc":[{"id":"1.195453700","rc":[{"atl":[[270,4.96]],"id":41419619}],"con":true,"img":false}]}
{"op":"mcm","clk":"5347867491","pt":1646209298210,"mc":[{"id":"1.195453700","rc":[{"atl":[[940,2],[1000,0]],"id":41419619}],"con":true,"img":false}]}
{"op":"mcm","clk":"5347867507","pt":1646209298621,"mc":[{"id":"1.195453700","rc":[{"atl":[[260,0.61],[1000,1.33]],"id":41419619}],"con":true,"img":false}]}
{"op":"mcm","clk":"5347867530","pt":1646209299024,"mc":[{"id":"1.195453700","rc":[{"atl":[[260,0],[270,4.96]],"id":41419603},{"atb":[[16.5,0],[17.5,4.96],[18.5,12.26],[21,0],[26,0]],"id":41419592},{"atb":[[75,2.72]],"id":41419596}],"con":true,"img":false}]}
{"op":"mcm","clk":"5347867536","pt":1646209299127,"mc":[{"id":"1.195453700","rc":[{"atl":[[16,4.96],[17.5,0],[18,9.92],[15.5,0]],"id":41419591}],"con":true,"img":false}]}
{"op":"mcm","clk":"5347867555","pt":1646209299435,"mc":[{"id":"1.195453700","rc":[{"atl":[[990,0]],"id":41419619}],"con":true,"img":false}]}
{"op":"mcm","clk":"5347867561","pt":1646209299538,"mc":[{"id":"1.195453700","rc":[{"atl":[[170,4.96],[180,4.96]],"id":41419598},{"atb":[[18.5,21.33],[11.5,45.74]],"id":41419592}],"con":true,"img":false}]}
{"op":"mcm","clk":"5347867567","pt":1646209299640,"mc":[{"id":"1.195453700","rc":[{"atl":[[170,0]],"id":41419598},{"atb":[[18.5,9.07]],"id":41419592}],"con":true,"img":false}]}
{"op":"mcm","clk":"5347867575","pt":1646209299744,"mc":[{"id":"1.195453700","rc":[{"atl":[[850,0],[500,2]],"id":41419598},{"atb":[[20,3.27],[25,2.72],[15.5,9.92]],"id":41419592},{"atb":[[65,7.44]],"id":41419596}],"con":true,"img":false}]}
{"op":"mcm","clk":"5347867581","pt":1646209299808,"mc":[{"id":"1.195453700","rc":[{"atl":[[36,4.53]],"id":41419591}],"con":true,"img":false}]}
{"op":"mcm","clk":"5347867588","pt":1646209300006,"mc":[{"id":"1.195453700","rc":[{"atl":[[850,1.57],[880,0]],"id":41419598}],"con":true,"img":false}]}
{"op":"mcm","clk":"5347867601","pt":1646209300317,"mc":[{"id":"1.195453700","rc":[{"atl":[[770,3.74],[250,0]],"id":41419614},{"atl":[[180,5.85]],"id":41419598},{"atl":[[36,24.18],[38,2.7]],"id":41419591},{"atb":[[11.5,12.7]],"id":41419592}],"con":true,"img":false}]}
{"op":"mcm","clk":"5347867611","pt":1646209300520,"mc":[{"id":"1.195453700","rc":[{"atl":[[310,0]],"id":41419591}],"con":true,"img":false}]}
{"op":"mcm","clk":"5347867621","pt":1646209300832,"mc":[{"id":"1.195453700","rc":[{"atl":[[990,3.29]],"id":41419603}],"con":true,"img":false}]}
{"op":"mcm","clk":"5347867632","pt":1646209301129,"mc":[{"id":"1.195453700","rc":[{"atl":[[42,0],[46,4.96],[50,0],[60,9.92]],"id":41419634},{"atb":[[70,4.96],[75,2.72],[50,25.46],[55,0]],"id":41419630},{"atb":[[44,0],[50,4.96],[55,0]],"id":41419597},{"atl":[[48,4.96]],"id":41419606},{"atl":[[770,2]],"id":41419614},{"atb":[[8,0],[9,0]],"id":41419590},{"atb":[[80,27.09],[85,0],[100,4.96],[110,1.45]],"id":41419594},{"atl":[[36,4.96]],"id":41419620},{"atl":[[65,4.96],[80,0],[85,9.92],[60,2.69]],"id":41419599},{"atb":[[70,4.96],[75,2.14],[50,9.92],[55,14.76]],"id":41419621}],"con":true,"img":false}]}
{"op":"mcm","clk":"5347867649","pt":1646209301498,"mc":[{"id":"1.195453700","rc":[{"atb":[[7.2,30.57],[6.4,56.05]],"id":41419590},{"atl":[[85,25.79],[200,2]],"id":41419599},{"atb":[[55,0]],"id":41419621}],"con":true,"img":false}]}
{"op":"mcm","clk":"5347867652","pt":1646209301601,"mc":[{"id":"1.195453700","rc":[{"atb":[[65,9.99]],"id":41419621}],"con":true,"img":false}]}
{"op":"mcm","clk":"5347867661","pt":1646209301806,"mc":[{"id":"1.195453700","rc":[{"atl":[[110,1.45]],"id":41419634},{"atb":[[70,7.26]],"id":41419630},{"atb":[[42,9.92]],"id":41419597},{"atl":[[60,2.69]],"id":41419606},{"atb":[[8.8,2.72],[7.8,3.27]],"id":41419590},{"atl":[[44,13.61]],"id":41419620}],"con":true,"img":false}]}
{"op":"mcm","clk":"5347867688","pt":1646209302426,"mc":[{"id":"1.195453700","rc":[{"atl":[[65,22.18],[150,2]],"id":41419606}],"con":true,"img":false}]}
{"op":"mcm","clk":"5347867694","pt":1646209302526,"mc":[{"id":"1.195453700","rc":[{"atl":[[120,11.02]],"id":41419634}],"con":true,"img":false}]}
{"op":"mcm","clk":"5347867785","pt":1646209304744,"mc":[{"id":"1.195453700","rc":[{"atb":[[150,0]],"id":41419602}],"con":true,"img":false}]}
{"op":"mcm","clk":"5347867793","pt":1646209304942,"mc":[{"id":"1.195453700","rc":[{"atl":[[850,3.57],[500,0]],"id":41419598}],"con":true,"img":false}]}
{"op":"mcm","clk":"5347867809","pt":1646209305207,"mc":[{"id":"1.195453700","rc":[{"atb":[[65,14.17],[100,9.92]],"id":41419602}],"con":true,"img":false}]}
{"op":"mcm","clk":"5347867822","pt":1646209305535,"mc":[{"id":"1.195453700","rc":[{"atb":[[140,6.1]],"id":41419602}],"con":true,"img":false}]}
{"op":"mcm","clk":"5347867914","pt":1646209307341,"mc":[{"id":"1.195453700","rc":[{"atb":[[130,6.19]],"id":41419615}],"con":true,"img":false}]}
{"op":"mcm","clk":"5347867923","pt":1646209307440,"mc":[{"id":"1.195453700","rc":[{"atl":[[110,13.72],[120,0]],"id":41419634},{"atl":[[580,2],[250,5.45]],"id":41419594},{"atl":[[600,2],[230,5.93]],"id":41419607}],"con":true,"img":false}]}
{"op":"mcm","clk":"5347867928","pt":1646209307540,"mc":[{"id":"1.195453700","rc":[{"atl":[[210,6.5]],"id":41419635}],"con":true,"img":false}]}
{"op":"mcm","clk":"5347867933","pt":1646209307643,"mc":[{"id":"1.195453700","rc":[{"atl":[[590,2]],"id":41419635}],"con":true,"img":false}]}
{"op":"mcm","clk":"5347867960","pt":1646209308012,"mc":[{"id":"1.195453700","rc":[{"atl":[[250,5.46]],"id":41419614}],"con":true,"img":false}]}
{"op":"mcm","clk":"5347867969","pt":1646209308218,"mc":[{"id":"1.195453700","rc":[{"atl":[[560,2],[200,6.83]],"id":41419639},{"atb":[[75,7.74]],"id":41419615}],"con":true,"img":false}]}
{"op":"mcm","clk":"5347867975","pt":1646209308424,"mc":[{"id":"1.195453700","rc":[{"atl":[[210,0]],"id":41419635}],"con":true,"img":false}]}
{"op":"mcm","clk":"5347867986","pt":1646209308734,"mc":[{"id":"1.195453700","rc":[{"atl":[[36,0],[38,4.96],[44,3.69],[46,9.92]],"id":41419620}],"con":true,"img":false}]}
{"op":"mcm","clk":"5347868003","pt":1646209309045,"mc":[{"id":"1.195453700","rc":[{"atl":[[200,0]],"id":41419639}],"con":true,"img":false}]}
{"op":"mcm","clk":"5347868008","pt":1646209309139,"mc":[{"id":"1.195453700","rc":[{"atl":[[46,22.81],[110,2]],"id":41419620}],"con":true,"img":false}]}
{"op":"mcm","clk":"5347868013","pt":1646209309244,"mc":[{"id":"1.195453700","rc":[{"atl":[[38,9.25]],"id":41419620}],"con":true,"img":false}]}
{"op":"mcm","clk":"5347868066","pt":1646209310342,"mc":[{"id":"1.195453700","rc":[{"atl":[[44,0]],"id":41419620}],"con":true,"img":false}]}
{"op":"mcm","clk":"5347868103","pt":1646209311015,"mc":[{"id":"1.195453700","rc":[{"atb":[[9.6,35.34],[11,4.96],[11.5,2.72],[9.8,0]],"id":41419588}],"con":true,"img":false}]}
{"op":"mcm","clk":"5347868169","pt":1646209311946,"mc":[{"id":"1.195453700","rc":[{"atb":[[11,20.84]],"id":41419588}],"con":true,"img":false}]}
{"op":"mcm","clk":"5347868292","pt":1646209313647,"mc":[{"id":"1.195453700","rc":[{"atl":[[940,3.46],[1000,0]],"id":41419619}],"con":true,"img":false}]}
{"op":"mcm","clk":"5347868333","pt":1646209314413,"mc":[{"id":"1.195453700","rc":[{"atb":[[18.5,27.45]],"id":41419592}],"con":true,"img":false}]}
{"op":"mcm","clk":"5347868358","pt":1646209314829,"mc":[{"id":"1.195453700","rc":[{"atl":[[580,4.37],[250,0]],"id":41419594},{"atl":[[600,4.3],[230,0]],"id":41419607}],"con":true,"img":false}]}
{"op":"mcm","clk":"5347868361","pt":1646209314931,"mc":[{"id":"1.195453700","rc":[{"atl":[[200,6.93]],"id":41419598}],"con":true,"img":false}]}
{"op":"mcm","clk":"5347868365","pt":1646209315029,"mc":[{"id":"1.195453700","rc":[{"atl":[[850,2]],"id":41419598}],"con":true,"img":false}]}
{"op":"mcm","clk":"5347868370","pt":1646209315134,"mc":[{"id":"1.195453700","rc":[{"atl":[[500,2]],"id":41419598}],"con":true,"img":false}]}
{"op":"mcm","clk":"5347868375","pt":1646209315240,"mc":[{"id":"1.195453700","rc":[{"atl":[[770,3.79],[250,0]],"id":41419614},{"atl":[[850,0]],"id":41419598}],"con":true,"img":false}]}
{"op":"mcm","clk":"5347868401","pt":1646209315751,"mc":[{"id":"1.195453700","rc":[{"atl":[[580,2]],"id":41419594}],"con":true,"img":false}]}
{"op":"mcm","clk":"5347868410","pt":1646209315957,"mc":[{"id":"1.195453700","rc":[{"atl":[[280,4.96]],"id":41419609}],"con":true,"img":false}]}
{"op":"mcm","clk":"5347868414","pt":1646209316008,"mc":[{"id":"1.195453700","rc":[{"atl":[[200,0]],"id":41419598}],"con":true,"img":false}]}
{"op":"mcm","clk":"5347868427","pt":1646209316314,"mc":[{"id":"1.195453700","rc":[{"atl":[[110,14.64]],"id":41419620}],"con":true,"img":false}]}
{"op":"mcm","clk":"5347868434","pt":1646209316419,"mc":[{"id":"1.195453700","rc":[{"atl":[[270,0.58]],"id":41419609},{"atb":[[7.2,66.58],[6.4,9.92]],"id":41419590},{"atl":[[46,9.92]],"id":41419620}],"con":true,"img":false}]}
{"op":"mcm","clk":"5347868457","pt":1646209317034,"mc":[{"id":"1.195453700","rc":[{"atl":[[1000,1.53]],"id":41419609}],"con":true,"img":false}]}
{"op":"mcm","clk":"5347868470","pt":1646209317445,"mc":[{"id":"1.195453700","rc":[{"atl":[[1000,1.38]],"id":41419609}],"con":true,"img":false}]}
{"op":"mcm","clk":"5347868641","pt":1646209321151,"mc":[{"id":"1.195453700","rc":[{"atb":[[18,0],[19,9.92],[20,12.26],[22,4.96]],"id":41419634},{"atb":[[85,0],[90,9.92],[110,1.45],[120,4.96]],"id":41419617},{"atb":[[24,3.27],[25,9.92],[28,8.6],[29,4.96]],"id":41419613},{"atl":[[240,4.96],[250,0.63]],"id":41419593},{"atl":[[170,4.96],[180,0.88]],"id":41419618},{"atl":[[210,4.96],[230,0]],"id":41419630},{"atl":[[200,5.75],[210,0],[250,5.28]],"id":41419597},{"atb":[[70,0],[80,9.92],[90,1.78],[100,4.96]],"id":41419639},{"atb":[[19,0],[19.5,9.92],[22,12.26],[23,4.96]],"id":41419606},{"atb":[[140,1.14],[150,4.96],[100,0],[110,9.92]],"id":41419602},{"atl":[[16.5,0],[16,9.92],[14,4.96],[14.5,11.76]],"id":41419585},{"atl":[[220,4.96],[230,0.69]],"id":41419614},{"atl":[[220,4.96],[230,0.69]],"id":41419610},{"atl":[[16.5,0],[16,9.92],[14,4.96],[14.5,11.76]],"id":41419590},{"atb":[[85,0],[90,9.92],[110,1.45],[120,4.96]],"id":41419619},{"atb":[[10.5,22.15],[11,9.92],[12.5,13.81],[13,4.96]],"id":41419586},{"atl":[[190,4.96],[200,0.79]],"id":41419631},{"atl":[[190,4.96]],"id":41419594},{"atb":[[42,0],[44,9.92],[50,0],[55,4.96]],"id":41419640},{"atl":[[190,4.96],[210,0.75]],"id":41419607},{"atb":[[130,0],[140,6.1],[95,9.08],[100,9.92]],"id":41419636},{"atl":[[270,0],[260,4.96]],"id":41419603},{"atl":[[200,4.96],[220,0]],"id":41419611},{"atb":[[17,12.26],[17.5,4.96],[15,0],[15.5,9.92]],"id":41419620},{"atb":[[32,4.96],[26,19.89],[27,9.92],[30,5.47]],"id":41419599},{"atl":[[210,4.96],[220,0.72]],"id":41419628},{"atl":[[210,4.96],[220,0.72]],"id":41419595},{"atl":[[210,5.72],[220,0]],"id":41419604},{"atb":[[17.5,0],[18.5,32.41],[15.5,0]],"id":41419592},{"atl":[[210,4.96],[220,0.72]],"id":41419629},{"atl":[[170,4.96],[200,0]],"id":41419596}],"con":true,"img":false}]}
{"op":"mcm","clk":"5347868648","pt":1646209321354,"mc":[{"id":"1.195453700","rc":[{"atb":[[9.6,32.07],[11.5,9.52]],"id":41419613},{"atl":[[870,2],[990,0]],"id":41419593},{"atl":[[830,0],[460,2]],"id":41419618},{"atl":[[850,1.49],[470,2]],"id":41419630},{"atl":[[720,2],[990,0]],"id":41419610},{"atl":[[830,0],[440,2]],"id":41419631},{"atl":[[770,1.65],[460,2]],"id":41419611},{"atl":[[330,2],[720,0]],"id":41419628},{"atl":[[660,2],[950,0]],"id":41419595},{"atl":[[540,2],[920,0]],"id":41419629}],"con":true,"img":false}]}
{"op":"mcm","clk":"5347868658","pt":1646209321561,"mc":[{"id":"1.195453700","rc":[{"atl":[[860,0]],"id":41419618},{"atl":[[400,5.5],[250,0]],"id":41419597},{"atb":[[110,1.45]],"id":41419639},{"atl":[[16,32.07]],"id":41419585},{"atl":[[100,2],[14,17.17]],"id":41419590},{"atl":[[190,5.8]],"id":41419631},{"atb":[[34,4.81],[26,0]],"id":41419599},{"atl":[[230,6.1]],"id":41419604}],"con":true,"img":false}]}
{"op":"mcm","clk":"5347868666","pt":1646209321663,"mc":[{"id":"1.195453700","rc":[{"atb":[[20,0],[22,19.72]],"id":41419634},{"atb":[[65,0],[90,22.53],[120,6.29]],"id":41419617},{"atb":[[9.6,0],[25,35.73],[30,5.47]],"id":41419613},{"atl":[[230,0.89],[990,1.41],[1000,0]],"id":41419593},{"atl":[[170,5.9],[830,1.68]],"id":41419618},{"atl":[[210,5.72]],"id":41419630},{"atb":[[65,0],[80,24.68]],"id":41419639},{"atb":[[22,0],[23,17.22]],"id":41419606},{"atb":[[65,2.72],[150,6.02],[110,19]],"id":41419602},{"atl":[[36,2.86],[14,17.17]],"id":41419585},{"atl":[[210,0.75]],"id":41419614},{"atl":[[210,0.75],[990,1.41],[1000,0]],"id":41419610},{"atl":[[16,32.07]],"id":41419590},{"atb":[[70,0],[90,22.45],[120,6.29]],"id":41419619},{"atb":[[10.5,0],[11.5,33.32],[13,18.19]],"id":41419586},{"atl":[[830,1.68],[860,0]],"id":41419631},{"atl":[[190,5.8]],"id":41419594},{"atl":[[180,0.88]],"id":41419607},{"atl":[[200,5.75]],"id":41419611},{"atb":[[17.5,26.11],[17,0]],"id":41419620},{"atb":[[29,17.49]],"id":41419599},{"atl":[[720,1.94],[750,0],[210,5.72]],"id":41419628},{"atl":[[200,0.79],[950,1.47],[980,0]],"id":41419595},{"atl":[[540,2]],"id":41419604},{"atl":[[210,5.72],[920,1.51],[930,0]],"id":41419629},{"atl":[[170,5.9]],"id":41419596}],"con":true,"img":false}]}
{"op":"mcm","clk":"5347868677","pt":1646209321871,"mc":[{"id":"1.195453700","rc":[{"atl":[[850,0],[470,4.98]],"id":41419630},{"atl":[[260,5.57],[270,0]],"id":41419619},{"atl":[[460,5.05]],"id":41419611}],"con":true,"img":false}]}
{"op":"mcm","clk":"5347868680","pt":1646209321920,"mc":[{"id":"1.195453700","rc":[{"atl":[[770,0]],"id":41419611},{"atl":[[46,4.96]],"id":41419592}],"con":true,"img":false}]}
{"op":"mcm","clk":"5347868688","pt":1646209322027,"mc":[{"id":"1.195453700","rc":[{"atl":[[80,16.57]],"id":41419592}],"con":true,"img":false}]}
{"op":"mcm","clk":"5347868697","pt":1646209322229,"mc":[{"id":"1.195453700","rc":[{"atl":[[770,2]],"id":41419614},{"atl":[[14.5,0]],"id":41419590},{"atl":[[200,0]],"id":41419631},{"atl":[[580,4.41]],"id":41419594},{"atl":[[600,2],[210,7.45]],"id":41419607},{"atb":[[30,0]],"id":41419599}],"con":true,"img":false}]}
{"op":"mcm","clk":"5347868701","pt":1646209322335,"mc":[{"id":"1.195453700","rc":[{"atb":[[90,0]],"id":41419639},{"atl":[[210,6.69]],"id":41419635},{"atl":[[230,0],[990,0]],"id":41419610},{"atb":[[110,0]],"id":41419619},{"atl":[[940,2]],"id":41419619},{"atb":[[12.5,0]],"id":41419586},{"atl":[[210,6.69]],"id":41419607},{"atl":[[220,0]],"id":41419595},{"atl":[[230,0]],"id":41419604},{"atl":[[46,8.48],[60,22.18]],"id":41419592},{"atl":[[220,0]],"id":41419629}],"con":true,"img":false}]}
{"op":"mcm","clk":"5347868705","pt":1646209322438,"mc":[{"id":"1.195453700","rc":[{"atb":[[110,0]],"id":41419617},{"atb":[[28,2.72]],"id":41419613},{"atl":[[990,0],[250,0]],"id":41419593},{"atl":[[180,0]],"id":41419618},{"atl":[[220,0]],"id":41419630},{"atb":[[140,0]],"id":41419602},{"atl":[[14.5,0]],"id":41419585},{"atl":[[230,0]],"id":41419614},{"atl":[[230,4.96]],"id":41419594},{"atl":[[210,0]],"id":41419611},{"atl":[[220,0]],"id":41419628},{"atl":[[80,0]],"id":41419592},{"atl":[[190,0]],"id":41419596}],"con":true,"img":false}]}
{"op":"mcm","clk":"5347868731","pt":1646209323053,"mc":[{"id":"1.195453700","rc":[{"atl":[[200,7.04]],"id":41419639},{"atl":[[770,3.82]],"id":41419614},{"atl":[[190,7.41],[480,2]],"id":41419596}],"con":true,"img":false}]}
{"op":"mcm","clk":"5347868742","pt":1646209323258,"mc":[{"id":"1.195453700","rc":[{"atl":[[55,0]],"id":41419592}],"con":true,"img":false}]}
{"op":"mcm","clk":"5347868770","pt":1646209323969,"mc":[{"id":"1.195453700","rc":[{"atl":[[190,0]],"id":41419596}],"con":true,"img":false}]}
{"op":"mcm","clk":"5347868898","pt":1646209326559,"mc":[{"id":"1.195453700","rc":[{"atl":[[70,9.92],[75,0],[50,4.96],[55,2.94]],"id":41419627},{"atl":[[160,0],[170,4.96]],"id":41419625}],"con":true,"img":false}]}
{"op":"mcm","clk":"5347868906","pt":1646209326762,"mc":[{"id":"1.195453700","rc":[{"atl":[[70,11.92],[420,3.04]],"id":41419627},{"atl":[[770,0],[390,2]],"id":41419625}],"con":true,"img":false}]}
{"op":"mcm","clk":"5347868924","pt":1646209327165,"mc":[{"id":"1.195453700","rc":[{"atl":[[70,24.18],[50,8.2],[420,0]],"id":41419627}],"con":true,"img":false}]}
{"op":"mcm","clk":"5347868939","pt":1646209327479,"mc":[{"id":"1.195453700","rc":[{"atl":[[170,5.9]],"id":41419625}],"con":true,"img":false}]}
{"op":"mcm","clk":"5347868951","pt":1646209327681,"mc":[{"id":"1.195453700","rc":[{"atb":[[85,9.92],[110,4.96]],"id":41419617},{"atb":[[150,0],[110,9.08]],"id":41419602},{"atl":[[170,4.96],[180,0.88]],"id":41419598},{"atl":[[170,0.93]],"id":41419625}],"con":true,"img":false}]}
{"op":"mcm","clk":"5347868954","pt":1646209327784,"mc":[{"id":"1.195453700","rc":[{"atb":[[90,12.6],[120,0]],"id":41419617},{"atb":[[140,4.96],[100,9.92]],"id":41419602},{"atl":[[160,4.96]],"id":41419625}],"con":true,"img":false}]}
{"op":"mcm","clk":"5347868965","pt":1646209328051,"mc":[{"id":"1.195453700","rc":[{"atb":[[10.5,9.92],[12.5,4.96],[13,4.96]],"id":41419586},{"atl":[[170,5.9]],"id":41419598},{"atl":[[55,0]],"id":41419627},{"atb":[[9.6,25.42],[11,15.87],[11.5,22.81],[9.8,9.92]],"id":41419588}],"con":true,"img":false}]}
{"op":"mcm","clk":"5347868968","pt":1646209328147,"mc":[{"id":"1.195453700","rc":[{"atb":[[11,0],[13,0]],"id":41419586},{"atl":[[75,9.92],[50,4.96],[55,4.96]],"id":41419627},{"atb":[[11,18.6]],"id":41419591},{"atl":[[16,15.54]],"id":41419591}],"con":true,"img":false}]}
{"op":"mcm","clk":"5347868977","pt":1646209328258,"mc":[{"id":"1.195453700","rc":[{"atl":[[70,14.26],[50,0]],"id":41419627},{"atl":[[390,5.64],[800,0]],"id":41419625}],"con":true,"img":false}]}
{"op":"mcm","clk":"5347868983","pt":1646209328361,"mc":[{"id":"1.195453700","rc":[{"atb":[[110,10.54]],"id":41419602},{"atl":[[170,0.93],[180,5.85]],"id":41419598}],"con":true,"img":false}]}
{"op":"mcm","clk":"5347868990","pt":1646209328467,"mc":[{"id":"1.195453700","rc":[{"atb":[[110,6.41]],"id":41419617},{"atl":[[160,0],[170,5.9]],"id":41419625},{"atb":[[9.6,3.27],[9.8,52.19]],"id":41419588}],"con":true,"img":false}]}
{"op":"mcm","clk":"5347869001","pt":1646209328670,"mc":[{"id":"1.195453700","rc":[{"atl":[[36,33.31]],"id":41419585}],"con":true,"img":false}]}
{"op":"mcm","clk":"5347869005","pt":1646209328773,"mc":[{"id":"1.195453700","rc":[{"atb":[[85,24.68],[90,0]],"id":41419617},{"atb":[[100,24.18],[110,1.45]],"id":41419602},{"atl":[[16,9.92]],"id":41419585},{"atl":[[16,9.92],[100,16.26]],"id":41419590},{"atb":[[65,19.31],[90,9.92]],"id":41419619},{"atb":[[10.5,40.51],[11.5,2.72],[12,14.43]],"id":41419586},{"atl":[[170,0],[180,4.96]],"id":41419598},{"atb":[[9.6,13.19],[11,4.96],[11.5,2.72],[9.8,42.27]],"id":41419588}],"con":true,"img":false}]}
{"op":"mcm","clk":"5347869015","pt":1646209328973,"mc":[{"id":"1.195453700","rc":[{"atl":[[65,2.48]],"id":41419627},{"atl":[[36,19.65]],"id":41419591}],"con":true,"img":false}]}
{"op":"mcm","clk":"5347869041","pt":1646209329486,"mc":[{"id":"1.195453700","rc":[{"atl":[[590,4.41]],"id":41419635},{"atb":[[10.5,9.92]],"id":41419586},{"atl":[[180,5.85]],"id":41419598},{"atl":[[90,17.86],[60,9.92]],"id":41419592}],"con":true,"img":false}]}
{"op":"mcm","clk":"5347869046","pt":1646209329589,"mc":[{"id":"1.195453700","rc":[{"atl":[[210,0]],"id":41419635},{"atl":[[200,7.13]],"id":41419598},{"atb":[[9.8,60.32]],"id":41419588}],"con":true,"img":false}]}
{"op":"mcm","clk":"5347869065","pt":1646209330162,"mc":[{"id":"1.195453700","rc":[{"atl":[[560,4.54],[200,0]],"id":41419639}],"con":true,"img":false}]}
{"op":"mcm","clk":"5347869068","pt":1646209330264,"mc":[{"id":"1.195453700","rc":[{"atl":[[590,2]],"id":41419635}],"con":true,"img":false}]}
{"op":"mcm","clk":"5347869107","pt":1646209330988,"mc":[{"id":"1.195453700","rc":[{"atl":[[560,2]],"id":41419639}],"con":true,"img":false}]}
{"op":"mcm","clk":"5347869276","pt":1646209334554,"mc":[{"id":"1.195453700","rc":[{"atl":[[290,4.96]],"id":41419638},{"atb":[[75,4.87]],"id":41419630}],"con":true,"img":false}]}
{"op":"mcm","clk":"5347869300","pt":1646209335078,"mc":[{"id":"1.195453700","rc":[{"atl":[[280,0.56]],"id":41419638},{"atl":[[200,0.79]],"id":41419611},{"atl":[[150,4.96],[160,4.96]],"id":41419621}],"con":true,"img":false}]}
{"op":"mcm","clk":"5347869306","pt":1646209335175,"mc":[{"id":"1.195453700","rc":[{"atl":[[200,0],[210,4.96]],"id":41419611},{"atl":[[150,0]],"id":41419621}],"con":true,"img":false}]}
{"op":"mcm","clk":"5347869312","pt":1646209335275,"mc":[{"id":"1.195453700","rc":[{"atb":[[70,4.96]],"id":41419630},{"atl":[[860,0],[480,2]],"id":41419621}],"con":true,"img":false}]}
{"op":"mcm","clk":"5347869317","pt":1646209335379,"mc":[{"id":"1.195453700","rc":[{"atl":[[390,2]],"id":41419625}],"con":true,"img":false}]}
{"op":"mcm","clk":"5347869322","pt":1646209335480,"mc":[{"id":"1.195453700","rc":[{"atl":[[800,1.79]],"id":41419625}],"con":true,"img":false}]}
{"op":"mcm","clk":"5347869328","pt":1646209335580,"mc":[{"id":"1.195453700","rc":[{"atl":[[990,1.61]],"id":41419638},{"atl":[[860,1.67],[890,0]],"id":41419621}],"con":true,"img":false}]}
{"op":"mcm","clk":"5347869334","pt":1646209335687,"mc":[{"id":"1.195453700","rc":[{"atl":[[390,0],[790,2]],"id":41419625}],"con":true,"img":false}]}
{"op":"mcm","clk":"5347869338","pt":1646209335793,"mc":[{"id":"1.195453700","rc":[{"atb":[[85,9.92],[60,15.33]],"id":41419617},{"atl":[[850,2],[480,0]],"id":41419621}],"con":true,"img":false}]}
{"op":"mcm","clk":"5347869343","pt":1646209335893,"mc":[{"id":"1.195453700","rc":[{"atl":[[990,1.45]],"id":41419638},{"atl":[[160,5.96]],"id":41419621}],"con":true,"img":false}]}
{"op":"mcm","clk":"5347869348","pt":1646209335991,"mc":[{"id":"1.195453700","rc":[{"atl":[[450,0.35]],"id":41419611}],"con":true,"img":false}]}
{"op":"mcm","clk":"5347869355","pt":1646209336094,"mc":[{"id":"1.195453700","rc":[{"atl":[[220,6.57]],"id":41419597},{"atl":[[230,6.28]],"id":41419604}],"con":true,"img":false}]}
{"op":"mcm","clk":"5347869357","pt":1646209336152,"mc":[{"id":"1.195453700","rc":[{"atb":[[25,9.92],[28,22.63]],"id":41419613},{"atl":[[870,3.65]],"id":41419593},{"atl":[[400,2]],"id":41419597},{"atb":[[140,6.1]],"id":41419602},{"atl":[[720,4]],"id":41419610},{"atb":[[11.5,33.32],[12.5,18.77]],"id":41419586},{"atl":[[660,4.18],[950,0]],"id":41419595}],"con":true,"img":false}]}
{"op":"mcm","clk":"5347869380","pt":1646209336461,"mc":[{"id":"1.195453700","rc":[{"atl":[[230,6.28],[470,2]],"id":41419630},{"atl":[[460,2],[230,6.28]],"id":41419611}],"con":true,"img":false}]}
{"op":"mcm","clk":"5347869389","pt":1646209336671,"mc":[{"id":"1.195453700","rc":[{"atl":[[200,0],[500,4.88]],"id":41419598}],"con":true,"img":false}]}
{"op":"mcm","clk":"5347869404","pt":1646209336879,"mc":[{"id":"1.195453700","rc":[{"atl":[[220,0]],"id":41419597},{"atl":[[210,6.89]],"id":41419635},{"atb":[[12,0]],"id":41419586}],"con":true,"img":false}]}
{"op":"mcm","clk":"5347869411","pt":1646209336988,"mc":[{"id":"1.195453700","rc":[{"atb":[[110,0]],"id":41419602}],"con":true,"img":false}]}
{"op":"mcm","clk":"5347869425","pt":1646209337286,"mc":[{"id":"1.195453700","rc":[{"atl":[[230,0]],"id":41419630},{"atl":[[230,0]],"id":41419611}],"con":true,"img":false}]}
{"op":"mcm","clk":"5347869436","pt":1646209337489,"mc":[{"id":"1.195453700","rc":[{"atb":[[65,15.87],[100,9.92]],"id":41419602}],"con":true,"img":false}]}
{"op":"mcm","clk":"5347869441","pt":1646209337599,"mc":[{"id":"1.195453700","rc":[{"atl":[[200,7.24]],"id":41419639},{"atl":[[190,7.63]],"id":41419596}],"con":true,"img":false}]}
{"op":"mcm","clk":"5347869507","pt":1646209338792,"mc":[{"id":"1.195453700","rc":[{"atl":[[180,0.88]],"id":41419640}],"con":true,"img":false}]}
{"op":"mcm","clk":"5347869513","pt":1646209338890,"mc":[{"id":"1.195453700","rc":[{"atl":[[180,0],[190,4.96]],"id":41419640}],"con":true,"img":false}]}
{"op":"mcm","clk":"5347869529","pt":1646209339090,"mc":[{"id":"1.195453700","rc":[{"atl":[[420,2]],"id":41419640}],"con":true,"img":false}]}
{"op":"mcm","clk":"5347869537","pt":1646209339202,"mc":[{"id":"1.195453700","rc":[{"atl":[[780,0]],"id":41419640}],"con":true,"img":false}]}
{"op":"mcm","clk":"5347869581","pt":1646209339762,"mc":[{"id":"1.195453700","rc":[{"atl":[[190,5.8],[780,1.86],[810,0]],"id":41419640}],"con":true,"img":false}]}
{"op":"mcm","clk":"5347869682","pt":1646209341568,"mc":[{"id":"1.195453700","rc":[{"atl":[[50,3.24]],"id":41419627}],"con":true,"img":false}]}
{"op":"mcm","clk":"5347869707","pt":1646209342083,"mc":[{"id":"1.195453700","rc":[{"atl":[[65,12.18],[70,2]],"id":41419627}],"con":true,"img":false}]}
{"op":"mcm","clk":"5347869726","pt":1646209342394,"mc":[{"id":"1.195453700","rc":[{"atl":[[65,9.7]],"id":41419627}],"con":true,"img":false}]}
{"op":"mcm","clk":"5347869759","pt":1646209342903,"mc":[{"id":"1.195453700","rc":[{"atl":[[200,4.96],[210,0.75]],"id":41419628},{"atl":[[200,4.96],[210,0.75]],"id":41419629}],"con":true,"img":false}]}
{"op":"mcm","clk":"5347869767","pt":1646209343068,"mc":[{"id":"1.195453700","rc":[{"atb":[[10.5,51.12],[11.5,2.72]],"id":41419586},{"atl":[[540,4.7],[230,0]],"id":41419604}],"con":true,"img":false}]}
{"op":"mcm","clk":"5347869778","pt":1646209343378,"mc":[{"id":"1.195453700","rc":[{"atl":[[330,6.43],[720,0]],"id":41419628},{"atl":[[540,4.7],[200,5.75],[920,0]],"id":41419629}],"con":true,"img":false}]}
{"op":"mcm","clk":"5347869789","pt":1646209343584,"mc":[{"id":"1.195453700","rc":[{"atl":[[210,5.72]],"id":41419628}],"con":true,"img":false}]}
{"op":"mcm","clk":"5347869794","pt":1646209343693,"mc":[{"id":"1.195453700","rc":[{"atl":[[200,0]],"id":41419628}],"con":true,"img":false}]}
{"op":"mcm","clk":"5347869800","pt":1646209343792,"mc":[{"id":"1.195453700","rc":[{"atl":[[200,0.79]],"id":41419628},{"atl":[[200,0.79],[210,5.72]],"id":41419629}],"con":true,"img":false}]}
{"op":"mcm","clk":"5347869806","pt":1646209343898,"mc":[{"id":"1.195453700","rc":[{"atl":[[590,4.48],[210,0]],"id":41419635},{"atl":[[540,2]],"id":41419604}],"con":true,"img":false}]}
{"op":"mcm","clk":"5347869816","pt":1646209344098,"mc":[{"id":"1.195453700","rc":[{"atl":[[200,7.34]],"id":41419598}],"con":true,"img":false}]}
{"op":"mcm","clk":"5347869821","pt":1646209344201,"mc":[{"id":"1.195453700","rc":[{"atl":[[500,2]],"id":41419598}],"con":true,"img":false}]}
{"op":"mcm","clk":"5347869825","pt":1646209344263,"mc":[{"id":"1.195453700","rc":[{"atl":[[780,3.86],[420,0]],"id":41419640},{"atl":[[210,4.96]],"id":41419629}],"con":true,"img":false}]}
{"op":"mcm","clk":"5347869832","pt":1646209344465,"mc":[{"id":"1.195453700","rc":[{"atl":[[210,0]],"id":41419628},{"atl":[[190,0],[480,5.05]],"id":41419596}],"con":true,"img":false}]}
{"op":"mcm","clk":"5347869848","pt":1646209344781,"mc":[{"id":"1.195453700","rc":[{"atl":[[560,4.62],[200,0]],"id":41419639}],"con":true,"img":false}]}
{"op":"mcm","clk":"5347869849","pt":1646209344875,"mc":[{"id":"1.195453700","rc":[{"atl":[[200,0]],"id":41419598}],"con":true,"img":false}]}
{"op":"mcm","clk":"5347869865","pt":1646209345193,"mc":[{"id":"1.195453700","rc":[{"atl":[[200,5.75]],"id":41419628}],"con":true,"img":false}]}
{"op":"mcm","clk":"5347869880","pt":1646209345502,"mc":[{"id":"1.195453700","rc":[{"atl":[[560,2]],"id":41419639},{"atb":[[70,7.69],[80,2],[50,9.92],[60,14.76]],"id":41419631}],"con":true,"img":false}]}
{"op":"mcm","clk":"5347869904","pt":1646209345710,"mc":[{"id":"1.195453700","rc":[{"atl":[[830,3.68],[440,0]],"id":41419631}],"con":true,"img":false}]}
{"op":"mcm","clk":"5347869952","pt":1646209346192,"mc":[{"id":"1.195453700","rc":[{"atl":[[830,2],[210,7.01]],"id":41419631}],"con":true,"img":false}]}
{"op":"mcm","clk":"5347869990","pt":1646209346606,"mc":[{"id":"1.195453700","rc":[{"atl":[[38,0],[40,4.96],[46,0],[48,9.92]],"id":41419620}],"con":true,"img":false}]}
{"op":"mcm","clk":"5347870033","pt":1646209347285,"mc":[{"id":"1.195453700","rc":[{"atl":[[46,3.52]],"id":41419620}],"con":true,"img":false}]}
{"op":"mcm","clk":"5347870063","pt":1646209347797,"mc":[{"id":"1.195453700","rc":[{"atl":[[48,22.56],[110,2]],"id":41419620}],"con":true,"img":false}]}
{"op":"mcm","clk":"5347870102","pt":1646209348883,"mc":[{"id":"1.195453700","rc":[{"atl":[[200,0]],"id":41419629}],"con":true,"img":false}]}
{"op":"mcm","clk":"5347870129","pt":1646209349603,"mc":[{"id":"1.195453700","rc":[{"atl":[[210,5.72]],"id":41419629}],"con":true,"img":false}]}
{"op":"mcm","clk":"5347870159","pt":1646209350377,"mc":[{"id":"1.195453700","rc":[{"atl":[[220,6.75]],"id":41419597},{"atl":[[200,0.79]],"id":41419611},{"atl":[[230,6.46]],"id":41419604}],"con":true,"img":false}]}
{"op":"mcm","clk":"5347870162","pt":1646209350477,"mc":[{"id":"1.195453700","rc":[{"atl":[[300,4.96]],"id":41419605},{"atl":[[180,4.96]],"id":41419640},{"atl":[[210,4.96]],"id":41419628},{"atl":[[160,4.96]],"id":41419621}],"con":true,"img":false}]}
{"op":"mcm","clk":"5347870168","pt":1646209350585,"mc":[{"id":"1.195453700","rc":[{"atl":[[190,0.84]],"id":41419640},{"atl":[[200,0]],"id":41419628},{"atl":[[160,0],[170,4.96]],"id":41419621},{"atl":[[170,0],[180,4.96]],"id":41419596}],"con":true,"img":false}]}
{"op":"mcm","clk":"5347870170","pt":1646209350681,"mc":[{"id":"1.195453700","rc":[{"atl":[[780,1.86],[420,2]],"id":41419640},{"atl":[[480,2]],"id":41419621}],"con":true,"img":false}]}
{"op":"mcm","clk":"5347870174","pt":1646209350787,"mc":[{"id":"1.195453700","rc":[{"atl":[[230,6.46]],"id":41419630},{"atl":[[460,5.22]],"id":41419611},{"atl":[[850,0]],"id":41419621}],"con":true,"img":false}]}
{"op":"mcm","clk":"5347870179","pt":1646209350891,"mc":[{"id":"1.195453700","rc":[{"atl":[[200,7.43]],"id":41419598}],"con":true,"img":false}]}
{"op":"mcm","clk":"5347870189","pt":1646209351096,"mc":[{"id":"1.195453700","rc":[{"atl":[[290,0.55],[320,4.64]],"id":41419605},{"atl":[[210,7.08]],"id":41419635},{"atl":[[450,0]],"id":41419611}],"con":true,"img":false}]}
{"op":"mcm","clk":"5347870193","pt":1646209351195,"mc":[{"id":"1.195453700","rc":[{"atl":[[590,2]],"id":41419635},{"atl":[[860,0],[850,1.74]],"id":41419621}],"con":true,"img":false}]}
{"op":"mcm","clk":"5347870199","pt":1646209351303,"mc":[{"id":"1.195453700","rc":[{"atl":[[210,5.72]],"id":41419628},{"atl":[[170,5.9]],"id":41419621}],"con":true,"img":false}]}
{"op":"mcm","clk":"5347870204","pt":1646209351403,"mc":[{"id":"1.195453700","rc":[{"atl":[[180,5.85]],"id":41419596}],"con":true,"img":false}]}
{"op":"mcm","clk":"5347870233","pt":1646209351869,"mc":[{"id":"1.195453700","rc":[{"atl":[[200,7.45]],"id":41419639},{"atl":[[210,0]],"id":41419635},{"atl":[[200,7.45],[480,2]],"id":41419596}],"con":true,"img":false}]}
{"op":"mcm","clk":"5347870235","pt":1646209351966,"mc":[{"id":"1.195453700","rc":[{"atl":[[1000,0]],"id":41419605}],"con":true,"img":false}]}
{"op":"mcm","clk":"5347870280","pt":1646209353096,"mc":[{"id":"1.195453700","rc":[{"atl":[[830,3.79],[210,0]],"id":41419631}],"con":true,"img":false}]}
{"op":"mcm","clk":"5347870315","pt":1646209353980,"mc":[{"id":"1.195453700","rc":[{"atl":[[180,5.85],[780,0],[420,5.55]],"id":41419640}],"con":true,"img":false}]}
{"op":"mcm","clk":"5347870338","pt":1646209354796,"mc":[{"id":"1.195453700","rc":[{"atl":[[280,5.34]],"id":41419619},{"atl":[[190,0]],"id":41419640}],"con":true,"img":false}]}
{"op":"mcm","clk":"5347870383","pt":1646209355881,"mc":[{"id":"1.195453700","rc":[{"atl":[[850,3.74],[480,0]],"id":41419621}],"con":true,"img":false}]}
{"op":"mcm","clk":"5347870428","pt":1646209357168,"mc":[{"id":"1.195453700","rc":[{"atl":[[400,5.76],[220,0]],"id":41419597},{"atl":[[540,4.78],[230,0]],"id":41419604}],"con":true,"img":false}]}
{"op":"mcm","clk":"5347870443","pt":1646209357480,"mc":[{"id":"1.195453700","rc":[{"atl":[[330,2],[230,6.55]],"id":41419628},{"atl":[[540,2],[230,6.55]],"id":41419629}],"con":true,"img":false}]}
{"op":"mcm","clk":"5347870451","pt":1646209357686,"mc":[{"id":"1.195453700","rc":[{"atl":[[230,0],[470,5.19]],"id":41419630}],"con":true,"img":false}]}
{"op":"mcm","clk":"5347870458","pt":1646209357788,"mc":[{"id":"1.195453700","rc":[{"atl":[[200,0],[500,5]],"id":41419598}],"con":true,"img":false}]}
{"op":"mcm","clk":"5347870464","pt":1646209357890,"mc":[{"id":"1.195453700","rc":[{"atl":[[210,7.17]],"id":41419635}],"con":true,"img":false}]}
{"op":"mcm","clk":"5347870468","pt":1646209357992,"mc":[{"id":"1.195453700","rc":[{"atl":[[250,5.6]],"id":41419617},{"atl":[[540,2]],"id":41419604},{"atb":[[75,4.87]],"id":41419596}],"con":true,"img":false}]}
{"op":"mcm","clk":"5347870472","pt":1646209358097,"mc":[{"id":"1.195453700","rc":[{"atl":[[260,0]],"id":41419617},{"atb":[[75,2.72]],"id":41419630},{"atl":[[260,0.61],[250,4.96]],"id":41419619},{"atb":[[80,17.16],[85,9.92],[100,0],[110,6.41]],"id":41419594},{"atb":[[11,2.72]],"id":41419591},{"atl":[[16,10.58],[17.5,9.92],[18,0],[15.5,4.96]],"id":41419591},{"atl":[[190,4.96],[200,0.79]],"id":41419633}],"con":true,"img":false}]}
{"op":"mcm","clk":"5347870480","pt":1646209358300,"mc":[{"id":"1.195453700","rc":[{"atl":[[890,2],[940,0]],"id":41419619},{"atl":[[370,2],[770,0]],"id":41419633}],"con":true,"img":false}]}
{"op":"mcm","clk":"5347870483","pt":1646209358403,"mc":[{"id":"1.195453700","rc":[{"atl":[[230,0]],"id":41419629}],"con":true,"img":false}]}
{"op":"mcm","clk":"5347870489","pt":1646209358506,"mc":[{"id":"1.195453700","rc":[{"atl":[[270,5.58],[880,2]],"id":41419617},{"atl":[[470,2]],"id":41419630},{"atl":[[240,0.66]],"id":41419619},{"atl":[[500,2]],"id":41419598},{"atl":[[17.5,36.95]],"id":41419591},{"atl":[[190,5.8],[770,1.95],[800,0]],"id":41419633}],"con":true,"img":false}]}
{"op":"mcm","clk":"5347870493","pt":1646209358609,"mc":[{"id":"1.195453700","rc":[{"atl":[[36,0]],"id":41419591}],"con":true,"img":false}]}
{"op":"mcm","clk":"5347870497","pt":1646209358714,"mc":[{"id":"1.195453700","rc":[{"atl":[[560,4.69],[200,0]],"id":41419639},{"atb":[[65,4.96]],"id":41419596},{"atl":[[200,0],[480,5.13]],"id":41419596}],"con":true,"img":false}]}
{"op":"mcm","clk":"5347870503","pt":1646209358814,"mc":[{"id":"1.195453700","rc":[{"atb":[[70,7.26]],"id":41419630},{"atb":[[9.4,27.13]],"id":41419591}],"con":true,"img":false}]}
{"op":"mcm","clk":"5347870512","pt":1646209358972,"mc":[{"id":"1.195453700","rc":[{"atl":[[280,0]],"id":41419619}],"con":true,"img":false}]}
{"op":"mcm","clk":"5347870524","pt":1646209359281,"mc":[{"id":"1.195453700","rc":[{"atl":[[270,0]],"id":41419617},{"atl":[[260,0]],"id":41419619},{"atl":[[200,0]],"id":41419633}],"con":true,"img":false}]}
{"op":"mcm","clk":"5347870533","pt":1646209359485,"mc":[{"id":"1.195453700","rc":[{"atl":[[480,2]],"id":41419596}],"con":true,"img":false}]}
{"op":"mcm","clk":"5347870573","pt":1646209360308,"mc":[{"id":"1.195453700","rc":[{"atl":[[830,2],[210,7.21]],"id":41419631}],"con":true,"img":false}]}
{"op":"mcm","clk":"5347870577","pt":1646209360412,"mc":[{"id":"1.195453700","rc":[{"atl":[[140,4.96]],"id":41419621}],"con":true,"img":false}]}
{"op":"mcm","clk":"5347870584","pt":1646209360515,"mc":[{"id":"1.195453700","rc":[{"atl":[[170,0],[180,4.96]],"id":41419618},{"atl":[[210,0],[220,4.96]],"id":41419630},{"atl":[[160,0.99],[170,4.96]],"id":41419626},{"atl":[[190,0],[830,0],[200,4.96],[430,2]],"id":41419631},{"atl":[[160,4.96],[180,0.88]],"id":41419598},{"atl":[[50,0]],"id":41419627},{"atl":[[180,0],[200,4.96],[420,2]],"id":41419640},{"atb":[[130,1.23],[140,4.96],[95,0],[100,9.92]],"id":41419615},{"atl":[[200,0]],"id":41419611},{"atl":[[40,0],[42,4.96],[48,12.63],[50,9.92]],"id":41419620},{"atl":[[190,0],[200,4.96]],"id":41419632},{"atb":[[80,24.09],[85,0],[100,4.96],[110,0]],"id":41419595},{"atl":[[210,0],[220,4.96]],"id":41419604},{"atb":[[130,1.23],[140,4.96],[95,0],[100,9.92]],"id":41419616},{"atl":[[170,0],[180,4.96]],"id":41419625},{"atl":[[170,0.93]],"id":41419621},{"atb":[[11.5,17.85]],"id":41419588},{"atl":[[190,0],[210,4.96]],"id":41419633},{"atl":[[210,0],[220,4.96]],"id":41419629}],"con":true,"img":false}]}
{"op":"mcm","clk":"5347870587","pt":1646209360619,"mc":[{"id":"1.195453700","rc":[{"atb":[[16,6.67],[20,0]],"id":41419597},{"atl":[[990,1.29]],"id":41419603}],"con":true,"img":false}]}
{"op":"mcm","clk":"5347870595","pt":1646209360675,"mc":[{"id":"1.195453700","rc":[{"atl":[[520,2],[880,0]],"id":41419626},{"atl":[[65,12.26],[70,9.92],[48,0],[50,4.96]],"id":41419606},{"atl":[[16,0],[16.5,9.92],[14,0],[14.5,4.96]],"id":41419590},{"atl":[[340,2],[720,0]],"id":41419632},{"atl":[[790,0],[400,2]],"id":41419625}],"con":true,"img":false}]}
{"op":"mcm","clk":"5347870600","pt":1646209360777,"mc":[{"id":"1.195453700","rc":[{"atl":[[210,0],[220,4.96]],"id":41419611}],"con":true,"img":false}]}
{"op":"mcm","clk":"5347870606","pt":1646209360883,"mc":[{"id":"1.195453700","rc":[{"atb":[[80,24.09],[85,0],[100,4.96],[110,0]],"id":41419593},{"atb":[[42,0],[44,4.96],[50,0]],"id":41419597},{"atb":[[80,2.72]],"id":41419598},{"atb":[[12.5,0],[13,9.92],[14.5,12.26],[15,4.96]],"id":41419627},{"atb":[[80,27.09],[85,0],[100,4.96],[110,0]],"id":41419594},{"atl":[[260,0],[270,4.96]],"id":41419603},{"atb":[[75,0],[150,1.06],[100,19.13]],"id":41419615},{"atl":[[16,15.54],[17.5,27.03],[18,9.92],[15.5,10.94]],"id":41419591},{"atb":[[100,19.13]],"id":41419616},{"atb":[[17,4.96],[18.5,0],[20,0],[25,0],[15,9.92]],"id":41419592},{"atb":[[65,0],[75,2.72],[48,0],[50,20.37]],"id":41419596}],"con":true,"img":false}]}
{"op":"mcm","clk":"5347870610","pt":1646209360983,"mc":[{"id":"1.195453700","rc":[{"atl":[[880,1.71],[910,0]],"id":41419626},{"atl":[[150,1.06]],"id":41419598},{"atl":[[65,0],[70,14.26]],"id":41419627},{"atb":[[80,12.65],[55,16.88]],"id":41419595},{"atb":[[150,1.06],[80,0]],"id":41419616}],"con":true,"img":false}]}
{"op":"mcm","clk":"5347870620","pt":1646209361193,"mc":[{"id":"1.195453700","rc":[{"atl":[[180,5.85]],"id":41419618},{"atl":[[220,5.68]],"id":41419630},{"atl":[[200,5.75]],"id":41419631},{"atb":[[75,0],[46,9.92],[55,17.71],[60,4.96]],"id":41419598},{"atl":[[200,5.75]],"id":41419640},{"atl":[[220,5.68]],"id":41419611},{"atl":[[200,5.75]],"id":41419632},{"atb":[[75,9.92],[80,14.66],[95,4.96]],"id":41419595},{"atl":[[530,0.3]],"id":41419604},{"atl":[[180,5.85]],"id":41419625},{"atb":[[9.8,42.27]],"id":41419588},{"atl":[[530,0.3],[220,0],[230,4.96]],"id":41419629}],"con":true,"img":false}]}
{"op":"mcm","clk":"5347870625","pt":1646209361297,"mc":[{"id":"1.195453700","rc":[{"atb":[[80,12.65]],"id":41419593},{"atb":[[14.5,0],[15,17.22]],"id":41419627},{"atl":[[60,2.69]],"id":41419627},{"atb":[[80,4.73],[100,0]],"id":41419595},{"atb":[[11.5,42.24]],"id":41419592},{"atl":[[360,0.44]],"id":41419633}],"con":true,"img":false}]}
{"op":"mcm","clk":"5347870630","pt":1646209361404,"mc":[{"id":"1.195453700","rc":[{"atb":[[55,16.09]],"id":41419593},{"atl":[[830,3.68],[460,0]],"id":41419618},{"atb":[[44,22.11],[48,3.27]],"id":41419597},{"atl":[[16,8.94]],"id":41419590},{"atb":[[80,12.65],[55,18.04]],"id":41419594},{"atl":[[340,0],[740,2]],"id":41419632},{"atl":[[400,0],[800,3.79]],"id":41419625},{"atb":[[50,8.23],[28,14.71]],"id":41419596}],"con":true,"img":false}]}
{"op":"mcm","clk":"5347870644","pt":1646209361611,"mc":[{"id":"1.195453700","rc":[{"atb":[[85,1.88]],"id":41419593},{"atl":[[220,4.96],[240,0]],"id":41419593},{"atb":[[36,9.92]],"id":41419597},{"atb":[[70,9.92],[80,4.73],[90,4.96],[100,0]],"id":41419594},{"atb":[[130,0]],"id":41419615},{"atl":[[16,4.96]],"id":41419591},{"atb":[[19.5,3.27],[24,2.72],[15.5,10.94]],"id":41419592},{"atb":[[50,11.47]],"id":41419596}],"con":true,"img":false}]}
{"op":"mcm","clk":"5347870648","pt":1646209361714,"mc":[{"id":"1.195453700","rc":[{"atl":[[180,0]],"id":41419598},{"atb":[[55,3.27]],"id":41419595},{"atb":[[130,0]],"id":41419616}],"con":true,"img":false}]}
{"op":"mcm","clk":"5347870651","pt":1646209361822,"mc":[{"id":"1.195453700","rc":[{"atl":[[730,2],[870,1.65]],"id":41419593},{"atl":[[180,0.88],[190,4.96],[830,2],[200,7.59]],"id":41419618},{"atl":[[230,4.96]],"id":41419630},{"atl":[[16.5,30.63],[100,2]],"id":41419590},{"atl":[[220,0],[230,4.96]],"id":41419604},{"atl":[[800,2],[200,7.59]],"id":41419625}],"con":true,"img":false}]}
{"op":"mcm","clk":"5347870656","pt":1646209361923,"mc":[{"id":"1.195453700","rc":[{"atl":[[220,0.72]],"id":41419630}],"con":true,"img":false}]}
{"op":"mcm","clk":"5347870661","pt":1646209362023,"mc":[{"id":"1.195453700","rc":[{"atl":[[180,0]],"id":41419618},{"atl":[[220,0]],"id":41419630}],"con":true,"img":false}]}
{"op":"mcm","clk":"5347870665","pt":1646209362080,"mc":[{"id":"1.195453700","rc":[{"atl":[[210,0.75]],"id":41419593}],"con":true,"img":false}]}
{"op":"mcm","clk":"5347870675","pt":1646209362287,"mc":[{"id":"1.195453700","rc":[{"atl":[[730,4.07],[870,0]],"id":41419593}],"con":true,"img":false}]}
{"op":"mcm","clk":"5347870691","pt":1646209362609,"mc":[{"id":"1.195453700","rc":[{"atl":[[200,0]],"id":41419625}],"con":true,"img":false}]}
{"op":"mcm","clk":"5347870697","pt":1646209362701,"mc":[{"id":"1.195453700","rc":[{"atl":[[190,5.8]],"id":41419618},{"atl":[[460,0.34]],"id":41419630}],"con":true,"img":false}]}
{"op":"mcm","clk":"5347870708","pt":1646209362905,"mc":[{"id":"1.195453700","rc":[{"atl":[[230,0]],"id":41419593}],"con":true,"img":false}]}
{"op":"mcm","clk":"5347870714","pt":1646209363008,"mc":[{"id":"1.195453700","rc":[{"atl":[[730,2]],"id":41419593}],"con":true,"img":false}]}
{"op":"mcm","clk":"5347870726","pt":1646209363326,"mc":[{"id":"1.195453700","rc":[{"atb":[[8.8,0],[7.8,0]],"id":41419590}],"con":true,"img":false}]}
{"op":"mcm","clk":"5347870738","pt":1646209363581,"mc":[{"id":"1.195453700","rc":[{"atl":[[520,0.3]],"id":41419629}],"con":true,"img":false}]}
{"op":"mcm","clk":"5347870747","pt":1646209363787,"mc":[{"id":"1.195453700","rc":[{"atb":[[7.2,30.57],[6.4,57.78]],"id":41419590}],"con":true,"img":false}]}
{"op":"mcm","clk":"5347870759","pt":1646209363996,"mc":[{"id":"1.195453700","rc":[{"atb":[[9,2.72]],"id":41419590}],"con":true,"img":false}]}
{"op":"mcm","clk":"5347870772","pt":1646209364208,"mc":[{"id":"1.195453700","rc":[{"atb":[[8,3.27]],"id":41419590}],"con":true,"img":false}]}
{"op":"mcm","clk":"5347870777","pt":1646209364305,"mc":[{"id":"1.195453700","rc":[{"atl":[[400,2],[220,6.93]],"id":41419597},{"atl":[[330,6.61],[230,0]],"id":41419628},{"atl":[[540,4.82]],"id":41419604},{"atl":[[530,0]],"id":41419629}],"con":true,"img":false}]}
{"op":"mcm","clk":"5347870786","pt":1646209364412,"mc":[{"id":"1.195453700","rc":[{"atl":[[350,2]],"id":41419597}],"con":true,"img":false}]}
{"op":"mcm","clk":"5347870791","pt":1646209364515,"mc":[{"id":"1.195453700","rc":[{"atl":[[400,0]],"id":41419597}],"con":true,"img":false}]}
{"op":"mcm","clk":"5347870800","pt":1646209364616,"mc":[{"id":"1.195453700","rc":[{"atl":[[590,4.58],[210,0]],"id":41419635}],"con":true,"img":false}]}
{"op":"mcm","clk":"5347870805","pt":1646209364720,"mc":[{"id":"1.195453700","rc":[{"atl":[[200,0.79]],"id":41419631},{"atl":[[460,2],[240,6.35]],"id":41419611}],"con":true,"img":false}]}
{"op":"mcm","clk":"5347870811","pt":1646209364826,"mc":[{"id":"1.195453700","rc":[{"atl":[[470,5.24]],"id":41419630},{"atl":[[200,0],[210,12.17]],"id":41419631},{"atl":[[500,5.05]],"id":41419598},{"atb":[[75,0],[80,14.66],[95,0],[100,4.96]],"id":41419595},{"atb":[[150,0]],"id":41419616}],"con":true,"img":false}]}
{"op":"mcm","clk":"5347870816","pt":1646209364881,"mc":[{"id":"1.195453700","rc":[{"atl":[[160,5.96],[170,0]],"id":41419626},{"atb":[[150,0]],"id":41419615},{"atl":[[40,4.96],[42,0],[48,22.56],[50,0]],"id":41419620},{"atl":[[190,4.96],[200,0.79]],"id":41419632},{"atl":[[140,0],[150,4.96]],"id":41419621}],"con":true,"img":false}]}
{"op":"mcm","clk":"5347870820","pt":1646209364984,"mc":[{"id":"1.195453700","rc":[{"atl":[[850,1.74],[470,2]],"id":41419621}],"con":true,"img":false}]}
{"op":"mcm","clk":"5347870824","pt":1646209365091,"mc":[{"id":"1.195453700","rc":[{"atl":[[220,0]],"id":41419597},{"atl":[[140,1.14]],"id":41419621}],"con":true,"img":false}]}
{"op":"mcm","clk":"5347870838","pt":1646209365397,"mc":[{"id":"1.195453700","rc":[{"atl":[[590,2]],"id":41419635},{"atl":[[240,0]],"id":41419611},{"atl":[[40,9.03]],"id":41419620},{"atl":[[740,4.05],[750,0]],"id":41419632},{"atl":[[850,0],[470,5.24]],"id":41419621}],"con":true,"img":false}]}
{"op":"mcm","clk":"5347870853","pt":1646209365706,"mc":[{"id":"1.195453700","rc":[{"atl":[[200,0.79]],"id":41419631},{"atb":[[140,6.1]],"id":41419615},{"atb":[[140,6.1]],"id":41419616}],"con":true,"img":false}]}
{"op":"mcm","clk":"5347870860","pt":1646209365811,"mc":[{"id":"1.195453700","rc":[{"atl":[[560,2],[200,7.65]],"id":41419639},{"atl":[[170,0]],"id":41419621},{"atl":[[200,7.65]],"id":41419596}],"con":true,"img":false}]}
{"op":"mcm","clk":"5347870864","pt":1646209366016,"mc":[{"id":"1.195453700","rc":[{"atl":[[380,2],[480,0]],"id":41419596}],"con":true,"img":false}]}
{"op":"mcm","clk":"5347870871","pt":1646209366117,"mc":[{"id":"1.195453700","rc":[{"atl":[[46,0]],"id":41419620}],"con":true,"img":false}]}
{"op":"mcm","clk":"5347870900","pt":1646209366687,"mc":[{"id":"1.195453700","rc":[{"atl":[[48,9.92],[110,15.94]],"id":41419620}],"con":true,"img":false}]}
{"op":"mcm","clk":"5347870913","pt":1646209367096,"mc":[{"id":"1.195453700","rc":[{"atl":[[210,4.96],[430,5.56]],"id":41419631},{"atb":[[28,11.01]],"id":41419596},{"atl":[[380,0],[440,2]],"id":41419596}],"con":true,"img":false}]}
{"op":"mcm","clk":"5347870917","pt":1646209367201,"mc":[{"id":"1.195453700","rc":[{"atb":[[23,4.55]],"id":41419596}],"con":true,"img":false}]}
{"op":"mcm","clk":"5347870929","pt":1646209367407,"mc":[{"id":"1.195453700","rc":[{"atb":[[36,0],[38,9.92],[44,17.15],[46,4.96]],"id":41419597},{"atb":[[65,4.96],[46,0],[48,9.92],[60,0]],"id":41419598},{"atb":[[44,9.92],[50,6.51],[55,4.96]],"id":41419596}],"con":true,"img":false}]}
{"op":"mcm","clk":"5347870937","pt":1646209367612,"mc":[{"id":"1.195453700","rc":[{"atb":[[65,15.87]],"id":41419615},{"atb":[[70,15.87],[100,9.92]],"id":41419616}],"con":true,"img":false}]}
{"op":"mcm","clk":"5347870942","pt":1646209367713,"mc":[{"id":"1.195453700","rc":[{"atb":[[100,9.92]],"id":41419615}],"con":true,"img":false}]}
{"op":"mcm","clk":"5347870953","pt":1646209367923,"mc":[{"id":"1.195453700","rc":[{"atl":[[220,6.98]],"id":41419640}],"con":true,"img":false}]}
{"op":"mcm","clk":"5347870964","pt":1646209368127,"mc":[{"id":"1.195453700","rc":[{"atl":[[310,4.96]],"id":41419616}],"con":true,"img":false}]}
{"op":"mcm","clk":"5347870985","pt":1646209368595,"mc":[{"id":"1.195453700","rc":[{"atl":[[200,0],[830,3.84]],"id":41419618},{"atl":[[890,3.71]],"id":41419619},{"atl":[[300,0.52]],"id":41419616}],"con":true,"img":false}]}
{"op":"mcm","clk":"5347871004","pt":1646209369109,"mc":[{"id":"1.195453700","rc":[{"atl":[[1000,1.69]],"id":41419616}],"con":true,"img":false}]}
{"op":"mcm","clk":"5347871017","pt":1646209369425,"mc":[{"id":"1.195453700","rc":[{"atl":[[1000,1.53]],"id":41419616}],"con":true,"img":false}]}
{"op":"mcm","clk":"5347871041","pt":1646209369928,"mc":[{"id":"1.195453700","rc":[{"atb":[[9,0]],"id":41419590}],"con":true,"img":false}]}
{"op":"mcm","clk":"5347871053","pt":1646209370135,"mc":[{"id":"1.195453700","rc":[{"atb":[[8,0]],"id":41419590}],"con":true,"img":false}]}
{"op":"mcm","clk":"5347871072","pt":1646209370612,"mc":[{"id":"1.195453700","rc":[{"atb":[[8.8,2.72]],"id":41419590}],"con":true,"img":false}]}
{"op":"mcm","clk":"5347871083","pt":1646209370805,"mc":[{"id":"1.195453700","rc":[{"atb":[[7.8,3.27]],"id":41419590}],"con":true,"img":false}]}
{"op":"mcm","clk":"5347871091","pt":1646209371018,"mc":[{"id":"1.195453700","rc":[{"atl":[[220,7.01]],"id":41419597}],"con":true,"img":false}]}
{"op":"mcm","clk":"5347871098","pt":1646209371320,"mc":[{"id":"1.195453700","rc":[{"atl":[[540,4.85]],"id":41419629}],"con":true,"img":false}]}
{"op":"mcm","clk":"5347871101","pt":1646209371424,"mc":[{"id":"1.195453700","rc":[{"atl":[[330,2],[230,6.71]],"id":41419628}],"con":true,"img":false}]}
{"op":"mcm","clk":"5347871115","pt":1646209371732,"mc":[{"id":"1.195453700","rc":[{"atl":[[210,7.36]],"id":41419635}],"con":true,"img":false}]}
{"op":"mcm","clk":"5347871144","pt":1646209372200,"mc":[{"id":"1.195453700","rc":[{"atl":[[230,0]],"id":41419628}],"con":true,"img":false}]}
{"op":"mcm","clk":"5347871155","pt":1646209372407,"mc":[{"id":"1.195453700","rc":[{"atl":[[270,5.73]],"id":41419617},{"atl":[[370,6.18],[770,0],[200,0.79]],"id":41419633}],"con":true,"img":false}]}
{"op":"mcm","clk":"5347871159","pt":1646209372506,"mc":[{"id":"1.195453700","rc":[{"atl":[[560,4.76]],"id":41419639},{"atl":[[440,5.51]],"id":41419596}],"con":true,"img":false}]}
{"op":"mcm","clk":"5347871164","pt":1646209372610,"mc":[{"id":"1.195453700","rc":[{"atl":[[200,0]],"id":41419639},{"atl":[[200,0]],"id":41419596}],"con":true,"img":false}]}
{"op":"mcm","clk":"5347871170","pt":1646209372719,"mc":[{"id":"1.195453700","rc":[{"atb":[[75,4.87]],"id":41419630},{"atb":[[11,18.6]],"id":41419591}],"con":true,"img":false}]}
{"op":"mcm","clk":"5347871199","pt":1646209373332,"mc":[{"id":"1.195453700","rc":[{"atl":[[360,0]],"id":41419633}],"con":true,"img":false}]}
{"op":"mcm","clk":"5347871204","pt":1646209373533,"mc":[{"id":"1.195453700","rc":[{"atb":[[70,4.96]],"id":41419630},{"atl":[[560,2]],"id":41419639},{"atb":[[9.4,8.23]],"id":41419591},{"atl":[[440,2]],"id":41419596}],"con":true,"img":false}]}
{"op":"mcm","clk":"5347871245","pt":1646209374623,"mc":[{"id":"1.195453700","rc":[{"atl":[[420,5.69]],"id":41419640}],"con":true,"img":false}]}
{"op":"mcm","clk":"5347871249","pt":1646209374729,"mc":[{"id":"1.195453700","rc":[{"atl":[[220,0]],"id":41419640},{"atb":[[55,16.88]],"id":41419595}],"con":true,"img":false}]}
{"op":"mcm","clk":"5347871258","pt":1646209374932,"mc":[{"id":"1.195453700","rc":[{"atl":[[190,5.8]],"id":41419632},{"atb":[[100,6.56]],"id":41419595},{"atl":[[220,0.72]],"id":41419604},{"atl":[[220,0.72]],"id":41419629}],"con":true,"img":false}]}
{"op":"mcm","clk":"5347871264","pt":1646209375037,"mc":[{"id":"1.195453700","rc":[{"atb":[[80,23.01],[55,3.27]],"id":41419593},{"atl":[[50,3.24]],"id":41419627},{"atb":[[17,24.98],[11.5,12.7]],"id":41419592}],"con":true,"img":false}]}
{"op":"mcm","clk":"5347871269","pt":1646209375136,"mc":[{"id":"1.195453700","rc":[{"atl":[[220,0.72]],"id":41419630},{"atb":[[44,0],[46,17.22]],"id":41419597},{"atl":[[14,12.21]],"id":41419590},{"atb":[[28,0]],"id":41419596}],"con":true,"img":false}]}
{"op":"mcm","clk":"5347871274","pt":1646209375240,"mc":[{"id":"1.195453700","rc":[{"atb":[[70,24.68],[55,3.27]],"id":41419594},{"atb":[[50,21.28]],"id":41419596}],"con":true,"img":false}]}
{"op":"mcm","clk":"5347871279","pt":1646209375295,"mc":[{"id":"1.195453700","rc":[{"atb":[[100,6.56]],"id":41419593},{"atb":[[70,26.99]],"id":41419594},{"atl":[[420,2]],"id":41419640}],"con":true,"img":false}]}
{"op":"mcm","clk":"5347871285","pt":1646209375399,"mc":[{"id":"1.195453700","rc":[{"atl":[[70,2],[60,12.39]],"id":41419627},{"atl":[[530,3.23],[540,2]],"id":41419604}],"con":true,"img":false}]}
{"op":"mcm","clk":"5347871290","pt":1646209375504,"mc":[{"id":"1.195453700","rc":[{"atl":[[830,2],[210,7.41]],"id":41419618},{"atl":[[200,7.78]],"id":41419625}],"con":true,"img":false}]}
{"op":"mcm","clk":"5347871297","pt":1646209375604,"mc":[{"id":"1.195453700","rc":[{"atl":[[460,3.72],[470,2]],"id":41419630},{"atl":[[16,29.65],[16.5,9.92]],"id":41419590},{"atl":[[200,0]],"id":41419632},{"atb":[[80,12.65]],"id":41419595},{"atl":[[520,0]],"id":41419629}],"con":true,"img":false}]}
{"op":"mcm","clk":"5347871301","pt":1646209375708,"mc":[{"id":"1.195453700","rc":[{"atl":[[830,0],[460,2]],"id":41419618},{"atl":[[60,9.7]],"id":41419627},{"atl":[[530,2.93]],"id":41419604},{"atl":[[800,0],[400,2]],"id":41419625}],"con":true,"img":false}]}
{"op":"mcm","clk":"5347871310","pt":1646209375914,"mc":[{"id":"1.195453700","rc":[{"atl":[[460,3.37]],"id":41419630},{"atl":[[16,20.7]],"id":41419590}],"con":true,"img":false}]}
{"op":"mcm","clk":"5347871315","pt":1646209376017,"mc":[{"id":"1.195453700","rc":[{"atl":[[730,4.12]],"id":41419593}],"con":true,"img":false}]}
{"op":"mcm","clk":"5347871320","pt":1646209376118,"mc":[{"id":"1.195453700","rc":[{"atb":[[85,0]],"id":41419593},{"atb":[[70,24.68]],"id":41419594}],"con":true,"img":false}]}
{"op":"mcm","clk":"5347871399","pt":1646209377616,"mc":[{"id":"1.195453700","rc":[{"atl":[[220,0]],"id":41419597},{"atb":[[7.2,56.14],[6.4,9.92]],"id":41419590}],"con":true,"img":false}]}
{"op":"mcm","clk":"5347871403","pt":1646209377716,"mc":[{"id":"1.195453700","rc":[{"atl":[[350,6.46]],"id":41419597}],"con":true,"img":false}]}
{"op":"mcm","clk":"5347871413","pt":1646209378022,"mc":[{"id":"1.195453700","rc":[{"atl":[[230,6.8]],"id":41419628}],"con":true,"img":false}]}
{"op":"mcm","clk":"5347871417","pt":1646209378128,"mc":[{"id":"1.195453700","rc":[{"atb":[[85,0],[90,9.92],[110,1.45],[120,4.96]],"id":41419617},{"atl":[[170,4.96],[190,0.84]],"id":41419618},{"atl":[[210,4.96],[230,0]],"id":41419630},{"atl":[[160,4.96]],"id":41419597},{"atb":[[19.5,0],[20,9.92],[23,12.26],[24,8.23]],"id":41419606},{"atb":[[140,1.14],[150,4.96],[100,0],[110,9.92]],"id":41419602},{"atl":[[16,30.63],[16.5,0],[14,17.17],[14.5,0]],"id":41419590},{"atb":[[10.5,41.2],[11,9.92],[12.5,13.81],[13,4.96]],"id":41419586},{"atl":[[190,4.96],[210,0]],"id":41419631},{"atl":[[170,4.96],[190,0.84],[230,0]],"id":41419594},{"atl":[[210,4.96],[220,0.72]],"id":41419611},{"atb":[[16.5,9.92],[17.5,21.15],[18.5,4.96],[15.5,0]],"id":41419620},{"atl":[[180,4.96],[210,0.75]],"id":41419628},{"atl":[[190,4.96],[210,0]],"id":41419595},{"atl":[[210,4.96],[230,0]],"id":41419604},{"atb":[[17,20.02],[17.5,4.96],[15,0],[15.5,20.87]],"id":41419592},{"atl":[[210,4.96],[230,0]],"id":41419629},{"atl":[[150,4.96],[180,0.88]],"id":41419596}],"con":true,"img":false}]}
{"op":"mcm","clk":"5347871421","pt":1646209378228,"mc":[{"id":"1.195453700","rc":[{"atb":[[32,0],[34,9.77],[27,0],[28,9.92]],"id":41419599}],"con":true,"img":false}]}
{"op":"mcm","clk":"5347871427","pt":1646209378331,"mc":[{"id":"1.195453700","rc":[{"atl":[[580,2.41],[480,2]],"id":41419594},{"atl":[[570,2],[660,2.18]],"id":41419595}],"con":true,"img":false}]}
{"op":"mcm","clk":"5347871430","pt":1646209378435,"mc":[{"id":"1.195453700","rc":[{"atl":[[590,4.64],[210,0]],"id":41419635},{"atl":[[240,6.52]],"id":41419611}],"con":true,"img":false}]}
{"op":"mcm","clk":"5347871435","pt":1646209378537,"mc":[{"id":"1.195453700","rc":[{"atb":[[60,2.72]],"id":41419617},{"atl":[[170,5.9]],"id":41419618},{"atl":[[210,5.72]],"id":41419630},{"atb":[[13,18.19]],"id":41419586}],"con":true,"img":false}]}
{"op":"mcm","clk":"5347871439","pt":1646209378641,"mc":[{"id":"1.195453700","rc":[{"atb":[[130,1.23],[90,25.64]],"id":41419617},{"atl":[[160,5.96]],"id":41419597},{"atb":[[65,2.72],[150,6.02],[110,19]],"id":41419602},{"atb":[[10.5,0],[11.5,33.32]],"id":41419586},{"atl":[[190,5.8]],"id":41419631},{"atl":[[160,0.99]],"id":41419594},{"atl":[[210,5.72]],"id":41419611},{"atb":[[17.5,0],[18.5,25.78]],"id":41419620},{"atl":[[180,5.85]],"id":41419628},{"atl":[[180,0.88]],"id":41419595},{"atl":[[210,5.72]],"id":41419629},{"atl":[[150,6.02]],"id":41419596}],"con":true,"img":false}]}
{"op":"mcm","clk":"5347871443","pt":1646209378699,"mc":[{"id":"1.195453700","rc":[{"atb":[[28,39.25],[29,2.72]],"id":41419599}],"con":true,"img":false}]}
{"op":"mcm","clk":"5347871446","pt":1646209378804,"mc":[{"id":"1.195453700","rc":[{"atl":[[580,0],[480,5.25]],"id":41419594},{"atl":[[570,4.74],[660,0]],"id":41419595},{"atl":[[38,4.96],[60,0]],"id":41419592}],"con":true,"img":false}]}
{"op":"mcm","clk":"5347871456","pt":1646209379117,"mc":[{"id":"1.195453700","rc":[{"atl":[[270,0],[880,3.77]],"id":41419617},{"atl":[[740,2],[210,7.46]],"id":41419632}],"con":true,"img":false}]}
{"op":"mcm","clk":"5347871458","pt":1646209379215,"mc":[{"id":"1.195453700","rc":[{"atl":[[220,0]],"id":41419630},{"atb":[[12.5,0]],"id":41419586},{"atl":[[340,2]],"id":41419632}],"con":true,"img":false}]}
{"op":"mcm","clk":"5347871461","pt":1646209379318,"mc":[{"id":"1.195453700","rc":[{"atb":[[110,0]],"id":41419617},{"atl":[[190,0]],"id":41419618},{"atl":[[200,0]],"id":41419631},{"atl":[[190,0]],"id":41419594},{"atl":[[740,0]],"id":41419632},{"atl":[[38,9.25]],"id":41419592}],"con":true,"img":false}]}
{"op":"mcm","clk":"5347871466","pt":1646209379421,"mc":[{"id":"1.195453700","rc":[{"atl":[[200,4.96]],"id":41419597},{"atl":[[200,7.84]],"id":41419639},{"atb":[[140,0]],"id":41419602},{"atl":[[220,0]],"id":41419611},{"atl":[[210,0]],"id":41419628},{"atl":[[200,0]],"id":41419595},{"atl":[[180,0],[440,5.55]],"id":41419596}],"con":true,"img":false}]}
{"op":"mcm","clk":"5347871470","pt":1646209379536,"mc":[{"id":"1.195453700","rc":[{"atl":[[220,0]],"id":41419629}],"con":true,"img":false}]}
{"op":"mcm","clk":"5347871486","pt":1646209379833,"mc":[{"id":"1.195453700","rc":[{"atl":[[210,7.47]],"id":41419631}],"con":true,"img":false}]}
{"op":"mcm","clk":"5347871492","pt":1646209379944,"mc":[{"id":"1.195453700","rc":[{"atl":[[430,2]],"id":41419631}],"con":true,"img":false}]}
{"op":"mcm","clk":"5347871496","pt":1646209380045,"mc":[{"id":"1.195453700","rc":[{"atl":[[880,2]],"id":41419617},{"atl":[[210,0]],"id":41419632},{"atl":[[46,4.96]],"id":41419592}],"con":true,"img":false}]}
{"op":"mcm","clk":"5347871527","pt":1646209380710,"mc":[{"id":"1.195453700","rc":[{"atl":[[210,0]],"id":41419631}],"con":true,"img":false}]}
{"op":"mcm","clk":"5347871575","pt":1646209381635,"mc":[{"id":"1.195453700","rc":[{"atb":[[80,12.65]],"id":41419593},{"atl":[[210,7.5]],"id":41419631}],"con":true,"img":false}]}
