{"op":"mcm","clk":"5317728507","pt":1646251399890,"mc":[{"id":"1.195532867","marketDefinition":{"bspMarket":true,"turnInPlayEnabled":false,"persistenceEnabled":false,"marketBaseRate":5.0,"eventId":"31275720","eventTypeId":"4339","numberOfWinners":2,"bettingType":"ODDS","marketType":"PLACE","marketTime":"2022-03-03T16:08:00.000Z","suspendTime":"2022-03-03T16:08:00.000Z","bspReconciled":false,"complete":true,"inPlay":false,"crossMatching":false,"runnersVoidable":false,"numberOfActiveRunners":6,"betDelay":0,"status":"OPEN","runners":[{"status":"ACTIVE","sortPriority":1,"id":41529439,"name":"1. Puttfor Daisy"},{"status":"ACTIVE","sortPriority":2,"id":26648132,"name":"2. Trapstyle Brae"},{"status":"ACTIVE","sortPriority":3,"id":35676762,"name":"3. Seven Of Nine"},{"status":"ACTIVE","sortPriority":4,"id":39213014,"name":"4. Watford Lad"},{"status":"ACTIVE","sortPriority":5,"id":43094640,"name":"5. Droopys Solution"},{"status":"ACTIVE","sortPriority":6,"id":28791281,"name":"6. Our Bill"}],"regulators":["MR_INT"],"venue":"Romford","countryCode":"GB","discountAllowed":false,"timezone":"Europe/London","openDate":"2022-03-03T13:57:00.000Z","version":4384107312,"name":"To Be Placed","eventName":"Romford 3rd Mar"},"rc":[],"con":true,"img":false}]}
{"op":"mcm","clk":"5317728859","pt":1646251401766,"mc":[{"id":"1.195532867","marketDefinition":{"bspMarket":true,"turnInPlayEnabled":false,"persistenceEnabled":false,"marketBaseRate":5.0,"eventId":"31275720","eventTypeId":"4339","numberOfWinners":2,"bettingType":"ODDS","marketType":"PLACE","marketTime":"2022-03-03T16:08:00.000Z","suspendTime":"2022-03-03T16:08:00.000Z","bspReconciled":false,"complete":true,"inPlay":false,"crossMatching":false,"runnersVoidable":false,"numberOfActiveRunners":6,"betDelay":0,"status":"OPEN","runners":[{"status":"ACTIVE","sortPriority":1,"id":41529439,"name":"1. Puttfor Daisy"},{"status":"ACTIVE","sortPriority":2,"id":26648132,"name":"2. Trapstyle Brae"},{"status":"ACTIVE","sortPriority":3,"id":35676762,"name":"3. Seven Of Nine"},{"status":"ACTIVE","sortPriority":4,"id":39213014,"name":"4. Watford Lad"},{"status":"ACTIVE","sortPriority":5,"id":43094640,"name":"5. Droopys Solution"},{"status":"ACTIVE","sortPriority":6,"id":28791281,"name":"6. Our Bill"}],"regulators":["MR_INT"],"venue":"Romford","countryCode":"GB","discountAllowed":true,"timezone":"Europe/London","openDate":"2022-03-03T13:57:00.000Z","version":4384107312,"name":"To Be Placed","eventName":"Romford 3rd Mar"},"rc":[],"con":true,"img":false}]}
{"op":"mcm","clk":"5318441621","pt":1646258378820,"mc":[{"id":"1.195532867","rc":[{"spl":[[1.01,10]],"id":35676762},{"spn":1.0,"spf":1.0,"id":35676762}],"con":true,"img":false}]}
{"op":"mcm","clk":"5321413411","pt":1646309408890,"mc":[{"id":"1.195532867","rc":[{"atb":[[1.01,102.04]],"id":26648132},{"spn":"Infinity","spf":"NaN","id":26648132},{"atb":[[1.01,102.04]],"id":43094640},{"spn":"Infinity","spf":"NaN","id":43094640},{"atb":[[1.01,102.04]],"id":28791281},{"spn":"Infinity","spf":"NaN","id":28791281},{"atb":[[1.01,102.04]],"id":35676762},{"spn":1.01,"spf":1.0,"id":35676762},{"atb":[[1.01,102.04]],"id":41529439},{"spn":"Infinity","spf":"NaN","id":41529439},{"atb":[[1.01,102.04]],"id":39213014},{"spn":"Infinity","spf":"NaN","id":39213014}],"con":true,"img":false}]}
{"op":"mcm","clk":"5321555524","pt":1646310925188,"mc":[{"id":"1.195532867","rc":[{"atl":[[1000,5]],"id":26648132},{"spn":500.5,"spf":"NaN","id":26648132},{"atl":[[1000,5]],"id":43094640},{"spn":500.5,"spf":"NaN","id":43094640},{"atl":[[1000,5]],"id":28791281},{"spn":500.5,"spf":"NaN","id":28791281},{"atl":[[1000,5]],"id":35676762},{"atl":[[1000,5]],"id":41529439},{"spn":500.5,"spf":"NaN","id":41529439},{"atl":[[1000,5]],"id":39213014},{"spn":500.5,"spf":"NaN","id":39213014}],"con":true,"img":false}]}
{"op":"mcm","clk":"5321555556","pt":1646310925499,"mc":[{"id":"1.195532867","rc":[{"atb":[[1.01,4802.04]],"id":26648132},{"atb":[[1.01,4802.04]],"id":43094640},{"atb":[[1.01,4802.04]],"id":28791281},{"atb":[[1.01,4802.04]],"id":35676762},{"atb":[[1.01,4802.04]],"id":41529439},{"atb":[[1.01,4802.04]],"id":39213014}],"con":true,"img":false}]}
{"op":"mcm","clk":"5322535101","pt":1646321434252,"mc":[{"id":"1.195532867","rc":[{"spl":[[1.01,8.24]],"id":41529439},{"spn":1.01,"spf":1.0,"id":41529439}],"con":true,"img":false}]}
{"op":"mcm","clk":"5322555345","pt":1646321691562,"mc":[{"id":"1.195532867","rc":[{"atl":[[46,2.73]],"id":26648132},{"spn":23.5,"spf":"NaN","id":26648132},{"atl":[[46,2.73]],"id":43094640},{"spn":23.5,"spf":"NaN","id":43094640},{"atl":[[46,2.73]],"id":28791281},{"spn":23.5,"spf":"NaN","id":28791281},{"atl":[[46,2.73]],"id":35676762},{"atl":[[46,2.73]],"id":41529439},{"atl":[[46,2.73]],"id":39213014},{"spn":23.5,"spf":"NaN","id":39213014}],"con":true,"img":false}]}
{"op":"mcm","clk":"5322570856","pt":1646321885388,"mc":[{"id":"1.195532867","rc":[{"atb":[[1.01,5052.04]],"id":26648132},{"atl":[[70,2.17],[80,3.16],[50,1],[60,1.69]],"id":26648132},{"atb":[[1.01,5052.04]],"id":43094640},{"atl":[[70,2.17],[80,3.16],[50,1],[60,1.69]],"id":43094640},{"atb":[[1.01,5052.04]],"id":28791281},{"atl":[[70,2.17],[80,3.16],[50,1],[60,1.69]],"id":28791281},{"atb":[[1.01,5052.04]],"id":35676762},{"atl":[[70,2.17],[80,3.16],[50,1],[60,1.69]],"id":35676762},{"atb":[[1.01,5052.04]],"id":41529439},{"atl":[[70,2.17],[80,3.16],[50,1],[60,1.69]],"id":41529439},{"atb":[[1.01,5052.04]],"id":39213014},{"atl":[[70,2.17],[80,3.16],[50,1],[60,1.69]],"id":39213014}],"con":true,"img":false}]}
{"op":"mcm","clk":"5322572862","pt":1646321910236,"mc":[{"id":"1.195532867","marketDefinition":{"bspMarket":true,"turnInPlayEnabled":false,"persistenceEnabled":false,"marketBaseRate":5.0,"eventId":"31275720","eventTypeId":"4339","numberOfWinners":2,"bettingType":"ODDS","marketType":"PLACE","marketTime":"2022-03-03T16:08:00.000Z","suspendTime":"2022-03-03T16:08:00.000Z","bspReconciled":false,"complete":true,"inPlay":false,"crossMatching":true,"runnersVoidable":false,"numberOfActiveRunners":6,"betDelay":0,"status":"OPEN","runners":[{"status":"ACTIVE","sortPriority":1,"id":41529439,"name":"1. Puttfor Daisy"},{"status":"ACTIVE","sortPriority":2,"id":26648132,"name":"2. Trapstyle Brae"},{"status":"ACTIVE","sortPriority":3,"id":35676762,"name":"3. Seven Of Nine"},{"status":"ACTIVE","sortPriority":4,"id":39213014,"name":"4. Watford Lad"},{"status":"ACTIVE","sortPriority":5,"id":43094640,"name":"5. Droopys Solution"},{"status":"ACTIVE","sortPriority":6,"id":28791281,"name":"6. Our Bill"}],"regulators":["MR_INT"],"venue":"Romford","countryCode":"GB","discountAllowed":true,"timezone":"Europe/London","openDate":"2022-03-03T13:57:00.000Z","version":4384107312,"name":"To Be Placed","eventName":"Romford 3rd Mar"},"rc":[],"con":true,"img":false}]}
{"op":"mcm","clk":"5322604726","pt":1646322284473,"mc":[{"id":"1.195532867","rc":[{"spl":[[1.01,1]],"id":39213014},{"spn":1.01,"spf":1.0,"id":39213014}],"con":true,"img":false}]}
{"op":"mcm","clk":"5322657944","pt":1646322780426,"mc":[{"id":"1.195532867","rc":[{"atb":[[1.6,166.67]],"id":43094640},{"atl":[[7.8,2]],"id":43094640},{"spn":4.7,"spf":"NaN","id":43094640},{"atb":[[2.26,79.37]],"id":35676762},{"atl":[[34,2]],"id":35676762},{"spn":2.26,"spf":1.0,"id":35676762},{"atb":[[1.51,196.08]],"id":39213014},{"atl":[[6.4,2]],"id":39213014},{"spn":1.51,"spf":1.0,"id":39213014}],"con":true,"img":false}]}
{"op":"mcm","clk":"5322657965","pt":1646322780542,"mc":[{"id":"1.195532867","rc":[{"atb":[[1.74,135.14]],"id":26648132},{"atl":[[12,2]],"id":26648132},{"atb":[[1.4,250]],"id":28791281},{"atl":[[6,2]],"id":28791281}],"con":true,"img":false}]}
{"op":"mcm","clk":"5322657974","pt":1646322780656,"mc":[{"id":"1.195532867","rc":[{"atb":[[1.68,147.06]],"id":41529439},{"atl":[[9.8,2]],"id":41529439}],"con":true,"img":false}]}
{"op":"mcm","clk":"5322658024","pt":1646322781183,"mc":[{"id":"1.195532867","rc":[{"atb":[[2.28,1.65]],"id":35676762}],"con":true,"img":false}]}
{"op":"mcm","clk":"5322658108","pt":1646322782035,"mc":[{"id":"1.195532867","rc":[{"atb":[[1.72,55.56]],"id":26648132},{"atl":[[50,0],[13,3.33]],"id":26648132},{"atb":[[1.58,68.97],[1.69,144.93]],"id":43094640},{"atl":[[8.2,5.56],[50,0]],"id":43094640},{"atl":[[50,0]],"id":28791281},{"atb":[[2.24,32.26],[2.26,0],[2.48,67.57]],"id":35676762},{"atl":[[34,0],[38,1.08]],"id":35676762},{"atb":[[1.66,60.61]],"id":41529439},{"atl":[[10.5,4.21],[50,0]],"id":41529439},{"atb":[[1.63,158.73],[1.49,81.63],[1.51,0]],"id":39213014},{"atl":[[6.8,6.9],[50,0]],"id":39213014}],"con":true,"img":false}]}
{"op":"mcm","clk":"5322658113","pt":1646322782069,"mc":[{"id":"1.195532867","rc":[{"atb":[[1.6,0]],"id":43094640},{"atb":[[1.38,105.26]],"id":28791281},{"atl":[[6.4,7.41]],"id":28791281},{"atl":[[36,2.86],[50,0]],"id":35676762}],"con":true,"img":false}]}
{"op":"mcm","clk":"5322658125","pt":1646322782173,"mc":[{"id":"1.195532867","rc":[{"atb":[[1.61,65.57]],"id":39213014}],"con":true,"img":false}]}
{"op":"mcm","clk":"5322658136","pt":1646322782282,"mc":[{"id":"1.195532867","rc":[{"atb":[[1.67,59.7]],"id":43094640},{"atb":[[2.44,27.78]],"id":35676762},{"atl":[[42,1]],"id":35676762},{"atl":[[70,0],[80,0],[60,0]],"id":41529439}],"con":true,"img":false}]}
{"op":"mcm","clk":"5322658147","pt":1646322782352,"mc":[{"id":"1.195532867","rc":[{"atl":[[38,0],[40,1.03]],"id":35676762}],"con":true,"img":false}]}
{"op":"mcm","clk":"5322658167","pt":1646322782555,"mc":[{"id":"1.195532867","rc":[{"atl":[[70,0],[80,0],[42,0],[60,0]],"id":35676762}],"con":true,"img":false}]}
{"op":"mcm","clk":"5322658437","pt":1646322785661,"mc":[{"id":"1.195532867","rc":[{"atl":[[6.2,4],[6,0]],"id":28791281}],"con":true,"img":false}]}
{"op":"mcm","clk":"5322658476","pt":1646322786108,"mc":[{"id":"1.195532867","rc":[{"atb":[[1.02,1150.01]],"id":28791281},{"atb":[[1.02,1088.26]],"id":41529439},{"atb":[[1.5,73.01]],"id":39213014}],"con":true,"img":false}]}
{"op":"mcm","clk":"5322658729","pt":1646322789186,"mc":[{"id":"1.195532867","rc":[{"atb":[[2.28,0]],"id":35676762}],"con":true,"img":false}]}
{"op":"mcm","clk":"5322658752","pt":1646322789388,"mc":[{"id":"1.195532867","rc":[{"atb":[[2.5,1.65]],"id":35676762}],"con":true,"img":false}]}
{"op":"mcm","clk":"5322658831","pt":1646322790283,"mc":[{"id":"1.195532867","rc":[{"atb":[[1.02,0]],"id":28791281},{"atb":[[1.02,0]],"id":41529439},{"atb":[[1.5,0]],"id":39213014}],"con":true,"img":false}]}
{"op":"mcm","clk":"5322658864","pt":1646322790661,"mc":[{"id":"1.195532867","rc":[{"atb":[[1.74,0],[1.87,114.94]],"id":26648132},{"atb":[[1.4,0],[1.57,175.44]],"id":28791281}],"con":true,"img":false}]}
{"op":"mcm","clk":"5322658875","pt":1646322790774,"mc":[{"id":"1.195532867","rc":[{"atl":[[9,2.74],[9.8,0]],"id":41529439}],"con":true,"img":false}]}
{"op":"mcm","clk":"5322658974","pt":1646322791978,"mc":[{"id":"1.195532867","rc":[{"atb":[[1.85,47.06]],"id":26648132},{"atl":[[14,7.69]],"id":26648132},{"atb":[[1.55,72.73]],"id":28791281},{"atl":[[6.4,0],[6.6,7.14]],"id":28791281},{"atb":[[1.64,156.25]],"id":41529439},{"atl":[[9.4,4.76]],"id":41529439}],"con":true,"img":false}]}
{"op":"mcm","clk":"5322658994","pt":1646322792186,"mc":[{"id":"1.195532867","rc":[{"atb":[[1.7,68.97],[1.65,153.85],[1.69,0]],"id":43094640},{"atl":[[8.6,13.16]],"id":43094640},{"atb":[[1.59,169.49]],"id":39213014},{"atl":[[7.2,16.13]],"id":39213014}],"con":true,"img":false}]}
{"op":"mcm","clk":"5322659015","pt":1646322792401,"mc":[{"id":"1.195532867","rc":[{"atb":[[2.46,27.4]],"id":35676762},{"atl":[[44,2.33]],"id":35676762}],"con":true,"img":false}]}
{"op":"mcm","clk":"5322659095","pt":1646322793175,"mc":[{"id":"1.195532867","rc":[{"atb":[[1.73,2.15]],"id":43094640},{"atb":[[2.54,2.15]],"id":35676762},{"atb":[[1.71,2.15]],"id":41529439},{"atb":[[1.66,2.15]],"id":39213014}],"con":true,"img":false}]}
{"op":"mcm","clk":"5322659158","pt":1646322793383,"mc":[{"id":"1.195532867","rc":[{"atb":[[1.73,61.85],[1.7,0]],"id":43094640},{"atb":[[2.54,4.31],[2.48,0]],"id":35676762},{"atb":[[1.68,0],[1.71,62.76]],"id":41529439},{"atb":[[1.63,0],[1.66,67.72]],"id":39213014}],"con":true,"img":false}]}
{"op":"mcm","clk":"5322659169","pt":1646322793493,"mc":[{"id":"1.195532867","rc":[{"atb":[[1.73,2.15],[1.7,68.97]],"id":43094640},{"atb":[[2.54,2.15]],"id":35676762},{"atb":[[1.68,147.06],[1.71,2.15]],"id":41529439},{"atb":[[1.63,158.73]],"id":39213014}],"con":true,"img":false}]}
{"op":"mcm","clk":"5322659179","pt":1646322793625,"mc":[{"id":"1.195532867","rc":[{"atb":[[2.5,29.05]],"id":35676762},{"atb":[[1.66,2.15]],"id":39213014}],"con":true,"img":false}]}
{"op":"mcm","clk":"5322659189","pt":1646322793704,"mc":[{"id":"1.195532867","rc":[{"atb":[[1.73,64.01],[1.7,0]],"id":43094640},{"atb":[[2.54,4.31]],"id":35676762},{"atb":[[1.68,0],[1.71,64.92]],"id":41529439}],"con":true,"img":false}]}
{"op":"mcm","clk":"5322659201","pt":1646322793795,"mc":[{"id":"1.195532867","rc":[{"atb":[[2.5,1.65]],"id":35676762},{"atb":[[1.63,0],[1.66,69.88]],"id":39213014}],"con":true,"img":false}]}
{"op":"mcm","clk":"5322659325","pt":1646322794897,"mc":[{"id":"1.195532867","rc":[{"atb":[[1.39,93.6]],"id":28791281},{"atb":[[1.69,52.9]],"id":41529439},{"atb":[[1.64,57.03]],"id":39213014}],"con":true,"img":false}]}
{"op":"mcm","clk":"5322659654","pt":1646322798201,"mc":[{"id":"1.195532867","rc":[{"atb":[[2.5,0]],"id":35676762}],"con":true,"img":false}]}
{"op":"mcm","clk":"5322659679","pt":1646322798402,"mc":[{"id":"1.195532867","rc":[{"atb":[[2.56,1.65]],"id":35676762}],"con":true,"img":false}]}
{"op":"mcm","clk":"5322659716","pt":1646322798883,"mc":[{"id":"1.195532867","rc":[{"atb":[[1.69,0]],"id":41529439},{"atb":[[1.64,0]],"id":39213014}],"con":true,"img":false}]}
{"op":"mcm","clk":"5322660069","pt":1646322802021,"mc":[{"id":"1.195532867","rc":[{"atb":[[1.83,120.48]],"id":26648132},{"atl":[[80,0],[15,10.71]],"id":26648132},{"atb":[[1.53,188.68]],"id":28791281},{"atl":[[7,16.67]],"id":28791281},{"atb":[[1.69,57.97]],"id":41529439},{"atl":[[9.8,11.36]],"id":41529439}],"con":true,"img":false}]}
{"op":"mcm","clk":"5322660089","pt":1646322802181,"mc":[{"id":"1.195532867","rc":[{"atb":[[1.67,0],[1.71,56.34]],"id":43094640},{"atl":[[70,0],[9,18.75],[80,0],[60,0]],"id":43094640},{"atb":[[1.64,62.5]],"id":39213014},{"atl":[[7.6,22.73]],"id":39213014}],"con":true,"img":false}]}
{"op":"mcm","clk":"5322660099","pt":1646322802274,"mc":[{"id":"1.195532867","rc":[{"atb":[[1.61,0]],"id":39213014},{"atl":[[80,0]],"id":39213014}],"con":true,"img":false}]}
{"op":"mcm","clk":"5322660110","pt":1646322802376,"mc":[{"id":"1.195532867","rc":[{"atb":[[2.52,26.32],[2.46,0]],"id":35676762},{"atl":[[48,3.19]],"id":35676762}],"con":true,"img":false}]}
{"op":"mcm","clk":"5322660119","pt":1646322802481,"mc":[{"id":"1.195532867","rc":[{"atb":[[1.9,2.15]],"id":26648132},{"atb":[[1.6,2.15]],"id":28791281}],"con":true,"img":false}]}
{"op":"mcm","clk":"5322660139","pt":1646322802692,"mc":[{"id":"1.195532867","rc":[{"atb":[[1.9,49.21],[1.87,0]],"id":26648132},{"atb":[[1.6,74.88],[1.57,0]],"id":28791281}],"con":true,"img":false}]}
{"op":"mcm","clk":"5322660195","pt":1646322803305,"mc":[{"id":"1.195532867","rc":[{"atb":[[1.67,54.48]],"id":41529439},{"atb":[[1.62,58.88]],"id":39213014}],"con":true,"img":false}]}
{"op":"mcm","clk":"5322660386","pt":1646322805299,"mc":[{"id":"1.195532867","rc":[{"atb":[[1.39,0]],"id":28791281}],"con":true,"img":false}]}
{"op":"mcm","clk":"5322660571","pt":1646322807403,"mc":[{"id":"1.195532867","rc":[{"atb":[[1.67,0]],"id":41529439},{"atb":[[1.62,0]],"id":39213014}],"con":true,"img":false}]}
{"op":"mcm","clk":"5322660801","pt":1646322809596,"mc":[{"id":"1.195532867","rc":[{"atb":[[1.56,65.18]],"id":28791281}],"con":true,"img":false}]}
{"op":"mcm","clk":"5322660963","pt":1646322811317,"mc":[{"id":"1.195532867","rc":[{"atb":[[1.85,0],[1.88,45.45]],"id":26648132},{"atl":[[70,0]],"id":26648132},{"atl":[[7.8,0]],"id":43094640},{"atb":[[1.55,0],[1.58,68.97]],"id":28791281},{"atl":[[70,0],[80,0],[60,0]],"id":28791281},{"atl":[[9,0],[8.6,4.76]],"id":41529439},{"atl":[[70,0],[6.4,0],[6.6,16.13]],"id":39213014}],"con":true,"img":false}]}
{"op":"mcm","clk":"5322660973","pt":1646322811386,"mc":[{"id":"1.195532867","rc":[{"atl":[[12,0],[13,11.02]],"id":26648132},{"atl":[[8,13.16]],"id":43094640},{"atl":[[6.2,0],[6,7.14]],"id":28791281},{"atl":[[34,2.33],[36,0]],"id":35676762}],"con":true,"img":false}]}
{"op":"mcm","clk":"5322661023","pt":1646322812210,"mc":[{"id":"1.195532867","rc":[{"atl":[[9,5]],"id":41529439}],"con":true,"img":false}]}
{"op":"mcm","clk":"5322661048","pt":1646322812246,"mc":[{"id":"1.195532867","rc":[{"atb":[[1.69,144.93]],"id":43094640},{"atl":[[8.2,0],[8.4,5.41]],"id":43094640},{"atb":[[1.62,161.29]],"id":39213014},{"atl":[[7,6.67]],"id":39213014}],"con":true,"img":false}]}
{"op":"mcm","clk":"5322661056","pt":1646322812310,"mc":[{"id":"1.195532867","rc":[{"atl":[[6.8,0]],"id":39213014}],"con":true,"img":false}]}
{"op":"mcm","clk":"5322661067","pt":1646322812413,"mc":[{"id":"1.195532867","rc":[{"atb":[[2.48,67.57]],"id":35676762},{"atl":[[38,1.08]],"id":35676762}],"con":true,"img":false}]}
{"op":"mcm","clk":"5322661087","pt":1646322812592,"mc":[{"id":"1.195532867","rc":[{"atb":[[1.9,2.15],[1.93,49.22]],"id":26648132},{"atb":[[1.67,54.48]],"id":41529439},{"atb":[[1.6,60.84]],"id":39213014}],"con":true,"img":false}]}
{"op":"mcm","clk":"5322661144","pt":1646322813108,"mc":[{"id":"1.195532867","rc":[{"atb":[[1.9,0],[1.96,2.15]],"id":26648132}],"con":true,"img":false}]}
{"op":"mcm","clk":"5322661248","pt":1646322814511,"mc":[{"id":"1.195532867","rc":[{"atb":[[1.56,0]],"id":28791281}],"con":true,"img":false}]}
{"op":"mcm","clk":"5322661388","pt":1646322816390,"mc":[{"id":"1.195532867","rc":[{"atb":[[1.6,0]],"id":39213014}],"con":true,"img":false}]}
{"op":"mcm","clk":"5322661403","pt":1646322816595,"mc":[{"id":"1.195532867","rc":[{"atl":[[13,3.33],[14,15.38]],"id":26648132},{"atl":[[34,0],[40,3.59]],"id":35676762}],"con":true,"img":false}]}
{"op":"mcm","clk":"5322661644","pt":1646322819644,"mc":[{"id":"1.195532867","rc":[{"atb":[[1.54,67.6]],"id":28791281}],"con":true,"img":false}]}
{"op":"mcm","clk":"5322661779","pt":1646322821124,"mc":[{"id":"1.195532867","rc":[{"atl":[[8.6,0],[8.4,4.76]],"id":41529439},{"atl":[[6.4,16.13]],"id":39213014}],"con":true,"img":false}]}
{"op":"mcm","clk":"5322661787","pt":1646322821227,"mc":[{"id":"1.195532867","rc":[{"atl":[[6.6,0]],"id":39213014}],"con":true,"img":false}]}
{"op":"mcm","clk":"5322661797","pt":1646322821321,"mc":[{"id":"1.195532867","rc":[{"atb":[[1.88,0],[1.94,42.55]],"id":26648132},{"atl":[[13,0],[14,10.77]],"id":26648132},{"atl":[[8,0],[7.4,13.16]],"id":43094640},{"atb":[[1.56,178.57]],"id":28791281},{"atl":[[6.4,7.41]],"id":28791281},{"atb":[[1.67,48.91]],"id":39213014}],"con":true,"img":false}]}
{"op":"mcm","clk":"5322661808","pt":1646322821484,"mc":[{"id":"1.195532867","rc":[{"atb":[[1.68,62.5],[1.66,2.15]],"id":39213014}],"con":true,"img":false}]}
{"op":"mcm","clk":"5322661849","pt":1646322822007,"mc":[{"id":"1.195532867","rc":[{"atl":[[9,0],[8.8,5.13]],"id":41529439}],"con":true,"img":false}]}
{"op":"mcm","clk":"5322661871","pt":1646322822215,"mc":[{"id":"1.195532867","rc":[{"atb":[[1.58,0],[1.67,223.88]],"id":43094640},{"atl":[[7.8,5.88]],"id":43094640},{"atb":[[1.64,0],[1.66,62.76]],"id":39213014},{"atl":[[6.8,6.9],[7,0]],"id":39213014}],"con":true,"img":false}]}
{"op":"mcm","clk":"5322661887","pt":1646322822423,"mc":[{"id":"1.195532867","rc":[{"atb":[[1.96,44.7]],"id":26648132},{"atb":[[1.01,4802.04],[2.44,104.17]],"id":35676762},{"atl":[[38,0],[42,1]],"id":35676762}],"con":true,"img":false}]}
{"op":"mcm","clk":"5322661900","pt":1646322822527,"mc":[{"id":"1.195532867","rc":[{"atb":[[1.93,0]],"id":26648132}],"con":true,"img":false}]}
{"op":"mcm","clk":"5322661998","pt":1646322823420,"mc":[{"id":"1.195532867","rc":[{"atb":[[1.67,0]],"id":41529439}],"con":true,"img":false}]}
{"op":"mcm","clk":"5322662026","pt":1646322823730,"mc":[{"id":"1.195532867","rc":[{"atb":[[1.66,60.61],[1.71,2.15]],"id":39213014}],"con":true,"img":false}]}
{"op":"mcm","clk":"5322662179","pt":1646322825512,"mc":[{"id":"1.195532867","rc":[{"atb":[[1.54,0]],"id":28791281},{"atb":[[1.67,0]],"id":39213014}],"con":true,"img":false}]}
{"op":"mcm","clk":"5322662371","pt":1646322827508,"mc":[{"id":"1.195532867","rc":[{"atb":[[1.67,54.48]],"id":41529439}],"con":true,"img":false}]}
{"op":"mcm","clk":"5322662618","pt":1646322830128,"mc":[{"id":"1.195532867","rc":[{"atb":[[1.61,52.42]],"id":28791281},{"atb":[[1.63,57.94]],"id":39213014}],"con":true,"img":false}]}
{"op":"mcm","clk":"5322662633","pt":1646322830333,"mc":[{"id":"1.195532867","rc":[{"atb":[[1.6,2.15],[1.62,68.97]],"id":28791281}],"con":true,"img":false}]}
{"op":"mcm","clk":"5322662718","pt":1646322831233,"mc":[{"id":"1.195532867","rc":[{"atb":[[1.68,0],[1.71,62.76]],"id":39213014}],"con":true,"img":false}]}
{"op":"mcm","clk":"5322662726","pt":1646322831336,"mc":[{"id":"1.195532867","rc":[{"atb":[[1.92,108.7]],"id":26648132},{"atl":[[14,7.69],[15,2.86]],"id":26648132},{"atb":[[1.6,68.82],[1.58,0]],"id":28791281},{"atl":[[6.8,17.24]],"id":28791281}],"con":true,"img":false}]}
{"op":"mcm","clk":"5322662807","pt":1646322832241,"mc":[{"id":"1.195532867","rc":[{"atb":[[1.66,0],[1.69,57.97]],"id":39213014},{"atl":[[8,35.71]],"id":39213014}],"con":true,"img":false}]}
{"op":"mcm","clk":"5322662819","pt":1646322832344,"mc":[{"id":"1.195532867","rc":[{"atb":[[1.01,4802.04],[1.65,250]],"id":43094640}],"con":true,"img":false}]}
{"op":"mcm","clk":"5322662829","pt":1646322832444,"mc":[{"id":"1.195532867","rc":[{"atb":[[2.4,178.57]],"id":35676762},{"atl":[[40,2.56],[44,1]],"id":35676762}],"con":true,"img":false}]}
{"op":"mcm","clk":"5322663005","pt":1646322834327,"mc":[{"id":"1.195532867","rc":[{"atb":[[1.6,66.67],[1.65,2.15]],"id":28791281}],"con":true,"img":false}]}
{"op":"mcm","clk":"5322663022","pt":1646322834532,"mc":[{"id":"1.195532867","rc":[{"atb":[[1.61,0]],"id":28791281}],"con":true,"img":false}]}
{"op":"mcm","clk":"5322663175","pt":1646322836329,"mc":[{"id":"1.195532867","rc":[{"atb":[[1.55,18.19]],"id":28791281}],"con":true,"img":false}]}
{"op":"mcm","clk":"5322663190","pt":1646322836536,"mc":[{"id":"1.195532867","rc":[{"atb":[[1.55,0]],"id":28791281},{"atb":[[1.63,0]],"id":39213014}],"con":true,"img":false}]}
{"op":"mcm","clk":"5322663392","pt":1646322838746,"mc":[{"id":"1.195532867","rc":[{"atb":[[1.57,64.04]],"id":28791281}],"con":true,"img":false}]}
{"op":"mcm","clk":"5322663517","pt":1646322839947,"mc":[{"id":"1.195532867","rc":[{"atb":[[1.62,0],[1.65,68.82]],"id":28791281}],"con":true,"img":false}]}
{"op":"mcm","clk":"5322663674","pt":1646322841254,"mc":[{"id":"1.195532867","rc":[{"atb":[[1.83,0],[1.82,15.06],[1.01,4802.04]],"id":26648132},{"spn":7.98,"spf":"NaN","id":26648132},{"spn":4.56,"spf":"NaN","id":43094640},{"atb":[[1.6,0],[1.63,63.49]],"id":28791281},{"spn":3.82,"spf":"NaN","id":28791281},{"atb":[[2.24,0]],"id":35676762},{"atl":[[42,0]],"id":35676762},{"spn":2.53,"spf":1.0,"id":35676762},{"spn":1.71,"spf":1.0,"id":41529439},{"atb":[[1.63,57.94],[1.62,0],[1.61,20.16]],"id":39213014},{"atl":[[60,0]],"id":39213014},{"spn":1.71,"spf":1.0,"id":39213014}],"con":true,"img":false}]}
{"op":"mcm","clk":"5322663684","pt":1646322841370,"mc":[{"id":"1.195532867","rc":[{"atb":[[1.9,166.67]],"id":26648132},{"atl":[[16,6.67]],"id":26648132}],"con":true,"img":false}]}
{"op":"mcm","clk":"5322663707","pt":1646322841568,"mc":[{"id":"1.195532867","rc":[{"atb":[[1.82,0]],"id":26648132},{"atb":[[1.61,0]],"id":39213014}],"con":true,"img":false}]}
{"op":"mcm","clk":"5322663792","pt":1646322842252,"mc":[{"id":"1.195532867","rc":[{"atb":[[1.67,149.25]],"id":39213014}],"con":true,"img":false}]}
{"op":"mcm","clk":"5322663812","pt":1646322842460,"mc":[{"id":"1.195532867","rc":[{"atb":[[3,6.63]],"id":35676762},{"atl":[[48,2.13]],"id":35676762}],"con":true,"img":false}]}
{"op":"mcm","clk":"5322663878","pt":1646322843044,"mc":[{"id":"1.195532867","rc":[{"atb":[[3,0],[2.98,3.05]],"id":35676762},{"atb":[[1.01,5054.04]],"id":41529439}],"con":true,"img":false}]}
{"op":"mcm","clk":"5322663891","pt":1646322843165,"mc":[{"id":"1.195532867","rc":[{"atb":[[2.56,0],[2.54,2.15],[2.98,0],[2.58,13.26]],"id":35676762}],"con":true,"img":false}]}
{"op":"mcm","clk":"5322663903","pt":1646322843270,"mc":[{"id":"1.195532867","rc":[{"atb":[[1.01,5056.03]],"id":41529439}],"con":true,"img":false}]}
{"op":"mcm","clk":"5322663919","pt":1646322843370,"mc":[{"id":"1.195532867","rc":[{"atb":[[3.05,1.65]],"id":35676762}],"con":true,"img":false}]}
{"op":"mcm","clk":"5322663951","pt":1646322843631,"mc":[{"id":"1.195532867","rc":[{"atb":[[1.01,5054.04]],"id":41529439}],"con":true,"img":false}]}
{"op":"mcm","clk":"5322663962","pt":1646322843732,"mc":[{"id":"1.195532867","rc":[{"atb":[[1.72,1.99]],"id":41529439}],"con":true,"img":false}]}
{"op":"mcm","clk":"5322663983","pt":1646322843938,"mc":[{"id":"1.195532867","rc":[{"atb":[[1.01,4804.04]],"id":26648132}],"con":true,"img":false}]}
{"op":"mcm","clk":"5322664002","pt":1646322844133,"mc":[{"id":"1.195532867","rc":[{"atb":[[1.01,4806.03]],"id":26648132}],"con":true,"img":false}]}
{"op":"mcm","clk":"5322664042","pt":1646322844549,"mc":[{"id":"1.195532867","rc":[{"atb":[[1.01,4804.04]],"id":26648132}],"con":true,"img":false}]}
{"op":"mcm","clk":"5322664052","pt":1646322844652,"mc":[{"id":"1.195532867","rc":[{"atb":[[1.97,1.99]],"id":26648132}],"con":true,"img":false}]}
{"op":"mcm","clk":"5322664071","pt":1646322844863,"mc":[{"id":"1.195532867","rc":[{"atb":[[2.54,0],[1.01,4804.04],[2.64,2.15]],"id":35676762}],"con":true,"img":false}]}
{"op":"mcm","clk":"5322664085","pt":1646322845039,"mc":[{"id":"1.195532867","rc":[{"atb":[[1.01,4806.03]],"id":35676762}],"con":true,"img":false}]}
{"op":"mcm","clk":"5322664125","pt":1646322845447,"mc":[{"id":"1.195532867","rc":[{"atb":[[1.01,4804.04]],"id":35676762}],"con":true,"img":false}]}
{"op":"mcm","clk":"5322664136","pt":1646322845553,"mc":[{"id":"1.195532867","rc":[{"atb":[[1.57,0]],"id":28791281},{"atb":[[2.56,1.99]],"id":35676762},{"atb":[[1.63,0]],"id":39213014}],"con":true,"img":false}]}
{"op":"mcm","clk":"5322664162","pt":1646322845758,"mc":[{"id":"1.195532867","rc":[{"atb":[[1.01,5054.04]],"id":39213014}],"con":true,"img":false}]}
{"op":"mcm","clk":"5322664187","pt":1646322845966,"mc":[{"id":"1.195532867","rc":[{"atb":[[1.01,5056.03]],"id":39213014}],"con":true,"img":false}]}
{"op":"mcm","clk":"5322664210","pt":1646322846142,"mc":[{"id":"1.195532867","rc":[{"atb":[[1.01,5054.04]],"id":39213014}],"con":true,"img":false}]}
{"op":"mcm","clk":"5322664220","pt":1646322846236,"mc":[{"id":"1.195532867","rc":[{"atb":[[1.72,1.99]],"id":39213014}],"con":true,"img":false}]}
{"op":"mcm","clk":"5322664230","pt":1646322846337,"mc":[{"id":"1.195532867","rc":[{"atb":[[1.01,4804.04]],"id":43094640}],"con":true,"img":false}]}
{"op":"mcm","clk":"5322664239","pt":1646322846448,"mc":[{"id":"1.195532867","rc":[{"atb":[[1.01,4806.03]],"id":43094640}],"con":true,"img":false}]}
{"op":"mcm","clk":"5322664247","pt":1646322846546,"mc":[{"id":"1.195532867","rc":[{"atb":[[1.01,4804.04]],"id":43094640}],"con":true,"img":false}]}
{"op":"mcm","clk":"5322664259","pt":1646322846652,"mc":[{"id":"1.195532867","rc":[{"atb":[[1.74,1.99]],"id":43094640}],"con":true,"img":false}]}
{"op":"mcm","clk":"5322664286","pt":1646322846862,"mc":[{"id":"1.195532867","rc":[{"atb":[[1.01,5054.04]],"id":28791281}],"con":true,"img":false}]}
{"op":"mcm","clk":"5322664305","pt":1646322847079,"mc":[{"id":"1.195532867","rc":[{"atb":[[1.01,5056.03]],"id":28791281}],"con":true,"img":false}]}
{"op":"mcm","clk":"5322664327","pt":1646322847242,"mc":[{"id":"1.195532867","rc":[{"atb":[[1.01,5054.04]],"id":28791281}],"con":true,"img":false}]}
{"op":"mcm","clk":"5322664336","pt":1646322847334,"mc":[{"id":"1.195532867","rc":[{"atb":[[1.66,1.99]],"id":28791281}],"con":true,"img":false}]}
{"op":"mcm","clk":"5322664498","pt":1646322848667,"mc":[{"id":"1.195532867","rc":[{"atb":[[2.56,0]],"id":35676762}],"con":true,"img":false}]}
{"op":"mcm","clk":"5322664510","pt":1646322848772,"mc":[{"id":"1.195532867","rc":[{"atb":[[2.66,1.99]],"id":35676762}],"con":true,"img":false}]}
{"op":"mcm","clk":"5322664631","pt":1646322849883,"mc":[{"id":"1.195532867","rc":[{"atb":[[1.57,64.04]],"id":28791281},{"atb":[[1.72,47.31]],"id":39213014}],"con":true,"img":false}]}
{"op":"mcm","clk":"5322664649","pt":1646322850087,"mc":[{"id":"1.195532867","rc":[{"atb":[[1.73,57.97],[1.71,2.15]],"id":39213014}],"con":true,"img":false}]}
{"op":"mcm","clk":"5322664717","pt":1646322850774,"mc":[{"id":"1.195532867","rc":[{"atb":[[1.94,0],[1.95,42.11]],"id":26648132},{"atb":[[1.72,55.56],[1.7,7.04],[1.71,0]],"id":43094640},{"atb":[[1.64,62.5],[1.63,0]],"id":28791281},{"atb":[[2.52,0],[2.98,20.2]],"id":35676762},{"atb":[[1.7,57.14],[1.69,0]],"id":41529439},{"atb":[[1.71,58.49],[1.69,0]],"id":39213014}],"con":true,"img":false}]}
{"op":"mcm","clk":"5322664763","pt":1646322851186,"mc":[{"id":"1.195532867","rc":[{"atb":[[1.7,0]],"id":43094640}],"con":true,"img":false}]}
{"op":"mcm","clk":"5322664806","pt":1646322851552,"mc":[{"id":"1.195532867","rc":[{"atb":[[2.66,0]],"id":35676762}],"con":true,"img":false}]}
{"op":"mcm","clk":"5322664818","pt":1646322851664,"mc":[{"id":"1.195532867","rc":[{"atb":[[3,1.99]],"id":35676762}],"con":true,"img":false}]}
{"op":"mcm","clk":"5322664826","pt":1646322851758,"mc":[{"id":"1.195532867","rc":[{"atb":[[1.01,4804.04],[1.53,0]],"id":28791281},{"atb":[[1.01,4804.04]],"id":39213014}],"con":true,"img":false}]}
{"op":"mcm","clk":"5322664836","pt":1646322851876,"mc":[{"id":"1.195532867","rc":[{"atb":[[1.72,45.32]],"id":39213014}],"con":true,"img":false}]}
{"op":"mcm","clk":"5322664845","pt":1646322851978,"mc":[{"id":"1.195532867","rc":[{"atb":[[1.74,1.99]],"id":39213014}],"con":true,"img":false}]}
{"op":"mcm","clk":"5322664913","pt":1646322852652,"mc":[{"id":"1.195532867","rc":[{"atb":[[2.58,0],[3.05,3.65]],"id":35676762}],"con":true,"img":false}]}
{"op":"mcm","clk":"5322664920","pt":1646322852757,"mc":[{"id":"1.195532867","rc":[{"atb":[[1.72,100.88],[1.71,2.15]],"id":39213014}],"con":true,"img":false}]}
{"op":"mcm","clk":"5322664964","pt":1646322853167,"mc":[{"id":"1.195532867","rc":[{"atb":[[3,0]],"id":35676762}],"con":true,"img":false}]}
{"op":"mcm","clk":"5322664971","pt":1646322853261,"mc":[{"id":"1.195532867","rc":[{"atb":[[3.1,1.99]],"id":35676762}],"con":true,"img":false}]}
{"op":"mcm","clk":"5322665048","pt":1646322854047,"mc":[{"id":"1.195532867","rc":[{"atb":[[1.67,0]],"id":41529439},{"atb":[[1.72,55.56]],"id":39213014}],"con":true,"img":false}]}
{"op":"mcm","clk":"5322665171","pt":1646322855453,"mc":[{"id":"1.195532867","rc":[{"atb":[[1.71,0],[1.76,2.15]],"id":39213014}],"con":true,"img":false}]}
{"op":"mcm","clk":"5322665244","pt":1646322856152,"mc":[{"id":"1.195532867","rc":[{"atb":[[1.74,0]],"id":39213014}],"con":true,"img":false}]}
{"op":"mcm","clk":"5322665261","pt":1646322856270,"mc":[{"id":"1.195532867","rc":[{"atb":[[1.77,1.99]],"id":39213014}],"con":true,"img":false}]}
{"op":"mcm","clk":"5322665472","pt":1646322858196,"mc":[{"id":"1.195532867","rc":[{"atl":[[7.4,7.62]],"id":39213014}],"con":true,"img":false}]}
{"op":"mcm","clk":"5322665516","pt":1646322858470,"mc":[{"id":"1.195532867","rc":[{"atb":[[1.7,52.15]],"id":43094640},{"atb":[[1.67,54.48]],"id":41529439}],"con":true,"img":false}]}
{"op":"mcm","clk":"5322665561","pt":1646322858885,"mc":[{"id":"1.195532867","rc":[{"atb":[[3,20],[2.98,0]],"id":35676762},{"atb":[[1.72,0],[1.75,53.33]],"id":39213014}],"con":true,"img":false}]}
{"op":"mcm","clk":"5322665586","pt":1646322859295,"mc":[{"id":"1.195532867","rc":[{"atl":[[7.4,0]],"id":39213014}],"con":true,"img":false}]}
{"op":"mcm","clk":"5322665609","pt":1646322859571,"mc":[{"id":"1.195532867","rc":[{"atb":[[1.73,0],[1.77,4.15]],"id":39213014}],"con":true,"img":false}]}
{"op":"mcm","clk":"5322665729","pt":1646322860763,"mc":[{"id":"1.195532867","rc":[{"atl":[[17,9.38]],"id":26648132},{"atb":[[1.62,161.29]],"id":28791281},{"atl":[[7.2,24.19]],"id":28791281},{"atb":[[1.68,147.06]],"id":41529439}],"con":true,"img":false}]}
{"op":"mcm","clk":"5322665761","pt":1646322861170,"mc":[{"id":"1.195532867","rc":[{"atb":[[3.05,2]],"id":35676762}],"con":true,"img":false}]}
{"op":"mcm","clk":"5322665776","pt":1646322861379,"mc":[{"id":"1.195532867","rc":[{"atb":[[3.15,1.65]],"id":35676762}],"con":true,"img":false}]}
{"op":"mcm","clk":"5322665835","pt":1646322862072,"mc":[{"id":"1.195532867","rc":[{"atb":[[3.15,3.65],[3.05,0]],"id":35676762}],"con":true,"img":false}]}
{"op":"mcm","clk":"5322665884","pt":1646322862693,"mc":[{"id":"1.195532867","rc":[{"atb":[[3.1,0]],"id":35676762}],"con":true,"img":false}]}
{"op":"mcm","clk":"5322665896","pt":1646322862796,"mc":[{"id":"1.195532867","rc":[{"atb":[[3.2,1.99]],"id":35676762}],"con":true,"img":false}]}
{"op":"mcm","clk":"5322666031","pt":1646322864375,"mc":[{"id":"1.195532867","rc":[{"atb":[[1.57,0]],"id":28791281},{"atb":[[1.67,0]],"id":41529439}],"con":true,"img":false}]}
{"op":"mcm","clk":"5322666362","pt":1646322868775,"mc":[{"id":"1.195532867","rc":[{"atb":[[1.66,51.55]],"id":28791281},{"atb":[[1.72,48.83]],"id":41529439}],"con":true,"img":false}]}
{"op":"mcm","clk":"5322666366","pt":1646322868873,"mc":[{"id":"1.195532867","rc":[{"atb":[[1.67,62.5],[1.65,2.15]],"id":28791281},{"atb":[[3.1,19.05],[3,0]],"id":35676762},{"atl":[[55,2.78]],"id":35676762},{"atb":[[1.73,57.14],[1.71,2.15]],"id":41529439},{"atb":[[1.73,136.99]],"id":39213014}],"con":true,"img":false}]}
{"op":"mcm","clk":"5322666385","pt":1646322869080,"mc":[{"id":"1.195532867","rc":[{"atb":[[1.65,0],[1.69,2.15]],"id":28791281},{"atb":[[1.75,2.15],[1.71,0]],"id":41529439}],"con":true,"img":false}]}
{"op":"mcm","clk":"5322666438","pt":1646322869665,"mc":[{"id":"1.195532867","rc":[{"atb":[[1.72,46.84]],"id":41529439}],"con":true,"img":false}]}
{"op":"mcm","clk":"5322666445","pt":1646322869768,"mc":[{"id":"1.195532867","rc":[{"atb":[[1.76,1.99]],"id":41529439}],"con":true,"img":false}]}
{"op":"mcm","clk":"5322666472","pt":1646322869977,"mc":[{"id":"1.195532867","rc":[{"atb":[[1.66,49.56]],"id":28791281}],"con":true,"img":false}]}
{"op":"mcm","clk":"5322666478","pt":1646322870080,"mc":[{"id":"1.195532867","rc":[{"atb":[[1.7,1.99]],"id":28791281}],"con":true,"img":false}]}
{"op":"mcm","clk":"5322666488","pt":1646322870187,"mc":[{"id":"1.195532867","rc":[{"atb":[[3.15,2]],"id":35676762}],"con":true,"img":false}]}
{"op":"mcm","clk":"5322666510","pt":1646322870410,"mc":[{"id":"1.195532867","rc":[{"atb":[[3.25,1.65]],"id":35676762}],"con":true,"img":false}]}
{"op":"mcm","clk":"5322666557","pt":1646322870808,"mc":[{"id":"1.195532867","rc":[{"atl":[[18,14.71]],"id":26648132},{"atb":[[1.64,0],[1.68,58.82]],"id":28791281},{"atl":[[7.6,37.88],[6.6,0],[7,0]],"id":28791281},{"atb":[[1.74,54.05],[1.7,0],[1.69,7.14]],"id":41529439}],"con":true,"img":false}]}
{"op":"mcm","clk":"5322666566","pt":1646322870863,"mc":[{"id":"1.195532867","rc":[{"atl":[[6.8,20.81]],"id":28791281}],"con":true,"img":false}]}
{"op":"mcm","clk":"5322666573","pt":1646322870967,"mc":[{"id":"1.195532867","rc":[{"atb":[[1.69,0]],"id":41529439}],"con":true,"img":false}]}
{"op":"mcm","clk":"5322666585","pt":1646322871070,"mc":[{"id":"1.195532867","rc":[{"atb":[[1.66,0]],"id":28791281},{"atb":[[1.72,0]],"id":41529439}],"con":true,"img":false}]}
{"op":"mcm","clk":"5322666611","pt":1646322871383,"mc":[{"id":"1.195532867","rc":[{"atl":[[6.8,17.24]],"id":28791281},{"atb":[[3.25,3.65],[3.15,0]],"id":35676762}],"con":true,"img":false}]}
{"op":"mcm","clk":"5322666685","pt":1646322872180,"mc":[{"id":"1.195532867","rc":[{"atb":[[3.2,0]],"id":35676762}],"con":true,"img":false}]}
{"op":"mcm","clk":"5322666693","pt":1646322872280,"mc":[{"id":"1.195532867","rc":[{"atb":[[3.3,1.99]],"id":35676762}],"con":true,"img":false}]}
{"op":"mcm","clk":"5322666943","pt":1646322875606,"mc":[{"id":"1.195532867","rc":[{"atb":[[1.7,4.89]],"id":28791281},{"atb":[[1.76,4.89]],"id":41529439}],"con":true,"img":false}]}
{"op":"mcm","clk":"5322667136","pt":1646322878216,"mc":[{"id":"1.195532867","rc":[{"atb":[[1.67,0],[1.71,4.89]],"id":28791281},{"atb":[[1.73,0],[1.77,4.89]],"id":41529439}],"con":true,"img":false}]}
{"op":"mcm","clk":"5322667179","pt":1646322878692,"mc":[{"id":"1.195532867","rc":[{"atb":[[1.76,2.9]],"id":41529439}],"con":true,"img":false}]}
{"op":"mcm","clk":"5322667191","pt":1646322878807,"mc":[{"id":"1.195532867","rc":[{"atb":[[1.78,1.99],[1.77,0],[1.76,12.68]],"id":41529439}],"con":true,"img":false}]}
{"op":"mcm","clk":"5322667201","pt":1646322878907,"mc":[{"id":"1.195532867","rc":[{"atb":[[3.2,18.18],[3.1,0]],"id":35676762},{"atl":[[65,3.91]],"id":35676762},{"atb":[[1.49,0],[1.71,211.27]],"id":39213014}],"con":true,"img":false}]}
{"op":"mcm","clk":"5322667219","pt":1646322879111,"mc":[{"id":"1.195532867","rc":[{"atb":[[1.7,2.9]],"id":28791281}],"con":true,"img":false}]}
{"op":"mcm","clk":"5322667233","pt":1646322879223,"mc":[{"id":"1.195532867","rc":[{"atb":[[1.72,1.99]],"id":28791281},{"atb":[[3.25,2]],"id":35676762}],"con":true,"img":false}]}
{"op":"mcm","clk":"5322667243","pt":1646322879365,"mc":[{"id":"1.195532867","rc":[{"atb":[[1.71,0]],"id":28791281}],"con":true,"img":false}]}
{"op":"mcm","clk":"5322667253","pt":1646322879376,"mc":[{"id":"1.195532867","rc":[{"atb":[[1.7,12.68]],"id":28791281},{"atb":[[3.35,1.65]],"id":35676762}],"con":true,"img":false}]}
{"op":"mcm","clk":"5322667268","pt":1646322879580,"mc":[{"id":"1.195532867","rc":[{"atb":[[3.35,3.65],[3.25,0]],"id":35676762}],"con":true,"img":false}]}
{"op":"mcm","clk":"5322667280","pt":1646322879788,"mc":[{"id":"1.195532867","rc":[{"atb":[[1.73,2.15],[1.69,0]],"id":28791281},{"atb":[[1.79,2.15],[1.75,0]],"id":41529439}],"con":true,"img":false}]}
{"op":"mcm","clk":"5322667305","pt":1646322880105,"mc":[{"id":"1.195532867","rc":[{"atb":[[1.78,0]],"id":41529439}],"con":true,"img":false}]}
{"op":"mcm","clk":"5322667313","pt":1646322880203,"mc":[{"id":"1.195532867","rc":[{"atb":[[1.8,1.99]],"id":41529439}],"con":true,"img":false}]}
{"op":"mcm","clk":"5322667324","pt":1646322880410,"mc":[{"id":"1.195532867","rc":[{"atb":[[3.3,0]],"id":35676762}],"con":true,"img":false}]}
{"op":"mcm","clk":"5322667331","pt":1646322880514,"mc":[{"id":"1.195532867","rc":[{"atb":[[3.4,1.99]],"id":35676762}],"con":true,"img":false}]}
{"op":"mcm","clk":"5322667360","pt":1646322880792,"mc":[{"id":"1.195532867","rc":[{"atl":[[60,0]],"id":26648132},{"atb":[[1.72,0],[1.67,7.35],[1.68,0],[1.71,56.34]],"id":28791281},{"atb":[[1.74,0],[1.77,51.95]],"id":41529439}],"con":true,"img":false}]}
{"op":"mcm","clk":"5322667367","pt":1646322880889,"mc":[{"id":"1.195532867","rc":[{"atb":[[1.74,1.99]],"id":28791281}],"con":true,"img":false}]}
{"op":"mcm","clk":"5322667378","pt":1646322881002,"mc":[{"id":"1.195532867","rc":[{"atb":[[1.67,0]],"id":28791281}],"con":true,"img":false}]}
{"op":"mcm","clk":"5322667456","pt":1646322881891,"mc":[{"id":"1.195532867","rc":[{"atb":[[1.7,9.78]],"id":28791281},{"atb":[[1.76,9.78]],"id":41529439}],"con":true,"img":false}]}
{"op":"mcm","clk":"5322667851","pt":1646322886416,"mc":[{"id":"1.195532867","rc":[{"atb":[[1.74,4.89]],"id":28791281},{"atb":[[1.78,2.9]],"id":39213014}],"con":true,"img":false}]}
{"op":"mcm","clk":"5322667894","pt":1646322886907,"mc":[{"id":"1.195532867","rc":[{"atb":[[1.77,2.16]],"id":39213014}],"con":true,"img":false}]}
{"op":"mcm","clk":"5322667904","pt":1646322886996,"mc":[{"id":"1.195532867","rc":[{"atb":[[1.79,1.99]],"id":39213014}],"con":true,"img":false}]}
{"op":"mcm","clk":"5322667911","pt":1646322887104,"mc":[{"id":"1.195532867","rc":[{"atb":[[1.79,4.15],[1.77,0]],"id":39213014}],"con":true,"img":false}]}
{"op":"mcm","clk":"5322667984","pt":1646322887997,"mc":[{"id":"1.195532867","rc":[{"atb":[[1.8,4.15],[1.76,0]],"id":41529439}],"con":true,"img":false}]}
{"op":"mcm","clk":"5322668002","pt":1646322888196,"mc":[{"id":"1.195532867","rc":[{"atb":[[3.35,2]],"id":35676762}],"con":true,"img":false}]}
{"op":"mcm","clk":"5322668015","pt":1646322888406,"mc":[{"id":"1.195532867","rc":[{"atb":[[3.45,1.65]],"id":35676762}],"con":true,"img":false}]}
{"op":"mcm","clk":"5322668026","pt":1646322888512,"mc":[{"id":"1.195532867","rc":[{"atb":[[1.7,0],[1.75,4.89]],"id":28791281}],"con":true,"img":false}]}
{"op":"mcm","clk":"5322668051","pt":1646322888721,"mc":[{"id":"1.195532867","rc":[{"atb":[[3.45,3.65]],"id":35676762}],"con":true,"img":false}]}
{"op":"mcm","clk":"5322668060","pt":1646322888824,"mc":[{"id":"1.195532867","rc":[{"atb":[[3.35,0]],"id":35676762}],"con":true,"img":false}]}
{"op":"mcm","clk":"5322668066","pt":1646322888929,"mc":[{"id":"1.195532867","rc":[{"atb":[[3.2,0],[3.35,17.02]],"id":35676762},{"atb":[[1.74,6.67],[1.77,51.95],[1.75,0]],"id":39213014}],"con":true,"img":false}]}
{"op":"mcm","clk":"5322668076","pt":1646322888994,"mc":[{"id":"1.195532867","rc":[{"atb":[[1.73,56.94],[1.71,0]],"id":28791281},{"atb":[[3.4,0]],"id":35676762},{"atb":[[1.64,0],[1.68,0],[1.66,0]],"id":41529439}],"con":true,"img":false}]}
{"op":"mcm","clk":"5322668085","pt":1646322889098,"mc":[{"id":"1.195532867","rc":[{"atb":[[3.5,1.99]],"id":35676762},{"atb":[[1.74,0]],"id":39213014}],"con":true,"img":false}]}
{"op":"mcm","clk":"5322668098","pt":1646322889294,"mc":[{"id":"1.195532867","rc":[{"atb":[[1.74,2.9]],"id":28791281}],"con":true,"img":false}]}
{"op":"mcm","clk":"5322668107","pt":1646322889398,"mc":[{"id":"1.195532867","rc":[{"atb":[[1.02,1.99]],"id":28791281}],"con":true,"img":false}]}
{"op":"mcm","clk":"5322668176","pt":1646322890198,"mc":[{"id":"1.195532867","rc":[{"atb":[[1.78,0]],"id":39213014}],"con":true,"img":false}]}
{"op":"mcm","clk":"5322668185","pt":1646322890298,"mc":[{"id":"1.195532867","rc":[{"atb":[[1.8,2.15],[1.76,0]],"id":39213014}],"con":true,"img":false}]}
{"op":"mcm","clk":"5322668197","pt":1646322890498,"mc":[{"id":"1.195532867","rc":[{"atb":[[1.79,2.16]],"id":39213014}],"con":true,"img":false}]}
{"op":"mcm","clk":"5322668212","pt":1646322890609,"mc":[{"id":"1.195532867","rc":[{"atb":[[1.81,1.99]],"id":39213014}],"con":true,"img":false}]}
{"op":"mcm","clk":"5322668235","pt":1646322890810,"mc":[{"id":"1.195532867","rc":[{"atb":[[1.75,133.33]],"id":41529439}],"con":true,"img":false}]}
{"op":"mcm","clk":"5322668384","pt":1646322892226,"mc":[{"id":"1.195532867","rc":[{"atb":[[1.74,0]],"id":28791281}],"con":true,"img":false}]}
{"op":"mcm","clk":"5322668540","pt":1646322893695,"mc":[{"id":"1.195532867","rc":[{"atb":[[1.73,193.93],[1.75,0]],"id":28791281}],"con":true,"img":false}]}
{"op":"mcm","clk":"5322668662","pt":1646322894799,"mc":[{"id":"1.195532867","rc":[{"atb":[[1.74,5.8]],"id":39213014}],"con":true,"img":false}]}
{"op":"mcm","clk":"5322668702","pt":1646322895211,"mc":[{"id":"1.195532867","rc":[{"atb":[[1.02,0]],"id":28791281}],"con":true,"img":false}]}
{"op":"mcm","clk":"5322668709","pt":1646322895315,"mc":[{"id":"1.195532867","rc":[{"atb":[[1.74,1.99]],"id":28791281}],"con":true,"img":false}]}
{"op":"mcm","clk":"5322668807","pt":1646322896219,"mc":[{"id":"1.195532867","rc":[{"atb":[[1.79,0],[1.81,4.15]],"id":39213014}],"con":true,"img":false}]}
{"op":"mcm","clk":"5322668914","pt":1646322897123,"mc":[{"id":"1.195532867","rc":[{"atb":[[1.57,64.04]],"id":28791281}],"con":true,"img":false}]}
{"op":"mcm","clk":"5322668923","pt":1646322897228,"mc":[{"id":"1.195532867","rc":[{"atb":[[3.45,2]],"id":35676762}],"con":true,"img":false}]}
{"op":"mcm","clk":"5322668936","pt":1646322897425,"mc":[{"id":"1.195532867","rc":[{"atb":[[3.55,1.65]],"id":35676762}],"con":true,"img":false}]}
{"op":"mcm","clk":"5322668970","pt":1646322897801,"mc":[{"id":"1.195532867","rc":[{"atb":[[3.45,0],[3.55,3.65]],"id":35676762}],"con":true,"img":false}]}
{"op":"mcm","clk":"5322669012","pt":1646322898331,"mc":[{"id":"1.195532867","rc":[{"atb":[[3.5,0]],"id":35676762}],"con":true,"img":false}]}
{"op":"mcm","clk":"5322669022","pt":1646322898427,"mc":[{"id":"1.195532867","rc":[{"atb":[[3.6,1.99]],"id":35676762}],"con":true,"img":false}]}
{"op":"mcm","clk":"5322669053","pt":1646322898936,"mc":[{"id":"1.195532867","rc":[{"atb":[[3.35,0],[3.5,16]],"id":35676762},{"atb":[[1.79,50.63],[1.77,0]],"id":39213014}],"con":true,"img":false}]}
{"op":"mcm","clk":"5322669067","pt":1646322898991,"mc":[{"id":"1.195532867","rc":[{"atb":[[1.72,55.56]],"id":28791281}],"con":true,"img":false}]}
{"op":"mcm","clk":"5322669073","pt":1646322899154,"mc":[{"id":"1.195532867","rc":[{"atb":[[1.73,139.14]],"id":28791281},{"atb":[[2.74,6.63]],"id":35676762}],"con":true,"img":false}]}
{"op":"mcm","clk":"5322669081","pt":1646322899198,"mc":[{"id":"1.195532867","rc":[{"atb":[[2.74,0]],"id":35676762}],"con":true,"img":false}]}
{"op":"mcm","clk":"5322669248","pt":1646322900818,"mc":[{"id":"1.195532867","rc":[{"atb":[[1.73,205.48]],"id":41529439}],"con":true,"img":false}]}
{"op":"mcm","clk":"5322669347","pt":1646322901924,"mc":[{"id":"1.195532867","rc":[{"spn":7.98,"spf":"NaN","id":26648132},{"spn":4.57,"spf":"NaN","id":43094640},{"atb":[[1.57,0]],"id":28791281},{"spn":3.87,"spf":"NaN","id":28791281},{"spn":3.53,"spf":1.0,"id":35676762},{"spn":1.79,"spf":1.0,"id":41529439},{"atb":[[1.74,0]],"id":39213014},{"spn":1.81,"spf":1.0,"id":39213014}],"con":true,"img":false}]}
{"op":"mcm","clk":"5322669588","pt":1646322904632,"mc":[{"id":"1.195532867","rc":[{"atb":[[1.63,57.94]],"id":28791281},{"atb":[[1.78,4.14]],"id":41529439}],"con":true,"img":false}]}
{"op":"mcm","clk":"5322669721","pt":1646322906105,"mc":[{"id":"1.195532867","rc":[{"atb":[[3.55,2]],"id":35676762}],"con":true,"img":false}]}
{"op":"mcm","clk":"5322669740","pt":1646322906313,"mc":[{"id":"1.195532867","rc":[{"atb":[[3.65,1.65]],"id":35676762}],"con":true,"img":false}]}
{"op":"mcm","clk":"5322669762","pt":1646322906520,"mc":[{"id":"1.195532867","rc":[{"atb":[[3.45,4.99]],"id":35676762}],"con":true,"img":false}]}
{"op":"mcm","clk":"5322669806","pt":1646322906833,"mc":[{"id":"1.195532867","rc":[{"atb":[[3.55,0],[3.65,3.65]],"id":35676762}],"con":true,"img":false}]}
{"op":"mcm","clk":"5322669825","pt":1646322907043,"mc":[{"id":"1.195532867","rc":[{"atb":[[3.45,0]],"id":35676762}],"con":true,"img":false}]}
{"op":"mcm","clk":"5322669863","pt":1646322907409,"mc":[{"id":"1.195532867","rc":[{"atb":[[3.6,0]],"id":35676762}],"con":true,"img":false}]}
{"op":"mcm","clk":"5322669873","pt":1646322907513,"mc":[{"id":"1.195532867","rc":[{"atb":[[3.7,1.99]],"id":35676762}],"con":true,"img":false}]}
{"op":"mcm","clk":"5322669996","pt":1646322908934,"mc":[{"id":"1.195532867","rc":[{"atb":[[3.55,15.69],[3.5,0]],"id":35676762},{"atb":[[1.59,0],[1.77,129.87]],"id":39213014}],"con":true,"img":false}]}
{"op":"mcm","clk":"5322670003","pt":1646322909037,"mc":[{"id":"1.195532867","rc":[{"atb":[[1.7,142.86]],"id":28791281}],"con":true,"img":false}]}
{"op":"mcm","clk":"5322670091","pt":1646322910135,"mc":[{"id":"1.195532867","rc":[{"atb":[[2.26,17.95]],"id":26648132},{"atb":[[1.76,17.24]],"id":43094640},{"atl":[[7.4,0],[7.6,19.05]],"id":43094640},{"atb":[[1.38,0]],"id":28791281},{"atb":[[1.72,55.56],[1.77,0]],"id":41529439},{"atl":[[8.6,3.38],[8.2,4.76],[8.4,0]],"id":41529439},{"atb":[[1.67,0]],"id":39213014}],"con":true,"img":false}]}
{"op":"mcm","clk":"5322670110","pt":1646322910343,"mc":[{"id":"1.195532867","rc":[{"atb":[[2.26,0]],"id":26648132},{"atb":[[1.76,0]],"id":43094640}],"con":true,"img":false}]}
{"op":"mcm","clk":"5322670121","pt":1646322910478,"mc":[{"id":"1.195532867","rc":[{"atl":[[7.6,15.15]],"id":43094640},{"atl":[[8.6,0]],"id":41529439}],"con":true,"img":false}]}
{"op":"mcm","clk":"5322670132","pt":1646322910556,"mc":[{"id":"1.195532867","rc":[{"atb":[[1.73,61.86],[1.79,2.15]],"id":43094640}],"con":true,"img":false}]}
{"op":"mcm","clk":"5322670142","pt":1646322910616,"mc":[{"id":"1.195532867","rc":[{"atb":[[1.97,0]],"id":26648132}],"con":true,"img":false}]}
{"op":"mcm","clk":"5322670148","pt":1646322910719,"mc":[{"id":"1.195532867","rc":[{"atb":[[2.28,1.99]],"id":26648132},{"atb":[[1.73,0],[1.79,4.31]],"id":43094640}],"con":true,"img":false}]}
{"op":"mcm","clk":"5322670159","pt":1646322910823,"mc":[{"id":"1.195532867","rc":[{"atb":[[1.79,2.15],[1.74,57.55]],"id":43094640}],"con":true,"img":false}]}
{"op":"mcm","clk":"5322670173","pt":1646322910925,"mc":[{"id":"1.195532867","rc":[{"atb":[[2.28,44.1],[1.96,2.15]],"id":26648132}],"con":true,"img":false}]}
{"op":"mcm","clk":"5322670186","pt":1646322911042,"mc":[{"id":"1.195532867","rc":[{"atb":[[1.74,55.56]],"id":43094640}],"con":true,"img":false}]}
{"op":"mcm","clk":"5322670194","pt":1646322911133,"mc":[{"id":"1.195532867","rc":[{"atb":[[1.77,1.99]],"id":43094640}],"con":true,"img":false}]}
{"op":"mcm","clk":"5322670291","pt":1646322912233,"mc":[{"id":"1.195532867","rc":[{"atb":[[1.77,0]],"id":43094640}],"con":true,"img":false}]}
{"op":"mcm","clk":"5322670303","pt":1646322912336,"mc":[{"id":"1.195532867","rc":[{"atb":[[1.8,1.99]],"id":43094640}],"con":true,"img":false}]}
{"op":"mcm","clk":"5322670339","pt":1646322912649,"mc":[{"id":"1.195532867","rc":[{"atb":[[1.7,0]],"id":43094640},{"atb":[[1.63,0]],"id":28791281},{"atb":[[1.78,0]],"id":41529439}],"con":true,"img":false}]}
{"op":"mcm","clk":"5322670567","pt":1646322915177,"mc":[{"id":"1.195532867","rc":[{"atb":[[3.65,2]],"id":35676762}],"con":true,"img":false}]}
{"op":"mcm","clk":"5322670583","pt":1646322915337,"mc":[{"id":"1.195532867","rc":[{"atb":[[2.3,1.65]],"id":26648132},{"atb":[[3.75,1.65]],"id":35676762}],"con":true,"img":false}]}
{"op":"mcm","clk":"5322670628","pt":1646322915755,"mc":[{"id":"1.195532867","rc":[{"atb":[[3.75,3.65],[3.65,0]],"id":35676762}],"con":true,"img":false}]}
{"op":"mcm","clk":"5322670660","pt":1646322916225,"mc":[{"id":"1.195532867","rc":[{"atb":[[3.7,0]],"id":35676762}],"con":true,"img":false}]}
{"op":"mcm","clk":"5322670668","pt":1646322916384,"mc":[{"id":"1.195532867","rc":[{"atb":[[3.8,1.99]],"id":35676762}],"con":true,"img":false}]}
{"op":"mcm","clk":"5322670741","pt":1646322917217,"mc":[{"id":"1.195532867","rc":[{"atb":[[1.75,4.97]],"id":43094640},{"atb":[[1.74,51.32]],"id":28791281},{"atb":[[1.76,4.97]],"id":41529439}],"con":true,"img":false}]}
{"op":"mcm","clk":"5322670750","pt":1646322917323,"mc":[{"id":"1.195532867","rc":[{"atb":[[1.73,2.15],[1.75,55.56]],"id":28791281}],"con":true,"img":false}]}
{"op":"mcm","clk":"5322670837","pt":1646322918316,"mc":[{"id":"1.195532867","rc":[{"atb":[[1.74,49.33]],"id":28791281}],"con":true,"img":false}]}
{"op":"mcm","clk":"5322670848","pt":1646322918418,"mc":[{"id":"1.195532867","rc":[{"atb":[[1.02,1.99]],"id":28791281}],"con":true,"img":false}]}
{"op":"mcm","clk":"5322670895","pt":1646322918856,"mc":[{"id":"1.195532867","rc":[{"atb":[[3.45,40.82]],"id":35676762}],"con":true,"img":false}]}
{"op":"mcm","clk":"5322670901","pt":1646322918943,"mc":[{"id":"1.195532867","rc":[{"atb":[[1.75,200]],"id":39213014}],"con":true,"img":false}]}
{"op":"mcm","clk":"5322670908","pt":1646322919048,"mc":[{"id":"1.195532867","rc":[{"atb":[[1.73,56.94],[1.72,0]],"id":28791281},{"atl":[[8,4.76],[8.2,0]],"id":41529439}],"con":true,"img":false}]}
{"op":"mcm","clk":"5322670960","pt":1646322919626,"mc":[{"id":"1.195532867","rc":[{"atb":[[1.8,4.15],[1.74,0]],"id":43094640}],"con":true,"img":false}]}
{"op":"mcm","clk":"5322670995","pt":1646322920048,"mc":[{"id":"1.195532867","rc":[{"atb":[[1.95,0]],"id":26648132}],"con":true,"img":false}]}
{"op":"mcm","clk":"5322671005","pt":1646322920153,"mc":[{"id":"1.195532867","rc":[{"atb":[[2.26,31.75]],"id":26648132},{"atb":[[1.74,11.9],[1.7,142.86],[1.75,0]],"id":41529439},{"atl":[[8.8,0],[8.4,5.41]],"id":41529439}],"con":true,"img":false}]}
{"op":"mcm","clk":"5322671034","pt":1646322920471,"mc":[{"id":"1.195532867","rc":[{"atb":[[1.74,0]],"id":41529439}],"con":true,"img":false}]}
{"op":"mcm","clk":"5322671095","pt":1646322921152,"mc":[{"id":"1.195532867","rc":[{"atb":[[1.73,54.79],[1.78,2.15]],"id":28791281}],"con":true,"img":false}]}
{"op":"mcm","clk":"5322671107","pt":1646322921316,"mc":[{"id":"1.195532867","rc":[{"atb":[[1.78,51.48]],"id":28791281}],"con":true,"img":false}]}
{"op":"mcm","clk":"5322671113","pt":1646322921422,"mc":[{"id":"1.195532867","rc":[{"atb":[[1.74,0],[1.75,0]],"id":28791281}],"con":true,"img":false}]}
{"op":"mcm","clk":"5322671246","pt":1646322923414,"mc":[{"id":"1.195532867","rc":[{"atb":[[1.75,0]],"id":43094640},{"atb":[[1.76,0]],"id":41529439}],"con":true,"img":false}]}
{"op":"mcm","clk":"5322671303","pt":1646322924145,"mc":[{"id":"1.195532867","rc":[{"atb":[[1.69,22.32]],"id":28791281},{"atb":[[3.75,2]],"id":35676762}],"con":true,"img":false}]}
{"op":"mcm","clk":"5322671320","pt":1646322924354,"mc":[{"id":"1.195532867","rc":[{"atb":[[3.85,1.65]],"id":35676762}],"con":true,"img":false}]}
{"op":"mcm","clk":"5322671338","pt":1646322924463,"mc":[{"id":"1.195532867","rc":[{"atb":[[1.69,0]],"id":28791281}],"con":true,"img":false}]}
{"op":"mcm","clk":"5322671349","pt":1646322924517,"mc":[{"id":"1.195532867","rc":[{"atb":[[3.8,5.31],[3.75,0]],"id":35676762}],"con":true,"img":false}]}
{"op":"mcm","clk":"5322671438","pt":1646322925712,"mc":[{"id":"1.195532867","rc":[{"atb":[[1.71,51.41]],"id":28791281}],"con":true,"img":false}]}
{"op":"mcm","clk":"5322671642","pt":1646322928226,"mc":[{"id":"1.195532867","rc":[{"atb":[[1.7,7.46]],"id":43094640},{"atb":[[1.74,5.8]],"id":41529439}],"con":true,"img":false}]}
{"op":"mcm","clk":"5322671695","pt":1646322928955,"mc":[{"id":"1.195532867","rc":[{"atb":[[2.4,0],[3.35,63.83],[2.44,0],[2.48,0]],"id":35676762},{"atb":[[1.73,250],[1.71,0]],"id":39213014}],"con":true,"img":false}]}
{"op":"mcm","clk":"5322671702","pt":1646322929059,"mc":[{"id":"1.195532867","rc":[{"atb":[[1.73,0],[1.76,52.63]],"id":28791281}],"con":true,"img":false}]}
{"op":"mcm","clk":"5322671793","pt":1646322930153,"mc":[{"id":"1.195532867","rc":[{"atb":[[2.22,81.97]],"id":26648132},{"atb":[[1.73,0],[1.68,220.59]],"id":41529439},{"atl":[[8.8,12.82]],"id":41529439}],"con":true,"img":false}]}
{"op":"mcm","clk":"5322671912","pt":1646322931678,"mc":[{"id":"1.195532867","rc":[{"atb":[[1.96,0],[2.34,2.15]],"id":26648132},{"atb":[[1.79,0],[1.75,2.15]],"id":43094640}],"con":true,"img":false}]}
{"op":"mcm","clk":"5322671929","pt":1646322931838,"mc":[{"id":"1.195532867","rc":[{"atb":[[2.28,1.99],[2.34,4.31]],"id":26648132}],"con":true,"img":false}]}
{"op":"mcm","clk":"5322672000","pt":1646322932782,"mc":[{"id":"1.195532867","rc":[{"atb":[[1.71,0]],"id":28791281}],"con":true,"img":false}]}
{"op":"mcm","clk":"5322672017","pt":1646322932943,"mc":[{"id":"1.195532867","rc":[{"atb":[[2.28,0]],"id":26648132}],"con":true,"img":false}]}
{"op":"mcm","clk":"5322672026","pt":1646322933047,"mc":[{"id":"1.195532867","rc":[{"atb":[[2.36,1.99]],"id":26648132}],"con":true,"img":false}]}
{"op":"mcm","clk":"5322672030","pt":1646322933150,"mc":[{"id":"1.195532867","rc":[{"atb":[[2.3,0]],"id":26648132}],"con":true,"img":false}]}
{"op":"mcm","clk":"5322672045","pt":1646322933361,"mc":[{"id":"1.195532867","rc":[{"atb":[[2.36,3.64]],"id":26648132}],"con":true,"img":false}]}
{"op":"mcm","clk":"5322672352","pt":1646322936987,"mc":[{"id":"1.195532867","rc":[{"atb":[[1.71,51.41]],"id":28791281}],"con":true,"img":false}]}
{"op":"mcm","clk":"5322672519","pt":1646322938993,"mc":[{"id":"1.195532867","rc":[{"atb":[[3.25,111.11]],"id":35676762}],"con":true,"img":false}]}
{"op":"mcm","clk":"5322672530","pt":1646322939087,"mc":[{"id":"1.195532867","rc":[{"atb":[[1.74,135.14]],"id":28791281}],"con":true,"img":false}]}
{"op":"mcm","clk":"5322672597","pt":1646322940181,"mc":[{"id":"1.195532867","rc":[{"atb":[[2.32,30.3],[2.26,0]],"id":26648132},{"atb":[[1.66,250]],"id":41529439},{"atl":[[9.2,18.29],[10.5,0],[9.8,0],[9.4,0]],"id":41529439}],"con":true,"img":false}]}
{"op":"mcm","clk":"5322672620","pt":1646322940447,"mc":[{"id":"1.195532867","rc":[{"atb":[[2.38,4.32],[2.34,2.15]],"id":26648132}],"con":true,"img":false}]}
{"op":"mcm","clk":"5322672639","pt":1646322940656,"mc":[{"id":"1.195532867","rc":[{"atb":[[2.36,1.65]],"id":26648132}],"con":true,"img":false}]}
{"op":"mcm","clk":"5322672648","pt":1646322940763,"mc":[{"id":"1.195532867","rc":[{"atb":[[2.4,1.99],[2.32,0],[2.34,32]],"id":26648132},{"atb":[[1.72,0],[1.78,51.28]],"id":43094640},{"atl":[[8,5.71],[7.8,0]],"id":43094640},{"atb":[[1.56,0]],"id":28791281},{"atb":[[1.01,4804.04]],"id":41529439}],"con":true,"img":false}]}
{"op":"mcm","clk":"5322672655","pt":1646322940865,"mc":[{"id":"1.195532867","rc":[{"atb":[[2.36,10.29],[2.38,0]],"id":26648132}],"con":true,"img":false}]}
{"op":"mcm","clk":"5322672661","pt":1646322940970,"mc":[{"id":"1.195532867","rc":[{"atb":[[2.4,3.99],[2.36,1.65]],"id":26648132}],"con":true,"img":false}]}
{"op":"mcm","clk":"5322672670","pt":1646322941078,"mc":[{"id":"1.195532867","rc":[{"atb":[[2.4,0],[2.36,33.66]],"id":26648132}],"con":true,"img":false}]}
{"op":"mcm","clk":"5322672677","pt":1646322941178,"mc":[{"id":"1.195532867","rc":[{"atb":[[2.38,1.99]],"id":26648132}],"con":true,"img":false}]}
{"op":"mcm","clk":"5322672747","pt":1646322942290,"mc":[{"id":"1.195532867","rc":[{"atb":[[2.36,32.01],[2.42,2.15],[2.34,29.85]],"id":26648132}],"con":true,"img":false}]}
{"op":"mcm","clk":"5322672757","pt":1646322942452,"mc":[{"id":"1.195532867","rc":[{"atb":[[2.4,1.65]],"id":26648132}],"con":true,"img":false}]}
{"op":"mcm","clk":"5322672831","pt":1646322943397,"mc":[{"id":"1.195532867","rc":[{"atb":[[1.7,0]],"id":43094640},{"atb":[[1.71,0]],"id":28791281}],"con":true,"img":false}]}
{"op":"mcm","clk":"5322672903","pt":1646322944297,"mc":[{"id":"1.195532867","rc":[{"atb":[[2.38,0]],"id":26648132}],"con":true,"img":false}]}
{"op":"mcm","clk":"5322672913","pt":1646322944353,"mc":[{"id":"1.195532867","rc":[{"atb":[[2.44,1.99]],"id":26648132}],"con":true,"img":false}]}
{"op":"mcm","clk":"5322673238","pt":1646322947863,"mc":[{"id":"1.195532867","rc":[{"atb":[[1.7,7.46]],"id":43094640},{"atb":[[1.79,36.03]],"id":28791281}],"con":true,"img":false}]}
{"op":"mcm","clk":"5322673246","pt":1646322947968,"mc":[{"id":"1.195532867","rc":[{"atb":[[1.8,51.49],[1.78,2.15]],"id":28791281}],"con":true,"img":false}]}
{"op":"mcm","clk":"5322673324","pt":1646322949078,"mc":[{"id":"1.195532867","rc":[{"atb":[[1.78,53.43],[1.76,0]],"id":28791281}],"con":true,"img":false}]}
{"op":"mcm","clk":"5322673371","pt":1646322949653,"mc":[{"id":"1.195532867","rc":[{"atb":[[2.36,0],[2.44,3.99]],"id":26648132}],"con":true,"img":false}]}
{"op":"mcm","clk":"5322673414","pt":1646322950182,"mc":[{"id":"1.195532867","rc":[{"atl":[[9.6,29.07]],"id":41529439}],"con":true,"img":false}]}
{"op":"mcm","clk":"5322673470","pt":1646322950759,"mc":[{"id":"1.195532867","rc":[{"atb":[[2.4,30.22],[2.34,3.68]],"id":26648132},{"atb":[[1.76,131.58]],"id":43094640},{"atl":[[8.4,13.51]],"id":43094640}],"con":true,"img":false}]}
{"op":"mcm","clk":"5322673492","pt":1646322950965,"mc":[{"id":"1.195532867","rc":[{"atb":[[2.34,0]],"id":26648132}],"con":true,"img":false}]}
{"op":"mcm","clk":"5322673519","pt":1646322951286,"mc":[{"id":"1.195532867","rc":[{"atb":[[2.4,28.57]],"id":26648132}],"con":true,"img":false}]}
{"op":"mcm","clk":"5322673528","pt":1646322951506,"mc":[{"id":"1.195532867","rc":[{"atb":[[2.46,1.65]],"id":26648132}],"con":true,"img":false}]}
{"op":"mcm","clk":"5322673602","pt":1646322952381,"mc":[{"id":"1.195532867","rc":[{"atb":[[1.79,0]],"id":28791281}],"con":true,"img":false}]}
{"op":"mcm","clk":"5322673656","pt":1646322952853,"mc":[{"id":"1.195532867","rc":[{"atb":[[1.81,2.15]],"id":43094640},{"atb":[[1.83,2.15]],"id":28791281}],"con":true,"img":false}]}
{"op":"mcm","clk":"5322673668","pt":1646322952961,"mc":[{"id":"1.195532867","rc":[{"atb":[[1.75,0]],"id":43094640},{"atb":[[1.78,51.28]],"id":28791281}],"con":true,"img":false}]}
{"op":"mcm","clk":"5322673712","pt":1646322953479,"mc":[{"id":"1.195532867","rc":[{"atb":[[1.8,2.16]],"id":43094640}],"con":true,"img":false}]}
{"op":"mcm","clk":"5322673725","pt":1646322953580,"mc":[{"id":"1.195532867","rc":[{"atb":[[1.82,1.99]],"id":43094640}],"con":true,"img":false}]}
{"op":"mcm","clk":"5322673749","pt":1646322953788,"mc":[{"id":"1.195532867","rc":[{"atb":[[1.82,4.15],[1.8,0]],"id":43094640}],"con":true,"img":false}]}
{"op":"mcm","clk":"5322673832","pt":1646322954776,"mc":[{"id":"1.195532867","rc":[{"atb":[[1.7,0]],"id":43094640}],"con":true,"img":false}]}
{"op":"mcm","clk":"5322673930","pt":1646322956005,"mc":[{"id":"1.195532867","rc":[{"atb":[[2.4,0],[2.42,30.32]],"id":26648132},{"atb":[[1.8,50],[1.78,0],[1.77,6.41]],"id":43094640},{"atb":[[1.81,49.38],[1.78,0]],"id":28791281},{"atl":[[8,0],[7.8,5.41]],"id":41529439}],"con":true,"img":false}]}
{"op":"mcm","clk":"5322673938","pt":1646322956055,"mc":[{"id":"1.195532867","rc":[{"atl":[[8.2,3.57]],"id":41529439}],"con":true,"img":false}]}
{"op":"mcm","clk":"5322673964","pt":1646322956371,"mc":[{"id":"1.195532867","rc":[{"atb":[[1.77,0]],"id":43094640},{"atl":[[8.2,0]],"id":41529439}],"con":true,"img":false}]}
{"op":"mcm","clk":"5322673977","pt":1646322956470,"mc":[{"id":"1.195532867","rc":[{"atb":[[1.83,51.53],[1.8,0]],"id":28791281}],"con":true,"img":false}]}
{"op":"mcm","clk":"5322673986","pt":1646322956575,"mc":[{"id":"1.195532867","rc":[{"atb":[[1.83,2.15],[1.8,125]],"id":28791281}],"con":true,"img":false}]}
{"op":"mcm","clk":"5322674002","pt":1646322956783,"mc":[{"id":"1.195532867","rc":[{"atb":[[1.83,53.69],[1.8,0]],"id":28791281}],"con":true,"img":false}]}
{"op":"mcm","clk":"5322674044","pt":1646322957305,"mc":[{"id":"1.195532867","rc":[{"atb":[[1.75,48.67]],"id":28791281}],"con":true,"img":false}]}
{"op":"mcm","clk":"5322674256","pt":1646322959797,"mc":[{"id":"1.195532867","rc":[{"atb":[[1.74,0]],"id":41529439}],"con":true,"img":false}]}
{"op":"mcm","clk":"5322674276","pt":1646322959908,"mc":[{"id":"1.195532867","rc":[{"atb":[[1.82,2.9]],"id":39213014}],"con":true,"img":false}]}
{"op":"mcm","clk":"5322674295","pt":1646322960168,"mc":[{"id":"1.195532867","rc":[{"atb":[[2,8.12],[1.72,69.08],[1.67,13.52]],"id":41529439},{"atl":[[7.2,8.12],[8.2,5.56],[8.8,34.46],[8.4,0]],"id":41529439}],"con":true,"img":false}]}
{"op":"mcm","clk":"5322674304","pt":1646322960274,"mc":[{"id":"1.195532867","rc":[{"atb":[[2.22,99.92],[2.52,10],[2.6,13],[2.68,2.5]],"id":26648132},{"atl":[[16,20.73],[9,8],[8.2,10],[7.4,5],[6.6,2.5]],"id":26648132},{"atb":[[2.24,14.42],[2,10],[1.8,74.02],[2.16,2.5],[2.08,5]],"id":43094640},{"atl":[[6.2,10],[5.3,2.5],[5.7,5],[7,13.33],[8.4,40.3]],"id":43094640},{"atb":[[1.82,10],[1.9,48.09],[1.86,5],[1.75,131.07]],"id":28791281},{"atl":[[4.6,5],[5,10],[6.8,50.34],[4.2,2.5],[5.9,16.33]],"id":28791281},{"atb":[[3.45,52.96],[3.85,5.63]],"id":35676762},{"atl":[[32,2.58],[10.5,2.5],[46,7.61],[12.5,5],[14.5,10]],"id":35676762},{"atb":[[1.8,1.99],[1.82,10],[1.9,2.5],[1.86,5]],"id":41529439},{"atl":[[5.1,5],[5.5,10],[4.7,2.5]],"id":41529439},{"atb":[[1.8,15.96],[1.98,5],[2.04,10.79],[1.94,10]],"id":39213014},{"atl":[[7.2,38.23],[6.2,8.29],[5.3,5],[4.9,2.5],[5.7,10]],"id":39213014}],"con":true,"img":false}]}
{"op":"mcm","clk":"5322674313","pt":1646322960379,"mc":[{"id":"1.195532867","rc":[{"atb":[[2.44,1.99],[2.68,12.5]],"id":26648132},{"atl":[[6.6,7.5],[14,0]],"id":26648132},{"atl":[[5.3,7.5],[7.6,0]],"id":43094640},{"atb":[[1.83,2.15],[1.91,48.09]],"id":28791281},{"atl":[[6,0],[4.2,7.5]],"id":28791281},{"atb":[[3.85,11.27],[3.8,1.99],[3.3,6.63]],"id":35676762},{"atl":[[40,0],[10.5,7.5]],"id":35676762},{"atb":[[2.02,4.15],[1.67,0]],"id":41529439},{"atb":[[2.06,10],[1.74,13.81]],"id":39213014},{"atl":[[4.9,7.5]],"id":39213014}],"con":true,"img":false}]}
{"op":"mcm","clk":"5322674318","pt":1646322960483,"mc":[{"id":"1.195532867","rc":[{"atl":[[14.5,5.77]],"id":26648132},{"atl":[[7.8,6.38]],"id":43094640},{"atl":[[6.2,5]],"id":28791281},{"atb":[[1.8,0],[1.9,15]],"id":41529439},{"atb":[[1.92,18.75],[1.81,1.99]],"id":39213014},{"atl":[[6.4,0],[6.6,4.63]],"id":39213014}],"con":true,"img":false}]}
{"op":"mcm","clk":"5322674330","pt":1646322960587,"mc":[{"id":"1.195532867","rc":[{"atb":[[1.91,0],[1.86,101.18]],"id":28791281},{"atl":[[5,22.5],[4.2,2.5]],"id":28791281},{"atb":[[2.02,6.14]],"id":41529439}],"con":true,"img":false}]}
{"op":"mcm","clk":"5322674340","pt":1646322960691,"mc":[{"id":"1.195532867","rc":[{"atl":[[14.5,0]],"id":26648132},{"atl":[[7.8,0]],"id":43094640},{"atl":[[6.2,0]],"id":28791281},{"atb":[[1.9,2.5]],"id":41529439},{"atb":[[1.92,0]],"id":39213014},{"atl":[[6.6,0]],"id":39213014}],"con":true,"img":false}]}
{"op":"mcm","clk":"5322674352","pt":1646322960794,"mc":[{"id":"1.195532867","rc":[{"atb":[[1.81,0]],"id":39213014}],"con":true,"img":false}]}
{"op":"mcm","clk":"5322674362","pt":1646322960897,"mc":[{"id":"1.195532867","rc":[{"atb":[[3.3,0]],"id":35676762},{"atb":[[1.83,1.99],[1.74,0]],"id":39213014}],"con":true,"img":false}]}
{"op":"mcm","clk":"5322674438","pt":1646322961677,"mc":[{"id":"1.195532867","rc":[{"atb":[[2.44,0]],"id":26648132}],"con":true,"img":false}]}
{"op":"mcm","clk":"5322674448","pt":1646322961779,"mc":[{"id":"1.195532867","rc":[{"atb":[[2.7,1.99]],"id":26648132}],"con":true,"img":false}]}
{"op":"mcm","clk":"5322674462","pt":1646322961988,"mc":[{"id":"1.195532867","rc":[{"spn":4.65,"spf":"NaN","id":26648132},{"spn":3.77,"spf":"NaN","id":43094640},{"spn":3.05,"spf":"NaN","id":28791281},{"atb":[[3.8,0]],"id":35676762},{"spn":3.85,"spf":1.0,"id":35676762},{"spn":2.01,"spf":1.0,"id":41529439},{"spn":2.06,"spf":1.0,"id":39213014}],"con":true,"img":false}]}
{"op":"mcm","clk":"5322674472","pt":1646322962093,"mc":[{"id":"1.195532867","rc":[{"atb":[[3.9,1.99]],"id":35676762}],"con":true,"img":false}]}
{"op":"mcm","clk":"5322674476","pt":1646322962197,"mc":[{"id":"1.195532867","rc":[{"atb":[[1.82,1.99],[2.08,21.92]],"id":43094640},{"atb":[[3.35,66.33]],"id":35676762},{"atb":[[1.73,6.21]],"id":41529439}],"con":true,"img":false}]}
{"op":"mcm","clk":"5322674493","pt":1646322962406,"mc":[{"id":"1.195532867","rc":[{"atb":[[1.83,0]],"id":39213014}],"con":true,"img":false}]}
{"op":"mcm","clk":"5322674502","pt":1646322962510,"mc":[{"id":"1.195532867","rc":[{"atb":[[2.08,1.99]],"id":39213014}],"con":true,"img":false}]}
{"op":"mcm","clk":"5322674529","pt":1646322962673,"mc":[{"id":"1.195532867","rc":[{"atb":[[1.82,0]],"id":43094640}],"con":true,"img":false}]}
{"op":"mcm","clk":"5322674539","pt":1646322962777,"mc":[{"id":"1.195532867","rc":[{"atb":[[2.26,1.99]],"id":43094640}],"con":true,"img":false}]}
{"op":"mcm","clk":"5322674594","pt":1646322963504,"mc":[{"id":"1.195532867","rc":[{"atb":[[1.83,0]],"id":28791281}],"con":true,"img":false}]}
{"op":"mcm","clk":"5322674612","pt":1646322963712,"mc":[{"id":"1.195532867","rc":[{"atb":[[1.93,2.15]],"id":28791281}],"con":true,"img":false}]}
{"op":"mcm","clk":"5322674680","pt":1646322964410,"mc":[{"id":"1.195532867","rc":[{"atl":[[5.5,18.12],[7.8,0]],"id":41529439}],"con":true,"img":false}]}
{"op":"mcm","clk":"5322674694","pt":1646322964607,"mc":[{"id":"1.195532867","rc":[{"atb":[[1.75,82.4]],"id":28791281},{"atb":[[1.73,0]],"id":41529439},{"atb":[[1.82,0]],"id":39213014}],"con":true,"img":false}]}
{"op":"mcm","clk":"5322674772","pt":1646322965600,"mc":[{"id":"1.195532867","rc":[{"atl":[[8.2,22.5],[6.6,2.5]],"id":26648132},{"atl":[[6.2,22.5],[5.3,2.5]],"id":43094640},{"atl":[[10.5,2.5],[14.5,17.41]],"id":35676762},{"atl":[[4.9,2.5],[5.7,22.5]],"id":39213014}],"con":true,"img":false}]}
{"op":"mcm","clk":"5322674813","pt":1646322966020,"mc":[{"id":"1.195532867","rc":[{"atb":[[2.5,26.67],[2.42,2.15]],"id":26648132},{"atl":[[7,6.67],[15,0]],"id":26648132},{"atb":[[2.14,35.09]],"id":43094640},{"atl":[[5.5,8.89]],"id":43094640},{"atb":[[1.79,126.58]],"id":28791281},{"atl":[[6.4,0],[4.4,11.76]],"id":28791281},{"atl":[[44,0],[11.5,3.81]],"id":35676762},{"atb":[[1.79,0],[1.95,42.11]],"id":39213014},{"atl":[[5.1,9.76],[6.8,0]],"id":39213014}],"con":true,"img":false}]}
{"op":"mcm","clk":"5322674823","pt":1646322966075,"mc":[{"id":"1.195532867","rc":[{"atb":[[1.8,24.02]],"id":43094640},{"atl":[[8,0]],"id":43094640}],"con":true,"img":false}]}
{"op":"mcm","clk":"5322675073","pt":1646322969017,"mc":[{"id":"1.195532867","rc":[{"atb":[[1.86,5],[1.93,50.24]],"id":28791281},{"atl":[[4.6,21.33],[5,10]],"id":28791281}],"con":true,"img":false}]}
{"op":"mcm","clk":"5322675079","pt":1646322969077,"mc":[{"id":"1.195532867","rc":[{"atb":[[1.86,55.25]],"id":28791281}],"con":true,"img":false}]}
{"op":"mcm","clk":"5322675087","pt":1646322969176,"mc":[{"id":"1.195532867","rc":[{"atb":[[2.46,0]],"id":26648132},{"atb":[[1.93,2.15]],"id":28791281},{"atb":[[3.85,9.62]],"id":35676762}],"con":true,"img":false}]}
{"op":"mcm","clk":"5322675104","pt":1646322969381,"mc":[{"id":"1.195532867","rc":[{"atb":[[2.72,1.65]],"id":26648132},{"atb":[[2.28,1.65]],"id":43094640},{"atb":[[3.95,1.65]],"id":35676762},{"atb":[[2.04,1.65]],"id":41529439},{"atb":[[2.1,1.65]],"id":39213014}],"con":true,"img":false}]}
{"op":"mcm","clk":"5322675112","pt":1646322969482,"mc":[{"id":"1.195532867","rc":[{"atb":[[1.83,43.98]],"id":28791281},{"atb":[[1.91,11.04]],"id":41529439},{"atb":[[1.99,14.38]],"id":39213014}],"con":true,"img":false}]}
{"op":"mcm","clk":"5322675119","pt":1646322969589,"mc":[{"id":"1.195532867","rc":[{"atb":[[1.93,50.24],[1.86,5]],"id":28791281}],"con":true,"img":false}]}
{"op":"mcm","clk":"5322675168","pt":1646322970213,"mc":[{"id":"1.195532867","rc":[{"atl":[[8.2,0],[4.9,10.26]],"id":41529439}],"con":true,"img":false}]}
{"op":"mcm","clk":"5322675199","pt":1646322970525,"mc":[{"id":"1.195532867","rc":[{"atb":[[2.08,4.99],[2.18,21.92]],"id":43094640}],"con":true,"img":false}]}
{"op":"mcm","clk":"5322675407","pt":1646322972707,"mc":[{"id":"1.195532867","rc":[{"atl":[[5.1,17.76],[5.5,10]],"id":41529439}],"con":true,"img":false}]}
{"op":"mcm","clk":"5322675506","pt":1646322973906,"mc":[{"id":"1.195532867","rc":[{"atl":[[8.2,10],[7.4,14.17]],"id":26648132},{"atl":[[6.2,10],[5.7,18.33]],"id":43094640},{"atb":[[1.83,0]],"id":28791281},{"atl":[[12.5,11.31],[14.5,10]],"id":35676762},{"atb":[[1.99,0]],"id":39213014},{"atl":[[5.3,17.26],[5.7,10]],"id":39213014}],"con":true,"img":false}]}
{"op":"mcm","clk":"5322675511","pt":1646322974009,"mc":[{"id":"1.195532867","rc":[{"atb":[[2.3,2.15],[1.81,0]],"id":43094640},{"atb":[[2.12,2.15],[1.8,13.81]],"id":39213014}],"con":true,"img":false}]}
{"op":"mcm","clk":"5322675526","pt":1646322974217,"mc":[{"id":"1.195532867","rc":[{"atb":[[2.22,5.82]],"id":43094640}],"con":true,"img":false}]}
{"op":"mcm","clk":"5322675573","pt":1646322974685,"mc":[{"id":"1.195532867","rc":[{"atb":[[2.22,0]],"id":43094640}],"con":true,"img":false}]}
{"op":"mcm","clk":"5322675606","pt":1646322975202,"mc":[{"id":"1.195532867","rc":[{"atb":[[2.08,0]],"id":39213014}],"con":true,"img":false}]}
{"op":"mcm","clk":"5322675614","pt":1646322975306,"mc":[{"id":"1.195532867","rc":[{"atb":[[2.14,1.99]],"id":39213014}],"con":true,"img":false}]}
{"op":"mcm","clk":"5322675625","pt":1646322975516,"mc":[{"id":"1.195532867","rc":[{"atb":[[2.26,0]],"id":43094640}],"con":true,"img":false}]}
{"op":"mcm","clk":"5322675639","pt":1646322975620,"mc":[{"id":"1.195532867","rc":[{"atb":[[2.32,1.99]],"id":43094640}],"con":true,"img":false}]}
{"op":"mcm","clk":"5322675673","pt":1646322975983,"mc":[{"id":"1.195532867","rc":[{"atb":[[1.72,0],[1.92,0],[1.9,0],[2.46,68.49]],"id":26648132},{"atl":[[7.4,29.79]],"id":26648132},{"atb":[[2.1,90.91],[1.76,0]],"id":43094640},{"atl":[[5.7,39.61]],"id":43094640},{"atb":[[1.7,0],[1.62,0],[1.74,0],[1.77,194.81]],"id":28791281},{"atl":[[4.6,49.11]],"id":28791281},{"atl":[[12.5,20.01]],"id":35676762},{"atb":[[1.93,107.53]],"id":39213014},{"atl":[[5.3,40.52]],"id":39213014}],"con":true,"img":false}]}
{"op":"mcm","clk":"5322675743","pt":1646322976914,"mc":[{"id":"1.195532867","rc":[{"atb":[[2.62,6.5]],"id":26648132}],"con":true,"img":false}]}
{"op":"mcm","clk":"5322675823","pt":1646322977707,"mc":[{"id":"1.195532867","rc":[{"atb":[[1.72,55.56],[1.91,34.02]],"id":41529439},{"atl":[[5.1,54.52],[4.6,10.69]],"id":41529439}],"con":true,"img":false}]}
{"op":"mcm","clk":"5322675830","pt":1646322977812,"mc":[{"id":"1.195532867","rc":[{"atb":[[3.7,3.6]],"id":35676762},{"atb":[[2.02,16.83]],"id":41529439},{"atl":[[8.8,12.82]],"id":41529439}],"con":true,"img":false}]}
{"op":"mcm","clk":"5322675839","pt":1646322977915,"mc":[{"id":"1.195532867","rc":[{"atb":[[2.22,81.97],[2.62,22.96],[2.7,8.87]],"id":26648132},{"atl":[[16,6.67],[6.4,6.88],[7.4,56.13]],"id":26648132},{"atb":[[2.3,5.65],[1.8,0],[2.18,53.13]],"id":43094640},{"atl":[[5.2,3.5],[5.7,81.3],[8.4,13.51]],"id":43094640},{"atb":[[1.89,3.18],[1.86,79.81],[1.93,92.83],[1.75,0]],"id":28791281},{"atl":[[4.6,100.77],[4.1,25.81],[6.8,17.24]],"id":28791281},{"atb":[[3.45,40.82],[3.95,6.38],[3.55,32.48]],"id":35676762},{"atl":[[10,4.73],[46,2.73],[12.5,39.01]],"id":35676762},{"atb":[[2,0]],"id":41529439},{"atl":[[7.2,0],[5.1,41.76],[4.5,10.26]],"id":41529439},{"atb":[[2.04,36.48],[2.12,5.65],[1.8,0]],"id":39213014},{"atl":[[4.8,3.5],[7.2,16.13],[5.3,81.62]],"id":39213014}],"con":true,"img":false}]}
{"op":"mcm","clk":"5322675848","pt":1646322978021,"mc":[{"id":"1.195532867","rc":[{"atb":[[2.6,5]],"id":26648132},{"atl":[[9,0],[7.4,46.96],[7,16.67]],"id":26648132},{"atb":[[1.89,98.34],[1.9,2.5],[1.93,44.74]],"id":28791281},{"atl":[[4.6,84.44],[4.4,23.52],[5.9,0]],"id":28791281},{"atb":[[3.85,5.64]],"id":35676762},{"atl":[[32,0],[11.5,13.33]],"id":35676762},{"atb":[[2.04,28.19]],"id":39213014},{"atl":[[6.2,0]],"id":39213014}],"con":true,"img":false}]}
{"op":"mcm","clk":"5322675855","pt":1646322978125,"mc":[{"id":"1.195532867","rc":[{"atb":[[2.24,0]],"id":43094640},{"atl":[[7,0]],"id":43094640},{"atl":[[12.5,32.7]],"id":35676762}],"con":true,"img":false}]}
{"op":"mcm","clk":"5322675863","pt":1646322978178,"mc":[{"id":"1.195532867","rc":[{"atb":[[2.28,0]],"id":43094640},{"atb":[[2.1,0]],"id":39213014}],"con":true,"img":false}]}
{"op":"mcm","clk":"5322675885","pt":1646322978385,"mc":[{"id":"1.195532867","rc":[{"atb":[[2.34,1.65]],"id":43094640},{"atb":[[2.16,1.65]],"id":39213014}],"con":true,"img":false}]}
{"op":"mcm","clk":"5322675898","pt":1646322978489,"mc":[{"id":"1.195532867","rc":[{"atb":[[3.9,0]],"id":35676762}],"con":true,"img":false}]}
{"op":"mcm","clk":"5322675907","pt":1646322978594,"mc":[{"id":"1.195532867","rc":[{"atb":[[1.87,41.96]],"id":28791281},{"atb":[[4,1.99]],"id":35676762},{"atb":[[2.14,4.89]],"id":39213014}],"con":true,"img":false}]}
{"op":"mcm","clk":"5322675926","pt":1646322978800,"mc":[{"id":"1.195532867","rc":[{"atb":[[2.62,16.46]],"id":26648132},{"atb":[[3.7,0]],"id":35676762}],"con":true,"img":false}]}
{"op":"mcm","clk":"5322676049","pt":1646322980207,"mc":[{"id":"1.195532867","rc":[{"atl":[[4.9,0],[4.7,13.31]],"id":41529439}],"con":true,"img":false}]}
{"op":"mcm","clk":"5322676204","pt":1646322982083,"mc":[{"id":"1.195532867","rc":[{"atl":[[5.5,18.89],[5.7,67.97]],"id":43094640},{"atl":[[5.1,19.76],[5.3,69.36]],"id":39213014}],"con":true,"img":false}]}
{"op":"mcm","clk":"5322676272","pt":1646322983021,"mc":[{"id":"1.195532867","rc":[{"atl":[[4.7,34.26]],"id":41529439}],"con":true,"img":false}]}
{"op":"mcm","clk":"5322676278","pt":1646322983125,"mc":[{"id":"1.195532867","rc":[{"atb":[[1.87,0]],"id":28791281},{"atl":[[4.5,0]],"id":41529439}],"con":true,"img":false}]}
{"op":"mcm","clk":"5322676362","pt":1646322984116,"mc":[{"id":"1.195532867","rc":[{"atl":[[6,3.47]],"id":43094640}],"con":true,"img":false}]}
{"op":"mcm","clk":"5322676390","pt":1646322984636,"mc":[{"id":"1.195532867","rc":[{"atl":[[6,0]],"id":43094640}],"con":true,"img":false}]}
{"op":"mcm","clk":"5322676486","pt":1646322985726,"mc":[{"id":"1.195532867","rc":[{"atb":[[1.94,31.32]],"id":28791281}],"con":true,"img":false}]}
{"op":"mcm","clk":"5322676503","pt":1646322985932,"mc":[{"id":"1.195532867","rc":[{"atb":[[1.91,11.04],[1.9,68.15]],"id":41529439}],"con":true,"img":false}]}
{"op":"mcm","clk":"5322676509","pt":1646322986029,"mc":[{"id":"1.195532867","rc":[{"atb":[[2.42,107.78]],"id":26648132},{"atl":[[6.8,6.9]],"id":26648132},{"atb":[[2.06,141.51],[1.65,0]],"id":43094640},{"atl":[[8.6,0],[9,0],[5.5,10],[5.7,46.69],[5.4,9.09]],"id":43094640},{"atb":[[1.75,250]],"id":28791281},{"atl":[[7.2,0],[4.3,12.12],[4.6,56.66],[6.8,0],[7.6,0],[4.4,11.76]],"id":28791281},{"atl":[[65,0],[11,4],[11.5,9.52],[48,0],[12.5,24],[55,0]],"id":35676762},{"atb":[[1.73,0],[1.91,164.84]],"id":39213014},{"atl":[[5.1,10],[5,10],[5.3,46.1]],"id":39213014}],"con":true,"img":false}]}
{"op":"mcm","clk":"5322676516","pt":1646322986134,"mc":[{"id":"1.195532867","rc":[{"atl":[[7.4,31.34],[7,10]],"id":26648132},{"atb":[[1.89,0],[1.95,31.32]],"id":28791281}],"con":true,"img":false}]}
{"op":"mcm","clk":"5322676551","pt":1646322986922,"mc":[{"id":"1.195532867","rc":[{"atb":[[1.98,2.15],[1.93,42.59]],"id":28791281}],"con":true,"img":false}]}
{"op":"mcm","clk":"5322676570","pt":1646322987229,"mc":[{"id":"1.195532867","rc":[{"atb":[[3.95,4.73]],"id":35676762}],"con":true,"img":false}]}
{"op":"mcm","clk":"5322676591","pt":1646322987438,"mc":[{"id":"1.195532867","rc":[{"atb":[[4.1,1.65]],"id":35676762}],"con":true,"img":false}]}
{"op":"mcm","clk":"5322676647","pt":1646322988218,"mc":[{"id":"1.195532867","rc":[{"atl":[[5.1,66.15],[4.7,13.31]],"id":41529439}],"con":true,"img":false}]}
{"op":"mcm","clk":"5322676771","pt":1646322990237,"mc":[{"id":"1.195532867","rc":[{"atl":[[4.8,10.53],[4.7,2.5]],"id":41529439}],"con":true,"img":false}]}
{"op":"mcm","clk":"5322676903","pt":1646322991950,"mc":[{"id":"1.195532867","rc":[{"atb":[[1.94,0]],"id":28791281}],"con":true,"img":false}]}
{"op":"mcm","clk":"5322676918","pt":1646322992116,"mc":[{"id":"1.195532867","rc":[{"atb":[[1.93,58.25]],"id":28791281}],"con":true,"img":false}]}
{"op":"mcm","clk":"5322676980","pt":1646322993046,"mc":[{"id":"1.195532867","rc":[{"atb":[[1.93,42.59]],"id":28791281}],"con":true,"img":false}]}
{"op":"mcm","clk":"5322677055","pt":1646322993834,"mc":[{"id":"1.195532867","rc":[{"atl":[[5.2,6.1]],"id":41529439}],"con":true,"img":false}]}
{"op":"mcm","clk":"5322677085","pt":1646322994146,"mc":[{"id":"1.195532867","rc":[{"atl":[[5.2,3.6]],"id":41529439}],"con":true,"img":false}]}
{"op":"mcm","clk":"5322677144","pt":1646322994926,"mc":[{"id":"1.195532867","rc":[{"atl":[[4.8,54.01],[5.1,29.39]],"id":41529439}],"con":true,"img":false}]}
{"op":"mcm","clk":"5322677149","pt":1646322995028,"mc":[{"id":"1.195532867","rc":[{"atb":[[1.93,90]],"id":28791281},{"atl":[[4.3,70.24],[4.6,5]],"id":28791281},{"atb":[[3.55,15.69]],"id":35676762},{"atl":[[11,21.46]],"id":35676762},{"atl":[[5.2,0]],"id":41529439},{"atb":[[2.14,11.18],[2.06,25.26]],"id":39213014}],"con":true,"img":false}]}
{"op":"mcm","clk":"5322677158","pt":1646322995137,"mc":[{"id":"1.195532867","rc":[{"atl":[[7.4,5],[6.8,41.76]],"id":26648132},{"atb":[[2.32,6.49]],"id":43094640},{"atl":[[5.7,5],[5.4,27.71]],"id":43094640},{"atb":[[1.98,30.6],[1.86,5]],"id":28791281},{"atb":[[3.85,16.55],[4.1,6.53]],"id":35676762},{"atl":[[12.5,5]],"id":35676762},{"atb":[[2.04,2.5]],"id":39213014},{"atl":[[5,34.42],[4.6,6.29],[5.3,5]],"id":39213014}],"con":true,"img":false}]}
{"op":"mcm","clk":"5322677168","pt":1646322995236,"mc":[{"id":"1.195532867","rc":[{"atl":[[4.4,0],[4.2,33.75]],"id":28791281},{"atl":[[10.5,12.02],[11.5,0]],"id":35676762},{"atb":[[2.12,2.15]],"id":39213014}],"con":true,"img":false}]}
{"op":"mcm","clk":"5322677174","pt":1646322995347,"mc":[{"id":"1.195532867","rc":[{"atl":[[6.6,16.26],[7,0]],"id":26648132},{"atb":[[2.3,2.15]],"id":43094640},{"atl":[[5.3,12.5],[5.5,0]],"id":43094640},{"atb":[[1.93,47.41]],"id":28791281},{"atb":[[3.95,0]],"id":35676762},{"atl":[[4.8,0],[5.1,0],[4.5,3.5]],"id":39213014}],"con":true,"img":false}]}
{"op":"mcm","clk":"5322677225","pt":1646322996022,"mc":[{"id":"1.195532867","rc":[{"atb":[[2.38,181.16]],"id":26648132},{"atl":[[7.2,16.13]],"id":26648132},{"atb":[[2.02,245.1],[1.67,0]],"id":43094640},{"atl":[[5.6,21.74]],"id":43094640},{"atl":[[4.5,28.57]],"id":28791281},{"atl":[[12,9.09]],"id":35676762},{"atb":[[1.89,250],[1.75,0]],"id":39213014},{"atl":[[5,24.42],[4.7,10.81]],"id":39213014}],"con":true,"img":false}]}
{"op":"mcm","clk":"5322677234","pt":1646322996124,"mc":[{"id":"1.195532867","rc":[{"atb":[[4,0]],"id":35676762}],"con":true,"img":false}]}
{"op":"mcm","clk":"5322677241","pt":1646322996232,"mc":[{"id":"1.195532867","rc":[{"atb":[[4.2,1.99]],"id":35676762}],"con":true,"img":false}]}
{"op":"mcm","clk":"5322677250","pt":1646322996336,"mc":[{"id":"1.195532867","rc":[{"atl":[[4.8,80.33],[5.1,5]],"id":41529439}],"con":true,"img":false}]}
{"op":"mcm","clk":"5322677257","pt":1646322996444,"mc":[{"id":"1.195532867","rc":[{"atl":[[5,32.08]],"id":39213014}],"con":true,"img":false}]}
{"op":"mcm","clk":"5322677266","pt":1646322996545,"mc":[{"id":"1.195532867","rc":[{"atb":[[1.91,40.11]],"id":28791281}],"con":true,"img":false}]}
{"op":"mcm","clk":"5322677306","pt":1646322997056,"mc":[{"id":"1.195532867","rc":[{"atl":[[5,24.42]],"id":39213014}],"con":true,"img":false}]}
{"op":"mcm","clk":"5322677436","pt":1646322998528,"mc":[{"id":"1.195532867","rc":[{"atb":[[2.14,8.28]],"id":39213014}],"con":true,"img":false}]}
{"op":"mcm","clk":"5322677598","pt":1646323000248,"mc":[{"id":"1.195532867","rc":[{"atl":[[5,25]],"id":41529439}],"con":true,"img":false}]}
{"op":"mcm","clk":"5322677607","pt":1646323000357,"mc":[{"id":"1.195532867","rc":[{"atl":[[4.3,100.54],[4.2,2.5]],"id":28791281},{"atl":[[10.5,2.5],[11,31.46]],"id":35676762}],"con":true,"img":false}]}
{"op":"mcm","clk":"5322677616","pt":1646323000456,"mc":[{"id":"1.195532867","rc":[{"atl":[[6.8,59]],"id":26648132},{"atl":[[5.4,49.45]],"id":43094640},{"atl":[[4.5,0],[4.7,21.62]],"id":39213014}],"con":true,"img":false}]}
{"op":"mcm","clk":"5322677623","pt":1646323000560,"mc":[{"id":"1.195532867","rc":[{"atl":[[6.6,2.5]],"id":26648132},{"atl":[[5.3,2.5]],"id":43094640},{"atb":[[1.91,0]],"id":28791281}],"con":true,"img":false}]}
{"op":"mcm","clk":"5322677795","pt":1646323002959,"mc":[{"id":"1.195532867","rc":[{"atb":[[2.08,10.93]],"id":39213014}],"con":true,"img":false}]}
{"op":"mcm","clk":"5322677803","pt":1646323003166,"mc":[{"id":"1.195532867","rc":[{"atb":[[3.85,5.64],[3.55,45.97]],"id":35676762}],"con":true,"img":false}]}
{"op":"mcm","clk":"5322677933","pt":1646323005151,"mc":[{"id":"1.195532867","rc":[{"atb":[[4.1,4.88]],"id":35676762}],"con":true,"img":false}]}
{"op":"mcm","clk":"5322677951","pt":1646323005389,"mc":[{"id":"1.195532867","rc":[{"atb":[[4.3,1.65]],"id":35676762}],"con":true,"img":false}]}
{"op":"mcm","clk":"5322677959","pt":1646323005465,"mc":[{"id":"1.195532867","rc":[{"atb":[[1.96,30.6]],"id":28791281}],"con":true,"img":false}]}
{"op":"mcm","clk":"5322677979","pt":1646323005672,"mc":[{"id":"1.195532867","rc":[{"atl":[[4.9,28.14],[4.7,10.81]],"id":39213014}],"con":true,"img":false}]}
{"op":"mcm","clk":"5322678019","pt":1646323006082,"mc":[{"id":"1.195532867","rc":[{"atb":[[2.22,0]],"id":26648132},{"atl":[[18,0],[7.6,22.73]],"id":26648132},{"atb":[[1.69,0]],"id":43094640},{"atl":[[5.8,31.25]],"id":43094640},{"atl":[[4.7,40.54]],"id":28791281},{"atl":[[13,12.5]],"id":35676762},{"atb":[[1.77,0]],"id":39213014},{"atl":[[4.8,15.93],[4.7,0]],"id":39213014}],"con":true,"img":false}]}
{"op":"mcm","clk":"5322678117","pt":1646323007138,"mc":[{"id":"1.195532867","rc":[{"atl":[[4.8,10.53]],"id":39213014}],"con":true,"img":false}]}
{"op":"mcm","clk":"5322678269","pt":1646323009374,"mc":[{"id":"1.195532867","rc":[{"atl":[[17,0]],"id":26648132}],"con":true,"img":false}]}
{"op":"mcm","clk":"5322678277","pt":1646323009478,"mc":[{"id":"1.195532867","rc":[{"atl":[[9.6,0]],"id":41529439}],"con":true,"img":false}]}
{"op":"mcm","clk":"5322678341","pt":1646323010262,"mc":[{"id":"1.195532867","rc":[{"atl":[[5.2,35.71]],"id":41529439}],"con":true,"img":false}]}
{"op":"mcm","clk":"5322678479","pt":1646323011971,"mc":[{"id":"1.195532867","rc":[{"atb":[[1.95,107.83],[1.93,0]],"id":28791281},{"atb":[[3.85,17.65],[3.55,15.69]],"id":35676762},{"atb":[[2.08,36.52],[2.06,10]],"id":39213014}],"con":true,"img":false}]}
{"op":"mcm","clk":"5322678490","pt":1646323012033,"mc":[{"id":"1.195532867","rc":[{"atb":[[4.3,7.07]],"id":35676762},{"atl":[[5,0],[4.9,69.08]],"id":39213014}],"con":true,"img":false}]}
{"op":"mcm","clk":"5322678504","pt":1646323012240,"mc":[{"id":"1.195532867","rc":[{"atb":[[4.1,0]],"id":35676762}],"con":true,"img":false}]}
{"op":"mcm","clk":"5322678515","pt":1646323012345,"mc":[{"id":"1.195532867","rc":[{"atb":[[4.2,0]],"id":35676762}],"con":true,"img":false}]}
{"op":"mcm","clk":"5322678526","pt":1646323012447,"mc":[{"id":"1.195532867","rc":[{"atb":[[2.18,56.85]],"id":43094640},{"atb":[[4.4,1.99]],"id":35676762}],"con":true,"img":false}]}
{"op":"mcm","clk":"5322678565","pt":1646323012974,"mc":[{"id":"1.195532867","rc":[{"atb":[[2.18,53.13]],"id":43094640}],"con":true,"img":false}]}
{"op":"mcm","clk":"5322678578","pt":1646323013074,"mc":[{"id":"1.195532867","rc":[{"atb":[[3.9,4.5]],"id":35676762}],"con":true,"img":false}]}
{"op":"mcm","clk":"5322678589","pt":1646323013284,"mc":[{"id":"1.195532867","rc":[{"atb":[[3.9,0]],"id":35676762}],"con":true,"img":false}]}
{"op":"mcm","clk":"5322678660","pt":1646323014165,"mc":[{"id":"1.195532867","rc":[{"atb":[[4.3,5.42]],"id":35676762}],"con":true,"img":false}]}
{"op":"mcm","clk":"5322678818","pt":1646323016054,"mc":[{"id":"1.195532867","rc":[{"atb":[[2.52,0],[2.6,0],[2.62,0],[2.68,10],[2.7,1.99]],"id":26648132},{"atl":[[8,35.71],[6.4,0],[8.2,0],[7.4,0],[6.8,33.6],[6.6,0]],"id":26648132},{"atb":[[2,0],[2.32,1.99],[2.08,0],[2.28,4.75],[2.18,21.92],[2.16,0]],"id":43094640},{"atl":[[6.2,0],[5.3,0],[5.5,7.5],[6,50],[5.2,0],[5.7,0],[5.4,30.83]],"id":43094640},{"atb":[[1.98,2.15],[1.95,31.31],[1.82,0],[1.88,4.16],[1.9,0],[1.86,0]],"id":28791281},{"atl":[[4.3,52.16],[4.6,0],[5,0],[4.1,0],[4.9,64.1],[4.2,0]],"id":28791281},{"atb":[[4.3,0],[3.85,5.64],[3.35,63.83]],"id":35676762},{"atl":[[10,0],[10.5,0],[11,14],[12.5,0],[14,19.23],[14.5,0]],"id":35676762},{"atb":[[1.87,7.1],[1.82,0],[1.99,23.64],[2.02,6.14],[1.9,0],[1.86,0]],"id":41529439},{"atl":[[4.8,36.85],[5.1,0],[4.6,0],[5.5,0],[4.7,0]],"id":41529439},{"atb":[[1.98,0],[2.04,0],[1.94,0],[2.14,1.99],[2.08,10.93]],"id":39213014},{"atl":[[4.6,0],[5,25],[5.3,0],[4.9,25.64],[5.7,0]],"id":39213014}],"con":true,"img":false}]}
{"op":"mcm","clk":"5322678835","pt":1646323016265,"mc":[{"id":"1.195532867","rc":[{"atb":[[2.6,4.17]],"id":26648132},{"atl":[[4.3,42.42]],"id":28791281},{"atb":[[4.4,0]],"id":35676762}],"con":true,"img":false}]}
{"op":"mcm","clk":"5322678841","pt":1646323016377,"mc":[{"id":"1.195532867","rc":[{"atb":[[3.9,1.99]],"id":35676762}],"con":true,"img":false}]}
{"op":"mcm","clk":"5322678849","pt":1646323016475,"mc":[{"id":"1.195532867","rc":[{"atb":[[2.6,0]],"id":26648132},{"atl":[[6.8,16.36],[7.6,37.88]],"id":26648132},{"atb":[[1.88,0]],"id":28791281},{"atl":[[4.3,12.12],[4.7,67.57]],"id":28791281},{"atb":[[3.45,81.64],[3.85,0],[3.5,9.8]],"id":35676762},{"atl":[[11,4],[13,20.83]],"id":35676762},{"atb":[[1.87,0]],"id":41529439},{"atb":[[2.06,13.32]],"id":39213014}],"con":true,"img":false}]}
{"op":"mcm","clk":"5322678862","pt":1646323016682,"mc":[{"id":"1.195532867","rc":[{"atl":[[4.8,10.53],[5.2,59.52]],"id":41529439},{"atl":[[5,50],[4.9,0]],"id":39213014}],"con":true,"img":false}]}
{"op":"mcm","clk":"5322678891","pt":1646323016985,"mc":[{"id":"1.195532867","rc":[{"atb":[[3.5,0]],"id":35676762},{"atb":[[2.06,10]],"id":39213014}],"con":true,"img":false}]}
{"op":"mcm","clk":"5322678895","pt":1646323017048,"mc":[{"id":"1.195532867","rc":[{"atb":[[3.9,0]],"id":35676762}],"con":true,"img":false}]}
{"op":"mcm","clk":"5322678908","pt":1646323017152,"mc":[{"id":"1.195532867","rc":[{"atb":[[3.6,1.99]],"id":35676762}],"con":true,"img":false}]}
{"op":"mcm","clk":"5322678912","pt":1646323017253,"mc":[{"id":"1.195532867","rc":[{"atl":[[6.8,6.9]],"id":26648132},{"atb":[[2.28,0]],"id":43094640},{"atl":[[5.5,0]],"id":43094640},{"atb":[[1.99,0]],"id":41529439}],"con":true,"img":false}]}
{"op":"mcm","clk":"5322678916","pt":1646323017363,"mc":[{"id":"1.195532867","rc":[{"atl":[[5.6,43.48],[5.4,9.09]],"id":43094640}],"con":true,"img":false}]}
{"op":"mcm","clk":"5322679010","pt":1646323018457,"mc":[{"id":"1.195532867","rc":[{"atb":[[1.96,0]],"id":28791281},{"atb":[[1.91,0]],"id":41529439}],"con":true,"img":false}]}
{"op":"mcm","clk":"5322679124","pt":1646323019964,"mc":[{"id":"1.195532867","rc":[{"atl":[[16,0],[7.2,9.78],[6.8,0]],"id":26648132},{"atl":[[5.6,30.44],[8.4,0],[5.4,0]],"id":43094640},{"atl":[[4.3,0],[4.5,11.43]],"id":28791281},{"atb":[[3.55,0],[3.5,16]],"id":35676762},{"atl":[[11,0],[12,3.64]],"id":35676762},{"atl":[[4.8,0],[5,10],[9.2,0]],"id":41529439},{"atl":[[4.8,0],[8,0],[5,35]],"id":39213014}],"con":true,"img":false}]}
{"op":"mcm","clk":"5322679139","pt":1646323020173,"mc":[{"id":"1.195532867","rc":[{"atl":[[7.2,6.45]],"id":26648132}],"con":true,"img":false}]}
{"op":"mcm","clk":"5322679175","pt":1646323020750,"mc":[{"id":"1.195532867","rc":[{"atb":[[3.6,0]],"id":35676762}],"con":true,"img":false}]}
{"op":"mcm","clk":"5322679185","pt":1646323020898,"mc":[{"id":"1.195532867","rc":[{"atb":[[3.55,1.99]],"id":35676762}],"con":true,"img":false}]}
{"op":"mcm","clk":"5322679240","pt":1646323021588,"mc":[{"id":"1.195532867","rc":[{"atl":[[5.7,5.44]],"id":43094640}],"con":true,"img":false}]}
{"op":"mcm","clk":"5322679248","pt":1646323021690,"mc":[{"id":"1.195532867","rc":[{"atl":[[8,50],[7.6,22.73]],"id":26648132},{"atl":[[4.9,89.74],[4.7,40.54]],"id":28791281},{"atl":[[13,12.5],[14,26.92]],"id":35676762}],"con":true,"img":false}]}
{"op":"mcm","clk":"5322679266","pt":1646323021901,"mc":[{"id":"1.195532867","rc":[{"atl":[[7.4,15.62],[5.2,35.71]],"id":41529439},{"atl":[[5,10],[6,20]],"id":39213014}],"con":true,"img":false}]}
{"op":"mcm","clk":"5322679288","pt":1646323022067,"mc":[{"id":"1.195532867","rc":[{"spn":4.96,"spf":"NaN","id":26648132},{"atl":[[5.7,0]],"id":43094640},{"spn":3.97,"spf":"NaN","id":43094640},{"spn":3.24,"spf":"NaN","id":28791281},{"spn":3.5,"spf":1.0,"id":35676762},{"spn":2.01,"spf":1.0,"id":41529439},{"spn":2.16,"spf":1.0,"id":39213014}],"con":true,"img":false}]}
{"op":"mcm","clk":"5322679296","pt":1646323022172,"mc":[{"id":"1.195532867","rc":[{"atb":[[3.6,1.65]],"id":35676762}],"con":true,"img":false}]}
{"op":"mcm","clk":"5322679304","pt":1646323022269,"mc":[{"id":"1.195532867","rc":[{"atl":[[7.2,0],[7.6,6.06]],"id":26648132},{"atl":[[5.6,21.74],[5.8,8.33]],"id":43094640},{"atl":[[4.5,0],[4.7,10.81]],"id":28791281},{"atb":[[3.45,57.15],[3.5,0]],"id":35676762},{"atl":[[12,0],[13,3.33]],"id":35676762},{"atl":[[5,0],[5.2,9.52]],"id":39213014}],"con":true,"img":false}]}
{"op":"mcm","clk":"5322679323","pt":1646323022477,"mc":[{"id":"1.195532867","rc":[{"atl":[[5.6,0]],"id":43094640},{"atl":[[12.5,4.09]],"id":35676762}],"con":true,"img":false}]}
{"op":"mcm","clk":"5322679335","pt":1646323022584,"mc":[{"id":"1.195532867","rc":[{"atl":[[6,70]],"id":43094640}],"con":true,"img":false}]}
{"op":"mcm","clk":"5322679356","pt":1646323022796,"mc":[{"id":"1.195532867","rc":[{"atl":[[12.5,0]],"id":35676762}],"con":true,"img":false}]}
{"op":"mcm","clk":"5322679373","pt":1646323022993,"mc":[{"id":"1.195532867","rc":[{"atb":[[3.55,0]],"id":35676762}],"con":true,"img":false}]}
{"op":"mcm","clk":"5322679382","pt":1646323023059,"mc":[{"id":"1.195532867","rc":[{"atb":[[3.5,1.99]],"id":35676762}],"con":true,"img":false}]}
{"op":"mcm","clk":"5322679393","pt":1646323023166,"mc":[{"id":"1.195532867","rc":[{"atb":[[1.82,44.51]],"id":28791281},{"atb":[[1.73,28.07]],"id":41529439}],"con":true,"img":false}]}
{"op":"mcm","clk":"5322679484","pt":1646323024259,"mc":[{"id":"1.195532867","rc":[{"atb":[[3.6,3.65],[3.45,16.33]],"id":35676762}],"con":true,"img":false}]}
{"op":"mcm","clk":"5322679524","pt":1646323024780,"mc":[{"id":"1.195532867","rc":[{"atb":[[3.5,0]],"id":35676762}],"con":true,"img":false}]}
{"op":"mcm","clk":"5322679532","pt":1646323024878,"mc":[{"id":"1.195532867","rc":[{"atb":[[3.65,1.99]],"id":35676762}],"con":true,"img":false}]}
{"op":"mcm","clk":"5322679664","pt":1646323026779,"mc":[{"id":"1.195532867","rc":[{"atl":[[4.9,64.1]],"id":28791281},{"atl":[[36,2.86]],"id":35676762}],"con":true,"img":false}]}
{"op":"mcm","clk":"5322679672","pt":1646323026883,"mc":[{"id":"1.195532867","rc":[{"atl":[[8,35.71],[13,8.33]],"id":26648132},{"atl":[[5.6,21.74]],"id":28791281},{"atl":[[14,19.23]],"id":35676762}],"con":true,"img":false}]}
{"op":"mcm","clk":"5322679746","pt":1646323027774,"mc":[{"id":"1.195532867","rc":[{"atl":[[7.4,15.62],[6,50]],"id":43094640}],"con":true,"img":false}]}
{"op":"mcm","clk":"5322679906","pt":1646323029992,"mc":[{"id":"1.195532867","rc":[{"atl":[[5,0],[5.2,9.52]],"id":41529439}],"con":true,"img":false}]}
{"op":"mcm","clk":"5322679913","pt":1646323030097,"mc":[{"id":"1.195532867","rc":[{"atl":[[5.3,5.95]],"id":41529439}],"con":true,"img":false}]}
{"op":"mcm","clk":"5322679921","pt":1646323030194,"mc":[{"id":"1.195532867","rc":[{"atb":[[3.6,2]],"id":35676762},{"atl":[[5.3,0]],"id":41529439}],"con":true,"img":false}]}
{"op":"mcm","clk":"5322679940","pt":1646323030364,"mc":[{"id":"1.195532867","rc":[{"atb":[[3.7,1.65]],"id":35676762}],"con":true,"img":false}]}
{"op":"mcm","clk":"5322680075","pt":1646323031969,"mc":[{"id":"1.195532867","rc":[{"atb":[[3.6,0],[3.7,3.65]],"id":35676762}],"con":true,"img":false}]}
{"op":"mcm","clk":"5322680108","pt":1646323032280,"mc":[{"id":"1.195532867","rc":[{"atl":[[8,5.71],[7.6,0]],"id":26648132},{"atl":[[5.8,0],[6,8]],"id":43094640},{"atl":[[5,7.69],[4.9,10.26],[4.7,0]],"id":28791281},{"atb":[[3.55,15.69]],"id":35676762},{"atl":[[13,0],[14,3.08]],"id":35676762},{"atl":[[5.4,22.73]],"id":39213014}],"con":true,"img":false}]}
{"op":"mcm","clk":"5322680123","pt":1646323032488,"mc":[{"id":"1.195532867","rc":[{"atl":[[5,6.41]],"id":28791281}],"con":true,"img":false}]}
{"op":"mcm","clk":"5322680138","pt":1646323032691,"mc":[{"id":"1.195532867","rc":[{"atl":[[5,0]],"id":28791281}],"con":true,"img":false}]}
{"op":"mcm","clk":"5322680149","pt":1646323032796,"mc":[{"id":"1.195532867","rc":[{"atb":[[3.65,0]],"id":35676762}],"con":true,"img":false}]}
{"op":"mcm","clk":"5322680157","pt":1646323032898,"mc":[{"id":"1.195532867","rc":[{"atb":[[3.75,1.99]],"id":35676762}],"con":true,"img":false}]}
{"op":"mcm","clk":"5322680310","pt":1646323035092,"mc":[{"id":"1.195532867","rc":[{"atl":[[5.4,5.82]],"id":41529439}],"con":true,"img":false}]}
{"op":"mcm","clk":"5322680329","pt":1646323035300,"mc":[{"id":"1.195532867","rc":[{"atl":[[5.4,0]],"id":41529439}],"con":true,"img":false}]}
{"op":"mcm","clk":"5322680466","pt":1646323036604,"mc":[{"id":"1.195532867","rc":[{"atl":[[5.6,0],[5.1,9.76],[6,20],[4.9,0]],"id":28791281},{"atb":[[3.55,0],[3.65,15.09]],"id":35676762},{"atl":[[14,0],[15,2.86]],"id":35676762},{"atb":[[2,28.07],[2.02,1.98]],"id":41529439},{"atl":[[5.2,0],[5.4,9.09]],"id":41529439},{"atl":[[5.2,0],[5.4,9.09]],"id":39213014}],"con":true,"img":false}]}
{"op":"mcm","clk":"5322680478","pt":1646323036658,"mc":[{"id":"1.195532867","rc":[{"atl":[[5.6,20.52],[6,0]],"id":28791281}],"con":true,"img":false}]}
{"op":"mcm","clk":"5322680497","pt":1646323036867,"mc":[{"id":"1.195532867","rc":[{"atl":[[5.6,0],[6,20]],"id":28791281}],"con":true,"img":false}]}
{"op":"mcm","clk":"5322680619","pt":1646323038171,"mc":[{"id":"1.195532867","rc":[{"atb":[[3.7,2]],"id":35676762}],"con":true,"img":false}]}
{"op":"mcm","clk":"5322680634","pt":1646323038378,"mc":[{"id":"1.195532867","rc":[{"atb":[[3.8,1.65]],"id":35676762}],"con":true,"img":false}]}
{"op":"mcm","clk":"5322680717","pt":1646323039685,"mc":[{"id":"1.195532867","rc":[{"atb":[[3.7,0],[3.8,3.65]],"id":35676762}],"con":true,"img":false}]}
{"op":"mcm","clk":"5322680732","pt":1646323039886,"mc":[{"id":"1.195532867","rc":[{"atb":[[1.73,0]],"id":41529439}],"con":true,"img":false}]}
{"op":"mcm","clk":"5322680743","pt":1646323039988,"mc":[{"id":"1.195532867","rc":[{"atb":[[3.75,0]],"id":35676762}],"con":true,"img":false}]}
{"op":"mcm","clk":"5322680753","pt":1646323040091,"mc":[{"id":"1.195532867","rc":[{"atb":[[3.85,1.99]],"id":35676762}],"con":true,"img":false}]}
{"op":"mcm","clk":"5322680942","pt":1646323042281,"mc":[{"id":"1.195532867","rc":[{"atl":[[8.4,13.51]],"id":26648132},{"atl":[[6.4,18.52]],"id":43094640},{"atl":[[5.5,4.54]],"id":39213014}],"con":true,"img":false}]}
{"op":"mcm","clk":"5322680950","pt":1646323042396,"mc":[{"id":"1.195532867","rc":[{"atl":[[6.2,5],[5.5,0]],"id":39213014}],"con":true,"img":false}]}
{"op":"mcm","clk":"5322680959","pt":1646323042491,"mc":[{"id":"1.195532867","rc":[{"atl":[[6.4,34.52],[7.4,0]],"id":43094640}],"con":true,"img":false}]}
{"op":"mcm","clk":"5322680982","pt":1646323042802,"mc":[{"id":"1.195532867","rc":[{"atl":[[6.2,0]],"id":39213014}],"con":true,"img":false}]}
{"op":"mcm","clk":"5322681106","pt":1646323044108,"mc":[{"id":"1.195532867","rc":[{"atb":[[1.73,13.12]],"id":41529439}],"con":true,"img":false}]}
{"op":"mcm","clk":"5322681284","pt":1646323046195,"mc":[{"id":"1.195532867","rc":[{"atb":[[3.8,2]],"id":35676762}],"con":true,"img":false}]}
{"op":"mcm","clk":"5322681299","pt":1646323046407,"mc":[{"id":"1.195532867","rc":[{"atb":[[3.9,1.65]],"id":35676762}],"con":true,"img":false}]}
{"op":"mcm","clk":"5322681312","pt":1646323046609,"mc":[{"id":"1.195532867","rc":[{"atl":[[5.1,0],[5.3,9.3]],"id":28791281},{"atb":[[3.55,39.22]],"id":35676762},{"atl":[[16,2.67],[15,0]],"id":35676762},{"atl":[[5.6,8.7],[5.4,0]],"id":41529439},{"atl":[[5.6,8.7],[5.4,0]],"id":39213014}],"con":true,"img":false}]}
{"op":"mcm","clk":"5322681324","pt":1646323046714,"mc":[{"id":"1.195532867","rc":[{"atl":[[5.6,19.52]],"id":28791281},{"atl":[[36,0],[40,2.56]],"id":35676762},{"atl":[[6.4,18.52],[6,0]],"id":39213014}],"con":true,"img":false}]}
{"op":"mcm","clk":"5322681335","pt":1646323046768,"mc":[{"id":"1.195532867","rc":[{"atl":[[6,0]],"id":28791281}],"con":true,"img":false}]}
{"op":"mcm","clk":"5322681362","pt":1646323047189,"mc":[{"id":"1.195532867","rc":[{"atb":[[3.85,5.31],[3.8,0]],"id":35676762}],"con":true,"img":false}]}
{"op":"mcm","clk":"5322681389","pt":1646323047705,"mc":[{"id":"1.195532867","rc":[{"atl":[[6.4,18.52],[7.6,15.15]],"id":43094640}],"con":true,"img":false}]}
{"op":"mcm","clk":"5322681517","pt":1646323049271,"mc":[{"id":"1.195532867","rc":[{"atl":[[6.2,5]],"id":28791281}],"con":true,"img":false}]}
{"op":"mcm","clk":"5322681548","pt":1646323049685,"mc":[{"id":"1.195532867","rc":[{"atl":[[6.2,0]],"id":28791281}],"con":true,"img":false}]}
{"op":"mcm","clk":"5322681619","pt":1646323050519,"mc":[{"id":"1.195532867","rc":[{"atb":[[1.73,0]],"id":41529439}],"con":true,"img":false}]}
{"op":"mcm","clk":"5322681698","pt":1646323051917,"mc":[{"id":"1.195532867","rc":[{"atl":[[5.6,0],[6,20]],"id":28791281}],"con":true,"img":false}]}
{"op":"mcm","clk":"5322681723","pt":1646323052290,"mc":[{"id":"1.195532867","rc":[{"atl":[[8,0],[8.4,5.41]],"id":26648132},{"atl":[[6.4,7.41],[6,0]],"id":43094640}],"con":true,"img":false}]}
{"op":"mcm","clk":"5322681736","pt":1646323052494,"mc":[{"id":"1.195532867","rc":[{"atl":[[13.5,4.16]],"id":26648132},{"atl":[[6.2,5.19]],"id":43094640}],"con":true,"img":false}]}
{"op":"mcm","clk":"5322681740","pt":1646323052597,"mc":[{"id":"1.195532867","rc":[{"atl":[[13.5,0]],"id":26648132},{"atl":[[7.6,0],[6,7.41]],"id":43094640}],"con":true,"img":false}]}
{"op":"mcm","clk":"5322681756","pt":1646323052909,"mc":[{"id":"1.195532867","rc":[{"atl":[[6.2,0]],"id":43094640}],"con":true,"img":false}]}
{"op":"mcm","clk":"5322681768","pt":1646323053115,"mc":[{"id":"1.195532867","rc":[{"atb":[[1.8,3.92]],"id":28791281}],"con":true,"img":false}]}
{"op":"mcm","clk":"5322681783","pt":1646323053376,"mc":[{"id":"1.195532867","rc":[{"atb":[[1.8,0]],"id":28791281}],"con":true,"img":false}]}
{"op":"mcm","clk":"5322681896","pt":1646323054884,"mc":[{"id":"1.195532867","rc":[{"atb":[[1.73,13.12]],"id":41529439}],"con":true,"img":false}]}
{"op":"mcm","clk":"5322682020","pt":1646323056600,"mc":[{"id":"1.195532867","rc":[{"atl":[[7,4.31]],"id":43094640},{"atl":[[5.3,0],[5.5,8.89]],"id":28791281},{"atb":[[3.45,61.22],[3.25,0]],"id":35676762},{"atl":[[16,0],[17,2.5]],"id":35676762},{"atl":[[5.6,0],[5.8,8.33]],"id":41529439},{"atl":[[5.6,0],[5.8,8.33]],"id":39213014}],"con":true,"img":false}]}
{"op":"mcm","clk":"5322682047","pt":1646323056916,"mc":[{"id":"1.195532867","rc":[{"atl":[[7,0]],"id":43094640}],"con":true,"img":false}]}
{"op":"mcm","clk":"5322682129","pt":1646323057705,"mc":[{"id":"1.195532867","rc":[{"atl":[[7.6,14.82]],"id":43094640}],"con":true,"img":false}]}
{"op":"mcm","clk":"5322682136","pt":1646323057802,"mc":[{"id":"1.195532867","rc":[{"atl":[[6,0]],"id":43094640}],"con":true,"img":false}]}
{"op":"mcm","clk":"5322682495","pt":1646323062326,"mc":[{"id":"1.195532867","rc":[{"atl":[[8.8,5.13],[8.4,0]],"id":26648132},{"atl":[[6.4,0],[6.8,6.9]],"id":43094640}],"con":true,"img":false}]}
{"op":"mcm","clk":"5322682503","pt":1646323062430,"mc":[{"id":"1.195532867","rc":[{"atl":[[6.8,21.72],[7.6,0]],"id":43094640}],"con":true,"img":false}]}
{"op":"mcm","clk":"5322682509","pt":1646323062490,"mc":[{"id":"1.195532867","rc":[{"atl":[[6.8,6.9],[7.6,13.8]],"id":43094640}],"con":true,"img":false}]}
{"op":"mcm","clk":"5322682619","pt":1646323064102,"mc":[{"id":"1.195532867","rc":[{"atl":[[8,3.68]],"id":41529439}],"con":true,"img":false}]}
{"op":"mcm","clk":"5322682635","pt":1646323064307,"mc":[{"id":"1.195532867","rc":[{"atl":[[8,0]],"id":41529439}],"con":true,"img":false}]}
{"op":"mcm","clk":"5322682793","pt":1646323066611,"mc":[{"id":"1.195532867","rc":[{"atl":[[5.7,21.28]],"id":28791281},{"atb":[[3.35,106.38],[3.3,6.63]],"id":35676762},{"atl":[[18,5.88]],"id":35676762},{"atl":[[5.8,0],[6,8]],"id":41529439},{"atl":[[6,20]],"id":39213014}],"con":true,"img":false}]}
{"op":"mcm","clk":"5322682808","pt":1646323066821,"mc":[{"id":"1.195532867","rc":[{"atb":[[3.3,0]],"id":35676762}],"con":true,"img":false}]}
{"op":"mcm","clk":"5322683018","pt":1646323069442,"mc":[{"id":"1.195532867","rc":[{"atl":[[9.2,4.88],[8.8,0]],"id":26648132},{"atl":[[7.2,6.45],[6.8,0]],"id":43094640},{"atl":[[5.5,0],[5.7,8.51]],"id":28791281},{"atl":[[17,0],[18,2.35]],"id":35676762},{"atl":[[5.8,0],[6,8]],"id":39213014}],"con":true,"img":false}]}
{"op":"mcm","clk":"5322683024","pt":1646323069504,"mc":[{"id":"1.195532867","rc":[{"atl":[[13,0],[14,7.69]],"id":26648132}],"con":true,"img":false}]}
{"op":"mcm","clk":"5322683055","pt":1646323069810,"mc":[{"id":"1.195532867","rc":[{"atb":[[1.73,0]],"id":41529439}],"con":true,"img":false}]}
{"op":"mcm","clk":"5322683384","pt":1646323074506,"mc":[{"id":"1.195532867","rc":[{"atb":[[1.73,13.12]],"id":41529439}],"con":true,"img":false}]}
{"op":"mcm","clk":"5322683480","pt":1646323076019,"mc":[{"id":"1.195532867","rc":[{"atb":[[2.52,65.79],[2.66,6.98],[2.68,0]],"id":26648132},{"atl":[[9,3.2]],"id":26648132},{"atb":[[2.18,26.27]],"id":43094640},{"atl":[[7.6,0],[8.4,13.51]],"id":43094640},{"atb":[[1.9,27.47],[1.95,0],[1.87,49.38]],"id":28791281},{"atl":[[6,0],[6.8,17.24]],"id":28791281},{"atb":[[3.85,1.99],[3.55,78.44]],"id":35676762},{"atl":[[8.6,13.16],[7.4,0],[6.8,4.38]],"id":41529439},{"atb":[[2.06,0],[1.98,102.04],[2.04,12.7]],"id":39213014},{"atl":[[6.4,4.81],[7,16.67]],"id":39213014}],"con":true,"img":false}]}
{"op":"mcm","clk":"5322683486","pt":1646323076122,"mc":[{"id":"1.195532867","rc":[{"atl":[[6.6,4.63]],"id":39213014}],"con":true,"img":false}]}
{"op":"mcm","clk":"5322683493","pt":1646323076228,"mc":[{"id":"1.195532867","rc":[{"atb":[[2.66,0]],"id":26648132},{"atb":[[2.18,21.92]],"id":43094640},{"atb":[[1.9,0]],"id":28791281},{"atl":[[6.8,0]],"id":41529439},{"atb":[[2.04,0]],"id":39213014},{"atl":[[6.4,0]],"id":39213014}],"con":true,"img":false}]}
{"op":"mcm","clk":"5322683499","pt":1646323076329,"mc":[{"id":"1.195532867","rc":[{"atl":[[6.6,0]],"id":39213014}],"con":true,"img":false}]}
{"op":"mcm","clk":"5322683517","pt":1646323076645,"mc":[{"id":"1.195532867","rc":[{"atb":[[2.48,6.49]],"id":26648132},{"atl":[[9,0]],"id":26648132},{"atl":[[6.2,5]],"id":28791281},{"atl":[[6.4,7.41],[6,0]],"id":41529439}],"con":true,"img":false}]}
{"op":"mcm","clk":"5322683538","pt":1646323076953,"mc":[{"id":"1.195532867","rc":[{"atb":[[2.7,0]],"id":26648132}],"con":true,"img":false}]}
{"op":"mcm","clk":"5322683544","pt":1646323077010,"mc":[{"id":"1.195532867","rc":[{"atb":[[2.54,1.99],[2.42,105.63],[2.58,2.15]],"id":26648132},{"atb":[[1.98,0],[1.9,2.15]],"id":28791281},{"atl":[[6.2,0]],"id":28791281}],"con":true,"img":false}]}
{"op":"mcm","clk":"5322683552","pt":1646323077162,"mc":[{"id":"1.195532867","rc":[{"atb":[[2.48,0]],"id":26648132}],"con":true,"img":false}]}
{"op":"mcm","clk":"5322683556","pt":1646323077217,"mc":[{"id":"1.195532867","rc":[{"atb":[[3.85,0]],"id":35676762}],"con":true,"img":false}]}
{"op":"mcm","clk":"5322683565","pt":1646323077319,"mc":[{"id":"1.195532867","rc":[{"atb":[[3.7,1.99]],"id":35676762}],"con":true,"img":false}]}
{"op":"mcm","clk":"5322683615","pt":1646323078258,"mc":[{"id":"1.195532867","rc":[{"atb":[[2.72,0],[2.54,0]],"id":26648132},{"atb":[[3.9,0]],"id":35676762}],"con":true,"img":false}]}
{"op":"mcm","clk":"5322683621","pt":1646323078303,"mc":[{"id":"1.195532867","rc":[{"atb":[[2.6,1.99]],"id":26648132}],"con":true,"img":false}]}
{"op":"mcm","clk":"5322683627","pt":1646323078410,"mc":[{"id":"1.195532867","rc":[{"atb":[[2.6,3.64]],"id":26648132},{"atb":[[3.75,1.65]],"id":35676762}],"con":true,"img":false}]}
{"op":"mcm","clk":"5322683651","pt":1646323078833,"mc":[{"id":"1.195532867","rc":[{"atb":[[2.08,0]],"id":39213014}],"con":true,"img":false}]}
{"op":"mcm","clk":"5322683685","pt":1646323079444,"mc":[{"id":"1.195532867","rc":[{"atl":[[9.6,4.65],[9.2,0]],"id":26648132},{"atl":[[7.2,0],[7.6,6.06]],"id":43094640},{"atl":[[5.7,0],[5.9,8.16]],"id":28791281},{"atl":[[18,0],[19,2.22]],"id":35676762},{"atl":[[6.4,7.41],[6,0]],"id":39213014}],"con":true,"img":false}]}
{"op":"mcm","clk":"5322683809","pt":1646323080912,"mc":[{"id":"1.195532867","rc":[{"atb":[[1.73,0]],"id":41529439}],"con":true,"img":false}]}
{"op":"mcm","clk":"5322683826","pt":1646323081124,"mc":[{"id":"1.195532867","rc":[{"atl":[[9.6,0],[10,4.44]],"id":26648132},{"atl":[[8,5.71],[7.6,0]],"id":43094640},{"atl":[[6.2,7.69],[6,4.08],[5.9,0]],"id":28791281},{"atl":[[19,0],[20,2.11]],"id":35676762},{"atl":[[6.4,0],[6.8,6.9]],"id":41529439},{"atl":[[6.4,0],[6.8,6.9]],"id":39213014}],"con":true,"img":false}]}
{"op":"mcm","clk":"5322683835","pt":1646323081229,"mc":[{"id":"1.195532867","rc":[{"atl":[[9.8,4.44],[14,0]],"id":26648132},{"atl":[[20,4.67]],"id":35676762}],"con":true,"img":false}]}
{"op":"mcm","clk":"5322683846","pt":1646323081336,"mc":[{"id":"1.195532867","rc":[{"atl":[[40,0]],"id":35676762}],"con":true,"img":false}]}
{"op":"mcm","clk":"5322683856","pt":1646323081437,"mc":[{"id":"1.195532867","rc":[{"atl":[[9.8,0],[14,7.69]],"id":26648132},{"atl":[[6,0]],"id":28791281},{"atl":[[20,2.11],[44,2.33]],"id":35676762},{"atb":[[1.01,4805.04]],"id":41529439}],"con":true,"img":false}]}
{"op":"mcm","clk":"5322683865","pt":1646323081544,"mc":[{"id":"1.195532867","rc":[{"atb":[[2.74,2.5],[2.52,75.9],[2.6,9.71],[2.66,5],[2.58,12.15]],"id":26648132},{"atl":[[8,10],[9.6,6.07],[7.2,5],[6.4,2.5],[10,0],[10.5,4.21],[46,9.49]],"id":26648132},{"atb":[[1.99,101.01],[2.3,7.15],[2.22,10],[2.38,2.5],[2.18,11.7]],"id":43094640},{"atl":[[6.2,10],[5.3,2.5],[8.2,3.11],[46,9.49],[5.7,5]],"id":43094640},{"atb":[[1.82,75.67],[1.7,142.86],[1.87,0]],"id":28791281},{"atl":[[4,2.5],[4.8,10],[6.8,63.06],[6,8.83],[4.4,5]],"id":28791281},{"atb":[[3.55,88.84]],"id":35676762},{"atl":[[20,0],[9.2,2.5],[10,5],[22,1.9],[46,9.49],[12,10]],"id":35676762},{"atb":[[1.79,26.8],[2.02,8.66],[1.98,10],[2.04,6.65],[2.12,2.5]],"id":41529439},{"atl":[[4.8,2.5],[5.6,10],[5.2,5],[8.8,48.22],[8.4,6.67]],"id":41529439},{"atb":[[2,2.5],[1.98,130.83],[2.14,5.1]],"id":39213014},{"atl":[[4.8,2.5],[5.6,10],[7.2,59.4],[6.8,10.01],[5.2,5]],"id":39213014}],"con":true,"img":false}]}
{"op":"mcm","clk":"5322683875","pt":1646323081649,"mc":[{"id":"1.195532867","rc":[{"atb":[[3.7,5.97]],"id":35676762},{"atl":[[19.5,3.98],[48,3.87]],"id":35676762},{"atb":[[1.71,11.11]],"id":41529439}],"con":true,"img":false}]}
{"op":"mcm","clk":"5322683886","pt":1646323081759,"mc":[{"id":"1.195532867","rc":[{"atl":[[6.8,6.9]],"id":26648132},{"atb":[[2.18,0]],"id":43094640},{"atl":[[5.5,8.89]],"id":43094640},{"atl":[[4.2,12.5]],"id":28791281},{"atl":[[9.6,4.65]],"id":35676762},{"atb":[[1.71,0]],"id":41529439},{"atl":[[5,10]],"id":41529439},{"atl":[[5,10]],"id":39213014}],"con":true,"img":false}]}
{"op":"mcm","clk":"5322683910","pt":1646323082018,"mc":[{"id":"1.195532867","rc":[{"atl":[[48,0]],"id":35676762},{"atb":[[2,33.07]],"id":41529439}],"con":true,"img":false}]}
{"op":"mcm","clk":"5322683916","pt":1646323082121,"mc":[{"id":"1.195532867","rc":[{"spn":4.57,"spf":"NaN","id":26648132},{"spn":3.84,"spf":"NaN","id":43094640},{"spn":2.95,"spf":"NaN","id":28791281},{"spn":3.69,"spf":1.0,"id":35676762},{"atb":[[2,28.07],[2.02,6.67]],"id":41529439},{"spn":2.06,"spf":1.0,"id":41529439}],"con":true,"img":false}]}
{"op":"mcm","clk":"5322683923","pt":1646323082225,"mc":[{"id":"1.195532867","rc":[{"atb":[[1.02,1.99]],"id":41529439}],"con":true,"img":false}]}
{"op":"mcm","clk":"5322683931","pt":1646323082330,"mc":[{"id":"1.195532867","rc":[{"atb":[[2.6,7.72]],"id":26648132}],"con":true,"img":false}]}
{"op":"mcm","clk":"5322683935","pt":1646323082435,"mc":[{"id":"1.195532867","rc":[{"atb":[[2.76,1.99]],"id":26648132}],"con":true,"img":false}]}
{"op":"mcm","clk":"5322683954","pt":1646323082746,"mc":[{"id":"1.195532867","rc":[{"atb":[[2.32,0]],"id":43094640}],"con":true,"img":false}]}
{"op":"mcm","clk":"5322683961","pt":1646323082847,"mc":[{"id":"1.195532867","rc":[{"atb":[[2.4,1.99]],"id":43094640}],"con":true,"img":false}]}
{"op":"mcm","clk":"5322683995","pt":1646323083217,"mc":[{"id":"1.195532867","rc":[{"atb":[[2.72,7.73]],"id":26648132},{"atl":[[5.7,16.39],[8.4,0]],"id":43094640},{"atl":[[6.8,45.82],[4.4,20]],"id":28791281},{"atb":[[3.7,21.06],[3.55,49.62]],"id":35676762},{"atl":[[8.6,0],[5.2,17.5]],"id":41529439},{"atb":[[1.98,28.79],[2.08,42.11]],"id":39213014},{"atl":[[5.2,17.5],[7,0]],"id":39213014}],"con":true,"img":false}]}
{"op":"mcm","clk":"5322684001","pt":1646323083319,"mc":[{"id":"1.195532867","rc":[{"atb":[[2.52,10.11]],"id":26648132}],"con":true,"img":false}]}
{"op":"mcm","clk":"5322684014","pt":1646323083528,"mc":[{"id":"1.195532867","rc":[{"atb":[[1.73,13.12]],"id":41529439},{"atb":[[1.96,6.92]],"id":39213014}],"con":true,"img":false}]}
{"op":"mcm","clk":"5322684165","pt":1646323085558,"mc":[{"id":"1.195532867","rc":[{"atl":[[6.4,6.71]],"id":26648132}],"con":true,"img":false}]}
{"op":"mcm","clk":"5322684196","pt":1646323085928,"mc":[{"id":"1.195532867","rc":[{"atl":[[6.4,2.5]],"id":26648132}],"con":true,"img":false}]}
{"op":"mcm","clk":"5322684215","pt":1646323086137,"mc":[{"id":"1.195532867","rc":[{"atb":[[2.6,6.07]],"id":26648132},{"atb":[[2.34,0]],"id":43094640},{"atb":[[2.04,5]],"id":41529439}],"con":true,"img":false}]}
{"op":"mcm","clk":"5322684228","pt":1646323086242,"mc":[{"id":"1.195532867","rc":[{"atl":[[4.1,26.86]],"id":28791281}],"con":true,"img":false}]}
{"op":"mcm","clk":"5322684239","pt":1646323086344,"mc":[{"id":"1.195532867","rc":[{"atb":[[2.78,1.65]],"id":26648132},{"atb":[[2.42,1.65]],"id":43094640},{"atl":[[4,15]],"id":28791281},{"atb":[[2.14,1.65]],"id":41529439}],"con":true,"img":false}]}
{"op":"mcm","clk":"5322684251","pt":1646323086448,"mc":[{"id":"1.195532867","rc":[{"atl":[[4.4,5]],"id":28791281}],"con":true,"img":false}]}
{"op":"mcm","clk":"5322684257","pt":1646323086554,"mc":[{"id":"1.195532867","rc":[{"atb":[[2.72,0],[2.7,6.07]],"id":26648132},{"atb":[[3.7,5.97],[3.55,88.84]],"id":35676762},{"atb":[[2.1,28.79],[2.08,0]],"id":39213014}],"con":true,"img":false}]}
{"op":"mcm","clk":"5322684270","pt":1646323086658,"mc":[{"id":"1.195532867","rc":[{"atl":[[4.1,0]],"id":28791281}],"con":true,"img":false}]}
{"op":"mcm","clk":"5322684291","pt":1646323086867,"mc":[{"id":"1.195532867","rc":[{"atl":[[4,2.5],[4.4,32.5]],"id":28791281}],"con":true,"img":false}]}
{"op":"mcm","clk":"5322684302","pt":1646323086924,"mc":[{"id":"1.195532867","rc":[{"atl":[[3.95,3.97]],"id":28791281}],"con":true,"img":false}]}
{"op":"mcm","clk":"5322684311","pt":1646323087026,"mc":[{"id":"1.195532867","rc":[{"atl":[[4.4,5],[3.9,3.97]],"id":28791281}],"con":true,"img":false}]}
{"op":"mcm","clk":"5322684358","pt":1646323087548,"mc":[{"id":"1.195532867","rc":[{"atb":[[1.85,2.15],[1.9,0]],"id":28791281},{"atb":[[2.08,2.15],[1.79,24.65]],"id":41529439}],"con":true,"img":false}]}
{"op":"mcm","clk":"5322684369","pt":1646323087654,"mc":[{"id":"1.195532867","rc":[{"atb":[[1.85,8.11]],"id":28791281}],"con":true,"img":false}]}
{"op":"mcm","clk":"5322684382","pt":1646323087758,"mc":[{"id":"1.195532867","rc":[{"atb":[[1.73,0]],"id":41529439},{"atb":[[1.96,0]],"id":39213014}],"con":true,"img":false}]}
{"op":"mcm","clk":"5322684422","pt":1646323088155,"mc":[{"id":"1.195532867","rc":[{"atl":[[7.4,4.03]],"id":43094640}],"con":true,"img":false}]}
{"op":"mcm","clk":"5322684428","pt":1646323088262,"mc":[{"id":"1.195532867","rc":[{"atl":[[7.4,0]],"id":43094640}],"con":true,"img":false}]}
{"op":"mcm","clk":"5322684461","pt":1646323088530,"mc":[{"id":"1.195532867","rc":[{"atl":[[14,0]],"id":26648132},{"atl":[[10,12.15],[44,0]],"id":35676762}],"con":true,"img":false}]}
{"op":"mcm","clk":"5322684468","pt":1646323088633,"mc":[{"id":"1.195532867","rc":[{"atl":[[7.2,14.4]],"id":26648132},{"atb":[[1.82,44.51],[1.81,64.49],[1.7,0],[1.78,8.32],[1.75,383.33]],"id":28791281},{"atb":[[3.65,24.35]],"id":35676762}],"con":true,"img":false}]}
{"op":"mcm","clk":"5322684479","pt":1646323088738,"mc":[{"id":"1.195532867","rc":[{"atb":[[1.78,0]],"id":28791281}],"con":true,"img":false}]}
{"op":"mcm","clk":"5322684537","pt":1646323089357,"mc":[{"id":"1.195532867","rc":[{"atb":[[3.65,15.09]],"id":35676762}],"con":true,"img":false}]}
{"op":"mcm","clk":"5322684647","pt":1646323090659,"mc":[{"id":"1.195532867","rc":[{"atl":[[4,15.83]],"id":28791281}],"con":true,"img":false}]}
{"op":"mcm","clk":"5322684806","pt":1646323092440,"mc":[{"id":"1.195532867","rc":[{"atb":[[2.06,4.58]],"id":41529439},{"atb":[[2.02,9.46]],"id":39213014}],"con":true,"img":false}]}
{"op":"mcm","clk":"5322684822","pt":1646323092650,"mc":[{"id":"1.195532867","rc":[{"atl":[[7.2,30.53]],"id":26648132},{"atl":[[5.7,37.67]],"id":43094640},{"atl":[[10,23.26]],"id":35676762},{"atl":[[5.2,41.31]],"id":41529439},{"atl":[[5.2,41.31]],"id":39213014}],"con":true,"img":false}]}
{"op":"mcm","clk":"5322684846","pt":1646323092964,"mc":[{"id":"1.195532867","rc":[{"atl":[[3.95,0]],"id":28791281}],"con":true,"img":false}]}
{"op":"mcm","clk":"5322684861","pt":1646323093170,"mc":[{"id":"1.195532867","rc":[{"atl":[[3.9,0],[4.2,32.3]],"id":28791281}],"con":true,"img":false}]}
{"op":"mcm","clk":"5322684882","pt":1646323093380,"mc":[{"id":"1.195532867","rc":[{"atl":[[4.4,34.41],[4.2,12.5]],"id":28791281}],"con":true,"img":false}]}
{"op":"mcm","clk":"5322684934","pt":1646323094058,"mc":[{"id":"1.195532867","rc":[{"atb":[[1.08,50]],"id":26648132},{"atb":[[1.08,50]],"id":43094640},{"atb":[[1.08,50]],"id":28791281},{"atb":[[1.08,50]],"id":35676762},{"atb":[[1.08,50]],"id":41529439},{"atb":[[1.08,50]],"id":39213014}],"con":true,"img":false}]}
{"op":"mcm","clk":"5322685118","pt":1646323096569,"mc":[{"id":"1.195532867","rc":[{"atl":[[5.8,5.32]],"id":43094640}],"con":true,"img":false}]}
{"op":"mcm","clk":"5322685134","pt":1646323096778,"mc":[{"id":"1.195532867","rc":[{"atb":[[2.76,5.74],[2.52,0],[2.7,18.22]],"id":26648132},{"atl":[[7.2,49.97],[6.2,3.75],[46,2.73],[7.4,4.03]],"id":26648132},{"atl":[[5.8,0],[46,2.73],[5.2,3.75],[5.7,59.29]],"id":43094640},{"atl":[[3.95,27.12],[6.8,0],[4.4,107.7]],"id":28791281},{"atb":[[3.9,7.97]],"id":35676762},{"atl":[[9,7.97],[10,55.5],[46,2.73]],"id":35676762},{"atb":[[2.12,6.25],[1.79,0],[2.06,15.5]],"id":41529439},{"atl":[[5.2,58.79],[8.8,12.82],[4.7,3.75]],"id":41529439},{"atb":[[1.98,0],[2.1,49.74]],"id":39213014},{"atl":[[7.2,16.13],[5.2,74.83],[4.7,5.7]],"id":39213014}],"con":true,"img":false}]}
{"op":"mcm","clk":"5322685140","pt":1646323096876,"mc":[{"id":"1.195532867","rc":[{"atl":[[6.8,16.9]],"id":26648132},{"atl":[[8.2,0],[5.7,47.9]],"id":43094640},{"atl":[[6,0]],"id":28791281},{"atb":[[3.7,1.99]],"id":35676762},{"atl":[[19.5,0]],"id":35676762},{"atb":[[2.02,0]],"id":41529439},{"atl":[[5,20],[5.2,46.29]],"id":41529439}],"con":true,"img":false}]}
{"op":"mcm","clk":"5322685147","pt":1646323096982,"mc":[{"id":"1.195532867","rc":[{"atb":[[2.6,0]],"id":26648132},{"atl":[[9.6,0],[7.2,40.57]],"id":26648132},{"atl":[[5.5,17.78]],"id":43094640},{"atb":[[3.55,78.44],[3.65,34.59]],"id":35676762},{"atl":[[9.6,14.65],[10,48.35]],"id":35676762},{"atl":[[8.4,0]],"id":41529439},{"atl":[[5,20],[6.8,6.9],[5.2,62.33]],"id":39213014}],"con":true,"img":false}]}
{"op":"mcm","clk":"5322685174","pt":1646323097259,"mc":[{"id":"1.195532867","rc":[{"atl":[[7.4,0]],"id":26648132}],"con":true,"img":false}]}
{"op":"mcm","clk":"5322685181","pt":1646323097360,"mc":[{"id":"1.195532867","rc":[{"atb":[[3.7,0]],"id":35676762}],"con":true,"img":false}]}
{"op":"mcm","clk":"5322685185","pt":1646323097464,"mc":[{"id":"1.195532867","rc":[{"atl":[[6.6,7.14]],"id":26648132},{"atl":[[5.4,9.09]],"id":43094640},{"atl":[[4,2.5],[4.1,12.9]],"id":28791281},{"atb":[[3.95,1.99]],"id":35676762},{"atl":[[9.4,4.76]],"id":35676762},{"atl":[[5.1,7.62],[5,10],[4.9,10.26]],"id":41529439},{"atl":[[7.2,0],[5,10],[6.8,0],[7.6,0],[5.2,38.52],[4.9,10.26]],"id":39213014}],"con":true,"img":false}]}
{"op":"mcm","clk":"5322685219","pt":1646323097854,"mc":[{"id":"1.195532867","rc":[{"atl":[[5.1,0]],"id":41529439}],"con":true,"img":false}]}
{"op":"mcm","clk":"5322685225","pt":1646323097946,"mc":[{"id":"1.195532867","rc":[{"atl":[[3.95,35.12]],"id":28791281}],"con":true,"img":false}]}
{"op":"mcm","clk":"5322685409","pt":1646323100386,"mc":[{"id":"1.195532867","rc":[{"atl":[[4.4,78.29],[3.9,12.9]],"id":28791281}],"con":true,"img":false}]}
{"op":"mcm","clk":"5322685465","pt":1646323101170,"mc":[{"id":"1.195532867","rc":[{"atb":[[2.02,0]],"id":39213014}],"con":true,"img":false}]}
{"op":"mcm","clk":"5322685604","pt":1646323103050,"mc":[{"id":"1.195532867","rc":[{"atl":[[4,15.83]],"id":28791281}],"con":true,"img":false}]}
{"op":"mcm","clk":"5322685650","pt":1646323103984,"mc":[{"id":"1.195532867","rc":[{"atb":[[3.55,100.85],[3.65,15.09]],"id":35676762}],"con":true,"img":false}]}
{"op":"mcm","clk":"5322685672","pt":1646323104285,"mc":[{"id":"1.195532867","rc":[{"atb":[[3.75,0]],"id":35676762}],"con":true,"img":false}]}
{"op":"mcm","clk":"5322685686","pt":1646323104455,"mc":[{"id":"1.195532867","rc":[{"atb":[[4,1.65]],"id":35676762}],"con":true,"img":false}]}
{"op":"mcm","clk":"5322685792","pt":1646323105498,"mc":[{"id":"1.195532867","rc":[{"atb":[[2.02,9.46]],"id":39213014}],"con":true,"img":false}]}
{"op":"mcm","clk":"5322685837","pt":1646323105976,"mc":[{"id":"1.195532867","rc":[{"atl":[[3.95,27.12]],"id":28791281}],"con":true,"img":false}]}
{"op":"mcm","clk":"5322685853","pt":1646323106185,"mc":[{"id":"1.195532867","rc":[{"atl":[[4,49.16]],"id":28791281}],"con":true,"img":false}]}
{"op":"mcm","clk":"5322685860","pt":1646323106286,"mc":[{"id":"1.195532867","rc":[{"atl":[[3.9,0]],"id":28791281}],"con":true,"img":false}]}
{"op":"mcm","clk":"5322685895","pt":1646323106758,"mc":[{"id":"1.195532867","rc":[{"atl":[[4,35.83]],"id":28791281}],"con":true,"img":false}]}
{"op":"mcm","clk":"5322685954","pt":1646323107788,"mc":[{"id":"1.195532867","rc":[{"atb":[[2.66,17.16],[2.7,12.15]],"id":26648132},{"atb":[[2.1,20.95],[2.06,9.46]],"id":39213014}],"con":true,"img":false}]}
{"op":"mcm","clk":"5322685960","pt":1646323107891,"mc":[{"id":"1.195532867","rc":[{"atb":[[2.08,9.5],[2.02,17]],"id":39213014}],"con":true,"img":false}]}
{"op":"mcm","clk":"5322685979","pt":1646323108157,"mc":[{"id":"1.195532867","rc":[{"atl":[[7,16.67]],"id":26648132},{"atl":[[5.6,21.74]],"id":43094640},{"atl":[[9.8,11.36]],"id":35676762},{"atl":[[5.1,24.39]],"id":39213014}],"con":true,"img":false}]}
{"op":"mcm","clk":"5322685989","pt":1646323108365,"mc":[{"id":"1.195532867","rc":[{"atb":[[2.08,0]],"id":39213014}],"con":true,"img":false}]}
{"op":"mcm","clk":"5322685998","pt":1646323108466,"mc":[{"id":"1.195532867","rc":[{"atb":[[2.02,9.46]],"id":39213014}],"con":true,"img":false}]}
{"op":"mcm","clk":"5322686023","pt":1646323108779,"mc":[{"id":"1.195532867","rc":[{"atl":[[7.2,24.44],[6.8,10]],"id":26648132},{"atl":[[5.5,8.89],[5.7,26.62]],"id":43094640},{"atl":[[9.6,10],[10,37.24],[22,0]],"id":35676762}],"con":true,"img":false}]}
{"op":"mcm","clk":"5322686202","pt":1646323111279,"mc":[{"id":"1.195532867","rc":[{"atl":[[4,2.5],[4.1,45.16]],"id":28791281}],"con":true,"img":false}]}
{"op":"mcm","clk":"5322686211","pt":1646323111386,"mc":[{"id":"1.195532867","rc":[{"atl":[[5.5,4.38]],"id":41529439},{"atl":[[5.1,28.77],[5,19.5]],"id":39213014}],"con":true,"img":false}]}
{"op":"mcm","clk":"5322686220","pt":1646323111487,"mc":[{"id":"1.195532867","rc":[{"atl":[[4.2,25.57]],"id":28791281},{"atl":[[5.5,0]],"id":41529439},{"atl":[[5,10]],"id":39213014}],"con":true,"img":false}]}
{"op":"mcm","clk":"5322686230","pt":1646323111599,"mc":[{"id":"1.195532867","rc":[{"atl":[[7.2,4.99],[6.6,28.92]],"id":26648132},{"atl":[[5.7,5],[5.4,23.89]],"id":43094640},{"atl":[[4.1,126.41],[4.4,4.99],[3.9,27.59]],"id":28791281},{"atb":[[4,7.09]],"id":35676762},{"atl":[[10,5],[9.4,30.22]],"id":35676762},{"atl":[[4.9,33.58],[5.2,28.81]],"id":41529439},{"atl":[[4.5,5.7],[4.9,35.18],[5.2,4.99]],"id":39213014}],"con":true,"img":false}]}
{"op":"mcm","clk":"5322686242","pt":1646323111796,"mc":[{"id":"1.195532867","rc":[{"atl":[[6.4,12.5],[6.8,0]],"id":26648132},{"atl":[[5.3,11.39],[5.5,0]],"id":43094640},{"atl":[[3.95,0]],"id":28791281},{"atb":[[3.9,0],[3.65,37.5]],"id":35676762},{"atl":[[9.6,0],[9.2,14.7]],"id":35676762},{"atl":[[4.8,12.5],[5,0]],"id":41529439},{"atb":[[2.02,0]],"id":39213014},{"atl":[[4.8,13.9],[5,0],[4.7,0]],"id":39213014}],"con":true,"img":false}]}
{"op":"mcm","clk":"5322686250","pt":1646323111860,"mc":[{"id":"1.195532867","rc":[{"atl":[[6.4,2.5]],"id":26648132},{"atl":[[5.4,45.63]],"id":43094640},{"atb":[[3.55,78.44]],"id":35676762},{"atl":[[9.2,2.5],[9.4,41.58]],"id":35676762},{"atl":[[4.8,2.5]],"id":41529439},{"atl":[[5.1,24.39]],"id":39213014}],"con":true,"img":false}]}
{"op":"mcm","clk":"5322686254","pt":1646323111966,"mc":[{"id":"1.195532867","rc":[{"atl":[[6.6,45.59]],"id":26648132},{"atl":[[5.3,2.5]],"id":43094640},{"atb":[[3.65,15.09]],"id":35676762},{"atl":[[4.9,59.22]],"id":41529439},{"atl":[[4.9,60.82]],"id":39213014}],"con":true,"img":false}]}
{"op":"mcm","clk":"5322686259","pt":1646323112068,"mc":[{"id":"1.195532867","rc":[{"atl":[[4.2,12.5]],"id":28791281},{"atl":[[4.8,2.5]],"id":39213014}],"con":true,"img":false}]}
{"op":"mcm","clk":"5322686272","pt":1646323112277,"mc":[{"id":"1.195532867","rc":[{"atb":[[3.95,0]],"id":35676762}],"con":true,"img":false}]}
{"op":"mcm","clk":"5322686282","pt":1646323112382,"mc":[{"id":"1.195532867","rc":[{"atb":[[4.1,1.99]],"id":35676762}],"con":true,"img":false}]}
{"op":"mcm","clk":"5322686304","pt":1646323112699,"mc":[{"id":"1.195532867","rc":[{"atl":[[4.2,1.67]],"id":39213014}],"con":true,"img":false}]}
{"op":"mcm","clk":"5322686326","pt":1646323112899,"mc":[{"id":"1.195532867","rc":[{"atl":[[4,15.83]],"id":28791281},{"atl":[[4.4,11.76]],"id":39213014}],"con":true,"img":false}]}
{"op":"mcm","clk":"5322686343","pt":1646323113067,"mc":[{"id":"1.195532867","rc":[{"atl":[[4.2,0]],"id":39213014}],"con":true,"img":false}]}
{"op":"mcm","clk":"5322686353","pt":1646323113166,"mc":[{"id":"1.195532867","rc":[{"atb":[[4,5.44]],"id":35676762}],"con":true,"img":false}]}
{"op":"mcm","clk":"5322686363","pt":1646323113269,"mc":[{"id":"1.195532867","rc":[{"atb":[[4.2,1.65]],"id":35676762}],"con":true,"img":false}]}
{"op":"mcm","clk":"5322686371","pt":1646323113371,"mc":[{"id":"1.195532867","rc":[{"atl":[[4.3,1.67]],"id":39213014}],"con":true,"img":false}]}
{"op":"mcm","clk":"5322686387","pt":1646323113579,"mc":[{"id":"1.195532867","rc":[{"atl":[[4.5,17.13],[4.4,0]],"id":39213014}],"con":true,"img":false}]}
{"op":"mcm","clk":"5322686449","pt":1646323114467,"mc":[{"id":"1.195532867","rc":[{"atl":[[4.3,0]],"id":39213014}],"con":true,"img":false}]}
{"op":"mcm","clk":"5322686535","pt":1646323115975,"mc":[{"id":"1.195532867","rc":[{"atb":[[2.16,6.38]],"id":39213014}],"con":true,"img":false}]}
{"op":"mcm","clk":"5322686549","pt":1646323116186,"mc":[{"id":"1.195532867","rc":[{"atb":[[2.12,16.51],[2.16,15],[2.1,0]],"id":39213014}],"con":true,"img":false}]}
{"op":"mcm","clk":"5322686566","pt":1646323116397,"mc":[{"id":"1.195532867","rc":[{"atb":[[2.14,1.99]],"id":39213014}],"con":true,"img":false}]}
{"op":"mcm","clk":"5322686573","pt":1646323116495,"mc":[{"id":"1.195532867","rc":[{"atl":[[4.4,22.57]],"id":39213014}],"con":true,"img":false}]}
{"op":"mcm","clk":"5322686590","pt":1646323116700,"mc":[{"id":"1.195532867","rc":[{"atb":[[2.14,0]],"id":39213014}],"con":true,"img":false}]}
{"op":"mcm","clk":"5322686596","pt":1646323116764,"mc":[{"id":"1.195532867","rc":[{"atb":[[2.18,1.99]],"id":39213014}],"con":true,"img":false}]}
{"op":"mcm","clk":"5322686612","pt":1646323116972,"mc":[{"id":"1.195532867","rc":[{"atl":[[4.4,0]],"id":39213014}],"con":true,"img":false}]}
{"op":"mcm","clk":"5322686623","pt":1646323117173,"mc":[{"id":"1.195532867","rc":[{"atb":[[2.22,2.15]],"id":39213014}],"con":true,"img":false}]}
{"op":"mcm","clk":"5322686630","pt":1646323117291,"mc":[{"id":"1.195532867","rc":[{"atb":[[2.12,14.36]],"id":39213014},{"atl":[[4.3,1.67]],"id":39213014}],"con":true,"img":false}]}
{"op":"mcm","clk":"5322686671","pt":1646323117858,"mc":[{"id":"1.195532867","rc":[{"atl":[[3.9,32.04]],"id":28791281},{"atb":[[2.18,0]],"id":39213014}],"con":true,"img":false}]}
{"op":"mcm","clk":"5322686679","pt":1646323117967,"mc":[{"id":"1.195532867","rc":[{"atb":[[2.24,1.99]],"id":39213014}],"con":true,"img":false}]}
{"op":"mcm","clk":"5322686686","pt":1646323118068,"mc":[{"id":"1.195532867","rc":[{"atl":[[3.85,32.04],[4.1,94.15]],"id":28791281},{"atl":[[4.3,0]],"id":39213014}],"con":true,"img":false}]}
{"op":"mcm","clk":"5322686712","pt":1646323118482,"mc":[{"id":"1.195532867","rc":[{"atl":[[3.95,13.56]],"id":28791281},{"atl":[[4.5,5.7],[4.7,10.81]],"id":39213014}],"con":true,"img":false}]}
{"op":"mcm","clk":"5322686721","pt":1646323118585,"mc":[{"id":"1.195532867","rc":[{"atl":[[4,2.5]],"id":28791281},{"atb":[[3.65,31.85]],"id":35676762}],"con":true,"img":false}]}
{"op":"mcm","clk":"5322686730","pt":1646323118696,"mc":[{"id":"1.195532867","rc":[{"atl":[[7.4,23.44]],"id":26648132},{"atl":[[5.8,31.25]],"id":43094640},{"atl":[[4.2,0]],"id":28791281},{"atl":[[10.5,15.79]],"id":35676762}],"con":true,"img":false}]}
{"op":"mcm","clk":"5322686754","pt":1646323119004,"mc":[{"id":"1.195532867","rc":[{"atl":[[3.9,27.59]],"id":28791281}],"con":true,"img":false}]}
{"op":"mcm","clk":"5322686778","pt":1646323119268,"mc":[{"id":"1.195532867","rc":[{"atl":[[3.85,35.57]],"id":28791281},{"atl":[[4.3,1.67]],"id":39213014}],"con":true,"img":false}]}
{"op":"mcm","clk":"5322686798","pt":1646323119481,"mc":[{"id":"1.195532867","rc":[{"atl":[[4.3,7.37],[4.9,35.18]],"id":39213014}],"con":true,"img":false}]}
{"op":"mcm","clk":"5322686806","pt":1646323119588,"mc":[{"id":"1.195532867","rc":[{"atl":[[4.3,1.67],[4.7,21.62]],"id":39213014}],"con":true,"img":false}]}
{"op":"mcm","clk":"5322686812","pt":1646323119687,"mc":[{"id":"1.195532867","rc":[{"atl":[[4.3,0]],"id":39213014}],"con":true,"img":false}]}
{"op":"mcm","clk":"5322686987","pt":1646323122177,"mc":[{"id":"1.195532867","rc":[{"atb":[[2.16,8.62]],"id":39213014}],"con":true,"img":false}]}
{"op":"mcm","clk":"5322687004","pt":1646323122381,"mc":[{"id":"1.195532867","rc":[{"atb":[[2.26,1.65]],"id":39213014}],"con":true,"img":false}]}
{"op":"mcm","clk":"5322687121","pt":1646323123777,"mc":[{"id":"1.195532867","rc":[{"atb":[[1.9,36.27],[1.78,128.21],[1.75,250]],"id":28791281},{"atb":[[3.55,39.22],[3.75,36.36]],"id":35676762},{"atb":[[2.1,9.46],[2.06,0]],"id":39213014}],"con":true,"img":false}]}
{"op":"mcm","clk":"5322687129","pt":1646323123884,"mc":[{"id":"1.195532867","rc":[{"atb":[[1.82,123.46],[1.85,2.15]],"id":28791281},{"atb":[[3.95,3.89]],"id":35676762}],"con":true,"img":false}]}
{"op":"mcm","clk":"5322687134","pt":1646323123985,"mc":[{"id":"1.195532867","rc":[{"atb":[[1.81,49.38]],"id":28791281}],"con":true,"img":false}]}
{"op":"mcm","clk":"5322687155","pt":1646323124304,"mc":[{"id":"1.195532867","rc":[{"atb":[[1.84,4.46]],"id":28791281},{"atb":[[3.95,0]],"id":35676762}],"con":true,"img":false}]}
{"op":"mcm","clk":"5322687195","pt":1646323124775,"mc":[{"id":"1.195532867","rc":[{"atl":[[5.5,4.76]],"id":43094640},{"atb":[[1.84,0]],"id":28791281},{"atl":[[4.8,28.82],[4.7,10.81]],"id":39213014}],"con":true,"img":false}]}
{"op":"mcm","clk":"5322687236","pt":1646323125191,"mc":[{"id":"1.195532867","rc":[{"atl":[[5.5,0]],"id":43094640}],"con":true,"img":false}]}
{"op":"mcm","clk":"5322687290","pt":1646323125766,"mc":[{"id":"1.195532867","rc":[{"atl":[[5.8,35]],"id":43094640},{"atl":[[4.1,114.96]],"id":28791281}],"con":true,"img":false}]}
{"op":"mcm","clk":"5322687303","pt":1646323125972,"mc":[{"id":"1.195532867","rc":[{"atl":[[5.4,49.5]],"id":43094640}],"con":true,"img":false}]}
{"op":"mcm","clk":"5322687312","pt":1646323126075,"mc":[{"id":"1.195532867","rc":[{"atl":[[5.8,31.25]],"id":43094640},{"atl":[[3.95,100.53],[4.1,12.9],[3.8,28.57]],"id":28791281},{"atb":[[4.2,7.61]],"id":35676762}],"con":true,"img":false}]}
{"op":"mcm","clk":"5322687319","pt":1646323126178,"mc":[{"id":"1.195532867","rc":[{"atl":[[4.8,57.46],[4.9,10.26]],"id":39213014}],"con":true,"img":false}]}
{"op":"mcm","clk":"5322687325","pt":1646323126282,"mc":[{"id":"1.195532867","rc":[{"atl":[[3.9,13.79]],"id":28791281},{"atb":[[4,0],[3.75,55.85]],"id":35676762}],"con":true,"img":false}]}
{"op":"mcm","clk":"5322687331","pt":1646323126386,"mc":[{"id":"1.195532867","rc":[{"atl":[[3.85,32.04]],"id":28791281},{"atb":[[3.65,15.08]],"id":35676762}],"con":true,"img":false}]}
{"op":"mcm","clk":"5322687340","pt":1646323126488,"mc":[{"id":"1.195532867","rc":[{"atl":[[3.9,48.27]],"id":28791281},{"atb":[[3.75,36.36]],"id":35676762}],"con":true,"img":false}]}
{"op":"mcm","clk":"5322687346","pt":1646323126595,"mc":[{"id":"1.195532867","rc":[{"atl":[[3.85,0]],"id":28791281},{"atb":[[4.1,0]],"id":35676762},{"atb":[[2.18,4.01]],"id":39213014}],"con":true,"img":false}]}
{"op":"mcm","clk":"5322687354","pt":1646323126697,"mc":[{"id":"1.195532867","rc":[{"atb":[[4.3,1.99]],"id":35676762}],"con":true,"img":false}]}
{"op":"mcm","clk":"5322687363","pt":1646323126801,"mc":[{"id":"1.195532867","rc":[{"atl":[[3.8,0]],"id":28791281}],"con":true,"img":false}]}
{"op":"mcm","clk":"5322687374","pt":1646323126906,"mc":[{"id":"1.195532867","rc":[{"atl":[[3.85,28.07]],"id":28791281}],"con":true,"img":false}]}
{"op":"mcm","clk":"5322687382","pt":1646323126960,"mc":[{"id":"1.195532867","rc":[{"atl":[[4,15.83],[3.9,34.48]],"id":28791281}],"con":true,"img":false}]}
{"op":"mcm","clk":"5322687442","pt":1646323127901,"mc":[{"id":"1.195532867","rc":[{"atl":[[3.75,5.74]],"id":28791281}],"con":true,"img":false}]}
{"op":"mcm","clk":"5322687511","pt":1646323128893,"mc":[{"id":"1.195532867","rc":[{"atl":[[4.9,25.64]],"id":39213014}],"con":true,"img":false}]}
{"op":"mcm","clk":"5322687537","pt":1646323129097,"mc":[{"id":"1.195532867","rc":[{"atl":[[7.8,36.76]],"id":26648132},{"atl":[[6,50]],"id":43094640},{"atl":[[11.5,23.81]],"id":35676762}],"con":true,"img":false}]}
{"op":"mcm","clk":"5322687635","pt":1646323130290,"mc":[{"id":"1.195532867","rc":[{"atb":[[1.81,54.97]],"id":28791281}],"con":true,"img":false}]}
{"op":"mcm","clk":"5322687654","pt":1646323130598,"mc":[{"id":"1.195532867","rc":[{"atb":[[1.81,49.38]],"id":28791281},{"atb":[[2.12,0],[2.24,7.89],[2.18,16.15]],"id":39213014}],"con":true,"img":false}]}
{"op":"mcm","clk":"5322687666","pt":1646323130704,"mc":[{"id":"1.195532867","rc":[{"atb":[[2.16,0]],"id":39213014}],"con":true,"img":false}]}
{"op":"mcm","clk":"5322687705","pt":1646323131172,"mc":[{"id":"1.195532867","rc":[{"atb":[[4.2,5.96]],"id":35676762}],"con":true,"img":false}]}
{"op":"mcm","clk":"5322687726","pt":1646323131381,"mc":[{"id":"1.195532867","rc":[{"atl":[[10.5,0]],"id":26648132},{"atb":[[2.3,16.4]],"id":43094640},{"atl":[[8,0]],"id":43094640},{"atb":[[1.9,0]],"id":28791281},{"atl":[[3.85,42.11],[3.95,86.97]],"id":28791281},{"atb":[[4.4,1.65]],"id":35676762},{"atb":[[2.24,1.99]],"id":39213014}],"con":true,"img":false}]}
{"op":"mcm","clk":"5322687740","pt":1646323131484,"mc":[{"id":"1.195532867","rc":[{"atl":[[5.4,45.63]],"id":43094640},{"atb":[[1.85,41.82]],"id":28791281}],"con":true,"img":false}]}
{"op":"mcm","clk":"5322687750","pt":1646323131599,"mc":[{"id":"1.195532867","rc":[{"atb":[[1.82,44.51],[1.81,145.12]],"id":28791281}],"con":true,"img":false}]}
{"op":"mcm","clk":"5322687869","pt":1646323132896,"mc":[{"id":"1.195532867","rc":[{"atl":[[5.2,7.78]],"id":43094640},{"atb":[[2.18,12.14]],"id":39213014}],"con":true,"img":false}]}
{"op":"mcm","clk":"5322687879","pt":1646323133000,"mc":[{"id":"1.195532867","rc":[{"atl":[[5.1,7.78],[5.4,23.89]],"id":43094640},{"atb":[[3.75,53.77]],"id":35676762}],"con":true,"img":false}]}
{"op":"mcm","clk":"5322687891","pt":1646323133213,"mc":[{"id":"1.195532867","rc":[{"atl":[[5.3,25.36],[5.4,9.09],[5,3.75],[5.5,4.54]],"id":43094640},{"atl":[[3.7,34.48],[3.9,0]],"id":28791281}],"con":true,"img":false}]}
{"op":"mcm","clk":"5322687911","pt":1646323133372,"mc":[{"id":"1.195532867","rc":[{"atl":[[5.5,0],[5.2,4.03]],"id":43094640}],"con":true,"img":false}]}
{"op":"mcm","clk":"5322687926","pt":1646323133582,"mc":[{"id":"1.195532867","rc":[{"atl":[[5.2,13.55],[5.4,0]],"id":43094640},{"atl":[[3.8,14.29]],"id":28791281}],"con":true,"img":false}]}
{"op":"mcm","clk":"5322687941","pt":1646323133687,"mc":[{"id":"1.195532867","rc":[{"atl":[[3.85,28.07]],"id":28791281}],"con":true,"img":false}]}
{"op":"mcm","clk":"5322687952","pt":1646323133787,"mc":[{"id":"1.195532867","rc":[{"atl":[[6.2,0],[4.1,0]],"id":28791281}],"con":true,"img":false}]}
{"op":"mcm","clk":"5322688043","pt":1646323134888,"mc":[{"id":"1.195532867","rc":[{"atb":[[2.14,12.65]],"id":41529439}],"con":true,"img":false}]}
{"op":"mcm","clk":"5322688056","pt":1646323135096,"mc":[{"id":"1.195532867","rc":[{"atb":[[2.08,14.65],[2.06,4.58],[2.16,7.5]],"id":41529439}],"con":true,"img":false}]}
{"op":"mcm","clk":"5322688078","pt":1646323135403,"mc":[{"id":"1.195532867","rc":[{"atb":[[2.12,2.5]],"id":41529439}],"con":true,"img":false}]}
{"op":"mcm","clk":"5322688088","pt":1646323135506,"mc":[{"id":"1.195532867","rc":[{"atl":[[7.4,26.94]],"id":26648132},{"atl":[[3.75,0]],"id":28791281}],"con":true,"img":false}]}
{"op":"mcm","clk":"5322688104","pt":1646323135712,"mc":[{"id":"1.195532867","rc":[{"atl":[[7.4,23.44]],"id":26648132},{"atb":[[2.08,17.79]],"id":41529439}],"con":true,"img":false}]}
{"op":"mcm","clk":"5322688153","pt":1646323136186,"mc":[{"id":"1.195532867","rc":[{"atb":[[2.08,12.5],[2.2,2.15]],"id":41529439}],"con":true,"img":false}]}
{"op":"mcm","clk":"5322688164","pt":1646323136498,"mc":[{"id":"1.195532867","rc":[{"atb":[[2.02,6.55]],"id":39213014}],"con":true,"img":false}]}
{"op":"mcm","clk":"5322688172","pt":1646323136706,"mc":[{"id":"1.195532867","rc":[{"atb":[[2.02,0]],"id":39213014}],"con":true,"img":false}]}
{"op":"mcm","clk":"5322688233","pt":1646323137697,"mc":[{"id":"1.195532867","rc":[{"atl":[[3.65,5.96]],"id":28791281},{"atb":[[2.06,0]],"id":41529439},{"atb":[[2.12,5.1]],"id":39213014}],"con":true,"img":false}]}
{"op":"mcm","clk":"5322688248","pt":1646323137903,"mc":[{"id":"1.195532867","rc":[{"atl":[[3.75,14.55]],"id":28791281}],"con":true,"img":false}]}
{"op":"mcm","clk":"5322688275","pt":1646323138324,"mc":[{"id":"1.195532867","rc":[{"atl":[[5.2,9.52]],"id":43094640}],"con":true,"img":false}]}
{"op":"mcm","clk":"5322688290","pt":1646323138480,"mc":[{"id":"1.195532867","rc":[{"atl":[[5.1,0],[5.2,31.26]],"id":43094640}],"con":true,"img":false}]}
{"op":"mcm","clk":"5322688333","pt":1646323139100,"mc":[{"id":"1.195532867","rc":[{"atl":[[5.1,36.59]],"id":39213014}],"con":true,"img":false}]}
{"op":"mcm","clk":"5322688378","pt":1646323139677,"mc":[{"id":"1.195532867","rc":[{"atl":[[5,7.96]],"id":43094640}],"con":true,"img":false}]}
{"op":"mcm","clk":"5322688386","pt":1646323139781,"mc":[{"id":"1.195532867","rc":[{"atl":[[5.2,9.52],[4.9,25.36]],"id":43094640},{"atl":[[3.6,14.55],[3.7,0]],"id":28791281}],"con":true,"img":false}]}
{"op":"mcm","clk":"5322688391","pt":1646323139883,"mc":[{"id":"1.195532867","rc":[{"atl":[[3.85,32.71]],"id":28791281}],"con":true,"img":false}]}
{"op":"mcm","clk":"5322688397","pt":1646323139990,"mc":[{"id":"1.195532867","rc":[{"atl":[[5.1,9.76],[5.2,0]],"id":43094640},{"atl":[[3.7,14.81]],"id":28791281}],"con":true,"img":false}]}
{"op":"mcm","clk":"5322688420","pt":1646323140305,"mc":[{"id":"1.195532867","rc":[{"atl":[[3.85,28.07],[3.55,31.37],[3.95,0],[3.7,110.39]],"id":28791281},{"atb":[[2.14,11]],"id":41529439}],"con":true,"img":false}]}
{"op":"mcm","clk":"5322688440","pt":1646323140510,"mc":[{"id":"1.195532867","rc":[{"atl":[[3.85,0]],"id":28791281},{"atb":[[2.22,1.65]],"id":41529439}],"con":true,"img":false}]}
{"op":"mcm","clk":"5322688456","pt":1646323140715,"mc":[{"id":"1.195532867","rc":[{"atl":[[3.7,95.58],[3.65,21.05]],"id":28791281}],"con":true,"img":false}]}
{"op":"mcm","clk":"5322688471","pt":1646323140876,"mc":[{"id":"1.195532867","rc":[{"atl":[[3.6,0],[3.65,58.79]],"id":28791281}],"con":true,"img":false}]}
{"op":"mcm","clk":"5322688520","pt":1646323141399,"mc":[{"id":"1.195532867","rc":[{"atb":[[2.8,2.5],[2.72,5],[2.58,2.15],[2.74,0],[2.66,12.16]],"id":26648132},{"atb":[[2.3,11.4],[2.22,0],[2.34,5],[2.42,4.15],[2.38,0]],"id":43094640},{"atb":[[1.98,0],[2.04,0],[2.12,0],[2.16,10]],"id":41529439},{"atl":[[5.6,0],[4.5,0],[4.4,2.5]],"id":39213014}],"con":true,"img":false}]}
{"op":"mcm","clk":"5322688526","pt":1646323141502,"mc":[{"id":"1.195532867","rc":[{"atl":[[4.6,4.96],[4.4,5.61]],"id":39213014}],"con":true,"img":false}]}
{"op":"mcm","clk":"5322688537","pt":1646323141606,"mc":[{"id":"1.195532867","rc":[{"atb":[[2.8,7.19],[2.72,19.69],[2.7,0]],"id":26648132},{"atl":[[4.7,31.95]],"id":39213014}],"con":true,"img":false}]}
{"op":"mcm","clk":"5322688545","pt":1646323141713,"mc":[{"id":"1.195532867","rc":[{"atb":[[2.6,26.67],[2.76,1.99]],"id":26648132},{"atb":[[2.36,3.3]],"id":43094640},{"atb":[[4.4,8]],"id":35676762},{"atb":[[2,0],[2.1,0],[1.81,123.46],[2.18,0]],"id":39213014},{"atl":[[4.8,28.82],[4.6,11.11]],"id":39213014}],"con":true,"img":false}]}
{"op":"mcm","clk":"5322688553","pt":1646323141826,"mc":[{"id":"1.195532867","rc":[{"atb":[[2.66,3]],"id":26648132},{"atb":[[1.9,38.19]],"id":28791281},{"atb":[[2.16,5.81]],"id":39213014},{"atl":[[4.8,35.37]],"id":39213014}],"con":true,"img":false}]}
{"op":"mcm","clk":"5322688562","pt":1646323141924,"mc":[{"id":"1.195532867","rc":[{"atb":[[2.72,15.94]],"id":26648132},{"atb":[[2.36,0],[2.3,2.15]],"id":43094640},{"atb":[[4.2,0]],"id":35676762}],"con":true,"img":false}]}
{"op":"mcm","clk":"5322688570","pt":1646323141979,"mc":[{"id":"1.195532867","rc":[{"atb":[[1.82,152.45],[1.85,2.15]],"id":28791281},{"atl":[[3.55,0]],"id":28791281},{"atb":[[2.16,0]],"id":39213014}],"con":true,"img":false}]}
{"op":"mcm","clk":"5322688578","pt":1646323142133,"mc":[{"id":"1.195532867","rc":[{"atb":[[2.76,0]],"id":26648132},{"spn":4.5,"spf":"NaN","id":26648132},{"spn":3.66,"spf":"NaN","id":43094640},{"atb":[[1.81,49.38]],"id":28791281},{"spn":2.77,"spf":"NaN","id":28791281},{"atb":[[3.75,36.36],[3.65,43.97]],"id":35676762},{"spn":4.37,"spf":1.0,"id":35676762},{"spn":2.18,"spf":1.0,"id":41529439},{"spn":2.26,"spf":1.0,"id":39213014}],"con":true,"img":false}]}
{"op":"mcm","clk":"5322688594","pt":1646323142191,"mc":[{"id":"1.195532867","rc":[{"atb":[[2.82,1.99],[2.66,0]],"id":26648132},{"atl":[[3.6,30.77]],"id":28791281},{"atb":[[2.18,6.75]],"id":41529439}],"con":true,"img":false}]}
{"op":"mcm","clk":"5322688601","pt":1646323142298,"mc":[{"id":"1.195532867","rc":[{"atl":[[4.8,28.82]],"id":39213014}],"con":true,"img":false}]}
{"op":"mcm","clk":"5322688609","pt":1646323142400,"mc":[{"id":"1.195532867","rc":[{"atb":[[4.3,0]],"id":35676762}],"con":true,"img":false}]}
{"op":"mcm","clk":"5322688615","pt":1646323142500,"mc":[{"id":"1.195532867","rc":[{"atb":[[1.02,1.99]],"id":35676762}],"con":true,"img":false}]}
{"op":"mcm","clk":"5322688633","pt":1646323142706,"mc":[{"id":"1.195532867","rc":[{"atb":[[2.4,0]],"id":43094640}],"con":true,"img":false}]}
{"op":"mcm","clk":"5322688638","pt":1646323142816,"mc":[{"id":"1.195532867","rc":[{"atb":[[2.44,1.99]],"id":43094640}],"con":true,"img":false}]}
{"op":"mcm","clk":"5322688653","pt":1646323143020,"mc":[{"id":"1.195532867","rc":[{"atl":[[3.7,110.39],[3.65,43.7]],"id":28791281}],"con":true,"img":false}]}
{"op":"mcm","clk":"5322688764","pt":1646323144212,"mc":[{"id":"1.195532867","rc":[{"atb":[[2.12,0]],"id":39213014}],"con":true,"img":false}]}
{"op":"mcm","clk":"5322688803","pt":1646323144691,"mc":[{"id":"1.195532867","rc":[{"atb":[[1.95,63.01]],"id":39213014}],"con":true,"img":false}]}
{"op":"mcm","clk":"5322688861","pt":1646323145516,"mc":[{"id":"1.195532867","rc":[{"atb":[[2.3,19.79]],"id":43094640}],"con":true,"img":false}]}
{"op":"mcm","clk":"5322688932","pt":1646323146299,"mc":[{"id":"1.195532867","rc":[{"atb":[[2.18,0]],"id":41529439}],"con":true,"img":false}]}
{"op":"mcm","clk":"5322688967","pt":1646323146712,"mc":[{"id":"1.195532867","rc":[{"atb":[[2.22,0]],"id":39213014}],"con":true,"img":false}]}
{"op":"mcm","clk":"5322688972","pt":1646323146814,"mc":[{"id":"1.195532867","rc":[{"atb":[[1.8,125],[1.78,0]],"id":28791281},{"atb":[[3.85,35.09],[3.75,0]],"id":35676762},{"atb":[[1.98,2.15]],"id":39213014}],"con":true,"img":false}]}
{"op":"mcm","clk":"5322688982","pt":1646323147022,"mc":[{"id":"1.195532867","rc":[{"atb":[[2.24,0]],"id":39213014}],"con":true,"img":false}]}
{"op":"mcm","clk":"5322688990","pt":1646323147126,"mc":[{"id":"1.195532867","rc":[{"atb":[[1.96,1.99]],"id":39213014}],"con":true,"img":false}]}
{"op":"mcm","clk":"5322689001","pt":1646323147229,"mc":[{"id":"1.195532867","rc":[{"atl":[[4.8,9.72],[5.1,45.2]],"id":43094640}],"con":true,"img":false}]}
{"op":"mcm","clk":"5322689015","pt":1646323147285,"mc":[{"id":"1.195532867","rc":[{"atl":[[5.3,2.5]],"id":43094640}],"con":true,"img":false}]}
{"op":"mcm","clk":"5322689023","pt":1646323147389,"mc":[{"id":"1.195532867","rc":[{"atl":[[5,4.21]],"id":43094640}],"con":true,"img":false}]}
{"op":"mcm","clk":"5322689048","pt":1646323147701,"mc":[{"id":"1.195532867","rc":[{"atb":[[1.96,0]],"id":39213014}],"con":true,"img":false}]}
{"op":"mcm","clk":"5322689053","pt":1646323147803,"mc":[{"id":"1.195532867","rc":[{"atb":[[1.99,1.99]],"id":39213014}],"con":true,"img":false}]}
{"op":"mcm","clk":"5322689059","pt":1646323147906,"mc":[{"id":"1.195532867","rc":[{"atl":[[5.1,35.44],[5,14.21]],"id":43094640}],"con":true,"img":false}]}
{"op":"mcm","clk":"5322689078","pt":1646323148117,"mc":[{"id":"1.195532867","rc":[{"atb":[[2.72,5],[2.6,60.14]],"id":26648132}],"con":true,"img":false}]}
{"op":"mcm","clk":"5322689113","pt":1646323148534,"mc":[{"id":"1.195532867","rc":[{"atb":[[1.96,8.74]],"id":39213014}],"con":true,"img":false}]}
{"op":"mcm","clk":"5322689176","pt":1646323149116,"mc":[{"id":"1.195532867","rc":[{"atb":[[2.14,28.27],[2.08,0],[2.2,6.84]],"id":41529439}],"con":true,"img":false}]}
{"op":"mcm","clk":"5322689194","pt":1646323149324,"mc":[{"id":"1.195532867","rc":[{"atb":[[2.78,0]],"id":26648132},{"atb":[[2.42,2.5]],"id":43094640},{"atb":[[2.16,2.5]],"id":41529439},{"atb":[[2.26,0]],"id":39213014}],"con":true,"img":false}]}
{"op":"mcm","clk":"5322689200","pt":1646323149425,"mc":[{"id":"1.195532867","rc":[{"atb":[[2.84,1.65]],"id":26648132},{"atb":[[2.46,1.65]],"id":43094640}],"con":true,"img":false}]}
{"op":"mcm","clk":"5322689222","pt":1646323149635,"mc":[{"id":"1.195532867","rc":[{"atb":[[2.3,2.15]],"id":43094640}],"con":true,"img":false}]}
{"op":"mcm","clk":"5322689363","pt":1646323150811,"mc":[{"id":"1.195532867","rc":[{"atb":[[2.22,4.33]],"id":41529439}],"con":true,"img":false}]}
{"op":"mcm","clk":"5322689440","pt":1646323151642,"mc":[{"id":"1.195532867","rc":[{"atl":[[4.8,55.14]],"id":39213014}],"con":true,"img":false}]}
{"op":"mcm","clk":"5322689483","pt":1646323151911,"mc":[{"id":"1.195532867","rc":[{"atb":[[4.4,1.65]],"id":35676762},{"atl":[[5.1,0],[4.9,0],[4.7,21.14]],"id":39213014}],"con":true,"img":false}]}
{"op":"mcm","clk":"5322689494","pt":1646323152011,"mc":[{"id":"1.195532867","rc":[{"atb":[[4.3,19.83],[3.55,143.8]],"id":35676762}],"con":true,"img":false}]}
{"op":"mcm","clk":"5322689503","pt":1646323152116,"mc":[{"id":"1.195532867","rc":[{"atb":[[3.65,15.09]],"id":35676762}],"con":true,"img":false}]}
{"op":"mcm","clk":"5322689516","pt":1646323152229,"mc":[{"id":"1.195532867","rc":[{"atb":[[4.3,16.12],[1.02,0],[3.55,48.84]],"id":35676762}],"con":true,"img":false}]}
{"op":"mcm","clk":"5322689522","pt":1646323152326,"mc":[{"id":"1.195532867","rc":[{"atb":[[3.55,39.22],[4.4,3.64]],"id":35676762}],"con":true,"img":false}]}
{"op":"mcm","clk":"5322689584","pt":1646323152947,"mc":[{"id":"1.195532867","rc":[{"atl":[[3.8,0]],"id":28791281}],"con":true,"img":false}]}
{"op":"mcm","clk":"5322689595","pt":1646323153011,"mc":[{"id":"1.195532867","rc":[{"atl":[[3.8,35.71]],"id":28791281}],"con":true,"img":false}]}
{"op":"mcm","clk":"5322689646","pt":1646323153528,"mc":[{"id":"1.195532867","rc":[{"atl":[[5.6,27.3]],"id":43094640}],"con":true,"img":false}]}
{"op":"mcm","clk":"5322689665","pt":1646323153735,"mc":[{"id":"1.195532867","rc":[{"atl":[[3.95,8.1]],"id":28791281}],"con":true,"img":false}]}
{"op":"mcm","clk":"5322689686","pt":1646323153942,"mc":[{"id":"1.195532867","rc":[{"atl":[[5.6,21.74]],"id":43094640},{"atl":[[3.95,0]],"id":28791281}],"con":true,"img":false}]}
{"op":"mcm","clk":"5322689842","pt":1646323155448,"mc":[{"id":"1.195532867","rc":[{"atl":[[4.1,10.77]],"id":39213014}],"con":true,"img":false}]}
{"op":"mcm","clk":"5322689855","pt":1646323155553,"mc":[{"id":"1.195532867","rc":[{"atb":[[2.82,6.68],[2.72,15.94],[2.6,26.67]],"id":26648132},{"atl":[[4.8,28.82],[4.6,71.29]],"id":39213014}],"con":true,"img":false}]}
{"op":"mcm","clk":"5322689866","pt":1646323155608,"mc":[{"id":"1.195532867","rc":[{"atb":[[2.8,2.49]],"id":26648132},{"atl":[[4.4,2.5],[4.7,0]],"id":39213014}],"con":true,"img":false}]}
{"op":"mcm","clk":"5322689889","pt":1646323155921,"mc":[{"id":"1.195532867","rc":[{"atl":[[3.65,37.74]],"id":28791281}],"con":true,"img":false}]}
{"op":"mcm","clk":"5322689898","pt":1646323156025,"mc":[{"id":"1.195532867","rc":[{"atl":[[3.7,147.43]],"id":28791281},{"atb":[[3.85,65.2]],"id":35676762}],"con":true,"img":false}]}
{"op":"mcm","clk":"5322689905","pt":1646323156124,"mc":[{"id":"1.195532867","rc":[{"atl":[[3.65,0]],"id":28791281},{"atl":[[4.3,12.12]],"id":39213014}],"con":true,"img":false}]}
{"op":"mcm","clk":"5322689914","pt":1646323156229,"mc":[{"id":"1.195532867","rc":[{"atl":[[3.75,111.9]],"id":28791281},{"atl":[[4.2,21.54]],"id":39213014}],"con":true,"img":false}]}
{"op":"mcm","clk":"5322689920","pt":1646323156332,"mc":[{"id":"1.195532867","rc":[{"atl":[[3.7,51.85]],"id":28791281},{"atl":[[4.6,50.15]],"id":39213014}],"con":true,"img":false}]}
{"op":"mcm","clk":"5322689931","pt":1646323156437,"mc":[{"id":"1.195532867","rc":[{"atl":[[3.6,0],[3.7,14.81],[3.75,148.26]],"id":28791281}],"con":true,"img":false}]}
{"op":"mcm","clk":"5322689953","pt":1646323156646,"mc":[{"id":"1.195532867","rc":[{"atl":[[3.65,30.19]],"id":28791281}],"con":true,"img":false}]}
{"op":"mcm","clk":"5322689971","pt":1646323156762,"mc":[{"id":"1.195532867","rc":[{"atl":[[3.7,0],[3.8,14.29]],"id":28791281}],"con":true,"img":false}]}
{"op":"mcm","clk":"5322690017","pt":1646323157130,"mc":[{"id":"1.195532867","rc":[{"atb":[[4.5,15.19]],"id":35676762},{"atb":[[1.98,16.79]],"id":39213014}],"con":true,"img":false}]}
{"op":"mcm","clk":"5322690029","pt":1646323157223,"mc":[{"id":"1.195532867","rc":[{"atl":[[3.55,6.19]],"id":28791281}],"con":true,"img":false}]}
{"op":"mcm","clk":"5322690047","pt":1646323157336,"mc":[{"id":"1.195532867","rc":[{"atb":[[4.3,0]],"id":35676762}],"con":true,"img":false}]}
{"op":"mcm","clk":"5322690099","pt":1646323157751,"mc":[{"id":"1.195532867","rc":[{"atl":[[5.2,23.81]],"id":43094640},{"atl":[[3.65,45.28]],"id":28791281}],"con":true,"img":false}]}
{"op":"mcm","clk":"5322690129","pt":1646323158060,"mc":[{"id":"1.195532867","rc":[{"atb":[[4.4,1.65]],"id":35676762}],"con":true,"img":false}]}
{"op":"mcm","clk":"5322690140","pt":1646323158120,"mc":[{"id":"1.195532867","rc":[{"atb":[[1.02,1.99]],"id":35676762}],"con":true,"img":false}]}
{"op":"mcm","clk":"5322690154","pt":1646323158221,"mc":[{"id":"1.195532867","rc":[{"atb":[[4.4,0]],"id":35676762}],"con":true,"img":false}]}
{"op":"mcm","clk":"5322690175","pt":1646323158431,"mc":[{"id":"1.195532867","rc":[{"atb":[[4.5,0],[3.85,35.09],[3.65,52.94]],"id":35676762}],"con":true,"img":false}]}
{"op":"mcm","clk":"5322690182","pt":1646323158531,"mc":[{"id":"1.195532867","rc":[{"atb":[[3.85,0],[3.65,90.68]],"id":35676762}],"con":true,"img":false}]}
{"op":"mcm","clk":"5322690191","pt":1646323158634,"mc":[{"id":"1.195532867","rc":[{"atb":[[4.4,16.91]],"id":35676762}],"con":true,"img":false}]}
{"op":"mcm","clk":"5322690198","pt":1646323158738,"mc":[{"id":"1.195532867","rc":[{"atb":[[3.35,108.88],[1.02,0]],"id":35676762}],"con":true,"img":false}]}
{"op":"mcm","clk":"5322690208","pt":1646323158843,"mc":[{"id":"1.195532867","rc":[{"atb":[[3.7,1.99]],"id":35676762}],"con":true,"img":false}]}
{"op":"mcm","clk":"5322690237","pt":1646323159259,"mc":[{"id":"1.195532867","rc":[{"atb":[[4.4,0]],"id":35676762}],"con":true,"img":false}]}
{"op":"mcm","clk":"5322690246","pt":1646323159316,"mc":[{"id":"1.195532867","rc":[{"atb":[[4.3,18.66]],"id":35676762}],"con":true,"img":false}]}
{"op":"mcm","clk":"5322690300","pt":1646323159938,"mc":[{"id":"1.195532867","rc":[{"atb":[[3.7,0]],"id":35676762}],"con":true,"img":false}]}
{"op":"mcm","clk":"5322690308","pt":1646323160042,"mc":[{"id":"1.195532867","rc":[{"atb":[[4.4,1.99]],"id":35676762}],"con":true,"img":false}]}
{"op":"mcm","clk":"5322690401","pt":1646323161029,"mc":[{"id":"1.195532867","rc":[{"atl":[[5.1,0],[5,43.65]],"id":43094640}],"con":true,"img":false}]}
{"op":"mcm","clk":"5322690429","pt":1646323161333,"mc":[{"id":"1.195532867","rc":[{"atl":[[4.3,42.42],[4.2,0]],"id":39213014}],"con":true,"img":false}]}
{"op":"mcm","clk":"5322690439","pt":1646323161437,"mc":[{"id":"1.195532867","rc":[{"atl":[[4.4,31.91]],"id":39213014}],"con":true,"img":false}]}
{"op":"mcm","clk":"5322690450","pt":1646323161546,"mc":[{"id":"1.195532867","rc":[{"atl":[[4.3,12.12]],"id":39213014}],"con":true,"img":false}]}
{"op":"mcm","clk":"5322690485","pt":1646323161957,"mc":[{"id":"1.195532867","rc":[{"atl":[[6,0]],"id":43094640},{"atl":[[5,6.41]],"id":41529439}],"con":true,"img":false}]}
{"op":"mcm","clk":"5322690510","pt":1646323162220,"mc":[{"id":"1.195532867","rc":[{"atl":[[5,39.44]],"id":43094640}],"con":true,"img":false}]}
{"op":"mcm","clk":"5322690519","pt":1646323162323,"mc":[{"id":"1.195532867","rc":[{"atl":[[5,64.44],[4.9,0]],"id":43094640}],"con":true,"img":false}]}
{"op":"mcm","clk":"5322690525","pt":1646323162424,"mc":[{"id":"1.195532867","rc":[{"atb":[[3.55,114.06],[3.65,52.83]],"id":35676762}],"con":true,"img":false}]}
{"op":"mcm","clk":"5322690534","pt":1646323162526,"mc":[{"id":"1.195532867","rc":[{"atl":[[4.8,0]],"id":43094640},{"atl":[[5,0]],"id":41529439}],"con":true,"img":false}]}
{"op":"mcm","clk":"5322690545","pt":1646323162632,"mc":[{"id":"1.195532867","rc":[{"atl":[[4.9,9.17]],"id":43094640}],"con":true,"img":false}]}
{"op":"mcm","clk":"5322690554","pt":1646323162734,"mc":[{"id":"1.195532867","rc":[{"atl":[[5,67.58]],"id":43094640}],"con":true,"img":false}]}
{"op":"mcm","clk":"5322690570","pt":1646323162848,"mc":[{"id":"1.195532867","rc":[{"atl":[[5.1,9.76],[5,57.58]],"id":43094640},{"atl":[[3.5,40],[3.75,111.9]],"id":28791281}],"con":true,"img":false}]}
{"op":"mcm","clk":"5322690583","pt":1646323162943,"mc":[{"id":"1.195532867","rc":[{"atl":[[5,54.44]],"id":43094640},{"atb":[[2.22,10.39],[2.16,12.6],[2.14,11]],"id":41529439}],"con":true,"img":false}]}
{"op":"mcm","clk":"5322690596","pt":1646323163045,"mc":[{"id":"1.195532867","rc":[{"atl":[[3.6,15.38],[3.65,30.19]],"id":28791281}],"con":true,"img":false}]}
{"op":"mcm","clk":"5322690610","pt":1646323163148,"mc":[{"id":"1.195532867","rc":[{"atb":[[2.2,2.15]],"id":41529439}],"con":true,"img":false}]}
{"op":"mcm","clk":"5322690673","pt":1646323163723,"mc":[{"id":"1.195532867","rc":[{"atb":[[2.28,2.15],[2.2,0]],"id":41529439}],"con":true,"img":false}]}
{"op":"mcm","clk":"5322690694","pt":1646323163930,"mc":[{"id":"1.195532867","rc":[{"atb":[[2.2,6]],"id":41529439}],"con":true,"img":false}]}
{"op":"mcm","clk":"5322690704","pt":1646323164033,"mc":[{"id":"1.195532867","rc":[{"atl":[[4.7,4.41]],"id":43094640}],"con":true,"img":false}]}
{"op":"mcm","clk":"5322690711","pt":1646323164135,"mc":[{"id":"1.195532867","rc":[{"atb":[[2.2,0]],"id":41529439}],"con":true,"img":false}]}
{"op":"mcm","clk":"5322690764","pt":1646323164757,"mc":[{"id":"1.195532867","rc":[{"atl":[[3.55,0]],"id":28791281}],"con":true,"img":false}]}
{"op":"mcm","clk":"5322690785","pt":1646323164963,"mc":[{"id":"1.195532867","rc":[{"atb":[[3.9,34.48]],"id":35676762}],"con":true,"img":false}]}
{"op":"mcm","clk":"5322690794","pt":1646323165067,"mc":[{"id":"1.195532867","rc":[{"atb":[[3.65,15.09]],"id":35676762}],"con":true,"img":false}]}
{"op":"mcm","clk":"5322690824","pt":1646323165331,"mc":[{"id":"1.195532867","rc":[{"atl":[[5.1,0],[4.9,19.43]],"id":43094640}],"con":true,"img":false}]}
{"op":"mcm","clk":"5322690849","pt":1646323165639,"mc":[{"id":"1.195532867","rc":[{"atb":[[2.22,7.71]],"id":41529439}],"con":true,"img":false}]}
{"op":"mcm","clk":"5322690859","pt":1646323165744,"mc":[{"id":"1.195532867","rc":[{"atb":[[3.55,39.22],[3.65,59.77]],"id":35676762}],"con":true,"img":false}]}
{"op":"mcm","clk":"5322690988","pt":1646323167227,"mc":[{"id":"1.195532867","rc":[{"atb":[[2.22,6.06]],"id":41529439}],"con":true,"img":false}]}
{"op":"mcm","clk":"5322690994","pt":1646323167344,"mc":[{"id":"1.195532867","rc":[{"atb":[[2.3,1.65]],"id":41529439}],"con":true,"img":false}]}
{"op":"mcm","clk":"5322691043","pt":1646323168055,"mc":[{"id":"1.195532867","rc":[{"atl":[[3.5,0],[3.65,67.93]],"id":28791281}],"con":true,"img":false}]}
{"op":"mcm","clk":"5322691057","pt":1646323168270,"mc":[{"id":"1.195532867","rc":[{"atl":[[3.55,9.5]],"id":28791281}],"con":true,"img":false}]}
{"op":"mcm","clk":"5322691079","pt":1646323168426,"mc":[{"id":"1.195532867","rc":[{"atl":[[3.55,0]],"id":28791281}],"con":true,"img":false}]}
{"op":"mcm","clk":"5322691097","pt":1646323168632,"mc":[{"id":"1.195532867","rc":[{"atl":[[5,29.44],[4.6,19.43]],"id":43094640}],"con":true,"img":false}]}
{"op":"mcm","clk":"5322691124","pt":1646323168955,"mc":[{"id":"1.195532867","rc":[{"atl":[[4.3,15.3]],"id":39213014}],"con":true,"img":false}]}
{"op":"mcm","clk":"5322691141","pt":1646323169157,"mc":[{"id":"1.195532867","rc":[{"atl":[[4.6,11.11],[4.4,100.09]],"id":39213014}],"con":true,"img":false}]}
{"op":"mcm","clk":"5322691165","pt":1646323169358,"mc":[{"id":"1.195532867","rc":[{"atl":[[4.3,12.12]],"id":39213014}],"con":true,"img":false}]}
{"op":"mcm","clk":"5322691233","pt":1646323170140,"mc":[{"id":"1.195532867","rc":[{"atb":[[2.18,4.96]],"id":41529439}],"con":true,"img":false}]}
{"op":"mcm","clk":"5322691240","pt":1646323170244,"mc":[{"id":"1.195532867","rc":[{"atl":[[3.55,31.37]],"id":28791281}],"con":true,"img":false}]}
{"op":"mcm","clk":"5322691248","pt":1646323170354,"mc":[{"id":"1.195532867","rc":[{"atl":[[3.65,140.52],[3.75,14.55]],"id":28791281}],"con":true,"img":false}]}
{"op":"mcm","clk":"5322691320","pt":1646323171251,"mc":[{"id":"1.195532867","rc":[{"atb":[[3.95,33.9],[3.9,0]],"id":35676762}],"con":true,"img":false}]}
{"op":"mcm","clk":"5322691350","pt":1646323171570,"mc":[{"id":"1.195532867","rc":[{"atl":[[4.8,10.53],[4.9,9.17]],"id":43094640},{"atl":[[3.6,0],[3.65,155.61]],"id":28791281}],"con":true,"img":false}]}
{"op":"mcm","clk":"5322691370","pt":1646323171760,"mc":[{"id":"1.195532867","rc":[{"atl":[[3.55,5.19]],"id":28791281}],"con":true,"img":false}]}
{"op":"mcm","clk":"5322691393","pt":1646323171979,"mc":[{"id":"1.195532867","rc":[{"atl":[[3.6,30.77]],"id":28791281}],"con":true,"img":false}]}
{"op":"mcm","clk":"5322691416","pt":1646323172186,"mc":[{"id":"1.195532867","rc":[{"atl":[[3.55,0]],"id":28791281}],"con":true,"img":false}]}
{"op":"mcm","clk":"5322691472","pt":1646323172753,"mc":[{"id":"1.195532867","rc":[{"atl":[[3.7,14.81],[3.65,140.52]],"id":28791281}],"con":true,"img":false}]}
{"op":"mcm","clk":"5322691484","pt":1646323172958,"mc":[{"id":"1.195532867","rc":[{"atb":[[1.9,13.44]],"id":39213014}],"con":true,"img":false}]}
{"op":"mcm","clk":"5322691501","pt":1646323173267,"mc":[{"id":"1.195532867","rc":[{"atl":[[3.7,51.85],[3.65,102.78]],"id":28791281}],"con":true,"img":false}]}
{"op":"mcm","clk":"5322691561","pt":1646323174048,"mc":[{"id":"1.195532867","rc":[{"atb":[[1.9,0]],"id":39213014}],"con":true,"img":false}]}
{"op":"mcm","clk":"5322691615","pt":1646323174569,"mc":[{"id":"1.195532867","rc":[{"atl":[[4.8,29.35],[5,0]],"id":43094640}],"con":true,"img":false}]}
{"op":"mcm","clk":"5322691741","pt":1646323176183,"mc":[{"id":"1.195532867","rc":[{"atl":[[4.5,5.18]],"id":43094640}],"con":true,"img":false}]}
{"op":"mcm","clk":"5322691764","pt":1646323176344,"mc":[{"id":"1.195532867","rc":[{"atl":[[4.9,0]],"id":43094640},{"atb":[[3.95,0],[3.9,34.48]],"id":35676762}],"con":true,"img":false}]}
{"op":"mcm","clk":"5322691771","pt":1646323176441,"mc":[{"id":"1.195532867","rc":[{"atb":[[2.28,6.84],[2.18,15.94],[2.16,2.5]],"id":41529439}],"con":true,"img":false}]}
{"op":"mcm","clk":"5322691781","pt":1646323176546,"mc":[{"id":"1.195532867","rc":[{"atl":[[3.7,154.44]],"id":28791281},{"atb":[[2.22,0]],"id":41529439}],"con":true,"img":false}]}
{"op":"mcm","clk":"5322691788","pt":1646323176650,"mc":[{"id":"1.195532867","rc":[{"atl":[[3.65,0]],"id":28791281}],"con":true,"img":false}]}
{"op":"mcm","clk":"5322691806","pt":1646323176870,"mc":[{"id":"1.195532867","rc":[{"atl":[[4.8,18.82],[4.7,15.22]],"id":43094640}],"con":true,"img":false}]}
{"op":"mcm","clk":"5322691823","pt":1646323177066,"mc":[{"id":"1.195532867","rc":[{"atl":[[4.6,0],[4.7,39.83]],"id":43094640}],"con":true,"img":false}]}
{"op":"mcm","clk":"5322691844","pt":1646323177271,"mc":[{"id":"1.195532867","rc":[{"atl":[[4.5,0]],"id":43094640}],"con":true,"img":false}]}
{"op":"mcm","clk":"5322691856","pt":1646323177375,"mc":[{"id":"1.195532867","rc":[{"atl":[[4.6,5.76]],"id":43094640}],"con":true,"img":false}]}
{"op":"mcm","clk":"5322691916","pt":1646323177857,"mc":[{"id":"1.195532867","rc":[{"atl":[[4.8,29.35],[4.7,29.02]],"id":43094640}],"con":true,"img":false}]}
{"op":"mcm","clk":"5322691927","pt":1646323177969,"mc":[{"id":"1.195532867","rc":[{"atb":[[3.95,33.9],[3.9,0]],"id":35676762}],"con":true,"img":false}]}
{"op":"mcm","clk":"5322691959","pt":1646323178372,"mc":[{"id":"1.195532867","rc":[{"atl":[[3.7,117.4],[3.75,50.91]],"id":28791281},{"atb":[[3.85,6.12]],"id":35676762}],"con":true,"img":false}]}
{"op":"mcm","clk":"5322691970","pt":1646323178481,"mc":[{"id":"1.195532867","rc":[{"atb":[[3.85,41.9]],"id":35676762}],"con":true,"img":false}]}
{"op":"mcm","clk":"5322691978","pt":1646323178579,"mc":[{"id":"1.195532867","rc":[{"atb":[[3.5,4.1],[3.65,15.09]],"id":35676762}],"con":true,"img":false}]}
{"op":"mcm","clk":"5322691997","pt":1646323178791,"mc":[{"id":"1.195532867","rc":[{"atl":[[4,13.33],[4.8,0],[4.4,0]],"id":28791281},{"atb":[[3.85,35.78]],"id":35676762}],"con":true,"img":false}]}
{"op":"mcm","clk":"5322692034","pt":1646323179155,"mc":[{"id":"1.195532867","rc":[{"atb":[[3.5,0]],"id":35676762}],"con":true,"img":false}]}
{"op":"mcm","clk":"5322692113","pt":1646323179891,"mc":[{"id":"1.195532867","rc":[{"atb":[[2.3,12.65]],"id":41529439}],"con":true,"img":false}]}
{"op":"mcm","clk":"5322692177","pt":1646323180673,"mc":[{"id":"1.195532867","rc":[{"atb":[[2.36,2.15],[2.28,4.69]],"id":41529439}],"con":true,"img":false}]}
{"op":"mcm","clk":"5322692300","pt":1646323182182,"mc":[{"id":"1.195532867","rc":[{"atl":[[4.8,55.67],[4.7,4.41]],"id":43094640}],"con":true,"img":false}]}
{"op":"mcm","clk":"5322692307","pt":1646323182249,"mc":[{"id":"1.195532867","rc":[{"atl":[[3.8,35.71]],"id":28791281}],"con":true,"img":false}]}
{"op":"mcm","clk":"5322692335","pt":1646323182758,"mc":[{"id":"1.195532867","rc":[{"atb":[[2.46,12.65]],"id":43094640},{"atl":[[3.7,14.81],[3.75,153.31]],"id":28791281}],"con":true,"img":false}]}
{"op":"mcm","clk":"5322692342","pt":1646323182865,"mc":[{"id":"1.195532867","rc":[{"atb":[[1.8,0],[1.79,152.56],[1.74,135.14]],"id":28791281},{"atb":[[1.98,2.15]],"id":39213014}],"con":true,"img":false}]}
{"op":"mcm","clk":"5322692352","pt":1646323182965,"mc":[{"id":"1.195532867","rc":[{"atb":[[1.9,47.04]],"id":28791281},{"atb":[[1.97,4.95]],"id":39213014}],"con":true,"img":false}]}
{"op":"mcm","clk":"5322692362","pt":1646323183077,"mc":[{"id":"1.195532867","rc":[{"atb":[[2.18,10.98]],"id":41529439}],"con":true,"img":false}]}
{"op":"mcm","clk":"5322692372","pt":1646323183175,"mc":[{"id":"1.195532867","rc":[{"atb":[[2.44,0]],"id":43094640},{"atl":[[4.6,11.52]],"id":43094640},{"atb":[[1.79,126.58],[1.9,38.19]],"id":28791281},{"atb":[[1.97,0],[1.96,33.14],[1.95,42.11]],"id":39213014}],"con":true,"img":false}]}
{"op":"mcm","clk":"5322692382","pt":1646323183278,"mc":[{"id":"1.195532867","rc":[{"atb":[[2.48,1.99]],"id":43094640},{"atl":[[4.8,29.35]],"id":43094640}],"con":true,"img":false}]}
{"op":"mcm","clk":"5322692446","pt":1646323184268,"mc":[{"id":"1.195532867","rc":[{"atb":[[1.9,0]],"id":28791281}],"con":true,"img":false}]}
{"op":"mcm","clk":"5322692453","pt":1646323184369,"mc":[{"id":"1.195532867","rc":[{"atb":[[1.82,44.51],[1.89,36.55]],"id":28791281}],"con":true,"img":false}]}
{"op":"mcm","clk":"5322692462","pt":1646323184474,"mc":[{"id":"1.195532867","rc":[{"atb":[[1.81,149.57]],"id":28791281}],"con":true,"img":false}]}
{"op":"mcm","clk":"5322692511","pt":1646323185151,"mc":[{"id":"1.195532867","rc":[{"atb":[[2.46,11]],"id":43094640},{"atb":[[2.3,11]],"id":41529439},{"atb":[[1.96,24.4]],"id":39213014}],"con":true,"img":false}]}
{"op":"mcm","clk":"5322692522","pt":1646323185254,"mc":[{"id":"1.195532867","rc":[{"atb":[[2.5,1.65]],"id":43094640},{"atb":[[2.38,1.65]],"id":41529439}],"con":true,"img":false}]}
{"op":"mcm","clk":"5322692553","pt":1646323185671,"mc":[{"id":"1.195532867","rc":[{"atb":[[2.4,3.33]],"id":43094640}],"con":true,"img":false}]}
{"op":"mcm","clk":"5322692561","pt":1646323185878,"mc":[{"id":"1.195532867","rc":[{"atb":[[2.4,0]],"id":43094640}],"con":true,"img":false}]}
{"op":"mcm","clk":"5322692580","pt":1646323186087,"mc":[{"id":"1.195532867","rc":[{"atl":[[3.55,13.05]],"id":28791281}],"con":true,"img":false}]}
{"op":"mcm","clk":"5322692585","pt":1646323186188,"mc":[{"id":"1.195532867","rc":[{"atl":[[3.5,32],[3.75,50.91]],"id":28791281}],"con":true,"img":false}]}
{"op":"mcm","clk":"5322692593","pt":1646323186246,"mc":[{"id":"1.195532867","rc":[{"atl":[[3.7,105.97],[3.5,46.81],[3.75,14.55]],"id":28791281}],"con":true,"img":false}]}
{"op":"mcm","clk":"5322692601","pt":1646323186350,"mc":[{"id":"1.195532867","rc":[{"atl":[[3.6,0]],"id":28791281}],"con":true,"img":false}]}
{"op":"mcm","clk":"5322692615","pt":1646323186454,"mc":[{"id":"1.195532867","rc":[{"atl":[[3.55,0]],"id":28791281}],"con":true,"img":false}]}
{"op":"mcm","clk":"5322692660","pt":1646323187180,"mc":[{"id":"1.195532867","rc":[{"atl":[[5,25]],"id":43094640}],"con":true,"img":false}]}
{"op":"mcm","clk":"5322692670","pt":1646323187280,"mc":[{"id":"1.195532867","rc":[{"atb":[[2.2,19.25]],"id":41529439}],"con":true,"img":false}]}
{"op":"mcm","clk":"5322692678","pt":1646323187380,"mc":[{"id":"1.195532867","rc":[{"atl":[[3.85,8.93]],"id":28791281}],"con":true,"img":false}]}
{"op":"mcm","clk":"5322692740","pt":1646323187956,"mc":[{"id":"1.195532867","rc":[{"atl":[[3.6,15.38],[3.7,91.16]],"id":28791281}],"con":true,"img":false}]}
{"op":"mcm","clk":"5322692747","pt":1646323188066,"mc":[{"id":"1.195532867","rc":[{"atl":[[5.8,0]],"id":43094640}],"con":true,"img":false}]}
{"op":"mcm","clk":"5322692752","pt":1646323188162,"mc":[{"id":"1.195532867","rc":[{"atl":[[3.4,2.53]],"id":28791281}],"con":true,"img":false}]}
{"op":"mcm","clk":"5322692771","pt":1646323188371,"mc":[{"id":"1.195532867","rc":[{"atl":[[3.6,0],[3.5,62.81]],"id":28791281}],"con":true,"img":false}]}
{"op":"mcm","clk":"5322692787","pt":1646323188581,"mc":[{"id":"1.195532867","rc":[{"atl":[[3.4,0]],"id":28791281}],"con":true,"img":false}]}
{"op":"mcm","clk":"5322692798","pt":1646323188686,"mc":[{"id":"1.195532867","rc":[{"atl":[[3.85,0]],"id":28791281}],"con":true,"img":false}]}
{"op":"mcm","clk":"5322692818","pt":1646323188887,"mc":[{"id":"1.195532867","rc":[{"atl":[[3.7,0],[3.75,118.11]],"id":28791281}],"con":true,"img":false}]}
{"op":"mcm","clk":"5322692835","pt":1646323189047,"mc":[{"id":"1.195532867","rc":[{"atl":[[3.95,2.5]],"id":28791281}],"con":true,"img":false}]}
{"op":"mcm","clk":"5322692848","pt":1646323189262,"mc":[{"id":"1.195532867","rc":[{"atb":[[1.96,0],[1.95,87.76]],"id":39213014}],"con":true,"img":false}]}
{"op":"mcm","clk":"5322692885","pt":1646323189673,"mc":[{"id":"1.195532867","rc":[{"atb":[[2.36,6.84],[2.28,15.33],[2.18,0]],"id":41529439}],"con":true,"img":false}]}
{"op":"mcm","clk":"5322692893","pt":1646323189777,"mc":[{"id":"1.195532867","rc":[{"atb":[[1.99,4.89]],"id":39213014}],"con":true,"img":false}]}
{"op":"mcm","clk":"5322692897","pt":1646323189882,"mc":[{"id":"1.195532867","rc":[{"atb":[[2.28,10.64]],"id":41529439}],"con":true,"img":false}]}
{"op":"mcm","clk":"5322692938","pt":1646323190448,"mc":[{"id":"1.195532867","rc":[{"atb":[[2.28,17.77]],"id":41529439}],"con":true,"img":false}]}
{"op":"mcm","clk":"5322692945","pt":1646323190562,"mc":[{"id":"1.195532867","rc":[{"atl":[[3.6,15.38],[3.5,46.81]],"id":28791281}],"con":true,"img":false}]}
{"op":"mcm","clk":"5322692954","pt":1646323190668,"mc":[{"id":"1.195532867","rc":[{"atb":[[2.28,10.64]],"id":41529439}],"con":true,"img":false}]}
{"op":"mcm","clk":"5322692997","pt":1646323191087,"mc":[{"id":"1.195532867","rc":[{"atb":[[1.92,2.15],[1.85,0]],"id":28791281}],"con":true,"img":false}]}
{"op":"mcm","clk":"5322693007","pt":1646323191191,"mc":[{"id":"1.195532867","rc":[{"atl":[[4.9,19.26]],"id":43094640}],"con":true,"img":false}]}
{"op":"mcm","clk":"5322693025","pt":1646323191396,"mc":[{"id":"1.195532867","rc":[{"atl":[[5,28.2],[4.9,0]],"id":43094640},{"atl":[[3.75,154.47]],"id":28791281}],"con":true,"img":false}]}
{"op":"mcm","clk":"5322693032","pt":1646323191496,"mc":[{"id":"1.195532867","rc":[{"atl":[[3.5,32]],"id":28791281}],"con":true,"img":false}]}
{"op":"mcm","clk":"5322693047","pt":1646323191750,"mc":[{"id":"1.195532867","rc":[{"atl":[[5,25]],"id":43094640},{"atl":[[3.5,0]],"id":28791281}],"con":true,"img":false}]}
{"op":"mcm","clk":"5322693055","pt":1646323191854,"mc":[{"id":"1.195532867","rc":[{"atl":[[3.55,31.37]],"id":28791281}],"con":true,"img":false}]}
{"op":"mcm","clk":"5322693061","pt":1646323191957,"mc":[{"id":"1.195532867","rc":[{"atb":[[2.2,0]],"id":41529439}],"con":true,"img":false}]}
{"op":"mcm","clk":"5322693143","pt":1646323193167,"mc":[{"id":"1.195532867","rc":[{"atl":[[3.6,0],[3.65,15.09]],"id":28791281},{"atb":[[3.95,0],[3.9,34.48]],"id":35676762}],"con":true,"img":false}]}
{"op":"mcm","clk":"5322693155","pt":1646323193368,"mc":[{"id":"1.195532867","rc":[{"atl":[[3.4,2.53]],"id":28791281}],"con":true,"img":false}]}
{"op":"mcm","clk":"5322693162","pt":1646323193474,"mc":[{"id":"1.195532867","rc":[{"atl":[[3.65,108.01],[3.75,50.91]],"id":28791281}],"con":true,"img":false}]}
{"op":"mcm","clk":"5322693184","pt":1646323193889,"mc":[{"id":"1.195532867","rc":[{"atl":[[3.4,0]],"id":28791281}],"con":true,"img":false}]}
{"op":"mcm","clk":"5322693250","pt":1646323194873,"mc":[{"id":"1.195532867","rc":[{"atl":[[3.75,155.62]],"id":28791281}],"con":true,"img":false}]}
{"op":"mcm","clk":"5322693259","pt":1646323194983,"mc":[{"id":"1.195532867","rc":[{"atl":[[4.7,0]],"id":43094640},{"atl":[[3.65,15.09]],"id":28791281}],"con":true,"img":false}]}
{"op":"mcm","clk":"5322693270","pt":1646323195187,"mc":[{"id":"1.195532867","rc":[{"atl":[[4.8,10.53],[4.6,5.76],[5,95.04]],"id":43094640}],"con":true,"img":false}]}
{"op":"mcm","clk":"5322693351","pt":1646323196298,"mc":[{"id":"1.195532867","rc":[{"atb":[[2.38,7.6]],"id":41529439}],"con":true,"img":false}]}
{"op":"mcm","clk":"5322693358","pt":1646323196400,"mc":[{"id":"1.195532867","rc":[{"atl":[[5.2,59.52]],"id":43094640}],"con":true,"img":false}]}
{"op":"mcm","clk":"5322693368","pt":1646323196504,"mc":[{"id":"1.195532867","rc":[{"atl":[[5.2,35.71]],"id":43094640}],"con":true,"img":false}]}
{"op":"mcm","clk":"5322693429","pt":1646323197502,"mc":[{"id":"1.195532867","rc":[{"atb":[[1.82,129.41]],"id":28791281}],"con":true,"img":false}]}
{"op":"mcm","clk":"5322693439","pt":1646323197606,"mc":[{"id":"1.195532867","rc":[{"atb":[[1.81,49.38]],"id":28791281}],"con":true,"img":false}]}
{"op":"mcm","clk":"5322693482","pt":1646323198177,"mc":[{"id":"1.195532867","rc":[{"atl":[[4.5,3.63]],"id":43094640}],"con":true,"img":false}]}
{"op":"mcm","clk":"5322693490","pt":1646323198279,"mc":[{"id":"1.195532867","rc":[{"atb":[[2.84,6.65],[2.76,10],[2.92,2.5]],"id":26648132},{"atl":[[4.8,26.32],[4.6,16.11],[5.2,0],[4.4,97.59],[4.2,2.5]],"id":39213014}],"con":true,"img":false}]}
{"op":"mcm","clk":"5322693497","pt":1646323198385,"mc":[{"id":"1.195532867","rc":[{"atb":[[2.82,19.69],[2.8,0],[2.72,10.94],[2.92,10.31]],"id":26648132},{"atl":[[4.4,7.04]],"id":43094640},{"atl":[[4.3,43.44],[4.4,29.4]],"id":39213014}],"con":true,"img":false}]}
{"op":"mcm","clk":"5322693504","pt":1646323198489,"mc":[{"id":"1.195532867","rc":[{"atb":[[2.72,0]],"id":26648132},{"atl":[[4.1,14.1]],"id":39213014}],"con":true,"img":false}]}
{"op":"mcm","clk":"5322693513","pt":1646323198594,"mc":[{"id":"1.195532867","rc":[{"atb":[[2.82,23.53]],"id":26648132},{"atl":[[4.6,0]],"id":43094640},{"atl":[[4,14.1],[4.4,0]],"id":39213014}],"con":true,"img":false}]}
{"op":"mcm","clk":"5322693522","pt":1646323198702,"mc":[{"id":"1.195532867","rc":[{"atl":[[4.8,0],[4.6,11.11]],"id":43094640},{"atb":[[1.92,37.81]],"id":28791281}],"con":true,"img":false}]}
{"op":"mcm","clk":"5322693530","pt":1646323198806,"mc":[{"id":"1.195532867","rc":[{"atb":[[2.82,15]],"id":26648132},{"atb":[[1.89,0]],"id":28791281},{"atl":[[3.95,14.24],[4.4,9.51]],"id":39213014}],"con":true,"img":false}]}
{"op":"mcm","clk":"5322693541","pt":1646323198963,"mc":[{"id":"1.195532867","rc":[{"atb":[[2.82,13.01]],"id":26648132},{"atl":[[4.1,3.33]],"id":39213014}],"con":true,"img":false}]}
{"op":"mcm","clk":"5322693549","pt":1646323199077,"mc":[{"id":"1.195532867","rc":[{"atb":[[2.94,1.99]],"id":26648132},{"atl":[[4.5,0]],"id":43094640}],"con":true,"img":false}]}
{"op":"mcm","clk":"5322693563","pt":1646323199277,"mc":[{"id":"1.195532867","rc":[{"atl":[[4.4,0]],"id":43094640},{"atl":[[4.4,0]],"id":39213014}],"con":true,"img":false}]}
{"op":"mcm","clk":"5322693582","pt":1646323199486,"mc":[{"id":"1.195532867","rc":[{"atl":[[4.5,9.74]],"id":43094640}],"con":true,"img":false}]}
{"op":"mcm","clk":"5322693596","pt":1646323199793,"mc":[{"id":"1.195532867","rc":[{"atl":[[4.1,0]],"id":39213014}],"con":true,"img":false}]}
{"op":"mcm","clk":"5322693608","pt":1646323200005,"mc":[{"id":"1.195532867","rc":[{"atl":[[4.7,10.81]],"id":43094640}],"con":true,"img":false}]}
{"op":"mcm","clk":"5322693615","pt":1646323200112,"mc":[{"id":"1.195532867","rc":[{"atl":[[4.6,0]],"id":43094640},{"atb":[[2.16,0]],"id":41529439}],"con":true,"img":false}]}
{"op":"mcm","clk":"5322693626","pt":1646323200229,"mc":[{"id":"1.195532867","rc":[{"atl":[[3.4,2.53]],"id":28791281}],"con":true,"img":false}]}
{"op":"mcm","clk":"5322693640","pt":1646323200380,"mc":[{"id":"1.195532867","rc":[{"atl":[[3.35,34.04],[3.4,17.62],[3.65,123.75],[3.75,14.55]],"id":28791281}],"con":true,"img":false}]}
{"op":"mcm","clk":"5322693654","pt":1646323200489,"mc":[{"id":"1.195532867","rc":[{"atl":[[3.55,38.87],[3.5,16],[3.65,108.66]],"id":28791281},{"atl":[[4.1,12.9]],"id":39213014}],"con":true,"img":false}]}
{"op":"mcm","clk":"5322693665","pt":1646323200595,"mc":[{"id":"1.195532867","rc":[{"atl":[[4.7,22.99]],"id":43094640},{"atl":[[3.45,16.33],[3.55,7.5]],"id":28791281}],"con":true,"img":false}]}
{"op":"mcm","clk":"5322693679","pt":1646323200701,"mc":[{"id":"1.195532867","rc":[{"atl":[[3.55,0]],"id":28791281}],"con":true,"img":false}]}
{"op":"mcm","clk":"5322693693","pt":1646323200809,"mc":[{"id":"1.195532867","rc":[{"atl":[[3.4,15.09]],"id":28791281}],"con":true,"img":false}]}
{"op":"mcm","clk":"5322693742","pt":1646323201187,"mc":[{"id":"1.195532867","rc":[{"atl":[[5,70.04],[4.6,27.78]],"id":43094640}],"con":true,"img":false}]}
{"op":"mcm","clk":"5322693792","pt":1646323201615,"mc":[{"id":"1.195532867","rc":[{"atl":[[4.7,10.81]],"id":43094640}],"con":true,"img":false}]}
{"op":"mcm","clk":"5322693813","pt":1646323201786,"mc":[{"id":"1.195532867","rc":[{"atl":[[4.6,0],[4.7,37.84]],"id":43094640},{"atl":[[3.45,131.58],[3.65,0]],"id":28791281}],"con":true,"img":false}]}
{"op":"mcm","clk":"5322693855","pt":1646323202215,"mc":[{"id":"1.195532867","rc":[{"spn":4.57,"spf":"NaN","id":26648132},{"spn":3.5,"spf":"NaN","id":43094640},{"atl":[[4,0],[3.8,0],[3.5,0]],"id":28791281},{"spn":2.63,"spf":"NaN","id":28791281},{"spn":4.31,"spf":1.0,"id":35676762},{"spn":2.37,"spf":1.0,"id":41529439},{"spn":1.99,"spf":1.0,"id":39213014}],"con":true,"img":false}]}
{"op":"mcm","clk":"5322693888","pt":1646323202478,"mc":[{"id":"1.195532867","rc":[{"atl":[[4.6,4.52]],"id":43094640}],"con":true,"img":false}]}
{"op":"mcm","clk":"5322693898","pt":1646323202593,"mc":[{"id":"1.195532867","rc":[{"atb":[[2.3,29.08],[2.28,0]],"id":41529439}],"con":true,"img":false}]}
{"op":"mcm","clk":"5322693914","pt":1646323202694,"mc":[{"id":"1.195532867","rc":[{"atb":[[2.4,10.84]],"id":41529439},{"atb":[[1.99,1.99]],"id":39213014}],"con":true,"img":false}]}
{"op":"mcm","clk":"5322693925","pt":1646323202800,"mc":[{"id":"1.195532867","rc":[{"atb":[[2.36,2.15],[2.16,2.5]],"id":41529439}],"con":true,"img":false}]}
{"op":"mcm","clk":"5322693937","pt":1646323202911,"mc":[{"id":"1.195532867","rc":[{"atb":[[1.95,42.11],[1.93,142.95]],"id":39213014}],"con":true,"img":false}]}
{"op":"mcm","clk":"5322693989","pt":1646323203380,"mc":[{"id":"1.195532867","rc":[{"atl":[[4.6,0]],"id":43094640}],"con":true,"img":false}]}
{"op":"mcm","clk":"5322693996","pt":1646323203484,"mc":[{"id":"1.195532867","rc":[{"atb":[[1.82,44.51],[1.81,158.38]],"id":28791281}],"con":true,"img":false}]}
{"op":"mcm","clk":"5322694028","pt":1646323203796,"mc":[{"id":"1.195532867","rc":[{"atl":[[4,0],[4.1,41.24]],"id":39213014}],"con":true,"img":false}]}
{"op":"mcm","clk":"5322694038","pt":1646323203904,"mc":[{"id":"1.195532867","rc":[{"atb":[[2.08,92.59],[1.99,0]],"id":43094640},{"atl":[[6.2,0],[5.3,0],[5.2,38.21],[5.7,0]],"id":43094640}],"con":true,"img":false}]}
{"op":"mcm","clk":"5322694050","pt":1646323204006,"mc":[{"id":"1.195532867","rc":[{"atl":[[3.95,0]],"id":39213014}],"con":true,"img":false}]}
{"op":"mcm","clk":"5322694056","pt":1646323204115,"mc":[{"id":"1.195532867","rc":[{"atl":[[4,12.56]],"id":39213014}],"con":true,"img":false}]}
{"op":"mcm","clk":"5322694116","pt":1646323204895,"mc":[{"id":"1.195532867","rc":[{"atb":[[2.84,6.65],[2.58,2.15]],"id":26648132},{"atl":[[46,2.74]],"id":26648132},{"atb":[[2.5,1.65],[2.3,2.15]],"id":43094640},{"atl":[[4.5,0],[46,2.74]],"id":43094640},{"atb":[[1.82,44.58],[1.92,37.81]],"id":28791281},{"atl":[[46,2.74]],"id":28791281},{"atb":[[2.64,2.15]],"id":35676762},{"atl":[[46,2.74]],"id":35676762},{"atb":[[2.36,2.15],[2.38,7.61]],"id":41529439},{"spl":[[1.01,8.22]],"id":41529439},{"atl":[[46,2.74]],"id":41529439},{"atb":[[1.98,2.15]],"id":39213014},{"atl":[[46,2.74]],"id":39213014}],"con":true,"img":false}]}
{"op":"mcm","clk":"5322694126","pt":1646323205000,"mc":[{"id":"1.195532867","rc":[{"atl":[[5,25],[4.6,15.56],[5.2,115.11]],"id":43094640}],"con":true,"img":false}]}
{"op":"mcm","clk":"5322694138","pt":1646323205107,"mc":[{"id":"1.195532867","rc":[{"atb":[[3.4,4.9]],"id":35676762}],"con":true,"img":false}]}
{"op":"mcm","clk":"5322694149","pt":1646323205207,"mc":[{"id":"1.195532867","rc":[{"atl":[[4.4,4.76]],"id":43094640}],"con":true,"img":false}]}
{"op":"mcm","clk":"5322694177","pt":1646323205572,"mc":[{"id":"1.195532867","rc":[{"atl":[[3.45,172.4],[3.4,0]],"id":28791281},{"atb":[[3.4,0]],"id":35676762}],"con":true,"img":false}]}
{"op":"mcm","clk":"5322694201","pt":1646323205885,"mc":[{"id":"1.195532867","rc":[{"atl":[[4.6,26.67],[4.7,27.03]],"id":43094640}],"con":true,"img":false}]}
{"op":"mcm","clk":"5322694245","pt":1646323206412,"mc":[{"id":"1.195532867","rc":[{"atl":[[3.45,57.15],[3.75,121.44]],"id":28791281}],"con":true,"img":false}]}
{"op":"mcm","clk":"5322694262","pt":1646323206615,"mc":[{"id":"1.195532867","rc":[{"atl":[[3.45,16.33],[3.35,0],[3.4,2.52],[3.75,157.8]],"id":28791281}],"con":true,"img":false}]}
{"op":"mcm","clk":"5322694271","pt":1646323206668,"mc":[{"id":"1.195532867","rc":[{"atl":[[3.4,35.85]],"id":28791281}],"con":true,"img":false}]}
{"op":"mcm","clk":"5322694280","pt":1646323206777,"mc":[{"id":"1.195532867","rc":[{"atl":[[3.4,52.18],[3.75,121.44]],"id":28791281}],"con":true,"img":false}]}
{"op":"mcm","clk":"5322694286","pt":1646323206883,"mc":[{"id":"1.195532867","rc":[{"atl":[[3.45,0],[3.5,16]],"id":28791281},{"atb":[[2.38,1.65]],"id":41529439},{"atb":[[1.96,4.14]],"id":39213014}],"con":true,"img":false}]}
{"op":"mcm","clk":"5322694295","pt":1646323206986,"mc":[{"id":"1.195532867","rc":[{"atl":[[3.4,49.66]],"id":28791281}],"con":true,"img":false}]}
{"op":"mcm","clk":"5322694310","pt":1646323207197,"mc":[{"id":"1.195532867","rc":[{"atl":[[4.4,0]],"id":43094640}],"con":true,"img":false}]}
{"op":"mcm","clk":"5322694320","pt":1646323207302,"mc":[{"id":"1.195532867","rc":[{"atl":[[5,50]],"id":43094640}],"con":true,"img":false}]}
{"op":"mcm","clk":"5322694326","pt":1646323207406,"mc":[{"id":"1.195532867","rc":[{"atl":[[4.7,0]],"id":43094640}],"con":true,"img":false}]}
{"op":"mcm","clk":"5322694338","pt":1646323207515,"mc":[{"id":"1.195532867","rc":[{"atl":[[5,25],[5.2,138.92]],"id":43094640}],"con":true,"img":false}]}
{"op":"mcm","clk":"5322694406","pt":1646323208504,"mc":[{"id":"1.195532867","rc":[{"atb":[[2.84,5]],"id":26648132},{"atb":[[2.38,0]],"id":41529439}],"con":true,"img":false}]}
{"op":"mcm","clk":"5322694415","pt":1646323208610,"mc":[{"id":"1.195532867","rc":[{"atb":[[2.4,0]],"id":41529439}],"con":true,"img":false}]}
{"op":"mcm","clk":"5322694424","pt":1646323208720,"mc":[{"id":"1.195532867","rc":[{"atb":[[2.96,1.65]],"id":26648132},{"atb":[[2.42,1.65],[2.38,10.94]],"id":41529439}],"con":true,"img":false}]}
{"op":"mcm","clk":"5322694430","pt":1646323208820,"mc":[{"id":"1.195532867","rc":[{"atl":[[4.8,10.53]],"id":43094640},{"atb":[[3.95,33.9]],"id":35676762},{"atb":[[2.3,11],[2.16,10.31]],"id":41529439},{"atb":[[1.98,7.14]],"id":39213014},{"atl":[[4.2,15]],"id":39213014}],"con":true,"img":false}]}
{"op":"mcm","clk":"5322694435","pt":1646323208874,"mc":[{"id":"1.195532867","rc":[{"atl":[[4.6,15.56]],"id":43094640},{"atb":[[3.9,0]],"id":35676762},{"atl":[[4.1,28.34],[4.2,46.25]],"id":39213014}],"con":true,"img":false}]}
{"op":"mcm","clk":"5322694439","pt":1646323208978,"mc":[{"id":"1.195532867","rc":[{"atl":[[5.6,0],[5,68.06],[5.2,62.01]],"id":43094640},{"atb":[[3.85,17.24],[3.9,68.19]],"id":35676762},{"atl":[[4.1,0]],"id":39213014}],"con":true,"img":false}]}
{"op":"mcm","clk":"5322694455","pt":1646323209187,"mc":[{"id":"1.195532867","rc":[{"atl":[[4.3,1.66]],"id":43094640}],"con":true,"img":false}]}
{"op":"mcm","clk":"5322694467","pt":1646323209301,"mc":[{"id":"1.195532867","rc":[{"atl":[[4.5,11.43]],"id":43094640}],"con":true,"img":false}]}
{"op":"mcm","clk":"5322694479","pt":1646323209504,"mc":[{"id":"1.195532867","rc":[{"atb":[[3.85,0]],"id":35676762}],"con":true,"img":false}]}
{"op":"mcm","clk":"5322694531","pt":1646323209977,"mc":[{"id":"1.195532867","rc":[{"atb":[[2.44,2.15],[2.36,0]],"id":41529439}],"con":true,"img":false}]}
{"op":"mcm","clk":"5322694620","pt":1646323211177,"mc":[{"id":"1.195532867","rc":[{"atb":[[2.82,0],[2.84,15.94],[2.94,6.68]],"id":26648132},{"atl":[[4.4,9.74]],"id":43094640}],"con":true,"img":false}]}
{"op":"mcm","clk":"5322694641","pt":1646323211385,"mc":[{"id":"1.195532867","rc":[{"atb":[[2.92,2.5]],"id":26648132},{"atl":[[4.6,0]],"id":43094640}],"con":true,"img":false}]}
{"op":"mcm","clk":"5322694657","pt":1646323211598,"mc":[{"id":"1.195532867","rc":[{"atb":[[2.18,22.68]],"id":41529439}],"con":true,"img":false}]}
{"op":"mcm","clk":"5322694687","pt":1646323212013,"mc":[{"id":"1.195532867","rc":[{"atl":[[3.4,33.33],[3.75,157.8]],"id":28791281}],"con":true,"img":false}]}
{"op":"mcm","clk":"5322694698","pt":1646323212220,"mc":[{"id":"1.195532867","rc":[{"atl":[[3.4,0]],"id":28791281}],"con":true,"img":false}]}
{"op":"mcm","clk":"5322694704","pt":1646323212326,"mc":[{"id":"1.195532867","rc":[{"atl":[[4.3,10.46]],"id":43094640},{"atl":[[3.45,32.65],[3.5,17.83]],"id":28791281}],"con":true,"img":false}]}
{"op":"mcm","clk":"5322694713","pt":1646323212383,"mc":[{"id":"1.195532867","rc":[{"atl":[[4.4,0]],"id":43094640},{"atl":[[3.95,105.06],[3.75,50.91]],"id":28791281}],"con":true,"img":false}]}
{"op":"mcm","clk":"5322694719","pt":1646323212489,"mc":[{"id":"1.195532867","rc":[{"atl":[[3.95,2.5]],"id":28791281}],"con":true,"img":false}]}
{"op":"mcm","clk":"5322694758","pt":1646323213013,"mc":[{"id":"1.195532867","rc":[{"atl":[[3.55,15.69],[3.5,1.83],[3.75,59.23]],"id":28791281}],"con":true,"img":false}]}
{"op":"mcm","clk":"5322694766","pt":1646323213117,"mc":[{"id":"1.195532867","rc":[{"atl":[[3.75,167.42]],"id":28791281}],"con":true,"img":false}]}
{"op":"mcm","clk":"5322694783","pt":1646323213324,"mc":[{"id":"1.195532867","rc":[{"atl":[[3.5,0],[3.75,159.1]],"id":28791281}],"con":true,"img":false}]}
{"op":"mcm","clk":"5322694794","pt":1646323213427,"mc":[{"id":"1.195532867","rc":[{"atl":[[4.3,20.99],[5.2,38.2]],"id":43094640}],"con":true,"img":false}]}
{"op":"mcm","clk":"5322694806","pt":1646323213479,"mc":[{"id":"1.195532867","rc":[{"atl":[[3.45,0]],"id":28791281}],"con":true,"img":false}]}
{"op":"mcm","clk":"5322694815","pt":1646323213584,"mc":[{"id":"1.195532867","rc":[{"atl":[[3.5,32]],"id":28791281}],"con":true,"img":false}]}
{"op":"mcm","clk":"5322694842","pt":1646323213895,"mc":[{"id":"1.195532867","rc":[{"atl":[[3.6,15.38],[3.55,0]],"id":28791281}],"con":true,"img":false}]}
{"op":"mcm","clk":"5322694852","pt":1646323214002,"mc":[{"id":"1.195532867","rc":[{"atb":[[2.36,3.05]],"id":43094640},{"atb":[[3.95,0],[3.9,102.67]],"id":35676762},{"atb":[[1.98,2.15],[1.97,4.39]],"id":39213014}],"con":true,"img":false}]}
{"op":"mcm","clk":"5322694863","pt":1646323214106,"mc":[{"id":"1.195532867","rc":[{"atl":[[4.3,19.33]],"id":43094640},{"atl":[[4.3,73.74],[4.2,15]],"id":39213014}],"con":true,"img":false}]}
{"op":"mcm","clk":"5322694870","pt":1646323214210,"mc":[{"id":"1.195532867","rc":[{"atb":[[2.36,0]],"id":43094640},{"atb":[[1.92,7.87],[1.97,12.71]],"id":39213014}],"con":true,"img":false}]}
{"op":"mcm","clk":"5322694908","pt":1646323214584,"mc":[{"id":"1.195532867","rc":[{"atb":[[1.92,0]],"id":39213014}],"con":true,"img":false}]}
{"op":"mcm","clk":"5322694929","pt":1646323214791,"mc":[{"id":"1.195532867","rc":[{"atb":[[3.35,106.38]],"id":35676762}],"con":true,"img":false}]}
{"op":"mcm","clk":"5322694939","pt":1646323214896,"mc":[{"id":"1.195532867","rc":[{"atb":[[3.9,34.48],[3.65,59.77]],"id":35676762}],"con":true,"img":false}]}
{"op":"mcm","clk":"5322694966","pt":1646323215314,"mc":[{"id":"1.195532867","rc":[{"atb":[[2.3,29.44],[2.16,2.5]],"id":41529439}],"con":true,"img":false}]}
{"op":"mcm","clk":"5322694972","pt":1646323215417,"mc":[{"id":"1.195532867","rc":[{"atb":[[2.44,6.84]],"id":41529439}],"con":true,"img":false}]}
{"op":"mcm","clk":"5322694986","pt":1646323215628,"mc":[{"id":"1.195532867","rc":[{"atl":[[4.3,23.23]],"id":43094640},{"atb":[[2.38,0]],"id":41529439},{"atb":[[1.96,35.73],[1.93,107.53]],"id":39213014}],"con":true,"img":false}]}
{"op":"mcm","clk":"5322694994","pt":1646323215732,"mc":[{"id":"1.195532867","rc":[{"atb":[[2.18,0]],"id":41529439}],"con":true,"img":false}]}
{"op":"mcm","clk":"5322695014","pt":1646323215890,"mc":[{"id":"1.195532867","rc":[{"atb":[[2.38,7.13]],"id":41529439}],"con":true,"img":false}]}
{"op":"mcm","clk":"5322695029","pt":1646323216099,"mc":[{"id":"1.195532867","rc":[{"atb":[[2.38,0]],"id":41529439}],"con":true,"img":false}]}
{"op":"mcm","clk":"5322695078","pt":1646323216721,"mc":[{"id":"1.195532867","rc":[{"atl":[[3.5,33.62]],"id":28791281}],"con":true,"img":false}]}
{"op":"mcm","clk":"5322695085","pt":1646323216825,"mc":[{"id":"1.195532867","rc":[{"atl":[[4.7,15.34]],"id":43094640}],"con":true,"img":false}]}
{"op":"mcm","clk":"5322695097","pt":1646323216928,"mc":[{"id":"1.195532867","rc":[{"atl":[[4.3,19.33],[4.7,0]],"id":43094640}],"con":true,"img":false}]}
{"op":"mcm","clk":"5322695174","pt":1646323217503,"mc":[{"id":"1.195532867","rc":[{"atb":[[2.42,0]],"id":41529439}],"con":true,"img":false}]}
{"op":"mcm","clk":"5322695183","pt":1646323217606,"mc":[{"id":"1.195532867","rc":[{"atl":[[4.8,53.59],[5.1,3.12]],"id":43094640}],"con":true,"img":false}]}
{"op":"mcm","clk":"5322695202","pt":1646323217771,"mc":[{"id":"1.195532867","rc":[{"atl":[[5,25],[4.1,2.52]],"id":43094640},{"atb":[[4.5,1.65]],"id":35676762},{"atb":[[2.46,1.65]],"id":41529439},{"atb":[[1.96,31.59]],"id":39213014},{"atl":[[4.4,29.41]],"id":39213014}],"con":true,"img":false}]}
{"op":"mcm","clk":"5322695206","pt":1646323217814,"mc":[{"id":"1.195532867","rc":[{"atl":[[5.1,0]],"id":43094640}],"con":true,"img":false}]}
{"op":"mcm","clk":"5322695215","pt":1646323217918,"mc":[{"id":"1.195532867","rc":[{"atl":[[4.1,12.66]],"id":43094640},{"atl":[[3.5,67.24],[3.75,122.74]],"id":28791281},{"atb":[[4.5,9.5]],"id":35676762}],"con":true,"img":false}]}
{"op":"mcm","clk":"5322695225","pt":1646323218039,"mc":[{"id":"1.195532867","rc":[{"atl":[[4.3,10.53]],"id":43094640},{"atb":[[4.3,0]],"id":35676762}],"con":true,"img":false}]}
{"op":"mcm","clk":"5322695231","pt":1646323218128,"mc":[{"id":"1.195532867","rc":[{"atl":[[3.5,65.62]],"id":28791281}],"con":true,"img":false}]}
{"op":"mcm","clk":"5322695239","pt":1646323218182,"mc":[{"id":"1.195532867","rc":[{"atl":[[4.3,22.65]],"id":43094640}],"con":true,"img":false}]}
{"op":"mcm","clk":"5322695285","pt":1646323218341,"mc":[{"id":"1.195532867","rc":[{"atl":[[4.5,0]],"id":43094640}],"con":true,"img":false}]}
{"op":"mcm","clk":"5322695315","pt":1646323218599,"mc":[{"id":"1.195532867","rc":[{"atb":[[4.4,0]],"id":35676762}],"con":true,"img":false}]}
{"op":"mcm","clk":"5322695324","pt":1646323218705,"mc":[{"id":"1.195532867","rc":[{"atb":[[1.02,1.99]],"id":35676762}],"con":true,"img":false}]}
{"op":"mcm","clk":"5322695353","pt":1646323219014,"mc":[{"id":"1.195532867","rc":[{"atl":[[4.3,61.62]],"id":39213014}],"con":true,"img":false}]}
{"op":"mcm","clk":"5322695361","pt":1646323219119,"mc":[{"id":"1.195532867","rc":[{"atb":[[3.6,2.5]],"id":35676762}],"con":true,"img":false}]}
{"op":"mcm","clk":"5322695374","pt":1646323219225,"mc":[{"id":"1.195532867","rc":[{"atl":[[4.3,12.12],[4.1,35.31]],"id":43094640}],"con":true,"img":false}]}
{"op":"mcm","clk":"5322695398","pt":1646323219430,"mc":[{"id":"1.195532867","rc":[{"atl":[[4.1,32.79]],"id":43094640}],"con":true,"img":false}]}
{"op":"mcm","clk":"5322695438","pt":1646323219793,"mc":[{"id":"1.195532867","rc":[{"atb":[[3.95,33.9],[3.9,0]],"id":35676762},{"atb":[[2.18,14.36]],"id":41529439}],"con":true,"img":false}]}
{"op":"mcm","clk":"5322695476","pt":1646323220209,"mc":[{"id":"1.195532867","rc":[{"atl":[[3.55,21.51]],"id":28791281}],"con":true,"img":false}]}
{"op":"mcm","clk":"5322695529","pt":1646323220415,"mc":[{"id":"1.195532867","rc":[{"atl":[[3.6,129.5],[3.75,14.55]],"id":28791281}],"con":true,"img":false}]}
{"op":"mcm","clk":"5322695542","pt":1646323220626,"mc":[{"id":"1.195532867","rc":[{"atb":[[2.44,4.69],[2.36,2.15]],"id":41529439}],"con":true,"img":false}]}
{"op":"mcm","clk":"5322695555","pt":1646323220785,"mc":[{"id":"1.195532867","rc":[{"atl":[[3.55,0]],"id":28791281}],"con":true,"img":false}]}
{"op":"mcm","clk":"5322695574","pt":1646323221098,"mc":[{"id":"1.195532867","rc":[{"atl":[[3.5,67.24]],"id":28791281}],"con":true,"img":false}]}
{"op":"mcm","clk":"5322695596","pt":1646323221407,"mc":[{"id":"1.195532867","rc":[{"atb":[[1.98,21.1]],"id":39213014}],"con":true,"img":false}]}
{"op":"mcm","clk":"5322695604","pt":1646323221512,"mc":[{"id":"1.195532867","rc":[{"atl":[[3.95,2.42]],"id":43094640},{"atb":[[1.97,0]],"id":39213014}],"con":true,"img":false}]}
{"op":"mcm","clk":"5322695614","pt":1646323221615,"mc":[{"id":"1.195532867","rc":[{"atl":[[4.3,41.42]],"id":43094640},{"atb":[[1.96,0],[1.95,110.47]],"id":39213014}],"con":true,"img":false}]}
{"op":"mcm","clk":"5322695621","pt":1646323221719,"mc":[{"id":"1.195532867","rc":[{"atl":[[4.8,10.53]],"id":43094640}],"con":true,"img":false}]}
{"op":"mcm","clk":"5322695653","pt":1646323222086,"mc":[{"id":"1.195532867","rc":[{"atl":[[4.3,29.3],[4.1,45.69]],"id":43094640},{"atb":[[1.99,4.89]],"id":39213014}],"con":true,"img":false}]}
{"op":"mcm","clk":"5322695777","pt":1646323223701,"mc":[{"id":"1.195532867","rc":[{"atl":[[3.95,12.48]],"id":43094640}],"con":true,"img":false}]}
{"op":"mcm","clk":"5322695797","pt":1646323223909,"mc":[{"id":"1.195532867","rc":[{"atl":[[4.1,35.55]],"id":43094640}],"con":true,"img":false}]}
{"op":"mcm","clk":"5322695816","pt":1646323224118,"mc":[{"id":"1.195532867","rc":[{"atb":[[2.6,0],[2.48,67.57]],"id":26648132},{"atb":[[2.42,31.85]],"id":43094640},{"atb":[[4,33.33],[3.95,0]],"id":35676762}],"con":true,"img":false}]}
{"op":"mcm","clk":"5322695851","pt":1646323224431,"mc":[{"id":"1.195532867","rc":[{"atl":[[3.5,65.62]],"id":28791281}],"con":true,"img":false}]}
{"op":"mcm","clk":"5322695871","pt":1646323224590,"mc":[{"id":"1.195532867","rc":[{"atl":[[3.75,50.91]],"id":28791281}],"con":true,"img":false}]}
{"op":"mcm","clk":"5322695879","pt":1646323224694,"mc":[{"id":"1.195532867","rc":[{"atl":[[3.5,32]],"id":28791281}],"con":true,"img":false}]}
{"op":"mcm","clk":"5322695897","pt":1646323224902,"mc":[{"id":"1.195532867","rc":[{"atl":[[3.95,41.78]],"id":43094640},{"atl":[[3.5,0]],"id":28791281}],"con":true,"img":false}]}
{"op":"mcm","clk":"5322695904","pt":1646323225007,"mc":[{"id":"1.195532867","rc":[{"atl":[[4.1,12.9]],"id":43094640},{"atl":[[3.55,31.37]],"id":28791281}],"con":true,"img":false}]}
{"op":"mcm","clk":"5322695915","pt":1646323225110,"mc":[{"id":"1.195532867","rc":[{"atl":[[3.55,37.12]],"id":28791281}],"con":true,"img":false}]}
{"op":"mcm","clk":"5322695923","pt":1646323225215,"mc":[{"id":"1.195532867","rc":[{"atl":[[3.6,114.12],[3.55,31.37],[3.65,15.09]],"id":28791281}],"con":true,"img":false}]}
{"op":"mcm","clk":"5322695969","pt":1646323225751,"mc":[{"id":"1.195532867","rc":[{"atl":[[3.85,3.51]],"id":39213014}],"con":true,"img":false}]}
{"op":"mcm","clk":"5322695992","pt":1646323225959,"mc":[{"id":"1.195532867","rc":[{"atl":[[4.3,0],[3.95,13.56],[3.8,33.23],[4.2,70.12]],"id":39213014}],"con":true,"img":false}]}
{"op":"mcm","clk":"5322695996","pt":1646323226004,"mc":[{"id":"1.195532867","rc":[{"atl":[[4.3,5.75],[4.2,57.62]],"id":39213014}],"con":true,"img":false}]}
{"op":"mcm","clk":"5322696002","pt":1646323226108,"mc":[{"id":"1.195532867","rc":[{"atl":[[4,0],[3.85,0]],"id":39213014}],"con":true,"img":false}]}
{"op":"mcm","clk":"5322696013","pt":1646323226211,"mc":[{"id":"1.195532867","rc":[{"atl":[[3.6,0],[3.65,128.79]],"id":28791281},{"atl":[[4.3,0]],"id":39213014}],"con":true,"img":false}]}
{"op":"mcm","clk":"5322696040","pt":1646323226528,"mc":[{"id":"1.195532867","rc":[{"atl":[[3.95,0],[3.9,13.79]],"id":39213014}],"con":true,"img":false}]}
{"op":"mcm","clk":"5322696044","pt":1646323226630,"mc":[{"id":"1.195532867","rc":[{"atl":[[3.85,4.54]],"id":39213014}],"con":true,"img":false}]}
{"op":"mcm","clk":"5322696055","pt":1646323226734,"mc":[{"id":"1.195532867","rc":[{"atb":[[1.99,37.87]],"id":39213014}],"con":true,"img":false}]}
{"op":"mcm","clk":"5322696064","pt":1646323226840,"mc":[{"id":"1.195532867","rc":[{"atb":[[1.98,2.15]],"id":39213014}],"con":true,"img":false}]}
{"op":"mcm","clk":"5322696073","pt":1646323226948,"mc":[{"id":"1.195532867","rc":[{"atl":[[3.85,0]],"id":39213014}],"con":true,"img":false}]}
{"op":"mcm","clk":"5322696083","pt":1646323226999,"mc":[{"id":"1.195532867","rc":[{"atl":[[3.55,0]],"id":28791281}],"con":true,"img":false}]}
{"op":"mcm","clk":"5322696091","pt":1646323227104,"mc":[{"id":"1.195532867","rc":[{"atl":[[3.6,30.77]],"id":28791281}],"con":true,"img":false}]}
{"op":"mcm","clk":"5322696100","pt":1646323227212,"mc":[{"id":"1.195532867","rc":[{"atl":[[3.5,1.62]],"id":28791281}],"con":true,"img":false}]}
{"op":"mcm","clk":"5322696126","pt":1646323227422,"mc":[{"id":"1.195532867","rc":[{"atl":[[3.95,39.36]],"id":43094640}],"con":true,"img":false}]}
{"op":"mcm","clk":"5322696161","pt":1646323227735,"mc":[{"id":"1.195532867","rc":[{"atl":[[3.9,3.1]],"id":43094640}],"con":true,"img":false}]}
{"op":"mcm","clk":"5322696175","pt":1646323227946,"mc":[{"id":"1.195532867","rc":[{"atl":[[3.9,13.68]],"id":43094640}],"con":true,"img":false}]}
{"op":"mcm","clk":"5322696198","pt":1646323228354,"mc":[{"id":"1.195532867","rc":[{"atl":[[3.95,29.3]],"id":43094640}],"con":true,"img":false}]}
{"op":"mcm","clk":"5322696213","pt":1646323228384,"mc":[{"id":"1.195532867","rc":[{"atl":[[4,13.33],[4.1,0]],"id":43094640},{"atl":[[3.6,46.15]],"id":28791281}],"con":true,"img":false}]}
{"op":"mcm","clk":"5322696241","pt":1646323228623,"mc":[{"id":"1.195532867","rc":[{"atl":[[3.9,10.58]],"id":43094640}],"con":true,"img":false}]}
{"op":"mcm","clk":"5322696288","pt":1646323229198,"mc":[{"id":"1.195532867","rc":[{"atb":[[2.08,0],[2.2,83.33]],"id":43094640},{"atl":[[3.85,5.54]],"id":43094640},{"atb":[[1.92,2.15]],"id":28791281},{"atb":[[3.8,35.71]],"id":35676762},{"atb":[[2,37.87],[2.02,2.5],[1.97,5],[1.93,117.53]],"id":39213014}],"con":true,"img":false}]}
{"op":"mcm","clk":"5322696295","pt":1646323229303,"mc":[{"id":"1.195532867","rc":[{"atb":[[1.83,51.06],[1.91,8.63],[1.9,4.34]],"id":28791281},{"atb":[[4,0],[3.8,89.26],[3.65,15.09]],"id":35676762},{"atb":[[1.99,126.75],[1.81,0],[1.95,42.11]],"id":39213014}],"con":true,"img":false}]}
{"op":"mcm","clk":"5322696303","pt":1646323229405,"mc":[{"id":"1.195532867","rc":[{"atb":[[1.81,49.38],[1.9,74.84]],"id":28791281}],"con":true,"img":false}]}
{"op":"mcm","clk":"5322696311","pt":1646323229512,"mc":[{"id":"1.195532867","rc":[{"atb":[[1.91,0],[1.9,70.5]],"id":28791281}],"con":true,"img":false}]}
{"op":"mcm","clk":"5322696321","pt":1646323229616,"mc":[{"id":"1.195532867","rc":[{"atl":[[4,0],[3.95,42.86]],"id":43094640},{"atl":[[3.5,0]],"id":28791281}],"con":true,"img":false}]}
{"op":"mcm","clk":"5322696343","pt":1646323229827,"mc":[{"id":"1.195532867","rc":[{"atl":[[3.6,30.77],[3.7,14.81]],"id":28791281}],"con":true,"img":false}]}
{"op":"mcm","clk":"5322696361","pt":1646323230032,"mc":[{"id":"1.195532867","rc":[{"atl":[[4.3,0],[3.85,0],[3.95,86.02]],"id":43094640},{"atb":[[1.99,123.85]],"id":39213014}],"con":true,"img":false}]}
{"op":"mcm","clk":"5322696378","pt":1646323230241,"mc":[{"id":"1.195532867","rc":[{"atl":[[4.8,36.85],[3.95,56.72]],"id":43094640}],"con":true,"img":false}]}
{"op":"mcm","clk":"5322696421","pt":1646323230608,"mc":[{"id":"1.195532867","rc":[{"atl":[[4,13.33],[3.95,43.16]],"id":43094640}],"con":true,"img":false}]}
{"op":"mcm","clk":"5322696432","pt":1646323230715,"mc":[{"id":"1.195532867","rc":[{"atl":[[4.8,10.53],[3.95,77.06]],"id":43094640},{"atl":[[3.65,113.7]],"id":28791281}],"con":true,"img":false}]}
{"op":"mcm","clk":"5322696443","pt":1646323230816,"mc":[{"id":"1.195532867","rc":[{"atl":[[3.5,5.94]],"id":28791281}],"con":true,"img":false}]}
{"op":"mcm","clk":"5322696453","pt":1646323230920,"mc":[{"id":"1.195532867","rc":[{"atl":[[3.45,30.77],[3.75,14.55]],"id":28791281}],"con":true,"img":false}]}
{"op":"mcm","clk":"5322696475","pt":1646323231128,"mc":[{"id":"1.195532867","rc":[{"atb":[[1.98,0],[2.06,2.15]],"id":39213014}],"con":true,"img":false}]}
{"op":"mcm","clk":"5322696485","pt":1646323231233,"mc":[{"id":"1.195532867","rc":[{"atl":[[3.5,0]],"id":28791281},{"atb":[[2.06,4.65]],"id":39213014},{"atl":[[4.2,88.87]],"id":39213014}],"con":true,"img":false}]}
{"op":"mcm","clk":"5322696495","pt":1646323231340,"mc":[{"id":"1.195532867","rc":[{"atb":[[2,0]],"id":39213014},{"atl":[[3.8,20.67]],"id":39213014}],"con":true,"img":false}]}
{"op":"mcm","clk":"5322696509","pt":1646323231498,"mc":[{"id":"1.195532867","rc":[{"atl":[[3.4,3.35]],"id":28791281},{"atl":[[3.8,0]],"id":39213014}],"con":true,"img":false}]}
{"op":"mcm","clk":"5322696520","pt":1646323231603,"mc":[{"id":"1.195532867","rc":[{"atl":[[3.55,15.69],[3.5,16]],"id":28791281},{"atl":[[4,13.33],[4.4,115.81],[3.9,0],[4.2,33.75]],"id":39213014}],"con":true,"img":false}]}
{"op":"mcm","clk":"5322696530","pt":1646323231708,"mc":[{"id":"1.195532867","rc":[{"atl":[[3.85,13.84],[3.95,33.75],[4.4,123.39],[4.2,2.5]],"id":39213014}],"con":true,"img":false}]}
{"op":"mcm","clk":"5322696539","pt":1646323231815,"mc":[{"id":"1.195532867","rc":[{"atl":[[3.85,0]],"id":39213014}],"con":true,"img":false}]}
{"op":"mcm","clk":"5322696552","pt":1646323231921,"mc":[{"id":"1.195532867","rc":[{"atl":[[3.85,2]],"id":43094640},{"atl":[[4,0],[3.95,47.31]],"id":39213014}],"con":true,"img":false}]}
{"op":"mcm","clk":"5322696563","pt":1646323232025,"mc":[{"id":"1.195532867","rc":[{"atb":[[1.82,0]],"id":28791281},{"atl":[[4.1,12.9],[3.9,13.49]],"id":39213014}],"con":true,"img":false}]}
{"op":"mcm","clk":"5322696577","pt":1646323232130,"mc":[{"id":"1.195532867","rc":[{"atl":[[3.8,9.44]],"id":43094640}],"con":true,"img":false}]}
{"op":"mcm","clk":"5322696586","pt":1646323232234,"mc":[{"id":"1.195532867","rc":[{"atl":[[3.85,0],[3.9,0]],"id":43094640}],"con":true,"img":false}]}
{"op":"mcm","clk":"5322696596","pt":1646323232341,"mc":[{"id":"1.195532867","rc":[{"atl":[[4.4,115.81]],"id":39213014}],"con":true,"img":false}]}
{"op":"mcm","clk":"5322696608","pt":1646323232445,"mc":[{"id":"1.195532867","rc":[{"atl":[[3.8,0]],"id":43094640}],"con":true,"img":false}]}
{"op":"mcm","clk":"5322696620","pt":1646323232550,"mc":[{"id":"1.195532867","rc":[{"atl":[[4,0],[3.85,15.33],[3.8,4.64],[3.9,13.79]],"id":43094640},{"atl":[[4,13.33],[3.95,33.75],[4.1,0]],"id":39213014}],"con":true,"img":false}]}
{"op":"mcm","clk":"5322696639","pt":1646323232708,"mc":[{"id":"1.195532867","rc":[{"atl":[[3.5,109.54]],"id":28791281}],"con":true,"img":false}]}
{"op":"mcm","clk":"5322696649","pt":1646323232812,"mc":[{"id":"1.195532867","rc":[{"atl":[[3.65,0]],"id":28791281}],"con":true,"img":false}]}
{"op":"mcm","clk":"5322696768","pt":1646323233767,"mc":[{"id":"1.195532867","rc":[{"atb":[[2.06,24.77]],"id":39213014}],"con":true,"img":false}]}
{"op":"mcm","clk":"5322696787","pt":1646323233921,"mc":[{"id":"1.195532867","rc":[{"atl":[[3.95,33.9],[3.9,63.37]],"id":43094640},{"atb":[[2,42.11],[1.99,90.87],[2.06,22.27]],"id":39213014},{"atl":[[3.8,2]],"id":39213014}],"con":true,"img":false}]}
{"op":"mcm","clk":"5322696796","pt":1646323234025,"mc":[{"id":"1.195532867","rc":[{"atb":[[2,86.82],[1.99,1.99]],"id":39213014}],"con":true,"img":false}]}
{"op":"mcm","clk":"5322696803","pt":1646323234128,"mc":[{"id":"1.195532867","rc":[{"atl":[[3.8,0]],"id":43094640}],"con":true,"img":false}]}
{"op":"mcm","clk":"5322696818","pt":1646323234341,"mc":[{"id":"1.195532867","rc":[{"atb":[[2.08,3.26]],"id":39213014}],"con":true,"img":false}]}
{"op":"mcm","clk":"5322696829","pt":1646323234442,"mc":[{"id":"1.195532867","rc":[{"atb":[[2.64,26.67],[2.48,0]],"id":26648132},{"atl":[[3.95,47.46]],"id":43094640},{"atb":[[4,19.02],[3.8,53.55]],"id":35676762},{"atl":[[4,0],[3.9,27.28]],"id":39213014}],"con":true,"img":false}]}
{"op":"mcm","clk":"5322696837","pt":1646323234549,"mc":[{"id":"1.195532867","rc":[{"atl":[[3.9,49.58]],"id":43094640}],"con":true,"img":false}]}
{"op":"mcm","clk":"5322696853","pt":1646323234679,"mc":[{"id":"1.195532867","rc":[{"atb":[[3.95,4.62]],"id":35676762}],"con":true,"img":false}]}
