{"op":"mcm","clk":"5317728514","pt":1646251399897,"mc":[{"id":"1.195532873","marketDefinition":{"bspMarket":true,"turnInPlayEnabled":false,"persistenceEnabled":false,"marketBaseRate":5.0,"eventId":"31275720","eventTypeId":"4339","numberOfWinners":2,"bettingType":"ODDS","marketType":"PLACE","marketTime":"2022-03-03T17:08:00.000Z","suspendTime":"2022-03-03T17:08:00.000Z","bspReconciled":false,"complete":true,"inPlay":false,"crossMatching":false,"runnersVoidable":false,"numberOfActiveRunners":6,"betDelay":0,"status":"OPEN","runners":[{"status":"ACTIVE","sortPriority":1,"id":39727103,"name":"1. Kahuna Debbie"},{"status":"ACTIVE","sortPriority":2,"id":37569661,"name":"2. Wychwood Jules"},{"status":"ACTIVE","sortPriority":3,"id":37510843,"name":"3. To Tone Kat"},{"status":"ACTIVE","sortPriority":4,"id":36601249,"name":"4. Jeopardy Belle"},{"status":"ACTIVE","sortPriority":5,"id":38114646,"name":"5. Hazelwood Alarm"},{"status":"ACTIVE","sortPriority":6,"id":39590546,"name":"6. Cill Dubh Cooper"}],"regulators":["MR_INT"],"venue":"Romford","countryCode":"GB","discountAllowed":false,"timezone":"Europe/London","openDate":"2022-03-03T13:57:00.000Z","version":4384107316,"name":"To Be Placed","eventName":"Romford 3rd Mar"},"rc":[],"con":true,"img":false}]}
{"op":"mcm","clk":"5317728864","pt":1646251401769,"mc":[{"id":"1.195532873","marketDefinition":{"bspMarket":true,"turnInPlayEnabled":false,"persistenceEnabled":false,"marketBaseRate":5.0,"eventId":"31275720","eventTypeId":"4339","numberOfWinners":2,"bettingType":"ODDS","marketType":"PLACE","marketTime":"2022-03-03T17:08:00.000Z","suspendTime":"2022-03-03T17:08:00.000Z","bspReconciled":false,"complete":true,"inPlay":false,"crossMatching":false,"runnersVoidable":false,"numberOfActiveRunners":6,"betDelay":0,"status":"OPEN","runners":[{"status":"ACTIVE","sortPriority":1,"id":39727103,"name":"1. Kahuna Debbie"},{"status":"ACTIVE","sortPriority":2,"id":37569661,"name":"2. Wychwood Jules"},{"status":"ACTIVE","sortPriority":3,"id":37510843,"name":"3. To Tone Kat"},{"status":"ACTIVE","sortPriority":4,"id":36601249,"name":"4. Jeopardy Belle"},{"status":"ACTIVE","sortPriority":5,"id":38114646,"name":"5. Hazelwood Alarm"},{"status":"ACTIVE","sortPriority":6,"id":39590546,"name":"6. Cill Dubh Cooper"}],"regulators":["MR_INT"],"venue":"Romford","countryCode":"GB","discountAllowed":true,"timezone":"Europe/London","openDate":"2022-03-03T13:57:00.000Z","version":4384107316,"name":"To Be Placed","eventName":"Romford 3rd Mar"},"rc":[],"con":true,"img":false}]}
{"op":"mcm","clk":"5318439017","pt":1646258328260,"mc":[{"id":"1.195532873","rc":[{"atl":[[20,10]],"id":36601249},{"spn":1.0,"spf":"NaN","id":36601249}],"con":true,"img":false}]}
{"op":"mcm","clk":"5321768314","pt":1646313039952,"mc":[{"id":"1.195532873","rc":[{"atb":[[1.01,102.04]],"id":36601249},{"spn":10.5,"spf":"NaN","id":36601249},{"atb":[[1.01,102.04]],"id":39727103},{"spn":"Infinity","spf":"NaN","id":39727103},{"atb":[[1.01,102.04]],"id":38114646},{"spn":"Infinity","spf":"NaN","id":38114646},{"atb":[[1.01,102.04]],"id":39590546},{"spn":"Infinity","spf":"NaN","id":39590546},{"atb":[[1.01,102.04]],"id":37510843},{"spn":"Infinity","spf":"NaN","id":37510843},{"atb":[[1.01,102.04]],"id":37569661},{"spn":"Infinity","spf":"NaN","id":37569661}],"con":true,"img":false}]}
{"op":"mcm","clk":"5321918342","pt":1646314526744,"mc":[{"id":"1.195532873","rc":[{"atl":[[1000,5]],"id":36601249},{"atl":[[1000,5]],"id":39727103},{"spn":500.5,"spf":"NaN","id":39727103},{"atl":[[1000,5]],"id":38114646},{"spn":500.5,"spf":"NaN","id":38114646},{"atl":[[1000,5]],"id":39590546},{"spn":500.5,"spf":"NaN","id":39590546},{"atl":[[1000,5]],"id":37510843},{"spn":500.5,"spf":"NaN","id":37510843},{"atl":[[1000,5]],"id":37569661},{"spn":500.5,"spf":"NaN","id":37569661}],"con":true,"img":false}]}
{"op":"mcm","clk":"5321918381","pt":1646314527049,"mc":[{"id":"1.195532873","rc":[{"atb":[[1.01,4802.04]],"id":36601249},{"atb":[[1.01,4802.04]],"id":39727103},{"atb":[[1.01,4802.04]],"id":38114646},{"atb":[[1.01,4802.04]],"id":39590546},{"atb":[[1.01,4802.04]],"id":37510843},{"atb":[[1.01,4802.04]],"id":37569661}],"con":true,"img":false}]}
{"op":"mcm","clk":"5322536890","pt":1646321457782,"mc":[{"id":"1.195532873","rc":[{"spl":[[1.01,8.24]],"id":39727103},{"spn":1.01,"spf":1.0,"id":39727103}],"con":true,"img":false}]}
{"op":"mcm","clk":"5322614904","pt":1646322395490,"mc":[{"id":"1.195532873","rc":[{"spl":[[1.01,9.24]],"id":39727103},{"spl":[[1.01,1]],"id":39590546},{"spn":1.01,"spf":1.0,"id":39590546}],"con":true,"img":false}]}
{"op":"mcm","clk":"5322799448","pt":1646324202566,"mc":[{"id":"1.195532873","marketDefinition":{"bspMarket":true,"turnInPlayEnabled":false,"persistenceEnabled":false,"marketBaseRate":5.0,"eventId":"31275720","eventTypeId":"4339","numberOfWinners":2,"bettingType":"ODDS","marketType":"PLACE","marketTime":"2022-03-03T17:08:00.000Z","suspendTime":"2022-03-03T17:08:00.000Z","bspReconciled":false,"complete":true,"inPlay":false,"crossMatching":false,"runnersVoidable":false,"numberOfActiveRunners":6,"betDelay":0,"status":"OPEN","runners":[{"status":"ACTIVE","sortPriority":1,"id":39727103,"name":"1. Kahuna Debbie"},{"status":"ACTIVE","sortPriority":2,"id":37569661,"name":"2. Wychwood Jules"},{"status":"ACTIVE","sortPriority":3,"id":37510843,"name":"3. To Tone Kat"},{"status":"ACTIVE","sortPriority":4,"id":36601249,"name":"4. Jeopardy Belle"},{"status":"ACTIVE","sortPriority":5,"id":38114646,"name":"5. Hazelwood Alarm"},{"status":"ACTIVE","sortPriority":6,"id":39590546,"name":"6. Cill Dubh Cooper"}],"regulators":["MR_INT"],"venue":"Romford","countryCode":"GB","discountAllowed":true,"timezone":"Europe/London","openDate":"2022-03-03T13:57:00.000Z","version":4384107316,"name":"To Be Placed","eventName":"Romford 3rd Mar"},"rc":[{"atb":[[1.01,4802.04]],"id":36601249},{"atl":[[20,10],[1000,5]],"id":36601249},{"spn":10.5,"spf":"NaN","id":36601249},{"atb":[[1.01,4802.04]],"id":39727103},{"spl":[[1.01,9.22]],"id":39727103},{"atl":[[1000,5]],"id":39727103},{"spn":1.01,"spf":1.0,"id":39727103},{"atb":[[1.01,4802.04]],"id":38114646},{"atl":[[1000,5]],"id":38114646},{"spn":500.5,"spf":"NaN","id":38114646},{"atb":[[1.01,4802.04]],"id":39590546},{"spl":[[1.01,1]],"id":39590546},{"atl":[[1000,5]],"id":39590546},{"spn":1.01,"spf":1.0,"id":39590546},{"atb":[[1.01,4802.04]],"id":37510843},{"atl":[[1000,5]],"id":37510843},{"spn":500.5,"spf":"NaN","id":37510843},{"atb":[[1.01,4802.04]],"id":37569661},{"atl":[[1000,5]],"id":37569661},{"spn":500.5,"spf":"NaN","id":37569661}],"con":true,"img":true}]}
{"op":"mcm","clk":"5322931634","pt":1646325485424,"mc":[{"id":"1.195532873","rc":[{"atb":[[1.01,5052.04]],"id":36601249},{"atl":[[22,1.9],[24,4.35],[26,6],[28,9.26]],"id":36601249},{"atb":[[1.01,5052.04]],"id":39727103},{"spl":[[1.01,9.22]],"id":39727103},{"atb":[[1.01,5052.04]],"id":38114646},{"atb":[[1.01,5052.04]],"id":39590546},{"atb":[[1.01,5052.04]],"id":37510843},{"atb":[[1.01,5052.04]],"id":37569661}],"con":true,"img":false}]}
{"op":"mcm","clk":"5322933856","pt":1646325510924,"mc":[{"id":"1.195532873","marketDefinition":{"bspMarket":true,"turnInPlayEnabled":false,"persistenceEnabled":false,"marketBaseRate":5.0,"eventId":"31275720","eventTypeId":"4339","numberOfWinners":2,"bettingType":"ODDS","marketType":"PLACE","marketTime":"2022-03-03T17:08:00.000Z","suspendTime":"2022-03-03T17:08:00.000Z","bspReconciled":false,"complete":true,"inPlay":false,"crossMatching":true,"runnersVoidable":false,"numberOfActiveRunners":6,"betDelay":0,"status":"OPEN","runners":[{"status":"ACTIVE","sortPriority":1,"id":39727103,"name":"1. Kahuna Debbie"},{"status":"ACTIVE","sortPriority":2,"id":37569661,"name":"2. Wychwood Jules"},{"status":"ACTIVE","sortPriority":3,"id":37510843,"name":"3. To Tone Kat"},{"status":"ACTIVE","sortPriority":4,"id":36601249,"name":"4. Jeopardy Belle"},{"status":"ACTIVE","sortPriority":5,"id":38114646,"name":"5. Hazelwood Alarm"},{"status":"ACTIVE","sortPriority":6,"id":39590546,"name":"6. Cill Dubh Cooper"}],"regulators":["MR_INT"],"venue":"Romford","countryCode":"GB","discountAllowed":true,"timezone":"Europe/London","openDate":"2022-03-03T13:57:00.000Z","version":4384107316,"name":"To Be Placed","eventName":"Romford 3rd Mar"},"rc":[],"con":true,"img":false}]}
{"op":"mcm","clk":"5322951945","pt":1646325706934,"mc":[{"id":"1.195532873","rc":[{"atl":[[46,2.74]],"id":36601249},{"atl":[[46,2.74]],"id":39727103},{"atl":[[46,2.74]],"id":38114646},{"spn":23.5,"spf":"NaN","id":38114646},{"atl":[[46,2.74]],"id":39590546},{"atl":[[46,2.74]],"id":37510843},{"spn":23.5,"spf":"NaN","id":37510843},{"atl":[[46,2.74]],"id":37569661},{"spn":23.5,"spf":"NaN","id":37569661}],"con":true,"img":false}]}
{"op":"mcm","clk":"5322952460","pt":1646325712386,"mc":[{"id":"1.195532873","rc":[{"atl":[[70,2.17],[80,3.16],[50,1],[60,1.69]],"id":39727103},{"atl":[[70,2.17],[80,3.16],[50,1],[60,1.69]],"id":38114646},{"atl":[[70,2.17],[80,3.16],[50,1],[60,1.69]],"id":39590546},{"atl":[[70,2.17],[80,3.16],[50,1],[60,1.69]],"id":37510843},{"atl":[[70,2.17],[80,3.16],[50,1],[60,1.69]],"id":37569661}],"con":true,"img":false}]}
{"op":"mcm","clk":"5323017509","pt":1646326464023,"mc":[{"id":"1.195532873","rc":[{"atb":[[1.01,5054.04]],"id":39727103}],"con":true,"img":false}]}
{"op":"mcm","clk":"5323017528","pt":1646326464190,"mc":[{"id":"1.195532873","rc":[{"atb":[[1.01,5056.03],[1.62,161.29]],"id":39727103},{"atl":[[10,2]],"id":39727103}],"con":true,"img":false}]}
{"op":"mcm","clk":"5323017534","pt":1646326464296,"mc":[{"id":"1.195532873","rc":[{"atb":[[2.32,75.76]],"id":36601249},{"atl":[[19.5,4.35]],"id":36601249},{"atb":[[1.27,370.37]],"id":38114646},{"atl":[[6.6,2]],"id":38114646},{"atb":[[1.41,243.9]],"id":39590546},{"atl":[[7,2]],"id":39590546},{"atb":[[1.69,144.93]],"id":37510843},{"atl":[[13,2]],"id":37510843},{"atb":[[1.55,181.82]],"id":37569661},{"atl":[[8.4,2]],"id":37569661}],"con":true,"img":false}]}
{"op":"mcm","clk":"5323017541","pt":1646326464397,"mc":[{"id":"1.195532873","rc":[{"atb":[[1.01,5054.04]],"id":39727103}],"con":true,"img":false}]}
{"op":"mcm","clk":"5323017549","pt":1646326464500,"mc":[{"id":"1.195532873","rc":[{"atb":[[1.02,1.99]],"id":39727103}],"con":true,"img":false}]}
{"op":"mcm","clk":"5323017553","pt":1646326464605,"mc":[{"id":"1.195532873","rc":[{"atb":[[1.01,5054.04]],"id":37569661}],"con":true,"img":false}]}
{"op":"mcm","clk":"5323017567","pt":1646326464814,"mc":[{"id":"1.195532873","rc":[{"atb":[[1.01,5056.03]],"id":37569661}],"con":true,"img":false}]}
{"op":"mcm","clk":"5323017576","pt":1646326465018,"mc":[{"id":"1.195532873","rc":[{"atb":[[1.01,5054.04]],"id":37569661}],"con":true,"img":false}]}
{"op":"mcm","clk":"5323017581","pt":1646326465123,"mc":[{"id":"1.195532873","rc":[{"atb":[[1.02,1.99]],"id":37569661}],"con":true,"img":false}]}
{"op":"mcm","clk":"5323017593","pt":1646326465287,"mc":[{"id":"1.195532873","rc":[{"atb":[[1.01,5054.04]],"id":37510843}],"con":true,"img":false}]}
{"op":"mcm","clk":"5323017605","pt":1646326465491,"mc":[{"id":"1.195532873","rc":[{"atb":[[1.01,5056.03]],"id":37510843}],"con":true,"img":false}]}
{"op":"mcm","clk":"5323017617","pt":1646326465702,"mc":[{"id":"1.195532873","rc":[{"atb":[[1.01,5054.04]],"id":37510843}],"con":true,"img":false}]}
{"op":"mcm","clk":"5323017623","pt":1646326465806,"mc":[{"id":"1.195532873","rc":[{"atb":[[1.02,1.99]],"id":37510843}],"con":true,"img":false}]}
{"op":"mcm","clk":"5323017633","pt":1646326465911,"mc":[{"id":"1.195532873","rc":[{"atb":[[1.01,5054.04]],"id":36601249}],"con":true,"img":false}]}
{"op":"mcm","clk":"5323017640","pt":1646326466014,"mc":[{"id":"1.195532873","rc":[{"atb":[[1.01,5056.03]],"id":36601249}],"con":true,"img":false}]}
{"op":"mcm","clk":"5323017656","pt":1646326466224,"mc":[{"id":"1.195532873","rc":[{"atb":[[1.01,5054.04]],"id":36601249}],"con":true,"img":false}]}
{"op":"mcm","clk":"5323017662","pt":1646326466327,"mc":[{"id":"1.195532873","rc":[{"atb":[[1.02,1.99]],"id":36601249}],"con":true,"img":false}]}
{"op":"mcm","clk":"5323017681","pt":1646326466588,"mc":[{"id":"1.195532873","rc":[{"atb":[[1.01,5054.04]],"id":38114646}],"con":true,"img":false}]}
{"op":"mcm","clk":"5323017693","pt":1646326466797,"mc":[{"id":"1.195532873","rc":[{"atb":[[1.01,5056.03]],"id":38114646}],"con":true,"img":false}]}
{"op":"mcm","clk":"5323017714","pt":1646326467002,"mc":[{"id":"1.195532873","rc":[{"atb":[[1.01,5054.04]],"id":38114646}],"con":true,"img":false}]}
{"op":"mcm","clk":"5323017721","pt":1646326467116,"mc":[{"id":"1.195532873","rc":[{"atb":[[1.02,1.99]],"id":38114646}],"con":true,"img":false}]}
{"op":"mcm","clk":"5323017732","pt":1646326467224,"mc":[{"id":"1.195532873","rc":[{"atb":[[1.01,5054.04]],"id":39590546}],"con":true,"img":false}]}
{"op":"mcm","clk":"5323017748","pt":1646326467422,"mc":[{"id":"1.195532873","rc":[{"atb":[[1.01,5056.03]],"id":39590546}],"con":true,"img":false}]}
{"op":"mcm","clk":"5323017762","pt":1646326467628,"mc":[{"id":"1.195532873","rc":[{"atb":[[1.01,5054.04]],"id":39590546}],"con":true,"img":false}]}
{"op":"mcm","clk":"5323017771","pt":1646326467732,"mc":[{"id":"1.195532873","rc":[{"atb":[[1.02,1.99]],"id":39590546}],"con":true,"img":false}]}
{"op":"mcm","clk":"5323017844","pt":1646326468620,"mc":[{"id":"1.195532873","rc":[{"atb":[[1.02,0]],"id":39727103}],"con":true,"img":false}]}
{"op":"mcm","clk":"5323017855","pt":1646326468725,"mc":[{"id":"1.195532873","rc":[{"atb":[[1.63,1.99]],"id":39727103}],"con":true,"img":false}]}
{"op":"mcm","clk":"5323017866","pt":1646326468932,"mc":[{"id":"1.195532873","rc":[{"atl":[[22,0]],"id":36601249},{"atl":[[50,0]],"id":38114646},{"atb":[[1.39,102.56]],"id":39590546},{"atl":[[7.4,6.25],[50,0]],"id":39590546},{"atb":[[1.67,59.7]],"id":37510843},{"atl":[[50,0],[14,3.08]],"id":37510843},{"atb":[[1.02,0],[1.53,75.47]],"id":37569661},{"atl":[[50,0],[8.8,5.13]],"id":37569661}],"con":true,"img":false}]}
{"op":"mcm","clk":"5323017876","pt":1646326469036,"mc":[{"id":"1.195532873","rc":[{"atb":[[2.28,31.25]],"id":36601249},{"atl":[[21,2]],"id":36601249},{"atb":[[1.25,160]],"id":38114646},{"atl":[[7,6.67]],"id":38114646},{"atb":[[1.56,1.99]],"id":37569661}],"con":true,"img":false}]}
{"op":"mcm","clk":"5323017896","pt":1646326469193,"mc":[{"id":"1.195532873","rc":[{"atb":[[1.02,0]],"id":37510843}],"con":true,"img":false}]}
{"op":"mcm","clk":"5323017903","pt":1646326469299,"mc":[{"id":"1.195532873","rc":[{"atb":[[1.7,1.99]],"id":37510843}],"con":true,"img":false}]}
{"op":"mcm","clk":"5323017914","pt":1646326469401,"mc":[{"id":"1.195532873","rc":[{"atb":[[1.02,0]],"id":36601249}],"con":true,"img":false}]}
{"op":"mcm","clk":"5323017922","pt":1646326469507,"mc":[{"id":"1.195532873","rc":[{"atb":[[2.34,1.99]],"id":36601249}],"con":true,"img":false}]}
{"op":"mcm","clk":"5323017940","pt":1646326469715,"mc":[{"id":"1.195532873","rc":[{"atb":[[1.02,0]],"id":38114646}],"con":true,"img":false}]}
{"op":"mcm","clk":"5323017947","pt":1646326469818,"mc":[{"id":"1.195532873","rc":[{"atb":[[1.28,1.99]],"id":38114646}],"con":true,"img":false}]}
{"op":"mcm","clk":"5323017964","pt":1646326470041,"mc":[{"id":"1.195532873","rc":[{"atb":[[1.02,0]],"id":39590546}],"con":true,"img":false}]}
{"op":"mcm","clk":"5323017971","pt":1646326470144,"mc":[{"id":"1.195532873","rc":[{"atb":[[1.42,1.99]],"id":39590546}],"con":true,"img":false}]}
{"op":"mcm","clk":"5323017993","pt":1646326470391,"mc":[{"id":"1.195532873","rc":[{"atb":[[2.36,1.65]],"id":36601249}],"con":true,"img":false}]}
{"op":"mcm","clk":"5323018029","pt":1646326471015,"mc":[{"id":"1.195532873","rc":[{"atb":[[1.61,65.57]],"id":39727103},{"atl":[[11,4],[50,0]],"id":39727103}],"con":true,"img":false}]}
{"op":"mcm","clk":"5323018118","pt":1646326472423,"mc":[{"id":"1.195532873","rc":[{"atb":[[1.02,1222.21]],"id":38114646},{"atb":[[1.02,1146.33]],"id":39590546},{"atb":[[1.02,1121.23]],"id":37569661}],"con":true,"img":false}]}
{"op":"mcm","clk":"5323018197","pt":1646326473653,"mc":[{"id":"1.195532873","rc":[{"atb":[[2.36,3.65],[2.32,0]],"id":36601249}],"con":true,"img":false}]}
{"op":"mcm","clk":"5323018386","pt":1646326476345,"mc":[{"id":"1.195532873","rc":[{"atb":[[2.34,0]],"id":36601249}],"con":true,"img":false}]}
{"op":"mcm","clk":"5323018395","pt":1646326476448,"mc":[{"id":"1.195532873","rc":[{"atb":[[2.38,1.99]],"id":36601249}],"con":true,"img":false}]}
{"op":"mcm","clk":"5323018571","pt":1646326478943,"mc":[{"id":"1.195532873","rc":[{"atb":[[2.34,29.85]],"id":36601249},{"atb":[[1.26,153.85]],"id":38114646},{"atl":[[7.4,15.62]],"id":38114646},{"atb":[[1.4,100]],"id":39590546},{"atl":[[7.8,14.71]],"id":39590546},{"atb":[[1.68,58.82]],"id":37510843},{"atl":[[15,7.14]],"id":37510843},{"atb":[[1.54,74.07]],"id":37569661},{"atl":[[9.2,12.2]],"id":37569661}],"con":true,"img":false}]}
{"op":"mcm","clk":"5323018606","pt":1646326479468,"mc":[{"id":"1.195532873","rc":[{"atb":[[2.36,2]],"id":36601249}],"con":true,"img":false}]}
{"op":"mcm","clk":"5323018613","pt":1646326479625,"mc":[{"id":"1.195532873","rc":[{"atb":[[2.4,1.65]],"id":36601249}],"con":true,"img":false}]}
{"op":"mcm","clk":"5323018632","pt":1646326480044,"mc":[{"id":"1.195532873","rc":[{"atb":[[1.44,2.15]],"id":39590546},{"atb":[[1.72,2.15]],"id":37510843},{"atb":[[1.58,2.15]],"id":37569661}],"con":true,"img":false}]}
{"op":"mcm","clk":"5323018643","pt":1646326480248,"mc":[{"id":"1.195532873","rc":[{"atb":[[1.41,0],[1.44,4.31]],"id":39590546},{"atb":[[1.72,4.31],[1.69,0]],"id":37510843},{"atb":[[1.58,4.31],[1.55,0]],"id":37569661}],"con":true,"img":false}]}
{"op":"mcm","clk":"5323018650","pt":1646326480354,"mc":[{"id":"1.195532873","rc":[{"atb":[[1.56,0]],"id":37569661}],"con":true,"img":false}]}
{"op":"mcm","clk":"5323018659","pt":1646326480457,"mc":[{"id":"1.195532873","rc":[{"atb":[[1.59,1.99]],"id":37569661}],"con":true,"img":false}]}
{"op":"mcm","clk":"5323018668","pt":1646326480615,"mc":[{"id":"1.195532873","rc":[{"atb":[[1.7,0]],"id":37510843}],"con":true,"img":false}]}
{"op":"mcm","clk":"5323018672","pt":1646326480718,"mc":[{"id":"1.195532873","rc":[{"atb":[[1.73,1.99]],"id":37510843}],"con":true,"img":false}]}
{"op":"mcm","clk":"5323018676","pt":1646326480924,"mc":[{"id":"1.195532873","rc":[{"atb":[[1.59,169.49]],"id":39727103},{"atl":[[12,9.09]],"id":39727103},{"atb":[[1.42,0]],"id":39590546}],"con":true,"img":false}]}
{"op":"mcm","clk":"5323018685","pt":1646326481032,"mc":[{"id":"1.195532873","rc":[{"atb":[[1.45,1.99]],"id":39590546}],"con":true,"img":false}]}
{"op":"mcm","clk":"5323018749","pt":1646326482125,"mc":[{"id":"1.195532873","rc":[{"atb":[[1.65,2.15]],"id":39727103}],"con":true,"img":false}]}
{"op":"mcm","clk":"5323018774","pt":1646326482436,"mc":[{"id":"1.195532873","rc":[{"atb":[[1.62,0],[1.65,4.31]],"id":39727103}],"con":true,"img":false}]}
{"op":"mcm","clk":"5323018793","pt":1646326482645,"mc":[{"id":"1.195532873","rc":[{"atb":[[1.02,0]],"id":38114646},{"atb":[[1.02,0]],"id":39590546},{"atb":[[1.02,0]],"id":37569661}],"con":true,"img":false}]}
{"op":"mcm","clk":"5323018807","pt":1646326482851,"mc":[{"id":"1.195532873","rc":[{"atb":[[2.4,3.65],[2.36,0]],"id":36601249}],"con":true,"img":false}]}
{"op":"mcm","clk":"5323018828","pt":1646326483163,"mc":[{"id":"1.195532873","rc":[{"atb":[[1.63,0]],"id":39727103}],"con":true,"img":false}]}
{"op":"mcm","clk":"5323018837","pt":1646326483216,"mc":[{"id":"1.195532873","rc":[{"atb":[[1.66,1.99]],"id":39727103}],"con":true,"img":false}]}
{"op":"mcm","clk":"5323018855","pt":1646326483529,"mc":[{"id":"1.195532873","rc":[{"atb":[[2.38,0]],"id":36601249}],"con":true,"img":false}]}
{"op":"mcm","clk":"5323018860","pt":1646326483634,"mc":[{"id":"1.195532873","rc":[{"atb":[[2.42,1.99]],"id":36601249}],"con":true,"img":false}]}
{"op":"mcm","clk":"5323019128","pt":1646326488167,"mc":[{"id":"1.195532873","rc":[{"atb":[[1.28,132.65]],"id":38114646},{"atb":[[1.41,6.93]],"id":39590546},{"atb":[[1.55,6.93]],"id":37569661}],"con":true,"img":false}]}
{"op":"mcm","clk":"5323019141","pt":1646326488364,"mc":[{"id":"1.195532873","rc":[{"atb":[[1.27,0],[1.29,153.85]],"id":38114646}],"con":true,"img":false}]}
{"op":"mcm","clk":"5323019149","pt":1646326488467,"mc":[{"id":"1.195532873","rc":[{"atb":[[2.4,2]],"id":36601249}],"con":true,"img":false}]}
{"op":"mcm","clk":"5323019159","pt":1646326488572,"mc":[{"id":"1.195532873","rc":[{"atb":[[2.44,1.65]],"id":36601249}],"con":true,"img":false}]}
{"op":"mcm","clk":"5323019177","pt":1646326488730,"mc":[{"id":"1.195532873","rc":[{"atb":[[2.4,0],[2.44,3.65]],"id":36601249}],"con":true,"img":false}]}
{"op":"mcm","clk":"5323019194","pt":1646326488939,"mc":[{"id":"1.195532873","rc":[{"atb":[[2.4,28.57]],"id":36601249},{"atb":[[1.27,148.15]],"id":38114646},{"atl":[[70,0],[80,0],[7.8,22.06],[60,0]],"id":38114646},{"atb":[[1.43,93.02]],"id":39590546},{"atl":[[70,0],[80,0],[8.2,20.83],[60,0]],"id":39590546},{"atb":[[1.71,56.34]],"id":37510843},{"atl":[[16,10]],"id":37510843},{"atb":[[1.57,70.18]],"id":37569661},{"atl":[[9.6,17.44],[80,0]],"id":37569661}],"con":true,"img":false}]}
{"op":"mcm","clk":"5323019208","pt":1646326489042,"mc":[{"id":"1.195532873","rc":[{"atl":[[80,0]],"id":37510843}],"con":true,"img":false}]}
{"op":"mcm","clk":"5323019246","pt":1646326489561,"mc":[{"id":"1.195532873","rc":[{"atb":[[2.46,2.15]],"id":36601249}],"con":true,"img":false}]}
{"op":"mcm","clk":"5323019293","pt":1646326490029,"mc":[{"id":"1.195532873","rc":[{"atb":[[2.42,0]],"id":36601249}],"con":true,"img":false}]}
{"op":"mcm","clk":"5323019301","pt":1646326490133,"mc":[{"id":"1.195532873","rc":[{"atb":[[2.48,1.99]],"id":36601249}],"con":true,"img":false}]}
{"op":"mcm","clk":"5323019316","pt":1646326490341,"mc":[{"id":"1.195532873","rc":[{"atb":[[2.4,0],[2.44,31.43]],"id":36601249},{"atb":[[1.64,62.5]],"id":39727103},{"atl":[[80,0]],"id":39727103},{"atb":[[1.28,130.66]],"id":38114646},{"atl":[[70,0]],"id":37510843},{"atl":[[70,0]],"id":37569661}],"con":true,"img":false}]}
{"op":"mcm","clk":"5323019326","pt":1646326490446,"mc":[{"id":"1.195532873","rc":[{"atb":[[1.3,1.99]],"id":38114646}],"con":true,"img":false}]}
{"op":"mcm","clk":"5323019585","pt":1646326494249,"mc":[{"id":"1.195532873","rc":[{"atb":[[1.28,0]],"id":38114646},{"atb":[[1.41,0]],"id":39590546},{"atb":[[1.55,0]],"id":37569661}],"con":true,"img":false}]}
{"op":"mcm","clk":"5323019792","pt":1646326497484,"mc":[{"id":"1.195532873","rc":[{"atb":[[2.44,29.78]],"id":36601249}],"con":true,"img":false}]}
{"op":"mcm","clk":"5323019802","pt":1646326497639,"mc":[{"id":"1.195532873","rc":[{"atb":[[2.5,1.65]],"id":36601249}],"con":true,"img":false}]}
{"op":"mcm","clk":"5323019811","pt":1646326497743,"mc":[{"id":"1.195532873","rc":[{"atb":[[2.5,3.65]],"id":36601249}],"con":true,"img":false}]}
{"op":"mcm","clk":"5323019818","pt":1646326497848,"mc":[{"id":"1.195532873","rc":[{"atb":[[2.44,27.78]],"id":36601249}],"con":true,"img":false}]}
{"op":"mcm","clk":"5323019882","pt":1646326498777,"mc":[{"id":"1.195532873","rc":[{"atb":[[2.48,0]],"id":36601249}],"con":true,"img":false}]}
{"op":"mcm","clk":"5323019888","pt":1646326498880,"mc":[{"id":"1.195532873","rc":[{"atb":[[2.52,1.99]],"id":36601249}],"con":true,"img":false}]}
{"op":"mcm","clk":"5323019890","pt":1646326498985,"mc":[{"id":"1.195532873","rc":[{"atb":[[1.28,142.86],[1.27,0]],"id":38114646},{"atl":[[8.2,34.72]],"id":38114646},{"atl":[[8.6,32.89]],"id":39590546},{"atl":[[17,15.62]],"id":37510843},{"atl":[[10,27.78]],"id":37569661}],"con":true,"img":false}]}
{"op":"mcm","clk":"5323019910","pt":1646326499347,"mc":[{"id":"1.195532873","rc":[{"atb":[[1.3,111.08]],"id":38114646},{"atb":[[1.41,6.93]],"id":39590546},{"atb":[[1.55,6.93]],"id":37569661}],"con":true,"img":false}]}
{"op":"mcm","clk":"5323019916","pt":1646326499451,"mc":[{"id":"1.195532873","rc":[{"atb":[[1.29,0],[1.31,142.86]],"id":38114646}],"con":true,"img":false}]}
{"op":"mcm","clk":"5323019961","pt":1646326500182,"mc":[{"id":"1.195532873","rc":[{"atb":[[1.34,2.15]],"id":38114646}],"con":true,"img":false}]}
{"op":"mcm","clk":"5323019970","pt":1646326500286,"mc":[{"id":"1.195532873","rc":[{"atb":[[2.48,27.03]],"id":36601249},{"atl":[[13,12.5]],"id":39727103}],"con":true,"img":false}]}
{"op":"mcm","clk":"5323019982","pt":1646326500390,"mc":[{"id":"1.195532873","rc":[{"atb":[[2.44,0]],"id":36601249}],"con":true,"img":false}]}
{"op":"mcm","clk":"5323020044","pt":1646326501276,"mc":[{"id":"1.195532873","rc":[{"atb":[[1.3,109.09]],"id":38114646}],"con":true,"img":false}]}
{"op":"mcm","clk":"5323020054","pt":1646326501383,"mc":[{"id":"1.195532873","rc":[{"atb":[[2.54,2.15]],"id":36601249},{"atb":[[1.35,1.99]],"id":38114646}],"con":true,"img":false}]}
{"op":"mcm","clk":"5323020062","pt":1646326501489,"mc":[{"id":"1.195532873","rc":[{"atb":[[2.54,4.31],[2.46,0]],"id":36601249}],"con":true,"img":false}]}
{"op":"mcm","clk":"5323020070","pt":1646326501591,"mc":[{"id":"1.195532873","rc":[{"atb":[[2.5,1.65],[2.52,6.31]],"id":36601249}],"con":true,"img":false}]}
{"op":"mcm","clk":"5323020078","pt":1646326501701,"mc":[{"id":"1.195532873","rc":[{"atb":[[2.54,2.15]],"id":36601249}],"con":true,"img":false}]}
{"op":"mcm","clk":"5323020102","pt":1646326502066,"mc":[{"id":"1.195532873","rc":[{"atb":[[2.52,4.32]],"id":36601249}],"con":true,"img":false}]}
{"op":"mcm","clk":"5323020110","pt":1646326502168,"mc":[{"id":"1.195532873","rc":[{"atb":[[2.56,1.99]],"id":36601249}],"con":true,"img":false}]}
{"op":"mcm","clk":"5323020118","pt":1646326502275,"mc":[{"id":"1.195532873","rc":[{"atb":[[2.56,4.15],[2.52,0]],"id":36601249}],"con":true,"img":false}]}
{"op":"mcm","clk":"5323020241","pt":1646326503783,"mc":[{"id":"1.195532873","rc":[{"atb":[[1.3,0]],"id":38114646}],"con":true,"img":false}]}
{"op":"mcm","clk":"5323020558","pt":1646326508404,"mc":[{"id":"1.195532873","rc":[{"atb":[[1.31,0],[1.35,4.15]],"id":38114646}],"con":true,"img":false}]}
{"op":"mcm","clk":"5323020570","pt":1646326508615,"mc":[{"id":"1.195532873","rc":[{"atb":[[1.29,5.38]],"id":38114646}],"con":true,"img":false}]}
{"op":"mcm","clk":"5323020593","pt":1646326508985,"mc":[{"id":"1.195532873","rc":[{"atb":[[1.28,0],[1.33,121.21]],"id":38114646},{"atl":[[60,0]],"id":37510843},{"atl":[[60,0]],"id":37569661}],"con":true,"img":false}]}
{"op":"mcm","clk":"5323020670","pt":1646326510281,"mc":[{"id":"1.195532873","rc":[{"atb":[[2.52,26.32],[2.48,0]],"id":36601249},{"atl":[[70,0],[14,19.23]],"id":39727103}],"con":true,"img":false}]}
{"op":"mcm","clk":"5323020870","pt":1646326513295,"mc":[{"id":"1.195532873","rc":[{"atb":[[1.29,0]],"id":38114646}],"con":true,"img":false}]}
{"op":"mcm","clk":"5323020912","pt":1646326513812,"mc":[{"id":"1.195532873","rc":[{"atl":[[60,0]],"id":39727103}],"con":true,"img":false}]}
{"op":"mcm","clk":"5323021009","pt":1646326515578,"mc":[{"id":"1.195532873","rc":[{"atb":[[2.5,0]],"id":36601249}],"con":true,"img":false}]}
{"op":"mcm","clk":"5323021018","pt":1646326515788,"mc":[{"id":"1.195532873","rc":[{"atb":[[2.58,1.65]],"id":36601249}],"con":true,"img":false}]}
{"op":"mcm","clk":"5323021147","pt":1646326517814,"mc":[{"id":"1.195532873","rc":[{"atb":[[1.27,6.64]],"id":38114646}],"con":true,"img":false}]}
{"op":"mcm","clk":"5323021220","pt":1646326519010,"mc":[{"id":"1.195532873","rc":[{"atb":[[1.31,250]],"id":38114646}],"con":true,"img":false}]}
{"op":"mcm","clk":"5323021258","pt":1646326519634,"mc":[{"id":"1.195532873","rc":[{"atb":[[2.54,28.12]],"id":36601249},{"atb":[[1.26,0]],"id":38114646}],"con":true,"img":false}]}
{"op":"mcm","clk":"5323021263","pt":1646326519715,"mc":[{"id":"1.195532873","rc":[{"atb":[[2.52,0]],"id":36601249}],"con":true,"img":false}]}
{"op":"mcm","clk":"5323021269","pt":1646326519813,"mc":[{"id":"1.195532873","rc":[{"atb":[[2.28,0]],"id":36601249}],"con":true,"img":false}]}
{"op":"mcm","clk":"5323021448","pt":1646326522220,"mc":[{"id":"1.195532873","rc":[{"atb":[[1.27,0]],"id":38114646}],"con":true,"img":false}]}
{"op":"mcm","clk":"5323021809","pt":1646326526912,"mc":[{"id":"1.195532873","rc":[{"spn":11.04,"spf":"NaN","id":36601249},{"spn":1.64,"spf":1.0,"id":39727103},{"atb":[[1.36,2.9]],"id":38114646},{"spn":3.98,"spf":"NaN","id":38114646},{"spn":1.45,"spf":1.0,"id":39590546},{"spn":7.36,"spf":"NaN","id":37510843},{"spn":4.99,"spf":"NaN","id":37569661}],"con":true,"img":false}]}
{"op":"mcm","clk":"5323021831","pt":1646326527223,"mc":[{"id":"1.195532873","rc":[{"atb":[[1.35,2.16]],"id":38114646}],"con":true,"img":false}]}
{"op":"mcm","clk":"5323021837","pt":1646326527327,"mc":[{"id":"1.195532873","rc":[{"atb":[[1.37,1.99]],"id":38114646}],"con":true,"img":false}]}
{"op":"mcm","clk":"5323021848","pt":1646326527459,"mc":[{"id":"1.195532873","rc":[{"atb":[[1.37,4.15],[1.35,0]],"id":38114646}],"con":true,"img":false}]}
{"op":"mcm","clk":"5323021854","pt":1646326527510,"mc":[{"id":"1.195532873","rc":[{"atb":[[1.36,6.88],[1.37,1.99]],"id":38114646}],"con":true,"img":false}]}
{"op":"mcm","clk":"5323021954","pt":1646326529016,"mc":[{"id":"1.195532873","rc":[{"atb":[[1.33,0],[1.35,114.29]],"id":38114646}],"con":true,"img":false}]}
{"op":"mcm","clk":"5323021990","pt":1646326529640,"mc":[{"id":"1.195532873","rc":[{"atb":[[2.5,66.67]],"id":36601249}],"con":true,"img":false}]}
{"op":"mcm","clk":"5323022164","pt":1646326531949,"mc":[{"id":"1.195532873","rc":[{"atb":[[1.36,3.98]],"id":38114646}],"con":true,"img":false}]}
{"op":"mcm","clk":"5323022509","pt":1646326536135,"mc":[{"id":"1.195532873","rc":[{"atb":[[1.76,13.21]],"id":39590546}],"con":true,"img":false}]}
{"op":"mcm","clk":"5323022558","pt":1646326536711,"mc":[{"id":"1.195532873","rc":[{"atb":[[1.32,7.15]],"id":38114646}],"con":true,"img":false}]}
{"op":"mcm","clk":"5323022569","pt":1646326536817,"mc":[{"id":"1.195532873","rc":[{"atb":[[1.45,0]],"id":39590546}],"con":true,"img":false}]}
{"op":"mcm","clk":"5323022578","pt":1646326536917,"mc":[{"id":"1.195532873","rc":[{"atb":[[1.77,1.99]],"id":39590546}],"con":true,"img":false}]}
{"op":"mcm","clk":"5323022588","pt":1646326537021,"mc":[{"id":"1.195532873","rc":[{"atb":[[1.44,2.15],[1.77,6.31]],"id":39590546}],"con":true,"img":false}]}
{"op":"mcm","clk":"5323022643","pt":1646326537748,"mc":[{"id":"1.195532873","rc":[{"atb":[[1.76,0]],"id":39590546}],"con":true,"img":false}]}
{"op":"mcm","clk":"5323022700","pt":1646326538628,"mc":[{"id":"1.195532873","rc":[{"atb":[[1.43,0],[1.75,53.33]],"id":39590546}],"con":true,"img":false}]}
{"op":"mcm","clk":"5323022715","pt":1646326538835,"mc":[{"id":"1.195532873","rc":[{"atb":[[1.41,0]],"id":39590546}],"con":true,"img":false}]}
{"op":"mcm","clk":"5323022730","pt":1646326539044,"mc":[{"id":"1.195532873","rc":[{"atb":[[1.33,250]],"id":38114646}],"con":true,"img":false}]}
{"op":"mcm","clk":"5323022767","pt":1646326539667,"mc":[{"id":"1.195532873","rc":[{"atb":[[2.46,102.74]],"id":36601249}],"con":true,"img":false}]}
{"op":"mcm","clk":"5323022790","pt":1646326539932,"mc":[{"id":"1.195532873","rc":[{"atb":[[1.01,4804.04]],"id":36601249},{"atb":[[1.01,4804.04]],"id":38114646}],"con":true,"img":false}]}
{"op":"mcm","clk":"5323022978","pt":1646326542543,"mc":[{"id":"1.195532873","rc":[{"atb":[[1.26,13.31]],"id":38114646}],"con":true,"img":false}]}
{"op":"mcm","clk":"5323023005","pt":1646326542968,"mc":[{"id":"1.195532873","rc":[{"atb":[[1.26,0]],"id":38114646}],"con":true,"img":false}]}
{"op":"mcm","clk":"5323023110","pt":1646326544229,"mc":[{"id":"1.195532873","rc":[{"atb":[[1.32,0]],"id":38114646}],"con":true,"img":false}]}
{"op":"mcm","clk":"5323023119","pt":1646326544334,"mc":[{"id":"1.195532873","rc":[{"atb":[[1.62,6.93]],"id":39727103}],"con":true,"img":false}]}
{"op":"mcm","clk":"5323023427","pt":1646326548672,"mc":[{"id":"1.195532873","rc":[{"atb":[[1.73,136.99]],"id":39590546}],"con":true,"img":false}]}
{"op":"mcm","clk":"5323023451","pt":1646326548932,"mc":[{"id":"1.195532873","rc":[{"atb":[[1.37,6.16]],"id":38114646}],"con":true,"img":false}]}
{"op":"mcm","clk":"5323023461","pt":1646326549036,"mc":[{"id":"1.195532873","rc":[{"atb":[[1.36,0],[1.29,250],[1.38,6.17]],"id":38114646}],"con":true,"img":false}]}
{"op":"mcm","clk":"5323023507","pt":1646326549661,"mc":[{"id":"1.195532873","rc":[{"atb":[[2.42,176.06]],"id":36601249},{"atb":[[1.37,4.17]],"id":38114646}],"con":true,"img":false}]}
{"op":"mcm","clk":"5323023513","pt":1646326549767,"mc":[{"id":"1.195532873","rc":[{"atb":[[1.39,1.99]],"id":38114646}],"con":true,"img":false}]}
{"op":"mcm","clk":"5323023526","pt":1646326549872,"mc":[{"id":"1.195532873","rc":[{"atb":[[2.34,0]],"id":36601249},{"atb":[[1.36,111.11],[1.35,0]],"id":38114646},{"atb":[[1.4,0]],"id":39590546}],"con":true,"img":false}]}
{"op":"mcm","clk":"5323023551","pt":1646326550190,"mc":[{"id":"1.195532873","rc":[{"atb":[[1.37,112.28]],"id":38114646}],"con":true,"img":false}]}
{"op":"mcm","clk":"5323023558","pt":1646326550241,"mc":[{"id":"1.195532873","rc":[{"atb":[[1.36,0]],"id":38114646}],"con":true,"img":false}]}
{"op":"mcm","clk":"5323023631","pt":1646326551079,"mc":[{"id":"1.195532873","rc":[{"atb":[[1.25,0]],"id":38114646}],"con":true,"img":false}]}
{"op":"mcm","clk":"5323023823","pt":1646326553678,"mc":[{"id":"1.195532873","rc":[{"atb":[[1.37,108.11]],"id":38114646}],"con":true,"img":false}]}
{"op":"mcm","clk":"5323024115","pt":1646326558460,"mc":[{"id":"1.195532873","rc":[{"atb":[[1.34,11.95]],"id":38114646}],"con":true,"img":false}]}
{"op":"mcm","clk":"5323024128","pt":1646326558614,"mc":[{"id":"1.195532873","rc":[{"atb":[[1.71,211.27]],"id":39590546}],"con":true,"img":false}]}
{"op":"mcm","clk":"5323024185","pt":1646326559355,"mc":[{"id":"1.195532873","rc":[{"atb":[[1.44,0],[1.78,2.15]],"id":39590546}],"con":true,"img":false}]}
{"op":"mcm","clk":"5323024208","pt":1646326559656,"mc":[{"id":"1.195532873","rc":[{"atb":[[1.77,4.32]],"id":39590546}],"con":true,"img":false}]}
{"op":"mcm","clk":"5323024215","pt":1646326559763,"mc":[{"id":"1.195532873","rc":[{"atb":[[1.79,1.99]],"id":39590546}],"con":true,"img":false}]}
{"op":"mcm","clk":"5323024229","pt":1646326559926,"mc":[{"id":"1.195532873","rc":[{"atb":[[1.79,4.15],[1.77,0]],"id":39590546}],"con":true,"img":false}]}
{"op":"mcm","clk":"5323024239","pt":1646326560036,"mc":[{"id":"1.195532873","rc":[{"atb":[[1.77,51.95]],"id":39590546}],"con":true,"img":false}]}
{"op":"mcm","clk":"5323024250","pt":1646326560137,"mc":[{"id":"1.195532873","rc":[{"atb":[[1.35,250]],"id":38114646},{"atb":[[1.75,0]],"id":39590546}],"con":true,"img":false}]}
{"op":"mcm","clk":"5323024335","pt":1646326561439,"mc":[{"id":"1.195532873","rc":[{"atb":[[1.29,0]],"id":38114646},{"atb":[[1.01,4804.04]],"id":39590546}],"con":true,"img":false}]}
{"op":"mcm","clk":"5323024418","pt":1646326562635,"mc":[{"id":"1.195532873","rc":[{"atb":[[1.34,2.15]],"id":38114646}],"con":true,"img":false}]}
{"op":"mcm","clk":"5323024698","pt":1646326567064,"mc":[{"id":"1.195532873","rc":[{"atb":[[1.39,7.7]],"id":38114646}],"con":true,"img":false}]}
{"op":"mcm","clk":"5323024704","pt":1646326567168,"mc":[{"id":"1.195532873","rc":[{"atb":[[1.4,7.7]],"id":38114646}],"con":true,"img":false}]}
{"op":"mcm","clk":"5323024712","pt":1646326567273,"mc":[{"id":"1.195532873","rc":[{"atb":[[1.38,0]],"id":38114646}],"con":true,"img":false}]}
{"op":"mcm","clk":"5323024807","pt":1646326568786,"mc":[{"id":"1.195532873","rc":[{"atb":[[1.37,0],[1.38,105.26]],"id":38114646}],"con":true,"img":false}]}
{"op":"mcm","clk":"5323024854","pt":1646326569465,"mc":[{"id":"1.195532873","rc":[{"atb":[[1.39,5.71]],"id":38114646}],"con":true,"img":false}]}
{"op":"mcm","clk":"5323024861","pt":1646326569560,"mc":[{"id":"1.195532873","rc":[{"atb":[[1.41,1.99]],"id":38114646}],"con":true,"img":false}]}
{"op":"mcm","clk":"5323024901","pt":1646326570083,"mc":[{"id":"1.195532873","rc":[{"atb":[[1.42,2.15],[1.34,0]],"id":38114646},{"atb":[[1.75,133.33]],"id":39590546}],"con":true,"img":false}]}
{"op":"mcm","clk":"5323024912","pt":1646326570149,"mc":[{"id":"1.195532873","rc":[{"atb":[[1.39,108.27],[1.38,0]],"id":38114646}],"con":true,"img":false}]}
{"op":"mcm","clk":"5323024918","pt":1646326570250,"mc":[{"id":"1.195532873","rc":[{"atb":[[1.4,0],[1.42,4.31]],"id":38114646}],"con":true,"img":false}]}
{"op":"mcm","clk":"5323024924","pt":1646326570351,"mc":[{"id":"1.195532873","rc":[{"atb":[[1.4,100],[1.39,5.71]],"id":38114646},{"atb":[[1.39,0]],"id":39590546}],"con":true,"img":false}]}
{"op":"mcm","clk":"5323024940","pt":1646326570661,"mc":[{"id":"1.195532873","rc":[{"atb":[[1.41,0]],"id":38114646}],"con":true,"img":false}]}
{"op":"mcm","clk":"5323024944","pt":1646326570758,"mc":[{"id":"1.195532873","rc":[{"atb":[[1.43,1.99]],"id":38114646}],"con":true,"img":false}]}
{"op":"mcm","clk":"5323024971","pt":1646326571184,"mc":[{"id":"1.195532873","rc":[{"atb":[[1.39,0]],"id":38114646}],"con":true,"img":false}]}
{"op":"mcm","clk":"5323025174","pt":1646326574358,"mc":[{"id":"1.195532873","rc":[{"atb":[[1.4,0],[1.41,97.56]],"id":38114646}],"con":true,"img":false}]}
{"op":"mcm","clk":"5323025249","pt":1646326575609,"mc":[{"id":"1.195532873","rc":[{"atb":[[1.36,8.82]],"id":38114646}],"con":true,"img":false}]}
{"op":"mcm","clk":"5323025547","pt":1646326580088,"mc":[{"id":"1.195532873","rc":[{"atb":[[1.73,342.47]],"id":39590546}],"con":true,"img":false}]}
{"op":"mcm","clk":"5323025554","pt":1646326580193,"mc":[{"id":"1.195532873","rc":[{"atb":[[1.73,205.48],[1.72,13]],"id":39590546}],"con":true,"img":false}]}
{"op":"mcm","clk":"5323025566","pt":1646326580403,"mc":[{"id":"1.195532873","rc":[{"atb":[[1.72,0]],"id":39590546}],"con":true,"img":false}]}
{"op":"mcm","clk":"5323025823","pt":1646326584475,"mc":[{"id":"1.195532873","rc":[{"atb":[[1.39,250]],"id":38114646}],"con":true,"img":false}]}
{"op":"mcm","clk":"5323026052","pt":1646326588085,"mc":[{"id":"1.195532873","rc":[{"atb":[[1.31,0]],"id":38114646},{"spn":4.01,"spf":"NaN","id":38114646},{"spn":1.79,"spf":1.0,"id":39590546}],"con":true,"img":false}]}
{"op":"mcm","clk":"5323026074","pt":1646326588489,"mc":[{"id":"1.195532873","rc":[{"atb":[[1.36,0]],"id":38114646}],"con":true,"img":false}]}
{"op":"mcm","clk":"5323026153","pt":1646326590103,"mc":[{"id":"1.195532873","rc":[{"atb":[[1.71,250]],"id":39590546}],"con":true,"img":false}]}
{"op":"mcm","clk":"5323026338","pt":1646326592976,"mc":[{"id":"1.195532873","rc":[{"atb":[[1.43,6.4]],"id":38114646}],"con":true,"img":false}]}
{"op":"mcm","clk":"5323026347","pt":1646326593082,"mc":[{"id":"1.195532873","rc":[{"atb":[[1.44,6.4]],"id":38114646}],"con":true,"img":false}]}
{"op":"mcm","clk":"5323026355","pt":1646326593186,"mc":[{"id":"1.195532873","rc":[{"atb":[[1.42,2.15]],"id":38114646}],"con":true,"img":false}]}
{"op":"mcm","clk":"5323026379","pt":1646326593600,"mc":[{"id":"1.195532873","rc":[{"atb":[[1.46,2.15],[1.43,4.41],[1.42,0]],"id":38114646}],"con":true,"img":false}]}
{"op":"mcm","clk":"5323026386","pt":1646326593703,"mc":[{"id":"1.195532873","rc":[{"atb":[[1.45,1.99]],"id":38114646}],"con":true,"img":false}]}
{"op":"mcm","clk":"5323026427","pt":1646326594392,"mc":[{"id":"1.195532873","rc":[{"atb":[[1.41,0],[1.4,10.7],[1.44,97.31]],"id":38114646}],"con":true,"img":false}]}
{"op":"mcm","clk":"5323026437","pt":1646326594601,"mc":[{"id":"1.195532873","rc":[{"atb":[[1.4,0]],"id":38114646}],"con":true,"img":false}]}
{"op":"mcm","clk":"5323026467","pt":1646326595016,"mc":[{"id":"1.195532873","rc":[{"atb":[[1.45,0]],"id":38114646}],"con":true,"img":false}]}
{"op":"mcm","clk":"5323026475","pt":1646326595117,"mc":[{"id":"1.195532873","rc":[{"atb":[[1.47,1.99]],"id":38114646}],"con":true,"img":false}]}
{"op":"mcm","clk":"5323026522","pt":1646326595697,"mc":[{"id":"1.195532873","rc":[{"atb":[[1.44,6.4],[1.45,88.89]],"id":38114646}],"con":true,"img":false}]}
{"op":"mcm","clk":"5323026672","pt":1646326597732,"mc":[{"id":"1.195532873","rc":[{"atb":[[1.43,0]],"id":38114646}],"con":true,"img":false}]}
{"op":"mcm","clk":"5323026860","pt":1646326601129,"mc":[{"id":"1.195532873","rc":[{"atb":[[1.44,0],[1.47,4.15]],"id":38114646}],"con":true,"img":false}]}
{"op":"mcm","clk":"5323026870","pt":1646326601330,"mc":[{"id":"1.195532873","rc":[{"atb":[[1.46,8.55],[1.47,1.99]],"id":38114646}],"con":true,"img":false}]}
{"op":"mcm","clk":"5323026958","pt":1646326602904,"mc":[{"id":"1.195532873","rc":[{"atb":[[1.47,4.89]],"id":38114646}],"con":true,"img":false}]}
{"op":"mcm","clk":"5323027124","pt":1646326605720,"mc":[{"id":"1.195532873","rc":[{"atb":[[1.43,232.56]],"id":38114646}],"con":true,"img":false}]}
{"op":"mcm","clk":"5323027347","pt":1646326609232,"mc":[{"id":"1.195532873","rc":[{"atb":[[1.46,2.15],[1.48,8.56]],"id":38114646}],"con":true,"img":false}]}
{"op":"mcm","clk":"5323027363","pt":1646326609443,"mc":[{"id":"1.195532873","rc":[{"atb":[[1.46,89.11],[1.45,0]],"id":38114646}],"con":true,"img":false}]}
{"op":"mcm","clk":"5323027372","pt":1646326609548,"mc":[{"id":"1.195532873","rc":[{"atb":[[1.46,86.96],[1.5,2.15]],"id":38114646}],"con":true,"img":false}]}
{"op":"mcm","clk":"5323027399","pt":1646326609915,"mc":[{"id":"1.195532873","rc":[{"atb":[[1.46,0],[1.48,91.89],[1.47,2.9]],"id":38114646}],"con":true,"img":false}]}
{"op":"mcm","clk":"5323027404","pt":1646326610018,"mc":[{"id":"1.195532873","rc":[{"atb":[[1.51,1.99]],"id":38114646}],"con":true,"img":false}]}
{"op":"mcm","clk":"5323027468","pt":1646326611221,"mc":[{"id":"1.195532873","rc":[{"atb":[[1.49,81.63],[1.48,8.56]],"id":38114646}],"con":true,"img":false}]}
{"op":"mcm","clk":"5323027630","pt":1646326613319,"mc":[{"id":"1.195532873","rc":[{"atb":[[1.47,0]],"id":38114646}],"con":true,"img":false}]}
{"op":"mcm","clk":"5323027876","pt":1646326617041,"mc":[{"id":"1.195532873","rc":[{"atb":[[1.51,4.15],[1.48,0]],"id":38114646}],"con":true,"img":false}]}
{"op":"mcm","clk":"5323027881","pt":1646326617146,"mc":[{"id":"1.195532873","rc":[{"atb":[[1.5,10.71],[1.51,1.99]],"id":38114646}],"con":true,"img":false}]}
{"op":"mcm","clk":"5323027910","pt":1646326617620,"mc":[{"id":"1.195532873","rc":[{"atb":[[1.51,4.89]],"id":38114646}],"con":true,"img":false}]}
{"op":"mcm","clk":"5323027914","pt":1646326617721,"mc":[{"id":"1.195532873","rc":[{"atb":[[1.5,2.15],[1.52,10.72]],"id":38114646}],"con":true,"img":false}]}
{"op":"mcm","clk":"5323027950","pt":1646326618246,"mc":[{"id":"1.195532873","rc":[{"atb":[[1.51,2.9]],"id":38114646}],"con":true,"img":false}]}
{"op":"mcm","clk":"5323027958","pt":1646326618367,"mc":[{"id":"1.195532873","rc":[{"atb":[[1.53,1.99]],"id":38114646}],"con":true,"img":false}]}
{"op":"mcm","clk":"5323028084","pt":1646326620235,"mc":[{"id":"1.195532873","rc":[{"atb":[[1.55,2.15],[1.5,0]],"id":38114646}],"con":true,"img":false}]}
{"op":"mcm","clk":"5323028098","pt":1646326620552,"mc":[{"id":"1.195532873","rc":[{"atb":[[1.53,0]],"id":38114646}],"con":true,"img":false}]}
{"op":"mcm","clk":"5323028103","pt":1646326620657,"mc":[{"id":"1.195532873","rc":[{"atb":[[1.56,1.99]],"id":38114646}],"con":true,"img":false}]}
{"op":"mcm","clk":"5323028142","pt":1646326621236,"mc":[{"id":"1.195532873","rc":[{"atb":[[1.54,74.07],[1.49,0]],"id":38114646}],"con":true,"img":false}]}
{"op":"mcm","clk":"5323028200","pt":1646326622134,"mc":[{"id":"1.195532873","rc":[{"atb":[[1.51,0]],"id":38114646}],"con":true,"img":false}]}
{"op":"mcm","clk":"5323028323","pt":1646326624057,"mc":[{"id":"1.195532873","rc":[{"atb":[[1.43,0],[1.33,0],[1.39,0],[1.35,0]],"id":38114646}],"con":true,"img":false}]}
{"op":"mcm","clk":"5323028438","pt":1646326625573,"mc":[{"id":"1.195532873","rc":[{"atb":[[1.56,4.15],[1.52,0]],"id":38114646}],"con":true,"img":false}]}
{"op":"mcm","clk":"5323028525","pt":1646326626878,"mc":[{"id":"1.195532873","rc":[{"atb":[[1.56,7.05]],"id":38114646}],"con":true,"img":false}]}
{"op":"mcm","clk":"5323028830","pt":1646326631276,"mc":[{"id":"1.195532873","rc":[{"atb":[[1.52,192.31]],"id":38114646}],"con":true,"img":false}]}
{"op":"mcm","clk":"5323028959","pt":1646326633455,"mc":[{"id":"1.195532873","rc":[{"atb":[[1.56,4.15]],"id":38114646}],"con":true,"img":false}]}
{"op":"mcm","clk":"5323029198","pt":1646326637785,"mc":[{"id":"1.195532873","rc":[{"atb":[[1.57,2.9]],"id":38114646}],"con":true,"img":false}]}
{"op":"mcm","clk":"5323029275","pt":1646326639196,"mc":[{"id":"1.195532873","rc":[{"atb":[[1.56,2.16]],"id":38114646}],"con":true,"img":false}]}
{"op":"mcm","clk":"5323029281","pt":1646326639300,"mc":[{"id":"1.195532873","rc":[{"atb":[[1.58,1.99]],"id":38114646}],"con":true,"img":false}]}
{"op":"mcm","clk":"5323029291","pt":1646326639458,"mc":[{"id":"1.195532873","rc":[{"atb":[[1.56,0],[1.58,4.15]],"id":38114646}],"con":true,"img":false}]}
{"op":"mcm","clk":"5323029355","pt":1646326640558,"mc":[{"id":"1.195532873","rc":[{"atb":[[1.56,71.43],[1.42,8.83]],"id":38114646}],"con":true,"img":false}]}
{"op":"mcm","clk":"5323029373","pt":1646326640870,"mc":[{"id":"1.195532873","rc":[{"atb":[[1.42,0]],"id":38114646}],"con":true,"img":false}]}
{"op":"mcm","clk":"5323029396","pt":1646326641286,"mc":[{"id":"1.195532873","rc":[{"atb":[[1.59,2.15],[1.55,0]],"id":38114646}],"con":true,"img":false}]}
{"op":"mcm","clk":"5323029439","pt":1646326641861,"mc":[{"id":"1.195532873","rc":[{"atb":[[1.58,2.16]],"id":38114646}],"con":true,"img":false}]}
{"op":"mcm","clk":"5323029445","pt":1646326641963,"mc":[{"id":"1.195532873","rc":[{"atb":[[1.6,1.99]],"id":38114646}],"con":true,"img":false}]}
{"op":"mcm","clk":"5323029454","pt":1646326642172,"mc":[{"id":"1.195532873","rc":[{"atb":[[1.57,0]],"id":38114646}],"con":true,"img":false}]}
{"op":"mcm","clk":"5323029601","pt":1646326644682,"mc":[{"id":"1.195532873","rc":[{"atb":[[1.58,71.13]],"id":38114646}],"con":true,"img":false}]}
{"op":"mcm","clk":"5323029690","pt":1646326646405,"mc":[{"id":"1.195532873","rc":[{"atb":[[1.57,4.14]],"id":38114646}],"con":true,"img":false}]}
{"op":"mcm","clk":"5323029740","pt":1646326646979,"mc":[{"id":"1.195532873","rc":[{"atb":[[1.58,68.97]],"id":38114646}],"con":true,"img":false}]}
{"op":"mcm","clk":"5323029751","pt":1646326647187,"mc":[{"id":"1.195532873","rc":[{"atb":[[1.6,4.15]],"id":38114646}],"con":true,"img":false}]}
{"op":"mcm","clk":"5323029755","pt":1646326647292,"mc":[{"id":"1.195532873","rc":[{"atb":[[1.59,6.3],[1.6,1.99]],"id":38114646}],"con":true,"img":false}]}
{"op":"mcm","clk":"5323029829","pt":1646326648697,"mc":[{"id":"1.195532873","rc":[{"atb":[[1.57,0]],"id":38114646},{"spn":4.1,"spf":"NaN","id":38114646}],"con":true,"img":false}]}
{"op":"mcm","clk":"5323030090","pt":1646326653282,"mc":[{"id":"1.195532873","rc":[{"atb":[[1.6,7.79]],"id":38114646}],"con":true,"img":false}]}
{"op":"mcm","clk":"5323030169","pt":1646326654638,"mc":[{"id":"1.195532873","rc":[{"atb":[[1.56,178.57]],"id":38114646}],"con":true,"img":false}]}
{"op":"mcm","clk":"5323030176","pt":1646326654691,"mc":[{"id":"1.195532873","rc":[{"atb":[[1.59,2.15],[1.61,7.8]],"id":38114646}],"con":true,"img":false}]}
{"op":"mcm","clk":"5323030202","pt":1646326655107,"mc":[{"id":"1.195532873","rc":[{"atb":[[1.6,5.8]],"id":38114646}],"con":true,"img":false}]}
{"op":"mcm","clk":"5323030210","pt":1646326655211,"mc":[{"id":"1.195532873","rc":[{"atb":[[1.62,1.99]],"id":38114646}],"con":true,"img":false}]}
{"op":"mcm","clk":"5323030262","pt":1646326655993,"mc":[{"id":"1.195532873","rc":[{"atb":[[1.6,72.47],[1.58,0]],"id":38114646}],"con":true,"img":false}]}
{"op":"mcm","clk":"5323030269","pt":1646326656098,"mc":[{"id":"1.195532873","rc":[{"atb":[[1.59,0],[1.63,2.15]],"id":38114646}],"con":true,"img":false}]}
{"op":"mcm","clk":"5323030305","pt":1646326656829,"mc":[{"id":"1.195532873","rc":[{"atb":[[1.6,5.8],[1.61,73.36]],"id":38114646}],"con":true,"img":false}]}
{"op":"mcm","clk":"5323030334","pt":1646326657302,"mc":[{"id":"1.195532873","rc":[{"atb":[[1.62,0]],"id":38114646}],"con":true,"img":false}]}
{"op":"mcm","clk":"5323030340","pt":1646326657360,"mc":[{"id":"1.195532873","rc":[{"atb":[[1.64,1.99]],"id":38114646}],"con":true,"img":false}]}
{"op":"mcm","clk":"5323030354","pt":1646326657562,"mc":[{"id":"1.195532873","rc":[{"atb":[[1.6,0],[1.62,64.52]],"id":38114646}],"con":true,"img":false}]}
{"op":"mcm","clk":"5323030361","pt":1646326657668,"mc":[{"id":"1.195532873","rc":[{"atb":[[1.61,7.8]],"id":38114646}],"con":true,"img":false}]}
{"op":"mcm","clk":"5323030524","pt":1646326660072,"mc":[{"id":"1.195532873","rc":[{"atb":[[1.64,4.89]],"id":38114646}],"con":true,"img":false}]}
{"op":"mcm","clk":"5323030633","pt":1646326662102,"mc":[{"id":"1.195532873","rc":[{"atb":[[1.65,4.89],[1.61,0]],"id":38114646}],"con":true,"img":false}]}
{"op":"mcm","clk":"5323030649","pt":1646326662308,"mc":[{"id":"1.195532873","rc":[{"atb":[[1.64,2.9]],"id":38114646}],"con":true,"img":false}]}
{"op":"mcm","clk":"5323030657","pt":1646326662421,"mc":[{"id":"1.195532873","rc":[{"atb":[[1.66,1.99]],"id":38114646}],"con":true,"img":false}]}
{"op":"mcm","clk":"5323030664","pt":1646326662516,"mc":[{"id":"1.195532873","rc":[{"atb":[[1.64,12.68],[1.65,0]],"id":38114646}],"con":true,"img":false}]}
{"op":"mcm","clk":"5323030751","pt":1646326663928,"mc":[{"id":"1.195532873","rc":[{"atb":[[1.66,0]],"id":38114646}],"con":true,"img":false}]}
{"op":"mcm","clk":"5323030759","pt":1646326663976,"mc":[{"id":"1.195532873","rc":[{"atb":[[1.65,1.99]],"id":38114646}],"con":true,"img":false}]}
{"op":"mcm","clk":"5323030908","pt":1646326666226,"mc":[{"id":"1.195532873","rc":[{"atb":[[1.64,9.78]],"id":38114646}],"con":true,"img":false}]}
{"op":"mcm","clk":"5323030935","pt":1646326666701,"mc":[{"id":"1.195532873","rc":[{"atb":[[1.63,0],[1.67,2.15]],"id":38114646}],"con":true,"img":false}]}
{"op":"mcm","clk":"5323030980","pt":1646326667487,"mc":[{"id":"1.195532873","rc":[{"atb":[[1.65,0]],"id":38114646}],"con":true,"img":false}]}
{"op":"mcm","clk":"5323030987","pt":1646326667587,"mc":[{"id":"1.195532873","rc":[{"atb":[[1.68,1.99],[1.65,61.54]],"id":38114646}],"con":true,"img":false}]}
{"op":"mcm","clk":"5323030992","pt":1646326667692,"mc":[{"id":"1.195532873","rc":[{"atb":[[1.62,0]],"id":38114646}],"con":true,"img":false}]}
{"op":"mcm","clk":"5323031093","pt":1646326669213,"mc":[{"id":"1.195532873","rc":[{"atb":[[1.65,0],[1.66,60.61]],"id":38114646}],"con":true,"img":false}]}
{"op":"mcm","clk":"5323031136","pt":1646326669815,"mc":[{"id":"1.195532873","rc":[{"atb":[[1.64,0],[1.67,11.93]],"id":38114646}],"con":true,"img":false}]}
{"op":"mcm","clk":"5323031203","pt":1646326671005,"mc":[{"id":"1.195532873","rc":[{"atb":[[1.68,4.89]],"id":38114646}],"con":true,"img":false}]}
{"op":"mcm","clk":"5323031720","pt":1646326679251,"mc":[{"id":"1.195532873","rc":[{"atb":[[1.64,156.25]],"id":38114646}],"con":true,"img":false}]}
{"op":"mcm","clk":"5323031833","pt":1646326680923,"mc":[{"id":"1.195532873","rc":[{"atb":[[1.77,55.45]],"id":39590546}],"con":true,"img":false}]}
{"op":"mcm","clk":"5323031863","pt":1646326681354,"mc":[{"id":"1.195532873","rc":[{"atb":[[1.52,0]],"id":38114646}],"con":true,"img":false}]}
{"op":"mcm","clk":"5323031869","pt":1646326681449,"mc":[{"id":"1.195532873","rc":[{"atb":[[1.77,51.95]],"id":39590546}],"con":true,"img":false}]}
{"op":"mcm","clk":"5323032380","pt":1646326689267,"mc":[{"id":"1.195532873","rc":[{"atb":[[1.55,23.26],[1.62,241.94]],"id":38114646}],"con":true,"img":false}]}
{"op":"mcm","clk":"5323032405","pt":1646326689844,"mc":[{"id":"1.195532873","rc":[{"atb":[[1.55,0]],"id":38114646}],"con":true,"img":false}]}
{"op":"mcm","clk":"5323032423","pt":1646326690261,"mc":[{"id":"1.195532873","rc":[{"atb":[[1.54,0]],"id":38114646}],"con":true,"img":false}]}
{"op":"mcm","clk":"5323032525","pt":1646326691841,"mc":[{"id":"1.195532873","rc":[{"atb":[[1.08,50]],"id":36601249},{"atb":[[1.08,50]],"id":39727103},{"atb":[[1.08,50]],"id":38114646},{"atb":[[1.08,50]],"id":39590546},{"atb":[[1.08,50]],"id":37510843},{"atb":[[1.08,50]],"id":37569661}],"con":true,"img":false}]}
{"op":"mcm","clk":"5323033025","pt":1646326700049,"mc":[{"id":"1.195532873","rc":[{"atb":[[1.6,250]],"id":38114646}],"con":true,"img":false}]}
{"op":"mcm","clk":"5323033076","pt":1646326700948,"mc":[{"id":"1.195532873","rc":[{"atb":[[1.56,0]],"id":38114646}],"con":true,"img":false}]}
{"op":"mcm","clk":"5323034682","pt":1646326729043,"mc":[{"id":"1.195532873","rc":[{"atb":[[1.63,23.26],[1.76,23.26]],"id":38114646},{"spn":4.18,"spf":"NaN","id":38114646}],"con":true,"img":false}]}
{"op":"mcm","clk":"5323034692","pt":1646326729255,"mc":[{"id":"1.195532873","rc":[{"atb":[[1.76,0]],"id":38114646}],"con":true,"img":false}]}
{"op":"mcm","clk":"5323034710","pt":1646326729962,"mc":[{"id":"1.195532873","rc":[{"atb":[[1.63,0]],"id":38114646}],"con":true,"img":false}]}
{"op":"mcm","clk":"5323037025","pt":1646326765722,"mc":[{"id":"1.195532873","rc":[{"atb":[[3.6,2.5],[2.5,86.43],[2.64,10.62],[2.58,8.03],[2.62,4.15],[2.56,1.99],[3.2,10],[3.4,5]],"id":36601249},{"atl":[[16,10],[19,4.44],[21,19.69],[12,2.5],[14,5]],"id":36601249},{"atb":[[2.36,5],[1.62,23.48],[2.28,10],[2.44,2.5],[1.66,8.23],[1.65,2.15]],"id":39727103},{"atl":[[7.2,10],[6.4,5],[10,0],[5.8,2.5],[11,13.09],[12,35.57],[9.8,6.24]],"id":39727103},{"atb":[[1.68,18.85],[1.78,5],[1.69,11.94],[1.82,2.5],[1.63,23.26],[1.67,2.15],[1.74,10],[1.66,83.87]],"id":38114646},{"atl":[[4.3,2.5],[5.1,10],[6.4,13.96],[6.2,6.67],[7.4,52.84],[6.6,0],[4.7,5]],"id":38114646},{"atb":[[2,5],[1.79,24.95],[1.74,13],[1.96,10],[1.77,64.95],[2.08,2.5]],"id":39590546},{"atl":[[4.6,2.5],[5,5],[6.8,7.8],[7,0],[7.8,35.51],[6.6,6.25],[5.4,10]],"id":39590546},{"atb":[[1.73,7.54],[2.36,2.5],[1.72,2.15],[1.8,4.32],[1.68,75.63],[2.28,5],[2.2,10]],"id":37510843},{"atl":[[5.6,5],[11,3.08],[6,10],[5.2,2.5],[12.5,5.55],[13,0],[15,31.92]],"id":37510843},{"atb":[[1.59,9.08],[1.98,2.5],[1.58,2.15],[1.55,23.48],[1.9,10],[1.94,5],[1.65,4.32]],"id":37569661},{"atl":[[5.1,5],[9.2,38.68],[5.5,10],[8.2,7.09],[7.4,5.13],[8.4,0],[4.7,2.5]],"id":37569661}],"con":true,"img":false}]}
{"op":"mcm","clk":"5323037030","pt":1646326765828,"mc":[{"id":"1.195532873","rc":[{"atl":[[19.5,0]],"id":36601249},{"atb":[[2.14,9.25]],"id":37510843}],"con":true,"img":false}]}
{"op":"mcm","clk":"5323037036","pt":1646326765933,"mc":[{"id":"1.195532873","rc":[{"atl":[[12,7.5]],"id":36601249},{"atb":[[1.71,4.32]],"id":39727103},{"atb":[[1.79,22.79],[2.06,10],[1.74,0]],"id":39590546}],"con":true,"img":false}]}
{"op":"mcm","clk":"5323037040","pt":1646326766037,"mc":[{"id":"1.195532873","rc":[{"atb":[[2.64,0]],"id":36601249},{"atl":[[16,16.67],[12,2.5]],"id":36601249},{"atb":[[2.28,18.23],[1.71,0]],"id":39727103},{"atl":[[5.5,5.12]],"id":39727103},{"atb":[[1.63,0]],"id":38114646},{"atb":[[1.79,9.79],[2.06,0],[1.96,20]],"id":39590546}],"con":true,"img":false}]}
{"op":"mcm","clk":"5323037046","pt":1646326766139,"mc":[{"id":"1.195532873","rc":[{"atb":[[1.66,6.24]],"id":39727103},{"atb":[[2,17.5],[1.96,10]],"id":39590546}],"con":true,"img":false}]}
{"op":"mcm","clk":"5323037054","pt":1646326766193,"mc":[{"id":"1.195532873","rc":[{"atb":[[2.46,1.99]],"id":39727103},{"atb":[[1.96,19.79]],"id":39590546}],"con":true,"img":false}]}
{"op":"mcm","clk":"5323037060","pt":1646326766296,"mc":[{"id":"1.195532873","rc":[{"atb":[[2,5]],"id":39590546}],"con":true,"img":false}]}
{"op":"mcm","clk":"5323037065","pt":1646326766403,"mc":[{"id":"1.195532873","rc":[{"atb":[[2.14,0]],"id":37510843},{"atb":[[1.59,7.09]],"id":37569661}],"con":true,"img":false}]}
{"op":"mcm","clk":"5323037068","pt":1646326766507,"mc":[{"id":"1.195532873","rc":[{"atb":[[1.64,0],[2.2,33.33]],"id":39727103},{"atl":[[11,9.09],[5.7,8.51]],"id":39727103},{"atb":[[1.99,1.99]],"id":37569661}],"con":true,"img":false}]}
{"op":"mcm","clk":"5323037080","pt":1646326766717,"mc":[{"id":"1.195532873","rc":[{"atb":[[1.73,5.55]],"id":37510843}],"con":true,"img":false}]}
{"op":"mcm","clk":"5323037084","pt":1646326766825,"mc":[{"id":"1.195532873","rc":[{"atb":[[1.02,1.99]],"id":37510843}],"con":true,"img":false}]}
{"op":"mcm","clk":"5323037088","pt":1646326766927,"mc":[{"id":"1.195532873","rc":[{"atb":[[1.67,0],[1.77,2.15]],"id":38114646}],"con":true,"img":false}]}
{"op":"mcm","clk":"5323037097","pt":1646326767031,"mc":[{"id":"1.195532873","rc":[{"atb":[[2.56,0]],"id":36601249}],"con":true,"img":false}]}
{"op":"mcm","clk":"5323037103","pt":1646326767136,"mc":[{"id":"1.195532873","rc":[{"atb":[[3.65,1.99]],"id":36601249}],"con":true,"img":false}]}
{"op":"mcm","clk":"5323037119","pt":1646326767448,"mc":[{"id":"1.195532873","rc":[{"atb":[[1.68,16.86]],"id":38114646}],"con":true,"img":false}]}
{"op":"mcm","clk":"5323037126","pt":1646326767549,"mc":[{"id":"1.195532873","rc":[{"atb":[[1.83,1.99]],"id":38114646}],"con":true,"img":false}]}
{"op":"mcm","clk":"5323037144","pt":1646326767812,"mc":[{"id":"1.195532873","rc":[{"atb":[[1.79,7.8]],"id":39590546}],"con":true,"img":false}]}
{"op":"mcm","clk":"5323037150","pt":1646326767919,"mc":[{"id":"1.195532873","rc":[{"atb":[[2.1,1.99]],"id":39590546}],"con":true,"img":false}]}
{"op":"mcm","clk":"5323037158","pt":1646326768126,"mc":[{"id":"1.195532873","rc":[{"atb":[[2.54,2.15],[3.4,21.67]],"id":36601249},{"atl":[[21,17.69],[13,3.33]],"id":36601249}],"con":true,"img":false}]}
{"op":"mcm","clk":"5323037167","pt":1646326768231,"mc":[{"id":"1.195532873","rc":[{"atl":[[12.5,5],[16,10]],"id":36601249},{"atb":[[1.77,54.1],[1.66,23.26]],"id":38114646},{"atl":[[4.5,11.43],[7,0]],"id":38114646},{"atl":[[4.8,10.53],[7.4,0]],"id":39590546},{"atb":[[2.26,31.75],[1.71,0]],"id":37510843},{"atl":[[14,0],[5.4,9.09]],"id":37510843},{"atb":[[1.57,0],[1.97,41.24]],"id":37569661},{"atl":[[4.9,10.26],[8.8,0]],"id":37569661}],"con":true,"img":false}]}
{"op":"mcm","clk":"5323037177","pt":1646326768438,"mc":[{"id":"1.195532873","rc":[{"atl":[[5.2,4.38]],"id":38114646},{"atl":[[5.5,4.38]],"id":39590546}],"con":true,"img":false}]}
{"op":"mcm","clk":"5323037206","pt":1646326768806,"mc":[{"id":"1.195532873","rc":[{"atb":[[2.58,6.38]],"id":36601249}],"con":true,"img":false}]}
{"op":"mcm","clk":"5323037212","pt":1646326768910,"mc":[{"id":"1.195532873","rc":[{"atb":[[3.7,1.65]],"id":36601249},{"atb":[[2.48,1.65]],"id":39727103},{"atl":[[5.2,0]],"id":38114646},{"atb":[[2.12,1.65]],"id":39590546},{"atb":[[2.38,1.65]],"id":37510843}],"con":true,"img":false}]}
{"op":"mcm","clk":"5323037219","pt":1646326769041,"mc":[{"id":"1.195532873","rc":[{"atb":[[1.62,16.55]],"id":39727103},{"atb":[[1.68,13.96]],"id":38114646},{"atl":[[5.5,0]],"id":39590546},{"atb":[[1.55,16.55]],"id":37569661}],"con":true,"img":false}]}
{"op":"mcm","clk":"5323037423","pt":1646326772039,"mc":[{"id":"1.195532873","rc":[{"atb":[[2.62,0],[3.7,3.65]],"id":36601249},{"atl":[[11,0],[5.4,5.12]],"id":39727103},{"atb":[[1.83,4.49],[1.69,0]],"id":38114646},{"atl":[[6.2,0],[4.7,18.93]],"id":38114646},{"atl":[[5,18.03],[6.6,0]],"id":39590546},{"atb":[[1.8,0],[2.38,4.15]],"id":37510843},{"atl":[[5.6,16.59],[11,0]],"id":37510843},{"atb":[[1.99,4.49],[1.65,0]],"id":37569661},{"atl":[[5.1,17.76],[7.4,0]],"id":37569661}],"con":true,"img":false}]}
{"op":"mcm","clk":"5323037442","pt":1646326772245,"mc":[{"id":"1.195532873","rc":[{"atl":[[5.6,8.7],[5.7,0]],"id":39727103}],"con":true,"img":false}]}
{"op":"mcm","clk":"5323037464","pt":1646326772510,"mc":[{"id":"1.195532873","rc":[{"atb":[[3.65,0]],"id":36601249},{"atb":[[2.04,7.8],[1.96,10]],"id":39590546}],"con":true,"img":false}]}
{"op":"mcm","clk":"5323037471","pt":1646326772616,"mc":[{"id":"1.195532873","rc":[{"atb":[[3.75,1.99]],"id":36601249}],"con":true,"img":false}]}
{"op":"mcm","clk":"5323037512","pt":1646326773445,"mc":[{"id":"1.195532873","rc":[{"atl":[[12.5,0],[13,10.83]],"id":36601249}],"con":true,"img":false}]}
{"op":"mcm","clk":"5323037517","pt":1646326773550,"mc":[{"id":"1.195532873","rc":[{"atl":[[13,3.33]],"id":36601249}],"con":true,"img":false}]}
{"op":"mcm","clk":"5323037526","pt":1646326773653,"mc":[{"id":"1.195532873","rc":[{"atl":[[14,12.69]],"id":36601249}],"con":true,"img":false}]}
{"op":"mcm","clk":"5323037589","pt":1646326774547,"mc":[{"id":"1.195532873","rc":[{"atb":[[1.79,4.93]],"id":38114646},{"atb":[[2.02,4.37]],"id":39590546},{"atb":[[1.95,4.93]],"id":37569661}],"con":true,"img":false}]}
{"op":"mcm","clk":"5323037740","pt":1646326777255,"mc":[{"id":"1.195532873","rc":[{"atb":[[2.36,10.82],[2.38,1.65]],"id":37510843}],"con":true,"img":false}]}
{"op":"mcm","clk":"5323037757","pt":1646326777671,"mc":[{"id":"1.195532873","rc":[{"atb":[[2.42,2.15],[1.65,0]],"id":39727103},{"atb":[[1.82,4.65],[1.77,51.95]],"id":38114646},{"atb":[[1.72,0],[2.42,2.15]],"id":37510843}],"con":true,"img":false}]}
{"op":"mcm","clk":"5323037765","pt":1646326777774,"mc":[{"id":"1.195532873","rc":[{"atb":[[3.3,43.48]],"id":36601249},{"atl":[[14,20.38]],"id":36601249},{"atb":[[1.75,133.33]],"id":38114646},{"atl":[[4.7,45.96]],"id":38114646},{"atl":[[5,43.03]],"id":39590546},{"atb":[[2.22,81.97]],"id":37510843},{"atl":[[5.6,38.33]],"id":37510843},{"atb":[[1.95,110.19]],"id":37569661},{"atl":[[5.1,42.15]],"id":37569661}],"con":true,"img":false}]}
{"op":"mcm","clk":"5323037768","pt":1646326777826,"mc":[{"id":"1.195532873","rc":[{"atb":[[3.7,2]],"id":36601249},{"atb":[[2.06,5]],"id":39590546}],"con":true,"img":false}]}
{"op":"mcm","clk":"5323037771","pt":1646326777930,"mc":[{"id":"1.195532873","rc":[{"atb":[[2.04,0]],"id":39590546}],"con":true,"img":false}]}
{"op":"mcm","clk":"5323037776","pt":1646326778037,"mc":[{"id":"1.195532873","rc":[{"atb":[[3.8,1.65]],"id":36601249}],"con":true,"img":false}]}
{"op":"mcm","clk":"5323037785","pt":1646326778141,"mc":[{"id":"1.195532873","rc":[{"atb":[[2.5,19.76],[2.42,0],[2.46,0]],"id":36601249},{"atl":[[28,0]],"id":36601249},{"atb":[[1.64,0],[1.6,0],[1.62,0]],"id":38114646},{"atl":[[8.2,0]],"id":38114646},{"atl":[[8.6,0],[8.2,0],[7.8,20.8]],"id":39590546},{"atb":[[1.68,16.81]],"id":37510843},{"atl":[[17,0]],"id":37510843},{"atb":[[1.54,0]],"id":37569661},{"atl":[[9.6,0],[9.2,26.48],[10,0]],"id":37569661}],"con":true,"img":false}]}
{"op":"mcm","clk":"5323037789","pt":1646326778241,"mc":[{"id":"1.195532873","rc":[{"atb":[[3.7,0],[3.8,3.65]],"id":36601249},{"atb":[[2.36,2.5],[2.42,4.31]],"id":37510843}],"con":true,"img":false}]}
{"op":"mcm","clk":"5323037799","pt":1646326778450,"mc":[{"id":"1.195532873","rc":[{"atb":[[3.6,9.79]],"id":36601249}],"con":true,"img":false}]}
{"op":"mcm","clk":"5323037841","pt":1646326779079,"mc":[{"id":"1.195532873","rc":[{"atb":[[3.6,2.5],[3.75,0]],"id":36601249}],"con":true,"img":false}]}
{"op":"mcm","clk":"5323037850","pt":1646326779181,"mc":[{"id":"1.195532873","rc":[{"atb":[[3.85,7.23],[3.4,40.97]],"id":36601249},{"atl":[[21,0],[11.5,5.24],[14,47.62]],"id":36601249},{"atb":[[2.46,7.71]],"id":39727103},{"atl":[[5.3,5.72]],"id":39727103},{"atb":[[1.79,12],[1.66,0]],"id":38114646},{"atl":[[7.4,15.62],[4.7,65.16]],"id":38114646},{"atb":[[2.02,0],[2.06,15.81],[1.77,51.95]],"id":39590546},{"atl":[[5,60.33],[7.8,0]],"id":39590546},{"atb":[[1.68,0],[2.42,9.43],[2.28,16.65]],"id":37510843},{"atl":[[5.1,5.12]],"id":37510843},{"atb":[[1.99,15.55],[1.97,59.68],[1.55,0],[1.95,105.26]],"id":37569661},{"atl":[[5.1,71.65],[4.5,11.06]],"id":37569661}],"con":true,"img":false}]}
{"op":"mcm","clk":"5323037856","pt":1646326779235,"mc":[{"id":"1.195532873","rc":[{"atb":[[2.5,0]],"id":36601249},{"atb":[[1.62,0],[2.42,13.11]],"id":39727103},{"atl":[[12,9.09],[5.6,26.24]],"id":39727103},{"atb":[[1.85,7.2]],"id":38114646},{"atl":[[4.2,7.2]],"id":38114646},{"atb":[[2.1,5.74]],"id":39590546},{"atl":[[4.5,3.75]],"id":39590546},{"atl":[[5.6,56.97],[15,7.14]],"id":37510843},{"atl":[[9.2,0]],"id":37569661}],"con":true,"img":false}]}
{"op":"mcm","clk":"5323037866","pt":1646326779342,"mc":[{"id":"1.195532873","rc":[{"atb":[[2.58,0]],"id":36601249},{"atl":[[19,0]],"id":36601249},{"atb":[[1.66,0]],"id":39727103},{"atl":[[9.8,0]],"id":39727103},{"atb":[[1.86,4.66]],"id":38114646},{"atl":[[4.1,7.2]],"id":38114646},{"atl":[[4.4,3.75]],"id":39590546},{"atb":[[1.73,0]],"id":37510843},{"atl":[[5.6,45.38],[12.5,0],[5.4,19.09]],"id":37510843},{"atb":[[1.59,0],[1.99,13.05],[1.97,100.92]],"id":37569661},{"atl":[[5.1,58.89],[8.2,0],[4.9,20.52]],"id":37569661}],"con":true,"img":false}]}
{"op":"mcm","clk":"5323037869","pt":1646326779445,"mc":[{"id":"1.195532873","rc":[{"atb":[[1.83,0],[1.68,0]],"id":38114646},{"atl":[[6.4,0],[4.7,51.23]],"id":38114646},{"atb":[[1.79,0]],"id":39590546},{"atl":[[5,47.3],[6.8,0],[4.2,25.22]],"id":39590546}],"con":true,"img":false}]}
{"op":"mcm","clk":"5323037878","pt":1646326779552,"mc":[{"id":"1.195532873","rc":[{"atb":[[1.84,11.86],[1.86,1.99]],"id":38114646},{"atl":[[4.3,16.9],[4.1,0]],"id":38114646},{"atl":[[4.6,13.03],[4.4,0]],"id":39590546}],"con":true,"img":false}]}
{"op":"mcm","clk":"5323037897","pt":1646326779864,"mc":[{"id":"1.195532873","rc":[{"atl":[[13,11.66],[14,39.93]],"id":36601249}],"con":true,"img":false}]}
{"op":"mcm","clk":"5323037912","pt":1646326780070,"mc":[{"id":"1.195532873","rc":[{"atb":[[1.81,5.34]],"id":38114646}],"con":true,"img":false}]}
{"op":"mcm","clk":"5323037943","pt":1646326780540,"mc":[{"id":"1.195532873","rc":[{"atb":[[1.81,0]],"id":38114646}],"con":true,"img":false}]}
{"op":"mcm","clk":"5323037979","pt":1646326781167,"mc":[{"id":"1.195532873","rc":[{"atl":[[12.5,3.48],[13,8.33]],"id":36601249},{"atl":[[5.6,17.54],[5.5,14.01]],"id":39727103},{"atl":[[4.5,0],[4.4,11.76]],"id":38114646},{"atl":[[4.4,11.76]],"id":39590546},{"atl":[[5.3,9.3],[5.4,10]],"id":37510843},{"atl":[[4.7,13.31]],"id":37569661}],"con":true,"img":false}]}
{"op":"mcm","clk":"5323037987","pt":1646326781273,"mc":[{"id":"1.195532873","rc":[{"atl":[[5.5,24.85],[5.4,0]],"id":39727103},{"atb":[[1.99,26.1],[1.97,59.68]],"id":37569661}],"con":true,"img":false}]}
{"op":"mcm","clk":"5323038187","pt":1646326784354,"mc":[{"id":"1.195532873","rc":[{"atl":[[4.7,15.31]],"id":37569661}],"con":true,"img":false}]}
{"op":"mcm","clk":"5323038194","pt":1646326784459,"mc":[{"id":"1.195532873","rc":[{"atb":[[1.86,8.42]],"id":38114646},{"atb":[[2.12,6.83]],"id":39590546},{"atb":[[2,9.13]],"id":37569661},{"atl":[[4.9,10.26],[4.7,37.43]],"id":37569661}],"con":true,"img":false}]}
{"op":"mcm","clk":"5323038207","pt":1646326784669,"mc":[{"id":"1.195532873","rc":[{"atl":[[4.4,35.86]],"id":38114646}],"con":true,"img":false}]}
{"op":"mcm","clk":"5323038211","pt":1646326784769,"mc":[{"id":"1.195532873","rc":[{"atl":[[4.3,2.5]],"id":38114646}],"con":true,"img":false}]}
{"op":"mcm","clk":"5323038217","pt":1646326784876,"mc":[{"id":"1.195532873","rc":[{"atb":[[1.99,24.11],[1.98,43.32],[1.97,18.44]],"id":37569661}],"con":true,"img":false}]}
{"op":"mcm","clk":"5323038224","pt":1646326784979,"mc":[{"id":"1.195532873","rc":[{"atb":[[2.02,1.99]],"id":37569661}],"con":true,"img":false}]}
{"op":"mcm","clk":"5323038238","pt":1646326785184,"mc":[{"id":"1.195532873","rc":[{"atb":[[2.1,3.75]],"id":39590546},{"atb":[[1.99,64.51],[1.98,2.5]],"id":37569661}],"con":true,"img":false}]}
{"op":"mcm","clk":"5323038245","pt":1646326785289,"mc":[{"id":"1.195532873","rc":[{"atb":[[2.14,1.99]],"id":39590546}],"con":true,"img":false}]}
{"op":"mcm","clk":"5323038268","pt":1646326785654,"mc":[{"id":"1.195532873","rc":[{"atb":[[1.84,0],[1.87,8.42]],"id":38114646}],"con":true,"img":false}]}
{"op":"mcm","clk":"5323038272","pt":1646326785758,"mc":[{"id":"1.195532873","rc":[{"atl":[[4.6,2.5],[4.1,11.76]],"id":39590546}],"con":true,"img":false}]}
{"op":"mcm","clk":"5323038313","pt":1646326786279,"mc":[{"id":"1.195532873","rc":[{"atl":[[4.3,12.12]],"id":39590546}],"con":true,"img":false}]}
{"op":"mcm","clk":"5323038344","pt":1646326786746,"mc":[{"id":"1.195532873","rc":[{"atb":[[1.86,6.43]],"id":38114646}],"con":true,"img":false}]}
{"op":"mcm","clk":"5323038353","pt":1646326786851,"mc":[{"id":"1.195532873","rc":[{"atb":[[1.88,1.99]],"id":38114646}],"con":true,"img":false}]}
{"op":"mcm","clk":"5323038365","pt":1646326787060,"mc":[{"id":"1.195532873","rc":[{"atb":[[3.8,2]],"id":36601249},{"atb":[[2.12,5.17]],"id":39590546},{"atb":[[2.38,0]],"id":37510843}],"con":true,"img":false}]}
{"op":"mcm","clk":"5323038382","pt":1646326787265,"mc":[{"id":"1.195532873","rc":[{"atb":[[2.16,1.65]],"id":39590546},{"atb":[[2.44,1.65]],"id":37510843},{"atb":[[2.04,1.65]],"id":37569661}],"con":true,"img":false}]}
{"op":"mcm","clk":"5323038387","pt":1646326787373,"mc":[{"id":"1.195532873","rc":[{"atb":[[2.02,11.13]],"id":37569661}],"con":true,"img":false}]}
{"op":"mcm","clk":"5323038392","pt":1646326787473,"mc":[{"id":"1.195532873","rc":[{"atb":[[1.99,51.46]],"id":37569661}],"con":true,"img":false}]}
{"op":"mcm","clk":"5323038419","pt":1646326787892,"mc":[{"id":"1.195532873","rc":[{"atb":[[2,49.13],[1.99,11.06]],"id":37569661}],"con":true,"img":false}]}
{"op":"mcm","clk":"5323038431","pt":1646326788101,"mc":[{"id":"1.195532873","rc":[{"atb":[[2.02,1.99]],"id":37569661}],"con":true,"img":false}]}
{"op":"mcm","clk":"5323038441","pt":1646326788260,"mc":[{"id":"1.195532873","rc":[{"atb":[[2.5,2.15],[2.42,10.96]],"id":39727103},{"atb":[[1.82,2.5],[1.9,2.15]],"id":38114646},{"atb":[[1.78,0],[2.16,3.81]],"id":39590546},{"atb":[[1.58,0],[1.94,27.26],[2.08,2.15]],"id":37569661}],"con":true,"img":false}]}
{"op":"mcm","clk":"5323038446","pt":1646326788364,"mc":[{"id":"1.195532873","rc":[{"atb":[[1.9,4.31]],"id":38114646},{"atl":[[1000,7.99]],"id":39590546},{"atl":[[4.7,35.43]],"id":37569661}],"con":true,"img":false}]}
{"op":"mcm","clk":"5323038453","pt":1646326788469,"mc":[{"id":"1.195532873","rc":[{"atl":[[5.3,0]],"id":39727103},{"atb":[[1.87,0]],"id":38114646}],"con":true,"img":false}]}
{"op":"mcm","clk":"5323038462","pt":1646326788577,"mc":[{"id":"1.195532873","rc":[{"atl":[[5.6,0],[5.8,26.24],[5.4,10.07]],"id":39727103},{"atb":[[1.86,0]],"id":38114646}],"con":true,"img":false}]}
{"op":"mcm","clk":"5323038483","pt":1646326788894,"mc":[{"id":"1.195532873","rc":[{"atb":[[2.46,5.72]],"id":39727103}],"con":true,"img":false}]}
{"op":"mcm","clk":"5323038489","pt":1646326788992,"mc":[{"id":"1.195532873","rc":[{"atb":[[2.52,1.99]],"id":39727103},{"atl":[[1000,6.06]],"id":39590546}],"con":true,"img":false}]}
{"op":"mcm","clk":"5323038493","pt":1646326789047,"mc":[{"id":"1.195532873","rc":[{"spn":7.67,"spf":"NaN","id":36601249},{"atl":[[5.6,8.7],[5.5,15.96]],"id":39727103},{"spn":2.48,"spf":1.0,"id":39727103},{"spn":3.05,"spf":"NaN","id":38114646},{"spn":2.16,"spf":1.0,"id":39590546},{"spn":3.77,"spf":"NaN","id":37510843},{"atb":[[2,9.13],[2.04,40.11]],"id":37569661},{"spn":3.29,"spf":"NaN","id":37569661}],"con":true,"img":false}]}
{"op":"mcm","clk":"5323038502","pt":1646326789160,"mc":[{"id":"1.195532873","rc":[{"atl":[[5.6,30.44],[5.5,5.12]],"id":39727103},{"atb":[[2.02,0]],"id":37569661}],"con":true,"img":false}]}
{"op":"mcm","clk":"5323038515","pt":1646326789270,"mc":[{"id":"1.195532873","rc":[{"atl":[[5.4,20.14]],"id":39727103},{"atb":[[2.1,1.99]],"id":37569661}],"con":true,"img":false}]}
{"op":"mcm","clk":"5323038519","pt":1646326789356,"mc":[{"id":"1.195532873","rc":[{"atl":[[5.6,8.7]],"id":39727103}],"con":true,"img":false}]}
{"op":"mcm","clk":"5323038533","pt":1646326789570,"mc":[{"id":"1.195532873","rc":[{"atb":[[1.88,0]],"id":38114646},{"atl":[[1000,5]],"id":39590546},{"atl":[[4.9,35.9]],"id":37569661}],"con":true,"img":false}]}
{"op":"mcm","clk":"5323038541","pt":1646326789677,"mc":[{"id":"1.195532873","rc":[{"atb":[[1.91,1.99]],"id":38114646},{"atb":[[2.16,2.75]],"id":39590546},{"trd":[[2.16,2.12]],"ltp":2.16,"tv":2.12,"id":39590546},{"atl":[[4.7,13.31]],"id":37569661}],"con":true,"img":false}]}
{"op":"mcm","clk":"5323038552","pt":1646326789883,"mc":[{"id":"1.195532873","rc":[{"atb":[[2.14,0]],"id":39590546}],"con":true,"img":false}]}
{"op":"mcm","clk":"5323038557","pt":1646326789985,"mc":[{"id":"1.195532873","rc":[{"atb":[[2.18,1.99]],"id":39590546}],"con":true,"img":false}]}
{"op":"mcm","clk":"5323038586","pt":1646326790458,"mc":[{"id":"1.195532873","rc":[{"atb":[[3.2,78.18]],"id":36601249},{"atb":[[1.73,205.48]],"id":38114646},{"atb":[[2.18,127.12]],"id":37510843}],"con":true,"img":false}]}
{"op":"mcm","clk":"5323038597","pt":1646326790666,"mc":[{"id":"1.195532873","rc":[{"atb":[[2.12,0]],"id":39590546},{"atl":[[4,2.48]],"id":39590546},{"atb":[[2,0]],"id":37569661}],"con":true,"img":false}]}
{"op":"mcm","clk":"5323038677","pt":1646326791864,"mc":[{"id":"1.195532873","rc":[{"atl":[[4.3,0],[4.2,37.72]],"id":39590546},{"atb":[[1.01,4804.04]],"id":37510843},{"atb":[[2.04,6.37],[2.06,37.74]],"id":37569661}],"con":true,"img":false}]}
{"op":"mcm","clk":"5323038692","pt":1646326792076,"mc":[{"id":"1.195532873","rc":[{"atl":[[5.7,9.1]],"id":39727103},{"atb":[[2.04,1.65]],"id":37569661}],"con":true,"img":false}]}
{"op":"mcm","clk":"5323038701","pt":1646326792175,"mc":[{"id":"1.195532873","rc":[{"atl":[[13,15.45]],"id":36601249},{"atb":[[2.4,6.44]],"id":37510843},{"atl":[[5.6,54.9]],"id":37510843}],"con":true,"img":false}]}
{"op":"mcm","clk":"5323038715","pt":1646326792389,"mc":[{"id":"1.195532873","rc":[{"atb":[[3.6,9.98],[3.4,21.67]],"id":36601249},{"atl":[[12.5,15.44],[14,12.69]],"id":36601249},{"atb":[[2.5,7.61]],"id":39727103},{"atb":[[1.82,19.39],[1.79,0]],"id":38114646},{"atl":[[4.4,62.88],[4.7,32.03]],"id":38114646},{"atb":[[2.08,13.11],[2.06,5]],"id":39590546},{"atl":[[5,30],[4.2,54.7]],"id":39590546},{"atb":[[2.36,16.95],[2.28,5]],"id":37510843},{"atb":[[2.08,20.43],[1.99,43.6],[1.97,0]],"id":37569661},{"atl":[[5.1,29.39],[4.3,18.28],[4.9,87.96]],"id":37569661}],"con":true,"img":false}]}
{"op":"mcm","clk":"5323038720","pt":1646326792492,"mc":[{"id":"1.195532873","rc":[{"atl":[[13,8.33]],"id":36601249},{"atb":[[2.44,18.12]],"id":39727103},{"atl":[[5.6,33.7],[5.7,0]],"id":39727103},{"atb":[[1.9,12.95]],"id":38114646},{"atb":[[2.16,7.63]],"id":39590546},{"atl":[[3.95,4.88]],"id":39590546},{"atb":[[2.4,0]],"id":37510843},{"atl":[[5.6,26.74],[5.3,32.42]],"id":37510843}],"con":true,"img":false}]}
{"op":"mcm","clk":"5323038725","pt":1646326792594,"mc":[{"id":"1.195532873","rc":[{"atb":[[2.42,0],[2.46,0]],"id":39727103},{"atl":[[5.8,2.5]],"id":39727103},{"atb":[[1.99,32.54]],"id":37569661},{"atl":[[4.5,0]],"id":37569661}],"con":true,"img":false}]}
{"op":"mcm","clk":"5323038733","pt":1646326792700,"mc":[{"id":"1.195532873","rc":[{"atb":[[1.85,0]],"id":38114646},{"atb":[[2.1,0]],"id":39590546},{"atl":[[4.5,0],[4.1,24.66],[4.2,42.2]],"id":39590546},{"atl":[[4.5,11.43]],"id":37569661}],"con":true,"img":false}]}
{"op":"mcm","clk":"5323038751","pt":1646326792963,"mc":[{"id":"1.195532873","rc":[{"atb":[[1.83,9.45]],"id":38114646},{"atb":[[2.08,17.61]],"id":39590546}],"con":true,"img":false}]}
{"op":"mcm","clk":"5323038762","pt":1646326793173,"mc":[{"id":"1.195532873","rc":[{"atb":[[2.08,13.11]],"id":39590546}],"con":true,"img":false}]}
{"op":"mcm","clk":"5323038766","pt":1646326793274,"mc":[{"id":"1.195532873","rc":[{"atl":[[4,0]],"id":39590546}],"con":true,"img":false}]}
{"op":"mcm","clk":"5323038774","pt":1646326793485,"mc":[{"id":"1.195532873","rc":[{"atl":[[3.95,0]],"id":39590546}],"con":true,"img":false}]}
{"op":"mcm","clk":"5323038784","pt":1646326793694,"mc":[{"id":"1.195532873","rc":[{"atl":[[4,15.56]],"id":39590546}],"con":true,"img":false}]}
{"op":"mcm","clk":"5323038822","pt":1646326794168,"mc":[{"id":"1.195532873","rc":[{"atl":[[4.1,11.76],[4.2,60.65]],"id":39590546}],"con":true,"img":false}]}
{"op":"mcm","clk":"5323038827","pt":1646326794272,"mc":[{"id":"1.195532873","rc":[{"atb":[[1.96,27.26]],"id":37569661}],"con":true,"img":false}]}
{"op":"mcm","clk":"5323038835","pt":1646326794374,"mc":[{"id":"1.195532873","rc":[{"atb":[[1.94,5]],"id":37569661}],"con":true,"img":false}]}
{"op":"mcm","clk":"5323038856","pt":1646326794691,"mc":[{"id":"1.195532873","rc":[{"atl":[[4.2,54.7]],"id":39590546}],"con":true,"img":false}]}
{"op":"mcm","clk":"5323038908","pt":1646326795615,"mc":[{"id":"1.195532873","rc":[{"atl":[[4.9,62.32],[4.7,40.34]],"id":37569661}],"con":true,"img":false}]}
{"op":"mcm","clk":"5323038923","pt":1646326795778,"mc":[{"id":"1.195532873","rc":[{"atb":[[2.48,0]],"id":39727103},{"atb":[[2.16,7.03]],"id":39590546},{"atb":[[2.04,0]],"id":37569661}],"con":true,"img":false}]}
{"op":"mcm","clk":"5323038929","pt":1646326795882,"mc":[{"id":"1.195532873","rc":[{"atb":[[2.54,1.65]],"id":39727103},{"atb":[[2.1,10.58],[2.2,1.65]],"id":39590546},{"atb":[[2,26.9],[2.12,1.65]],"id":37569661}],"con":true,"img":false}]}
{"op":"mcm","clk":"5323038935","pt":1646326795983,"mc":[{"id":"1.195532873","rc":[{"atl":[[3.95,2.48]],"id":39590546}],"con":true,"img":false}]}
{"op":"mcm","clk":"5323038938","pt":1646326796086,"mc":[{"id":"1.195532873","rc":[{"atb":[[2.46,3.19]],"id":39727103}],"con":true,"img":false}]}
{"op":"mcm","clk":"5323038942","pt":1646326796195,"mc":[{"id":"1.195532873","rc":[{"atl":[[3.95,14.24],[4.1,0]],"id":39590546}],"con":true,"img":false}]}
{"op":"mcm","clk":"5323038946","pt":1646326796297,"mc":[{"id":"1.195532873","rc":[{"atb":[[2.46,0]],"id":39727103}],"con":true,"img":false}]}
{"op":"mcm","clk":"5323038951","pt":1646326796403,"mc":[{"id":"1.195532873","rc":[{"atl":[[3.95,2.48],[4.1,18.05]],"id":39590546}],"con":true,"img":false}]}
{"op":"mcm","clk":"5323038964","pt":1646326796613,"mc":[{"id":"1.195532873","rc":[{"atb":[[1.76,20.81]],"id":38114646},{"atl":[[3.95,18.04],[4.1,0]],"id":39590546},{"atb":[[2.08,24.55]],"id":37569661}],"con":true,"img":false}]}
{"op":"mcm","clk":"5323038976","pt":1646326796773,"mc":[{"id":"1.195532873","rc":[{"atb":[[1.76,0]],"id":38114646},{"atb":[[2.08,20.43]],"id":37569661}],"con":true,"img":false}]}
{"op":"mcm","clk":"5323038996","pt":1646326797097,"mc":[{"id":"1.195532873","rc":[{"atl":[[4.1,12.9],[4.2,42.2]],"id":39590546},{"atb":[[2.08,57.47]],"id":37569661}],"con":true,"img":false}]}
{"op":"mcm","clk":"5323039000","pt":1646326797194,"mc":[{"id":"1.195532873","rc":[{"atb":[[2.34,5.22]],"id":37510843},{"atb":[[2.06,0]],"id":37569661}],"con":true,"img":false}]}
{"op":"mcm","clk":"5323039035","pt":1646326797710,"mc":[{"id":"1.195532873","rc":[{"atb":[[2.34,0]],"id":37510843}],"con":true,"img":false}]}
{"op":"mcm","clk":"5323039071","pt":1646326798289,"mc":[{"id":"1.195532873","rc":[{"atb":[[2.16,86.21]],"id":39727103},{"atl":[[5.8,23.33]],"id":39727103}],"con":true,"img":false}]}
{"op":"mcm","clk":"5323039077","pt":1646326798390,"mc":[{"id":"1.195532873","rc":[{"atb":[[2.36,2.5],[2.28,25.27]],"id":37510843},{"atb":[[1.96,0],[2.08,39.19]],"id":37569661}],"con":true,"img":false}]}
{"op":"mcm","clk":"5323039084","pt":1646326798498,"mc":[{"id":"1.195532873","rc":[{"atb":[[1.88,75.47]],"id":37569661}],"con":true,"img":false}]}
{"op":"mcm","clk":"5323039120","pt":1646326799117,"mc":[{"id":"1.195532873","rc":[{"atb":[[1.59,0],[1.01,4804.04],[1.61,0]],"id":39727103},{"atl":[[14,0]],"id":39727103}],"con":true,"img":false}]}
{"op":"mcm","clk":"5323039158","pt":1646326799593,"mc":[{"id":"1.195532873","rc":[{"atb":[[3.1,119.05]],"id":36601249},{"atb":[[1.71,250]],"id":38114646},{"atb":[[2.14,219.3]],"id":37510843}],"con":true,"img":false}]}
{"op":"mcm","clk":"5323039172","pt":1646326799804,"mc":[{"id":"1.195532873","rc":[{"atb":[[1.67,0]],"id":37510843}],"con":true,"img":false}]}
{"op":"mcm","clk":"5323039397","pt":1646326802179,"mc":[{"id":"1.195532873","rc":[{"atb":[[2.1,0]],"id":39590546}],"con":true,"img":false}]}
{"op":"mcm","clk":"5323039520","pt":1646326803622,"mc":[{"id":"1.195532873","rc":[{"atb":[[1.94,58.82],[2.1,24.27],[1.88,0]],"id":37569661}],"con":true,"img":false}]}
{"op":"mcm","clk":"5323039575","pt":1646326804199,"mc":[{"id":"1.195532873","rc":[{"atb":[[2.08,37.04],[2.16,2.15]],"id":37569661}],"con":true,"img":false}]}
{"op":"mcm","clk":"5323039648","pt":1646326804840,"mc":[{"id":"1.195532873","rc":[{"atb":[[2.1,22.28]],"id":37569661}],"con":true,"img":false}]}
{"op":"mcm","clk":"5323039657","pt":1646326804892,"mc":[{"id":"1.195532873","rc":[{"atb":[[2.18,1.99]],"id":37569661}],"con":true,"img":false}]}
{"op":"mcm","clk":"5323039665","pt":1646326805003,"mc":[{"id":"1.195532873","rc":[{"atl":[[5.7,4.52]],"id":37510843},{"atb":[[2.12,37.36],[2.08,0]],"id":37569661}],"con":true,"img":false}]}
{"op":"mcm","clk":"5323039683","pt":1646326805210,"mc":[{"id":"1.195532873","rc":[{"atl":[[5.7,0]],"id":37510843}],"con":true,"img":false}]}
{"op":"mcm","clk":"5323039689","pt":1646326805314,"mc":[{"id":"1.195532873","rc":[{"atb":[[2.52,11.55]],"id":39727103},{"atl":[[4.1,64.92],[4.2,25.22]],"id":39590546},{"atb":[[2.1,72.98],[1.99,0]],"id":37569661},{"atl":[[4.9,10.26],[4.7,121.46]],"id":37569661}],"con":true,"img":false}]}
{"op":"mcm","clk":"5323039696","pt":1646326805420,"mc":[{"id":"1.195532873","rc":[{"atb":[[2.5,2.15]],"id":39727103},{"atb":[[2.18,16.95]],"id":39590546},{"atl":[[3.9,14.96]],"id":39590546}],"con":true,"img":false}]}
{"op":"mcm","clk":"5323039705","pt":1646326805525,"mc":[{"id":"1.195532873","rc":[{"atb":[[2.16,2.15]],"id":39590546},{"atl":[[4,0]],"id":39590546}],"con":true,"img":false}]}
{"op":"mcm","clk":"5323039736","pt":1646326805893,"mc":[{"id":"1.195532873","rc":[{"atl":[[4,13.33],[4.1,52.02]],"id":39590546},{"atb":[[2.12,1.65],[2.14,35.09]],"id":37569661}],"con":true,"img":false}]}
{"op":"mcm","clk":"5323039820","pt":1646326806901,"mc":[{"id":"1.195532873","rc":[{"atb":[[2.1,4.37]],"id":39590546}],"con":true,"img":false}]}
{"op":"mcm","clk":"5323039829","pt":1646326806997,"mc":[{"id":"1.195532873","rc":[{"atb":[[2.1,39.73]],"id":39590546}],"con":true,"img":false}]}
{"op":"mcm","clk":"5323039839","pt":1646326807103,"mc":[{"id":"1.195532873","rc":[{"atb":[[2.08,2.5]],"id":39590546},{"atl":[[3.95,15.56]],"id":39590546}],"con":true,"img":false}]}
{"op":"mcm","clk":"5323039854","pt":1646326807315,"mc":[{"id":"1.195532873","rc":[{"atb":[[2.12,133.93]],"id":39727103},{"atl":[[6,30]],"id":39727103},{"atl":[[4,43.85],[3.95,0]],"id":39590546}],"con":true,"img":false}]}
{"op":"mcm","clk":"5323039869","pt":1646326807526,"mc":[{"id":"1.195532873","rc":[{"atl":[[3.9,0]],"id":39590546}],"con":true,"img":false}]}
{"op":"mcm","clk":"5323039879","pt":1646326807622,"mc":[{"id":"1.195532873","rc":[{"atl":[[3.95,23.93]],"id":39590546}],"con":true,"img":false}]}
{"op":"mcm","clk":"5323039922","pt":1646326808004,"mc":[{"id":"1.195532873","rc":[{"atb":[[2.12,0]],"id":37569661}],"con":true,"img":false}]}
{"op":"mcm","clk":"5323039932","pt":1646326808102,"mc":[{"id":"1.195532873","rc":[{"atl":[[13,0]],"id":39727103},{"atl":[[4,30.52],[4.1,64.92]],"id":39590546}],"con":true,"img":false}]}
{"op":"mcm","clk":"5323039937","pt":1646326808213,"mc":[{"id":"1.195532873","rc":[{"atb":[[2.2,1.65]],"id":37569661}],"con":true,"img":false}]}
{"op":"mcm","clk":"5323039964","pt":1646326808530,"mc":[{"id":"1.195532873","rc":[{"atb":[[2.1,22.28]],"id":37569661}],"con":true,"img":false}]}
{"op":"mcm","clk":"5323039996","pt":1646326808925,"mc":[{"id":"1.195532873","rc":[{"atb":[[2,0]],"id":37569661}],"con":true,"img":false}]}
{"op":"mcm","clk":"5323040054","pt":1646326809837,"mc":[{"id":"1.195532873","rc":[{"atl":[[3.9,2.48]],"id":39590546}],"con":true,"img":false}]}
{"op":"mcm","clk":"5323040133","pt":1646326810935,"mc":[{"id":"1.195532873","rc":[{"atl":[[4,43.85],[4.1,52.02]],"id":39590546}],"con":true,"img":false}]}
{"op":"mcm","clk":"5323040156","pt":1646326811304,"mc":[{"id":"1.195532873","rc":[{"atb":[[3.35,3.55]],"id":36601249}],"con":true,"img":false}]}
{"op":"mcm","clk":"5323040196","pt":1646326811932,"mc":[{"id":"1.195532873","rc":[{"atb":[[3.35,0]],"id":36601249}],"con":true,"img":false}]}
{"op":"mcm","clk":"5323040263","pt":1646326812821,"mc":[{"id":"1.195532873","rc":[{"atl":[[4.2,18.2]],"id":38114646}],"con":true,"img":false}]}
{"op":"mcm","clk":"5323040286","pt":1646326813234,"mc":[{"id":"1.195532873","rc":[{"atl":[[3.9,26.41]],"id":39590546}],"con":true,"img":false}]}
{"op":"mcm","clk":"5323040292","pt":1646326813342,"mc":[{"id":"1.195532873","rc":[{"atl":[[4,13.33]],"id":39590546}],"con":true,"img":false}]}
{"op":"mcm","clk":"5323040306","pt":1646326813618,"mc":[{"id":"1.195532873","rc":[{"atb":[[2.2,4.21]],"id":37569661}],"con":true,"img":false}]}
{"op":"mcm","clk":"5323040312","pt":1646326813717,"mc":[{"id":"1.195532873","rc":[{"atb":[[2.1,0]],"id":37569661}],"con":true,"img":false}]}
{"op":"mcm","clk":"5323040319","pt":1646326813825,"mc":[{"id":"1.195532873","rc":[{"atb":[[2.18,0]],"id":37569661}],"con":true,"img":false}]}
{"op":"mcm","clk":"5323040326","pt":1646326813935,"mc":[{"id":"1.195532873","rc":[{"atb":[[2.22,1.99]],"id":37569661}],"con":true,"img":false}]}
{"op":"mcm","clk":"5323040383","pt":1646326814725,"mc":[{"id":"1.195532873","rc":[{"atb":[[2.24,2.15],[2.16,0]],"id":39590546}],"con":true,"img":false}]}
{"op":"mcm","clk":"5323040393","pt":1646326814825,"mc":[{"id":"1.195532873","rc":[{"atb":[[2.1,90.91]],"id":37569661},{"atl":[[4.8,4.03],[4.7,137.68]],"id":37569661}],"con":true,"img":false}]}
{"op":"mcm","clk":"5323040409","pt":1646326815127,"mc":[{"id":"1.195532873","rc":[{"atb":[[2.54,12.65]],"id":39727103},{"atl":[[4.8,0]],"id":37569661}],"con":true,"img":false}]}
{"op":"mcm","clk":"5323040418","pt":1646326815330,"mc":[{"id":"1.195532873","rc":[{"atb":[[2.5,32.41]],"id":39727103}],"con":true,"img":false}]}
{"op":"mcm","clk":"5323040424","pt":1646326815433,"mc":[{"id":"1.195532873","rc":[{"atb":[[2.44,2.5]],"id":39727103}],"con":true,"img":false}]}
{"op":"mcm","clk":"5323040458","pt":1646326815906,"mc":[{"id":"1.195532873","rc":[{"atb":[[2.52,9.56]],"id":39727103}],"con":true,"img":false}]}
{"op":"mcm","clk":"5323040468","pt":1646326816008,"mc":[{"id":"1.195532873","rc":[{"atb":[[2.56,1.99]],"id":39727103},{"atb":[[1.01,4804.04]],"id":37569661}],"con":true,"img":false}]}
{"op":"mcm","clk":"5323040478","pt":1646326816217,"mc":[{"id":"1.195532873","rc":[{"atb":[[2.08,231.48]],"id":39727103},{"atl":[[6.4,51.3]],"id":39727103},{"atb":[[2.18,14.96]],"id":39590546}],"con":true,"img":false}]}
{"op":"mcm","clk":"5323040482","pt":1646326816319,"mc":[{"id":"1.195532873","rc":[{"atb":[[1.02,1.99]],"id":39590546}],"con":true,"img":false}]}
{"op":"mcm","clk":"5323040492","pt":1646326816528,"mc":[{"id":"1.195532873","rc":[{"atl":[[5.7,4.35]],"id":39727103}],"con":true,"img":false}]}
{"op":"mcm","clk":"5323040514","pt":1646326816838,"mc":[{"id":"1.195532873","rc":[{"atl":[[5.7,0]],"id":39727103}],"con":true,"img":false}]}
{"op":"mcm","clk":"5323040523","pt":1646326817045,"mc":[{"id":"1.195532873","rc":[{"atb":[[2.54,11]],"id":39727103},{"atb":[[2.2,0]],"id":39590546},{"atb":[[2.2,2.55]],"id":37569661}],"con":true,"img":false}]}
{"op":"mcm","clk":"5323040539","pt":1646326817206,"mc":[{"id":"1.195532873","rc":[{"atb":[[2.58,1.65]],"id":39727103},{"atl":[[12,0]],"id":39727103},{"atb":[[2.26,1.65]],"id":39590546},{"atb":[[2.24,1.65]],"id":37569661}],"con":true,"img":false}]}
{"op":"mcm","clk":"5323040565","pt":1646326817522,"mc":[{"id":"1.195532873","rc":[{"atb":[[2.14,14.6]],"id":39590546}],"con":true,"img":false}]}
{"op":"mcm","clk":"5323040577","pt":1646326817734,"mc":[{"id":"1.195532873","rc":[{"atl":[[5.4,31.14]],"id":39727103},{"atb":[[2.14,0]],"id":39590546}],"con":true,"img":false}]}
{"op":"mcm","clk":"5323040587","pt":1646326817834,"mc":[{"id":"1.195532873","rc":[{"atb":[[1.94,63.48]],"id":37569661}],"con":true,"img":false}]}
{"op":"mcm","clk":"5323040603","pt":1646326817941,"mc":[{"id":"1.195532873","rc":[{"atb":[[2.56,14.08]],"id":39727103},{"atb":[[2.1,35.36]],"id":39590546},{"atl":[[4,91.11],[4.1,0]],"id":39590546}],"con":true,"img":false}]}
{"op":"mcm","clk":"5323040617","pt":1646326818042,"mc":[{"id":"1.195532873","rc":[{"atb":[[1.94,58.82]],"id":37569661}],"con":true,"img":false}]}
{"op":"mcm","clk":"5323040625","pt":1646326818146,"mc":[{"id":"1.195532873","rc":[{"atb":[[2.52,0]],"id":39727103},{"atl":[[3.85,21.22]],"id":39590546}],"con":true,"img":false}]}
{"op":"mcm","clk":"5323040630","pt":1646326818206,"mc":[{"id":"1.195532873","rc":[{"atl":[[3.95,0]],"id":39590546}],"con":true,"img":false}]}
{"op":"mcm","clk":"5323040654","pt":1646326818514,"mc":[{"id":"1.195532873","rc":[{"atl":[[4,103.07]],"id":39590546}],"con":true,"img":false}]}
{"op":"mcm","clk":"5323040658","pt":1646326818625,"mc":[{"id":"1.195532873","rc":[{"atl":[[4,77.78],[3.95,13.56]],"id":39590546}],"con":true,"img":false}]}
{"op":"mcm","clk":"5323040664","pt":1646326818727,"mc":[{"id":"1.195532873","rc":[{"atl":[[3.95,20.46]],"id":39590546}],"con":true,"img":false}]}
{"op":"mcm","clk":"5323040682","pt":1646326818947,"mc":[{"id":"1.195532873","rc":[{"atl":[[3.95,13.56]],"id":39590546}],"con":true,"img":false}]}
{"op":"mcm","clk":"5323040734","pt":1646326819940,"mc":[{"id":"1.195532873","rc":[{"atl":[[3.9,23.93]],"id":39590546}],"con":true,"img":false}]}
{"op":"mcm","clk":"5323040740","pt":1646326820042,"mc":[{"id":"1.195532873","rc":[{"atb":[[2.2,0]],"id":37569661}],"con":true,"img":false}]}
{"op":"mcm","clk":"5323040743","pt":1646326820139,"mc":[{"id":"1.195532873","rc":[{"atl":[[3.95,47.46],[3.9,0]],"id":39590546}],"con":true,"img":false}]}
{"op":"mcm","clk":"5323040754","pt":1646326820347,"mc":[{"id":"1.195532873","rc":[{"atl":[[4,111.11],[3.85,0],[3.95,13.56]],"id":39590546}],"con":true,"img":false}]}
{"op":"mcm","clk":"5323040762","pt":1646326820454,"mc":[{"id":"1.195532873","rc":[{"atl":[[4,77.78],[3.9,27.14]],"id":39590546}],"con":true,"img":false}]}
{"op":"mcm","clk":"5323040765","pt":1646326820510,"mc":[{"id":"1.195532873","rc":[{"atl":[[4.1,32.26]],"id":39590546}],"con":true,"img":false}]}
{"op":"mcm","clk":"5323040778","pt":1646326820721,"mc":[{"id":"1.195532873","rc":[{"atl":[[3.8,2.48]],"id":39590546}],"con":true,"img":false}]}
{"op":"mcm","clk":"5323040795","pt":1646326821035,"mc":[{"id":"1.195532873","rc":[{"atb":[[2.22,0]],"id":37569661}],"con":true,"img":false}]}
{"op":"mcm","clk":"5323040798","pt":1646326821137,"mc":[{"id":"1.195532873","rc":[{"atb":[[2.18,1.99]],"id":37569661}],"con":true,"img":false}]}
{"op":"mcm","clk":"5323040807","pt":1646326821352,"mc":[{"id":"1.195532873","rc":[{"atb":[[2.44,0],[2.36,0],[2.28,8.23]],"id":39727103},{"atl":[[4.3,0],[5.1,0],[4.6,5],[4.2,20.7],[4.7,27.03]],"id":38114646},{"atb":[[2,0],[2.12,2.5],[1.96,0],[2.08,0],[2.24,14.19]],"id":39590546},{"atb":[[2.3,8.79],[2.34,5],[2.36,0],[2.42,11.93],[2.28,20.27],[2.2,0]],"id":37510843},{"atl":[[4.8,5],[4.3,0],[5.1,24.39],[4.6,4.3],[5.5,0],[4.4,2.5],[4.7,135.18]],"id":37569661}],"con":true,"img":false}]}
{"op":"mcm","clk":"5323040813","pt":1646326821450,"mc":[{"id":"1.195532873","rc":[{"atb":[[2.18,0]],"id":39590546},{"atb":[[2.2,4.12]],"id":37569661},{"atl":[[4.5,40],[4.7,108.15]],"id":37569661}],"con":true,"img":false}]}
{"op":"mcm","clk":"5323040816","pt":1646326821554,"mc":[{"id":"1.195532873","rc":[{"atl":[[4.6,101.46],[4.4,11.76]],"id":38114646},{"atb":[[2.12,38.15],[2.1,0]],"id":39590546},{"atb":[[2.3,26.18],[2.28,0],[2.34,8.91]],"id":37510843},{"atl":[[4.3,3.11],[4.6,34.13],[4.7,27.03]],"id":37569661}],"con":true,"img":false}]}
{"op":"mcm","clk":"5323040819","pt":1646326821658,"mc":[{"id":"1.195532873","rc":[{"atl":[[4.4,15.51]],"id":38114646},{"atb":[[2.2,0]],"id":37569661},{"atl":[[4.5,11.43]],"id":37569661}],"con":true,"img":false}]}
{"op":"mcm","clk":"5323040824","pt":1646326821716,"mc":[{"id":"1.195532873","rc":[{"atb":[[2.12,2.5]],"id":39590546},{"atb":[[2.18,0]],"id":37569661}],"con":true,"img":false}]}
{"op":"mcm","clk":"5323040830","pt":1646326821823,"mc":[{"id":"1.195532873","rc":[{"atb":[[2.22,1.99]],"id":37569661}],"con":true,"img":false}]}
{"op":"mcm","clk":"5323040834","pt":1646326821923,"mc":[{"id":"1.195532873","rc":[{"atl":[[3.95,0],[3.9,40.93]],"id":39590546},{"atb":[[2.3,17.39]],"id":37510843},{"atl":[[4.6,29.83]],"id":37569661}],"con":true,"img":false}]}
{"op":"mcm","clk":"5323040838","pt":1646326822030,"mc":[{"id":"1.195532873","rc":[{"atl":[[4.4,11.76]],"id":38114646}],"con":true,"img":false}]}
{"op":"mcm","clk":"5323040844","pt":1646326822132,"mc":[{"id":"1.195532873","rc":[{"atb":[[2.34,5]],"id":37510843}],"con":true,"img":false}]}
{"op":"mcm","clk":"5323040870","pt":1646326822548,"mc":[{"id":"1.195532873","rc":[{"atb":[[2.12,7.84]],"id":39590546}],"con":true,"img":false}]}
{"op":"mcm","clk":"5323040921","pt":1646326823226,"mc":[{"id":"1.195532873","rc":[{"atl":[[4.7,3.69]],"id":39590546}],"con":true,"img":false}]}
{"op":"mcm","clk":"5323040940","pt":1646326823440,"mc":[{"id":"1.195532873","rc":[{"atl":[[4.7,0]],"id":39590546}],"con":true,"img":false}]}
{"op":"mcm","clk":"5323040951","pt":1646326823543,"mc":[{"id":"1.195532873","rc":[{"atb":[[2.06,141.51]],"id":37569661},{"atl":[[4.9,38.46]],"id":37569661}],"con":true,"img":false}]}
{"op":"mcm","clk":"5323041067","pt":1646326825060,"mc":[{"id":"1.195532873","rc":[{"atb":[[2.16,6.17]],"id":37569661}],"con":true,"img":false}]}
{"op":"mcm","clk":"5323041084","pt":1646326825262,"mc":[{"id":"1.195532873","rc":[{"atb":[[2.62,2.15]],"id":39727103}],"con":true,"img":false}]}
{"op":"mcm","clk":"5323041089","pt":1646326825385,"mc":[{"id":"1.195532873","rc":[{"atb":[[2.5,30.26]],"id":39727103}],"con":true,"img":false}]}
{"op":"mcm","clk":"5323041115","pt":1646326825845,"mc":[{"id":"1.195532873","rc":[{"atb":[[1.94,5],[1.53,0],[1.87,75.47]],"id":37569661}],"con":true,"img":false}]}
{"op":"mcm","clk":"5323041123","pt":1646326825946,"mc":[{"id":"1.195532873","rc":[{"atb":[[2.58,0]],"id":39727103}],"con":true,"img":false}]}
{"op":"mcm","clk":"5323041129","pt":1646326826058,"mc":[{"id":"1.195532873","rc":[{"atb":[[2.64,1.65]],"id":39727103}],"con":true,"img":false}]}
{"op":"mcm","clk":"5323041139","pt":1646326826264,"mc":[{"id":"1.195532873","rc":[{"atl":[[4.1,0],[3.8,38.19]],"id":39590546}],"con":true,"img":false}]}
{"op":"mcm","clk":"5323041144","pt":1646326826363,"mc":[{"id":"1.195532873","rc":[{"atl":[[4,111.11],[3.8,2.48]],"id":39590546}],"con":true,"img":false}]}
{"op":"mcm","clk":"5323041151","pt":1646326826477,"mc":[{"id":"1.195532873","rc":[{"atl":[[3.8,38.19]],"id":39590546}],"con":true,"img":false}]}
{"op":"mcm","clk":"5323041156","pt":1646326826578,"mc":[{"id":"1.195532873","rc":[{"atl":[[4,77.78]],"id":39590546}],"con":true,"img":false}]}
{"op":"mcm","clk":"5323041162","pt":1646326826635,"mc":[{"id":"1.195532873","rc":[{"atb":[[2.56,17.66]],"id":39727103}],"con":true,"img":false}]}
{"op":"mcm","clk":"5323041175","pt":1646326826844,"mc":[{"id":"1.195532873","rc":[{"atb":[[2.56,14.08]],"id":39727103}],"con":true,"img":false}]}
{"op":"mcm","clk":"5323041198","pt":1646326827259,"mc":[{"id":"1.195532873","rc":[{"atb":[[2.12,2.5]],"id":39590546}],"con":true,"img":false}]}
{"op":"mcm","clk":"5323041229","pt":1646326827777,"mc":[{"id":"1.195532873","rc":[{"atb":[[2.54,42.35],[2.5,0]],"id":39727103}],"con":true,"img":false}]}
{"op":"mcm","clk":"5323041381","pt":1646326829763,"mc":[{"id":"1.195532873","rc":[{"atl":[[5.4,12.85]],"id":37510843}],"con":true,"img":false}]}
{"op":"mcm","clk":"5323041397","pt":1646326829968,"mc":[{"id":"1.195532873","rc":[{"atl":[[5.5,0]],"id":39727103}],"con":true,"img":false}]}
{"op":"mcm","clk":"5323041409","pt":1646326830176,"mc":[{"id":"1.195532873","rc":[{"atb":[[3.6,7.48],[3.45,5],[3.2,68.18],[3.4,16.67],[3.65,2.5]],"id":36601249},{"atl":[[5.6,8.7],[5.8,116.19],[5.4,21.07]],"id":39727103},{"atl":[[4.2,0]],"id":39590546}],"con":true,"img":false}]}
{"op":"mcm","clk":"5323041421","pt":1646326830375,"mc":[{"id":"1.195532873","rc":[{"atb":[[3.6,0],[3.65,12.18]],"id":36601249}],"con":true,"img":false}]}
{"op":"mcm","clk":"5323041428","pt":1646326830478,"mc":[{"id":"1.195532873","rc":[{"atl":[[5.4,24.02]],"id":39727103}],"con":true,"img":false}]}
{"op":"mcm","clk":"5323041436","pt":1646326830583,"mc":[{"id":"1.195532873","rc":[{"atl":[[5.7,3.17]],"id":39727103},{"atl":[[4,111.11],[3.75,29.09]],"id":39590546}],"con":true,"img":false}]}
{"op":"mcm","clk":"5323041445","pt":1646326830692,"mc":[{"id":"1.195532873","rc":[{"atl":[[3.9,13.79]],"id":39590546}],"con":true,"img":false}]}
{"op":"mcm","clk":"5323041454","pt":1646326830747,"mc":[{"id":"1.195532873","rc":[{"atl":[[4,33.33],[3.9,103.69]],"id":39590546},{"atl":[[5.4,10]],"id":37510843}],"con":true,"img":false}]}
{"op":"mcm","clk":"5323041484","pt":1646326831059,"mc":[{"id":"1.195532873","rc":[{"atl":[[5.7,0]],"id":39727103}],"con":true,"img":false}]}
{"op":"mcm","clk":"5323041494","pt":1646326831268,"mc":[{"id":"1.195532873","rc":[{"atb":[[2.24,2.15]],"id":39590546},{"atl":[[4,0],[4.8,0],[3.85,14.04],[5,5],[4.4,0],[3.9,89.9]],"id":39590546}],"con":true,"img":false}]}
{"op":"mcm","clk":"5323041509","pt":1646326831470,"mc":[{"id":"1.195532873","rc":[{"atb":[[2.12,14.9]],"id":39590546}],"con":true,"img":false}]}
{"op":"mcm","clk":"5323041526","pt":1646326831682,"mc":[{"id":"1.195532873","rc":[{"atb":[[2.08,25.36]],"id":39590546}],"con":true,"img":false}]}
{"op":"mcm","clk":"5323041573","pt":1646326832166,"mc":[{"id":"1.195532873","rc":[{"atb":[[2.02,245.1]],"id":37569661},{"atl":[[5.1,60.98]],"id":37569661}],"con":true,"img":false}]}
{"op":"mcm","clk":"5323041588","pt":1646326832377,"mc":[{"id":"1.195532873","rc":[{"atl":[[3.8,35.71]],"id":39590546}],"con":true,"img":false}]}
{"op":"mcm","clk":"5323041607","pt":1646326832579,"mc":[{"id":"1.195532873","rc":[{"atl":[[3.85,49.13],[3.8,0]],"id":39590546}],"con":true,"img":false}]}
{"op":"mcm","clk":"5323041628","pt":1646326832747,"mc":[{"id":"1.195532873","rc":[{"atl":[[3.75,0]],"id":39590546}],"con":true,"img":false}]}
{"op":"mcm","clk":"5323041634","pt":1646326832866,"mc":[{"id":"1.195532873","rc":[{"atl":[[3.8,12.8]],"id":39590546}],"con":true,"img":false}]}
{"op":"mcm","clk":"5323041651","pt":1646326833062,"mc":[{"id":"1.195532873","rc":[{"atl":[[3.95,16.02]],"id":39590546}],"con":true,"img":false}]}
{"op":"mcm","clk":"5323041661","pt":1646326833166,"mc":[{"id":"1.195532873","rc":[{"atb":[[1.8,16.67]],"id":38114646}],"con":true,"img":false}]}
{"op":"mcm","clk":"5323041707","pt":1646326833685,"mc":[{"id":"1.195532873","rc":[{"atb":[[1.8,0]],"id":38114646}],"con":true,"img":false}]}
{"op":"mcm","clk":"5323041728","pt":1646326833848,"mc":[{"id":"1.195532873","rc":[{"atb":[[2.08,75.7]],"id":39590546},{"atl":[[4.5,31.07],[4.6,13.93],[4.2,4.21]],"id":37569661}],"con":true,"img":false}]}
{"op":"mcm","clk":"5323041738","pt":1646326833959,"mc":[{"id":"1.195532873","rc":[{"atl":[[4.3,0],[4.6,0],[4.1,3.11]],"id":37569661}],"con":true,"img":false}]}
{"op":"mcm","clk":"5323041803","pt":1646326834889,"mc":[{"id":"1.195532873","rc":[{"atl":[[3.75,2.48]],"id":39590546},{"atl":[[4,2.48]],"id":37569661}],"con":true,"img":false}]}
{"op":"mcm","clk":"5323041837","pt":1646326835160,"mc":[{"id":"1.195532873","rc":[{"atb":[[3.9,2.25]],"id":36601249},{"atb":[[2.66,2.29]],"id":39727103},{"atb":[[1.92,2.85]],"id":38114646},{"atb":[[2.28,3.46]],"id":39590546},{"atb":[[2.46,2.81]],"id":37510843},{"atb":[[2.26,3.55],[1.95,0]],"id":37569661},{"atl":[[4.5,19.64],[4.2,16.71]],"id":37569661}],"con":true,"img":false}]}
{"op":"mcm","clk":"5323041843","pt":1646326835264,"mc":[{"id":"1.195532873","rc":[{"atb":[[1.83,42.84],[1.82,2.5],[1.9,10.79]],"id":38114646},{"atb":[[2.3,0],[2.42,9.77]],"id":37510843}],"con":true,"img":false}]}
{"op":"mcm","clk":"5323041850","pt":1646326835364,"mc":[{"id":"1.195532873","rc":[{"atb":[[3.95,5.8],[3.9,4.5]],"id":36601249},{"atb":[[1.92,21.39],[1.91,11.44]],"id":38114646},{"atb":[[2.46,11.57],[2.34,17.65]],"id":37510843}],"con":true,"img":false}]}
{"op":"mcm","clk":"5323041854","pt":1646326835468,"mc":[{"id":"1.195532873","rc":[{"atb":[[3.8,0]],"id":36601249},{"atb":[[1.89,4.62],[1.91,1.99],[1.9,12.95]],"id":38114646},{"atb":[[2.44,7.27]],"id":37510843}],"con":true,"img":false}]}
{"op":"mcm","clk":"5323041860","pt":1646326835575,"mc":[{"id":"1.195532873","rc":[{"atb":[[3.85,1.99],[4,2.11],[3.7,9.09]],"id":36601249},{"atb":[[1.89,0],[1.91,44.77],[1.9,2.15]],"id":38114646},{"atb":[[2.42,4.65],[2.46,8.76]],"id":37510843}],"con":true,"img":false}]}
{"op":"mcm","clk":"5323041869","pt":1646326835674,"mc":[{"id":"1.195532873","rc":[{"atb":[[4,6.61]],"id":36601249}],"con":true,"img":false}]}
{"op":"mcm","clk":"5323041880","pt":1646326835782,"mc":[{"id":"1.195532873","rc":[{"atb":[[3.9,2.25]],"id":36601249},{"atb":[[1.95,2.15],[1.9,0]],"id":38114646},{"atb":[[2.42,2.5],[2.52,2.15]],"id":37510843}],"con":true,"img":false}]}
{"op":"mcm","clk":"5323041887","pt":1646326835886,"mc":[{"id":"1.195532873","rc":[{"atl":[[5.8,95.36],[5.4,46.75]],"id":39727103},{"atb":[[1.96,2.68]],"id":38114646},{"atb":[[2.54,2.58]],"id":37510843}],"con":true,"img":false}]}
{"op":"mcm","clk":"5323041900","pt":1646326835989,"mc":[{"id":"1.195532873","rc":[{"atb":[[3.7,0]],"id":36601249},{"atb":[[2.44,1.65],[2.52,9.43]],"id":37510843}],"con":true,"img":false}]}
{"op":"mcm","clk":"5323041937","pt":1646326836369,"mc":[{"id":"1.195532873","rc":[{"atl":[[4.3,3.72]],"id":38114646}],"con":true,"img":false}]}
{"op":"mcm","clk":"5323041944","pt":1646326836471,"mc":[{"id":"1.195532873","rc":[{"atl":[[4.2,32.46]],"id":38114646}],"con":true,"img":false}]}
{"op":"mcm","clk":"5323041951","pt":1646326836578,"mc":[{"id":"1.195532873","rc":[{"atl":[[4.6,5],[4.4,42.72]],"id":38114646}],"con":true,"img":false}]}
{"op":"mcm","clk":"5323041958","pt":1646326836680,"mc":[{"id":"1.195532873","rc":[{"atl":[[4.3,0]],"id":38114646}],"con":true,"img":false}]}
{"op":"mcm","clk":"5323041983","pt":1646326837094,"mc":[{"id":"1.195532873","rc":[{"atl":[[4.1,19.79]],"id":38114646}],"con":true,"img":false}]}
{"op":"mcm","clk":"5323041993","pt":1646326837258,"mc":[{"id":"1.195532873","rc":[{"atl":[[4.2,25.26]],"id":38114646}],"con":true,"img":false}]}
{"op":"mcm","clk":"5323042033","pt":1646326837878,"mc":[{"id":"1.195532873","rc":[{"atl":[[4,2.48]],"id":38114646}],"con":true,"img":false}]}
{"op":"mcm","clk":"5323042042","pt":1646326837985,"mc":[{"id":"1.195532873","rc":[{"atl":[[3.95,0]],"id":39590546}],"con":true,"img":false}]}
{"op":"mcm","clk":"5323042047","pt":1646326838091,"mc":[{"id":"1.195532873","rc":[{"atb":[[1.83,33.39]],"id":38114646},{"atb":[[2.08,50.34]],"id":39590546},{"atb":[[2.16,2.15]],"id":37569661}],"con":true,"img":false}]}
{"op":"mcm","clk":"5323042054","pt":1646326838192,"mc":[{"id":"1.195532873","rc":[{"atl":[[3.85,14.03],[3.75,15.28]],"id":39590546}],"con":true,"img":false}]}
{"op":"mcm","clk":"5323042064","pt":1646326838349,"mc":[{"id":"1.195532873","rc":[{"atl":[[4.4,30.96],[4.2,37.76]],"id":38114646}],"con":true,"img":false}]}
{"op":"mcm","clk":"5323042121","pt":1646326839290,"mc":[{"id":"1.195532873","rc":[{"atl":[[3.85,19.57]],"id":39590546}],"con":true,"img":false}]}
{"op":"mcm","clk":"5323042145","pt":1646326839661,"mc":[{"id":"1.195532873","rc":[{"atl":[[3.95,33.9]],"id":39590546}],"con":true,"img":false}]}
{"op":"mcm","clk":"5323042164","pt":1646326839977,"mc":[{"id":"1.195532873","rc":[{"atb":[[2.56,42.56],[2.54,11]],"id":39727103}],"con":true,"img":false}]}
{"op":"mcm","clk":"5323042214","pt":1646326840590,"mc":[{"id":"1.195532873","rc":[{"atb":[[3.65,16.44]],"id":36601249}],"con":true,"img":false}]}
{"op":"mcm","clk":"5323042232","pt":1646326841144,"mc":[{"id":"1.195532873","rc":[{"atb":[[3.65,12.18]],"id":36601249}],"con":true,"img":false}]}
{"op":"mcm","clk":"5323042313","pt":1646326841853,"mc":[{"id":"1.195532873","rc":[{"atl":[[3.95,52.08]],"id":39590546}],"con":true,"img":false}]}
{"op":"mcm","clk":"5323042328","pt":1646326842070,"mc":[{"id":"1.195532873","rc":[{"atl":[[4,22.27],[4.2,26]],"id":38114646}],"con":true,"img":false}]}
{"op":"mcm","clk":"5323042350","pt":1646326842382,"mc":[{"id":"1.195532873","rc":[{"atl":[[3.95,33.9]],"id":39590546}],"con":true,"img":false}]}
{"op":"mcm","clk":"5323042358","pt":1646326842484,"mc":[{"id":"1.195532873","rc":[{"atb":[[3.9,16.05]],"id":36601249}],"con":true,"img":false}]}
{"op":"mcm","clk":"5323042363","pt":1646326842587,"mc":[{"id":"1.195532873","rc":[{"atb":[[3.65,2.5]],"id":36601249}],"con":true,"img":false}]}
{"op":"mcm","clk":"5323042368","pt":1646326842694,"mc":[{"id":"1.195532873","rc":[{"atl":[[3.7,12.2]],"id":39590546}],"con":true,"img":false}]}
{"op":"mcm","clk":"5323042381","pt":1646326842906,"mc":[{"id":"1.195532873","rc":[{"atl":[[3.8,50]],"id":39590546}],"con":true,"img":false}]}
{"op":"mcm","clk":"5323042388","pt":1646326842963,"mc":[{"id":"1.195532873","rc":[{"atl":[[3.9,0]],"id":39590546}],"con":true,"img":false}]}
{"op":"mcm","clk":"5323042427","pt":1646326843594,"mc":[{"id":"1.195532873","rc":[{"atl":[[4.4,31.91]],"id":37569661}],"con":true,"img":false}]}
{"op":"mcm","clk":"5323042434","pt":1646326843700,"mc":[{"id":"1.195532873","rc":[{"atb":[[1.93,2.95]],"id":38114646},{"atb":[[2.14,5.19]],"id":39590546},{"atb":[[2.16,6.77]],"id":37569661}],"con":true,"img":false}]}
{"op":"mcm","clk":"5323042458","pt":1646326844012,"mc":[{"id":"1.195532873","rc":[{"atb":[[2.64,0]],"id":39727103},{"atb":[[2.26,0]],"id":39590546},{"atb":[[2.44,0]],"id":37510843},{"atb":[[2.24,0]],"id":37569661}],"con":true,"img":false}]}
{"op":"mcm","clk":"5323042478","pt":1646326844174,"mc":[{"id":"1.195532873","rc":[{"atb":[[2.68,1.65]],"id":39727103},{"atb":[[2.3,1.65]],"id":39590546},{"atb":[[2.56,1.65]],"id":37510843}],"con":true,"img":false}]}
{"op":"mcm","clk":"5323042486","pt":1646326844294,"mc":[{"id":"1.195532873","rc":[{"atb":[[2.7,2.21]],"id":39727103},{"atb":[[2.32,3.3]],"id":39590546},{"atb":[[2.58,2.48],[2.56,4.23],[2.52,2.15]],"id":37510843}],"con":true,"img":false}]}
{"op":"mcm","clk":"5323042493","pt":1646326844382,"mc":[{"id":"1.195532873","rc":[{"atl":[[3.75,12.8]],"id":39590546},{"atb":[[2.54,11.34]],"id":37510843}],"con":true,"img":false}]}
{"op":"mcm","clk":"5323042498","pt":1646326844489,"mc":[{"id":"1.195532873","rc":[{"atb":[[2.56,14.08]],"id":39727103},{"atb":[[2.56,1.65]],"id":37510843}],"con":true,"img":false}]}
{"op":"mcm","clk":"5323042505","pt":1646326844590,"mc":[{"id":"1.195532873","rc":[{"atl":[[3.8,83.9]],"id":39590546}],"con":true,"img":false}]}
{"op":"mcm","clk":"5323042512","pt":1646326844697,"mc":[{"id":"1.195532873","rc":[{"atl":[[3.75,0]],"id":39590546},{"atb":[[2.54,2.58],[2.56,6.61]],"id":37510843}],"con":true,"img":false}]}
{"op":"mcm","clk":"5323042527","pt":1646326844904,"mc":[{"id":"1.195532873","rc":[{"atl":[[3.7,0]],"id":39590546}],"con":true,"img":false}]}
{"op":"mcm","clk":"5323042533","pt":1646326844959,"mc":[{"id":"1.195532873","rc":[{"atl":[[3.75,11.74]],"id":39590546}],"con":true,"img":false}]}
{"op":"mcm","clk":"5323042544","pt":1646326845067,"mc":[{"id":"1.195532873","rc":[{"atb":[[2.22,4.6]],"id":39590546},{"atl":[[3.7,19.58],[3.8,50]],"id":39590546}],"con":true,"img":false}]}
{"op":"mcm","clk":"5323042578","pt":1646326845683,"mc":[{"id":"1.195532873","rc":[{"atb":[[2.22,0]],"id":39590546}],"con":true,"img":false}]}
{"op":"mcm","clk":"5323042595","pt":1646326845997,"mc":[{"id":"1.195532873","rc":[{"atb":[[2.08,0],[2.24,23.23]],"id":39590546},{"atl":[[4.5,0],[3.95,5],[4.2,41.33]],"id":37569661}],"con":true,"img":false}]}
{"op":"mcm","clk":"5323042608","pt":1646326846206,"mc":[{"id":"1.195532873","rc":[{"atb":[[2.56,12.09]],"id":39727103},{"atl":[[4.6,8.13],[4.2,37.12]],"id":37569661}],"con":true,"img":false}]}
{"op":"mcm","clk":"5323042616","pt":1646326846306,"mc":[{"id":"1.195532873","rc":[{"atb":[[2.72,1.99]],"id":39727103},{"atl":[[4.4,38.99]],"id":37569661}],"con":true,"img":false}]}
{"op":"mcm","clk":"5323042627","pt":1646326846474,"mc":[{"id":"1.195532873","rc":[{"atb":[[2.74,2.12]],"id":39727103},{"atb":[[2.6,2.15],[2.52,0]],"id":37510843},{"atb":[[2.22,0]],"id":37569661}],"con":true,"img":false}]}
{"op":"mcm","clk":"5323042636","pt":1646326846576,"mc":[{"id":"1.195532873","rc":[{"atb":[[2.62,2.38]],"id":37510843},{"atb":[[2.26,0],[2.28,1.99]],"id":37569661}],"con":true,"img":false}]}
{"op":"mcm","clk":"5323042641","pt":1646326846679,"mc":[{"id":"1.195532873","rc":[{"atl":[[4.4,60.37]],"id":38114646},{"atb":[[2.28,5.45]],"id":37569661},{"atl":[[4.6,0],[4.4,31.91]],"id":37569661}],"con":true,"img":false}]}
{"op":"mcm","clk":"5323042648","pt":1646326846779,"mc":[{"id":"1.195532873","rc":[{"atb":[[3.85,0]],"id":36601249},{"atl":[[3.65,2.48]],"id":39590546},{"atl":[[4,0]],"id":37569661}],"con":true,"img":false}]}
{"op":"mcm","clk":"5323042653","pt":1646326846885,"mc":[{"id":"1.195532873","rc":[{"atb":[[4.1,1.99]],"id":36601249},{"atl":[[3.95,0],[4.2,68.37]],"id":37569661}],"con":true,"img":false}]}
{"op":"mcm","clk":"5323042663","pt":1646326846985,"mc":[{"id":"1.195532873","rc":[{"atb":[[4.2,3.82]],"id":36601249},{"atl":[[4,9.16],[4.1,0],[4.4,61.32],[4.2,37.12]],"id":37569661}],"con":true,"img":false}]}
{"op":"mcm","clk":"5323042669","pt":1646326847090,"mc":[{"id":"1.195532873","rc":[{"atb":[[4.3,3.82],[4,2.11]],"id":36601249},{"atb":[[1.91,42.78]],"id":38114646},{"atl":[[3.95,33.9],[4.4,31.91]],"id":37569661}],"con":true,"img":false}]}
{"op":"mcm","clk":"5323042679","pt":1646326847195,"mc":[{"id":"1.195532873","rc":[{"atb":[[4.4,3.42]],"id":36601249},{"atb":[[1.97,1.99]],"id":38114646},{"atl":[[7.4,0],[7.8,0],[4.7,0]],"id":38114646},{"atl":[[3.75,26.29]],"id":39590546},{"atl":[[5.1,0],[4.9,0],[4.7,0]],"id":37569661}],"con":true,"img":false}]}
{"op":"mcm","clk":"5323042688","pt":1646326847299,"mc":[{"id":"1.195532873","rc":[{"atb":[[1.83,0],[1.98,2.59],[1.93,33.53]],"id":38114646},{"atl":[[4,6.86]],"id":39590546},{"atb":[[2.38,4.64]],"id":37510843}],"con":true,"img":false}]}
{"op":"mcm","clk":"5323042698","pt":1646326847404,"mc":[{"id":"1.195532873","rc":[{"atb":[[4.5,5.73]],"id":36601249},{"atb":[[1.96,19.53]],"id":38114646},{"atl":[[3.85,14.03]],"id":39590546},{"atb":[[2.58,8.7],[2.62,6.12],[2.34,5]],"id":37510843}],"con":true,"img":false}]}
{"op":"mcm","clk":"5323042713","pt":1646326847571,"mc":[{"id":"1.195532873","rc":[{"atb":[[4.6,3.09],[3.95,0]],"id":36601249},{"atb":[[1.92,2.85]],"id":38114646},{"atb":[[2.46,2.81]],"id":37510843}],"con":true,"img":false}]}
{"op":"mcm","clk":"5323042734","pt":1646326847884,"mc":[{"id":"1.195532873","rc":[{"atb":[[2.14,0]],"id":39590546},{"atl":[[4,0]],"id":39590546},{"atb":[[2.38,0]],"id":37510843}],"con":true,"img":false}]}
{"op":"mcm","clk":"5323042788","pt":1646326848563,"mc":[{"id":"1.195532873","rc":[{"atl":[[4.2,108.62]],"id":38114646}],"con":true,"img":false}]}
{"op":"mcm","clk":"5323042795","pt":1646326848673,"mc":[{"id":"1.195532873","rc":[{"atl":[[4.4,29.41]],"id":38114646}],"con":true,"img":false}]}
{"op":"mcm","clk":"5323042803","pt":1646326848774,"mc":[{"id":"1.195532873","rc":[{"atb":[[2.72,0]],"id":39727103}],"con":true,"img":false}]}
{"op":"mcm","clk":"5323042808","pt":1646326848879,"mc":[{"id":"1.195532873","rc":[{"atb":[[2.76,1.99]],"id":39727103}],"con":true,"img":false}]}
{"op":"mcm","clk":"5323042822","pt":1646326848980,"mc":[{"id":"1.195532873","rc":[{"atb":[[2.74,0],[2.66,0],[2.7,0]],"id":39727103},{"atl":[[3.9,2.48]],"id":37569661}],"con":true,"img":false}]}
{"op":"mcm","clk":"5323042830","pt":1646326849085,"mc":[{"id":"1.195532873","rc":[{"atb":[[4.1,0]],"id":36601249},{"spn":8.05,"spf":"NaN","id":36601249},{"spn":2.63,"spf":1.0,"id":39727103},{"atl":[[4.5,18.27],[3.65,29.49]],"id":38114646},{"spn":2.81,"spf":"NaN","id":38114646},{"spn":2.32,"spf":1.0,"id":39590546},{"spn":3.86,"spf":"NaN","id":37510843},{"spn":3.09,"spf":"NaN","id":37569661}],"con":true,"img":false}]}
{"op":"mcm","clk":"5323042838","pt":1646326849190,"mc":[{"id":"1.195532873","rc":[{"atb":[[4.7,1.99]],"id":36601249},{"atb":[[2.78,2.04]],"id":39727103}],"con":true,"img":false}]}
{"op":"mcm","clk":"5323042844","pt":1646326849293,"mc":[{"id":"1.195532873","rc":[{"atb":[[4.8,2.8]],"id":36601249},{"atb":[[1.97,0]],"id":38114646},{"atl":[[4,2.48],[3.6,22.28],[4.1,0]],"id":38114646}],"con":true,"img":false}]}
{"op":"mcm","clk":"5323042853","pt":1646326849399,"mc":[{"id":"1.195532873","rc":[{"atb":[[2.68,5.26]],"id":39727103},{"atb":[[1.99,1.99]],"id":38114646},{"atl":[[4.5,14.02]],"id":38114646}],"con":true,"img":false}]}
{"op":"mcm","clk":"5323042860","pt":1646326849501,"mc":[{"id":"1.195532873","rc":[{"atb":[[2.68,1.65]],"id":39727103},{"atb":[[2,2.52]],"id":38114646},{"atl":[[4.5,0]],"id":38114646}],"con":true,"img":false}]}
{"op":"mcm","clk":"5323042886","pt":1646326849890,"mc":[{"id":"1.195532873","rc":[{"atb":[[1.93,30.58]],"id":38114646}],"con":true,"img":false}]}
{"op":"mcm","clk":"5323042914","pt":1646326850190,"mc":[{"id":"1.195532873","rc":[{"atl":[[4,22.49]],"id":37569661}],"con":true,"img":false}]}
{"op":"mcm","clk":"5323042941","pt":1646326850611,"mc":[{"id":"1.195532873","rc":[{"atl":[[4,0]],"id":38114646}],"con":true,"img":false}]}
{"op":"mcm","clk":"5323043003","pt":1646326851407,"mc":[{"id":"1.195532873","rc":[{"atl":[[3.55,2.48]],"id":38114646}],"con":true,"img":false}]}
{"op":"mcm","clk":"5323043026","pt":1646326851782,"mc":[{"id":"1.195532873","rc":[{"atb":[[2.52,3.58]],"id":37510843}],"con":true,"img":false}]}
{"op":"mcm","clk":"5323043047","pt":1646326851992,"mc":[{"id":"1.195532873","rc":[{"atb":[[2.52,0]],"id":37510843}],"con":true,"img":false}]}
{"op":"mcm","clk":"5323043078","pt":1646326852518,"mc":[{"id":"1.195532873","rc":[{"atb":[[2.34,2.3]],"id":39590546}],"con":true,"img":false}]}
{"op":"mcm","clk":"5323043090","pt":1646326852680,"mc":[{"id":"1.195532873","rc":[{"atb":[[2.24,2.15],[2.36,3.15]],"id":39590546}],"con":true,"img":false}]}
{"op":"mcm","clk":"5323043119","pt":1646326853095,"mc":[{"id":"1.195532873","rc":[{"atb":[[2.68,0]],"id":39727103},{"atb":[[2.3,0]],"id":39590546},{"atb":[[2.56,4.96]],"id":37510843}],"con":true,"img":false}]}
{"op":"mcm","clk":"5323043128","pt":1646326853199,"mc":[{"id":"1.195532873","rc":[{"atb":[[2.56,38.08]],"id":39727103}],"con":true,"img":false}]}
{"op":"mcm","clk":"5323043134","pt":1646326853302,"mc":[{"id":"1.195532873","rc":[{"atb":[[2.8,1.65]],"id":39727103},{"atb":[[2.02,1.65]],"id":38114646},{"atb":[[2.38,1.65]],"id":39590546},{"atb":[[2.64,1.65]],"id":37510843}],"con":true,"img":false}]}
{"op":"mcm","clk":"5323043138","pt":1646326853408,"mc":[{"id":"1.195532873","rc":[{"atb":[[2.82,1.97]],"id":39727103},{"atb":[[2.04,4.76]],"id":38114646},{"atb":[[2.38,4.73]],"id":39590546},{"atb":[[2.66,2.29]],"id":37510843}],"con":true,"img":false}]}
{"op":"mcm","clk":"5323043152","pt":1646326853617,"mc":[{"id":"1.195532873","rc":[{"atb":[[2.56,12.09]],"id":39727103}],"con":true,"img":false}]}
{"op":"mcm","clk":"5323043220","pt":1646326854405,"mc":[{"id":"1.195532873","rc":[{"atb":[[4.5,18.63],[3.9,2.25]],"id":36601249},{"atb":[[1.91,0]],"id":38114646},{"atl":[[3.65,44.58]],"id":38114646},{"atb":[[1.87,0],[2.14,71.66],[2.24,35.09]],"id":37569661}],"con":true,"img":false}]}
{"op":"mcm","clk":"5323043227","pt":1646326854511,"mc":[{"id":"1.195532873","rc":[{"atb":[[2.38,33.33],[2.28,0]],"id":39727103},{"atb":[[1.85,5.44]],"id":38114646},{"atb":[[2.58,13.66],[2.56,0]],"id":37510843},{"atb":[[2.28,27.39]],"id":37569661}],"con":true,"img":false}]}
{"op":"mcm","clk":"5323043235","pt":1646326854616,"mc":[{"id":"1.195532873","rc":[{"atl":[[3.6,5.92]],"id":39590546},{"atb":[[2.12,17.05]],"id":37569661}],"con":true,"img":false}]}
{"op":"mcm","clk":"5323043243","pt":1646326854676,"mc":[{"id":"1.195532873","rc":[{"atl":[[3.8,58.46],[3.75,30.33]],"id":39590546}],"con":true,"img":false}]}
{"op":"mcm","clk":"5323043250","pt":1646326854781,"mc":[{"id":"1.195532873","rc":[{"atl":[[3.8,8.46]],"id":39590546},{"atb":[[2.12,0]],"id":37569661}],"con":true,"img":false}]}
{"op":"mcm","clk":"5323043255","pt":1646326854886,"mc":[{"id":"1.195532873","rc":[{"atb":[[1.2,2.24]],"id":38114646}],"con":true,"img":false}]}
{"op":"mcm","clk":"5323043287","pt":1646326855307,"mc":[{"id":"1.195532873","rc":[{"atb":[[1.2,1.76]],"id":38114646}],"con":true,"img":false}]}
{"op":"mcm","clk":"5323043295","pt":1646326855403,"mc":[{"id":"1.195532873","rc":[{"atb":[[2.76,0]],"id":39727103},{"atl":[[3.7,34.39]],"id":39590546}],"con":true,"img":false}]}
{"op":"mcm","clk":"5323043301","pt":1646326855504,"mc":[{"id":"1.195532873","rc":[{"atb":[[2.82,3.96]],"id":39727103}],"con":true,"img":false}]}
{"op":"mcm","clk":"5323043305","pt":1646326855610,"mc":[{"id":"1.195532873","rc":[{"atb":[[1.2,0]],"id":38114646}],"con":true,"img":false}]}
{"op":"mcm","clk":"5323043317","pt":1646326855713,"mc":[{"id":"1.195532873","rc":[{"atb":[[4.7,0]],"id":36601249},{"atb":[[2.02,3.41]],"id":38114646}],"con":true,"img":false}]}
{"op":"mcm","clk":"5323043319","pt":1646326855817,"mc":[{"id":"1.195532873","rc":[{"atb":[[4.9,1.99]],"id":36601249},{"atl":[[3.65,0]],"id":39590546}],"con":true,"img":false}]}
{"op":"mcm","clk":"5323043323","pt":1646326855875,"mc":[{"id":"1.195532873","rc":[{"atb":[[4.8,0],[4.4,0],[4,0],[4.6,0],[3.9,0],[4.2,0]],"id":36601249}],"con":true,"img":false}]}
{"op":"mcm","clk":"5323043327","pt":1646326855979,"mc":[{"id":"1.195532873","rc":[{"atl":[[3.6,0],[3.7,14.81],[3.75,66.69]],"id":39590546}],"con":true,"img":false}]}
{"op":"mcm","clk":"5323043330","pt":1646326856083,"mc":[{"id":"1.195532873","rc":[{"atb":[[1.99,0]],"id":38114646},{"atl":[[3.65,5.92]],"id":39590546}],"con":true,"img":false}]}
{"op":"mcm","clk":"5323043339","pt":1646326856197,"mc":[{"id":"1.195532873","rc":[{"atb":[[5,2.56]],"id":36601249},{"atb":[[2.06,1.99]],"id":38114646},{"atl":[[3.6,14.81]],"id":39590546}],"con":true,"img":false}]}
{"op":"mcm","clk":"5323043345","pt":1646326856297,"mc":[{"id":"1.195532873","rc":[{"atb":[[2.08,4.5]],"id":38114646},{"atl":[[3.75,30.33]],"id":39590546}],"con":true,"img":false}]}
{"op":"mcm","clk":"5323043372","pt":1646326856812,"mc":[{"id":"1.195532873","rc":[{"atl":[[3.55,8]],"id":39590546}],"con":true,"img":false}]}
{"op":"mcm","clk":"5323043377","pt":1646326857020,"mc":[{"id":"1.195532873","rc":[{"atl":[[3.65,0]],"id":39590546}],"con":true,"img":false}]}
{"op":"mcm","clk":"5323043382","pt":1646326857125,"mc":[{"id":"1.195532873","rc":[{"atb":[[2.16,2.15]],"id":37569661}],"con":true,"img":false}]}
{"op":"mcm","clk":"5323043389","pt":1646326857187,"mc":[{"id":"1.195532873","rc":[{"atb":[[1.95,0],[2.1,2.15]],"id":38114646},{"atb":[[2.34,2.15],[2.16,0]],"id":37569661}],"con":true,"img":false}]}
{"op":"mcm","clk":"5323043396","pt":1646326857285,"mc":[{"id":"1.195532873","rc":[{"atb":[[2.12,4.26]],"id":38114646}],"con":true,"img":false}]}
{"op":"mcm","clk":"5323043429","pt":1646326857904,"mc":[{"id":"1.195532873","rc":[{"atl":[[4,122.25],[3.85,28.07],[4.2,12.5]],"id":37569661}],"con":true,"img":false}]}
{"op":"mcm","clk":"5323043442","pt":1646326858110,"mc":[{"id":"1.195532873","rc":[{"atl":[[4,113.09]],"id":37569661}],"con":true,"img":false}]}
{"op":"mcm","clk":"5323043454","pt":1646326858321,"mc":[{"id":"1.195532873","rc":[{"atl":[[3.95,47.46]],"id":37569661}],"con":true,"img":false}]}
{"op":"mcm","clk":"5323043468","pt":1646326858485,"mc":[{"id":"1.195532873","rc":[{"atl":[[3.5,2.48]],"id":39590546}],"con":true,"img":false}]}
{"op":"mcm","clk":"5323043482","pt":1646326858696,"mc":[{"id":"1.195532873","rc":[{"atb":[[2.82,1.97]],"id":39727103}],"con":true,"img":false}]}
{"op":"mcm","clk":"5323043489","pt":1646326858799,"mc":[{"id":"1.195532873","rc":[{"atb":[[2.8,3.64]],"id":39727103}],"con":true,"img":false}]}
{"op":"mcm","clk":"5323043502","pt":1646326859014,"mc":[{"id":"1.195532873","rc":[{"atb":[[2.34,0]],"id":39590546}],"con":true,"img":false}]}
{"op":"mcm","clk":"5323043511","pt":1646326859113,"mc":[{"id":"1.195532873","rc":[{"atb":[[1.93,0],[2.08,15.45]],"id":38114646}],"con":true,"img":false}]}
{"op":"mcm","clk":"5323043521","pt":1646326859213,"mc":[{"id":"1.195532873","rc":[{"atb":[[5.1,5.85]],"id":36601249},{"atb":[[2.6,11.67],[2.58,7.44],[2.66,8.01]],"id":37510843},{"atb":[[2.28,25.4]],"id":37569661}],"con":true,"img":false}]}
{"op":"mcm","clk":"5323043527","pt":1646326859320,"mc":[{"id":"1.195532873","rc":[{"atb":[[4.5,12.9],[5.2,2.34]],"id":36601249},{"atb":[[2.36,1.99]],"id":37569661}],"con":true,"img":false}]}
{"op":"mcm","clk":"5323043532","pt":1646326859426,"mc":[{"id":"1.195532873","rc":[{"atb":[[2.62,2.38]],"id":37510843},{"atl":[[3.9,0]],"id":37569661}],"con":true,"img":false}]}
{"op":"mcm","clk":"5323043541","pt":1646326859531,"mc":[{"id":"1.195532873","rc":[{"atl":[[3.4,5.12]],"id":38114646},{"atb":[[2.12,11.06]],"id":37569661}],"con":true,"img":false}]}
{"op":"mcm","clk":"5323043548","pt":1646326859589,"mc":[{"id":"1.195532873","rc":[{"atb":[[2.58,2.48]],"id":37510843},{"atb":[[2.24,0],[2.18,84.75]],"id":37569661},{"atl":[[4,146.42],[3.85,0],[3.95,13.56]],"id":37569661}],"con":true,"img":false}]}
{"op":"mcm","clk":"5323043552","pt":1646326859696,"mc":[{"id":"1.195532873","rc":[{"atb":[[4.5,17.8]],"id":36601249},{"atl":[[3.5,16]],"id":38114646},{"atl":[[3.6,30.19],[3.7,0]],"id":39590546},{"atb":[[2.52,10.02]],"id":37510843},{"atb":[[2.14,35.09],[2.28,3.46]],"id":37569661}],"con":true,"img":false}]}
{"op":"mcm","clk":"5323043561","pt":1646326859803,"mc":[{"id":"1.195532873","rc":[{"atb":[[4.3,0]],"id":36601249},{"atl":[[3.6,0],[3.45,16],[3.4,0]],"id":38114646},{"atb":[[2.12,0],[2.18,0]],"id":37569661},{"atl":[[4,113.09],[3.9,11.79],[4.2,43.75]],"id":37569661}],"con":true,"img":false}]}
{"op":"mcm","clk":"5323043566","pt":1646326859905,"mc":[{"id":"1.195532873","rc":[{"atb":[[1.85,0],[1.95,6.84]],"id":38114646},{"atl":[[3.8,0]],"id":39590546}],"con":true,"img":false}]}
{"op":"mcm","clk":"5323043569","pt":1646326860006,"mc":[{"id":"1.195532873","rc":[{"atb":[[1.89,112.36]],"id":37569661}],"con":true,"img":false}]}
{"op":"mcm","clk":"5323043596","pt":1646326860405,"mc":[{"id":"1.195532873","rc":[{"atl":[[3.55,41.9],[4.2,26]],"id":38114646}],"con":true,"img":false}]}
{"op":"mcm","clk":"5323043602","pt":1646326860507,"mc":[{"id":"1.195532873","rc":[{"atl":[[3.95,0]],"id":37569661}],"con":true,"img":false}]}
{"op":"mcm","clk":"5323043613","pt":1646326860711,"mc":[{"id":"1.195532873","rc":[{"atl":[[3.9,0]],"id":37569661}],"con":true,"img":false}]}
{"op":"mcm","clk":"5323043626","pt":1646326860919,"mc":[{"id":"1.195532873","rc":[{"atl":[[3.4,23.59],[3.55,39.42]],"id":38114646},{"atl":[[3.95,4.22]],"id":37569661}],"con":true,"img":false}]}
{"op":"mcm","clk":"5323043637","pt":1646326861128,"mc":[{"id":"1.195532873","rc":[{"atb":[[2,8.64]],"id":38114646},{"atl":[[3.65,15.09]],"id":38114646}],"con":true,"img":false}]}
{"op":"mcm","clk":"5323043645","pt":1646326861233,"mc":[{"id":"1.195532873","rc":[{"atb":[[2,2.52]],"id":38114646}],"con":true,"img":false}]}
{"op":"mcm","clk":"5323043684","pt":1646326861607,"mc":[{"id":"1.195532873","rc":[{"atb":[[2.02,1.65]],"id":38114646},{"atl":[[3.6,15.38],[3.5,10.48]],"id":39590546},{"atb":[[2.16,31.54]],"id":37569661}],"con":true,"img":false}]}
{"op":"mcm","clk":"5323043716","pt":1646326862124,"mc":[{"id":"1.195532873","rc":[{"atb":[[2.8,1.99]],"id":39727103},{"atb":[[2.02,0]],"id":38114646},{"atb":[[2.64,0]],"id":37510843}],"con":true,"img":false}]}
{"op":"mcm","clk":"5323043726","pt":1646326862228,"mc":[{"id":"1.195532873","rc":[{"atl":[[3.9,2.48]],"id":37569661}],"con":true,"img":false}]}
{"op":"mcm","clk":"5323043734","pt":1646326862333,"mc":[{"id":"1.195532873","rc":[{"atb":[[2.84,1.65]],"id":39727103},{"atb":[[2.68,1.65]],"id":37510843}],"con":true,"img":false}]}
{"op":"mcm","clk":"5323043750","pt":1646326862496,"mc":[{"id":"1.195532873","rc":[{"atb":[[2.84,3.58]],"id":39727103},{"atb":[[2.7,2.21]],"id":37510843}],"con":true,"img":false}]}
{"op":"mcm","clk":"5323043852","pt":1646326864113,"mc":[{"id":"1.195532873","rc":[{"atb":[[2.4,3.31]],"id":39590546}],"con":true,"img":false}]}
{"op":"mcm","clk":"5323043873","pt":1646326864521,"mc":[{"id":"1.195532873","rc":[{"atb":[[4.9,0]],"id":36601249}],"con":true,"img":false}]}
{"op":"mcm","clk":"5323043876","pt":1646326864626,"mc":[{"id":"1.195532873","rc":[{"atb":[[5.1,7.84]],"id":36601249}],"con":true,"img":false}]}
{"op":"mcm","clk":"5323043889","pt":1646326864833,"mc":[{"id":"1.195532873","rc":[{"atb":[[2.06,0]],"id":38114646},{"atl":[[3.35,2.48]],"id":38114646}],"con":true,"img":false}]}
{"op":"mcm","clk":"5323043895","pt":1646326864895,"mc":[{"id":"1.195532873","rc":[{"atb":[[1.02,1.99]],"id":38114646}],"con":true,"img":false}]}
{"op":"mcm","clk":"5323043901","pt":1646326865000,"mc":[{"id":"1.195532873","rc":[{"atl":[[3.45,32.33],[3.5,0]],"id":38114646}],"con":true,"img":false}]}
{"op":"mcm","clk":"5323043910","pt":1646326865105,"mc":[{"id":"1.195532873","rc":[{"atb":[[4.5,12.9],[4.6,5.12]],"id":36601249},{"atb":[[2.64,4.42],[2.52,0]],"id":37510843}],"con":true,"img":false}]}
{"op":"mcm","clk":"5323043918","pt":1646326865209,"mc":[{"id":"1.195532873","rc":[{"atl":[[3.45,16.33],[3.35,26.07]],"id":38114646},{"atl":[[3.9,6.7],[4.2,12.5]],"id":37569661}],"con":true,"img":false}]}
{"op":"mcm","clk":"5323043987","pt":1646326866092,"mc":[{"id":"1.195532873","rc":[{"atb":[[4.5,0],[5,12.31]],"id":36601249}],"con":true,"img":false}]}
{"op":"mcm","clk":"5323044001","pt":1646326866307,"mc":[{"id":"1.195532873","rc":[{"atb":[[2.8,0]],"id":39727103},{"atl":[[3.6,40.86],[3.5,20.04]],"id":39590546}],"con":true,"img":false}]}
{"op":"mcm","clk":"5323044010","pt":1646326866408,"mc":[{"id":"1.195532873","rc":[{"atb":[[2.62,18.04],[2.86,1.99]],"id":39727103},{"atl":[[3.75,14.55]],"id":39590546},{"atl":[[4.2,31.25]],"id":37569661}],"con":true,"img":false}]}
{"op":"mcm","clk":"5323044017","pt":1646326866512,"mc":[{"id":"1.195532873","rc":[{"atl":[[3.55,0]],"id":39590546}],"con":true,"img":false}]}
{"op":"mcm","clk":"5323044027","pt":1646326866718,"mc":[{"id":"1.195532873","rc":[{"atb":[[5.1,5.85]],"id":36601249},{"atb":[[2.14,2.98]],"id":38114646},{"atl":[[3.6,44.86]],"id":39590546}],"con":true,"img":false}]}
{"op":"mcm","clk":"5323044035","pt":1646326866826,"mc":[{"id":"1.195532873","rc":[{"atb":[[5.3,1.99]],"id":36601249},{"atb":[[2.14,7.11]],"id":38114646}],"con":true,"img":false}]}
{"op":"mcm","clk":"5323044041","pt":1646326866926,"mc":[{"id":"1.195532873","rc":[{"atl":[[3.6,40.86]],"id":39590546}],"con":true,"img":false}]}
{"op":"mcm","clk":"5323044045","pt":1646326867032,"mc":[{"id":"1.195532873","rc":[{"atb":[[5.3,4.24]],"id":36601249}],"con":true,"img":false}]}
{"op":"mcm","clk":"5323044099","pt":1646326867821,"mc":[{"id":"1.195532873","rc":[{"atb":[[2.22,2.15],[2.34,0]],"id":37569661}],"con":true,"img":false}]}
{"op":"mcm","clk":"5323044197","pt":1646326869497,"mc":[{"id":"1.195532873","rc":[{"atl":[[4,119.37],[3.85,5.76]],"id":37569661}],"con":true,"img":false}]}
{"op":"mcm","clk":"5323044205","pt":1646326869628,"mc":[{"id":"1.195532873","rc":[{"atl":[[3.95,22.42]],"id":37569661}],"con":true,"img":false}]}
{"op":"mcm","clk":"5323044210","pt":1646326869725,"mc":[{"id":"1.195532873","rc":[{"atl":[[4,19.61],[4.3,5.75]],"id":37569661}],"con":true,"img":false}]}
{"op":"mcm","clk":"5323044227","pt":1646326870037,"mc":[{"id":"1.195532873","rc":[{"atl":[[4,13.33],[4.3,0]],"id":37569661}],"con":true,"img":false}]}
{"op":"mcm","clk":"5323044263","pt":1646326870615,"mc":[{"id":"1.195532873","rc":[{"atb":[[4.9,3.85]],"id":36601249},{"atb":[[2.1,31.45],[2.08,4.5]],"id":38114646}],"con":true,"img":false}]}
{"op":"mcm","clk":"5323044272","pt":1646326870721,"mc":[{"id":"1.195532873","rc":[{"atb":[[5.3,11.35]],"id":36601249},{"atb":[[2.64,16.34]],"id":37510843}],"con":true,"img":false}]}
{"op":"mcm","clk":"5323044278","pt":1646326870824,"mc":[{"id":"1.195532873","rc":[{"atb":[[2.6,2.15],[2.7,7.93]],"id":37510843}],"con":true,"img":false}]}
{"op":"mcm","clk":"5323044286","pt":1646326870921,"mc":[{"id":"1.195532873","rc":[{"atb":[[5.1,0]],"id":36601249}],"con":true,"img":false}]}
{"op":"mcm","clk":"5323044292","pt":1646326871026,"mc":[{"id":"1.195532873","rc":[{"atb":[[4.9,0]],"id":36601249},{"atb":[[2.84,1.93]],"id":39727103},{"atb":[[2.38,3.08]],"id":39590546},{"atb":[[2.64,11.92],[2.62,18.32],[2.66,2.29],[2.68,0]],"id":37510843},{"atb":[[1.98,0],[2.12,35.71],[1.94,0],[2.14,0],[1.9,0]],"id":37569661},{"atl":[[3.95,35.98]],"id":37569661}],"con":true,"img":false}]}
{"op":"mcm","clk":"5323044305","pt":1646326871235,"mc":[{"id":"1.195532873","rc":[{"atb":[[2.88,1.65]],"id":39727103},{"atb":[[2.42,1.65]],"id":39590546},{"atb":[[2.72,1.65]],"id":37510843}],"con":true,"img":false}]}
{"op":"mcm","clk":"5323044315","pt":1646326871339,"mc":[{"id":"1.195532873","rc":[{"atl":[[3.9,4.22]],"id":37569661}],"con":true,"img":false}]}
{"op":"mcm","clk":"5323044320","pt":1646326871400,"mc":[{"id":"1.195532873","rc":[{"atb":[[2.62,2.15]],"id":39727103},{"atb":[[2.74,2.12]],"id":37510843}],"con":true,"img":false}]}
{"op":"mcm","clk":"5323044326","pt":1646326871548,"mc":[{"id":"1.195532873","rc":[{"atl":[[3.95,67.23],[3.9,0]],"id":37569661}],"con":true,"img":false}]}
{"op":"mcm","clk":"5323044334","pt":1646326871604,"mc":[{"id":"1.195532873","rc":[{"atl":[[3.6,15.38],[3.75,53.59]],"id":39590546}],"con":true,"img":false}]}
{"op":"mcm","clk":"5323044345","pt":1646326871810,"mc":[{"id":"1.195532873","rc":[{"atl":[[3.8,6.86]],"id":39590546}],"con":true,"img":false}]}
{"op":"mcm","clk":"5323044354","pt":1646326871912,"mc":[{"id":"1.195532873","rc":[{"atl":[[3.45,96.17],[3.55,0]],"id":38114646}],"con":true,"img":false}]}
{"op":"mcm","clk":"5323044360","pt":1646326872129,"mc":[{"id":"1.195532873","rc":[{"atl":[[3.55,18.62]],"id":38114646},{"atl":[[3.8,0]],"id":39590546}],"con":true,"img":false}]}
{"op":"mcm","clk":"5323044371","pt":1646326872435,"mc":[{"id":"1.195532873","rc":[{"atl":[[3.3,34.78]],"id":38114646}],"con":true,"img":false}]}
{"op":"mcm","clk":"5323044378","pt":1646326872539,"mc":[{"id":"1.195532873","rc":[{"atl":[[3.55,0],[3.25,26.08]],"id":38114646}],"con":true,"img":false}]}
{"op":"mcm","clk":"5323044386","pt":1646326872645,"mc":[{"id":"1.195532873","rc":[{"atl":[[3.35,2.48],[3.4,0]],"id":38114646}],"con":true,"img":false}]}
{"op":"mcm","clk":"5323044394","pt":1646326872702,"mc":[{"id":"1.195532873","rc":[{"atl":[[3.25,0],[3.3,78.26]],"id":38114646}],"con":true,"img":false}]}
{"op":"mcm","clk":"5323044401","pt":1646326872809,"mc":[{"id":"1.195532873","rc":[{"atl":[[3.35,45.03],[3.3,34.78]],"id":38114646}],"con":true,"img":false}]}
{"op":"mcm","clk":"5323044409","pt":1646326872914,"mc":[{"id":"1.195532873","rc":[{"atl":[[3.45,79.84],[3.4,16.67]],"id":38114646}],"con":true,"img":false}]}
{"op":"mcm","clk":"5323044438","pt":1646326873428,"mc":[{"id":"1.195532873","rc":[{"atb":[[2.36,0]],"id":37569661}],"con":true,"img":false}]}
{"op":"mcm","clk":"5323044442","pt":1646326873530,"mc":[{"id":"1.195532873","rc":[{"atb":[[2.3,1.99]],"id":37569661}],"con":true,"img":false}]}
{"op":"mcm","clk":"5323044448","pt":1646326873635,"mc":[{"id":"1.195532873","rc":[{"atl":[[3.85,0]],"id":37569661}],"con":true,"img":false}]}
{"op":"mcm","clk":"5323044461","pt":1646326873844,"mc":[{"id":"1.195532873","rc":[{"atl":[[3.9,4.22]],"id":37569661}],"con":true,"img":false}]}
{"op":"mcm","clk":"5323044485","pt":1646326874115,"mc":[{"id":"1.195532873","rc":[{"atl":[[3.35,42.55]],"id":38114646},{"atl":[[3.8,2.48]],"id":37569661}],"con":true,"img":false}]}
{"op":"mcm","clk":"5323044502","pt":1646326874326,"mc":[{"id":"1.195532873","rc":[{"atl":[[3.35,0],[3.4,58.34]],"id":38114646},{"atb":[[2.12,12.4]],"id":39590546},{"atb":[[2.34,0],[2.42,5.02]],"id":37510843},{"atl":[[4.8,0],[4.4,29.41]],"id":37569661}],"con":true,"img":false}]}
{"op":"mcm","clk":"5323044516","pt":1646326874532,"mc":[{"id":"1.195532873","rc":[{"atl":[[3.3,0]],"id":38114646}],"con":true,"img":false}]}
{"op":"mcm","clk":"5323044525","pt":1646326874636,"mc":[{"id":"1.195532873","rc":[{"atb":[[2.42,0]],"id":37510843}],"con":true,"img":false}]}
{"op":"mcm","clk":"5323044533","pt":1646326874740,"mc":[{"id":"1.195532873","rc":[{"atl":[[3.35,28.93]],"id":38114646}],"con":true,"img":false}]}
{"op":"mcm","clk":"5323044576","pt":1646326875418,"mc":[{"id":"1.195532873","rc":[{"atb":[[2.16,0]],"id":37569661}],"con":true,"img":false}]}
{"op":"mcm","clk":"5323044586","pt":1646326875633,"mc":[{"id":"1.195532873","rc":[{"atb":[[2.86,0]],"id":39727103}],"con":true,"img":false}]}
{"op":"mcm","clk":"5323044590","pt":1646326875730,"mc":[{"id":"1.195532873","rc":[{"atb":[[2.84,3.92]],"id":39727103},{"atl":[[3.45,96.17],[3.4,41.67]],"id":38114646},{"atl":[[3.9,18.01]],"id":37569661}],"con":true,"img":false}]}
{"op":"mcm","clk":"5323044596","pt":1646326875839,"mc":[{"id":"1.195532873","rc":[{"atb":[[3.5,16],[3.4,0]],"id":36601249},{"atb":[[2.26,31.75],[2.48,33.33],[2.38,0],[2.2,0]],"id":39727103},{"atb":[[2.1,2.15]],"id":38114646},{"atb":[[2.12,0],[2.1,36.36]],"id":37569661},{"atl":[[3.95,53.67]],"id":37569661}],"con":true,"img":false}]}
{"op":"mcm","clk":"5323044602","pt":1646326875938,"mc":[{"id":"1.195532873","rc":[{"atb":[[1.84,5.24]],"id":38114646}],"con":true,"img":false}]}
{"op":"mcm","clk":"5323044609","pt":1646326876042,"mc":[{"id":"1.195532873","rc":[{"atb":[[3.35,3.58]],"id":36601249}],"con":true,"img":false}]}
{"op":"mcm","clk":"5323044615","pt":1646326876147,"mc":[{"id":"1.195532873","rc":[{"atb":[[1.84,0]],"id":38114646}],"con":true,"img":false}]}
{"op":"mcm","clk":"5323044619","pt":1646326876213,"mc":[{"id":"1.195532873","rc":[{"atb":[[3.35,0]],"id":36601249}],"con":true,"img":false}]}
{"op":"mcm","clk":"5323044625","pt":1646326876310,"mc":[{"id":"1.195532873","rc":[{"atl":[[3.3,2.48]],"id":38114646}],"con":true,"img":false}]}
{"op":"mcm","clk":"5323044633","pt":1646326876416,"mc":[{"id":"1.195532873","rc":[{"atb":[[2.28,7.92],[2.1,65.69]],"id":37569661}],"con":true,"img":false}]}
{"op":"mcm","clk":"5323044638","pt":1646326876521,"mc":[{"id":"1.195532873","rc":[{"atl":[[5.7,3.22]],"id":39727103},{"atb":[[1.89,8.76],[1.95,0]],"id":38114646},{"atb":[[2.62,2.38],[2.68,11.92]],"id":37510843},{"atb":[[2.24,36.36],[1.89,0]],"id":37569661}],"con":true,"img":false}]}
{"op":"mcm","clk":"5323044646","pt":1646326876628,"mc":[{"id":"1.195532873","rc":[{"atl":[[5.8,23.33],[5.7,22.4]],"id":39727103}],"con":true,"img":false}]}
{"op":"mcm","clk":"5323044652","pt":1646326876728,"mc":[{"id":"1.195532873","rc":[{"atl":[[5.7,19.18]],"id":39727103},{"atb":[[2.24,0],[2.18,84.75]],"id":37569661}],"con":true,"img":false}]}
{"op":"mcm","clk":"5323044658","pt":1646326876829,"mc":[{"id":"1.195532873","rc":[{"atl":[[3.95,22.42],[3.8,20.49]],"id":37569661}],"con":true,"img":false}]}
{"op":"mcm","clk":"5323044664","pt":1646326876938,"mc":[{"id":"1.195532873","rc":[{"atl":[[3.95,53.67],[3.8,2.48]],"id":37569661}],"con":true,"img":false}]}
{"op":"mcm","clk":"5323044672","pt":1646326877033,"mc":[{"id":"1.195532873","rc":[{"atl":[[3.8,22.98]],"id":37569661}],"con":true,"img":false}]}
{"op":"mcm","clk":"5323044680","pt":1646326877240,"mc":[{"id":"1.195532873","rc":[{"atl":[[3.95,22.42]],"id":37569661}],"con":true,"img":false}]}
{"op":"mcm","clk":"5323044686","pt":1646326877344,"mc":[{"id":"1.195532873","rc":[{"atb":[[2.54,0]],"id":36601249},{"atb":[[2.62,0]],"id":39727103},{"atb":[[2.1,0]],"id":38114646},{"atb":[[2.24,0]],"id":39590546},{"atb":[[2.6,0]],"id":37510843},{"atb":[[2.22,0]],"id":37569661}],"con":true,"img":false}]}
{"op":"mcm","clk":"5323044712","pt":1646326877812,"mc":[{"id":"1.195532873","rc":[{"atb":[[2.56,38.08]],"id":39727103}],"con":true,"img":false}]}
{"op":"mcm","clk":"5323044729","pt":1646326878125,"mc":[{"id":"1.195532873","rc":[{"atl":[[3.45,79.84],[3.4,58.34]],"id":38114646}],"con":true,"img":false}]}
{"op":"mcm","clk":"5323044808","pt":1646326879536,"mc":[{"id":"1.195532873","rc":[{"atl":[[3.4,16.67],[3.3,31.41]],"id":38114646}],"con":true,"img":false}]}
{"op":"mcm","clk":"5323044842","pt":1646326880061,"mc":[{"id":"1.195532873","rc":[{"atb":[[4.3,16.47],[5.3,4.24],[5,2.56],[4.6,0]],"id":36601249},{"atl":[[16,0],[11,2.5],[12,0],[13,13.33],[14,7.69]],"id":36601249},{"atb":[[2.6,33.33],[2.48,0],[2.86,9.46]],"id":39727103},{"atb":[[1.89,0]],"id":38114646},{"atl":[[4.6,0],[4.2,23.5]],"id":38114646},{"atb":[[2.4,17.33],[2.36,28.59]],"id":39590546},{"atb":[[2.28,12.02],[2.18,0],[2.08,92.59]],"id":37569661}],"con":true,"img":false}]}
{"op":"mcm","clk":"5323044851","pt":1646326880118,"mc":[{"id":"1.195532873","rc":[{"atb":[[2.88,0]],"id":39727103},{"atb":[[2.72,0]],"id":37510843}],"con":true,"img":false}]}
{"op":"mcm","clk":"5323044857","pt":1646326880221,"mc":[{"id":"1.195532873","rc":[{"atl":[[11,8.3],[12,9.09],[12.5,19.19],[13,5]],"id":36601249},{"atb":[[2.56,25.99]],"id":39727103},{"atb":[[1.84,9]],"id":38114646},{"atb":[[2.12,0]],"id":39590546},{"atb":[[2.28,7.92]],"id":37569661}],"con":true,"img":false}]}
{"op":"mcm","clk":"5323044868","pt":1646326880425,"mc":[{"id":"1.195532873","rc":[{"atl":[[12,18.96],[12.5,24.14]],"id":36601249},{"atb":[[2.86,11.11]],"id":39727103},{"atb":[[2.76,1.65]],"id":37510843},{"atb":[[2.32,1.65],[2.12,15.85]],"id":37569661}],"con":true,"img":false}]}
{"op":"mcm","clk":"5323044875","pt":1646326880479,"mc":[{"id":"1.195532873","rc":[{"atl":[[11.5,0],[12.5,12.18]],"id":36601249}],"con":true,"img":false}]}
{"op":"mcm","clk":"5323044887","pt":1646326880690,"mc":[{"id":"1.195532873","rc":[{"atl":[[12,0]],"id":36601249}],"con":true,"img":false}]}
{"op":"mcm","clk":"5323044895","pt":1646326880897,"mc":[{"id":"1.195532873","rc":[{"atl":[[3.75,19.45]],"id":37569661}],"con":true,"img":false}]}
{"op":"mcm","clk":"5323044904","pt":1646326881003,"mc":[{"id":"1.195532873","rc":[{"atb":[[2.84,1.93]],"id":39727103},{"atl":[[3.9,85.73]],"id":37569661}],"con":true,"img":false}]}
{"op":"mcm","clk":"5323044909","pt":1646326881106,"mc":[{"id":"1.195532873","rc":[{"atb":[[2.88,1.99]],"id":39727103},{"atl":[[3.95,0],[3.9,81.51]],"id":37569661}],"con":true,"img":false}]}
{"op":"mcm","clk":"5323044919","pt":1646326881218,"mc":[{"id":"1.195532873","rc":[{"atb":[[4.3,0]],"id":36601249},{"atl":[[12,3.64],[12.5,8.7]],"id":36601249},{"atb":[[2.28,3.46],[2.1,43.54],[2.08,0]],"id":37569661},{"atl":[[3.85,14.04],[3.9,67.72]],"id":37569661}],"con":true,"img":false}]}
{"op":"mcm","clk":"5323044924","pt":1646326881317,"mc":[{"id":"1.195532873","rc":[{"atb":[[3.95,6.8]],"id":36601249},{"atb":[[1.86,116.28]],"id":37569661}],"con":true,"img":false}]}
{"op":"mcm","clk":"5323044927","pt":1646326881418,"mc":[{"id":"1.195532873","rc":[{"atb":[[2.1,36.36]],"id":37569661}],"con":true,"img":false}]}
{"op":"mcm","clk":"5323044942","pt":1646326881627,"mc":[{"id":"1.195532873","rc":[{"atb":[[2.66,11.81]],"id":37510843}],"con":true,"img":false}]}
{"op":"mcm","clk":"5323044948","pt":1646326881732,"mc":[{"id":"1.195532873","rc":[{"atb":[[1.89,8.76],[1.84,0]],"id":38114646},{"atb":[[2.62,12.6],[2.68,0]],"id":37510843},{"atl":[[3.8,20.5]],"id":37569661}],"con":true,"img":false}]}
{"op":"mcm","clk":"5323044960","pt":1646326881894,"mc":[{"id":"1.195532873","rc":[{"atb":[[2.66,2.29]],"id":37510843}],"con":true,"img":false}]}
{"op":"mcm","clk":"5323044968","pt":1646326882007,"mc":[{"id":"1.195532873","rc":[{"atb":[[2.64,0],[2.66,18.59]],"id":37510843}],"con":true,"img":false}]}
{"op":"mcm","clk":"5323044976","pt":1646326882155,"mc":[{"id":"1.195532873","rc":[{"atb":[[2.74,7.84]],"id":37510843}],"con":true,"img":false}]}
{"op":"mcm","clk":"5323044984","pt":1646326882218,"mc":[{"id":"1.195532873","rc":[{"atl":[[3.85,49.13],[3.8,0]],"id":37569661}],"con":true,"img":false}]}
{"op":"mcm","clk":"5323044990","pt":1646326882313,"mc":[{"id":"1.195532873","rc":[{"atb":[[2.7,2.21]],"id":37510843}],"con":true,"img":false}]}
{"op":"mcm","clk":"5323044996","pt":1646326882416,"mc":[{"id":"1.195532873","rc":[{"atl":[[3.75,0]],"id":37569661}],"con":true,"img":false}]}
{"op":"mcm","clk":"5323045002","pt":1646326882519,"mc":[{"id":"1.195532873","rc":[{"atl":[[3.8,17.18]],"id":37569661}],"con":true,"img":false}]}
{"op":"mcm","clk":"5323045043","pt":1646326883091,"mc":[{"id":"1.195532873","rc":[{"atl":[[3.8,19.66]],"id":37569661}],"con":true,"img":false}]}
{"op":"mcm","clk":"5323045049","pt":1646326883195,"mc":[{"id":"1.195532873","rc":[{"atl":[[3.4,64.23]],"id":38114646}],"con":true,"img":false}]}
{"op":"mcm","clk":"5323045055","pt":1646326883311,"mc":[{"id":"1.195532873","rc":[{"atl":[[3.45,0]],"id":38114646}],"con":true,"img":false}]}
{"op":"mcm","clk":"5323045062","pt":1646326883511,"mc":[{"id":"1.195532873","rc":[{"atb":[[2.22,81.97]],"id":39727103}],"con":true,"img":false}]}
{"op":"mcm","clk":"5323045080","pt":1646326883719,"mc":[{"id":"1.195532873","rc":[{"atl":[[3.25,27.03]],"id":38114646}],"con":true,"img":false}]}
{"op":"mcm","clk":"5323045101","pt":1646326883937,"mc":[{"id":"1.195532873","rc":[{"atl":[[3.35,0]],"id":38114646}],"con":true,"img":false}]}
{"op":"mcm","clk":"5323045138","pt":1646326884409,"mc":[{"id":"1.195532873","rc":[{"atb":[[2.3,30.77],[2.26,0]],"id":39727103},{"atl":[[3.35,17.02],[3.4,47.56]],"id":38114646},{"atb":[[2,40],[2.06,0],[2.1,0]],"id":37569661},{"atl":[[3.85,35.09],[3.9,81.51]],"id":37569661}],"con":true,"img":false}]}
{"op":"mcm","clk":"5323045152","pt":1646326884711,"mc":[{"id":"1.195532873","rc":[{"atl":[[3.55,7.01]],"id":38114646}],"con":true,"img":false}]}
{"op":"mcm","clk":"5323045174","pt":1646326885129,"mc":[{"id":"1.195532873","rc":[{"atb":[[1.89,0],[1.94,9],[2.08,34.66]],"id":38114646},{"atl":[[3.55,0]],"id":38114646},{"atb":[[2.62,2.37],[2.7,14.81]],"id":37510843}],"con":true,"img":false}]}
{"op":"mcm","clk":"5323045224","pt":1646326886018,"mc":[{"id":"1.195532873","rc":[{"atl":[[3.3,28.93]],"id":38114646}],"con":true,"img":false}]}
{"op":"mcm","clk":"5323045240","pt":1646326886226,"mc":[{"id":"1.195532873","rc":[{"atl":[[3.35,59.57],[3.3,0]],"id":38114646}],"con":true,"img":false}]}
{"op":"mcm","clk":"5323045253","pt":1646326886432,"mc":[{"id":"1.195532873","rc":[{"atl":[[3.35,17.02],[3.4,89.23]],"id":38114646}],"con":true,"img":false}]}
{"op":"mcm","clk":"5323045274","pt":1646326886698,"mc":[{"id":"1.195532873","rc":[{"atb":[[2.12,0]],"id":37569661}],"con":true,"img":false}]}
{"op":"mcm","clk":"5323045390","pt":1646326888318,"mc":[{"id":"1.195532873","rc":[{"atl":[[3.2,2.48]],"id":38114646}],"con":true,"img":false}]}
{"op":"mcm","clk":"5323045402","pt":1646326888526,"mc":[{"id":"1.195532873","rc":[{"atl":[[3.15,18.1]],"id":38114646}],"con":true,"img":false}]}
{"op":"mcm","clk":"5323045417","pt":1646326888733,"mc":[{"id":"1.195532873","rc":[{"atl":[[3.25,0]],"id":38114646}],"con":true,"img":false}]}
{"op":"mcm","clk":"5323045423","pt":1646326888840,"mc":[{"id":"1.195532873","rc":[{"atb":[[3.4,41.67]],"id":36601249},{"atl":[[13,13.33]],"id":36601249}],"con":true,"img":false}]}
{"op":"mcm","clk":"5323045437","pt":1646326888993,"mc":[{"id":"1.195532873","rc":[{"atb":[[3.1,0]],"id":36601249},{"atl":[[26,0]],"id":36601249},{"atb":[[2.12,0],[2.08,0],[2.56,0],[2.86,9.46],[2.78,29.3],[2.16,0]],"id":39727103}],"con":true,"img":false}]}
{"op":"mcm","clk":"5323045447","pt":1646326889201,"mc":[{"id":"1.195532873","rc":[{"atb":[[2.9,1.65]],"id":39727103}],"con":true,"img":false}]}
{"op":"mcm","clk":"5323045543","pt":1646326890713,"mc":[{"id":"1.195532873","rc":[{"atl":[[3.2,0]],"id":38114646}],"con":true,"img":false}]}
{"op":"mcm","clk":"5323045559","pt":1646326890919,"mc":[{"id":"1.195532873","rc":[{"atl":[[3.15,0]],"id":38114646}],"con":true,"img":false}]}
{"op":"mcm","clk":"5323045561","pt":1646326891023,"mc":[{"id":"1.195532873","rc":[{"atl":[[4.1,2.5],[3.4,41.67]],"id":38114646}],"con":true,"img":false}]}
{"op":"mcm","clk":"5323045566","pt":1646326891128,"mc":[{"id":"1.195532873","rc":[{"atb":[[2.8,9.09]],"id":39727103},{"atl":[[3.2,18.1],[3.65,79.31]],"id":38114646},{"atl":[[3.95,5.3]],"id":37569661}],"con":true,"img":false}]}
{"op":"mcm","clk":"5323045580","pt":1646326891236,"mc":[{"id":"1.195532873","rc":[{"atb":[[2.88,15.61]],"id":39727103}],"con":true,"img":false}]}
{"op":"mcm","clk":"5323045586","pt":1646326891337,"mc":[{"id":"1.195532873","rc":[{"atb":[[2.8,0],[2.86,0]],"id":39727103},{"atl":[[3.2,0],[3.35,0],[3.3,17.39]],"id":38114646},{"atb":[[2.68,15.68],[2.7,2.21]],"id":37510843},{"atb":[[2.02,0],[2.04,7.66]],"id":37569661},{"atl":[[3.95,0]],"id":37569661}],"con":true,"img":false}]}
{"op":"mcm","clk":"5323045590","pt":1646326891391,"mc":[{"id":"1.195532873","rc":[{"atl":[[3.25,18.1]],"id":38114646}],"con":true,"img":false}]}
{"op":"mcm","clk":"5323045597","pt":1646326891497,"mc":[{"id":"1.195532873","rc":[{"atl":[[12.5,24.46]],"id":36601249},{"atl":[[3.4,0],[3.65,117.05]],"id":38114646}],"con":true,"img":false}]}
{"op":"mcm","clk":"5323045627","pt":1646326891914,"mc":[{"id":"1.195532873","rc":[{"atb":[[2.26,79.37]],"id":39727103}],"con":true,"img":false}]}
{"op":"mcm","clk":"5323045633","pt":1646326892019,"mc":[{"id":"1.195532873","rc":[{"atb":[[1.98,102.04]],"id":37569661},{"atl":[[4,33.33]],"id":37569661}],"con":true,"img":false}]}
{"op":"mcm","clk":"5323045705","pt":1646326893125,"mc":[{"id":"1.195532873","rc":[{"atb":[[2.66,2.29],[2.68,33.96]],"id":37510843}],"con":true,"img":false}]}
{"op":"mcm","clk":"5323045709","pt":1646326893223,"mc":[{"id":"1.195532873","rc":[{"atl":[[3.2,2.48]],"id":38114646}],"con":true,"img":false}]}
{"op":"mcm","clk":"5323045734","pt":1646326893640,"mc":[{"id":"1.195532873","rc":[{"atl":[[3.25,27.22]],"id":38114646}],"con":true,"img":false}]}
{"op":"mcm","clk":"5323045748","pt":1646326893902,"mc":[{"id":"1.195532873","rc":[{"atl":[[3.25,18.1]],"id":38114646}],"con":true,"img":false}]}
{"op":"mcm","clk":"5323045778","pt":1646326894322,"mc":[{"id":"1.195532873","rc":[{"atl":[[3.3,66.39],[3.65,52.83]],"id":38114646}],"con":true,"img":false}]}
{"op":"mcm","clk":"5323045805","pt":1646326894839,"mc":[{"id":"1.195532873","rc":[{"atl":[[3.15,18.91]],"id":38114646}],"con":true,"img":false}]}
{"op":"mcm","clk":"5323045815","pt":1646326894999,"mc":[{"id":"1.195532873","rc":[{"atl":[[3.25,0]],"id":38114646}],"con":true,"img":false}]}
{"op":"mcm","clk":"5323045898","pt":1646326896406,"mc":[{"id":"1.195532873","rc":[{"atb":[[3.3,65.22]],"id":36601249},{"atl":[[14,11.54]],"id":36601249}],"con":true,"img":false}]}
{"op":"mcm","clk":"5323045910","pt":1646326896614,"mc":[{"id":"1.195532873","rc":[{"atl":[[3.2,47.93],[3.65,15.09]],"id":38114646}],"con":true,"img":false}]}
{"op":"mcm","clk":"5323045920","pt":1646326896727,"mc":[{"id":"1.195532873","rc":[{"atl":[[3.2,45.45]],"id":38114646},{"atb":[[2.6,3.66]],"id":37510843}],"con":true,"img":false}]}
{"op":"mcm","clk":"5323045926","pt":1646326896833,"mc":[{"id":"1.195532873","rc":[{"atl":[[3.3,109.87]],"id":38114646},{"atb":[[2.6,0]],"id":37510843}],"con":true,"img":false}]}
{"op":"mcm","clk":"5323045933","pt":1646326896925,"mc":[{"id":"1.195532873","rc":[{"atl":[[3.2,0]],"id":38114646}],"con":true,"img":false}]}
{"op":"mcm","clk":"5323045942","pt":1646326897138,"mc":[{"id":"1.195532873","rc":[{"atl":[[3.15,0],[3.3,17.39],[3.65,120.83]],"id":38114646}],"con":true,"img":false}]}
{"op":"mcm","clk":"5323045946","pt":1646326897241,"mc":[{"id":"1.195532873","rc":[{"atl":[[3.2,25.5]],"id":38114646}],"con":true,"img":false}]}
{"op":"mcm","clk":"5323046038","pt":1646326898842,"mc":[{"id":"1.195532873","rc":[{"atl":[[3.4,41.67]],"id":38114646}],"con":true,"img":false}]}
{"op":"mcm","clk":"5323046052","pt":1646326899047,"mc":[{"id":"1.195532873","rc":[{"atl":[[3.2,0]],"id":38114646}],"con":true,"img":false}]}
{"op":"mcm","clk":"5323046058","pt":1646326899150,"mc":[{"id":"1.195532873","rc":[{"atb":[[3.45,14.85]],"id":36601249},{"atl":[[3.25,32.17]],"id":38114646}],"con":true,"img":false}]}
{"op":"mcm","clk":"5323046073","pt":1646326899314,"mc":[{"id":"1.195532873","rc":[{"atb":[[3.45,5]],"id":36601249},{"atl":[[3.15,2.48]],"id":38114646}],"con":true,"img":false}]}
{"op":"mcm","clk":"5323046078","pt":1646326899419,"mc":[{"id":"1.195532873","rc":[{"atb":[[2.22,122.95]],"id":39727103},{"atl":[[3.2,36.36]],"id":38114646}],"con":true,"img":false}]}
{"op":"mcm","clk":"5323046082","pt":1646326899517,"mc":[{"id":"1.195532873","rc":[{"atb":[[1.96,156.25]],"id":37569661},{"atl":[[4.2,46.88]],"id":37569661}],"con":true,"img":false}]}
{"op":"mcm","clk":"5323046090","pt":1646326899626,"mc":[{"id":"1.195532873","rc":[{"atl":[[3.25,0]],"id":38114646}],"con":true,"img":false}]}
{"op":"mcm","clk":"5323046236","pt":1646326902041,"mc":[{"id":"1.195532873","rc":[{"atl":[[3.15,22.86],[3.3,66.39],[3.65,52.83]],"id":38114646}],"con":true,"img":false}]}
{"op":"mcm","clk":"5323046247","pt":1646326902248,"mc":[{"id":"1.195532873","rc":[{"atb":[[2.54,14.01]],"id":39727103},{"atl":[[3.2,0],[3.65,15.09]],"id":38114646}],"con":true,"img":false}]}
{"op":"mcm","clk":"5323046256","pt":1646326902350,"mc":[{"id":"1.195532873","rc":[{"atl":[[3.15,59.22]],"id":38114646}],"con":true,"img":false}]}
{"op":"mcm","clk":"5323046265","pt":1646326902406,"mc":[{"id":"1.195532873","rc":[{"atb":[[2.54,11]],"id":39727103},{"atl":[[3.4,83.34]],"id":38114646}],"con":true,"img":false}]}
{"op":"mcm","clk":"5323046270","pt":1646326902509,"mc":[{"id":"1.195532873","rc":[{"atl":[[3.15,22.86]],"id":38114646}],"con":true,"img":false}]}
{"op":"mcm","clk":"5323046278","pt":1646326902614,"mc":[{"id":"1.195532873","rc":[{"atl":[[3.4,41.67],[3.25,17.78],[4.4,0],[3.3,49],[4.2,11]],"id":38114646}],"con":true,"img":false}]}
{"op":"mcm","clk":"5323046284","pt":1646326902720,"mc":[{"id":"1.195532873","rc":[{"atl":[[3.4,0],[3.3,92.48]],"id":38114646}],"con":true,"img":false}]}
{"op":"mcm","clk":"5323046291","pt":1646326902824,"mc":[{"id":"1.195532873","rc":[{"atl":[[3.15,45.73],[3.3,49]],"id":38114646}],"con":true,"img":false}]}
{"op":"mcm","clk":"5323046370","pt":1646326903866,"mc":[{"id":"1.195532873","rc":[{"atb":[[3.2,113.64]],"id":36601249},{"atl":[[15,17.86]],"id":36601249}],"con":true,"img":false}]}
{"op":"mcm","clk":"5323046423","pt":1646326904855,"mc":[{"id":"1.195532873","rc":[{"atb":[[2.9,12.65]],"id":39727103}],"con":true,"img":false}]}
{"op":"mcm","clk":"5323046437","pt":1646326905063,"mc":[{"id":"1.195532873","rc":[{"atb":[[2.82,37.31],[2.78,2.04]],"id":39727103}],"con":true,"img":false}]}
{"op":"mcm","clk":"5323046447","pt":1646326905224,"mc":[{"id":"1.195532873","rc":[{"atb":[[2.78,2.04]],"id":37510843}],"con":true,"img":false}]}
{"op":"mcm","clk":"5323046453","pt":1646326905324,"mc":[{"id":"1.195532873","rc":[{"atl":[[24,0]],"id":36601249},{"atb":[[2.78,7.76],[2.68,15.68],[2.7,11.73]],"id":37510843}],"con":true,"img":false}]}
{"op":"mcm","clk":"5323046461","pt":1646326905432,"mc":[{"id":"1.195532873","rc":[{"atb":[[2.74,2.12]],"id":37510843}],"con":true,"img":false}]}
{"op":"mcm","clk":"5323046467","pt":1646326905533,"mc":[{"id":"1.195532873","rc":[{"atb":[[2.68,25.2]],"id":37510843}],"con":true,"img":false}]}
{"op":"mcm","clk":"5323046480","pt":1646326905744,"mc":[{"id":"1.195532873","rc":[{"atl":[[3.45,8.44]],"id":38114646}],"con":true,"img":false}]}
{"op":"mcm","clk":"5323046492","pt":1646326905955,"mc":[{"id":"1.195532873","rc":[{"atb":[[2.88,13.62]],"id":39727103},{"atl":[[3.45,0]],"id":38114646}],"con":true,"img":false}]}
{"op":"mcm","clk":"5323046498","pt":1646326906059,"mc":[{"id":"1.195532873","rc":[{"atb":[[2.92,3.79]],"id":39727103},{"atb":[[2.68,15.68]],"id":37510843}],"con":true,"img":false}]}
{"op":"mcm","clk":"5323046532","pt":1646326906635,"mc":[{"id":"1.195532873","rc":[{"atb":[[2.92,23.5]],"id":39727103},{"atb":[[2.68,0],[2.7,23.46]],"id":37510843}],"con":true,"img":false}]}
{"op":"mcm","clk":"5323046548","pt":1646326906844,"mc":[{"id":"1.195532873","rc":[{"atb":[[3.2,18.18],[3.4,0],[3.5,0],[3.3,0]],"id":36601249},{"atb":[[2.36,29.41],[2.88,0]],"id":39727103},{"atb":[[2.24,51.95],[2.06,0],[1.86,46.51],[1.77,0]],"id":39590546},{"atb":[[2.26,0],[2.36,29.41]],"id":37510843},{"atb":[[2,0],[1.98,0],[1.97,12.76],[1.9,44.44]],"id":37569661}],"con":true,"img":false}]}
{"op":"mcm","clk":"5323046564","pt":1646326907053,"mc":[{"id":"1.195532873","rc":[{"atb":[[1.97,0]],"id":37569661}],"con":true,"img":false}]}
{"op":"mcm","clk":"5323046585","pt":1646326907363,"mc":[{"id":"1.195532873","rc":[{"atb":[[2.9,11]],"id":39727103},{"atb":[[2.76,0]],"id":37510843}],"con":true,"img":false}]}
{"op":"mcm","clk":"5323046593","pt":1646326907419,"mc":[{"id":"1.195532873","rc":[{"atb":[[2.94,1.65]],"id":39727103},{"atb":[[2.8,1.65]],"id":37510843}],"con":true,"img":false}]}
{"op":"mcm","clk":"5323046600","pt":1646326907523,"mc":[{"id":"1.195532873","rc":[{"atb":[[2.94,3.42]],"id":39727103},{"atb":[[2.82,1.97]],"id":37510843}],"con":true,"img":false}]}
{"op":"mcm","clk":"5323046605","pt":1646326907629,"mc":[{"id":"1.195532873","rc":[{"atl":[[5.7,22.4]],"id":39727103},{"atb":[[1.96,0]],"id":37569661}],"con":true,"img":false}]}
{"op":"mcm","clk":"5323046634","pt":1646326908052,"mc":[{"id":"1.195532873","rc":[{"atb":[[2.92,21.51]],"id":39727103}],"con":true,"img":false}]}
{"op":"mcm","clk":"5323046637","pt":1646326908157,"mc":[{"id":"1.195532873","rc":[{"atb":[[2.96,1.99]],"id":39727103},{"atl":[[5.7,19.18]],"id":39727103}],"con":true,"img":false}]}
{"op":"mcm","clk":"5323046687","pt":1646326908939,"mc":[{"id":"1.195532873","rc":[{"atl":[[5.3,2.25]],"id":39727103},{"atl":[[3.1,3.91]],"id":38114646},{"atl":[[3.45,3.01]],"id":39590546},{"atb":[[2.82,0],[2.54,0],[2.58,0],[2.62,0],[2.74,0],[2.66,0],[2.78,5.72],[2.7,21.25]],"id":37510843},{"atl":[[5,2.56]],"id":37510843},{"atl":[[3.75,2.46]],"id":37569661}],"con":true,"img":false}]}
{"op":"mcm","clk":"5323046693","pt":1646326909044,"mc":[{"id":"1.195532873","rc":[{"atl":[[3.25,67.56],[3.3,0]],"id":38114646},{"atl":[[5.3,9.3]],"id":37510843},{"atl":[[3.85,0],[3.9,13.79],[3.75,22.13]],"id":37569661}],"con":true,"img":false}]}
{"op":"mcm","clk":"5323046699","pt":1646326909149,"mc":[{"id":"1.195532873","rc":[{"spn":8.15,"spf":"NaN","id":36601249},{"atl":[[5.6,48.1],[5.2,9.1],[5.7,0]],"id":39727103},{"spn":2.93,"spf":1.0,"id":39727103},{"atl":[[3.1,22.58],[3.15,22.86],[3.05,17.78]],"id":38114646},{"spn":2.59,"spf":"NaN","id":38114646},{"atl":[[3.45,16.85],[3.6,84.12],[3.4,15.38],[3.5,12.04],[3.75,14.55]],"id":39590546},{"spn":2.42,"spf":1.0,"id":39590546},{"atb":[[2.52,2.5]],"id":37510843},{"atl":[[5,5.12],[5.2,18.36],[4.9,5.76],[5.4,4.65]],"id":37510843},{"spn":3.85,"spf":"NaN","id":37510843},{"atl":[[3.85,22.64],[3.7,4.44]],"id":37569661},{"spn":3.01,"spf":"NaN","id":37569661}],"con":true,"img":false}]}
{"op":"mcm","clk":"5323046706","pt":1646326909262,"mc":[{"id":"1.195532873","rc":[{"atl":[[5.6,39.4],[5.5,8.89],[5.9,5.21]],"id":39727103},{"atl":[[3.2,18.18],[3.15,4.48]],"id":38114646},{"atl":[[3.6,68.74],[3.55,15.69],[3.75,21.31]],"id":39590546},{"atl":[[5.1,0],[5.3,0],[5.2,27.88]],"id":37510843},{"atl":[[3.85,36.68],[3.95,6.81],[3.9,0]],"id":37569661}],"con":true,"img":false}]}
{"op":"mcm","clk":"5323046714","pt":1646326909360,"mc":[{"id":"1.195532873","rc":[{"atl":[[5.9,0],[5.4,36.68],[5.1,2.44]],"id":39727103},{"atl":[[3,1.68]],"id":38114646},{"atl":[[3.35,3.23],[3.5,2.48],[3.75,14.55]],"id":39590546},{"atl":[[4.8,2.8],[5.5,3.39]],"id":37510843},{"atl":[[3.8,2.48],[3.65,2.63]],"id":37569661}],"con":true,"img":false}]}
{"op":"mcm","clk":"5323046720","pt":1646326909457,"mc":[{"id":"1.195532873","rc":[{"atl":[[3.7,4.69]],"id":39590546}],"con":true,"img":false}]}
{"op":"mcm","clk":"5323046729","pt":1646326909562,"mc":[{"id":"1.195532873","rc":[{"atl":[[5.1,4.88],[5.4,13.95]],"id":39727103},{"atl":[[5.5,0]],"id":37510843},{"atl":[[3.65,7.07],[3.75,2.45]],"id":37569661}],"con":true,"img":false}]}
{"op":"mcm","clk":"5323046737","pt":1646326909666,"mc":[{"id":"1.195532873","rc":[{"atl":[[5.1,2.44],[5.2,18.2]],"id":39727103},{"atl":[[2.94,12.84]],"id":38114646},{"atl":[[5.4,0]],"id":37510843},{"atl":[[3.95,0],[3.7,9.7],[3.65,2.62]],"id":37569661}],"con":true,"img":false}]}
{"op":"mcm","clk":"5323046749","pt":1646326909826,"mc":[{"id":"1.195532873","rc":[{"atl":[[2.92,16.76],[3.15,2]],"id":38114646},{"atl":[[3.5,0],[3.7,0]],"id":39590546},{"atl":[[3.8,0]],"id":37569661}],"con":true,"img":false}]}
{"op":"mcm","clk":"5323046766","pt":1646326910031,"mc":[{"id":"1.195532873","rc":[{"atl":[[3.1,3.9]],"id":38114646}],"con":true,"img":false}]}
{"op":"mcm","clk":"5323046778","pt":1646326910238,"mc":[{"id":"1.195532873","rc":[{"atl":[[5.3,11.55],[5.5,0]],"id":39727103},{"atl":[[2.96,20.41]],"id":38114646},{"atl":[[3.55,0],[3.45,33.18]],"id":39590546},{"atb":[[2.52,16.1],[2.7,11.73]],"id":37510843},{"atl":[[5,15.12],[5.2,18.36]],"id":37510843},{"atl":[[3.85,22.64],[3.75,17]],"id":37569661}],"con":true,"img":false}]}
{"op":"mcm","clk":"5323046836","pt":1646326911461,"mc":[{"id":"1.195532873","rc":[{"atl":[[2.9,2.48]],"id":38114646},{"atl":[[3.3,2.48]],"id":39590546},{"atl":[[3.6,2.48]],"id":37569661}],"con":true,"img":false}]}
{"op":"mcm","clk":"5323046848","pt":1646326911669,"mc":[{"id":"1.195532873","rc":[{"atb":[[2.7,29.41]],"id":39727103},{"atl":[[2.94,33.46],[2.9,17.44],[2.96,0]],"id":38114646},{"atl":[[3.45,16.85],[3.4,32.05]],"id":39590546},{"atl":[[3.7,24.51]],"id":37569661}],"con":true,"img":false}]}
{"op":"mcm","clk":"5323046856","pt":1646326911721,"mc":[{"id":"1.195532873","rc":[{"atb":[[2.6,0]],"id":39727103},{"atl":[[3.75,2.45]],"id":37569661}],"con":true,"img":false}]}
{"op":"mcm","clk":"5323046860","pt":1646326911824,"mc":[{"id":"1.195532873","rc":[{"atl":[[2.92,1.8]],"id":38114646},{"atb":[[2.04,0]],"id":37569661}],"con":true,"img":false}]}
{"op":"mcm","clk":"5323046868","pt":1646326911928,"mc":[{"id":"1.195532873","rc":[{"atb":[[1.9,53.33]],"id":37569661}],"con":true,"img":false}]}
{"op":"mcm","clk":"5323046919","pt":1646326912772,"mc":[{"id":"1.195532873","rc":[{"atl":[[3.25,17.78],[3.05,91.6]],"id":38114646}],"con":true,"img":false}]}
{"op":"mcm","clk":"5323046983","pt":1646326913560,"mc":[{"id":"1.195532873","rc":[{"atb":[[3.3,17.39]],"id":36601249},{"atb":[[1.9,8.89],[1.86,162.79]],"id":37569661}],"con":true,"img":false}]}
{"op":"mcm","clk":"5323047030","pt":1646326914227,"mc":[{"id":"1.195532873","rc":[{"atl":[[3.05,73.82],[2.9,34.89]],"id":38114646},{"atl":[[3.3,5.71],[3.4,16.67]],"id":39590546},{"atl":[[4.8,8.56],[5,12.56]],"id":37510843}],"con":true,"img":false}]}
{"op":"mcm","clk":"5323047038","pt":1646326914394,"mc":[{"id":"1.195532873","rc":[{"atl":[[3.9,6.4]],"id":37569661}],"con":true,"img":false}]}
{"op":"mcm","clk":"5323047050","pt":1646326914544,"mc":[{"id":"1.195532873","rc":[{"atl":[[3.9,0]],"id":37569661}],"con":true,"img":false}]}
{"op":"mcm","clk":"5323047066","pt":1646326914749,"mc":[{"id":"1.195532873","rc":[{"atl":[[3.6,5.11],[3.7,19.25]],"id":37569661}],"con":true,"img":false}]}
{"op":"mcm","clk":"5323047072","pt":1646326914856,"mc":[{"id":"1.195532873","rc":[{"atl":[[3.6,2.48],[3.65,7.61]],"id":37569661}],"con":true,"img":false}]}
{"op":"mcm","clk":"5323047113","pt":1646326915542,"mc":[{"id":"1.195532873","rc":[{"atl":[[2.94,20.62]],"id":38114646}],"con":true,"img":false}]}
{"op":"mcm","clk":"5323047124","pt":1646326915752,"mc":[{"id":"1.195532873","rc":[{"atb":[[2.82,1.97],[2.9,39.19]],"id":39727103}],"con":true,"img":false}]}
{"op":"mcm","clk":"5323047131","pt":1646326915856,"mc":[{"id":"1.195532873","rc":[{"atl":[[2.88,2.7]],"id":38114646}],"con":true,"img":false}]}
{"op":"mcm","clk":"5323047144","pt":1646326916063,"mc":[{"id":"1.195532873","rc":[{"atl":[[2.88,11.23],[2.96,4.79]],"id":38114646}],"con":true,"img":false}]}
{"op":"mcm","clk":"5323047152","pt":1646326916167,"mc":[{"id":"1.195532873","rc":[{"atl":[[2.9,19.93]],"id":38114646}],"con":true,"img":false}]}
{"op":"mcm","clk":"5323047168","pt":1646326916376,"mc":[{"id":"1.195532873","rc":[{"atb":[[2.94,1.77]],"id":39727103},{"atb":[[1.91,11.67]],"id":37569661}],"con":true,"img":false}]}
{"op":"mcm","clk":"5323047175","pt":1646326916480,"mc":[{"id":"1.195532873","rc":[{"atl":[[2.94,0],[2.92,22.63],[2.88,8.53],[2.96,0]],"id":38114646}],"con":true,"img":false}]}
{"op":"mcm","clk":"5323047183","pt":1646326916537,"mc":[{"id":"1.195532873","rc":[{"atb":[[2.98,1.65]],"id":39727103}],"con":true,"img":false}]}
{"op":"mcm","clk":"5323047191","pt":1646326916644,"mc":[{"id":"1.195532873","rc":[{"atl":[[2.9,17.45]],"id":38114646},{"atb":[[1.91,23.35],[1.86,46.51]],"id":37569661}],"con":true,"img":false}]}
{"op":"mcm","clk":"5323047215","pt":1646326916954,"mc":[{"id":"1.195532873","rc":[{"atb":[[2.54,3.66]],"id":37510843}],"con":true,"img":false}]}
{"op":"mcm","clk":"5323047231","pt":1646326917162,"mc":[{"id":"1.195532873","rc":[{"atb":[[2.54,19.92],[2.52,2.5]],"id":37510843}],"con":true,"img":false}]}
{"op":"mcm","clk":"5323047239","pt":1646326917367,"mc":[{"id":"1.195532873","rc":[{"atl":[[5.5,22.22]],"id":39727103},{"atb":[[2.32,75.76]],"id":37510843},{"atl":[[5.2,42.17]],"id":37510843}],"con":true,"img":false}]}
{"op":"mcm","clk":"5323047288","pt":1646326918047,"mc":[{"id":"1.195532873","rc":[{"atb":[[2.96,0]],"id":39727103}],"con":true,"img":false}]}
{"op":"mcm","clk":"5323047294","pt":1646326918151,"mc":[{"id":"1.195532873","rc":[{"atb":[[2.94,14.25]],"id":39727103}],"con":true,"img":false}]}
{"op":"mcm","clk":"5323047309","pt":1646326918360,"mc":[{"id":"1.195532873","rc":[{"atb":[[2.92,1.8]],"id":39727103}],"con":true,"img":false}]}
{"op":"mcm","clk":"5323047347","pt":1646326918777,"mc":[{"id":"1.195532873","rc":[{"atb":[[1.84,119.05]],"id":39590546},{"atl":[[3.5,40]],"id":39590546}],"con":true,"img":false}]}
{"op":"mcm","clk":"5323047410","pt":1646326919669,"mc":[{"id":"1.195532873","rc":[{"atl":[[5.3,66.47],[5.6,0],[5,10.49]],"id":39727103},{"atl":[[3.05,0],[2.92,74.59]],"id":38114646},{"atl":[[3.6,0],[3.3,12.42],[3.4,61.45]],"id":39590546},{"atl":[[5,53.14],[5.2,26.31],[4.7,10.74]],"id":37510843},{"atl":[[3.85,0],[3.7,41.77],[3.55,4.46]],"id":37569661}],"con":true,"img":false}]}
{"op":"mcm","clk":"5323047417","pt":1646326919771,"mc":[{"id":"1.195532873","rc":[{"atl":[[2.92,100.57]],"id":38114646},{"atl":[[3.7,37.33]],"id":37569661}],"con":true,"img":false}]}
{"op":"mcm","clk":"5323047424","pt":1646326919878,"mc":[{"id":"1.195532873","rc":[{"atl":[[5.2,9.1]],"id":39727103},{"atl":[[2.9,0]],"id":38114646},{"atl":[[3.45,3.01]],"id":39590546},{"atl":[[4.9,0]],"id":37510843}],"con":true,"img":false}]}
{"op":"mcm","clk":"5323047438","pt":1646326920035,"mc":[{"id":"1.195532873","rc":[{"atl":[[2.88,0]],"id":38114646}],"con":true,"img":false}]}
{"op":"mcm","clk":"5323047452","pt":1646326920247,"mc":[{"id":"1.195532873","rc":[{"atl":[[2.9,8.53]],"id":38114646}],"con":true,"img":false}]}
{"op":"mcm","clk":"5323047467","pt":1646326920567,"mc":[{"id":"1.195532873","rc":[{"atb":[[2.82,26.46],[2.9,11]],"id":39727103}],"con":true,"img":false}]}
{"op":"mcm","clk":"5323047472","pt":1646326920674,"mc":[{"id":"1.195532873","rc":[{"atb":[[3.2,63.63]],"id":36601249},{"atb":[[1.84,119.05]],"id":37569661},{"atl":[[3.7,22.52],[3.65,22.7]],"id":37569661}],"con":true,"img":false}]}
{"op":"mcm","clk":"5323047476","pt":1646326920779,"mc":[{"id":"1.195532873","rc":[{"atb":[[3.2,45.45]],"id":36601249}],"con":true,"img":false}]}
{"op":"mcm","clk":"5323047540","pt":1646326921473,"mc":[{"id":"1.195532873","rc":[{"atl":[[5.3,57.17],[5.5,0],[5.2,18.62]],"id":39727103},{"atb":[[1.73,0],[1.71,0],[1.75,0]],"id":39590546},{"atl":[[3.85,0],[3.75,0],[3.95,0]],"id":39590546},{"atb":[[2.22,0],[2.14,0],[2.18,0]],"id":37510843},{"atl":[[5.6,5],[16,0],[5,43.14],[5.2,2.5],[4.9,10.26],[15,0]],"id":37510843}],"con":true,"img":false}]}
{"op":"mcm","clk":"5323047553","pt":1646326921632,"mc":[{"id":"1.195532873","rc":[{"atl":[[2.94,20.62]],"id":38114646}],"con":true,"img":false}]}
{"op":"mcm","clk":"5323047558","pt":1646326921738,"mc":[{"id":"1.195532873","rc":[{"atl":[[5.4,11]],"id":39727103},{"atl":[[2.92,79.74]],"id":38114646},{"atl":[[3.6,0]],"id":37569661}],"con":true,"img":false}]}
{"op":"mcm","clk":"5323047565","pt":1646326921844,"mc":[{"id":"1.195532873","rc":[{"atb":[[2.92,7.56]],"id":39727103}],"con":true,"img":false}]}
{"op":"mcm","clk":"5323047571","pt":1646326921950,"mc":[{"id":"1.195532873","rc":[{"atl":[[3.55,0]],"id":37569661}],"con":true,"img":false}]}
{"op":"mcm","clk":"5323047577","pt":1646326922056,"mc":[{"id":"1.195532873","rc":[{"atb":[[2.92,1.8]],"id":39727103},{"atl":[[3.6,5.94]],"id":37569661}],"con":true,"img":false}]}
{"op":"mcm","clk":"5323047585","pt":1646326922161,"mc":[{"id":"1.195532873","rc":[{"atl":[[5.3,59.16]],"id":39727103}],"con":true,"img":false}]}
{"op":"mcm","clk":"5323047599","pt":1646326922370,"mc":[{"id":"1.195532873","rc":[{"atb":[[5.1,1.08]],"id":36601249},{"atl":[[7.6,1.08]],"id":36601249},{"atl":[[3.85,1.08]],"id":39727103},{"atb":[[2.1,1.08]],"id":38114646},{"atl":[[2.52,1.08]],"id":38114646},{"atl":[[2.86,1.08]],"id":39590546},{"atb":[[2.74,1.08]],"id":37510843},{"atl":[[3.6,1.08]],"id":37510843},{"atb":[[2.26,1.08]],"id":37569661},{"atl":[[2.9,1.08]],"id":37569661}],"con":true,"img":false}]}
{"op":"mcm","clk":"5323047605","pt":1646326922475,"mc":[{"id":"1.195532873","rc":[{"atb":[[1.91,58.93]],"id":37569661}],"con":true,"img":false}]}
{"op":"mcm","clk":"5323047610","pt":1646326922579,"mc":[{"id":"1.195532873","rc":[{"atb":[[4.9,4.5]],"id":36601249},{"atl":[[9,8.3],[10.5,4.49],[12.5,15.76]],"id":36601249},{"atl":[[3.95,10.49],[5.2,9.52]],"id":39727103},{"atl":[[3.1,12.43],[3.3,9.19]],"id":39590546},{"atl":[[4.8,2.8],[3.95,10.26]],"id":37510843},{"atb":[[1.9,0]],"id":37569661},{"atl":[[2.9,7.02],[3.65,17.72]],"id":37569661}],"con":true,"img":false}]}
{"op":"mcm","clk":"5323047617","pt":1646326922630,"mc":[{"id":"1.195532873","rc":[{"atl":[[12,11.12]],"id":36601249}],"con":true,"img":false}]}
{"op":"mcm","clk":"5323047620","pt":1646326922736,"mc":[{"id":"1.195532873","rc":[{"atl":[[8,5.71],[11,2.5],[12,22.06],[12.5,0]],"id":36601249},{"atl":[[4.3,12.12],[5.2,0]],"id":39727103},{"atl":[[3.15,18.6]],"id":39590546},{"atl":[[4.3,12.12]],"id":37510843},{"atb":[[1.91,47.26]],"id":37569661},{"atl":[[3.15,18.6],[3.65,2.63]],"id":37569661}],"con":true,"img":false}]}
{"op":"mcm","clk":"5323047643","pt":1646326923153,"mc":[{"id":"1.195532873","rc":[{"atb":[[4.9,0]],"id":36601249},{"atl":[[12,14.58]],"id":36601249}],"con":true,"img":false}]}
{"op":"mcm","clk":"5323047652","pt":1646326923260,"mc":[{"id":"1.195532873","rc":[{"atb":[[2.06,14.21]],"id":38114646}],"con":true,"img":false}]}
{"op":"mcm","clk":"5323047671","pt":1646326923678,"mc":[{"id":"1.195532873","rc":[{"atb":[[1.93,4.16]],"id":38114646}],"con":true,"img":false}]}
{"op":"mcm","clk":"5323047678","pt":1646326923782,"mc":[{"id":"1.195532873","rc":[{"atl":[[7,1.08]],"id":36601249},{"atb":[[3,1.08]],"id":39727103},{"atl":[[3.6,1.08]],"id":39727103},{"atb":[[2.06,0],[2.16,1.08]],"id":38114646},{"atl":[[2.58,1.08]],"id":38114646},{"atl":[[2.84,1.08]],"id":39590546},{"atb":[[2.82,1.08]],"id":37510843},{"atl":[[3.5,1.08]],"id":37510843},{"atl":[[2.68,1.08]],"id":37569661}],"con":true,"img":false}]}
{"op":"mcm","clk":"5323047696","pt":1646326923943,"mc":[{"id":"1.195532873","rc":[{"atb":[[2.94,12.26]],"id":39727103},{"atl":[[2.58,5.09]],"id":38114646},{"atb":[[2.8,3.71],[2.54,0],[2.7,31.71]],"id":37510843}],"con":true,"img":false}]}
{"op":"mcm","clk":"5323047703","pt":1646326924048,"mc":[{"id":"1.195532873","rc":[{"atb":[[3,3.07]],"id":39727103}],"con":true,"img":false}]}
{"op":"mcm","clk":"5323047706","pt":1646326924202,"mc":[{"id":"1.195532873","rc":[{"atb":[[1.93,0]],"id":38114646},{"atl":[[2.9,0]],"id":38114646},{"atb":[[2.78,0]],"id":37510843}],"con":true,"img":false}]}
{"op":"mcm","clk":"5323047725","pt":1646326924361,"mc":[{"id":"1.195532873","rc":[{"atb":[[2.98,0]],"id":39727103},{"atl":[[2.94,78.26],[2.92,27.78]],"id":38114646},{"atb":[[2.72,6.01]],"id":37510843}],"con":true,"img":false}]}
{"op":"mcm","clk":"5323047734","pt":1646326924469,"mc":[{"id":"1.195532873","rc":[{"atb":[[3.05,1.65]],"id":39727103},{"atl":[[2.52,0]],"id":38114646},{"atl":[[3.3,6.71]],"id":39590546}],"con":true,"img":false}]}
{"op":"mcm","clk":"5323047748","pt":1646326924677,"mc":[{"id":"1.195532873","rc":[{"atl":[[8,0],[7.4,6.25]],"id":36601249}],"con":true,"img":false}]}
{"op":"mcm","clk":"5323047760","pt":1646326924883,"mc":[{"id":"1.195532873","rc":[{"atl":[[2.92,1.8],[2.7,27.78]],"id":38114646},{"atb":[[2.72,0]],"id":37510843}],"con":true,"img":false}]}
{"op":"mcm","clk":"5323047830","pt":1646326926189,"mc":[{"id":"1.195532873","rc":[{"atb":[[2.82,1.97],[2.9,39.26]],"id":39727103}],"con":true,"img":false}]}
{"op":"mcm","clk":"5323047914","pt":1646326927184,"mc":[{"id":"1.195532873","rc":[{"atb":[[1.92,11.31]],"id":37569661}],"con":true,"img":false}]}
{"op":"mcm","clk":"5323047938","pt":1646326927556,"mc":[{"id":"1.195532873","rc":[{"atb":[[2.98,1.08]],"id":39727103},{"atl":[[3.65,1.08]],"id":39727103},{"atb":[[2.44,1.08]],"id":39590546},{"atl":[[2.88,1.08]],"id":39590546},{"atl":[[3.55,1.08]],"id":37510843},{"atb":[[2.34,1.08]],"id":37569661},{"atl":[[2.7,1.08]],"id":37569661}],"con":true,"img":false}]}
{"op":"mcm","clk":"5323047944","pt":1646326927660,"mc":[{"id":"1.195532873","rc":[{"atb":[[2.42,3.65]],"id":39590546},{"atl":[[2.76,7.03],[2.68,0]],"id":37569661}],"con":true,"img":false}]}
{"op":"mcm","clk":"5323047954","pt":1646326927767,"mc":[{"id":"1.195532873","rc":[{"atl":[[4,2.72]],"id":39727103},{"atb":[[2.4,3.31],[2.36,3.15],[2.38,23.83]],"id":39590546},{"atl":[[3.15,21.32]],"id":39590546},{"atl":[[4,2.72]],"id":37510843},{"atl":[[3.2,3.44],[2.9,1.08]],"id":37569661}],"con":true,"img":false}]}
{"op":"mcm","clk":"5323047960","pt":1646326927870,"mc":[{"id":"1.195532873","rc":[{"atl":[[5.7,2.72]],"id":39727103}],"con":true,"img":false}]}
{"op":"mcm","clk":"5323047968","pt":1646326927979,"mc":[{"id":"1.195532873","rc":[{"atl":[[4,0]],"id":39727103},{"atb":[[2.36,5.87]],"id":39590546},{"atl":[[3.15,18.6]],"id":39590546},{"atl":[[4,0]],"id":37510843},{"atb":[[2.3,0]],"id":37569661},{"atl":[[3.2,0]],"id":37569661}],"con":true,"img":false}]}
{"op":"mcm","clk":"5323047977","pt":1646326928081,"mc":[{"id":"1.195532873","rc":[{"atb":[[2.22,2.72]],"id":39590546},{"atb":[[2.34,3.07]],"id":37569661}],"con":true,"img":false}]}
{"op":"mcm","clk":"5323047984","pt":1646326928184,"mc":[{"id":"1.195532873","rc":[{"atl":[[5.7,0]],"id":39727103}],"con":true,"img":false}]}
{"op":"mcm","clk":"5323047999","pt":1646326928393,"mc":[{"id":"1.195532873","rc":[{"atb":[[2.22,0]],"id":39590546}],"con":true,"img":false}]}
{"op":"mcm","clk":"5323048008","pt":1646326928500,"mc":[{"id":"1.195532873","rc":[{"atb":[[2.34,1.08]],"id":37569661}],"con":true,"img":false}]}
{"op":"mcm","clk":"5323048017","pt":1646326928557,"mc":[{"id":"1.195532873","rc":[{"atb":[[2.36,3.15]],"id":39590546},{"atb":[[2.3,1.99]],"id":37569661}],"con":true,"img":false}]}
{"op":"mcm","clk":"5323048032","pt":1646326928662,"mc":[{"id":"1.195532873","rc":[{"atl":[[3.7,1.08]],"id":39727103},{"atl":[[2.94,57.64],[2.92,22.63]],"id":38114646},{"atb":[[2.46,1.08]],"id":39590546},{"atb":[[2.52,22.7],[2.7,11.73]],"id":37510843},{"atb":[[1.99,3.08]],"id":37569661},{"atl":[[2.64,1.08]],"id":37569661}],"con":true,"img":false}]}
{"op":"mcm","clk":"5323048049","pt":1646326928874,"mc":[{"id":"1.195532873","rc":[{"atb":[[1.99,0]],"id":37569661}],"con":true,"img":false}]}
{"op":"mcm","clk":"5323048076","pt":1646326929210,"mc":[{"id":"1.195532873","rc":[{"atb":[[2.14,4.13]],"id":38114646},{"atb":[[2.3,0]],"id":37569661}],"con":true,"img":false}]}
{"op":"mcm","clk":"5323048091","pt":1646326929301,"mc":[{"id":"1.195532873","rc":[{"atb":[[2.34,3.07]],"id":37569661}],"con":true,"img":false}]}
{"op":"mcm","clk":"5323048128","pt":1646326929653,"mc":[{"id":"1.195532873","rc":[{"atl":[[4.5,28.57]],"id":39727103},{"atb":[[1.82,182.93]],"id":39590546},{"atl":[[3.25,44.44]],"id":39590546},{"atb":[[2.28,117.19]],"id":37510843},{"atl":[[4.5,28.57]],"id":37510843},{"atb":[[1.82,182.93]],"id":37569661},{"atl":[[2.64,0],[3.25,44.44]],"id":37569661}],"con":true,"img":false}]}
{"op":"mcm","clk":"5323048149","pt":1646326929969,"mc":[{"id":"1.195532873","rc":[{"atl":[[5.3,4.24],[3.95,40.95]],"id":39727103},{"atl":[[2.94,0],[2.92,78.33]],"id":38114646},{"atl":[[3.4,16.67],[3.15,32.54]],"id":39590546},{"atl":[[4.3,59.06]],"id":37510843},{"atl":[[3.25,85.5],[3.7,0],[2.66,3.56]],"id":37569661}],"con":true,"img":false}]}
{"op":"mcm","clk":"5323048157","pt":1646326930068,"mc":[{"id":"1.195532873","rc":[{"atl":[[3.55,3.08],[5,2.56]],"id":37510843}],"con":true,"img":false}]}
{"op":"mcm","clk":"5323048163","pt":1646326930174,"mc":[{"id":"1.195532873","rc":[{"atl":[[5.3,2.72]],"id":37510843},{"atl":[[3.6,0],[2.66,0]],"id":37569661}],"con":true,"img":false}]}
{"op":"mcm","clk":"5323048204","pt":1646326930279,"mc":[{"id":"1.195532873","rc":[{"atl":[[4.7,0]],"id":37510843}],"con":true,"img":false}]}
{"op":"mcm","clk":"5323048211","pt":1646326930384,"mc":[{"id":"1.195532873","rc":[{"atl":[[6.4,5],[5.8,2.5],[6,0]],"id":39727103},{"atl":[[2.72,4.9],[4.4,0],[4,0],[4.2,0]],"id":37569661}],"con":true,"img":false}]}
{"op":"mcm","clk":"5323048217","pt":1646326930485,"mc":[{"id":"1.195532873","rc":[{"atl":[[3.75,1.08]],"id":39727103},{"atl":[[2.66,1.08]],"id":37569661}],"con":true,"img":false}]}
{"op":"mcm","clk":"5323048229","pt":1646326930692,"mc":[{"id":"1.195532873","rc":[{"atl":[[5.3,0]],"id":37510843}],"con":true,"img":false}]}
{"op":"mcm","clk":"5323048246","pt":1646326930954,"mc":[{"id":"1.195532873","rc":[{"atb":[[2.34,1.08]],"id":37569661}],"con":true,"img":false}]}
{"op":"mcm","clk":"5323048248","pt":1646326931060,"mc":[{"id":"1.195532873","rc":[{"atb":[[2.3,1.99]],"id":37569661}],"con":true,"img":false}]}
{"op":"mcm","clk":"5323048273","pt":1646326931397,"mc":[{"id":"1.195532873","rc":[{"atb":[[2.4,0]],"id":39590546}],"con":true,"img":false}]}
{"op":"mcm","clk":"5323048279","pt":1646326931452,"mc":[{"id":"1.195532873","rc":[{"atl":[[3.55,2]],"id":37510843}],"con":true,"img":false}]}
{"op":"mcm","clk":"5323048285","pt":1646326931555,"mc":[{"id":"1.195532873","rc":[{"atb":[[3.1,71.43]],"id":36601249},{"atl":[[7.8,14.71]],"id":36601249}],"con":true,"img":false}]}
{"op":"mcm","clk":"5323048305","pt":1646326931865,"mc":[{"id":"1.195532873","rc":[{"atb":[[2.3,0]],"id":37569661}],"con":true,"img":false}]}
{"op":"mcm","clk":"5323048311","pt":1646326931969,"mc":[{"id":"1.195532873","rc":[{"atl":[[13,5],[14,0],[15,0]],"id":36601249},{"atb":[[2.34,3.07]],"id":37569661}],"con":true,"img":false}]}
{"op":"mcm","clk":"5323048314","pt":1646326932073,"mc":[{"id":"1.195532873","rc":[{"atb":[[4.4,5],[3.95,0]],"id":36601249},{"atb":[[1.94,0],[1.99,9]],"id":38114646},{"atb":[[2.32,0],[2.36,0],[2.42,1.65],[2.38,20.75]],"id":39590546},{"atb":[[2.8,7.43],[2.7,0]],"id":37510843},{"atb":[[1.99,46.51],[1.91,35.58]],"id":37569661}],"con":true,"img":false}]}
{"op":"mcm","clk":"5323048318","pt":1646326932177,"mc":[{"id":"1.195532873","rc":[{"atb":[[4,4.29]],"id":36601249}],"con":true,"img":false}]}
{"op":"mcm","clk":"5323048359","pt":1646326932386,"mc":[{"id":"1.195532873","rc":[{"atb":[[4,0]],"id":36601249},{"atb":[[3.1,1.08]],"id":39727103},{"atl":[[2.9,1.08]],"id":39590546},{"atb":[[2.32,0]],"id":37569661},{"atl":[[2.68,4.64]],"id":37569661}],"con":true,"img":false}]}
{"op":"mcm","clk":"5323048363","pt":1646326932487,"mc":[{"id":"1.195532873","rc":[{"atb":[[2.38,0],[2.28,24.68]],"id":39590546}],"con":true,"img":false}]}
{"op":"mcm","clk":"5323048368","pt":1646326932591,"mc":[{"id":"1.195532873","rc":[{"atb":[[2.94,19.55],[2.9,11]],"id":39727103},{"atl":[[2.72,0]],"id":37569661}],"con":true,"img":false}]}
{"op":"mcm","clk":"5323048378","pt":1646326932800,"mc":[{"id":"1.195532873","rc":[{"atl":[[3.6,0]],"id":39727103},{"atb":[[1.99,63.84],[1.91,0],[2.34,1.99]],"id":37569661}],"con":true,"img":false}]}
{"op":"mcm","clk":"5323048386","pt":1646326932853,"mc":[{"id":"1.195532873","rc":[{"atl":[[3.7,4.65]],"id":37569661}],"con":true,"img":false}]}
{"op":"mcm","clk":"5323048398","pt":1646326933064,"mc":[{"id":"1.195532873","rc":[{"atl":[[9,31.46],[12,0]],"id":36601249},{"atl":[[3.6,2.71]],"id":39727103},{"atl":[[2.56,2.52]],"id":38114646},{"atl":[[2.82,1.97]],"id":39590546}],"con":true,"img":false}]}
{"op":"mcm","clk":"5323048403","pt":1646326933167,"mc":[{"id":"1.195532873","rc":[{"atl":[[2.56,8.81]],"id":38114646},{"atl":[[3.7,0]],"id":37569661}],"con":true,"img":false}]}
{"op":"mcm","clk":"5323048409","pt":1646326933270,"mc":[{"id":"1.195532873","rc":[{"atl":[[2.58,1.08],[2.96,5.84]],"id":38114646}],"con":true,"img":false}]}
{"op":"mcm","clk":"5323048416","pt":1646326933375,"mc":[{"id":"1.195532873","rc":[{"atb":[[2.52,2.5],[2.46,27.66]],"id":37510843}],"con":true,"img":false}]}
{"op":"mcm","clk":"5323048427","pt":1646326933587,"mc":[{"id":"1.195532873","rc":[{"atb":[[3,1.08]],"id":39727103}],"con":true,"img":false}]}
{"op":"mcm","clk":"5323048434","pt":1646326933691,"mc":[{"id":"1.195532873","rc":[{"atb":[[3.1,3.07]],"id":39727103},{"atl":[[2.96,0]],"id":38114646}],"con":true,"img":false}]}
{"op":"mcm","clk":"5323048440","pt":1646326933793,"mc":[{"id":"1.195532873","rc":[{"atl":[[7.2,1.08]],"id":36601249},{"atl":[[3.8,1.08]],"id":39727103},{"atb":[[2.72,5.76]],"id":37510843},{"atb":[[1.92,0],[2.32,1.08]],"id":37569661}],"con":true,"img":false}]}
{"op":"mcm","clk":"5323048453","pt":1646326934005,"mc":[{"id":"1.195532873","rc":[{"atl":[[9,8.3]],"id":36601249},{"atb":[[2.34,0]],"id":37569661}],"con":true,"img":false}]}
{"op":"mcm","clk":"5323048462","pt":1646326934106,"mc":[{"id":"1.195532873","rc":[{"atb":[[2.3,1.99]],"id":37569661}],"con":true,"img":false}]}
{"op":"mcm","clk":"5323048476","pt":1646326934214,"mc":[{"id":"1.195532873","rc":[{"atb":[[2.52,21.73],[2.46,2.81]],"id":37510843}],"con":true,"img":false}]}
{"op":"mcm","clk":"5323048529","pt":1646326934894,"mc":[{"id":"1.195532873","rc":[{"atb":[[5.4,1.08]],"id":36601249},{"atb":[[2.18,1.08]],"id":38114646},{"atl":[[2.48,1.08]],"id":38114646},{"atb":[[2.88,1.08]],"id":37510843},{"atb":[[2.32,0]],"id":37569661}],"con":true,"img":false}]}
{"op":"mcm","clk":"5323048537","pt":1646326935006,"mc":[{"id":"1.195532873","rc":[{"atb":[[2.82,3.08]],"id":37510843}],"con":true,"img":false}]}
{"op":"mcm","clk":"5323048542","pt":1646326935101,"mc":[{"id":"1.195532873","rc":[{"atb":[[2.08,4.5]],"id":38114646},{"atl":[[2.72,2.72],[2.46,2.81]],"id":38114646}],"con":true,"img":false}]}
{"op":"mcm","clk":"5323048553","pt":1646326935205,"mc":[{"id":"1.195532873","rc":[{"atb":[[2.8,5.37]],"id":37510843}],"con":true,"img":false}]}
{"op":"mcm","clk":"5323048558","pt":1646326935333,"mc":[{"id":"1.195532873","rc":[{"atl":[[2.72,0],[2.92,22.63],[2.7,44.56]],"id":38114646}],"con":true,"img":false}]}
{"op":"mcm","clk":"5323048577","pt":1646326935494,"mc":[{"id":"1.195532873","rc":[{"atb":[[3.1,1.08]],"id":39727103},{"atl":[[2.96,51.02]],"id":38114646}],"con":true,"img":false}]}
{"op":"mcm","clk":"5323048585","pt":1646326935600,"mc":[{"id":"1.195532873","rc":[{"atb":[[3.05,3.64]],"id":39727103}],"con":true,"img":false}]}
{"op":"mcm","clk":"5323048623","pt":1646326936177,"mc":[{"id":"1.195532873","rc":[{"atb":[[2.24,1.08]],"id":37569661}],"con":true,"img":false}]}
{"op":"mcm","clk":"5323048633","pt":1646326936385,"mc":[{"id":"1.195532873","rc":[{"atb":[[2.26,0]],"id":37569661}],"con":true,"img":false}]}
{"op":"mcm","clk":"5323048649","pt":1646326936593,"mc":[{"id":"1.195532873","rc":[{"atl":[[4.7,40.54]],"id":39727103},{"atb":[[1.8,250]],"id":39590546},{"atl":[[3.35,67.06]],"id":39590546},{"atb":[[2.24,201.61]],"id":37510843},{"atl":[[4.7,40.54]],"id":37510843},{"atb":[[1.8,250]],"id":37569661},{"atl":[[3.35,63.83]],"id":37569661}],"con":true,"img":false}]}
{"op":"mcm","clk":"5323048686","pt":1646326937063,"mc":[{"id":"1.195532873","rc":[{"atb":[[2.24,72.67]],"id":39590546}],"con":true,"img":false}]}
{"op":"mcm","clk":"5323048691","pt":1646326937187,"mc":[{"id":"1.195532873","rc":[{"atb":[[2.28,3.46]],"id":39590546}],"con":true,"img":false}]}
{"op":"mcm","clk":"5323048710","pt":1646326937385,"mc":[{"id":"1.195532873","rc":[{"atb":[[1.99,46.51],[1.86,81.27]],"id":37569661}],"con":true,"img":false}]}
{"op":"mcm","clk":"5323048718","pt":1646326937490,"mc":[{"id":"1.195532873","rc":[{"atb":[[2.24,2.17]],"id":37569661}],"con":true,"img":false}]}
{"op":"mcm","clk":"5323048743","pt":1646326937806,"mc":[{"id":"1.195532873","rc":[{"atl":[[9,0],[8.6,4.49]],"id":36601249},{"atb":[[2.8,11],[2.7,0]],"id":39727103},{"atl":[[3.25,0],[3.65,0]],"id":38114646},{"atl":[[3.5,0],[3.4,0]],"id":39590546}],"con":true,"img":false}]}
{"op":"mcm","clk":"5323048790","pt":1646326938381,"mc":[{"id":"1.195532873","rc":[{"atb":[[3,125]],"id":36601249},{"atl":[[8.2,20.83]],"id":36601249}],"con":true,"img":false}]}
{"op":"mcm","clk":"5323048817","pt":1646326938804,"mc":[{"id":"1.195532873","rc":[{"atb":[[2.72,21.05],[2.52,2.5]],"id":37510843}],"con":true,"img":false}]}
{"op":"mcm","clk":"5323048901","pt":1646326940015,"mc":[{"id":"1.195532873","rc":[{"atb":[[2.72,15.29]],"id":37510843},{"atb":[[1.87,19.06]],"id":37569661}],"con":true,"img":false}]}
{"op":"mcm","clk":"5323048910","pt":1646326940121,"mc":[{"id":"1.195532873","rc":[{"atl":[[3.8,10.86],[3.95,10.49]],"id":39727103},{"atl":[[3.1,28.79],[3.45,5.73],[3.15,18.6]],"id":39590546},{"atl":[[3.15,46.32],[3.25,44.44]],"id":37569661}],"con":true,"img":false}]}
{"op":"mcm","clk":"5323048923","pt":1646326940337,"mc":[{"id":"1.195532873","rc":[{"atl":[[3.45,3.01]],"id":39590546}],"con":true,"img":false}]}
{"op":"mcm","clk":"5323048928","pt":1646326940434,"mc":[{"id":"1.195532873","rc":[{"atb":[[3.05,1.99]],"id":39727103},{"atb":[[2.42,0]],"id":39590546},{"atb":[[2.8,3.72]],"id":37510843}],"con":true,"img":false}]}
{"op":"mcm","clk":"5323048939","pt":1646326940590,"mc":[{"id":"1.195532873","rc":[{"atb":[[2.3,1.65]],"id":39590546},{"atb":[[2.84,1.65]],"id":37510843}],"con":true,"img":false}]}
{"op":"mcm","clk":"5323049029","pt":1646326941939,"mc":[{"id":"1.195532873","rc":[{"atb":[[3.05,0]],"id":39727103},{"atb":[[2.42,1.08]],"id":39590546}],"con":true,"img":false}]}
{"op":"mcm","clk":"5323049037","pt":1646326942036,"mc":[{"id":"1.195532873","rc":[{"atb":[[3,3.07]],"id":39727103}],"con":true,"img":false}]}
{"op":"mcm","clk":"5323049044","pt":1646326942095,"mc":[{"id":"1.195532873","rc":[{"atb":[[2.94,12.26],[2.9,29.34]],"id":39727103},{"atb":[[2.24,51.95],[2.28,10.72]],"id":39590546}],"con":true,"img":false}]}
{"op":"mcm","clk":"5323049059","pt":1646326942350,"mc":[{"id":"1.195532873","rc":[{"atl":[[3,76.68]],"id":38114646},{"atb":[[2.44,0],[2.46,0]],"id":39590546}],"con":true,"img":false}]}
{"op":"mcm","clk":"5323049075","pt":1646326942517,"mc":[{"id":"1.195532873","rc":[{"atb":[[2.3,3.71]],"id":39590546}],"con":true,"img":false}]}
{"op":"mcm","clk":"5323049101","pt":1646326942925,"mc":[{"id":"1.195532873","rc":[{"atb":[[1.99,63.84],[1.86,46.51]],"id":37569661}],"con":true,"img":false}]}
{"op":"mcm","clk":"5323049122","pt":1646326943239,"mc":[{"id":"1.195532873","rc":[{"atb":[[3.05,1.08]],"id":39727103},{"atb":[[2.38,1.08]],"id":39590546}],"con":true,"img":false}]}
{"op":"mcm","clk":"5323049126","pt":1646326943340,"mc":[{"id":"1.195532873","rc":[{"atl":[[9,3.14]],"id":36601249},{"atl":[[4.9,64.1]],"id":39727103},{"atl":[[3.45,105.05]],"id":39590546},{"atl":[[4.9,64.1]],"id":37510843},{"atl":[[3.45,102.04]],"id":37569661}],"con":true,"img":false}]}
{"op":"mcm","clk":"5323049132","pt":1646326943441,"mc":[{"id":"1.195532873","rc":[{"atb":[[3,1.99],[2.94,19.5],[2.9,11]],"id":39727103}],"con":true,"img":false}]}
{"op":"mcm","clk":"5323049138","pt":1646326943531,"mc":[{"id":"1.195532873","rc":[{"atb":[[2.8,12.23],[2.72,0]],"id":37510843}],"con":true,"img":false}]}
{"op":"mcm","clk":"5323049155","pt":1646326943706,"mc":[{"id":"1.195532873","rc":[{"atl":[[9,0]],"id":36601249}],"con":true,"img":false}]}
{"op":"mcm","clk":"5323049205","pt":1646326944335,"mc":[{"id":"1.195532873","rc":[{"atb":[[2.4,1.08]],"id":39590546}],"con":true,"img":false}]}
{"op":"mcm","clk":"5323049253","pt":1646326945011,"mc":[{"id":"1.195532873","rc":[{"atb":[[2.86,2.06]],"id":37510843}],"con":true,"img":false}]}
{"op":"mcm","clk":"5323049263","pt":1646326945114,"mc":[{"id":"1.195532873","rc":[{"atl":[[8.6,37.38]],"id":36601249},{"atb":[[3,0]],"id":39727103}],"con":true,"img":false}]}
{"op":"mcm","clk":"5323049270","pt":1646326945221,"mc":[{"id":"1.195532873","rc":[{"atb":[[3.1,3.07]],"id":39727103},{"atb":[[2.82,1.08],[2.78,3.44]],"id":37510843}],"con":true,"img":false}]}
{"op":"mcm","clk":"5323049278","pt":1646326945314,"mc":[{"id":"1.195532873","rc":[{"atb":[[2.78,0]],"id":37510843}],"con":true,"img":false}]}
{"op":"mcm","clk":"5323049290","pt":1646326945629,"mc":[{"id":"1.195532873","rc":[{"atb":[[3.1,1.08]],"id":39727103}],"con":true,"img":false}]}
{"op":"mcm","clk":"5323049298","pt":1646326945740,"mc":[{"id":"1.195532873","rc":[{"atb":[[3,1.99]],"id":39727103}],"con":true,"img":false}]}
{"op":"mcm","clk":"5323049302","pt":1646326945837,"mc":[{"id":"1.195532873","rc":[{"atb":[[2.36,1.08]],"id":39590546},{"atb":[[2.96,1.08]],"id":37510843}],"con":true,"img":false}]}
{"op":"mcm","clk":"5323049310","pt":1646326946046,"mc":[{"id":"1.195532873","rc":[{"atb":[[2.3,10.26],[2.28,3.46]],"id":39590546},{"atb":[[2.82,8.38],[2.8,3.72]],"id":37510843}],"con":true,"img":false}]}
{"op":"mcm","clk":"5323049323","pt":1646326946246,"mc":[{"id":"1.195532873","rc":[{"atb":[[3,0]],"id":39727103}],"con":true,"img":false}]}
{"op":"mcm","clk":"5323049329","pt":1646326946351,"mc":[{"id":"1.195532873","rc":[{"atb":[[3.1,3.07]],"id":39727103}],"con":true,"img":false}]}
{"op":"mcm","clk":"5323049359","pt":1646326946770,"mc":[{"id":"1.195532873","rc":[{"atl":[[2.64,2.33]],"id":37569661}],"con":true,"img":false}]}
{"op":"mcm","clk":"5323049367","pt":1646326946830,"mc":[{"id":"1.195532873","rc":[{"atb":[[2.14,0]],"id":38114646},{"atb":[[2.36,2.17]],"id":39590546},{"atb":[[2.98,1.08]],"id":37510843},{"atl":[[3.55,0]],"id":37510843},{"atb":[[2.28,0]],"id":37569661}],"con":true,"img":false}]}
{"op":"mcm","clk":"5323049376","pt":1646326946933,"mc":[{"id":"1.195532873","rc":[{"atb":[[3.1,1.08]],"id":39727103},{"atb":[[2.08,16.81]],"id":38114646},{"atl":[[2.64,3.38]],"id":37569661}],"con":true,"img":false}]}
{"op":"mcm","clk":"5323049383","pt":1646326947041,"mc":[{"id":"1.195532873","rc":[{"atb":[[3,1.99]],"id":39727103}],"con":true,"img":false}]}
{"op":"mcm","clk":"5323049393","pt":1646326947143,"mc":[{"id":"1.195532873","rc":[{"atb":[[2.9,29.34]],"id":39727103},{"atl":[[2.68,1.08]],"id":37569661}],"con":true,"img":false}]}
{"op":"mcm","clk":"5323049398","pt":1646326947246,"mc":[{"id":"1.195532873","rc":[{"atb":[[2.94,12.26],[2.9,11]],"id":39727103}],"con":true,"img":false}]}
{"op":"mcm","clk":"5323049409","pt":1646326947348,"mc":[{"id":"1.195532873","rc":[{"atb":[[2.04,8.2]],"id":38114646}],"con":true,"img":false}]}
{"op":"mcm","clk":"5323049418","pt":1646326947446,"mc":[{"id":"1.195532873","rc":[{"atb":[[1.87,34.41]],"id":37569661}],"con":true,"img":false}]}
{"op":"mcm","clk":"5323049427","pt":1646326947551,"mc":[{"id":"1.195532873","rc":[{"atb":[[1.99,46.51]],"id":37569661}],"con":true,"img":false}]}
{"op":"mcm","clk":"5323049436","pt":1646326947617,"mc":[{"id":"1.195532873","rc":[{"atb":[[2.54,2.72]],"id":37510843}],"con":true,"img":false}]}
{"op":"mcm","clk":"5323049453","pt":1646326947817,"mc":[{"id":"1.195532873","rc":[{"atb":[[3.1,0]],"id":39727103},{"atb":[[2.04,4.76]],"id":38114646},{"atb":[[2.54,0]],"id":37510843}],"con":true,"img":false}]}
{"op":"mcm","clk":"5323049491","pt":1646326948344,"mc":[{"id":"1.195532873","rc":[{"atb":[[2.3,8.61]],"id":39590546},{"atb":[[2.84,0]],"id":37510843}],"con":true,"img":false}]}
{"op":"mcm","clk":"5323049498","pt":1646326948437,"mc":[{"id":"1.195532873","rc":[{"atb":[[3,0]],"id":39727103},{"atb":[[2.38,2.74]],"id":39590546},{"atb":[[2.88,2.74]],"id":37510843}],"con":true,"img":false}]}
{"op":"mcm","clk":"5323049505","pt":1646326948543,"mc":[{"id":"1.195532873","rc":[{"atb":[[2.96,1.99]],"id":39727103}],"con":true,"img":false}]}
{"op":"mcm","clk":"5323049515","pt":1646326948649,"mc":[{"id":"1.195532873","rc":[{"atb":[[2.3,2.06],[2.36,8.32]],"id":39590546}],"con":true,"img":false}]}
{"op":"mcm","clk":"5323049523","pt":1646326948750,"mc":[{"id":"1.195532873","rc":[{"atb":[[2.82,1.08],[2.86,8.21]],"id":37510843},{"atb":[[2.3,0]],"id":37569661}],"con":true,"img":false}]}
{"op":"mcm","clk":"5323049532","pt":1646326948864,"mc":[{"id":"1.195532873","rc":[{"atb":[[2.26,1.99]],"id":37569661}],"con":true,"img":false}]}
{"op":"mcm","clk":"5323049539","pt":1646326948915,"mc":[{"id":"1.195532873","rc":[{"atl":[[3.1,122.96]],"id":38114646}],"con":true,"img":false}]}
{"op":"mcm","clk":"5323049560","pt":1646326949323,"mc":[{"id":"1.195532873","rc":[{"atb":[[2.96,0]],"id":39727103},{"atb":[[1.87,15.35]],"id":37569661}],"con":true,"img":false}]}
{"op":"mcm","clk":"5323049567","pt":1646326949428,"mc":[{"id":"1.195532873","rc":[{"atb":[[3,1.99]],"id":39727103}],"con":true,"img":false}]}
{"op":"mcm","clk":"5323049611","pt":1646326950051,"mc":[{"id":"1.195532873","rc":[{"atl":[[2.76,31.59],[3.15,18.6]],"id":37569661}],"con":true,"img":false}]}
{"op":"mcm","clk":"5323049619","pt":1646326950149,"mc":[{"id":"1.195532873","rc":[{"atb":[[2.38,1.65]],"id":39590546},{"atl":[[3.6,0],[3.5,0]],"id":37510843},{"atb":[[2.24,0]],"id":37569661},{"atl":[[2.68,4.2]],"id":37569661}],"con":true,"img":false}]}
{"op":"mcm","clk":"5323049624","pt":1646326950256,"mc":[{"id":"1.195532873","rc":[{"atb":[[2.94,14.98]],"id":39727103},{"atl":[[3.2,5.2]],"id":37569661}],"con":true,"img":false}]}
{"op":"mcm","clk":"5323049631","pt":1646326950362,"mc":[{"id":"1.195532873","rc":[{"atl":[[3.2,0]],"id":38114646},{"atl":[[4.3,12.12],[4.5,94.08],[3.95,9.75]],"id":37510843},{"atb":[[1.99,52.2]],"id":37569661},{"atl":[[3.2,0],[2.68,1.08]],"id":37569661}],"con":true,"img":false}]}
{"op":"mcm","clk":"5323049643","pt":1646326950525,"mc":[{"id":"1.195532873","rc":[{"atb":[[2.3,8.61],[2.36,2.17]],"id":39590546},{"atl":[[4.8,9.56],[3.95,0]],"id":37510843}],"con":true,"img":false}]}
{"op":"mcm","clk":"5323049647","pt":1646326950638,"mc":[{"id":"1.195532873","rc":[{"atb":[[3,0]],"id":39727103},{"atl":[[4.2,3.82],[4.7,67.57]],"id":37510843}],"con":true,"img":false}]}
{"op":"mcm","clk":"5323049652","pt":1646326950739,"mc":[{"id":"1.195532873","rc":[{"atb":[[2.94,12.26],[2.96,1.99]],"id":39727103},{"atl":[[4.3,21.49],[4,4.63],[4.5,65.51]],"id":37510843}],"con":true,"img":false}]}
{"op":"mcm","clk":"5323049659","pt":1646326950847,"mc":[{"id":"1.195532873","rc":[{"atl":[[4.8,2.8]],"id":37510843}],"con":true,"img":false}]}
{"op":"mcm","clk":"5323049667","pt":1646326950943,"mc":[{"id":"1.195532873","rc":[{"atl":[[4,2.11]],"id":37510843}],"con":true,"img":false}]}
{"op":"mcm","clk":"5323049672","pt":1646326951049,"mc":[{"id":"1.195532873","rc":[{"atb":[[2.26,0]],"id":37569661}],"con":true,"img":false}]}
{"op":"mcm","clk":"5323049677","pt":1646326951154,"mc":[{"id":"1.195532873","rc":[{"atl":[[2.94,4.88]],"id":38114646},{"atl":[[4.8,0],[4,0],[5,0],[4.2,0]],"id":37510843},{"atb":[[2,1.99]],"id":37569661}],"con":true,"img":false}]}
{"op":"mcm","clk":"5323049683","pt":1646326951257,"mc":[{"id":"1.195532873","rc":[{"atb":[[1.99,5.69],[1.86,162.79]],"id":37569661}],"con":true,"img":false}]}
{"op":"mcm","clk":"5323049693","pt":1646326951361,"mc":[{"id":"1.195532873","rc":[{"atl":[[2.94,0]],"id":38114646},{"atb":[[1.97,54.19]],"id":37569661}],"con":true,"img":false}]}
{"op":"mcm","clk":"5323049700","pt":1646326951432,"mc":[{"id":"1.195532873","rc":[{"atb":[[1.86,46.51]],"id":37569661}],"con":true,"img":false}]}
{"op":"mcm","clk":"5323049707","pt":1646326951537,"mc":[{"id":"1.195532873","rc":[{"atl":[[4.2,3.82]],"id":37510843}],"con":true,"img":false}]}
{"op":"mcm","clk":"5323049715","pt":1646326951642,"mc":[{"id":"1.195532873","rc":[{"atb":[[2.96,0]],"id":39727103},{"atb":[[1.81,6.71]],"id":37569661}],"con":true,"img":false}]}
{"op":"mcm","clk":"5323049722","pt":1646326951739,"mc":[{"id":"1.195532873","rc":[{"atb":[[3,3.07]],"id":39727103},{"atb":[[2.14,1.08]],"id":38114646},{"atl":[[3.75,1.08]],"id":37510843},{"atb":[[2.16,1.08]],"id":37569661}],"con":true,"img":false}]}
{"op":"mcm","clk":"5323049726","pt":1646326951843,"mc":[{"id":"1.195532873","rc":[{"atb":[[1.81,0]],"id":37569661}],"con":true,"img":false}]}
{"op":"mcm","clk":"5323049734","pt":1646326951948,"mc":[{"id":"1.195532873","rc":[{"atb":[[1.96,3.85]],"id":37569661}],"con":true,"img":false}]}
{"op":"mcm","clk":"5323049740","pt":1646326952050,"mc":[{"id":"1.195532873","rc":[{"atb":[[2.9,31.16]],"id":39727103}],"con":true,"img":false}]}
{"op":"mcm","clk":"5323049745","pt":1646326952156,"mc":[{"id":"1.195532873","rc":[{"atb":[[1.96,0]],"id":37569661}],"con":true,"img":false}]}
{"op":"mcm","clk":"5323049786","pt":1646326952848,"mc":[{"id":"1.195532873","rc":[{"atb":[[1.97,65.53]],"id":37569661}],"con":true,"img":false}]}
{"op":"mcm","clk":"5323049796","pt":1646326952955,"mc":[{"id":"1.195532873","rc":[{"atb":[[1.87,0]],"id":37569661}],"con":true,"img":false}]}
{"op":"mcm","clk":"5323049823","pt":1646326953384,"mc":[{"id":"1.195532873","rc":[{"atb":[[2.98,2.79]],"id":37510843},{"atb":[[2.18,3.93]],"id":37569661}],"con":true,"img":false}]}
{"op":"mcm","clk":"5323049831","pt":1646326953444,"mc":[{"id":"1.195532873","rc":[{"atb":[[3,4.16]],"id":39727103},{"atb":[[2.14,2.17]],"id":38114646},{"atl":[[4.1,1.08]],"id":37510843},{"atb":[[2.1,1.08]],"id":37569661}],"con":true,"img":false}]}
{"op":"mcm","clk":"5323049846","pt":1646326953633,"mc":[{"id":"1.195532873","rc":[{"atb":[[2.08,4.5]],"id":38114646}],"con":true,"img":false}]}
{"op":"mcm","clk":"5323049852","pt":1646326953747,"mc":[{"id":"1.195532873","rc":[{"atb":[[3,3.07]],"id":39727103},{"atl":[[3.75,0]],"id":37510843},{"atb":[[2.16,0]],"id":37569661}],"con":true,"img":false}]}
{"op":"mcm","clk":"5323049859","pt":1646326953843,"mc":[{"id":"1.195532873","rc":[{"atl":[[4,2.11]],"id":37510843},{"atb":[[2,0],[2.18,0]],"id":37569661}],"con":true,"img":false}]}
{"op":"mcm","clk":"5323049868","pt":1646326953947,"mc":[{"id":"1.195532873","rc":[{"atb":[[2.9,3.44]],"id":37510843},{"atb":[[1.88,14.6],[2.12,4.26],[2.2,5.82]],"id":37569661}],"con":true,"img":false}]}
{"op":"mcm","clk":"5323049875","pt":1646326954050,"mc":[{"id":"1.195532873","rc":[{"atb":[[2.88,11.9]],"id":37510843}],"con":true,"img":false}]}
{"op":"mcm","clk":"5323049885","pt":1646326954152,"mc":[{"id":"1.195532873","rc":[{"atb":[[2.86,2.06]],"id":37510843}],"con":true,"img":false}]}
{"op":"mcm","clk":"5323049908","pt":1646326954568,"mc":[{"id":"1.195532873","rc":[{"atl":[[3.9,1.08]],"id":37510843}],"con":true,"img":false}]}
{"op":"mcm","clk":"5323049920","pt":1646326954735,"mc":[{"id":"1.195532873","rc":[{"atb":[[3,1.99]],"id":39727103},{"atb":[[2.98,1.71]],"id":37510843}],"con":true,"img":false}]}
{"op":"mcm","clk":"5323049924","pt":1646326954838,"mc":[{"id":"1.195532873","rc":[{"atb":[[2.96,3.18]],"id":37510843}],"con":true,"img":false}]}
{"op":"mcm","clk":"5323049935","pt":1646326955044,"mc":[{"id":"1.195532873","rc":[{"atb":[[2.86,0]],"id":37510843}],"con":true,"img":false}]}
{"op":"mcm","clk":"5323049955","pt":1646326955361,"mc":[{"id":"1.195532873","rc":[{"atb":[[5,13.79]],"id":36601249},{"atl":[[7.8,32.67]],"id":36601249},{"atb":[[1.92,0]],"id":38114646},{"atb":[[2.4,3.08]],"id":39590546},{"atb":[[2.46,0]],"id":37510843}],"con":true,"img":false}]}
{"op":"mcm","clk":"5323049963","pt":1646326955461,"mc":[{"id":"1.195532873","rc":[{"atb":[[2.14,2.72]],"id":39590546}],"con":true,"img":false}]}
{"op":"mcm","clk":"5323049969","pt":1646326955563,"mc":[{"id":"1.195532873","rc":[{"atb":[[2.3,6.55]],"id":39590546},{"atb":[[3.1,1.08]],"id":37510843},{"atl":[[3.8,1.08]],"id":37510843},{"atb":[[2.26,1.08]],"id":37569661}],"con":true,"img":false}]}
{"op":"mcm","clk":"5323049990","pt":1646326955769,"mc":[{"id":"1.195532873","rc":[{"atl":[[3.95,2.18],[4.7,40.54]],"id":37510843},{"atb":[[2.28,3.46]],"id":37569661}],"con":true,"img":false}]}
{"op":"mcm","clk":"5323050001","pt":1646326955835,"mc":[{"id":"1.195532873","rc":[{"atb":[[2.14,0]],"id":39590546},{"atb":[[2.88,2.74],[2.9,10.93]],"id":37510843}],"con":true,"img":false}]}
{"op":"mcm","clk":"5323050009","pt":1646326955936,"mc":[{"id":"1.195532873","rc":[{"atb":[[3,0]],"id":39727103},{"atb":[[1.97,54.19]],"id":37569661}],"con":true,"img":false}]}
{"op":"mcm","clk":"5323050016","pt":1646326956074,"mc":[{"id":"1.195532873","rc":[{"atb":[[2.96,1.99]],"id":39727103}],"con":true,"img":false}]}
{"op":"mcm","clk":"5323050036","pt":1646326956243,"mc":[{"id":"1.195532873","rc":[{"atb":[[2.2,3.83]],"id":37569661}],"con":true,"img":false}]}
{"op":"mcm","clk":"5323050045","pt":1646326956353,"mc":[{"id":"1.195532873","rc":[{"atb":[[2.3,1.99]],"id":37569661}],"con":true,"img":false}]}
{"op":"mcm","clk":"5323050054","pt":1646326956465,"mc":[{"id":"1.195532873","rc":[{"atb":[[2.38,0]],"id":39590546},{"atb":[[2.88,1.08]],"id":37510843}],"con":true,"img":false}]}
{"op":"mcm","clk":"5323050060","pt":1646326956557,"mc":[{"id":"1.195532873","rc":[{"atb":[[2.32,3.3]],"id":37569661}],"con":true,"img":false}]}
{"op":"mcm","clk":"5323050065","pt":1646326956665,"mc":[{"id":"1.195532873","rc":[{"atb":[[2.98,2.74]],"id":39727103},{"atb":[[3,1.65]],"id":37510843}],"con":true,"img":false}]}
{"op":"mcm","clk":"5323050089","pt":1646326957032,"mc":[{"id":"1.195532873","rc":[{"atb":[[3,1.08]],"id":39727103},{"atb":[[3.05,1.08]],"id":37510843},{"atl":[[3.75,1.08]],"id":37510843},{"atb":[[2.3,3.07]],"id":37569661}],"con":true,"img":false}]}
{"op":"mcm","clk":"5323050096","pt":1646326957135,"mc":[{"id":"1.195532873","rc":[{"atb":[[2.94,19.07],[2.9,11]],"id":39727103}],"con":true,"img":false}]}
{"op":"mcm","clk":"5323050123","pt":1646326957549,"mc":[{"id":"1.195532873","rc":[{"atb":[[2.96,0]],"id":39727103}],"con":true,"img":false}]}
{"op":"mcm","clk":"5323050131","pt":1646326957663,"mc":[{"id":"1.195532873","rc":[{"atb":[[3.05,3.07]],"id":39727103}],"con":true,"img":false}]}
{"op":"mcm","clk":"5323050142","pt":1646326957860,"mc":[{"id":"1.195532873","rc":[{"atb":[[2.3,1.08]],"id":37569661}],"con":true,"img":false}]}
{"op":"mcm","clk":"5323050150","pt":1646326957964,"mc":[{"id":"1.195532873","rc":[{"atb":[[2.9,7.49]],"id":37510843},{"atb":[[2.34,1.99],[1.88,0]],"id":37569661}],"con":true,"img":false}]}
{"op":"mcm","clk":"5323050164","pt":1646326958130,"mc":[{"id":"1.195532873","rc":[{"atb":[[2.36,3.15]],"id":37569661}],"con":true,"img":false}]}
{"op":"mcm","clk":"5323050197","pt":1646326958549,"mc":[{"id":"1.195532873","rc":[{"atb":[[2.9,0],[2.96,9.89]],"id":37510843}],"con":true,"img":false}]}
{"op":"mcm","clk":"5323050203","pt":1646326958653,"mc":[{"id":"1.195532873","rc":[{"atb":[[3.05,1.99]],"id":39727103},{"atl":[[3.7,1.08]],"id":37510843},{"atb":[[2.34,3.07]],"id":37569661}],"con":true,"img":false}]}
{"op":"mcm","clk":"5323050245","pt":1646326959226,"mc":[{"id":"1.195532873","rc":[{"atb":[[2.34,1.08]],"id":37569661}],"con":true,"img":false}]}
{"op":"mcm","clk":"5323050254","pt":1646326959329,"mc":[{"id":"1.195532873","rc":[{"atb":[[2.38,1.99]],"id":37569661}],"con":true,"img":false}]}
{"op":"mcm","clk":"5323050292","pt":1646326960057,"mc":[{"id":"1.195532873","rc":[{"atl":[[3.75,3.08],[4.5,28.57],[3.95,10.9]],"id":37510843}],"con":true,"img":false}]}
{"op":"mcm","clk":"5323050305","pt":1646326960262,"mc":[{"id":"1.195532873","rc":[{"atl":[[4.3,12.12]],"id":37510843}],"con":true,"img":false}]}
{"op":"mcm","clk":"5323050331","pt":1646326960529,"mc":[{"id":"1.195532873","rc":[{"atl":[[2.84,3.38]],"id":39590546}],"con":true,"img":false}]}
{"op":"mcm","clk":"5323050341","pt":1646326960639,"mc":[{"id":"1.195532873","rc":[{"atl":[[3.3,0]],"id":39590546}],"con":true,"img":false}]}
{"op":"mcm","clk":"5323050371","pt":1646326961159,"mc":[{"id":"1.195532873","rc":[{"atl":[[3.75,2]],"id":37510843}],"con":true,"img":false}]}
{"op":"mcm","clk":"5323050531","pt":1646326963359,"mc":[{"id":"1.195532873","rc":[{"atl":[[4.4,3.85]],"id":39727103}],"con":true,"img":false}]}
{"op":"mcm","clk":"5323050549","pt":1646326963669,"mc":[{"id":"1.195532873","rc":[{"atl":[[4.4,0]],"id":39727103}],"con":true,"img":false}]}
{"op":"mcm","clk":"5323050568","pt":1646326963947,"mc":[{"id":"1.195532873","rc":[{"atb":[[3.1,4.99]],"id":37510843}],"con":true,"img":false}]}
{"op":"mcm","clk":"5323050603","pt":1646326964469,"mc":[{"id":"1.195532873","rc":[{"atb":[[2.98,1.08]],"id":39727103},{"atb":[[3,0]],"id":37510843}],"con":true,"img":false}]}
{"op":"mcm","clk":"5323050618","pt":1646326964655,"mc":[{"id":"1.195532873","rc":[{"atb":[[2.94,12.26],[2.9,29.8]],"id":39727103}],"con":true,"img":false}]}
{"op":"mcm","clk":"5323050632","pt":1646326964844,"mc":[{"id":"1.195532873","rc":[{"atb":[[3.05,0]],"id":39727103}],"con":true,"img":false}]}
{"op":"mcm","clk":"5323050640","pt":1646326964941,"mc":[{"id":"1.195532873","rc":[{"atb":[[1.02,1.99]],"id":39727103}],"con":true,"img":false}]}
{"op":"mcm","clk":"5323050675","pt":1646326965740,"mc":[{"id":"1.195532873","rc":[{"atb":[[2.38,0]],"id":37569661}],"con":true,"img":false}]}
{"op":"mcm","clk":"5323050683","pt":1646326965752,"mc":[{"id":"1.195532873","rc":[{"atl":[[4,4.29],[3.95,8.72]],"id":37510843},{"atb":[[1.02,1.99]],"id":37569661}],"con":true,"img":false}]}
{"op":"mcm","clk":"5323050692","pt":1646326966069,"mc":[{"id":"1.195532873","rc":[{"atb":[[2.96,1.08]],"id":39727103},{"atb":[[2.52,0],[3.15,1.08],[2.96,13.39]],"id":37510843}],"con":true,"img":false}]}
{"op":"mcm","clk":"5323050701","pt":1646326966083,"mc":[{"id":"1.195532873","rc":[{"atb":[[5.3,2.25]],"id":36601249},{"atb":[[2.34,0]],"id":37569661}],"con":true,"img":false}]}
{"op":"mcm","clk":"5323050708","pt":1646326966105,"mc":[{"id":"1.195532873","rc":[{"atb":[[1.02,1.99]],"id":36601249},{"atb":[[2.96,9.89]],"id":37510843}],"con":true,"img":false}]}
{"op":"mcm","clk":"5323050738","pt":1646326966242,"mc":[{"id":"1.195532873","rc":[{"atb":[[2.32,0],[2.12,0],[2.36,0],[2.28,0],[2.2,0]],"id":37569661}],"con":true,"img":false}]}
{"op":"mcm","clk":"5323050745","pt":1646326966347,"mc":[{"id":"1.195532873","rc":[{"atb":[[1.97,66.89]],"id":37569661}],"con":true,"img":false}]}
{"op":"mcm","clk":"5323050769","pt":1646326966659,"mc":[{"id":"1.195532873","rc":[{"atb":[[2.32,3.3]],"id":37569661}],"con":true,"img":false}]}
