{"op":"mcm","clk":"5317728504","pt":1646251399885,"mc":[{"id":"1.195532865","marketDefinition":{"bspMarket":true,"turnInPlayEnabled":false,"persistenceEnabled":false,"marketBaseRate":5.0,"eventId":"31275720","eventTypeId":"4339","numberOfWinners":2,"bettingType":"ODDS","marketType":"PLACE","marketTime":"2022-03-03T15:48:00.000Z","suspendTime":"2022-03-03T15:48:00.000Z","bspReconciled":false,"complete":true,"inPlay":false,"crossMatching":false,"runnersVoidable":false,"numberOfActiveRunners":6,"betDelay":0,"status":"OPEN","runners":[{"status":"ACTIVE","sortPriority":1,"id":35701941,"name":"1. Dark Phoenix"},{"status":"ACTIVE","sortPriority":2,"id":40133341,"name":"2. Tennesse Whiskey"},{"status":"ACTIVE","sortPriority":3,"id":28041476,"name":"3. Bowmers Alpha"},{"status":"ACTIVE","sortPriority":4,"id":43189002,"name":"4. Pennys Toran"},{"status":"ACTIVE","sortPriority":5,"id":37307439,"name":"5. Davys Ellie"},{"status":"ACTIVE","sortPriority":6,"id":36909459,"name":"6. Teaboy Bruno"}],"regulators":["MR_INT"],"venue":"Romford","countryCode":"GB","discountAllowed":false,"timezone":"Europe/London","openDate":"2022-03-03T13:57:00.000Z","version":4384107304,"name":"To Be Placed","eventName":"Romford 3rd Mar"},"rc":[],"con":true,"img":false}]}
{"op":"mcm","clk":"5317728855","pt":1646251401763,"mc":[{"id":"1.195532865","marketDefinition":{"bspMarket":true,"turnInPlayEnabled":false,"persistenceEnabled":false,"marketBaseRate":5.0,"eventId":"31275720","eventTypeId":"4339","numberOfWinners":2,"bettingType":"ODDS","marketType":"PLACE","marketTime":"2022-03-03T15:48:00.000Z","suspendTime":"2022-03-03T15:48:00.000Z","bspReconciled":false,"complete":true,"inPlay":false,"crossMatching":false,"runnersVoidable":false,"numberOfActiveRunners":6,"betDelay":0,"status":"OPEN","runners":[{"status":"ACTIVE","sortPriority":1,"id":35701941,"name":"1. Dark Phoenix"},{"status":"ACTIVE","sortPriority":2,"id":40133341,"name":"2. Tennesse Whiskey"},{"status":"ACTIVE","sortPriority":3,"id":28041476,"name":"3. Bowmers Alpha"},{"status":"ACTIVE","sortPriority":4,"id":43189002,"name":"4. Pennys Toran"},{"status":"ACTIVE","sortPriority":5,"id":37307439,"name":"5. Davys Ellie"},{"status":"ACTIVE","sortPriority":6,"id":36909459,"name":"6. Teaboy Bruno"}],"regulators":["MR_INT"],"venue":"Romford","countryCode":"GB","discountAllowed":true,"timezone":"Europe/London","openDate":"2022-03-03T13:57:00.000Z","version":4384107304,"name":"To Be Placed","eventName":"Romford 3rd Mar"},"rc":[],"con":true,"img":false}]}
{"op":"mcm","clk":"5318435936","pt":1646258265707,"mc":[{"id":"1.195532865","rc":[{"spl":[[1.01,10]],"id":35701941},{"spn":1.0,"spf":1.0,"id":35701941}],"con":true,"img":false}]}
{"op":"mcm","clk":"5321318397","pt":1646308342475,"mc":[{"id":"1.195532865","rc":[{"atb":[[1.01,102.04]],"id":40133341},{"spn":"Infinity","spf":"NaN","id":40133341},{"atb":[[1.01,102.04]],"id":43189002},{"spn":"Infinity","spf":"NaN","id":43189002},{"atb":[[1.01,102.04]],"id":36909459},{"spn":"Infinity","spf":"NaN","id":36909459},{"atb":[[1.01,102.04]],"id":37307439},{"spn":"Infinity","spf":"NaN","id":37307439}],"con":true,"img":false}]}
{"op":"mcm","clk":"5321318410","pt":1646308342579,"mc":[{"id":"1.195532865","rc":[{"atb":[[1.01,102.04]],"id":35701941},{"atb":[[1.01,102.04]],"id":28041476}],"con":true,"img":false}]}
{"op":"mcm","clk":"5321555303","pt":1646310922894,"mc":[{"id":"1.195532865","rc":[{"atb":[[1.01,4802.04]],"id":40133341},{"atb":[[1.01,4802.04]],"id":43189002},{"atb":[[1.01,4802.04]],"id":35701941},{"spn":1.01,"spf":1.0,"id":35701941},{"atb":[[1.01,4802.04]],"id":28041476},{"spn":"Infinity","spf":"NaN","id":28041476},{"atb":[[1.01,4802.04]],"id":36909459},{"atb":[[1.01,4802.04]],"id":37307439}],"con":true,"img":false}]}
{"op":"mcm","clk":"5321905629","pt":1646314395071,"mc":[{"id":"1.195532865","rc":[{"spl":[[1.01,1]],"id":36909459},{"spn":1.01,"spf":1.0,"id":36909459}],"con":true,"img":false}]}
{"op":"mcm","clk":"5322477353","pt":1646320681703,"mc":[{"id":"1.195532865","rc":[{"atb":[[1.01,5052.04]],"id":40133341},{"atb":[[1.01,5052.04]],"id":43189002},{"atb":[[1.01,5052.04]],"id":35701941},{"atb":[[1.01,5052.04]],"id":28041476},{"atb":[[1.01,5052.04]],"id":36909459},{"atb":[[1.01,5052.04]],"id":37307439}],"con":true,"img":false}]}
{"op":"mcm","clk":"5322489076","pt":1646320831065,"mc":[{"id":"1.195532865","rc":[{"atl":[[46,2.73]],"id":40133341},{"spn":23.5,"spf":"NaN","id":40133341},{"atl":[[46,2.73]],"id":43189002},{"spn":23.5,"spf":"NaN","id":43189002},{"atl":[[46,2.73]],"id":35701941},{"atl":[[46,2.73]],"id":28041476},{"spn":23.5,"spf":"NaN","id":28041476},{"atl":[[46,2.73]],"id":36909459},{"atl":[[46,2.73]],"id":37307439},{"spn":23.5,"spf":"NaN","id":37307439}],"con":true,"img":false}]}
{"op":"mcm","clk":"5322489145","pt":1646320831990,"mc":[{"id":"1.195532865","rc":[{"atl":[[70,2.17],[80,3.16],[50,1],[60,1.69]],"id":40133341},{"atl":[[70,2.17],[80,3.16],[50,1],[60,1.69]],"id":43189002},{"atl":[[70,2.17],[80,3.16],[50,1],[60,1.69]],"id":35701941},{"atl":[[70,2.17],[80,3.16],[50,1],[60,1.69]],"id":28041476},{"atl":[[70,2.17],[80,3.16],[50,1],[60,1.69]],"id":36909459},{"atl":[[70,2.17],[80,3.16],[50,1],[60,1.69]],"id":37307439}],"con":true,"img":false}]}
{"op":"mcm","clk":"5322491568","pt":1646320860774,"mc":[{"id":"1.195532865","marketDefinition":{"bspMarket":true,"turnInPlayEnabled":false,"persistenceEnabled":false,"marketBaseRate":5.0,"eventId":"31275720","eventTypeId":"4339","numberOfWinners":2,"bettingType":"ODDS","marketType":"PLACE","marketTime":"2022-03-03T15:48:00.000Z","suspendTime":"2022-03-03T15:48:00.000Z","bspReconciled":false,"complete":true,"inPlay":false,"crossMatching":true,"runnersVoidable":false,"numberOfActiveRunners":6,"betDelay":0,"status":"OPEN","runners":[{"status":"ACTIVE","sortPriority":1,"id":35701941,"name":"1. Dark Phoenix"},{"status":"ACTIVE","sortPriority":2,"id":40133341,"name":"2. Tennesse Whiskey"},{"status":"ACTIVE","sortPriority":3,"id":28041476,"name":"3. Bowmers Alpha"},{"status":"ACTIVE","sortPriority":4,"id":43189002,"name":"4. Pennys Toran"},{"status":"ACTIVE","sortPriority":5,"id":37307439,"name":"5. Davys Ellie"},{"status":"ACTIVE","sortPriority":6,"id":36909459,"name":"6. Teaboy Bruno"}],"regulators":["MR_INT"],"venue":"Romford","countryCode":"GB","discountAllowed":true,"timezone":"Europe/London","openDate":"2022-03-03T13:57:00.000Z","version":4384107304,"name":"To Be Placed","eventName":"Romford 3rd Mar"},"rc":[],"con":true,"img":false}]}
{"op":"mcm","clk":"5322548936","pt":1646321612691,"mc":[{"id":"1.195532865","rc":[{"atb":[[1.66,151.52]],"id":40133341},{"atl":[[8.2,2]],"id":40133341},{"spn":4.93,"spf":"NaN","id":40133341},{"atb":[[2.44,69.44]],"id":35701941},{"atl":[[46,4.73]],"id":35701941},{"spn":2.44,"spf":1.0,"id":35701941},{"atb":[[2.24,80.65]],"id":28041476},{"atl":[[27,2]],"id":28041476},{"spn":14.62,"spf":"NaN","id":28041476},{"atb":[[1.42,238.1]],"id":36909459},{"atl":[[5.6,2]],"id":36909459},{"spn":1.42,"spf":1.0,"id":36909459}],"con":true,"img":false}]}
{"op":"mcm","clk":"5322548944","pt":1646321612796,"mc":[{"id":"1.195532865","rc":[{"atb":[[1.44,227.27]],"id":43189002},{"atl":[[11,2]],"id":43189002},{"atb":[[1.02,5000]],"id":37307439},{"atl":[[3.05,2]],"id":37307439}],"con":true,"img":false}]}
{"op":"mcm","clk":"5322548955","pt":1646321612898,"mc":[{"id":"1.195532865","rc":[{"atb":[[1.77,129.87],[1.66,0]],"id":40133341},{"atb":[[1.44,0],[1.65,153.85]],"id":43189002},{"atb":[[2.44,0],[2.66,60.24]],"id":35701941},{"atl":[[46,2.73],[60,3.69]],"id":35701941},{"atb":[[2.24,0],[2.44,69.44]],"id":28041476},{"atb":[[1.58,172.41],[1.42,0]],"id":36909459},{"atb":[[1.03,3333.33],[1.02,0]],"id":37307439}],"con":true,"img":false}]}
{"op":"mcm","clk":"5322548964","pt":1646321612997,"mc":[{"id":"1.195532865","rc":[{"atl":[[46,4.73],[60,1.69]],"id":35701941}],"con":true,"img":false}]}
{"op":"mcm","clk":"5322548973","pt":1646321613106,"mc":[{"id":"1.195532865","rc":[{"atb":[[1.75,53.33]],"id":40133341},{"atl":[[8.6,5.26],[50,0]],"id":40133341},{"atb":[[1.63,63.49]],"id":43189002},{"atl":[[12,3.64],[50,0]],"id":43189002},{"atb":[[2.62,24.69]],"id":35701941},{"atb":[[2.4,28.57]],"id":28041476},{"atl":[[50,0],[29,1.43]],"id":28041476},{"atb":[[1.56,71.43]],"id":36909459},{"atl":[[5.8,8.33],[50,0]],"id":36909459},{"atl":[[50,0],[3.15,18.6]],"id":37307439}],"con":true,"img":false}]}
{"op":"mcm","clk":"5322549027","pt":1646321613788,"mc":[{"id":"1.195532865","rc":[{"atb":[[2.68,1.65]],"id":35701941},{"atb":[[2.46,1.65]],"id":28041476}],"con":true,"img":false}]}
{"op":"mcm","clk":"5322549185","pt":1646321615759,"mc":[{"id":"1.195532865","rc":[{"atb":[[2.64,24.39]],"id":35701941},{"atb":[[2.42,28.17]],"id":28041476}],"con":true,"img":false}]}
{"op":"mcm","clk":"5322549271","pt":1646321616730,"mc":[{"id":"1.195532865","rc":[{"atb":[[2.5,2.15]],"id":28041476}],"con":true,"img":false}]}
{"op":"mcm","clk":"5322549290","pt":1646321616934,"mc":[{"id":"1.195532865","rc":[{"atb":[[2.5,4.31],[2.44,0]],"id":28041476}],"con":true,"img":false}]}
{"op":"mcm","clk":"5322549304","pt":1646321617035,"mc":[{"id":"1.195532865","rc":[{"atb":[[2.46,29.82]],"id":28041476}],"con":true,"img":false}]}
{"op":"mcm","clk":"5322549314","pt":1646321617136,"mc":[{"id":"1.195532865","rc":[{"atb":[[2.5,2.15]],"id":28041476}],"con":true,"img":false}]}
{"op":"mcm","clk":"5322549330","pt":1646321617307,"mc":[{"id":"1.195532865","rc":[{"atb":[[2.5,30.32],[2.46,1.65]],"id":28041476}],"con":true,"img":false}]}
{"op":"mcm","clk":"5322549548","pt":1646321620434,"mc":[{"id":"1.195532865","rc":[{"atb":[[2.46,29.05]],"id":28041476},{"atl":[[26,2],[27,0]],"id":28041476}],"con":true,"img":false}]}
{"op":"mcm","clk":"5322549627","pt":1646321621374,"mc":[{"id":"1.195532865","rc":[{"atl":[[28,1.48],[29,0]],"id":28041476}],"con":true,"img":false}]}
{"op":"mcm","clk":"5322549721","pt":1646321622906,"mc":[{"id":"1.195532865","rc":[{"atb":[[2.46,27.4]],"id":28041476}],"con":true,"img":false}]}
{"op":"mcm","clk":"5322549732","pt":1646321623098,"mc":[{"id":"1.195532865","rc":[{"atb":[[1.73,136.99]],"id":40133341},{"atl":[[9,12.5]],"id":40133341},{"atb":[[1.61,163.93]],"id":43189002},{"atl":[[13,8.33]],"id":43189002},{"atb":[[2.52,1.65]],"id":28041476},{"atb":[[1.54,185.19]],"id":36909459},{"atl":[[6,20]],"id":36909459},{"atl":[[3.25,44.44]],"id":37307439}],"con":true,"img":false}]}
{"op":"mcm","clk":"5322549799","pt":1646321623997,"mc":[{"id":"1.195532865","rc":[{"atb":[[1.8,2.15]],"id":40133341},{"atb":[[1.68,2.15]],"id":43189002},{"atb":[[1.61,2.15]],"id":36909459}],"con":true,"img":false}]}
{"op":"mcm","clk":"5322549817","pt":1646321624198,"mc":[{"id":"1.195532865","rc":[{"atb":[[1.8,55.48],[1.77,0]],"id":40133341},{"atb":[[1.68,65.64],[1.65,0]],"id":43189002},{"atb":[[1.58,0],[1.61,73.58]],"id":36909459}],"con":true,"img":false}]}
{"op":"mcm","clk":"5322549943","pt":1646321625683,"mc":[{"id":"1.195532865","rc":[{"atb":[[2.6,62.5]],"id":35701941}],"con":true,"img":false}]}
{"op":"mcm","clk":"5322550369","pt":1646321630602,"mc":[{"id":"1.195532865","rc":[{"atb":[[1.78,51.28]],"id":40133341},{"atl":[[70,0],[80,0],[60,0]],"id":40133341},{"atb":[[1.66,60.61]],"id":43189002},{"atl":[[80,0]],"id":43189002},{"atb":[[2.46,0],[2.48,27.03]],"id":28041476},{"atb":[[1.59,67.8]],"id":36909459},{"atl":[[80,0]],"id":36909459},{"atl":[[70,0],[80,0],[60,0]],"id":37307439}],"con":true,"img":false}]}
{"op":"mcm","clk":"5322550542","pt":1646321632694,"mc":[{"id":"1.195532865","rc":[{"atb":[[1.01,5054.04]],"id":35701941}],"con":true,"img":false}]}
{"op":"mcm","clk":"5322550570","pt":1646321633004,"mc":[{"id":"1.195532865","rc":[{"atb":[[1.01,5056.03]],"id":35701941}],"con":true,"img":false}]}
{"op":"mcm","clk":"5322550577","pt":1646321633111,"mc":[{"id":"1.195532865","rc":[{"atl":[[3.35,63.83]],"id":37307439}],"con":true,"img":false}]}
{"op":"mcm","clk":"5322550600","pt":1646321633375,"mc":[{"id":"1.195532865","rc":[{"atb":[[1.01,5054.04]],"id":35701941}],"con":true,"img":false}]}
{"op":"mcm","clk":"5322550608","pt":1646321633476,"mc":[{"id":"1.195532865","rc":[{"atb":[[2.68,3.64]],"id":35701941}],"con":true,"img":false}]}
{"op":"mcm","clk":"5322550616","pt":1646321633586,"mc":[{"id":"1.195532865","rc":[{"atb":[[2.7,24.39]],"id":35701941}],"con":true,"img":false}]}
{"op":"mcm","clk":"5322550625","pt":1646321633691,"mc":[{"id":"1.195532865","rc":[{"atb":[[2.66,0]],"id":35701941}],"con":true,"img":false}]}
{"op":"mcm","clk":"5322550638","pt":1646321633897,"mc":[{"id":"1.195532865","rc":[{"atb":[[1.01,5054.04]],"id":40133341}],"con":true,"img":false}]}
{"op":"mcm","clk":"5322550660","pt":1646321634211,"mc":[{"id":"1.195532865","rc":[{"atb":[[1.01,5056.03]],"id":40133341}],"con":true,"img":false}]}
{"op":"mcm","clk":"5322550699","pt":1646321634692,"mc":[{"id":"1.195532865","rc":[{"atb":[[1.01,5054.04]],"id":40133341}],"con":true,"img":false}]}
{"op":"mcm","clk":"5322550706","pt":1646321634789,"mc":[{"id":"1.195532865","rc":[{"atb":[[1.81,1.99]],"id":40133341}],"con":true,"img":false}]}
{"op":"mcm","clk":"5322550735","pt":1646321635104,"mc":[{"id":"1.195532865","rc":[{"atb":[[1.01,5054.04]],"id":28041476}],"con":true,"img":false}]}
{"op":"mcm","clk":"5322550745","pt":1646321635206,"mc":[{"id":"1.195532865","rc":[{"atb":[[1.01,5056.03]],"id":28041476}],"con":true,"img":false}]}
{"op":"mcm","clk":"5322550762","pt":1646321635418,"mc":[{"id":"1.195532865","rc":[{"atb":[[1.01,5054.04]],"id":28041476}],"con":true,"img":false}]}
{"op":"mcm","clk":"5322550771","pt":1646321635470,"mc":[{"id":"1.195532865","rc":[{"atb":[[2.52,3.64]],"id":28041476}],"con":true,"img":false}]}
{"op":"mcm","clk":"5322550781","pt":1646321635574,"mc":[{"id":"1.195532865","rc":[{"atb":[[2.54,27.03],[2.5,2.15]],"id":28041476}],"con":true,"img":false}]}
{"op":"mcm","clk":"5322550785","pt":1646321635678,"mc":[{"id":"1.195532865","rc":[{"atb":[[2.64,0],[2.66,24.1]],"id":35701941}],"con":true,"img":false}]}
{"op":"mcm","clk":"5322550827","pt":1646321636200,"mc":[{"id":"1.195532865","rc":[{"atb":[[1.01,5054.04]],"id":43189002}],"con":true,"img":false}]}
{"op":"mcm","clk":"5322550841","pt":1646321636409,"mc":[{"id":"1.195532865","rc":[{"atb":[[1.01,5056.03]],"id":43189002}],"con":true,"img":false}]}
{"op":"mcm","clk":"5322550865","pt":1646321636618,"mc":[{"id":"1.195532865","rc":[{"atb":[[1.01,5054.04]],"id":43189002}],"con":true,"img":false}]}
{"op":"mcm","clk":"5322550877","pt":1646321636680,"mc":[{"id":"1.195532865","rc":[{"atb":[[1.69,1.99]],"id":43189002}],"con":true,"img":false}]}
{"op":"mcm","clk":"5322550884","pt":1646321636791,"mc":[{"id":"1.195532865","rc":[{"atb":[[1.79,50.63],[1.78,0]],"id":40133341},{"atb":[[2.5,28.82],[2.48,0]],"id":28041476}],"con":true,"img":false}]}
{"op":"mcm","clk":"5322550893","pt":1646321636885,"mc":[{"id":"1.195532865","rc":[{"atb":[[1.01,5054.04]],"id":37307439}],"con":true,"img":false}]}
{"op":"mcm","clk":"5322550902","pt":1646321636990,"mc":[{"id":"1.195532865","rc":[{"atb":[[2.5,26.67],[2.6,2.15]],"id":28041476},{"atb":[[1.01,5056.03]],"id":37307439}],"con":true,"img":false}]}
{"op":"mcm","clk":"5322550919","pt":1646321637198,"mc":[{"id":"1.195532865","rc":[{"atb":[[1.01,5054.04]],"id":37307439}],"con":true,"img":false}]}
{"op":"mcm","clk":"5322550927","pt":1646321637297,"mc":[{"id":"1.195532865","rc":[{"atb":[[1.04,1.99]],"id":37307439}],"con":true,"img":false}]}
{"op":"mcm","clk":"5322550946","pt":1646321637512,"mc":[{"id":"1.195532865","rc":[{"atb":[[1.01,5054.04]],"id":36909459}],"con":true,"img":false}]}
{"op":"mcm","clk":"5322550961","pt":1646321637720,"mc":[{"id":"1.195532865","rc":[{"atb":[[1.01,5056.03]],"id":36909459}],"con":true,"img":false}]}
{"op":"mcm","clk":"5322550975","pt":1646321637878,"mc":[{"id":"1.195532865","rc":[{"atb":[[1.01,5054.04]],"id":36909459}],"con":true,"img":false}]}
{"op":"mcm","clk":"5322550986","pt":1646321637980,"mc":[{"id":"1.195532865","rc":[{"atb":[[1.62,1.99]],"id":36909459}],"con":true,"img":false}]}
{"op":"mcm","clk":"5322551044","pt":1646321638915,"mc":[{"id":"1.195532865","rc":[{"atb":[[2.68,1.65]],"id":35701941}],"con":true,"img":false}]}
{"op":"mcm","clk":"5322551053","pt":1646321639020,"mc":[{"id":"1.195532865","rc":[{"atb":[[2.72,1.99]],"id":35701941}],"con":true,"img":false}]}
{"op":"mcm","clk":"5322551065","pt":1646321639071,"mc":[{"id":"1.195532865","rc":[{"atb":[[2.68,50.43],[2.7,0]],"id":35701941}],"con":true,"img":false}]}
{"op":"mcm","clk":"5322551078","pt":1646321639280,"mc":[{"id":"1.195532865","rc":[{"atb":[[2.52,1.65]],"id":28041476}],"con":true,"img":false}]}
{"op":"mcm","clk":"5322551085","pt":1646321639384,"mc":[{"id":"1.195532865","rc":[{"atb":[[2.62,1.99]],"id":28041476}],"con":true,"img":false}]}
{"op":"mcm","clk":"5322551091","pt":1646321639489,"mc":[{"id":"1.195532865","rc":[{"atb":[[1.67,59.7],[1.66,0]],"id":43189002},{"atb":[[2.66,0],[2.68,74.24]],"id":35701941},{"atb":[[2.56,25.64],[2.5,0]],"id":28041476},{"atb":[[1.59,0],[1.6,66.67]],"id":36909459}],"con":true,"img":false}]}
{"op":"mcm","clk":"5322551159","pt":1646321640277,"mc":[{"id":"1.195532865","rc":[{"atb":[[2.72,0]],"id":35701941}],"con":true,"img":false}]}
{"op":"mcm","clk":"5322551173","pt":1646321640382,"mc":[{"id":"1.195532865","rc":[{"atb":[[2.7,1.99]],"id":35701941}],"con":true,"img":false}]}
{"op":"mcm","clk":"5322551210","pt":1646321640798,"mc":[{"id":"1.195532865","rc":[{"atb":[[2.68,72.59]],"id":35701941},{"atb":[[2.52,0]],"id":28041476}],"con":true,"img":false}]}
{"op":"mcm","clk":"5322551229","pt":1646321641003,"mc":[{"id":"1.195532865","rc":[{"atb":[[2.72,1.65]],"id":35701941},{"atb":[[2.64,1.65]],"id":28041476}],"con":true,"img":false}]}
{"op":"mcm","clk":"5322551286","pt":1646321641789,"mc":[{"id":"1.195532865","rc":[{"atb":[[2.56,0],[2.6,27.15]],"id":28041476},{"atb":[[1.02,250]],"id":37307439}],"con":true,"img":false}]}
{"op":"mcm","clk":"5322551576","pt":1646321645202,"mc":[{"id":"1.195532865","rc":[{"atb":[[2.54,0],[2.64,3.65]],"id":28041476}],"con":true,"img":false}]}
{"op":"mcm","clk":"5322551601","pt":1646321645614,"mc":[{"id":"1.195532865","rc":[{"atb":[[2.62,0]],"id":28041476}],"con":true,"img":false}]}
{"op":"mcm","clk":"5322551611","pt":1646321645720,"mc":[{"id":"1.195532865","rc":[{"atb":[[2.66,1.99]],"id":28041476}],"con":true,"img":false}]}
{"op":"mcm","clk":"5322551699","pt":1646321646824,"mc":[{"id":"1.195532865","rc":[{"atb":[[1.77,129.87]],"id":40133341},{"atl":[[9.4,17.86]],"id":40133341}],"con":true,"img":false}]}
{"op":"mcm","clk":"5322551731","pt":1646321647086,"mc":[{"id":"1.195532865","rc":[{"atb":[[1.01,4804.04]],"id":40133341},{"atb":[[2.6,2.15],[2.62,24.69]],"id":28041476},{"atb":[[1.03,0],[1.06,250]],"id":37307439}],"con":true,"img":false}]}
{"op":"mcm","clk":"5322551766","pt":1646321647510,"mc":[{"id":"1.195532865","rc":[{"atb":[[1.04,0]],"id":37307439}],"con":true,"img":false}]}
{"op":"mcm","clk":"5322551775","pt":1646321647611,"mc":[{"id":"1.195532865","rc":[{"atb":[[1.07,1.99]],"id":37307439}],"con":true,"img":false}]}
{"op":"mcm","clk":"5322551859","pt":1646321648603,"mc":[{"id":"1.195532865","rc":[{"atb":[[2.72,3.65],[2.68,23.81]],"id":35701941}],"con":true,"img":false}]}
{"op":"mcm","clk":"5322551908","pt":1646321649082,"mc":[{"id":"1.195532865","rc":[{"atb":[[2.7,0]],"id":35701941}],"con":true,"img":false}]}
{"op":"mcm","clk":"5322551917","pt":1646321649184,"mc":[{"id":"1.195532865","rc":[{"atb":[[2.74,1.99]],"id":35701941}],"con":true,"img":false}]}
{"op":"mcm","clk":"5322551937","pt":1646321649392,"mc":[{"id":"1.195532865","rc":[{"atb":[[1.65,153.85]],"id":43189002},{"atl":[[14,11.54]],"id":43189002},{"atb":[[1.58,172.41]],"id":36909459},{"atl":[[6.4,27.78]],"id":36909459}],"con":true,"img":false}]}
{"op":"mcm","clk":"5322551945","pt":1646321649495,"mc":[{"id":"1.195532865","rc":[{"atb":[[2.68,0],[2.7,23.53]],"id":35701941}],"con":true,"img":false}]}
{"op":"mcm","clk":"5322551973","pt":1646321649808,"mc":[{"id":"1.195532865","rc":[{"atb":[[2.72,2]],"id":35701941},{"atb":[[2.64,2]],"id":28041476}],"con":true,"img":false}]}
{"op":"mcm","clk":"5322551990","pt":1646321650016,"mc":[{"id":"1.195532865","rc":[{"atb":[[2.76,1.65]],"id":35701941},{"atb":[[2.68,1.65]],"id":28041476}],"con":true,"img":false}]}
{"op":"mcm","clk":"5322552173","pt":1646321651790,"mc":[{"id":"1.195532865","rc":[{"atb":[[1.05,250]],"id":37307439},{"atl":[[3.45,102.04]],"id":37307439}],"con":true,"img":false}]}
{"op":"mcm","clk":"5322552391","pt":1646321654703,"mc":[{"id":"1.195532865","rc":[{"atb":[[2.64,0],[2.68,3.65]],"id":28041476}],"con":true,"img":false}]}
{"op":"mcm","clk":"5322552412","pt":1646321655016,"mc":[{"id":"1.195532865","rc":[{"atb":[[2.66,0]],"id":28041476}],"con":true,"img":false}]}
{"op":"mcm","clk":"5322552419","pt":1646321655119,"mc":[{"id":"1.195532865","rc":[{"atb":[[2.7,1.99]],"id":28041476}],"con":true,"img":false}]}
{"op":"mcm","clk":"5322552558","pt":1646321656788,"mc":[{"id":"1.195532865","rc":[{"atb":[[1.75,200]],"id":40133341},{"atl":[[9.8,28.41]],"id":40133341}],"con":true,"img":false}]}
{"op":"mcm","clk":"5322552575","pt":1646321656999,"mc":[{"id":"1.195532865","rc":[{"atb":[[2.66,24.1],[2.62,0]],"id":28041476},{"atl":[[30,3.45]],"id":28041476}],"con":true,"img":false}]}
{"op":"mcm","clk":"5322552669","pt":1646321658100,"mc":[{"id":"1.195532865","rc":[{"atb":[[2.72,0],[2.76,3.65]],"id":35701941}],"con":true,"img":false}]}
{"op":"mcm","clk":"5322552705","pt":1646321658512,"mc":[{"id":"1.195532865","rc":[{"atb":[[2.74,0]],"id":35701941}],"con":true,"img":false}]}
{"op":"mcm","clk":"5322552713","pt":1646321658620,"mc":[{"id":"1.195532865","rc":[{"atb":[[2.78,1.99]],"id":35701941}],"con":true,"img":false}]}
{"op":"mcm","clk":"5322552726","pt":1646321658725,"mc":[{"id":"1.195532865","rc":[{"atb":[[2.68,2]],"id":28041476}],"con":true,"img":false}]}
{"op":"mcm","clk":"5322552745","pt":1646321658933,"mc":[{"id":"1.195532865","rc":[{"atb":[[2.72,1.65]],"id":28041476}],"con":true,"img":false}]}
{"op":"mcm","clk":"5322552791","pt":1646321659449,"mc":[{"id":"1.195532865","rc":[{"atb":[[1.63,238.1],[1.01,4804.04]],"id":43189002},{"atl":[[70,0],[15,17.86]],"id":43189002},{"atb":[[2.74,22.99],[2.7,0]],"id":35701941},{"atb":[[1.56,321.43]],"id":36909459},{"atl":[[6.8,43.1]],"id":36909459}],"con":true,"img":false}]}
{"op":"mcm","clk":"5322552805","pt":1646321659504,"mc":[{"id":"1.195532865","rc":[{"atb":[[1.56,250],[1.01,4804.04]],"id":36909459},{"atl":[[70,0]],"id":36909459}],"con":true,"img":false}]}
{"op":"mcm","clk":"5322552861","pt":1646321660127,"mc":[{"id":"1.195532865","rc":[{"atl":[[60,0]],"id":43189002},{"atb":[[2.66,0],[2.68,25.81]],"id":28041476},{"atl":[[80,0]],"id":28041476},{"atl":[[60,0]],"id":36909459}],"con":true,"img":false}]}
{"op":"mcm","clk":"5322553208","pt":1646321664144,"mc":[{"id":"1.195532865","rc":[{"atb":[[2.72,3.65],[2.68,23.81]],"id":28041476}],"con":true,"img":false}]}
{"op":"mcm","clk":"5322553226","pt":1646321664307,"mc":[{"id":"1.195532865","rc":[{"atb":[[2.7,0]],"id":28041476}],"con":true,"img":false}]}
{"op":"mcm","clk":"5322553236","pt":1646321664409,"mc":[{"id":"1.195532865","rc":[{"atb":[[2.74,1.99]],"id":28041476}],"con":true,"img":false}]}
{"op":"mcm","clk":"5322553278","pt":1646321664827,"mc":[{"id":"1.195532865","rc":[{"atb":[[2.68,0],[2.7,23.53]],"id":28041476}],"con":true,"img":false}]}
{"op":"mcm","clk":"5322553458","pt":1646321666812,"mc":[{"id":"1.195532865","rc":[{"atb":[[1.73,250]],"id":40133341}],"con":true,"img":false}]}
{"op":"mcm","clk":"5322553542","pt":1646321667850,"mc":[{"id":"1.195532865","rc":[{"atb":[[2.76,2]],"id":35701941},{"atb":[[2.72,2]],"id":28041476}],"con":true,"img":false}]}
{"op":"mcm","clk":"5322553557","pt":1646321668005,"mc":[{"id":"1.195532865","rc":[{"atb":[[2.8,1.65]],"id":35701941},{"atb":[[2.76,1.65]],"id":28041476}],"con":true,"img":false}]}
{"op":"mcm","clk":"5322553567","pt":1646321668115,"mc":[{"id":"1.195532865","rc":[{"atb":[[2.8,3.65],[2.76,0]],"id":35701941}],"con":true,"img":false}]}
{"op":"mcm","clk":"5322553577","pt":1646321668219,"mc":[{"id":"1.195532865","rc":[{"atb":[[2.8,1.65],[2.78,5.31]],"id":35701941}],"con":true,"img":false}]}
{"op":"mcm","clk":"5322553693","pt":1646321669422,"mc":[{"id":"1.195532865","rc":[{"atb":[[1.61,0]],"id":43189002},{"atb":[[1.54,250]],"id":36909459}],"con":true,"img":false}]}
{"op":"mcm","clk":"5322553700","pt":1646321669529,"mc":[{"id":"1.195532865","rc":[{"atb":[[1.61,250]],"id":43189002},{"atb":[[2.74,0],[2.76,22.73]],"id":35701941},{"atb":[[1.53,23.15]],"id":36909459}],"con":true,"img":false}]}
{"op":"mcm","clk":"5322553715","pt":1646321669735,"mc":[{"id":"1.195532865","rc":[{"atb":[[1.53,0]],"id":36909459}],"con":true,"img":false}]}
{"op":"mcm","clk":"5322554015","pt":1646321673420,"mc":[{"id":"1.195532865","rc":[{"spn":5.0,"spf":"NaN","id":40133341},{"spn":6.34,"spf":"NaN","id":43189002},{"spn":2.77,"spf":1.0,"id":35701941},{"atb":[[2.72,0],[2.76,3.65]],"id":28041476},{"spn":14.38,"spf":"NaN","id":28041476},{"spn":1.62,"spf":1.0,"id":36909459},{"spn":2.06,"spf":"NaN","id":37307439}],"con":true,"img":false}]}
{"op":"mcm","clk":"5322554094","pt":1646321674358,"mc":[{"id":"1.195532865","rc":[{"atb":[[2.74,0]],"id":28041476}],"con":true,"img":false}]}
{"op":"mcm","clk":"5322554106","pt":1646321674461,"mc":[{"id":"1.195532865","rc":[{"atb":[[2.78,1.99]],"id":28041476}],"con":true,"img":false}]}
{"op":"mcm","clk":"5322554143","pt":1646321674827,"mc":[{"id":"1.195532865","rc":[{"atb":[[2.74,22.99],[2.7,0]],"id":28041476},{"atl":[[34,4.55]],"id":28041476}],"con":true,"img":false}]}
{"op":"mcm","clk":"5322554326","pt":1646321676937,"mc":[{"id":"1.195532865","rc":[{"atb":[[2.76,2]],"id":28041476}],"con":true,"img":false}]}
{"op":"mcm","clk":"5322554342","pt":1646321677155,"mc":[{"id":"1.195532865","rc":[{"atb":[[2.8,1.65]],"id":28041476}],"con":true,"img":false}]}
{"op":"mcm","clk":"5322554505","pt":1646321679455,"mc":[{"id":"1.195532865","rc":[{"atb":[[2.72,58.14]],"id":35701941}],"con":true,"img":false}]}
{"op":"mcm","clk":"5322554720","pt":1646321682634,"mc":[{"id":"1.195532865","rc":[{"atb":[[2.8,3.65],[2.76,0]],"id":28041476}],"con":true,"img":false}]}
{"op":"mcm","clk":"5322554748","pt":1646321683164,"mc":[{"id":"1.195532865","rc":[{"atb":[[2.78,0]],"id":28041476}],"con":true,"img":false}]}
{"op":"mcm","clk":"5322554754","pt":1646321683274,"mc":[{"id":"1.195532865","rc":[{"atb":[[2.82,1.99]],"id":28041476}],"con":true,"img":false}]}
{"op":"mcm","clk":"5322554877","pt":1646321684857,"mc":[{"id":"1.195532865","rc":[{"atb":[[2.74,0],[2.78,22.47]],"id":28041476},{"atl":[[70,0],[38,6.76]],"id":28041476}],"con":true,"img":false}]}
{"op":"mcm","clk":"5322554945","pt":1646321685851,"mc":[{"id":"1.195532865","rc":[{"atb":[[2.8,2]],"id":28041476}],"con":true,"img":false}]}
{"op":"mcm","clk":"5322554962","pt":1646321686062,"mc":[{"id":"1.195532865","rc":[{"atb":[[2.84,1.65]],"id":28041476}],"con":true,"img":false}]}
{"op":"mcm","clk":"5322555189","pt":1646321689460,"mc":[{"id":"1.195532865","rc":[{"atb":[[2.68,89.29]],"id":35701941}],"con":true,"img":false}]}
{"op":"mcm","clk":"5322555198","pt":1646321689565,"mc":[{"id":"1.195532865","rc":[{"atb":[[1.01,4804.04],[2.62,0]],"id":35701941}],"con":true,"img":false}]}
{"op":"mcm","clk":"5322555361","pt":1646321691772,"mc":[{"id":"1.195532865","rc":[{"atb":[[2.8,0],[2.84,3.65]],"id":28041476}],"con":true,"img":false}]}
{"op":"mcm","clk":"5322555367","pt":1646321691869,"mc":[{"id":"1.195532865","rc":[{"atb":[[2.82,5.31]],"id":28041476}],"con":true,"img":false}]}
{"op":"mcm","clk":"5322555375","pt":1646321691973,"mc":[{"id":"1.195532865","rc":[{"atb":[[2.82,3.32],[2.84,1.65]],"id":28041476}],"con":true,"img":false}]}
{"op":"mcm","clk":"5322555384","pt":1646321692078,"mc":[{"id":"1.195532865","rc":[{"atb":[[2.86,1.99],[2.78,44.94]],"id":28041476}],"con":true,"img":false}]}
{"op":"mcm","clk":"5322555394","pt":1646321692183,"mc":[{"id":"1.195532865","rc":[{"atb":[[2.82,0],[2.86,3.99]],"id":28041476}],"con":true,"img":false}]}
{"op":"mcm","clk":"5322555405","pt":1646321692286,"mc":[{"id":"1.195532865","rc":[{"atb":[[2.78,22.47]],"id":28041476}],"con":true,"img":false}]}
{"op":"mcm","clk":"5322555619","pt":1646321694808,"mc":[{"id":"1.195532865","rc":[{"atb":[[2.74,57.47],[2.84,0]],"id":28041476}],"con":true,"img":false}]}
{"op":"mcm","clk":"5322555627","pt":1646321694869,"mc":[{"id":"1.195532865","rc":[{"atl":[[60,0]],"id":28041476}],"con":true,"img":false}]}
{"op":"mcm","clk":"5322555637","pt":1646321694973,"mc":[{"id":"1.195532865","rc":[{"atb":[[2.88,1.65]],"id":28041476}],"con":true,"img":false}]}
{"op":"mcm","clk":"5322555763","pt":1646321696697,"mc":[{"id":"1.195532865","rc":[{"atb":[[2.4,0]],"id":28041476}],"con":true,"img":false}]}
{"op":"mcm","clk":"5322555973","pt":1646321699513,"mc":[{"id":"1.195532865","rc":[{"atb":[[2.64,152.44]],"id":35701941}],"con":true,"img":false}]}
{"op":"mcm","clk":"5322556421","pt":1646321704820,"mc":[{"id":"1.195532865","rc":[{"atb":[[2.7,88.24]],"id":28041476}],"con":true,"img":false}]}
{"op":"mcm","clk":"5322556430","pt":1646321704918,"mc":[{"id":"1.195532865","rc":[{"atb":[[2.7,91.71]],"id":28041476}],"con":true,"img":false}]}
{"op":"mcm","clk":"5322556462","pt":1646321705293,"mc":[{"id":"1.195532865","rc":[{"atb":[[2.7,88.24]],"id":28041476}],"con":true,"img":false}]}
{"op":"mcm","clk":"5322556816","pt":1646321709531,"mc":[{"id":"1.195532865","rc":[{"atb":[[2.6,0]],"id":35701941}],"con":true,"img":false}]}
{"op":"mcm","clk":"5322557258","pt":1646321714827,"mc":[{"id":"1.195532865","rc":[{"atb":[[2.66,150.6]],"id":28041476}],"con":true,"img":false}]}
{"op":"mcm","clk":"5322557265","pt":1646321714933,"mc":[{"id":"1.195532865","rc":[{"atb":[[1.01,4804.04]],"id":28041476}],"con":true,"img":false}]}
{"op":"mcm","clk":"5322558004","pt":1646321724915,"mc":[{"id":"1.195532865","rc":[{"atb":[[2.42,0]],"id":28041476}],"con":true,"img":false}]}
{"op":"mcm","clk":"5322562399","pt":1646321779291,"mc":[{"id":"1.195532865","rc":[{"atb":[[1.69,49.33]],"id":43189002},{"spn":14.44,"spf":"NaN","id":28041476},{"atb":[[1.62,54.89]],"id":36909459},{"atb":[[1.03,277.18]],"id":37307439}],"con":true,"img":false}]}
{"op":"mcm","clk":"5322562408","pt":1646321779399,"mc":[{"id":"1.195532865","rc":[{"atb":[[1.68,2.15]],"id":43189002},{"atb":[[1.8,56.18],[1.61,2.15]],"id":36909459},{"atl":[[5.2,19.05]],"id":36909459},{"atb":[[1.4,5],[1.36,10],[1.44,2.5],[1.07,49.27]],"id":37307439},{"atl":[[3.35,66.33],[2.64,47.28]],"id":37307439}],"con":true,"img":false}]}
{"op":"mcm","clk":"5322562416","pt":1646321779504,"mc":[{"id":"1.195532865","rc":[{"atb":[[2.24,43.25],[2.42,2.5],[1.67,131.79],[1.7,78.93],[2.26,10],[2.34,5]],"id":43189002},{"atl":[[7.4,10],[13,26.69],[6.6,5],[5.9,2.5],[8.4,10.81]],"id":43189002},{"atb":[[1.73,5],[1.6,160.29],[1.69,10],[1.63,66.67],[1.57,26.47],[1.77,2.5]],"id":36909459},{"atl":[[4.3,2.5],[5.1,10],[6,59.79],[4.7,5]],"id":36909459},{"atb":[[1.36,260],[1.03,509.02],[1.06,0]],"id":37307439},{"atl":[[3.25,117.91]],"id":37307439}],"con":true,"img":false}]}
{"op":"mcm","clk":"5322562422","pt":1646321779612,"mc":[{"id":"1.195532865","rc":[{"atb":[[2.06,10],[2.22,2.5],[1.77,208.78],[1.93,22.2],[2.14,5],[2.34,13.32]],"id":40133341},{"atl":[[9,39.03],[5.5,2.5],[7.4,12.5],[6.6,10],[5.9,5]],"id":40133341},{"atb":[[2.04,23.59]],"id":43189002},{"atl":[[11,0],[7.4,13.64]],"id":43189002},{"atb":[[2.8,7.75],[2.72,72.78],[3.6,4.82],[3.95,2.5],[3.55,10],[3.75,5]],"id":35701941},{"atl":[[44,1.86],[11.5,2.5],[13.5,5],[60,5.66],[15.5,10]],"id":35701941},{"atb":[[2.72,5.04],[2.88,11.65],[2.74,68.85],[2.9,4.09],[3.1,2.5],[2.96,5]],"id":28041476},{"atl":[[16.5,4.09],[8.6,2.5],[10.5,10],[30,11.4],[9.4,5]],"id":28041476},{"atb":[[1.7,30]],"id":36909459},{"atl":[[5.6,0],[5.1,20.33],[5.2,0]],"id":36909459},{"atb":[[1.07,47.28]],"id":37307439},{"atl":[[2.64,0],[3.3,18.75]],"id":37307439}],"con":true,"img":false}]}
{"op":"mcm","clk":"5322562431","pt":1646321779726,"mc":[{"id":"1.195532865","rc":[{"atb":[[2.14,10.43],[1.8,2.15],[1.82,50.63]],"id":40133341},{"atl":[[6.6,15.26],[8.4,3.14]],"id":40133341},{"atb":[[3.1,8.04]],"id":35701941},{"atb":[[2.86,1.99]],"id":28041476},{"atl":[[26,0]],"id":28041476},{"atb":[[1.45,1.99]],"id":37307439},{"atl":[[3,17.7]],"id":37307439}],"con":true,"img":false}]}
{"op":"mcm","clk":"5322562443","pt":1646321779818,"mc":[{"id":"1.195532865","rc":[{"atl":[[8.2,0]],"id":40133341},{"atb":[[3.55,15.31],[2.78,1.99]],"id":35701941},{"atl":[[46,2.73],[15.5,12]],"id":35701941},{"atb":[[2.9,8.08]],"id":28041476},{"atl":[[10.5,12]],"id":28041476},{"atb":[[1.62,52.9]],"id":36909459},{"atl":[[3.3,0]],"id":37307439}],"con":true,"img":false}]}
{"op":"mcm","clk":"5322562451","pt":1646321779926,"mc":[{"id":"1.195532865","rc":[{"atb":[[1.68,0],[1.72,2.15]],"id":43189002},{"atb":[[1.81,1.99]],"id":36909459}],"con":true,"img":false}]}
{"op":"mcm","clk":"5322562459","pt":1646321780021,"mc":[{"id":"1.195532865","rc":[{"atb":[[1.93,0]],"id":40133341},{"atl":[[8.4,0]],"id":40133341},{"atb":[[1.7,59.7]],"id":43189002},{"atb":[[2.8,1.65]],"id":35701941},{"atb":[[2.72,0]],"id":28041476},{"atb":[[1.57,0]],"id":36909459},{"atb":[[1.39,2.15]],"id":37307439}],"con":true,"img":false}]}
{"op":"mcm","clk":"5322562509","pt":1646321780512,"mc":[{"id":"1.195532865","rc":[{"atb":[[2.78,0]],"id":35701941}],"con":true,"img":false}]}
{"op":"mcm","clk":"5322562516","pt":1646321780618,"mc":[{"id":"1.195532865","rc":[{"atb":[[4,1.99]],"id":35701941}],"con":true,"img":false}]}
{"op":"mcm","clk":"5322562529","pt":1646321780825,"mc":[{"id":"1.195532865","rc":[{"atb":[[4,4.49],[3.55,10]],"id":35701941}],"con":true,"img":false}]}
{"op":"mcm","clk":"5322562543","pt":1646321781032,"mc":[{"id":"1.195532865","rc":[{"atb":[[1.81,0]],"id":40133341}],"con":true,"img":false}]}
{"op":"mcm","clk":"5322562550","pt":1646321781090,"mc":[{"id":"1.195532865","rc":[{"atb":[[2.36,1.99]],"id":40133341}],"con":true,"img":false}]}
{"op":"mcm","clk":"5322562563","pt":1646321781300,"mc":[{"id":"1.195532865","rc":[{"atb":[[2.86,0]],"id":28041476}],"con":true,"img":false}]}
{"op":"mcm","clk":"5322562570","pt":1646321781406,"mc":[{"id":"1.195532865","rc":[{"atb":[[3.15,1.99]],"id":28041476}],"con":true,"img":false}]}
{"op":"mcm","clk":"5322562583","pt":1646321781620,"mc":[{"id":"1.195532865","rc":[{"atb":[[2.14,5]],"id":40133341},{"atb":[[2.04,0]],"id":43189002},{"atb":[[3.1,0]],"id":35701941},{"atb":[[2.9,4.09],[3.15,4.49]],"id":28041476},{"atb":[[1.7,0]],"id":36909459}],"con":true,"img":false}]}
{"op":"mcm","clk":"5322562588","pt":1646321781725,"mc":[{"id":"1.195532865","rc":[{"atb":[[1.69,47.34]],"id":43189002}],"con":true,"img":false}]}
{"op":"mcm","clk":"5322562596","pt":1646321781831,"mc":[{"id":"1.195532865","rc":[{"atb":[[2.44,1.99]],"id":43189002}],"con":true,"img":false}]}
{"op":"mcm","clk":"5322562724","pt":1646321783294,"mc":[{"id":"1.195532865","rc":[{"atb":[[1.69,0]],"id":43189002},{"atb":[[1.62,0]],"id":36909459},{"atb":[[1.03,231.84]],"id":37307439}],"con":true,"img":false}]}
{"op":"mcm","clk":"5322562841","pt":1646321784835,"mc":[{"id":"1.195532865","rc":[{"atb":[[2.8,0]],"id":35701941},{"atb":[[2.88,10]],"id":28041476}],"con":true,"img":false}]}
{"op":"mcm","clk":"5322562859","pt":1646321784992,"mc":[{"id":"1.195532865","rc":[{"atb":[[2.38,1.65]],"id":40133341},{"atb":[[2.46,1.65]],"id":43189002},{"atb":[[4.1,1.65]],"id":35701941},{"atb":[[3.2,1.65]],"id":28041476}],"con":true,"img":false}]}
{"op":"mcm","clk":"5322562870","pt":1646321785200,"mc":[{"id":"1.195532865","rc":[{"atb":[[1.67,59.7]],"id":43189002}],"con":true,"img":false}]}
{"op":"mcm","clk":"5322563047","pt":1646321787611,"mc":[{"id":"1.195532865","rc":[{"atb":[[1.7,0],[2.1,59.7]],"id":43189002},{"atb":[[1.45,4.49]],"id":37307439}],"con":true,"img":false}]}
{"op":"mcm","clk":"5322563058","pt":1646321787717,"mc":[{"id":"1.195532865","rc":[{"atb":[[2.24,5.1]],"id":40133341},{"atb":[[1.63,0],[1.81,4.49],[1.74,49.33]],"id":36909459},{"atb":[[1.36,10],[1.37,6.73]],"id":37307439}],"con":true,"img":false}]}
{"op":"mcm","clk":"5322563066","pt":1646321787821,"mc":[{"id":"1.195532865","rc":[{"atb":[[1.4,10],[1.45,1.99]],"id":37307439}],"con":true,"img":false}]}
{"op":"mcm","clk":"5322563073","pt":1646321787926,"mc":[{"id":"1.195532865","rc":[{"atb":[[2.34,18.32],[1.82,0]],"id":40133341},{"atb":[[1.81,1.99],[1.77,60.67]],"id":36909459}],"con":true,"img":false}]}
{"op":"mcm","clk":"5322563333","pt":1646321791019,"mc":[{"id":"1.195532865","rc":[{"atb":[[2.4,2.15],[1.72,0]],"id":43189002},{"atb":[[1.83,2.15],[1.61,0]],"id":36909459}],"con":true,"img":false}]}
{"op":"mcm","clk":"5322563399","pt":1646321791918,"mc":[{"id":"1.195532865","rc":[{"atb":[[1.81,0]],"id":36909459}],"con":true,"img":false}]}
{"op":"mcm","clk":"5322563411","pt":1646321792021,"mc":[{"id":"1.195532865","rc":[{"atb":[[1.84,1.99]],"id":36909459}],"con":true,"img":false}]}
{"op":"mcm","clk":"5322563599","pt":1646321794226,"mc":[{"id":"1.195532865","rc":[{"atb":[[1.74,0]],"id":36909459}],"con":true,"img":false}]}
{"op":"mcm","clk":"5322563725","pt":1646321796014,"mc":[{"id":"1.195532865","rc":[{"atb":[[1.84,4.15],[1.77,2.5]],"id":36909459}],"con":true,"img":false}]}
{"op":"mcm","clk":"5322563760","pt":1646321796545,"mc":[{"id":"1.195532865","rc":[{"atb":[[2.22,0],[2.14,0],[2.34,5],[2.06,0],[1.77,129.87]],"id":40133341},{"atl":[[9,12.5],[5.5,0],[7.4,0],[6.6,5.26],[5.9,0]],"id":40133341},{"atb":[[2.26,0],[2.34,0],[2.24,0],[2.42,0]],"id":43189002},{"atl":[[7.4,3.64],[13,8.33],[6.6,0],[5.9,0],[8.4,0]],"id":43189002},{"atb":[[3.6,0],[2.72,58.14],[3.95,0],[3.55,0],[3.75,0]],"id":35701941},{"atl":[[44,0],[11.5,0],[13.5,0],[60,1.69],[15.5,2]],"id":35701941},{"atb":[[2.88,0],[2.9,0],[2.74,57.47],[3.1,0],[2.96,0]],"id":28041476},{"atl":[[16.5,0],[8.6,0],[10.5,2],[30,3.45],[9.4,0]],"id":28041476},{"atb":[[1.73,0],[1.8,0],[1.6,66.67],[1.77,0],[1.69,0]],"id":36909459},{"atl":[[4.3,0],[5.1,8.33],[6,20],[4.7,0]],"id":36909459},{"atb":[[1.03,0],[1.07,0]],"id":37307439},{"atl":[[3,0],[3.25,44.44]],"id":37307439}],"con":true,"img":false}]}
{"op":"mcm","clk":"5322563769","pt":1646321796644,"mc":[{"id":"1.195532865","rc":[{"atb":[[1.4,5],[1.36,0],[1.44,0]],"id":37307439},{"atl":[[3.35,63.83]],"id":37307439}],"con":true,"img":false}]}
{"op":"mcm","clk":"5322563780","pt":1646321796743,"mc":[{"id":"1.195532865","rc":[{"atl":[[8.2,12.5],[6.6,0]],"id":40133341},{"atl":[[11,8.33],[7.4,0]],"id":43189002},{"atl":[[46,4.95],[15.5,0]],"id":35701941},{"atl":[[10.5,0],[26,4]],"id":28041476},{"atl":[[5.6,20],[5.1,0]],"id":36909459},{"atb":[[1.4,0],[1.45,4.49]],"id":37307439}],"con":true,"img":false}]}
{"op":"mcm","clk":"5322563785","pt":1646321796846,"mc":[{"id":"1.195532865","rc":[{"atb":[[1.67,0],[2.44,0],[2.14,35.09]],"id":43189002},{"atl":[[12,0],[7.8,5.88]],"id":43189002},{"atb":[[3.4,16.67],[2.76,0]],"id":35701941},{"atl":[[16.5,2.58],[50,0]],"id":35701941},{"atl":[[11.5,3.81],[28,0]],"id":28041476}],"con":true,"img":false}]}
{"op":"mcm","clk":"5322563795","pt":1646321796950,"mc":[{"id":"1.195532865","rc":[{"atb":[[2.42,1.99]],"id":43189002},{"atl":[[46,2.73],[50,2.04]],"id":35701941}],"con":true,"img":false}]}
{"op":"mcm","clk":"5322563924","pt":1646321798446,"mc":[{"id":"1.195532865","rc":[{"atb":[[1.78,5.8]],"id":36909459}],"con":true,"img":false}]}
{"op":"mcm","clk":"5322564119","pt":1646321800436,"mc":[{"id":"1.195532865","rc":[{"atb":[[2.24,0]],"id":40133341},{"atb":[[1.37,0]],"id":37307439}],"con":true,"img":false}]}
{"op":"mcm","clk":"5322564307","pt":1646321802848,"mc":[{"id":"1.195532865","rc":[{"atb":[[2.46,0]],"id":43189002},{"atb":[[1.78,0]],"id":36909459}],"con":true,"img":false}]}
{"op":"mcm","clk":"5322564314","pt":1646321802952,"mc":[{"id":"1.195532865","rc":[{"atb":[[2.44,1.65]],"id":43189002}],"con":true,"img":false}]}
{"op":"mcm","clk":"5322564390","pt":1646321803854,"mc":[{"id":"1.195532865","rc":[{"atb":[[1.83,0],[1.63,2.15]],"id":36909459}],"con":true,"img":false}]}
{"op":"mcm","clk":"5322564477","pt":1646321805256,"mc":[{"id":"1.195532865","rc":[{"atb":[[1.8,18.92]],"id":40133341},{"atb":[[1.03,22.45]],"id":37307439}],"con":true,"img":false}]}
{"op":"mcm","clk":"5322564609","pt":1646321806841,"mc":[{"id":"1.195532865","rc":[{"atb":[[2.1,150.61]],"id":43189002},{"atl":[[8.2,5.56]],"id":43189002},{"atb":[[3.3,43.48]],"id":35701941},{"atl":[[16.5,0],[17.5,2.42]],"id":35701941},{"atl":[[11.5,0],[12.5,3.48]],"id":28041476}],"con":true,"img":false}]}
{"op":"mcm","clk":"5322564619","pt":1646321806947,"mc":[{"id":"1.195532865","rc":[{"atl":[[7.8,0]],"id":43189002}],"con":true,"img":false}]}
{"op":"mcm","clk":"5322564629","pt":1646321807052,"mc":[{"id":"1.195532865","rc":[{"atl":[[46,4.95],[50,0]],"id":35701941}],"con":true,"img":false}]}
{"op":"mcm","clk":"5322564662","pt":1646321807461,"mc":[{"id":"1.195532865","rc":[{"atb":[[1.61,12.85]],"id":36909459}],"con":true,"img":false}]}
{"op":"mcm","clk":"5322565373","pt":1646321816662,"mc":[{"id":"1.195532865","rc":[{"atb":[[2.1,90.91]],"id":43189002},{"atl":[[5.6,0]],"id":36909459}],"con":true,"img":false}]}
{"op":"mcm","clk":"5322565382","pt":1646321816778,"mc":[{"id":"1.195532865","rc":[{"atb":[[2.22,50.63],[1.93,12.82],[2.34,0]],"id":40133341},{"atl":[[9,25],[8.2,0]],"id":40133341},{"atb":[[1.96,104.17]],"id":43189002},{"atb":[[4,1.99],[3.9,34.48]],"id":35701941},{"atb":[[1.57,26.48]],"id":36909459},{"atl":[[6,40],[5.7,5.44]],"id":36909459},{"atb":[[1.41,22.45],[1.45,1.99],[1.05,278.86]],"id":37307439},{"atl":[[3.1,3.14],[3.25,88.88],[3.05,0]],"id":37307439}],"con":true,"img":false}]}
{"op":"mcm","clk":"5322565390","pt":1646321816887,"mc":[{"id":"1.195532865","rc":[{"atb":[[2.06,141.51],[1.7,9.65],[1.61,0]],"id":43189002},{"atl":[[8.6,5.26],[8.2,0]],"id":43189002},{"atb":[[2.8,7.1],[3.2,68.18],[2.64,0]],"id":35701941},{"atl":[[17.5,0],[18.5,2.29]],"id":35701941},{"atl":[[12.5,0],[13.5,3.2]],"id":28041476}],"con":true,"img":false}]}
{"op":"mcm","clk":"5322565399","pt":1646321816981,"mc":[{"id":"1.195532865","rc":[{"atb":[[2.32,5.73],[1.93,0]],"id":40133341},{"atl":[[8.4,3.47]],"id":40133341},{"atb":[[1.57,0]],"id":36909459},{"atb":[[1.05,250]],"id":37307439},{"atl":[[3.1,0]],"id":37307439}],"con":true,"img":false}]}
{"op":"mcm","clk":"5322565411","pt":1646321817086,"mc":[{"id":"1.195532865","rc":[{"atl":[[11,0],[12.5,8.7],[8.4,5.56]],"id":43189002},{"atl":[[26,0],[30,6.9]],"id":28041476}],"con":true,"img":false}]}
{"op":"mcm","clk":"5322565425","pt":1646321817203,"mc":[{"id":"1.195532865","rc":[{"atb":[[1.63,0]],"id":43189002},{"atb":[[2.68,0]],"id":35701941}],"con":true,"img":false}]}
{"op":"mcm","clk":"5322565440","pt":1646321817405,"mc":[{"id":"1.195532865","rc":[{"atb":[[1.7,0]],"id":43189002},{"atb":[[4,0],[2.8,0]],"id":35701941}],"con":true,"img":false}]}
{"op":"mcm","clk":"5322565452","pt":1646321817547,"mc":[{"id":"1.195532865","rc":[{"atb":[[3.95,1.99]],"id":35701941}],"con":true,"img":false}]}
{"op":"mcm","clk":"5322565476","pt":1646321817677,"mc":[{"id":"1.195532865","rc":[{"atb":[[2.36,0]],"id":40133341}],"con":true,"img":false}]}
{"op":"mcm","clk":"5322565484","pt":1646321817767,"mc":[{"id":"1.195532865","rc":[{"atb":[[2.34,1.99]],"id":40133341}],"con":true,"img":false}]}
{"op":"mcm","clk":"5322565493","pt":1646321817881,"mc":[{"id":"1.195532865","rc":[{"atb":[[2.4,0]],"id":43189002}],"con":true,"img":false}]}
{"op":"mcm","clk":"5322565506","pt":1646321817991,"mc":[{"id":"1.195532865","rc":[{"atb":[[2.2,2.15]],"id":43189002}],"con":true,"img":false}]}
{"op":"mcm","clk":"5322565518","pt":1646321818081,"mc":[{"id":"1.195532865","rc":[{"atb":[[2.32,0]],"id":40133341},{"atl":[[8.4,0]],"id":40133341},{"atl":[[8.4,0]],"id":43189002},{"atl":[[5.7,0]],"id":36909459},{"atb":[[1.45,0]],"id":37307439}],"con":true,"img":false}]}
{"op":"mcm","clk":"5322565529","pt":1646321818202,"mc":[{"id":"1.195532865","rc":[{"atb":[[1.42,1.99]],"id":37307439}],"con":true,"img":false}]}
{"op":"mcm","clk":"5322565626","pt":1646321819296,"mc":[{"id":"1.195532865","rc":[{"atb":[[2.34,0]],"id":40133341}],"con":true,"img":false}]}
{"op":"mcm","clk":"5322565635","pt":1646321819401,"mc":[{"id":"1.195532865","rc":[{"atb":[[2.24,1.99],[1.8,2.15]],"id":40133341},{"atb":[[1.03,0]],"id":37307439}],"con":true,"img":false}]}
{"op":"mcm","clk":"5322565670","pt":1646321819777,"mc":[{"id":"1.195532865","rc":[{"atb":[[2.42,0]],"id":43189002}],"con":true,"img":false}]}
{"op":"mcm","clk":"5322565678","pt":1646321819879,"mc":[{"id":"1.195532865","rc":[{"atb":[[2.22,1.99]],"id":43189002}],"con":true,"img":false}]}
{"op":"mcm","clk":"5322565751","pt":1646321820984,"mc":[{"id":"1.195532865","rc":[{"atb":[[2.38,0]],"id":40133341},{"atb":[[2.44,0]],"id":43189002},{"atb":[[4.1,0]],"id":35701941}],"con":true,"img":false}]}
{"op":"mcm","clk":"5322565767","pt":1646321821089,"mc":[{"id":"1.195532865","rc":[{"atb":[[2.26,1.65]],"id":40133341},{"atb":[[2.24,1.65]],"id":43189002},{"atb":[[4,1.65]],"id":35701941}],"con":true,"img":false}]}
{"op":"mcm","clk":"5322565785","pt":1646321821306,"mc":[{"id":"1.195532865","rc":[{"atb":[[3.85,5.35]],"id":35701941}],"con":true,"img":false}]}
{"op":"mcm","clk":"5322565826","pt":1646321821716,"mc":[{"id":"1.195532865","rc":[{"atb":[[3.85,0]],"id":35701941}],"con":true,"img":false}]}
{"op":"mcm","clk":"5322565856","pt":1646321821984,"mc":[{"id":"1.195532865","rc":[{"atl":[[6.4,46.3],[6,20]],"id":36909459},{"atl":[[3.35,106.38],[3.25,44.44]],"id":37307439}],"con":true,"img":false}]}
{"op":"mcm","clk":"5322565867","pt":1646321822099,"mc":[{"id":"1.195532865","rc":[{"atb":[[1.79,0],[2.22,83.42]],"id":40133341},{"atl":[[8.6,0],[9,17.5]],"id":40133341},{"atl":[[8.6,0],[9,5]],"id":43189002},{"atl":[[18.5,0],[19.5,2.16]],"id":35701941},{"atl":[[13.5,0],[14.5,2.96]],"id":28041476},{"atb":[[1.72,55.56],[1.6,0]],"id":36909459},{"atl":[[5.8,0],[6,8]],"id":36909459},{"atb":[[1.4,100]],"id":37307439},{"atl":[[3.15,0],[3.25,17.78]],"id":37307439}],"con":true,"img":false}]}
{"op":"mcm","clk":"5322566035","pt":1646321823826,"mc":[{"id":"1.195532865","rc":[{"atb":[[2.16,4.01]],"id":43189002},{"atb":[[1.03,112.4]],"id":37307439}],"con":true,"img":false}]}
{"op":"mcm","clk":"5322566167","pt":1646321825318,"mc":[{"id":"1.195532865","rc":[{"atl":[[9,12.5],[9.4,4.76]],"id":40133341},{"atl":[[9,0],[9.4,4.76]],"id":43189002},{"atl":[[19.5,0],[21,2]],"id":35701941},{"atl":[[6.4,25.93],[6,0]],"id":36909459}],"con":true,"img":false}]}
{"op":"mcm","clk":"5322566214","pt":1646321825998,"mc":[{"id":"1.195532865","rc":[{"atb":[[1.61,0]],"id":36909459}],"con":true,"img":false}]}
{"op":"mcm","clk":"5322566362","pt":1646321828101,"mc":[{"id":"1.195532865","rc":[{"atb":[[1.03,0]],"id":37307439}],"con":true,"img":false}]}
{"op":"mcm","clk":"5322566542","pt":1646321830293,"mc":[{"id":"1.195532865","rc":[{"atb":[[1.59,13.68]],"id":36909459}],"con":true,"img":false}]}
{"op":"mcm","clk":"5322566665","pt":1646321832116,"mc":[{"id":"1.195532865","rc":[{"atl":[[15.5,6.9]],"id":28041476},{"atb":[[1.38,250]],"id":37307439},{"atl":[[3.35,59.57],[3.4,8.51],[3.25,0]],"id":37307439}],"con":true,"img":false}]}
{"op":"mcm","clk":"5322566676","pt":1646321832221,"mc":[{"id":"1.195532865","rc":[{"atl":[[3.4,6.38]],"id":37307439}],"con":true,"img":false}]}
{"op":"mcm","clk":"5322566704","pt":1646321832589,"mc":[{"id":"1.195532865","rc":[{"atl":[[3.4,0]],"id":37307439}],"con":true,"img":false}]}
{"op":"mcm","clk":"5322566737","pt":1646321832934,"mc":[{"id":"1.195532865","rc":[{"atb":[[1.06,105.08]],"id":37307439}],"con":true,"img":false}]}
{"op":"mcm","clk":"5322566744","pt":1646321832985,"mc":[{"id":"1.195532865","rc":[{"atb":[[1.39,0]],"id":37307439}],"con":true,"img":false}]}
{"op":"mcm","clk":"5322566760","pt":1646321833096,"mc":[{"id":"1.195532865","rc":[{"atb":[[1.44,2.15]],"id":37307439}],"con":true,"img":false}]}
{"op":"mcm","clk":"5322566912","pt":1646321835296,"mc":[{"id":"1.195532865","rc":[{"atb":[[2.18,84.75]],"id":40133341},{"atl":[[9.8,11.36]],"id":40133341},{"atb":[[2.02,245.1]],"id":43189002},{"atl":[[9.8,4.55],[9.4,0]],"id":43189002},{"atb":[[3.1,119.05]],"id":35701941},{"atl":[[21,0],[23,1.82]],"id":35701941},{"atb":[[1.7,142.86]],"id":36909459},{"atl":[[6.4,18.52],[6.8,6.9]],"id":36909459},{"atb":[[1.42,0]],"id":37307439}],"con":true,"img":false}]}
{"op":"mcm","clk":"5322566926","pt":1646321835411,"mc":[{"id":"1.195532865","rc":[{"atl":[[9.6,8.33],[12.5,0]],"id":43189002},{"atl":[[23,3.82],[46,2.73]],"id":35701941},{"atb":[[1.45,1.99]],"id":37307439}],"con":true,"img":false}]}
{"op":"mcm","clk":"5322566942","pt":1646321835619,"mc":[{"id":"1.195532865","rc":[{"atl":[[9.6,0],[12.5,8.7]],"id":43189002},{"atl":[[44,2.33],[23,1.82]],"id":35701941}],"con":true,"img":false}]}
{"op":"mcm","clk":"5322567043","pt":1646321837002,"mc":[{"id":"1.195532865","rc":[{"atb":[[1.06,0]],"id":37307439}],"con":true,"img":false}]}
{"op":"mcm","clk":"5322567187","pt":1646321839030,"mc":[{"id":"1.195532865","rc":[{"atb":[[1.59,0]],"id":36909459}],"con":true,"img":false}]}
{"op":"mcm","clk":"5322567259","pt":1646321840038,"mc":[{"id":"1.195532865","rc":[{"atb":[[1.73,0]],"id":40133341},{"spn":5.63,"spf":"NaN","id":40133341},{"atb":[[1.65,0]],"id":43189002},{"atl":[[10.5,4.21],[9.8,0]],"id":43189002},{"spn":6.37,"spf":"NaN","id":43189002},{"atb":[[2.72,0]],"id":35701941},{"atl":[[23,0],[25,1.67]],"id":35701941},{"spn":3.92,"spf":1.0,"id":35701941},{"atl":[[34,0],[38,0],[14.5,0],[30,3.45],[15.5,2.76]],"id":28041476},{"spn":9.35,"spf":"NaN","id":28041476},{"atb":[[1.54,0]],"id":36909459},{"atl":[[6.6,5.56]],"id":36909459},{"spn":1.84,"spf":1.0,"id":36909459},{"atb":[[1.4,0],[1.43,93.02]],"id":37307439},{"atl":[[3.45,16.33],[3.35,42.55]],"id":37307439},{"spn":2.4,"spf":"NaN","id":37307439}],"con":true,"img":false}]}
{"op":"mcm","clk":"5322567271","pt":1646321840212,"mc":[{"id":"1.195532865","rc":[{"atl":[[10.5,13.31],[12.5,0]],"id":43189002},{"atl":[[6.6,0]],"id":36909459}],"con":true,"img":false}]}
{"op":"mcm","clk":"5322567344","pt":1646321841419,"mc":[{"id":"1.195532865","rc":[{"atb":[[1.45,4.89]],"id":37307439}],"con":true,"img":false}]}
{"op":"mcm","clk":"5322567518","pt":1646321843620,"mc":[{"id":"1.195532865","rc":[{"atb":[[1.73,7.88]],"id":36909459}],"con":true,"img":false}]}
{"op":"mcm","clk":"5322567593","pt":1646321844622,"mc":[{"id":"1.195532865","rc":[{"atl":[[10.5,9.1],[11.5,3.81]],"id":43189002}],"con":true,"img":false}]}
{"op":"mcm","clk":"5322567600","pt":1646321844723,"mc":[{"id":"1.195532865","rc":[{"atb":[[1.63,0],[1.76,2.15]],"id":36909459}],"con":true,"img":false}]}
{"op":"mcm","clk":"5322567652","pt":1646321845305,"mc":[{"id":"1.195532865","rc":[{"atb":[[2.14,131.58]],"id":40133341},{"atl":[[10.5,15.79]],"id":40133341},{"atb":[[1.68,220.59]],"id":36909459},{"atl":[[7.2,16.13]],"id":36909459}],"con":true,"img":false}]}
{"op":"mcm","clk":"5322567662","pt":1646321845411,"mc":[{"id":"1.195532865","rc":[{"atl":[[10.5,0],[12.5,8.7]],"id":43189002}],"con":true,"img":false}]}
{"op":"mcm","clk":"5322567993","pt":1646321850031,"mc":[{"id":"1.195532865","rc":[{"atl":[[27,3.85]],"id":35701941},{"atl":[[16.5,6.45]],"id":28041476},{"atb":[[1.41,266.35],[1.02,0],[1.38,0]],"id":37307439},{"atl":[[3.55,39.22]],"id":37307439}],"con":true,"img":false}]}
{"op":"mcm","clk":"5322568020","pt":1646321850351,"mc":[{"id":"1.195532865","rc":[{"atb":[[1.62,18.48]],"id":36909459}],"con":true,"img":false}]}
{"op":"mcm","clk":"5322568047","pt":1646321850758,"mc":[{"id":"1.195532865","rc":[{"atb":[[1.62,0]],"id":36909459}],"con":true,"img":false}]}
{"op":"mcm","clk":"5322568070","pt":1646321851034,"mc":[{"id":"1.195532865","rc":[{"atb":[[3.15,5.4]],"id":35701941}],"con":true,"img":false}]}
{"op":"mcm","clk":"5322568085","pt":1646321851247,"mc":[{"id":"1.195532865","rc":[{"atb":[[3.15,0]],"id":35701941}],"con":true,"img":false}]}
{"op":"mcm","clk":"5322568365","pt":1646321854657,"mc":[{"id":"1.195532865","rc":[{"atl":[[11.5,0],[12.5,12.18]],"id":43189002}],"con":true,"img":false}]}
{"op":"mcm","clk":"5322568379","pt":1646321854860,"mc":[{"id":"1.195532865","rc":[{"atl":[[12,3.81]],"id":43189002}],"con":true,"img":false}]}
{"op":"mcm","clk":"5322568410","pt":1646321855241,"mc":[{"id":"1.195532865","rc":[{"atl":[[12,0]],"id":43189002}],"con":true,"img":false}]}
{"op":"mcm","clk":"5322568420","pt":1646321855346,"mc":[{"id":"1.195532865","rc":[{"atb":[[1.75,0],[2.1,227.27]],"id":40133341},{"atl":[[11.5,23.81]],"id":40133341},{"atb":[[1.56,0],[1.66,250]],"id":36909459},{"atl":[[7.6,22.73]],"id":36909459}],"con":true,"img":false}]}
{"op":"mcm","clk":"5322568427","pt":1646321855449,"mc":[{"id":"1.195532865","rc":[{"atb":[[1.8,0]],"id":40133341}],"con":true,"img":false}]}
{"op":"mcm","clk":"5322568438","pt":1646321855547,"mc":[{"id":"1.195532865","rc":[{"atb":[[2.28,2.15]],"id":40133341}],"con":true,"img":false}]}
{"op":"mcm","clk":"5322568523","pt":1646321856555,"mc":[{"id":"1.195532865","rc":[{"atb":[[2.24,0]],"id":40133341}],"con":true,"img":false}]}
{"op":"mcm","clk":"5322568532","pt":1646321856650,"mc":[{"id":"1.195532865","rc":[{"atb":[[2.3,1.99]],"id":40133341}],"con":true,"img":false}]}
{"op":"mcm","clk":"5322568796","pt":1646321860071,"mc":[{"id":"1.195532865","rc":[{"atl":[[70,0],[80,0],[25,0],[27,1.54],[60,0]],"id":35701941},{"atl":[[16.5,2.58],[15.5,0]],"id":28041476},{"atb":[[1.39,250],[1.04,69.44]],"id":37307439},{"atl":[[3.65,56.6]],"id":37307439}],"con":true,"img":false}]}
{"op":"mcm","clk":"5322568812","pt":1646321860245,"mc":[{"id":"1.195532865","rc":[{"atl":[[16,3.45]],"id":28041476}],"con":true,"img":false}]}
{"op":"mcm","clk":"5322568830","pt":1646321860456,"mc":[{"id":"1.195532865","rc":[{"atb":[[1.04,0]],"id":37307439}],"con":true,"img":false}]}
{"op":"mcm","clk":"5322568859","pt":1646321860853,"mc":[{"id":"1.195532865","rc":[{"atb":[[2.26,0]],"id":40133341}],"con":true,"img":false}]}
{"op":"mcm","clk":"5322568865","pt":1646321860957,"mc":[{"id":"1.195532865","rc":[{"atb":[[2.32,1.65]],"id":40133341}],"con":true,"img":false}]}
{"op":"mcm","clk":"5322568912","pt":1646321861654,"mc":[{"id":"1.195532865","rc":[{"atl":[[16,0]],"id":28041476}],"con":true,"img":false}]}
{"op":"mcm","clk":"5322569158","pt":1646321864672,"mc":[{"id":"1.195532865","rc":[{"atl":[[12.5,8.7],[13.5,3.2]],"id":43189002}],"con":true,"img":false}]}
{"op":"mcm","clk":"5322569226","pt":1646321865343,"mc":[{"id":"1.195532865","rc":[{"atb":[[2.22,54.66],[2.26,31.75]],"id":40133341},{"atb":[[1.58,0]],"id":36909459},{"atl":[[8,35.71]],"id":36909459}],"con":true,"img":false}]}
{"op":"mcm","clk":"5322569235","pt":1646321865452,"mc":[{"id":"1.195532865","rc":[{"atb":[[2.22,50.63]],"id":40133341}],"con":true,"img":false}]}
{"op":"mcm","clk":"5322569630","pt":1646321870079,"mc":[{"id":"1.195532865","rc":[{"atl":[[27,0],[29,1.43]],"id":35701941},{"atl":[[16.5,0],[17.5,2.42]],"id":28041476},{"atb":[[1.01,4804.04],[1.37,250]],"id":37307439},{"atl":[[3.75,90.91]],"id":37307439}],"con":true,"img":false}]}
{"op":"mcm","clk":"5322569642","pt":1646321870205,"mc":[{"id":"1.195532865","rc":[{"atl":[[17.5,7.58],[30,0]],"id":28041476}],"con":true,"img":false}]}
{"op":"mcm","clk":"5322569650","pt":1646321870260,"mc":[{"id":"1.195532865","rc":[{"atl":[[17.5,2.42],[30,3.45]],"id":28041476}],"con":true,"img":false}]}
{"op":"mcm","clk":"5322569943","pt":1646321874049,"mc":[{"id":"1.195532865","rc":[{"spl":[[1.01,12.5]],"id":35701941}],"con":true,"img":false}]}
{"op":"mcm","clk":"5322569988","pt":1646321874679,"mc":[{"id":"1.195532865","rc":[{"atl":[[13,0],[14.5,7.41]],"id":43189002}],"con":true,"img":false}]}
{"op":"mcm","clk":"5322570046","pt":1646321875402,"mc":[{"id":"1.195532865","rc":[{"atb":[[2.22,132.6],[1.77,0]],"id":40133341}],"con":true,"img":false}]}
{"op":"mcm","clk":"5322570395","pt":1646321880085,"mc":[{"id":"1.195532865","rc":[{"atl":[[32,1.29],[29,0]],"id":35701941},{"atl":[[17.5,0],[18.5,2.29]],"id":28041476},{"atb":[[1.05,0]],"id":37307439}],"con":true,"img":false}]}
{"op":"mcm","clk":"5322570436","pt":1646321880615,"mc":[{"id":"1.195532865","rc":[{"atl":[[3.5,7.75]],"id":37307439}],"con":true,"img":false}]}
{"op":"mcm","clk":"5322570449","pt":1646321880713,"mc":[{"id":"1.195532865","rc":[{"atb":[[3.85,4.87]],"id":35701941},{"atb":[[2.72,7.74],[3.1,3.62]],"id":28041476},{"atb":[[1.75,13.47]],"id":36909459}],"con":true,"img":false}]}
{"op":"mcm","clk":"5322570461","pt":1646321880827,"mc":[{"id":"1.195532865","rc":[{"atb":[[3.1,0]],"id":28041476},{"atl":[[3.5,0]],"id":37307439}],"con":true,"img":false}]}
{"op":"mcm","clk":"5322570468","pt":1646321880897,"mc":[{"id":"1.195532865","rc":[{"atb":[[3.85,0]],"id":35701941}],"con":true,"img":false}]}
{"op":"mcm","clk":"5322570483","pt":1646321881099,"mc":[{"id":"1.195532865","rc":[{"atb":[[1.75,0]],"id":36909459}],"con":true,"img":false}]}
{"op":"mcm","clk":"5322570491","pt":1646321881214,"mc":[{"id":"1.195532865","rc":[{"atb":[[2.72,0]],"id":28041476}],"con":true,"img":false}]}
{"op":"mcm","clk":"5322570607","pt":1646321882417,"mc":[{"id":"1.195532865","rc":[{"atb":[[2.1,0]],"id":40133341},{"atl":[[32,0],[36,1.14]],"id":35701941},{"atl":[[18.5,0],[19.5,2.16]],"id":28041476}],"con":true,"img":false}]}
{"op":"mcm","clk":"5322570653","pt":1646321882901,"mc":[{"id":"1.195532865","rc":[{"atb":[[1.73,0]],"id":36909459}],"con":true,"img":false}]}
{"op":"mcm","clk":"5322570806","pt":1646321884710,"mc":[{"id":"1.195532865","rc":[{"atl":[[15.5,10.34]],"id":43189002}],"con":true,"img":false}]}
{"op":"mcm","clk":"5322570813","pt":1646321884814,"mc":[{"id":"1.195532865","rc":[{"atl":[[36,0]],"id":35701941},{"atl":[[19.5,0],[21,2]],"id":28041476}],"con":true,"img":false}]}
{"op":"mcm","clk":"5322570822","pt":1646321884910,"mc":[{"id":"1.195532865","rc":[{"atl":[[40,1.03]],"id":35701941}],"con":true,"img":false}]}
{"op":"mcm","clk":"5322570828","pt":1646321885020,"mc":[{"id":"1.195532865","rc":[{"atl":[[44,0],[46,4.95]],"id":35701941}],"con":true,"img":false}]}
{"op":"mcm","clk":"5322570836","pt":1646321885119,"mc":[{"id":"1.195532865","rc":[{"atb":[[1.71,28.79]],"id":36909459}],"con":true,"img":false}]}
{"op":"mcm","clk":"5322570850","pt":1646321885296,"mc":[{"id":"1.195532865","rc":[{"atb":[[1.71,0]],"id":36909459}],"con":true,"img":false}]}
{"op":"mcm","clk":"5322570856","pt":1646321885388,"mc":[{"id":"1.195532865","rc":[{"atb":[[2.18,127.12]],"id":40133341}],"con":true,"img":false}]}
{"op":"mcm","clk":"5322570878","pt":1646321885697,"mc":[{"id":"1.195532865","rc":[{"atl":[[14,0],[15,0]],"id":43189002},{"atl":[[40,0],[44,1]],"id":35701941}],"con":true,"img":false}]}
{"op":"mcm","clk":"5322570919","pt":1646321886261,"mc":[{"id":"1.195532865","rc":[{"atl":[[14.5,12.6]],"id":43189002}],"con":true,"img":false}]}
{"op":"mcm","clk":"5322570936","pt":1646321886403,"mc":[{"id":"1.195532865","rc":[{"atl":[[14.5,7.41],[15,3.16]],"id":43189002}],"con":true,"img":false}]}
{"op":"mcm","clk":"5322570964","pt":1646321886812,"mc":[{"id":"1.195532865","rc":[{"atl":[[15,0]],"id":43189002}],"con":true,"img":false}]}
{"op":"mcm","clk":"5322570979","pt":1646321887015,"mc":[{"id":"1.195532865","rc":[{"atb":[[1.73,7.88]],"id":36909459}],"con":true,"img":false}]}
{"op":"mcm","clk":"5322571733","pt":1646321895632,"mc":[{"id":"1.195532865","rc":[{"atl":[[16.5,16.13]],"id":43189002}],"con":true,"img":false}]}
{"op":"mcm","clk":"5322571742","pt":1646321895736,"mc":[{"id":"1.195532865","rc":[{"atl":[[23,4.55]],"id":28041476}],"con":true,"img":false}]}
{"op":"mcm","clk":"5322571799","pt":1646321896328,"mc":[{"id":"1.195532865","rc":[{"atb":[[2.14,219.3]],"id":40133341}],"con":true,"img":false}]}
{"op":"mcm","clk":"5322571828","pt":1646321896633,"mc":[{"id":"1.195532865","rc":[{"atl":[[48,2.13]],"id":35701941}],"con":true,"img":false}]}
{"op":"mcm","clk":"5322572121","pt":1646321900222,"mc":[{"id":"1.195532865","rc":[{"spn":5.66,"spf":"NaN","id":40133341},{"spn":7.37,"spf":"NaN","id":43189002},{"atl":[[44,0],[48,1]],"id":35701941},{"spn":3.92,"spf":1.0,"id":35701941},{"atl":[[21,0],[23,1.82]],"id":28041476},{"spn":13.1,"spf":"NaN","id":28041476}],"con":true,"img":false}]}
{"op":"mcm","clk":"5322572840","pt":1646321909827,"mc":[{"id":"1.195532865","rc":[{"atl":[[48,0],[50,1]],"id":35701941},{"atl":[[23,0],[25,1.67]],"id":28041476}],"con":true,"img":false}]}
{"op":"mcm","clk":"5322572852","pt":1646321910037,"mc":[{"id":"1.195532865","rc":[{"atl":[[25,0],[27,1.54]],"id":28041476}],"con":true,"img":false}]}
{"op":"mcm","clk":"5322572921","pt":1646321911034,"mc":[{"id":"1.195532865","rc":[{"atl":[[27,0],[29,1.43]],"id":28041476}],"con":true,"img":false}]}
{"op":"mcm","clk":"5322572988","pt":1646321911824,"mc":[{"id":"1.195532865","rc":[{"atb":[[1.08,50]],"id":40133341},{"atb":[[1.08,50]],"id":43189002},{"atb":[[1.08,50]],"id":35701941},{"atb":[[1.08,50]],"id":28041476},{"atb":[[1.08,50]],"id":36909459},{"atb":[[1.08,50]],"id":37307439}],"con":true,"img":false}]}
{"op":"mcm","clk":"5322573234","pt":1646321915032,"mc":[{"id":"1.195532865","rc":[{"atb":[[1.69,18.48]],"id":36909459}],"con":true,"img":false}]}
{"op":"mcm","clk":"5322573283","pt":1646321915616,"mc":[{"id":"1.195532865","rc":[{"atb":[[1.69,0]],"id":36909459}],"con":true,"img":false}]}
{"op":"mcm","clk":"5322573505","pt":1646321918439,"mc":[{"id":"1.195532865","rc":[{"atl":[[32,1.29],[29,0]],"id":28041476}],"con":true,"img":false}]}
{"op":"mcm","clk":"5322573548","pt":1646321918925,"mc":[{"id":"1.195532865","rc":[{"atl":[[32,0],[34,1.21]],"id":28041476}],"con":true,"img":false}]}
{"op":"mcm","clk":"5322573662","pt":1646321920344,"mc":[{"id":"1.195532865","rc":[{"atl":[[60,1.69]],"id":35701941}],"con":true,"img":false}]}
{"op":"mcm","clk":"5322573896","pt":1646321923158,"mc":[{"id":"1.195532865","rc":[{"atb":[[2.32,3.65],[2.3,7.18],[2.22,81.97],[2.26,54.4]],"id":40133341},{"atl":[[9,0],[9.2,3.12],[8.4,11.36],[6.2,5],[7.6,3.29],[9.8,43.6],[5.7,2.5],[8.8,5.19],[7,10]],"id":40133341},{"atb":[[2.3,10],[2.22,6.01],[2.12,89.29],[1.96,0],[2.38,5],[2.46,2.5],[2.16,13.58]],"id":43189002},{"atl":[[7.2,10],[6.4,5],[5.8,2.5],[11,7.41],[12,4.02],[12.5,0],[14.5,22.73]],"id":43189002},{"atb":[[4,6.41],[3.85,5],[4.1,2.5],[3.4,27.43],[3.9,0],[3.65,10]],"id":35701941},{"atl":[[16,10],[44,1.86],[12,2.5],[14,5],[60,7.37]],"id":35701941},{"atb":[[2.74,71.97],[3.1,47.62],[3.15,5.82]],"id":28041476},{"atl":[[8.6,10],[46,10.14],[23,2.74],[7,2.5],[7.8,5],[29,2.86],[30,0]],"id":28041476},{"atb":[[1.73,26.36],[1.82,2.5],[1.84,15.23],[1.74,10],[1.78,5]],"id":36909459},{"atl":[[5.6,16.13],[7.2,45.69],[4.3,2.5],[5.1,10],[6.4,0],[6.2,11.08],[6.6,4.63],[4.7,5]],"id":36909459},{"atb":[[1.41,243.9],[1.46,9.89],[1.45,46.55],[1.43,162.46],[1.5,2.5],[1.42,10]],"id":37307439},{"atl":[[3.6,5],[3.2,39.22],[3.35,0],[3.4,13.14],[3.55,135.37],[3.3,34.78]],"id":37307439}],"con":true,"img":false}]}
{"op":"mcm","clk":"5322573904","pt":1646321923258,"mc":[{"id":"1.195532865","rc":[{"atb":[[2.22,90.62]],"id":40133341},{"atl":[[8.6,3.33]],"id":43189002},{"atb":[[3.35,4.6]],"id":35701941},{"atl":[[6.4,4.81]],"id":36909459},{"atb":[[1.4,51.71]],"id":37307439},{"atl":[[2.74,7.88]],"id":37307439}],"con":true,"img":false}]}
{"op":"mcm","clk":"5322573914","pt":1646321923358,"mc":[{"id":"1.195532865","rc":[{"atl":[[5.9,8.16],[9.4,0]],"id":40133341},{"atl":[[6,8],[13.5,0]],"id":43189002},{"atl":[[46,2.73],[12,7.5],[13,3.33]],"id":35701941},{"atb":[[2.72,10.74]],"id":28041476},{"atl":[[7.4,6.25]],"id":28041476},{"atb":[[1.84,13.07],[1.76,10.45]],"id":36909459},{"atl":[[6.8,0],[4.5,11.43],[6.6,4.13]],"id":36909459}],"con":true,"img":false}]}
{"op":"mcm","clk":"5322573919","pt":1646321923457,"mc":[{"id":"1.195532865","rc":[{"atl":[[9.2,0]],"id":40133341},{"atl":[[13,6.52]],"id":43189002},{"atb":[[3.95,0]],"id":35701941},{"atb":[[1.72,59.5]],"id":36909459},{"atl":[[6.6,0]],"id":36909459},{"atl":[[3.4,2.5]],"id":37307439}],"con":true,"img":false}]}
{"op":"mcm","clk":"5322573926","pt":1646321923562,"mc":[{"id":"1.195532865","rc":[{"atb":[[4.2,1.99]],"id":35701941},{"atl":[[12,2.5],[14,12.69]],"id":35701941},{"atb":[[1.78,20.57],[1.76,2.15]],"id":36909459}],"con":true,"img":false}]}
{"op":"mcm","clk":"5322573937","pt":1646321923675,"mc":[{"id":"1.195532865","rc":[{"atb":[[2.22,81.97]],"id":40133341},{"atl":[[7.6,0]],"id":40133341},{"atl":[[8.6,0],[6.2,3.42]],"id":43189002},{"atb":[[3.35,0]],"id":35701941},{"atb":[[2.72,0]],"id":28041476},{"atl":[[6.4,0]],"id":36909459},{"atb":[[1.4,0]],"id":37307439},{"atl":[[2.72,9.08],[2.74,0]],"id":37307439}],"con":true,"img":false}]}
{"op":"mcm","clk":"5322573944","pt":1646321923732,"mc":[{"id":"1.195532865","rc":[{"atb":[[2.3,5.19]],"id":40133341},{"atl":[[13,0]],"id":43189002},{"atb":[[1.72,55.56]],"id":36909459}],"con":true,"img":false}]}
{"op":"mcm","clk":"5322573955","pt":1646321923837,"mc":[{"id":"1.195532865","rc":[{"atb":[[2.34,1.99]],"id":40133341}],"con":true,"img":false}]}
{"op":"mcm","clk":"5322573972","pt":1646321924048,"mc":[{"id":"1.195532865","rc":[{"atb":[[2.22,4.02]],"id":43189002},{"atb":[[1.43,69.44],[1.48,83.33]],"id":37307439},{"atl":[[3.45,0],[2.76,22.73]],"id":37307439}],"con":true,"img":false}]}
{"op":"mcm","clk":"5322573977","pt":1646321924153,"mc":[{"id":"1.195532865","rc":[{"atb":[[2.48,1.99]],"id":43189002}],"con":true,"img":false}]}
{"op":"mcm","clk":"5322573993","pt":1646321924354,"mc":[{"id":"1.195532865","rc":[{"atb":[[2.36,2.15],[2.28,0]],"id":40133341},{"atb":[[2.36,2.15],[2.2,0]],"id":43189002},{"atb":[[1.87,2.15],[1.76,0]],"id":36909459},{"atb":[[1.44,0],[1.51,2.15]],"id":37307439}],"con":true,"img":false}]}
{"op":"mcm","clk":"5322574000","pt":1646321924462,"mc":[{"id":"1.195532865","rc":[{"atb":[[1.45,44.56]],"id":37307439}],"con":true,"img":false}]}
{"op":"mcm","clk":"5322574008","pt":1646321924570,"mc":[{"id":"1.195532865","rc":[{"atb":[[1.51,4.14]],"id":37307439}],"con":true,"img":false}]}
{"op":"mcm","clk":"5322574047","pt":1646321925048,"mc":[{"id":"1.195532865","rc":[{"atl":[[6.2,0]],"id":43189002}],"con":true,"img":false}]}
{"op":"mcm","clk":"5322574177","pt":1646321925682,"mc":[{"id":"1.195532865","rc":[{"atb":[[2.34,0]],"id":40133341},{"atb":[[2.16,9.57]],"id":43189002},{"atb":[[1.73,18.48]],"id":36909459},{"atb":[[1.45,41.66]],"id":37307439}],"con":true,"img":false}]}
{"op":"mcm","clk":"5322574196","pt":1646321925737,"mc":[{"id":"1.195532865","rc":[{"atb":[[2.38,1.99]],"id":40133341}],"con":true,"img":false}]}
{"op":"mcm","clk":"5322574219","pt":1646321926020,"mc":[{"id":"1.195532865","rc":[{"atb":[[1.84,11.08]],"id":36909459}],"con":true,"img":false}]}
{"op":"mcm","clk":"5322574230","pt":1646321926328,"mc":[{"id":"1.195532865","rc":[{"atb":[[1.88,1.99]],"id":36909459}],"con":true,"img":false}]}
{"op":"mcm","clk":"5322574236","pt":1646321926391,"mc":[{"id":"1.195532865","rc":[{"atl":[[6,11.54]],"id":43189002}],"con":true,"img":false}]}
{"op":"mcm","clk":"5322574284","pt":1646321926746,"mc":[{"id":"1.195532865","rc":[{"atb":[[1.49,81.63]],"id":37307439}],"con":true,"img":false}]}
{"op":"mcm","clk":"5322574293","pt":1646321926772,"mc":[{"id":"1.195532865","rc":[{"atb":[[1.48,0]],"id":37307439}],"con":true,"img":false}]}
{"op":"mcm","clk":"5322574405","pt":1646321928040,"mc":[{"id":"1.195532865","rc":[{"atl":[[2.72,0]],"id":37307439}],"con":true,"img":false}]}
{"op":"mcm","clk":"5322574417","pt":1646321928142,"mc":[{"id":"1.195532865","rc":[{"atb":[[2.16,0]],"id":43189002}],"con":true,"img":false}]}
{"op":"mcm","clk":"5322574528","pt":1646321929238,"mc":[{"id":"1.195532865","rc":[{"atl":[[2.8,22.22],[2.76,0]],"id":37307439}],"con":true,"img":false}]}
{"op":"mcm","clk":"5322574583","pt":1646321929770,"mc":[{"id":"1.195532865","rc":[{"atb":[[2.28,5.94]],"id":40133341}],"con":true,"img":false}]}
{"op":"mcm","clk":"5322574595","pt":1646321929881,"mc":[{"id":"1.195532865","rc":[{"atb":[[2.32,0],[2.34,5.19]],"id":40133341},{"atl":[[6.2,15.66],[8.4,0]],"id":40133341},{"atb":[[2.24,0]],"id":43189002},{"atl":[[11,0]],"id":43189002},{"atb":[[4,2.76],[4.2,4.49]],"id":35701941},{"atl":[[23,0],[7.8,13.75]],"id":28041476},{"atl":[[5.6,0],[4.7,18.93]],"id":36909459},{"atb":[[1.46,5]],"id":37307439}],"con":true,"img":false}]}
{"op":"mcm","clk":"5322574604","pt":1646321929979,"mc":[{"id":"1.195532865","rc":[{"atl":[[5.9,10]],"id":43189002},{"atb":[[1.5,12.39]],"id":37307439}],"con":true,"img":false}]}
{"op":"mcm","clk":"5322574610","pt":1646321930036,"mc":[{"id":"1.195532865","rc":[{"atb":[[2.4,1.65],[2.28,0]],"id":40133341},{"atb":[[2.5,1.65]],"id":43189002},{"atb":[[4.3,1.65]],"id":35701941},{"atl":[[2.8,0],[2.84,21.74]],"id":37307439}],"con":true,"img":false}]}
{"op":"mcm","clk":"5322574619","pt":1646321930143,"mc":[{"id":"1.195532865","rc":[{"atl":[[2.82,34.78]],"id":37307439}],"con":true,"img":false}]}
{"op":"mcm","clk":"5322574626","pt":1646321930246,"mc":[{"id":"1.195532865","rc":[{"atb":[[1.78,5],[1.88,4.15]],"id":36909459},{"atl":[[3.2,0],[2.84,56.52]],"id":37307439}],"con":true,"img":false}]}
{"op":"mcm","clk":"5322574634","pt":1646321930351,"mc":[{"id":"1.195532865","rc":[{"atl":[[2.82,0]],"id":37307439}],"con":true,"img":false}]}
{"op":"mcm","clk":"5322574643","pt":1646321930456,"mc":[{"id":"1.195532865","rc":[{"atb":[[2.38,4.89]],"id":40133341},{"atb":[[1.85,4.14]],"id":36909459},{"atb":[[1.52,2.9]],"id":37307439}],"con":true,"img":false}]}
{"op":"mcm","clk":"5322574679","pt":1646321930871,"mc":[{"id":"1.195532865","rc":[{"atb":[[1.5,92.39],[1.49,0]],"id":37307439},{"atl":[[2.88,21.28],[2.84,34.78]],"id":37307439}],"con":true,"img":false}]}
{"op":"mcm","clk":"5322574756","pt":1646321931769,"mc":[{"id":"1.195532865","rc":[{"atb":[[1.51,2.15]],"id":37307439}],"con":true,"img":false}]}
{"op":"mcm","clk":"5322574766","pt":1646321931868,"mc":[{"id":"1.195532865","rc":[{"atb":[[1.53,1.99]],"id":37307439}],"con":true,"img":false}]}
{"op":"mcm","clk":"5322574828","pt":1646321932558,"mc":[{"id":"1.195532865","rc":[{"atl":[[6,8]],"id":43189002}],"con":true,"img":false}]}
{"op":"mcm","clk":"5322574851","pt":1646321932868,"mc":[{"id":"1.195532865","rc":[{"atl":[[5.9,12.11]],"id":43189002}],"con":true,"img":false}]}
{"op":"mcm","clk":"5322574890","pt":1646321933345,"mc":[{"id":"1.195532865","rc":[{"atl":[[5.9,10]],"id":43189002}],"con":true,"img":false}]}
{"op":"mcm","clk":"5322574905","pt":1646321933556,"mc":[{"id":"1.195532865","rc":[{"atb":[[3.1,0],[3.15,28.29]],"id":28041476},{"atb":[[1.51,80.58]],"id":37307439}],"con":true,"img":false}]}
{"op":"mcm","clk":"5322574914","pt":1646321933672,"mc":[{"id":"1.195532865","rc":[{"atl":[[6.2,34.89]],"id":40133341},{"atl":[[6.4,23.52]],"id":43189002},{"atl":[[14,20.38]],"id":35701941},{"atl":[[7.8,28.46]],"id":28041476},{"atl":[[4.7,45.96]],"id":36909459},{"atb":[[1.5,12.39]],"id":37307439}],"con":true,"img":false}]}
{"op":"mcm","clk":"5322574918","pt":1646321933756,"mc":[{"id":"1.195532865","rc":[{"atb":[[3.05,9.52]],"id":28041476}],"con":true,"img":false}]}
{"op":"mcm","clk":"5322574925","pt":1646321933863,"mc":[{"id":"1.195532865","rc":[{"atl":[[5.7,3.66]],"id":43189002}],"con":true,"img":false}]}
{"op":"mcm","clk":"5322574948","pt":1646321934183,"mc":[{"id":"1.195532865","rc":[{"atb":[[3.05,0]],"id":28041476}],"con":true,"img":false}]}
{"op":"mcm","clk":"5322575024","pt":1646321935168,"mc":[{"id":"1.195532865","rc":[{"atl":[[6.4,5],[6,0],[5.9,18.16]],"id":43189002},{"atl":[[8,0],[7.2,29.56],[7.6,0]],"id":36909459}],"con":true,"img":false}]}
{"op":"mcm","clk":"5322575028","pt":1646321935265,"mc":[{"id":"1.195532865","rc":[{"atl":[[11.5,0]],"id":40133341}],"con":true,"img":false}]}
{"op":"mcm","clk":"5322575036","pt":1646321935422,"mc":[{"id":"1.195532865","rc":[{"atl":[[3.05,48.78]],"id":37307439}],"con":true,"img":false}]}
{"op":"mcm","clk":"5322575043","pt":1646321935485,"mc":[{"id":"1.195532865","rc":[{"atl":[[2.84,0]],"id":37307439}],"con":true,"img":false}]}
{"op":"mcm","clk":"5322575127","pt":1646321936684,"mc":[{"id":"1.195532865","rc":[{"atl":[[5.6,3.66],[5.9,8.16]],"id":43189002}],"con":true,"img":false}]}
{"op":"mcm","clk":"5322575136","pt":1646321936785,"mc":[{"id":"1.195532865","rc":[{"atl":[[2.92,20.83],[2.88,0]],"id":37307439}],"con":true,"img":false}]}
{"op":"mcm","clk":"5322575163","pt":1646321937054,"mc":[{"id":"1.195532865","rc":[{"atl":[[5.8,10.83],[5.9,0]],"id":43189002},{"atl":[[2.92,0],[2.96,20.41]],"id":37307439}],"con":true,"img":false}]}
{"op":"mcm","clk":"5322575192","pt":1646321937472,"mc":[{"id":"1.195532865","rc":[{"atb":[[2.38,10.43],[2.26,34.25],[2.34,19.87]],"id":40133341},{"atl":[[5.6,5.54],[6.2,58.37],[9.8,11.36]],"id":40133341},{"atl":[[5.8,25.47],[5.5,4.62],[14.5,7.41]],"id":43189002},{"atb":[[4,10.37],[4.3,6.02],[3.4,16.67]],"id":35701941},{"atl":[[11.5,4.37],[14,32.56],[60,1.69]],"id":35701941},{"atl":[[46,2.73],[6.8,13.79],[7.8,73.54]],"id":28041476},{"atb":[[1.73,0],[1.85,14.52],[1.88,10.37]],"id":36909459},{"atl":[[7.2,0],[4.2,6.22],[4.7,62.56]],"id":36909459},{"atb":[[1.43,0],[1.5,81.38],[1.52,44.29]],"id":37307439},{"atl":[[2.64,41.39],[3.55,39.22],[3.3,141.34]],"id":37307439}],"con":true,"img":false}]}
{"op":"mcm","clk":"5322575198","pt":1646321937576,"mc":[{"id":"1.195532865","rc":[{"atb":[[2.3,0]],"id":40133341},{"atb":[[4,7.61]],"id":35701941},{"atl":[[44,0]],"id":35701941}],"con":true,"img":false}]}
{"op":"mcm","clk":"5322575205","pt":1646321937680,"mc":[{"id":"1.195532865","rc":[{"atl":[[6.2,47.71],[8.8,0],[5.9,18.16]],"id":40133341},{"atl":[[12,0]],"id":43189002},{"atb":[[4.2,2.5]],"id":35701941},{"atl":[[13,11.66],[14,24.87]],"id":35701941},{"atl":[[7.4,16.25],[7.8,64.79],[29,0]],"id":28041476},{"atb":[[1.84,0],[1.87,10.45],[1.88,8.21]],"id":36909459},{"atl":[[4.5,22.86],[6.2,0],[4.7,48.63]],"id":36909459},{"atb":[[1.45,0]],"id":37307439},{"atl":[[3.3,106.56]],"id":37307439}],"con":true,"img":false}]}
{"op":"mcm","clk":"5322575214","pt":1646321937783,"mc":[{"id":"1.195532865","rc":[{"atb":[[4.4,1.99]],"id":35701941}],"con":true,"img":false}]}
{"op":"mcm","clk":"5322575221","pt":1646321937885,"mc":[{"id":"1.195532865","rc":[{"atl":[[5.8,8.33],[5.9,10]],"id":40133341},{"atl":[[5.8,17.14],[5.7,12.17]],"id":43189002},{"atl":[[12.5,3.48],[13,8.33]],"id":35701941},{"atl":[[7.2,6.45]],"id":28041476},{"atl":[[4.4,11.76]],"id":36909459}],"con":true,"img":false}]}
{"op":"mcm","clk":"5322575228","pt":1646321937987,"mc":[{"id":"1.195532865","rc":[{"atl":[[5.6,0],[5.7,20.45]],"id":43189002},{"atb":[[4.4,4.49],[4.2,0]],"id":35701941},{"atl":[[2.96,0],[2.68,23.81]],"id":37307439}],"con":true,"img":false}]}
{"op":"mcm","clk":"5322575243","pt":1646321938157,"mc":[{"id":"1.195532865","rc":[{"atl":[[5.5,0]],"id":43189002}],"con":true,"img":false}]}
{"op":"mcm","clk":"5322575250","pt":1646321938258,"mc":[{"id":"1.195532865","rc":[{"atb":[[2.36,0],[2.44,2.15]],"id":40133341},{"atl":[[5.6,5.34]],"id":43189002},{"atb":[[1.55,2.15],[1.51,78.43]],"id":37307439}],"con":true,"img":false}]}
{"op":"mcm","clk":"5322575272","pt":1646321938572,"mc":[{"id":"1.195532865","rc":[{"atl":[[5.8,25.47],[5.7,11.94]],"id":43189002},{"atb":[[1.51,0],[1.53,77.46]],"id":37307439},{"atl":[[2.6,9.72]],"id":37307439}],"con":true,"img":false}]}
{"op":"mcm","clk":"5322575302","pt":1646321938979,"mc":[{"id":"1.195532865","rc":[{"atb":[[2.4,0]],"id":40133341},{"atb":[[4.3,4.37]],"id":35701941}],"con":true,"img":false}]}
{"op":"mcm","clk":"5322575321","pt":1646321939186,"mc":[{"id":"1.195532865","rc":[{"atb":[[2.38,8.44],[2.46,1.65]],"id":40133341},{"atb":[[4.5,1.65]],"id":35701941}],"con":true,"img":false}]}
{"op":"mcm","clk":"5322575328","pt":1646321939288,"mc":[{"id":"1.195532865","rc":[{"atb":[[2.46,3.64]],"id":40133341}],"con":true,"img":false}]}
{"op":"mcm","clk":"5322575337","pt":1646321939351,"mc":[{"id":"1.195532865","rc":[{"atb":[[1.53,75.47]],"id":37307439}],"con":true,"img":false}]}
{"op":"mcm","clk":"5322575344","pt":1646321939458,"mc":[{"id":"1.195532865","rc":[{"atb":[[1.56,1.99]],"id":37307439}],"con":true,"img":false}]}
{"op":"mcm","clk":"5322575383","pt":1646321939873,"mc":[{"id":"1.195532865","rc":[{"atb":[[1.54,5.62]],"id":37307439}],"con":true,"img":false}]}
{"op":"mcm","clk":"5322575398","pt":1646321940087,"mc":[{"id":"1.195532865","rc":[{"atb":[[1.54,0]],"id":37307439}],"con":true,"img":false}]}
{"op":"mcm","clk":"5322575441","pt":1646321940563,"mc":[{"id":"1.195532865","rc":[{"atb":[[2.38,5.54]],"id":40133341},{"atb":[[1.85,10.38]],"id":36909459},{"atb":[[1.52,41.39]],"id":37307439}],"con":true,"img":false}]}
{"op":"mcm","clk":"5322575550","pt":1646321941977,"mc":[{"id":"1.195532865","rc":[{"atl":[[2.58,23.81],[3.05,0]],"id":37307439}],"con":true,"img":false}]}
{"op":"mcm","clk":"5322575665","pt":1646321943356,"mc":[{"id":"1.195532865","rc":[{"atl":[[7.2,10.62]],"id":28041476}],"con":true,"img":false}]}
{"op":"mcm","clk":"5322575691","pt":1646321943672,"mc":[{"id":"1.195532865","rc":[{"atl":[[7.2,6.45]],"id":28041476}],"con":true,"img":false}]}
{"op":"mcm","clk":"5322575706","pt":1646321943872,"mc":[{"id":"1.195532865","rc":[{"atb":[[1.53,0],[1.54,74.07]],"id":37307439},{"atl":[[2.62,24.69],[2.68,0]],"id":37307439}],"con":true,"img":false}]}
{"op":"mcm","clk":"5322575853","pt":1646321945498,"mc":[{"id":"1.195532865","rc":[{"atb":[[2.4,4.01]],"id":40133341},{"atb":[[1.89,5.74]],"id":36909459},{"atb":[[1.56,4.89]],"id":37307439}],"con":true,"img":false}]}
{"op":"mcm","clk":"5322575862","pt":1646321945555,"mc":[{"id":"1.195532865","rc":[{"atl":[[5.7,8.28]],"id":43189002}],"con":true,"img":false}]}
{"op":"mcm","clk":"5322575871","pt":1646321945661,"mc":[{"id":"1.195532865","rc":[{"atl":[[5.8,39.09],[5.7,0]],"id":43189002},{"atb":[[1.87,2.15],[1.9,8.21]],"id":36909459}],"con":true,"img":false}]}
{"op":"mcm","clk":"5322575880","pt":1646321945763,"mc":[{"id":"1.195532865","rc":[{"atl":[[6.4,25],[5.8,24.45]],"id":43189002},{"atl":[[2.6,0]],"id":37307439}],"con":true,"img":false}]}
{"op":"mcm","clk":"5322575908","pt":1646321946075,"mc":[{"id":"1.195532865","rc":[{"atl":[[5.6,7.45]],"id":43189002}],"con":true,"img":false}]}
{"op":"mcm","clk":"5322575940","pt":1646321946493,"mc":[{"id":"1.195532865","rc":[{"atb":[[1.88,6.22]],"id":36909459}],"con":true,"img":false}]}
{"op":"mcm","clk":"5322575945","pt":1646321946596,"mc":[{"id":"1.195532865","rc":[{"atb":[[1.91,1.99]],"id":36909459}],"con":true,"img":false}]}
{"op":"mcm","clk":"5322575982","pt":1646321947076,"mc":[{"id":"1.195532865","rc":[{"atl":[[2.64,89.89]],"id":37307439}],"con":true,"img":false}]}
{"op":"mcm","clk":"5322575989","pt":1646321947173,"mc":[{"id":"1.195532865","rc":[{"atl":[[2.58,0]],"id":37307439}],"con":true,"img":false}]}
{"op":"mcm","clk":"5322576048","pt":1646321947861,"mc":[{"id":"1.195532865","rc":[{"atl":[[7.6,15.15]],"id":28041476},{"atl":[[4.6,27.78]],"id":36909459}],"con":true,"img":false}]}
{"op":"mcm","clk":"5322576098","pt":1646321948582,"mc":[{"id":"1.195532865","rc":[{"atl":[[6,20]],"id":43189002}],"con":true,"img":false}]}
{"op":"mcm","clk":"5322576113","pt":1646321948792,"mc":[{"id":"1.195532865","rc":[{"atb":[[2.38,20.56]],"id":43189002},{"atl":[[16.5,0],[14.5,0],[15.5,0]],"id":43189002},{"atl":[[7.4,10],[7.8,50.08]],"id":28041476},{"atb":[[1.51,46.28],[1.5,71.49]],"id":37307439},{"atl":[[2.66,24.1],[2.62,0]],"id":37307439}],"con":true,"img":false}]}
{"op":"mcm","clk":"5322576121","pt":1646321948899,"mc":[{"id":"1.195532865","rc":[{"atb":[[1.87,0],[1.93,2.15]],"id":36909459}],"con":true,"img":false}]}
{"op":"mcm","clk":"5322576142","pt":1646321949170,"mc":[{"id":"1.195532865","rc":[{"atl":[[5.6,5.34]],"id":43189002}],"con":true,"img":false}]}
{"op":"mcm","clk":"5322576151","pt":1646321949270,"mc":[{"id":"1.195532865","rc":[{"atb":[[1.89,0]],"id":36909459}],"con":true,"img":false}]}
{"op":"mcm","clk":"5322576197","pt":1646321949791,"mc":[{"id":"1.195532865","rc":[{"atb":[[1.91,0]],"id":36909459}],"con":true,"img":false}]}
{"op":"mcm","clk":"5322576205","pt":1646321949893,"mc":[{"id":"1.195532865","rc":[{"atb":[[1.94,1.99]],"id":36909459}],"con":true,"img":false}]}
{"op":"mcm","clk":"5322576259","pt":1646321950478,"mc":[{"id":"1.195532865","rc":[{"atl":[[5.5,3.79]],"id":43189002}],"con":true,"img":false}]}
{"op":"mcm","clk":"5322576322","pt":1646321951264,"mc":[{"id":"1.195532865","rc":[{"atl":[[5.9,4.58]],"id":43189002},{"atb":[[1.43,5.42]],"id":37307439},{"atl":[[2.66,30.54]],"id":37307439}],"con":true,"img":false}]}
{"op":"mcm","clk":"5322576331","pt":1646321951367,"mc":[{"id":"1.195532865","rc":[{"atb":[[2.26,43.82]],"id":40133341},{"atb":[[4,11.99]],"id":35701941},{"atb":[[1.56,1.99]],"id":37307439},{"atl":[[2.96,8.66]],"id":37307439}],"con":true,"img":false}]}
{"op":"mcm","clk":"5322576342","pt":1646321951474,"mc":[{"id":"1.195532865","rc":[{"atb":[[2.4,13.58],[2.46,9.38],[2.26,34.25],[2.34,5.19]],"id":40133341},{"atl":[[5.8,23.65],[6.2,24.23]],"id":40133341},{"atl":[[6.4,5],[5.8,42.71],[5.9,0],[5.4,4.72]],"id":43189002},{"atb":[[4,0],[4.5,7.54],[4.1,12.31]],"id":35701941},{"atl":[[12.5,19.18],[14,12.69]],"id":35701941},{"atl":[[7.2,56.67]],"id":28041476},{"atb":[[1.85,0],[1.93,8.69],[1.88,21.77]],"id":36909459},{"atl":[[4.4,36.64],[4.7,32.03]],"id":36909459},{"atb":[[1.43,0],[1.56,68.19],[1.54,204.83],[1.5,2.5]],"id":37307439},{"atl":[[2.66,24.1],[2.96,122.19],[3.3,0],[2.62,49.38]],"id":37307439}],"con":true,"img":false}]}
{"op":"mcm","clk":"5322576353","pt":1646321951576,"mc":[{"id":"1.195532865","rc":[{"atb":[[2.38,0]],"id":40133341},{"atl":[[5.7,13.58]],"id":40133341},{"atl":[[5.7,8.51]],"id":43189002},{"atb":[[4.5,12.03]],"id":35701941},{"atl":[[12,11.24]],"id":35701941},{"atl":[[7,19.17],[7.8,5]],"id":28041476},{"atl":[[4.3,25.36],[4.5,11.43]],"id":36909459},{"atb":[[1.52,0]],"id":37307439}],"con":true,"img":false}]}
{"op":"mcm","clk":"5322576360","pt":1646321951680,"mc":[{"id":"1.195532865","rc":[{"atl":[[5.8,44.48],[5.7,2.5],[5.9,0]],"id":40133341},{"atl":[[5.6,0],[6,23.64]],"id":43189002},{"atb":[[4.3,0],[4.4,1.99]],"id":35701941},{"atl":[[12,2.5],[12.5,27.88],[13,0]],"id":35701941},{"atl":[[7.2,72.8],[7.4,0],[7,2.5]],"id":28041476},{"atb":[[1.88,15.55]],"id":36909459},{"atl":[[4.3,2.5],[4.4,64.42]],"id":36909459},{"atl":[[2.64,48.5]],"id":37307439}],"con":true,"img":false}]}
{"op":"mcm","clk":"5322576383","pt":1646321951988,"mc":[{"id":"1.195532865","rc":[{"atl":[[6,20]],"id":43189002}],"con":true,"img":false}]}
{"op":"mcm","clk":"5322576402","pt":1646321952197,"mc":[{"id":"1.195532865","rc":[{"atl":[[5.8,29.09],[5.4,9.44]],"id":43189002},{"atb":[[1.92,10.69],[1.9,0]],"id":36909459},{"atl":[[2.64,0],[2.66,84.34]],"id":37307439}],"con":true,"img":false}]}
{"op":"mcm","clk":"5322576410","pt":1646321952301,"mc":[{"id":"1.195532865","rc":[{"atb":[[1.87,6.02]],"id":36909459}],"con":true,"img":false}]}
{"op":"mcm","clk":"5322576419","pt":1646321952363,"mc":[{"id":"1.195532865","rc":[{"atb":[[4.4,0]],"id":35701941},{"atl":[[2.66,24.1],[2.96,173.21]],"id":37307439}],"con":true,"img":false}]}
{"op":"mcm","clk":"5322576428","pt":1646321952464,"mc":[{"id":"1.195532865","rc":[{"atb":[[4.6,1.99]],"id":35701941}],"con":true,"img":false}]}
{"op":"mcm","clk":"5322576435","pt":1646321952570,"mc":[{"id":"1.195532865","rc":[{"atb":[[1.87,5.39]],"id":36909459}],"con":true,"img":false}]}
{"op":"mcm","clk":"5322576442","pt":1646321952670,"mc":[{"id":"1.195532865","rc":[{"atb":[[1.87,0]],"id":36909459}],"con":true,"img":false}]}
{"op":"mcm","clk":"5322576497","pt":1646321953296,"mc":[{"id":"1.195532865","rc":[{"atl":[[5.6,8.7]],"id":43189002}],"con":true,"img":false}]}
{"op":"mcm","clk":"5322576535","pt":1646321953769,"mc":[{"id":"1.195532865","rc":[{"atb":[[1.93,19.38],[1.92,0]],"id":36909459},{"atb":[[1.5,116.98],[1.51,0]],"id":37307439}],"con":true,"img":false}]}
{"op":"mcm","clk":"5322576577","pt":1646321954187,"mc":[{"id":"1.195532865","rc":[{"atl":[[5.5,0]],"id":43189002}],"con":true,"img":false}]}
{"op":"mcm","clk":"5322576584","pt":1646321954292,"mc":[{"id":"1.195532865","rc":[{"atl":[[5.7,28.51]],"id":43189002}],"con":true,"img":false}]}
{"op":"mcm","clk":"5322576594","pt":1646321954396,"mc":[{"id":"1.195532865","rc":[{"atl":[[5.4,4.72]],"id":43189002}],"con":true,"img":false}]}
{"op":"mcm","clk":"5322576611","pt":1646321954599,"mc":[{"id":"1.195532865","rc":[{"atl":[[5.4,0]],"id":43189002}],"con":true,"img":false}]}
{"op":"mcm","clk":"5322576632","pt":1646321954811,"mc":[{"id":"1.195532865","rc":[{"atl":[[5.5,3.37]],"id":43189002}],"con":true,"img":false}]}
{"op":"mcm","clk":"5322576743","pt":1646321955975,"mc":[{"id":"1.195532865","rc":[{"atb":[[2.4,9.57],[2.48,2.75]],"id":40133341},{"atb":[[2.52,2.64]],"id":43189002},{"atb":[[4.6,4.56]],"id":35701941},{"atb":[[3.25,3.48]],"id":28041476},{"atb":[[1.89,12.82],[1.95,2.72]],"id":36909459},{"atb":[[1.57,5.63],[1.52,70.2]],"id":37307439}],"con":true,"img":false}]}
{"op":"mcm","clk":"5322576755","pt":1646321956082,"mc":[{"id":"1.195532865","rc":[{"atb":[[2.38,5]],"id":43189002},{"atl":[[5.6,0]],"id":43189002},{"atb":[[2.74,59.97],[3.25,19.91],[3.15,5.82],[2.78,67.79]],"id":28041476}],"con":true,"img":false}]}
{"op":"mcm","clk":"5322576766","pt":1646321956190,"mc":[{"id":"1.195532865","rc":[{"atl":[[5.8,49.92]],"id":43189002},{"atb":[[3.1,3.16],[3.15,1.99]],"id":28041476},{"atb":[[1.55,74.88],[1.54,130.76]],"id":37307439}],"con":true,"img":false}]}
{"op":"mcm","clk":"5322576777","pt":1646321956291,"mc":[{"id":"1.195532865","rc":[{"atl":[[5.7,8.51]],"id":43189002}],"con":true,"img":false}]}
{"op":"mcm","clk":"5322576785","pt":1646321956392,"mc":[{"id":"1.195532865","rc":[{"atb":[[2.46,7.39]],"id":40133341},{"atb":[[3.1,0]],"id":28041476},{"atb":[[1.85,3.18]],"id":36909459}],"con":true,"img":false}]}
{"op":"mcm","clk":"5322576792","pt":1646321956494,"mc":[{"id":"1.195532865","rc":[{"atb":[[2.5,1.99]],"id":40133341}],"con":true,"img":false}]}
{"op":"mcm","clk":"5322576809","pt":1646321956704,"mc":[{"id":"1.195532865","rc":[{"atb":[[3.15,0]],"id":28041476},{"atb":[[1.85,0]],"id":36909459}],"con":true,"img":false}]}
{"op":"mcm","clk":"5322576817","pt":1646321956805,"mc":[{"id":"1.195532865","rc":[{"atb":[[2.46,5.74]],"id":40133341},{"atb":[[2.5,0]],"id":43189002},{"atb":[[4.5,10.38]],"id":35701941},{"atb":[[3.2,0],[3.3,1.99]],"id":28041476}],"con":true,"img":false}]}
{"op":"mcm","clk":"5322576823","pt":1646321956912,"mc":[{"id":"1.195532865","rc":[{"atb":[[2.52,1.65]],"id":40133341},{"atb":[[2.54,1.65],[2.48,0]],"id":43189002},{"atb":[[4.7,1.65]],"id":35701941}],"con":true,"img":false}]}
{"op":"mcm","clk":"5322576833","pt":1646321956972,"mc":[{"id":"1.195532865","rc":[{"atb":[[2.54,3.64]],"id":43189002}],"con":true,"img":false}]}
{"op":"mcm","clk":"5322576856","pt":1646321957282,"mc":[{"id":"1.195532865","rc":[{"atb":[[1.56,66.21]],"id":37307439}],"con":true,"img":false}]}
{"op":"mcm","clk":"5322576866","pt":1646321957389,"mc":[{"id":"1.195532865","rc":[{"atl":[[5.3,3.94]],"id":43189002},{"atb":[[1.58,1.99]],"id":37307439}],"con":true,"img":false}]}
{"op":"mcm","clk":"5322576886","pt":1646321957599,"mc":[{"id":"1.195532865","rc":[{"atl":[[5.5,12.26]],"id":43189002},{"atb":[[1.94,0]],"id":36909459},{"atb":[[1.56,137.64],[1.55,2.15]],"id":37307439}],"con":true,"img":false}]}
{"op":"mcm","clk":"5322576895","pt":1646321957702,"mc":[{"id":"1.195532865","rc":[{"atb":[[1.96,1.99]],"id":36909459}],"con":true,"img":false}]}
{"op":"mcm","clk":"5322576903","pt":1646321957802,"mc":[{"id":"1.195532865","rc":[{"atl":[[8,21.43]],"id":28041476},{"atl":[[4.8,39.47]],"id":36909459}],"con":true,"img":false}]}
{"op":"mcm","clk":"5322576993","pt":1646321958800,"mc":[{"id":"1.195532865","rc":[{"atl":[[4.5,0],[4.6,32.5],[4.7,5]],"id":36909459}],"con":true,"img":false}]}
{"op":"mcm","clk":"5322577012","pt":1646321959001,"mc":[{"id":"1.195532865","rc":[{"atl":[[4.6,27.78]],"id":36909459}],"con":true,"img":false}]}
{"op":"mcm","clk":"5322577037","pt":1646321959315,"mc":[{"id":"1.195532865","rc":[{"atb":[[2.44,0],[2.52,3.81]],"id":40133341},{"atb":[[1.59,2.15],[1.55,0]],"id":37307439}],"con":true,"img":false}]}
{"op":"mcm","clk":"5322577063","pt":1646321959580,"mc":[{"id":"1.195532865","rc":[{"atb":[[2.5,0]],"id":40133341},{"atl":[[5.8,31.66],[5.7,23.69]],"id":43189002}],"con":true,"img":false}]}
{"op":"mcm","clk":"5322577071","pt":1646321959684,"mc":[{"id":"1.195532865","rc":[{"atb":[[2.54,1.99]],"id":40133341},{"atb":[[4.4,10],[4.5,5.89]],"id":35701941},{"atb":[[1.93,8.69],[1.91,12.83]],"id":36909459},{"atb":[[1.56,66.21],[1.57,75.81]],"id":37307439}],"con":true,"img":false}]}
{"op":"mcm","clk":"5322577097","pt":1646321960126,"mc":[{"id":"1.195532865","rc":[{"atb":[[1.58,0]],"id":37307439},{"atl":[[2.62,0]],"id":37307439}],"con":true,"img":false}]}
{"op":"mcm","clk":"5322577102","pt":1646321960181,"mc":[{"id":"1.195532865","rc":[{"atb":[[1.02,1.99]],"id":37307439},{"atl":[[2.64,48.78]],"id":37307439}],"con":true,"img":false}]}
{"op":"mcm","clk":"5322577108","pt":1646321960287,"mc":[{"id":"1.195532865","rc":[{"atb":[[2.52,6.36]],"id":40133341},{"spn":4.07,"spf":"NaN","id":40133341},{"spn":3.92,"spf":"NaN","id":43189002},{"spn":4.55,"spf":1.0,"id":35701941},{"spn":5.05,"spf":"NaN","id":28041476},{"spn":1.96,"spf":1.0,"id":36909459},{"atb":[[1.52,0]],"id":37307439},{"atl":[[3.4,110.71],[2.96,51.02]],"id":37307439},{"spn":2.11,"spf":"NaN","id":37307439}],"con":true,"img":false}]}
{"op":"mcm","clk":"5322577120","pt":1646321960496,"mc":[{"id":"1.195532865","rc":[{"atl":[[3.4,2.5]],"id":37307439}],"con":true,"img":false}]}
{"op":"mcm","clk":"5322577265","pt":1646321962283,"mc":[{"id":"1.195532865","rc":[{"atl":[[5.3,0]],"id":43189002}],"con":true,"img":false}]}
{"op":"mcm","clk":"5322577273","pt":1646321962389,"mc":[{"id":"1.195532865","rc":[{"atb":[[1.89,0]],"id":36909459},{"atl":[[2.66,0],[2.68,23.81]],"id":37307439}],"con":true,"img":false}]}
{"op":"mcm","clk":"5322577283","pt":1646321962495,"mc":[{"id":"1.195532865","rc":[{"atb":[[2.74,162.31],[2.78,22.47]],"id":28041476}],"con":true,"img":false}]}
{"op":"mcm","clk":"5322577292","pt":1646321962599,"mc":[{"id":"1.195532865","rc":[{"atl":[[2.96,0],[2.68,83.33]],"id":37307439}],"con":true,"img":false}]}
{"op":"mcm","clk":"5322577420","pt":1646321964216,"mc":[{"id":"1.195532865","rc":[{"atl":[[5.5,3.37]],"id":43189002}],"con":true,"img":false}]}
{"op":"mcm","clk":"5322577457","pt":1646321964691,"mc":[{"id":"1.195532865","rc":[{"atb":[[1.58,54.57]],"id":37307439}],"con":true,"img":false}]}
{"op":"mcm","clk":"5322577473","pt":1646321964900,"mc":[{"id":"1.195532865","rc":[{"atb":[[2.44,6.4]],"id":40133341}],"con":true,"img":false}]}
{"op":"mcm","clk":"5322577496","pt":1646321965213,"mc":[{"id":"1.195532865","rc":[{"atb":[[2.54,8.21],[2.4,0],[2.46,19.84]],"id":40133341},{"atb":[[4.4,25.14],[4.1,2.5],[4.7,8.35]],"id":35701941},{"atb":[[1.95,9.42]],"id":36909459},{"atb":[[1.59,67.66]],"id":37307439},{"atl":[[3.4,111.75]],"id":37307439}],"con":true,"img":false}]}
{"op":"mcm","clk":"5322577505","pt":1646321965314,"mc":[{"id":"1.195532865","rc":[{"atb":[[2.44,0]],"id":40133341},{"atb":[[1.88,0],[1.91,31.48]],"id":36909459},{"atb":[[1.57,205.01],[1.54,0]],"id":37307439}],"con":true,"img":false}]}
{"op":"mcm","clk":"5322577516","pt":1646321965425,"mc":[{"id":"1.195532865","rc":[{"atb":[[2.46,14.1]],"id":40133341},{"atb":[[4.5,0]],"id":35701941},{"atb":[[1.93,2.15]],"id":36909459},{"atb":[[1.56,0]],"id":37307439}],"con":true,"img":false}]}
{"op":"mcm","clk":"5322577555","pt":1646321965899,"mc":[{"id":"1.195532865","rc":[{"atb":[[2.52,4.7]],"id":40133341}],"con":true,"img":false}]}
{"op":"mcm","clk":"5322577562","pt":1646321966006,"mc":[{"id":"1.195532865","rc":[{"atl":[[5.8,45.7],[5.7,8.51]],"id":43189002}],"con":true,"img":false}]}
{"op":"mcm","clk":"5322577570","pt":1646321966106,"mc":[{"id":"1.195532865","rc":[{"atb":[[2.56,1.65]],"id":40133341},{"atb":[[1.92,5],[1.91,18.65]],"id":36909459}],"con":true,"img":false}]}
{"op":"mcm","clk":"5322577588","pt":1646321966416,"mc":[{"id":"1.195532865","rc":[{"atb":[[4.6,2.57]],"id":35701941}],"con":true,"img":false}]}
{"op":"mcm","clk":"5322577596","pt":1646321966520,"mc":[{"id":"1.195532865","rc":[{"atb":[[4.8,1.99]],"id":35701941}],"con":true,"img":false}]}
{"op":"mcm","clk":"5322577621","pt":1646321966784,"mc":[{"id":"1.195532865","rc":[{"atb":[[1.96,5.28]],"id":36909459}],"con":true,"img":false}]}
{"op":"mcm","clk":"5322577660","pt":1646321967301,"mc":[{"id":"1.195532865","rc":[{"atl":[[5.9,20.41]],"id":43189002}],"con":true,"img":false}]}
{"op":"mcm","clk":"5322577673","pt":1646321967509,"mc":[{"id":"1.195532865","rc":[{"atl":[[8.4,33.78]],"id":28041476},{"atl":[[5,62.5]],"id":36909459}],"con":true,"img":false}]}
{"op":"mcm","clk":"5322577695","pt":1646321967820,"mc":[{"id":"1.195532865","rc":[{"atl":[[3.1,47.62],[2.68,23.81]],"id":37307439}],"con":true,"img":false}]}
{"op":"mcm","clk":"5322577795","pt":1646321968997,"mc":[{"id":"1.195532865","rc":[{"atb":[[2.52,2.15]],"id":40133341},{"atb":[[1.58,0]],"id":37307439}],"con":true,"img":false}]}
{"op":"mcm","clk":"5322577862","pt":1646321969725,"mc":[{"id":"1.195532865","rc":[{"atb":[[3.3,27.27]],"id":28041476}],"con":true,"img":false}]}
{"op":"mcm","clk":"5322577874","pt":1646321969892,"mc":[{"id":"1.195532865","rc":[{"atb":[[2.74,59.97],[3.25,6.96],[2.78,75.44]],"id":28041476},{"atl":[[34,0]],"id":28041476}],"con":true,"img":false}]}
{"op":"mcm","clk":"5322577927","pt":1646321970418,"mc":[{"id":"1.195532865","rc":[{"atb":[[3.2,7.55]],"id":28041476}],"con":true,"img":false}]}
{"op":"mcm","clk":"5322577953","pt":1646321970728,"mc":[{"id":"1.195532865","rc":[{"atb":[[3.2,0]],"id":28041476}],"con":true,"img":false}]}
{"op":"mcm","clk":"5322578026","pt":1646321971621,"mc":[{"id":"1.195532865","rc":[{"atb":[[1.5,262.54]],"id":37307439}],"con":true,"img":false}]}
{"op":"mcm","clk":"5322578035","pt":1646321971726,"mc":[{"id":"1.195532865","rc":[{"atb":[[1.57,75.81]],"id":37307439}],"con":true,"img":false}]}
{"op":"mcm","clk":"5322578060","pt":1646321971989,"mc":[{"id":"1.195532865","rc":[{"atb":[[1.55,181.82]],"id":37307439},{"atl":[[2.72,58.14]],"id":37307439}],"con":true,"img":false}]}
{"op":"mcm","clk":"5322578167","pt":1646321973394,"mc":[{"id":"1.195532865","rc":[{"atb":[[2.56,2.55]],"id":43189002},{"atb":[[1.51,71.58]],"id":37307439}],"con":true,"img":false}]}
{"op":"mcm","clk":"5322578197","pt":1646321973811,"mc":[{"id":"1.195532865","rc":[{"atl":[[2.72,196.97]],"id":37307439}],"con":true,"img":false}]}
{"op":"mcm","clk":"5322578208","pt":1646321973916,"mc":[{"id":"1.195532865","rc":[{"atl":[[3.4,2.5]],"id":37307439}],"con":true,"img":false}]}
{"op":"mcm","clk":"5322578227","pt":1646321974122,"mc":[{"id":"1.195532865","rc":[{"atl":[[2.72,255.11],[3.1,0]],"id":37307439}],"con":true,"img":false}]}
{"op":"mcm","clk":"5322578237","pt":1646321974224,"mc":[{"id":"1.195532865","rc":[{"atb":[[2.54,1.65]],"id":43189002}],"con":true,"img":false}]}
{"op":"mcm","clk":"5322578244","pt":1646321974331,"mc":[{"id":"1.195532865","rc":[{"atb":[[2.58,1.99]],"id":43189002}],"con":true,"img":false}]}
{"op":"mcm","clk":"5322578288","pt":1646321974908,"mc":[{"id":"1.195532865","rc":[{"atb":[[2.54,0]],"id":43189002},{"atb":[[4.7,6.7]],"id":35701941}],"con":true,"img":false}]}
{"op":"mcm","clk":"5322578302","pt":1646321975118,"mc":[{"id":"1.195532865","rc":[{"atb":[[2.6,1.65]],"id":43189002},{"atb":[[4.9,1.65]],"id":35701941}],"con":true,"img":false}]}
{"op":"mcm","clk":"5322578356","pt":1646321975796,"mc":[{"id":"1.195532865","rc":[{"atb":[[1.93,16.85],[1.92,0]],"id":36909459},{"atb":[[1.37,0]],"id":37307439},{"atl":[[3.55,0],[3.65,0],[3.75,0]],"id":37307439}],"con":true,"img":false}]}
{"op":"mcm","clk":"5322578384","pt":1646321976110,"mc":[{"id":"1.195532865","rc":[{"atl":[[3.75,11.73]],"id":36909459}],"con":true,"img":false}]}
{"op":"mcm","clk":"5322578391","pt":1646321976210,"mc":[{"id":"1.195532865","rc":[{"atb":[[1.98,2.15],[1.93,14.7]],"id":36909459},{"atl":[[4.3,33.78],[3.7,6.22],[4.4,36.64],[4.2,0]],"id":36909459}],"con":true,"img":false}]}
{"op":"mcm","clk":"5322578400","pt":1646321976318,"mc":[{"id":"1.195532865","rc":[{"atl":[[4.3,61.56],[3.7,0],[4.4,11.76]],"id":36909459}],"con":true,"img":false}]}
{"op":"mcm","clk":"5322578436","pt":1646321976731,"mc":[{"id":"1.195532865","rc":[{"atl":[[2.62,49.38]],"id":37307439}],"con":true,"img":false}]}
{"op":"mcm","clk":"5322578444","pt":1646321976831,"mc":[{"id":"1.195532865","rc":[{"atl":[[6.2,28.85]],"id":43189002},{"atl":[[2.64,0],[2.68,83.33]],"id":37307439}],"con":true,"img":false}]}
{"op":"mcm","clk":"5322578452","pt":1646321976934,"mc":[{"id":"1.195532865","rc":[{"atl":[[2.72,196.97]],"id":37307439}],"con":true,"img":false}]}
{"op":"mcm","clk":"5322578462","pt":1646321977041,"mc":[{"id":"1.195532865","rc":[{"atb":[[1.96,3.29]],"id":36909459},{"atl":[[3.85,14.04],[4.4,0]],"id":36909459},{"atl":[[2.72,255.11],[2.68,23.81]],"id":37307439}],"con":true,"img":false}]}
{"op":"mcm","clk":"5322578472","pt":1646321977097,"mc":[{"id":"1.195532865","rc":[{"atb":[[1.99,1.99]],"id":36909459}],"con":true,"img":false}]}
{"op":"mcm","clk":"5322578516","pt":1646321977626,"mc":[{"id":"1.195532865","rc":[{"atb":[[2.56,0]],"id":43189002},{"atb":[[1.51,0]],"id":37307439}],"con":true,"img":false}]}
{"op":"mcm","clk":"5322578528","pt":1646321977731,"mc":[{"id":"1.195532865","rc":[{"atl":[[2.68,39.9]],"id":37307439}],"con":true,"img":false}]}
{"op":"mcm","clk":"5322578545","pt":1646321977933,"mc":[{"id":"1.195532865","rc":[{"atl":[[2.68,23.81]],"id":37307439}],"con":true,"img":false}]}
{"op":"mcm","clk":"5322578570","pt":1646321978200,"mc":[{"id":"1.195532865","rc":[{"atb":[[2.58,0]],"id":43189002}],"con":true,"img":false}]}
{"op":"mcm","clk":"5322578579","pt":1646321978304,"mc":[{"id":"1.195532865","rc":[{"atb":[[2.34,9.16]],"id":40133341},{"atb":[[2.54,1.99],[2.38,16.62]],"id":43189002},{"atl":[[5.8,37.37],[6,0]],"id":43189002},{"atb":[[4.6,7.39]],"id":35701941},{"atl":[[2.66,24.1],[2.7,25.4]],"id":37307439}],"con":true,"img":false}]}
{"op":"mcm","clk":"5322578587","pt":1646321978405,"mc":[{"id":"1.195532865","rc":[{"atb":[[2.38,5]],"id":43189002}],"con":true,"img":false}]}
{"op":"mcm","clk":"5322578601","pt":1646321978612,"mc":[{"id":"1.195532865","rc":[{"atb":[[2.46,0],[2.48,13.11]],"id":40133341},{"atb":[[4.9,6.8],[4.4,10],[4.6,21.23]],"id":35701941},{"atb":[[1.98,13.41]],"id":36909459},{"atl":[[2.72,116.27],[2.68,165.99]],"id":37307439}],"con":true,"img":false}]}
{"op":"mcm","clk":"5322578609","pt":1646321978721,"mc":[{"id":"1.195532865","rc":[{"atb":[[2.34,5.19]],"id":40133341},{"atb":[[4.7,0]],"id":35701941},{"atb":[[1.95,35.86],[1.91,0]],"id":36909459},{"atb":[[1.55,328.13],[1.5,116.98]],"id":37307439},{"atl":[[2.7,0]],"id":37307439}],"con":true,"img":false}]}
{"op":"mcm","clk":"5322578617","pt":1646321978822,"mc":[{"id":"1.195532865","rc":[{"atb":[[4.6,16.41]],"id":35701941},{"atb":[[1.95,29.16]],"id":36909459}],"con":true,"img":false}]}
{"op":"mcm","clk":"5322578623","pt":1646321978929,"mc":[{"id":"1.195532865","rc":[{"atb":[[4.8,0]],"id":35701941},{"atb":[[1.46,37.79]],"id":37307439}],"con":true,"img":false}]}
{"op":"mcm","clk":"5322578632","pt":1646321979030,"mc":[{"id":"1.195532865","rc":[{"atb":[[5,1.99]],"id":35701941}],"con":true,"img":false}]}
{"op":"mcm","clk":"5322578650","pt":1646321979234,"mc":[{"id":"1.195532865","rc":[{"atb":[[1.46,5]],"id":37307439}],"con":true,"img":false}]}
{"op":"mcm","clk":"5322578694","pt":1646321979711,"mc":[{"id":"1.195532865","rc":[{"atb":[[1.96,0]],"id":36909459}],"con":true,"img":false}]}
{"op":"mcm","clk":"5322578801","pt":1646321980912,"mc":[{"id":"1.195532865","rc":[{"atl":[[5.6,2.5]],"id":43189002},{"atb":[[3.85,0],[4.1,0],[3.65,0]],"id":35701941},{"atb":[[2.74,57.47],[2.86,2.5],[2.78,80.44]],"id":28041476},{"atl":[[4.6,32.78],[4.2,2.5]],"id":36909459},{"atb":[[1.51,2.5]],"id":37307439}],"con":true,"img":false}]}
{"op":"mcm","clk":"5322578808","pt":1646321981018,"mc":[{"id":"1.195532865","rc":[{"atl":[[7.2,0],[6.4,0],[5.8,34.87]],"id":43189002},{"atb":[[2.86,28.44]],"id":28041476},{"atl":[[4.3,59.06],[5.1,0],[4.7,0]],"id":36909459},{"atb":[[1.46,0],[1.5,114.48],[1.42,0]],"id":37307439}],"con":true,"img":false}]}
{"op":"mcm","clk":"5322578817","pt":1646321981124,"mc":[{"id":"1.195532865","rc":[{"atl":[[5.8,20.83],[5.7,20.53]],"id":43189002},{"atb":[[2.78,27.47]],"id":28041476}],"con":true,"img":false}]}
{"op":"mcm","clk":"5322578967","pt":1646321982914,"mc":[{"id":"1.195532865","rc":[{"atb":[[4.5,16.67]],"id":35701941},{"atb":[[1.94,26.84],[1.93,0]],"id":36909459}],"con":true,"img":false}]}
{"op":"mcm","clk":"5322578973","pt":1646321983012,"mc":[{"id":"1.195532865","rc":[{"atb":[[4.4,0]],"id":35701941}],"con":true,"img":false}]}
{"op":"mcm","clk":"5322578988","pt":1646321983221,"mc":[{"id":"1.195532865","rc":[{"atl":[[2.72,58.13],[2.68,225.51]],"id":37307439}],"con":true,"img":false}]}
{"op":"mcm","clk":"5322579035","pt":1646321983696,"mc":[{"id":"1.195532865","rc":[{"atb":[[2.56,2.55]],"id":43189002},{"atb":[[1.6,47.36]],"id":37307439}],"con":true,"img":false}]}
{"op":"mcm","clk":"5322579041","pt":1646321983802,"mc":[{"id":"1.195532865","rc":[{"atb":[[2.6,0]],"id":43189002},{"atb":[[4.9,5.15]],"id":35701941},{"atb":[[1.61,60.3]],"id":37307439}],"con":true,"img":false}]}
{"op":"mcm","clk":"5322579057","pt":1646321984021,"mc":[{"id":"1.195532865","rc":[{"atb":[[2.56,4.21]],"id":43189002},{"atb":[[5.1,1.65]],"id":35701941},{"atb":[[1.59,2.15]],"id":37307439}],"con":true,"img":false}]}
{"op":"mcm","clk":"5322579064","pt":1646321984122,"mc":[{"id":"1.195532865","rc":[{"atb":[[1.59,23.27]],"id":37307439}],"con":true,"img":false}]}
{"op":"mcm","clk":"5322579070","pt":1646321984227,"mc":[{"id":"1.195532865","rc":[{"atb":[[1.59,2.15]],"id":37307439}],"con":true,"img":false}]}
{"op":"mcm","clk":"5322579083","pt":1646321984334,"mc":[{"id":"1.195532865","rc":[{"atb":[[1.59,69.95],[1.57,5.63]],"id":37307439}],"con":true,"img":false}]}
{"op":"mcm","clk":"5322579094","pt":1646321984435,"mc":[{"id":"1.195532865","rc":[{"atb":[[2.54,0]],"id":43189002}],"con":true,"img":false}]}
{"op":"mcm","clk":"5322579104","pt":1646321984539,"mc":[{"id":"1.195532865","rc":[{"atb":[[2.58,1.99]],"id":43189002}],"con":true,"img":false}]}
{"op":"mcm","clk":"5322579126","pt":1646321984847,"mc":[{"id":"1.195532865","rc":[{"atb":[[1.94,63.65],[1.95,2.72]],"id":36909459}],"con":true,"img":false}]}
{"op":"mcm","clk":"5322579135","pt":1646321984905,"mc":[{"id":"1.195532865","rc":[{"atb":[[1.59,207.05],[1.55,181.82]],"id":37307439}],"con":true,"img":false}]}
{"op":"mcm","clk":"5322579245","pt":1646321986222,"mc":[{"id":"1.195532865","rc":[{"atl":[[6.6,44.64]],"id":43189002}],"con":true,"img":false}]}
{"op":"mcm","clk":"5322579258","pt":1646321986325,"mc":[{"id":"1.195532865","rc":[{"atb":[[1.99,12.77]],"id":36909459}],"con":true,"img":false}]}
{"op":"mcm","clk":"5322579270","pt":1646321986430,"mc":[{"id":"1.195532865","rc":[{"atl":[[3.95,33.9]],"id":36909459}],"con":true,"img":false}]}
{"op":"mcm","clk":"5322579280","pt":1646321986535,"mc":[{"id":"1.195532865","rc":[{"atl":[[4.3,31.28],[3.95,66.68],[4.4,4.7]],"id":36909459}],"con":true,"img":false}]}
{"op":"mcm","clk":"5322579298","pt":1646321986746,"mc":[{"id":"1.195532865","rc":[{"atl":[[4.4,0]],"id":36909459}],"con":true,"img":false}]}
{"op":"mcm","clk":"5322579306","pt":1646321986845,"mc":[{"id":"1.195532865","rc":[{"atb":[[1.98,11.26],[2.04,2.15]],"id":36909459},{"atb":[[1.64,2.15],[1.59,204.9]],"id":37307439}],"con":true,"img":false}]}
{"op":"mcm","clk":"5322579321","pt":1646321987002,"mc":[{"id":"1.195532865","rc":[{"atl":[[4.8,0],[4.6,5],[5,0]],"id":36909459}],"con":true,"img":false}]}
{"op":"mcm","clk":"5322579328","pt":1646321987111,"mc":[{"id":"1.195532865","rc":[{"atb":[[1.99,10.78]],"id":36909459}],"con":true,"img":false}]}
{"op":"mcm","clk":"5322579335","pt":1646321987216,"mc":[{"id":"1.195532865","rc":[{"atb":[[1.98,14.63],[2.06,1.99]],"id":36909459}],"con":true,"img":false}]}
{"op":"mcm","clk":"5322579342","pt":1646321987320,"mc":[{"id":"1.195532865","rc":[{"atb":[[1.98,11.26]],"id":36909459}],"con":true,"img":false}]}
{"op":"mcm","clk":"5322579418","pt":1646321988415,"mc":[{"id":"1.195532865","rc":[{"atb":[[2.26,31.75]],"id":40133341}],"con":true,"img":false}]}
{"op":"mcm","clk":"5322579438","pt":1646321988725,"mc":[{"id":"1.195532865","rc":[{"atb":[[1.6,0]],"id":37307439}],"con":true,"img":false}]}
{"op":"mcm","clk":"5322579486","pt":1646321989355,"mc":[{"id":"1.195532865","rc":[{"atl":[[3.7,16.89]],"id":36909459}],"con":true,"img":false}]}
{"op":"mcm","clk":"5322579494","pt":1646321989450,"mc":[{"id":"1.195532865","rc":[{"atl":[[3.95,112.66]],"id":36909459}],"con":true,"img":false}]}
{"op":"mcm","clk":"5322579504","pt":1646321989556,"mc":[{"id":"1.195532865","rc":[{"atl":[[4.3,0],[3.75,0]],"id":36909459}],"con":true,"img":false}]}
{"op":"mcm","clk":"5322579609","pt":1646321991019,"mc":[{"id":"1.195532865","rc":[{"atb":[[1.99,0]],"id":36909459}],"con":true,"img":false}]}
{"op":"mcm","clk":"5322579659","pt":1646321991754,"mc":[{"id":"1.195532865","rc":[{"atb":[[2.04,21.12]],"id":36909459}],"con":true,"img":false}]}
{"op":"mcm","clk":"5322579667","pt":1646321991850,"mc":[{"id":"1.195532865","rc":[{"atb":[[5.1,6.8]],"id":35701941}],"con":true,"img":false}]}
{"op":"mcm","clk":"5322579675","pt":1646321991968,"mc":[{"id":"1.195532865","rc":[{"atb":[[1.98,0],[1.94,26.84],[1.95,34.34]],"id":36909459}],"con":true,"img":false}]}
{"op":"mcm","clk":"5322579685","pt":1646321992014,"mc":[{"id":"1.195532865","rc":[{"atb":[[4.9,0]],"id":35701941}],"con":true,"img":false}]}
{"op":"mcm","clk":"5322579702","pt":1646321992223,"mc":[{"id":"1.195532865","rc":[{"atb":[[4.5,46.02],[4.6,2.57]],"id":35701941},{"atl":[[3.8,14.29]],"id":36909459}],"con":true,"img":false}]}
{"op":"mcm","clk":"5322579714","pt":1646321992332,"mc":[{"id":"1.195532865","rc":[{"atl":[[2.66,27.47]],"id":37307439}],"con":true,"img":false}]}
{"op":"mcm","clk":"5322579731","pt":1646321992558,"mc":[{"id":"1.195532865","rc":[{"atl":[[2.64,60.98]],"id":37307439}],"con":true,"img":false}]}
{"op":"mcm","clk":"5322579737","pt":1646321992643,"mc":[{"id":"1.195532865","rc":[{"atl":[[3.85,45.22]],"id":36909459},{"atl":[[2.68,165.99]],"id":37307439}],"con":true,"img":false}]}
{"op":"mcm","clk":"5322579745","pt":1646321992745,"mc":[{"id":"1.195532865","rc":[{"atl":[[3.95,79.88]],"id":36909459},{"atl":[[2.66,174.5],[2.68,23.81]],"id":37307439}],"con":true,"img":false}]}
{"op":"mcm","clk":"5322579753","pt":1646321992851,"mc":[{"id":"1.195532865","rc":[{"atb":[[2.56,2.55]],"id":43189002}],"con":true,"img":false}]}
{"op":"mcm","clk":"5322579773","pt":1646321993057,"mc":[{"id":"1.195532865","rc":[{"atb":[[2.6,1.65]],"id":43189002},{"atl":[[5.8,24.58]],"id":43189002},{"atb":[[2.08,1.65]],"id":36909459}],"con":true,"img":false}]}
{"op":"mcm","clk":"5322579781","pt":1646321993157,"mc":[{"id":"1.195532865","rc":[{"atb":[[1.62,43.72]],"id":37307439}],"con":true,"img":false}]}
{"op":"mcm","clk":"5322579788","pt":1646321993260,"mc":[{"id":"1.195532865","rc":[{"atl":[[5.8,20.83]],"id":43189002}],"con":true,"img":false}]}
{"op":"mcm","clk":"5322579791","pt":1646321993321,"mc":[{"id":"1.195532865","rc":[{"atb":[[1.59,67.8],[1.61,197.4]],"id":37307439}],"con":true,"img":false}]}
{"op":"mcm","clk":"5322579804","pt":1646321993535,"mc":[{"id":"1.195532865","rc":[{"atb":[[1.57,181.07]],"id":37307439},{"atl":[[2.7,58.82]],"id":37307439}],"con":true,"img":false}]}
{"op":"mcm","clk":"5322579824","pt":1646321993844,"mc":[{"id":"1.195532865","rc":[{"atb":[[1.39,0]],"id":37307439}],"con":true,"img":false}]}
{"op":"mcm","clk":"5322579949","pt":1646321995564,"mc":[{"id":"1.195532865","rc":[{"atb":[[2.56,0]],"id":43189002}],"con":true,"img":false}]}
{"op":"mcm","clk":"5322579956","pt":1646321995661,"mc":[{"id":"1.195532865","rc":[{"atb":[[1.96,5.46]],"id":36909459}],"con":true,"img":false}]}
{"op":"mcm","clk":"5322580121","pt":1646321997868,"mc":[{"id":"1.195532865","rc":[{"atb":[[1.96,44.44],[1.95,2.72]],"id":36909459}],"con":true,"img":false}]}
{"op":"mcm","clk":"5322580126","pt":1646321997966,"mc":[{"id":"1.195532865","rc":[{"atb":[[2.36,16.77]],"id":40133341}],"con":true,"img":false}]}
{"op":"mcm","clk":"5322580274","pt":1646321999947,"mc":[{"id":"1.195532865","rc":[{"atl":[[2.66,171.13]],"id":37307439}],"con":true,"img":false}]}
{"op":"mcm","clk":"5322580286","pt":1646322000063,"mc":[{"id":"1.195532865","rc":[{"atl":[[2.64,0],[2.66,231.37]],"id":37307439}],"con":true,"img":false}]}
{"op":"mcm","clk":"5322580306","pt":1646322000265,"mc":[{"id":"1.195532865","rc":[{"atl":[[2.66,84.34],[2.68,171.74]],"id":37307439}],"con":true,"img":false}]}
{"op":"mcm","clk":"5322580405","pt":1646322001366,"mc":[{"id":"1.195532865","rc":[{"atl":[[3.9,34.48]],"id":36909459}],"con":true,"img":false}]}
{"op":"mcm","clk":"5322580482","pt":1646322002149,"mc":[{"id":"1.195532865","rc":[{"atl":[[3.9,39.37]],"id":36909459}],"con":true,"img":false}]}
{"op":"mcm","clk":"5322580500","pt":1646322002357,"mc":[{"id":"1.195532865","rc":[{"atl":[[3.85,121.26],[3.95,33.9]],"id":36909459}],"con":true,"img":false}]}
{"op":"mcm","clk":"5322580516","pt":1646322002574,"mc":[{"id":"1.195532865","rc":[{"atl":[[3.9,34.48]],"id":36909459}],"con":true,"img":false}]}
{"op":"mcm","clk":"5322580528","pt":1646322002678,"mc":[{"id":"1.195532865","rc":[{"atb":[[5,0]],"id":35701941},{"atb":[[1.55,431.82]],"id":37307439},{"atl":[[2.74,86.21]],"id":37307439}],"con":true,"img":false}]}
{"op":"mcm","clk":"5322580536","pt":1646322002775,"mc":[{"id":"1.195532865","rc":[{"atb":[[5.2,1.99]],"id":35701941},{"atb":[[1.55,250]],"id":37307439}],"con":true,"img":false}]}
{"op":"mcm","clk":"5322580543","pt":1646322002883,"mc":[{"id":"1.195532865","rc":[{"atb":[[3.7,10],[3.9,5],[4.2,2.5]],"id":35701941}],"con":true,"img":false}]}
{"op":"mcm","clk":"5322580581","pt":1646322003257,"mc":[{"id":"1.195532865","rc":[{"atb":[[2.58,0]],"id":43189002}],"con":true,"img":false}]}
{"op":"mcm","clk":"5322580588","pt":1646322003360,"mc":[{"id":"1.195532865","rc":[{"atb":[[2.54,1.99]],"id":43189002}],"con":true,"img":false}]}
{"op":"mcm","clk":"5322580598","pt":1646322003461,"mc":[{"id":"1.195532865","rc":[{"atb":[[2.38,14.59]],"id":43189002}],"con":true,"img":false}]}
{"op":"mcm","clk":"5322580603","pt":1646322003570,"mc":[{"id":"1.195532865","rc":[{"atb":[[2.38,5]],"id":43189002}],"con":true,"img":false}]}
{"op":"mcm","clk":"5322580662","pt":1646322004246,"mc":[{"id":"1.195532865","rc":[{"atb":[[3.8,5.1],[5,4]],"id":35701941}],"con":true,"img":false}]}
{"op":"mcm","clk":"5322580680","pt":1646322004453,"mc":[{"id":"1.195532865","rc":[{"atb":[[5,0]],"id":35701941}],"con":true,"img":false}]}
{"op":"mcm","clk":"5322580687","pt":1646322004554,"mc":[{"id":"1.195532865","rc":[{"atb":[[3.8,0]],"id":35701941},{"atb":[[1.54,12.85]],"id":37307439}],"con":true,"img":false}]}
{"op":"mcm","clk":"5322580694","pt":1646322004663,"mc":[{"id":"1.195532865","rc":[{"atb":[[2.06,25.37]],"id":36909459}],"con":true,"img":false}]}
{"op":"mcm","clk":"5322580697","pt":1646322004771,"mc":[{"id":"1.195532865","rc":[{"atb":[[5.2,7.19]],"id":35701941}],"con":true,"img":false}]}
{"op":"mcm","clk":"5322580708","pt":1646322004872,"mc":[{"id":"1.195532865","rc":[{"atb":[[2.04,2.15]],"id":36909459}],"con":true,"img":false}]}
{"op":"mcm","clk":"5322580719","pt":1646322004978,"mc":[{"id":"1.195532865","rc":[{"atb":[[5.1,1.65]],"id":35701941},{"atb":[[1.54,0]],"id":37307439}],"con":true,"img":false}]}
{"op":"mcm","clk":"5322580735","pt":1646322005179,"mc":[{"id":"1.195532865","rc":[{"atb":[[4.5,16.67],[4.6,16.55]],"id":35701941},{"atl":[[2.66,24.1],[2.68,231.26]],"id":37307439}],"con":true,"img":false}]}
{"op":"mcm","clk":"5322580803","pt":1646322005868,"mc":[{"id":"1.195532865","rc":[{"atb":[[2.04,0],[2.12,2.15]],"id":36909459}],"con":true,"img":false}]}
{"op":"mcm","clk":"5322580847","pt":1646322006384,"mc":[{"id":"1.195532865","rc":[{"atb":[[1.94,0],[1.87,28.09],[2.06,1.99]],"id":36909459},{"atl":[[2.72,0],[2.68,207.45]],"id":37307439}],"con":true,"img":false}]}
{"op":"mcm","clk":"5322580853","pt":1646322006444,"mc":[{"id":"1.195532865","rc":[{"atb":[[2.54,13.52]],"id":40133341},{"atl":[[2.7,67.72]],"id":37307439}],"con":true,"img":false}]}
{"op":"mcm","clk":"5322580868","pt":1646322006657,"mc":[{"id":"1.195532865","rc":[{"atl":[[3.7,0]],"id":36909459}],"con":true,"img":false}]}
{"op":"mcm","clk":"5322580884","pt":1646322006859,"mc":[{"id":"1.195532865","rc":[{"atl":[[3.75,3.11]],"id":36909459}],"con":true,"img":false}]}
{"op":"mcm","clk":"5322580890","pt":1646322006961,"mc":[{"id":"1.195532865","rc":[{"atl":[[2.7,58.82]],"id":37307439}],"con":true,"img":false}]}
{"op":"mcm","clk":"5322580898","pt":1646322007068,"mc":[{"id":"1.195532865","rc":[{"atb":[[2.54,8.21]],"id":40133341}],"con":true,"img":false}]}
{"op":"mcm","clk":"5322580907","pt":1646322007171,"mc":[{"id":"1.195532865","rc":[{"atl":[[3.8,0]],"id":36909459}],"con":true,"img":false}]}
{"op":"mcm","clk":"5322580913","pt":1646322007278,"mc":[{"id":"1.195532865","rc":[{"atl":[[3.9,68.96]],"id":36909459}],"con":true,"img":false}]}
{"op":"mcm","clk":"5322580919","pt":1646322007378,"mc":[{"id":"1.195532865","rc":[{"atb":[[2.06,0]],"id":36909459},{"atl":[[3.85,90.08]],"id":36909459}],"con":true,"img":false}]}
{"op":"mcm","clk":"5322580928","pt":1646322007480,"mc":[{"id":"1.195532865","rc":[{"atb":[[2.14,1.99]],"id":36909459}],"con":true,"img":false}]}
{"op":"mcm","clk":"5322580935","pt":1646322007539,"mc":[{"id":"1.195532865","rc":[{"atb":[[1.95,64.23]],"id":36909459}],"con":true,"img":false}]}
{"op":"mcm","clk":"5322580940","pt":1646322007643,"mc":[{"id":"1.195532865","rc":[{"atb":[[1.96,5.46]],"id":36909459}],"con":true,"img":false}]}
{"op":"mcm","clk":"5322580986","pt":1646322008271,"mc":[{"id":"1.195532865","rc":[{"atb":[[1.96,0]],"id":36909459},{"atl":[[3.85,14.03],[3.9,172.09]],"id":36909459}],"con":true,"img":false}]}
{"op":"mcm","clk":"5322581160","pt":1646322010349,"mc":[{"id":"1.195532865","rc":[{"atl":[[4.1,48.39]],"id":36909459}],"con":true,"img":false}]}
{"op":"mcm","clk":"5322581209","pt":1646322010867,"mc":[{"id":"1.195532865","rc":[{"atb":[[2.6,0]],"id":43189002},{"atb":[[5.1,0]],"id":35701941},{"atb":[[2.08,0]],"id":36909459}],"con":true,"img":false}]}
{"op":"mcm","clk":"5322581229","pt":1646322011072,"mc":[{"id":"1.195532865","rc":[{"atb":[[2.56,1.65]],"id":43189002},{"atb":[[5.3,1.65],[4.5,46.35],[4.6,2.57]],"id":35701941}],"con":true,"img":false}]}
{"op":"mcm","clk":"5322581252","pt":1646322011493,"mc":[{"id":"1.195532865","rc":[{"atb":[[1.81,5.63]],"id":36909459}],"con":true,"img":false}]}
{"op":"mcm","clk":"5322581269","pt":1646322011649,"mc":[{"id":"1.195532865","rc":[{"atb":[[1.81,0]],"id":36909459},{"atb":[[1.53,250]],"id":37307439},{"atl":[[2.78,140.45]],"id":37307439}],"con":true,"img":false}]}
{"op":"mcm","clk":"5322581298","pt":1646322012060,"mc":[{"id":"1.195532865","rc":[{"atl":[[3.8,9.09]],"id":36909459}],"con":true,"img":false}]}
{"op":"mcm","clk":"5322581310","pt":1646322012271,"mc":[{"id":"1.195532865","rc":[{"atl":[[3.8,0]],"id":36909459}],"con":true,"img":false}]}
{"op":"mcm","clk":"5322581337","pt":1646322012586,"mc":[{"id":"1.195532865","rc":[{"atb":[[1.88,10.77]],"id":36909459}],"con":true,"img":false}]}
{"op":"mcm","clk":"5322581402","pt":1646322013477,"mc":[{"id":"1.195532865","rc":[{"atb":[[1.95,2.72],[1.88,41.79]],"id":36909459}],"con":true,"img":false}]}
{"op":"mcm","clk":"5322581640","pt":1646322016176,"mc":[{"id":"1.195532865","rc":[{"atb":[[2.46,10.01]],"id":43189002}],"con":true,"img":false}]}
{"op":"mcm","clk":"5322581794","pt":1646322017894,"mc":[{"id":"1.195532865","rc":[{"atb":[[1.41,0]],"id":37307439}],"con":true,"img":false}]}
{"op":"mcm","clk":"5322581901","pt":1646322019196,"mc":[{"id":"1.195532865","rc":[{"atl":[[4.3,75.76]],"id":36909459}],"con":true,"img":false}]}
{"op":"mcm","clk":"5322581963","pt":1646322019877,"mc":[{"id":"1.195532865","rc":[{"atl":[[3.9,137.61]],"id":36909459}],"con":true,"img":false}]}
{"op":"mcm","clk":"5322581980","pt":1646322020097,"mc":[{"id":"1.195532865","rc":[{"atl":[[2.66,28.48]],"id":37307439}],"con":true,"img":false}]}
{"op":"mcm","clk":"5322581999","pt":1646322020306,"mc":[{"id":"1.195532865","rc":[{"spn":4.08,"spf":"NaN","id":40133341},{"spn":4.03,"spf":"NaN","id":43189002},{"spn":5.02,"spf":1.0,"id":35701941},{"spn":2.14,"spf":1.0,"id":36909459},{"atl":[[2.64,60.98],[2.68,147.93]],"id":37307439},{"spn":2.13,"spf":"NaN","id":37307439}],"con":true,"img":false}]}
{"op":"mcm","clk":"5322582016","pt":1646322020466,"mc":[{"id":"1.195532865","rc":[{"atl":[[2.66,182.96],[2.68,0]],"id":37307439}],"con":true,"img":false}]}
{"op":"mcm","clk":"5322582617","pt":1646322027494,"mc":[{"id":"1.195532865","rc":[{"atl":[[2.66,178.58]],"id":37307439}],"con":true,"img":false}]}
{"op":"mcm","clk":"5322582627","pt":1646322027599,"mc":[{"id":"1.195532865","rc":[{"atl":[[2.64,0]],"id":37307439}],"con":true,"img":false}]}
{"op":"mcm","clk":"5322582639","pt":1646322027700,"mc":[{"id":"1.195532865","rc":[{"atl":[[2.66,238.82]],"id":37307439}],"con":true,"img":false}]}
{"op":"mcm","clk":"5322582648","pt":1646322027806,"mc":[{"id":"1.195532865","rc":[{"atl":[[2.66,84.34],[2.64,3.31],[2.7,212.94]],"id":37307439}],"con":true,"img":false}]}
{"op":"mcm","clk":"5322582658","pt":1646322027906,"mc":[{"id":"1.195532865","rc":[{"atl":[[2.66,24.1],[2.7,271.76]],"id":37307439}],"con":true,"img":false}]}
{"op":"mcm","clk":"5322582863","pt":1646322030572,"mc":[{"id":"1.195532865","rc":[{"atl":[[2.64,0]],"id":37307439}],"con":true,"img":false}]}
{"op":"mcm","clk":"5322582887","pt":1646322030883,"mc":[{"id":"1.195532865","rc":[{"atl":[[2.6,4.4]],"id":37307439}],"con":true,"img":false}]}
{"op":"mcm","clk":"5322582894","pt":1646322030986,"mc":[{"id":"1.195532865","rc":[{"atl":[[2.58,50.63]],"id":37307439}],"con":true,"img":false}]}
{"op":"mcm","clk":"5322582902","pt":1646322031088,"mc":[{"id":"1.195532865","rc":[{"atl":[[2.68,14.56]],"id":37307439}],"con":true,"img":false}]}
{"op":"mcm","clk":"5322582911","pt":1646322031193,"mc":[{"id":"1.195532865","rc":[{"atl":[[2.62,6.25]],"id":37307439}],"con":true,"img":false}]}
{"op":"mcm","clk":"5322582925","pt":1646322031400,"mc":[{"id":"1.195532865","rc":[{"atl":[[2.62,0]],"id":37307439}],"con":true,"img":false}]}
{"op":"mcm","clk":"5322582949","pt":1646322031709,"mc":[{"id":"1.195532865","rc":[{"atl":[[2.68,0]],"id":37307439}],"con":true,"img":false}]}
{"op":"mcm","clk":"5322583047","pt":1646322032911,"mc":[{"id":"1.195532865","rc":[{"atl":[[2.66,159.74],[2.7,117.64]],"id":37307439}],"con":true,"img":false}]}
{"op":"mcm","clk":"5322583089","pt":1646322033489,"mc":[{"id":"1.195532865","rc":[{"atl":[[2.58,101.26]],"id":37307439}],"con":true,"img":false}]}
{"op":"mcm","clk":"5322583098","pt":1646322033592,"mc":[{"id":"1.195532865","rc":[{"atl":[[2.7,58.82]],"id":37307439}],"con":true,"img":false}]}
{"op":"mcm","clk":"5322583152","pt":1646322034218,"mc":[{"id":"1.195532865","rc":[{"atl":[[2.66,135.64],[2.62,24.69]],"id":37307439}],"con":true,"img":false}]}
{"op":"mcm","clk":"5322583318","pt":1646322035897,"mc":[{"id":"1.195532865","rc":[{"atl":[[5.6,0],[5.8,25.83],[5.9,25.62],[5.4,2.5]],"id":43189002},{"atl":[[4.6,0],[4.2,0]],"id":36909459},{"atb":[[1.51,0]],"id":37307439}],"con":true,"img":false}]}
{"op":"mcm","clk":"5322583326","pt":1646322036010,"mc":[{"id":"1.195532865","rc":[{"atl":[[5.6,20.53],[5.8,5],[5.5,8.04],[5.4,5.87]],"id":43189002}],"con":true,"img":false}]}
{"op":"mcm","clk":"5322583333","pt":1646322036103,"mc":[{"id":"1.195532865","rc":[{"atl":[[5.6,57.05],[5.5,0],[5.7,12.02],[5.9,20.41]],"id":43189002}],"con":true,"img":false}]}
{"op":"mcm","clk":"5322583343","pt":1646322036210,"mc":[{"id":"1.195532865","rc":[{"atl":[[5.6,36.52],[5.7,21.28]],"id":43189002}],"con":true,"img":false}]}
{"op":"mcm","clk":"5322583351","pt":1646322036313,"mc":[{"id":"1.195532865","rc":[{"atl":[[5.6,8.7]],"id":43189002}],"con":true,"img":false}]}
{"op":"mcm","clk":"5322583391","pt":1646322036787,"mc":[{"id":"1.195532865","rc":[{"atb":[[1.81,7.29]],"id":36909459}],"con":true,"img":false}]}
{"op":"mcm","clk":"5322583425","pt":1646322037306,"mc":[{"id":"1.195532865","rc":[{"atb":[[1.81,0]],"id":36909459}],"con":true,"img":false}]}
{"op":"mcm","clk":"5322583446","pt":1646322037520,"mc":[{"id":"1.195532865","rc":[{"atb":[[5.3,6.85]],"id":35701941}],"con":true,"img":false}]}
{"op":"mcm","clk":"5322583457","pt":1646322037621,"mc":[{"id":"1.195532865","rc":[{"atb":[[5.1,3.98]],"id":35701941}],"con":true,"img":false}]}
{"op":"mcm","clk":"5322583469","pt":1646322037725,"mc":[{"id":"1.195532865","rc":[{"atb":[[4.5,16.67],[4.6,16.61],[5.2,1.99]],"id":35701941}],"con":true,"img":false}]}
{"op":"mcm","clk":"5322583495","pt":1646322037884,"mc":[{"id":"1.195532865","rc":[{"atl":[[5.6,8.04],[6.2,19.23],[6,5],[5.7,0],[7,0]],"id":40133341}],"con":true,"img":false}]}
{"op":"mcm","clk":"5322583514","pt":1646322038095,"mc":[{"id":"1.195532865","rc":[{"atl":[[5.8,12.08],[6,60.82]],"id":40133341},{"atb":[[5.1,0]],"id":35701941}],"con":true,"img":false}]}
{"op":"mcm","clk":"5322583545","pt":1646322038611,"mc":[{"id":"1.195532865","rc":[{"atl":[[5.8,8.33]],"id":40133341}],"con":true,"img":false}]}
{"op":"mcm","clk":"5322583612","pt":1646322039501,"mc":[{"id":"1.195532865","rc":[{"atl":[[3.8,5.47],[3.75,0]],"id":36909459}],"con":true,"img":false}]}
{"op":"mcm","clk":"5322583620","pt":1646322039608,"mc":[{"id":"1.195532865","rc":[{"atl":[[3.95,41.19],[3.75,14.04]],"id":36909459}],"con":true,"img":false}]}
{"op":"mcm","clk":"5322583627","pt":1646322039711,"mc":[{"id":"1.195532865","rc":[{"atl":[[3.85,47.93],[3.9,103.13],[3.75,3.66]],"id":36909459}],"con":true,"img":false}]}
{"op":"mcm","clk":"5322583640","pt":1646322039815,"mc":[{"id":"1.195532865","rc":[{"atl":[[3.85,86.96],[3.9,0]],"id":36909459}],"con":true,"img":false}]}
{"op":"mcm","clk":"5322583649","pt":1646322039917,"mc":[{"id":"1.195532865","rc":[{"atb":[[5.2,0]],"id":35701941},{"atl":[[3.8,0]],"id":36909459}],"con":true,"img":false}]}
{"op":"mcm","clk":"5322583656","pt":1646322040022,"mc":[{"id":"1.195532865","rc":[{"atb":[[5.4,1.99]],"id":35701941},{"atl":[[2.66,0],[2.62,161.51]],"id":37307439}],"con":true,"img":false}]}
{"op":"mcm","clk":"5322583665","pt":1646322040126,"mc":[{"id":"1.195532865","rc":[{"atl":[[3.85,53.06],[3.95,67.8],[4.1,50.89]],"id":36909459},{"atl":[[2.6,0]],"id":37307439}],"con":true,"img":false}]}
{"op":"mcm","clk":"5322583685","pt":1646322040282,"mc":[{"id":"1.195532865","rc":[{"atl":[[2.7,117.64]],"id":37307439}],"con":true,"img":false}]}
{"op":"mcm","clk":"5322583691","pt":1646322040389,"mc":[{"id":"1.195532865","rc":[{"atl":[[2.58,55.02]],"id":37307439}],"con":true,"img":false}]}
{"op":"mcm","clk":"5322583755","pt":1646322041219,"mc":[{"id":"1.195532865","rc":[{"atb":[[2.36,0]],"id":40133341}],"con":true,"img":false}]}
{"op":"mcm","clk":"5322583778","pt":1646322041483,"mc":[{"id":"1.195532865","rc":[{"atb":[[8,6.67]],"id":35701941}],"con":true,"img":false}]}
{"op":"mcm","clk":"5322583800","pt":1646322041803,"mc":[{"id":"1.195532865","rc":[{"atb":[[5.4,0]],"id":35701941}],"con":true,"img":false}]}
{"op":"mcm","clk":"5322583811","pt":1646322041905,"mc":[{"id":"1.195532865","rc":[{"atb":[[1.02,1.99]],"id":35701941}],"con":true,"img":false}]}
{"op":"mcm","clk":"5322583870","pt":1646322042704,"mc":[{"id":"1.195532865","rc":[{"atl":[[2.66,60.24]],"id":37307439}],"con":true,"img":false}]}
{"op":"mcm","clk":"5322583975","pt":1646322044007,"mc":[{"id":"1.195532865","rc":[{"atl":[[2.78,0]],"id":37307439}],"con":true,"img":false}]}
{"op":"mcm","clk":"5322584075","pt":1646322045200,"mc":[{"id":"1.195532865","rc":[{"atb":[[2.58,2.48]],"id":40133341},{"atb":[[2.58,2.48]],"id":43189002},{"atb":[[3.35,3.23]],"id":28041476},{"atb":[[1.65,4.7]],"id":37307439}],"con":true,"img":false}]}
{"op":"mcm","clk":"5322584082","pt":1646322045305,"mc":[{"id":"1.195532865","rc":[{"atb":[[2.52,22.61],[2.58,14.67],[2.48,2.75]],"id":40133341},{"atb":[[2.46,2.5]],"id":43189002},{"atb":[[2.86,2.5],[3.35,18.79],[3.25,29.42],[3.3,54.54]],"id":28041476},{"atl":[[3.85,14.03],[3.95,159.7]],"id":36909459},{"atb":[[1.62,167.15],[1.61,60.3]],"id":37307439}],"con":true,"img":false}]}
{"op":"mcm","clk":"5322584092","pt":1646322045414,"mc":[{"id":"1.195532865","rc":[{"atb":[[2.56,4.21]],"id":43189002},{"atb":[[3.25,59.92]],"id":28041476}],"con":true,"img":false}]}
{"op":"mcm","clk":"5322584099","pt":1646322045517,"mc":[{"id":"1.195532865","rc":[{"atb":[[2.54,1.99]],"id":40133341},{"atb":[[3.3,1.99]],"id":28041476},{"atb":[[1.6,4.86]],"id":37307439},{"atl":[[2.66,221.46],[2.62,24.69]],"id":37307439}],"con":true,"img":false}]}
{"op":"mcm","clk":"5322584112","pt":1646322045727,"mc":[{"id":"1.195532865","rc":[{"atb":[[3.2,7.76],[3.25,29.42],[3.3,39.57]],"id":28041476},{"atb":[[1.6,0]],"id":37307439}],"con":true,"img":false}]}
{"op":"mcm","clk":"5322584119","pt":1646322045829,"mc":[{"id":"1.195532865","rc":[{"atb":[[3.2,0]],"id":28041476},{"atl":[[2.56,55.02],[2.7,58.82]],"id":37307439}],"con":true,"img":false}]}
{"op":"mcm","clk":"5322584126","pt":1646322045884,"mc":[{"id":"1.195532865","rc":[{"atb":[[2.5,16.43]],"id":40133341},{"atl":[[2.56,77.06]],"id":37307439}],"con":true,"img":false}]}
{"op":"mcm","clk":"5322584133","pt":1646322045991,"mc":[{"id":"1.195532865","rc":[{"atl":[[2.58,4.39]],"id":37307439}],"con":true,"img":false}]}
{"op":"mcm","clk":"5322584138","pt":1646322046093,"mc":[{"id":"1.195532865","rc":[{"atl":[[2.56,22.04],[2.62,86.42]],"id":37307439}],"con":true,"img":false}]}
{"op":"mcm","clk":"5322584149","pt":1646322046202,"mc":[{"id":"1.195532865","rc":[{"atb":[[2.54,0]],"id":40133341}],"con":true,"img":false}]}
{"op":"mcm","clk":"5322584155","pt":1646322046305,"mc":[{"id":"1.195532865","rc":[{"atb":[[2.6,1.99]],"id":40133341}],"con":true,"img":false}]}
{"op":"mcm","clk":"5322584165","pt":1646322046409,"mc":[{"id":"1.195532865","rc":[{"atb":[[2.5,0],[2.62,2.38]],"id":40133341}],"con":true,"img":false}]}
{"op":"mcm","clk":"5322584184","pt":1646322046622,"mc":[{"id":"1.195532865","rc":[{"atb":[[3.3,37.58]],"id":28041476}],"con":true,"img":false}]}
{"op":"mcm","clk":"5322584193","pt":1646322046722,"mc":[{"id":"1.195532865","rc":[{"atb":[[1.02,1.99]],"id":28041476}],"con":true,"img":false}]}
{"op":"mcm","clk":"5322584213","pt":1646322046911,"mc":[{"id":"1.195532865","rc":[{"atb":[[2.56,0]],"id":40133341},{"atb":[[2.56,2.55]],"id":43189002},{"atb":[[5.3,5.2]],"id":35701941}],"con":true,"img":false}]}
{"op":"mcm","clk":"5322584221","pt":1646322047019,"mc":[{"id":"1.195532865","rc":[{"atb":[[2.54,0]],"id":43189002}],"con":true,"img":false}]}
{"op":"mcm","clk":"5322584229","pt":1646322047121,"mc":[{"id":"1.195532865","rc":[{"atb":[[2.64,1.65]],"id":40133341},{"atb":[[2.6,3.64]],"id":43189002},{"atb":[[2.16,1.65]],"id":36909459}],"con":true,"img":false}]}
{"op":"mcm","clk":"5322584239","pt":1646322047227,"mc":[{"id":"1.195532865","rc":[{"atb":[[2.66,2.29]],"id":40133341},{"atb":[[2.62,2.38]],"id":43189002}],"con":true,"img":false}]}
{"op":"mcm","clk":"5322584250","pt":1646322047327,"mc":[{"id":"1.195532865","rc":[{"atb":[[1.95,11.86],[1.88,10.77]],"id":36909459}],"con":true,"img":false}]}
{"op":"mcm","clk":"5322584260","pt":1646322047431,"mc":[{"id":"1.195532865","rc":[{"atb":[[2.5,3.75]],"id":43189002},{"atb":[[1.94,5.3]],"id":36909459}],"con":true,"img":false}]}
{"op":"mcm","clk":"5322584275","pt":1646322047588,"mc":[{"id":"1.195532865","rc":[{"atb":[[2.5,0]],"id":43189002},{"atb":[[1.62,123.43]],"id":37307439}],"con":true,"img":false}]}
{"op":"mcm","clk":"5322584294","pt":1646322047904,"mc":[{"id":"1.195532865","rc":[{"atb":[[1.98,2.15],[2.12,0]],"id":36909459}],"con":true,"img":false}]}
{"op":"mcm","clk":"5322584301","pt":1646322048009,"mc":[{"id":"1.195532865","rc":[{"atl":[[5.3,7.14]],"id":43189002},{"atb":[[1.94,0]],"id":36909459}],"con":true,"img":false}]}
{"op":"mcm","clk":"5322584317","pt":1646322048113,"mc":[{"id":"1.195532865","rc":[{"atl":[[5.7,40.32],[5.4,2.5]],"id":43189002}],"con":true,"img":false}]}
{"op":"mcm","clk":"5322584369","pt":1646322048839,"mc":[{"id":"1.195532865","rc":[{"atl":[[5.6,0],[5.5,8.89]],"id":43189002}],"con":true,"img":false}]}
{"op":"mcm","clk":"5322584374","pt":1646322048893,"mc":[{"id":"1.195532865","rc":[{"atb":[[2.6,0]],"id":40133341},{"atl":[[5.5,18.53],[5.7,19.04]],"id":43189002}],"con":true,"img":false}]}
{"op":"mcm","clk":"5322584384","pt":1646322049003,"mc":[{"id":"1.195532865","rc":[{"atb":[[2.68,1.99]],"id":40133341}],"con":true,"img":false}]}
{"op":"mcm","clk":"5322584392","pt":1646322049105,"mc":[{"id":"1.195532865","rc":[{"atb":[[2.7,2.21]],"id":40133341}],"con":true,"img":false}]}
{"op":"mcm","clk":"5322584405","pt":1646322049210,"mc":[{"id":"1.195532865","rc":[{"atb":[[2.52,2.15]],"id":40133341},{"atb":[[2.6,1.65]],"id":43189002}],"con":true,"img":false}]}
{"op":"mcm","clk":"5322584416","pt":1646322049314,"mc":[{"id":"1.195532865","rc":[{"atb":[[2.64,1.99]],"id":43189002}],"con":true,"img":false}]}
{"op":"mcm","clk":"5322584425","pt":1646322049420,"mc":[{"id":"1.195532865","rc":[{"atb":[[2.14,0]],"id":36909459}],"con":true,"img":false}]}
{"op":"mcm","clk":"5322584434","pt":1646322049521,"mc":[{"id":"1.195532865","rc":[{"atb":[[2.66,2.29]],"id":43189002},{"atb":[[1.99,1.99]],"id":36909459}],"con":true,"img":false}]}
{"op":"mcm","clk":"5322584440","pt":1646322049625,"mc":[{"id":"1.195532865","rc":[{"atb":[[1.98,13.79]],"id":36909459}],"con":true,"img":false}]}
{"op":"mcm","clk":"5322584459","pt":1646322049936,"mc":[{"id":"1.195532865","rc":[{"atl":[[2.6,25],[2.62,61.73]],"id":37307439}],"con":true,"img":false}]}
{"op":"mcm","clk":"5322584479","pt":1646322050196,"mc":[{"id":"1.195532865","rc":[{"atb":[[2.68,0]],"id":40133341}],"con":true,"img":false}]}
{"op":"mcm","clk":"5322584489","pt":1646322050298,"mc":[{"id":"1.195532865","rc":[{"atb":[[2.72,1.99]],"id":40133341}],"con":true,"img":false}]}
{"op":"mcm","clk":"5322584497","pt":1646322050405,"mc":[{"id":"1.195532865","rc":[{"atb":[[2.58,12.19],[2.62,0],[2.48,0],[2.66,0],[2.7,0]],"id":40133341},{"atb":[[2.56,0]],"id":43189002},{"atb":[[1.88,0]],"id":36909459},{"atb":[[1.66,3.29]],"id":37307439}],"con":true,"img":false}]}
{"op":"mcm","clk":"5322584507","pt":1646322050510,"mc":[{"id":"1.195532865","rc":[{"atb":[[2.64,0]],"id":43189002},{"atb":[[1.62,0],[1.67,4.5]],"id":37307439}],"con":true,"img":false}]}
{"op":"mcm","clk":"5322584519","pt":1646322050610,"mc":[{"id":"1.195532865","rc":[{"atb":[[2.74,2.12]],"id":40133341},{"atb":[[2.68,1.99]],"id":43189002}],"con":true,"img":false}]}
{"op":"mcm","clk":"5322584524","pt":1646322050715,"mc":[{"id":"1.195532865","rc":[{"atb":[[2.58,0],[2.62,0],[2.52,0],[2.66,0]],"id":43189002},{"atb":[[1.6,3.96]],"id":37307439}],"con":true,"img":false}]}
{"op":"mcm","clk":"5322584533","pt":1646322050822,"mc":[{"id":"1.195532865","rc":[{"atb":[[2.38,15.81]],"id":43189002}],"con":true,"img":false}]}
{"op":"mcm","clk":"5322584544","pt":1646322051032,"mc":[{"id":"1.195532865","rc":[{"atb":[[2.72,0]],"id":40133341},{"atb":[[1.6,0]],"id":37307439}],"con":true,"img":false}]}
{"op":"mcm","clk":"5322584550","pt":1646322051136,"mc":[{"id":"1.195532865","rc":[{"atb":[[2.74,0],[2.76,1.99]],"id":40133341},{"atb":[[2.7,2.21]],"id":43189002}],"con":true,"img":false}]}
{"op":"mcm","clk":"5322584561","pt":1646322051235,"mc":[{"id":"1.195532865","rc":[{"atb":[[2.76,4.07]],"id":40133341}],"con":true,"img":false}]}
{"op":"mcm","clk":"5322584568","pt":1646322051339,"mc":[{"id":"1.195532865","rc":[{"atb":[[2.68,0]],"id":43189002}],"con":true,"img":false}]}
{"op":"mcm","clk":"5322584578","pt":1646322051393,"mc":[{"id":"1.195532865","rc":[{"atb":[[2.62,1.99]],"id":43189002}],"con":true,"img":false}]}
{"op":"mcm","clk":"5322584591","pt":1646322051603,"mc":[{"id":"1.195532865","rc":[{"atb":[[2.7,0]],"id":43189002},{"atl":[[2.56,44.08],[2.62,0]],"id":37307439}],"con":true,"img":false}]}
{"op":"mcm","clk":"5322584600","pt":1646322051704,"mc":[{"id":"1.195532865","rc":[{"atb":[[2.64,2.33]],"id":43189002}],"con":true,"img":false}]}
{"op":"mcm","clk":"5322584610","pt":1646322051916,"mc":[{"id":"1.195532865","rc":[{"atl":[[2.6,43.4],[2.66,60.24]],"id":37307439}],"con":true,"img":false}]}
{"op":"mcm","clk":"5322584637","pt":1646322052328,"mc":[{"id":"1.195532865","rc":[{"atb":[[2.62,0]],"id":43189002}],"con":true,"img":false}]}
{"op":"mcm","clk":"5322584646","pt":1646322052433,"mc":[{"id":"1.195532865","rc":[{"atb":[[2.66,1.99]],"id":43189002}],"con":true,"img":false}]}
{"op":"mcm","clk":"5322584656","pt":1646322052641,"mc":[{"id":"1.195532865","rc":[{"atb":[[2.68,2.25]],"id":43189002}],"con":true,"img":false}]}
{"op":"mcm","clk":"5322584792","pt":1646322054313,"mc":[{"id":"1.195532865","rc":[{"atb":[[2.66,0]],"id":43189002}],"con":true,"img":false}]}
{"op":"mcm","clk":"5322584801","pt":1646322054415,"mc":[{"id":"1.195532865","rc":[{"atb":[[2.64,0],[2.68,0],[2.7,1.99]],"id":43189002}],"con":true,"img":false}]}
{"op":"mcm","clk":"5322584834","pt":1646322054726,"mc":[{"id":"1.195532865","rc":[{"atb":[[1.2,2.24]],"id":43189002},{"atb":[[1.66,0]],"id":37307439}],"con":true,"img":false}]}
{"op":"mcm","clk":"5322584844","pt":1646322054828,"mc":[{"id":"1.195532865","rc":[{"atb":[[1.57,175.44],[1.67,0],[1.65,0]],"id":37307439}],"con":true,"img":false}]}
{"op":"mcm","clk":"5322584849","pt":1646322054931,"mc":[{"id":"1.195532865","rc":[{"atb":[[2.72,2.16]],"id":43189002}],"con":true,"img":false}]}
{"op":"mcm","clk":"5322584859","pt":1646322055138,"mc":[{"id":"1.195532865","rc":[{"atb":[[1.2,1.63]],"id":43189002}],"con":true,"img":false}]}
{"op":"mcm","clk":"5322584873","pt":1646322055295,"mc":[{"id":"1.195532865","rc":[{"atb":[[1.65,4.7]],"id":37307439}],"con":true,"img":false}]}
{"op":"mcm","clk":"5322584881","pt":1646322055401,"mc":[{"id":"1.195532865","rc":[{"atb":[[1.2,0],[2.7,0]],"id":43189002}],"con":true,"img":false}]}
{"op":"mcm","clk":"5322584888","pt":1646322055503,"mc":[{"id":"1.195532865","rc":[{"atb":[[2.74,1.99],[2.66,1.63]],"id":43189002}],"con":true,"img":false}]}
{"op":"mcm","clk":"5322584896","pt":1646322055606,"mc":[{"id":"1.195532865","rc":[{"atb":[[2.72,0],[2.76,2.08]],"id":43189002}],"con":true,"img":false}]}
{"op":"mcm","clk":"5322584906","pt":1646322055815,"mc":[{"id":"1.195532865","rc":[{"atb":[[2.64,0]],"id":40133341},{"atb":[[2.6,0]],"id":43189002},{"atb":[[1.96,4.01],[2.16,0]],"id":36909459}],"con":true,"img":false}]}
{"op":"mcm","clk":"5322584917","pt":1646322055920,"mc":[{"id":"1.195532865","rc":[{"atb":[[2,2.52],[1.87,0],[1.9,15.87]],"id":36909459}],"con":true,"img":false}]}
{"op":"mcm","clk":"5322584920","pt":1646322056025,"mc":[{"id":"1.195532865","rc":[{"atb":[[2.76,3.73]],"id":43189002}],"con":true,"img":false}]}
{"op":"mcm","clk":"5322584954","pt":1646322056543,"mc":[{"id":"1.195532865","rc":[{"atb":[[2.74,0]],"id":43189002}],"con":true,"img":false}]}
{"op":"mcm","clk":"5322584958","pt":1646322056598,"mc":[{"id":"1.195532865","rc":[{"atb":[[2.78,1.99]],"id":43189002}],"con":true,"img":false}]}
{"op":"mcm","clk":"5322584978","pt":1646322056915,"mc":[{"id":"1.195532865","rc":[{"atl":[[5.7,40.32]],"id":43189002},{"atb":[[1.99,0]],"id":36909459},{"atb":[[1.62,5.84]],"id":37307439}],"con":true,"img":false}]}
{"op":"mcm","clk":"5322584985","pt":1646322057016,"mc":[{"id":"1.195532865","rc":[{"atb":[[2.02,1.99]],"id":36909459}],"con":true,"img":false}]}
{"op":"mcm","clk":"5322584991","pt":1646322057121,"mc":[{"id":"1.195532865","rc":[{"atb":[[2.52,22.61]],"id":40133341},{"atb":[[2.04,4.76]],"id":36909459},{"atb":[[1.62,19.03]],"id":37307439}],"con":true,"img":false}]}
{"op":"mcm","clk":"5322585049","pt":1646322057799,"mc":[{"id":"1.195532865","rc":[{"atb":[[2.02,0]],"id":36909459}],"con":true,"img":false}]}
{"op":"mcm","clk":"5322585059","pt":1646322057904,"mc":[{"id":"1.195532865","rc":[{"atb":[[2.06,1.99]],"id":36909459}],"con":true,"img":false}]}
{"op":"mcm","clk":"5322585066","pt":1646322058009,"mc":[{"id":"1.195532865","rc":[{"atb":[[2,0],[2.04,0],[1.95,9.14]],"id":36909459}],"con":true,"img":false}]}
{"op":"mcm","clk":"5322585091","pt":1646322058526,"mc":[{"id":"1.195532865","rc":[{"atl":[[2.62,19.18]],"id":37307439}],"con":true,"img":false}]}
{"op":"mcm","clk":"5322585098","pt":1646322058629,"mc":[{"id":"1.195532865","rc":[{"atb":[[2.08,4.5]],"id":36909459}],"con":true,"img":false}]}
{"op":"mcm","clk":"5322585126","pt":1646322059044,"mc":[{"id":"1.195532865","rc":[{"atb":[[2.06,0]],"id":36909459},{"atl":[[2.62,0]],"id":37307439}],"con":true,"img":false}]}
{"op":"mcm","clk":"5322585133","pt":1646322059098,"mc":[{"id":"1.195532865","rc":[{"atb":[[1.96,27.18],[1.95,0],[2.1,1.99]],"id":36909459}],"con":true,"img":false}]}
{"op":"mcm","clk":"5322585140","pt":1646322059199,"mc":[{"id":"1.195532865","rc":[{"atb":[[2.1,6.37],[2.08,0]],"id":36909459}],"con":true,"img":false}]}
{"op":"mcm","clk":"5322585186","pt":1646322059931,"mc":[{"id":"1.195532865","rc":[{"atl":[[5.5,44.27],[5.2,4.68],[5.7,21.28]],"id":43189002}],"con":true,"img":false}]}
{"op":"mcm","clk":"5322585200","pt":1646322060143,"mc":[{"id":"1.195532865","rc":[{"atl":[[5.3,0],[5.5,52.07]],"id":43189002}],"con":true,"img":false}]}
{"op":"mcm","clk":"5322585230","pt":1646322060515,"mc":[{"id":"1.195532865","rc":[{"atl":[[5.5,44.27]],"id":43189002}],"con":true,"img":false}]}
{"op":"mcm","clk":"5322585304","pt":1646322061451,"mc":[{"id":"1.195532865","rc":[{"atb":[[2.66,0]],"id":43189002},{"atb":[[2.1,27.25]],"id":36909459}],"con":true,"img":false}]}
{"op":"mcm","clk":"5322585318","pt":1646322061610,"mc":[{"id":"1.195532865","rc":[{"atb":[[1.98,2.15]],"id":36909459}],"con":true,"img":false}]}
{"op":"mcm","clk":"5322585422","pt":1646322063028,"mc":[{"id":"1.195532865","rc":[{"atl":[[4.2,4.24]],"id":36909459}],"con":true,"img":false}]}
{"op":"mcm","clk":"5322585429","pt":1646322063140,"mc":[{"id":"1.195532865","rc":[{"atl":[[4.2,0]],"id":36909459}],"con":true,"img":false}]}
{"op":"mcm","clk":"5322585450","pt":1646322063349,"mc":[{"id":"1.195532865","rc":[{"atb":[[1.96,23.17]],"id":36909459}],"con":true,"img":false}]}
{"op":"mcm","clk":"5322585525","pt":1646322064340,"mc":[{"id":"1.195532865","rc":[{"atl":[[5.4,11.59]],"id":43189002}],"con":true,"img":false}]}
{"op":"mcm","clk":"5322585530","pt":1646322064443,"mc":[{"id":"1.195532865","rc":[{"atl":[[6.2,0],[5.5,35.38],[5.7,0],[6.6,0],[5.9,0]],"id":43189002}],"con":true,"img":false}]}
{"op":"mcm","clk":"5322585569","pt":1646322064915,"mc":[{"id":"1.195532865","rc":[{"atb":[[2.76,2.08]],"id":43189002}],"con":true,"img":false}]}
{"op":"mcm","clk":"5322585574","pt":1646322065020,"mc":[{"id":"1.195532865","rc":[{"atb":[[2.8,1.65]],"id":43189002},{"atb":[[2.12,1.65]],"id":36909459}],"con":true,"img":false}]}
{"op":"mcm","clk":"5322585583","pt":1646322065120,"mc":[{"id":"1.195532865","rc":[{"atb":[[2.38,5],[2.46,12.91]],"id":43189002}],"con":true,"img":false}]}
{"op":"mcm","clk":"5322585600","pt":1646322065433,"mc":[{"id":"1.195532865","rc":[{"atb":[[2.4,14.88]],"id":43189002},{"atb":[[3.35,48.21],[3.3,0]],"id":28041476}],"con":true,"img":false}]}
{"op":"mcm","clk":"5322585609","pt":1646322065540,"mc":[{"id":"1.195532865","rc":[{"atb":[[2.86,56.51],[3.25,3.48],[3.3,37.58]],"id":28041476}],"con":true,"img":false}]}
{"op":"mcm","clk":"5322585619","pt":1646322065647,"mc":[{"id":"1.195532865","rc":[{"atb":[[3.35,18.79]],"id":28041476}],"con":true,"img":false}]}
{"op":"mcm","clk":"5322585637","pt":1646322065853,"mc":[{"id":"1.195532865","rc":[{"atb":[[2.86,2.5]],"id":28041476}],"con":true,"img":false}]}
{"op":"mcm","clk":"5322585711","pt":1646322066742,"mc":[{"id":"1.195532865","rc":[{"atb":[[2.36,0],[2.52,2.15]],"id":43189002}],"con":true,"img":false}]}
{"op":"mcm","clk":"5322585724","pt":1646322066951,"mc":[{"id":"1.195532865","rc":[{"atb":[[2.46,2.5]],"id":43189002}],"con":true,"img":false}]}
{"op":"mcm","clk":"5322585784","pt":1646322067739,"mc":[{"id":"1.195532865","rc":[{"atb":[[2.14,4.13],[1.91,40.11]],"id":36909459}],"con":true,"img":false}]}
{"op":"mcm","clk":"5322585798","pt":1646322067947,"mc":[{"id":"1.195532865","rc":[{"atb":[[1.98,7.74]],"id":36909459}],"con":true,"img":false}]}
{"op":"mcm","clk":"5322585819","pt":1646322068262,"mc":[{"id":"1.195532865","rc":[{"atb":[[1.98,2.15]],"id":36909459}],"con":true,"img":false}]}
{"op":"mcm","clk":"5322585837","pt":1646322068524,"mc":[{"id":"1.195532865","rc":[{"atb":[[2.1,25.26]],"id":36909459}],"con":true,"img":false}]}
{"op":"mcm","clk":"5322585847","pt":1646322068630,"mc":[{"id":"1.195532865","rc":[{"atb":[[2.32,3.72]],"id":40133341},{"atb":[[2.84,3.35]],"id":28041476},{"atb":[[2.16,1.99]],"id":36909459}],"con":true,"img":false}]}
{"op":"mcm","clk":"5322585881","pt":1646322069152,"mc":[{"id":"1.195532865","rc":[{"atb":[[2.32,0]],"id":40133341},{"atb":[[2.84,0]],"id":28041476}],"con":true,"img":false}]}
{"op":"mcm","clk":"5322585897","pt":1646322069359,"mc":[{"id":"1.195532865","rc":[{"atb":[[2.16,6.02]],"id":36909459}],"con":true,"img":false}]}
{"op":"mcm","clk":"5322585909","pt":1646322069517,"mc":[{"id":"1.195532865","rc":[{"atb":[[1.78,0],[1.82,0],[1.74,0]],"id":36909459}],"con":true,"img":false}]}
{"op":"mcm","clk":"5322585945","pt":1646322070043,"mc":[{"id":"1.195532865","rc":[{"atb":[[2.4,0]],"id":43189002},{"atb":[[1.91,0]],"id":36909459}],"con":true,"img":false}]}
{"op":"mcm","clk":"5322586002","pt":1646322070626,"mc":[{"id":"1.195532865","rc":[{"atb":[[1.96,0],[2.1,50.34]],"id":36909459}],"con":true,"img":false}]}
{"op":"mcm","clk":"5322586025","pt":1646322070945,"mc":[{"id":"1.195532865","rc":[{"atb":[[3.3,48.22]],"id":28041476}],"con":true,"img":false}]}
{"op":"mcm","clk":"5322586045","pt":1646322071157,"mc":[{"id":"1.195532865","rc":[{"atb":[[3.3,37.58]],"id":28041476}],"con":true,"img":false}]}
{"op":"mcm","clk":"5322586119","pt":1646322072248,"mc":[{"id":"1.195532865","rc":[{"atl":[[5.6,21.74]],"id":43189002}],"con":true,"img":false}]}
{"op":"mcm","clk":"5322586149","pt":1646322072770,"mc":[{"id":"1.195532865","rc":[{"atb":[[3.55,15.69],[3.4,0]],"id":35701941},{"atb":[[1.59,0],[1.54,74.07]],"id":37307439}],"con":true,"img":false}]}
{"op":"mcm","clk":"5322586156","pt":1646322072826,"mc":[{"id":"1.195532865","rc":[{"atb":[[1.58,8.47]],"id":37307439}],"con":true,"img":false}]}
{"op":"mcm","clk":"5322586179","pt":1646322073246,"mc":[{"id":"1.195532865","rc":[{"atb":[[1.58,0]],"id":37307439}],"con":true,"img":false}]}
{"op":"mcm","clk":"5322586233","pt":1646322074030,"mc":[{"id":"1.195532865","rc":[{"atb":[[2.12,0]],"id":36909459}],"con":true,"img":false}]}
{"op":"mcm","clk":"5322586241","pt":1646322074133,"mc":[{"id":"1.195532865","rc":[{"atb":[[2.6,6.51]],"id":40133341},{"atb":[[2.18,4.21]],"id":36909459}],"con":true,"img":false}]}
{"op":"mcm","clk":"5322586249","pt":1646322074235,"mc":[{"id":"1.195532865","rc":[{"atb":[[2.18,5.87]],"id":36909459}],"con":true,"img":false}]}
{"op":"mcm","clk":"5322586260","pt":1646322074342,"mc":[{"id":"1.195532865","rc":[{"atb":[[2.52,2.15],[2.58,32.65]],"id":40133341},{"atb":[[2.1,25.26],[2.08,12.79],[2.16,4.03]],"id":36909459}],"con":true,"img":false}]}
{"op":"mcm","clk":"5322586265","pt":1646322074444,"mc":[{"id":"1.195532865","rc":[{"atb":[[2.2,1.99]],"id":36909459}],"con":true,"img":false}]}
{"op":"mcm","clk":"5322586274","pt":1646322074653,"mc":[{"id":"1.195532865","rc":[{"atb":[[2.22,39.11],[2.12,0]],"id":43189002},{"atb":[[1.62,5.84],[1.61,0]],"id":37307439}],"con":true,"img":false}]}
{"op":"mcm","clk":"5322586283","pt":1646322074758,"mc":[{"id":"1.195532865","rc":[{"atb":[[1.61,29.67]],"id":37307439}],"con":true,"img":false}]}
{"op":"mcm","clk":"5322586292","pt":1646322074863,"mc":[{"id":"1.195532865","rc":[{"atb":[[2.58,36.77]],"id":40133341},{"atb":[[2.08,0]],"id":36909459}],"con":true,"img":false}]}
{"op":"mcm","clk":"5322586299","pt":1646322074968,"mc":[{"id":"1.195532865","rc":[{"atb":[[2.58,32.65]],"id":40133341},{"atb":[[1.61,0]],"id":37307439}],"con":true,"img":false}]}
{"op":"mcm","clk":"5322586329","pt":1646322075255,"mc":[{"id":"1.195532865","rc":[{"atl":[[3.75,0]],"id":36909459}],"con":true,"img":false}]}
{"op":"mcm","clk":"5322586338","pt":1646322075359,"mc":[{"id":"1.195532865","rc":[{"atl":[[3.8,7.43]],"id":36909459}],"con":true,"img":false}]}
{"op":"mcm","clk":"5322586348","pt":1646322075460,"mc":[{"id":"1.195532865","rc":[{"atl":[[3.95,33.9],[4.1,126.95]],"id":36909459}],"con":true,"img":false}]}
{"op":"mcm","clk":"5322586354","pt":1646322075567,"mc":[{"id":"1.195532865","rc":[{"atl":[[3.95,67.8],[4.1,94.69]],"id":36909459}],"con":true,"img":false}]}
{"op":"mcm","clk":"5322586379","pt":1646322075929,"mc":[{"id":"1.195532865","rc":[{"atl":[[3.95,84.42]],"id":36909459}],"con":true,"img":false}]}
{"op":"mcm","clk":"5322586405","pt":1646322076452,"mc":[{"id":"1.195532865","rc":[{"atl":[[3.95,67.8]],"id":36909459}],"con":true,"img":false}]}
{"op":"mcm","clk":"5322586409","pt":1646322076554,"mc":[{"id":"1.195532865","rc":[{"atb":[[2.52,12.56]],"id":43189002}],"con":true,"img":false}]}
{"op":"mcm","clk":"5322586438","pt":1646322076973,"mc":[{"id":"1.195532865","rc":[{"atb":[[3.25,44.2]],"id":28041476}],"con":true,"img":false}]}
{"op":"mcm","clk":"5322586546","pt":1646322078382,"mc":[{"id":"1.195532865","rc":[{"atb":[[1.62,0]],"id":37307439}],"con":true,"img":false}]}
{"op":"mcm","clk":"5322586562","pt":1646322078541,"mc":[{"id":"1.195532865","rc":[{"atb":[[1.57,235.56]],"id":37307439}],"con":true,"img":false}]}
{"op":"mcm","clk":"5322586648","pt":1646322079534,"mc":[{"id":"1.195532865","rc":[{"atb":[[1.6,2.15]],"id":37307439}],"con":true,"img":false}]}
{"op":"mcm","clk":"5322586660","pt":1646322079637,"mc":[{"id":"1.195532865","rc":[{"atb":[[1.64,0]],"id":37307439}],"con":true,"img":false}]}
{"op":"mcm","clk":"5322586671","pt":1646322079742,"mc":[{"id":"1.195532865","rc":[{"atb":[[1.65,0]],"id":37307439}],"con":true,"img":false}]}
{"op":"mcm","clk":"5322586680","pt":1646322079845,"mc":[{"id":"1.195532865","rc":[{"atb":[[1.6,67.76],[1.61,5.13]],"id":37307439}],"con":true,"img":false}]}
{"op":"mcm","clk":"5322586691","pt":1646322080052,"mc":[{"id":"1.195532865","rc":[{"atl":[[5.8,36.25]],"id":43189002}],"con":true,"img":false}]}
{"op":"mcm","clk":"5322586728","pt":1646322080574,"mc":[{"id":"1.195532865","rc":[{"spn":4.18,"spf":"NaN","id":40133341},{"spn":4.0,"spf":"NaN","id":43189002},{"atb":[[3.45,40.82]],"id":35701941},{"spn":6.7,"spf":1.0,"id":35701941},{"spn":5.07,"spf":"NaN","id":28041476},{"atl":[[3.85,0],[3.9,13.79]],"id":36909459},{"spn":2.2,"spf":1.0,"id":36909459},{"atb":[[1.57,60.12],[1.52,192.31]],"id":37307439},{"spn":2.08,"spf":"NaN","id":37307439}],"con":true,"img":false}]}
{"op":"mcm","clk":"5322586858","pt":1646322082245,"mc":[{"id":"1.195532865","rc":[{"atb":[[3.1,0],[3.3,0],[3.2,0]],"id":35701941},{"atb":[[1.55,0]],"id":37307439}],"con":true,"img":false}]}
{"op":"mcm","clk":"5322586878","pt":1646322082456,"mc":[{"id":"1.195532865","rc":[{"atb":[[1.58,5.63]],"id":37307439}],"con":true,"img":false}]}
{"op":"mcm","clk":"5322586923","pt":1646322082977,"mc":[{"id":"1.195532865","rc":[{"atb":[[2.18,4.21]],"id":36909459}],"con":true,"img":false}]}
{"op":"mcm","clk":"5322586943","pt":1646322083183,"mc":[{"id":"1.195532865","rc":[{"atb":[[2.22,1.65]],"id":36909459}],"con":true,"img":false}]}
{"op":"mcm","clk":"5322587122","pt":1646322085786,"mc":[{"id":"1.195532865","rc":[{"atb":[[2.3,30.77],[2.26,0]],"id":40133341},{"atb":[[2.1,127.27]],"id":43189002}],"con":true,"img":false}]}
{"op":"mcm","clk":"5322587132","pt":1646322085886,"mc":[{"id":"1.195532865","rc":[{"atb":[[2.14,0],[2.1,36.36]],"id":43189002}],"con":true,"img":false}]}
{"op":"mcm","clk":"5322587161","pt":1646322086254,"mc":[{"id":"1.195532865","rc":[{"atl":[[4,9.03]],"id":36909459}],"con":true,"img":false}]}
{"op":"mcm","clk":"5322587173","pt":1646322086462,"mc":[{"id":"1.195532865","rc":[{"atb":[[2.18,0]],"id":36909459}],"con":true,"img":false}]}
{"op":"mcm","clk":"5322587186","pt":1646322086674,"mc":[{"id":"1.195532865","rc":[{"atl":[[3.95,90.92],[4.1,50.89]],"id":36909459}],"con":true,"img":false}]}
{"op":"mcm","clk":"5322587191","pt":1646322086780,"mc":[{"id":"1.195532865","rc":[{"atl":[[4,0]],"id":36909459}],"con":true,"img":false}]}
{"op":"mcm","clk":"5322587219","pt":1646322087193,"mc":[{"id":"1.195532865","rc":[{"atb":[[2.2,0]],"id":36909459}],"con":true,"img":false}]}
{"op":"mcm","clk":"5322587230","pt":1646322087248,"mc":[{"id":"1.195532865","rc":[{"atb":[[2.18,1.99]],"id":36909459}],"con":true,"img":false}]}
{"op":"mcm","clk":"5322587237","pt":1646322087353,"mc":[{"id":"1.195532865","rc":[{"atb":[[2.1,51.78]],"id":36909459}],"con":true,"img":false}]}
{"op":"mcm","clk":"5322587250","pt":1646322087563,"mc":[{"id":"1.195532865","rc":[{"atb":[[2.1,25.26]],"id":36909459}],"con":true,"img":false}]}
{"op":"mcm","clk":"5322587293","pt":1646322088189,"mc":[{"id":"1.195532865","rc":[{"atb":[[3.35,63.83]],"id":35701941}],"con":true,"img":false}]}
{"op":"mcm","clk":"5322587300","pt":1646322088291,"mc":[{"id":"1.195532865","rc":[{"atb":[[3.35,56.37],[3.3,0]],"id":28041476},{"atl":[[4,33.33]],"id":36909459},{"atb":[[1.5,364.48]],"id":37307439}],"con":true,"img":false}]}
{"op":"mcm","clk":"5322587309","pt":1646322088451,"mc":[{"id":"1.195532865","rc":[{"atl":[[5.7,4.97]],"id":40133341},{"atb":[[2.86,74.99],[3.25,3.48]],"id":28041476}],"con":true,"img":false}]}
{"op":"mcm","clk":"5322587317","pt":1646322088556,"mc":[{"id":"1.195532865","rc":[{"atl":[[5.6,16.08],[5.8,37.43],[6,5]],"id":40133341}],"con":true,"img":false}]}
{"op":"mcm","clk":"5322587325","pt":1646322088662,"mc":[{"id":"1.195532865","rc":[{"atl":[[5.8,58.26],[5.7,0]],"id":40133341}],"con":true,"img":false}]}
{"op":"mcm","clk":"5322587338","pt":1646322088770,"mc":[{"id":"1.195532865","rc":[{"atl":[[5.6,8.04]],"id":40133341}],"con":true,"img":false}]}
{"op":"mcm","clk":"5322587345","pt":1646322088877,"mc":[{"id":"1.195532865","rc":[{"atl":[[6,25]],"id":40133341}],"con":true,"img":false}]}
{"op":"mcm","clk":"5322587355","pt":1646322088977,"mc":[{"id":"1.195532865","rc":[{"atl":[[5.8,37.43]],"id":40133341}],"con":true,"img":false}]}
{"op":"mcm","clk":"5322587411","pt":1646322089764,"mc":[{"id":"1.195532865","rc":[{"atb":[[1.58,66.93]],"id":37307439}],"con":true,"img":false}]}
{"op":"mcm","clk":"5322587418","pt":1646322089868,"mc":[{"id":"1.195532865","rc":[{"atb":[[1.57,0]],"id":37307439}],"con":true,"img":false}]}
{"op":"mcm","clk":"5322587431","pt":1646322090078,"mc":[{"id":"1.195532865","rc":[{"atl":[[5.6,5.54],[5.5,2.5],[6,20],[5.9,5]],"id":40133341}],"con":true,"img":false}]}
{"op":"mcm","clk":"5322587441","pt":1646322090287,"mc":[{"id":"1.195532865","rc":[{"atl":[[5.5,13.41]],"id":40133341}],"con":true,"img":false}]}
{"op":"mcm","clk":"5322587453","pt":1646322090493,"mc":[{"id":"1.195532865","rc":[{"atl":[[5.6,0]],"id":40133341},{"atl":[[3.8,18.43]],"id":36909459},{"atb":[[1.58,61.3]],"id":37307439}],"con":true,"img":false}]}
{"op":"mcm","clk":"5322587459","pt":1646322090597,"mc":[{"id":"1.195532865","rc":[{"atb":[[2.2,2.55]],"id":36909459}],"con":true,"img":false}]}
{"op":"mcm","clk":"5322587492","pt":1646322091073,"mc":[{"id":"1.195532865","rc":[{"atb":[[1.85,9.72]],"id":36909459}],"con":true,"img":false}]}
{"op":"mcm","clk":"5322587506","pt":1646322091287,"mc":[{"id":"1.195532865","rc":[{"atb":[[2.18,0]],"id":36909459}],"con":true,"img":false}]}
{"op":"mcm","clk":"5322587514","pt":1646322091393,"mc":[{"id":"1.195532865","rc":[{"atb":[[1.85,0],[1.02,1.99]],"id":36909459}],"con":true,"img":false}]}
{"op":"mcm","clk":"5322587624","pt":1646322092810,"mc":[{"id":"1.195532865","rc":[{"atb":[[1.62,3.59]],"id":37307439}],"con":true,"img":false}]}
{"op":"mcm","clk":"5322587638","pt":1646322092973,"mc":[{"id":"1.195532865","rc":[{"atb":[[1.63,4.91]],"id":37307439}],"con":true,"img":false}]}
{"op":"mcm","clk":"5322587650","pt":1646322093078,"mc":[{"id":"1.195532865","rc":[{"atb":[[3.35,67.37]],"id":28041476}],"con":true,"img":false}]}
{"op":"mcm","clk":"5322587661","pt":1646322093183,"mc":[{"id":"1.195532865","rc":[{"atb":[[2.86,85.87]],"id":28041476},{"atb":[[1.58,0]],"id":37307439}],"con":true,"img":false}]}
{"op":"mcm","clk":"5322587679","pt":1646322093392,"mc":[{"id":"1.195532865","rc":[{"atb":[[2.26,79.37]],"id":40133341},{"atl":[[5.8,29.1],[5.7,8.51]],"id":40133341},{"atb":[[2.06,94.34]],"id":43189002},{"atl":[[6,50]],"id":43189002},{"atb":[[2.86,74.99]],"id":28041476}],"con":true,"img":false}]}
{"op":"mcm","clk":"5322587725","pt":1646322093967,"mc":[{"id":"1.195532865","rc":[{"atl":[[5.8,49.93],[6,0]],"id":40133341}],"con":true,"img":false}]}
{"op":"mcm","clk":"5322587739","pt":1646322094180,"mc":[{"id":"1.195532865","rc":[{"atb":[[1.64,2.15],[1.6,65.61]],"id":37307439}],"con":true,"img":false}]}
{"op":"mcm","clk":"5322587754","pt":1646322094389,"mc":[{"id":"1.195532865","rc":[{"atb":[[1.65,4.7]],"id":37307439}],"con":true,"img":false}]}
{"op":"mcm","clk":"5322587866","pt":1646322095797,"mc":[{"id":"1.195532865","rc":[{"atb":[[3.25,111.11]],"id":35701941},{"atl":[[4.3,0],[3.95,57.02],[4.1,2.5],[4.2,46.88]],"id":36909459},{"atb":[[1.48,250]],"id":37307439}],"con":true,"img":false}]}
{"op":"mcm","clk":"5322587973","pt":1646322096997,"mc":[{"id":"1.195532865","rc":[{"atb":[[1.62,0]],"id":37307439}],"con":true,"img":false}]}
{"op":"mcm","clk":"5322588295","pt":1646322100787,"mc":[{"id":"1.195532865","rc":[{"atb":[[2.22,122.95],[2.14,0]],"id":40133341},{"atl":[[5.9,25.41]],"id":40133341},{"atb":[[2.02,147.06]],"id":43189002}],"con":true,"img":false}]}
{"op":"mcm","clk":"5322588303","pt":1646322100895,"mc":[{"id":"1.195532865","rc":[{"atb":[[3.4,1.65]],"id":28041476}],"con":true,"img":false}]}
{"op":"mcm","clk":"5322588312","pt":1646322100999,"mc":[{"id":"1.195532865","rc":[{"atb":[[3.45,3.01],[3.4,14.6]],"id":28041476}],"con":true,"img":false}]}
{"op":"mcm","clk":"5322588323","pt":1646322101105,"mc":[{"id":"1.195532865","rc":[{"atb":[[3.35,102.87],[2.86,2.5],[2.9,13.02]],"id":28041476}],"con":true,"img":false}]}
{"op":"mcm","clk":"5322588334","pt":1646322101209,"mc":[{"id":"1.195532865","rc":[{"atb":[[3.35,87.31]],"id":28041476}],"con":true,"img":false}]}
{"op":"mcm","clk":"5322588350","pt":1646322101419,"mc":[{"id":"1.195532865","rc":[{"atb":[[2.9,0]],"id":28041476},{"atb":[[1.66,3.29]],"id":37307439}],"con":true,"img":false}]}
{"op":"mcm","clk":"5322588362","pt":1646322101523,"mc":[{"id":"1.195532865","rc":[{"atb":[[1.67,4.5]],"id":37307439}],"con":true,"img":false}]}
{"op":"mcm","clk":"5322588506","pt":1646322103215,"mc":[{"id":"1.195532865","rc":[{"atl":[[4.4,73.53]],"id":36909459},{"atb":[[1.53,0],[1.52,203.81]],"id":37307439}],"con":true,"img":false}]}
{"op":"mcm","clk":"5322588536","pt":1646322103524,"mc":[{"id":"1.195532865","rc":[{"atb":[[1.52,192.31]],"id":37307439}],"con":true,"img":false}]}
{"op":"mcm","clk":"5322588637","pt":1646322104719,"mc":[{"id":"1.195532865","rc":[{"atb":[[1.64,0],[1.68,2.15]],"id":37307439}],"con":true,"img":false}]}
{"op":"mcm","clk":"5322588657","pt":1646322104927,"mc":[{"id":"1.195532865","rc":[{"atb":[[1.69,4.32]],"id":37307439}],"con":true,"img":false}]}
{"op":"mcm","clk":"5322588696","pt":1646322105292,"mc":[{"id":"1.195532865","rc":[{"atb":[[1.66,0]],"id":37307439}],"con":true,"img":false}]}
{"op":"mcm","clk":"5322588938","pt":1646322108113,"mc":[{"id":"1.195532865","rc":[{"atb":[[2.18,211.86]],"id":40133341},{"atl":[[6.2,28.85],[10.5,0]],"id":40133341}],"con":true,"img":false}]}
{"op":"mcm","clk":"5322588948","pt":1646322108216,"mc":[{"id":"1.195532865","rc":[{"atb":[[1.99,250]],"id":43189002}],"con":true,"img":false}]}
{"op":"mcm","clk":"5322589085","pt":1646322109829,"mc":[{"id":"1.195532865","rc":[{"atb":[[1.7,3.02]],"id":37307439}],"con":true,"img":false}]}
{"op":"mcm","clk":"5322589106","pt":1646322109988,"mc":[{"id":"1.195532865","rc":[{"atb":[[3.4,12.95]],"id":28041476},{"atb":[[1.71,4.16]],"id":37307439}],"con":true,"img":false}]}
{"op":"mcm","clk":"5322589131","pt":1646322110201,"mc":[{"id":"1.195532865","rc":[{"atb":[[3.5,1.65]],"id":28041476}],"con":true,"img":false}]}
{"op":"mcm","clk":"5322589139","pt":1646322110304,"mc":[{"id":"1.195532865","rc":[{"atb":[[3.55,2.81]],"id":28041476}],"con":true,"img":false}]}
{"op":"mcm","clk":"5322589252","pt":1646322111713,"mc":[{"id":"1.195532865","rc":[{"atb":[[3.55,7.17]],"id":28041476}],"con":true,"img":false}]}
{"op":"mcm","clk":"5322589262","pt":1646322111820,"mc":[{"id":"1.195532865","rc":[{"atb":[[3.35,51.81],[3.4,34.97]],"id":28041476}],"con":true,"img":false}]}
{"op":"mcm","clk":"5322589271","pt":1646322111923,"mc":[{"id":"1.195532865","rc":[{"atb":[[3.4,22.02]],"id":28041476}],"con":true,"img":false}]}
{"op":"mcm","clk":"5322589285","pt":1646322112131,"mc":[{"id":"1.195532865","rc":[{"atl":[[6,4.4]],"id":40133341}],"con":true,"img":false}]}
{"op":"mcm","clk":"5322589327","pt":1646322112605,"mc":[{"id":"1.195532865","rc":[{"atl":[[6,0]],"id":40133341}],"con":true,"img":false}]}
{"op":"mcm","clk":"5322589334","pt":1646322112710,"mc":[{"id":"1.195532865","rc":[{"atb":[[2.08,5.9]],"id":36909459}],"con":true,"img":false}]}
{"op":"mcm","clk":"5322589371","pt":1646322113130,"mc":[{"id":"1.195532865","rc":[{"atb":[[2.08,0]],"id":36909459}],"con":true,"img":false}]}
{"op":"mcm","clk":"5322589449","pt":1646322114018,"mc":[{"id":"1.195532865","rc":[{"atb":[[1.7,0]],"id":37307439}],"con":true,"img":false}]}
{"op":"mcm","clk":"5322589468","pt":1646322114230,"mc":[{"id":"1.195532865","rc":[{"atb":[[1.71,0],[1.69,0],[1.63,0],[1.67,0],[1.65,0],[1.61,0]],"id":37307439}],"con":true,"img":false}]}
{"op":"mcm","clk":"5322589482","pt":1646322114438,"mc":[{"id":"1.195532865","rc":[{"atb":[[1.54,183.42],[1.53,2.5]],"id":37307439}],"con":true,"img":false}]}
{"op":"mcm","clk":"5322589500","pt":1646322114596,"mc":[{"id":"1.195532865","rc":[{"atb":[[1.69,4.32]],"id":37307439}],"con":true,"img":false}]}
{"op":"mcm","clk":"5322589553","pt":1646322115330,"mc":[{"id":"1.195532865","rc":[{"atl":[[6.6,44.64]],"id":40133341},{"atb":[[1.63,2.15],[1.68,0]],"id":37307439}],"con":true,"img":false}]}
{"op":"mcm","clk":"5322589562","pt":1646322115434,"mc":[{"id":"1.195532865","rc":[{"atl":[[5.5,39.92]],"id":43189002}],"con":true,"img":false}]}
{"op":"mcm","clk":"5322589569","pt":1646322115486,"mc":[{"id":"1.195532865","rc":[{"atb":[[1.69,0]],"id":37307439}],"con":true,"img":false}]}
{"op":"mcm","clk":"5322589577","pt":1646322115593,"mc":[{"id":"1.195532865","rc":[{"atb":[[1.64,4.8]],"id":37307439}],"con":true,"img":false}]}
{"op":"mcm","clk":"5322589595","pt":1646322115904,"mc":[{"id":"1.195532865","rc":[{"atl":[[5.5,35.38]],"id":43189002},{"atb":[[1.67,7.46]],"id":37307439}],"con":true,"img":false}]}
{"op":"mcm","clk":"5322589600","pt":1646322116010,"mc":[{"id":"1.195532865","rc":[{"atb":[[1.68,4.41]],"id":37307439}],"con":true,"img":false}]}
{"op":"mcm","clk":"5322589608","pt":1646322116113,"mc":[{"id":"1.195532865","rc":[{"atb":[[1.67,0],[1.54,74.07]],"id":37307439}],"con":true,"img":false}]}
{"op":"mcm","clk":"5322589624","pt":1646322116325,"mc":[{"id":"1.195532865","rc":[{"atb":[[1.64,0],[1.68,0]],"id":37307439}],"con":true,"img":false}]}
{"op":"mcm","clk":"5322589644","pt":1646322116531,"mc":[{"id":"1.195532865","rc":[{"atb":[[3.3,4.02]],"id":28041476},{"atb":[[1.64,4.8]],"id":37307439}],"con":true,"img":false}]}
{"op":"mcm","clk":"5322589661","pt":1646322116741,"mc":[{"id":"1.195532865","rc":[{"atb":[[3.3,0]],"id":28041476}],"con":true,"img":false}]}
{"op":"mcm","clk":"5322589781","pt":1646322118435,"mc":[{"id":"1.195532865","rc":[{"atb":[[1.61,6.61]],"id":37307439}],"con":true,"img":false}]}
{"op":"mcm","clk":"5322589829","pt":1646322119008,"mc":[{"id":"1.195532865","rc":[{"atb":[[3.5,0]],"id":28041476}],"con":true,"img":false}]}
{"op":"mcm","clk":"5322589839","pt":1646322119112,"mc":[{"id":"1.195532865","rc":[{"atb":[[3.6,1.65]],"id":28041476}],"con":true,"img":false}]}
{"op":"mcm","clk":"5322589847","pt":1646322119216,"mc":[{"id":"1.195532865","rc":[{"atb":[[3.65,2.63]],"id":28041476}],"con":true,"img":false}]}
{"op":"mcm","clk":"5322590026","pt":1646322121525,"mc":[{"id":"1.195532865","rc":[{"atl":[[9.8,0]],"id":40133341}],"con":true,"img":false}]}
{"op":"mcm","clk":"5322590091","pt":1646322122211,"mc":[{"id":"1.195532865","rc":[{"atb":[[3.65,9.98]],"id":28041476}],"con":true,"img":false}]}
{"op":"mcm","clk":"5322590098","pt":1646322122330,"mc":[{"id":"1.195532865","rc":[{"atb":[[3.55,2.8],[3.5,7.06],[3.45,17.81],[3.4,0]],"id":28041476}],"con":true,"img":false}]}
{"op":"mcm","clk":"5322590121","pt":1646322122527,"mc":[{"id":"1.195532865","rc":[{"atb":[[3.5,0],[2.86,0],[2.78,22.47]],"id":28041476}],"con":true,"img":false}]}
{"op":"mcm","clk":"5322590143","pt":1646322122735,"mc":[{"id":"1.195532865","rc":[{"atb":[[2.58,0]],"id":40133341},{"atb":[[1.96,55.56],[2.14,26.63],[1.9,0]],"id":36909459},{"atb":[[1.44,131.22],[1.5,250]],"id":37307439}],"con":true,"img":false}]}
{"op":"mcm","clk":"5322590151","pt":1646322122840,"mc":[{"id":"1.195532865","rc":[{"atb":[[2.56,27.4]],"id":40133341}],"con":true,"img":false}]}
{"op":"mcm","clk":"5322590158","pt":1646322122945,"mc":[{"id":"1.195532865","rc":[{"atb":[[2.52,20.92]],"id":40133341}],"con":true,"img":false}]}
{"op":"mcm","clk":"5322590169","pt":1646322123055,"mc":[{"id":"1.195532865","rc":[{"atb":[[2.52,2.15]],"id":40133341}],"con":true,"img":false}]}
{"op":"mcm","clk":"5322590189","pt":1646322123214,"mc":[{"id":"1.195532865","rc":[{"atl":[[5.4,2.15]],"id":40133341},{"atl":[[5.1,2.41]],"id":43189002},{"atl":[[11,2.39]],"id":35701941},{"atl":[[6.6,2.8]],"id":28041476},{"atl":[[3.75,2.46]],"id":36909459},{"atl":[[2.54,2.58]],"id":37307439}],"con":true,"img":false}]}
{"op":"mcm","clk":"5322590198","pt":1646322123315,"mc":[{"id":"1.195532865","rc":[{"atb":[[2.56,0],[2.54,6.3]],"id":40133341},{"atl":[[6.6,5.6]],"id":28041476}],"con":true,"img":false}]}
{"op":"mcm","clk":"5322590205","pt":1646322123423,"mc":[{"id":"1.195532865","rc":[{"atl":[[5.8,0],[5.3,11.26],[5.7,38.55],[5.4,10.66]],"id":40133341},{"atl":[[5.1,7.09],[5.5,0],[5.4,28.25]],"id":43189002},{"atl":[[10.5,7.18],[11,4.89],[12,21.64],[12.5,3.48]],"id":35701941},{"atl":[[7.2,6.45],[6.4,4.21],[7,31.4]],"id":28041476},{"atl":[[3.95,0],[3.7,4.94],[3.9,49.79],[3.75,16.25]],"id":36909459},{"atl":[[2.54,9.47],[2.6,25],[2.58,22.77],[2.62,11.49]],"id":37307439}],"con":true,"img":false}]}
{"op":"mcm","clk":"5322590223","pt":1646322123531,"mc":[{"id":"1.195532865","rc":[{"atl":[[5.2,2.34]],"id":40133341},{"atl":[[5,3.37]],"id":43189002},{"atl":[[10,1.13]],"id":35701941},{"atl":[[7.4,3.22],[6.2,8.81],[6.6,2.8]],"id":28041476},{"atl":[[3.65,2.63]],"id":36909459},{"atl":[[2.56,22.04],[2.52,22.77]],"id":37307439}],"con":true,"img":false}]}
{"op":"mcm","clk":"5322590229","pt":1646322123634,"mc":[{"id":"1.195532865","rc":[{"atl":[[5.6,4.44],[5.5,2.5]],"id":40133341},{"atl":[[11.5,0]],"id":35701941},{"atl":[[6.8,0]],"id":28041476},{"atl":[[3.85,3.39],[3.95,5.14],[3.8,11],[3.65,18.88],[3.75,2.46]],"id":36909459},{"atl":[[2.56,0]],"id":37307439}],"con":true,"img":false}]}
{"op":"mcm","clk":"5322590244","pt":1646322123737,"mc":[{"id":"1.195532865","rc":[{"atb":[[2.54,0]],"id":40133341},{"atl":[[5.2,13],[5.4,2.15]],"id":40133341},{"atl":[[5.2,0],[4.9,2.37]],"id":43189002},{"atl":[[7.4,0]],"id":28041476},{"atl":[[2.54,55.01],[2.5,2.69],[2.62,0],[2.52,0],[2.68,9.18]],"id":37307439}],"con":true,"img":false}]}
{"op":"mcm","clk":"5322590252","pt":1646322123845,"mc":[{"id":"1.195532865","rc":[{"atl":[[5.6,0]],"id":40133341},{"atl":[[12.5,8.48]],"id":35701941},{"atl":[[3.85,0],[3.95,0]],"id":36909459},{"atl":[[2.68,0]],"id":37307439}],"con":true,"img":false}]}
{"op":"mcm","clk":"5322590280","pt":1646322124154,"mc":[{"id":"1.195532865","rc":[{"atl":[[5.7,30.04],[5.4,11.24]],"id":40133341},{"atl":[[5.1,16.85],[5.4,19.16]],"id":43189002},{"atl":[[11,8.89],[12.5,5]],"id":35701941},{"atl":[[7.2,0],[6.6,9.94]],"id":28041476},{"atl":[[3.9,36],[3.75,17.01]],"id":36909459},{"atl":[[2.54,80.98],[2.6,0]],"id":37307439}],"con":true,"img":false}]}
{"op":"mcm","clk":"5322590288","pt":1646322124208,"mc":[{"id":"1.195532865","rc":[{"atl":[[12.5,3.18]],"id":35701941},{"atl":[[7.2,3.52]],"id":28041476}],"con":true,"img":false}]}
{"op":"mcm","clk":"5322590298","pt":1646322124308,"mc":[{"id":"1.195532865","rc":[{"atl":[[12.5,0]],"id":35701941}],"con":true,"img":false}]}
{"op":"mcm","clk":"5322590340","pt":1646322124725,"mc":[{"id":"1.195532865","rc":[{"atl":[[7.2,0]],"id":28041476}],"con":true,"img":false}]}
{"op":"mcm","clk":"5322590496","pt":1646322126615,"mc":[{"id":"1.195532865","rc":[{"atb":[[2.6,0]],"id":40133341}],"con":true,"img":false}]}
{"op":"mcm","clk":"5322590587","pt":1646322127606,"mc":[{"id":"1.195532865","rc":[{"atb":[[2.4,2.15],[2.52,0]],"id":40133341}],"con":true,"img":false}]}
{"op":"mcm","clk":"5322590622","pt":1646322128027,"mc":[{"id":"1.195532865","rc":[{"atb":[[3.6,0]],"id":28041476}],"con":true,"img":false}]}
{"op":"mcm","clk":"5322590638","pt":1646322128240,"mc":[{"id":"1.195532865","rc":[{"atb":[[2.32,36.36],[2.22,4.02]],"id":43189002},{"atb":[[3.35,14.23],[3.45,35.62],[3.7,1.65]],"id":28041476},{"atb":[[2,55.56],[1.96,0]],"id":36909459}],"con":true,"img":false}]}
{"op":"mcm","clk":"5322590650","pt":1646322128342,"mc":[{"id":"1.195532865","rc":[{"atb":[[4.2,6.08]],"id":35701941}],"con":true,"img":false}]}
{"op":"mcm","clk":"5322590677","pt":1646322128655,"mc":[{"id":"1.195532865","rc":[{"atl":[[5.1,12.17],[4.9,5.74]],"id":43189002},{"atl":[[10,8.31],[11,6.39]],"id":35701941}],"con":true,"img":false}]}
{"op":"mcm","clk":"5322590698","pt":1646322128814,"mc":[{"id":"1.195532865","rc":[{"atb":[[4.2,2.5]],"id":35701941},{"atl":[[2.5,25.46]],"id":37307439}],"con":true,"img":false}]}
{"op":"mcm","clk":"5322590706","pt":1646322128918,"mc":[{"id":"1.195532865","rc":[{"atl":[[2.54,35.44]],"id":37307439}],"con":true,"img":false}]}
{"op":"mcm","clk":"5322590850","pt":1646322130752,"mc":[{"id":"1.195532865","rc":[{"atb":[[2.36,11.39]],"id":40133341}],"con":true,"img":false}]}
{"op":"mcm","clk":"5322590874","pt":1646322131063,"mc":[{"id":"1.195532865","rc":[{"atl":[[5.6,21.74]],"id":40133341},{"atl":[[5.3,23.26]],"id":43189002},{"atl":[[12,30.73]],"id":35701941},{"atl":[[7,48.07]],"id":28041476},{"atl":[[3.85,35.09]],"id":36909459},{"atl":[[2.58,86.06]],"id":37307439}],"con":true,"img":false}]}
{"op":"mcm","clk":"5322590900","pt":1646322131325,"mc":[{"id":"1.195532865","rc":[{"atl":[[6.2,0],[6.6,0],[5.9,5]],"id":40133341},{"atl":[[5.6,0],[5.8,5],[6,0]],"id":43189002},{"atl":[[60,0]],"id":35701941},{"atl":[[8,0],[7.6,0],[8.4,0]],"id":28041476},{"atl":[[4,0],[4.4,0],[4.2,0]],"id":36909459},{"atl":[[2.74,0]],"id":37307439}],"con":true,"img":false}]}
{"op":"mcm","clk":"5322590908","pt":1646322131429,"mc":[{"id":"1.195532865","rc":[{"atl":[[2.58,81.67]],"id":37307439}],"con":true,"img":false}]}
{"op":"mcm","clk":"5322590922","pt":1646322131534,"mc":[{"id":"1.195532865","rc":[{"atl":[[5.7,4.22]],"id":43189002}],"con":true,"img":false}]}
{"op":"mcm","clk":"5322590943","pt":1646322131739,"mc":[{"id":"1.195532865","rc":[{"atl":[[5.8,3.8]],"id":40133341},{"atl":[[5.7,0]],"id":43189002},{"atl":[[2.52,50.36]],"id":37307439}],"con":true,"img":false}]}
{"op":"mcm","clk":"5322590958","pt":1646322131949,"mc":[{"id":"1.195532865","rc":[{"atl":[[5.8,0]],"id":40133341}],"con":true,"img":false}]}
{"op":"mcm","clk":"5322591009","pt":1646322132523,"mc":[{"id":"1.195532865","rc":[{"atb":[[3.7,11.41]],"id":28041476}],"con":true,"img":false}]}
{"op":"mcm","clk":"5322591018","pt":1646322132627,"mc":[{"id":"1.195532865","rc":[{"atb":[[3.55,26.25],[3.45,20.82],[3.65,2.63]],"id":28041476}],"con":true,"img":false}]}
{"op":"mcm","clk":"5322591034","pt":1646322132837,"mc":[{"id":"1.195532865","rc":[{"atb":[[3.7,13.95]],"id":28041476}],"con":true,"img":false}]}
{"op":"mcm","clk":"5322591066","pt":1646322133150,"mc":[{"id":"1.195532865","rc":[{"atb":[[2.36,39.51]],"id":40133341}],"con":true,"img":false}]}
{"op":"mcm","clk":"5322591110","pt":1646322133724,"mc":[{"id":"1.195532865","rc":[{"atl":[[5.1,16.88],[5.7,0],[5.4,56.24]],"id":40133341},{"atl":[[5.1,30.95],[5.4,2.5]],"id":43189002},{"atl":[[11,34.09],[12,11.59],[9.8,9.09]],"id":35701941},{"atl":[[6,14.06],[6.6,47.44],[7,19.17]],"id":28041476},{"atl":[[3.6,6.73],[3.9,0],[3.75,60.91]],"id":36909459},{"atl":[[2.54,99.6],[2.5,49.52],[2.58,63.29]],"id":37307439}],"con":true,"img":false}]}
{"op":"mcm","clk":"5322591122","pt":1646322133828,"mc":[{"id":"1.195532865","rc":[{"atl":[[5,15.56]],"id":40133341},{"atl":[[4.8,4.09]],"id":43189002},{"atl":[[9.6,1.24]],"id":35701941},{"atl":[[5.9,1.76]],"id":28041476},{"atl":[[3.55,9.54],[3.65,2.63]],"id":36909459}],"con":true,"img":false}]}
{"op":"mcm","clk":"5322591132","pt":1646322133930,"mc":[{"id":"1.195532865","rc":[{"atl":[[5.3,0],[5.2,2.34]],"id":40133341},{"atl":[[4.9,2.37],[4.7,6.2]],"id":43189002},{"atl":[[10.5,0]],"id":35701941},{"atl":[[6.4,0]],"id":28041476},{"atl":[[3.7,0]],"id":36909459},{"atl":[[2.54,92.71]],"id":37307439}],"con":true,"img":false}]}
{"op":"mcm","clk":"5322591141","pt":1646322134034,"mc":[{"id":"1.195532865","rc":[{"atl":[[5,0],[4.9,10.55],[4.7,2.11]],"id":43189002}],"con":true,"img":false}]}
{"op":"mcm","clk":"5322591149","pt":1646322134139,"mc":[{"id":"1.195532865","rc":[{"atl":[[5.3,28.71]],"id":43189002}],"con":true,"img":false}]}
{"op":"mcm","clk":"5322591158","pt":1646322134242,"mc":[{"id":"1.195532865","rc":[{"atl":[[4.7,6.2]],"id":43189002}],"con":true,"img":false}]}
{"op":"mcm","clk":"5322591166","pt":1646322134346,"mc":[{"id":"1.195532865","rc":[{"atl":[[4.9,2.37]],"id":43189002}],"con":true,"img":false}]}
{"op":"mcm","clk":"5322591180","pt":1646322134553,"mc":[{"id":"1.195532865","rc":[{"atl":[[5.3,23.26]],"id":43189002}],"con":true,"img":false}]}
{"op":"mcm","clk":"5322591245","pt":1646322135547,"mc":[{"id":"1.195532865","rc":[{"atb":[[1.51,9.26]],"id":37307439}],"con":true,"img":false}]}
{"op":"mcm","clk":"5322591266","pt":1646322135860,"mc":[{"id":"1.195532865","rc":[{"atb":[[1.51,0]],"id":37307439}],"con":true,"img":false}]}
{"op":"mcm","clk":"5322591338","pt":1646322136977,"mc":[{"id":"1.195532865","rc":[{"atb":[[3.4,3.02]],"id":28041476}],"con":true,"img":false}]}
{"op":"mcm","clk":"5322591371","pt":1646322137429,"mc":[{"id":"1.195532865","rc":[{"atb":[[3.4,0]],"id":28041476}],"con":true,"img":false}]}
{"op":"mcm","clk":"5322591401","pt":1646322137850,"mc":[{"id":"1.195532865","rc":[{"atl":[[5.2,11.86]],"id":40133341},{"atl":[[4.9,12.63]],"id":43189002},{"atl":[[10,12.75],[11,30.09]],"id":35701941},{"atl":[[6.2,16.5]],"id":28041476},{"atl":[[3.65,17.72]],"id":36909459},{"atl":[[2.62,92.59]],"id":37307439}],"con":true,"img":false}]}
{"op":"mcm","clk":"5322591425","pt":1646322138059,"mc":[{"id":"1.195532865","rc":[{"atb":[[1.98,0],[2.2,4.7]],"id":36909459}],"con":true,"img":false}]}
{"op":"mcm","clk":"5322591438","pt":1646322138266,"mc":[{"id":"1.195532865","rc":[{"atl":[[2.7,0]],"id":37307439}],"con":true,"img":false}]}
{"op":"mcm","clk":"5322591545","pt":1646322139566,"mc":[{"id":"1.195532865","rc":[{"atl":[[5.5,0],[5.2,14.36],[5.9,0]],"id":40133341}],"con":true,"img":false}]}
{"op":"mcm","clk":"5322591894","pt":1646322143742,"mc":[{"id":"1.195532865","rc":[{"atl":[[5.2,74.2],[4.9,20.51],[5.4,15.93]],"id":40133341},{"spn":3.83,"spf":"NaN","id":40133341},{"atl":[[5.1,12.17],[4.9,33.21]],"id":43189002},{"spn":3.75,"spf":"NaN","id":43189002},{"atl":[[10,44.27],[11,2.39],[9.4,9.52]],"id":35701941},{"atl":[[6.2,20.5]],"id":28041476},{"spn":4.8,"spf":"NaN","id":28041476},{"atl":[[3.5,8.58],[3.65,50.26],[3.75,64.61]],"id":36909459},{"spn":2.22,"spf":1.0,"id":36909459},{"spn":2.07,"spf":"NaN","id":37307439}],"con":true,"img":false}]}
{"op":"mcm","clk":"5322591900","pt":1646322143847,"mc":[{"id":"1.195532865","rc":[{"atl":[[4.8,19.68],[5.1,0],[5,2.56]],"id":40133341},{"atl":[[4.6,4.63]],"id":43189002},{"atl":[[9.2,1.36],[9.8,0]],"id":35701941},{"atl":[[3.6,0],[3.45,11.59],[3.55,2.81],[3.75,17.01]],"id":36909459}],"con":true,"img":false}]}
{"op":"mcm","clk":"5322591906","pt":1646322143951,"mc":[{"id":"1.195532865","rc":[{"atl":[[5.4,11.24]],"id":40133341},{"atl":[[4.5,6.56],[4.7,2.11]],"id":43189002},{"atl":[[6.2,16.5]],"id":28041476}],"con":true,"img":false}]}
{"op":"mcm","clk":"5322591916","pt":1646322144056,"mc":[{"id":"1.195532865","rc":[{"atl":[[4.8,0]],"id":43189002},{"atl":[[10,48.11]],"id":35701941},{"atl":[[3.65,57.95]],"id":36909459}],"con":true,"img":false}]}
{"op":"mcm","clk":"5322591924","pt":1646322144160,"mc":[{"id":"1.195532865","rc":[{"atl":[[4.3,4.11]],"id":43189002}],"con":true,"img":false}]}
{"op":"mcm","clk":"5322591935","pt":1646322144266,"mc":[{"id":"1.195532865","rc":[{"atl":[[4.2,1.93]],"id":43189002},{"atl":[[6.8,3.64]],"id":28041476}],"con":true,"img":false}]}
{"op":"mcm","clk":"5322591946","pt":1646322144369,"mc":[{"id":"1.195532865","rc":[{"atl":[[6.8,0]],"id":28041476}],"con":true,"img":false}]}
{"op":"mcm","clk":"5322591960","pt":1646322144574,"mc":[{"id":"1.195532865","rc":[{"atl":[[5,12.56]],"id":40133341},{"atl":[[4.4,11.76]],"id":43189002},{"atl":[[9.6,5.89],[10,39.83]],"id":35701941},{"atl":[[6.6,58.16]],"id":28041476},{"atl":[[3.55,18.5],[3.65,50.26]],"id":36909459},{"atl":[[2.66,150.6]],"id":37307439}],"con":true,"img":false}]}
{"op":"mcm","clk":"5322592252","pt":1646322148348,"mc":[{"id":"1.195532865","rc":[{"atb":[[2.3,38.23]],"id":40133341}],"con":true,"img":false}]}
{"op":"mcm","clk":"5322592262","pt":1646322148452,"mc":[{"id":"1.195532865","rc":[{"atb":[[2.3,34.41]],"id":40133341}],"con":true,"img":false}]}
{"op":"mcm","clk":"5322592305","pt":1646322148972,"mc":[{"id":"1.195532865","rc":[{"atb":[[2.3,30.77]],"id":40133341}],"con":true,"img":false}]}
{"op":"mcm","clk":"5322592317","pt":1646322149079,"mc":[{"id":"1.195532865","rc":[{"atl":[[4.5,1.93],[4.2,6.04]],"id":43189002}],"con":true,"img":false}]}
{"op":"mcm","clk":"5322592400","pt":1646322150063,"mc":[{"id":"1.195532865","rc":[{"atl":[[2.52,0]],"id":37307439}],"con":true,"img":false}]}
{"op":"mcm","clk":"5322592409","pt":1646322150168,"mc":[{"id":"1.195532865","rc":[{"atl":[[2.54,28.55],[2.58,175.57]],"id":37307439}],"con":true,"img":false}]}
{"op":"mcm","clk":"5322592416","pt":1646322150273,"mc":[{"id":"1.195532865","rc":[{"atl":[[2.54,53.73]],"id":37307439}],"con":true,"img":false}]}
{"op":"mcm","clk":"5322592427","pt":1646322150375,"mc":[{"id":"1.195532865","rc":[{"atl":[[2.48,50.37]],"id":37307439}],"con":true,"img":false}]}
{"op":"mcm","clk":"5322592437","pt":1646322150479,"mc":[{"id":"1.195532865","rc":[{"atl":[[2.46,53.18]],"id":37307439}],"con":true,"img":false}]}
{"op":"mcm","clk":"5322592446","pt":1646322150583,"mc":[{"id":"1.195532865","rc":[{"atl":[[2.56,7.81],[2.5,26.75],[2.46,95.28]],"id":37307439}],"con":true,"img":false}]}
{"op":"mcm","clk":"5322592459","pt":1646322150690,"mc":[{"id":"1.195532865","rc":[{"atl":[[2.54,28.55],[2.5,2.69]],"id":37307439}],"con":true,"img":false}]}
{"op":"mcm","clk":"5322592483","pt":1646322150951,"mc":[{"id":"1.195532865","rc":[{"atl":[[2.56,0]],"id":37307439}],"con":true,"img":false}]}
{"op":"mcm","clk":"5322592498","pt":1646322151157,"mc":[{"id":"1.195532865","rc":[{"atl":[[5.2,88.49]],"id":40133341},{"atl":[[4.6,32.41]],"id":43189002},{"atl":[[10,50.94]],"id":35701941},{"atl":[[7,27.5]],"id":28041476},{"atl":[[3.65,72.91]],"id":36909459},{"atl":[[2.54,2.58],[2.5,29.36]],"id":37307439}],"con":true,"img":false}]}
{"op":"mcm","clk":"5322592552","pt":1646322151887,"mc":[{"id":"1.195532865","rc":[{"atl":[[5.1,2.41],[5.3,0],[4.9,22.95]],"id":43189002},{"atl":[[50,0]],"id":35701941}],"con":true,"img":false}]}
{"op":"mcm","clk":"5322592607","pt":1646322152568,"mc":[{"id":"1.195532865","rc":[{"atl":[[2.48,0]],"id":37307439}],"con":true,"img":false}]}
{"op":"mcm","clk":"5322592635","pt":1646322152881,"mc":[{"id":"1.195532865","rc":[{"atl":[[2.44,1.78]],"id":37307439}],"con":true,"img":false}]}
{"op":"mcm","clk":"5322592656","pt":1646322153092,"mc":[{"id":"1.195532865","rc":[{"atl":[[2.42,2.94]],"id":37307439}],"con":true,"img":false}]}
{"op":"mcm","clk":"5322592672","pt":1646322153249,"mc":[{"id":"1.195532865","rc":[{"atl":[[2.42,5.88],[2.46,44.91]],"id":37307439}],"con":true,"img":false}]}
{"op":"mcm","clk":"5322592693","pt":1646322153458,"mc":[{"id":"1.195532865","rc":[{"atl":[[10,43.76],[10.5,10.53]],"id":35701941},{"atb":[[1.44,0],[1.49,131.22],[1.61,22.23]],"id":37307439},{"atl":[[3.6,0],[2.5,2.69],[2.46,72.31],[3.4,0]],"id":37307439}],"con":true,"img":false}]}
{"op":"mcm","clk":"5322592703","pt":1646322153562,"mc":[{"id":"1.195532865","rc":[{"atl":[[5,77.04]],"id":40133341},{"atl":[[5,3.53]],"id":43189002},{"atl":[[9.6,31.01],[9.2,10.78]],"id":35701941},{"atl":[[3.4,9.97],[3.55,58.84],[3.65,40.37]],"id":36909459}],"con":true,"img":false}]}
{"op":"mcm","clk":"5322592714","pt":1646322153668,"mc":[{"id":"1.195532865","rc":[{"atl":[[5.2,28.65],[4.7,21.62]],"id":40133341},{"atl":[[4.9,2.37],[4.4,32.06]],"id":43189002},{"atl":[[10,12.24]],"id":35701941},{"atl":[[3.35,13.2]],"id":36909459}],"con":true,"img":false}]}
{"op":"mcm","clk":"5322592724","pt":1646322153773,"mc":[{"id":"1.195532865","rc":[{"atl":[[4.6,3.09],[4.9,0]],"id":40133341},{"atl":[[4.1,4.64]],"id":43189002},{"atl":[[9.4,0]],"id":35701941},{"atl":[[3.45,3.01],[3.5,0]],"id":36909459}],"con":true,"img":false}]}
{"op":"mcm","clk":"5322592734","pt":1646322153878,"mc":[{"id":"1.195532865","rc":[{"atl":[[4.8,2.8],[4.5,19.68]],"id":40133341},{"atl":[[4,1.8],[4.6,27.78],[4.7,7.04]],"id":43189002}],"con":true,"img":false}]}
{"op":"mcm","clk":"5322592742","pt":1646322153983,"mc":[{"id":"1.195532865","rc":[{"atl":[[4.4,3.42]],"id":40133341},{"atl":[[5,0]],"id":43189002},{"atl":[[3.2,8.91]],"id":36909459}],"con":true,"img":false}]}
{"op":"mcm","clk":"5322592749","pt":1646322154087,"mc":[{"id":"1.195532865","rc":[{"atl":[[4.3,3.42]],"id":40133341}],"con":true,"img":false}]}
{"op":"mcm","clk":"5322592760","pt":1646322154188,"mc":[{"id":"1.195532865","rc":[{"atl":[[4.5,0]],"id":40133341},{"atl":[[3.15,3.76]],"id":36909459}],"con":true,"img":false}]}
{"op":"mcm","clk":"5322592765","pt":1646322154293,"mc":[{"id":"1.195532865","rc":[{"atl":[[4.2,3.82]],"id":40133341},{"atl":[[4,6.44],[4.7,2.11]],"id":43189002}],"con":true,"img":false}]}
{"op":"mcm","clk":"5322592775","pt":1646322154350,"mc":[{"id":"1.195532865","rc":[{"atl":[[4.2,11.98]],"id":40133341},{"atl":[[4.2,1.92]],"id":43189002}],"con":true,"img":false}]}
{"op":"mcm","clk":"5322592782","pt":1646322154453,"mc":[{"id":"1.195532865","rc":[{"atl":[[4.3,0],[4.1,3.42]],"id":40133341}],"con":true,"img":false}]}
{"op":"mcm","clk":"5322592794","pt":1646322154557,"mc":[{"id":"1.195532865","rc":[{"atl":[[4,2.11]],"id":40133341}],"con":true,"img":false}]}
{"op":"mcm","clk":"5322593008","pt":1646322157696,"mc":[{"id":"1.195532865","rc":[{"atl":[[5,67.04],[4.2,24.48]],"id":40133341},{"atl":[[4.2,14.43]],"id":43189002},{"atl":[[7.4,39.06]],"id":28041476},{"atl":[[3.55,43.15],[3.25,17.78]],"id":36909459}],"con":true,"img":false}]}
{"op":"mcm","clk":"5322593016","pt":1646322157749,"mc":[{"id":"1.195532865","rc":[{"atl":[[11,17.39]],"id":35701941}],"con":true,"img":false}]}
{"op":"mcm","clk":"5322593038","pt":1646322158068,"mc":[{"id":"1.195532865","rc":[{"atl":[[9.6,5.89],[10,58.28]],"id":35701941}],"con":true,"img":false}]}
{"op":"mcm","clk":"5322593099","pt":1646322158749,"mc":[{"id":"1.195532865","rc":[{"atl":[[3.1,8.91],[3.35,3.22]],"id":36909459}],"con":true,"img":false}]}
{"op":"mcm","clk":"5322593105","pt":1646322158853,"mc":[{"id":"1.195532865","rc":[{"atl":[[14,5]],"id":35701941},{"atl":[[3.05,3.73]],"id":36909459}],"con":true,"img":false}]}
{"op":"mcm","clk":"5322593112","pt":1646322158958,"mc":[{"id":"1.195532865","rc":[{"atl":[[3.1,0],[3,3.76]],"id":36909459}],"con":true,"img":false}]}
{"op":"mcm","clk":"5322593121","pt":1646322159062,"mc":[{"id":"1.195532865","rc":[{"atl":[[2.98,1.71]],"id":36909459}],"con":true,"img":false}]}
{"op":"mcm","clk":"5322593185","pt":1646322159899,"mc":[{"id":"1.195532865","rc":[{"atl":[[2.5,69.36]],"id":37307439}],"con":true,"img":false}]}
{"op":"mcm","clk":"5322593194","pt":1646322160004,"mc":[{"id":"1.195532865","rc":[{"atl":[[2.5,90.72],[2.58,63.29]],"id":37307439}],"con":true,"img":false}]}
{"op":"mcm","clk":"5322593218","pt":1646322160273,"mc":[{"id":"1.195532865","rc":[{"atl":[[3.25,0],[3.05,23.24]],"id":36909459},{"atl":[[2.42,13.89]],"id":37307439}],"con":true,"img":false}]}
{"op":"mcm","clk":"5322593234","pt":1646322160480,"mc":[{"id":"1.195532865","rc":[{"atl":[[2.46,30.21]],"id":37307439}],"con":true,"img":false}]}
{"op":"mcm","clk":"5322593330","pt":1646322161578,"mc":[{"id":"1.195532865","rc":[{"atl":[[2.66,0]],"id":37307439}],"con":true,"img":false}]}
{"op":"mcm","clk":"5322593344","pt":1646322161788,"mc":[{"id":"1.195532865","rc":[{"atl":[[2.44,0]],"id":37307439}],"con":true,"img":false}]}
{"op":"mcm","clk":"5322593370","pt":1646322162100,"mc":[{"id":"1.195532865","rc":[{"atl":[[2.44,50.46]],"id":37307439}],"con":true,"img":false}]}
{"op":"mcm","clk":"5322593479","pt":1646322163204,"mc":[{"id":"1.195532865","rc":[{"atl":[[5.2,32.87]],"id":40133341}],"con":true,"img":false}]}
{"op":"mcm","clk":"5322593487","pt":1646322163257,"mc":[{"id":"1.195532865","rc":[{"atl":[[5,2.56],[4.2,39.46]],"id":40133341},{"atl":[[3,9.6],[3.55,2.8],[3.15,27.44]],"id":36909459}],"con":true,"img":false}]}
{"op":"mcm","clk":"5322593497","pt":1646322163363,"mc":[{"id":"1.195532865","rc":[{"atl":[[3.95,5.62]],"id":40133341},{"atl":[[4.4,11.76],[4,11.48],[4.2,36.59]],"id":43189002},{"atl":[[9,2]],"id":35701941},{"atl":[[3.4,0]],"id":36909459}],"con":true,"img":false}]}
{"op":"mcm","clk":"5322593510","pt":1646322163467,"mc":[{"id":"1.195532865","rc":[{"atl":[[4.1,0],[3.9,5.67]],"id":40133341},{"atl":[[9.6,31.01],[10,12.24],[8.8,1.5]],"id":35701941},{"atl":[[3.6,5.77]],"id":36909459}],"con":true,"img":false}]}
{"op":"mcm","clk":"5322593519","pt":1646322163575,"mc":[{"id":"1.195532865","rc":[{"atl":[[4.3,7.85],[4,13.35],[4.7,0]],"id":40133341},{"atl":[[4.1,0]],"id":43189002},{"atb":[[3.7,0],[3.9,0],[4.2,0]],"id":35701941},{"atl":[[9.6,26.36],[9.2,1.36],[10.5,15.4],[9.4,4.76]],"id":35701941},{"atb":[[2.2,11.26]],"id":36909459}],"con":true,"img":false}]}
{"op":"mcm","clk":"5322593535","pt":1646322163783,"mc":[{"id":"1.195532865","rc":[{"atl":[[5.2,28.65],[3.9,2.25]],"id":40133341},{"atl":[[9.6,1.24],[9.2,6.24]],"id":35701941},{"atb":[[2.14,29.71]],"id":36909459},{"atl":[[3.6,0]],"id":36909459}],"con":true,"img":false}]}
{"op":"mcm","clk":"5322593538","pt":1646322163784,"mc":[{"id":"1.195532865","rc":[{"atl":[[4.3,0]],"id":40133341},{"atl":[[4.3,0]],"id":43189002},{"atl":[[10.5,10.53]],"id":35701941}],"con":true,"img":false}]}
{"op":"mcm","clk":"5322593551","pt":1646322163898,"mc":[{"id":"1.195532865","rc":[{"atl":[[4,2.11],[3.9,7.92]],"id":40133341},{"atl":[[9.4,0]],"id":35701941},{"atb":[[2.1,4.38]],"id":36909459}],"con":true,"img":false}]}
{"op":"mcm","clk":"5322593560","pt":1646322164002,"mc":[{"id":"1.195532865","rc":[{"atl":[[4.2,31.3]],"id":40133341},{"atb":[[2.14,26.63]],"id":36909459}],"con":true,"img":false}]}
{"op":"mcm","clk":"5322593567","pt":1646322164097,"mc":[{"id":"1.195532865","rc":[{"atl":[[4.4,32.83]],"id":40133341},{"atl":[[4.4,29.41]],"id":43189002}],"con":true,"img":false}]}
{"op":"mcm","clk":"5322593582","pt":1646322164312,"mc":[{"id":"1.195532865","rc":[{"atl":[[4.1,1.58]],"id":40133341},{"atl":[[4.3,7.68]],"id":43189002}],"con":true,"img":false}]}
{"op":"mcm","clk":"5322593613","pt":1646322164673,"mc":[{"id":"1.195532865","rc":[{"atl":[[5.6,0]],"id":40133341}],"con":true,"img":false}]}
{"op":"mcm","clk":"5322593629","pt":1646322164883,"mc":[{"id":"1.195532865","rc":[{"atl":[[4.1,0]],"id":40133341}],"con":true,"img":false}]}
{"op":"mcm","clk":"5322593733","pt":1646322166187,"mc":[{"id":"1.195532865","rc":[{"atl":[[4.3,0]],"id":43189002}],"con":true,"img":false}]}
{"op":"mcm","clk":"5322593743","pt":1646322166290,"mc":[{"id":"1.195532865","rc":[{"atl":[[2.54,99.98]],"id":37307439}],"con":true,"img":false}]}
{"op":"mcm","clk":"5322593763","pt":1646322166498,"mc":[{"id":"1.195532865","rc":[{"atl":[[4.1,1.59]],"id":40133341},{"atl":[[4.3,2.11]],"id":43189002}],"con":true,"img":false}]}
{"op":"mcm","clk":"5322593767","pt":1646322166599,"mc":[{"id":"1.195532865","rc":[{"atl":[[3.15,73.95]],"id":36909459}],"con":true,"img":false}]}
{"op":"mcm","clk":"5322593826","pt":1646322167186,"mc":[{"id":"1.195532865","rc":[{"atb":[[2.22,5.38]],"id":36909459}],"con":true,"img":false}]}
{"op":"mcm","clk":"5322593840","pt":1646322167287,"mc":[{"id":"1.195532865","rc":[{"atb":[[2.14,4.13],[2.16,32.25]],"id":36909459},{"atl":[[2.52,11.92]],"id":37307439}],"con":true,"img":false}]}
{"op":"mcm","clk":"5322593860","pt":1646322167495,"mc":[{"id":"1.195532865","rc":[{"atl":[[2.52,0]],"id":37307439}],"con":true,"img":false}]}
{"op":"mcm","clk":"5322593878","pt":1646322167704,"mc":[{"id":"1.195532865","rc":[{"atl":[[4.3,32.37],[4.2,14.43]],"id":43189002}],"con":true,"img":false}]}
{"op":"mcm","clk":"5322593908","pt":1646322168011,"mc":[{"id":"1.195532865","rc":[{"atl":[[3.85,0]],"id":36909459}],"con":true,"img":false}]}
{"op":"mcm","clk":"5322593935","pt":1646322168275,"mc":[{"id":"1.195532865","rc":[{"atl":[[4.1,0]],"id":40133341}],"con":true,"img":false}]}
{"op":"mcm","clk":"5322593952","pt":1646322168484,"mc":[{"id":"1.195532865","rc":[{"atl":[[2.62,0]],"id":37307439}],"con":true,"img":false}]}
{"op":"mcm","clk":"5322593965","pt":1646322168696,"mc":[{"id":"1.195532865","rc":[{"atl":[[2.44,0]],"id":37307439}],"con":true,"img":false}]}
{"op":"mcm","clk":"5322593984","pt":1646322169015,"mc":[{"id":"1.195532865","rc":[{"atl":[[2.44,4.02]],"id":37307439}],"con":true,"img":false}]}
{"op":"mcm","clk":"5322594027","pt":1646322169385,"mc":[{"id":"1.195532865","rc":[{"atl":[[2.44,0]],"id":37307439}],"con":true,"img":false}]}
{"op":"mcm","clk":"5322594052","pt":1646322169705,"mc":[{"id":"1.195532865","rc":[{"atl":[[2.44,2.64]],"id":37307439}],"con":true,"img":false}]}
{"op":"mcm","clk":"5322594073","pt":1646322169924,"mc":[{"id":"1.195532865","rc":[{"atl":[[9.6,12.87]],"id":35701941},{"atl":[[2.5,69.36],[2.46,67.59]],"id":37307439}],"con":true,"img":false}]}
{"op":"mcm","clk":"5322594123","pt":1646322170387,"mc":[{"id":"1.195532865","rc":[{"atl":[[4.6,44.76]],"id":40133341},{"atl":[[4.6,41.67]],"id":43189002}],"con":true,"img":false}]}
{"op":"mcm","clk":"5322594201","pt":1646322171279,"mc":[{"id":"1.195532865","rc":[{"atb":[[2.2,8.71]],"id":36909459}],"con":true,"img":false}]}
{"op":"mcm","clk":"5322594209","pt":1646322171383,"mc":[{"id":"1.195532865","rc":[{"atl":[[12,2.5]],"id":35701941}],"con":true,"img":false}]}
{"op":"mcm","clk":"5322594228","pt":1646322171591,"mc":[{"id":"1.195532865","rc":[{"atl":[[4.1,1.62]],"id":40133341}],"con":true,"img":false}]}
{"op":"mcm","clk":"5322594251","pt":1646322171902,"mc":[{"id":"1.195532865","rc":[{"atl":[[2.44,0]],"id":37307439}],"con":true,"img":false}]}
{"op":"mcm","clk":"5322594279","pt":1646322172212,"mc":[{"id":"1.195532865","rc":[{"atl":[[2.44,4.1]],"id":37307439}],"con":true,"img":false}]}
{"op":"mcm","clk":"5322594302","pt":1646322172520,"mc":[{"id":"1.195532865","rc":[{"atl":[[2.58,158.23]],"id":37307439}],"con":true,"img":false}]}
{"op":"mcm","clk":"5322594323","pt":1646322172697,"mc":[{"id":"1.195532865","rc":[{"atl":[[10,17.34]],"id":35701941}],"con":true,"img":false}]}
{"op":"mcm","clk":"5322594333","pt":1646322172782,"mc":[{"id":"1.195532865","rc":[{"atl":[[3.85,7.27],[4,21.49],[4.2,16.32]],"id":40133341},{"atl":[[10,12.24]],"id":35701941},{"atl":[[3.25,66.67]],"id":36909459}],"con":true,"img":false}]}
{"op":"mcm","clk":"5322594343","pt":1646322172886,"mc":[{"id":"1.195532865","rc":[{"atl":[[3.8,9.66]],"id":40133341}],"con":true,"img":false}]}
{"op":"mcm","clk":"5322594358","pt":1646322172999,"mc":[{"id":"1.195532865","rc":[{"atl":[[3.95,0],[3.9,2.25]],"id":40133341},{"atl":[[4.5,4.99]],"id":43189002}],"con":true,"img":false}]}
{"op":"mcm","clk":"5322594387","pt":1646322173317,"mc":[{"id":"1.195532865","rc":[{"atl":[[4.5,1.93]],"id":43189002}],"con":true,"img":false}]}
{"op":"mcm","clk":"5322594431","pt":1646322173689,"mc":[{"id":"1.195532865","rc":[{"atl":[[4.5,18.88]],"id":43189002}],"con":true,"img":false}]}
{"op":"mcm","clk":"5322594452","pt":1646322173894,"mc":[{"id":"1.195532865","rc":[{"atl":[[5.4,2.15]],"id":40133341},{"atl":[[4.5,1.93]],"id":43189002},{"atb":[[2.22,19.12]],"id":36909459},{"atl":[[3.75,2.46]],"id":36909459}],"con":true,"img":false}]}
{"op":"mcm","clk":"5322594468","pt":1646322174097,"mc":[{"id":"1.195532865","rc":[{"atb":[[2.2,2.15]],"id":36909459}],"con":true,"img":false}]}
{"op":"mcm","clk":"5322594487","pt":1646322174309,"mc":[{"id":"1.195532865","rc":[{"atl":[[4.1,0]],"id":40133341}],"con":true,"img":false}]}
{"op":"mcm","clk":"5322594614","pt":1646322175781,"mc":[{"id":"1.195532865","rc":[{"atb":[[2.24,3.77]],"id":36909459}],"con":true,"img":false}]}
{"op":"mcm","clk":"5322594639","pt":1646322176087,"mc":[{"id":"1.195532865","rc":[{"atl":[[10,17.8]],"id":35701941}],"con":true,"img":false}]}
{"op":"mcm","clk":"5322594656","pt":1646322176402,"mc":[{"id":"1.195532865","rc":[{"atb":[[2.14,20.84]],"id":36909459}],"con":true,"img":false}]}
{"op":"mcm","clk":"5322594665","pt":1646322176518,"mc":[{"id":"1.195532865","rc":[{"atl":[[4.8,68.59]],"id":40133341},{"atl":[[4.8,65.79]],"id":43189002}],"con":true,"img":false}]}
{"op":"mcm","clk":"5322594681","pt":1646322176715,"mc":[{"id":"1.195532865","rc":[{"atb":[[2.2,40.2],[2.16,4.03]],"id":36909459}],"con":true,"img":false}]}
{"op":"mcm","clk":"5322594687","pt":1646322176821,"mc":[{"id":"1.195532865","rc":[{"atb":[[2.28,2.15],[2.2,38.05]],"id":36909459}],"con":true,"img":false}]}
{"op":"mcm","clk":"5322594698","pt":1646322176978,"mc":[{"id":"1.195532865","rc":[{"atb":[[2.14,4.13]],"id":36909459}],"con":true,"img":false}]}
{"op":"mcm","clk":"5322594853","pt":1646322178808,"mc":[{"id":"1.195532865","rc":[{"atl":[[5.2,4.84]],"id":40133341},{"atb":[[2.22,5.38],[2.2,0]],"id":36909459}],"con":true,"img":false}]}
{"op":"mcm","clk":"5322594864","pt":1646322178911,"mc":[{"id":"1.195532865","rc":[{"atl":[[3.35,109.61]],"id":36909459}],"con":true,"img":false}]}
{"op":"mcm","clk":"5322594984","pt":1646322180330,"mc":[{"id":"1.195532865","rc":[{"atb":[[3.3,4.38]],"id":28041476},{"atb":[[1.53,6]],"id":37307439}],"con":true,"img":false}]}
{"op":"mcm","clk":"5322595011","pt":1646322180592,"mc":[{"id":"1.195532865","rc":[{"atl":[[3.65,2.63]],"id":36909459},{"atl":[[2.46,71.06]],"id":37307439}],"con":true,"img":false}]}
{"op":"mcm","clk":"5322595029","pt":1646322180802,"mc":[{"id":"1.195532865","rc":[{"atl":[[2.46,67.59]],"id":37307439}],"con":true,"img":false}]}
{"op":"mcm","clk":"5322595041","pt":1646322180910,"mc":[{"id":"1.195532865","rc":[{"atl":[[6.4,5.63]],"id":28041476},{"atl":[[3.1,3.49]],"id":36909459}],"con":true,"img":false}]}
{"op":"mcm","clk":"5322595061","pt":1646322181121,"mc":[{"id":"1.195532865","rc":[{"atl":[[6.4,65.19],[6.6,20.66]],"id":28041476},{"atl":[[3.1,21.81],[3.15,50.27]],"id":36909459}],"con":true,"img":false}]}
{"op":"mcm","clk":"5322595092","pt":1646322181389,"mc":[{"id":"1.195532865","rc":[{"atl":[[6.4,59.56]],"id":28041476},{"atl":[[3.1,18.32]],"id":36909459}],"con":true,"img":false}]}
{"op":"mcm","clk":"5322595125","pt":1646322181803,"mc":[{"id":"1.195532865","rc":[{"atl":[[3.9,9.27]],"id":40133341},{"atb":[[2.24,0]],"id":36909459}],"con":true,"img":false}]}
{"op":"mcm","clk":"5322595157","pt":1646322182117,"mc":[{"id":"1.195532865","rc":[{"atl":[[3.75,12.4],[4,2.11],[3.9,42.35]],"id":40133341}],"con":true,"img":false}]}
{"op":"mcm","clk":"5322595166","pt":1646322182222,"mc":[{"id":"1.195532865","rc":[{"atl":[[3.7,2.54],[3.9,35.33]],"id":40133341},{"atl":[[11,27.39]],"id":35701941}],"con":true,"img":false}]}
{"op":"mcm","clk":"5322595179","pt":1646322182325,"mc":[{"id":"1.195532865","rc":[{"atl":[[3.85,0]],"id":40133341},{"atb":[[2.22,3.73]],"id":36909459}],"con":true,"img":false}]}
{"op":"mcm","clk":"5322595187","pt":1646322182428,"mc":[{"id":"1.195532865","rc":[{"atl":[[3.8,2.39],[4,5.53],[3.7,12.2]],"id":40133341}],"con":true,"img":false}]}
{"op":"mcm","clk":"5322595240","pt":1646322182904,"mc":[{"id":"1.195532865","rc":[{"atl":[[4,2.11]],"id":40133341}],"con":true,"img":false}]}
{"op":"mcm","clk":"5322595510","pt":1646322185972,"mc":[{"id":"1.195532865","rc":[{"atb":[[2.24,4.11],[2.16,23.21]],"id":36909459}],"con":true,"img":false}]}
{"op":"mcm","clk":"5322595542","pt":1646322186308,"mc":[{"id":"1.195532865","rc":[{"atb":[[2.16,4.03]],"id":36909459}],"con":true,"img":false}]}
{"op":"mcm","clk":"5322596013","pt":1646322191239,"mc":[{"id":"1.195532865","rc":[{"atl":[[3.8,34.93],[3.7,24.4],[3.9,2.25]],"id":40133341}],"con":true,"img":false}]}
{"op":"mcm","clk":"5322596027","pt":1646322191354,"mc":[{"id":"1.195532865","rc":[{"atl":[[3.75,24.4],[3.7,14.74]],"id":40133341}],"con":true,"img":false}]}
{"op":"mcm","clk":"5322596322","pt":1646322194709,"mc":[{"id":"1.195532865","rc":[{"atb":[[1.23,250]],"id":40133341},{"atb":[[1.23,250]],"id":43189002},{"atb":[[1.23,250]],"id":35701941},{"atb":[[1.23,250]],"id":28041476},{"atb":[[1.23,250]],"id":36909459}],"con":true,"img":false}]}
{"op":"mcm","clk":"5322596343","pt":1646322194920,"mc":[{"id":"1.195532865","rc":[{"atl":[[4.5,6.86]],"id":43189002}],"con":true,"img":false}]}
{"op":"mcm","clk":"5322596422","pt":1646322195623,"mc":[{"id":"1.195532865","rc":[{"atl":[[4.5,1.93]],"id":43189002}],"con":true,"img":false}]}
{"op":"mcm","clk":"5322596829","pt":1646322200257,"mc":[{"id":"1.195532865","rc":[{"atb":[[2.32,7.6]],"id":40133341},{"atl":[[6.2,10.9],[6,30.56]],"id":28041476},{"atb":[[2.22,23.02]],"id":36909459}],"con":true,"img":false}]}
{"op":"mcm","clk":"5322596846","pt":1646322200420,"mc":[{"id":"1.195532865","rc":[{"atl":[[6.4,64.97]],"id":28041476}],"con":true,"img":false}]}
{"op":"mcm","clk":"5322596867","pt":1646322200632,"mc":[{"id":"1.195532865","rc":[{"atb":[[2.32,0]],"id":40133341},{"atl":[[6.4,59.56]],"id":28041476}],"con":true,"img":false}]}
{"op":"mcm","clk":"5322597090","pt":1646322202936,"mc":[{"id":"1.195532865","rc":[{"atl":[[4.3,30.26]],"id":43189002}],"con":true,"img":false}]}
{"op":"mcm","clk":"5322597276","pt":1646322205245,"mc":[{"id":"1.195532865","rc":[{"atb":[[2.36,46.16]],"id":40133341},{"atl":[[3.7,18.15]],"id":40133341},{"spn":3.23,"spf":"NaN","id":40133341},{"atb":[[2.52,15.91]],"id":43189002},{"atl":[[4,16.85]],"id":43189002},{"spn":3.4,"spf":"NaN","id":43189002},{"atl":[[5.9,7.2]],"id":28041476},{"atb":[[2,61.68]],"id":36909459},{"atl":[[3,15.31]],"id":36909459},{"spn":2.28,"spf":1.0,"id":36909459},{"atb":[[1.61,35.44]],"id":37307439},{"atl":[[2.42,19.96]],"id":37307439},{"spn":2.03,"spf":"NaN","id":37307439}],"con":true,"img":false}]}
{"op":"mcm","clk":"5322597289","pt":1646322205357,"mc":[{"id":"1.195532865","rc":[{"atl":[[3.75,0],[3.65,24.4]],"id":40133341},{"atl":[[6.4,0],[5.8,16.67],[6.2,60.62]],"id":28041476},{"atl":[[2.98,16.28]],"id":36909459}],"con":true,"img":false}]}
{"op":"mcm","clk":"5322597297","pt":1646322205463,"mc":[{"id":"1.195532865","rc":[{"atl":[[3.65,41.07]],"id":40133341},{"atl":[[6,16.5]],"id":28041476},{"atl":[[3,9.47]],"id":36909459}],"con":true,"img":false}]}
{"op":"mcm","clk":"5322597305","pt":1646322205558,"mc":[{"id":"1.195532865","rc":[{"atl":[[3.6,2.71],[3.85,4.33],[3.7,5.95]],"id":40133341},{"atl":[[5.7,1.9]],"id":28041476},{"atl":[[3.1,0],[3.05,86.42],[3.15,53.47]],"id":36909459}],"con":true,"img":false}]}
{"op":"mcm","clk":"5322597315","pt":1646322205662,"mc":[{"id":"1.195532865","rc":[{"atl":[[3.85,8.25]],"id":40133341},{"atb":[[3.3,0]],"id":28041476},{"atl":[[6.4,4.72]],"id":28041476}],"con":true,"img":false}]}
{"op":"mcm","clk":"5322597330","pt":1646322205769,"mc":[{"id":"1.195532865","rc":[{"atl":[[3.85,3.92],[3.8,2.39],[3.7,26.01]],"id":40133341},{"atb":[[3.3,4.38]],"id":28041476},{"atl":[[3.15,70.87]],"id":36909459}],"con":true,"img":false}]}
{"op":"mcm","clk":"5322597337","pt":1646322205829,"mc":[{"id":"1.195532865","rc":[{"atl":[[5.9,15.36]],"id":28041476}],"con":true,"img":false}]}
{"op":"mcm","clk":"5322597350","pt":1646322205934,"mc":[{"id":"1.195532865","rc":[{"atl":[[6.2,52.93]],"id":28041476}],"con":true,"img":false}]}
{"op":"mcm","clk":"5322597372","pt":1646322206140,"mc":[{"id":"1.195532865","rc":[{"atl":[[3.85,0]],"id":40133341},{"atl":[[3.15,67.67]],"id":36909459}],"con":true,"img":false}]}
{"op":"mcm","clk":"5322597378","pt":1646322206247,"mc":[{"id":"1.195532865","rc":[{"atl":[[6.4,0]],"id":28041476}],"con":true,"img":false}]}
{"op":"mcm","clk":"5322597392","pt":1646322206381,"mc":[{"id":"1.195532865","rc":[{"atl":[[3.15,50.27]],"id":36909459}],"con":true,"img":false}]}
{"op":"mcm","clk":"5322597515","pt":1646322207858,"mc":[{"id":"1.195532865","rc":[{"atb":[[2.24,0]],"id":36909459}],"con":true,"img":false}]}
{"op":"mcm","clk":"5322597524","pt":1646322207962,"mc":[{"id":"1.195532865","rc":[{"atb":[[2.16,36.22]],"id":36909459}],"con":true,"img":false}]}
{"op":"mcm","clk":"5322597533","pt":1646322208068,"mc":[{"id":"1.195532865","rc":[{"atb":[[2.22,8.11]],"id":36909459}],"con":true,"img":false}]}
{"op":"mcm","clk":"5322597567","pt":1646322208437,"mc":[{"id":"1.195532865","rc":[{"atb":[[2.22,3.73]],"id":36909459}],"con":true,"img":false}]}
{"op":"mcm","clk":"5322597589","pt":1646322208750,"mc":[{"id":"1.195532865","rc":[{"atl":[[4.2,16.07]],"id":43189002}],"con":true,"img":false}]}
{"op":"mcm","clk":"5322597708","pt":1646322210377,"mc":[{"id":"1.195532865","rc":[{"atb":[[2.24,17.62]],"id":36909459}],"con":true,"img":false}]}
{"op":"mcm","clk":"5322597723","pt":1646322210538,"mc":[{"id":"1.195532865","rc":[{"atb":[[2.76,1.99]],"id":40133341},{"atl":[[5.2,2.34]],"id":40133341},{"atb":[[2.22,35.92],[2.16,4.03]],"id":36909459}],"con":true,"img":false}]}
{"op":"mcm","clk":"5322597731","pt":1646322210639,"mc":[{"id":"1.195532865","rc":[{"atb":[[2.4,23.7],[2.36,18.04],[2.34,44.2]],"id":40133341},{"atb":[[2.12,3.12]],"id":36909459}],"con":true,"img":false}]}
{"op":"mcm","clk":"5322597748","pt":1646322210848,"mc":[{"id":"1.195532865","rc":[{"atl":[[4.2,14.43]],"id":43189002}],"con":true,"img":false}]}
{"op":"mcm","clk":"5322597756","pt":1646322210955,"mc":[{"id":"1.195532865","rc":[{"atb":[[2.78,2.04]],"id":40133341}],"con":true,"img":false}]}
{"op":"mcm","clk":"5322597763","pt":1646322211060,"mc":[{"id":"1.195532865","rc":[{"atb":[[2.78,0]],"id":40133341},{"atl":[[3.2,0]],"id":36909459}],"con":true,"img":false}]}
{"op":"mcm","clk":"5322597774","pt":1646322211169,"mc":[{"id":"1.195532865","rc":[{"atb":[[2.34,44.21],[2.4,2.15],[2.2,83.33],[2.78,2.04]],"id":40133341},{"atb":[[4.7,2.5]],"id":35701941},{"atl":[[10.5,0]],"id":35701941},{"atb":[[2.12,0]],"id":36909459}],"con":true,"img":false}]}
{"op":"mcm","clk":"5322597777","pt":1646322211270,"mc":[{"id":"1.195532865","rc":[{"atb":[[2.34,39.01]],"id":40133341},{"atl":[[11.5,9.52],[9.8,5.55]],"id":35701941},{"atl":[[2.44,0]],"id":37307439}],"con":true,"img":false}]}
{"op":"mcm","clk":"5322597782","pt":1646322211377,"mc":[{"id":"1.195532865","rc":[{"atb":[[4.5,23.77],[4.6,2.57],[4.7,12.12]],"id":35701941}],"con":true,"img":false}]}
{"op":"mcm","clk":"5322597791","pt":1646322211437,"mc":[{"id":"1.195532865","rc":[{"atb":[[2.78,0]],"id":40133341},{"atl":[[6.2,72.16]],"id":28041476},{"atl":[[2.5,180.18],[2.46,34.72]],"id":37307439}],"con":true,"img":false}]}
{"op":"mcm","clk":"5322597801","pt":1646322211546,"mc":[{"id":"1.195532865","rc":[{"atl":[[4.3,41.96]],"id":43189002},{"atb":[[4.5,16.67]],"id":35701941}],"con":true,"img":false}]}
{"op":"mcm","clk":"5322597807","pt":1646322211645,"mc":[{"id":"1.195532865","rc":[{"atl":[[2.46,30.2]],"id":37307439}],"con":true,"img":false}]}
{"op":"mcm","clk":"5322597816","pt":1646322211755,"mc":[{"id":"1.195532865","rc":[{"atb":[[4.4,6.58]],"id":35701941},{"atl":[[9.8,0]],"id":35701941},{"atl":[[2.46,35.16]],"id":37307439}],"con":true,"img":false}]}
{"op":"mcm","clk":"5322597823","pt":1646322211854,"mc":[{"id":"1.195532865","rc":[{"atl":[[7.4,0]],"id":28041476}],"con":true,"img":false}]}
{"op":"mcm","clk":"5322597861","pt":1646322212276,"mc":[{"id":"1.195532865","rc":[{"atb":[[2.78,2.04]],"id":40133341},{"atb":[[4.4,0]],"id":35701941},{"atl":[[2.46,30.2]],"id":37307439}],"con":true,"img":false}]}
{"op":"mcm","clk":"5322597893","pt":1646322212547,"mc":[{"id":"1.195532865","rc":[{"atb":[[2.76,0]],"id":40133341}],"con":true,"img":false}]}
{"op":"mcm","clk":"5322597901","pt":1646322212646,"mc":[{"id":"1.195532865","rc":[{"atb":[[2.42,1.99]],"id":40133341}],"con":true,"img":false}]}
{"op":"mcm","clk":"5322597906","pt":1646322212750,"mc":[{"id":"1.195532865","rc":[{"atb":[[2.78,0]],"id":40133341}],"con":true,"img":false}]}
{"op":"mcm","clk":"5322597919","pt":1646322212861,"mc":[{"id":"1.195532865","rc":[{"atb":[[2.8,2],[2.44,2.87]],"id":40133341}],"con":true,"img":false}]}
{"op":"mcm","clk":"5322597936","pt":1646322213072,"mc":[{"id":"1.195532865","rc":[{"atb":[[2.8,0],[2.44,0],[2.34,0]],"id":40133341}],"con":true,"img":false}]}
{"op":"mcm","clk":"5322597964","pt":1646322213338,"mc":[{"id":"1.195532865","rc":[{"atb":[[2.44,2.87]],"id":40133341}],"con":true,"img":false}]}
{"op":"mcm","clk":"5322597997","pt":1646322213762,"mc":[{"id":"1.195532865","rc":[{"atb":[[2.42,0]],"id":40133341}],"con":true,"img":false}]}
{"op":"mcm","clk":"5322598008","pt":1646322213866,"mc":[{"id":"1.195532865","rc":[{"atb":[[2.46,1.99]],"id":40133341}],"con":true,"img":false}]}
