{"op":"mcm","clk":"5317728519","pt":1646251399900,"mc":[{"id":"1.195532877","marketDefinition":{"bspMarket":true,"turnInPlayEnabled":false,"persistenceEnabled":false,"marketBaseRate":5.0,"eventId":"31275720","eventTypeId":"4339","numberOfWinners":2,"bettingType":"ODDS","marketType":"PLACE","marketTime":"2022-03-03T17:44:00.000Z","suspendTime":"2022-03-03T17:44:00.000Z","bspReconciled":false,"complete":true,"inPlay":false,"crossMatching":false,"runnersVoidable":false,"numberOfActiveRunners":6,"betDelay":0,"status":"OPEN","runners":[{"status":"ACTIVE","sortPriority":1,"id":39236417,"name":"1. Bennos Bash"},{"status":"ACTIVE","sortPriority":2,"id":42327927,"name":"2. Bonville Lemon"},{"status":"ACTIVE","sortPriority":3,"id":38519823,"name":"3. Trapstyle Velvet"},{"status":"ACTIVE","sortPriority":4,"id":43189004,"name":"4. Pro Lois"},{"status":"ACTIVE","sortPriority":5,"id":41696085,"name":"5. Rays Freddy"},{"status":"ACTIVE","sortPriority":6,"id":43094641,"name":"6. Millgan Callum"}],"regulators":["MR_INT"],"venue":"Romford","countryCode":"GB","discountAllowed":false,"timezone":"Europe/London","openDate":"2022-03-03T13:57:00.000Z","version":4384107331,"name":"To Be Placed","eventName":"Romford 3rd Mar"},"rc":[],"con":true,"img":false}]}
{"op":"mcm","clk":"5317728870","pt":1646251401774,"mc":[{"id":"1.195532877","marketDefinition":{"bspMarket":true,"turnInPlayEnabled":false,"persistenceEnabled":false,"marketBaseRate":5.0,"eventId":"31275720","eventTypeId":"4339","numberOfWinners":2,"bettingType":"ODDS","marketType":"PLACE","marketTime":"2022-03-03T17:44:00.000Z","suspendTime":"2022-03-03T17:44:00.000Z","bspReconciled":false,"complete":true,"inPlay":false,"crossMatching":false,"runnersVoidable":false,"numberOfActiveRunners":6,"betDelay":0,"status":"OPEN","runners":[{"status":"ACTIVE","sortPriority":1,"id":39236417,"name":"1. Bennos Bash"},{"status":"ACTIVE","sortPriority":2,"id":42327927,"name":"2. Bonville Lemon"},{"status":"ACTIVE","sortPriority":3,"id":38519823,"name":"3. Trapstyle Velvet"},{"status":"ACTIVE","sortPriority":4,"id":43189004,"name":"4. Pro Lois"},{"status":"ACTIVE","sortPriority":5,"id":41696085,"name":"5. Rays Freddy"},{"status":"ACTIVE","sortPriority":6,"id":43094641,"name":"6. Millgan Callum"}],"regulators":["MR_INT"],"venue":"Romford","countryCode":"GB","discountAllowed":true,"timezone":"Europe/London","openDate":"2022-03-03T13:57:00.000Z","version":4384107331,"name":"To Be Placed","eventName":"Romford 3rd Mar"},"rc":[],"con":true,"img":false}]}
{"op":"mcm","clk":"5319286946","pt":1646269477370,"mc":[{"id":"1.195532877","rc":[{"spl":[[1.01,3]],"id":38519823},{"spn":1.0,"spf":1.0,"id":38519823}],"con":true,"img":false}]}
{"op":"mcm","clk":"5321983118","pt":1646315137120,"mc":[{"id":"1.195532877","rc":[{"atb":[[1.01,102.04]],"id":38519823},{"spn":1.01,"spf":1.0,"id":38519823}],"con":true,"img":false}]}
{"op":"mcm","clk":"5321983131","pt":1646315137218,"mc":[{"id":"1.195532877","rc":[{"atb":[[1.01,102.04]],"id":41696085},{"atb":[[1.01,102.04]],"id":43189004},{"atb":[[1.01,102.04]],"id":42327927},{"atb":[[1.01,102.04]],"id":39236417}],"con":true,"img":false}]}
{"op":"mcm","clk":"5321983141","pt":1646315137325,"mc":[{"id":"1.195532877","rc":[{"atb":[[1.01,102.04]],"id":43094641}],"con":true,"img":false}]}
{"op":"mcm","clk":"5322254635","pt":1646318125066,"mc":[{"id":"1.195532877","rc":[{"atl":[[1000,5]],"id":43094641},{"spn":500.5,"spf":"NaN","id":43094641},{"atl":[[1000,5]],"id":41696085},{"spn":500.5,"spf":"NaN","id":41696085},{"atl":[[1000,5]],"id":43189004},{"spn":500.5,"spf":"NaN","id":43189004},{"atl":[[1000,5]],"id":42327927},{"spn":500.5,"spf":"NaN","id":42327927},{"atl":[[1000,5]],"id":38519823},{"atl":[[1000,5]],"id":39236417},{"spn":500.5,"spf":"NaN","id":39236417}],"con":true,"img":false}]}
{"op":"mcm","clk":"5322254657","pt":1646318125367,"mc":[{"id":"1.195532877","rc":[{"atb":[[1.01,4802.04]],"id":43094641},{"atb":[[1.01,4802.04]],"id":41696085},{"atb":[[1.01,4802.04]],"id":43189004},{"atb":[[1.01,4802.04]],"id":42327927},{"atb":[[1.01,4802.04]],"id":38519823},{"atb":[[1.01,4802.04]],"id":39236417}],"con":true,"img":false}]}
{"op":"mcm","clk":"5322619359","pt":1646322442816,"mc":[{"id":"1.195532877","rc":[{"spl":[[1.01,1]],"id":43189004},{"spn":1.01,"spf":1.0,"id":43189004}],"con":true,"img":false}]}
{"op":"mcm","clk":"5323114523","pt":1646327643731,"mc":[{"id":"1.195532877","rc":[{"atb":[[1.01,5052.04]],"id":43094641},{"atb":[[1.01,5052.04]],"id":41696085},{"atb":[[1.01,5052.04]],"id":43189004},{"atb":[[1.01,5052.04]],"id":42327927},{"atb":[[1.01,5052.04]],"id":38519823},{"atb":[[1.01,5052.04]],"id":39236417}],"con":true,"img":false}]}
{"op":"mcm","clk":"5323144714","pt":1646327957818,"mc":[{"id":"1.195532877","rc":[{"atl":[[46,2.74]],"id":43094641},{"spn":23.5,"spf":"NaN","id":43094641},{"atl":[[46,2.74]],"id":41696085},{"spn":23.5,"spf":"NaN","id":41696085},{"atl":[[46,2.74]],"id":43189004},{"atl":[[46,2.74]],"id":42327927},{"spn":23.5,"spf":"NaN","id":42327927},{"atl":[[46,2.74]],"id":38519823},{"atl":[[46,2.74]],"id":39236417},{"spn":23.5,"spf":"NaN","id":39236417}],"con":true,"img":false}]}
{"op":"mcm","clk":"5323145818","pt":1646327970915,"mc":[{"id":"1.195532877","marketDefinition":{"bspMarket":true,"turnInPlayEnabled":false,"persistenceEnabled":false,"marketBaseRate":5.0,"eventId":"31275720","eventTypeId":"4339","numberOfWinners":2,"bettingType":"ODDS","marketType":"PLACE","marketTime":"2022-03-03T17:44:00.000Z","suspendTime":"2022-03-03T17:44:00.000Z","bspReconciled":false,"complete":true,"inPlay":false,"crossMatching":true,"runnersVoidable":false,"numberOfActiveRunners":6,"betDelay":0,"status":"OPEN","runners":[{"status":"ACTIVE","sortPriority":1,"id":39236417,"name":"1. Bennos Bash"},{"status":"ACTIVE","sortPriority":2,"id":42327927,"name":"2. Bonville Lemon"},{"status":"ACTIVE","sortPriority":3,"id":38519823,"name":"3. Trapstyle Velvet"},{"status":"ACTIVE","sortPriority":4,"id":43189004,"name":"4. Pro Lois"},{"status":"ACTIVE","sortPriority":5,"id":41696085,"name":"5. Rays Freddy"},{"status":"ACTIVE","sortPriority":6,"id":43094641,"name":"6. Millgan Callum"}],"regulators":["MR_INT"],"venue":"Romford","countryCode":"GB","discountAllowed":true,"timezone":"Europe/London","openDate":"2022-03-03T13:57:00.000Z","version":4384107331,"name":"To Be Placed","eventName":"Romford 3rd Mar"},"rc":[],"con":true,"img":false}]}
{"op":"mcm","clk":"5323145995","pt":1646327972811,"mc":[{"id":"1.195532877","rc":[{"atl":[[70,2.17],[80,3.16],[50,1],[60,1.69]],"id":43094641},{"atl":[[70,2.17],[80,3.16],[50,1],[60,1.69]],"id":41696085},{"atl":[[70,2.17],[80,3.16],[50,1],[60,1.69]],"id":43189004},{"atl":[[70,2.17],[80,3.16],[50,1],[60,1.69]],"id":42327927},{"atl":[[70,2.17],[80,3.16],[50,1],[60,1.69]],"id":38519823},{"atl":[[70,2.17],[80,3.16],[50,1],[60,1.69]],"id":39236417}],"con":true,"img":false}]}
{"op":"mcm","clk":"5323207713","pt":1646328625655,"mc":[{"id":"1.195532877","rc":[{"atb":[[1.01,5054.04]],"id":39236417}],"con":true,"img":false}]}
{"op":"mcm","clk":"5323207721","pt":1646328625758,"mc":[{"id":"1.195532877","rc":[{"atb":[[1.58,172.41]],"id":39236417},{"atl":[[10.5,2]],"id":39236417}],"con":true,"img":false}]}
{"op":"mcm","clk":"5323207732","pt":1646328625862,"mc":[{"id":"1.195532877","rc":[{"atb":[[1.74,135.14]],"id":43094641},{"atl":[[18.5,2]],"id":43094641},{"atb":[[1.96,104.17]],"id":41696085},{"atl":[[36,2]],"id":41696085},{"atb":[[1.51,196.08]],"id":43189004},{"atl":[[9.2,2]],"id":43189004},{"atb":[[1.65,153.85]],"id":42327927},{"atl":[[14,2]],"id":42327927},{"atb":[[1.25,400]],"id":38519823},{"atl":[[7.8,2]],"id":38519823},{"atb":[[1.01,5056.03]],"id":39236417}],"con":true,"img":false}]}
{"op":"mcm","clk":"5323207738","pt":1646328625970,"mc":[{"id":"1.195532877","rc":[{"atb":[[1.01,5054.04]],"id":39236417}],"con":true,"img":false}]}
{"op":"mcm","clk":"5323207750","pt":1646328626071,"mc":[{"id":"1.195532877","rc":[{"atb":[[1.02,1.99]],"id":39236417}],"con":true,"img":false}]}
{"op":"mcm","clk":"5323207758","pt":1646328626176,"mc":[{"id":"1.195532877","rc":[{"atb":[[1.01,5054.04]],"id":42327927}],"con":true,"img":false}]}
{"op":"mcm","clk":"5323207777","pt":1646328626383,"mc":[{"id":"1.195532877","rc":[{"atb":[[1.01,5056.03]],"id":42327927}],"con":true,"img":false}]}
{"op":"mcm","clk":"5323207797","pt":1646328626592,"mc":[{"id":"1.195532877","rc":[{"atb":[[1.01,5054.04]],"id":42327927}],"con":true,"img":false}]}
{"op":"mcm","clk":"5323207807","pt":1646328626650,"mc":[{"id":"1.195532877","rc":[{"atb":[[1.02,1.99]],"id":42327927}],"con":true,"img":false}]}
{"op":"mcm","clk":"5323207815","pt":1646328626815,"mc":[{"id":"1.195532877","rc":[{"atb":[[1.01,5054.04]],"id":38519823}],"con":true,"img":false}]}
{"op":"mcm","clk":"5323207831","pt":1646328626963,"mc":[{"id":"1.195532877","rc":[{"atb":[[1.01,5056.03]],"id":38519823}],"con":true,"img":false}]}
{"op":"mcm","clk":"5323207846","pt":1646328627173,"mc":[{"id":"1.195532877","rc":[{"atb":[[1.01,5054.04]],"id":38519823}],"con":true,"img":false}]}
{"op":"mcm","clk":"5323207856","pt":1646328627278,"mc":[{"id":"1.195532877","rc":[{"atb":[[1.02,1.99]],"id":38519823}],"con":true,"img":false}]}
{"op":"mcm","clk":"5323207882","pt":1646328627591,"mc":[{"id":"1.195532877","rc":[{"atb":[[1.01,5054.04]],"id":43189004}],"con":true,"img":false}]}
{"op":"mcm","clk":"5323207890","pt":1646328627698,"mc":[{"id":"1.195532877","rc":[{"atb":[[1.01,5056.03]],"id":43189004}],"con":true,"img":false}]}
{"op":"mcm","clk":"5323207908","pt":1646328627854,"mc":[{"id":"1.195532877","rc":[{"atb":[[1.72,55.56]],"id":43094641},{"atl":[[19.5,2.16],[50,0]],"id":43094641},{"atb":[[1.94,42.55]],"id":41696085},{"atl":[[40,1.03],[50,0]],"id":41696085},{"atb":[[1.01,5054.04],[1.49,81.63]],"id":43189004},{"atl":[[9.6,4.65],[50,0]],"id":43189004},{"atb":[[1.63,63.49]],"id":42327927},{"atl":[[50,0],[15,2.86]],"id":42327927},{"atb":[[1.23,173.91]],"id":38519823},{"atl":[[8.2,5.56],[50,0]],"id":38519823},{"atb":[[1.56,71.43]],"id":39236417},{"atl":[[11.5,3.81],[50,0]],"id":39236417}],"con":true,"img":false}]}
{"op":"mcm","clk":"5323207916","pt":1646328628011,"mc":[{"id":"1.195532877","rc":[{"atb":[[1.02,1.99]],"id":43189004}],"con":true,"img":false}]}
{"op":"mcm","clk":"5323207932","pt":1646328628166,"mc":[{"id":"1.195532877","rc":[{"atb":[[1.01,5054.04]],"id":41696085}],"con":true,"img":false}]}
{"op":"mcm","clk":"5323207957","pt":1646328628479,"mc":[{"id":"1.195532877","rc":[{"atb":[[1.01,5056.03]],"id":41696085}],"con":true,"img":false}]}
{"op":"mcm","clk":"5323207983","pt":1646328628790,"mc":[{"id":"1.195532877","rc":[{"atb":[[1.01,5054.04]],"id":41696085}],"con":true,"img":false}]}
{"op":"mcm","clk":"5323207995","pt":1646328628895,"mc":[{"id":"1.195532877","rc":[{"atb":[[1.02,1.99]],"id":41696085}],"con":true,"img":false}]}
{"op":"mcm","clk":"5323208005","pt":1646328629000,"mc":[{"id":"1.195532877","rc":[{"atb":[[1.01,5054.04]],"id":43094641}],"con":true,"img":false}]}
{"op":"mcm","clk":"5323208020","pt":1646328629116,"mc":[{"id":"1.195532877","rc":[{"atb":[[1.01,5056.03]],"id":43094641}],"con":true,"img":false}]}
{"op":"mcm","clk":"5323208030","pt":1646328629213,"mc":[{"id":"1.195532877","rc":[{"atb":[[1.01,5054.04]],"id":43094641}],"con":true,"img":false}]}
{"op":"mcm","clk":"5323208049","pt":1646328629370,"mc":[{"id":"1.195532877","rc":[{"atb":[[1.02,1.99]],"id":43094641}],"con":true,"img":false}]}
{"op":"mcm","clk":"5323208171","pt":1646328630566,"mc":[{"id":"1.195532877","rc":[{"atb":[[1.02,0]],"id":39236417}],"con":true,"img":false}]}
{"op":"mcm","clk":"5323208181","pt":1646328630671,"mc":[{"id":"1.195532877","rc":[{"atb":[[1.59,1.99]],"id":39236417}],"con":true,"img":false}]}
{"op":"mcm","clk":"5323208205","pt":1646328630986,"mc":[{"id":"1.195532877","rc":[{"atb":[[1.02,0]],"id":42327927},{"atb":[[1.57,70.18]],"id":39236417}],"con":true,"img":false}]}
{"op":"mcm","clk":"5323208215","pt":1646328631091,"mc":[{"id":"1.195532877","rc":[{"atb":[[1.66,1.99]],"id":42327927}],"con":true,"img":false}]}
{"op":"mcm","clk":"5323208240","pt":1646328631406,"mc":[{"id":"1.195532877","rc":[{"atb":[[1.02,0]],"id":38519823}],"con":true,"img":false}]}
{"op":"mcm","clk":"5323208252","pt":1646328631525,"mc":[{"id":"1.195532877","rc":[{"atb":[[1.26,1.99]],"id":38519823}],"con":true,"img":false}]}
{"op":"mcm","clk":"5323208276","pt":1646328631669,"mc":[{"id":"1.195532877","rc":[{"atb":[[1.02,0]],"id":43189004},{"atb":[[1.61,2.15]],"id":39236417}],"con":true,"img":false}]}
{"op":"mcm","clk":"5323208291","pt":1646328631773,"mc":[{"id":"1.195532877","rc":[{"atb":[[1.52,1.99]],"id":43189004}],"con":true,"img":false}]}
{"op":"mcm","clk":"5323208300","pt":1646328631881,"mc":[{"id":"1.195532877","rc":[{"atb":[[1.02,0]],"id":43094641}],"con":true,"img":false}]}
{"op":"mcm","clk":"5323208313","pt":1646328631984,"mc":[{"id":"1.195532877","rc":[{"atb":[[1.75,1.99]],"id":43094641}],"con":true,"img":false}]}
{"op":"mcm","clk":"5323208323","pt":1646328632089,"mc":[{"id":"1.195532877","rc":[{"atb":[[1.02,1117.65]],"id":43189004},{"atb":[[1.02,1239.99]],"id":38519823},{"atb":[[1.02,1103.41]],"id":39236417}],"con":true,"img":false}]}
{"op":"mcm","clk":"5323208449","pt":1646328633192,"mc":[{"id":"1.195532877","rc":[{"atb":[[1.73,54.79]],"id":43094641},{"atb":[[1.5,80]],"id":43189004},{"atb":[[1.64,62.5]],"id":42327927},{"atb":[[1.24,166.67]],"id":38519823},{"atb":[[1.59,69.79]],"id":39236417}],"con":true,"img":false}]}
{"op":"mcm","clk":"5323208456","pt":1646328633298,"mc":[{"id":"1.195532877","rc":[{"atb":[[1.59,67.8]],"id":39236417}],"con":true,"img":false}]}
{"op":"mcm","clk":"5323208470","pt":1646328633353,"mc":[{"id":"1.195532877","rc":[{"atb":[[1.62,1.99]],"id":39236417}],"con":true,"img":false}]}
{"op":"mcm","clk":"5323208478","pt":1646328633466,"mc":[{"id":"1.195532877","rc":[{"atb":[[1.03,1576.62]],"id":43094641},{"atb":[[1.03,1576.62]],"id":41696085},{"atb":[[1.03,1576.62]],"id":43189004},{"atb":[[1.03,1576.62]],"id":42327927},{"atb":[[1.03,1576.62]],"id":38519823},{"atb":[[1.03,1576.62]],"id":39236417}],"con":true,"img":false}]}
{"op":"mcm","clk":"5323208506","pt":1646328633665,"mc":[{"id":"1.195532877","rc":[{"atb":[[1.77,2.15]],"id":43094641},{"atb":[[1.54,2.15]],"id":43189004},{"atb":[[1.68,2.15]],"id":42327927}],"con":true,"img":false}]}
{"op":"mcm","clk":"5323208556","pt":1646328634185,"mc":[{"id":"1.195532877","rc":[{"atb":[[1.66,0]],"id":42327927}],"con":true,"img":false}]}
{"op":"mcm","clk":"5323208570","pt":1646328634289,"mc":[{"id":"1.195532877","rc":[{"atb":[[1.69,1.99]],"id":42327927}],"con":true,"img":false}]}
{"op":"mcm","clk":"5323208613","pt":1646328634662,"mc":[{"id":"1.195532877","rc":[{"atb":[[1.52,0]],"id":43189004}],"con":true,"img":false}]}
{"op":"mcm","clk":"5323208625","pt":1646328634765,"mc":[{"id":"1.195532877","rc":[{"atb":[[1.55,1.99]],"id":43189004}],"con":true,"img":false}]}
{"op":"mcm","clk":"5323208648","pt":1646328634982,"mc":[{"id":"1.195532877","rc":[{"atb":[[1.75,0]],"id":43094641}],"con":true,"img":false}]}
{"op":"mcm","clk":"5323208659","pt":1646328635077,"mc":[{"id":"1.195532877","rc":[{"atb":[[1.78,1.99]],"id":43094641},{"atb":[[1.58,0],[1.62,4.15]],"id":39236417}],"con":true,"img":false}]}
{"op":"mcm","clk":"5323208669","pt":1646328635184,"mc":[{"id":"1.195532877","rc":[{"atb":[[1.74,0],[1.77,56.94]],"id":43094641},{"atb":[[1.55,4.15],[1.51,0]],"id":43189004},{"atb":[[1.65,0],[1.69,4.15]],"id":42327927},{"atb":[[1.62,1.99],[1.61,69.95]],"id":39236417}],"con":true,"img":false}]}
{"op":"mcm","clk":"5323208682","pt":1646328635291,"mc":[{"id":"1.195532877","rc":[{"atb":[[1.55,1.99],[1.54,82.15]],"id":43189004},{"atb":[[1.68,64.65],[1.69,1.99]],"id":42327927}],"con":true,"img":false}]}
{"op":"mcm","clk":"5323208796","pt":1646328636281,"mc":[{"id":"1.195532877","rc":[{"atb":[[1.76,52.63]],"id":43094641},{"atb":[[1.53,75.47]],"id":43189004},{"atb":[[1.67,59.7]],"id":42327927},{"atb":[[1.59,0],[1.6,66.67]],"id":39236417}],"con":true,"img":false}]}
{"op":"mcm","clk":"5323208879","pt":1646328637170,"mc":[{"id":"1.195532877","rc":[{"atb":[[1.02,0]],"id":43189004},{"atb":[[1.02,0]],"id":38519823},{"atb":[[1.02,0]],"id":39236417}],"con":true,"img":false}]}
{"op":"mcm","clk":"5323208944","pt":1646328637910,"mc":[{"id":"1.195532877","rc":[{"atb":[[1.92,108.7]],"id":41696085},{"atl":[[44,2.33]],"id":41696085}],"con":true,"img":false}]}
{"op":"mcm","clk":"5323208961","pt":1646328638116,"mc":[{"id":"1.195532877","rc":[{"atb":[[1.03,0]],"id":43094641},{"atb":[[1.03,0]],"id":43189004},{"atb":[[1.03,0]],"id":42327927},{"atb":[[1.03,0]],"id":38519823},{"atb":[[1.03,0]],"id":39236417}],"con":true,"img":false}]}
{"op":"mcm","clk":"5323209063","pt":1646328639003,"mc":[{"id":"1.195532877","rc":[{"atb":[[1.99,2.15]],"id":41696085}],"con":true,"img":false}]}
{"op":"mcm","clk":"5323209071","pt":1646328639069,"mc":[{"id":"1.195532877","rc":[{"atl":[[70,0],[80,0],[60,0]],"id":41696085}],"con":true,"img":false}]}
{"op":"mcm","clk":"5323209083","pt":1646328639216,"mc":[{"id":"1.195532877","rc":[{"atb":[[1.99,44.7],[1.97,41.24],[1.96,0]],"id":41696085}],"con":true,"img":false}]}
{"op":"mcm","clk":"5323209179","pt":1646328640159,"mc":[{"id":"1.195532877","rc":[{"atb":[[1.03,0]],"id":41696085}],"con":true,"img":false}]}
{"op":"mcm","clk":"5323209399","pt":1646328642682,"mc":[{"id":"1.195532877","rc":[{"atb":[[1.51,71.74]],"id":43189004},{"atb":[[1.26,142.7]],"id":38519823},{"atb":[[1.58,63.08]],"id":39236417}],"con":true,"img":false}]}
{"op":"mcm","clk":"5323209426","pt":1646328642889,"mc":[{"id":"1.195532877","rc":[{"atb":[[1.27,166.67],[1.25,0]],"id":38519823}],"con":true,"img":false}]}
{"op":"mcm","clk":"5323209455","pt":1646328643190,"mc":[{"id":"1.195532877","rc":[{"atb":[[1.25,160]],"id":38519823},{"atl":[[8.6,13.16]],"id":38519823}],"con":true,"img":false}]}
{"op":"mcm","clk":"5323209488","pt":1646328643607,"mc":[{"id":"1.195532877","rc":[{"atb":[[1.26,140.71]],"id":38519823}],"con":true,"img":false}]}
{"op":"mcm","clk":"5323209500","pt":1646328643661,"mc":[{"id":"1.195532877","rc":[{"atb":[[1.28,1.99]],"id":38519823}],"con":true,"img":false}]}
{"op":"mcm","clk":"5323209540","pt":1646328644181,"mc":[{"id":"1.195532877","rc":[{"atb":[[1.25,0],[1.26,294.56]],"id":38519823},{"atl":[[70,0],[80,0],[60,0]],"id":38519823}],"con":true,"img":false}]}
{"op":"mcm","clk":"5323209560","pt":1646328644496,"mc":[{"id":"1.195532877","rc":[{"atb":[[1.79,3.97]],"id":43094641},{"atb":[[1.56,3.97]],"id":43189004},{"atb":[[1.7,3.97]],"id":42327927},{"atb":[[1.27,170.64]],"id":38519823},{"atb":[[1.63,3.97]],"id":39236417}],"con":true,"img":false}]}
{"op":"mcm","clk":"5323209565","pt":1646328644601,"mc":[{"id":"1.195532877","rc":[{"atb":[[1.8,3.97]],"id":43094641},{"atb":[[1.68,2.15]],"id":42327927},{"atb":[[1.64,3.97],[1.61,2.15]],"id":39236417}],"con":true,"img":false}]}
{"op":"mcm","clk":"5323209576","pt":1646328644714,"mc":[{"id":"1.195532877","rc":[{"atb":[[1.77,2.15]],"id":43094641},{"atb":[[1.57,3.97],[1.54,2.15]],"id":43189004},{"atb":[[1.71,3.97]],"id":42327927}],"con":true,"img":false}]}
{"op":"mcm","clk":"5323209618","pt":1646328645076,"mc":[{"id":"1.195532877","rc":[{"atb":[[1.78,53.27],[1.76,0]],"id":43094641},{"atb":[[1.55,74.72],[1.53,0]],"id":43189004},{"atb":[[1.67,0],[1.69,59.96]],"id":42327927},{"atb":[[1.6,0],[1.62,66.51]],"id":39236417}],"con":true,"img":false}]}
{"op":"mcm","clk":"5323209629","pt":1646328645180,"mc":[{"id":"1.195532877","rc":[{"atb":[[1.62,64.52]],"id":39236417}],"con":true,"img":false}]}
{"op":"mcm","clk":"5323209641","pt":1646328645294,"mc":[{"id":"1.195532877","rc":[{"atb":[[1.65,1.99]],"id":39236417}],"con":true,"img":false}]}
{"op":"mcm","clk":"5323209653","pt":1646328645497,"mc":[{"id":"1.195532877","rc":[{"atb":[[1.81,2.15],[1.77,0]],"id":43094641},{"atb":[[1.58,2.15],[1.54,0]],"id":43189004},{"atb":[[1.72,2.15],[1.68,0]],"id":42327927},{"atb":[[1.65,4.14],[1.61,0]],"id":39236417}],"con":true,"img":false}]}
{"op":"mcm","clk":"5323209664","pt":1646328645599,"mc":[{"id":"1.195532877","rc":[{"atb":[[1.69,57.97]],"id":42327927}],"con":true,"img":false}]}
{"op":"mcm","clk":"5323209671","pt":1646328645706,"mc":[{"id":"1.195532877","rc":[{"atb":[[1.72,4.14]],"id":42327927}],"con":true,"img":false}]}
{"op":"mcm","clk":"5323209680","pt":1646328645809,"mc":[{"id":"1.195532877","rc":[{"atb":[[1.55,72.73]],"id":43189004}],"con":true,"img":false}]}
{"op":"mcm","clk":"5323209695","pt":1646328645872,"mc":[{"id":"1.195532877","rc":[{"atb":[[1.58,4.14]],"id":43189004}],"con":true,"img":false}]}
{"op":"mcm","clk":"5323209712","pt":1646328646072,"mc":[{"id":"1.195532877","rc":[{"atb":[[1.78,51.28]],"id":43094641}],"con":true,"img":false}]}
{"op":"mcm","clk":"5323209724","pt":1646328646178,"mc":[{"id":"1.195532877","rc":[{"atb":[[1.81,4.14]],"id":43094641}],"con":true,"img":false}]}
{"op":"mcm","clk":"5323209774","pt":1646328646802,"mc":[{"id":"1.195532877","rc":[{"atb":[[1.95,49.78]],"id":41696085}],"con":true,"img":false}]}
{"op":"mcm","clk":"5323209848","pt":1646328647690,"mc":[{"id":"1.195532877","rc":[{"atb":[[1.51,0]],"id":43189004},{"atb":[[1.26,153.85]],"id":38519823},{"atb":[[1.58,0]],"id":39236417}],"con":true,"img":false}]}
{"op":"mcm","clk":"5323209988","pt":1646328649204,"mc":[{"id":"1.195532877","rc":[{"atl":[[48,3.19]],"id":41696085}],"con":true,"img":false}]}
{"op":"mcm","clk":"5323210035","pt":1646328649728,"mc":[{"id":"1.195532877","rc":[{"atb":[[1.79,50.63],[1.78,0]],"id":43094641},{"atb":[[1.56,71.43],[1.55,0]],"id":43189004},{"atb":[[1.7,57.14],[1.69,0]],"id":42327927},{"atb":[[1.27,166.67]],"id":38519823},{"atb":[[1.63,63.49],[1.62,0]],"id":39236417}],"con":true,"img":false}]}
{"op":"mcm","clk":"5323210164","pt":1646328651509,"mc":[{"id":"1.195532877","rc":[{"atb":[[1.59,2.9]],"id":43189004},{"atb":[[1.28,122.83]],"id":38519823},{"atb":[[1.66,2.9]],"id":39236417}],"con":true,"img":false}]}
{"op":"mcm","clk":"5323210177","pt":1646328651716,"mc":[{"id":"1.195532877","rc":[{"atb":[[1.27,0],[1.29,153.85]],"id":38519823}],"con":true,"img":false}]}
{"op":"mcm","clk":"5323210345","pt":1646328653286,"mc":[{"id":"1.195532877","rc":[{"atb":[[1.65,2.15]],"id":39236417}],"con":true,"img":false}]}
{"op":"mcm","clk":"5323210359","pt":1646328653394,"mc":[{"id":"1.195532877","rc":[{"atb":[[1.67,1.99]],"id":39236417}],"con":true,"img":false}]}
{"op":"mcm","clk":"5323210386","pt":1646328653601,"mc":[{"id":"1.195532877","rc":[{"atb":[[1.28,120.84]],"id":38519823}],"con":true,"img":false}]}
{"op":"mcm","clk":"5323210399","pt":1646328653706,"mc":[{"id":"1.195532877","rc":[{"atb":[[1.8,0],[1.82,4.15]],"id":43094641},{"atb":[[1.3,1.99]],"id":38519823},{"atb":[[1.64,0],[1.67,4.15]],"id":39236417}],"con":true,"img":false}]}
{"op":"mcm","clk":"5323210408","pt":1646328653805,"mc":[{"id":"1.195532877","rc":[{"atb":[[1.59,6.87],[1.57,0]],"id":43189004},{"atb":[[1.73,4.15],[1.71,0]],"id":42327927},{"atb":[[1.67,1.99],[1.66,6.88]],"id":39236417}],"con":true,"img":false}]}
{"op":"mcm","clk":"5323210419","pt":1646328653907,"mc":[{"id":"1.195532877","rc":[{"atb":[[1.58,2.15]],"id":43189004}],"con":true,"img":false}]}
{"op":"mcm","clk":"5323210426","pt":1646328654005,"mc":[{"id":"1.195532877","rc":[{"atb":[[1.6,1.99]],"id":43189004}],"con":true,"img":false}]}
{"op":"mcm","clk":"5323210448","pt":1646328654228,"mc":[{"id":"1.195532877","rc":[{"atb":[[1.28,263.7],[1.26,0]],"id":38519823},{"atl":[[9,18.75]],"id":38519823}],"con":true,"img":false}]}
{"op":"mcm","clk":"5323210467","pt":1646328654375,"mc":[{"id":"1.195532877","rc":[{"atb":[[1.72,2.15]],"id":42327927}],"con":true,"img":false}]}
{"op":"mcm","clk":"5323210478","pt":1646328654495,"mc":[{"id":"1.195532877","rc":[{"atb":[[1.73,0],[1.72,59.29],[1.74,1.99]],"id":42327927}],"con":true,"img":false}]}
{"op":"mcm","clk":"5323210492","pt":1646328654700,"mc":[{"id":"1.195532877","rc":[{"atb":[[1.81,2.15]],"id":43094641}],"con":true,"img":false}]}
{"op":"mcm","clk":"5323210505","pt":1646328654807,"mc":[{"id":"1.195532877","rc":[{"atb":[[1.83,1.99],[1.81,52.78]],"id":43094641}],"con":true,"img":false}]}
{"op":"mcm","clk":"5323210512","pt":1646328654906,"mc":[{"id":"1.195532877","rc":[{"atb":[[1.82,0],[1.79,105.42],[1.81,2.15]],"id":43094641}],"con":true,"img":false}]}
{"op":"mcm","clk":"5323210523","pt":1646328655012,"mc":[{"id":"1.195532877","rc":[{"atb":[[1.83,6.14],[1.79,50.63]],"id":43094641}],"con":true,"img":false}]}
{"op":"mcm","clk":"5323210532","pt":1646328655111,"mc":[{"id":"1.195532877","rc":[{"atb":[[1.81,56.94]],"id":43094641}],"con":true,"img":false}]}
{"op":"mcm","clk":"5323210540","pt":1646328655209,"mc":[{"id":"1.195532877","rc":[{"atb":[[1.83,1.98]],"id":43094641}],"con":true,"img":false}]}
{"op":"mcm","clk":"5323210550","pt":1646328655314,"mc":[{"id":"1.195532877","rc":[{"atb":[[1.83,52.62],[1.81,2.15]],"id":43094641},{"atb":[[1.74,0]],"id":42327927}],"con":true,"img":false}]}
{"op":"mcm","clk":"5323210556","pt":1646328655419,"mc":[{"id":"1.195532877","rc":[{"atb":[[1.73,1.99]],"id":42327927}],"con":true,"img":false}]}
{"op":"mcm","clk":"5323210562","pt":1646328655477,"mc":[{"id":"1.195532877","rc":[{"atb":[[1.83,1.99],[1.81,56.94]],"id":43094641}],"con":true,"img":false}]}
{"op":"mcm","clk":"5323210575","pt":1646328655594,"mc":[{"id":"1.195532877","rc":[{"atb":[[1.79,0],[1.81,106.32]],"id":43094641},{"atb":[[1.56,0],[1.58,71.12]],"id":43189004},{"atb":[[1.7,0],[1.71,56.34]],"id":42327927},{"atb":[[1.63,0],[1.65,63.69]],"id":39236417}],"con":true,"img":false}]}
{"op":"mcm","clk":"5323210603","pt":1646328655896,"mc":[{"id":"1.195532877","rc":[{"atb":[[1.82,8.29]],"id":43094641},{"atb":[[1.6,7.79]],"id":43189004},{"atb":[[1.73,10.28]],"id":42327927},{"atb":[[1.29,316.94]],"id":38519823},{"atb":[[1.67,7.79]],"id":39236417}],"con":true,"img":false}]}
{"op":"mcm","clk":"5323210620","pt":1646328656106,"mc":[{"id":"1.195532877","rc":[{"atb":[[1.61,7.79]],"id":43189004},{"atb":[[1.68,7.79],[1.66,2.9]],"id":39236417}],"con":true,"img":false}]}
{"op":"mcm","clk":"5323210632","pt":1646328656213,"mc":[{"id":"1.195532877","rc":[{"atb":[[1.83,0]],"id":43094641},{"atb":[[1.59,2.9]],"id":43189004}],"con":true,"img":false}]}
{"op":"mcm","clk":"5323210641","pt":1646328656321,"mc":[{"id":"1.195532877","rc":[{"atb":[[1.82,10.28]],"id":43094641},{"atb":[[1.28,142.86]],"id":38519823}],"con":true,"img":false}]}
{"op":"mcm","clk":"5323210737","pt":1646328656902,"mc":[{"id":"1.195532877","rc":[{"atb":[[1.67,5.8]],"id":39236417}],"con":true,"img":false}]}
{"op":"mcm","clk":"5323210748","pt":1646328657010,"mc":[{"id":"1.195532877","rc":[{"atb":[[1.69,1.99]],"id":39236417}],"con":true,"img":false}]}
{"op":"mcm","clk":"5323210767","pt":1646328657213,"mc":[{"id":"1.195532877","rc":[{"atb":[[1.72,57.14],[1.76,2.15]],"id":42327927}],"con":true,"img":false}]}
{"op":"mcm","clk":"5323210775","pt":1646328657316,"mc":[{"id":"1.195532877","rc":[{"atb":[[1.6,5.8]],"id":43189004}],"con":true,"img":false}]}
{"op":"mcm","clk":"5323210783","pt":1646328657421,"mc":[{"id":"1.195532877","rc":[{"atb":[[1.62,1.99]],"id":43189004}],"con":true,"img":false}]}
{"op":"mcm","clk":"5323210923","pt":1646328658630,"mc":[{"id":"1.195532877","rc":[{"atb":[[1.59,0]],"id":43189004},{"atb":[[1.66,0]],"id":39236417}],"con":true,"img":false}]}
{"op":"mcm","clk":"5323210960","pt":1646328658905,"mc":[{"id":"1.195532877","rc":[{"atb":[[1.82,1.99]],"id":43094641},{"atb":[[1.73,8.29]],"id":42327927},{"atb":[[1.29,153.85]],"id":38519823}],"con":true,"img":false}]}
{"op":"mcm","clk":"5323210975","pt":1646328659008,"mc":[{"id":"1.195532877","rc":[{"atb":[[1.77,1.99]],"id":42327927}],"con":true,"img":false}]}
{"op":"mcm","clk":"5323210996","pt":1646328659221,"mc":[{"id":"1.195532877","rc":[{"atl":[[55,4.63]],"id":41696085}],"con":true,"img":false}]}
{"op":"mcm","clk":"5323211200","pt":1646328661200,"mc":[{"id":"1.195532877","rc":[{"atb":[[1.8,50],[1.81,56.94]],"id":43094641},{"atb":[[1.6,66.67],[1.58,2.15]],"id":43189004},{"atb":[[1.73,0],[1.75,53.33],[1.71,0]],"id":42327927},{"atb":[[1.25,146.34]],"id":38519823},{"atb":[[1.67,59.7],[1.65,2.15]],"id":39236417}],"con":true,"img":false}]}
{"op":"mcm","clk":"5323211449","pt":1646328663534,"mc":[{"id":"1.195532877","rc":[{"atb":[[1.72,0],[1.77,4.15]],"id":42327927}],"con":true,"img":false}]}
{"op":"mcm","clk":"5323211516","pt":1646328664122,"mc":[{"id":"1.195532877","rc":[{"atb":[[1.74,8.44]],"id":43094641},{"atb":[[1.62,8.84]],"id":43189004},{"atb":[[1.26,250],[1.31,3.97]],"id":38519823},{"atl":[[9.4,29.76]],"id":38519823},{"atb":[[1.69,8.84]],"id":39236417}],"con":true,"img":false}]}
{"op":"mcm","clk":"5323211536","pt":1646328664348,"mc":[{"id":"1.195532877","rc":[{"atb":[[1.63,8.84],[1.61,0]],"id":43189004},{"atb":[[1.32,3.97],[1.29,0]],"id":38519823},{"atb":[[1.68,0],[1.7,8.84]],"id":39236417}],"con":true,"img":false}]}
{"op":"mcm","clk":"5323211644","pt":1646328665326,"mc":[{"id":"1.195532877","rc":[{"atb":[[1.69,6.85]],"id":39236417}],"con":true,"img":false}]}
{"op":"mcm","clk":"5323211657","pt":1646328665429,"mc":[{"id":"1.195532877","rc":[{"atb":[[1.71,1.99]],"id":39236417}],"con":true,"img":false}]}
{"op":"mcm","clk":"5323211687","pt":1646328665628,"mc":[{"id":"1.195532877","rc":[{"atb":[[1.3,0]],"id":38519823}],"con":true,"img":false}]}
{"op":"mcm","clk":"5323211698","pt":1646328665732,"mc":[{"id":"1.195532877","rc":[{"atb":[[1.33,1.99]],"id":38519823}],"con":true,"img":false}]}
{"op":"mcm","clk":"5323211732","pt":1646328666004,"mc":[{"id":"1.195532877","rc":[{"atb":[[1.62,6.85]],"id":43189004}],"con":true,"img":false}]}
{"op":"mcm","clk":"5323211747","pt":1646328666105,"mc":[{"id":"1.195532877","rc":[{"atb":[[1.64,1.99]],"id":43189004}],"con":true,"img":false}]}
{"op":"mcm","clk":"5323211868","pt":1646328667262,"mc":[{"id":"1.195532877","rc":[{"atb":[[1.62,71.37]],"id":43189004},{"atb":[[1.28,0],[1.31,133]],"id":38519823},{"atb":[[1.69,64.82]],"id":39236417}],"con":true,"img":false}]}
{"op":"mcm","clk":"5323211883","pt":1646328667365,"mc":[{"id":"1.195532877","rc":[{"atb":[[1.6,0]],"id":43189004},{"atb":[[1.67,0]],"id":39236417}],"con":true,"img":false}]}
{"op":"mcm","clk":"5323211899","pt":1646328667428,"mc":[{"id":"1.195532877","rc":[{"atb":[[1.63,12.81]],"id":43189004},{"atb":[[1.78,8.3]],"id":42327927},{"atb":[[1.7,12.81]],"id":39236417}],"con":true,"img":false}]}
{"op":"mcm","clk":"5323211920","pt":1646328667633,"mc":[{"id":"1.195532877","rc":[{"atb":[[1.26,0],[1.24,0]],"id":38519823}],"con":true,"img":false}]}
{"op":"mcm","clk":"5323211930","pt":1646328667739,"mc":[{"id":"1.195532877","rc":[{"atb":[[1.34,2.15]],"id":38519823}],"con":true,"img":false}]}
{"op":"mcm","clk":"5323211953","pt":1646328667942,"mc":[{"id":"1.195532877","rc":[{"atb":[[1.32,0],[1.34,4.31]],"id":38519823}],"con":true,"img":false}]}
{"op":"mcm","clk":"5323211980","pt":1646328668114,"mc":[{"id":"1.195532877","rc":[{"atb":[[1.33,6.31],[1.34,2.15]],"id":38519823}],"con":true,"img":false}]}
{"op":"mcm","clk":"5323212019","pt":1646328668431,"mc":[{"id":"1.195532877","rc":[{"atb":[[1.77,2.16]],"id":42327927}],"con":true,"img":false}]}
{"op":"mcm","clk":"5323212030","pt":1646328668542,"mc":[{"id":"1.195532877","rc":[{"atb":[[1.79,1.99]],"id":42327927}],"con":true,"img":false}]}
{"op":"mcm","clk":"5323212061","pt":1646328668821,"mc":[{"id":"1.195532877","rc":[{"atb":[[1.33,4.32]],"id":38519823}],"con":true,"img":false}]}
{"op":"mcm","clk":"5323212075","pt":1646328668923,"mc":[{"id":"1.195532877","rc":[{"atb":[[1.62,64.52]],"id":43189004},{"atb":[[1.25,0],[1.35,1.99]],"id":38519823},{"atb":[[1.69,57.97]],"id":39236417}],"con":true,"img":false}]}
{"op":"mcm","clk":"5323212095","pt":1646328669129,"mc":[{"id":"1.195532877","rc":[{"atb":[[1.33,0],[1.35,4.15]],"id":38519823}],"con":true,"img":false}]}
{"op":"mcm","clk":"5323212172","pt":1646328669815,"mc":[{"id":"1.195532877","rc":[{"atb":[[1.74,0]],"id":43094641},{"atb":[[1.31,129.03]],"id":38519823}],"con":true,"img":false}]}
{"op":"mcm","clk":"5323212310","pt":1646328671223,"mc":[{"id":"1.195532877","rc":[{"atb":[[1.78,128.21]],"id":43094641},{"atl":[[21,5]],"id":43094641},{"atb":[[1.77,54.11],[1.75,0]],"id":42327927},{"atl":[[16,6.67]],"id":42327927}],"con":true,"img":false}]}
{"op":"mcm","clk":"5323212418","pt":1646328672415,"mc":[{"id":"1.195532877","rc":[{"atb":[[1.63,8.84]],"id":43189004},{"atb":[[1.79,10.3],[1.78,0],[1.77,51.95]],"id":42327927},{"atb":[[1.7,8.84]],"id":39236417}],"con":true,"img":false}]}
{"op":"mcm","clk":"5323212496","pt":1646328673240,"mc":[{"id":"1.195532877","rc":[{"atb":[[1.73,0],[1.01,4804.04]],"id":43094641},{"atl":[[70,0],[80,0],[60,0]],"id":43094641},{"atl":[[80,0]],"id":42327927},{"atb":[[1.33,121.21]],"id":38519823}],"con":true,"img":false}]}
{"op":"mcm","clk":"5323212607","pt":1646328674511,"mc":[{"id":"1.195532877","rc":[{"atb":[[1.51,29.6]],"id":43189004},{"atb":[[1.24,7.89]],"id":38519823},{"atb":[[1.58,29.6]],"id":39236417}],"con":true,"img":false}]}
{"op":"mcm","clk":"5323212710","pt":1646328675447,"mc":[{"id":"1.195532877","rc":[{"atb":[[1.83,3.97]],"id":43094641},{"atb":[[1.32,12.45]],"id":38519823}],"con":true,"img":false}]}
{"op":"mcm","clk":"5323212729","pt":1646328675648,"mc":[{"id":"1.195532877","rc":[{"atb":[[1.81,2.15],[1.84,3.97]],"id":43094641}],"con":true,"img":false}]}
{"op":"mcm","clk":"5323212791","pt":1646328676229,"mc":[{"id":"1.195532877","rc":[{"atb":[[1.82,0]],"id":43094641}],"con":true,"img":false}]}
{"op":"mcm","clk":"5323212803","pt":1646328676340,"mc":[{"id":"1.195532877","rc":[{"atb":[[1.85,1.99]],"id":43094641}],"con":true,"img":false}]}
{"op":"mcm","clk":"5323212888","pt":1646328677222,"mc":[{"id":"1.195532877","rc":[{"atb":[[1.6,166.67]],"id":43189004},{"atl":[[10,11.11]],"id":43189004},{"atb":[[1.24,0]],"id":38519823},{"atb":[[1.67,149.25]],"id":39236417},{"atl":[[12.5,8.7]],"id":39236417}],"con":true,"img":false}]}
{"op":"mcm","clk":"5323212997","pt":1646328678346,"mc":[{"id":"1.195532877","rc":[{"atb":[[1.58,0],[1.66,2.15]],"id":43189004},{"atb":[[1.73,2.15],[1.65,0]],"id":39236417}],"con":true,"img":false}]}
{"op":"mcm","clk":"5323213018","pt":1646328678544,"mc":[{"id":"1.195532877","rc":[{"atb":[[1.83,52.16]],"id":43094641},{"atb":[[1.64,64.49],[1.63,0],[1.62,0],[1.66,4.31]],"id":43189004},{"atl":[[80,0]],"id":43189004},{"atb":[[1.73,4.31],[1.7,0],[1.68,7.25],[1.71,58.33],[1.69,0]],"id":39236417},{"atl":[[70,0],[80,0],[60,0]],"id":39236417}],"con":true,"img":false}]}
{"op":"mcm","clk":"5323213039","pt":1646328678711,"mc":[{"id":"1.195532877","rc":[{"atb":[[1.63,64.52],[1.66,2.15],[1.65,3.97]],"id":43189004},{"atb":[[1.8,20.59]],"id":42327927},{"atb":[[1.73,2.15],[1.72,3.97],[1.68,0],[1.7,57.97]],"id":39236417}],"con":true,"img":false}]}
{"op":"mcm","clk":"5323213059","pt":1646328678918,"mc":[{"id":"1.195532877","rc":[{"atb":[[1.01,4804.04],[1.49,0]],"id":43189004},{"atb":[[1.56,0]],"id":39236417}],"con":true,"img":false}]}
{"op":"mcm","clk":"5323213139","pt":1646328679856,"mc":[{"id":"1.195532877","rc":[{"atb":[[1.71,56.34]],"id":39236417}],"con":true,"img":false}]}
{"op":"mcm","clk":"5323213146","pt":1646328679949,"mc":[{"id":"1.195532877","rc":[{"atb":[[1.74,1.99]],"id":39236417}],"con":true,"img":false}]}
{"op":"mcm","clk":"5323213169","pt":1646328680119,"mc":[{"id":"1.195532877","rc":[{"atb":[[1.79,8.31]],"id":42327927}],"con":true,"img":false}]}
{"op":"mcm","clk":"5323213180","pt":1646328680265,"mc":[{"id":"1.195532877","rc":[{"atb":[[1.81,1.99]],"id":42327927}],"con":true,"img":false}]}
{"op":"mcm","clk":"5323213212","pt":1646328680537,"mc":[{"id":"1.195532877","rc":[{"atb":[[1.64,62.5]],"id":43189004}],"con":true,"img":false}]}
{"op":"mcm","clk":"5323213225","pt":1646328680642,"mc":[{"id":"1.195532877","rc":[{"atb":[[1.67,1.99]],"id":43189004}],"con":true,"img":false}]}
{"op":"mcm","clk":"5323213243","pt":1646328680844,"mc":[{"id":"1.195532877","rc":[{"atb":[[1.65,65.51]],"id":43189004},{"atb":[[1.79,58.94],[1.77,0]],"id":42327927},{"atb":[[1.72,59.53],[1.71,0]],"id":39236417}],"con":true,"img":false}]}
{"op":"mcm","clk":"5323213260","pt":1646328681047,"mc":[{"id":"1.195532877","rc":[{"atb":[[1.83,48.19]],"id":43094641},{"atb":[[1.32,0]],"id":38519823}],"con":true,"img":false}]}
{"op":"mcm","clk":"5323213279","pt":1646328681210,"mc":[{"id":"1.195532877","rc":[{"atb":[[1.79,50.63],[1.81,22.59]],"id":42327927}],"con":true,"img":false}]}
{"op":"mcm","clk":"5323213404","pt":1646328682524,"mc":[{"id":"1.195532877","rc":[{"atb":[[1.51,0]],"id":43189004},{"atb":[[1.36,2.9]],"id":38519823},{"atb":[[1.58,0]],"id":39236417}],"con":true,"img":false}]}
{"op":"mcm","clk":"5323213479","pt":1646328683247,"mc":[{"id":"1.195532877","rc":[{"atb":[[1.33,0],[1.34,119.8]],"id":38519823}],"con":true,"img":false}]}
{"op":"mcm","clk":"5323213526","pt":1646328683658,"mc":[{"id":"1.195532877","rc":[{"atb":[[1.65,61.54]],"id":43189004},{"atb":[[1.8,0]],"id":42327927},{"atb":[[1.72,55.56]],"id":39236417}],"con":true,"img":false}]}
{"op":"mcm","clk":"5323213576","pt":1646328684140,"mc":[{"id":"1.195532877","rc":[{"atb":[[1.35,2.16]],"id":38519823}],"con":true,"img":false}]}
{"op":"mcm","clk":"5323213590","pt":1646328684245,"mc":[{"id":"1.195532877","rc":[{"atb":[[1.37,1.99]],"id":38519823}],"con":true,"img":false}]}
{"op":"mcm","clk":"5323213611","pt":1646328684450,"mc":[{"id":"1.195532877","rc":[{"atb":[[1.37,4.15]],"id":38519823}],"con":true,"img":false}]}
{"op":"mcm","clk":"5323213621","pt":1646328684560,"mc":[{"id":"1.195532877","rc":[{"atb":[[1.35,0]],"id":38519823}],"con":true,"img":false}]}
{"op":"mcm","clk":"5323213633","pt":1646328684647,"mc":[{"id":"1.195532877","rc":[{"atb":[[1.36,6.88],[1.37,1.99]],"id":38519823}],"con":true,"img":false}]}
{"op":"mcm","clk":"5323213658","pt":1646328684918,"mc":[{"id":"1.195532877","rc":[{"atb":[[1.33,14.7],[1.34,2.15],[1.35,114.29]],"id":38519823}],"con":true,"img":false}]}
{"op":"mcm","clk":"5323213701","pt":1646328685334,"mc":[{"id":"1.195532877","rc":[{"atb":[[1.33,0]],"id":38519823}],"con":true,"img":false}]}
{"op":"mcm","clk":"5323213812","pt":1646328686522,"mc":[{"id":"1.195532877","rc":[{"atb":[[1.86,3.97]],"id":43094641},{"spn":10.18,"spf":"NaN","id":43094641},{"spn":18.99,"spf":"NaN","id":41696085},{"spn":1.67,"spf":1.0,"id":43189004},{"spn":7.9,"spf":"NaN","id":42327927},{"atb":[[1.37,7.8]],"id":38519823},{"spn":1.37,"spf":1.0,"id":38519823},{"spn":6.12,"spf":"NaN","id":39236417}],"con":true,"img":false}]}
{"op":"mcm","clk":"5323213838","pt":1646328686733,"mc":[{"id":"1.195532877","rc":[{"atb":[[1.84,0],[1.87,3.97]],"id":43094641}],"con":true,"img":false}]}
{"op":"mcm","clk":"5323213902","pt":1646328687455,"mc":[{"id":"1.195532877","rc":[{"atb":[[1.85,0]],"id":43094641}],"con":true,"img":false}]}
{"op":"mcm","clk":"5323213910","pt":1646328687549,"mc":[{"id":"1.195532877","rc":[{"atb":[[1.88,1.99]],"id":43094641},{"atb":[[1.63,0],[1.67,4.15]],"id":43189004},{"atb":[[1.74,4.15],[1.7,0]],"id":39236417}],"con":true,"img":false}]}
{"op":"mcm","clk":"5323213956","pt":1646328687926,"mc":[{"id":"1.195532877","rc":[{"atb":[[1.36,3.98]],"id":38519823}],"con":true,"img":false}]}
{"op":"mcm","clk":"5323213969","pt":1646328688027,"mc":[{"id":"1.195532877","rc":[{"atb":[[1.67,7.05]],"id":43189004},{"atb":[[1.74,7.05]],"id":39236417}],"con":true,"img":false}]}
{"op":"mcm","clk":"5323214014","pt":1646328688547,"mc":[{"id":"1.195532877","rc":[{"atb":[[1.83,0],[1.82,6.02],[1.86,50.48]],"id":43094641},{"atl":[[23,6.82]],"id":43094641}],"con":true,"img":false}]}
{"op":"mcm","clk":"5323214048","pt":1646328688960,"mc":[{"id":"1.195532877","rc":[{"atb":[[1.82,0],[1.81,0]],"id":43094641}],"con":true,"img":false}]}
{"op":"mcm","clk":"5323214056","pt":1646328689028,"mc":[{"id":"1.195532877","rc":[{"atb":[[1.89,2.15]],"id":43094641}],"con":true,"img":false}]}
{"op":"mcm","clk":"5323214074","pt":1646328689231,"mc":[{"id":"1.195532877","rc":[{"atb":[[1.89,4.31],[1.87,0]],"id":43094641}],"con":true,"img":false}]}
{"op":"mcm","clk":"5323214127","pt":1646328689752,"mc":[{"id":"1.195532877","rc":[{"atb":[[1.88,0]],"id":43094641}],"con":true,"img":false}]}
{"op":"mcm","clk":"5323214137","pt":1646328689854,"mc":[{"id":"1.195532877","rc":[{"atb":[[1.9,1.99]],"id":43094641},{"atb":[[1.68,3.97]],"id":43189004},{"atb":[[1.77,61.42]],"id":42327927},{"atb":[[1.75,3.97]],"id":39236417}],"con":true,"img":false}]}
{"op":"mcm","clk":"5323214207","pt":1646328690532,"mc":[{"id":"1.195532877","rc":[{"atb":[[1.38,5.46]],"id":38519823}],"con":true,"img":false}]}
{"op":"mcm","clk":"5323214240","pt":1646328690743,"mc":[{"id":"1.195532877","rc":[{"atb":[[1.74,5.06]],"id":39236417}],"con":true,"img":false}]}
{"op":"mcm","clk":"5323214248","pt":1646328690848,"mc":[{"id":"1.195532877","rc":[{"atb":[[1.66,62.76],[1.65,0]],"id":43189004},{"atl":[[11,15]],"id":43189004},{"atb":[[1.77,191.29]],"id":42327927},{"atl":[[17,9.38]],"id":42327927},{"atb":[[1.73,56.94],[1.72,0],[1.76,1.99]],"id":39236417},{"atl":[[13.5,12]],"id":39236417}],"con":true,"img":false}]}
{"op":"mcm","clk":"5323214258","pt":1646328690951,"mc":[{"id":"1.195532877","rc":[{"atb":[[1.88,45.45],[1.86,3.97]],"id":43094641},{"atb":[[1.64,70.19]],"id":43189004},{"atb":[[1.63,71.3]],"id":42327927},{"atb":[[1.36,115.09],[1.35,0]],"id":38519823}],"con":true,"img":false}]}
{"op":"mcm","clk":"5323214268","pt":1646328691053,"mc":[{"id":"1.195532877","rc":[{"atb":[[1.64,62.5],[1.67,5.06]],"id":43189004}],"con":true,"img":false}]}
{"op":"mcm","clk":"5323214280","pt":1646328691154,"mc":[{"id":"1.195532877","rc":[{"atb":[[1.69,1.99]],"id":43189004}],"con":true,"img":false}]}
{"op":"mcm","clk":"5323214292","pt":1646328691263,"mc":[{"id":"1.195532877","rc":[{"atb":[[1.74,59.11]],"id":39236417}],"con":true,"img":false}]}
{"op":"mcm","clk":"5323214306","pt":1646328691358,"mc":[{"id":"1.195532877","rc":[{"atl":[[70,0]],"id":43189004},{"atb":[[1.64,0]],"id":42327927},{"atl":[[70,0]],"id":42327927},{"atb":[[1.73,2.15]],"id":39236417}],"con":true,"img":false}]}
{"op":"mcm","clk":"5323214314","pt":1646328691463,"mc":[{"id":"1.195532877","rc":[{"atb":[[1.63,63.49]],"id":42327927}],"con":true,"img":false}]}
{"op":"mcm","clk":"5323214382","pt":1646328692144,"mc":[{"id":"1.195532877","rc":[{"atb":[[1.86,0]],"id":43094641}],"con":true,"img":false}]}
{"op":"mcm","clk":"5323214456","pt":1646328692927,"mc":[{"id":"1.195532877","rc":[{"atb":[[1.67,2.16]],"id":43189004},{"atb":[[1.74,56.21]],"id":39236417}],"con":true,"img":false}]}
{"op":"mcm","clk":"5323214503","pt":1646328693358,"mc":[{"id":"1.195532877","rc":[{"atb":[[1.36,111.11],[1.39,7.81]],"id":38519823}],"con":true,"img":false}]}
{"op":"mcm","clk":"5323214654","pt":1646328694858,"mc":[{"id":"1.195532877","rc":[{"atb":[[1.68,0]],"id":43189004},{"atb":[[1.37,1.99]],"id":38519823},{"atb":[[1.75,0]],"id":39236417}],"con":true,"img":false}]}
{"op":"mcm","clk":"5323214764","pt":1646328695830,"mc":[{"id":"1.195532877","rc":[{"atb":[[1.67,61.86],[1.66,2.15]],"id":43189004},{"atb":[[1.36,0],[1.37,110.1]],"id":38519823}],"con":true,"img":false}]}
{"op":"mcm","clk":"5323214813","pt":1646328696250,"mc":[{"id":"1.195532877","rc":[{"atb":[[1.67,59.7],[1.69,4.15]],"id":43189004},{"atb":[[1.74,54.05],[1.76,4.15]],"id":39236417}],"con":true,"img":false}]}
{"op":"mcm","clk":"5323214893","pt":1646328696961,"mc":[{"id":"1.195532877","rc":[{"atb":[[1.37,108.11]],"id":38519823}],"con":true,"img":false}]}
{"op":"mcm","clk":"5323214904","pt":1646328697021,"mc":[{"id":"1.195532877","rc":[{"atb":[[1.39,9.8]],"id":38519823}],"con":true,"img":false}]}
{"op":"mcm","clk":"5323214936","pt":1646328697347,"mc":[{"id":"1.195532877","rc":[{"atb":[[1.91,3.97]],"id":43094641}],"con":true,"img":false}]}
{"op":"mcm","clk":"5323214956","pt":1646328697542,"mc":[{"id":"1.195532877","rc":[{"atb":[[1.92,3.97],[1.89,2.15]],"id":43094641}],"con":true,"img":false}]}
{"op":"mcm","clk":"5323215014","pt":1646328698172,"mc":[{"id":"1.195532877","rc":[{"atb":[[1.38,0]],"id":38519823}],"con":true,"img":false}]}
{"op":"mcm","clk":"5323215023","pt":1646328698267,"mc":[{"id":"1.195532877","rc":[{"atb":[[1.9,0]],"id":43094641},{"atb":[[1.68,2.9]],"id":43189004},{"atb":[[1.58,63.08]],"id":39236417}],"con":true,"img":false}]}
{"op":"mcm","clk":"5323215033","pt":1646328698369,"mc":[{"id":"1.195532877","rc":[{"atb":[[1.93,1.99]],"id":43094641}],"con":true,"img":false}]}
{"op":"mcm","clk":"5323215159","pt":1646328699666,"mc":[{"id":"1.195532877","rc":[{"atb":[[1.7,2.15],[1.66,0]],"id":43189004},{"atb":[[1.84,2.15],[1.76,0]],"id":42327927}],"con":true,"img":false}]}
{"op":"mcm","clk":"5323215232","pt":1646328699833,"mc":[{"id":"1.195532877","rc":[{"atb":[[1.84,24.74]],"id":42327927}],"con":true,"img":false}]}
{"op":"mcm","clk":"5323215239","pt":1646328699929,"mc":[{"id":"1.195532877","rc":[{"atb":[[1.81,1.99]],"id":42327927}],"con":true,"img":false}]}
{"op":"mcm","clk":"5323215265","pt":1646328700245,"mc":[{"id":"1.195532877","rc":[{"atb":[[1.81,0]],"id":42327927}],"con":true,"img":false}]}
{"op":"mcm","clk":"5323215273","pt":1646328700340,"mc":[{"id":"1.195532877","rc":[{"atb":[[1.85,1.99]],"id":42327927}],"con":true,"img":false}]}
{"op":"mcm","clk":"5323215307","pt":1646328700663,"mc":[{"id":"1.195532877","rc":[{"atb":[[1.32,14.69]],"id":38519823}],"con":true,"img":false}]}
{"op":"mcm","clk":"5323215315","pt":1646328700761,"mc":[{"id":"1.195532877","rc":[{"atb":[[1.88,0],[1.91,47.93]],"id":43094641},{"atb":[[1.67,0],[1.7,10.46],[1.68,61.72]],"id":43189004},{"atb":[[1.83,48.19],[1.79,0]],"id":42327927},{"atb":[[1.4,19.59]],"id":38519823},{"atb":[[1.77,8.3]],"id":39236417}],"con":true,"img":false}]}
{"op":"mcm","clk":"5323215331","pt":1646328700874,"mc":[{"id":"1.195532877","rc":[{"atb":[[1.71,10.46]],"id":43189004}],"con":true,"img":false}]}
{"op":"mcm","clk":"5323215341","pt":1646328700939,"mc":[{"id":"1.195532877","rc":[{"atb":[[1.69,1.99]],"id":43189004},{"atb":[[1.78,8.31],[1.76,1.99]],"id":39236417}],"con":true,"img":false}]}
{"op":"mcm","clk":"5323215355","pt":1646328701042,"mc":[{"id":"1.195532877","rc":[{"atb":[[1.68,2.9],[1.69,59.96]],"id":43189004},{"atb":[[1.37,0],[1.38,105.26]],"id":38519823},{"atb":[[1.74,0],[1.75,53.33]],"id":39236417}],"con":true,"img":false}]}
{"op":"mcm","clk":"5323215452","pt":1646328701972,"mc":[{"id":"1.195532877","rc":[{"atb":[[1.41,19.59],[1.39,1.99]],"id":38519823}],"con":true,"img":false}]}
{"op":"mcm","clk":"5323215616","pt":1646328703067,"mc":[{"id":"1.195532877","rc":[{"atb":[[1.91,43.96]],"id":43094641},{"atb":[[1.77,129.87]],"id":42327927}],"con":true,"img":false}]}
{"op":"mcm","clk":"5323215628","pt":1646328703172,"mc":[{"id":"1.195532877","rc":[{"atb":[[1.68,0]],"id":43189004},{"atb":[[1.58,0]],"id":39236417}],"con":true,"img":false}]}
{"op":"mcm","clk":"5323215867","pt":1646328705568,"mc":[{"id":"1.195532877","rc":[{"atb":[[1.69,57.97]],"id":43189004}],"con":true,"img":false}]}
{"op":"mcm","clk":"5323215876","pt":1646328705677,"mc":[{"id":"1.195532877","rc":[{"atb":[[1.7,2.15],[1.71,12.45]],"id":43189004},{"atb":[[1.4,0]],"id":38519823},{"atb":[[1.77,0]],"id":39236417}],"con":true,"img":false}]}
{"op":"mcm","clk":"5323215889","pt":1646328705732,"mc":[{"id":"1.195532877","rc":[{"atb":[[1.39,104.55],[1.38,0]],"id":38519823},{"atb":[[1.75,0],[1.76,54.62]],"id":39236417}],"con":true,"img":false}]}
{"op":"mcm","clk":"5323215900","pt":1646328705849,"mc":[{"id":"1.195532877","rc":[{"atb":[[1.32,0]],"id":38519823}],"con":true,"img":false}]}
{"op":"mcm","clk":"5323215918","pt":1646328706046,"mc":[{"id":"1.195532877","rc":[{"atb":[[1.76,109.24]],"id":39236417}],"con":true,"img":false}]}
{"op":"mcm","clk":"5323215928","pt":1646328706159,"mc":[{"id":"1.195532877","rc":[{"atb":[[1.78,0]],"id":39236417}],"con":true,"img":false}]}
{"op":"mcm","clk":"5323215950","pt":1646328706366,"mc":[{"id":"1.195532877","rc":[{"atb":[[1.74,54.05]],"id":39236417}],"con":true,"img":false}]}
{"op":"mcm","clk":"5323215959","pt":1646328706464,"mc":[{"id":"1.195532877","rc":[{"atb":[[1.76,56.61]],"id":39236417}],"con":true,"img":false}]}
{"op":"mcm","clk":"5323216050","pt":1646328707160,"mc":[{"id":"1.195532877","rc":[{"atb":[[1.41,0],[1.39,209.1]],"id":38519823}],"con":true,"img":false}]}
{"op":"mcm","clk":"5323216096","pt":1646328707587,"mc":[{"id":"1.195532877","rc":[{"atb":[[1.37,108.11],[1.39,106.54]],"id":38519823}],"con":true,"img":false}]}
{"op":"mcm","clk":"5323216204","pt":1646328708574,"mc":[{"id":"1.195532877","rc":[{"atb":[[1.94,3.97]],"id":43094641},{"atb":[[1.86,3.97]],"id":42327927}],"con":true,"img":false}]}
{"op":"mcm","clk":"5323216225","pt":1646328708772,"mc":[{"id":"1.195532877","rc":[{"atb":[[1.95,3.97]],"id":43094641},{"atb":[[1.84,2.15],[1.87,3.97]],"id":42327927}],"con":true,"img":false}]}
{"op":"mcm","clk":"5323216235","pt":1646328708877,"mc":[{"id":"1.195532877","rc":[{"atb":[[1.92,0]],"id":43094641},{"atb":[[1.65,17.42]],"id":43189004},{"atb":[[1.68,14.96]],"id":39236417}],"con":true,"img":false}]}
{"op":"mcm","clk":"5323216392","pt":1646328710559,"mc":[{"id":"1.195532877","rc":[{"atb":[[1.74,2.15],[1.7,0]],"id":43189004},{"atb":[[1.42,2.15],[1.34,0]],"id":38519823},{"atb":[[1.73,0],[1.79,2.15]],"id":39236417}],"con":true,"img":false}]}
{"op":"mcm","clk":"5323216414","pt":1646328710759,"mc":[{"id":"1.195532877","rc":[{"atb":[[1.91,0],[1.93,45]],"id":43094641},{"atl":[[25,10.42]],"id":43094641},{"atb":[[1.74,14.6],[1.71,1.99]],"id":43189004},{"atb":[[1.83,0],[1.85,49.05]],"id":42327927},{"atl":[[18,14.71]],"id":42327927}],"con":true,"img":false}]}
{"op":"mcm","clk":"5323216426","pt":1646328710871,"mc":[{"id":"1.195532877","rc":[{"atb":[[1.74,2.15],[1.71,19.42]],"id":43189004}],"con":true,"img":false}]}
{"op":"mcm","clk":"5323216443","pt":1646328711083,"mc":[{"id":"1.195532877","rc":[{"atb":[[1.72,55.56],[1.74,16.76],[1.71,1.99],[1.69,0]],"id":43189004},{"atl":[[12,22.73]],"id":43189004}],"con":true,"img":false}]}
{"op":"mcm","clk":"5323216453","pt":1646328711179,"mc":[{"id":"1.195532877","rc":[{"atl":[[60,0]],"id":42327927},{"atb":[[1.4,100],[1.37,0]],"id":38519823},{"atb":[[1.74,0],[1.77,51.95]],"id":39236417}],"con":true,"img":false}]}
{"op":"mcm","clk":"5323216465","pt":1646328711287,"mc":[{"id":"1.195532877","rc":[{"atb":[[1.32,114.33]],"id":38519823}],"con":true,"img":false}]}
{"op":"mcm","clk":"5323216485","pt":1646328711451,"mc":[{"id":"1.195532877","rc":[{"atl":[[60,0]],"id":43189004}],"con":true,"img":false}]}
{"op":"mcm","clk":"5323216530","pt":1646328711894,"mc":[{"id":"1.195532877","rc":[{"atb":[[1.72,80.46]],"id":43189004},{"atb":[[1.39,104.55],[1.35,135.13]],"id":38519823},{"atb":[[1.77,113.37]],"id":39236417}],"con":true,"img":false}]}
{"op":"mcm","clk":"5323216539","pt":1646328711950,"mc":[{"id":"1.195532877","rc":[{"atb":[[1.42,4.14]],"id":38519823}],"con":true,"img":false}]}
{"op":"mcm","clk":"5323216666","pt":1646328713260,"mc":[{"id":"1.195532877","rc":[{"atb":[[1.76,54.62]],"id":39236417}],"con":true,"img":false}]}
{"op":"mcm","clk":"5323216673","pt":1646328713359,"mc":[{"id":"1.195532877","rc":[{"atb":[[1.8,1.99]],"id":39236417}],"con":true,"img":false}]}
{"op":"mcm","clk":"5323216703","pt":1646328713676,"mc":[{"id":"1.195532877","rc":[{"atb":[[1.85,47.06]],"id":42327927}],"con":true,"img":false}]}
{"op":"mcm","clk":"5323216713","pt":1646328713776,"mc":[{"id":"1.195532877","rc":[{"atb":[[1.88,1.99]],"id":42327927}],"con":true,"img":false}]}
{"op":"mcm","clk":"5323216747","pt":1646328714190,"mc":[{"id":"1.195532877","rc":[{"atb":[[1.71,0]],"id":43189004}],"con":true,"img":false}]}
{"op":"mcm","clk":"5323216761","pt":1646328714294,"mc":[{"id":"1.195532877","rc":[{"atb":[[1.75,1.99]],"id":43189004}],"con":true,"img":false}]}
{"op":"mcm","clk":"5323216772","pt":1646328714400,"mc":[{"id":"1.195532877","rc":[{"atb":[[1.94,0]],"id":43094641},{"atb":[[1.86,0]],"id":42327927}],"con":true,"img":false}]}
{"op":"mcm","clk":"5323216795","pt":1646328714565,"mc":[{"id":"1.195532877","rc":[{"atb":[[1.95,0],[1.93,90]],"id":43094641},{"atb":[[1.8,4.15],[1.76,0]],"id":39236417}],"con":true,"img":false}]}
{"op":"mcm","clk":"5323216861","pt":1646328715087,"mc":[{"id":"1.195532877","rc":[{"atb":[[1.91,43.96],[1.93,46.99]],"id":43094641},{"atb":[[1.73,54.79],[1.72,24.9]],"id":43189004},{"atb":[[1.85,0],[1.86,46.51]],"id":42327927},{"atb":[[1.78,51.28],[1.77,61.42]],"id":39236417}],"con":true,"img":false}]}
{"op":"mcm","clk":"5323216949","pt":1646328715677,"mc":[{"id":"1.195532877","rc":[{"atb":[[1.43,100],[1.39,0]],"id":38519823}],"con":true,"img":false}]}
{"op":"mcm","clk":"5323217003","pt":1646328716059,"mc":[{"id":"1.195532877","rc":[{"atb":[[1.32,0]],"id":38519823},{"atb":[[1.68,0]],"id":39236417}],"con":true,"img":false}]}
{"op":"mcm","clk":"5323217019","pt":1646328716207,"mc":[{"id":"1.195532877","rc":[{"atb":[[1.4,0],[1.41,97.56]],"id":38519823}],"con":true,"img":false}]}
{"op":"mcm","clk":"5323217115","pt":1646328716887,"mc":[{"id":"1.195532877","rc":[{"atb":[[1.72,0]],"id":43189004},{"atb":[[1.35,0]],"id":38519823},{"atb":[[1.77,0]],"id":39236417}],"con":true,"img":false}]}
{"op":"mcm","clk":"5323217144","pt":1646328717096,"mc":[{"id":"1.195532877","rc":[{"atb":[[1.75,3.84]],"id":39236417}],"con":true,"img":false}]}
{"op":"mcm","clk":"5323217209","pt":1646328717682,"mc":[{"id":"1.195532877","rc":[{"atb":[[1.75,0]],"id":39236417}],"con":true,"img":false}]}
{"op":"mcm","clk":"5323217289","pt":1646328718520,"mc":[{"id":"1.195532877","rc":[{"atb":[[1.65,0]],"id":43189004}],"con":true,"img":false}]}
{"op":"mcm","clk":"5323217406","pt":1646328719496,"mc":[{"id":"1.195532877","rc":[{"atb":[[1.93,45]],"id":43094641}],"con":true,"img":false}]}
{"op":"mcm","clk":"5323217416","pt":1646328719553,"mc":[{"id":"1.195532877","rc":[{"atb":[[1.96,1.99]],"id":43094641}],"con":true,"img":false}]}
{"op":"mcm","clk":"5323217427","pt":1646328719670,"mc":[{"id":"1.195532877","rc":[{"atb":[[1.94,50.31]],"id":43094641},{"atb":[[1.89,3.97]],"id":42327927}],"con":true,"img":false}]}
{"op":"mcm","clk":"5323217448","pt":1646328719874,"mc":[{"id":"1.195532877","rc":[{"atb":[[1.9,3.97],[1.87,0]],"id":42327927}],"con":true,"img":false}]}
{"op":"mcm","clk":"5323217460","pt":1646328719977,"mc":[{"id":"1.195532877","rc":[{"atb":[[1.94,92.86]],"id":43094641},{"atb":[[1.86,0],[1.87,45.98]],"id":42327927}],"con":true,"img":false}]}
{"op":"mcm","clk":"5323217471","pt":1646328720081,"mc":[{"id":"1.195532877","rc":[{"atb":[[1.91,0]],"id":43094641}],"con":true,"img":false}]}
{"op":"mcm","clk":"5323217549","pt":1646328720896,"mc":[{"id":"1.195532877","rc":[{"atb":[[1.88,0]],"id":42327927}],"con":true,"img":false}]}
{"op":"mcm","clk":"5323217559","pt":1646328720973,"mc":[{"id":"1.195532877","rc":[{"atb":[[1.91,1.99]],"id":42327927}],"con":true,"img":false}]}
{"op":"mcm","clk":"5323217628","pt":1646328721619,"mc":[{"id":"1.195532877","rc":[{"atb":[[1.44,70]],"id":38519823},{"atb":[[1.68,8.3]],"id":39236417}],"con":true,"img":false}]}
{"op":"mcm","clk":"5323217675","pt":1646328722013,"mc":[{"id":"1.195532877","rc":[{"atb":[[1.89,48.91],[1.87,0]],"id":42327927},{"atb":[[1.41,0],[1.42,97.23],[1.47,2.15]],"id":38519823}],"con":true,"img":false}]}
{"op":"mcm","clk":"5323217700","pt":1646328722223,"mc":[{"id":"1.195532877","rc":[{"atb":[[1.45,88.89],[1.42,1.99]],"id":38519823}],"con":true,"img":false}]}
{"op":"mcm","clk":"5323217804","pt":1646328723013,"mc":[{"id":"1.195532877","rc":[{"atb":[[1.96,46.99],[1.93,0]],"id":43094641}],"con":true,"img":false}]}
{"op":"mcm","clk":"5323217817","pt":1646328723118,"mc":[{"id":"1.195532877","rc":[{"atb":[[1.96,1.99],[1.95,45]],"id":43094641},{"atb":[[1.76,3.97]],"id":43189004},{"atb":[[1.44,177.49]],"id":38519823},{"atb":[[1.81,8.3]],"id":39236417}],"con":true,"img":false}]}
{"op":"mcm","clk":"5323217842","pt":1646328723291,"mc":[{"id":"1.195532877","rc":[{"atb":[[1.74,2.15],[1.77,3.97]],"id":43189004},{"atb":[[1.8,1.99],[1.82,4.15]],"id":39236417}],"con":true,"img":false}]}
{"op":"mcm","clk":"5323217925","pt":1646328724016,"mc":[{"id":"1.195532877","rc":[{"atb":[[1.65,31.87]],"id":43189004}],"con":true,"img":false}]}
{"op":"mcm","clk":"5323217941","pt":1646328724121,"mc":[{"id":"1.195532877","rc":[{"atb":[[1.43,0],[1.47,91.04]],"id":38519823}],"con":true,"img":false}]}
{"op":"mcm","clk":"5323217954","pt":1646328724183,"mc":[{"id":"1.195532877","rc":[{"atb":[[1.45,188.89]],"id":38519823}],"con":true,"img":false}]}
{"op":"mcm","clk":"5323217967","pt":1646328724293,"mc":[{"id":"1.195532877","rc":[{"atb":[[1.47,2.15]],"id":38519823}],"con":true,"img":false}]}
{"op":"mcm","clk":"5323217981","pt":1646328724394,"mc":[{"id":"1.195532877","rc":[{"atb":[[1.47,179.65]],"id":38519823}],"con":true,"img":false}]}
{"op":"mcm","clk":"5323218020","pt":1646328724708,"mc":[{"id":"1.195532877","rc":[{"atb":[[1.45,88.89]],"id":38519823}],"con":true,"img":false}]}
{"op":"mcm","clk":"5323218071","pt":1646328725116,"mc":[{"id":"1.195532877","rc":[{"atb":[[1.73,0],[1.75,55.32]],"id":43189004},{"atb":[[1.8,51.99],[1.78,0]],"id":39236417},{"atl":[[14.5,18.52]],"id":39236417}],"con":true,"img":false}]}
{"op":"mcm","clk":"5323218113","pt":1646328725539,"mc":[{"id":"1.195532877","rc":[{"atb":[[1.94,42.55]],"id":43094641},{"atb":[[1.89,44.94]],"id":42327927}],"con":true,"img":false}]}
{"op":"mcm","clk":"5323218206","pt":1646328726321,"mc":[{"id":"1.195532877","rc":[{"atb":[[1.42,0]],"id":38519823}],"con":true,"img":false}]}
{"op":"mcm","clk":"5323218217","pt":1646328726389,"mc":[{"id":"1.195532877","rc":[{"atb":[[1.44,179.48]],"id":38519823}],"con":true,"img":false}]}
{"op":"mcm","clk":"5323218230","pt":1646328726492,"mc":[{"id":"1.195532877","rc":[{"atb":[[1.44,109.48]],"id":38519823},{"atb":[[1.68,0]],"id":39236417}],"con":true,"img":false}]}
{"op":"mcm","clk":"5323218252","pt":1646328726740,"mc":[{"id":"1.195532877","rc":[{"atb":[[1.96,0]],"id":43094641}],"con":true,"img":false}]}
{"op":"mcm","clk":"5323218274","pt":1646328726907,"mc":[{"id":"1.195532877","rc":[{"atb":[[1.9,87.55],[1.95,46.99]],"id":43094641}],"con":true,"img":false}]}
{"op":"mcm","clk":"5323218286","pt":1646328727008,"mc":[{"id":"1.195532877","rc":[{"atb":[[1.95,1.99]],"id":43094641}],"con":true,"img":false}]}
{"op":"mcm","clk":"5323218407","pt":1646328728001,"mc":[{"id":"1.195532877","rc":[{"atb":[[1.94,0],[1.93,48.33]],"id":43094641}],"con":true,"img":false}]}
{"op":"mcm","clk":"5323218420","pt":1646328728107,"mc":[{"id":"1.195532877","rc":[{"atb":[[1.76,0]],"id":43189004},{"atb":[[1.44,1.99]],"id":38519823},{"atb":[[1.8,50],[1.81,0]],"id":39236417}],"con":true,"img":false}]}
{"op":"mcm","clk":"5323218433","pt":1646328728211,"mc":[{"id":"1.195532877","rc":[{"atb":[[1.93,43.01]],"id":43094641},{"atb":[[1.83,1.99]],"id":39236417}],"con":true,"img":false}]}
{"op":"mcm","clk":"5323218446","pt":1646328728317,"mc":[{"id":"1.195532877","rc":[{"atb":[[1.77,0],[1.75,87.2]],"id":43189004},{"atb":[[1.82,0],[1.8,100]],"id":39236417}],"con":true,"img":false}]}
{"op":"mcm","clk":"5323218470","pt":1646328728494,"mc":[{"id":"1.195532877","rc":[{"atb":[[1.44,0]],"id":38519823}],"con":true,"img":false}]}
{"op":"mcm","clk":"5323218482","pt":1646328728592,"mc":[{"id":"1.195532877","rc":[{"atb":[[1.48,1.99]],"id":38519823}],"con":true,"img":false}]}
{"op":"mcm","clk":"5323218501","pt":1646328728803,"mc":[{"id":"1.195532877","rc":[{"atb":[[1.65,0]],"id":43189004}],"con":true,"img":false}]}
{"op":"mcm","clk":"5323218522","pt":1646328729005,"mc":[{"id":"1.195532877","rc":[{"atb":[[1.75,85.21]],"id":43189004}],"con":true,"img":false}]}
{"op":"mcm","clk":"5323218534","pt":1646328729113,"mc":[{"id":"1.195532877","rc":[{"atb":[[1.78,1.99]],"id":43189004}],"con":true,"img":false}]}
{"op":"mcm","clk":"5323218727","pt":1646328730632,"mc":[{"id":"1.195532877","rc":[{"atb":[[1.75,93.72]],"id":43189004}],"con":true,"img":false}]}
{"op":"mcm","clk":"5323218740","pt":1646328730694,"mc":[{"id":"1.195532877","rc":[{"atb":[[1.63,8.51]],"id":43189004}],"con":true,"img":false}]}
{"op":"mcm","clk":"5323218756","pt":1646328730809,"mc":[{"id":"1.195532877","rc":[{"atb":[[1.75,31.88],[1.76,52.63]],"id":43189004},{"atb":[[1.46,86.96],[1.44,11.11],[1.45,0]],"id":38519823},{"atb":[[1.8,50],[1.81,49.38]],"id":39236417}],"con":true,"img":false}]}
{"op":"mcm","clk":"5323218777","pt":1646328731067,"mc":[{"id":"1.195532877","rc":[{"atb":[[1.44,0]],"id":38519823}],"con":true,"img":false}]}
{"op":"mcm","clk":"5323218806","pt":1646328731220,"mc":[{"id":"1.195532877","rc":[{"atb":[[1.63,0]],"id":43189004}],"con":true,"img":false}]}
{"op":"mcm","clk":"5323218815","pt":1646328731325,"mc":[{"id":"1.195532877","rc":[{"atb":[[1.91,6.45]],"id":43094641},{"atb":[[1.92,3.97]],"id":42327927}],"con":true,"img":false}]}
{"op":"mcm","clk":"5323218834","pt":1646328731490,"mc":[{"id":"1.195532877","rc":[{"atb":[[1.9,0],[1.93,3.97]],"id":42327927}],"con":true,"img":false}]}
{"op":"mcm","clk":"5323218867","pt":1646328731801,"mc":[{"id":"1.195532877","rc":[{"atb":[[1.32,114.33]],"id":38519823},{"atb":[[1.58,63.08]],"id":39236417}],"con":true,"img":false}]}
{"op":"mcm","clk":"5323218888","pt":1646328732000,"mc":[{"id":"1.195532877","rc":[{"atb":[[1.89,0],[1.88,5.62],[1.91,45.95]],"id":42327927}],"con":true,"img":false}]}
{"op":"mcm","clk":"5323218901","pt":1646328732102,"mc":[{"id":"1.195532877","rc":[{"atb":[[1.88,0]],"id":42327927}],"con":true,"img":false}]}
{"op":"mcm","clk":"5323219182","pt":1646328734405,"mc":[{"id":"1.195532877","rc":[{"atb":[[1.65,56.28]],"id":43189004}],"con":true,"img":false}]}
{"op":"mcm","clk":"5323219213","pt":1646328734718,"mc":[{"id":"1.195532877","rc":[{"atb":[[1.79,3.97]],"id":43189004},{"atb":[[1.49,3.97]],"id":38519823},{"atb":[[1.84,3.97]],"id":39236417}],"con":true,"img":false}]}
{"op":"mcm","clk":"5323219238","pt":1646328734925,"mc":[{"id":"1.195532877","rc":[{"atb":[[1.5,3.97],[1.47,2.15]],"id":38519823}],"con":true,"img":false}]}
{"op":"mcm","clk":"5323219274","pt":1646328735202,"mc":[{"id":"1.195532877","rc":[{"atb":[[1.95,8.44]],"id":43094641}],"con":true,"img":false}]}
{"op":"mcm","clk":"5323219285","pt":1646328735304,"mc":[{"id":"1.195532877","rc":[{"atb":[[1.9,0]],"id":43094641}],"con":true,"img":false}]}
{"op":"mcm","clk":"5323219424","pt":1646328736510,"mc":[{"id":"1.195532877","rc":[{"atb":[[1.8,3.97],[1.75,0]],"id":43189004},{"atb":[[1.85,3.97]],"id":39236417}],"con":true,"img":false}]}
{"op":"mcm","clk":"5323219437","pt":1646328736602,"mc":[{"id":"1.195532877","rc":[{"atb":[[1.8,0]],"id":39236417}],"con":true,"img":false}]}
{"op":"mcm","clk":"5323219458","pt":1646328736805,"mc":[{"id":"1.195532877","rc":[{"atb":[[1.58,0]],"id":39236417}],"con":true,"img":false}]}
{"op":"mcm","clk":"5323219472","pt":1646328736908,"mc":[{"id":"1.195532877","rc":[{"atb":[[1.92,0]],"id":42327927}],"con":true,"img":false}]}
{"op":"mcm","clk":"5323219484","pt":1646328737013,"mc":[{"id":"1.195532877","rc":[{"atb":[[1.91,91.9],[1.93,0]],"id":42327927}],"con":true,"img":false}]}
{"op":"mcm","clk":"5323219594","pt":1646328738005,"mc":[{"id":"1.195532877","rc":[{"atb":[[1.91,116.34]],"id":43094641}],"con":true,"img":false}]}
{"op":"mcm","clk":"5323219741","pt":1646328739313,"mc":[{"id":"1.195532877","rc":[{"atb":[[1.65,0]],"id":43189004},{"atb":[[1.32,0]],"id":38519823}],"con":true,"img":false}]}
{"op":"mcm","clk":"5323219767","pt":1646328739521,"mc":[{"id":"1.195532877","rc":[{"atb":[[1.8,0],[1.72,0],[1.78,0]],"id":43094641},{"atb":[[1.78,53.27],[1.76,0]],"id":43189004},{"atb":[[1.89,44.94],[1.91,47.94]],"id":42327927},{"atb":[[1.46,0],[1.48,85.32]],"id":38519823},{"atb":[[1.83,50.18],[1.81,0]],"id":39236417}],"con":true,"img":false}]}
{"op":"mcm","clk":"5323219780","pt":1646328739614,"mc":[{"id":"1.195532877","rc":[{"atb":[[1.79,0]],"id":43189004},{"atb":[[1.9,11.91]],"id":42327927},{"atb":[[1.49,0]],"id":38519823},{"atb":[[1.84,0]],"id":39236417}],"con":true,"img":false}]}
{"op":"mcm","clk":"5323219813","pt":1646328739930,"mc":[{"id":"1.195532877","rc":[{"atb":[[1.84,0],[1.94,2.15]],"id":42327927}],"con":true,"img":false}]}
{"op":"mcm","clk":"5323219826","pt":1646328740032,"mc":[{"id":"1.195532877","rc":[{"atb":[[1.48,170.64]],"id":38519823},{"atb":[[1.83,48.19]],"id":39236417}],"con":true,"img":false}]}
{"op":"mcm","clk":"5323219837","pt":1646328740137,"mc":[{"id":"1.195532877","rc":[{"atb":[[1.5,0]],"id":38519823},{"atb":[[1.81,1.99]],"id":39236417}],"con":true,"img":false}]}
{"op":"mcm","clk":"5323219850","pt":1646328740210,"mc":[{"id":"1.195532877","rc":[{"atb":[[1.92,43.48],[1.89,0]],"id":42327927}],"con":true,"img":false}]}
{"op":"mcm","clk":"5323219863","pt":1646328740305,"mc":[{"id":"1.195532877","rc":[{"atb":[[1.78,51.28]],"id":43189004},{"atb":[[1.9,0]],"id":42327927}],"con":true,"img":false}]}
{"op":"mcm","clk":"5323219877","pt":1646328740419,"mc":[{"id":"1.195532877","rc":[{"atb":[[1.76,1.99]],"id":43189004}],"con":true,"img":false}]}
{"op":"mcm","clk":"5323219887","pt":1646328740528,"mc":[{"id":"1.195532877","rc":[{"atb":[[1.46,86.96],[1.48,87.31]],"id":38519823}],"con":true,"img":false}]}
{"op":"mcm","clk":"5323219896","pt":1646328740612,"mc":[{"id":"1.195532877","rc":[{"atb":[[1.95,6.45]],"id":43094641}],"con":true,"img":false}]}
{"op":"mcm","clk":"5323219911","pt":1646328740722,"mc":[{"id":"1.195532877","rc":[{"atb":[[1.92,108.7],[1.94,1.99]],"id":43094641}],"con":true,"img":false}]}
{"op":"mcm","clk":"5323219922","pt":1646328740826,"mc":[{"id":"1.195532877","rc":[{"atb":[[1.95,0]],"id":43094641}],"con":true,"img":false}]}
{"op":"mcm","clk":"5323219946","pt":1646328741037,"mc":[{"id":"1.195532877","rc":[{"atb":[[1.94,10.94]],"id":43094641}],"con":true,"img":false}]}
{"op":"mcm","clk":"5323220020","pt":1646328741720,"mc":[{"id":"1.195532877","rc":[{"atb":[[1.8,0],[1.77,55.25]],"id":43189004},{"atb":[[1.82,52.16],[1.81,0],[1.85,0]],"id":39236417}],"con":true,"img":false}]}
{"op":"mcm","clk":"5323220032","pt":1646328741820,"mc":[{"id":"1.195532877","rc":[{"atb":[[1.86,1.99]],"id":39236417}],"con":true,"img":false}]}
{"op":"mcm","clk":"5323220043","pt":1646328741927,"mc":[{"id":"1.195532877","rc":[{"atb":[[1.82,56.52]],"id":39236417}],"con":true,"img":false}]}
{"op":"mcm","clk":"5323220052","pt":1646328742033,"mc":[{"id":"1.195532877","rc":[{"atb":[[1.91,45.95]],"id":42327927}],"con":true,"img":false}]}
{"op":"mcm","clk":"5323220064","pt":1646328742137,"mc":[{"id":"1.195532877","rc":[{"atb":[[1.85,55.64],[1.95,1.99]],"id":42327927}],"con":true,"img":false}]}
{"op":"mcm","clk":"5323220092","pt":1646328742308,"mc":[{"id":"1.195532877","rc":[{"atb":[[1.76,0]],"id":43189004}],"con":true,"img":false}]}
{"op":"mcm","clk":"5323220104","pt":1646328742452,"mc":[{"id":"1.195532877","rc":[{"atb":[[1.81,1.99]],"id":43189004}],"con":true,"img":false}]}
{"op":"mcm","clk":"5323220157","pt":1646328742922,"mc":[{"id":"1.195532877","rc":[{"atb":[[1.94,1.99]],"id":43094641}],"con":true,"img":false}]}
{"op":"mcm","clk":"5323220283","pt":1646328744026,"mc":[{"id":"1.195532877","rc":[{"atb":[[1.86,0]],"id":39236417}],"con":true,"img":false}]}
{"op":"mcm","clk":"5323220301","pt":1646328744128,"mc":[{"id":"1.195532877","rc":[{"atb":[[1.84,1.99]],"id":39236417}],"con":true,"img":false}]}
{"op":"mcm","clk":"5323220341","pt":1646328744445,"mc":[{"id":"1.195532877","rc":[{"atb":[[1.81,0]],"id":43189004}],"con":true,"img":false}]}
{"op":"mcm","clk":"5323220357","pt":1646328744511,"mc":[{"id":"1.195532877","rc":[{"atb":[[1.79,1.99]],"id":43189004}],"con":true,"img":false}]}
{"op":"mcm","clk":"5323220420","pt":1646328745106,"mc":[{"id":"1.195532877","rc":[{"atb":[[1.75,48.78]],"id":43189004},{"atb":[[1.32,114.33]],"id":38519823}],"con":true,"img":false}]}
{"op":"mcm","clk":"5323220446","pt":1646328745315,"mc":[{"id":"1.195532877","rc":[{"atb":[[1.91,0],[1.95,4.15]],"id":42327927}],"con":true,"img":false}]}
{"op":"mcm","clk":"5323220460","pt":1646328745694,"mc":[{"id":"1.195532877","rc":[{"atb":[[1.92,152.18],[1.93,0]],"id":43094641},{"atb":[[1.78,0],[1.77,107.2]],"id":43189004},{"atb":[[1.92,0],[1.93,43.01]],"id":42327927},{"atb":[[1.83,0],[1.82,105.3]],"id":39236417}],"con":true,"img":false}]}
{"op":"mcm","clk":"5323220505","pt":1646328746093,"mc":[{"id":"1.195532877","rc":[{"atb":[[1.91,109.89]],"id":43094641},{"atb":[[1.79,61.86]],"id":43189004},{"atb":[[1.49,96.52]],"id":38519823},{"atb":[[1.87,3.97]],"id":39236417}],"con":true,"img":false}]}
{"op":"mcm","clk":"5323220600","pt":1646328746637,"mc":[{"id":"1.195532877","rc":[{"spn":10.22,"spf":"NaN","id":43094641},{"spn":1.79,"spf":1.0,"id":43189004},{"spn":7.97,"spf":"NaN","id":42327927},{"spn":1.49,"spf":1.0,"id":38519823},{"atb":[[1.84,0]],"id":39236417},{"spn":6.18,"spf":"NaN","id":39236417}],"con":true,"img":false}]}
{"op":"mcm","clk":"5323220613","pt":1646328746740,"mc":[{"id":"1.195532877","rc":[{"atb":[[1.46,0],[1.47,87.26]],"id":38519823},{"atb":[[1.82,56.52],[1.83,1.99],[1.85,47.06]],"id":39236417}],"con":true,"img":false}]}
{"op":"mcm","clk":"5323220639","pt":1646328746953,"mc":[{"id":"1.195532877","rc":[{"atb":[[1.79,59.87]],"id":43189004}],"con":true,"img":false}]}
{"op":"mcm","clk":"5323220649","pt":1646328747014,"mc":[{"id":"1.195532877","rc":[{"atb":[[1.78,1.99]],"id":43189004}],"con":true,"img":false}]}
{"op":"mcm","clk":"5323220669","pt":1646328747222,"mc":[{"id":"1.195532877","rc":[{"atb":[[1.94,0]],"id":43094641}],"con":true,"img":false}]}
{"op":"mcm","clk":"5323220684","pt":1646328747326,"mc":[{"id":"1.195532877","rc":[{"atb":[[1.93,1.99]],"id":43094641}],"con":true,"img":false}]}
{"op":"mcm","clk":"5323220696","pt":1646328747433,"mc":[{"id":"1.195532877","rc":[{"atb":[[1.92,43.48],[1.9,111.11]],"id":43094641}],"con":true,"img":false}]}
{"op":"mcm","clk":"5323220730","pt":1646328747743,"mc":[{"id":"1.195532877","rc":[{"atb":[[1.82,52.16]],"id":39236417}],"con":true,"img":false}]}
{"op":"mcm","clk":"5323220740","pt":1646328747850,"mc":[{"id":"1.195532877","rc":[{"atb":[[1.85,0]],"id":42327927}],"con":true,"img":false}]}
{"op":"mcm","clk":"5323220767","pt":1646328748014,"mc":[{"id":"1.195532877","rc":[{"atb":[[1.92,0],[1.91,43.96]],"id":43094641}],"con":true,"img":false}]}
{"op":"mcm","clk":"5323220796","pt":1646328748227,"mc":[{"id":"1.195532877","rc":[{"atb":[[1.5,87.31],[1.48,1.99]],"id":38519823},{"atb":[[1.83,0]],"id":39236417}],"con":true,"img":false}]}
{"op":"mcm","clk":"5323220808","pt":1646328748328,"mc":[{"id":"1.195532877","rc":[{"atb":[[1.88,1.99]],"id":39236417}],"con":true,"img":false}]}
{"op":"mcm","clk":"5323220854","pt":1646328748643,"mc":[{"id":"1.195532877","rc":[{"atb":[[1.48,0]],"id":38519823}],"con":true,"img":false}]}
{"op":"mcm","clk":"5323220870","pt":1646328748743,"mc":[{"id":"1.195532877","rc":[{"atb":[[1.5,89.3],[1.48,83.33],[1.47,2.15]],"id":38519823},{"atb":[[1.85,0],[1.86,46.51]],"id":39236417}],"con":true,"img":false}]}
{"op":"mcm","clk":"5323220881","pt":1646328748854,"mc":[{"id":"1.195532877","rc":[{"atb":[[1.93,45.95]],"id":43094641}],"con":true,"img":false}]}
{"op":"mcm","clk":"5323220895","pt":1646328748917,"mc":[{"id":"1.195532877","rc":[{"atb":[[1.9,0]],"id":43094641},{"atb":[[1.78,0]],"id":43189004}],"con":true,"img":false}]}
{"op":"mcm","clk":"5323220911","pt":1646328749016,"mc":[{"id":"1.195532877","rc":[{"atb":[[1.8,1.99]],"id":43189004}],"con":true,"img":false}]}
{"op":"mcm","clk":"5323220998","pt":1646328749853,"mc":[{"id":"1.195532877","rc":[{"atb":[[1.8,61.87],[1.77,51.95]],"id":43189004},{"atb":[[1.82,0]],"id":39236417}],"con":true,"img":false}]}
{"op":"mcm","clk":"5323221009","pt":1646328749909,"mc":[{"id":"1.195532877","rc":[{"atb":[[1.88,5.96]],"id":39236417}],"con":true,"img":false}]}
{"op":"mcm","clk":"5323221046","pt":1646328750226,"mc":[{"id":"1.195532877","rc":[{"atb":[[1.75,0]],"id":43189004},{"atb":[[1.32,0]],"id":38519823}],"con":true,"img":false}]}
{"op":"mcm","clk":"5323221086","pt":1646328750538,"mc":[{"id":"1.195532877","rc":[{"atb":[[1.74,0]],"id":43189004},{"atb":[[1.47,0]],"id":38519823}],"con":true,"img":false}]}
{"op":"mcm","clk":"5323221099","pt":1646328750635,"mc":[{"id":"1.195532877","rc":[{"atb":[[1.78,51.28],[1.77,0]],"id":43189004}],"con":true,"img":false}]}
{"op":"mcm","clk":"5323221111","pt":1646328750740,"mc":[{"id":"1.195532877","rc":[{"atb":[[1.94,3.97]],"id":43094641},{"atb":[[1.83,2.15]],"id":43189004},{"atb":[[1.53,2.15]],"id":38519823}],"con":true,"img":false}]}
{"op":"mcm","clk":"5323221131","pt":1646328750845,"mc":[{"id":"1.195532877","rc":[{"atb":[[1.95,43.96]],"id":43094641}],"con":true,"img":false}]}
{"op":"mcm","clk":"5323221150","pt":1646328750948,"mc":[{"id":"1.195532877","rc":[{"atb":[[1.93,1.99]],"id":43094641},{"atb":[[1.83,62.03],[1.8,1.99]],"id":43189004}],"con":true,"img":false}]}
{"op":"mcm","clk":"5323221164","pt":1646328751053,"mc":[{"id":"1.195532877","rc":[{"atb":[[1.93,45]],"id":43094641},{"atb":[[1.83,2.15],[1.8,61.87],[1.81,49.38],[1.78,0]],"id":43189004},{"atb":[[1.51,78.43],[1.48,0]],"id":38519823}],"con":true,"img":false}]}
{"op":"mcm","clk":"5323221191","pt":1646328751218,"mc":[{"id":"1.195532877","rc":[{"atb":[[1.83,62.03],[1.8,1.99]],"id":43189004}],"con":true,"img":false}]}
{"op":"mcm","clk":"5323221201","pt":1646328751321,"mc":[{"id":"1.195532877","rc":[{"atb":[[1.5,87.31]],"id":38519823}],"con":true,"img":false}]}
{"op":"mcm","clk":"5323221214","pt":1646328751427,"mc":[{"id":"1.195532877","rc":[{"atb":[[1.54,1.99]],"id":38519823}],"con":true,"img":false}]}
{"op":"mcm","clk":"5323221260","pt":1646328751738,"mc":[{"id":"1.195532877","rc":[{"atb":[[1.8,0]],"id":43189004}],"con":true,"img":false}]}
{"op":"mcm","clk":"5323221272","pt":1646328751845,"mc":[{"id":"1.195532877","rc":[{"atb":[[1.84,1.99]],"id":43189004}],"con":true,"img":false}]}
{"op":"mcm","clk":"5323221312","pt":1646328752111,"mc":[{"id":"1.195532877","rc":[{"atb":[[1.93,43.01]],"id":43094641}],"con":true,"img":false}]}
{"op":"mcm","clk":"5323221326","pt":1646328752218,"mc":[{"id":"1.195532877","rc":[{"atb":[[1.96,1.99]],"id":43094641}],"con":true,"img":false}]}
{"op":"mcm","clk":"5323221400","pt":1646328752841,"mc":[{"id":"1.195532877","rc":[{"atb":[[1.89,4.17]],"id":39236417}],"con":true,"img":false}]}
{"op":"mcm","clk":"5323221427","pt":1646328753053,"mc":[{"id":"1.195532877","rc":[{"atb":[[1.88,1.99],[1.9,4.18]],"id":39236417}],"con":true,"img":false}]}
{"op":"mcm","clk":"5323221497","pt":1646328753638,"mc":[{"id":"1.195532877","rc":[{"atb":[[1.79,0]],"id":43189004},{"atb":[[1.96,8.3]],"id":42327927},{"atb":[[1.49,0]],"id":38519823},{"atb":[[1.87,0]],"id":39236417}],"con":true,"img":false}]}
{"op":"mcm","clk":"5323221521","pt":1646328753841,"mc":[{"id":"1.195532877","rc":[{"atb":[[1.97,4.15],[1.95,1.99]],"id":42327927},{"atb":[[1.88,0]],"id":39236417}],"con":true,"img":false}]}
{"op":"mcm","clk":"5323221535","pt":1646328753944,"mc":[{"id":"1.195532877","rc":[{"atb":[[1.91,1.99]],"id":39236417}],"con":true,"img":false}]}
{"op":"mcm","clk":"5323221682","pt":1646328755152,"mc":[{"id":"1.195532877","rc":[{"atb":[[1.95,0]],"id":42327927}],"con":true,"img":false}]}
{"op":"mcm","clk":"5323221695","pt":1646328755258,"mc":[{"id":"1.195532877","rc":[{"atb":[[1.98,1.99]],"id":42327927}],"con":true,"img":false}]}
{"op":"mcm","clk":"5323221709","pt":1646328755321,"mc":[{"id":"1.195532877","rc":[{"atb":[[1.93,0],[1.95,42.11]],"id":42327927}],"con":true,"img":false}]}
{"op":"mcm","clk":"5323221743","pt":1646328755629,"mc":[{"id":"1.195532877","rc":[{"atb":[[1.94,46.52]],"id":43094641},{"atb":[[1.82,48.78],[1.81,0]],"id":43189004},{"atb":[[1.96,49.97],[1.95,0]],"id":42327927},{"atb":[[1.51,0],[1.52,76.92]],"id":38519823},{"atb":[[1.89,49.11],[1.85,5.82],[1.86,0]],"id":39236417}],"con":true,"img":false}]}
{"op":"mcm","clk":"5323221764","pt":1646328755838,"mc":[{"id":"1.195532877","rc":[{"atb":[[1.85,0]],"id":39236417}],"con":true,"img":false}]}
{"op":"mcm","clk":"5323221776","pt":1646328755936,"mc":[{"id":"1.195532877","rc":[{"atb":[[1.94,42.55]],"id":43094641},{"atb":[[1.84,45.54]],"id":43189004},{"atb":[[1.54,4.89]],"id":38519823}],"con":true,"img":false}]}
{"op":"mcm","clk":"5323221826","pt":1646328756350,"mc":[{"id":"1.195532877","rc":[{"atb":[[1.55,4.89],[1.5,0]],"id":38519823}],"con":true,"img":false}]}
{"op":"mcm","clk":"5323221982","pt":1646328757617,"mc":[{"id":"1.195532877","rc":[{"atb":[[1.54,2.9]],"id":38519823}],"con":true,"img":false}]}
{"op":"mcm","clk":"5323221996","pt":1646328757724,"mc":[{"id":"1.195532877","rc":[{"atb":[[1.56,1.99]],"id":38519823}],"con":true,"img":false}]}
{"op":"mcm","clk":"5323222058","pt":1646328758249,"mc":[{"id":"1.195532877","rc":[{"atb":[[1.89,44.94]],"id":39236417}],"con":true,"img":false}]}
{"op":"mcm","clk":"5323222178","pt":1646328759253,"mc":[{"id":"1.195532877","rc":[{"atb":[[1.83,2.15],[1.85,48.78]],"id":43189004}],"con":true,"img":false}]}
{"op":"mcm","clk":"5323222226","pt":1646328759618,"mc":[{"id":"1.195532877","rc":[{"atb":[[1.85,52.75]],"id":43189004},{"atb":[[1.96,41.67]],"id":42327927},{"atb":[[1.55,8.86]],"id":38519823},{"atb":[[1.92,3.97]],"id":39236417}],"con":true,"img":false}]}
{"op":"mcm","clk":"5323222319","pt":1646328760554,"mc":[{"id":"1.195532877","rc":[{"atb":[[1.54,0]],"id":38519823}],"con":true,"img":false}]}
{"op":"mcm","clk":"5323222345","pt":1646328760719,"mc":[{"id":"1.195532877","rc":[{"atb":[[1.91,0]],"id":39236417}],"con":true,"img":false}]}
{"op":"mcm","clk":"5323222353","pt":1646328760818,"mc":[{"id":"1.195532877","rc":[{"atb":[[1.93,1.99]],"id":39236417}],"con":true,"img":false}]}
{"op":"mcm","clk":"5323222362","pt":1646328760924,"mc":[{"id":"1.195532877","rc":[{"atb":[[1.83,50.34],[1.82,0]],"id":43189004},{"atb":[[1.54,74.07],[1.52,0]],"id":38519823},{"atb":[[1.89,0],[1.9,48.62]],"id":39236417}],"con":true,"img":false}]}
{"op":"mcm","clk":"5323222372","pt":1646328761028,"mc":[{"id":"1.195532877","rc":[{"atb":[[1.93,5.96]],"id":39236417}],"con":true,"img":false}]}
{"op":"mcm","clk":"5323222384","pt":1646328761135,"mc":[{"id":"1.195532877","rc":[{"atb":[[1.89,0],[1.98,2.15]],"id":43094641},{"atb":[[1.83,48.19],[1.84,43.55],[1.88,2.15]],"id":43189004},{"atb":[[1.9,0],[1.91,43.96]],"id":39236417}],"con":true,"img":false}]}
{"op":"mcm","clk":"5323222394","pt":1646328761236,"mc":[{"id":"1.195532877","rc":[{"atb":[[1.86,1.99]],"id":43189004}],"con":true,"img":false}]}
{"op":"mcm","clk":"5323222404","pt":1646328761341,"mc":[{"id":"1.195532877","rc":[{"atb":[[1.98,4.31],[1.95,0]],"id":43094641}],"con":true,"img":false}]}
{"op":"mcm","clk":"5323222466","pt":1646328761958,"mc":[{"id":"1.195532877","rc":[{"atb":[[1.97,3.97]],"id":43094641}],"con":true,"img":false}]}
{"op":"mcm","clk":"5323222577","pt":1646328762952,"mc":[{"id":"1.195532877","rc":[{"atb":[[1.86,0]],"id":43189004}],"con":true,"img":false}]}
{"op":"mcm","clk":"5323222589","pt":1646328763011,"mc":[{"id":"1.195532877","rc":[{"atb":[[1.89,1.99]],"id":43189004}],"con":true,"img":false}]}
{"op":"mcm","clk":"5323222609","pt":1646328763221,"mc":[{"id":"1.195532877","rc":[{"atb":[[1.96,0]],"id":43094641}],"con":true,"img":false}]}
{"op":"mcm","clk":"5323222620","pt":1646328763323,"mc":[{"id":"1.195532877","rc":[{"atb":[[1.99,1.99]],"id":43094641},{"atb":[[1.84,0]],"id":43189004}],"con":true,"img":false}]}
{"op":"mcm","clk":"5323222631","pt":1646328763434,"mc":[{"id":"1.195532877","rc":[{"atb":[[1.93,8.74]],"id":39236417}],"con":true,"img":false}]}
{"op":"mcm","clk":"5323222818","pt":1646328765223,"mc":[{"id":"1.195532877","rc":[{"atb":[[1.85,48.78]],"id":43189004},{"atb":[[1.99,3.97]],"id":42327927},{"atb":[[1.55,4.89]],"id":38519823},{"atb":[[1.92,0]],"id":39236417}],"con":true,"img":false}]}
{"op":"mcm","clk":"5323222841","pt":1646328765431,"mc":[{"id":"1.195532877","rc":[{"atb":[[2,3.97],[1.97,0]],"id":42327927}],"con":true,"img":false}]}
{"op":"mcm","clk":"5323222865","pt":1646328765643,"mc":[{"id":"1.195532877","rc":[{"atb":[[1.97,45.21],[1.9,7.66]],"id":43094641},{"atb":[[1.98,42.81],[1.96,0]],"id":42327927}],"con":true,"img":false}]}
{"op":"mcm","clk":"5323222876","pt":1646328765744,"mc":[{"id":"1.195532877","rc":[{"atb":[[1.98,40.82]],"id":42327927}],"con":true,"img":false}]}
{"op":"mcm","clk":"5323222890","pt":1646328765851,"mc":[{"id":"1.195532877","rc":[{"atb":[[2,5.96],[2.02,1.65]],"id":42327927}],"con":true,"img":false}]}
{"op":"mcm","clk":"5323222903","pt":1646328765955,"mc":[{"id":"1.195532877","rc":[{"atb":[[1.9,0]],"id":43094641}],"con":true,"img":false}]}
{"op":"mcm","clk":"5323222982","pt":1646328766747,"mc":[{"id":"1.195532877","rc":[{"atb":[[1.86,4.14]],"id":43189004},{"atb":[[1.32,33.64]],"id":38519823}],"con":true,"img":false}]}
{"op":"mcm","clk":"5323223001","pt":1646328766951,"mc":[{"id":"1.195532877","rc":[{"atb":[[1.84,7.89]],"id":43189004}],"con":true,"img":false}]}
{"op":"mcm","clk":"5323223021","pt":1646328767156,"mc":[{"id":"1.195532877","rc":[{"atb":[[1.89,4.15],[1.84,0],[1.85,0]],"id":43189004}],"con":true,"img":false}]}
{"op":"mcm","clk":"5323223029","pt":1646328767260,"mc":[{"id":"1.195532877","rc":[{"atb":[[1.83,0],[1.82,6.02],[1.87,45.98]],"id":43189004},{"atb":[[1.99,44.37],[1.98,0]],"id":42327927}],"con":true,"img":false}]}
{"op":"mcm","clk":"5323223053","pt":1646328767472,"mc":[{"id":"1.195532877","rc":[{"atb":[[1.97,41.24]],"id":43094641},{"atb":[[1.82,0]],"id":43189004}],"con":true,"img":false}]}
{"op":"mcm","clk":"5323223388","pt":1646328770656,"mc":[{"id":"1.195532877","rc":[{"atb":[[1.76,11.02]],"id":42327927}],"con":true,"img":false}]}
{"op":"mcm","clk":"5323223423","pt":1646328770965,"mc":[{"id":"1.195532877","rc":[{"atb":[[1.76,0]],"id":42327927},{"atb":[[1.3,13.06],[1.52,192.31]],"id":38519823}],"con":true,"img":false}]}
{"op":"mcm","clk":"5323223437","pt":1646328771073,"mc":[{"id":"1.195532877","rc":[{"atb":[[1.9,8.3]],"id":43189004},{"atb":[[1.99,40.4]],"id":42327927},{"atb":[[1.57,3.97]],"id":38519823},{"atb":[[1.8,48.06]],"id":39236417}],"con":true,"img":false}]}
{"op":"mcm","clk":"5323223452","pt":1646328771138,"mc":[{"id":"1.195532877","rc":[{"atb":[[1.89,112.36]],"id":39236417}],"con":true,"img":false}]}
{"op":"mcm","clk":"5323223465","pt":1646328771237,"mc":[{"id":"1.195532877","rc":[{"atb":[[1.55,0],[1.58,3.97]],"id":38519823}],"con":true,"img":false}]}
{"op":"mcm","clk":"5323223476","pt":1646328771353,"mc":[{"id":"1.195532877","rc":[{"atb":[[1.56,0]],"id":38519823}],"con":true,"img":false}]}
{"op":"mcm","clk":"5323223486","pt":1646328771449,"mc":[{"id":"1.195532877","rc":[{"atb":[[1.58,5.96],[1.3,0]],"id":38519823}],"con":true,"img":false}]}
{"op":"mcm","clk":"5323223515","pt":1646328771756,"mc":[{"id":"1.195532877","rc":[{"atb":[[1.89,2.16],[1.86,0]],"id":43189004}],"con":true,"img":false}]}
{"op":"mcm","clk":"5323223527","pt":1646328771807,"mc":[{"id":"1.195532877","rc":[{"atb":[[1.91,1.99]],"id":43189004}],"con":true,"img":false}]}
{"op":"mcm","clk":"5323223594","pt":1646328772433,"mc":[{"id":"1.195532877","rc":[{"atb":[[1.56,71.43],[1.54,0]],"id":38519823},{"atb":[[1.01,4804.04]],"id":39236417}],"con":true,"img":false}]}
{"op":"mcm","clk":"5323223621","pt":1646328772650,"mc":[{"id":"1.195532877","rc":[{"atb":[[1.01,4804.04],[1.23,0],[1.31,0]],"id":38519823}],"con":true,"img":false}]}
{"op":"mcm","clk":"5323223701","pt":1646328773475,"mc":[{"id":"1.195532877","rc":[{"atb":[[2,3.97]],"id":43094641}],"con":true,"img":false}]}
{"op":"mcm","clk":"5323223722","pt":1646328773631,"mc":[{"id":"1.195532877","rc":[{"atb":[[2.02,3.97],[1.98,2.15]],"id":43094641}],"con":true,"img":false}]}
{"op":"mcm","clk":"5323223740","pt":1646328773843,"mc":[{"id":"1.195532877","rc":[{"atb":[[1.99,0],[2.02,5.62]],"id":43094641}],"con":true,"img":false}]}
{"op":"mcm","clk":"5323223752","pt":1646328773940,"mc":[{"id":"1.195532877","rc":[{"atb":[[2.02,7.61]],"id":43094641}],"con":true,"img":false}]}
{"op":"mcm","clk":"5323223760","pt":1646328774046,"mc":[{"id":"1.195532877","rc":[{"atb":[[1.32,0]],"id":38519823},{"atb":[[1.93,5.96]],"id":39236417}],"con":true,"img":false}]}
{"op":"mcm","clk":"5323223853","pt":1646328774938,"mc":[{"id":"1.195532877","rc":[{"atb":[[1.98,0],[2.06,2.15]],"id":43094641}],"con":true,"img":false}]}
{"op":"mcm","clk":"5323223863","pt":1646328775047,"mc":[{"id":"1.195532877","rc":[{"atb":[[1.89,0],[1.91,4.15]],"id":43189004}],"con":true,"img":false}]}
{"op":"mcm","clk":"5323223878","pt":1646328775145,"mc":[{"id":"1.195532877","rc":[{"atb":[[2.06,6.12]],"id":43094641}],"con":true,"img":false}]}
{"op":"mcm","clk":"5323223887","pt":1646328775257,"mc":[{"id":"1.195532877","rc":[{"atb":[[2.02,3.64]],"id":43094641}],"con":true,"img":false}]}
{"op":"mcm","clk":"5323223942","pt":1646328775629,"mc":[{"id":"1.195532877","rc":[{"atb":[[2.02,42.86]],"id":43094641}],"con":true,"img":false}]}
{"op":"mcm","clk":"5323223953","pt":1646328775734,"mc":[{"id":"1.195532877","rc":[{"atb":[[1.97,0]],"id":43094641}],"con":true,"img":false}]}
{"op":"mcm","clk":"5323223992","pt":1646328776047,"mc":[{"id":"1.195532877","rc":[{"atb":[[2.02,40.87]],"id":43094641}],"con":true,"img":false}]}
{"op":"mcm","clk":"5323224007","pt":1646328776152,"mc":[{"id":"1.195532877","rc":[{"atb":[[2.08,1.99]],"id":43094641}],"con":true,"img":false}]}
{"op":"mcm","clk":"5323224053","pt":1646328776523,"mc":[{"id":"1.195532877","rc":[{"atb":[[1.9,0]],"id":43189004},{"atb":[[2.04,3.31]],"id":42327927},{"atb":[[1.57,0]],"id":38519823},{"atb":[[1.8,0]],"id":39236417}],"con":true,"img":false}]}
{"op":"mcm","clk":"5323224068","pt":1646328776681,"mc":[{"id":"1.195532877","rc":[{"atb":[[2.06,3.31]],"id":42327927}],"con":true,"img":false}]}
{"op":"mcm","clk":"5323224079","pt":1646328776742,"mc":[{"id":"1.195532877","rc":[{"atb":[[1.91,11.35]],"id":43189004},{"atb":[[2,1.99]],"id":42327927}],"con":true,"img":false}]}
{"op":"mcm","clk":"5323224089","pt":1646328776837,"mc":[{"id":"1.195532877","rc":[{"atb":[[1.99,48.11]],"id":42327927}],"con":true,"img":false}]}
{"op":"mcm","clk":"5323224105","pt":1646328776943,"mc":[{"id":"1.195532877","rc":[{"atb":[[2,0]],"id":42327927}],"con":true,"img":false}]}
{"op":"mcm","clk":"5323224116","pt":1646328777056,"mc":[{"id":"1.195532877","rc":[{"atb":[[2.06,5.3]],"id":42327927}],"con":true,"img":false}]}
{"op":"mcm","clk":"5323224140","pt":1646328777258,"mc":[{"id":"1.195532877","rc":[{"atb":[[1.85,117.65]],"id":43189004},{"atb":[[1.99,0],[2.02,40.87]],"id":42327927}],"con":true,"img":false}]}
{"op":"mcm","clk":"5323224245","pt":1646328778144,"mc":[{"id":"1.195532877","rc":[{"atb":[[2.02,1.65],[2.04,38.46]],"id":43094641},{"atb":[[1.64,0],[1.6,0],[1.5,0]],"id":43189004}],"con":true,"img":false}]}
{"op":"mcm","clk":"5323224304","pt":1646328778719,"mc":[{"id":"1.195532877","rc":[{"atb":[[2,0]],"id":43094641}],"con":true,"img":false}]}
{"op":"mcm","clk":"5323224391","pt":1646328779608,"mc":[{"id":"1.195532877","rc":[{"atb":[[1.53,9.9]],"id":38519823},{"atb":[[1.94,4.17]],"id":39236417}],"con":true,"img":false}]}
{"op":"mcm","clk":"5323224402","pt":1646328779713,"mc":[{"id":"1.195532877","rc":[{"atb":[[1.93,1.99],[1.95,5.96]],"id":39236417}],"con":true,"img":false}]}
{"op":"mcm","clk":"5323224415","pt":1646328779841,"mc":[{"id":"1.195532877","rc":[{"atb":[[1.93,0]],"id":39236417}],"con":true,"img":false}]}
{"op":"mcm","clk":"5323224421","pt":1646328779941,"mc":[{"id":"1.195532877","rc":[{"atb":[[1.95,7.95]],"id":39236417}],"con":true,"img":false}]}
{"op":"mcm","clk":"5323224556","pt":1646328781148,"mc":[{"id":"1.195532877","rc":[{"atb":[[1.91,0],[1.93,43.01]],"id":39236417}],"con":true,"img":false}]}
{"op":"mcm","clk":"5323224637","pt":1646328781937,"mc":[{"id":"1.195532877","rc":[{"atb":[[2.02,0]],"id":43094641},{"atb":[[2.02,39.22]],"id":42327927}],"con":true,"img":false}]}
{"op":"mcm","clk":"5323224666","pt":1646328782250,"mc":[{"id":"1.195532877","rc":[{"atb":[[2.1,1.65]],"id":43094641},{"atb":[[2.08,1.65]],"id":42327927}],"con":true,"img":false}]}
{"op":"mcm","clk":"5323224680","pt":1646328782361,"mc":[{"id":"1.195532877","rc":[{"atb":[[1.92,22.71]],"id":43189004},{"atb":[[2.04,0]],"id":42327927},{"atb":[[1.54,19.36]],"id":38519823},{"atb":[[1.94,16.09]],"id":39236417}],"con":true,"img":false}]}
{"op":"mcm","clk":"5323224694","pt":1646328782456,"mc":[{"id":"1.195532877","rc":[{"atb":[[1.54,204.55]],"id":38519823}],"con":true,"img":false}]}
{"op":"mcm","clk":"5323224784","pt":1646328782972,"mc":[{"id":"1.195532877","rc":[{"atb":[[2.06,2.15],[2.1,3.65]],"id":43094641}],"con":true,"img":false}]}
{"op":"mcm","clk":"5323224810","pt":1646328783106,"mc":[{"id":"1.195532877","rc":[{"atb":[[2.04,0]],"id":43094641},{"atb":[[2.02,0]],"id":42327927}],"con":true,"img":false}]}
{"op":"mcm","clk":"5323224828","pt":1646328783185,"mc":[{"id":"1.195532877","rc":[{"atb":[[2.06,39.89]],"id":43094641},{"atb":[[2.04,38.46]],"id":42327927}],"con":true,"img":false}]}
{"op":"mcm","clk":"5323224984","pt":1646328783967,"mc":[{"id":"1.195532877","rc":[{"atb":[[1.91,9.36]],"id":43189004}],"con":true,"img":false}]}
{"op":"mcm","clk":"5323224995","pt":1646328784072,"mc":[{"id":"1.195532877","rc":[{"atb":[[1.93,1.99]],"id":43189004}],"con":true,"img":false}]}
{"op":"mcm","clk":"5323225031","pt":1646328784247,"mc":[{"id":"1.195532877","rc":[{"atb":[[2.08,0]],"id":43094641},{"atb":[[1.94,11.91]],"id":39236417}],"con":true,"img":false}]}
{"op":"mcm","clk":"5323225062","pt":1646328784399,"mc":[{"id":"1.195532877","rc":[{"atb":[[2.12,1.99]],"id":43094641}],"con":true,"img":false}]}
{"op":"mcm","clk":"5323225119","pt":1646328784722,"mc":[{"id":"1.195532877","rc":[{"atb":[[2.12,5.3]],"id":43094641}],"con":true,"img":false}]}
{"op":"mcm","clk":"5323225224","pt":1646328785674,"mc":[{"id":"1.195532877","rc":[{"atb":[[1.88,0],[1.95,2.15]],"id":43189004},{"atb":[[1.59,2.15],[1.53,7.75]],"id":38519823},{"atb":[[1.79,0],[1.97,2.15]],"id":39236417}],"con":true,"img":false}]}
{"op":"mcm","clk":"5323225264","pt":1646328785884,"mc":[{"id":"1.195532877","rc":[{"atb":[[1.97,10.1],[1.95,1.99]],"id":39236417}],"con":true,"img":false}]}
{"op":"mcm","clk":"5323225341","pt":1646328786348,"mc":[{"id":"1.195532877","rc":[{"atb":[[1.95,0]],"id":39236417}],"con":true,"img":false}]}
{"op":"mcm","clk":"5323225352","pt":1646328786453,"mc":[{"id":"1.195532877","rc":[{"atb":[[1.91,2.16]],"id":43189004},{"atb":[[1.53,0]],"id":38519823},{"atb":[[1.98,1.99]],"id":39236417}],"con":true,"img":false}]}
{"op":"mcm","clk":"5323225391","pt":1646328786618,"mc":[{"id":"1.195532877","rc":[{"atb":[[1.58,3.97]],"id":38519823}],"con":true,"img":false}]}
{"op":"mcm","clk":"5323225406","pt":1646328786725,"mc":[{"id":"1.195532877","rc":[{"atb":[[1.6,1.99]],"id":38519823}],"con":true,"img":false}]}
{"op":"mcm","clk":"5323225434","pt":1646328786963,"mc":[{"id":"1.195532877","rc":[{"atb":[[1.93,0]],"id":43189004},{"atb":[[1.6,4.15],[1.58,0]],"id":38519823}],"con":true,"img":false}]}
{"op":"mcm","clk":"5323225450","pt":1646328787037,"mc":[{"id":"1.195532877","rc":[{"atb":[[1.96,1.99]],"id":43189004}],"con":true,"img":false}]}
{"op":"mcm","clk":"5323225478","pt":1646328787248,"mc":[{"id":"1.195532877","rc":[{"atb":[[1.83,180.72]],"id":43189004}],"con":true,"img":false}]}
{"op":"mcm","clk":"5323225593","pt":1646328787935,"mc":[{"id":"1.195532877","rc":[{"atb":[[1.92,0]],"id":43189004},{"atb":[[2.1,3.31]],"id":42327927},{"atb":[[1.94,0]],"id":39236417}],"con":true,"img":false}]}
{"op":"mcm","clk":"5323225618","pt":1646328788144,"mc":[{"id":"1.195532877","rc":[{"atb":[[2.06,1.99],[2.1,6.62]],"id":42327927}],"con":true,"img":false}]}
{"op":"mcm","clk":"5323225664","pt":1646328788459,"mc":[{"id":"1.195532877","rc":[{"atb":[[2.06,2.15],[2.08,37.04]],"id":43094641},{"atb":[[2.06,39.73],[2.04,0]],"id":42327927},{"atb":[[1.58,68.97]],"id":38519823},{"atb":[[1.96,41.67],[1.93,0]],"id":39236417}],"con":true,"img":false}]}
{"op":"mcm","clk":"5323225755","pt":1646328788952,"mc":[{"id":"1.195532877","rc":[{"atb":[[2.06,37.74]],"id":42327927}],"con":true,"img":false}]}
{"op":"mcm","clk":"5323225773","pt":1646328789036,"mc":[{"id":"1.195532877","rc":[{"atb":[[2.12,1.99]],"id":42327927}],"con":true,"img":false}]}
{"op":"mcm","clk":"5323225788","pt":1646328789140,"mc":[{"id":"1.195532877","rc":[{"atb":[[1.98,9.06]],"id":39236417}],"con":true,"img":false}]}
{"op":"mcm","clk":"5323225922","pt":1646328789836,"mc":[{"id":"1.195532877","rc":[{"atb":[[2.1,2]],"id":43094641},{"atb":[[2.08,0]],"id":42327927}],"con":true,"img":false}]}
{"op":"mcm","clk":"5323225963","pt":1646328790035,"mc":[{"id":"1.195532877","rc":[{"atb":[[2.14,1.65]],"id":43094641},{"atb":[[2.14,1.65]],"id":42327927}],"con":true,"img":false}]}
{"op":"mcm","clk":"5323225985","pt":1646328790138,"mc":[{"id":"1.195532877","rc":[{"atb":[[1.54,185.19]],"id":38519823}],"con":true,"img":false}]}
{"op":"mcm","clk":"5323226078","pt":1646328790662,"mc":[{"id":"1.195532877","rc":[{"atb":[[2.14,3.65],[2.1,0]],"id":43094641}],"con":true,"img":false}]}
{"op":"mcm","clk":"5323226161","pt":1646328791170,"mc":[{"id":"1.195532877","rc":[{"atb":[[2.12,3.31]],"id":43094641}],"con":true,"img":false}]}
{"op":"mcm","clk":"5323226176","pt":1646328791241,"mc":[{"id":"1.195532877","rc":[{"atb":[[2.16,1.99]],"id":43094641}],"con":true,"img":false}]}
{"op":"mcm","clk":"5323226324","pt":1646328792232,"mc":[{"id":"1.195532877","rc":[{"atb":[[1.88,6.22]],"id":43189004},{"atb":[[1.61,2.9]],"id":38519823}],"con":true,"img":false}]}
{"op":"mcm","clk":"5323226349","pt":1646328792447,"mc":[{"id":"1.195532877","rc":[{"atb":[[1.6,2.16]],"id":38519823}],"con":true,"img":false}]}
{"op":"mcm","clk":"5323226365","pt":1646328792552,"mc":[{"id":"1.195532877","rc":[{"atb":[[1.62,1.99]],"id":38519823}],"con":true,"img":false}]}
{"op":"mcm","clk":"5323226488","pt":1646328793546,"mc":[{"id":"1.195532877","rc":[{"atb":[[2.12,0]],"id":43094641},{"atb":[[1.92,6.45]],"id":43189004},{"atb":[[2.1,3.31]],"id":42327927},{"atb":[[1.99,18.12]],"id":39236417}],"con":true,"img":false}]}
{"op":"mcm","clk":"5323226503","pt":1646328793650,"mc":[{"id":"1.195532877","rc":[{"atb":[[1.98,19.17],[1.97,2.15]],"id":39236417}],"con":true,"img":false}]}
{"op":"mcm","clk":"5323226527","pt":1646328793861,"mc":[{"id":"1.195532877","rc":[{"atb":[[1.98,17.18]],"id":39236417}],"con":true,"img":false}]}
{"op":"mcm","clk":"5323226541","pt":1646328793965,"mc":[{"id":"1.195532877","rc":[{"atb":[[2,1.99]],"id":39236417}],"con":true,"img":false}]}
{"op":"mcm","clk":"5323226563","pt":1646328794174,"mc":[{"id":"1.195532877","rc":[{"atb":[[1.66,15.64]],"id":39236417}],"con":true,"img":false}]}
{"op":"mcm","clk":"5323226578","pt":1646328794228,"mc":[{"id":"1.195532877","rc":[{"atb":[[2.12,35.71],[2.08,0]],"id":43094641},{"atb":[[2.06,0],[2.1,39.67]],"id":42327927},{"atb":[[1.6,68.83],[1.58,0]],"id":38519823},{"atb":[[1.98,58],[1.96,0]],"id":39236417}],"con":true,"img":false}]}
{"op":"mcm","clk":"5323226621","pt":1646328794645,"mc":[{"id":"1.195532877","rc":[{"atb":[[1.6,66.67],[1.62,4.9]],"id":38519823},{"atb":[[1.66,0]],"id":39236417}],"con":true,"img":false}]}
{"op":"mcm","clk":"5323226645","pt":1646328794853,"mc":[{"id":"1.195532877","rc":[{"atb":[[1.62,1.99],[1.61,6.88]],"id":38519823}],"con":true,"img":false}]}
{"op":"mcm","clk":"5323226799","pt":1646328796159,"mc":[{"id":"1.195532877","rc":[{"atb":[[1.63,3.97]],"id":38519823}],"con":true,"img":false}]}
{"op":"mcm","clk":"5323226814","pt":1646328796265,"mc":[{"id":"1.195532877","rc":[{"atb":[[1.59,0],[1.63,6.12]],"id":38519823}],"con":true,"img":false}]}
{"op":"mcm","clk":"5323226893","pt":1646328796944,"mc":[{"id":"1.195532877","rc":[{"atb":[[1.62,0]],"id":38519823}],"con":true,"img":false}]}
{"op":"mcm","clk":"5323226901","pt":1646328797053,"mc":[{"id":"1.195532877","rc":[{"atb":[[1.64,1.99]],"id":38519823}],"con":true,"img":false}]}
{"op":"mcm","clk":"5323226930","pt":1646328797261,"mc":[{"id":"1.195532877","rc":[{"atb":[[1.81,250],[1.88,0]],"id":43189004},{"atb":[[1.61,3.98]],"id":38519823},{"atb":[[1.98,50.93]],"id":39236417}],"con":true,"img":false}]}
{"op":"mcm","clk":"5323227023","pt":1646328797840,"mc":[{"id":"1.195532877","rc":[{"atb":[[2.14,2]],"id":43094641}],"con":true,"img":false}]}
{"op":"mcm","clk":"5323227044","pt":1646328798050,"mc":[{"id":"1.195532877","rc":[{"atb":[[2.18,1.65]],"id":43094641},{"atb":[[2.02,1.65]],"id":39236417}],"con":true,"img":false}]}
{"op":"mcm","clk":"5323227069","pt":1646328798256,"mc":[{"id":"1.195532877","rc":[{"atb":[[2.18,3.65],[2.14,0]],"id":43094641}],"con":true,"img":false}]}
{"op":"mcm","clk":"5323227083","pt":1646328798362,"mc":[{"id":"1.195532877","rc":[{"atb":[[2.12,40.71]],"id":43094641}],"con":true,"img":false}]}
{"op":"mcm","clk":"5323227130","pt":1646328798674,"mc":[{"id":"1.195532877","rc":[{"atb":[[2.12,35.71]],"id":43094641}],"con":true,"img":false}]}
{"op":"mcm","clk":"5323227137","pt":1646328798783,"mc":[{"id":"1.195532877","rc":[{"atb":[[2.16,0]],"id":43094641}],"con":true,"img":false}]}
{"op":"mcm","clk":"5323227148","pt":1646328798860,"mc":[{"id":"1.195532877","rc":[{"atb":[[2.2,1.99]],"id":43094641}],"con":true,"img":false}]}
{"op":"mcm","clk":"5323227212","pt":1646328799361,"mc":[{"id":"1.195532877","rc":[{"atb":[[2.02,7.28]],"id":43094641}],"con":true,"img":false}]}
{"op":"mcm","clk":"5323227223","pt":1646328799465,"mc":[{"id":"1.195532877","rc":[{"atb":[[2.18,7.63]],"id":43094641},{"atb":[[2.16,3.31]],"id":42327927},{"atb":[[1.99,0]],"id":39236417}],"con":true,"img":false}]}
{"op":"mcm","clk":"5323227242","pt":1646328799678,"mc":[{"id":"1.195532877","rc":[{"atb":[[2.02,1.67]],"id":43094641}],"con":true,"img":false}]}
{"op":"mcm","clk":"5323227268","pt":1646328799867,"mc":[{"id":"1.195532877","rc":[{"atb":[[2.02,0]],"id":43094641}],"con":true,"img":false}]}
{"op":"mcm","clk":"5323227280","pt":1646328799952,"mc":[{"id":"1.195532877","rc":[{"atb":[[2.12,0],[2.16,34.48]],"id":43094641},{"atb":[[2.12,37.7],[2.1,3.31]],"id":42327927},{"atb":[[1.6,0],[1.62,64.52]],"id":38519823},{"atb":[[1.99,40.4],[1.98,10.11]],"id":39236417}],"con":true,"img":false}]}
{"op":"mcm","clk":"5323227488","pt":1646328801664,"mc":[{"id":"1.195532877","rc":[{"atb":[[1.63,2.15]],"id":38519823}],"con":true,"img":false}]}
{"op":"mcm","clk":"5323227558","pt":1646328802451,"mc":[{"id":"1.195532877","rc":[{"atb":[[1.64,4.15],[1.61,0]],"id":38519823}],"con":true,"img":false}]}
{"op":"mcm","clk":"5323227593","pt":1646328802765,"mc":[{"id":"1.195532877","rc":[{"atb":[[2,31.29]],"id":41696085},{"atb":[[1.88,6.22]],"id":43189004},{"atb":[[1.64,9.83]],"id":38519823}],"con":true,"img":false}]}
{"op":"mcm","clk":"5323227627","pt":1646328803074,"mc":[{"id":"1.195532877","rc":[{"atb":[[1.99,2.15],[2.02,41.24]],"id":41696085}],"con":true,"img":false}]}
{"op":"mcm","clk":"5323227750","pt":1646328804279,"mc":[{"id":"1.195532877","rc":[{"atb":[[1.99,42.55],[1.97,0]],"id":41696085}],"con":true,"img":false}]}
{"op":"mcm","clk":"5323227796","pt":1646328804652,"mc":[{"id":"1.195532877","rc":[{"atb":[[2.18,3.65]],"id":43094641},{"atb":[[2.04,3.31]],"id":39236417}],"con":true,"img":false}]}
{"op":"mcm","clk":"5323227820","pt":1646328804860,"mc":[{"id":"1.195532877","rc":[{"atb":[[2,0]],"id":39236417}],"con":true,"img":false}]}
{"op":"mcm","clk":"5323227833","pt":1646328804964,"mc":[{"id":"1.195532877","rc":[{"atb":[[1.99,42.39]],"id":39236417}],"con":true,"img":false}]}
{"op":"mcm","clk":"5323227857","pt":1646328805174,"mc":[{"id":"1.195532877","rc":[{"atb":[[2.12,35.71]],"id":42327927}],"con":true,"img":false}]}
{"op":"mcm","clk":"5323227868","pt":1646328805274,"mc":[{"id":"1.195532877","rc":[{"atb":[[2.18,1.99]],"id":42327927}],"con":true,"img":false}]}
{"op":"mcm","clk":"5323227931","pt":1646328805744,"mc":[{"id":"1.195532877","rc":[{"atb":[[1.99,40.4]],"id":39236417}],"con":true,"img":false}]}
{"op":"mcm","clk":"5323227947","pt":1646328805854,"mc":[{"id":"1.195532877","rc":[{"atb":[[2.18,2]],"id":43094641},{"atb":[[2.14,0]],"id":42327927},{"atb":[[2.02,0],[2.06,1.99]],"id":39236417}],"con":true,"img":false}]}
{"op":"mcm","clk":"5323227964","pt":1646328805953,"mc":[{"id":"1.195532877","rc":[{"atb":[[2.12,0],[2.14,35.09]],"id":42327927},{"atb":[[2,40],[1.99,0]],"id":39236417}],"con":true,"img":false}]}
{"op":"mcm","clk":"5323227976","pt":1646328806058,"mc":[{"id":"1.195532877","rc":[{"atb":[[2.22,1.65]],"id":43094641},{"atb":[[2.04,1.65]],"id":41696085},{"atb":[[2.2,1.65]],"id":42327927},{"atb":[[2.06,3.64]],"id":39236417}],"con":true,"img":false}]}
{"op":"mcm","clk":"5323227987","pt":1646328806163,"mc":[{"id":"1.195532877","rc":[{"atb":[[2,0],[2.02,39.22]],"id":39236417}],"con":true,"img":false}]}
{"op":"mcm","clk":"5323227994","pt":1646328806264,"mc":[{"id":"1.195532877","rc":[{"atb":[[2.22,3.65],[2.18,0]],"id":43094641}],"con":true,"img":false}]}
{"op":"mcm","clk":"5323228041","pt":1646328806744,"mc":[{"id":"1.195532877","rc":[{"spn":10.36,"spf":"NaN","id":43094641},{"atb":[[1.99,40.4],[2.08,2.15]],"id":41696085},{"spn":19.04,"spf":"NaN","id":41696085},{"spn":1.96,"spf":1.0,"id":43189004},{"spn":8.1,"spf":"NaN","id":42327927},{"spn":1.64,"spf":1.0,"id":38519823},{"spn":6.28,"spf":"NaN","id":39236417}],"con":true,"img":false}]}
{"op":"mcm","clk":"5323228062","pt":1646328806949,"mc":[{"id":"1.195532877","rc":[{"atb":[[2.2,0]],"id":43094641},{"atb":[[2.02,0],[2.08,4.31]],"id":41696085}],"con":true,"img":false}]}
{"op":"mcm","clk":"5323228069","pt":1646328807058,"mc":[{"id":"1.195532877","rc":[{"atb":[[2.24,1.99]],"id":43094641}],"con":true,"img":false}]}
{"op":"mcm","clk":"5323228092","pt":1646328807371,"mc":[{"id":"1.195532877","rc":[{"atb":[[1.95,0]],"id":41696085},{"atb":[[1.65,19.66]],"id":38519823}],"con":true,"img":false}]}
{"op":"mcm","clk":"5323228099","pt":1646328807475,"mc":[{"id":"1.195532877","rc":[{"atb":[[2,0]],"id":41696085}],"con":true,"img":false}]}
{"op":"mcm","clk":"5323228109","pt":1646328807533,"mc":[{"id":"1.195532877","rc":[{"atb":[[1.64,7.67],[1.65,29.49]],"id":38519823}],"con":true,"img":false}]}
{"op":"mcm","clk":"5323228137","pt":1646328807742,"mc":[{"id":"1.195532877","rc":[{"atb":[[1.64,5.68]],"id":38519823}],"con":true,"img":false}]}
{"op":"mcm","clk":"5323228145","pt":1646328807844,"mc":[{"id":"1.195532877","rc":[{"atb":[[1.66,1.99]],"id":38519823}],"con":true,"img":false}]}
{"op":"mcm","clk":"5323228331","pt":1646328809780,"mc":[{"id":"1.195532877","rc":[{"atb":[[1.64,0]],"id":38519823}],"con":true,"img":false}]}
{"op":"mcm","clk":"5323228356","pt":1646328809946,"mc":[{"id":"1.195532877","rc":[{"atb":[[2.2,33.33],[2.16,0]],"id":43094641},{"atb":[[1.76,6.07]],"id":42327927},{"atb":[[1.64,62.5],[1.62,0],[1.61,8.06]],"id":38519823}],"con":true,"img":false}]}
{"op":"mcm","clk":"5323228376","pt":1646328810149,"mc":[{"id":"1.195532877","rc":[{"atb":[[1.76,0]],"id":42327927},{"atb":[[1.61,0]],"id":38519823}],"con":true,"img":false}]}
{"op":"mcm","clk":"5323228388","pt":1646328810256,"mc":[{"id":"1.195532877","rc":[{"atb":[[2.18,5.95]],"id":43094641},{"atb":[[2.16,0]],"id":42327927},{"atb":[[2.04,0]],"id":39236417}],"con":true,"img":false}]}
{"op":"mcm","clk":"5323228427","pt":1646328810569,"mc":[{"id":"1.195532877","rc":[{"atb":[[2.06,1.65]],"id":39236417}],"con":true,"img":false}]}
{"op":"mcm","clk":"5323228441","pt":1646328810675,"mc":[{"id":"1.195532877","rc":[{"atb":[[2.04,1.99]],"id":39236417}],"con":true,"img":false}]}
{"op":"mcm","clk":"5323228470","pt":1646328810838,"mc":[{"id":"1.195532877","rc":[{"atb":[[2.18,0]],"id":42327927}],"con":true,"img":false}]}
{"op":"mcm","clk":"5323228482","pt":1646328810939,"mc":[{"id":"1.195532877","rc":[{"atb":[[2.16,1.99]],"id":42327927}],"con":true,"img":false}]}
{"op":"mcm","clk":"5323228553","pt":1646328811571,"mc":[{"id":"1.195532877","rc":[{"atb":[[1.99,0],[2.04,40.11]],"id":41696085}],"con":true,"img":false}]}
{"op":"mcm","clk":"5323228594","pt":1646328811940,"mc":[{"id":"1.195532877","rc":[{"atb":[[2.24,8.31]],"id":41696085}],"con":true,"img":false}]}
{"op":"mcm","clk":"5323228613","pt":1646328812148,"mc":[{"id":"1.195532877","rc":[{"atb":[[2.24,0]],"id":41696085}],"con":true,"img":false}]}
{"op":"mcm","clk":"5323228638","pt":1646328812280,"mc":[{"id":"1.195532877","rc":[{"atb":[[2.04,1.65],[2.2,33.33]],"id":41696085}],"con":true,"img":false}]}
{"op":"mcm","clk":"5323228668","pt":1646328812464,"mc":[{"id":"1.195532877","rc":[{"atb":[[2.08,2.55]],"id":39236417}],"con":true,"img":false}]}
{"op":"mcm","clk":"5323228711","pt":1646328812692,"mc":[{"id":"1.195532877","rc":[{"atb":[[2.2,0],[2.16,34.48]],"id":41696085}],"con":true,"img":false}]}
{"op":"mcm","clk":"5323229029","pt":1646328814044,"mc":[{"id":"1.195532877","rc":[{"atb":[[2.22,2]],"id":43094641},{"atb":[[2.04,0]],"id":41696085},{"atb":[[2.2,0]],"id":42327927},{"atb":[[2.06,0],[2.04,0]],"id":39236417}],"con":true,"img":false}]}
{"op":"mcm","clk":"5323229062","pt":1646328814199,"mc":[{"id":"1.195532877","rc":[{"atb":[[2.1,1.99]],"id":39236417}],"con":true,"img":false}]}
{"op":"mcm","clk":"5323229103","pt":1646328814318,"mc":[{"id":"1.195532877","rc":[{"atb":[[2.26,1.65]],"id":43094641},{"atb":[[2.18,1.65]],"id":41696085},{"atb":[[2.18,1.65]],"id":42327927},{"atb":[[2.1,3.64]],"id":39236417}],"con":true,"img":false}]}
{"op":"mcm","clk":"5323229142","pt":1646328814531,"mc":[{"id":"1.195532877","rc":[{"atb":[[2.22,0],[2.26,3.65]],"id":43094641},{"atb":[[2.18,5.97],[2.08,2.15]],"id":41696085}],"con":true,"img":false}]}
{"op":"mcm","clk":"5323229179","pt":1646328814799,"mc":[{"id":"1.195532877","rc":[{"atb":[[1.65,9.83]],"id":38519823}],"con":true,"img":false}]}
{"op":"mcm","clk":"5323229191","pt":1646328814901,"mc":[{"id":"1.195532877","rc":[{"atb":[[2.1,33.25]],"id":41696085},{"atb":[[1.57,50.38]],"id":38519823}],"con":true,"img":false}]}
{"op":"mcm","clk":"5323229202","pt":1646328815005,"mc":[{"id":"1.195532877","rc":[{"atb":[[2.24,0]],"id":43094641}],"con":true,"img":false}]}
{"op":"mcm","clk":"5323229214","pt":1646328815066,"mc":[{"id":"1.195532877","rc":[{"atb":[[2.28,1.99]],"id":43094641}],"con":true,"img":false}]}
{"op":"mcm","clk":"5323229314","pt":1646328816002,"mc":[{"id":"1.195532877","rc":[{"atb":[[2.1,94.22]],"id":42327927}],"con":true,"img":false}]}
{"op":"mcm","clk":"5323229340","pt":1646328816210,"mc":[{"id":"1.195532877","rc":[{"atb":[[2.02,0],[2.06,37.74]],"id":39236417}],"con":true,"img":false}]}
{"op":"mcm","clk":"5323229483","pt":1646328817389,"mc":[{"id":"1.195532877","rc":[{"atb":[[2.08,0]],"id":39236417}],"con":true,"img":false}]}
{"op":"mcm","clk":"5323229502","pt":1646328817601,"mc":[{"id":"1.195532877","rc":[{"atb":[[1.63,0],[1.68,2.15]],"id":38519823}],"con":true,"img":false}]}
{"op":"mcm","clk":"5323229514","pt":1646328817707,"mc":[{"id":"1.195532877","rc":[{"atb":[[2.24,32.26],[2.2,0]],"id":43094641},{"atb":[[2.16,0],[2.14,35.09]],"id":41696085},{"atb":[[1.82,8.51]],"id":43189004},{"atb":[[1.01,4804.04]],"id":42327927}],"con":true,"img":false}]}
{"op":"mcm","clk":"5323229539","pt":1646328817873,"mc":[{"id":"1.195532877","rc":[{"atb":[[1.82,0]],"id":43189004}],"con":true,"img":false}]}
{"op":"mcm","clk":"5323229549","pt":1646328817974,"mc":[{"id":"1.195532877","rc":[{"atb":[[2.18,0]],"id":43094641},{"atb":[[2.2,3.31]],"id":42327927},{"atb":[[2.04,10.95]],"id":39236417}],"con":true,"img":false}]}
{"op":"mcm","clk":"5323229559","pt":1646328818084,"mc":[{"id":"1.195532877","rc":[{"atb":[[1.64,0],[1.66,62.6]],"id":38519823}],"con":true,"img":false}]}
{"op":"mcm","clk":"5323229570","pt":1646328818189,"mc":[{"id":"1.195532877","rc":[{"atb":[[2.12,6.07]],"id":42327927},{"atb":[[2.1,1.65]],"id":39236417}],"con":true,"img":false}]}
{"op":"mcm","clk":"5323229583","pt":1646328818292,"mc":[{"id":"1.195532877","rc":[{"atb":[[2.08,1.99]],"id":39236417}],"con":true,"img":false}]}
{"op":"mcm","clk":"5323229616","pt":1646328818563,"mc":[{"id":"1.195532877","rc":[{"atb":[[2.16,0]],"id":42327927}],"con":true,"img":false}]}
{"op":"mcm","clk":"5323229627","pt":1646328818665,"mc":[{"id":"1.195532877","rc":[{"atb":[[2.22,1.99]],"id":42327927}],"con":true,"img":false}]}
{"op":"mcm","clk":"5323229647","pt":1646328818875,"mc":[{"id":"1.195532877","rc":[{"atb":[[2.12,0]],"id":42327927},{"atb":[[1.66,60.61]],"id":38519823}],"con":true,"img":false}]}
{"op":"mcm","clk":"5323229656","pt":1646328818981,"mc":[{"id":"1.195532877","rc":[{"atb":[[1.69,1.99]],"id":38519823}],"con":true,"img":false}]}
{"op":"mcm","clk":"5323229847","pt":1646328820789,"mc":[{"id":"1.195532877","rc":[{"atb":[[2.1,0]],"id":41696085},{"atb":[[1.69,6.3]],"id":38519823}],"con":true,"img":false}]}
{"op":"mcm","clk":"5323229950","pt":1646328821901,"mc":[{"id":"1.195532877","rc":[{"atb":[[2.26,2]],"id":43094641},{"atb":[[2.18,0]],"id":42327927}],"con":true,"img":false}]}
{"op":"mcm","clk":"5323229969","pt":1646328822116,"mc":[{"id":"1.195532877","rc":[{"atb":[[2.3,1.65]],"id":43094641},{"atb":[[2.24,1.65]],"id":42327927}],"con":true,"img":false}]}
{"op":"mcm","clk":"5323229978","pt":1646328822221,"mc":[{"id":"1.195532877","rc":[{"atb":[[1.57,0]],"id":38519823}],"con":true,"img":false}]}
{"op":"mcm","clk":"5323229987","pt":1646328822282,"mc":[{"id":"1.195532877","rc":[{"atb":[[2.28,5.31],[2.26,0]],"id":43094641},{"atb":[[2.1,4.21]],"id":39236417}],"con":true,"img":false}]}
{"op":"mcm","clk":"5323230024","pt":1646328822704,"mc":[{"id":"1.195532877","rc":[{"atb":[[2.08,0]],"id":39236417}],"con":true,"img":false}]}
{"op":"mcm","clk":"5323230034","pt":1646328822810,"mc":[{"id":"1.195532877","rc":[{"atb":[[2.12,1.99]],"id":39236417}],"con":true,"img":false}]}
{"op":"mcm","clk":"5323230110","pt":1646328823490,"mc":[{"id":"1.195532877","rc":[{"atb":[[2.24,0],[2.26,31.75]],"id":43094641},{"atb":[[1.67,59.7],[1.66,0]],"id":38519823},{"atb":[[2.06,0],[2.08,37.04]],"id":39236417}],"con":true,"img":false}]}
{"op":"mcm","clk":"5323230130","pt":1646328823699,"mc":[{"id":"1.195532877","rc":[{"atb":[[2.3,5.63]],"id":43094641},{"atb":[[2.2,0]],"id":42327927},{"atb":[[2.04,0]],"id":39236417}],"con":true,"img":false}]}
{"op":"mcm","clk":"5323230219","pt":1646328824503,"mc":[{"id":"1.195532877","rc":[{"atb":[[2.22,0]],"id":42327927}],"con":true,"img":false}]}
{"op":"mcm","clk":"5323230230","pt":1646328824601,"mc":[{"id":"1.195532877","rc":[{"atb":[[2.16,1.99]],"id":42327927}],"con":true,"img":false}]}
{"op":"mcm","clk":"5323230251","pt":1646328824807,"mc":[{"id":"1.195532877","rc":[{"atb":[[2.28,3.32]],"id":43094641}],"con":true,"img":false}]}
{"op":"mcm","clk":"5323230261","pt":1646328824901,"mc":[{"id":"1.195532877","rc":[{"atb":[[2.32,1.99]],"id":43094641}],"con":true,"img":false}]}
{"op":"mcm","clk":"5323230275","pt":1646328824977,"mc":[{"id":"1.195532877","rc":[{"atb":[[1.7,4.41]],"id":38519823}],"con":true,"img":false}]}
{"op":"mcm","clk":"5323230311","pt":1646328825288,"mc":[{"id":"1.195532877","rc":[{"atb":[[1.69,4.31]],"id":38519823}],"con":true,"img":false}]}
{"op":"mcm","clk":"5323230322","pt":1646328825389,"mc":[{"id":"1.195532877","rc":[{"atb":[[1.71,1.99]],"id":38519823}],"con":true,"img":false}]}
{"op":"mcm","clk":"5323230374","pt":1646328825969,"mc":[{"id":"1.195532877","rc":[{"atb":[[2.06,141.51]],"id":42327927}],"con":true,"img":false}]}
{"op":"mcm","clk":"5323230415","pt":1646328826387,"mc":[{"id":"1.195532877","rc":[{"atb":[[2.1,19.43]],"id":41696085}],"con":true,"img":false}]}
{"op":"mcm","clk":"5323230529","pt":1646328827687,"mc":[{"id":"1.195532877","rc":[{"atb":[[2.1,110.34]],"id":41696085}],"con":true,"img":false}]}
{"op":"mcm","clk":"5323230556","pt":1646328828000,"mc":[{"id":"1.195532877","rc":[{"atb":[[1.94,0],[2.2,2.15]],"id":42327927}],"con":true,"img":false}]}
{"op":"mcm","clk":"5323230713","pt":1646328829313,"mc":[{"id":"1.195532877","rc":[{"atb":[[1.92,0],[1.94,0]],"id":41696085},{"atb":[[1.63,0]],"id":42327927},{"atb":[[1.67,0],[1.69,62.28]],"id":38519823}],"con":true,"img":false}]}
{"op":"mcm","clk":"5323230767","pt":1646328829689,"mc":[{"id":"1.195532877","rc":[{"atb":[[2.3,1.65]],"id":43094641},{"atb":[[2.18,4.96]],"id":42327927},{"atb":[[1.69,57.97]],"id":38519823},{"atb":[[2.14,3.97]],"id":39236417}],"con":true,"img":false}]}
{"op":"mcm","clk":"5323230794","pt":1646328829891,"mc":[{"id":"1.195532877","rc":[{"atb":[[2.3,0]],"id":43094641},{"atb":[[2.24,0]],"id":42327927},{"atb":[[2.1,2.55]],"id":39236417}],"con":true,"img":false}]}
{"op":"mcm","clk":"5323230832","pt":1646328830099,"mc":[{"id":"1.195532877","rc":[{"atb":[[2.34,1.65]],"id":43094641},{"atb":[[2.22,1.65]],"id":42327927},{"atb":[[2.14,5.63]],"id":39236417}],"con":true,"img":false}]}
{"op":"mcm","clk":"5323230862","pt":1646328830314,"mc":[{"id":"1.195532877","rc":[{"atb":[[2.12,0],[2.1,38.91],[2.08,4.54]],"id":39236417}],"con":true,"img":false}]}
{"op":"mcm","clk":"5323230872","pt":1646328830416,"mc":[{"id":"1.195532877","rc":[{"atb":[[2.16,1.99]],"id":39236417}],"con":true,"img":false}]}
{"op":"mcm","clk":"5323230892","pt":1646328830520,"mc":[{"id":"1.195532877","rc":[{"atb":[[2.08,0]],"id":39236417}],"con":true,"img":false}]}
{"op":"mcm","clk":"5323230906","pt":1646328830577,"mc":[{"id":"1.195532877","rc":[{"atb":[[2.16,0]],"id":42327927},{"atb":[[2.12,35.71]],"id":39236417}],"con":true,"img":false}]}
{"op":"mcm","clk":"5323230918","pt":1646328830682,"mc":[{"id":"1.195532877","rc":[{"atb":[[2.22,3.64]],"id":42327927},{"atb":[[2.1,2.55]],"id":39236417}],"con":true,"img":false}]}
{"op":"mcm","clk":"5323230946","pt":1646328830892,"mc":[{"id":"1.195532877","rc":[{"atb":[[2.32,0]],"id":43094641}],"con":true,"img":false}]}
{"op":"mcm","clk":"5323230965","pt":1646328831002,"mc":[{"id":"1.195532877","rc":[{"atb":[[2.3,1.99]],"id":43094641}],"con":true,"img":false}]}
{"op":"mcm","clk":"5323231059","pt":1646328831781,"mc":[{"id":"1.195532877","rc":[{"atb":[[1.7,0]],"id":38519823}],"con":true,"img":false}]}
{"op":"mcm","clk":"5323231093","pt":1646328832095,"mc":[{"id":"1.195532877","rc":[{"atb":[[1.71,0]],"id":38519823}],"con":true,"img":false}]}
{"op":"mcm","clk":"5323231109","pt":1646328832201,"mc":[{"id":"1.195532877","rc":[{"atb":[[1.7,1.99]],"id":38519823}],"con":true,"img":false}]}
{"op":"mcm","clk":"5323231271","pt":1646328833512,"mc":[{"id":"1.195532877","rc":[{"atb":[[2.22,81.97]],"id":43094641}],"con":true,"img":false}]}
{"op":"mcm","clk":"5323231354","pt":1646328834305,"mc":[{"id":"1.195532877","rc":[{"atb":[[2.1,0]],"id":39236417}],"con":true,"img":false}]}
{"op":"mcm","clk":"5323231442","pt":1646328834893,"mc":[{"id":"1.195532877","rc":[{"atb":[[1.94,0],[1.93,48.21]],"id":43094641},{"atb":[[1.68,60.97],[1.69,0]],"id":38519823}],"con":true,"img":false}]}
{"op":"mcm","clk":"5323231488","pt":1646328835194,"mc":[{"id":"1.195532877","rc":[{"atb":[[2.36,3.31]],"id":43094641},{"atb":[[2.18,0]],"id":42327927},{"atb":[[1.72,3.97]],"id":38519823},{"atb":[[2.14,1.65]],"id":39236417}],"con":true,"img":false}]}
{"op":"mcm","clk":"5323231505","pt":1646328835297,"mc":[{"id":"1.195532877","rc":[{"atb":[[1.93,43.01]],"id":43094641}],"con":true,"img":false}]}
{"op":"mcm","clk":"5323231522","pt":1646328835400,"mc":[{"id":"1.195532877","rc":[{"atb":[[1.7,0]],"id":38519823}],"con":true,"img":false}]}
{"op":"mcm","clk":"5323231537","pt":1646328835502,"mc":[{"id":"1.195532877","rc":[{"atb":[[1.69,1.99]],"id":38519823}],"con":true,"img":false}]}
{"op":"mcm","clk":"5323231603","pt":1646328836025,"mc":[{"id":"1.195532877","rc":[{"atb":[[2.02,245.1]],"id":42327927}],"con":true,"img":false}]}
{"op":"mcm","clk":"5323231635","pt":1646328836187,"mc":[{"id":"1.195532877","rc":[{"atb":[[1.69,0]],"id":38519823}],"con":true,"img":false}]}
{"op":"mcm","clk":"5323231653","pt":1646328836291,"mc":[{"id":"1.195532877","rc":[{"atb":[[1.73,1.99]],"id":38519823}],"con":true,"img":false}]}
{"op":"mcm","clk":"5323231696","pt":1646328836607,"mc":[{"id":"1.195532877","rc":[{"atb":[[2.3,0]],"id":43094641}],"con":true,"img":false}]}
{"op":"mcm","clk":"5323231710","pt":1646328836709,"mc":[{"id":"1.195532877","rc":[{"atb":[[2.38,1.99]],"id":43094641}],"con":true,"img":false}]}
{"op":"mcm","clk":"5323231765","pt":1646328837124,"mc":[{"id":"1.195532877","rc":[{"atb":[[1.57,64.18]],"id":38519823}],"con":true,"img":false}]}
{"op":"mcm","clk":"5323231842","pt":1646328837699,"mc":[{"id":"1.195532877","rc":[{"atb":[[2.06,141.51]],"id":41696085}],"con":true,"img":false}]}
{"op":"mcm","clk":"5323231856","pt":1646328837801,"mc":[{"id":"1.195532877","rc":[{"atb":[[2.34,0]],"id":43094641},{"atb":[[2.14,0]],"id":39236417}],"con":true,"img":false}]}
{"op":"mcm","clk":"5323231881","pt":1646328838012,"mc":[{"id":"1.195532877","rc":[{"atb":[[2.4,1.65]],"id":43094641},{"atb":[[2.18,1.65]],"id":39236417}],"con":true,"img":false}]}
{"op":"mcm","clk":"5323231933","pt":1646328838491,"mc":[{"id":"1.195532877","rc":[{"atb":[[2.06,0],[2.34,2.15]],"id":43094641},{"atb":[[2.2,2.15],[2.08,0]],"id":41696085}],"con":true,"img":false}]}
{"op":"mcm","clk":"5323231990","pt":1646328838906,"mc":[{"id":"1.195532877","rc":[{"atb":[[2.16,0]],"id":39236417}],"con":true,"img":false}]}
{"op":"mcm","clk":"5323232002","pt":1646328839010,"mc":[{"id":"1.195532877","rc":[{"atb":[[2.14,1.99]],"id":39236417}],"con":true,"img":false}]}
{"op":"mcm","clk":"5323232113","pt":1646328839921,"mc":[{"id":"1.195532877","rc":[{"atb":[[1.99,5.83]],"id":39236417}],"con":true,"img":false}]}
{"op":"mcm","clk":"5323232222","pt":1646328840602,"mc":[{"id":"1.195532877","rc":[{"atb":[[2.36,0]],"id":43094641},{"atb":[[2.16,10.95]],"id":42327927},{"atb":[[1.72,0]],"id":38519823},{"atb":[[2.12,0],[2.18,5.63],[2.14,37.08]],"id":39236417}],"con":true,"img":false}]}
{"op":"mcm","clk":"5323232256","pt":1646328840814,"mc":[{"id":"1.195532877","rc":[{"atb":[[2.14,4.31],[2.16,34.48]],"id":41696085},{"atb":[[1.77,0]],"id":42327927},{"atb":[[1.68,2.15],[1.71,56.34]],"id":38519823}],"con":true,"img":false}]}
{"op":"mcm","clk":"5323232285","pt":1646328841009,"mc":[{"id":"1.195532877","rc":[{"atb":[[2.14,0]],"id":41696085}],"con":true,"img":false}]}
{"op":"mcm","clk":"5323232341","pt":1646328841215,"mc":[{"id":"1.195532877","rc":[{"atb":[[2.34,5.24]],"id":43094641}],"con":true,"img":false}]}
{"op":"mcm","clk":"5323232369","pt":1646328841424,"mc":[{"id":"1.195532877","rc":[{"atb":[[2.34,2.15]],"id":43094641}],"con":true,"img":false}]}
{"op":"mcm","clk":"5323232398","pt":1646328841627,"mc":[{"id":"1.195532877","rc":[{"atb":[[2.14,35.09]],"id":39236417}],"con":true,"img":false}]}
{"op":"mcm","clk":"5323232414","pt":1646328841685,"mc":[{"id":"1.195532877","rc":[{"atb":[[2.2,1.99]],"id":39236417}],"con":true,"img":false}]}
{"op":"mcm","clk":"5323232437","pt":1646328841896,"mc":[{"id":"1.195532877","rc":[{"atb":[[1.73,0]],"id":38519823},{"atb":[[2.14,0],[2.16,34.48]],"id":39236417}],"con":true,"img":false}]}
{"op":"mcm","clk":"5323232447","pt":1646328841996,"mc":[{"id":"1.195532877","rc":[{"atb":[[1.72,1.99]],"id":38519823}],"con":true,"img":false}]}
{"op":"mcm","clk":"5323232474","pt":1646328842206,"mc":[{"id":"1.195532877","rc":[{"atb":[[2.38,0]],"id":43094641}],"con":true,"img":false}]}
{"op":"mcm","clk":"5323232490","pt":1646328842312,"mc":[{"id":"1.195532877","rc":[{"atb":[[2.36,1.99]],"id":43094641}],"con":true,"img":false}]}
{"op":"mcm","clk":"5323232511","pt":1646328842515,"mc":[{"id":"1.195532877","rc":[{"atb":[[1.57,0],[1.7,57.14],[1.71,0]],"id":38519823}],"con":true,"img":false}]}
{"op":"mcm","clk":"5323232523","pt":1646328842623,"mc":[{"id":"1.195532877","rc":[{"atb":[[1.7,64.18]],"id":38519823}],"con":true,"img":false}]}
{"op":"mcm","clk":"5323232541","pt":1646328842727,"mc":[{"id":"1.195532877","rc":[{"atb":[[2.1,90.91]],"id":41696085}],"con":true,"img":false}]}
{"op":"mcm","clk":"5323232553","pt":1646328842833,"mc":[{"id":"1.195532877","rc":[{"atb":[[1.7,57.14]],"id":38519823}],"con":true,"img":false}]}
{"op":"mcm","clk":"5323232592","pt":1646328843102,"mc":[{"id":"1.195532877","rc":[{"atb":[[1.72,0]],"id":38519823}],"con":true,"img":false}]}
{"op":"mcm","clk":"5323232603","pt":1646328843220,"mc":[{"id":"1.195532877","rc":[{"atb":[[1.71,1.99]],"id":38519823}],"con":true,"img":false}]}
{"op":"mcm","clk":"5323232646","pt":1646328843514,"mc":[{"id":"1.195532877","rc":[{"atb":[[2.18,127.12]],"id":43094641}],"con":true,"img":false}]}
{"op":"mcm","clk":"5323232793","pt":1646328844717,"mc":[{"id":"1.195532877","rc":[{"atb":[[1.91,0]],"id":43094641},{"atb":[[1.7,0],[1.69,57.97]],"id":38519823}],"con":true,"img":false}]}
{"op":"mcm","clk":"5323232942","pt":1646328845818,"mc":[{"id":"1.195532877","rc":[{"atb":[[1.71,0]],"id":38519823}],"con":true,"img":false}]}
{"op":"mcm","clk":"5323232952","pt":1646328845921,"mc":[{"id":"1.195532877","rc":[{"atb":[[2.4,0]],"id":43094641},{"atb":[[2.18,4.32]],"id":41696085},{"atb":[[1.7,1.99]],"id":38519823},{"atb":[[2.18,3.97]],"id":39236417}],"con":true,"img":false}]}
{"op":"mcm","clk":"5323232965","pt":1646328846024,"mc":[{"id":"1.195532877","rc":[{"atb":[[2.42,3.31]],"id":43094641},{"atb":[[1.73,3.97]],"id":38519823},{"atb":[[2.18,0]],"id":39236417}],"con":true,"img":false}]}
{"op":"mcm","clk":"5323232993","pt":1646328846126,"mc":[{"id":"1.195532877","rc":[{"atb":[[2.38,1.65]],"id":43094641},{"atb":[[2.22,1.65]],"id":41696085},{"atb":[[2.22,1.65]],"id":39236417}],"con":true,"img":false}]}
{"op":"mcm","clk":"5323233011","pt":1646328846336,"mc":[{"id":"1.195532877","rc":[{"atb":[[2.22,3.81],[2.18,0]],"id":41696085},{"atb":[[2.2,0]],"id":39236417}],"con":true,"img":false}]}
{"op":"mcm","clk":"5323233021","pt":1646328846396,"mc":[{"id":"1.195532877","rc":[{"atb":[[2.18,1.99]],"id":39236417}],"con":true,"img":false}]}
{"op":"mcm","clk":"5323233044","pt":1646328846650,"mc":[{"id":"1.195532877","rc":[{"atb":[[1.7,0]],"id":38519823}],"con":true,"img":false}]}
{"op":"mcm","clk":"5323233054","pt":1646328846700,"mc":[{"id":"1.195532877","rc":[{"atb":[[1.74,1.99]],"id":38519823}],"con":true,"img":false}]}
{"op":"mcm","clk":"5323233080","pt":1646328847337,"mc":[{"id":"1.195532877","rc":[{"atb":[[2.36,0]],"id":43094641}],"con":true,"img":false}]}
{"op":"mcm","clk":"5323233094","pt":1646328847350,"mc":[{"id":"1.195532877","rc":[{"atb":[[2.44,1.99]],"id":43094641}],"con":true,"img":false}]}
{"op":"mcm","clk":"5323233193","pt":1646328848005,"mc":[{"id":"1.195532877","rc":[{"atb":[[2.18,33.9],[2.16,0]],"id":41696085},{"atb":[[1.72,55.56],[1.69,0]],"id":38519823},{"atb":[[2.18,35.89],[2.16,0]],"id":39236417}],"con":true,"img":false}]}
{"op":"mcm","clk":"5323233255","pt":1646328848525,"mc":[{"id":"1.195532877","rc":[{"atb":[[2.22,8.13]],"id":41696085}],"con":true,"img":false}]}
{"op":"mcm","clk":"5323233333","pt":1646328849318,"mc":[{"id":"1.195532877","rc":[{"atb":[[1.66,5.95]],"id":38519823}],"con":true,"img":false}]}
{"op":"mcm","clk":"5323233620","pt":1646328851501,"mc":[{"id":"1.195532877","rc":[{"atb":[[2.42,0]],"id":43094641},{"atb":[[1.73,0]],"id":38519823},{"atb":[[2,8.28]],"id":39236417}],"con":true,"img":false}]}
{"op":"mcm","clk":"5323233702","pt":1646328852123,"mc":[{"id":"1.195532877","rc":[{"atb":[[1.74,0]],"id":38519823}],"con":true,"img":false}]}
{"op":"mcm","clk":"5323233718","pt":1646328852223,"mc":[{"id":"1.195532877","rc":[{"atb":[[1.73,1.99]],"id":38519823}],"con":true,"img":false}]}
{"op":"mcm","clk":"5323233739","pt":1646328852430,"mc":[{"id":"1.195532877","rc":[{"atb":[[2.44,0]],"id":43094641}],"con":true,"img":false}]}
{"op":"mcm","clk":"5323233754","pt":1646328852591,"mc":[{"id":"1.195532877","rc":[{"atb":[[2.4,1.99]],"id":43094641}],"con":true,"img":false}]}
{"op":"mcm","clk":"5323233962","pt":1646328854420,"mc":[{"id":"1.195532877","rc":[{"atb":[[2.14,219.3]],"id":43094641}],"con":true,"img":false}]}
{"op":"mcm","clk":"5323234017","pt":1646328854933,"mc":[{"id":"1.195532877","rc":[{"atb":[[2.38,0]],"id":43094641},{"atb":[[2.22,0]],"id":39236417}],"con":true,"img":false}]}
{"op":"mcm","clk":"5323234033","pt":1646328855090,"mc":[{"id":"1.195532877","rc":[{"atb":[[2.42,1.65]],"id":43094641},{"atb":[[2.2,1.65]],"id":39236417}],"con":true,"img":false}]}
{"op":"mcm","clk":"5323234067","pt":1646328855408,"mc":[{"id":"1.195532877","rc":[{"atb":[[2.4,0]],"id":43094641}],"con":true,"img":false}]}
{"op":"mcm","clk":"5323234075","pt":1646328855510,"mc":[{"id":"1.195532877","rc":[{"atb":[[2.36,1.99]],"id":43094641}],"con":true,"img":false}]}
{"op":"mcm","clk":"5323234137","pt":1646328856084,"mc":[{"id":"1.195532877","rc":[{"atb":[[1.08,50]],"id":43094641},{"atb":[[1.08,50]],"id":41696085},{"atb":[[1.08,50]],"id":43189004},{"atb":[[1.08,50]],"id":42327927},{"atb":[[1.08,50]],"id":38519823},{"atb":[[1.08,50]],"id":39236417}],"con":true,"img":false}]}
{"op":"mcm","clk":"5323234148","pt":1646328856293,"mc":[{"id":"1.195532877","rc":[{"atb":[[1.99,0]],"id":39236417}],"con":true,"img":false}]}
{"op":"mcm","clk":"5323234215","pt":1646328856915,"mc":[{"id":"1.195532877","rc":[{"atb":[[2.42,5.63]],"id":43094641},{"atb":[[1.69,6.45]],"id":38519823}],"con":true,"img":false}]}
{"op":"mcm","clk":"5323234342","pt":1646328858015,"mc":[{"id":"1.195532877","rc":[{"atb":[[2.36,0]],"id":43094641}],"con":true,"img":false}]}
{"op":"mcm","clk":"5323234356","pt":1646328858078,"mc":[{"id":"1.195532877","rc":[{"atb":[[2.44,1.99]],"id":43094641}],"con":true,"img":false}]}
{"op":"mcm","clk":"5323234451","pt":1646328858911,"mc":[{"id":"1.195532877","rc":[{"atb":[[2.14,87.72]],"id":41696085},{"atb":[[1.72,0],[1.71,56.34]],"id":38519823},{"atb":[[2.18,1.99],[2.16,34.48]],"id":39236417}],"con":true,"img":false}]}
{"op":"mcm","clk":"5323234465","pt":1646328859029,"mc":[{"id":"1.195532877","rc":[{"atb":[[2,0]],"id":39236417}],"con":true,"img":false}]}
{"op":"mcm","clk":"5323234499","pt":1646328859225,"mc":[{"id":"1.195532877","rc":[{"atb":[[2.08,3.51]],"id":42327927}],"con":true,"img":false}]}
{"op":"mcm","clk":"5323234510","pt":1646328859326,"mc":[{"id":"1.195532877","rc":[{"atb":[[1.73,0]],"id":38519823}],"con":true,"img":false}]}
{"op":"mcm","clk":"5323234527","pt":1646328859433,"mc":[{"id":"1.195532877","rc":[{"atb":[[2.08,0]],"id":42327927},{"atb":[[1.72,1.99]],"id":38519823}],"con":true,"img":false}]}
{"op":"mcm","clk":"5323234689","pt":1646328860580,"mc":[{"id":"1.195532877","rc":[{"atb":[[1.93,0]],"id":43094641},{"atb":[[1.01,4804.04]],"id":41696085},{"atb":[[1.7,57.14],[1.71,0]],"id":38519823}],"con":true,"img":false}]}
{"op":"mcm","clk":"5323234723","pt":1646328860893,"mc":[{"id":"1.195532877","rc":[{"atb":[[1.72,0]],"id":38519823}],"con":true,"img":false}]}
{"op":"mcm","clk":"5323234733","pt":1646328860997,"mc":[{"id":"1.195532877","rc":[{"atb":[[1.71,1.99]],"id":38519823}],"con":true,"img":false}]}
{"op":"mcm","clk":"5323234778","pt":1646328861316,"mc":[{"id":"1.195532877","rc":[{"atb":[[1.7,0],[1.69,64.42]],"id":38519823}],"con":true,"img":false}]}
{"op":"mcm","clk":"5323234793","pt":1646328861418,"mc":[{"id":"1.195532877","rc":[{"atb":[[1.66,0]],"id":38519823}],"con":true,"img":false}]}
{"op":"mcm","clk":"5323234808","pt":1646328861520,"mc":[{"id":"1.195532877","rc":[{"atb":[[2.42,1.65]],"id":43094641},{"atb":[[2.02,35.86]],"id":39236417}],"con":true,"img":false}]}
{"op":"mcm","clk":"5323234829","pt":1646328861679,"mc":[{"id":"1.195532877","rc":[{"atb":[[1.88,7.26]],"id":39236417}],"con":true,"img":false}]}
{"op":"mcm","clk":"5323234858","pt":1646328861887,"mc":[{"id":"1.195532877","rc":[{"atb":[[1.71,0]],"id":38519823}],"con":true,"img":false}]}
{"op":"mcm","clk":"5323234873","pt":1646328862000,"mc":[{"id":"1.195532877","rc":[{"atb":[[1.7,1.99]],"id":38519823},{"atb":[[1.88,0]],"id":39236417}],"con":true,"img":false}]}
{"op":"mcm","clk":"5323234900","pt":1646328862201,"mc":[{"id":"1.195532877","rc":[{"atb":[[1.97,0],[2.22,2.15]],"id":39236417}],"con":true,"img":false}]}
{"op":"mcm","clk":"5323234924","pt":1646328862409,"mc":[{"id":"1.195532877","rc":[{"atb":[[2.14,5.2]],"id":39236417}],"con":true,"img":false}]}
{"op":"mcm","clk":"5323234942","pt":1646328862617,"mc":[{"id":"1.195532877","rc":[{"atb":[[2.14,0]],"id":39236417}],"con":true,"img":false}]}
{"op":"mcm","clk":"5323234967","pt":1646328862772,"mc":[{"id":"1.195532877","rc":[{"atb":[[2.18,0]],"id":39236417}],"con":true,"img":false}]}
{"op":"mcm","clk":"5323234976","pt":1646328862876,"mc":[{"id":"1.195532877","rc":[{"atb":[[2.24,1.99]],"id":39236417}],"con":true,"img":false}]}
{"op":"mcm","clk":"5323235001","pt":1646328863085,"mc":[{"id":"1.195532877","rc":[{"atb":[[1.68,60.97]],"id":38519823},{"atb":[[2.2,34.98]],"id":39236417}],"con":true,"img":false}]}
{"op":"mcm","clk":"5323235015","pt":1646328863188,"mc":[{"id":"1.195532877","rc":[{"atb":[[1.69,6.45]],"id":38519823},{"atb":[[2.16,0]],"id":39236417}],"con":true,"img":false}]}
{"op":"mcm","clk":"5323235093","pt":1646328863811,"mc":[{"id":"1.195532877","rc":[{"atb":[[2.42,0]],"id":43094641},{"atb":[[2.2,33.33]],"id":39236417}],"con":true,"img":false}]}
{"op":"mcm","clk":"5323235118","pt":1646328864017,"mc":[{"id":"1.195532877","rc":[{"atb":[[2.46,1.65]],"id":43094641},{"atb":[[2.26,1.65]],"id":39236417}],"con":true,"img":false}]}
{"op":"mcm","clk":"5323235146","pt":1646328864175,"mc":[{"id":"1.195532877","rc":[{"atb":[[2.22,5.46]],"id":39236417}],"con":true,"img":false}]}
{"op":"mcm","clk":"5323235159","pt":1646328864285,"mc":[{"id":"1.195532877","rc":[{"atb":[[1.57,64.18]],"id":38519823}],"con":true,"img":false}]}
{"op":"mcm","clk":"5323235208","pt":1646328864703,"mc":[{"id":"1.195532877","rc":[{"atb":[[2.22,38.25],[2.2,0]],"id":39236417}],"con":true,"img":false}]}
{"op":"mcm","clk":"5323235436","pt":1646328866724,"mc":[{"id":"1.195532877","rc":[{"atb":[[2.02,0]],"id":39236417}],"con":true,"img":false}]}
{"op":"mcm","clk":"5323235459","pt":1646328866876,"mc":[{"id":"1.195532877","rc":[{"atb":[[2.36,5.8]],"id":43094641},{"spn":10.48,"spf":"NaN","id":43094641},{"spn":19.11,"spf":"NaN","id":41696085},{"spn":8.11,"spf":"NaN","id":42327927},{"spn":1.69,"spf":1.0,"id":38519823},{"spn":6.38,"spf":"NaN","id":39236417}],"con":true,"img":false}]}
{"op":"mcm","clk":"5323235723","pt":1646328869213,"mc":[{"id":"1.195532877","rc":[{"atb":[[1.57,0]],"id":38519823}],"con":true,"img":false}]}
{"op":"mcm","clk":"5323235733","pt":1646328869321,"mc":[{"id":"1.195532877","rc":[{"atb":[[2.44,0]],"id":43094641},{"atb":[[2.22,34.94]],"id":39236417}],"con":true,"img":false}]}
{"op":"mcm","clk":"5323235748","pt":1646328869371,"mc":[{"id":"1.195532877","rc":[{"atb":[[2.36,7.79]],"id":43094641}],"con":true,"img":false}]}
{"op":"mcm","clk":"5323235774","pt":1646328869580,"mc":[{"id":"1.195532877","rc":[{"atb":[[2.1,136.36]],"id":41696085}],"con":true,"img":false}]}
{"op":"mcm","clk":"5323236113","pt":1646328872190,"mc":[{"id":"1.195532877","rc":[{"atb":[[2.24,2.55]],"id":42327927}],"con":true,"img":false}]}
{"op":"mcm","clk":"5323236138","pt":1646328872400,"mc":[{"id":"1.195532877","rc":[{"atb":[[2.14,40.07]],"id":42327927}],"con":true,"img":false}]}
{"op":"mcm","clk":"5323236163","pt":1646328872607,"mc":[{"id":"1.195532877","rc":[{"atb":[[2.22,1.65]],"id":42327927}],"con":true,"img":false}]}
{"op":"mcm","clk":"5323236178","pt":1646328872718,"mc":[{"id":"1.195532877","rc":[{"atb":[[2.26,1.99]],"id":42327927}],"con":true,"img":false}]}
{"op":"mcm","clk":"5323236205","pt":1646328872916,"mc":[{"id":"1.195532877","rc":[{"atb":[[2.46,0]],"id":43094641},{"atb":[[2.22,0]],"id":42327927}],"con":true,"img":false}]}
{"op":"mcm","clk":"5323236214","pt":1646328873023,"mc":[{"id":"1.195532877","rc":[{"atb":[[2.38,1.65]],"id":43094641},{"atb":[[2.26,3.64],[2.14,35.09]],"id":42327927}],"con":true,"img":false}]}
{"op":"mcm","clk":"5323236288","pt":1646328873805,"mc":[{"id":"1.195532877","rc":[{"atb":[[1.55,15.01],[1.66,151.52]],"id":38519823}],"con":true,"img":false}]}
{"op":"mcm","clk":"5323236312","pt":1646328874013,"mc":[{"id":"1.195532877","rc":[{"atb":[[1.55,0]],"id":38519823}],"con":true,"img":false}]}
{"op":"mcm","clk":"5323236326","pt":1646328874116,"mc":[{"id":"1.195532877","rc":[{"atb":[[1.52,0]],"id":38519823}],"con":true,"img":false}]}
{"op":"mcm","clk":"5323236366","pt":1646328874378,"mc":[{"id":"1.195532877","rc":[{"atb":[[2.28,3.31]],"id":39236417}],"con":true,"img":false}]}
{"op":"mcm","clk":"5323236460","pt":1646328875213,"mc":[{"id":"1.195532877","rc":[{"atb":[[1.66,160.8]],"id":38519823}],"con":true,"img":false}]}
{"op":"mcm","clk":"5323236473","pt":1646328875318,"mc":[{"id":"1.195532877","rc":[{"atb":[[2.24,32.26],[2.22,2.15]],"id":39236417}],"con":true,"img":false}]}
{"op":"mcm","clk":"5323236488","pt":1646328875423,"mc":[{"id":"1.195532877","rc":[{"atb":[[2.3,1.99]],"id":39236417}],"con":true,"img":false}]}
{"op":"mcm","clk":"5323236520","pt":1646328875682,"mc":[{"id":"1.195532877","rc":[{"atb":[[2.24,0],[2.26,33.4]],"id":39236417}],"con":true,"img":false}]}
{"op":"mcm","clk":"5323236561","pt":1646328876104,"mc":[{"id":"1.195532877","rc":[{"atb":[[2.4,2.5],[2.32,5],[2.38,7.05],[2.28,6.85]],"id":43094641},{"atl":[[16,2.16],[18.5,0],[18,3.24],[21,15.96],[7.4,10],[6.6,5],[5.9,2.5]],"id":43094641},{"atb":[[2.72,2.5],[2.64,5],[2.56,10],[2.24,3.37],[2.18,39.51]],"id":41696085},{"atl":[[34,2.42],[36,0],[44,9.96],[6.8,2.5],[7.6,5],[26,2],[8.4,10]],"id":41696085},{"atb":[[1.96,4.15],[1.95,17.26],[1.99,5],[2.06,2.5],[1.91,11]],"id":43189004},{"atl":[[9,5.11],[9.2,0],[10,28.71],[4.6,2.5],[5,5],[8.2,4.65],[5.4,10]],"id":43189004},{"atb":[[2.24,5.05],[2.28,2.56],[2.26,7.7],[2.2,8.93],[2.16,15.95],[2.1,90.91]],"id":42327927},{"atl":[[16,17.51],[5,2.5],[5.8,10],[12,2.86],[13.5,4.06],[14,0],[5.4,5]],"id":42327927},{"atb":[[2.04,10],[1.7,17.45],[2.12,5],[2.2,2.5],[1.66,187.8],[1.65,0]],"id":38519823},{"atl":[[4.8,2.5],[5.6,10],[8.6,65.42],[7.6,9.01],[5.2,5],[7.8,0]],"id":38519823},{"atb":[[1.98,0],[2.22,16.04],[2.28,8.65],[2.12,89.29]],"id":39236417},{"atl":[[7.2,10],[6.4,5],[5.8,2.5],[10,5.34],[10.5,0],[12.5,26.92],[9.8,3.81]],"id":39236417}],"con":true,"img":false}]}
{"op":"mcm","clk":"5323236573","pt":1646328876210,"mc":[{"id":"1.195532877","rc":[{"atb":[[2.24,5.4]],"id":43094641},{"atb":[[2.3,5.61]],"id":41696085},{"atb":[[1.86,8.51]],"id":43189004}],"con":true,"img":false}]}
{"op":"mcm","clk":"5323236582","pt":1646328876312,"mc":[{"id":"1.195532877","rc":[{"atl":[[19.5,0],[6.2,7.69]],"id":43094641},{"atb":[[2.72,7.5],[2.5,26.67],[2.22,5.97],[2.18,5.61]],"id":41696085},{"atl":[[7.2,6.45],[40,0]],"id":41696085},{"atl":[[5.2,9.52],[15,0]],"id":42327927},{"atb":[[1.66,160.8]],"id":38519823},{"atl":[[7.2,17.5],[11.5,0],[6,8],[9.8,0]],"id":39236417}],"con":true,"img":false}]}
{"op":"mcm","clk":"5323236594","pt":1646328876415,"mc":[{"id":"1.195532877","rc":[{"atl":[[5.9,4.5]],"id":43094641},{"atl":[[5,7.24]],"id":42327927},{"atl":[[6.2,8.7]],"id":39236417}],"con":true,"img":false}]}
{"op":"mcm","clk":"5323236604","pt":1646328876520,"mc":[{"id":"1.195532877","rc":[{"atb":[[2.24,0]],"id":43094641},{"atb":[[1.86,0]],"id":43189004}],"con":true,"img":false}]}
{"op":"mcm","clk":"5323236618","pt":1646328876627,"mc":[{"id":"1.195532877","rc":[{"atb":[[2.3,0]],"id":41696085},{"atl":[[9.6,0],[4.8,10.53]],"id":43189004},{"atb":[[2.26,5.71]],"id":42327927}],"con":true,"img":false}]}
{"op":"mcm","clk":"5323236631","pt":1646328876680,"mc":[{"id":"1.195532877","rc":[{"atb":[[2.3,1.99]],"id":42327927}],"con":true,"img":false}]}
{"op":"mcm","clk":"5323236640","pt":1646328876841,"mc":[{"id":"1.195532877","rc":[{"atb":[[2.16,5]],"id":42327927},{"atl":[[6.2,0]],"id":39236417}],"con":true,"img":false}]}
{"op":"mcm","clk":"5323236654","pt":1646328876892,"mc":[{"id":"1.195532877","rc":[{"atb":[[2.34,0],[2.42,2.15]],"id":43094641},{"atb":[[1.95,15.11],[1.99,7.15]],"id":43189004},{"atb":[[2.3,4.14],[2.2,6.78]],"id":42327927},{"atb":[[1.79,50.63],[1.68,2.15]],"id":38519823},{"atl":[[5,10],[8.2,0]],"id":38519823},{"atb":[[2.22,13.89],[2.34,2.15]],"id":39236417}],"con":true,"img":false}]}
{"op":"mcm","clk":"5323236667","pt":1646328877000,"mc":[{"id":"1.195532877","rc":[{"atl":[[5.9,2.5]],"id":43094641}],"con":true,"img":false}]}
{"op":"mcm","clk":"5323236680","pt":1646328877103,"mc":[{"id":"1.195532877","rc":[{"atb":[[1.7,15.46]],"id":38519823}],"con":true,"img":false}]}
{"op":"mcm","clk":"5323236691","pt":1646328877212,"mc":[{"id":"1.195532877","rc":[{"atb":[[2.22,1.99]],"id":38519823}],"con":true,"img":false}]}
{"op":"mcm","clk":"5323236743","pt":1646328877627,"mc":[{"id":"1.195532877","rc":[{"atb":[[2.24,2.5]],"id":42327927}],"con":true,"img":false}]}
{"op":"mcm","clk":"5323236805","pt":1646328878091,"mc":[{"id":"1.195532877","rc":[{"atl":[[5.7,4.66]],"id":43094641}],"con":true,"img":false}]}
{"op":"mcm","clk":"5323236894","pt":1646328878925,"mc":[{"id":"1.195532877","rc":[{"atl":[[6.2,0],[5.9,10.66]],"id":43094641}],"con":true,"img":false}]}
{"op":"mcm","clk":"5323236949","pt":1646328879496,"mc":[{"id":"1.195532877","rc":[{"atb":[[2.36,1.99]],"id":43094641},{"atb":[[2.22,1.65]],"id":41696085},{"atb":[[1.92,0]],"id":43189004},{"atb":[[1.69,0]],"id":38519823},{"atb":[[2.28,5.34]],"id":39236417}],"con":true,"img":false}]}
{"op":"mcm","clk":"5323236997","pt":1646328880017,"mc":[{"id":"1.195532877","rc":[{"atb":[[1.88,0]],"id":43189004},{"atb":[[1.66,151.52]],"id":38519823}],"con":true,"img":false}]}
{"op":"mcm","clk":"5323237180","pt":1646328881422,"mc":[{"id":"1.195532877","rc":[{"atb":[[2.72,2.5],[2.56,22.5]],"id":41696085}],"con":true,"img":false}]}
{"op":"mcm","clk":"5323237234","pt":1646328881791,"mc":[{"id":"1.195532877","rc":[{"atb":[[2.38,5.4]],"id":43094641},{"atb":[[2.22,0]],"id":41696085},{"atb":[[2.26,4.06]],"id":42327927},{"atb":[[2.26,31.75]],"id":39236417}],"con":true,"img":false}]}
{"op":"mcm","clk":"5323237246","pt":1646328881896,"mc":[{"id":"1.195532877","rc":[{"atb":[[2.44,1.65]],"id":43094641},{"atb":[[2.74,1.65]],"id":41696085},{"atb":[[2.08,1.65]],"id":43189004},{"atb":[[2.32,1.65]],"id":42327927},{"atb":[[2.24,1.65]],"id":38519823},{"atb":[[2.36,1.65]],"id":39236417}],"con":true,"img":false}]}
{"op":"mcm","clk":"5323237267","pt":1646328882104,"mc":[{"id":"1.195532877","rc":[{"atb":[[2.54,5]],"id":41696085},{"atb":[[2.32,9.94]],"id":42327927}],"con":true,"img":false}]}
{"op":"mcm","clk":"5323237313","pt":1646328882519,"mc":[{"id":"1.195532877","rc":[{"atb":[[2.54,0]],"id":41696085},{"atl":[[6,11.93]],"id":39236417}],"con":true,"img":false}]}
{"op":"mcm","clk":"5323237324","pt":1646328882621,"mc":[{"id":"1.195532877","rc":[{"atb":[[2.32,12.84]],"id":42327927}],"con":true,"img":false}]}
{"op":"mcm","clk":"5323237361","pt":1646328883042,"mc":[{"id":"1.195532877","rc":[{"atb":[[2.44,3.81],[2.38,3.24]],"id":43094641},{"atl":[[16,0],[5.6,5]],"id":43094641},{"atl":[[7.6,13.95],[26,0]],"id":41696085},{"atb":[[1.96,1.99],[2.08,4.15]],"id":43189004},{"atl":[[5,18.03],[8.2,0]],"id":43189004},{"atb":[[2.34,4.15],[2.28,0]],"id":42327927},{"atl":[[12,0],[4.9,7.24]],"id":42327927},{"atb":[[1.7,9.01],[1.77,15.46]],"id":38519823},{"atl":[[8.6,52.26],[5.2,17.5]],"id":38519823},{"atb":[[2.12,0],[2.24,80.65]],"id":39236417}],"con":true,"img":false}]}
{"op":"mcm","clk":"5323237373","pt":1646328883093,"mc":[{"id":"1.195532877","rc":[{"atl":[[7.2,10],[5.9,11.93]],"id":39236417}],"con":true,"img":false}]}
{"op":"mcm","clk":"5323237385","pt":1646328883198,"mc":[{"id":"1.195532877","rc":[{"atl":[[5.8,8.33],[5.9,2.5]],"id":43094641},{"atl":[[5.1,9.76],[5.2,0]],"id":42327927}],"con":true,"img":false}]}
{"op":"mcm","clk":"5323237405","pt":1646328883411,"mc":[{"id":"1.195532877","rc":[{"atl":[[6,8]],"id":39236417}],"con":true,"img":false}]}
{"op":"mcm","clk":"5323237418","pt":1646328883513,"mc":[{"id":"1.195532877","rc":[{"atl":[[6,22.43],[5.9,0]],"id":39236417}],"con":true,"img":false}]}
{"op":"mcm","clk":"5323237431","pt":1646328883615,"mc":[{"id":"1.195532877","rc":[{"atl":[[5.7,0]],"id":43094641}],"con":true,"img":false}]}
{"op":"mcm","clk":"5323237440","pt":1646328883722,"mc":[{"id":"1.195532877","rc":[{"atl":[[5.6,0],[5.9,15.83]],"id":43094641},{"atl":[[6.4,23.52],[6,8]],"id":39236417}],"con":true,"img":false}]}
{"op":"mcm","clk":"5323237461","pt":1646328883937,"mc":[{"id":"1.195532877","rc":[{"atl":[[6,11.39]],"id":39236417}],"con":true,"img":false}]}
{"op":"mcm","clk":"5323237475","pt":1646328884035,"mc":[{"id":"1.195532877","rc":[{"atl":[[5.8,0],[6,8]],"id":43094641}],"con":true,"img":false}]}
{"op":"mcm","clk":"5323237485","pt":1646328884137,"mc":[{"id":"1.195532877","rc":[{"atl":[[6.4,5],[5.9,11.39]],"id":39236417}],"con":true,"img":false}]}
{"op":"mcm","clk":"5323237501","pt":1646328884240,"mc":[{"id":"1.195532877","rc":[{"atl":[[6.6,22.86],[5.9,2.5]],"id":43094641}],"con":true,"img":false}]}
{"op":"mcm","clk":"5323237510","pt":1646328884325,"mc":[{"id":"1.195532877","rc":[{"atl":[[5.5,2]],"id":43094641}],"con":true,"img":false}]}
{"op":"mcm","clk":"5323237524","pt":1646328884430,"mc":[{"id":"1.195532877","rc":[{"atl":[[6.2,7.69],[6,0]],"id":43094641}],"con":true,"img":false}]}
{"op":"mcm","clk":"5323237535","pt":1646328884535,"mc":[{"id":"1.195532877","rc":[{"atl":[[5.7,8.51]],"id":43094641}],"con":true,"img":false}]}
{"op":"mcm","clk":"5323237545","pt":1646328884644,"mc":[{"id":"1.195532877","rc":[{"atl":[[5,2.5]],"id":42327927}],"con":true,"img":false}]}
{"op":"mcm","clk":"5323237559","pt":1646328884692,"mc":[{"id":"1.195532877","rc":[{"atl":[[25,0]],"id":43094641}],"con":true,"img":false}]}
{"op":"mcm","clk":"5323237568","pt":1646328884794,"mc":[{"id":"1.195532877","rc":[{"atl":[[5.5,0]],"id":43094641},{"atl":[[5.1,19.52],[4.9,0]],"id":42327927}],"con":true,"img":false}]}
{"op":"mcm","clk":"5323237604","pt":1646328885110,"mc":[{"id":"1.195532877","rc":[{"atl":[[5.5,2.79]],"id":43094641}],"con":true,"img":false}]}
{"op":"mcm","clk":"5323237628","pt":1646328885319,"mc":[{"id":"1.195532877","rc":[{"atl":[[5.1,9.76],[5.2,9.52]],"id":42327927}],"con":true,"img":false}]}
{"op":"mcm","clk":"5323237638","pt":1646328885429,"mc":[{"id":"1.195532877","rc":[{"atl":[[5.5,0]],"id":43094641},{"atl":[[5.2,21.78]],"id":42327927}],"con":true,"img":false}]}
{"op":"mcm","clk":"5323237650","pt":1646328885534,"mc":[{"id":"1.195532877","rc":[{"atl":[[5.1,0]],"id":42327927}],"con":true,"img":false}]}
{"op":"mcm","clk":"5323237668","pt":1646328885635,"mc":[{"id":"1.195532877","rc":[{"atl":[[5.7,0],[5.9,10.66]],"id":43094641}],"con":true,"img":false}]}
{"op":"mcm","clk":"5323237677","pt":1646328885691,"mc":[{"id":"1.195532877","rc":[{"atl":[[5.2,9.52],[5.4,27.73],[4.7,4.41]],"id":42327927}],"con":true,"img":false}]}
{"op":"mcm","clk":"5323237690","pt":1646328885799,"mc":[{"id":"1.195532877","rc":[{"atl":[[5.9,2.5]],"id":43094641},{"atl":[[4.6,4.41]],"id":42327927}],"con":true,"img":false}]}
{"op":"mcm","clk":"5323237702","pt":1646328885899,"mc":[{"id":"1.195532877","rc":[{"atl":[[5.4,5]],"id":42327927}],"con":true,"img":false}]}
{"op":"mcm","clk":"5323237713","pt":1646328886009,"mc":[{"id":"1.195532877","rc":[{"atl":[[4.8,10.53],[5.2,0]],"id":42327927},{"atb":[[2.24,0],[2.26,63.5]],"id":39236417}],"con":true,"img":false}]}
{"op":"mcm","clk":"5323237729","pt":1646328886116,"mc":[{"id":"1.195532877","rc":[{"atb":[[2.44,8.13]],"id":43094641},{"atl":[[5.9,4.5]],"id":43094641},{"atb":[[2.58,10.01]],"id":41696085},{"atb":[[1.97,15.2]],"id":43189004},{"atb":[[2.14,10.83]],"id":38519823},{"atb":[[2.36,5.97]],"id":39236417}],"con":true,"img":false}]}
{"op":"mcm","clk":"5323237804","pt":1646328886734,"mc":[{"id":"1.195532877","rc":[{"atb":[[2.46,68.49]],"id":41696085},{"atl":[[7.6,29.1]],"id":41696085},{"atb":[[2.22,95.86]],"id":39236417},{"atl":[[6.4,23.52]],"id":39236417}],"con":true,"img":false}]}
{"op":"mcm","clk":"5323237829","pt":1646328886893,"mc":[{"id":"1.195532877","rc":[{"atb":[[2.06,0]],"id":41696085},{"atl":[[44,7.63],[48,0],[55,0]],"id":41696085},{"atb":[[1.57,0]],"id":39236417},{"atl":[[12.5,18.22],[13.5,0],[14.5,0]],"id":39236417}],"con":true,"img":false}]}
{"op":"mcm","clk":"5323237841","pt":1646328887001,"mc":[{"id":"1.195532877","rc":[{"atl":[[5,43.03]],"id":43189004}],"con":true,"img":false}]}
{"op":"mcm","clk":"5323237864","pt":1646328887205,"mc":[{"id":"1.195532877","rc":[{"atb":[[1.77,145.33]],"id":38519823},{"atl":[[5.2,41.31]],"id":38519823}],"con":true,"img":false}]}
{"op":"mcm","clk":"5323237875","pt":1646328887305,"mc":[{"id":"1.195532877","rc":[{"atl":[[12,0]],"id":43189004}],"con":true,"img":false}]}
{"op":"mcm","clk":"5323237894","pt":1646328887512,"mc":[{"id":"1.195532877","rc":[{"atb":[[1.96,0]],"id":43189004}],"con":true,"img":false}]}
{"op":"mcm","clk":"5323237900","pt":1646328887616,"mc":[{"id":"1.195532877","rc":[{"atb":[[2.2,0]],"id":41696085},{"atb":[[2.08,6.14]],"id":43189004},{"atb":[[2.3,1.99]],"id":42327927}],"con":true,"img":false}]}
{"op":"mcm","clk":"5323237910","pt":1646328887722,"mc":[{"id":"1.195532877","rc":[{"atb":[[2.36,0]],"id":43094641},{"atb":[[2.64,7.15]],"id":41696085},{"atb":[[2.38,2.15]],"id":42327927}],"con":true,"img":false}]}
{"op":"mcm","clk":"5323237915","pt":1646328887823,"mc":[{"id":"1.195532877","rc":[{"atb":[[2.42,4.14]],"id":43094641}],"con":true,"img":false}]}
{"op":"mcm","clk":"5323237925","pt":1646328887931,"mc":[{"id":"1.195532877","rc":[{"atb":[[2.34,0],[2.38,6.3]],"id":42327927}],"con":true,"img":false}]}
{"op":"mcm","clk":"5323237937","pt":1646328888038,"mc":[{"id":"1.195532877","rc":[{"atb":[[2.34,4.32],[2.38,2.15]],"id":42327927}],"con":true,"img":false}]}
{"op":"mcm","clk":"5323237949","pt":1646328888148,"mc":[{"id":"1.195532877","rc":[{"atb":[[2.56,10],[2.74,4.15]],"id":41696085},{"atb":[[2.32,4.55]],"id":42327927}],"con":true,"img":false}]}
{"op":"mcm","clk":"5323238021","pt":1646328888727,"mc":[{"id":"1.195532877","rc":[{"atb":[[1.56,0],[1.54,0],[1.66,0]],"id":38519823},{"atl":[[8.6,39.1],[9,0],[9.4,0]],"id":38519823},{"atb":[[2.3,0]],"id":39236417}],"con":true,"img":false}]}
{"op":"mcm","clk":"5323238030","pt":1646328888824,"mc":[{"id":"1.195532877","rc":[{"atb":[[1.97,9.38]],"id":43189004},{"atb":[[2.32,1.65]],"id":42327927},{"atb":[[2.38,1.99]],"id":39236417}],"con":true,"img":false}]}
{"op":"mcm","clk":"5323238068","pt":1646328889135,"mc":[{"id":"1.195532877","rc":[{"atb":[[2.3,0]],"id":42327927}],"con":true,"img":false}]}
{"op":"mcm","clk":"5323238079","pt":1646328889242,"mc":[{"id":"1.195532877","rc":[{"atb":[[2.4,1.99]],"id":42327927}],"con":true,"img":false}]}
{"op":"mcm","clk":"5323238102","pt":1646328889447,"mc":[{"id":"1.195532877","rc":[{"atb":[[2.42,2.15]],"id":43094641}],"con":true,"img":false}]}
{"op":"mcm","clk":"5323238121","pt":1646328889556,"mc":[{"id":"1.195532877","rc":[{"atb":[[2.46,1.99]],"id":43094641}],"con":true,"img":false}]}
{"op":"mcm","clk":"5323238233","pt":1646328890651,"mc":[{"id":"1.195532877","rc":[{"atb":[[2.4,17.74],[2.46,11.13],[2.28,0]],"id":43094641},{"atl":[[5.8,9.14],[21,5],[6.6,47.24]],"id":43094641},{"atb":[[2.64,20.41],[2.74,12.11],[2.18,0]],"id":41696085},{"atl":[[44,0],[7.6,50.32],[6.6,7.96]],"id":41696085},{"atb":[[1.99,23.79],[1.91,0]],"id":43189004},{"atl":[[5,69.65],[10,11.1],[4.4,9.98]],"id":43189004},{"atb":[[2.26,15.08],[2.38,8.7],[2.2,0]],"id":42327927},{"atl":[[4.8,28.17],[16,6.67],[4.5,6.55]],"id":42327927},{"atl":[[8.6,0],[5.2,68.61],[4.7,3.75]],"id":38519823},{"atb":[[2.22,84.47],[2.38,8.35],[2.28,21.98]],"id":39236417},{"atl":[[6,38.01],[12.5,0],[5.7,6.36]],"id":39236417}],"con":true,"img":false}]}
{"op":"mcm","clk":"5323238248","pt":1646328890710,"mc":[{"id":"1.195532877","rc":[{"atb":[[2.08,16.12]],"id":43189004}],"con":true,"img":false}]}
{"op":"mcm","clk":"5323238261","pt":1646328890814,"mc":[{"id":"1.195532877","rc":[{"atb":[[2.38,0],[2.44,6.47]],"id":43094641},{"atl":[[18,0]],"id":43094641},{"atb":[[2.24,0]],"id":41696085},{"atl":[[7.2,16.45],[34,0],[7.6,41.37]],"id":41696085},{"atb":[[1.95,10]],"id":43189004},{"atl":[[4.8,21.06],[9,0],[5,56.62]],"id":43189004},{"atb":[[2.32,0],[2.26,11.02]],"id":42327927},{"atl":[[4.4,4.41],[4.6,0]],"id":42327927},{"atl":[[5,20],[7.6,0],[5.2,56.11]],"id":38519823},{"atb":[[2.36,4.31],[2.28,16.64]],"id":39236417},{"atl":[[10,0],[6,51.9],[5.9,0]],"id":39236417}],"con":true,"img":false}]}
{"op":"mcm","clk":"5323238274","pt":1646328890919,"mc":[{"id":"1.195532877","rc":[{"atl":[[6.6,29.38],[5.9,22.78]],"id":43094641},{"atb":[[2.14,38.16]],"id":42327927},{"atl":[[13.5,0]],"id":42327927}],"con":true,"img":false}]}
{"op":"mcm","clk":"5323238286","pt":1646328891031,"mc":[{"id":"1.195532877","rc":[{"atb":[[2.48,1.65]],"id":43094641},{"atl":[[6,8],[5.9,2.5]],"id":43094641},{"atb":[[2.58,0]],"id":41696085},{"atl":[[7,6.67]],"id":41696085},{"atb":[[1.97,0]],"id":43189004},{"atl":[[4.8,10.53],[4.6,13.61]],"id":43189004},{"atb":[[2.42,1.65]],"id":42327927},{"atl":[[4.8,17.64],[4.4,0],[4.6,22.07],[4.7,15.22]],"id":42327927},{"atb":[[2.14,4.37]],"id":38519823},{"atl":[[4.9,10.26]],"id":38519823},{"atb":[[2.4,1.65]],"id":39236417},{"atl":[[5.9,8.16]],"id":39236417}],"con":true,"img":false}]}
{"op":"mcm","clk":"5323238302","pt":1646328891131,"mc":[{"id":"1.195532877","rc":[{"atl":[[6.2,21.33]],"id":43094641},{"atb":[[2.14,35.09]],"id":42327927}],"con":true,"img":false}]}
{"op":"mcm","clk":"5323238313","pt":1646328891229,"mc":[{"id":"1.195532877","rc":[{"atl":[[7.2,6.45],[6.8,18.42]],"id":41696085},{"atl":[[4.8,12.76],[5,10]],"id":38519823}],"con":true,"img":false}]}
{"op":"mcm","clk":"5323238418","pt":1646328892121,"mc":[{"id":"1.195532877","rc":[{"atl":[[5.6,4.73]],"id":43094641}],"con":true,"img":false}]}
{"op":"mcm","clk":"5323238444","pt":1646328892320,"mc":[{"id":"1.195532877","rc":[{"atl":[[6.2,7.69],[5.5,4.73]],"id":43094641}],"con":true,"img":false}]}
{"op":"mcm","clk":"5323238477","pt":1646328892633,"mc":[{"id":"1.195532877","rc":[{"atl":[[6,0],[5.7,8.51]],"id":43094641},{"atl":[[16,0],[17,0],[18,0],[4.6,10.96]],"id":42327927}],"con":true,"img":false}]}
{"op":"mcm","clk":"5323238497","pt":1646328892841,"mc":[{"id":"1.195532877","rc":[{"atl":[[5.6,0]],"id":43094641}],"con":true,"img":false}]}
{"op":"mcm","clk":"5323238525","pt":1646328893105,"mc":[{"id":"1.195532877","rc":[{"atl":[[5.4,2]],"id":43094641},{"atl":[[5.7,18.36]],"id":39236417}],"con":true,"img":false}]}
{"op":"mcm","clk":"5323238535","pt":1646328893216,"mc":[{"id":"1.195532877","rc":[{"atb":[[2.32,6.31],[2.34,0]],"id":42327927}],"con":true,"img":false}]}
{"op":"mcm","clk":"5323238611","pt":1646328893832,"mc":[{"id":"1.195532877","rc":[{"atb":[[2.44,2.16]],"id":43094641},{"atb":[[2.42,5.63]],"id":42327927},{"atb":[[2.36,0]],"id":39236417}],"con":true,"img":false}]}
{"op":"mcm","clk":"5323238663","pt":1646328894199,"mc":[{"id":"1.195532877","rc":[{"atb":[[2.14,0]],"id":38519823}],"con":true,"img":false}]}
{"op":"mcm","clk":"5323238677","pt":1646328894356,"mc":[{"id":"1.195532877","rc":[{"atb":[[2,19.35]],"id":43189004},{"atb":[[2.3,12]],"id":39236417}],"con":true,"img":false}]}
{"op":"mcm","clk":"5323238702","pt":1646328894525,"mc":[{"id":"1.195532877","rc":[{"atl":[[5.7,0]],"id":43094641},{"atb":[[2.4,0]],"id":42327927}],"con":true,"img":false}]}
{"op":"mcm","clk":"5323238715","pt":1646328894629,"mc":[{"id":"1.195532877","rc":[{"atl":[[5.6,8.7]],"id":43094641},{"atb":[[2.44,1.99]],"id":42327927}],"con":true,"img":false}]}
{"op":"mcm","clk":"5323238737","pt":1646328894828,"mc":[{"id":"1.195532877","rc":[{"atl":[[4.7,10.81]],"id":42327927}],"con":true,"img":false}]}
{"op":"mcm","clk":"5323238756","pt":1646328895035,"mc":[{"id":"1.195532877","rc":[{"atl":[[4.6,0],[4.7,28.32]],"id":42327927}],"con":true,"img":false}]}
{"op":"mcm","clk":"5323238777","pt":1646328895242,"mc":[{"id":"1.195532877","rc":[{"atl":[[4.5,0]],"id":42327927}],"con":true,"img":false}]}
{"op":"mcm","clk":"5323238790","pt":1646328895367,"mc":[{"id":"1.195532877","rc":[{"atl":[[4.6,11.44]],"id":42327927}],"con":true,"img":false}]}
{"op":"mcm","clk":"5323238917","pt":1646328896344,"mc":[{"id":"1.195532877","rc":[{"atl":[[6.8,2.5],[7,23.34]],"id":41696085},{"atl":[[4.8,2.5],[4.9,26.77]],"id":38519823}],"con":true,"img":false}]}
{"op":"mcm","clk":"5323238929","pt":1646328896449,"mc":[{"id":"1.195532877","rc":[{"atb":[[2.42,7.15],[2.44,0]],"id":43094641},{"atl":[[4.8,28.17],[4.7,17.51]],"id":42327927}],"con":true,"img":false}]}
{"op":"mcm","clk":"5323238986","pt":1646328896922,"mc":[{"id":"1.195532877","rc":[{"atl":[[4.5,4.63]],"id":42327927}],"con":true,"img":false}]}
{"op":"mcm","clk":"5323238994","pt":1646328897023,"mc":[{"id":"1.195532877","rc":[{"atb":[[2.14,4.37]],"id":38519823}],"con":true,"img":false}]}
{"op":"mcm","clk":"5323239021","pt":1646328897217,"mc":[{"id":"1.195532877","rc":[{"atb":[[2.66,28.49]],"id":41696085},{"atb":[[2,66.65]],"id":43189004},{"atb":[[2.26,3.31]],"id":38519823}],"con":true,"img":false}]}
{"op":"mcm","clk":"5323239082","pt":1646328897842,"mc":[{"id":"1.195532877","rc":[{"atl":[[5.4,0]],"id":43094641},{"atl":[[4.7,28.32]],"id":42327927}],"con":true,"img":false}]}
{"op":"mcm","clk":"5323239097","pt":1646328897950,"mc":[{"id":"1.195532877","rc":[{"atb":[[2.22,0]],"id":38519823}],"con":true,"img":false}]}
{"op":"mcm","clk":"5323239107","pt":1646328898054,"mc":[{"id":"1.195532877","rc":[{"atl":[[5.8,22.57],[5.5,0]],"id":43094641},{"atb":[[2.28,1.99]],"id":38519823}],"con":true,"img":false}]}
{"op":"mcm","clk":"5323239121","pt":1646328898105,"mc":[{"id":"1.195532877","rc":[{"atl":[[5.2,2]],"id":43094641}],"con":true,"img":false}]}
{"op":"mcm","clk":"5323239138","pt":1646328898312,"mc":[{"id":"1.195532877","rc":[{"atb":[[2.42,5],[2.52,2.15]],"id":43094641},{"atb":[[1.99,21.64],[2.14,2.15]],"id":43189004},{"atb":[[2.44,2.15],[2.34,0]],"id":39236417}],"con":true,"img":false}]}
{"op":"mcm","clk":"5323239148","pt":1646328898421,"mc":[{"id":"1.195532877","rc":[{"atb":[[2.14,4.65],[2.08,13.62]],"id":43189004}],"con":true,"img":false}]}
{"op":"mcm","clk":"5323239159","pt":1646328898527,"mc":[{"id":"1.195532877","rc":[{"atb":[[2.4,20.82]],"id":43094641},{"atb":[[1.99,31.32]],"id":43189004}],"con":true,"img":false}]}
{"op":"mcm","clk":"5323239168","pt":1646328898634,"mc":[{"id":"1.195532877","rc":[{"atb":[[2.38,6.36]],"id":39236417}],"con":true,"img":false}]}
{"op":"mcm","clk":"5323239180","pt":1646328898730,"mc":[{"id":"1.195532877","rc":[{"atb":[[2.4,17.74]],"id":43094641},{"atb":[[1.99,21.64]],"id":43189004},{"atb":[[2.46,1.99]],"id":39236417}],"con":true,"img":false}]}
{"op":"mcm","clk":"5323239210","pt":1646328899041,"mc":[{"id":"1.195532877","rc":[{"atl":[[5.6,0],[5.4,9.09]],"id":43094641}],"con":true,"img":false}]}
{"op":"mcm","clk":"5323239220","pt":1646328899150,"mc":[{"id":"1.195532877","rc":[{"atb":[[2.08,11.63]],"id":43189004}],"con":true,"img":false}]}
{"op":"mcm","clk":"5323239230","pt":1646328899254,"mc":[{"id":"1.195532877","rc":[{"atb":[[2.16,1.99]],"id":43189004}],"con":true,"img":false}]}
{"op":"mcm","clk":"5323239322","pt":1646328899933,"mc":[{"id":"1.195532877","rc":[{"atb":[[2.48,0]],"id":43094641},{"atb":[[2.08,9.98]],"id":43189004},{"atb":[[2.42,3.97]],"id":42327927},{"atb":[[2.24,0]],"id":38519823},{"atb":[[2.4,0]],"id":39236417}],"con":true,"img":false}]}
{"op":"mcm","clk":"5323239348","pt":1646328900141,"mc":[{"id":"1.195532877","rc":[{"atb":[[2.54,1.65]],"id":43094641},{"atb":[[2.18,1.65]],"id":43189004},{"atb":[[2.46,1.65]],"id":42327927},{"atb":[[2.3,1.65]],"id":38519823},{"atb":[[2.48,1.65]],"id":39236417}],"con":true,"img":false}]}
{"op":"mcm","clk":"5323239364","pt":1646328900248,"mc":[{"id":"1.195532877","rc":[{"atb":[[2.42,0]],"id":42327927}],"con":true,"img":false}]}
{"op":"mcm","clk":"5323239379","pt":1646328900350,"mc":[{"id":"1.195532877","rc":[{"atb":[[2.5,3.31]],"id":43094641},{"atb":[[2.14,2.15],[2.16,6.65]],"id":43189004},{"atb":[[2.36,3.18],[2.42,3.31]],"id":39236417}],"con":true,"img":false}]}
{"op":"mcm","clk":"5323239392","pt":1646328900458,"mc":[{"id":"1.195532877","rc":[{"atb":[[2.22,90.29]],"id":39236417}],"con":true,"img":false}]}
{"op":"mcm","clk":"5323239409","pt":1646328900562,"mc":[{"id":"1.195532877","rc":[{"atb":[[2.36,0]],"id":39236417}],"con":true,"img":false}]}
{"op":"mcm","clk":"5323239424","pt":1646328900616,"mc":[{"id":"1.195532877","rc":[{"atb":[[2.22,84.47]],"id":39236417}],"con":true,"img":false}]}
{"op":"mcm","clk":"5323239488","pt":1646328901135,"mc":[{"id":"1.195532877","rc":[{"atb":[[2.42,105.63]],"id":41696085},{"atl":[[7.4,15.62]],"id":41696085},{"atl":[[4.8,36.85]],"id":43189004},{"atb":[[1.75,200]],"id":38519823},{"atl":[[5.1,24.39]],"id":38519823},{"atb":[[2.18,127.12]],"id":39236417},{"atl":[[6.2,19.23]],"id":39236417}],"con":true,"img":false}]}
{"op":"mcm","clk":"5323239548","pt":1646328901618,"mc":[{"id":"1.195532877","rc":[{"atl":[[4.4,11.44],[4.7,10.8]],"id":42327927}],"con":true,"img":false}]}
{"op":"mcm","clk":"5323239561","pt":1646328901724,"mc":[{"id":"1.195532877","rc":[{"atb":[[2.1,0]],"id":41696085},{"atl":[[11,0]],"id":43189004},{"atb":[[1.67,0]],"id":39236417}],"con":true,"img":false}]}
{"op":"mcm","clk":"5323239574","pt":1646328901829,"mc":[{"id":"1.195532877","rc":[{"atl":[[4.5,0]],"id":42327927}],"con":true,"img":false}]}
{"op":"mcm","clk":"5323239598","pt":1646328902140,"mc":[{"id":"1.195532877","rc":[{"atl":[[4.6,22.55]],"id":42327927}],"con":true,"img":false}]}
{"op":"mcm","clk":"5323239612","pt":1646328902154,"mc":[{"id":"1.195532877","rc":[{"atb":[[2,47.29]],"id":43189004},{"atb":[[2.3,0]],"id":39236417}],"con":true,"img":false}]}
{"op":"mcm","clk":"5323239692","pt":1646328902778,"mc":[{"id":"1.195532877","rc":[{"atb":[[2,0]],"id":43189004},{"atb":[[2.26,0]],"id":38519823}],"con":true,"img":false}]}
{"op":"mcm","clk":"5323239831","pt":1646328903870,"mc":[{"id":"1.195532877","rc":[{"atl":[[4.3,4.9]],"id":42327927}],"con":true,"img":false}]}
{"op":"mcm","clk":"5323239921","pt":1646328904557,"mc":[{"id":"1.195532877","rc":[{"atb":[[2.38,12.56]],"id":42327927}],"con":true,"img":false}]}
{"op":"mcm","clk":"5323239936","pt":1646328904659,"mc":[{"id":"1.195532877","rc":[{"atl":[[5.8,9.14],[5.2,11.09]],"id":43094641}],"con":true,"img":false}]}
{"op":"mcm","clk":"5323239949","pt":1646328904758,"mc":[{"id":"1.195532877","rc":[{"atb":[[2.46,9.14]],"id":43094641},{"atb":[[2.38,8.7]],"id":42327927}],"con":true,"img":false}]}
{"op":"mcm","clk":"5323239963","pt":1646328904861,"mc":[{"id":"1.195532877","rc":[{"atb":[[2.54,3.64],[2.4,2.5],[2.52,11.45],[2.46,31.93]],"id":43094641},{"atl":[[5.8,45.6],[6.6,5]],"id":43094641},{"atb":[[2.66,53.59],[2.64,7.15]],"id":41696085},{"atl":[[7.6,20.15],[7,63.5]],"id":41696085},{"atb":[[2.08,34.93],[1.99,5],[2.16,19.12]],"id":43189004},{"atl":[[4.8,76.77],[4.3,12.47],[5,30]],"id":43189004},{"atb":[[2.32,28.5],[2.44,14.25],[2.26,0]],"id":42327927},{"atl":[[4.8,10.53],[4.6,58.05],[4.2,12.26]],"id":42327927},{"atl":[[4.9,41.57],[5.2,28.81]],"id":38519823},{"atb":[[2.42,12.01],[2.46,5.49],[2.28,0]],"id":39236417},{"atl":[[5.6,3.5],[6,25.28],[5.9,22.08]],"id":39236417}],"con":true,"img":false}]}
{"op":"mcm","clk":"5323239974","pt":1646328904967,"mc":[{"id":"1.195532877","rc":[{"atl":[[5.1,9.3]],"id":43094641}],"con":true,"img":false}]}
{"op":"mcm","clk":"5323239986","pt":1646328905067,"mc":[{"id":"1.195532877","rc":[{"atb":[[2.46,22.79]],"id":43094641},{"atb":[[2.08,24.95]],"id":43189004},{"atl":[[4.8,66.24],[4.6,41.39],[4.4,0]],"id":43189004},{"atb":[[2.38,2.15]],"id":42327927},{"atl":[[4.6,46.61]],"id":42327927},{"atb":[[2.38,0]],"id":39236417},{"atl":[[5.8,23.33],[6,11.39],[5.7,12]],"id":39236417}],"con":true,"img":false}]}
{"op":"mcm","clk":"5323240000","pt":1646328905168,"mc":[{"id":"1.195532877","rc":[{"atl":[[5.8,36.46]],"id":43094641}],"con":true,"img":false}]}
{"op":"mcm","clk":"5323240011","pt":1646328905272,"mc":[{"id":"1.195532877","rc":[{"atl":[[6,14.97]],"id":39236417}],"con":true,"img":false}]}
{"op":"mcm","clk":"5323240032","pt":1646328905380,"mc":[{"id":"1.195532877","rc":[{"atb":[[2.14,0]],"id":38519823}],"con":true,"img":false}]}
{"op":"mcm","clk":"5323240052","pt":1646328905484,"mc":[{"id":"1.195532877","rc":[{"atb":[[2.1,9.13]],"id":43189004},{"atb":[[2.34,4.74]],"id":42327927},{"atl":[[6,11.39]],"id":39236417}],"con":true,"img":false}]}
{"op":"mcm","clk":"5323240078","pt":1646328905554,"mc":[{"id":"1.195532877","rc":[{"atb":[[2.28,0]],"id":38519823}],"con":true,"img":false}]}
{"op":"mcm","clk":"5323240091","pt":1646328905646,"mc":[{"id":"1.195532877","rc":[{"atb":[[2.22,1.99]],"id":38519823}],"con":true,"img":false}]}
{"op":"mcm","clk":"5323240109","pt":1646328905753,"mc":[{"id":"1.195532877","rc":[{"atb":[[2.5,0]],"id":43094641},{"atb":[[2.4,4.96]],"id":42327927},{"atb":[[2.42,8.7]],"id":39236417}],"con":true,"img":false}]}
{"op":"mcm","clk":"5323240120","pt":1646328905857,"mc":[{"id":"1.195532877","rc":[{"atl":[[5.3,9.3],[5.4,0]],"id":43094641},{"atl":[[4.5,11.43],[4.6,30.28]],"id":43189004},{"atl":[[4.4,23.2]],"id":42327927},{"atl":[[5.8,31.66],[5.9,13.92]],"id":39236417}],"con":true,"img":false}]}
{"op":"mcm","clk":"5323240179","pt":1646328906272,"mc":[{"id":"1.195532877","rc":[{"atl":[[5.2,9.09]],"id":43094641}],"con":true,"img":false}]}
{"op":"mcm","clk":"5323240231","pt":1646328906643,"mc":[{"id":"1.195532877","rc":[{"atb":[[2.34,31.75],[2.42,0],[2.38,3.9]],"id":43094641},{"atb":[[2.14,22.93],[2.16,14.46]],"id":43189004}],"con":true,"img":false}]}
{"op":"mcm","clk":"5323240278","pt":1646328907055,"mc":[{"id":"1.195532877","rc":[{"atl":[[4.6,6.38]],"id":38519823}],"con":true,"img":false}]}
{"op":"mcm","clk":"5323240300","pt":1646328907260,"mc":[{"id":"1.195532877","rc":[{"atb":[[2.38,0]],"id":43094641},{"atl":[[4.5,7.5],[4.9,25.06]],"id":38519823}],"con":true,"img":false}]}
{"op":"mcm","clk":"5323240316","pt":1646328907367,"mc":[{"id":"1.195532877","rc":[{"atl":[[4.7,0]],"id":38519823}],"con":true,"img":false}]}
{"op":"mcm","clk":"5323240323","pt":1646328907468,"mc":[{"id":"1.195532877","rc":[{"atl":[[4.6,0]],"id":38519823}],"con":true,"img":false}]}
{"op":"mcm","clk":"5323240349","pt":1646328907669,"mc":[{"id":"1.195532877","rc":[{"atl":[[4.9,49.45]],"id":38519823}],"con":true,"img":false}]}
{"op":"mcm","clk":"5323240361","pt":1646328907776,"mc":[{"id":"1.195532877","rc":[{"atl":[[4.5,7.41]],"id":38519823}],"con":true,"img":false}]}
{"op":"mcm","clk":"5323240385","pt":1646328907945,"mc":[{"id":"1.195532877","rc":[{"atb":[[2.14,5.47]],"id":38519823}],"con":true,"img":false}]}
{"op":"mcm","clk":"5323240406","pt":1646328908152,"mc":[{"id":"1.195532877","rc":[{"atl":[[4.4,11.76],[4.2,24.52]],"id":42327927},{"atl":[[4.5,3.75]],"id":38519823}],"con":true,"img":false}]}
{"op":"mcm","clk":"5323240424","pt":1646328908361,"mc":[{"id":"1.195532877","rc":[{"atl":[[4.5,0]],"id":38519823}],"con":true,"img":false}]}
{"op":"mcm","clk":"5323240438","pt":1646328908465,"mc":[{"id":"1.195532877","rc":[{"atl":[[4.6,3.75]],"id":38519823}],"con":true,"img":false}]}
{"op":"mcm","clk":"5323240457","pt":1646328908674,"mc":[{"id":"1.195532877","rc":[{"atb":[[2.2,3.31]],"id":43189004},{"atb":[[2.24,4.96]],"id":38519823},{"atl":[[4.8,13.03],[4.6,0],[4.9,39.19]],"id":38519823}],"con":true,"img":false}]}
{"op":"mcm","clk":"5323240481","pt":1646328908875,"mc":[{"id":"1.195532877","rc":[{"atb":[[2.22,2.15],[2.14,20.78]],"id":43189004},{"atb":[[2.5,2.15],[2.38,0]],"id":42327927},{"atl":[[4.7,3.75]],"id":38519823}],"con":true,"img":false}]}
{"op":"mcm","clk":"5323240492","pt":1646328908980,"mc":[{"id":"1.195532877","rc":[{"atb":[[2.3,0],[2.22,0]],"id":38519823}],"con":true,"img":false}]}
{"op":"mcm","clk":"5323240504","pt":1646328909085,"mc":[{"id":"1.195532877","rc":[{"atb":[[2.22,3.13],[2.26,1.99],[2.24,6.62]],"id":38519823}],"con":true,"img":false}]}
{"op":"mcm","clk":"5323240516","pt":1646328909146,"mc":[{"id":"1.195532877","rc":[{"atb":[[2.22,0]],"id":38519823}],"con":true,"img":false}]}
{"op":"mcm","clk":"5323240526","pt":1646328909251,"mc":[{"id":"1.195532877","rc":[{"atb":[[2.16,12.47]],"id":43189004}],"con":true,"img":false}]}
{"op":"mcm","clk":"5323240538","pt":1646328909360,"mc":[{"id":"1.195532877","rc":[{"atb":[[2.22,4.14]],"id":43189004}],"con":true,"img":false}]}
{"op":"mcm","clk":"5323240594","pt":1646328909775,"mc":[{"id":"1.195532877","rc":[{"atl":[[5.3,27.69]],"id":43094641}],"con":true,"img":false}]}
{"op":"mcm","clk":"5323240608","pt":1646328909881,"mc":[{"id":"1.195532877","rc":[{"atl":[[5.2,0]],"id":43094641}],"con":true,"img":false}]}
{"op":"mcm","clk":"5323240659","pt":1646328910389,"mc":[{"id":"1.195532877","rc":[{"atl":[[5.1,0],[5.8,57.29],[5.3,9.3]],"id":43094641},{"atl":[[4.8,2.5],[4.9,49.45]],"id":38519823}],"con":true,"img":false}]}
{"op":"mcm","clk":"5323240671","pt":1646328910494,"mc":[{"id":"1.195532877","rc":[{"atl":[[5.2,19.05]],"id":43094641},{"atl":[[4.3,0]],"id":42327927}],"con":true,"img":false}]}
{"op":"mcm","clk":"5323240686","pt":1646328910555,"mc":[{"id":"1.195532877","rc":[{"atl":[[5.3,0],[5.4,3.53],[5.5,8.89]],"id":43094641}],"con":true,"img":false}]}
{"op":"mcm","clk":"5323240699","pt":1646328910668,"mc":[{"id":"1.195532877","rc":[{"atl":[[5.4,12.62]],"id":43094641}],"con":true,"img":false}]}
{"op":"mcm","clk":"5323240710","pt":1646328910772,"mc":[{"id":"1.195532877","rc":[{"atb":[[2.1,0]],"id":43189004}],"con":true,"img":false}]}
{"op":"mcm","clk":"5323240734","pt":1646328910981,"mc":[{"id":"1.195532877","rc":[{"atl":[[6.2,0],[21,0],[5.5,0],[23,0]],"id":43094641}],"con":true,"img":false}]}
{"op":"mcm","clk":"5323240750","pt":1646328911079,"mc":[{"id":"1.195532877","rc":[{"atl":[[5.4,9.09]],"id":43094641}],"con":true,"img":false}]}
{"op":"mcm","clk":"5323240761","pt":1646328911178,"mc":[{"id":"1.195532877","rc":[{"atb":[[2.38,181.16]],"id":41696085},{"atl":[[7.8,22.06]],"id":41696085}],"con":true,"img":false}]}
{"op":"mcm","clk":"5323240812","pt":1646328911656,"mc":[{"id":"1.195532877","rc":[{"atb":[[2.48,10.95]],"id":43094641},{"atb":[[2.14,0]],"id":41696085},{"atl":[[7.2,0],[7.6,5]],"id":41696085},{"atb":[[2.5,3.31]],"id":39236417}],"con":true,"img":false}]}
{"op":"mcm","clk":"5323240826","pt":1646328911764,"mc":[{"id":"1.195532877","rc":[{"atl":[[4.1,5.2]],"id":42327927}],"con":true,"img":false}]}
{"op":"mcm","clk":"5323240851","pt":1646328911974,"mc":[{"id":"1.195532877","rc":[{"atl":[[4,12.72],[4.7,16.22]],"id":42327927}],"con":true,"img":false}]}
{"op":"mcm","clk":"5323240874","pt":1646328912176,"mc":[{"id":"1.195532877","rc":[{"atl":[[4.2,12.26],[4.7,10.8]],"id":42327927}],"con":true,"img":false}]}
{"op":"mcm","clk":"5323240917","pt":1646328912545,"mc":[{"id":"1.195532877","rc":[{"atl":[[4.4,0],[4.2,24.76]],"id":42327927}],"con":true,"img":false}]}
{"op":"mcm","clk":"5323240963","pt":1646328913066,"mc":[{"id":"1.195532877","rc":[{"atb":[[2.34,0]],"id":42327927},{"atb":[[2.14,0]],"id":38519823}],"con":true,"img":false}]}
{"op":"mcm","clk":"5323241067","pt":1646328914046,"mc":[{"id":"1.195532877","rc":[{"atb":[[2.2,0]],"id":43189004},{"atb":[[2.4,0]],"id":42327927}],"con":true,"img":false}]}
{"op":"mcm","clk":"5323241134","pt":1646328914674,"mc":[{"id":"1.195532877","rc":[{"atb":[[2.44,12.26]],"id":42327927},{"atl":[[4,25.44],[4.2,12.5]],"id":42327927}],"con":true,"img":false}]}
{"op":"mcm","clk":"5323241144","pt":1646328914780,"mc":[{"id":"1.195532877","rc":[{"atb":[[2.52,1.99]],"id":42327927}],"con":true,"img":false}]}
{"op":"mcm","clk":"5323241242","pt":1646328915460,"mc":[{"id":"1.195532877","rc":[{"atl":[[6,8]],"id":39236417}],"con":true,"img":false}]}
{"op":"mcm","clk":"5323241253","pt":1646328915564,"mc":[{"id":"1.195532877","rc":[{"atb":[[2.46,3.5]],"id":39236417}],"con":true,"img":false}]}
{"op":"mcm","clk":"5323241264","pt":1646328915670,"mc":[{"id":"1.195532877","rc":[{"atb":[[2.52,1.99]],"id":39236417}],"con":true,"img":false}]}
{"op":"mcm","clk":"5323241276","pt":1646328915777,"mc":[{"id":"1.195532877","rc":[{"atb":[[2.24,2.9]],"id":43189004},{"atb":[[2.14,219.3]],"id":39236417},{"atl":[[6,20]],"id":39236417}],"con":true,"img":false}]}
{"op":"mcm","clk":"5323241336","pt":1646328916287,"mc":[{"id":"1.195532877","rc":[{"atb":[[2.22,2.15]],"id":43189004}],"con":true,"img":false}]}
{"op":"mcm","clk":"5323241351","pt":1646328916350,"mc":[{"id":"1.195532877","rc":[{"atb":[[2.26,1.99]],"id":43189004}],"con":true,"img":false}]}
{"op":"mcm","clk":"5323241380","pt":1646328916660,"mc":[{"id":"1.195532877","rc":[{"atb":[[1.89,0]],"id":39236417}],"con":true,"img":false}]}
{"op":"mcm","clk":"5323241519","pt":1646328917953,"mc":[{"id":"1.195532877","rc":[{"atb":[[2.18,0]],"id":43189004},{"atb":[[2.46,0]],"id":42327927},{"atb":[[2.24,4.96]],"id":38519823},{"atb":[[2.48,0]],"id":39236417}],"con":true,"img":false}]}
{"op":"mcm","clk":"5323241531","pt":1646328918057,"mc":[{"id":"1.195532877","rc":[{"atl":[[4.1,0]],"id":42327927}],"con":true,"img":false}]}
{"op":"mcm","clk":"5323241539","pt":1646328918169,"mc":[{"id":"1.195532877","rc":[{"atb":[[2.28,1.65]],"id":43189004},{"atb":[[2.28,1.65]],"id":38519823},{"atb":[[2.54,1.65]],"id":39236417}],"con":true,"img":false}]}
{"op":"mcm","clk":"5323241566","pt":1646328918371,"mc":[{"id":"1.195532877","rc":[{"atl":[[5.3,4.45]],"id":42327927}],"con":true,"img":false}]}
{"op":"mcm","clk":"5323241581","pt":1646328918476,"mc":[{"id":"1.195532877","rc":[{"atl":[[5.3,0]],"id":42327927},{"atb":[[2.5,0]],"id":39236417}],"con":true,"img":false}]}
{"op":"mcm","clk":"5323241592","pt":1646328918581,"mc":[{"id":"1.195532877","rc":[{"atl":[[5,13.22]],"id":38519823}],"con":true,"img":false}]}
{"op":"mcm","clk":"5323241604","pt":1646328918682,"mc":[{"id":"1.195532877","rc":[{"atb":[[2.22,21],[2.26,12.74],[2.08,0]],"id":43189004},{"atb":[[2.5,20.72]],"id":42327927},{"atb":[[2.42,0]],"id":39236417},{"atl":[[5.8,45.96],[5.9,0]],"id":39236417}],"con":true,"img":false}]}
{"op":"mcm","clk":"5323241617","pt":1646328918782,"mc":[{"id":"1.195532877","rc":[{"atb":[[2.48,38.96],[2.46,0]],"id":43094641},{"atl":[[4.8,26.32],[4.6,60.44]],"id":43189004},{"atb":[[2.44,11.09]],"id":39236417}],"con":true,"img":false}]}
{"op":"mcm","clk":"5323241628","pt":1646328918882,"mc":[{"id":"1.195532877","rc":[{"atb":[[2.16,0]],"id":43189004},{"atb":[[2.44,0]],"id":42327927}],"con":true,"img":false}]}
{"op":"mcm","clk":"5323241652","pt":1646328919089,"mc":[{"id":"1.195532877","rc":[{"atb":[[2.24,62.7],[2.32,6.31]],"id":42327927},{"atl":[[5,10]],"id":38519823}],"con":true,"img":false}]}
{"op":"mcm","clk":"5323241663","pt":1646328919196,"mc":[{"id":"1.195532877","rc":[{"atl":[[4.1,4.88]],"id":43189004},{"atb":[[2.34,6.63]],"id":42327927},{"atb":[[2.14,11.2]],"id":38519823}],"con":true,"img":false}]}
{"op":"mcm","clk":"5323241678","pt":1646328919268,"mc":[{"id":"1.195532877","rc":[{"atb":[[2.52,0]],"id":39236417}],"con":true,"img":false}]}
{"op":"mcm","clk":"5323241689","pt":1646328919360,"mc":[{"id":"1.195532877","rc":[{"atl":[[4,23.66],[4.6,32.66]],"id":43189004},{"atb":[[2.48,1.99]],"id":39236417}],"con":true,"img":false}]}
{"op":"mcm","clk":"5323241702","pt":1646328919465,"mc":[{"id":"1.195532877","rc":[{"atl":[[4.3,0]],"id":43189004}],"con":true,"img":false}]}
{"op":"mcm","clk":"5323241714","pt":1646328919566,"mc":[{"id":"1.195532877","rc":[{"atb":[[2.22,18.85]],"id":43189004},{"atb":[[1.68,0]],"id":38519823}],"con":true,"img":false}]}
{"op":"mcm","clk":"5323241726","pt":1646328919673,"mc":[{"id":"1.195532877","rc":[{"atb":[[2.32,2.15]],"id":43189004},{"atb":[[2.26,4.14]],"id":38519823}],"con":true,"img":false}]}
{"op":"mcm","clk":"5323241740","pt":1646328919772,"mc":[{"id":"1.195532877","rc":[{"atl":[[4.5,0],[4.2,12.5]],"id":43189004},{"atl":[[4,12.72],[4.6,74.39]],"id":42327927}],"con":true,"img":false}]}
{"op":"mcm","clk":"5323241753","pt":1646328919879,"mc":[{"id":"1.195532877","rc":[{"atl":[[3.9,5.45]],"id":42327927}],"con":true,"img":false}]}
{"op":"mcm","clk":"5323241775","pt":1646328920084,"mc":[{"id":"1.195532877","rc":[{"atl":[[3.85,14.35],[4.6,38.89],[4.2,50.76]],"id":42327927}],"con":true,"img":false}]}
{"op":"mcm","clk":"5323241789","pt":1646328920189,"mc":[{"id":"1.195532877","rc":[{"atb":[[1.73,250]],"id":38519823},{"atl":[[5.3,34.88]],"id":38519823}],"con":true,"img":false}]}
{"op":"mcm","clk":"5323241802","pt":1646328920287,"mc":[{"id":"1.195532877","rc":[{"atl":[[4,0]],"id":42327927}],"con":true,"img":false}]}
{"op":"mcm","clk":"5323241834","pt":1646328920558,"mc":[{"id":"1.195532877","rc":[{"atl":[[5.6,21.74]],"id":43094641}],"con":true,"img":false}]}
{"op":"mcm","clk":"5323241849","pt":1646328920660,"mc":[{"id":"1.195532877","rc":[{"atl":[[5.6,43.48]],"id":43094641}],"con":true,"img":false}]}
{"op":"mcm","clk":"5323241863","pt":1646328920767,"mc":[{"id":"1.195532877","rc":[{"atl":[[5.6,104.5],[5.8,0]],"id":43094641}],"con":true,"img":false}]}
{"op":"mcm","clk":"5323241888","pt":1646328920973,"mc":[{"id":"1.195532877","rc":[{"atl":[[8.2,34.72]],"id":41696085},{"atl":[[3.95,13.56],[4.2,38.26]],"id":42327927},{"atl":[[5,0],[5.2,5]],"id":38519823}],"con":true,"img":false}]}
{"op":"mcm","clk":"5323241967","pt":1646328921653,"mc":[{"id":"1.195532877","rc":[{"atb":[[2.54,22.79]],"id":43094641},{"atb":[[2.24,0]],"id":43189004}],"con":true,"img":false}]}
{"op":"mcm","clk":"5323241983","pt":1646328921762,"mc":[{"id":"1.195532877","rc":[{"atb":[[2.3,3.31]],"id":43189004},{"atb":[[2.46,5.95]],"id":42327927},{"atb":[[2.24,0]],"id":38519823}],"con":true,"img":false}]}
{"op":"mcm","clk":"5323241993","pt":1646328921863,"mc":[{"id":"1.195532877","rc":[{"atb":[[2.52,2.15]],"id":43094641}],"con":true,"img":false}]}
{"op":"mcm","clk":"5323242058","pt":1646328922498,"mc":[{"id":"1.195532877","rc":[{"atl":[[7,65.33]],"id":41696085}],"con":true,"img":false}]}
{"op":"mcm","clk":"5323242135","pt":1646328923274,"mc":[{"id":"1.195532877","rc":[{"atb":[[2.18,8.54]],"id":42327927}],"con":true,"img":false}]}
{"op":"mcm","clk":"5323242146","pt":1646328923376,"mc":[{"id":"1.195532877","rc":[{"atb":[[2.18,0]],"id":42327927}],"con":true,"img":false}]}
{"op":"mcm","clk":"5323242250","pt":1646328924310,"mc":[{"id":"1.195532877","rc":[{"atb":[[2.14,0]],"id":38519823},{"atb":[[2.56,3.31]],"id":39236417}],"con":true,"img":false}]}
{"op":"mcm","clk":"5323242417","pt":1646328925371,"mc":[{"id":"1.195532877","rc":[{"atl":[[3.9,0]],"id":42327927}],"con":true,"img":false}]}
{"op":"mcm","clk":"5323242431","pt":1646328925473,"mc":[{"id":"1.195532877","rc":[{"atl":[[6.4,32.78]],"id":39236417}],"con":true,"img":false}]}
{"op":"mcm","clk":"5323242508","pt":1646328926099,"mc":[{"id":"1.195532877","rc":[{"atl":[[4.6,11.11],[4.2,69.51]],"id":42327927}],"con":true,"img":false}]}
{"op":"mcm","clk":"5323242576","pt":1646328926675,"mc":[{"id":"1.195532877","rc":[{"atl":[[3.8,5.64]],"id":42327927}],"con":true,"img":false}]}
{"op":"mcm","clk":"5323242597","pt":1646328926887,"mc":[{"id":"1.195532877","rc":[{"atb":[[2.54,3.64]],"id":43094641},{"spn":3.87,"spf":"NaN","id":43094641},{"spn":4.67,"spf":"NaN","id":41696085},{"spn":2.32,"spf":1.0,"id":43189004},{"atb":[[2.5,2.15]],"id":42327927},{"atl":[[3.75,14.64],[3.95,0],[3.9,13.79]],"id":42327927},{"spn":3.13,"spf":"NaN","id":42327927},{"spn":2.27,"spf":1.0,"id":38519823},{"spn":4.08,"spf":"NaN","id":39236417}],"con":true,"img":false}]}
{"op":"mcm","clk":"5323242611","pt":1646328926989,"mc":[{"id":"1.195532877","rc":[{"atb":[[2.52,6.62]],"id":43094641},{"atb":[[2.28,0]],"id":43189004},{"atb":[[2.54,0]],"id":39236417}],"con":true,"img":false}]}
{"op":"mcm","clk":"5323242622","pt":1646328927088,"mc":[{"id":"1.195532877","rc":[{"atl":[[3.85,0]],"id":42327927}],"con":true,"img":false}]}
{"op":"mcm","clk":"5323242638","pt":1646328927191,"mc":[{"id":"1.195532877","rc":[{"atb":[[2.52,2.15]],"id":43094641},{"atb":[[2.34,1.65]],"id":43189004},{"atb":[[2.5,10.85],[2.34,0]],"id":42327927},{"atb":[[2.58,1.65]],"id":39236417}],"con":true,"img":false}]}
{"op":"mcm","clk":"5323242650","pt":1646328927295,"mc":[{"id":"1.195532877","rc":[{"atb":[[2.32,5.98],[2.3,0]],"id":43189004},{"atb":[[2.22,4.96]],"id":38519823}],"con":true,"img":false}]}
{"op":"mcm","clk":"5323242704","pt":1646328927770,"mc":[{"id":"1.195532877","rc":[{"atl":[[3.85,14.04],[3.9,0]],"id":42327927}],"con":true,"img":false}]}
{"op":"mcm","clk":"5323242770","pt":1646328928326,"mc":[{"id":"1.195532877","rc":[{"atl":[[4.4,14.91]],"id":38519823}],"con":true,"img":false}]}
{"op":"mcm","clk":"5323242793","pt":1646328928494,"mc":[{"id":"1.195532877","rc":[{"atl":[[4.8,19.94],[4.3,9.68],[4.9,10.26]],"id":38519823}],"con":true,"img":false}]}
{"op":"mcm","clk":"5323242810","pt":1646328928696,"mc":[{"id":"1.195532877","rc":[{"atl":[[4.7,0]],"id":38519823}],"con":true,"img":false}]}
{"op":"mcm","clk":"5323242822","pt":1646328928767,"mc":[{"id":"1.195532877","rc":[{"atl":[[4.5,11.43]],"id":38519823}],"con":true,"img":false}]}
{"op":"mcm","clk":"5323242875","pt":1646328929171,"mc":[{"id":"1.195532877","rc":[{"atl":[[4.4,0]],"id":38519823}],"con":true,"img":false}]}
{"op":"mcm","clk":"5323242904","pt":1646328929484,"mc":[{"id":"1.195532877","rc":[{"atl":[[4.4,29.41]],"id":43189004},{"atl":[[4.3,13.28]],"id":38519823}],"con":true,"img":false}]}
{"op":"mcm","clk":"5323242940","pt":1646328929796,"mc":[{"id":"1.195532877","rc":[{"atb":[[2.46,0]],"id":42327927},{"atb":[[2.56,0]],"id":39236417}],"con":true,"img":false}]}
{"op":"mcm","clk":"5323242954","pt":1646328929895,"mc":[{"id":"1.195532877","rc":[{"atl":[[10,0]],"id":43189004}],"con":true,"img":false}]}
{"op":"mcm","clk":"5323242966","pt":1646328930003,"mc":[{"id":"1.195532877","rc":[{"atb":[[2.54,22.79]],"id":43094641}],"con":true,"img":false}]}
{"op":"mcm","clk":"5323242990","pt":1646328930164,"mc":[{"id":"1.195532877","rc":[{"atl":[[5.8,31.25]],"id":43094641},{"atb":[[2.26,10.75]],"id":43189004},{"atl":[[4.3,9.68]],"id":38519823}],"con":true,"img":false}]}
{"op":"mcm","clk":"5323243001","pt":1646328930268,"mc":[{"id":"1.195532877","rc":[{"atb":[[2.6,2.15],[2.52,0]],"id":43094641},{"atb":[[2.34,3.64]],"id":43189004}],"con":true,"img":false}]}
{"op":"mcm","clk":"5323243024","pt":1646328930478,"mc":[{"id":"1.195532877","rc":[{"atb":[[2.34,20.55]],"id":42327927},{"atb":[[2.14,8.12]],"id":38519823},{"atl":[[4.2,3.87]],"id":38519823}],"con":true,"img":false}]}
{"op":"mcm","clk":"5323243090","pt":1646328931099,"mc":[{"id":"1.195532877","rc":[{"atl":[[4.2,0]],"id":38519823}],"con":true,"img":false}]}
{"op":"mcm","clk":"5323243103","pt":1646328931199,"mc":[{"id":"1.195532877","rc":[{"atl":[[4.5,0],[4.4,11.76]],"id":38519823}],"con":true,"img":false}]}
{"op":"mcm","clk":"5323243129","pt":1646328931405,"mc":[{"id":"1.195532877","rc":[{"atl":[[3.8,0]],"id":42327927}],"con":true,"img":false}]}
{"op":"mcm","clk":"5323243155","pt":1646328931615,"mc":[{"id":"1.195532877","rc":[{"atl":[[3.75,0]],"id":42327927}],"con":true,"img":false}]}
{"op":"mcm","clk":"5323243177","pt":1646328931783,"mc":[{"id":"1.195532877","rc":[{"atb":[[2.54,20.8]],"id":43094641},{"atl":[[4.6,92.67],[3.8,21.51],[4.2,0],[3.75,2.95]],"id":42327927}],"con":true,"img":false}]}
{"op":"mcm","clk":"5323243192","pt":1646328931885,"mc":[{"id":"1.195532877","rc":[{"atb":[[2.62,1.99]],"id":43094641}],"con":true,"img":false}]}
{"op":"mcm","clk":"5323243206","pt":1646328931994,"mc":[{"id":"1.195532877","rc":[{"atl":[[4.6,38.89]],"id":42327927},{"atb":[[1.88,113.64],[1.77,129.87]],"id":38519823},{"atl":[[4.5,11.43],[4.4,0]],"id":38519823},{"atb":[[2.46,0]],"id":39236417}],"con":true,"img":false}]}
{"op":"mcm","clk":"5323243218","pt":1646328932098,"mc":[{"id":"1.195532877","rc":[{"atb":[[2.24,8.75]],"id":39236417}],"con":true,"img":false}]}
{"op":"mcm","clk":"5323243231","pt":1646328932197,"mc":[{"id":"1.195532877","rc":[{"atl":[[3.75,0]],"id":42327927},{"atb":[[2.44,2.15],[2.26,92.38]],"id":39236417}],"con":true,"img":false}]}
{"op":"mcm","clk":"5323243239","pt":1646328932292,"mc":[{"id":"1.195532877","rc":[{"atb":[[2.22,0],[2.26,31.68]],"id":43189004}],"con":true,"img":false}]}
{"op":"mcm","clk":"5323243253","pt":1646328932399,"mc":[{"id":"1.195532877","rc":[{"atb":[[2.28,4.96]],"id":43189004},{"atl":[[4.6,2.5],[4.2,45.98]],"id":43189004},{"atl":[[3.85,0],[3.9,13.79]],"id":42327927},{"atb":[[2.24,0]],"id":39236417}],"con":true,"img":false}]}
{"op":"mcm","clk":"5323243261","pt":1646328932455,"mc":[{"id":"1.195532877","rc":[{"atl":[[3.7,5.84]],"id":42327927},{"atl":[[4.1,5.23]],"id":38519823}],"con":true,"img":false}]}
{"op":"mcm","clk":"5323243285","pt":1646328932714,"mc":[{"id":"1.195532877","rc":[{"atb":[[2.24,2.5],[2.32,39.6]],"id":42327927}],"con":true,"img":false}]}
{"op":"mcm","clk":"5323243322","pt":1646328932997,"mc":[{"id":"1.195532877","rc":[{"atl":[[4.2,51.38]],"id":43189004}],"con":true,"img":false}]}
{"op":"mcm","clk":"5323243336","pt":1646328933093,"mc":[{"id":"1.195532877","rc":[{"atl":[[3.8,35.8],[3.9,0]],"id":42327927},{"atl":[[4.3,21.8],[4.5,0]],"id":38519823}],"con":true,"img":false}]}
{"op":"mcm","clk":"5323243381","pt":1646328933400,"mc":[{"id":"1.195532877","rc":[{"atb":[[2.32,2.15]],"id":43189004},{"atl":[[4.2,45.98]],"id":43189004},{"atb":[[2.14,0]],"id":38519823}],"con":true,"img":false}]}
{"op":"mcm","clk":"5323243389","pt":1646328933502,"mc":[{"id":"1.195532877","rc":[{"atl":[[4.5,3.12]],"id":43189004}],"con":true,"img":false}]}
{"op":"mcm","clk":"5323243407","pt":1646328933631,"mc":[{"id":"1.195532877","rc":[{"atl":[[3.65,23.56]],"id":42327927}],"con":true,"img":false}]}
{"op":"mcm","clk":"5323243417","pt":1646328933664,"mc":[{"id":"1.195532877","rc":[{"atl":[[4.6,120.94]],"id":42327927}],"con":true,"img":false}]}
{"op":"mcm","clk":"5323243431","pt":1646328933807,"mc":[{"id":"1.195532877","rc":[{"atl":[[3.8,14.29]],"id":42327927}],"con":true,"img":false}]}
{"op":"mcm","clk":"5323243444","pt":1646328933876,"mc":[{"id":"1.195532877","rc":[{"atl":[[4.5,0]],"id":43189004}],"con":true,"img":false}]}
{"op":"mcm","clk":"5323243458","pt":1646328933967,"mc":[{"id":"1.195532877","rc":[{"atl":[[3.8,0],[3.75,14.55]],"id":42327927}],"con":true,"img":false}]}
{"op":"mcm","clk":"5323243490","pt":1646328934292,"mc":[{"id":"1.195532877","rc":[{"atl":[[5.1,2.5],[5.5,5],[7.4,0],[6.6,0]],"id":43094641},{"atb":[[2.8,10],[2.72,0],[2.64,2.15],[2.62,4.49],[2.56,0],[2.88,5],[2.96,2.5],[2.68,4.56]],"id":41696085},{"atb":[[2.26,34.18],[1.95,0],[1.99,0],[2.06,0]],"id":43189004},{"atl":[[5,0],[5.8,0],[5.4,0]],"id":42327927},{"atl":[[4.8,17.44],[5.6,0],[4.3,24.3],[5.2,0],[4.7,5]],"id":38519823},{"atb":[[2.32,2.5],[2.22,81.97]],"id":39236417}],"con":true,"img":false}]}
{"op":"mcm","clk":"5323243499","pt":1646328934394,"mc":[{"id":"1.195532877","rc":[{"atl":[[5.2,0]],"id":43094641},{"atb":[[2.96,17.56]],"id":41696085}],"con":true,"img":false}]}
{"op":"mcm","clk":"5323243513","pt":1646328934496,"mc":[{"id":"1.195532877","rc":[{"atl":[[5.6,21.74],[5.1,10.94],[5.4,88.1]],"id":43094641},{"atb":[[2.8,38.32],[2.62,0],[2.74,9.61],[2.66,28.49],[2.68,0]],"id":41696085},{"atb":[[2.32,11.44]],"id":39236417}],"con":true,"img":false}]}
{"op":"mcm","clk":"5323243526","pt":1646328934600,"mc":[{"id":"1.195532877","rc":[{"atl":[[5.5,27.22],[5.4,65.37]],"id":43094641},{"atb":[[2.74,1.65]],"id":41696085},{"atb":[[2.26,63.5]],"id":39236417}],"con":true,"img":false}]}
{"op":"mcm","clk":"5323243538","pt":1646328934702,"mc":[{"id":"1.195532877","rc":[{"atl":[[4,5.23],[4.3,20.55]],"id":38519823}],"con":true,"img":false}]}
{"op":"mcm","clk":"5323243575","pt":1646328934979,"mc":[{"id":"1.195532877","rc":[{"atl":[[5.3,9.3]],"id":43094641},{"atl":[[4.3,8.43],[4.2,12.5]],"id":38519823}],"con":true,"img":false}]}
{"op":"mcm","clk":"5323243582","pt":1646328935083,"mc":[{"id":"1.195532877","rc":[{"atl":[[6.8,43.1]],"id":39236417}],"con":true,"img":false}]}
{"op":"mcm","clk":"5323243624","pt":1646328935386,"mc":[{"id":"1.195532877","rc":[{"atl":[[6.2,0]],"id":39236417}],"con":true,"img":false}]}
{"op":"mcm","clk":"5323243635","pt":1646328935489,"mc":[{"id":"1.195532877","rc":[{"atb":[[2.48,28.01]],"id":43094641},{"atb":[[2.36,8.44]],"id":42327927},{"atb":[[2.5,5.38]],"id":39236417}],"con":true,"img":false}]}
{"op":"mcm","clk":"5323243659","pt":1646328935700,"mc":[{"id":"1.195532877","rc":[{"atb":[[2.42,4.8]],"id":39236417}],"con":true,"img":false}]}
{"op":"mcm","clk":"5323243690","pt":1646328936011,"mc":[{"id":"1.195532877","rc":[{"atb":[[2.54,19.15]],"id":43094641},{"atb":[[2.74,0]],"id":41696085},{"atb":[[2.42,0],[2.58,0]],"id":39236417}],"con":true,"img":false}]}
{"op":"mcm","clk":"5323243700","pt":1646328936107,"mc":[{"id":"1.195532877","rc":[{"atb":[[2.34,23.93]],"id":42327927}],"con":true,"img":false}]}
{"op":"mcm","clk":"5323243709","pt":1646328936169,"mc":[{"id":"1.195532877","rc":[{"atb":[[2.98,1.65]],"id":41696085},{"atb":[[2.52,1.65]],"id":39236417}],"con":true,"img":false}]}
{"op":"mcm","clk":"5323243724","pt":1646328936275,"mc":[{"id":"1.195532877","rc":[{"atb":[[2.98,6.65]],"id":41696085},{"atb":[[2.34,20.55]],"id":42327927}],"con":true,"img":false}]}
{"op":"mcm","clk":"5323243737","pt":1646328936380,"mc":[{"id":"1.195532877","rc":[{"atb":[[2.8,26.2]],"id":41696085}],"con":true,"img":false}]}
{"op":"mcm","clk":"5323243794","pt":1646328936895,"mc":[{"id":"1.195532877","rc":[{"atl":[[4.1,0]],"id":43189004}],"con":true,"img":false}]}
{"op":"mcm","clk":"5323243809","pt":1646328936999,"mc":[{"id":"1.195532877","rc":[{"atb":[[2.34,0],[2.42,21.31]],"id":43094641},{"atb":[[2.38,20.55]],"id":42327927}],"con":true,"img":false}]}
{"op":"mcm","clk":"5323243820","pt":1646328937108,"mc":[{"id":"1.195532877","rc":[{"atl":[[4,12.23],[4.4,58.82]],"id":43189004},{"atb":[[2.32,33.3]],"id":42327927}],"con":true,"img":false}]}
{"op":"mcm","clk":"5323243835","pt":1646328937211,"mc":[{"id":"1.195532877","rc":[{"atl":[[4.2,50.71]],"id":43189004}],"con":true,"img":false}]}
{"op":"mcm","clk":"5323243872","pt":1646328937486,"mc":[{"id":"1.195532877","rc":[{"atl":[[4.1,0]],"id":38519823}],"con":true,"img":false}]}
{"op":"mcm","clk":"5323243885","pt":1646328937585,"mc":[{"id":"1.195532877","rc":[{"atb":[[2.48,0]],"id":39236417}],"con":true,"img":false}]}
{"op":"mcm","clk":"5323243899","pt":1646328937687,"mc":[{"id":"1.195532877","rc":[{"atl":[[4,0],[4.3,26.16]],"id":38519823},{"atb":[[2.46,1.99]],"id":39236417}],"con":true,"img":false}]}
{"op":"mcm","clk":"5323243910","pt":1646328937792,"mc":[{"id":"1.195532877","rc":[{"atb":[[2.66,0]],"id":41696085},{"atb":[[2.22,0]],"id":38519823},{"atl":[[3.95,3.35]],"id":38519823}],"con":true,"img":false}]}
{"op":"mcm","clk":"5323243922","pt":1646328937898,"mc":[{"id":"1.195532877","rc":[{"atl":[[4.4,11.76],[4.2,0]],"id":38519823}],"con":true,"img":false}]}
{"op":"mcm","clk":"5323243930","pt":1646328937996,"mc":[{"id":"1.195532877","rc":[{"atl":[[4.1,12.9]],"id":38519823}],"con":true,"img":false}]}
{"op":"mcm","clk":"5323243942","pt":1646328938103,"mc":[{"id":"1.195532877","rc":[{"atl":[[4.6,93.16],[3.65,38.11]],"id":42327927}],"con":true,"img":false}]}
{"op":"mcm","clk":"5323243952","pt":1646328938199,"mc":[{"id":"1.195532877","rc":[{"atl":[[3.95,0]],"id":38519823},{"atb":[[2.46,0]],"id":39236417}],"con":true,"img":false}]}
{"op":"mcm","clk":"5323243965","pt":1646328938304,"mc":[{"id":"1.195532877","rc":[{"atb":[[1.93,107.53],[1.88,0]],"id":38519823}],"con":true,"img":false}]}
{"op":"mcm","clk":"5323243975","pt":1646328938409,"mc":[{"id":"1.195532877","rc":[{"atb":[[2.52,3.64]],"id":39236417}],"con":true,"img":false}]}
{"op":"mcm","clk":"5323243984","pt":1646328938517,"mc":[{"id":"1.195532877","rc":[{"atl":[[4.3,38.28],[4.1,0],[4.4,0],[3.9,5.48]],"id":38519823}],"con":true,"img":false}]}
{"op":"mcm","clk":"5323243995","pt":1646328938621,"mc":[{"id":"1.195532877","rc":[{"atl":[[4.4,93.22],[4.2,17.23]],"id":43189004}],"con":true,"img":false}]}
{"op":"mcm","clk":"5323244042","pt":1646328938994,"mc":[{"id":"1.195532877","rc":[{"atb":[[2.36,2.55]],"id":43189004},{"atl":[[4.6,44.17]],"id":43189004},{"atb":[[2.34,0]],"id":42327927},{"atb":[[2.28,5.72]],"id":38519823}],"con":true,"img":false}]}
{"op":"mcm","clk":"5323244082","pt":1646328939405,"mc":[{"id":"1.195532877","rc":[{"atb":[[2.26,2.15]],"id":38519823},{"atl":[[3.9,0]],"id":38519823}],"con":true,"img":false}]}
{"op":"mcm","clk":"5323244094","pt":1646328939468,"mc":[{"id":"1.195532877","rc":[{"atb":[[2.3,1.99],[2.28,5.62]],"id":38519823},{"trd":[[2.28,0.19]],"ltp":2.28,"tv":0.19,"id":38519823}],"con":true,"img":false}]}
{"op":"mcm","clk":"5323244119","pt":1646328939680,"mc":[{"id":"1.195532877","rc":[{"atb":[[2.34,1.65]],"id":43189004}],"con":true,"img":false}]}
{"op":"mcm","clk":"5323244131","pt":1646328939785,"mc":[{"id":"1.195532877","rc":[{"atb":[[2.38,1.99]],"id":43189004}],"con":true,"img":false}]}
{"op":"mcm","clk":"5323244144","pt":1646328939880,"mc":[{"id":"1.195532877","rc":[{"atl":[[5,5]],"id":43189004},{"atl":[[4.3,26.16],[4.5,11.43]],"id":38519823}],"con":true,"img":false}]}
{"op":"mcm","clk":"5323244202","pt":1646328940508,"mc":[{"id":"1.195532877","rc":[{"atl":[[3.7,0]],"id":42327927}],"con":true,"img":false}]}
{"op":"mcm","clk":"5323244234","pt":1646328940770,"mc":[{"id":"1.195532877","rc":[{"atb":[[2.28,0]],"id":43189004},{"atb":[[2.36,0]],"id":42327927},{"atl":[[3.65,41.01]],"id":42327927}],"con":true,"img":false}]}
{"op":"mcm","clk":"5323244245","pt":1646328940873,"mc":[{"id":"1.195532877","rc":[{"atb":[[2.56,5.95]],"id":43094641}],"con":true,"img":false}]}
{"op":"mcm","clk":"5323244256","pt":1646328940982,"mc":[{"id":"1.195532877","rc":[{"atb":[[2.54,44.45],[2.48,0]],"id":43094641}],"con":true,"img":false}]}
{"op":"mcm","clk":"5323244266","pt":1646328941080,"mc":[{"id":"1.195532877","rc":[{"atl":[[3.75,19.97]],"id":42327927}],"con":true,"img":false}]}
{"op":"mcm","clk":"5323244294","pt":1646328941290,"mc":[{"id":"1.195532877","rc":[{"atl":[[3.75,14.55]],"id":42327927}],"con":true,"img":false}]}
{"op":"mcm","clk":"5323244299","pt":1646328941387,"mc":[{"id":"1.195532877","rc":[{"atl":[[3.65,38.11]],"id":42327927}],"con":true,"img":false}]}
{"op":"mcm","clk":"5323244355","pt":1646328941802,"mc":[{"id":"1.195532877","rc":[{"atl":[[4.7,30.22]],"id":38519823}],"con":true,"img":false}]}
{"op":"mcm","clk":"5323244364","pt":1646328941859,"mc":[{"id":"1.195532877","rc":[{"atl":[[4.8,0]],"id":38519823}],"con":true,"img":false}]}
{"op":"mcm","clk":"5323244401","pt":1646328942173,"mc":[{"id":"1.195532877","rc":[{"atl":[[3.6,6.07]],"id":42327927}],"con":true,"img":false}]}
{"op":"mcm","clk":"5323244424","pt":1646328942382,"mc":[{"id":"1.195532877","rc":[{"atl":[[3.55,19.06]],"id":42327927}],"con":true,"img":false}]}
{"op":"mcm","clk":"5323244449","pt":1646328942586,"mc":[{"id":"1.195532877","rc":[{"atl":[[3.65,14.55]],"id":42327927}],"con":true,"img":false}]}
{"op":"mcm","clk":"5323244470","pt":1646328942798,"mc":[{"id":"1.195532877","rc":[{"atl":[[4.3,8.43],[4.7,57.25]],"id":38519823}],"con":true,"img":false}]}
{"op":"mcm","clk":"5323244528","pt":1646328943311,"mc":[{"id":"1.195532877","rc":[{"atl":[[4.1,32.26],[4.4,63.81]],"id":43189004}],"con":true,"img":false}]}
{"op":"mcm","clk":"5323244541","pt":1646328943376,"mc":[{"id":"1.195532877","rc":[{"atl":[[3.85,35.09]],"id":42327927}],"con":true,"img":false}]}
{"op":"mcm","clk":"5323244592","pt":1646328943896,"mc":[{"id":"1.195532877","rc":[{"atb":[[2.9,21.63]],"id":41696085},{"atb":[[2.34,20.55]],"id":42327927},{"atb":[[2.5,0]],"id":39236417}],"con":true,"img":false}]}
{"op":"mcm","clk":"5323244601","pt":1646328944001,"mc":[{"id":"1.195532877","rc":[{"atl":[[4.8,0],[4.6,82.05]],"id":42327927}],"con":true,"img":false}]}
{"op":"mcm","clk":"5323244633","pt":1646328944305,"mc":[{"id":"1.195532877","rc":[{"atl":[[3.55,33.61],[3.65,0]],"id":42327927}],"con":true,"img":false}]}
{"op":"mcm","clk":"5323244659","pt":1646328944528,"mc":[{"id":"1.195532877","rc":[{"atl":[[5.5,49.44]],"id":43094641}],"con":true,"img":false}]}
{"op":"mcm","clk":"5323244696","pt":1646328944778,"mc":[{"id":"1.195532877","rc":[{"atl":[[5.6,0],[5.8,0],[5.4,56.28]],"id":43094641}],"con":true,"img":false}]}
{"op":"mcm","clk":"5323244713","pt":1646328944989,"mc":[{"id":"1.195532877","rc":[{"atb":[[2.34,0]],"id":43189004},{"atb":[[2.28,4.06]],"id":38519823}],"con":true,"img":false}]}
{"op":"mcm","clk":"5323244722","pt":1646328945092,"mc":[{"id":"1.195532877","rc":[{"atb":[[2.1,5.15]],"id":43189004},{"atl":[[4.6,0],[3.75,84.75]],"id":42327927}],"con":true,"img":false}]}
{"op":"mcm","clk":"5323244730","pt":1646328945196,"mc":[{"id":"1.195532877","rc":[{"atb":[[2.64,1.65]],"id":43094641},{"atb":[[2.4,1.65]],"id":43189004},{"atb":[[2.54,1.65]],"id":42327927}],"con":true,"img":false}]}
{"op":"mcm","clk":"5323244740","pt":1646328945299,"mc":[{"id":"1.195532877","rc":[{"atl":[[4.7,69.65]],"id":38519823}],"con":true,"img":false}]}
{"op":"mcm","clk":"5323244750","pt":1646328945407,"mc":[{"id":"1.195532877","rc":[{"atb":[[2.1,0]],"id":43189004},{"atb":[[2.52,14.69]],"id":42327927},{"atl":[[4.2,9.37]],"id":38519823},{"atb":[[2.52,1.65]],"id":39236417}],"con":true,"img":false}]}
{"op":"mcm","clk":"5323244763","pt":1646328945509,"mc":[{"id":"1.195532877","rc":[{"atb":[[2.5,2.15]],"id":42327927},{"atl":[[4.2,3.92]],"id":42327927},{"atl":[[4.3,2.5],[4.5,28.29],[4.7,42.62]],"id":38519823},{"atb":[[2.46,1.99]],"id":39236417}],"con":true,"img":false}]}
{"op":"mcm","clk":"5323244774","pt":1646328945608,"mc":[{"id":"1.195532877","rc":[{"atb":[[2.32,22],[2.26,13.25]],"id":43189004},{"atb":[[2.32,2.5],[2.44,13.35],[2.26,92.8]],"id":39236417}],"con":true,"img":false}]}
{"op":"mcm","clk":"5323244789","pt":1646328945667,"mc":[{"id":"1.195532877","rc":[{"atb":[[2.3,3.58]],"id":43189004},{"atl":[[4.4,29.41],[4.2,48.99]],"id":43189004},{"atl":[[4.7,30.22]],"id":38519823}],"con":true,"img":false}]}
{"op":"mcm","clk":"5323244816","pt":1646328945879,"mc":[{"id":"1.195532877","rc":[{"atb":[[2.3,0]],"id":43189004},{"atl":[[4.2,0]],"id":42327927}],"con":true,"img":false}]}
{"op":"mcm","clk":"5323244826","pt":1646328945983,"mc":[{"id":"1.195532877","rc":[{"atb":[[2.32,0],[2.38,66.67]],"id":42327927}],"con":true,"img":false}]}
{"op":"mcm","clk":"5323244845","pt":1646328946192,"mc":[{"id":"1.195532877","rc":[{"atb":[[2.36,0]],"id":43189004},{"atb":[[2.5,0],[2.58,2.15]],"id":42327927},{"atl":[[4.5,16.86],[4.4,11.76]],"id":38519823}],"con":true,"img":false}]}
{"op":"mcm","clk":"5323244876","pt":1646328946401,"mc":[{"id":"1.195532877","rc":[{"atl":[[4.3,21.24],[4.5,0]],"id":38519823}],"con":true,"img":false}]}
{"op":"mcm","clk":"5323244918","pt":1646328946772,"mc":[{"id":"1.195532877","rc":[{"atb":[[2.52,12.7]],"id":42327927}],"con":true,"img":false}]}
{"op":"mcm","clk":"5323244928","pt":1646328946879,"mc":[{"id":"1.195532877","rc":[{"atb":[[2.6,1.99]],"id":42327927}],"con":true,"img":false}]}
{"op":"mcm","clk":"5323244946","pt":1646328947094,"mc":[{"id":"1.195532877","rc":[{"atb":[[2.54,19.15]],"id":43094641},{"atb":[[2.52,0]],"id":42327927},{"atb":[[2.04,0],[2.12,0],[2.2,0]],"id":38519823},{"atb":[[2.12,89.29],[2.44,2.15],[2.26,61.05]],"id":39236417}],"con":true,"img":false}]}
{"op":"mcm","clk":"5323244954","pt":1646328947204,"mc":[{"id":"1.195532877","rc":[{"atb":[[2.4,5.63]],"id":43189004},{"atb":[[2.4,7.45]],"id":42327927}],"con":true,"img":false}]}
{"op":"mcm","clk":"5323244987","pt":1646328947512,"mc":[{"id":"1.195532877","rc":[{"atb":[[1.94,2.5],[1.93,133.94]],"id":38519823}],"con":true,"img":false}]}
{"op":"mcm","clk":"5323245013","pt":1646328947716,"mc":[{"id":"1.195532877","rc":[{"atb":[[2.98,25.79]],"id":41696085}],"con":true,"img":false}]}
{"op":"mcm","clk":"5323245020","pt":1646328947777,"mc":[{"id":"1.195532877","rc":[{"atb":[[2.8,10],[2.9,53.53]],"id":41696085},{"atb":[[2.32,11.44],[2.26,31.75]],"id":39236417}],"con":true,"img":false}]}
{"op":"mcm","clk":"5323245033","pt":1646328947880,"mc":[{"id":"1.195532877","rc":[{"atb":[[2.98,20.79],[2.92,24.22],[2.96,2.5]],"id":41696085}],"con":true,"img":false}]}
{"op":"mcm","clk":"5323245087","pt":1646328948328,"mc":[{"id":"1.195532877","rc":[{"atl":[[4.8,65.79]],"id":43189004}],"con":true,"img":false}]}
{"op":"mcm","clk":"5323245133","pt":1646328948713,"mc":[{"id":"1.195532877","rc":[{"atb":[[2.34,0]],"id":42327927},{"atb":[[2.28,0]],"id":38519823}],"con":true,"img":false}]}
{"op":"mcm","clk":"5323245262","pt":1646328949915,"mc":[{"id":"1.195532877","rc":[{"atb":[[2.22,6.41]],"id":42327927}],"con":true,"img":false}]}
{"op":"mcm","clk":"5323245285","pt":1646328950110,"mc":[{"id":"1.195532877","rc":[{"atb":[[2.56,0]],"id":43094641},{"atb":[[2.22,0]],"id":42327927}],"con":true,"img":false}]}
{"op":"mcm","clk":"5323245297","pt":1646328950214,"mc":[{"id":"1.195532877","rc":[{"atb":[[2.54,3.31]],"id":39236417}],"con":true,"img":false}]}
{"op":"mcm","clk":"5323245320","pt":1646328950415,"mc":[{"id":"1.195532877","rc":[{"atb":[[2.32,2.5]],"id":39236417}],"con":true,"img":false}]}
{"op":"mcm","clk":"5323245338","pt":1646328950621,"mc":[{"id":"1.195532877","rc":[{"atl":[[6,24.1]],"id":39236417}],"con":true,"img":false}]}
{"op":"mcm","clk":"5323245388","pt":1646328951149,"mc":[{"id":"1.195532877","rc":[{"atl":[[6,20]],"id":39236417}],"con":true,"img":false}]}
{"op":"mcm","clk":"5323245439","pt":1646328951523,"mc":[{"id":"1.195532877","rc":[{"atb":[[2.28,7.87]],"id":43189004},{"atl":[[4.3,2.5],[4.4,41.17]],"id":38519823}],"con":true,"img":false}]}
{"op":"mcm","clk":"5323245462","pt":1646328951737,"mc":[{"id":"1.195532877","rc":[{"atb":[[2.32,2.15],[2.26,59.81]],"id":43189004}],"con":true,"img":false}]}
{"op":"mcm","clk":"5323245498","pt":1646328952147,"mc":[{"id":"1.195532877","rc":[{"atb":[[2.38,0]],"id":43189004}],"con":true,"img":false}]}
{"op":"mcm","clk":"5323245509","pt":1646328952253,"mc":[{"id":"1.195532877","rc":[{"atb":[[2.34,1.99]],"id":43189004}],"con":true,"img":false}]}
{"op":"mcm","clk":"5323245566","pt":1646328952724,"mc":[{"id":"1.195532877","rc":[{"atl":[[3.95,50.85]],"id":42327927}],"con":true,"img":false}]}
{"op":"mcm","clk":"5323245589","pt":1646328952930,"mc":[{"id":"1.195532877","rc":[{"atb":[[2.9,31.9]],"id":41696085},{"atb":[[2.4,0]],"id":42327927}],"con":true,"img":false}]}
{"op":"mcm","clk":"5323245600","pt":1646328953036,"mc":[{"id":"1.195532877","rc":[{"atb":[[2.24,52.1],[2.38,20.55]],"id":42327927},{"atb":[[1.95,14.39]],"id":38519823},{"atb":[[2.46,0]],"id":39236417}],"con":true,"img":false}]}
{"op":"mcm","clk":"5323245610","pt":1646328953136,"mc":[{"id":"1.195532877","rc":[{"atb":[[2.56,1.99]],"id":39236417}],"con":true,"img":false}]}
{"op":"mcm","clk":"5323245682","pt":1646328953759,"mc":[{"id":"1.195532877","rc":[{"atl":[[5.7,31.91]],"id":43094641}],"con":true,"img":false}]}
{"op":"mcm","clk":"5323245711","pt":1646328953975,"mc":[{"id":"1.195532877","rc":[{"atb":[[2.98,41.59],[2.92,0]],"id":41696085},{"atb":[[2.54,0]],"id":42327927},{"atb":[[2.52,0]],"id":39236417}],"con":true,"img":false}]}
{"op":"mcm","clk":"5323245734","pt":1646328954135,"mc":[{"id":"1.195532877","rc":[{"atb":[[2.54,44.45]],"id":43094641},{"atb":[[2.58,1.65]],"id":39236417}],"con":true,"img":false}]}
{"op":"mcm","clk":"5323245779","pt":1646328954558,"mc":[{"id":"1.195532877","rc":[{"atb":[[1.95,25.17]],"id":38519823},{"atb":[[2.34,5.96]],"id":39236417}],"con":true,"img":false}]}
{"op":"mcm","clk":"5323245809","pt":1646328954860,"mc":[{"id":"1.195532877","rc":[{"atl":[[4.4,68.21],[4.7,5]],"id":38519823}],"con":true,"img":false}]}
{"op":"mcm","clk":"5323245875","pt":1646328955471,"mc":[{"id":"1.195532877","rc":[{"atl":[[4.6,27.78]],"id":38519823}],"con":true,"img":false}]}
{"op":"mcm","clk":"5323245914","pt":1646328955740,"mc":[{"id":"1.195532877","rc":[{"atb":[[2.66,3.31]],"id":43094641},{"atb":[[2.4,1.65]],"id":43189004}],"con":true,"img":false}]}
{"op":"mcm","clk":"5323245943","pt":1646328955947,"mc":[{"id":"1.195532877","rc":[{"atb":[[2.54,19.15]],"id":43094641},{"atl":[[5.1,0],[5.3,0],[4.9,0]],"id":38519823}],"con":true,"img":false}]}
{"op":"mcm","clk":"5323246040","pt":1646328956946,"mc":[{"id":"1.195532877","rc":[{"atb":[[2.44,2.15],[2.58,0]],"id":42327927}],"con":true,"img":false}]}
{"op":"mcm","clk":"5323246060","pt":1646328957153,"mc":[{"id":"1.195532877","rc":[{"atb":[[2.44,22.11]],"id":42327927}],"con":true,"img":false}]}
{"op":"mcm","clk":"5323246104","pt":1646328957666,"mc":[{"id":"1.195532877","rc":[{"atb":[[3,1.68]],"id":41696085},{"atb":[[2.42,2.94]],"id":43189004},{"atb":[[2.62,2.38]],"id":42327927},{"atb":[[2.6,2.44]],"id":39236417}],"con":true,"img":false}]}
{"op":"mcm","clk":"5323246114","pt":1646328957771,"mc":[{"id":"1.195532877","rc":[{"atb":[[2.54,0]],"id":43094641}],"con":true,"img":false}]}
{"op":"mcm","clk":"5323246128","pt":1646328957840,"mc":[{"id":"1.195532877","rc":[{"atb":[[2.26,13.25]],"id":43189004},{"atl":[[4.2,44.26]],"id":43189004}],"con":true,"img":false}]}
{"op":"mcm","clk":"5323246159","pt":1646328958045,"mc":[{"id":"1.195532877","rc":[{"atl":[[4.1,0],[4.2,75.51]],"id":43189004}],"con":true,"img":false}]}
{"op":"mcm","clk":"5323246176","pt":1646328958252,"mc":[{"id":"1.195532877","rc":[{"atl":[[4.4,61.17],[4.2,43.75]],"id":43189004}],"con":true,"img":false}]}
{"op":"mcm","clk":"5323246188","pt":1646328958363,"mc":[{"id":"1.195532877","rc":[{"atl":[[4.2,59.88]],"id":43189004},{"atb":[[2.3,0]],"id":38519823}],"con":true,"img":false}]}
{"op":"mcm","clk":"5323246199","pt":1646328958463,"mc":[{"id":"1.195532877","rc":[{"atl":[[4.3,3.52]],"id":43189004},{"atb":[[2.28,1.99]],"id":38519823},{"atl":[[3.9,8.9]],"id":38519823}],"con":true,"img":false}]}
{"op":"mcm","clk":"5323246211","pt":1646328958565,"mc":[{"id":"1.195532877","rc":[{"atl":[[4.2,43.75]],"id":43189004}],"con":true,"img":false}]}
{"op":"mcm","clk":"5323246223","pt":1646328958667,"mc":[{"id":"1.195532877","rc":[{"atb":[[2.34,0]],"id":43189004},{"atl":[[4.2,0]],"id":38519823}],"con":true,"img":false}]}
{"op":"mcm","clk":"5323246235","pt":1646328959275,"mc":[{"id":"1.195532877","rc":[{"atb":[[2.42,4.93]],"id":43189004},{"atl":[[4.3,17.86],[4.4,29.41]],"id":43189004}],"con":true,"img":false}]}
{"op":"mcm","clk":"5323246246","pt":1646328959315,"mc":[{"id":"1.195532877","rc":[{"atb":[[2.28,22.49]],"id":43189004}],"con":true,"img":false}]}
{"op":"mcm","clk":"5323246262","pt":1646328959326,"mc":[{"id":"1.195532877","rc":[{"atb":[[2.92,24.63]],"id":41696085},{"atb":[[2.4,9.43]],"id":42327927},{"atb":[[2.54,0]],"id":39236417}],"con":true,"img":false}]}
