{"op":"mcm","clk":"5305619432","pt":1646080581433,"mc":[{"id":"1.195395419","marketDefinition":{"bspMarket":true,"turnInPlayEnabled":false,"persistenceEnabled":false,"marketBaseRate":7.0,"eventId":"31270458","eventTypeId":"4339","numberOfWinners":1,"bettingType":"ODDS","marketType":"WIN","marketTime":"2022-03-01T02:00:00.000Z","suspendTime":"2022-03-01T02:00:00.000Z","bspReconciled":false,"complete":true,"inPlay":false,"crossMatching":false,"runnersVoidable":false,"numberOfActiveRunners":8,"betDelay":0,"status":"OPEN","runners":[{"status":"ACTIVE","sortPriority":1,"id":43154446,"name":"1. Magic Rogue"},{"status":"ACTIVE","sortPriority":2,"id":43154447,"name":"2. Youre Off"},{"status":"ACTIVE","sortPriority":3,"id":42352031,"name":"3. Castle Town"},{"status":"ACTIVE","sortPriority":4,"id":43154448,"name":"4. Buckle Up Aumond"},{"status":"ACTIVE","sortPriority":5,"id":42413752,"name":"5. Was That Then"},{"status":"ACTIVE","sortPriority":6,"id":42248828,"name":"6. Wheres Starc"},{"status":"ACTIVE","sortPriority":7,"id":41642357,"name":"7. Calgary Stampede"},{"status":"ACTIVE","sortPriority":8,"id":43154449,"name":"8. Tilikum Boloney"}],"regulators":["MR_INT"],"venue":"Devonport","countryCode":"AU","discountAllowed":true,"timezone":"Australia/Sydney","openDate":"2022-03-01T02:00:00.000Z","version":4380714800,"name":"R1 452m Gr6","eventName":"Devonport (AUS) 1st Mar"},"rc":[],"con":true,"img":false}]}
{"op":"mcm","clk":"5305743101","pt":1646082026907,"mc":[{"id":"1.195395419","rc":[{"atb":[[4.8,26.7],[4.3,30.75],[5.3,23.6],[6,20.29]],"id":42352031},{"atl":[[36,5.66],[19,7.34],[23,6],[28,7.34]],"id":42352031},{"spn":12.5,"spf":"NaN","id":42352031},{"atb":[[2.88,53.98],[2.78,57.02],[2.68,60.41],[3.05,49.5]],"id":42248828},{"atl":[[9.2,16.11],[10.5,20.87],[8.2,18.36],[13,16.52]],"id":42248828},{"spn":5.62,"spf":"NaN","id":42248828},{"atb":[[18,5.97],[21,5.07],[28,3.75],[15.5,6.99]],"id":42413752},{"atl":[[290,0.45],[340,0.58],[390,0.5],[240,0.55]],"id":42413752},{"spn":134.0,"spf":"NaN","id":42413752},{"atb":[[4.8,26.7],[4.3,30.75],[5.3,23.6],[6,20.29]],"id":43154448},{"atl":[[36,5.66],[19,7.34],[23,6],[28,7.34]],"id":43154448},{"spn":12.5,"spf":"NaN","id":43154448},{"atb":[[40,2.6],[25,4.22],[60,1.72],[30,3.5]],"id":41642357},{"atl":[[540,0.36],[390,0.34],[440,0.3],[490,0.4]],"id":41642357},{"spn":225.0,"spf":"NaN","id":41642357},{"atb":[[2.3,78.07],[2.44,70.48],[2.2,84.57],[2.1,92.26]],"id":43154449},{"atl":[[8.6,26.09],[5.8,27.54],[7.6,30.04],[6.6,23.6]],"id":43154449},{"spn":4.12,"spf":"NaN","id":43154449},{"atb":[[7.2,16.36],[9.2,12.37],[8.2,14.09],[11.5,9.66]],"id":43154446},{"atl":[[80,1.67],[160,1.24],[210,0.94],[110,1.21]],"id":43154446},{"spn":45.75,"spf":"NaN","id":43154446},{"atb":[[3.6,39.03],[3.95,34.4],[3.1,48.33],[3.35,43.19]],"id":43154447},{"atl":[[17.5,12.01],[20,10.43],[12.5,11.49],[15,9.44]],"id":43154447},{"spn":8.22,"spf":"NaN","id":43154447}],"con":true,"img":false}]}
{"op":"mcm","clk":"5305747392","pt":1646082083712,"mc":[{"id":"1.195395419","rc":[{"atb":[[4.8,0],[4.3,0],[5.3,0],[6,0]],"id":42352031},{"atl":[[36,0],[19,0],[23,0],[28,0]],"id":42352031},{"atb":[[2.88,0],[2.78,0],[2.68,0],[3.05,0]],"id":42248828},{"atl":[[9.2,0],[10.5,0],[8.2,0],[13,0]],"id":42248828},{"atb":[[18,0],[21,0],[28,0],[15.5,0]],"id":42413752},{"atl":[[290,0],[340,0],[390,0],[240,0]],"id":42413752},{"atb":[[4.8,0],[4.3,0],[5.3,0],[6,0]],"id":43154448},{"atl":[[36,0],[19,0],[23,0],[28,0]],"id":43154448},{"atb":[[40,0],[25,0],[60,0],[30,0]],"id":41642357},{"atl":[[540,0],[390,0],[440,0],[490,0]],"id":41642357},{"atb":[[2.3,0],[2.44,0],[2.2,0],[2.1,0]],"id":43154449},{"atl":[[8.6,0],[5.8,0],[7.6,0],[6.6,0]],"id":43154449},{"atb":[[7.2,0],[9.2,0],[8.2,0],[11.5,0]],"id":43154446},{"atl":[[80,0],[160,0],[210,0],[110,0]],"id":43154446},{"atb":[[3.6,0],[3.95,0],[3.1,0],[3.35,0]],"id":43154447},{"atl":[[17.5,0],[20,0],[12.5,0],[15,0]],"id":43154447}],"con":true,"img":false}]}
{"op":"mcm","clk":"5305747684","pt":1646082087094,"mc":[{"id":"1.195395419","rc":[{"atb":[[4.8,26.7],[4.3,30.75],[5.3,23.6],[6,20.29]],"id":42352031},{"atl":[[36,5.66],[19,7.34],[23,6],[28,7.34]],"id":42352031},{"atb":[[2.88,53.98],[2.78,57.02],[2.68,60.41],[3.05,49.5]],"id":42248828},{"atl":[[9.2,16.11],[10.5,20.87],[8.2,18.36],[13,16.52]],"id":42248828},{"atb":[[18,5.97],[21,5.07],[28,3.75],[15.5,6.99]],"id":42413752},{"atl":[[290,0.45],[340,0.58],[390,0.5],[240,0.55]],"id":42413752},{"atb":[[4.8,26.7],[4.3,30.75],[5.3,23.6],[6,20.29]],"id":43154448},{"atl":[[36,5.66],[19,7.34],[23,6],[28,7.34]],"id":43154448},{"atb":[[40,2.6],[25,4.22],[60,1.72],[30,3.5]],"id":41642357},{"atl":[[540,0.36],[390,0.34],[440,0.3],[490,0.4]],"id":41642357},{"atb":[[2.3,78.07],[2.44,70.48],[2.2,84.57],[2.1,92.26]],"id":43154449},{"atl":[[8.6,26.09],[5.8,27.54],[7.6,30.04],[6.6,23.6]],"id":43154449},{"atb":[[7.2,16.36],[9.2,12.37],[8.2,14.09],[11.5,9.66]],"id":43154446},{"atl":[[80,1.67],[160,1.24],[210,0.94],[110,1.21]],"id":43154446},{"atb":[[3.6,39.03],[3.95,34.4],[3.1,48.33],[3.35,43.19]],"id":43154447},{"atl":[[17.5,12.01],[20,10.43],[12.5,11.49],[15,9.44]],"id":43154447}],"con":true,"img":false}]}
{"op":"mcm","clk":"5305885847","pt":1646083972347,"mc":[{"id":"1.195395419","rc":[{"atb":[[4.8,0],[4.3,0],[5.3,0],[6,0]],"id":42352031},{"atl":[[36,0],[19,0],[23,0],[28,0]],"id":42352031},{"spn":"NaN","spf":"NaN","id":42352031},{"atb":[[2.88,0],[2.78,0],[2.68,0],[3.05,0]],"id":42248828},{"atl":[[9.2,0],[10.5,0],[8.2,0],[13,0]],"id":42248828},{"spn":"NaN","spf":"NaN","id":42248828},{"atb":[[18,0],[21,0],[28,0],[15.5,0]],"id":42413752},{"atl":[[290,0],[340,0],[390,0],[240,0]],"id":42413752},{"spn":"NaN","spf":"NaN","id":42413752},{"atb":[[4.8,0],[4.3,0],[5.3,0],[6,0]],"id":43154448},{"atl":[[36,0],[19,0],[23,0],[28,0]],"id":43154448},{"spn":"NaN","spf":"NaN","id":43154448},{"atb":[[40,0],[25,0],[60,0],[30,0]],"id":41642357},{"atl":[[540,0],[390,0],[440,0],[490,0]],"id":41642357},{"spn":"NaN","spf":"NaN","id":41642357},{"atb":[[2.3,0],[2.44,0],[2.2,0],[2.1,0]],"id":43154449},{"atl":[[8.6,0],[5.8,0],[7.6,0],[6.6,0]],"id":43154449},{"spn":"NaN","spf":"NaN","id":43154449},{"atb":[[7.2,0],[9.2,0],[8.2,0],[11.5,0]],"id":43154446},{"atl":[[80,0],[160,0],[210,0],[110,0]],"id":43154446},{"spn":"NaN","spf":"NaN","id":43154446}],"con":true,"img":false}]}
{"op":"mcm","clk":"5305886418","pt":1646083981498,"mc":[{"id":"1.195395419","rc":[{"atb":[[4.8,26.7],[4.3,30.75],[5.3,23.6],[6,20.29]],"id":42352031},{"atl":[[36,5.66],[19,7.34],[23,6],[28,7.34]],"id":42352031},{"atb":[[2.4,72.49],[2.54,65.9],[2.3,78.07],[2.2,84.57]],"id":42248828},{"atl":[[8,28.32],[9,24.78],[6,26.43],[7,22.03]],"id":42248828},{"atb":[[16,6.76],[18.5,5.79],[22,4.83],[29,3.62]],"id":42413752},{"atl":[[300,0.44],[350,0.56],[400,0.49],[250,0.53]],"id":42413752},{"atb":[[8,14.5],[5.8,21.14],[5.3,23.6],[6.6,18.12]],"id":43154448},{"atl":[[65,3.09],[36,3.77],[90,2.23],[46,2.93]],"id":43154448},{"atb":[[32,3.27],[42,2.47],[90,1.14],[55,1.87]],"id":41642357},{"atl":[[530,0.24],[580,0.22],[630,0.31],[680,0.29]],"id":41642357},{"atb":[[2.3,78.07],[2.44,70.48],[2.2,84.57],[2.1,92.26]],"id":43154449},{"atl":[[8.6,26.09],[5.8,27.54],[7.6,30.04],[6.6,23.6]],"id":43154449},{"atb":[[7.2,16.36],[9.2,12.37],[8.2,14.09],[11.5,9.66]],"id":43154446},{"atl":[[80,1.67],[160,1.24],[210,0.94],[110,1.21]],"id":43154446}],"con":true,"img":false}]}
{"op":"mcm","clk":"5305889404","pt":1646084033069,"mc":[{"id":"1.195395419","rc":[{"atb":[[4.8,0],[4.3,0],[5.3,0],[6,0]],"id":42352031},{"atl":[[36,0],[19,0],[23,0],[28,0]],"id":42352031},{"spn":4.27,"spf":"NaN","id":42248828},{"atb":[[16,0],[18.5,0],[22,0],[29,0]],"id":42413752},{"atl":[[300,0],[350,0],[400,0],[250,0]],"id":42413752},{"atb":[[8,0],[5.8,0],[5.3,0],[6.6,0]],"id":43154448},{"atl":[[65,0],[36,0],[90,0],[46,0]],"id":43154448},{"atb":[[32,0],[42,0],[90,0],[55,0]],"id":41642357},{"atl":[[530,0],[580,0],[630,0],[680,0]],"id":41642357},{"atb":[[2.3,0],[2.44,0],[2.2,0],[2.1,0]],"id":43154449},{"atl":[[8.6,0],[5.8,0],[7.6,0],[6.6,0]],"id":43154449},{"spn":45.75,"spf":"NaN","id":43154446}],"con":true,"img":false}]}
{"op":"mcm","clk":"5305889678","pt":1646084040462,"mc":[{"id":"1.195395419","rc":[{"atb":[[4.5,28.99],[6.4,18.79],[5,25.37],[5.5,22.55]],"id":42352031},{"atl":[[19.5,7.14],[38,5.35],[24,5.74],[29,7.08]],"id":42352031},{"atb":[[16.5,6.54],[19,5.64],[23,4.61],[30,3.5]],"id":42413752},{"atl":[[260,0.5],[310,0.42],[360,0.55],[410,0.48]],"id":42413752},{"atb":[[4.8,26.7],[4.3,30.75],[5.3,23.6],[6,20.29]],"id":43154448},{"atl":[[36,5.66],[19,7.34],[23,6],[28,7.34]],"id":43154448},{"atb":[[38,2.74],[24,4.41],[55,1.87],[29,3.62]],"id":41642357},{"atl":[[530,0.37],[380,0.34],[430,0.3],[480,0.41]],"id":41642357},{"atb":[[2.4,72.49],[2.54,65.9],[2.3,78.07],[2.2,84.57]],"id":43154449},{"atl":[[8,28.32],[9,24.78],[6,26.43],[7,22.03]],"id":43154449}],"con":true,"img":false}]}
{"op":"mcm","clk":"5305990501","pt":1646086602698,"mc":[{"id":"1.195395419","marketDefinition":{"bspMarket":true,"turnInPlayEnabled":false,"persistenceEnabled":false,"marketBaseRate":7.0,"eventId":"31270458","eventTypeId":"4339","numberOfWinners":1,"bettingType":"ODDS","marketType":"WIN","marketTime":"2022-03-01T02:00:00.000Z","suspendTime":"2022-03-01T02:00:00.000Z","bspReconciled":false,"complete":true,"inPlay":false,"crossMatching":false,"runnersVoidable":false,"numberOfActiveRunners":8,"betDelay":0,"status":"OPEN","runners":[{"status":"ACTIVE","sortPriority":1,"id":43154446,"name":"1. Magic Rogue"},{"status":"ACTIVE","sortPriority":2,"id":43154447,"name":"2. Youre Off"},{"status":"ACTIVE","sortPriority":3,"id":42352031,"name":"3. Castle Town"},{"status":"ACTIVE","sortPriority":4,"id":43154448,"name":"4. Buckle Up Aumond"},{"status":"ACTIVE","sortPriority":5,"id":42413752,"name":"5. Was That Then"},{"status":"ACTIVE","sortPriority":6,"id":42248828,"name":"6. Wheres Starc"},{"status":"ACTIVE","sortPriority":7,"id":41642357,"name":"7. Calgary Stampede"},{"status":"ACTIVE","sortPriority":8,"id":43154449,"name":"8. Tilikum Boloney"}],"regulators":["MR_INT"],"venue":"Devonport","countryCode":"AU","discountAllowed":true,"timezone":"Australia/Sydney","openDate":"2022-03-01T02:00:00.000Z","version":4380714800,"name":"R1 452m Gr6","eventName":"Devonport (AUS) 1st Mar"},"rc":[{"atb":[[4.5,28.99],[6.4,18.79],[5,25.37],[5.5,22.55]],"id":42352031},{"atl":[[19.5,7.14],[38,5.35],[24,5.74],[29,7.07]],"id":42352031},{"spn":12.95,"spf":"NaN","id":42352031},{"atb":[[2.4,72.48],[2.54,65.89],[2.3,78.05],[2.2,84.56]],"id":42248828},{"atl":[[8,28.32],[9,24.78],[6,26.43],[7,22.02]],"id":42248828},{"spn":4.27,"spf":"NaN","id":42248828},{"atb":[[16.5,6.54],[19,5.63],[23,4.61],[30,3.5]],"id":42413752},{"atl":[[260,0.5],[310,0.42],[360,0.55],[410,0.48]],"id":42413752},{"spn":145.0,"spf":"NaN","id":42413752},{"atb":[[4.8,26.7],[4.3,30.75],[5.3,23.59],[6,20.29]],"id":43154448},{"atl":[[36,5.66],[19,7.34],[23,6],[28,7.34]],"id":43154448},{"spn":12.5,"spf":"NaN","id":43154448},{"atb":[[38,2.74],[24,4.41],[55,1.87],[29,3.62]],"id":41642357},{"atl":[[530,0.37],[380,0.34],[430,0.3],[480,0.41]],"id":41642357},{"spn":217.5,"spf":"NaN","id":41642357},{"atb":[[2.4,72.48],[2.54,65.89],[2.3,78.05],[2.2,84.56]],"id":43154449},{"atl":[[8,28.32],[9,24.78],[6,26.43],[7,22.02]],"id":43154449},{"spn":4.27,"spf":"NaN","id":43154449},{"atb":[[7.2,16.36],[9.2,12.37],[8.2,14.09],[11.5,9.66]],"id":43154446},{"atl":[[80,1.67],[160,1.24],[210,0.94],[110,1.21]],"id":43154446},{"spn":45.75,"spf":"NaN","id":43154446},{"atb":[[3.6,39.03],[3.95,34.39],[3.1,48.32],[3.35,43.18]],"id":43154447},{"atl":[[17.5,12.01],[20,10.43],[12.5,11.48],[15,9.43]],"id":43154447},{"spn":8.22,"spf":"NaN","id":43154447}],"con":true,"img":true}]}
{"op":"mcm","clk":"5306102093","pt":1646089390925,"mc":[{"id":"1.195395419","rc":[{"atb":[[4.5,28.99],[6.4,18.79],[5,25.37],[5.5,22.55]],"id":42352031},{"spl":[[100,2]],"id":42352031},{"atl":[[19.5,7.14],[38,5.35],[24,5.74],[29,7.07]],"id":42352031},{"spn":12.95,"spf":1.0,"id":42352031},{"atb":[[2.4,72.48],[2.54,65.89],[2.3,78.05],[2.2,84.56]],"id":42248828},{"spl":[[100,2]],"id":42248828},{"atl":[[8,28.32],[9,24.78],[6,26.43],[7,22.02]],"id":42248828},{"spn":4.27,"spf":1.0,"id":42248828},{"atb":[[16.5,6.54],[19,5.63],[23,4.61],[30,3.5]],"id":42413752},{"spl":[[100,2]],"id":42413752},{"spn":65.0,"spf":1.0,"id":42413752},{"atb":[[4.8,26.7],[4.3,30.75],[5.3,23.59],[6,20.29]],"id":43154448},{"spl":[[100,2]],"id":43154448},{"atl":[[36,5.66],[19,7.34],[23,6],[28,7.34]],"id":43154448},{"spn":12.5,"spf":1.0,"id":43154448},{"atb":[[38,2.74],[24,4.41],[55,1.87],[29,3.62]],"id":41642357},{"spl":[[100,2]],"id":41642357},{"spn":77.5,"spf":1.0,"id":41642357},{"atb":[[2.4,72.48],[2.54,65.89],[2.3,78.05],[2.2,84.56]],"id":43154449},{"spl":[[100,2]],"id":43154449},{"atl":[[8,28.32],[9,24.78],[6,26.43],[7,22.02]],"id":43154449},{"spn":4.27,"spf":1.0,"id":43154449},{"atb":[[7.2,16.36],[9.2,12.37],[8.2,14.09],[11.5,9.66]],"id":43154446},{"spl":[[100,2]],"id":43154446},{"atl":[[80,1.67],[160,1.24],[210,0.94],[110,1.21]],"id":43154446},{"spn":45.75,"spf":1.0,"id":43154446},{"atb":[[3.6,39.03],[3.95,34.39],[3.1,48.32],[3.35,43.18]],"id":43154447},{"spl":[[100,2]],"id":43154447},{"atl":[[17.5,12.01],[20,10.43],[12.5,11.48],[15,9.43]],"id":43154447},{"spn":8.22,"spf":1.0,"id":43154447}],"con":true,"img":false}]}
{"op":"mcm","clk":"5306159286","pt":1646091202116,"mc":[{"id":"1.195395419","rc":[{"atb":[[4.5,0],[6.4,0],[5,0],[5.5,0]],"id":42352031},{"atl":[[19.5,0],[38,0],[24,0],[29,0]],"id":42352031},{"spn":1.0,"spf":1.0,"id":42352031},{"atb":[[2.4,0],[2.54,0],[2.3,0],[2.2,0]],"id":42248828},{"atl":[[8,0],[9,0],[6,0],[7,0]],"id":42248828},{"spn":1.0,"spf":1.0,"id":42248828},{"atb":[[16.5,0],[19,0],[23,0],[30,0]],"id":42413752},{"atl":[[260,0],[310,0],[360,0],[410,0]],"id":42413752},{"spn":1.0,"spf":1.0,"id":42413752},{"atb":[[4.8,0],[4.3,0],[5.3,0],[6,0]],"id":43154448},{"atl":[[36,0],[19,0],[23,0],[28,0]],"id":43154448},{"spn":1.0,"spf":1.0,"id":43154448},{"atb":[[2.4,0],[2.54,0],[2.3,0],[2.2,0]],"id":43154449},{"atl":[[8,0],[9,0],[6,0],[7,0]],"id":43154449},{"spn":1.0,"spf":1.0,"id":43154449},{"atb":[[7.2,0],[9.2,0],[8.2,0],[11.5,0]],"id":43154446},{"atl":[[80,0],[160,0],[210,0],[110,0]],"id":43154446},{"spn":1.0,"spf":1.0,"id":43154446},{"atb":[[3.6,0],[3.95,0],[3.1,0],[3.35,0]],"id":43154447},{"atl":[[17.5,0],[20,0],[12.5,0],[15,0]],"id":43154447},{"spn":1.0,"spf":1.0,"id":43154447}],"con":true,"img":false}]}
{"op":"mcm","clk":"5306159532","pt":1646091208487,"mc":[{"id":"1.195395419","rc":[{"atb":[[4.8,26.7],[5.8,21.13],[5.3,23.59],[7,16.91]],"id":42352031},{"atl":[[38,5.35],[24,5.74],[48,4.21],[29,4.71]],"id":42352031},{"atb":[[2.4,72.48],[2.5,67.65],[2.3,78.05],[2.64,61.87]],"id":42248828},{"atl":[[7.2,21.31],[9.2,24.17],[6.2,25.41],[8.2,27.53]],"id":42248828},{"atb":[[18.5,5.79],[10,11.27],[12.5,8.82],[15,7.24]],"id":42413752},{"atl":[[150,0.88],[300,0.66],[200,0.66],[250,0.79]],"id":42413752},{"atb":[[8,14.49],[6,20.29],[7,16.91],[9.4,12.07]],"id":43154448},{"atl":[[75,1.78],[150,1.33],[50,2.69],[100,2]],"id":43154448},{"atb":[[2.4,72.48],[2.54,65.89],[2.3,78.05],[2.2,84.56]],"id":43154449},{"atl":[[8,28.32],[9,24.78],[6,26.43],[7,22.02]],"id":43154449},{"atb":[[8,14.49],[9,12.68],[10,11.27],[13.5,8.11]],"id":43154446},{"atl":[[150,0.88],[100,1.33],[200,0.99],[250,0.79]],"id":43154446},{"atb":[[3.45,41.41],[3.2,46.12],[4.1,32.73],[3.7,37.58]],"id":43154447},{"atl":[[16,8.81],[18.5,11.32],[22,9.43],[13.5,10.57]],"id":43154447}],"con":true,"img":false}]}
{"op":"mcm","clk":"5306160261","pt":1646091226208,"mc":[{"id":"1.195395419","rc":[{"atb":[[2.68,4.87]],"id":42248828},{"atb":[[2.58,5.18]],"id":43154449},{"atb":[[4.2,2.55]],"id":43154447}],"con":true,"img":false}]}
{"op":"mcm","clk":"5306162451","pt":1646091280083,"mc":[{"id":"1.195395419","rc":[{"spn":15.5,"spf":1.0,"id":42352031},{"spn":4.44,"spf":1.0,"id":42248828},{"spn":59.25,"spf":1.0,"id":42413752},{"spn":29.7,"spf":1.0,"id":43154448},{"spn":4.29,"spf":1.0,"id":43154449},{"spn":56.75,"spf":1.0,"id":43154446},{"atb":[[4.2,5.42]],"id":43154447},{"spn":8.85,"spf":1.0,"id":43154447}],"con":true,"img":false}]}
{"op":"mcm","clk":"5306162454","pt":1646091280186,"mc":[{"id":"1.195395419","rc":[{"atb":[[2.68,10.34]],"id":42248828}],"con":true,"img":false}]}
{"op":"mcm","clk":"5306162461","pt":1646091280390,"mc":[{"id":"1.195395419","rc":[{"atb":[[2.58,11]],"id":43154449}],"con":true,"img":false}]}
{"op":"mcm","clk":"5306163023","pt":1646091292918,"mc":[{"id":"1.195395419","rc":[{"atb":[[18.5,0],[10,0],[12.5,0],[15,0]],"id":42413752},{"atl":[[150,0],[300,0],[200,0],[250,0]],"id":42413752}],"con":true,"img":false}]}
{"op":"mcm","clk":"5306163249","pt":1646091298508,"mc":[{"id":"1.195395419","rc":[{"atb":[[12,9.22],[9.8,11.53],[8.8,13.01],[15.5,6.99]],"id":42413752},{"atl":[[270,0.73],[170,0.77],[220,0.9],[120,1.1]],"id":42413752}],"con":true,"img":false}]}
{"op":"mcm","clk":"5306165600","pt":1646091353676,"mc":[{"id":"1.195395419","rc":[{"atb":[[4.8,0],[5.8,0],[5.3,0],[7,0]],"id":42352031},{"atl":[[38,0],[24,0],[48,0],[29,0]],"id":42352031},{"spn":1.0,"spf":1.0,"id":42352031},{"spn":57.75,"spf":1.0,"id":42413752}],"con":true,"img":false}]}
{"op":"mcm","clk":"5306165874","pt":1646091361214,"mc":[{"id":"1.195395419","rc":[{"atb":[[4.8,26.7],[5.8,21.13],[5.3,23.59],[7,16.91]],"id":42352031},{"atl":[[38,5.35],[24,5.74],[48,4.21],[29,4.71]],"id":42352031}],"con":true,"img":false}]}
{"op":"mcm","clk":"5306175550","pt":1646091627049,"mc":[{"id":"1.195395419","rc":[{"spn":15.5,"spf":1.0,"id":42352031},{"spl":[[1.01,3.78]],"id":43154449},{"spn":2.58,"spf":1.0,"id":43154449}],"con":true,"img":false}]}
{"op":"mcm","clk":"5306226925","pt":1646092800136,"mc":[{"id":"1.195395419","rc":[{"atb":[[7.2,1.62]],"id":42352031},{"spn":15.6,"spf":1.0,"id":42352031},{"atb":[[2.64,63.87]],"id":42248828},{"atb":[[17,0.64]],"id":42413752},{"spn":58.5,"spf":1.0,"id":42413752},{"atb":[[9.6,1.17]],"id":43154448},{"spn":29.8,"spf":1.0,"id":43154448},{"atb":[[70,0.15]],"id":41642357},{"spn":85.0,"spf":1.0,"id":41642357},{"atb":[[2.42,2]],"id":43154449},{"atb":[[15.5,0.7]],"id":43154446},{"spn":57.75,"spf":1.0,"id":43154446},{"atb":[[4.3,2]],"id":43154447},{"spn":8.9,"spf":1.0,"id":43154447}],"con":true,"img":false}]}
{"op":"mcm","clk":"5306227686","pt":1646092815042,"mc":[{"id":"1.195395419","rc":[{"atb":[[4.8,26.68],[5.8,21.12],[5.3,23.58],[7,16.9]],"id":42352031},{"atl":[[38,5.35],[24,5.74],[48,4.21],[29,4.71]],"id":42352031},{"atb":[[2.4,72.43],[2.5,67.6],[2.3,78],[2.64,63.83],[2.68,10.33]],"id":42248828},{"atl":[[7.2,21.3],[9.2,24.16],[6.2,25.39],[8.2,27.51]],"id":42248828},{"atb":[[17,0],[12,9.22],[9.8,11.52],[8.8,13],[15.5,6.99]],"id":42413752},{"atl":[[270,0.73],[170,0.77],[220,0.9],[120,1.1]],"id":42413752},{"atb":[[9.6,0],[8,14.48],[6,20.28],[7,16.9],[9.4,12.07]],"id":43154448},{"atl":[[75,1.78],[150,1.33],[50,2.69],[100,2]],"id":43154448},{"atb":[[38,2.74],[24,4.4],[55,1.87],[29,3.62]],"id":41642357},{"atl":[[530,0.37],[380,0.34],[430,0.3],[480,0.41]],"id":41642357},{"atb":[[2.4,72.43],[2.54,65.84],[2.3,78],[2.58,11],[2.2,84.5]],"id":43154449},{"spl":[[1.01,3.78]],"id":43154449},{"atl":[[8,28.3],[9,24.76],[6,26.41],[7,22.01]],"id":43154449},{"atb":[[8,14.48],[9,12.67],[10,11.26],[13.5,8.11]],"id":43154446},{"atl":[[150,0.88],[100,1.33],[200,0.99],[250,0.79]],"id":43154446},{"atb":[[3.45,41.39],[3.2,46.09],[4.1,32.71],[3.7,37.55],[4.2,5.42]],"id":43154447},{"atl":[[16,8.8],[18.5,11.32],[22,9.43],[13.5,10.56]],"id":43154447}],"con":true,"img":false}]}
{"op":"mcm","clk":"5306227695","pt":1646092815143,"mc":[{"id":"1.195395419","rc":[{"atb":[[17.5,0.62]],"id":42413752},{"atb":[[9.4,13.27]],"id":43154448}],"con":true,"img":false}]}
{"op":"mcm","clk":"5306228186","pt":1646092828246,"mc":[{"id":"1.195395419","marketDefinition":{"bspMarket":true,"turnInPlayEnabled":false,"persistenceEnabled":false,"marketBaseRate":7.0,"eventId":"31270458","eventTypeId":"4339","numberOfWinners":1,"bettingType":"ODDS","marketType":"WIN","marketTime":"2022-03-01T02:00:00.000Z","suspendTime":"2022-03-01T02:00:00.000Z","bspReconciled":false,"complete":true,"inPlay":false,"crossMatching":true,"runnersVoidable":false,"numberOfActiveRunners":8,"betDelay":0,"status":"OPEN","runners":[{"status":"ACTIVE","sortPriority":1,"id":43154446,"name":"1. Magic Rogue"},{"status":"ACTIVE","sortPriority":2,"id":43154447,"name":"2. Youre Off"},{"status":"ACTIVE","sortPriority":3,"id":42352031,"name":"3. Castle Town"},{"status":"ACTIVE","sortPriority":4,"id":43154448,"name":"4. Buckle Up Aumond"},{"status":"ACTIVE","sortPriority":5,"id":42413752,"name":"5. Was That Then"},{"status":"ACTIVE","sortPriority":6,"id":42248828,"name":"6. Wheres Starc"},{"status":"ACTIVE","sortPriority":7,"id":41642357,"name":"7. Calgary Stampede"},{"status":"ACTIVE","sortPriority":8,"id":43154449,"name":"8. Tilikum Boloney"}],"regulators":["MR_INT"],"venue":"Devonport","countryCode":"AU","discountAllowed":true,"timezone":"Australia/Sydney","openDate":"2022-03-01T02:00:00.000Z","version":4380714800,"name":"R1 452m Gr6","eventName":"Devonport (AUS) 1st Mar"},"rc":[],"con":true,"img":false}]}
{"op":"mcm","clk":"5306229143","pt":1646092850368,"mc":[{"id":"1.195395419","rc":[{"atb":[[7.2,0]],"id":42352031},{"atb":[[4.3,0]],"id":43154447}],"con":true,"img":false}]}
{"op":"mcm","clk":"5306229151","pt":1646092850472,"mc":[{"id":"1.195395419","rc":[{"atb":[[7.6,1.53]],"id":42352031},{"atb":[[4.4,2]],"id":43154447}],"con":true,"img":false}]}
{"op":"mcm","clk":"5306229431","pt":1646092858395,"mc":[{"id":"1.195395419","rc":[{"atb":[[7.6,0]],"id":42352031},{"atb":[[2.64,61.83]],"id":42248828},{"atb":[[4.4,0]],"id":43154447}],"con":true,"img":false}]}
{"op":"mcm","clk":"5306229434","pt":1646092858498,"mc":[{"id":"1.195395419","rc":[{"atb":[[7.2,1.62]],"id":42352031},{"atb":[[2.62,2]],"id":42248828},{"atb":[[4.3,2]],"id":43154447}],"con":true,"img":false}]}
{"op":"mcm","clk":"5306249862","pt":1646093420095,"mc":[{"id":"1.195395419","rc":[{"spn":58.75,"spf":1.0,"id":42413752},{"spn":29.7,"spf":1.0,"id":43154448},{"atb":[[2.42,0]],"id":43154449}],"con":true,"img":false}]}
{"op":"mcm","clk":"5306249866","pt":1646093420195,"mc":[{"id":"1.195395419","rc":[{"atb":[[2.32,2]],"id":43154449}],"con":true,"img":false}]}
{"op":"mcm","clk":"5306254717","pt":1646093538759,"mc":[{"id":"1.195395419","rc":[{"atb":[[9.4,12.07]],"id":43154448}],"con":true,"img":false}]}
{"op":"mcm","clk":"5306254723","pt":1646093538863,"mc":[{"id":"1.195395419","rc":[{"atb":[[9.6,1.17]],"id":43154448}],"con":true,"img":false}]}
{"op":"mcm","clk":"5306291754","pt":1646094610656,"mc":[{"id":"1.195395419","rc":[{"atb":[[4,24]],"id":42352031},{"spn":29.8,"spf":1.0,"id":43154448},{"atb":[[7.2,11.61]],"id":43154446},{"atb":[[2.64,43.9]],"id":43154447}],"con":true,"img":false}]}
{"op":"mcm","clk":"5306291759","pt":1646094610756,"mc":[{"id":"1.195395419","rc":[{"atb":[[2.62,46.3]],"id":42352031},{"atl":[[60,8.2]],"id":42352031},{"atb":[[1.76,94.74]],"id":42248828},{"atl":[[17,8.5],[11,8.2]],"id":42248828},{"atb":[[8.2,10],[2.62,46.3],[4.2,26.56]],"id":42413752},{"atb":[[5.2,17.14],[2.62,46.3]],"id":43154448},{"atb":[[2.62,46.3],[4.2,26.56]],"id":41642357},{"atb":[[1.72,100]],"id":43154449},{"atl":[[10.5,8.2]],"id":43154449},{"atb":[[2.62,46.3],[4.2,26.56]],"id":43154446},{"atl":[[25,8.2]],"id":43154447}],"con":true,"img":false}]}
{"op":"mcm","clk":"5306291764","pt":1646094610859,"mc":[{"id":"1.195395419","rc":[{"atl":[[34,13.5]],"id":42248828},{"atl":[[17,8.5]],"id":43154449}],"con":true,"img":false}]}
{"op":"mcm","clk":"5306291771","pt":1646094610961,"mc":[{"id":"1.195395419","rc":[{"atl":[[34,13.5]],"id":43154449}],"con":true,"img":false}]}
{"op":"mcm","clk":"5306296488","pt":1646094746297,"mc":[{"id":"1.195395419","rc":[{"atb":[[7.2,10.97],[6,24.39]],"id":42352031},{"atl":[[17.5,3.51],[23,5.43]],"id":42352031},{"spn":12.35,"spf":1.0,"id":42352031},{"atb":[[2.52,80.95],[2.66,34.94]],"id":42248828},{"atl":[[5,14.5],[6,24.6]],"id":42248828},{"spn":3.84,"spf":1.0,"id":42248828},{"atb":[[16,3.86],[13.5,9.62]],"id":42413752},{"atl":[[70,2.7],[55,2.7]],"id":42413752},{"spn":36.25,"spf":1.0,"id":42413752},{"atb":[[9.6,7.91],[8.2,18.38]],"id":43154448},{"atl":[[23,2.7],[30,4.32]],"id":43154448},{"spn":16.3,"spf":1.0,"id":43154448},{"atb":[[46,2.7],[60,2.7]],"id":41642357},{"atl":[[830,2.7],[470,0.12]],"id":41642357},{"atb":[[2.02,112.67],[2.32,45.94]],"id":43154449},{"atl":[[4.1,18.71],[5.2,23.45]],"id":43154449},{"atb":[[14,9.73],[14.5,4.29]],"id":43154446},{"atl":[[48,2.7],[60,2.7]],"id":43154446},{"spn":31.75,"spf":1.0,"id":43154446},{"atb":[[4.2,56.76]],"id":43154447},{"atl":[[9.2,7.07],[12,8.85]],"id":43154447},{"spn":6.75,"spf":1.0,"id":43154447}],"con":true,"img":false}]}
{"op":"mcm","clk":"5306296690","pt":1646094753999,"mc":[{"id":"1.195395419","rc":[{"atb":[[2.68,5.46]],"id":42248828},{"atb":[[4.2,54.2]],"id":43154447}],"con":true,"img":false}]}
{"op":"mcm","clk":"5306296914","pt":1646094760824,"mc":[{"id":"1.195395419","rc":[{"atb":[[16,4.8]],"id":41642357}],"con":true,"img":false}]}
{"op":"mcm","clk":"5306296968","pt":1646094762588,"mc":[{"id":"1.195395419","rc":[{"atb":[[2.68,0]],"id":42248828},{"atb":[[4.2,51.34]],"id":43154447}],"con":true,"img":false}]}
{"op":"mcm","clk":"5306297055","pt":1646094765918,"mc":[{"id":"1.195395419","rc":[{"atb":[[2.7,5.29]],"id":42248828},{"atb":[[4.3,4.73]],"id":43154447}],"con":true,"img":false}]}
{"op":"mcm","clk":"5306297164","pt":1646094768538,"mc":[{"id":"1.195395419","rc":[{"atb":[[2.7,10.7]],"id":42248828}],"con":true,"img":false}]}
{"op":"mcm","clk":"5306297174","pt":1646094768693,"mc":[{"id":"1.195395419","rc":[{"atb":[[4.3,7.51]],"id":43154447}],"con":true,"img":false}]}
{"op":"mcm","clk":"5306317342","pt":1646095368963,"mc":[{"id":"1.195395419","rc":[{"spn":3.85,"spf":1.0,"id":42248828},{"atl":[[34,13.5]],"id":43154447}],"con":true,"img":false}]}
{"op":"mcm","clk":"5306329922","pt":1646095661376,"mc":[{"id":"1.195395419","rc":[{"atl":[[55,8.2]],"id":43154448}],"con":true,"img":false}]}
{"op":"mcm","clk":"5306368048","pt":1646096600749,"mc":[{"id":"1.195395419","rc":[{"atl":[[1000,2.23]],"id":42413752},{"atl":[[1000,2.23]],"id":43154446}],"con":true,"img":false}]}
{"op":"mcm","clk":"5306368052","pt":1646096600848,"mc":[{"id":"1.195395419","rc":[{"atb":[[1.03,2.23]],"id":42352031},{"atb":[[1.01,2.23]],"id":43154447}],"con":true,"img":false}]}
{"op":"mcm","clk":"5306368058","pt":1646096600956,"mc":[{"id":"1.195395419","rc":[{"atb":[[1.02,2.23]],"id":43154448}],"con":true,"img":false}]}
{"op":"mcm","clk":"5306368064","pt":1646096601155,"mc":[{"id":"1.195395419","rc":[{"atb":[[1.01,0.84]],"id":43154447}],"con":true,"img":false}]}
{"op":"mcm","clk":"5306368073","pt":1646096601365,"mc":[{"id":"1.195395419","rc":[{"atl":[[1000,0.08]],"id":43154446}],"con":true,"img":false}]}
{"op":"mcm","clk":"5306368084","pt":1646096601524,"mc":[{"id":"1.195395419","rc":[{"atb":[[1.02,0.37]],"id":43154448}],"con":true,"img":false}]}
{"op":"mcm","clk":"5306368088","pt":1646096601625,"mc":[{"id":"1.195395419","rc":[{"atb":[[1.03,0.5]],"id":42352031}],"con":true,"img":false}]}
{"op":"mcm","clk":"5306368092","pt":1646096601725,"mc":[{"id":"1.195395419","rc":[{"atl":[[1000,0.07]],"id":42413752}],"con":true,"img":false}]}
{"op":"mcm","clk":"5306368099","pt":1646096601931,"mc":[{"id":"1.195395419","rc":[{"atb":[[1.01,0]],"id":43154447}],"con":true,"img":false}]}
{"op":"mcm","clk":"5306368101","pt":1646096602034,"mc":[{"id":"1.195395419","rc":[{"atb":[[4.4,0.84]],"id":43154447}],"con":true,"img":false}]}
{"op":"mcm","clk":"5306368112","pt":1646096602241,"mc":[{"id":"1.195395419","rc":[{"atl":[[1000,0]],"id":43154446}],"con":true,"img":false}]}
{"op":"mcm","clk":"5306368114","pt":1646096602341,"mc":[{"id":"1.195395419","rc":[{"atl":[[46,0.08]],"id":43154446}],"con":true,"img":false}]}
{"op":"mcm","clk":"5306368119","pt":1646096602445,"mc":[{"id":"1.195395419","rc":[{"atb":[[1.02,0]],"id":43154448}],"con":true,"img":false}]}
{"op":"mcm","clk":"5306368122","pt":1646096602545,"mc":[{"id":"1.195395419","rc":[{"atb":[[9.8,0.37]],"id":43154448}],"con":true,"img":false}]}
{"op":"mcm","clk":"5306368129","pt":1646096602754,"mc":[{"id":"1.195395419","rc":[{"atb":[[1.03,0]],"id":42352031}],"con":true,"img":false}]}
{"op":"mcm","clk":"5306368133","pt":1646096602854,"mc":[{"id":"1.195395419","rc":[{"atb":[[7.4,0.5]],"id":42352031}],"con":true,"img":false}]}
{"op":"mcm","clk":"5306368141","pt":1646096603059,"mc":[{"id":"1.195395419","rc":[{"atl":[[1000,0]],"id":42413752}],"con":true,"img":false}]}
{"op":"mcm","clk":"5306368145","pt":1646096603164,"mc":[{"id":"1.195395419","rc":[{"atl":[[50,0.07]],"id":42413752}],"con":true,"img":false}]}
{"op":"mcm","clk":"5306369174","pt":1646096630771,"mc":[{"id":"1.195395419","rc":[{"atb":[[1.03,2.23]],"id":43154446}],"con":true,"img":false}]}
{"op":"mcm","clk":"5306369180","pt":1646096630875,"mc":[{"id":"1.195395419","rc":[{"atb":[[1.03,2.23]],"id":42413752}],"con":true,"img":false}]}
{"op":"mcm","clk":"5306369196","pt":1646096631286,"mc":[{"id":"1.195395419","rc":[{"atb":[[1.03,0.2]],"id":42413752}],"con":true,"img":false}]}
{"op":"mcm","clk":"5306369206","pt":1646096631492,"mc":[{"id":"1.195395419","rc":[{"atb":[[1.03,0.23]],"id":43154446}],"con":true,"img":false}]}
{"op":"mcm","clk":"5306369210","pt":1646096631594,"mc":[{"id":"1.195395419","rc":[{"atb":[[1.03,0]],"id":42413752}],"con":true,"img":false}]}
{"op":"mcm","clk":"5306369214","pt":1646096631698,"mc":[{"id":"1.195395419","rc":[{"atb":[[18,0.2]],"id":42413752}],"con":true,"img":false}]}
{"op":"mcm","clk":"5306369222","pt":1646096631855,"mc":[{"id":"1.195395419","rc":[{"atb":[[1.03,0]],"id":43154446}],"con":true,"img":false}]}
{"op":"mcm","clk":"5306369228","pt":1646096631958,"mc":[{"id":"1.195395419","rc":[{"atb":[[16,0.23]],"id":43154446}],"con":true,"img":false}]}
{"op":"mcm","clk":"5306398355","pt":1646097401782,"mc":[{"id":"1.195395419","rc":[{"spn":12.45,"spf":1.0,"id":42352031},{"spn":34.0,"spf":1.0,"id":42413752},{"spn":16.4,"spf":1.0,"id":43154448},{"atb":[[2.58,0]],"id":43154449},{"atl":[[2.58,0.99]],"id":43154449},{"trd":[[2.58,22.01]],"ltp":2.58,"tv":22.01,"id":43154449},{"spn":2.54,"spf":1.0,"id":43154449},{"spn":31.0,"spf":1.0,"id":43154446},{"spn":6.8,"spf":1.0,"id":43154447}],"con":true,"img":false}]}
{"op":"mcm","clk":"5306406238","pt":1646097404753,"mc":[{"id":"1.195395419","rc":[{"atl":[[2.98,4.49]],"id":43154449}],"con":true,"img":false}]}
{"op":"mcm","clk":"5306408989","pt":1646097483895,"mc":[{"id":"1.195395419","rc":[{"atl":[[2.92,5.13]],"id":43154449}],"con":true,"img":false}]}
{"op":"mcm","clk":"5306409081","pt":1646097485905,"mc":[{"id":"1.195395419","rc":[{"atl":[[2.98,0]],"id":43154449}],"con":true,"img":false}]}
{"op":"mcm","clk":"5306409088","pt":1646097486003,"mc":[{"id":"1.195395419","rc":[{"atl":[[2.86,4.67]],"id":43154449}],"con":true,"img":false}]}
{"op":"mcm","clk":"5306409273","pt":1646097489791,"mc":[{"id":"1.195395419","rc":[{"atl":[[2.92,0]],"id":43154449}],"con":true,"img":false}]}
{"op":"mcm","clk":"5306409283","pt":1646097490000,"mc":[{"id":"1.195395419","rc":[{"atl":[[2.8,5.35]],"id":43154449}],"con":true,"img":false}]}
{"op":"mcm","clk":"5306409366","pt":1646097492007,"mc":[{"id":"1.195395419","rc":[{"atl":[[2.86,0]],"id":43154449}],"con":true,"img":false}]}
{"op":"mcm","clk":"5306409372","pt":1646097492113,"mc":[{"id":"1.195395419","rc":[{"atl":[[2.74,4.88]],"id":43154449}],"con":true,"img":false}]}
{"op":"mcm","clk":"5306409536","pt":1646097496128,"mc":[{"id":"1.195395419","rc":[{"atl":[[2.8,0]],"id":43154449}],"con":true,"img":false}]}
{"op":"mcm","clk":"5306409546","pt":1646097496333,"mc":[{"id":"1.195395419","rc":[{"atl":[[2.68,5.59]],"id":43154449}],"con":true,"img":false}]}
{"op":"mcm","clk":"5306409619","pt":1646097498030,"mc":[{"id":"1.195395419","rc":[{"atl":[[2.74,0]],"id":43154449}],"con":true,"img":false}]}
{"op":"mcm","clk":"5306409623","pt":1646097498136,"mc":[{"id":"1.195395419","rc":[{"atl":[[2.62,5.11]],"id":43154449}],"con":true,"img":false}]}
{"op":"mcm","clk":"5306409758","pt":1646097501945,"mc":[{"id":"1.195395419","rc":[{"atl":[[2.68,0]],"id":43154449}],"con":true,"img":false}]}
{"op":"mcm","clk":"5306409771","pt":1646097502309,"mc":[{"id":"1.195395419","rc":[{"atl":[[2.62,10.83]],"id":43154449}],"con":true,"img":false}]}
{"op":"mcm","clk":"5306422677","pt":1646097807710,"mc":[{"id":"1.195395419","rc":[{"atb":[[9.6,1.17]],"id":43154448}],"con":true,"img":false}]}
{"op":"mcm","clk":"5306422680","pt":1646097807813,"mc":[{"id":"1.195395419","rc":[{"atb":[[8.4,6.74]],"id":43154448}],"con":true,"img":false}]}
{"op":"mcm","clk":"5306423302","pt":1646097823297,"mc":[{"id":"1.195395419","rc":[{"atl":[[55,0]],"id":42413752}],"con":true,"img":false}]}
{"op":"mcm","clk":"5306423309","pt":1646097823403,"mc":[{"id":"1.195395419","rc":[{"atl":[[50,2.77]],"id":42413752}],"con":true,"img":false}]}
{"op":"mcm","clk":"5306439855","pt":1646098199299,"mc":[{"id":"1.195395419","rc":[{"atb":[[1.22,47.16]],"id":42352031},{"atl":[[65,2]],"id":42352031},{"atb":[[2.2,83.33]],"id":42248828},{"atl":[[13.5,8]],"id":42248828},{"atb":[[4.8,26.32]],"id":42413752},{"atl":[[180,2]],"id":42413752},{"atb":[[5.9,20.41]],"id":43154448},{"atl":[[80,2]],"id":43154448},{"atb":[[23,4.55]],"id":41642357},{"atl":[[590,2]],"id":41642357},{"atb":[[1.35,156.02]],"id":43154449},{"atl":[[6.6,17.86]],"id":43154449},{"atb":[[5.7,21.28]],"id":43154446},{"atl":[[70,2]],"id":43154446},{"atb":[[2.96,51.02]],"id":43154447},{"atl":[[13,8.33]],"id":43154447}],"con":true,"img":false}]}
{"op":"mcm","clk":"5306440033","pt":1646098203324,"mc":[{"id":"1.195395419","rc":[{"atb":[[5.6,27.17],[6.4,3.7],[5.8,36.74],[6,34.39]],"id":42352031},{"atl":[[16,3.33],[17,4.69],[18,7.35],[15,1.43]],"id":42352031},{"atb":[[2.54,12.99],[2.5,100.93],[2.42,88.03],[2.46,51.37]],"id":42248828},{"atl":[[13.5,9.6],[14.5,3.7],[15.5,5.17],[16.5,8.06]],"id":42248828},{"atb":[[10.5,13.16],[11.5,7.14],[12.5,4.35],[13.5,11.22]],"id":42413752},{"atl":[[270,1.73],[290,1],[230,1],[250,1]],"id":42413752},{"atb":[[9,2.5],[8.2,28.8],[7.8,18.38],[5.9,0],[8.6,6.58]],"id":43154448},{"atl":[[24,1],[26,2],[28,2.78],[30,8.63]],"id":43154448},{"atb":[[32,1],[23,0],[25,5.21],[27,2.88],[29,5.41]],"id":41642357},{"atb":[[1.41,182.93],[1.45,44.44],[1.43,116.28],[1.39,250]],"id":43154449},{"atl":[[4.3,15.15],[4.5,21.43],[4.1,25.16],[4.7,33.78]],"id":43154449},{"atb":[[9,28.29],[10.5,2.11],[9.4,8.93],[9.8,5.68],[5.7,0]],"id":43154446},{"atl":[[160,1],[180,1],[200,1.99],[220,1]],"id":43154446},{"atb":[[4,6.67],[3.7,83.85],[3.8,26.79],[3.9,17.24]],"id":43154447},{"atl":[[10.5,2.11],[11.5,4.76],[12.5,6.52],[13.5,20.56]],"id":43154447}],"con":true,"img":false}]}
{"op":"mcm","clk":"5306440045","pt":1646098203479,"mc":[{"id":"1.195395419","rc":[{"atb":[[5.3,23.26]],"id":43154448},{"atb":[[15.5,6.9]],"id":41642357},{"atb":[[4.7,27.03]],"id":43154446}],"con":true,"img":false}]}
{"op":"mcm","clk":"5306440091","pt":1646098204406,"mc":[{"id":"1.195395419","rc":[{"atb":[[7.4,3.01]],"id":42352031},{"atb":[[2.88,2.5]],"id":42248828},{"atb":[[16.5,2.08]],"id":42413752},{"atb":[[9.8,2.88]],"id":43154448},{"atb":[[16,2.31]],"id":43154446},{"atb":[[4.5,2.5]],"id":43154447}],"con":true,"img":false}]}
{"op":"mcm","clk":"5306440732","pt":1646098218383,"mc":[{"id":"1.195395419","rc":[{"atb":[[5,25],[1.22,0]],"id":42352031},{"atl":[[36,2.86],[65,0]],"id":42352031},{"atb":[[4.8,0],[9,12.5]],"id":42413752},{"atl":[[80,0],[44,2.33]],"id":43154448},{"atl":[[470,2.12]],"id":41642357},{"atl":[[70,0],[48,4.83]],"id":43154446},{"atb":[[3.2,91.54],[2.96,0]],"id":43154447}],"con":true,"img":false}]}
{"op":"mcm","clk":"5306440736","pt":1646098218485,"mc":[{"id":"1.195395419","rc":[{"atl":[[590,0]],"id":41642357}],"con":true,"img":false}]}
{"op":"mcm","clk":"5306440998","pt":1646098224505,"mc":[{"id":"1.195395419","rc":[{"spn":11.2,"spf":1.0,"id":42352031},{"spn":3.94,"spf":1.0,"id":42248828},{"spn":6.85,"spf":1.0,"id":43154447}],"con":true,"img":false}]}
{"op":"mcm","clk":"5306441297","pt":1646098231898,"mc":[{"id":"1.195395419","rc":[{"atb":[[8.4,0]],"id":43154448}],"con":true,"img":false}]}
{"op":"mcm","clk":"5306441302","pt":1646098232052,"mc":[{"id":"1.195395419","rc":[{"atb":[[8.8,6.74]],"id":43154448}],"con":true,"img":false}]}
{"op":"mcm","clk":"5306441396","pt":1646098233338,"mc":[{"id":"1.195395419","rc":[{"atl":[[17.5,4.72],[15,0]],"id":42352031},{"atb":[[5.3,0]],"id":43154448},{"atl":[[44,0]],"id":43154448},{"atl":[[5.8,20.83],[3.95,6.78],[4.1,18.71]],"id":43154449},{"atb":[[10.5,0],[12,1.82],[4.7,0]],"id":43154446},{"atl":[[48,2.7]],"id":43154446}],"con":true,"img":false}]}
{"op":"mcm","clk":"5306441400","pt":1646098233440,"mc":[{"id":"1.195395419","rc":[{"atb":[[3.2,45.45],[5,0]],"id":42352031},{"atb":[[1.62,31.39]],"id":43154448},{"atl":[[65,2]],"id":43154448},{"atb":[[15.5,0],[23,4.55]],"id":41642357},{"atl":[[6.6,0]],"id":43154449},{"atb":[[2.54,19.48]],"id":43154446},{"atl":[[55,2]],"id":43154446},{"atb":[[2.94,51.55],[3.2,46.09]],"id":43154447},{"atl":[[11.5,13.94],[13,0]],"id":43154447}],"con":true,"img":false}]}
{"op":"mcm","clk":"5306441404","pt":1646098233543,"mc":[{"id":"1.195395419","rc":[{"atb":[[1.62,0],[5.9,20.41]],"id":43154448},{"atb":[[2.54,0],[5.6,21.74]],"id":43154446},{"atl":[[10.5,12.64],[11.5,4.76]],"id":43154447}],"con":true,"img":false}]}
{"op":"mcm","clk":"5306441503","pt":1646098237333,"mc":[{"id":"1.195395419","rc":[{"atb":[[3.2,0],[5.3,46.84]],"id":42352031}],"con":true,"img":false}]}
{"op":"mcm","clk":"5306441694","pt":1646098243329,"mc":[{"id":"1.195395419","rc":[{"atl":[[16,0],[18.5,2.86]],"id":42352031},{"atl":[[4.1,34.84]],"id":43154449},{"atb":[[11,5]],"id":43154446}],"con":true,"img":false}]}
{"op":"mcm","clk":"5306441937","pt":1646098251857,"mc":[{"id":"1.195395419","rc":[{"atl":[[17.5,11.96]],"id":42352031},{"atl":[[30,4.31]],"id":43154448},{"atl":[[4.2,35.91]],"id":43154449}],"con":true,"img":false}]}
{"op":"mcm","clk":"5306441939","pt":1646098251954,"mc":[{"id":"1.195395419","rc":[{"atl":[[23,0]],"id":42352031},{"atl":[[27,4.32]],"id":43154448},{"atl":[[5.2,0]],"id":43154449}],"con":true,"img":false}]}
{"op":"mcm","clk":"5306441982","pt":1646098253341,"mc":[{"id":"1.195395419","rc":[{"atl":[[17,0],[19.5,4.05]],"id":42352031},{"atl":[[4.3,22.73],[4.7,0]],"id":43154449},{"atb":[[9,12.67],[10,19.59],[9.4,0],[9.8,0]],"id":43154446}],"con":true,"img":false}]}
{"op":"mcm","clk":"5306442366","pt":1646098263385,"mc":[{"id":"1.195395419","rc":[{"atl":[[21,6.25]],"id":42352031},{"atl":[[4.5,35.71]],"id":43154449},{"atb":[[9.6,14.53]],"id":43154446}],"con":true,"img":false}]}
{"op":"mcm","clk":"5306442724","pt":1646098273470,"mc":[{"id":"1.195395419","rc":[{"atl":[[18,0]],"id":42352031}],"con":true,"img":false}]}
{"op":"mcm","clk":"5306442949","pt":1646098280287,"mc":[{"id":"1.195395419","rc":[{"atb":[[1.01,2.23]],"id":43154447}],"con":true,"img":false}]}
{"op":"mcm","clk":"5306442956","pt":1646098280389,"mc":[{"id":"1.195395419","rc":[{"atb":[[4.4,0]],"id":43154447}],"con":true,"img":false}]}
{"op":"mcm","clk":"5306442972","pt":1646098280700,"mc":[{"id":"1.195395419","rc":[{"atb":[[1.01,0.81]],"id":43154447}],"con":true,"img":false}]}
{"op":"mcm","clk":"5306442988","pt":1646098281013,"mc":[{"id":"1.195395419","rc":[{"atb":[[1.01,0]],"id":43154447}],"con":true,"img":false}]}
{"op":"mcm","clk":"5306442994","pt":1646098281062,"mc":[{"id":"1.195395419","rc":[{"atb":[[4.6,0.81]],"id":43154447}],"con":true,"img":false}]}
{"op":"mcm","clk":"5306443024","pt":1646098281880,"mc":[{"id":"1.195395419","rc":[{"atl":[[17.5,4.72]],"id":42352031},{"atl":[[60,0]],"id":43154446},{"atl":[[10,11.8],[12,0]],"id":43154447}],"con":true,"img":false}]}
{"op":"mcm","clk":"5306443030","pt":1646098281984,"mc":[{"id":"1.195395419","rc":[{"atl":[[19,7.24]],"id":42352031},{"atl":[[50,2.7]],"id":43154446}],"con":true,"img":false}]}
{"op":"mcm","clk":"5306443035","pt":1646098282085,"mc":[{"id":"1.195395419","rc":[{"atl":[[46,0],[1000,2.23]],"id":43154446}],"con":true,"img":false}]}
{"op":"mcm","clk":"5306443041","pt":1646098282190,"mc":[{"id":"1.195395419","rc":[{"atl":[[1000,0.08]],"id":43154446}],"con":true,"img":false}]}
{"op":"mcm","clk":"5306443046","pt":1646098282289,"mc":[{"id":"1.195395419","rc":[{"atl":[[1000,0]],"id":43154446}],"con":true,"img":false}]}
{"op":"mcm","clk":"5306443052","pt":1646098282394,"mc":[{"id":"1.195395419","rc":[{"atl":[[48,2.78]],"id":43154446}],"con":true,"img":false}]}
{"op":"mcm","clk":"5306443241","pt":1646098287370,"mc":[{"id":"1.195395419","rc":[{"spn":12.45,"spf":1.0,"id":42352031},{"spn":32.0,"spf":1.0,"id":43154446},{"spn":6.9,"spf":1.0,"id":43154447}],"con":true,"img":false}]}
{"op":"mcm","clk":"5306445945","pt":1646098353367,"mc":[{"id":"1.195395419","rc":[{"atl":[[36,0],[48,6.34]],"id":42352031},{"atb":[[9,0],[7.4,15.62]],"id":42413752},{"atb":[[5.3,23.26],[5.9,0]],"id":43154448},{"atl":[[530,2.37],[470,0.12]],"id":41642357},{"atb":[[5.6,0],[5,25]],"id":43154446},{"atl":[[55,0],[60,2]],"id":43154446},{"atb":[[2.8,55.56],[2.94,0]],"id":43154447}],"con":true,"img":false}]}
{"op":"mcm","clk":"5306446301","pt":1646098361981,"mc":[{"id":"1.195395419","rc":[{"atl":[[50,0]],"id":43154446}],"con":true,"img":false}]}
{"op":"mcm","clk":"5306446308","pt":1646098362084,"mc":[{"id":"1.195395419","rc":[{"atl":[[55,2.7]],"id":43154446}],"con":true,"img":false}]}
{"op":"mcm","clk":"5306447580","pt":1646098391935,"mc":[{"id":"1.195395419","rc":[{"atl":[[25,5.4],[27,0]],"id":43154448}],"con":true,"img":false}]}
{"op":"mcm","clk":"5306447581","pt":1646098392036,"mc":[{"id":"1.195395419","rc":[{"atl":[[19,0]],"id":42352031}],"con":true,"img":false}]}
{"op":"mcm","clk":"5306447583","pt":1646098392141,"mc":[{"id":"1.195395419","rc":[{"atl":[[18,7.24]],"id":42352031}],"con":true,"img":false}]}
{"op":"mcm","clk":"5306450795","pt":1646098474223,"mc":[{"id":"1.195395419","rc":[{"atb":[[4.3,30.3],[5.3,23.58]],"id":42352031},{"atl":[[17.5,3.51],[17,1.25]],"id":42352031},{"atb":[[2.3,154.92],[2.2,0]],"id":42248828},{"atb":[[7.4,0]],"id":42413752},{"atl":[[180,0],[110,2]],"id":42413752},{"atb":[[5.3,0],[3.5,40]],"id":43154448},{"atb":[[13,8.33],[23,0]],"id":41642357},{"atl":[[530,0.37],[470,2.12]],"id":41642357},{"atl":[[3.95,0],[4.1,25.16]],"id":43154449},{"atb":[[11,2],[12,0],[5,0],[2.86,46.3]],"id":43154446},{"atl":[[48,4.91],[60,0]],"id":43154446},{"atb":[[2.8,0],[2.92,52.08]],"id":43154447},{"atl":[[10.5,2.11],[11,10]],"id":43154447}],"con":true,"img":false}]}
{"op":"mcm","clk":"5306450803","pt":1646098474428,"mc":[{"id":"1.195395419","rc":[{"atb":[[7,16.67]],"id":42413752}],"con":true,"img":false}]}
{"op":"mcm","clk":"5306451045","pt":1646098481922,"mc":[{"id":"1.195395419","rc":[{"atl":[[18,0]],"id":42352031},{"atl":[[25,0]],"id":43154448},{"atl":[[55,0]],"id":43154446},{"atl":[[10,0]],"id":43154447}],"con":true,"img":false}]}
{"op":"mcm","clk":"5306451050","pt":1646098482025,"mc":[{"id":"1.195395419","rc":[{"atl":[[19,7.24]],"id":42352031},{"atl":[[27,5.4]],"id":43154448},{"atl":[[60,2.7]],"id":43154446},{"atl":[[10.5,13.91]],"id":43154447}],"con":true,"img":false}]}
{"op":"mcm","clk":"5306451142","pt":1646098484228,"mc":[{"id":"1.195395419","rc":[{"atl":[[4.3,37.88]],"id":43154449},{"atb":[[10,16.82]],"id":43154446}],"con":true,"img":false}]}
{"op":"mcm","clk":"5306451146","pt":1646098484334,"mc":[{"id":"1.195395419","rc":[{"atl":[[4.3,15.15]],"id":43154449}],"con":true,"img":false}]}
{"op":"mcm","clk":"5306451341","pt":1646098490646,"mc":[{"id":"1.195395419","rc":[{"atb":[[4.3,0],[5.3,46.84]],"id":42352031},{"atb":[[3.5,0],[5.4,22.73]],"id":43154448},{"atb":[[2.86,0],[4.7,27.03]],"id":43154446}],"con":true,"img":false}]}
{"op":"mcm","clk":"5306451481","pt":1646098494251,"mc":[{"id":"1.195395419","rc":[{"atl":[[4.5,57.14]],"id":43154449},{"atb":[[9.6,23.25]],"id":43154446}],"con":true,"img":false}]}
{"op":"mcm","clk":"5306451487","pt":1646098494353,"mc":[{"id":"1.195395419","rc":[{"atl":[[4.5,21.43]],"id":43154449},{"atb":[[9.6,8.72]],"id":43154446}],"con":true,"img":false}]}
{"op":"mcm","clk":"5306451838","pt":1646098504279,"mc":[{"id":"1.195395419","rc":[{"atl":[[4.7,33.78]],"id":43154449},{"atb":[[9.2,15.24]],"id":43154446}],"con":true,"img":false}]}
{"op":"mcm","clk":"5306452865","pt":1646098533680,"mc":[{"id":"1.195395419","rc":[{"spn":12.2,"spf":1.0,"id":42352031}],"con":true,"img":false}]}
{"op":"mcm","clk":"5306455073","pt":1646098594281,"mc":[{"id":"1.195395419","rc":[{"atb":[[2.76,56.82],[2.92,0]],"id":43154447}],"con":true,"img":false}]}
{"op":"mcm","clk":"5306462331","pt":1646098786408,"mc":[{"id":"1.195395419","rc":[{"atl":[[17,0],[17.5,4.72]],"id":42352031},{"atl":[[9.2,38.8],[13.5,0]],"id":42248828},{"atb":[[10.5,0],[11.5,0],[12.5,0],[13.5,9.62],[5.1,4.88],[5,25],[7,0]],"id":42413752},{"atb":[[9,0],[8.2,18.38],[4.4,5.88],[7.8,0],[5.4,0],[8.6,0],[4.2,31.25]],"id":43154448},{"atb":[[32,0],[46,3.7]],"id":41642357},{"atb":[[1.45,0],[1.35,0],[2.4,86.72],[2.24,80.65]],"id":43154449},{"atb":[[2.76,0]],"id":43154447},{"atl":[[10.5,11.8],[7,3.33]],"id":43154447}],"con":true,"img":false}]}
{"op":"mcm","clk":"5306462336","pt":1646098786512,"mc":[{"id":"1.195395419","rc":[{"atb":[[2.92,52.08]],"id":43154447}],"con":true,"img":false}]}
{"op":"mcm","clk":"5306462397","pt":1646098787945,"mc":[{"id":"1.195395419","rc":[{"atb":[[2.88,0]],"id":42248828}],"con":true,"img":false}]}
{"op":"mcm","clk":"5306462459","pt":1646098790152,"mc":[{"id":"1.195395419","rc":[{"atb":[[3.1,2.5]],"id":42248828}],"con":true,"img":false}]}
{"op":"mcm","clk":"5306462497","pt":1646098791129,"mc":[{"id":"1.195395419","rc":[{"atb":[[3.75,0.01]],"id":42248828},{"trd":[[3.75,16.97]],"ltp":3.75,"tv":16.97,"id":42248828}],"con":true,"img":false}]}
{"op":"mcm","clk":"5306462522","pt":1646098791743,"mc":[{"id":"1.195395419","rc":[{"atl":[[4.9,4.32]],"id":42248828}],"con":true,"img":false}]}
{"op":"mcm","clk":"5306462527","pt":1646098791846,"mc":[{"id":"1.195395419","rc":[{"atb":[[8.8,0]],"id":43154448}],"con":true,"img":false}]}
{"op":"mcm","clk":"5306462534","pt":1646098791948,"mc":[{"id":"1.195395419","rc":[{"atb":[[17.5,0]],"id":42413752},{"atb":[[8.4,6.74]],"id":43154448},{"atb":[[2.92,0]],"id":43154447}],"con":true,"img":false}]}
{"op":"mcm","clk":"5306462541","pt":1646098792050,"mc":[{"id":"1.195395419","rc":[{"atb":[[5.3,23.58],[2.66,50.69]],"id":42352031},{"atl":[[17.5,3.51],[21,1]],"id":42352031},{"atb":[[2.5,167.6],[2.3,78]],"id":42248828},{"atb":[[16.5,2.74]],"id":42413752},{"atl":[[75,2],[110,0]],"id":42413752},{"atb":[[9.6,0]],"id":43154448},{"atl":[[36,2.86],[65,0]],"id":43154448},{"atb":[[46,2.7],[50,1],[13,0],[4,33.33]],"id":41642357},{"atl":[[5.8,0],[3.75,7.27],[4.1,18.71],[5.2,23.81]],"id":43154449},{"atb":[[11,0],[12,1.82],[4.7,0]],"id":43154446},{"atl":[[80,2],[48,2.78]],"id":43154446},{"atb":[[2.48,65.42]],"id":43154447},{"atl":[[7.4,3.12],[7,0]],"id":43154447}],"con":true,"img":false}]}
{"op":"mcm","clk":"5306462545","pt":1646098792152,"mc":[{"id":"1.195395419","rc":[{"atb":[[9.2,1.23]],"id":43154448},{"atl":[[10,10.4],[11,0]],"id":43154447}],"con":true,"img":false}]}
{"op":"mcm","clk":"5306462558","pt":1646098792412,"mc":[{"id":"1.195395419","rc":[{"atb":[[3.75,0]],"id":42248828}],"con":true,"img":false}]}
{"op":"mcm","clk":"5306462694","pt":1646098796151,"mc":[{"id":"1.195395419","rc":[{"atl":[[4.2,0]],"id":43154449}],"con":true,"img":false}]}
{"op":"mcm","clk":"5306462697","pt":1646098796255,"mc":[{"id":"1.195395419","rc":[{"atl":[[4.4,35.91]],"id":43154449}],"con":true,"img":false}]}
{"op":"mcm","clk":"5306462704","pt":1646098796461,"mc":[{"id":"1.195395419","rc":[{"atl":[[9.6,5.81]],"id":42248828},{"atb":[[4.9,12.82]],"id":42413752},{"atb":[[4.2,46.87]],"id":43154448}],"con":true,"img":false}]}
{"op":"mcm","clk":"5306462919","pt":1646098802051,"mc":[{"id":"1.195395419","rc":[{"atb":[[7.6,2.69]],"id":42352031},{"atl":[[18.5,0],[23,2.27]],"id":42352031},{"atb":[[46,3.81]],"id":41642357},{"atl":[[460,2]],"id":41642357},{"atb":[[2.36,36.76]],"id":43154449},{"atl":[[3.85,17.54]],"id":43154449},{"atb":[[11,5]],"id":43154446},{"atl":[[48,4.78]],"id":43154446},{"atl":[[7.8,7.35]],"id":43154447}],"con":true,"img":false}]}
{"op":"mcm","clk":"5306462929","pt":1646098802254,"mc":[{"id":"1.195395419","rc":[{"atl":[[50,4.77]],"id":42413752},{"atb":[[9.8,4.88]],"id":43154448},{"atl":[[23,4.7]],"id":43154448}],"con":true,"img":false}]}
{"op":"mcm","clk":"5306462956","pt":1646098802924,"mc":[{"id":"1.195395419","rc":[{"atb":[[7.4,0.5]],"id":42352031}],"con":true,"img":false}]}
{"op":"mcm","clk":"5306463050","pt":1646098805231,"mc":[{"id":"1.195395419","rc":[{"atb":[[4.4,29.41],[2.66,0]],"id":42352031},{"atl":[[65,2]],"id":42413752},{"atl":[[32,3.23],[36,0]],"id":43154448},{"atl":[[70,2],[80,0]],"id":43154446},{"atb":[[3.1,47.62],[2.48,0]],"id":43154447}],"con":true,"img":false}]}
{"op":"mcm","clk":"5306463054","pt":1646098805333,"mc":[{"id":"1.195395419","rc":[{"atb":[[7.8,2.5]],"id":42352031},{"atl":[[75,0]],"id":42413752}],"con":true,"img":false}]}
{"op":"mcm","clk":"5306463084","pt":1646098805823,"mc":[{"id":"1.195395419","rc":[{"atb":[[7.8,4.07]],"id":42352031},{"atl":[[4.8,2.53]],"id":42248828},{"atb":[[17,1.56]],"id":42413752},{"atb":[[10,1.51]],"id":43154448},{"atb":[[15,1.57]],"id":43154446},{"atb":[[4.6,2.46]],"id":43154447}],"con":true,"img":false}]}
{"op":"mcm","clk":"5306463090","pt":1646098806026,"mc":[{"id":"1.195395419","rc":[{"atl":[[19,0],[22,5.68]],"id":42352031},{"atl":[[10.5,0]],"id":43154447}],"con":true,"img":false}]}
{"op":"mcm","clk":"5306463093","pt":1646098806128,"mc":[{"id":"1.195395419","rc":[{"atl":[[11,11.8]],"id":43154447}],"con":true,"img":false}]}
{"op":"mcm","clk":"5306463101","pt":1646098806435,"mc":[{"id":"1.195395419","rc":[{"atb":[[16.5,0.66]],"id":42413752},{"atb":[[9.8,2.37]],"id":43154448},{"atb":[[4.5,0]],"id":43154447}],"con":true,"img":false}]}
{"op":"mcm","clk":"5306463106","pt":1646098806538,"mc":[{"id":"1.195395419","rc":[{"atl":[[10,8.33],[14.5,0],[15.5,0],[16.5,0]],"id":42248828},{"atb":[[4.7,20.27]],"id":42413752},{"atb":[[4,25]],"id":43154448}],"con":true,"img":false}]}
{"op":"mcm","clk":"5306463129","pt":1646098807155,"mc":[{"id":"1.195395419","rc":[{"atb":[[8,2],[7.6,0]],"id":42352031},{"atb":[[17,0]],"id":42413752},{"atb":[[10,0]],"id":43154448},{"atb":[[4.6,0.81]],"id":43154447}],"con":true,"img":false}]}
{"op":"mcm","clk":"5306463135","pt":1646098807256,"mc":[{"id":"1.195395419","rc":[{"atb":[[16.5,2.22]],"id":42413752},{"atb":[[9.6,1.51]],"id":43154448},{"atb":[[4.4,1.65]],"id":43154447}],"con":true,"img":false}]}
{"op":"mcm","clk":"5306463138","pt":1646098807359,"mc":[{"id":"1.195395419","rc":[{"atb":[[9.6,3.51],[9.8,0.37]],"id":43154448}],"con":true,"img":false}]}
{"op":"mcm","clk":"5306463145","pt":1646098807665,"mc":[{"id":"1.195395419","rc":[{"atb":[[7.8,2.5]],"id":42352031}],"con":true,"img":false}]}
{"op":"mcm","clk":"5306463148","pt":1646098807768,"mc":[{"id":"1.195395419","rc":[{"atb":[[1.01,1.57]],"id":42352031},{"atb":[[17,2.08]],"id":42413752},{"atb":[[10,2.5]],"id":43154448},{"atb":[[4.5,2.5]],"id":43154447}],"con":true,"img":false}]}
{"op":"mcm","clk":"5306463150","pt":1646098807821,"mc":[{"id":"1.195395419","rc":[{"atb":[[7.8,0]],"id":42352031}],"con":true,"img":false}]}
{"op":"mcm","clk":"5306463166","pt":1646098808335,"mc":[{"id":"1.195395419","rc":[{"atb":[[1.01,0]],"id":42352031},{"atb":[[4.4,0]],"id":43154447}],"con":true,"img":false}]}
{"op":"mcm","clk":"5306463171","pt":1646098808437,"mc":[{"id":"1.195395419","rc":[{"atb":[[7.4,2.07]],"id":42352031},{"atb":[[4.6,2.46]],"id":43154447}],"con":true,"img":false}]}
{"op":"mcm","clk":"5306463229","pt":1646098810127,"mc":[{"id":"1.195395419","rc":[{"atb":[[8.2,2.5]],"id":42352031}],"con":true,"img":false}]}
{"op":"mcm","clk":"5306463233","pt":1646098810231,"mc":[{"id":"1.195395419","rc":[{"atb":[[4.5,0]],"id":43154447}],"con":true,"img":false}]}
{"op":"mcm","clk":"5306463242","pt":1646098810742,"mc":[{"id":"1.195395419","rc":[{"atb":[[4.6,0.81]],"id":43154447}],"con":true,"img":false}]}
{"op":"mcm","clk":"5306463246","pt":1646098810846,"mc":[{"id":"1.195395419","rc":[{"atb":[[4.4,1.65]],"id":43154447}],"con":true,"img":false}]}
{"op":"mcm","clk":"5306463274","pt":1646098811566,"mc":[{"id":"1.195395419","rc":[{"atl":[[17,1.21]],"id":42352031},{"atl":[[4.7,1.32]],"id":42248828},{"atl":[[48,1.35]],"id":42413752},{"atl":[[22,1.33]],"id":43154448},{"atl":[[450,1.21]],"id":41642357},{"atl":[[46,1.37]],"id":43154446},{"atl":[[7.2,1.26]],"id":43154447}],"con":true,"img":false}]}
{"op":"mcm","clk":"5306463290","pt":1646098811772,"mc":[{"id":"1.195395419","rc":[{"atl":[[440,4],[460,0],[470,0.12]],"id":41642357}],"con":true,"img":false}]}
{"op":"mcm","clk":"5306463307","pt":1646098812031,"mc":[{"id":"1.195395419","rc":[{"atl":[[19.5,0],[25,3.12]],"id":42352031},{"atb":[[42,1.83],[25,0],[27,0],[29,3.62]],"id":41642357},{"atb":[[1.41,0],[2.32,102.76],[1.43,0],[1.39,0]],"id":43154449},{"atl":[[3.95,25.42],[4.7,0]],"id":43154449},{"atb":[[10,19.59],[9.2,0]],"id":43154446},{"atl":[[8.2,10.42],[13.5,10.56]],"id":43154447}],"con":true,"img":false}]}
{"op":"mcm","clk":"5306463313","pt":1646098812234,"mc":[{"id":"1.195395419","rc":[{"atl":[[450,0]],"id":41642357}],"con":true,"img":false}]}
{"op":"mcm","clk":"5306463316","pt":1646098812338,"mc":[{"id":"1.195395419","rc":[{"atl":[[1000,1.21]],"id":41642357}],"con":true,"img":false}]}
{"op":"mcm","clk":"5306463322","pt":1646098812441,"mc":[{"id":"1.195395419","rc":[{"atb":[[10,4.5]],"id":43154448}],"con":true,"img":false}]}
{"op":"mcm","clk":"5306463324","pt":1646098812544,"mc":[{"id":"1.195395419","rc":[{"atl":[[4.8,0]],"id":42248828},{"atb":[[10,2.5],[9.6,1.51]],"id":43154448},{"atb":[[4.5,2.5]],"id":43154447}],"con":true,"img":false}]}
{"op":"mcm","clk":"5306463328","pt":1646098812647,"mc":[{"id":"1.195395419","rc":[{"atb":[[9.6,3.51]],"id":43154448}],"con":true,"img":false}]}
{"op":"mcm","clk":"5306463337","pt":1646098812751,"mc":[{"id":"1.195395419","rc":[{"atl":[[4.7,0]],"id":42248828}],"con":true,"img":false}]}
{"op":"mcm","clk":"5306463341","pt":1646098812854,"mc":[{"id":"1.195395419","rc":[{"atl":[[4.8,1.32]],"id":42248828}],"con":true,"img":false}]}
{"op":"mcm","clk":"5306463475","pt":1646098816546,"mc":[{"id":"1.195395419","rc":[{"atl":[[11,20.7]],"id":42248828},{"atb":[[4.5,35.71]],"id":42413752},{"atb":[[3.9,43.1]],"id":43154448}],"con":true,"img":false}]}
{"op":"mcm","clk":"5306463517","pt":1646098817878,"mc":[{"id":"1.195395419","rc":[{"atb":[[10,4.5],[9.6,1.51]],"id":43154448}],"con":true,"img":false}]}
{"op":"mcm","clk":"5306463524","pt":1646098817930,"mc":[{"id":"1.195395419","rc":[{"atb":[[10,2.5],[9.8,2.37]],"id":43154448}],"con":true,"img":false}]}
{"op":"mcm","clk":"5306463611","pt":1646098821161,"mc":[{"id":"1.195395419","rc":[{"atb":[[1.03,2.23],[18,0]],"id":42413752}],"con":true,"img":false}]}
{"op":"mcm","clk":"5306463618","pt":1646098821367,"mc":[{"id":"1.195395419","rc":[{"atb":[[1.03,0.2]],"id":42413752}],"con":true,"img":false}]}
{"op":"mcm","clk":"5306463623","pt":1646098821569,"mc":[{"id":"1.195395419","rc":[{"atb":[[1.03,0]],"id":42413752}],"con":true,"img":false}]}
{"op":"mcm","clk":"5306463625","pt":1646098821672,"mc":[{"id":"1.195395419","rc":[{"atb":[[17.5,0.2]],"id":42413752}],"con":true,"img":false}]}
{"op":"mcm","clk":"5306463637","pt":1646098822080,"mc":[{"id":"1.195395419","rc":[{"atl":[[27,4.81]],"id":42352031},{"atl":[[4.9,0]],"id":42248828},{"atb":[[38,6.12]],"id":41642357},{"atb":[[2.28,97.66]],"id":43154449},{"atl":[[4.5,0],[4.1,59.03]],"id":43154449},{"atb":[[9.6,14.53]],"id":43154446},{"atl":[[12.5,0],[8.6,16.45]],"id":43154447}],"con":true,"img":false}]}
{"op":"mcm","clk":"5306463641","pt":1646098822236,"mc":[{"id":"1.195395419","rc":[{"atl":[[4.7,4.32]],"id":42248828}],"con":true,"img":false}]}
{"op":"mcm","clk":"5306463646","pt":1646098822441,"mc":[{"id":"1.195395419","rc":[{"atl":[[4.8,0]],"id":42248828}],"con":true,"img":false}]}
{"op":"mcm","clk":"5306463651","pt":1646098822547,"mc":[{"id":"1.195395419","rc":[{"atl":[[4.9,1.32]],"id":42248828}],"con":true,"img":false}]}
{"op":"mcm","clk":"5306463654","pt":1646098822644,"mc":[{"id":"1.195395419","rc":[{"atl":[[4.6,2.53]],"id":42248828}],"con":true,"img":false}]}
{"op":"mcm","clk":"5306463662","pt":1646098823054,"mc":[{"id":"1.195395419","rc":[{"atl":[[4.9,0]],"id":42248828}],"con":true,"img":false}]}
{"op":"mcm","clk":"5306463665","pt":1646098823155,"mc":[{"id":"1.195395419","rc":[{"atl":[[4.5,1.32]],"id":42248828}],"con":true,"img":false}]}
{"op":"mcm","clk":"5306463743","pt":1646098825976,"mc":[{"id":"1.195395419","rc":[{"atl":[[4.4,0],[5.1,28.03]],"id":43154449}],"con":true,"img":false}]}
{"op":"mcm","clk":"5306463902","pt":1646098830445,"mc":[{"id":"1.195395419","rc":[{"atl":[[4.6,0]],"id":42248828}],"con":true,"img":false}]}
{"op":"mcm","clk":"5306463925","pt":1646098830856,"mc":[{"id":"1.195395419","rc":[{"atl":[[4.5,0]],"id":42248828}],"con":true,"img":false}]}
{"op":"mcm","clk":"5306463933","pt":1646098830962,"mc":[{"id":"1.195395419","rc":[{"atl":[[4.6,1.32]],"id":42248828}],"con":true,"img":false}]}
{"op":"mcm","clk":"5306463975","pt":1646098832190,"mc":[{"id":"1.195395419","rc":[{"atl":[[4.3,0]],"id":43154449},{"atl":[[11.5,0]],"id":43154447}],"con":true,"img":false}]}
{"op":"mcm","clk":"5306464095","pt":1646098836090,"mc":[{"id":"1.195395419","rc":[{"atl":[[4.1,40.32]],"id":43154449}],"con":true,"img":false}]}
{"op":"mcm","clk":"5306464101","pt":1646098836193,"mc":[{"id":"1.195395419","rc":[{"atl":[[3.9,18.71]],"id":43154449}],"con":true,"img":false}]}
{"op":"mcm","clk":"5306464233","pt":1646098839997,"mc":[{"id":"1.195395419","rc":[{"spn":12.6,"spf":1.0,"id":42352031},{"spn":3.85,"spf":1.0,"id":42248828},{"spn":32.75,"spf":1.0,"id":42413752},{"spn":16.0,"spf":1.0,"id":43154448},{"spn":31.0,"spf":1.0,"id":43154446},{"spn":5.9,"spf":1.0,"id":43154447}],"con":true,"img":false}]}
{"op":"mcm","clk":"5306464436","pt":1646098846102,"mc":[{"id":"1.195395419","rc":[{"atl":[[70,0]],"id":42413752}],"con":true,"img":false}]}
{"op":"mcm","clk":"5306464441","pt":1646098846203,"mc":[{"id":"1.195395419","rc":[{"atl":[[60,2.7]],"id":42413752}],"con":true,"img":false}]}
{"op":"mcm","clk":"5306464621","pt":1646098851074,"mc":[{"id":"1.195395419","rc":[{"atl":[[27,0]],"id":43154448},{"atl":[[9.2,0]],"id":43154447}],"con":true,"img":false}]}
{"op":"mcm","clk":"5306464626","pt":1646098851177,"mc":[{"id":"1.195395419","rc":[{"atl":[[25,5.4]],"id":43154448},{"atl":[[8.4,7.07]],"id":43154447}],"con":true,"img":false}]}
{"op":"mcm","clk":"5306464671","pt":1646098852104,"mc":[{"id":"1.195395419","rc":[{"atb":[[8,0]],"id":42352031},{"atl":[[50,2.77]],"id":42413752},{"atb":[[9.8,0.37]],"id":43154448},{"atl":[[23,2.7]],"id":43154448},{"atl":[[440,2]],"id":41642357},{"atl":[[48,2.78]],"id":43154446}],"con":true,"img":false}]}
{"op":"mcm","clk":"5306464690","pt":1646098852409,"mc":[{"id":"1.195395419","rc":[{"atl":[[4.7,0]],"id":42248828}],"con":true,"img":false}]}
{"op":"mcm","clk":"5306464699","pt":1646098852612,"mc":[{"id":"1.195395419","rc":[{"atl":[[4.5,6.86]],"id":42248828}],"con":true,"img":false}]}
{"op":"mcm","clk":"5306464717","pt":1646098853126,"mc":[{"id":"1.195395419","rc":[{"atl":[[4.6,0]],"id":42248828}],"con":true,"img":false}]}
{"op":"mcm","clk":"5306464725","pt":1646098853228,"mc":[{"id":"1.195395419","rc":[{"atl":[[4.4,1.32]],"id":42248828}],"con":true,"img":false}]}
{"op":"mcm","clk":"5306465032","pt":1646098860327,"mc":[{"id":"1.195395419","rc":[{"atl":[[4.5,4.32]],"id":42248828}],"con":true,"img":false}]}
{"op":"mcm","clk":"5306465742","pt":1646098876043,"mc":[{"id":"1.195395419","rc":[{"atl":[[3.9,0]],"id":43154449}],"con":true,"img":false}]}
{"op":"mcm","clk":"5306465748","pt":1646098876145,"mc":[{"id":"1.195395419","rc":[{"atl":[[3.8,18.71]],"id":43154449}],"con":true,"img":false}]}
{"op":"mcm","clk":"5306465894","pt":1646098878919,"mc":[{"id":"1.195395419","rc":[{"atb":[[1.2,2.23]],"id":43154446}],"con":true,"img":false}]}
{"op":"mcm","clk":"5306465907","pt":1646098879128,"mc":[{"id":"1.195395419","rc":[{"atb":[[1.2,1.46]],"id":43154446}],"con":true,"img":false}]}
{"op":"mcm","clk":"5306465916","pt":1646098879332,"mc":[{"id":"1.195395419","rc":[{"atb":[[1.2,0]],"id":43154446}],"con":true,"img":false}]}
{"op":"mcm","clk":"5306465919","pt":1646098879433,"mc":[{"id":"1.195395419","rc":[{"atb":[[16.5,1.46]],"id":43154446}],"con":true,"img":false}]}
{"op":"mcm","clk":"5306465924","pt":1646098879644,"mc":[{"id":"1.195395419","rc":[{"atb":[[7.4,5.07]],"id":42352031}],"con":true,"img":false}]}
{"op":"mcm","clk":"5306466000","pt":1646098881233,"mc":[{"id":"1.195395419","rc":[{"atb":[[1.02,2.23]],"id":42352031},{"atb":[[16,0.23]],"id":43154446}],"con":true,"img":false}]}
{"op":"mcm","clk":"5306466006","pt":1646098881334,"mc":[{"id":"1.195395419","rc":[{"atb":[[7.4,4.57]],"id":42352031},{"atb":[[1.02,2.23]],"id":43154448}],"con":true,"img":false}]}
{"op":"mcm","clk":"5306466014","pt":1646098881539,"mc":[{"id":"1.195395419","rc":[{"atb":[[1.02,0.44]],"id":42352031},{"atb":[[9.8,0]],"id":43154448}],"con":true,"img":false}]}
{"op":"mcm","clk":"5306466022","pt":1646098881743,"mc":[{"id":"1.195395419","rc":[{"atb":[[1.02,0]],"id":42352031},{"atb":[[1.02,0.35]],"id":43154448}],"con":true,"img":false}]}
{"op":"mcm","clk":"5306466028","pt":1646098881849,"mc":[{"id":"1.195395419","rc":[{"atb":[[8.4,0.44]],"id":42352031}],"con":true,"img":false}]}
{"op":"mcm","clk":"5306466040","pt":1646098882050,"mc":[{"id":"1.195395419","rc":[{"atb":[[1.02,0]],"id":43154448}],"con":true,"img":false}]}
{"op":"mcm","clk":"5306466045","pt":1646098882154,"mc":[{"id":"1.195395419","rc":[{"atb":[[10.5,0.35]],"id":43154448}],"con":true,"img":false}]}
{"op":"mcm","clk":"5306466057","pt":1646098882255,"mc":[{"id":"1.195395419","rc":[{"atb":[[17,2.08]],"id":43154446}],"con":true,"img":false}]}
{"op":"mcm","clk":"5306466084","pt":1646098882819,"mc":[{"id":"1.195395419","rc":[{"atl":[[4.5,0]],"id":42248828}],"con":true,"img":false}]}
{"op":"mcm","clk":"5306466100","pt":1646098883026,"mc":[{"id":"1.195395419","rc":[{"atl":[[4.4,0]],"id":42248828}],"con":true,"img":false}]}
{"op":"mcm","clk":"5306466107","pt":1646098883128,"mc":[{"id":"1.195395419","rc":[{"atl":[[4.9,1.32]],"id":42248828}],"con":true,"img":false}]}
{"op":"mcm","clk":"5306466117","pt":1646098883332,"mc":[{"id":"1.195395419","rc":[{"atl":[[4.9,3.85]],"id":42248828}],"con":true,"img":false}]}
{"op":"mcm","clk":"5306466177","pt":1646098884361,"mc":[{"id":"1.195395419","rc":[{"atl":[[4.8,4.32]],"id":42248828}],"con":true,"img":false}]}
{"op":"mcm","clk":"5306466190","pt":1646098884616,"mc":[{"id":"1.195395419","rc":[{"atb":[[16.5,0]],"id":43154446}],"con":true,"img":false}]}
{"op":"mcm","clk":"5306466201","pt":1646098884925,"mc":[{"id":"1.195395419","rc":[{"atl":[[4.9,2.53]],"id":42248828}],"con":true,"img":false}]}
{"op":"mcm","clk":"5306466207","pt":1646098885028,"mc":[{"id":"1.195395419","rc":[{"atl":[[4.7,1.32]],"id":42248828}],"con":true,"img":false}]}
{"op":"mcm","clk":"5306466432","pt":1646098890470,"mc":[{"id":"1.195395419","rc":[{"atb":[[1.2,2.23]],"id":43154446}],"con":true,"img":false}]}
{"op":"mcm","clk":"5306466442","pt":1646098890730,"mc":[{"id":"1.195395419","rc":[{"atb":[[1.2,1.46]],"id":43154446}],"con":true,"img":false}]}
{"op":"mcm","clk":"5306466462","pt":1646098891042,"mc":[{"id":"1.195395419","rc":[{"atl":[[4.9,0]],"id":42248828},{"atb":[[1.2,0]],"id":43154446}],"con":true,"img":false}]}
{"op":"mcm","clk":"5306466466","pt":1646098891145,"mc":[{"id":"1.195395419","rc":[{"atb":[[16.5,1.46]],"id":43154446}],"con":true,"img":false}]}
{"op":"mcm","clk":"5306466659","pt":1646098896066,"mc":[{"id":"1.195395419","rc":[{"atl":[[11,0]],"id":43154447}],"con":true,"img":false}]}
{"op":"mcm","clk":"5306466669","pt":1646098896269,"mc":[{"id":"1.195395419","rc":[{"atl":[[9.8,11.8]],"id":43154447}],"con":true,"img":false}]}
{"op":"mcm","clk":"5306466680","pt":1646098896473,"mc":[{"id":"1.195395419","rc":[{"atb":[[8,2]],"id":42352031},{"atl":[[50,4.77]],"id":42413752},{"atb":[[9.8,2]],"id":43154448},{"atl":[[23,4.7]],"id":43154448},{"atb":[[4,0],[2.68,46.3]],"id":41642357},{"atl":[[440,4]],"id":41642357},{"atl":[[3.75,0],[5.2,0],[3.65,7.55],[4.7,27.03]],"id":43154449},{"atl":[[48,4.78]],"id":43154446},{"atl":[[7.4,0],[7.2,4.49]],"id":43154447}],"con":true,"img":false}]}
{"op":"mcm","clk":"5306466840","pt":1646098900989,"mc":[{"id":"1.195395419","rc":[{"spn":12.7,"spf":1.0,"id":42352031},{"spn":3.9,"spf":1.0,"id":42248828},{"spn":16.25,"spf":1.0,"id":43154448},{"spn":31.5,"spf":1.0,"id":43154446},{"atl":[[12,8.85]],"id":43154447}],"con":true,"img":false}]}
{"op":"mcm","clk":"5306466846","pt":1646098901145,"mc":[{"id":"1.195395419","rc":[{"atl":[[9.8,0]],"id":43154447}],"con":true,"img":false}]}
{"op":"mcm","clk":"5306467046","pt":1646098906078,"mc":[{"id":"1.195395419","rc":[{"atl":[[3.8,0]],"id":43154449}],"con":true,"img":false}]}
{"op":"mcm","clk":"5306467050","pt":1646098906179,"mc":[{"id":"1.195395419","rc":[{"atl":[[3.9,18.71]],"id":43154449}],"con":true,"img":false}]}
{"op":"mcm","clk":"5306467060","pt":1646098906486,"mc":[{"id":"1.195395419","rc":[{"atl":[[3.75,18.18]],"id":43154449}],"con":true,"img":false}]}
{"op":"mcm","clk":"5306467394","pt":1646098914560,"mc":[{"id":"1.195395419","rc":[{"atl":[[4.8,0]],"id":42248828}],"con":true,"img":false}]}
{"op":"mcm","clk":"5306467403","pt":1646098914765,"mc":[{"id":"1.195395419","rc":[{"atl":[[4.6,4.32]],"id":42248828}],"con":true,"img":false}]}
{"op":"mcm","clk":"5306467423","pt":1646098915174,"mc":[{"id":"1.195395419","rc":[{"atl":[[4.7,0]],"id":42248828}],"con":true,"img":false}]}
{"op":"mcm","clk":"5306467428","pt":1646098915278,"mc":[{"id":"1.195395419","rc":[{"atl":[[4.5,1.32]],"id":42248828}],"con":true,"img":false}]}
{"op":"mcm","clk":"5306467470","pt":1646098916459,"mc":[{"id":"1.195395419","rc":[{"atl":[[3.85,43.86]],"id":43154449}],"con":true,"img":false}]}
{"op":"mcm","clk":"5306467476","pt":1646098916562,"mc":[{"id":"1.195395419","rc":[{"atl":[[3.85,26.32],[4.1,0]],"id":43154449}],"con":true,"img":false}]}
{"op":"mcm","clk":"5306467845","pt":1646098926469,"mc":[{"id":"1.195395419","rc":[{"atl":[[3.95,42.37]],"id":43154449}],"con":true,"img":false}]}
{"op":"mcm","clk":"5306468019","pt":1646098930975,"mc":[{"id":"1.195395419","rc":[{"atl":[[3.9,0]],"id":43154449}],"con":true,"img":false}]}
{"op":"mcm","clk":"5306468024","pt":1646098931078,"mc":[{"id":"1.195395419","rc":[{"atl":[[3.8,18.71]],"id":43154449}],"con":true,"img":false}]}
{"op":"mcm","clk":"5306468436","pt":1646098941090,"mc":[{"id":"1.195395419","rc":[{"atl":[[5.1,0]],"id":43154449}],"con":true,"img":false}]}
{"op":"mcm","clk":"5306468440","pt":1646098941192,"mc":[{"id":"1.195395419","rc":[{"atl":[[4.6,28.03]],"id":43154449}],"con":true,"img":false}]}
{"op":"mcm","clk":"5306468608","pt":1646098945040,"mc":[{"id":"1.195395419","rc":[{"atl":[[4.6,0]],"id":42248828}],"con":true,"img":false}]}
{"op":"mcm","clk":"5306468613","pt":1646098945195,"mc":[{"id":"1.195395419","rc":[{"atl":[[4.4,4.32]],"id":42248828}],"con":true,"img":false}]}
{"op":"mcm","clk":"5306468626","pt":1646098945401,"mc":[{"id":"1.195395419","rc":[{"atl":[[4.5,0]],"id":42248828}],"con":true,"img":false}]}
{"op":"mcm","clk":"5306468632","pt":1646098945503,"mc":[{"id":"1.195395419","rc":[{"atl":[[4.3,1.32]],"id":42248828}],"con":true,"img":false}]}
{"op":"mcm","clk":"5306469086","pt":1646098956538,"mc":[{"id":"1.195395419","rc":[{"atb":[[8,0]],"id":42352031},{"atl":[[50,2.77]],"id":42413752},{"atb":[[9.8,0]],"id":43154448},{"atl":[[23,2.7]],"id":43154448},{"atl":[[440,2]],"id":41642357},{"atl":[[48,2.78]],"id":43154446}],"con":true,"img":false}]}
{"op":"mcm","clk":"5306469097","pt":1646098956743,"mc":[{"id":"1.195395419","rc":[{"atb":[[8.4,0],[1.02,2.23]],"id":42352031}],"con":true,"img":false}]}
{"op":"mcm","clk":"5306469106","pt":1646098956947,"mc":[{"id":"1.195395419","rc":[{"atb":[[1.02,0.44]],"id":42352031},{"atb":[[10.5,0]],"id":43154448}],"con":true,"img":false}]}
{"op":"mcm","clk":"5306469108","pt":1646098957048,"mc":[{"id":"1.195395419","rc":[{"atb":[[1.02,0]],"id":42352031},{"atb":[[1.02,2.23]],"id":43154448}],"con":true,"img":false}]}
{"op":"mcm","clk":"5306469112","pt":1646098957150,"mc":[{"id":"1.195395419","rc":[{"atb":[[7.6,0.44]],"id":42352031}],"con":true,"img":false}]}
{"op":"mcm","clk":"5306469115","pt":1646098957355,"mc":[{"id":"1.195395419","rc":[{"atb":[[1.02,0.35]],"id":43154448}],"con":true,"img":false}]}
{"op":"mcm","clk":"5306469122","pt":1646098957516,"mc":[{"id":"1.195395419","rc":[{"atb":[[1.02,0]],"id":43154448}],"con":true,"img":false}]}
{"op":"mcm","clk":"5306469129","pt":1646098957616,"mc":[{"id":"1.195395419","rc":[{"atb":[[9.8,0.35]],"id":43154448}],"con":true,"img":false}]}
{"op":"mcm","clk":"5306469282","pt":1646098961420,"mc":[{"id":"1.195395419","rc":[{"spn":12.6,"spf":1.0,"id":42352031},{"spn":3.7,"spf":1.0,"id":42248828},{"spn":16.0,"spf":1.0,"id":43154448}],"con":true,"img":false}]}
{"op":"mcm","clk":"5306469683","pt":1646098971326,"mc":[{"id":"1.195395419","rc":[{"atb":[[1.03,2.23]],"id":43154446}],"con":true,"img":false}]}
{"op":"mcm","clk":"5306469690","pt":1646098971533,"mc":[{"id":"1.195395419","rc":[{"atb":[[16,0]],"id":43154446}],"con":true,"img":false}]}
{"op":"mcm","clk":"5306469694","pt":1646098971737,"mc":[{"id":"1.195395419","rc":[{"atb":[[1.03,0.21]],"id":43154446}],"con":true,"img":false}]}
{"op":"mcm","clk":"5306469721","pt":1646098972152,"mc":[{"id":"1.195395419","rc":[{"atb":[[1.03,0]],"id":43154446}],"con":true,"img":false}]}
{"op":"mcm","clk":"5306469726","pt":1646098972256,"mc":[{"id":"1.195395419","rc":[{"atb":[[17.5,0.21]],"id":43154446}],"con":true,"img":false}]}
{"op":"mcm","clk":"5306469833","pt":1646098975432,"mc":[{"id":"1.195395419","rc":[{"atl":[[4.4,0]],"id":42248828}],"con":true,"img":false}]}
{"op":"mcm","clk":"5306469844","pt":1646098975842,"mc":[{"id":"1.195395419","rc":[{"atb":[[16.5,0]],"id":43154446}],"con":true,"img":false}]}
{"op":"mcm","clk":"5306469855","pt":1646098976150,"mc":[{"id":"1.195395419","rc":[{"atl":[[4.3,0]],"id":42248828}],"con":true,"img":false}]}
{"op":"mcm","clk":"5306469860","pt":1646098976253,"mc":[{"id":"1.195395419","rc":[{"atl":[[4.9,1.32]],"id":42248828}],"con":true,"img":false}]}
{"op":"mcm","clk":"5306469938","pt":1646098977950,"mc":[{"id":"1.195395419","rc":[{"atl":[[4.8,4.32]],"id":42248828}],"con":true,"img":false}]}
{"op":"mcm","clk":"5306469957","pt":1646098978565,"mc":[{"id":"1.195395419","rc":[{"atl":[[4.9,0]],"id":42248828}],"con":true,"img":false}]}
{"op":"mcm","clk":"5306469961","pt":1646098978667,"mc":[{"id":"1.195395419","rc":[{"atl":[[4.7,1.32]],"id":42248828}],"con":true,"img":false}]}
{"op":"mcm","clk":"5306470061","pt":1646098981032,"mc":[{"id":"1.195395419","rc":[{"atb":[[1.2,2.23]],"id":43154446}],"con":true,"img":false}]}
{"op":"mcm","clk":"5306470070","pt":1646098981339,"mc":[{"id":"1.195395419","rc":[{"atb":[[1.2,1.55]],"id":43154446}],"con":true,"img":false}]}
{"op":"mcm","clk":"5306470079","pt":1646098981650,"mc":[{"id":"1.195395419","rc":[{"atb":[[1.2,0]],"id":43154446}],"con":true,"img":false}]}
{"op":"mcm","clk":"5306470082","pt":1646098981750,"mc":[{"id":"1.195395419","rc":[{"atb":[[15.5,2.25]],"id":43154446}],"con":true,"img":false}]}
{"op":"mcm","clk":"5306470879","pt":1646099000970,"mc":[{"id":"1.195395419","rc":[{"atl":[[12,0],[9.8,12.07]],"id":43154447}],"con":true,"img":false}]}
{"op":"mcm","clk":"5306471202","pt":1646099008184,"mc":[{"id":"1.195395419","rc":[{"atl":[[4.8,0]],"id":42248828}],"con":true,"img":false}]}
{"op":"mcm","clk":"5306471211","pt":1646099008389,"mc":[{"id":"1.195395419","rc":[{"atl":[[4.6,4.32]],"id":42248828}],"con":true,"img":false}]}
{"op":"mcm","clk":"5306471219","pt":1646099008492,"mc":[{"id":"1.195395419","rc":[{"atl":[[4.7,0]],"id":42248828}],"con":true,"img":false}]}
{"op":"mcm","clk":"5306471225","pt":1646099008595,"mc":[{"id":"1.195395419","rc":[{"atl":[[4.9,1.32]],"id":42248828}],"con":true,"img":false}]}
{"op":"mcm","clk":"5306471246","pt":1646099009110,"mc":[{"id":"1.195395419","rc":[{"atl":[[4.9,0]],"id":42248828}],"con":true,"img":false}]}
{"op":"mcm","clk":"5306471253","pt":1646099009207,"mc":[{"id":"1.195395419","rc":[{"atl":[[4.5,1.32]],"id":42248828}],"con":true,"img":false}]}
{"op":"mcm","clk":"5306471551","pt":1646099016504,"mc":[{"id":"1.195395419","rc":[{"atb":[[3,47.16]],"id":42352031},{"atb":[[2.5,100.93],[2.28,78.13]],"id":42248828},{"atl":[[65,0],[75,2]],"id":42413752},{"atb":[[2.68,0]],"id":41642357},{"atb":[[3.1,0],[2.86,53.58]],"id":43154447}],"con":true,"img":false}]}
{"op":"mcm","clk":"5306471555","pt":1646099016606,"mc":[{"id":"1.195395419","rc":[{"atb":[[4.4,0]],"id":42352031}],"con":true,"img":false}]}
{"op":"mcm","clk":"5306471849","pt":1646099023594,"mc":[{"id":"1.195395419","rc":[{"spn":3.8,"spf":1.0,"id":42248828},{"spn":31.75,"spf":1.0,"id":43154446}],"con":true,"img":false}]}
{"op":"mcm","clk":"5306472164","pt":1646099031498,"mc":[{"id":"1.195395419","rc":[{"atb":[[1.02,2.23],[7.6,0]],"id":42352031}],"con":true,"img":false}]}
{"op":"mcm","clk":"5306472167","pt":1646099031600,"mc":[{"id":"1.195395419","rc":[{"atb":[[1.02,0.44]],"id":42352031},{"atb":[[1.02,2.23]],"id":43154448}],"con":true,"img":false}]}
{"op":"mcm","clk":"5306472175","pt":1646099031804,"mc":[{"id":"1.195395419","rc":[{"atb":[[1.02,0.35],[9.8,0]],"id":43154448}],"con":true,"img":false}]}
{"op":"mcm","clk":"5306472185","pt":1646099032011,"mc":[{"id":"1.195395419","rc":[{"atb":[[1.02,0]],"id":42352031}],"con":true,"img":false}]}
{"op":"mcm","clk":"5306472188","pt":1646099032115,"mc":[{"id":"1.195395419","rc":[{"atb":[[8.4,0.44]],"id":42352031}],"con":true,"img":false}]}
{"op":"mcm","clk":"5306472194","pt":1646099032216,"mc":[{"id":"1.195395419","rc":[{"atb":[[1.02,0]],"id":43154448}],"con":true,"img":false}]}
{"op":"mcm","clk":"5306472198","pt":1646099032321,"mc":[{"id":"1.195395419","rc":[{"atb":[[10.5,0.35]],"id":43154448}],"con":true,"img":false}]}
{"op":"mcm","clk":"5306472457","pt":1646099038543,"mc":[{"id":"1.195395419","rc":[{"atl":[[4.6,0]],"id":42248828}],"con":true,"img":false}]}
{"op":"mcm","clk":"5306472466","pt":1646099038745,"mc":[{"id":"1.195395419","rc":[{"atl":[[4.4,4.32]],"id":42248828}],"con":true,"img":false}]}
{"op":"mcm","clk":"5306472480","pt":1646099039107,"mc":[{"id":"1.195395419","rc":[{"atl":[[4.5,0]],"id":42248828}],"con":true,"img":false}]}
{"op":"mcm","clk":"5306472484","pt":1646099039208,"mc":[{"id":"1.195395419","rc":[{"atl":[[4.3,1.32]],"id":42248828}],"con":true,"img":false}]}
{"op":"mcm","clk":"5306472519","pt":1646099040132,"mc":[{"id":"1.195395419","rc":[{"atb":[[2.4,72.43],[2.36,0],[2.34,14.93]],"id":43154449},{"atb":[[4,0],[3.9,6.9]],"id":43154447}],"con":true,"img":false}]}
{"op":"mcm","clk":"5306472900","pt":1646099050151,"mc":[{"id":"1.195395419","rc":[{"atb":[[2.3,116.46]],"id":43154449},{"atb":[[3.8,17.86]],"id":43154447}],"con":true,"img":false}]}
{"op":"mcm","clk":"5306473268","pt":1646099060148,"mc":[{"id":"1.195395419","rc":[{"atb":[[2.26,59.52]],"id":43154449},{"atb":[[3.7,111.63]],"id":43154447}],"con":true,"img":false}]}
{"op":"mcm","clk":"5306473273","pt":1646099060249,"mc":[{"id":"1.195395419","rc":[{"atb":[[3.7,65.33]],"id":43154447}],"con":true,"img":false}]}
{"op":"mcm","clk":"5306473595","pt":1646099068979,"mc":[{"id":"1.195395419","rc":[{"atl":[[4.4,0]],"id":42248828}],"con":true,"img":false}]}
{"op":"mcm","clk":"5306473622","pt":1646099069747,"mc":[{"id":"1.195395419","rc":[{"atl":[[4.3,0]],"id":42248828}],"con":true,"img":false}]}
{"op":"mcm","clk":"5306473629","pt":1646099069851,"mc":[{"id":"1.195395419","rc":[{"atl":[[4.9,1.32]],"id":42248828}],"con":true,"img":false}]}
{"op":"mcm","clk":"5306473643","pt":1646099070162,"mc":[{"id":"1.195395419","rc":[{"atb":[[2.32,45.94],[2.22,102.46],[2.28,0]],"id":43154449},{"atb":[[3.6,48.08]],"id":43154447}],"con":true,"img":false}]}
{"op":"mcm","clk":"5306473697","pt":1646099071752,"mc":[{"id":"1.195395419","rc":[{"atl":[[4.8,4.32]],"id":42248828}],"con":true,"img":false}]}
{"op":"mcm","clk":"5306473707","pt":1646099072164,"mc":[{"id":"1.195395419","rc":[{"atl":[[4.9,0]],"id":42248828}],"con":true,"img":false}]}
{"op":"mcm","clk":"5306473710","pt":1646099072266,"mc":[{"id":"1.195395419","rc":[{"atl":[[4.7,1.32]],"id":42248828}],"con":true,"img":false}]}
{"op":"mcm","clk":"5306473818","pt":1646099075501,"mc":[{"id":"1.195395419","rc":[{"atl":[[7.2,1.8]],"id":43154447},{"trd":[[7.2,5.4]],"ltp":7.2,"tv":5.4,"id":43154447}],"con":true,"img":false}]}
{"op":"mcm","clk":"5306473822","pt":1646099075556,"mc":[{"id":"1.195395419","rc":[{"atl":[[8.2,0],[7.8,2.86],[7.2,0],[8.6,0]],"id":43154447}],"con":true,"img":false}]}
{"op":"mcm","clk":"5306473826","pt":1646099075658,"mc":[{"id":"1.195395419","rc":[{"atb":[[4.3,7.65]],"id":43154447}],"con":true,"img":false}]}
{"op":"mcm","clk":"5306473839","pt":1646099075967,"mc":[{"id":"1.195395419","rc":[{"atl":[[8.4,0]],"id":43154447}],"con":true,"img":false}]}
{"op":"mcm","clk":"5306473842","pt":1646099076067,"mc":[{"id":"1.195395419","rc":[{"atl":[[9.2,7.07]],"id":43154447}],"con":true,"img":false}]}
{"op":"mcm","clk":"5306473932","pt":1646099078582,"mc":[{"id":"1.195395419","rc":[{"atl":[[70,0]],"id":43154446}],"con":true,"img":false}]}
{"op":"mcm","clk":"5306473937","pt":1646099078686,"mc":[{"id":"1.195395419","rc":[{"atb":[[8,2],[4.3,30.3],[3,0]],"id":42352031},{"atb":[[2.38,72.46],[2.28,0]],"id":42248828},{"atb":[[18.5,2]],"id":42413752},{"atl":[[70,2],[75,0],[50,4.77]],"id":42413752},{"atb":[[4.4,0],[4.1,6.45],[9.8,2],[4.2,31.25]],"id":43154448},{"atl":[[23,4.7]],"id":43154448},{"atb":[[1.04,7.43]],"id":41642357},{"atl":[[440,4]],"id":41642357},{"atl":[[3.55,7.84],[3.65,0]],"id":43154449},{"atl":[[65,2],[48,4.78]],"id":43154446},{"atb":[[2.86,0],[3.15,46.51]],"id":43154447}],"con":true,"img":false}]}
{"op":"mcm","clk":"5306473949","pt":1646099078889,"mc":[{"id":"1.195395419","rc":[{"atb":[[1.02,2.23]],"id":42352031}],"con":true,"img":false}]}
{"op":"mcm","clk":"5306473954","pt":1646099078992,"mc":[{"id":"1.195395419","rc":[{"atb":[[8.4,0]],"id":42352031}],"con":true,"img":false}]}
{"op":"mcm","clk":"5306473961","pt":1646099079095,"mc":[{"id":"1.195395419","rc":[{"atb":[[1.02,0.44]],"id":42352031}],"con":true,"img":false}]}
{"op":"mcm","clk":"5306473965","pt":1646099079197,"mc":[{"id":"1.195395419","rc":[{"atb":[[10.5,0]],"id":43154448}],"con":true,"img":false}]}
{"op":"mcm","clk":"5306473969","pt":1646099079301,"mc":[{"id":"1.195395419","rc":[{"atb":[[1.02,0]],"id":42352031},{"atb":[[1.02,2.23]],"id":43154448}],"con":true,"img":false}]}
{"op":"mcm","clk":"5306473975","pt":1646099079404,"mc":[{"id":"1.195395419","rc":[{"atb":[[8.2,2.95]],"id":42352031}],"con":true,"img":false}]}
{"op":"mcm","clk":"5306473983","pt":1646099079506,"mc":[{"id":"1.195395419","rc":[{"atb":[[17,0]],"id":42413752}],"con":true,"img":false}]}
{"op":"mcm","clk":"5306473994","pt":1646099079712,"mc":[{"id":"1.195395419","rc":[{"atb":[[1.02,0.35]],"id":43154448}],"con":true,"img":false}]}
{"op":"mcm","clk":"5306474001","pt":1646099079765,"mc":[{"id":"1.195395419","rc":[{"atl":[[19.5,1.08],[21,0]],"id":42352031},{"atb":[[1.04,0]],"id":41642357},{"atl":[[3.55,0],[3.7,7.41]],"id":43154449},{"atb":[[2.08,17.85]],"id":43154446},{"atb":[[4,6.67],[3.9,0]],"id":43154447},{"atl":[[8,2.78],[9,10.4],[10,0],[7.8,0]],"id":43154447}],"con":true,"img":false}]}
{"op":"mcm","clk":"5306474007","pt":1646099079867,"mc":[{"id":"1.195395419","rc":[{"atb":[[1.02,0]],"id":43154448}],"con":true,"img":false}]}
{"op":"mcm","clk":"5306474012","pt":1646099079970,"mc":[{"id":"1.195395419","rc":[{"atb":[[10,2.86]],"id":43154448}],"con":true,"img":false}]}
{"op":"mcm","clk":"5306474033","pt":1646099080590,"mc":[{"id":"1.195395419","rc":[{"atl":[[9.2,24.16],[6.6,21.43]],"id":42248828},{"atb":[[8,17.15],[5.1,0],[5,0]],"id":42413752},{"atb":[[5.9,18.81],[6.2,3.85],[4.2,0]],"id":43154448},{"atb":[[50,0],[65,1]],"id":41642357},{"atb":[[2.34,0],[2.24,0],[2.42,14.08],[2.52,65.79],[2.46,13.7]],"id":43154449},{"atl":[[3.85,0],[3.75,0],[4.6,33.59],[3.95,0],[3.7,0]],"id":43154449},{"atb":[[3.6,0],[2.5,13.33],[3.8,0],[4,0],[2.42,14.08],[3.7,37.55],[3.15,0]],"id":43154447},{"atl":[[7.8,2.86]],"id":43154447}],"con":true,"img":false}]}
{"op":"mcm","clk":"5306474042","pt":1646099080792,"mc":[{"id":"1.195395419","rc":[{"atb":[[2.34,46.79]],"id":43154447}],"con":true,"img":false}]}
{"op":"mcm","clk":"5306474054","pt":1646099080997,"mc":[{"id":"1.195395419","rc":[{"atl":[[12,8.85]],"id":43154447}],"con":true,"img":false}]}
{"op":"mcm","clk":"5306474061","pt":1646099081099,"mc":[{"id":"1.195395419","rc":[{"atl":[[3.8,0]],"id":43154449},{"atl":[[9.8,0]],"id":43154447}],"con":true,"img":false}]}
{"op":"mcm","clk":"5306474066","pt":1646099081202,"mc":[{"id":"1.195395419","rc":[{"atl":[[4.1,18.71]],"id":43154449}],"con":true,"img":false}]}
{"op":"mcm","clk":"5306474179","pt":1646099083773,"mc":[{"id":"1.195395419","rc":[{"spn":3.9,"spf":1.0,"id":42248828},{"atl":[[85,2]],"id":42413752},{"spn":33.25,"spf":1.0,"id":42413752},{"spn":6.2,"spf":1.0,"id":43154447}],"con":true,"img":false}]}
{"op":"mcm","clk":"5306474187","pt":1646099083874,"mc":[{"id":"1.195395419","rc":[{"atl":[[70,0]],"id":42413752}],"con":true,"img":false}]}
{"op":"mcm","clk":"5306474289","pt":1646099085986,"mc":[{"id":"1.195395419","rc":[{"atb":[[6.8,3.45],[6.2,0]],"id":43154448},{"atb":[[2.22,0]],"id":43154449}],"con":true,"img":false}]}
{"op":"mcm","clk":"5306474422","pt":1646099088907,"mc":[{"id":"1.195395419","rc":[{"atl":[[24,0],[25,6.4]],"id":43154448}],"con":true,"img":false}]}
{"op":"mcm","clk":"5306474429","pt":1646099089008,"mc":[{"id":"1.195395419","rc":[{"atb":[[4.3,0],[4.9,25.64]],"id":42352031}],"con":true,"img":false}]}
{"op":"mcm","clk":"5306474435","pt":1646099089111,"mc":[{"id":"1.195395419","rc":[{"atl":[[65,0],[48,6.91]],"id":43154446}],"con":true,"img":false}]}
{"op":"mcm","clk":"5306474458","pt":1646099089782,"mc":[{"id":"1.195395419","rc":[{"atl":[[21,2.5]],"id":42352031}],"con":true,"img":false}]}
{"op":"mcm","clk":"5306474467","pt":1646099090089,"mc":[{"id":"1.195395419","rc":[{"atb":[[2.08,0],[3.15,32.08]],"id":43154446}],"con":true,"img":false}]}
{"op":"mcm","clk":"5306474485","pt":1646099090601,"mc":[{"id":"1.195395419","rc":[{"atl":[[7,8.33]],"id":42248828},{"atb":[[7.6,7.58]],"id":42413752},{"atb":[[55,2.87]],"id":41642357},{"atb":[[2.42,35.21]],"id":43154449},{"atl":[[4.8,13.16]],"id":43154449},{"atb":[[2.46,34.25]],"id":43154447},{"atl":[[8.2,6.76]],"id":43154447}],"con":true,"img":false}]}
{"op":"mcm","clk":"5306474489","pt":1646099090702,"mc":[{"id":"1.195395419","rc":[{"atl":[[8.4,8.86]],"id":43154447}],"con":true,"img":false}]}
{"op":"mcm","clk":"5306474493","pt":1646099090805,"mc":[{"id":"1.195395419","rc":[{"atl":[[9,0]],"id":43154447}],"con":true,"img":false}]}
{"op":"mcm","clk":"5306474760","pt":1646099097997,"mc":[{"id":"1.195395419","rc":[{"atb":[[16.5,1.56]],"id":42413752},{"atb":[[9.2,0]],"id":43154448}],"con":true,"img":false}]}
{"op":"mcm","clk":"5306474767","pt":1646099098099,"mc":[{"id":"1.195395419","rc":[{"atb":[[18.5,2.58]],"id":42413752},{"atb":[[10,3.98]],"id":43154448}],"con":true,"img":false}]}
{"op":"mcm","clk":"5306474770","pt":1646099098203,"mc":[{"id":"1.195395419","rc":[{"atb":[[10.5,2],[9.8,0]],"id":43154448}],"con":true,"img":false}]}
{"op":"mcm","clk":"5306474792","pt":1646099098921,"mc":[{"id":"1.195395419","rc":[{"atb":[[6.4,9.26]],"id":43154448},{"atl":[[27,1.92]],"id":43154448}],"con":true,"img":false}]}
{"op":"mcm","clk":"5306474806","pt":1646099099336,"mc":[{"id":"1.195395419","rc":[{"atb":[[7.6,7.43]],"id":42352031},{"atb":[[2.88,7.56]],"id":42248828},{"atb":[[17,3.32]],"id":42413752},{"atl":[[2.58,0],[2.62,0]],"id":43154449},{"trd":[[2.62,21.66],[2.58,23.99]],"ltp":2.62,"tv":45.65,"id":43154449},{"atb":[[16,3.41]],"id":43154446}],"con":true,"img":false}]}
{"op":"mcm","clk":"5306474814","pt":1646099099492,"mc":[{"id":"1.195395419","rc":[{"atb":[[10,1.47]],"id":43154448},{"atb":[[1.03,2.23]],"id":43154446}],"con":true,"img":false}]}
{"op":"mcm","clk":"5306474819","pt":1646099099598,"mc":[{"id":"1.195395419","rc":[{"atb":[[2.88,8.91]],"id":42248828},{"atb":[[2.56,1.29]],"id":43154449},{"atb":[[1.03,0.21],[17.5,0]],"id":43154446},{"atb":[[4.5,3.8]],"id":43154447}],"con":true,"img":false}]}
{"op":"mcm","clk":"5306474826","pt":1646099099701,"mc":[{"id":"1.195395419","rc":[{"atb":[[2.56,2.88]],"id":43154449},{"atl":[[4,1.22]],"id":43154449},{"atb":[[1.03,0]],"id":43154446}],"con":true,"img":false}]}
{"op":"mcm","clk":"5306474832","pt":1646099099807,"mc":[{"id":"1.195395419","rc":[{"atl":[[23,3.41],[27,0]],"id":42352031},{"atb":[[16.5,0.21]],"id":43154446}],"con":true,"img":false}]}
{"op":"mcm","clk":"5306474848","pt":1646099100214,"mc":[{"id":"1.195395419","rc":[{"atb":[[9.6,2.88]],"id":43154448},{"atb":[[2.58,5.18]],"id":43154449},{"atl":[[4,5.73],[3.95,6.49]],"id":43154449}],"con":true,"img":false}]}
{"op":"mcm","clk":"5306474852","pt":1646099100326,"mc":[{"id":"1.195395419","rc":[{"atb":[[7.2,4]],"id":43154448}],"con":true,"img":false}]}
{"op":"mcm","clk":"5306474880","pt":1646099100636,"mc":[{"id":"1.195395419","rc":[{"atl":[[10,0],[11,8.2],[7.4,11.72],[9.6,0]],"id":42248828},{"atb":[[4.9,0],[7.2,12.1],[4.5,0],[4.7,0]],"id":42413752},{"atb":[[48,1.6]],"id":41642357},{"atb":[[2.38,54.35]],"id":43154449},{"atl":[[5,18.75]],"id":43154449},{"atb":[[2.42,52.82]],"id":43154447},{"atl":[[8.6,9.6]],"id":43154447}],"con":true,"img":false}]}
{"op":"mcm","clk":"5306474887","pt":1646099100692,"mc":[{"id":"1.195395419","rc":[{"atb":[[38,2.74],[42,0],[46,2.7]],"id":41642357}],"con":true,"img":false}]}
{"op":"mcm","clk":"5306474898","pt":1646099101009,"mc":[{"id":"1.195395419","rc":[{"atb":[[2.56,1.58]],"id":43154449},{"atl":[[4,4.5],[3.9,4.32]],"id":43154449},{"atb":[[4.2,33.21]],"id":43154447}],"con":true,"img":false}]}
{"op":"mcm","clk":"5306474903","pt":1646099101104,"mc":[{"id":"1.195395419","rc":[{"atb":[[2.38,0],[2.2,83.33]],"id":42248828},{"atb":[[6.4,0],[7.4,4],[6.8,0],[7.2,0],[6.2,3.85],[4.1,0]],"id":43154448},{"atl":[[24,1],[25,5.4],[26,0],[27,0],[28,0],[30,0]],"id":43154448},{"atb":[[2.44,54.35],[2.58,6.48],[2.26,0],[2.52,0]],"id":43154449},{"atl":[[3.9,5.55]],"id":43154449},{"atb":[[2.58,17.85],[3.15,0]],"id":43154446},{"atb":[[2.5,0],[4.4,19.78],[2.42,14.08],[2.46,0]],"id":43154447},{"atl":[[5.2,4]],"id":43154447}],"con":true,"img":false}]}
{"op":"mcm","clk":"5306474925","pt":1646099101516,"mc":[{"id":"1.195395419","rc":[{"atb":[[4.5,2.5]],"id":43154447}],"con":true,"img":false}]}
{"op":"mcm","clk":"5306474930","pt":1646099101618,"mc":[{"id":"1.195395419","rc":[{"atb":[[4.3,7.61],[1.02,1.3]],"id":43154447}],"con":true,"img":false}]}
{"op":"mcm","clk":"5306474960","pt":1646099102030,"mc":[{"id":"1.195395419","rc":[{"atl":[[4.8,0]],"id":42248828},{"atb":[[19,2.08]],"id":42413752},{"atb":[[11,2.08]],"id":43154448},{"atb":[[2.6,2.5]],"id":43154449},{"atb":[[1.01,2.53],[4.5,0]],"id":43154447}],"con":true,"img":false}]}
{"op":"mcm","clk":"5306474967","pt":1646099102237,"mc":[{"id":"1.195395419","rc":[{"atl":[[4.6,4.32]],"id":42248828},{"atb":[[4.3,5.51],[1.01,2.11]],"id":43154447}],"con":true,"img":false}]}
{"op":"mcm","clk":"5306474971","pt":1646099102291,"mc":[{"id":"1.195395419","rc":[{"atb":[[4.5,2.09]],"id":43154447}],"con":true,"img":false}]}
{"op":"mcm","clk":"5306474978","pt":1646099102394,"mc":[{"id":"1.195395419","rc":[{"atb":[[1.01,0]],"id":43154447}],"con":true,"img":false}]}
{"op":"mcm","clk":"5306474985","pt":1646099102546,"mc":[{"id":"1.195395419","rc":[{"atb":[[7.4,1.57]],"id":42352031},{"atb":[[2.44,0],[2.56,16.09],[2.52,35.21]],"id":43154449},{"atb":[[15.5,0.7]],"id":43154446},{"atb":[[4.6,2.92]],"id":43154447}],"con":true,"img":false}]}
{"op":"mcm","clk":"5306475009","pt":1646099102805,"mc":[{"id":"1.195395419","rc":[{"atl":[[4.7,0]],"id":42248828}],"con":true,"img":false}]}
{"op":"mcm","clk":"5306475018","pt":1646099102909,"mc":[{"id":"1.195395419","rc":[{"atl":[[4.5,1.32]],"id":42248828}],"con":true,"img":false}]}
{"op":"mcm","clk":"5306475040","pt":1646099103215,"mc":[{"id":"1.195395419","rc":[{"atb":[[2.88,1.35]],"id":42248828}],"con":true,"img":false}]}
{"op":"mcm","clk":"5306475093","pt":1646099103935,"mc":[{"id":"1.195395419","rc":[{"atb":[[2.88,0]],"id":42248828}],"con":true,"img":false}]}
{"op":"mcm","clk":"5306475096","pt":1646099104040,"mc":[{"id":"1.195395419","rc":[{"atb":[[2.72,1.35]],"id":42248828},{"atb":[[2.58,12.29],[2.56,14.5]],"id":43154449},{"atb":[[4.4,18.12]],"id":43154447}],"con":true,"img":false}]}
{"op":"mcm","clk":"5306475101","pt":1646099104105,"mc":[{"id":"1.195395419","rc":[{"atb":[[2.6,4.09]],"id":43154449},{"atb":[[1.01,1.65]],"id":43154447}],"con":true,"img":false}]}
{"op":"mcm","clk":"5306475126","pt":1646099104511,"mc":[{"id":"1.195395419","rc":[{"atl":[[25,0]],"id":43154448}],"con":true,"img":false}]}
{"op":"mcm","clk":"5306475132","pt":1646099104614,"mc":[{"id":"1.195395419","rc":[{"atl":[[29,5.4]],"id":43154448}],"con":true,"img":false}]}
{"op":"mcm","clk":"5306475139","pt":1646099104721,"mc":[{"id":"1.195395419","rc":[{"atb":[[2.58,11]],"id":43154449}],"con":true,"img":false}]}
{"op":"mcm","clk":"5306475144","pt":1646099104819,"mc":[{"id":"1.195395419","rc":[{"atb":[[2.6,5.38]],"id":43154449}],"con":true,"img":false}]}
{"op":"mcm","clk":"5306475234","pt":1646099106728,"mc":[{"id":"1.195395419","rc":[{"atb":[[6.8,3.45],[7.2,2]],"id":43154448},{"atl":[[24,0],[25,1]],"id":43154448},{"atb":[[2.5,13.33]],"id":43154447},{"atl":[[5.2,0]],"id":43154447}],"con":true,"img":false}]}
{"op":"mcm","clk":"5306475243","pt":1646099106932,"mc":[{"id":"1.195395419","rc":[{"atb":[[7.6,0]],"id":42352031},{"atb":[[17,0]],"id":42413752},{"atl":[[3.85,4.16]],"id":43154449},{"atb":[[16,0]],"id":43154446}],"con":true,"img":false}]}
{"op":"mcm","clk":"5306475248","pt":1646099107035,"mc":[{"id":"1.195395419","rc":[{"atb":[[1.01,0]],"id":43154447}],"con":true,"img":false}]}
{"op":"mcm","clk":"5306475254","pt":1646099107137,"mc":[{"id":"1.195395419","rc":[{"atb":[[4.7,1.65]],"id":43154447}],"con":true,"img":false}]}
{"op":"mcm","clk":"5306475270","pt":1646099107499,"mc":[{"id":"1.195395419","rc":[{"atb":[[1.02,0]],"id":43154447}],"con":true,"img":false}]}
{"op":"mcm","clk":"5306475276","pt":1646099107601,"mc":[{"id":"1.195395419","rc":[{"atl":[[3.9,4.32]],"id":43154449},{"atb":[[4.6,4.22]],"id":43154447}],"con":true,"img":false}]}
{"op":"mcm","clk":"5306475280","pt":1646099107702,"mc":[{"id":"1.195395419","rc":[{"atl":[[3.8,1.22]],"id":43154449}],"con":true,"img":false}]}
{"op":"mcm","clk":"5306475301","pt":1646099108112,"mc":[{"id":"1.195395419","rc":[{"atb":[[7.8,2.95]],"id":42352031},{"atb":[[2.72,7.35]],"id":42248828},{"atb":[[2.56,0]],"id":43154449},{"atb":[[4.8,2.5]],"id":43154447}],"con":true,"img":false}]}
{"op":"mcm","clk":"5306475324","pt":1646099108624,"mc":[{"id":"1.195395419","rc":[{"atb":[[60,0]],"id":41642357}],"con":true,"img":false}]}
{"op":"mcm","clk":"5306475331","pt":1646099108725,"mc":[{"id":"1.195395419","rc":[{"atb":[[7.4,0]],"id":42352031},{"atb":[[70,2.85]],"id":41642357},{"atb":[[4.7,0]],"id":43154447}],"con":true,"img":false}]}
{"op":"mcm","clk":"5306475335","pt":1646099108828,"mc":[{"id":"1.195395419","rc":[{"atb":[[8.4,1.57]],"id":42352031},{"atb":[[4.8,4.16]],"id":43154447}],"con":true,"img":false}]}
{"op":"mcm","clk":"5306475342","pt":1646099108930,"mc":[{"id":"1.195395419","rc":[{"atb":[[8,0],[8.4,3.57]],"id":42352031}],"con":true,"img":false}]}
{"op":"mcm","clk":"5306475356","pt":1646099109138,"mc":[{"id":"1.195395419","rc":[{"atb":[[8.4,1.57]],"id":42352031}],"con":true,"img":false}]}
{"op":"mcm","clk":"5306475370","pt":1646099109341,"mc":[{"id":"1.195395419","rc":[{"atb":[[8.2,4.95]],"id":42352031},{"atb":[[4.3,2.78],[4.6,2.92]],"id":43154447}],"con":true,"img":false}]}
{"op":"mcm","clk":"5306475375","pt":1646099109444,"mc":[{"id":"1.195395419","rc":[{"atb":[[4.8,5.46]],"id":43154447}],"con":true,"img":false}]}
{"op":"mcm","clk":"5306475390","pt":1646099109602,"mc":[{"id":"1.195395419","rc":[{"atb":[[8.2,2.44]],"id":42352031}],"con":true,"img":false}]}
{"op":"mcm","clk":"5306475399","pt":1646099109809,"mc":[{"id":"1.195395419","rc":[{"atl":[[25,5.21]],"id":42352031},{"atb":[[4.6,0.81]],"id":43154447}],"con":true,"img":false}]}
{"op":"mcm","clk":"5306475410","pt":1646099110014,"mc":[{"id":"1.195395419","rc":[{"atb":[[8.4,0]],"id":42352031},{"atb":[[4.5,1.92]],"id":43154447}],"con":true,"img":false}]}
{"op":"mcm","clk":"5306475415","pt":1646099110116,"mc":[{"id":"1.195395419","rc":[{"atb":[[1.01,1.57]],"id":42352031},{"atb":[[2.74,2.89]],"id":42248828}],"con":true,"img":false}]}
{"op":"mcm","clk":"5306475423","pt":1646099110318,"mc":[{"id":"1.195395419","rc":[{"atl":[[4.5,4.07]],"id":43154449}],"con":true,"img":false}]}
{"op":"mcm","clk":"5306475438","pt":1646099110630,"mc":[{"id":"1.195395419","rc":[{"atl":[[7.8,18.38]],"id":42248828},{"atb":[[6.8,21.55]],"id":42413752},{"atb":[[44,2.91]],"id":41642357},{"atb":[[2.34,93.28]],"id":43154449},{"atl":[[5.2,29.76]],"id":43154449},{"atb":[[4.8,3.8],[4.5,0]],"id":43154447}],"con":true,"img":false}]}
{"op":"mcm","clk":"5306475445","pt":1646099110730,"mc":[{"id":"1.195395419","rc":[{"atb":[[1.01,4.18],[4.9,1.92]],"id":43154447}],"con":true,"img":false}]}
{"op":"mcm","clk":"5306475450","pt":1646099110832,"mc":[{"id":"1.195395419","rc":[{"atb":[[2.72,6]],"id":42248828},{"atb":[[2.44,54.35]],"id":43154449},{"atb":[[4.8,2.5]],"id":43154447}],"con":true,"img":false}]}
{"op":"mcm","clk":"5306475459","pt":1646099110935,"mc":[{"id":"1.195395419","rc":[{"atb":[[2.74,4.24]],"id":42248828},{"atb":[[2.52,0]],"id":43154449},{"atb":[[1.01,3.76],[1.02,1.3]],"id":43154447}],"con":true,"img":false}]}
{"op":"mcm","clk":"5306475464","pt":1646099111037,"mc":[{"id":"1.195395419","rc":[{"atb":[[2.62,3.76]],"id":43154449},{"atb":[[1.01,1.65]],"id":43154447}],"con":true,"img":false}]}
{"op":"mcm","clk":"5306475466","pt":1646099111141,"mc":[{"id":"1.195395419","rc":[{"atb":[[4.9,2.11]],"id":43154447}],"con":true,"img":false}]}
{"op":"mcm","clk":"5306475471","pt":1646099111243,"mc":[{"id":"1.195395419","rc":[{"atb":[[4.5,1.92]],"id":43154447}],"con":true,"img":false}]}
{"op":"mcm","clk":"5306475482","pt":1646099111448,"mc":[{"id":"1.195395419","rc":[{"atb":[[1.02,0]],"id":43154447}],"con":true,"img":false}]}
{"op":"mcm","clk":"5306475489","pt":1646099111552,"mc":[{"id":"1.195395419","rc":[{"atb":[[4.5,3.23]],"id":43154447}],"con":true,"img":false}]}
{"op":"mcm","clk":"5306475497","pt":1646099111605,"mc":[{"id":"1.195395419","rc":[{"spl":[[1.01,37.86]],"id":43154447}],"con":true,"img":false}]}
{"op":"mcm","clk":"5306475504","pt":1646099111708,"mc":[{"id":"1.195395419","rc":[{"atb":[[2.6,4.09]],"id":43154449}],"con":true,"img":false}]}
{"op":"mcm","clk":"5306475511","pt":1646099111811,"mc":[{"id":"1.195395419","rc":[{"atb":[[2.6,2.5],[2.62,5.06]],"id":43154449}],"con":true,"img":false}]}
{"op":"mcm","clk":"5306475517","pt":1646099111914,"mc":[{"id":"1.195395419","rc":[{"atb":[[2.64,1.58]],"id":43154449}],"con":true,"img":false}]}
{"op":"mcm","clk":"5306475524","pt":1646099112019,"mc":[{"id":"1.195395419","rc":[{"atb":[[8.4,2.5]],"id":42352031}],"con":true,"img":false}]}
{"op":"mcm","clk":"5306475527","pt":1646099112124,"mc":[{"id":"1.195395419","rc":[{"atb":[[2.6,0]],"id":43154449},{"atb":[[4.8,0]],"id":43154447}],"con":true,"img":false}]}
{"op":"mcm","clk":"5306475537","pt":1646099112430,"mc":[{"id":"1.195395419","rc":[{"atb":[[1.01,0]],"id":43154447}],"con":true,"img":false}]}
{"op":"mcm","clk":"5306475541","pt":1646099112528,"mc":[{"id":"1.195395419","rc":[{"atl":[[3.95,0]],"id":43154449},{"atb":[[4.6,2.46]],"id":43154447},{"atl":[[9.2,0]],"id":43154447}],"con":true,"img":false}]}
{"op":"mcm","clk":"5306475545","pt":1646099112632,"mc":[{"id":"1.195395419","rc":[{"atl":[[8.2,13.83]],"id":43154447}],"con":true,"img":false}]}
{"op":"mcm","clk":"5306475548","pt":1646099112734,"mc":[{"id":"1.195395419","rc":[{"atl":[[3.75,6.49]],"id":43154449}],"con":true,"img":false}]}
{"op":"mcm","clk":"5306475564","pt":1646099113042,"mc":[{"id":"1.195395419","rc":[{"atl":[[3.8,0]],"id":43154449}],"con":true,"img":false}]}
{"op":"mcm","clk":"5306475571","pt":1646099113145,"mc":[{"id":"1.195395419","rc":[{"atl":[[3.7,1.22]],"id":43154449}],"con":true,"img":false}]}
{"op":"mcm","clk":"5306475593","pt":1646099113608,"mc":[{"id":"1.195395419","rc":[{"atb":[[2.72,0]],"id":42248828}],"con":true,"img":false}]}
{"op":"mcm","clk":"5306475608","pt":1646099113916,"mc":[{"id":"1.195395419","rc":[{"atb":[[7.4,8.09]],"id":42352031},{"atb":[[16.5,7.54]],"id":42413752},{"atb":[[16,2.24]],"id":43154446}],"con":true,"img":false}]}
{"op":"mcm","clk":"5306475619","pt":1646099114122,"mc":[{"id":"1.195395419","rc":[{"atl":[[38,8.05],[48,4.21],[19.5,0],[19,1.11]],"id":42352031},{"atb":[[2.44,69.44],[2.2,0]],"id":42248828},{"atl":[[75,2],[85,0]],"id":42413752},{"atb":[[7.6,4]],"id":43154448},{"atb":[[2.3,78]],"id":43154449},{"atb":[[2.58,0],[3.55,32.08]],"id":43154446},{"atb":[[2.5,0]],"id":43154447},{"atl":[[8,11.64],[5.5,3]],"id":43154447}],"con":true,"img":false}]}
{"op":"mcm","clk":"5306475624","pt":1646099114222,"mc":[{"id":"1.195395419","rc":[{"atl":[[8.4,0]],"id":43154447}],"con":true,"img":false}]}
{"op":"mcm","clk":"5306475629","pt":1646099114328,"mc":[{"id":"1.195395419","rc":[{"atl":[[8,2.78]],"id":43154447}],"con":true,"img":false}]}
{"op":"mcm","clk":"5306475634","pt":1646099114427,"mc":[{"id":"1.195395419","rc":[{"atl":[[10.5,8.86]],"id":43154447}],"con":true,"img":false}]}
{"op":"mcm","clk":"5306475639","pt":1646099114633,"mc":[{"id":"1.195395419","rc":[{"atb":[[7.8,4.23]],"id":42352031},{"atb":[[2.66,2.5]],"id":43154449},{"atb":[[4.5,1.92],[5,2.5]],"id":43154447}],"con":true,"img":false}]}
{"op":"mcm","clk":"5306475648","pt":1646099114734,"mc":[{"id":"1.195395419","rc":[{"atb":[[1.02,1.3]],"id":43154447}],"con":true,"img":false}]}
{"op":"mcm","clk":"5306475655","pt":1646099114837,"mc":[{"id":"1.195395419","rc":[{"atb":[[4.6,0.81]],"id":43154447}],"con":true,"img":false}]}
{"op":"mcm","clk":"5306475662","pt":1646099114938,"mc":[{"id":"1.195395419","rc":[{"atb":[[1.01,1.65]],"id":43154447}],"con":true,"img":false}]}
{"op":"mcm","clk":"5306475684","pt":1646099115451,"mc":[{"id":"1.195395419","rc":[{"atb":[[2.64,0]],"id":43154449}],"con":true,"img":false}]}
{"op":"mcm","clk":"5306475688","pt":1646099115555,"mc":[{"id":"1.195395419","rc":[{"atb":[[2.66,4.09]],"id":43154449}],"con":true,"img":false}]}
{"op":"mcm","clk":"5306475706","pt":1646099115917,"mc":[{"id":"1.195395419","rc":[{"atb":[[2.62,3.76]],"id":43154449}],"con":true,"img":false}]}
{"op":"mcm","clk":"5306475709","pt":1646099116019,"mc":[{"id":"1.195395419","rc":[{"atb":[[2.66,5.38]],"id":43154449}],"con":true,"img":false}]}
{"op":"mcm","clk":"5306475716","pt":1646099116225,"mc":[{"id":"1.195395419","rc":[{"atb":[[4.3,0]],"id":43154447}],"con":true,"img":false}]}
{"op":"mcm","clk":"5306475720","pt":1646099116331,"mc":[{"id":"1.195395419","rc":[{"atb":[[7.8,1.28]],"id":42352031}],"con":true,"img":false}]}
{"op":"mcm","clk":"5306475735","pt":1646099116738,"mc":[{"id":"1.195395419","rc":[{"atl":[[27,1.92]],"id":43154448},{"atb":[[2.38,36.23]],"id":43154447},{"atl":[[9,15.21]],"id":43154447}],"con":true,"img":false}]}
{"op":"mcm","clk":"5306475748","pt":1646099117047,"mc":[{"id":"1.195395419","rc":[{"atb":[[7.8,0]],"id":42352031}],"con":true,"img":false}]}
{"op":"mcm","clk":"5306475754","pt":1646099117149,"mc":[{"id":"1.195395419","rc":[{"atb":[[7.4,9.37]],"id":42352031},{"atb":[[5,0]],"id":43154447}],"con":true,"img":false}]}
{"op":"mcm","clk":"5306475794","pt":1646099118126,"mc":[{"id":"1.195395419","rc":[{"atl":[[3.85,0]],"id":43154449}],"con":true,"img":false}]}
{"op":"mcm","clk":"5306475805","pt":1646099118534,"mc":[{"id":"1.195395419","rc":[{"atb":[[4.9,0],[5.4,22.73]],"id":42352031},{"atb":[[4.9,0],[4.4,0]],"id":43154447}],"con":true,"img":false}]}
{"op":"mcm","clk":"5306475809","pt":1646099118636,"mc":[{"id":"1.195395419","rc":[{"atb":[[4.2,51.34]],"id":43154447}],"con":true,"img":false}]}
{"op":"mcm","clk":"5306475825","pt":1646099119047,"mc":[{"id":"1.195395419","rc":[{"atb":[[4.5,0]],"id":43154447}],"con":true,"img":false}]}
{"op":"mcm","clk":"5306475828","pt":1646099119150,"mc":[{"id":"1.195395419","rc":[{"atb":[[4.3,1.92]],"id":43154447}],"con":true,"img":false}]}
{"op":"mcm","clk":"5306475832","pt":1646099119253,"mc":[{"id":"1.195395419","rc":[{"atb":[[2.76,5.5]],"id":42248828},{"atb":[[2.62,0]],"id":43154449}],"con":true,"img":false}]}
{"op":"mcm","clk":"5306475837","pt":1646099119435,"mc":[{"id":"1.195395419","rc":[{"atb":[[2.74,2.89]],"id":42248828},{"atb":[[2.66,4.09]],"id":43154449},{"atb":[[4.4,2.53]],"id":43154447}],"con":true,"img":false}]}
{"op":"mcm","clk":"5306475845","pt":1646099119514,"mc":[{"id":"1.195395419","rc":[{"atb":[[2.76,6.85]],"id":42248828},{"atb":[[1.02,1.29]],"id":43154449}],"con":true,"img":false}]}
{"op":"mcm","clk":"5306475852","pt":1646099119618,"mc":[{"id":"1.195395419","rc":[{"atb":[[2.66,2.5]],"id":43154449}],"con":true,"img":false}]}
{"op":"mcm","clk":"5306475857","pt":1646099119720,"mc":[{"id":"1.195395419","rc":[{"atb":[[1.01,1.58]],"id":43154449}],"con":true,"img":false}]}
{"op":"mcm","clk":"5306475874","pt":1646099120029,"mc":[{"id":"1.195395419","rc":[{"atb":[[1.02,0]],"id":43154449}],"con":true,"img":false}]}
{"op":"mcm","clk":"5306475880","pt":1646099120132,"mc":[{"id":"1.195395419","rc":[{"atb":[[2.6,1.29]],"id":43154449}],"con":true,"img":false}]}
{"op":"mcm","clk":"5306475913","pt":1646099120847,"mc":[{"id":"1.195395419","rc":[{"atb":[[2.52,35.21]],"id":43154449}],"con":true,"img":false}]}
{"op":"mcm","clk":"5306475917","pt":1646099120950,"mc":[{"id":"1.195395419","rc":[{"atb":[[2.44,0]],"id":43154449}],"con":true,"img":false}]}
{"op":"mcm","clk":"5306475960","pt":1646099121720,"mc":[{"id":"1.195395419","rc":[{"atb":[[4.6,0]],"id":43154447}],"con":true,"img":false}]}
{"op":"mcm","clk":"5306475964","pt":1646099121823,"mc":[{"id":"1.195395419","rc":[{"atb":[[1.01,3.88]],"id":43154447}],"con":true,"img":false}]}
{"op":"mcm","clk":"5306475982","pt":1646099122234,"mc":[{"id":"1.195395419","rc":[{"atb":[[1.01,2.46]],"id":43154447}],"con":true,"img":false}]}
{"op":"mcm","clk":"5306475998","pt":1646099122538,"mc":[{"id":"1.195395419","rc":[{"atl":[[8.2,6.76]],"id":43154447}],"con":true,"img":false}]}
{"op":"mcm","clk":"5306476002","pt":1646099122641,"mc":[{"id":"1.195395419","rc":[{"atb":[[1.01,1.65]],"id":43154447},{"atl":[[8.4,7.07]],"id":43154447}],"con":true,"img":false}]}
{"op":"mcm","clk":"5306476007","pt":1646099122743,"mc":[{"id":"1.195395419","rc":[{"atb":[[4.5,0.81]],"id":43154447}],"con":true,"img":false}]}
{"op":"mcm","clk":"5306476030","pt":1646099123155,"mc":[{"id":"1.195395419","rc":[{"spl":[[1.01,37.86]],"id":43154448}],"con":true,"img":false}]}
{"op":"mcm","clk":"5306476077","pt":1646099124134,"mc":[{"id":"1.195395419","rc":[{"atb":[[7.8,2]],"id":43154448},{"atb":[[3.55,0],[4.1,32.26]],"id":43154446},{"atl":[[5.1,4],[5.5,0]],"id":43154447}],"con":true,"img":false}]}
{"op":"mcm","clk":"5306476106","pt":1646099124951,"mc":[{"id":"1.195395419","rc":[{"atl":[[3.75,0]],"id":43154449}],"con":true,"img":false}]}
{"op":"mcm","clk":"5306476114","pt":1646099125053,"mc":[{"id":"1.195395419","rc":[{"atb":[[2.74,0]],"id":42248828},{"atb":[[2.6,4.05]],"id":43154449},{"atl":[[3.65,5.78]],"id":43154449}],"con":true,"img":false}]}
{"op":"mcm","clk":"5306476120","pt":1646099125156,"mc":[{"id":"1.195395419","rc":[{"atl":[[3.65,12.27]],"id":43154449}],"con":true,"img":false}]}
{"op":"mcm","clk":"5306476133","pt":1646099125464,"mc":[{"id":"1.195395419","rc":[{"atl":[[3.6,3.38]],"id":43154449}],"con":true,"img":false}]}
{"op":"mcm","clk":"5306476148","pt":1646099125620,"mc":[{"id":"1.195395419","rc":[{"atb":[[1.01,0]],"id":43154449},{"atl":[[3.7,0]],"id":43154449}],"con":true,"img":false}]}
{"op":"mcm","clk":"5306476152","pt":1646099125723,"mc":[{"id":"1.195395419","rc":[{"atb":[[2.66,4.09]],"id":43154449},{"atl":[[3.6,4.6]],"id":43154449}],"con":true,"img":false}]}
{"op":"mcm","clk":"5306476178","pt":1646099126287,"mc":[{"id":"1.195395419","rc":[{"atb":[[2.66,2.5]],"id":43154449}],"con":true,"img":false}]}
{"op":"mcm","clk":"5306476184","pt":1646099126342,"mc":[{"id":"1.195395419","rc":[{"atb":[[1.01,1.58]],"id":43154449}],"con":true,"img":false}]}
{"op":"mcm","clk":"5306476203","pt":1646099126749,"mc":[{"id":"1.195395419","rc":[{"atl":[[29,8.08]],"id":43154448},{"atb":[[2.34,102.76]],"id":43154447},{"atl":[[8,0]],"id":43154447}],"con":true,"img":false}]}
{"op":"mcm","clk":"5306476236","pt":1646099127529,"mc":[{"id":"1.195395419","rc":[{"atb":[[2.76,1.35]],"id":42248828}],"con":true,"img":false}]}
{"op":"mcm","clk":"5306476272","pt":1646099128243,"mc":[{"id":"1.195395419","rc":[{"atb":[[2.76,0]],"id":42248828}],"con":true,"img":false}]}
{"op":"mcm","clk":"5306476277","pt":1646099128346,"mc":[{"id":"1.195395419","rc":[{"atb":[[2.72,1.35]],"id":42248828}],"con":true,"img":false}]}
{"op":"mcm","clk":"5306476291","pt":1646099128653,"mc":[{"id":"1.195395419","rc":[{"atl":[[50,2.07],[60,0]],"id":42413752},{"atl":[[23,2]],"id":43154448}],"con":true,"img":false}]}
{"op":"mcm","clk":"5306476294","pt":1646099128755,"mc":[{"id":"1.195395419","rc":[{"atl":[[70,2.7],[55,2.7]],"id":42413752},{"atl":[[25,3.7]],"id":43154448}],"con":true,"img":false}]}
{"op":"mcm","clk":"5306476372","pt":1646099130553,"mc":[{"id":"1.195395419","rc":[{"atb":[[2.32,2]],"id":43154449}],"con":true,"img":false}]}
{"op":"mcm","clk":"5306476377","pt":1646099130657,"mc":[{"id":"1.195395419","rc":[{"atb":[[2.36,43.94]],"id":43154449}],"con":true,"img":false}]}
{"op":"mcm","clk":"5306476408","pt":1646099131222,"mc":[{"id":"1.195395419","rc":[{"atl":[[3.9,0]],"id":43154449}],"con":true,"img":false}]}
{"op":"mcm","clk":"5306476414","pt":1646099131426,"mc":[{"id":"1.195395419","rc":[{"atl":[[3.55,4.32]],"id":43154449}],"con":true,"img":false}]}
{"op":"mcm","clk":"5306476430","pt":1646099131834,"mc":[{"id":"1.195395419","rc":[{"atb":[[2.72,7.14]],"id":42248828},{"atl":[[3.65,6.49]],"id":43154449}],"con":true,"img":false}]}
{"op":"mcm","clk":"5306476447","pt":1646099132246,"mc":[{"id":"1.195395419","rc":[{"atl":[[3.6,3.38]],"id":43154449}],"con":true,"img":false}]}
{"op":"mcm","clk":"5306476454","pt":1646099132348,"mc":[{"id":"1.195395419","rc":[{"atl":[[3.5,1.22]],"id":43154449}],"con":true,"img":false}]}
{"op":"mcm","clk":"5306476459","pt":1646099132453,"mc":[{"id":"1.195395419","rc":[{"atl":[[4.6,0]],"id":42248828}],"con":true,"img":false}]}
{"op":"mcm","clk":"5306476464","pt":1646099132551,"mc":[{"id":"1.195395419","rc":[{"atl":[[48,4.21]],"id":43154446}],"con":true,"img":false}]}
{"op":"mcm","clk":"5306476469","pt":1646099132657,"mc":[{"id":"1.195395419","rc":[{"atl":[[4.4,4.32]],"id":42248828},{"atl":[[46,4.08]],"id":43154446}],"con":true,"img":false}]}
{"op":"mcm","clk":"5306476472","pt":1646099132756,"mc":[{"id":"1.195395419","rc":[{"atl":[[4.5,0]],"id":42248828},{"atl":[[3.6,0]],"id":43154449},{"atl":[[44,4.33],[48,0.08]],"id":43154446}],"con":true,"img":false}]}
{"op":"mcm","clk":"5306476477","pt":1646099132859,"mc":[{"id":"1.195395419","rc":[{"atl":[[4.9,1.32]],"id":42248828}],"con":true,"img":false}]}
{"op":"mcm","clk":"5306476493","pt":1646099133166,"mc":[{"id":"1.195395419","rc":[{"atb":[[2.72,13.14]],"id":42248828}],"con":true,"img":false}]}
{"op":"mcm","clk":"5306476508","pt":1646099133526,"mc":[{"id":"1.195395419","rc":[{"atl":[[4.9,0]],"id":42248828},{"atl":[[46,2.7]],"id":43154446}],"con":true,"img":false}]}
{"op":"mcm","clk":"5306476511","pt":1646099133627,"mc":[{"id":"1.195395419","rc":[{"atl":[[4.3,1.32]],"id":42248828},{"atl":[[42,1.37]],"id":43154446}],"con":true,"img":false}]}
{"op":"mcm","clk":"5306476537","pt":1646099134145,"mc":[{"id":"1.195395419","rc":[{"atl":[[5,4]],"id":43154447}],"con":true,"img":false}]}
{"op":"mcm","clk":"5306476549","pt":1646099134552,"mc":[{"id":"1.195395419","rc":[{"atb":[[8.4,0]],"id":43154448}],"con":true,"img":false}]}
{"op":"mcm","clk":"5306476552","pt":1646099134657,"mc":[{"id":"1.195395419","rc":[{"atb":[[9.6,9.62]],"id":43154448}],"con":true,"img":false}]}
{"op":"mcm","clk":"5306476632","pt":1646099136757,"mc":[{"id":"1.195395419","rc":[{"atl":[[32,7.26]],"id":43154448},{"atb":[[2.3,96.15]],"id":43154447},{"atl":[[7.8,0],[7,3.24]],"id":43154447}],"con":true,"img":false}]}
{"op":"mcm","clk":"5306476660","pt":1646099137423,"mc":[{"id":"1.195395419","rc":[{"atl":[[3.65,0]],"id":43154449}],"con":true,"img":false}]}
{"op":"mcm","clk":"5306476669","pt":1646099137631,"mc":[{"id":"1.195395419","rc":[{"atl":[[3.45,6.49]],"id":43154449}],"con":true,"img":false}]}
{"op":"mcm","clk":"5306476691","pt":1646099138383,"mc":[{"id":"1.195395419","rc":[{"atl":[[3.5,0]],"id":43154449}],"con":true,"img":false}]}
{"op":"mcm","clk":"5306476699","pt":1646099138479,"mc":[{"id":"1.195395419","rc":[{"atl":[[3.4,1.22]],"id":43154449}],"con":true,"img":false}]}
{"op":"mcm","clk":"5306476702","pt":1646099138579,"mc":[{"id":"1.195395419","rc":[{"atb":[[7.2,1.62]],"id":42352031}],"con":true,"img":false}]}
{"op":"mcm","clk":"5306476704","pt":1646099138684,"mc":[{"id":"1.195395419","rc":[{"atb":[[7.6,9.35]],"id":42352031}],"con":true,"img":false}]}
{"op":"mcm","clk":"5306476708","pt":1646099138752,"mc":[{"id":"1.195395419","rc":[{"atl":[[3.5,4.16]],"id":43154449},{"atb":[[16,0]],"id":43154446}],"con":true,"img":false}]}
{"op":"mcm","clk":"5306476731","pt":1646099139366,"mc":[{"id":"1.195395419","rc":[{"atb":[[2.66,0]],"id":43154449}],"con":true,"img":false}]}
{"op":"mcm","clk":"5306476734","pt":1646099139467,"mc":[{"id":"1.195395419","rc":[{"atb":[[7.4,8.09]],"id":42352031}],"con":true,"img":false}]}
{"op":"mcm","clk":"5306476738","pt":1646099139569,"mc":[{"id":"1.195395419","rc":[{"atb":[[7.8,1.28]],"id":42352031}],"con":true,"img":false}]}
{"op":"mcm","clk":"5306476784","pt":1646099140546,"mc":[{"id":"1.195395419","rc":[{"atb":[[46,0]],"id":41642357}],"con":true,"img":false}]}
{"op":"mcm","clk":"5306476789","pt":1646099140650,"mc":[{"id":"1.195395419","rc":[{"atb":[[50,2.7]],"id":41642357}],"con":true,"img":false}]}
{"op":"mcm","clk":"5306476824","pt":1646099141470,"mc":[{"id":"1.195395419","rc":[{"atb":[[2.72,7.14]],"id":42248828}],"con":true,"img":false}]}
{"op":"mcm","clk":"5306476836","pt":1646099141776,"mc":[{"id":"1.195395419","rc":[{"atb":[[2.62,2.5]],"id":43154449}],"con":true,"img":false}]}
{"op":"mcm","clk":"5306476850","pt":1646099142031,"mc":[{"id":"1.195395419","rc":[{"atb":[[7.4,0]],"id":42352031},{"atb":[[2.72,1.35]],"id":42248828}],"con":true,"img":false}]}
{"op":"mcm","clk":"5306476927","pt":1646099144135,"mc":[{"id":"1.195395419","rc":[{"spn":12.7,"spf":1.0,"id":42352031},{"spn":3.7,"spf":1.0,"id":42248828},{"spn":33.5,"spf":1.0,"id":42413752},{"spn":9.28,"spf":1.0,"id":43154448},{"spn":2.61,"spf":1.0,"id":43154449},{"spn":29.5,"spf":1.0,"id":43154446},{"atl":[[4.9,4]],"id":43154447},{"spn":4.22,"spf":1.0,"id":43154447}],"con":true,"img":false}]}
{"op":"mcm","clk":"5306476973","pt":1646099145462,"mc":[{"id":"1.195395419","rc":[{"atl":[[3.5,0]],"id":43154449},{"atb":[[16,2.24]],"id":43154446}],"con":true,"img":false}]}
{"op":"mcm","clk":"5306477023","pt":1646099146646,"mc":[{"id":"1.195395419","rc":[{"atb":[[2.8,5]],"id":42248828}],"con":true,"img":false}]}
{"op":"mcm","clk":"5306477032","pt":1646099146750,"mc":[{"id":"1.195395419","rc":[{"atl":[[7.4,7.6]],"id":43154447}],"con":true,"img":false}]}
{"op":"mcm","clk":"5306477059","pt":1646099147260,"mc":[{"id":"1.195395419","rc":[{"atb":[[2.72,0]],"id":42248828}],"con":true,"img":false}]}
{"op":"mcm","clk":"5306477062","pt":1646099147362,"mc":[{"id":"1.195395419","rc":[{"atb":[[2.8,6.35]],"id":42248828}],"con":true,"img":false}]}
{"op":"mcm","clk":"5306477097","pt":1646099148644,"mc":[{"id":"1.195395419","rc":[{"atb":[[7.6,0]],"id":42352031},{"atl":[[17.5,0]],"id":42352031}],"con":true,"img":false}]}
{"op":"mcm","clk":"5306477102","pt":1646099148744,"mc":[{"id":"1.195395419","rc":[{"atb":[[7.2,10.97]],"id":42352031},{"atl":[[17,4.73]],"id":42352031}],"con":true,"img":false}]}
{"op":"mcm","clk":"5306477108","pt":1646099148948,"mc":[{"id":"1.195395419","rc":[{"atb":[[7.8,8.72]],"id":42352031},{"atb":[[2.76,7.95]],"id":42248828}],"con":true,"img":false}]}
{"op":"mcm","clk":"5306477110","pt":1646099149052,"mc":[{"id":"1.195395419","rc":[{"atb":[[7.8,7.43]],"id":42352031}],"con":true,"img":false}]}
{"op":"mcm","clk":"5306477117","pt":1646099149152,"mc":[{"id":"1.195395419","rc":[{"atb":[[7.4,1.28]],"id":42352031}],"con":true,"img":false}]}
{"op":"mcm","clk":"5306477136","pt":1646099149662,"mc":[{"id":"1.195395419","rc":[{"atb":[[7.4,0]],"id":42352031}],"con":true,"img":false}]}
{"op":"mcm","clk":"5306477141","pt":1646099149765,"mc":[{"id":"1.195395419","rc":[{"atb":[[7.8,8.72]],"id":42352031}],"con":true,"img":false}]}
{"op":"mcm","clk":"5306477144","pt":1646099149867,"mc":[{"id":"1.195395419","rc":[{"atl":[[3.45,0]],"id":43154449}],"con":true,"img":false}]}
{"op":"mcm","clk":"5306477149","pt":1646099150072,"mc":[{"id":"1.195395419","rc":[{"atl":[[3.35,6.49]],"id":43154449}],"con":true,"img":false}]}
{"op":"mcm","clk":"5306477158","pt":1646099150378,"mc":[{"id":"1.195395419","rc":[{"atl":[[3.4,0]],"id":43154449}],"con":true,"img":false}]}
{"op":"mcm","clk":"5306477159","pt":1646099150480,"mc":[{"id":"1.195395419","rc":[{"atl":[[3.3,1.22]],"id":43154449}],"con":true,"img":false}]}
{"op":"mcm","clk":"5306477163","pt":1646099150583,"mc":[{"id":"1.195395419","rc":[{"atb":[[16,0]],"id":42413752}],"con":true,"img":false}]}
{"op":"mcm","clk":"5306477168","pt":1646099150635,"mc":[{"id":"1.195395419","rc":[{"atb":[[17,3.86]],"id":42413752}],"con":true,"img":false}]}
{"op":"mcm","clk":"5306477176","pt":1646099150839,"mc":[{"id":"1.195395419","rc":[{"atb":[[2.6,2.75]],"id":43154449}],"con":true,"img":false}]}
{"op":"mcm","clk":"5306477179","pt":1646099150940,"mc":[{"id":"1.195395419","rc":[{"atb":[[1.02,1.29]],"id":43154449}],"con":true,"img":false}]}
{"op":"mcm","clk":"5306477198","pt":1646099151759,"mc":[{"id":"1.195395419","rc":[{"atb":[[2.62,0]],"id":43154449}],"con":true,"img":false}]}
{"op":"mcm","clk":"5306477204","pt":1646099151861,"mc":[{"id":"1.195395419","rc":[{"atb":[[2.8,1.35]],"id":42248828}],"con":true,"img":false}]}
{"op":"mcm","clk":"5306477218","pt":1646099152269,"mc":[{"id":"1.195395419","rc":[{"atl":[[3.4,5.78]],"id":43154449}],"con":true,"img":false}]}
{"op":"mcm","clk":"5306477228","pt":1646099152678,"mc":[{"id":"1.195395419","rc":[{"atb":[[2.8,0]],"id":42248828}],"con":true,"img":false}]}
{"op":"mcm","clk":"5306477234","pt":1646099152779,"mc":[{"id":"1.195395419","rc":[{"atb":[[2.76,9.3]],"id":42248828}],"con":true,"img":false}]}
{"op":"mcm","clk":"5306477278","pt":1646099154163,"mc":[{"id":"1.195395419","rc":[{"atl":[[4.8,3]],"id":43154447}],"con":true,"img":false}]}
{"op":"mcm","clk":"5306477336","pt":1646099155652,"mc":[{"id":"1.195395419","rc":[{"atb":[[2.76,1.35]],"id":42248828},{"atb":[[16.5,1.56]],"id":42413752}],"con":true,"img":false}]}
{"op":"mcm","clk":"5306477357","pt":1646099156265,"mc":[{"id":"1.195395419","rc":[{"atb":[[2.76,0]],"id":42248828}],"con":true,"img":false}]}
{"op":"mcm","clk":"5306477360","pt":1646099156368,"mc":[{"id":"1.195395419","rc":[{"atb":[[2.72,1.35]],"id":42248828}],"con":true,"img":false}]}
{"op":"mcm","clk":"5306477366","pt":1646099156573,"mc":[{"id":"1.195395419","rc":[{"atl":[[46,0]],"id":43154446}],"con":true,"img":false}]}
{"op":"mcm","clk":"5306477370","pt":1646099156675,"mc":[{"id":"1.195395419","rc":[{"atl":[[42,4.08]],"id":43154446}],"con":true,"img":false}]}
{"op":"mcm","clk":"5306477374","pt":1646099156777,"mc":[{"id":"1.195395419","rc":[{"atl":[[40,2],[44,2.33]],"id":43154446}],"con":true,"img":false}]}
{"op":"mcm","clk":"5306477378","pt":1646099156879,"mc":[{"id":"1.195395419","rc":[{"atl":[[9,0],[7.8,10.74]],"id":43154447}],"con":true,"img":false}]}
{"op":"mcm","clk":"5306477395","pt":1646099157546,"mc":[{"id":"1.195395419","rc":[{"atb":[[2.94,3.25]],"id":42248828},{"atb":[[2.6,0]],"id":43154449},{"atl":[[42,2.7]],"id":43154446}],"con":true,"img":false}]}
{"op":"mcm","clk":"5306477398","pt":1646099157649,"mc":[{"id":"1.195395419","rc":[{"atl":[[40,1.37],[42,4.7]],"id":43154446}],"con":true,"img":false}]}
{"op":"mcm","clk":"5306477413","pt":1646099158058,"mc":[{"id":"1.195395419","rc":[{"atb":[[2.58,13.93]],"id":43154449}],"con":true,"img":false}]}
{"op":"mcm","clk":"5306477445","pt":1646099158979,"mc":[{"id":"1.195395419","rc":[{"atl":[[3.4,0]],"id":43154449}],"con":true,"img":false}]}
{"op":"mcm","clk":"5306477492","pt":1646099160261,"mc":[{"id":"1.195395419","rc":[{"atb":[[1.01,3.65]],"id":43154447}],"con":true,"img":false}]}
{"op":"mcm","clk":"5306477497","pt":1646099160466,"mc":[{"id":"1.195395419","rc":[{"atb":[[1.01,5.64]],"id":43154447}],"con":true,"img":false}]}
{"op":"mcm","clk":"5306477503","pt":1646099160569,"mc":[{"id":"1.195395419","rc":[{"atl":[[42,2]],"id":43154446}],"con":true,"img":false}]}
{"op":"mcm","clk":"5306477505","pt":1646099160672,"mc":[{"id":"1.195395419","rc":[{"atl":[[48,2.78]],"id":43154446},{"atb":[[1.01,3.65]],"id":43154447}],"con":true,"img":false}]}
{"op":"mcm","clk":"5306477509","pt":1646099160773,"mc":[{"id":"1.195395419","rc":[{"atb":[[1.02,3.29]],"id":43154447}],"con":true,"img":false}]}
{"op":"mcm","clk":"5306477523","pt":1646099161388,"mc":[{"id":"1.195395419","rc":[{"atb":[[1.01,3.57]],"id":42352031}],"con":true,"img":false}]}
{"op":"mcm","clk":"5306477531","pt":1646099161593,"mc":[{"id":"1.195395419","rc":[{"atb":[[1.01,5.56]],"id":42352031}],"con":true,"img":false}]}
{"op":"mcm","clk":"5306477537","pt":1646099161696,"mc":[{"id":"1.195395419","rc":[{"atl":[[3.55,0]],"id":43154449}],"con":true,"img":false}]}
{"op":"mcm","clk":"5306477549","pt":1646099161852,"mc":[{"id":"1.195395419","rc":[{"atl":[[3.25,4.32]],"id":43154449}],"con":true,"img":false}]}
{"op":"mcm","clk":"5306477558","pt":1646099162056,"mc":[{"id":"1.195395419","rc":[{"atb":[[1.01,3.57]],"id":42352031}],"con":true,"img":false}]}
{"op":"mcm","clk":"5306477560","pt":1646099162157,"mc":[{"id":"1.195395419","rc":[{"atb":[[8.6,1.99]],"id":42352031}],"con":true,"img":false}]}
{"op":"mcm","clk":"5306477566","pt":1646099162259,"mc":[{"id":"1.195395419","rc":[{"atb":[[8.2,0.44],[8.6,3.99]],"id":42352031},{"atl":[[48,0]],"id":42413752},{"atl":[[3.35,0],[3.3,0]],"id":43154449},{"atb":[[16,0]],"id":43154446}],"con":true,"img":false}]}
{"op":"mcm","clk":"5306477569","pt":1646099162367,"mc":[{"id":"1.195395419","rc":[{"atb":[[2.98,2.9]],"id":42248828},{"atl":[[50,0.07],[55,4.7],[1000,1.35],[75,0],[80,2]],"id":42413752},{"atl":[[3.2,1.22]],"id":43154449}],"con":true,"img":false}]}
{"op":"mcm","clk":"5306477572","pt":1646099162464,"mc":[{"id":"1.195395419","rc":[{"atl":[[3.25,10.81]],"id":43154449}],"con":true,"img":false}]}
{"op":"mcm","clk":"5306477588","pt":1646099162874,"mc":[{"id":"1.195395419","rc":[{"atb":[[1.01,2]],"id":42352031},{"atb":[[2.72,0]],"id":42248828},{"atl":[[4.4,0]],"id":42248828},{"atl":[[1000,0]],"id":42413752}],"con":true,"img":false}]}
{"op":"mcm","clk":"5306477595","pt":1646099162976,"mc":[{"id":"1.195395419","rc":[{"atb":[[8.8,1.57]],"id":42352031},{"atb":[[2.98,4.25]],"id":42248828},{"atl":[[50,1.42]],"id":42413752}],"con":true,"img":false}]}
{"op":"mcm","clk":"5306477603","pt":1646099163183,"mc":[{"id":"1.195395419","rc":[{"atb":[[8.4,0]],"id":42352031},{"atb":[[2.6,9.75]],"id":43154449}],"con":true,"img":false}]}
{"op":"mcm","clk":"5306477620","pt":1646099163490,"mc":[{"id":"1.195395419","rc":[{"atb":[[8.8,0]],"id":42352031},{"atl":[[4.3,0],[4.2,2.53]],"id":42248828}],"con":true,"img":false}]}
{"op":"mcm","clk":"5306477625","pt":1646099163593,"mc":[{"id":"1.195395419","rc":[{"atb":[[1.01,3.57]],"id":42352031},{"atl":[[4.9,1.32]],"id":42248828}],"con":true,"img":false}]}
{"op":"mcm","clk":"5306477644","pt":1646099164157,"mc":[{"id":"1.195395419","rc":[{"atl":[[4.9,0]],"id":42248828}],"con":true,"img":false}]}
{"op":"mcm","clk":"5306477647","pt":1646099164259,"mc":[{"id":"1.195395419","rc":[{"atl":[[4.1,1.32]],"id":42248828}],"con":true,"img":false}]}
{"op":"mcm","clk":"5306477657","pt":1646099164673,"mc":[{"id":"1.195395419","rc":[{"atb":[[1.01,2]],"id":42248828}],"con":true,"img":false}]}
{"op":"mcm","clk":"5306477664","pt":1646099164876,"mc":[{"id":"1.195395419","rc":[{"atb":[[1.01,3.99]],"id":42248828}],"con":true,"img":false}]}
{"op":"mcm","clk":"5306477675","pt":1646099165184,"mc":[{"id":"1.195395419","rc":[{"atb":[[1.01,2]],"id":42248828}],"con":true,"img":false}]}
{"op":"mcm","clk":"5306477678","pt":1646099165286,"mc":[{"id":"1.195395419","rc":[{"atb":[[1.02,1.99]],"id":42248828}],"con":true,"img":false}]}
{"op":"mcm","clk":"5306477687","pt":1646099165594,"mc":[{"id":"1.195395419","rc":[{"atb":[[7.8,1.28]],"id":42352031},{"atl":[[3.2,4.47]],"id":43154449}],"con":true,"img":false}]}
{"op":"mcm","clk":"5306477699","pt":1646099165851,"mc":[{"id":"1.195395419","rc":[{"atb":[[2.94,0]],"id":42248828}],"con":true,"img":false}]}
{"op":"mcm","clk":"5306477712","pt":1646099166158,"mc":[{"id":"1.195395419","rc":[{"atb":[[1.01,3.58]],"id":43154449}],"con":true,"img":false}]}
{"op":"mcm","clk":"5306477719","pt":1646099166362,"mc":[{"id":"1.195395419","rc":[{"atb":[[2.98,2.9]],"id":42248828},{"atb":[[1.01,5.57]],"id":43154449}],"con":true,"img":false}]}
{"op":"mcm","clk":"5306477723","pt":1646099166464,"mc":[{"id":"1.195395419","rc":[{"atb":[[1.01,3.35]],"id":42248828}],"con":true,"img":false}]}
{"op":"mcm","clk":"5306477731","pt":1646099166668,"mc":[{"id":"1.195395419","rc":[{"atb":[[1.01,3.58]],"id":43154449}],"con":true,"img":false}]}
{"op":"mcm","clk":"5306477734","pt":1646099166773,"mc":[{"id":"1.195395419","rc":[{"atb":[[2.6,11.74]],"id":43154449}],"con":true,"img":false}]}
{"op":"mcm","clk":"5306477740","pt":1646099166875,"mc":[{"id":"1.195395419","rc":[{"atl":[[8.2,16.9],[8.6,0]],"id":43154447}],"con":true,"img":false}]}
{"op":"mcm","clk":"5306477787","pt":1646099168665,"mc":[{"id":"1.195395419","rc":[{"atb":[[7.4,3.53]],"id":42352031},{"atb":[[2.6,1.99]],"id":43154449}],"con":true,"img":false}]}
{"op":"mcm","clk":"5306477804","pt":1646099169179,"mc":[{"id":"1.195395419","rc":[{"atb":[[7.4,13.52]],"id":42352031},{"atb":[[2.98,0]],"id":42248828}],"con":true,"img":false}]}
{"op":"mcm","clk":"5306477813","pt":1646099169485,"mc":[{"id":"1.195395419","rc":[{"atb":[[1.01,2]],"id":42248828}],"con":true,"img":false}]}
{"op":"mcm","clk":"5306477818","pt":1646099169589,"mc":[{"id":"1.195395419","rc":[{"atb":[[2.72,1.35]],"id":42248828}],"con":true,"img":false}]}
{"op":"mcm","clk":"5306477821","pt":1646099169693,"mc":[{"id":"1.195395419","rc":[{"atb":[[1.04,2.83]],"id":42352031},{"atb":[[1.02,5.02]],"id":42248828},{"atb":[[1.02,6.23]],"id":43154447}],"con":true,"img":false}]}
{"op":"mcm","clk":"5306477826","pt":1646099169795,"mc":[{"id":"1.195395419","rc":[{"atb":[[1.03,3.08]],"id":43154449}],"con":true,"img":false}]}
{"op":"mcm","clk":"5306477838","pt":1646099170204,"mc":[{"id":"1.195395419","rc":[{"atb":[[1.04,0.13]],"id":42352031},{"atb":[[1.02,2.31]],"id":42248828},{"atb":[[2.58,11]],"id":43154449},{"atb":[[1.02,3.52]],"id":43154447}],"con":true,"img":false}]}
{"op":"mcm","clk":"5306477842","pt":1646099170260,"mc":[{"id":"1.195395419","rc":[{"atb":[[1.03,0.38]],"id":43154449}],"con":true,"img":false}]}
{"op":"mcm","clk":"5306477860","pt":1646099170566,"mc":[{"id":"1.195395419","rc":[{"atl":[[3.2,3.24]],"id":43154449}],"con":true,"img":false}]}
{"op":"mcm","clk":"5306477863","pt":1646099170670,"mc":[{"id":"1.195395419","rc":[{"atb":[[1.04,0]],"id":42352031},{"atb":[[1.02,1.99]],"id":42248828},{"atl":[[1000,1.22]],"id":43154449},{"atb":[[1.02,3.29]],"id":43154447}],"con":true,"img":false}]}
{"op":"mcm","clk":"5306477868","pt":1646099170769,"mc":[{"id":"1.195395419","rc":[{"atb":[[8,0.13]],"id":42352031},{"atb":[[3.2,0.32]],"id":42248828},{"atb":[[1.03,0]],"id":43154449},{"atb":[[4.6,0.23]],"id":43154447}],"con":true,"img":false}]}
{"op":"mcm","clk":"5306477873","pt":1646099170873,"mc":[{"id":"1.195395419","rc":[{"atb":[[2.76,0.38]],"id":43154449}],"con":true,"img":false}]}
{"op":"mcm","clk":"5306477891","pt":1646099171180,"mc":[{"id":"1.195395419","rc":[{"atl":[[4.2,0]],"id":42248828},{"atb":[[4.4,0]],"id":43154447}],"con":true,"img":false}]}
{"op":"mcm","clk":"5306477894","pt":1646099171283,"mc":[{"id":"1.195395419","rc":[{"atb":[[1.01,5.88],[4.5,0]],"id":43154447},{"atl":[[4.8,0],[5.2,3]],"id":43154447}],"con":true,"img":false}]}
{"op":"mcm","clk":"5306477900","pt":1646099171487,"mc":[{"id":"1.195395419","rc":[{"atb":[[1.01,4.46]],"id":43154447}],"con":true,"img":false}]}
{"op":"mcm","clk":"5306477907","pt":1646099171693,"mc":[{"id":"1.195395419","rc":[{"atb":[[1.01,3.65]],"id":43154447}],"con":true,"img":false}]}
{"op":"mcm","clk":"5306477911","pt":1646099171793,"mc":[{"id":"1.195395419","rc":[{"atl":[[4.1,0]],"id":42248828},{"atb":[[4.4,0.81]],"id":43154447}],"con":true,"img":false}]}
{"op":"mcm","clk":"5306477913","pt":1646099171896,"mc":[{"id":"1.195395419","rc":[{"atl":[[4.9,1.32],[4,2.53]],"id":42248828},{"atb":[[4.4,3.34]],"id":43154447}],"con":true,"img":false}]}
{"op":"mcm","clk":"5306477922","pt":1646099172305,"mc":[{"id":"1.195395419","rc":[{"atl":[[4.9,0]],"id":42248828}],"con":true,"img":false}]}
{"op":"mcm","clk":"5306477927","pt":1646099172358,"mc":[{"id":"1.195395419","rc":[{"atl":[[3.95,1.32]],"id":42248828}],"con":true,"img":false}]}
{"op":"mcm","clk":"5306477932","pt":1646099172461,"mc":[{"id":"1.195395419","rc":[{"atb":[[13.5,0],[16,8.02]],"id":42413752}],"con":true,"img":false}]}
{"op":"mcm","clk":"5306477963","pt":1646099173284,"mc":[{"id":"1.195395419","rc":[{"atb":[[3.1,0]],"id":42248828}],"con":true,"img":false}]}
{"op":"mcm","clk":"5306477975","pt":1646099173693,"mc":[{"id":"1.195395419","rc":[{"atb":[[2.72,2.89]],"id":42248828}],"con":true,"img":false}]}
{"op":"mcm","clk":"5306477982","pt":1646099173896,"mc":[{"id":"1.195395419","rc":[{"atl":[[19,0],[19.5,1.08]],"id":42352031},{"atl":[[75,2],[80,0]],"id":42413752},{"atl":[[42,4.44],[44,0]],"id":43154446}],"con":true,"img":false}]}
{"op":"mcm","clk":"5306477988","pt":1646099173998,"mc":[{"id":"1.195395419","rc":[{"atb":[[1.2,2.23]],"id":42248828}],"con":true,"img":false}]}
{"op":"mcm","clk":"5306477995","pt":1646099174203,"mc":[{"id":"1.195395419","rc":[{"atb":[[1.02,0]],"id":42248828}],"con":true,"img":false}]}
{"op":"mcm","clk":"5306478002","pt":1646099174305,"mc":[{"id":"1.195395419","rc":[{"atb":[[1.2,1.98],[2.74,1.99]],"id":42248828}],"con":true,"img":false}]}
{"op":"mcm","clk":"5306478018","pt":1646099174562,"mc":[{"id":"1.195395419","rc":[{"atb":[[1.2,0]],"id":42248828},{"atb":[[17,0]],"id":42413752}],"con":true,"img":false}]}
{"op":"mcm","clk":"5306478021","pt":1646099174664,"mc":[{"id":"1.195395419","rc":[{"atb":[[3.15,1.98]],"id":42248828},{"atb":[[16,11.88]],"id":42413752},{"atl":[[3.25,4.32]],"id":43154449}],"con":true,"img":false}]}
{"op":"mcm","clk":"5306478029","pt":1646099174871,"mc":[{"id":"1.195395419","rc":[{"atl":[[3.15,6.49]],"id":43154449}],"con":true,"img":false}]}
{"op":"mcm","clk":"5306478039","pt":1646099175076,"mc":[{"id":"1.195395419","rc":[{"atb":[[2.74,0]],"id":42248828}],"con":true,"img":false}]}
{"op":"mcm","clk":"5306478042","pt":1646099175177,"mc":[{"id":"1.195395419","rc":[{"atb":[[1.02,1.99]],"id":42248828}],"con":true,"img":false}]}
{"op":"mcm","clk":"5306478090","pt":1646099176609,"mc":[{"id":"1.195395419","rc":[{"atl":[[8.4,0]],"id":43154447}],"con":true,"img":false}]}
{"op":"mcm","clk":"5306478093","pt":1646099176662,"mc":[{"id":"1.195395419","rc":[{"atl":[[8.8,7.07]],"id":43154447}],"con":true,"img":false}]}
{"op":"mcm","clk":"5306478176","pt":1646099178764,"mc":[{"id":"1.195395419","rc":[{"atb":[[16.5,7.54]],"id":42413752},{"atl":[[3.2,0]],"id":43154449},{"atb":[[16,2.24]],"id":43154446}],"con":true,"img":false}]}
{"op":"mcm","clk":"5306478192","pt":1646099179174,"mc":[{"id":"1.195395419","rc":[{"atb":[[3.15,0]],"id":42248828}],"con":true,"img":false}]}
{"op":"mcm","clk":"5306478207","pt":1646099179583,"mc":[{"id":"1.195395419","rc":[{"atl":[[4,0]],"id":42248828}],"con":true,"img":false}]}
{"op":"mcm","clk":"5306478228","pt":1646099180197,"mc":[{"id":"1.195395419","rc":[{"atb":[[1.02,0]],"id":42248828},{"atl":[[3.95,0]],"id":42248828}],"con":true,"img":false}]}
{"op":"mcm","clk":"5306478231","pt":1646099180299,"mc":[{"id":"1.195395419","rc":[{"atb":[[2.74,1.99]],"id":42248828},{"atl":[[4.9,1.32]],"id":42248828}],"con":true,"img":false}]}
{"op":"mcm","clk":"5306478274","pt":1646099181578,"mc":[{"id":"1.195395419","rc":[{"atl":[[4.8,4.32]],"id":42248828}],"con":true,"img":false}]}
{"op":"mcm","clk":"5306478277","pt":1646099181681,"mc":[{"id":"1.195395419","rc":[{"atb":[[1.03,2.23],[16.5,0]],"id":43154446}],"con":true,"img":false}]}
{"op":"mcm","clk":"5306478282","pt":1646099181783,"mc":[{"id":"1.195395419","rc":[{"atb":[[1.02,2.23]],"id":43154448}],"con":true,"img":false}]}
{"op":"mcm","clk":"5306478285","pt":1646099181882,"mc":[{"id":"1.195395419","rc":[{"atb":[[17.5,0]],"id":42413752}],"con":true,"img":false}]}
{"op":"mcm","clk":"5306478288","pt":1646099181986,"mc":[{"id":"1.195395419","rc":[{"atb":[[1.03,0.21]],"id":43154446}],"con":true,"img":false}]}
{"op":"mcm","clk":"5306478292","pt":1646099182088,"mc":[{"id":"1.195395419","rc":[{"atb":[[1.04,2.23]],"id":42413752},{"atb":[[10,1.12]],"id":43154448}],"con":true,"img":false}]}
{"op":"mcm","clk":"5306478299","pt":1646099182291,"mc":[{"id":"1.195395419","rc":[{"atb":[[1.02,0.32]],"id":43154448},{"atb":[[1.03,0]],"id":43154446}],"con":true,"img":false}]}
{"op":"mcm","clk":"5306478301","pt":1646099182395,"mc":[{"id":"1.195395419","rc":[{"atb":[[17.5,0.21]],"id":43154446}],"con":true,"img":false}]}
{"op":"mcm","clk":"5306478309","pt":1646099182600,"mc":[{"id":"1.195395419","rc":[{"atb":[[1.04,0.19]],"id":42413752},{"atb":[[1.02,0]],"id":43154448}],"con":true,"img":false}]}
{"op":"mcm","clk":"5306478312","pt":1646099182701,"mc":[{"id":"1.195395419","rc":[{"atb":[[11.5,0.32]],"id":43154448}],"con":true,"img":false}]}
{"op":"mcm","clk":"5306478323","pt":1646099182905,"mc":[{"id":"1.195395419","rc":[{"atb":[[1.04,0]],"id":42413752}],"con":true,"img":false}]}
{"op":"mcm","clk":"5306478326","pt":1646099183007,"mc":[{"id":"1.195395419","rc":[{"atb":[[19.5,0.19]],"id":42413752}],"con":true,"img":false}]}
{"op":"mcm","clk":"5306478356","pt":1646099183775,"mc":[{"id":"1.195395419","rc":[{"atl":[[4.9,0]],"id":42248828}],"con":true,"img":false}]}
{"op":"mcm","clk":"5306478359","pt":1646099183878,"mc":[{"id":"1.195395419","rc":[{"atl":[[4.7,1.32]],"id":42248828}],"con":true,"img":false}]}
{"op":"mcm","clk":"5306478385","pt":1646099184695,"mc":[{"id":"1.195395419","rc":[{"atb":[[2.94,8.1]],"id":42248828}],"con":true,"img":false}]}
{"op":"mcm","clk":"5306478397","pt":1646099185001,"mc":[{"id":"1.195395419","rc":[{"atb":[[2.74,0]],"id":42248828}],"con":true,"img":false}]}
{"op":"mcm","clk":"5306478401","pt":1646099185103,"mc":[{"id":"1.195395419","rc":[{"atb":[[2.72,0],[2.96,1.99]],"id":42248828}],"con":true,"img":false}]}
{"op":"mcm","clk":"5306478404","pt":1646099185207,"mc":[{"id":"1.195395419","rc":[{"atb":[[2.96,4.88]],"id":42248828}],"con":true,"img":false}]}
{"op":"mcm","clk":"5306478411","pt":1646099185410,"mc":[{"id":"1.195395419","rc":[{"atb":[[2.74,30.4]],"id":42248828}],"con":true,"img":false}]}
{"op":"mcm","clk":"5306478415","pt":1646099185513,"mc":[{"id":"1.195395419","rc":[{"atl":[[3.1,4.86]],"id":43154449}],"con":true,"img":false}]}
{"op":"mcm","clk":"5306478424","pt":1646099185819,"mc":[{"id":"1.195395419","rc":[{"atb":[[3.1,2.5]],"id":42248828}],"con":true,"img":false}]}
{"op":"mcm","clk":"5306478433","pt":1646099186079,"mc":[{"id":"1.195395419","rc":[{"atb":[[2.96,2.89]],"id":42248828}],"con":true,"img":false}]}
{"op":"mcm","clk":"5306478435","pt":1646099186184,"mc":[{"id":"1.195395419","rc":[{"atb":[[1.02,1.99]],"id":42248828}],"con":true,"img":false}]}
{"op":"mcm","clk":"5306478446","pt":1646099186588,"mc":[{"id":"1.195395419","rc":[{"atl":[[25,1]],"id":43154448}],"con":true,"img":false}]}
{"op":"mcm","clk":"5306478450","pt":1646099186691,"mc":[{"id":"1.195395419","rc":[{"atl":[[24,2.7]],"id":43154448}],"con":true,"img":false}]}
{"op":"mcm","clk":"5306478467","pt":1646099187101,"mc":[{"id":"1.195395419","rc":[{"atl":[[3.15,0]],"id":43154449}],"con":true,"img":false}]}
{"op":"mcm","clk":"5306478474","pt":1646099187306,"mc":[{"id":"1.195395419","rc":[{"atb":[[3.15,2.53]],"id":42248828},{"atl":[[3.05,6.49]],"id":43154449}],"con":true,"img":false}]}
{"op":"mcm","clk":"5306478481","pt":1646099187613,"mc":[{"id":"1.195395419","rc":[{"atb":[[2.96,1.35]],"id":42248828}],"con":true,"img":false}]}
{"op":"mcm","clk":"5306478484","pt":1646099187715,"mc":[{"id":"1.195395419","rc":[{"atb":[[3.2,1.87]],"id":42248828}],"con":true,"img":false}]}
{"op":"mcm","clk":"5306478492","pt":1646099188024,"mc":[{"id":"1.195395419","rc":[{"atb":[[4.2,18.12]],"id":43154447}],"con":true,"img":false}]}
{"op":"mcm","clk":"5306478497","pt":1646099188124,"mc":[{"id":"1.195395419","rc":[{"atb":[[2.58,5.18]],"id":43154449},{"atb":[[3.75,33.21]],"id":43154447}],"con":true,"img":false}]}
{"op":"mcm","clk":"5306478509","pt":1646099188382,"mc":[{"id":"1.195395419","rc":[{"atb":[[3.1,0]],"id":42248828}],"con":true,"img":false}]}
{"op":"mcm","clk":"5306478523","pt":1646099188791,"mc":[{"id":"1.195395419","rc":[{"atb":[[3.2,0.32]],"id":42248828}],"con":true,"img":false}]}
{"op":"mcm","clk":"5306478529","pt":1646099188893,"mc":[{"id":"1.195395419","rc":[{"atb":[[1.01,3.54]],"id":42248828}],"con":true,"img":false}]}
{"op":"mcm","clk":"5306478555","pt":1646099189609,"mc":[{"id":"1.195395419","rc":[{"atb":[[2.94,0]],"id":42248828}],"con":true,"img":false}]}
{"op":"mcm","clk":"5306478584","pt":1646099190530,"mc":[{"id":"1.195395419","rc":[{"atb":[[2.58,0]],"id":43154449}],"con":true,"img":false}]}
{"op":"mcm","clk":"5306478596","pt":1646099190889,"mc":[{"id":"1.195395419","rc":[{"atb":[[3.2,2.83]],"id":42248828}],"con":true,"img":false}]}
{"op":"mcm","clk":"5306478603","pt":1646099191095,"mc":[{"id":"1.195395419","rc":[{"atb":[[1.01,2]],"id":42248828},{"atb":[[2.6,4.87]],"id":43154449}],"con":true,"img":false}]}
{"op":"mcm","clk":"5306478609","pt":1646099191198,"mc":[{"id":"1.195395419","rc":[{"atb":[[3.25,1.54]],"id":42248828}],"con":true,"img":false}]}
{"op":"mcm","clk":"5306478624","pt":1646099191729,"mc":[{"id":"1.195395419","rc":[{"atb":[[2.96,0]],"id":42248828}],"con":true,"img":false}]}
{"op":"mcm","clk":"5306478630","pt":1646099191831,"mc":[{"id":"1.195395419","rc":[{"atb":[[2.76,1.35]],"id":42248828}],"con":true,"img":false}]}
{"op":"mcm","clk":"5306478645","pt":1646099192092,"mc":[{"id":"1.195395419","rc":[{"atl":[[3.25,0]],"id":43154449}],"con":true,"img":false}]}
{"op":"mcm","clk":"5306478652","pt":1646099192300,"mc":[{"id":"1.195395419","rc":[{"atb":[[2.74,0]],"id":42248828}],"con":true,"img":false}]}
{"op":"mcm","clk":"5306478656","pt":1646099192400,"mc":[{"id":"1.195395419","rc":[{"atl":[[3.1,0]],"id":43154449}],"con":true,"img":false}]}
{"op":"mcm","clk":"5306478672","pt":1646099192808,"mc":[{"id":"1.195395419","rc":[{"atb":[[2.76,0]],"id":42248828}],"con":true,"img":false}]}
{"op":"mcm","clk":"5306478678","pt":1646099192910,"mc":[{"id":"1.195395419","rc":[{"atb":[[2.72,1.35]],"id":42248828}],"con":true,"img":false}]}
{"op":"mcm","clk":"5306478699","pt":1646099193525,"mc":[{"id":"1.195395419","rc":[{"atb":[[3.2,0.32]],"id":42248828}],"con":true,"img":false}]}
{"op":"mcm","clk":"5306478727","pt":1646099194141,"mc":[{"id":"1.195395419","rc":[{"atb":[[3.25,0]],"id":42248828}],"con":true,"img":false}]}
{"op":"mcm","clk":"5306478733","pt":1646099194194,"mc":[{"id":"1.195395419","rc":[{"atb":[[1.01,3.54]],"id":42248828}],"con":true,"img":false}]}
{"op":"mcm","clk":"5306478746","pt":1646099194602,"mc":[{"id":"1.195395419","rc":[{"atb":[[7.2,1.62]],"id":42352031}],"con":true,"img":false}]}
{"op":"mcm","clk":"5306478751","pt":1646099194706,"mc":[{"id":"1.195395419","rc":[{"atb":[[7.6,9.35]],"id":42352031}],"con":true,"img":false}]}
{"op":"mcm","clk":"5306478755","pt":1646099194809,"mc":[{"id":"1.195395419","rc":[{"atb":[[3.15,0]],"id":42248828}],"con":true,"img":false}]}
{"op":"mcm","clk":"5306478764","pt":1646099195011,"mc":[{"id":"1.195395419","rc":[{"atb":[[3.2,2.86],[1.02,0]],"id":42248828}],"con":true,"img":false}]}
{"op":"mcm","clk":"5306478767","pt":1646099195114,"mc":[{"id":"1.195395419","rc":[{"atb":[[2.72,3.34]],"id":42248828}],"con":true,"img":false}]}
{"op":"mcm","clk":"5306478776","pt":1646099195422,"mc":[{"id":"1.195395419","rc":[{"atb":[[2.72,1.35]],"id":42248828},{"atl":[[17.5,5.4]],"id":43154448}],"con":true,"img":false}]}
{"op":"mcm","clk":"5306478780","pt":1646099195526,"mc":[{"id":"1.195395419","rc":[{"atb":[[1.02,1.99]],"id":42248828}],"con":true,"img":false}]}
{"op":"mcm","clk":"5306478794","pt":1646099195936,"mc":[{"id":"1.195395419","rc":[{"atb":[[3.25,2.5]],"id":42248828}],"con":true,"img":false}]}
{"op":"mcm","clk":"5306478837","pt":1646099197015,"mc":[{"id":"1.195395419","rc":[{"atb":[[1.01,5.24]],"id":42352031},{"atb":[[1.02,1.67]],"id":42413752},{"atl":[[1000,1.67]],"id":42413752},{"atb":[[1.02,1.67]],"id":43154446}],"con":true,"img":false}]}
{"op":"mcm","clk":"5306478852","pt":1646099197426,"mc":[{"id":"1.195395419","rc":[{"atb":[[2.72,14.51]],"id":42248828},{"atb":[[2.56,5.25]],"id":43154449}],"con":true,"img":false}]}
{"op":"mcm","clk":"5306478882","pt":1646099198142,"mc":[{"id":"1.195395419","rc":[{"atb":[[1.01,4.52]],"id":42352031},{"atb":[[1.02,0.41]],"id":42413752},{"atl":[[1000,0.17]],"id":42413752},{"atb":[[1.02,0.46]],"id":43154446}],"con":true,"img":false}]}
{"op":"mcm","clk":"5306478895","pt":1646099198400,"mc":[{"id":"1.195395419","rc":[{"atl":[[1000,0]],"id":42413752}],"con":true,"img":false}]}
{"op":"mcm","clk":"5306478898","pt":1646099198554,"mc":[{"id":"1.195395419","rc":[{"atl":[[48,0.17]],"id":42413752},{"atl":[[48,0.08]],"id":43154446}],"con":true,"img":false}]}
{"op":"mcm","clk":"5306478905","pt":1646099198605,"mc":[{"id":"1.195395419","rc":[{"atl":[[46,2.7]],"id":43154446}],"con":true,"img":false}]}
{"op":"mcm","clk":"5306478912","pt":1646099198810,"mc":[{"id":"1.195395419","rc":[{"atb":[[1.01,3.57]],"id":42352031}],"con":true,"img":false}]}
{"op":"mcm","clk":"5306478918","pt":1646099198913,"mc":[{"id":"1.195395419","rc":[{"atb":[[8.8,0.95]],"id":42352031}],"con":true,"img":false}]}
{"op":"mcm","clk":"5306478924","pt":1646099199014,"mc":[{"id":"1.195395419","rc":[{"atb":[[7.4,3.53]],"id":42352031},{"atb":[[2.74,45.44]],"id":42248828},{"atl":[[3,4.86]],"id":43154449},{"atb":[[1.02,0]],"id":43154446}],"con":true,"img":false}]}
{"op":"mcm","clk":"5306478929","pt":1646099199119,"mc":[{"id":"1.195395419","rc":[{"atb":[[18,0.46]],"id":43154446}],"con":true,"img":false}]}
{"op":"mcm","clk":"5306478939","pt":1646099199323,"mc":[{"id":"1.195395419","rc":[{"atb":[[2.7,5.4]],"id":42248828},{"atb":[[1.02,0]],"id":42413752}],"con":true,"img":false}]}
{"op":"mcm","clk":"5306478944","pt":1646099199424,"mc":[{"id":"1.195395419","rc":[{"atb":[[20,0.41]],"id":42413752}],"con":true,"img":false}]}
{"op":"mcm","clk":"5306478948","pt":1646099199527,"mc":[{"id":"1.195395419","rc":[{"atb":[[18.5,0.58],[19.5,2.19]],"id":42413752},{"atl":[[3.05,0]],"id":43154449}],"con":true,"img":false}]}
{"op":"mcm","clk":"5306478954","pt":1646099199629,"mc":[{"id":"1.195395419","rc":[{"atb":[[19.5,0.19],[19,4.08]],"id":42413752}],"con":true,"img":false}]}
{"op":"mcm","clk":"5306478958","pt":1646099199731,"mc":[{"id":"1.195395419","rc":[{"atb":[[7.4,0]],"id":42352031},{"atl":[[3,11.35]],"id":43154449}],"con":true,"img":false}]}
{"op":"mcm","clk":"5306478980","pt":1646099200244,"mc":[{"id":"1.195395419","rc":[{"atb":[[2.7,0]],"id":42248828}],"con":true,"img":false}]}
{"op":"mcm","clk":"5306478996","pt":1646099200604,"mc":[{"id":"1.195395419","rc":[{"atb":[[16,8.02]],"id":42413752}],"con":true,"img":false}]}
{"op":"mcm","clk":"5306479000","pt":1646099200708,"mc":[{"id":"1.195395419","rc":[{"atb":[[17,3.86]],"id":42413752}],"con":true,"img":false}]}
{"op":"mcm","clk":"5306479009","pt":1646099200911,"mc":[{"id":"1.195395419","rc":[{"atb":[[9,2.5]],"id":42352031}],"con":true,"img":false}]}
{"op":"mcm","clk":"5306479015","pt":1646099201012,"mc":[{"id":"1.195395419","rc":[{"atb":[[9,4.5],[1.01,5.24],[8.6,1.99]],"id":42352031},{"atb":[[3.25,0]],"id":42248828}],"con":true,"img":false}]}
{"op":"mcm","clk":"5306479019","pt":1646099201115,"mc":[{"id":"1.195395419","rc":[{"atb":[[9,2.5],[8.8,2]],"id":42352031}],"con":true,"img":false}]}
{"op":"mcm","clk":"5306479024","pt":1646099201217,"mc":[{"id":"1.195395419","rc":[{"atb":[[1.01,4.48]],"id":42352031}],"con":true,"img":false}]}
{"op":"mcm","clk":"5306479032","pt":1646099201422,"mc":[{"id":"1.195395419","rc":[{"atb":[[1.01,3.57]],"id":42352031}],"con":true,"img":false}]}
{"op":"mcm","clk":"5306479036","pt":1646099201524,"mc":[{"id":"1.195395419","rc":[{"atb":[[9.2,0.91]],"id":42352031}],"con":true,"img":false}]}
{"op":"mcm","clk":"5306479054","pt":1646099201935,"mc":[{"id":"1.195395419","rc":[{"atb":[[8.6,0]],"id":42352031}],"con":true,"img":false}]}
{"op":"mcm","clk":"5306479058","pt":1646099202038,"mc":[{"id":"1.195395419","rc":[{"atb":[[9.2,2.9]],"id":42352031}],"con":true,"img":false}]}
{"op":"mcm","clk":"5306479064","pt":1646099202143,"mc":[{"id":"1.195395419","rc":[{"atb":[[9.2,4.9],[8.8,0]],"id":42352031}],"con":true,"img":false}]}
{"op":"mcm","clk":"5306479071","pt":1646099202244,"mc":[{"id":"1.195395419","rc":[{"atb":[[9,4.5]],"id":42352031}],"con":true,"img":false}]}
{"op":"mcm","clk":"5306479075","pt":1646099202347,"mc":[{"id":"1.195395419","rc":[{"atb":[[9.2,2.9]],"id":42352031}],"con":true,"img":false}]}
{"op":"mcm","clk":"5306479084","pt":1646099202627,"mc":[{"id":"1.195395419","rc":[{"atb":[[1.01,2]],"id":42352031}],"con":true,"img":false}]}
{"op":"mcm","clk":"5306479089","pt":1646099202708,"mc":[{"id":"1.195395419","rc":[{"atb":[[9.4,1.57]],"id":42352031},{"atb":[[2.72,1.35],[3.2,0.32]],"id":42248828}],"con":true,"img":false}]}
{"op":"mcm","clk":"5306479099","pt":1646099202912,"mc":[{"id":"1.195395419","rc":[{"atb":[[9,2.5],[9.4,3.57]],"id":42352031}],"con":true,"img":false}]}
{"op":"mcm","clk":"5306479104","pt":1646099203013,"mc":[{"id":"1.195395419","rc":[{"atb":[[9.2,4.9],[9.4,1.57]],"id":42352031},{"atb":[[2.72,0],[1.02,0]],"id":42248828}],"con":true,"img":false}]}
{"op":"mcm","clk":"5306479107","pt":1646099203115,"mc":[{"id":"1.195395419","rc":[{"atb":[[9.4,0]],"id":42352031},{"atb":[[2.76,6.2]],"id":42248828}],"con":true,"img":false}]}
{"op":"mcm","clk":"5306479111","pt":1646099203218,"mc":[{"id":"1.195395419","rc":[{"atb":[[1.01,3.57]],"id":42352031}],"con":true,"img":false}]}
{"op":"mcm","clk":"5306479120","pt":1646099203423,"mc":[{"id":"1.195395419","rc":[{"atb":[[3.4,2.5]],"id":42248828}],"con":true,"img":false}]}
{"op":"mcm","clk":"5306479127","pt":1646099203627,"mc":[{"id":"1.195395419","rc":[{"atb":[[9,0]],"id":42352031}],"con":true,"img":false}]}
{"op":"mcm","clk":"5306479147","pt":1646099204347,"mc":[{"id":"1.195395419","rc":[{"atb":[[9.2,2.91]],"id":42352031},{"spn":13.1,"spf":1.0,"id":42352031},{"spn":4.05,"spf":1.0,"id":42248828},{"spn":34.0,"spf":1.0,"id":42413752},{"spn":9.29,"spf":1.0,"id":43154448},{"spn":2.61,"spf":1.0,"id":43154449},{"spn":29.0,"spf":1.0,"id":43154446},{"spn":4.18,"spf":1.0,"id":43154447}],"con":true,"img":false}]}
{"op":"mcm","clk":"5306479151","pt":1646099204448,"mc":[{"id":"1.195395419","rc":[{"atb":[[1.02,1.99]],"id":42352031}],"con":true,"img":false}]}
{"op":"mcm","clk":"5306479156","pt":1646099204551,"mc":[{"id":"1.195395419","rc":[{"atb":[[8,2.13],[9.2,0.91]],"id":42352031},{"atb":[[2.76,4.21]],"id":42248828},{"atl":[[70,4.7],[75,0]],"id":42413752},{"atl":[[9,8.86],[10.5,0]],"id":43154447}],"con":true,"img":false}]}
{"op":"mcm","clk":"5306479159","pt":1646099204604,"mc":[{"id":"1.195395419","rc":[{"atb":[[1.02,1.99]],"id":42248828}],"con":true,"img":false}]}
{"op":"mcm","clk":"5306479167","pt":1646099205016,"mc":[{"id":"1.195395419","rc":[{"atb":[[1.01,2]],"id":42352031}],"con":true,"img":false}]}
{"op":"mcm","clk":"5306479172","pt":1646099205119,"mc":[{"id":"1.195395419","rc":[{"atb":[[7.8,2.85],[1.02,0]],"id":42352031}],"con":true,"img":false}]}
{"op":"mcm","clk":"5306479177","pt":1646099205222,"mc":[{"id":"1.195395419","rc":[{"atb":[[8.2,2.43]],"id":42352031}],"con":true,"img":false}]}
{"op":"mcm","clk":"5306479207","pt":1646099205835,"mc":[{"id":"1.195395419","rc":[{"atb":[[2.74,0]],"id":42248828},{"atb":[[16.5,1.56]],"id":42413752}],"con":true,"img":false}]}
{"op":"mcm","clk":"5306479216","pt":1646099206142,"mc":[{"id":"1.195395419","rc":[{"atb":[[2.76,2.86]],"id":42248828}],"con":true,"img":false}]}
{"op":"mcm","clk":"5306479220","pt":1646099206244,"mc":[{"id":"1.195395419","rc":[{"atb":[[1.01,4.89]],"id":42248828}],"con":true,"img":false}]}
{"op":"mcm","clk":"5306479235","pt":1646099206603,"mc":[{"id":"1.195395419","rc":[{"atb":[[7.6,0]],"id":42352031}],"con":true,"img":false}]}
{"op":"mcm","clk":"5306479240","pt":1646099206706,"mc":[{"id":"1.195395419","rc":[{"atb":[[7.2,10.97]],"id":42352031}],"con":true,"img":false}]}
{"op":"mcm","clk":"5306479261","pt":1646099207320,"mc":[{"id":"1.195395419","rc":[{"atb":[[7.8,1.28]],"id":42352031}],"con":true,"img":false}]}
{"op":"mcm","clk":"5306479266","pt":1646099207479,"mc":[{"id":"1.195395419","rc":[{"atb":[[1.01,3.57]],"id":42352031}],"con":true,"img":false}]}
{"op":"mcm","clk":"5306479280","pt":1646099207734,"mc":[{"id":"1.195395419","rc":[{"atb":[[8.2,4.88]],"id":42352031}],"con":true,"img":false}]}
{"op":"mcm","clk":"5306479314","pt":1646099208605,"mc":[{"id":"1.195395419","rc":[{"atl":[[8.8,0]],"id":43154447}],"con":true,"img":false}]}
{"op":"mcm","clk":"5306479318","pt":1646099208707,"mc":[{"id":"1.195395419","rc":[{"atl":[[8,7.07]],"id":43154447}],"con":true,"img":false}]}
{"op":"mcm","clk":"5306479355","pt":1646099209630,"mc":[{"id":"1.195395419","rc":[{"atb":[[8,0.13],[8.4,2]],"id":42352031}],"con":true,"img":false}]}
{"op":"mcm","clk":"5306479373","pt":1646099210446,"mc":[{"id":"1.195395419","rc":[{"atb":[[8.2,2.89]],"id":42352031}],"con":true,"img":false}]}
{"op":"mcm","clk":"5306479377","pt":1646099210548,"mc":[{"id":"1.195395419","rc":[{"atb":[[8.2,4.89],[8.4,0],[8.6,1.99]],"id":42352031}],"con":true,"img":false}]}
{"op":"mcm","clk":"5306479384","pt":1646099210754,"mc":[{"id":"1.195395419","rc":[{"atb":[[8.2,2.89]],"id":42352031}],"con":true,"img":false}]}
{"op":"mcm","clk":"5306479387","pt":1646099210858,"mc":[{"id":"1.195395419","rc":[{"atb":[[8.6,3.99]],"id":42352031}],"con":true,"img":false}]}
{"op":"mcm","clk":"5306479418","pt":1646099211729,"mc":[{"id":"1.195395419","rc":[{"atl":[[4.8,0]],"id":42248828}],"con":true,"img":false}]}
{"op":"mcm","clk":"5306479432","pt":1646099212036,"mc":[{"id":"1.195395419","rc":[{"atl":[[4.7,0]],"id":42248828},{"atl":[[3,4.86]],"id":43154449}],"con":true,"img":false}]}
{"op":"mcm","clk":"5306479438","pt":1646099212137,"mc":[{"id":"1.195395419","rc":[{"atb":[[9.4,2.5]],"id":42352031},{"atl":[[4.9,1.32]],"id":42248828}],"con":true,"img":false}]}
{"op":"mcm","clk":"5306479447","pt":1646099212343,"mc":[{"id":"1.195395419","rc":[{"atl":[[4.9,3.85]],"id":42248828}],"con":true,"img":false}]}
{"op":"mcm","clk":"5306479457","pt":1646099212548,"mc":[{"id":"1.195395419","rc":[{"atb":[[8.2,0.44]],"id":42352031}],"con":true,"img":false}]}
{"op":"mcm","clk":"5306479500","pt":1646099213623,"mc":[{"id":"1.195395419","rc":[{"atb":[[8.6,2]],"id":42352031}],"con":true,"img":false}]}
{"op":"mcm","clk":"5306479508","pt":1646099213727,"mc":[{"id":"1.195395419","rc":[{"atb":[[9.6,1.99]],"id":42352031}],"con":true,"img":false}]}
{"op":"mcm","clk":"5306479532","pt":1646099214338,"mc":[{"id":"1.195395419","rc":[{"atl":[[5.8,10.81]],"id":43154447}],"con":true,"img":false}]}
{"op":"mcm","clk":"5306479547","pt":1646099214748,"mc":[{"id":"1.195395419","rc":[{"atb":[[9.4,0]],"id":42352031}],"con":true,"img":false}]}
{"op":"mcm","clk":"5306479569","pt":1646099215258,"mc":[{"id":"1.195395419","rc":[{"atb":[[9.6,0]],"id":42352031},{"atb":[[2.76,0]],"id":42248828}],"con":true,"img":false}]}
{"op":"mcm","clk":"5306479576","pt":1646099215362,"mc":[{"id":"1.195395419","rc":[{"atb":[[9.4,1.99]],"id":42352031}],"con":true,"img":false}]}
{"op":"mcm","clk":"5306479585","pt":1646099215618,"mc":[{"id":"1.195395419","rc":[{"atb":[[9.4,3.99]],"id":42352031}],"con":true,"img":false}]}
{"op":"mcm","clk":"5306479591","pt":1646099215720,"mc":[{"id":"1.195395419","rc":[{"atb":[[8.6,0]],"id":42352031},{"atb":[[1.01,3.54]],"id":42248828}],"con":true,"img":false}]}
{"op":"mcm","clk":"5306479596","pt":1646099215824,"mc":[{"id":"1.195395419","rc":[{"atb":[[2.68,1.35]],"id":42248828}],"con":true,"img":false}]}
{"op":"mcm","clk":"5306479614","pt":1646099216232,"mc":[{"id":"1.195395419","rc":[{"atb":[[9.6,2.5]],"id":42352031}],"con":true,"img":false}]}
{"op":"mcm","clk":"5306479645","pt":1646099217052,"mc":[{"id":"1.195395419","rc":[{"atb":[[9.4,2]],"id":42352031}],"con":true,"img":false}]}
{"op":"mcm","clk":"5306479651","pt":1646099217155,"mc":[{"id":"1.195395419","rc":[{"atb":[[1.02,1.99]],"id":42352031}],"con":true,"img":false}]}
{"op":"mcm","clk":"5306479664","pt":1646099217565,"mc":[{"id":"1.195395419","rc":[{"atb":[[7.8,0]],"id":42352031},{"atl":[[4,0]],"id":43154449}],"con":true,"img":false}]}
{"op":"mcm","clk":"5306479671","pt":1646099217619,"mc":[{"id":"1.195395419","rc":[{"atb":[[7.4,1.28]],"id":42352031}],"con":true,"img":false}]}
{"op":"mcm","clk":"5306479713","pt":1646099218640,"mc":[{"id":"1.195395419","rc":[{"atb":[[7.4,13.54]],"id":42352031},{"atb":[[2.68,35.24]],"id":42248828}],"con":true,"img":false}]}
{"op":"mcm","clk":"5306479881","pt":1646099221979,"mc":[{"id":"1.195395419","rc":[{"atl":[[3,0]],"id":43154449}],"con":true,"img":false}]}
{"op":"mcm","clk":"5306479893","pt":1646099222186,"mc":[{"id":"1.195395419","rc":[{"atl":[[4.6,60.62]],"id":43154449}],"con":true,"img":false}]}
{"op":"mcm","clk":"5306479899","pt":1646099222234,"mc":[{"id":"1.195395419","rc":[{"atl":[[1000,0],[4.7,0]],"id":43154449}],"con":true,"img":false}]}
{"op":"mcm","clk":"5306479902","pt":1646099222341,"mc":[{"id":"1.195395419","rc":[{"atb":[[1.01,2],[1.02,0]],"id":43154449},{"atl":[[4,1.22]],"id":43154449}],"con":true,"img":false}]}
{"op":"mcm","clk":"5306479907","pt":1646099222442,"mc":[{"id":"1.195395419","rc":[{"atb":[[2.6,6.16],[2.62,1.58]],"id":43154449}],"con":true,"img":false}]}
{"op":"mcm","clk":"5306479911","pt":1646099222547,"mc":[{"id":"1.195395419","rc":[{"atb":[[2.52,0]],"id":42248828},{"atb":[[2.56,40.46]],"id":43154449}],"con":true,"img":false}]}
{"op":"mcm","clk":"5306479915","pt":1646099222646,"mc":[{"id":"1.195395419","rc":[{"atb":[[2.56,80.95]],"id":42248828},{"atb":[[2.52,0]],"id":43154449},{"atl":[[3.95,6.49]],"id":43154449}],"con":true,"img":false}]}
{"op":"mcm","clk":"5306479942","pt":1646099223262,"mc":[{"id":"1.195395419","rc":[{"atl":[[3.9,4.32]],"id":43154449}],"con":true,"img":false}]}
{"op":"mcm","clk":"5306479947","pt":1646099223362,"mc":[{"id":"1.195395419","rc":[{"atl":[[4,0]],"id":43154449}],"con":true,"img":false}]}
{"op":"mcm","clk":"5306479954","pt":1646099223464,"mc":[{"id":"1.195395419","rc":[{"atl":[[3.9,5.55]],"id":43154449}],"con":true,"img":false}]}
{"op":"mcm","clk":"5306479966","pt":1646099223773,"mc":[{"id":"1.195395419","rc":[{"atb":[[2.64,2.5]],"id":43154449}],"con":true,"img":false}]}
{"op":"mcm","clk":"5306479979","pt":1646099224130,"mc":[{"id":"1.195395419","rc":[{"atb":[[2.6,4.87],[2.62,0]],"id":43154449}],"con":true,"img":false}]}
{"op":"mcm","clk":"5306479981","pt":1646099224233,"mc":[{"id":"1.195395419","rc":[{"atb":[[2.64,3.8],[2.6,0],[2.66,1.58]],"id":43154449}],"con":true,"img":false}]}
{"op":"mcm","clk":"5306479988","pt":1646099224337,"mc":[{"id":"1.195395419","rc":[{"atb":[[1.02,1.99]],"id":43154449}],"con":true,"img":false}]}
{"op":"mcm","clk":"5306480007","pt":1646099224747,"mc":[{"id":"1.195395419","rc":[{"atb":[[2.64,2.5],[2.66,0]],"id":43154449}],"con":true,"img":false}]}
{"op":"mcm","clk":"5306480011","pt":1646099224850,"mc":[{"id":"1.195395419","rc":[{"atb":[[1.01,3.58],[2.58,1.29]],"id":43154449}],"con":true,"img":false}]}
{"op":"mcm","clk":"5306480036","pt":1646099225467,"mc":[{"id":"1.195395419","rc":[{"atb":[[2.7,7.76]],"id":42248828}],"con":true,"img":false}]}
{"op":"mcm","clk":"5306480051","pt":1646099225876,"mc":[{"id":"1.195395419","rc":[{"atb":[[2.68,33.88]],"id":42248828}],"con":true,"img":false}]}
{"op":"mcm","clk":"5306480056","pt":1646099225930,"mc":[{"id":"1.195395419","rc":[{"atb":[[2.7,9.11]],"id":42248828}],"con":true,"img":false}]}
{"op":"mcm","clk":"5306480106","pt":1646099227055,"mc":[{"id":"1.195395419","rc":[{"atl":[[1000,1.67]],"id":43154446}],"con":true,"img":false}]}
{"op":"mcm","clk":"5306480115","pt":1646099227261,"mc":[{"id":"1.195395419","rc":[{"atl":[[1000,0.21]],"id":43154446}],"con":true,"img":false}]}
{"op":"mcm","clk":"5306480124","pt":1646099227466,"mc":[{"id":"1.195395419","rc":[{"atl":[[1000,0]],"id":43154446}],"con":true,"img":false}]}
{"op":"mcm","clk":"5306480128","pt":1646099227568,"mc":[{"id":"1.195395419","rc":[{"atl":[[38,0.21]],"id":43154446}],"con":true,"img":false}]}
{"op":"mcm","clk":"5306480176","pt":1646099228545,"mc":[{"id":"1.195395419","rc":[{"atb":[[2.68,0]],"id":42248828},{"atl":[[3.85,4.16]],"id":43154449}],"con":true,"img":false}]}
{"op":"mcm","clk":"5306480193","pt":1646099228755,"mc":[{"id":"1.195395419","rc":[{"atl":[[3.9,4.32]],"id":43154449}],"con":true,"img":false}]}
{"op":"mcm","clk":"5306480201","pt":1646099228853,"mc":[{"id":"1.195395419","rc":[{"atl":[[3.8,1.22]],"id":43154449}],"con":true,"img":false}]}
{"op":"mcm","clk":"5306480320","pt":1646099230954,"mc":[{"id":"1.195395419","rc":[{"atl":[[4.5,0]],"id":43154449}],"con":true,"img":false}]}
{"op":"mcm","clk":"5306480522","pt":1646099234859,"mc":[{"id":"1.195395419","rc":[{"atl":[[3.95,0]],"id":43154449}],"con":true,"img":false}]}
{"op":"mcm","clk":"5306480535","pt":1646099235067,"mc":[{"id":"1.195395419","rc":[{"atb":[[2.74,3.41]],"id":42248828},{"atl":[[3.75,6.49]],"id":43154449}],"con":true,"img":false}]}
{"op":"mcm","clk":"5306480554","pt":1646099235474,"mc":[{"id":"1.195395419","rc":[{"atl":[[3.8,0]],"id":43154449}],"con":true,"img":false}]}
{"op":"mcm","clk":"5306480560","pt":1646099235577,"mc":[{"id":"1.195395419","rc":[{"atb":[[2.7,7.76]],"id":42248828},{"atl":[[3.7,1.22]],"id":43154449}],"con":true,"img":false}]}
{"op":"mcm","clk":"5306480567","pt":1646099235678,"mc":[{"id":"1.195395419","rc":[{"atb":[[2.74,4.76]],"id":42248828}],"con":true,"img":false}]}
{"op":"mcm","clk":"5306480705","pt":1646099238962,"mc":[{"id":"1.195395419","rc":[{"atb":[[2.7,0]],"id":42248828}],"con":true,"img":false}]}
{"op":"mcm","clk":"5306480737","pt":1646099239783,"mc":[{"id":"1.195395419","rc":[{"atb":[[2.74,3.41]],"id":42248828}],"con":true,"img":false}]}
{"op":"mcm","clk":"5306480743","pt":1646099239886,"mc":[{"id":"1.195395419","rc":[{"atb":[[1.01,4.89]],"id":42248828}],"con":true,"img":false}]}
{"op":"mcm","clk":"5306480833","pt":1646099241686,"mc":[{"id":"1.195395419","rc":[{"atb":[[2.74,0]],"id":42248828},{"atl":[[3.85,0]],"id":43154449}],"con":true,"img":false}]}
{"op":"mcm","clk":"5306480857","pt":1646099242100,"mc":[{"id":"1.195395419","rc":[{"atb":[[1.01,3.54]],"id":42248828}],"con":true,"img":false}]}
{"op":"mcm","clk":"5306480862","pt":1646099242154,"mc":[{"id":"1.195395419","rc":[{"atb":[[2.68,1.35]],"id":42248828}],"con":true,"img":false}]}
{"op":"mcm","clk":"5306480965","pt":1646099244261,"mc":[{"id":"1.195395419","rc":[{"atb":[[2.76,7.01]],"id":42248828}],"con":true,"img":false}]}
{"op":"mcm","clk":"5306480978","pt":1646099244567,"mc":[{"id":"1.195395419","rc":[{"atb":[[7.2,1.62]],"id":42352031},{"atb":[[2.68,0]],"id":42248828}],"con":true,"img":false}]}
{"op":"mcm","clk":"5306480983","pt":1646099244670,"mc":[{"id":"1.195395419","rc":[{"atb":[[7.6,9.35]],"id":42352031},{"atb":[[2.76,8.36]],"id":42248828}],"con":true,"img":false}]}
{"op":"mcm","clk":"5306481030","pt":1646099245694,"mc":[{"id":"1.195395419","rc":[{"atb":[[7.4,12.25]],"id":42352031}],"con":true,"img":false}]}
{"op":"mcm","clk":"5306481036","pt":1646099245797,"mc":[{"id":"1.195395419","rc":[{"atb":[[7.8,1.28]],"id":42352031}],"con":true,"img":false}]}
{"op":"mcm","clk":"5306481107","pt":1646099247391,"mc":[{"id":"1.195395419","rc":[{"atl":[[3.75,0]],"id":43154449}],"con":true,"img":false}]}
{"op":"mcm","clk":"5306481115","pt":1646099247596,"mc":[{"id":"1.195395419","rc":[{"atl":[[3.65,6.49]],"id":43154449}],"con":true,"img":false}]}
{"op":"mcm","clk":"5306481131","pt":1646099248065,"mc":[{"id":"1.195395419","rc":[{"atl":[[3.7,0]],"id":43154449}],"con":true,"img":false}]}
{"op":"mcm","clk":"5306481135","pt":1646099248163,"mc":[{"id":"1.195395419","rc":[{"atl":[[3.6,1.22]],"id":43154449}],"con":true,"img":false}]}
{"op":"mcm","clk":"5306481143","pt":1646099248366,"mc":[{"id":"1.195395419","rc":[{"atb":[[7.4,0]],"id":42352031},{"atb":[[2.78,9.63]],"id":42248828},{"atl":[[3.65,12.27]],"id":43154449}],"con":true,"img":false}]}
{"op":"mcm","clk":"5306481153","pt":1646099248674,"mc":[{"id":"1.195395419","rc":[{"atb":[[2.76,7.01]],"id":42248828}],"con":true,"img":false}]}
{"op":"mcm","clk":"5306481157","pt":1646099248777,"mc":[{"id":"1.195395419","rc":[{"atb":[[2.8,1.35]],"id":42248828}],"con":true,"img":false}]}
{"op":"mcm","clk":"5306481299","pt":1646099251984,"mc":[{"id":"1.195395419","rc":[{"atb":[[7.8,14.8]],"id":42352031},{"atb":[[2.78,0]],"id":42248828}],"con":true,"img":false}]}
{"op":"mcm","clk":"5306481306","pt":1646099252190,"mc":[{"id":"1.195395419","rc":[{"atb":[[2.76,0]],"id":42248828}],"con":true,"img":false}]}
{"op":"mcm","clk":"5306481316","pt":1646099252397,"mc":[{"id":"1.195395419","rc":[{"atb":[[2.8,0]],"id":42248828}],"con":true,"img":false}]}
{"op":"mcm","clk":"5306481323","pt":1646099252499,"mc":[{"id":"1.195395419","rc":[{"atb":[[2.76,1.35]],"id":42248828}],"con":true,"img":false}]}
{"op":"mcm","clk":"5306481340","pt":1646099252908,"mc":[{"id":"1.195395419","rc":[{"atb":[[2.76,0]],"id":42248828}],"con":true,"img":false}]}
{"op":"mcm","clk":"5306481344","pt":1646099253011,"mc":[{"id":"1.195395419","rc":[{"atb":[[2.68,1.35]],"id":42248828}],"con":true,"img":false}]}
{"op":"mcm","clk":"5306481365","pt":1646099253475,"mc":[{"id":"1.195395419","rc":[{"atl":[[3.9,0]],"id":43154449}],"con":true,"img":false}]}
{"op":"mcm","clk":"5306481376","pt":1646099253680,"mc":[{"id":"1.195395419","rc":[{"atl":[[3.55,4.32]],"id":43154449}],"con":true,"img":false}]}
{"op":"mcm","clk":"5306481394","pt":1646099254090,"mc":[{"id":"1.195395419","rc":[{"atl":[[3.6,0]],"id":43154449}],"con":true,"img":false}]}
{"op":"mcm","clk":"5306481398","pt":1646099254193,"mc":[{"id":"1.195395419","rc":[{"atl":[[3.5,1.22]],"id":43154449}],"con":true,"img":false}]}
{"op":"mcm","clk":"5306481511","pt":1646099256604,"mc":[{"id":"1.195395419","rc":[{"atb":[[7.6,0]],"id":42352031}],"con":true,"img":false}]}
{"op":"mcm","clk":"5306481519","pt":1646099256707,"mc":[{"id":"1.195395419","rc":[{"atb":[[7.2,10.97]],"id":42352031}],"con":true,"img":false}]}
{"op":"mcm","clk":"5306481553","pt":1646099257174,"mc":[{"id":"1.195395419","rc":[{"atb":[[1.01,5.24]],"id":42352031}],"con":true,"img":false}]}
{"op":"mcm","clk":"5306481561","pt":1646099257278,"mc":[{"id":"1.195395419","rc":[{"atb":[[9.2,0]],"id":42352031}],"con":true,"img":false}]}
{"op":"mcm","clk":"5306481566","pt":1646099257380,"mc":[{"id":"1.195395419","rc":[{"atb":[[1.01,4.42]],"id":42352031}],"con":true,"img":false}]}
{"op":"mcm","clk":"5306481580","pt":1646099257685,"mc":[{"id":"1.195395419","rc":[{"atb":[[2.88,5.5]],"id":42248828}],"con":true,"img":false}]}
{"op":"mcm","clk":"5306481588","pt":1646099257889,"mc":[{"id":"1.195395419","rc":[{"atb":[[1.01,3.57]],"id":42352031},{"atb":[[2.68,0]],"id":42248828}],"con":true,"img":false}]}
{"op":"mcm","clk":"5306481594","pt":1646099257991,"mc":[{"id":"1.195395419","rc":[{"atb":[[9.8,0.85]],"id":42352031},{"atb":[[2.88,6.85]],"id":42248828}],"con":true,"img":false}]}
{"op":"mcm","clk":"5306481618","pt":1646099258504,"mc":[{"id":"1.195395419","rc":[{"atb":[[2.76,11.88]],"id":42248828},{"atl":[[3.65,6.49]],"id":43154449}],"con":true,"img":false}]}
{"op":"mcm","clk":"5306481662","pt":1646099259379,"mc":[{"id":"1.195395419","rc":[{"atb":[[9.6,0]],"id":42352031}],"con":true,"img":false}]}
{"op":"mcm","clk":"5306481666","pt":1646099259480,"mc":[{"id":"1.195395419","rc":[{"atb":[[8,2.13],[9.4,0]],"id":42352031}],"con":true,"img":false}]}
{"op":"mcm","clk":"5306481683","pt":1646099259889,"mc":[{"id":"1.195395419","rc":[{"atl":[[3.65,0]],"id":43154449}],"con":true,"img":false}]}
{"op":"mcm","clk":"5306481690","pt":1646099260095,"mc":[{"id":"1.195395419","rc":[{"atl":[[3.45,6.49]],"id":43154449}],"con":true,"img":false}]}
{"op":"mcm","clk":"5306481693","pt":1646099260201,"mc":[{"id":"1.195395419","rc":[{"atb":[[1.01,2]],"id":42352031}],"con":true,"img":false}]}
{"op":"mcm","clk":"5306481698","pt":1646099260302,"mc":[{"id":"1.195395419","rc":[{"atb":[[8,3.7]],"id":42352031}],"con":true,"img":false}]}
{"op":"mcm","clk":"5306481715","pt":1646099260610,"mc":[{"id":"1.195395419","rc":[{"atl":[[3.5,0]],"id":43154449}],"con":true,"img":false}]}
{"op":"mcm","clk":"5306481722","pt":1646099260712,"mc":[{"id":"1.195395419","rc":[{"atl":[[3.4,1.22]],"id":43154449}],"con":true,"img":false}]}
{"op":"mcm","clk":"5306481769","pt":1646099261795,"mc":[{"id":"1.195395419","rc":[{"atb":[[4.8,53],[7.8,1.28],[5.4,0]],"id":42352031},{"atl":[[19.5,0],[20,1.05]],"id":42352031},{"atl":[[70,2.7],[75,2]],"id":42413752},{"atb":[[5.3,23.26],[4.1,0]],"id":43154446}],"con":true,"img":false}]}
{"op":"mcm","clk":"5306481773","pt":1646099261898,"mc":[{"id":"1.195395419","rc":[{"atb":[[2.64,0]],"id":43154449}],"con":true,"img":false}]}
{"op":"mcm","clk":"5306481784","pt":1646099262104,"mc":[{"id":"1.195395419","rc":[{"atl":[[24,3.7]],"id":43154448},{"atb":[[1.02,0]],"id":43154449},{"atb":[[2.5,13.33],[2.42,0]],"id":43154447}],"con":true,"img":false}]}
{"op":"mcm","clk":"5306481789","pt":1646099262207,"mc":[{"id":"1.195395419","rc":[{"atb":[[7.4,0],[7.8,0],[7.2,0],[7.6,0]],"id":43154448},{"atl":[[25,0]],"id":43154448},{"atb":[[2.58,3.28]],"id":43154449},{"atl":[[4.9,0],[5.1,0],[5,0],[5.2,0]],"id":43154447}],"con":true,"img":false}]}
{"op":"mcm","clk":"5306481813","pt":1646099262618,"mc":[{"id":"1.195395419","rc":[{"atb":[[8,2.13]],"id":42352031}],"con":true,"img":false}]}
{"op":"mcm","clk":"5306481818","pt":1646099262721,"mc":[{"id":"1.195395419","rc":[{"atb":[[7.4,1.57]],"id":42352031}],"con":true,"img":false}]}
{"op":"mcm","clk":"5306481821","pt":1646099262774,"mc":[{"id":"1.195395419","rc":[{"atb":[[9.6,8.25]],"id":43154448}],"con":true,"img":false}]}
{"op":"mcm","clk":"5306481823","pt":1646099262883,"mc":[{"id":"1.195395419","rc":[{"atb":[[1.01,1.37]],"id":43154448}],"con":true,"img":false}]}
{"op":"mcm","clk":"5306481846","pt":1646099263315,"mc":[{"id":"1.195395419","rc":[{"atb":[[7.8,0]],"id":42352031},{"atb":[[2.58,6.15]],"id":43154449}],"con":true,"img":false}]}
{"op":"mcm","clk":"5306481851","pt":1646099263413,"mc":[{"id":"1.195395419","rc":[{"atb":[[8.2,3.59],[7.4,2.85]],"id":42352031},{"atb":[[2.88,1.35]],"id":42248828}],"con":true,"img":false}]}
{"op":"mcm","clk":"5306481858","pt":1646099263517,"mc":[{"id":"1.195395419","rc":[{"atb":[[8,0.13],[8.4,2]],"id":42352031}],"con":true,"img":false}]}
{"op":"mcm","clk":"5306481868","pt":1646099263722,"mc":[{"id":"1.195395419","rc":[{"atb":[[7.4,1.28]],"id":42352031},{"atl":[[19.5,1.08]],"id":42352031}],"con":true,"img":false}]}
{"op":"mcm","clk":"5306481875","pt":1646099263779,"mc":[{"id":"1.195395419","rc":[{"atb":[[8.6,1.57]],"id":42352031},{"atl":[[20,0]],"id":42352031}],"con":true,"img":false}]}
{"op":"mcm","clk":"5306481885","pt":1646099263982,"mc":[{"id":"1.195395419","rc":[{"atb":[[2.88,0]],"id":42248828},{"atl":[[6.4,3.7],[6.6,17.86]],"id":42248828},{"atb":[[8,14.29],[8.2,12.78]],"id":42413752},{"atb":[[6.4,3.7],[6.8,0],[7,20.23]],"id":43154448},{"atl":[[14,4]],"id":43154448},{"atl":[[4.6,55.06],[4.7,5.41]],"id":43154449},{"atb":[[11,2],[12,0]],"id":43154446},{"atb":[[2.5,0],[2.6,12.5]],"id":43154447},{"atl":[[5.2,2]],"id":43154447}],"con":true,"img":false}]}
{"op":"mcm","clk":"5306481890","pt":1646099264086,"mc":[{"id":"1.195395419","rc":[{"atb":[[2.78,1.35]],"id":42248828}],"con":true,"img":false}]}
{"op":"mcm","clk":"5306481901","pt":1646099264391,"mc":[{"id":"1.195395419","rc":[{"atb":[[8.6,0]],"id":42352031},{"spn":13.4,"spf":1.0,"id":42352031},{"spn":4.15,"spf":1.0,"id":42248828},{"spn":9.24,"spf":1.0,"id":43154448},{"atb":[[2.6,2.5]],"id":43154449},{"spn":2.61,"spf":1.0,"id":43154449},{"spn":28.0,"spf":1.0,"id":43154446}],"con":true,"img":false}]}
{"op":"mcm","clk":"5306481905","pt":1646099264495,"mc":[{"id":"1.195395419","rc":[{"atb":[[1.01,3.57]],"id":42352031}],"con":true,"img":false}]}
{"op":"mcm","clk":"5306481928","pt":1646099265006,"mc":[{"id":"1.195395419","rc":[{"atb":[[1.01,2]],"id":42352031}],"con":true,"img":false}]}
{"op":"mcm","clk":"5306481936","pt":1646099265109,"mc":[{"id":"1.195395419","rc":[{"atb":[[8.6,1.57]],"id":42352031},{"atb":[[2.76,0]],"id":42248828},{"atb":[[2.58,2.87]],"id":43154449},{"atl":[[3.35,5.78]],"id":43154449}],"con":true,"img":false}]}
{"op":"mcm","clk":"5306481942","pt":1646099265211,"mc":[{"id":"1.195395419","rc":[{"atb":[[2.6,3.8],[1.02,1.99]],"id":43154449}],"con":true,"img":false}]}
{"op":"mcm","clk":"5306481956","pt":1646099265519,"mc":[{"id":"1.195395419","rc":[{"atl":[[3.4,0]],"id":43154449}],"con":true,"img":false}]}
{"op":"mcm","clk":"5306481963","pt":1646099265622,"mc":[{"id":"1.195395419","rc":[{"atb":[[8.6,0]],"id":42352031},{"atl":[[3.3,1.22]],"id":43154449}],"con":true,"img":false}]}
{"op":"mcm","clk":"5306481967","pt":1646099265678,"mc":[{"id":"1.195395419","rc":[{"atb":[[1.01,3.57]],"id":42352031},{"atb":[[11,0]],"id":43154448}],"con":true,"img":false}]}
{"op":"mcm","clk":"5306481972","pt":1646099265780,"mc":[{"id":"1.195395419","rc":[{"atb":[[2.78,0]],"id":42248828},{"atb":[[10,3.12]],"id":43154448},{"atb":[[2.6,2.5]],"id":43154449}],"con":true,"img":false}]}
{"op":"mcm","clk":"5306481979","pt":1646099265885,"mc":[{"id":"1.195395419","rc":[{"atb":[[2.68,1.35]],"id":42248828},{"atb":[[10.5,0]],"id":43154448},{"atb":[[1.02,3.28]],"id":43154449}],"con":true,"img":false}]}
{"op":"mcm","clk":"5306481985","pt":1646099265984,"mc":[{"id":"1.195395419","rc":[{"atb":[[10,1.12]],"id":43154448}],"con":true,"img":false}]}
{"op":"mcm","clk":"5306481989","pt":1646099266090,"mc":[{"id":"1.195395419","rc":[{"atb":[[9.8,2]],"id":43154448}],"con":true,"img":false}]}
{"op":"mcm","clk":"5306481994","pt":1646099266195,"mc":[{"id":"1.195395419","rc":[{"atb":[[9.6,6.74]],"id":43154448}],"con":true,"img":false}]}
{"op":"mcm","clk":"5306482000","pt":1646099266295,"mc":[{"id":"1.195395419","rc":[{"atb":[[10.5,1.51]],"id":43154448}],"con":true,"img":false}]}
{"op":"mcm","clk":"5306482011","pt":1646099266500,"mc":[{"id":"1.195395419","rc":[{"atb":[[1.01,3.37]],"id":43154448}],"con":true,"img":false}]}
{"op":"mcm","clk":"5306482018","pt":1646099266598,"mc":[{"id":"1.195395419","rc":[{"atb":[[1.01,5.36]],"id":43154448}],"con":true,"img":false}]}
{"op":"mcm","clk":"5306482030","pt":1646099266804,"mc":[{"id":"1.195395419","rc":[{"atb":[[1.01,3.37],[10.5,0]],"id":43154448}],"con":true,"img":false}]}
{"op":"mcm","clk":"5306482036","pt":1646099266906,"mc":[{"id":"1.195395419","rc":[{"atb":[[1.02,1.99],[9.8,3.51]],"id":43154448},{"atb":[[2.6,0]],"id":43154449}],"con":true,"img":false}]}
{"op":"mcm","clk":"5306482056","pt":1646099267522,"mc":[{"id":"1.195395419","rc":[{"atb":[[1.02,0]],"id":43154448}],"con":true,"img":false}]}
{"op":"mcm","clk":"5306482062","pt":1646099267576,"mc":[{"id":"1.195395419","rc":[{"atb":[[10,3.11]],"id":43154448}],"con":true,"img":false}]}
{"op":"mcm","clk":"5306482072","pt":1646099267883,"mc":[{"id":"1.195395419","rc":[{"atb":[[1.02,1.29]],"id":43154449}],"con":true,"img":false}]}
{"op":"mcm","clk":"5306482077","pt":1646099267986,"mc":[{"id":"1.195395419","rc":[{"atb":[[9.8,2]],"id":43154448},{"atb":[[2.6,1.99]],"id":43154449}],"con":true,"img":false}]}
{"op":"mcm","clk":"5306482081","pt":1646099268091,"mc":[{"id":"1.195395419","rc":[{"atb":[[10.5,1.51]],"id":43154448}],"con":true,"img":false}]}
{"op":"mcm","clk":"5306482092","pt":1646099268397,"mc":[{"id":"1.195395419","rc":[{"atb":[[8.2,0.44],[7.4,14.17]],"id":42352031},{"atb":[[2.56,35.21]],"id":43154449}],"con":true,"img":false}]}
{"op":"mcm","clk":"5306482106","pt":1646099268703,"mc":[{"id":"1.195395419","rc":[{"atb":[[8,2.13],[8.4,0]],"id":42352031}],"con":true,"img":false}]}
{"op":"mcm","clk":"5306482120","pt":1646099268908,"mc":[{"id":"1.195395419","rc":[{"atl":[[19.5,0],[20,1.05]],"id":42352031},{"atb":[[7,16.9]],"id":43154448},{"atl":[[13.5,4]],"id":43154448},{"atb":[[2.5,13.33],[2.6,0]],"id":43154447},{"atl":[[5.1,2]],"id":43154447}],"con":true,"img":false}]}
{"op":"mcm","clk":"5306482135","pt":1646099269216,"mc":[{"id":"1.195395419","rc":[{"atb":[[10.5,0]],"id":43154448}],"con":true,"img":false}]}
{"op":"mcm","clk":"5306482143","pt":1646099269319,"mc":[{"id":"1.195395419","rc":[{"atb":[[1.01,4.88]],"id":43154448}],"con":true,"img":false}]}
{"op":"mcm","clk":"5306482172","pt":1646099269685,"mc":[{"id":"1.195395419","rc":[{"atl":[[22,0]],"id":43154448}],"con":true,"img":false}]}
{"op":"mcm","clk":"5306482175","pt":1646099269784,"mc":[{"id":"1.195395419","rc":[{"atl":[[13,1.33]],"id":43154448}],"con":true,"img":false}]}
{"op":"mcm","clk":"5306482242","pt":1646099271221,"mc":[{"id":"1.195395419","rc":[{"atb":[[10.5,2]],"id":43154448}],"con":true,"img":false}]}
{"op":"mcm","clk":"5306482249","pt":1646099271322,"mc":[{"id":"1.195395419","rc":[{"atb":[[9.8,0]],"id":43154448}],"con":true,"img":false}]}
{"op":"mcm","clk":"5306482270","pt":1646099271686,"mc":[{"id":"1.195395419","rc":[{"atb":[[10,1.12]],"id":43154448}],"con":true,"img":false}]}
{"op":"mcm","clk":"5306482275","pt":1646099271790,"mc":[{"id":"1.195395419","rc":[{"atb":[[2.78,16.65]],"id":42248828},{"atb":[[11.5,0],[1.02,1.99]],"id":43154448}],"con":true,"img":false}]}
{"op":"mcm","clk":"5306482279","pt":1646099271891,"mc":[{"id":"1.195395419","rc":[{"atb":[[1.02,4.22]],"id":43154448},{"atb":[[1.03,2.23]],"id":43154446}],"con":true,"img":false}]}
{"op":"mcm","clk":"5306482285","pt":1646099271994,"mc":[{"id":"1.195395419","rc":[{"atb":[[1.04,2.23]],"id":42413752}],"con":true,"img":false}]}
{"op":"mcm","clk":"5306482287","pt":1646099272096,"mc":[{"id":"1.195395419","rc":[{"atb":[[17.5,0]],"id":43154446}],"con":true,"img":false}]}
{"op":"mcm","clk":"5306482290","pt":1646099272198,"mc":[{"id":"1.195395419","rc":[{"atb":[[19.5,0]],"id":42413752},{"atb":[[1.01,3.37]],"id":43154448}],"con":true,"img":false}]}
{"op":"mcm","clk":"5306482293","pt":1646099272300,"mc":[{"id":"1.195395419","rc":[{"atb":[[2.68,0]],"id":42248828},{"atb":[[9.8,1.51]],"id":43154448},{"atl":[[3.45,0]],"id":43154449}],"con":true,"img":false}]}
{"op":"mcm","clk":"5306482300","pt":1646099272402,"mc":[{"id":"1.195395419","rc":[{"atb":[[2.8,1.35]],"id":42248828},{"atb":[[1.02,2.31]],"id":43154448},{"atb":[[1.03,0.2]],"id":43154446}],"con":true,"img":false}]}
{"op":"mcm","clk":"5306482303","pt":1646099272505,"mc":[{"id":"1.195395419","rc":[{"atl":[[3.25,6.49]],"id":43154449}],"con":true,"img":false}]}
{"op":"mcm","clk":"5306482309","pt":1646099272610,"mc":[{"id":"1.195395419","rc":[{"atb":[[1.04,0.17]],"id":42413752}],"con":true,"img":false}]}
{"op":"mcm","clk":"5306482323","pt":1646099272912,"mc":[{"id":"1.195395419","rc":[{"atb":[[1.03,0]],"id":43154446}],"con":true,"img":false}]}
{"op":"mcm","clk":"5306482331","pt":1646099273015,"mc":[{"id":"1.195395419","rc":[{"atb":[[18.5,0.2]],"id":43154446}],"con":true,"img":false}]}
{"op":"mcm","clk":"5306482336","pt":1646099273219,"mc":[{"id":"1.195395419","rc":[{"atb":[[7.6,3.42]],"id":42352031},{"atb":[[1.02,1.99]],"id":43154448}],"con":true,"img":false}]}
{"op":"mcm","clk":"5306482338","pt":1646099273321,"mc":[{"id":"1.195395419","rc":[{"atb":[[11,0.32]],"id":43154448},{"atl":[[3.3,0]],"id":43154449}],"con":true,"img":false}]}
{"op":"mcm","clk":"5306482341","pt":1646099273424,"mc":[{"id":"1.195395419","rc":[{"atl":[[3.2,1.22]],"id":43154449}],"con":true,"img":false}]}
{"op":"mcm","clk":"5306482346","pt":1646099273526,"mc":[{"id":"1.195395419","rc":[{"atb":[[1.04,0]],"id":42413752}],"con":true,"img":false}]}
{"op":"mcm","clk":"5306482351","pt":1646099273629,"mc":[{"id":"1.195395419","rc":[{"atb":[[7.4,12.88]],"id":42352031},{"atb":[[21,0.17]],"id":42413752}],"con":true,"img":false}]}
{"op":"mcm","clk":"5306482358","pt":1646099273731,"mc":[{"id":"1.195395419","rc":[{"atb":[[7.6,4.71]],"id":42352031}],"con":true,"img":false}]}
{"op":"mcm","clk":"5306482370","pt":1646099273890,"mc":[{"id":"1.195395419","rc":[{"atl":[[13,3.33],[14,0]],"id":43154448},{"atl":[[5,3]],"id":43154447}],"con":true,"img":false}]}
{"op":"mcm","clk":"5306482376","pt":1646099273991,"mc":[{"id":"1.195395419","rc":[{"atb":[[6,30.28]],"id":43154448},{"atl":[[4.9,12.82]],"id":43154449},{"atb":[[10,16.82]],"id":43154446}],"con":true,"img":false}]}
{"op":"mcm","clk":"5306482396","pt":1646099274505,"mc":[{"id":"1.195395419","rc":[{"atl":[[13,2]],"id":43154448}],"con":true,"img":false}]}
{"op":"mcm","clk":"5306482403","pt":1646099274612,"mc":[{"id":"1.195395419","rc":[{"atl":[[1000,1.33]],"id":43154448}],"con":true,"img":false}]}
{"op":"mcm","clk":"5306482438","pt":1646099275423,"mc":[{"id":"1.195395419","rc":[{"atb":[[2.58,0]],"id":43154449}],"con":true,"img":false}]}
{"op":"mcm","clk":"5306482478","pt":1646099276297,"mc":[{"id":"1.195395419","rc":[{"atb":[[10,3.12],[10.5,0]],"id":43154448}],"con":true,"img":false}]}
{"op":"mcm","clk":"5306482520","pt":1646099277012,"mc":[{"id":"1.195395419","rc":[{"atb":[[9.8,0]],"id":43154448}],"con":true,"img":false}]}
{"op":"mcm","clk":"5306482524","pt":1646099277114,"mc":[{"id":"1.195395419","rc":[{"atb":[[1.01,4.88]],"id":43154448}],"con":true,"img":false}]}
{"op":"mcm","clk":"5306482574","pt":1646099278502,"mc":[{"id":"1.195395419","rc":[{"atb":[[2.56,0]],"id":42248828},{"atb":[[2.6,4.93]],"id":43154449}],"con":true,"img":false}]}
{"op":"mcm","clk":"5306482578","pt":1646099278604,"mc":[{"id":"1.195395419","rc":[{"atb":[[7.4,0]],"id":42352031},{"atb":[[2.52,80.95],[2.78,0]],"id":42248828},{"atl":[[3.35,0]],"id":43154449}],"con":true,"img":false}]}
{"op":"mcm","clk":"5306482590","pt":1646099278911,"mc":[{"id":"1.195395419","rc":[{"atl":[[22,8.06]],"id":42352031},{"atb":[[2.8,0]],"id":42248828},{"atb":[[2.46,34.25]],"id":43154447}],"con":true,"img":false}]}
{"op":"mcm","clk":"5306482594","pt":1646099279014,"mc":[{"id":"1.195395419","rc":[{"atb":[[2.68,1.35]],"id":42248828}],"con":true,"img":false}]}
{"op":"mcm","clk":"5306482600","pt":1646099279115,"mc":[{"id":"1.195395419","rc":[{"atb":[[6.2,0]],"id":43154448},{"atl":[[12.5,3]],"id":43154448},{"atl":[[4.9,3]],"id":43154447}],"con":true,"img":false}]}
{"op":"mcm","clk":"5306482606","pt":1646099279217,"mc":[{"id":"1.195395419","rc":[{"atl":[[21,0],[23,0],[25,0]],"id":42352031},{"atl":[[4.8,0],[5,0],[5.2,0]],"id":43154449},{"atb":[[2.3,0]],"id":43154447}],"con":true,"img":false}]}
{"op":"mcm","clk":"5306482754","pt":1646099282815,"mc":[{"id":"1.195395419","rc":[{"atb":[[7.6,1.28]],"id":42352031},{"atb":[[2.62,3.71]],"id":43154449}],"con":true,"img":false}]}
{"op":"mcm","clk":"5306482775","pt":1646099283122,"mc":[{"id":"1.195395419","rc":[{"atb":[[7.6,0]],"id":42352031}],"con":true,"img":false}]}
{"op":"mcm","clk":"5306482782","pt":1646099283226,"mc":[{"id":"1.195395419","rc":[{"atb":[[7.4,1.28]],"id":42352031}],"con":true,"img":false}]}
{"op":"mcm","clk":"5306482796","pt":1646099283534,"mc":[{"id":"1.195395419","rc":[{"atl":[[3.2,0]],"id":43154449}],"con":true,"img":false}]}
{"op":"mcm","clk":"5306482802","pt":1646099283637,"mc":[{"id":"1.195395419","rc":[{"atl":[[1000,1.22]],"id":43154449}],"con":true,"img":false}]}
{"op":"mcm","clk":"5306482808","pt":1646099283741,"mc":[{"id":"1.195395419","rc":[{"atb":[[2.6,2.94]],"id":43154449}],"con":true,"img":false}]}
{"op":"mcm","clk":"5306482814","pt":1646099283843,"mc":[{"id":"1.195395419","rc":[{"atb":[[1.02,3.28]],"id":43154449}],"con":true,"img":false}]}
{"op":"mcm","clk":"5306482816","pt":1646099283946,"mc":[{"id":"1.195395419","rc":[{"atl":[[3.55,0]],"id":43154449}],"con":true,"img":false}]}
{"op":"mcm","clk":"5306482821","pt":1646099284048,"mc":[{"id":"1.195395419","rc":[{"atb":[[5.8,15.62]],"id":43154448},{"atl":[[5.1,18.29]],"id":43154449},{"atb":[[9.6,8.72]],"id":43154446}],"con":true,"img":false}]}
{"op":"mcm","clk":"5306482826","pt":1646099284102,"mc":[{"id":"1.195395419","rc":[{"atl":[[3.15,4.32]],"id":43154449}],"con":true,"img":false}]}
{"op":"mcm","clk":"5306482828","pt":1646099284255,"mc":[{"id":"1.195395419","rc":[{"atb":[[3.9,0]],"id":43154448},{"atl":[[12,2]],"id":43154448}],"con":true,"img":false}]}
{"op":"mcm","clk":"5306482852","pt":1646099284821,"mc":[{"id":"1.195395419","rc":[{"atl":[[3.25,0]],"id":43154449}],"con":true,"img":false}]}
{"op":"mcm","clk":"5306482858","pt":1646099284925,"mc":[{"id":"1.195395419","rc":[{"atb":[[3.4,0]],"id":42248828}],"con":true,"img":false}]}
{"op":"mcm","clk":"5306482864","pt":1646099285026,"mc":[{"id":"1.195395419","rc":[{"atl":[[3.15,10.81]],"id":43154449}],"con":true,"img":false}]}
{"op":"mcm","clk":"5306482872","pt":1646099285233,"mc":[{"id":"1.195395419","rc":[{"atb":[[8.2,3.02]],"id":42352031},{"atl":[[3.15,16.6]],"id":43154449}],"con":true,"img":false}]}
{"op":"mcm","clk":"5306482878","pt":1646099285335,"mc":[{"id":"1.195395419","rc":[{"atb":[[8.4,2]],"id":42352031},{"atb":[[1.01,2]],"id":42248828}],"con":true,"img":false}]}
{"op":"mcm","clk":"5306482885","pt":1646099285437,"mc":[{"id":"1.195395419","rc":[{"atb":[[8,0.13]],"id":42352031},{"atb":[[2.68,2.89]],"id":42248828}],"con":true,"img":false}]}
{"op":"mcm","clk":"5306482892","pt":1646099285540,"mc":[{"id":"1.195395419","rc":[{"atl":[[3.1,3.38]],"id":43154449}],"con":true,"img":false}]}
{"op":"mcm","clk":"5306482907","pt":1646099285744,"mc":[{"id":"1.195395419","rc":[{"atb":[[7.4,4.82]],"id":42352031}],"con":true,"img":false}]}
{"op":"mcm","clk":"5306482984","pt":1646099287338,"mc":[{"id":"1.195395419","rc":[{"atb":[[1.01,5.24],[9.8,0]],"id":42352031}],"con":true,"img":false}]}
{"op":"mcm","clk":"5306482988","pt":1646099287441,"mc":[{"id":"1.195395419","rc":[{"atb":[[1.01,4.42]],"id":42352031},{"atb":[[2.68,5.79]],"id":42248828},{"atb":[[20,0],[1.02,1.67]],"id":42413752},{"atb":[[18,0],[1.02,1.67]],"id":43154446}],"con":true,"img":false}]}
{"op":"mcm","clk":"5306482993","pt":1646099287544,"mc":[{"id":"1.195395419","rc":[{"atb":[[3.6,2.5]],"id":42248828}],"con":true,"img":false}]}
{"op":"mcm","clk":"5306482999","pt":1646099287648,"mc":[{"id":"1.195395419","rc":[{"atb":[[1.01,3.57]],"id":42352031}],"con":true,"img":false}]}
{"op":"mcm","clk":"5306483005","pt":1646099287751,"mc":[{"id":"1.195395419","rc":[{"atb":[[8.6,0.85]],"id":42352031}],"con":true,"img":false}]}
{"op":"mcm","clk":"5306483017","pt":1646099287956,"mc":[{"id":"1.195395419","rc":[{"atb":[[1.02,0.37]],"id":42413752},{"atb":[[1.02,0.44]],"id":43154446}],"con":true,"img":false}]}
{"op":"mcm","clk":"5306483041","pt":1646099288324,"mc":[{"id":"1.195395419","rc":[{"atb":[[7.4,1.28]],"id":42352031},{"atb":[[1.02,0]],"id":42413752},{"atb":[[2.62,0]],"id":43154449}],"con":true,"img":false}]}
{"op":"mcm","clk":"5306483047","pt":1646099288424,"mc":[{"id":"1.195395419","rc":[{"atb":[[22,0.37]],"id":42413752}],"con":true,"img":false}]}
{"op":"mcm","clk":"5306483055","pt":1646099288531,"mc":[{"id":"1.195395419","rc":[{"atb":[[1.02,0]],"id":43154446}],"con":true,"img":false}]}
{"op":"mcm","clk":"5306483063","pt":1646099288629,"mc":[{"id":"1.195395419","rc":[{"atb":[[19,0.44]],"id":43154446}],"con":true,"img":false}]}
{"op":"mcm","clk":"5306483077","pt":1646099288938,"mc":[{"id":"1.195395419","rc":[{"atl":[[24,9]],"id":42352031},{"atb":[[2.42,52.82]],"id":43154447}],"con":true,"img":false}]}
{"op":"mcm","clk":"5306483131","pt":1646099290020,"mc":[{"id":"1.195395419","rc":[{"atb":[[8.8,2.5]],"id":42352031}],"con":true,"img":false}]}
{"op":"mcm","clk":"5306483137","pt":1646099290122,"mc":[{"id":"1.195395419","rc":[{"atb":[[8.4,0],[8.8,4.5]],"id":42352031}],"con":true,"img":false}]}
{"op":"mcm","clk":"5306483145","pt":1646099290224,"mc":[{"id":"1.195395419","rc":[{"atb":[[8.4,2],[8.8,2.5]],"id":42352031},{"atl":[[19.5,1.08]],"id":42352031},{"atb":[[2.34,46.79]],"id":43154447}],"con":true,"img":false}]}
{"op":"mcm","clk":"5306483207","pt":1646099291529,"mc":[{"id":"1.195395419","rc":[{"atl":[[3.15,10.81]],"id":43154449}],"con":true,"img":false}]}
{"op":"mcm","clk":"5306483332","pt":1646099294042,"mc":[{"id":"1.195395419","rc":[{"atb":[[5.6,27.17]],"id":43154448},{"atl":[[5.3,29.07]],"id":43154449},{"atb":[[9.2,15.24]],"id":43154446}],"con":true,"img":false}]}
{"op":"mcm","clk":"5306483346","pt":1646099294349,"mc":[{"id":"1.195395419","rc":[{"atl":[[17,3.51]],"id":42352031},{"atl":[[4.9,2.53]],"id":42248828},{"atl":[[50,0.07]],"id":42413752},{"atl":[[40,0]],"id":43154446}],"con":true,"img":false}]}
{"op":"mcm","clk":"5306483351","pt":1646099294451,"mc":[{"id":"1.195395419","rc":[{"atb":[[8.4,0],[8.8,4.5]],"id":42352031},{"atl":[[1000,1.21]],"id":42352031},{"atl":[[1000,1.32]],"id":42248828},{"atl":[[1000,1.35]],"id":42413752},{"atl":[[42,2],[44,2.33],[1000,1.37]],"id":43154446}],"con":true,"img":false}]}
{"op":"mcm","clk":"5306483356","pt":1646099294554,"mc":[{"id":"1.195395419","rc":[{"atb":[[8.4,2],[8.8,2.5]],"id":42352031},{"atl":[[42,0],[44,4.33]],"id":43154446}],"con":true,"img":false}]}
{"op":"mcm","clk":"5306483362","pt":1646099294656,"mc":[{"id":"1.195395419","rc":[{"atb":[[8.2,0.44],[8.4,0],[8.8,4.5]],"id":42352031}],"con":true,"img":false}]}
{"op":"mcm","clk":"5306483486","pt":1646099297229,"mc":[{"id":"1.195395419","rc":[{"atl":[[3.15,4.32]],"id":43154449}],"con":true,"img":false}]}
{"op":"mcm","clk":"5306483502","pt":1646099297432,"mc":[{"id":"1.195395419","rc":[{"atl":[[3.05,6.49]],"id":43154449}],"con":true,"img":false}]}
{"op":"mcm","clk":"5306483510","pt":1646099297536,"mc":[{"id":"1.195395419","rc":[{"atb":[[7.6,3.42]],"id":42352031}],"con":true,"img":false}]}
{"op":"mcm","clk":"5306483526","pt":1646099297944,"mc":[{"id":"1.195395419","rc":[{"atl":[[3.05,9.02]],"id":43154449},{"atb":[[16,0]],"id":43154446}],"con":true,"img":false}]}
{"op":"mcm","clk":"5306483550","pt":1646099298559,"mc":[{"id":"1.195395419","rc":[{"atl":[[3.1,0]],"id":43154449}],"con":true,"img":false}]}
{"op":"mcm","clk":"5306483573","pt":1646099298972,"mc":[{"id":"1.195395419","rc":[{"atb":[[2.38,90.58]],"id":43154447}],"con":true,"img":false}]}
{"op":"mcm","clk":"5306483606","pt":1646099299438,"mc":[{"id":"1.195395419","rc":[{"atb":[[2.68,2.89]],"id":42248828}],"con":true,"img":false}]}
{"op":"mcm","clk":"5306483643","pt":1646099300255,"mc":[{"id":"1.195395419","rc":[{"atl":[[21,2.5]],"id":42352031}],"con":true,"img":false}]}
{"op":"mcm","clk":"5306483696","pt":1646099301130,"mc":[{"id":"1.195395419","rc":[{"atb":[[7.8,10.13]],"id":42352031}],"con":true,"img":false}]}
{"op":"mcm","clk":"5306483723","pt":1646099301851,"mc":[{"id":"1.195395419","rc":[{"atb":[[11,0],[1.02,4.22]],"id":43154448}],"con":true,"img":false}]}
{"op":"mcm","clk":"5306483740","pt":1646099302055,"mc":[{"id":"1.195395419","rc":[{"atb":[[1.02,2.31]],"id":43154448}],"con":true,"img":false}]}
{"op":"mcm","clk":"5306483746","pt":1646099302158,"mc":[{"id":"1.195395419","rc":[{"atb":[[1.02,1.99]],"id":43154448},{"atl":[[11.5,3]],"id":43154448}],"con":true,"img":false}]}
{"op":"mcm","clk":"5306483754","pt":1646099302261,"mc":[{"id":"1.195395419","rc":[{"atb":[[10.5,0.32]],"id":43154448},{"atl":[[13,0],[13.5,0]],"id":43154448}],"con":true,"img":false}]}
{"op":"mcm","clk":"5306483764","pt":1646099302466,"mc":[{"id":"1.195395419","rc":[{"atl":[[20,0],[22,5.68],[24,5.74]],"id":42352031},{"atb":[[4,0]],"id":43154448},{"atl":[[13,3]],"id":43154448}],"con":true,"img":false}]}
{"op":"mcm","clk":"5306483843","pt":1646099303960,"mc":[{"id":"1.195395419","rc":[{"atb":[[3.6,0]],"id":42248828}],"con":true,"img":false}]}
{"op":"mcm","clk":"5306483869","pt":1646099304474,"mc":[{"id":"1.195395419","rc":[{"atb":[[16,2.57]],"id":43154446}],"con":true,"img":false}]}
{"op":"mcm","clk":"5306483895","pt":1646099304937,"mc":[{"id":"1.195395419","rc":[{"atb":[[7.6,0]],"id":42352031}],"con":true,"img":false}]}
{"op":"mcm","clk":"5306483908","pt":1646099305245,"mc":[{"id":"1.195395419","rc":[{"atb":[[15,0]],"id":43154446}],"con":true,"img":false}]}
{"op":"mcm","clk":"5306483913","pt":1646099305347,"mc":[{"id":"1.195395419","rc":[{"atb":[[17,3.66]],"id":43154446}],"con":true,"img":false}]}
{"op":"mcm","clk":"5306483918","pt":1646099305449,"mc":[{"id":"1.195395419","rc":[{"atb":[[2.68,5.78]],"id":42248828}],"con":true,"img":false}]}
{"op":"mcm","clk":"5306484103","pt":1646099309668,"mc":[{"id":"1.195395419","rc":[{"atl":[[3.05,2.53]],"id":43154449}],"con":true,"img":false}]}
{"op":"mcm","clk":"5306484110","pt":1646099309874,"mc":[{"id":"1.195395419","rc":[{"atl":[[3,6.49]],"id":43154449}],"con":true,"img":false}]}
{"op":"mcm","clk":"5306484117","pt":1646099309976,"mc":[{"id":"1.195395419","rc":[{"atb":[[8,3.36]],"id":42352031}],"con":true,"img":false}]}
{"op":"mcm","clk":"5306484129","pt":1646099310284,"mc":[{"id":"1.195395419","rc":[{"atl":[[23,3.41]],"id":42352031}],"con":true,"img":false}]}
{"op":"mcm","clk":"5306484147","pt":1646099310750,"mc":[{"id":"1.195395419","rc":[{"atb":[[7.8,0]],"id":42352031},{"atb":[[16,0]],"id":43154446}],"con":true,"img":false}]}
{"op":"mcm","clk":"5306484165","pt":1646099311262,"mc":[{"id":"1.195395419","rc":[{"atb":[[17,2.08]],"id":43154446}],"con":true,"img":false}]}
{"op":"mcm","clk":"5306484170","pt":1646099311364,"mc":[{"id":"1.195395419","rc":[{"atb":[[1.01,1.57]],"id":43154446}],"con":true,"img":false}]}
{"op":"mcm","clk":"5306484287","pt":1646099313886,"mc":[{"id":"1.195395419","rc":[{"atl":[[3.05,0]],"id":43154449}],"con":true,"img":false}]}
{"op":"mcm","clk":"5306484312","pt":1646099314349,"mc":[{"id":"1.195395419","rc":[{"atl":[[3.15,0]],"id":43154449}],"con":true,"img":false}]}
{"op":"mcm","clk":"5306484333","pt":1646099314962,"mc":[{"id":"1.195395419","rc":[{"atb":[[8,0.13]],"id":42352031}],"con":true,"img":false}]}
{"op":"mcm","clk":"5306484403","pt":1646099316455,"mc":[{"id":"1.195395419","rc":[{"atl":[[46,0]],"id":43154446}],"con":true,"img":false}]}
{"op":"mcm","clk":"5306484409","pt":1646099316555,"mc":[{"id":"1.195395419","rc":[{"atl":[[42,2.7],[44,2],[48,2.13],[1000,3.61]],"id":43154446}],"con":true,"img":false}]}
{"op":"mcm","clk":"5306484418","pt":1646099316759,"mc":[{"id":"1.195395419","rc":[{"atl":[[1000,1.46]],"id":43154446}],"con":true,"img":false}]}
{"op":"mcm","clk":"5306484420","pt":1646099316861,"mc":[{"id":"1.195395419","rc":[{"atl":[[1000,1.37]],"id":43154446}],"con":true,"img":false}]}
{"op":"mcm","clk":"5306484423","pt":1646099316964,"mc":[{"id":"1.195395419","rc":[{"atl":[[55,0.08]],"id":43154446}],"con":true,"img":false}]}
{"op":"mcm","clk":"5306484426","pt":1646099317064,"mc":[{"id":"1.195395419","rc":[{"atb":[[16,2.57]],"id":43154446}],"con":true,"img":false}]}
{"op":"mcm","clk":"5306484432","pt":1646099317270,"mc":[{"id":"1.195395419","rc":[{"atl":[[38,0],[1000,3.04]],"id":43154446}],"con":true,"img":false}]}
{"op":"mcm","clk":"5306484439","pt":1646099317475,"mc":[{"id":"1.195395419","rc":[{"atl":[[1000,1.59]],"id":43154446}],"con":true,"img":false}]}
{"op":"mcm","clk":"5306484465","pt":1646099317887,"mc":[{"id":"1.195395419","rc":[{"atb":[[2.74,13]],"id":42248828},{"atb":[[2.62,2.32]],"id":43154449},{"atb":[[1.01,0]],"id":43154446}],"con":true,"img":false}]}
{"op":"mcm","clk":"5306484472","pt":1646099317989,"mc":[{"id":"1.195395419","rc":[{"atb":[[17,3.66]],"id":43154446},{"atl":[[1000,1.37]],"id":43154446}],"con":true,"img":false}]}
{"op":"mcm","clk":"5306484478","pt":1646099318092,"mc":[{"id":"1.195395419","rc":[{"atl":[[40,0.21]],"id":43154446}],"con":true,"img":false}]}
{"op":"mcm","clk":"5306484500","pt":1646099318456,"mc":[{"id":"1.195395419","rc":[{"atb":[[2.68,4.24]],"id":42248828}],"con":true,"img":false}]}
{"op":"mcm","clk":"5306484506","pt":1646099318558,"mc":[{"id":"1.195395419","rc":[{"atb":[[2.76,1.54]],"id":42248828},{"atl":[[42,0]],"id":43154446}],"con":true,"img":false}]}
{"op":"mcm","clk":"5306484511","pt":1646099318659,"mc":[{"id":"1.195395419","rc":[{"atl":[[44,0],[48,6.83]],"id":43154446}],"con":true,"img":false}]}
{"op":"mcm","clk":"5306484523","pt":1646099318968,"mc":[{"id":"1.195395419","rc":[{"atb":[[2.68,2.89]],"id":42248828}],"con":true,"img":false}]}
{"op":"mcm","clk":"5306484526","pt":1646099319070,"mc":[{"id":"1.195395419","rc":[{"atb":[[2.76,2.89]],"id":42248828}],"con":true,"img":false}]}
{"op":"mcm","clk":"5306484544","pt":1646099319481,"mc":[{"id":"1.195395419","rc":[{"atl":[[2.98,3.38]],"id":43154449}],"con":true,"img":false}]}
{"op":"mcm","clk":"5306484580","pt":1646099320355,"mc":[{"id":"1.195395419","rc":[{"atl":[[25,5.21]],"id":42352031}],"con":true,"img":false}]}
{"op":"mcm","clk":"5306484583","pt":1646099320456,"mc":[{"id":"1.195395419","rc":[{"atb":[[7.8,10.13]],"id":42352031},{"atb":[[2.74,42.94],[2.68,0]],"id":42248828}],"con":true,"img":false}]}
{"op":"mcm","clk":"5306484585","pt":1646099320561,"mc":[{"id":"1.195395419","rc":[{"atl":[[4,4.86]],"id":43154449}],"con":true,"img":false}]}
{"op":"mcm","clk":"5306484593","pt":1646099320765,"mc":[{"id":"1.195395419","rc":[{"atb":[[2.6,0]],"id":43154449}],"con":true,"img":false}]}
{"op":"mcm","clk":"5306484639","pt":1646099322156,"mc":[{"id":"1.195395419","rc":[{"atl":[[3,0]],"id":43154449}],"con":true,"img":false}]}
{"op":"mcm","clk":"5306484665","pt":1646099322772,"mc":[{"id":"1.195395419","rc":[{"atb":[[2.74,29.94]],"id":42248828},{"atb":[[2.62,0]],"id":43154449}],"con":true,"img":false}]}
{"op":"mcm","clk":"5306484687","pt":1646099323184,"mc":[{"id":"1.195395419","rc":[{"atb":[[1.02,1.29]],"id":43154449}],"con":true,"img":false}]}
{"op":"mcm","clk":"5306484694","pt":1646099323287,"mc":[{"id":"1.195395419","rc":[{"atb":[[2.58,1.99]],"id":43154449}],"con":true,"img":false}]}
{"op":"mcm","clk":"5306484703","pt":1646099323491,"mc":[{"id":"1.195395419","rc":[{"atb":[[2.76,5.78]],"id":42248828}],"con":true,"img":false}]}
{"op":"mcm","clk":"5306484713","pt":1646099323698,"mc":[{"id":"1.195395419","rc":[{"atb":[[2.58,4.92]],"id":43154449}],"con":true,"img":false}]}
{"op":"mcm","clk":"5306484730","pt":1646099324008,"mc":[{"id":"1.195395419","rc":[{"atb":[[2.74,0]],"id":42248828},{"atb":[[16,0]],"id":43154446}],"con":true,"img":false}]}
{"op":"mcm","clk":"5306484758","pt":1646099324471,"mc":[{"id":"1.195395419","rc":[{"spn":12.9,"spf":1.0,"id":42352031},{"atb":[[2.76,4.24]],"id":42248828},{"spn":4.05,"spf":1.0,"id":42248828},{"spn":35.0,"spf":1.0,"id":42413752},{"spn":8.99,"spf":1.0,"id":43154448},{"spn":2.59,"spf":1.0,"id":43154449},{"atb":[[17,2.08]],"id":43154446},{"spn":29.5,"spf":1.0,"id":43154446}],"con":true,"img":false}]}
{"op":"mcm","clk":"5306484765","pt":1646099324575,"mc":[{"id":"1.195395419","rc":[{"atb":[[1.01,3.54]],"id":42248828},{"atb":[[1.01,1.57]],"id":43154446}],"con":true,"img":false}]}
{"op":"mcm","clk":"5306484789","pt":1646099324985,"mc":[{"id":"1.195395419","rc":[{"atb":[[2.76,2.89]],"id":42248828}],"con":true,"img":false}]}
{"op":"mcm","clk":"5306484795","pt":1646099325088,"mc":[{"id":"1.195395419","rc":[{"atb":[[1.01,4.89]],"id":42248828}],"con":true,"img":false}]}
{"op":"mcm","clk":"5306484888","pt":1646099327397,"mc":[{"id":"1.195395419","rc":[{"atl":[[2.98,0]],"id":43154449}],"con":true,"img":false}]}
{"op":"mcm","clk":"5306484901","pt":1646099327705,"mc":[{"id":"1.195395419","rc":[{"atb":[[1.02,0]],"id":43154449}],"con":true,"img":false}]}
{"op":"mcm","clk":"5306484906","pt":1646099327762,"mc":[{"id":"1.195395419","rc":[{"atb":[[2.58,6.21]],"id":43154449}],"con":true,"img":false}]}
{"op":"mcm","clk":"5306484910","pt":1646099327864,"mc":[{"id":"1.195395419","rc":[{"atl":[[4.8,4.32]],"id":42248828},{"atl":[[3.95,4.32]],"id":43154449}],"con":true,"img":false}]}
{"op":"mcm","clk":"5306484915","pt":1646099327967,"mc":[{"id":"1.195395419","rc":[{"atl":[[1000,0]],"id":42352031},{"atl":[[1000,0]],"id":42248828},{"atb":[[10,2]],"id":43154448},{"atb":[[1.01,2]],"id":43154449},{"atl":[[1000,0]],"id":43154449},{"atl":[[1000,0]],"id":43154446}],"con":true,"img":false}]}
{"op":"mcm","clk":"5306484923","pt":1646099328069,"mc":[{"id":"1.195395419","rc":[{"atl":[[16.5,1.21]],"id":42352031},{"atl":[[4.8,5.64]],"id":42248828},{"atb":[[10,0],[9.6,7.91],[9.8,2]],"id":43154448},{"atb":[[2.6,1.58]],"id":43154449},{"atl":[[3.95,5.55]],"id":43154449},{"atl":[[46,1.37]],"id":43154446}],"con":true,"img":false}]}
{"op":"mcm","clk":"5306484928","pt":1646099328172,"mc":[{"id":"1.195395419","rc":[{"atl":[[4.9,0]],"id":42248828},{"atb":[[1.07,1.67]],"id":41642357}],"con":true,"img":false}]}
{"op":"mcm","clk":"5306484942","pt":1646099328375,"mc":[{"id":"1.195395419","rc":[{"atl":[[4.7,2.53]],"id":42248828},{"atb":[[1.07,0.1]],"id":41642357}],"con":true,"img":false}]}
{"op":"mcm","clk":"5306484953","pt":1646099328581,"mc":[{"id":"1.195395419","rc":[{"atb":[[1.07,0]],"id":41642357},{"atb":[[1.2,2.23]],"id":43154446}],"con":true,"img":false}]}
{"op":"mcm","clk":"5306484961","pt":1646099328682,"mc":[{"id":"1.195395419","rc":[{"atb":[[75,0.1]],"id":41642357}],"con":true,"img":false}]}
{"op":"mcm","clk":"5306484967","pt":1646099328784,"mc":[{"id":"1.195395419","rc":[{"atl":[[3.9,6.49]],"id":43154449}],"con":true,"img":false}]}
{"op":"mcm","clk":"5306484974","pt":1646099328888,"mc":[{"id":"1.195395419","rc":[{"atb":[[1.2,1.61]],"id":43154446}],"con":true,"img":false}]}
{"op":"mcm","clk":"5306484977","pt":1646099328990,"mc":[{"id":"1.195395419","rc":[{"atb":[[2.9,2.5]],"id":42248828},{"atb":[[2.62,2.5]],"id":43154449}],"con":true,"img":false}]}
{"op":"mcm","clk":"5306484988","pt":1646099329195,"mc":[{"id":"1.195395419","rc":[{"atl":[[4.8,4.32]],"id":42248828},{"atl":[[3.95,4.32]],"id":43154449},{"atb":[[1.2,0]],"id":43154446}],"con":true,"img":false}]}
{"op":"mcm","clk":"5306484994","pt":1646099329299,"mc":[{"id":"1.195395419","rc":[{"atl":[[4.6,1.32]],"id":42248828},{"atb":[[2.6,0]],"id":43154449},{"atl":[[3.85,1.22]],"id":43154449},{"atb":[[15,1.61]],"id":43154446}],"con":true,"img":false}]}
{"op":"mcm","clk":"5306484999","pt":1646099329401,"mc":[{"id":"1.195395419","rc":[{"atb":[[2.64,1.58]],"id":43154449}],"con":true,"img":false}]}
{"op":"mcm","clk":"5306485006","pt":1646099329505,"mc":[{"id":"1.195395419","rc":[{"atb":[[2.8,7.39]],"id":42248828},{"atb":[[2.6,3.71],[2.58,2.93]],"id":43154449}],"con":true,"img":false}]}
{"op":"mcm","clk":"5306485010","pt":1646099329556,"mc":[{"id":"1.195395419","rc":[{"atb":[[2.62,3.8],[1.02,1.99]],"id":43154449}],"con":true,"img":false}]}
{"op":"mcm","clk":"5306485035","pt":1646099330078,"mc":[{"id":"1.195395419","rc":[{"atb":[[1.01,3.54]],"id":42248828}],"con":true,"img":false}]}
{"op":"mcm","clk":"5306485039","pt":1646099330176,"mc":[{"id":"1.195395419","rc":[{"atb":[[2.8,8.75]],"id":42248828}],"con":true,"img":false}]}
{"op":"mcm","clk":"5306485059","pt":1646099330484,"mc":[{"id":"1.195395419","rc":[{"atb":[[2.9,0],[2.78,14.36]],"id":42248828},{"atb":[[2.62,1.29]],"id":43154449},{"atb":[[16,2.57]],"id":43154446}],"con":true,"img":false}]}
{"op":"mcm","clk":"5306485089","pt":1646099331098,"mc":[{"id":"1.195395419","rc":[{"atb":[[1.01,2]],"id":42248828},{"atb":[[2.64,0]],"id":43154449}],"con":true,"img":false}]}
{"op":"mcm","clk":"5306485094","pt":1646099331202,"mc":[{"id":"1.195395419","rc":[{"atb":[[2.82,1.54]],"id":42248828},{"atb":[[2.62,2.88]],"id":43154449}],"con":true,"img":false}]}
{"op":"mcm","clk":"5306485134","pt":1646099331974,"mc":[{"id":"1.195395419","rc":[{"atb":[[10.5,0],[1.02,4.22]],"id":43154448}],"con":true,"img":false}]}
{"op":"mcm","clk":"5306485156","pt":1646099332383,"mc":[{"id":"1.195395419","rc":[{"atb":[[1.02,2.31]],"id":43154448}],"con":true,"img":false}]}
{"op":"mcm","clk":"5306485162","pt":1646099332487,"mc":[{"id":"1.195395419","rc":[{"atl":[[11,2],[13,0]],"id":43154448}],"con":true,"img":false}]}
{"op":"mcm","clk":"5306485178","pt":1646099332796,"mc":[{"id":"1.195395419","rc":[{"atb":[[1.02,1.99]],"id":43154448}],"con":true,"img":false}]}
{"op":"mcm","clk":"5306485183","pt":1646099332899,"mc":[{"id":"1.195395419","rc":[{"atb":[[10,0.32]],"id":43154448}],"con":true,"img":false}]}
{"op":"mcm","clk":"5306485187","pt":1646099333002,"mc":[{"id":"1.195395419","rc":[{"atb":[[2.94,2.5]],"id":42248828},{"atb":[[2.64,2.5]],"id":43154449}],"con":true,"img":false}]}
{"op":"mcm","clk":"5306485211","pt":1646099333465,"mc":[{"id":"1.195395419","rc":[{"atb":[[2.62,1.29]],"id":43154449}],"con":true,"img":false}]}
{"op":"mcm","clk":"5306485217","pt":1646099333568,"mc":[{"id":"1.195395419","rc":[{"atb":[[2.8,1.35]],"id":42248828},{"atb":[[2.6,0],[2.66,1.58]],"id":43154449},{"atb":[[15,0]],"id":43154446}],"con":true,"img":false}]}
{"op":"mcm","clk":"5306485223","pt":1646099333671,"mc":[{"id":"1.195395419","rc":[{"atl":[[4,0]],"id":43154449}],"con":true,"img":false}]}
{"op":"mcm","clk":"5306485241","pt":1646099333977,"mc":[{"id":"1.195395419","rc":[{"atb":[[2.62,0]],"id":43154449}],"con":true,"img":false}]}
{"op":"mcm","clk":"5306485246","pt":1646099334090,"mc":[{"id":"1.195395419","rc":[{"atb":[[2.64,3.8]],"id":43154449}],"con":true,"img":false}]}
{"op":"mcm","clk":"5306485293","pt":1646099334902,"mc":[{"id":"1.195395419","rc":[{"atb":[[2.64,2.5]],"id":43154449}],"con":true,"img":false}]}
{"op":"mcm","clk":"5306485301","pt":1646099335006,"mc":[{"id":"1.195395419","rc":[{"atb":[[2.58,4.22]],"id":43154449}],"con":true,"img":false}]}
{"op":"mcm","clk":"5306485326","pt":1646099335520,"mc":[{"id":"1.195395419","rc":[{"atb":[[2.94,0],[2.76,0]],"id":42248828},{"atb":[[2.64,0]],"id":43154449}],"con":true,"img":false}]}
{"op":"mcm","clk":"5306485342","pt":1646099335777,"mc":[{"id":"1.195395419","rc":[{"atb":[[2.82,0]],"id":42248828},{"atl":[[4.7,0]],"id":42248828},{"atb":[[2.58,1.29],[2.66,0]],"id":43154449}],"con":true,"img":false}]}
{"op":"mcm","clk":"5306485349","pt":1646099335930,"mc":[{"id":"1.195395419","rc":[{"atb":[[2.8,2.89]],"id":42248828},{"atb":[[2.6,1.58]],"id":43154449}],"con":true,"img":false}]}
{"op":"mcm","clk":"5306485382","pt":1646099336406,"mc":[{"id":"1.195395419","rc":[{"atl":[[4.6,0]],"id":42248828}],"con":true,"img":false}]}
{"op":"mcm","clk":"5306485387","pt":1646099336495,"mc":[{"id":"1.195395419","rc":[{"atl":[[4.7,1.32]],"id":42248828},{"atb":[[2.6,0]],"id":43154449}],"con":true,"img":false}]}
{"op":"mcm","clk":"5306485393","pt":1646099336601,"mc":[{"id":"1.195395419","rc":[{"atb":[[2.58,2.88]],"id":43154449}],"con":true,"img":false}]}
{"op":"mcm","clk":"5306485398","pt":1646099336702,"mc":[{"id":"1.195395419","rc":[{"atl":[[4.7,3.85]],"id":42248828}],"con":true,"img":false}]}
{"op":"mcm","clk":"5306485415","pt":1646099337011,"mc":[{"id":"1.195395419","rc":[{"atb":[[2.78,0]],"id":42248828}],"con":true,"img":false}]}
{"op":"mcm","clk":"5306485432","pt":1646099337167,"mc":[{"id":"1.195395419","rc":[{"atl":[[4.7,1.32]],"id":42248828}],"con":true,"img":false}]}
{"op":"mcm","clk":"5306485437","pt":1646099337270,"mc":[{"id":"1.195395419","rc":[{"atb":[[2.8,1.54]],"id":42248828}],"con":true,"img":false}]}
{"op":"mcm","clk":"5306485444","pt":1646099337374,"mc":[{"id":"1.195395419","rc":[{"atb":[[2.68,1.35]],"id":42248828}],"con":true,"img":false}]}
{"op":"mcm","clk":"5306485461","pt":1646099337578,"mc":[{"id":"1.195395419","rc":[{"atb":[[2.8,0]],"id":42248828},{"atl":[[4.1,0]],"id":43154449}],"con":true,"img":false}]}
{"op":"mcm","clk":"5306485466","pt":1646099337682,"mc":[{"id":"1.195395419","rc":[{"atb":[[2.68,2.89]],"id":42248828},{"atl":[[4.3,18.71]],"id":43154449}],"con":true,"img":false}]}
{"op":"mcm","clk":"5306485488","pt":1646099338091,"mc":[{"id":"1.195395419","rc":[{"atb":[[2.98,2.5]],"id":42248828},{"atb":[[2.62,2.5]],"id":43154449}],"con":true,"img":false}]}
{"op":"mcm","clk":"5306485507","pt":1646099338502,"mc":[{"id":"1.195395419","rc":[{"atb":[[2.58,1.58]],"id":43154449}],"con":true,"img":false}]}
{"op":"mcm","clk":"5306485511","pt":1646099338605,"mc":[{"id":"1.195395419","rc":[{"atb":[[2.62,3.8]],"id":43154449}],"con":true,"img":false}]}
