{"op":"mcm","clk":"5345985299","pt":1646174444261,"mc":[{"id":"1.195453623","marketDefinition":{"bspMarket":true,"turnInPlayEnabled":false,"persistenceEnabled":false,"marketBaseRate":7.0,"eventId":"31272494","eventTypeId":"4339","numberOfWinners":1,"bettingType":"ODDS","marketType":"WIN","marketTime":"2022-03-02T10:51:00.000Z","suspendTime":"2022-03-02T10:51:00.000Z","bspReconciled":false,"complete":true,"inPlay":false,"crossMatching":false,"runnersVoidable":false,"numberOfActiveRunners":7,"betDelay":0,"status":"OPEN","runners":[{"status":"ACTIVE","sortPriority":1,"id":39658516,"name":"1. Jeza You Beauty"},{"status":"ACTIVE","sortPriority":2,"id":36074465,"name":"2. Whistling Bullet"},{"status":"ACTIVE","sortPriority":3,"id":41788482,"name":"3. Flossie Ann"},{"status":"ACTIVE","sortPriority":4,"id":37447009,"name":"4. Annie Rose"},{"status":"ACTIVE","sortPriority":5,"id":28222454,"name":"5. She Wiggles"},{"status":"ACTIVE","sortPriority":6,"id":37286329,"name":"6. Dr Danika"},{"status":"ACTIVE","sortPriority":7,"id":42513983,"name":"8. Magic Mist"}],"regulators":["MR_INT"],"venue":"Traralgon","countryCode":"AU","discountAllowed":true,"timezone":"Australia/Sydney","openDate":"2022-03-02T08:31:00.000Z","version":4382425381,"name":"R8 500m Gr5","eventName":"Traralgon (AUS) 2nd Mar"},"rc":[],"con":true,"img":false}]}
{"op":"mcm","clk":"5346059516","pt":1646175786519,"mc":[{"id":"1.195453623","rc":[{"atb":[[6.4,15.12],[7.4,6.37],[5.2,38.88],[5.7,17.37],[9.4,4.86]],"id":37447009},{"atl":[[80,1.68],[160,1.25],[55,2.46],[110,1.82]],"id":37447009},{"spn":32.2,"spf":"NaN","id":37447009},{"atb":[[1.8,102.06],[1.85,48.03],[1.7,233.29],[1.95,42.97],[1.75,108.87]],"id":36074465},{"atl":[[5.6,43.38],[5.1,32.44],[4.6,36.95],[6.2,38.37]],"id":36074465},{"spn":3.27,"spf":"NaN","id":36074465},{"atb":[[3.45,16.66],[3.2,37.11],[2.88,86.86],[3.95,13.83],[2.98,41.24]],"id":41788482},{"atl":[[16,8.86],[18.5,11.4],[22,9.5],[13.5,10.64]],"id":41788482},{"spn":8.72,"spf":"NaN","id":41788482},{"atb":[[6.4,30.24],[7.4,12.75],[13.5,3.26],[8.4,11.03],[9.4,4.86]],"id":39658516},{"atl":[[260,0.77],[160,0.83],[210,0.95],[110,1.21]],"id":39658516},{"spn":61.75,"spf":"NaN","id":39658516},{"atb":[[2.4,116.65],[2.9,21.48],[2.5,54.43],[2.6,51.03],[2.7,24.01]],"id":42513983},{"atl":[[12,18.14],[9.8,22.67],[8.8,17.05],[7.8,19.56]],"id":42513983},{"spn":5.35,"spf":"NaN","id":42513983},{"atb":[[4,27.21],[4.5,11.66],[5.5,9.07],[3.5,65.32],[3.75,29.69]],"id":37286329},{"atl":[[34,6.04],[18.5,7.6],[22,6.33],[27,7.67]],"id":37286329},{"spn":12.0,"spf":"NaN","id":37286329},{"atb":[[18,2.4],[10.5,17.19],[26,1.63],[13,6.8],[15.5,5.62]],"id":28222454},{"atl":[[290,0.46],[340,0.58],[390,0.51],[240,0.55]],"id":28222454},{"spn":133.0,"spf":"NaN","id":28222454}],"con":true,"img":false}]}
{"op":"mcm","clk":"5346061998","pt":1646175839944,"mc":[{"id":"1.195453623","rc":[{"atb":[[6.4,0],[7.4,0],[5.2,0],[5.7,0],[9.4,0]],"id":37447009},{"atl":[[80,0],[160,0],[55,0],[110,0]],"id":37447009},{"atb":[[1.8,0],[1.85,0],[1.7,0],[1.95,0],[1.75,0]],"id":36074465},{"atl":[[5.6,0],[5.1,0],[4.6,0],[6.2,0]],"id":36074465},{"atb":[[3.45,0],[3.2,0],[2.88,0],[3.95,0],[2.98,0]],"id":41788482},{"atl":[[16,0],[18.5,0],[22,0],[13.5,0]],"id":41788482},{"atb":[[6.4,0],[7.4,0],[13.5,0],[8.4,0],[9.4,0]],"id":39658516},{"atl":[[260,0],[160,0],[210,0],[110,0]],"id":39658516},{"atb":[[2.4,0],[2.9,0],[2.5,0],[2.6,0],[2.7,0]],"id":42513983},{"atl":[[12,0],[9.8,0],[8.8,0],[7.8,0]],"id":42513983},{"atb":[[4,0],[4.5,0],[5.5,0],[3.5,0],[3.75,0]],"id":37286329},{"atl":[[34,0],[18.5,0],[22,0],[27,0]],"id":37286329},{"atb":[[18,0],[10.5,0],[26,0],[13,0],[15.5,0]],"id":28222454},{"atl":[[290,0],[340,0],[390,0],[240,0]],"id":28222454}],"con":true,"img":false}]}
{"op":"mcm","clk":"5346062228","pt":1646175844782,"mc":[{"id":"1.195453623","rc":[{"atb":[[6.4,15.12],[7.4,6.37],[5.2,38.88],[5.7,17.37],[9.4,4.86]],"id":37447009},{"atl":[[80,1.68],[160,1.25],[55,2.46],[110,1.82]],"id":37447009},{"atb":[[1.8,102.06],[1.85,48.03],[1.7,233.29],[1.95,42.97],[1.75,108.87]],"id":36074465},{"atl":[[5.6,43.38],[5.1,32.44],[4.6,36.95],[6.2,38.37]],"id":36074465},{"atb":[[3.45,16.66],[3.2,37.11],[2.88,86.86],[3.95,13.83],[2.98,41.24]],"id":41788482},{"atl":[[16,8.86],[18.5,11.4],[22,9.5],[13.5,10.64]],"id":41788482},{"atb":[[6.4,30.24],[7.4,12.75],[13.5,3.26],[8.4,11.03],[9.4,4.86]],"id":39658516},{"atl":[[260,0.77],[160,0.83],[210,0.95],[110,1.21]],"id":39658516},{"atb":[[2.4,116.65],[2.9,21.48],[2.5,54.43],[2.6,51.03],[2.7,24.01]],"id":42513983},{"atl":[[12,18.14],[9.8,22.67],[8.8,17.05],[7.8,19.56]],"id":42513983},{"atb":[[4,27.21],[4.5,11.66],[5.5,9.07],[3.5,65.32],[3.75,29.69]],"id":37286329},{"atl":[[34,6.04],[18.5,7.6],[22,6.33],[27,7.67]],"id":37286329},{"atb":[[18,2.4],[10.5,17.19],[26,1.63],[13,6.8],[15.5,5.62]],"id":28222454},{"atl":[[290,0.46],[340,0.58],[390,0.51],[240,0.55]],"id":28222454}],"con":true,"img":false}]}
{"op":"mcm","clk":"5346105175","pt":1646176602702,"mc":[{"id":"1.195453623","marketDefinition":{"bspMarket":true,"turnInPlayEnabled":false,"persistenceEnabled":false,"marketBaseRate":7.0,"eventId":"31272494","eventTypeId":"4339","numberOfWinners":1,"bettingType":"ODDS","marketType":"WIN","marketTime":"2022-03-02T10:51:00.000Z","suspendTime":"2022-03-02T10:51:00.000Z","bspReconciled":false,"complete":true,"inPlay":false,"crossMatching":false,"runnersVoidable":false,"numberOfActiveRunners":7,"betDelay":0,"status":"OPEN","runners":[{"status":"ACTIVE","sortPriority":1,"id":39658516,"name":"1. Jeza You Beauty"},{"status":"ACTIVE","sortPriority":2,"id":36074465,"name":"2. Whistling Bullet"},{"status":"ACTIVE","sortPriority":3,"id":41788482,"name":"3. Flossie Ann"},{"status":"ACTIVE","sortPriority":4,"id":37447009,"name":"4. Annie Rose"},{"status":"ACTIVE","sortPriority":5,"id":28222454,"name":"5. She Wiggles"},{"status":"ACTIVE","sortPriority":6,"id":37286329,"name":"6. Dr Danika"},{"status":"ACTIVE","sortPriority":7,"id":42513983,"name":"8. Magic Mist"}],"regulators":["MR_INT"],"venue":"Traralgon","countryCode":"AU","discountAllowed":true,"timezone":"Australia/Sydney","openDate":"2022-03-02T08:31:00.000Z","version":4382425381,"name":"R8 500m Gr5","eventName":"Traralgon (AUS) 2nd Mar"},"rc":[{"atb":[[6.4,15.12],[7.4,6.37],[5.2,38.88],[5.7,17.37],[9.4,4.86]],"id":37447009},{"atl":[[80,1.68],[160,1.25],[55,2.46],[110,1.82]],"id":37447009},{"spn":32.2,"spf":"NaN","id":37447009},{"atb":[[1.8,102.06],[1.85,48.03],[1.7,233.29],[1.95,42.97],[1.75,108.87]],"id":36074465},{"atl":[[5.6,43.38],[5.1,32.44],[4.6,36.95],[6.2,38.37]],"id":36074465},{"spn":3.27,"spf":"NaN","id":36074465},{"atb":[[3.45,16.66],[3.2,37.11],[2.88,86.86],[3.95,13.83],[2.98,41.24]],"id":41788482},{"atl":[[16,8.86],[18.5,11.4],[22,9.5],[13.5,10.64]],"id":41788482},{"spn":8.72,"spf":"NaN","id":41788482},{"atb":[[6.4,30.24],[7.4,12.75],[13.5,3.26],[8.4,11.03],[9.4,4.86]],"id":39658516},{"atl":[[260,0.77],[160,0.83],[210,0.95],[110,1.21]],"id":39658516},{"spn":61.75,"spf":"NaN","id":39658516},{"atb":[[2.4,116.65],[2.9,21.48],[2.5,54.43],[2.6,51.03],[2.7,24.01]],"id":42513983},{"atl":[[12,18.14],[9.8,22.67],[8.8,17.05],[7.8,19.56]],"id":42513983},{"spn":5.35,"spf":"NaN","id":42513983},{"atb":[[4,27.21],[4.5,11.66],[5.5,9.07],[3.5,65.32],[3.75,29.69]],"id":37286329},{"atl":[[34,6.04],[18.5,7.6],[22,6.33],[27,7.67]],"id":37286329},{"spn":12.0,"spf":"NaN","id":37286329},{"atb":[[18,2.4],[10.5,17.19],[26,1.63],[13,6.8],[15.5,5.62]],"id":28222454},{"atl":[[290,0.46],[340,0.58],[390,0.51],[240,0.55]],"id":28222454},{"spn":133.0,"spf":"NaN","id":28222454}],"con":true,"img":true}]}
{"op":"mcm","clk":"5346115817","pt":1646176767103,"mc":[{"id":"1.195453623","rc":[{"atb":[[6.4,0],[7.4,0],[5.2,0],[5.7,0],[9.4,0]],"id":37447009},{"atl":[[80,0],[160,0],[55,0],[110,0]],"id":37447009},{"spn":"NaN","spf":"NaN","id":37447009},{"atb":[[1.8,0],[1.85,0],[1.7,0],[1.95,0],[1.75,0]],"id":36074465},{"atl":[[5.6,0],[5.1,0],[4.6,0],[6.2,0]],"id":36074465},{"spn":"NaN","spf":"NaN","id":36074465},{"atb":[[3.45,0],[3.2,0],[2.88,0],[3.95,0],[2.98,0]],"id":41788482},{"atl":[[16,0],[18.5,0],[22,0],[13.5,0]],"id":41788482},{"spn":"NaN","spf":"NaN","id":41788482},{"atb":[[6.4,0],[7.4,0],[13.5,0],[8.4,0],[9.4,0]],"id":39658516},{"atl":[[260,0],[160,0],[210,0],[110,0]],"id":39658516},{"spn":"NaN","spf":"NaN","id":39658516},{"atb":[[4,0],[4.5,0],[5.5,0],[3.5,0],[3.75,0]],"id":37286329},{"atl":[[34,0],[18.5,0],[22,0],[27,0]],"id":37286329},{"spn":"NaN","spf":"NaN","id":37286329},{"atb":[[18,0],[10.5,0],[26,0],[13,0],[15.5,0]],"id":28222454},{"atl":[[290,0],[340,0],[390,0],[240,0]],"id":28222454},{"spn":"NaN","spf":"NaN","id":28222454}],"con":true,"img":false}]}
{"op":"mcm","clk":"5346116894","pt":1646176785836,"mc":[{"id":"1.195453623","rc":[{"atb":[[6.4,15.12],[7.4,6.37],[5.2,38.88],[5.7,17.37],[9.4,4.86]],"id":37447009},{"atl":[[80,1.68],[160,1.25],[55,2.46],[110,1.82]],"id":37447009},{"atb":[[1.8,102.06],[1.85,48.03],[1.7,233.29],[1.95,42.97],[1.75,108.87]],"id":36074465},{"atl":[[5.6,43.38],[5.1,32.44],[4.6,36.95],[6.2,38.37]],"id":36074465},{"atb":[[3.45,16.66],[3.2,37.11],[2.88,86.86],[3.95,13.83],[2.98,41.24]],"id":41788482},{"atl":[[16,8.86],[18.5,11.4],[22,9.5],[13.5,10.64]],"id":41788482},{"atb":[[6.4,30.24],[7.4,12.75],[13.5,3.26],[8.4,11.03],[9.4,4.86]],"id":39658516},{"atl":[[260,0.77],[160,0.83],[210,0.95],[110,1.21]],"id":39658516},{"atb":[[4,27.21],[4.5,11.66],[5.5,9.07],[3.5,65.32],[3.75,29.69]],"id":37286329},{"atl":[[34,6.04],[18.5,7.6],[22,6.33],[27,7.67]],"id":37286329},{"atb":[[32,1.31],[18,4.8],[21,2.04],[13,13.6],[15.5,5.62]],"id":28222454},{"atl":[[300,0.44],[350,0.38],[400,0.5],[450,0.44]],"id":28222454}],"con":true,"img":false}]}
{"op":"mcm","clk":"5346280648","pt":1646180069851,"mc":[{"id":"1.195453623","rc":[{"atb":[[6.4,15.12],[7.4,6.38],[5.2,38.88],[5.7,17.37],[9.4,4.86]],"id":37447009},{"spl":[[1.01,2.72]],"id":37447009},{"atl":[[80,1.68],[160,1.25],[55,2.46],[110,1.82]],"id":37447009},{"spn":9.4,"spf":1.0,"id":37447009},{"atb":[[1.8,102.07],[1.85,48.04],[1.7,233.32],[1.95,42.98],[1.75,108.88]],"id":36074465},{"atl":[[5.6,43.39],[5.1,32.45],[4.6,36.96],[6.2,38.38]],"id":36074465},{"spn":3.27,"spf":"NaN","id":36074465},{"atb":[[3.45,16.66],[3.2,37.11],[2.88,86.87],[3.95,13.83],[2.98,41.24]],"id":41788482},{"atl":[[16,8.86],[18.5,11.4],[22,9.5],[13.5,10.64]],"id":41788482},{"spn":8.72,"spf":"NaN","id":41788482},{"atb":[[6.4,30.24],[7.4,12.76],[13.5,3.26],[8.4,11.03],[9.4,4.86]],"id":39658516},{"atl":[[210,0.95],[110,1.21]],"id":39658516},{"spn":61.75,"spf":"NaN","id":39658516},{"atb":[[2.4,116.66],[2.9,21.48],[2.5,54.44],[2.6,51.03],[2.7,24.02]],"id":42513983},{"atl":[[12,18.14],[9.8,22.68],[8.8,17.05],[7.8,19.56]],"id":42513983},{"atb":[[4,27.22],[4.5,11.66],[5.5,9.07],[3.5,65.33],[3.75,29.69]],"id":37286329},{"atl":[[34,6.04],[18.5,7.6],[22,6.33],[27,7.67]],"id":37286329},{"spn":12.0,"spf":"NaN","id":37286329},{"atb":[[32,1.31],[18,4.8],[21,2.04],[13,13.61],[15.5,5.62]],"id":28222454},{"spn":166.0,"spf":"NaN","id":28222454}],"con":true,"img":false}]}
{"op":"mcm","clk":"5346281161","pt":1646180077133,"mc":[{"id":"1.195453623","rc":[{"spl":[[1.01,2.72]],"id":37286329}],"con":true,"img":false}]}
{"op":"mcm","clk":"5346401633","pt":1646182002789,"mc":[{"id":"1.195453623","marketDefinition":{"bspMarket":true,"turnInPlayEnabled":false,"persistenceEnabled":false,"marketBaseRate":7.0,"eventId":"31272494","eventTypeId":"4339","numberOfWinners":1,"bettingType":"ODDS","marketType":"WIN","marketTime":"2022-03-02T10:51:00.000Z","suspendTime":"2022-03-02T10:51:00.000Z","bspReconciled":false,"complete":true,"inPlay":false,"crossMatching":false,"runnersVoidable":false,"numberOfActiveRunners":7,"betDelay":0,"status":"OPEN","runners":[{"status":"ACTIVE","sortPriority":1,"id":39658516,"name":"1. Jeza You Beauty"},{"status":"ACTIVE","sortPriority":2,"id":36074465,"name":"2. Whistling Bullet"},{"status":"ACTIVE","sortPriority":3,"id":41788482,"name":"3. Flossie Ann"},{"status":"ACTIVE","sortPriority":4,"id":37447009,"name":"4. Annie Rose"},{"status":"ACTIVE","sortPriority":5,"id":28222454,"name":"5. She Wiggles"},{"status":"ACTIVE","sortPriority":6,"id":37286329,"name":"6. Dr Danika"},{"status":"ACTIVE","sortPriority":7,"id":42513983,"name":"8. Magic Mist"}],"regulators":["MR_INT"],"venue":"Traralgon","countryCode":"AU","discountAllowed":true,"timezone":"Australia/Sydney","openDate":"2022-03-02T08:31:00.000Z","version":4382425381,"name":"R8 500m Gr5","eventName":"Traralgon (AUS) 2nd Mar"},"rc":[{"atb":[[6.4,15.12],[7.4,6.38],[5.2,38.88],[5.7,17.37],[9.4,4.86]],"id":37447009},{"spl":[[1.01,2.72]],"id":37447009},{"atl":[[80,1.68],[160,1.25],[55,2.46],[110,1.82]],"id":37447009},{"spn":9.4,"spf":1.0,"id":37447009},{"atb":[[1.8,102.07],[1.85,48.04],[1.7,233.32],[1.95,42.98],[1.75,108.88]],"id":36074465},{"atl":[[5.6,43.39],[5.1,32.45],[4.6,36.96],[6.2,38.38]],"id":36074465},{"spn":3.27,"spf":"NaN","id":36074465},{"atb":[[3.45,16.66],[3.2,37.11],[2.88,86.87],[3.95,13.83],[2.98,41.24]],"id":41788482},{"atl":[[16,8.86],[18.5,11.4],[22,9.5],[13.5,10.64]],"id":41788482},{"spn":8.72,"spf":"NaN","id":41788482},{"atb":[[6.4,30.24],[7.4,12.76],[13.5,3.26],[8.4,11.03],[9.4,4.86]],"id":39658516},{"atl":[[260,0.77],[160,0.83],[210,0.95],[110,1.21]],"id":39658516},{"spn":61.75,"spf":"NaN","id":39658516},{"atb":[[2.4,116.66],[2.9,21.48],[2.5,54.44],[2.6,51.03],[2.7,24.02]],"id":42513983},{"atl":[[12,18.14],[9.8,22.68],[8.8,17.05],[7.8,19.56]],"id":42513983},{"spn":5.35,"spf":"NaN","id":42513983},{"atb":[[4,27.22],[4.5,11.66],[5.5,9.07],[3.5,65.33],[3.75,29.69]],"id":37286329},{"spl":[[1.01,2.72]],"id":37286329},{"atl":[[34,6.04],[18.5,7.6],[22,6.33],[27,7.67]],"id":37286329},{"spn":5.5,"spf":1.0,"id":37286329},{"atb":[[32,1.31],[18,4.8],[21,2.04],[13,13.61],[15.5,5.62]],"id":28222454},{"atl":[[300,0.44],[350,0.38],[400,0.5],[450,0.44]],"id":28222454},{"spn":166.0,"spf":"NaN","id":28222454}],"con":true,"img":true}]}
{"op":"mcm","clk":"5346485117","pt":1646183185237,"mc":[{"id":"1.195453623","rc":[{"atb":[[6.4,15.14],[7.4,6.39],[5.2,38.94],[5.7,17.4],[9.4,4.86]],"id":37447009},{"spl":[[1.01,2.72]],"id":37447009},{"atl":[[80,1.68],[160,1.25],[55,2.47],[110,1.83]],"id":37447009},{"atb":[[1.8,102.24],[1.85,48.11],[1.7,233.69],[1.95,43.05],[1.75,109.05]],"id":36074465},{"atl":[[5.6,43.45],[5.1,32.5],[4.6,37.01],[6.2,38.44]],"id":36074465},{"atb":[[3.45,0],[3.2,0],[2.88,0],[3.95,0],[2.98,0]],"id":41788482},{"atl":[[16,0],[18.5,0],[22,0],[13.5,0]],"id":41788482},{"spn":"NaN","spf":"NaN","id":41788482},{"atb":[[6.4,30.29],[7.4,12.78],[13.5,3.27],[8.4,11.05],[9.4,4.86]],"id":39658516},{"atl":[[260,0.77],[160,0.83],[210,0.95],[110,1.22]],"id":39658516},{"atb":[[2.4,0],[2.9,0],[2.5,0],[2.6,0],[2.7,0]],"id":42513983},{"atl":[[12,0],[9.8,0],[8.8,0],[7.8,0]],"id":42513983},{"spn":"NaN","spf":"NaN","id":42513983},{"atb":[[4,0],[4.5,0],[5.5,0],[3.5,0],[3.75,0]],"id":37286329},{"spl":[[1.01,2.72]],"id":37286329},{"atl":[[34,0],[18.5,0],[22,0],[27,0]],"id":37286329},{"spn":1.0,"spf":1.0,"id":37286329},{"atb":[[32,1.31],[18,4.8],[21,2.04],[13,13.63],[15.5,5.63]],"id":28222454},{"atl":[[300,0.44],[350,0.38],[400,0.5],[450,0.44]],"id":28222454}],"con":true,"img":false}]}
{"op":"mcm","clk":"5346487163","pt":1646183210693,"mc":[{"id":"1.195453623","rc":[{"atb":[[3.85,14.35],[3.1,38.94],[3.35,17.4],[2.84,88.9],[2.94,42.16]],"id":41788482},{"atl":[[17.5,12.11],[20,10.51],[12.5,11.58],[15,9.52]],"id":41788482},{"atb":[[2.82,22.47],[2.72,47.55],[2.52,107.62],[2.62,50.48],[3.05,19.95]],"id":42513983},{"atl":[[9.2,16.24],[10.5,21.04],[8.2,18.5],[13,16.65]],"id":42513983},{"atb":[[4,27.26],[4.5,11.68],[5.5,9.08],[3.5,65.43],[3.75,29.74]],"id":37286329},{"atl":[[34,6.05],[18.5,7.61],[22,6.34],[27,7.68]],"id":37286329}],"con":true,"img":false}]}
{"op":"mcm","clk":"5346767987","pt":1646187402734,"mc":[{"id":"1.195453623","marketDefinition":{"bspMarket":true,"turnInPlayEnabled":false,"persistenceEnabled":false,"marketBaseRate":7.0,"eventId":"31272494","eventTypeId":"4339","numberOfWinners":1,"bettingType":"ODDS","marketType":"WIN","marketTime":"2022-03-02T10:51:00.000Z","suspendTime":"2022-03-02T10:51:00.000Z","bspReconciled":false,"complete":true,"inPlay":false,"crossMatching":false,"runnersVoidable":false,"numberOfActiveRunners":7,"betDelay":0,"status":"OPEN","runners":[{"status":"ACTIVE","sortPriority":1,"id":39658516,"name":"1. Jeza You Beauty"},{"status":"ACTIVE","sortPriority":2,"id":36074465,"name":"2. Whistling Bullet"},{"status":"ACTIVE","sortPriority":3,"id":41788482,"name":"3. Flossie Ann"},{"status":"ACTIVE","sortPriority":4,"id":37447009,"name":"4. Annie Rose"},{"status":"ACTIVE","sortPriority":5,"id":28222454,"name":"5. She Wiggles"},{"status":"ACTIVE","sortPriority":6,"id":37286329,"name":"6. Dr Danika"},{"status":"ACTIVE","sortPriority":7,"id":42513983,"name":"8. Magic Mist"}],"regulators":["MR_INT"],"venue":"Traralgon","countryCode":"AU","discountAllowed":true,"timezone":"Australia/Sydney","openDate":"2022-03-02T08:31:00.000Z","version":4382425381,"name":"R8 500m Gr5","eventName":"Traralgon (AUS) 2nd Mar"},"rc":[{"atb":[[6.4,15.14],[7.4,6.39],[5.2,38.94],[5.7,17.4],[9.4,4.86]],"id":37447009},{"spl":[[1.01,2.72]],"id":37447009},{"atl":[[80,1.68],[160,1.25],[55,2.47],[110,1.83]],"id":37447009},{"spn":9.4,"spf":1.0,"id":37447009},{"atb":[[1.8,102.24],[1.85,48.11],[1.7,233.69],[1.95,43.05],[1.75,109.05]],"id":36074465},{"atl":[[5.6,43.45],[5.1,32.5],[4.6,37.01],[6.2,38.44]],"id":36074465},{"spn":3.27,"spf":"NaN","id":36074465},{"atb":[[3.85,14.35],[3.1,38.94],[3.35,17.4],[2.84,88.9],[2.94,42.16]],"id":41788482},{"atl":[[17.5,12.11],[20,10.51],[12.5,11.58],[15,9.52]],"id":41788482},{"spn":8.17,"spf":"NaN","id":41788482},{"atb":[[6.4,30.29],[7.4,12.78],[13.5,3.27],[8.4,11.05],[9.4,4.86]],"id":39658516},{"atl":[[260,0.77],[160,0.83],[210,0.95],[110,1.22]],"id":39658516},{"spn":61.75,"spf":"NaN","id":39658516},{"atb":[[2.82,22.47],[2.72,47.55],[2.52,107.62],[2.62,50.48],[3.05,19.95]],"id":42513983},{"atl":[[9.2,16.24],[10.5,21.04],[8.2,18.5],[13,16.65]],"id":42513983},{"spn":5.62,"spf":"NaN","id":42513983},{"atb":[[4,27.26],[4.5,11.68],[5.5,9.08],[3.5,65.43],[3.75,29.74]],"id":37286329},{"spl":[[1.01,2.72]],"id":37286329},{"atl":[[34,6.05],[18.5,7.61],[22,6.34],[27,7.68]],"id":37286329},{"spn":5.5,"spf":1.0,"id":37286329},{"atb":[[32,1.31],[18,4.8],[21,2.04],[13,13.63],[15.5,5.63]],"id":28222454},{"atl":[[300,0.44],[350,0.38],[400,0.5],[450,0.44]],"id":28222454},{"spn":166.0,"spf":"NaN","id":28222454}],"con":true,"img":true}]}
{"op":"mcm","clk":"5347092538","pt":1646192802713,"mc":[{"id":"1.195453623","marketDefinition":{"bspMarket":true,"turnInPlayEnabled":false,"persistenceEnabled":false,"marketBaseRate":7.0,"eventId":"31272494","eventTypeId":"4339","numberOfWinners":1,"bettingType":"ODDS","marketType":"WIN","marketTime":"2022-03-02T10:51:00.000Z","suspendTime":"2022-03-02T10:51:00.000Z","bspReconciled":false,"complete":true,"inPlay":false,"crossMatching":false,"runnersVoidable":false,"numberOfActiveRunners":7,"betDelay":0,"status":"OPEN","runners":[{"status":"ACTIVE","sortPriority":1,"id":39658516,"name":"1. Jeza You Beauty"},{"status":"ACTIVE","sortPriority":2,"id":36074465,"name":"2. Whistling Bullet"},{"status":"ACTIVE","sortPriority":3,"id":41788482,"name":"3. Flossie Ann"},{"status":"ACTIVE","sortPriority":4,"id":37447009,"name":"4. Annie Rose"},{"status":"ACTIVE","sortPriority":5,"id":28222454,"name":"5. She Wiggles"},{"status":"ACTIVE","sortPriority":6,"id":37286329,"name":"6. Dr Danika"},{"status":"ACTIVE","sortPriority":7,"id":42513983,"name":"8. Magic Mist"}],"regulators":["MR_INT"],"venue":"Traralgon","countryCode":"AU","discountAllowed":true,"timezone":"Australia/Sydney","openDate":"2022-03-02T08:31:00.000Z","version":4382425381,"name":"R8 500m Gr5","eventName":"Traralgon (AUS) 2nd Mar"},"rc":[{"atb":[[6.4,15.17],[7.4,6.4],[5.2,39.01],[5.7,17.42],[9.4,4.87]],"id":37447009},{"spl":[[1.01,2.73]],"id":37447009},{"atl":[[80,1.68],[160,1.26],[55,2.47],[110,1.83]],"id":37447009},{"spn":9.4,"spf":1.0,"id":37447009},{"atb":[[1.8,102.41],[1.85,48.19],[1.7,234.08],[1.95,43.12],[1.75,109.24]],"id":36074465},{"atl":[[5.6,43.53],[5.1,32.55],[4.6,37.08],[6.2,38.5]],"id":36074465},{"spn":3.27,"spf":"NaN","id":36074465},{"atb":[[3.85,14.37],[3.1,39.01],[3.35,17.42],[2.84,89.05],[2.94,42.23]],"id":41788482},{"atl":[[17.5,12.13],[20,10.53],[12.5,11.6],[15,9.53]],"id":41788482},{"spn":8.17,"spf":"NaN","id":41788482},{"atb":[[6.4,30.34],[7.4,12.8],[13.5,3.27],[8.4,11.07],[9.4,4.87]],"id":39658516},{"atl":[[260,0.77],[160,0.84],[210,0.95],[110,1.22]],"id":39658516},{"spn":61.75,"spf":"NaN","id":39658516},{"atb":[[2.82,22.5],[2.72,47.63],[2.52,107.8],[2.62,50.57],[3.05,19.98]],"id":42513983},{"atl":[[9.2,16.27],[10.5,21.07],[8.2,18.53],[13,16.68]],"id":42513983},{"spn":5.62,"spf":"NaN","id":42513983},{"atb":[[4,27.31],[4.5,11.7],[5.5,9.1],[3.5,65.54],[3.75,29.79]],"id":37286329},{"spl":[[1.01,2.73]],"id":37286329},{"atl":[[34,6.06],[18.5,7.63],[22,6.35],[27,7.7]],"id":37286329},{"spn":5.5,"spf":1.0,"id":37286329},{"atb":[[32,1.32],[18,4.81],[21,2.04],[13,13.65],[15.5,5.64]],"id":28222454},{"atl":[[300,0.44],[350,0.38],[400,0.5],[450,0.44]],"id":28222454},{"spn":166.0,"spf":"NaN","id":28222454}],"con":true,"img":true}]}
{"op":"mcm","clk":"5347342306","pt":1646197453805,"mc":[{"id":"1.195453623","rc":[{"atb":[[6.4,15.16],[7.4,6.39],[5.2,39],[5.7,17.42],[9.4,4.87]],"id":37447009},{"spl":[[1.01,2.73]],"id":37447009},{"atl":[[80,1.68],[160,1.26],[55,2.47],[110,1.83]],"id":37447009},{"atb":[[1.8,102.37],[1.85,48.17],[1.7,233.99],[1.95,43.1],[1.75,109.2]],"id":36074465},{"atl":[[5.6,43.51],[5.1,32.54],[4.6,37.06],[6.2,38.49],[3.25,8.19]],"id":36074465},{"spn":2.6,"spf":"NaN","id":36074465},{"atb":[[3.85,14.37],[3.1,39],[3.35,17.42],[2.84,89.01],[2.94,42.21]],"id":41788482},{"atl":[[17.5,12.13],[20,10.53],[12.5,11.6],[15,9.53]],"id":41788482},{"spn":8.17,"spf":"NaN","id":41788482},{"atb":[[6.4,30.33],[7.4,12.79],[13.5,3.27],[8.4,11.06],[9.4,4.87]],"id":39658516},{"atl":[[260,0.77],[160,0.84],[210,0.95],[110,1.22]],"id":39658516},{"atb":[[2.82,22.5],[2.72,47.61],[2.52,107.76],[2.62,50.55],[3.05,19.97]],"id":42513983},{"atl":[[9.2,16.27],[10.5,21.07],[8.2,18.53],[13,16.68]],"id":42513983},{"spn":5.62,"spf":"NaN","id":42513983},{"atb":[[4,27.3],[4.5,11.7],[5.5,9.1],[3.5,65.52],[3.75,29.78]],"id":37286329},{"spl":[[1.01,2.73]],"id":37286329},{"atl":[[34,6.06],[18.5,7.62],[22,6.35],[27,7.69]],"id":37286329},{"spn":5.5,"spf":1.0,"id":37286329},{"atb":[[32,1.32],[18,4.81],[21,2.04],[13,13.65],[15.5,5.64]],"id":28222454},{"atl":[[300,0.44],[350,0.38],[400,0.5],[450,0.44]],"id":28222454}],"con":true,"img":false}]}
{"op":"mcm","clk":"5347385823","pt":1646198260689,"mc":[{"id":"1.195453623","rc":[{"spl":[[1.01,78.07]],"id":36074465}],"con":true,"img":false}]}
{"op":"mcm","clk":"5347458684","pt":1646199820719,"mc":[{"id":"1.195453623","rc":[{"atl":[[2.5,6.2]],"id":36074465},{"spn":1.9,"spf":1.0,"id":36074465}],"con":true,"img":false}]}
{"op":"mcm","clk":"5347459006","pt":1646199827714,"mc":[{"id":"1.195453623","rc":[{"atl":[[2.7,6.2]],"id":36074465}],"con":true,"img":false}]}
{"op":"mcm","clk":"5347693924","pt":1646205594678,"mc":[{"id":"1.195453623","rc":[{"atb":[[6.4,15.16],[7.4,6.39],[5.2,38.99],[5.7,17.41],[9.4,4.87]],"id":37447009},{"spl":[[1.01,2.72]],"id":37447009},{"atl":[[80,1.68],[160,1.26],[55,2.47],[110,1.83]],"id":37447009},{"atb":[[1.8,102.34],[1.85,48.16],[1.7,233.93],[1.95,43.09],[1.75,109.17]],"id":36074465},{"spl":[[1.01,78.05]],"id":36074465},{"atl":[[5.6,43.5],[5.1,32.53],[2.5,6.21],[4.6,37.05],[6.2,38.48],[3.25,8.18],[2.7,6.21]],"id":36074465},{"atb":[[3.85,14.36],[3.1,38.99],[3.35,17.41],[2.84,88.99],[2.94,42.2]],"id":41788482},{"atl":[[17.5,12.12],[20,10.52],[12.5,11.59],[15,9.53]],"id":41788482},{"atb":[[6.4,0],[7.4,0],[13.5,0],[8.4,0],[9.4,0]],"id":39658516},{"atl":[[260,0],[160,0],[210,0],[110,0]],"id":39658516},{"spn":"NaN","spf":"NaN","id":39658516},{"atb":[[2.82,22.49],[2.72,47.6],[2.52,107.73],[2.62,50.54],[3.05,19.97]],"id":42513983},{"atl":[[9.2,16.26],[10.5,21.06],[8.2,18.52],[13,16.67]],"id":42513983},{"atb":[[4,27.29],[4.5,11.69],[5.5,9.09],[3.5,65.5],[3.75,29.77]],"id":37286329},{"spl":[[1.01,2.72]],"id":37286329},{"atl":[[34,6.06],[18.5,7.62],[22,6.35],[27,7.69]],"id":37286329},{"atb":[[32,0],[18,0],[21,0],[13,0],[15.5,0]],"id":28222454},{"atl":[[300,0],[350,0],[400,0],[450,0]],"id":28222454},{"spn":"NaN","spf":"NaN","id":28222454}],"con":true,"img":false}]}
{"op":"mcm","clk":"5347694674","pt":1646205611310,"mc":[{"id":"1.195453623","rc":[{"atb":[[16.5,2.64],[9.6,9.51],[8.6,10.77],[11.5,3.89],[7.6,24.8]],"id":39658516},{"atl":[[140,0.96],[290,0.69],[190,0.7],[240,0.83]],"id":39658516},{"atb":[[18,4.81],[42,0.99],[21,4.09],[26,1.63],[15.5,11.29]],"id":28222454},{"atl":[[350,0.38],[400,0.33],[450,0.44],[500,0.39]],"id":28222454}],"con":true,"img":false}]}
{"op":"mcm","clk":"5347767060","pt":1646207383268,"mc":[{"id":"1.195453623","rc":[{"atb":[[1.95,15.8]],"id":36074465},{"trd":[[1.95,54.58]],"ltp":1.95,"tv":54.58,"id":36074465},{"spn":1.86,"spf":1.0,"id":36074465},{"spn":78.25,"spf":"NaN","id":39658516},{"spn":196.0,"spf":"NaN","id":28222454}],"con":true,"img":false}]}
{"op":"mcm","clk":"5347792366","pt":1646207876107,"mc":[{"id":"1.195453623","rc":[{"spl":[[1.01,296.39]],"id":36074465},{"spn":1.79,"spf":1.0,"id":36074465}],"con":true,"img":false}]}
{"op":"mcm","clk":"5347814570","pt":1646208419956,"mc":[{"id":"1.195453623","rc":[{"atl":[[2.48,1.29]],"id":36074465},{"atl":[[12,1.31]],"id":41788482},{"spn":7.92,"spf":"NaN","id":41788482},{"atl":[[990,1.33]],"id":39658516},{"atl":[[8,1.31]],"id":42513983},{"spn":5.52,"spf":"NaN","id":42513983},{"atl":[[18,1.32]],"id":37286329},{"atl":[[990,1.33]],"id":28222454}],"con":true,"img":false}]}
{"op":"mcm","clk":"5347814630","pt":1646208421760,"mc":[{"id":"1.195453623","rc":[{"atb":[[1.95,4.66]],"id":36074465},{"trd":[[1.95,76.85]],"ltp":1.95,"tv":76.85,"id":36074465}],"con":true,"img":false}]}
{"op":"mcm","clk":"5347814654","pt":1646208422374,"mc":[{"id":"1.195453623","rc":[{"atb":[[3.9,1.64]],"id":41788482},{"atb":[[3.1,1.63]],"id":42513983},{"atb":[[5.6,1.52]],"id":37286329}],"con":true,"img":false}]}
{"op":"mcm","clk":"5347815999","pt":1646208452741,"mc":[{"id":"1.195453623","marketDefinition":{"bspMarket":true,"turnInPlayEnabled":false,"persistenceEnabled":false,"marketBaseRate":7.0,"eventId":"31272494","eventTypeId":"4339","numberOfWinners":1,"bettingType":"ODDS","marketType":"WIN","marketTime":"2022-03-02T10:51:00.000Z","suspendTime":"2022-03-02T10:51:00.000Z","bspReconciled":false,"complete":true,"inPlay":false,"crossMatching":true,"runnersVoidable":false,"numberOfActiveRunners":7,"betDelay":0,"status":"OPEN","runners":[{"status":"ACTIVE","sortPriority":1,"id":39658516,"name":"1. Jeza You Beauty"},{"status":"ACTIVE","sortPriority":2,"id":36074465,"name":"2. Whistling Bullet"},{"status":"ACTIVE","sortPriority":3,"id":41788482,"name":"3. Flossie Ann"},{"status":"ACTIVE","sortPriority":4,"id":37447009,"name":"4. Annie Rose"},{"status":"ACTIVE","sortPriority":5,"id":28222454,"name":"5. She Wiggles"},{"status":"ACTIVE","sortPriority":6,"id":37286329,"name":"6. Dr Danika"},{"status":"ACTIVE","sortPriority":7,"id":42513983,"name":"8. Magic Mist"}],"regulators":["MR_INT"],"venue":"Traralgon","countryCode":"AU","discountAllowed":true,"timezone":"Australia/Sydney","openDate":"2022-03-02T08:31:00.000Z","version":4382425381,"name":"R8 500m Gr5","eventName":"Traralgon (AUS) 2nd Mar"},"rc":[],"con":true,"img":false}]}
{"op":"mcm","clk":"5347849091","pt":1646209002735,"mc":[{"id":"1.195453623","marketDefinition":{"bspMarket":true,"turnInPlayEnabled":false,"persistenceEnabled":false,"marketBaseRate":7.0,"eventId":"31272494","eventTypeId":"4339","numberOfWinners":1,"bettingType":"ODDS","marketType":"WIN","marketTime":"2022-03-02T10:51:00.000Z","suspendTime":"2022-03-02T10:51:00.000Z","bspReconciled":false,"complete":true,"inPlay":false,"crossMatching":true,"runnersVoidable":false,"numberOfActiveRunners":7,"betDelay":0,"status":"OPEN","runners":[{"status":"ACTIVE","sortPriority":1,"id":39658516,"name":"1. Jeza You Beauty"},{"status":"ACTIVE","sortPriority":2,"id":36074465,"name":"2. Whistling Bullet"},{"status":"ACTIVE","sortPriority":3,"id":41788482,"name":"3. Flossie Ann"},{"status":"ACTIVE","sortPriority":4,"id":37447009,"name":"4. Annie Rose"},{"status":"ACTIVE","sortPriority":5,"id":28222454,"name":"5. She Wiggles"},{"status":"ACTIVE","sortPriority":6,"id":37286329,"name":"6. Dr Danika"},{"status":"ACTIVE","sortPriority":7,"id":42513983,"name":"8. Magic Mist"}],"regulators":["MR_INT"],"venue":"Traralgon","countryCode":"AU","discountAllowed":true,"timezone":"Australia/Sydney","openDate":"2022-03-02T08:31:00.000Z","version":4382425381,"name":"R8 500m Gr5","eventName":"Traralgon (AUS) 2nd Mar"},"rc":[{"atb":[[6.4,15.16],[7.4,6.39],[5.2,38.99],[5.7,17.41],[9.4,4.87]],"id":37447009},{"spl":[[1.01,2.72]],"id":37447009},{"atl":[[80,1.68],[160,1.26],[55,2.47],[110,1.83]],"id":37447009},{"spn":9.4,"spf":1.0,"id":37447009},{"atb":[[1.8,102.34],[1.85,48.16],[1.7,233.93],[1.95,4.66],[1.75,109.17]],"id":36074465},{"spl":[[1.01,296.39]],"id":36074465},{"atl":[[5.6,43.5],[5.1,32.53],[2.5,6.21],[4.6,37.05],[6.2,38.48],[3.25,8.18],[2.48,1.29],[2.7,6.21]],"id":36074465},{"trd":[[1.95,76.85]],"ltp":1.95,"tv":76.85,"id":36074465},{"spn":1.78,"spf":1.0,"id":36074465},{"atb":[[3.85,14.36],[3.1,38.99],[3.35,17.41],[2.84,88.99],[3.9,1.64],[2.94,42.2]],"id":41788482},{"atl":[[17.5,12.12],[20,10.52],[12,1.31],[12.5,11.59],[15,9.53]],"id":41788482},{"spn":7.95,"spf":"NaN","id":41788482},{"atb":[[16.5,2.64],[9.6,9.51],[8.6,10.77],[11.5,3.89],[7.6,24.8]],"id":39658516},{"atl":[[140,0.96],[290,0.69],[190,0.7],[240,0.83],[990,1.33]],"id":39658516},{"spn":78.25,"spf":"NaN","id":39658516},{"atb":[[2.82,22.49],[2.72,47.6],[3.1,1.63],[2.52,107.73],[2.62,50.54],[3.05,19.97]],"id":42513983},{"atl":[[8,1.31],[9.2,16.26],[10.5,21.06],[8.2,18.52],[13,16.67]],"id":42513983},{"spn":5.55,"spf":"NaN","id":42513983},{"atb":[[5.6,1.52],[4,27.29],[4.5,11.69],[5.5,9.09],[3.5,65.5],[3.75,29.77]],"id":37286329},{"spl":[[1.01,2.72]],"id":37286329},{"atl":[[34,6.06],[18,1.32],[18.5,7.62],[22,6.35],[27,7.69]],"id":37286329},{"spn":5.55,"spf":1.0,"id":37286329},{"atb":[[18,4.81],[42,0.99],[21,4.09],[26,1.63],[15.5,11.29]],"id":28222454},{"atl":[[350,0.38],[400,0.33],[450,0.44],[990,1.33],[500,0.39]],"id":28222454},{"spn":196.0,"spf":"NaN","id":28222454}],"con":true,"img":true}]}
{"op":"mcm","clk":"5347867163","pt":1646209291319,"mc":[{"id":"1.195453623","rc":[{"atb":[[1.01,2.25]],"id":37447009},{"atb":[[1.88,8.54]],"id":36074465},{"spn":1.78,"spf":1.0,"id":36074465},{"atb":[[3.15,3.49]],"id":41788482},{"spn":7.95,"spf":"NaN","id":41788482},{"atb":[[2.76,4.27]],"id":42513983},{"spn":5.55,"spf":"NaN","id":42513983},{"atb":[[4.1,2.43]],"id":37286329},{"spn":5.55,"spf":1.0,"id":37286329}],"con":true,"img":false}]}
{"op":"mcm","clk":"5347867175","pt":1646209291525,"mc":[{"id":"1.195453623","rc":[{"atb":[[1.01,1.34]],"id":37447009}],"con":true,"img":false}]}
{"op":"mcm","clk":"5347867191","pt":1646209291889,"mc":[{"id":"1.195453623","rc":[{"atb":[[1.01,0]],"id":37447009}],"con":true,"img":false}]}
{"op":"mcm","clk":"5347867197","pt":1646209291992,"mc":[{"id":"1.195453623","rc":[{"atb":[[6.6,1.34]],"id":37447009}],"con":true,"img":false}]}
{"op":"mcm","clk":"5347880058","pt":1646209558917,"mc":[{"id":"1.195453623","rc":[{"atb":[[1.88,20.03]],"id":36074465},{"spn":1.79,"spf":1.0,"id":36074465}],"con":true,"img":false}]}
{"op":"mcm","clk":"5347880067","pt":1646209559120,"mc":[{"id":"1.195453623","rc":[{"atb":[[6.6,3.15]],"id":37447009}],"con":true,"img":false}]}
{"op":"mcm","clk":"5347880069","pt":1646209559223,"mc":[{"id":"1.195453623","rc":[{"atb":[[2.76,10.01]],"id":42513983}],"con":true,"img":false}]}
{"op":"mcm","clk":"5347880078","pt":1646209559430,"mc":[{"id":"1.195453623","rc":[{"atb":[[3.15,8.2]],"id":41788482},{"atb":[[4.1,5.69]],"id":37286329}],"con":true,"img":false}]}
{"op":"mcm","clk":"5347946900","pt":1646211060226,"mc":[{"id":"1.195453623","rc":[{"atb":[[12.5,0.88]],"id":37447009},{"spn":10.39,"spf":1.0,"id":37447009},{"atb":[[4.1,2]],"id":41788482},{"spn":8.05,"spf":"NaN","id":41788482},{"atb":[[18.5,0.58]],"id":39658516},{"spn":79.25,"spf":"NaN","id":39658516},{"atb":[[3.15,2]],"id":42513983},{"spn":5.57,"spf":"NaN","id":42513983},{"atb":[[7,1.68]],"id":37286329},{"spn":6.46,"spf":1.0,"id":37286329},{"atb":[[42,1.24]],"id":28222454}],"con":true,"img":false}]}
{"op":"mcm","clk":"5347956473","pt":1646211255870,"mc":[{"id":"1.195453623","rc":[{"atl":[[3.25,0]],"id":36074465}],"con":true,"img":false}]}
{"op":"mcm","clk":"5347956480","pt":1646211255972,"mc":[{"id":"1.195453623","rc":[{"atl":[[3.15,8.18]],"id":36074465}],"con":true,"img":false}]}
{"op":"mcm","clk":"5347961153","pt":1646211353318,"mc":[{"id":"1.195453623","rc":[{"atb":[[3.1,0]],"id":42513983}],"con":true,"img":false}]}
{"op":"mcm","clk":"5347961157","pt":1646211353419,"mc":[{"id":"1.195453623","rc":[{"atb":[[3.15,3.63]],"id":42513983}],"con":true,"img":false}]}
{"op":"mcm","clk":"5347981185","pt":1646211785412,"mc":[{"id":"1.195453623","rc":[{"atb":[[6.4,15.13],[7.4,6.38],[5.2,38.92],[5.7,17.39],[6.6,3.15],[9.4,4.86]],"id":37447009},{"spl":[[1.01,2.72]],"id":37447009},{"atl":[[80,1.68],[160,1.25],[55,2.46],[110,1.83]],"id":37447009},{"spn":10.4,"spf":1.0,"id":37447009},{"atb":[[1.8,102.18],[1.88,20],[1.85,48.08],[1.7,233.56],[1.95,4.65],[1.75,108.99]],"id":36074465},{"spl":[[1.01,295.92]],"id":36074465},{"atl":[[5.6,43.43],[5.1,32.48],[2.5,6.2],[4.6,36.99],[6.2,38.42],[3.15,8.17],[2.48,1.29],[2.7,6.2]],"id":36074465},{"trd":[[1.95,76.73]],"ltp":1.95,"tv":76.73,"id":36074465},{"atb":[[3.85,14.34],[3.1,38.92],[3.35,17.39],[3.15,8.18],[2.84,88.85],[3.9,1.64],[2.94,42.13]],"id":41788482},{"atl":[[17.5,12.1],[20,10.51],[12,1.31],[12.5,11.58],[15,9.51]],"id":41788482},{"atb":[[16.5,2.63],[9.6,9.5],[8.6,10.75],[11.5,3.89],[7.6,24.76]],"id":39658516},{"atl":[[140,0.95],[290,0.69],[190,0.7],[240,0.83],[990,1.33]],"id":39658516},{"atb":[[2.82,22.45],[2.72,47.52],[2.52,107.56],[3.15,3.63],[2.62,50.46],[3.05,19.94],[2.76,9.99]],"id":42513983},{"atl":[[8,1.3],[9.2,16.24],[10.5,21.03],[8.2,18.49],[13,16.64]],"id":42513983},{"atb":[[5.6,1.51],[4,27.24],[4.5,11.67],[5.5,9.08],[4.1,5.68],[7,0],[3.5,65.39],[3.75,29.72]],"id":37286329},{"spl":[[1.01,2.72]],"id":37286329},{"atl":[[34,6.05],[18,1.32],[18.5,7.61],[22,6.34],[27,7.68]],"id":37286329},{"spn":5.55,"spf":1.0,"id":37286329},{"atb":[[18,4.8],[42,1.24],[21,4.08],[26,1.63],[15.5,11.27]],"id":28222454},{"atl":[[350,0.38],[400,0.33],[450,0.44],[990,1.33],[500,0.39]],"id":28222454}],"con":true,"img":false}]}
{"op":"mcm","clk":"5347981191","pt":1646211785524,"mc":[{"id":"1.195453623","rc":[{"atb":[[7.2,1.62]],"id":37286329}],"con":true,"img":false}]}
{"op":"mcm","clk":"5347981201","pt":1646211785728,"mc":[{"id":"1.195453623","rc":[{"atb":[[9.6,1.51]],"id":37447009}],"con":true,"img":false}]}
{"op":"mcm","clk":"5347981248","pt":1646211786646,"mc":[{"id":"1.195453623","rc":[{"atb":[[9.6,0]],"id":37447009}],"con":true,"img":false}]}
{"op":"mcm","clk":"5347981254","pt":1646211786712,"mc":[{"id":"1.195453623","rc":[{"atb":[[1.01,1.51]],"id":37447009}],"con":true,"img":false}]}
{"op":"mcm","clk":"5347981304","pt":1646211787536,"mc":[{"id":"1.195453623","rc":[{"atb":[[1.01,0]],"id":37447009}],"con":true,"img":false}]}
{"op":"mcm","clk":"5347981312","pt":1646211787641,"mc":[{"id":"1.195453623","rc":[{"atb":[[9.6,1.51]],"id":37447009}],"con":true,"img":false}]}
{"op":"mcm","clk":"5347981351","pt":1646211788326,"mc":[{"id":"1.195453623","rc":[{"atb":[[9.6,0]],"id":37447009}],"con":true,"img":false}]}
{"op":"mcm","clk":"5347981356","pt":1646211788428,"mc":[{"id":"1.195453623","rc":[{"atb":[[1.01,1.51]],"id":37447009}],"con":true,"img":false}]}
{"op":"mcm","clk":"5347997238","pt":1646212106873,"mc":[{"id":"1.195453623","rc":[{"atb":[[1.01,0]],"id":37447009},{"spn":6.55,"spf":1.0,"id":37286329}],"con":true,"img":false}]}
{"op":"mcm","clk":"5347997243","pt":1646212106977,"mc":[{"id":"1.195453623","rc":[{"atb":[[9.6,1.51]],"id":37447009}],"con":true,"img":false}]}
{"op":"mcm","clk":"5347997299","pt":1646212107802,"mc":[{"id":"1.195453623","rc":[{"atb":[[9.6,0]],"id":37447009}],"con":true,"img":false}]}
{"op":"mcm","clk":"5347997309","pt":1646212107906,"mc":[{"id":"1.195453623","rc":[{"atb":[[1.01,1.51]],"id":37447009}],"con":true,"img":false}]}
{"op":"mcm","clk":"5347997354","pt":1646212108679,"mc":[{"id":"1.195453623","rc":[{"atb":[[1.01,0]],"id":37447009}],"con":true,"img":false}]}
{"op":"mcm","clk":"5347997360","pt":1646212108784,"mc":[{"id":"1.195453623","rc":[{"atb":[[9.6,1.51]],"id":37447009}],"con":true,"img":false}]}
{"op":"mcm","clk":"5347997392","pt":1646212109710,"mc":[{"id":"1.195453623","rc":[{"atb":[[9.6,0]],"id":37447009}],"con":true,"img":false}]}
{"op":"mcm","clk":"5347997398","pt":1646212109810,"mc":[{"id":"1.195453623","rc":[{"atb":[[1.01,1.51]],"id":37447009}],"con":true,"img":false}]}
{"op":"mcm","clk":"5347997451","pt":1646212110792,"mc":[{"id":"1.195453623","rc":[{"atb":[[1.01,0]],"id":37447009}],"con":true,"img":false}]}
{"op":"mcm","clk":"5347997458","pt":1646212110900,"mc":[{"id":"1.195453623","rc":[{"atb":[[9.6,1.51]],"id":37447009}],"con":true,"img":false}]}
{"op":"mcm","clk":"5347997500","pt":1646212111673,"mc":[{"id":"1.195453623","rc":[{"atb":[[9.6,0]],"id":37447009}],"con":true,"img":false}]}
{"op":"mcm","clk":"5347997504","pt":1646212111777,"mc":[{"id":"1.195453623","rc":[{"atb":[[1.01,1.51]],"id":37447009}],"con":true,"img":false}]}
{"op":"mcm","clk":"5348015645","pt":1646212475621,"mc":[{"id":"1.195453623","rc":[{"atb":[[1.01,0]],"id":37447009}],"con":true,"img":false}]}
{"op":"mcm","clk":"5348015650","pt":1646212475722,"mc":[{"id":"1.195453623","rc":[{"atb":[[9.6,1.51]],"id":37447009}],"con":true,"img":false}]}
{"op":"mcm","clk":"5348015676","pt":1646212476329,"mc":[{"id":"1.195453623","rc":[{"atb":[[9.6,0]],"id":37447009}],"con":true,"img":false}]}
{"op":"mcm","clk":"5348015683","pt":1646212476431,"mc":[{"id":"1.195453623","rc":[{"atb":[[1.01,1.51]],"id":37447009}],"con":true,"img":false}]}
{"op":"mcm","clk":"5348015728","pt":1646212477318,"mc":[{"id":"1.195453623","rc":[{"atb":[[1.01,0]],"id":37447009}],"con":true,"img":false}]}
{"op":"mcm","clk":"5348015736","pt":1646212477423,"mc":[{"id":"1.195453623","rc":[{"atb":[[9.6,1.51]],"id":37447009}],"con":true,"img":false}]}
{"op":"mcm","clk":"5348015785","pt":1646212478342,"mc":[{"id":"1.195453623","rc":[{"atb":[[9.6,0]],"id":37447009}],"con":true,"img":false}]}
{"op":"mcm","clk":"5348015794","pt":1646212478401,"mc":[{"id":"1.195453623","rc":[{"atb":[[1.01,1.51]],"id":37447009}],"con":true,"img":false}]}
{"op":"mcm","clk":"5348015859","pt":1646212479325,"mc":[{"id":"1.195453623","rc":[{"atb":[[1.01,0]],"id":37447009}],"con":true,"img":false}]}
{"op":"mcm","clk":"5348015865","pt":1646212479425,"mc":[{"id":"1.195453623","rc":[{"atb":[[9.6,1.51]],"id":37447009}],"con":true,"img":false}]}
{"op":"mcm","clk":"5348015905","pt":1646212480304,"mc":[{"id":"1.195453623","rc":[{"atb":[[9.6,0]],"id":37447009}],"con":true,"img":false}]}
{"op":"mcm","clk":"5348015912","pt":1646212480405,"mc":[{"id":"1.195453623","rc":[{"atb":[[1.01,1.51]],"id":37447009}],"con":true,"img":false}]}
{"op":"mcm","clk":"5348036722","pt":1646212862547,"mc":[{"id":"1.195453623","rc":[{"atb":[[5.2,56.06]],"id":37447009},{"atb":[[1.43,167.44]],"id":36074465},{"atb":[[5.6,17.83],[8.6,20.22]],"id":39658516},{"atb":[[2.06,67.92]],"id":42513983},{"atb":[[3.3,31.3]],"id":37286329}],"con":true,"img":false}]}
{"op":"mcm","clk":"5348036728","pt":1646212862656,"mc":[{"id":"1.195453623","rc":[{"atb":[[3.5,32.8]],"id":37447009},{"atb":[[1.25,328]],"id":36074465},{"atl":[[4.5,8.2],[5.4,14.2]],"id":36074465},{"atl":[[23,8.2],[30,14.2]],"id":41788482},{"atb":[[1.64,128.13]],"id":42513983},{"atl":[[19,14.2],[15,8.2]],"id":42513983},{"atb":[[2.36,60.29]],"id":37286329},{"atl":[[46,8.2],[60,14.2]],"id":37286329},{"atb":[[10,8],[6.8,14.14]],"id":28222454}],"con":true,"img":false}]}
{"op":"mcm","clk":"5348036736","pt":1646212862767,"mc":[{"id":"1.195453623","rc":[{"atb":[[2.62,46.3]],"id":37447009},{"atl":[[17,8.5],[34,13.5]],"id":36074465},{"atb":[[2.62,46.3],[4.2,26.56]],"id":39658516},{"atl":[[34,13.5]],"id":42513983},{"atb":[[2.62,46.3]],"id":37286329},{"atb":[[2.62,46.3]],"id":28222454}],"con":true,"img":false}]}
{"op":"mcm","clk":"5348036742","pt":1646212862869,"mc":[{"id":"1.195453623","rc":[{"atl":[[34,13.5]],"id":41788482},{"atb":[[4.2,26.56]],"id":28222454}],"con":true,"img":false}]}
{"op":"mcm","clk":"5348037202","pt":1646212870561,"mc":[{"id":"1.195453623","rc":[{"atb":[[6.8,0]],"id":28222454}],"con":true,"img":false}]}
{"op":"mcm","clk":"5348057469","pt":1646213238720,"mc":[{"id":"1.195453623","rc":[{"atb":[[18.5,0]],"id":39658516},{"spn":78.25,"spf":"NaN","id":39658516}],"con":true,"img":false}]}
{"op":"mcm","clk":"5348057474","pt":1646213238822,"mc":[{"id":"1.195453623","rc":[{"atb":[[4.1,0]],"id":41788482},{"atb":[[18.5,0.58]],"id":39658516},{"atb":[[3.15,1.63]],"id":42513983},{"atb":[[42,0.99]],"id":28222454}],"con":true,"img":false}]}
{"op":"mcm","clk":"5348057476","pt":1646213238924,"mc":[{"id":"1.195453623","rc":[{"atb":[[4.1,2]],"id":41788482},{"atb":[[3.15,3.63]],"id":42513983},{"atb":[[42,1.24]],"id":28222454}],"con":true,"img":false}]}
{"op":"mcm","clk":"5348057481","pt":1646213239132,"mc":[{"id":"1.195453623","rc":[{"atb":[[3.15,2]],"id":42513983}],"con":true,"img":false}]}
{"op":"mcm","clk":"5348057486","pt":1646213239235,"mc":[{"id":"1.195453623","rc":[{"atb":[[3.1,1.63]],"id":42513983}],"con":true,"img":false}]}
{"op":"mcm","clk":"5348089679","pt":1646213799004,"mc":[{"id":"1.195453623","rc":[{"atb":[[1.86,2]],"id":36074465},{"spn":1.79,"spf":1.0,"id":36074465},{"spn":79.25,"spf":"NaN","id":39658516}],"con":true,"img":false}]}
{"op":"mcm","clk":"5348137972","pt":1646214444256,"mc":[{"id":"1.195453623","rc":[{"atb":[[10,14.71],[12.5,5.96]],"id":37447009},{"atl":[[40,2.72],[50,2.72]],"id":37447009},{"atb":[[1.89,59.65],[1.76,140.9]],"id":36074465},{"atl":[[3.05,28.51],[4,30.59]],"id":36074465},{"atb":[[4.3,17.71],[3.9,40.26]],"id":41788482},{"atl":[[9.2,7.12],[12,11.49]],"id":41788482},{"atb":[[18,3.43],[14.5,9.8]],"id":39658516},{"atl":[[75,2.72],[100,2.72]],"id":39658516},{"atb":[[3.1,29.46],[2.84,61.75]],"id":42513983},{"atl":[[8,17.54],[6,11.69]],"id":42513983},{"atb":[[5.6,28.53],[6.4,10.82]],"id":37286329},{"atl":[[18,8.63],[15.5,4.03]],"id":37286329},{"atb":[[34,2.72],[26,6.16]],"id":28222454},{"atl":[[330,2.72],[240,0.24]],"id":28222454}],"con":true,"img":false}]}
{"op":"mcm","clk":"5348138016","pt":1646214444975,"mc":[{"id":"1.195453623","rc":[{"atl":[[38,1.3]],"id":37447009},{"atl":[[18,7.3]],"id":37286329}],"con":true,"img":false}]}
{"op":"mcm","clk":"5348138019","pt":1646214445028,"mc":[{"id":"1.195453623","rc":[{"atb":[[1.98,83.67],[2.64,43.9]],"id":41788482},{"atl":[[15,1.32]],"id":37286329}],"con":true,"img":false}]}
{"op":"mcm","clk":"5348138449","pt":1646214451466,"mc":[{"id":"1.195453623","rc":[{"atb":[[6.6,1.8]],"id":37447009},{"atb":[[1.88,11.46]],"id":36074465},{"atb":[[3.15,4.69]],"id":41788482},{"atb":[[2.76,5.72]],"id":42513983},{"atb":[[4.1,3.25]],"id":37286329}],"con":true,"img":false}]}
{"op":"mcm","clk":"5348139283","pt":1646214463047,"mc":[{"id":"1.195453623","rc":[{"spn":12.5,"spf":1.0,"id":37447009},{"atb":[[1.89,0]],"id":36074465},{"spn":1.79,"spf":1.0,"id":36074465},{"spn":6.75,"spf":"NaN","id":41788482},{"spn":46.75,"spf":"NaN","id":39658516},{"spn":4.57,"spf":"NaN","id":42513983},{"spn":6.87,"spf":1.0,"id":37286329},{"spn":141.0,"spf":"NaN","id":28222454}],"con":true,"img":false}]}
{"op":"mcm","clk":"5348139294","pt":1646214463249,"mc":[{"id":"1.195453623","rc":[{"atb":[[1.86,61.65]],"id":36074465}],"con":true,"img":false}]}
{"op":"mcm","clk":"5348139307","pt":1646214463404,"mc":[{"id":"1.195453623","rc":[{"atb":[[1.01,2.25]],"id":41788482},{"atb":[[3.15,5.49]],"id":42513983},{"atb":[[1.01,2.25]],"id":37286329}],"con":true,"img":false}]}
{"op":"mcm","clk":"5348139310","pt":1646214463559,"mc":[{"id":"1.195453623","rc":[{"atb":[[1.01,2.21]],"id":41788482},{"atb":[[1.01,1.6]],"id":37286329}],"con":true,"img":false}]}
{"op":"mcm","clk":"5348139323","pt":1646214463614,"mc":[{"id":"1.195453623","rc":[{"atb":[[1.01,0]],"id":37286329}],"con":true,"img":false}]}
{"op":"mcm","clk":"5348139333","pt":1646214463715,"mc":[{"id":"1.195453623","rc":[{"atb":[[5.7,1.6]],"id":37286329}],"con":true,"img":false}]}
{"op":"mcm","clk":"5348139342","pt":1646214463820,"mc":[{"id":"1.195453623","rc":[{"atb":[[1.01,0]],"id":41788482}],"con":true,"img":false}]}
{"op":"mcm","clk":"5348139351","pt":1646214463920,"mc":[{"id":"1.195453623","rc":[{"atb":[[4.4,2.21]],"id":41788482}],"con":true,"img":false}]}
{"op":"mcm","clk":"5348139683","pt":1646214468330,"mc":[{"id":"1.195453623","rc":[{"atb":[[6.6,0]],"id":37447009},{"atb":[[1.88,0]],"id":36074465},{"atb":[[3.15,0]],"id":41788482},{"atb":[[2.76,0]],"id":42513983},{"atb":[[4.1,0]],"id":37286329}],"con":true,"img":false}]}
{"op":"mcm","clk":"5348140505","pt":1646214480465,"mc":[{"id":"1.195453623","rc":[{"atb":[[1.89,9.36]],"id":36074465}],"con":true,"img":false}]}
{"op":"mcm","clk":"5348140528","pt":1646214480776,"mc":[{"id":"1.195453623","rc":[{"atb":[[3.95,2.82]],"id":41788482}],"con":true,"img":false}]}
{"op":"mcm","clk":"5348140544","pt":1646214480985,"mc":[{"id":"1.195453623","rc":[{"atb":[[5.7,3.37]],"id":37286329}],"con":true,"img":false}]}
{"op":"mcm","clk":"5348140558","pt":1646214481191,"mc":[{"id":"1.195453623","rc":[{"atb":[[3.15,9.37]],"id":42513983}],"con":true,"img":false}]}
{"op":"mcm","clk":"5348140577","pt":1646214481503,"mc":[{"id":"1.195453623","rc":[{"atb":[[1.89,17.82]],"id":36074465}],"con":true,"img":false}]}
{"op":"mcm","clk":"5348140791","pt":1646214484294,"mc":[{"id":"1.195453623","rc":[{"atb":[[34,0]],"id":28222454}],"con":true,"img":false}]}
{"op":"mcm","clk":"5348140799","pt":1646214484397,"mc":[{"id":"1.195453623","rc":[{"atb":[[44,2.72]],"id":28222454}],"con":true,"img":false}]}
{"op":"mcm","clk":"5348142956","pt":1646214512294,"mc":[{"id":"1.195453623","rc":[{"atb":[[14.5,0]],"id":39658516}],"con":true,"img":false}]}
{"op":"mcm","clk":"5348142964","pt":1646214512397,"mc":[{"id":"1.195453623","rc":[{"atb":[[17,9.8]],"id":39658516}],"con":true,"img":false}]}
{"op":"mcm","clk":"5348142970","pt":1646214512500,"mc":[{"id":"1.195453623","rc":[{"atl":[[3.15,0]],"id":36074465}],"con":true,"img":false}]}
{"op":"mcm","clk":"5348143256","pt":1646214516318,"mc":[{"id":"1.195453623","rc":[{"atb":[[1.86,2]],"id":36074465}],"con":true,"img":false}]}
{"op":"mcm","clk":"5348143264","pt":1646214516420,"mc":[{"id":"1.195453623","rc":[{"atb":[[1.9,59.65]],"id":36074465}],"con":true,"img":false}]}
{"op":"mcm","clk":"5348143767","pt":1646214523548,"mc":[{"id":"1.195453623","rc":[{"atb":[[1.89,9.36]],"id":36074465},{"spn":1.82,"spf":1.0,"id":36074465},{"spn":6.8,"spf":"NaN","id":41788482},{"spn":142.0,"spf":"NaN","id":28222454}],"con":true,"img":false}]}
{"op":"mcm","clk":"5348144468","pt":1646214532561,"mc":[{"id":"1.195453623","rc":[{"atb":[[1.93,8.08]],"id":36074465}],"con":true,"img":false}]}
{"op":"mcm","clk":"5348144558","pt":1646214533807,"mc":[{"id":"1.195453623","rc":[{"atb":[[1.9,0]],"id":36074465}],"con":true,"img":false}]}
{"op":"mcm","clk":"5348144569","pt":1646214533910,"mc":[{"id":"1.195453623","rc":[{"atb":[[1.86,61.65]],"id":36074465}],"con":true,"img":false}]}
{"op":"mcm","clk":"5348145133","pt":1646214541632,"mc":[{"id":"1.195453623","rc":[{"atb":[[1.93,0]],"id":36074465}],"con":true,"img":false}]}
{"op":"mcm","clk":"5348145500","pt":1646214546868,"mc":[{"id":"1.195453623","rc":[{"atb":[[26,1.63]],"id":28222454}],"con":true,"img":false}]}
{"op":"mcm","clk":"5348145511","pt":1646214546968,"mc":[{"id":"1.195453623","rc":[{"atb":[[27,4.53]],"id":28222454}],"con":true,"img":false}]}
{"op":"mcm","clk":"5348146056","pt":1646214553656,"mc":[{"id":"1.195453623","rc":[{"atb":[[1.89,17.82]],"id":36074465}],"con":true,"img":false}]}
{"op":"mcm","clk":"5348148659","pt":1646214589943,"mc":[{"id":"1.195453623","rc":[{"atb":[[1.86,2]],"id":36074465},{"spn":1.79,"spf":1.0,"id":36074465}],"con":true,"img":false}]}
{"op":"mcm","clk":"5348148669","pt":1646214590046,"mc":[{"id":"1.195453623","rc":[{"atb":[[1.9,59.65]],"id":36074465}],"con":true,"img":false}]}
{"op":"mcm","clk":"5348149182","pt":1646214597621,"mc":[{"id":"1.195453623","rc":[{"atb":[[1.89,8.45]],"id":36074465}],"con":true,"img":false}]}
{"op":"mcm","clk":"5348149258","pt":1646214598711,"mc":[{"id":"1.195453623","rc":[{"atb":[[1.89,0]],"id":36074465}],"con":true,"img":false}]}
{"op":"mcm","clk":"5348149896","pt":1646214607755,"mc":[{"id":"1.195453623","rc":[{"atb":[[1.93,8.08]],"id":36074465}],"con":true,"img":false}]}
{"op":"mcm","clk":"5348150050","pt":1646214609777,"mc":[{"id":"1.195453623","rc":[{"atb":[[1.93,17.04]],"id":36074465}],"con":true,"img":false}]}
{"op":"mcm","clk":"5348150100","pt":1646214610349,"mc":[{"id":"1.195453623","rc":[{"atb":[[1.9,0]],"id":36074465}],"con":true,"img":false}]}
{"op":"mcm","clk":"5348150106","pt":1646214610449,"mc":[{"id":"1.195453623","rc":[{"atb":[[1.86,61.65]],"id":36074465}],"con":true,"img":false}]}
{"op":"mcm","clk":"5348150555","pt":1646214616792,"mc":[{"id":"1.195453623","rc":[{"atb":[[1.93,8.96]],"id":36074465}],"con":true,"img":false}]}
{"op":"mcm","clk":"5348150766","pt":1646214619950,"mc":[{"id":"1.195453623","rc":[{"atl":[[2.5,0],[2.48,0]],"id":36074465},{"trd":[[2.5,12.41],[2.48,2.58]],"ltp":2.5,"tv":14.99,"id":36074465},{"atl":[[75,0]],"id":39658516},{"trd":[[75,5.44]],"ltp":75.0,"tv":5.44,"id":39658516}],"con":true,"img":false}]}
{"op":"mcm","clk":"5348150786","pt":1646214620272,"mc":[{"id":"1.195453623","rc":[{"atb":[[1.95,6.36]],"id":36074465}],"con":true,"img":false}]}
{"op":"mcm","clk":"5348150940","pt":1646214622651,"mc":[{"id":"1.195453623","rc":[{"atb":[[12.5,0.88]],"id":37447009},{"atb":[[4.3,0]],"id":41788482},{"atl":[[100,0]],"id":39658516},{"atb":[[6.4,0]],"id":37286329}],"con":true,"img":false}]}
{"op":"mcm","clk":"5348150948","pt":1646214622753,"mc":[{"id":"1.195453623","rc":[{"atb":[[11,5.08]],"id":37447009},{"atb":[[4,17.71]],"id":41788482},{"atl":[[130,2.72]],"id":39658516},{"atb":[[6,10.82]],"id":37286329}],"con":true,"img":false}]}
{"op":"mcm","clk":"5348151378","pt":1646214628709,"mc":[{"id":"1.195453623","rc":[{"atb":[[44,0]],"id":28222454}],"con":true,"img":false}]}
{"op":"mcm","clk":"5348151384","pt":1646214628803,"mc":[{"id":"1.195453623","rc":[{"atb":[[1.89,8.45]],"id":36074465},{"atb":[[30,2.72]],"id":28222454}],"con":true,"img":false}]}
{"op":"mcm","clk":"5348151643","pt":1646214631868,"mc":[{"id":"1.195453623","rc":[{"atb":[[4.4,0]],"id":41788482}],"con":true,"img":false}]}
{"op":"mcm","clk":"5348152009","pt":1646214636790,"mc":[{"id":"1.195453623","rc":[{"atb":[[1.93,0]],"id":36074465}],"con":true,"img":false}]}
{"op":"mcm","clk":"5348152304","pt":1646214640790,"mc":[{"id":"1.195453623","rc":[{"atb":[[3.95,5.37]],"id":41788482}],"con":true,"img":false}]}
{"op":"mcm","clk":"5348152837","pt":1646214648398,"mc":[{"id":"1.195453623","rc":[{"atb":[[18,0]],"id":39658516}],"con":true,"img":false}]}
{"op":"mcm","clk":"5348152845","pt":1646214648501,"mc":[{"id":"1.195453623","rc":[{"atb":[[19,1.72]],"id":39658516}],"con":true,"img":false}]}
{"op":"mcm","clk":"5348152849","pt":1646214648605,"mc":[{"id":"1.195453623","rc":[{"atl":[[40,0]],"id":37447009},{"atl":[[3.05,0]],"id":36074465},{"atl":[[9.2,0]],"id":41788482},{"atl":[[6,0]],"id":42513983},{"atb":[[27,0]],"id":28222454},{"atl":[[240,0]],"id":28222454}],"con":true,"img":false}]}
{"op":"mcm","clk":"5348152857","pt":1646214648708,"mc":[{"id":"1.195453623","rc":[{"atl":[[34,2.72]],"id":37447009},{"atl":[[3.15,8.17],[2.96,28.51]],"id":36074465},{"atl":[[7.8,7.12]],"id":41788482},{"atl":[[5.5,11.69]],"id":42513983},{"atb":[[22,4.53]],"id":28222454},{"atl":[[200,0.24]],"id":28222454}],"con":true,"img":false}]}
{"op":"mcm","clk":"5348152892","pt":1646214649377,"mc":[{"id":"1.195453623","rc":[{"atl":[[38,0]],"id":37447009}],"con":true,"img":false}]}
{"op":"mcm","clk":"5348152900","pt":1646214649481,"mc":[{"id":"1.195453623","rc":[{"atl":[[1000,1.3]],"id":37447009}],"con":true,"img":false}]}
{"op":"mcm","clk":"5348153037","pt":1646214652001,"mc":[{"id":"1.195453623","rc":[{"spn":11.48,"spf":1.0,"id":37447009},{"atb":[[1.89,17.82]],"id":36074465},{"spn":1.82,"spf":1.0,"id":36074465},{"spn":5.95,"spf":"NaN","id":41788482},{"spn":74.5,"spf":"NaN","id":39658516},{"spn":4.32,"spf":"NaN","id":42513983},{"spn":6.71,"spf":1.0,"id":37286329},{"spn":121.0,"spf":"NaN","id":28222454}],"con":true,"img":false}]}
{"op":"mcm","clk":"5348154500","pt":1646214673436,"mc":[{"id":"1.195453623","rc":[{"atb":[[3.2,29.42]],"id":37447009},{"atl":[[75,2]],"id":37447009},{"atb":[[1.86,123.31]],"id":36074465},{"atl":[[3.9,30.6]],"id":36074465},{"atb":[[3.05,43.9]],"id":41788482},{"atl":[[55,2]],"id":41788482},{"atb":[[15,7.14]],"id":39658516},{"atl":[[620,2]],"id":39658516},{"atb":[[2.66,60.24]],"id":42513983},{"atl":[[36,2.86]],"id":42513983},{"atb":[[1.8,55.78]],"id":37286329},{"atl":[[19,5.56]],"id":37286329},{"atb":[[10,19.11]],"id":28222454},{"atl":[[370,2]],"id":28222454}],"con":true,"img":false}]}
{"op":"mcm","clk":"5348155482","pt":1646214688682,"mc":[{"id":"1.195453623","rc":[{"atl":[[990,0]],"id":28222454}],"con":true,"img":false}]}
{"op":"mcm","clk":"5348155489","pt":1646214688784,"mc":[{"id":"1.195453623","rc":[{"atl":[[320,1.33]],"id":28222454}],"con":true,"img":false}]}
{"op":"mcm","clk":"5348155698","pt":1646214692088,"mc":[{"id":"1.195453623","rc":[{"atb":[[7.6,39.91],[15,0]],"id":39658516}],"con":true,"img":false}]}
{"op":"mcm","clk":"5348156811","pt":1646214710484,"mc":[{"id":"1.195453623","rc":[{"atb":[[3.85,32.8],[3.2,0]],"id":37447009},{"atl":[[40,2.56],[55,0]],"id":41788482},{"atb":[[2.24,55.78],[1.8,0]],"id":37286329}],"con":true,"img":false}]}
{"op":"mcm","clk":"5348156823","pt":1646214710697,"mc":[{"id":"1.195453623","rc":[{"atl":[[3.15,0]],"id":36074465}],"con":true,"img":false}]}
{"op":"mcm","clk":"5348157599","pt":1646214722627,"mc":[{"id":"1.195453623","rc":[{"spn":1.84,"spf":1.0,"id":36074465},{"atb":[[7.2,0]],"id":37286329},{"spn":6.0,"spf":1.0,"id":37286329}],"con":true,"img":false}]}
{"op":"mcm","clk":"5348157615","pt":1646214722836,"mc":[{"id":"1.195453623","rc":[{"atb":[[7.4,1.57]],"id":37286329}],"con":true,"img":false}]}
{"op":"mcm","clk":"5348158148","pt":1646214730552,"mc":[{"id":"1.195453623","rc":[{"atl":[[3.8,37.57],[4,0]],"id":36074465}],"con":true,"img":false}]}
{"op":"mcm","clk":"5348158726","pt":1646214738970,"mc":[{"id":"1.195453623","rc":[{"atl":[[200,0]],"id":28222454}],"con":true,"img":false}]}
{"op":"mcm","clk":"5348158732","pt":1646214739073,"mc":[{"id":"1.195453623","rc":[{"atl":[[220,0.24]],"id":28222454}],"con":true,"img":false}]}
{"op":"mcm","clk":"5348158738","pt":1646214739176,"mc":[{"id":"1.195453623","rc":[{"atl":[[340,2],[370,0]],"id":28222454}],"con":true,"img":false}]}
{"op":"mcm","clk":"5348159016","pt":1646214743266,"mc":[{"id":"1.195453623","rc":[{"atl":[[330,0]],"id":28222454}],"con":true,"img":false}]}
{"op":"mcm","clk":"5348159021","pt":1646214743364,"mc":[{"id":"1.195453623","rc":[{"atl":[[300,2.72]],"id":28222454}],"con":true,"img":false}]}
{"op":"mcm","clk":"5348159037","pt":1646214743661,"mc":[{"id":"1.195453623","rc":[{"atl":[[320,0]],"id":28222454}],"con":true,"img":false}]}
{"op":"mcm","clk":"5348159048","pt":1646214743772,"mc":[{"id":"1.195453623","rc":[{"atl":[[290,1.33]],"id":28222454}],"con":true,"img":false}]}
{"op":"mcm","clk":"5348159092","pt":1646214744288,"mc":[{"id":"1.195453623","rc":[{"atl":[[290,0]],"id":28222454}],"con":true,"img":false}]}
{"op":"mcm","clk":"5348159100","pt":1646214744386,"mc":[{"id":"1.195453623","rc":[{"atl":[[1000,1.33]],"id":28222454}],"con":true,"img":false}]}
{"op":"mcm","clk":"5348159134","pt":1646214744856,"mc":[{"id":"1.195453623","rc":[{"atl":[[1000,0]],"id":28222454}],"con":true,"img":false}]}
{"op":"mcm","clk":"5348159145","pt":1646214744959,"mc":[{"id":"1.195453623","rc":[{"atl":[[290,1.33]],"id":28222454}],"con":true,"img":false}]}
{"op":"mcm","clk":"5348159186","pt":1646214745575,"mc":[{"id":"1.195453623","rc":[{"atl":[[290,0]],"id":28222454}],"con":true,"img":false}]}
{"op":"mcm","clk":"5348159195","pt":1646214745681,"mc":[{"id":"1.195453623","rc":[{"atl":[[1000,1.33]],"id":28222454}],"con":true,"img":false}]}
{"op":"mcm","clk":"5348159673","pt":1646214752661,"mc":[{"id":"1.195453623","rc":[{"atl":[[36,0],[15.5,6.9]],"id":42513983},{"atb":[[2.24,0],[2.42,58.04]],"id":37286329}],"con":true,"img":false}]}
{"op":"mcm","clk":"5348159978","pt":1646214757503,"mc":[{"id":"1.195453623","rc":[{"atb":[[3.5,0]],"id":37447009}],"con":true,"img":false}]}
{"op":"mcm","clk":"5348160258","pt":1646214761993,"mc":[{"id":"1.195453623","rc":[{"atb":[[1.8,211.18],[1.86,61.65]],"id":36074465},{"atb":[[3.05,0],[2.9,52.63]],"id":41788482},{"atl":[[620,0],[680,2]],"id":39658516},{"atb":[[2.54,64.94],[2.66,0]],"id":42513983}],"con":true,"img":false}]}
{"op":"mcm","clk":"5348160413","pt":1646214764209,"mc":[{"id":"1.195453623","rc":[{"atb":[[6,0]],"id":37286329}],"con":true,"img":false}]}
{"op":"mcm","clk":"5348160420","pt":1646214764342,"mc":[{"id":"1.195453623","rc":[{"atb":[[6.2,10.82]],"id":37286329}],"con":true,"img":false}]}
{"op":"mcm","clk":"5348167514","pt":1646214868256,"mc":[{"id":"1.195453623","rc":[{"spn":1.82,"spf":1.0,"id":36074465},{"atb":[[1.04,2.25]],"id":39658516},{"atb":[[1.03,2.25]],"id":37286329},{"spn":6.89,"spf":1.0,"id":37286329},{"spn":131.0,"spf":"NaN","id":28222454}],"con":true,"img":false}]}
{"op":"mcm","clk":"5348167532","pt":1646214868457,"mc":[{"id":"1.195453623","rc":[{"atb":[[1.04,0.19]],"id":39658516},{"atb":[[1.03,0.49]],"id":37286329}],"con":true,"img":false}]}
{"op":"mcm","clk":"5348167568","pt":1646214868870,"mc":[{"id":"1.195453623","rc":[{"atb":[[1.03,0]],"id":37286329}],"con":true,"img":false}]}
{"op":"mcm","clk":"5348167576","pt":1646214868974,"mc":[{"id":"1.195453623","rc":[{"atb":[[7.6,0.49]],"id":37286329}],"con":true,"img":false}]}
{"op":"mcm","clk":"5348167590","pt":1646214869181,"mc":[{"id":"1.195453623","rc":[{"atb":[[1.04,0]],"id":39658516}],"con":true,"img":false}]}
{"op":"mcm","clk":"5348167602","pt":1646214869285,"mc":[{"id":"1.195453623","rc":[{"atb":[[19.5,0.19]],"id":39658516}],"con":true,"img":false}]}
{"op":"mcm","clk":"5348170377","pt":1646214911719,"mc":[{"id":"1.195453623","rc":[{"atl":[[2.5,12.41]],"id":36074465}],"con":true,"img":false}]}
{"op":"mcm","clk":"5348170469","pt":1646214913008,"mc":[{"id":"1.195453623","rc":[{"atl":[[2.5,9.59]],"id":36074465},{"trd":[[2.5,18.04]],"ltp":2.5,"tv":18.04,"id":36074465}],"con":true,"img":false}]}
{"op":"mcm","clk":"5348172733","pt":1646214946678,"mc":[{"id":"1.195453623","rc":[{"atb":[[2.1,8.53]],"id":36074465},{"spn":1.83,"spf":1.0,"id":36074465},{"spn":74.75,"spf":"NaN","id":39658516},{"spn":7.14,"spf":1.0,"id":37286329}],"con":true,"img":false}]}
{"op":"mcm","clk":"5348172789","pt":1646214947456,"mc":[{"id":"1.195453623","rc":[{"atb":[[1.95,6.23]],"id":36074465}],"con":true,"img":false}]}
{"op":"mcm","clk":"5348172827","pt":1646214948075,"mc":[{"id":"1.195453623","rc":[{"atb":[[1.95,4.65]],"id":36074465}],"con":true,"img":false}]}
{"op":"mcm","clk":"5348172835","pt":1646214948180,"mc":[{"id":"1.195453623","rc":[{"atb":[[2.12,1.57]],"id":36074465}],"con":true,"img":false}]}
{"op":"mcm","clk":"5348172995","pt":1646214951068,"mc":[{"id":"1.195453623","rc":[{"atl":[[570,2],[680,0]],"id":39658516},{"atl":[[17.5,6.06],[19,0]],"id":37286329},{"atl":[[310,2],[340,0]],"id":28222454}],"con":true,"img":false}]}
{"op":"mcm","clk":"5348173037","pt":1646214951788,"mc":[{"id":"1.195453623","rc":[{"atb":[[1.01,0]],"id":37447009},{"atb":[[3.9,38.61]],"id":41788482},{"atb":[[3.1,27.83]],"id":42513983}],"con":true,"img":false}]}
{"op":"mcm","clk":"5348173045","pt":1646214951893,"mc":[{"id":"1.195453623","rc":[{"atb":[[11.5,1.51]],"id":37447009},{"atb":[[4.1,3.64]],"id":41788482},{"atb":[[3.2,1.63]],"id":42513983}],"con":true,"img":false}]}
{"op":"mcm","clk":"5348174706","pt":1646214979013,"mc":[{"id":"1.195453623","rc":[{"atl":[[140,14.2]],"id":37447009}],"con":true,"img":false}]}
{"op":"mcm","clk":"5348175151","pt":1646214986926,"mc":[{"id":"1.195453623","rc":[{"atb":[[19,0]],"id":39658516}],"con":true,"img":false}]}
{"op":"mcm","clk":"5348175160","pt":1646214987031,"mc":[{"id":"1.195453623","rc":[{"atb":[[20,1.72]],"id":39658516}],"con":true,"img":false}]}
{"op":"mcm","clk":"5348175179","pt":1646214987344,"mc":[{"id":"1.195453623","rc":[{"atl":[[1000,0]],"id":28222454}],"con":true,"img":false}]}
{"op":"mcm","clk":"5348175185","pt":1646214987447,"mc":[{"id":"1.195453623","rc":[{"atl":[[290,1.33]],"id":28222454}],"con":true,"img":false}]}
{"op":"mcm","clk":"5348175549","pt":1646214993337,"mc":[{"id":"1.195453623","rc":[{"atb":[[30,0]],"id":28222454}],"con":true,"img":false}]}
{"op":"mcm","clk":"5348175557","pt":1646214993440,"mc":[{"id":"1.195453623","rc":[{"atb":[[44,2.72]],"id":28222454}],"con":true,"img":false}]}
{"op":"mcm","clk":"5348175945","pt":1646214999648,"mc":[{"id":"1.195453623","rc":[{"atb":[[22,0]],"id":28222454}],"con":true,"img":false}]}
{"op":"mcm","clk":"5348175953","pt":1646214999750,"mc":[{"id":"1.195453623","rc":[{"atb":[[27,4.53]],"id":28222454}],"con":true,"img":false}]}
{"op":"mcm","clk":"5348176391","pt":1646215005789,"mc":[{"id":"1.195453623","rc":[{"atl":[[18,0]],"id":37286329}],"con":true,"img":false}]}
{"op":"mcm","clk":"5348176398","pt":1646215005889,"mc":[{"id":"1.195453623","rc":[{"atl":[[17,7.3]],"id":37286329}],"con":true,"img":false}]}
{"op":"mcm","clk":"5348177294","pt":1646215018378,"mc":[{"id":"1.195453623","rc":[{"atb":[[1.03,2.25]],"id":37447009},{"spn":11.76,"spf":1.0,"id":37447009},{"spn":1.83,"spf":1.0,"id":36074465},{"spn":75.0,"spf":"NaN","id":39658516},{"spn":4.35,"spf":"NaN","id":42513983},{"spn":132.0,"spf":"NaN","id":28222454}],"con":true,"img":false}]}
{"op":"mcm","clk":"5348177303","pt":1646215018483,"mc":[{"id":"1.195453623","rc":[{"atb":[[1.03,0.28]],"id":37447009}],"con":true,"img":false}]}
{"op":"mcm","clk":"5348177317","pt":1646215018684,"mc":[{"id":"1.195453623","rc":[{"atb":[[1.03,0]],"id":37447009}],"con":true,"img":false}]}
{"op":"mcm","clk":"5348177325","pt":1646215018787,"mc":[{"id":"1.195453623","rc":[{"atb":[[13,0.28]],"id":37447009}],"con":true,"img":false}]}
{"op":"mcm","clk":"5348178932","pt":1646215043513,"mc":[{"id":"1.195453623","rc":[{"atl":[[300,0]],"id":28222454}],"con":true,"img":false}]}
{"op":"mcm","clk":"5348178938","pt":1646215043671,"mc":[{"id":"1.195453623","rc":[{"atl":[[280,2.72]],"id":28222454}],"con":true,"img":false}]}
{"op":"mcm","clk":"5348179242","pt":1646215048421,"mc":[{"id":"1.195453623","rc":[{"atb":[[19.5,0],[1.04,2.25]],"id":39658516},{"atb":[[5.6,1.51]],"id":37286329}],"con":true,"img":false}]}
{"op":"mcm","clk":"5348179247","pt":1646215048526,"mc":[{"id":"1.195453623","rc":[{"atb":[[1.04,0.18]],"id":39658516},{"atb":[[5.7,30.39]],"id":37286329}],"con":true,"img":false}]}
{"op":"mcm","clk":"5348179255","pt":1646215048628,"mc":[{"id":"1.195453623","rc":[{"atb":[[1.04,0]],"id":39658516}],"con":true,"img":false}]}
{"op":"mcm","clk":"5348179261","pt":1646215048729,"mc":[{"id":"1.195453623","rc":[{"atb":[[21,0.18]],"id":39658516}],"con":true,"img":false}]}
{"op":"mcm","clk":"5348179572","pt":1646215053381,"mc":[{"id":"1.195453623","rc":[{"atl":[[290,0]],"id":28222454}],"con":true,"img":false}]}
{"op":"mcm","clk":"5348179578","pt":1646215053434,"mc":[{"id":"1.195453623","rc":[{"atl":[[270,1.33]],"id":28222454}],"con":true,"img":false}]}
{"op":"mcm","clk":"5348179610","pt":1646215053951,"mc":[{"id":"1.195453623","rc":[{"atl":[[270,0]],"id":28222454}],"con":true,"img":false}]}
{"op":"mcm","clk":"5348179615","pt":1646215054053,"mc":[{"id":"1.195453623","rc":[{"atl":[[1000,1.33]],"id":28222454}],"con":true,"img":false}]}
{"op":"mcm","clk":"5348179644","pt":1646215054520,"mc":[{"id":"1.195453623","rc":[{"atl":[[1000,0]],"id":28222454}],"con":true,"img":false}]}
{"op":"mcm","clk":"5348179652","pt":1646215054673,"mc":[{"id":"1.195453623","rc":[{"atl":[[270,1.33]],"id":28222454}],"con":true,"img":false}]}
{"op":"mcm","clk":"5348179696","pt":1646215055140,"mc":[{"id":"1.195453623","rc":[{"atl":[[270,0]],"id":28222454}],"con":true,"img":false}]}
{"op":"mcm","clk":"5348179703","pt":1646215055245,"mc":[{"id":"1.195453623","rc":[{"atl":[[1000,1.33]],"id":28222454}],"con":true,"img":false}]}
{"op":"mcm","clk":"5348179731","pt":1646215055659,"mc":[{"id":"1.195453623","rc":[{"atb":[[5.7,28.79]],"id":37286329}],"con":true,"img":false}]}
{"op":"mcm","clk":"5348179820","pt":1646215057257,"mc":[{"id":"1.195453623","rc":[{"atl":[[17,8.5]],"id":42513983}],"con":true,"img":false}]}
{"op":"mcm","clk":"5348180285","pt":1646215065672,"mc":[{"id":"1.195453623","rc":[{"atb":[[1.01,2.25]],"id":37286329}],"con":true,"img":false}]}
{"op":"mcm","clk":"5348180296","pt":1646215065875,"mc":[{"id":"1.195453623","rc":[{"atb":[[1.01,1.56]],"id":37286329}],"con":true,"img":false}]}
{"op":"mcm","clk":"5348180303","pt":1646215066080,"mc":[{"id":"1.195453623","rc":[{"atb":[[1.01,0]],"id":37286329}],"con":true,"img":false}]}
{"op":"mcm","clk":"5348180314","pt":1646215066182,"mc":[{"id":"1.195453623","rc":[{"atb":[[5.8,1.56]],"id":37286329}],"con":true,"img":false}]}
{"op":"mcm","clk":"5348180655","pt":1646215072788,"mc":[{"id":"1.195453623","rc":[{"atb":[[5.7,27.01]],"id":37286329}],"con":true,"img":false}]}
{"op":"mcm","clk":"5348181008","pt":1646215079997,"mc":[{"id":"1.195453623","rc":[{"spn":11.97,"spf":1.0,"id":37447009},{"atb":[[22,1.48]],"id":39658516},{"spn":76.0,"spf":"NaN","id":39658516}],"con":true,"img":false}]}
{"op":"mcm","clk":"5348181009","pt":1646215080100,"mc":[{"id":"1.195453623","rc":[{"atb":[[20,0]],"id":39658516}],"con":true,"img":false}]}
{"op":"mcm","clk":"5348181515","pt":1646215088412,"mc":[{"id":"1.195453623","rc":[{"atb":[[5.8,3.29]],"id":37286329}],"con":true,"img":false}]}
{"op":"mcm","clk":"5348185711","pt":1646215156301,"mc":[{"id":"1.195453623","rc":[{"atb":[[1.87,61.66],[1.8,102.18]],"id":36074465},{"atl":[[3.9,0],[3.65,30.6]],"id":36074465},{"spn":1.85,"spf":1.0,"id":36074465},{"atb":[[2.9,0],[3.15,42.14]],"id":41788482},{"atb":[[7.6,24.76]],"id":39658516},{"atl":[[570,0],[440,2]],"id":39658516},{"atb":[[2.72,97.98],[2.54,0]],"id":42513983},{"atl":[[16,6.67],[17.5,0]],"id":37286329},{"atb":[[10,8],[14,7.69]],"id":28222454}],"con":true,"img":false}]}
{"op":"mcm","clk":"5348185715","pt":1646215156403,"mc":[{"id":"1.195453623","rc":[{"atb":[[7.8,14.71]],"id":39658516}],"con":true,"img":false}]}
{"op":"mcm","clk":"5348186294","pt":1646215163930,"mc":[{"id":"1.195453623","rc":[{"atb":[[1.89,9.36]],"id":36074465}],"con":true,"img":false}]}
{"op":"mcm","clk":"5348186645","pt":1646215168655,"mc":[{"id":"1.195453623","rc":[{"atb":[[21,0],[1.04,2.25]],"id":39658516}],"con":true,"img":false}]}
{"op":"mcm","clk":"5348186661","pt":1646215168862,"mc":[{"id":"1.195453623","rc":[{"atb":[[1.04,0.16]],"id":39658516}],"con":true,"img":false}]}
{"op":"mcm","clk":"5348186677","pt":1646215169068,"mc":[{"id":"1.195453623","rc":[{"atb":[[1.04,0]],"id":39658516}],"con":true,"img":false}]}
{"op":"mcm","clk":"5348186686","pt":1646215169173,"mc":[{"id":"1.195453623","rc":[{"atb":[[23,0.16]],"id":39658516}],"con":true,"img":false}]}
{"op":"mcm","clk":"5348186980","pt":1646215172842,"mc":[{"id":"1.195453623","rc":[{"atb":[[1.9,8.35]],"id":36074465}],"con":true,"img":false}]}
{"op":"mcm","clk":"5348186993","pt":1646215173047,"mc":[{"id":"1.195453623","rc":[{"atl":[[520,2]],"id":39658516},{"atl":[[16.5,6.45]],"id":37286329},{"atl":[[280,4.72]],"id":28222454}],"con":true,"img":false}]}
{"op":"mcm","clk":"5348187000","pt":1646215173148,"mc":[{"id":"1.195453623","rc":[{"atb":[[7.8,0]],"id":39658516},{"atl":[[440,0]],"id":39658516},{"atl":[[16,0]],"id":37286329},{"atl":[[310,0]],"id":28222454}],"con":true,"img":false}]}
{"op":"mcm","clk":"5348187012","pt":1646215173358,"mc":[{"id":"1.195453623","rc":[{"atb":[[7.8,14.71]],"id":39658516}],"con":true,"img":false}]}
{"op":"mcm","clk":"5348187413","pt":1646215180061,"mc":[{"id":"1.195453623","rc":[{"atb":[[1.86,2]],"id":36074465}],"con":true,"img":false}]}
{"op":"mcm","clk":"5348187418","pt":1646215180164,"mc":[{"id":"1.195453623","rc":[{"atb":[[1.88,59.65]],"id":36074465}],"con":true,"img":false}]}
{"op":"mcm","clk":"5348187521","pt":1646215182043,"mc":[{"id":"1.195453623","rc":[{"atb":[[1.89,0]],"id":36074465}],"con":true,"img":false}]}
{"op":"mcm","clk":"5348187755","pt":1646215185891,"mc":[{"id":"1.195453623","rc":[{"atl":[[2.96,0]],"id":36074465}],"con":true,"img":false}]}
{"op":"mcm","clk":"5348187761","pt":1646215185978,"mc":[{"id":"1.195453623","rc":[{"atl":[[2.88,28.51]],"id":36074465}],"con":true,"img":false}]}
{"op":"mcm","clk":"5348187766","pt":1646215186037,"mc":[{"id":"1.195453623","rc":[{"atl":[[3.15,8.17]],"id":36074465}],"con":true,"img":false}]}
{"op":"mcm","clk":"5348187879","pt":1646215187846,"mc":[{"id":"1.195453623","rc":[{"atb":[[1.9,0]],"id":36074465}],"con":true,"img":false}]}
{"op":"mcm","clk":"5348188201","pt":1646215193599,"mc":[{"id":"1.195453623","rc":[{"atb":[[1.91,9.16]],"id":36074465}],"con":true,"img":false}]}
{"op":"mcm","clk":"5348188355","pt":1646215195885,"mc":[{"id":"1.195453623","rc":[{"atb":[[2.36,0]],"id":37286329}],"con":true,"img":false}]}
{"op":"mcm","clk":"5348188447","pt":1646215196974,"mc":[{"id":"1.195453623","rc":[{"atb":[[1.91,17.42]],"id":36074465}],"con":true,"img":false}]}
{"op":"mcm","clk":"5348188476","pt":1646215197496,"mc":[{"id":"1.195453623","rc":[{"atb":[[22,0]],"id":39658516}],"con":true,"img":false}]}
{"op":"mcm","clk":"5348188483","pt":1646215197598,"mc":[{"id":"1.195453623","rc":[{"atb":[[24,1.36]],"id":39658516}],"con":true,"img":false}]}
{"op":"mcm","clk":"5348189563","pt":1646215208904,"mc":[{"id":"1.195453623","rc":[{"atl":[[3.8,0]],"id":36074465},{"atl":[[17,0]],"id":37286329}],"con":true,"img":false}]}
{"op":"mcm","clk":"5348189571","pt":1646215208962,"mc":[{"id":"1.195453623","rc":[{"atl":[[3.6,37.57]],"id":36074465},{"atl":[[16,7.3]],"id":37286329}],"con":true,"img":false}]}
{"op":"mcm","clk":"5348189604","pt":1646215209472,"mc":[{"id":"1.195453623","rc":[{"atb":[[17.5,1.65]],"id":39658516}],"con":true,"img":false}]}
{"op":"mcm","clk":"5348193504","pt":1646215258757,"mc":[{"id":"1.195453623","rc":[{"spn":1.85,"spf":1.0,"id":36074465},{"atb":[[23,0],[1.04,2.25]],"id":39658516},{"spn":77.0,"spf":"NaN","id":39658516}],"con":true,"img":false}]}
{"op":"mcm","clk":"5348193513","pt":1646215258963,"mc":[{"id":"1.195453623","rc":[{"atl":[[3.15,0]],"id":36074465},{"atb":[[1.04,0.15]],"id":39658516}],"con":true,"img":false}]}
{"op":"mcm","clk":"5348193523","pt":1646215259166,"mc":[{"id":"1.195453623","rc":[{"atb":[[1.04,0]],"id":39658516}],"con":true,"img":false}]}
{"op":"mcm","clk":"5348193526","pt":1646215259268,"mc":[{"id":"1.195453623","rc":[{"atb":[[25,0.15]],"id":39658516}],"con":true,"img":false}]}
{"op":"mcm","clk":"5348194029","pt":1646215266497,"mc":[{"id":"1.195453623","rc":[{"atb":[[18,7.62]],"id":39658516}],"con":true,"img":false}]}
{"op":"mcm","clk":"5348194038","pt":1646215266599,"mc":[{"id":"1.195453623","rc":[{"atb":[[17,0]],"id":39658516}],"con":true,"img":false}]}
{"op":"mcm","clk":"5348194323","pt":1646215269995,"mc":[{"id":"1.195453623","rc":[{"atb":[[1.25,0]],"id":36074465}],"con":true,"img":false}]}
{"op":"mcm","clk":"5348195404","pt":1646215285634,"mc":[{"id":"1.195453623","rc":[{"atb":[[24,0]],"id":39658516}],"con":true,"img":false}]}
{"op":"mcm","clk":"5348195411","pt":1646215285676,"mc":[{"id":"1.195453623","rc":[{"atb":[[25,1.51]],"id":39658516}],"con":true,"img":false}]}
{"op":"mcm","clk":"5348195887","pt":1646215293142,"mc":[{"id":"1.195453623","rc":[{"atb":[[2.72,47.52],[2.6,62.5]],"id":42513983},{"atl":[[16.5,0],[17.5,6.06]],"id":37286329},{"atb":[[10.5,10.53],[14,0]],"id":28222454},{"atl":[[280,2.72],[310,2]],"id":28222454}],"con":true,"img":false}]}
{"op":"mcm","clk":"5348195943","pt":1646215293808,"mc":[{"id":"1.195453623","rc":[{"atl":[[1000,0]],"id":28222454}],"con":true,"img":false}]}
{"op":"mcm","clk":"5348195951","pt":1646215294020,"mc":[{"id":"1.195453623","rc":[{"atb":[[17.5,0]],"id":39658516},{"atl":[[270,1.33]],"id":28222454}],"con":true,"img":false}]}
{"op":"mcm","clk":"5348195960","pt":1646215294029,"mc":[{"id":"1.195453623","rc":[{"atb":[[18.5,2.23]],"id":39658516}],"con":true,"img":false}]}
{"op":"mcm","clk":"5348195982","pt":1646215294430,"mc":[{"id":"1.195453623","rc":[{"atl":[[270,0]],"id":28222454}],"con":true,"img":false}]}
{"op":"mcm","clk":"5348195989","pt":1646215294531,"mc":[{"id":"1.195453623","rc":[{"atl":[[1000,1.33]],"id":28222454}],"con":true,"img":false}]}
{"op":"mcm","clk":"5348196156","pt":1646215296821,"mc":[{"id":"1.195453623","rc":[{"atl":[[16,0]],"id":37286329}],"con":true,"img":false}]}
{"op":"mcm","clk":"5348196163","pt":1646215296912,"mc":[{"id":"1.195453623","rc":[{"atl":[[17,7.3]],"id":37286329}],"con":true,"img":false}]}
{"op":"mcm","clk":"5348196444","pt":1646215302008,"mc":[{"id":"1.195453623","rc":[{"atb":[[19,1.72]],"id":39658516}],"con":true,"img":false}]}
{"op":"mcm","clk":"5348196451","pt":1646215302113,"mc":[{"id":"1.195453623","rc":[{"atb":[[25,0.15]],"id":39658516}],"con":true,"img":false}]}
{"op":"mcm","clk":"5348197611","pt":1646215318852,"mc":[{"id":"1.195453623","rc":[{"atb":[[25,0],[1.04,2.25]],"id":39658516},{"spn":74.5,"spf":"NaN","id":39658516}],"con":true,"img":false}]}
{"op":"mcm","clk":"5348197617","pt":1646215318956,"mc":[{"id":"1.195453623","rc":[{"atb":[[1.04,0.15]],"id":39658516}],"con":true,"img":false}]}
{"op":"mcm","clk":"5348197622","pt":1646215319057,"mc":[{"id":"1.195453623","rc":[{"atb":[[1.04,0]],"id":39658516}],"con":true,"img":false}]}
{"op":"mcm","clk":"5348197627","pt":1646215319162,"mc":[{"id":"1.195453623","rc":[{"atb":[[19.5,0.15]],"id":39658516}],"con":true,"img":false}]}
{"op":"mcm","clk":"5348199773","pt":1646215348702,"mc":[{"id":"1.195453623","rc":[{"atb":[[18,0]],"id":39658516}],"con":true,"img":false}]}
{"op":"mcm","clk":"5348199780","pt":1646215348804,"mc":[{"id":"1.195453623","rc":[{"atb":[[19,9.35]],"id":39658516}],"con":true,"img":false}]}
{"op":"mcm","clk":"5348201916","pt":1646215382216,"mc":[{"id":"1.195453623","rc":[{"atb":[[1.04,1.66]],"id":36074465},{"spn":74.75,"spf":"NaN","id":39658516},{"atb":[[1.04,1.66]],"id":42513983}],"con":true,"img":false}]}
{"op":"mcm","clk":"5348201935","pt":1646215382527,"mc":[{"id":"1.195453623","rc":[{"atb":[[1.04,1.65]],"id":36074465},{"atb":[[1.04,1.65]],"id":42513983}],"con":true,"img":false}]}
{"op":"mcm","clk":"5348201950","pt":1646215382736,"mc":[{"id":"1.195453623","rc":[{"atb":[[1.04,0]],"id":36074465},{"atb":[[1.04,0]],"id":42513983}],"con":true,"img":false}]}
{"op":"mcm","clk":"5348201957","pt":1646215382839,"mc":[{"id":"1.195453623","rc":[{"atb":[[2.16,1.65]],"id":36074465},{"atb":[[3.3,1.65]],"id":42513983}],"con":true,"img":false}]}
{"op":"mcm","clk":"5348202006","pt":1646215383414,"mc":[{"id":"1.195453623","rc":[{"atl":[[1000,0]],"id":28222454}],"con":true,"img":false}]}
{"op":"mcm","clk":"5348202012","pt":1646215383516,"mc":[{"id":"1.195453623","rc":[{"atl":[[270,1.33]],"id":28222454}],"con":true,"img":false}]}
{"op":"mcm","clk":"5348202053","pt":1646215384032,"mc":[{"id":"1.195453623","rc":[{"atl":[[270,0]],"id":28222454}],"con":true,"img":false}]}
{"op":"mcm","clk":"5348202058","pt":1646215384134,"mc":[{"id":"1.195453623","rc":[{"atl":[[1000,1.33]],"id":28222454}],"con":true,"img":false}]}
{"op":"mcm","clk":"5348202098","pt":1646215384611,"mc":[{"id":"1.195453623","rc":[{"atl":[[1000,0]],"id":28222454}],"con":true,"img":false}]}
{"op":"mcm","clk":"5348202104","pt":1646215384711,"mc":[{"id":"1.195453623","rc":[{"atl":[[270,1.33]],"id":28222454}],"con":true,"img":false}]}
{"op":"mcm","clk":"5348202136","pt":1646215385231,"mc":[{"id":"1.195453623","rc":[{"atl":[[270,0]],"id":28222454}],"con":true,"img":false}]}
{"op":"mcm","clk":"5348202143","pt":1646215385333,"mc":[{"id":"1.195453623","rc":[{"atl":[[1000,1.33]],"id":28222454}],"con":true,"img":false}]}
{"op":"mcm","clk":"5348216582","pt":1646215560469,"mc":[{"id":"1.195453623","rc":[{"atb":[[1.06,1.66]],"id":37447009},{"atb":[[1.01,1.66]],"id":36074465},{"spn":1.86,"spf":1.0,"id":36074465},{"atb":[[1.02,1.66]],"id":41788482},{"atb":[[1.09,1.66]],"id":39658516},{"atb":[[1.02,1.66]],"id":42513983},{"spn":4.4,"spf":"NaN","id":42513983},{"atb":[[1.04,1.66]],"id":37286329},{"atb":[[1.21,1.66]],"id":28222454}],"con":true,"img":false}]}
{"op":"mcm","clk":"5348216602","pt":1646215560679,"mc":[{"id":"1.195453623","rc":[{"atb":[[1.06,0.12]],"id":37447009},{"atb":[[1.01,0.76]],"id":36074465},{"atb":[[1.02,0.39]],"id":41788482},{"atb":[[1.09,0.08]],"id":39658516},{"atb":[[1.02,0.49]],"id":42513983},{"atb":[[1.04,0.21]],"id":37286329},{"atb":[[1.21,0.03]],"id":28222454}],"con":true,"img":false}]}
{"op":"mcm","clk":"5348216623","pt":1646215560870,"mc":[{"id":"1.195453623","rc":[{"atb":[[1.06,0]],"id":37447009},{"atb":[[1.01,0]],"id":36074465},{"atb":[[1.02,0]],"id":41788482},{"atb":[[1.09,0]],"id":39658516},{"atb":[[1.02,0]],"id":42513983},{"atb":[[1.04,0]],"id":37286329},{"atb":[[1.21,0]],"id":28222454}],"con":true,"img":false}]}
{"op":"mcm","clk":"5348216632","pt":1646215560937,"mc":[{"id":"1.195453623","rc":[{"atb":[[13,0.41]],"id":37447009},{"atb":[[2.18,0.76]],"id":36074465},{"atb":[[4.2,0.39]],"id":41788482},{"atb":[[19.5,0.23]],"id":39658516},{"atb":[[3.35,0.49]],"id":42513983},{"atb":[[7.6,0.71]],"id":37286329},{"atb":[[46,0.03]],"id":28222454}],"con":true,"img":false}]}
{"op":"mcm","clk":"5348216736","pt":1646215562044,"mc":[{"id":"1.195453623","rc":[{"atb":[[18.5,0.58]],"id":39658516}],"con":true,"img":false}]}
{"op":"mcm","clk":"5348216747","pt":1646215562151,"mc":[{"id":"1.195453623","rc":[{"atb":[[19.5,1.89]],"id":39658516}],"con":true,"img":false}]}
{"op":"mcm","clk":"5348217076","pt":1646215565335,"mc":[{"id":"1.195453623","rc":[{"atb":[[19,1.72]],"id":39658516}],"con":true,"img":false}]}
{"op":"mcm","clk":"5348217087","pt":1646215565449,"mc":[{"id":"1.195453623","rc":[{"atb":[[17,7.62]],"id":39658516}],"con":true,"img":false}]}
{"op":"mcm","clk":"5348217147","pt":1646215566058,"mc":[{"id":"1.195453623","rc":[{"atb":[[19.5,0.23]],"id":39658516}],"con":true,"img":false}]}
{"op":"mcm","clk":"5348217153","pt":1646215566164,"mc":[{"id":"1.195453623","rc":[{"atb":[[17.5,1.65]],"id":39658516}],"con":true,"img":false}]}
{"op":"mcm","clk":"5348218858","pt":1646215585161,"mc":[{"id":"1.195453623","rc":[{"atl":[[120,8.2]],"id":37447009}],"con":true,"img":false}]}
{"op":"mcm","clk":"5348219757","pt":1646215594896,"mc":[{"id":"1.195453623","rc":[{"atb":[[19,0]],"id":39658516}],"con":true,"img":false}]}
{"op":"mcm","clk":"5348219767","pt":1646215594995,"mc":[{"id":"1.195453623","rc":[{"atb":[[20,1.72]],"id":39658516}],"con":true,"img":false}]}
{"op":"mcm","clk":"5348219811","pt":1646215595374,"mc":[{"id":"1.195453623","rc":[{"atl":[[1000,0]],"id":28222454}],"con":true,"img":false}]}
{"op":"mcm","clk":"5348219818","pt":1646215595474,"mc":[{"id":"1.195453623","rc":[{"atl":[[270,1.33]],"id":28222454}],"con":true,"img":false}]}
{"op":"mcm","clk":"5348219882","pt":1646215596201,"mc":[{"id":"1.195453623","rc":[{"atl":[[270,0]],"id":28222454}],"con":true,"img":false}]}
{"op":"mcm","clk":"5348219890","pt":1646215596306,"mc":[{"id":"1.195453623","rc":[{"atl":[[1000,1.33]],"id":28222454}],"con":true,"img":false}]}
{"op":"mcm","clk":"5348221994","pt":1646215621331,"mc":[{"id":"1.195453623","rc":[{"spn":12.04,"spf":1.0,"id":37447009},{"spn":1.86,"spf":1.0,"id":36074465},{"spn":6.0,"spf":"NaN","id":41788482},{"atb":[[17,0]],"id":39658516},{"spn":75.0,"spf":"NaN","id":39658516},{"spn":4.42,"spf":"NaN","id":42513983},{"spn":7.25,"spf":1.0,"id":37286329},{"spn":133.0,"spf":"NaN","id":28222454}],"con":true,"img":false}]}
{"op":"mcm","clk":"5348222001","pt":1646215621431,"mc":[{"id":"1.195453623","rc":[{"atb":[[18,7.62]],"id":39658516}],"con":true,"img":false}]}
{"op":"mcm","clk":"5348222694","pt":1646215630010,"mc":[{"id":"1.195453623","rc":[{"spl":[[1.01,304.1]],"id":36074465}],"con":true,"img":false}]}
{"op":"mcm","clk":"5348226655","pt":1646215676485,"mc":[{"id":"1.195453623","rc":[{"atb":[[1.04,2.25]],"id":39658516}],"con":true,"img":false}]}
{"op":"mcm","clk":"5348226665","pt":1646215676584,"mc":[{"id":"1.195453623","rc":[{"atb":[[19.5,0.08]],"id":39658516}],"con":true,"img":false}]}
{"op":"mcm","clk":"5348226676","pt":1646215676694,"mc":[{"id":"1.195453623","rc":[{"atb":[[1.04,0.18]],"id":39658516}],"con":true,"img":false}]}
{"op":"mcm","clk":"5348226702","pt":1646215676963,"mc":[{"id":"1.195453623","rc":[{"atb":[[1.04,0]],"id":39658516}],"con":true,"img":false}]}
{"op":"mcm","clk":"5348226710","pt":1646215677068,"mc":[{"id":"1.195453623","rc":[{"atb":[[21,0.18]],"id":39658516}],"con":true,"img":false}]}
{"op":"mcm","clk":"5348226858","pt":1646215678594,"mc":[{"id":"1.195453623","rc":[{"atl":[[2.3,30.51]],"id":36074465}],"con":true,"img":false}]}
{"op":"mcm","clk":"5348227503","pt":1646215685416,"mc":[{"id":"1.195453623","rc":[{"spn":1.85,"spf":1.0,"id":36074465},{"atl":[[7.8,0]],"id":41788482},{"spn":8.1,"spf":"NaN","id":41788482},{"spn":75.5,"spf":"NaN","id":39658516}],"con":true,"img":false}]}
{"op":"mcm","clk":"5348227517","pt":1646215685486,"mc":[{"id":"1.195453623","rc":[{"atl":[[8.4,7.12]],"id":41788482}],"con":true,"img":false}]}
{"op":"mcm","clk":"5348227583","pt":1646215686210,"mc":[{"id":"1.195453623","rc":[{"atl":[[1000,0]],"id":28222454}],"con":true,"img":false}]}
{"op":"mcm","clk":"5348227592","pt":1646215686316,"mc":[{"id":"1.195453623","rc":[{"atl":[[270,1.33]],"id":28222454}],"con":true,"img":false}]}
{"op":"mcm","clk":"5348227653","pt":1646215686902,"mc":[{"id":"1.195453623","rc":[{"atl":[[270,0]],"id":28222454}],"con":true,"img":false}]}
{"op":"mcm","clk":"5348227661","pt":1646215687004,"mc":[{"id":"1.195453623","rc":[{"atl":[[1000,1.33]],"id":28222454}],"con":true,"img":false}]}
{"op":"mcm","clk":"5348227723","pt":1646215687691,"mc":[{"id":"1.195453623","rc":[{"atl":[[1000,0]],"id":28222454}],"con":true,"img":false}]}
{"op":"mcm","clk":"5348227732","pt":1646215687790,"mc":[{"id":"1.195453623","rc":[{"atl":[[270,1.33]],"id":28222454}],"con":true,"img":false}]}
{"op":"mcm","clk":"5348227781","pt":1646215688414,"mc":[{"id":"1.195453623","rc":[{"atl":[[270,0]],"id":28222454}],"con":true,"img":false}]}
{"op":"mcm","clk":"5348227789","pt":1646215688471,"mc":[{"id":"1.195453623","rc":[{"atl":[[1000,1.33]],"id":28222454}],"con":true,"img":false}]}
{"op":"mcm","clk":"5348228912","pt":1646215700924,"mc":[{"id":"1.195453623","rc":[{"atl":[[2.3,24.82]],"id":36074465},{"trd":[[2.3,11.37]],"ltp":2.3,"tv":11.37,"id":36074465}],"con":true,"img":false}]}
{"op":"mcm","clk":"5348228967","pt":1646215701514,"mc":[{"id":"1.195453623","rc":[{"atb":[[4.1,4.95]],"id":41788482},{"atb":[[3.2,2.96]],"id":42513983},{"atb":[[6.4,1.37]],"id":37286329}],"con":true,"img":false}]}
{"op":"mcm","clk":"5348228983","pt":1646215701729,"mc":[{"id":"1.195453623","rc":[{"atb":[[1.03,2.25],[7.6,0.21]],"id":37286329}],"con":true,"img":false}]}
{"op":"mcm","clk":"5348228996","pt":1646215701888,"mc":[{"id":"1.195453623","rc":[{"atb":[[1.03,0.49]],"id":37286329}],"con":true,"img":false}]}
{"op":"mcm","clk":"5348229014","pt":1646215702100,"mc":[{"id":"1.195453623","rc":[{"atb":[[1.03,0]],"id":37286329}],"con":true,"img":false}]}
{"op":"mcm","clk":"5348229026","pt":1646215702205,"mc":[{"id":"1.195453623","rc":[{"atb":[[6.6,0.49]],"id":37286329}],"con":true,"img":false}]}
{"op":"mcm","clk":"5348229228","pt":1646215704832,"mc":[{"id":"1.195453623","rc":[{"atb":[[20,0],[22,1.48]],"id":39658516}],"con":true,"img":false}]}
{"op":"mcm","clk":"5348229412","pt":1646215707022,"mc":[{"id":"1.195453623","rc":[{"atb":[[19.5,0.07]],"id":39658516}],"con":true,"img":false}]}
{"op":"mcm","clk":"5348229431","pt":1646215707230,"mc":[{"id":"1.195453623","rc":[{"atb":[[2.18,0]],"id":36074465},{"atb":[[4.2,0]],"id":41788482},{"atb":[[19.5,0]],"id":39658516},{"atb":[[3.35,0]],"id":42513983},{"atb":[[7.6,0]],"id":37286329}],"con":true,"img":false}]}
{"op":"mcm","clk":"5348229439","pt":1646215707330,"mc":[{"id":"1.195453623","rc":[{"atb":[[2.16,2.42]],"id":36074465},{"atb":[[4.2,0.39]],"id":41788482},{"atb":[[23,0.07]],"id":39658516},{"atb":[[3.35,0.49]],"id":42513983},{"atb":[[7.6,0.21]],"id":37286329}],"con":true,"img":false}]}
{"op":"mcm","clk":"5348229665","pt":1646215709799,"mc":[{"id":"1.195453623","rc":[{"atl":[[2.88,0]],"id":36074465}],"con":true,"img":false}]}
{"op":"mcm","clk":"5348229675","pt":1646215709910,"mc":[{"id":"1.195453623","rc":[{"atl":[[2.68,28.51]],"id":36074465}],"con":true,"img":false}]}
{"op":"mcm","clk":"5348231536","pt":1646215730048,"mc":[{"id":"1.195453623","rc":[{"atl":[[8.4,0]],"id":41788482}],"con":true,"img":false}]}
{"op":"mcm","clk":"5348231545","pt":1646215730151,"mc":[{"id":"1.195453623","rc":[{"atl":[[8.2,7.12]],"id":41788482}],"con":true,"img":false}]}
{"op":"mcm","clk":"5348233656","pt":1646215753678,"mc":[{"id":"1.195453623","rc":[{"spn":6.2,"spf":"NaN","id":41788482},{"spn":76.5,"spf":"NaN","id":39658516},{"atb":[[2.6,58.04],[2.42,0]],"id":37286329},{"spn":7.1,"spf":1.0,"id":37286329}],"con":true,"img":false}]}
{"op":"mcm","clk":"5348237702","pt":1646215796689,"mc":[{"id":"1.195453623","rc":[{"atb":[[1.01,2.25]],"id":41788482},{"atb":[[21,0],[1.04,2.25]],"id":39658516},{"atb":[[1.03,2.25],[6.6,0]],"id":37286329}],"con":true,"img":false}]}
{"op":"mcm","clk":"5348237721","pt":1646215796897,"mc":[{"id":"1.195453623","rc":[{"atb":[[1.01,0.87]],"id":41788482},{"atb":[[1.04,0.15]],"id":39658516},{"atb":[[1.03,0.48]],"id":37286329}],"con":true,"img":false}]}
{"op":"mcm","clk":"5348237733","pt":1646215797002,"mc":[{"id":"1.195453623","rc":[{"atb":[[17.5,0]],"id":39658516},{"atb":[[5.6,0]],"id":37286329}],"con":true,"img":false}]}
{"op":"mcm","clk":"5348237744","pt":1646215797104,"mc":[{"id":"1.195453623","rc":[{"atb":[[1.01,0]],"id":41788482},{"atb":[[18.5,2.23]],"id":39658516},{"atb":[[6.4,2.89]],"id":37286329}],"con":true,"img":false}]}
{"op":"mcm","clk":"5348237757","pt":1646215797235,"mc":[{"id":"1.195453623","rc":[{"atb":[[4.3,0.87]],"id":41788482}],"con":true,"img":false}]}
{"op":"mcm","clk":"5348237776","pt":1646215797393,"mc":[{"id":"1.195453623","rc":[{"atb":[[1.04,0]],"id":39658516}],"con":true,"img":false}]}
{"op":"mcm","clk":"5348237788","pt":1646215797490,"mc":[{"id":"1.195453623","rc":[{"atb":[[24,0.15]],"id":39658516}],"con":true,"img":false}]}
{"op":"mcm","clk":"5348237795","pt":1646215797592,"mc":[{"id":"1.195453623","rc":[{"atb":[[1.03,0]],"id":37286329}],"con":true,"img":false}]}
{"op":"mcm","clk":"5348237802","pt":1646215797697,"mc":[{"id":"1.195453623","rc":[{"atb":[[7.8,0.48]],"id":37286329}],"con":true,"img":false}]}
{"op":"mcm","clk":"5348240701","pt":1646215831065,"mc":[{"id":"1.195453623","rc":[{"spn":6.25,"spf":"NaN","id":41788482},{"atb":[[22,0],[25,1.3]],"id":39658516},{"spn":77.5,"spf":"NaN","id":39658516},{"spn":7.31,"spf":1.0,"id":37286329}],"con":true,"img":false}]}
{"op":"mcm","clk":"5348242996","pt":1646215853567,"mc":[{"id":"1.195453623","rc":[{"atb":[[18,0]],"id":39658516}],"con":true,"img":false}]}
{"op":"mcm","clk":"5348243006","pt":1646215853665,"mc":[{"id":"1.195453623","rc":[{"atb":[[19,7.62]],"id":39658516}],"con":true,"img":false}]}
{"op":"mcm","clk":"5348246231","pt":1646215886893,"mc":[{"id":"1.195453623","rc":[{"atb":[[3.9,0]],"id":41788482}],"con":true,"img":false}]}
{"op":"mcm","clk":"5348246243","pt":1646215887006,"mc":[{"id":"1.195453623","rc":[{"atb":[[4,56.33]],"id":41788482}],"con":true,"img":false}]}
{"op":"mcm","clk":"5348246587","pt":1646215891154,"mc":[{"id":"1.195453623","rc":[{"atb":[[4,17.71]],"id":41788482}],"con":true,"img":false}]}
{"op":"mcm","clk":"5348246593","pt":1646215891258,"mc":[{"id":"1.195453623","rc":[{"atb":[[3.9,38.61]],"id":41788482}],"con":true,"img":false}]}
{"op":"mcm","clk":"5348249016","pt":1646215916912,"mc":[{"id":"1.195453623","rc":[{"atb":[[1.05,2.25]],"id":39658516}],"con":true,"img":false}]}
{"op":"mcm","clk":"5348249022","pt":1646215916965,"mc":[{"id":"1.195453623","rc":[{"atb":[[24,0]],"id":39658516}],"con":true,"img":false}]}
{"op":"mcm","clk":"5348249033","pt":1646215917075,"mc":[{"id":"1.195453623","rc":[{"atb":[[1.05,0.14]],"id":39658516}],"con":true,"img":false}]}
{"op":"mcm","clk":"5348249048","pt":1646215917279,"mc":[{"id":"1.195453623","rc":[{"atb":[[1.05,0]],"id":39658516}],"con":true,"img":false}]}
{"op":"mcm","clk":"5348249059","pt":1646215917381,"mc":[{"id":"1.195453623","rc":[{"atb":[[26,0.14]],"id":39658516}],"con":true,"img":false}]}
{"op":"mcm","clk":"5348249112","pt":1646215918002,"mc":[{"id":"1.195453623","rc":[{"atb":[[18.5,0.58]],"id":39658516}],"con":true,"img":false}]}
{"op":"mcm","clk":"5348249121","pt":1646215918108,"mc":[{"id":"1.195453623","rc":[{"atb":[[19.5,1.65]],"id":39658516}],"con":true,"img":false}]}
{"op":"mcm","clk":"5348249193","pt":1646215918885,"mc":[{"id":"1.195453623","rc":[{"atl":[[1000,0]],"id":28222454}],"con":true,"img":false}]}
{"op":"mcm","clk":"5348249202","pt":1646215918988,"mc":[{"id":"1.195453623","rc":[{"atb":[[19,0]],"id":39658516},{"atl":[[270,1.33]],"id":28222454}],"con":true,"img":false}]}
{"op":"mcm","clk":"5348249212","pt":1646215919096,"mc":[{"id":"1.195453623","rc":[{"atb":[[17,7.62]],"id":39658516}],"con":true,"img":false}]}
{"op":"mcm","clk":"5348249220","pt":1646215919197,"mc":[{"id":"1.195453623","rc":[{"atb":[[9.8,1.31]],"id":39658516}],"con":true,"img":false}]}
{"op":"mcm","clk":"5348249249","pt":1646215919615,"mc":[{"id":"1.195453623","rc":[{"atl":[[270,0]],"id":28222454}],"con":true,"img":false}]}
{"op":"mcm","clk":"5348249257","pt":1646215919718,"mc":[{"id":"1.195453623","rc":[{"atl":[[1000,1.33]],"id":28222454}],"con":true,"img":false}]}
{"op":"mcm","clk":"5348249276","pt":1646215919926,"mc":[{"id":"1.195453623","rc":[{"atb":[[19.5,0]],"id":39658516}],"con":true,"img":false}]}
{"op":"mcm","clk":"5348249286","pt":1646215919980,"mc":[{"id":"1.195453623","rc":[{"atb":[[17.5,1.65]],"id":39658516}],"con":true,"img":false}]}
{"op":"mcm","clk":"5348251712","pt":1646215947036,"mc":[{"id":"1.195453623","rc":[{"atb":[[25,0],[27,1.2]],"id":39658516}],"con":true,"img":false}]}
{"op":"mcm","clk":"5348254452","pt":1646215974998,"mc":[{"id":"1.195453623","rc":[{"atb":[[17,0]],"id":39658516},{"spn":78.5,"spf":"NaN","id":39658516}],"con":true,"img":false}]}
{"op":"mcm","clk":"5348254461","pt":1646215975100,"mc":[{"id":"1.195453623","rc":[{"atb":[[18,7.62]],"id":39658516}],"con":true,"img":false}]}
{"op":"mcm","clk":"5348254795","pt":1646215977800,"mc":[{"id":"1.195453623","rc":[{"atb":[[17.5,0]],"id":39658516}],"con":true,"img":false}]}
{"op":"mcm","clk":"5348254859","pt":1646215978051,"mc":[{"id":"1.195453623","rc":[{"atb":[[18.5,2.23],[18,0]],"id":39658516}],"con":true,"img":false}]}
{"op":"mcm","clk":"5348254903","pt":1646215978184,"mc":[{"id":"1.195453623","rc":[{"atb":[[17,7.62]],"id":39658516}],"con":true,"img":false}]}
{"op":"mcm","clk":"5348254963","pt":1646215978624,"mc":[{"id":"1.195453623","rc":[{"atb":[[18.5,0.58]],"id":39658516}],"con":true,"img":false}]}
{"op":"mcm","clk":"5348254976","pt":1646215978666,"mc":[{"id":"1.195453623","rc":[{"atb":[[17.5,1.65]],"id":39658516}],"con":true,"img":false}]}
{"op":"mcm","clk":"5348257348","pt":1646216003238,"mc":[{"id":"1.195453623","rc":[{"atb":[[3.9,0]],"id":41788482}],"con":true,"img":false}]}
{"op":"mcm","clk":"5348257358","pt":1646216003343,"mc":[{"id":"1.195453623","rc":[{"atb":[[4,56.33]],"id":41788482}],"con":true,"img":false}]}
{"op":"mcm","clk":"5348257435","pt":1646216004124,"mc":[{"id":"1.195453623","rc":[{"atl":[[1000,0]],"id":28222454}],"con":true,"img":false}]}
{"op":"mcm","clk":"5348257445","pt":1646216004227,"mc":[{"id":"1.195453623","rc":[{"atl":[[270,1.33]],"id":28222454}],"con":true,"img":false}]}
{"op":"mcm","clk":"5348257523","pt":1646216004906,"mc":[{"id":"1.195453623","rc":[{"atl":[[270,0]],"id":28222454}],"con":true,"img":false}]}
{"op":"mcm","clk":"5348257531","pt":1646216005010,"mc":[{"id":"1.195453623","rc":[{"atl":[[1000,1.33]],"id":28222454}],"con":true,"img":false}]}
{"op":"mcm","clk":"5348257585","pt":1646216005631,"mc":[{"id":"1.195453623","rc":[{"atb":[[3.95,2.82]],"id":41788482}],"con":true,"img":false}]}
{"op":"mcm","clk":"5348257594","pt":1646216005736,"mc":[{"id":"1.195453623","rc":[{"atl":[[1000,0]],"id":28222454}],"con":true,"img":false}]}
{"op":"mcm","clk":"5348257606","pt":1646216005843,"mc":[{"id":"1.195453623","rc":[{"atl":[[270,1.33]],"id":28222454}],"con":true,"img":false}]}
{"op":"mcm","clk":"5348257667","pt":1646216006416,"mc":[{"id":"1.195453623","rc":[{"atl":[[270,0]],"id":28222454}],"con":true,"img":false}]}
{"op":"mcm","clk":"5348257677","pt":1646216006522,"mc":[{"id":"1.195453623","rc":[{"atl":[[1000,1.33]],"id":28222454}],"con":true,"img":false}]}
{"op":"mcm","clk":"5348257871","pt":1646216008513,"mc":[{"id":"1.195453623","rc":[{"atb":[[4,17.71]],"id":41788482}],"con":true,"img":false}]}
{"op":"mcm","clk":"5348257884","pt":1646216008617,"mc":[{"id":"1.195453623","rc":[{"atb":[[3.9,38.61]],"id":41788482}],"con":true,"img":false}]}
{"op":"mcm","clk":"5348259929","pt":1646216026540,"mc":[{"id":"1.195453623","rc":[{"atb":[[3.95,5.37]],"id":41788482}],"con":true,"img":false}]}
{"op":"mcm","clk":"5348260688","pt":1646216033869,"mc":[{"id":"1.195453623","rc":[{"atb":[[17,0]],"id":39658516}],"con":true,"img":false}]}
{"op":"mcm","clk":"5348260697","pt":1646216033970,"mc":[{"id":"1.195453623","rc":[{"atb":[[18,7.62]],"id":39658516}],"con":true,"img":false}]}
{"op":"mcm","clk":"5348261004","pt":1646216037065,"mc":[{"id":"1.195453623","rc":[{"atb":[[26,0],[1.05,2.25]],"id":39658516}],"con":true,"img":false}]}
{"op":"mcm","clk":"5348261024","pt":1646216037282,"mc":[{"id":"1.195453623","rc":[{"atb":[[1.05,0.13]],"id":39658516}],"con":true,"img":false}]}
{"op":"mcm","clk":"5348261102","pt":1646216037957,"mc":[{"id":"1.195453623","rc":[{"atb":[[1.05,0]],"id":39658516}],"con":true,"img":false}]}
{"op":"mcm","clk":"5348261113","pt":1646216038064,"mc":[{"id":"1.195453623","rc":[{"atb":[[28,0.13]],"id":39658516}],"con":true,"img":false}]}
{"op":"mcm","clk":"5348264932","pt":1646216071079,"mc":[{"id":"1.195453623","rc":[{"atb":[[27,0],[29,1.12]],"id":39658516}],"con":true,"img":false}]}
{"op":"mcm","clk":"5348276355","pt":1646216117817,"mc":[{"id":"1.195453623","rc":[{"atl":[[32,10.89]],"id":37447009},{"spn":79.5,"spf":"NaN","id":39658516},{"atl":[[16,13.62]],"id":37286329}],"con":true,"img":false}]}
{"op":"mcm","clk":"5348276445","pt":1646216118298,"mc":[{"id":"1.195453623","rc":[{"atl":[[1000,0]],"id":37447009}],"con":true,"img":false}]}
{"op":"mcm","clk":"5348276468","pt":1646216118398,"mc":[{"id":"1.195453623","rc":[{"atl":[[30,1.3]],"id":37447009}],"con":true,"img":false}]}
{"op":"mcm","clk":"5348277559","pt":1646216123532,"mc":[{"id":"1.195453623","rc":[{"atb":[[17.5,0]],"id":39658516}],"con":true,"img":false}]}
{"op":"mcm","clk":"5348277578","pt":1646216123597,"mc":[{"id":"1.195453623","rc":[{"atb":[[18.5,2.23]],"id":39658516}],"con":true,"img":false}]}
{"op":"mcm","clk":"5348277920","pt":1646216125000,"mc":[{"id":"1.195453623","rc":[{"atl":[[5.5,0]],"id":42513983}],"con":true,"img":false}]}
{"op":"mcm","clk":"5348277949","pt":1646216125113,"mc":[{"id":"1.195453623","rc":[{"atl":[[5.7,11.69]],"id":42513983}],"con":true,"img":false}]}
{"op":"mcm","clk":"5348283106","pt":1646216156224,"mc":[{"id":"1.195453623","rc":[{"atl":[[34,0]],"id":37447009}],"con":true,"img":false}]}
{"op":"mcm","clk":"5348283119","pt":1646216156325,"mc":[{"id":"1.195453623","rc":[{"atl":[[30,4.03]],"id":37447009}],"con":true,"img":false}]}
{"op":"mcm","clk":"5348283252","pt":1646216157228,"mc":[{"id":"1.195453623","rc":[{"atb":[[28,0]],"id":39658516}],"con":true,"img":false}]}
{"op":"mcm","clk":"5348283268","pt":1646216157326,"mc":[{"id":"1.195453623","rc":[{"atb":[[1.05,2.25]],"id":39658516}],"con":true,"img":false}]}
{"op":"mcm","clk":"5348283296","pt":1646216157534,"mc":[{"id":"1.195453623","rc":[{"atb":[[1.05,0.12]],"id":39658516}],"con":true,"img":false}]}
{"op":"mcm","clk":"5348283420","pt":1646216158425,"mc":[{"id":"1.195453623","rc":[{"atb":[[1.05,0]],"id":39658516}],"con":true,"img":false}]}
{"op":"mcm","clk":"5348283435","pt":1646216158535,"mc":[{"id":"1.195453623","rc":[{"atb":[[30,0.12]],"id":39658516}],"con":true,"img":false}]}
{"op":"mcm","clk":"5348285235","pt":1646216171745,"mc":[{"id":"1.195453623","rc":[{"atb":[[24,1.36]],"id":39658516},{"atl":[[17,0]],"id":37286329}],"con":true,"img":false}]}
{"op":"mcm","clk":"5348285247","pt":1646216171850,"mc":[{"id":"1.195453623","rc":[{"atb":[[29,0]],"id":39658516},{"atl":[[15.5,11.34]],"id":37286329}],"con":true,"img":false}]}
{"op":"mcm","clk":"5348286937","pt":1646216183565,"mc":[{"id":"1.195453623","rc":[{"atb":[[18,0]],"id":39658516},{"spn":80.0,"spf":"NaN","id":39658516},{"spn":4.52,"spf":"NaN","id":42513983}],"con":true,"img":false}]}
{"op":"mcm","clk":"5348286972","pt":1646216183779,"mc":[{"id":"1.195453623","rc":[{"atb":[[19,7.62]],"id":39658516}],"con":true,"img":false}]}
{"op":"mcm","clk":"5348287610","pt":1646216187348,"mc":[{"id":"1.195453623","rc":[{"atb":[[1.05,2.25],[30,0]],"id":39658516}],"con":true,"img":false}]}
{"op":"mcm","clk":"5348287647","pt":1646216187599,"mc":[{"id":"1.195453623","rc":[{"atb":[[1.05,0.12]],"id":39658516}],"con":true,"img":false}]}
{"op":"mcm","clk":"5348287687","pt":1646216187765,"mc":[{"id":"1.195453623","rc":[{"atb":[[1.05,0]],"id":39658516}],"con":true,"img":false}]}
{"op":"mcm","clk":"5348287708","pt":1646216187873,"mc":[{"id":"1.195453623","rc":[{"atb":[[25,0.12]],"id":39658516}],"con":true,"img":false}]}
{"op":"mcm","clk":"5348289025","pt":1646216196886,"mc":[{"id":"1.195453623","rc":[{"atb":[[24,0],[26,1.25]],"id":39658516}],"con":true,"img":false}]}
{"op":"mcm","clk":"5348296602","pt":1646216254233,"mc":[{"id":"1.195453623","rc":[{"atb":[[3.9,0]],"id":41788482},{"spn":78.0,"spf":"NaN","id":39658516}],"con":true,"img":false}]}
{"op":"mcm","clk":"5348296615","pt":1646216254336,"mc":[{"id":"1.195453623","rc":[{"atb":[[4,56.33]],"id":41788482}],"con":true,"img":false}]}
{"op":"mcm","clk":"5348296716","pt":1646216255241,"mc":[{"id":"1.195453623","rc":[{"atl":[[1000,0]],"id":28222454}],"con":true,"img":false}]}
{"op":"mcm","clk":"5348296729","pt":1646216255333,"mc":[{"id":"1.195453623","rc":[{"atl":[[270,1.33]],"id":28222454}],"con":true,"img":false}]}
{"op":"mcm","clk":"5348296806","pt":1646216256023,"mc":[{"id":"1.195453623","rc":[{"atl":[[270,0]],"id":28222454}],"con":true,"img":false}]}
{"op":"mcm","clk":"5348296818","pt":1646216256125,"mc":[{"id":"1.195453623","rc":[{"atl":[[1000,1.33]],"id":28222454}],"con":true,"img":false}]}
{"op":"mcm","clk":"5348296991","pt":1646216257652,"mc":[{"id":"1.195453623","rc":[{"atb":[[4,17.71]],"id":41788482}],"con":true,"img":false}]}
{"op":"mcm","clk":"5348297004","pt":1646216257718,"mc":[{"id":"1.195453623","rc":[{"atb":[[3.9,38.61]],"id":41788482}],"con":true,"img":false}]}
{"op":"mcm","clk":"5348299727","pt":1646216277452,"mc":[{"id":"1.195453623","rc":[{"atb":[[25,0],[1.05,2.25]],"id":39658516}],"con":true,"img":false}]}
{"op":"mcm","clk":"5348299740","pt":1646216277557,"mc":[{"id":"1.195453623","rc":[{"atb":[[1.05,0.14]],"id":39658516}],"con":true,"img":false}]}
{"op":"mcm","clk":"5348299748","pt":1646216277660,"mc":[{"id":"1.195453623","rc":[{"atb":[[1.05,0]],"id":39658516}],"con":true,"img":false}]}
{"op":"mcm","clk":"5348299758","pt":1646216277763,"mc":[{"id":"1.195453623","rc":[{"atb":[[27,0.14]],"id":39658516}],"con":true,"img":false}]}
{"op":"mcm","clk":"5348303046","pt":1646216303996,"mc":[{"id":"1.195453623","rc":[{"atb":[[26,0],[28,1.16]],"id":39658516}],"con":true,"img":false}]}
{"op":"mcm","clk":"5348309255","pt":1646216360609,"mc":[{"id":"1.195453623","rc":[{"atb":[[3.9,0]],"id":41788482},{"spn":79.0,"spf":"NaN","id":39658516}],"con":true,"img":false}]}
{"op":"mcm","clk":"5348309261","pt":1646216360712,"mc":[{"id":"1.195453623","rc":[{"atb":[[4,56.33]],"id":41788482}],"con":true,"img":false}]}
{"op":"mcm","clk":"5348309310","pt":1646216361336,"mc":[{"id":"1.195453623","rc":[{"atb":[[3.95,2.82]],"id":41788482},{"atl":[[1000,0]],"id":28222454}],"con":true,"img":false}]}
{"op":"mcm","clk":"5348309319","pt":1646216361450,"mc":[{"id":"1.195453623","rc":[{"atl":[[270,1.33]],"id":28222454}],"con":true,"img":false}]}
{"op":"mcm","clk":"5348309378","pt":1646216362015,"mc":[{"id":"1.195453623","rc":[{"atl":[[270,0]],"id":28222454}],"con":true,"img":false}]}
{"op":"mcm","clk":"5348309386","pt":1646216362115,"mc":[{"id":"1.195453623","rc":[{"atl":[[1000,1.33]],"id":28222454}],"con":true,"img":false}]}
{"op":"mcm","clk":"5348309448","pt":1646216362646,"mc":[{"id":"1.195453623","rc":[{"atl":[[1000,0]],"id":28222454}],"con":true,"img":false}]}
{"op":"mcm","clk":"5348309460","pt":1646216362746,"mc":[{"id":"1.195453623","rc":[{"atl":[[270,1.33]],"id":28222454}],"con":true,"img":false}]}
{"op":"mcm","clk":"5348309531","pt":1646216363323,"mc":[{"id":"1.195453623","rc":[{"atl":[[270,0]],"id":28222454}],"con":true,"img":false}]}
{"op":"mcm","clk":"5348309542","pt":1646216363427,"mc":[{"id":"1.195453623","rc":[{"atl":[[1000,1.33]],"id":28222454}],"con":true,"img":false}]}
{"op":"mcm","clk":"5348309565","pt":1646216363637,"mc":[{"id":"1.195453623","rc":[{"atb":[[4,17.71]],"id":41788482}],"con":true,"img":false}]}
{"op":"mcm","clk":"5348309573","pt":1646216363741,"mc":[{"id":"1.195453623","rc":[{"atb":[[3.9,38.61]],"id":41788482}],"con":true,"img":false}]}
{"op":"mcm","clk":"5348309948","pt":1646216367548,"mc":[{"id":"1.195453623","rc":[{"atb":[[1.05,2.25]],"id":39658516}],"con":true,"img":false}]}
{"op":"mcm","clk":"5348309959","pt":1646216367659,"mc":[{"id":"1.195453623","rc":[{"atb":[[27,0]],"id":39658516}],"con":true,"img":false}]}
{"op":"mcm","clk":"5348309965","pt":1646216367710,"mc":[{"id":"1.195453623","rc":[{"atb":[[1.05,0.12]],"id":39658516}],"con":true,"img":false}]}
{"op":"mcm","clk":"5348309975","pt":1646216367863,"mc":[{"id":"1.195453623","rc":[{"atb":[[1.05,0]],"id":39658516}],"con":true,"img":false}]}
{"op":"mcm","clk":"5348309985","pt":1646216367923,"mc":[{"id":"1.195453623","rc":[{"atb":[[29,0.12]],"id":39658516}],"con":true,"img":false}]}
{"op":"mcm","clk":"5348311854","pt":1646216384329,"mc":[{"id":"1.195453623","rc":[{"atb":[[3.95,5.37]],"id":41788482}],"con":true,"img":false}]}
{"op":"mcm","clk":"5348313679","pt":1646216401186,"mc":[{"id":"1.195453623","rc":[{"atb":[[28,0],[30,1.08]],"id":39658516}],"con":true,"img":false}]}
{"op":"mcm","clk":"5348316858","pt":1646216432238,"mc":[{"id":"1.195453623","rc":[{"spn":80.0,"spf":"NaN","id":39658516},{"spl":[[1.01,5.44]],"id":42513983},{"spn":3.24,"spf":1.0,"id":42513983}],"con":true,"img":false}]}
{"op":"mcm","clk":"5348319609","pt":1646216461072,"mc":[{"id":"1.195453623","rc":[{"atb":[[4.3,6.06],[3.85,76.66],[3.95,25.42],[4.1,16.13]],"id":37447009},{"atl":[[32,11.89],[36,1.43],[40,1.92],[44,2.91]],"id":37447009},{"atb":[[1.73,171.23],[1.79,25.32],[1.77,64.94],[1.75,208.99]],"id":36074465},{"atl":[[2.98,37.88],[2.94,25.77],[3.05,60.98],[2.9,10.53]],"id":36074465},{"atb":[[3.8,26.79],[4,24.38],[3.7,46.3],[3.9,55.85]],"id":41788482},{"atl":[[190,1],[210,1],[230,1],[250,1]],"id":41788482},{"atb":[[8,2.86],[6.8,21.55],[7.2,12.1],[7.6,32.34]],"id":39658516},{"atl":[[610,1],[630,1],[650,1],[670,1]],"id":39658516},{"atb":[[2.98,10.1],[2.94,25.77],[2.9,39.47],[2.86,67.2]],"id":42513983},{"atl":[[15,9.62],[16,3.33],[17,13.19],[18,7.35]],"id":42513983},{"atb":[[2.74,28.74],[2.66,75.3],[2.78,11.24],[2.7,44.12]],"id":37286329},{"atl":[[17,1.25],[18,2.94],[19,4.17],[20,6.58]],"id":37286329},{"atb":[[18,12.15],[19,4.17],[20,2.63],[22,1]],"id":28222454},{"atl":[[790,1],[810,1],[830,1],[850,1]],"id":28222454}],"con":true,"img":false}]}
{"op":"mcm","clk":"5348319616","pt":1646216461128,"mc":[{"id":"1.195453623","rc":[{"atl":[[3.15,58.14]],"id":36074465},{"atb":[[2.94,86.03],[3.15,0]],"id":41788482},{"atb":[[7.8,0]],"id":39658516},{"atl":[[520,0],[530,1],[440,2],[470,1],[490,1],[510,1]],"id":39658516},{"atb":[[2.72,97.98]],"id":42513983},{"atl":[[17.5,0]],"id":37286329}],"con":true,"img":false}]}
{"op":"mcm","clk":"5348319623","pt":1646216461232,"mc":[{"id":"1.195453623","rc":[{"atb":[[2.6,0]],"id":42513983},{"atl":[[16,20.29]],"id":37286329}],"con":true,"img":false}]}
{"op":"mcm","clk":"5348319631","pt":1646216461332,"mc":[{"id":"1.195453623","rc":[{"atb":[[8,14.96]],"id":39658516}],"con":true,"img":false}]}
{"op":"mcm","clk":"5348319659","pt":1646216461649,"mc":[{"id":"1.195453623","rc":[{"atb":[[1.78,25.64],[1.79,0]],"id":36074465},{"atl":[[2.94,10.31],[2.9,0],[3.15,0]],"id":36074465},{"atl":[[610,0],[630,0],[650,0],[670,0]],"id":39658516},{"atl":[[16,13.62],[17,6.25],[18,1.18]],"id":37286329},{"atb":[[42,0.99]],"id":28222454},{"atl":[[790,0],[780,1]],"id":28222454}],"con":true,"img":false}]}
{"op":"mcm","clk":"5348319679","pt":1646216461858,"mc":[{"id":"1.195453623","rc":[{"atb":[[46,0.26]],"id":28222454}],"con":true,"img":false}]}
{"op":"mcm","clk":"5348319771","pt":1646216462645,"mc":[{"id":"1.195453623","rc":[{"atb":[[44,0]],"id":28222454}],"con":true,"img":false}]}
{"op":"mcm","clk":"5348319785","pt":1646216462755,"mc":[{"id":"1.195453623","rc":[{"atb":[[29,2.72]],"id":28222454}],"con":true,"img":false}]}
{"op":"mcm","clk":"5348319956","pt":1646216464373,"mc":[{"id":"1.195453623","rc":[{"atb":[[13,2.49]],"id":37447009},{"atb":[[4.4,2.5]],"id":41788482},{"atb":[[3.35,2.99]],"id":42513983}],"con":true,"img":false}]}
{"op":"mcm","clk":"5348319989","pt":1646216464635,"mc":[{"id":"1.195453623","rc":[{"atb":[[4.2,26.56]],"id":37447009}],"con":true,"img":false}]}
{"op":"mcm","clk":"5348320418","pt":1646216468474,"mc":[{"id":"1.195453623","rc":[{"atb":[[3.95,2.82]],"id":41788482}],"con":true,"img":false}]}
{"op":"mcm","clk":"5348320449","pt":1646216468793,"mc":[{"id":"1.195453623","rc":[{"atb":[[12.5,0]],"id":37447009},{"atl":[[36,4.29],[75,0]],"id":37447009},{"atl":[[2.86,10.75],[3.15,46.51],[3.65,0]],"id":36074465},{"atb":[[2.94,42.13],[1.32,51.17]],"id":41788482},{"atl":[[360,1],[470,0]],"id":39658516},{"atb":[[2.72,47.52],[1.98,102.04]],"id":42513983},{"atb":[[10.5,0],[13.5,8]],"id":28222454},{"atl":[[280,4.72],[310,0]],"id":28222454}],"con":true,"img":false}]}
{"op":"mcm","clk":"5348320466","pt":1646216468950,"mc":[{"id":"1.195453623","rc":[{"atb":[[11.5,2.47]],"id":37447009}],"con":true,"img":false}]}
{"op":"mcm","clk":"5348320744","pt":1646216471663,"mc":[{"id":"1.195453623","rc":[{"atl":[[19,2.78]],"id":37286329}],"con":true,"img":false}]}
{"op":"mcm","clk":"5348320839","pt":1646216472655,"mc":[{"id":"1.195453623","rc":[{"atb":[[24,1.36],[30,0]],"id":39658516}],"con":true,"img":false}]}
{"op":"mcm","clk":"5348321297","pt":1646216477467,"mc":[{"id":"1.195453623","rc":[{"atb":[[4.1,7.38]],"id":41788482}],"con":true,"img":false}]}
{"op":"mcm","clk":"5348321418","pt":1646216478661,"mc":[{"id":"1.195453623","rc":[{"atb":[[1.76,206.69]],"id":36074465},{"atl":[[2.9,26.32]],"id":36074465}],"con":true,"img":false}]}
{"op":"mcm","clk":"5348321431","pt":1646216478764,"mc":[{"id":"1.195453623","rc":[{"atl":[[380,1]],"id":39658516}],"con":true,"img":false}]}
{"op":"mcm","clk":"5348321584","pt":1646216480378,"mc":[{"id":"1.195453623","rc":[{"atl":[[300,2],[440,0]],"id":39658516}],"con":true,"img":false}]}
{"op":"mcm","clk":"5348321704","pt":1646216481644,"mc":[{"id":"1.195453623","rc":[{"atl":[[20,3.95]],"id":37286329}],"con":true,"img":false}]}
{"op":"mcm","clk":"5348322300","pt":1646216487944,"mc":[{"id":"1.195453623","rc":[{"atl":[[32,15.12],[36,1.43]],"id":37447009},{"atb":[[2,67.42],[1.32,0]],"id":41788482},{"atb":[[1.98,0],[2.44,69.44]],"id":42513983}],"con":true,"img":false}]}
{"op":"mcm","clk":"5348322310","pt":1646216487970,"mc":[{"id":"1.195453623","rc":[{"atb":[[29,0],[1.05,2.25]],"id":39658516}],"con":true,"img":false}]}
{"op":"mcm","clk":"5348322331","pt":1646216488182,"mc":[{"id":"1.195453623","rc":[{"atb":[[1.05,0.12]],"id":39658516}],"con":true,"img":false}]}
{"op":"mcm","clk":"5348322351","pt":1646216488387,"mc":[{"id":"1.195453623","rc":[{"atb":[[1.05,0]],"id":39658516}],"con":true,"img":false}]}
{"op":"mcm","clk":"5348322360","pt":1646216488489,"mc":[{"id":"1.195453623","rc":[{"atb":[[25,0.12]],"id":39658516}],"con":true,"img":false}]}
{"op":"mcm","clk":"5348322375","pt":1646216488651,"mc":[{"id":"1.195453623","rc":[{"atb":[[1.74,101.35]],"id":36074465},{"atl":[[2.94,48.97]],"id":36074465},{"atl":[[530,0],[400,1],[490,0],[510,0]],"id":39658516}],"con":true,"img":false}]}
{"op":"mcm","clk":"5348322383","pt":1646216488755,"mc":[{"id":"1.195453623","rc":[{"atb":[[1.73,0],[1.77,0],[1.75,108.99]],"id":36074465},{"atl":[[2.94,38.66],[3.05,0]],"id":36074465}],"con":true,"img":false}]}
{"op":"mcm","clk":"5348322638","pt":1646216491665,"mc":[{"id":"1.195453623","rc":[{"atl":[[22,12.29]],"id":37286329}],"con":true,"img":false}]}
{"op":"mcm","clk":"5348322776","pt":1646216493072,"mc":[{"id":"1.195453623","rc":[{"spn":12.87,"spf":1.0,"id":37447009},{"spn":6.3,"spf":"NaN","id":41788482},{"atl":[[360,0],[370,1]],"id":39658516},{"spn":77.5,"spf":"NaN","id":39658516},{"spn":3.31,"spf":1.0,"id":42513983}],"con":true,"img":false}]}
{"op":"mcm","clk":"5348323119","pt":1646216496578,"mc":[{"id":"1.195453623","rc":[{"atb":[[19,9.35],[24,0]],"id":39658516}],"con":true,"img":false}]}
{"op":"mcm","clk":"5348323292","pt":1646216498364,"mc":[{"id":"1.195453623","rc":[{"atb":[[19.5,2.08]],"id":39658516}],"con":true,"img":false}]}
{"op":"mcm","clk":"5348323333","pt":1646216498780,"mc":[{"id":"1.195453623","rc":[{"atb":[[1.72,173.61]],"id":36074465},{"atl":[[2.98,63.13]],"id":36074465}],"con":true,"img":false}]}
{"op":"mcm","clk":"5348323526","pt":1646216500574,"mc":[{"id":"1.195453623","rc":[{"atb":[[3.9,17.24]],"id":41788482},{"atb":[[2.84,0]],"id":42513983}],"con":true,"img":false}]}
{"op":"mcm","clk":"5348323535","pt":1646216500682,"mc":[{"id":"1.195453623","rc":[{"atb":[[4,63]],"id":41788482},{"atb":[[2.88,61.75]],"id":42513983}],"con":true,"img":false}]}
{"op":"mcm","clk":"5348323788","pt":1646216502680,"mc":[{"id":"1.195453623","rc":[{"atl":[[50,0]],"id":37447009}],"con":true,"img":false}]}
{"op":"mcm","clk":"5348323799","pt":1646216502782,"mc":[{"id":"1.195453623","rc":[{"atl":[[38,2.72]],"id":37447009}],"con":true,"img":false}]}
{"op":"mcm","clk":"5348323833","pt":1646216503099,"mc":[{"id":"1.195453623","rc":[{"atl":[[390,1]],"id":39658516}],"con":true,"img":false}]}
{"op":"mcm","clk":"5348324004","pt":1646216504580,"mc":[{"id":"1.195453623","rc":[{"atl":[[3.6,0],[2.88,56.96]],"id":36074465}],"con":true,"img":false}]}
{"op":"mcm","clk":"5348324436","pt":1646216506869,"mc":[{"id":"1.195453623","rc":[{"atb":[[2,0],[2.14,75.54]],"id":41788482}],"con":true,"img":false}]}
{"op":"mcm","clk":"5348325423","pt":1646216513086,"mc":[{"id":"1.195453623","rc":[{"atl":[[410,1]],"id":39658516}],"con":true,"img":false}]}
{"op":"mcm","clk":"5348325764","pt":1646216516582,"mc":[{"id":"1.195453623","rc":[{"atb":[[24,1.36]],"id":39658516}],"con":true,"img":false}]}
{"op":"mcm","clk":"5348325768","pt":1646216516685,"mc":[{"id":"1.195453623","rc":[{"atb":[[19,7.62]],"id":39658516}],"con":true,"img":false}]}
{"op":"mcm","clk":"5348325915","pt":1646216518110,"mc":[{"id":"1.195453623","rc":[{"atb":[[19.5,0]],"id":39658516}],"con":true,"img":false}]}
{"op":"mcm","clk":"5348326472","pt":1646216523095,"mc":[{"id":"1.195453623","rc":[{"atl":[[380,0],[400,0],[430,1]],"id":39658516}],"con":true,"img":false}]}
{"op":"mcm","clk":"5348334036","pt":1646216579769,"mc":[{"id":"1.195453623","rc":[{"atl":[[17,1.25],[18,0]],"id":37286329},{"atl":[[780,0]],"id":28222454}],"con":true,"img":false}]}
{"op":"mcm","clk":"5348334048","pt":1646216579868,"mc":[{"id":"1.195453623","rc":[{"atl":[[16,20.29]],"id":37286329},{"atl":[[800,1]],"id":28222454}],"con":true,"img":false}]}
{"op":"mcm","clk":"5348335248","pt":1646216589798,"mc":[{"id":"1.195453623","rc":[{"atl":[[18,2.94]],"id":37286329},{"atl":[[820,1]],"id":28222454}],"con":true,"img":false}]}
{"op":"mcm","clk":"5348335494","pt":1646216591893,"mc":[{"id":"1.195453623","rc":[{"atb":[[3.95,0]],"id":41788482}],"con":true,"img":false}]}
{"op":"mcm","clk":"5348335550","pt":1646216592576,"mc":[{"id":"1.195453623","rc":[{"atb":[[4,24.38]],"id":41788482}],"con":true,"img":false}]}
{"op":"mcm","clk":"5348335562","pt":1646216592679,"mc":[{"id":"1.195453623","rc":[{"atb":[[3.95,38.61]],"id":41788482}],"con":true,"img":false}]}
{"op":"mcm","clk":"5348336401","pt":1646216599807,"mc":[{"id":"1.195453623","rc":[{"atl":[[19,4.17],[22,6.34]],"id":37286329},{"atl":[[810,0],[830,0],[850,0],[840,1]],"id":28222454}],"con":true,"img":false}]}
{"op":"mcm","clk":"5348337450","pt":1646216609809,"mc":[{"id":"1.195453623","rc":[{"atl":[[20,6.58]],"id":37286329},{"atl":[[860,1]],"id":28222454}],"con":true,"img":false}]}
{"op":"mcm","clk":"5348337747","pt":1646216613168,"mc":[{"id":"1.195453623","rc":[{"atl":[[32,11.89],[34,3.03]],"id":37447009},{"atb":[[2.14,0],[1.75,53.58]],"id":41788482},{"atl":[[300,0],[360,2]],"id":39658516},{"atb":[[2.44,0],[2.2,83.33]],"id":42513983}],"con":true,"img":false}]}
{"op":"mcm","clk":"5348337882","pt":1646216614636,"mc":[{"id":"1.195453623","rc":[{"atb":[[4.1,10.08]],"id":41788482}],"con":true,"img":false}]}
{"op":"mcm","clk":"5348340484","pt":1646216645269,"mc":[{"id":"1.195453623","rc":[{"atl":[[32,10.89],[140,15.2]],"id":37447009},{"atl":[[16.5,1.29],[17,0]],"id":37286329},{"atl":[[780,1],[800,0]],"id":28222454}],"con":true,"img":false}]}
{"op":"mcm","clk":"5348341348","pt":1646216655314,"mc":[{"id":"1.195453623","rc":[{"atl":[[36,0],[160,2.25]],"id":37447009},{"atl":[[800,1]],"id":28222454}],"con":true,"img":false}]}
{"op":"mcm","clk":"5348341461","pt":1646216656627,"mc":[{"id":"1.195453623","rc":[{"atl":[[38,0]],"id":37447009}],"con":true,"img":false}]}
{"op":"mcm","clk":"5348341478","pt":1646216656732,"mc":[{"id":"1.195453623","rc":[{"atl":[[42,2.72]],"id":37447009}],"con":true,"img":false}]}
{"op":"mcm","clk":"5348342345","pt":1646216665320,"mc":[{"id":"1.195453623","rc":[{"atl":[[40,0],[180,1]],"id":37447009},{"atl":[[860,0]],"id":28222454}],"con":true,"img":false}]}
{"op":"mcm","clk":"5348343331","pt":1646216675346,"mc":[{"id":"1.195453623","rc":[{"atl":[[44,0],[200,1]],"id":37447009}],"con":true,"img":false}]}
{"op":"mcm","clk":"5348343544","pt":1646216677028,"mc":[{"id":"1.195453623","rc":[{"atl":[[2.3,27.55]],"id":36074465}],"con":true,"img":false}]}
{"op":"mcm","clk":"5348376705","pt":1646217038557,"mc":[{"id":"1.195453623","rc":[{"atb":[[2.12,68.62],[1.75,0]],"id":41788482},{"atb":[[2.46,68.49],[2.2,0]],"id":42513983}],"con":true,"img":false}]}
{"op":"mcm","clk":"5348376927","pt":1646217040810,"mc":[{"id":"1.195453623","rc":[{"atl":[[370,0],[380,1]],"id":39658516}],"con":true,"img":false}]}
{"op":"mcm","clk":"5348377563","pt":1646217047625,"mc":[{"id":"1.195453623","rc":[{"atb":[[3.85,43.86],[3.3,8.7],[3.15,46.3]],"id":37447009},{"atl":[[2.98,0],[2.94,0],[3.45,48.98],[2.86,0],[2.9,0],[3.15,0]],"id":36074465},{"atl":[[40,0],[190,0],[23,13.75]],"id":41788482},{"atb":[[8,0],[9,2.5],[9.2,12.2]],"id":39658516},{"atb":[[2.6,0],[3.05,9.76],[2.88,28.74],[2.78,0]],"id":37286329}],"con":true,"img":false}]}
{"op":"mcm","clk":"5348377574","pt":1646217047730,"mc":[{"id":"1.195453623","rc":[{"atb":[[4.3,0],[3.85,0],[3.95,0],[4.1,0]],"id":37447009}],"con":true,"img":false}]}
{"op":"mcm","clk":"5348377666","pt":1646217048628,"mc":[{"id":"1.195453623","rc":[{"atl":[[2.88,0],[3.4,44.62]],"id":36074465}],"con":true,"img":false}]}
{"op":"mcm","clk":"5348377970","pt":1646217051828,"mc":[{"id":"1.195453623","rc":[{"atb":[[2.38,72.46]],"id":41788482}],"con":true,"img":false}]}
{"op":"mcm","clk":"5348377980","pt":1646217051925,"mc":[{"id":"1.195453623","rc":[{"atb":[[2.12,0]],"id":41788482}],"con":true,"img":false}]}
{"op":"mcm","clk":"5348378585","pt":1646217057646,"mc":[{"id":"1.195453623","rc":[{"atb":[[3.2,22.73]],"id":37447009},{"atl":[[3.55,19.61]],"id":36074465},{"atl":[[25,2.08]],"id":41788482},{"atb":[[8.6,26.8]],"id":39658516},{"atl":[[400,1]],"id":39658516},{"atb":[[2.98,25.25]],"id":37286329}],"con":true,"img":false}]}
{"op":"mcm","clk":"5348379089","pt":1646217063355,"mc":[{"id":"1.195453623","rc":[{"atb":[[11.5,1.51]],"id":37447009},{"atb":[[24,3.36]],"id":39658516},{"atl":[[15,3.32]],"id":37286329},{"atb":[[42,2.99]],"id":28222454},{"atl":[[270,2]],"id":28222454}],"con":true,"img":false}]}
{"op":"mcm","clk":"5348379111","pt":1646217063457,"mc":[{"id":"1.195453623","rc":[{"atb":[[12.5,0.88]],"id":37447009}],"con":true,"img":false}]}
{"op":"mcm","clk":"5348379182","pt":1646217064037,"mc":[{"id":"1.195453623","rc":[{"atl":[[1000,0]],"id":28222454}],"con":true,"img":false}]}
{"op":"mcm","clk":"5348379190","pt":1646217064147,"mc":[{"id":"1.195453623","rc":[{"atl":[[270,3.33]],"id":28222454}],"con":true,"img":false}]}
{"op":"mcm","clk":"5348379483","pt":1646217067647,"mc":[{"id":"1.195453623","rc":[{"atb":[[3.1,35.71]],"id":37447009},{"atl":[[3.65,28.3]],"id":36074465},{"atl":[[250,0],[27,2.88]],"id":41788482},{"atb":[[8.2,10.42],[6.8,0],[7.2,0],[7.6,24.76]],"id":39658516},{"atl":[[390,0],[410,0],[430,0],[420,1]],"id":39658516},{"atb":[[2.94,38.66],[2.66,0]],"id":37286329}],"con":true,"img":false}]}
{"op":"mcm","clk":"5348380413","pt":1646217077675,"mc":[{"id":"1.195453623","rc":[{"atb":[[3,62.5]],"id":37447009},{"atl":[[3.75,45.45]],"id":36074465},{"atl":[[29,4.46]],"id":41788482},{"atb":[[7.8,18.38]],"id":39658516},{"atl":[[440,1]],"id":39658516},{"atb":[[2.9,65.79],[2.7,0]],"id":37286329}],"con":true,"img":false}]}
{"op":"mcm","clk":"5348380424","pt":1646217077778,"mc":[{"id":"1.195453623","rc":[{"atl":[[230,0]],"id":41788482}],"con":true,"img":false}]}
{"op":"mcm","clk":"5348381318","pt":1646217087690,"mc":[{"id":"1.195453623","rc":[{"atl":[[210,0]],"id":41788482},{"atb":[[2.74,0]],"id":37286329}],"con":true,"img":false}]}
{"op":"mcm","clk":"5348381695","pt":1646217091890,"mc":[{"id":"1.195453623","rc":[{"atb":[[2.16,1.62]],"id":36074465},{"trd":[[2.16,1.6]],"ltp":2.16,"tv":1.6,"id":36074465},{"atb":[[3.35,2.65]],"id":42513983},{"trd":[[3.35,0.68]],"ltp":3.35,"tv":0.68,"id":42513983}],"con":true,"img":false}]}
{"op":"mcm","clk":"5348381713","pt":1646217092057,"mc":[{"id":"1.195453623","rc":[{"atb":[[4.3,0],[1.01,2.25]],"id":41788482}],"con":true,"img":false}]}
{"op":"mcm","clk":"5348381724","pt":1646217092202,"mc":[{"id":"1.195453623","rc":[{"atb":[[1.01,0.83]],"id":41788482}],"con":true,"img":false}]}
{"op":"mcm","clk":"5348381733","pt":1646217092263,"mc":[{"id":"1.195453623","rc":[{"atl":[[2.28,4.21]],"id":36074465},{"atl":[[5.6,2.52]],"id":42513983}],"con":true,"img":false}]}
{"op":"mcm","clk":"5348381744","pt":1646217092369,"mc":[{"id":"1.195453623","rc":[{"atb":[[1.01,0]],"id":41788482}],"con":true,"img":false}]}
{"op":"mcm","clk":"5348381752","pt":1646217092472,"mc":[{"id":"1.195453623","rc":[{"atb":[[4.5,0.83]],"id":41788482}],"con":true,"img":false}]}
{"op":"mcm","clk":"5348381786","pt":1646217092785,"mc":[{"id":"1.195453623","rc":[{"atl":[[8,16.23]],"id":42513983}],"con":true,"img":false}]}
{"op":"mcm","clk":"5348381797","pt":1646217092896,"mc":[{"id":"1.195453623","rc":[{"atl":[[5.5,1.3]],"id":42513983}],"con":true,"img":false}]}
{"op":"mcm","clk":"5348381933","pt":1646217094297,"mc":[{"id":"1.195453623","rc":[{"atb":[[4.4,0]],"id":41788482}],"con":true,"img":false}]}
{"op":"mcm","clk":"5348382444","pt":1646217100201,"mc":[{"id":"1.195453623","rc":[{"spn":12.95,"spf":1.0,"id":37447009},{"spn":1.85,"spf":1.0,"id":36074465},{"spn":6.35,"spf":"NaN","id":41788482},{"atl":[[5.6,0]],"id":42513983},{"spn":3.3,"spf":1.0,"id":42513983}],"con":true,"img":false}]}
{"op":"mcm","clk":"5348382467","pt":1646217100523,"mc":[{"id":"1.195453623","rc":[{"atl":[[5.5,0]],"id":42513983}],"con":true,"img":false}]}
{"op":"mcm","clk":"5348382479","pt":1646217100576,"mc":[{"id":"1.195453623","rc":[{"atl":[[1000,1.3]],"id":42513983},{"atb":[[29,0]],"id":28222454}],"con":true,"img":false}]}
{"op":"mcm","clk":"5348382494","pt":1646217100685,"mc":[{"id":"1.195453623","rc":[{"atb":[[44,2.72]],"id":28222454}],"con":true,"img":false}]}
{"op":"mcm","clk":"5348382542","pt":1646217101299,"mc":[{"id":"1.195453623","rc":[{"atl":[[5.6,2.52]],"id":42513983}],"con":true,"img":false}]}
{"op":"mcm","clk":"5348382556","pt":1646217101512,"mc":[{"id":"1.195453623","rc":[{"atl":[[5.6,0]],"id":42513983}],"con":true,"img":false}]}
{"op":"mcm","clk":"5348382661","pt":1646217102700,"mc":[{"id":"1.195453623","rc":[{"atl":[[280,2]],"id":28222454}],"con":true,"img":false}]}
{"op":"mcm","clk":"5348382669","pt":1646217102806,"mc":[{"id":"1.195453623","rc":[{"atl":[[260,2.72]],"id":28222454}],"con":true,"img":false}]}
{"op":"mcm","clk":"5348382693","pt":1646217103014,"mc":[{"id":"1.195453623","rc":[{"atl":[[260,4.72],[280,0]],"id":28222454}],"con":true,"img":false}]}
{"op":"mcm","clk":"5348382716","pt":1646217103223,"mc":[{"id":"1.195453623","rc":[{"atl":[[270,1.33],[250,2]],"id":28222454}],"con":true,"img":false}]}
{"op":"mcm","clk":"5348382725","pt":1646217103285,"mc":[{"id":"1.195453623","rc":[{"atl":[[270,0]],"id":28222454}],"con":true,"img":false}]}
{"op":"mcm","clk":"5348382739","pt":1646217103387,"mc":[{"id":"1.195453623","rc":[{"atl":[[250,3.33]],"id":28222454}],"con":true,"img":false}]}
{"op":"mcm","clk":"5348382835","pt":1646217104589,"mc":[{"id":"1.195453623","rc":[{"atl":[[130,0]],"id":39658516}],"con":true,"img":false}]}
{"op":"mcm","clk":"5348382849","pt":1646217104693,"mc":[{"id":"1.195453623","rc":[{"atl":[[180,2.72]],"id":39658516}],"con":true,"img":false}]}
{"op":"mcm","clk":"5348382863","pt":1646217104793,"mc":[{"id":"1.195453623","rc":[{"atl":[[240,2.83]],"id":39658516}],"con":true,"img":false}]}
{"op":"mcm","clk":"5348383020","pt":1646217106422,"mc":[{"id":"1.195453623","rc":[{"atl":[[5.6,2.52]],"id":42513983}],"con":true,"img":false}]}
{"op":"mcm","clk":"5348383047","pt":1646217106679,"mc":[{"id":"1.195453623","rc":[{"atl":[[5.6,0]],"id":42513983}],"con":true,"img":false}]}
{"op":"mcm","clk":"5348383054","pt":1646217106796,"mc":[{"id":"1.195453623","rc":[{"atl":[[1000,0]],"id":42513983}],"con":true,"img":false}]}
{"op":"mcm","clk":"5348383063","pt":1646217106893,"mc":[{"id":"1.195453623","rc":[{"atl":[[5.5,1.3]],"id":42513983}],"con":true,"img":false}]}
{"op":"mcm","clk":"5348383105","pt":1646217107511,"mc":[{"id":"1.195453623","rc":[{"atl":[[5.5,0]],"id":42513983}],"con":true,"img":false}]}
{"op":"mcm","clk":"5348383118","pt":1646217107611,"mc":[{"id":"1.195453623","rc":[{"atl":[[1000,1.3]],"id":42513983}],"con":true,"img":false}]}
{"op":"mcm","clk":"5348383139","pt":1646217107921,"mc":[{"id":"1.195453623","rc":[{"atb":[[24,1.36]],"id":39658516},{"atl":[[240,0.83]],"id":39658516},{"atl":[[15,1.32]],"id":37286329},{"atb":[[42,0.99]],"id":28222454},{"atl":[[250,1.33]],"id":28222454}],"con":true,"img":false}]}
{"op":"mcm","clk":"5348383216","pt":1646217108704,"mc":[{"id":"1.195453623","rc":[{"atb":[[44,0]],"id":28222454}],"con":true,"img":false}]}
{"op":"mcm","clk":"5348383222","pt":1646217108811,"mc":[{"id":"1.195453623","rc":[{"atb":[[29,2.72]],"id":28222454}],"con":true,"img":false}]}
{"op":"mcm","clk":"5348383508","pt":1646217112098,"mc":[{"id":"1.195453623","rc":[{"atl":[[5.6,2.52]],"id":42513983}],"con":true,"img":false}]}
{"op":"mcm","clk":"5348383553","pt":1646217112610,"mc":[{"id":"1.195453623","rc":[{"atl":[[5.6,0]],"id":42513983}],"con":true,"img":false}]}
{"op":"mcm","clk":"5348383954","pt":1646217117428,"mc":[{"id":"1.195453623","rc":[{"atl":[[250,0]],"id":28222454}],"con":true,"img":false}]}
{"op":"mcm","clk":"5348383962","pt":1646217117532,"mc":[{"id":"1.195453623","rc":[{"atl":[[1000,1.33]],"id":28222454}],"con":true,"img":false}]}
{"op":"mcm","clk":"5348383971","pt":1646217117591,"mc":[{"id":"1.195453623","rc":[{"atl":[[5.6,2.52]],"id":42513983}],"con":true,"img":false}]}
{"op":"mcm","clk":"5348383991","pt":1646217117900,"mc":[{"id":"1.195453623","rc":[{"atl":[[5.6,0]],"id":42513983}],"con":true,"img":false}]}
{"op":"mcm","clk":"5348384092","pt":1646217118997,"mc":[{"id":"1.195453623","rc":[{"atb":[[1.01,2.25],[4.5,0]],"id":41788482}],"con":true,"img":false}]}
{"op":"mcm","clk":"5348384113","pt":1646217119207,"mc":[{"id":"1.195453623","rc":[{"atb":[[1.01,0.83]],"id":41788482}],"con":true,"img":false}]}
{"op":"mcm","clk":"5348384160","pt":1646217119623,"mc":[{"id":"1.195453623","rc":[{"atb":[[1.01,0]],"id":41788482}],"con":true,"img":false}]}
{"op":"mcm","clk":"5348384165","pt":1646217119729,"mc":[{"id":"1.195453623","rc":[{"atb":[[4.3,0.83]],"id":41788482}],"con":true,"img":false}]}
{"op":"mcm","clk":"5348384182","pt":1646217119833,"mc":[{"id":"1.195453623","rc":[{"atb":[[4.1,13.03],[4.2,2.89]],"id":41788482}],"con":true,"img":false}]}
{"op":"mcm","clk":"5348384345","pt":1646217121617,"mc":[{"id":"1.195453623","rc":[{"atb":[[4.2,0.39]],"id":41788482}],"con":true,"img":false}]}
{"op":"mcm","clk":"5348384478","pt":1646217123046,"mc":[{"id":"1.195453623","rc":[{"atl":[[5.6,2.52]],"id":42513983}],"con":true,"img":false}]}
{"op":"mcm","clk":"5348384516","pt":1646217123408,"mc":[{"id":"1.195453623","rc":[{"atl":[[5.6,0]],"id":42513983}],"con":true,"img":false}]}
{"op":"mcm","clk":"5348384600","pt":1646217124503,"mc":[{"id":"1.195453623","rc":[{"atb":[[4.4,2.5]],"id":41788482}],"con":true,"img":false}]}
{"op":"mcm","clk":"5348384939","pt":1646217128523,"mc":[{"id":"1.195453623","rc":[{"atl":[[5.6,2.52]],"id":42513983}],"con":true,"img":false}]}
{"op":"mcm","clk":"5348384993","pt":1646217129154,"mc":[{"id":"1.195453623","rc":[{"atl":[[5.6,0]],"id":42513983}],"con":true,"img":false}]}
{"op":"mcm","clk":"5348385127","pt":1646217130621,"mc":[{"id":"1.195453623","rc":[{"atb":[[19,9.35],[24,0]],"id":39658516}],"con":true,"img":false}]}
{"op":"mcm","clk":"5348385190","pt":1646217131453,"mc":[{"id":"1.195453623","rc":[{"atb":[[19.5,2.08]],"id":39658516}],"con":true,"img":false}]}
{"op":"mcm","clk":"5348385457","pt":1646217134329,"mc":[{"id":"1.195453623","rc":[{"atl":[[5.6,2.52]],"id":42513983}],"con":true,"img":false}]}
{"op":"mcm","clk":"5348385488","pt":1646217134746,"mc":[{"id":"1.195453623","rc":[{"atl":[[5.6,0]],"id":42513983}],"con":true,"img":false}]}
{"op":"mcm","clk":"5348385919","pt":1646217139750,"mc":[{"id":"1.195453623","rc":[{"atl":[[5.6,2.52]],"id":42513983}],"con":true,"img":false}]}
{"op":"mcm","clk":"5348385944","pt":1646217140062,"mc":[{"id":"1.195453623","rc":[{"atl":[[5.6,0]],"id":42513983}],"con":true,"img":false}]}
{"op":"mcm","clk":"5348386158","pt":1646217142565,"mc":[{"id":"1.195453623","rc":[{"atl":[[260,2]],"id":28222454}],"con":true,"img":false}]}
{"op":"mcm","clk":"5348386168","pt":1646217142668,"mc":[{"id":"1.195453623","rc":[{"atl":[[250,2.72]],"id":28222454}],"con":true,"img":false}]}
{"op":"mcm","clk":"5348386178","pt":1646217142773,"mc":[{"id":"1.195453623","rc":[{"atl":[[260,0],[350,2.38]],"id":28222454}],"con":true,"img":false}]}
{"op":"mcm","clk":"5348386200","pt":1646217142990,"mc":[{"id":"1.195453623","rc":[{"atb":[[4.2,6.02]],"id":41788482},{"atb":[[20,3.42]],"id":39658516}],"con":true,"img":false}]}
{"op":"mcm","clk":"5348386221","pt":1646217143141,"mc":[{"id":"1.195453623","rc":[{"atb":[[4.1,11.71]],"id":41788482}],"con":true,"img":false}]}
{"op":"mcm","clk":"5348386227","pt":1646217143241,"mc":[{"id":"1.195453623","rc":[{"atb":[[4.2,7.34]],"id":41788482}],"con":true,"img":false}]}
{"op":"mcm","clk":"5348386337","pt":1646217144647,"mc":[{"id":"1.195453623","rc":[{"atb":[[4,6.67]],"id":41788482},{"atl":[[250,0]],"id":28222454}],"con":true,"img":false}]}
{"op":"mcm","clk":"5348386348","pt":1646217144753,"mc":[{"id":"1.195453623","rc":[{"atb":[[4.2,25.05]],"id":41788482},{"atb":[[19.5,0]],"id":39658516},{"atl":[[300,2.72]],"id":28222454}],"con":true,"img":false}]}
{"op":"mcm","clk":"5348386401","pt":1646217145376,"mc":[{"id":"1.195453623","rc":[{"atl":[[5.6,2.52]],"id":42513983}],"con":true,"img":false}]}
{"op":"mcm","clk":"5348386431","pt":1646217145639,"mc":[{"id":"1.195453623","rc":[{"atl":[[5.6,0]],"id":42513983},{"atl":[[1000,0]],"id":28222454}],"con":true,"img":false}]}
{"op":"mcm","clk":"5348386440","pt":1646217145743,"mc":[{"id":"1.195453623","rc":[{"atl":[[290,1.33]],"id":28222454}],"con":true,"img":false}]}
{"op":"mcm","clk":"5348386475","pt":1646217146162,"mc":[{"id":"1.195453623","rc":[{"atb":[[21,1.66]],"id":39658516}],"con":true,"img":false}]}
{"op":"mcm","clk":"5348386486","pt":1646217146268,"mc":[{"id":"1.195453623","rc":[{"atl":[[290,0]],"id":28222454}],"con":true,"img":false}]}
{"op":"mcm","clk":"5348386494","pt":1646217146370,"mc":[{"id":"1.195453623","rc":[{"atl":[[1000,1.33]],"id":28222454}],"con":true,"img":false}]}
{"op":"mcm","clk":"5348386693","pt":1646217148673,"mc":[{"id":"1.195453623","rc":[{"atl":[[180,0]],"id":39658516}],"con":true,"img":false}]}
{"op":"mcm","clk":"5348386702","pt":1646217148776,"mc":[{"id":"1.195453623","rc":[{"atl":[[130,2.72]],"id":39658516}],"con":true,"img":false}]}
{"op":"mcm","clk":"5348386721","pt":1646217149038,"mc":[{"id":"1.195453623","rc":[{"atb":[[25,0],[1.05,2.25]],"id":39658516}],"con":true,"img":false}]}
{"op":"mcm","clk":"5348386734","pt":1646217149247,"mc":[{"id":"1.195453623","rc":[{"atb":[[1.05,0.12]],"id":39658516}],"con":true,"img":false}]}
{"op":"mcm","clk":"5348386780","pt":1646217149774,"mc":[{"id":"1.195453623","rc":[{"atb":[[1.05,0]],"id":39658516}],"con":true,"img":false}]}
{"op":"mcm","clk":"5348386792","pt":1646217149878,"mc":[{"id":"1.195453623","rc":[{"atb":[[24,0.12]],"id":39658516}],"con":true,"img":false}]}
{"op":"mcm","clk":"5348386843","pt":1646217150457,"mc":[{"id":"1.195453623","rc":[{"atl":[[5.6,2.52]],"id":42513983}],"con":true,"img":false}]}
{"op":"mcm","clk":"5348386864","pt":1646217150773,"mc":[{"id":"1.195453623","rc":[{"atb":[[20,0]],"id":39658516},{"atl":[[5.6,0]],"id":42513983}],"con":true,"img":false}]}
{"op":"mcm","clk":"5348387001","pt":1646217152567,"mc":[{"id":"1.195453623","rc":[{"atb":[[24,1.49]],"id":39658516}],"con":true,"img":false}]}
{"op":"mcm","clk":"5348387006","pt":1646217152671,"mc":[{"id":"1.195453623","rc":[{"atb":[[19,7.62]],"id":39658516}],"con":true,"img":false}]}
{"op":"mcm","clk":"5348387139","pt":1646217153870,"mc":[{"id":"1.195453623","rc":[{"atb":[[4.1,9.28]],"id":41788482}],"con":true,"img":false}]}
{"op":"mcm","clk":"5348387163","pt":1646217154184,"mc":[{"id":"1.195453623","rc":[{"atb":[[21,0]],"id":39658516}],"con":true,"img":false}]}
{"op":"mcm","clk":"5348387197","pt":1646217154549,"mc":[{"id":"1.195453623","rc":[{"atb":[[4.2,7.34]],"id":41788482}],"con":true,"img":false}]}
{"op":"mcm","clk":"5348387206","pt":1646217154655,"mc":[{"id":"1.195453623","rc":[{"atb":[[4,24.38]],"id":41788482},{"atb":[[17,5.92]],"id":39658516}],"con":true,"img":false}]}
{"op":"mcm","clk":"5348387245","pt":1646217155072,"mc":[{"id":"1.195453623","rc":[{"atl":[[300,4.72],[350,0.38]],"id":28222454}],"con":true,"img":false}]}
{"op":"mcm","clk":"5348387307","pt":1646217155853,"mc":[{"id":"1.195453623","rc":[{"atb":[[4.1,6.33]],"id":41788482}],"con":true,"img":false}]}
{"op":"mcm","clk":"5348387326","pt":1646217156063,"mc":[{"id":"1.195453623","rc":[{"atb":[[24,3.49]],"id":39658516},{"atl":[[5.6,2.52]],"id":42513983},{"atl":[[15,3.32]],"id":37286329},{"atb":[[42,2.99]],"id":28222454},{"atl":[[290,2]],"id":28222454}],"con":true,"img":false}]}
{"op":"mcm","clk":"5348387351","pt":1646217156374,"mc":[{"id":"1.195453623","rc":[{"atl":[[5.6,0]],"id":42513983}],"con":true,"img":false}]}
{"op":"mcm","clk":"5348387515","pt":1646217158366,"mc":[{"id":"1.195453623","rc":[{"atb":[[17,0]],"id":39658516}],"con":true,"img":false}]}
{"op":"mcm","clk":"5348387772","pt":1646217161449,"mc":[{"id":"1.195453623","rc":[{"spn":6.3,"spf":"NaN","id":41788482},{"spn":77.0,"spf":"NaN","id":39658516},{"atl":[[5.6,2.52]],"id":42513983}],"con":true,"img":false}]}
{"op":"mcm","clk":"5348387814","pt":1646217161975,"mc":[{"id":"1.195453623","rc":[{"atl":[[5.6,0]],"id":42513983}],"con":true,"img":false}]}
{"op":"mcm","clk":"5348387824","pt":1646217162080,"mc":[{"id":"1.195453623","rc":[{"atb":[[19.5,5.12]],"id":39658516}],"con":true,"img":false}]}
{"op":"mcm","clk":"5348388272","pt":1646217167095,"mc":[{"id":"1.195453623","rc":[{"atl":[[5.6,2.52]],"id":42513983}],"con":true,"img":false}]}
{"op":"mcm","clk":"5348388301","pt":1646217167359,"mc":[{"id":"1.195453623","rc":[{"atl":[[5.6,0]],"id":42513983}],"con":true,"img":false}]}
{"op":"mcm","clk":"5348388689","pt":1646217171891,"mc":[{"id":"1.195453623","rc":[{"atb":[[4.1,8.76]],"id":41788482}],"con":true,"img":false}]}
{"op":"mcm","clk":"5348388743","pt":1646217172414,"mc":[{"id":"1.195453623","rc":[{"atl":[[5.6,2.52]],"id":42513983}],"con":true,"img":false}]}
{"op":"mcm","clk":"5348388785","pt":1646217172781,"mc":[{"id":"1.195453623","rc":[{"atl":[[5.6,0]],"id":42513983}],"con":true,"img":false}]}
{"op":"mcm","clk":"5348389191","pt":1646217177485,"mc":[{"id":"1.195453623","rc":[{"atl":[[5.6,2.52]],"id":42513983}],"con":true,"img":false}]}
{"op":"mcm","clk":"5348389232","pt":1646217178005,"mc":[{"id":"1.195453623","rc":[{"atl":[[5.6,0]],"id":42513983}],"con":true,"img":false}]}
{"op":"mcm","clk":"5348389661","pt":1646217182925,"mc":[{"id":"1.195453623","rc":[{"atl":[[5.6,2.52]],"id":42513983}],"con":true,"img":false}]}
{"op":"mcm","clk":"5348389700","pt":1646217183258,"mc":[{"id":"1.195453623","rc":[{"atl":[[5.6,0]],"id":42513983}],"con":true,"img":false}]}
{"op":"mcm","clk":"5348390217","pt":1646217188784,"mc":[{"id":"1.195453623","rc":[{"atl":[[5.6,2.52]],"id":42513983}],"con":true,"img":false}]}
{"op":"mcm","clk":"5348390240","pt":1646217189199,"mc":[{"id":"1.195453623","rc":[{"atl":[[5.6,0]],"id":42513983}],"con":true,"img":false}]}
{"op":"mcm","clk":"5348390519","pt":1646217192629,"mc":[{"id":"1.195453623","rc":[{"atb":[[29,0]],"id":28222454}],"con":true,"img":false}]}
{"op":"mcm","clk":"5348390529","pt":1646217192725,"mc":[{"id":"1.195453623","rc":[{"atb":[[44,2.72]],"id":28222454}],"con":true,"img":false}]}
{"op":"mcm","clk":"5348390649","pt":1646217194088,"mc":[{"id":"1.195453623","rc":[{"atl":[[5.6,2.52]],"id":42513983}],"con":true,"img":false}]}
{"op":"mcm","clk":"5348390698","pt":1646217194611,"mc":[{"id":"1.195453623","rc":[{"atl":[[5.6,0]],"id":42513983},{"atl":[[300,2]],"id":28222454}],"con":true,"img":false}]}
{"op":"mcm","clk":"5348390710","pt":1646217194715,"mc":[{"id":"1.195453623","rc":[{"atl":[[280,2.72]],"id":28222454}],"con":true,"img":false}]}
{"op":"mcm","clk":"5348390721","pt":1646217194820,"mc":[{"id":"1.195453623","rc":[{"atl":[[290,0],[300,4]],"id":28222454}],"con":true,"img":false}]}
{"op":"mcm","clk":"5348390731","pt":1646217194924,"mc":[{"id":"1.195453623","rc":[{"atl":[[280,6.72],[300,2]],"id":28222454}],"con":true,"img":false}]}
{"op":"mcm","clk":"5348390739","pt":1646217195029,"mc":[{"id":"1.195453623","rc":[{"atl":[[300,0]],"id":28222454}],"con":true,"img":false}]}
{"op":"mcm","clk":"5348390746","pt":1646217195136,"mc":[{"id":"1.195453623","rc":[{"atl":[[280,4.72],[1000,0]],"id":28222454}],"con":true,"img":false}]}
{"op":"mcm","clk":"5348390755","pt":1646217195191,"mc":[{"id":"1.195453623","rc":[{"atl":[[270,1.33],[280,6.72]],"id":28222454}],"con":true,"img":false}]}
{"op":"mcm","clk":"5348390810","pt":1646217195814,"mc":[{"id":"1.195453623","rc":[{"atl":[[270,0]],"id":28222454}],"con":true,"img":false}]}
{"op":"mcm","clk":"5348390821","pt":1646217195920,"mc":[{"id":"1.195453623","rc":[{"atl":[[1000,1.33]],"id":28222454}],"con":true,"img":false}]}
{"op":"mcm","clk":"5348391199","pt":1646217199904,"mc":[{"id":"1.195453623","rc":[{"atl":[[5.6,2.52]],"id":42513983}],"con":true,"img":false}]}
{"op":"mcm","clk":"5348391232","pt":1646217200218,"mc":[{"id":"1.195453623","rc":[{"atl":[[5.6,0]],"id":42513983}],"con":true,"img":false}]}
{"op":"mcm","clk":"5348391664","pt":1646217205043,"mc":[{"id":"1.195453623","rc":[{"atl":[[5.6,2.52]],"id":42513983}],"con":true,"img":false}]}
{"op":"mcm","clk":"5348391695","pt":1646217205412,"mc":[{"id":"1.195453623","rc":[{"atl":[[5.6,0]],"id":42513983}],"con":true,"img":false}]}
{"op":"mcm","clk":"5348391995","pt":1646217209213,"mc":[{"id":"1.195453623","rc":[{"atb":[[4.3,0],[1.01,2.25]],"id":41788482}],"con":true,"img":false}]}
{"op":"mcm","clk":"5348392035","pt":1646217209639,"mc":[{"id":"1.195453623","rc":[{"atb":[[1.01,0.83]],"id":41788482}],"con":true,"img":false}]}
{"op":"mcm","clk":"5348392062","pt":1646217210001,"mc":[{"id":"1.195453623","rc":[{"atb":[[1.01,0]],"id":41788482},{"atl":[[5.6,2.52]],"id":42513983}],"con":true,"img":false}]}
{"op":"mcm","clk":"5348392070","pt":1646217210106,"mc":[{"id":"1.195453623","rc":[{"atb":[[4.5,0.83]],"id":41788482}],"con":true,"img":false}]}
{"op":"mcm","clk":"5348392080","pt":1646217210212,"mc":[{"id":"1.195453623","rc":[{"atl":[[5.6,0]],"id":42513983}],"con":true,"img":false}]}
{"op":"mcm","clk":"5348392134","pt":1646217210940,"mc":[{"id":"1.195453623","rc":[{"atb":[[4.4,0]],"id":41788482}],"con":true,"img":false}]}
{"op":"mcm","clk":"5348392243","pt":1646217212408,"mc":[{"id":"1.195453623","rc":[{"atb":[[4.6,2.5]],"id":41788482}],"con":true,"img":false}]}
{"op":"mcm","clk":"5348392309","pt":1646217213340,"mc":[{"id":"1.195453623","rc":[{"atl":[[300,2],[360,0]],"id":39658516}],"con":true,"img":false}]}
{"op":"mcm","clk":"5348392474","pt":1646217215120,"mc":[{"id":"1.195453623","rc":[{"atl":[[5.6,2.52]],"id":42513983}],"con":true,"img":false}]}
{"op":"mcm","clk":"5348392496","pt":1646217215331,"mc":[{"id":"1.195453623","rc":[{"atb":[[2.46,0]],"id":42513983}],"con":true,"img":false}]}
{"op":"mcm","clk":"5348392506","pt":1646217215433,"mc":[{"id":"1.195453623","rc":[{"atb":[[2.12,83.67],[2.38,0]],"id":41788482},{"atl":[[380,0],[370,1]],"id":39658516},{"atb":[[2.94,65.24]],"id":42513983}],"con":true,"img":false}]}
{"op":"mcm","clk":"5348392520","pt":1646217215643,"mc":[{"id":"1.195453623","rc":[{"atl":[[5.6,0]],"id":42513983}],"con":true,"img":false}]}
{"op":"mcm","clk":"5348392975","pt":1646217220629,"mc":[{"id":"1.195453623","rc":[{"atl":[[5.6,2.52]],"id":42513983}],"con":true,"img":false}]}
{"op":"mcm","clk":"5348393007","pt":1646217220952,"mc":[{"id":"1.195453623","rc":[{"atl":[[5.6,0]],"id":42513983}],"con":true,"img":false}]}
{"op":"mcm","clk":"5348393484","pt":1646217225852,"mc":[{"id":"1.195453623","rc":[{"spn":6.4,"spf":"NaN","id":41788482},{"atl":[[5.6,2.52]],"id":42513983}],"con":true,"img":false}]}
{"op":"mcm","clk":"5348393512","pt":1646217226267,"mc":[{"id":"1.195453623","rc":[{"atl":[[5.6,0]],"id":42513983}],"con":true,"img":false}]}
{"op":"mcm","clk":"5348393984","pt":1646217230927,"mc":[{"id":"1.195453623","rc":[{"atl":[[5.6,2.52]],"id":42513983}],"con":true,"img":false}]}
{"op":"mcm","clk":"5348394009","pt":1646217231246,"mc":[{"id":"1.195453623","rc":[{"atl":[[5.6,0]],"id":42513983}],"con":true,"img":false}]}
{"op":"mcm","clk":"5348394310","pt":1646217234660,"mc":[{"id":"1.195453623","rc":[{"atl":[[280,4]],"id":28222454}],"con":true,"img":false}]}
{"op":"mcm","clk":"5348394318","pt":1646217234761,"mc":[{"id":"1.195453623","rc":[{"atl":[[270,2.72]],"id":28222454}],"con":true,"img":false}]}
{"op":"mcm","clk":"5348394329","pt":1646217234877,"mc":[{"id":"1.195453623","rc":[{"atl":[[280,2],[350,2.38]],"id":28222454}],"con":true,"img":false}]}
{"op":"mcm","clk":"5348394346","pt":1646217235029,"mc":[{"id":"1.195453623","rc":[{"atl":[[270,4.72],[350,0.38]],"id":28222454}],"con":true,"img":false}]}
{"op":"mcm","clk":"5348394369","pt":1646217235344,"mc":[{"id":"1.195453623","rc":[{"atl":[[260,2],[280,0]],"id":28222454}],"con":true,"img":false}]}
{"op":"mcm","clk":"5348394452","pt":1646217236452,"mc":[{"id":"1.195453623","rc":[{"atl":[[5.6,2.52]],"id":42513983}],"con":true,"img":false}]}
{"op":"mcm","clk":"5348394482","pt":1646217236867,"mc":[{"id":"1.195453623","rc":[{"atl":[[5.6,0]],"id":42513983}],"con":true,"img":false}]}
{"op":"mcm","clk":"5348394931","pt":1646217241652,"mc":[{"id":"1.195453623","rc":[{"atl":[[1000,0]],"id":28222454}],"con":true,"img":false}]}
{"op":"mcm","clk":"5348394942","pt":1646217241758,"mc":[{"id":"1.195453623","rc":[{"atl":[[260,3.33]],"id":28222454}],"con":true,"img":false}]}
{"op":"mcm","clk":"5348394994","pt":1646217242342,"mc":[{"id":"1.195453623","rc":[{"atl":[[5.6,2.52]],"id":42513983}],"con":true,"img":false}]}
{"op":"mcm","clk":"5348395031","pt":1646217242769,"mc":[{"id":"1.195453623","rc":[{"atl":[[5.6,0]],"id":42513983}],"con":true,"img":false}]}
{"op":"mcm","clk":"5348395214","pt":1646217244544,"mc":[{"id":"1.195453623","rc":[{"atl":[[130,0]],"id":39658516}],"con":true,"img":false}]}
{"op":"mcm","clk":"5348395227","pt":1646217244649,"mc":[{"id":"1.195453623","rc":[{"atl":[[180,2.72]],"id":39658516}],"con":true,"img":false}]}
{"op":"mcm","clk":"5348395236","pt":1646217244751,"mc":[{"id":"1.195453623","rc":[{"atl":[[240,2.83]],"id":39658516}],"con":true,"img":false}]}
{"op":"mcm","clk":"5348395527","pt":1646217248076,"mc":[{"id":"1.195453623","rc":[{"atl":[[5.6,2.52]],"id":42513983}],"con":true,"img":false}]}
{"op":"mcm","clk":"5348395544","pt":1646217248284,"mc":[{"id":"1.195453623","rc":[{"atl":[[370,0],[380,1]],"id":39658516}],"con":true,"img":false}]}
{"op":"mcm","clk":"5348395552","pt":1646217248388,"mc":[{"id":"1.195453623","rc":[{"atl":[[5.6,0]],"id":42513983}],"con":true,"img":false}]}
{"op":"mcm","clk":"5348395695","pt":1646217249967,"mc":[{"id":"1.195453623","rc":[{"atl":[[180,4.72],[240,0.83]],"id":39658516}],"con":true,"img":false}]}
{"op":"mcm","clk":"5348396037","pt":1646217253980,"mc":[{"id":"1.195453623","rc":[{"atl":[[5.6,2.52]],"id":42513983}],"con":true,"img":false}]}
{"op":"mcm","clk":"5348396103","pt":1646217254555,"mc":[{"id":"1.195453623","rc":[{"atl":[[5.6,0]],"id":42513983}],"con":true,"img":false}]}
{"op":"mcm","clk":"5348396570","pt":1646217259877,"mc":[{"id":"1.195453623","rc":[{"atl":[[5.6,2.52]],"id":42513983}],"con":true,"img":false}]}
{"op":"mcm","clk":"5348396610","pt":1646217260397,"mc":[{"id":"1.195453623","rc":[{"atl":[[5.6,0]],"id":42513983}],"con":true,"img":false}]}
{"op":"mcm","clk":"5348397099","pt":1646217265792,"mc":[{"id":"1.195453623","rc":[{"atl":[[5.6,2.52]],"id":42513983}],"con":true,"img":false}]}
{"op":"mcm","clk":"5348397126","pt":1646217266105,"mc":[{"id":"1.195453623","rc":[{"atl":[[5.6,0]],"id":42513983}],"con":true,"img":false}]}
{"op":"mcm","clk":"5348397619","pt":1646217271679,"mc":[{"id":"1.195453623","rc":[{"atl":[[5.6,2.52]],"id":42513983}],"con":true,"img":false}]}
{"op":"mcm","clk":"5348397654","pt":1646217272097,"mc":[{"id":"1.195453623","rc":[{"atl":[[5.6,0]],"id":42513983}],"con":true,"img":false}]}
{"op":"mcm","clk":"5348397894","pt":1646217274700,"mc":[{"id":"1.195453623","rc":[{"atl":[[270,2]],"id":28222454}],"con":true,"img":false}]}
{"op":"mcm","clk":"5348397904","pt":1646217274803,"mc":[{"id":"1.195453623","rc":[{"atl":[[250,2.72]],"id":28222454}],"con":true,"img":false}]}
{"op":"mcm","clk":"5348397920","pt":1646217275011,"mc":[{"id":"1.195453623","rc":[{"atl":[[270,0],[250,4.72]],"id":28222454}],"con":true,"img":false}]}
{"op":"mcm","clk":"5348397943","pt":1646217275218,"mc":[{"id":"1.195453623","rc":[{"atl":[[260,0],[240,2]],"id":28222454}],"con":true,"img":false}]}
{"op":"mcm","clk":"5348397952","pt":1646217275320,"mc":[{"id":"1.195453623","rc":[{"atl":[[240,3.33]],"id":28222454}],"con":true,"img":false}]}
{"op":"mcm","clk":"5348398135","pt":1646217277421,"mc":[{"id":"1.195453623","rc":[{"atl":[[5.6,2.52]],"id":42513983}],"con":true,"img":false}]}
{"op":"mcm","clk":"5348398186","pt":1646217277794,"mc":[{"id":"1.195453623","rc":[{"atl":[[5.6,0]],"id":42513983}],"con":true,"img":false}]}
{"op":"mcm","clk":"5348398756","pt":1646217283129,"mc":[{"id":"1.195453623","rc":[{"atl":[[5.6,2.52]],"id":42513983}],"con":true,"img":false}]}
{"op":"mcm","clk":"5348398789","pt":1646217283443,"mc":[{"id":"1.195453623","rc":[{"atl":[[5.6,0]],"id":42513983}],"con":true,"img":false}]}
{"op":"mcm","clk":"5348399330","pt":1646217289130,"mc":[{"id":"1.195453623","rc":[{"spn":82.0,"spf":"NaN","id":39658516},{"atl":[[5.6,2.52]],"id":42513983}],"con":true,"img":false}]}
{"op":"mcm","clk":"5348399359","pt":1646217289545,"mc":[{"id":"1.195453623","rc":[{"atl":[[5.6,0]],"id":42513983}],"con":true,"img":false}]}
{"op":"mcm","clk":"5348399902","pt":1646217295263,"mc":[{"id":"1.195453623","rc":[{"atl":[[5.6,2.52]],"id":42513983}],"con":true,"img":false}]}
{"op":"mcm","clk":"5348399943","pt":1646217295627,"mc":[{"id":"1.195453623","rc":[{"atl":[[5.6,0]],"id":42513983}],"con":true,"img":false}]}
{"op":"mcm","clk":"5348400235","pt":1646217299281,"mc":[{"id":"1.195453623","rc":[{"atb":[[1.01,2.25],[4.5,0]],"id":41788482}],"con":true,"img":false}]}
{"op":"mcm","clk":"5348400259","pt":1646217299441,"mc":[{"id":"1.195453623","rc":[{"atb":[[1.01,0.79]],"id":41788482}],"con":true,"img":false}]}
{"op":"mcm","clk":"5348400274","pt":1646217299646,"mc":[{"id":"1.195453623","rc":[{"atb":[[1.01,0]],"id":41788482}],"con":true,"img":false}]}
{"op":"mcm","clk":"5348400282","pt":1646217299752,"mc":[{"id":"1.195453623","rc":[{"atb":[[4.7,0.79]],"id":41788482}],"con":true,"img":false}]}
{"op":"mcm","clk":"5348400316","pt":1646217300169,"mc":[{"id":"1.195453623","rc":[{"atl":[[140,14.2],[150,1]],"id":37447009},{"atb":[[4,17.71],[3.9,6.9]],"id":41788482}],"con":true,"img":false}]}
{"op":"mcm","clk":"5348400364","pt":1646217300651,"mc":[{"id":"1.195453623","rc":[{"atb":[[3.95,0]],"id":41788482}],"con":true,"img":false}]}
{"op":"mcm","clk":"5348400371","pt":1646217300742,"mc":[{"id":"1.195453623","rc":[{"atb":[[3.9,45.51]],"id":41788482}],"con":true,"img":false}]}
{"op":"mcm","clk":"5348400478","pt":1646217301736,"mc":[{"id":"1.195453623","rc":[{"atl":[[5.6,2.52]],"id":42513983}],"con":true,"img":false}]}
{"op":"mcm","clk":"5348400555","pt":1646217302579,"mc":[{"id":"1.195453623","rc":[{"atl":[[5.6,0]],"id":42513983}],"con":true,"img":false}]}
{"op":"mcm","clk":"5348400993","pt":1646217306960,"mc":[{"id":"1.195453623","rc":[{"atl":[[5.6,2.52]],"id":42513983}],"con":true,"img":false}]}
{"op":"mcm","clk":"5348401016","pt":1646217307275,"mc":[{"id":"1.195453623","rc":[{"atl":[[5.6,0]],"id":42513983}],"con":true,"img":false}]}
{"op":"mcm","clk":"5348401027","pt":1646217307387,"mc":[{"id":"1.195453623","rc":[{"atb":[[4.1,6.33]],"id":41788482}],"con":true,"img":false}]}
{"op":"mcm","clk":"5348401223","pt":1646217309278,"mc":[{"id":"1.195453623","rc":[{"atb":[[4.1,3.64]],"id":41788482}],"con":true,"img":false}]}
{"op":"mcm","clk":"5348401320","pt":1646217310162,"mc":[{"id":"1.195453623","rc":[{"atl":[[170,1]],"id":37447009},{"atb":[[3.8,17.86]],"id":41788482}],"con":true,"img":false}]}
{"op":"mcm","clk":"5348401519","pt":1646217312466,"mc":[{"id":"1.195453623","rc":[{"atl":[[5.6,2.52]],"id":42513983}],"con":true,"img":false}]}
{"op":"mcm","clk":"5348401560","pt":1646217312885,"mc":[{"id":"1.195453623","rc":[{"atl":[[5.6,0]],"id":42513983}],"con":true,"img":false}]}
{"op":"mcm","clk":"5348401743","pt":1646217314655,"mc":[{"id":"1.195453623","rc":[{"atl":[[250,2]],"id":28222454}],"con":true,"img":false}]}
{"op":"mcm","clk":"5348401754","pt":1646217314760,"mc":[{"id":"1.195453623","rc":[{"atl":[[230,2.72]],"id":28222454}],"con":true,"img":false}]}
{"op":"mcm","clk":"5348401764","pt":1646217314864,"mc":[{"id":"1.195453623","rc":[{"atl":[[240,5.33],[250,0]],"id":28222454}],"con":true,"img":false}]}
{"op":"mcm","clk":"5348401781","pt":1646217315071,"mc":[{"id":"1.195453623","rc":[{"atl":[[240,4]],"id":28222454}],"con":true,"img":false}]}
{"op":"mcm","clk":"5348401790","pt":1646217315175,"mc":[{"id":"1.195453623","rc":[{"atl":[[220,1.57]],"id":28222454}],"con":true,"img":false}]}
{"op":"mcm","clk":"5348401812","pt":1646217315383,"mc":[{"id":"1.195453623","rc":[{"atl":[[220,3.57],[240,2]],"id":28222454}],"con":true,"img":false}]}
{"op":"mcm","clk":"5348401824","pt":1646217315488,"mc":[{"id":"1.195453623","rc":[{"atl":[[220,1.57],[230,4.72]],"id":28222454}],"con":true,"img":false}]}
{"op":"mcm","clk":"5348402087","pt":1646217318270,"mc":[{"id":"1.195453623","rc":[{"atl":[[5.6,2.52]],"id":42513983}],"con":true,"img":false}]}
{"op":"mcm","clk":"5348402105","pt":1646217318476,"mc":[{"id":"1.195453623","rc":[{"atl":[[5.6,0]],"id":42513983}],"con":true,"img":false}]}
{"op":"mcm","clk":"5348402168","pt":1646217319260,"mc":[{"id":"1.195453623","rc":[{"atb":[[3.95,2.54]],"id":41788482}],"con":true,"img":false}]}
{"op":"mcm","clk":"5348402241","pt":1646217320098,"mc":[{"id":"1.195453623","rc":[{"spl":[[26,2.72]],"id":39658516}],"con":true,"img":false}]}
{"op":"mcm","clk":"5348402252","pt":1646217320203,"mc":[{"id":"1.195453623","rc":[{"atl":[[160,1.25],[180,0],[190,1],[200,0]],"id":37447009},{"atb":[[3.7,27.78]],"id":41788482}],"con":true,"img":false}]}
{"op":"mcm","clk":"5348402576","pt":1646217323686,"mc":[{"id":"1.195453623","rc":[{"atl":[[5.6,2.52]],"id":42513983}],"con":true,"img":false}]}
{"op":"mcm","clk":"5348402603","pt":1646217323988,"mc":[{"id":"1.195453623","rc":[{"atl":[[5.6,0]],"id":42513983}],"con":true,"img":false}]}
{"op":"mcm","clk":"5348402614","pt":1646217324093,"mc":[{"id":"1.195453623","rc":[{"atb":[[3.95,5.37]],"id":41788482}],"con":true,"img":false}]}
{"op":"mcm","clk":"5348403178","pt":1646217329612,"mc":[{"id":"1.195453623","rc":[{"atl":[[5.6,2.52]],"id":42513983}],"con":true,"img":false}]}
{"op":"mcm","clk":"5348403210","pt":1646217329883,"mc":[{"id":"1.195453623","rc":[{"atl":[[5.6,0]],"id":42513983}],"con":true,"img":false}]}
{"op":"mcm","clk":"5348403243","pt":1646217330195,"mc":[{"id":"1.195453623","rc":[{"atl":[[210,1]],"id":37447009},{"atb":[[3.6,48.08]],"id":41788482}],"con":true,"img":false}]}
{"op":"mcm","clk":"5348403808","pt":1646217335830,"mc":[{"id":"1.195453623","rc":[{"atl":[[5.6,2.52]],"id":42513983}],"con":true,"img":false}]}
{"op":"mcm","clk":"5348403838","pt":1646217336089,"mc":[{"id":"1.195453623","rc":[{"atl":[[5.6,0]],"id":42513983}],"con":true,"img":false}]}
{"op":"mcm","clk":"5348404295","pt":1646217341230,"mc":[{"id":"1.195453623","rc":[{"atb":[[2.12,0],[2.42,70.42]],"id":41788482}],"con":true,"img":false}]}
{"op":"mcm","clk":"5348404348","pt":1646217341701,"mc":[{"id":"1.195453623","rc":[{"atb":[[3.3,0],[3.5,8]],"id":37447009},{"atl":[[140,15.2],[150,0]],"id":37447009},{"atl":[[3.55,0],[3.45,40.82]],"id":36074465},{"atb":[[4,24.38],[3.9,38.61]],"id":41788482},{"atl":[[13,1.67],[15.5,6.9],[23,8.2]],"id":41788482},{"atb":[[9,0],[9.2,14.64]],"id":39658516},{"atl":[[14.5,1.48],[15,8.2],[5.6,2.52]],"id":42513983},{"atb":[[21,5.08],[22,0]],"id":28222454}],"con":true,"img":false}]}
{"op":"mcm","clk":"5348404359","pt":1646217341806,"mc":[{"id":"1.195453623","rc":[{"atl":[[3.55,7.84]],"id":36074465}],"con":true,"img":false}]}
{"op":"mcm","clk":"5348404393","pt":1646217342229,"mc":[{"id":"1.195453623","rc":[{"atl":[[5.6,0]],"id":42513983}],"con":true,"img":false}]}
{"op":"mcm","clk":"5348404618","pt":1646217344833,"mc":[{"id":"1.195453623","rc":[{"atl":[[140,14.2],[150,1]],"id":37447009},{"atb":[[4,17.71],[3.9,45.51]],"id":41788482}],"con":true,"img":false}]}
{"op":"mcm","clk":"5348404828","pt":1646217347395,"mc":[{"id":"1.195453623","rc":[{"atl":[[5.6,2.52]],"id":42513983}],"con":true,"img":false}]}
{"op":"mcm","clk":"5348404845","pt":1646217347605,"mc":[{"id":"1.195453623","rc":[{"atl":[[5.6,0]],"id":42513983}],"con":true,"img":false}]}
{"op":"mcm","clk":"5348404963","pt":1646217348915,"mc":[{"id":"1.195453623","rc":[{"atl":[[140,15.2],[150,0]],"id":37447009},{"atb":[[1.78,0],[1.76,140.9],[1.75,135.66]],"id":36074465},{"atb":[[4,24.38],[3.9,38.61]],"id":41788482},{"atl":[[16.5,0],[17.5,1.21]],"id":37286329}],"con":true,"img":false}]}
{"op":"mcm","clk":"5348405004","pt":1646217349433,"mc":[{"id":"1.195453623","rc":[{"atb":[[3.95,2.82]],"id":41788482},{"spn":6.45,"spf":"NaN","id":41788482},{"spn":25.0,"spf":1.0,"id":39658516}],"con":true,"img":false}]}
{"op":"mcm","clk":"5348405248","pt":1646217351739,"mc":[{"id":"1.195453623","rc":[{"atb":[[19.5,2.7]],"id":28222454}],"con":true,"img":false}]}
{"op":"mcm","clk":"5348405447","pt":1646217353945,"mc":[{"id":"1.195453623","rc":[{"atl":[[5.6,2.52]],"id":42513983}],"con":true,"img":false}]}
{"op":"mcm","clk":"5348405485","pt":1646217354368,"mc":[{"id":"1.195453623","rc":[{"atl":[[5.6,0]],"id":42513983}],"con":true,"img":false}]}
{"op":"mcm","clk":"5348405508","pt":1646217354622,"mc":[{"id":"1.195453623","rc":[{"atl":[[230,2]],"id":28222454}],"con":true,"img":false}]}
{"op":"mcm","clk":"5348405517","pt":1646217354727,"mc":[{"id":"1.195453623","rc":[{"atl":[[210,2.72]],"id":28222454}],"con":true,"img":false}]}
{"op":"mcm","clk":"5348405537","pt":1646217354943,"mc":[{"id":"1.195453623","rc":[{"atl":[[210,4.72],[230,0]],"id":28222454}],"con":true,"img":false}]}
{"op":"mcm","clk":"5348405959","pt":1646217358921,"mc":[{"id":"1.195453623","rc":[{"atb":[[3.4,20.83]],"id":37447009},{"atb":[[1.73,68.49]],"id":36074465},{"atl":[[3.65,18.87]],"id":36074465},{"atb":[[3.9,55.85]],"id":41788482},{"atl":[[14,3.85]],"id":41788482},{"atl":[[18.5,10.47]],"id":37286329}],"con":true,"img":false}]}
{"op":"mcm","clk":"5348406044","pt":1646217359736,"mc":[{"id":"1.195453623","rc":[{"atl":[[220,0.24]],"id":28222454}],"con":true,"img":false}]}
{"op":"mcm","clk":"5348406050","pt":1646217359837,"mc":[{"id":"1.195453623","rc":[{"atl":[[200,1.33]],"id":28222454}],"con":true,"img":false}]}
{"op":"mcm","clk":"5348406070","pt":1646217360047,"mc":[{"id":"1.195453623","rc":[{"atb":[[3,0]],"id":37447009},{"atl":[[5.6,2.52]],"id":42513983},{"atl":[[18,0],[19,0],[20,0]],"id":37286329},{"atb":[[18,4.8],[19,0],[20,0]],"id":28222454}],"con":true,"img":false}]}
{"op":"mcm","clk":"5348406084","pt":1646217360157,"mc":[{"id":"1.195453623","rc":[{"atb":[[3.6,0]],"id":41788482},{"atl":[[25,0],[27,0],[29,0]],"id":41788482}],"con":true,"img":false}]}
{"op":"mcm","clk":"5348406096","pt":1646217360210,"mc":[{"id":"1.195453623","rc":[{"atb":[[3.2,2]],"id":37286329}],"con":true,"img":false}]}
{"op":"mcm","clk":"5348406114","pt":1646217360417,"mc":[{"id":"1.195453623","rc":[{"atl":[[5.6,0]],"id":42513983}],"con":true,"img":false}]}
{"op":"mcm","clk":"5348406135","pt":1646217360627,"mc":[{"id":"1.195453623","rc":[{"atl":[[210,2]],"id":28222454}],"con":true,"img":false}]}
{"op":"mcm","clk":"5348406145","pt":1646217360726,"mc":[{"id":"1.195453623","rc":[{"atl":[[230,2.72]],"id":28222454}],"con":true,"img":false}]}
{"op":"mcm","clk":"5348406251","pt":1646217361738,"mc":[{"id":"1.195453623","rc":[{"atb":[[18.5,4.29]],"id":28222454}],"con":true,"img":false}]}
{"op":"mcm","clk":"5348406475","pt":1646217364425,"mc":[{"id":"1.195453623","rc":[{"atb":[[4.1,6.07]],"id":41788482}],"con":true,"img":false}]}
{"op":"mcm","clk":"5348406582","pt":1646217365614,"mc":[{"id":"1.195453623","rc":[{"atl":[[5.6,2.52]],"id":42513983}],"con":true,"img":false}]}
{"op":"mcm","clk":"5348406601","pt":1646217365830,"mc":[{"id":"1.195453623","rc":[{"atl":[[3.2,2]],"id":36074465},{"atb":[[3.25,4]],"id":37286329}],"con":true,"img":false}]}
{"op":"mcm","clk":"5348406611","pt":1646217365928,"mc":[{"id":"1.195453623","rc":[{"atl":[[5.6,0]],"id":42513983}],"con":true,"img":false}]}
{"op":"mcm","clk":"5348406868","pt":1646217368949,"mc":[{"id":"1.195453623","rc":[{"atb":[[1.71,105.63]],"id":36074465},{"atl":[[3.75,27.27]],"id":36074465},{"atb":[[3.8,26.79]],"id":41788482},{"atl":[[15,14.87]],"id":41788482},{"atl":[[19.5,4.05]],"id":37286329}],"con":true,"img":false}]}
{"op":"mcm","clk":"5348406892","pt":1646217369261,"mc":[{"id":"1.195453623","rc":[{"atb":[[3.3,32.61]],"id":37447009}],"con":true,"img":false}]}
{"op":"mcm","clk":"5348406927","pt":1646217369730,"mc":[{"id":"1.195453623","rc":[{"atb":[[3.95,0]],"id":41788482}],"con":true,"img":false}]}
{"op":"mcm","clk":"5348407074","pt":1646217371453,"mc":[{"id":"1.195453623","rc":[{"atl":[[5.6,2.52]],"id":42513983}],"con":true,"img":false}]}
{"op":"mcm","clk":"5348407103","pt":1646217371766,"mc":[{"id":"1.195453623","rc":[{"atb":[[17.5,7.58]],"id":28222454}],"con":true,"img":false}]}
{"op":"mcm","clk":"5348407114","pt":1646217371872,"mc":[{"id":"1.195453623","rc":[{"atl":[[5.6,0]],"id":42513983}],"con":true,"img":false}]}
{"op":"mcm","clk":"5348407490","pt":1646217375852,"mc":[{"id":"1.195453623","rc":[{"atl":[[3.15,2]],"id":36074465},{"atb":[[3.3,34.3]],"id":37286329}],"con":true,"img":false}]}
{"op":"mcm","clk":"5348407536","pt":1646217376265,"mc":[{"id":"1.195453623","rc":[{"atb":[[5.6,0]],"id":39658516}],"con":true,"img":false}]}
{"op":"mcm","clk":"5348407664","pt":1646217377626,"mc":[{"id":"1.195453623","rc":[{"atl":[[5.6,2.52]],"id":42513983}],"con":true,"img":false}]}
{"op":"mcm","clk":"5348407703","pt":1646217378050,"mc":[{"id":"1.195453623","rc":[{"atl":[[5.6,0]],"id":42513983}],"con":true,"img":false}]}
{"op":"mcm","clk":"5348407747","pt":1646217378563,"mc":[{"id":"1.195453623","rc":[{"atl":[[220,0]],"id":28222454}],"con":true,"img":false}]}
{"op":"mcm","clk":"5348407758","pt":1646217378667,"mc":[{"id":"1.195453623","rc":[{"atl":[[190,0.24]],"id":28222454}],"con":true,"img":false}]}
{"op":"mcm","clk":"5348407781","pt":1646217378927,"mc":[{"id":"1.195453623","rc":[{"atb":[[3.2,79.55]],"id":37447009},{"atb":[[1.69,181.16],[1.72,0],[1.74,0]],"id":36074465},{"atl":[[3.85,43.86]],"id":36074465},{"atb":[[3.7,74.08]],"id":41788482},{"atl":[[16,8.33]],"id":41788482},{"atl":[[21,6.25]],"id":37286329}],"con":true,"img":false}]}
{"op":"mcm","clk":"5348407787","pt":1646217379084,"mc":[{"id":"1.195453623","rc":[{"atb":[[3.1,0],[3.2,56.82]],"id":37447009},{"atb":[[3.7,46.3]],"id":41788482}],"con":true,"img":false}]}
{"op":"mcm","clk":"5348408234","pt":1646217383641,"mc":[{"id":"1.195453623","rc":[{"atl":[[5.6,2.52]],"id":42513983}],"con":true,"img":false}]}
{"op":"mcm","clk":"5348408259","pt":1646217383865,"mc":[{"id":"1.195453623","rc":[{"atl":[[3.1,4]],"id":36074465},{"atb":[[3.35,4]],"id":37286329}],"con":true,"img":false}]}
{"op":"mcm","clk":"5348408283","pt":1646217384056,"mc":[{"id":"1.195453623","rc":[{"atl":[[5.6,0]],"id":42513983}],"con":true,"img":false}]}
{"op":"mcm","clk":"5348408301","pt":1646217384263,"mc":[{"id":"1.195453623","rc":[{"atb":[[4.1,8.76]],"id":41788482}],"con":true,"img":false}]}
{"op":"mcm","clk":"5348408800","pt":1646217389760,"mc":[{"id":"1.195453623","rc":[{"atl":[[5.6,2.52]],"id":42513983}],"con":true,"img":false}]}
{"op":"mcm","clk":"5348408827","pt":1646217390173,"mc":[{"id":"1.195453623","rc":[{"atl":[[5.6,0]],"id":42513983}],"con":true,"img":false}]}
{"op":"mcm","clk":"5348409128","pt":1646217393884,"mc":[{"id":"1.195453623","rc":[{"atl":[[3.05,2]],"id":36074465}],"con":true,"img":false}]}
{"op":"mcm","clk":"5348409256","pt":1646217395448,"mc":[{"id":"1.195453623","rc":[{"atl":[[5.6,2.52]],"id":42513983}],"con":true,"img":false}]}
{"op":"mcm","clk":"5348409281","pt":1646217395757,"mc":[{"id":"1.195453623","rc":[{"atl":[[5.6,0]],"id":42513983}],"con":true,"img":false}]}
{"op":"mcm","clk":"5348409669","pt":1646217400601,"mc":[{"id":"1.195453623","rc":[{"atl":[[180,2]],"id":39658516}],"con":true,"img":false}]}
{"op":"mcm","clk":"5348409681","pt":1646217400654,"mc":[{"id":"1.195453623","rc":[{"atl":[[130,2.72]],"id":39658516}],"con":true,"img":false}]}
{"op":"mcm","clk":"5348409695","pt":1646217400825,"mc":[{"id":"1.195453623","rc":[{"atl":[[180,0],[240,2.83]],"id":39658516}],"con":true,"img":false}]}
{"op":"mcm","clk":"5348409728","pt":1646217401178,"mc":[{"id":"1.195453623","rc":[{"atl":[[5.6,2.52]],"id":42513983}],"con":true,"img":false}]}
{"op":"mcm","clk":"5348409747","pt":1646217401390,"mc":[{"id":"1.195453623","rc":[{"atl":[[1000,0]],"id":42513983}],"con":true,"img":false}]}
{"op":"mcm","clk":"5348409752","pt":1646217401487,"mc":[{"id":"1.195453623","rc":[{"atl":[[5.6,0],[5.5,1.3]],"id":42513983}],"con":true,"img":false}]}
{"op":"mcm","clk":"5348409807","pt":1646217402165,"mc":[{"id":"1.195453623","rc":[{"atl":[[5.5,0]],"id":42513983}],"con":true,"img":false}]}
{"op":"mcm","clk":"5348409815","pt":1646217402270,"mc":[{"id":"1.195453623","rc":[{"atl":[[1000,1.3]],"id":42513983}],"con":true,"img":false}]}
{"op":"mcm","clk":"5348410219","pt":1646217406879,"mc":[{"id":"1.195453623","rc":[{"atl":[[5.6,2.52]],"id":42513983}],"con":true,"img":false}]}
{"op":"mcm","clk":"5348410248","pt":1646217407192,"mc":[{"id":"1.195453623","rc":[{"atl":[[1000,0]],"id":42513983}],"con":true,"img":false}]}
{"op":"mcm","clk":"5348410254","pt":1646217407293,"mc":[{"id":"1.195453623","rc":[{"atl":[[5.5,1.3]],"id":42513983}],"con":true,"img":false}]}
{"op":"mcm","clk":"5348410258","pt":1646217407396,"mc":[{"id":"1.195453623","rc":[{"atl":[[5.6,0]],"id":42513983}],"con":true,"img":false}]}
{"op":"mcm","clk":"5348410310","pt":1646217407867,"mc":[{"id":"1.195453623","rc":[{"atl":[[5.5,0]],"id":42513983}],"con":true,"img":false}]}
{"op":"mcm","clk":"5348410322","pt":1646217407967,"mc":[{"id":"1.195453623","rc":[{"atl":[[1000,1.3]],"id":42513983}],"con":true,"img":false}]}
{"op":"mcm","clk":"5348410758","pt":1646217412795,"mc":[{"id":"1.195453623","rc":[{"atl":[[5.6,2.52]],"id":42513983},{"spn":118.0,"spf":"NaN","id":28222454}],"con":true,"img":false}]}
{"op":"mcm","clk":"5348410800","pt":1646217413272,"mc":[{"id":"1.195453623","rc":[{"atl":[[5.6,0]],"id":42513983}],"con":true,"img":false}]}
{"op":"mcm","clk":"5348411167","pt":1646217417515,"mc":[{"id":"1.195453623","rc":[{"atb":[[6.4,0],[7.4,0],[9.4,0],[5.2,17.14],[5.7,0]],"id":37447009},{"atl":[[160,0],[55,0],[80,0],[110,0]],"id":37447009},{"atb":[[1.85,0],[1.7,0],[1.95,0],[1.8,0],[1.75,26.67]],"id":36074465},{"atl":[[5.6,0],[5.1,0],[4.6,0],[6.2,0]],"id":36074465},{"atb":[[3.85,0],[3.1,0],[3.35,0],[2.84,0],[2.94,0]],"id":41788482},{"atl":[[12.5,0],[15,5.36],[17.5,0],[20,0]],"id":41788482},{"atb":[[11.5,0],[16.5,0],[9.6,0],[8.6,16.05],[7.6,0]],"id":39658516},{"atl":[[140,0],[290,0],[190,0],[240,2]],"id":39658516},{"atb":[[2.82,0],[2.72,0],[2.62,0],[3.05,0],[2.52,0]],"id":42513983},{"atl":[[9.2,0],[10.5,0],[8.2,0],[13,0]],"id":42513983},{"atb":[[3.5,0],[3.75,0],[4,0],[4.5,0],[5.5,0]],"id":37286329},{"atl":[[34,0],[18.5,2.86],[22,0],[27,0]],"id":37286329},{"atb":[[42,2],[15.5,0],[18,0],[21,1],[26,0]],"id":28222454},{"atl":[[350,0],[400,0],[450,0],[500,0]],"id":28222454}],"con":true,"img":false}]}
{"op":"mcm","clk":"5348411232","pt":1646217418200,"mc":[{"id":"1.195453623","rc":[{"atb":[[6.4,1.51]],"id":37286329}],"con":true,"img":false}]}
{"op":"mcm","clk":"5348411240","pt":1646217418307,"mc":[{"id":"1.195453623","rc":[{"atb":[[1.01,1.37]],"id":37286329}],"con":true,"img":false}]}
{"op":"mcm","clk":"5348411252","pt":1646217418410,"mc":[{"id":"1.195453623","rc":[{"atb":[[1.03,2.25],[7.8,0]],"id":37286329}],"con":true,"img":false}]}
{"op":"mcm","clk":"5348411268","pt":1646217418580,"mc":[{"id":"1.195453623","rc":[{"atl":[[130,0]],"id":39658516},{"atb":[[1.03,0.48]],"id":37286329},{"atb":[[27,0]],"id":28222454}],"con":true,"img":false}]}
{"op":"mcm","clk":"5348411280","pt":1646217418679,"mc":[{"id":"1.195453623","rc":[{"atl":[[180,2.72]],"id":39658516},{"atb":[[23,4.53]],"id":28222454}],"con":true,"img":false}]}
{"op":"mcm","clk":"5348411290","pt":1646217418791,"mc":[{"id":"1.195453623","rc":[{"atl":[[380,3],[240,0]],"id":39658516},{"atl":[[5.6,2.52]],"id":42513983},{"atb":[[1.03,0]],"id":37286329}],"con":true,"img":false}]}
{"op":"mcm","clk":"5348411299","pt":1646217418894,"mc":[{"id":"1.195453623","rc":[{"atb":[[6.6,0.48]],"id":37286329}],"con":true,"img":false}]}
{"op":"mcm","clk":"5348411312","pt":1646217419020,"mc":[{"id":"1.195453623","rc":[{"atl":[[180,4.72],[380,1]],"id":39658516},{"atl":[[5.6,0]],"id":42513983}],"con":true,"img":false}]}
{"op":"mcm","clk":"5348411333","pt":1646217419216,"mc":[{"id":"1.195453623","rc":[{"atl":[[180,2.72]],"id":39658516}],"con":true,"img":false}]}
{"op":"mcm","clk":"5348411352","pt":1646217419377,"mc":[{"id":"1.195453623","rc":[{"atl":[[180,4.72]],"id":39658516}],"con":true,"img":false}]}
{"op":"mcm","clk":"5348411485","pt":1646217420740,"mc":[{"id":"1.195453623","rc":[{"atb":[[6.4,16.56],[7.4,6.98],[9.4,5.32],[5.2,59.71],[5.7,19.02]],"id":37447009},{"atl":[[160,1.18],[55,2.32],[80,1.59],[110,1.72]],"id":37447009},{"atb":[[1.85,43.8],[1.7,212.73],[1.95,39.19],[1.8,93.07],[1.75,125.95]],"id":36074465},{"atl":[[5.6,45.81],[5.1,34.26],[4.6,39.02],[6.2,40.52]],"id":36074465},{"atb":[[3.85,15.69],[3.1,42.57],[3.35,19.02],[2.84,97.19],[2.94,46.09]],"id":41788482},{"atl":[[12.5,10.91],[15,14.32],[17.5,11.41],[20,9.9]],"id":41788482},{"atb":[[11.5,4.25],[16.5,2.88],[9.6,10.39],[8.6,27.81],[7.6,27.09]],"id":39658516},{"atl":[[140,0.9],[290,0.65],[190,0.66],[240,0.79]],"id":39658516},{"atb":[[2.82,24.56],[2.72,51.99],[2.62,55.19],[3.05,21.81],[2.52,117.65]],"id":42513983},{"atl":[[9.2,15.3],[10.5,19.82],[8.2,17.43],[13,15.69]],"id":42513983},{"atb":[[3.5,71.53],[3.75,32.51],[4,29.8],[4.5,12.77],[5.5,9.93]],"id":37286329},{"atl":[[34,5.7],[18.5,10.03],[22,5.97],[27,7.24]],"id":37286329},{"atb":[[42,3.08],[15.5,12.33],[18,5.25],[21,5.46],[26,1.78]],"id":28222454},{"atl":[[350,0.35],[400,0.31],[450,0.41],[500,0.37]],"id":28222454}],"con":true,"img":false}]}
{"op":"mcm","clk":"5348411540","pt":1646217421210,"mc":[{"id":"1.195453623","rc":[{"atb":[[1.02,3.17]],"id":36074465},{"atb":[[1.03,2.93]],"id":41788482},{"atb":[[1.01,0]],"id":37286329}],"con":true,"img":false}]}
{"op":"mcm","clk":"5348411550","pt":1646217421317,"mc":[{"id":"1.195453623","rc":[{"atb":[[6.4,2.89]],"id":37286329}],"con":true,"img":false}]}
{"op":"mcm","clk":"5348411560","pt":1646217421422,"mc":[{"id":"1.195453623","rc":[{"atb":[[1.03,2.87]],"id":37286329}],"con":true,"img":false}]}
{"op":"mcm","clk":"5348411586","pt":1646217421580,"mc":[{"id":"1.195453623","rc":[{"atb":[[1.02,0.44]],"id":36074465},{"atb":[[1.03,0.2]],"id":41788482}],"con":true,"img":false}]}
{"op":"mcm","clk":"5348411624","pt":1646217421899,"mc":[{"id":"1.195453623","rc":[{"atb":[[1.03,0.15]],"id":37286329}],"con":true,"img":false}]}
{"op":"mcm","clk":"5348411636","pt":1646217422001,"mc":[{"id":"1.195453623","rc":[{"atb":[[1.02,0]],"id":36074465},{"atb":[[1.03,0]],"id":41788482}],"con":true,"img":false}]}
{"op":"mcm","clk":"5348411644","pt":1646217422105,"mc":[{"id":"1.195453623","rc":[{"atl":[[2.28,3.76]],"id":36074465},{"trd":[[2.28,0.89]],"ltp":2.28,"tv":0.89,"id":36074465},{"atb":[[5.1,0.2]],"id":41788482}],"con":true,"img":false}]}
{"op":"mcm","clk":"5348411669","pt":1646217422420,"mc":[{"id":"1.195453623","rc":[{"atb":[[1.02,3]],"id":42513983},{"atb":[[1.03,0]],"id":37286329}],"con":true,"img":false}]}
{"op":"mcm","clk":"5348411678","pt":1646217422527,"mc":[{"id":"1.195453623","rc":[{"atb":[[7,0.15]],"id":37286329}],"con":true,"img":false}]}
{"op":"mcm","clk":"5348411687","pt":1646217422582,"mc":[{"id":"1.195453623","rc":[{"atb":[[19,0]],"id":39658516}],"con":true,"img":false}]}
{"op":"mcm","clk":"5348411697","pt":1646217422690,"mc":[{"id":"1.195453623","rc":[{"atb":[[17,7.62]],"id":39658516}],"con":true,"img":false}]}
{"op":"mcm","clk":"5348411708","pt":1646217422796,"mc":[{"id":"1.195453623","rc":[{"atb":[[1.02,0.27]],"id":42513983}],"con":true,"img":false}]}
{"op":"mcm","clk":"5348411763","pt":1646217423319,"mc":[{"id":"1.195453623","rc":[{"atb":[[1.02,0]],"id":42513983}],"con":true,"img":false}]}
{"op":"mcm","clk":"5348411771","pt":1646217423373,"mc":[{"id":"1.195453623","rc":[{"atb":[[3.85,0.27]],"id":42513983}],"con":true,"img":false}]}
{"op":"mcm","clk":"5348411790","pt":1646217423580,"mc":[{"id":"1.195453623","rc":[{"atl":[[380,0],[370,1]],"id":39658516},{"atl":[[220,2],[240,0]],"id":28222454}],"con":true,"img":false}]}
{"op":"mcm","clk":"5348411819","pt":1646217423894,"mc":[{"id":"1.195453623","rc":[{"atb":[[4.6,0]],"id":41788482}],"con":true,"img":false}]}
{"op":"mcm","clk":"5348411837","pt":1646217424101,"mc":[{"id":"1.195453623","rc":[{"atb":[[1.01,2.25],[4.7,0]],"id":41788482}],"con":true,"img":false}]}
{"op":"mcm","clk":"5348411844","pt":1646217424204,"mc":[{"id":"1.195453623","rc":[{"atb":[[1.01,0.79]],"id":41788482}],"con":true,"img":false}]}
{"op":"mcm","clk":"5348411860","pt":1646217424415,"mc":[{"id":"1.195453623","rc":[{"atb":[[1.01,0]],"id":41788482}],"con":true,"img":false}]}
{"op":"mcm","clk":"5348411869","pt":1646217424548,"mc":[{"id":"1.195453623","rc":[{"atb":[[4.3,0.79]],"id":41788482}],"con":true,"img":false}]}
{"op":"mcm","clk":"5348411922","pt":1646217425017,"mc":[{"id":"1.195453623","rc":[{"atl":[[5.6,2.52]],"id":42513983}],"con":true,"img":false}]}
{"op":"mcm","clk":"5348411953","pt":1646217425282,"mc":[{"id":"1.195453623","rc":[{"atl":[[5.6,0]],"id":42513983}],"con":true,"img":false}]}
{"op":"mcm","clk":"5348411975","pt":1646217425488,"mc":[{"id":"1.195453623","rc":[{"atb":[[19.5,0]],"id":39658516}],"con":true,"img":false}]}
{"op":"mcm","clk":"5348412056","pt":1646217426325,"mc":[{"id":"1.195453623","rc":[{"atb":[[18.5,0.58]],"id":39658516}],"con":true,"img":false}]}
{"op":"mcm","clk":"5348412066","pt":1646217426389,"mc":[{"id":"1.195453623","rc":[{"atb":[[1.01,1.65]],"id":39658516}],"con":true,"img":false}]}
{"op":"mcm","clk":"5348412073","pt":1646217426494,"mc":[{"id":"1.195453623","rc":[{"atb":[[4.4,2.5]],"id":41788482}],"con":true,"img":false}]}
{"op":"mcm","clk":"5348412163","pt":1646217427521,"mc":[{"id":"1.195453623","rc":[{"atb":[[1.91,9.16]],"id":36074465}],"con":true,"img":false}]}
{"op":"mcm","clk":"5348412239","pt":1646217428307,"mc":[{"id":"1.195453623","rc":[{"atb":[[1.03,1.66]],"id":37447009},{"atl":[[1000,1.66]],"id":37447009},{"atb":[[1.02,1.66]],"id":39658516},{"atb":[[1.02,1.66]],"id":37286329},{"atl":[[1000,1.66]],"id":37286329}],"con":true,"img":false}]}
{"op":"mcm","clk":"5348412259","pt":1646217428517,"mc":[{"id":"1.195453623","rc":[{"atb":[[1.03,0.61]],"id":37447009},{"atl":[[1000,0.28]],"id":37447009},{"atb":[[1.02,0.33]],"id":39658516},{"atb":[[1.02,1.06]],"id":37286329},{"atl":[[1000,0.57]],"id":37286329}],"con":true,"img":false}]}
{"op":"mcm","clk":"5348412280","pt":1646217428731,"mc":[{"id":"1.195453623","rc":[{"atb":[[17.5,5.74]],"id":39658516}],"con":true,"img":false}]}
{"op":"mcm","clk":"5348412292","pt":1646217428797,"mc":[{"id":"1.195453623","rc":[{"atb":[[1.02,0]],"id":39658516}],"con":true,"img":false}]}
{"op":"mcm","clk":"5348412302","pt":1646217428893,"mc":[{"id":"1.195453623","rc":[{"atb":[[25,0.33]],"id":39658516}],"con":true,"img":false}]}
{"op":"mcm","clk":"5348412320","pt":1646217429108,"mc":[{"id":"1.195453623","rc":[{"atb":[[1.03,0]],"id":37447009}],"con":true,"img":false}]}
{"op":"mcm","clk":"5348412332","pt":1646217429215,"mc":[{"id":"1.195453623","rc":[{"atb":[[13.5,0.61]],"id":37447009}],"con":true,"img":false}]}
{"op":"mcm","clk":"5348412347","pt":1646217429413,"mc":[{"id":"1.195453623","rc":[{"atl":[[1000,0]],"id":37447009}],"con":true,"img":false}]}
{"op":"mcm","clk":"5348412356","pt":1646217429516,"mc":[{"id":"1.195453623","rc":[{"atl":[[29,0.28]],"id":37447009}],"con":true,"img":false}]}
{"op":"mcm","clk":"5348412376","pt":1646217429723,"mc":[{"id":"1.195453623","rc":[{"atl":[[1000,0]],"id":37286329}],"con":true,"img":false}]}
{"op":"mcm","clk":"5348412387","pt":1646217429829,"mc":[{"id":"1.195453623","rc":[{"atl":[[14.5,0.57]],"id":37286329}],"con":true,"img":false}]}
{"op":"mcm","clk":"5348412408","pt":1646217430036,"mc":[{"id":"1.195453623","rc":[{"atb":[[1.02,0]],"id":37286329}],"con":true,"img":false}]}
{"op":"mcm","clk":"5348412420","pt":1646217430095,"mc":[{"id":"1.195453623","rc":[{"atb":[[7.8,1.06]],"id":37286329}],"con":true,"img":false}]}
{"op":"mcm","clk":"5348412443","pt":1646217430301,"mc":[{"id":"1.195453623","rc":[{"atb":[[1.02,1.66],[7.8,0]],"id":37286329}],"con":true,"img":false}]}
{"op":"mcm","clk":"5348412459","pt":1646217430510,"mc":[{"id":"1.195453623","rc":[{"atb":[[1.02,1.06]],"id":37286329}],"con":true,"img":false}]}
{"op":"mcm","clk":"5348412483","pt":1646217430718,"mc":[{"id":"1.195453623","rc":[{"atb":[[1.02,0]],"id":37286329}],"con":true,"img":false}]}
{"op":"mcm","clk":"5348412491","pt":1646217430821,"mc":[{"id":"1.195453623","rc":[{"atb":[[7.6,1.28]],"id":37286329}],"con":true,"img":false}]}
{"op":"mcm","clk":"5348412503","pt":1646217430925,"mc":[{"id":"1.195453623","rc":[{"atb":[[8,2.5]],"id":37286329}],"con":true,"img":false}]}
{"op":"mcm","clk":"5348412516","pt":1646217431086,"mc":[{"id":"1.195453623","rc":[{"atb":[[1.01,1.66],[7.6,0.21]],"id":37286329}],"con":true,"img":false}]}
{"op":"mcm","clk":"5348412530","pt":1646217431342,"mc":[{"id":"1.195453623","rc":[{"atb":[[1.01,1.01]],"id":37286329}],"con":true,"img":false}]}
{"op":"mcm","clk":"5348412552","pt":1646217431604,"mc":[{"id":"1.195453623","rc":[{"atl":[[5.6,2.52]],"id":42513983},{"atb":[[1.01,0]],"id":37286329}],"con":true,"img":false}]}
{"op":"mcm","clk":"5348412562","pt":1646217431706,"mc":[{"id":"1.195453623","rc":[{"atb":[[8.2,1.01]],"id":37286329}],"con":true,"img":false}]}
{"op":"mcm","clk":"5348412580","pt":1646217431912,"mc":[{"id":"1.195453623","rc":[{"atl":[[5.6,0]],"id":42513983}],"con":true,"img":false}]}
{"op":"mcm","clk":"5348412752","pt":1646217433693,"mc":[{"id":"1.195453623","rc":[{"atb":[[8,0]],"id":37286329}],"con":true,"img":false}]}
{"op":"mcm","clk":"5348412990","pt":1646217436414,"mc":[{"id":"1.195453623","rc":[{"atb":[[1.01,2]],"id":36074465}],"con":true,"img":false}]}
{"op":"mcm","clk":"5348413012","pt":1646217436622,"mc":[{"id":"1.195453623","rc":[{"atb":[[1.01,3.99]],"id":36074465},{"atl":[[370,0],[380,1]],"id":39658516}],"con":true,"img":false}]}
{"op":"mcm","clk":"5348413033","pt":1646217436829,"mc":[{"id":"1.195453623","rc":[{"atb":[[1.01,2]],"id":36074465}],"con":true,"img":false}]}
{"op":"mcm","clk":"5348413039","pt":1646217436933,"mc":[{"id":"1.195453623","rc":[{"atb":[[1.02,1.99]],"id":36074465}],"con":true,"img":false}]}
{"op":"mcm","clk":"5348413103","pt":1646217437721,"mc":[{"id":"1.195453623","rc":[{"atl":[[5.6,2.52]],"id":42513983}],"con":true,"img":false}]}
{"op":"mcm","clk":"5348413130","pt":1646217437941,"mc":[{"id":"1.195453623","rc":[{"atb":[[1.01,2]],"id":41788482}],"con":true,"img":false}]}
{"op":"mcm","clk":"5348413136","pt":1646217438038,"mc":[{"id":"1.195453623","rc":[{"atl":[[1000,0],[5.6,0]],"id":42513983}],"con":true,"img":false}]}
{"op":"mcm","clk":"5348413144","pt":1646217438147,"mc":[{"id":"1.195453623","rc":[{"atb":[[1.01,3.99]],"id":41788482},{"atl":[[5.5,1.3]],"id":42513983}],"con":true,"img":false}]}
{"op":"mcm","clk":"5348413173","pt":1646217438406,"mc":[{"id":"1.195453623","rc":[{"atb":[[1.01,2]],"id":41788482}],"con":true,"img":false}]}
{"op":"mcm","clk":"5348413183","pt":1646217438561,"mc":[{"id":"1.195453623","rc":[{"atb":[[1.02,1.99]],"id":41788482}],"con":true,"img":false}]}
{"op":"mcm","clk":"5348413196","pt":1646217438729,"mc":[{"id":"1.195453623","rc":[{"atl":[[5.5,0]],"id":42513983}],"con":true,"img":false}]}
{"op":"mcm","clk":"5348413205","pt":1646217438828,"mc":[{"id":"1.195453623","rc":[{"atl":[[1000,1.3]],"id":42513983}],"con":true,"img":false}]}
{"op":"mcm","clk":"5348413347","pt":1646217440551,"mc":[{"id":"1.195453623","rc":[{"atb":[[1.01,2]],"id":37286329}],"con":true,"img":false}]}
{"op":"mcm","clk":"5348413372","pt":1646217440823,"mc":[{"id":"1.195453623","rc":[{"atb":[[1.01,3.99]],"id":37286329}],"con":true,"img":false}]}
{"op":"mcm","clk":"5348413392","pt":1646217441023,"mc":[{"id":"1.195453623","rc":[{"atb":[[1.01,2]],"id":37286329}],"con":true,"img":false}]}
{"op":"mcm","clk":"5348413400","pt":1646217441128,"mc":[{"id":"1.195453623","rc":[{"atb":[[1.02,1.99]],"id":37286329}],"con":true,"img":false}]}
{"op":"mcm","clk":"5348413610","pt":1646217443236,"mc":[{"id":"1.195453623","rc":[{"atb":[[1.01,2]],"id":42513983}],"con":true,"img":false}]}
{"op":"mcm","clk":"5348413630","pt":1646217443543,"mc":[{"id":"1.195453623","rc":[{"atb":[[1.01,3.99]],"id":42513983}],"con":true,"img":false}]}
{"op":"mcm","clk":"5348413648","pt":1646217443755,"mc":[{"id":"1.195453623","rc":[{"atb":[[1.01,2]],"id":42513983}],"con":true,"img":false}]}
{"op":"mcm","clk":"5348413662","pt":1646217443858,"mc":[{"id":"1.195453623","rc":[{"atb":[[1.02,1.99]],"id":42513983}],"con":true,"img":false}]}
{"op":"mcm","clk":"5348413690","pt":1646217444168,"mc":[{"id":"1.195453623","rc":[{"atl":[[5.6,2.52]],"id":42513983}],"con":true,"img":false}]}
{"op":"mcm","clk":"5348413706","pt":1646217444330,"mc":[{"id":"1.195453623","rc":[{"atb":[[8.2,0],[1.01,3.66]],"id":37286329}],"con":true,"img":false}]}
{"op":"mcm","clk":"5348413718","pt":1646217444436,"mc":[{"id":"1.195453623","rc":[{"atl":[[5.6,0]],"id":42513983}],"con":true,"img":false}]}
{"op":"mcm","clk":"5348413731","pt":1646217444540,"mc":[{"id":"1.195453623","rc":[{"atb":[[1.01,3.01]],"id":37286329}],"con":true,"img":false}]}
{"op":"mcm","clk":"5348413745","pt":1646217444750,"mc":[{"id":"1.195453623","rc":[{"atb":[[1.01,2]],"id":37286329}],"con":true,"img":false}]}
{"op":"mcm","clk":"5348413758","pt":1646217444855,"mc":[{"id":"1.195453623","rc":[{"atb":[[7.6,1.23]],"id":37286329}],"con":true,"img":false}]}
{"op":"mcm","clk":"5348413898","pt":1646217446469,"mc":[{"id":"1.195453623","rc":[{"atb":[[7.8,2.5]],"id":37286329}],"con":true,"img":false}]}
{"op":"mcm","clk":"5348413921","pt":1646217446632,"mc":[{"id":"1.195453623","rc":[{"atb":[[1.02,3.65],[7.6,0.21]],"id":37286329}],"con":true,"img":false}]}
{"op":"mcm","clk":"5348413934","pt":1646217446839,"mc":[{"id":"1.195453623","rc":[{"atb":[[1.02,3.03]],"id":37286329}],"con":true,"img":false}]}
{"op":"mcm","clk":"5348413951","pt":1646217447047,"mc":[{"id":"1.195453623","rc":[{"atb":[[1.02,1.99]],"id":37286329}],"con":true,"img":false}]}
{"op":"mcm","clk":"5348413960","pt":1646217447149,"mc":[{"id":"1.195453623","rc":[{"atb":[[8,1.04]],"id":37286329}],"con":true,"img":false}]}
{"op":"mcm","clk":"5348414124","pt":1646217449166,"mc":[{"id":"1.195453623","rc":[{"atb":[[7.8,0]],"id":37286329}],"con":true,"img":false}]}
{"op":"mcm","clk":"5348414293","pt":1646217450761,"mc":[{"id":"1.195453623","rc":[{"atb":[[8.2,2.5]],"id":37286329}],"con":true,"img":false}]}
{"op":"mcm","clk":"5348414304","pt":1646217450863,"mc":[{"id":"1.195453623","rc":[{"atb":[[7.4,0]],"id":37286329}],"con":true,"img":false}]}
{"op":"mcm","clk":"5348414315","pt":1646217450969,"mc":[{"id":"1.195453623","rc":[{"atb":[[7.2,1.62]],"id":37286329}],"con":true,"img":false}]}
{"op":"mcm","clk":"5348414326","pt":1646217451079,"mc":[{"id":"1.195453623","rc":[{"atl":[[5.6,2.52]],"id":42513983}],"con":true,"img":false}]}
{"op":"mcm","clk":"5348414334","pt":1646217451126,"mc":[{"id":"1.195453623","rc":[{"atb":[[8,0],[1.01,3.66]],"id":37286329}],"con":true,"img":false}]}
{"op":"mcm","clk":"5348414341","pt":1646217451234,"mc":[{"id":"1.195453623","rc":[{"atb":[[1.01,2.99]],"id":37286329}],"con":true,"img":false}]}
{"op":"mcm","clk":"5348414349","pt":1646217451337,"mc":[{"id":"1.195453623","rc":[{"atl":[[5.6,0]],"id":42513983}],"con":true,"img":false}]}
{"op":"mcm","clk":"5348414364","pt":1646217451438,"mc":[{"id":"1.195453623","rc":[{"atb":[[1.01,2]],"id":37286329}],"con":true,"img":false}]}
{"op":"mcm","clk":"5348414375","pt":1646217451541,"mc":[{"id":"1.195453623","rc":[{"atb":[[8.4,0.99]],"id":37286329}],"con":true,"img":false}]}
{"op":"mcm","clk":"5348414462","pt":1646217452533,"mc":[{"id":"1.195453623","rc":[{"atb":[[24,2.12]],"id":39658516}],"con":true,"img":false}]}
{"op":"mcm","clk":"5348414471","pt":1646217452637,"mc":[{"id":"1.195453623","rc":[{"atb":[[23,2.07],[26,1.25]],"id":39658516}],"con":true,"img":false}]}
{"op":"mcm","clk":"5348414479","pt":1646217452743,"mc":[{"id":"1.195453623","rc":[{"atb":[[24,0.12]],"id":39658516}],"con":true,"img":false}]}
{"op":"mcm","clk":"5348414488","pt":1646217452845,"mc":[{"id":"1.195453623","rc":[{"atb":[[23,0.07]],"id":39658516}],"con":true,"img":false}]}
{"op":"mcm","clk":"5348414499","pt":1646217452950,"mc":[{"id":"1.195453623","rc":[{"atb":[[26,3.25]],"id":39658516}],"con":true,"img":false}]}
{"op":"mcm","clk":"5348414511","pt":1646217453054,"mc":[{"id":"1.195453623","rc":[{"atb":[[1.03,1.66],[25,0]],"id":39658516}],"con":true,"img":false}]}
{"op":"mcm","clk":"5348414522","pt":1646217453158,"mc":[{"id":"1.195453623","rc":[{"atb":[[1.03,0.3]],"id":39658516}],"con":true,"img":false}]}
{"op":"mcm","clk":"5348414540","pt":1646217453366,"mc":[{"id":"1.195453623","rc":[{"atb":[[1.03,0]],"id":39658516}],"con":true,"img":false}]}
{"op":"mcm","clk":"5348414550","pt":1646217453470,"mc":[{"id":"1.195453623","rc":[{"atb":[[27,0.3]],"id":39658516}],"con":true,"img":false}]}
{"op":"mcm","clk":"5348414582","pt":1646217453735,"mc":[{"id":"1.195453623","rc":[{"atb":[[8.2,0]],"id":37286329}],"con":true,"img":false}]}
{"op":"mcm","clk":"5348414889","pt":1646217457342,"mc":[{"id":"1.195453623","rc":[{"atl":[[5.6,2.52]],"id":42513983}],"con":true,"img":false}]}
{"op":"mcm","clk":"5348414900","pt":1646217457443,"mc":[{"id":"1.195453623","rc":[{"atb":[[1.01,3.66],[8.4,0]],"id":37286329}],"con":true,"img":false}]}
{"op":"mcm","clk":"5348414909","pt":1646217457548,"mc":[{"id":"1.195453623","rc":[{"atl":[[380,0],[390,1]],"id":39658516},{"atb":[[1.01,2.99]],"id":37286329}],"con":true,"img":false}]}
{"op":"mcm","clk":"5348414925","pt":1646217457657,"mc":[{"id":"1.195453623","rc":[{"atl":[[5.6,0]],"id":42513983},{"atb":[[1.01,2]],"id":37286329}],"con":true,"img":false}]}
{"op":"mcm","clk":"5348414935","pt":1646217457760,"mc":[{"id":"1.195453623","rc":[{"atb":[[7.4,0.99]],"id":37286329}],"con":true,"img":false}]}
{"op":"mcm","clk":"5348414957","pt":1646217457970,"mc":[{"id":"1.195453623","rc":[{"atb":[[7.4,0],[1.02,3.65]],"id":37286329}],"con":true,"img":false}]}
{"op":"mcm","clk":"5348414968","pt":1646217458080,"mc":[{"id":"1.195453623","rc":[{"atb":[[1.02,3.05]],"id":37286329}],"con":true,"img":false}]}
{"op":"mcm","clk":"5348414990","pt":1646217458281,"mc":[{"id":"1.195453623","rc":[{"atb":[[1.02,1.99]],"id":37286329}],"con":true,"img":false}]}
{"op":"mcm","clk":"5348415001","pt":1646217458343,"mc":[{"id":"1.195453623","rc":[{"atb":[[7.8,1.06]],"id":37286329}],"con":true,"img":false}]}
{"op":"mcm","clk":"5348415099","pt":1646217459485,"mc":[{"id":"1.195453623","rc":[{"atb":[[8,2.5]],"id":37286329}],"con":true,"img":false}]}
{"op":"mcm","clk":"5348415119","pt":1646217459646,"mc":[{"id":"1.195453623","rc":[{"atb":[[1.01,3.66],[7.8,0]],"id":37286329}],"con":true,"img":false}]}
{"op":"mcm","clk":"5348415130","pt":1646217459748,"mc":[{"id":"1.195453623","rc":[{"atb":[[1.01,3.01]],"id":37286329}],"con":true,"img":false}]}
{"op":"mcm","clk":"5348415138","pt":1646217459854,"mc":[{"id":"1.195453623","rc":[{"atb":[[1.01,2]],"id":37286329}],"con":true,"img":false}]}
{"op":"mcm","clk":"5348415152","pt":1646217459961,"mc":[{"id":"1.195453623","rc":[{"atb":[[8.2,1.01]],"id":37286329}],"con":true,"img":false}]}
{"op":"mcm","clk":"5348415215","pt":1646217460684,"mc":[{"id":"1.195453623","rc":[{"atl":[[180,2]],"id":39658516}],"con":true,"img":false}]}
{"op":"mcm","clk":"5348415225","pt":1646217460792,"mc":[{"id":"1.195453623","rc":[{"atl":[[130,2.72]],"id":39658516}],"con":true,"img":false}]}
{"op":"mcm","clk":"5348415235","pt":1646217460893,"mc":[{"id":"1.195453623","rc":[{"atl":[[180,0],[240,2.79]],"id":39658516}],"con":true,"img":false}]}
{"op":"mcm","clk":"5348415321","pt":1646217461784,"mc":[{"id":"1.195453623","rc":[{"atb":[[5.7,0]],"id":37286329}],"con":true,"img":false}]}
{"op":"mcm","clk":"5348415330","pt":1646217461888,"mc":[{"id":"1.195453623","rc":[{"atb":[[5.6,27.01]],"id":37286329}],"con":true,"img":false}]}
{"op":"mcm","clk":"5348415365","pt":1646217462204,"mc":[{"id":"1.195453623","rc":[{"atb":[[6.4,1.51],[8,0]],"id":37286329}],"con":true,"img":false}]}
{"op":"mcm","clk":"5348415375","pt":1646217462257,"mc":[{"id":"1.195453623","rc":[{"atb":[[1.01,3.37]],"id":37286329}],"con":true,"img":false}]}
{"op":"mcm","clk":"5348415407","pt":1646217462674,"mc":[{"id":"1.195453623","rc":[{"atl":[[230,0]],"id":28222454}],"con":true,"img":false}]}
{"op":"mcm","clk":"5348415415","pt":1646217462780,"mc":[{"id":"1.195453623","rc":[{"atl":[[210,4.72]],"id":28222454}],"con":true,"img":false}]}
{"op":"mcm","clk":"5348415430","pt":1646217462991,"mc":[{"id":"1.195453623","rc":[{"atb":[[1.01,2]],"id":37286329}],"con":true,"img":false}]}
{"op":"mcm","clk":"5348415439","pt":1646217463096,"mc":[{"id":"1.195453623","rc":[{"atl":[[380,1],[390,0]],"id":39658516},{"atb":[[6.4,2.89]],"id":37286329}],"con":true,"img":false}]}
{"op":"mcm","clk":"5348415491","pt":1646217463773,"mc":[{"id":"1.195453623","rc":[{"atl":[[5.6,2.52]],"id":42513983}],"con":true,"img":false}]}
{"op":"mcm","clk":"5348415517","pt":1646217464091,"mc":[{"id":"1.195453623","rc":[{"atl":[[5.6,0]],"id":42513983}],"con":true,"img":false}]}
{"op":"mcm","clk":"5348415763","pt":1646217466573,"mc":[{"id":"1.195453623","rc":[{"atb":[[23,0]],"id":28222454}],"con":true,"img":false}]}
{"op":"mcm","clk":"5348415776","pt":1646217466679,"mc":[{"id":"1.195453623","rc":[{"atb":[[27,4.53]],"id":28222454}],"con":true,"img":false}]}
{"op":"mcm","clk":"5348416053","pt":1646217469573,"mc":[{"id":"1.195453623","rc":[{"atb":[[5.8,1.73]],"id":37286329}],"con":true,"img":false}]}
{"op":"mcm","clk":"5348416075","pt":1646217469784,"mc":[{"id":"1.195453623","rc":[{"atb":[[8.2,0],[1.01,3.66]],"id":37286329}],"con":true,"img":false}]}
{"op":"mcm","clk":"5348416086","pt":1646217469887,"mc":[{"id":"1.195453623","rc":[{"atb":[[1.01,3.01]],"id":37286329}],"con":true,"img":false}]}
{"op":"mcm","clk":"5348416095","pt":1646217469990,"mc":[{"id":"1.195453623","rc":[{"atb":[[1.01,2]],"id":37286329}],"con":true,"img":false}]}
{"op":"mcm","clk":"5348416104","pt":1646217470096,"mc":[{"id":"1.195453623","rc":[{"atb":[[7.4,1.01]],"id":37286329}],"con":true,"img":false}]}
{"op":"mcm","clk":"5348416121","pt":1646217470263,"mc":[{"id":"1.195453623","rc":[{"atb":[[7.4,0],[1.02,3.65]],"id":37286329}],"con":true,"img":false}]}
{"op":"mcm","clk":"5348416131","pt":1646217470362,"mc":[{"id":"1.195453623","rc":[{"atl":[[5.6,2.52]],"id":42513983}],"con":true,"img":false}]}
{"op":"mcm","clk":"5348416139","pt":1646217470469,"mc":[{"id":"1.195453623","rc":[{"atb":[[1.02,3.05]],"id":37286329}],"con":true,"img":false}]}
{"op":"mcm","clk":"5348416149","pt":1646217470572,"mc":[{"id":"1.195453623","rc":[{"atb":[[17,0]],"id":39658516},{"atb":[[1.02,1.99]],"id":37286329}],"con":true,"img":false}]}
{"op":"mcm","clk":"5348416160","pt":1646217470676,"mc":[{"id":"1.195453623","rc":[{"atb":[[18,7.62]],"id":39658516},{"atl":[[5.6,0]],"id":42513983},{"atb":[[7.8,1.06]],"id":37286329}],"con":true,"img":false}]}
{"op":"mcm","clk":"5348416180","pt":1646217470885,"mc":[{"id":"1.195453623","rc":[{"atb":[[1.03,1.66],[27,0]],"id":39658516}],"con":true,"img":false}]}
{"op":"mcm","clk":"5348416203","pt":1646217471096,"mc":[{"id":"1.195453623","rc":[{"atb":[[1.03,0.3]],"id":39658516}],"con":true,"img":false}]}
{"op":"mcm","clk":"5348416218","pt":1646217471252,"mc":[{"id":"1.195453623","rc":[{"atb":[[1.03,0]],"id":39658516}],"con":true,"img":false}]}
{"op":"mcm","clk":"5348416226","pt":1646217471355,"mc":[{"id":"1.195453623","rc":[{"atb":[[18.5,0.88]],"id":39658516}],"con":true,"img":false}]}
{"op":"mcm","clk":"5348416235","pt":1646217471512,"mc":[{"id":"1.195453623","rc":[{"atb":[[8,2.5]],"id":37286329}],"con":true,"img":false}]}
{"op":"mcm","clk":"5348416255","pt":1646217471667,"mc":[{"id":"1.195453623","rc":[{"atb":[[1.01,3.66],[7.8,0]],"id":37286329}],"con":true,"img":false}]}
{"op":"mcm","clk":"5348416275","pt":1646217471876,"mc":[{"id":"1.195453623","rc":[{"atb":[[1.01,3.01]],"id":37286329}],"con":true,"img":false}]}
{"op":"mcm","clk":"5348416294","pt":1646217472086,"mc":[{"id":"1.195453623","rc":[{"atb":[[1.01,2]],"id":37286329}],"con":true,"img":false}]}
{"op":"mcm","clk":"5348416304","pt":1646217472191,"mc":[{"id":"1.195453623","rc":[{"atb":[[8.2,1.01]],"id":37286329}],"con":true,"img":false}]}
{"op":"mcm","clk":"5348416410","pt":1646217473403,"mc":[{"id":"1.195453623","rc":[{"spn":13.11,"spf":1.0,"id":37447009},{"spn":1.87,"spf":1.0,"id":36074465},{"spn":6.65,"spf":"NaN","id":41788482},{"atb":[[17.5,0]],"id":39658516},{"spn":26.0,"spf":1.0,"id":39658516},{"spn":3.33,"spf":1.0,"id":42513983},{"spn":8.07,"spf":1.0,"id":37286329}],"con":true,"img":false}]}
{"op":"mcm","clk":"5348416492","pt":1646217474325,"mc":[{"id":"1.195453623","rc":[{"atb":[[8,0]],"id":37286329}],"con":true,"img":false}]}
{"op":"mcm","clk":"5348416526","pt":1646217474605,"mc":[{"id":"1.195453623","rc":[{"atb":[[18,0]],"id":39658516}],"con":true,"img":false}]}
{"op":"mcm","clk":"5348416536","pt":1646217474710,"mc":[{"id":"1.195453623","rc":[{"atb":[[17,7.62]],"id":39658516}],"con":true,"img":false}]}
{"op":"mcm","clk":"5348416651","pt":1646217475921,"mc":[{"id":"1.195453623","rc":[{"atl":[[5.6,2.52]],"id":42513983}],"con":true,"img":false}]}
{"op":"mcm","clk":"5348416685","pt":1646217476295,"mc":[{"id":"1.195453623","rc":[{"atl":[[5.6,0]],"id":42513983}],"con":true,"img":false}]}
{"op":"mcm","clk":"5348416705","pt":1646217476608,"mc":[{"id":"1.195453623","rc":[{"atb":[[26,2]],"id":39658516}],"con":true,"img":false}]}
{"op":"mcm","clk":"5348416715","pt":1646217476713,"mc":[{"id":"1.195453623","rc":[{"atb":[[27,1.25]],"id":39658516}],"con":true,"img":false}]}
{"op":"mcm","clk":"5348416725","pt":1646217476818,"mc":[{"id":"1.195453623","rc":[{"atb":[[17.5,5.74]],"id":39658516}],"con":true,"img":false}]}
{"op":"mcm","clk":"5348417253","pt":1646217482401,"mc":[{"id":"1.195453623","rc":[{"atl":[[5.6,2.52]],"id":42513983}],"con":true,"img":false}]}
{"op":"mcm","clk":"5348417311","pt":1646217482984,"mc":[{"id":"1.195453623","rc":[{"atb":[[8.2,0],[1.01,3.66]],"id":37286329}],"con":true,"img":false}]}
{"op":"mcm","clk":"5348417332","pt":1646217483195,"mc":[{"id":"1.195453623","rc":[{"atb":[[1.01,3.01]],"id":37286329}],"con":true,"img":false}]}
{"op":"mcm","clk":"5348417354","pt":1646217483405,"mc":[{"id":"1.195453623","rc":[{"atb":[[1.01,2]],"id":37286329}],"con":true,"img":false}]}
{"op":"mcm","clk":"5348417367","pt":1646217483513,"mc":[{"id":"1.195453623","rc":[{"atb":[[7.4,1.01]],"id":37286329}],"con":true,"img":false}]}
{"op":"mcm","clk":"5348417393","pt":1646217483723,"mc":[{"id":"1.195453623","rc":[{"atl":[[5.6,0]],"id":42513983},{"atb":[[7.4,0],[1.02,3.65]],"id":37286329}],"con":true,"img":false}]}
{"op":"mcm","clk":"5348417420","pt":1646217483909,"mc":[{"id":"1.195453623","rc":[{"atb":[[1.02,3.05],[5.8,0]],"id":37286329}],"con":true,"img":false}]}
{"op":"mcm","clk":"5348417442","pt":1646217484120,"mc":[{"id":"1.195453623","rc":[{"atb":[[1.02,1.99]],"id":37286329}],"con":true,"img":false}]}
{"op":"mcm","clk":"5348417453","pt":1646217484174,"mc":[{"id":"1.195453623","rc":[{"atb":[[7.8,1.06]],"id":37286329}],"con":true,"img":false}]}
{"op":"mcm","clk":"5348417541","pt":1646217485120,"mc":[{"id":"1.195453623","rc":[{"atb":[[8,2.5]],"id":37286329}],"con":true,"img":false}]}
{"op":"mcm","clk":"5348417585","pt":1646217485592,"mc":[{"id":"1.195453623","rc":[{"atb":[[1.01,3.66],[7.8,0]],"id":37286329}],"con":true,"img":false}]}
{"op":"mcm","clk":"5348417596","pt":1646217485703,"mc":[{"id":"1.195453623","rc":[{"atb":[[1.01,3.01]],"id":37286329}],"con":true,"img":false}]}
{"op":"mcm","clk":"5348417618","pt":1646217485913,"mc":[{"id":"1.195453623","rc":[{"atb":[[1.01,2]],"id":37286329}],"con":true,"img":false}]}
{"op":"mcm","clk":"5348417630","pt":1646217486015,"mc":[{"id":"1.195453623","rc":[{"atb":[[8.2,1.01]],"id":37286329}],"con":true,"img":false}]}
{"op":"mcm","clk":"5348417698","pt":1646217486695,"mc":[{"id":"1.195453623","rc":[{"atl":[[2.3,24.82]],"id":36074465}],"con":true,"img":false}]}
{"op":"mcm","clk":"5348417708","pt":1646217486799,"mc":[{"id":"1.195453623","rc":[{"atl":[[2.28,6.48]],"id":36074465}],"con":true,"img":false}]}
{"op":"mcm","clk":"5348417783","pt":1646217487593,"mc":[{"id":"1.195453623","rc":[{"atl":[[5.6,2.52]],"id":42513983}],"con":true,"img":false}]}
{"op":"mcm","clk":"5348417810","pt":1646217487902,"mc":[{"id":"1.195453623","rc":[{"atl":[[5.6,0]],"id":42513983}],"con":true,"img":false}]}
{"op":"mcm","clk":"5348417843","pt":1646217488216,"mc":[{"id":"1.195453623","rc":[{"atb":[[8,0]],"id":37286329}],"con":true,"img":false}]}
{"op":"mcm","clk":"5348418186","pt":1646217491887,"mc":[{"id":"1.195453623","rc":[{"atl":[[2.28,3.76]],"id":36074465}],"con":true,"img":false}]}
{"op":"mcm","clk":"5348418197","pt":1646217491991,"mc":[{"id":"1.195453623","rc":[{"atl":[[2.2,2.72]],"id":36074465}],"con":true,"img":false}]}
{"op":"mcm","clk":"5348418232","pt":1646217492304,"mc":[{"id":"1.195453623","rc":[{"atl":[[2.28,0]],"id":36074465}],"con":true,"img":false}]}
{"op":"mcm","clk":"5348418289","pt":1646217492831,"mc":[{"id":"1.195453623","rc":[{"atl":[[5.6,2.52]],"id":42513983}],"con":true,"img":false}]}
{"op":"mcm","clk":"5348418308","pt":1646217492991,"mc":[{"id":"1.195453623","rc":[{"atb":[[8.2,0],[1.01,3.66]],"id":37286329}],"con":true,"img":false}]}
{"op":"mcm","clk":"5348418325","pt":1646217493205,"mc":[{"id":"1.195453623","rc":[{"atl":[[5.6,0]],"id":42513983},{"atb":[[1.01,3.01]],"id":37286329}],"con":true,"img":false}]}
{"op":"mcm","clk":"5348418347","pt":1646217493410,"mc":[{"id":"1.195453623","rc":[{"atb":[[1.01,2]],"id":37286329}],"con":true,"img":false}]}
{"op":"mcm","clk":"5348418357","pt":1646217493514,"mc":[{"id":"1.195453623","rc":[{"atb":[[7.4,1.01]],"id":37286329}],"con":true,"img":false}]}
{"op":"mcm","clk":"5348418375","pt":1646217493724,"mc":[{"id":"1.195453623","rc":[{"atb":[[7.4,0],[1.01,3.66]],"id":37286329}],"con":true,"img":false}]}
{"op":"mcm","clk":"5348418394","pt":1646217493935,"mc":[{"id":"1.195453623","rc":[{"atb":[[1.01,2.99]],"id":37286329}],"con":true,"img":false}]}
{"op":"mcm","clk":"5348418403","pt":1646217493993,"mc":[{"id":"1.195453623","rc":[{"atb":[[1.01,2]],"id":37286329}],"con":true,"img":false}]}
{"op":"mcm","clk":"5348418415","pt":1646217494145,"mc":[{"id":"1.195453623","rc":[{"atb":[[8.4,0.99]],"id":37286329}],"con":true,"img":false}]}
{"op":"mcm","clk":"5348418526","pt":1646217495414,"mc":[{"id":"1.195453623","rc":[{"atb":[[1.91,0]],"id":36074465}],"con":true,"img":false}]}
{"op":"mcm","clk":"5348418811","pt":1646217498339,"mc":[{"id":"1.195453623","rc":[{"atl":[[5.6,2.52]],"id":42513983}],"con":true,"img":false}]}
{"op":"mcm","clk":"5348418838","pt":1646217498608,"mc":[{"id":"1.195453623","rc":[{"atl":[[5.6,0]],"id":42513983}],"con":true,"img":false}]}
{"op":"mcm","clk":"5348419454","pt":1646217504636,"mc":[{"id":"1.195453623","rc":[{"atl":[[5.6,2.52]],"id":42513983}],"con":true,"img":false}]}
{"op":"mcm","clk":"5348419472","pt":1646217504844,"mc":[{"id":"1.195453623","rc":[{"atb":[[1.01,3.66],[8.4,0]],"id":37286329}],"con":true,"img":false}]}
{"op":"mcm","clk":"5348419482","pt":1646217504948,"mc":[{"id":"1.195453623","rc":[{"atl":[[5.6,0]],"id":42513983}],"con":true,"img":false}]}
{"op":"mcm","clk":"5348419497","pt":1646217505056,"mc":[{"id":"1.195453623","rc":[{"atb":[[1.01,2.99]],"id":37286329}],"con":true,"img":false}]}
{"op":"mcm","clk":"5348419513","pt":1646217505215,"mc":[{"id":"1.195453623","rc":[{"atb":[[1.01,2]],"id":37286329}],"con":true,"img":false}]}
{"op":"mcm","clk":"5348419523","pt":1646217505317,"mc":[{"id":"1.195453623","rc":[{"atb":[[7.4,0.99]],"id":37286329}],"con":true,"img":false}]}
{"op":"mcm","clk":"5348419544","pt":1646217505528,"mc":[{"id":"1.195453623","rc":[{"atb":[[7.4,0],[1.01,3.66]],"id":37286329}],"con":true,"img":false}]}
{"op":"mcm","clk":"5348419564","pt":1646217505737,"mc":[{"id":"1.195453623","rc":[{"atb":[[1.01,2.99]],"id":37286329}],"con":true,"img":false}]}
{"op":"mcm","clk":"5348419573","pt":1646217505840,"mc":[{"id":"1.195453623","rc":[{"atb":[[1.01,2]],"id":37286329}],"con":true,"img":false}]}
{"op":"mcm","clk":"5348419585","pt":1646217505942,"mc":[{"id":"1.195453623","rc":[{"atb":[[8.4,0.99]],"id":37286329}],"con":true,"img":false}]}
{"op":"mcm","clk":"5348419668","pt":1646217506628,"mc":[{"id":"1.195453623","rc":[{"atb":[[1.03,2.25],[13,2.2]],"id":37447009}],"con":true,"img":false}]}
{"op":"mcm","clk":"5348419680","pt":1646217506735,"mc":[{"id":"1.195453623","rc":[{"atb":[[1.03,0.27]],"id":37447009}],"con":true,"img":false}]}
{"op":"mcm","clk":"5348419698","pt":1646217506943,"mc":[{"id":"1.195453623","rc":[{"atb":[[1.03,0]],"id":37447009}],"con":true,"img":false}]}
{"op":"mcm","clk":"5348419710","pt":1646217507048,"mc":[{"id":"1.195453623","rc":[{"atb":[[14,0.27]],"id":37447009}],"con":true,"img":false}]}
{"op":"mcm","clk":"5348419853","pt":1646217508361,"mc":[{"id":"1.195453623","rc":[{"atb":[[13,0.12]],"id":37447009}],"con":true,"img":false}]}
{"op":"mcm","clk":"5348420068","pt":1646217510250,"mc":[{"id":"1.195453623","rc":[{"atb":[[14,2.35]],"id":37447009}],"con":true,"img":false}]}
{"op":"mcm","clk":"5348420083","pt":1646217510462,"mc":[{"id":"1.195453623","rc":[{"atb":[[1.03,1.66],[13.5,0]],"id":37447009}],"con":true,"img":false}]}
{"op":"mcm","clk":"5348420105","pt":1646217510618,"mc":[{"id":"1.195453623","rc":[{"atb":[[1.03,0.57]],"id":37447009}],"con":true,"img":false}]}
{"op":"mcm","clk":"5348420117","pt":1646217510722,"mc":[{"id":"1.195453623","rc":[{"atl":[[5.6,2.52]],"id":42513983}],"con":true,"img":false}]}
{"op":"mcm","clk":"5348420130","pt":1646217510879,"mc":[{"id":"1.195453623","rc":[{"atb":[[1.03,0]],"id":37447009}],"con":true,"img":false}]}
{"op":"mcm","clk":"5348420144","pt":1646217510929,"mc":[{"id":"1.195453623","rc":[{"atb":[[14.5,0.57]],"id":37447009}],"con":true,"img":false}]}
{"op":"mcm","clk":"5348420165","pt":1646217511143,"mc":[{"id":"1.195453623","rc":[{"atl":[[5.6,0]],"id":42513983}],"con":true,"img":false}]}
{"op":"mcm","clk":"5348420797","pt":1646217517469,"mc":[{"id":"1.195453623","rc":[{"atl":[[5.6,2.52]],"id":42513983}],"con":true,"img":false}]}
{"op":"mcm","clk":"5348420818","pt":1646217517623,"mc":[{"id":"1.195453623","rc":[{"atb":[[1.01,3.66],[8.4,0]],"id":37286329}],"con":true,"img":false}]}
{"op":"mcm","clk":"5348420829","pt":1646217517727,"mc":[{"id":"1.195453623","rc":[{"atl":[[5.6,0]],"id":42513983}],"con":true,"img":false}]}
{"op":"mcm","clk":"5348420839","pt":1646217517832,"mc":[{"id":"1.195453623","rc":[{"atb":[[1.01,2.99]],"id":37286329}],"con":true,"img":false}]}
{"op":"mcm","clk":"5348420862","pt":1646217518040,"mc":[{"id":"1.195453623","rc":[{"atb":[[1.01,2]],"id":37286329}],"con":true,"img":false}]}
{"op":"mcm","clk":"5348420870","pt":1646217518145,"mc":[{"id":"1.195453623","rc":[{"atb":[[7.4,0.99]],"id":37286329}],"con":true,"img":false}]}
{"op":"mcm","clk":"5348420887","pt":1646217518354,"mc":[{"id":"1.195453623","rc":[{"atb":[[7.4,0],[1.01,3.66]],"id":37286329}],"con":true,"img":false}]}
{"op":"mcm","clk":"5348420896","pt":1646217518461,"mc":[{"id":"1.195453623","rc":[{"atb":[[1.03,1.66]],"id":39658516}],"con":true,"img":false}]}
{"op":"mcm","clk":"5348420907","pt":1646217518563,"mc":[{"id":"1.195453623","rc":[{"atb":[[18.5,0.58]],"id":39658516},{"atb":[[1.01,2.99]],"id":37286329}],"con":true,"img":false}]}
{"op":"mcm","clk":"5348420919","pt":1646217518679,"mc":[{"id":"1.195453623","rc":[{"atb":[[1.03,0.3],[17,0]],"id":39658516}],"con":true,"img":false}]}
{"op":"mcm","clk":"5348420931","pt":1646217518726,"mc":[{"id":"1.195453623","rc":[{"atb":[[18,7.62]],"id":39658516},{"atb":[[1.01,2]],"id":37286329}],"con":true,"img":false}]}
{"op":"mcm","clk":"5348420946","pt":1646217518880,"mc":[{"id":"1.195453623","rc":[{"atb":[[8.4,0.99]],"id":37286329}],"con":true,"img":false}]}
{"op":"mcm","clk":"5348420962","pt":1646217519037,"mc":[{"id":"1.195453623","rc":[{"atb":[[1.03,0]],"id":39658516}],"con":true,"img":false}]}
{"op":"mcm","clk":"5348420972","pt":1646217519140,"mc":[{"id":"1.195453623","rc":[{"atb":[[28,0.3]],"id":39658516}],"con":true,"img":false}]}
{"op":"mcm","clk":"5348421161","pt":1646217520950,"mc":[{"id":"1.195453623","rc":[{"atb":[[3.7,2]],"id":37447009},{"atl":[[140,14.2],[150,1]],"id":37447009},{"atb":[[1.78,25.64],[1.75,99.28]],"id":36074465},{"atl":[[3.1,0],[3.05,0],[3.2,0],[3.15,0]],"id":36074465},{"atb":[[4,17.71],[3.9,45.51]],"id":41788482},{"atl":[[13,5.67]],"id":41788482},{"atb":[[17.5,0]],"id":39658516},{"atb":[[3.35,0],[3.25,0],[3.2,0],[3.3,31.3]],"id":37286329},{"atl":[[16.5,1.29],[17.5,0]],"id":37286329}],"con":true,"img":false}]}
{"op":"mcm","clk":"5348421183","pt":1646217521160,"mc":[{"id":"1.195453623","rc":[{"atl":[[3.2,2]],"id":36074465},{"atb":[[3.2,2]],"id":37286329}],"con":true,"img":false}]}
