{"op":"mcm","clk":"5317728452","pt":1646251399792,"mc":[{"id":"1.195532859","marketDefinition":{"bspMarket":true,"turnInPlayEnabled":false,"persistenceEnabled":false,"marketBaseRate":5.0,"eventId":"31275720","eventTypeId":"4339","numberOfWinners":2,"bettingType":"ODDS","marketType":"PLACE","marketTime":"2022-03-03T14:52:00.000Z","suspendTime":"2022-03-03T14:52:00.000Z","bspReconciled":false,"complete":true,"inPlay":false,"crossMatching":false,"runnersVoidable":false,"numberOfActiveRunners":6,"betDelay":0,"status":"OPEN","runners":[{"status":"ACTIVE","sortPriority":1,"id":41288595,"name":"1. Corten Steel"},{"status":"ACTIVE","sortPriority":2,"id":38324360,"name":"2. Slippy Bull"},{"status":"ACTIVE","sortPriority":3,"id":39290878,"name":"3. Crohane Ollie"},{"status":"ACTIVE","sortPriority":4,"id":38357910,"name":"4. Kincora Beauty"},{"status":"ACTIVE","sortPriority":5,"id":40124755,"name":"5. Right Joe"},{"status":"ACTIVE","sortPriority":6,"id":38983972,"name":"6. Roll On Bucko"}],"regulators":["MR_INT"],"venue":"Romford","countryCode":"GB","discountAllowed":false,"timezone":"Europe/London","openDate":"2022-03-03T13:57:00.000Z","version":4384107294,"name":"To Be Placed","eventName":"Romford 3rd Mar"},"rc":[],"con":true,"img":false}]}
{"op":"mcm","clk":"5317728849","pt":1646251401757,"mc":[{"id":"1.195532859","marketDefinition":{"bspMarket":true,"turnInPlayEnabled":false,"persistenceEnabled":false,"marketBaseRate":5.0,"eventId":"31275720","eventTypeId":"4339","numberOfWinners":2,"bettingType":"ODDS","marketType":"PLACE","marketTime":"2022-03-03T14:52:00.000Z","suspendTime":"2022-03-03T14:52:00.000Z","bspReconciled":false,"complete":true,"inPlay":false,"crossMatching":false,"runnersVoidable":false,"numberOfActiveRunners":6,"betDelay":0,"status":"OPEN","runners":[{"status":"ACTIVE","sortPriority":1,"id":41288595,"name":"1. Corten Steel"},{"status":"ACTIVE","sortPriority":2,"id":38324360,"name":"2. Slippy Bull"},{"status":"ACTIVE","sortPriority":3,"id":39290878,"name":"3. Crohane Ollie"},{"status":"ACTIVE","sortPriority":4,"id":38357910,"name":"4. Kincora Beauty"},{"status":"ACTIVE","sortPriority":5,"id":40124755,"name":"5. Right Joe"},{"status":"ACTIVE","sortPriority":6,"id":38983972,"name":"6. Roll On Bucko"}],"regulators":["MR_INT"],"venue":"Romford","countryCode":"GB","discountAllowed":true,"timezone":"Europe/London","openDate":"2022-03-03T13:57:00.000Z","version":4384107294,"name":"To Be Placed","eventName":"Romford 3rd Mar"},"rc":[],"con":true,"img":false}]}
{"op":"mcm","clk":"5320990907","pt":1646304809140,"mc":[{"id":"1.195532859","rc":[{"atb":[[1.01,102.04]],"id":41288595},{"spn":"Infinity","spf":"NaN","id":41288595},{"atb":[[1.01,102.04]],"id":38324360},{"spn":"Infinity","spf":"NaN","id":38324360}],"con":true,"img":false}]}
{"op":"mcm","clk":"5320990912","pt":1646304809244,"mc":[{"id":"1.195532859","rc":[{"atb":[[1.01,102.04]],"id":38983972},{"atb":[[1.01,102.04]],"id":39290878},{"atb":[[1.01,102.04]],"id":38357910},{"atb":[[1.01,102.04]],"id":40124755}],"con":true,"img":false}]}
{"op":"mcm","clk":"5321039318","pt":1646305449087,"mc":[{"id":"1.195532859","marketDefinition":{"bspMarket":true,"turnInPlayEnabled":false,"persistenceEnabled":false,"marketBaseRate":5.0,"eventId":"31275720","eventTypeId":"4339","numberOfWinners":2,"bettingType":"ODDS","marketType":"PLACE","marketTime":"2022-03-03T14:52:00.000Z","suspendTime":"2022-03-03T14:52:00.000Z","bspReconciled":false,"complete":true,"inPlay":false,"crossMatching":false,"runnersVoidable":false,"numberOfActiveRunners":6,"betDelay":0,"status":"OPEN","runners":[{"status":"ACTIVE","sortPriority":1,"id":41288595,"name":"1. Corten Steel"},{"status":"ACTIVE","sortPriority":2,"id":38324360,"name":"2. Slippy Bull"},{"status":"ACTIVE","sortPriority":3,"id":39290878,"name":"3. Crohane Ollie"},{"status":"ACTIVE","sortPriority":4,"id":38357910,"name":"4. Kincora Beauty"},{"status":"ACTIVE","sortPriority":5,"id":40124755,"name":"5. Right Joe"},{"status":"ACTIVE","sortPriority":6,"id":38983972,"name":"6. Roll On Bucko"}],"regulators":["MR_INT"],"venue":"Romford","countryCode":"GB","discountAllowed":true,"timezone":"Europe/London","openDate":"2022-03-03T13:57:00.000Z","version":4384107294,"name":"To Be Placed","eventName":"Romford 3rd Mar"},"rc":[{"atb":[[1.01,102.04]],"id":41288595},{"spn":"Infinity","spf":"NaN","id":41288595},{"atb":[[1.01,102.04]],"id":38983972},{"spn":"Infinity","spf":"NaN","id":38983972},{"atb":[[1.01,102.04]],"id":38324360},{"spn":"Infinity","spf":"NaN","id":38324360},{"atb":[[1.01,102.04]],"id":39290878},{"spn":"Infinity","spf":"NaN","id":39290878},{"atb":[[1.01,102.04]],"id":38357910},{"spn":"Infinity","spf":"NaN","id":38357910},{"atb":[[1.01,102.04]],"id":40124755},{"spn":"Infinity","spf":"NaN","id":40124755}],"con":true,"img":true}]}
{"op":"mcm","clk":"5321220326","pt":1646307329950,"mc":[{"id":"1.195532859","rc":[{"atl":[[1000,5]],"id":41288595},{"spn":500.5,"spf":"NaN","id":41288595},{"atl":[[1000,5]],"id":38983972},{"spn":500.5,"spf":"NaN","id":38983972},{"atl":[[1000,5]],"id":38324360},{"spn":500.5,"spf":"NaN","id":38324360},{"atl":[[1000,5]],"id":39290878},{"spn":500.5,"spf":"NaN","id":39290878},{"atl":[[1000,5]],"id":38357910},{"spn":500.5,"spf":"NaN","id":38357910},{"atl":[[1000,5]],"id":40124755},{"spn":500.5,"spf":"NaN","id":40124755}],"con":true,"img":false}]}
{"op":"mcm","clk":"5321220373","pt":1646307330468,"mc":[{"id":"1.195532859","rc":[{"atb":[[1.01,4802.04]],"id":41288595},{"atb":[[1.01,4802.04]],"id":38983972},{"atb":[[1.01,4802.04]],"id":38324360},{"atb":[[1.01,4802.04]],"id":39290878},{"atb":[[1.01,4802.04]],"id":38357910},{"atb":[[1.01,4802.04]],"id":40124755}],"con":true,"img":false}]}
{"op":"mcm","clk":"5321417708","pt":1646309469904,"mc":[{"id":"1.195532859","rc":[{"spl":[[1.01,8.18]],"id":41288595},{"spn":1.01,"spf":1.0,"id":41288595}],"con":true,"img":false}]}
{"op":"mcm","clk":"5321809187","pt":1646313402551,"mc":[{"id":"1.195532859","marketDefinition":{"bspMarket":true,"turnInPlayEnabled":false,"persistenceEnabled":false,"marketBaseRate":5.0,"eventId":"31275720","eventTypeId":"4339","numberOfWinners":2,"bettingType":"ODDS","marketType":"PLACE","marketTime":"2022-03-03T14:52:00.000Z","suspendTime":"2022-03-03T14:52:00.000Z","bspReconciled":false,"complete":true,"inPlay":false,"crossMatching":false,"runnersVoidable":false,"numberOfActiveRunners":6,"betDelay":0,"status":"OPEN","runners":[{"status":"ACTIVE","sortPriority":1,"id":41288595,"name":"1. Corten Steel"},{"status":"ACTIVE","sortPriority":2,"id":38324360,"name":"2. Slippy Bull"},{"status":"ACTIVE","sortPriority":3,"id":39290878,"name":"3. Crohane Ollie"},{"status":"ACTIVE","sortPriority":4,"id":38357910,"name":"4. Kincora Beauty"},{"status":"ACTIVE","sortPriority":5,"id":40124755,"name":"5. Right Joe"},{"status":"ACTIVE","sortPriority":6,"id":38983972,"name":"6. Roll On Bucko"}],"regulators":["MR_INT"],"venue":"Romford","countryCode":"GB","discountAllowed":true,"timezone":"Europe/London","openDate":"2022-03-03T13:57:00.000Z","version":4384107294,"name":"To Be Placed","eventName":"Romford 3rd Mar"},"rc":[{"atb":[[1.01,4802.04]],"id":41288595},{"spl":[[1.01,8.19]],"id":41288595},{"atl":[[1000,5]],"id":41288595},{"spn":1.01,"spf":1.0,"id":41288595},{"atb":[[1.01,4802.04]],"id":38983972},{"atl":[[1000,5]],"id":38983972},{"spn":500.5,"spf":"NaN","id":38983972},{"atb":[[1.01,4802.04]],"id":38324360},{"atl":[[1000,5]],"id":38324360},{"spn":500.5,"spf":"NaN","id":38324360},{"atb":[[1.01,4802.04]],"id":39290878},{"atl":[[1000,5]],"id":39290878},{"spn":500.5,"spf":"NaN","id":39290878},{"atb":[[1.01,4802.04]],"id":38357910},{"atl":[[1000,5]],"id":38357910},{"spn":500.5,"spf":"NaN","id":38357910},{"atb":[[1.01,4802.04]],"id":40124755},{"atl":[[1000,5]],"id":40124755},{"spn":500.5,"spf":"NaN","id":40124755}],"con":true,"img":true}]}
{"op":"mcm","clk":"5321892145","pt":1646314227371,"mc":[{"id":"1.195532859","rc":[{"spl":[[1.01,9.19]],"id":41288595},{"spl":[[1.01,1]],"id":39290878},{"spn":1.01,"spf":1.0,"id":39290878}],"con":true,"img":false}]}
{"op":"mcm","clk":"5322183127","pt":1646317322084,"mc":[{"id":"1.195532859","rc":[{"atb":[[1.01,5052.04]],"id":41288595},{"atb":[[1.01,5052.04]],"id":38983972},{"atb":[[1.01,5052.04]],"id":38324360},{"atb":[[1.01,5052.04]],"id":39290878},{"atb":[[1.01,5052.04]],"id":38357910},{"atb":[[1.01,5052.04]],"id":40124755}],"con":true,"img":false}]}
{"op":"mcm","clk":"5322205013","pt":1646317559008,"mc":[{"id":"1.195532859","rc":[{"atl":[[46,2.73]],"id":41288595},{"atl":[[46,2.73]],"id":38983972},{"spn":23.5,"spf":"NaN","id":38983972},{"atl":[[46,2.73]],"id":38324360},{"spn":23.5,"spf":"NaN","id":38324360},{"atl":[[46,2.73]],"id":39290878},{"atl":[[46,2.73]],"id":38357910},{"spn":23.5,"spf":"NaN","id":38357910},{"atl":[[46,2.73]],"id":40124755},{"spn":23.5,"spf":"NaN","id":40124755}],"con":true,"img":false}]}
{"op":"mcm","clk":"5322205080","pt":1646317559666,"mc":[{"id":"1.195532859","marketDefinition":{"bspMarket":true,"turnInPlayEnabled":false,"persistenceEnabled":false,"marketBaseRate":5.0,"eventId":"31275720","eventTypeId":"4339","numberOfWinners":2,"bettingType":"ODDS","marketType":"PLACE","marketTime":"2022-03-03T14:52:00.000Z","suspendTime":"2022-03-03T14:52:00.000Z","bspReconciled":false,"complete":true,"inPlay":false,"crossMatching":true,"runnersVoidable":false,"numberOfActiveRunners":6,"betDelay":0,"status":"OPEN","runners":[{"status":"ACTIVE","sortPriority":1,"id":41288595,"name":"1. Corten Steel"},{"status":"ACTIVE","sortPriority":2,"id":38324360,"name":"2. Slippy Bull"},{"status":"ACTIVE","sortPriority":3,"id":39290878,"name":"3. Crohane Ollie"},{"status":"ACTIVE","sortPriority":4,"id":38357910,"name":"4. Kincora Beauty"},{"status":"ACTIVE","sortPriority":5,"id":40124755,"name":"5. Right Joe"},{"status":"ACTIVE","sortPriority":6,"id":38983972,"name":"6. Roll On Bucko"}],"regulators":["MR_INT"],"venue":"Romford","countryCode":"GB","discountAllowed":true,"timezone":"Europe/London","openDate":"2022-03-03T13:57:00.000Z","version":4384107294,"name":"To Be Placed","eventName":"Romford 3rd Mar"},"rc":[],"con":true,"img":false}]}
{"op":"mcm","clk":"5322218846","pt":1646317701354,"mc":[{"id":"1.195532859","rc":[{"atl":[[70,2.17],[80,3.16],[50,1],[60,1.69]],"id":41288595},{"atl":[[70,2.17],[80,3.16],[50,1],[60,1.69]],"id":38983972},{"atl":[[70,2.17],[80,3.16],[50,1],[60,1.69]],"id":38324360},{"atl":[[70,2.17],[80,3.16],[50,1],[60,1.69]],"id":39290878},{"atl":[[70,2.17],[80,3.16],[50,1],[60,1.69]],"id":38357910},{"atl":[[70,2.17],[80,3.16],[50,1],[60,1.69]],"id":40124755}],"con":true,"img":false}]}
{"op":"mcm","clk":"5322254757","pt":1646318126576,"mc":[{"id":"1.195532859","rc":[{"atl":[[3.45,14],[3.1,6],[3.7,21],[3,4],[3.25,9]],"id":39290878}],"con":true,"img":false}]}
{"op":"mcm","clk":"5322254773","pt":1646318126732,"mc":[{"id":"1.195532859","rc":[{"atl":[[3.1,25.05],[50,0]],"id":39290878}],"con":true,"img":false}]}
{"op":"mcm","clk":"5322255477","pt":1646318135269,"mc":[{"id":"1.195532859","rc":[{"atb":[[5.1,4],[3.85,21],[4.6,9],[4.9,6],[4.2,14]],"id":38324360}],"con":true,"img":false}]}
{"op":"mcm","clk":"5322255503","pt":1646318135534,"mc":[{"id":"1.195532859","rc":[{"atb":[[3.95,13.56]],"id":38324360}],"con":true,"img":false}]}
{"op":"mcm","clk":"5322255610","pt":1646318136737,"mc":[{"id":"1.195532859","rc":[{"atl":[[3.2,45.45]],"id":39290878}],"con":true,"img":false}]}
{"op":"mcm","clk":"5322255866","pt":1646318140082,"mc":[{"id":"1.195532859","rc":[{"atb":[[5.2,1.65]],"id":38324360}],"con":true,"img":false}]}
{"op":"mcm","clk":"5322256010","pt":1646318141769,"mc":[{"id":"1.195532859","rc":[{"atl":[[80,0]],"id":39290878}],"con":true,"img":false}]}
{"op":"mcm","clk":"5322256309","pt":1646318145550,"mc":[{"id":"1.195532859","rc":[{"atb":[[3.85,56.09]],"id":38324360}],"con":true,"img":false}]}
{"op":"mcm","clk":"5322256394","pt":1646318146759,"mc":[{"id":"1.195532859","rc":[{"atl":[[3.3,65.22]],"id":39290878}],"con":true,"img":false}]}
{"op":"mcm","clk":"5322256990","pt":1646318153772,"mc":[{"id":"1.195532859","rc":[{"atl":[[70,0]],"id":39290878}],"con":true,"img":false}]}
{"op":"mcm","clk":"5322257131","pt":1646318155610,"mc":[{"id":"1.195532859","rc":[{"atb":[[3.75,54.55]],"id":38324360}],"con":true,"img":false}]}
{"op":"mcm","clk":"5322257227","pt":1646318156808,"mc":[{"id":"1.195532859","rc":[{"atl":[[3.4,104.17]],"id":39290878}],"con":true,"img":false}]}
{"op":"mcm","clk":"5322257257","pt":1646318157178,"mc":[{"id":"1.195532859","rc":[{"atl":[[60,0]],"id":39290878}],"con":true,"img":false}]}
{"op":"mcm","clk":"5322258013","pt":1646318165569,"mc":[{"id":"1.195532859","rc":[{"atb":[[3.65,94.34]],"id":38324360}],"con":true,"img":false}]}
{"op":"mcm","clk":"5322258231","pt":1646318168095,"mc":[{"id":"1.195532859","rc":[{"atb":[[1.01,4802.04]],"id":38324360}],"con":true,"img":false}]}
{"op":"mcm","clk":"5322262770","pt":1646318223817,"mc":[{"id":"1.195532859","rc":[{"atb":[[1.9,111.11]],"id":41288595},{"atl":[[13.5,2]],"id":41288595},{"spn":1.9,"spf":1.0,"id":41288595},{"atb":[[1.71,140.85]],"id":38983972},{"atl":[[9.4,2]],"id":38983972},{"spn":5.55,"spf":"NaN","id":38983972},{"atb":[[4.8,13.56]],"id":38324360},{"atl":[[46,4.73]],"id":38324360},{"spn":25.6,"spf":"NaN","id":38324360},{"atb":[[1.27,370.37]],"id":39290878},{"atl":[[3.2,90.9]],"id":39290878},{"spn":1.27,"spf":1.0,"id":39290878},{"atb":[[1.42,238.1]],"id":38357910},{"atl":[[6,2]],"id":38357910},{"spn":3.71,"spf":"NaN","id":38357910},{"atb":[[1.64,156.25]],"id":40124755},{"atl":[[8.4,2]],"id":40124755},{"spn":5.02,"spf":"NaN","id":40124755}],"con":true,"img":false}]}
{"op":"mcm","clk":"5322263039","pt":1646318226920,"mc":[{"id":"1.195532859","rc":[{"atl":[[17.5,14],[20,21],[13,4],[14,6],[15.5,9]],"id":38324360}],"con":true,"img":false}]}
{"op":"mcm","clk":"5322263059","pt":1646318227099,"mc":[{"id":"1.195532859","rc":[{"atb":[[1.88,45.45]],"id":41288595},{"atl":[[50,0],[14.5,2.96]],"id":41288595},{"atb":[[1.69,57.97]],"id":38983972},{"atl":[[50,0],[9.8,4.55]],"id":38983972},{"atl":[[50,0],[14,9.08]],"id":38324360},{"atb":[[1.25,160]],"id":39290878},{"atb":[[1.4,100]],"id":38357910},{"atl":[[6.4,7.41],[50,0]],"id":38357910},{"atb":[[1.62,64.52]],"id":40124755},{"atl":[[50,0],[8.8,5.13]],"id":40124755}],"con":true,"img":false}]}
{"op":"mcm","clk":"5322263198","pt":1646318229017,"mc":[{"id":"1.195532859","rc":[{"atb":[[1.89,112.36],[1.9,0]],"id":41288595}],"con":true,"img":false}]}
{"op":"mcm","clk":"5322263577","pt":1646318233891,"mc":[{"id":"1.195532859","rc":[{"atb":[[1.88,0],[1.87,45.98]],"id":41288595},{"atb":[[4.8,0],[4.7,13.56]],"id":38324360},{"atl":[[15.5,15.9]],"id":38324360}],"con":true,"img":false}]}
{"op":"mcm","clk":"5322263586","pt":1646318234008,"mc":[{"id":"1.195532859","rc":[{"atl":[[46,2.73]],"id":38324360}],"con":true,"img":false}]}
{"op":"mcm","clk":"5322263856","pt":1646318237091,"mc":[{"id":"1.195532859","rc":[{"atb":[[1.67,149.25]],"id":38983972},{"atl":[[10.5,10.53]],"id":38983972},{"atl":[[15,7.14]],"id":38324360},{"atb":[[1.23,250]],"id":39290878},{"atb":[[1.38,250]],"id":38357910},{"atl":[[6.8,17.24]],"id":38357910},{"atb":[[1.6,166.67]],"id":40124755},{"atl":[[9.2,12.2]],"id":40124755}],"con":true,"img":false}]}
{"op":"mcm","clk":"5322263952","pt":1646318238129,"mc":[{"id":"1.195532859","rc":[{"atb":[[1.74,2.15]],"id":38983972},{"atb":[[1.45,2.15]],"id":38357910},{"atb":[[1.67,2.15]],"id":40124755}],"con":true,"img":false}]}
{"op":"mcm","clk":"5322263962","pt":1646318238235,"mc":[{"id":"1.195532859","rc":[{"atb":[[1.45,102.15]],"id":38357910}],"con":true,"img":false}]}
{"op":"mcm","clk":"5322263974","pt":1646318238287,"mc":[{"id":"1.195532859","rc":[{"atb":[[1.74,60.12],[1.71,0]],"id":38983972},{"atb":[[1.42,0]],"id":38357910},{"atb":[[1.64,0],[1.67,66.67]],"id":40124755}],"con":true,"img":false}]}
{"op":"mcm","clk":"5322264059","pt":1646318239135,"mc":[{"id":"1.195532859","rc":[{"atb":[[1.89,0],[1.9,111.11]],"id":41288595}],"con":true,"img":false}]}
{"op":"mcm","clk":"5322264110","pt":1646318239709,"mc":[{"id":"1.195532859","rc":[{"atb":[[1.88,45.45]],"id":41288595},{"atb":[[1.72,55.56]],"id":38983972},{"atl":[[70,0],[80,0],[60,0]],"id":38983972},{"atb":[[1.65,61.54]],"id":40124755},{"atl":[[80,0]],"id":40124755}],"con":true,"img":false}]}
{"op":"mcm","clk":"5322264119","pt":1646318239819,"mc":[{"id":"1.195532859","rc":[{"atl":[[80,0]],"id":38324360},{"atb":[[1.43,93.02]],"id":38357910},{"atl":[[80,0]],"id":38357910}],"con":true,"img":false}]}
{"op":"mcm","clk":"5322264147","pt":1646318240124,"mc":[{"id":"1.195532859","rc":[{"atb":[[1.93,2.15]],"id":41288595}],"con":true,"img":false}]}
{"op":"mcm","clk":"5322264167","pt":1646318240326,"mc":[{"id":"1.195532859","rc":[{"atb":[[1.93,47.6]],"id":41288595}],"con":true,"img":false}]}
{"op":"mcm","clk":"5322264174","pt":1646318240435,"mc":[{"id":"1.195532859","rc":[{"atb":[[1.9,0]],"id":41288595}],"con":true,"img":false}]}
{"op":"mcm","clk":"5322264390","pt":1646318242741,"mc":[{"id":"1.195532859","rc":[{"atb":[[1.91,43.96]],"id":41288595}],"con":true,"img":false}]}
{"op":"mcm","clk":"5322264800","pt":1646318247131,"mc":[{"id":"1.195532859","rc":[{"atl":[[16,10]],"id":38324360},{"atb":[[1.21,250]],"id":39290878}],"con":true,"img":false}]}
{"op":"mcm","clk":"5322265027","pt":1646318249847,"mc":[{"id":"1.195532859","rc":[{"atl":[[11.5,14.29]],"id":38983972},{"atl":[[7.2,24.19]],"id":38357910},{"atl":[[9.6,17.44]],"id":40124755}],"con":true,"img":false}]}
{"op":"mcm","clk":"5322265045","pt":1646318250010,"mc":[{"id":"1.195532859","rc":[{"atl":[[70,0]],"id":38324360},{"atl":[[70,0]],"id":38357910},{"atl":[[70,0]],"id":40124755}],"con":true,"img":false}]}
{"op":"mcm","clk":"5322265369","pt":1646318252727,"mc":[{"id":"1.195532859","rc":[{"atl":[[15.5,6.9]],"id":41288595}],"con":true,"img":false}]}
{"op":"mcm","clk":"5322265880","pt":1646318257131,"mc":[{"id":"1.195532859","rc":[{"atl":[[17,15.62]],"id":38324360},{"atb":[[1.19,250]],"id":39290878}],"con":true,"img":false}]}
{"op":"mcm","clk":"5322266147","pt":1646318259740,"mc":[{"id":"1.195532859","rc":[{"atl":[[10,27.78]],"id":40124755}],"con":true,"img":false}]}
{"op":"mcm","clk":"5322266159","pt":1646318259840,"mc":[{"id":"1.195532859","rc":[{"atl":[[12.5,21.74]],"id":38983972},{"atl":[[7.6,37.88]],"id":38357910}],"con":true,"img":false}]}
{"op":"mcm","clk":"5322266395","pt":1646318262730,"mc":[{"id":"1.195532859","rc":[{"atl":[[16.5,9.68],[70,0],[80,0],[60,0]],"id":41288595}],"con":true,"img":false}]}
{"op":"mcm","clk":"5322266816","pt":1646318267138,"mc":[{"id":"1.195532859","rc":[{"atl":[[60,0]],"id":38324360},{"atb":[[1.01,4802.04]],"id":39290878}],"con":true,"img":false}]}
{"op":"mcm","clk":"5322267035","pt":1646318269869,"mc":[{"id":"1.195532859","rc":[{"atl":[[60,0]],"id":38357910},{"atl":[[60,0]],"id":40124755}],"con":true,"img":false}]}
{"op":"mcm","clk":"5322267279","pt":1646318272759,"mc":[{"id":"1.195532859","rc":[{"atl":[[17.5,15.15]],"id":41288595}],"con":true,"img":false}]}
{"op":"mcm","clk":"5322269302","pt":1646318294407,"mc":[{"id":"1.195532859","rc":[{"atb":[[2.18,21.01],[1.94,45.45],[1.93,2.15]],"id":41288595},{"spn":2.18,"spf":1.0,"id":41288595},{"atl":[[10.5,21.06],[9.4,0]],"id":38983972},{"spn":5.77,"spf":"NaN","id":38983972},{"atb":[[4.9,15],[4.7,0]],"id":38324360},{"spn":9.1,"spf":"NaN","id":38324360},{"atb":[[1.27,0],[1.26,384.62]],"id":39290878},{"spn":1.26,"spf":1.0,"id":39290878},{"spn":3.72,"spf":"NaN","id":38357910},{"atl":[[7.2,5.13],[8.4,0]],"id":40124755},{"spn":4.43,"spf":"NaN","id":40124755}],"con":true,"img":false}]}
{"op":"mcm","clk":"5322269310","pt":1646318294515,"mc":[{"id":"1.195532859","rc":[{"atb":[[4.6,15.76],[3.9,8.48]],"id":38324360}],"con":true,"img":false}]}
{"op":"mcm","clk":"5322269317","pt":1646318294609,"mc":[{"id":"1.195532859","rc":[{"atl":[[9.6,3.98]],"id":38983972}],"con":true,"img":false}]}
{"op":"mcm","clk":"5322269368","pt":1646318294983,"mc":[{"id":"1.195532859","rc":[{"atb":[[2.18,0]],"id":41288595},{"atb":[[3.9,0]],"id":38324360}],"con":true,"img":false}]}
{"op":"mcm","clk":"5322269437","pt":1646318295719,"mc":[{"id":"1.195532859","rc":[{"atb":[[1.97,2.15],[1.93,0]],"id":41288595}],"con":true,"img":false}]}
{"op":"mcm","clk":"5322269469","pt":1646318296324,"mc":[{"id":"1.195532859","rc":[{"atl":[[9.6,0]],"id":38983972},{"atb":[[4.6,9]],"id":38324360}],"con":true,"img":false}]}
{"op":"mcm","clk":"5322269698","pt":1646318298400,"mc":[{"id":"1.195532859","rc":[{"atb":[[1.01,5054.04]],"id":41288595}],"con":true,"img":false}]}
{"op":"mcm","clk":"5322269729","pt":1646318298711,"mc":[{"id":"1.195532859","rc":[{"atb":[[1.01,5056.03]],"id":41288595}],"con":true,"img":false}]}
{"op":"mcm","clk":"5322269757","pt":1646318298912,"mc":[{"id":"1.195532859","rc":[{"atb":[[1.01,5054.04]],"id":41288595}],"con":true,"img":false}]}
{"op":"mcm","clk":"5322269764","pt":1646318299022,"mc":[{"id":"1.195532859","rc":[{"atb":[[1.94,47.44]],"id":41288595}],"con":true,"img":false}]}
{"op":"mcm","clk":"5322269773","pt":1646318299125,"mc":[{"id":"1.195532859","rc":[{"atb":[[1.91,0],[1.95,42.11]],"id":41288595},{"atl":[[10.5,14.74],[9.8,0]],"id":38983972}],"con":true,"img":false}]}
{"op":"mcm","clk":"5322269820","pt":1646318299503,"mc":[{"id":"1.195532859","rc":[{"atl":[[10.5,10.53],[11.5,3.81]],"id":38983972},{"atb":[[1.25,0],[1.24,166.67]],"id":39290878},{"atl":[[7.6,6.06],[8.8,0]],"id":40124755}],"con":true,"img":false}]}
{"op":"mcm","clk":"5322269828","pt":1646318299603,"mc":[{"id":"1.195532859","rc":[{"atb":[[1.01,4804.04]],"id":38324360}],"con":true,"img":false}]}
{"op":"mcm","clk":"5322269847","pt":1646318299812,"mc":[{"id":"1.195532859","rc":[{"atb":[[1.01,4806.03]],"id":38324360}],"con":true,"img":false}]}
{"op":"mcm","clk":"5322269879","pt":1646318300223,"mc":[{"id":"1.195532859","rc":[{"atb":[[1.01,4804.04]],"id":38324360}],"con":true,"img":false}]}
{"op":"mcm","clk":"5322269891","pt":1646318300284,"mc":[{"id":"1.195532859","rc":[{"atb":[[5.2,3.64]],"id":38324360}],"con":true,"img":false}]}
{"op":"mcm","clk":"5322269912","pt":1646318300492,"mc":[{"id":"1.195532859","rc":[{"atb":[[1.01,4804.04]],"id":39290878}],"con":true,"img":false}]}
{"op":"mcm","clk":"5322269936","pt":1646318300702,"mc":[{"id":"1.195532859","rc":[{"atb":[[1.01,4806.03]],"id":39290878}],"con":true,"img":false}]}
{"op":"mcm","clk":"5322269959","pt":1646318300913,"mc":[{"id":"1.195532859","rc":[{"atb":[[1.01,4804.04]],"id":39290878}],"con":true,"img":false}]}
{"op":"mcm","clk":"5322269967","pt":1646318301014,"mc":[{"id":"1.195532859","rc":[{"atb":[[1.28,1.99]],"id":39290878}],"con":true,"img":false}]}
{"op":"mcm","clk":"5322269993","pt":1646318301227,"mc":[{"id":"1.195532859","rc":[{"atb":[[1.01,5054.04]],"id":38357910}],"con":true,"img":false}]}
{"op":"mcm","clk":"5322270017","pt":1646318301390,"mc":[{"id":"1.195532859","rc":[{"atb":[[1.01,5056.03]],"id":38357910}],"con":true,"img":false}]}
{"op":"mcm","clk":"5322270035","pt":1646318301608,"mc":[{"id":"1.195532859","rc":[{"atb":[[1.01,5054.04]],"id":38357910}],"con":true,"img":false}]}
{"op":"mcm","clk":"5322270046","pt":1646318301708,"mc":[{"id":"1.195532859","rc":[{"atb":[[1.46,1.99]],"id":38357910}],"con":true,"img":false}]}
{"op":"mcm","clk":"5322270072","pt":1646318302025,"mc":[{"id":"1.195532859","rc":[{"atb":[[1.01,5054.04]],"id":40124755}],"con":true,"img":false}]}
{"op":"mcm","clk":"5322270091","pt":1646318302183,"mc":[{"id":"1.195532859","rc":[{"atb":[[1.01,5056.03]],"id":40124755}],"con":true,"img":false}]}
{"op":"mcm","clk":"5322270113","pt":1646318302402,"mc":[{"id":"1.195532859","rc":[{"atb":[[1.01,5054.04]],"id":40124755}],"con":true,"img":false}]}
{"op":"mcm","clk":"5322270126","pt":1646318302502,"mc":[{"id":"1.195532859","rc":[{"atb":[[1.68,1.99]],"id":40124755}],"con":true,"img":false}]}
{"op":"mcm","clk":"5322270156","pt":1646318302815,"mc":[{"id":"1.195532859","rc":[{"atb":[[1.01,5054.04]],"id":38983972}],"con":true,"img":false}]}
{"op":"mcm","clk":"5322270182","pt":1646318303124,"mc":[{"id":"1.195532859","rc":[{"atb":[[1.01,5056.03]],"id":38983972}],"con":true,"img":false}]}
{"op":"mcm","clk":"5322270204","pt":1646318303286,"mc":[{"id":"1.195532859","rc":[{"atb":[[1.01,5054.04]],"id":38983972}],"con":true,"img":false}]}
{"op":"mcm","clk":"5322270211","pt":1646318303396,"mc":[{"id":"1.195532859","rc":[{"atb":[[1.75,1.99]],"id":38983972}],"con":true,"img":false}]}
{"op":"mcm","clk":"5322270244","pt":1646318303811,"mc":[{"id":"1.195532859","rc":[{"atb":[[1.97,44.26],[1.94,1.99]],"id":41288595},{"atb":[[1.28,168.66],[1.26,0]],"id":39290878}],"con":true,"img":false}]}
{"op":"mcm","clk":"5322270314","pt":1646318304610,"mc":[{"id":"1.195532859","rc":[{"atb":[[1.73,54.79],[1.72,0]],"id":38983972},{"atb":[[1.26,153.85],[1.24,0]],"id":39290878},{"atb":[[1.44,90.91],[1.43,0]],"id":38357910},{"atb":[[1.65,0],[1.66,60.61]],"id":40124755}],"con":true,"img":false}]}
{"op":"mcm","clk":"5322270353","pt":1646318304987,"mc":[{"id":"1.195532859","rc":[{"atb":[[1.94,0]],"id":41288595}],"con":true,"img":false}]}
{"op":"mcm","clk":"5322270363","pt":1646318305090,"mc":[{"id":"1.195532859","rc":[{"atb":[[1.98,1.99]],"id":41288595}],"con":true,"img":false}]}
{"op":"mcm","clk":"5322270741","pt":1646318309126,"mc":[{"id":"1.195532859","rc":[{"atb":[[1.96,41.67],[1.95,0]],"id":41288595}],"con":true,"img":false}]}
{"op":"mcm","clk":"5322271274","pt":1646318314610,"mc":[{"id":"1.195532859","rc":[{"atb":[[1.71,140.85]],"id":38983972},{"atl":[[12.5,8.7]],"id":38983972},{"atb":[[1.42,238.1]],"id":38357910},{"atb":[[1.64,156.25]],"id":40124755},{"atl":[[8,14.29]],"id":40124755}],"con":true,"img":false}]}
{"op":"mcm","clk":"5322271725","pt":1646318319104,"mc":[{"id":"1.195532859","rc":[{"atb":[[1.94,106.38]],"id":41288595}],"con":true,"img":false}]}
{"op":"mcm","clk":"5322271810","pt":1646318319735,"mc":[{"id":"1.195532859","rc":[{"atb":[[1.01,4804.04],[1.87,0]],"id":41288595},{"atb":[[1.01,4804.04]],"id":38983972},{"atl":[[10.5,0],[9.8,8.7]],"id":38983972},{"atb":[[4.8,13.56],[4.9,6]],"id":38324360},{"atb":[[1.01,4804.04]],"id":38357910},{"atb":[[1.01,4804.04]],"id":40124755},{"atl":[[7.2,0],[10,0],[7.6,18.26]],"id":40124755}],"con":true,"img":false}]}
{"op":"mcm","clk":"5322272339","pt":1646318324630,"mc":[{"id":"1.195532859","rc":[{"atb":[[1.69,217.39]],"id":38983972},{"atl":[[10.5,4.21]],"id":38983972},{"atb":[[1.4,250]],"id":38357910},{"atb":[[1.62,241.94]],"id":40124755},{"atl":[[8,5.71],[7.6,12.2]],"id":40124755}],"con":true,"img":false}]}
{"op":"mcm","clk":"5322272771","pt":1646318329129,"mc":[{"id":"1.195532859","rc":[{"atb":[[1.92,163.04]],"id":41288595}],"con":true,"img":false}]}
{"op":"mcm","clk":"5322273322","pt":1646318334642,"mc":[{"id":"1.195532859","rc":[{"atb":[[1.67,250]],"id":38983972},{"atl":[[11.5,9.52]],"id":38983972},{"atb":[[1.6,250]],"id":40124755},{"atl":[[8.4,13.51]],"id":40124755}],"con":true,"img":false}]}
{"op":"mcm","clk":"5322273452","pt":1646318335856,"mc":[{"id":"1.195532859","rc":[{"atl":[[9.4,6.1]],"id":40124755}],"con":true,"img":false}]}
{"op":"mcm","clk":"5322273493","pt":1646318336269,"mc":[{"id":"1.195532859","rc":[{"atl":[[9.4,0]],"id":40124755}],"con":true,"img":false}]}
{"op":"mcm","clk":"5322273767","pt":1646318339139,"mc":[{"id":"1.195532859","rc":[{"atb":[[1.9,250]],"id":41288595}],"con":true,"img":false}]}
{"op":"mcm","clk":"5322274281","pt":1646318344688,"mc":[{"id":"1.195532859","rc":[{"atl":[[12.5,13.04],[13,3.26]],"id":38983972},{"atl":[[8.8,19.23]],"id":40124755}],"con":true,"img":false}]}
{"op":"mcm","clk":"5322274294","pt":1646318344798,"mc":[{"id":"1.195532859","rc":[{"atl":[[13,0]],"id":38983972}],"con":true,"img":false}]}
{"op":"mcm","clk":"5322274703","pt":1646318349186,"mc":[{"id":"1.195532859","rc":[{"atb":[[1.88,0]],"id":41288595}],"con":true,"img":false}]}
{"op":"mcm","clk":"5322275031","pt":1646318353021,"mc":[{"id":"1.195532859","rc":[{"atl":[[10.5,14.74],[9.8,0]],"id":38983972},{"atb":[[4.9,15]],"id":38324360},{"atl":[[9.6,0],[7.6,0],[7.8,14.71]],"id":40124755}],"con":true,"img":false}]}
{"op":"mcm","clk":"5322275040","pt":1646318353117,"mc":[{"id":"1.195532859","rc":[{"atb":[[2.18,12.32]],"id":41288595},{"atb":[[1.79,17.6]],"id":38983972},{"atb":[[4.8,0]],"id":38324360},{"atb":[[1.25,96.16]],"id":39290878},{"atl":[[3.35,10.6]],"id":39290878},{"atb":[[1.73,16.13]],"id":40124755}],"con":true,"img":false}]}
{"op":"mcm","clk":"5322275052","pt":1646318353177,"mc":[{"id":"1.195532859","rc":[{"atb":[[1.79,0]],"id":38983972},{"atb":[[1.73,0]],"id":40124755}],"con":true,"img":false}]}
{"op":"mcm","clk":"5322275060","pt":1646318353286,"mc":[{"id":"1.195532859","rc":[{"atb":[[2.18,0]],"id":41288595},{"atb":[[3.9,8.48]],"id":38324360},{"atb":[[1.25,0]],"id":39290878},{"atl":[[3.35,0]],"id":39290878}],"con":true,"img":false}]}
{"op":"mcm","clk":"5322275077","pt":1646318353392,"mc":[{"id":"1.195532859","rc":[{"atb":[[1.98,0]],"id":41288595}],"con":true,"img":false}]}
{"op":"mcm","clk":"5322275086","pt":1646318353497,"mc":[{"id":"1.195532859","rc":[{"atb":[[2.2,1.99]],"id":41288595}],"con":true,"img":false}]}
{"op":"mcm","clk":"5322275099","pt":1646318353600,"mc":[{"id":"1.195532859","rc":[{"atb":[[3.9,0]],"id":38324360}],"con":true,"img":false}]}
{"op":"mcm","clk":"5322275104","pt":1646318353697,"mc":[{"id":"1.195532859","rc":[{"atb":[[1.97,2.15],[2.2,43.66]],"id":41288595},{"atb":[[1.68,0]],"id":40124755}],"con":true,"img":false}]}
{"op":"mcm","clk":"5322275117","pt":1646318353813,"mc":[{"id":"1.195532859","rc":[{"atb":[[1.97,46.41],[2.2,1.99]],"id":41288595},{"atb":[[1.74,1.99]],"id":40124755}],"con":true,"img":false}]}
{"op":"mcm","clk":"5322275131","pt":1646318354012,"mc":[{"id":"1.195532859","rc":[{"atb":[[1.97,2.15],[2.2,43.66]],"id":41288595},{"atb":[[1.74,62.6],[1.67,2.15]],"id":40124755}],"con":true,"img":false}]}
{"op":"mcm","clk":"5322275143","pt":1646318354115,"mc":[{"id":"1.195532859","rc":[{"atb":[[1.75,0]],"id":38983972}],"con":true,"img":false}]}
{"op":"mcm","clk":"5322275153","pt":1646318354217,"mc":[{"id":"1.195532859","rc":[{"atb":[[1.8,1.99]],"id":38983972}],"con":true,"img":false}]}
{"op":"mcm","clk":"5322275173","pt":1646318354384,"mc":[{"id":"1.195532859","rc":[{"atb":[[1.8,56.78],[1.74,2.15]],"id":38983972}],"con":true,"img":false}]}
{"op":"mcm","clk":"5322275193","pt":1646318354592,"mc":[{"id":"1.195532859","rc":[{"spn":2.2,"spf":1.0,"id":41288595},{"spn":6.15,"spf":"NaN","id":38983972},{"spn":1.28,"spf":1.0,"id":39290878},{"spn":3.73,"spf":"NaN","id":38357910},{"atb":[[1.72,55.56],[1.66,0]],"id":40124755},{"atl":[[8,0],[8.2,5.56]],"id":40124755},{"spn":4.77,"spf":"NaN","id":40124755}],"con":true,"img":false}]}
{"op":"mcm","clk":"5322275201","pt":1646318354688,"mc":[{"id":"1.195532859","rc":[{"atb":[[1.73,0],[1.78,51.28]],"id":38983972},{"atl":[[10.5,10.53],[11.5,3.81]],"id":38983972}],"con":true,"img":false}]}
{"op":"mcm","clk":"5322275210","pt":1646318354795,"mc":[{"id":"1.195532859","rc":[{"atb":[[2.04,23.58]],"id":38983972}],"con":true,"img":false}]}
{"op":"mcm","clk":"5322275241","pt":1646318355117,"mc":[{"id":"1.195532859","rc":[{"atb":[[1.8,54.79]],"id":38983972}],"con":true,"img":false}]}
{"op":"mcm","clk":"5322275252","pt":1646318355219,"mc":[{"id":"1.195532859","rc":[{"atb":[[2.06,1.99]],"id":38983972}],"con":true,"img":false}]}
{"op":"mcm","clk":"5322275365","pt":1646318356619,"mc":[{"id":"1.195532859","rc":[{"atb":[[2.04,0]],"id":38983972}],"con":true,"img":false}]}
{"op":"mcm","clk":"5322275412","pt":1646318357107,"mc":[{"id":"1.195532859","rc":[{"atb":[[2.22,1.65]],"id":41288595},{"atb":[[2.08,1.65]],"id":38983972}],"con":true,"img":false}]}
{"op":"mcm","clk":"5322275451","pt":1646318357622,"mc":[{"id":"1.195532859","rc":[{"atb":[[2.06,0]],"id":38983972}],"con":true,"img":false}]}
{"op":"mcm","clk":"5322275461","pt":1646318357726,"mc":[{"id":"1.195532859","rc":[{"atb":[[1.81,1.99]],"id":38983972}],"con":true,"img":false}]}
{"op":"mcm","clk":"5322275471","pt":1646318357825,"mc":[{"id":"1.195532859","rc":[{"atb":[[1.83,2.15],[1.74,0]],"id":38983972}],"con":true,"img":false}]}
{"op":"mcm","clk":"5322275510","pt":1646318358292,"mc":[{"id":"1.195532859","rc":[{"atb":[[1.81,0]],"id":38983972}],"con":true,"img":false}]}
{"op":"mcm","clk":"5322275520","pt":1646318358395,"mc":[{"id":"1.195532859","rc":[{"atb":[[1.84,1.99]],"id":38983972}],"con":true,"img":false}]}
{"op":"mcm","clk":"5322275957","pt":1646318363028,"mc":[{"id":"1.195532859","rc":[{"atb":[[1.96,0],[2.18,33.9]],"id":41288595}],"con":true,"img":false}]}
{"op":"mcm","clk":"5322275981","pt":1646318363234,"mc":[{"id":"1.195532859","rc":[{"atb":[[1.8,0],[2.08,3.65]],"id":38983972}],"con":true,"img":false}]}
{"op":"mcm","clk":"5322276102","pt":1646318364536,"mc":[{"id":"1.195532859","rc":[{"atb":[[1.84,0]],"id":38983972}],"con":true,"img":false}]}
{"op":"mcm","clk":"5322276110","pt":1646318364596,"mc":[{"id":"1.195532859","rc":[{"atb":[[2.04,38.46],[1.78,0],[2.1,1.99]],"id":38983972},{"atl":[[12.5,8.7]],"id":38983972},{"atb":[[1.7,142.86]],"id":40124755},{"atl":[[8.6,13.16]],"id":40124755}],"con":true,"img":false}]}
{"op":"mcm","clk":"5322276431","pt":1646318368311,"mc":[{"id":"1.195532859","rc":[{"atb":[[1.67,0],[1.77,2.15]],"id":40124755}],"con":true,"img":false}]}
{"op":"mcm","clk":"5322276445","pt":1646318368407,"mc":[{"id":"1.195532859","rc":[{"atb":[[1.77,57.71]],"id":40124755}],"con":true,"img":false}]}
{"op":"mcm","clk":"5322276458","pt":1646318368517,"mc":[{"id":"1.195532859","rc":[{"atb":[[1.74,1.99]],"id":40124755}],"con":true,"img":false}]}
{"op":"mcm","clk":"5322276489","pt":1646318368828,"mc":[{"id":"1.195532859","rc":[{"atb":[[1.74,0]],"id":40124755}],"con":true,"img":false}]}
{"op":"mcm","clk":"5322276497","pt":1646318368934,"mc":[{"id":"1.195532859","rc":[{"atb":[[1.78,1.99]],"id":40124755}],"con":true,"img":false}]}
{"op":"mcm","clk":"5322276734","pt":1646318371228,"mc":[{"id":"1.195532859","rc":[{"atb":[[2.08,2]],"id":38983972}],"con":true,"img":false}]}
{"op":"mcm","clk":"5322276744","pt":1646318371334,"mc":[{"id":"1.195532859","rc":[{"atb":[[2.12,1.65]],"id":38983972}],"con":true,"img":false}]}
{"op":"mcm","clk":"5322276793","pt":1646318371900,"mc":[{"id":"1.195532859","rc":[{"atb":[[2.12,3.65],[2.08,0]],"id":38983972}],"con":true,"img":false}]}
{"op":"mcm","clk":"5322276876","pt":1646318372842,"mc":[{"id":"1.195532859","rc":[{"atb":[[2.1,0]],"id":38983972}],"con":true,"img":false}]}
{"op":"mcm","clk":"5322276887","pt":1646318372952,"mc":[{"id":"1.195532859","rc":[{"atb":[[2.14,1.99]],"id":38983972}],"con":true,"img":false}]}
{"op":"mcm","clk":"5322276895","pt":1646318373003,"mc":[{"id":"1.195532859","rc":[{"atb":[[2.14,87.72]],"id":41288595}],"con":true,"img":false}]}
{"op":"mcm","clk":"5322277062","pt":1646318374730,"mc":[{"id":"1.195532859","rc":[{"atb":[[2.04,0],[2.1,36.36]],"id":38983972},{"atl":[[13.5,12]],"id":38983972},{"atb":[[1.72,0],[1.76,52.63]],"id":40124755},{"atl":[[9,18.75],[9.2,0],[8.8,0],[8.4,0]],"id":40124755}],"con":true,"img":false}]}
{"op":"mcm","clk":"5322277109","pt":1646318375149,"mc":[{"id":"1.195532859","rc":[{"atl":[[8.6,19.92]],"id":40124755}],"con":true,"img":false}]}
{"op":"mcm","clk":"5322277281","pt":1646318376922,"mc":[{"id":"1.195532859","rc":[{"atl":[[8.6,13.16]],"id":40124755}],"con":true,"img":false}]}
{"op":"mcm","clk":"5322277404","pt":1646318378228,"mc":[{"id":"1.195532859","rc":[{"atb":[[2.12,2]],"id":38983972}],"con":true,"img":false}]}
{"op":"mcm","clk":"5322277425","pt":1646318378440,"mc":[{"id":"1.195532859","rc":[{"atb":[[2.16,1.65]],"id":38983972}],"con":true,"img":false}]}
{"op":"mcm","clk":"5322277460","pt":1646318378811,"mc":[{"id":"1.195532859","rc":[{"atb":[[1.97,0],[2.26,2.15]],"id":41288595}],"con":true,"img":false}]}
{"op":"mcm","clk":"5322277471","pt":1646318378910,"mc":[{"id":"1.195532859","rc":[{"atb":[[2.26,4.3]],"id":41288595}],"con":true,"img":false}]}
{"op":"mcm","clk":"5322277481","pt":1646318379015,"mc":[{"id":"1.195532859","rc":[{"atb":[[2.2,1.99]],"id":41288595}],"con":true,"img":false}]}
{"op":"mcm","clk":"5322277552","pt":1646318379807,"mc":[{"id":"1.195532859","rc":[{"atb":[[2.2,0]],"id":41288595}],"con":true,"img":false}]}
{"op":"mcm","clk":"5322277563","pt":1646318379908,"mc":[{"id":"1.195532859","rc":[{"atb":[[2.28,1.99]],"id":41288595}],"con":true,"img":false}]}
{"op":"mcm","clk":"5322277607","pt":1646318380428,"mc":[{"id":"1.195532859","rc":[{"atb":[[2.24,3.3]],"id":41288595},{"atb":[[2.16,5.63]],"id":38983972},{"atb":[[5.3,7.29]],"id":38324360},{"atb":[[1.24,195.14]],"id":39290878},{"atb":[[1.47,3.97]],"id":38357910},{"atb":[[1.79,3.97]],"id":40124755}],"con":true,"img":false}]}
{"op":"mcm","clk":"5322277614","pt":1646318380532,"mc":[{"id":"1.195532859","rc":[{"atb":[[2.16,7.63]],"id":38983972}],"con":true,"img":false}]}
{"op":"mcm","clk":"5322277628","pt":1646318380647,"mc":[{"id":"1.195532859","rc":[{"atb":[[2.12,0]],"id":38983972},{"atb":[[4.8,3]],"id":38324360},{"atb":[[1.45,2.15],[1.48,3.98]],"id":38357910},{"atb":[[1.8,3.98],[1.77,2.15]],"id":40124755}],"con":true,"img":false}]}
{"op":"mcm","clk":"5322277633","pt":1646318380741,"mc":[{"id":"1.195532859","rc":[{"atb":[[5.2,1.65]],"id":38324360}],"con":true,"img":false}]}
{"op":"mcm","clk":"5322277646","pt":1646318380847,"mc":[{"id":"1.195532859","rc":[{"atb":[[4.8,0],[5.4,1.99]],"id":38324360}],"con":true,"img":false}]}
{"op":"mcm","clk":"5322277662","pt":1646318381006,"mc":[{"id":"1.195532859","rc":[{"atb":[[1.46,0]],"id":38357910}],"con":true,"img":false}]}
{"op":"mcm","clk":"5322277673","pt":1646318381111,"mc":[{"id":"1.195532859","rc":[{"atb":[[1.48,5.97]],"id":38357910}],"con":true,"img":false}]}
{"op":"mcm","clk":"5322277691","pt":1646318381314,"mc":[{"id":"1.195532859","rc":[{"atb":[[1.78,0]],"id":40124755}],"con":true,"img":false}]}
{"op":"mcm","clk":"5322277702","pt":1646318381419,"mc":[{"id":"1.195532859","rc":[{"atb":[[1.8,5.97]],"id":40124755}],"con":true,"img":false}]}
{"op":"mcm","clk":"5322277719","pt":1646318381628,"mc":[{"id":"1.195532859","rc":[{"atb":[[2.14,0]],"id":38983972}],"con":true,"img":false}]}
{"op":"mcm","clk":"5322277731","pt":1646318381733,"mc":[{"id":"1.195532859","rc":[{"atb":[[2.18,1.99]],"id":38983972}],"con":true,"img":false}]}
{"op":"mcm","clk":"5322277849","pt":1646318383043,"mc":[{"id":"1.195532859","rc":[{"atb":[[2.24,35.56],[2.18,0]],"id":41288595}],"con":true,"img":false}]}
{"op":"mcm","clk":"5322278001","pt":1646318384705,"mc":[{"id":"1.195532859","rc":[{"atb":[[2.1,0],[2.14,35.09]],"id":38983972},{"atl":[[14.5,18.52]],"id":38983972},{"atb":[[1.78,51.28],[1.76,0]],"id":40124755},{"atl":[[9.4,29.76]],"id":40124755}],"con":true,"img":false}]}
{"op":"mcm","clk":"5322278058","pt":1646318385231,"mc":[{"id":"1.195532859","rc":[{"atb":[[2.22,0]],"id":41288595},{"atb":[[2.16,5.97]],"id":38983972},{"atb":[[5.2,0]],"id":38324360}],"con":true,"img":false}]}
{"op":"mcm","clk":"5322278078","pt":1646318385432,"mc":[{"id":"1.195532859","rc":[{"atb":[[2.3,1.65]],"id":41288595},{"atb":[[2.2,1.65]],"id":38983972},{"atb":[[5.5,1.65]],"id":38324360}],"con":true,"img":false}]}
{"op":"mcm","clk":"5322278087","pt":1646318385537,"mc":[{"id":"1.195532859","rc":[{"atb":[[2.3,3.65]],"id":41288595}],"con":true,"img":false}]}
{"op":"mcm","clk":"5322278100","pt":1646318385645,"mc":[{"id":"1.195532859","rc":[{"atb":[[2.26,2.15]],"id":41288595}],"con":true,"img":false}]}
{"op":"mcm","clk":"5322278121","pt":1646318385857,"mc":[{"id":"1.195532859","rc":[{"atb":[[2.28,0]],"id":41288595}],"con":true,"img":false}]}
{"op":"mcm","clk":"5322278128","pt":1646318385912,"mc":[{"id":"1.195532859","rc":[{"atb":[[2.24,32.26],[2.32,1.99]],"id":41288595},{"atb":[[2.16,2]],"id":38983972},{"atb":[[5.3,0]],"id":38324360},{"atb":[[1.47,0]],"id":38357910},{"atb":[[1.79,0]],"id":40124755}],"con":true,"img":false}]}
{"op":"mcm","clk":"5322278174","pt":1646318386326,"mc":[{"id":"1.195532859","rc":[{"atb":[[5.4,0]],"id":38324360}],"con":true,"img":false}]}
{"op":"mcm","clk":"5322278181","pt":1646318386430,"mc":[{"id":"1.195532859","rc":[{"atb":[[5.2,1.99]],"id":38324360}],"con":true,"img":false}]}
{"op":"mcm","clk":"5322278358","pt":1646318388358,"mc":[{"id":"1.195532859","rc":[{"atb":[[2.24,0],[2.28,31.25]],"id":41288595},{"atb":[[1.46,86.96],[1.44,0],[1.43,11.36]],"id":38357910},{"atb":[[1.6,0]],"id":40124755}],"con":true,"img":false}]}
{"op":"mcm","clk":"5322278375","pt":1646318388522,"mc":[{"id":"1.195532859","rc":[{"atb":[[2.14,0]],"id":41288595},{"atb":[[5,14],[4.9,6]],"id":38324360},{"atb":[[1.43,0]],"id":38357910}],"con":true,"img":false}]}
{"op":"mcm","clk":"5322278452","pt":1646318389450,"mc":[{"id":"1.195532859","rc":[{"atb":[[1.45,0],[1.49,2.15]],"id":38357910}],"con":true,"img":false}]}
{"op":"mcm","clk":"5322278499","pt":1646318389923,"mc":[{"id":"1.195532859","rc":[{"atb":[[1.48,3.98]],"id":38357910}],"con":true,"img":false}]}
{"op":"mcm","clk":"5322278509","pt":1646318390029,"mc":[{"id":"1.195532859","rc":[{"atb":[[1.5,1.99]],"id":38357910}],"con":true,"img":false}]}
{"op":"mcm","clk":"5322278523","pt":1646318390231,"mc":[{"id":"1.195532859","rc":[{"atb":[[1.5,4.14],[1.48,0]],"id":38357910}],"con":true,"img":false}]}
{"op":"mcm","clk":"5322278699","pt":1646318392138,"mc":[{"id":"1.195532859","rc":[{"atb":[[2.3,2]],"id":41288595},{"atb":[[5.5,0]],"id":38324360}],"con":true,"img":false}]}
{"op":"mcm","clk":"5322278704","pt":1646318392236,"mc":[{"id":"1.195532859","rc":[{"atb":[[1.46,0],[1.48,83.33]],"id":38357910}],"con":true,"img":false}]}
{"op":"mcm","clk":"5322278712","pt":1646318392339,"mc":[{"id":"1.195532859","rc":[{"atb":[[2.34,1.65]],"id":41288595},{"atb":[[5.3,1.65]],"id":38324360}],"con":true,"img":false}]}
{"op":"mcm","clk":"5322278752","pt":1646318392442,"mc":[{"id":"1.195532859","rc":[{"atb":[[2.34,5.63]],"id":41288595},{"atb":[[2.22,3.3]],"id":38983972},{"atb":[[5.3,6.2]],"id":38324360},{"atb":[[1.49,14.09]],"id":38357910},{"atb":[[1.81,11.94]],"id":40124755}],"con":true,"img":false}]}
{"op":"mcm","clk":"5322278797","pt":1646318392653,"mc":[{"id":"1.195532859","rc":[{"atb":[[1.8,1.99],[1.82,11.95]],"id":40124755}],"con":true,"img":false}]}
{"op":"mcm","clk":"5322278829","pt":1646318393037,"mc":[{"id":"1.195532859","rc":[{"atb":[[2.32,0]],"id":41288595}],"con":true,"img":false}]}
{"op":"mcm","clk":"5322278833","pt":1646318393132,"mc":[{"id":"1.195532859","rc":[{"atb":[[2.36,1.99]],"id":41288595}],"con":true,"img":false}]}
{"op":"mcm","clk":"5322278852","pt":1646318393339,"mc":[{"id":"1.195532859","rc":[{"atb":[[5.2,0]],"id":38324360}],"con":true,"img":false}]}
{"op":"mcm","clk":"5322278860","pt":1646318393442,"mc":[{"id":"1.195532859","rc":[{"atb":[[5.4,1.99]],"id":38324360}],"con":true,"img":false}]}
{"op":"mcm","clk":"5322278886","pt":1646318393755,"mc":[{"id":"1.195532859","rc":[{"atb":[[1.8,0]],"id":40124755}],"con":true,"img":false}]}
{"op":"mcm","clk":"5322278892","pt":1646318393859,"mc":[{"id":"1.195532859","rc":[{"atb":[[1.83,1.99]],"id":40124755}],"con":true,"img":false}]}
{"op":"mcm","clk":"5322278908","pt":1646318394022,"mc":[{"id":"1.195532859","rc":[{"atb":[[2.36,3.99],[2.3,0]],"id":41288595},{"atb":[[2.18,0]],"id":38983972}],"con":true,"img":false}]}
{"op":"mcm","clk":"5322278917","pt":1646318394126,"mc":[{"id":"1.195532859","rc":[{"atb":[[2.24,1.99]],"id":38983972}],"con":true,"img":false}]}
{"op":"mcm","clk":"5322278967","pt":1646318394641,"mc":[{"id":"1.195532859","rc":[{"atb":[[1.81,61.32]],"id":40124755}],"con":true,"img":false}]}
{"op":"mcm","clk":"5322278977","pt":1646318394745,"mc":[{"id":"1.195532859","rc":[{"atb":[[2.1,90.91]],"id":38983972},{"atb":[[1.78,0],[1.77,8.56]],"id":40124755}],"con":true,"img":false}]}
{"op":"mcm","clk":"5322278992","pt":1646318394956,"mc":[{"id":"1.195532859","rc":[{"atb":[[1.77,2.15]],"id":40124755}],"con":true,"img":false}]}
{"op":"mcm","clk":"5322279089","pt":1646318395838,"mc":[{"id":"1.195532859","rc":[{"atb":[[2.32,30.3],[2.28,3.84]],"id":41288595},{"atb":[[1.67,0]],"id":38983972}],"con":true,"img":false}]}
{"op":"mcm","clk":"5322279112","pt":1646318396051,"mc":[{"id":"1.195532859","rc":[{"atb":[[2.28,0]],"id":41288595}],"con":true,"img":false}]}
{"op":"mcm","clk":"5322279191","pt":1646318397039,"mc":[{"id":"1.195532859","rc":[{"atb":[[5.1,12.19],[5,0]],"id":38324360}],"con":true,"img":false}]}
{"op":"mcm","clk":"5322279213","pt":1646318397350,"mc":[{"id":"1.195532859","rc":[{"atb":[[2.34,1.65]],"id":41288595},{"atb":[[2.22,0]],"id":38983972},{"atb":[[1.49,2.15]],"id":38357910},{"atb":[[1.81,49.38]],"id":40124755}],"con":true,"img":false}]}
{"op":"mcm","clk":"5322279341","pt":1646318398968,"mc":[{"id":"1.195532859","rc":[{"atb":[[2.24,0]],"id":38983972}],"con":true,"img":false}]}
{"op":"mcm","clk":"5322279349","pt":1646318399027,"mc":[{"id":"1.195532859","rc":[{"atb":[[2.22,1.99]],"id":38983972}],"con":true,"img":false}]}
{"op":"mcm","clk":"5322279359","pt":1646318399129,"mc":[{"id":"1.195532859","rc":[{"atb":[[2.34,0]],"id":41288595},{"atb":[[2.2,0]],"id":38983972},{"atb":[[5.3,4.54]],"id":38324360}],"con":true,"img":false}]}
{"op":"mcm","clk":"5322279371","pt":1646318399338,"mc":[{"id":"1.195532859","rc":[{"atb":[[2.38,1.65]],"id":41288595},{"atb":[[2.26,1.65]],"id":38983972},{"atb":[[5.5,1.65]],"id":38324360}],"con":true,"img":false}]}
{"op":"mcm","clk":"5322279380","pt":1646318399443,"mc":[{"id":"1.195532859","rc":[{"atb":[[2.22,0]],"id":38983972}],"con":true,"img":false}]}
{"op":"mcm","clk":"5322279387","pt":1646318399541,"mc":[{"id":"1.195532859","rc":[{"atb":[[2.18,1.99]],"id":38983972}],"con":true,"img":false}]}
{"op":"mcm","clk":"5322279447","pt":1646318400226,"mc":[{"id":"1.195532859","rc":[{"atb":[[2.06,10],[2.22,2.5],[1.77,36.03],[2.2,18.83],[2.14,5]],"id":40124755},{"atl":[[7.2,12.9],[8.6,39.32],[5.1,2.5],[5.5,5],[5.9,10]],"id":40124755}],"con":true,"img":false}]}
{"op":"mcm","clk":"5322279477","pt":1646318400445,"mc":[{"id":"1.195532859","rc":[{"atb":[[2.8,5.21],[2.5,2.5],[2.42,5],[2.26,12.91],[2.34,10]],"id":41288595},{"atl":[[8,10],[7.2,5],[9,5.21],[6.4,2.5],[15.5,21.42]],"id":41288595},{"atb":[[2.32,10],[2.14,50.73],[2.48,2.5],[1.76,7.26],[2.4,5],[2.24,4.36]],"id":38983972},{"atl":[[7.4,10],[12.5,26.71],[6.6,5],[5.9,2.5],[8.4,4.36]],"id":38983972},{"atb":[[5.1,26.8],[5.5,8.06],[3.9,3.41]],"id":38324360},{"atl":[[12.5,6.41],[14.5,2.5],[15,22.15]],"id":38324360},{"atb":[[1.59,2.5],[1.55,5],[1.23,354.17],[1.51,10],[1.24,376.77]],"id":39290878},{"atl":[[3.2,161.27],[2.98,40.4]],"id":39290878},{"atb":[[1.64,2.5],[1.56,10],[1.6,5],[1.48,97.77],[1.65,8.66]],"id":38357910},{"atl":[[4.5,5],[4.1,2.5],[6.8,40.34],[4.9,10],[5.9,8.66]],"id":38357910},{"atb":[[2,3.56]],"id":40124755},{"atl":[[7.8,0],[5.9,23.16]],"id":40124755}],"con":true,"img":false}]}
{"op":"mcm","clk":"5322279485","pt":1646318400537,"mc":[{"id":"1.195532859","rc":[{"atl":[[8,12.96],[13.5,0]],"id":41288595},{"atl":[[10.5,0],[7.4,18.7]],"id":38983972},{"atl":[[14.5,9.91],[15.5,9]],"id":38324360},{"atb":[[1.28,1.99],[1.29,134.18],[1.51,178.66]],"id":39290878},{"atb":[[1.55,14.44],[1.5,1.99]],"id":38357910},{"atl":[[6,0]],"id":38357910}],"con":true,"img":false}]}
{"op":"mcm","clk":"5322279495","pt":1646318400643,"mc":[{"id":"1.195532859","rc":[{"atl":[[12,7.14]],"id":38983972},{"atl":[[3.2,115.82],[3.1,50.1]],"id":39290878},{"atb":[[1.6,9.14]],"id":38357910},{"atl":[[4.9,17.41]],"id":38357910},{"atb":[[1.83,0]],"id":40124755}],"con":true,"img":false}]}
{"op":"mcm","clk":"5322279503","pt":1646318400747,"mc":[{"id":"1.195532859","rc":[{"atb":[[1.76,0]],"id":38983972},{"atb":[[3.9,0]],"id":38324360},{"atb":[[1.23,250]],"id":39290878},{"atb":[[2.24,1.99]],"id":40124755}],"con":true,"img":false}]}
{"op":"mcm","clk":"5322279523","pt":1646318401052,"mc":[{"id":"1.195532859","rc":[{"atb":[[2.26,10.76],[2.48,2.15]],"id":41288595},{"atb":[[1.54,2.15]],"id":39290878},{"atb":[[2.12,10],[1.82,0]],"id":40124755}],"con":true,"img":false}]}
{"op":"mcm","clk":"5322279535","pt":1646318401263,"mc":[{"id":"1.195532859","rc":[{"atl":[[12,0]],"id":38983972},{"atb":[[1.55,0]],"id":38357910},{"atb":[[2,0]],"id":40124755}],"con":true,"img":false}]}
{"op":"mcm","clk":"5322279547","pt":1646318401474,"mc":[{"id":"1.195532859","rc":[{"atb":[[2.36,2]],"id":41288595}],"con":true,"img":false}]}
{"op":"mcm","clk":"5322279555","pt":1646318401577,"mc":[{"id":"1.195532859","rc":[{"atb":[[2.82,1.99]],"id":41288595}],"con":true,"img":false}]}
{"op":"mcm","clk":"5322279578","pt":1646318401842,"mc":[{"id":"1.195532859","rc":[{"atb":[[5.4,0]],"id":38324360}],"con":true,"img":false}]}
{"op":"mcm","clk":"5322279583","pt":1646318401945,"mc":[{"id":"1.195532859","rc":[{"atb":[[1.02,1.99]],"id":38324360}],"con":true,"img":false}]}
{"op":"mcm","clk":"5322279616","pt":1646318402254,"mc":[{"id":"1.195532859","rc":[{"atb":[[1.28,0]],"id":39290878},{"atb":[[1.59,67.8],[1.48,14.44]],"id":38357910},{"atl":[[4.3,12.12],[6.4,0]],"id":38357910}],"con":true,"img":false}]}
{"op":"mcm","clk":"5322279623","pt":1646318402357,"mc":[{"id":"1.195532859","rc":[{"atb":[[1.6,1.99]],"id":39290878}],"con":true,"img":false}]}
{"op":"mcm","clk":"5322279636","pt":1646318402465,"mc":[{"id":"1.195532859","rc":[{"atb":[[2.64,7.2]],"id":41288595},{"atl":[[4.9,10],[4.2,12.12]],"id":38357910}],"con":true,"img":false}]}
{"op":"mcm","clk":"5322279647","pt":1646318402564,"mc":[{"id":"1.195532859","rc":[{"atb":[[2.36,0]],"id":41288595},{"atb":[[1.5,0]],"id":38357910}],"con":true,"img":false}]}
{"op":"mcm","clk":"5322279656","pt":1646318402669,"mc":[{"id":"1.195532859","rc":[{"atb":[[1.66,1.99]],"id":38357910}],"con":true,"img":false}]}
{"op":"mcm","clk":"5322279665","pt":1646318402833,"mc":[{"id":"1.195532859","rc":[{"atb":[[1.6,5],[1.66,4.49]],"id":38357910}],"con":true,"img":false}]}
{"op":"mcm","clk":"5322279674","pt":1646318402937,"mc":[{"id":"1.195532859","rc":[{"atb":[[2.18,0]],"id":38983972}],"con":true,"img":false}]}
{"op":"mcm","clk":"5322279683","pt":1646318403041,"mc":[{"id":"1.195532859","rc":[{"atb":[[2.5,1.99]],"id":38983972}],"con":true,"img":false}]}
{"op":"mcm","clk":"5322279707","pt":1646318403448,"mc":[{"id":"1.195532859","rc":[{"atb":[[2.4,3.3]],"id":41288595},{"atb":[[2.2,4.95]],"id":38983972},{"atb":[[5.3,0]],"id":38324360},{"atb":[[1.51,8.28]],"id":38357910},{"atb":[[1.84,3.97]],"id":40124755}],"con":true,"img":false}]}
{"op":"mcm","clk":"5322279804","pt":1646318404654,"mc":[{"id":"1.195532859","rc":[{"atl":[[11.5,0]],"id":38983972},{"atb":[[2.1,36.36],[1.81,0]],"id":40124755},{"atl":[[8.2,0],[5.3,9.3]],"id":40124755}],"con":true,"img":false}]}
{"op":"mcm","clk":"5322279816","pt":1646318404775,"mc":[{"id":"1.195532859","rc":[{"atb":[[2.68,23.81]],"id":41288595},{"atl":[[6.8,6.9]],"id":41288595},{"atb":[[2.06,141.51]],"id":38983972},{"atl":[[6.2,7.69]],"id":38983972},{"atb":[[4.6,11.5]],"id":38324360},{"atl":[[13.5,3.2],[14,6]],"id":38324360},{"atb":[[1.58,68.97],[1.26,0]],"id":39290878},{"atl":[[3.1,31.05],[3.05,19.51]],"id":39290878}],"con":true,"img":false}]}
{"op":"mcm","clk":"5322279821","pt":1646318404862,"mc":[{"id":"1.195532859","rc":[{"atb":[[2.8,0],[2.32,0]],"id":41288595},{"atl":[[14.5,0]],"id":41288595},{"atb":[[4,33.33],[5.1,18.61],[5.5,1.65]],"id":38324360},{"atl":[[12.5,0],[14.5,2.5],[15,7.14]],"id":38324360},{"atl":[[3.15,9.53]],"id":39290878},{"atb":[[2.12,0],[2.14,15]],"id":40124755}],"con":true,"img":false}]}
{"op":"mcm","clk":"5322279828","pt":1646318404966,"mc":[{"id":"1.195532859","rc":[{"atb":[[2.8,3.65]],"id":41288595},{"atl":[[7.4,10],[6.6,10]],"id":38983972},{"atl":[[14.5,0],[19.5,5.41]],"id":38324360}],"con":true,"img":false}]}
{"op":"mcm","clk":"5322279835","pt":1646318405072,"mc":[{"id":"1.195532859","rc":[{"atb":[[2.68,32.74]],"id":41288595},{"atl":[[14,9.08]],"id":38324360}],"con":true,"img":false}]}
{"op":"mcm","clk":"5322279840","pt":1646318405176,"mc":[{"id":"1.195532859","rc":[{"atl":[[13.5,0]],"id":38324360}],"con":true,"img":false}]}
{"op":"mcm","clk":"5322279852","pt":1646318405281,"mc":[{"id":"1.195532859","rc":[{"atb":[[1.02,0]],"id":38324360}],"con":true,"img":false}]}
{"op":"mcm","clk":"5322279864","pt":1646318405450,"mc":[{"id":"1.195532859","rc":[{"atb":[[2.8,0]],"id":41288595},{"atb":[[5.2,1.99]],"id":38324360},{"atl":[[3.15,0]],"id":39290878}],"con":true,"img":false}]}
{"op":"mcm","clk":"5322279910","pt":1646318405974,"mc":[{"id":"1.195532859","rc":[{"atb":[[2.82,0]],"id":41288595},{"atb":[[1.24,181.63]],"id":39290878}],"con":true,"img":false}]}
{"op":"mcm","clk":"5322279919","pt":1646318406075,"mc":[{"id":"1.195532859","rc":[{"atb":[[2.7,1.99]],"id":41288595}],"con":true,"img":false}]}
{"op":"mcm","clk":"5322279929","pt":1646318406180,"mc":[{"id":"1.195532859","rc":[{"atb":[[2.38,0]],"id":41288595},{"atb":[[2.26,0]],"id":38983972},{"atb":[[5.5,0]],"id":38324360}],"con":true,"img":false}]}
{"op":"mcm","clk":"5322279949","pt":1646318406402,"mc":[{"id":"1.195532859","rc":[{"atb":[[2.84,1.65]],"id":41288595},{"atb":[[2.52,1.65]],"id":38983972},{"atb":[[5.3,1.65]],"id":38324360},{"atb":[[2.26,1.65]],"id":40124755}],"con":true,"img":false}]}
{"op":"mcm","clk":"5322279966","pt":1646318406605,"mc":[{"id":"1.195532859","rc":[{"atb":[[2.14,35.09]],"id":38983972}],"con":true,"img":false}]}
{"op":"mcm","clk":"5322280072","pt":1646318407593,"mc":[{"id":"1.195532859","rc":[{"atl":[[4.3,26.74],[4.2,0]],"id":38357910}],"con":true,"img":false}]}
{"op":"mcm","clk":"5322280186","pt":1646318408796,"mc":[{"id":"1.195532859","rc":[{"atb":[[5.1,4],[4.9,22.42]],"id":38324360},{"atl":[[5.5,17.9]],"id":40124755}],"con":true,"img":false}]}
{"op":"mcm","clk":"5322280197","pt":1646318408898,"mc":[{"id":"1.195532859","rc":[{"atl":[[8,10],[7.2,14.4]],"id":41288595},{"atb":[[1.6,4.49],[1.51,10]],"id":39290878},{"atl":[[5.9,10]],"id":40124755}],"con":true,"img":false}]}
{"op":"mcm","clk":"5322280205","pt":1646318408960,"mc":[{"id":"1.195532859","rc":[{"atb":[[1.6,1.99]],"id":39290878}],"con":true,"img":false}]}
{"op":"mcm","clk":"5322280217","pt":1646318409068,"mc":[{"id":"1.195532859","rc":[{"atb":[[2.4,0]],"id":41288595},{"atb":[[2.2,0]],"id":38983972},{"atb":[[5.3,6.2]],"id":38324360},{"atb":[[1.58,73.97]],"id":39290878},{"atb":[[1.51,0]],"id":38357910},{"atb":[[1.84,0]],"id":40124755}],"con":true,"img":false}]}
{"op":"mcm","clk":"5322280227","pt":1646318409182,"mc":[{"id":"1.195532859","rc":[{"atb":[[1.6,4.49]],"id":39290878}],"con":true,"img":false}]}
{"op":"mcm","clk":"5322280241","pt":1646318409287,"mc":[{"id":"1.195532859","rc":[{"atb":[[1.58,68.97]],"id":39290878}],"con":true,"img":false}]}
{"op":"mcm","clk":"5322280291","pt":1646318409792,"mc":[{"id":"1.195532859","rc":[{"atb":[[5.2,0]],"id":38324360}],"con":true,"img":false}]}
{"op":"mcm","clk":"5322280301","pt":1646318409955,"mc":[{"id":"1.195532859","rc":[{"atb":[[5.4,1.99]],"id":38324360}],"con":true,"img":false}]}
{"op":"mcm","clk":"5322280452","pt":1646318411471,"mc":[{"id":"1.195532859","rc":[{"atb":[[1.61,3.97]],"id":39290878}],"con":true,"img":false}]}
{"op":"mcm","clk":"5322280461","pt":1646318411581,"mc":[{"id":"1.195532859","rc":[{"atb":[[1.68,2.15],[1.49,0]],"id":38357910},{"atb":[[2.26,3.8],[1.77,33.88]],"id":40124755}],"con":true,"img":false}]}
{"op":"mcm","clk":"5322280471","pt":1646318411680,"mc":[{"id":"1.195532859","rc":[{"atb":[[1.6,1.99],[1.62,3.98]],"id":39290878}],"con":true,"img":false}]}
{"op":"mcm","clk":"5322280478","pt":1646318411785,"mc":[{"id":"1.195532859","rc":[{"atb":[[1.68,6.64],[1.66,1.99]],"id":38357910}],"con":true,"img":false}]}
{"op":"mcm","clk":"5322280519","pt":1646318412305,"mc":[{"id":"1.195532859","rc":[{"atb":[[1.57,175.44]],"id":38357910},{"atl":[[4.5,33.57]],"id":38357910}],"con":true,"img":false}]}
{"op":"mcm","clk":"5322280554","pt":1646318412581,"mc":[{"id":"1.195532859","rc":[{"atb":[[1.6,0]],"id":39290878}],"con":true,"img":false}]}
{"op":"mcm","clk":"5322280565","pt":1646318412693,"mc":[{"id":"1.195532859","rc":[{"atb":[[1.63,1.99]],"id":39290878}],"con":true,"img":false}]}
{"op":"mcm","clk":"5322280575","pt":1646318412790,"mc":[{"id":"1.195532859","rc":[{"atl":[[4.3,12.12],[4.5,62.14]],"id":38357910}],"con":true,"img":false}]}
{"op":"mcm","clk":"5322280593","pt":1646318412998,"mc":[{"id":"1.195532859","rc":[{"atb":[[1.66,0]],"id":38357910}],"con":true,"img":false}]}
{"op":"mcm","clk":"5322280602","pt":1646318413093,"mc":[{"id":"1.195532859","rc":[{"atb":[[1.69,1.99]],"id":38357910}],"con":true,"img":false}]}
{"op":"mcm","clk":"5322280611","pt":1646318413213,"mc":[{"id":"1.195532859","rc":[{"atb":[[2.84,0]],"id":41288595},{"atb":[[5.3,4.54]],"id":38324360}],"con":true,"img":false}]}
{"op":"mcm","clk":"5322280628","pt":1646318413368,"mc":[{"id":"1.195532859","rc":[{"atb":[[2.72,1.65],[2.64,0],[2.56,14.4]],"id":41288595},{"atb":[[5.5,1.65]],"id":38324360}],"con":true,"img":false}]}
{"op":"mcm","clk":"5322280636","pt":1646318413471,"mc":[{"id":"1.195532859","rc":[{"atb":[[4.9,5.99]],"id":38324360},{"atb":[[2.24,0]],"id":40124755}],"con":true,"img":false}]}
{"op":"mcm","clk":"5322280643","pt":1646318413579,"mc":[{"id":"1.195532859","rc":[{"atb":[[2.28,1.99]],"id":40124755}],"con":true,"img":false}]}
{"op":"mcm","clk":"5322280752","pt":1646318414672,"mc":[{"id":"1.195532859","rc":[{"spn":2.69,"spf":1.0,"id":41288595},{"atb":[[1.69,0],[2.02,245.1]],"id":38983972},{"atl":[[6.6,27.86]],"id":38983972},{"spn":4.21,"spf":"NaN","id":38983972},{"spn":9.25,"spf":"NaN","id":38324360},{"spn":1.63,"spf":1.0,"id":39290878},{"spn":2.89,"spf":"NaN","id":38357910},{"atb":[[2.06,104.34]],"id":40124755},{"atl":[[5.5,40.12]],"id":40124755},{"spn":3.69,"spf":"NaN","id":40124755}],"con":true,"img":false}]}
{"op":"mcm","clk":"5322280759","pt":1646318414783,"mc":[{"id":"1.195532859","rc":[{"atb":[[2.64,60.98]],"id":41288595},{"atl":[[7.2,30.53]],"id":41288595},{"atb":[[1.58,0],[1.61,69.54]],"id":39290878}],"con":true,"img":false}]}
{"op":"mcm","clk":"5322280799","pt":1646318415197,"mc":[{"id":"1.195532859","rc":[{"atb":[[2.72,7.85]],"id":41288595},{"atb":[[2.54,3.3]],"id":38983972},{"atb":[[1.67,8.98]],"id":38357910},{"atb":[[2.28,5.29]],"id":40124755}],"con":true,"img":false}]}
{"op":"mcm","clk":"5322280958","pt":1646318417192,"mc":[{"id":"1.195532859","rc":[{"atb":[[5.3,0]],"id":38324360},{"atb":[[1.61,65.57]],"id":39290878}],"con":true,"img":false}]}
{"op":"mcm","clk":"5322281015","pt":1646318417807,"mc":[{"id":"1.195532859","rc":[{"atb":[[2.22,13.88],[1.77,0]],"id":40124755}],"con":true,"img":false}]}
{"op":"mcm","clk":"5322281024","pt":1646318417867,"mc":[{"id":"1.195532859","rc":[{"atl":[[3.25,26.59]],"id":39290878},{"atl":[[8.6,13.16],[5,6.82],[5.5,58.32]],"id":40124755}],"con":true,"img":false}]}
{"op":"mcm","clk":"5322281034","pt":1646318417976,"mc":[{"id":"1.195532859","rc":[{"atb":[[2.64,108.96],[2.26,0],[2.74,11.06]],"id":41288595},{"atl":[[7.2,63.54],[6.2,11.06],[15.5,6.9]],"id":41288595},{"atl":[[5.8,4.35],[12.5,8.69],[6.6,41.76]],"id":38983972},{"atb":[[4.9,18.49]],"id":38324360},{"atb":[[1.59,34.35],[1.24,0]],"id":39290878},{"atl":[[3.2,45.45],[3.05,70.47]],"id":39290878},{"atb":[[1.68,18.36],[1.48,0],[1.65,30.72]],"id":38357910},{"atl":[[4,11.72],[4.5,97.44],[6.8,17.24]],"id":38357910},{"atl":[[5.5,45.42],[4.9,6.82]],"id":40124755}],"con":true,"img":false}]}
{"op":"mcm","clk":"5322281043","pt":1646318418076,"mc":[{"id":"1.195532859","rc":[{"atl":[[7.2,54.14]],"id":41288595},{"atb":[[1.62,21.61]],"id":39290878},{"atl":[[3,54]],"id":39290878},{"atl":[[7.2,0]],"id":40124755}],"con":true,"img":false}]}
{"op":"mcm","clk":"5322281049","pt":1646318418184,"mc":[{"id":"1.195532859","rc":[{"atb":[[2.68,23.81]],"id":41288595},{"atl":[[9,0],[6,6.9]],"id":41288595},{"atl":[[5.7,4.35],[6.6,36.76],[8.4,0]],"id":38983972},{"atb":[[1.29,0]],"id":39290878},{"atl":[[3.1,6],[3.05,115.92]],"id":39290878},{"atb":[[1.65,22.06]],"id":38357910},{"atl":[[5.9,0]],"id":38357910}],"con":true,"img":false}]}
{"op":"mcm","clk":"5322281058","pt":1646318418288,"mc":[{"id":"1.195532859","rc":[{"atl":[[3,4]],"id":39290878},{"atl":[[5.4,3.33]],"id":40124755}],"con":true,"img":false}]}
{"op":"mcm","clk":"5322281068","pt":1646318418394,"mc":[{"id":"1.195532859","rc":[{"atl":[[6,0],[6.8,20.46]],"id":41288595},{"atl":[[6.2,17.69],[5.7,0]],"id":38983972}],"con":true,"img":false}]}
{"op":"mcm","clk":"5322281074","pt":1646318418493,"mc":[{"id":"1.195532859","rc":[{"atl":[[3.25,9]],"id":39290878}],"con":true,"img":false}]}
{"op":"mcm","clk":"5322281089","pt":1646318418609,"mc":[{"id":"1.195532859","rc":[{"atl":[[6.4,20.46],[6.8,6.9]],"id":41288595},{"atl":[[6.2,7.69],[5.9,11.2]],"id":38983972}],"con":true,"img":false}]}
{"op":"mcm","clk":"5322281111","pt":1646318418809,"mc":[{"id":"1.195532859","rc":[{"atb":[[1.9,0]],"id":41288595},{"atl":[[7.2,38.01],[6.8,0],[6.6,7.14]],"id":41288595},{"atb":[[1.71,0]],"id":38983972},{"atl":[[6.2,0],[6,8],[12.5,0],[13.5,0],[6.6,18.9],[14.5,0]],"id":38983972},{"atb":[[1.4,0],[1.42,0],[1.38,0]],"id":38357910},{"atl":[[4.3,0],[4.5,68.87],[4.2,12.5]],"id":38357910},{"atb":[[1.64,0],[1.7,0],[1.62,0]],"id":40124755},{"atl":[[5.1,12.26],[5.3,0],[9.4,0]],"id":40124755}],"con":true,"img":false}]}
{"op":"mcm","clk":"5322281156","pt":1646318419291,"mc":[{"id":"1.195532859","rc":[{"atl":[[5.4,0]],"id":40124755}],"con":true,"img":false}]}
{"op":"mcm","clk":"5322281195","pt":1646318419722,"mc":[{"id":"1.195532859","rc":[{"atb":[[1.67,0]],"id":38357910}],"con":true,"img":false}]}
{"op":"mcm","clk":"5322281235","pt":1646318420203,"mc":[{"id":"1.195532859","rc":[{"atb":[[2.72,6.19]],"id":41288595},{"atb":[[2.52,0]],"id":38983972},{"atb":[[2.26,2.15]],"id":40124755}],"con":true,"img":false}]}
{"op":"mcm","clk":"5322281257","pt":1646318420403,"mc":[{"id":"1.195532859","rc":[{"atb":[[2.76,1.65]],"id":41288595},{"atb":[[2.56,1.65]],"id":38983972},{"atb":[[2.3,1.65]],"id":40124755}],"con":true,"img":false}]}
{"op":"mcm","clk":"5322281303","pt":1646318420985,"mc":[{"id":"1.195532859","rc":[{"atl":[[4.2,26.72]],"id":38357910}],"con":true,"img":false}]}
{"op":"mcm","clk":"5322281315","pt":1646318421092,"mc":[{"id":"1.195532859","rc":[{"atl":[[4.5,40.3]],"id":38357910}],"con":true,"img":false}]}
{"op":"mcm","clk":"5322281406","pt":1646318422183,"mc":[{"id":"1.195532859","rc":[{"atb":[[1.54,0],[1.65,2.15]],"id":39290878}],"con":true,"img":false}]}
{"op":"mcm","clk":"5322281424","pt":1646318422390,"mc":[{"id":"1.195532859","rc":[{"atb":[[1.63,23.6],[1.62,17.63]],"id":39290878}],"con":true,"img":false}]}
{"op":"mcm","clk":"5322281491","pt":1646318423219,"mc":[{"id":"1.195532859","rc":[{"atl":[[5.1,25.9],[4.9,0]],"id":40124755}],"con":true,"img":false}]}
{"op":"mcm","clk":"5322281518","pt":1646318423486,"mc":[{"id":"1.195532859","rc":[{"atb":[[1.63,87.09],[1.61,0]],"id":39290878},{"atl":[[5.1,16.14],[5.2,9.52]],"id":40124755}],"con":true,"img":false}]}
{"op":"mcm","clk":"5322281538","pt":1646318423696,"mc":[{"id":"1.195532859","rc":[{"atl":[[6.4,2.5],[6.6,25]],"id":41288595},{"atl":[[6,23.55],[5.9,2.5]],"id":38983972}],"con":true,"img":false}]}
{"op":"mcm","clk":"5322281670","pt":1646318425108,"mc":[{"id":"1.195532859","rc":[{"atb":[[2.72,0]],"id":41288595},{"atb":[[2.54,0]],"id":38983972},{"atb":[[5.6,3.3]],"id":38324360},{"atb":[[1.64,3.97]],"id":39290878},{"atb":[[2.28,1.99]],"id":40124755}],"con":true,"img":false}]}
{"op":"mcm","clk":"5322281685","pt":1646318425308,"mc":[{"id":"1.195532859","rc":[{"atb":[[4.9,5.99]],"id":38324360}],"con":true,"img":false}]}
{"op":"mcm","clk":"5322281765","pt":1646318426196,"mc":[{"id":"1.195532859","rc":[{"atb":[[1.64,42.59]],"id":38357910}],"con":true,"img":false}]}
{"op":"mcm","clk":"5322281773","pt":1646318426303,"mc":[{"id":"1.195532859","rc":[{"atb":[[1.65,0]],"id":38357910}],"con":true,"img":false}]}
{"op":"mcm","clk":"5322281857","pt":1646318427198,"mc":[{"id":"1.195532859","rc":[{"atb":[[2.56,0]],"id":38983972},{"atb":[[5.5,0]],"id":38324360}],"con":true,"img":false}]}
{"op":"mcm","clk":"5322281866","pt":1646318427300,"mc":[{"id":"1.195532859","rc":[{"atb":[[1.66,5.96]],"id":38357910}],"con":true,"img":false}]}
{"op":"mcm","clk":"5322281880","pt":1646318427409,"mc":[{"id":"1.195532859","rc":[{"atb":[[2.32,21.86],[2.52,1.65]],"id":38983972},{"atb":[[4.9,20.99],[5.7,1.65]],"id":38324360}],"con":true,"img":false}]}
{"op":"mcm","clk":"5322281900","pt":1646318427609,"mc":[{"id":"1.195532859","rc":[{"atb":[[2.7,0]],"id":41288595},{"atb":[[2.32,10]],"id":38983972}],"con":true,"img":false}]}
{"op":"mcm","clk":"5322281910","pt":1646318427713,"mc":[{"id":"1.195532859","rc":[{"atb":[[2.76,3.64]],"id":41288595}],"con":true,"img":false}]}
{"op":"mcm","clk":"5322281917","pt":1646318427815,"mc":[{"id":"1.195532859","rc":[{"atb":[[5.4,0]],"id":38324360}],"con":true,"img":false}]}
{"op":"mcm","clk":"5322281927","pt":1646318427920,"mc":[{"id":"1.195532859","rc":[{"atb":[[2.76,20.23]],"id":41288595},{"atb":[[1.02,1.99]],"id":38324360}],"con":true,"img":false}]}
{"op":"mcm","clk":"5322281946","pt":1646318428123,"mc":[{"id":"1.195532859","rc":[{"atb":[[2.74,0]],"id":41288595},{"atb":[[1.63,85.1]],"id":39290878}],"con":true,"img":false}]}
{"op":"mcm","clk":"5322281956","pt":1646318428189,"mc":[{"id":"1.195532859","rc":[{"atb":[[1.66,1.99]],"id":39290878}],"con":true,"img":false}]}
{"op":"mcm","clk":"5322281964","pt":1646318428295,"mc":[{"id":"1.195532859","rc":[{"atl":[[5.1,2.5],[5.2,32.48]],"id":40124755}],"con":true,"img":false}]}
{"op":"mcm","clk":"5322282000","pt":1646318428807,"mc":[{"id":"1.195532859","rc":[{"atb":[[2.6,93.75]],"id":41288595},{"atl":[[7,16.67]],"id":41288595},{"atl":[[6.4,18.52],[6.6,22.11]],"id":38983972},{"atb":[[1.55,250]],"id":38357910},{"atl":[[4.4,29.41]],"id":38357910}],"con":true,"img":false}]}
{"op":"mcm","clk":"5322282016","pt":1646318429018,"mc":[{"id":"1.195532859","rc":[{"atl":[[6.6,18.9]],"id":38983972}],"con":true,"img":false}]}
{"op":"mcm","clk":"5322282161","pt":1646318430703,"mc":[{"id":"1.195532859","rc":[{"atb":[[1.92,0]],"id":41288595},{"atl":[[17.5,0]],"id":41288595},{"atb":[[1.64,66.47],[1.63,21.61]],"id":39290878},{"atl":[[7.6,0]],"id":38357910}],"con":true,"img":false}]}
{"op":"mcm","clk":"5322282183","pt":1646318430911,"mc":[{"id":"1.195532859","rc":[{"atb":[[2.76,3.64]],"id":41288595},{"atb":[[1.63,0],[1.66,4.14]],"id":39290878}],"con":true,"img":false}]}
{"op":"mcm","clk":"5322282193","pt":1646318431012,"mc":[{"id":"1.195532859","rc":[{"atb":[[1.64,62.5]],"id":39290878}],"con":true,"img":false}]}
{"op":"mcm","clk":"5322282202","pt":1646318431130,"mc":[{"id":"1.195532859","rc":[{"atb":[[2.78,3.3]],"id":41288595},{"atb":[[2.42,6.46]],"id":38983972},{"atb":[[1.66,1.99],[1.65,23.76]],"id":39290878},{"atb":[[2.32,3.3]],"id":40124755}],"con":true,"img":false}]}
{"op":"mcm","clk":"5322282228","pt":1646318431402,"mc":[{"id":"1.195532859","rc":[{"atb":[[2.64,60.98]],"id":41288595}],"con":true,"img":false}]}
{"op":"mcm","clk":"5322282247","pt":1646318431712,"mc":[{"id":"1.195532859","rc":[{"atb":[[2.76,1.65]],"id":41288595}],"con":true,"img":false}]}
{"op":"mcm","clk":"5322282258","pt":1646318431816,"mc":[{"id":"1.195532859","rc":[{"atb":[[2.8,1.99]],"id":41288595}],"con":true,"img":false}]}
{"op":"mcm","clk":"5322282286","pt":1646318432128,"mc":[{"id":"1.195532859","rc":[{"atb":[[2.28,0]],"id":40124755}],"con":true,"img":false}]}
{"op":"mcm","clk":"5322282295","pt":1646318432231,"mc":[{"id":"1.195532859","rc":[{"atb":[[2.34,1.99]],"id":40124755}],"con":true,"img":false}]}
{"op":"mcm","clk":"5322282418","pt":1646318433497,"mc":[{"id":"1.195532859","rc":[{"atb":[[2.02,147.06]],"id":40124755}],"con":true,"img":false}]}
{"op":"mcm","clk":"5322282473","pt":1646318434017,"mc":[{"id":"1.195532859","rc":[{"atb":[[5.6,0]],"id":38324360},{"atb":[[1.67,8.28]],"id":39290878}],"con":true,"img":false}]}
{"op":"mcm","clk":"5322282494","pt":1646318434226,"mc":[{"id":"1.195532859","rc":[{"atb":[[2.76,0]],"id":41288595},{"atb":[[2.3,0]],"id":40124755}],"con":true,"img":false}]}
{"op":"mcm","clk":"5322282509","pt":1646318434434,"mc":[{"id":"1.195532859","rc":[{"atb":[[2.82,1.65]],"id":41288595},{"atb":[[2.36,1.65]],"id":40124755}],"con":true,"img":false}]}
{"op":"mcm","clk":"5322282554","pt":1646318434906,"mc":[{"id":"1.195532859","rc":[{"atb":[[1.69,2.15],[1.65,21.61]],"id":39290878}],"con":true,"img":false}]}
{"op":"mcm","clk":"5322282565","pt":1646318435014,"mc":[{"id":"1.195532859","rc":[{"atb":[[1.62,3.93]],"id":38357910},{"atb":[[2.22,2.5],[2.26,10.84]],"id":40124755}],"con":true,"img":false}]}
{"op":"mcm","clk":"5322282578","pt":1646318435113,"mc":[{"id":"1.195532859","rc":[{"atl":[[5.5,27.22],[5.2,46.38],[4.9,4.35]],"id":40124755}],"con":true,"img":false}]}
{"op":"mcm","clk":"5322282589","pt":1646318435216,"mc":[{"id":"1.195532859","rc":[{"atl":[[7.2,5],[6.6,54.42]],"id":41288595},{"atl":[[6,39.55],[6.6,5]],"id":38983972},{"atb":[[1.64,0],[1.59,2.5],[1.67,67.98],[1.65,61.46]],"id":39290878},{"atb":[[1.62,0]],"id":38357910},{"atl":[[4.5,5],[4.2,86.25]],"id":38357910}],"con":true,"img":false}]}
{"op":"mcm","clk":"5322282598","pt":1646318435324,"mc":[{"id":"1.195532859","rc":[{"atb":[[1.75,9.21]],"id":39290878},{"atl":[[5,0]],"id":40124755}],"con":true,"img":false}]}
{"op":"mcm","clk":"5322282608","pt":1646318435425,"mc":[{"id":"1.195532859","rc":[{"atb":[[1.62,0]],"id":39290878}],"con":true,"img":false}]}
{"op":"mcm","clk":"5322282617","pt":1646318435524,"mc":[{"id":"1.195532859","rc":[{"atb":[[4.6,31.77],[4.9,6]],"id":38324360}],"con":true,"img":false}]}
{"op":"mcm","clk":"5322282630","pt":1646318435630,"mc":[{"id":"1.195532859","rc":[{"atb":[[1.65,96.37]],"id":39290878}],"con":true,"img":false}]}
{"op":"mcm","clk":"5322282644","pt":1646318435735,"mc":[{"id":"1.195532859","rc":[{"atb":[[1.02,0]],"id":38324360}],"con":true,"img":false}]}
{"op":"mcm","clk":"5322282654","pt":1646318435801,"mc":[{"id":"1.195532859","rc":[{"atb":[[5.2,1.99]],"id":38324360},{"atb":[[1.68,58.82],[1.67,8.28]],"id":39290878},{"atl":[[5.1,12.26],[5.2,36.86]],"id":40124755}],"con":true,"img":false}]}
{"op":"mcm","clk":"5322282673","pt":1646318436012,"mc":[{"id":"1.195532859","rc":[{"atb":[[1.66,0]],"id":39290878}],"con":true,"img":false}]}
{"op":"mcm","clk":"5322282683","pt":1646318436112,"mc":[{"id":"1.195532859","rc":[{"atb":[[1.76,1.99]],"id":39290878}],"con":true,"img":false}]}
{"op":"mcm","clk":"5322282735","pt":1646318436630,"mc":[{"id":"1.195532859","rc":[{"atl":[[4.4,34.06]],"id":38357910}],"con":true,"img":false}]}
{"op":"mcm","clk":"5322282748","pt":1646318436725,"mc":[{"id":"1.195532859","rc":[{"atl":[[6.8,3.57]],"id":41288595},{"atb":[[1.74,5.04]],"id":39290878}],"con":true,"img":false}]}
{"op":"mcm","clk":"5322282785","pt":1646318437112,"mc":[{"id":"1.195532859","rc":[{"atb":[[1.74,0]],"id":39290878}],"con":true,"img":false}]}
{"op":"mcm","clk":"5322282795","pt":1646318437247,"mc":[{"id":"1.195532859","rc":[{"atb":[[2.78,0]],"id":41288595},{"atb":[[2.42,0]],"id":38983972},{"atb":[[2.32,0]],"id":40124755}],"con":true,"img":false}]}
{"op":"mcm","clk":"5322282816","pt":1646318437415,"mc":[{"id":"1.195532859","rc":[{"atb":[[2.64,104.57]],"id":41288595}],"con":true,"img":false}]}
{"op":"mcm","clk":"5322282835","pt":1646318437624,"mc":[{"id":"1.195532859","rc":[{"atl":[[6.8,0]],"id":41288595},{"atb":[[4.8,5.31]],"id":38324360},{"atb":[[1.65,61.46]],"id":39290878},{"atl":[[4.4,29.41]],"id":38357910}],"con":true,"img":false}]}
{"op":"mcm","clk":"5322282871","pt":1646318438134,"mc":[{"id":"1.195532859","rc":[{"atb":[[2.8,0]],"id":41288595}],"con":true,"img":false}]}
{"op":"mcm","clk":"5322282883","pt":1646318438238,"mc":[{"id":"1.195532859","rc":[{"atb":[[2.7,1.99]],"id":41288595}],"con":true,"img":false}]}
{"op":"mcm","clk":"5322282904","pt":1646318438418,"mc":[{"id":"1.195532859","rc":[{"atb":[[2.34,0]],"id":40124755}],"con":true,"img":false}]}
{"op":"mcm","clk":"5322282915","pt":1646318438520,"mc":[{"id":"1.195532859","rc":[{"atb":[[2.28,1.99]],"id":40124755}],"con":true,"img":false}]}
{"op":"mcm","clk":"5322282925","pt":1646318438623,"mc":[{"id":"1.195532859","rc":[{"atb":[[2.26,22.23]],"id":40124755}],"con":true,"img":false}]}
{"op":"mcm","clk":"5322282933","pt":1646318438724,"mc":[{"id":"1.195532859","rc":[{"atb":[[2.2,0]],"id":40124755}],"con":true,"img":false}]}
{"op":"mcm","clk":"5322282943","pt":1646318438830,"mc":[{"id":"1.195532859","rc":[{"atb":[[2.56,174.66]],"id":41288595},{"atl":[[7.4,23.44]],"id":41288595},{"atl":[[6.8,25.86]],"id":38983972},{"atb":[[1.53,250]],"id":38357910},{"atl":[[4.6,41.67]],"id":38357910}],"con":true,"img":false}]}
{"op":"mcm","clk":"5322283014","pt":1646318439621,"mc":[{"id":"1.195532859","rc":[{"atb":[[4.8,0]],"id":38324360}],"con":true,"img":false}]}
{"op":"mcm","clk":"5322283039","pt":1646318439835,"mc":[{"id":"1.195532859","rc":[{"atb":[[5.3,5.36]],"id":38324360},{"atb":[[1.67,0]],"id":39290878}],"con":true,"img":false}]}
{"op":"mcm","clk":"5322283097","pt":1646318440416,"mc":[{"id":"1.195532859","rc":[{"atb":[[5.2,0]],"id":38324360}],"con":true,"img":false}]}
{"op":"mcm","clk":"5322283106","pt":1646318440520,"mc":[{"id":"1.195532859","rc":[{"atb":[[5.4,1.99]],"id":38324360}],"con":true,"img":false}]}
{"op":"mcm","clk":"5322283127","pt":1646318440726,"mc":[{"id":"1.195532859","rc":[{"atb":[[4.6,11.5]],"id":38324360}],"con":true,"img":false}]}
{"op":"mcm","clk":"5322283170","pt":1646318441239,"mc":[{"id":"1.195532859","rc":[{"atb":[[2.82,0]],"id":41288595},{"atb":[[5.7,0]],"id":38324360},{"atb":[[2.36,0]],"id":40124755}],"con":true,"img":false}]}
{"op":"mcm","clk":"5322283179","pt":1646318441343,"mc":[{"id":"1.195532859","rc":[{"atb":[[2.72,1.65]],"id":41288595},{"atb":[[5.5,1.65]],"id":38324360},{"atb":[[2.3,1.65]],"id":40124755}],"con":true,"img":false}]}
{"op":"mcm","clk":"5322283189","pt":1646318441413,"mc":[{"id":"1.195532859","rc":[{"atb":[[2.56,160.26],[2.5,69.17]],"id":41288595}],"con":true,"img":false}]}
{"op":"mcm","clk":"5322283218","pt":1646318441621,"mc":[{"id":"1.195532859","rc":[{"atb":[[2.2,8.22]],"id":40124755}],"con":true,"img":false}]}
{"op":"mcm","clk":"5322283236","pt":1646318441823,"mc":[{"id":"1.195532859","rc":[{"atb":[[2.2,0]],"id":40124755}],"con":true,"img":false}]}
{"op":"mcm","clk":"5322283315","pt":1646318442820,"mc":[{"id":"1.195532859","rc":[{"atb":[[2.72,7.44]],"id":41288595},{"atb":[[2.54,3.3]],"id":38983972},{"atb":[[2.3,6.61]],"id":40124755}],"con":true,"img":false}]}
{"op":"mcm","clk":"5322283336","pt":1646318443034,"mc":[{"id":"1.195532859","rc":[{"atb":[[2.22,26.09],[2.26,13.54]],"id":40124755}],"con":true,"img":false}]}
{"op":"mcm","clk":"5322283514","pt":1646318444847,"mc":[{"id":"1.195532859","rc":[{"atb":[[2.7,0]],"id":41288595}],"con":true,"img":false}]}
{"op":"mcm","clk":"5322283532","pt":1646318444911,"mc":[{"id":"1.195532859","rc":[{"atb":[[2.74,1.99]],"id":41288595}],"con":true,"img":false}]}
{"op":"mcm","clk":"5322283550","pt":1646318445127,"mc":[{"id":"1.195532859","rc":[{"atb":[[2.28,0]],"id":40124755}],"con":true,"img":false}]}
{"op":"mcm","clk":"5322283563","pt":1646318445226,"mc":[{"id":"1.195532859","rc":[{"atb":[[2.32,1.99]],"id":40124755}],"con":true,"img":false}]}
{"op":"mcm","clk":"5322283581","pt":1646318445428,"mc":[{"id":"1.195532859","rc":[{"atb":[[2.5,0]],"id":38983972}],"con":true,"img":false}]}
{"op":"mcm","clk":"5322283588","pt":1646318445530,"mc":[{"id":"1.195532859","rc":[{"atb":[[2.56,1.99]],"id":38983972},{"atb":[[1.78,2.15],[1.69,0]],"id":39290878}],"con":true,"img":false}]}
{"op":"mcm","clk":"5322283613","pt":1646318445843,"mc":[{"id":"1.195532859","rc":[{"atb":[[5.3,0]],"id":38324360},{"atb":[[1.7,7.46],[1.66,151.52]],"id":39290878},{"atb":[[1.99,250]],"id":40124755},{"atl":[[5.3,23.26]],"id":40124755}],"con":true,"img":false}]}
{"op":"mcm","clk":"5322283634","pt":1646318446046,"mc":[{"id":"1.195532859","rc":[{"atb":[[4.9,18.5]],"id":38324360}],"con":true,"img":false}]}
{"op":"mcm","clk":"5322283677","pt":1646318446523,"mc":[{"id":"1.195532859","rc":[{"atb":[[5.4,0]],"id":38324360}],"con":true,"img":false}]}
{"op":"mcm","clk":"5322283685","pt":1646318446630,"mc":[{"id":"1.195532859","rc":[{"atb":[[5.2,1.99]],"id":38324360}],"con":true,"img":false}]}
{"op":"mcm","clk":"5322283711","pt":1646318446943,"mc":[{"id":"1.195532859","rc":[{"atb":[[1.76,0]],"id":39290878}],"con":true,"img":false}]}
{"op":"mcm","clk":"5322283720","pt":1646318447048,"mc":[{"id":"1.195532859","rc":[{"atb":[[1.79,1.99]],"id":39290878}],"con":true,"img":false}]}
{"op":"mcm","clk":"5322283817","pt":1646318448246,"mc":[{"id":"1.195532859","rc":[{"atb":[[2.72,5.78]],"id":41288595},{"atb":[[2.54,0],[2.52,0]],"id":38983972},{"atb":[[5.5,0]],"id":38324360},{"atb":[[2.3,4.95]],"id":40124755}],"con":true,"img":false}]}
{"op":"mcm","clk":"5322283833","pt":1646318448451,"mc":[{"id":"1.195532859","rc":[{"atb":[[2.76,1.65]],"id":41288595},{"atb":[[2.32,21.86]],"id":38983972},{"atb":[[5.3,1.65]],"id":38324360},{"atb":[[2.34,1.65]],"id":40124755}],"con":true,"img":false}]}
{"op":"mcm","clk":"5322283846","pt":1646318448677,"mc":[{"id":"1.195532859","rc":[{"atb":[[2.64,60.98]],"id":41288595}],"con":true,"img":false}]}
{"op":"mcm","clk":"5322283862","pt":1646318448844,"mc":[{"id":"1.195532859","rc":[{"atb":[[1.94,0]],"id":41288595},{"atl":[[16.5,0],[7.8,36.76]],"id":41288595},{"atl":[[7.2,40.32]],"id":38983972},{"atl":[[4.8,65.79],[7.2,0]],"id":38357910}],"con":true,"img":false}]}
{"op":"mcm","clk":"5322283916","pt":1646318449454,"mc":[{"id":"1.195532859","rc":[{"atb":[[2.56,0]],"id":38983972}],"con":true,"img":false}]}
{"op":"mcm","clk":"5322283930","pt":1646318449559,"mc":[{"id":"1.195532859","rc":[{"atb":[[2.5,1.99]],"id":38983972}],"con":true,"img":false}]}
{"op":"mcm","clk":"5322284099","pt":1646318451251,"mc":[{"id":"1.195532859","rc":[{"atb":[[5.3,6.2]],"id":38324360},{"atb":[[1.7,0]],"id":39290878}],"con":true,"img":false}]}
{"op":"mcm","clk":"5322284159","pt":1646318451834,"mc":[{"id":"1.195532859","rc":[{"atb":[[2.22,2.5],[2.26,35.06]],"id":40124755}],"con":true,"img":false}]}
{"op":"mcm","clk":"5322284183","pt":1646318452035,"mc":[{"id":"1.195532859","rc":[{"atb":[[1.68,120.83],[1.65,21.61]],"id":39290878}],"con":true,"img":false}]}
{"op":"mcm","clk":"5322284198","pt":1646318452242,"mc":[{"id":"1.195532859","rc":[{"atb":[[5.2,0]],"id":38324360}],"con":true,"img":false}]}
{"op":"mcm","clk":"5322284211","pt":1646318452347,"mc":[{"id":"1.195532859","rc":[{"atb":[[5.4,1.99]],"id":38324360}],"con":true,"img":false}]}
{"op":"mcm","clk":"5322284338","pt":1646318453742,"mc":[{"id":"1.195532859","rc":[{"atb":[[2.72,0]],"id":41288595},{"atb":[[2.42,6.46]],"id":38983972},{"atb":[[2.3,0]],"id":40124755}],"con":true,"img":false}]}
{"op":"mcm","clk":"5322284384","pt":1646318454264,"mc":[{"id":"1.195532859","rc":[{"atb":[[2.64,104.57]],"id":41288595}],"con":true,"img":false}]}
{"op":"mcm","clk":"5322284432","pt":1646318454738,"mc":[{"id":"1.195532859","rc":[{"atb":[[2.74,0]],"id":41288595}],"con":true,"img":false}]}
{"op":"mcm","clk":"5322284441","pt":1646318454837,"mc":[{"id":"1.195532859","rc":[{"atb":[[2.7,1.99]],"id":41288595}],"con":true,"img":false}]}
{"op":"mcm","clk":"5322284468","pt":1646318455150,"mc":[{"id":"1.195532859","rc":[{"atb":[[2.32,0]],"id":40124755}],"con":true,"img":false}]}
{"op":"mcm","clk":"5322284477","pt":1646318455254,"mc":[{"id":"1.195532859","rc":[{"atb":[[2.76,0]],"id":41288595},{"atb":[[5.3,4.54]],"id":38324360},{"atb":[[2.28,1.99]],"id":40124755}],"con":true,"img":false}]}
{"op":"mcm","clk":"5322284498","pt":1646318455462,"mc":[{"id":"1.195532859","rc":[{"atb":[[2.72,1.65]],"id":41288595},{"atb":[[2.52,1.65]],"id":38983972},{"atb":[[5.5,1.65]],"id":38324360}],"con":true,"img":false}]}
{"op":"mcm","clk":"5322284520","pt":1646318455664,"mc":[{"id":"1.195532859","rc":[{"atb":[[2.32,10]],"id":38983972},{"atb":[[4.9,6]],"id":38324360}],"con":true,"img":false}]}
{"op":"mcm","clk":"5322284538","pt":1646318455835,"mc":[{"id":"1.195532859","rc":[{"atb":[[1.64,234.38],[1.21,0],[1.19,0],[1.23,0]],"id":39290878},{"atl":[[9,0],[5.5,38.33]],"id":40124755}],"con":true,"img":false}]}
{"op":"mcm","clk":"5322284594","pt":1646318456462,"mc":[{"id":"1.195532859","rc":[{"atb":[[1.76,5.96]],"id":39290878}],"con":true,"img":false}]}
{"op":"mcm","clk":"5322284626","pt":1646318456966,"mc":[{"id":"1.195532859","rc":[{"atb":[[2.28,14.45]],"id":40124755}],"con":true,"img":false}]}
{"op":"mcm","clk":"5322284644","pt":1646318457131,"mc":[{"id":"1.195532859","rc":[{"atb":[[2.26,23.67]],"id":40124755}],"con":true,"img":false}]}
{"op":"mcm","clk":"5322284710","pt":1646318458021,"mc":[{"id":"1.195532859","rc":[{"atl":[[15.5,0]],"id":41288595},{"atl":[[6.8,0]],"id":38357910}],"con":true,"img":false}]}
{"op":"mcm","clk":"5322284725","pt":1646318458223,"mc":[{"id":"1.195532859","rc":[{"atb":[[2.26,21.52],[2.34,3.8]],"id":40124755}],"con":true,"img":false}]}
{"op":"mcm","clk":"5322284778","pt":1646318458692,"mc":[{"id":"1.195532859","rc":[{"atb":[[2.28,12.46]],"id":40124755}],"con":true,"img":false}]}
{"op":"mcm","clk":"5322284788","pt":1646318458805,"mc":[{"id":"1.195532859","rc":[{"atb":[[2.36,1.99]],"id":40124755}],"con":true,"img":false}]}
{"op":"mcm","clk":"5322284902","pt":1646318459646,"mc":[{"id":"1.195532859","rc":[{"atb":[[2.42,0]],"id":38983972},{"atb":[[5.3,0]],"id":38324360}],"con":true,"img":false}]}
{"op":"mcm","clk":"5322284910","pt":1646318459711,"mc":[{"id":"1.195532859","rc":[{"atb":[[2.74,3.3]],"id":41288595},{"atb":[[2.36,5.29]],"id":40124755}],"con":true,"img":false}]}
{"op":"mcm","clk":"5322284951","pt":1646318459900,"mc":[{"id":"1.195532859","rc":[{"atb":[[4.9,18.5]],"id":38324360}],"con":true,"img":false}]}
{"op":"mcm","clk":"5322284969","pt":1646318459967,"mc":[{"id":"1.195532859","rc":[{"atb":[[2.64,60.98],[2.66,6.68]],"id":41288595},{"atb":[[2.28,34.4],[2.26,0]],"id":40124755}],"con":true,"img":false}]}
{"op":"mcm","clk":"5322284981","pt":1646318460020,"mc":[{"id":"1.195532859","rc":[{"atb":[[2.7,0]],"id":41288595}],"con":true,"img":false}]}
{"op":"mcm","clk":"5322284991","pt":1646318460119,"mc":[{"id":"1.195532859","rc":[{"atb":[[2.76,1.99]],"id":41288595}],"con":true,"img":false}]}
{"op":"mcm","clk":"5322285009","pt":1646318460231,"mc":[{"id":"1.195532859","rc":[{"atb":[[2.66,0]],"id":41288595}],"con":true,"img":false}]}
{"op":"mcm","clk":"5322285026","pt":1646318460338,"mc":[{"id":"1.195532859","rc":[{"atb":[[5.4,0]],"id":38324360}],"con":true,"img":false}]}
{"op":"mcm","clk":"5322285044","pt":1646318460439,"mc":[{"id":"1.195532859","rc":[{"atb":[[5.2,1.99]],"id":38324360}],"con":true,"img":false}]}
{"op":"mcm","clk":"5322285135","pt":1646318461246,"mc":[{"id":"1.195532859","rc":[{"atb":[[2.72,0]],"id":41288595},{"atb":[[5.5,0]],"id":38324360},{"atb":[[2.34,2.15]],"id":40124755}],"con":true,"img":false}]}
{"op":"mcm","clk":"5322285154","pt":1646318461406,"mc":[{"id":"1.195532859","rc":[{"atb":[[2.78,1.65]],"id":41288595},{"atb":[[5.3,1.65]],"id":38324360},{"atb":[[2.38,1.65]],"id":40124755}],"con":true,"img":false}]}
{"op":"mcm","clk":"5322285210","pt":1646318462026,"mc":[{"id":"1.195532859","rc":[{"atb":[[4.5,3.01]],"id":38324360}],"con":true,"img":false}]}
{"op":"mcm","clk":"5322285247","pt":1646318462443,"mc":[{"id":"1.195532859","rc":[{"atb":[[4.5,0]],"id":38324360}],"con":true,"img":false}]}
{"op":"mcm","clk":"5322285289","pt":1646318462822,"mc":[{"id":"1.195532859","rc":[{"atb":[[2.64,64.75]],"id":41288595},{"atb":[[4,0],[5.3,7.65],[5.2,5.99]],"id":38324360},{"atl":[[19.5,0],[13,10],[15,32.25]],"id":38324360},{"atb":[[1.78,9.63]],"id":39290878},{"atl":[[3.05,121.6]],"id":39290878},{"atb":[[2.28,0]],"id":40124755}],"con":true,"img":false}]}
{"op":"mcm","clk":"5322285305","pt":1646318463017,"mc":[{"id":"1.195532859","rc":[{"atb":[[2.64,60.98]],"id":41288595},{"atb":[[1.75,0]],"id":39290878},{"atl":[[3.05,115.92]],"id":39290878}],"con":true,"img":false}]}
{"op":"mcm","clk":"5322285315","pt":1646318463125,"mc":[{"id":"1.195532859","rc":[{"atb":[[5.1,24.93],[4.9,6]],"id":38324360}],"con":true,"img":false}]}
{"op":"mcm","clk":"5322285355","pt":1646318463538,"mc":[{"id":"1.195532859","rc":[{"atb":[[5.2,4]],"id":38324360}],"con":true,"img":false}]}
{"op":"mcm","clk":"5322285370","pt":1646318463642,"mc":[{"id":"1.195532859","rc":[{"atb":[[5.4,1.99]],"id":38324360}],"con":true,"img":false}]}
{"op":"mcm","clk":"5322285476","pt":1646318464954,"mc":[{"id":"1.195532859","rc":[{"atb":[[2.74,0]],"id":41288595},{"atb":[[2.36,1.99]],"id":40124755}],"con":true,"img":false}]}
{"op":"mcm","clk":"5322285483","pt":1646318465051,"mc":[{"id":"1.195532859","rc":[{"atb":[[2.54,3.3]],"id":38983972},{"atb":[[5.4,5.29]],"id":38324360}],"con":true,"img":false}]}
{"op":"mcm","clk":"5322285556","pt":1646318465849,"mc":[{"id":"1.195532859","rc":[{"atb":[[1.62,250]],"id":39290878},{"atl":[[5.7,53.19]],"id":40124755}],"con":true,"img":false}]}
{"op":"mcm","clk":"5322285572","pt":1646318466025,"mc":[{"id":"1.195532859","rc":[{"atb":[[2.76,0]],"id":41288595}],"con":true,"img":false}]}
{"op":"mcm","clk":"5322285582","pt":1646318466126,"mc":[{"id":"1.195532859","rc":[{"atb":[[2.7,1.99]],"id":41288595}],"con":true,"img":false}]}
{"op":"mcm","clk":"5322285587","pt":1646318466228,"mc":[{"id":"1.195532859","rc":[{"atb":[[2.24,2.5],[2.06,94.34],[2.22,0],[2.14,10]],"id":40124755}],"con":true,"img":false}]}
{"op":"mcm","clk":"5322285603","pt":1646318466433,"mc":[{"id":"1.195532859","rc":[{"atl":[[8,0],[5.8,2.5]],"id":41288595},{"atb":[[2.5,0]],"id":38983972},{"atb":[[1.59,0],[1.55,0],[1.51,0]],"id":39290878},{"atb":[[1.64,40.09],[1.56,0],[1.6,0],[1.67,2.5]],"id":38357910}],"con":true,"img":false}]}
{"op":"mcm","clk":"5322285611","pt":1646318466537,"mc":[{"id":"1.195532859","rc":[{"atl":[[5.6,10.17]],"id":41288595},{"atb":[[2.56,1.99]],"id":38983972}],"con":true,"img":false}]}
{"op":"mcm","clk":"5322285619","pt":1646318466639,"mc":[{"id":"1.195532859","rc":[{"atl":[[6.4,31.92],[6.2,0],[6.6,7.14]],"id":41288595},{"atb":[[1.64,0],[1.66,28.07]],"id":38357910}],"con":true,"img":false}]}
{"op":"mcm","clk":"5322285627","pt":1646318466743,"mc":[{"id":"1.195532859","rc":[{"atl":[[6.2,11.06]],"id":41288595}],"con":true,"img":false}]}
{"op":"mcm","clk":"5322285635","pt":1646318466840,"mc":[{"id":"1.195532859","rc":[{"atl":[[6.4,48.59]],"id":41288595}],"con":true,"img":false}]}
{"op":"mcm","clk":"5322285641","pt":1646318466946,"mc":[{"id":"1.195532859","rc":[{"atl":[[6.2,0]],"id":41288595}],"con":true,"img":false}]}
{"op":"mcm","clk":"5322285664","pt":1646318467223,"mc":[{"id":"1.195532859","rc":[{"atb":[[2.78,0]],"id":41288595},{"atb":[[2.52,0]],"id":38983972},{"atb":[[5.3,6]],"id":38324360}],"con":true,"img":false}]}
{"op":"mcm","clk":"5322285678","pt":1646318467424,"mc":[{"id":"1.195532859","rc":[{"atb":[[2.72,1.65]],"id":41288595},{"atb":[[5.5,1.65]],"id":38324360}],"con":true,"img":false}]}
{"op":"mcm","clk":"5322285752","pt":1646318468313,"mc":[{"id":"1.195532859","rc":[{"atb":[[2.24,12.5]],"id":40124755}],"con":true,"img":false}]}
{"op":"mcm","clk":"5322285773","pt":1646318468524,"mc":[{"id":"1.195532859","rc":[{"atb":[[2.34,0]],"id":40124755}],"con":true,"img":false}]}
{"op":"mcm","clk":"5322285784","pt":1646318468621,"mc":[{"id":"1.195532859","rc":[{"atb":[[2.2,2.15]],"id":40124755}],"con":true,"img":false}]}
{"op":"mcm","clk":"5322285800","pt":1646318468844,"mc":[{"id":"1.195532859","rc":[{"atb":[[1.66,22.11]],"id":38357910},{"atb":[[2.36,0]],"id":40124755}],"con":true,"img":false}]}
{"op":"mcm","clk":"5322285806","pt":1646318468934,"mc":[{"id":"1.195532859","rc":[{"atb":[[2.26,1.99]],"id":40124755}],"con":true,"img":false}]}
{"op":"mcm","clk":"5322285817","pt":1646318469040,"mc":[{"id":"1.195532859","rc":[{"atb":[[2.26,14.45]],"id":40124755}],"con":true,"img":false}]}
{"op":"mcm","clk":"5322285897","pt":1646318470046,"mc":[{"id":"1.195532859","rc":[{"atl":[[5.8,10.83],[6.6,0]],"id":41288595},{"atl":[[8.6,0]],"id":40124755}],"con":true,"img":false}]}
{"op":"mcm","clk":"5322285945","pt":1646318470566,"mc":[{"id":"1.195532859","rc":[{"atl":[[2.96,11.7]],"id":39290878}],"con":true,"img":false}]}
{"op":"mcm","clk":"5322286015","pt":1646318470733,"mc":[{"id":"1.195532859","rc":[{"atl":[[3,60.74],[2.98,0],[3.05,64.96]],"id":39290878}],"con":true,"img":false}]}
{"op":"mcm","clk":"5322286034","pt":1646318470934,"mc":[{"id":"1.195532859","rc":[{"atl":[[3,50.64]],"id":39290878}],"con":true,"img":false}]}
{"op":"mcm","clk":"5322286096","pt":1646318471518,"mc":[{"id":"1.195532859","rc":[{"atb":[[1.66,26.83]],"id":38357910}],"con":true,"img":false}]}
{"op":"mcm","clk":"5322286108","pt":1646318471621,"mc":[{"id":"1.195532859","rc":[{"atb":[[1.66,22.11]],"id":38357910}],"con":true,"img":false}]}
{"op":"mcm","clk":"5322286190","pt":1646318472354,"mc":[{"id":"1.195532859","rc":[{"atb":[[2.74,3.3]],"id":41288595},{"atb":[[2.54,0]],"id":38983972},{"atb":[[5.4,1.99]],"id":38324360},{"atb":[[2.26,20.64]],"id":40124755}],"con":true,"img":false}]}
{"op":"mcm","clk":"5322286206","pt":1646318472550,"mc":[{"id":"1.195532859","rc":[{"atb":[[2.32,21.86]],"id":38983972}],"con":true,"img":false}]}
{"op":"mcm","clk":"5322286220","pt":1646318472617,"mc":[{"id":"1.195532859","rc":[{"atb":[[2.7,0]],"id":41288595}],"con":true,"img":false}]}
{"op":"mcm","clk":"5322286229","pt":1646318472752,"mc":[{"id":"1.195532859","rc":[{"atb":[[2.76,1.99]],"id":41288595}],"con":true,"img":false}]}
{"op":"mcm","clk":"5322286252","pt":1646318472938,"mc":[{"id":"1.195532859","rc":[{"atb":[[2.56,0]],"id":38983972}],"con":true,"img":false}]}
{"op":"mcm","clk":"5322286263","pt":1646318473037,"mc":[{"id":"1.195532859","rc":[{"atb":[[2.5,1.99]],"id":38983972}],"con":true,"img":false}]}
{"op":"mcm","clk":"5322286368","pt":1646318474128,"mc":[{"id":"1.195532859","rc":[{"atb":[[2.72,0]],"id":41288595},{"atb":[[1.76,0]],"id":39290878},{"atb":[[2.38,0]],"id":40124755}],"con":true,"img":false}]}
{"op":"mcm","clk":"5322286377","pt":1646318474223,"mc":[{"id":"1.195532859","rc":[{"atb":[[1.68,58.82],[1.66,296.02]],"id":39290878}],"con":true,"img":false}]}
{"op":"mcm","clk":"5322286389","pt":1646318474337,"mc":[{"id":"1.195532859","rc":[{"atb":[[2.78,1.65]],"id":41288595},{"atb":[[2.52,1.65]],"id":38983972},{"atb":[[2.28,1.65]],"id":40124755}],"con":true,"img":false}]}
{"op":"mcm","clk":"5322286403","pt":1646318474546,"mc":[{"id":"1.195532859","rc":[{"atb":[[2.32,10]],"id":38983972}],"con":true,"img":false}]}
{"op":"mcm","clk":"5322286540","pt":1646318475857,"mc":[{"id":"1.195532859","rc":[{"spn":2.73,"spf":1.0,"id":41288595},{"spn":4.16,"spf":"NaN","id":38983972},{"atl":[[3,70.64],[3.05,45.45]],"id":39290878},{"spn":1.79,"spf":1.0,"id":39290878},{"spn":2.84,"spf":"NaN","id":38357910},{"spn":3.59,"spf":"NaN","id":40124755}],"con":true,"img":false}]}
{"op":"mcm","clk":"5322286563","pt":1646318476059,"mc":[{"id":"1.195532859","rc":[{"atb":[[2.24,2.5],[2.2,33.1]],"id":40124755}],"con":true,"img":false}]}
{"op":"mcm","clk":"5322286585","pt":1646318476220,"mc":[{"id":"1.195532859","rc":[{"atb":[[5.1,4],[5.2,22.85]],"id":38324360}],"con":true,"img":false}]}
{"op":"mcm","clk":"5322286723","pt":1646318477535,"mc":[{"id":"1.195532859","rc":[{"atb":[[2.74,0]],"id":41288595},{"atb":[[2.42,6.46]],"id":38983972},{"atb":[[5.6,3.3]],"id":38324360},{"atb":[[1.7,3.97]],"id":38357910}],"con":true,"img":false}]}
{"op":"mcm","clk":"5322286734","pt":1646318477633,"mc":[{"id":"1.195532859","rc":[{"atb":[[1.7,15.75],[1.71,3.98]],"id":38357910}],"con":true,"img":false}]}
{"op":"mcm","clk":"5322286751","pt":1646318477747,"mc":[{"id":"1.195532859","rc":[{"atb":[[1.7,19.73],[1.68,13.87]],"id":38357910}],"con":true,"img":false}]}
{"op":"mcm","clk":"5322286760","pt":1646318477843,"mc":[{"id":"1.195532859","rc":[{"atb":[[1.68,2.15],[1.71,0]],"id":38357910}],"con":true,"img":false}]}
{"op":"mcm","clk":"5322286773","pt":1646318477951,"mc":[{"id":"1.195532859","rc":[{"atb":[[1.66,34.85]],"id":38357910}],"con":true,"img":false}]}
{"op":"mcm","clk":"5322286825","pt":1646318478370,"mc":[{"id":"1.195532859","rc":[{"atl":[[3,24],[3.05,137.53]],"id":39290878},{"atb":[[1.66,22.11]],"id":38357910}],"con":true,"img":false}]}
{"op":"mcm","clk":"5322286886","pt":1646318479041,"mc":[{"id":"1.195532859","rc":[{"atl":[[16.5,4.21]],"id":38324360}],"con":true,"img":false}]}
{"op":"mcm","clk":"5322286896","pt":1646318479145,"mc":[{"id":"1.195532859","rc":[{"atb":[[5.7,9.28]],"id":38324360},{"atb":[[1.73,2.15],[1.68,0]],"id":38357910},{"atb":[[2.32,2.15],[2.2,30.95]],"id":40124755}],"con":true,"img":false}]}
{"op":"mcm","clk":"5322286906","pt":1646318479257,"mc":[{"id":"1.195532859","rc":[{"atb":[[2.76,0]],"id":41288595},{"atb":[[5.3,0]],"id":38324360},{"atl":[[16.5,0]],"id":38324360}],"con":true,"img":false}]}
{"op":"mcm","clk":"5322286916","pt":1646318479354,"mc":[{"id":"1.195532859","rc":[{"atb":[[2.7,1.99]],"id":41288595},{"atb":[[1.69,19.75]],"id":39290878},{"atb":[[1.69,16.23]],"id":38357910},{"atb":[[2.24,23.26],[2.22,6.25],[2.28,17.26],[2.2,0]],"id":40124755}],"con":true,"img":false}]}
{"op":"mcm","clk":"5322286924","pt":1646318479455,"mc":[{"id":"1.195532859","rc":[{"atb":[[2.6,186.33]],"id":41288595},{"atb":[[5.4,24.94]],"id":38324360}],"con":true,"img":false}]}
{"op":"mcm","clk":"5322286935","pt":1646318479564,"mc":[{"id":"1.195532859","rc":[{"atb":[[5.4,22.95],[5.2,3.99]],"id":38324360},{"atb":[[2.22,0]],"id":40124755}],"con":true,"img":false}]}
{"op":"mcm","clk":"5322286948","pt":1646318479660,"mc":[{"id":"1.195532859","rc":[{"atb":[[2.6,93.75]],"id":41288595},{"atb":[[5.3,4.54],[1.02,1.99]],"id":38324360}],"con":true,"img":false}]}
{"op":"mcm","clk":"5322286969","pt":1646318479828,"mc":[{"id":"1.195532859","rc":[{"atb":[[1.69,29.2]],"id":39290878},{"atb":[[1.69,14.24]],"id":38357910}],"con":true,"img":false}]}
{"op":"mcm","clk":"5322286982","pt":1646318479925,"mc":[{"id":"1.195532859","rc":[{"atb":[[5.3,0]],"id":38324360},{"atb":[[1.71,1.99]],"id":38357910}],"con":true,"img":false}]}
{"op":"mcm","clk":"5322286992","pt":1646318480028,"mc":[{"id":"1.195532859","rc":[{"atl":[[6,20]],"id":41288595}],"con":true,"img":false}]}
{"op":"mcm","clk":"5322287001","pt":1646318480133,"mc":[{"id":"1.195532859","rc":[{"atl":[[6.4,31.92]],"id":41288595}],"con":true,"img":false}]}
{"op":"mcm","clk":"5322287012","pt":1646318480238,"mc":[{"id":"1.195532859","rc":[{"atl":[[5.9,20.41]],"id":41288595}],"con":true,"img":false}]}
{"op":"mcm","clk":"5322287118","pt":1646318481244,"mc":[{"id":"1.195532859","rc":[{"atb":[[2.78,0]],"id":41288595},{"atb":[[5.5,0]],"id":38324360},{"atb":[[1.71,0]],"id":38357910},{"atb":[[2.28,15.61]],"id":40124755}],"con":true,"img":false}]}
{"op":"mcm","clk":"5322287131","pt":1646318481344,"mc":[{"id":"1.195532859","rc":[{"atb":[[2.72,1.65]],"id":41288595},{"atb":[[5.8,1.65]],"id":38324360},{"atb":[[1.74,1.99]],"id":38357910},{"atb":[[2.34,1.65]],"id":40124755}],"con":true,"img":false}]}
{"op":"mcm","clk":"5322287143","pt":1646318481458,"mc":[{"id":"1.195532859","rc":[{"atb":[[1.69,0]],"id":38357910},{"atb":[[2.26,18.65]],"id":40124755}],"con":true,"img":false}]}
{"op":"mcm","clk":"5322287155","pt":1646318481557,"mc":[{"id":"1.195532859","rc":[{"atb":[[2.34,3.64]],"id":40124755}],"con":true,"img":false}]}
{"op":"mcm","clk":"5322287193","pt":1646318481865,"mc":[{"id":"1.195532859","rc":[{"atb":[[2.24,2.5]],"id":40124755}],"con":true,"img":false}]}
{"op":"mcm","clk":"5322287260","pt":1646318482543,"mc":[{"id":"1.195532859","rc":[{"atl":[[5.6,0]],"id":41288595}],"con":true,"img":false}]}
{"op":"mcm","clk":"5322287275","pt":1646318482648,"mc":[{"id":"1.195532859","rc":[{"atl":[[5.7,15.75]],"id":41288595}],"con":true,"img":false}]}
{"op":"mcm","clk":"5322287286","pt":1646318482761,"mc":[{"id":"1.195532859","rc":[{"atl":[[5.8,2.5],[6.2,5],[7.4,0],[6,8],[7,0],[7.8,0]],"id":41288595}],"con":true,"img":false}]}
{"op":"mcm","clk":"5322287298","pt":1646318482857,"mc":[{"id":"1.195532859","rc":[{"atl":[[6.4,2.5],[5.9,68.55]],"id":41288595},{"atb":[[1.67,22.32]],"id":38357910}],"con":true,"img":false}]}
{"op":"mcm","clk":"5322287313","pt":1646318482973,"mc":[{"id":"1.195532859","rc":[{"atb":[[2.42,0]],"id":38983972},{"atb":[[5.6,0]],"id":38324360},{"atb":[[1.7,15.76],[1.66,0]],"id":38357910},{"atb":[[2.26,12.46]],"id":40124755}],"con":true,"img":false}]}
{"op":"mcm","clk":"5322287325","pt":1646318483068,"mc":[{"id":"1.195532859","rc":[{"atb":[[2.72,6.61]],"id":41288595}],"con":true,"img":false}]}
{"op":"mcm","clk":"5322287337","pt":1646318483168,"mc":[{"id":"1.195532859","rc":[{"atl":[[6.2,0]],"id":41288595}],"con":true,"img":false}]}
{"op":"mcm","clk":"5322287351","pt":1646318483268,"mc":[{"id":"1.195532859","rc":[{"atb":[[2.28,0]],"id":40124755}],"con":true,"img":false}]}
{"op":"mcm","clk":"5322287370","pt":1646318483435,"mc":[{"id":"1.195532859","rc":[{"atb":[[2.7,0]],"id":41288595}],"con":true,"img":false}]}
{"op":"mcm","clk":"5322287389","pt":1646318483545,"mc":[{"id":"1.195532859","rc":[{"atb":[[2.74,1.99]],"id":41288595}],"con":true,"img":false}]}
{"op":"mcm","clk":"5322287414","pt":1646318483854,"mc":[{"id":"1.195532859","rc":[{"atb":[[5.4,0],[5.2,30.17]],"id":38324360}],"con":true,"img":false}]}
{"op":"mcm","clk":"5322287477","pt":1646318484538,"mc":[{"id":"1.195532859","rc":[{"atb":[[2.26,33.22]],"id":40124755}],"con":true,"img":false}]}
{"op":"mcm","clk":"5322287548","pt":1646318485252,"mc":[{"id":"1.195532859","rc":[{"atb":[[1.74,4.14],[1.7,11.78],[1.68,5.38]],"id":38357910}],"con":true,"img":false}]}
{"op":"mcm","clk":"5322287554","pt":1646318485348,"mc":[{"id":"1.195532859","rc":[{"atb":[[1.73,17.91],[1.74,1.99]],"id":38357910}],"con":true,"img":false}]}
{"op":"mcm","clk":"5322287598","pt":1646318485869,"mc":[{"id":"1.195532859","rc":[{"atl":[[3.1,53.62]],"id":39290878}],"con":true,"img":false}]}
{"op":"mcm","clk":"5322287610","pt":1646318485975,"mc":[{"id":"1.195532859","rc":[{"atb":[[1.73,10.09]],"id":39290878}],"con":true,"img":false}]}
{"op":"mcm","clk":"5322287647","pt":1646318486245,"mc":[{"id":"1.195532859","rc":[{"atb":[[1.73,0],[1.66,303.76]],"id":39290878}],"con":true,"img":false}]}
{"op":"mcm","clk":"5322287704","pt":1646318486776,"mc":[{"id":"1.195532859","rc":[{"atb":[[1.66,296.02]],"id":39290878},{"atl":[[2.94,16]],"id":39290878}],"con":true,"img":false}]}
{"op":"mcm","clk":"5322287728","pt":1646318486983,"mc":[{"id":"1.195532859","rc":[{"atb":[[5.1,30.17]],"id":38324360},{"atl":[[3,104],[3.05,45.45],[2.96,0]],"id":39290878}],"con":true,"img":false}]}
{"op":"mcm","clk":"5322287732","pt":1646318487078,"mc":[{"id":"1.195532859","rc":[{"atb":[[5.2,4]],"id":38324360}],"con":true,"img":false}]}
{"op":"mcm","clk":"5322287745","pt":1646318487182,"mc":[{"id":"1.195532859","rc":[{"atb":[[2.28,4.01]],"id":40124755}],"con":true,"img":false}]}
{"op":"mcm","clk":"5322287766","pt":1646318487353,"mc":[{"id":"1.195532859","rc":[{"atb":[[2.26,12.46]],"id":40124755}],"con":true,"img":false}]}
{"op":"mcm","clk":"5322287781","pt":1646318487459,"mc":[{"id":"1.195532859","rc":[{"atb":[[1.7,18.6]],"id":39290878},{"atb":[[1.71,4.55]],"id":38357910},{"atb":[[2.28,8.02]],"id":40124755}],"con":true,"img":false}]}
{"op":"mcm","clk":"5322287857","pt":1646318488182,"mc":[{"id":"1.195532859","rc":[{"atb":[[2.72,4.95]],"id":41288595}],"con":true,"img":false}]}
{"op":"mcm","clk":"5322287877","pt":1646318488345,"mc":[{"id":"1.195532859","rc":[{"atb":[[2.76,1.65]],"id":41288595}],"con":true,"img":false}]}
{"op":"mcm","clk":"5322287913","pt":1646318488653,"mc":[{"id":"1.195532859","rc":[{"atb":[[2.4,15]],"id":38983972}],"con":true,"img":false}]}
{"op":"mcm","clk":"5322287948","pt":1646318488963,"mc":[{"id":"1.195532859","rc":[{"atb":[[2.54,3.3]],"id":38983972},{"atb":[[5.9,3.3]],"id":38324360},{"atb":[[1.71,10.51]],"id":38357910},{"atb":[[2.28,18.97]],"id":40124755}],"con":true,"img":false}]}
{"op":"mcm","clk":"5322287971","pt":1646318489156,"mc":[{"id":"1.195532859","rc":[{"atb":[[2.4,5]],"id":38983972}],"con":true,"img":false}]}
{"op":"mcm","clk":"5322288024","pt":1646318489669,"mc":[{"id":"1.195532859","rc":[{"atb":[[2.5,0]],"id":38983972}],"con":true,"img":false}]}
{"op":"mcm","clk":"5322288035","pt":1646318489775,"mc":[{"id":"1.195532859","rc":[{"atb":[[2.56,1.99]],"id":38983972}],"con":true,"img":false}]}
{"op":"mcm","clk":"5322288091","pt":1646318490294,"mc":[{"id":"1.195532859","rc":[{"atb":[[1.69,88.96]],"id":39290878}],"con":true,"img":false}]}
{"op":"mcm","clk":"5322288102","pt":1646318490356,"mc":[{"id":"1.195532859","rc":[{"atb":[[1.66,151.52]],"id":39290878}],"con":true,"img":false}]}
{"op":"mcm","clk":"5322288153","pt":1646318490874,"mc":[{"id":"1.195532859","rc":[{"atb":[[2.72,0]],"id":41288595},{"atb":[[1.69,79.51]],"id":39290878}],"con":true,"img":false}]}
{"op":"mcm","clk":"5322288163","pt":1646318490970,"mc":[{"id":"1.195532859","rc":[{"atb":[[1.69,59.76]],"id":39290878},{"atb":[[1.68,0]],"id":38357910}],"con":true,"img":false}]}
{"op":"mcm","clk":"5322288256","pt":1646318491964,"mc":[{"id":"1.195532859","rc":[{"atb":[[2.74,0]],"id":41288595}],"con":true,"img":false}]}
{"op":"mcm","clk":"5322288266","pt":1646318492067,"mc":[{"id":"1.195532859","rc":[{"atb":[[2.7,1.99]],"id":41288595}],"con":true,"img":false}]}
{"op":"mcm","clk":"5322288288","pt":1646318492277,"mc":[{"id":"1.195532859","rc":[{"atb":[[5.1,4],[5.2,27.85]],"id":38324360}],"con":true,"img":false}]}
{"op":"mcm","clk":"5322288341","pt":1646318492790,"mc":[{"id":"1.195532859","rc":[{"atl":[[5.9,76.71]],"id":41288595}],"con":true,"img":false}]}
{"op":"mcm","clk":"5322288389","pt":1646318493272,"mc":[{"id":"1.195532859","rc":[{"atb":[[2.54,0]],"id":38983972}],"con":true,"img":false}]}
{"op":"mcm","clk":"5322288421","pt":1646318493683,"mc":[{"id":"1.195532859","rc":[{"atb":[[1.73,34.59]],"id":38357910}],"con":true,"img":false}]}
{"op":"mcm","clk":"5322288443","pt":1646318493895,"mc":[{"id":"1.195532859","rc":[{"atb":[[1.7,0]],"id":38357910}],"con":true,"img":false}]}
{"op":"mcm","clk":"5322288497","pt":1646318494361,"mc":[{"id":"1.195532859","rc":[{"atb":[[2.56,0]],"id":38983972}],"con":true,"img":false}]}
{"op":"mcm","clk":"5322288508","pt":1646318494469,"mc":[{"id":"1.195532859","rc":[{"atb":[[2.54,1.99]],"id":38983972},{"atl":[[3,24],[3.05,141.3]],"id":39290878}],"con":true,"img":false}]}
{"op":"mcm","clk":"5322288563","pt":1646318495096,"mc":[{"id":"1.195532859","rc":[{"atb":[[6,13.77]],"id":38324360}],"con":true,"img":false}]}
{"op":"mcm","clk":"5322288574","pt":1646318495188,"mc":[{"id":"1.195532859","rc":[{"atb":[[2.76,0]],"id":41288595},{"atb":[[2.52,0]],"id":38983972},{"atb":[[5.8,0]],"id":38324360},{"atb":[[1.71,17.44]],"id":39290878},{"atb":[[1.74,15.91]],"id":38357910}],"con":true,"img":false}]}
{"op":"mcm","clk":"5322288585","pt":1646318495294,"mc":[{"id":"1.195532859","rc":[{"atb":[[5.7,0]],"id":38324360},{"atb":[[2.28,39.73]],"id":40124755}],"con":true,"img":false}]}
{"op":"mcm","clk":"5322288595","pt":1646318495363,"mc":[{"id":"1.195532859","rc":[{"atb":[[2.72,1.65],[2.6,202.23]],"id":41288595},{"atb":[[2.56,1.65]],"id":38983972},{"atb":[[6,15.42],[5.2,4],[5.7,24.1]],"id":38324360},{"atb":[[1.73,18.83],[1.75,15.92]],"id":38357910}],"con":true,"img":false}]}
{"op":"mcm","clk":"5322288611","pt":1646318495561,"mc":[{"id":"1.195532859","rc":[{"atb":[[2.6,93.75]],"id":41288595}],"con":true,"img":false}]}
{"op":"mcm","clk":"5322288618","pt":1646318495672,"mc":[{"id":"1.195532859","rc":[{"atb":[[1.74,13.92]],"id":38357910}],"con":true,"img":false}]}
{"op":"mcm","clk":"5322288631","pt":1646318495781,"mc":[{"id":"1.195532859","rc":[{"atb":[[1.76,1.99]],"id":38357910}],"con":true,"img":false}]}
{"op":"mcm","clk":"5322288645","pt":1646318495878,"mc":[{"id":"1.195532859","rc":[{"atb":[[2.78,3.3]],"id":41288595},{"atb":[[1.71,25.89]],"id":39290878},{"atl":[[2.98,20.2]],"id":39290878}],"con":true,"img":false}]}
{"op":"mcm","clk":"5322288655","pt":1646318495980,"mc":[{"id":"1.195532859","rc":[{"atl":[[3.1,6],[3,4],[3.3,0],[3.2,0],[3.4,0]],"id":39290878}],"con":true,"img":false}]}
{"op":"mcm","clk":"5322288669","pt":1646318496081,"mc":[{"id":"1.195532859","rc":[{"atb":[[2.66,7.25]],"id":41288595},{"atb":[[2.54,0]],"id":38983972},{"atb":[[1.73,16.68],[1.78,2.15]],"id":38357910}],"con":true,"img":false}]}
{"op":"mcm","clk":"5322288677","pt":1646318496187,"mc":[{"id":"1.195532859","rc":[{"atb":[[2.5,1.99]],"id":38983972}],"con":true,"img":false}]}
{"op":"mcm","clk":"5322288685","pt":1646318496290,"mc":[{"id":"1.195532859","rc":[{"atb":[[1.78,4.3],[1.75,0]],"id":38357910}],"con":true,"img":false}]}
{"op":"mcm","clk":"5322288696","pt":1646318496398,"mc":[{"id":"1.195532859","rc":[{"atb":[[1.78,2.15],[1.76,15.92]],"id":38357910}],"con":true,"img":false}]}
{"op":"mcm","clk":"5322288705","pt":1646318496491,"mc":[{"id":"1.195532859","rc":[{"atb":[[1.78,6.45]],"id":38357910}],"con":true,"img":false}]}
{"op":"mcm","clk":"5322288717","pt":1646318496556,"mc":[{"id":"1.195532859","rc":[{"atb":[[2.66,0]],"id":41288595},{"atb":[[1.76,1.99]],"id":38357910}],"con":true,"img":false}]}
{"op":"mcm","clk":"5322288735","pt":1646318496766,"mc":[{"id":"1.195532859","rc":[{"atb":[[2.7,0]],"id":41288595},{"atb":[[1.71,5.96]],"id":38357910}],"con":true,"img":false}]}
{"op":"mcm","clk":"5322288745","pt":1646318496871,"mc":[{"id":"1.195532859","rc":[{"atb":[[2.8,1.99]],"id":41288595}],"con":true,"img":false}]}
{"op":"mcm","clk":"5322288755","pt":1646318496977,"mc":[{"id":"1.195532859","rc":[{"atb":[[1.76,0]],"id":38357910}],"con":true,"img":false}]}
{"op":"mcm","clk":"5322288767","pt":1646318497080,"mc":[{"id":"1.195532859","rc":[{"atb":[[1.79,1.99]],"id":38357910}],"con":true,"img":false}]}
{"op":"mcm","clk":"5322288914","pt":1646318498490,"mc":[{"id":"1.195532859","rc":[{"atl":[[5.5,4.35]],"id":41288595}],"con":true,"img":false}]}
{"op":"mcm","clk":"5322288936","pt":1646318498692,"mc":[{"id":"1.195532859","rc":[{"atl":[[5.7,0]],"id":41288595},{"atb":[[2.5,6.94]],"id":38983972},{"atb":[[5.9,0]],"id":38324360},{"atb":[[1.71,0]],"id":38357910}],"con":true,"img":false}]}
{"op":"mcm","clk":"5322288948","pt":1646318498802,"mc":[{"id":"1.195532859","rc":[{"atl":[[5.8,44.58],[5.9,28.57]],"id":41288595},{"atb":[[1.7,0]],"id":39290878},{"atb":[[1.73,48.74],[1.67,2.5]],"id":38357910}],"con":true,"img":false}]}
{"op":"mcm","clk":"5322288959","pt":1646318498859,"mc":[{"id":"1.195532859","rc":[{"atb":[[1.74,0]],"id":38357910}],"con":true,"img":false}]}
{"op":"mcm","clk":"5322289027","pt":1646318499686,"mc":[{"id":"1.195532859","rc":[{"atb":[[5.2,35.79],[5.7,0]],"id":38324360}],"con":true,"img":false}]}
{"op":"mcm","clk":"5322289114","pt":1646318500679,"mc":[{"id":"1.195532859","rc":[{"atb":[[1.75,9.28]],"id":38357910}],"con":true,"img":false}]}
{"op":"mcm","clk":"5322289154","pt":1646318501190,"mc":[{"id":"1.195532859","rc":[{"atb":[[2.78,0]],"id":41288595},{"atb":[[1.68,15.19]],"id":38357910}],"con":true,"img":false}]}
{"op":"mcm","clk":"5322289163","pt":1646318501293,"mc":[{"id":"1.195532859","rc":[{"atb":[[1.71,8.45]],"id":39290878}],"con":true,"img":false}]}
{"op":"mcm","clk":"5322289189","pt":1646318501566,"mc":[{"id":"1.195532859","rc":[{"atb":[[2.8,0]],"id":41288595},{"trd":[[2.8,3.97]],"ltp":2.8,"tv":3.97,"id":41288595}],"con":true,"img":false}]}
{"op":"mcm","clk":"5322289251","pt":1646318502190,"mc":[{"id":"1.195532859","rc":[{"atb":[[2.72,0]],"id":41288595},{"atb":[[2.56,0]],"id":38983972}],"con":true,"img":false}]}
{"op":"mcm","clk":"5322289273","pt":1646318502391,"mc":[{"id":"1.195532859","rc":[{"atb":[[2.7,1.65]],"id":41288595},{"atb":[[2.52,1.65]],"id":38983972},{"atl":[[3,12.78]],"id":39290878}],"con":true,"img":false}]}
{"op":"mcm","clk":"5322289307","pt":1646318502662,"mc":[{"id":"1.195532859","rc":[{"atb":[[1.72,16.27]],"id":39290878}],"con":true,"img":false}]}
{"op":"mcm","clk":"5322289323","pt":1646318502767,"mc":[{"id":"1.195532859","rc":[{"atb":[[2.66,24.1]],"id":41288595},{"atl":[[5.7,8.51]],"id":41288595},{"atb":[[5.1,35.79],[5.2,4]],"id":38324360},{"atl":[[3,70.34],[3.05,45.45]],"id":39290878}],"con":true,"img":false}]}
{"op":"mcm","clk":"5322289331","pt":1646318502866,"mc":[{"id":"1.195532859","rc":[{"atb":[[2.68,0]],"id":41288595}],"con":true,"img":false}]}
{"op":"mcm","clk":"5322289341","pt":1646318502975,"mc":[{"id":"1.195532859","rc":[{"atl":[[2.92,2.48],[3,61.56]],"id":39290878},{"atl":[[3.95,2.48]],"id":38357910}],"con":true,"img":false}]}
{"op":"mcm","clk":"5322289351","pt":1646318503075,"mc":[{"id":"1.195532859","rc":[{"atl":[[3.1,29.96]],"id":39290878}],"con":true,"img":false}]}
{"op":"mcm","clk":"5322289361","pt":1646318503185,"mc":[{"id":"1.195532859","rc":[{"atl":[[2.92,18.48],[2.9,19.22],[3.05,0]],"id":39290878},{"atl":[[4.3,6.25],[3.95,4.98],[4.1,37.96],[3.9,6.71],[4.2,12.5]],"id":38357910}],"con":true,"img":false}]}
{"op":"mcm","clk":"5322289371","pt":1646318503285,"mc":[{"id":"1.195532859","rc":[{"atl":[[3.1,6]],"id":39290878}],"con":true,"img":false}]}
{"op":"mcm","clk":"5322289385","pt":1646318503390,"mc":[{"id":"1.195532859","rc":[{"atl":[[2.94,0]],"id":39290878},{"atl":[[4,0]],"id":38357910}],"con":true,"img":false}]}
{"op":"mcm","clk":"5322289426","pt":1646318503796,"mc":[{"id":"1.195532859","rc":[{"atl":[[4.3,0]],"id":38357910}],"con":true,"img":false}]}
{"op":"mcm","clk":"5322289474","pt":1646318504377,"mc":[{"id":"1.195532859","rc":[{"atb":[[5.3,10.89]],"id":38324360},{"atb":[[1.76,5.96]],"id":38357910}],"con":true,"img":false}]}
{"op":"mcm","clk":"5322289487","pt":1646318504495,"mc":[{"id":"1.195532859","rc":[{"atb":[[2.4,16.69]],"id":38983972},{"atl":[[2.92,16]],"id":39290878},{"atl":[[3.95,2.5]],"id":38357910}],"con":true,"img":false}]}
{"op":"mcm","clk":"5322289561","pt":1646318505273,"mc":[{"id":"1.195532859","rc":[{"atb":[[1.68,0]],"id":38357910}],"con":true,"img":false}]}
{"op":"mcm","clk":"5322289575","pt":1646318505377,"mc":[{"id":"1.195532859","rc":[{"atb":[[1.73,15.11]],"id":39290878}],"con":true,"img":false}]}
{"op":"mcm","clk":"5322289620","pt":1646318505902,"mc":[{"id":"1.195532859","rc":[{"atl":[[2.94,20.62]],"id":39290878}],"con":true,"img":false}]}
{"op":"mcm","clk":"5322289629","pt":1646318506010,"mc":[{"id":"1.195532859","rc":[{"atb":[[1.72,56.62],[1.69,0]],"id":39290878}],"con":true,"img":false}]}
{"op":"mcm","clk":"5322289690","pt":1646318506591,"mc":[{"id":"1.195532859","rc":[{"atb":[[1.83,0],[2.54,2.15]],"id":38983972}],"con":true,"img":false}]}
{"op":"mcm","clk":"5322289700","pt":1646318506694,"mc":[{"id":"1.195532859","rc":[{"atb":[[1.71,0]],"id":39290878},{"atb":[[1.75,0]],"id":38357910}],"con":true,"img":false}]}
{"op":"mcm","clk":"5322289712","pt":1646318506797,"mc":[{"id":"1.195532859","rc":[{"atb":[[2.4,5]],"id":38983972}],"con":true,"img":false}]}
{"op":"mcm","clk":"5322289722","pt":1646318506900,"mc":[{"id":"1.195532859","rc":[{"atl":[[2.88,2.48]],"id":39290878},{"atl":[[3.85,2.48]],"id":38357910}],"con":true,"img":false}]}
{"op":"mcm","clk":"5322289741","pt":1646318507100,"mc":[{"id":"1.195532859","rc":[{"atb":[[2.5,4.95]],"id":38983972}],"con":true,"img":false}]}
{"op":"mcm","clk":"5322289749","pt":1646318507204,"mc":[{"id":"1.195532859","rc":[{"atb":[[2.56,1.99]],"id":38983972}],"con":true,"img":false}]}
{"op":"mcm","clk":"5322289780","pt":1646318507486,"mc":[{"id":"1.195532859","rc":[{"atb":[[1.79,7.89]],"id":38357910}],"con":true,"img":false}]}
{"op":"mcm","clk":"5322289804","pt":1646318507685,"mc":[{"id":"1.195532859","rc":[{"atb":[[1.8,6.45],[1.78,2.15]],"id":38357910}],"con":true,"img":false}]}
{"op":"mcm","clk":"5322289836","pt":1646318507994,"mc":[{"id":"1.195532859","rc":[{"atb":[[5.1,4],[5.2,30.11]],"id":38324360}],"con":true,"img":false}]}
{"op":"mcm","clk":"5322289846","pt":1646318508095,"mc":[{"id":"1.195532859","rc":[{"atb":[[1.79,5.9]],"id":38357910}],"con":true,"img":false}]}
{"op":"mcm","clk":"5322289861","pt":1646318508200,"mc":[{"id":"1.195532859","rc":[{"atb":[[1.81,1.99]],"id":38357910}],"con":true,"img":false}]}
{"op":"mcm","clk":"5322289882","pt":1646318508403,"mc":[{"id":"1.195532859","rc":[{"atb":[[1.72,40.35]],"id":39290878},{"atl":[[4.2,17.22]],"id":38357910}],"con":true,"img":false}]}
{"op":"mcm","clk":"5322289903","pt":1646318508602,"mc":[{"id":"1.195532859","rc":[{"atl":[[4.2,12.5]],"id":38357910}],"con":true,"img":false}]}
{"op":"mcm","clk":"5322289956","pt":1646318509193,"mc":[{"id":"1.195532859","rc":[{"atb":[[2.7,0]],"id":41288595},{"atb":[[2.52,0]],"id":38983972}],"con":true,"img":false}]}
{"op":"mcm","clk":"5322289973","pt":1646318509429,"mc":[{"id":"1.195532859","rc":[{"atb":[[2.68,1.65]],"id":41288595},{"atb":[[2.58,1.65]],"id":38983972},{"atb":[[1.8,12.76]],"id":38357910}],"con":true,"img":false}]}
{"op":"mcm","clk":"5322289990","pt":1646318509609,"mc":[{"id":"1.195532859","rc":[{"atb":[[1.73,32.06]],"id":38357910}],"con":true,"img":false}]}
{"op":"mcm","clk":"5322290041","pt":1646318510125,"mc":[{"id":"1.195532859","rc":[{"atl":[[2.92,78.24],[3,4]],"id":39290878}],"con":true,"img":false}]}
{"op":"mcm","clk":"5322290056","pt":1646318510191,"mc":[{"id":"1.195532859","rc":[{"atb":[[1.74,8.52]],"id":38357910}],"con":true,"img":false}]}
{"op":"mcm","clk":"5322290100","pt":1646318510506,"mc":[{"id":"1.195532859","rc":[{"atl":[[2.92,62.24],[2.88,21.7]],"id":39290878},{"atb":[[1.74,0]],"id":38357910},{"atl":[[3.85,4.98],[3.95,0]],"id":38357910}],"con":true,"img":false}]}
{"op":"mcm","clk":"5322290110","pt":1646318510608,"mc":[{"id":"1.195532859","rc":[{"atb":[[1.68,5.73],[1.77,9.28]],"id":38357910}],"con":true,"img":false}]}
{"op":"mcm","clk":"5322290154","pt":1646318511017,"mc":[{"id":"1.195532859","rc":[{"atb":[[2.6,181.68]],"id":41288595},{"atb":[[1.68,0]],"id":38357910}],"con":true,"img":false}]}
{"op":"mcm","clk":"5322290206","pt":1646318511493,"mc":[{"id":"1.195532859","rc":[{"atb":[[1.79,0]],"id":38357910}],"con":true,"img":false}]}
{"op":"mcm","clk":"5322290254","pt":1646318512013,"mc":[{"id":"1.195532859","rc":[{"atb":[[2.5,0]],"id":38983972},{"atb":[[1.74,6.96]],"id":39290878},{"atb":[[1.76,0]],"id":38357910}],"con":true,"img":false}]}
{"op":"mcm","clk":"5322290313","pt":1646318512700,"mc":[{"id":"1.195532859","rc":[{"atb":[[1.74,20.91]],"id":39290878}],"con":true,"img":false}]}
{"op":"mcm","clk":"5322290323","pt":1646318512790,"mc":[{"id":"1.195532859","rc":[{"atb":[[2.66,0],[2.64,24.39]],"id":41288595},{"atl":[[5.9,40.82]],"id":41288595}],"con":true,"img":false}]}
{"op":"mcm","clk":"5322290344","pt":1646318512998,"mc":[{"id":"1.195532859","rc":[{"atb":[[2.6,191.32]],"id":41288595}],"con":true,"img":false}]}
{"op":"mcm","clk":"5322290482","pt":1646318514409,"mc":[{"id":"1.195532859","rc":[{"atb":[[1.73,0],[1.77,29.28]],"id":38357910}],"con":true,"img":false}]}
{"op":"mcm","clk":"5322290497","pt":1646318514627,"mc":[{"id":"1.195532859","rc":[{"atb":[[1.77,20]],"id":38357910}],"con":true,"img":false}]}
{"op":"mcm","clk":"5322290569","pt":1646318515305,"mc":[{"id":"1.195532859","rc":[{"atb":[[1.73,0]],"id":39290878}],"con":true,"img":false}]}
{"op":"mcm","clk":"5322290577","pt":1646318515409,"mc":[{"id":"1.195532859","rc":[{"atb":[[1.74,20.64]],"id":38357910}],"con":true,"img":false}]}
{"op":"mcm","clk":"5322290634","pt":1646318515883,"mc":[{"id":"1.195532859","rc":[{"atl":[[2.92,83.07]],"id":39290878}],"con":true,"img":false}]}
{"op":"mcm","clk":"5322290666","pt":1646318516195,"mc":[{"id":"1.195532859","rc":[{"atb":[[2.68,0]],"id":41288595}],"con":true,"img":false}]}
{"op":"mcm","clk":"5322290674","pt":1646318516298,"mc":[{"id":"1.195532859","rc":[{"atb":[[2.42,75.42]],"id":41288595}],"con":true,"img":false}]}
{"op":"mcm","clk":"5322290684","pt":1646318516401,"mc":[{"id":"1.195532859","rc":[{"atb":[[2.5,2.5],[2.66,1.65]],"id":41288595}],"con":true,"img":false}]}
{"op":"mcm","clk":"5322290759","pt":1646318517183,"mc":[{"id":"1.195532859","rc":[{"atb":[[2.66,9.13],[2.64,0],[2.62,24.69]],"id":41288595},{"atb":[[1.83,2.15],[1.78,0]],"id":38357910},{"atl":[[3.95,13.56],[4.2,0]],"id":38357910}],"con":true,"img":false}]}
{"op":"mcm","clk":"5322290767","pt":1646318517315,"mc":[{"id":"1.195532859","rc":[{"atb":[[2.6,3.3]],"id":38983972},{"atb":[[1.82,3.97]],"id":38357910}],"con":true,"img":false}]}
{"op":"mcm","clk":"5322290776","pt":1646318517389,"mc":[{"id":"1.195532859","rc":[{"atb":[[1.75,12.78]],"id":39290878},{"atb":[[1.82,16.73],[1.8,6.31]],"id":38357910}],"con":true,"img":false}]}
{"op":"mcm","clk":"5322290801","pt":1646318517601,"mc":[{"id":"1.195532859","rc":[{"atb":[[2.66,1.65]],"id":41288595}],"con":true,"img":false}]}
{"op":"mcm","clk":"5322290812","pt":1646318517708,"mc":[{"id":"1.195532859","rc":[{"atb":[[1.73,3.48]],"id":39290878}],"con":true,"img":false}]}
{"op":"mcm","clk":"5322290825","pt":1646318517812,"mc":[{"id":"1.195532859","rc":[{"atb":[[1.81,0]],"id":38357910}],"con":true,"img":false}]}
{"op":"mcm","clk":"5322290834","pt":1646318517916,"mc":[{"id":"1.195532859","rc":[{"atb":[[1.73,0]],"id":39290878},{"atb":[[1.84,1.99]],"id":38357910}],"con":true,"img":false}]}
{"op":"mcm","clk":"5322290861","pt":1646318518187,"mc":[{"id":"1.195532859","rc":[{"atb":[[2.56,248.92],[2.6,103.39]],"id":41288595}],"con":true,"img":false}]}
{"op":"mcm","clk":"5322290870","pt":1646318518286,"mc":[{"id":"1.195532859","rc":[{"atb":[[2.56,0]],"id":38983972}],"con":true,"img":false}]}
{"op":"mcm","clk":"5322290877","pt":1646318518384,"mc":[{"id":"1.195532859","rc":[{"atb":[[1.02,1.99]],"id":38983972},{"atb":[[1.75,19.17]],"id":38357910}],"con":true,"img":false}]}
{"op":"mcm","clk":"5322290899","pt":1646318518711,"mc":[{"id":"1.195532859","rc":[{"atl":[[2.86,24]],"id":39290878},{"atl":[[3.95,39.6],[4.1,2.5],[3.8,8.77]],"id":38357910}],"con":true,"img":false}]}
{"op":"mcm","clk":"5322290914","pt":1646318518910,"mc":[{"id":"1.195532859","rc":[{"atl":[[2.92,20.83],[2.9,80.26]],"id":39290878},{"atl":[[3.9,0]],"id":38357910}],"con":true,"img":false}]}
{"op":"mcm","clk":"5322290941","pt":1646318519220,"mc":[{"id":"1.195532859","rc":[{"atb":[[1.74,0]],"id":38357910}],"con":true,"img":false}]}
{"op":"mcm","clk":"5322290966","pt":1646318519477,"mc":[{"id":"1.195532859","rc":[{"atb":[[2.68,18.27]],"id":41288595}],"con":true,"img":false}]}
{"op":"mcm","clk":"5322290972","pt":1646318519593,"mc":[{"id":"1.195532859","rc":[{"atl":[[2.88,19.22]],"id":39290878},{"atl":[[3.85,2.5]],"id":38357910}],"con":true,"img":false}]}
{"op":"mcm","clk":"5322290983","pt":1646318519705,"mc":[{"id":"1.195532859","rc":[{"atl":[[2.88,0]],"id":39290878},{"atl":[[3.85,0],[3.95,69.01]],"id":38357910}],"con":true,"img":false}]}
{"op":"mcm","clk":"5322291008","pt":1646318519908,"mc":[{"id":"1.195532859","rc":[{"atl":[[2.86,0],[2.9,123.48]],"id":39290878},{"atl":[[3.95,39.6],[4.1,34.76],[3.8,0]],"id":38357910}],"con":true,"img":false}]}
{"op":"mcm","clk":"5322291026","pt":1646318520104,"mc":[{"id":"1.195532859","rc":[{"atb":[[1.74,6.96]],"id":39290878},{"atl":[[2.88,16.81]],"id":39290878},{"atl":[[3.85,14.17]],"id":38357910}],"con":true,"img":false}]}
{"op":"mcm","clk":"5322291055","pt":1646318520421,"mc":[{"id":"1.195532859","rc":[{"atl":[[5.9,46.03]],"id":41288595},{"atl":[[6.4,23.33]],"id":38983972},{"atl":[[15.5,12.53]],"id":38324360}],"con":true,"img":false}]}
{"op":"mcm","clk":"5322291062","pt":1646318520528,"mc":[{"id":"1.195532859","rc":[{"atl":[[5.3,29.21]],"id":40124755}],"con":true,"img":false}]}
{"op":"mcm","clk":"5322291076","pt":1646318520633,"mc":[{"id":"1.195532859","rc":[{"atl":[[6,60.32]],"id":38983972},{"atl":[[4.6,3.15]],"id":40124755}],"con":true,"img":false}]}
{"op":"mcm","clk":"5322291096","pt":1646318520786,"mc":[{"id":"1.195532859","rc":[{"atl":[[5.1,28.26],[4.5,10.35],[5.2,0]],"id":40124755}],"con":true,"img":false}]}
{"op":"mcm","clk":"5322291101","pt":1646318520887,"mc":[{"id":"1.195532859","rc":[{"atl":[[5.9,40.82]],"id":41288595},{"atl":[[6.4,18.52]],"id":38983972},{"atl":[[15.5,9]],"id":38324360},{"atl":[[2.86,2.48]],"id":39290878},{"atl":[[3.8,2.48]],"id":38357910},{"atl":[[5.1,18.5],[5.3,23.26],[4.7,10.81]],"id":40124755}],"con":true,"img":false}]}
{"op":"mcm","clk":"5322291115","pt":1646318520995,"mc":[{"id":"1.195532859","rc":[{"atb":[[2.64,24.39]],"id":41288595},{"atl":[[4.9,0],[5.2,3.22]],"id":40124755}],"con":true,"img":false}]}
{"op":"mcm","clk":"5322291138","pt":1646318521197,"mc":[{"id":"1.195532859","rc":[{"atl":[[6,39.55]],"id":38983972},{"atl":[[5.2,0]],"id":40124755}],"con":true,"img":false}]}
{"op":"mcm","clk":"5322291156","pt":1646318521407,"mc":[{"id":"1.195532859","rc":[{"atb":[[1.72,0],[1.74,37.46]],"id":39290878},{"atl":[[4.6,0]],"id":40124755}],"con":true,"img":false}]}
{"op":"mcm","clk":"5322291171","pt":1646318521617,"mc":[{"id":"1.195532859","rc":[{"atl":[[4.5,6],[5.1,41.76]],"id":40124755}],"con":true,"img":false}]}
{"op":"mcm","clk":"5322291185","pt":1646318521720,"mc":[{"id":"1.195532859","rc":[{"atl":[[5.9,4.41]],"id":38983972}],"con":true,"img":false}]}
{"op":"mcm","clk":"5322291198","pt":1646318521780,"mc":[{"id":"1.195532859","rc":[{"atb":[[2.3,5.8],[2.48,11.39],[2.16,0]],"id":38983972},{"atb":[[2.28,18.97],[2.26,19.33]],"id":40124755},{"atl":[[4.5,0]],"id":40124755}],"con":true,"img":false}]}
{"op":"mcm","clk":"5322291209","pt":1646318521884,"mc":[{"id":"1.195532859","rc":[{"atl":[[3.95,26.04],[3.9,13.79]],"id":38357910},{"atl":[[4.6,10.84]],"id":40124755}],"con":true,"img":false}]}
{"op":"mcm","clk":"5322291219","pt":1646318521988,"mc":[{"id":"1.195532859","rc":[{"atb":[[1.74,30.5]],"id":39290878},{"atb":[[1.82,12.76]],"id":38357910},{"atb":[[2.26,12.46]],"id":40124755}],"con":true,"img":false}]}
{"op":"mcm","clk":"5322291225","pt":1646318522091,"mc":[{"id":"1.195532859","rc":[{"atl":[[2.9,144.53]],"id":39290878},{"atl":[[4.8,10.53],[4.7,0]],"id":40124755}],"con":true,"img":false}]}
{"op":"mcm","clk":"5322291243","pt":1646318522302,"mc":[{"id":"1.195532859","rc":[{"atl":[[15.5,11.5]],"id":38324360},{"atl":[[4.6,0]],"id":40124755}],"con":true,"img":false}]}
{"op":"mcm","clk":"5322291261","pt":1646318522511,"mc":[{"id":"1.195532859","rc":[{"atl":[[4.7,16.03]],"id":40124755}],"con":true,"img":false}]}
{"op":"mcm","clk":"5322291273","pt":1646318522619,"mc":[{"id":"1.195532859","rc":[{"atl":[[5.9,2.5]],"id":38983972},{"atb":[[1.75,0]],"id":38357910},{"atl":[[4.8,0],[5,10]],"id":40124755}],"con":true,"img":false}]}
{"op":"mcm","clk":"5322291282","pt":1646318522724,"mc":[{"id":"1.195532859","rc":[{"atb":[[1.79,10.13]],"id":39290878}],"con":true,"img":false}]}
{"op":"mcm","clk":"5322291293","pt":1646318522824,"mc":[{"id":"1.195532859","rc":[{"atl":[[5,0],[4.9,10.26]],"id":40124755}],"con":true,"img":false}]}
{"op":"mcm","clk":"5322291323","pt":1646318523087,"mc":[{"id":"1.195532859","rc":[{"atl":[[5.6,3]],"id":38983972},{"atl":[[4.8,1.72],[4.7,0]],"id":40124755}],"con":true,"img":false}]}
{"op":"mcm","clk":"5322291334","pt":1646318523195,"mc":[{"id":"1.195532859","rc":[{"atb":[[2.66,0]],"id":41288595},{"atb":[[2.58,0]],"id":38983972},{"atl":[[6,23.55]],"id":38983972},{"atl":[[4.8,21.44]],"id":40124755}],"con":true,"img":false}]}
{"op":"mcm","clk":"5322291346","pt":1646318523291,"mc":[{"id":"1.195532859","rc":[{"atl":[[6.4,21.63],[5.5,7.12],[6,8],[5.9,16.72]],"id":38983972},{"atb":[[1.84,4.89]],"id":38357910}],"con":true,"img":false}]}
{"op":"mcm","clk":"5322291354","pt":1646318523398,"mc":[{"id":"1.195532859","rc":[{"atb":[[2.7,1.65]],"id":41288595},{"atb":[[2.62,1.65]],"id":38983972},{"atl":[[5.6,17.24],[5.8,0]],"id":38983972}],"con":true,"img":false}]}
{"op":"mcm","clk":"5322291363","pt":1646318523504,"mc":[{"id":"1.195532859","rc":[{"atl":[[5.8,10.12],[5.5,4.12]],"id":38983972}],"con":true,"img":false}]}
{"op":"mcm","clk":"5322291373","pt":1646318523610,"mc":[{"id":"1.195532859","rc":[{"atb":[[2.64,0],[2.66,24.1]],"id":41288595},{"atb":[[2.46,4.46]],"id":38983972},{"atl":[[5.6,3],[6,0],[5.7,8.51]],"id":38983972},{"atl":[[5,10],[4.9,0]],"id":40124755}],"con":true,"img":false}]}
{"op":"mcm","clk":"5322291385","pt":1646318523709,"mc":[{"id":"1.195532859","rc":[{"atl":[[5.6,19.72],[6.4,18.52]],"id":38983972}],"con":true,"img":false}]}
{"op":"mcm","clk":"5322291391","pt":1646318523814,"mc":[{"id":"1.195532859","rc":[{"atb":[[2.46,0]],"id":38983972},{"atl":[[5.8,0]],"id":38983972}],"con":true,"img":false}]}
{"op":"mcm","clk":"5322291442","pt":1646318524285,"mc":[{"id":"1.195532859","rc":[{"atb":[[2.28,8.02]],"id":40124755},{"atl":[[4.8,19.72]],"id":40124755}],"con":true,"img":false}]}
{"op":"mcm","clk":"5322291481","pt":1646318524697,"mc":[{"id":"1.195532859","rc":[{"atl":[[4.6,1.69]],"id":40124755}],"con":true,"img":false}]}
{"op":"mcm","clk":"5322291491","pt":1646318524800,"mc":[{"id":"1.195532859","rc":[{"atb":[[1.84,18.13]],"id":38357910}],"con":true,"img":false}]}
{"op":"mcm","clk":"5322291500","pt":1646318524910,"mc":[{"id":"1.195532859","rc":[{"atb":[[1.8,0]],"id":38357910}],"con":true,"img":false}]}
{"op":"mcm","clk":"5322291526","pt":1646318525119,"mc":[{"id":"1.195532859","rc":[{"atb":[[1.75,0]],"id":39290878},{"atl":[[4.8,30.25],[5,0]],"id":40124755}],"con":true,"img":false}]}
{"op":"mcm","clk":"5322291673","pt":1646318526328,"mc":[{"id":"1.195532859","rc":[{"atb":[[2.56,160.26],[2.62,79.73]],"id":41288595}],"con":true,"img":false}]}
{"op":"mcm","clk":"5322291738","pt":1646318526903,"mc":[{"id":"1.195532859","rc":[{"atb":[[1.85,3.42]],"id":38357910}],"con":true,"img":false}]}
{"op":"mcm","clk":"5322291761","pt":1646318527114,"mc":[{"id":"1.195532859","rc":[{"atb":[[2.68,0]],"id":41288595},{"atb":[[2.6,0]],"id":38983972},{"atb":[[1.76,30.39]],"id":39290878},{"atl":[[2.86,19.29],[2.9,101.31]],"id":39290878},{"atb":[[1.85,13.2]],"id":38357910},{"atl":[[4.1,2.5],[3.8,16.27]],"id":38357910}],"con":true,"img":false}]}
{"op":"mcm","clk":"5322291785","pt":1646318527319,"mc":[{"id":"1.195532859","rc":[{"atb":[[2.66,28.48]],"id":41288595}],"con":true,"img":false}]}
{"op":"mcm","clk":"5322291798","pt":1646318527424,"mc":[{"id":"1.195532859","rc":[{"atb":[[2.66,37.61]],"id":41288595}],"con":true,"img":false}]}
{"op":"mcm","clk":"5322291810","pt":1646318527528,"mc":[{"id":"1.195532859","rc":[{"atb":[[1.84,16.14]],"id":38357910}],"con":true,"img":false}]}
{"op":"mcm","clk":"5322291819","pt":1646318527629,"mc":[{"id":"1.195532859","rc":[{"atb":[[1.02,1.99]],"id":38357910}],"con":true,"img":false}]}
{"op":"mcm","clk":"5322291830","pt":1646318527732,"mc":[{"id":"1.195532859","rc":[{"atb":[[1.82,2.15],[1.78,7.48]],"id":39290878},{"atb":[[1.83,0],[1.88,2.15]],"id":38357910}],"con":true,"img":false}]}
{"op":"mcm","clk":"5322291839","pt":1646318527836,"mc":[{"id":"1.195532859","rc":[{"atb":[[2.66,24.1]],"id":41288595},{"atb":[[1.02,0]],"id":38983972},{"atb":[[1.79,37.2]],"id":39290878}],"con":true,"img":false}]}
{"op":"mcm","clk":"5322291852","pt":1646318527896,"mc":[{"id":"1.195532859","rc":[{"atb":[[2.56,1.99]],"id":38983972},{"atl":[[5.1,25.76],[5.3,82.93]],"id":40124755}],"con":true,"img":false}]}
{"op":"mcm","clk":"5322291864","pt":1646318527999,"mc":[{"id":"1.195532859","rc":[{"atb":[[1.78,0]],"id":39290878}],"con":true,"img":false}]}
{"op":"mcm","clk":"5322291929","pt":1646318528630,"mc":[{"id":"1.195532859","rc":[{"atb":[[1.79,35.21]],"id":39290878}],"con":true,"img":false}]}
{"op":"mcm","clk":"5322291944","pt":1646318528729,"mc":[{"id":"1.195532859","rc":[{"atb":[[1.83,1.99]],"id":39290878},{"atl":[[5.1,2.5],[4.6,27.45]],"id":40124755}],"con":true,"img":false}]}
{"op":"mcm","clk":"5322291954","pt":1646318528842,"mc":[{"id":"1.195532859","rc":[{"atl":[[5.1,26.89],[4.6,1.69]],"id":40124755}],"con":true,"img":false}]}
{"op":"mcm","clk":"5322291966","pt":1646318528894,"mc":[{"id":"1.195532859","rc":[{"atb":[[2.24,0],[2.26,14.96]],"id":40124755},{"atl":[[4.6,29.14]],"id":40124755}],"con":true,"img":false}]}
{"op":"mcm","clk":"5322291974","pt":1646318529027,"mc":[{"id":"1.195532859","rc":[{"atl":[[5.1,2.5]],"id":40124755}],"con":true,"img":false}]}
{"op":"mcm","clk":"5322291982","pt":1646318529131,"mc":[{"id":"1.195532859","rc":[{"atl":[[5.6,2.5],[7.2,0],[6.4,0],[5.8,42.08]],"id":41288595},{"atb":[[1.79,27.07]],"id":39290878}],"con":true,"img":false}]}
{"op":"mcm","clk":"5322291993","pt":1646318529234,"mc":[{"id":"1.195532859","rc":[{"atl":[[5.5,0],[5.4,18.18]],"id":41288595},{"atl":[[5.1,26.89],[4.6,1.69]],"id":40124755}],"con":true,"img":false}]}
{"op":"mcm","clk":"5322292004","pt":1646318529333,"mc":[{"id":"1.195532859","rc":[{"atl":[[5.8,0],[5.7,85.44],[5.9,20.41]],"id":41288595},{"atb":[[1.75,12.15]],"id":39290878},{"atb":[[1.84,13.24]],"id":38357910},{"atb":[[2.36,7.29]],"id":40124755}],"con":true,"img":false}]}
{"op":"mcm","clk":"5322292024","pt":1646318529498,"mc":[{"id":"1.195532859","rc":[{"atb":[[2.34,1.65]],"id":40124755}],"con":true,"img":false}]}
{"op":"mcm","clk":"5322292033","pt":1646318529602,"mc":[{"id":"1.195532859","rc":[{"atb":[[1.84,47.03]],"id":38357910},{"atb":[[2.38,1.99]],"id":40124755}],"con":true,"img":false}]}
{"op":"mcm","clk":"5322292044","pt":1646318529705,"mc":[{"id":"1.195532859","rc":[{"atb":[[1.77,0]],"id":38357910}],"con":true,"img":false}]}
{"op":"mcm","clk":"5322292097","pt":1646318530226,"mc":[{"id":"1.195532859","rc":[{"atb":[[2.7,0]],"id":41288595},{"atl":[[5.6,11.2]],"id":41288595},{"atb":[[2.62,0]],"id":38983972},{"atb":[[2.34,0]],"id":40124755}],"con":true,"img":false}]}
{"op":"mcm","clk":"5322292111","pt":1646318530330,"mc":[{"id":"1.195532859","rc":[{"atl":[[5.8,4.59]],"id":41288595}],"con":true,"img":false}]}
{"op":"mcm","clk":"5322292116","pt":1646318530429,"mc":[{"id":"1.195532859","rc":[{"atb":[[2.68,1.65]],"id":41288595},{"atb":[[2.58,1.65],[2.48,2.5],[2.4,21.89]],"id":38983972},{"atb":[[2.4,1.65]],"id":40124755}],"con":true,"img":false}]}
{"op":"mcm","clk":"5322292151","pt":1646318530695,"mc":[{"id":"1.195532859","rc":[{"atl":[[5.8,0]],"id":41288595}],"con":true,"img":false}]}
{"op":"mcm","clk":"5322292160","pt":1646318530800,"mc":[{"id":"1.195532859","rc":[{"atb":[[2.66,0],[2.64,24.39]],"id":41288595},{"atl":[[5.6,16.72]],"id":38983972}],"con":true,"img":false}]}
{"op":"mcm","clk":"5322292171","pt":1646318530909,"mc":[{"id":"1.195532859","rc":[{"atl":[[5.6,0],[5.7,29.35]],"id":38983972}],"con":true,"img":false}]}
{"op":"mcm","clk":"5322292182","pt":1646318531010,"mc":[{"id":"1.195532859","rc":[{"atb":[[1.08,50]],"id":41288595},{"atb":[[1.08,50]],"id":38983972},{"atb":[[1.08,50]],"id":38324360},{"atb":[[1.08,50]],"id":39290878},{"atb":[[1.08,50]],"id":38357910},{"atb":[[1.08,50]],"id":40124755}],"con":true,"img":false}]}
{"op":"mcm","clk":"5322292193","pt":1646318531119,"mc":[{"id":"1.195532859","rc":[{"atl":[[5.5,0],[5.7,8.51],[5.9,37.13]],"id":38983972}],"con":true,"img":false}]}
{"op":"mcm","clk":"5322292202","pt":1646318531218,"mc":[{"id":"1.195532859","rc":[{"atb":[[2.28,4.01]],"id":40124755}],"con":true,"img":false}]}
{"op":"mcm","clk":"5322292211","pt":1646318531328,"mc":[{"id":"1.195532859","rc":[{"atl":[[5.6,4.7],[6.4,37.04],[5.9,2.5]],"id":38983972}],"con":true,"img":false}]}
{"op":"mcm","clk":"5322292224","pt":1646318531434,"mc":[{"id":"1.195532859","rc":[{"atl":[[6.4,61.36]],"id":38983972}],"con":true,"img":false}]}
{"op":"mcm","clk":"5322292234","pt":1646318531532,"mc":[{"id":"1.195532859","rc":[{"atl":[[6.4,42.84],[5.9,21.02]],"id":38983972}],"con":true,"img":false}]}
{"op":"mcm","clk":"5322292246","pt":1646318531636,"mc":[{"id":"1.195532859","rc":[{"atl":[[5.4,3]],"id":38983972}],"con":true,"img":false}]}
{"op":"mcm","clk":"5322292257","pt":1646318531689,"mc":[{"id":"1.195532859","rc":[{"atl":[[5.8,8.33],[5.7,0]],"id":38983972}],"con":true,"img":false}]}
{"op":"mcm","clk":"5322292270","pt":1646318531796,"mc":[{"id":"1.195532859","rc":[{"atl":[[5.3,4.7],[5.9,2.5]],"id":38983972},{"atl":[[4.6,0]],"id":40124755}],"con":true,"img":false}]}
{"op":"mcm","clk":"5322292320","pt":1646318532321,"mc":[{"id":"1.195532859","rc":[{"atb":[[1.76,0]],"id":39290878},{"atb":[[1.85,3.42]],"id":38357910}],"con":true,"img":false}]}
{"op":"mcm","clk":"5322292331","pt":1646318532420,"mc":[{"id":"1.195532859","rc":[{"atb":[[2.64,3.3]],"id":38983972}],"con":true,"img":false}]}
{"op":"mcm","clk":"5322292341","pt":1646318532525,"mc":[{"id":"1.195532859","rc":[{"atl":[[5.8,0],[5.5,8.89]],"id":38983972},{"atl":[[4.8,19.72],[5,10]],"id":40124755}],"con":true,"img":false}]}
{"op":"mcm","clk":"5322292349","pt":1646318532630,"mc":[{"id":"1.195532859","rc":[{"atb":[[2.4,5]],"id":38983972}],"con":true,"img":false}]}
{"op":"mcm","clk":"5322292381","pt":1646318532898,"mc":[{"id":"1.195532859","rc":[{"atb":[[1.77,5.38]],"id":39290878},{"atl":[[4,33.33]],"id":38357910},{"atb":[[2.28,0]],"id":40124755}],"con":true,"img":false}]}
{"op":"mcm","clk":"5322292390","pt":1646318532995,"mc":[{"id":"1.195532859","rc":[{"atl":[[2.94,72.17]],"id":39290878}],"con":true,"img":false}]}
{"op":"mcm","clk":"5322292402","pt":1646318533103,"mc":[{"id":"1.195532859","rc":[{"atb":[[1.75,0]],"id":39290878},{"atl":[[2.94,51.55]],"id":39290878},{"atb":[[1.86,10.75]],"id":38357910}],"con":true,"img":false}]}
{"op":"mcm","clk":"5322292428","pt":1646318533416,"mc":[{"id":"1.195532859","rc":[{"atb":[[2.6,226.53],[2.62,24.69]],"id":41288595}],"con":true,"img":false}]}
{"op":"mcm","clk":"5322292444","pt":1646318533627,"mc":[{"id":"1.195532859","rc":[{"atb":[[2.56,0]],"id":38983972}],"con":true,"img":false}]}
{"op":"mcm","clk":"5322292454","pt":1646318533727,"mc":[{"id":"1.195532859","rc":[{"atb":[[1.02,1.99]],"id":38983972}],"con":true,"img":false}]}
{"op":"mcm","clk":"5322292465","pt":1646318533832,"mc":[{"id":"1.195532859","rc":[{"atl":[[2.92,27.08]],"id":39290878}],"con":true,"img":false}]}
{"op":"mcm","clk":"5322292474","pt":1646318533934,"mc":[{"id":"1.195532859","rc":[{"atl":[[2.84,27.07]],"id":39290878},{"atl":[[3.75,18.4],[3.95,0],[3.9,62.87]],"id":38357910}],"con":true,"img":false}]}
{"op":"mcm","clk":"5322292484","pt":1646318534039,"mc":[{"id":"1.195532859","rc":[{"atl":[[2.88,0]],"id":39290878},{"atl":[[3.85,0]],"id":38357910}],"con":true,"img":false}]}
{"op":"mcm","clk":"5322292496","pt":1646318534143,"mc":[{"id":"1.195532859","rc":[{"atl":[[2.94,56.67],[2.88,72.2],[2.9,21.04]],"id":39290878},{"atl":[[3.85,3.62]],"id":38357910}],"con":true,"img":false}]}
{"op":"mcm","clk":"5322292515","pt":1646318534310,"mc":[{"id":"1.195532859","rc":[{"atl":[[2.94,51.55],[2.92,20.83],[2.88,0]],"id":39290878},{"atl":[[3.85,0]],"id":38357910}],"con":true,"img":false}]}
{"op":"mcm","clk":"5322292524","pt":1646318534411,"mc":[{"id":"1.195532859","rc":[{"atl":[[2.86,16.81]],"id":39290878},{"atl":[[3.8,13.79]],"id":38357910}],"con":true,"img":false}]}
{"op":"mcm","clk":"5322292533","pt":1646318534523,"mc":[{"id":"1.195532859","rc":[{"atl":[[2.88,43.88],[2.86,0]],"id":39290878},{"atl":[[3.85,33.33],[3.8,0]],"id":38357910},{"atb":[[2.36,0]],"id":40124755}],"con":true,"img":false}]}
{"op":"mcm","clk":"5322292544","pt":1646318534623,"mc":[{"id":"1.195532859","rc":[{"atl":[[2.84,0],[2.88,0],[2.9,73.67]],"id":39290878},{"atl":[[3.85,0],[3.9,97.35]],"id":38357910},{"atb":[[2.26,46.16]],"id":40124755}],"con":true,"img":false}]}
{"op":"mcm","clk":"5322292554","pt":1646318534732,"mc":[{"id":"1.195532859","rc":[{"atl":[[2.86,36.09]],"id":39290878}],"con":true,"img":false}]}
{"op":"mcm","clk":"5322292600","pt":1646318535100,"mc":[{"id":"1.195532859","rc":[{"atb":[[2.28,4.73]],"id":40124755}],"con":true,"img":false}]}
{"op":"mcm","clk":"5322292611","pt":1646318535250,"mc":[{"id":"1.195532859","rc":[{"atb":[[2.26,14.96]],"id":40124755}],"con":true,"img":false}]}
{"op":"mcm","clk":"5322292636","pt":1646318535409,"mc":[{"id":"1.195532859","rc":[{"atb":[[2.38,0]],"id":40124755}],"con":true,"img":false}]}
{"op":"mcm","clk":"5322292650","pt":1646318535523,"mc":[{"id":"1.195532859","rc":[{"atb":[[2.34,1.99]],"id":40124755},{"atl":[[4.8,0]],"id":40124755}],"con":true,"img":false}]}
{"op":"mcm","clk":"5322292678","pt":1646318535731,"mc":[{"id":"1.195532859","rc":[{"atl":[[4.8,11.06],[5.1,2.5],[5.3,106.19]],"id":40124755}],"con":true,"img":false}]}
{"op":"mcm","clk":"5322292702","pt":1646318535935,"mc":[{"id":"1.195532859","rc":[{"spn":2.64,"spf":1.0,"id":41288595},{"spn":3.97,"spf":"NaN","id":38983972},{"spn":9.5,"spf":"NaN","id":38324360},{"spn":1.83,"spf":1.0,"id":39290878},{"spn":2.81,"spf":"NaN","id":38357910},{"atl":[[5.1,19.28],[5.3,46.52]],"id":40124755},{"spn":3.6,"spf":"NaN","id":40124755}],"con":true,"img":false}]}
{"op":"mcm","clk":"5322292757","pt":1646318536508,"mc":[{"id":"1.195532859","rc":[{"atb":[[1.74,0],[1.77,65.26]],"id":39290878}],"con":true,"img":false}]}
{"op":"mcm","clk":"5322292783","pt":1646318536819,"mc":[{"id":"1.195532859","rc":[{"atb":[[1.85,0]],"id":38357910}],"con":true,"img":false}]}
{"op":"mcm","clk":"5322292789","pt":1646318536923,"mc":[{"id":"1.195532859","rc":[{"atb":[[2.48,11.39]],"id":38983972},{"atl":[[5.3,0],[5.4,12.4]],"id":38983972},{"atl":[[2.84,2.48]],"id":39290878},{"atl":[[3.7,2.48]],"id":38357910},{"atb":[[2.16,6.93]],"id":40124755}],"con":true,"img":false}]}
{"op":"mcm","clk":"5322292800","pt":1646318537029,"mc":[{"id":"1.195532859","rc":[{"atl":[[5.5,16.59],[5.4,3]],"id":38983972}],"con":true,"img":false}]}
{"op":"mcm","clk":"5322292815","pt":1646318537133,"mc":[{"id":"1.195532859","rc":[{"atl":[[2.82,22.16]],"id":39290878},{"atl":[[3.65,21.86]],"id":38357910}],"con":true,"img":false}]}
{"op":"mcm","clk":"5322292825","pt":1646318537246,"mc":[{"id":"1.195532859","rc":[{"atb":[[2.68,0]],"id":41288595},{"atb":[[2.58,0]],"id":38983972},{"atb":[[1.8,4.14]],"id":39290878},{"atb":[[2.4,0]],"id":40124755}],"con":true,"img":false}]}
{"op":"mcm","clk":"5322292837","pt":1646318537295,"mc":[{"id":"1.195532859","rc":[{"atl":[[2.86,0]],"id":39290878},{"atl":[[3.75,0]],"id":38357910}],"con":true,"img":false}]}
{"op":"mcm","clk":"5322292849","pt":1646318537399,"mc":[{"id":"1.195532859","rc":[{"atb":[[2.66,1.65]],"id":41288595},{"atb":[[2.36,1.65]],"id":40124755}],"con":true,"img":false}]}
{"op":"mcm","clk":"5322292879","pt":1646318537709,"mc":[{"id":"1.195532859","rc":[{"atb":[[1.8,10.1]],"id":39290878},{"atb":[[1.89,4.3]],"id":38357910}],"con":true,"img":false}]}
{"op":"mcm","clk":"5322292948","pt":1646318538339,"mc":[{"id":"1.195532859","rc":[{"atb":[[2.64,0]],"id":41288595},{"atl":[[5.6,13.4],[5.5,7.7]],"id":38983972},{"atl":[[2.84,0],[2.9,52.62],[2.86,21.51]],"id":39290878},{"atl":[[4.8,0],[4.4,0],[3.75,14.55],[4,0],[4.6,0],[3.7,0],[3.9,83.56]],"id":38357910}],"con":true,"img":false}]}
{"op":"mcm","clk":"5322292962","pt":1646318538444,"mc":[{"id":"1.195532859","rc":[{"atl":[[5.6,29.4],[6.4,18.52],[5.3,6]],"id":38983972}],"con":true,"img":false}]}
{"op":"mcm","clk":"5322292972","pt":1646318538548,"mc":[{"id":"1.195532859","rc":[{"atb":[[2.62,43.77]],"id":41288595},{"atl":[[2.82,0]],"id":39290878},{"atl":[[3.65,0]],"id":38357910}],"con":true,"img":false}]}
{"op":"mcm","clk":"5322292981","pt":1646318538605,"mc":[{"id":"1.195532859","rc":[{"atl":[[5.6,24.7]],"id":38983972}],"con":true,"img":false}]}
{"op":"mcm","clk":"5322292991","pt":1646318538706,"mc":[{"id":"1.195532859","rc":[{"atl":[[5.4,0]],"id":38983972},{"atl":[[2.84,23.72]],"id":39290878},{"atl":[[3.7,18.98]],"id":38357910}],"con":true,"img":false}]}
{"op":"mcm","clk":"5322293010","pt":1646318538913,"mc":[{"id":"1.195532859","rc":[{"atb":[[2.6,216.89]],"id":41288595},{"atl":[[5.6,16],[5.3,0],[5.5,16.59]],"id":38983972},{"atb":[[1.77,59.88]],"id":39290878},{"atl":[[2.88,21.28],[2.86,0]],"id":39290878},{"atb":[[1.87,9.03]],"id":38357910},{"atl":[[3.8,14.29],[3.75,0]],"id":38357910}],"con":true,"img":false}]}
{"op":"mcm","clk":"5322293020","pt":1646318539018,"mc":[{"id":"1.195532859","rc":[{"atl":[[5.3,2.1]],"id":38983972},{"atb":[[1.86,0]],"id":38357910},{"atl":[[4.7,2.21]],"id":40124755}],"con":true,"img":false}]}
{"op":"mcm","clk":"5322293031","pt":1646318539135,"mc":[{"id":"1.195532859","rc":[{"atl":[[6.4,23.52],[5.8,2.5],[7.4,0],[5.9,0],[5.4,10.27],[5.5,7.7],[5.7,8.51],[6.6,0]],"id":38983972},{"atl":[[2.84,0]],"id":39290878},{"atl":[[4.6,3.27]],"id":40124755}],"con":true,"img":false}]}
{"op":"mcm","clk":"5322293043","pt":1646318539229,"mc":[{"id":"1.195532859","rc":[{"atl":[[2.86,23.54]],"id":39290878},{"atl":[[3.7,0]],"id":38357910}],"con":true,"img":false}]}
{"op":"mcm","clk":"5322293054","pt":1646318539337,"mc":[{"id":"1.195532859","rc":[{"atl":[[3.75,17.49]],"id":38357910},{"atl":[[4.8,0]],"id":40124755}],"con":true,"img":false}]}
{"op":"mcm","clk":"5322293064","pt":1646318539438,"mc":[{"id":"1.195532859","rc":[{"atl":[[5.3,0]],"id":38983972}],"con":true,"img":false}]}
{"op":"mcm","clk":"5322293101","pt":1646318539704,"mc":[{"id":"1.195532859","rc":[{"atl":[[5.2,3]],"id":38983972}],"con":true,"img":false}]}
{"op":"mcm","clk":"5322293111","pt":1646318539810,"mc":[{"id":"1.195532859","rc":[{"atb":[[1.89,21.79]],"id":38357910}],"con":true,"img":false}]}
{"op":"mcm","clk":"5322293121","pt":1646318539913,"mc":[{"id":"1.195532859","rc":[{"atb":[[1.84,33.79]],"id":38357910}],"con":true,"img":false}]}
{"op":"mcm","clk":"5322293151","pt":1646318540228,"mc":[{"id":"1.195532859","rc":[{"atl":[[5.7,0],[5.4,19.36]],"id":38983972},{"atl":[[2.88,0],[2.9,73.67]],"id":39290878},{"atl":[[3.85,14.04],[3.8,0]],"id":38357910},{"atl":[[4.8,10.53],[5,0]],"id":40124755}],"con":true,"img":false}]}
{"op":"mcm","clk":"5322293163","pt":1646318540341,"mc":[{"id":"1.195532859","rc":[{"atl":[[2.92,72.91]],"id":39290878},{"atb":[[1.92,2.15],[1.88,0]],"id":38357910},{"atl":[[4.7,0]],"id":40124755}],"con":true,"img":false}]}
{"op":"mcm","clk":"5322293171","pt":1646318540437,"mc":[{"id":"1.195532859","rc":[{"atb":[[2.56,287.29],[2.6,93.75],[2.68,3.3]],"id":41288595},{"atb":[[2.64,0]],"id":38983972},{"atl":[[2.86,0],[2.9,21.04]],"id":39290878},{"atl":[[4.1,10.83]],"id":38357910},{"atb":[[2.38,3.3]],"id":40124755}],"con":true,"img":false}]}
{"op":"mcm","clk":"5322293183","pt":1646318540541,"mc":[{"id":"1.195532859","rc":[{"atl":[[4.6,0]],"id":40124755}],"con":true,"img":false}]}
{"op":"mcm","clk":"5322293193","pt":1646318540645,"mc":[{"id":"1.195532859","rc":[{"atb":[[2.48,2.5],[2.4,20.88]],"id":38983972},{"atl":[[2.88,25.24]],"id":39290878},{"atl":[[4.5,1.62],[4.7,4.93]],"id":40124755}],"con":true,"img":false}]}
{"op":"mcm","clk":"5322293205","pt":1646318540748,"mc":[{"id":"1.195532859","rc":[{"atl":[[2.84,2.48]],"id":39290878},{"atl":[[3.7,2.48]],"id":38357910}],"con":true,"img":false}]}
{"op":"mcm","clk":"5322293213","pt":1646318540829,"mc":[{"id":"1.195532859","rc":[{"atb":[[2.16,0]],"id":40124755}],"con":true,"img":false}]}
{"op":"mcm","clk":"5322293222","pt":1646318540931,"mc":[{"id":"1.195532859","rc":[{"atl":[[4.1,2.5]],"id":38357910}],"con":true,"img":false}]}
{"op":"mcm","clk":"5322293230","pt":1646318541038,"mc":[{"id":"1.195532859","rc":[{"atb":[[2.34,0]],"id":40124755}],"con":true,"img":false}]}
{"op":"mcm","clk":"5322293242","pt":1646318541141,"mc":[{"id":"1.195532859","rc":[{"atb":[[2.4,1.99]],"id":40124755}],"con":true,"img":false}]}
{"op":"mcm","clk":"5322293264","pt":1646318541305,"mc":[{"id":"1.195532859","rc":[{"atb":[[2.56,160.26],[2.6,173.26]],"id":41288595},{"atb":[[1.02,0]],"id":38983972}],"con":true,"img":false}]}
{"op":"mcm","clk":"5322293276","pt":1646318541402,"mc":[{"id":"1.195532859","rc":[{"atb":[[2.56,1.99]],"id":38983972}],"con":true,"img":false}]}
{"op":"mcm","clk":"5322293291","pt":1646318541608,"mc":[{"id":"1.195532859","rc":[{"atb":[[2.64,24.39]],"id":41288595},{"atl":[[5.8,20.83]],"id":41288595},{"atl":[[3.7,16.52]],"id":38357910}],"con":true,"img":false}]}
{"op":"mcm","clk":"5322293301","pt":1646318541711,"mc":[{"id":"1.195532859","rc":[{"atl":[[3.9,49.08]],"id":38357910}],"con":true,"img":false}]}
{"op":"mcm","clk":"5322293341","pt":1646318542128,"mc":[{"id":"1.195532859","rc":[{"atl":[[5.7,76.93],[5.9,0]],"id":41288595},{"atl":[[2.88,46.52],[2.9,0]],"id":39290878},{"atl":[[3.8,14.29]],"id":38357910},{"atl":[[4.8,0],[4.7,15.74]],"id":40124755}],"con":true,"img":false}]}
{"op":"mcm","clk":"5322293391","pt":1646318542661,"mc":[{"id":"1.195532859","rc":[{"atb":[[1.89,17.49]],"id":38357910}],"con":true,"img":false}]}
{"op":"mcm","clk":"5322293400","pt":1646318542706,"mc":[{"id":"1.195532859","rc":[{"atl":[[4.5,17.36],[5.3,23.26]],"id":40124755}],"con":true,"img":false}]}
{"op":"mcm","clk":"5322293429","pt":1646318543020,"mc":[{"id":"1.195532859","rc":[{"atb":[[1.87,0]],"id":38357910}],"con":true,"img":false}]}
{"op":"mcm","clk":"5322293440","pt":1646318543124,"mc":[{"id":"1.195532859","rc":[{"atb":[[1.83,4.89]],"id":39290878},{"atb":[[1.85,28.73]],"id":38357910},{"atb":[[2.28,0]],"id":40124755}],"con":true,"img":false}]}
{"op":"mcm","clk":"5322293451","pt":1646318543227,"mc":[{"id":"1.195532859","rc":[{"atb":[[1.86,4.51]],"id":38357910}],"con":true,"img":false}]}
{"op":"mcm","clk":"5322293462","pt":1646318543332,"mc":[{"id":"1.195532859","rc":[{"atb":[[1.77,0]],"id":39290878}],"con":true,"img":false}]}
{"op":"mcm","clk":"5322293471","pt":1646318543435,"mc":[{"id":"1.195532859","rc":[{"atb":[[1.68,3.57]],"id":38357910},{"atl":[[2,10.76]],"id":38357910}],"con":true,"img":false}]}
{"op":"mcm","clk":"5322293482","pt":1646318543541,"mc":[{"id":"1.195532859","rc":[{"atl":[[2,0]],"id":38357910},{"trd":[[2,21.53]],"ltp":2.0,"tv":21.53,"id":38357910}],"con":true,"img":false}]}
{"op":"mcm","clk":"5322293491","pt":1646318543644,"mc":[{"id":"1.195532859","rc":[{"atb":[[1.86,0]],"id":38357910}],"con":true,"img":false}]}
{"op":"mcm","clk":"5322293518","pt":1646318543851,"mc":[{"id":"1.195532859","rc":[{"atb":[[2.54,6.27]],"id":38983972}],"con":true,"img":false}]}
{"op":"mcm","clk":"5322293525","pt":1646318543903,"mc":[{"id":"1.195532859","rc":[{"atb":[[1.68,0]],"id":38357910}],"con":true,"img":false}]}
{"op":"mcm","clk":"5322293535","pt":1646318544015,"mc":[{"id":"1.195532859","rc":[{"atb":[[2.24,0]],"id":38983972},{"atl":[[5.1,7.7],[5.5,0]],"id":38983972}],"con":true,"img":false}]}
{"op":"mcm","clk":"5322293553","pt":1646318544214,"mc":[{"id":"1.195532859","rc":[{"atb":[[2.66,0]],"id":41288595},{"atb":[[2.36,0]],"id":40124755}],"con":true,"img":false}]}
{"op":"mcm","clk":"5322293571","pt":1646318544421,"mc":[{"id":"1.195532859","rc":[{"atb":[[2.7,1.65]],"id":41288595},{"atb":[[2.58,1.65]],"id":38983972},{"atb":[[2.42,1.65]],"id":40124755}],"con":true,"img":false}]}
{"op":"mcm","clk":"5322293582","pt":1646318544523,"mc":[{"id":"1.195532859","rc":[{"atb":[[1.85,71.24]],"id":38357910}],"con":true,"img":false}]}
{"op":"mcm","clk":"5322293589","pt":1646318544625,"mc":[{"id":"1.195532859","rc":[{"atb":[[1.84,0]],"id":38357910}],"con":true,"img":false}]}
{"op":"mcm","clk":"5322293642","pt":1646318545348,"mc":[{"id":"1.195532859","rc":[{"atb":[[2.5,5.96],[2.48,14.9]],"id":38983972},{"atb":[[1.8,4.14]],"id":39290878},{"atb":[[2.38,0]],"id":40124755}],"con":true,"img":false}]}
{"op":"mcm","clk":"5322293648","pt":1646318545455,"mc":[{"id":"1.195532859","rc":[{"atb":[[2.4,5]],"id":38983972}],"con":true,"img":false}]}
{"op":"mcm","clk":"5322293656","pt":1646318545507,"mc":[{"id":"1.195532859","rc":[{"atb":[[1.85,94.81]],"id":38357910},{"atb":[[2.34,5.29]],"id":40124755}],"con":true,"img":false}]}
{"op":"mcm","clk":"5322293673","pt":1646318545714,"mc":[{"id":"1.195532859","rc":[{"atb":[[2.4,0]],"id":40124755}],"con":true,"img":false}]}
{"op":"mcm","clk":"5322293684","pt":1646318545818,"mc":[{"id":"1.195532859","rc":[{"atb":[[2.36,1.99]],"id":40124755}],"con":true,"img":false}]}
{"op":"mcm","clk":"5322293721","pt":1646318546233,"mc":[{"id":"1.195532859","rc":[{"atl":[[5,6.95]],"id":38983972}],"con":true,"img":false}]}
{"op":"mcm","clk":"5322293728","pt":1646318546337,"mc":[{"id":"1.195532859","rc":[{"atl":[[5.4,33.57]],"id":38983972}],"con":true,"img":false}]}
{"op":"mcm","clk":"5322293739","pt":1646318546442,"mc":[{"id":"1.195532859","rc":[{"atl":[[5.6,0]],"id":38983972}],"con":true,"img":false}]}
{"op":"mcm","clk":"5322293770","pt":1646318546755,"mc":[{"id":"1.195532859","rc":[{"atb":[[2.64,0],[2.66,24.1]],"id":41288595},{"atl":[[5.2,12.52],[5.4,24.48]],"id":38983972}],"con":true,"img":false}]}
{"op":"mcm","clk":"5322293821","pt":1646318547224,"mc":[{"id":"1.195532859","rc":[{"atl":[[2.92,20.83],[2.84,49]],"id":39290878}],"con":true,"img":false}]}
{"op":"mcm","clk":"5322293929","pt":1646318548329,"mc":[{"id":"1.195532859","rc":[{"atb":[[2.6,93.75],[2.62,96.62]],"id":41288595}],"con":true,"img":false}]}
{"op":"mcm","clk":"5322293939","pt":1646318548431,"mc":[{"id":"1.195532859","rc":[{"atl":[[4.5,15.74]],"id":40124755}],"con":true,"img":false}]}
{"op":"mcm","clk":"5322293947","pt":1646318548538,"mc":[{"id":"1.195532859","rc":[{"atl":[[4.5,0],[5.1,43.67]],"id":40124755}],"con":true,"img":false}]}
{"op":"mcm","clk":"5322293960","pt":1646318548643,"mc":[{"id":"1.195532859","rc":[{"atl":[[5.1,26.89],[5.3,65.32]],"id":40124755}],"con":true,"img":false}]}
{"op":"mcm","clk":"5322293967","pt":1646318548751,"mc":[{"id":"1.195532859","rc":[{"atb":[[2.62,24.69]],"id":41288595},{"atb":[[2.3,0],[2.42,11.94]],"id":38983972},{"atb":[[5.6,21.74],[5.2,26.11]],"id":38324360},{"atb":[[1.81,2.5],[1.66,181.11]],"id":39290878},{"atl":[[2.84,68.29]],"id":39290878},{"atl":[[3.8,82.31],[3.9,0],[3.65,25.51]],"id":38357910},{"atl":[[4.9,10.26],[4.7,7.14]],"id":40124755}],"con":true,"img":false}]}
{"op":"mcm","clk":"5322293989","pt":1646318548960,"mc":[{"id":"1.195532859","rc":[{"atb":[[5.3,43.79],[5.2,0]],"id":38324360},{"atb":[[1.66,151.52]],"id":39290878},{"atl":[[2.92,72.27],[2.88,21.28]],"id":39290878},{"atb":[[1.85,66.07]],"id":38357910},{"atl":[[3.75,14.55]],"id":38357910}],"con":true,"img":false}]}
{"op":"mcm","clk":"5322293997","pt":1646318549010,"mc":[{"id":"1.195532859","rc":[{"atb":[[2.28,4.38]],"id":40124755}],"con":true,"img":false}]}
{"op":"mcm","clk":"5322294009","pt":1646318549117,"mc":[{"id":"1.195532859","rc":[{"atl":[[5.2,9.52]],"id":38983972},{"atb":[[5.1,14.99]],"id":38324360}],"con":true,"img":false}]}
{"op":"mcm","clk":"5322294020","pt":1646318549221,"mc":[{"id":"1.195532859","rc":[{"atl":[[5.1,0],[5.2,24.17]],"id":38983972}],"con":true,"img":false}]}
{"op":"mcm","clk":"5322294029","pt":1646318549323,"mc":[{"id":"1.195532859","rc":[{"atb":[[5.1,4]],"id":38324360},{"atb":[[1.78,4.88]],"id":39290878}],"con":true,"img":false}]}
{"op":"mcm","clk":"5322294038","pt":1646318549428,"mc":[{"id":"1.195532859","rc":[{"atl":[[5,0]],"id":38983972},{"atb":[[1.78,0]],"id":39290878}],"con":true,"img":false}]}
{"op":"mcm","clk":"5322294048","pt":1646318549531,"mc":[{"id":"1.195532859","rc":[{"atl":[[5.1,9.91]],"id":38983972}],"con":true,"img":false}]}
{"op":"mcm","clk":"5322294056","pt":1646318549634,"mc":[{"id":"1.195532859","rc":[{"atl":[[3.7,14.04]],"id":38357910}],"con":true,"img":false}]}
{"op":"mcm","clk":"5322294067","pt":1646318549739,"mc":[{"id":"1.195532859","rc":[{"atl":[[3.75,50.91]],"id":38357910}],"con":true,"img":false}]}
{"op":"mcm","clk":"5322294075","pt":1646318549843,"mc":[{"id":"1.195532859","rc":[{"atb":[[2.68,0]],"id":41288595},{"atb":[[2.5,0]],"id":38983972},{"atb":[[1.84,9.77]],"id":39290878},{"atb":[[1.86,8.07]],"id":38357910},{"atl":[[3.7,0]],"id":38357910},{"atb":[[2.44,3.3]],"id":40124755}],"con":true,"img":false}]}
{"op":"mcm","clk":"5322294084","pt":1646318549949,"mc":[{"id":"1.195532859","rc":[{"atl":[[5,3]],"id":38983972}],"con":true,"img":false}]}
{"op":"mcm","clk":"5322294114","pt":1646318550215,"mc":[{"id":"1.195532859","rc":[{"atb":[[1.83,2.9]],"id":39290878}],"con":true,"img":false}]}
{"op":"mcm","clk":"5322294121","pt":1646318550321,"mc":[{"id":"1.195532859","rc":[{"atb":[[1.85,1.99]],"id":39290878}],"con":true,"img":false}]}
{"op":"mcm","clk":"5322294140","pt":1646318550527,"mc":[{"id":"1.195532859","rc":[{"atl":[[5,0]],"id":38983972},{"atb":[[2.36,0]],"id":40124755},{"atl":[[4.5,7.83]],"id":40124755}],"con":true,"img":false}]}
{"op":"mcm","clk":"5322294151","pt":1646318550634,"mc":[{"id":"1.195532859","rc":[{"atb":[[2.46,1.99]],"id":40124755}],"con":true,"img":false}]}
{"op":"mcm","clk":"5322294163","pt":1646318550739,"mc":[{"id":"1.195532859","rc":[{"atl":[[5.4,36.56]],"id":38983972},{"atl":[[5.3,23.26],[4.9,38.44],[4.7,2.21]],"id":40124755}],"con":true,"img":false}]}
{"op":"mcm","clk":"5322294177","pt":1646318550841,"mc":[{"id":"1.195532859","rc":[{"atb":[[1.87,2.15],[1.82,0]],"id":39290878},{"atb":[[2.32,0],[2.4,2.15]],"id":40124755}],"con":true,"img":false}]}
{"op":"mcm","clk":"5322294187","pt":1646318550950,"mc":[{"id":"1.195532859","rc":[{"atl":[[5.4,24.48]],"id":38983972},{"atl":[[3.6,2.48]],"id":38357910}],"con":true,"img":false}]}
{"op":"mcm","clk":"5322294207","pt":1646318551156,"mc":[{"id":"1.195532859","rc":[{"atb":[[1.8,0]],"id":39290878},{"atb":[[1.83,27.49],[1.85,42.51]],"id":38357910},{"atb":[[2.34,0]],"id":40124755}],"con":true,"img":false}]}
{"op":"mcm","clk":"5322294217","pt":1646318551262,"mc":[{"id":"1.195532859","rc":[{"atl":[[5.3,9.3],[5.2,14.65]],"id":38983972},{"atl":[[4.9,28.18],[4.7,13.02]],"id":40124755}],"con":true,"img":false}]}
{"op":"mcm","clk":"5322294229","pt":1646318551316,"mc":[{"id":"1.195532859","rc":[{"atb":[[2.7,0]],"id":41288595},{"atb":[[2.42,0],[2.28,16.47]],"id":40124755},{"atl":[[4.7,10.81]],"id":40124755}],"con":true,"img":false}]}
{"op":"mcm","clk":"5322294236","pt":1646318551420,"mc":[{"id":"1.195532859","rc":[{"atb":[[2.68,1.65]],"id":41288595},{"atb":[[2.48,1.65]],"id":40124755}],"con":true,"img":false}]}
{"op":"mcm","clk":"5322294247","pt":1646318551524,"mc":[{"id":"1.195532859","rc":[{"atb":[[2.28,4.38]],"id":40124755}],"con":true,"img":false}]}
{"op":"mcm","clk":"5322294256","pt":1646318551628,"mc":[{"id":"1.195532859","rc":[{"atl":[[4.5,9.45]],"id":40124755}],"con":true,"img":false}]}
{"op":"mcm","clk":"5322294266","pt":1646318551733,"mc":[{"id":"1.195532859","rc":[{"atb":[[1.85,0]],"id":39290878}],"con":true,"img":false}]}
{"op":"mcm","clk":"5322294274","pt":1646318551835,"mc":[{"id":"1.195532859","rc":[{"atb":[[1.88,1.99]],"id":39290878}],"con":true,"img":false}]}
{"op":"mcm","clk":"5322294284","pt":1646318551938,"mc":[{"id":"1.195532859","rc":[{"atl":[[3.55,19.17]],"id":38357910}],"con":true,"img":false}]}
{"op":"mcm","clk":"5322294298","pt":1646318552148,"mc":[{"id":"1.195532859","rc":[{"atb":[[5.3,32.9]],"id":38324360},{"atl":[[3.65,0]],"id":38357910}],"con":true,"img":false}]}
{"op":"mcm","clk":"5322294343","pt":1646318552564,"mc":[{"id":"1.195532859","rc":[{"atb":[[2.66,0],[2.64,24.39]],"id":41288595}],"con":true,"img":false}]}
{"op":"mcm","clk":"5322294360","pt":1646318552719,"mc":[{"id":"1.195532859","rc":[{"atl":[[2.92,103.52]],"id":39290878}],"con":true,"img":false}]}
{"op":"mcm","clk":"5322294370","pt":1646318552825,"mc":[{"id":"1.195532859","rc":[{"atl":[[4.5,7.83]],"id":40124755}],"con":true,"img":false}]}
{"op":"mcm","clk":"5322294382","pt":1646318552928,"mc":[{"id":"1.195532859","rc":[{"atb":[[1.83,0]],"id":39290878}],"con":true,"img":false}]}
{"op":"mcm","clk":"5322294406","pt":1646318553138,"mc":[{"id":"1.195532859","rc":[{"atl":[[4.7,13.02]],"id":40124755}],"con":true,"img":false}]}
{"op":"mcm","clk":"5322294417","pt":1646318553242,"mc":[{"id":"1.195532859","rc":[{"atl":[[5.3,47.72],[5.4,0]],"id":38983972}],"con":true,"img":false}]}
{"op":"mcm","clk":"5322294461","pt":1646318553659,"mc":[{"id":"1.195532859","rc":[{"atl":[[3.65,15.09]],"id":38357910}],"con":true,"img":false}]}
{"op":"mcm","clk":"5322294483","pt":1646318553922,"mc":[{"id":"1.195532859","rc":[{"atl":[[3.6,0]],"id":38357910},{"atl":[[4.5,5.49],[5.1,32.58]],"id":40124755}],"con":true,"img":false}]}
{"op":"mcm","clk":"5322294493","pt":1646318554026,"mc":[{"id":"1.195532859","rc":[{"atl":[[3.55,0]],"id":38357910},{"atl":[[4.5,0],[5.1,26.89],[4.6,6.59]],"id":40124755}],"con":true,"img":false}]}
{"op":"mcm","clk":"5322294510","pt":1646318554235,"mc":[{"id":"1.195532859","rc":[{"atl":[[3.6,17.37]],"id":38357910},{"atl":[[4.8,10.53],[4.7,2.21]],"id":40124755}],"con":true,"img":false}]}
{"op":"mcm","clk":"5322294519","pt":1646318554338,"mc":[{"id":"1.195532859","rc":[{"atl":[[5.2,0]],"id":38983972}],"con":true,"img":false}]}
{"op":"mcm","clk":"5322294530","pt":1646318554444,"mc":[{"id":"1.195532859","rc":[{"atl":[[5.3,70.98]],"id":38983972}],"con":true,"img":false}]}
{"op":"mcm","clk":"5322294538","pt":1646318554549,"mc":[{"id":"1.195532859","rc":[{"atl":[[5.8,23.33]],"id":38983972},{"atb":[[1.92,26.49]],"id":38357910}],"con":true,"img":false}]}
{"op":"mcm","clk":"5322294547","pt":1646318554653,"mc":[{"id":"1.195532859","rc":[{"atl":[[5.3,47.72]],"id":38983972}],"con":true,"img":false}]}
{"op":"mcm","clk":"5322294558","pt":1646318554757,"mc":[{"id":"1.195532859","rc":[{"atb":[[1.89,0]],"id":38357910}],"con":true,"img":false}]}
{"op":"mcm","clk":"5322294576","pt":1646318554916,"mc":[{"id":"1.195532859","rc":[{"atb":[[1.9,13.74]],"id":38357910},{"atb":[[2.3,5.83]],"id":40124755}],"con":true,"img":false}]}
{"op":"mcm","clk":"5322294595","pt":1646318555126,"mc":[{"id":"1.195532859","rc":[{"atb":[[1.82,5.38]],"id":39290878},{"atb":[[1.83,0]],"id":38357910},{"atb":[[2.28,0]],"id":40124755}],"con":true,"img":false}]}
{"op":"mcm","clk":"5322294621","pt":1646318555441,"mc":[{"id":"1.195532859","rc":[{"atl":[[5.1,2.5],[4.7,15.39]],"id":40124755}],"con":true,"img":false}]}
{"op":"mcm","clk":"5322294629","pt":1646318555544,"mc":[{"id":"1.195532859","rc":[{"atl":[[4.8,36.85]],"id":40124755}],"con":true,"img":false}]}
{"op":"mcm","clk":"5322294643","pt":1646318555648,"mc":[{"id":"1.195532859","rc":[{"atl":[[4.7,2.21]],"id":40124755}],"con":true,"img":false}]}
{"op":"mcm","clk":"5322294652","pt":1646318555753,"mc":[{"id":"1.195532859","rc":[{"atb":[[2.6,3.3]],"id":38983972},{"atb":[[1.84,0]],"id":39290878},{"atb":[[2.44,0]],"id":40124755}],"con":true,"img":false}]}
{"op":"mcm","clk":"5322294663","pt":1646318555858,"mc":[{"id":"1.195532859","rc":[{"atb":[[2.54,26.5],[2.48,2.5]],"id":38983972}],"con":true,"img":false}]}
{"op":"mcm","clk":"5322294680","pt":1646318556026,"mc":[{"id":"1.195532859","rc":[{"atb":[[2.46,0]],"id":40124755}],"con":true,"img":false}]}
{"op":"mcm","clk":"5322294690","pt":1646318556122,"mc":[{"id":"1.195532859","rc":[{"atl":[[3.55,2.48]],"id":38357910},{"atb":[[2.42,1.99]],"id":40124755}],"con":true,"img":false}]}
{"op":"mcm","clk":"5322294717","pt":1646318556332,"mc":[{"id":"1.195532859","rc":[{"atb":[[2.56,0]],"id":38983972}],"con":true,"img":false}]}
{"op":"mcm","clk":"5322294722","pt":1646318556435,"mc":[{"id":"1.195532859","rc":[{"atb":[[1.02,1.99]],"id":38983972}],"con":true,"img":false}]}
{"op":"mcm","clk":"5322294741","pt":1646318556642,"mc":[{"id":"1.195532859","rc":[{"atl":[[3.55,17.57],[3.75,14.55]],"id":38357910}],"con":true,"img":false}]}
{"op":"mcm","clk":"5322294770","pt":1646318556956,"mc":[{"id":"1.195532859","rc":[{"atb":[[1.82,10.76]],"id":39290878},{"atl":[[4.7,0]],"id":40124755}],"con":true,"img":false}]}
{"op":"mcm","clk":"5322294807","pt":1646318557218,"mc":[{"id":"1.195532859","rc":[{"atl":[[5.4,3]],"id":38983972},{"atl":[[4.5,1.62]],"id":40124755}],"con":true,"img":false}]}
{"op":"mcm","clk":"5322294821","pt":1646318557323,"mc":[{"id":"1.195532859","rc":[{"atb":[[2.62,27.74]],"id":41288595},{"atl":[[5.8,2.5],[5.3,70.98]],"id":38983972},{"atl":[[4.5,4.72]],"id":40124755}],"con":true,"img":false}]}
{"op":"mcm","clk":"5322294830","pt":1646318557427,"mc":[{"id":"1.195532859","rc":[{"atl":[[4.6,0]],"id":40124755}],"con":true,"img":false}]}
{"op":"mcm","clk":"5322294838","pt":1646318557533,"mc":[{"id":"1.195532859","rc":[{"atb":[[2.62,24.69]],"id":41288595}],"con":true,"img":false}]}
{"op":"mcm","clk":"5322294865","pt":1646318557846,"mc":[{"id":"1.195532859","rc":[{"atl":[[4.7,10.81]],"id":40124755}],"con":true,"img":false}]}
{"op":"mcm","clk":"5322294879","pt":1646318557950,"mc":[{"id":"1.195532859","rc":[{"atl":[[4.8,26.32]],"id":40124755}],"con":true,"img":false}]}
{"op":"mcm","clk":"5322294900","pt":1646318558158,"mc":[{"id":"1.195532859","rc":[{"atb":[[2.68,0]],"id":41288595},{"atb":[[2.58,0]],"id":38983972},{"atb":[[2.48,0]],"id":40124755}],"con":true,"img":false}]}
{"op":"mcm","clk":"5322294911","pt":1646318558265,"mc":[{"id":"1.195532859","rc":[{"atb":[[2.66,1.65]],"id":41288595},{"atb":[[2.44,1.65]],"id":40124755}],"con":true,"img":false}]}
{"op":"mcm","clk":"5322294924","pt":1646318558366,"mc":[{"id":"1.195532859","rc":[{"atb":[[2.64,0],[2.6,25],[2.62,36.38]],"id":41288595},{"atb":[[5.7,9.96]],"id":38324360},{"atb":[[1.86,0]],"id":38357910}],"con":true,"img":false}]}
{"op":"mcm","clk":"5322294944","pt":1646318558528,"mc":[{"id":"1.195532859","rc":[{"atb":[[2.56,239.06],[2.66,3.13]],"id":41288595},{"atb":[[2.6,4.79]],"id":38983972},{"atb":[[6.2,1.44]],"id":38324360},{"atb":[[1.88,3.5]],"id":39290878},{"atb":[[1.93,1.44]],"id":38357910},{"atb":[[2.42,3.51]],"id":40124755}],"con":true,"img":false}]}
{"op":"mcm","clk":"5322294954","pt":1646318558628,"mc":[{"id":"1.195532859","rc":[{"atb":[[6.2,16.09]],"id":38324360}],"con":true,"img":false}]}
{"op":"mcm","clk":"5322294964","pt":1646318558733,"mc":[{"id":"1.195532859","rc":[{"atb":[[2.56,160.26]],"id":41288595}],"con":true,"img":false}]}
{"op":"mcm","clk":"5322294976","pt":1646318558837,"mc":[{"id":"1.195532859","rc":[{"atb":[[2.62,24.69]],"id":41288595},{"atb":[[2.56,3.58]],"id":38983972},{"atb":[[6,1.65]],"id":38324360},{"atl":[[4.5,3.1]],"id":40124755}],"con":true,"img":false}]}
{"op":"mcm","clk":"5322294989","pt":1646318559043,"mc":[{"id":"1.195532859","rc":[{"atb":[[2.56,0]],"id":38983972},{"atb":[[1.9,0]],"id":38357910},{"atb":[[2.3,0]],"id":40124755},{"atl":[[4.5,0]],"id":40124755}],"con":true,"img":false}]}
{"op":"mcm","clk":"5322294998","pt":1646318559147,"mc":[{"id":"1.195532859","rc":[{"atb":[[1.82,56.44],[1.85,0]],"id":38357910},{"atl":[[4.6,6.92]],"id":40124755}],"con":true,"img":false}]}
{"op":"mcm","clk":"5322295010","pt":1646318559252,"mc":[{"id":"1.195532859","rc":[{"atl":[[4.9,38.44],[4.7,0]],"id":40124755}],"con":true,"img":false}]}
{"op":"mcm","clk":"5322295024","pt":1646318559354,"mc":[{"id":"1.195532859","rc":[{"atl":[[5.4,0]],"id":38983972},{"atb":[[1.87,34.44]],"id":38357910},{"atb":[[2.32,4.73]],"id":40124755},{"atl":[[4.8,36.85]],"id":40124755}],"con":true,"img":false}]}
{"op":"mcm","clk":"5322295044","pt":1646318559562,"mc":[{"id":"1.195532859","rc":[{"atb":[[2.66,1.65]],"id":41288595},{"atl":[[5.8,23.33],[5.3,47.72]],"id":38983972}],"con":true,"img":false}]}
{"op":"mcm","clk":"5322295056","pt":1646318559665,"mc":[{"id":"1.195532859","rc":[{"atb":[[2.64,1.48]],"id":41288595}],"con":true,"img":false}]}
{"op":"mcm","clk":"5322295098","pt":1646318560032,"mc":[{"id":"1.195532859","rc":[{"atl":[[5.8,81.81],[5.3,9.3]],"id":38983972}],"con":true,"img":false}]}
{"op":"mcm","clk":"5322295161","pt":1646318560656,"mc":[{"id":"1.195532859","rc":[{"atl":[[5.2,4.02]],"id":38983972}],"con":true,"img":false}]}
{"op":"mcm","clk":"5322295193","pt":1646318560966,"mc":[{"id":"1.195532859","rc":[{"atl":[[5.8,23.33],[5.3,37.48]],"id":38983972}],"con":true,"img":false}]}
{"op":"mcm","clk":"5322295235","pt":1646318561334,"mc":[{"id":"1.195532859","rc":[{"atb":[[2.68,3.3]],"id":41288595},{"atb":[[1.83,6.96]],"id":39290878},{"atb":[[2.46,3.3]],"id":40124755}],"con":true,"img":false}]}
{"op":"mcm","clk":"5322295288","pt":1646318561749,"mc":[{"id":"1.195532859","rc":[{"atl":[[5.8,27.15],[5.5,22.22]],"id":38983972}],"con":true,"img":false}]}
{"op":"mcm","clk":"5322295304","pt":1646318561958,"mc":[{"id":"1.195532859","rc":[{"atb":[[2.6,34.1]],"id":41288595}],"con":true,"img":false}]}
{"op":"mcm","clk":"5322295325","pt":1646318562165,"mc":[{"id":"1.195532859","rc":[{"atb":[[2.6,25]],"id":41288595},{"atl":[[5.8,23.33]],"id":38983972},{"atb":[[2.42,1.52]],"id":40124755}],"con":true,"img":false}]}
{"op":"mcm","clk":"5322295336","pt":1646318562269,"mc":[{"id":"1.195532859","rc":[{"atb":[[2.48,1.99]],"id":40124755}],"con":true,"img":false}]}
{"op":"mcm","clk":"5322295347","pt":1646318562324,"mc":[{"id":"1.195532859","rc":[{"atl":[[4.8,10.53]],"id":40124755}],"con":true,"img":false}]}
{"op":"mcm","clk":"5322295358","pt":1646318562440,"mc":[{"id":"1.195532859","rc":[{"atb":[[2.64,0]],"id":41288595},{"atb":[[2.42,0]],"id":40124755},{"atl":[[4.6,34.7]],"id":40124755}],"con":true,"img":false}]}
{"op":"mcm","clk":"5322295367","pt":1646318562531,"mc":[{"id":"1.195532859","rc":[{"atb":[[2.68,4.78]],"id":41288595},{"atb":[[2.46,4.82]],"id":40124755}],"con":true,"img":false}]}
{"op":"mcm","clk":"5322295378","pt":1646318562636,"mc":[{"id":"1.195532859","rc":[{"atb":[[2.54,6.27],[2.48,20.88]],"id":38983972}],"con":true,"img":false}]}
{"op":"mcm","clk":"5322295400","pt":1646318562843,"mc":[{"id":"1.195532859","rc":[{"atb":[[1.83,43.93]],"id":38357910},{"atb":[[2.28,7.74]],"id":40124755}],"con":true,"img":false}]}
{"op":"mcm","clk":"5322295419","pt":1646318563051,"mc":[{"id":"1.195532859","rc":[{"atb":[[1.87,0]],"id":38357910}],"con":true,"img":false}]}
{"op":"mcm","clk":"5322295427","pt":1646318563155,"mc":[{"id":"1.195532859","rc":[{"atl":[[2.96,76.53]],"id":39290878}],"con":true,"img":false}]}
{"op":"mcm","clk":"5322295449","pt":1646318563363,"mc":[{"id":"1.195532859","rc":[{"atl":[[3.8,14.29],[3.5,26.2],[3.65,106.09]],"id":38357910},{"atb":[[2.46,3.3]],"id":40124755}],"con":true,"img":false}]}
{"op":"mcm","clk":"5322295456","pt":1646318563466,"mc":[{"id":"1.195532859","rc":[{"atl":[[3.45,17.57]],"id":38357910},{"atb":[[2.48,3.51]],"id":40124755}],"con":true,"img":false}]}
{"op":"mcm","clk":"5322295463","pt":1646318563571,"mc":[{"id":"1.195532859","rc":[{"atb":[[5.3,0],[5.6,56.39]],"id":38324360},{"atl":[[3.6,0],[3.55,2.48],[3.7,5.67]],"id":38357910}],"con":true,"img":false}]}
{"op":"mcm","clk":"5322295473","pt":1646318563626,"mc":[{"id":"1.195532859","rc":[{"atl":[[3.7,0]],"id":38357910}],"con":true,"img":false}]}
{"op":"mcm","clk":"5322295479","pt":1646318563730,"mc":[{"id":"1.195532859","rc":[{"atb":[[2.6,1.49]],"id":38983972},{"atb":[[5.7,0]],"id":38324360},{"atb":[[1.88,5.05]],"id":38357910}],"con":true,"img":false}]}
{"op":"mcm","clk":"5322295489","pt":1646318563833,"mc":[{"id":"1.195532859","rc":[{"atb":[[2.56,12.14]],"id":38983972}],"con":true,"img":false}]}
{"op":"mcm","clk":"5322295496","pt":1646318563936,"mc":[{"id":"1.195532859","rc":[{"atb":[[2.54,2.15]],"id":38983972}],"con":true,"img":false}]}
{"op":"mcm","clk":"5322295502","pt":1646318564043,"mc":[{"id":"1.195532859","rc":[{"atb":[[1.02,0]],"id":38983972},{"atl":[[3.55,15.69],[3.65,91]],"id":38357910}],"con":true,"img":false}]}
{"op":"mcm","clk":"5322295510","pt":1646318564149,"mc":[{"id":"1.195532859","rc":[{"atb":[[2.56,14.13]],"id":38983972}],"con":true,"img":false}]}
{"op":"mcm","clk":"5322295525","pt":1646318564359,"mc":[{"id":"1.195532859","rc":[{"atb":[[2.6,0]],"id":38983972}],"con":true,"img":false}]}
{"op":"mcm","clk":"5322295533","pt":1646318564461,"mc":[{"id":"1.195532859","rc":[{"atb":[[2.54,0],[2.58,1.49],[2.62,2.15]],"id":38983972}],"con":true,"img":false}]}
{"op":"mcm","clk":"5322295553","pt":1646318564676,"mc":[{"id":"1.195532859","rc":[{"atb":[[1.82,5.38]],"id":39290878}],"con":true,"img":false}]}
{"op":"mcm","clk":"5322295564","pt":1646318564775,"mc":[{"id":"1.195532859","rc":[{"atl":[[3.4,2.48]],"id":38357910}],"con":true,"img":false}]}
{"op":"mcm","clk":"5322295574","pt":1646318564881,"mc":[{"id":"1.195532859","rc":[{"atb":[[1.82,0]],"id":39290878},{"atb":[[2.32,0]],"id":40124755}],"con":true,"img":false}]}
{"op":"mcm","clk":"5322295618","pt":1646318565246,"mc":[{"id":"1.195532859","rc":[{"atb":[[2.66,0]],"id":41288595},{"atb":[[2.58,0],[2.56,12.14]],"id":38983972},{"atb":[[6,0]],"id":38324360},{"atb":[[2.44,0]],"id":40124755}],"con":true,"img":false}]}
{"op":"mcm","clk":"5322295627","pt":1646318565351,"mc":[{"id":"1.195532859","rc":[{"atb":[[2.62,3.64],[1.02,1.99]],"id":38983972}],"con":true,"img":false}]}
{"op":"mcm","clk":"5322295639","pt":1646318565455,"mc":[{"id":"1.195532859","rc":[{"atb":[[2.7,1.65]],"id":41288595},{"atb":[[2.5,1.65]],"id":40124755}],"con":true,"img":false}]}
{"op":"mcm","clk":"5322295658","pt":1646318565668,"mc":[{"id":"1.195532859","rc":[{"atb":[[2.66,24.1]],"id":41288595},{"atl":[[7.2,0],[6.4,5],[6.8,0]],"id":38983972},{"atl":[[2.98,0],[2.94,0],[2.96,87.23]],"id":39290878},{"atl":[[3.55,0],[3.5,42.2]],"id":38357910},{"atl":[[5.3,0],[5.5,5],[4.9,28.18],[5.7,0]],"id":40124755}],"con":true,"img":false}]}
{"op":"mcm","clk":"5322295678","pt":1646318565871,"mc":[{"id":"1.195532859","rc":[{"atl":[[2.96,76.53]],"id":39290878}],"con":true,"img":false}]}
{"op":"mcm","clk":"5322295701","pt":1646318566081,"mc":[{"id":"1.195532859","rc":[{"atb":[[2.46,0]],"id":40124755}],"con":true,"img":false}]}
{"op":"mcm","clk":"5322295725","pt":1646318566245,"mc":[{"id":"1.195532859","rc":[{"atl":[[5.1,19.82],[5.8,2.5]],"id":38983972},{"atb":[[2.28,30.59]],"id":40124755}],"con":true,"img":false}]}
{"op":"mcm","clk":"5322295734","pt":1646318566343,"mc":[{"id":"1.195532859","rc":[{"atb":[[2.44,4.65]],"id":40124755}],"con":true,"img":false}]}
{"op":"mcm","clk":"5322295744","pt":1646318566454,"mc":[{"id":"1.195532859","rc":[{"atl":[[3.35,16.96]],"id":38357910},{"atb":[[2.44,0],[2.28,7.74]],"id":40124755}],"con":true,"img":false}]}
{"op":"mcm","clk":"5322295763","pt":1646318566659,"mc":[{"id":"1.195532859","rc":[{"atl":[[3.5,16]],"id":38357910}],"con":true,"img":false}]}
{"op":"mcm","clk":"5322295775","pt":1646318566769,"mc":[{"id":"1.195532859","rc":[{"atb":[[1.84,43.41]],"id":38357910},{"atb":[[2.28,0]],"id":40124755}],"con":true,"img":false}]}
{"op":"mcm","clk":"5322295831","pt":1646318567236,"mc":[{"id":"1.195532859","rc":[{"atb":[[2.48,1.99]],"id":40124755}],"con":true,"img":false}]}
{"op":"mcm","clk":"5322295847","pt":1646318567347,"mc":[{"id":"1.195532859","rc":[{"atb":[[1.01,4805.56]],"id":40124755}],"con":true,"img":false}]}
{"op":"mcm","clk":"5322295859","pt":1646318567448,"mc":[{"id":"1.195532859","rc":[{"atl":[[3.5,0],[3.45,33.9]],"id":38357910}],"con":true,"img":false}]}
{"op":"mcm","clk":"5322295873","pt":1646318567549,"mc":[{"id":"1.195532859","rc":[{"atl":[[5.2,0]],"id":38983972},{"atl":[[3.4,0]],"id":38357910}],"con":true,"img":false}]}
{"op":"mcm","clk":"5322295885","pt":1646318567657,"mc":[{"id":"1.195532859","rc":[{"atl":[[5.3,9.3],[5.5,107.1]],"id":38983972},{"atl":[[3.35,0]],"id":38357910},{"atb":[[2.48,0]],"id":40124755}],"con":true,"img":false}]}
{"op":"mcm","clk":"5322295896","pt":1646318567756,"mc":[{"id":"1.195532859","rc":[{"atl":[[5.1,9.91]],"id":38983972},{"atb":[[2.42,1.99]],"id":40124755}],"con":true,"img":false}]}
{"op":"mcm","clk":"5322295905","pt":1646318567859,"mc":[{"id":"1.195532859","rc":[{"atl":[[3.4,23.66]],"id":38357910}],"con":true,"img":false}]}
{"op":"mcm","clk":"5322295934","pt":1646318568276,"mc":[{"id":"1.195532859","rc":[{"atb":[[1.01,4804.04]],"id":40124755}],"con":true,"img":false}]}
{"op":"mcm","clk":"5322295945","pt":1646318568380,"mc":[{"id":"1.195532859","rc":[{"atb":[[2.42,3.51]],"id":40124755}],"con":true,"img":false}]}
{"op":"mcm","clk":"5322295976","pt":1646318568640,"mc":[{"id":"1.195532859","rc":[{"atl":[[3.45,16.33],[3.65,128.74]],"id":38357910}],"con":true,"img":false}]}
{"op":"mcm","clk":"5322295984","pt":1646318568745,"mc":[{"id":"1.195532859","rc":[{"atb":[[1.83,0]],"id":38357910}],"con":true,"img":false}]}
{"op":"mcm","clk":"5322295996","pt":1646318568850,"mc":[{"id":"1.195532859","rc":[{"atb":[[1.84,4.2]],"id":39290878}],"con":true,"img":false}]}
{"op":"mcm","clk":"5322296003","pt":1646318568961,"mc":[{"id":"1.195532859","rc":[{"atb":[[1.84,8.41]],"id":39290878},{"atl":[[3.35,2.48]],"id":38357910},{"atb":[[2.16,12.39]],"id":40124755}],"con":true,"img":false}]}
{"op":"mcm","clk":"5322296015","pt":1646318569074,"mc":[{"id":"1.195532859","rc":[{"atl":[[3.3,16.04]],"id":38357910}],"con":true,"img":false}]}
{"op":"mcm","clk":"5322296035","pt":1646318569268,"mc":[{"id":"1.195532859","rc":[{"atb":[[2.68,1.48]],"id":41288595},{"atb":[[2.5,13.65]],"id":38983972},{"atb":[[5.7,9.96]],"id":38324360},{"atl":[[3.4,0]],"id":38357910}],"con":true,"img":false}]}
{"op":"mcm","clk":"5322296077","pt":1646318569701,"mc":[{"id":"1.195532859","rc":[{"atl":[[5,25]],"id":40124755}],"con":true,"img":false}]}
{"op":"mcm","clk":"5322296107","pt":1646318570000,"mc":[{"id":"1.195532859","rc":[{"atl":[[3.35,0]],"id":38357910}],"con":true,"img":false}]}
{"op":"mcm","clk":"5322296133","pt":1646318570336,"mc":[{"id":"1.195532859","rc":[{"atb":[[2.5,41.21],[2.48,2.5]],"id":38983972},{"atl":[[3.3,0]],"id":38357910}],"con":true,"img":false}]}
{"op":"mcm","clk":"5322296148","pt":1646318570467,"mc":[{"id":"1.195532859","rc":[{"atl":[[3.35,24.28],[3.65,37.74],[3.75,103.07]],"id":38357910}],"con":true,"img":false}]}
{"op":"mcm","clk":"5322296175","pt":1646318570781,"mc":[{"id":"1.195532859","rc":[{"atl":[[3.35,0]],"id":38357910}],"con":true,"img":false}]}
{"op":"mcm","clk":"5322296187","pt":1646318570886,"mc":[{"id":"1.195532859","rc":[{"atl":[[3.4,30.46]],"id":38357910}],"con":true,"img":false}]}
{"op":"mcm","clk":"5322296196","pt":1646318570990,"mc":[{"id":"1.195532859","rc":[{"atb":[[2.16,23.24]],"id":40124755}],"con":true,"img":false}]}
{"op":"mcm","clk":"5322296256","pt":1646318571668,"mc":[{"id":"1.195532859","rc":[{"atb":[[1.83,0]],"id":39290878},{"atb":[[1.88,0]],"id":38357910},{"atb":[[2.44,4.95]],"id":40124755}],"con":true,"img":false}]}
{"op":"mcm","clk":"5322296287","pt":1646318571990,"mc":[{"id":"1.195532859","rc":[{"atl":[[5.7,31.91]],"id":38983972}],"con":true,"img":false}]}
{"op":"mcm","clk":"5322296294","pt":1646318572082,"mc":[{"id":"1.195532859","rc":[{"atb":[[2.42,1.99]],"id":40124755}],"con":true,"img":false}]}
{"op":"mcm","clk":"5322296302","pt":1646318572184,"mc":[{"id":"1.195532859","rc":[{"atb":[[2.7,0]],"id":41288595},{"atb":[[1.83,8.88]],"id":38357910},{"atb":[[2.5,0],[2.46,1.52]],"id":40124755}],"con":true,"img":false}]}
{"op":"mcm","clk":"5322296310","pt":1646318572290,"mc":[{"id":"1.195532859","rc":[{"atl":[[3.45,0],[3.8,20.87],[3.5,16]],"id":38357910}],"con":true,"img":false}]}
{"op":"mcm","clk":"5322296316","pt":1646318572394,"mc":[{"id":"1.195532859","rc":[{"atb":[[2.68,3.13]],"id":41288595},{"atb":[[1.83,0]],"id":38357910},{"atb":[[2.46,3.17]],"id":40124755}],"con":true,"img":false}]}
{"op":"mcm","clk":"5322296327","pt":1646318572503,"mc":[{"id":"1.195532859","rc":[{"atl":[[3.35,2.48],[3.4,0]],"id":38357910}],"con":true,"img":false}]}
{"op":"mcm","clk":"5322296338","pt":1646318572555,"mc":[{"id":"1.195532859","rc":[{"atl":[[3.45,32.65]],"id":38357910},{"atb":[[2.42,0]],"id":40124755}],"con":true,"img":false}]}
{"op":"mcm","clk":"5322296347","pt":1646318572685,"mc":[{"id":"1.195532859","rc":[{"atb":[[2.46,5.16]],"id":40124755}],"con":true,"img":false}]}
{"op":"mcm","clk":"5322296367","pt":1646318572847,"mc":[{"id":"1.195532859","rc":[{"atl":[[3.8,14.29]],"id":38357910}],"con":true,"img":false}]}
{"op":"mcm","clk":"5322296388","pt":1646318573157,"mc":[{"id":"1.195532859","rc":[{"atb":[[1.84,0],[1.85,41.89]],"id":38357910}],"con":true,"img":false}]}
{"op":"mcm","clk":"5322296416","pt":1646318573483,"mc":[{"id":"1.195532859","rc":[{"atl":[[3,129]],"id":39290878}],"con":true,"img":false}]}
{"op":"mcm","clk":"5322296566","pt":1646318575208,"mc":[{"id":"1.195532859","rc":[{"atb":[[1.84,4.2]],"id":39290878},{"atb":[[2.16,10.84]],"id":40124755}],"con":true,"img":false}]}
{"op":"mcm","clk":"5322296575","pt":1646318575301,"mc":[{"id":"1.195532859","rc":[{"atb":[[1.84,0]],"id":39290878},{"atb":[[2.16,0]],"id":40124755}],"con":true,"img":false}]}
{"op":"mcm","clk":"5322296587","pt":1646318575358,"mc":[{"id":"1.195532859","rc":[{"atl":[[3.35,18.48],[3.65,0]],"id":38357910}],"con":true,"img":false}]}
{"op":"mcm","clk":"5322296593","pt":1646318575463,"mc":[{"id":"1.195532859","rc":[{"atl":[[3.5,53.74]],"id":38357910}],"con":true,"img":false}]}
{"op":"mcm","clk":"5322296603","pt":1646318575568,"mc":[{"id":"1.195532859","rc":[{"atl":[[3.35,2.48]],"id":38357910}],"con":true,"img":false}]}
{"op":"mcm","clk":"5322296637","pt":1646318575882,"mc":[{"id":"1.195532859","rc":[{"atb":[[2.66,0],[2.64,24.39]],"id":41288595},{"atl":[[6,30]],"id":41288595}],"con":true,"img":false}]}
{"op":"mcm","clk":"5322296647","pt":1646318575990,"mc":[{"id":"1.195532859","rc":[{"atl":[[3.45,48.98],[3.5,37.74]],"id":38357910}],"con":true,"img":false}]}
{"op":"mcm","clk":"5322296715","pt":1646318576671,"mc":[{"id":"1.195532859","rc":[{"atl":[[5.4,5.86]],"id":38983972}],"con":true,"img":false}]}
{"op":"mcm","clk":"5322296723","pt":1646318576774,"mc":[{"id":"1.195532859","rc":[{"atl":[[5.3,29.12],[5.5,22.22],[5.4,44.28]],"id":38983972}],"con":true,"img":false}]}
{"op":"mcm","clk":"5322296749","pt":1646318577090,"mc":[{"id":"1.195532859","rc":[{"atb":[[1.85,10.51]],"id":39290878},{"atb":[[1.86,5.77]],"id":38357910}],"con":true,"img":false}]}
{"op":"mcm","clk":"5322296757","pt":1646318577189,"mc":[{"id":"1.195532859","rc":[{"atb":[[2.68,1.65]],"id":41288595}],"con":true,"img":false}]}
{"op":"mcm","clk":"5322296766","pt":1646318577296,"mc":[{"id":"1.195532859","rc":[{"atb":[[2.66,1.48]],"id":41288595},{"atb":[[1.85,82.09],[1.82,12.76]],"id":38357910}],"con":true,"img":false}]}
{"op":"mcm","clk":"5322296799","pt":1646318577654,"mc":[{"id":"1.195532859","rc":[{"atl":[[3.5,138.25],[3.3,24.2],[3.75,14.55]],"id":38357910}],"con":true,"img":false}]}
{"op":"mcm","clk":"5322296818","pt":1646318577866,"mc":[{"id":"1.195532859","rc":[{"atl":[[3.45,16.33]],"id":38357910}],"con":true,"img":false}]}
{"op":"mcm","clk":"5322296880","pt":1646318578601,"mc":[{"id":"1.195532859","rc":[{"atl":[[3.4,16.67]],"id":38357910}],"con":true,"img":false}]}
{"op":"mcm","clk":"5322296888","pt":1646318578705,"mc":[{"id":"1.195532859","rc":[{"atl":[[3.45,0]],"id":38357910}],"con":true,"img":false}]}
{"op":"mcm","clk":"5322296907","pt":1646318578859,"mc":[{"id":"1.195532859","rc":[{"atl":[[5.4,38.42]],"id":38983972},{"atb":[[1.83,43.93]],"id":38357910},{"atl":[[3.35,0]],"id":38357910}],"con":true,"img":false}]}
{"op":"mcm","clk":"5322296923","pt":1646318579070,"mc":[{"id":"1.195532859","rc":[{"atl":[[3.3,0]],"id":38357910}],"con":true,"img":false}]}
{"op":"mcm","clk":"5322296935","pt":1646318579171,"mc":[{"id":"1.195532859","rc":[{"atb":[[2.68,0]],"id":41288595},{"atl":[[3.35,30.65]],"id":38357910}],"con":true,"img":false}]}
{"op":"mcm","clk":"5322296953","pt":1646318579383,"mc":[{"id":"1.195532859","rc":[{"atb":[[2.66,3.13]],"id":41288595},{"atl":[[3.45,16.33],[3.4,0]],"id":38357910}],"con":true,"img":false}]}
{"op":"mcm","clk":"5322296966","pt":1646318579487,"mc":[{"id":"1.195532859","rc":[{"atb":[[2.64,0]],"id":41288595},{"atb":[[1.82,4.91]],"id":39290878},{"atb":[[2.28,8.78]],"id":40124755}],"con":true,"img":false}]}
{"op":"mcm","clk":"5322297003","pt":1646318579900,"mc":[{"id":"1.195532859","rc":[{"atl":[[5.2,35.71]],"id":40124755}],"con":true,"img":false}]}
{"op":"mcm","clk":"5322297017","pt":1646318580006,"mc":[{"id":"1.195532859","rc":[{"atb":[[2.66,1.65]],"id":41288595}],"con":true,"img":false}]}
{"op":"mcm","clk":"5322297031","pt":1646318580117,"mc":[{"id":"1.195532859","rc":[{"atb":[[2.64,1.48]],"id":41288595}],"con":true,"img":false}]}
{"op":"mcm","clk":"5322297040","pt":1646318580164,"mc":[{"id":"1.195532859","rc":[{"atb":[[2.56,224.45]],"id":41288595}],"con":true,"img":false}]}
{"op":"mcm","clk":"5322297062","pt":1646318580373,"mc":[{"id":"1.195532859","rc":[{"atb":[[2.56,160.26]],"id":41288595},{"atl":[[3.3,2.48]],"id":38357910}],"con":true,"img":false}]}
{"op":"mcm","clk":"5322297072","pt":1646318580477,"mc":[{"id":"1.195532859","rc":[{"atl":[[5.2,4.02]],"id":38983972}],"con":true,"img":false}]}
{"op":"mcm","clk":"5322297096","pt":1646318580683,"mc":[{"id":"1.195532859","rc":[{"atl":[[3.25,16.58]],"id":38357910}],"con":true,"img":false}]}
{"op":"mcm","clk":"5322297113","pt":1646318580891,"mc":[{"id":"1.195532859","rc":[{"atb":[[1.82,9.82]],"id":39290878},{"atl":[[3.35,0]],"id":38357910},{"atb":[[2.28,17.56]],"id":40124755}],"con":true,"img":false}]}
{"op":"mcm","clk":"5322297129","pt":1646318581100,"mc":[{"id":"1.195532859","rc":[{"atl":[[3.35,17.02],[3.45,0]],"id":38357910}],"con":true,"img":false}]}
{"op":"mcm","clk":"5322297141","pt":1646318581201,"mc":[{"id":"1.195532859","rc":[{"atl":[[5.3,2.25]],"id":41288595},{"atl":[[5,2.56]],"id":38983972},{"atl":[[2.82,1.97]],"id":39290878},{"atl":[[3.2,3.61]],"id":38357910},{"atl":[[4.5,3.25]],"id":40124755}],"con":true,"img":false}]}
{"op":"mcm","clk":"5322297162","pt":1646318581418,"mc":[{"id":"1.195532859","rc":[{"atl":[[5.6,69.96],[5.8,24.58],[5.3,13.45],[5.2,10.09],[5.7,0]],"id":41288595},{"atl":[[5.2,13.54],[4.9,10.45],[5.4,41.94]],"id":38983972},{"atl":[[2.88,0],[2.86,21.51]],"id":39290878},{"atl":[[3.35,0],[3.3,19.87]],"id":38357910},{"atl":[[4.8,30.79],[4.9,0],[4.4,18.13],[4.6,6.92],[4.7,10.81]],"id":40124755}],"con":true,"img":false}]}
{"op":"mcm","clk":"5322297172","pt":1646318581466,"mc":[{"id":"1.195532859","rc":[{"atl":[[5.5,8.89]],"id":41288595}],"con":true,"img":false}]}
{"op":"mcm","clk":"5322297179","pt":1646318581574,"mc":[{"id":"1.195532859","rc":[{"atl":[[5.1,2.44],[5.8,20.83],[5.5,0],[5.4,9.09]],"id":41288595},{"atl":[[4.8,2.8],[5.1,0],[5.2,4.02]],"id":38983972},{"atb":[[1.87,36.31]],"id":38357910},{"atl":[[4.3,3.61],[4.6,13.07],[4.7,0]],"id":40124755}],"con":true,"img":false}]}
{"op":"mcm","clk":"5322297188","pt":1646318581677,"mc":[{"id":"1.195532859","rc":[{"atl":[[5.8,27.65]],"id":41288595},{"atl":[[5.1,9.76]],"id":38983972},{"atl":[[2.88,2.24]],"id":39290878}],"con":true,"img":false}]}
{"op":"mcm","clk":"5322297201","pt":1646318581781,"mc":[{"id":"1.195532859","rc":[{"atl":[[5.4,38.42]],"id":38983972},{"atl":[[2.92,52.08],[2.88,36.88]],"id":39290878}],"con":true,"img":false}]}
{"op":"mcm","clk":"5322297216","pt":1646318581889,"mc":[{"id":"1.195532859","rc":[{"atb":[[2.68,2.96]],"id":41288595},{"atl":[[5.8,20.83]],"id":41288595},{"atl":[[5.4,0],[5,30.74]],"id":38983972}],"con":true,"img":false}]}
{"op":"mcm","clk":"5322297238","pt":1646318582095,"mc":[{"id":"1.195532859","rc":[{"atb":[[2.64,25.87]],"id":41288595},{"atl":[[5.3,22.75],[5.4,0]],"id":41288595},{"atl":[[5.1,0],[5,40.74]],"id":38983972},{"atl":[[3.5,100.51],[3.2,30.95],[3.15,16.58]],"id":38357910},{"atl":[[4.5,14.68],[4.6,1.96]],"id":40124755}],"con":true,"img":false}]}
{"op":"mcm","clk":"5322297246","pt":1646318582202,"mc":[{"id":"1.195532859","rc":[{"atl":[[4.8,41.5]],"id":40124755}],"con":true,"img":false}]}
{"op":"mcm","clk":"5322297256","pt":1646318582308,"mc":[{"id":"1.195532859","rc":[{"atb":[[5.6,34.65],[5.5,22.22]],"id":38324360},{"atb":[[1.7,58.82],[1.65,0]],"id":39290878},{"atl":[[2.88,30.3]],"id":39290878},{"atl":[[3.1,3.91],[3.25,37.65],[3.3,2.48],[3.15,0]],"id":38357910},{"atl":[[4.8,30.79],[4.9,3.9]],"id":40124755}],"con":true,"img":false}]}
{"op":"mcm","clk":"5322297265","pt":1646318582410,"mc":[{"id":"1.195532859","rc":[{"atb":[[5.5,25.4]],"id":38324360}],"con":true,"img":false}]}
{"op":"mcm","clk":"5322297275","pt":1646318582510,"mc":[{"id":"1.195532859","rc":[{"atl":[[3.25,17.78],[3.15,16.58]],"id":38357910}],"con":true,"img":false}]}
{"op":"mcm","clk":"5322297294","pt":1646318582670,"mc":[{"id":"1.195532859","rc":[{"atl":[[4.6,0]],"id":40124755}],"con":true,"img":false}]}
{"op":"mcm","clk":"5322297306","pt":1646318582787,"mc":[{"id":"1.195532859","rc":[{"atl":[[2.84,65.81]],"id":39290878},{"atb":[[1.83,0]],"id":38357910},{"atl":[[3.3,0]],"id":38357910}],"con":true,"img":false}]}
{"op":"mcm","clk":"5322297320","pt":1646318582887,"mc":[{"id":"1.195532859","rc":[{"atb":[[5.5,22.22]],"id":38324360},{"atl":[[4.9,0]],"id":40124755}],"con":true,"img":false}]}
{"op":"mcm","clk":"5322297327","pt":1646318582992,"mc":[{"id":"1.195532859","rc":[{"atb":[[2.64,24.39]],"id":41288595}],"con":true,"img":false}]}
{"op":"mcm","clk":"5322297338","pt":1646318583099,"mc":[{"id":"1.195532859","rc":[{"atb":[[2.68,4.44]],"id":41288595}],"con":true,"img":false}]}
{"op":"mcm","clk":"5322297362","pt":1646318583304,"mc":[{"id":"1.195532859","rc":[{"atl":[[3.1,36.2]],"id":38357910}],"con":true,"img":false}]}
{"op":"mcm","clk":"5322297372","pt":1646318583401,"mc":[{"id":"1.195532859","rc":[{"atl":[[4.8,13.25],[5.3,9.3]],"id":38983972},{"atl":[[3.25,0],[3.2,49.13]],"id":38357910}],"con":true,"img":false}]}
{"op":"mcm","clk":"5322297384","pt":1646318583506,"mc":[{"id":"1.195532859","rc":[{"atl":[[3.2,21.79]],"id":38357910}],"con":true,"img":false}]}
{"op":"mcm","clk":"5322297407","pt":1646318583780,"mc":[{"id":"1.195532859","rc":[{"atl":[[2.8,2.48]],"id":39290878},{"atl":[[3.05,2.48]],"id":38357910}],"con":true,"img":false}]}
{"op":"mcm","clk":"5322297419","pt":1646318583881,"mc":[{"id":"1.195532859","rc":[{"atl":[[2.8,9.45],[2.84,19.29]],"id":39290878}],"con":true,"img":false}]}
{"op":"mcm","clk":"5322297442","pt":1646318584089,"mc":[{"id":"1.195532859","rc":[{"atl":[[2.84,0]],"id":39290878}],"con":true,"img":false}]}
{"op":"mcm","clk":"5322297474","pt":1646318584403,"mc":[{"id":"1.195532859","rc":[{"atb":[[2.5,27.56]],"id":38983972},{"atb":[[1.85,0]],"id":39290878},{"atb":[[1.86,0]],"id":38357910},{"atb":[[2.44,0]],"id":40124755}],"con":true,"img":false}]}
{"op":"mcm","clk":"5322297489","pt":1646318584605,"mc":[{"id":"1.195532859","rc":[{"atb":[[1.84,5.26]],"id":39290878},{"atl":[[3.5,0],[3.05,33.77],[3.15,129.84]],"id":38357910},{"atb":[[2.28,42.37]],"id":40124755}],"con":true,"img":false}]}
{"op":"mcm","clk":"5322297506","pt":1646318584812,"mc":[{"id":"1.195532859","rc":[{"atb":[[1.77,5.01]],"id":39290878},{"atl":[[3.1,3.91]],"id":38357910}],"con":true,"img":false}]}
{"op":"mcm","clk":"5322297524","pt":1646318584981,"mc":[{"id":"1.195532859","rc":[{"atb":[[1.84,0],[1.77,0]],"id":39290878}],"con":true,"img":false}]}
{"op":"mcm","clk":"5322297555","pt":1646318585299,"mc":[{"id":"1.195532859","rc":[{"atb":[[1.88,33.51]],"id":38357910}],"con":true,"img":false}]}
{"op":"mcm","clk":"5322297561","pt":1646318585393,"mc":[{"id":"1.195532859","rc":[{"atb":[[1.66,3.01]],"id":38357910},{"atb":[[2.28,33.59]],"id":40124755}],"con":true,"img":false}]}
{"op":"mcm","clk":"5322297571","pt":1646318585506,"mc":[{"id":"1.195532859","rc":[{"atl":[[2.84,21.74],[2.86,0],[2.78,2.04]],"id":39290878},{"atl":[[3,1.68],[3.2,3.61],[3.15,148.44]],"id":38357910}],"con":true,"img":false}]}
{"op":"mcm","clk":"5322297590","pt":1646318585725,"mc":[{"id":"1.195532859","rc":[{"atl":[[2.82,23.95],[2.84,0]],"id":39290878},{"atl":[[3.1,22.96]],"id":38357910}],"con":true,"img":false}]}
{"op":"mcm","clk":"5322297597","pt":1646318585808,"mc":[{"id":"1.195532859","rc":[{"atl":[[2.88,28.06]],"id":39290878},{"atl":[[3.15,129.84]],"id":38357910}],"con":true,"img":false}]}
{"op":"mcm","clk":"5322297608","pt":1646318585913,"mc":[{"id":"1.195532859","rc":[{"atb":[[1.66,0]],"id":38357910}],"con":true,"img":false}]}
{"op":"mcm","clk":"5322297627","pt":1646318586081,"mc":[{"id":"1.195532859","rc":[{"atl":[[2.78,3.64]],"id":39290878}],"con":true,"img":false}]}
{"op":"mcm","clk":"5322297635","pt":1646318586181,"mc":[{"id":"1.195532859","rc":[{"atb":[[2.66,0]],"id":41288595},{"atl":[[2.76,9.45]],"id":39290878}],"con":true,"img":false}]}
{"op":"mcm","clk":"5322297644","pt":1646318586282,"mc":[{"id":"1.195532859","rc":[{"atl":[[2.8,6.97],[2.74,2.12]],"id":39290878}],"con":true,"img":false}]}
{"op":"mcm","clk":"5322297652","pt":1646318586394,"mc":[{"id":"1.195532859","rc":[{"atb":[[2.7,1.65]],"id":41288595},{"atb":[[2.64,1.65]],"id":38983972},{"atl":[[2.8,4.49]],"id":39290878},{"atl":[[3.05,31.29]],"id":38357910}],"con":true,"img":false}]}
{"op":"mcm","clk":"5322297660","pt":1646318586503,"mc":[{"id":"1.195532859","rc":[{"atb":[[2.6,29.5]],"id":41288595}],"con":true,"img":false}]}
{"op":"mcm","clk":"5322297671","pt":1646318586607,"mc":[{"id":"1.195532859","rc":[{"atb":[[2.64,3.01],[2.6,25],[2.66,24.1]],"id":41288595},{"atl":[[2.82,1.97],[2.78,26.11]],"id":39290878}],"con":true,"img":false}]}
{"op":"mcm","clk":"5322297699","pt":1646318586922,"mc":[{"id":"1.195532859","rc":[{"atb":[[2.48,6.9]],"id":38983972}],"con":true,"img":false}]}
{"op":"mcm","clk":"5322297706","pt":1646318586980,"mc":[{"id":"1.195532859","rc":[{"atb":[[2.64,0]],"id":41288595}],"con":true,"img":false}]}
{"op":"mcm","clk":"5322297724","pt":1646318587188,"mc":[{"id":"1.195532859","rc":[{"atb":[[2.48,2.49]],"id":38983972}],"con":true,"img":false}]}
{"op":"mcm","clk":"5322297733","pt":1646318587295,"mc":[{"id":"1.195532859","rc":[{"atb":[[1.87,0]],"id":38357910}],"con":true,"img":false}]}
{"op":"mcm","clk":"5322297743","pt":1646318587396,"mc":[{"id":"1.195532859","rc":[{"atb":[[2.42,5],[2.48,50.35]],"id":41288595}],"con":true,"img":false}]}
{"op":"mcm","clk":"5322297751","pt":1646318587493,"mc":[{"id":"1.195532859","rc":[{"atl":[[2.72,2.48]],"id":39290878},{"atl":[[2.98,2.48]],"id":38357910}],"con":true,"img":false}]}
{"op":"mcm","clk":"5322297761","pt":1646318587609,"mc":[{"id":"1.195532859","rc":[{"atl":[[2.72,4.96],[2.76,0],[2.7,2.21]],"id":39290878},{"atl":[[2.96,1.74]],"id":38357910}],"con":true,"img":false}]}
{"op":"mcm","clk":"5322297768","pt":1646318587700,"mc":[{"id":"1.195532859","rc":[{"atl":[[2.98,24.21]],"id":38357910}],"con":true,"img":false}]}
{"op":"mcm","clk":"5322297783","pt":1646318587920,"mc":[{"id":"1.195532859","rc":[{"atl":[[5.1,12.53],[5.3,11.55]],"id":41288595},{"atl":[[2.74,25.11]],"id":39290878},{"atl":[[3,21.68],[3.05,0]],"id":38357910},{"atl":[[4.4,7.6],[4.2,14.68]],"id":40124755}],"con":true,"img":false}]}
{"op":"mcm","clk":"5322297789","pt":1646318588011,"mc":[{"id":"1.195532859","rc":[{"atl":[[2.78,3.64]],"id":39290878},{"atl":[[3.1,3.91]],"id":38357910}],"con":true,"img":false}]}
{"op":"mcm","clk":"5322297800","pt":1646318588121,"mc":[{"id":"1.195532859","rc":[{"atl":[[4.1,4.04]],"id":40124755}],"con":true,"img":false}]}
{"op":"mcm","clk":"5322297862","pt":1646318588816,"mc":[{"id":"1.195532859","rc":[{"atl":[[2.72,2.48]],"id":39290878},{"atl":[[2.98,21.73]],"id":38357910}],"con":true,"img":false}]}
{"op":"mcm","clk":"5322297884","pt":1646318589027,"mc":[{"id":"1.195532859","rc":[{"atl":[[3.15,113.26],[2.96,23.42]],"id":38357910},{"atl":[[4.3,15.73],[4.5,3.25]],"id":40124755}],"con":true,"img":false}]}
{"op":"mcm","clk":"5322297894","pt":1646318589121,"mc":[{"id":"1.195532859","rc":[{"atb":[[2.16,4.63]],"id":41288595},{"atb":[[1.67,0]],"id":38357910}],"con":true,"img":false}]}
{"op":"mcm","clk":"5322297911","pt":1646318589292,"mc":[{"id":"1.195532859","rc":[{"atb":[[5,2]],"id":38324360}],"con":true,"img":false}]}
{"op":"mcm","clk":"5322297923","pt":1646318589401,"mc":[{"id":"1.195532859","rc":[{"atb":[[2.3,8.26]],"id":40124755}],"con":true,"img":false}]}
{"op":"mcm","clk":"5322297943","pt":1646318589609,"mc":[{"id":"1.195532859","rc":[{"atb":[[1.5,6.67]],"id":39290878}],"con":true,"img":false}]}
{"op":"mcm","clk":"5322297964","pt":1646318589808,"mc":[{"id":"1.195532859","rc":[{"atb":[[1.54,6.49]],"id":38357910}],"con":true,"img":false}]}
{"op":"mcm","clk":"5322297986","pt":1646318590016,"mc":[{"id":"1.195532859","rc":[{"atb":[[2.68,1.48]],"id":41288595},{"atb":[[2.58,4.95]],"id":38983972},{"atb":[[1.83,12.27]],"id":39290878},{"atb":[[1.89,4.68]],"id":38357910},{"atb":[[2.3,30.22],[1.97,5.08]],"id":40124755},{"atl":[[4,2.48]],"id":40124755}],"con":true,"img":false}]}
{"op":"mcm","clk":"5322298008","pt":1646318590224,"mc":[{"id":"1.195532859","rc":[{"atb":[[2.5,0],[2.12,4.72],[2.56,40.38]],"id":38983972},{"atl":[[3.95,2.19]],"id":40124755}],"con":true,"img":false}]}
{"op":"mcm","clk":"5322298095","pt":1646318591019,"mc":[{"id":"1.195532859","rc":[{"atb":[[1.88,0]],"id":38357910}],"con":true,"img":false}]}
{"op":"mcm","clk":"5322298122","pt":1646318591330,"mc":[{"id":"1.195532859","rc":[{"atl":[[2.78,2.04]],"id":39290878}],"con":true,"img":false}]}
{"op":"mcm","clk":"5322298144","pt":1646318591598,"mc":[{"id":"1.195532859","rc":[{"atl":[[2.76,2.44]],"id":39290878},{"atl":[[3,111.98],[3.15,0],[2.96,50.77]],"id":38357910}],"con":true,"img":false}]}
{"op":"mcm","clk":"5322298154","pt":1646318591700,"mc":[{"id":"1.195532859","rc":[{"atb":[[1.86,39.09]],"id":38357910}],"con":true,"img":false}]}
{"op":"mcm","clk":"5322298162","pt":1646318591804,"mc":[{"id":"1.195532859","rc":[{"atb":[[1.86,122.88]],"id":38357910},{"atl":[[2.98,0]],"id":38357910}],"con":true,"img":false}]}
{"op":"mcm","clk":"5322298176","pt":1646318591908,"mc":[{"id":"1.195532859","rc":[{"atb":[[1.85,0]],"id":38357910}],"con":true,"img":false}]}
{"op":"mcm","clk":"5322298214","pt":1646318592419,"mc":[{"id":"1.195532859","rc":[{"atl":[[2.68,2.48]],"id":39290878},{"atl":[[2.94,2.48]],"id":38357910},{"atl":[[4,0]],"id":40124755}],"con":true,"img":false}]}
{"op":"mcm","clk":"5322298224","pt":1646318592529,"mc":[{"id":"1.195532859","rc":[{"atl":[[4.3,3.61],[4.1,16.94]],"id":40124755}],"con":true,"img":false}]}
{"op":"mcm","clk":"5322298232","pt":1646318592624,"mc":[{"id":"1.195532859","rc":[{"atl":[[2.72,0],[2.66,2.29],[2.68,4.96]],"id":39290878},{"atl":[[2.92,1.8]],"id":38357910},{"atl":[[4.3,0],[4.5,0],[3.95,0],[4.1,12.9]],"id":40124755}],"con":true,"img":false}]}
{"op":"mcm","clk":"5322298239","pt":1646318592730,"mc":[{"id":"1.195532859","rc":[{"atb":[[2.66,22.54],[2.68,0],[2.7,0]],"id":41288595},{"trd":[[2.66,3.12],[2.68,2.96],[2.7,3.31]],"ltp":2.66,"tv":9.39,"id":41288595},{"atl":[[3.15,5.32]],"id":38357910}],"con":true,"img":false}]}
{"op":"mcm","clk":"5322298259","pt":1646318592900,"mc":[{"id":"1.195532859","rc":[{"atb":[[2.56,25.5],[2.66,0],[2.6,0],[2.62,0]],"id":41288595}],"con":true,"img":false}]}
{"op":"mcm","clk":"5322298267","pt":1646318593011,"mc":[{"id":"1.195532859","rc":[{"atb":[[2.56,33.07]],"id":41288595},{"atl":[[4,2.11],[4.4,35.18],[4.2,0]],"id":40124755}],"con":true,"img":false}]}
{"op":"mcm","clk":"5322298273","pt":1646318593109,"mc":[{"id":"1.195532859","rc":[{"atb":[[2.64,12.05]],"id":41288595},{"atl":[[2.94,7.86]],"id":38357910}],"con":true,"img":false}]}
{"op":"mcm","clk":"5322298286","pt":1646318593317,"mc":[{"id":"1.195532859","rc":[{"atb":[[2.64,0]],"id":41288595},{"atl":[[3.15,0],[2.96,23.42]],"id":38357910}],"con":true,"img":false}]}
{"op":"mcm","clk":"5322298299","pt":1646318593523,"mc":[{"id":"1.195532859","rc":[{"atl":[[5.1,13.88]],"id":41288595}],"con":true,"img":false}]}
{"op":"mcm","clk":"5322298320","pt":1646318593833,"mc":[{"id":"1.195532859","rc":[{"atb":[[1.82,4.91]],"id":39290878},{"atl":[[2.68,2.48]],"id":39290878},{"atl":[[2.94,5.38]],"id":38357910}],"con":true,"img":false}]}
{"op":"mcm","clk":"5322298328","pt":1646318593928,"mc":[{"id":"1.195532859","rc":[{"atb":[[1.82,0]],"id":39290878},{"atb":[[2.28,24.81]],"id":40124755}],"con":true,"img":false}]}
{"op":"mcm","clk":"5322298336","pt":1646318594030,"mc":[{"id":"1.195532859","rc":[{"atb":[[2.62,2.15],[2.48,48.2]],"id":41288595}],"con":true,"img":false}]}
{"op":"mcm","clk":"5322298342","pt":1646318594095,"mc":[{"id":"1.195532859","rc":[{"atb":[[2.48,80]],"id":41288595}],"con":true,"img":false}]}
{"op":"mcm","clk":"5322298351","pt":1646318594199,"mc":[{"id":"1.195532859","rc":[{"atb":[[2.58,1.65]],"id":41288595}],"con":true,"img":false}]}
{"op":"mcm","clk":"5322298361","pt":1646318594301,"mc":[{"id":"1.195532859","rc":[{"atl":[[2.76,7.66]],"id":39290878}],"con":true,"img":false}]}
{"op":"mcm","clk":"5322298416","pt":1646318594825,"mc":[{"id":"1.195532859","rc":[{"atl":[[2.76,2.44]],"id":39290878}],"con":true,"img":false}]}
{"op":"mcm","clk":"5322298423","pt":1646318594929,"mc":[{"id":"1.195532859","rc":[{"atl":[[3.95,2.48]],"id":40124755}],"con":true,"img":false}]}
{"op":"mcm","clk":"5322298435","pt":1646318595131,"mc":[{"id":"1.195532859","rc":[{"atb":[[2.56,7.57],[2.52,26.17]],"id":41288595},{"atl":[[3.9,2.25]],"id":40124755}],"con":true,"img":false}]}
{"op":"mcm","clk":"5322298449","pt":1646318595334,"mc":[{"id":"1.195532859","rc":[{"atl":[[5.6,11.2],[5,13.24],[5.3,54.83]],"id":41288595},{"atl":[[4.7,11.56]],"id":38983972},{"atl":[[4.8,10.52],[3.85,3.55],[4,11.57]],"id":40124755}],"con":true,"img":false}]}
{"op":"mcm","clk":"5322298456","pt":1646318595438,"mc":[{"id":"1.195532859","rc":[{"atl":[[5.6,5.56]],"id":38983972},{"atl":[[2.92,7.18]],"id":38357910}],"con":true,"img":false}]}
{"op":"mcm","clk":"5322298466","pt":1646318595543,"mc":[{"id":"1.195532859","rc":[{"atl":[[5.1,3.79],[5.2,0],[4.9,15.92]],"id":41288595},{"atl":[[4.9,44.02],[5.6,0],[5,12.56],[4.6,3.09]],"id":38983972},{"atl":[[2.94,28.8],[2.92,1.8],[2.96,1.74]],"id":38357910},{"atl":[[3.8,2.39],[4.4,27.58]],"id":40124755}],"con":true,"img":false}]}
{"op":"mcm","clk":"5322298479","pt":1646318595612,"mc":[{"id":"1.195532859","rc":[{"atl":[[4.9,2.68]],"id":41288595},{"atl":[[2.92,11.22]],"id":38357910}],"con":true,"img":false}]}
{"op":"mcm","clk":"5322298491","pt":1646318595715,"mc":[{"id":"1.195532859","rc":[{"atl":[[5,26.48]],"id":41288595},{"atl":[[4.8,2.8],[4.5,11.56]],"id":38983972},{"atl":[[2.88,0],[2.7,11.75]],"id":39290878}],"con":true,"img":false}]}
{"op":"mcm","clk":"5322298496","pt":1646318595823,"mc":[{"id":"1.195532859","rc":[{"atl":[[4.8,36.52],[4.9,0]],"id":38983972},{"atb":[[1.87,36.31]],"id":38357910},{"atl":[[2.94,23.42]],"id":38357910}],"con":true,"img":false}]}
{"op":"mcm","clk":"5322298506","pt":1646318595920,"mc":[{"id":"1.195532859","rc":[{"atl":[[4.4,3.42]],"id":38983972},{"atb":[[5.6,56.39],[5.5,0]],"id":38324360}],"con":true,"img":false}]}
{"op":"mcm","clk":"5322298514","pt":1646318596029,"mc":[{"id":"1.195532859","rc":[{"atl":[[4.6,2.36]],"id":41288595},{"spn":2.57,"spf":1.0,"id":41288595},{"spn":3.52,"spf":"NaN","id":38983972},{"spn":9.6,"spf":"NaN","id":38324360},{"spn":1.88,"spf":1.0,"id":39290878},{"spn":2.42,"spf":"NaN","id":38357910},{"spn":3.13,"spf":"NaN","id":40124755}],"con":true,"img":false}]}
{"op":"mcm","clk":"5322298522","pt":1646318596131,"mc":[{"id":"1.195532859","rc":[{"atb":[[5.1,7.62]],"id":38324360}],"con":true,"img":false}]}
{"op":"mcm","clk":"5322298532","pt":1646318596240,"mc":[{"id":"1.195532859","rc":[{"atl":[[4.5,3.25]],"id":41288595},{"atl":[[3.95,0]],"id":40124755}],"con":true,"img":false}]}
{"op":"mcm","clk":"5322298559","pt":1646318596638,"mc":[{"id":"1.195532859","rc":[{"atb":[[5.1,4]],"id":38324360}],"con":true,"img":false}]}
{"op":"mcm","clk":"5322298598","pt":1646318597019,"mc":[{"id":"1.195532859","rc":[{"atb":[[1.83,0]],"id":39290878},{"atb":[[1.89,0]],"id":38357910},{"atb":[[2.3,8.26]],"id":40124755}],"con":true,"img":false}]}
{"op":"mcm","clk":"5322298610","pt":1646318597149,"mc":[{"id":"1.195532859","rc":[{"atb":[[1.81,8.72]],"id":39290878}],"con":true,"img":false}]}
{"op":"mcm","clk":"5322298643","pt":1646318597437,"mc":[{"id":"1.195532859","rc":[{"atl":[[5.1,2.44]],"id":41288595}],"con":true,"img":false}]}
{"op":"mcm","clk":"5322298655","pt":1646318597543,"mc":[{"id":"1.195532859","rc":[{"atl":[[5.3,45.53],[4.4,1.35],[5.2,9.52]],"id":41288595},{"atl":[[4.6,14.2],[5,2.56]],"id":38983972},{"atl":[[3,91.98],[2.96,22.15]],"id":38357910},{"atl":[[4.1,0],[3.9,16.04]],"id":40124755}],"con":true,"img":false}]}
{"op":"mcm","clk":"5322298666","pt":1646318597640,"mc":[{"id":"1.195532859","rc":[{"atl":[[2.64,2.48]],"id":39290878},{"atb":[[1.86,83.79]],"id":38357910},{"atl":[[2.9,2.48]],"id":38357910}],"con":true,"img":false}]}
{"op":"mcm","clk":"5322298677","pt":1646318597736,"mc":[{"id":"1.195532859","rc":[{"atl":[[4.3,3.61]],"id":41288595},{"atb":[[3.75,14.55],[3.95,0]],"id":38324360},{"atl":[[2.76,25.17],[2.74,2.12]],"id":39290878}],"con":true,"img":false}]}
{"op":"mcm","clk":"5322298687","pt":1646318597840,"mc":[{"id":"1.195532859","rc":[{"atl":[[5.1,12.2],[5.2,0]],"id":41288595},{"atl":[[2.62,2.38],[2.66,6.78]],"id":39290878},{"atb":[[1.59,0],[1.82,0],[1.63,63.49],[1.88,36.31]],"id":38357910},{"atl":[[2.94,20.62],[2.88,1.86],[2.9,38.61],[2.96,1.74]],"id":38357910}],"con":true,"img":false}]}
{"op":"mcm","clk":"5322298697","pt":1646318597905,"mc":[{"id":"1.195532859","rc":[{"atb":[[3.85,20.99]],"id":38324360},{"atl":[[2.8,0]],"id":39290878},{"atl":[[2.92,1.8]],"id":38357910}],"con":true,"img":false}]}
{"op":"mcm","clk":"5322298704","pt":1646318598009,"mc":[{"id":"1.195532859","rc":[{"atb":[[1.84,4.2]],"id":39290878},{"atb":[[2.32,7.74]],"id":40124755}],"con":true,"img":false}]}
{"op":"mcm","clk":"5322298722","pt":1646318598222,"mc":[{"id":"1.195532859","rc":[{"atb":[[1.81,2.5]],"id":39290878},{"atl":[[2.82,1.48]],"id":38357910},{"atb":[[2.28,28.95]],"id":40124755}],"con":true,"img":false}]}
{"op":"mcm","clk":"5322298742","pt":1646318598425,"mc":[{"id":"1.195532859","rc":[{"atl":[[4.4,0]],"id":41288595},{"atl":[[2.8,2],[3,1.68],[2.94,145.33],[2.88,23.12]],"id":38357910},{"atb":[[2.32,18.64],[2.28,4.14]],"id":40124755}],"con":true,"img":false}]}
{"op":"mcm","clk":"5322298753","pt":1646318598531,"mc":[{"id":"1.195532859","rc":[{"atl":[[4.2,1.35]],"id":41288595},{"atb":[[2.28,0]],"id":40124755}],"con":true,"img":false}]}
{"op":"mcm","clk":"5322298763","pt":1646318598627,"mc":[{"id":"1.195532859","rc":[{"atl":[[4.3,0],[5.3,43.28],[4.9,0],[4.5,0],[5.1,9.76]],"id":41288595}],"con":true,"img":false}]}
{"op":"mcm","clk":"5322298772","pt":1646318598738,"mc":[{"id":"1.195532859","rc":[{"atl":[[2.9,13.7]],"id":38357910}],"con":true,"img":false}]}
{"op":"mcm","clk":"5322298791","pt":1646318598941,"mc":[{"id":"1.195532859","rc":[{"atl":[[4.1,4.04]],"id":41288595}],"con":true,"img":false}]}
{"op":"mcm","clk":"5322298804","pt":1646318599043,"mc":[{"id":"1.195532859","rc":[{"atl":[[2.62,4.86],[2.68,0]],"id":39290878}],"con":true,"img":false}]}
{"op":"mcm","clk":"5322298814","pt":1646318599110,"mc":[{"id":"1.195532859","rc":[{"atl":[[2.64,7.24],[2.62,2.38]],"id":39290878}],"con":true,"img":false}]}
{"op":"mcm","clk":"5322298825","pt":1646318599213,"mc":[{"id":"1.195532859","rc":[{"atb":[[2.58,0]],"id":38983972}],"con":true,"img":false}]}
