{"op":"mcm","clk":"5351767862","pt":1646175389026,"mc":[{"id":"1.195453772","marketDefinition":{"bspMarket":true,"turnInPlayEnabled":false,"persistenceEnabled":false,"marketBaseRate":7.0,"eventId":"31272499","eventTypeId":"4339","numberOfWinners":1,"bettingType":"ODDS","marketType":"WIN","marketTime":"2022-03-02T10:15:00.000Z","suspendTime":"2022-03-02T10:15:00.000Z","bspReconciled":false,"complete":true,"inPlay":false,"crossMatching":false,"runnersVoidable":false,"numberOfActiveRunners":8,"betDelay":0,"status":"OPEN","runners":[{"status":"ACTIVE","sortPriority":1,"id":36500408,"name":"1. Mexicali Jane"},{"status":"ACTIVE","sortPriority":2,"id":42860579,"name":"2. Petite Olga"},{"status":"ACTIVE","sortPriority":3,"id":39786791,"name":"3. Tiger Talks"},{"status":"ACTIVE","sortPriority":4,"id":43167135,"name":"4. Pereira"},{"status":"ACTIVE","sortPriority":5,"id":42077854,"name":"5. Red Card Bob"},{"status":"ACTIVE","sortPriority":6,"id":37260099,"name":"7. Hear Footsteps"},{"status":"ACTIVE","sortPriority":7,"id":40120078,"name":"8. Informality"},{"status":"ACTIVE","sortPriority":8,"id":28506637,"name":"9. Tuesdays Gone"}],"regulators":["MR_INT"],"venue":"Rockhampton","countryCode":"AU","discountAllowed":true,"timezone":"Australia/Queensland","openDate":"2022-03-02T08:34:00.000Z","version":4382437855,"name":"R6 407m Gr3/4","eventName":"Rockhampton (AUS) 2nd Mar"},"rc":[],"con":true,"img":false}]}
{"op":"mcm","clk":"5351835810","pt":1646176785738,"mc":[{"id":"1.195453772","rc":[{"atb":[[4,34.25],[4.5,29.35],[5,25.68],[3.75,37.36]],"id":43167135},{"atl":[[16,8.86],[18.5,7.6],[22,9.5],[27,7.67]],"id":43167135},{"spn":10.5,"spf":"NaN","id":43167135},{"atb":[[2,102.74],[1.85,120.88],[1.9,114.16],[1.95,108.15]],"id":40120078},{"atl":[[5.6,43.38],[5.1,32.44],[4.6,36.95],[6.2,38.37]],"id":40120078},{"spn":3.3,"spf":"NaN","id":40120078},{"atb":[[34,3.11],[18.5,5.87],[22,4.89],[27,3.95]],"id":37260099},{"atl":[[300,0.44],[350,0.57],[400,0.5],[250,0.53]],"id":37260099},{"spn":142.0,"spf":"NaN","id":37260099},{"atb":[[4,34.25],[4.5,29.35],[5,25.68],[5.5,22.83]],"id":36500408},{"atl":[[17,8.31],[19.5,7.19],[24,8.67],[29,7.12]],"id":36500408},{"spn":11.25,"spf":"NaN","id":36500408},{"atb":[[16,6.84],[18.5,5.87],[22,4.89],[27,3.95]],"id":28506637},{"atl":[[260,0.51],[310,0.64],[360,0.55],[210,0.63]],"id":28506637},{"spn":118.5,"spf":"NaN","id":28506637},{"atb":[[16,6.84],[11,10.27],[13.5,8.21],[9.4,12.23]],"id":42077854},{"atl":[[260,0.77],[160,0.83],[210,0.95],[110,1.21]],"id":42077854},{"spn":63.0,"spf":"NaN","id":42077854},{"atb":[[8.6,13.52],[5.8,21.4],[7.6,15.56],[6.6,18.35]],"id":42860579},{"atl":[[65,3.11],[36,3.79],[90,2.24],[46,2.95]],"id":42860579},{"spn":22.3,"spf":"NaN","id":42860579},{"atb":[[4.8,27.03],[4.3,31.13],[3.9,35.43],[3.65,38.77]],"id":39786791},{"atl":[[18,7.82],[21,9.97],[26,7.98],[15.5,9.17]],"id":39786791},{"spn":10.15,"spf":"NaN","id":39786791}],"con":true,"img":false}]}
{"op":"mcm","clk":"5351837288","pt":1646176822490,"mc":[{"id":"1.195453772","rc":[{"atb":[[4,0],[4.5,0],[5,0],[3.75,0]],"id":43167135},{"atl":[[16,0],[18.5,0],[22,0],[27,0]],"id":43167135},{"atb":[[2,0],[1.85,0],[1.9,0],[1.95,0]],"id":40120078},{"atl":[[5.6,0],[5.1,0],[4.6,0],[6.2,0]],"id":40120078},{"atb":[[34,0],[18.5,0],[22,0],[27,0]],"id":37260099},{"atl":[[300,0],[350,0],[400,0],[250,0]],"id":37260099},{"atb":[[4,0],[4.5,0],[5,0],[5.5,0]],"id":36500408},{"atl":[[17,0],[19.5,0],[24,0],[29,0]],"id":36500408},{"atb":[[16,0],[18.5,0],[22,0],[27,0]],"id":28506637},{"atl":[[260,0],[310,0],[360,0],[210,0]],"id":28506637},{"atb":[[16,0],[11,0],[13.5,0],[9.4,0]],"id":42077854},{"atl":[[260,0],[160,0],[210,0],[110,0]],"id":42077854},{"atb":[[8.6,0],[5.8,0],[7.6,0],[6.6,0]],"id":42860579},{"atl":[[65,0],[36,0],[90,0],[46,0]],"id":42860579},{"atb":[[4.8,0],[4.3,0],[3.9,0],[3.65,0]],"id":39786791},{"atl":[[18,0],[21,0],[26,0],[15.5,0]],"id":39786791}],"con":true,"img":false}]}
{"op":"mcm","clk":"5351837809","pt":1646176834572,"mc":[{"id":"1.195453772","rc":[{"atb":[[4,34.25],[4.5,29.35],[5,25.68],[3.75,37.36]],"id":43167135},{"atl":[[16,8.86],[18.5,7.6],[22,9.5],[27,7.67]],"id":43167135},{"atb":[[2.06,96.93],[1.98,104.84],[1.88,116.76],[1.93,110.48]],"id":40120078},{"atl":[[6.8,34.4],[4.9,34.11],[5.9,40.72],[5.4,30.23]],"id":40120078},{"atb":[[34,3.11],[18.5,5.87],[22,4.89],[27,3.95]],"id":37260099},{"atl":[[300,0.44],[350,0.57],[400,0.5],[250,0.53]],"id":37260099},{"atb":[[4,34.25],[4.5,29.35],[5,25.68],[5.5,22.83]],"id":36500408},{"atl":[[17,8.31],[19.5,7.19],[24,8.67],[29,7.12]],"id":36500408},{"atb":[[16,6.84],[18.5,5.87],[22,4.89],[27,3.95]],"id":28506637},{"atl":[[260,0.51],[310,0.64],[360,0.55],[210,0.63]],"id":28506637},{"atb":[[16,6.84],[11,10.27],[13.5,8.21],[9.4,12.23]],"id":42077854},{"atl":[[260,0.77],[160,0.83],[210,0.95],[110,1.21]],"id":42077854},{"atb":[[8.6,13.52],[5.8,21.4],[7.6,15.56],[6.6,18.35]],"id":42860579},{"atl":[[65,3.11],[36,3.79],[90,2.24],[46,2.95]],"id":42860579},{"atb":[[4.8,27.03],[4.3,31.13],[3.9,35.43],[3.65,38.77]],"id":39786791},{"atl":[[18,7.82],[21,9.97],[26,7.98],[15.5,9.17]],"id":39786791}],"con":true,"img":false}]}
{"op":"mcm","clk":"5351847482","pt":1646177062628,"mc":[{"id":"1.195453772","rc":[{"atb":[[4,0],[4.5,0],[5,0],[3.75,0]],"id":43167135},{"atl":[[16,0],[18.5,0],[22,0],[27,0]],"id":43167135},{"spn":"NaN","spf":"NaN","id":43167135},{"atb":[[2.06,0],[1.98,0],[1.88,0],[1.93,0]],"id":40120078},{"atl":[[6.8,0],[4.9,0],[5.9,0],[5.4,0]],"id":40120078},{"spn":"NaN","spf":"NaN","id":40120078},{"atb":[[34,0],[18.5,0],[22,0],[27,0]],"id":37260099},{"atl":[[300,0],[350,0],[400,0],[250,0]],"id":37260099},{"spn":"NaN","spf":"NaN","id":37260099},{"atb":[[4,0],[4.5,0],[5,0],[5.5,0]],"id":36500408},{"atl":[[17,0],[19.5,0],[24,0],[29,0]],"id":36500408},{"spn":"NaN","spf":"NaN","id":36500408},{"atb":[[16,0],[18.5,0],[22,0],[27,0]],"id":28506637},{"atl":[[260,0],[310,0],[360,0],[210,0]],"id":28506637},{"spn":"NaN","spf":"NaN","id":28506637},{"atb":[[16,0],[11,0],[13.5,0],[9.4,0]],"id":42077854},{"atl":[[260,0],[160,0],[210,0],[110,0]],"id":42077854},{"spn":"NaN","spf":"NaN","id":42077854},{"atb":[[8.6,0],[5.8,0],[7.6,0],[6.6,0]],"id":42860579},{"atl":[[65,0],[36,0],[90,0],[46,0]],"id":42860579},{"spn":"NaN","spf":"NaN","id":42860579},{"atb":[[4.8,0],[4.3,0],[3.9,0],[3.65,0]],"id":39786791},{"atl":[[18,0],[21,0],[26,0],[15.5,0]],"id":39786791},{"spn":"NaN","spf":"NaN","id":39786791}],"con":true,"img":false}]}
{"op":"mcm","clk":"5351848003","pt":1646177072654,"mc":[{"id":"1.195453772","rc":[{"atb":[[4,34.25],[4.5,29.35],[5,25.68],[3.75,37.36]],"id":43167135},{"atl":[[16,8.86],[18.5,7.6],[22,9.5],[27,7.67]],"id":43167135},{"atb":[[2,102.74],[1.85,120.88],[1.9,114.16],[1.95,108.15]],"id":40120078},{"atl":[[5.6,43.38],[5.1,32.44],[4.6,36.95],[6.2,38.37]],"id":40120078},{"atb":[[34,3.11],[18.5,5.87],[22,4.89],[27,3.95]],"id":37260099},{"atl":[[300,0.44],[350,0.57],[400,0.5],[250,0.53]],"id":37260099},{"atb":[[4,34.25],[4.5,29.35],[5,25.68],[5.5,22.83]],"id":36500408},{"atl":[[17,8.31],[19.5,7.19],[24,8.67],[29,7.12]],"id":36500408},{"atb":[[34,3.11],[18.5,5.87],[22,4.89],[27,3.95]],"id":28506637},{"atl":[[300,0.44],[350,0.57],[400,0.5],[250,0.53]],"id":28506637},{"atb":[[17,6.42],[12,9.34],[9.8,11.67],[14.5,7.61]],"id":42077854},{"atl":[[270,0.74],[170,0.78],[220,0.9],[120,1.11]],"id":42077854},{"atb":[[8.6,13.52],[5.8,21.4],[7.6,15.56],[6.6,18.35]],"id":42860579},{"atl":[[65,3.11],[36,3.79],[90,2.24],[46,2.95]],"id":42860579},{"atb":[[4.6,28.54],[4.1,33.14],[3.8,36.69],[3.55,40.29]],"id":39786791},{"atl":[[17,8.31],[19.5,10.78],[24,8.67],[14.5,9.85]],"id":39786791}],"con":true,"img":false}]}
{"op":"mcm","clk":"5351857589","pt":1646177303151,"mc":[{"id":"1.195453772","rc":[{"spn":10.5,"spf":"NaN","id":43167135},{"spn":3.3,"spf":"NaN","id":40120078},{"spn":142.0,"spf":"NaN","id":37260099},{"atb":[[4,0],[4.5,0],[5,0],[5.5,0]],"id":36500408},{"atl":[[17,0],[19.5,0],[24,0],[29,0]],"id":36500408},{"spn":142.0,"spf":"NaN","id":28506637},{"spn":68.5,"spf":"NaN","id":42077854},{"atb":[[8.6,0],[5.8,0],[7.6,0],[6.6,0]],"id":42860579},{"atl":[[65,0],[36,0],[90,0],[46,0]],"id":42860579},{"spn":9.55,"spf":"NaN","id":39786791}],"con":true,"img":false}]}
{"op":"mcm","clk":"5351858183","pt":1646177316284,"mc":[{"id":"1.195453772","rc":[{"atb":[[4,34.25],[4.5,29.35],[5,25.68],[5.5,22.83]],"id":36500408},{"atl":[[17,8.31],[19.5,7.19],[24,8.67],[29,7.12]],"id":36500408},{"atb":[[8,14.67],[9,12.84],[6,20.54],[7,17.12]],"id":42860579},{"atl":[[75,2.69],[40,3.41],[50,2.71],[100,2.01]],"id":42860579}],"con":true,"img":false}]}
{"op":"mcm","clk":"5351869726","pt":1646177573150,"mc":[{"id":"1.195453772","rc":[{"spn":11.25,"spf":"NaN","id":36500408},{"atb":[[17,0],[12,0],[9.8,0],[14.5,0]],"id":42077854},{"atl":[[270,0],[170,0],[220,0],[120,0]],"id":42077854},{"spn":"NaN","spf":"NaN","id":42077854},{"atb":[[8,0],[9,0],[6,0],[7,0]],"id":42860579},{"atl":[[75,0],[40,0],[50,0],[100,0]],"id":42860579}],"con":true,"img":false}]}
{"op":"mcm","clk":"5351870292","pt":1646177583506,"mc":[{"id":"1.195453772","rc":[{"atb":[[18,6.04],[10.5,10.81],[13,8.56],[15.5,7.08]],"id":42077854},{"atl":[[130,1.02],[280,0.71],[180,0.74],[230,0.87]],"id":42077854},{"atb":[[8.6,13.52],[5.8,21.4],[7.6,15.56],[6.6,18.35]],"id":42860579},{"atl":[[65,3.11],[36,3.79],[90,2.24],[46,2.95]],"id":42860579}],"con":true,"img":false}]}
{"op":"mcm","clk":"5352003871","pt":1646180202622,"mc":[{"id":"1.195453772","marketDefinition":{"bspMarket":true,"turnInPlayEnabled":false,"persistenceEnabled":false,"marketBaseRate":7.0,"eventId":"31272499","eventTypeId":"4339","numberOfWinners":1,"bettingType":"ODDS","marketType":"WIN","marketTime":"2022-03-02T10:15:00.000Z","suspendTime":"2022-03-02T10:15:00.000Z","bspReconciled":false,"complete":true,"inPlay":false,"crossMatching":false,"runnersVoidable":false,"numberOfActiveRunners":8,"betDelay":0,"status":"OPEN","runners":[{"status":"ACTIVE","sortPriority":1,"id":36500408,"name":"1. Mexicali Jane"},{"status":"ACTIVE","sortPriority":2,"id":42860579,"name":"2. Petite Olga"},{"status":"ACTIVE","sortPriority":3,"id":39786791,"name":"3. Tiger Talks"},{"status":"ACTIVE","sortPriority":4,"id":43167135,"name":"4. Pereira"},{"status":"ACTIVE","sortPriority":5,"id":42077854,"name":"5. Red Card Bob"},{"status":"ACTIVE","sortPriority":6,"id":37260099,"name":"7. Hear Footsteps"},{"status":"ACTIVE","sortPriority":7,"id":40120078,"name":"8. Informality"},{"status":"ACTIVE","sortPriority":8,"id":28506637,"name":"9. Tuesdays Gone"}],"regulators":["MR_INT"],"venue":"Rockhampton","countryCode":"AU","discountAllowed":true,"timezone":"Australia/Queensland","openDate":"2022-03-02T08:34:00.000Z","version":4382437855,"name":"R6 407m Gr3/4","eventName":"Rockhampton (AUS) 2nd Mar"},"rc":[{"atb":[[4,34.25],[4.5,29.36],[5,25.69],[3.75,37.36]],"id":43167135},{"atl":[[16,8.86],[18.5,7.6],[22,9.5],[27,7.67]],"id":43167135},{"spn":10.5,"spf":"NaN","id":43167135},{"atb":[[2,102.76],[1.85,120.89],[1.9,114.17],[1.95,108.16]],"id":40120078},{"atl":[[5.6,43.39],[5.1,32.45],[4.6,36.96],[6.2,38.38]],"id":40120078},{"spn":3.3,"spf":"NaN","id":40120078},{"atb":[[34,3.11],[18.5,5.87],[22,4.89],[27,3.95]],"id":37260099},{"atl":[[300,0.44],[350,0.57],[400,0.5],[250,0.53]],"id":37260099},{"spn":142.0,"spf":"NaN","id":37260099},{"atb":[[4,34.25],[4.5,29.36],[5,25.69],[5.5,22.83]],"id":36500408},{"atl":[[17,8.31],[19.5,7.19],[24,8.67],[29,7.12]],"id":36500408},{"spn":11.25,"spf":"NaN","id":36500408},{"atb":[[34,3.11],[18.5,5.87],[22,4.89],[27,3.95]],"id":28506637},{"atl":[[300,0.44],[350,0.57],[400,0.5],[250,0.53]],"id":28506637},{"spn":142.0,"spf":"NaN","id":28506637},{"atb":[[18,6.04],[10.5,10.81],[13,8.56],[15.5,7.08]],"id":42077854},{"atl":[[130,1.02],[280,0.71],[180,0.74],[230,0.87]],"id":42077854},{"spn":74.0,"spf":"NaN","id":42077854},{"atb":[[8.6,13.52],[5.8,21.4],[7.6,15.57],[6.6,18.35]],"id":42860579},{"atl":[[65,3.11],[36,3.8],[90,2.24],[46,2.95]],"id":42860579},{"spn":22.3,"spf":"NaN","id":42860579},{"atb":[[4.6,28.54],[4.1,33.15],[3.8,36.69],[3.55,40.29]],"id":39786791},{"atl":[[17,8.31],[19.5,10.79],[24,8.67],[14.5,9.85]],"id":39786791},{"spn":9.55,"spf":"NaN","id":39786791}],"con":true,"img":true}]}
{"op":"mcm","clk":"5352146204","pt":1646183572661,"mc":[{"id":"1.195453772","marketDefinition":{"bspMarket":true,"turnInPlayEnabled":false,"persistenceEnabled":false,"marketBaseRate":7.0,"eventId":"31272499","eventTypeId":"4339","numberOfWinners":1,"bettingType":"ODDS","marketType":"WIN","marketTime":"2022-03-02T10:15:00.000Z","suspendTime":"2022-03-02T10:15:00.000Z","bspReconciled":false,"complete":true,"inPlay":false,"crossMatching":false,"runnersVoidable":false,"numberOfActiveRunners":8,"betDelay":0,"status":"OPEN","runners":[{"status":"ACTIVE","sortPriority":1,"id":36500408,"name":"1. Mexicali Jane"},{"status":"ACTIVE","sortPriority":2,"id":42860579,"name":"2. Petite Olga"},{"status":"ACTIVE","sortPriority":3,"id":39786791,"name":"3. Tiger Talks"},{"status":"ACTIVE","sortPriority":4,"id":43167135,"name":"4. Pereira"},{"status":"ACTIVE","sortPriority":5,"id":42077854,"name":"5. Red Card Bob"},{"status":"ACTIVE","sortPriority":6,"id":37260099,"name":"7. Hear Footsteps"},{"status":"ACTIVE","sortPriority":7,"id":40120078,"name":"8. Informality"},{"status":"ACTIVE","sortPriority":8,"id":28506637,"name":"9. Tuesdays Gone"}],"regulators":["MR_INT"],"venue":"Rockhampton","countryCode":"AU","discountAllowed":true,"timezone":"Australia/Queensland","openDate":"2022-03-02T08:28:00.000Z","version":4382597836,"name":"R6 407m Gr3/4","eventName":"Rockhampton (AUS) 2nd Mar"},"rc":[],"con":true,"img":false}]}
{"op":"mcm","clk":"5352159039","pt":1646183914364,"mc":[{"id":"1.195453772","marketDefinition":{"bspMarket":true,"turnInPlayEnabled":false,"persistenceEnabled":false,"marketBaseRate":7.0,"eventId":"31272499","eventTypeId":"4339","numberOfWinners":1,"bettingType":"ODDS","marketType":"WIN","marketTime":"2022-03-02T10:08:00.000Z","suspendTime":"2022-03-02T10:08:00.000Z","bspReconciled":false,"complete":true,"inPlay":false,"crossMatching":false,"runnersVoidable":false,"numberOfActiveRunners":8,"betDelay":0,"status":"OPEN","runners":[{"status":"ACTIVE","sortPriority":1,"id":36500408,"name":"1. Mexicali Jane"},{"status":"ACTIVE","sortPriority":2,"id":42860579,"name":"2. Petite Olga"},{"status":"ACTIVE","sortPriority":3,"id":39786791,"name":"3. Tiger Talks"},{"status":"ACTIVE","sortPriority":4,"id":43167135,"name":"4. Pereira"},{"status":"ACTIVE","sortPriority":5,"id":42077854,"name":"5. Red Card Bob"},{"status":"ACTIVE","sortPriority":6,"id":37260099,"name":"7. Hear Footsteps"},{"status":"ACTIVE","sortPriority":7,"id":40120078,"name":"8. Informality"},{"status":"ACTIVE","sortPriority":8,"id":28506637,"name":"9. Tuesdays Gone"}],"regulators":["MR_INT"],"venue":"Rockhampton","countryCode":"AU","discountAllowed":true,"timezone":"Australia/Queensland","openDate":"2022-03-02T08:28:00.000Z","version":4382602386,"name":"R6 407m Gr3/4","eventName":"Rockhampton (AUS) 2nd Mar"},"rc":[],"con":true,"img":false}]}
{"op":"mcm","clk":"5352237991","pt":1646185602657,"mc":[{"id":"1.195453772","marketDefinition":{"bspMarket":true,"turnInPlayEnabled":false,"persistenceEnabled":false,"marketBaseRate":7.0,"eventId":"31272499","eventTypeId":"4339","numberOfWinners":1,"bettingType":"ODDS","marketType":"WIN","marketTime":"2022-03-02T10:08:00.000Z","suspendTime":"2022-03-02T10:08:00.000Z","bspReconciled":false,"complete":true,"inPlay":false,"crossMatching":false,"runnersVoidable":false,"numberOfActiveRunners":8,"betDelay":0,"status":"OPEN","runners":[{"status":"ACTIVE","sortPriority":1,"id":36500408,"name":"1. Mexicali Jane"},{"status":"ACTIVE","sortPriority":2,"id":42860579,"name":"2. Petite Olga"},{"status":"ACTIVE","sortPriority":3,"id":39786791,"name":"3. Tiger Talks"},{"status":"ACTIVE","sortPriority":4,"id":43167135,"name":"4. Pereira"},{"status":"ACTIVE","sortPriority":5,"id":42077854,"name":"5. Red Card Bob"},{"status":"ACTIVE","sortPriority":6,"id":37260099,"name":"7. Hear Footsteps"},{"status":"ACTIVE","sortPriority":7,"id":40120078,"name":"8. Informality"},{"status":"ACTIVE","sortPriority":8,"id":28506637,"name":"9. Tuesdays Gone"}],"regulators":["MR_INT"],"venue":"Rockhampton","countryCode":"AU","discountAllowed":true,"timezone":"Australia/Queensland","openDate":"2022-03-02T08:28:00.000Z","version":4382602386,"name":"R6 407m Gr3/4","eventName":"Rockhampton (AUS) 2nd Mar"},"rc":[{"atb":[[4,34.3],[4.5,29.4],[5,25.73],[3.75,37.42]],"id":43167135},{"atl":[[16,8.88],[18.5,7.61],[22,9.52],[27,7.68]],"id":43167135},{"spn":10.5,"spf":"NaN","id":43167135},{"atb":[[2,102.92],[1.85,121.08],[1.9,114.35],[1.95,108.33]],"id":40120078},{"atl":[[5.6,43.45],[5.1,32.5],[4.6,37.01],[6.2,38.44]],"id":40120078},{"spn":3.3,"spf":"NaN","id":40120078},{"atb":[[34,3.11],[18.5,5.88],[22,4.9],[27,3.95]],"id":37260099},{"atl":[[300,0.44],[350,0.57],[400,0.5],[250,0.53]],"id":37260099},{"spn":142.0,"spf":"NaN","id":37260099},{"atb":[[4,34.3],[4.5,29.4],[5,25.73],[5.5,22.86]],"id":36500408},{"atl":[[17,8.33],[19.5,7.2],[24,8.69],[29,7.13]],"id":36500408},{"spn":11.25,"spf":"NaN","id":36500408},{"atb":[[34,3.11],[18.5,5.88],[22,4.9],[27,3.95]],"id":28506637},{"atl":[[300,0.44],[350,0.57],[400,0.5],[250,0.53]],"id":28506637},{"spn":142.0,"spf":"NaN","id":28506637},{"atb":[[18,6.05],[10.5,10.83],[13,8.57],[15.5,7.09]],"id":42077854},{"atl":[[130,1.03],[280,0.71],[180,0.74],[230,0.87]],"id":42077854},{"spn":74.0,"spf":"NaN","id":42077854},{"atb":[[8.6,13.54],[5.8,21.44],[7.6,15.59],[6.6,18.38]],"id":42860579},{"atl":[[65,3.12],[36,3.8],[90,2.24],[46,2.96]],"id":42860579},{"spn":22.3,"spf":"NaN","id":42860579},{"atb":[[4.6,28.58],[4.1,33.2],[3.8,36.75],[3.55,40.36]],"id":39786791},{"atl":[[17,8.33],[19.5,10.8],[24,8.69],[14.5,9.86]],"id":39786791},{"spn":9.55,"spf":"NaN","id":39786791}],"con":true,"img":true}]}
{"op":"mcm","clk":"5352465288","pt":1646191002605,"mc":[{"id":"1.195453772","marketDefinition":{"bspMarket":true,"turnInPlayEnabled":false,"persistenceEnabled":false,"marketBaseRate":7.0,"eventId":"31272499","eventTypeId":"4339","numberOfWinners":1,"bettingType":"ODDS","marketType":"WIN","marketTime":"2022-03-02T10:08:00.000Z","suspendTime":"2022-03-02T10:08:00.000Z","bspReconciled":false,"complete":true,"inPlay":false,"crossMatching":false,"runnersVoidable":false,"numberOfActiveRunners":8,"betDelay":0,"status":"OPEN","runners":[{"status":"ACTIVE","sortPriority":1,"id":36500408,"name":"1. Mexicali Jane"},{"status":"ACTIVE","sortPriority":2,"id":42860579,"name":"2. Petite Olga"},{"status":"ACTIVE","sortPriority":3,"id":39786791,"name":"3. Tiger Talks"},{"status":"ACTIVE","sortPriority":4,"id":43167135,"name":"4. Pereira"},{"status":"ACTIVE","sortPriority":5,"id":42077854,"name":"5. Red Card Bob"},{"status":"ACTIVE","sortPriority":6,"id":37260099,"name":"7. Hear Footsteps"},{"status":"ACTIVE","sortPriority":7,"id":40120078,"name":"8. Informality"},{"status":"ACTIVE","sortPriority":8,"id":28506637,"name":"9. Tuesdays Gone"}],"regulators":["MR_INT"],"venue":"Rockhampton","countryCode":"AU","discountAllowed":true,"timezone":"Australia/Queensland","openDate":"2022-03-02T08:28:00.000Z","version":4382602386,"name":"R6 407m Gr3/4","eventName":"Rockhampton (AUS) 2nd Mar"},"rc":[{"atb":[[4,34.36],[4.5,29.45],[5,25.77],[3.75,37.49]],"id":43167135},{"atl":[[16,8.89],[18.5,7.63],[22,9.53],[27,7.7]],"id":43167135},{"spn":10.5,"spf":"NaN","id":43167135},{"atb":[[2,103.09],[1.85,121.29],[1.9,114.55],[1.95,108.52]],"id":40120078},{"atl":[[5.6,43.53],[5.1,32.55],[4.6,37.08],[6.2,38.5]],"id":40120078},{"spn":3.3,"spf":"NaN","id":40120078},{"atb":[[34,3.12],[18.5,5.89],[22,4.91],[27,3.96]],"id":37260099},{"atl":[[300,0.44],[350,0.57],[400,0.5],[250,0.53]],"id":37260099},{"spn":142.0,"spf":"NaN","id":37260099},{"atb":[[4,34.36],[4.5,29.45],[5,25.77],[5.5,22.9]],"id":36500408},{"atl":[[17,8.34],[19.5,7.21],[24,8.7],[29,7.14]],"id":36500408},{"spn":11.25,"spf":"NaN","id":36500408},{"atb":[[34,3.12],[18.5,5.89],[22,4.91],[27,3.96]],"id":28506637},{"atl":[[300,0.44],[350,0.57],[400,0.5],[250,0.53]],"id":28506637},{"spn":142.0,"spf":"NaN","id":28506637},{"atb":[[18,6.06],[10.5,10.85],[13,8.59],[15.5,7.11]],"id":42077854},{"atl":[[130,1.03],[280,0.71],[180,0.74],[230,0.87]],"id":42077854},{"spn":74.0,"spf":"NaN","id":42077854},{"atb":[[8.6,13.56],[5.8,21.47],[7.6,15.62],[6.6,18.41]],"id":42860579},{"atl":[[65,3.12],[36,3.81],[90,2.25],[46,2.96]],"id":42860579},{"spn":22.3,"spf":"NaN","id":42860579},{"atb":[[4.6,28.63],[4.1,33.25],[3.8,36.81],[3.55,40.43]],"id":39786791},{"atl":[[17,8.34],[19.5,10.82],[24,8.7],[14.5,9.88]],"id":39786791},{"spn":9.55,"spf":"NaN","id":39786791}],"con":true,"img":true}]}
{"op":"mcm","clk":"5352614876","pt":1646195096570,"mc":[{"id":"1.195453772","rc":[{"atb":[[4,34.36],[4.5,29.45],[5,25.77],[3.75,37.49]],"id":43167135},{"atl":[[16,8.89],[18.5,7.63],[22,9.53],[27,7.7]],"id":43167135},{"atb":[[2,103.09],[1.85,121.29],[1.9,114.55],[1.95,108.52]],"id":40120078},{"spl":[[1.01,21.84]],"id":40120078},{"atl":[[5.6,43.53],[5.1,32.55],[4.6,37.08],[6.2,38.5]],"id":40120078},{"spn":2.0,"spf":1.0,"id":40120078},{"atb":[[34,3.12],[18.5,5.89],[22,4.91],[27,3.96]],"id":37260099},{"atl":[[300,0.44],[350,0.57],[400,0.5],[250,0.53]],"id":37260099},{"atb":[[4,34.36],[4.5,29.45],[5,25.77],[5.5,22.9]],"id":36500408},{"atl":[[17,8.34],[19.5,7.21],[24,8.7],[29,7.14]],"id":36500408},{"atb":[[34,3.12],[18.5,5.89],[22,4.91],[27,3.96]],"id":28506637},{"atl":[[300,0.44],[350,0.57],[400,0.5],[250,0.53]],"id":28506637},{"atb":[[18,6.06],[10.5,10.85],[13,8.59],[15.5,7.11]],"id":42077854},{"atl":[[130,1.03],[280,0.71],[180,0.74],[230,0.87]],"id":42077854},{"spn":74.0,"spf":"NaN","id":42077854},{"atb":[[8.6,13.56],[5.8,21.47],[7.6,15.62],[6.6,18.41]],"id":42860579},{"atl":[[65,3.12],[36,3.81],[90,2.25],[46,2.96]],"id":42860579},{"spn":22.3,"spf":"NaN","id":42860579},{"atb":[[4.6,28.63],[4.1,33.25],[3.8,36.81],[3.55,40.43]],"id":39786791},{"atl":[[17,8.34],[19.5,10.82],[24,8.7],[14.5,9.88]],"id":39786791}],"con":true,"img":false}]}
{"op":"mcm","clk":"5352646203","pt":1646195941074,"mc":[{"id":"1.195453772","rc":[{"atl":[[3.25,8.19]],"id":40120078}],"con":true,"img":false}]}
{"op":"mcm","clk":"5352720547","pt":1646198181648,"mc":[{"id":"1.195453772","rc":[{"atb":[[4,34.35],[4.5,29.44],[5,25.76],[3.75,37.47]],"id":43167135},{"atl":[[16,8.89],[18.5,7.62],[22,9.53],[27,7.69]],"id":43167135},{"atb":[[2,103.05],[1.85,121.24],[1.9,114.5],[1.95,108.47]],"id":40120078},{"spl":[[1.01,21.84]],"id":40120078},{"atl":[[5.6,43.51],[5.1,32.54],[4.6,37.06],[6.2,38.49],[3.25,8.19],[2.7,6.2]],"id":40120078},{"atb":[[34,3.12],[18.5,5.89],[22,4.9],[27,3.96]],"id":37260099},{"atl":[[300,0.44],[350,0.57],[400,0.5],[250,0.53]],"id":37260099},{"atb":[[4,34.35],[4.5,29.44],[5,25.76],[5.5,22.89]],"id":36500408},{"atl":[[17,8.34],[19.5,7.21],[24,8.7],[29,7.14]],"id":36500408},{"atb":[[34,3.12],[18.5,5.89],[22,4.9],[27,3.96]],"id":28506637},{"atl":[[300,0.44],[350,0.57],[400,0.5],[250,0.53]],"id":28506637},{"atb":[[18,6.06],[10.5,10.84],[13,8.58],[15.5,7.1]],"id":42077854},{"atl":[[130,1.03],[280,0.71],[180,0.74],[230,0.87]],"id":42077854},{"atb":[[8.6,13.56],[5.8,21.46],[7.6,15.61],[6.6,18.4]],"id":42860579},{"atl":[[65,3.12],[36,3.81],[90,2.24],[46,2.96]],"id":42860579},{"atb":[[4.6,28.62],[4.1,33.24],[3.8,36.8],[3.55,40.41]],"id":39786791},{"atl":[[17,8.34],[19.5,10.82],[24,8.7],[14.5,9.88]],"id":39786791}],"con":true,"img":false}]}
{"op":"mcm","clk":"5352720644","pt":1646198185693,"mc":[{"id":"1.195453772","rc":[{"atl":[[3,4.92]],"id":40120078}],"con":true,"img":false}]}
{"op":"mcm","clk":"5352772392","pt":1646200024613,"mc":[{"id":"1.195453772","rc":[{"atl":[[120,0.49]],"id":42077854},{"spn":69.0,"spf":"NaN","id":42077854}],"con":true,"img":false}]}
{"op":"mcm","clk":"5352772395","pt":1646200024718,"mc":[{"id":"1.195453772","rc":[{"atl":[[340,0.49]],"id":37260099}],"con":true,"img":false}]}
{"op":"mcm","clk":"5352772401","pt":1646200024820,"mc":[{"id":"1.195453772","rc":[{"atl":[[340,0.49]],"id":28506637}],"con":true,"img":false}]}
{"op":"mcm","clk":"5352772968","pt":1646200051970,"mc":[{"id":"1.195453772","marketDefinition":{"bspMarket":true,"turnInPlayEnabled":false,"persistenceEnabled":false,"marketBaseRate":7.0,"eventId":"31272499","eventTypeId":"4339","numberOfWinners":1,"bettingType":"ODDS","marketType":"WIN","marketTime":"2022-03-02T10:08:00.000Z","suspendTime":"2022-03-02T10:08:00.000Z","bspReconciled":false,"complete":true,"inPlay":false,"crossMatching":true,"runnersVoidable":false,"numberOfActiveRunners":8,"betDelay":0,"status":"OPEN","runners":[{"status":"ACTIVE","sortPriority":1,"id":36500408,"name":"1. Mexicali Jane"},{"status":"ACTIVE","sortPriority":2,"id":42860579,"name":"2. Petite Olga"},{"status":"ACTIVE","sortPriority":3,"id":39786791,"name":"3. Tiger Talks"},{"status":"ACTIVE","sortPriority":4,"id":43167135,"name":"4. Pereira"},{"status":"ACTIVE","sortPriority":5,"id":42077854,"name":"5. Red Card Bob"},{"status":"ACTIVE","sortPriority":6,"id":37260099,"name":"7. Hear Footsteps"},{"status":"ACTIVE","sortPriority":7,"id":40120078,"name":"8. Informality"},{"status":"ACTIVE","sortPriority":8,"id":28506637,"name":"9. Tuesdays Gone"}],"regulators":["MR_INT"],"venue":"Rockhampton","countryCode":"AU","discountAllowed":true,"timezone":"Australia/Queensland","openDate":"2022-03-02T08:28:00.000Z","version":4382602386,"name":"R6 407m Gr3/4","eventName":"Rockhampton (AUS) 2nd Mar"},"rc":[],"con":true,"img":false}]}
{"op":"mcm","clk":"5353005147","pt":1646206847771,"mc":[{"id":"1.195453772","rc":[{"atb":[[4,34.34],[4.5,29.43],[5,25.75],[3.75,37.46]],"id":43167135},{"atl":[[16,8.89],[18.5,7.62],[22,9.53],[27,7.69]],"id":43167135},{"atb":[[2,103.02],[1.85,121.21],[1.9,114.47],[1.95,108.44]],"id":40120078},{"spl":[[1.01,21.83]],"id":40120078},{"atl":[[5.6,43.5],[5.1,32.53],[4.6,37.05],[6.2,38.48],[3,4.93],[3.25,8.18],[2.7,6.21]],"id":40120078},{"atb":[[34,3.12],[18.5,5.88],[22,4.9],[27,3.96]],"id":37260099},{"atl":[[300,0.44],[350,0.57],[400,0.5],[250,0.53]],"id":37260099},{"atb":[[4,34.34],[5.6,2.19],[4.5,29.43],[5,25.75],[5.5,22.89]],"id":36500408},{"atl":[[17,8.34],[19.5,7.21],[24,8.7],[29,7.14]],"id":36500408},{"spn":11.3,"spf":"NaN","id":36500408},{"atb":[[34,3.12],[18.5,5.88],[22,4.9],[27,3.96]],"id":28506637},{"atl":[[300,0.44],[350,0.57],[400,0.5],[250,0.53]],"id":28506637},{"atb":[[18,6.05],[10.5,10.84],[13,8.58],[15.5,7.1]],"id":42077854},{"atl":[[130,1.03],[280,0.71],[180,0.74],[230,0.87]],"id":42077854},{"atb":[[8.6,13.55],[5.8,21.46],[7.6,15.61],[6.6,18.4]],"id":42860579},{"atl":[[65,3.12],[36,3.81],[90,2.24],[46,2.96]],"id":42860579},{"atb":[[4.6,28.61],[4.1,33.23],[3.8,36.79],[3.55,40.4]],"id":39786791},{"atl":[[17,8.34],[19.5,10.81],[24,8.7],[14.5,9.87]],"id":39786791}],"con":true,"img":false}]}
{"op":"mcm","clk":"5353005160","pt":1646206848029,"mc":[{"id":"1.195453772","rc":[{"atb":[[5.1,2.46]],"id":43167135},{"atb":[[2.04,9.72]],"id":40120078}],"con":true,"img":false}]}
{"op":"mcm","clk":"5353005173","pt":1646206848340,"mc":[{"id":"1.195453772","rc":[{"atb":[[4.7,2.73]],"id":39786791}],"con":true,"img":false}]}
{"op":"mcm","clk":"5353006870","pt":1646206889921,"mc":[{"id":"1.195453772","rc":[{"atb":[[1.01,2.25]],"id":43167135},{"atb":[[2.04,16.96]],"id":40120078},{"atb":[[1.01,2.25]],"id":36500408},{"atb":[[1.01,2.25]],"id":39786791}],"con":true,"img":false}]}
{"op":"mcm","clk":"5353006883","pt":1646206890127,"mc":[{"id":"1.195453772","rc":[{"atb":[[1.01,1.83]],"id":43167135},{"atb":[[1.01,1.63]],"id":36500408},{"atb":[[1.01,2.03]],"id":39786791}],"con":true,"img":false}]}
{"op":"mcm","clk":"5353006894","pt":1646206890334,"mc":[{"id":"1.195453772","rc":[{"atb":[[1.01,0]],"id":39786791}],"con":true,"img":false}]}
{"op":"mcm","clk":"5353006899","pt":1646206890437,"mc":[{"id":"1.195453772","rc":[{"atb":[[4.7,4.76]],"id":39786791}],"con":true,"img":false}]}
{"op":"mcm","clk":"5353006911","pt":1646206890698,"mc":[{"id":"1.195453772","rc":[{"atb":[[1.01,0]],"id":36500408}],"con":true,"img":false}]}
{"op":"mcm","clk":"5353006918","pt":1646206890800,"mc":[{"id":"1.195453772","rc":[{"atb":[[5.6,3.82]],"id":36500408}],"con":true,"img":false}]}
{"op":"mcm","clk":"5353006927","pt":1646206891007,"mc":[{"id":"1.195453772","rc":[{"atb":[[1.01,0]],"id":43167135}],"con":true,"img":false}]}
{"op":"mcm","clk":"5353006933","pt":1646206891107,"mc":[{"id":"1.195453772","rc":[{"atb":[[5.1,4.3]],"id":43167135}],"con":true,"img":false}]}
{"op":"mcm","clk":"5353027457","pt":1646207202672,"mc":[{"id":"1.195453772","marketDefinition":{"bspMarket":true,"turnInPlayEnabled":false,"persistenceEnabled":false,"marketBaseRate":7.0,"eventId":"31272499","eventTypeId":"4339","numberOfWinners":1,"bettingType":"ODDS","marketType":"WIN","marketTime":"2022-03-02T10:08:00.000Z","suspendTime":"2022-03-02T10:08:00.000Z","bspReconciled":false,"complete":true,"inPlay":false,"crossMatching":true,"runnersVoidable":false,"numberOfActiveRunners":8,"betDelay":0,"status":"OPEN","runners":[{"status":"ACTIVE","sortPriority":1,"id":36500408,"name":"1. Mexicali Jane"},{"status":"ACTIVE","sortPriority":2,"id":42860579,"name":"2. Petite Olga"},{"status":"ACTIVE","sortPriority":3,"id":39786791,"name":"3. Tiger Talks"},{"status":"ACTIVE","sortPriority":4,"id":43167135,"name":"4. Pereira"},{"status":"ACTIVE","sortPriority":5,"id":42077854,"name":"5. Red Card Bob"},{"status":"ACTIVE","sortPriority":6,"id":37260099,"name":"7. Hear Footsteps"},{"status":"ACTIVE","sortPriority":7,"id":40120078,"name":"8. Informality"},{"status":"ACTIVE","sortPriority":8,"id":28506637,"name":"9. Tuesdays Gone"}],"regulators":["MR_INT"],"venue":"Rockhampton","countryCode":"AU","discountAllowed":true,"timezone":"Australia/Queensland","openDate":"2022-03-02T08:28:00.000Z","version":4382602386,"name":"R6 407m Gr3/4","eventName":"Rockhampton (AUS) 2nd Mar"},"rc":[{"atb":[[4,34.34],[5.1,4.3],[4.5,29.43],[5,25.75],[3.75,37.46]],"id":43167135},{"atl":[[16,8.89],[18.5,7.62],[22,9.53],[27,7.69]],"id":43167135},{"spn":10.55,"spf":"NaN","id":43167135},{"atb":[[2,103.02],[2.04,16.96],[1.85,121.21],[1.9,114.47],[1.95,108.44]],"id":40120078},{"spl":[[1.01,21.83]],"id":40120078},{"atl":[[5.6,43.5],[5.1,32.53],[4.6,37.05],[6.2,38.48],[3,4.93],[3.25,8.18],[2.7,6.21]],"id":40120078},{"spn":2.03,"spf":1.0,"id":40120078},{"atb":[[34,3.12],[18.5,5.88],[22,4.9],[27,3.96]],"id":37260099},{"atl":[[300,0.44],[340,0.49],[350,0.57],[400,0.5],[250,0.53]],"id":37260099},{"spn":142.0,"spf":"NaN","id":37260099},{"atb":[[5.6,3.82],[4,34.34],[4.5,29.43],[5,25.75],[5.5,22.89]],"id":36500408},{"atl":[[17,8.34],[19.5,7.21],[24,8.7],[29,7.14]],"id":36500408},{"spn":11.3,"spf":"NaN","id":36500408},{"atb":[[34,3.12],[18.5,5.88],[22,4.9],[27,3.96]],"id":28506637},{"atl":[[300,0.44],[340,0.49],[350,0.57],[400,0.5],[250,0.53]],"id":28506637},{"spn":142.0,"spf":"NaN","id":28506637},{"atb":[[18,6.05],[10.5,10.84],[13,8.58],[15.5,7.1]],"id":42077854},{"atl":[[130,1.03],[280,0.71],[180,0.74],[230,0.87],[120,0.49]],"id":42077854},{"spn":69.0,"spf":"NaN","id":42077854},{"atb":[[8.6,13.55],[5.8,21.46],[7.6,15.61],[6.6,18.4]],"id":42860579},{"atl":[[65,3.12],[36,3.81],[90,2.24],[46,2.96]],"id":42860579},{"spn":22.3,"spf":"NaN","id":42860579},{"atb":[[4.6,28.61],[4.1,33.23],[3.8,36.79],[3.55,40.4],[4.7,4.76]],"id":39786791},{"atl":[[17,8.34],[19.5,10.81],[24,8.7],[14.5,9.87]],"id":39786791},{"spn":9.6,"spf":"NaN","id":39786791}],"con":true,"img":true}]}
{"op":"mcm","clk":"5353043742","pt":1646207518160,"mc":[{"id":"1.195453772","rc":[{"spl":[[1.01,10.91]],"id":43167135},{"spn":5.03,"spf":1.0,"id":43167135},{"spn":2.03,"spf":1.0,"id":40120078},{"spn":9.6,"spf":"NaN","id":39786791}],"con":true,"img":false}]}
{"op":"mcm","clk":"5353084220","pt":1646208480124,"mc":[{"id":"1.195453772","rc":[{"atb":[[1.85,123.21]],"id":40120078},{"atb":[[32,0.33]],"id":37260099},{"atb":[[5.1,2]],"id":36500408},{"atb":[[32,0.33]],"id":28506637}],"con":true,"img":false}]}
{"op":"mcm","clk":"5353084224","pt":1646208480225,"mc":[{"id":"1.195453772","rc":[{"atb":[[4.4,2]],"id":43167135},{"atb":[[15.5,7.8]],"id":42077854},{"atb":[[8.2,1.4]],"id":42860579},{"atb":[[4.7,6.76]],"id":39786791}],"con":true,"img":false}]}
{"op":"mcm","clk":"5353090475","pt":1646208623509,"mc":[{"id":"1.195453772","rc":[{"atb":[[32,0]],"id":28506637}],"con":true,"img":false}]}
{"op":"mcm","clk":"5353090484","pt":1646208623613,"mc":[{"id":"1.195453772","rc":[{"atb":[[36,0.3]],"id":28506637}],"con":true,"img":false}]}
{"op":"mcm","clk":"5353149047","pt":1646209829170,"mc":[{"id":"1.195453772","rc":[{"atl":[[4.5,4.48]],"id":40120078},{"spn":143.0,"spf":"NaN","id":28506637}],"con":true,"img":false}]}
{"op":"mcm","clk":"5353152159","pt":1646209885773,"mc":[{"id":"1.195453772","rc":[{"atl":[[4.5,7.82]],"id":40120078}],"con":true,"img":false}]}
{"op":"mcm","clk":"5353155307","pt":1646209949331,"mc":[{"id":"1.195453772","rc":[{"atl":[[4.5,3.34]],"id":40120078}],"con":true,"img":false}]}
{"op":"mcm","clk":"5353155945","pt":1646209961374,"mc":[{"id":"1.195453772","rc":[{"atl":[[4.5,7.82]],"id":40120078}],"con":true,"img":false}]}
{"op":"mcm","clk":"5353158240","pt":1646210003101,"mc":[{"id":"1.195453772","rc":[{"atl":[[4.5,4.48]],"id":40120078}],"con":true,"img":false}]}
{"op":"mcm","clk":"5353158410","pt":1646210006039,"mc":[{"id":"1.195453772","rc":[{"atl":[[4.5,7.82]],"id":40120078}],"con":true,"img":false}]}
{"op":"mcm","clk":"5353162625","pt":1646210085183,"mc":[{"id":"1.195453772","rc":[{"atl":[[4.5,3.34]],"id":40120078}],"con":true,"img":false}]}
{"op":"mcm","clk":"5353163238","pt":1646210096624,"mc":[{"id":"1.195453772","rc":[{"atl":[[4.5,7.82]],"id":40120078}],"con":true,"img":false}]}
{"op":"mcm","clk":"5353164624","pt":1646210123350,"mc":[{"id":"1.195453772","rc":[{"atl":[[4.5,4.48]],"id":40120078}],"con":true,"img":false}]}
{"op":"mcm","clk":"5353164782","pt":1646210126223,"mc":[{"id":"1.195453772","rc":[{"atl":[[4.5,7.82]],"id":40120078}],"con":true,"img":false}]}
{"op":"mcm","clk":"5353169658","pt":1646210216845,"mc":[{"id":"1.195453772","rc":[{"atl":[[4.5,3.34]],"id":40120078}],"con":true,"img":false}]}
{"op":"mcm","clk":"5353170249","pt":1646210228744,"mc":[{"id":"1.195453772","rc":[{"atl":[[4.5,7.82]],"id":40120078}],"con":true,"img":false}]}
{"op":"mcm","clk":"5353171050","pt":1646210243602,"mc":[{"id":"1.195453772","rc":[{"atl":[[4.5,4.48]],"id":40120078}],"con":true,"img":false}]}
{"op":"mcm","clk":"5353171211","pt":1646210246484,"mc":[{"id":"1.195453772","rc":[{"atl":[[4.5,7.82]],"id":40120078}],"con":true,"img":false}]}
{"op":"mcm","clk":"5353174528","pt":1646210307480,"mc":[{"id":"1.195453772","rc":[{"atb":[[4.1,18.88],[3.8,41.32]],"id":43167135},{"atl":[[12,10.51],[8.8,7.5]],"id":43167135},{"atb":[[1.86,60.71],[1.61,182.54]],"id":40120078},{"atl":[[4,31.81],[3.1,27.87]],"id":40120078},{"atb":[[36,2.72],[23,6]],"id":37260099},{"atl":[[170,0.34],[230,2.72]],"id":37260099},{"spn":103.0,"spf":"NaN","id":37260099},{"atb":[[5.6,42.36]],"id":36500408},{"atl":[[16.5,7.65],[13,4.87]],"id":36500408},{"spn":9.3,"spf":"NaN","id":36500408},{"atb":[[36,3.02],[26,4.26]],"id":28506637},{"atl":[[240,2.97]],"id":28506637},{"spn":138.0,"spf":"NaN","id":28506637},{"atb":[[13.5,8.62],[14,4.5]],"id":42077854},{"atl":[[65,2.72],[46,2.72]],"id":42077854},{"spn":32.0,"spf":"NaN","id":42077854},{"atb":[[8.8,7.5],[7.8,17.82]],"id":42860579},{"atl":[[21,2.92],[29,3.67]],"id":42860579},{"spn":14.9,"spf":"NaN","id":42860579},{"atb":[[4.2,39.3],[4.7,22.58]],"id":39786791},{"atl":[[10.5,6.16],[14,9.82]],"id":39786791},{"spn":7.6,"spf":"NaN","id":39786791}],"con":true,"img":false}]}
{"op":"mcm","clk":"5353175013","pt":1646210315746,"mc":[{"id":"1.195453772","rc":[{"atb":[[5.6,40.73]],"id":36500408},{"atb":[[4.7,20.55]],"id":39786791}],"con":true,"img":false}]}
{"op":"mcm","clk":"5353175444","pt":1646210324580,"mc":[{"id":"1.195453772","rc":[{"atb":[[1.01,2.25]],"id":36500408},{"atb":[[1.01,2.25]],"id":39786791}],"con":true,"img":false}]}
{"op":"mcm","clk":"5353175452","pt":1646210324786,"mc":[{"id":"1.195453772","rc":[{"atb":[[1.01,1.6]],"id":36500408},{"atb":[[1.01,1.97]],"id":39786791}],"con":true,"img":false}]}
{"op":"mcm","clk":"5353175460","pt":1646210324991,"mc":[{"id":"1.195453772","rc":[{"atb":[[1.01,0]],"id":36500408}],"con":true,"img":false}]}
{"op":"mcm","clk":"5353175465","pt":1646210325095,"mc":[{"id":"1.195453772","rc":[{"atb":[[5.7,1.6]],"id":36500408}],"con":true,"img":false}]}
{"op":"mcm","clk":"5353175470","pt":1646210325250,"mc":[{"id":"1.195453772","rc":[{"atb":[[1.01,0]],"id":39786791}],"con":true,"img":false}]}
{"op":"mcm","clk":"5353175475","pt":1646210325355,"mc":[{"id":"1.195453772","rc":[{"atb":[[4.8,1.97]],"id":39786791}],"con":true,"img":false}]}
{"op":"mcm","clk":"5353175901","pt":1646210334064,"mc":[{"id":"1.195453772","rc":[{"atb":[[5.6,38.53]],"id":36500408},{"atb":[[4.7,17.82]],"id":39786791}],"con":true,"img":false}]}
{"op":"mcm","clk":"5353176327","pt":1646210342977,"mc":[{"id":"1.195453772","rc":[{"atb":[[4.8,4.63]],"id":39786791}],"con":true,"img":false}]}
{"op":"mcm","clk":"5353176347","pt":1646210343289,"mc":[{"id":"1.195453772","rc":[{"atb":[[5.7,3.75]],"id":36500408}],"con":true,"img":false}]}
{"op":"mcm","clk":"5353176864","pt":1646210352615,"mc":[{"id":"1.195453772","rc":[{"atl":[[4.5,3.34]],"id":40120078}],"con":true,"img":false}]}
{"op":"mcm","clk":"5353177429","pt":1646210363700,"mc":[{"id":"1.195453772","rc":[{"atl":[[4.5,0]],"id":40120078}],"con":true,"img":false}]}
{"op":"mcm","clk":"5353177492","pt":1646210364834,"mc":[{"id":"1.195453772","rc":[{"atl":[[3.05,6.63]],"id":40120078}],"con":true,"img":false}]}
{"op":"mcm","clk":"5353177596","pt":1646210366637,"mc":[{"id":"1.195453772","rc":[{"atl":[[3.05,11.56]],"id":40120078}],"con":true,"img":false}]}
{"op":"mcm","clk":"5353178871","pt":1646210393561,"mc":[{"id":"1.195453772","rc":[{"spn":9.35,"spf":"NaN","id":36500408},{"atb":[[26,0]],"id":28506637},{"spn":7.65,"spf":"NaN","id":39786791}],"con":true,"img":false}]}
{"op":"mcm","clk":"5353178877","pt":1646210393665,"mc":[{"id":"1.195453772","rc":[{"atb":[[28,4.26]],"id":28506637}],"con":true,"img":false}]}
{"op":"mcm","clk":"5353178884","pt":1646210393766,"mc":[{"id":"1.195453772","rc":[{"atl":[[3.25,0]],"id":40120078}],"con":true,"img":false}]}
{"op":"mcm","clk":"5353183668","pt":1646210483971,"mc":[{"id":"1.195453772","rc":[{"atl":[[3.05,6.63]],"id":40120078}],"con":true,"img":false}]}
{"op":"mcm","clk":"5353183805","pt":1646210486903,"mc":[{"id":"1.195453772","rc":[{"atl":[[3.05,11.56]],"id":40120078}],"con":true,"img":false}]}
{"op":"mcm","clk":"5353184006","pt":1646210490872,"mc":[{"id":"1.195453772","rc":[{"atl":[[3.05,4.93]],"id":40120078}],"con":true,"img":false}]}
{"op":"mcm","clk":"5353184580","pt":1646210500624,"mc":[{"id":"1.195453772","rc":[{"atl":[[3.05,11.56]],"id":40120078}],"con":true,"img":false}]}
{"op":"mcm","clk":"5353190387","pt":1646210604148,"mc":[{"id":"1.195453772","rc":[{"atl":[[3.05,6.63]],"id":40120078}],"con":true,"img":false}]}
{"op":"mcm","clk":"5353190518","pt":1646210607143,"mc":[{"id":"1.195453772","rc":[{"atl":[[3.05,11.56]],"id":40120078}],"con":true,"img":false}]}
{"op":"mcm","clk":"5353191097","pt":1646210619765,"mc":[{"id":"1.195453772","rc":[{"atl":[[3.05,4.93]],"id":40120078}],"con":true,"img":false}]}
{"op":"mcm","clk":"5353191595","pt":1646210631768,"mc":[{"id":"1.195453772","rc":[{"atl":[[3.05,11.56]],"id":40120078}],"con":true,"img":false}]}
{"op":"mcm","clk":"5353194940","pt":1646210700772,"mc":[{"id":"1.195453772","rc":[{"atb":[[3.35,30.64]],"id":36500408},{"atb":[[4.9,18.46]],"id":42860579},{"atb":[[2.9,37.89]],"id":39786791}],"con":true,"img":false}]}
{"op":"mcm","clk":"5353194944","pt":1646210700877,"mc":[{"id":"1.195453772","rc":[{"atb":[[2.22,67.21],[3.05,35.12]],"id":43167135},{"atl":[[16,17.09]],"id":43167135},{"atb":[[1.28,292.86],[1.47,153.19]],"id":40120078},{"atb":[[14,5.54],[9.4,9.76]],"id":37260099},{"atb":[[2.4,58.57]],"id":36500408},{"atl":[[24,16.9]],"id":36500408},{"atb":[[14,5.54],[9.4,9.76]],"id":28506637},{"atb":[[6,16.4],[9.4,8.57]],"id":42077854},{"atb":[[3.3,35.65]],"id":42860579},{"atl":[[50,8.2]],"id":42860579},{"atl":[[19.5,19.01]],"id":39786791}],"con":true,"img":false}]}
{"op":"mcm","clk":"5353194948","pt":1646210700981,"mc":[{"id":"1.195453772","rc":[{"atl":[[5,8.2],[6,14.2]],"id":40120078},{"atb":[[2.62,46.3]],"id":37260099},{"atl":[[32,14.2]],"id":36500408},{"atb":[[4.2,26.56]],"id":28506637},{"atl":[[70,14.2]],"id":42860579},{"atb":[[2.12,73.21]],"id":39786791}],"con":true,"img":false}]}
{"op":"mcm","clk":"5353194957","pt":1646210701086,"mc":[{"id":"1.195453772","rc":[{"atl":[[21,14.2]],"id":43167135},{"atl":[[34,13.5],[17,8.5]],"id":40120078},{"atb":[[4.2,26.56]],"id":37260099},{"atb":[[2.62,46.3]],"id":36500408},{"atb":[[2.62,46.3]],"id":28506637},{"atb":[[2.62,46.3],[4.2,26.56]],"id":42077854},{"atb":[[2.62,46.3]],"id":42860579},{"atl":[[25,14.2]],"id":39786791}],"con":true,"img":false}]}
{"op":"mcm","clk":"5353196095","pt":1646210724307,"mc":[{"id":"1.195453772","rc":[{"atl":[[3.05,6.63]],"id":40120078}],"con":true,"img":false}]}
{"op":"mcm","clk":"5353196232","pt":1646210727298,"mc":[{"id":"1.195453772","rc":[{"atl":[[3.05,11.56]],"id":40120078}],"con":true,"img":false}]}
{"op":"mcm","clk":"5353197456","pt":1646210755052,"mc":[{"id":"1.195453772","rc":[{"atl":[[3.05,4.93]],"id":40120078}],"con":true,"img":false}]}
{"op":"mcm","clk":"5353198122","pt":1646210767657,"mc":[{"id":"1.195453772","rc":[{"atl":[[3.05,11.56]],"id":40120078}],"con":true,"img":false}]}
{"op":"mcm","clk":"5353201842","pt":1646210844505,"mc":[{"id":"1.195453772","rc":[{"atl":[[3.05,6.63]],"id":40120078}],"con":true,"img":false}]}
{"op":"mcm","clk":"5353201997","pt":1646210847503,"mc":[{"id":"1.195453772","rc":[{"atl":[[3.05,11.56]],"id":40120078}],"con":true,"img":false}]}
{"op":"mcm","clk":"5353203923","pt":1646210887845,"mc":[{"id":"1.195453772","rc":[{"atl":[[3.05,4.93]],"id":40120078}],"con":true,"img":false}]}
{"op":"mcm","clk":"5353204463","pt":1646210899942,"mc":[{"id":"1.195453772","rc":[{"atl":[[3.05,11.56]],"id":40120078}],"con":true,"img":false}]}
{"op":"mcm","clk":"5353205219","pt":1646210916558,"mc":[{"id":"1.195453772","rc":[{"atl":[[34,13.5]],"id":43167135},{"atl":[[34,13.5]],"id":39786791}],"con":true,"img":false}]}
{"op":"mcm","clk":"5353206888","pt":1646210964840,"mc":[{"id":"1.195453772","rc":[{"atl":[[3.05,6.63]],"id":40120078}],"con":true,"img":false}]}
{"op":"mcm","clk":"5353206982","pt":1646210967772,"mc":[{"id":"1.195453772","rc":[{"atl":[[3.05,11.56]],"id":40120078}],"con":true,"img":false}]}
{"op":"mcm","clk":"5353210920","pt":1646211073836,"mc":[{"id":"1.195453772","rc":[{"atl":[[3.05,4.93]],"id":40120078}],"con":true,"img":false}]}
{"op":"mcm","clk":"5353211399","pt":1646211084937,"mc":[{"id":"1.195453772","rc":[{"atl":[[3.05,0]],"id":40120078}],"con":true,"img":false}]}
{"op":"mcm","clk":"5353211508","pt":1646211087118,"mc":[{"id":"1.195453772","rc":[{"atl":[[3.05,6.63]],"id":40120078}],"con":true,"img":false}]}
{"op":"mcm","clk":"5353211548","pt":1646211087943,"mc":[{"id":"1.195453772","rc":[{"atl":[[3.05,11.56]],"id":40120078}],"con":true,"img":false}]}
{"op":"mcm","clk":"5353215943","pt":1646211205216,"mc":[{"id":"1.195453772","rc":[{"atl":[[3.05,6.63]],"id":40120078}],"con":true,"img":false}]}
{"op":"mcm","clk":"5353216061","pt":1646211208141,"mc":[{"id":"1.195453772","rc":[{"atl":[[3.05,11.56]],"id":40120078}],"con":true,"img":false}]}
{"op":"mcm","clk":"5353216393","pt":1646211214947,"mc":[{"id":"1.195453772","rc":[{"atl":[[190,14.2]],"id":42077854}],"con":true,"img":false}]}
{"op":"mcm","clk":"5353220559","pt":1646211314501,"mc":[{"id":"1.195453772","rc":[{"atl":[[3.05,4.93]],"id":40120078}],"con":true,"img":false}]}
{"op":"mcm","clk":"5353221015","pt":1646211325520,"mc":[{"id":"1.195453772","rc":[{"atl":[[3.05,0]],"id":40120078}],"con":true,"img":false}]}
{"op":"mcm","clk":"5353221058","pt":1646211326752,"mc":[{"id":"1.195453772","rc":[{"atl":[[3.05,6.63]],"id":40120078}],"con":true,"img":false}]}
{"op":"mcm","clk":"5353221269","pt":1646211331462,"mc":[{"id":"1.195453772","rc":[{"atl":[[3.05,11.56]],"id":40120078}],"con":true,"img":false}]}
{"op":"mcm","clk":"5353226580","pt":1646211447420,"mc":[{"id":"1.195453772","rc":[{"atl":[[3.05,4.93]],"id":40120078}],"con":true,"img":false}]}
{"op":"mcm","clk":"5353226637","pt":1646211448607,"mc":[{"id":"1.195453772","rc":[{"atl":[[3.05,0]],"id":40120078}],"con":true,"img":false}]}
{"op":"mcm","clk":"5353226765","pt":1646211451616,"mc":[{"id":"1.195453772","rc":[{"atl":[[3.05,4.93]],"id":40120078}],"con":true,"img":false}]}
{"op":"mcm","clk":"5353227137","pt":1646211459429,"mc":[{"id":"1.195453772","rc":[{"atl":[[3.05,11.56]],"id":40120078}],"con":true,"img":false}]}
{"op":"mcm","clk":"5353232654","pt":1646211568845,"mc":[{"id":"1.195453772","rc":[{"atl":[[3.05,6.63]],"id":40120078}],"con":true,"img":false}]}
{"op":"mcm","clk":"5353232835","pt":1646211571837,"mc":[{"id":"1.195453772","rc":[{"atl":[[3.05,11.56]],"id":40120078}],"con":true,"img":false}]}
{"op":"mcm","clk":"5353233385","pt":1646211582843,"mc":[{"id":"1.195453772","rc":[{"atl":[[3.05,4.93]],"id":40120078}],"con":true,"img":false}]}
{"op":"mcm","clk":"5353233880","pt":1646211593744,"mc":[{"id":"1.195453772","rc":[{"atl":[[3.05,11.56]],"id":40120078}],"con":true,"img":false}]}
{"op":"mcm","clk":"5353239761","pt":1646211689158,"mc":[{"id":"1.195453772","rc":[{"atb":[[4,34.29],[5.1,4.29],[4.5,29.39],[5,25.71],[4.1,18.85],[3.8,41.26],[3.75,37.4]],"id":43167135},{"spl":[[1.01,10.89]],"id":43167135},{"atl":[[16,17.07],[18.5,7.61],[22,9.51],[12,10.5],[8.8,7.49],[27,7.68]],"id":43167135},{"atb":[[2,102.86],[2.04,16.93],[1.85,123.02],[1.9,114.29],[1.86,60.61],[1.95,108.27],[1.61,182.26]],"id":40120078},{"spl":[[1.01,21.79]],"id":40120078},{"atl":[[3.1,27.83],[3,4.93],[3.05,6.61],[4,31.76],[5.6,43.43],[5.1,32.48],[4.6,36.99],[6.2,38.42],[2.7,6.2]],"id":40120078},{"atb":[[34,3.11],[36,2.72],[18.5,5.88],[22,4.89],[23,5.99],[27,3.95]],"id":37260099},{"atl":[[300,0.44],[170,0.34],[350,0.57],[400,0.5],[230,2.72],[250,0.53]],"id":37260099},{"atb":[[5.6,38.47],[4,34.29],[4.5,29.39],[5,25.71],[5.5,22.85],[5.7,3.75]],"id":36500408},{"atl":[[16.5,7.64],[17,8.32],[19.5,7.19],[24,16.88],[13,4.87],[29,7.13]],"id":36500408},{"atb":[[34,3.11],[36,3.02],[18.5,5.88],[22,4.89],[27,3.95],[28,4.26]],"id":28506637},{"atl":[[300,0.44],[350,0.57],[400,0.5],[240,2.97],[250,0.53]],"id":28506637},{"atb":[[18,6.04],[10.5,10.82],[13,8.57],[13.5,8.61],[14,4.49],[15.5,7.79]],"id":42077854},{"atl":[[65,2.72],[130,1.03],[280,0.71],[180,0.74],[46,2.72],[230,0.87]],"id":42077854},{"atb":[[8.6,13.53],[5.8,21.42],[7.6,15.58],[8.8,7.49],[7.8,17.79],[6.6,18.37]],"id":42860579},{"atl":[[65,3.12],[36,3.8],[21,2.92],[90,2.24],[46,2.95],[29,3.66]],"id":42860579},{"atb":[[4.8,4.62],[4.6,28.57],[4.1,33.18],[3.8,36.73],[3.55,40.34],[4.2,39.23],[4.7,17.79]],"id":39786791},{"atl":[[17,8.32],[19.5,19],[10.5,6.15],[24,8.68],[14,9.8],[14.5,9.86]],"id":39786791}],"con":true,"img":false}]}
{"op":"mcm","clk":"5353239929","pt":1646211692159,"mc":[{"id":"1.195453772","rc":[{"atl":[[3.05,11.55]],"id":40120078}],"con":true,"img":false}]}
{"op":"mcm","clk":"5353240979","pt":1646211709763,"mc":[{"id":"1.195453772","rc":[{"atl":[[3.05,4.93]],"id":40120078}],"con":true,"img":false}]}
{"op":"mcm","clk":"5353241627","pt":1646211720575,"mc":[{"id":"1.195453772","rc":[{"atl":[[3.05,11.55]],"id":40120078}],"con":true,"img":false}]}
{"op":"mcm","clk":"5353247026","pt":1646211809458,"mc":[{"id":"1.195453772","rc":[{"atl":[[3.05,6.61]],"id":40120078}],"con":true,"img":false}]}
{"op":"mcm","clk":"5353247167","pt":1646211812353,"mc":[{"id":"1.195453772","rc":[{"atl":[[3.05,11.55]],"id":40120078}],"con":true,"img":false}]}
{"op":"mcm","clk":"5353248907","pt":1646211841980,"mc":[{"id":"1.195453772","rc":[{"atl":[[3.05,4.93]],"id":40120078}],"con":true,"img":false}]}
{"op":"mcm","clk":"5353249482","pt":1646211853026,"mc":[{"id":"1.195453772","rc":[{"atl":[[3.05,11.55]],"id":40120078}],"con":true,"img":false}]}
{"op":"mcm","clk":"5353253817","pt":1646211929634,"mc":[{"id":"1.195453772","rc":[{"atl":[[3.05,6.61]],"id":40120078}],"con":true,"img":false}]}
{"op":"mcm","clk":"5353254013","pt":1646211932659,"mc":[{"id":"1.195453772","rc":[{"atl":[[3.05,11.55]],"id":40120078}],"con":true,"img":false}]}
{"op":"mcm","clk":"5353256536","pt":1646211973743,"mc":[{"id":"1.195453772","rc":[{"atl":[[3.05,4.93]],"id":40120078}],"con":true,"img":false}]}
{"op":"mcm","clk":"5353257483","pt":1646211988158,"mc":[{"id":"1.195453772","rc":[{"atl":[[3.05,11.55]],"id":40120078}],"con":true,"img":false}]}
{"op":"mcm","clk":"5353261225","pt":1646212049866,"mc":[{"id":"1.195453772","rc":[{"atl":[[3.05,6.61]],"id":40120078}],"con":true,"img":false}]}
{"op":"mcm","clk":"5353261413","pt":1646212052908,"mc":[{"id":"1.195453772","rc":[{"atl":[[3.05,11.55]],"id":40120078}],"con":true,"img":false}]}
{"op":"mcm","clk":"5353263593","pt":1646212088455,"mc":[{"id":"1.195453772","rc":[{"atb":[[2.52,65.79]],"id":43167135},{"atl":[[11,10]],"id":43167135},{"atb":[[1.17,228.6]],"id":40120078},{"atl":[[5,33.2]],"id":40120078},{"atb":[[9.8,11.36]],"id":37260099},{"atl":[[430,2]],"id":37260099},{"atb":[[3.2,45.45]],"id":36500408},{"atl":[[25,4.17]],"id":36500408},{"atb":[[9.2,12.2]],"id":28506637},{"atl":[[350,2.57]],"id":28506637},{"atb":[[4.6,27.78]],"id":42077854},{"atl":[[95,2]],"id":42077854},{"atb":[[3.4,40.97]],"id":42860579},{"atl":[[29,7.23]],"id":42860579},{"atb":[[3,50]],"id":39786791},{"atl":[[15,7.14]],"id":39786791}],"con":true,"img":false}]}
{"op":"mcm","clk":"5353263888","pt":1646212093682,"mc":[{"id":"1.195453772","rc":[{"atb":[[2.86,53.76],[3,0]],"id":39786791}],"con":true,"img":false}]}
{"op":"mcm","clk":"5353265272","pt":1646212115818,"mc":[{"id":"1.195453772","rc":[{"atl":[[3.05,4.93]],"id":40120078}],"con":true,"img":false}]}
{"op":"mcm","clk":"5353265930","pt":1646212125518,"mc":[{"id":"1.195453772","rc":[{"atb":[[1.26,228.6],[1.17,0]],"id":40120078}],"con":true,"img":false}]}
{"op":"mcm","clk":"5353266061","pt":1646212127705,"mc":[{"id":"1.195453772","rc":[{"atl":[[3.05,11.55]],"id":40120078}],"con":true,"img":false}]}
{"op":"mcm","clk":"5353266868","pt":1646212141952,"mc":[{"id":"1.195453772","rc":[{"atb":[[11,10.76],[13.5,0]],"id":42077854}],"con":true,"img":false}]}
{"op":"mcm","clk":"5353266871","pt":1646212142051,"mc":[{"id":"1.195453772","rc":[{"atl":[[12,0]],"id":43167135},{"atb":[[7.8,0]],"id":42860579}],"con":true,"img":false}]}
{"op":"mcm","clk":"5353266875","pt":1646212142154,"mc":[{"id":"1.195453772","rc":[{"atl":[[10.5,10.5]],"id":43167135},{"atb":[[6.8,17.79]],"id":42860579}],"con":true,"img":false}]}
{"op":"mcm","clk":"5353267082","pt":1646212146550,"mc":[{"id":"1.195453772","rc":[{"atb":[[1.85,121.02]],"id":40120078}],"con":true,"img":false}]}
{"op":"mcm","clk":"5353267084","pt":1646212146654,"mc":[{"id":"1.195453772","rc":[{"atb":[[1.87,2]],"id":40120078}],"con":true,"img":false}]}
{"op":"mcm","clk":"5353267213","pt":1646212148562,"mc":[{"id":"1.195453772","rc":[{"atb":[[8.8,0]],"id":42860579}],"con":true,"img":false}]}
{"op":"mcm","clk":"5353267221","pt":1646212148667,"mc":[{"id":"1.195453772","rc":[{"atb":[[7.8,7.49]],"id":42860579}],"con":true,"img":false}]}
{"op":"mcm","clk":"5353268340","pt":1646212169071,"mc":[{"id":"1.195453772","rc":[{"atb":[[1.86,0]],"id":40120078},{"atb":[[14,0]],"id":42077854},{"atl":[[46,0]],"id":42077854},{"atl":[[21,0]],"id":42860579}],"con":true,"img":false}]}
{"op":"mcm","clk":"5353268346","pt":1646212169176,"mc":[{"id":"1.195453772","rc":[{"atb":[[1.91,60.61]],"id":40120078},{"atb":[[13.5,4.49]],"id":42077854},{"atl":[[42,2.72],[90,2],[95,0]],"id":42077854},{"atl":[[20,2.92]],"id":42860579}],"con":true,"img":false}]}
{"op":"mcm","clk":"5353268436","pt":1646212171188,"mc":[{"id":"1.195453772","rc":[{"atl":[[3.05,6.61]],"id":40120078}],"con":true,"img":false}]}
{"op":"mcm","clk":"5353268540","pt":1646212173099,"mc":[{"id":"1.195453772","rc":[{"atl":[[3.05,11.55]],"id":40120078}],"con":true,"img":false}]}
{"op":"mcm","clk":"5353271517","pt":1646212227018,"mc":[{"id":"1.195453772","rc":[{"atb":[[1.01,2.25]],"id":36500408},{"atb":[[1.03,2.25]],"id":42077854},{"spn":30.0,"spf":"NaN","id":42077854},{"atb":[[1.02,2.25]],"id":42860579},{"spn":14.3,"spf":"NaN","id":42860579},{"atb":[[1.01,2.25]],"id":39786791}],"con":true,"img":false}]}
{"op":"mcm","clk":"5353271531","pt":1646212227223,"mc":[{"id":"1.195453772","rc":[{"atb":[[1.01,0.64]],"id":36500408},{"atb":[[1.02,0.42]],"id":42860579},{"atb":[[1.01,0.76]],"id":39786791}],"con":true,"img":false}]}
{"op":"mcm","clk":"5353271537","pt":1646212227325,"mc":[{"id":"1.195453772","rc":[{"atb":[[1.03,0.2]],"id":42077854}],"con":true,"img":false}]}
{"op":"mcm","clk":"5353271556","pt":1646212227587,"mc":[{"id":"1.195453772","rc":[{"atb":[[1.01,0]],"id":39786791}],"con":true,"img":false}]}
{"op":"mcm","clk":"5353271562","pt":1646212227691,"mc":[{"id":"1.195453772","rc":[{"atb":[[4.9,0.76]],"id":39786791}],"con":true,"img":false}]}
{"op":"mcm","clk":"5353271573","pt":1646212227896,"mc":[{"id":"1.195453772","rc":[{"atb":[[1.02,0]],"id":42860579}],"con":true,"img":false}]}
{"op":"mcm","clk":"5353271581","pt":1646212227999,"mc":[{"id":"1.195453772","rc":[{"atb":[[8.8,0.42]],"id":42860579}],"con":true,"img":false}]}
{"op":"mcm","clk":"5353271593","pt":1646212228206,"mc":[{"id":"1.195453772","rc":[{"atb":[[1.01,0]],"id":36500408}],"con":true,"img":false}]}
{"op":"mcm","clk":"5353271599","pt":1646212228314,"mc":[{"id":"1.195453772","rc":[{"atb":[[5.8,0.64]],"id":36500408}],"con":true,"img":false}]}
{"op":"mcm","clk":"5353271609","pt":1646212228520,"mc":[{"id":"1.195453772","rc":[{"atb":[[1.03,0]],"id":42077854}],"con":true,"img":false}]}
{"op":"mcm","clk":"5353271614","pt":1646212228626,"mc":[{"id":"1.195453772","rc":[{"atb":[[18.5,0.2]],"id":42077854}],"con":true,"img":false}]}
{"op":"mcm","clk":"5353272639","pt":1646212246840,"mc":[{"id":"1.195453772","rc":[{"atl":[[3.05,4.93]],"id":40120078}],"con":true,"img":false}]}
{"op":"mcm","clk":"5353273316","pt":1646212258734,"mc":[{"id":"1.195453772","rc":[{"atl":[[3.05,11.55]],"id":40120078}],"con":true,"img":false}]}
{"op":"mcm","clk":"5353274292","pt":1646212276172,"mc":[{"id":"1.195453772","rc":[{"atl":[[20,0]],"id":42860579}],"con":true,"img":false}]}
{"op":"mcm","clk":"5353274297","pt":1646212276275,"mc":[{"id":"1.195453772","rc":[{"atl":[[19.5,2.92]],"id":42860579}],"con":true,"img":false}]}
{"op":"mcm","clk":"5353275080","pt":1646212290389,"mc":[{"id":"1.195453772","rc":[{"atl":[[3.05,6.61]],"id":40120078},{"spn":9.4,"spf":"NaN","id":36500408},{"spn":30.25,"spf":"NaN","id":42077854},{"spn":14.15,"spf":"NaN","id":42860579},{"spn":7.7,"spf":"NaN","id":39786791}],"con":true,"img":false}]}
{"op":"mcm","clk":"5353275344","pt":1646212294393,"mc":[{"id":"1.195453772","rc":[{"atl":[[3.05,11.55]],"id":40120078}],"con":true,"img":false}]}
{"op":"mcm","clk":"5353280331","pt":1646212378132,"mc":[{"id":"1.195453772","rc":[{"atl":[[3.05,4.93]],"id":40120078}],"con":true,"img":false}]}
{"op":"mcm","clk":"5353281005","pt":1646212389156,"mc":[{"id":"1.195453772","rc":[{"atl":[[3.05,11.55]],"id":40120078}],"con":true,"img":false}]}
{"op":"mcm","clk":"5353282311","pt":1646212410618,"mc":[{"id":"1.195453772","rc":[{"atl":[[3.05,6.61]],"id":40120078}],"con":true,"img":false}]}
{"op":"mcm","clk":"5353282495","pt":1646212413512,"mc":[{"id":"1.195453772","rc":[{"atl":[[3.05,11.55]],"id":40120078}],"con":true,"img":false}]}
{"op":"mcm","clk":"5353288236","pt":1646212513169,"mc":[{"id":"1.195453772","rc":[{"atl":[[3.05,4.93]],"id":40120078}],"con":true,"img":false}]}
{"op":"mcm","clk":"5353288986","pt":1646212525097,"mc":[{"id":"1.195453772","rc":[{"atl":[[3.05,11.55]],"id":40120078}],"con":true,"img":false}]}
{"op":"mcm","clk":"5353289289","pt":1646212530793,"mc":[{"id":"1.195453772","rc":[{"atl":[[3.05,6.61]],"id":40120078}],"con":true,"img":false}]}
{"op":"mcm","clk":"5353289457","pt":1646212533685,"mc":[{"id":"1.195453772","rc":[{"atl":[[3.05,11.55]],"id":40120078}],"con":true,"img":false}]}
{"op":"mcm","clk":"5353303833","pt":1646212646980,"mc":[{"id":"1.195453772","rc":[{"atl":[[3.05,4.93]],"id":40120078}],"con":true,"img":false}]}
{"op":"mcm","clk":"5353304030","pt":1646212650857,"mc":[{"id":"1.195453772","rc":[{"atl":[[3.05,0]],"id":40120078}],"con":true,"img":false}]}
{"op":"mcm","clk":"5353304192","pt":1646212653977,"mc":[{"id":"1.195453772","rc":[{"atl":[[3.05,4.93]],"id":40120078}],"con":true,"img":false}]}
{"op":"mcm","clk":"5353304635","pt":1646212661759,"mc":[{"id":"1.195453772","rc":[{"atl":[[3.05,11.55]],"id":40120078}],"con":true,"img":false}]}
{"op":"mcm","clk":"5353309867","pt":1646212754986,"mc":[{"id":"1.195453772","rc":[{"atb":[[2.52,0],[2.66,60.24]],"id":43167135},{"atb":[[4.6,0],[5.5,22.22]],"id":42077854},{"atb":[[3.4,0],[3.9,34.48]],"id":42860579},{"atl":[[26,4],[29,3.66]],"id":42860579},{"atb":[[2.86,0],[2.74,57.47]],"id":39786791}],"con":true,"img":false}]}
{"op":"mcm","clk":"5353309874","pt":1646212755192,"mc":[{"id":"1.195453772","rc":[{"atb":[[2.98,50.51]],"id":39786791}],"con":true,"img":false}]}
{"op":"mcm","clk":"5353309882","pt":1646212755295,"mc":[{"id":"1.195453772","rc":[{"atb":[[2.74,0]],"id":39786791}],"con":true,"img":false}]}
{"op":"mcm","clk":"5353310713","pt":1646212771209,"mc":[{"id":"1.195453772","rc":[{"atl":[[3.05,6.61]],"id":40120078}],"con":true,"img":false}]}
{"op":"mcm","clk":"5353310802","pt":1646212773021,"mc":[{"id":"1.195453772","rc":[{"atl":[[80,2],[90,0]],"id":42077854}],"con":true,"img":false}]}
{"op":"mcm","clk":"5353310849","pt":1646212774243,"mc":[{"id":"1.195453772","rc":[{"atl":[[3.05,11.55]],"id":40120078}],"con":true,"img":false}]}
{"op":"mcm","clk":"5353311550","pt":1646212788375,"mc":[{"id":"1.195453772","rc":[{"atl":[[3.05,4.93]],"id":40120078}],"con":true,"img":false}]}
{"op":"mcm","clk":"5353312235","pt":1646212801847,"mc":[{"id":"1.195453772","rc":[{"atl":[[3.05,11.55]],"id":40120078}],"con":true,"img":false}]}
{"op":"mcm","clk":"5353312257","pt":1646212802157,"mc":[{"id":"1.195453772","rc":[{"atb":[[1.04,1.66]],"id":40120078}],"con":true,"img":false}]}
{"op":"mcm","clk":"5353312264","pt":1646212802263,"mc":[{"id":"1.195453772","rc":[{"atb":[[1.04,1.65]],"id":40120078}],"con":true,"img":false}]}
{"op":"mcm","clk":"5353312276","pt":1646212802476,"mc":[{"id":"1.195453772","rc":[{"atb":[[1.04,0]],"id":40120078}],"con":true,"img":false}]}
{"op":"mcm","clk":"5353312283","pt":1646212802578,"mc":[{"id":"1.195453772","rc":[{"atb":[[2.1,1.65]],"id":40120078}],"con":true,"img":false}]}
{"op":"mcm","clk":"5353312590","pt":1646212808489,"mc":[{"id":"1.195453772","rc":[{"atl":[[25,5.04],[29,0]],"id":42860579}],"con":true,"img":false}]}
{"op":"mcm","clk":"5353317631","pt":1646212891572,"mc":[{"id":"1.195453772","rc":[{"atl":[[3.05,6.61]],"id":40120078},{"spn":2.03,"spf":1.0,"id":40120078}],"con":true,"img":false}]}
{"op":"mcm","clk":"5353317733","pt":1646212893116,"mc":[{"id":"1.195453772","rc":[{"atb":[[2.52,65.79],[2.66,0]],"id":43167135},{"atb":[[4.9,25.64],[5.5,0]],"id":42077854},{"atb":[[3.4,40.97],[3.9,0]],"id":42860579},{"atl":[[26,0],[29,3.57]],"id":42860579},{"atb":[[2.86,53.76],[2.98,0]],"id":39786791}],"con":true,"img":false}]}
{"op":"mcm","clk":"5353317921","pt":1646212896577,"mc":[{"id":"1.195453772","rc":[{"atb":[[9.2,0],[7.4,15.62]],"id":28506637}],"con":true,"img":false}]}
{"op":"mcm","clk":"5353318679","pt":1646212909926,"mc":[{"id":"1.195453772","rc":[{"atl":[[170,0]],"id":37260099},{"atl":[[10.5,0]],"id":39786791}],"con":true,"img":false}]}
{"op":"mcm","clk":"5353318684","pt":1646212910028,"mc":[{"id":"1.195453772","rc":[{"atl":[[160,0.34]],"id":37260099},{"atl":[[10,6.15]],"id":39786791}],"con":true,"img":false}]}
{"op":"mcm","clk":"5353318726","pt":1646212910807,"mc":[{"id":"1.195453772","rc":[{"atb":[[1.87,0]],"id":40120078}],"con":true,"img":false}]}
{"op":"mcm","clk":"5353319346","pt":1646212922147,"mc":[{"id":"1.195453772","rc":[{"atb":[[2.52,0],[2.64,60.98]],"id":43167135},{"atb":[[3.95,33.9],[3.4,0]],"id":42860579},{"atl":[[26,4],[29,0]],"id":42860579},{"atb":[[2.86,0],[3,50]],"id":39786791}],"con":true,"img":false}]}
{"op":"mcm","clk":"5353319528","pt":1646212925545,"mc":[{"id":"1.195453772","rc":[{"atb":[[7.4,0],[9.4,21.66]],"id":28506637}],"con":true,"img":false}]}
{"op":"mcm","clk":"5353319618","pt":1646212927037,"mc":[{"id":"1.195453772","rc":[{"atl":[[3.05,0]],"id":40120078}],"con":true,"img":false}]}
{"op":"mcm","clk":"5353324907","pt":1646213016545,"mc":[{"id":"1.195453772","rc":[{"atb":[[2.52,65.79],[2.64,0]],"id":43167135},{"spn":98.0,"spf":"NaN","id":37260099},{"atb":[[3.95,0],[3.65,37.74]],"id":42860579},{"atb":[[2.88,53.19],[3,0]],"id":39786791},{"spn":7.45,"spf":"NaN","id":39786791}],"con":true,"img":false}]}
{"op":"mcm","clk":"5353334943","pt":1646213183725,"mc":[{"id":"1.195453772","rc":[{"atb":[[2.88,0]],"id":39786791}],"con":true,"img":false}]}
{"op":"mcm","clk":"5353334946","pt":1646213183827,"mc":[{"id":"1.195453772","rc":[{"atb":[[1.26,0],[1.35,260.73]],"id":40120078},{"atl":[[26,0],[30,3.45]],"id":42860579},{"atb":[[3,50]],"id":39786791}],"con":true,"img":false}]}
{"op":"mcm","clk":"5353337459","pt":1646213229668,"mc":[{"id":"1.195453772","rc":[{"atb":[[2.52,0],[2.64,60.98],[4.4,0]],"id":43167135},{"atl":[[10.5,21.03],[11,0]],"id":43167135},{"atb":[[1.35,0]],"id":40120078},{"atl":[[5,8.2]],"id":40120078},{"atb":[[32,0],[11,10],[9.8,0]],"id":37260099},{"atl":[[400,2.5],[430,0]],"id":37260099},{"atb":[[3.3,43.48],[5.1,0],[3.2,0]],"id":36500408},{"atl":[[25,0],[28,3.7]],"id":36500408},{"atb":[[36,2.72],[9.4,9.76]],"id":28506637},{"atl":[[350,0.57],[360,2]],"id":28506637},{"atb":[[4.9,0],[14.5,0.75],[15.5,7.09],[5.1,24.39]],"id":42077854},{"atl":[[75,2],[80,0]],"id":42077854},{"atb":[[8.2,0],[3.65,0]],"id":42860579},{"atl":[[28,3.7],[30,0]],"id":42860579},{"atb":[[3.2,45.45],[3,0],[4.7,15.79]],"id":39786791},{"atl":[[14,17.49],[15,0]],"id":39786791}],"con":true,"img":false}]}
{"op":"mcm","clk":"5353337465","pt":1646213229772,"mc":[{"id":"1.195453772","rc":[{"atb":[[4.4,2]],"id":43167135},{"atb":[[1.02,2.25],[8.8,0],[3.65,37.74]],"id":42860579}],"con":true,"img":false}]}
{"op":"mcm","clk":"5353337469","pt":1646213229876,"mc":[{"id":"1.195453772","rc":[{"atb":[[1.35,285.71]],"id":40120078},{"atl":[[5,33.2]],"id":40120078},{"atb":[[32,0.33]],"id":37260099},{"atb":[[5.1,2]],"id":36500408},{"atb":[[36,3.02],[9.4,21.66]],"id":28506637},{"atb":[[8.2,1.4]],"id":42860579},{"atb":[[1.01,2.25],[4.9,0],[4.7,17.79]],"id":39786791}],"con":true,"img":false}]}
{"op":"mcm","clk":"5353337474","pt":1646213229980,"mc":[{"id":"1.195453772","rc":[{"atb":[[1.02,0.42]],"id":42860579}],"con":true,"img":false}]}
{"op":"mcm","clk":"5353337478","pt":1646213230083,"mc":[{"id":"1.195453772","rc":[{"atb":[[1.03,2.25],[18.5,0]],"id":42077854},{"atb":[[1.01,0.76]],"id":39786791}],"con":true,"img":false}]}
{"op":"mcm","clk":"5353337481","pt":1646213230186,"mc":[{"id":"1.195453772","rc":[{"atb":[[1.02,0]],"id":42860579}],"con":true,"img":false}]}
{"op":"mcm","clk":"5353337485","pt":1646213230288,"mc":[{"id":"1.195453772","rc":[{"atb":[[8,0.42]],"id":42860579}],"con":true,"img":false}]}
{"op":"mcm","clk":"5353337503","pt":1646213230705,"mc":[{"id":"1.195453772","rc":[{"atb":[[1.01,0]],"id":39786791}],"con":true,"img":false}]}
{"op":"mcm","clk":"5353337510","pt":1646213230809,"mc":[{"id":"1.195453772","rc":[{"atb":[[4.8,5.39]],"id":39786791}],"con":true,"img":false}]}
{"op":"mcm","clk":"5353337519","pt":1646213230966,"mc":[{"id":"1.195453772","rc":[{"atb":[[1.03,0.2]],"id":42077854}],"con":true,"img":false}]}
{"op":"mcm","clk":"5353337527","pt":1646213231172,"mc":[{"id":"1.195453772","rc":[{"atb":[[1.03,0]],"id":42077854}],"con":true,"img":false}]}
{"op":"mcm","clk":"5353337533","pt":1646213231275,"mc":[{"id":"1.195453772","rc":[{"atb":[[16,0.2]],"id":42077854}],"con":true,"img":false}]}
{"op":"mcm","clk":"5353339981","pt":1646213274758,"mc":[{"id":"1.195453772","rc":[{"atb":[[1.44,227.27],[1.35,0]],"id":40120078},{"spn":30.0,"spf":"NaN","id":42077854},{"spn":14.05,"spf":"NaN","id":42860579},{"spn":7.4,"spf":"NaN","id":39786791}],"con":true,"img":false}]}
{"op":"mcm","clk":"5353341720","pt":1646213308702,"mc":[{"id":"1.195453772","rc":[{"atb":[[1.03,2.25]],"id":42077854},{"atb":[[1.02,2.25]],"id":42860579}],"con":true,"img":false}]}
{"op":"mcm","clk":"5353341724","pt":1646213308755,"mc":[{"id":"1.195453772","rc":[{"atb":[[16,0]],"id":42077854},{"atb":[[8,0]],"id":42860579}],"con":true,"img":false}]}
{"op":"mcm","clk":"5353341732","pt":1646213308961,"mc":[{"id":"1.195453772","rc":[{"atb":[[1.03,0.2]],"id":42077854},{"atb":[[1.02,0.42]],"id":42860579}],"con":true,"img":false}]}
{"op":"mcm","clk":"5353341756","pt":1646213309581,"mc":[{"id":"1.195453772","rc":[{"atb":[[1.02,0]],"id":42860579}],"con":true,"img":false}]}
{"op":"mcm","clk":"5353341762","pt":1646213309683,"mc":[{"id":"1.195453772","rc":[{"atb":[[8.8,0.42]],"id":42860579}],"con":true,"img":false}]}
{"op":"mcm","clk":"5353341775","pt":1646213309991,"mc":[{"id":"1.195453772","rc":[{"atb":[[1.03,0]],"id":42077854}],"con":true,"img":false}]}
{"op":"mcm","clk":"5353341781","pt":1646213310095,"mc":[{"id":"1.195453772","rc":[{"atb":[[18.5,0.2]],"id":42077854}],"con":true,"img":false}]}
{"op":"mcm","clk":"5353343495","pt":1646213349668,"mc":[{"id":"1.195453772","rc":[{"atb":[[2.52,65.79]],"id":43167135},{"atb":[[4.3,30.3],[5.1,0]],"id":42077854},{"spn":30.25,"spf":"NaN","id":42077854},{"spn":14.15,"spf":"NaN","id":42860579}],"con":true,"img":false}]}
{"op":"mcm","clk":"5353343499","pt":1646213349719,"mc":[{"id":"1.195453772","rc":[{"atb":[[2.64,0]],"id":43167135}],"con":true,"img":false}]}
{"op":"mcm","clk":"5353348901","pt":1646213454487,"mc":[{"id":"1.195453772","rc":[{"atb":[[8.2,0]],"id":42860579}],"con":true,"img":false}]}
{"op":"mcm","clk":"5353348908","pt":1646213454591,"mc":[{"id":"1.195453772","rc":[{"atb":[[8.4,1.36]],"id":42860579}],"con":true,"img":false}]}
{"op":"mcm","clk":"5353348917","pt":1646213454646,"mc":[{"id":"1.195453772","rc":[{"atb":[[1.02,2.25]],"id":42860579}],"con":true,"img":false}]}
{"op":"mcm","clk":"5353348921","pt":1646213454750,"mc":[{"id":"1.195453772","rc":[{"atb":[[8.8,0]],"id":42860579}],"con":true,"img":false}]}
{"op":"mcm","clk":"5353348929","pt":1646213454855,"mc":[{"id":"1.195453772","rc":[{"atb":[[1.02,0.42]],"id":42860579}],"con":true,"img":false}]}
{"op":"mcm","clk":"5353348940","pt":1646213455061,"mc":[{"id":"1.195453772","rc":[{"atb":[[1.02,0]],"id":42860579}],"con":true,"img":false}]}
{"op":"mcm","clk":"5353348949","pt":1646213455161,"mc":[{"id":"1.195453772","rc":[{"atb":[[8,0.42]],"id":42860579}],"con":true,"img":false}]}
{"op":"mcm","clk":"5353350200","pt":1646213480487,"mc":[{"id":"1.195453772","rc":[{"atb":[[5.1,0]],"id":36500408}],"con":true,"img":false}]}
{"op":"mcm","clk":"5353350211","pt":1646213480693,"mc":[{"id":"1.195453772","rc":[{"atb":[[5.6,40.47]],"id":36500408}],"con":true,"img":false}]}
{"op":"mcm","clk":"5353350222","pt":1646213480803,"mc":[{"id":"1.195453772","rc":[{"atb":[[1.01,2.25],[5.8,0]],"id":36500408}],"con":true,"img":false}]}
{"op":"mcm","clk":"5353350230","pt":1646213481002,"mc":[{"id":"1.195453772","rc":[{"atb":[[1.01,0.64]],"id":36500408}],"con":true,"img":false}]}
{"op":"mcm","clk":"5353350247","pt":1646213481307,"mc":[{"id":"1.195453772","rc":[{"atb":[[1.01,0]],"id":36500408}],"con":true,"img":false}]}
{"op":"mcm","clk":"5353350253","pt":1646213481410,"mc":[{"id":"1.195453772","rc":[{"atb":[[5.7,4.39]],"id":36500408}],"con":true,"img":false}]}
{"op":"mcm","clk":"5353351953","pt":1646213516053,"mc":[{"id":"1.195453772","rc":[{"spn":9.35,"spf":"NaN","id":36500408},{"atb":[[1.02,2.25]],"id":42860579},{"spn":14.05,"spf":"NaN","id":42860579}],"con":true,"img":false}]}
{"op":"mcm","clk":"5353351958","pt":1646213516153,"mc":[{"id":"1.195453772","rc":[{"atb":[[8,0]],"id":42860579}],"con":true,"img":false}]}
{"op":"mcm","clk":"5353351965","pt":1646213516256,"mc":[{"id":"1.195453772","rc":[{"atb":[[1.02,0.42]],"id":42860579}],"con":true,"img":false}]}
{"op":"mcm","clk":"5353351977","pt":1646213516463,"mc":[{"id":"1.195453772","rc":[{"atb":[[1.02,0]],"id":42860579}],"con":true,"img":false}]}
{"op":"mcm","clk":"5353351984","pt":1646213516519,"mc":[{"id":"1.195453772","rc":[{"atb":[[8.8,0.42]],"id":42860579}],"con":true,"img":false}]}
{"op":"mcm","clk":"5353356450","pt":1646213601127,"mc":[{"id":"1.195453772","rc":[{"atb":[[1.02,3.22]],"id":43167135},{"atb":[[1.02,4.02]],"id":40120078},{"atb":[[1.04,2.83]],"id":37260099},{"atb":[[1.04,2.83]],"id":28506637},{"atb":[[1.03,2.91]],"id":42077854},{"atb":[[1.02,3.04]],"id":42860579},{"spn":14.15,"spf":"NaN","id":42860579},{"atb":[[1.02,3.25]],"id":39786791}],"con":true,"img":false}]}
{"op":"mcm","clk":"5353356478","pt":1646213601652,"mc":[{"id":"1.195453772","rc":[{"atb":[[1.02,0.49]],"id":43167135},{"atb":[[1.02,1.29]],"id":40120078},{"atb":[[1.04,0.1]],"id":37260099},{"atb":[[1.04,0.1]],"id":28506637},{"atb":[[1.03,0.19]],"id":42077854},{"atb":[[1.02,0.31]],"id":42860579},{"atb":[[1.02,0.53]],"id":39786791}],"con":true,"img":false}]}
{"op":"mcm","clk":"5353356493","pt":1646213602068,"mc":[{"id":"1.195453772","rc":[{"atb":[[1.02,3.17]],"id":36500408}],"con":true,"img":false}]}
{"op":"mcm","clk":"5353356497","pt":1646213602171,"mc":[{"id":"1.195453772","rc":[{"atb":[[1.02,0]],"id":43167135},{"atb":[[1.02,0]],"id":40120078},{"atb":[[1.04,0]],"id":37260099},{"atb":[[1.04,0]],"id":28506637},{"atb":[[1.03,0]],"id":42077854},{"atb":[[1.02,0]],"id":42860579},{"atb":[[1.02,0]],"id":39786791}],"con":true,"img":false}]}
{"op":"mcm","clk":"5353356501","pt":1646213602274,"mc":[{"id":"1.195453772","rc":[{"atb":[[5.6,0.49]],"id":43167135},{"atb":[[2.14,1.29]],"id":40120078},{"atb":[[25,0.1]],"id":37260099},{"atb":[[25,0.1]],"id":28506637},{"atb":[[14.5,0.94]],"id":42077854},{"atb":[[8.8,0.74]],"id":42860579},{"atb":[[5.2,0.53]],"id":39786791}],"con":true,"img":false}]}
{"op":"mcm","clk":"5353356512","pt":1646213602535,"mc":[{"id":"1.195453772","rc":[{"atb":[[1.02,0.44]],"id":36500408}],"con":true,"img":false}]}
{"op":"mcm","clk":"5353356527","pt":1646213602949,"mc":[{"id":"1.195453772","rc":[{"atb":[[1.02,0]],"id":36500408}],"con":true,"img":false}]}
{"op":"mcm","clk":"5353356533","pt":1646213603053,"mc":[{"id":"1.195453772","rc":[{"atb":[[6.2,0.44]],"id":36500408}],"con":true,"img":false}]}
{"op":"mcm","clk":"5353373082","pt":1646213880890,"mc":[{"id":"1.195453772","rc":[{"atb":[[4.4,7.88],[4,59.29],[3.9,43.1],[4.2,15.62]],"id":43167135},{"atl":[[11,2],[12,4.55],[13,6.25],[14,9.62]],"id":43167135},{"spn":5.06,"spf":1.0,"id":43167135},{"atb":[[1.59,127.12],[1.44,0],[1.53,188.68],[1.63,31.75],[1.57,219.3],[1.61,264.23]],"id":40120078},{"atl":[[3.55,19.61],[3.75,45.45],[3.45,8.16],[3.65,28.3]],"id":40120078},{"spn":2.04,"spf":1.0,"id":40120078},{"atb":[[10.5,13.16],[11.5,7.14],[12.5,4.35],[13.5,1.6]],"id":37260099},{"atl":[[420,1],[440,1],[460,1],[480,1]],"id":37260099},{"atb":[[4.3,37.88],[4.9,5.13],[4.5,50.82],[4.7,13.51]],"id":36500408},{"atl":[[32,15.2],[36,1.43],[40,1.92],[44,2.91]],"id":36500408},{"spn":9.6,"spf":"NaN","id":36500408},{"atb":[[17.5,7.58],[18.5,10.17],[19.5,2.7],[21,1]],"id":28506637},{"atl":[[420,1],[440,1],[460,1],[480,1]],"id":28506637},{"atb":[[5.8,4.17],[5.4,17.05],[5.6,10.87],[5.2,29.76]],"id":42077854},{"atl":[[170,1],[190,15.2],[210,1],[230,1.87]],"id":42077854},{"atb":[[6.4,13.89],[6.8,26.41],[7.2,3.23],[6,25]],"id":42860579},{"atl":[[17.5,1.21],[18.5,2.86],[19.5,6.97],[21,6.25]],"id":42860579},{"spn":13.15,"spf":"NaN","id":42860579},{"atb":[[4.3,6.06],[3.85,43.86],[3.95,25.42],[4.1,49.31]],"id":39786791},{"atl":[[8,2.86],[9.2,15.24],[8.8,9.62],[8.4,6.76]],"id":39786791},{"spn":6.6,"spf":"NaN","id":39786791}],"con":true,"img":false}]}
{"op":"mcm","clk":"5353373244","pt":1646213883467,"mc":[{"id":"1.195453772","rc":[{"atb":[[4.8,3.41]],"id":39786791}],"con":true,"img":false}]}
{"op":"mcm","clk":"5353373923","pt":1646213894736,"mc":[{"id":"1.195453772","rc":[{"atb":[[4.4,2],[4.5,35.1],[2.52,0],[2.66,60.24]],"id":43167135},{"atl":[[3.55,7.84],[3.45,0]],"id":40120078},{"atb":[[11,0],[4.1,32.26]],"id":37260099},{"atb":[[3.35,42.55],[9.4,9.76]],"id":28506637},{"atl":[[310,2],[360,0]],"id":28506637},{"atb":[[2.98,46.3],[3.65,0]],"id":42860579},{"atl":[[25,9.21],[28,0]],"id":42860579},{"atb":[[2.82,54.95],[3.2,0]],"id":39786791}],"con":true,"img":false}]}
{"op":"mcm","clk":"5353373962","pt":1646213895210,"mc":[{"id":"1.195453772","rc":[{"atb":[[4.1,0]],"id":43167135}],"con":true,"img":false}]}
{"op":"mcm","clk":"5353373969","pt":1646213895317,"mc":[{"id":"1.195453772","rc":[{"atb":[[4.3,18.85]],"id":43167135}],"con":true,"img":false}]}
{"op":"mcm","clk":"5353374574","pt":1646213904733,"mc":[{"id":"1.195453772","rc":[{"atl":[[3.65,18.87]],"id":40120078},{"atb":[[4.8,0.76]],"id":39786791}],"con":true,"img":false}]}
{"op":"mcm","clk":"5353374602","pt":1646213905249,"mc":[{"id":"1.195453772","rc":[{"atl":[[10,0]],"id":39786791}],"con":true,"img":false}]}
{"op":"mcm","clk":"5353374612","pt":1646213905315,"mc":[{"id":"1.195453772","rc":[{"atl":[[9.8,6.15]],"id":39786791}],"con":true,"img":false}]}
{"op":"mcm","clk":"5353375123","pt":1646213913743,"mc":[{"id":"1.195453772","rc":[{"atb":[[10,11.11],[4.1,0]],"id":37260099},{"atb":[[9,12.5],[3.35,0]],"id":28506637},{"atb":[[3.6,38.46],[2.98,0]],"id":42860579},{"atb":[[2.82,0],[3.15,46.51]],"id":39786791}],"con":true,"img":false}]}
{"op":"mcm","clk":"5353375176","pt":1646213914673,"mc":[{"id":"1.195453772","rc":[{"atl":[[3.75,0]],"id":40120078}],"con":true,"img":false}]}
{"op":"mcm","clk":"5353375181","pt":1646213914776,"mc":[{"id":"1.195453772","rc":[{"atl":[[3.75,27.27]],"id":40120078}],"con":true,"img":false}]}
{"op":"mcm","clk":"5353375204","pt":1646213915144,"mc":[{"id":"1.195453772","rc":[{"atb":[[3.8,0]],"id":43167135},{"atl":[[3.6,42.75],[4,0]],"id":40120078},{"atl":[[20,6.36],[25,4.17]],"id":42860579}],"con":true,"img":false}]}
{"op":"mcm","clk":"5353375211","pt":1646213915257,"mc":[{"id":"1.195453772","rc":[{"atb":[[3.95,41.26]],"id":43167135}],"con":true,"img":false}]}
{"op":"mcm","clk":"5353375778","pt":1646213924768,"mc":[{"id":"1.195453772","rc":[{"atl":[[3.85,43.86]],"id":40120078}],"con":true,"img":false}]}
{"op":"mcm","clk":"5353377697","pt":1646213955106,"mc":[{"id":"1.195453772","rc":[{"atl":[[3.55,0],[3.5,8]],"id":40120078},{"atb":[[4.8,26.32],[4.3,0]],"id":42077854}],"con":true,"img":false}]}
{"op":"mcm","clk":"5353378456","pt":1646213966852,"mc":[{"id":"1.195453772","rc":[{"atb":[[1.03,2.25]],"id":36500408}],"con":true,"img":false}]}
{"op":"mcm","clk":"5353378462","pt":1646213966911,"mc":[{"id":"1.195453772","rc":[{"atb":[[5.7,3.75]],"id":36500408}],"con":true,"img":false}]}
{"op":"mcm","clk":"5353378467","pt":1646213967012,"mc":[{"id":"1.195453772","rc":[{"atb":[[1.03,0.58]],"id":36500408}],"con":true,"img":false}]}
{"op":"mcm","clk":"5353378471","pt":1646213967114,"mc":[{"id":"1.195453772","rc":[{"atb":[[1.03,0]],"id":36500408}],"con":true,"img":false}]}
{"op":"mcm","clk":"5353378478","pt":1646213967222,"mc":[{"id":"1.195453772","rc":[{"atb":[[6.4,0.58]],"id":36500408}],"con":true,"img":false}]}
{"op":"mcm","clk":"5353378484","pt":1646213967326,"mc":[{"id":"1.195453772","rc":[{"atb":[[1.03,2.25]],"id":36500408}],"con":true,"img":false}]}
{"op":"mcm","clk":"5353378490","pt":1646213967423,"mc":[{"id":"1.195453772","rc":[{"atb":[[6.4,0]],"id":36500408}],"con":true,"img":false}]}
{"op":"mcm","clk":"5353378495","pt":1646213967527,"mc":[{"id":"1.195453772","rc":[{"atb":[[1.03,0.58]],"id":36500408}],"con":true,"img":false}]}
{"op":"mcm","clk":"5353378507","pt":1646213967734,"mc":[{"id":"1.195453772","rc":[{"atb":[[1.03,0]],"id":36500408}],"con":true,"img":false}]}
{"op":"mcm","clk":"5353378510","pt":1646213967837,"mc":[{"id":"1.195453772","rc":[{"atb":[[5.8,0.58]],"id":36500408}],"con":true,"img":false}]}
{"op":"mcm","clk":"5353378786","pt":1646213972636,"mc":[{"id":"1.195453772","rc":[{"atl":[[3.1,0]],"id":40120078}],"con":true,"img":false}]}
{"op":"mcm","clk":"5353378791","pt":1646213972738,"mc":[{"id":"1.195453772","rc":[{"atl":[[3.2,27.83]],"id":40120078}],"con":true,"img":false}]}
{"op":"mcm","clk":"5353378794","pt":1646213972842,"mc":[{"id":"1.195453772","rc":[{"atl":[[3.25,8.17]],"id":40120078}],"con":true,"img":false}]}
{"op":"mcm","clk":"5353378802","pt":1646213972946,"mc":[{"id":"1.195453772","rc":[{"atl":[[3.55,7.84]],"id":40120078}],"con":true,"img":false}]}
{"op":"mcm","clk":"5353378808","pt":1646213973049,"mc":[{"id":"1.195453772","rc":[{"atl":[[3.5,0]],"id":40120078}],"con":true,"img":false}]}
{"op":"mcm","clk":"5353380339","pt":1646213995269,"mc":[{"id":"1.195453772","rc":[{"atl":[[9.8,0]],"id":39786791}],"con":true,"img":false}]}
{"op":"mcm","clk":"5353380345","pt":1646213995369,"mc":[{"id":"1.195453772","rc":[{"atl":[[9,6.15]],"id":39786791}],"con":true,"img":false}]}
{"op":"mcm","clk":"5353381698","pt":1646214015428,"mc":[{"id":"1.195453772","rc":[{"atl":[[3.6,0]],"id":40120078}],"con":true,"img":false}]}
{"op":"mcm","clk":"5353381703","pt":1646214015530,"mc":[{"id":"1.195453772","rc":[{"atl":[[3.5,42.75]],"id":40120078}],"con":true,"img":false}]}
{"op":"mcm","clk":"5353384257","pt":1646214057001,"mc":[{"id":"1.195453772","rc":[{"atb":[[5.8,0],[1.03,2.25]],"id":36500408}],"con":true,"img":false}]}
{"op":"mcm","clk":"5353384263","pt":1646214057070,"mc":[{"id":"1.195453772","rc":[{"atb":[[1.03,0.58]],"id":36500408}],"con":true,"img":false}]}
{"op":"mcm","clk":"5353384273","pt":1646214057266,"mc":[{"id":"1.195453772","rc":[{"atl":[[3.25,0]],"id":40120078}],"con":true,"img":false}]}
{"op":"mcm","clk":"5353384303","pt":1646214057778,"mc":[{"id":"1.195453772","rc":[{"atb":[[1.03,0]],"id":36500408}],"con":true,"img":false}]}
{"op":"mcm","clk":"5353384310","pt":1646214057879,"mc":[{"id":"1.195453772","rc":[{"atb":[[6.4,0.58]],"id":36500408}],"con":true,"img":false}]}
{"op":"mcm","clk":"5353384366","pt":1646214058666,"mc":[{"id":"1.195453772","rc":[{"atb":[[6.4,0],[1.03,2.25]],"id":36500408}],"con":true,"img":false}]}
{"op":"mcm","clk":"5353384384","pt":1646214058869,"mc":[{"id":"1.195453772","rc":[{"atb":[[1.03,0.58]],"id":36500408}],"con":true,"img":false}]}
{"op":"mcm","clk":"5353384392","pt":1646214058976,"mc":[{"id":"1.195453772","rc":[{"atb":[[1.03,0]],"id":36500408}],"con":true,"img":false}]}
{"op":"mcm","clk":"5353384398","pt":1646214059074,"mc":[{"id":"1.195453772","rc":[{"atb":[[5.8,0.58]],"id":36500408}],"con":true,"img":false}]}
{"op":"mcm","clk":"5353384455","pt":1646214059794,"mc":[{"id":"1.195453772","rc":[{"atb":[[2.06,2.95]],"id":40120078},{"atb":[[5.8,3.93]],"id":36500408}],"con":true,"img":false}]}
{"op":"mcm","clk":"5353384855","pt":1646214065186,"mc":[{"id":"1.195453772","rc":[{"atl":[[3.5,0]],"id":40120078}],"con":true,"img":false}]}
{"op":"mcm","clk":"5353384863","pt":1646214065290,"mc":[{"id":"1.195453772","rc":[{"atl":[[3.6,42.75]],"id":40120078}],"con":true,"img":false}]}
{"op":"mcm","clk":"5353385580","pt":1646214074934,"mc":[{"id":"1.195453772","rc":[{"atl":[[3.55,0],[3.5,8]],"id":40120078}],"con":true,"img":false}]}
{"op":"mcm","clk":"5353390018","pt":1646214138636,"mc":[{"id":"1.195453772","rc":[{"spl":[[1.01,40.87]],"id":43167135},{"spn":4.89,"spf":1.0,"id":43167135},{"spl":[[1.01,51.77]],"id":40120078},{"spn":2.02,"spf":1.0,"id":40120078},{"spl":[[1.01,29.97]],"id":37260099},{"spn":24.02,"spf":1.0,"id":37260099},{"spl":[[1.01,29.97]],"id":36500408},{"spn":5.64,"spf":1.0,"id":36500408},{"spl":[[1.01,29.97]],"id":28506637},{"spn":25.11,"spf":1.0,"id":28506637},{"spl":[[1.01,29.97]],"id":42077854},{"spn":14.58,"spf":1.0,"id":42077854},{"spl":[[1.01,29.97]],"id":42860579},{"spn":8.16,"spf":1.0,"id":42860579},{"spl":[[1.01,29.97]],"id":39786791},{"spn":4.67,"spf":1.0,"id":39786791}],"con":true,"img":false}]}
{"op":"mcm","clk":"5353392577","pt":1646214177163,"mc":[{"id":"1.195453772","rc":[{"atb":[[5.8,3.34],[1.03,2.25]],"id":36500408}],"con":true,"img":false}]}
{"op":"mcm","clk":"5353392581","pt":1646214177269,"mc":[{"id":"1.195453772","rc":[{"atb":[[1.03,0.58]],"id":36500408}],"con":true,"img":false}]}
{"op":"mcm","clk":"5353392608","pt":1646214177684,"mc":[{"id":"1.195453772","rc":[{"atb":[[1.03,0]],"id":36500408}],"con":true,"img":false}]}
{"op":"mcm","clk":"5353392622","pt":1646214177787,"mc":[{"id":"1.195453772","rc":[{"atb":[[6.4,0.58]],"id":36500408}],"con":true,"img":false}]}
{"op":"mcm","clk":"5353392669","pt":1646214178457,"mc":[{"id":"1.195453772","rc":[{"atb":[[6.4,0],[1.03,2.25]],"id":36500408}],"con":true,"img":false}]}
{"op":"mcm","clk":"5353392675","pt":1646214178561,"mc":[{"id":"1.195453772","rc":[{"atb":[[1.03,0.58]],"id":36500408}],"con":true,"img":false}]}
{"op":"mcm","clk":"5353392681","pt":1646214178660,"mc":[{"id":"1.195453772","rc":[{"atb":[[1.03,0]],"id":36500408}],"con":true,"img":false}]}
{"op":"mcm","clk":"5353392689","pt":1646214178765,"mc":[{"id":"1.195453772","rc":[{"atb":[[5.9,0.58]],"id":36500408}],"con":true,"img":false}]}
{"op":"mcm","clk":"5353393768","pt":1646214194902,"mc":[{"id":"1.195453772","rc":[{"atl":[[340,2.49]],"id":28506637}],"con":true,"img":false}]}
{"op":"mcm","clk":"5353393773","pt":1646214195005,"mc":[{"id":"1.195453772","rc":[{"atl":[[310,0]],"id":28506637}],"con":true,"img":false}]}
{"op":"mcm","clk":"5353397822","pt":1646214254225,"mc":[{"id":"1.195453772","rc":[{"atl":[[3.55,7.84],[3.5,0]],"id":40120078},{"atl":[[330,2],[400,0.5]],"id":37260099},{"spn":5.64,"spf":1.0,"id":36500408},{"atl":[[320,2],[340,0.49]],"id":28506637}],"con":true,"img":false}]}
{"op":"mcm","clk":"5353398750","pt":1646214267340,"mc":[{"id":"1.195453772","rc":[{"atb":[[1.03,2.25],[5.9,0]],"id":36500408}],"con":true,"img":false}]}
{"op":"mcm","clk":"5353398772","pt":1646214267744,"mc":[{"id":"1.195453772","rc":[{"atb":[[1.03,0.58]],"id":36500408}],"con":true,"img":false}]}
{"op":"mcm","clk":"5353398795","pt":1646214268163,"mc":[{"id":"1.195453772","rc":[{"atb":[[1.03,0]],"id":36500408}],"con":true,"img":false}]}
{"op":"mcm","clk":"5353398799","pt":1646214268218,"mc":[{"id":"1.195453772","rc":[{"atb":[[6.4,0.58]],"id":36500408}],"con":true,"img":false}]}
{"op":"mcm","clk":"5353399397","pt":1646214277559,"mc":[{"id":"1.195453772","rc":[{"atb":[[6.4,0],[1.03,2.25]],"id":36500408}],"con":true,"img":false}]}
{"op":"mcm","clk":"5353399412","pt":1646214277772,"mc":[{"id":"1.195453772","rc":[{"atb":[[1.03,0.58]],"id":36500408}],"con":true,"img":false}]}
{"op":"mcm","clk":"5353399424","pt":1646214277975,"mc":[{"id":"1.195453772","rc":[{"atb":[[1.03,0]],"id":36500408}],"con":true,"img":false}]}
{"op":"mcm","clk":"5353399429","pt":1646214278072,"mc":[{"id":"1.195453772","rc":[{"atb":[[5.9,0.58]],"id":36500408}],"con":true,"img":false}]}
{"op":"mcm","clk":"5353400132","pt":1646214289361,"mc":[{"id":"1.195453772","rc":[{"atb":[[8,14.29],[10,0]],"id":37260099}],"con":true,"img":false}]}
{"op":"mcm","clk":"5353400136","pt":1646214289460,"mc":[{"id":"1.195453772","rc":[{"atl":[[3.6,50.44],[3.55,0]],"id":40120078}],"con":true,"img":false}]}
{"op":"mcm","clk":"5353400737","pt":1646214299374,"mc":[{"id":"1.195453772","rc":[{"atl":[[3.7,18.52]],"id":40120078}],"con":true,"img":false}]}
{"op":"mcm","clk":"5353401016","pt":1646214303476,"mc":[{"id":"1.195453772","rc":[{"atl":[[3.85,0],[3.75,0],[3.65,0]],"id":40120078}],"con":true,"img":false}]}
{"op":"mcm","clk":"5353401083","pt":1646214304401,"mc":[{"id":"1.195453772","rc":[{"atb":[[8,0],[9.2,12.2]],"id":37260099}],"con":true,"img":false}]}
{"op":"mcm","clk":"5353401142","pt":1646214305175,"mc":[{"id":"1.195453772","rc":[{"atl":[[3.6,7.69]],"id":40120078}],"con":true,"img":false}]}
{"op":"mcm","clk":"5353401154","pt":1646214305286,"mc":[{"id":"1.195453772","rc":[{"atl":[[3.65,42.75]],"id":40120078}],"con":true,"img":false}]}
{"op":"mcm","clk":"5353401469","pt":1646214309530,"mc":[{"id":"1.195453772","rc":[{"atl":[[3.8,26.79]],"id":40120078}],"con":true,"img":false}]}
{"op":"mcm","clk":"5353401568","pt":1646214310932,"mc":[{"id":"1.195453772","rc":[{"atl":[[2.46,2.72]],"id":40120078}],"con":true,"img":false}]}
{"op":"mcm","clk":"5353402254","pt":1646214319410,"mc":[{"id":"1.195453772","rc":[{"atl":[[3.9,43.1]],"id":40120078}],"con":true,"img":false}]}
{"op":"mcm","clk":"5353408845","pt":1646214410318,"mc":[{"id":"1.195453772","rc":[{"atl":[[3.6,0],[3.65,50.3]],"id":40120078},{"atb":[[9,0],[5,25]],"id":28506637},{"atl":[[290,2],[320,0]],"id":28506637}],"con":true,"img":false}]}
{"op":"mcm","clk":"5353409497","pt":1646214420330,"mc":[{"id":"1.195453772","rc":[{"atl":[[3.75,18.18]],"id":40120078}],"con":true,"img":false}]}
{"op":"mcm","clk":"5353409774","pt":1646214424228,"mc":[{"id":"1.195453772","rc":[{"atb":[[9.4,21.66],[5,0]],"id":28506637}],"con":true,"img":false}]}
{"op":"mcm","clk":"5353409790","pt":1646214424440,"mc":[{"id":"1.195453772","rc":[{"atl":[[3.8,0],[3.7,0],[3.9,0]],"id":40120078},{"atl":[[280,2],[290,0]],"id":28506637}],"con":true,"img":false}]}
{"op":"mcm","clk":"5353409847","pt":1646214425117,"mc":[{"id":"1.195453772","rc":[{"atl":[[3.65,7.55]],"id":40120078}],"con":true,"img":false}]}
{"op":"mcm","clk":"5353409852","pt":1646214425221,"mc":[{"id":"1.195453772","rc":[{"atl":[[3.7,42.75]],"id":40120078}],"con":true,"img":false}]}
{"op":"mcm","clk":"5353410225","pt":1646214430333,"mc":[{"id":"1.195453772","rc":[{"atl":[[3.85,26.32]],"id":40120078}],"con":true,"img":false}]}
{"op":"mcm","clk":"5353410909","pt":1646214440371,"mc":[{"id":"1.195453772","rc":[{"atl":[[3.95,42.37]],"id":40120078}],"con":true,"img":false}]}
{"op":"mcm","clk":"5353411342","pt":1646214447572,"mc":[{"id":"1.195453772","rc":[{"atb":[[1.03,2.25],[5.9,0]],"id":36500408}],"con":true,"img":false}]}
{"op":"mcm","clk":"5353411354","pt":1646214447778,"mc":[{"id":"1.195453772","rc":[{"atb":[[1.03,0.58]],"id":36500408}],"con":true,"img":false}]}
{"op":"mcm","clk":"5353411409","pt":1646214448561,"mc":[{"id":"1.195453772","rc":[{"atb":[[1.03,0]],"id":36500408}],"con":true,"img":false}]}
{"op":"mcm","clk":"5353411415","pt":1646214448666,"mc":[{"id":"1.195453772","rc":[{"atb":[[6.4,0.58]],"id":36500408}],"con":true,"img":false}]}
{"op":"mcm","clk":"5353411431","pt":1646214448871,"mc":[{"id":"1.195453772","rc":[{"atb":[[6.4,0],[1.03,2.25]],"id":36500408}],"con":true,"img":false}]}
{"op":"mcm","clk":"5353411442","pt":1646214449072,"mc":[{"id":"1.195453772","rc":[{"atb":[[1.03,0.58]],"id":36500408}],"con":true,"img":false}]}
{"op":"mcm","clk":"5353411455","pt":1646214449279,"mc":[{"id":"1.195453772","rc":[{"atb":[[1.03,0]],"id":36500408}],"con":true,"img":false}]}
{"op":"mcm","clk":"5353411459","pt":1646214449388,"mc":[{"id":"1.195453772","rc":[{"atb":[[5.9,0.58]],"id":36500408}],"con":true,"img":false}]}
{"op":"mcm","clk":"5353412138","pt":1646214460615,"mc":[{"id":"1.195453772","rc":[{"atb":[[2.66,0]],"id":43167135},{"atl":[[10.5,10.5]],"id":43167135},{"atl":[[4.3,30.3],[5,8.2]],"id":40120078},{"atb":[[12.5,8.7]],"id":28506637},{"atl":[[55,2]],"id":42077854}],"con":true,"img":false}]}
{"op":"mcm","clk":"5353412147","pt":1646214460781,"mc":[{"id":"1.195453772","rc":[{"atb":[[1.41,70.22]],"id":43167135},{"atl":[[16,23.74]],"id":43167135},{"atl":[[2.84,10.87],[3.65,0]],"id":40120078},{"atb":[[9.2,0],[12,9.09]],"id":37260099},{"atl":[[330,0],[230,4.72]],"id":37260099},{"atb":[[3.3,0],[1.32,56.36]],"id":36500408},{"atb":[[9.4,9.76]],"id":28506637},{"atl":[[280,0],[240,4.97]],"id":28506637},{"atb":[[4.8,0],[5.7,17.05]],"id":42077854},{"atl":[[75,0]],"id":42077854},{"atb":[[3.6,0],[2.06,36.74]],"id":42860579},{"atl":[[32,3.23],[25,0]],"id":42860579},{"atb":[[2.86,53.76],[3.15,0]],"id":39786791},{"atl":[[11,10],[14,9.8]],"id":39786791}],"con":true,"img":false}]}
{"op":"mcm","clk":"5353412417","pt":1646214465215,"mc":[{"id":"1.195453772","rc":[{"atl":[[10.5,0]],"id":43167135}],"con":true,"img":false}]}
{"op":"mcm","clk":"5353412426","pt":1646214465321,"mc":[{"id":"1.195453772","rc":[{"atl":[[11.5,10.5]],"id":43167135}],"con":true,"img":false}]}
{"op":"mcm","clk":"5353412650","pt":1646214469102,"mc":[{"id":"1.195453772","rc":[{"atl":[[11,0],[8.8,10.05]],"id":43167135},{"atb":[[1.53,0],[1.71,127.12],[1.63,0],[1.81,24.69]],"id":40120078},{"atb":[[13.5,0],[14.5,1.48]],"id":37260099},{"atl":[[32,14.2],[36,0],[150,1]],"id":36500408},{"atb":[[20,1.05]],"id":28506637},{"atb":[[5.8,0],[6.6,3.57]],"id":42077854},{"atb":[[6.4,0],[6.8,17.79],[5.4,4.55],[7.2,0],[6,0]],"id":42860579},{"atl":[[17.5,0],[17,1.25]],"id":42860579},{"atl":[[8,0],[9.2,2.44],[8.4,0]],"id":39786791}],"con":true,"img":false}]}
{"op":"mcm","clk":"5353412654","pt":1646214469207,"mc":[{"id":"1.195453772","rc":[{"atl":[[3,14.93],[2.84,0]],"id":40120078},{"atb":[[21,0]],"id":28506637}],"con":true,"img":false}]}
{"op":"mcm","clk":"5353412665","pt":1646214469415,"mc":[{"id":"1.195453772","rc":[{"atl":[[2.98,10.1]],"id":40120078},{"atl":[[40,0]],"id":36500408},{"atl":[[8.8,0]],"id":39786791}],"con":true,"img":false}]}
{"op":"mcm","clk":"5353412684","pt":1646214469830,"mc":[{"id":"1.195453772","rc":[{"atb":[[5.2,3.35]],"id":43167135}],"con":true,"img":false}]}
{"op":"mcm","clk":"5353412893","pt":1646214474035,"mc":[{"id":"1.195453772","rc":[{"spn":4.94,"spf":1.0,"id":43167135},{"atl":[[4.3,0],[3.85,56.62]],"id":40120078},{"spn":24.04,"spf":1.0,"id":37260099},{"spn":25.08,"spf":1.0,"id":28506637},{"atl":[[46,2.22],[55,0]],"id":42077854}],"con":true,"img":false}]}
{"op":"mcm","clk":"5353412908","pt":1646214474237,"mc":[{"id":"1.195453772","rc":[{"atb":[[2.76,56.82],[1.41,0]],"id":43167135},{"atl":[[16,17.07],[10.5,10.53]],"id":43167135},{"atb":[[2.3,56.36],[1.32,0]],"id":36500408},{"atb":[[2.06,0],[5,25]],"id":42860579},{"atl":[[32,0],[18.5,8.57]],"id":42860579},{"atb":[[3.5,40],[2.86,0]],"id":39786791}],"con":true,"img":false}]}
{"op":"mcm","clk":"5353412930","pt":1646214474598,"mc":[{"id":"1.195453772","rc":[{"atl":[[3,4.93]],"id":40120078},{"atl":[[44,0]],"id":36500408}],"con":true,"img":false}]}
{"op":"mcm","clk":"5353412961","pt":1646214475221,"mc":[{"id":"1.195453772","rc":[{"atl":[[3.7,0]],"id":40120078},{"atl":[[9,0]],"id":39786791}],"con":true,"img":false}]}
{"op":"mcm","clk":"5353412972","pt":1646214475324,"mc":[{"id":"1.195453772","rc":[{"atl":[[3.8,42.75]],"id":40120078},{"atl":[[11,0],[9.8,6.15],[13.5,8]],"id":39786791}],"con":true,"img":false}]}
{"op":"mcm","clk":"5353413189","pt":1646214479113,"mc":[{"id":"1.195453772","rc":[{"atl":[[9.2,6.1]],"id":43167135},{"atb":[[13.5,4]],"id":37260099},{"atl":[[170,1]],"id":36500408},{"atb":[[19,2.78]],"id":28506637},{"atb":[[6.2,9.62]],"id":42077854},{"atb":[[5.2,11.9]],"id":42860579},{"atl":[[9.6,5.81]],"id":39786791}],"con":true,"img":false}]}
{"op":"mcm","clk":"5353413200","pt":1646214479323,"mc":[{"id":"1.195453772","rc":[{"atb":[[2.56,64.1]],"id":43167135},{"atb":[[2.3,0],[2.06,56.36]],"id":36500408},{"atl":[[18.5,2.86],[19,5.56]],"id":42860579}],"con":true,"img":false}]}
{"op":"mcm","clk":"5353413203","pt":1646214479422,"mc":[{"id":"1.195453772","rc":[{"atb":[[1.79,63.29]],"id":40120078},{"atl":[[3.05,24.39]],"id":40120078}],"con":true,"img":false}]}
{"op":"mcm","clk":"5353413208","pt":1646214479526,"mc":[{"id":"1.195453772","rc":[{"atb":[[2.76,0]],"id":43167135}],"con":true,"img":false}]}
{"op":"mcm","clk":"5353413211","pt":1646214479629,"mc":[{"id":"1.195453772","rc":[{"atl":[[14,0]],"id":43167135},{"atb":[[1.57,0]],"id":40120078},{"atl":[[3.95,0]],"id":40120078},{"atb":[[17.5,0],[18.5,5.88],[19.5,0]],"id":28506637},{"atb":[[5.4,0],[5.6,0],[5.2,0]],"id":42077854}],"con":true,"img":false}]}
{"op":"mcm","clk":"5353413217","pt":1646214479733,"mc":[{"id":"1.195453772","rc":[{"atb":[[10.5,0]],"id":37260099}],"con":true,"img":false}]}
{"op":"mcm","clk":"5353413423","pt":1646214483415,"mc":[{"id":"1.195453772","rc":[{"atb":[[5.2,0]],"id":43167135}],"con":true,"img":false}]}
{"op":"mcm","clk":"5353413514","pt":1646214485641,"mc":[{"id":"1.195453772","rc":[{"atb":[[1.01,2.25]],"id":39786791}],"con":true,"img":false}]}
{"op":"mcm","clk":"5353413521","pt":1646214485847,"mc":[{"id":"1.195453772","rc":[{"atb":[[1.01,1.97]],"id":39786791}],"con":true,"img":false}]}
{"op":"mcm","clk":"5353413533","pt":1646214486055,"mc":[{"id":"1.195453772","rc":[{"atb":[[1.01,0]],"id":39786791}],"con":true,"img":false}]}
{"op":"mcm","clk":"5353413538","pt":1646214486109,"mc":[{"id":"1.195453772","rc":[{"atb":[[4.8,2.74]],"id":39786791}],"con":true,"img":false}]}
{"op":"mcm","clk":"5353413658","pt":1646214488539,"mc":[{"id":"1.195453772","rc":[{"atl":[[12,9.09],[13.5,0]],"id":39786791}],"con":true,"img":false}]}
{"op":"mcm","clk":"5353413685","pt":1646214489155,"mc":[{"id":"1.195453772","rc":[{"atl":[[9.6,8.72]],"id":43167135},{"atb":[[36,4.72],[12.5,6.52]],"id":37260099},{"atl":[[220,2]],"id":37260099},{"atl":[[190,1]],"id":36500408},{"atb":[[38,2],[18,4.41]],"id":28506637},{"atl":[[230,2]],"id":28506637},{"atb":[[5.9,15.31]],"id":42077854},{"atl":[[42,4.72]],"id":42077854},{"atb":[[5,43.75]],"id":42860579},{"atl":[[17,3.25]],"id":42860579},{"atl":[[10,8.33]],"id":39786791}],"con":true,"img":false}]}
{"op":"mcm","clk":"5353413689","pt":1646214489256,"mc":[{"id":"1.195453772","rc":[{"atl":[[42,2.72],[46,2],[60,2]],"id":42077854},{"atl":[[17,1.25],[18.5,4.86]],"id":42860579}],"con":true,"img":false}]}
{"op":"mcm","clk":"5353413693","pt":1646214489360,"mc":[{"id":"1.195453772","rc":[{"atl":[[42,4.72],[46,2.22]],"id":42077854},{"atl":[[17,3.25],[18.5,2.86]],"id":42860579}],"con":true,"img":false}]}
{"op":"mcm","clk":"5353413700","pt":1646214489463,"mc":[{"id":"1.195453772","rc":[{"atb":[[1.77,97.4]],"id":40120078},{"atl":[[3.15,34.88]],"id":40120078},{"atl":[[42,2.72]],"id":42077854},{"atl":[[18.5,4.86]],"id":42860579}],"con":true,"img":false}]}
{"op":"mcm","clk":"5353413706","pt":1646214489517,"mc":[{"id":"1.195453772","rc":[{"atl":[[42,4.72]],"id":42077854},{"atl":[[17,1.25]],"id":42860579}],"con":true,"img":false}]}
{"op":"mcm","clk":"5353413713","pt":1646214489618,"mc":[{"id":"1.195453772","rc":[{"atl":[[60,0]],"id":42077854}],"con":true,"img":false}]}
{"op":"mcm","clk":"5353413823","pt":1646214492051,"mc":[{"id":"1.195453772","rc":[{"atb":[[40,5]],"id":28506637}],"con":true,"img":false}]}
{"op":"mcm","clk":"5353413832","pt":1646214492257,"mc":[{"id":"1.195453772","rc":[{"atl":[[13,0]],"id":43167135},{"atb":[[1.59,0]],"id":40120078},{"atl":[[3.85,30.3]],"id":40120078}],"con":true,"img":false}]}
{"op":"mcm","clk":"5353414072","pt":1646214495260,"mc":[{"id":"1.195453772","rc":[{"atl":[[19.5,4.05]],"id":42860579}],"con":true,"img":false}]}
{"op":"mcm","clk":"5353414078","pt":1646214495364,"mc":[{"id":"1.195453772","rc":[{"atl":[[17,3.25],[18.5,5.78]],"id":42860579}],"con":true,"img":false}]}
{"op":"mcm","clk":"5353414288","pt":1646214499178,"mc":[{"id":"1.195453772","rc":[{"atl":[[10,13.89]],"id":43167135},{"atb":[[11.5,11.9]],"id":37260099},{"atl":[[210,1]],"id":36500408},{"atb":[[17,7.81]],"id":28506637},{"atb":[[5.7,43.65]],"id":42077854},{"atb":[[4.8,32.89]],"id":42860579},{"atl":[[11,12.5]],"id":39786791}],"con":true,"img":false}]}
{"op":"mcm","clk":"5353414299","pt":1646214499333,"mc":[{"id":"1.195453772","rc":[{"atb":[[1.75,166.67]],"id":40120078},{"atl":[[3.25,55.56]],"id":40120078}],"con":true,"img":false}]}
{"op":"mcm","clk":"5353414632","pt":1646214505161,"mc":[{"id":"1.195453772","rc":[{"atl":[[10.5,13.07],[14,0]],"id":39786791}],"con":true,"img":false}]}
{"op":"mcm","clk":"5353414637","pt":1646214505264,"mc":[{"id":"1.195453772","rc":[{"atl":[[3.2,0]],"id":40120078},{"atl":[[65,0]],"id":42077854}],"con":true,"img":false}]}
{"op":"mcm","clk":"5353414644","pt":1646214505368,"mc":[{"id":"1.195453772","rc":[{"atl":[[3.1,27.83]],"id":40120078},{"atl":[[44,2.72]],"id":42077854}],"con":true,"img":false}]}
{"op":"mcm","clk":"5353414852","pt":1646214509291,"mc":[{"id":"1.195453772","rc":[{"atl":[[12,0]],"id":43167135}],"con":true,"img":false}]}
{"op":"mcm","clk":"5353414863","pt":1646214509447,"mc":[{"id":"1.195453772","rc":[{"atb":[[1.61,182.26]],"id":40120078},{"atl":[[3.75,0]],"id":40120078}],"con":true,"img":false}]}
{"op":"mcm","clk":"5353415127","pt":1646214515182,"mc":[{"id":"1.195453772","rc":[{"atl":[[11.5,0],[9.4,13.75]],"id":43167135},{"atb":[[1.8,138.97],[1.61,0]],"id":40120078},{"atl":[[240,4.72]],"id":28506637}],"con":true,"img":false}]}
{"op":"mcm","clk":"5353415133","pt":1646214515286,"mc":[{"id":"1.195453772","rc":[{"atl":[[220,0.24]],"id":28506637}],"con":true,"img":false}]}
{"op":"mcm","clk":"5353415582","pt":1646214525192,"mc":[{"id":"1.195453772","rc":[{"atl":[[230,2]],"id":37260099},{"atb":[[36,0.3]],"id":28506637}],"con":true,"img":false}]}
{"op":"mcm","clk":"5353415588","pt":1646214525293,"mc":[{"id":"1.195453772","rc":[{"atl":[[210,2.72],[230,4]],"id":37260099},{"atb":[[42,2.72]],"id":28506637}],"con":true,"img":false}]}
{"op":"mcm","clk":"5353415591","pt":1646214525397,"mc":[{"id":"1.195453772","rc":[{"atl":[[210,4.72],[220,0],[230,2]],"id":37260099}],"con":true,"img":false}]}
{"op":"mcm","clk":"5353415599","pt":1646214525503,"mc":[{"id":"1.195453772","rc":[{"atl":[[230,0]],"id":37260099}],"con":true,"img":false}]}
{"op":"mcm","clk":"5353415607","pt":1646214525605,"mc":[{"id":"1.195453772","rc":[{"atl":[[200,2]],"id":37260099}],"con":true,"img":false}]}
{"op":"mcm","clk":"5353416483","pt":1646214541313,"mc":[{"id":"1.195453772","rc":[{"spn":4.89,"spf":1.0,"id":43167135},{"spn":25.5,"spf":1.0,"id":37260099},{"atb":[[40,0]],"id":28506637},{"spn":26.89,"spf":1.0,"id":28506637},{"spn":4.68,"spf":1.0,"id":39786791}],"con":true,"img":false}]}
{"op":"mcm","clk":"5353416491","pt":1646214541415,"mc":[{"id":"1.195453772","rc":[{"atb":[[44,5]],"id":28506637}],"con":true,"img":false}]}
{"op":"mcm","clk":"5353416554","pt":1646214542711,"mc":[{"id":"1.195453772","rc":[{"atl":[[3.8,0]],"id":40120078}],"con":true,"img":false}]}
{"op":"mcm","clk":"5353416561","pt":1646214542816,"mc":[{"id":"1.195453772","rc":[{"atl":[[3.2,42.75]],"id":40120078}],"con":true,"img":false}]}
{"op":"mcm","clk":"5353417793","pt":1646214565268,"mc":[{"id":"1.195453772","rc":[{"atl":[[210,2]],"id":37260099}],"con":true,"img":false}]}
{"op":"mcm","clk":"5353417802","pt":1646214565372,"mc":[{"id":"1.195453772","rc":[{"atl":[[190,2.72],[200,0],[210,4]],"id":37260099}],"con":true,"img":false}]}
{"op":"mcm","clk":"5353417807","pt":1646214565475,"mc":[{"id":"1.195453772","rc":[{"atl":[[300,2.44],[190,4.72],[210,0]],"id":37260099}],"con":true,"img":false}]}
{"op":"mcm","clk":"5353417813","pt":1646214565578,"mc":[{"id":"1.195453772","rc":[{"atl":[[300,0.44],[190,6.72],[210,2]],"id":37260099}],"con":true,"img":false}]}
{"op":"mcm","clk":"5353417820","pt":1646214565681,"mc":[{"id":"1.195453772","rc":[{"atl":[[190,4.72]],"id":37260099}],"con":true,"img":false}]}
{"op":"mcm","clk":"5353417827","pt":1646214565785,"mc":[{"id":"1.195453772","rc":[{"atl":[[190,6.72]],"id":37260099}],"con":true,"img":false}]}
{"op":"mcm","clk":"5353417835","pt":1646214565889,"mc":[{"id":"1.195453772","rc":[{"atl":[[210,0]],"id":37260099}],"con":true,"img":false}]}
{"op":"mcm","clk":"5353418306","pt":1646214575206,"mc":[{"id":"1.195453772","rc":[{"atb":[[42,0]],"id":28506637}],"con":true,"img":false}]}
{"op":"mcm","clk":"5353418313","pt":1646214575313,"mc":[{"id":"1.195453772","rc":[{"atb":[[2.56,0],[2.68,59.52]],"id":43167135},{"atl":[[2.98,0],[3.05,9.76]],"id":40120078},{"atb":[[46,2.72]],"id":28506637}],"con":true,"img":false}]}
{"op":"mcm","clk":"5353418541","pt":1646214579305,"mc":[{"id":"1.195453772","rc":[{"atl":[[3,14.93]],"id":40120078},{"atb":[[2.06,0],[2.2,56.36]],"id":36500408},{"atl":[[44,5.05],[46,0]],"id":42077854}],"con":true,"img":false}]}
{"op":"mcm","clk":"5353418589","pt":1646214580397,"mc":[{"id":"1.195453772","rc":[{"atb":[[2.56,64.1],[2.68,0]],"id":43167135}],"con":true,"img":false}]}
{"op":"mcm","clk":"5353418863","pt":1646214585214,"mc":[{"id":"1.195453772","rc":[{"atl":[[18.5,2.86]],"id":42860579}],"con":true,"img":false}]}
{"op":"mcm","clk":"5353418872","pt":1646214585319,"mc":[{"id":"1.195453772","rc":[{"atl":[[19.5,6.97]],"id":42860579}],"con":true,"img":false}]}
{"op":"mcm","clk":"5353419089","pt":1646214589315,"mc":[{"id":"1.195453772","rc":[{"atl":[[3.1,51.64]],"id":40120078}],"con":true,"img":false}]}
{"op":"mcm","clk":"5353419585","pt":1646214599326,"mc":[{"id":"1.195453772","rc":[{"atl":[[3.25,0],[3.05,0],[3.2,76.84],[3.15,0]],"id":40120078}],"con":true,"img":false}]}
{"op":"mcm","clk":"5353419916","pt":1646214605256,"mc":[{"id":"1.195453772","rc":[{"atl":[[190,4]],"id":37260099},{"spn":31.5,"spf":1.0,"id":28506637}],"con":true,"img":false}]}
{"op":"mcm","clk":"5353419922","pt":1646214605309,"mc":[{"id":"1.195453772","rc":[{"atl":[[180,2.72]],"id":37260099}],"con":true,"img":false}]}
{"op":"mcm","clk":"5353419929","pt":1646214605412,"mc":[{"id":"1.195453772","rc":[{"atl":[[190,2],[250,2.53]],"id":37260099}],"con":true,"img":false}]}
{"op":"mcm","clk":"5353420098","pt":1646214609355,"mc":[{"id":"1.195453772","rc":[{"atl":[[3.3,54.35]],"id":40120078}],"con":true,"img":false}]}
{"op":"mcm","clk":"5353420185","pt":1646214611332,"mc":[{"id":"1.195453772","rc":[{"atl":[[2.34,7.08]],"id":40120078}],"con":true,"img":false}]}
{"op":"mcm","clk":"5353420190","pt":1646214611539,"mc":[{"id":"1.195453772","rc":[{"atb":[[2.56,0],[2.74,57.47]],"id":43167135},{"atl":[[3,4.93],[2.98,10.1]],"id":40120078},{"atb":[[2.4,116.03]],"id":36500408}],"con":true,"img":false}]}
{"op":"mcm","clk":"5353420194","pt":1646214611642,"mc":[{"id":"1.195453772","rc":[{"atb":[[2.2,0]],"id":36500408}],"con":true,"img":false}]}
{"op":"mcm","clk":"5353420306","pt":1646214613837,"mc":[{"id":"1.195453772","rc":[{"atb":[[2.04,9.7]],"id":40120078}],"con":true,"img":false}]}
{"op":"mcm","clk":"5353420361","pt":1646214614768,"mc":[{"id":"1.195453772","rc":[{"atl":[[2.34,0]],"id":40120078},{"trd":[[2.34,14.16]],"ltp":2.34,"tv":14.16,"id":40120078}],"con":true,"img":false}]}
{"op":"mcm","clk":"5353420467","pt":1646214616738,"mc":[{"id":"1.195453772","rc":[{"atb":[[2.06,0]],"id":40120078}],"con":true,"img":false}]}
{"op":"mcm","clk":"5353420496","pt":1646214617357,"mc":[{"id":"1.195453772","rc":[{"atl":[[180,4.72]],"id":37260099}],"con":true,"img":false}]}
{"op":"mcm","clk":"5353420504","pt":1646214617461,"mc":[{"id":"1.195453772","rc":[{"atl":[[170,2],[180,2.72],[250,0.53]],"id":37260099}],"con":true,"img":false}]}
{"op":"mcm","clk":"5353420509","pt":1646214617565,"mc":[{"id":"1.195453772","rc":[{"atb":[[2.54,64.94],[2.74,0]],"id":43167135},{"atl":[[2.98,0],[3.05,9.76]],"id":40120078},{"atl":[[180,4.72],[190,0]],"id":37260099},{"atb":[[2.4,58.57],[2.16,51.44]],"id":36500408}],"con":true,"img":false}]}
{"op":"mcm","clk":"5353420512","pt":1646214617668,"mc":[{"id":"1.195453772","rc":[{"atl":[[170,0],[180,6.72]],"id":37260099}],"con":true,"img":false}]}
{"op":"mcm","clk":"5353420739","pt":1646214622337,"mc":[{"id":"1.195453772","rc":[{"atb":[[2.06,2.95]],"id":40120078}],"con":true,"img":false}]}
{"op":"mcm","clk":"5353420981","pt":1646214627553,"mc":[{"id":"1.195453772","rc":[{"atl":[[3.15,23.26]],"id":40120078}],"con":true,"img":false}]}
{"op":"mcm","clk":"5353421500","pt":1646214637593,"mc":[{"id":"1.195453772","rc":[{"atl":[[3.25,33.33]],"id":40120078}],"con":true,"img":false}]}
{"op":"mcm","clk":"5353421506","pt":1646214637695,"mc":[{"id":"1.195453772","rc":[{"atl":[[3.1,27.83],[3.3,0],[3.2,42.75]],"id":40120078}],"con":true,"img":false}]}
{"op":"mcm","clk":"5353421959","pt":1646214647572,"mc":[{"id":"1.195453772","rc":[{"atl":[[3.35,53.19]],"id":40120078}],"con":true,"img":false}]}
{"op":"mcm","clk":"5353422416","pt":1646214657922,"mc":[{"id":"1.195453772","rc":[{"atb":[[1.03,2.25],[5.9,0]],"id":36500408}],"con":true,"img":false}]}
{"op":"mcm","clk":"5353422466","pt":1646214658697,"mc":[{"id":"1.195453772","rc":[{"atb":[[1.03,0.58]],"id":36500408}],"con":true,"img":false}]}
{"op":"mcm","clk":"5353422505","pt":1646214659520,"mc":[{"id":"1.195453772","rc":[{"atb":[[1.03,0]],"id":36500408}],"con":true,"img":false}]}
{"op":"mcm","clk":"5353422510","pt":1646214659624,"mc":[{"id":"1.195453772","rc":[{"atb":[[6.4,0.58]],"id":36500408}],"con":true,"img":false}]}
{"op":"mcm","clk":"5353422526","pt":1646214659831,"mc":[{"id":"1.195453772","rc":[{"atb":[[6.4,0],[1.03,2.25]],"id":36500408}],"con":true,"img":false}]}
{"op":"mcm","clk":"5353422535","pt":1646214660034,"mc":[{"id":"1.195453772","rc":[{"atb":[[1.03,0.58]],"id":36500408}],"con":true,"img":false}]}
{"op":"mcm","clk":"5353422542","pt":1646214660240,"mc":[{"id":"1.195453772","rc":[{"atb":[[1.03,0]],"id":36500408}],"con":true,"img":false}]}
{"op":"mcm","clk":"5353422551","pt":1646214660343,"mc":[{"id":"1.195453772","rc":[{"atb":[[5.9,0.58]],"id":36500408}],"con":true,"img":false}]}
{"op":"mcm","clk":"5353422612","pt":1646214661639,"mc":[{"id":"1.195453772","rc":[{"atb":[[2.54,0],[2.78,56.18]],"id":43167135},{"atl":[[10.5,0],[8.4,2.7],[9.8,11.36],[8.8,7.49]],"id":43167135},{"atb":[[1.71,0],[1.8,236.37],[1.81,0],[1.86,23.26]],"id":40120078},{"atl":[[3.1,37.35]],"id":40120078},{"atb":[[14.5,0],[15.5,1.38]],"id":37260099},{"atl":[[150,0],[38,2.7],[160,1],[28,0]],"id":36500408},{"atb":[[20,0],[21,1]],"id":28506637},{"atb":[[7.2,3.23],[6.6,0]],"id":42077854},{"atl":[[44,2.72],[46,2.22]],"id":42077854},{"atb":[[5.4,0],[5.7,4.26]],"id":42860579},{"atl":[[9.2,0],[8.4,2.7]],"id":39786791}],"con":true,"img":false}]}
{"op":"mcm","clk":"5353422616","pt":1646214661737,"mc":[{"id":"1.195453772","rc":[{"atl":[[3.05,0]],"id":40120078},{"atl":[[8,2.86]],"id":39786791}],"con":true,"img":false}]}
{"op":"mcm","clk":"5353422620","pt":1646214661841,"mc":[{"id":"1.195453772","rc":[{"atl":[[11.5,9.52],[12,0]],"id":39786791}],"con":true,"img":false}]}
{"op":"mcm","clk":"5353422626","pt":1646214661946,"mc":[{"id":"1.195453772","rc":[{"atb":[[2.4,113.57],[2.16,0]],"id":36500408},{"atb":[[3.5,0]],"id":39786791}],"con":true,"img":false}]}
{"op":"mcm","clk":"5353422634","pt":1646214662048,"mc":[{"id":"1.195453772","rc":[{"atb":[[3.75,36.36]],"id":39786791}],"con":true,"img":false}]}
{"op":"mcm","clk":"5353422764","pt":1646214665034,"mc":[{"id":"1.195453772","rc":[{"atb":[[5.1,2.45]],"id":43167135},{"atb":[[4.8,0.76]],"id":39786791}],"con":true,"img":false}]}
{"op":"mcm","clk":"5353422769","pt":1646214665241,"mc":[{"id":"1.195453772","rc":[{"atl":[[3.1,27.83],[3.15,9.3]],"id":40120078},{"atl":[[8,0],[10,0],[11,0],[7.8,2.94],[8.4,0],[9.6,0]],"id":39786791}],"con":true,"img":false}]}
{"op":"mcm","clk":"5353422915","pt":1646214668473,"mc":[{"id":"1.195453772","rc":[{"atb":[[5.1,0]],"id":43167135},{"spn":4.82,"spf":1.0,"id":43167135},{"spn":2.01,"spf":1.0,"id":40120078},{"spn":25.54,"spf":1.0,"id":37260099},{"spn":31.53,"spf":1.0,"id":28506637},{"spn":4.67,"spf":1.0,"id":39786791}],"con":true,"img":false}]}
{"op":"mcm","clk":"5353422917","pt":1646214668524,"mc":[{"id":"1.195453772","rc":[{"atb":[[4.8,7]],"id":39786791}],"con":true,"img":false}]}
{"op":"mcm","clk":"5353423019","pt":1646214671051,"mc":[{"id":"1.195453772","rc":[{"atb":[[4.8,9.97]],"id":39786791}],"con":true,"img":false}]}
{"op":"mcm","clk":"5353423047","pt":1646214671517,"mc":[{"id":"1.195453772","rc":[{"atl":[[180,1]],"id":36500408},{"atb":[[6.8,8.62]],"id":42077854},{"atb":[[5.5,11.11]],"id":42860579}],"con":true,"img":false}]}
{"op":"mcm","clk":"5353423051","pt":1646214671621,"mc":[{"id":"1.195453772","rc":[{"atl":[[8.8,13.9]],"id":43167135},{"atb":[[14.5,3.7]],"id":37260099}],"con":true,"img":false}]}
{"op":"mcm","clk":"5353423100","pt":1646214672962,"mc":[{"id":"1.195453772","rc":[{"atb":[[3,50]],"id":43167135}],"con":true,"img":false}]}
{"op":"mcm","clk":"5353423104","pt":1646214673014,"mc":[{"id":"1.195453772","rc":[{"atb":[[2.78,0]],"id":43167135}],"con":true,"img":false}]}
{"op":"mcm","clk":"5353423208","pt":1646214675235,"mc":[{"id":"1.195453772","rc":[{"atb":[[1.84,59.52]],"id":40120078},{"atl":[[3.25,55.55]],"id":40120078},{"atl":[[10.5,0],[8.2,6.94]],"id":39786791}],"con":true,"img":false}]}
{"op":"mcm","clk":"5353423211","pt":1646214675338,"mc":[{"id":"1.195453772","rc":[{"atl":[[3.25,22.22]],"id":40120078},{"atl":[[11,13.07]],"id":39786791}],"con":true,"img":false}]}
{"op":"mcm","clk":"5353423394","pt":1646214679148,"mc":[{"id":"1.195453772","rc":[{"atb":[[4.8,3.73]],"id":39786791}],"con":true,"img":false}]}
{"op":"mcm","clk":"5353423500","pt":1646214681573,"mc":[{"id":"1.195453772","rc":[{"atl":[[9.2,9.15],[10,0]],"id":43167135},{"atb":[[11.5,0],[13.5,6]],"id":37260099},{"atl":[[170,0],[190,0],[200,1],[210,0]],"id":36500408},{"atb":[[6.4,13.89],[5.9,0],[6.2,0],[5.7,17.05]],"id":42077854},{"atb":[[4.8,0],[5.3,17.44],[5,25],[5.2,0]],"id":42860579}],"con":true,"img":false}]}
{"op":"mcm","clk":"5353423630","pt":1646214685284,"mc":[{"id":"1.195453772","rc":[{"atb":[[1.82,91.46],[1.79,0],[1.77,0],[1.75,0]],"id":40120078},{"atl":[[3.35,31.91]],"id":40120078},{"atl":[[8.6,9.87]],"id":39786791}],"con":true,"img":false}]}
{"op":"mcm","clk":"5353423902","pt":1646214691571,"mc":[{"id":"1.195453772","rc":[{"atl":[[9.6,14.53]],"id":43167135},{"atb":[[12.5,17.39]],"id":37260099},{"atl":[[220,1]],"id":36500408},{"atb":[[6,41.4]],"id":42077854},{"atb":[[5.1,30.49]],"id":42860579}],"con":true,"img":false}]}
{"op":"mcm","clk":"5353423909","pt":1646214691681,"mc":[{"id":"1.195453772","rc":[{"atb":[[12.5,10.87]],"id":37260099}],"con":true,"img":false}]}
{"op":"mcm","clk":"5353424095","pt":1646214695284,"mc":[{"id":"1.195453772","rc":[{"atb":[[1.8,392.62]],"id":40120078},{"atl":[[3.45,51.02]],"id":40120078},{"atl":[[9,15.62]],"id":39786791}],"con":true,"img":false}]}
{"op":"mcm","clk":"5353424625","pt":1646214705283,"mc":[{"id":"1.195453772","rc":[{"atl":[[9.4,0]],"id":43167135}],"con":true,"img":false}]}
{"op":"mcm","clk":"5353424631","pt":1646214705387,"mc":[{"id":"1.195453772","rc":[{"atl":[[9,13.75]],"id":43167135}],"con":true,"img":false}]}
{"op":"mcm","clk":"5353424741","pt":1646214707594,"mc":[{"id":"1.195453772","rc":[{"atl":[[1000,1.24]],"id":36500408}],"con":true,"img":false}]}
{"op":"mcm","clk":"5353424748","pt":1646214707691,"mc":[{"id":"1.195453772","rc":[{"atl":[[16.5,1.24]],"id":42860579},{"atl":[[1000,1.24]],"id":39786791}],"con":true,"img":false}]}
{"op":"mcm","clk":"5353424754","pt":1646214707796,"mc":[{"id":"1.195453772","rc":[{"atl":[[1000,1.24]],"id":43167135},{"atl":[[1000,0]],"id":36500408},{"atl":[[16.5,4.1],[19,0]],"id":42860579}],"con":true,"img":false}]}
{"op":"mcm","clk":"5353424757","pt":1646214707898,"mc":[{"id":"1.195453772","rc":[{"atl":[[170,1.24]],"id":37260099},{"atl":[[12.5,1.24]],"id":36500408},{"atl":[[40,1.24]],"id":42077854},{"atl":[[1000,0]],"id":39786791}],"con":true,"img":false}]}
{"op":"mcm","clk":"5353424762","pt":1646214708001,"mc":[{"id":"1.195453772","rc":[{"atl":[[1000,0]],"id":43167135},{"atl":[[220,1.48]],"id":28506637},{"atl":[[16,2],[17,1.25]],"id":42860579},{"atl":[[7.6,1.24]],"id":39786791}],"con":true,"img":false}]}
{"op":"mcm","clk":"5353424768","pt":1646214708103,"mc":[{"id":"1.195453772","rc":[{"atl":[[8.2,1.24]],"id":43167135},{"atl":[[220,3.48]],"id":28506637}],"con":true,"img":false}]}
{"op":"mcm","clk":"5353424772","pt":1646214708206,"mc":[{"id":"1.195453772","rc":[{"atl":[[210,2],[240,2.72]],"id":28506637}],"con":true,"img":false}]}
{"op":"mcm","clk":"5353424782","pt":1646214708411,"mc":[{"id":"1.195453772","rc":[{"atl":[[230,0]],"id":28506637}],"con":true,"img":false}]}
{"op":"mcm","clk":"5353424788","pt":1646214708514,"mc":[{"id":"1.195453772","rc":[{"atl":[[210,0]],"id":28506637}],"con":true,"img":false}]}
{"op":"mcm","clk":"5353424798","pt":1646214708619,"mc":[{"id":"1.195453772","rc":[{"atl":[[210,2]],"id":28506637}],"con":true,"img":false}]}
{"op":"mcm","clk":"5353425382","pt":1646214720141,"mc":[{"id":"1.195453772","rc":[{"atl":[[8.6,2.63]],"id":43167135},{"atb":[[1.83,24.1],[1.84,0],[1.86,0]],"id":40120078},{"atb":[[5.3,4.65],[5.5,0],[5.7,0]],"id":42860579},{"atb":[[4.3,0],[4.2,45.48]],"id":39786791}],"con":true,"img":false}]}
{"op":"mcm","clk":"5353425386","pt":1646214720242,"mc":[{"id":"1.195453772","rc":[{"atl":[[8.4,0]],"id":43167135}],"con":true,"img":false}]}
{"op":"mcm","clk":"5353425500","pt":1646214722419,"mc":[{"id":"1.195453772","rc":[{"atl":[[3.2,0]],"id":40120078}],"con":true,"img":false}]}
{"op":"mcm","clk":"5353425503","pt":1646214722520,"mc":[{"id":"1.195453772","rc":[{"atl":[[3.3,42.75]],"id":40120078}],"con":true,"img":false}]}
{"op":"mcm","clk":"5353425629","pt":1646214725261,"mc":[{"id":"1.195453772","rc":[{"atl":[[3.1,0]],"id":40120078}],"con":true,"img":false}]}
{"op":"mcm","clk":"5353425640","pt":1646214725322,"mc":[{"id":"1.195453772","rc":[{"atl":[[3.2,27.83]],"id":40120078}],"con":true,"img":false}]}
{"op":"mcm","clk":"5353425646","pt":1646214725428,"mc":[{"id":"1.195453772","rc":[{"atl":[[3.25,30.39]],"id":40120078}],"con":true,"img":false}]}
{"op":"mcm","clk":"5353425883","pt":1646214730146,"mc":[{"id":"1.195453772","rc":[{"atl":[[9,20]],"id":43167135},{"atb":[[1.81,61.73]],"id":40120078},{"atb":[[5.1,12.2]],"id":42860579},{"atb":[[4,16.67]],"id":39786791},{"spn":4.69,"spf":1.0,"id":39786791}],"con":true,"img":false}]}
{"op":"mcm","clk":"5353426012","pt":1646214732365,"mc":[{"id":"1.195453772","rc":[{"atl":[[220,2.24]],"id":28506637},{"atl":[[16.5,2.86]],"id":42860579}],"con":true,"img":false}]}
{"op":"mcm","clk":"5353426023","pt":1646214732566,"mc":[{"id":"1.195453772","rc":[{"atl":[[210,0],[230,2]],"id":28506637},{"atl":[[16,0],[16.5,2],[17,6.11]],"id":42860579}],"con":true,"img":false}]}
{"op":"mcm","clk":"5353426030","pt":1646214732670,"mc":[{"id":"1.195453772","rc":[{"atl":[[16.5,0]],"id":42860579}],"con":true,"img":false}]}
{"op":"mcm","clk":"5353426038","pt":1646214732770,"mc":[{"id":"1.195453772","rc":[{"atl":[[16.5,2]],"id":42860579}],"con":true,"img":false}]}
{"op":"mcm","clk":"5353426166","pt":1646214735153,"mc":[{"id":"1.195453772","rc":[{"atl":[[9.8,0]],"id":39786791}],"con":true,"img":false}]}
{"op":"mcm","clk":"5353426174","pt":1646214735254,"mc":[{"id":"1.195453772","rc":[{"atl":[[9.6,6.15]],"id":39786791}],"con":true,"img":false}]}
{"op":"mcm","clk":"5353426308","pt":1646214737637,"mc":[{"id":"1.195453772","rc":[{"atl":[[220,0.24],[230,4]],"id":28506637},{"atl":[[17,1.24],[18.5,8.57]],"id":42860579}],"con":true,"img":false}]}
{"op":"mcm","clk":"5353426318","pt":1646214737850,"mc":[{"id":"1.195453772","rc":[{"atl":[[9.2,0],[9.6,0],[8.8,7.49]],"id":43167135},{"atl":[[17,3.24]],"id":42860579},{"atb":[[3.85,0],[3.95,0],[4.1,33.18]],"id":39786791}],"con":true,"img":false}]}
{"op":"mcm","clk":"5353426328","pt":1646214738046,"mc":[{"id":"1.195453772","rc":[{"atl":[[16.5,0]],"id":42860579}],"con":true,"img":false}]}
{"op":"mcm","clk":"5353426446","pt":1646214740161,"mc":[{"id":"1.195453772","rc":[{"atl":[[9.4,8.93]],"id":43167135},{"atb":[[1.79,94.94]],"id":40120078},{"atb":[[4.9,37.69]],"id":42860579},{"atb":[[3.9,25.86]],"id":39786791}],"con":true,"img":false}]}
{"op":"mcm","clk":"5353426585","pt":1646214742884,"mc":[{"id":"1.195453772","rc":[{"atl":[[18.5,2.86],[19,5.56]],"id":42860579}],"con":true,"img":false}]}
{"op":"mcm","clk":"5353426610","pt":1646214743264,"mc":[{"id":"1.195453772","rc":[{"atb":[[1.82,0],[1.8,236.37]],"id":40120078}],"con":true,"img":false}]}
{"op":"mcm","clk":"5353426701","pt":1646214745190,"mc":[{"id":"1.195453772","rc":[{"atl":[[9,6.25]],"id":43167135},{"atl":[[180,4]],"id":37260099}],"con":true,"img":false}]}
{"op":"mcm","clk":"5353426709","pt":1646214745275,"mc":[{"id":"1.195453772","rc":[{"atl":[[9.2,13.75]],"id":43167135},{"atl":[[160,3.06]],"id":37260099}],"con":true,"img":false}]}
{"op":"mcm","clk":"5353426724","pt":1646214745473,"mc":[{"id":"1.195453772","rc":[{"atl":[[150,2],[180,2]],"id":37260099}],"con":true,"img":false}]}
{"op":"mcm","clk":"5353426959","pt":1646214750175,"mc":[{"id":"1.195453772","rc":[{"atl":[[9.8,25.56]],"id":43167135},{"atb":[[1.77,162.34]],"id":40120078},{"atb":[[4.7,33.78]],"id":42860579},{"atb":[[3.8,81.37]],"id":39786791}],"con":true,"img":false}]}
{"op":"mcm","clk":"5353427203","pt":1646214755187,"mc":[{"id":"1.195453772","rc":[{"atl":[[19.5,4.05]],"id":42860579}],"con":true,"img":false}]}
{"op":"mcm","clk":"5353427208","pt":1646214755289,"mc":[{"id":"1.195453772","rc":[{"atl":[[18.5,5.78]],"id":42860579}],"con":true,"img":false}]}
{"op":"mcm","clk":"5353427273","pt":1646214756583,"mc":[{"id":"1.195453772","rc":[{"atl":[[170,0]],"id":37260099}],"con":true,"img":false}]}
{"op":"mcm","clk":"5353427469","pt":1646214759816,"mc":[{"id":"1.195453772","rc":[{"atl":[[3.1,9.52],[3.15,0]],"id":40120078}],"con":true,"img":false}]}
{"op":"mcm","clk":"5353427495","pt":1646214760184,"mc":[{"id":"1.195453772","rc":[{"atb":[[4.3,24.91],[4.5,29.39]],"id":43167135},{"atl":[[8.4,2.7],[8.6,0]],"id":43167135},{"atb":[[1.83,0],[1.86,23.26]],"id":40120078},{"atb":[[4.9,0],[4.7,5.41]],"id":36500408},{"atb":[[5.3,0],[5.7,4.26]],"id":42860579},{"atl":[[17,1.99],[17.5,1.21]],"id":42860579},{"atb":[[4.3,6.06],[4.2,39.23]],"id":39786791}],"con":true,"img":false}]}
{"op":"mcm","clk":"5353427508","pt":1646214760298,"mc":[{"id":"1.195453772","rc":[{"atl":[[17.5,3.21]],"id":42860579}],"con":true,"img":false}]}
{"op":"mcm","clk":"5353427512","pt":1646214760394,"mc":[{"id":"1.195453772","rc":[{"atl":[[17,0],[17.5,8.77],[19,0]],"id":42860579}],"con":true,"img":false}]}
{"op":"mcm","clk":"5353427519","pt":1646214760497,"mc":[{"id":"1.195453772","rc":[{"atl":[[17.5,6.77]],"id":42860579}],"con":true,"img":false}]}
{"op":"mcm","clk":"5353427524","pt":1646214760601,"mc":[{"id":"1.195453772","rc":[{"atl":[[17.5,8.77]],"id":42860579}],"con":true,"img":false}]}
{"op":"mcm","clk":"5353427703","pt":1646214763899,"mc":[{"id":"1.195453772","rc":[{"atb":[[1.83,24.1],[1.89,70.32],[1.8,138.97],[1.86,0]],"id":40120078},{"atb":[[15.5,0],[16,1.33]],"id":37260099},{"atb":[[4.9,5.13]],"id":36500408},{"atb":[[21,0],[22,5.89]],"id":28506637},{"atb":[[7.4,3.12],[7.2,0]],"id":42077854},{"atb":[[5.9,4.08],[5.5,4.44],[5.7,0]],"id":42860579},{"atl":[[17.5,7.56],[17,1.25]],"id":42860579}],"con":true,"img":false}]}
{"op":"mcm","clk":"5353427711","pt":1646214764004,"mc":[{"id":"1.195453772","rc":[{"atl":[[9.2,25.95],[9.8,14.2]],"id":43167135},{"atl":[[3.1,0],[3.15,9.3]],"id":40120078},{"atl":[[180,0],[190,2]],"id":37260099},{"atl":[[46,0],[48,2.13]],"id":42077854},{"atl":[[8,2.86],[7.8,0]],"id":39786791}],"con":true,"img":false}]}
{"op":"mcm","clk":"5353427779","pt":1646214765186,"mc":[{"id":"1.195453772","rc":[{"atb":[[1.8,0]],"id":40120078},{"atl":[[3.3,0]],"id":40120078},{"atl":[[160,0.34]],"id":37260099},{"atl":[[44,0]],"id":42077854}],"con":true,"img":false}]}
{"op":"mcm","clk":"5353427784","pt":1646214765285,"mc":[{"id":"1.195453772","rc":[{"atb":[[1.82,138.97]],"id":40120078},{"atl":[[3.2,70.59]],"id":40120078},{"atl":[[150,0],[180,2.72],[190,4]],"id":37260099},{"atl":[[46,2.72]],"id":42077854}],"con":true,"img":false}]}
{"op":"mcm","clk":"5353427790","pt":1646214765391,"mc":[{"id":"1.195453772","rc":[{"atl":[[300,2.44],[190,2]],"id":37260099}],"con":true,"img":false}]}
{"op":"mcm","clk":"5353427792","pt":1646214765489,"mc":[{"id":"1.195453772","rc":[{"atl":[[17.5,2],[18,5.88]],"id":42860579}],"con":true,"img":false}]}
{"op":"mcm","clk":"5353427802","pt":1646214765698,"mc":[{"id":"1.195453772","rc":[{"atb":[[5.9,0]],"id":42860579}],"con":true,"img":false}]}
{"op":"mcm","clk":"5353427895","pt":1646214767213,"mc":[{"id":"1.195453772","rc":[{"atb":[[4.3,18.85],[4.5,35.1]],"id":43167135},{"atl":[[8.4,0],[8.6,2.63]],"id":43167135},{"atb":[[1.83,0],[1.86,23.26]],"id":40120078},{"atb":[[5.9,4.08],[5.5,0]],"id":42860579},{"atl":[[17,0],[17.5,3.21]],"id":42860579},{"atb":[[4.3,0],[4.2,45.48]],"id":39786791}],"con":true,"img":false}]}
{"op":"mcm","clk":"5353428003","pt":1646214768905,"mc":[{"id":"1.195453772","rc":[{"atl":[[17,1.24]],"id":42860579}],"con":true,"img":false}]}
{"op":"mcm","clk":"5353428087","pt":1646214770504,"mc":[{"id":"1.195453772","rc":[{"atl":[[300,0.44],[180,4.72]],"id":37260099}],"con":true,"img":false}]}
{"op":"mcm","clk":"5353428271","pt":1646214773943,"mc":[{"id":"1.195453772","rc":[{"atb":[[4.7,13.51]],"id":36500408},{"atb":[[20,2.63]],"id":28506637}],"con":true,"img":false}]}
{"op":"mcm","clk":"5353428357","pt":1646214775810,"mc":[{"id":"1.195453772","rc":[{"atl":[[17,4.45],[18,0]],"id":42860579}],"con":true,"img":false}]}
{"op":"mcm","clk":"5353428361","pt":1646214775909,"mc":[{"id":"1.195453772","rc":[{"atl":[[16.5,2],[17.5,1.21]],"id":42860579}],"con":true,"img":false}]}
{"op":"mcm","clk":"5353428425","pt":1646214777226,"mc":[{"id":"1.195453772","rc":[{"atb":[[5.7,10.64]],"id":42860579},{"atl":[[8.4,6.76]],"id":39786791}],"con":true,"img":false}]}
{"op":"mcm","clk":"5353428431","pt":1646214777331,"mc":[{"id":"1.195453772","rc":[{"atb":[[1.84,59.52]],"id":40120078}],"con":true,"img":false}]}
{"op":"mcm","clk":"5353428555","pt":1646214780318,"mc":[{"id":"1.195453772","rc":[{"atb":[[4.3,24.91],[4.5,29.39],[5.1,3]],"id":43167135},{"atl":[[8.4,2.7],[8.6,0]],"id":43167135},{"atb":[[1.83,24.1],[1.84,0],[1.79,0],[1.81,0],[1.86,0],[1.77,0]],"id":40120078},{"atl":[[2.32,3]],"id":40120078},{"atb":[[17,0]],"id":28506637},{"atb":[[5.9,0],[6.2,2],[5.5,4.44],[5.7,0],[4.7,0]],"id":42860579},{"atl":[[17,5.7],[17.5,0]],"id":42860579},{"atb":[[4.3,6.06],[4.2,39.23]],"id":39786791},{"atl":[[9,0],[8.2,0],[7.2,2],[8.6,0]],"id":39786791}],"con":true,"img":false}]}
{"op":"mcm","clk":"5353428596","pt":1646214781037,"mc":[{"id":"1.195453772","rc":[{"atl":[[7.6,0]],"id":39786791}],"con":true,"img":false}]}
{"op":"mcm","clk":"5353428727","pt":1646214783929,"mc":[{"id":"1.195453772","rc":[{"atb":[[19,6.95]],"id":28506637}],"con":true,"img":false}]}
{"op":"mcm","clk":"5353428733","pt":1646214784041,"mc":[{"id":"1.195453772","rc":[{"atb":[[19,4.17]],"id":28506637}],"con":true,"img":false}]}
{"op":"mcm","clk":"5353428737","pt":1646214784143,"mc":[{"id":"1.195453772","rc":[{"atb":[[5.1,0]],"id":43167135},{"atl":[[6.4,4]],"id":43167135},{"atl":[[2.3,4],[3.1,9.52]],"id":40120078},{"atb":[[6.2,0]],"id":42860579},{"atl":[[10,3]],"id":42860579},{"atl":[[7.2,0]],"id":39786791}],"con":true,"img":false}]}
{"op":"mcm","clk":"5353428742","pt":1646214784245,"mc":[{"id":"1.195453772","rc":[{"atl":[[3.15,0]],"id":40120078}],"con":true,"img":false}]}
{"op":"mcm","clk":"5353428756","pt":1646214784454,"mc":[{"id":"1.195453772","rc":[{"atb":[[2.06,0]],"id":40120078}],"con":true,"img":false}]}
{"op":"mcm","clk":"5353428784","pt":1646214785130,"mc":[{"id":"1.195453772","rc":[{"atb":[[1.82,0],[1.65,171.04]],"id":40120078},{"atl":[[18.5,2.86]],"id":42860579}],"con":true,"img":false}]}
{"op":"mcm","clk":"5353428791","pt":1646214785231,"mc":[{"id":"1.195453772","rc":[{"atl":[[19.5,6.97]],"id":42860579}],"con":true,"img":false}]}
{"op":"mcm","clk":"5353428874","pt":1646214786937,"mc":[{"id":"1.195453772","rc":[{"atb":[[5.8,0]],"id":36500408}],"con":true,"img":false}]}
{"op":"mcm","clk":"5353428879","pt":1646214787040,"mc":[{"id":"1.195453772","rc":[{"atl":[[3.25,22.22]],"id":40120078},{"atb":[[1.03,2.25]],"id":36500408}],"con":true,"img":false}]}
{"op":"mcm","clk":"5353428885","pt":1646214787144,"mc":[{"id":"1.195453772","rc":[{"atb":[[5.9,0]],"id":36500408}],"con":true,"img":false}]}
{"op":"mcm","clk":"5353428892","pt":1646214787244,"mc":[{"id":"1.195453772","rc":[{"atb":[[1.03,0.58]],"id":36500408}],"con":true,"img":false}]}
{"op":"mcm","clk":"5353428907","pt":1646214787553,"mc":[{"id":"1.195453772","rc":[{"atb":[[1.03,0]],"id":36500408}],"con":true,"img":false}]}
{"op":"mcm","clk":"5353428911","pt":1646214787654,"mc":[{"id":"1.195453772","rc":[{"atb":[[5.8,0.58]],"id":36500408}],"con":true,"img":false}]}
{"op":"mcm","clk":"5353429046","pt":1646214790338,"mc":[{"id":"1.195453772","rc":[{"atb":[[4.1,16.13]],"id":43167135},{"spn":2.01,"spf":1.0,"id":40120078},{"spn":25.55,"spf":1.0,"id":37260099},{"spn":5.62,"spf":1.0,"id":36500408},{"spn":31.65,"spf":1.0,"id":28506637},{"atb":[[5.3,11.63]],"id":42860579},{"atl":[[8.8,9.62]],"id":39786791}],"con":true,"img":false}]}
{"op":"mcm","clk":"5353429054","pt":1646214790439,"mc":[{"id":"1.195453772","rc":[{"atl":[[6.2,4]],"id":43167135},{"atb":[[1.86,23.26]],"id":40120078},{"atl":[[2.3,0],[2.32,0]],"id":40120078},{"atb":[[4.9,0],[4.7,5.41]],"id":36500408},{"atl":[[40,3]],"id":36500408},{"atb":[[5.9,4.08],[6.2,2]],"id":42860579},{"atl":[[10,0],[17,4.45],[17.5,1.21]],"id":42860579}],"con":true,"img":false}]}
{"op":"mcm","clk":"5353429065","pt":1646214790646,"mc":[{"id":"1.195453772","rc":[{"atb":[[4,34.29],[3.9,0],[4.2,0]],"id":43167135},{"atl":[[6,2]],"id":43167135},{"atl":[[3.1,0],[3.15,9.3]],"id":40120078},{"atb":[[2.22,61.28],[2.4,58.57]],"id":36500408},{"atl":[[38,6.7]],"id":36500408},{"atb":[[6.4,3],[4.9,18.46]],"id":42860579},{"atl":[[17,1.24],[17.5,7.27]],"id":42860579},{"atl":[[8,0],[8.2,2.78]],"id":39786791}],"con":true,"img":false}]}
{"op":"mcm","clk":"5353429075","pt":1646214790852,"mc":[{"id":"1.195453772","rc":[{"atl":[[16.5,0],[17,3.24]],"id":42860579}],"con":true,"img":false}]}
{"op":"mcm","clk":"5353429144","pt":1646214792450,"mc":[{"id":"1.195453772","rc":[{"atb":[[5.8,3.56]],"id":36500408}],"con":true,"img":false}]}
{"op":"mcm","clk":"5353429182","pt":1646214793267,"mc":[{"id":"1.195453772","rc":[{"atl":[[8.2,0]],"id":43167135},{"atl":[[1000,1.24]],"id":39786791}],"con":true,"img":false}]}
{"op":"mcm","clk":"5353429192","pt":1646214793424,"mc":[{"id":"1.195453772","rc":[{"atl":[[1000,0]],"id":39786791}],"con":true,"img":false}]}
{"op":"mcm","clk":"5353429200","pt":1646214793527,"mc":[{"id":"1.195453772","rc":[{"atl":[[8,1.24]],"id":39786791}],"con":true,"img":false}]}
{"op":"mcm","clk":"5353429226","pt":1646214793942,"mc":[{"id":"1.195453772","rc":[{"atb":[[18,7.35]],"id":28506637}],"con":true,"img":false}]}
{"op":"mcm","clk":"5353429277","pt":1646214795124,"mc":[{"id":"1.195453772","rc":[{"atb":[[4.3,6.06],[3.95,0]],"id":43167135},{"atl":[[3.2,27.83]],"id":40120078}],"con":true,"img":false}]}
{"op":"mcm","clk":"5353429280","pt":1646214795228,"mc":[{"id":"1.195453772","rc":[{"atb":[[3.8,41.26],[4.2,18.85]],"id":43167135},{"atl":[[3.3,42.75]],"id":40120078}],"con":true,"img":false}]}
{"op":"mcm","clk":"5353429286","pt":1646214795332,"mc":[{"id":"1.195453772","rc":[{"atb":[[2.06,2.95]],"id":40120078}],"con":true,"img":false}]}
{"op":"mcm","clk":"5353429584","pt":1646214800384,"mc":[{"id":"1.195453772","rc":[{"atb":[[3.95,25.42]],"id":43167135}],"con":true,"img":false}]}
{"op":"mcm","clk":"5353429590","pt":1646214800487,"mc":[{"id":"1.195453772","rc":[{"atb":[[4.5,43.68]],"id":36500408},{"atb":[[5.7,10.64]],"id":42860579}],"con":true,"img":false}]}
{"op":"mcm","clk":"5353429600","pt":1646214800597,"mc":[{"id":"1.195453772","rc":[{"atb":[[3.25,44.44],[4.5,35.1]],"id":43167135},{"atl":[[5.9,2]],"id":43167135},{"atb":[[5.1,0]],"id":42860579}],"con":true,"img":false}]}
{"op":"mcm","clk":"5353429608","pt":1646214800654,"mc":[{"id":"1.195453772","rc":[{"atb":[[3,0]],"id":43167135},{"atl":[[6.4,0],[6.2,0],[6,0]],"id":43167135},{"atl":[[36,3]],"id":36500408},{"atb":[[6.6,22.37]],"id":42860579},{"atl":[[8.6,6.58]],"id":39786791}],"con":true,"img":false}]}
{"op":"mcm","clk":"5353429817","pt":1646214805175,"mc":[{"id":"1.195453772","rc":[{"atl":[[180,2]],"id":37260099}],"con":true,"img":false}]}
{"op":"mcm","clk":"5353429825","pt":1646214805279,"mc":[{"id":"1.195453772","rc":[{"atl":[[170,2.72]],"id":37260099}],"con":true,"img":false}]}
{"op":"mcm","clk":"5353429830","pt":1646214805382,"mc":[{"id":"1.195453772","rc":[{"atl":[[180,0],[190,4]],"id":37260099}],"con":true,"img":false}]}
{"op":"mcm","clk":"5353430096","pt":1646214810487,"mc":[{"id":"1.195453772","rc":[{"atl":[[170,4.72]],"id":37260099},{"atb":[[4.3,22.73]],"id":36500408},{"atb":[[5.5,16.67]],"id":42860579}],"con":true,"img":false}]}
{"op":"mcm","clk":"5353430104","pt":1646214810591,"mc":[{"id":"1.195453772","rc":[{"atl":[[190,2]],"id":37260099}],"con":true,"img":false}]}
{"op":"mcm","clk":"5353430111","pt":1646214810697,"mc":[{"id":"1.195453772","rc":[{"atb":[[4.3,15.15]],"id":43167135},{"atl":[[5.9,0]],"id":43167135},{"atl":[[170,2.72]],"id":37260099},{"atl":[[34,3]],"id":36500408},{"atb":[[6.8,20.79]],"id":42860579},{"atl":[[9,9.38]],"id":39786791}],"con":true,"img":false}]}
{"op":"mcm","clk":"5353430116","pt":1646214810747,"mc":[{"id":"1.195453772","rc":[{"atl":[[8.6,7.49]],"id":43167135}],"con":true,"img":false}]}
{"op":"mcm","clk":"5353430125","pt":1646214810852,"mc":[{"id":"1.195453772","rc":[{"atl":[[9.2,13.75]],"id":43167135},{"atl":[[170,4.72]],"id":37260099}],"con":true,"img":false}]}
{"op":"mcm","clk":"5353430367","pt":1646214815178,"mc":[{"id":"1.195453772","rc":[{"atl":[[19.5,4.05]],"id":42860579}],"con":true,"img":false}]}
{"op":"mcm","clk":"5353430374","pt":1646214815277,"mc":[{"id":"1.195453772","rc":[{"atl":[[19,2.92]],"id":42860579}],"con":true,"img":false}]}
{"op":"mcm","clk":"5353430618","pt":1646214819822,"mc":[{"id":"1.195453772","rc":[{"atb":[[3.75,0],[4,0],[4.5,5.71],[5,0]],"id":43167135},{"atl":[[16,8.2],[18.5,0],[22,0],[27,0]],"id":43167135},{"atb":[[2,0],[1.85,0],[1.95,0],[1.9,0]],"id":40120078},{"atl":[[5.6,0],[5.1,0],[4.6,0],[6.2,0]],"id":40120078},{"atb":[[34,0],[18.5,0],[22,0],[27,0]],"id":37260099},{"atl":[[300,0],[350,0],[400,0],[250,0]],"id":37260099},{"atb":[[4,0],[4.5,14.29],[5,0],[5.5,0]],"id":36500408},{"atl":[[17,0],[19.5,0],[24,8.2],[29,0]],"id":36500408},{"atb":[[34,0],[18.5,0],[22,1],[27,0]],"id":28506637},{"atl":[[300,0],[350,0],[400,0],[250,0]],"id":28506637},{"atb":[[10.5,0],[13,0],[15.5,0],[18,0]],"id":42077854},{"atl":[[130,0],[280,0],[180,0],[230,1]],"id":42077854},{"atb":[[5.8,0],[8.6,0],[7.6,0],[6.6,4]],"id":42860579},{"atl":[[36,0],[46,0],[65,0],[90,0]],"id":42860579},{"atb":[[3.8,44.64],[3.55,0],[4.6,0],[4.1,0]],"id":39786791},{"atl":[[14.5,0],[17,0],[19.5,8.2],[24,0]],"id":39786791}],"con":true,"img":false}]}
{"op":"mcm","clk":"5353430626","pt":1646214820080,"mc":[{"id":"1.195453772","rc":[{"atb":[[4.5,0],[4.3,6.06]],"id":43167135},{"atl":[[8.6,0],[6.4,2],[9.2,25.95]],"id":43167135},{"atl":[[3.1,9.52],[3.15,0]],"id":40120078},{"atb":[[2.4,118.49],[2.22,0]],"id":36500408},{"atl":[[8,4.1],[8.6,0],[9,0],[8.2,0]],"id":39786791}],"con":true,"img":false}]}
{"op":"mcm","clk":"5353430641","pt":1646214820492,"mc":[{"id":"1.195453772","rc":[{"atb":[[4.1,40.32]],"id":36500408},{"atb":[[5.3,40.7]],"id":42860579}],"con":true,"img":false}]}
{"op":"mcm","clk":"5353430645","pt":1646214820595,"mc":[{"id":"1.195453772","rc":[{"atb":[[5.3,29.07]],"id":42860579}],"con":true,"img":false}]}
{"op":"mcm","clk":"5353430838","pt":1646214824570,"mc":[{"id":"1.195453772","rc":[{"atb":[[11.5,2.25]],"id":42077854}],"con":true,"img":false}]}
{"op":"mcm","clk":"5353430851","pt":1646214824878,"mc":[{"id":"1.195453772","rc":[{"atb":[[2.04,0]],"id":40120078}],"con":true,"img":false}]}
{"op":"mcm","clk":"5353430862","pt":1646214825185,"mc":[{"id":"1.195453772","rc":[{"atb":[[1.91,0]],"id":40120078},{"atb":[[5.6,14.7],[4.8,31.19]],"id":36500408},{"atl":[[240,0]],"id":28506637},{"atb":[[4.2,0],[4.7,2]],"id":39786791}],"con":true,"img":false}]}
{"op":"mcm","clk":"5353430868","pt":1646214825288,"mc":[{"id":"1.195453772","rc":[{"atb":[[1.9,60.61]],"id":40120078},{"atl":[[330,2.72],[340,2.49],[230,2]],"id":28506637},{"atb":[[4.1,39.23],[4.4,15.79]],"id":39786791}],"con":true,"img":false}]}
{"op":"mcm","clk":"5353430872","pt":1646214825392,"mc":[{"id":"1.195453772","rc":[{"atl":[[6.2,2]],"id":43167135},{"atl":[[3.1,0],[3.15,9.3]],"id":40120078},{"atl":[[330,4.72],[320,2],[340,0.49],[230,0]],"id":28506637}],"con":true,"img":false}]}
{"op":"mcm","clk":"5353430878","pt":1646214825495,"mc":[{"id":"1.195453772","rc":[{"atl":[[330,2.72]],"id":28506637}],"con":true,"img":false}]}
{"op":"mcm","clk":"5353430884","pt":1646214825600,"mc":[{"id":"1.195453772","rc":[{"atl":[[330,4.72]],"id":28506637}],"con":true,"img":false}]}
{"op":"mcm","clk":"5353430892","pt":1646214825707,"mc":[{"id":"1.195453772","rc":[{"atb":[[3.75,37.4],[4,34.29],[4.5,29.39],[5,25.71]],"id":43167135},{"atl":[[16,17.07],[18.5,7.61],[22,9.51],[27,7.68]],"id":43167135},{"atb":[[2,102.86],[1.85,121.02],[1.95,108.27],[1.9,174.91]],"id":40120078},{"atl":[[5.6,43.43],[5.1,32.48],[4.6,36.99],[6.2,38.42]],"id":40120078},{"atb":[[34,3.11],[18.5,5.88],[22,4.89],[27,3.95]],"id":37260099},{"atl":[[300,0.44],[350,0.57],[400,0.5],[250,0.53]],"id":37260099},{"atb":[[4,34.29],[4.5,43.68],[5,25.71],[5.5,22.85]],"id":36500408},{"atl":[[17,8.32],[19.5,7.19],[24,16.88],[29,7.13]],"id":36500408},{"atb":[[34,3.11],[18.5,5.88],[22,5.89],[27,3.95]],"id":28506637},{"atl":[[300,0.44],[350,0.57],[400,0.5],[250,0.53]],"id":28506637},{"atb":[[10.5,10.82],[13,8.57],[15.5,7.09],[18,6.04]],"id":42077854},{"atl":[[130,1.03],[280,0.71],[180,0.74],[230,1.87]],"id":42077854},{"atb":[[5.8,21.42],[8.6,13.53],[7.6,15.58],[6.6,22.37]],"id":42860579},{"atl":[[36,3.8],[46,2.95],[65,3.12],[90,2.24]],"id":42860579},{"atb":[[3.8,81.37],[3.55,40.34],[4.6,28.57],[4.1,72.42]],"id":39786791},{"atl":[[17,8.32],[19.5,19],[24,8.68],[14.5,9.86]],"id":39786791}],"con":true,"img":false}]}
{"op":"mcm","clk":"5353430991","pt":1646214827406,"mc":[{"id":"1.195453772","rc":[{"atb":[[4.8,0.76]],"id":39786791}],"con":true,"img":false}]}
{"op":"mcm","clk":"5353431135","pt":1646214829673,"mc":[{"id":"1.195453772","rc":[{"atl":[[310,1.24]],"id":28506637}],"con":true,"img":false}]}
{"op":"mcm","clk":"5353431141","pt":1646214829777,"mc":[{"id":"1.195453772","rc":[{"atb":[[2.06,0]],"id":40120078}],"con":true,"img":false}]}
{"op":"mcm","clk":"5353431159","pt":1646214830092,"mc":[{"id":"1.195453772","rc":[{"atb":[[3.85,43.86]],"id":43167135},{"atb":[[1.01,2]],"id":36500408},{"atl":[[9.2,15.24]],"id":39786791}],"con":true,"img":false}]}
{"op":"mcm","clk":"5353431168","pt":1646214830292,"mc":[{"id":"1.195453772","rc":[{"atb":[[1.01,3.99]],"id":36500408}],"con":true,"img":false}]}
{"op":"mcm","clk":"5353431187","pt":1646214830500,"mc":[{"id":"1.195453772","rc":[{"atl":[[6,3]],"id":43167135},{"atb":[[1.01,2]],"id":36500408},{"atl":[[300,2.44]],"id":28506637}],"con":true,"img":false}]}
{"op":"mcm","clk":"5353431191","pt":1646214830602,"mc":[{"id":"1.195453772","rc":[{"atb":[[5.9,1.99]],"id":36500408},{"atl":[[330,2.72]],"id":28506637}],"con":true,"img":false}]}
{"op":"mcm","clk":"5353431246","pt":1646214831381,"mc":[{"id":"1.195453772","rc":[{"atb":[[1.01,2]],"id":42860579}],"con":true,"img":false}]}
{"op":"mcm","clk":"5353431264","pt":1646214831584,"mc":[{"id":"1.195453772","rc":[{"atb":[[1.01,3.99]],"id":42860579}],"con":true,"img":false}]}
{"op":"mcm","clk":"5353431276","pt":1646214831689,"mc":[{"id":"1.195453772","rc":[{"atb":[[1.01,2]],"id":42860579}],"con":true,"img":false}]}
{"op":"mcm","clk":"5353431281","pt":1646214831791,"mc":[{"id":"1.195453772","rc":[{"atb":[[8.8,2.73]],"id":42860579}],"con":true,"img":false}]}
{"op":"mcm","clk":"5353431320","pt":1646214832512,"mc":[{"id":"1.195453772","rc":[{"atb":[[11.5,0]],"id":42077854}],"con":true,"img":false}]}
{"op":"mcm","clk":"5353431344","pt":1646214832773,"mc":[{"id":"1.195453772","rc":[{"atb":[[1.01,2]],"id":39786791}],"con":true,"img":false}]}
{"op":"mcm","clk":"5353431352","pt":1646214832975,"mc":[{"id":"1.195453772","rc":[{"atb":[[1.01,3.99]],"id":39786791}],"con":true,"img":false}]}
{"op":"mcm","clk":"5353431366","pt":1646214833285,"mc":[{"id":"1.195453772","rc":[{"atb":[[1.01,2]],"id":39786791}],"con":true,"img":false}]}
{"op":"mcm","clk":"5353431370","pt":1646214833387,"mc":[{"id":"1.195453772","rc":[{"atb":[[4.8,2.75]],"id":39786791}],"con":true,"img":false}]}
{"op":"mcm","clk":"5353431435","pt":1646214834723,"mc":[{"id":"1.195453772","rc":[{"atb":[[1.01,2]],"id":43167135}],"con":true,"img":false}]}
{"op":"mcm","clk":"5353431454","pt":1646214834981,"mc":[{"id":"1.195453772","rc":[{"atb":[[1.01,3.99]],"id":43167135}],"con":true,"img":false}]}
{"op":"mcm","clk":"5353431457","pt":1646214835085,"mc":[{"id":"1.195453772","rc":[{"atl":[[300,4.44],[320,0]],"id":28506637}],"con":true,"img":false}]}
{"op":"mcm","clk":"5353431466","pt":1646214835293,"mc":[{"id":"1.195453772","rc":[{"atb":[[1.01,2]],"id":43167135}],"con":true,"img":false}]}
{"op":"mcm","clk":"5353431472","pt":1646214835402,"mc":[{"id":"1.195453772","rc":[{"atb":[[1.02,1.99]],"id":43167135}],"con":true,"img":false}]}
{"op":"mcm","clk":"5353431478","pt":1646214835498,"mc":[{"id":"1.195453772","rc":[{"atb":[[1.96,5.02]],"id":40120078}],"con":true,"img":false}]}
{"op":"mcm","clk":"5353431492","pt":1646214835705,"mc":[{"id":"1.195453772","rc":[{"atb":[[4.3,0],[4.5,35.1]],"id":43167135},{"atl":[[6.4,0],[5.9,3],[6.2,0],[6,0]],"id":43167135},{"atl":[[8,1.24],[8.2,2.78]],"id":39786791}],"con":true,"img":false}]}
{"op":"mcm","clk":"5353431496","pt":1646214835808,"mc":[{"id":"1.195453772","rc":[{"atl":[[9.2,13.75],[8.6,7.49]],"id":43167135}],"con":true,"img":false}]}
{"op":"mcm","clk":"5353431517","pt":1646214836117,"mc":[{"id":"1.195453772","rc":[{"atb":[[44,0]],"id":28506637}],"con":true,"img":false}]}
{"op":"mcm","clk":"5353431523","pt":1646214836222,"mc":[{"id":"1.195453772","rc":[{"atb":[[50,5]],"id":28506637}],"con":true,"img":false}]}
{"op":"mcm","clk":"5353431689","pt":1646214839211,"mc":[{"id":"1.195453772","rc":[{"atb":[[1.01,2]],"id":40120078}],"con":true,"img":false}]}
{"op":"mcm","clk":"5353431700","pt":1646214839419,"mc":[{"id":"1.195453772","rc":[{"atb":[[1.01,3.99]],"id":40120078}],"con":true,"img":false}]}
{"op":"mcm","clk":"5353431718","pt":1646214839676,"mc":[{"id":"1.195453772","rc":[{"atb":[[1.01,2]],"id":40120078}],"con":true,"img":false}]}
{"op":"mcm","clk":"5353431724","pt":1646214839780,"mc":[{"id":"1.195453772","rc":[{"atb":[[1.02,1.99]],"id":40120078}],"con":true,"img":false}]}
{"op":"mcm","clk":"5353431779","pt":1646214840819,"mc":[{"id":"1.195453772","rc":[{"atb":[[1.02,5.21]],"id":40120078},{"atb":[[1.03,2.9]],"id":36500408},{"atb":[[1.02,2.94]],"id":39786791}],"con":true,"img":false}]}
{"op":"mcm","clk":"5353431786","pt":1646214840923,"mc":[{"id":"1.195453772","rc":[{"atb":[[1.03,2.92]],"id":43167135}],"con":true,"img":false}]}
{"op":"mcm","clk":"5353431802","pt":1646214841125,"mc":[{"id":"1.195453772","rc":[{"atl":[[5.9,0]],"id":43167135}],"con":true,"img":false}]}
{"op":"mcm","clk":"5353431812","pt":1646214841282,"mc":[{"id":"1.195453772","rc":[{"atb":[[1.02,2.48]],"id":40120078},{"atb":[[1.03,0.17]],"id":36500408},{"atb":[[1.02,0.21]],"id":39786791}],"con":true,"img":false}]}
{"op":"mcm","clk":"5353431819","pt":1646214841385,"mc":[{"id":"1.195453772","rc":[{"atb":[[1.03,0.19]],"id":43167135}],"con":true,"img":false}]}
{"op":"mcm","clk":"5353431832","pt":1646214841697,"mc":[{"id":"1.195453772","rc":[{"atb":[[1.02,1.99]],"id":40120078},{"atb":[[1.03,0]],"id":36500408},{"atb":[[1.02,0]],"id":39786791}],"con":true,"img":false}]}
{"op":"mcm","clk":"5353431836","pt":1646214841801,"mc":[{"id":"1.195453772","rc":[{"atb":[[1.03,0]],"id":43167135},{"atb":[[2.14,1.79]],"id":40120078},{"atb":[[6,0.17]],"id":36500408},{"atb":[[4.9,0.21]],"id":39786791}],"con":true,"img":false}]}
{"op":"mcm","clk":"5353431841","pt":1646214841903,"mc":[{"id":"1.195453772","rc":[{"atb":[[5.4,0.19]],"id":43167135}],"con":true,"img":false}]}
{"op":"mcm","clk":"5353432001","pt":1646214845192,"mc":[{"id":"1.195453772","rc":[{"atb":[[3.8,0]],"id":43167135},{"atl":[[170,2]],"id":37260099}],"con":true,"img":false}]}
{"op":"mcm","clk":"5353432006","pt":1646214845297,"mc":[{"id":"1.195453772","rc":[{"atb":[[4,75.55]],"id":43167135},{"atl":[[160,3.06],[170,0],[190,4]],"id":37260099}],"con":true,"img":false}]}
{"op":"mcm","clk":"5353432012","pt":1646214845400,"mc":[{"id":"1.195453772","rc":[{"atl":[[150,2]],"id":37260099}],"con":true,"img":false}]}
{"op":"mcm","clk":"5353432017","pt":1646214845503,"mc":[{"id":"1.195453772","rc":[{"atl":[[190,2]],"id":37260099}],"con":true,"img":false}]}
{"op":"mcm","clk":"5353432029","pt":1646214845709,"mc":[{"id":"1.195453772","rc":[{"atb":[[4.3,15.15]],"id":43167135},{"atl":[[8.6,6.58]],"id":39786791}],"con":true,"img":false}]}
{"op":"mcm","clk":"5353432091","pt":1646214846900,"mc":[{"id":"1.195453772","rc":[{"atb":[[1.02,1.66]],"id":36500408},{"atl":[[1000,1.66]],"id":36500408},{"atl":[[1000,1.66]],"id":42077854},{"atb":[[1.01,3.66]],"id":42860579}],"con":true,"img":false}]}
{"op":"mcm","clk":"5353432100","pt":1646214847107,"mc":[{"id":"1.195453772","rc":[{"atb":[[4.3,6.06],[3.85,0],[4.5,29.39]],"id":43167135},{"atl":[[6.4,3],[9.2,25.95],[8.6,0]],"id":43167135},{"atl":[[3.1,9.52],[3.15,0]],"id":40120078},{"atb":[[1.02,1.3]],"id":36500408},{"atl":[[1000,0.69]],"id":36500408},{"atl":[[1000,0.21]],"id":42077854},{"atb":[[1.01,2.92]],"id":42860579},{"atl":[[8,4.1],[8.2,0],[8.6,0]],"id":39786791}],"con":true,"img":false}]}
{"op":"mcm","clk":"5353432104","pt":1646214847210,"mc":[{"id":"1.195453772","rc":[{"atb":[[1.02,0]],"id":36500408}],"con":true,"img":false}]}
{"op":"mcm","clk":"5353432108","pt":1646214847313,"mc":[{"id":"1.195453772","rc":[{"atb":[[6.4,1.3]],"id":36500408}],"con":true,"img":false}]}
{"op":"mcm","clk":"5353432117","pt":1646214847519,"mc":[{"id":"1.195453772","rc":[{"atb":[[1.01,2]],"id":42860579}],"con":true,"img":false}]}
{"op":"mcm","clk":"5353432122","pt":1646214847620,"mc":[{"id":"1.195453772","rc":[{"atb":[[9,0.92]],"id":42860579}],"con":true,"img":false}]}
{"op":"mcm","clk":"5353432139","pt":1646214847830,"mc":[{"id":"1.195453772","rc":[{"atl":[[1000,0]],"id":36500408}],"con":true,"img":false}]}
{"op":"mcm","clk":"5353432149","pt":1646214847931,"mc":[{"id":"1.195453772","rc":[{"atl":[[12,0.69]],"id":36500408}],"con":true,"img":false}]}
{"op":"mcm","clk":"5353432160","pt":1646214848138,"mc":[{"id":"1.195453772","rc":[{"atl":[[1000,0]],"id":42077854}],"con":true,"img":false}]}
{"op":"mcm","clk":"5353432165","pt":1646214848186,"mc":[{"id":"1.195453772","rc":[{"atl":[[38,0.21]],"id":42077854}],"con":true,"img":false}]}
{"op":"mcm","clk":"5353432169","pt":1646214848288,"mc":[{"id":"1.195453772","rc":[{"atb":[[6.4,0],[1.02,1.66]],"id":36500408}],"con":true,"img":false}]}
{"op":"mcm","clk":"5353432176","pt":1646214848496,"mc":[{"id":"1.195453772","rc":[{"atb":[[1.02,1.3]],"id":36500408}],"con":true,"img":false}]}
{"op":"mcm","clk":"5353432182","pt":1646214848702,"mc":[{"id":"1.195453772","rc":[{"atb":[[1.02,0]],"id":36500408}],"con":true,"img":false}]}
{"op":"mcm","clk":"5353432185","pt":1646214848805,"mc":[{"id":"1.195453772","rc":[{"atb":[[6,1.48]],"id":36500408}],"con":true,"img":false}]}
{"op":"mcm","clk":"5353432460","pt":1646214854041,"mc":[{"id":"1.195453772","rc":[{"spn":4.83,"spf":1.0,"id":43167135},{"spn":2.0,"spf":1.0,"id":40120078},{"atl":[[140,1.24]],"id":37260099},{"spn":5.67,"spf":1.0,"id":36500408},{"spn":32.65,"spf":1.0,"id":28506637},{"spn":8.29,"spf":1.0,"id":42860579},{"spn":4.63,"spf":1.0,"id":39786791}],"con":true,"img":false}]}
{"op":"mcm","clk":"5353432470","pt":1646214854247,"mc":[{"id":"1.195453772","rc":[{"atl":[[3.1,0],[3.15,9.3]],"id":40120078}],"con":true,"img":false}]}
{"op":"mcm","clk":"5353432478","pt":1646214854299,"mc":[{"id":"1.195453772","rc":[{"atl":[[6.2,3]],"id":43167135}],"con":true,"img":false}]}
{"op":"mcm","clk":"5353432500","pt":1646214854713,"mc":[{"id":"1.195453772","rc":[{"atb":[[1.02,1.66],[6,0.17]],"id":36500408}],"con":true,"img":false}]}
{"op":"mcm","clk":"5353432513","pt":1646214854921,"mc":[{"id":"1.195453772","rc":[{"atb":[[1.02,1.3]],"id":36500408}],"con":true,"img":false}]}
{"op":"mcm","clk":"5353432522","pt":1646214855126,"mc":[{"id":"1.195453772","rc":[{"atb":[[1.02,0]],"id":36500408}],"con":true,"img":false}]}
{"op":"mcm","clk":"5353432526","pt":1646214855229,"mc":[{"id":"1.195453772","rc":[{"atb":[[1.9,114.29]],"id":40120078},{"atl":[[160,0.34]],"id":37260099},{"atb":[[6.4,1.3]],"id":36500408},{"atb":[[46,0]],"id":28506637},{"atl":[[9.6,0]],"id":39786791}],"con":true,"img":false}]}
{"op":"mcm","clk":"5353432532","pt":1646214855336,"mc":[{"id":"1.195453772","rc":[{"atb":[[1.91,60.61]],"id":40120078},{"atl":[[180,2.72]],"id":37260099},{"atb":[[40,2.72]],"id":28506637},{"atl":[[9,6.15]],"id":39786791}],"con":true,"img":false}]}
{"op":"mcm","clk":"5353432567","pt":1646214855852,"mc":[{"id":"1.195453772","rc":[{"atb":[[4.4,0]],"id":39786791}],"con":true,"img":false}]}
{"op":"mcm","clk":"5353432573","pt":1646214855952,"mc":[{"id":"1.195453772","rc":[{"atb":[[4.7,17.79]],"id":39786791}],"con":true,"img":false}]}
{"op":"mcm","clk":"5353432632","pt":1646214857163,"mc":[{"id":"1.195453772","rc":[{"atb":[[3.85,43.86]],"id":43167135}],"con":true,"img":false}]}
{"op":"mcm","clk":"5353433015","pt":1646214864223,"mc":[{"id":"1.195453772","rc":[{"atl":[[6,3]],"id":43167135}],"con":true,"img":false}]}
{"op":"mcm","clk":"5353433023","pt":1646214864330,"mc":[{"id":"1.195453772","rc":[{"atb":[[1.02,1.66]],"id":36500408}],"con":true,"img":false}]}
{"op":"mcm","clk":"5353433026","pt":1646214864430,"mc":[{"id":"1.195453772","rc":[{"atb":[[4.3,0],[4.5,35.1]],"id":43167135},{"atl":[[6.4,0],[5.9,4],[6.2,0],[6,0]],"id":43167135},{"atb":[[6.4,0]],"id":36500408},{"atl":[[8,1.24],[8.2,2.78]],"id":39786791}],"con":true,"img":false}]}
{"op":"mcm","clk":"5353433028","pt":1646214864531,"mc":[{"id":"1.195453772","rc":[{"atl":[[9.2,13.75],[8.6,7.49]],"id":43167135},{"atb":[[1.02,1.3]],"id":36500408}],"con":true,"img":false}]}
{"op":"mcm","clk":"5353433034","pt":1646214864736,"mc":[{"id":"1.195453772","rc":[{"atb":[[1.02,0]],"id":36500408}],"con":true,"img":false}]}
{"op":"mcm","clk":"5353433039","pt":1646214864839,"mc":[{"id":"1.195453772","rc":[{"atb":[[6,1.48]],"id":36500408}],"con":true,"img":false}]}
{"op":"mcm","clk":"5353433056","pt":1646214865255,"mc":[{"id":"1.195453772","rc":[{"atl":[[3.3,0]],"id":40120078},{"atb":[[4.1,33.18]],"id":39786791}],"con":true,"img":false}]}
{"op":"mcm","clk":"5353433060","pt":1646214865353,"mc":[{"id":"1.195453772","rc":[{"atl":[[3.2,70.59]],"id":40120078},{"atb":[[4.2,39.23]],"id":39786791}],"con":true,"img":false}]}
{"op":"mcm","clk":"5353433069","pt":1646214865456,"mc":[{"id":"1.195453772","rc":[{"atb":[[1.02,1.66],[6,0.17]],"id":36500408}],"con":true,"img":false}]}
{"op":"mcm","clk":"5353433080","pt":1646214865661,"mc":[{"id":"1.195453772","rc":[{"atb":[[1.02,1.3]],"id":36500408}],"con":true,"img":false}]}
{"op":"mcm","clk":"5353433087","pt":1646214865817,"mc":[{"id":"1.195453772","rc":[{"atb":[[1.02,0]],"id":36500408}],"con":true,"img":false}]}
{"op":"mcm","clk":"5353433090","pt":1646214865920,"mc":[{"id":"1.195453772","rc":[{"atb":[[6.4,1.3]],"id":36500408}],"con":true,"img":false}]}
{"op":"mcm","clk":"5353433109","pt":1646214866439,"mc":[{"id":"1.195453772","rc":[{"atl":[[330,0]],"id":28506637}],"con":true,"img":false}]}
{"op":"mcm","clk":"5353433113","pt":1646214866546,"mc":[{"id":"1.195453772","rc":[{"atl":[[240,2.72]],"id":28506637}],"con":true,"img":false}]}
{"op":"mcm","clk":"5353433119","pt":1646214866649,"mc":[{"id":"1.195453772","rc":[{"atl":[[300,2.44],[240,6.72]],"id":28506637}],"con":true,"img":false}]}
{"op":"mcm","clk":"5353433122","pt":1646214866752,"mc":[{"id":"1.195453772","rc":[{"atl":[[300,0.44]],"id":28506637}],"con":true,"img":false}]}
{"op":"mcm","clk":"5353433126","pt":1646214866853,"mc":[{"id":"1.195453772","rc":[{"atl":[[240,4.72]],"id":28506637}],"con":true,"img":false}]}
{"op":"mcm","clk":"5353433136","pt":1646214867113,"mc":[{"id":"1.195453772","rc":[{"atl":[[240,6.72]],"id":28506637}],"con":true,"img":false}]}
{"op":"mcm","clk":"5353433524","pt":1646214874476,"mc":[{"id":"1.195453772","rc":[{"atb":[[4.3,15.15]],"id":43167135},{"atl":[[5.9,0]],"id":43167135},{"atl":[[8.6,6.58]],"id":39786791}],"con":true,"img":false}]}
{"op":"mcm","clk":"5353433532","pt":1646214874681,"mc":[{"id":"1.195453772","rc":[{"atb":[[6.4,0],[1.02,1.66]],"id":36500408}],"con":true,"img":false}]}
{"op":"mcm","clk":"5353433536","pt":1646214874787,"mc":[{"id":"1.195453772","rc":[{"atb":[[4.3,6.06],[3.85,0],[4.5,29.39]],"id":43167135},{"atl":[[6.4,4],[9.2,25.95],[8.6,0]],"id":43167135},{"atl":[[3.1,9.52],[3.15,0]],"id":40120078},{"atl":[[46,4.94],[48,0]],"id":42077854},{"atl":[[8,4.1],[8.2,0],[8.6,0]],"id":39786791}],"con":true,"img":false}]}
{"op":"mcm","clk":"5353433540","pt":1646214874835,"mc":[{"id":"1.195453772","rc":[{"atb":[[1.02,1.3]],"id":36500408}],"con":true,"img":false}]}
{"op":"mcm","clk":"5353433546","pt":1646214874942,"mc":[{"id":"1.195453772","rc":[{"atb":[[1.02,0]],"id":36500408}],"con":true,"img":false}]}
{"op":"mcm","clk":"5353433553","pt":1646214875095,"mc":[{"id":"1.195453772","rc":[{"atb":[[6,1.48]],"id":36500408}],"con":true,"img":false}]}
{"op":"mcm","clk":"5353433559","pt":1646214875198,"mc":[{"id":"1.195453772","rc":[{"atl":[[3.2,27.83]],"id":40120078},{"atb":[[4.8,0],[5.6,40.47]],"id":36500408},{"atl":[[220,0]],"id":28506637}],"con":true,"img":false}]}
{"op":"mcm","clk":"5353433568","pt":1646214875255,"mc":[{"id":"1.195453772","rc":[{"atl":[[3.3,42.75]],"id":40120078},{"atb":[[1.02,1.66],[6,0.17]],"id":36500408},{"atl":[[240,6.97]],"id":28506637}],"con":true,"img":false}]}
{"op":"mcm","clk":"5353433572","pt":1646214875356,"mc":[{"id":"1.195453772","rc":[{"atb":[[1.02,1.3]],"id":36500408}],"con":true,"img":false}]}
{"op":"mcm","clk":"5353433582","pt":1646214875559,"mc":[{"id":"1.195453772","rc":[{"atb":[[1.02,0]],"id":36500408}],"con":true,"img":false}]}
{"op":"mcm","clk":"5353433587","pt":1646214875662,"mc":[{"id":"1.195453772","rc":[{"atb":[[6.4,1.3]],"id":36500408}],"con":true,"img":false}]}
{"op":"mcm","clk":"5353433639","pt":1646214876851,"mc":[{"id":"1.195453772","rc":[{"atb":[[1.02,1.66]],"id":42077854}],"con":true,"img":false}]}
{"op":"mcm","clk":"5353433648","pt":1646214877055,"mc":[{"id":"1.195453772","rc":[{"atb":[[1.02,0.44]],"id":42077854}],"con":true,"img":false}]}
{"op":"mcm","clk":"5353433660","pt":1646214877262,"mc":[{"id":"1.195453772","rc":[{"atb":[[1.02,0]],"id":42077854}],"con":true,"img":false}]}
{"op":"mcm","clk":"5353433665","pt":1646214877367,"mc":[{"id":"1.195453772","rc":[{"atb":[[19,0.44]],"id":42077854}],"con":true,"img":false}]}
{"op":"mcm","clk":"5353433767","pt":1646214879277,"mc":[{"id":"1.195453772","rc":[{"atl":[[160,0]],"id":37260099}],"con":true,"img":false}]}
{"op":"mcm","clk":"5353433773","pt":1646214879381,"mc":[{"id":"1.195453772","rc":[{"atl":[[140,1.58]],"id":37260099}],"con":true,"img":false}]}
{"op":"mcm","clk":"5353433783","pt":1646214879588,"mc":[{"id":"1.195453772","rc":[{"atb":[[14.5,0.19]],"id":42077854},{"atb":[[8.4,0]],"id":42860579}],"con":true,"img":false}]}
{"op":"mcm","clk":"5353433789","pt":1646214879644,"mc":[{"id":"1.195453772","rc":[{"atb":[[15.5,7.79]],"id":42077854},{"atb":[[8.6,14.86]],"id":42860579}],"con":true,"img":false}]}
{"op":"mcm","clk":"5353433792","pt":1646214879743,"mc":[{"id":"1.195453772","rc":[{"atb":[[9,0],[1.01,3.66]],"id":42860579}],"con":true,"img":false}]}
{"op":"mcm","clk":"5353433796","pt":1646214879854,"mc":[{"id":"1.195453772","rc":[{"atl":[[6.2,2]],"id":43167135},{"atl":[[3.15,9.3]],"id":40120078}],"con":true,"img":false}]}
{"op":"mcm","clk":"5353433803","pt":1646214879956,"mc":[{"id":"1.195453772","rc":[{"atl":[[3.1,0]],"id":40120078},{"atl":[[46,2.72],[48,2.13]],"id":42077854},{"atb":[[1.01,2.92]],"id":42860579}],"con":true,"img":false}]}
{"op":"mcm","clk":"5353433807","pt":1646214880063,"mc":[{"id":"1.195453772","rc":[{"atb":[[1.01,2]],"id":42860579}],"con":true,"img":false}]}
{"op":"mcm","clk":"5353433815","pt":1646214880161,"mc":[{"id":"1.195453772","rc":[{"atb":[[8.8,3.65]],"id":42860579}],"con":true,"img":false}]}
{"op":"mcm","clk":"5353433827","pt":1646214880373,"mc":[{"id":"1.195453772","rc":[{"atb":[[1.01,3.66],[8.8,2.73]],"id":42860579}],"con":true,"img":false}]}
{"op":"mcm","clk":"5353433836","pt":1646214880573,"mc":[{"id":"1.195453772","rc":[{"atb":[[1.01,2.9]],"id":42860579}],"con":true,"img":false}]}
{"op":"mcm","clk":"5353433846","pt":1646214880779,"mc":[{"id":"1.195453772","rc":[{"atb":[[1.01,2]],"id":42860579}],"con":true,"img":false}]}
{"op":"mcm","clk":"5353433851","pt":1646214880884,"mc":[{"id":"1.195453772","rc":[{"atb":[[9.2,0.9]],"id":42860579}],"con":true,"img":false}]}
{"op":"mcm","clk":"5353434057","pt":1646214884766,"mc":[{"id":"1.195453772","rc":[{"atb":[[3.85,43.86]],"id":43167135}],"con":true,"img":false}]}
{"op":"mcm","clk":"5353434071","pt":1646214884976,"mc":[{"id":"1.195453772","rc":[{"atl":[[6,2]],"id":43167135}],"con":true,"img":false}]}
{"op":"mcm","clk":"5353434576","pt":1646214894982,"mc":[{"id":"1.195453772","rc":[{"atl":[[5.9,2]],"id":43167135}],"con":true,"img":false}]}
{"op":"mcm","clk":"5353434590","pt":1646214895188,"mc":[{"id":"1.195453772","rc":[{"atb":[[4.3,0],[4.5,35.1]],"id":43167135},{"atl":[[6.4,0],[5.9,0],[6.2,0],[6,0]],"id":43167135},{"atl":[[240,6.72]],"id":28506637},{"atl":[[8,1.24],[8.2,2.78]],"id":39786791}],"con":true,"img":false}]}
{"op":"mcm","clk":"5353434593","pt":1646214895291,"mc":[{"id":"1.195453772","rc":[{"atl":[[9.2,13.75],[8.6,7.49]],"id":43167135},{"atl":[[230,0.24]],"id":28506637}],"con":true,"img":false}]}
{"op":"mcm","clk":"5353435082","pt":1646214905211,"mc":[{"id":"1.195453772","rc":[{"atb":[[4.3,15.15]],"id":43167135},{"atl":[[8.6,6.58]],"id":39786791}],"con":true,"img":false}]}
{"op":"mcm","clk":"5353435093","pt":1646214905418,"mc":[{"id":"1.195453772","rc":[{"atb":[[4.3,6.06],[3.85,0],[4.5,29.39]],"id":43167135},{"atl":[[6.4,4],[9.2,25.95],[8.6,0]],"id":43167135},{"atl":[[3.1,9.52],[3.15,0]],"id":40120078},{"atl":[[8,4.1],[8.2,0],[8.6,0]],"id":39786791}],"con":true,"img":false}]}
{"op":"mcm","clk":"5353435156","pt":1646214906607,"mc":[{"id":"1.195453772","rc":[{"atb":[[2.16,4.21]],"id":40120078}],"con":true,"img":false}]}
{"op":"mcm","clk":"5353435183","pt":1646214906915,"mc":[{"id":"1.195453772","rc":[{"atb":[[1.01,3.66],[9.2,0]],"id":42860579}],"con":true,"img":false}]}
{"op":"mcm","clk":"5353435194","pt":1646214907120,"mc":[{"id":"1.195453772","rc":[{"atb":[[1.01,2.9]],"id":42860579}],"con":true,"img":false}]}
{"op":"mcm","clk":"5353435207","pt":1646214907326,"mc":[{"id":"1.195453772","rc":[{"atb":[[1.01,2]],"id":42860579}],"con":true,"img":false}]}
{"op":"mcm","clk":"5353435213","pt":1646214907430,"mc":[{"id":"1.195453772","rc":[{"atb":[[9,0.9]],"id":42860579}],"con":true,"img":false}]}
{"op":"mcm","clk":"5353435221","pt":1646214907530,"mc":[{"id":"1.195453772","rc":[{"atb":[[1.01,3.66]],"id":42860579}],"con":true,"img":false}]}
{"op":"mcm","clk":"5353435227","pt":1646214907636,"mc":[{"id":"1.195453772","rc":[{"atb":[[9,0],[1.01,2.88]],"id":42860579}],"con":true,"img":false}]}
{"op":"mcm","clk":"5353435237","pt":1646214907840,"mc":[{"id":"1.195453772","rc":[{"atb":[[1.01,2]],"id":42860579}],"con":true,"img":false}]}
{"op":"mcm","clk":"5353435243","pt":1646214907943,"mc":[{"id":"1.195453772","rc":[{"atb":[[9.4,0.88]],"id":42860579}],"con":true,"img":false}]}
{"op":"mcm","clk":"5353435270","pt":1646214908303,"mc":[{"id":"1.195453772","rc":[{"atl":[[240,4]],"id":28506637}],"con":true,"img":false}]}
{"op":"mcm","clk":"5353435277","pt":1646214908409,"mc":[{"id":"1.195453772","rc":[{"atl":[[230,2.97],[240,2],[250,2.53]],"id":28506637}],"con":true,"img":false}]}
{"op":"mcm","clk":"5353435281","pt":1646214908512,"mc":[{"id":"1.195453772","rc":[{"atl":[[230,4.97]],"id":28506637}],"con":true,"img":false}]}
{"op":"mcm","clk":"5353435285","pt":1646214908615,"mc":[{"id":"1.195453772","rc":[{"atl":[[220,2],[240,0],[250,0.53]],"id":28506637}],"con":true,"img":false}]}
{"op":"mcm","clk":"5353435373","pt":1646214910528,"mc":[{"id":"1.195453772","rc":[{"atb":[[1.96,0]],"id":40120078}],"con":true,"img":false}]}
{"op":"mcm","clk":"5353435447","pt":1646214911719,"mc":[{"id":"1.195453772","rc":[{"atl":[[170,2],[190,0]],"id":37260099},{"atl":[[44,2.33],[48,0]],"id":42077854}],"con":true,"img":false}]}
{"op":"mcm","clk":"5353435459","pt":1646214911926,"mc":[{"id":"1.195453772","rc":[{"atl":[[6.2,4]],"id":43167135},{"atl":[[3.1,0],[3.15,9.3]],"id":40120078}],"con":true,"img":false}]}
{"op":"mcm","clk":"5353435586","pt":1646214914347,"mc":[{"id":"1.195453772","rc":[{"atl":[[9.2,13.75],[8.4,10.7]],"id":43167135},{"spn":2.02,"spf":1.0,"id":40120078},{"spn":5.7,"spf":1.0,"id":36500408},{"spn":32.11,"spf":1.0,"id":28506637},{"spn":14.72,"spf":1.0,"id":42077854},{"spn":8.3,"spf":1.0,"id":42860579},{"spn":4.69,"spf":1.0,"id":39786791}],"con":true,"img":false}]}
{"op":"mcm","clk":"5353435649","pt":1646214915225,"mc":[{"id":"1.195453772","rc":[{"atl":[[230,2.24]],"id":28506637},{"atl":[[46,0]],"id":42077854},{"atl":[[9,0]],"id":39786791}],"con":true,"img":false}]}
{"op":"mcm","clk":"5353435653","pt":1646214915329,"mc":[{"id":"1.195453772","rc":[{"atl":[[220,0],[240,2.72],[250,2.53]],"id":28506637},{"atl":[[60,2.72]],"id":42077854},{"atl":[[9.8,6.15]],"id":39786791}],"con":true,"img":false}]}
{"op":"mcm","clk":"5353435658","pt":1646214915431,"mc":[{"id":"1.195453772","rc":[{"atb":[[3.85,43.86]],"id":43167135},{"atl":[[240,4.72]],"id":28506637}],"con":true,"img":false}]}
{"op":"mcm","clk":"5353435663","pt":1646214915535,"mc":[{"id":"1.195453772","rc":[{"atl":[[230,0.24]],"id":28506637}],"con":true,"img":false}]}
{"op":"mcm","clk":"5353435670","pt":1646214915641,"mc":[{"id":"1.195453772","rc":[{"atl":[[240,2.72]],"id":28506637}],"con":true,"img":false}]}
{"op":"mcm","clk":"5353435676","pt":1646214915743,"mc":[{"id":"1.195453772","rc":[{"atl":[[240,4.72]],"id":28506637}],"con":true,"img":false}]}
{"op":"mcm","clk":"5353436017","pt":1646214921939,"mc":[{"id":"1.195453772","rc":[{"atl":[[6,3]],"id":43167135}],"con":true,"img":false}]}
{"op":"mcm","clk":"5353436025","pt":1646214922144,"mc":[{"id":"1.195453772","rc":[{"atb":[[4.3,0],[4.5,35.1]],"id":43167135},{"atl":[[6.4,0],[5.9,3],[6.2,0],[6,0]],"id":43167135}],"con":true,"img":false}]}
{"op":"mcm","clk":"5353436028","pt":1646214922248,"mc":[{"id":"1.195453772","rc":[{"atl":[[8.2,8],[8.4,2.7]],"id":43167135}],"con":true,"img":false}]}
{"op":"mcm","clk":"5353436191","pt":1646214925139,"mc":[{"id":"1.195453772","rc":[{"atl":[[8.8,0]],"id":43167135},{"atb":[[1.91,0]],"id":40120078},{"atl":[[130,2.72],[140,1.24]],"id":37260099}],"con":true,"img":false}]}
{"op":"mcm","clk":"5353436198","pt":1646214925236,"mc":[{"id":"1.195453772","rc":[{"atl":[[8.6,7.49]],"id":43167135},{"atb":[[1.96,60.61]],"id":40120078},{"atl":[[130,4.72]],"id":37260099}],"con":true,"img":false}]}
{"op":"mcm","clk":"5353436203","pt":1646214925339,"mc":[{"id":"1.195453772","rc":[{"atl":[[140,3.24],[150,0]],"id":37260099}],"con":true,"img":false}]}
{"op":"mcm","clk":"5353436207","pt":1646214925444,"mc":[{"id":"1.195453772","rc":[{"atl":[[130,2.72]],"id":37260099}],"con":true,"img":false}]}
{"op":"mcm","clk":"5353436273","pt":1646214927038,"mc":[{"id":"1.195453772","rc":[{"atl":[[140,2]],"id":37260099},{"atl":[[310,0]],"id":28506637}],"con":true,"img":false}]}
{"op":"mcm","clk":"5353436289","pt":1646214927348,"mc":[{"id":"1.195453772","rc":[{"atl":[[5.9,0]],"id":43167135}],"con":true,"img":false}]}
{"op":"mcm","clk":"5353436295","pt":1646214927453,"mc":[{"id":"1.195453772","rc":[{"atl":[[8.2,0],[8.4,13.7]],"id":43167135}],"con":true,"img":false}]}
{"op":"mcm","clk":"5353436538","pt":1646214932156,"mc":[{"id":"1.195453772","rc":[{"atb":[[4.3,15.15]],"id":43167135}],"con":true,"img":false}]}
{"op":"mcm","clk":"5353436550","pt":1646214932362,"mc":[{"id":"1.195453772","rc":[{"atb":[[4.3,6.06],[3.85,0],[4.5,29.39]],"id":43167135},{"atl":[[6.4,3]],"id":43167135},{"atl":[[3.1,9.52],[3.15,0]],"id":40120078}],"con":true,"img":false}]}
{"op":"mcm","clk":"5353436647","pt":1646214934477,"mc":[{"id":"1.195453772","rc":[{"atb":[[4.4,0]],"id":43167135}],"con":true,"img":false}]}
{"op":"mcm","clk":"5353436656","pt":1646214934633,"mc":[{"id":"1.195453772","rc":[{"atb":[[4.5,31.39]],"id":43167135}],"con":true,"img":false}]}
{"op":"mcm","clk":"5353436683","pt":1646214935154,"mc":[{"id":"1.195453772","rc":[{"atb":[[13.5,0]],"id":42077854}],"con":true,"img":false}]}
{"op":"mcm","clk":"5353436692","pt":1646214935299,"mc":[{"id":"1.195453772","rc":[{"atb":[[14,4.49]],"id":42077854}],"con":true,"img":false}]}
{"op":"mcm","clk":"5353436889","pt":1646214936959,"mc":[{"id":"1.195453772","rc":[{"atb":[[1.01,3.66]],"id":42860579}],"con":true,"img":false}]}
{"op":"mcm","clk":"5353436895","pt":1646214937061,"mc":[{"id":"1.195453772","rc":[{"atb":[[9.4,0]],"id":42860579}],"con":true,"img":false}]}
{"op":"mcm","clk":"5353436902","pt":1646214937165,"mc":[{"id":"1.195453772","rc":[{"atb":[[1.01,2.88]],"id":42860579}],"con":true,"img":false}]}
{"op":"mcm","clk":"5353436912","pt":1646214937371,"mc":[{"id":"1.195453772","rc":[{"atl":[[6.2,3]],"id":43167135},{"atl":[[3.1,0],[3.15,9.3]],"id":40120078},{"atl":[[170,0],[190,2]],"id":37260099},{"atl":[[44,0],[48,2.13]],"id":42077854},{"atb":[[1.01,2]],"id":42860579}],"con":true,"img":false}]}
{"op":"mcm","clk":"5353436918","pt":1646214937472,"mc":[{"id":"1.195453772","rc":[{"atb":[[9,0.88]],"id":42860579}],"con":true,"img":false}]}
{"op":"mcm","clk":"5353436944","pt":1646214937678,"mc":[{"id":"1.195453772","rc":[{"atb":[[9,0],[1.01,3.66]],"id":42860579}],"con":true,"img":false}]}
{"op":"mcm","clk":"5353436956","pt":1646214937885,"mc":[{"id":"1.195453772","rc":[{"atb":[[1.01,2.86]],"id":42860579}],"con":true,"img":false}]}
{"op":"mcm","clk":"5353436966","pt":1646214938042,"mc":[{"id":"1.195453772","rc":[{"atb":[[1.01,2]],"id":42860579}],"con":true,"img":false}]}
{"op":"mcm","clk":"5353436971","pt":1646214938144,"mc":[{"id":"1.195453772","rc":[{"atb":[[9.6,0.86]],"id":42860579}],"con":true,"img":false}]}
{"op":"mcm","clk":"5353437109","pt":1646214939287,"mc":[{"id":"1.195453772","rc":[{"atl":[[120,1.24]],"id":37260099},{"atl":[[230,1.48]],"id":28506637}],"con":true,"img":false}]}
{"op":"mcm","clk":"5353437114","pt":1646214939381,"mc":[{"id":"1.195453772","rc":[{"atl":[[230,3.48]],"id":28506637}],"con":true,"img":false}]}
{"op":"mcm","clk":"5353437118","pt":1646214939485,"mc":[{"id":"1.195453772","rc":[{"atl":[[140,0],[120,3.24]],"id":37260099},{"atl":[[220,2],[240,2.72],[250,0.53]],"id":28506637}],"con":true,"img":false}]}
{"op":"mcm","clk":"5353437285","pt":1646214942381,"mc":[{"id":"1.195453772","rc":[{"atb":[[3.85,43.86]],"id":43167135}],"con":true,"img":false}]}
{"op":"mcm","clk":"5353437297","pt":1646214942590,"mc":[{"id":"1.195453772","rc":[{"atl":[[6,4]],"id":43167135}],"con":true,"img":false}]}
{"op":"mcm","clk":"5353437301","pt":1646214942693,"mc":[{"id":"1.195453772","rc":[{"atb":[[4.3,0],[4.5,37.1]],"id":43167135},{"atl":[[6.4,0],[6.2,0]],"id":43167135}],"con":true,"img":false}]}
{"op":"mcm","clk":"5353437356","pt":1646214943678,"mc":[{"id":"1.195453772","rc":[{"atb":[[5.1,4]],"id":43167135},{"atl":[[2.34,2]],"id":40120078}],"con":true,"img":false}]}
{"op":"mcm","clk":"5353437362","pt":1646214943780,"mc":[{"id":"1.195453772","rc":[{"atl":[[8.4,11],[8.6,10.12],[6,0]],"id":43167135},{"atb":[[1.86,0]],"id":40120078}],"con":true,"img":false}]}
{"op":"mcm","clk":"5353437396","pt":1646214944400,"mc":[{"id":"1.195453772","rc":[{"atb":[[5.3,3],[5.1,0]],"id":43167135},{"atl":[[2.32,2]],"id":40120078},{"atb":[[4.9,5.13],[4.7,0]],"id":36500408},{"atl":[[34,0],[36,0],[38,2.7],[40,0]],"id":36500408},{"atb":[[6.4,0],[6.8,17.79],[6.2,0],[6.6,18.37]],"id":42860579},{"atl":[[17,4.49],[17.5,6.06]],"id":42860579},{"atb":[[4.3,0],[4.2,45.48]],"id":39786791},{"atl":[[7.2,4]],"id":39786791}],"con":true,"img":false}]}
{"op":"mcm","clk":"5353437405","pt":1646214944456,"mc":[{"id":"1.195453772","rc":[{"atl":[[17.5,0]],"id":42860579}],"con":true,"img":false}]}
{"op":"mcm","clk":"5353437411","pt":1646214944558,"mc":[{"id":"1.195453772","rc":[{"atl":[[18.5,8.57]],"id":42860579}],"con":true,"img":false}]}
{"op":"mcm","clk":"5353437459","pt":1646214945587,"mc":[{"id":"1.195453772","rc":[{"atb":[[6.4,0],[1.02,1.66]],"id":36500408}],"con":true,"img":false}]}
{"op":"mcm","clk":"5353437463","pt":1646214945698,"mc":[{"id":"1.195453772","rc":[{"atb":[[1.02,1.3]],"id":36500408}],"con":true,"img":false}]}
{"op":"mcm","clk":"5353437473","pt":1646214945897,"mc":[{"id":"1.195453772","rc":[{"atb":[[1.02,0]],"id":36500408}],"con":true,"img":false}]}
{"op":"mcm","clk":"5353437481","pt":1646214945952,"mc":[{"id":"1.195453772","rc":[{"atl":[[170,2],[190,0]],"id":37260099},{"atb":[[6,1.48]],"id":36500408},{"atl":[[44,2.33],[48,0]],"id":42077854}],"con":true,"img":false}]}
{"op":"mcm","clk":"5353437541","pt":1646214947299,"mc":[{"id":"1.195453772","rc":[{"spl":[[1.01,126.77]],"id":40120078}],"con":true,"img":false}]}
{"op":"mcm","clk":"5353437546","pt":1646214947403,"mc":[{"id":"1.195453772","rc":[{"atb":[[5.7,3]],"id":43167135},{"atb":[[1.81,61.73]],"id":40120078},{"atl":[[2.3,2]],"id":40120078},{"atb":[[16,0],[17,1.25]],"id":37260099},{"atb":[[2.4,58.57]],"id":36500408},{"atl":[[38,0]],"id":36500408},{"atb":[[22,4.89]],"id":28506637},{"atb":[[5.9,0],[6.2,3.85]],"id":42860579},{"atl":[[7.4,2]],"id":39786791}],"con":true,"img":false}]}
{"op":"mcm","clk":"5353437555","pt":1646214947505,"mc":[{"id":"1.195453772","rc":[{"atb":[[5.3,0]],"id":43167135},{"atl":[[8.6,23.28],[8.4,0]],"id":43167135},{"atl":[[3.2,36.92],[3.15,0]],"id":40120078},{"atl":[[170,0],[180,4.72]],"id":37260099},{"atb":[[2.92,46.3]],"id":36500408},{"atl":[[160,0],[12,2.51],[17,14.57]],"id":36500408},{"atb":[[23,1]],"id":28506637},{"atb":[[6.4,30.94],[7.4,0],[7.8,2.94],[5.7,0]],"id":42077854},{"atl":[[44,0],[46,2.22]],"id":42077854},{"atb":[[4.3,6.06],[4.2,39.23]],"id":39786791},{"atl":[[8,1.24],[8.2,2.78],[7.2,0]],"id":39786791}],"con":true,"img":false}]}
{"op":"mcm","clk":"5353437558","pt":1646214947560,"mc":[{"id":"1.195453772","rc":[{"atb":[[4.3,6.06],[5.8,4],[4.5,31.39]],"id":43167135},{"atl":[[8.6,20.65],[8.4,2.7]],"id":43167135},{"atl":[[3.2,27.83],[2.28,3],[3.15,9.3]],"id":40120078},{"atb":[[1.02,1.66],[6,0.17]],"id":36500408},{"atl":[[8,4.1],[8.2,0],[7.4,0]],"id":39786791}],"con":true,"img":false}]}
{"op":"mcm","clk":"5353437570","pt":1646214947766,"mc":[{"id":"1.195453772","rc":[{"atb":[[5.7,0]],"id":43167135},{"atb":[[1.02,1.26]],"id":36500408}],"con":true,"img":false}]}
{"op":"mcm","clk":"5353437576","pt":1646214947870,"mc":[{"id":"1.195453772","rc":[{"atb":[[1.02,0]],"id":36500408}],"con":true,"img":false}]}
{"op":"mcm","clk":"5353437583","pt":1646214947973,"mc":[{"id":"1.195453772","rc":[{"atb":[[6.6,1.26]],"id":36500408}],"con":true,"img":false}]}
{"op":"mcm","clk":"5353437649","pt":1646214949164,"mc":[{"id":"1.195453772","rc":[{"atb":[[5.8,0]],"id":43167135},{"trd":[[5.8,8]],"ltp":5.8,"tv":8.0,"id":43167135}],"con":true,"img":false}]}
{"op":"mcm","clk":"5353437655","pt":1646214949265,"mc":[{"id":"1.195453772","rc":[{"atb":[[4.5,29.39]],"id":43167135}],"con":true,"img":false}]}
{"op":"mcm","clk":"5353437674","pt":1646214949677,"mc":[{"id":"1.195453772","rc":[{"atb":[[4.7,15.79]],"id":39786791}],"con":true,"img":false}]}
{"op":"mcm","clk":"5353437679","pt":1646214949781,"mc":[{"id":"1.195453772","rc":[{"atb":[[4.8,4.75]],"id":39786791}],"con":true,"img":false}]}
{"op":"mcm","clk":"5353437694","pt":1646214949994,"mc":[{"id":"1.195453772","rc":[{"atb":[[1.01,4.52]],"id":43167135}],"con":true,"img":false}]}
{"op":"mcm","clk":"5353437705","pt":1646214950193,"mc":[{"id":"1.195453772","rc":[{"atb":[[1.01,4.1]],"id":43167135}],"con":true,"img":false}]}
{"op":"mcm","clk":"5353437715","pt":1646214950498,"mc":[{"id":"1.195453772","rc":[{"atb":[[1.01,2]],"id":43167135},{"atb":[[5.8,0.58]],"id":36500408}],"con":true,"img":false}]}
{"op":"mcm","clk":"5353437721","pt":1646214950602,"mc":[{"id":"1.195453772","rc":[{"atb":[[5.1,2.1]],"id":43167135}],"con":true,"img":false}]}
{"op":"mcm","clk":"5353437829","pt":1646214952670,"mc":[{"id":"1.195453772","rc":[{"atl":[[9,18.75]],"id":43167135}],"con":true,"img":false}]}
{"op":"mcm","clk":"5353437834","pt":1646214952773,"mc":[{"id":"1.195453772","rc":[{"atl":[[8.6,7.49]],"id":43167135}],"con":true,"img":false}]}
{"op":"mcm","clk":"5353437839","pt":1646214952878,"mc":[{"id":"1.195453772","rc":[{"atb":[[4.3,0],[4.5,34.76]],"id":43167135},{"atl":[[8.4,0],[8.6,10.12],[8.8,2.64]],"id":43167135},{"atb":[[5.8,25.59],[6.2,0]],"id":42860579},{"atl":[[12,2]],"id":42860579},{"atb":[[4.3,0],[4.2,45.48]],"id":39786791},{"atl":[[8,1.24],[8.2,2.78],[7.4,3]],"id":39786791}],"con":true,"img":false}]}
{"op":"mcm","clk":"5353437852","pt":1646214953086,"mc":[{"id":"1.195453772","rc":[{"atl":[[17,8.98],[18.5,2.86]],"id":42860579}],"con":true,"img":false}]}
{"op":"mcm","clk":"5353437926","pt":1646214954583,"mc":[{"id":"1.195453772","rc":[{"atb":[[1.86,129.27],[1.65,0]],"id":40120078},{"atl":[[130,0],[150,0.39]],"id":37260099},{"atb":[[11,0],[13.5,8.61]],"id":42077854},{"atb":[[6.8,0]],"id":42860579}],"con":true,"img":false}]}
{"op":"mcm","clk":"5353437933","pt":1646214954685,"mc":[{"id":"1.195453772","rc":[{"atb":[[7.8,25.28]],"id":42860579}],"con":true,"img":false}]}
{"op":"mcm","clk":"5353437964","pt":1646214955301,"mc":[{"id":"1.195453772","rc":[{"atl":[[19,0]],"id":42860579}],"con":true,"img":false}]}
{"op":"mcm","clk":"5353437970","pt":1646214955405,"mc":[{"id":"1.195453772","rc":[{"atl":[[18,2.92]],"id":42860579}],"con":true,"img":false}]}
{"op":"mcm","clk":"5353437998","pt":1646214955974,"mc":[{"id":"1.195453772","rc":[{"atb":[[2.92,0],[3.7,37.04]],"id":36500408},{"atl":[[14,7.65],[17,8.32]],"id":36500408}],"con":true,"img":false}]}
{"op":"mcm","clk":"5353438005","pt":1646214956080,"mc":[{"id":"1.195453772","rc":[{"atb":[[1.02,1.66]],"id":36500408}],"con":true,"img":false}]}
{"op":"mcm","clk":"5353438008","pt":1646214956180,"mc":[{"id":"1.195453772","rc":[{"atb":[[6.6,0]],"id":36500408}],"con":true,"img":false}]}
{"op":"mcm","clk":"5353438013","pt":1646214956284,"mc":[{"id":"1.195453772","rc":[{"atb":[[1.02,1.26]],"id":36500408}],"con":true,"img":false}]}
{"op":"mcm","clk":"5353438026","pt":1646214956489,"mc":[{"id":"1.195453772","rc":[{"atb":[[1.02,0]],"id":36500408}],"con":true,"img":false}]}
{"op":"mcm","clk":"5353438028","pt":1646214956592,"mc":[{"id":"1.195453772","rc":[{"atb":[[6,1.44]],"id":36500408}],"con":true,"img":false}]}
{"op":"mcm","clk":"5353438031","pt":1646214956695,"mc":[{"id":"1.195453772","rc":[{"atl":[[12,0]],"id":42860579},{"trd":[[12,4]],"ltp":12.0,"tv":4.0,"id":42860579}],"con":true,"img":false}]}
{"op":"mcm","clk":"5353438038","pt":1646214956797,"mc":[{"id":"1.195453772","rc":[{"atb":[[8.8,4.73]],"id":42860579}],"con":true,"img":false}]}
{"op":"mcm","clk":"5353438044","pt":1646214956900,"mc":[{"id":"1.195453772","rc":[{"atb":[[8.6,13.53]],"id":42860579}],"con":true,"img":false}]}
{"op":"mcm","clk":"5353438064","pt":1646214957219,"mc":[{"id":"1.195453772","rc":[{"atb":[[8.8,2.74]],"id":42860579}],"con":true,"img":false}]}
{"op":"mcm","clk":"5353438069","pt":1646214957265,"mc":[{"id":"1.195453772","rc":[{"atb":[[1.02,1.99]],"id":42860579}],"con":true,"img":false}]}
{"op":"mcm","clk":"5353438080","pt":1646214957368,"mc":[{"id":"1.195453772","rc":[{"atb":[[16,3.33]],"id":37260099},{"atb":[[4.7,13.51]],"id":36500408},{"atl":[[13,9.04]],"id":36500408},{"atb":[[7.4,7.81]],"id":42077854}],"con":true,"img":false}]}
{"op":"mcm","clk":"5353438090","pt":1646214957573,"mc":[{"id":"1.195453772","rc":[{"atb":[[1.79,94.94]],"id":40120078}],"con":true,"img":false}]}
{"op":"mcm","clk":"5353438292","pt":1646214961200,"mc":[{"id":"1.195453772","rc":[{"atl":[[8.6,20.24],[9,6.25]],"id":43167135}],"con":true,"img":false}]}
{"op":"mcm","clk":"5353438304","pt":1646214961407,"mc":[{"id":"1.195453772","rc":[{"atb":[[4.1,0]],"id":36500408},{"atl":[[220,0]],"id":36500408},{"atb":[[6.4,17.05],[6.8,0],[6,16.4]],"id":42077854},{"atb":[[4.4,29.41],[5,0]],"id":42860579},{"atl":[[17,4.49],[19,5.56]],"id":42860579},{"atb":[[4.3,6.06],[4.2,39.23]],"id":39786791},{"atl":[[8,4.1],[8.2,0],[7.4,0],[7.2,4]],"id":39786791}],"con":true,"img":false}]}
{"op":"mcm","clk":"5353438310","pt":1646214961512,"mc":[{"id":"1.195453772","rc":[{"atb":[[12.5,0],[13.5,0],[14.5,0]],"id":37260099}],"con":true,"img":false}]}
{"op":"mcm","clk":"5353438362","pt":1646214962289,"mc":[{"id":"1.195453772","rc":[{"atb":[[1.01,4.52]],"id":42860579}],"con":true,"img":false}]}
{"op":"mcm","clk":"5353438371","pt":1646214962495,"mc":[{"id":"1.195453772","rc":[{"atb":[[1.01,3.68]],"id":42860579}],"con":true,"img":false}]}
{"op":"mcm","clk":"5353438384","pt":1646214962805,"mc":[{"id":"1.195453772","rc":[{"atb":[[1.01,2]],"id":42860579}],"con":true,"img":false}]}
{"op":"mcm","clk":"5353438393","pt":1646214962908,"mc":[{"id":"1.195453772","rc":[{"atb":[[4.3,14.24]],"id":43167135},{"atb":[[9,1.68],[5.6,10.87]],"id":42860579}],"con":true,"img":false}]}
{"op":"mcm","clk":"5353438432","pt":1646214963581,"mc":[{"id":"1.195453772","rc":[{"atl":[[12.5,0]],"id":36500408},{"atl":[[8,2.86]],"id":39786791}],"con":true,"img":false}]}
{"op":"mcm","clk":"5353438440","pt":1646214963684,"mc":[{"id":"1.195453772","rc":[{"atl":[[1000,1.24]],"id":43167135},{"atl":[[120,2]],"id":37260099},{"atl":[[230,2.24]],"id":28506637}],"con":true,"img":false}]}
{"op":"mcm","clk":"5353438446","pt":1646214963786,"mc":[{"id":"1.195453772","rc":[{"atl":[[170,2]],"id":37260099},{"atl":[[230,4.24]],"id":28506637}],"con":true,"img":false}]}
{"op":"mcm","clk":"5353438453","pt":1646214963890,"mc":[{"id":"1.195453772","rc":[{"atl":[[1000,0]],"id":43167135},{"atl":[[120,0]],"id":37260099},{"atl":[[220,0]],"id":28506637}],"con":true,"img":false}]}
{"op":"mcm","clk":"5353438457","pt":1646214963989,"mc":[{"id":"1.195453772","rc":[{"atl":[[8.4,1.24]],"id":43167135}],"con":true,"img":false}]}
{"op":"mcm","clk":"5353438614","pt":1646214967097,"mc":[{"id":"1.195453772","rc":[{"atb":[[1.01,3.66],[9.6,0]],"id":42860579}],"con":true,"img":false}]}
{"op":"mcm","clk":"5353438621","pt":1646214967296,"mc":[{"id":"1.195453772","rc":[{"atb":[[3.85,0]],"id":43167135},{"atl":[[8.6,10.12],[8.8,12.82]],"id":43167135},{"atl":[[180,2.72],[190,2]],"id":37260099},{"atl":[[14,0],[14.5,7.41]],"id":36500408},{"atl":[[46,0],[48,2.13]],"id":42077854},{"atb":[[1.01,2.86],[5.3,0],[5.5,0],[5.7,0]],"id":42860579},{"atl":[[19,0],[20,11.62]],"id":42860579},{"atl":[[7.2,0]],"id":39786791}],"con":true,"img":false}]}
{"op":"mcm","clk":"5353438627","pt":1646214967397,"mc":[{"id":"1.195453772","rc":[{"atb":[[15,5.36]],"id":37260099},{"atl":[[170,0],[180,4.72]],"id":37260099},{"atb":[[4.5,29.39]],"id":36500408},{"atb":[[7,12.5]],"id":42077854},{"atb":[[1.01,2]],"id":42860579}],"con":true,"img":false}]}
{"op":"mcm","clk":"5353438631","pt":1646214967503,"mc":[{"id":"1.195453772","rc":[{"atb":[[4.5,50.82]],"id":36500408},{"atl":[[14,5.77]],"id":36500408},{"atb":[[9.2,0.86]],"id":42860579}],"con":true,"img":false}]}
{"op":"mcm","clk":"5353438637","pt":1646214967604,"mc":[{"id":"1.195453772","rc":[{"atb":[[1.77,162.34]],"id":40120078}],"con":true,"img":false}]}
{"op":"mcm","clk":"5353438863","pt":1646214972925,"mc":[{"id":"1.195453772","rc":[{"atb":[[4.1,22.74]],"id":43167135},{"atb":[[5.4,17.05]],"id":42860579}],"con":true,"img":false}]}
{"op":"mcm","clk":"5353438874","pt":1646214973231,"mc":[{"id":"1.195453772","rc":[{"atl":[[200,0]],"id":36500408},{"atl":[[8,0],[8.2,2.78]],"id":39786791}],"con":true,"img":false}]}
{"op":"mcm","clk":"5353438966","pt":1646214975193,"mc":[{"id":"1.195453772","rc":[{"spn":4.86,"spf":1.0,"id":43167135},{"spn":2.0,"spf":1.0,"id":40120078},{"spn":25.58,"spf":1.0,"id":37260099},{"spn":5.66,"spf":1.0,"id":36500408},{"spn":32.14,"spf":1.0,"id":28506637},{"spn":15.08,"spf":1.0,"id":42077854},{"spn":8.36,"spf":1.0,"id":42860579},{"atl":[[9.8,0]],"id":39786791},{"spn":4.69,"spf":1.0,"id":39786791}],"con":true,"img":false}]}
{"op":"mcm","clk":"5353438971","pt":1646214975295,"mc":[{"id":"1.195453772","rc":[{"atl":[[9,6.15]],"id":39786791}],"con":true,"img":false}]}
{"op":"mcm","clk":"5353438983","pt":1646214975709,"mc":[{"id":"1.195453772","rc":[{"atl":[[170,1.24]],"id":37260099},{"atl":[[1000,1.24]],"id":36500408}],"con":true,"img":false}]}
{"op":"mcm","clk":"5353438995","pt":1646214975913,"mc":[{"id":"1.195453772","rc":[{"atl":[[1000,0]],"id":36500408}],"con":true,"img":false}]}
{"op":"mcm","clk":"5353439000","pt":1646214976016,"mc":[{"id":"1.195453772","rc":[{"atl":[[11.5,1.24]],"id":36500408}],"con":true,"img":false}]}
{"op":"mcm","clk":"5353439078","pt":1646214977414,"mc":[{"id":"1.195453772","rc":[{"atb":[[14,15.16]],"id":37260099},{"atb":[[4.3,37.88]],"id":36500408},{"atl":[[15,8.93]],"id":36500408},{"atb":[[6.6,22.32]],"id":42077854}],"con":true,"img":false}]}
{"op":"mcm","clk":"5353439297","pt":1646214982905,"mc":[{"id":"1.195453772","rc":[{"atb":[[3.95,39.82]],"id":43167135},{"atb":[[5.2,29.76]],"id":42860579}],"con":true,"img":false}]}
{"op":"mcm","clk":"5353439310","pt":1646214983211,"mc":[{"id":"1.195453772","rc":[{"atl":[[180,0]],"id":36500408},{"atl":[[8.6,6.58]],"id":39786791}],"con":true,"img":false}]}
{"op":"mcm","clk":"5353439411","pt":1646214985222,"mc":[{"id":"1.195453772","rc":[{"atb":[[4,34.29],[4.2,0]],"id":43167135},{"atl":[[240,0]],"id":28506637},{"atl":[[60,0]],"id":42077854}],"con":true,"img":false}]}
{"op":"mcm","clk":"5353439417","pt":1646214985324,"mc":[{"id":"1.195453772","rc":[{"atb":[[4.4,18.85],[4.1,64]],"id":43167135},{"atl":[[300,2.44],[220,2.72]],"id":28506637},{"atl":[[46,2.72]],"id":42077854}],"con":true,"img":false}]}
{"op":"mcm","clk":"5353439420","pt":1646214985428,"mc":[{"id":"1.195453772","rc":[{"atl":[[300,0.44],[220,4.72],[230,2.24]],"id":28506637}],"con":true,"img":false}]}
{"op":"mcm","clk":"5353439426","pt":1646214985535,"mc":[{"id":"1.195453772","rc":[{"atl":[[210,2]],"id":28506637}],"con":true,"img":false}]}
{"op":"mcm","clk":"5353439430","pt":1646214985636,"mc":[{"id":"1.195453772","rc":[{"atl":[[230,0.24]],"id":28506637}],"con":true,"img":false}]}
{"op":"mcm","clk":"5353439433","pt":1646214985739,"mc":[{"id":"1.195453772","rc":[{"atl":[[210,0]],"id":28506637}],"con":true,"img":false}]}
{"op":"mcm","clk":"5353439438","pt":1646214985842,"mc":[{"id":"1.195453772","rc":[{"atl":[[210,2]],"id":28506637}],"con":true,"img":false}]}
{"op":"mcm","clk":"5353439559","pt":1646214987907,"mc":[{"id":"1.195453772","rc":[{"atl":[[200,1.24]],"id":28506637}],"con":true,"img":false}]}
{"op":"mcm","clk":"5353439566","pt":1646214988011,"mc":[{"id":"1.195453772","rc":[{"atl":[[200,3.24],[220,2.72]],"id":28506637}],"con":true,"img":false}]}
{"op":"mcm","clk":"5353439583","pt":1646214988218,"mc":[{"id":"1.195453772","rc":[{"atl":[[9.2,0],[8.4,0],[8.8,0]],"id":39786791}],"con":true,"img":false}]}
{"op":"mcm","clk":"5353439594","pt":1646214988424,"mc":[{"id":"1.195453772","rc":[{"atb":[[18.5,0],[1.04,2.25]],"id":42077854}],"con":true,"img":false}]}
{"op":"mcm","clk":"5353439601","pt":1646214988630,"mc":[{"id":"1.195453772","rc":[{"atb":[[1.04,0.19]],"id":42077854}],"con":true,"img":false}]}
{"op":"mcm","clk":"5353439614","pt":1646214988939,"mc":[{"id":"1.195453772","rc":[{"atb":[[1.04,0]],"id":42077854}],"con":true,"img":false}]}
{"op":"mcm","clk":"5353439619","pt":1646214989044,"mc":[{"id":"1.195453772","rc":[{"atb":[[19.5,0.19]],"id":42077854}],"con":true,"img":false}]}
{"op":"mcm","clk":"5353439707","pt":1646214990650,"mc":[{"id":"1.195453772","rc":[{"atl":[[190,2]],"id":28506637}],"con":true,"img":false}]}
{"op":"mcm","clk":"5353439714","pt":1646214990753,"mc":[{"id":"1.195453772","rc":[{"atl":[[210,0]],"id":28506637}],"con":true,"img":false}]}
{"op":"mcm","clk":"5353439848","pt":1646214993231,"mc":[{"id":"1.195453772","rc":[{"atl":[[9,15.53]],"id":39786791}],"con":true,"img":false}]}
{"op":"mcm","clk":"5353439953","pt":1646214995247,"mc":[{"id":"1.195453772","rc":[{"atl":[[220,0]],"id":28506637}],"con":true,"img":false}]}
{"op":"mcm","clk":"5353439961","pt":1646214995352,"mc":[{"id":"1.195453772","rc":[{"atl":[[240,2.72]],"id":28506637}],"con":true,"img":false}]}
{"op":"mcm","clk":"5353440047","pt":1646214997061,"mc":[{"id":"1.195453772","rc":[{"atl":[[1000,1.66]],"id":43167135},{"atb":[[1.02,1.66],[6,0.17]],"id":36500408},{"atb":[[19,0],[1.02,1.66]],"id":42077854}],"con":true,"img":false}]}
{"op":"mcm","clk":"5353440055","pt":1646214997113,"mc":[{"id":"1.195453772","rc":[{"atl":[[1000,1.66]],"id":42860579}],"con":true,"img":false}]}
{"op":"mcm","clk":"5353440061","pt":1646214997320,"mc":[{"id":"1.195453772","rc":[{"atl":[[1000,1.01]],"id":43167135},{"atb":[[1.02,1.3]],"id":36500408},{"atb":[[1.02,0.41]],"id":42077854},{"atl":[[1000,0.5]],"id":42860579}],"con":true,"img":false}]}
{"op":"mcm","clk":"5353440068","pt":1646214997528,"mc":[{"id":"1.195453772","rc":[{"atl":[[1000,0]],"id":42860579}],"con":true,"img":false}]}
{"op":"mcm","clk":"5353440075","pt":1646214997631,"mc":[{"id":"1.195453772","rc":[{"atl":[[16.5,0.5]],"id":42860579}],"con":true,"img":false}]}
{"op":"mcm","clk":"5353440084","pt":1646214997838,"mc":[{"id":"1.195453772","rc":[{"atb":[[1.02,0]],"id":42077854}],"con":true,"img":false}]}
{"op":"mcm","clk":"5353440091","pt":1646214997941,"mc":[{"id":"1.195453772","rc":[{"atb":[[20,0.41]],"id":42077854}],"con":true,"img":false}]}
{"op":"mcm","clk":"5353440103","pt":1646214998148,"mc":[{"id":"1.195453772","rc":[{"atl":[[1000,0]],"id":43167135}],"con":true,"img":false}]}
{"op":"mcm","clk":"5353440107","pt":1646214998251,"mc":[{"id":"1.195453772","rc":[{"atl":[[8.2,1.01]],"id":43167135}],"con":true,"img":false}]}
{"op":"mcm","clk":"5353440117","pt":1646214998458,"mc":[{"id":"1.195453772","rc":[{"atl":[[8.4,4]],"id":43167135},{"atb":[[1.02,0]],"id":36500408}],"con":true,"img":false}]}
{"op":"mcm","clk":"5353440123","pt":1646214998560,"mc":[{"id":"1.195453772","rc":[{"atb":[[6.4,1.3]],"id":36500408}],"con":true,"img":false}]}
{"op":"mcm","clk":"5353440129","pt":1646214998662,"mc":[{"id":"1.195453772","rc":[{"atb":[[6.4,0],[1.02,1.66]],"id":36500408}],"con":true,"img":false}]}
{"op":"mcm","clk":"5353440139","pt":1646214998818,"mc":[{"id":"1.195453772","rc":[{"atb":[[1.02,1.3]],"id":36500408}],"con":true,"img":false}]}
{"op":"mcm","clk":"5353440143","pt":1646214998922,"mc":[{"id":"1.195453772","rc":[{"atb":[[1.02,0]],"id":36500408}],"con":true,"img":false}]}
{"op":"mcm","clk":"5353440149","pt":1646214999023,"mc":[{"id":"1.195453772","rc":[{"atb":[[6,1.48]],"id":36500408}],"con":true,"img":false}]}
{"op":"mcm","clk":"5353440370","pt":1646215003260,"mc":[{"id":"1.195453772","rc":[{"atl":[[9.4,14.88]],"id":39786791}],"con":true,"img":false}]}
{"op":"mcm","clk":"5353440381","pt":1646215003465,"mc":[{"id":"1.195453772","rc":[{"atb":[[1.02,1.66]],"id":36500408}],"con":true,"img":false}]}
{"op":"mcm","clk":"5353440385","pt":1646215003568,"mc":[{"id":"1.195453772","rc":[{"atb":[[6,0.17]],"id":36500408}],"con":true,"img":false}]}
{"op":"mcm","clk":"5353440391","pt":1646215003671,"mc":[{"id":"1.195453772","rc":[{"atb":[[1.02,1.3]],"id":36500408}],"con":true,"img":false}]}
{"op":"mcm","clk":"5353440400","pt":1646215003825,"mc":[{"id":"1.195453772","rc":[{"atb":[[1.02,0]],"id":36500408}],"con":true,"img":false}]}
{"op":"mcm","clk":"5353440405","pt":1646215003927,"mc":[{"id":"1.195453772","rc":[{"atb":[[6.4,1.3]],"id":36500408}],"con":true,"img":false}]}
{"op":"mcm","clk":"5353440461","pt":1646215005165,"mc":[{"id":"1.195453772","rc":[{"atl":[[13.5,9.48]],"id":36500408}],"con":true,"img":false}]}
{"op":"mcm","clk":"5353440466","pt":1646215005268,"mc":[{"id":"1.195453772","rc":[{"atl":[[16.5,0]],"id":36500408}],"con":true,"img":false}]}
{"op":"mcm","clk":"5353440797","pt":1646215011839,"mc":[{"id":"1.195453772","rc":[{"atl":[[8.4,14.12],[8.8,0]],"id":43167135},{"atl":[[180,6.72],[190,0]],"id":37260099},{"atl":[[13.5,16.89],[14.5,0]],"id":36500408},{"atl":[[46,4.94],[48,0]],"id":42077854},{"atl":[[19,5.56],[20,6.36]],"id":42860579}],"con":true,"img":false}]}
{"op":"mcm","clk":"5353440805","pt":1646215011942,"mc":[{"id":"1.195453772","rc":[{"atb":[[6.4,0],[1.02,1.66]],"id":36500408}],"con":true,"img":false}]}
{"op":"mcm","clk":"5353440816","pt":1646215012151,"mc":[{"id":"1.195453772","rc":[{"atl":[[8.4,11.36]],"id":43167135},{"atb":[[1.02,1.3]],"id":36500408}],"con":true,"img":false}]}
{"op":"mcm","clk":"5353440830","pt":1646215012356,"mc":[{"id":"1.195453772","rc":[{"atb":[[1.02,0]],"id":36500408},{"atl":[[200,2]],"id":28506637}],"con":true,"img":false}]}
{"op":"mcm","clk":"5353440839","pt":1646215012459,"mc":[{"id":"1.195453772","rc":[{"atb":[[6,1.48]],"id":36500408},{"atl":[[190,0],[200,4],[230,2.24]],"id":28506637}],"con":true,"img":false}]}
{"op":"mcm","clk":"5353440848","pt":1646215012564,"mc":[{"id":"1.195453772","rc":[{"atb":[[1.02,1.66]],"id":36500408},{"atl":[[200,0],[240,4.72]],"id":28506637}],"con":true,"img":false}]}
{"op":"mcm","clk":"5353440858","pt":1646215012668,"mc":[{"id":"1.195453772","rc":[{"atb":[[6,0.17]],"id":36500408},{"atl":[[200,2]],"id":28506637}],"con":true,"img":false}]}
{"op":"mcm","clk":"5353440865","pt":1646215012772,"mc":[{"id":"1.195453772","rc":[{"atb":[[1.02,1.3]],"id":36500408},{"atl":[[200,0]],"id":28506637}],"con":true,"img":false}]}
{"op":"mcm","clk":"5353440880","pt":1646215012929,"mc":[{"id":"1.195453772","rc":[{"atb":[[1.02,0]],"id":36500408}],"con":true,"img":false}]}
{"op":"mcm","clk":"5353440887","pt":1646215013031,"mc":[{"id":"1.195453772","rc":[{"atb":[[6.4,1.3]],"id":36500408}],"con":true,"img":false}]}
{"op":"mcm","clk":"5353441032","pt":1646215015164,"mc":[{"id":"1.195453772","rc":[{"atl":[[180,4]],"id":37260099},{"atl":[[9,9.38]],"id":39786791}],"con":true,"img":false}]}
{"op":"mcm","clk":"5353441038","pt":1646215015265,"mc":[{"id":"1.195453772","rc":[{"atl":[[160,2.72]],"id":37260099},{"atl":[[9.2,6.15]],"id":39786791}],"con":true,"img":false}]}
{"op":"mcm","clk":"5353441043","pt":1646215015369,"mc":[{"id":"1.195453772","rc":[{"atl":[[160,4.72],[180,2]],"id":37260099}],"con":true,"img":false}]}
{"op":"mcm","clk":"5353441119","pt":1646215017075,"mc":[{"id":"1.195453772","rc":[{"atl":[[13.5,9.48],[14,13.46]],"id":36500408}],"con":true,"img":false}]}
{"op":"mcm","clk":"5353441524","pt":1646215024586,"mc":[{"id":"1.195453772","rc":[{"atl":[[220,1.24]],"id":28506637}],"con":true,"img":false}]}
{"op":"mcm","clk":"5353441534","pt":1646215024743,"mc":[{"id":"1.195453772","rc":[{"atb":[[1.02,1.66]],"id":36500408},{"atl":[[220,3.24],[240,2.72]],"id":28506637}],"con":true,"img":false}]}
{"op":"mcm","clk":"5353441537","pt":1646215024846,"mc":[{"id":"1.195453772","rc":[{"atb":[[6.4,0]],"id":36500408},{"atl":[[210,2]],"id":28506637}],"con":true,"img":false}]}
{"op":"mcm","clk":"5353441541","pt":1646215024948,"mc":[{"id":"1.195453772","rc":[{"atb":[[1.02,1.3]],"id":36500408},{"atl":[[210,0],[230,0.24]],"id":28506637}],"con":true,"img":false}]}
{"op":"mcm","clk":"5353441545","pt":1646215025052,"mc":[{"id":"1.195453772","rc":[{"atl":[[210,2]],"id":28506637}],"con":true,"img":false}]}
{"op":"mcm","clk":"5353441550","pt":1646215025155,"mc":[{"id":"1.195453772","rc":[{"atb":[[1.02,0]],"id":36500408}],"con":true,"img":false}]}
{"op":"mcm","clk":"5353441555","pt":1646215025258,"mc":[{"id":"1.195453772","rc":[{"atb":[[6,1.48]],"id":36500408}],"con":true,"img":false}]}
{"op":"mcm","clk":"5353441559","pt":1646215025359,"mc":[{"id":"1.195453772","rc":[{"atb":[[1.02,1.66],[6,0.17]],"id":36500408}],"con":true,"img":false}]}
{"op":"mcm","clk":"5353441566","pt":1646215025566,"mc":[{"id":"1.195453772","rc":[{"atb":[[1.02,1.3]],"id":36500408}],"con":true,"img":false}]}
{"op":"mcm","clk":"5353441580","pt":1646215025773,"mc":[{"id":"1.195453772","rc":[{"atb":[[1.02,0]],"id":36500408}],"con":true,"img":false}]}
{"op":"mcm","clk":"5353441588","pt":1646215025875,"mc":[{"id":"1.195453772","rc":[{"atb":[[6.4,1.3]],"id":36500408}],"con":true,"img":false}]}
{"op":"mcm","clk":"5353442019","pt":1646215035280,"mc":[{"id":"1.195453772","rc":[{"atl":[[8.6,2.63]],"id":43167135},{"spn":5.68,"spf":1.0,"id":36500408},{"spn":15.1,"spf":1.0,"id":42077854}],"con":true,"img":false}]}
{"op":"mcm","clk":"5353442022","pt":1646215035384,"mc":[{"id":"1.195453772","rc":[{"atl":[[8.2,8.51]],"id":43167135}],"con":true,"img":false}]}
{"op":"mcm","clk":"5353442070","pt":1646215036572,"mc":[{"id":"1.195453772","rc":[{"atl":[[8.4,10.12]],"id":43167135}],"con":true,"img":false}]}
{"op":"mcm","clk":"5353442752","pt":1646215049189,"mc":[{"id":"1.195453772","rc":[{"atl":[[1000,1.24]],"id":43167135}],"con":true,"img":false}]}
{"op":"mcm","clk":"5353442756","pt":1646215049292,"mc":[{"id":"1.195453772","rc":[{"atl":[[220,2]],"id":28506637}],"con":true,"img":false}]}
{"op":"mcm","clk":"5353442762","pt":1646215049395,"mc":[{"id":"1.195453772","rc":[{"atl":[[1000,0]],"id":43167135},{"atl":[[210,0],[230,2.24]],"id":28506637}],"con":true,"img":false}]}
{"op":"mcm","clk":"5353442769","pt":1646215049498,"mc":[{"id":"1.195453772","rc":[{"atl":[[8,1.24]],"id":43167135}],"con":true,"img":false}]}
{"op":"mcm","clk":"5353443083","pt":1646215054619,"mc":[{"id":"1.195453772","rc":[{"atl":[[220,0],[230,4.24]],"id":28506637}],"con":true,"img":false}]}
{"op":"mcm","clk":"5353443091","pt":1646215054722,"mc":[{"id":"1.195453772","rc":[{"atl":[[230,2.24],[240,4.72]],"id":28506637}],"con":true,"img":false}]}
{"op":"mcm","clk":"5353443095","pt":1646215054824,"mc":[{"id":"1.195453772","rc":[{"atl":[[8.2,11.34]],"id":43167135}],"con":true,"img":false}]}
{"op":"mcm","clk":"5353443277","pt":1646215057513,"mc":[{"id":"1.195453772","rc":[{"atl":[[2.28,2.32]],"id":40120078},{"trd":[[2.28,1.36]],"ltp":2.28,"tv":1.36,"id":40120078}],"con":true,"img":false}]}
{"op":"mcm","clk":"5353443292","pt":1646215057719,"mc":[{"id":"1.195453772","rc":[{"atl":[[2.3,0],[2.32,0],[2.34,0],[2.28,0]],"id":40120078}],"con":true,"img":false}]}
{"op":"mcm","clk":"5353444311","pt":1646215077685,"mc":[{"id":"1.195453772","rc":[{"atb":[[3.75,0],[4,0],[4.5,5.37],[5,0]],"id":43167135},{"atl":[[16,8.2],[18.5,0],[22,0],[27,0]],"id":43167135},{"atb":[[2,0],[1.85,0],[1.95,0],[1.9,0]],"id":40120078},{"atl":[[5.6,0],[5.1,0],[4.6,0],[6.2,0]],"id":40120078},{"atb":[[34,0],[18.5,0],[22,0],[27,0]],"id":37260099},{"atl":[[250,0],[300,0],[350,0],[400,0]],"id":37260099},{"atb":[[4,0],[4.5,21.43],[5,0],[5.5,0]],"id":36500408},{"atl":[[17,0],[19.5,0],[24,8.2],[29,0]],"id":36500408},{"atb":[[34,0],[18.5,0],[22,0],[27,0]],"id":28506637},{"atl":[[300,0],[350,0],[400,0],[250,0]],"id":28506637},{"atb":[[10.5,0],[13,0],[15.5,0.7],[18,0]],"id":42077854},{"atl":[[130,0],[280,0],[180,0],[230,1]],"id":42077854},{"atb":[[5.8,4.17],[8.6,0],[7.6,0],[6.6,0]],"id":42860579},{"atl":[[36,0],[46,0],[65,0],[90,0]],"id":42860579},{"atb":[[3.8,44.64],[3.55,0],[4.6,0],[4.1,0]],"id":39786791},{"atl":[[14.5,0],[17,0],[19.5,8.2],[24,0]],"id":39786791}],"con":true,"img":false}]}
{"op":"mcm","clk":"5353444317","pt":1646215077839,"mc":[{"id":"1.195453772","rc":[{"atb":[[5.9,2]],"id":42860579}],"con":true,"img":false}]}
{"op":"mcm","clk":"5353444328","pt":1646215077940,"mc":[{"id":"1.195453772","rc":[{"atl":[[13.5,17.48],[14,5.77]],"id":36500408}],"con":true,"img":false}]}
{"op":"mcm","clk":"5353444378","pt":1646215079124,"mc":[{"id":"1.195453772","rc":[{"atb":[[5.1,0]],"id":43167135}],"con":true,"img":false}]}
{"op":"mcm","clk":"5353444398","pt":1646215079536,"mc":[{"id":"1.195453772","rc":[{"atb":[[1.04,1.66]],"id":40120078}],"con":true,"img":false}]}
{"op":"mcm","clk":"5353444401","pt":1646215079636,"mc":[{"id":"1.195453772","rc":[{"atb":[[2.1,0]],"id":40120078}],"con":true,"img":false}]}
{"op":"mcm","clk":"5353444406","pt":1646215079738,"mc":[{"id":"1.195453772","rc":[{"atb":[[1.04,1.65]],"id":40120078}],"con":true,"img":false}]}
{"op":"mcm","clk":"5353444413","pt":1646215079944,"mc":[{"id":"1.195453772","rc":[{"atb":[[1.01,4.52]],"id":43167135},{"atb":[[1.04,0]],"id":40120078}],"con":true,"img":false}]}
{"op":"mcm","clk":"5353444419","pt":1646215080047,"mc":[{"id":"1.195453772","rc":[{"atb":[[1.99,1.65]],"id":40120078}],"con":true,"img":false}]}
{"op":"mcm","clk":"5353444426","pt":1646215080150,"mc":[{"id":"1.195453772","rc":[{"atb":[[1.01,4.1]],"id":43167135},{"atb":[[9.2,1.32]],"id":42860579},{"atl":[[16.5,0.77]],"id":42860579}],"con":true,"img":false}]}
{"op":"mcm","clk":"5353444431","pt":1646215080253,"mc":[{"id":"1.195453772","rc":[{"atl":[[1000,1.66]],"id":43167135},{"atl":[[1000,1.66]],"id":40120078},{"atl":[[1000,1.66]],"id":37260099},{"atl":[[1000,1.66]],"id":36500408},{"atl":[[1000,1.66]],"id":28506637},{"atl":[[1000,1.66]],"id":42077854},{"atb":[[9.2,3.32]],"id":42860579},{"atl":[[1000,1.66]],"id":42860579},{"atl":[[1000,1.66]],"id":39786791}],"con":true,"img":false}]}
{"op":"mcm","clk":"5353444438","pt":1646215080357,"mc":[{"id":"1.195453772","rc":[{"atb":[[1.01,2]],"id":43167135},{"atb":[[8.8,0.74]],"id":42860579}],"con":true,"img":false}]}
{"op":"mcm","clk":"5353444442","pt":1646215080459,"mc":[{"id":"1.195453772","rc":[{"atb":[[4.6,2.1]],"id":43167135},{"atl":[[1000,0.83]],"id":43167135},{"atl":[[1000,0.83]],"id":40120078},{"atl":[[1000,0.83]],"id":37260099},{"atl":[[1000,0.83]],"id":36500408},{"atl":[[1000,0.83]],"id":28506637},{"atl":[[1000,0.83]],"id":42077854},{"atb":[[9.2,1.32]],"id":42860579},{"atl":[[1000,0.83]],"id":42860579},{"atl":[[1000,0.83]],"id":39786791}],"con":true,"img":false}]}
{"op":"mcm","clk":"5353444451","pt":1646215080562,"mc":[{"id":"1.195453772","rc":[{"atb":[[9.2,3.32]],"id":42860579}],"con":true,"img":false}]}
{"op":"mcm","clk":"5353444458","pt":1646215080665,"mc":[{"id":"1.195453772","rc":[{"atl":[[1000,0]],"id":43167135},{"atl":[[1000,0]],"id":40120078},{"atl":[[1000,0]],"id":37260099},{"atl":[[1000,0]],"id":36500408},{"atl":[[1000,0]],"id":28506637},{"atl":[[1000,0]],"id":42077854},{"atl":[[1000,0]],"id":42860579},{"atl":[[1000,0]],"id":39786791}],"con":true,"img":false}]}
{"op":"mcm","clk":"5353444469","pt":1646215080771,"mc":[{"id":"1.195453772","rc":[{"atl":[[8,2.07]],"id":43167135},{"atl":[[2.44,0.83]],"id":40120078},{"atl":[[150,1.22]],"id":37260099},{"atl":[[11.5,2.07]],"id":36500408},{"atl":[[220,0.83]],"id":28506637},{"atl":[[40,2.07]],"id":42077854},{"atl":[[16.5,1.61]],"id":42860579},{"atl":[[8,0.83]],"id":39786791}],"con":true,"img":false}]}
{"op":"mcm","clk":"5353444483","pt":1646215080930,"mc":[{"id":"1.195453772","rc":[{"atb":[[9,0]],"id":42860579}],"con":true,"img":false}]}
{"op":"mcm","clk":"5353444518","pt":1646215081549,"mc":[{"id":"1.195453772","rc":[{"atb":[[4.7,1]],"id":43167135},{"atb":[[2.18,1]],"id":40120078},{"atb":[[6,1.17]],"id":36500408},{"atb":[[4.9,1.21]],"id":39786791}],"con":true,"img":false}]}
{"op":"mcm","clk":"5353444526","pt":1646215081653,"mc":[{"id":"1.195453772","rc":[{"atb":[[2.18,1.21]],"id":40120078},{"atl":[[2.44,1.02]],"id":40120078}],"con":true,"img":false}]}
{"op":"mcm","clk":"5353444533","pt":1646215081757,"mc":[{"id":"1.195453772","rc":[{"atb":[[6.4,0],[1.02,1.66]],"id":36500408}],"con":true,"img":false}]}
{"op":"mcm","clk":"5353444545","pt":1646215081964,"mc":[{"id":"1.195453772","rc":[{"atb":[[1.02,1.3]],"id":36500408}],"con":true,"img":false}]}
{"op":"mcm","clk":"5353444552","pt":1646215082068,"mc":[{"id":"1.195453772","rc":[{"atb":[[2.16,0]],"id":40120078},{"atb":[[1.01,4.52]],"id":42860579}],"con":true,"img":false}]}
{"op":"mcm","clk":"5353444559","pt":1646215082174,"mc":[{"id":"1.195453772","rc":[{"atb":[[1.02,0]],"id":36500408}],"con":true,"img":false}]}
{"op":"mcm","clk":"5353444565","pt":1646215082278,"mc":[{"id":"1.195453772","rc":[{"atb":[[3.75,37.4],[4,34.29],[4.5,34.76],[5,25.71]],"id":43167135},{"atl":[[16,17.07],[18.5,7.61],[22,9.51],[27,7.68]],"id":43167135},{"atb":[[2,102.86],[1.85,121.02],[1.95,108.27],[1.9,114.29]],"id":40120078},{"atl":[[5.6,43.43],[5.1,32.48],[4.6,36.99],[6.2,38.42]],"id":40120078},{"atb":[[34,3.11],[18.5,5.88],[22,4.89],[27,3.95]],"id":37260099},{"atl":[[250,0.53],[300,0.44],[350,0.57],[400,0.5]],"id":37260099},{"atb":[[4,34.29],[4.5,50.82],[5,25.71],[6.2,1.74],[5.5,22.85]],"id":36500408},{"atl":[[17,8.32],[19.5,7.19],[24,16.88],[29,7.13]],"id":36500408},{"atb":[[34,3.11],[18.5,5.88],[22,4.89],[27,3.95]],"id":28506637},{"atl":[[300,0.44],[350,0.57],[400,0.5],[250,0.53]],"id":28506637},{"atb":[[10.5,10.82],[13,8.57],[15.5,7.79],[18,6.04]],"id":42077854},{"atl":[[130,1.03],[280,0.71],[180,0.74],[230,1.87]],"id":42077854},{"atb":[[1.01,3.68],[5.8,25.59],[8.6,13.53],[7.6,15.58],[6.6,18.37]],"id":42860579},{"atl":[[36,3.8],[46,2.95],[65,3.12],[90,2.24]],"id":42860579},{"atb":[[3.8,81.37],[3.55,40.34],[4.6,28.57],[4.1,33.18]],"id":39786791},{"atl":[[14.5,9.86],[17,8.32],[19.5,19],[24,8.68]],"id":39786791}],"con":true,"img":false}]}
{"op":"mcm","clk":"5353444581","pt":1646215082441,"mc":[{"id":"1.195453772","rc":[{"atb":[[6.2,0.44],[1.02,1.66]],"id":36500408},{"atb":[[1.01,2]],"id":42860579}],"con":true,"img":false}]}
{"op":"mcm","clk":"5353444592","pt":1646215082538,"mc":[{"id":"1.195453772","rc":[{"atb":[[4.7,0]],"id":43167135},{"atb":[[2.18,0.21]],"id":40120078},{"atb":[[1.02,1.26],[6,0.17]],"id":36500408},{"atb":[[9.4,1.68]],"id":42860579}],"con":true,"img":false}]}
{"op":"mcm","clk":"5353444600","pt":1646215082644,"mc":[{"id":"1.195453772","rc":[{"atb":[[5.1,1]],"id":43167135},{"atb":[[1.9,125.24],[2.16,1]],"id":40120078},{"atb":[[6.4,1],[5.9,0],[1.02,0]],"id":36500408},{"atb":[[9.4,2.13]],"id":42860579}],"con":true,"img":false}]}
{"op":"mcm","clk":"5353444611","pt":1646215082746,"mc":[{"id":"1.195453772","rc":[{"atb":[[6.2,2.43],[6.6,1.26]],"id":36500408}],"con":true,"img":false}]}
{"op":"mcm","clk":"5353444625","pt":1646215082953,"mc":[{"id":"1.195453772","rc":[{"atl":[[13.5,9.48],[14,13.46]],"id":36500408},{"atl":[[8,3.69],[8.2,0]],"id":39786791}],"con":true,"img":false}]}
{"op":"mcm","clk":"5353444628","pt":1646215083055,"mc":[{"id":"1.195453772","rc":[{"atb":[[2.18,4.42]],"id":40120078}],"con":true,"img":false}]}
{"op":"mcm","clk":"5353444653","pt":1646215083467,"mc":[{"id":"1.195453772","rc":[{"spb":[[1000,32.63]],"id":37260099},{"atb":[[6.2,0.44]],"id":36500408}],"con":true,"img":false}]}
{"op":"mcm","clk":"5353444657","pt":1646215083569,"mc":[{"id":"1.195453772","rc":[{"atb":[[6.6,3.25]],"id":36500408}],"con":true,"img":false}]}
{"op":"mcm","clk":"5353444667","pt":1646215083674,"mc":[{"id":"1.195453772","rc":[{"atb":[[2.16,0]],"id":40120078}],"con":true,"img":false}]}
{"op":"mcm","clk":"5353444675","pt":1646215083773,"mc":[{"id":"1.195453772","rc":[{"atb":[[2.2,1]],"id":40120078}],"con":true,"img":false}]}
{"op":"mcm","clk":"5353444684","pt":1646215083947,"mc":[{"id":"1.195453772","rc":[{"atb":[[2.2,1.22]],"id":40120078}],"con":true,"img":false}]}
{"op":"mcm","clk":"5353444730","pt":1646215084650,"mc":[{"id":"1.195453772","rc":[{"atb":[[6.4,0]],"id":36500408}],"con":true,"img":false}]}
{"op":"mcm","clk":"5353444735","pt":1646215084752,"mc":[{"id":"1.195453772","rc":[{"atb":[[6.8,1]],"id":36500408}],"con":true,"img":false}]}
{"op":"mcm","clk":"5353444862","pt":1646215087378,"mc":[{"id":"1.195453772","rc":[{"atb":[[1.9,114.29]],"id":40120078}],"con":true,"img":false}]}
{"op":"mcm","clk":"5353444869","pt":1646215087538,"mc":[{"id":"1.195453772","rc":[{"atb":[[4.6,0]],"id":43167135}],"con":true,"img":false}]}
{"op":"mcm","clk":"5353444877","pt":1646215087642,"mc":[{"id":"1.195453772","rc":[{"atl":[[240,2]],"id":28506637}],"con":true,"img":false}]}
{"op":"mcm","clk":"5353444883","pt":1646215087745,"mc":[{"id":"1.195453772","rc":[{"atl":[[220,3.55]],"id":28506637}],"con":true,"img":false}]}
{"op":"mcm","clk":"5353444888","pt":1646215087844,"mc":[{"id":"1.195453772","rc":[{"atl":[[210,4],[230,0.24],[240,0]],"id":28506637}],"con":true,"img":false}]}
{"op":"mcm","clk":"5353444897","pt":1646215088051,"mc":[{"id":"1.195453772","rc":[{"atl":[[8.2,21.46]],"id":43167135},{"atl":[[220,2.72]],"id":28506637}],"con":true,"img":false}]}
{"op":"mcm","clk":"5353444905","pt":1646215088153,"mc":[{"id":"1.195453772","rc":[{"atl":[[8.4,0]],"id":43167135},{"atl":[[200,0.83]],"id":28506637}],"con":true,"img":false}]}
{"op":"mcm","clk":"5353444994","pt":1646215090474,"mc":[{"id":"1.195453772","rc":[{"atb":[[2.18,0.21]],"id":40120078}],"con":true,"img":false}]}
{"op":"mcm","clk":"5353445043","pt":1646215091559,"mc":[{"id":"1.195453772","rc":[{"atb":[[2.2,0.22]],"id":40120078}],"con":true,"img":false}]}
{"op":"mcm","clk":"5353445050","pt":1646215091661,"mc":[{"id":"1.195453772","rc":[{"atb":[[2.16,1]],"id":40120078}],"con":true,"img":false}]}
{"op":"mcm","clk":"5353445056","pt":1646215091764,"mc":[{"id":"1.195453772","rc":[{"atb":[[1.04,1.66]],"id":40120078}],"con":true,"img":false}]}
{"op":"mcm","clk":"5353445065","pt":1646215091867,"mc":[{"id":"1.195453772","rc":[{"atb":[[1.99,0]],"id":40120078}],"con":true,"img":false}]}
{"op":"mcm","clk":"5353445068","pt":1646215091970,"mc":[{"id":"1.195453772","rc":[{"atb":[[1.04,1.65]],"id":40120078}],"con":true,"img":false}]}
{"op":"mcm","clk":"5353445077","pt":1646215092177,"mc":[{"id":"1.195453772","rc":[{"atb":[[1.04,0]],"id":40120078}],"con":true,"img":false}]}
{"op":"mcm","clk":"5353445083","pt":1646215092280,"mc":[{"id":"1.195453772","rc":[{"atb":[[2.06,1.65],[2.18,4.42]],"id":40120078}],"con":true,"img":false}]}
