{"op":"mcm","clk":"5352092078","pt":1646182318996,"mc":[{"id":"1.195503868","marketDefinition":{"bspMarket":false,"turnInPlayEnabled":false,"persistenceEnabled":false,"marketBaseRate":7.0,"eventId":"31272499","eventTypeId":"4339","numberOfWinners":1,"bettingType":"ODDS","marketType":"EXACTA","marketTime":"2022-03-02T11:19:00.000Z","suspendTime":"2022-03-02T11:19:00.000Z","bspReconciled":false,"complete":true,"inPlay":false,"crossMatching":false,"runnersVoidable":false,"numberOfActiveRunners":56,"betDelay":0,"status":"OPEN","runners":[{"status":"ACTIVE","sortPriority":1,"id":41419585,"name":"1 - 2"},{"status":"ACTIVE","sortPriority":2,"id":41419586,"name":"1 - 3"},{"status":"ACTIVE","sortPriority":3,"id":41419587,"name":"1 - 4"},{"status":"ACTIVE","sortPriority":4,"id":41419588,"name":"1 - 5"},{"status":"ACTIVE","sortPriority":5,"id":41419589,"name":"1 - 6"},{"status":"ACTIVE","sortPriority":6,"id":41419590,"name":"1 - 7"},{"status":"ACTIVE","sortPriority":7,"id":28546943,"name":"1 - 9"},{"status":"ACTIVE","sortPriority":8,"id":41419592,"name":"2 - 1"},{"status":"ACTIVE","sortPriority":9,"id":41419593,"name":"2 - 3"},{"status":"ACTIVE","sortPriority":10,"id":41419594,"name":"2 - 4"},{"status":"ACTIVE","sortPriority":11,"id":41419595,"name":"2 - 5"},{"status":"ACTIVE","sortPriority":12,"id":41419596,"name":"2 - 6"},{"status":"ACTIVE","sortPriority":13,"id":41419597,"name":"2 - 7"},{"status":"ACTIVE","sortPriority":14,"id":41419651,"name":"2 - 9"},{"status":"ACTIVE","sortPriority":15,"id":41419599,"name":"3 - 1"},{"status":"ACTIVE","sortPriority":16,"id":41419600,"name":"3 - 2"},{"status":"ACTIVE","sortPriority":17,"id":41419601,"name":"3 - 4"},{"status":"ACTIVE","sortPriority":18,"id":41419602,"name":"3 - 5"},{"status":"ACTIVE","sortPriority":19,"id":41419603,"name":"3 - 6"},{"status":"ACTIVE","sortPriority":20,"id":41419604,"name":"3 - 7"},{"status":"ACTIVE","sortPriority":21,"id":41419652,"name":"3 - 9"},{"status":"ACTIVE","sortPriority":22,"id":41419606,"name":"4 - 1"},{"status":"ACTIVE","sortPriority":23,"id":41419607,"name":"4 - 2"},{"status":"ACTIVE","sortPriority":24,"id":41419608,"name":"4 - 3"},{"status":"ACTIVE","sortPriority":25,"id":41419609,"name":"4 - 5"},{"status":"ACTIVE","sortPriority":26,"id":41419610,"name":"4 - 6"},{"status":"ACTIVE","sortPriority":27,"id":41419611,"name":"4 - 7"},{"status":"ACTIVE","sortPriority":28,"id":41435525,"name":"4 - 9"},{"status":"ACTIVE","sortPriority":29,"id":41419613,"name":"5 - 1"},{"status":"ACTIVE","sortPriority":30,"id":41419614,"name":"5 - 2"},{"status":"ACTIVE","sortPriority":31,"id":41419615,"name":"5 - 3"},{"status":"ACTIVE","sortPriority":32,"id":41419616,"name":"5 - 4"},{"status":"ACTIVE","sortPriority":33,"id":41419617,"name":"5 - 6"},{"status":"ACTIVE","sortPriority":34,"id":41419618,"name":"5 - 7"},{"status":"ACTIVE","sortPriority":35,"id":41419653,"name":"5 - 9"},{"status":"ACTIVE","sortPriority":36,"id":41419620,"name":"6 - 1"},{"status":"ACTIVE","sortPriority":37,"id":41419621,"name":"6 - 2"},{"status":"ACTIVE","sortPriority":38,"id":41419622,"name":"6 - 3"},{"status":"ACTIVE","sortPriority":39,"id":41419623,"name":"6 - 4"},{"status":"ACTIVE","sortPriority":40,"id":41419624,"name":"6 - 5"},{"status":"ACTIVE","sortPriority":41,"id":41419625,"name":"6 - 7"},{"status":"ACTIVE","sortPriority":42,"id":41435526,"name":"6 - 9"},{"status":"ACTIVE","sortPriority":43,"id":41419627,"name":"7 - 1"},{"status":"ACTIVE","sortPriority":44,"id":41419628,"name":"7 - 2"},{"status":"ACTIVE","sortPriority":45,"id":41419629,"name":"7 - 3"},{"status":"ACTIVE","sortPriority":46,"id":41419630,"name":"7 - 4"},{"status":"ACTIVE","sortPriority":47,"id":41419631,"name":"7 - 5"},{"status":"ACTIVE","sortPriority":48,"id":41419632,"name":"7 - 6"},{"status":"ACTIVE","sortPriority":49,"id":41419654,"name":"7 - 9"},{"status":"ACTIVE","sortPriority":50,"id":28546950,"name":"9 - 1"},{"status":"ACTIVE","sortPriority":51,"id":41419656,"name":"9 - 2"},{"status":"ACTIVE","sortPriority":52,"id":41419657,"name":"9 - 3"},{"status":"ACTIVE","sortPriority":53,"id":41435527,"name":"9 - 4"},{"status":"ACTIVE","sortPriority":54,"id":41419658,"name":"9 - 5"},{"status":"ACTIVE","sortPriority":55,"id":41435528,"name":"9 - 6"},{"status":"ACTIVE","sortPriority":56,"id":41419659,"name":"9 - 7"}],"regulators":["MR_INT"],"venue":"Rockhampton","countryCode":"AU","discountAllowed":true,"timezone":"Australia/Queensland","openDate":"2022-03-02T08:34:00.000Z","version":4382565144,"name":"Exacta","eventName":"Rockhampton (AUS) 2nd Mar"},"rc":[],"con":true,"img":false}]}
{"op":"mcm","clk":"5352095669","pt":1646182412947,"mc":[{"id":"1.195503868","rc":[{"atb":[[18,11.73],[10.5,21],[8.2,36.96]],"id":41419609},{"atb":[[16.5,12.87],[11.5,25.34],[28,7.39]],"id":41419617},{"atb":[[11,19.95],[7.4,31.18],[5.7,56.62]],"id":41419613},{"atb":[[600,0.44],[700,0.28],[850,0.23]],"id":41419593},{"atb":[[32,6.44],[80,2.52],[21,13.3]],"id":41419622},{"atb":[[5.1,64.9],[9.2,24.34],[6.2,38.38]],"id":41419589},{"atb":[[44,4.64],[27,10.23],[120,1.67]],"id":41435527},{"atb":[[600,0.44],[700,0.28],[850,0.23]],"id":41419651},{"atb":[[16.5,12.87],[11.5,25.34],[28,7.39]],"id":41419618},{"atb":[[16,17.74],[44,4.64],[22,9.5]],"id":41419601},{"atb":[[9.2,32.45],[21,9.97],[13,16.63]],"id":41419630},{"atb":[[360,0.55],[210,0.95],[110,2.43]],"id":41419597},{"atb":[[38,5.39],[19.5,10.79],[14.5,19.71]],"id":28546943},{"atb":[[360,0.55],[210,0.95],[110,2.43]],"id":41419659},{"atb":[[7.2,32.19],[5.1,48.67],[4.1,85.84]],"id":41419606},{"atb":[[75,2.69],[20,14],[30,6.88]],"id":41419602},{"atb":[[38,5.39],[19.5,10.79],[14.5,19.71]],"id":41419585},{"atb":[[95,2.12],[48,5.66],[240,0.83]],"id":41419614},{"atb":[[19.5,10.79],[12,18.14],[8.8,34.11]],"id":41419610},{"atb":[[600,0.44],[700,0.28],[850,0.23]],"id":41419656},{"atb":[[9.2,32.45],[21,9.97],[13,16.63]],"id":41419623},{"atb":[[5.1,64.9],[9.2,24.34],[6.2,38.38]],"id":41419590},{"atb":[[600,0.44],[700,0.28],[850,0.23]],"id":41419652},{"atb":[[360,0.55],[210,0.95],[110,2.43]],"id":41435528},{"atb":[[9.2,32.45],[21,9.97],[13,16.63]],"id":41419586},{"atb":[[17,12.47],[12,24.19],[29,7.12]],"id":41419631},{"atb":[[6.4,49.28],[13.5,15.96],[8.4,26.97]],"id":41419627},{"atb":[[44,4.64],[27,10.23],[120,1.67]],"id":41419594},{"atb":[[34,6.04],[85,2.37],[22,12.67]],"id":41419607},{"atb":[[17.5,16.12],[50,4.07],[25,8.31]],"id":28546950},{"atb":[[36,5.7],[90,2.24],[23,12.09]],"id":41419603},{"atb":[[65,3.11],[19,14.78],[28,7.39]],"id":41419615},{"atb":[[19.5,10.79],[12,18.14],[8.8,34.11]],"id":41419611},{"atb":[[600,0.44],[700,0.28],[850,0.23]],"id":41419657},{"atb":[[17,12.47],[12,24.19],[29,7.12]],"id":41419624},{"atb":[[34,6.04],[85,2.37],[22,12.67]],"id":41435525},{"atb":[[95,2.12],[48,5.66],[240,0.83]],"id":41419653},{"atb":[[6.4,49.28],[13.5,15.96],[8.4,26.97]],"id":41419620},{"atb":[[5.6,43.39],[4.1,64.38],[3.55,104.36]],"id":41419587},{"atb":[[32,6.44],[18,11.73],[13,22.17]],"id":41419632},{"atb":[[16.5,12.87],[11.5,25.34],[28,7.39]],"id":41419599},{"atb":[[310,0.64],[160,1.25],[80,3.36]],"id":41419628},{"atb":[[140,1.43],[70,3.85],[290,0.69]],"id":41419595},{"atb":[[40,5.11],[20,10.5],[15,19]],"id":41419608},{"atb":[[36,5.7],[90,2.24],[23,12.09]],"id":41419604},{"atb":[[18.5,11.4],[11,19.95],[8.4,35.95]],"id":41419616},{"atb":[[32,6.44],[18,11.73],[13,22.17]],"id":41419625},{"atb":[[17.5,16.12],[50,4.07],[25,8.31]],"id":41419592},{"atb":[[310,0.64],[160,1.25],[80,3.36]],"id":41419654},{"atb":[[310,0.64],[160,1.25],[80,3.36]],"id":41435526},{"atb":[[310,0.64],[160,1.25],[80,3.36]],"id":41419621},{"atb":[[5.7,42.46],[8.4,26.97],[4.7,71.92]],"id":41419588},{"atb":[[600,0.44],[700,0.28],[850,0.23]],"id":41419600},{"atb":[[32,6.44],[80,2.52],[21,13.3]],"id":41419629},{"atb":[[360,0.55],[210,0.95],[110,2.43]],"id":41419596},{"atb":[[140,1.43],[70,3.85],[290,0.69]],"id":41419658}],"con":true,"img":false}]}
{"op":"mcm","clk":"5352146183","pt":1646183572645,"mc":[{"id":"1.195503868","marketDefinition":{"bspMarket":false,"turnInPlayEnabled":false,"persistenceEnabled":false,"marketBaseRate":7.0,"eventId":"31272499","eventTypeId":"4339","numberOfWinners":1,"bettingType":"ODDS","marketType":"EXACTA","marketTime":"2022-03-02T11:19:00.000Z","suspendTime":"2022-03-02T11:19:00.000Z","bspReconciled":false,"complete":true,"inPlay":false,"crossMatching":false,"runnersVoidable":false,"numberOfActiveRunners":56,"betDelay":0,"status":"OPEN","runners":[{"status":"ACTIVE","sortPriority":1,"id":41419585,"name":"1 - 2"},{"status":"ACTIVE","sortPriority":2,"id":41419586,"name":"1 - 3"},{"status":"ACTIVE","sortPriority":3,"id":41419587,"name":"1 - 4"},{"status":"ACTIVE","sortPriority":4,"id":41419588,"name":"1 - 5"},{"status":"ACTIVE","sortPriority":5,"id":41419589,"name":"1 - 6"},{"status":"ACTIVE","sortPriority":6,"id":41419590,"name":"1 - 7"},{"status":"ACTIVE","sortPriority":7,"id":28546943,"name":"1 - 9"},{"status":"ACTIVE","sortPriority":8,"id":41419592,"name":"2 - 1"},{"status":"ACTIVE","sortPriority":9,"id":41419593,"name":"2 - 3"},{"status":"ACTIVE","sortPriority":10,"id":41419594,"name":"2 - 4"},{"status":"ACTIVE","sortPriority":11,"id":41419595,"name":"2 - 5"},{"status":"ACTIVE","sortPriority":12,"id":41419596,"name":"2 - 6"},{"status":"ACTIVE","sortPriority":13,"id":41419597,"name":"2 - 7"},{"status":"ACTIVE","sortPriority":14,"id":41419651,"name":"2 - 9"},{"status":"ACTIVE","sortPriority":15,"id":41419599,"name":"3 - 1"},{"status":"ACTIVE","sortPriority":16,"id":41419600,"name":"3 - 2"},{"status":"ACTIVE","sortPriority":17,"id":41419601,"name":"3 - 4"},{"status":"ACTIVE","sortPriority":18,"id":41419602,"name":"3 - 5"},{"status":"ACTIVE","sortPriority":19,"id":41419603,"name":"3 - 6"},{"status":"ACTIVE","sortPriority":20,"id":41419604,"name":"3 - 7"},{"status":"ACTIVE","sortPriority":21,"id":41419652,"name":"3 - 9"},{"status":"ACTIVE","sortPriority":22,"id":41419606,"name":"4 - 1"},{"status":"ACTIVE","sortPriority":23,"id":41419607,"name":"4 - 2"},{"status":"ACTIVE","sortPriority":24,"id":41419608,"name":"4 - 3"},{"status":"ACTIVE","sortPriority":25,"id":41419609,"name":"4 - 5"},{"status":"ACTIVE","sortPriority":26,"id":41419610,"name":"4 - 6"},{"status":"ACTIVE","sortPriority":27,"id":41419611,"name":"4 - 7"},{"status":"ACTIVE","sortPriority":28,"id":41435525,"name":"4 - 9"},{"status":"ACTIVE","sortPriority":29,"id":41419613,"name":"5 - 1"},{"status":"ACTIVE","sortPriority":30,"id":41419614,"name":"5 - 2"},{"status":"ACTIVE","sortPriority":31,"id":41419615,"name":"5 - 3"},{"status":"ACTIVE","sortPriority":32,"id":41419616,"name":"5 - 4"},{"status":"ACTIVE","sortPriority":33,"id":41419617,"name":"5 - 6"},{"status":"ACTIVE","sortPriority":34,"id":41419618,"name":"5 - 7"},{"status":"ACTIVE","sortPriority":35,"id":41419653,"name":"5 - 9"},{"status":"ACTIVE","sortPriority":36,"id":41419620,"name":"6 - 1"},{"status":"ACTIVE","sortPriority":37,"id":41419621,"name":"6 - 2"},{"status":"ACTIVE","sortPriority":38,"id":41419622,"name":"6 - 3"},{"status":"ACTIVE","sortPriority":39,"id":41419623,"name":"6 - 4"},{"status":"ACTIVE","sortPriority":40,"id":41419624,"name":"6 - 5"},{"status":"ACTIVE","sortPriority":41,"id":41419625,"name":"6 - 7"},{"status":"ACTIVE","sortPriority":42,"id":41435526,"name":"6 - 9"},{"status":"ACTIVE","sortPriority":43,"id":41419627,"name":"7 - 1"},{"status":"ACTIVE","sortPriority":44,"id":41419628,"name":"7 - 2"},{"status":"ACTIVE","sortPriority":45,"id":41419629,"name":"7 - 3"},{"status":"ACTIVE","sortPriority":46,"id":41419630,"name":"7 - 4"},{"status":"ACTIVE","sortPriority":47,"id":41419631,"name":"7 - 5"},{"status":"ACTIVE","sortPriority":48,"id":41419632,"name":"7 - 6"},{"status":"ACTIVE","sortPriority":49,"id":41419654,"name":"7 - 9"},{"status":"ACTIVE","sortPriority":50,"id":28546950,"name":"9 - 1"},{"status":"ACTIVE","sortPriority":51,"id":41419656,"name":"9 - 2"},{"status":"ACTIVE","sortPriority":52,"id":41419657,"name":"9 - 3"},{"status":"ACTIVE","sortPriority":53,"id":41435527,"name":"9 - 4"},{"status":"ACTIVE","sortPriority":54,"id":41419658,"name":"9 - 5"},{"status":"ACTIVE","sortPriority":55,"id":41435528,"name":"9 - 6"},{"status":"ACTIVE","sortPriority":56,"id":41419659,"name":"9 - 7"}],"regulators":["MR_INT"],"venue":"Rockhampton","countryCode":"AU","discountAllowed":true,"timezone":"Australia/Queensland","openDate":"2022-03-02T08:28:00.000Z","version":4382597904,"name":"Exacta","eventName":"Rockhampton (AUS) 2nd Mar"},"rc":[],"con":true,"img":false}]}
{"op":"mcm","clk":"5352163211","pt":1646184024604,"mc":[{"id":"1.195503868","marketDefinition":{"bspMarket":false,"turnInPlayEnabled":false,"persistenceEnabled":false,"marketBaseRate":7.0,"eventId":"31272499","eventTypeId":"4339","numberOfWinners":1,"bettingType":"ODDS","marketType":"EXACTA","marketTime":"2022-03-02T11:09:00.000Z","suspendTime":"2022-03-02T11:09:00.000Z","bspReconciled":false,"complete":true,"inPlay":false,"crossMatching":false,"runnersVoidable":false,"numberOfActiveRunners":56,"betDelay":0,"status":"OPEN","runners":[{"status":"ACTIVE","sortPriority":1,"id":41419585,"name":"1 - 2"},{"status":"ACTIVE","sortPriority":2,"id":41419586,"name":"1 - 3"},{"status":"ACTIVE","sortPriority":3,"id":41419587,"name":"1 - 4"},{"status":"ACTIVE","sortPriority":4,"id":41419588,"name":"1 - 5"},{"status":"ACTIVE","sortPriority":5,"id":41419589,"name":"1 - 6"},{"status":"ACTIVE","sortPriority":6,"id":41419590,"name":"1 - 7"},{"status":"ACTIVE","sortPriority":7,"id":28546943,"name":"1 - 9"},{"status":"ACTIVE","sortPriority":8,"id":41419592,"name":"2 - 1"},{"status":"ACTIVE","sortPriority":9,"id":41419593,"name":"2 - 3"},{"status":"ACTIVE","sortPriority":10,"id":41419594,"name":"2 - 4"},{"status":"ACTIVE","sortPriority":11,"id":41419595,"name":"2 - 5"},{"status":"ACTIVE","sortPriority":12,"id":41419596,"name":"2 - 6"},{"status":"ACTIVE","sortPriority":13,"id":41419597,"name":"2 - 7"},{"status":"ACTIVE","sortPriority":14,"id":41419651,"name":"2 - 9"},{"status":"ACTIVE","sortPriority":15,"id":41419599,"name":"3 - 1"},{"status":"ACTIVE","sortPriority":16,"id":41419600,"name":"3 - 2"},{"status":"ACTIVE","sortPriority":17,"id":41419601,"name":"3 - 4"},{"status":"ACTIVE","sortPriority":18,"id":41419602,"name":"3 - 5"},{"status":"ACTIVE","sortPriority":19,"id":41419603,"name":"3 - 6"},{"status":"ACTIVE","sortPriority":20,"id":41419604,"name":"3 - 7"},{"status":"ACTIVE","sortPriority":21,"id":41419652,"name":"3 - 9"},{"status":"ACTIVE","sortPriority":22,"id":41419606,"name":"4 - 1"},{"status":"ACTIVE","sortPriority":23,"id":41419607,"name":"4 - 2"},{"status":"ACTIVE","sortPriority":24,"id":41419608,"name":"4 - 3"},{"status":"ACTIVE","sortPriority":25,"id":41419609,"name":"4 - 5"},{"status":"ACTIVE","sortPriority":26,"id":41419610,"name":"4 - 6"},{"status":"ACTIVE","sortPriority":27,"id":41419611,"name":"4 - 7"},{"status":"ACTIVE","sortPriority":28,"id":41435525,"name":"4 - 9"},{"status":"ACTIVE","sortPriority":29,"id":41419613,"name":"5 - 1"},{"status":"ACTIVE","sortPriority":30,"id":41419614,"name":"5 - 2"},{"status":"ACTIVE","sortPriority":31,"id":41419615,"name":"5 - 3"},{"status":"ACTIVE","sortPriority":32,"id":41419616,"name":"5 - 4"},{"status":"ACTIVE","sortPriority":33,"id":41419617,"name":"5 - 6"},{"status":"ACTIVE","sortPriority":34,"id":41419618,"name":"5 - 7"},{"status":"ACTIVE","sortPriority":35,"id":41419653,"name":"5 - 9"},{"status":"ACTIVE","sortPriority":36,"id":41419620,"name":"6 - 1"},{"status":"ACTIVE","sortPriority":37,"id":41419621,"name":"6 - 2"},{"status":"ACTIVE","sortPriority":38,"id":41419622,"name":"6 - 3"},{"status":"ACTIVE","sortPriority":39,"id":41419623,"name":"6 - 4"},{"status":"ACTIVE","sortPriority":40,"id":41419624,"name":"6 - 5"},{"status":"ACTIVE","sortPriority":41,"id":41419625,"name":"6 - 7"},{"status":"ACTIVE","sortPriority":42,"id":41435526,"name":"6 - 9"},{"status":"ACTIVE","sortPriority":43,"id":41419627,"name":"7 - 1"},{"status":"ACTIVE","sortPriority":44,"id":41419628,"name":"7 - 2"},{"status":"ACTIVE","sortPriority":45,"id":41419629,"name":"7 - 3"},{"status":"ACTIVE","sortPriority":46,"id":41419630,"name":"7 - 4"},{"status":"ACTIVE","sortPriority":47,"id":41419631,"name":"7 - 5"},{"status":"ACTIVE","sortPriority":48,"id":41419632,"name":"7 - 6"},{"status":"ACTIVE","sortPriority":49,"id":41419654,"name":"7 - 9"},{"status":"ACTIVE","sortPriority":50,"id":28546950,"name":"9 - 1"},{"status":"ACTIVE","sortPriority":51,"id":41419656,"name":"9 - 2"},{"status":"ACTIVE","sortPriority":52,"id":41419657,"name":"9 - 3"},{"status":"ACTIVE","sortPriority":53,"id":41435527,"name":"9 - 4"},{"status":"ACTIVE","sortPriority":54,"id":41419658,"name":"9 - 5"},{"status":"ACTIVE","sortPriority":55,"id":41435528,"name":"9 - 6"},{"status":"ACTIVE","sortPriority":56,"id":41419659,"name":"9 - 7"}],"regulators":["MR_INT"],"venue":"Rockhampton","countryCode":"AU","discountAllowed":true,"timezone":"Australia/Queensland","openDate":"2022-03-02T08:28:00.000Z","version":4382605979,"name":"Exacta","eventName":"Rockhampton (AUS) 2nd Mar"},"rc":[],"con":true,"img":false}]}
{"op":"mcm","clk":"5352239446","pt":1646185602749,"mc":[{"id":"1.195503868","marketDefinition":{"bspMarket":false,"turnInPlayEnabled":false,"persistenceEnabled":false,"marketBaseRate":7.0,"eventId":"31272499","eventTypeId":"4339","numberOfWinners":1,"bettingType":"ODDS","marketType":"EXACTA","marketTime":"2022-03-02T11:09:00.000Z","suspendTime":"2022-03-02T11:09:00.000Z","bspReconciled":false,"complete":true,"inPlay":false,"crossMatching":false,"runnersVoidable":false,"numberOfActiveRunners":56,"betDelay":0,"status":"OPEN","runners":[{"status":"ACTIVE","sortPriority":1,"id":41419585,"name":"1 - 2"},{"status":"ACTIVE","sortPriority":2,"id":41419586,"name":"1 - 3"},{"status":"ACTIVE","sortPriority":3,"id":41419587,"name":"1 - 4"},{"status":"ACTIVE","sortPriority":4,"id":41419588,"name":"1 - 5"},{"status":"ACTIVE","sortPriority":5,"id":41419589,"name":"1 - 6"},{"status":"ACTIVE","sortPriority":6,"id":41419590,"name":"1 - 7"},{"status":"ACTIVE","sortPriority":7,"id":28546943,"name":"1 - 9"},{"status":"ACTIVE","sortPriority":8,"id":41419592,"name":"2 - 1"},{"status":"ACTIVE","sortPriority":9,"id":41419593,"name":"2 - 3"},{"status":"ACTIVE","sortPriority":10,"id":41419594,"name":"2 - 4"},{"status":"ACTIVE","sortPriority":11,"id":41419595,"name":"2 - 5"},{"status":"ACTIVE","sortPriority":12,"id":41419596,"name":"2 - 6"},{"status":"ACTIVE","sortPriority":13,"id":41419597,"name":"2 - 7"},{"status":"ACTIVE","sortPriority":14,"id":41419651,"name":"2 - 9"},{"status":"ACTIVE","sortPriority":15,"id":41419599,"name":"3 - 1"},{"status":"ACTIVE","sortPriority":16,"id":41419600,"name":"3 - 2"},{"status":"ACTIVE","sortPriority":17,"id":41419601,"name":"3 - 4"},{"status":"ACTIVE","sortPriority":18,"id":41419602,"name":"3 - 5"},{"status":"ACTIVE","sortPriority":19,"id":41419603,"name":"3 - 6"},{"status":"ACTIVE","sortPriority":20,"id":41419604,"name":"3 - 7"},{"status":"ACTIVE","sortPriority":21,"id":41419652,"name":"3 - 9"},{"status":"ACTIVE","sortPriority":22,"id":41419606,"name":"4 - 1"},{"status":"ACTIVE","sortPriority":23,"id":41419607,"name":"4 - 2"},{"status":"ACTIVE","sortPriority":24,"id":41419608,"name":"4 - 3"},{"status":"ACTIVE","sortPriority":25,"id":41419609,"name":"4 - 5"},{"status":"ACTIVE","sortPriority":26,"id":41419610,"name":"4 - 6"},{"status":"ACTIVE","sortPriority":27,"id":41419611,"name":"4 - 7"},{"status":"ACTIVE","sortPriority":28,"id":41435525,"name":"4 - 9"},{"status":"ACTIVE","sortPriority":29,"id":41419613,"name":"5 - 1"},{"status":"ACTIVE","sortPriority":30,"id":41419614,"name":"5 - 2"},{"status":"ACTIVE","sortPriority":31,"id":41419615,"name":"5 - 3"},{"status":"ACTIVE","sortPriority":32,"id":41419616,"name":"5 - 4"},{"status":"ACTIVE","sortPriority":33,"id":41419617,"name":"5 - 6"},{"status":"ACTIVE","sortPriority":34,"id":41419618,"name":"5 - 7"},{"status":"ACTIVE","sortPriority":35,"id":41419653,"name":"5 - 9"},{"status":"ACTIVE","sortPriority":36,"id":41419620,"name":"6 - 1"},{"status":"ACTIVE","sortPriority":37,"id":41419621,"name":"6 - 2"},{"status":"ACTIVE","sortPriority":38,"id":41419622,"name":"6 - 3"},{"status":"ACTIVE","sortPriority":39,"id":41419623,"name":"6 - 4"},{"status":"ACTIVE","sortPriority":40,"id":41419624,"name":"6 - 5"},{"status":"ACTIVE","sortPriority":41,"id":41419625,"name":"6 - 7"},{"status":"ACTIVE","sortPriority":42,"id":41435526,"name":"6 - 9"},{"status":"ACTIVE","sortPriority":43,"id":41419627,"name":"7 - 1"},{"status":"ACTIVE","sortPriority":44,"id":41419628,"name":"7 - 2"},{"status":"ACTIVE","sortPriority":45,"id":41419629,"name":"7 - 3"},{"status":"ACTIVE","sortPriority":46,"id":41419630,"name":"7 - 4"},{"status":"ACTIVE","sortPriority":47,"id":41419631,"name":"7 - 5"},{"status":"ACTIVE","sortPriority":48,"id":41419632,"name":"7 - 6"},{"status":"ACTIVE","sortPriority":49,"id":41419654,"name":"7 - 9"},{"status":"ACTIVE","sortPriority":50,"id":28546950,"name":"9 - 1"},{"status":"ACTIVE","sortPriority":51,"id":41419656,"name":"9 - 2"},{"status":"ACTIVE","sortPriority":52,"id":41419657,"name":"9 - 3"},{"status":"ACTIVE","sortPriority":53,"id":41435527,"name":"9 - 4"},{"status":"ACTIVE","sortPriority":54,"id":41419658,"name":"9 - 5"},{"status":"ACTIVE","sortPriority":55,"id":41435528,"name":"9 - 6"},{"status":"ACTIVE","sortPriority":56,"id":41419659,"name":"9 - 7"}],"regulators":["MR_INT"],"venue":"Rockhampton","countryCode":"AU","discountAllowed":true,"timezone":"Australia/Queensland","openDate":"2022-03-02T08:28:00.000Z","version":4382605979,"name":"Exacta","eventName":"Rockhampton (AUS) 2nd Mar"},"rc":[{"atb":[[18,11.75],[10.5,21.04],[8.2,37.01]],"id":41419609},{"atb":[[16.5,12.89],[11.5,25.38],[28,7.4]],"id":41419617},{"atb":[[11,19.99],[7.4,31.23],[5.7,56.7]],"id":41419613},{"atb":[[600,0.44],[700,0.28],[850,0.23]],"id":41419593},{"atb":[[32,6.45],[80,2.53],[21,13.32]],"id":41419622},{"atb":[[5.1,65],[9.2,24.37],[6.2,38.44]],"id":41419589},{"atb":[[44,4.65],[27,10.25],[120,1.67]],"id":41435527},{"atb":[[600,0.44],[700,0.28],[850,0.23]],"id":41419651},{"atb":[[16.5,12.89],[11.5,25.38],[28,7.4]],"id":41419618},{"atb":[[16,17.77],[44,4.65],[22,9.52]],"id":41419601},{"atb":[[9.2,32.5],[21,9.99],[13,16.65]],"id":41419630},{"atb":[[360,0.55],[210,0.95],[110,2.44]],"id":41419597},{"atb":[[38,5.4],[19.5,10.8],[14.5,19.74]],"id":28546943},{"atb":[[360,0.55],[210,0.95],[110,2.44]],"id":41419659},{"atb":[[7.2,32.24],[5.1,48.75],[4.1,85.98]],"id":41419606},{"atb":[[75,2.69],[20,14.03],[30,6.89]],"id":41419602},{"atb":[[38,5.4],[19.5,10.8],[14.5,19.74]],"id":41419585},{"atb":[[95,2.12],[48,5.67],[240,0.83]],"id":41419614},{"atb":[[19.5,10.8],[12,18.17],[8.8,34.17]],"id":41419610},{"atb":[[600,0.44],[700,0.28],[850,0.23]],"id":41419656},{"atb":[[9.2,32.5],[21,9.99],[13,16.65]],"id":41419623},{"atb":[[5.1,65],[9.2,24.37],[6.2,38.44]],"id":41419590},{"atb":[[600,0.44],[700,0.28],[850,0.23]],"id":41419652},{"atb":[[360,0.55],[210,0.95],[110,2.44]],"id":41435528},{"atb":[[9.2,32.5],[21,9.99],[13,16.65]],"id":41419586},{"atb":[[17,12.49],[12,24.23],[29,7.13]],"id":41419631},{"atb":[[6.4,49.35],[13.5,15.99],[8.4,27.01]],"id":41419627},{"atb":[[44,4.65],[27,10.25],[120,1.67]],"id":41419594},{"atb":[[34,6.05],[85,2.37],[22,12.69]],"id":41419607},{"atb":[[17.5,16.15],[50,4.07],[25,8.32]],"id":28546950},{"atb":[[36,5.7],[90,2.24],[23,12.11]],"id":41419603},{"atb":[[65,3.12],[19,14.8],[28,7.4]],"id":41419615},{"atb":[[19.5,10.8],[12,18.17],[8.8,34.17]],"id":41419611},{"atb":[[600,0.44],[700,0.28],[850,0.23]],"id":41419657},{"atb":[[17,12.49],[12,24.23],[29,7.13]],"id":41419624},{"atb":[[34,6.05],[85,2.37],[22,12.69]],"id":41435525},{"atb":[[95,2.12],[48,5.67],[240,0.83]],"id":41419653},{"atb":[[6.4,49.35],[13.5,15.99],[8.4,27.01]],"id":41419620},{"atb":[[5.6,43.45],[4.1,64.48],[3.55,104.52]],"id":41419587},{"atb":[[32,6.45],[18,11.75],[13,22.2]],"id":41419632},{"atb":[[16.5,12.89],[11.5,25.38],[28,7.4]],"id":41419599},{"atb":[[310,0.64],[160,1.25],[80,3.37]],"id":41419628},{"atb":[[140,1.43],[70,3.86],[290,0.69]],"id":41419595},{"atb":[[40,5.12],[20,10.51],[15,19.03]],"id":41419608},{"atb":[[36,5.7],[90,2.24],[23,12.11]],"id":41419604},{"atb":[[18.5,11.42],[11,19.99],[8.4,36.01]],"id":41419616},{"atb":[[32,6.45],[18,11.75],[13,22.2]],"id":41419625},{"atb":[[17.5,16.15],[50,4.07],[25,8.32]],"id":41419592},{"atb":[[310,0.64],[160,1.25],[80,3.37]],"id":41419654},{"atb":[[310,0.64],[160,1.25],[80,3.37]],"id":41435526},{"atb":[[310,0.64],[160,1.25],[80,3.37]],"id":41419621},{"atb":[[5.7,42.53],[8.4,27.01],[4.7,72.03]],"id":41419588},{"atb":[[600,0.44],[700,0.28],[850,0.23]],"id":41419600},{"atb":[[32,6.45],[80,2.53],[21,13.32]],"id":41419629},{"atb":[[360,0.55],[210,0.95],[110,2.44]],"id":41419596},{"atb":[[140,1.43],[70,3.86],[290,0.69]],"id":41419658}],"con":true,"img":true}]}
{"op":"mcm","clk":"5352466733","pt":1646191002692,"mc":[{"id":"1.195503868","marketDefinition":{"bspMarket":false,"turnInPlayEnabled":false,"persistenceEnabled":false,"marketBaseRate":7.0,"eventId":"31272499","eventTypeId":"4339","numberOfWinners":1,"bettingType":"ODDS","marketType":"EXACTA","marketTime":"2022-03-02T11:09:00.000Z","suspendTime":"2022-03-02T11:09:00.000Z","bspReconciled":false,"complete":true,"inPlay":false,"crossMatching":false,"runnersVoidable":false,"numberOfActiveRunners":56,"betDelay":0,"status":"OPEN","runners":[{"status":"ACTIVE","sortPriority":1,"id":41419585,"name":"1 - 2"},{"status":"ACTIVE","sortPriority":2,"id":41419586,"name":"1 - 3"},{"status":"ACTIVE","sortPriority":3,"id":41419587,"name":"1 - 4"},{"status":"ACTIVE","sortPriority":4,"id":41419588,"name":"1 - 5"},{"status":"ACTIVE","sortPriority":5,"id":41419589,"name":"1 - 6"},{"status":"ACTIVE","sortPriority":6,"id":41419590,"name":"1 - 7"},{"status":"ACTIVE","sortPriority":7,"id":28546943,"name":"1 - 9"},{"status":"ACTIVE","sortPriority":8,"id":41419592,"name":"2 - 1"},{"status":"ACTIVE","sortPriority":9,"id":41419593,"name":"2 - 3"},{"status":"ACTIVE","sortPriority":10,"id":41419594,"name":"2 - 4"},{"status":"ACTIVE","sortPriority":11,"id":41419595,"name":"2 - 5"},{"status":"ACTIVE","sortPriority":12,"id":41419596,"name":"2 - 6"},{"status":"ACTIVE","sortPriority":13,"id":41419597,"name":"2 - 7"},{"status":"ACTIVE","sortPriority":14,"id":41419651,"name":"2 - 9"},{"status":"ACTIVE","sortPriority":15,"id":41419599,"name":"3 - 1"},{"status":"ACTIVE","sortPriority":16,"id":41419600,"name":"3 - 2"},{"status":"ACTIVE","sortPriority":17,"id":41419601,"name":"3 - 4"},{"status":"ACTIVE","sortPriority":18,"id":41419602,"name":"3 - 5"},{"status":"ACTIVE","sortPriority":19,"id":41419603,"name":"3 - 6"},{"status":"ACTIVE","sortPriority":20,"id":41419604,"name":"3 - 7"},{"status":"ACTIVE","sortPriority":21,"id":41419652,"name":"3 - 9"},{"status":"ACTIVE","sortPriority":22,"id":41419606,"name":"4 - 1"},{"status":"ACTIVE","sortPriority":23,"id":41419607,"name":"4 - 2"},{"status":"ACTIVE","sortPriority":24,"id":41419608,"name":"4 - 3"},{"status":"ACTIVE","sortPriority":25,"id":41419609,"name":"4 - 5"},{"status":"ACTIVE","sortPriority":26,"id":41419610,"name":"4 - 6"},{"status":"ACTIVE","sortPriority":27,"id":41419611,"name":"4 - 7"},{"status":"ACTIVE","sortPriority":28,"id":41435525,"name":"4 - 9"},{"status":"ACTIVE","sortPriority":29,"id":41419613,"name":"5 - 1"},{"status":"ACTIVE","sortPriority":30,"id":41419614,"name":"5 - 2"},{"status":"ACTIVE","sortPriority":31,"id":41419615,"name":"5 - 3"},{"status":"ACTIVE","sortPriority":32,"id":41419616,"name":"5 - 4"},{"status":"ACTIVE","sortPriority":33,"id":41419617,"name":"5 - 6"},{"status":"ACTIVE","sortPriority":34,"id":41419618,"name":"5 - 7"},{"status":"ACTIVE","sortPriority":35,"id":41419653,"name":"5 - 9"},{"status":"ACTIVE","sortPriority":36,"id":41419620,"name":"6 - 1"},{"status":"ACTIVE","sortPriority":37,"id":41419621,"name":"6 - 2"},{"status":"ACTIVE","sortPriority":38,"id":41419622,"name":"6 - 3"},{"status":"ACTIVE","sortPriority":39,"id":41419623,"name":"6 - 4"},{"status":"ACTIVE","sortPriority":40,"id":41419624,"name":"6 - 5"},{"status":"ACTIVE","sortPriority":41,"id":41419625,"name":"6 - 7"},{"status":"ACTIVE","sortPriority":42,"id":41435526,"name":"6 - 9"},{"status":"ACTIVE","sortPriority":43,"id":41419627,"name":"7 - 1"},{"status":"ACTIVE","sortPriority":44,"id":41419628,"name":"7 - 2"},{"status":"ACTIVE","sortPriority":45,"id":41419629,"name":"7 - 3"},{"status":"ACTIVE","sortPriority":46,"id":41419630,"name":"7 - 4"},{"status":"ACTIVE","sortPriority":47,"id":41419631,"name":"7 - 5"},{"status":"ACTIVE","sortPriority":48,"id":41419632,"name":"7 - 6"},{"status":"ACTIVE","sortPriority":49,"id":41419654,"name":"7 - 9"},{"status":"ACTIVE","sortPriority":50,"id":28546950,"name":"9 - 1"},{"status":"ACTIVE","sortPriority":51,"id":41419656,"name":"9 - 2"},{"status":"ACTIVE","sortPriority":52,"id":41419657,"name":"9 - 3"},{"status":"ACTIVE","sortPriority":53,"id":41435527,"name":"9 - 4"},{"status":"ACTIVE","sortPriority":54,"id":41419658,"name":"9 - 5"},{"status":"ACTIVE","sortPriority":55,"id":41435528,"name":"9 - 6"},{"status":"ACTIVE","sortPriority":56,"id":41419659,"name":"9 - 7"}],"regulators":["MR_INT"],"venue":"Rockhampton","countryCode":"AU","discountAllowed":true,"timezone":"Australia/Queensland","openDate":"2022-03-02T08:28:00.000Z","version":4382605979,"name":"Exacta","eventName":"Rockhampton (AUS) 2nd Mar"},"rc":[{"atb":[[18,11.77],[10.5,21.07],[8.2,37.08]],"id":41419609},{"atb":[[16.5,12.91],[11.5,25.42],[28,7.41]],"id":41419617},{"atb":[[11,20.02],[7.4,31.28],[5.7,56.8]],"id":41419613},{"atb":[[600,0.44],[700,0.28],[850,0.23]],"id":41419593},{"atb":[[32,6.46],[80,2.53],[21,13.34]],"id":41419622},{"atb":[[5.1,65.11],[9.2,24.42],[6.2,38.5]],"id":41419589},{"atb":[[44,4.65],[27,10.26],[120,1.68]],"id":41435527},{"atb":[[600,0.44],[700,0.28],[850,0.23]],"id":41419651},{"atb":[[16.5,12.91],[11.5,25.42],[28,7.41]],"id":41419618},{"atb":[[16,17.8],[44,4.65],[22,9.53]],"id":41419601},{"atb":[[9.2,32.55],[21,10.01],[13,16.68]],"id":41419630},{"atb":[[360,0.55],[210,0.95],[110,2.44]],"id":41419597},{"atb":[[38,5.41],[19.5,10.82],[14.5,19.77]],"id":28546943},{"atb":[[360,0.55],[210,0.95],[110,2.44]],"id":41419659},{"atb":[[7.2,32.29],[5.1,48.83],[4.1,86.12]],"id":41419606},{"atb":[[75,2.7],[20,14.05],[30,6.9]],"id":41419602},{"atb":[[38,5.41],[19.5,10.82],[14.5,19.77]],"id":41419585},{"atb":[[95,2.13],[48,5.68],[240,0.83]],"id":41419614},{"atb":[[19.5,10.82],[12,18.2],[8.8,34.23]],"id":41419610},{"atb":[[600,0.44],[700,0.28],[850,0.23]],"id":41419656},{"atb":[[9.2,32.55],[21,10.01],[13,16.68]],"id":41419623},{"atb":[[5.1,65.11],[9.2,24.42],[6.2,38.5]],"id":41419590},{"atb":[[600,0.44],[700,0.28],[850,0.23]],"id":41419652},{"atb":[[360,0.55],[210,0.95],[110,2.44]],"id":41435528},{"atb":[[9.2,32.55],[21,10.01],[13,16.68]],"id":41419586},{"atb":[[17,12.51],[12,24.27],[29,7.14]],"id":41419631},{"atb":[[6.4,49.44],[13.5,16.02],[8.4,27.05]],"id":41419627},{"atb":[[44,4.65],[27,10.26],[120,1.68]],"id":41419594},{"atb":[[34,6.06],[85,2.38],[22,12.71]],"id":41419607},{"atb":[[17.5,16.17],[50,4.08],[25,8.34]],"id":28546950},{"atb":[[36,5.71],[90,2.25],[23,12.13]],"id":41419603},{"atb":[[65,3.12],[19,14.83],[28,7.41]],"id":41419615},{"atb":[[19.5,10.82],[12,18.2],[8.8,34.23]],"id":41419611},{"atb":[[600,0.44],[700,0.28],[850,0.23]],"id":41419657},{"atb":[[17,12.51],[12,24.27],[29,7.14]],"id":41419624},{"atb":[[34,6.06],[85,2.38],[22,12.71]],"id":41435525},{"atb":[[95,2.13],[48,5.68],[240,0.83]],"id":41419653},{"atb":[[6.4,49.44],[13.5,16.02],[8.4,27.05]],"id":41419620},{"atb":[[5.6,43.53],[4.1,64.59],[3.55,104.7]],"id":41419587},{"atb":[[32,6.46],[18,11.77],[13,22.24]],"id":41419632},{"atb":[[16.5,12.91],[11.5,25.42],[28,7.41]],"id":41419599},{"atb":[[310,0.64],[160,1.26],[80,3.38]],"id":41419628},{"atb":[[140,1.44],[70,3.86],[290,0.69]],"id":41419595},{"atb":[[40,5.13],[20,10.53],[15,19.06]],"id":41419608},{"atb":[[36,5.71],[90,2.25],[23,12.13]],"id":41419604},{"atb":[[18.5,11.44],[11,20.02],[8.4,36.07]],"id":41419616},{"atb":[[32,6.46],[18,11.77],[13,22.24]],"id":41419625},{"atb":[[17.5,16.17],[50,4.08],[25,8.34]],"id":41419592},{"atb":[[310,0.64],[160,1.26],[80,3.38]],"id":41419654},{"atb":[[310,0.64],[160,1.26],[80,3.38]],"id":41435526},{"atb":[[310,0.64],[160,1.26],[80,3.38]],"id":41419621},{"atb":[[5.7,42.6],[8.4,27.05],[4.7,72.15]],"id":41419588},{"atb":[[600,0.44],[700,0.28],[850,0.23]],"id":41419600},{"atb":[[32,6.46],[80,2.53],[21,13.34]],"id":41419629},{"atb":[[360,0.55],[210,0.95],[110,2.44]],"id":41419596},{"atb":[[140,1.44],[70,3.86],[290,0.69]],"id":41419658}],"con":true,"img":true}]}
{"op":"mcm","clk":"5352823536","pt":1646201802743,"mc":[{"id":"1.195503868","marketDefinition":{"bspMarket":false,"turnInPlayEnabled":false,"persistenceEnabled":false,"marketBaseRate":7.0,"eventId":"31272499","eventTypeId":"4339","numberOfWinners":1,"bettingType":"ODDS","marketType":"EXACTA","marketTime":"2022-03-02T11:09:00.000Z","suspendTime":"2022-03-02T11:09:00.000Z","bspReconciled":false,"complete":true,"inPlay":false,"crossMatching":false,"runnersVoidable":false,"numberOfActiveRunners":56,"betDelay":0,"status":"OPEN","runners":[{"status":"ACTIVE","sortPriority":1,"id":41419585,"name":"1 - 2"},{"status":"ACTIVE","sortPriority":2,"id":41419586,"name":"1 - 3"},{"status":"ACTIVE","sortPriority":3,"id":41419587,"name":"1 - 4"},{"status":"ACTIVE","sortPriority":4,"id":41419588,"name":"1 - 5"},{"status":"ACTIVE","sortPriority":5,"id":41419589,"name":"1 - 6"},{"status":"ACTIVE","sortPriority":6,"id":41419590,"name":"1 - 7"},{"status":"ACTIVE","sortPriority":7,"id":28546943,"name":"1 - 9"},{"status":"ACTIVE","sortPriority":8,"id":41419592,"name":"2 - 1"},{"status":"ACTIVE","sortPriority":9,"id":41419593,"name":"2 - 3"},{"status":"ACTIVE","sortPriority":10,"id":41419594,"name":"2 - 4"},{"status":"ACTIVE","sortPriority":11,"id":41419595,"name":"2 - 5"},{"status":"ACTIVE","sortPriority":12,"id":41419596,"name":"2 - 6"},{"status":"ACTIVE","sortPriority":13,"id":41419597,"name":"2 - 7"},{"status":"ACTIVE","sortPriority":14,"id":41419651,"name":"2 - 9"},{"status":"ACTIVE","sortPriority":15,"id":41419599,"name":"3 - 1"},{"status":"ACTIVE","sortPriority":16,"id":41419600,"name":"3 - 2"},{"status":"ACTIVE","sortPriority":17,"id":41419601,"name":"3 - 4"},{"status":"ACTIVE","sortPriority":18,"id":41419602,"name":"3 - 5"},{"status":"ACTIVE","sortPriority":19,"id":41419603,"name":"3 - 6"},{"status":"ACTIVE","sortPriority":20,"id":41419604,"name":"3 - 7"},{"status":"ACTIVE","sortPriority":21,"id":41419652,"name":"3 - 9"},{"status":"ACTIVE","sortPriority":22,"id":41419606,"name":"4 - 1"},{"status":"ACTIVE","sortPriority":23,"id":41419607,"name":"4 - 2"},{"status":"ACTIVE","sortPriority":24,"id":41419608,"name":"4 - 3"},{"status":"ACTIVE","sortPriority":25,"id":41419609,"name":"4 - 5"},{"status":"ACTIVE","sortPriority":26,"id":41419610,"name":"4 - 6"},{"status":"ACTIVE","sortPriority":27,"id":41419611,"name":"4 - 7"},{"status":"ACTIVE","sortPriority":28,"id":41435525,"name":"4 - 9"},{"status":"ACTIVE","sortPriority":29,"id":41419613,"name":"5 - 1"},{"status":"ACTIVE","sortPriority":30,"id":41419614,"name":"5 - 2"},{"status":"ACTIVE","sortPriority":31,"id":41419615,"name":"5 - 3"},{"status":"ACTIVE","sortPriority":32,"id":41419616,"name":"5 - 4"},{"status":"ACTIVE","sortPriority":33,"id":41419617,"name":"5 - 6"},{"status":"ACTIVE","sortPriority":34,"id":41419618,"name":"5 - 7"},{"status":"ACTIVE","sortPriority":35,"id":41419653,"name":"5 - 9"},{"status":"ACTIVE","sortPriority":36,"id":41419620,"name":"6 - 1"},{"status":"ACTIVE","sortPriority":37,"id":41419621,"name":"6 - 2"},{"status":"ACTIVE","sortPriority":38,"id":41419622,"name":"6 - 3"},{"status":"ACTIVE","sortPriority":39,"id":41419623,"name":"6 - 4"},{"status":"ACTIVE","sortPriority":40,"id":41419624,"name":"6 - 5"},{"status":"ACTIVE","sortPriority":41,"id":41419625,"name":"6 - 7"},{"status":"ACTIVE","sortPriority":42,"id":41435526,"name":"6 - 9"},{"status":"ACTIVE","sortPriority":43,"id":41419627,"name":"7 - 1"},{"status":"ACTIVE","sortPriority":44,"id":41419628,"name":"7 - 2"},{"status":"ACTIVE","sortPriority":45,"id":41419629,"name":"7 - 3"},{"status":"ACTIVE","sortPriority":46,"id":41419630,"name":"7 - 4"},{"status":"ACTIVE","sortPriority":47,"id":41419631,"name":"7 - 5"},{"status":"ACTIVE","sortPriority":48,"id":41419632,"name":"7 - 6"},{"status":"ACTIVE","sortPriority":49,"id":41419654,"name":"7 - 9"},{"status":"ACTIVE","sortPriority":50,"id":28546950,"name":"9 - 1"},{"status":"ACTIVE","sortPriority":51,"id":41419656,"name":"9 - 2"},{"status":"ACTIVE","sortPriority":52,"id":41419657,"name":"9 - 3"},{"status":"ACTIVE","sortPriority":53,"id":41435527,"name":"9 - 4"},{"status":"ACTIVE","sortPriority":54,"id":41419658,"name":"9 - 5"},{"status":"ACTIVE","sortPriority":55,"id":41435528,"name":"9 - 6"},{"status":"ACTIVE","sortPriority":56,"id":41419659,"name":"9 - 7"}],"regulators":["MR_INT"],"venue":"Rockhampton","countryCode":"AU","discountAllowed":true,"timezone":"Australia/Queensland","openDate":"2022-03-02T08:28:00.000Z","version":4382605979,"name":"Exacta","eventName":"Rockhampton (AUS) 2nd Mar"},"rc":[{"atb":[[18,11.77],[10.5,21.07],[8.2,37.06]],"id":41419609},{"atb":[[16.5,12.91],[11.5,25.41],[28,7.41]],"id":41419617},{"atb":[[11,20.01],[7.4,31.27],[5.7,56.78]],"id":41419613},{"atb":[[600,0.44],[700,0.28],[850,0.23]],"id":41419593},{"atb":[[32,6.45],[80,2.53],[21,13.34]],"id":41419622},{"atb":[[5.1,65.09],[9.2,24.41],[6.2,38.49]],"id":41419589},{"atb":[[44,4.65],[27,10.26],[120,1.68]],"id":41435527},{"atb":[[600,0.44],[700,0.28],[850,0.23]],"id":41419651},{"atb":[[16.5,12.91],[11.5,25.41],[28,7.41]],"id":41419618},{"atb":[[16,17.79],[44,4.65],[22,9.53]],"id":41419601},{"atb":[[9.2,32.54],[21,10],[13,16.68]],"id":41419630},{"atb":[[360,0.55],[210,0.95],[110,2.44]],"id":41419597},{"atb":[[38,5.41],[19.5,10.82],[14.5,19.77]],"id":28546943},{"atb":[[360,0.55],[210,0.95],[110,2.44]],"id":41419659},{"atb":[[7.2,32.28],[5.1,48.81],[4.1,86.09]],"id":41419606},{"atb":[[75,2.7],[20,14.04],[30,6.9]],"id":41419602},{"atb":[[38,5.41],[19.5,10.82],[14.5,19.77]],"id":41419585},{"atb":[[95,2.12],[48,5.67],[240,0.83]],"id":41419614},{"atb":[[19.5,10.82],[12,18.19],[8.8,34.21]],"id":41419610},{"atb":[[600,0.44],[700,0.28],[850,0.23]],"id":41419656},{"atb":[[9.2,32.54],[21,10],[13,16.68]],"id":41419623},{"atb":[[5.1,65.09],[9.2,24.41],[6.2,38.49]],"id":41419590},{"atb":[[600,0.44],[700,0.28],[850,0.23]],"id":41419652},{"atb":[[360,0.55],[210,0.95],[110,2.44]],"id":41435528},{"atb":[[9.2,32.54],[21,10],[13,16.68]],"id":41419586},{"atb":[[17,12.5],[12,24.26],[29,7.14]],"id":41419631},{"atb":[[6.4,49.42],[13.5,16.01],[8.4,27.04]],"id":41419627},{"atb":[[44,4.65],[27,10.26],[120,1.68]],"id":41419594},{"atb":[[34,6.06],[85,2.38],[22,12.71]],"id":41419607},{"atb":[[17.5,16.17],[50,4.08],[25,8.33]],"id":28546950},{"atb":[[36,5.71],[90,2.24],[23,12.13]],"id":41419603},{"atb":[[65,3.12],[19,14.82],[28,7.41]],"id":41419615},{"atb":[[19.5,10.82],[12,18.19],[8.8,34.21]],"id":41419611},{"atb":[[600,0.44],[700,0.28],[850,0.23]],"id":41419657},{"atb":[[17,12.5],[12,24.26],[29,7.14]],"id":41419624},{"atb":[[34,6.06],[85,2.38],[22,12.71]],"id":41435525},{"atb":[[95,2.12],[48,5.67],[240,0.83]],"id":41419653},{"atb":[[6.4,49.42],[13.5,16.01],[8.4,27.04]],"id":41419620},{"atb":[[5.6,43.51],[4.1,64.57],[3.55,104.66]],"id":41419587},{"atb":[[32,6.45],[18,11.77],[13,22.23]],"id":41419632},{"atb":[[16.5,12.91],[11.5,25.41],[28,7.41]],"id":41419599},{"atb":[[310,0.64],[160,1.26],[80,3.37]],"id":41419628},{"atb":[[140,1.44],[70,3.86],[290,0.69]],"id":41419595},{"atb":[[40,5.13],[20,10.53],[15,19.06]],"id":41419608},{"atb":[[36,5.71],[90,2.24],[23,12.13]],"id":41419604},{"atb":[[18.5,11.43],[11,20.01],[8.4,36.06]],"id":41419616},{"atb":[[32,6.45],[18,11.77],[13,22.23]],"id":41419625},{"atb":[[17.5,16.17],[50,4.08],[25,8.33]],"id":41419592},{"atb":[[310,0.64],[160,1.26],[80,3.37]],"id":41419654},{"atb":[[310,0.64],[160,1.26],[80,3.37]],"id":41435526},{"atb":[[310,0.64],[160,1.26],[80,3.37]],"id":41419621},{"atb":[[5.7,42.58],[8.4,27.04],[4.7,72.13]],"id":41419588},{"atb":[[600,0.44],[700,0.28],[850,0.23]],"id":41419600},{"atb":[[32,6.45],[80,2.53],[21,13.34]],"id":41419629},{"atb":[[360,0.55],[210,0.95],[110,2.44]],"id":41419596},{"atb":[[140,1.44],[70,3.86],[290,0.69]],"id":41419658}],"con":true,"img":true}]}
{"op":"mcm","clk":"5352957928","pt":1646205655485,"mc":[{"id":"1.195503868","rc":[{"atb":[[18,0],[10.5,0],[8.2,0]],"id":41419609},{"atb":[[16.5,0],[11.5,0],[28,0]],"id":41419617},{"atb":[[11,0],[7.4,0],[5.7,0]],"id":41419613},{"atb":[[600,0],[700,0],[850,0]],"id":41419593},{"atb":[[32,0],[80,0],[21,0]],"id":41419622},{"atb":[[5.1,0],[9.2,0],[6.2,0]],"id":41419589},{"atb":[[44,4.65],[27,10.26],[120,1.68]],"id":41435527},{"atb":[[600,0.44],[700,0.28],[850,0.23]],"id":41419651},{"atb":[[16.5,0],[11.5,0],[28,0]],"id":41419618},{"atb":[[16,0],[44,0],[22,0]],"id":41419601},{"atb":[[9.2,32.53],[21,10],[13,16.67]],"id":41419630},{"atb":[[360,0],[210,0],[110,0]],"id":41419597},{"atb":[[38,0],[19.5,0],[14.5,0]],"id":28546943},{"atb":[[360,0.55],[210,0.95],[110,2.44]],"id":41419659},{"atb":[[7.2,0],[5.1,0],[4.1,0]],"id":41419606},{"atb":[[75,0],[20,0],[30,0]],"id":41419602},{"atb":[[38,0],[19.5,0],[14.5,0]],"id":41419585},{"atb":[[95,0],[48,0],[240,0]],"id":41419614},{"atb":[[19.5,0],[12,0],[8.8,0]],"id":41419610},{"atb":[[600,0.44],[700,0.28],[850,0.23]],"id":41419656},{"atb":[[9.2,0],[21,0],[13,0]],"id":41419623},{"atb":[[5.1,0],[9.2,0],[6.2,0]],"id":41419590},{"atb":[[600,0.44],[700,0.28],[850,0.23]],"id":41419652},{"atb":[[360,0.55],[210,0.95],[110,2.44]],"id":41435528},{"atb":[[9.2,0],[21,0],[13,0]],"id":41419586},{"atb":[[17,12.5],[12,24.25],[29,7.14]],"id":41419631},{"atb":[[6.4,0],[13.5,0],[8.4,0]],"id":41419627},{"atb":[[44,0],[27,0],[120,0]],"id":41419594},{"atb":[[34,0],[85,0],[22,0]],"id":41419607},{"atb":[[17.5,0],[50,0],[25,0]],"id":28546950},{"atb":[[36,0],[90,0],[23,0]],"id":41419603},{"atb":[[65,0],[19,0],[28,0]],"id":41419615},{"atb":[[19.5,0],[12,0],[8.8,0]],"id":41419611},{"atb":[[600,0.44],[700,0.28],[850,0.23]],"id":41419657},{"atb":[[17,0],[12,0],[29,0]],"id":41419624},{"atb":[[34,6.06],[85,2.37],[22,12.7]],"id":41435525},{"atb":[[95,2.12],[48,5.67],[240,0.83]],"id":41419653},{"atb":[[6.4,0],[13.5,0],[8.4,0]],"id":41419620},{"atb":[[5.6,0],[4.1,0],[3.55,0]],"id":41419587},{"atb":[[32,6.45],[18,11.76],[13,22.23]],"id":41419632},{"atb":[[16.5,0],[11.5,0],[28,0]],"id":41419599},{"atb":[[310,0],[160,0],[80,0]],"id":41419628},{"atb":[[140,0],[70,0],[290,0]],"id":41419595},{"atb":[[40,0],[20,0],[15,0]],"id":41419608},{"atb":[[36,0],[90,0],[23,0]],"id":41419604},{"atb":[[18.5,0],[11,0],[8.4,0]],"id":41419616},{"atb":[[32,0],[18,0],[13,0]],"id":41419625},{"atb":[[17.5,0],[50,0],[25,0]],"id":41419592},{"atb":[[310,0.64],[160,1.26],[80,3.37]],"id":41419654},{"atb":[[310,0.64],[160,1.26],[80,3.37]],"id":41435526},{"atb":[[310,0],[160,0],[80,0]],"id":41419621},{"atb":[[5.7,0],[8.4,0],[4.7,0]],"id":41419588},{"atb":[[600,0],[700,0],[850,0]],"id":41419600},{"atb":[[32,6.45],[80,2.53],[21,13.34]],"id":41419629},{"atb":[[360,0],[210,0],[110,0]],"id":41419596},{"atb":[[140,1.44],[70,3.86],[290,0.69]],"id":41419658}],"con":true,"img":false}]}
{"op":"mcm","clk":"5352957937","pt":1646205655691,"mc":[{"id":"1.195503868","rc":[{"atb":[[44,0],[27,0],[120,0]],"id":41435527},{"atb":[[600,0],[700,0],[850,0]],"id":41419651},{"atb":[[9.2,0],[21,0],[13,0]],"id":41419630},{"atb":[[360,0],[210,0],[110,0]],"id":41419659},{"atb":[[600,0],[700,0],[850,0]],"id":41419656},{"atb":[[600,0],[700,0],[850,0]],"id":41419652},{"atb":[[360,0],[210,0],[110,0]],"id":41435528},{"atb":[[17,0],[12,0],[29,0]],"id":41419631},{"atb":[[600,0],[700,0],[850,0]],"id":41419657},{"atb":[[34,0],[85,0],[22,0]],"id":41435525},{"atb":[[95,0],[48,0],[240,0]],"id":41419653},{"atb":[[32,0],[18,0],[13,0]],"id":41419632},{"atb":[[310,0],[160,0],[80,0]],"id":41419654},{"atb":[[310,0],[160,0],[80,0]],"id":41435526},{"atb":[[32,0],[80,0],[21,0]],"id":41419629},{"atb":[[140,0],[70,0],[290,0]],"id":41419658}],"con":true,"img":false}]}
{"op":"mcm","clk":"5352958469","pt":1646205672803,"mc":[{"id":"1.195503868","rc":[{"atb":[[18,11.76],[10.5,21.06],[8.2,37.05]],"id":41419609},{"atb":[[600,0.44],[700,0.28],[850,0.23]],"id":41419593},{"atb":[[5.1,65.07],[9.2,24.4],[6.2,38.48]],"id":41419589},{"atb":[[600,0.44],[700,0.28],[850,0.23]],"id":41419651},{"atb":[[16,17.78],[44,4.65],[22,9.53]],"id":41419601},{"atb":[[360,0.55],[210,0.95],[110,2.44]],"id":41419597},{"atb":[[38,5.4],[19.5,10.81],[14.5,19.76]],"id":28546943},{"atb":[[7.2,32.27],[5.1,48.8],[4.1,86.06]],"id":41419606},{"atb":[[75,2.7],[20,14.04],[30,6.89]],"id":41419602},{"atb":[[38,5.4],[19.5,10.81],[14.5,19.76]],"id":41419585},{"atb":[[19.5,10.81],[12,18.19],[8.8,34.2]],"id":41419610},{"atb":[[5.1,65.07],[9.2,24.4],[6.2,38.48]],"id":41419590},{"atb":[[600,0.44],[700,0.28],[850,0.23]],"id":41419652},{"atb":[[9.2,32.53],[21,10],[13,16.67]],"id":41419586},{"atb":[[44,4.65],[27,10.26],[120,1.68]],"id":41419594},{"atb":[[34,6.06],[85,2.37],[22,12.7]],"id":41419607},{"atb":[[36,5.71],[90,2.24],[23,12.12]],"id":41419603},{"atb":[[19.5,10.81],[12,18.19],[8.8,34.2]],"id":41419611},{"atb":[[34,6.06],[85,2.37],[22,12.7]],"id":41435525},{"atb":[[5.6,43.5],[4.1,64.55],[3.55,104.63]],"id":41419587},{"atb":[[16.5,12.9],[11.5,25.4],[28,7.41]],"id":41419599},{"atb":[[140,1.44],[70,3.86],[290,0.69]],"id":41419595},{"atb":[[40,5.13],[20,10.52],[15,19.05]],"id":41419608},{"atb":[[36,5.71],[90,2.24],[23,12.12]],"id":41419604},{"atb":[[17.5,16.16],[50,4.08],[25,8.33]],"id":41419592},{"atb":[[5.7,42.57],[8.4,27.04],[4.7,72.11]],"id":41419588},{"atb":[[600,0.44],[700,0.28],[850,0.23]],"id":41419600},{"atb":[[360,0.55],[210,0.95],[110,2.44]],"id":41419596}],"con":true,"img":false}]}
{"op":"mcm","clk":"5352958472","pt":1646205672913,"mc":[{"id":"1.195503868","rc":[{"atb":[[16.5,12.9],[11.5,25.4],[28,7.41]],"id":41419617},{"atb":[[11,20.01],[7.4,31.26],[5.7,56.76]],"id":41419613},{"atb":[[32,6.45],[80,2.53],[21,13.34]],"id":41419622},{"atb":[[44,4.65],[27,10.26],[120,1.68]],"id":41435527},{"atb":[[16.5,12.9],[11.5,25.4],[28,7.41]],"id":41419618},{"atb":[[9.2,32.53],[21,10],[13,16.67]],"id":41419630},{"atb":[[360,0.55],[210,0.95],[110,2.44]],"id":41419659},{"atb":[[95,2.12],[48,5.67],[240,0.83]],"id":41419614},{"atb":[[600,0.44],[700,0.28],[850,0.23]],"id":41419656},{"atb":[[9.2,32.53],[21,10],[13,16.67]],"id":41419623},{"atb":[[360,0.55],[210,0.95],[110,2.44]],"id":41435528},{"atb":[[17,12.5],[12,24.25],[29,7.14]],"id":41419631},{"atb":[[6.4,49.41],[13.5,16],[8.4,27.04]],"id":41419627},{"atb":[[17.5,16.16],[50,4.08],[25,8.33]],"id":28546950},{"atb":[[65,3.12],[19,14.82],[28,7.41]],"id":41419615},{"atb":[[600,0.44],[700,0.28],[850,0.23]],"id":41419657},{"atb":[[17,12.5],[12,24.25],[29,7.14]],"id":41419624},{"atb":[[95,2.12],[48,5.67],[240,0.83]],"id":41419653},{"atb":[[6.4,49.41],[13.5,16],[8.4,27.04]],"id":41419620},{"atb":[[32,6.45],[18,11.76],[13,22.23]],"id":41419632},{"atb":[[310,0.64],[160,1.26],[80,3.37]],"id":41419628},{"atb":[[18.5,11.43],[11,20.01],[8.4,36.05]],"id":41419616},{"atb":[[32,6.45],[18,11.76],[13,22.23]],"id":41419625},{"atb":[[310,0.64],[160,1.26],[80,3.37]],"id":41419654},{"atb":[[310,0.64],[160,1.26],[80,3.37]],"id":41435526},{"atb":[[310,0.64],[160,1.26],[80,3.37]],"id":41419621},{"atb":[[32,6.45],[80,2.53],[21,13.34]],"id":41419629},{"atb":[[140,1.44],[70,3.86],[290,0.69]],"id":41419658}],"con":true,"img":false}]}
{"op":"mcm","clk":"5353266784","pt":1646212140462,"mc":[{"id":"1.195503868","rc":[{"atb":[[17.5,3.26],[18,11.74],[20,2.72],[10.5,21.03],[8.2,36.99]],"id":41419609},{"atb":[[16.5,12.88],[32,2.72],[11.5,25.36],[26,3.26],[28,7.4]],"id":41419617},{"atb":[[11,19.97],[7.4,31.21],[12,3.26],[5.7,56.67],[14.5,2.72]],"id":41419613},{"atb":[[600,0.44],[700,0.28],[180,3.26],[850,0.23],[230,2.72]],"id":41419593},{"atb":[[32,6.44],[75,2.72],[80,2.52],[21,13.31],[50,3.26]],"id":41419622},{"atb":[[5.1,64.97],[9.2,24.36],[6.2,38.42]],"id":41419589},{"atb":[[140,2.72],[44,4.64],[95,3.26],[27,10.24],[120,1.67]],"id":41435527},{"atb":[[600,0.44],[290,3.26],[700,0.28],[340,2.72],[850,0.23]],"id":41419651},{"atb":[[16.5,12.88],[20,3.26],[11.5,25.36],[25,2.72],[28,7.4]],"id":41419618},{"atb":[[16,17.76],[75,2.72],[44,4.64],[22,9.51],[50,3.26]],"id":41419601},{"atb":[[18.5,3.26],[9.2,32.48],[21,9.98],[22,2.72],[13,16.64]],"id":41419630},{"atb":[[85,3.26],[360,0.55],[210,0.95],[110,2.44],[120,2.72]],"id":41419597},{"atb":[[38,8.12],[19.5,10.8],[14.5,19.73],[29,3.26]],"id":28546943},{"atb":[[150,2.72],[360,0.55],[100,3.26],[210,0.95],[110,2.44]],"id":41419659},{"atb":[[7.2,32.22],[5.1,48.72],[4.1,85.93],[12,2.72],[9.8,3.26]],"id":41419606},{"atb":[[75,2.69],[20,14.02],[80,2.72],[55,3.26],[30,6.88]],"id":41419602},{"atb":[[32,2.72],[38,5.4],[19.5,10.8],[26,3.26],[14.5,19.73]],"id":41419585},{"atb":[[65,2.72],[95,2.12],[46,3.26],[48,5.66],[240,0.83]],"id":41419614},{"atb":[[19.5,10.8],[22,3.26],[12,18.16],[8.8,34.15],[27,2.72]],"id":41419610},{"atb":[[600,0.44],[320,3.26],[700,0.28],[370,2.72],[850,0.23]],"id":41419656},{"atb":[[34,2.72],[9.2,32.48],[21,9.98],[13,16.64],[27,3.26]],"id":41419623},{"atb":[[5.1,64.97],[9.2,24.36],[6.2,38.42],[8.4,3.26],[9.4,2.72]],"id":41419590},{"atb":[[600,0.44],[700,0.28],[170,3.26],[850,0.23],[220,2.72]],"id":41419652},{"atb":[[140,3.26],[360,0.55],[190,2.72],[210,0.95],[110,2.44]],"id":41435528},{"atb":[[9.2,32.48],[20,3.26],[21,9.98],[25,2.72],[13,16.64]],"id":41419586},{"atb":[[17,12.48],[20,3.26],[12,24.21],[25,2.72],[29,7.13]],"id":41419631},{"atb":[[6.4,49.33],[12,3.26],[13.5,15.98],[8.4,26.99],[14.5,2.72]],"id":41419627},{"atb":[[80,3.26],[44,4.64],[27,10.24],[110,2.72],[120,1.67]],"id":41419594},{"atb":[[34,6.05],[85,2.37],[42,3.26],[22,12.68],[55,2.72]],"id":41419607},{"atb":[[17.5,16.14],[80,3.26],[50,4.07],[25,8.32],[110,2.72]],"id":28546950},{"atb":[[36,5.7],[75,3.26],[90,2.24],[23,12.1],[100,2.72]],"id":41419603},{"atb":[[65,3.12],[19,14.8],[38,3.26],[48,2.72],[28,7.4]],"id":41419615},{"atb":[[17.5,3.26],[19.5,10.8],[20,2.72],[12,18.16],[8.8,34.15]],"id":41419611},{"atb":[[600,0.44],[290,2.72],[700,0.28],[850,0.23],[240,3.26]],"id":41419657},{"atb":[[17,12.48],[38,2.72],[12,24.21],[29,10.4]],"id":41419624},{"atb":[[65,2.72],[34,6.05],[85,2.37],[22,12.68],[46,3.26]],"id":41435525},{"atb":[[75,2.72],[95,2.12],[48,5.66],[50,3.26],[240,0.83]],"id":41419653},{"atb":[[6.4,49.33],[21,3.26],[26,2.72],[13.5,15.98],[8.4,26.99]],"id":41419620},{"atb":[[5.6,43.43],[4.1,64.45],[7.4,3.26],[3.55,104.46],[8.4,2.72]],"id":41419587},{"atb":[[32,9.17],[18,11.74],[13,22.19],[26,3.26]],"id":41419632},{"atb":[[16.5,12.88],[42,3.26],[11.5,25.36],[55,2.72],[28,7.4]],"id":41419599},{"atb":[[65,2.72],[310,0.64],[160,1.25],[80,3.37],[46,3.26]],"id":41419628},{"atb":[[140,1.43],[70,3.85],[290,0.69],[85,3.26],[120,2.72]],"id":41419595},{"atb":[[32,3.26],[40,5.12],[20,10.51],[42,2.72],[15,19.02]],"id":41419608},{"atb":[[36,5.7],[80,2.72],[90,2.24],[23,12.1],[55,3.26]],"id":41419604},{"atb":[[18.5,14.68],[11,19.97],[22,2.72],[8.4,35.99]],"id":41419616},{"atb":[[32,6.44],[18,11.74],[38,2.72],[13,22.19],[29,3.26]],"id":41419625},{"atb":[[17.5,16.14],[85,2.72],[50,4.07],[25,8.32],[60,3.26]],"id":41419592},{"atb":[[75,2.72],[310,0.64],[160,1.25],[80,3.37],[50,3.26]],"id":41419654},{"atb":[[310,0.64],[160,1.25],[80,6.64],[110,2.72]],"id":41435526},{"atb":[[70,3.26],[310,0.64],[160,1.25],[80,3.37],[95,2.72]],"id":41419621},{"atb":[[5.7,42.5],[8.4,30.26],[4.7,71.99],[9.4,2.72]],"id":41419588},{"atb":[[600,0.44],[700,0.28],[850,0.23]],"id":41419600},{"atb":[[32,6.44],[38,3.26],[80,2.52],[21,13.31],[48,2.72]],"id":41419629},{"atb":[[150,2.72],[360,0.55],[100,3.26],[210,0.95],[110,2.44]],"id":41419596},{"atb":[[140,1.43],[70,3.85],[290,0.69],[150,2.72],[100,3.26]],"id":41419658}],"con":true,"img":false}]}
{"op":"mcm","clk":"5353266789","pt":1646212140558,"mc":[{"id":"1.195503868","rc":[{"atb":[[10.5,3.26],[13,2.72]],"id":41419589},{"atb":[[150,3.26],[200,2.72]],"id":41419600}],"con":true,"img":false}]}
{"op":"mcm","clk":"5353305253","pt":1646212673305,"mc":[{"id":"1.195503868","rc":[{"atb":[[600,0],[700,0],[850,0]],"id":41419593},{"atb":[[5.1,0],[9.2,0],[6.2,0]],"id":41419589},{"atb":[[16,0],[44,0],[22,0]],"id":41419601},{"atb":[[360,0],[210,0],[110,0]],"id":41419597},{"atb":[[38,2.72],[19.5,0],[14.5,0]],"id":28546943},{"atb":[[75,0],[20,0],[30,0]],"id":41419602},{"atb":[[38,0],[19.5,0],[14.5,0]],"id":41419585},{"atb":[[5.1,0],[9.2,0],[6.2,0]],"id":41419590},{"atb":[[9.2,0],[21,0],[13,0]],"id":41419586},{"atb":[[44,0],[27,0],[120,0]],"id":41419594},{"atb":[[17.5,0],[50,0],[25,0]],"id":28546950},{"atb":[[36,0],[90,0],[23,0]],"id":41419603},{"atb":[[5.6,0],[4.1,0],[3.55,0]],"id":41419587},{"atb":[[16.5,0],[11.5,0],[28,0]],"id":41419599},{"atb":[[140,0],[70,0],[290,0]],"id":41419595},{"atb":[[36,0],[90,0],[23,0]],"id":41419604},{"atb":[[17.5,0],[50,0],[25,0]],"id":41419592},{"atb":[[5.7,0],[8.4,3.26],[4.7,0]],"id":41419588},{"atb":[[600,0],[700,0],[850,0]],"id":41419600},{"atb":[[360,0],[210,0],[110,0]],"id":41419596}],"con":true,"img":false}]}
{"op":"mcm","clk":"5353305261","pt":1646212673410,"mc":[{"id":"1.195503868","rc":[{"atb":[[18,0],[10.5,0],[8.2,0]],"id":41419609},{"atb":[[16.5,0],[11.5,0],[28,0]],"id":41419617},{"atb":[[11,0],[7.4,0],[5.7,0]],"id":41419613},{"atb":[[32,0],[80,0],[21,0]],"id":41419622},{"atb":[[16.5,0],[11.5,0],[28,0]],"id":41419618},{"atb":[[7.2,0],[5.1,0],[4.1,0]],"id":41419606},{"atb":[[95,0],[48,0],[240,0]],"id":41419614},{"atb":[[19.5,0],[12,0],[8.8,0]],"id":41419610},{"atb":[[9.2,0],[21,0],[13,0]],"id":41419623},{"atb":[[6.4,0],[13.5,0],[8.4,0]],"id":41419627},{"atb":[[34,0],[85,0],[22,0]],"id":41419607},{"atb":[[65,0],[19,0],[28,0]],"id":41419615},{"atb":[[19.5,0],[12,0],[8.8,0]],"id":41419611},{"atb":[[17,0],[12,0],[29,3.26]],"id":41419624},{"atb":[[6.4,0],[13.5,0],[8.4,0]],"id":41419620},{"atb":[[310,0],[160,0],[80,0]],"id":41419628},{"atb":[[40,0],[20,0],[15,0]],"id":41419608},{"atb":[[18.5,3.26],[11,0],[8.4,0]],"id":41419616},{"atb":[[32,0],[18,0],[13,0]],"id":41419625},{"atb":[[310,0],[160,0],[80,0]],"id":41419621}],"con":true,"img":false}]}
{"op":"mcm","clk":"5353305273","pt":1646212673626,"mc":[{"id":"1.195503868","rc":[{"atb":[[44,0],[27,0],[120,0]],"id":41435527},{"atb":[[600,0],[700,0],[850,0]],"id":41419651},{"atb":[[9.2,0],[21,0],[13,0]],"id":41419630},{"atb":[[360,0],[210,0],[110,0]],"id":41419659},{"atb":[[600,0],[700,0],[850,0]],"id":41419656},{"atb":[[600,0],[700,0],[850,0]],"id":41419652},{"atb":[[360,0],[210,0],[110,0]],"id":41435528},{"atb":[[17,0],[12,0],[29,0]],"id":41419631},{"atb":[[600,0],[700,0],[850,0]],"id":41419657},{"atb":[[34,0],[85,0],[22,0]],"id":41435525},{"atb":[[95,0],[48,0],[240,0]],"id":41419653},{"atb":[[32,2.72],[18,0],[13,0]],"id":41419632},{"atb":[[310,0],[160,0],[80,0]],"id":41419654},{"atb":[[310,0],[160,0],[80,3.26]],"id":41435526},{"atb":[[32,0],[80,0],[21,0]],"id":41419629},{"atb":[[140,0],[70,0],[290,0]],"id":41419658}],"con":true,"img":false}]}
{"op":"mcm","clk":"5353305895","pt":1646212685147,"mc":[{"id":"1.195503868","rc":[{"atb":[[17.5,12.1],[12.5,23.16],[30,6.88]],"id":41419617},{"atb":[[6.2,51.22],[8.2,27.75],[13,16.64]],"id":41419613},{"atb":[[38,5.4],[95,2.12],[24,11.58]],"id":41419622},{"atb":[[100,2.01],[50,5.43],[250,0.8]],"id":41435527},{"atb":[[24,8.68],[9.8,30.27],[14.5,14.8]],"id":41419618},{"atb":[[17,12.48],[9.8,22.7],[7.8,39.17]],"id":41419630},{"atb":[[340,0.58],[190,1.05],[95,2.83]],"id":41419659},{"atb":[[270,0.74],[170,1.57],[420,0.47]],"id":41419614},{"atb":[[600,0.44],[700,0.28],[850,0.23]],"id":41419656},{"atb":[[9.6,30.97],[23,9.07],[14,15.36]],"id":41419623},{"atb":[[600,0.33],[350,0.76],[450,0.44]],"id":41435528},{"atb":[[9.6,30.97],[23,9.07],[14,15.36]],"id":41419631},{"atb":[[9,24.97],[5,66.59],[6,39.95]],"id":41419627},{"atb":[[32,6.44],[80,5.79],[21,13.31]],"id":28546950},{"atb":[[75,2.69],[20,14.02],[30,6.88]],"id":41419615},{"atb":[[600,0.44],[700,0.28],[850,0.23]],"id":41419657},{"atb":[[17.5,12.1],[12.5,23.16],[30,6.88]],"id":41419624},{"atb":[[270,0.74],[170,1.57],[420,0.47]],"id":41419653},{"atb":[[6.8,45.93],[8.8,25.61],[14.5,14.8]],"id":41419620},{"atb":[[10.5,28.03],[26,11.25],[15.5,13.77]],"id":41419632},{"atb":[[270,0.74],[120,1.67],[60,4.51]],"id":41419628},{"atb":[[9,33.29],[20,10.51],[12.5,17.37]],"id":41419616},{"atb":[[16,13.31],[11,26.63],[27,7.68]],"id":41419625},{"atb":[[270,0.74],[120,1.67],[60,4.51]],"id":41419654},{"atb":[[530,0.37],[280,0.95],[380,0.52]],"id":41435526},{"atb":[[530,0.37],[280,0.95],[380,0.52]],"id":41419621},{"atb":[[17.5,16.14],[50,4.07],[25,8.32]],"id":41419629},{"atb":[[340,0.58],[490,0.4],[240,1.11]],"id":41419658}],"con":true,"img":false}]}
{"op":"mcm","clk":"5353305900","pt":1646212685201,"mc":[{"id":"1.195503868","rc":[{"atb":[[8.6,35.05],[19,11.1],[11.5,19.02]],"id":41419609},{"atb":[[600,0.44],[700,0.28],[850,0.23]],"id":41419593},{"atb":[[6.8,34.44],[9.8,22.7],[5.4,60.54]],"id":41419589},{"atb":[[600,0.44],[700,0.28],[850,0.23]],"id":41419651},{"atb":[[17,16.64],[48,4.25],[24,8.68]],"id":41419601},{"atb":[[340,0.58],[190,1.05],[95,2.83]],"id":41419597},{"atb":[[17,16.64],[48,4.25],[24,8.68]],"id":28546943},{"atb":[[4.3,80.72],[5.3,46.46],[7.6,30.27]],"id":41419606},{"atb":[[34,6.05],[85,2.37],[22,12.68]],"id":41419602},{"atb":[[17,16.64],[48,4.25],[24,8.68]],"id":41419585},{"atb":[[9.2,32.48],[21,9.98],[13,16.64]],"id":41419610},{"atb":[[4.3,80.72],[5.3,46.46],[7.6,30.27]],"id":41419590},{"atb":[[600,0.44],[700,0.28],[850,0.23]],"id":41419652},{"atb":[[9.6,30.97],[23,9.07],[14,15.36]],"id":41419586},{"atb":[[100,2.01],[50,5.43],[250,0.8]],"id":41419594},{"atb":[[65,3.12],[36,7.61],[180,1.11]],"id":41419607},{"atb":[[42,4.87],[26,10.65],[110,1.83]],"id":41419603},{"atb":[[16,13.31],[7.4,41.62],[9.4,23.78]],"id":41419611},{"atb":[[65,5.84],[36,7.61],[180,1.11]],"id":41435525},{"atb":[[4.5,57.08],[6,39.95],[3.75,96.87]],"id":41419587},{"atb":[[17,12.48],[12,24.21],[29,7.13]],"id":41419599},{"atb":[[340,0.58],[490,0.4],[240,1.11]],"id":41419595},{"atb":[[16,17.76],[44,4.64],[22,9.51]],"id":41419608},{"atb":[[18.5,15.22],[27,7.68],[60,3.38]],"id":41419604},{"atb":[[32,6.44],[80,2.52],[21,13.31]],"id":41419592},{"atb":[[9,24.97],[5,66.59],[6,39.95]],"id":41419588},{"atb":[[600,0.44],[700,0.28],[850,0.23]],"id":41419600},{"atb":[[600,0.33],[350,0.76],[450,0.44]],"id":41419596}],"con":true,"img":false}]}
{"op":"mcm","clk":"5353306744","pt":1646212700410,"mc":[{"id":"1.195503868","rc":[{"atb":[[20,0],[25,0]],"id":41419586}],"con":true,"img":false}]}
{"op":"mcm","clk":"5353306802","pt":1646212701133,"mc":[{"id":"1.195503868","rc":[{"atb":[[19.5,3.26],[24,2.72]],"id":41419586}],"con":true,"img":false}]}
{"op":"mcm","clk":"5353309188","pt":1646212742310,"mc":[{"id":"1.195503868","rc":[{"atb":[[10.5,0],[13,0]],"id":41419589},{"atb":[[8.4,0],[9.4,0]],"id":41419590},{"atb":[[21,0],[26,0]],"id":41419620}],"con":true,"img":false}]}
{"op":"mcm","clk":"5353309240","pt":1646212743100,"mc":[{"id":"1.195503868","rc":[{"atb":[[10,3.26],[12.5,2.72]],"id":41419589},{"atb":[[9.2,2.72],[8.2,3.26]],"id":41419590},{"atb":[[20,3.26],[25,2.72]],"id":41419620}],"con":true,"img":false}]}
{"op":"mcm","clk":"5353316105","pt":1646212866160,"mc":[{"id":"1.195503868","rc":[{"atb":[[17.5,0],[20,0]],"id":41419609},{"atb":[[14.5,0]],"id":41419613},{"atb":[[290,0]],"id":41419651},{"atb":[[20,0]],"id":41419618},{"atb":[[18.5,0],[22,0]],"id":41419630},{"atb":[[85,0]],"id":41419597},{"atb":[[150,0]],"id":41419659},{"atb":[[27,0]],"id":41419610},{"atb":[[34,0],[27,0]],"id":41419623},{"atb":[[220,0]],"id":41419652},{"atb":[[20,0],[25,0]],"id":41419631},{"atb":[[12,0],[14.5,0]],"id":41419627},{"atb":[[80,0]],"id":41419594},{"atb":[[38,0],[48,0]],"id":41419615},{"atb":[[29,0]],"id":41419624},{"atb":[[85,0]],"id":41419595}],"con":true,"img":false}]}
{"op":"mcm","clk":"5353316112","pt":1646212866265,"mc":[{"id":"1.195503868","rc":[{"atb":[[32,0],[26,0]],"id":41419617},{"atb":[[12,0]],"id":41419613},{"atb":[[180,0],[230,0]],"id":41419593},{"atb":[[140,0],[95,0]],"id":41435527},{"atb":[[340,0]],"id":41419651},{"atb":[[25,0]],"id":41419618},{"atb":[[120,0]],"id":41419597},{"atb":[[100,0]],"id":41419659},{"atb":[[12,0],[9.8,0]],"id":41419606},{"atb":[[80,0],[55,0]],"id":41419602},{"atb":[[65,0],[46,0]],"id":41419614},{"atb":[[22,0]],"id":41419610},{"atb":[[320,0],[370,0]],"id":41419656},{"atb":[[170,0]],"id":41419652},{"atb":[[110,0]],"id":41419594},{"atb":[[42,0],[55,0]],"id":41419607},{"atb":[[17.5,0],[20,0]],"id":41419611},{"atb":[[290,0],[240,0]],"id":41419657},{"atb":[[38,0]],"id":41419624},{"atb":[[75,0],[50,0]],"id":41419653},{"atb":[[120,0]],"id":41419595},{"atb":[[32,0],[42,0]],"id":41419608},{"atb":[[18.5,0],[22,0]],"id":41419616},{"atb":[[8.4,0],[9.4,0]],"id":41419588},{"atb":[[150,0],[200,0]],"id":41419600},{"atb":[[38,0],[48,0]],"id":41419629},{"atb":[[150,0],[100,0]],"id":41419596},{"atb":[[150,0],[100,0]],"id":41419658}],"con":true,"img":false}]}
{"op":"mcm","clk":"5353316158","pt":1646212866834,"mc":[{"id":"1.195503868","rc":[{"atb":[[18.5,3.26],[22,2.72]],"id":41419609},{"atb":[[16,2.72]],"id":41419613},{"atb":[[310,3.26]],"id":41419651},{"atb":[[22,3.26]],"id":41419618},{"atb":[[19,3.26],[23,2.72]],"id":41419630},{"atb":[[90,3.26]],"id":41419597},{"atb":[[160,2.72]],"id":41419659},{"atb":[[28,2.72]],"id":41419610},{"atb":[[36,2.72],[28,3.26]],"id":41419623},{"atb":[[240,2.72]],"id":41419652},{"atb":[[22,3.26],[27,2.72]],"id":41419631},{"atb":[[12.5,3.26],[15,2.72]],"id":41419627},{"atb":[[85,3.26]],"id":41419594},{"atb":[[42,3.26],[55,2.72]],"id":41419615},{"atb":[[30,10.15]],"id":41419624},{"atb":[[90,3.26]],"id":41419595}],"con":true,"img":false}]}
{"op":"mcm","clk":"5353316162","pt":1646212866937,"mc":[{"id":"1.195503868","rc":[{"atb":[[27,3.26]],"id":41419617},{"atb":[[13.5,3.26]],"id":41419613},{"atb":[[200,3.26],[250,2.72]],"id":41419593},{"atb":[[150,2.72],[100,5.28]],"id":41435527},{"atb":[[360,2.72]],"id":41419651},{"atb":[[27,2.72]],"id":41419618},{"atb":[[130,2.72]],"id":41419597},{"atb":[[110,3.26]],"id":41419659},{"atb":[[10,3.26],[12.5,2.72]],"id":41419606},{"atb":[[85,5.1],[60,3.26]],"id":41419602},{"atb":[[70,2.72],[48,3.26]],"id":41419614},{"atb":[[340,3.26]],"id":41419656},{"atb":[[190,3.26]],"id":41419652},{"atb":[[120,2.72]],"id":41419594},{"atb":[[44,3.26],[60,2.72]],"id":41419607},{"atb":[[18,3.26],[21,2.72]],"id":41419611},{"atb":[[300,2.72],[250,3.26]],"id":41419657},{"atb":[[40,2.72]],"id":41419624},{"atb":[[80,2.72]],"id":41419653},{"atb":[[130,2.72]],"id":41419595},{"atb":[[34,3.26]],"id":41419608},{"atb":[[20,13.78],[25,2.72]],"id":41419616},{"atb":[[9.8,2.72],[8.8,3.26]],"id":41419588},{"atb":[[160,3.26],[210,2.72]],"id":41419600},{"atb":[[40,3.26],[50,6.8]],"id":41419629},{"atb":[[160,2.72],[110,3.26]],"id":41419596},{"atb":[[160,2.72],[110,3.26]],"id":41419658}],"con":true,"img":false}]}
{"op":"mcm","clk":"5353316178","pt":1646212867147,"mc":[{"id":"1.195503868","rc":[{"atb":[[34,2.72]],"id":41419617},{"atb":[[23,3.26]],"id":41419610},{"atb":[[390,2.72]],"id":41419656},{"atb":[[55,3.26]],"id":41419653},{"atb":[[44,7.37]],"id":41419608}],"con":true,"img":false}]}
{"op":"mcm","clk":"5353330620","pt":1646213109663,"mc":[{"id":"1.195503868","rc":[{"atb":[[18.5,0],[22,0]],"id":41419609},{"atb":[[10,0],[12.5,0]],"id":41419589},{"atb":[[10,0],[12.5,0]],"id":41419606},{"atb":[[9.2,0],[8.2,0]],"id":41419590},{"atb":[[19.5,0],[24,0]],"id":41419586}],"con":true,"img":false}]}
{"op":"mcm","clk":"5353330635","pt":1646213109872,"mc":[{"id":"1.195503868","rc":[{"atb":[[22,0]],"id":41419618},{"atb":[[42,0],[55,0]],"id":41419615},{"atb":[[7.4,0],[8.4,0]],"id":41419587}],"con":true,"img":false}]}
{"op":"mcm","clk":"5353330664","pt":1646213110380,"mc":[{"id":"1.195503868","rc":[{"atb":[[19,14.37],[23,2.72]],"id":41419609},{"atb":[[12,2.72],[9.8,25.97]],"id":41419589},{"atb":[[12,2.72],[9.8,3.26]],"id":41419606},{"atb":[[8.8,2.72],[7.8,3.26]],"id":41419590},{"atb":[[19,3.26],[23,11.8]],"id":41419586}],"con":true,"img":false}]}
{"op":"mcm","clk":"5353330674","pt":1646213110544,"mc":[{"id":"1.195503868","rc":[{"atb":[[24,11.95]],"id":41419618},{"atb":[[44,3.26],[60,2.72]],"id":41419615},{"atb":[[8,2.72],[7,3.26]],"id":41419587}],"con":true,"img":false}]}
{"op":"mcm","clk":"5353338326","pt":1646213243911,"mc":[{"id":"1.195503868","rc":[{"atb":[[34,0],[36,2.72],[27,0],[28,3.26]],"id":41419617},{"atb":[[70,0],[75,2.72],[48,0],[50,3.26]],"id":41419614},{"atb":[[23,0],[28,0]],"id":41419610},{"atb":[[80,0],[55,0]],"id":41419604},{"atb":[[70,0],[95,0]],"id":41419621}],"con":true,"img":false}]}
{"op":"mcm","clk":"5353338335","pt":1646213244017,"mc":[{"id":"1.195503868","rc":[{"atb":[[200,0],[250,0]],"id":41419593},{"atb":[[140,2.72],[150,0],[95,3.26],[100,2.01]],"id":41435527},{"atb":[[75,0],[50,0]],"id":41419601},{"atb":[[130,0],[90,0]],"id":41419597},{"atb":[[160,0],[110,0]],"id":41419659},{"atb":[[32,0],[26,0]],"id":41419585},{"atb":[[340,0],[350,3.26],[390,0],[400,2.72]],"id":41419656},{"atb":[[34,2.72],[36,0],[27,3.26],[28,0]],"id":41419623},{"atb":[[22,0],[27,0]],"id":41419631},{"atb":[[12,3.26],[12.5,0],[14.5,2.72],[15,0]],"id":41419627},{"atb":[[85,0],[120,0]],"id":41419594},{"atb":[[44,0],[60,0]],"id":41419607},{"atb":[[300,0],[250,0]],"id":41419657},{"atb":[[32,0],[26,7.98]],"id":41419632},{"atb":[[20,10.51],[22,3.26],[25,0],[27,2.72]],"id":41419616},{"atb":[[38,0],[29,0]],"id":41419625},{"atb":[[75,0],[50,0]],"id":41419654},{"atb":[[40,0],[50,4.07]],"id":41419629},{"atb":[[160,0],[170,2.72],[110,0],[120,3.26]],"id":41419658}],"con":true,"img":false}]}
{"op":"mcm","clk":"5353338343","pt":1646213244119,"mc":[{"id":"1.195503868","rc":[{"atb":[[75,0],[50,0]],"id":41419622},{"atb":[[12,0],[9.8,22.7]],"id":41419589},{"atb":[[140,0],[190,0]],"id":41435528},{"atb":[[75,0],[100,0]],"id":41419603},{"atb":[[44,0],[60,0]],"id":41419615},{"atb":[[40,0],[30,6.88]],"id":41419624},{"atb":[[85,2.72],[60,3.26]],"id":41419653},{"atb":[[85,0],[60,0]],"id":41419592},{"atb":[[160,0],[210,0]],"id":41419600},{"atb":[[160,0],[110,0]],"id":41419596}],"con":true,"img":false}]}
{"op":"mcm","clk":"5353338349","pt":1646213244222,"mc":[{"id":"1.195503868","rc":[{"atb":[[19,11.1],[23,0]],"id":41419609},{"atb":[[16,0],[17,2.72],[13.5,0],[14.5,3.26]],"id":41419613},{"atb":[[310,0],[320,3.26],[360,0],[370,2.72]],"id":41419651},{"atb":[[24,8.68],[27,0],[29,2.72]],"id":41419618},{"atb":[[19,0],[23,0]],"id":41419630},{"atb":[[12,0],[9.8,0]],"id":41419606},{"atb":[[85,2.37],[60,0]],"id":41419602},{"atb":[[8.8,0],[7.8,0]],"id":41419590},{"atb":[[180,3.26],[190,0],[230,2.72],[240,0]],"id":41419652},{"atb":[[19,0],[23,9.07]],"id":41419586},{"atb":[[18,0],[21,0]],"id":41419611},{"atb":[[65,3.12],[46,0]],"id":41435525},{"atb":[[80,0],[55,0]],"id":41419653},{"atb":[[8,0],[7,0]],"id":41419587},{"atb":[[34,0],[44,4.64]],"id":41419608},{"atb":[[80,0],[110,0]],"id":41435526}],"con":true,"img":false}]}
{"op":"mcm","clk":"5353338354","pt":1646213244325,"mc":[{"id":"1.195503868","rc":[{"atb":[[20,0],[25,0]],"id":41419620},{"atb":[[130,0],[140,2.72],[90,0],[95,3.26]],"id":41419595}],"con":true,"img":false}]}
{"op":"mcm","clk":"5353338374","pt":1646213244634,"mc":[{"id":"1.195503868","rc":[{"atb":[[38,0],[29,0]],"id":28546943}],"con":true,"img":false}]}
{"op":"mcm","clk":"5353338379","pt":1646213244737,"mc":[{"id":"1.195503868","rc":[{"atb":[[36,2.72],[28,3.26]],"id":28546943},{"atb":[[9.6,2.72],[8.6,3.26],[9.8,0],[8.8,0]],"id":41419588}],"con":true,"img":false}]}
{"op":"mcm","clk":"5353338383","pt":1646213244842,"mc":[{"id":"1.195503868","rc":[{"atb":[[200,3.26],[250,2.72]],"id":41419593},{"atb":[[75,2.72],[50,3.26]],"id":41419622},{"atb":[[12,2.72],[9.8,25.97]],"id":41419589},{"atb":[[75,2.72],[50,3.26]],"id":41419601},{"atb":[[130,2.72],[90,3.26]],"id":41419597},{"atb":[[160,2.72],[110,3.26]],"id":41419659},{"atb":[[32,2.72],[26,3.26]],"id":41419585},{"atb":[[23,3.26],[28,2.72]],"id":41419610},{"atb":[[140,3.26],[190,2.72]],"id":41435528},{"atb":[[22,3.26],[27,2.72]],"id":41419631},{"atb":[[85,3.26],[120,2.72]],"id":41419594},{"atb":[[44,3.26],[60,2.72]],"id":41419607},{"atb":[[44,3.26],[60,2.72]],"id":41419615},{"atb":[[300,2.72],[250,3.26]],"id":41419657},{"atb":[[40,2.72],[30,10.15]],"id":41419624},{"atb":[[32,2.72],[26,11.25]],"id":41419632},{"atb":[[80,2.72],[55,3.26]],"id":41419604},{"atb":[[38,2.72],[29,3.26]],"id":41419625},{"atb":[[85,2.72],[60,3.26]],"id":41419592},{"atb":[[75,2.72],[50,3.26]],"id":41419654},{"atb":[[70,3.26],[95,2.72]],"id":41419621},{"atb":[[40,3.26],[50,6.8]],"id":41419629}],"con":true,"img":false}]}
{"op":"mcm","clk":"5353338387","pt":1646213244892,"mc":[{"id":"1.195503868","rc":[{"atb":[[19,14.37],[23,2.72]],"id":41419609},{"atb":[[24,11.95]],"id":41419618},{"atb":[[19,3.26],[23,2.72]],"id":41419630},{"atb":[[85,5.1],[60,3.26]],"id":41419602},{"atb":[[8.8,2.72],[7.8,3.26]],"id":41419590},{"atb":[[75,3.26],[100,2.72]],"id":41419603},{"atb":[[65,5.84],[46,3.26]],"id":41435525},{"atb":[[8,2.72],[7,3.26]],"id":41419587},{"atb":[[34,3.26],[44,7.37]],"id":41419608},{"atb":[[80,3.26],[110,2.72]],"id":41435526},{"atb":[[160,3.26],[210,2.72]],"id":41419600},{"atb":[[160,2.72],[110,3.26]],"id":41419596}],"con":true,"img":false}]}
{"op":"mcm","clk":"5353338392","pt":1646213244996,"mc":[{"id":"1.195503868","rc":[{"atb":[[12,2.72],[9.8,3.26]],"id":41419606},{"atb":[[19,3.26],[23,11.8]],"id":41419586},{"atb":[[18,3.26],[21,2.72]],"id":41419611},{"atb":[[20,3.26],[25,2.72]],"id":41419620},{"atb":[[65,0],[46,0]],"id":41419628}],"con":true,"img":false}]}
{"op":"mcm","clk":"5353338437","pt":1646213245715,"mc":[{"id":"1.195503868","rc":[{"atb":[[65,2.72],[46,3.26]],"id":41419628}],"con":true,"img":false}]}
{"op":"mcm","clk":"5353375550","pt":1646213920692,"mc":[{"id":"1.195503868","rc":[{"atb":[[200,0],[250,0]],"id":41419593},{"atb":[[140,0],[95,0]],"id":41435527},{"atb":[[24,8.68],[29,0]],"id":41419618},{"atb":[[19,0],[23,0]],"id":41419630},{"atb":[[130,0],[90,0]],"id":41419597},{"atb":[[350,0],[400,0]],"id":41419656},{"atb":[[8.8,0],[7.8,0]],"id":41419590},{"atb":[[22,0],[27,0]],"id":41419631},{"atb":[[12,0],[14.5,0]],"id":41419627},{"atb":[[18,0],[21,0]],"id":41419611},{"atb":[[300,0],[250,0]],"id":41419657},{"atb":[[32,0],[26,7.98]],"id":41419632},{"atb":[[80,0],[55,0]],"id":41419604},{"atb":[[85,0],[60,0]],"id":41419592},{"atb":[[75,0],[50,0]],"id":41419654},{"atb":[[70,0],[95,0]],"id":41419621},{"atb":[[40,0],[50,4.07]],"id":41419629}],"con":true,"img":false}]}
{"op":"mcm","clk":"5353375555","pt":1646213920751,"mc":[{"id":"1.195503868","rc":[{"atb":[[85,2.37],[60,0]],"id":41419602},{"atb":[[8,0],[7,0]],"id":41419587},{"atb":[[65,0],[46,0]],"id":41419628}],"con":true,"img":false}]}
{"op":"mcm","clk":"5353375567","pt":1646213920957,"mc":[{"id":"1.195503868","rc":[{"atb":[[320,0],[370,0]],"id":41419651},{"atb":[[180,0],[230,0]],"id":41419652},{"atb":[[140,0],[190,0]],"id":41435528},{"atb":[[20,0],[25,0]],"id":41419620}],"con":true,"img":false}]}
{"op":"mcm","clk":"5353375592","pt":1646213921365,"mc":[{"id":"1.195503868","rc":[{"atb":[[260,2.72],[210,3.26]],"id":41419593},{"atb":[[150,2.72],[100,5.28]],"id":41435527},{"atb":[[25,3.26],[30,2.72]],"id":41419618},{"atb":[[20,3.26],[25,2.72]],"id":41419630},{"atb":[[140,2.72],[95,6.1]],"id":41419597},{"atb":[[360,3.26],[410,2.72]],"id":41419656},{"atb":[[9.2,2.72],[8.2,3.26]],"id":41419590},{"atb":[[24,3.26],[29,2.72]],"id":41419631},{"atb":[[13,3.26],[15.5,2.72]],"id":41419627},{"atb":[[18.5,3.26],[22,2.72]],"id":41419611},{"atb":[[260,3.26],[310,2.72]],"id":41419657},{"atb":[[85,2.72],[60,6.65]],"id":41419604},{"atb":[[65,3.26],[90,2.72]],"id":41419592},{"atb":[[80,2.72],[55,3.26]],"id":41419654},{"atb":[[75,3.26],[100,2.72]],"id":41419621},{"atb":[[42,3.26],[55,2.72]],"id":41419629}],"con":true,"img":false}]}
{"op":"mcm","clk":"5353375609","pt":1646213921672,"mc":[{"id":"1.195503868","rc":[{"atb":[[65,3.26],[90,2.72]],"id":41419602},{"atb":[[19.5,3.26],[24,2.72]],"id":41419620},{"atb":[[6.8,3.26],[7.8,2.72]],"id":41419587},{"atb":[[34,2.72],[27,3.26]],"id":41419632},{"atb":[[70,2.72],[48,3.26]],"id":41419628}],"con":true,"img":false}]}
{"op":"mcm","clk":"5353375623","pt":1646213921982,"mc":[{"id":"1.195503868","rc":[{"atb":[[330,3.26],[380,2.72]],"id":41419651},{"atb":[[190,3.26],[240,2.72]],"id":41419652},{"atb":[[150,3.26],[200,2.72]],"id":41435528}],"con":true,"img":false}]}
{"op":"mcm","clk":"5353506697","pt":1646215870228,"mc":[{"id":"1.195503868","rc":[{"atb":[[19.5,0],[24,0]],"id":41419620},{"atb":[[6.8,0],[7.8,0]],"id":41419587},{"atb":[[9.6,0],[8.6,0]],"id":41419588}],"con":true,"img":false}]}
{"op":"mcm","clk":"5353506751","pt":1646215870960,"mc":[{"id":"1.195503868","rc":[{"atb":[[20,3.26],[25,2.72]],"id":41419620},{"atb":[[8,2.72],[7,3.26]],"id":41419587},{"atb":[[9.8,2.72],[8.8,3.26]],"id":41419588}],"con":true,"img":false}]}
{"op":"mcm","clk":"5353512561","pt":1646215935725,"mc":[{"id":"1.195503868","rc":[{"atb":[[34,0],[27,0]],"id":41419623}],"con":true,"img":false}]}
{"op":"mcm","clk":"5353512598","pt":1646215936041,"mc":[{"id":"1.195503868","rc":[{"atb":[[9.2,0],[8.2,0]],"id":41419590},{"atb":[[13,0],[15.5,0]],"id":41419627},{"atb":[[38,0],[29,0]],"id":41419625},{"atb":[[9.8,0],[8.8,0]],"id":41419588}],"con":true,"img":false}]}
{"op":"mcm","clk":"5353512647","pt":1646215936457,"mc":[{"id":"1.195503868","rc":[{"atb":[[36,2.72],[28,3.26]],"id":41419623}],"con":true,"img":false}]}
{"op":"mcm","clk":"5353512690","pt":1646215936829,"mc":[{"id":"1.195503868","rc":[{"atb":[[8.4,3.26],[9.4,2.72]],"id":41419590},{"atb":[[16,2.72],[13.5,3.26]],"id":41419627},{"atb":[[40,2.72],[30,3.26]],"id":41419625},{"atb":[[9.6,2.72],[8.6,3.26]],"id":41419588}],"con":true,"img":false}]}
{"op":"mcm","clk":"5353513969","pt":1646215949680,"mc":[{"id":"1.195503868","rc":[{"atb":[[4.5,28.57]],"id":41419609},{"atl":[[520,2]],"id":41419609},{"atb":[[6.8,13.78]],"id":41419617},{"atl":[[720,2]],"id":41419617},{"atb":[[4.9,25.64]],"id":41419613},{"atl":[[540,2]],"id":41419613},{"atb":[[29,2]],"id":41419593},{"atb":[[26,4]],"id":41419622},{"atl":[[1000,2]],"id":41419622},{"atb":[[3.85,35.09]],"id":41419589},{"atl":[[410,2]],"id":41419589},{"atb":[[29,3.57]],"id":41435527},{"atb":[[30,2]],"id":41419651},{"atb":[[6.6,17.38]],"id":41419618},{"atl":[[680,2]],"id":41419618},{"atb":[[22,4.76]],"id":41419601},{"atl":[[1000,2]],"id":41419601},{"atb":[[5.5,22.22]],"id":41419630},{"atl":[[570,2]],"id":41419630},{"atb":[[27,3.78]],"id":41419597},{"atb":[[11.5,8.5]],"id":28546943},{"atl":[[1000,2]],"id":28546943},{"atb":[[29,3.57]],"id":41419659},{"atb":[[3.95,33.9]],"id":41419606},{"atl":[[430,2]],"id":41419606},{"atb":[[4.4,8.5]],"id":41419585},{"atl":[[630,2]],"id":41419585},{"atb":[[25,3.16]],"id":41419614},{"atl":[[1000,2]],"id":41419614},{"atb":[[5.5,19.98]],"id":41419610},{"atl":[[570,2]],"id":41419610},{"atb":[[30,2]],"id":41419656},{"atb":[[6.4,18.16]],"id":41419623},{"atl":[[660,2]],"id":41419623},{"atb":[[3.7,37.04]],"id":41419590},{"atl":[[390,2]],"id":41419590},{"atb":[[29,2]],"id":41419652},{"atb":[[29,2]],"id":41435528},{"atb":[[5.7,21.28]],"id":41419586},{"atl":[[580,2]],"id":41419586},{"atb":[[6.2,18.16]],"id":41419631},{"atl":[[620,2]],"id":41419631},{"atb":[[4.9,25.64]],"id":41419627},{"atl":[[540,2]],"id":41419627},{"atb":[[26,4]],"id":41419594},{"atb":[[13.5,6.24]],"id":41419607},{"atl":[[990,2]],"id":41419607},{"atb":[[11.5,9.52]],"id":28546950},{"atb":[[26,14.65]],"id":41419603},{"atb":[[20,19.28]],"id":41419615},{"atl":[[1000,2]],"id":41419615},{"atb":[[5.1,24.39]],"id":41419611},{"atl":[[550,2]],"id":41419611},{"atb":[[30,2]],"id":41419657},{"atb":[[7,16.67]],"id":41419624},{"atl":[[750,2]],"id":41419624},{"atb":[[27,3.85]],"id":41435525},{"atb":[[28,3.16]],"id":41419653},{"atb":[[6,20]],"id":41419620},{"atl":[[610,2]],"id":41419620},{"atb":[[3.15,46.51]],"id":41419587},{"atl":[[250,2]],"id":41419587},{"atb":[[6.8,15.98]],"id":41419632},{"atl":[[700,2]],"id":41419632},{"atb":[[11.5,9.52]],"id":41419599},{"atl":[[1000,2]],"id":41419599},{"atb":[[25,4.17]],"id":41419628},{"atl":[[1000,2]],"id":41419628},{"atb":[[27,2.24]],"id":41419595},{"atb":[[9.2,12.2]],"id":41419608},{"atl":[[880,2]],"id":41419608},{"atb":[[26,4]],"id":41419604},{"atb":[[5.4,21.02]],"id":41419616},{"atl":[[560,2]],"id":41419616},{"atb":[[7.4,15.36]],"id":41419625},{"atl":[[820,2]],"id":41419625},{"atb":[[11.5,6.54]],"id":41419592},{"atl":[[1000,2]],"id":41419592},{"atb":[[28,3.7]],"id":41419654},{"atb":[[29,2]],"id":41435526},{"atb":[[27,2]],"id":41419621},{"atb":[[3.5,40]],"id":41419588},{"atl":[[340,2]],"id":41419588},{"atb":[[28,2]],"id":41419600},{"atb":[[20,5.26]],"id":41419629},{"atl":[[1000,2]],"id":41419629},{"atb":[[27,2]],"id":41419596},{"atb":[[29,2.24]],"id":41419658}],"con":true,"img":false}]}
{"op":"mcm","clk":"5353513978","pt":1646215949736,"mc":[{"id":"1.195503868","rc":[{"atb":[[26,4]],"id":41419602},{"atl":[[1000,2]],"id":41419602}],"con":true,"img":false}]}
{"op":"mcm","clk":"5353515149","pt":1646215961877,"mc":[{"id":"1.195503868","rc":[{"atb":[[22,0],[27,0]],"id":41419616}],"con":true,"img":false}]}
{"op":"mcm","clk":"5353515164","pt":1646215962084,"mc":[{"id":"1.195503868","rc":[{"atb":[[19,11.1],[23,0]],"id":41419609}],"con":true,"img":false}]}
{"op":"mcm","clk":"5353515238","pt":1646215962773,"mc":[{"id":"1.195503868","rc":[{"atb":[[18.5,3.26],[22,2.72]],"id":41419609},{"atb":[[20,13.78],[25,2.72]],"id":41419616}],"con":true,"img":false}]}
{"op":"mcm","clk":"5353584789","pt":1646216514818,"mc":[{"id":"1.195503868","rc":[{"atb":[[20,10.51],[25,0]],"id":41419616}],"con":true,"img":false}]}
{"op":"mcm","clk":"5353584882","pt":1646216515660,"mc":[{"id":"1.195503868","rc":[{"atb":[[21,3.26],[26,2.72]],"id":41419616}],"con":true,"img":false}]}
{"op":"mcm","clk":"5353616842","pt":1646216823068,"mc":[{"id":"1.195503868","rc":[{"atb":[[22,4.76]],"id":41419607}],"con":true,"img":false}]}
{"op":"mcm","clk":"5353616853","pt":1646216823225,"mc":[{"id":"1.195503868","rc":[{"atb":[[4.5,0],[5.2,23.81]],"id":41419609},{"atl":[[670,2],[720,0]],"id":41419617},{"atl":[[540,0],[520,2]],"id":41419613},{"atl":[[1000,0]],"id":41419622},{"atl":[[600,2],[680,0]],"id":41419618},{"atb":[[22,0],[28,3.7]],"id":41419601},{"atl":[[520,2],[570,0]],"id":41419630},{"atl":[[1000,0]],"id":28546943},{"atb":[[3.95,0],[4.4,29.41]],"id":41419606},{"atl":[[1000,0]],"id":41419602},{"atb":[[6.4,18.52],[5.5,0]],"id":41419610},{"atl":[[330,2],[390,0]],"id":41419590},{"atb":[[5.7,0],[6.6,17.86]],"id":41419586},{"atl":[[540,2],[620,0]],"id":41419631},{"atl":[[540,0],[470,2]],"id":41419627},{"atb":[[13.5,0]],"id":41419607},{"atl":[[540,2],[550,0]],"id":41419611},{"atl":[[720,2],[750,0]],"id":41419624},{"atl":[[600,2],[610,0]],"id":41419620},{"atb":[[3.45,40.82],[3.15,0]],"id":41419587},{"atl":[[590,2],[700,0]],"id":41419632},{"atb":[[9.2,0],[14,7.69]],"id":41419608},{"atb":[[5.9,20.41],[5.4,0]],"id":41419616},{"atl":[[560,0],[550,2]],"id":41419616},{"atl":[[720,2],[820,0]],"id":41419625},{"atl":[[320,2],[340,0]],"id":41419588},{"atb":[[17,6.25],[20,0]],"id":41419629},{"atl":[[980,2],[1000,0]],"id":41419629}],"con":true,"img":false}]}
{"op":"mcm","clk":"5353619828","pt":1646216852916,"mc":[{"id":"1.195503868","rc":[{"atl":[[630,0],[610,2]],"id":41419585},{"atl":[[990,2]],"id":41419599},{"atb":[[17,0],[22,4.76]],"id":41419629}],"con":true,"img":false}]}
{"op":"mcm","clk":"5353619837","pt":1646216853018,"mc":[{"id":"1.195503868","rc":[{"atl":[[520,0],[510,2]],"id":41419609},{"atl":[[1000,2]],"id":41419622},{"atl":[[410,0],[400,2]],"id":41419589},{"atl":[[1000,2]],"id":28546943},{"atl":[[430,0],[420,2]],"id":41419606},{"atl":[[1000,2]],"id":41419602},{"atl":[[570,0],[550,2]],"id":41419610},{"atl":[[660,0],[640,2]],"id":41419623},{"atb":[[3.95,33.9],[3.7,0]],"id":41419590},{"atl":[[560,2],[580,0]],"id":41419586},{"atb":[[22,0],[14.5,6.39]],"id":41419607},{"atl":[[950,2],[990,0]],"id":41419607},{"atl":[[600,0],[590,2]],"id":41419620},{"atl":[[230,2],[250,0]],"id":41419587},{"atl":[[1000,0]],"id":41419599},{"atb":[[10,11.11],[14,0]],"id":41419608},{"atl":[[840,2],[880,0]],"id":41419608},{"atb":[[3.5,0],[3.75,36.36]],"id":41419588}],"con":true,"img":false}]}
{"op":"mcm","clk":"5353631540","pt":1646216972994,"mc":[{"id":"1.195503868","rc":[{"atb":[[4.5,28.57],[5.2,0]],"id":41419609},{"atl":[[520,2],[510,0]],"id":41419609},{"atl":[[400,0],[410,2]],"id":41419589},{"atb":[[22,4.76],[28,0]],"id":41419601},{"atl":[[420,0],[430,2]],"id":41419606},{"atl":[[610,0],[630,2]],"id":41419585},{"atb":[[6.4,0],[5.5,22.22]],"id":41419610},{"atl":[[550,0],[570,2]],"id":41419610},{"atl":[[640,0],[660,2]],"id":41419623},{"atb":[[5.7,21.28],[6.6,0]],"id":41419586},{"atl":[[560,0],[580,2]],"id":41419586},{"atl":[[950,0],[990,2]],"id":41419607},{"atl":[[590,0],[600,2]],"id":41419620},{"atb":[[3.45,0],[3.15,46.51]],"id":41419587},{"atl":[[230,0],[250,2]],"id":41419587},{"atl":[[990,0],[1000,2]],"id":41419599},{"atl":[[840,0],[880,2]],"id":41419608}],"con":true,"img":false}]}
{"op":"mcm","clk":"5353686512","pt":1646217542148,"mc":[{"id":"1.195503868","rc":[{"atb":[[12,0],[9.8,22.7]],"id":41419589},{"atb":[[23,0],[28,0]],"id":41419610},{"atb":[[9.6,0],[8.6,0]],"id":41419588}],"con":true,"img":false}]}
{"op":"mcm","clk":"5353686589","pt":1646217542843,"mc":[{"id":"1.195503868","rc":[{"atb":[[22,3.26],[27,2.72]],"id":41419610},{"atb":[[9.8,2.72],[8.8,3.26]],"id":41419588}],"con":true,"img":false}]}
{"op":"mcm","clk":"5353686604","pt":1646217542948,"mc":[{"id":"1.195503868","rc":[{"atb":[[10,3.26],[12.5,2.72]],"id":41419589}],"con":true,"img":false}]}
{"op":"mcm","clk":"5353686613","pt":1646217543051,"mc":[{"id":"1.195503868","rc":[{"atb":[[4.5,0],[5,25]],"id":41419609},{"atl":[[1000,0]],"id":41419622},{"atb":[[3.85,0],[4.2,31.25]],"id":41419589},{"atb":[[6.4,18.52],[5.5,0]],"id":41419610},{"atl":[[570,2],[580,0]],"id":41419586},{"atl":[[990,0],[980,2]],"id":41419607},{"atb":[[3.15,0],[3.5,40]],"id":41419587},{"atl":[[880,0]],"id":41419608},{"atb":[[16,6.67],[22,0]],"id":41419629},{"atl":[[980,0],[970,2]],"id":41419629}],"con":true,"img":false}]}
{"op":"mcm","clk":"5353686621","pt":1646217543153,"mc":[{"id":"1.195503868","rc":[{"atl":[[870,2]],"id":41419608}],"con":true,"img":false}]}
{"op":"mcm","clk":"5353693399","pt":1646217603499,"mc":[{"id":"1.195503868","rc":[{"atb":[[18.5,0],[22,0]],"id":41419611}],"con":true,"img":false}]}
{"op":"mcm","clk":"5353693478","pt":1646217604232,"mc":[{"id":"1.195503868","rc":[{"atb":[[18,3.26],[21,2.72]],"id":41419611}],"con":true,"img":false}]}
{"op":"mcm","clk":"5353694107","pt":1646217609204,"mc":[{"id":"1.195503868","rc":[{"atb":[[20,0],[25,0]],"id":41419630},{"atb":[[16,0],[13.5,0]],"id":41419627}],"con":true,"img":false}]}
{"op":"mcm","clk":"5353694206","pt":1646217610025,"mc":[{"id":"1.195503868","rc":[{"atb":[[19.5,3.26],[24,2.72]],"id":41419630},{"atb":[[13,3.26],[15.5,2.72]],"id":41419627}],"con":true,"img":false}]}
{"op":"mcm","clk":"5353700599","pt":1646217663130,"mc":[{"id":"1.195503868","rc":[{"atb":[[4.8,26.32],[5.5,0]],"id":41419630},{"atl":[[1000,0]],"id":28546943},{"atb":[[3.95,0],[3.65,37.74]],"id":41419590},{"atb":[[6.2,0],[5.5,22.22]],"id":41419631},{"atb":[[4.3,30.3],[4.9,0]],"id":41419627},{"atb":[[5.3,23.26],[5.9,0]],"id":41419616}],"con":true,"img":false}]}
{"op":"mcm","clk":"5353756612","pt":1646218122868,"mc":[{"id":"1.195503868","rc":[{"atb":[[8.2,12.75]],"id":28546943},{"atb":[[11,2.45],[30,0]],"id":41419656},{"atb":[[3.1,47.62],[3.5,0]],"id":41419587},{"atb":[[11.5,0]],"id":41419599},{"atb":[[3.35,42.55]],"id":41419588}],"con":true,"img":false}]}
{"op":"mcm","clk":"5353756617","pt":1646218122971,"mc":[{"id":"1.195503868","rc":[{"atb":[[11,2.45],[30,0]],"id":41419651},{"atb":[[11.5,0]],"id":28546943},{"atb":[[16.5,6.45]],"id":41419599},{"atb":[[3.75,0]],"id":41419588}],"con":true,"img":false}]}
{"op":"mcm","clk":"5353756655","pt":1646218123334,"mc":[{"id":"1.195503868","rc":[{"atb":[[24,0],[29,0]],"id":41419631}],"con":true,"img":false}]}
{"op":"mcm","clk":"5353756731","pt":1646218124173,"mc":[{"id":"1.195503868","rc":[{"atb":[[23,12.34],[28,2.72]],"id":41419631}],"con":true,"img":false}]}
{"op":"mcm","clk":"5353757120","pt":1646218128664,"mc":[{"id":"1.195503868","rc":[{"atb":[[5.6,21.74],[5,0]],"id":41419609},{"atb":[[5.5,22.22],[4.9,0]],"id":41419613},{"atl":[[520,0],[510,2]],"id":41419613},{"atb":[[22,0],[28,3.7]],"id":41419601},{"atl":[[1000,0]],"id":41419602},{"atb":[[5.7,0],[6.6,17.86]],"id":41419586},{"atb":[[22,4.76],[14.5,0]],"id":41419607},{"atb":[[5.1,0],[5.9,20.41]],"id":41419611},{"atl":[[540,0],[530,2]],"id":41419611},{"atb":[[10,0],[14,7.69]],"id":41419608},{"atb":[[6.4,18.52],[5.3,0]],"id":41419616},{"atl":[[540,2],[550,0]],"id":41419616}],"con":true,"img":false}]}
{"op":"mcm","clk":"5353758238","pt":1646218143002,"mc":[{"id":"1.195503868","rc":[{"atl":[[520,0],[510,2]],"id":41419609},{"atl":[[1000,2]],"id":28546943},{"atl":[[1000,2]],"id":41419602},{"atb":[[4.3,0],[4.9,25.64]],"id":41419627},{"atb":[[16.5,6.39],[22,0]],"id":41419607},{"atl":[[530,0],[520,2]],"id":41419611},{"atb":[[11,10],[14,0]],"id":41419608}],"con":true,"img":false}]}
{"op":"mcm","clk":"5353762897","pt":1646218201091,"mc":[{"id":"1.195503868","rc":[{"atb":[[36,0],[28,0]],"id":28546943},{"atb":[[32,0],[26,0]],"id":41419585},{"atb":[[8.4,0],[9.4,0]],"id":41419590},{"atb":[[8,0],[7,0]],"id":41419587},{"atb":[[9.8,0],[8.8,0]],"id":41419588}],"con":true,"img":false}]}
{"op":"mcm","clk":"5353762951","pt":1646218201780,"mc":[{"id":"1.195503868","rc":[{"atb":[[38,2.72],[29,3.26]],"id":28546943},{"atb":[[34,2.72],[27,3.26]],"id":41419585},{"atb":[[9.6,2.72],[8.6,3.26]],"id":41419590},{"atb":[[7.2,3.26],[8.2,2.72]],"id":41419587},{"atb":[[9,28.24],[10,2.72]],"id":41419588}],"con":true,"img":false}]}
{"op":"mcm","clk":"5353769345","pt":1646218262953,"mc":[{"id":"1.195503868","rc":[{"atb":[[5.6,0],[5,25]],"id":41419609},{"atl":[[1000,0]],"id":28546943}],"con":true,"img":false}]}
{"op":"mcm","clk":"5353786272","pt":1646218469584,"mc":[{"id":"1.195503868","rc":[{"atb":[[160,0],[110,0]],"id":41419659},{"atb":[[23,9.07],[28,0]],"id":41419631},{"atb":[[13,0],[15.5,0]],"id":41419627},{"atb":[[21,0],[26,0]],"id":41419616}],"con":true,"img":false}]}
{"op":"mcm","clk":"5353786339","pt":1646218470372,"mc":[{"id":"1.195503868","rc":[{"atb":[[170,2.72],[120,3.26]],"id":41419659},{"atb":[[24,3.26],[29,2.72]],"id":41419631},{"atb":[[16,2.72],[13.5,3.26]],"id":41419627},{"atb":[[20,13.78],[25,2.72]],"id":41419616}],"con":true,"img":false}]}
{"op":"mcm","clk":"5353790116","pt":1646218503660,"mc":[{"id":"1.195503868","rc":[{"atb":[[8.6,0],[19,0],[11.5,0]],"id":41419609},{"atb":[[17.5,0],[12.5,0],[30,0]],"id":41419617},{"atb":[[6.2,0],[8.2,0],[13,0]],"id":41419613},{"atb":[[600,0],[700,0],[850,0]],"id":41419593},{"atb":[[38,0],[95,0],[24,0]],"id":41419622},{"atb":[[6.8,0],[9.8,0],[5.4,0]],"id":41419589},{"atb":[[100,3.26],[50,0],[250,0]],"id":41435527},{"atb":[[600,0],[700,0],[850,0]],"id":41419651},{"atb":[[24,0],[9.8,0],[14.5,0]],"id":41419618},{"atb":[[17,0],[48,0],[24,0]],"id":41419601},{"atb":[[17,0],[9.8,0],[7.8,0]],"id":41419630},{"atb":[[340,0],[190,0],[95,3.26]],"id":41419597},{"atb":[[17,0],[48,0],[24,0]],"id":28546943},{"atb":[[340,0],[190,0],[95,0]],"id":41419659},{"atb":[[4.3,0],[5.3,0],[7.6,0]],"id":41419606},{"atb":[[34,0],[85,0],[22,0]],"id":41419602},{"atb":[[17,0],[48,0],[24,0]],"id":41419585},{"atb":[[270,0],[170,0],[420,0]],"id":41419614},{"atb":[[9.2,0],[21,0],[13,0]],"id":41419610},{"atb":[[600,0],[700,0],[850,0]],"id":41419656},{"atb":[[9.6,0],[23,0],[14,0]],"id":41419623},{"atb":[[4.3,0],[5.3,0],[7.6,0]],"id":41419590},{"atb":[[600,0],[700,0],[850,0]],"id":41419652},{"atb":[[600,0],[350,0],[450,0]],"id":41435528},{"atb":[[9.6,0],[23,2.72],[14,0]],"id":41419586},{"atb":[[9.6,0],[23,0],[14,0]],"id":41419631},{"atb":[[9,0],[5,0],[6,0]],"id":41419627},{"atb":[[100,0],[50,0],[250,0]],"id":41419594},{"atb":[[65,0],[36,0],[180,0]],"id":41419607},{"atb":[[32,0],[80,3.26],[21,0]],"id":28546950},{"atb":[[42,0],[26,4],[110,0]],"id":41419603},{"atb":[[75,0],[20,5.26],[30,0]],"id":41419615},{"atb":[[16,0],[7.4,0],[9.4,0]],"id":41419611},{"atb":[[600,0],[700,0],[850,0]],"id":41419657},{"atb":[[17.5,0],[12.5,0],[30,3.26]],"id":41419624},{"atb":[[65,2.72],[36,0],[180,0]],"id":41435525},{"atb":[[270,0],[170,0],[420,0]],"id":41419653},{"atb":[[6.8,0],[8.8,0],[14.5,0]],"id":41419620},{"atb":[[4.5,0],[6,0],[3.75,0]],"id":41419587},{"atb":[[10.5,0],[26,0],[15.5,0]],"id":41419632},{"atb":[[17,0],[12,0],[29,0]],"id":41419599},{"atb":[[270,0],[120,0],[60,0]],"id":41419628},{"atb":[[340,0],[490,0],[240,0]],"id":41419595},{"atb":[[16,0],[44,2.72],[22,0]],"id":41419608},{"atb":[[18.5,0],[27,0],[60,3.26]],"id":41419604},{"atb":[[9,0],[20,3.26],[12.5,0]],"id":41419616},{"atb":[[16,0],[11,0],[27,0]],"id":41419625},{"atb":[[32,0],[80,0],[21,0]],"id":41419592},{"atb":[[270,0],[120,0],[60,0]],"id":41419654},{"atb":[[530,0],[280,0],[380,0]],"id":41435526},{"atb":[[530,0],[280,0],[380,0]],"id":41419621},{"atb":[[9,3.26],[5,0],[6,0]],"id":41419588},{"atb":[[600,0],[700,0],[850,0]],"id":41419600},{"atb":[[17.5,0],[50,0],[25,0]],"id":41419629},{"atb":[[600,0],[350,0],[450,0]],"id":41419596},{"atb":[[340,0],[490,0],[240,0]],"id":41419658}],"con":true,"img":false}]}
{"op":"mcm","clk":"5353790606","pt":1646218508393,"mc":[{"id":"1.195503868","rc":[{"atb":[[5.3,61.94],[11.5,12.68],[6.6,47.57]],"id":41419609},{"atb":[[17.5,8.07],[9,33.29],[7,44.4]],"id":41419617},{"atb":[[5.1,64.97],[8.2,18.49],[4.1,85.93]],"id":41419613},{"atb":[[700,0.19],[400,0.67],[500,0.53]],"id":41419593},{"atb":[[17,16.64],[38,3.6],[12,24.21]],"id":41419622},{"atb":[[3.7,98.66],[6.8,22.96],[4.4,78.34]],"id":41419589},{"atb":[[20,14.02],[100,4.61],[30,9.18]],"id":41435527},{"atb":[[700,0.19],[400,0.67],[500,0.53]],"id":41419651},{"atb":[[7.8,39.17],[14.5,9.86],[5.9,54.36]],"id":41419618},{"atb":[[24,5.79],[12,24.21],[8.8,34.15]],"id":41419601},{"atb":[[9.8,15.13],[4.9,68.3],[5.9,54.36]],"id":41419630},{"atb":[[190,0.7],[48,5.66],[29,9.51]],"id":41419597},{"atb":[[24,5.79],[12,24.21],[8.8,34.15]],"id":28546943},{"atb":[[190,0.7],[48,5.66],[29,13.08]],"id":41419659},{"atb":[[5.3,30.97],[3.15,123.9],[3.65,100.52]],"id":41419606},{"atb":[[16,17.76],[34,4.03],[11,26.63]],"id":41419602},{"atb":[[24,5.79],[12,24.21],[8.8,34.15]],"id":41419585},{"atb":[[270,0.49],[85,3.17],[44,6.19]],"id":41419614},{"atb":[[5.6,57.91],[7.2,42.96],[13,11.1]],"id":41419610},{"atb":[[700,0.19],[400,0.67],[500,0.53]],"id":41419656},{"atb":[[5.8,55.49],[7.6,40.36],[14,10.24]],"id":41419623},{"atb":[[5.3,30.97],[3.15,123.9],[3.65,138.26]],"id":41419590},{"atb":[[700,0.19],[400,0.67],[500,0.53]],"id":41419652},{"atb":[[150,5.05],[450,0.29],[250,1.06]],"id":41435528},{"atb":[[5.8,55.49],[7.6,40.36],[14,10.24]],"id":41419586},{"atb":[[5.8,55.49],[7.6,40.36],[14,10.24]],"id":41419631},{"atb":[[4,88.79],[6,26.63],[3.5,106.55]],"id":41419627},{"atb":[[20,14.02],[100,1.34],[30,9.18]],"id":41419594},{"atb":[[16.5,23.57],[65,2.08],[23,12.1]],"id":41419607},{"atb":[[32,4.29],[10.5,28.03],[15.5,18.37]],"id":28546950},{"atb":[[18,15.66],[42,3.24],[13,22.19]],"id":41419603},{"atb":[[10,29.59],[30,4.59],[15,19.02]],"id":41419615},{"atb":[[5.7,56.67],[9.4,15.85],[4.7,71.99]],"id":41419611},{"atb":[[700,0.19],[400,0.67],[500,0.53]],"id":41419657},{"atb":[[17.5,8.07],[9,33.29],[7,61.07]],"id":41419624},{"atb":[[65,4.8],[16.5,17.18],[23,12.1]],"id":41435525},{"atb":[[270,0.49],[85,5.89],[44,6.19]],"id":41419653},{"atb":[[8.8,17.07],[4.4,78.34],[5.4,60.54]],"id":41419620},{"atb":[[4.5,38.05],[2.9,140.2],[3.25,118.39]],"id":41419587},{"atb":[[6.2,51.22],[8.2,36.99],[15.5,9.18]],"id":41419632},{"atb":[[17,8.32],[6.8,45.93],[8.8,34.15]],"id":41419599},{"atb":[[34,8.07],[22,12.68],[120,1.11]],"id":41419628},{"atb":[[140,4.64],[70,3.85],[340,0.39]],"id":41419595},{"atb":[[11,36.63],[22,6.34],[8.4,35.99]],"id":41419608},{"atb":[[27,5.12],[13.5,21.3],[9.4,31.71]],"id":41419604},{"atb":[[5.5,59.19],[12.5,11.58],[7,44.4]],"id":41419616},{"atb":[[16,8.87],[6.4,49.33],[8.4,35.99]],"id":41419625},{"atb":[[32,4.29],[10.5,28.03],[15.5,18.37]],"id":41419592},{"atb":[[34,8.07],[22,12.68],[120,1.11]],"id":41419654},{"atb":[[180,1.48],[90,2.99],[380,0.34]],"id":41435526},{"atb":[[180,1.48],[90,2.99],[380,0.34]],"id":41419621},{"atb":[[4,88.79],[6,26.63],[3.5,106.55]],"id":41419588},{"atb":[[700,0.19],[400,0.67],[500,0.53]],"id":41419600},{"atb":[[9,33.29],[25,5.54],[12.5,23.16]],"id":41419629},{"atb":[[150,1.78],[450,0.29],[250,1.06]],"id":41419596},{"atb":[[140,1.91],[70,3.85],[340,0.39]],"id":41419658}],"con":true,"img":false}]}
{"op":"mcm","clk":"5353790617","pt":1646218508443,"mc":[{"id":"1.195503868","rc":[{"atl":[[1000,2]],"id":41419622},{"atl":[[410,0]],"id":41419589},{"atl":[[560,2]],"id":41419585},{"atl":[[540,2],[570,0]],"id":41419610},{"atb":[[16.5,17.18]],"id":41419607},{"atl":[[980,0]],"id":41419607},{"atl":[[1000,2]],"id":41419603},{"atb":[[16.5,0]],"id":41419599},{"atl":[[1000,0]],"id":41419599},{"atl":[[870,0]],"id":41419608},{"atl":[[540,0]],"id":41419616},{"atl":[[960,2],[1000,0]],"id":41419592},{"atl":[[1000,2]],"id":41419621}],"con":true,"img":false}]}
{"op":"mcm","clk":"5353790627","pt":1646218508550,"mc":[{"id":"1.195503868","rc":[{"atb":[[5,0],[6.2,19.23]],"id":41419609},{"atl":[[470,2],[510,0]],"id":41419609},{"atb":[[6.8,0],[8.8,12.82]],"id":41419617},{"atl":[[630,2],[670,0]],"id":41419617},{"atb":[[5.5,0]],"id":41419613},{"atl":[[510,0],[500,2]],"id":41419613},{"atb":[[38,2],[29,0]],"id":41419593},{"atb":[[34,3.03],[26,0]],"id":41419622},{"atb":[[4.2,0],[4.7,27.03]],"id":41419589},{"atl":[[390,2]],"id":41419589},{"atb":[[9,12.5],[6.6,0]],"id":41419618},{"atb":[[20,5.26],[28,0]],"id":41419601},{"atl":[[910,2],[1000,0]],"id":41419601},{"atb":[[4.8,0]],"id":41419630},{"atb":[[36,2.86],[27,0]],"id":41419597},{"atl":[[1000,2]],"id":28546943},{"atb":[[29,9.51]],"id":41419659},{"atl":[[390,2],[430,0]],"id":41419606},{"atl":[[920,2],[1000,0]],"id":41419602},{"atl":[[630,0]],"id":41419585},{"atb":[[19,5.56],[25,0]],"id":41419614},{"atl":[[900,2],[1000,0]],"id":41419614},{"atb":[[6.4,0],[7.6,15.15]],"id":41419610},{"atb":[[9,12.5],[6.4,0]],"id":41419623},{"atl":[[660,0],[640,2]],"id":41419623},{"atb":[[4.9,25.64],[3.65,100.52]],"id":41419590},{"atb":[[29,0]],"id":41419652},{"atb":[[40,2.56],[29,0]],"id":41435528},{"atl":[[540,2],[570,0]],"id":41419586},{"atb":[[5.5,0]],"id":41419631},{"atb":[[6.2,19.23],[4.9,0]],"id":41419627},{"atb":[[26,0]],"id":41419594},{"atl":[[1000,2]],"id":41419594},{"atb":[[9.6,6.54]],"id":41419607},{"atl":[[830,2]],"id":41419607},{"atb":[[26,0]],"id":41419603},{"atb":[[20,0],[14.5,6.54]],"id":41419615},{"atl":[[940,2],[1000,0]],"id":41419615},{"atb":[[8,14.29],[5.9,0]],"id":41419611},{"atb":[[40,2]],"id":41419657},{"atb":[[10,11.11],[7,44.4]],"id":41419624},{"atb":[[38,2.7],[28,0]],"id":41419653},{"atb":[[6,0]],"id":41419620},{"atl":[[540,2],[600,0]],"id":41419620},{"atb":[[3.1,0],[3.75,36.36]],"id":41419587},{"atb":[[6.8,0]],"id":41419632},{"atb":[[10.5,6.54]],"id":41419599},{"atl":[[860,2]],"id":41419599},{"atl":[[940,2],[1000,0]],"id":41419628},{"atb":[[34,3.03]],"id":41419595},{"atl":[[850,2]],"id":41419608},{"atl":[[1000,2]],"id":41419604},{"atb":[[6.4,0],[7.4,15.62]],"id":41419616},{"atl":[[530,2]],"id":41419616},{"atb":[[7.4,0],[9.4,11.9]],"id":41419625},{"atl":[[690,2],[720,0]],"id":41419625},{"atb":[[40,2.56],[29,0]],"id":41435526},{"atb":[[3.35,0]],"id":41419588},{"atb":[[38,2],[28,0]],"id":41419600},{"atb":[[16,0],[23,4.55]],"id":41419629},{"atl":[[900,2],[970,0]],"id":41419629},{"atb":[[34,3.03],[27,0]],"id":41419596},{"atl":[[1000,2]],"id":41419596},{"atb":[[40,2.56],[29,0]],"id":41419658}],"con":true,"img":false}]}
{"op":"mcm","clk":"5353790641","pt":1646218508653,"mc":[{"id":"1.195503868","rc":[{"atb":[[6,20]],"id":41419613},{"atb":[[8.2,13.89]],"id":41419630},{"atb":[[40,2.56]],"id":41419659},{"atl":[[540,0],[510,2]],"id":41419610},{"atb":[[40,2]],"id":41419652},{"atb":[[9,12.5]],"id":41419631},{"atb":[[34,3.03]],"id":41419594},{"atb":[[34,3.03]],"id":41419603},{"atb":[[30,0]],"id":41419657},{"atb":[[7.8,14.71]],"id":41419620},{"atb":[[8.6,13.16]],"id":41419632},{"atb":[[27,0]],"id":41419595},{"atb":[[40,2.56],[28,0]],"id":41419654},{"atb":[[4.3,30.3]],"id":41419588}],"con":true,"img":false}]}
{"op":"mcm","clk":"5353790666","pt":1646218508865,"mc":[{"id":"1.195503868","rc":[{"atb":[[34,0],[27,0]],"id":41419585}],"con":true,"img":false}]}
{"op":"mcm","clk":"5353790810","pt":1646218509851,"mc":[{"id":"1.195503868","rc":[{"atb":[[32,2.72],[26,3.26]],"id":41419585}],"con":true,"img":false}]}
{"op":"mcm","clk":"5353791475","pt":1646218514833,"mc":[{"id":"1.195503868","rc":[{"atl":[[700,2],[720,0]],"id":41419624}],"con":true,"img":false}]}
{"op":"mcm","clk":"5353791881","pt":1646218517947,"mc":[{"id":"1.195503868","rc":[{"atl":[[530,2],[560,0]],"id":41419585},{"atl":[[860,2],[960,0]],"id":41419592},{"atl":[[930,2],[1000,0]],"id":41419621}],"con":true,"img":false}]}
{"op":"mcm","clk":"5353791891","pt":1646218518051,"mc":[{"id":"1.195503868","rc":[{"atl":[[630,0],[610,2]],"id":41419617},{"atl":[[460,2],[500,0]],"id":41419613},{"atl":[[350,2],[390,0]],"id":41419589},{"atb":[[20,0],[25,4.17]],"id":41419601},{"atl":[[360,2],[390,0]],"id":41419606},{"atl":[[890,2],[900,0]],"id":41419614},{"atl":[[630,2],[640,0]],"id":41419623},{"atb":[[9.6,0],[12.5,6.54]],"id":41419607},{"atl":[[770,2],[830,0]],"id":41419607},{"atl":[[840,2],[940,0]],"id":41419615},{"atl":[[540,0],[510,2]],"id":41419620},{"atl":[[770,2],[860,0]],"id":41419599},{"atl":[[940,0],[930,2]],"id":41419628},{"atl":[[780,2],[850,0]],"id":41419608},{"atl":[[950,2],[1000,0]],"id":41419604},{"atl":[[530,0],[510,2]],"id":41419616},{"atl":[[670,2],[690,0]],"id":41419625}],"con":true,"img":false}]}
{"op":"mcm","clk":"5353793310","pt":1646218528671,"mc":[{"id":"1.195503868","rc":[{"atl":[[350,0],[340,2]],"id":41419589},{"atb":[[17,6.25],[14.5,0]],"id":41419615},{"atl":[[920,2],[930,0]],"id":41419621}],"con":true,"img":false}]}
{"op":"mcm","clk":"5353796172","pt":1646218551483,"mc":[{"id":"1.195503868","rc":[{"atl":[[700,0],[710,2]],"id":41419624},{"atl":[[860,0]],"id":41419592}],"con":true,"img":false}]}
{"op":"mcm","clk":"5353796181","pt":1646218551590,"mc":[{"id":"1.195503868","rc":[{"atb":[[10,0],[12.5,0]],"id":41419589},{"atb":[[19.5,0],[24,0]],"id":41419630},{"atb":[[22,0],[27,0]],"id":41419610},{"atb":[[9.6,0],[8.6,0]],"id":41419590},{"atb":[[85,0],[120,0]],"id":41419594},{"atb":[[18,0],[21,0]],"id":41419611},{"atb":[[7.2,0],[8.2,0]],"id":41419587},{"atb":[[70,0],[48,0]],"id":41419628},{"atb":[[65,0],[90,0]],"id":41419592},{"atl":[[850,2]],"id":41419592},{"atb":[[9,0],[10,0]],"id":41419588}],"con":true,"img":false}]}
{"op":"mcm","clk":"5353796202","pt":1646218551791,"mc":[{"id":"1.195503868","rc":[{"atb":[[8,0],[7.4,15.62]],"id":41419611}],"con":true,"img":false}]}
{"op":"mcm","clk":"5353796246","pt":1646218552315,"mc":[{"id":"1.195503868","rc":[{"atb":[[9.6,3.26],[11.5,2.72]],"id":41419589},{"atb":[[20,3.26],[25,2.72]],"id":41419630},{"atb":[[20,3.26],[25,2.72]],"id":41419610},{"atb":[[9,3.26],[10,2.72]],"id":41419590},{"atb":[[130,2.72],[90,3.26]],"id":41419594},{"atb":[[18.5,3.26],[22,2.72]],"id":41419611},{"atb":[[7.4,3.26],[8.4,2.72]],"id":41419587},{"atb":[[75,2.72],[50,3.26]],"id":41419628},{"atb":[[70,3.26],[95,2.72]],"id":41419592},{"atb":[[9.2,3.26],[10.5,2.72]],"id":41419588}],"con":true,"img":false}]}
{"op":"mcm","clk":"5353797025","pt":1646218558810,"mc":[{"id":"1.195503868","rc":[{"atl":[[700,2],[710,0]],"id":41419624}],"con":true,"img":false}]}
{"op":"mcm","clk":"5353797474","pt":1646218563129,"mc":[{"id":"1.195503868","rc":[{"atb":[[16,0],[13.5,0]],"id":41419627},{"atb":[[20,0],[25,0]],"id":41419616}],"con":true,"img":false}]}
{"op":"mcm","clk":"5353797593","pt":1646218564035,"mc":[{"id":"1.195503868","rc":[{"atb":[[16.5,2.72],[14,3.26]],"id":41419627},{"atb":[[21,3.26],[26,2.72]],"id":41419616}],"con":true,"img":false}]}
{"op":"mcm","clk":"5353798987","pt":1646218578546,"mc":[{"id":"1.195503868","rc":[{"atb":[[360,0],[410,0]],"id":41419656},{"atb":[[21,0],[26,0]],"id":41419616}],"con":true,"img":false}]}
{"op":"mcm","clk":"5353799003","pt":1646218578753,"mc":[{"id":"1.195503868","rc":[{"atb":[[7.4,0],[8.4,0]],"id":41419587},{"atb":[[70,0],[95,0]],"id":41419592},{"atb":[[160,0],[110,0]],"id":41419596}],"con":true,"img":false}]}
{"op":"mcm","clk":"5353799011","pt":1646218578854,"mc":[{"id":"1.195503868","rc":[{"atb":[[330,0],[380,0]],"id":41419651}],"con":true,"img":false}]}
{"op":"mcm","clk":"5353799048","pt":1646218579227,"mc":[{"id":"1.195503868","rc":[{"atb":[[370,3.26],[420,2.72]],"id":41419656},{"atb":[[20,3.26],[25,2.72]],"id":41419616}],"con":true,"img":false}]}
{"op":"mcm","clk":"5353799073","pt":1646218579534,"mc":[{"id":"1.195503868","rc":[{"atb":[[7.2,3.26],[8.2,2.72]],"id":41419587},{"atb":[[65,3.26],[90,2.72]],"id":41419592},{"atb":[[170,2.72],[120,3.26]],"id":41419596}],"con":true,"img":false}]}
{"op":"mcm","clk":"5353799093","pt":1646218579743,"mc":[{"id":"1.195503868","rc":[{"atb":[[340,3.26],[390,2.72]],"id":41419651}],"con":true,"img":false}]}
{"op":"mcm","clk":"5353801577","pt":1646218604698,"mc":[{"id":"1.195503868","rc":[{"atb":[[170,0],[120,0]],"id":41419596}],"con":true,"img":false}]}
{"op":"mcm","clk":"5353801656","pt":1646218605504,"mc":[{"id":"1.195503868","rc":[{"atb":[[160,2.72],[110,3.26]],"id":41419596}],"con":true,"img":false}]}
{"op":"mcm","clk":"5353803992","pt":1646218629626,"mc":[{"id":"1.195503868","rc":[{"atb":[[140,1.91],[95,0]],"id":41419595}],"con":true,"img":false}]}
{"op":"mcm","clk":"5353804077","pt":1646218630356,"mc":[{"id":"1.195503868","rc":[{"atb":[[150,2.72],[100,3.26]],"id":41419595}],"con":true,"img":false}]}
{"op":"mcm","clk":"5353804723","pt":1646218636826,"mc":[{"id":"1.195503868","rc":[{"atb":[[9.6,0],[11.5,0]],"id":41419589},{"atb":[[20,0],[25,0]],"id":41419610}],"con":true,"img":false}]}
{"op":"mcm","clk":"5353804789","pt":1646218637559,"mc":[{"id":"1.195503868","rc":[{"atb":[[10.5,3.26],[13,2.72]],"id":41419589},{"atb":[[22,3.26],[27,2.72]],"id":41419610}],"con":true,"img":false}]}
{"op":"mcm","clk":"5353806892","pt":1646218660962,"mc":[{"id":"1.195503868","rc":[{"atb":[[370,0],[420,0]],"id":41419656}],"con":true,"img":false}]}
{"op":"mcm","clk":"5353806920","pt":1646218661273,"mc":[{"id":"1.195503868","rc":[{"atb":[[7.2,0]],"id":41419587},{"atb":[[65,0],[90,0]],"id":41419592}],"con":true,"img":false}]}
{"op":"mcm","clk":"5353806942","pt":1646218661484,"mc":[{"id":"1.195503868","rc":[{"atb":[[340,0],[390,0]],"id":41419651}],"con":true,"img":false}]}
{"op":"mcm","clk":"5353806963","pt":1646218661790,"mc":[{"id":"1.195503868","rc":[{"atb":[[380,3.26],[430,2.72]],"id":41419656}],"con":true,"img":false}]}
{"op":"mcm","clk":"5353806983","pt":1646218662053,"mc":[{"id":"1.195503868","rc":[{"atb":[[8.2,0],[7.4,3.26]],"id":41419587},{"atb":[[70,3.26],[95,2.72]],"id":41419592}],"con":true,"img":false}]}
{"op":"mcm","clk":"5353806999","pt":1646218662260,"mc":[{"id":"1.195503868","rc":[{"atb":[[350,3.26],[400,3.39]],"id":41419651}],"con":true,"img":false}]}
{"op":"mcm","clk":"5353807068","pt":1646218662994,"mc":[{"id":"1.195503868","rc":[{"atb":[[8.4,2.72]],"id":41419587}],"con":true,"img":false}]}
{"op":"mcm","clk":"5353809007","pt":1646218684698,"mc":[{"id":"1.195503868","rc":[{"atb":[[160,0]],"id":41419596}],"con":true,"img":false}]}
{"op":"mcm","clk":"5353809017","pt":1646218684797,"mc":[{"id":"1.195503868","rc":[{"atb":[[110,0]],"id":41419596}],"con":true,"img":false}]}
{"op":"mcm","clk":"5353809081","pt":1646218685423,"mc":[{"id":"1.195503868","rc":[{"atb":[[170,2.72]],"id":41419596}],"con":true,"img":false}]}
{"op":"mcm","clk":"5353809103","pt":1646218685582,"mc":[{"id":"1.195503868","rc":[{"atb":[[120,3.26]],"id":41419596}],"con":true,"img":false}]}
{"op":"mcm","clk":"5353810008","pt":1646218695689,"mc":[{"id":"1.195503868","rc":[{"atb":[[10.5,0],[13,0]],"id":41419589},{"atb":[[22,0],[27,0]],"id":41419610}],"con":true,"img":false}]}
{"op":"mcm","clk":"5353810019","pt":1646218695795,"mc":[{"id":"1.195503868","rc":[{"atb":[[170,0],[120,0]],"id":41419596}],"con":true,"img":false}]}
{"op":"mcm","clk":"5353810078","pt":1646218696414,"mc":[{"id":"1.195503868","rc":[{"atb":[[12,2.72],[9.8,3.26]],"id":41419589},{"atb":[[20,3.26],[25,2.72]],"id":41419610}],"con":true,"img":false}]}
{"op":"mcm","clk":"5353810090","pt":1646218696522,"mc":[{"id":"1.195503868","rc":[{"atb":[[160,2.72],[110,3.26]],"id":41419596}],"con":true,"img":false}]}
{"op":"mcm","clk":"5353811317","pt":1646218709658,"mc":[{"id":"1.195503868","rc":[{"atb":[[18.5,0],[22,0]],"id":41419609},{"atb":[[17,0],[14.5,0]],"id":41419613},{"atb":[[75,0],[50,0]],"id":41419614}],"con":true,"img":false}]}
{"op":"mcm","clk":"5353811396","pt":1646218710443,"mc":[{"id":"1.195503868","rc":[{"atb":[[19,3.26],[23,2.72]],"id":41419609},{"atb":[[18,2.72],[15.5,3.26]],"id":41419613},{"atb":[[80,2.72],[55,3.26]],"id":41419614}],"con":true,"img":false}]}
{"op":"mcm","clk":"5353812029","pt":1646218716569,"mc":[{"id":"1.195503868","rc":[{"atl":[[920,0],[910,2]],"id":41419602}],"con":true,"img":false}]}
{"op":"mcm","clk":"5353813827","pt":1646218735535,"mc":[{"id":"1.195503868","rc":[{"atb":[[5.3,0],[11.5,0],[6.6,0]],"id":41419609},{"atb":[[17.5,0],[9,0],[7,0]],"id":41419617},{"atb":[[5.1,0],[8.2,0],[4.1,0]],"id":41419613},{"atb":[[700,0],[400,0],[500,0]],"id":41419593},{"atb":[[17,0],[38,0],[12,0]],"id":41419622},{"atb":[[3.7,0],[6.8,0],[4.4,0]],"id":41419589},{"atb":[[20,0],[100,3.26],[30,0]],"id":41435527},{"atb":[[700,0],[400,2.72],[500,0]],"id":41419651},{"atb":[[7.8,0],[14.5,0],[5.9,0]],"id":41419618},{"atb":[[24,0],[12,0],[8.8,0]],"id":41419601},{"atb":[[9.8,0],[4.9,0],[5.9,0]],"id":41419630},{"atb":[[190,0],[48,0],[29,0]],"id":41419597},{"atb":[[24,0],[12,0],[8.8,0]],"id":28546943},{"atb":[[190,0],[48,0],[29,0]],"id":41419659},{"atb":[[5.3,0],[3.15,0],[3.65,0]],"id":41419606},{"atb":[[16,0],[34,0],[11,0]],"id":41419602},{"atb":[[24,0],[12,0],[8.8,0]],"id":41419585},{"atb":[[270,0],[85,0],[44,0]],"id":41419614},{"atb":[[5.6,0],[7.2,0],[13,0]],"id":41419610},{"atb":[[700,0],[400,0],[500,0]],"id":41419656},{"atb":[[5.8,0],[7.6,0],[14,0]],"id":41419623},{"atb":[[5.3,0],[3.15,0],[3.65,0]],"id":41419590},{"atb":[[700,0],[400,0],[500,0]],"id":41419652},{"atb":[[150,3.26],[450,0],[250,0]],"id":41435528},{"atb":[[5.8,0],[7.6,0],[14,0]],"id":41419586},{"atb":[[5.8,0],[7.6,0],[14,0]],"id":41419631},{"atb":[[4,0],[6,0],[3.5,0]],"id":41419627},{"atb":[[20,0],[100,0],[30,0]],"id":41419594},{"atb":[[65,0],[16.5,0],[23,0]],"id":41419607},{"atb":[[32,0],[10.5,0],[15.5,0]],"id":28546950},{"atb":[[18,0],[42,0],[13,0]],"id":41419603},{"atb":[[10,0],[30,0],[15,0]],"id":41419615},{"atb":[[5.7,0],[9.4,0],[4.7,0]],"id":41419611},{"atb":[[700,0],[400,0],[500,0]],"id":41419657},{"atb":[[17.5,0],[9,0],[7,0]],"id":41419624},{"atb":[[65,2.72],[16.5,0],[23,0]],"id":41435525},{"atb":[[270,0],[85,2.72],[44,0]],"id":41419653},{"atb":[[8.8,0],[4.4,0],[5.4,0]],"id":41419620},{"atb":[[4.5,0],[2.9,0],[3.25,0]],"id":41419587},{"atb":[[6.2,0],[8.2,0],[15.5,0]],"id":41419632},{"atb":[[17,0],[6.8,0],[8.8,0]],"id":41419599},{"atb":[[34,0],[22,0],[120,0]],"id":41419628},{"atb":[[140,0],[70,0],[340,0]],"id":41419595},{"atb":[[22,0],[11,10],[8.4,0]],"id":41419608},{"atb":[[27,0],[13.5,0],[9.4,0]],"id":41419604},{"atb":[[5.5,0],[12.5,0],[7,0]],"id":41419616},{"atb":[[16,0],[6.4,0],[8.4,0]],"id":41419625},{"atb":[[32,0],[10.5,0],[15.5,0]],"id":41419592},{"atb":[[34,0],[22,0],[120,0]],"id":41419654},{"atb":[[180,0],[90,0],[380,0]],"id":41435526},{"atb":[[180,0],[90,0],[380,0]],"id":41419621},{"atb":[[4,0],[6,0],[3.5,0]],"id":41419588},{"atb":[[700,0],[400,0],[500,0]],"id":41419600},{"atb":[[9,0],[25,0],[12.5,0]],"id":41419629},{"atb":[[150,0],[450,0],[250,0]],"id":41419596},{"atb":[[140,0],[70,0],[340,0]],"id":41419658}],"con":true,"img":false}]}
{"op":"mcm","clk":"5353813851","pt":1646218735797,"mc":[{"id":"1.195503868","rc":[{"atl":[[1000,2]],"id":41419595}],"con":true,"img":false}]}
{"op":"mcm","clk":"5353813857","pt":1646218735896,"mc":[{"id":"1.195503868","rc":[{"atb":[[19,0],[23,0]],"id":41419609},{"atb":[[7.4,0],[8.4,0]],"id":41419587}],"con":true,"img":false}]}
{"op":"mcm","clk":"5353813936","pt":1646218736685,"mc":[{"id":"1.195503868","rc":[{"atb":[[18.5,3.26],[22,2.72]],"id":41419609},{"atb":[[7.2,3.26],[8.2,2.72]],"id":41419587}],"con":true,"img":false}]}
{"op":"mcm","clk":"5353814248","pt":1646218739604,"mc":[{"id":"1.195503868","rc":[{"atb":[[5.3,61.94],[11.5,12.68],[6.6,47.57]],"id":41419609},{"atb":[[17.5,8.07],[9,33.29],[7,44.4]],"id":41419617},{"atb":[[5.1,64.97],[8.2,18.49],[4.1,85.93]],"id":41419613},{"atb":[[700,0.19],[400,0.67],[500,0.53]],"id":41419593},{"atb":[[17,16.64],[38,3.6],[12,24.21]],"id":41419622},{"atb":[[3.7,98.66],[6.8,22.96],[4.4,78.34]],"id":41419589},{"atb":[[20,14.02],[100,4.61],[30,9.18]],"id":41435527},{"atb":[[700,0.19],[400,3.39],[500,0.53]],"id":41419651},{"atb":[[7.8,39.17],[14.5,9.86],[5.9,54.36]],"id":41419618},{"atb":[[24,5.79],[12,24.21],[8.8,34.15]],"id":41419601},{"atb":[[9.8,15.13],[4.9,68.3],[5.9,54.36]],"id":41419630},{"atb":[[190,0.7],[48,5.66],[29,9.51]],"id":41419597},{"atb":[[24,5.79],[12,24.21],[8.8,34.15]],"id":28546943},{"atb":[[190,0.7],[48,5.66],[29,9.51]],"id":41419659},{"atb":[[5.3,30.97],[3.15,123.9],[3.65,100.52]],"id":41419606},{"atb":[[16,17.76],[34,4.03],[11,26.63]],"id":41419602},{"atb":[[24,5.79],[12,24.21],[8.8,34.15]],"id":41419585},{"atb":[[270,0.49],[85,3.17],[44,6.19]],"id":41419614},{"atb":[[5.6,57.91],[7.2,42.96],[13,11.1]],"id":41419610},{"atb":[[700,0.19],[400,0.67],[500,0.53]],"id":41419656},{"atb":[[5.8,55.49],[7.6,40.36],[14,10.24]],"id":41419623},{"atb":[[5.3,30.97],[3.15,123.9],[3.65,100.52]],"id":41419590},{"atb":[[700,0.19],[400,0.67],[500,0.53]],"id":41419652},{"atb":[[150,5.05],[450,0.29],[250,1.06]],"id":41435528},{"atb":[[5.8,55.49],[7.6,40.36],[14,10.24]],"id":41419586},{"atb":[[5.8,55.49],[7.6,40.36],[14,10.24]],"id":41419631},{"atb":[[4,88.79],[6,26.63],[3.5,106.55]],"id":41419627},{"atb":[[20,14.02],[100,1.34],[30,9.18]],"id":41419594},{"atb":[[65,2.08],[16.5,17.18],[23,12.1]],"id":41419607},{"atb":[[32,4.29],[10.5,28.03],[15.5,18.37]],"id":28546950},{"atb":[[18,15.66],[42,3.24],[13,22.19]],"id":41419603},{"atb":[[10,29.59],[30,4.59],[15,19.02]],"id":41419615},{"atb":[[5.7,56.67],[9.4,15.85],[4.7,71.99]],"id":41419611},{"atb":[[700,0.19],[400,0.67],[500,0.53]],"id":41419657},{"atb":[[17.5,8.07],[9,33.29],[7,44.4]],"id":41419624},{"atb":[[65,4.8],[16.5,17.18],[23,12.1]],"id":41435525},{"atb":[[270,0.49],[85,5.89],[44,6.19]],"id":41419653},{"atb":[[8.8,17.07],[4.4,78.34],[5.4,60.54]],"id":41419620},{"atb":[[4.5,38.05],[2.9,140.2],[3.25,118.39]],"id":41419587},{"atb":[[6.2,51.22],[8.2,36.99],[15.5,9.18]],"id":41419632},{"atb":[[17,8.32],[6.8,45.93],[8.8,34.15]],"id":41419599},{"atb":[[34,8.07],[22,12.68],[120,1.11]],"id":41419628},{"atb":[[140,1.91],[70,3.85],[340,0.39]],"id":41419595},{"atb":[[11,36.63],[22,6.34],[8.4,35.99]],"id":41419608},{"atb":[[27,5.12],[13.5,21.3],[9.4,31.71]],"id":41419604},{"atb":[[5.5,59.19],[12.5,11.58],[7,44.4]],"id":41419616},{"atb":[[16,8.87],[6.4,49.33],[8.4,35.99]],"id":41419625},{"atb":[[32,4.29],[10.5,28.03],[15.5,18.37]],"id":41419592},{"atb":[[34,8.07],[22,12.68],[120,1.11]],"id":41419654},{"atb":[[180,1.48],[90,2.99],[380,0.34]],"id":41435526},{"atb":[[180,1.48],[90,2.99],[380,0.34]],"id":41419621},{"atb":[[4,88.79],[6,26.63],[3.5,106.55]],"id":41419588},{"atb":[[700,0.19],[400,0.67],[500,0.53]],"id":41419600},{"atb":[[9,33.29],[25,5.54],[12.5,23.16]],"id":41419629},{"atb":[[150,1.78],[450,0.29],[250,1.06]],"id":41419596},{"atb":[[140,1.91],[70,3.85],[340,0.39]],"id":41419658}],"con":true,"img":false}]}
{"op":"mcm","clk":"5353814373","pt":1646218740808,"mc":[{"id":"1.195503868","rc":[{"atl":[[1000,0]],"id":41419595}],"con":true,"img":false}]}
{"op":"mcm","clk":"5353814403","pt":1646218741112,"mc":[{"id":"1.195503868","rc":[{"atb":[[32,4.95],[17.5,16.97],[27,9.9]],"id":41419617},{"atl":[[65,4.95],[630,1.94],[85,9.9]],"id":41419617},{"atb":[[160,0.99],[30,22.92]],"id":41435527},{"atb":[[95,11.35]],"id":41419597},{"atb":[[200,0.79],[120,11.35]],"id":41419659},{"atb":[[34,12.94]],"id":41419602},{"atl":[[930,1.31]],"id":41419602},{"atb":[[18.5,9.9],[21,4.95]],"id":41419585},{"atl":[[65,4.95],[520,0.3],[85,9.9]],"id":41419585},{"atb":[[65,4.95]],"id":41419614},{"atb":[[13,20]],"id":41419610},{"atl":[[530,2.31]],"id":41419610},{"atb":[[26,9.9],[30,4.95]],"id":41419623},{"atl":[[65,4.95],[85,9.9]],"id":41419623},{"atb":[[32,4.95],[27,9.9]],"id":41419631},{"atl":[[70,4.95],[90,9.9]],"id":41419631},{"atb":[[16.5,11.63],[17,9.9],[19,4.95]],"id":41419627},{"atl":[[34,4.95],[42,9.9],[460,0.34]],"id":41419627},{"atb":[[80,9.9],[90,10.28],[100,6.3]],"id":41419594},{"atb":[[80,9.9],[42,12.12],[100,7.67]],"id":41419603},{"atb":[[44,13.17],[55,4.95]],"id":41419615},{"atl":[[140,4.95]],"id":41419615},{"atb":[[17.5,16.97]],"id":41419624},{"atl":[[720,1.7]],"id":41419624},{"atb":[[4.5,46.96],[8.2,11.63]],"id":41419587},{"atl":[[270,4.55],[240,0.66]],"id":41419587},{"atl":[[580,0.27]],"id":41419632},{"atb":[[32,9.9],[17,17.23],[40,4.95]],"id":41419599},{"atl":[[760,0.2],[790,1.55],[120,4.95]],"id":41419599},{"atb":[[27,14.02]],"id":41419604},{"atl":[[970,1.26]],"id":41419604},{"atl":[[500,0.31]],"id":41419616},{"atb":[[16,17.78]],"id":41419625},{"atl":[[690,1.77]],"id":41419625},{"atl":[[840,0.19]],"id":41419592},{"atb":[[110,7.15]],"id":41435526},{"atl":[[940,1.3]],"id":41419621},{"atb":[[70,4.95],[50,9.9],[60,2.68]],"id":41419629},{"atl":[[160,4.95],[890,0.17]],"id":41419629},{"atb":[[140,7.62]],"id":41419658}],"con":true,"img":false}]}
{"op":"mcm","clk":"5353814415","pt":1646218741228,"mc":[{"id":"1.195503868","rc":[{"atb":[[11.5,21.59],[13.5,9.9],[15.5,4.95]],"id":41419609},{"atl":[[32,4.95],[40,9.9],[460,0.34],[490,2.5]],"id":41419609},{"atl":[[600,0.26]],"id":41419617},{"atb":[[8.2,27.4],[13,9.9],[15,4.95]],"id":41419613},{"atl":[[32,9.9],[27,4.95],[450,0.35],[480,2.56]],"id":41419613},{"atb":[[38,12.5],[80,2],[85,9.9],[110,4.95]],"id":41419622},{"atl":[[220,4.95],[990,0.15]],"id":41419622},{"atb":[[10,4.95],[9.2,9.9],[6.8,31.87]],"id":41419589},{"atl":[[16.5,4.95],[18.5,9.9],[330,0.47],[360,3.41]],"id":41419589},{"atb":[[160,5.95],[120,9.9]],"id":41435527},{"atb":[[32,4.95],[27,9.9],[14.5,18.76],[30,8.19]],"id":41419618},{"atl":[[590,0.26],[620,1.97],[80,9.9],[60,4.95]],"id":41419618},{"atb":[[65,9.9],[75,4.86],[85,4.95],[25,13.07]],"id":41419601},{"atl":[[180,4.95],[900,0.17],[930,1.31]],"id":41419601},{"atb":[[23,9.9],[25,9.33],[27,4.95]],"id":41419630},{"atl":[[75,9.9],[55,4.95],[510,0.31]],"id":41419630},{"atb":[[90,9.9],[120,4.95]],"id":41419597},{"atl":[[1000,0.15]],"id":41419597},{"atb":[[40,4.06],[46,9.9],[24,14.69],[60,4.95]],"id":28546943},{"atl":[[220,4.95],[990,0.15]],"id":28546943},{"atb":[[160,4.95],[120,21.26]],"id":41419659},{"atb":[[10,4.95],[9.2,9.9],[5.3,39.88]],"id":41419606},{"atl":[[17.5,4.95],[19.5,9.9],[350,0.45],[380,3.23]],"id":41419606},{"atb":[[80,4.95],[90,4.5],[60,9.9]],"id":41419602},{"atl":[[900,0.17]],"id":41419602},{"atl":[[550,2.23]],"id":41419585},{"atb":[[80,9.73]],"id":41419614},{"atl":[[880,0.17],[910,1.34]],"id":41419614},{"atb":[[18.5,9.9],[21,4.95]],"id":41419610},{"atl":[[42,4.95],[50,9.9],[500,0.31]],"id":41419610},{"atb":[[14,19.15]],"id":41419623},{"atl":[[620,0.25],[650,1.88]],"id":41419623},{"atb":[[10,11.63],[10.5,4.95],[5.3,39.88],[9.4,9.9]],"id":41419590},{"atl":[[19,4.95],[320,0.49],[350,3.51],[22,9.9]],"id":41419590},{"atb":[[160,4.95],[200,5.9]],"id":41435528},{"atb":[[19,13.17],[22,4.95],[23,9.92],[14,19.15]],"id":41419586},{"atl":[[530,0.29],[560,2.19],[44,4.95],[55,9.9]],"id":41419586},{"atb":[[14,19.15],[29,8.38]],"id":41419631},{"atl":[[530,0.29],[560,2.19]],"id":41419631},{"atb":[[6.2,28.13]],"id":41419627},{"atl":[[490,2.5]],"id":41419627},{"atl":[[990,0.15]],"id":41419594},{"atb":[[40,9.9],[44,10.4],[48,4.95]],"id":41419607},{"atl":[[150,4.95],[760,0.2],[790,1.55]],"id":41419607},{"atb":[[32,14.01],[160,4.95],[120,11.23]],"id":28546950},{"atl":[[1000,0.15]],"id":28546950},{"atb":[[100,9.28]],"id":41419603},{"atl":[[990,0.15]],"id":41419603},{"atb":[[60,5.41],[30,13.49]],"id":41419615},{"atl":[[830,0.19],[860,1.42]],"id":41419615},{"atb":[[19,9.9],[22,15.22],[9.4,24.76]],"id":41419611},{"atl":[[540,2.27],[42,4.95],[50,9.9],[510,0.31]],"id":41419611},{"atb":[[32,4.95],[27,9.9]],"id":41419624},{"atl":[[80,4.95],[690,0.22],[100,9.9]],"id":41419624},{"atb":[[140,4.95],[70,2.29],[100,9.9],[27,15.29]],"id":41435525},{"atl":[[1000,0.15]],"id":41435525},{"atb":[[160,4.95],[60,12.99],[120,9.9]],"id":41419653},{"atb":[[18,9.9],[20,8.22],[8.8,25.97]],"id":41419620},{"atl":[[530,2.31],[38,4.95],[46,9.9]],"id":41419620},{"atb":[[7.4,4.95],[6.6,9.9]],"id":41419587},{"atl":[[12,4.95],[14,9.9]],"id":41419587},{"atb":[[22,9.9],[26,4.95],[15.5,18.09]],"id":41419632},{"atl":[[610,2.01],[80,9.9],[60,4.95]],"id":41419632},{"atb":[[75,12.63],[95,4.95],[50,10.28]],"id":41419628},{"atl":[[210,4.95],[920,0.17],[950,1.28]],"id":41419628},{"atb":[[130,4.95],[140,7.74]],"id":41419595},{"atl":[[990,0.15]],"id":41419595},{"atb":[[42,9.9],[44,6.41],[22,15.24],[50,4.95]],"id":41419608},{"atl":[[770,0.2],[800,1.53],[110,4.95]],"id":41419608},{"atb":[[80,9.9],[85,4.61],[100,4.95]],"id":41419604},{"atl":[[230,4.95],[940,0.16]],"id":41419604},{"atb":[[18,9.9],[20,8.22],[12.5,20.48]],"id":41419616},{"atl":[[530,2.31],[42,4.95],[50,9.9]],"id":41419616},{"atb":[[36,4.95],[29,9.9]],"id":41419625},{"atl":[[70,4.95],[660,0.23],[90,9.9]],"id":41419625},{"atb":[[32,13.19],[44,9.9],[55,4.95]],"id":41419592},{"atl":[[870,1.4]],"id":41419592},{"atb":[[130,1.23],[160,4.95],[55,11.35],[120,11.02]],"id":41419654},{"atl":[[1000,0.15]],"id":41419654},{"atb":[[160,4.95],[120,9.9]],"id":41435526},{"atl":[[910,0.17]],"id":41419621},{"atb":[[9,9.9],[10.5,11.63],[6,35.54],[9.8,4.95]],"id":41419588},{"atl":[[16,4.95],[18,9.9],[310,0.51],[340,3.61]],"id":41419588},{"atb":[[25,14.45]],"id":41419629},{"atl":[[920,1.32]],"id":41419629},{"atl":[[990,0.15]],"id":41419596},{"atb":[[160,4.95],[120,13.17]],"id":41419658}],"con":true,"img":false}]}
{"op":"mcm","clk":"5353814421","pt":1646218741277,"mc":[{"id":"1.195503868","rc":[{"atl":[[610,0],[220,2]],"id":41419617},{"atb":[[40,2.56],[29,0]],"id":41435527},{"atl":[[530,0],[130,2]],"id":41419585},{"atl":[[520,2],[510,0]],"id":41419610},{"atl":[[630,0],[240,2]],"id":41419623},{"atl":[[540,0],[250,2]],"id":41419631},{"atl":[[95,2],[470,0]],"id":41419627},{"atl":[[840,0],[440,2]],"id":41419615},{"atl":[[700,0],[710,2]],"id":41419624},{"atl":[[500,0.31]],"id":41419620},{"atl":[[260,2],[250,0]],"id":41419587},{"atl":[[370,2],[770,0]],"id":41419599},{"atl":[[670,0],[680,2]],"id":41419625},{"atl":[[920,0],[930,2]],"id":41419621},{"atl":[[900,0],[500,2]],"id":41419629}],"con":true,"img":false}]}
{"op":"mcm","clk":"5353814433","pt":1646218741391,"mc":[{"id":"1.195503868","rc":[{"atl":[[90,2],[470,0]],"id":41419609},{"atl":[[80,2],[460,0]],"id":41419613},{"atl":[[720,2],[1000,0]],"id":41419622},{"atl":[[38,2.7],[340,0]],"id":41419589},{"atl":[[600,0],[230,2]],"id":41419618},{"atl":[[510,2]],"id":41419601},{"atl":[[520,0],[190,2]],"id":41419630},{"atl":[[790,2],[1000,0]],"id":28546943},{"atl":[[42,2.44]],"id":41419606},{"atl":[[330,0],[44,2.33]],"id":41419590},{"atl":[[540,0],[140,2]],"id":41419586},{"atl":[[370,2],[770,0]],"id":41419607},{"atl":[[520,0],[140,2]],"id":41419611},{"atb":[[38,2.7],[27,11.44]],"id":41435525},{"atl":[[120,2],[510,0]],"id":41419620},{"atl":[[590,0],[200,2]],"id":41419632},{"atl":[[530,2],[930,0]],"id":41419628},{"atl":[[380,2],[780,0]],"id":41419608},{"atb":[[32,3.23],[26,0]],"id":41419604},{"atl":[[550,2],[950,0]],"id":41419604},{"atl":[[110,2],[510,0]],"id":41419616},{"atl":[[320,0],[40,2.56]],"id":41419588}],"con":true,"img":false}]}
{"op":"mcm","clk":"5353814443","pt":1646218741496,"mc":[{"id":"1.195503868","rc":[{"atl":[[910,0]],"id":41419601},{"atl":[[360,0]],"id":41419606}],"con":true,"img":false}]}
{"op":"mcm","clk":"5353814462","pt":1646218741693,"mc":[{"id":"1.195503868","rc":[{"atl":[[1000,1.22]],"id":41419622},{"atl":[[1000,1.22]],"id":28546943}],"con":true,"img":false}]}
{"op":"mcm","clk":"5353814472","pt":1646218741801,"mc":[{"id":"1.195503868","rc":[{"atl":[[140,0],[150,4.95]],"id":41419615},{"atl":[[130,4.95]],"id":41419599}],"con":true,"img":false}]}
{"op":"mcm","clk":"5353814480","pt":1646218741906,"mc":[{"id":"1.195503868","rc":[{"atl":[[34,4.95],[42,9.9]],"id":41419609},{"atl":[[180,0],[200,4.95]],"id":41419601},{"atb":[[9.8,24.03]],"id":41419630},{"atl":[[540,2.27]],"id":41419630},{"atl":[[65,0],[70,4.95],[85,0],[90,9.9]],"id":41419585},{"atl":[[120,0]],"id":41419599},{"atl":[[230,0]],"id":41419604}],"con":true,"img":false}]}
{"op":"mcm","clk":"5353814493","pt":1646218742009,"mc":[{"id":"1.195503868","rc":[{"atl":[[32,0],[40,0]],"id":41419609},{"atl":[[150,0],[160,4.95]],"id":41419607},{"atl":[[210,0],[240,4.95]],"id":41419628},{"atl":[[42,0],[44,4.95],[50,0],[55,9.9]],"id":41419616}],"con":true,"img":false}]}
{"op":"mcm","clk":"5353814574","pt":1646218742690,"mc":[{"id":"1.195503868","rc":[{"atl":[[70,0],[90,0]],"id":41419585},{"atl":[[150,0]],"id":41419615},{"atl":[[44,0],[55,0]],"id":41419616}],"con":true,"img":false}]}
{"op":"mcm","clk":"5353814638","pt":1646218743287,"mc":[{"id":"1.195503868","rc":[{"atl":[[250,4.95]],"id":41419604}],"con":true,"img":false}]}
{"op":"mcm","clk":"5353814647","pt":1646218743385,"mc":[{"id":"1.195503868","rc":[{"atl":[[65,4.95],[85,9.9]],"id":41419585},{"atl":[[140,4.95]],"id":41419615},{"atl":[[42,4.95],[50,9.9]],"id":41419616}],"con":true,"img":false}]}
{"op":"mcm","clk":"5353814913","pt":1646218745924,"mc":[{"id":"1.195503868","rc":[{"atb":[[11.5,9.52]],"id":41419617},{"atb":[[38,0]],"id":41419593},{"atb":[[46,2.22]],"id":41419622},{"atb":[[6.2,19.23]],"id":41419589},{"atb":[[36,0]],"id":41419597},{"atb":[[7.6,0]],"id":41419610},{"atb":[[12,9.09]],"id":41419623},{"atb":[[46,2.22]],"id":41419594},{"atb":[[12.5,0]],"id":41419607},{"atb":[[23,4.55]],"id":41419615},{"atb":[[12.5,8.7]],"id":41419625},{"atb":[[27,0]],"id":41419621},{"atb":[[60,2]],"id":41419658}],"con":true,"img":false}]}
{"op":"mcm","clk":"5353814928","pt":1646218746033,"mc":[{"id":"1.195503868","rc":[{"atb":[[9,12.5],[6.2,0]],"id":41419609},{"atb":[[8.8,0]],"id":41419617},{"atb":[[8.2,41.29],[6,0]],"id":41419613},{"atb":[[55,2]],"id":41419593},{"atb":[[34,0]],"id":41419622},{"atb":[[4.7,0]],"id":41419589},{"atb":[[9,0],[12,9.09]],"id":41419618},{"atb":[[32,3.23],[25,8.9]],"id":41419601},{"atb":[[8.2,0],[11,10]],"id":41419630},{"atb":[[50,2.04]],"id":41419597},{"atb":[[40,0],[60,2]],"id":41419659},{"atb":[[6.2,19.23],[4.4,0]],"id":41419606},{"atb":[[34,15.97],[26,0]],"id":41419602},{"atb":[[19,0],[30,3.45]],"id":41419614},{"atb":[[11,10]],"id":41419610},{"atb":[[9,0]],"id":41419623},{"atb":[[6.4,18.52],[4.9,0]],"id":41419590},{"atb":[[40,0],[60,2]],"id":41419652},{"atb":[[40,0],[60,2]],"id":41435528},{"atb":[[10,11.11],[6.6,0]],"id":41419586},{"atb":[[9,0],[12,9.09]],"id":41419631},{"atb":[[6.2,8.9],[9.4,11.9]],"id":41419627},{"atb":[[34,0]],"id":41419594},{"atb":[[17,6.25]],"id":41419607},{"atb":[[34,0],[46,2.22]],"id":41419603},{"atb":[[17,0]],"id":41419615},{"atb":[[10,11.11],[7.4,0]],"id":41419611},{"atb":[[40,0],[60,2]],"id":41419657},{"atb":[[10,0],[13,8.33]],"id":41419624},{"atb":[[38,0],[55,2]],"id":41419653},{"atb":[[10.5,10.53],[7.8,0]],"id":41419620},{"atb":[[4.6,27.78],[3.75,0]],"id":41419587},{"atb":[[8.6,0],[11.5,9.52]],"id":41419632},{"atb":[[17,23.48],[10.5,0]],"id":41419599},{"atb":[[40,2.56],[25,0]],"id":41419628},{"atb":[[34,0],[50,2.04]],"id":41419595},{"atl":[[1000,2]],"id":41419595},{"atb":[[18,5.88],[11,26.63]],"id":41419608},{"atb":[[10,11.11],[7.4,0]],"id":41419616},{"atb":[[9.4,0]],"id":41419625},{"atb":[[40,0],[55,13.35]],"id":41419654},{"atb":[[40,0],[55,2]],"id":41435526},{"atb":[[36,2.86]],"id":41419621},{"atb":[[4.3,0],[5.4,22.73]],"id":41419588},{"atb":[[38,0],[55,2]],"id":41419600},{"atb":[[32,3.23],[23,0]],"id":41419629},{"atb":[[34,0],[48,2.13]],"id":41419596},{"atb":[[40,0]],"id":41419658}],"con":true,"img":false}]}
{"op":"mcm","clk":"5353814964","pt":1646218746406,"mc":[{"id":"1.195503868","rc":[{"atl":[[760,2.2]],"id":41419599}],"con":true,"img":false}]}
{"op":"mcm","clk":"5353814975","pt":1646218746508,"mc":[{"id":"1.195503868","rc":[{"atl":[[990,2.15]],"id":41419622},{"atl":[[830,2.19],[440,0]],"id":41419615},{"atl":[[370,0]],"id":41419599},{"atl":[[890,2.17],[500,0]],"id":41419629}],"con":true,"img":false}]}
{"op":"mcm","clk":"5353814982","pt":1646218746602,"mc":[{"id":"1.195503868","rc":[{"atl":[[720,0]],"id":41419622},{"atl":[[900,2.17],[510,0]],"id":41419601},{"atl":[[790,0],[990,2.15]],"id":28546943},{"atl":[[370,0],[760,2.2]],"id":41419607},{"atl":[[530,0],[920,2.17]],"id":41419628},{"atl":[[380,0],[770,2.2]],"id":41419608},{"atl":[[550,0],[940,2.16]],"id":41419604}],"con":true,"img":false}]}
{"op":"mcm","clk":"5353815148","pt":1646218748380,"mc":[{"id":"1.195503868","rc":[{"atb":[[40,0],[60,2]],"id":41435527},{"atl":[[920,2],[930,0]],"id":41419621}],"con":true,"img":false}]}
{"op":"mcm","clk":"5353815160","pt":1646218748487,"mc":[{"id":"1.195503868","rc":[{"atb":[[38,0],[55,2]],"id":41435525}],"con":true,"img":false}]}
{"op":"mcm","clk":"5353815174","pt":1646218748585,"mc":[{"id":"1.195503868","rc":[{"atb":[[32,0],[44,2.33]],"id":41419604}],"con":true,"img":false}]}
{"op":"mcm","clk":"5353815227","pt":1646218749111,"mc":[{"id":"1.195503868","rc":[{"atb":[[18.5,0],[22,0]],"id":41419609},{"atb":[[12,0],[9.8,0]],"id":41419589}],"con":true,"img":false}]}
{"op":"mcm","clk":"5353815264","pt":1646218749451,"mc":[{"id":"1.195503868","rc":[{"atl":[[240,4.95]],"id":41419602}],"con":true,"img":false}]}
{"op":"mcm","clk":"5353815285","pt":1646218749585,"mc":[{"id":"1.195503868","rc":[{"atb":[[15.5,15.28]],"id":41419609},{"atb":[[10,16.32]],"id":41419589},{"atl":[[910,0],[510,2]],"id":41419602}],"con":true,"img":false}]}
{"op":"mcm","clk":"5353815313","pt":1646218749898,"mc":[{"id":"1.195503868","rc":[{"atb":[[19,3.26],[23,2.72]],"id":41419609},{"atb":[[9.6,3.26],[11.5,2.72]],"id":41419589}],"con":true,"img":false}]}
{"op":"mcm","clk":"5353815652","pt":1646218753293,"mc":[{"id":"1.195503868","rc":[{"atl":[[1000,0.15]],"id":41419653}],"con":true,"img":false}]}
{"op":"mcm","clk":"5353815669","pt":1646218753502,"mc":[{"id":"1.195503868","rc":[{"atl":[[240,0],[250,4.95]],"id":41419602},{"atl":[[250,4.95]],"id":41419603},{"atl":[[920,0]],"id":41419621}],"con":true,"img":false}]}
{"op":"mcm","clk":"5353815679","pt":1646218753610,"mc":[{"id":"1.195503868","rc":[{"atl":[[930,2]],"id":41419621}],"con":true,"img":false}]}
{"op":"mcm","clk":"5353815688","pt":1646218753710,"mc":[{"id":"1.195503868","rc":[{"atl":[[690,2],[1000,0]],"id":41419603}],"con":true,"img":false}]}
{"op":"mcm","clk":"5353815708","pt":1646218753920,"mc":[{"id":"1.195503868","rc":[{"atl":[[690,0],[1000,1.25]],"id":41419603}],"con":true,"img":false}]}
{"op":"mcm","clk":"5353815719","pt":1646218754022,"mc":[{"id":"1.195503868","rc":[{"atl":[[990,2.15]],"id":41419603}],"con":true,"img":false}]}
{"op":"mcm","clk":"5353815974","pt":1646218756832,"mc":[{"id":"1.195503868","rc":[{"atb":[[17.5,8.07],[28,15.48]],"id":41419617},{"atl":[[630,0],[220,7.79]],"id":41419617},{"atb":[[120,20.54],[30,9.18]],"id":41435527},{"atb":[[95,3.26],[120,10.03]],"id":41419597},{"atb":[[170,5.1],[120,13.17]],"id":41419659},{"atb":[[65,14.83],[34,7.06]],"id":41419602},{"atl":[[900,1.58],[930,0]],"id":41419602},{"atl":[[65,7.43]],"id":41419585},{"atb":[[20,15.48],[13,11.1]],"id":41419610},{"atl":[[530,0],[500,2.86]],"id":41419610},{"atb":[[19,13.76]],"id":41419627},{"atl":[[34,9.76]],"id":41419627},{"atb":[[75,15.48],[42,3.24]],"id":41419603},{"atb":[[17.5,8.07],[30,15.48]],"id":41419624},{"atl":[[690,2.07],[720,0]],"id":41419624},{"atb":[[7.2,17.98],[4.5,38.05]],"id":41419587},{"atl":[[270,0],[12,19.36],[240,5.97]],"id":41419587},{"atb":[[17,14.57],[40,13.85]],"id":41419599},{"atl":[[120,1.32]],"id":41419599},{"atb":[[80,24.11],[27,5.12]],"id":41419604},{"atl":[[42,8.82]],"id":41419616},{"atb":[[16,8.87],[30,15.48]],"id":41419625},{"atl":[[660,2.16],[690,0]],"id":41419625},{"atb":[[160,9.38],[110,2.72]],"id":41435526},{"atb":[[70,7.25]],"id":41419629},{"atl":[[160,5.95]],"id":41419629},{"atb":[[140,1.91],[160,12.93]],"id":41419658}],"con":true,"img":false}]}
{"op":"mcm","clk":"5353815983","pt":1646218756936,"mc":[{"id":"1.195503868","rc":[{"atb":[[11.5,12.68],[15.5,27.5]],"id":41419609},{"atl":[[34,9.76],[90,14.21],[490,0]],"id":41419609},{"atb":[[8.2,32.38],[15,17.17]],"id":41419613},{"atl":[[80,14.21],[480,0]],"id":41419613},{"atb":[[38,3.6],[80,12.57],[110,6.4]],"id":41419622},{"atl":[[220,5.67]],"id":41419622},{"atb":[[9.6,15.48],[6.8,22.96]],"id":41419589},{"atl":[[38,14.91],[360,0]],"id":41419589},{"atb":[[32,10.06],[27,29.44],[14.5,9.86]],"id":41419618},{"atl":[[620,0],[60,7.64]],"id":41419618},{"atb":[[65,24.5],[85,6.83],[25,0]],"id":41419601},{"atl":[[190,0.83]],"id":41419601},{"atb":[[27,11.05]],"id":41419630},{"atl":[[55,7.89]],"id":41419630},{"atb":[[65,2.47],[40,17.47],[24,5.79]],"id":28546943},{"atl":[[220,5.67]],"id":28546943},{"atb":[[5.3,30.97],[9.8,15.48]],"id":41419606},{"atl":[[42,14.65],[380,0]],"id":41419606},{"atl":[[500,0.31]],"id":41419602},{"atl":[[550,0]],"id":41419585},{"atb":[[28,15.48],[14,10.24]],"id":41419623},{"atl":[[650,0],[240,7.31]],"id":41419623},{"atb":[[10.5,21.64],[5.3,30.97]],"id":41419590},{"atl":[[19,13.76],[350,0],[44,24.41]],"id":41419590},{"atb":[[19,35.26],[14,10.24]],"id":41419586},{"atl":[[140,11.12],[560,0],[44,8.64]],"id":41419586},{"atb":[[32,10.06],[27,29.73],[14,10.24]],"id":41419631},{"atl":[[70,7.25],[560,0],[250,7.1]],"id":41419631},{"atb":[[16.5,33.71],[6.2,0]],"id":41419627},{"atl":[[95,15.44],[490,0]],"id":41419627},{"atb":[[44,3.26],[48,12.28]],"id":41419607},{"atl":[[150,1.06]],"id":41419607},{"atb":[[32,4.29],[110,14.12]],"id":28546950},{"atl":[[250,5.59]],"id":41419603},{"atb":[[44,27.89],[30,4.59]],"id":41419615},{"atl":[[140,6.09]],"id":41419615},{"atb":[[18.5,25.35],[9.4,15.85]],"id":41419611},{"atl":[[140,11.12],[42,8.82]],"id":41419611},{"atb":[[150,1.06]],"id":41435525},{"atb":[[120,18],[60,3.26]],"id":41419653},{"atb":[[18,29.48],[8.8,17.07]],"id":41419620},{"atl":[[530,0],[120,12.64]],"id":41419620},{"atb":[[26,17.17]],"id":41419632},{"atl":[[610,0],[200,8.38]],"id":41419632},{"atb":[[50,3.26]],"id":41419628},{"atl":[[230,0.69]],"id":41419628},{"atb":[[42,24.62],[22,6.34],[50,8.19]],"id":41419608},{"atl":[[110,6.4]],"id":41419608},{"atb":[[18,29.48],[12.5,11.58]],"id":41419616},{"atl":[[530,0],[110,13.6]],"id":41419616},{"atb":[[55,11.96]],"id":41419592},{"atb":[[170,0.93],[55,5.26],[120,20.2]],"id":41419654},{"atb":[[9.2,17.98],[6,26.63]],"id":41419588},{"atl":[[16,15.52],[40,17.27],[340,0]],"id":41419588},{"atb":[[25,5.54],[55,10.76]],"id":41419629}],"con":true,"img":false}]}
{"op":"mcm","clk":"5353815992","pt":1646218756993,"mc":[{"id":"1.195503868","rc":[{"atl":[[890,2],[510,0]],"id":41419602},{"atl":[[130,11.82]],"id":41419585},{"atb":[[170,0.93]],"id":28546950},{"atb":[[70,13.07],[27,0]],"id":41435525},{"atl":[[260,0],[26,4]],"id":41419587},{"atl":[[760,0.2],[370,2]],"id":41419599},{"atb":[[75,23.21]],"id":41419628},{"atb":[[100,6.55]],"id":41419604},{"atb":[[32,4.29]],"id":41419592}],"con":true,"img":false}]}
{"op":"mcm","clk":"5353816001","pt":1646218757097,"mc":[{"id":"1.195503868","rc":[{"atb":[[9.4,31.99]],"id":41419590},{"atl":[[760,0.2],[370,2]],"id":41419607},{"atl":[[240,0.66]],"id":41419604}],"con":true,"img":false}]}
{"op":"mcm","clk":"5353816013","pt":1646218757200,"mc":[{"id":"1.195503868","rc":[{"atl":[[890,0],[510,2]],"id":41419602}],"con":true,"img":false}]}
{"op":"mcm","clk":"5353816038","pt":1646218757410,"mc":[{"id":"1.195503868","rc":[{"atl":[[900,3.58],[930,0]],"id":41419601},{"atl":[[760,1.88],[790,0]],"id":41419607},{"atl":[[760,1.88],[790,0]],"id":41419599},{"atl":[[920,3.55],[950,0]],"id":41419628}],"con":true,"img":false}]}
{"op":"mcm","clk":"5353816053","pt":1646218757515,"mc":[{"id":"1.195503868","rc":[{"atl":[[520,0]],"id":41419585},{"atb":[[16.5,24.81]],"id":41419627},{"atl":[[460,0]],"id":41419627},{"atl":[[240,5.31]],"id":41419587},{"atl":[[760,1.67]],"id":41419599},{"atl":[[940,3.52]],"id":41419604},{"atl":[[500,0]],"id":41419616},{"atb":[[60,0]],"id":41419629}],"con":true,"img":false}]}
{"op":"mcm","clk":"5353816066","pt":1646218757621,"mc":[{"id":"1.195503868","rc":[{"atb":[[80,10.56]],"id":41419622},{"atl":[[990,2]],"id":41419622},{"atb":[[75,2.72]],"id":41419601},{"atb":[[23,38.5],[25,2.72],[9.8,15.13]],"id":41419630},{"atl":[[540,0],[190,8.72],[510,0]],"id":41419630},{"atb":[[40,13.4]],"id":28546943},{"atl":[[990,2]],"id":28546943},{"atb":[[10,2.72]],"id":41419590},{"atl":[[530,0]],"id":41419586},{"atb":[[29,2.72]],"id":41419631},{"atl":[[530,0]],"id":41419631},{"atl":[[830,2]],"id":41419615},{"atl":[[510,0]],"id":41419611},{"atl":[[770,2]],"id":41419608}],"con":true,"img":false}]}
{"op":"mcm","clk":"5353816076","pt":1646218757726,"mc":[{"id":"1.195503868","rc":[{"atl":[[460,0]],"id":41419609},{"atb":[[30,2.72]],"id":41419618},{"atl":[[590,0],[230,7.54]],"id":41419618},{"atl":[[900,3.41]],"id":41419601},{"atl":[[900,1.41]],"id":41419602},{"atl":[[320,0]],"id":41419590},{"atl":[[760,1.67]],"id":41419607},{"atb":[[120,9.9]],"id":28546950},{"atl":[[990,2]],"id":41419603},{"atl":[[540,0]],"id":41419611},{"atb":[[70,10.77]],"id":41435525},{"atb":[[15.5,9.18]],"id":41419632},{"atl":[[920,3.37]],"id":41419628},{"atb":[[44,2.72]],"id":41419608},{"atb":[[85,2.72]],"id":41419604},{"atb":[[130,0]],"id":41419654},{"atl":[[310,0]],"id":41419588}],"con":true,"img":false}]}
{"op":"mcm","clk":"5353816089","pt":1646218757831,"mc":[{"id":"1.195503868","rc":[{"atl":[[940,3.35],[970,0]],"id":41419604},{"atl":[[890,2]],"id":41419629}],"con":true,"img":false}]}
{"op":"mcm","clk":"5353816174","pt":1646218758624,"mc":[{"id":"1.195503868","rc":[{"atb":[[90,2.72]],"id":41419602}],"con":true,"img":false}]}
{"op":"mcm","clk":"5353816242","pt":1646218759305,"mc":[{"id":"1.195503868","rc":[{"atb":[[80,6.95]],"id":41419602}],"con":true,"img":false}]}
{"op":"mcm","clk":"5353816377","pt":1646218760632,"mc":[{"id":"1.195503868","rc":[{"atl":[[920,2],[930,0]],"id":41419621}],"con":true,"img":false}]}
{"op":"mcm","clk":"5353816820","pt":1646218764522,"mc":[{"id":"1.195503868","rc":[{"atb":[[50,29.52],[55,2.72]],"id":41419629}],"con":true,"img":false}]}
{"op":"mcm","clk":"5353817318","pt":1646218769526,"mc":[{"id":"1.195503868","rc":[{"atl":[[920,0],[930,2]],"id":41419621}],"con":true,"img":false}]}
{"op":"mcm","clk":"5353817331","pt":1646218769631,"mc":[{"id":"1.195503868","rc":[{"atl":[[260,4.95],[250,0]],"id":41419603},{"atb":[[150,0]],"id":41435525},{"atl":[[1000,0.15]],"id":41419600}],"con":true,"img":false}]}
{"op":"mcm","clk":"5353817343","pt":1646218769734,"mc":[{"id":"1.195503868","rc":[{"atb":[[65,0]],"id":28546943}],"con":true,"img":false}]}
{"op":"mcm","clk":"5353817351","pt":1646218769837,"mc":[{"id":"1.195503868","rc":[{"atl":[[690,2],[990,0]],"id":41419603},{"atb":[[40,6.79]],"id":41419624},{"atl":[[80,6.95]],"id":41419624}],"con":true,"img":false}]}
{"op":"mcm","clk":"5353817406","pt":1646218770308,"mc":[{"id":"1.195503868","rc":[{"atl":[[680,0.23]],"id":41419603},{"atb":[[150,1.06]],"id":41435525}],"con":true,"img":false}]}
{"op":"mcm","clk":"5353817430","pt":1646218770524,"mc":[{"id":"1.195503868","rc":[{"atb":[[65,2.47]],"id":28546943},{"atl":[[690,1.84]],"id":41419624},{"atl":[[1000,0]],"id":41419600}],"con":true,"img":false}]}
{"op":"mcm","clk":"5353817455","pt":1646218770830,"mc":[{"id":"1.195503868","rc":[{"atl":[[690,3.9],[1000,0]],"id":41419603}],"con":true,"img":false}]}
{"op":"mcm","clk":"5353817584","pt":1646218772234,"mc":[{"id":"1.195503868","rc":[{"atl":[[900,0],[510,4.58]],"id":41419602},{"atl":[[26,36.01],[240,0]],"id":41419587}],"con":true,"img":false}]}
{"op":"mcm","clk":"5353817593","pt":1646218772335,"mc":[{"id":"1.195503868","rc":[{"atl":[[250,5.59]],"id":41419602},{"atb":[[110,2.72],[120,18.66]],"id":28546950},{"atl":[[260,5.56]],"id":41419603}],"con":true,"img":false}]}
{"op":"mcm","clk":"5353817615","pt":1646218772543,"mc":[{"id":"1.195503868","rc":[{"atb":[[40,0],[46,20.94]],"id":28546943},{"atb":[[70,0],[100,18.84]],"id":41435525}],"con":true,"img":false}]}
{"op":"mcm","clk":"5353817643","pt":1646218772810,"mc":[{"id":"1.195503868","rc":[{"atl":[[370,5.56],[760,0]],"id":41419607},{"atl":[[370,5.56],[760,0]],"id":41419599}],"con":true,"img":false}]}
{"op":"mcm","clk":"5353817662","pt":1646218773016,"mc":[{"id":"1.195503868","rc":[{"atl":[[500,0]],"id":41419602},{"atl":[[680,0]],"id":41419603}],"con":true,"img":false}]}
{"op":"mcm","clk":"5353817801","pt":1646218774639,"mc":[{"id":"1.195503868","rc":[{"atb":[[90,4.5]],"id":41419602}],"con":true,"img":false}]}
{"op":"mcm","clk":"5353817878","pt":1646218775424,"mc":[{"id":"1.195503868","rc":[{"atb":[[80,4.95]],"id":41419602},{"atb":[[40,2.72]],"id":41419624},{"atl":[[80,4.95]],"id":41419624}],"con":true,"img":false}]}
{"op":"mcm","clk":"5353817960","pt":1646218776354,"mc":[{"id":"1.195503868","rc":[{"atb":[[32,10.06]],"id":41419624}],"con":true,"img":false}]}
{"op":"mcm","clk":"5353817970","pt":1646218776407,"mc":[{"id":"1.195503868","rc":[{"atl":[[920,2],[930,0]],"id":41419621}],"con":true,"img":false}]}
{"op":"mcm","clk":"5353818037","pt":1646218777142,"mc":[{"id":"1.195503868","rc":[{"atb":[[6.2,0],[5.4,22.73]],"id":41419589},{"atl":[[620,2],[710,0]],"id":41419624},{"atl":[[850,0],[860,2]],"id":41419592}],"con":true,"img":false}]}
{"op":"mcm","clk":"5353818061","pt":1646218777454,"mc":[{"id":"1.195503868","rc":[{"atb":[[32,0],[36,0],[27,0],[28,0]],"id":41419617},{"atl":[[60,2.68]],"id":41419617},{"atl":[[16.5,15.18]],"id":41419589},{"atl":[[220,0.72],[230,4.95]],"id":28546943},{"atb":[[24,25.44]],"id":41419585},{"atl":[[42,8.82]],"id":41419610},{"atb":[[40,0],[30,12.21]],"id":41419624},{"atl":[[75,2.14]],"id":41419624},{"atb":[[20,4.95],[25,0]],"id":41419620}],"con":true,"img":false}]}
{"op":"mcm","clk":"5353818081","pt":1646218777611,"mc":[{"id":"1.195503868","rc":[{"atl":[[160,2],[220,5.79]],"id":41419617},{"atl":[[840,2],[990,0]],"id":28546943}],"con":true,"img":false}]}
{"op":"mcm","clk":"5353818092","pt":1646218777733,"mc":[{"id":"1.195503868","rc":[{"atl":[[620,4.14],[690,0]],"id":41419624}],"con":true,"img":false}]}
{"op":"mcm","clk":"5353818101","pt":1646218777847,"mc":[{"id":"1.195503868","rc":[{"atb":[[65,0]],"id":28546943},{"atb":[[150,0]],"id":41435525},{"atb":[[20,13.29]],"id":41419620},{"atl":[[1000,0.15]],"id":41419600}],"con":true,"img":false}]}
{"op":"mcm","clk":"5353818109","pt":1646218777923,"mc":[{"id":"1.195503868","rc":[{"atb":[[9,59.44],[18,4],[22,9.9],[26,4.95]],"id":41419617},{"atl":[[85,25.63],[220,0]],"id":41419617},{"atl":[[990,1.34],[1000,0]],"id":28546943},{"atb":[[27,39.36],[30,0]],"id":41419624},{"atb":[[18,9.9],[10.5,40.91]],"id":41419620}],"con":true,"img":false}]}
{"op":"mcm","clk":"5353818127","pt":1646218778133,"mc":[{"id":"1.195503868","rc":[{"atb":[[34,2.72],[27,3.26]],"id":41419617},{"atl":[[600,0],[60,0]],"id":41419617},{"atl":[[330,0]],"id":41419589},{"atl":[[500,2.54]],"id":41419610},{"atb":[[36,2.72],[28,3.26]],"id":41419624},{"atb":[[18,13.17],[21,2.72]],"id":41419620}],"con":true,"img":false}]}
{"op":"mcm","clk":"5353818144","pt":1646218778343,"mc":[{"id":"1.195503868","rc":[{"atl":[[38,9.23]],"id":41419620}],"con":true,"img":false}]}
{"op":"mcm","clk":"5353818171","pt":1646218778653,"mc":[{"id":"1.195503868","rc":[{"atl":[[85,9.9]],"id":41419617},{"atb":[[60,7.64]],"id":28546943},{"atb":[[140,6.09]],"id":41435525}],"con":true,"img":false}]}
{"op":"mcm","clk":"5353818201","pt":1646218778922,"mc":[{"id":"1.195503868","rc":[{"atl":[[65,7.43]],"id":41419617}],"con":true,"img":false}]}
{"op":"mcm","clk":"5353818223","pt":1646218779129,"mc":[{"id":"1.195503868","rc":[{"atl":[[500,0]],"id":41419620}],"con":true,"img":false}]}
{"op":"mcm","clk":"5353818303","pt":1646218779955,"mc":[{"id":"1.195503868","rc":[{"atb":[[38,14.12]],"id":28546943}],"con":true,"img":false}]}
{"op":"mcm","clk":"5353818317","pt":1646218780058,"mc":[{"id":"1.195503868","rc":[{"atb":[[46,9.9]],"id":28546943},{"atb":[[65,21],[100,9.9]],"id":41435525}],"con":true,"img":false}]}
{"op":"mcm","clk":"5353818412","pt":1646218780947,"mc":[{"id":"1.195503868","rc":[{"atl":[[1000,0]],"id":41419595}],"con":true,"img":false}]}
{"op":"mcm","clk":"5353818446","pt":1646218781258,"mc":[{"id":"1.195503868","rc":[{"atl":[[16.5,4.95]],"id":41419589},{"atl":[[1000,0.15]],"id":41435527},{"atl":[[1000,0.15]],"id":41419659},{"atl":[[17.5,0],[18.5,4.95],[19.5,0],[21,9.9]],"id":41419606},{"atb":[[32,0],[26,0]],"id":41419585},{"atl":[[42,4.95]],"id":41419610},{"atl":[[42,3.86],[44,4.95],[50,0],[55,9.9]],"id":41419611}],"con":true,"img":false}]}
{"op":"mcm","clk":"5353818458","pt":1646218781315,"mc":[{"id":"1.195503868","rc":[{"atb":[[90,2.72]],"id":41419602}],"con":true,"img":false}]}
{"op":"mcm","clk":"5353818484","pt":1646218781523,"mc":[{"id":"1.195503868","rc":[{"atl":[[920,0],[930,2]],"id":41419621}],"con":true,"img":false}]}
{"op":"mcm","clk":"5353818505","pt":1646218781733,"mc":[{"id":"1.195503868","rc":[{"atb":[[24,32.33]],"id":41419585},{"atl":[[140,2],[55,34.41]],"id":41419611}],"con":true,"img":false}]}
{"op":"mcm","clk":"5353818528","pt":1646218781940,"mc":[{"id":"1.195503868","rc":[{"atl":[[40,4.06]],"id":41419606},{"atb":[[34,2.72],[27,3.26]],"id":41419585},{"atl":[[50,13.14]],"id":41419610}],"con":true,"img":false}]}
{"op":"mcm","clk":"5353818547","pt":1646218782081,"mc":[{"id":"1.195503868","rc":[{"atl":[[18.5,18.96]],"id":41419589},{"atb":[[80,6.95]],"id":41419602}],"con":true,"img":false}]}
{"op":"mcm","clk":"5353818574","pt":1646218782348,"mc":[{"id":"1.195503868","rc":[{"atl":[[40,18.78]],"id":41419606},{"atl":[[860,0],[870,3.4]],"id":41419592}],"con":true,"img":false}]}
{"op":"mcm","clk":"5353818587","pt":1646218782500,"mc":[{"id":"1.195503868","rc":[{"atl":[[42,2.44]],"id":41419606}],"con":true,"img":false}]}
{"op":"mcm","clk":"5353818617","pt":1646218782724,"mc":[{"id":"1.195503868","rc":[{"atl":[[350,0]],"id":41419606}],"con":true,"img":false}]}
{"op":"mcm","clk":"5353818629","pt":1646218782825,"mc":[{"id":"1.195503868","rc":[{"atl":[[860,1.56],[870,2]],"id":41419592}],"con":true,"img":false}]}
{"op":"mcm","clk":"5353818646","pt":1646218783061,"mc":[{"id":"1.195503868","rc":[{"atb":[[12,17.13]],"id":41419606}],"con":true,"img":false}]}
{"op":"mcm","clk":"5353818713","pt":1646218783810,"mc":[{"id":"1.195503868","rc":[{"atl":[[1000,0]],"id":41419600}],"con":true,"img":false}]}
{"op":"mcm","clk":"5353818720","pt":1646218783922,"mc":[{"id":"1.195503868","rc":[{"atb":[[6.2,19.23],[5.4,0]],"id":41419589},{"atl":[[620,2.14],[230,2]],"id":41419624}],"con":true,"img":false}]}
{"op":"mcm","clk":"5353818913","pt":1646218786052,"mc":[{"id":"1.195503868","rc":[{"atl":[[690,2]],"id":41419603}],"con":true,"img":false}]}
{"op":"mcm","clk":"5353818946","pt":1646218786315,"mc":[{"id":"1.195503868","rc":[{"atl":[[280,4.85]],"id":41419603}],"con":true,"img":false}]}
{"op":"mcm","clk":"5353818959","pt":1646218786418,"mc":[{"id":"1.195503868","rc":[{"atl":[[690,0]],"id":41419603}],"con":true,"img":false}]}
{"op":"mcm","clk":"5353818971","pt":1646218786522,"mc":[{"id":"1.195503868","rc":[{"atl":[[640,2]],"id":41419603}],"con":true,"img":false}]}
{"op":"mcm","clk":"5353819044","pt":1646218787348,"mc":[{"id":"1.195503868","rc":[{"atl":[[510,2]],"id":41419602}],"con":true,"img":false}]}
{"op":"mcm","clk":"5353819084","pt":1646218787609,"mc":[{"id":"1.195503868","rc":[{"atl":[[270,5.04]],"id":41419602}],"con":true,"img":false}]}
{"op":"mcm","clk":"5353819325","pt":1646218790109,"mc":[{"id":"1.195503868","rc":[{"atl":[[860,0]],"id":41419592}],"con":true,"img":false}]}
{"op":"mcm","clk":"5353819355","pt":1646218790421,"mc":[{"id":"1.195503868","rc":[{"atl":[[870,3.56]],"id":41419592}],"con":true,"img":false}]}
{"op":"mcm","clk":"5353819364","pt":1646218790525,"mc":[{"id":"1.195503868","rc":[{"atb":[[19,0],[23,0]],"id":41419609}],"con":true,"img":false}]}
{"op":"mcm","clk":"5353819413","pt":1646218791042,"mc":[{"id":"1.195503868","rc":[{"atb":[[15.5,15.28]],"id":41419609}],"con":true,"img":false}]}
{"op":"mcm","clk":"5353819442","pt":1646218791354,"mc":[{"id":"1.195503868","rc":[{"atb":[[18.5,3.26],[22,2.72],[11.5,46.28]],"id":41419609}],"con":true,"img":false}]}
{"op":"mcm","clk":"5353819541","pt":1646218792341,"mc":[{"id":"1.195503868","rc":[{"atl":[[16.5,15.18]],"id":41419589}],"con":true,"img":false}]}
{"op":"mcm","clk":"5353819571","pt":1646218792755,"mc":[{"id":"1.195503868","rc":[{"atl":[[620,0],[100,22.12]],"id":41419624}],"con":true,"img":false}]}
{"op":"mcm","clk":"5353819581","pt":1646218792858,"mc":[{"id":"1.195503868","rc":[{"atb":[[9,33.29]],"id":41419617},{"atl":[[990,0]],"id":28546943},{"atb":[[27,9.9]],"id":41419624},{"atb":[[21,10.65]],"id":41419620}],"con":true,"img":false}]}
{"op":"mcm","clk":"5353819591","pt":1646218792961,"mc":[{"id":"1.195503868","rc":[{"atb":[[26,17.17]],"id":41419617},{"atl":[[160,10.61]],"id":41419617},{"atl":[[840,3.63]],"id":28546943},{"atb":[[28,15.48]],"id":41419624}],"con":true,"img":false}]}
{"op":"mcm","clk":"5353819602","pt":1646218793015,"mc":[{"id":"1.195503868","rc":[{"atb":[[18,46.69],[10.5,10.53]],"id":41419620}],"con":true,"img":false}]}
{"op":"mcm","clk":"5353819611","pt":1646218793119,"mc":[{"id":"1.195503868","rc":[{"atl":[[18.5,9.9]],"id":41419589}],"con":true,"img":false}]}
{"op":"mcm","clk":"5353819655","pt":1646218793541,"mc":[{"id":"1.195503868","rc":[{"atb":[[20,4.95]],"id":41419620}],"con":true,"img":false}]}
{"op":"mcm","clk":"5353819680","pt":1646218793746,"mc":[{"id":"1.195503868","rc":[{"atl":[[280,0],[640,4.14]],"id":41419603}],"con":true,"img":false}]}
{"op":"mcm","clk":"5353819750","pt":1646218794527,"mc":[{"id":"1.195503868","rc":[{"atl":[[640,2]],"id":41419603}],"con":true,"img":false}]}
{"op":"mcm","clk":"5353819778","pt":1646218794835,"mc":[{"id":"1.195503868","rc":[{"atl":[[270,0]],"id":41419602}],"con":true,"img":false}]}
{"op":"mcm","clk":"5353819818","pt":1646218795253,"mc":[{"id":"1.195503868","rc":[{"atl":[[510,4.7]],"id":41419602}],"con":true,"img":false}]}
{"op":"mcm","clk":"5353819905","pt":1646218796243,"mc":[{"id":"1.195503868","rc":[{"atl":[[280,4.95]],"id":41419614}],"con":true,"img":false}]}
{"op":"mcm","clk":"5353819924","pt":1646218796446,"mc":[{"id":"1.195503868","rc":[{"atl":[[890,0],[490,2]],"id":41419614}],"con":true,"img":false}]}
{"op":"mcm","clk":"5353819943","pt":1646218796658,"mc":[{"id":"1.195503868","rc":[{"atb":[[270,0]],"id":41419614},{"atl":[[880,2.17],[490,0]],"id":41419614},{"trd":[[270,0.99]],"ltp":270.0,"tv":0.99,"id":41419614}],"con":true,"img":false}]}
{"op":"mcm","clk":"5353819975","pt":1646218797022,"mc":[{"id":"1.195503868","rc":[{"atl":[[18.5,14.01]],"id":41419606},{"atl":[[890,1.55],[910,0]],"id":41419614}],"con":true,"img":false}]}
{"op":"mcm","clk":"5353820006","pt":1646218797331,"mc":[{"id":"1.195503868","rc":[{"atb":[[80,2.72],[90,0.49]],"id":41419614},{"atl":[[270,0.58]],"id":41419614}],"con":true,"img":false}]}
{"op":"mcm","clk":"5353820018","pt":1646218797434,"mc":[{"id":"1.195503868","rc":[{"atb":[[65,17.02]],"id":41419614}],"con":true,"img":false}]}
{"op":"mcm","clk":"5353820048","pt":1646218797745,"mc":[{"id":"1.195503868","rc":[{"atl":[[860,1.61],[870,2]],"id":41419592}],"con":true,"img":false}]}
{"op":"mcm","clk":"5353820075","pt":1646218798056,"mc":[{"id":"1.195503868","rc":[{"atl":[[40,14.71]],"id":41419606}],"con":true,"img":false}]}
{"op":"mcm","clk":"5353820102","pt":1646218798370,"mc":[{"id":"1.195503868","rc":[{"atl":[[880,2]],"id":41419614}],"con":true,"img":false}]}
{"op":"mcm","clk":"5353820400","pt":1646218801072,"mc":[{"id":"1.195503868","rc":[{"atb":[[16,4.95],[13.5,0],[14,9.9],[15.5,10.32]],"id":41419609},{"atl":[[170,4.95],[200,0]],"id":41419601},{"atb":[[23,28.59],[24,9.9],[27,6.09],[28,4.95]],"id":41419630},{"atl":[[230,4.95],[250,0.63]],"id":41419602},{"atb":[[18.5,0],[21,0],[22,4.95]],"id":41419585},{"atl":[[280,0]],"id":41419614},{"atb":[[19,25.35],[19.5,9.9],[22,0],[23,14.88]],"id":41419586},{"atb":[[17,0],[17.5,9.9],[19,8.8],[19.5,4.95]],"id":41419627},{"atb":[[40,0],[48,7.33],[50,4.95]],"id":41419607},{"atl":[[130,4.95],[140,1.13]],"id":41419615},{"atb":[[19,0],[19.5,9.9],[22,10.27],[23,4.95]],"id":41419611},{"atl":[[70,4.95],[80,0],[90,9.9],[100,12.21]],"id":41419624},{"atb":[[7.4,0],[6.6,0],[7.8,4.95],[7,9.9]],"id":41419587},{"atl":[[75,9.9],[80,0],[55,4.95],[60,0]],"id":41419632},{"atl":[[130,0],[110,4.95]],"id":41419599},{"atl":[[220,4.95],[250,0]],"id":41419604},{"atl":[[40,4.95],[42,3.86],[48,9.9],[50,0]],"id":41419616},{"atb":[[70,2.29],[75,4.95],[50,19.61],[55,12.63]],"id":41419629}],"con":true,"img":false}]}
{"op":"mcm","clk":"5353820425","pt":1646218801237,"mc":[{"id":"1.195503868","rc":[{"atl":[[900,1.41],[510,2]],"id":41419601},{"atl":[[830,0],[440,2]],"id":41419615},{"atl":[[540,2]],"id":41419604}],"con":true,"img":false}]}
{"op":"mcm","clk":"5353820443","pt":1646218801343,"mc":[{"id":"1.195503868","rc":[{"atl":[[170,4.95],[230,0]],"id":28546943},{"atl":[[280,5]],"id":41419603},{"atb":[[75,13.3],[80,9.9],[95,0],[100,4.95]],"id":41419628},{"atl":[[940,1.35]],"id":41419604}],"con":true,"img":false}]}
{"op":"mcm","clk":"5353820467","pt":1646218801553,"mc":[{"id":"1.195503868","rc":[{"atb":[[23,0],[25,23.51],[29,5.66]],"id":41419630},{"atl":[[540,2],[840,1.63]],"id":28546943},{"atl":[[230,5.64]],"id":41419602},{"atb":[[16.5,2.72],[17.5,39.14],[20,8.34]],"id":41419627},{"atb":[[48,0],[50,16.35]],"id":41419607},{"atl":[[830,1.68],[860,0],[120,1.32]],"id":41419615},{"atb":[[18.5,3.26],[19.5,31.99],[24,6.89]],"id":41419611},{"atl":[[70,7.25]],"id":41419624},{"atl":[[110,6.4]],"id":41419599},{"atl":[[40,9.01],[48,29.48],[110,2]],"id":41419616},{"atb":[[80,2],[50,0],[55,23.4]],"id":41419629}],"con":true,"img":false}]}
{"op":"mcm","clk":"5353820485","pt":1646218801761,"mc":[{"id":"1.195503868","rc":[{"atl":[[34,4.8],[42,0]],"id":41419609},{"atl":[[900,0],[510,4.74]],"id":41419601},{"atb":[[80,22.29]],"id":41419628},{"atl":[[540,4.59],[220,5.67],[940,0]],"id":41419604}],"con":true,"img":false}]}
{"op":"mcm","clk":"5353820492","pt":1646218801863,"mc":[{"id":"1.195503868","rc":[{"atl":[[32,4.95],[40,9.9]],"id":41419609},{"atl":[[170,5.89]],"id":41419601},{"atl":[[160,1.59]],"id":28546943},{"atl":[[140,4.95],[160,0]],"id":41419607},{"atb":[[75,2.72]],"id":41419628}],"con":true,"img":false}]}
{"op":"mcm","clk":"5353820515","pt":1646218802070,"mc":[{"id":"1.195503868","rc":[{"atl":[[220,4.95],[240,0]],"id":41419628}],"con":true,"img":false}]}
{"op":"mcm","clk":"5353820534","pt":1646218802232,"mc":[{"id":"1.195503868","rc":[{"atl":[[38,14.3],[90,2]],"id":41419609},{"atl":[[250,0]],"id":41419602},{"atb":[[19,0]],"id":41419627},{"atb":[[22,2.72]],"id":41419611},{"atl":[[120,0]],"id":41419599},{"atl":[[540,2],[920,1.37]],"id":41419628},{"atl":[[42,0]],"id":41419616},{"atb":[[70,0]],"id":41419629}],"con":true,"img":false}]}
{"op":"mcm","clk":"5353820551","pt":1646218802440,"mc":[{"id":"1.195503868","rc":[{"atb":[[27,0]],"id":41419630},{"atl":[[140,6.09]],"id":41419607},{"atl":[[140,0]],"id":41419615},{"atl":[[75,0]],"id":41419624}],"con":true,"img":false}]}
{"op":"mcm","clk":"5353820562","pt":1646218802543,"mc":[{"id":"1.195503868","rc":[{"atl":[[190,0]],"id":41419601},{"atl":[[220,5.67]],"id":41419628},{"atl":[[240,0]],"id":41419604}],"con":true,"img":false}]}
{"op":"mcm","clk":"5353820578","pt":1646218802648,"mc":[{"id":"1.195503868","rc":[{"atl":[[220,0]],"id":28546943}],"con":true,"img":false}]}
{"op":"mcm","clk":"5353820591","pt":1646218802762,"mc":[{"id":"1.195503868","rc":[{"atl":[[510,2],[250,5.61]],"id":41419602},{"atb":[[7.2,14.71],[8.2,8.9]],"id":41419587},{"atl":[[130,10.81],[370,2]],"id":41419599},{"atl":[[540,4.59],[920,0]],"id":41419628}],"con":true,"img":false}]}
{"op":"mcm","clk":"5353820673","pt":1646218803274,"mc":[{"id":"1.195503868","rc":[{"atb":[[16,4.95],[18.5,3.27],[22,2.72],[5.3,61.95],[11.5,46.28],[14,9.9],[6.6,47.57],[15.5,10.32]],"id":41419609},{"atl":[[32,4.95],[34,4.8],[38,14.3],[40,9.9]],"id":41419609},{"atb":[[34,2.72],[17.5,8.07],[18,4],[9,33.3],[22,9.9],[26,17.17],[27,3.27],[7,44.4]],"id":41419617},{"atl":[[65,7.43],[160,10.61],[85,9.9]],"id":41419617},{"atb":[[18,2.72],[5.1,64.97],[8.2,32.38],[4.1,85.93],[13,9.9],[15,17.17],[15.5,3.27]],"id":41419613},{"atl":[[32,9.9],[80,14.21],[27,4.95]],"id":41419613},{"atb":[[260,2.72],[210,3.27]],"id":41419593},{"atb":[[17,16.65],[75,2.72],[38,3.6],[80,10.56],[85,9.9],[12,24.22],[50,3.27],[110,6.4]],"id":41419622},{"atl":[[220,5.67]],"id":41419622},{"atb":[[9.6,15.48],[10,16.32],[9.2,9.9],[11.5,2.72],[3.7,98.67],[6.8,22.96],[4.4,78.35]],"id":41419589},{"atl":[[16.5,15.18],[18.5,9.9],[38,14.91]],"id":41419589},{"atb":[[150,2.72],[160,5.95],[20,14.02],[100,4.61],[120,20.54],[30,9.18]],"id":41435527},{"atb":[[350,3.27],[400,3.39]],"id":41419651},{"atb":[[32,10.06],[25,3.27],[27,29.44],[7.8,39.17],[14.5,9.86],[5.9,54.37],[30,2.72]],"id":41419618},{"atl":[[80,9.9],[230,7.54],[60,7.64]],"id":41419618},{"atb":[[65,24.5],[75,2.72],[85,6.83],[24,5.79],[12,24.22],[50,3.27],[8.8,34.15]],"id":41419601},{"atl":[[170,5.89],[510,4.74]],"id":41419601},{"atb":[[20,3.27],[24,9.9],[25,23.51],[9.8,15.13],[4.9,68.3],[28,4.95],[29,5.66],[5.9,54.37]],"id":41419630},{"atl":[[75,9.9],[190,8.72],[55,7.89]],"id":41419630},{"atb":[[140,2.72],[90,9.9],[95,3.27],[48,5.66],[29,9.51],[120,10.03]],"id":41419597},{"atb":[[38,14.12],[46,9.9],[24,5.79],[12,24.22],[8.8,34.15],[29,3.27],[60,7.64]],"id":28546943},{"atl":[[170,4.95]],"id":28546943},{"atb":[[160,4.95],[170,5.1],[48,5.66],[29,9.51],[120,13.17]],"id":41419659},{"atb":[[10,4.95],[9.2,9.9],[5.3,30.97],[12,17.14],[9.8,15.48],[3.15,123.9],[3.65,100.52]],"id":41419606},{"atl":[[18.5,14.01],[40,14.71],[21,9.9]],"id":41419606},{"atb":[[65,14.83],[16,17.76],[34,7.06],[80,6.95],[90,2.72],[11,26.64],[60,9.9]],"id":41419602},{"atl":[[230,5.64],[250,5.61]],"id":41419602},{"atb":[[34,2.72],[22,4.95],[24,32.33],[12,24.22],[27,3.27],[8.8,34.15]],"id":41419585},{"atl":[[65,7.43],[130,11.82],[85,9.9]],"id":41419585},{"atb":[[65,17.02],[80,2.72],[85,3.17],[44,6.19],[55,3.27]],"id":41419614},{"atb":[[5.6,57.91],[7.2,42.96],[18.5,9.9],[20,15.48],[21,4.95],[25,2.72],[13,11.1]],"id":41419610},{"atl":[[42,4.95],[50,13.14],[500,2.54]],"id":41419610},{"atb":[[380,3.27],[430,2.72]],"id":41419656},{"atb":[[36,2.72],[5.8,55.49],[7.6,40.36],[26,9.9],[28,15.48],[14,10.24],[30,4.95]],"id":41419623},{"atl":[[65,4.95],[85,9.9],[240,7.31]],"id":41419623},{"atb":[[9,3.27],[10,2.72],[10.5,21.64],[5.3,30.97],[3.15,123.9],[3.65,100.52],[9.4,31.99]],"id":41419590},{"atl":[[19,13.76],[22,9.9],[44,24.41]],"id":41419590},{"atb":[[190,3.27],[240,2.72]],"id":41419652},{"atb":[[150,5.05],[160,4.95],[200,5.9]],"id":41435528},{"atb":[[19.5,9.9],[19,25.35],[5.8,55.49],[23,14.88],[7.6,40.36],[14,10.24]],"id":41419586},{"atl":[[140,11.12],[44,8.64],[55,9.9]],"id":41419586},{"atb":[[32,10.06],[5.8,55.49],[24,3.27],[7.6,40.36],[27,29.73],[14,10.24],[29,2.72]],"id":41419631},{"atl":[[70,7.25],[90,9.9],[250,7.1]],"id":41419631},{"atb":[[16.5,2.72],[4,88.79],[17.5,39.14],[19.5,4.95],[20,8.34],[6,26.64],[14,3.27],[3.5,106.56]],"id":41419627},{"atl":[[34,9.76],[42,9.9],[95,15.44]],"id":41419627},{"atb":[[130,2.72],[80,9.9],[20,14.02],[90,10.28],[100,6.3],[30,9.18]],"id":41419594},{"atb":[[65,2.08],[16.5,17.18],[44,3.27],[23,12.11],[50,16.35],[60,2.72]],"id":41419607},{"atl":[[140,6.09],[150,0],[370,5.56]],"id":41419607},{"atb":[[32,4.29],[160,4.95],[80,3.27],[10.5,28.04],[110,2.72],[120,18.66],[15.5,18.37]],"id":28546950},{"atb":[[75,15.48],[18,15.66],[80,9.9],[42,3.24],[100,9.28],[13,22.19]],"id":41419603},{"atl":[[260,5.56],[280,5]],"id":41419603},{"atb":[[10,29.59],[44,27.89],[55,4.95],[60,5.41],[30,4.59],[15,19.02]],"id":41419615},{"atl":[[130,4.95]],"id":41419615},{"atb":[[18.5,3.27],[19.5,31.99],[22,2.72],[23,4.95],[24,6.89],[5.7,56.68],[9.4,15.86],[4.7,72]],"id":41419611},{"atl":[[42,3.86],[44,4.95],[55,34.41]],"id":41419611},{"atb":[[260,3.27],[310,2.72]],"id":41419657},{"atb":[[32,10.06],[17.5,8.07],[36,2.72],[9,33.3],[27,9.9],[28,15.48],[7,44.4]],"id":41419624},{"atl":[[70,7.25],[90,9.9],[100,12.21]],"id":41419624},{"atb":[[65,21.01],[16.5,17.18],[140,6.09],[46,3.27],[23,12.11],[100,9.9]],"id":41435525},{"atb":[[160,4.95],[85,5.89],[44,6.19],[120,18],[60,3.27]],"id":41419653},{"atb":[[18,46.69],[20,4.95],[21,10.65],[8.8,17.07],[4.4,78.35],[5.4,60.54]],"id":41419620},{"atl":[[38,9.23],[46,9.9],[120,12.64]],"id":41419620},{"atb":[[7.2,14.71],[4.5,38.05],[2.9,140.21],[8.2,8.9],[3.25,118.39],[7.8,4.95],[7,9.9]],"id":41419587},{"atl":[[12,19.36],[26,36.01],[14,9.9]],"id":41419587},{"atb":[[34,2.72],[6.2,51.23],[22,9.9],[8.2,37],[26,17.17],[27,3.27],[15.5,9.18]],"id":41419632},{"atl":[[75,9.9],[200,8.38],[55,4.95]],"id":41419632},{"atb":[[32,9.9],[17,14.57],[40,13.85],[42,3.27],[6.8,45.93],[55,2.72],[8.8,34.15]],"id":41419599},{"atl":[[130,10.81],[110,6.4]],"id":41419599},{"atb":[[34,8.07],[75,2.72],[80,22.29],[22,12.68],[100,4.95],[50,3.27]],"id":41419628},{"atl":[[540,4.59],[220,5.67]],"id":41419628},{"atb":[[130,4.95],[140,7.74],[70,3.85],[150,2.72],[100,3.27]],"id":41419595},{"atb":[[34,3.27],[42,24.62],[44,2.72],[22,6.34],[11,26.64],[50,8.19],[8.4,35.99]],"id":41419608},{"atl":[[110,6.4]],"id":41419608},{"atb":[[80,24.11],[85,2.72],[100,6.55],[27,5.12],[13.5,21.31],[60,3.27],[9.4,31.71]],"id":41419604},{"atl":[[540,4.59],[220,5.67]],"id":41419604},{"atb":[[18,29.48],[20,8.22],[5.5,59.19],[25,2.72],[12.5,11.58],[7,44.4]],"id":41419616},{"atl":[[40,9.02],[48,29.48]],"id":41419616},{"atb":[[16,8.87],[36,4.95],[6.4,49.33],[40,2.72],[29,9.9],[8.4,35.99],[30,15.48]],"id":41419625},{"atl":[[70,4.95],[660,2.16],[90,9.9]],"id":41419625},{"atb":[[32,4.29],[70,3.27],[10.5,28.04],[44,9.9],[95,2.72],[55,11.96],[15.5,18.37]],"id":41419592},{"atb":[[34,8.07],[160,4.95],[80,2.72],[22,12.68],[55,5.27],[120,20.2]],"id":41419654},{"atb":[[160,9.38],[80,3.27],[90,2.99],[110,2.72],[120,9.9]],"id":41435526},{"atb":[[75,3.27],[90,2.99],[100,2.72]],"id":41419621},{"atb":[[4,88.79],[9,9.9],[9.2,17.98],[10.5,11.63],[6,26.64],[9.8,4.95],[3.5,106.56]],"id":41419588},{"atl":[[16,15.52],[18,9.9],[40,17.27]],"id":41419588},{"atb":[[160,3.27],[210,2.72]],"id":41419600},{"atb":[[75,4.95],[9,33.3],[80,2],[42,3.27],[25,5.54],[12.5,23.16],[55,23.4]],"id":41419629},{"atl":[[160,5.95]],"id":41419629},{"atb":[[160,2.72],[110,3.27]],"id":41419596},{"atb":[[140,1.91],[70,3.85],[160,12.93],[170,2.72],[120,13.17]],"id":41419658}],"con":true,"img":false}]}
{"op":"mcm","clk":"5353820717","pt":1646218803545,"mc":[{"id":"1.195503868","rc":[{"atb":[[7.4,3.27],[8.4,2.72]],"id":41419587},{"atl":[[230,0]],"id":41419628}],"con":true,"img":false}]}
{"op":"mcm","clk":"5353820757","pt":1646218803864,"mc":[{"id":"1.195503868","rc":[{"atl":[[370,2]],"id":41419607}],"con":true,"img":false}]}
{"op":"mcm","clk":"5353820769","pt":1646218803966,"mc":[{"id":"1.195503868","rc":[{"atl":[[160,8.8]],"id":41419607}],"con":true,"img":false}]}
{"op":"mcm","clk":"5353820809","pt":1646218804246,"mc":[{"id":"1.195503868","rc":[{"atb":[[7.2,0],[8.6,20.86],[7.8,32.93]],"id":41419587}],"con":true,"img":false}]}
{"op":"mcm","clk":"5353820900","pt":1646218804963,"mc":[{"id":"1.195503868","rc":[{"atl":[[860,0]],"id":41419592}],"con":true,"img":false}]}
{"op":"mcm","clk":"5353820931","pt":1646218805178,"mc":[{"id":"1.195503868","rc":[{"atl":[[870,3.61]],"id":41419592}],"con":true,"img":false}]}
{"op":"mcm","clk":"5353820951","pt":1646218805236,"mc":[{"id":"1.195503868","rc":[{"atb":[[8.2,0]],"id":41419587}],"con":true,"img":false}]}
{"op":"mcm","clk":"5353821045","pt":1646218806058,"mc":[{"id":"1.195503868","rc":[{"atb":[[11.5,12.68]],"id":41419609}],"con":true,"img":false}]}
{"op":"mcm","clk":"5353821074","pt":1646218806372,"mc":[{"id":"1.195503868","rc":[{"atb":[[16,19.46]],"id":41419609}],"con":true,"img":false}]}
{"op":"mcm","clk":"5353821087","pt":1646218806473,"mc":[{"id":"1.195503868","rc":[{"atb":[[18.5,0],[22,0]],"id":41419609},{"atb":[[20,12.21],[25,0]],"id":41419610},{"atb":[[70,0],[95,0]],"id":41419592}],"con":true,"img":false}]}
{"op":"mcm","clk":"5353821123","pt":1646218806844,"mc":[{"id":"1.195503868","rc":[{"atb":[[20,0]],"id":41419610}],"con":true,"img":false}]}
{"op":"mcm","clk":"5353821147","pt":1646218807148,"mc":[{"id":"1.195503868","rc":[{"atb":[[16,30.03],[18,3.27],[21,2.72]],"id":41419609},{"atb":[[18.5,31.99],[21,12.88]],"id":41419610},{"atb":[[32,17.04],[55,5.52]],"id":41419592}],"con":true,"img":false}]}
{"op":"mcm","clk":"5353821154","pt":1646218807249,"mc":[{"id":"1.195503868","rc":[{"atb":[[22,3.27],[27,2.72]],"id":41419610},{"atb":[[65,3.27],[90,2.72]],"id":41419592}],"con":true,"img":false}]}
{"op":"mcm","clk":"5353821171","pt":1646218807465,"mc":[{"id":"1.195503868","rc":[{"atl":[[42,8.82]],"id":41419610}],"con":true,"img":false}]}
{"op":"mcm","clk":"5353821188","pt":1646218807672,"mc":[{"id":"1.195503868","rc":[{"atl":[[540,4.62],[840,0]],"id":28546943}],"con":true,"img":false}]}
{"op":"mcm","clk":"5353821213","pt":1646218807936,"mc":[{"id":"1.195503868","rc":[{"atb":[[15.5,0]],"id":41419609},{"atb":[[32,4.29]],"id":41419592}],"con":true,"img":false}]}
{"op":"mcm","clk":"5353821238","pt":1646218808248,"mc":[{"id":"1.195503868","rc":[{"atl":[[42,4.95],[50,9.9]],"id":41419610},{"atl":[[220,0.72]],"id":41419604},{"atl":[[40,0],[42,4.95],[48,19.57],[50,9.9]],"id":41419616},{"atl":[[1000,0.15]],"id":41419600}],"con":true,"img":false}]}
{"op":"mcm","clk":"5353821254","pt":1646218808451,"mc":[{"id":"1.195503868","rc":[{"atl":[[210,4.95]],"id":41419604}],"con":true,"img":false}]}
{"op":"mcm","clk":"5353821265","pt":1646218808559,"mc":[{"id":"1.195503868","rc":[{"atl":[[280,0],[640,4.21]],"id":41419603}],"con":true,"img":false}]}
{"op":"mcm","clk":"5353821283","pt":1646218808869,"mc":[{"id":"1.195503868","rc":[{"atl":[[48,0],[110,14.94]],"id":41419616}],"con":true,"img":false}]}
{"op":"mcm","clk":"5353821309","pt":1646218809175,"mc":[{"id":"1.195503868","rc":[{"atl":[[46,3.52]],"id":41419616}],"con":true,"img":false}]}
{"op":"mcm","clk":"5353821322","pt":1646218809279,"mc":[{"id":"1.195503868","rc":[{"atl":[[50,13.14]],"id":41419610}],"con":true,"img":false}]}
{"op":"mcm","clk":"5353821384","pt":1646218809859,"mc":[{"id":"1.195503868","rc":[{"atl":[[250,0],[510,4.79]],"id":41419602},{"atl":[[130,0],[370,5.84]],"id":41419599}],"con":true,"img":false}]}
{"op":"mcm","clk":"5353821467","pt":1646218810541,"mc":[{"id":"1.195503868","rc":[{"atl":[[510,2]],"id":41419602}],"con":true,"img":false}]}
{"op":"mcm","clk":"5353821522","pt":1646218811061,"mc":[{"id":"1.195503868","rc":[{"atl":[[160,0]],"id":41419607}],"con":true,"img":false}]}
{"op":"mcm","clk":"5353821553","pt":1646218811375,"mc":[{"id":"1.195503868","rc":[{"atl":[[370,5.85]],"id":41419607}],"con":true,"img":false}]}
{"op":"mcm","clk":"5353821608","pt":1646218811847,"mc":[{"id":"1.195503868","rc":[{"atb":[[130,3.95]],"id":41419594}],"con":true,"img":false}]}
{"op":"mcm","clk":"5353821638","pt":1646218812157,"mc":[{"id":"1.195503868","rc":[{"atb":[[65,4.95]],"id":41419614}],"con":true,"img":false}]}
{"op":"mcm","clk":"5353821645","pt":1646218812262,"mc":[{"id":"1.195503868","rc":[{"atb":[[80,8]],"id":41419614}],"con":true,"img":false}]}
{"op":"mcm","clk":"5353821673","pt":1646218812572,"mc":[{"id":"1.195503868","rc":[{"atl":[[860,1.65],[870,2]],"id":41419592}],"con":true,"img":false}]}
{"op":"mcm","clk":"5353821758","pt":1646218813251,"mc":[{"id":"1.195503868","rc":[{"atl":[[860,0]],"id":41419592}],"con":true,"img":false}]}
{"op":"mcm","clk":"5353821893","pt":1646218814557,"mc":[{"id":"1.195503868","rc":[{"atb":[[11.5,0]],"id":41419589}],"con":true,"img":false}]}
{"op":"mcm","clk":"5353821936","pt":1646218814982,"mc":[{"id":"1.195503868","rc":[{"atb":[[9.6,12.21]],"id":41419589}],"con":true,"img":false}]}
{"op":"mcm","clk":"5353821973","pt":1646218815286,"mc":[{"id":"1.195503868","rc":[{"atb":[[9.6,0],[9.2,54.64]],"id":41419589}],"con":true,"img":false}]}
{"op":"mcm","clk":"5353822027","pt":1646218815768,"mc":[{"id":"1.195503868","rc":[{"atb":[[13,2.72]],"id":41419589}],"con":true,"img":false}]}
{"op":"mcm","clk":"5353822041","pt":1646218815864,"mc":[{"id":"1.195503868","rc":[{"atl":[[280,5.15]],"id":41419603}],"con":true,"img":false}]}
{"op":"mcm","clk":"5353822049","pt":1646218815970,"mc":[{"id":"1.195503868","rc":[{"atl":[[640,2]],"id":41419603}],"con":true,"img":false}]}
{"op":"mcm","clk":"5353822077","pt":1646218816273,"mc":[{"id":"1.195503868","rc":[{"atl":[[830,0],[440,5.27]],"id":41419615},{"atb":[[19.5,9.9],[22,17.44]],"id":41419611},{"atl":[[42,8.82],[50,29.48],[110,2]],"id":41419616}],"con":true,"img":false}]}
{"op":"mcm","clk":"5353822088","pt":1646218816377,"mc":[{"id":"1.195503868","rc":[{"atb":[[10.5,3.27]],"id":41419589}],"con":true,"img":false}]}
{"op":"mcm","clk":"5353822106","pt":1646218816582,"mc":[{"id":"1.195503868","rc":[{"atl":[[190,7.6],[510,2]],"id":41419601},{"atl":[[210,5.71]],"id":41419604}],"con":true,"img":false}]}
{"op":"mcm","clk":"5353822113","pt":1646218816687,"mc":[{"id":"1.195503868","rc":[{"atl":[[280,0]],"id":41419603}],"con":true,"img":false}]}
{"op":"mcm","clk":"5353822158","pt":1646218817153,"mc":[{"id":"1.195503868","rc":[{"atl":[[46,0]],"id":41419616}],"con":true,"img":false}]}
{"op":"mcm","clk":"5353822165","pt":1646218817252,"mc":[{"id":"1.195503868","rc":[{"atl":[[190,0]],"id":41419601},{"atl":[[250,5.78]],"id":41419602},{"atl":[[130,11.13],[370,2]],"id":41419599},{"atl":[[540,2],[240,6.02]],"id":41419628}],"con":true,"img":false}]}
{"op":"mcm","clk":"5353822174","pt":1646218817359,"mc":[{"id":"1.195503868","rc":[{"atl":[[220,0]],"id":41419604}],"con":true,"img":false}]}
{"op":"mcm","clk":"5353822222","pt":1646218817880,"mc":[{"id":"1.195503868","rc":[{"atl":[[540,2]],"id":41419604}],"con":true,"img":false}]}
{"op":"mcm","clk":"5353822241","pt":1646218818088,"mc":[{"id":"1.195503868","rc":[{"atl":[[230,6.29]],"id":41419604}],"con":true,"img":false}]}
{"op":"mcm","clk":"5353822251","pt":1646218818193,"mc":[{"id":"1.195503868","rc":[{"atl":[[240,0]],"id":41419628}],"con":true,"img":false}]}
{"op":"mcm","clk":"5353822281","pt":1646218818454,"mc":[{"id":"1.195503868","rc":[{"atl":[[160,9.06],[370,2]],"id":41419607}],"con":true,"img":false}]}
{"op":"mcm","clk":"5353822303","pt":1646218818662,"mc":[{"id":"1.195503868","rc":[{"atl":[[1000,2.15]],"id":41419597},{"atl":[[790,2],[880,0]],"id":41419614},{"atl":[[300,2],[370,0]],"id":41419607},{"atl":[[180,2],[230,0]],"id":41419624},{"atl":[[1000,2]],"id":41419595},{"atl":[[710,2],[770,0]],"id":41419608},{"atl":[[85,2],[110,0]],"id":41419616},{"atl":[[620,2],[680,0]],"id":41419625},{"atl":[[770,2],[870,0]],"id":41419592},{"atl":[[820,2],[930,0]],"id":41419621},{"atl":[[810,2],[890,0]],"id":41419629}],"con":true,"img":false}]}
{"op":"mcm","clk":"5353822329","pt":1646218818976,"mc":[{"id":"1.195503868","rc":[{"atb":[[100,6.87]],"id":41419621}],"con":true,"img":false}]}
{"op":"mcm","clk":"5353822358","pt":1646218819281,"mc":[{"id":"1.195503868","rc":[{"atl":[[620,4.33],[660,0.23]],"id":41419625},{"atl":[[760,0.2]],"id":41419592},{"atl":[[810,0.19]],"id":41419621}],"con":true,"img":false}]}
{"op":"mcm","clk":"5353822393","pt":1646218819644,"mc":[{"id":"1.195503868","rc":[{"atl":[[870,1.66]],"id":41419592}],"con":true,"img":false}]}
{"op":"mcm","clk":"5353822421","pt":1646218819960,"mc":[{"id":"1.195503868","rc":[{"atl":[[910,1.76],[940,0]],"id":41419621}],"con":true,"img":false}]}
{"op":"mcm","clk":"5353822457","pt":1646218820272,"mc":[{"id":"1.195503868","rc":[{"atl":[[840,0]],"id":41419592},{"atl":[[910,1.59]],"id":41419621}],"con":true,"img":false}]}
{"op":"mcm","clk":"5353822588","pt":1646218821592,"mc":[{"id":"1.195503868","rc":[{"atb":[[55,12.55]],"id":41419592}],"con":true,"img":false}]}
{"op":"mcm","clk":"5353822604","pt":1646218821749,"mc":[{"id":"1.195503868","rc":[{"atl":[[65,2.47],[85,0]],"id":41419585},{"atb":[[18.5,9.9],[21,25.1]],"id":41419610},{"atl":[[40,4.95],[42,3.86],[48,9.9],[50,19.57]],"id":41419616},{"atl":[[1000,0.15]],"id":41435526}],"con":true,"img":false}]}
{"op":"mcm","clk":"5353822616","pt":1646218821867,"mc":[{"id":"1.195503868","rc":[{"atl":[[80,9.9],[60,4.95]],"id":41419585}],"con":true,"img":false}]}
{"op":"mcm","clk":"5353822638","pt":1646218822068,"mc":[{"id":"1.195503868","rc":[{"atl":[[110,2]],"id":41419585}],"con":true,"img":false}]}
{"op":"mcm","clk":"5353822649","pt":1646218822174,"mc":[{"id":"1.195503868","rc":[{"atl":[[130,0],[75,9.72]],"id":41419585}],"con":true,"img":false}]}
{"op":"mcm","clk":"5353822660","pt":1646218822277,"mc":[{"id":"1.195503868","rc":[{"atb":[[140,1.13],[150,4.95],[100,0],[110,9.9]],"id":41435525}],"con":true,"img":false}]}
{"op":"mcm","clk":"5353822689","pt":1646218822592,"mc":[{"id":"1.195503868","rc":[{"atl":[[60,7.64]],"id":41419585},{"atl":[[40,0],[42,8.82],[48,0],[50,29.48]],"id":41419616}],"con":true,"img":false}]}
{"op":"mcm","clk":"5353822715","pt":1646218822848,"mc":[{"id":"1.195503868","rc":[{"atl":[[280,5.22]],"id":41419603},{"atb":[[65,4.8],[150,6.01],[110,18.96]],"id":41435525},{"atl":[[210,0],[220,4.95]],"id":41419604}],"con":true,"img":false}]}
{"op":"mcm","clk":"5353822727","pt":1646218822954,"mc":[{"id":"1.195503868","rc":[{"atl":[[510,2]],"id":41419603},{"atl":[[540,0],[440,2]],"id":41419604}],"con":true,"img":false}]}
{"op":"mcm","clk":"5353822741","pt":1646218823058,"mc":[{"id":"1.195503868","rc":[{"atl":[[640,0]],"id":41419603}],"con":true,"img":false}]}
{"op":"mcm","clk":"5353822752","pt":1646218823160,"mc":[{"id":"1.195503868","rc":[{"atl":[[50,9.9]],"id":41419616}],"con":true,"img":false}]}
{"op":"mcm","clk":"5353822793","pt":1646218823574,"mc":[{"id":"1.195503868","rc":[{"atl":[[65,0]],"id":41419585},{"atl":[[85,19.23],[48,3.37]],"id":41419616}],"con":true,"img":false}]}
{"op":"mcm","clk":"5353822806","pt":1646218823781,"mc":[{"id":"1.195503868","rc":[{"atb":[[140,0]],"id":41435525},{"atl":[[220,5.67]],"id":41419604}],"con":true,"img":false}]}
{"op":"mcm","clk":"5353822842","pt":1646218824298,"mc":[{"id":"1.195503868","rc":[{"atl":[[250,0],[510,4.87]],"id":41419602},{"atl":[[130,0],[370,5.96]],"id":41419599}],"con":true,"img":false}]}
{"op":"mcm","clk":"5353822870","pt":1646218824560,"mc":[{"id":"1.195503868","rc":[{"atl":[[48,0]],"id":41419616}],"con":true,"img":false}]}
{"op":"mcm","clk":"5353822945","pt":1646218825288,"mc":[{"id":"1.195503868","rc":[{"atl":[[440,5.33],[230,0]],"id":41419604}],"con":true,"img":false}]}
{"op":"mcm","clk":"5353822973","pt":1646218825598,"mc":[{"id":"1.195503868","rc":[{"atb":[[46,0],[60,2.68]],"id":28546943}],"con":true,"img":false}]}
{"op":"mcm","clk":"5353822984","pt":1646218825653,"mc":[{"id":"1.195503868","rc":[{"atb":[[65,4.95],[48,9.9]],"id":28546943},{"atl":[[300,6.89],[160,0]],"id":41419607}],"con":true,"img":false}]}
{"op":"mcm","clk":"5353823013","pt":1646218825965,"mc":[{"id":"1.195503868","rc":[{"atb":[[38,2.72]],"id":28546943}],"con":true,"img":false}]}
{"op":"mcm","clk":"5353823056","pt":1646218826381,"mc":[{"id":"1.195503868","rc":[{"atb":[[65,7.43],[29,14.99]],"id":28546943}],"con":true,"img":false}]}
{"op":"mcm","clk":"5353823114","pt":1646218826901,"mc":[{"id":"1.195503868","rc":[{"atb":[[6.2,0],[5.3,23.26]],"id":41419589},{"atl":[[1000,0.15]],"id":41419597},{"atb":[[17,0],[19.5,5.41]],"id":41419607},{"atl":[[820,0],[840,2]],"id":41419621}],"con":true,"img":false}]}
{"op":"mcm","clk":"5353823132","pt":1646218827105,"mc":[{"id":"1.195503868","rc":[{"atb":[[60,0]],"id":28546943},{"atb":[[24,5.79]],"id":41419585},{"atb":[[18.5,0],[21,20.14]],"id":41419610},{"atb":[[46,9.9],[60,10.36]],"id":41419615},{"atl":[[44,0],[55,24.5]],"id":41419611},{"atb":[[8.6,0]],"id":41419587},{"atl":[[1000,0]],"id":41435526}],"con":true,"img":false}]}
{"op":"mcm","clk":"5353823140","pt":1646218827211,"mc":[{"id":"1.195503868","rc":[{"atl":[[34,0]],"id":41419609},{"atb":[[22,0],[24,9.9],[26,12.21],[28,4.95]],"id":41419617},{"atb":[[10.5,0],[13,0]],"id":41419589},{"atl":[[16.5,10.22],[17,9.9],[18.5,0],[15,4.95]],"id":41419589},{"atl":[[65,4.95],[80,0],[85,9.9],[60,2.68]],"id":41419618},{"atb":[[65,14.59],[75,12.63],[85,1.88],[95,4.95]],"id":41419601},{"atl":[[75,0],[80,9.9],[55,2.93],[60,4.95]],"id":41419630},{"atb":[[130,4.95],[90,0],[95,13.17],[120,5.08]],"id":41419597},{"atb":[[10,0],[9.2,0],[10.5,4.95],[9.4,9.9]],"id":41419606},{"atb":[[65,24.74],[80,2],[85,4.95],[90,4.5],[60,0]],"id":41419602},{"atb":[[34,0],[27,0]],"id":41419585},{"atb":[[65,0],[70,4.95],[90,2.27]],"id":41419614},{"atb":[[19,9.9],[22,8.22]],"id":41419610},{"atb":[[36,7.25]],"id":41419623},{"atl":[[65,7.43]],"id":41419623},{"atl":[[18.5,4.95],[19,8.8],[21,9.9],[22,0]],"id":41419590},{"atb":[[44,17.98],[55,0]],"id":41419615},{"atl":[[46,4.95],[60,9.9]],"id":41419611},{"atb":[[36,7.25]],"id":41419624},{"atl":[[11.5,4.95],[12,14.41],[13.5,9.9],[14,0]],"id":41419587},{"atb":[[22,0],[23,9.9],[26,12.21],[27,8.22]],"id":41419632},{"atl":[[75,0],[80,9.9],[55,0],[60,4.95]],"id":41419632},{"atb":[[130,0],[140,12.69]],"id":41419595},{"atb":[[42,14.71],[44,12.63],[50,3.23],[55,4.95]],"id":41419608},{"atb":[[18,19.57],[18.5,9.9],[20,3.27],[21,4.95]],"id":41419616},{"atb":[[36,0],[38,4.95],[40,6.79],[29,0],[30,25.39]],"id":41419625},{"atl":[[70,2.34],[75,4.95],[90,0],[95,9.9]],"id":41419625},{"atb":[[44,0],[46,9.9],[55,7.59],[60,4.95]],"id":41419592},{"atb":[[95,4.95]],"id":41419621},{"atb":[[9.2,14.71],[10.5,0]],"id":41419588},{"atl":[[16,10.56],[18,0]],"id":41419588}],"con":true,"img":false}]}
{"op":"mcm","clk":"5353823161","pt":1646218827367,"mc":[{"id":"1.195503868","rc":[{"atl":[[34,3.03],[44,22.08]],"id":41419590},{"atl":[[620,2.33],[230,2]],"id":41419625}],"con":true,"img":false}]}
{"op":"mcm","clk":"5353823170","pt":1646218827473,"mc":[{"id":"1.195503868","rc":[{"atl":[[17,9.9],[15,4.95]],"id":41419588}],"con":true,"img":false}]}
{"op":"mcm","clk":"5353823187","pt":1646218827683,"mc":[{"id":"1.195503868","rc":[{"atl":[[38,0],[40,31.99]],"id":41419609},{"atb":[[26,0]],"id":41419617},{"atb":[[9.2,9.9],[6.8,62.43]],"id":41419589},{"atl":[[17,49.37],[38,2.7]],"id":41419589},{"atl":[[85,27.29],[230,2]],"id":41419618},{"atb":[[65,0],[75,27.34]],"id":41419601},{"atl":[[80,25.68],[190,2]],"id":41419630},{"atb":[[130,10.05],[120,0]],"id":41419597},{"atb":[[65,13.17],[80,16.48]],"id":41419602},{"atb":[[12,50.02]],"id":41419585},{"atl":[[18,9.32],[21,37.73],[44,0]],"id":41419590},{"atb":[[44,3.27],[46,25.11]],"id":41419615},{"atl":[[140,12.55],[55,0]],"id":41419611},{"atb":[[7.4,46.78],[7.8,4.95]],"id":41419587},{"atl":[[11,15.85],[26,4],[13.5,31.99]],"id":41419587},{"atb":[[42,0],[44,24.8],[60,2.68]],"id":41419608},{"atb":[[18,0],[20,23.73]],"id":41419616},{"atb":[[9,41.32],[9.2,0]],"id":41419588},{"atl":[[17,41.32],[40,0],[30,3.45]],"id":41419588}],"con":true,"img":false}]}
{"op":"mcm","clk":"5353823199","pt":1646218827789,"mc":[{"id":"1.195503868","rc":[{"atb":[[95,6.63]],"id":41419601}],"con":true,"img":false}]}
{"op":"mcm","clk":"5353823209","pt":1646218827890,"mc":[{"id":"1.195503868","rc":[{"atb":[[22,12.5],[25,3.27],[30,2.72]],"id":41419585},{"atb":[[32,4.95]],"id":41419624},{"atb":[[7.8,27.04]],"id":41419587},{"atb":[[9,44.59],[10,2.72],[9.2,19.33]],"id":41419588}],"con":true,"img":false}]}
{"op":"mcm","clk":"5353823216","pt":1646218827998,"mc":[{"id":"1.195503868","rc":[{"atb":[[27,21.66]],"id":41419617},{"atb":[[10,19.59],[12.5,2.72]],"id":41419589},{"atb":[[80,14.47]],"id":41419602},{"atl":[[620,0]],"id":41419623},{"atl":[[190,0.83]],"id":41419632},{"atl":[[660,0]],"id":41419625},{"atl":[[15,16.27]],"id":41419588}],"con":true,"img":false}]}
{"op":"mcm","clk":"5353823228","pt":1646218828101,"mc":[{"id":"1.195503868","rc":[{"atl":[[15,16.27]],"id":41419589},{"atl":[[570,2]],"id":41419603}],"con":true,"img":false}]}
{"op":"mcm","clk":"5353823238","pt":1646218828219,"mc":[{"id":"1.195503868","rc":[{"atl":[[510,0]],"id":41419603}],"con":true,"img":false}]}
{"op":"mcm","clk":"5353823256","pt":1646218828368,"mc":[{"id":"1.195503868","rc":[{"atb":[[12,24.22]],"id":41419585},{"atl":[[19,0]],"id":41419590},{"atl":[[12,0]],"id":41419587},{"atl":[[190,8.62],[200,2]],"id":41419632},{"atb":[[50,0]],"id":41419608}],"con":true,"img":false}]}
{"op":"mcm","clk":"5353823266","pt":1646218828468,"mc":[{"id":"1.195503868","rc":[{"atb":[[46,9.9]],"id":41419615},{"atb":[[9,13.17]],"id":41419588}],"con":true,"img":false}]}
{"op":"mcm","clk":"5353823283","pt":1646218828683,"mc":[{"id":"1.195503868","rc":[{"atb":[[85,0]],"id":41419601}],"con":true,"img":false}]}
{"op":"mcm","clk":"5353823293","pt":1646218828781,"mc":[{"id":"1.195503868","rc":[{"atl":[[580,0]],"id":41419632},{"atl":[[16,0]],"id":41419588}],"con":true,"img":false}]}
{"op":"mcm","clk":"5353823324","pt":1646218829102,"mc":[{"id":"1.195503868","rc":[{"atl":[[16.5,0],[15,4.95]],"id":41419589}],"con":true,"img":false}]}
{"op":"mcm","clk":"5353823368","pt":1646218829468,"mc":[{"id":"1.195503868","rc":[{"atl":[[75,0],[80,28.43]],"id":41419585}],"con":true,"img":false}]}
{"op":"mcm","clk":"5353823411","pt":1646218829785,"mc":[{"id":"1.195503868","rc":[{"atb":[[9.2,49.31],[6.8,22.96]],"id":41419589},{"atl":[[280,0],[570,4.59]],"id":41419603},{"atb":[[65,20.9],[110,9.9]],"id":41435525}],"con":true,"img":false}]}
{"op":"mcm","clk":"5353823449","pt":1646218830113,"mc":[{"id":"1.195503868","rc":[{"atl":[[17,59.28]],"id":41419589}],"con":true,"img":false}]}
{"op":"mcm","clk":"5353823491","pt":1646218830436,"mc":[{"id":"1.195503868","rc":[{"atl":[[790,0],[890,3.55]],"id":41419614},{"atl":[[300,4.89],[400,2]],"id":41419607},{"atl":[[180,0],[250,2]],"id":41419624},{"atl":[[1000,0]],"id":41419595},{"atl":[[710,0],[800,3.53]],"id":41419608},{"atl":[[580,2],[440,3.33]],"id":41419604},{"atl":[[770,0],[870,3.66]],"id":41419592},{"atl":[[810,0],[890,2]],"id":41419629}],"con":true,"img":false}]}
{"op":"mcm","clk":"5353823537","pt":1646218830777,"mc":[{"id":"1.195503868","rc":[{"atl":[[570,2]],"id":41419603},{"atb":[[7.4,43.51],[8.4,0]],"id":41419587},{"atb":[[65,0],[90,0]],"id":41419592}],"con":true,"img":false}]}
{"op":"mcm","clk":"5353823551","pt":1646218830881,"mc":[{"id":"1.195503868","rc":[{"atl":[[190,7.82]],"id":41419601},{"atl":[[290,4.53],[890,2]],"id":41419614},{"atl":[[260,0.61]],"id":41419603},{"atl":[[130,11.43],[800,2]],"id":41419608},{"atl":[[780,1.89],[870,2]],"id":41419592}],"con":true,"img":false}]}
{"op":"mcm","clk":"5353823577","pt":1646218831090,"mc":[{"id":"1.195503868","rc":[{"atl":[[220,4.95],[230,0.69]],"id":41419602},{"atl":[[250,4.95]],"id":41419603}],"con":true,"img":false}]}
{"op":"mcm","clk":"5353823616","pt":1646218831400,"mc":[{"id":"1.195503868","rc":[{"atb":[[55,0.56]],"id":41419592}],"con":true,"img":false}]}
{"op":"mcm","clk":"5353823628","pt":1646218831501,"mc":[{"id":"1.195503868","rc":[{"atl":[[220,5.67],[510,2],[250,5.94]],"id":41419602},{"atl":[[250,5.59]],"id":41419603},{"atl":[[130,11.44]],"id":41419599},{"atl":[[240,6.19]],"id":41419628},{"atb":[[85,2.72],[46,24.62],[60,8.85]],"id":41419592}],"con":true,"img":false}]}
{"op":"mcm","clk":"5353823642","pt":1646218831605,"mc":[{"id":"1.195503868","rc":[{"atl":[[370,2]],"id":41419599}],"con":true,"img":false}]}
{"op":"mcm","clk":"5353823666","pt":1646218831764,"mc":[{"id":"1.195503868","rc":[{"atl":[[290,0]],"id":41419614},{"atb":[[8,2.72],[7,13.17]],"id":41419587},{"atl":[[780,0]],"id":41419592}],"con":true,"img":false}]}
{"op":"mcm","clk":"5353823694","pt":1646218832079,"mc":[{"id":"1.195503868","rc":[{"atl":[[300,4.95]],"id":41419592},{"atl":[[840,0],[910,3.59]],"id":41419621}],"con":true,"img":false}]}
{"op":"mcm","clk":"5353823704","pt":1646218832192,"mc":[{"id":"1.195503868","rc":[{"atl":[[32,0],[38,4.95],[40,22.08],[46,9.9]],"id":41419609},{"atl":[[65,0],[80,4.95],[85,0],[100,9.9]],"id":41419617},{"atl":[[60,0]],"id":41419618},{"atb":[[70,9.9],[75,17.44],[90,4.95],[95,1.68]],"id":41419601},{"atl":[[170,4.95]],"id":41419601},{"atb":[[65,0],[46,9.9],[48,0],[60,4.95]],"id":28546943},{"atl":[[1000,0]],"id":41419659},{"atl":[[280,4.95],[220,0],[230,0],[250,0]],"id":41419602},{"atl":[[270,0]],"id":41419614},{"atl":[[42,0],[44,4.95],[50,3.23],[55,9.9]],"id":41419610},{"atb":[[10,7.67],[9.2,9.9],[10.5,0],[9.4,22.08]],"id":41419590},{"atl":[[140,0],[170,4.95]],"id":41419607},{"atl":[[260,0],[250,0]],"id":41419603},{"atl":[[130,0],[150,4.95],[120,0]],"id":41419615},{"atl":[[70,0],[120,9.9]],"id":41419624},{"atb":[[7.2,4.95],[6.4,9.9],[7.8,0],[7,3.27]],"id":41419587},{"atl":[[75,4.95],[80,0],[95,9.9],[60,0]],"id":41419632},{"atl":[[130,0]],"id":41419599},{"atl":[[290,4.95],[220,0]],"id":41419628},{"atl":[[270,4.95],[580,4.56],[220,0.72],[440,0]],"id":41419604},{"atl":[[65,9.9],[42,0],[48,4.95],[50,0]],"id":41419616},{"atl":[[75,0],[95,0]],"id":41419625},{"atb":[[55,0]],"id":41419592},{"atl":[[1000,0]],"id":41419600}],"con":true,"img":false}]}
{"op":"mcm","clk":"5353823726","pt":1646218832390,"mc":[{"id":"1.195503868","rc":[{"atl":[[520,0],[140,2]],"id":41419610},{"atl":[[220,0]],"id":41419604}],"con":true,"img":false}]}
{"op":"mcm","clk":"5353823734","pt":1646218832491,"mc":[{"id":"1.195503868","rc":[{"atl":[[300,4.95]],"id":41419603},{"atb":[[8,25.37]],"id":41419587},{"atl":[[300,2],[230,0]],"id":41419625}],"con":true,"img":false}]}
{"op":"mcm","clk":"5353823745","pt":1646218832597,"mc":[{"id":"1.195503868","rc":[{"atl":[[38,9.23]],"id":41419609},{"atl":[[55,29.48],[500,0]],"id":41419610},{"atb":[[9.4,0]],"id":41419590},{"atl":[[300,0],[400,5.72]],"id":41419607},{"atl":[[170,8.76]],"id":41419615}],"con":true,"img":false}]}
{"op":"mcm","clk":"5353823755","pt":1646218832700,"mc":[{"id":"1.195503868","rc":[{"atl":[[440,2]],"id":41419615},{"atl":[[300,0],[620,4.33]],"id":41419625}],"con":true,"img":false}]}
{"op":"mcm","clk":"5353823765","pt":1646218832806,"mc":[{"id":"1.195503868","rc":[{"atb":[[9.2,38.5]],"id":41419590},{"atl":[[100,0],[120,22.34]],"id":41419624},{"atl":[[300,0]],"id":41419592}],"con":true,"img":false}]}
{"op":"mcm","clk":"5353823774","pt":1646218832911,"mc":[{"id":"1.195503868","rc":[{"atl":[[36,4.95],[38,4.28],[44,9.9],[46,0]],"id":41419609},{"atl":[[75,7.09],[80,0],[95,9.9],[100,0]],"id":41419617},{"atl":[[65,7.43]],"id":41419618},{"atl":[[170,0],[190,12.77]],"id":41419601},{"atb":[[40,4.06]],"id":28546943},{"atl":[[260,4.95],[280,0],[500,0.31]],"id":41419602},{"atl":[[880,0.17]],"id":41419614},{"atb":[[9.4,18.87]],"id":41419590},{"atl":[[160,5.95],[170,0]],"id":41419607},{"atl":[[1000,0.15]],"id":41419603},{"atl":[[150,6.01]],"id":41419615},{"atl":[[80,4.95],[85,1.88],[90,0],[100,9.9],[120,12.43]],"id":41419624},{"atl":[[70,4.95],[75,0],[90,9.9],[95,0]],"id":41419632},{"atl":[[280,0.56]],"id":41419628},{"atl":[[580,2]],"id":41419604},{"atl":[[80,2]],"id":41419616},{"atl":[[85,4.95],[110,9.9]],"id":41419625}],"con":true,"img":false}]}
{"op":"mcm","clk":"5353823786","pt":1646218833012,"mc":[{"id":"1.195503868","rc":[{"atl":[[70,0]],"id":41419625}],"con":true,"img":false}]}
{"op":"mcm","clk":"5353823797","pt":1646218833079,"mc":[{"id":"1.195503868","rc":[{"atl":[[1000,0.15]],"id":41419604}],"con":true,"img":false}]}
{"op":"mcm","clk":"5353823819","pt":1646218833172,"mc":[{"id":"1.195503868","rc":[{"atl":[[620,2]],"id":41419625}],"con":true,"img":false}]}
{"op":"mcm","clk":"5353823835","pt":1646218833276,"mc":[{"id":"1.195503868","rc":[{"atl":[[570,0],[1000,2.15]],"id":41419603}],"con":true,"img":false}]}
{"op":"mcm","clk":"5353823861","pt":1646218833485,"mc":[{"id":"1.195503868","rc":[{"atl":[[190,13.61]],"id":41419601},{"atl":[[170,0]],"id":41419615},{"atl":[[80,16.72],[85,2]],"id":41419616},{"atl":[[110,23.49]],"id":41419625},{"atl":[[750,0.21]],"id":41419592}],"con":true,"img":false}]}
{"op":"mcm","clk":"5353823874","pt":1646218833603,"mc":[{"id":"1.195503868","rc":[{"atl":[[160,0.99]],"id":41419607},{"atl":[[140,4.95],[150,1.06]],"id":41419615},{"atl":[[120,0]],"id":41419624},{"atl":[[80,4.95],[85,0],[100,9.9],[110,13.58]],"id":41419625}],"con":true,"img":false}]}
{"op":"mcm","clk":"5353823883","pt":1646218833696,"mc":[{"id":"1.195503868","rc":[{"atl":[[300,2],[620,0]],"id":41419625}],"con":true,"img":false}]}
{"op":"mcm","clk":"5353823898","pt":1646218833797,"mc":[{"id":"1.195503868","rc":[{"atl":[[160,0],[170,4.95]],"id":41419607},{"atl":[[85,1.88]],"id":41419625},{"atl":[[780,1.9]],"id":41419592},{"atb":[[9,9.9],[10,0]],"id":41419588}],"con":true,"img":false}]}
{"op":"mcm","clk":"5353823907","pt":1646218833903,"mc":[{"id":"1.195503868","rc":[{"atl":[[70,4.95],[75,2.14],[90,9.9],[95,0]],"id":41419617},{"atl":[[240,0]],"id":41419628}],"con":true,"img":false}]}
{"op":"mcm","clk":"5353823940","pt":1646218834164,"mc":[{"id":"1.195503868","rc":[{"atl":[[760,0]],"id":41419592},{"atl":[[830,1.79],[910,2]],"id":41419621}],"con":true,"img":false}]}
{"op":"mcm","clk":"5353823953","pt":1646218834274,"mc":[{"id":"1.195503868","rc":[{"atl":[[830,3.79]],"id":41419621}],"con":true,"img":false}]}
{"op":"mcm","clk":"5353823962","pt":1646218834375,"mc":[{"id":"1.195503868","rc":[{"atl":[[910,0]],"id":41419621}],"con":true,"img":false}]}
{"op":"mcm","clk":"5353823975","pt":1646218834479,"mc":[{"id":"1.195503868","rc":[{"atl":[[160,2],[90,24.62]],"id":41419617},{"atl":[[17,19.81],[38,39.17]],"id":41419589},{"atl":[[85,9.9],[230,8.5]],"id":41419618},{"atl":[[390,0.4]],"id":41419607},{"atb":[[7.2,66.24],[7.4,0]],"id":41419587},{"atb":[[9.8,7.67],[8.8,3.27]],"id":41419588},{"atl":[[17,9.9],[30,42.38]],"id":41419588}],"con":true,"img":false}]}
{"op":"mcm","clk":"5353824071","pt":1646218835514,"mc":[{"id":"1.195503868","rc":[{"atl":[[980,2]],"id":41419604}],"con":true,"img":false}]}
{"op":"mcm","clk":"5353824084","pt":1646218835567,"mc":[{"id":"1.195503868","rc":[{"atl":[[580,0]],"id":41419604}],"con":true,"img":false}]}
{"op":"mcm","clk":"5353824096","pt":1646218835725,"mc":[{"id":"1.195503868","rc":[{"atb":[[6.2,19.23],[5.3,0]],"id":41419589},{"atl":[[260,2]],"id":41419632},{"atl":[[540,0],[700,2]],"id":41419628},{"atb":[[36,0],[46,2.22]],"id":41419621},{"atb":[[32,0],[40,2.56]],"id":41419629},{"atl":[[1000,0]],"id":41419596}],"con":true,"img":false}]}
{"op":"mcm","clk":"5353824109","pt":1646218835781,"mc":[{"id":"1.195503868","rc":[{"atl":[[200,0]],"id":41419632}],"con":true,"img":false}]}
{"op":"mcm","clk":"5353824118","pt":1646218835886,"mc":[{"id":"1.195503868","rc":[{"atb":[[18,0],[15.5,0]],"id":41419613},{"atl":[[220,0.72],[250,4.95]],"id":41419622},{"atb":[[10,14.63],[9.2,39.4],[10.5,4.95],[9.4,9.9]],"id":41419589},{"atl":[[17,9.9],[19,9.9],[15,0]],"id":41419589},{"atl":[[65,2.47],[80,9.9],[85,0],[60,4.95]],"id":41419618},{"atb":[[12,0],[9.8,12.21]],"id":41419606},{"atl":[[17.5,4.95],[18.5,9.05],[19.5,9.9],[21,0]],"id":41419606},{"atb":[[32,4.95],[26,0],[27,9.9],[30,0]],"id":41419623},{"atl":[[65,2.47],[70,4.95],[85,0],[90,9.9]],"id":41419623},{"atl":[[34,4.8],[38,4.95],[42,0],[46,9.9]],"id":41419627},{"atb":[[80,0],[85,9.9],[100,1.34],[110,4.95]],"id":41419594},{"atb":[[80,0],[85,9.9],[100,4.32],[110,4.95]],"id":41419603},{"atl":[[44,4.95],[46,0],[55,9.9],[60,0]],"id":41419611},{"atb":[[18,36.78],[20,0]],"id":41419620},{"atl":[[38,4.28],[46,0]],"id":41419620},{"atb":[[34,7.53]],"id":41419632},{"atb":[[32,0],[34,9.9],[40,8.9],[42,8.22]],"id":41419599},{"atl":[[110,4.95]],"id":41419599},{"atb":[[120,2.44]],"id":41419628},{"atb":[[60,0]],"id":41419608},{"atl":[[110,4.95]],"id":41419608},{"atb":[[9,0],[9.8,2.72]],"id":41419588},{"atl":[[160,0.99],[180,4.95]],"id":41419629}],"con":true,"img":false}]}
{"op":"mcm","clk":"5353824134","pt":1646218836092,"mc":[{"id":"1.195503868","rc":[{"atl":[[880,2],[990,0]],"id":41419622},{"atb":[[19,9.9],[22,4.95]],"id":41419620},{"atl":[[42,4.95],[50,9.9]],"id":41419620}],"con":true,"img":false}]}
{"op":"mcm","clk":"5353824161","pt":1646218836301,"mc":[{"id":"1.195503868","rc":[{"atb":[[15,4.95]],"id":41419613},{"atl":[[1000,0]],"id":41419622},{"atb":[[9.8,0],[9.4,38.1]],"id":41419606},{"atl":[[19.5,38.1],[40,0]],"id":41419606},{"atl":[[80,9.9],[110,15.46]],"id":41419585},{"atl":[[90,26.6],[240,2]],"id":41419623},{"atl":[[46,29.66],[95,2]],"id":41419627},{"atb":[[90,3.27],[100,7.29]],"id":41419594},{"atb":[[75,3.27],[85,24.62],[120,1.32]],"id":41419603},{"atb":[[10.5,42.22]],"id":41419620},{"atb":[[34,17.98],[44,12.63]],"id":41419608},{"atb":[[8.6,4.95],[7.8,9.9]],"id":41419588}],"con":true,"img":false}]}
{"op":"mcm","clk":"5353824171","pt":1646218836401,"mc":[{"id":"1.195503868","rc":[{"atb":[[18,3.27]],"id":41419620},{"atl":[[120,2]],"id":41419620}],"con":true,"img":false}]}
{"op":"mcm","clk":"5353824185","pt":1646218836512,"mc":[{"id":"1.195503868","rc":[{"atb":[[8.2,68.25],[15,16.27]],"id":41419613},{"atl":[[17.5,14.56]],"id":41419606},{"atb":[[23,7.2]],"id":41419620},{"atl":[[50,31.99]],"id":41419620},{"atl":[[890,3.67],[920,0]],"id":41419629}],"con":true,"img":false}]}
{"op":"mcm","clk":"5353824193","pt":1646218836612,"mc":[{"id":"1.195503868","rc":[{"atb":[[16.5,2.72],[14,3.27]],"id":41419613},{"atl":[[18.5,9.05]],"id":41419589},{"atb":[[9.6,3.27],[11.5,2.72],[9.8,18.01]],"id":41419606},{"atb":[[120,1.11]],"id":41419628},{"atb":[[55,7.89]],"id":41419608}],"con":true,"img":false}]}
{"op":"mcm","clk":"5353824202","pt":1646218836717,"mc":[{"id":"1.195503868","rc":[{"atb":[[6.2,0],[5.3,23.26]],"id":41419589},{"atb":[[18,0],[21,5]],"id":41419608},{"atl":[[780,3.9],[870,0]],"id":41419592},{"atl":[[1000,2]],"id":41419596}],"con":true,"img":false}]}
{"op":"mcm","clk":"5353824228","pt":1646218836927,"mc":[{"id":"1.195503868","rc":[{"atl":[[32,0],[27,6.09]],"id":41419613},{"atl":[[17.5,9.6],[18.5,14.01],[19.5,28.19],[21,9.9]],"id":41419606},{"atl":[[36,4.95],[38,0],[44,9.9],[46,19.75]],"id":41419627},{"atb":[[34,2.72]],"id":41419632},{"atl":[[110,6.4]],"id":41419608},{"atb":[[36,4.95],[38,0],[40,2.72],[29,9.9],[30,15.48]],"id":41419625},{"atl":[[170,4.95],[180,0]],"id":41419629}],"con":true,"img":false}]}
{"op":"mcm","clk":"5353824239","pt":1646218836981,"mc":[{"id":"1.195503868","rc":[{"atl":[[34,9.9],[28,4.95]],"id":41419613},{"atl":[[320,4.69]],"id":41419603},{"atb":[[10.5,10.53]],"id":41419620},{"atl":[[40,4.95],[42,0],[48,9.9],[50,22.08]],"id":41419620},{"atb":[[8.6,0],[7.8,0]],"id":41419588}],"con":true,"img":false}]}
{"op":"mcm","clk":"5353824246","pt":1646218837087,"mc":[{"id":"1.195503868","rc":[{"atl":[[530,2],[890,1.67]],"id":41419629}],"con":true,"img":false}]}
{"op":"mcm","clk":"5353824261","pt":1646218837193,"mc":[{"id":"1.195503868","rc":[{"atl":[[990,1.5]],"id":41419622},{"atb":[[10.5,0],[9.8,4.95],[9.4,0]],"id":41419589},{"atl":[[18.5,4.95]],"id":41419606},{"atb":[[100,2.72]],"id":41419603},{"atl":[[1000,0.15]],"id":41419603},{"atb":[[21,2.72]],"id":41419620},{"atb":[[9.2,24.29]],"id":41419588}],"con":true,"img":false}]}
{"op":"mcm","clk":"5353824281","pt":1646218837396,"mc":[{"id":"1.195503868","rc":[{"atl":[[770,2]],"id":41419603}],"con":true,"img":false}]}
{"op":"mcm","clk":"5353824291","pt":1646218837500,"mc":[{"id":"1.195503868","rc":[{"atl":[[80,2],[450,3.68]],"id":41419613},{"atb":[[100,6.55]],"id":41419628}],"con":true,"img":false}]}
{"op":"mcm","clk":"5353824300","pt":1646218837605,"mc":[{"id":"1.195503868","rc":[{"atl":[[770,0],[1000,2.15]],"id":41419603}],"con":true,"img":false}]}
{"op":"mcm","clk":"5353824310","pt":1646218837711,"mc":[{"id":"1.195503868","rc":[{"atl":[[450,3.33]],"id":41419613},{"atl":[[190,5.79],[210,7.16]],"id":41419601},{"atb":[[27,14.32]],"id":41419632},{"atl":[[130,0],[800,3.87]],"id":41419608},{"atl":[[48,8.32]],"id":41419616},{"atb":[[30,20.95]],"id":41419625}],"con":true,"img":false}]}
{"op":"mcm","clk":"5353824331","pt":1646218837915,"mc":[{"id":"1.195503868","rc":[{"atl":[[260,0.61]],"id":41419604}],"con":true,"img":false}]}
{"op":"mcm","clk":"5353824355","pt":1646218838193,"mc":[{"id":"1.195503868","rc":[{"atl":[[450,0]],"id":41419613}],"con":true,"img":false}]}
{"op":"mcm","clk":"5353824391","pt":1646218838623,"mc":[{"id":"1.195503868","rc":[{"atl":[[510,4.94]],"id":41419602},{"atl":[[130,11.59]],"id":41419599},{"atl":[[800,2]],"id":41419608},{"atl":[[80,14.71]],"id":41419616}],"con":true,"img":false}]}
{"op":"mcm","clk":"5353824427","pt":1646218838917,"mc":[{"id":"1.195503868","rc":[{"atl":[[1000,0]],"id":41419604}],"con":true,"img":false}]}
{"op":"mcm","clk":"5353824474","pt":1646218839285,"mc":[{"id":"1.195503868","rc":[{"atl":[[980,3.53]],"id":41419604}],"con":true,"img":false}]}
{"op":"mcm","clk":"5353824552","pt":1646218840013,"mc":[{"id":"1.195503868","rc":[{"atl":[[1000,0]],"id":41435527}],"con":true,"img":false}]}
{"op":"mcm","clk":"5353824588","pt":1646218840279,"mc":[{"id":"1.195503868","rc":[{"atb":[[36,4.52],[28,12.21]],"id":41419624},{"atb":[[18,0],[21,0]],"id":41419620},{"atl":[[280,0]],"id":41419628}],"con":true,"img":false}]}
{"op":"mcm","clk":"5353824635","pt":1646218840696,"mc":[{"id":"1.195503868","rc":[{"atb":[[65,2.47],[40,18.29],[29,3.27]],"id":28546943}],"con":true,"img":false}]}
{"op":"mcm","clk":"5353824665","pt":1646218841004,"mc":[{"id":"1.195503868","rc":[{"atb":[[40,2.72],[30,3.27]],"id":41419624},{"atb":[[20,3.27],[25,2.72]],"id":41419620},{"atl":[[290,5.5]],"id":41419628}],"con":true,"img":false}]}
{"op":"mcm","clk":"5353824694","pt":1646218841274,"mc":[{"id":"1.195503868","rc":[{"atb":[[7.2,4.95]],"id":41419587}],"con":true,"img":false}]}
{"op":"mcm","clk":"5353824708","pt":1646218841373,"mc":[{"id":"1.195503868","rc":[{"atb":[[7,64.55]],"id":41419587}],"con":true,"img":false}]}
{"op":"mcm","clk":"5353824730","pt":1646218841583,"mc":[{"id":"1.195503868","rc":[{"atl":[[230,2]],"id":41419618},{"atb":[[40,14.22]],"id":28546943},{"atb":[[44,15.48]],"id":41419615},{"atl":[[140,2],[55,27.5]],"id":41419611},{"atb":[[32,19.04],[28,0]],"id":41419624},{"atl":[[38,0]],"id":41419620}],"con":true,"img":false}]}
{"op":"mcm","clk":"5353824738","pt":1646218841687,"mc":[{"id":"1.195503868","rc":[{"atb":[[9.2,0],[9.8,33.15]],"id":41419589},{"atl":[[19,38.1],[38,2.7]],"id":41419589},{"atl":[[80,28.87]],"id":41419618},{"atb":[[8.8,42.2]],"id":41419588}],"con":true,"img":false}]}
{"op":"mcm","clk":"5353824754","pt":1646218841892,"mc":[{"id":"1.195503868","rc":[{"atb":[[9.8,20.74]],"id":41419588}],"con":true,"img":false}]}
{"op":"mcm","clk":"5353824762","pt":1646218842010,"mc":[{"id":"1.195503868","rc":[{"atl":[[70,7.25]],"id":41419632}],"con":true,"img":false}]}
{"op":"mcm","clk":"5353824788","pt":1646218842310,"mc":[{"id":"1.195503868","rc":[{"atl":[[17,19.81]],"id":41419589}],"con":true,"img":false}]}
{"op":"mcm","clk":"5353824798","pt":1646218842414,"mc":[{"id":"1.195503868","rc":[{"atl":[[48,13.28]],"id":41419620}],"con":true,"img":false}]}
{"op":"mcm","clk":"5353824821","pt":1646218842575,"mc":[{"id":"1.195503868","rc":[{"atl":[[110,6.4]],"id":41419599},{"atb":[[9.2,4.95]],"id":41419588}],"con":true,"img":false}]}
{"op":"mcm","clk":"5353824864","pt":1646218842988,"mc":[{"id":"1.195503868","rc":[{"atl":[[190,7.78]],"id":41419632}],"con":true,"img":false}]}
{"op":"mcm","clk":"5353824900","pt":1646218843301,"mc":[{"id":"1.195503868","rc":[{"atl":[[18.5,0]],"id":41419589}],"con":true,"img":false}]}
{"op":"mcm","clk":"5353824927","pt":1646218843712,"mc":[{"id":"1.195503868","rc":[{"atb":[[34,0],[27,18.39]],"id":41419617}],"con":true,"img":false}]}
{"op":"mcm","clk":"5353824954","pt":1646218843972,"mc":[{"id":"1.195503868","rc":[{"atb":[[10,11.36],[12.5,0]],"id":41419589},{"atl":[[320,0],[1000,3.67]],"id":41419603},{"atb":[[8,22.65],[7,61.28]],"id":41419587}],"con":true,"img":false}]}
{"op":"mcm","clk":"5353824987","pt":1646218844386,"mc":[{"id":"1.195503868","rc":[{"atb":[[24,31.99],[27,0],[28,10.82]],"id":41419617}],"con":true,"img":false}]}
{"op":"mcm","clk":"5353825015","pt":1646218844699,"mc":[{"id":"1.195503868","rc":[{"atb":[[36,2.72],[28,14.09]],"id":41419617},{"atl":[[210,0],[510,4.98]],"id":41419601}],"con":true,"img":false}]}
{"op":"mcm","clk":"5353825021","pt":1646218844803,"mc":[{"id":"1.195503868","rc":[{"atb":[[12,2.72],[9.8,36.42]],"id":41419589},{"atl":[[900,1.49]],"id":41419614},{"atb":[[6.8,3.27],[7.8,2.72]],"id":41419587},{"atl":[[130,11.73]],"id":41419608},{"atl":[[780,2],[770,1.97]],"id":41419592}],"con":true,"img":false}]}
{"op":"mcm","clk":"5353825039","pt":1646218845009,"mc":[{"id":"1.195503868","rc":[{"atl":[[800,0],[420,2]],"id":41419608}],"con":true,"img":false}]}
{"op":"mcm","clk":"5353825048","pt":1646218845115,"mc":[{"id":"1.195503868","rc":[{"atb":[[18,0]],"id":41419617}],"con":true,"img":false}]}
{"op":"mcm","clk":"5353825062","pt":1646218845216,"mc":[{"id":"1.195503868","rc":[{"atl":[[890,0],[900,3.49]],"id":41419614}],"con":true,"img":false}]}
{"op":"mcm","clk":"5353825082","pt":1646218845377,"mc":[{"id":"1.195503868","rc":[{"atl":[[250,0.63]],"id":41419602},{"atl":[[290,0.55]],"id":41419603},{"atl":[[130,0],[370,6.12]],"id":41419599},{"atl":[[310,4.92]],"id":41419628}],"con":true,"img":false}]}
{"op":"mcm","clk":"5353825102","pt":1646218845588,"mc":[{"id":"1.195503868","rc":[{"atl":[[570,2],[700,0]],"id":41419628}],"con":true,"img":false}]}
{"op":"mcm","clk":"5353825124","pt":1646218845792,"mc":[{"id":"1.195503868","rc":[{"atl":[[770,0]],"id":41419592}],"con":true,"img":false}]}
{"op":"mcm","clk":"5353825151","pt":1646218846106,"mc":[{"id":"1.195503868","rc":[{"atl":[[500,3.05],[510,2]],"id":41419602},{"atl":[[1000,3.51]],"id":41419603},{"atl":[[370,2]],"id":41419599}],"con":true,"img":false}]}
{"op":"mcm","clk":"5353825186","pt":1646218846474,"mc":[{"id":"1.195503868","rc":[{"atl":[[36,9.48]],"id":41419609}],"con":true,"img":false}]}
{"op":"mcm","clk":"5353825203","pt":1646218846682,"mc":[{"id":"1.195503868","rc":[{"atl":[[70,7.25]],"id":41419617},{"atb":[[10,25.29]],"id":41419590},{"atl":[[170,5.89]],"id":41419607},{"atl":[[140,6.09],[440,5.47]],"id":41419615},{"atl":[[80,6.95],[100,23.99]],"id":41419624}],"con":true,"img":false}]}
{"op":"mcm","clk":"5353825212","pt":1646218846785,"mc":[{"id":"1.195503868","rc":[{"atl":[[60,7.64]],"id":41419618}],"con":true,"img":false}]}
{"op":"mcm","clk":"5353825239","pt":1646218847203,"mc":[{"id":"1.195503868","rc":[{"atl":[[38,0]],"id":41419609}],"con":true,"img":false}]}
{"op":"mcm","clk":"5353825266","pt":1646218847512,"mc":[{"id":"1.195503868","rc":[{"atl":[[75,0]],"id":41419617},{"atl":[[65,0]],"id":41419618},{"atb":[[9.4,0]],"id":41419590},{"atl":[[390,0]],"id":41419607},{"atl":[[150,0]],"id":41419615},{"atl":[[85,0]],"id":41419624},{"atl":[[100,24.62],[110,0]],"id":41419625}],"con":true,"img":false}]}
{"op":"mcm","clk":"5353825290","pt":1646218847776,"mc":[{"id":"1.195503868","rc":[{"atl":[[40,0],[44,38.72]],"id":41419609},{"atl":[[290,0],[300,4.95]],"id":41419628},{"atl":[[770,1.98]],"id":41419592}],"con":true,"img":false}]}
{"op":"mcm","clk":"5353825304","pt":1646218847982,"mc":[{"id":"1.195503868","rc":[{"atl":[[160,11.59],[90,9.9]],"id":41419617},{"atb":[[9,54.73],[9.2,9.9]],"id":41419590},{"atl":[[190,8.07],[400,2]],"id":41419607}],"con":true,"img":false}]}
{"op":"mcm","clk":"5353825349","pt":1646218848605,"mc":[{"id":"1.195503868","rc":[{"atl":[[19,9.9]],"id":41419589},{"atl":[[230,8.67]],"id":41419618},{"atb":[[7.2,35.87]],"id":41419587}],"con":true,"img":false}]}
{"op":"mcm","clk":"5353825361","pt":1646218848709,"mc":[{"id":"1.195503868","rc":[{"atl":[[38,43.14]],"id":41419589},{"atl":[[80,9.9]],"id":41419618},{"atb":[[7,0]],"id":41419587},{"atl":[[300,5.48]],"id":41419628}],"con":true,"img":false}]}
{"op":"mcm","clk":"5353825372","pt":1646218848813,"mc":[{"id":"1.195503868","rc":[{"atl":[[65,4.95],[80,0],[85,9.9],[60,2.68]],"id":41419618},{"atl":[[170,0],[180,4.95]],"id":41419607}],"con":true,"img":false}]}
{"op":"mcm","clk":"5353825398","pt":1646218849125,"mc":[{"id":"1.195503868","rc":[{"atl":[[70,0],[75,4.95],[90,0],[95,9.9]],"id":41419632},{"atl":[[300,0.52],[310,9.87]],"id":41419628}],"con":true,"img":false}]}
{"op":"mcm","clk":"5353825427","pt":1646218849420,"mc":[{"id":"1.195503868","rc":[{"atl":[[300,0]],"id":41419628}],"con":true,"img":false}]}
{"op":"mcm","clk":"5353825467","pt":1646218849781,"mc":[{"id":"1.195503868","rc":[{"atl":[[180,5.84]],"id":41419607},{"atb":[[34,7.53]],"id":41419632}],"con":true,"img":false}]}
