{"op":"mcm","clk":"5345904401","pt":1646079078744,"mc":[{"id":"1.195395453","marketDefinition":{"bspMarket":true,"turnInPlayEnabled":false,"persistenceEnabled":false,"marketBaseRate":5.0,"eventId":"31270459","eventTypeId":"4339","numberOfWinners":1,"bettingType":"ODDS","marketType":"WIN","marketTime":"2022-03-01T01:45:00.000Z","suspendTime":"2022-03-01T01:45:00.000Z","bspReconciled":false,"complete":true,"inPlay":false,"crossMatching":false,"runnersVoidable":false,"numberOfActiveRunners":8,"betDelay":0,"status":"OPEN","runners":[{"status":"ACTIVE","sortPriority":1,"id":39586887,"name":"1. Homebush Bun"},{"status":"ACTIVE","sortPriority":2,"id":42901530,"name":"2. Wild Thyme"},{"status":"ACTIVE","sortPriority":3,"id":40612296,"name":"3. Opawa Duchess"},{"status":"ACTIVE","sortPriority":4,"id":37076607,"name":"4. Opawa Ruby"},{"status":"ACTIVE","sortPriority":5,"id":42845264,"name":"5. Opawa Dragon"},{"status":"ACTIVE","sortPriority":6,"id":43154432,"name":"6. Iced Mocha"},{"status":"ACTIVE","sortPriority":7,"id":43066392,"name":"7. Go Hazel"},{"status":"ACTIVE","sortPriority":8,"id":40324412,"name":"8. Goldstar Charm"}],"regulators":["MR_INT"],"venue":"Addington","countryCode":"NZ","discountAllowed":false,"timezone":"NZ","openDate":"2022-02-28T23:02:00.000Z","version":4380660693,"name":"R10 520m S/E","eventName":"Addington (NZL) 1st Mar"},"rc":[],"con":true,"img":false}]}
{"op":"mcm","clk":"5345904624","pt":1646079080740,"mc":[{"id":"1.195395453","marketDefinition":{"bspMarket":true,"turnInPlayEnabled":false,"persistenceEnabled":false,"marketBaseRate":5.0,"eventId":"31270459","eventTypeId":"4339","numberOfWinners":1,"bettingType":"ODDS","marketType":"WIN","marketTime":"2022-03-01T01:45:00.000Z","suspendTime":"2022-03-01T01:45:00.000Z","bspReconciled":false,"complete":true,"inPlay":false,"crossMatching":false,"runnersVoidable":false,"numberOfActiveRunners":8,"betDelay":0,"status":"OPEN","runners":[{"status":"ACTIVE","sortPriority":1,"id":39586887,"name":"1. Homebush Bun"},{"status":"ACTIVE","sortPriority":2,"id":42901530,"name":"2. Wild Thyme"},{"status":"ACTIVE","sortPriority":3,"id":40612296,"name":"3. Opawa Duchess"},{"status":"ACTIVE","sortPriority":4,"id":37076607,"name":"4. Opawa Ruby"},{"status":"ACTIVE","sortPriority":5,"id":42845264,"name":"5. Opawa Dragon"},{"status":"ACTIVE","sortPriority":6,"id":43154432,"name":"6. Iced Mocha"},{"status":"ACTIVE","sortPriority":7,"id":43066392,"name":"7. Go Hazel"},{"status":"ACTIVE","sortPriority":8,"id":40324412,"name":"8. Goldstar Charm"}],"regulators":["MR_INT"],"venue":"Addington","countryCode":"NZ","discountAllowed":true,"timezone":"NZ","openDate":"2022-02-28T23:02:00.000Z","version":4380660693,"name":"R10 520m S/E","eventName":"Addington (NZL) 1st Mar"},"rc":[],"con":true,"img":false}]}
{"op":"mcm","clk":"5346133741","pt":1646081621322,"mc":[{"id":"1.195395453","rc":[{"atb":[[16.5,7.85],[19,4.5],[23,1.84],[11.5,15.46]],"id":37076607},{"atl":[[260,0.76],[310,0.64],[160,0.83],[210,0.63]],"id":37076607},{"spn":91.5,"spf":"NaN","id":37076607},{"atb":[[16.5,7.85],[19,4.5],[23,1.84],[11.5,15.46]],"id":42901530},{"atl":[[260,0.76],[310,0.64],[160,0.83],[210,0.63]],"id":42901530},{"spn":91.5,"spf":"NaN","id":42901530},{"atb":[[12,3.69],[6.8,27.99],[9.8,9.22],[8.8,15.61]],"id":40612296},{"atl":[[70,1.91],[140,1.42],[95,1.4],[190,1.05]],"id":40612296},{"spn":41.0,"spf":"NaN","id":40612296},{"atb":[[9.6,14.16],[11.5,7.73],[7.6,24.6],[14,3.12]],"id":40324412},{"atl":[[130,1.02],[90,1.48],[180,1.1],[230,0.86]],"id":40324412},{"spn":52.0,"spf":"NaN","id":40324412},{"atb":[[8.6,5.34],[5.3,37.76],[7.6,12.3],[6.6,21.74]],"id":43066392},{"atl":[[65,3.1],[36,3.77],[90,2.23],[46,2.93]],"id":43066392},{"spn":22.3,"spf":"NaN","id":43066392},{"atb":[[1.12,1014.93],[1.02,8119.51],[1.22,184.53],[1.17,477.61]],"id":42845264},{"atl":[[2.36,97.27],[2.56,127.2],[2.46,135.92],[2.26,104.99]],"id":42845264},{"spn":1.74,"spf":"NaN","id":42845264},{"atb":[[12,3.69],[6.8,27.99],[9.8,9.22],[8.8,15.61]],"id":43154432},{"atl":[[70,1.91],[140,1.42],[95,1.4],[190,1.05]],"id":43154432},{"spn":41.0,"spf":"NaN","id":43154432},{"atb":[[18,4.77],[21,2.02],[10.5,17.09],[15.5,8.4]],"id":39586887},{"atl":[[150,0.88],[300,0.66],[200,0.66],[250,0.79]],"id":39586887},{"spn":85.5,"spf":"NaN","id":39586887}],"con":true,"img":false}]}
{"op":"mcm","clk":"5346134820","pt":1646081637966,"mc":[{"id":"1.195395453","rc":[{"atb":[[16.5,0],[19,0],[23,0],[11.5,0]],"id":37076607},{"atl":[[260,0],[310,0],[160,0],[210,0]],"id":37076607},{"atb":[[16.5,0],[19,0],[23,0],[11.5,0]],"id":42901530},{"atl":[[260,0],[310,0],[160,0],[210,0]],"id":42901530},{"atb":[[12,0],[6.8,0],[9.8,0],[8.8,0]],"id":40612296},{"atl":[[70,0],[140,0],[95,0],[190,0]],"id":40612296},{"atb":[[9.6,0],[11.5,0],[7.6,0],[14,0]],"id":40324412},{"atl":[[130,0],[90,0],[180,0],[230,0]],"id":40324412},{"atb":[[8.6,0],[5.3,0],[7.6,0],[6.6,0]],"id":43066392},{"atl":[[65,0],[36,0],[90,0],[46,0]],"id":43066392},{"atb":[[1.12,0],[1.02,0],[1.22,0],[1.17,0]],"id":42845264},{"atl":[[2.36,0],[2.56,0],[2.46,0],[2.26,0]],"id":42845264},{"atb":[[12,0],[6.8,0],[9.8,0],[8.8,0]],"id":43154432},{"atl":[[70,0],[140,0],[95,0],[190,0]],"id":43154432},{"atb":[[18,0],[21,0],[10.5,0],[15.5,0]],"id":39586887},{"atl":[[150,0],[300,0],[200,0],[250,0]],"id":39586887}],"con":true,"img":false}]}
{"op":"mcm","clk":"5346135989","pt":1646081656821,"mc":[{"id":"1.195395453","rc":[{"atb":[[16.5,7.85],[19,4.5],[23,1.84],[11.5,15.46]],"id":37076607},{"atl":[[260,0.76],[310,0.64],[160,0.83],[210,0.63]],"id":37076607},{"atb":[[16.5,7.85],[19,4.5],[23,1.84],[11.5,15.46]],"id":42901530},{"atl":[[260,0.76],[310,0.64],[160,0.83],[210,0.63]],"id":42901530},{"atb":[[12,3.69],[6.8,27.99],[9.8,9.22],[8.8,15.61]],"id":40612296},{"atl":[[70,1.91],[140,1.42],[95,1.4],[190,1.05]],"id":40612296},{"atb":[[9.6,14.16],[11.5,7.73],[7.6,24.6],[14,3.12]],"id":40324412},{"atl":[[130,1.02],[90,1.48],[180,1.1],[230,0.86]],"id":40324412},{"atb":[[8.6,5.34],[5.3,37.76],[7.6,12.3],[6.6,21.74]],"id":43066392},{"atl":[[65,3.1],[36,3.77],[90,2.23],[46,2.93]],"id":43066392},{"atb":[[1.12,1014.93],[1.02,8119.51],[1.22,184.53],[1.17,477.61]],"id":42845264},{"atl":[[2.36,97.27],[2.56,127.2],[2.46,135.92],[2.26,104.99]],"id":42845264},{"atb":[[12,3.69],[6.8,27.99],[9.8,9.22],[8.8,15.61]],"id":43154432},{"atl":[[70,1.91],[140,1.42],[95,1.4],[190,1.05]],"id":43154432},{"atb":[[18,4.77],[21,2.02],[10.5,17.09],[15.5,8.4]],"id":39586887},{"atl":[[150,0.88],[300,0.66],[200,0.66],[250,0.79]],"id":39586887}],"con":true,"img":false}]}
{"op":"mcm","clk":"5346138725","pt":1646081695955,"mc":[{"id":"1.195395453","rc":[{"atb":[[16.5,0],[19,0],[23,0],[11.5,0]],"id":37076607},{"atl":[[260,0],[310,0],[160,0],[210,0]],"id":37076607},{"spn":"NaN","spf":"NaN","id":37076607},{"atb":[[16.5,0],[19,0],[23,0],[11.5,0]],"id":42901530},{"atl":[[260,0],[310,0],[160,0],[210,0]],"id":42901530},{"spn":"NaN","spf":"NaN","id":42901530},{"atb":[[12,0],[6.8,0],[9.8,0],[8.8,0]],"id":40612296},{"atl":[[70,0],[140,0],[95,0],[190,0]],"id":40612296},{"spn":"NaN","spf":"NaN","id":40612296},{"atb":[[9.6,0],[11.5,0],[7.6,0],[14,0]],"id":40324412},{"atl":[[130,0],[90,0],[180,0],[230,0]],"id":40324412},{"spn":"NaN","spf":"NaN","id":40324412},{"atb":[[8.6,0],[5.3,0],[7.6,0],[6.6,0]],"id":43066392},{"atl":[[65,0],[36,0],[90,0],[46,0]],"id":43066392},{"spn":"NaN","spf":"NaN","id":43066392},{"atb":[[1.12,0],[1.02,0],[1.22,0],[1.17,0]],"id":42845264},{"atl":[[2.36,0],[2.56,0],[2.46,0],[2.26,0]],"id":42845264},{"spn":"NaN","spf":"NaN","id":42845264},{"atb":[[12,0],[6.8,0],[9.8,0],[8.8,0]],"id":43154432},{"atl":[[70,0],[140,0],[95,0],[190,0]],"id":43154432},{"spn":"NaN","spf":"NaN","id":43154432},{"atb":[[18,0],[21,0],[10.5,0],[15.5,0]],"id":39586887},{"atl":[[150,0],[300,0],[200,0],[250,0]],"id":39586887},{"spn":"NaN","spf":"NaN","id":39586887}],"con":true,"img":false}]}
{"op":"mcm","clk":"5346140410","pt":1646081720446,"mc":[{"id":"1.195395453","rc":[{"atb":[[16.5,7.85],[19,4.5],[23,1.84],[11.5,15.46]],"id":37076607},{"atl":[[260,0.76],[310,0.64],[160,0.83],[210,0.63]],"id":37076607},{"atb":[[16.5,7.85],[19,4.5],[23,1.84],[11.5,15.46]],"id":42901530},{"atl":[[260,0.76],[310,0.64],[160,0.83],[210,0.63]],"id":42901530},{"atb":[[8,11.6],[9,5.07],[5.5,36.08],[7,20.29]],"id":40612296},{"atl":[[75,2.67],[40,3.39],[50,2.7],[100,2]],"id":40612296},{"atb":[[9.6,14.16],[11.5,7.73],[7.6,24.6],[14,3.12]],"id":40324412},{"atl":[[130,1.02],[90,1.48],[180,1.1],[230,0.86]],"id":40324412},{"atb":[[4.3,49.2],[5.8,16.91],[5.3,28.32],[6.6,7.24]],"id":43066392},{"atl":[[36,5.66],[19,7.35],[23,6.01],[28,7.35]],"id":43066392},{"atb":[[1.12,1014.93],[1.02,8119.51],[1.22,184.53],[1.17,477.61]],"id":42845264},{"atl":[[2.36,97.27],[2.56,127.2],[2.46,135.92],[2.26,104.99]],"id":42845264},{"atb":[[12,3.69],[6.8,27.99],[9.8,9.22],[8.8,15.61]],"id":43154432},{"atl":[[70,1.91],[140,1.42],[95,1.4],[190,1.05]],"id":43154432},{"atb":[[18,4.77],[21,2.02],[10.5,17.09],[15.5,8.4]],"id":39586887},{"atl":[[150,0.88],[300,0.66],[200,0.66],[250,0.79]],"id":39586887}],"con":true,"img":false}]}
{"op":"mcm","clk":"5346183415","pt":1646082292968,"mc":[{"id":"1.195395453","rc":[{"atb":[[16.5,0],[19,0],[23,0],[11.5,0]],"id":37076607},{"atl":[[260,0],[310,0],[160,0],[210,0]],"id":37076607},{"spn":91.5,"spf":"NaN","id":42901530},{"atb":[[8,0],[9,0],[5.5,0],[7,0]],"id":40612296},{"atl":[[75,0],[40,0],[50,0],[100,0]],"id":40612296},{"atb":[[9.6,0],[11.5,0],[7.6,0],[14,0]],"id":40324412},{"atl":[[130,0],[90,0],[180,0],[230,0]],"id":40324412},{"atb":[[4.3,0],[5.8,0],[5.3,0],[6.6,0]],"id":43066392},{"atl":[[36,0],[19,0],[23,0],[28,0]],"id":43066392},{"atb":[[1.12,0],[1.02,0],[1.22,0],[1.17,0]],"id":42845264},{"atl":[[2.36,0],[2.56,0],[2.46,0],[2.26,0]],"id":42845264},{"spn":41.0,"spf":"NaN","id":43154432},{"spn":85.5,"spf":"NaN","id":39586887}],"con":true,"img":false}]}
{"op":"mcm","clk":"5346184036","pt":1646082300481,"mc":[{"id":"1.195395453","rc":[{"atb":[[32,1.3],[21,6.08],[26,3.24],[15.5,11.19]],"id":37076607},{"atl":[[290,0.46],[340,0.58],[390,0.5],[240,0.55]],"id":37076607},{"atb":[[8.6,5.34],[5.3,37.76],[7.6,12.3],[6.6,21.74]],"id":40612296},{"atl":[[65,3.1],[36,3.77],[90,2.23],[46,2.93]],"id":40612296},{"atb":[[17,2.53],[12,11.06],[8.8,20.81],[14.5,6.01]],"id":40324412},{"atl":[[270,0.73],[170,0.78],[220,0.9],[120,1.1]],"id":40324412},{"atb":[[4,54.13],[5,30.44],[5.5,18.04],[6,8.11]],"id":43066392},{"atl":[[34,6.01],[18.5,7.56],[22,6.3],[27,7.63]],"id":43066392},{"atb":[[1.28,144.99],[1.18,676.62],[1.23,353.02],[1.08,2029.87]],"id":42845264},{"atl":[[2.38,95.86],[2.58,125.59],[2.68,118.11],[2.48,89.39]],"id":42845264}],"con":true,"img":false}]}
{"op":"mcm","clk":"5346223628","pt":1646082746274,"mc":[{"id":"1.195395453","rc":[{"atb":[[32,0],[21,0],[26,0],[15.5,0]],"id":37076607},{"atl":[[290,0],[340,0],[390,0],[240,0]],"id":37076607},{"atb":[[16.5,0],[19,0],[23,0],[11.5,0]],"id":42901530},{"atl":[[260,0],[310,0],[160,0],[210,0]],"id":42901530},{"spn":"NaN","spf":"NaN","id":42901530},{"atb":[[8.6,0],[5.3,0],[7.6,0],[6.6,0]],"id":40612296},{"atl":[[65,0],[36,0],[90,0],[46,0]],"id":40612296},{"atb":[[17,0],[12,0],[8.8,0],[14.5,0]],"id":40324412},{"atl":[[270,0],[170,0],[220,0],[120,0]],"id":40324412},{"atb":[[4,0],[5,0],[5.5,0],[6,0]],"id":43066392},{"atl":[[34,0],[18.5,0],[22,0],[27,0]],"id":43066392},{"atb":[[1.28,0],[1.18,0],[1.23,0],[1.08,0]],"id":42845264},{"atl":[[2.38,0],[2.58,0],[2.68,0],[2.48,0]],"id":42845264},{"atb":[[12,0],[6.8,0],[9.8,0],[8.8,0]],"id":43154432},{"atl":[[70,0],[140,0],[95,0],[190,0]],"id":43154432},{"spn":"NaN","spf":"NaN","id":43154432},{"atb":[[18,0],[21,0],[10.5,0],[15.5,0]],"id":39586887},{"atl":[[150,0],[300,0],[200,0],[250,0]],"id":39586887},{"spn":"NaN","spf":"NaN","id":39586887}],"con":true,"img":false}]}
{"op":"mcm","clk":"5346226100","pt":1646082775428,"mc":[{"id":"1.195395453","rc":[{"atb":[[16.5,7.85],[19,4.5],[23,1.84],[11.5,15.46]],"id":37076607},{"atl":[[260,0.76],[310,0.64],[160,0.83],[210,0.63]],"id":37076607},{"atb":[[16.5,7.85],[19,4.5],[23,1.84],[11.5,15.46]],"id":42901530},{"atl":[[260,0.76],[310,0.64],[160,0.83],[210,0.63]],"id":42901530},{"atb":[[8,5.79],[5,40.59],[6,24.35],[7,13.53]],"id":40612296},{"atl":[[70,2.87],[38,3.57],[48,4.22],[29,4.72]],"id":40612296},{"atb":[[9.6,14.16],[11.5,7.73],[7.6,24.6],[14,3.12]],"id":40324412},{"atl":[[130,1.02],[90,1.48],[180,1.1],[230,0.86]],"id":40324412},{"atb":[[4,54.13],[5,30.44],[5.5,18.04],[6,8.11]],"id":43066392},{"atl":[[34,6.01],[18.5,7.56],[22,6.3],[27,7.63]],"id":43066392},{"atb":[[1.12,1014.93],[1.02,8119.51],[1.22,184.53],[1.17,477.61]],"id":42845264},{"atl":[[2.36,97.27],[2.56,127.2],[2.46,135.92],[2.26,104.99]],"id":42845264},{"atb":[[12,3.69],[6.8,27.99],[9.8,9.22],[8.8,15.61]],"id":43154432},{"atl":[[70,1.91],[140,1.42],[95,1.4],[190,1.05]],"id":43154432},{"atb":[[18,4.77],[21,2.02],[10.5,17.09],[15.5,8.4]],"id":39586887},{"atl":[[150,0.88],[300,0.66],[200,0.66],[250,0.79]],"id":39586887}],"con":true,"img":false}]}
{"op":"mcm","clk":"5346252985","pt":1646083002680,"mc":[{"id":"1.195395453","marketDefinition":{"bspMarket":true,"turnInPlayEnabled":false,"persistenceEnabled":false,"marketBaseRate":5.0,"eventId":"31270459","eventTypeId":"4339","numberOfWinners":1,"bettingType":"ODDS","marketType":"WIN","marketTime":"2022-03-01T01:45:00.000Z","suspendTime":"2022-03-01T01:45:00.000Z","bspReconciled":false,"complete":true,"inPlay":false,"crossMatching":false,"runnersVoidable":false,"numberOfActiveRunners":8,"betDelay":0,"status":"OPEN","runners":[{"status":"ACTIVE","sortPriority":1,"id":39586887,"name":"1. Homebush Bun"},{"status":"ACTIVE","sortPriority":2,"id":42901530,"name":"2. Wild Thyme"},{"status":"ACTIVE","sortPriority":3,"id":40612296,"name":"3. Opawa Duchess"},{"status":"ACTIVE","sortPriority":4,"id":37076607,"name":"4. Opawa Ruby"},{"status":"ACTIVE","sortPriority":5,"id":42845264,"name":"5. Opawa Dragon"},{"status":"ACTIVE","sortPriority":6,"id":43154432,"name":"6. Iced Mocha"},{"status":"ACTIVE","sortPriority":7,"id":43066392,"name":"7. Go Hazel"},{"status":"ACTIVE","sortPriority":8,"id":40324412,"name":"8. Goldstar Charm"}],"regulators":["MR_INT"],"venue":"Addington","countryCode":"NZ","discountAllowed":true,"timezone":"NZ","openDate":"2022-02-28T23:02:00.000Z","version":4380660693,"name":"R10 520m S/E","eventName":"Addington (NZL) 1st Mar"},"rc":[{"atb":[[16.5,7.85],[19,4.5],[23,1.84],[11.5,15.46]],"id":37076607},{"atl":[[260,0.76],[310,0.64],[160,0.83],[210,0.63]],"id":37076607},{"spn":91.5,"spf":"NaN","id":37076607},{"atb":[[16.5,7.85],[19,4.5],[23,1.84],[11.5,15.46]],"id":42901530},{"atl":[[260,0.76],[310,0.64],[160,0.83],[210,0.63]],"id":42901530},{"spn":91.5,"spf":"NaN","id":42901530},{"atb":[[8,5.79],[5,40.59],[6,24.35],[7,13.53]],"id":40612296},{"atl":[[70,2.87],[38,3.57],[48,4.22],[29,4.72]],"id":40612296},{"spn":18.5,"spf":"NaN","id":40612296},{"atb":[[9.6,14.16],[11.5,7.73],[7.6,24.6],[14,3.12]],"id":40324412},{"atl":[[130,1.02],[90,1.48],[180,1.1],[230,0.86]],"id":40324412},{"spn":52.0,"spf":"NaN","id":40324412},{"atb":[[4,54.13],[5,30.44],[5.5,18.04],[6,8.11]],"id":43066392},{"atl":[[34,6.01],[18.5,7.56],[22,6.3],[27,7.63]],"id":43066392},{"spn":12.25,"spf":"NaN","id":43066392},{"atb":[[1.12,1014.93],[1.02,8119.51],[1.22,184.53],[1.17,477.61]],"id":42845264},{"atl":[[2.36,97.27],[2.56,127.2],[2.46,135.92],[2.26,104.99]],"id":42845264},{"spn":1.74,"spf":"NaN","id":42845264},{"atb":[[12,3.69],[6.8,27.99],[9.8,9.22],[8.8,15.61]],"id":43154432},{"atl":[[70,1.91],[140,1.42],[95,1.4],[190,1.05]],"id":43154432},{"spn":41.0,"spf":"NaN","id":43154432},{"atb":[[18,4.77],[21,2.02],[10.5,17.09],[15.5,8.4]],"id":39586887},{"atl":[[150,0.88],[300,0.66],[200,0.66],[250,0.79]],"id":39586887},{"spn":85.5,"spf":"NaN","id":39586887}],"con":true,"img":true}]}
{"op":"mcm","clk":"5346421614","pt":1646085945582,"mc":[{"id":"1.195395453","rc":[{"atb":[[16.5,7.85],[19,4.5],[23,1.84],[11.5,15.46]],"id":37076607},{"atl":[[260,0.76],[310,0.64],[160,0.83],[210,0.63]],"id":37076607},{"spn":91.5,"spf":"NaN","id":37076607},{"atb":[[16.5,7.85],[19,4.5],[23,1.84],[11.5,15.46]],"id":42901530},{"atl":[[260,0.76],[310,0.64],[160,0.83],[210,0.63]],"id":42901530},{"spn":91.5,"spf":"NaN","id":42901530},{"atb":[[8,5.79],[5,40.59],[6,24.35],[7,13.53]],"id":40612296},{"atl":[[70,2.87],[38,3.57],[48,4.22],[29,4.72]],"id":40612296},{"spn":18.5,"spf":"NaN","id":40612296},{"atb":[[9.6,14.15],[11.5,7.73],[7.6,24.59],[14,3.12]],"id":40324412},{"atl":[[130,1.02],[90,1.48],[180,1.1],[230,0.86]],"id":40324412},{"spn":52.0,"spf":"NaN","id":40324412},{"atb":[[4,54.12],[5,30.44],[5.5,18.03],[6,8.11]],"id":43066392},{"atl":[[34,6.01],[18.5,7.56],[22,6.29],[27,7.63]],"id":43066392},{"spn":12.25,"spf":"NaN","id":43066392},{"atb":[[1.12,1014.77],[1.02,8118.2],[1.22,184.5],[1.17,477.53]],"id":42845264},{"atl":[[2.36,97.26],[2.56,127.18],[2.46,135.89],[2.26,104.97],[1.94,17.86]],"id":42845264},{"spn":1.58,"spf":"NaN","id":42845264},{"atb":[[12,3.69],[6.8,27.99],[9.8,9.22],[8.8,15.61]],"id":43154432},{"atl":[[70,1.91],[140,1.42],[95,1.4],[190,1.04]],"id":43154432},{"spn":41.0,"spf":"NaN","id":43154432},{"atb":[[18,4.77],[21,2.02],[10.5,17.09],[15.5,8.39]],"id":39586887},{"atl":[[150,0.88],[300,0.66],[200,0.66],[250,0.79]],"id":39586887},{"spn":85.5,"spf":"NaN","id":39586887}],"con":true,"img":false}]}
{"op":"mcm","clk":"5346529713","pt":1646089282706,"mc":[{"id":"1.195395453","rc":[{"atl":[[2.02,4.05]],"id":42845264}],"con":true,"img":false}]}
{"op":"mcm","clk":"5346531205","pt":1646089331799,"mc":[{"id":"1.195395453","rc":[{"spl":[[100,2]],"id":37076607},{"spl":[[100,2]],"id":42901530},{"spl":[[100,2]],"id":40612296},{"spl":[[100,2]],"id":40324412},{"spl":[[100,2]],"id":43066392},{"spl":[[100,2]],"id":42845264},{"spl":[[100,2]],"id":43154432},{"spl":[[100,2]],"id":39586887}],"con":true,"img":false}]}
{"op":"mcm","clk":"5346553980","pt":1646090324621,"mc":[{"id":"1.195395453","rc":[{"spn":61.5,"spf":1.0,"id":37076607},{"spn":61.5,"spf":1.0,"id":42901530},{"spn":18.5,"spf":1.0,"id":40612296},{"spn":52.0,"spf":1.0,"id":40324412},{"atb":[[1.01,2.23]],"id":43066392},{"spn":12.25,"spf":1.0,"id":43066392},{"spn":1.58,"spf":1.0,"id":42845264},{"spn":41.0,"spf":1.0,"id":43154432},{"spn":60.5,"spf":1.0,"id":39586887}],"con":true,"img":false}]}
{"op":"mcm","clk":"5346553988","pt":1646090324827,"mc":[{"id":"1.195395453","rc":[{"atb":[[1.01,1.78]],"id":43066392}],"con":true,"img":false}]}
{"op":"mcm","clk":"5346553991","pt":1646090324926,"mc":[{"id":"1.195395453","rc":[{"atb":[[1.01,0]],"id":43066392}],"con":true,"img":false}]}
{"op":"mcm","clk":"5346553996","pt":1646090325026,"mc":[{"id":"1.195395453","rc":[{"atb":[[5.6,1.78]],"id":43066392}],"con":true,"img":false}]}
{"op":"mcm","clk":"5346554344","pt":1646090337000,"mc":[{"id":"1.195395453","marketDefinition":{"bspMarket":true,"turnInPlayEnabled":false,"persistenceEnabled":false,"marketBaseRate":5.0,"eventId":"31270459","eventTypeId":"4339","numberOfWinners":1,"bettingType":"ODDS","marketType":"WIN","marketTime":"2022-03-01T01:45:00.000Z","suspendTime":"2022-03-01T01:45:00.000Z","bspReconciled":false,"complete":true,"inPlay":false,"crossMatching":true,"runnersVoidable":false,"numberOfActiveRunners":8,"betDelay":0,"status":"OPEN","runners":[{"status":"ACTIVE","sortPriority":1,"id":39586887,"name":"1. Homebush Bun"},{"status":"ACTIVE","sortPriority":2,"id":42901530,"name":"2. Wild Thyme"},{"status":"ACTIVE","sortPriority":3,"id":40612296,"name":"3. Opawa Duchess"},{"status":"ACTIVE","sortPriority":4,"id":37076607,"name":"4. Opawa Ruby"},{"status":"ACTIVE","sortPriority":5,"id":42845264,"name":"5. Opawa Dragon"},{"status":"ACTIVE","sortPriority":6,"id":43154432,"name":"6. Iced Mocha"},{"status":"ACTIVE","sortPriority":7,"id":43066392,"name":"7. Go Hazel"},{"status":"ACTIVE","sortPriority":8,"id":40324412,"name":"8. Goldstar Charm"}],"regulators":["MR_INT"],"venue":"Addington","countryCode":"NZ","discountAllowed":true,"timezone":"NZ","openDate":"2022-02-28T23:02:00.000Z","version":4380660693,"name":"R10 520m S/E","eventName":"Addington (NZL) 1st Mar"},"rc":[],"con":true,"img":false}]}
{"op":"mcm","clk":"5346555654","pt":1646090379491,"mc":[{"id":"1.195395453","rc":[{"atb":[[5.6,3.77]],"id":43066392}],"con":true,"img":false}]}
{"op":"mcm","clk":"5346589603","pt":1646091561861,"mc":[{"id":"1.195395453","rc":[{"spl":[[1.01,3.78]],"id":37076607},{"spn":20.94,"spf":1.0,"id":37076607}],"con":true,"img":false}]}
{"op":"mcm","clk":"5346598962","pt":1646091900160,"mc":[{"id":"1.195395453","rc":[{"atb":[[32,0.33]],"id":37076607},{"spn":22.08,"spf":1.0,"id":37076607},{"atb":[[27,0.39]],"id":42901530},{"spn":63.5,"spf":1.0,"id":42901530},{"atb":[[7,15.21]],"id":40612296},{"atb":[[17.5,0.62]],"id":40324412},{"spn":53.75,"spf":1.0,"id":40324412},{"atb":[[4.9,2]],"id":43066392},{"atb":[[1.25,2]],"id":42845264},{"spn":1.59,"spf":1.0,"id":42845264},{"atb":[[13.5,0.81]],"id":43154432},{"spn":41.75,"spf":1.0,"id":43154432},{"atb":[[22,0.49]],"id":39586887},{"spn":61.0,"spf":1.0,"id":39586887}],"con":true,"img":false}]}
{"op":"mcm","clk":"5346661567","pt":1646093701972,"mc":[{"id":"1.195395453","rc":[{"atb":[[16.5,7.85],[19,4.5],[23,1.84],[11.5,15.45]],"id":37076607},{"spl":[[1.01,3.78]],"id":37076607},{"atl":[[260,0.76],[310,0.64],[160,0.83],[210,0.63]],"id":37076607},{"spn":22.08,"spf":1.0,"id":37076607},{"atb":[[16.5,7.85],[19,4.5],[23,1.84],[11.5,15.45]],"id":42901530},{"atl":[[260,0.76],[310,0.64],[160,0.83],[210,0.63]],"id":42901530},{"atb":[[8,5.79],[5,40.56],[6,24.33],[7,15.2]],"id":40612296},{"atl":[[70,2.87],[38,3.57],[48,4.21],[29,4.72]],"id":40612296},{"atb":[[9.6,14.14],[11.5,7.72],[7.6,24.58],[14,3.12]],"id":40324412},{"atl":[[130,1.02],[90,1.48],[180,1.1],[230,0.86]],"id":40324412},{"atb":[[5.6,3.77],[4,54.08],[5,30.42],[5.5,18.02],[6,8.11]],"id":43066392},{"atl":[[34,6],[18.5,7.55],[22,6.29],[27,7.62]],"id":43066392},{"atb":[[1.12,1014.11],[1.02,8112.93],[1.22,184.38],[1.17,477.22]],"id":42845264},{"atl":[[2.36,97.19],[2.56,127.1],[2.02,4.05],[2.46,135.81],[1.94,17.84],[2.26,104.91]],"id":42845264},{"atb":[[12,3.68],[6.8,27.97],[9.8,9.22],[8.8,15.6]],"id":43154432},{"atl":[[70,1.91],[140,1.42],[95,1.4],[190,1.04]],"id":43154432},{"atb":[[18,4.77],[21,2.02],[10.5,17.08],[11,7.2],[15.5,8.39]],"id":39586887},{"atl":[[150,0.88],[300,0.66],[200,0.66],[250,0.79]],"id":39586887}],"con":true,"img":false}]}
{"op":"mcm","clk":"5346661571","pt":1646093702074,"mc":[{"id":"1.195395453","rc":[{"atb":[[4.5,20.57]],"id":40612296},{"atb":[[7.4,11.25]],"id":40324412},{"atb":[[3.5,28.8]],"id":43066392},{"atb":[[6.4,13.33]],"id":43154432}],"con":true,"img":false}]}
{"op":"mcm","clk":"5346661576","pt":1646093702177,"mc":[{"id":"1.195395453","rc":[{"atb":[[2.62,46.3],[4.2,26.56]],"id":37076607},{"atb":[[2.62,46.3],[4.2,26.56]],"id":42901530},{"atb":[[2.62,46.3]],"id":40612296},{"atl":[[70,11.07]],"id":40612296},{"atb":[[2.62,46.3],[4.2,26.56]],"id":40324412},{"atb":[[2.62,46.3]],"id":43066392},{"atl":[[46,8.2]],"id":43066392},{"atl":[[34,13.5]],"id":42845264},{"atb":[[2.62,46.3],[4.2,26.56]],"id":43154432},{"atb":[[2.62,46.3],[4.2,26.56]],"id":39586887}],"con":true,"img":false}]}
{"op":"mcm","clk":"5346661589","pt":1646093702330,"mc":[{"id":"1.195395453","rc":[{"atl":[[17,8.5]],"id":42845264}],"con":true,"img":false}]}
{"op":"mcm","clk":"5346664375","pt":1646093785302,"mc":[{"id":"1.195395453","rc":[{"atb":[[19.5,7.03],[28,2.7]],"id":37076607},{"atl":[[160,1.1],[250,2.7]],"id":37076607},{"spn":27.35,"spf":1.0,"id":37076607},{"atb":[[19.5,7.03],[26,2.7]],"id":42901530},{"atl":[[150,2.7],[160,1.1]],"id":42901530},{"atb":[[7.2,6.97],[6.2,24.87]],"id":40612296},{"atl":[[34,2.7],[36,3.78]],"id":40612296},{"atb":[[12,11.35],[15.5,2.98]],"id":40324412},{"atl":[[90,1.97],[120,2.7]],"id":40324412},{"atb":[[5.1,10.55],[4.1,39.34]],"id":43066392},{"atl":[[18,2.7],[26,4.87]],"id":43066392},{"spn":12.0,"spf":1.0,"id":43066392},{"atb":[[1.18,685.09],[1.23,43.26]],"id":42845264},{"atl":[[2.24,99.44],[1.93,43.26]],"id":42845264},{"spn":1.59,"spf":1.0,"id":42845264},{"atb":[[10,13.46],[12,7.62]],"id":43154432},{"atl":[[70,2.54],[90,2.7]],"id":43154432},{"atb":[[18.5,6.5],[22,3.19]],"id":39586887},{"atl":[[140,3.01]],"id":39586887}],"con":true,"img":false}]}
{"op":"mcm","clk":"5346664383","pt":1646093785509,"mc":[{"id":"1.195395453","rc":[{"atl":[[150,0]],"id":42901530}],"con":true,"img":false}]}
{"op":"mcm","clk":"5346664384","pt":1646093785613,"mc":[{"id":"1.195395453","rc":[{"atl":[[200,2.7]],"id":42901530}],"con":true,"img":false}]}
{"op":"mcm","clk":"5346664401","pt":1646093786077,"mc":[{"id":"1.195395453","rc":[{"atb":[[10,8]],"id":42901530}],"con":true,"img":false}]}
{"op":"mcm","clk":"5346674750","pt":1646093867140,"mc":[{"id":"1.195395453","rc":[{"atl":[[250,0]],"id":37076607},{"atl":[[200,0]],"id":42901530},{"atl":[[34,0]],"id":40612296},{"atb":[[12,3.68]],"id":43154432}],"con":true,"img":false}]}
{"op":"mcm","clk":"5346674754","pt":1646093867193,"mc":[{"id":"1.195395453","rc":[{"atl":[[200,2.7]],"id":37076607},{"atl":[[150,2.7]],"id":42901530},{"atl":[[28,2.7]],"id":40612296},{"atb":[[12.5,3.93]],"id":43154432}],"con":true,"img":false}]}
{"op":"mcm","clk":"5346674761","pt":1646093867396,"mc":[{"id":"1.195395453","rc":[{"atl":[[2.02,0]],"id":42845264}],"con":true,"img":false}]}
{"op":"mcm","clk":"5346682978","pt":1646094090101,"mc":[{"id":"1.195395453","rc":[{"atb":[[11,7.2]],"id":37076607},{"spn":18.0,"spf":1.0,"id":40612296}],"con":true,"img":false}]}
{"op":"mcm","clk":"5346736055","pt":1646095530250,"mc":[{"id":"1.195395453","rc":[{"atb":[[9.2,12.2]],"id":37076607},{"atb":[[8.8,12.82]],"id":42901530},{"atl":[[150,4.7]],"id":42901530},{"atb":[[3.75,36.36]],"id":40612296},{"atl":[[28,6.4]],"id":40612296},{"atb":[[9.6,25.77]],"id":40324412},{"atl":[[180,3.1]],"id":40324412},{"atb":[[3.6,37.55]],"id":43066392},{"atl":[[18,8.58]],"id":43066392},{"atb":[[1.2,500]],"id":42845264},{"atl":[[2.28,78.13]],"id":42845264},{"atb":[[4.7,27.03]],"id":43154432},{"atl":[[70,4.54]],"id":43154432},{"atb":[[19.5,5.41]],"id":39586887},{"atl":[[580,2]],"id":39586887}],"con":true,"img":false}]}
{"op":"mcm","clk":"5346736474","pt":1646095540046,"mc":[{"id":"1.195395453","rc":[{"atl":[[200,0]],"id":37076607},{"atl":[[120,0]],"id":40324412},{"atl":[[90,0]],"id":43154432},{"atl":[[140,0.31]],"id":39586887}],"con":true,"img":false}]}
{"op":"mcm","clk":"5346736479","pt":1646095540148,"mc":[{"id":"1.195395453","rc":[{"atl":[[250,2.7]],"id":37076607},{"atl":[[170,2.7]],"id":40324412},{"atl":[[130,2.7]],"id":43154432},{"atl":[[240,2.7]],"id":39586887}],"con":true,"img":false}]}
{"op":"mcm","clk":"5346737605","pt":1646095568919,"mc":[{"id":"1.195395453","rc":[{"atl":[[160,0.83]],"id":42901530},{"atb":[[1.18,0]],"id":42845264},{"atb":[[18.5,0]],"id":39586887}],"con":true,"img":false}]}
{"op":"mcm","clk":"5346737611","pt":1646095569018,"mc":[{"id":"1.195395453","rc":[{"atl":[[140,0.27]],"id":42901530},{"atb":[[1.21,685.09]],"id":42845264},{"atb":[[20,6.5]],"id":39586887}],"con":true,"img":false}]}
{"op":"mcm","clk":"5346738814","pt":1646095597182,"mc":[{"id":"1.195395453","rc":[{"atl":[[70,3.91]],"id":43154432}],"con":true,"img":false}]}
{"op":"mcm","clk":"5346738818","pt":1646095597285,"mc":[{"id":"1.195395453","rc":[{"atl":[[65,0.62]],"id":43154432}],"con":true,"img":false}]}
{"op":"mcm","clk":"5346740056","pt":1646095625599,"mc":[{"id":"1.195395453","rc":[{"atl":[[170,0]],"id":40324412},{"atl":[[130,0]],"id":43154432},{"atl":[[240,0]],"id":39586887}],"con":true,"img":false}]}
{"op":"mcm","clk":"5346740061","pt":1646095625701,"mc":[{"id":"1.195395453","rc":[{"atl":[[120,2.7]],"id":40324412},{"atl":[[90,2.7]],"id":43154432},{"atl":[[140,3.01]],"id":39586887}],"con":true,"img":false}]}
{"op":"mcm","clk":"5346741096","pt":1646095653462,"mc":[{"id":"1.195395453","rc":[{"atl":[[250,0]],"id":37076607}],"con":true,"img":false}]}
{"op":"mcm","clk":"5346741099","pt":1646095653566,"mc":[{"id":"1.195395453","rc":[{"atl":[[200,2.7]],"id":37076607}],"con":true,"img":false}]}
{"op":"mcm","clk":"5346748549","pt":1646095904060,"mc":[{"id":"1.195395453","rc":[{"atb":[[3.6,0],[3.9,34.48]],"id":43066392},{"spn":39.25,"spf":1.0,"id":43154432}],"con":true,"img":false}]}
{"op":"mcm","clk":"5346750442","pt":1646095969387,"mc":[{"id":"1.195395453","rc":[{"atl":[[150,2.7],[170,2]],"id":42901530},{"atb":[[5.2,23.81]],"id":40612296},{"atl":[[34,3.03]],"id":40612296},{"atb":[[3.35,42.55],[3.9,0]],"id":43066392},{"atl":[[1.92,43.27]],"id":42845264},{"spn":1.58,"spf":1.0,"id":42845264},{"atb":[[6.2,19.23],[4.7,0]],"id":43154432},{"atl":[[70,1.91],[85,2]],"id":43154432},{"atl":[[580,0],[680,2]],"id":39586887}],"con":true,"img":false}]}
{"op":"mcm","clk":"5346750444","pt":1646095969438,"mc":[{"id":"1.195395453","rc":[{"atb":[[3.75,0]],"id":40612296},{"atl":[[28,2.7]],"id":40612296},{"atl":[[2.28,0]],"id":42845264}],"con":true,"img":false}]}
{"op":"mcm","clk":"5346751098","pt":1646095992211,"mc":[{"id":"1.195395453","rc":[{"atl":[[140,0]],"id":42901530}],"con":true,"img":false}]}
{"op":"mcm","clk":"5346751101","pt":1646095992315,"mc":[{"id":"1.195395453","rc":[{"atl":[[150,2.97]],"id":42901530}],"con":true,"img":false}]}
{"op":"mcm","clk":"5346751941","pt":1646096019650,"mc":[{"id":"1.195395453","rc":[{"atl":[[80,2],[85,0]],"id":43154432}],"con":true,"img":false}]}
{"op":"mcm","clk":"5346752095","pt":1646096024773,"mc":[{"id":"1.195395453","rc":[{"atl":[[80,0],[85,2]],"id":43154432}],"con":true,"img":false}]}
{"op":"mcm","clk":"5346752573","pt":1646096041202,"mc":[{"id":"1.195395453","rc":[{"atl":[[1.93,0]],"id":42845264},{"atl":[[90,0]],"id":43154432}],"con":true,"img":false}]}
{"op":"mcm","clk":"5346752577","pt":1646096041302,"mc":[{"id":"1.195395453","rc":[{"atl":[[1.91,43.26],[1.93,99.45]],"id":42845264},{"atl":[[80,2.7]],"id":43154432}],"con":true,"img":false}]}
{"op":"mcm","clk":"5346752581","pt":1646096041404,"mc":[{"id":"1.195395453","rc":[{"atl":[[1.92,0]],"id":42845264}],"con":true,"img":false}]}
{"op":"mcm","clk":"5346752583","pt":1646096041507,"mc":[{"id":"1.195395453","rc":[{"atl":[[1.91,86.53]],"id":42845264}],"con":true,"img":false}]}
{"op":"mcm","clk":"5346752587","pt":1646096041610,"mc":[{"id":"1.195395453","rc":[{"atl":[[1.93,0]],"id":42845264}],"con":true,"img":false}]}
{"op":"mcm","clk":"5346753954","pt":1646096081288,"mc":[{"id":"1.195395453","rc":[{"atl":[[80,4.7],[85,0]],"id":43154432}],"con":true,"img":false}]}
{"op":"mcm","clk":"5346753959","pt":1646096081391,"mc":[{"id":"1.195395453","rc":[{"atl":[[85,2]],"id":43154432}],"con":true,"img":false}]}
{"op":"mcm","clk":"5346753964","pt":1646096081495,"mc":[{"id":"1.195395453","rc":[{"atl":[[80,2.7]],"id":43154432}],"con":true,"img":false}]}
{"op":"mcm","clk":"5346754071","pt":1646096083806,"mc":[{"id":"1.195395453","rc":[{"atb":[[9.2,0],[11,17.2]],"id":37076607},{"atl":[[34,0],[38,6.27]],"id":40612296},{"atb":[[19.5,0],[15.5,15.29]],"id":39586887}],"con":true,"img":false}]}
{"op":"mcm","clk":"5346754277","pt":1646096089098,"mc":[{"id":"1.195395453","rc":[{"atl":[[150,0.27]],"id":42901530},{"atl":[[28,0]],"id":40612296},{"atb":[[20,0]],"id":39586887}],"con":true,"img":false}]}
{"op":"mcm","clk":"5346754285","pt":1646096089302,"mc":[{"id":"1.195395453","rc":[{"atl":[[160,3.53]],"id":42901530},{"atl":[[34,2.7]],"id":40612296},{"atb":[[18.5,6.5]],"id":39586887}],"con":true,"img":false}]}
{"op":"mcm","clk":"5346755199","pt":1646096112321,"mc":[{"id":"1.195395453","rc":[{"atb":[[26,0]],"id":42901530},{"spn":18.5,"spf":1.0,"id":40612296},{"atl":[[1.91,43.27]],"id":42845264},{"spn":1.58,"spf":1.0,"id":42845264}],"con":true,"img":false}]}
{"op":"mcm","clk":"5346755204","pt":1646096112423,"mc":[{"id":"1.195395453","rc":[{"atb":[[27,3.09]],"id":42901530},{"atl":[[1.9,43.26],[1.93,99.45]],"id":42845264}],"con":true,"img":false}]}
{"op":"mcm","clk":"5346755208","pt":1646096112526,"mc":[{"id":"1.195395453","rc":[{"atl":[[1.91,0]],"id":42845264}],"con":true,"img":false}]}
{"op":"mcm","clk":"5346756024","pt":1646096135954,"mc":[{"id":"1.195395453","rc":[{"atl":[[200,0]],"id":37076607},{"atl":[[120,0]],"id":40324412},{"atl":[[1.9,0]],"id":42845264},{"atl":[[140,0.31]],"id":39586887}],"con":true,"img":false}]}
{"op":"mcm","clk":"5346756028","pt":1646096136055,"mc":[{"id":"1.195395453","rc":[{"atl":[[250,2.7]],"id":37076607},{"atl":[[170,2.7]],"id":40324412},{"atl":[[1.92,43.26]],"id":42845264},{"atl":[[240,2.7]],"id":39586887}],"con":true,"img":false}]}
{"op":"mcm","clk":"5346756277","pt":1646096142645,"mc":[{"id":"1.195395453","rc":[{"atl":[[80,4.7],[85,0]],"id":43154432}],"con":true,"img":false}]}
{"op":"mcm","clk":"5346756280","pt":1646096142746,"mc":[{"id":"1.195395453","rc":[{"atl":[[85,2]],"id":43154432}],"con":true,"img":false}]}
{"op":"mcm","clk":"5346756283","pt":1646096142850,"mc":[{"id":"1.195395453","rc":[{"atl":[[80,2.7]],"id":43154432}],"con":true,"img":false}]}
{"op":"mcm","clk":"5346756299","pt":1646096143465,"mc":[{"id":"1.195395453","rc":[{"atl":[[1.91,43.27]],"id":42845264}],"con":true,"img":false}]}
{"op":"mcm","clk":"5346756303","pt":1646096143568,"mc":[{"id":"1.195395453","rc":[{"atl":[[1.93,0]],"id":42845264}],"con":true,"img":false}]}
{"op":"mcm","clk":"5346756837","pt":1646096159104,"mc":[{"id":"1.195395453","rc":[{"atl":[[34,0]],"id":40612296}],"con":true,"img":false}]}
{"op":"mcm","clk":"5346756840","pt":1646096159207,"mc":[{"id":"1.195395453","rc":[{"atl":[[32,2.7]],"id":40612296}],"con":true,"img":false}]}
{"op":"mcm","clk":"5346758366","pt":1646096204272,"mc":[{"id":"1.195395453","rc":[{"atl":[[80,4.7],[85,0]],"id":43154432}],"con":true,"img":false}]}
{"op":"mcm","clk":"5346758378","pt":1646096204578,"mc":[{"id":"1.195395453","rc":[{"atl":[[250,0]],"id":37076607},{"atl":[[170,0]],"id":40324412},{"atl":[[1.92,0]],"id":42845264},{"atl":[[240,0]],"id":39586887}],"con":true,"img":false}]}
{"op":"mcm","clk":"5346758382","pt":1646096204682,"mc":[{"id":"1.195395453","rc":[{"atl":[[200,2.7]],"id":37076607},{"atl":[[120,2.7]],"id":40324412},{"atl":[[1.9,43.26]],"id":42845264},{"atl":[[140,3.01]],"id":39586887}],"con":true,"img":false}]}
{"op":"mcm","clk":"5346758387","pt":1646096204785,"mc":[{"id":"1.195395453","rc":[{"atl":[[1.91,0],[1.93,99.45]],"id":42845264}],"con":true,"img":false}]}
{"op":"mcm","clk":"5346758391","pt":1646096204891,"mc":[{"id":"1.195395453","rc":[{"atl":[[1.91,86.54],[1.93,0]],"id":42845264}],"con":true,"img":false}]}
{"op":"mcm","clk":"5346758585","pt":1646096209411,"mc":[{"id":"1.195395453","rc":[{"atl":[[80,2.7],[85,2]],"id":43154432}],"con":true,"img":false}]}
{"op":"mcm","clk":"5346759388","pt":1646096226724,"mc":[{"id":"1.195395453","rc":[{"atl":[[200,0]],"id":37076607},{"atl":[[32,0]],"id":40612296},{"atl":[[120,0]],"id":40324412},{"atl":[[140,0.31]],"id":39586887}],"con":true,"img":false}]}
{"op":"mcm","clk":"5346759394","pt":1646096226825,"mc":[{"id":"1.195395453","rc":[{"atl":[[250,2.7]],"id":37076607},{"atl":[[30,2.7]],"id":40612296},{"atl":[[170,2.7]],"id":40324412},{"atl":[[240,2.7]],"id":39586887}],"con":true,"img":false}]}
{"op":"mcm","clk":"5346760454","pt":1646096249341,"mc":[{"id":"1.195395453","rc":[{"atl":[[30,0]],"id":40612296}],"con":true,"img":false}]}
{"op":"mcm","clk":"5346760459","pt":1646096249442,"mc":[{"id":"1.195395453","rc":[{"atl":[[34,2.7]],"id":40612296}],"con":true,"img":false}]}
{"op":"mcm","clk":"5346761145","pt":1646096266190,"mc":[{"id":"1.195395453","rc":[{"spn":1.57,"spf":1.0,"id":42845264},{"atl":[[80,4.7],[85,0]],"id":43154432}],"con":true,"img":false}]}
{"op":"mcm","clk":"5346761352","pt":1646096271280,"mc":[{"id":"1.195395453","rc":[{"atl":[[80,2.7],[85,2]],"id":43154432}],"con":true,"img":false}]}
{"op":"mcm","clk":"5346762940","pt":1646096315351,"mc":[{"id":"1.195395453","rc":[{"atl":[[34,0]],"id":40612296}],"con":true,"img":false}]}
{"op":"mcm","clk":"5346762943","pt":1646096315455,"mc":[{"id":"1.195395453","rc":[{"atl":[[32,2.7]],"id":40612296}],"con":true,"img":false}]}
{"op":"mcm","clk":"5346763243","pt":1646096326994,"mc":[{"id":"1.195395453","rc":[{"atl":[[80,4.7],[85,0]],"id":43154432}],"con":true,"img":false}]}
{"op":"mcm","clk":"5346763245","pt":1646096327098,"mc":[{"id":"1.195395453","rc":[{"atl":[[80,2.7],[85,2]],"id":43154432}],"con":true,"img":false}]}
{"op":"mcm","clk":"5346764762","pt":1646096379901,"mc":[{"id":"1.195395453","rc":[{"atl":[[32,0]],"id":40612296}],"con":true,"img":false}]}
{"op":"mcm","clk":"5346764765","pt":1646096380003,"mc":[{"id":"1.195395453","rc":[{"atl":[[30,2.7]],"id":40612296}],"con":true,"img":false}]}
{"op":"mcm","clk":"5346764989","pt":1646096387799,"mc":[{"id":"1.195395453","rc":[{"atl":[[80,4.7],[85,0]],"id":43154432}],"con":true,"img":false}]}
{"op":"mcm","clk":"5346764995","pt":1646096388006,"mc":[{"id":"1.195395453","rc":[{"atl":[[80,2.7],[85,2]],"id":43154432}],"con":true,"img":false}]}
{"op":"mcm","clk":"5346765367","pt":1646096400518,"mc":[{"id":"1.195395453","rc":[{"atl":[[30,0]],"id":40612296}],"con":true,"img":false}]}
{"op":"mcm","clk":"5346765372","pt":1646096400619,"mc":[{"id":"1.195395453","rc":[{"atl":[[34,2.7]],"id":40612296}],"con":true,"img":false}]}
{"op":"mcm","clk":"5346767136","pt":1646096448803,"mc":[{"id":"1.195395453","rc":[{"atl":[[80,4.7],[85,0]],"id":43154432}],"con":true,"img":false}]}
{"op":"mcm","clk":"5346767297","pt":1646096453888,"mc":[{"id":"1.195395453","rc":[{"atl":[[85,2]],"id":43154432}],"con":true,"img":false}]}
{"op":"mcm","clk":"5346767300","pt":1646096453987,"mc":[{"id":"1.195395453","rc":[{"atl":[[80,2.7]],"id":43154432}],"con":true,"img":false}]}
{"op":"mcm","clk":"5346767655","pt":1646096463233,"mc":[{"id":"1.195395453","rc":[{"atl":[[34,0]],"id":40612296}],"con":true,"img":false}]}
{"op":"mcm","clk":"5346767661","pt":1646096463334,"mc":[{"id":"1.195395453","rc":[{"atl":[[32,2.7]],"id":40612296}],"con":true,"img":false}]}
{"op":"mcm","clk":"5346769469","pt":1646096509479,"mc":[{"id":"1.195395453","rc":[{"atl":[[80,4.7]],"id":43154432}],"con":true,"img":false}]}
{"op":"mcm","clk":"5346769470","pt":1646096509582,"mc":[{"id":"1.195395453","rc":[{"atl":[[85,0]],"id":43154432}],"con":true,"img":false}]}
{"op":"mcm","clk":"5346769475","pt":1646096509683,"mc":[{"id":"1.195395453","rc":[{"atl":[[85,2]],"id":43154432}],"con":true,"img":false}]}
{"op":"mcm","clk":"5346769480","pt":1646096509790,"mc":[{"id":"1.195395453","rc":[{"atl":[[80,2.7]],"id":43154432}],"con":true,"img":false}]}
{"op":"mcm","clk":"5346769911","pt":1646096524189,"mc":[{"id":"1.195395453","rc":[{"atl":[[32,0]],"id":40612296}],"con":true,"img":false}]}
{"op":"mcm","clk":"5346769913","pt":1646096524292,"mc":[{"id":"1.195395453","rc":[{"atl":[[30,2.7]],"id":40612296}],"con":true,"img":false}]}
{"op":"mcm","clk":"5346770611","pt":1646096544232,"mc":[{"id":"1.195395453","rc":[{"atl":[[30,0]],"id":40612296}],"con":true,"img":false}]}
{"op":"mcm","clk":"5346770614","pt":1646096544334,"mc":[{"id":"1.195395453","rc":[{"atl":[[34,2.7]],"id":40612296}],"con":true,"img":false}]}
{"op":"mcm","clk":"5346771570","pt":1646096570571,"mc":[{"id":"1.195395453","rc":[{"atl":[[80,4.7]],"id":43154432}],"con":true,"img":false}]}
{"op":"mcm","clk":"5346771574","pt":1646096570673,"mc":[{"id":"1.195395453","rc":[{"atl":[[85,0]],"id":43154432}],"con":true,"img":false}]}
{"op":"mcm","clk":"5346771777","pt":1646096575663,"mc":[{"id":"1.195395453","rc":[{"atl":[[80,2.7],[85,2]],"id":43154432}],"con":true,"img":false}]}
{"op":"mcm","clk":"5346772919","pt":1646096603269,"mc":[{"id":"1.195395453","rc":[{"atl":[[34,0]],"id":40612296}],"con":true,"img":false}]}
{"op":"mcm","clk":"5346772927","pt":1646096603423,"mc":[{"id":"1.195395453","rc":[{"atl":[[32,2.7]],"id":40612296}],"con":true,"img":false}]}
{"op":"mcm","clk":"5346774083","pt":1646096631491,"mc":[{"id":"1.195395453","rc":[{"atl":[[80,4.7]],"id":43154432}],"con":true,"img":false}]}
{"op":"mcm","clk":"5346774085","pt":1646096631597,"mc":[{"id":"1.195395453","rc":[{"atl":[[85,0]],"id":43154432}],"con":true,"img":false}]}
{"op":"mcm","clk":"5346774243","pt":1646096636588,"mc":[{"id":"1.195395453","rc":[{"atl":[[80,2.7],[85,2]],"id":43154432}],"con":true,"img":false}]}
{"op":"mcm","clk":"5346775094","pt":1646096661414,"mc":[{"id":"1.195395453","rc":[{"atl":[[32,0]],"id":40612296}],"con":true,"img":false}]}
{"op":"mcm","clk":"5346775099","pt":1646096661515,"mc":[{"id":"1.195395453","rc":[{"atl":[[30,2.7]],"id":40612296}],"con":true,"img":false}]}
{"op":"mcm","clk":"5346775838","pt":1646096680379,"mc":[{"id":"1.195395453","rc":[{"atl":[[30,0]],"id":40612296}],"con":true,"img":false}]}
{"op":"mcm","clk":"5346775841","pt":1646096680435,"mc":[{"id":"1.195395453","rc":[{"atl":[[34,2.7]],"id":40612296}],"con":true,"img":false}]}
{"op":"mcm","clk":"5346777973","pt":1646096736339,"mc":[{"id":"1.195395453","rc":[{"atl":[[34,0]],"id":40612296}],"con":true,"img":false}]}
{"op":"mcm","clk":"5346777975","pt":1646096736442,"mc":[{"id":"1.195395453","rc":[{"atl":[[32,2.7]],"id":40612296}],"con":true,"img":false}]}
{"op":"mcm","clk":"5346778448","pt":1646096751551,"mc":[{"id":"1.195395453","rc":[{"atl":[[170,0],[180,2]],"id":42901530},{"atb":[[4.3,30.3],[5.2,0]],"id":40612296},{"atl":[[180,1.1],[240,2]],"id":40324412},{"atl":[[1.98,99.45],[1.91,0]],"id":42845264},{"atl":[[85,0],[90,2]],"id":43154432},{"atl":[[680,0],[750,2]],"id":39586887}],"con":true,"img":false}]}
{"op":"mcm","clk":"5346778548","pt":1646096754979,"mc":[{"id":"1.195395453","rc":[{"atl":[[160,0.83]],"id":42901530},{"atl":[[1.9,0]],"id":42845264},{"atl":[[80,0]],"id":43154432}],"con":true,"img":false}]}
{"op":"mcm","clk":"5346778551","pt":1646096755082,"mc":[{"id":"1.195395453","rc":[{"atl":[[170,2.7]],"id":42901530},{"atl":[[1.93,43.26]],"id":42845264},{"atl":[[85,2.7]],"id":43154432}],"con":true,"img":false}]}
{"op":"mcm","clk":"5346779160","pt":1646096776230,"mc":[{"id":"1.195395453","rc":[{"atl":[[170,4.7]],"id":42901530},{"atl":[[1.92,43.27],[1.98,0]],"id":42845264},{"atl":[[85,4.7],[90,0]],"id":43154432},{"atl":[[670,2]],"id":39586887}],"con":true,"img":false}]}
{"op":"mcm","clk":"5346779166","pt":1646096776331,"mc":[{"id":"1.195395453","rc":[{"atl":[[180,0]],"id":42901530},{"atl":[[750,0]],"id":39586887}],"con":true,"img":false}]}
{"op":"mcm","clk":"5346779576","pt":1646096791422,"mc":[{"id":"1.195395453","rc":[{"atl":[[32,0]],"id":40612296}],"con":true,"img":false}]}
{"op":"mcm","clk":"5346779580","pt":1646096791525,"mc":[{"id":"1.195395453","rc":[{"atl":[[30,2.7]],"id":40612296}],"con":true,"img":false}]}
{"op":"mcm","clk":"5346779990","pt":1646096809742,"mc":[{"id":"1.195395453","rc":[{"atl":[[30,0]],"id":40612296},{"spn":1.58,"spf":1.0,"id":42845264}],"con":true,"img":false}]}
{"op":"mcm","clk":"5346779993","pt":1646096809845,"mc":[{"id":"1.195395453","rc":[{"atl":[[34,2.7]],"id":40612296}],"con":true,"img":false}]}
{"op":"mcm","clk":"5346780094","pt":1646096814762,"mc":[{"id":"1.195395453","rc":[{"atl":[[38,3.57],[28,3.7]],"id":40612296},{"atl":[[190,2],[240,0]],"id":40324412},{"atl":[[1.92,0],[2.06,94.34]],"id":42845264},{"atb":[[6.2,0],[5.4,22.73]],"id":43154432},{"atl":[[70,3.91],[85,2.7]],"id":43154432}],"con":true,"img":false}]}
{"op":"mcm","clk":"5346780485","pt":1646096827804,"mc":[{"id":"1.195395453","rc":[{"atl":[[36,0]],"id":40612296}],"con":true,"img":false}]}
{"op":"mcm","clk":"5346780491","pt":1646096828009,"mc":[{"id":"1.195395453","rc":[{"atl":[[85,0]],"id":43154432}],"con":true,"img":false}]}
{"op":"mcm","clk":"5346780496","pt":1646096828111,"mc":[{"id":"1.195395453","rc":[{"atl":[[130,2.7]],"id":43154432}],"con":true,"img":false}]}
{"op":"mcm","clk":"5346781651","pt":1646096863757,"mc":[{"id":"1.195395453","rc":[{"atl":[[46,2.7]],"id":40612296}],"con":true,"img":false}]}
{"op":"mcm","clk":"5346781654","pt":1646096863861,"mc":[{"id":"1.195395453","rc":[{"atl":[[34,0]],"id":40612296}],"con":true,"img":false}]}
{"op":"mcm","clk":"5346781661","pt":1646096863961,"mc":[{"id":"1.195395453","rc":[{"atl":[[28,6.4]],"id":40612296}],"con":true,"img":false}]}
{"op":"mcm","clk":"5346782286","pt":1646096881093,"mc":[{"id":"1.195395453","rc":[{"atl":[[28,3.7]],"id":40612296},{"spn":18.0,"spf":1.0,"id":40612296},{"atl":[[1.93,0]],"id":42845264},{"spn":1.59,"spf":1.0,"id":42845264}],"con":true,"img":false}]}
{"op":"mcm","clk":"5346782292","pt":1646096881196,"mc":[{"id":"1.195395453","rc":[{"atl":[[34,2.7]],"id":40612296},{"atl":[[2.02,4.05],[2.04,43.26]],"id":42845264}],"con":true,"img":false}]}
{"op":"mcm","clk":"5346784140","pt":1646096933779,"mc":[{"id":"1.195395453","rc":[{"atl":[[34,0]],"id":40612296},{"atl":[[2.04,0]],"id":42845264}],"con":true,"img":false}]}
{"op":"mcm","clk":"5346784145","pt":1646096933882,"mc":[{"id":"1.195395453","rc":[{"atl":[[28,6.4]],"id":40612296},{"atl":[[1.93,43.26]],"id":42845264}],"con":true,"img":false}]}
{"op":"mcm","clk":"5346786739","pt":1646096997611,"mc":[{"id":"1.195395453","rc":[{"spn":1.59,"spf":1.0,"id":42845264},{"atl":[[70,1.91],[75,2]],"id":43154432}],"con":true,"img":false}]}
{"op":"mcm","clk":"5346786749","pt":1646096997915,"mc":[{"id":"1.195395453","rc":[{"atl":[[2.02,0]],"id":42845264}],"con":true,"img":false}]}
{"op":"mcm","clk":"5346788643","pt":1646097051687,"mc":[{"id":"1.195395453","rc":[{"atl":[[130,0]],"id":43154432}],"con":true,"img":false}]}
{"op":"mcm","clk":"5346788646","pt":1646097051786,"mc":[{"id":"1.195395453","rc":[{"atl":[[70,4.61]],"id":43154432}],"con":true,"img":false}]}
{"op":"mcm","clk":"5346792891","pt":1646097163753,"mc":[{"id":"1.195395453","rc":[{"atl":[[70,6.61],[75,0]],"id":43154432},{"atl":[[570,2],[670,0]],"id":39586887}],"con":true,"img":false}]}
{"op":"mcm","clk":"5346792912","pt":1646097164369,"mc":[{"id":"1.195395453","rc":[{"atl":[[28,3.7]],"id":40612296},{"atl":[[1.93,0]],"id":42845264}],"con":true,"img":false}]}
{"op":"mcm","clk":"5346792919","pt":1646097164473,"mc":[{"id":"1.195395453","rc":[{"atl":[[34,2.7]],"id":40612296},{"atl":[[2.02,4.05],[2.04,43.26]],"id":42845264}],"con":true,"img":false}]}
{"op":"mcm","clk":"5346794868","pt":1646097211556,"mc":[{"id":"1.195395453","rc":[{"atl":[[34,0]],"id":40612296},{"atl":[[2.04,0]],"id":42845264}],"con":true,"img":false}]}
{"op":"mcm","clk":"5346794871","pt":1646097211609,"mc":[{"id":"1.195395453","rc":[{"atl":[[28,6.4]],"id":40612296},{"atl":[[1.93,43.26]],"id":42845264}],"con":true,"img":false}]}
{"op":"mcm","clk":"5346796244","pt":1646097245575,"mc":[{"id":"1.195395453","rc":[{"atb":[[10.5,27.61],[15.5,8.39]],"id":39586887}],"con":true,"img":false}]}
{"op":"mcm","clk":"5346798512","pt":1646097303618,"mc":[{"id":"1.195395453","rc":[{"atb":[[10.5,5.26],[11.5,17.35],[9.4,14.88],[9.8,8.52]],"id":37076607},{"atb":[[6.4,9.26],[5.8,26.04],[6,39.33],[6.8,3.45]],"id":40612296},{"atl":[[32,2.42],[36,3.57],[27,1],[29,6.51]],"id":40612296},{"atb":[[10,13.89],[11,7.5],[12,15.9],[13,1.67]],"id":40324412},{"atl":[[260,1],[280,1],[220,1],[240,1]],"id":40324412},{"atb":[[4.3,37.88],[4.9,7.13],[4.5,21.43],[4.7,13.51]],"id":43066392},{"atl":[[17,1.25],[18,11.52],[19,4.17],[20,6.58]],"id":43066392},{"atb":[[1.15,250],[1.21,780.33],[1.19,250],[1.17,727.22]],"id":42845264},{"atl":[[1.84,148.81],[1.78,25.64],[1.8,62.5],[1.82,91.46]],"id":42845264},{"atb":[[9,2.5],[8.2,10.42],[7.8,18.38],[8.6,6.58]],"id":43154432},{"atl":[[170,1],[190,2.04],[210,1],[230,1]],"id":43154432},{"atb":[[10,2.22],[9.2,9.15],[9.6,5.81],[8.8,16.03]],"id":39586887},{"atl":[[750,1],[770,1],[790,1],[810,1]],"id":39586887}],"con":true,"img":false}]}
{"op":"mcm","clk":"5346798514","pt":1646097303674,"mc":[{"id":"1.195395453","rc":[{"atb":[[8,17.86],[9.2,2.44],[8.4,10.14],[8.8,19.23]],"id":42901530},{"atl":[[360,1],[380,1],[400,1],[420,1]],"id":42901530},{"atl":[[1.83,90.36],[1.85,147.06],[1.79,25.32],[1.81,61.73]],"id":42845264}],"con":true,"img":false}]}
{"op":"mcm","clk":"5346798518","pt":1646097303775,"mc":[{"id":"1.195395453","rc":[{"atl":[[17,7.5],[18,5.64]],"id":43066392},{"atl":[[2.02,0]],"id":42845264}],"con":true,"img":false}]}
{"op":"mcm","clk":"5346798631","pt":1646097306183,"mc":[{"id":"1.195395453","rc":[{"spn":17.5,"spf":1.0,"id":40612296},{"spn":11.5,"spf":1.0,"id":43066392},{"atl":[[1.83,0],[1.85,0],[1.79,0],[1.81,0]],"id":42845264},{"spn":1.51,"spf":1.0,"id":42845264}],"con":true,"img":false}]}
{"op":"mcm","clk":"5346798743","pt":1646097308901,"mc":[{"id":"1.195395453","rc":[{"atl":[[17,1.25],[18,11.52]],"id":43066392}],"con":true,"img":false}]}
{"op":"mcm","clk":"5346798950","pt":1646097314288,"mc":[{"id":"1.195395453","rc":[{"atl":[[1.79,25.32]],"id":42845264}],"con":true,"img":false}]}
{"op":"mcm","clk":"5346798953","pt":1646097314399,"mc":[{"id":"1.195395453","rc":[{"atl":[[1.78,0]],"id":42845264}],"con":true,"img":false}]}
{"op":"mcm","clk":"5346799002","pt":1646097315723,"mc":[{"id":"1.195395453","rc":[{"atl":[[1.78,25.64],[1.79,0]],"id":42845264}],"con":true,"img":false}]}
{"op":"mcm","clk":"5346799202","pt":1646097321221,"mc":[{"id":"1.195395453","rc":[{"atl":[[160,0.83]],"id":37076607},{"atl":[[150,0]],"id":42901530},{"atl":[[65,0],[70,3.91]],"id":43154432}],"con":true,"img":false}]}
{"op":"mcm","clk":"5346799209","pt":1646097321313,"mc":[{"id":"1.195395453","rc":[{"atl":[[180,0.27]],"id":37076607},{"atl":[[160,1.1]],"id":42901530},{"atl":[[75,0.62],[150,2.7]],"id":43154432}],"con":true,"img":false}]}
{"op":"mcm","clk":"5346799330","pt":1646097324441,"mc":[{"id":"1.195395453","rc":[{"atl":[[360,0],[440,1]],"id":42901530}],"con":true,"img":false}]}
{"op":"mcm","clk":"5346799429","pt":1646097326702,"mc":[{"id":"1.195395453","rc":[{"atl":[[1.78,0],[1.79,25.32]],"id":42845264}],"con":true,"img":false}]}
{"op":"mcm","clk":"5346799430","pt":1646097326804,"mc":[{"id":"1.195395453","rc":[{"atl":[[380,0]],"id":42901530}],"con":true,"img":false}]}
{"op":"mcm","clk":"5346799478","pt":1646097327734,"mc":[{"id":"1.195395453","rc":[{"atl":[[400,0]],"id":42901530},{"atl":[[1.78,25.64],[1.79,0]],"id":42845264}],"con":true,"img":false}]}
{"op":"mcm","clk":"5346799484","pt":1646097327832,"mc":[{"id":"1.195395453","rc":[{"atb":[[27,2.7]],"id":42901530}],"con":true,"img":false}]}
{"op":"mcm","clk":"5346799495","pt":1646097328039,"mc":[{"id":"1.195395453","rc":[{"atb":[[32,0.33]],"id":42901530}],"con":true,"img":false}]}
{"op":"mcm","clk":"5346799637","pt":1646097331325,"mc":[{"id":"1.195395453","rc":[{"atl":[[1.93,0]],"id":42845264}],"con":true,"img":false}]}
{"op":"mcm","clk":"5346799643","pt":1646097331427,"mc":[{"id":"1.195395453","rc":[{"atl":[[1.83,43.26]],"id":42845264}],"con":true,"img":false}]}
{"op":"mcm","clk":"5346799749","pt":1646097334449,"mc":[{"id":"1.195395453","rc":[{"atl":[[420,0],[460,1]],"id":42901530}],"con":true,"img":false}]}
{"op":"mcm","clk":"5346799920","pt":1646097338814,"mc":[{"id":"1.195395453","rc":[{"atl":[[1.78,0],[1.79,25.32]],"id":42845264}],"con":true,"img":false}]}
{"op":"mcm","clk":"5346799982","pt":1646097340249,"mc":[{"id":"1.195395453","rc":[{"atl":[[1.78,25.64],[1.79,0]],"id":42845264}],"con":true,"img":false}]}
{"op":"mcm","clk":"5346800028","pt":1646097341325,"mc":[{"id":"1.195395453","rc":[{"atb":[[28,0]],"id":37076607}],"con":true,"img":false}]}
{"op":"mcm","clk":"5346800036","pt":1646097341430,"mc":[{"id":"1.195395453","rc":[{"atb":[[29,2.7]],"id":37076607}],"con":true,"img":false}]}
{"op":"mcm","clk":"5346800138","pt":1646097344452,"mc":[{"id":"1.195395453","rc":[{"atl":[[480,1]],"id":42901530}],"con":true,"img":false}]}
{"op":"mcm","clk":"5346800400","pt":1646097351237,"mc":[{"id":"1.195395453","rc":[{"atl":[[36,7.35],[46,0]],"id":40612296},{"atb":[[4.8,32.09],[4.1,0]],"id":43066392},{"atl":[[1.78,0],[1.79,25.32]],"id":42845264}],"con":true,"img":false}]}
{"op":"mcm","clk":"5346800406","pt":1646097351341,"mc":[{"id":"1.195395453","rc":[{"atb":[[6.2,0]],"id":40612296},{"atb":[[12,4.55]],"id":40324412}],"con":true,"img":false}]}
{"op":"mcm","clk":"5346800411","pt":1646097351444,"mc":[{"id":"1.195395453","rc":[{"atb":[[6.6,24.87]],"id":40612296},{"atl":[[36,3.57]],"id":40612296},{"atb":[[13.5,11.35]],"id":40324412}],"con":true,"img":false}]}
{"op":"mcm","clk":"5346800416","pt":1646097351544,"mc":[{"id":"1.195395453","rc":[{"atl":[[44,3.78]],"id":40612296}],"con":true,"img":false}]}
{"op":"mcm","clk":"5346800431","pt":1646097351852,"mc":[{"id":"1.195395453","rc":[{"atl":[[1.78,25.64]],"id":42845264}],"con":true,"img":false}]}
{"op":"mcm","clk":"5346800435","pt":1646097351957,"mc":[{"id":"1.195395453","rc":[{"atl":[[1.79,0]],"id":42845264}],"con":true,"img":false}]}
{"op":"mcm","clk":"5346800527","pt":1646097354475,"mc":[{"id":"1.195395453","rc":[{"atl":[[500,1]],"id":42901530}],"con":true,"img":false}]}
{"op":"mcm","clk":"5346800857","pt":1646097364180,"mc":[{"id":"1.195395453","rc":[{"atl":[[1.79,25.32]],"id":42845264}],"con":true,"img":false}]}
{"op":"mcm","clk":"5346800861","pt":1646097364282,"mc":[{"id":"1.195395453","rc":[{"atl":[[1.78,0]],"id":42845264}],"con":true,"img":false}]}
{"op":"mcm","clk":"5346801241","pt":1646097374201,"mc":[{"id":"1.195395453","rc":[{"spn":28.07,"spf":1.0,"id":37076607},{"spn":66.0,"spf":1.0,"id":42901530},{"atl":[[1.78,25.64],[1.79,0]],"id":42845264},{"spn":41.75,"spf":1.0,"id":43154432}],"con":true,"img":false}]}
{"op":"mcm","clk":"5346801286","pt":1646097375689,"mc":[{"id":"1.195395453","rc":[{"atl":[[1.78,0],[1.79,25.32]],"id":42845264}],"con":true,"img":false}]}
{"op":"mcm","clk":"5346801318","pt":1646097376713,"mc":[{"id":"1.195395453","rc":[{"atl":[[1.78,25.64],[1.79,0]],"id":42845264}],"con":true,"img":false}]}
{"op":"mcm","clk":"5346801702","pt":1646097387503,"mc":[{"id":"1.195395453","rc":[{"atl":[[1.78,0],[1.79,25.32]],"id":42845264}],"con":true,"img":false}]}
{"op":"mcm","clk":"5346801752","pt":1646097388732,"mc":[{"id":"1.195395453","rc":[{"atl":[[1.78,25.64],[1.79,0]],"id":42845264}],"con":true,"img":false}]}
{"op":"mcm","clk":"5346802163","pt":1646097399725,"mc":[{"id":"1.195395453","rc":[{"atl":[[1.78,0],[1.79,25.32]],"id":42845264}],"con":true,"img":false}]}
{"op":"mcm","clk":"5346802231","pt":1646097401219,"mc":[{"id":"1.195395453","rc":[{"atl":[[44,0]],"id":40612296},{"atl":[[1.78,25.64],[1.79,0]],"id":42845264}],"con":true,"img":false}]}
{"op":"mcm","clk":"5346802236","pt":1646097401320,"mc":[{"id":"1.195395453","rc":[{"atl":[[36,7.35]],"id":40612296}],"con":true,"img":false}]}
{"op":"mcm","clk":"5346802645","pt":1646097411827,"mc":[{"id":"1.195395453","rc":[{"atl":[[1.78,0],[1.79,25.32]],"id":42845264}],"con":true,"img":false}]}
{"op":"mcm","clk":"5346802696","pt":1646097413669,"mc":[{"id":"1.195395453","rc":[{"atl":[[1.78,25.64],[1.79,0]],"id":42845264}],"con":true,"img":false}]}
{"op":"mcm","clk":"5346803091","pt":1646097424254,"mc":[{"id":"1.195395453","rc":[{"atl":[[1.78,0],[1.79,25.32]],"id":42845264}],"con":true,"img":false}]}
{"op":"mcm","clk":"5346803136","pt":1646097424869,"mc":[{"id":"1.195395453","rc":[{"atl":[[1.78,25.64],[1.79,0]],"id":42845264}],"con":true,"img":false}]}
{"op":"mcm","clk":"5346803975","pt":1646097448815,"mc":[{"id":"1.195395453","rc":[{"atl":[[1.78,0],[1.79,25.32]],"id":42845264},{"spn":1.52,"spf":1.0,"id":42845264}],"con":true,"img":false}]}
{"op":"mcm","clk":"5346803999","pt":1646097449431,"mc":[{"id":"1.195395453","rc":[{"atl":[[1.78,25.64]],"id":42845264}],"con":true,"img":false}]}
{"op":"mcm","clk":"5346804002","pt":1646097449483,"mc":[{"id":"1.195395453","rc":[{"atl":[[1.79,0]],"id":42845264}],"con":true,"img":false}]}
{"op":"mcm","clk":"5346804425","pt":1646097460438,"mc":[{"id":"1.195395453","rc":[{"atl":[[1.79,25.32]],"id":42845264}],"con":true,"img":false}]}
{"op":"mcm","clk":"5346804429","pt":1646097460537,"mc":[{"id":"1.195395453","rc":[{"atl":[[1.78,0]],"id":42845264}],"con":true,"img":false}]}
{"op":"mcm","clk":"5346804480","pt":1646097462234,"mc":[{"id":"1.195395453","rc":[{"atl":[[1.78,25.64],[1.79,0]],"id":42845264}],"con":true,"img":false}]}
{"op":"mcm","clk":"5346804850","pt":1646097472856,"mc":[{"id":"1.195395453","rc":[{"atl":[[1.78,0],[1.79,25.32]],"id":42845264}],"con":true,"img":false}]}
{"op":"mcm","clk":"5346804920","pt":1646097474651,"mc":[{"id":"1.195395453","rc":[{"atl":[[1.78,25.64],[1.79,0]],"id":42845264}],"con":true,"img":false}]}
{"op":"mcm","clk":"5346805285","pt":1646097484877,"mc":[{"id":"1.195395453","rc":[{"atl":[[1.78,0],[1.79,25.32]],"id":42845264}],"con":true,"img":false}]}
{"op":"mcm","clk":"5346805377","pt":1646097487242,"mc":[{"id":"1.195395453","rc":[{"atl":[[1.78,25.64],[1.79,0]],"id":42845264}],"con":true,"img":false}]}
{"op":"mcm","clk":"5346805751","pt":1646097496794,"mc":[{"id":"1.195395453","rc":[{"atl":[[1.78,0]],"id":42845264}],"con":true,"img":false}]}
{"op":"mcm","clk":"5346805755","pt":1646097496898,"mc":[{"id":"1.195395453","rc":[{"atl":[[1.79,25.32]],"id":42845264}],"con":true,"img":false}]}
{"op":"mcm","clk":"5346805895","pt":1646097499885,"mc":[{"id":"1.195395453","rc":[{"atl":[[1.78,25.64],[1.79,0]],"id":42845264}],"con":true,"img":false}]}
{"op":"mcm","clk":"5346806248","pt":1646097509186,"mc":[{"id":"1.195395453","rc":[{"atl":[[1.78,0],[1.79,25.32]],"id":42845264}],"con":true,"img":false}]}
{"op":"mcm","clk":"5346806332","pt":1646097511395,"mc":[{"id":"1.195395453","rc":[{"atl":[[1.78,25.64],[1.79,0]],"id":42845264}],"con":true,"img":false}]}
{"op":"mcm","clk":"5346807161","pt":1646097534742,"mc":[{"id":"1.195395453","rc":[{"atl":[[1.78,0],[1.8,25]],"id":42845264},{"atl":[[750,0],[740,1]],"id":39586887}],"con":true,"img":false}]}
{"op":"mcm","clk":"5346807442","pt":1646097544745,"mc":[{"id":"1.195395453","rc":[{"atl":[[1.82,60.98]],"id":42845264}],"con":true,"img":false}]}
{"op":"mcm","clk":"5346807714","pt":1646097554753,"mc":[{"id":"1.195395453","rc":[{"atl":[[1.84,89.29]],"id":42845264}],"con":true,"img":false}]}
{"op":"mcm","clk":"5346808046","pt":1646097564813,"mc":[{"id":"1.195395453","rc":[{"atl":[[1.86,145.35]],"id":42845264}],"con":true,"img":false}]}
{"op":"mcm","clk":"5346811093","pt":1646097655623,"mc":[{"id":"1.195395453","rc":[{"atl":[[1.94,0]],"id":42845264},{"spn":1.52,"spf":1.0,"id":42845264}],"con":true,"img":false}]}
{"op":"mcm","clk":"5346813226","pt":1646097713813,"mc":[{"id":"1.195395453","rc":[{"atb":[[3.6,38.46],[3.35,0]],"id":43066392},{"atl":[[1.78,25.64],[1.8,0]],"id":42845264},{"atl":[[740,0],[750,1]],"id":39586887}],"con":true,"img":false}]}
{"op":"mcm","clk":"5346813594","pt":1646097723824,"mc":[{"id":"1.195395453","rc":[{"atl":[[1.8,62.5]],"id":42845264},{"spn":1.51,"spf":1.0,"id":42845264}],"con":true,"img":false}]}
{"op":"mcm","clk":"5346813827","pt":1646097730436,"mc":[{"id":"1.195395453","rc":[{"atl":[[1.86,0]],"id":42845264}],"con":true,"img":false}]}
{"op":"mcm","clk":"5346813939","pt":1646097733869,"mc":[{"id":"1.195395453","rc":[{"atl":[[1.82,91.46]],"id":42845264}],"con":true,"img":false}]}
{"op":"mcm","clk":"5346814278","pt":1646097743863,"mc":[{"id":"1.195395453","rc":[{"atl":[[1.84,148.81]],"id":42845264}],"con":true,"img":false}]}
{"op":"mcm","clk":"5346814597","pt":1646097752988,"mc":[{"id":"1.195395453","rc":[{"atb":[[7.4,3.53]],"id":40612296},{"atb":[[5.7,4.81]],"id":43066392},{"atb":[[1.24,31.68]],"id":42845264}],"con":true,"img":false}]}
{"op":"mcm","clk":"5346815297","pt":1646097774129,"mc":[{"id":"1.195395453","rc":[{"atl":[[1.78,0],[1.77,25.97]],"id":42845264}],"con":true,"img":false}]}
{"op":"mcm","clk":"5346815353","pt":1646097775417,"mc":[{"id":"1.195395453","rc":[{"atl":[[1.78,25.64],[1.77,0]],"id":42845264}],"con":true,"img":false}]}
{"op":"mcm","clk":"5346815455","pt":1646097778701,"mc":[{"id":"1.195395453","rc":[{"atl":[[1.78,0],[1.77,25.97]],"id":42845264}],"con":true,"img":false}]}
{"op":"mcm","clk":"5346815546","pt":1646097781212,"mc":[{"id":"1.195395453","rc":[{"atb":[[1.23,0]],"id":42845264}],"con":true,"img":false}]}
{"op":"mcm","clk":"5346815548","pt":1646097781315,"mc":[{"id":"1.195395453","rc":[{"atb":[[1.25,45.26]],"id":42845264}],"con":true,"img":false}]}
{"op":"mcm","clk":"5346815741","pt":1646097786609,"mc":[{"id":"1.195395453","rc":[{"atb":[[1.24,0]],"id":42845264},{"spn":1.51,"spf":1.0,"id":42845264}],"con":true,"img":false}]}
{"op":"mcm","clk":"5346815789","pt":1646097787739,"mc":[{"id":"1.195395453","rc":[{"atl":[[1.78,25.64],[1.77,0]],"id":42845264}],"con":true,"img":false}]}
{"op":"mcm","clk":"5346815893","pt":1646097791238,"mc":[{"id":"1.195395453","rc":[{"atb":[[1.25,2]],"id":42845264},{"atl":[[1.78,0],[1.77,25.97]],"id":42845264}],"con":true,"img":false}]}
{"op":"mcm","clk":"5346815897","pt":1646097791346,"mc":[{"id":"1.195395453","rc":[{"atb":[[1.23,43.26]],"id":42845264}],"con":true,"img":false}]}
{"op":"mcm","clk":"5346815916","pt":1646097791753,"mc":[{"id":"1.195395453","rc":[{"atb":[[1.26,31.68]],"id":42845264}],"con":true,"img":false}]}
{"op":"mcm","clk":"5346816187","pt":1646097799140,"mc":[{"id":"1.195395453","rc":[{"atl":[[1.78,25.64],[1.77,0]],"id":42845264}],"con":true,"img":false}]}
{"op":"mcm","clk":"5346816292","pt":1646097802268,"mc":[{"id":"1.195395453","rc":[{"atb":[[1.26,0]],"id":42845264}],"con":true,"img":false}]}
{"op":"mcm","clk":"5346816341","pt":1646097803758,"mc":[{"id":"1.195395453","rc":[{"atl":[[1.78,0],[1.77,25.97]],"id":42845264}],"con":true,"img":false}]}
{"op":"mcm","clk":"5346816485","pt":1646097807867,"mc":[{"id":"1.195395453","rc":[{"atb":[[1.24,31.68]],"id":42845264}],"con":true,"img":false}]}
{"op":"mcm","clk":"5346816586","pt":1646097810382,"mc":[{"id":"1.195395453","rc":[{"atl":[[1.78,25.64],[1.77,0]],"id":42845264}],"con":true,"img":false}]}
{"op":"mcm","clk":"5346816830","pt":1646097815669,"mc":[{"id":"1.195395453","rc":[{"atl":[[1.78,0],[1.77,25.97]],"id":42845264}],"con":true,"img":false}]}
{"op":"mcm","clk":"5346817037","pt":1646097821292,"mc":[{"id":"1.195395453","rc":[{"atb":[[1.23,0]],"id":42845264}],"con":true,"img":false}]}
{"op":"mcm","clk":"5346817041","pt":1646097821397,"mc":[{"id":"1.195395453","rc":[{"atb":[[1.25,45.26]],"id":42845264}],"con":true,"img":false}]}
{"op":"mcm","clk":"5346817204","pt":1646097826282,"mc":[{"id":"1.195395453","rc":[{"atb":[[1.24,0]],"id":42845264}],"con":true,"img":false}]}
{"op":"mcm","clk":"5346817409","pt":1646097831306,"mc":[{"id":"1.195395453","rc":[{"atb":[[1.25,2]],"id":42845264}],"con":true,"img":false}]}
{"op":"mcm","clk":"5346817411","pt":1646097831409,"mc":[{"id":"1.195395453","rc":[{"atb":[[1.26,31.68],[1.23,43.26]],"id":42845264}],"con":true,"img":false}]}
{"op":"mcm","clk":"5346817493","pt":1646097834075,"mc":[{"id":"1.195395453","rc":[{"atl":[[1.79,25.32],[1.77,0]],"id":42845264}],"con":true,"img":false}]}
{"op":"mcm","clk":"5346817674","pt":1646097838695,"mc":[{"id":"1.195395453","rc":[{"atb":[[1.26,0]],"id":42845264}],"con":true,"img":false}]}
{"op":"mcm","clk":"5346817871","pt":1646097843729,"mc":[{"id":"1.195395453","rc":[{"atb":[[1.24,31.68]],"id":42845264}],"con":true,"img":false}]}
{"op":"mcm","clk":"5346817885","pt":1646097844141,"mc":[{"id":"1.195395453","rc":[{"atl":[[1.81,61.73]],"id":42845264}],"con":true,"img":false}]}
{"op":"mcm","clk":"5346817976","pt":1646097846502,"mc":[{"id":"1.195395453","rc":[{"atl":[[1.84,0],[1.8,0],[1.82,0]],"id":42845264}],"con":true,"img":false}]}
{"op":"mcm","clk":"5346818179","pt":1646097851329,"mc":[{"id":"1.195395453","rc":[{"atl":[[1.83,0]],"id":42845264},{"spn":1.52,"spf":1.0,"id":42845264}],"con":true,"img":false}]}
{"op":"mcm","clk":"5346818185","pt":1646097851431,"mc":[{"id":"1.195395453","rc":[{"atl":[[2.04,43.26]],"id":42845264}],"con":true,"img":false}]}
{"op":"mcm","clk":"5346818255","pt":1646097853234,"mc":[{"id":"1.195395453","rc":[{"atb":[[9,12.5],[10.5,0],[11,7.2],[11.5,15.45],[9.8,0],[8.8,2.56]],"id":37076607},{"atb":[[8,0],[9.2,0],[8.4,0],[8.8,0],[6.6,21.43]],"id":42901530},{"atl":[[21,1],[27,0]],"id":40612296},{"atl":[[17,0],[12.5,1.74]],"id":43066392},{"atl":[[1.79,0],[1.87,22.99]],"id":42845264},{"atb":[[9,0],[10.5,2.11]],"id":43154432},{"atb":[[8,17.15],[10,0],[9.2,0],[10.5,17.08],[9.6,0],[8.8,0]],"id":39586887}],"con":true,"img":false}]}
{"op":"mcm","clk":"5346818261","pt":1646097853336,"mc":[{"id":"1.195395453","rc":[{"atl":[[16,6.67]],"id":43066392}],"con":true,"img":false}]}
{"op":"mcm","clk":"5346818266","pt":1646097853442,"mc":[{"id":"1.195395453","rc":[{"atl":[[16,0],[17.5,6.06],[18,5.64]],"id":43066392}],"con":true,"img":false}]}
{"op":"mcm","clk":"5346818469","pt":1646097858732,"mc":[{"id":"1.195395453","rc":[{"atb":[[9.4,0]],"id":37076607},{"atl":[[1.81,0]],"id":42845264}],"con":true,"img":false}]}
{"op":"mcm","clk":"5346818474","pt":1646097858835,"mc":[{"id":"1.195395453","rc":[{"atl":[[2.02,4.05]],"id":42845264}],"con":true,"img":false}]}
{"op":"mcm","clk":"5346818670","pt":1646097863268,"mc":[{"id":"1.195395453","rc":[{"atb":[[8.4,6.76]],"id":37076607},{"atb":[[6.2,9.62]],"id":42901530},{"atl":[[23,2.27]],"id":40612296},{"atl":[[13.5,4]],"id":43066392},{"atl":[[1.89,56.18]],"id":42845264},{"atb":[[9.8,14.9]],"id":43154432},{"atb":[[7.6,7.58]],"id":39586887}],"con":true,"img":false}]}
{"op":"mcm","clk":"5346818785","pt":1646097866041,"mc":[{"id":"1.195395453","rc":[{"atl":[[36,3.78]],"id":40612296},{"atl":[[18,2.7],[19,0],[20,0]],"id":43066392},{"atb":[[7.8,0]],"id":43154432}],"con":true,"img":false}]}
{"op":"mcm","clk":"5346819010","pt":1646097871280,"mc":[{"id":"1.195395453","rc":[{"atl":[[46,2.7]],"id":40612296},{"atb":[[1.23,0]],"id":42845264}],"con":true,"img":false}]}
{"op":"mcm","clk":"5346819013","pt":1646097871332,"mc":[{"id":"1.195395453","rc":[{"atl":[[36,0]],"id":40612296},{"atb":[[1.25,45.26]],"id":42845264},{"atl":[[75,0]],"id":43154432}],"con":true,"img":false}]}
{"op":"mcm","clk":"5346819016","pt":1646097871433,"mc":[{"id":"1.195395453","rc":[{"atl":[[65,0.62]],"id":43154432}],"con":true,"img":false}]}
{"op":"mcm","clk":"5346819079","pt":1646097873281,"mc":[{"id":"1.195395453","rc":[{"atb":[[8,10.71]],"id":37076607},{"atb":[[5.9,15.31]],"id":42901530},{"atl":[[25,3.12]],"id":40612296},{"atl":[[14.5,5.56]],"id":43066392},{"atl":[[1.91,82.42]],"id":42845264},{"atb":[[9.4,8.93]],"id":43154432},{"atb":[[7.2,12.1]],"id":39586887}],"con":true,"img":false}]}
{"op":"mcm","clk":"5346819082","pt":1646097873383,"mc":[{"id":"1.195395453","rc":[{"atl":[[25,7.29],[28,2.7]],"id":40612296},{"atl":[[16,6.06],[17.5,0]],"id":43066392}],"con":true,"img":false}]}
{"op":"mcm","clk":"5346819204","pt":1646097876472,"mc":[{"id":"1.195395453","rc":[{"atb":[[1.24,0]],"id":42845264}],"con":true,"img":false}]}
{"op":"mcm","clk":"5346819231","pt":1646097877086,"mc":[{"id":"1.195395453","rc":[{"atl":[[32,0]],"id":40612296},{"atb":[[8.2,0]],"id":43154432}],"con":true,"img":false}]}
{"op":"mcm","clk":"5346819265","pt":1646097877857,"mc":[{"id":"1.195395453","rc":[{"atb":[[6.4,12.96]],"id":40612296}],"con":true,"img":false}]}
{"op":"mcm","clk":"5346819269","pt":1646097877959,"mc":[{"id":"1.195395453","rc":[{"atl":[[440,0]],"id":42901530},{"atb":[[6.4,3.7],[6.8,0]],"id":40612296},{"atl":[[170,0],[180,1]],"id":43154432}],"con":true,"img":false}]}
{"op":"mcm","clk":"5346819400","pt":1646097881258,"mc":[{"id":"1.195395453","rc":[{"atl":[[170,2]],"id":42901530},{"atb":[[6.6,0]],"id":40612296},{"atl":[[90,1.48]],"id":40324412},{"atb":[[4.8,0]],"id":43066392},{"atb":[[1.25,2]],"id":42845264},{"atl":[[2.04,0]],"id":42845264},{"atl":[[150,0]],"id":43154432},{"atl":[[140,0]],"id":39586887}],"con":true,"img":false}]}
{"op":"mcm","clk":"5346819404","pt":1646097881361,"mc":[{"id":"1.195395453","rc":[{"atl":[[250,2.7]],"id":42901530},{"atb":[[6.2,24.87]],"id":40612296},{"atl":[[100,0.48]],"id":40324412},{"atb":[[4.6,32.09]],"id":43066392},{"atb":[[1.23,43.26]],"id":42845264},{"atl":[[1.86,43.26]],"id":42845264},{"atl":[[130,2.7]],"id":43154432},{"atl":[[160,0.31]],"id":39586887}],"con":true,"img":false}]}
{"op":"mcm","clk":"5346819411","pt":1646097881565,"mc":[{"id":"1.195395453","rc":[{"atb":[[7.6,13.03]],"id":40612296},{"atb":[[14.5,6.85]],"id":40324412},{"atb":[[1.26,67.89]],"id":42845264},{"atb":[[13,7.12]],"id":43154432},{"atb":[[19,5.14]],"id":39586887}],"con":true,"img":false}]}
{"op":"mcm","clk":"5346819429","pt":1646097881977,"mc":[{"id":"1.195395453","rc":[{"atb":[[1.26,99.58]],"id":42845264}],"con":true,"img":false}]}
{"op":"mcm","clk":"5346819495","pt":1646097883264,"mc":[{"id":"1.195395453","rc":[{"atb":[[7.6,18.94]],"id":37076607},{"atb":[[5.7,26.6]],"id":42901530},{"atl":[[520,1]],"id":42901530},{"atl":[[15.5,8.62]],"id":43066392},{"atl":[[1.93,134.41]],"id":42845264},{"atb":[[6.8,21.55]],"id":39586887}],"con":true,"img":false}]}
{"op":"mcm","clk":"5346819540","pt":1646097884606,"mc":[{"id":"1.195395453","rc":[{"atb":[[7.4,0]],"id":40612296}],"con":true,"img":false}]}
{"op":"mcm","clk":"5346819643","pt":1646097887078,"mc":[{"id":"1.195395453","rc":[{"atb":[[7.6,0]],"id":40612296}],"con":true,"img":false}]}
{"op":"mcm","clk":"5346819680","pt":1646097887902,"mc":[{"id":"1.195395453","rc":[{"atb":[[6,34.33]],"id":40612296},{"atl":[[27,4.81]],"id":40612296},{"atb":[[9,15.62]],"id":43154432},{"atl":[[200,1]],"id":43154432}],"con":true,"img":false}]}
{"op":"mcm","clk":"5346819718","pt":1646097888673,"mc":[{"id":"1.195395453","rc":[{"atl":[[29,4.72]],"id":40612296},{"atb":[[8.6,0]],"id":43154432},{"atl":[[190,1.04],[210,0],[230,0]],"id":43154432}],"con":true,"img":false}]}
{"op":"mcm","clk":"5346819768","pt":1646097890265,"mc":[{"id":"1.195395453","rc":[{"atb":[[7.4,3.53]],"id":40612296}],"con":true,"img":false}]}
{"op":"mcm","clk":"5346819785","pt":1646097890886,"mc":[{"id":"1.195395453","rc":[{"atb":[[7.4,17.99]],"id":40612296}],"con":true,"img":false}]}
{"op":"mcm","clk":"5346819801","pt":1646097891296,"mc":[{"id":"1.195395453","rc":[{"atl":[[18,0]],"id":43066392},{"atl":[[1.86,0]],"id":42845264},{"atl":[[65,0]],"id":43154432}],"con":true,"img":false}]}
{"op":"mcm","clk":"5346819804","pt":1646097891399,"mc":[{"id":"1.195395453","rc":[{"atl":[[21,2.7]],"id":43066392},{"atl":[[1.88,43.26]],"id":42845264},{"atl":[[75,0.62]],"id":43154432}],"con":true,"img":false}]}
{"op":"mcm","clk":"5346819957","pt":1646097894512,"mc":[{"id":"1.195395453","rc":[{"atl":[[750,0],[740,1]],"id":39586887}],"con":true,"img":false}]}
{"op":"mcm","clk":"5346819982","pt":1646097895282,"mc":[{"id":"1.195395453","rc":[{"atb":[[1.26,67.89]],"id":42845264}],"con":true,"img":false}]}
{"op":"mcm","clk":"5346820086","pt":1646097897905,"mc":[{"id":"1.195395453","rc":[{"atb":[[5.8,15.62]],"id":40612296}],"con":true,"img":false}]}
{"op":"mcm","clk":"5346820090","pt":1646097898007,"mc":[{"id":"1.195395453","rc":[{"atl":[[220,1]],"id":43154432}],"con":true,"img":false}]}
{"op":"mcm","clk":"5346820215","pt":1646097900995,"mc":[{"id":"1.195395453","rc":[{"atb":[[1.27,47.53]],"id":42845264}],"con":true,"img":false}]}
{"op":"mcm","clk":"5346820222","pt":1646097901201,"mc":[{"id":"1.195395453","rc":[{"atb":[[10,0]],"id":43154432}],"con":true,"img":false}]}
{"op":"mcm","clk":"5346820226","pt":1646097901306,"mc":[{"id":"1.195395453","rc":[{"atb":[[11,13.46]],"id":43154432}],"con":true,"img":false}]}
{"op":"mcm","clk":"5346820240","pt":1646097901616,"mc":[{"id":"1.195395453","rc":[{"atb":[[1.27,149.37]],"id":42845264}],"con":true,"img":false}]}
{"op":"mcm","clk":"5346820322","pt":1646097903730,"mc":[{"id":"1.195395453","rc":[{"atl":[[1.85,9.74]],"id":42845264}],"con":true,"img":false}]}
{"op":"mcm","clk":"5346820341","pt":1646097904196,"mc":[{"id":"1.195395453","rc":[{"atl":[[1.86,9.87]],"id":42845264}],"con":true,"img":false}]}
{"op":"mcm","clk":"5346820392","pt":1646097905327,"mc":[{"id":"1.195395453","rc":[{"atb":[[1.27,47.53],[1.26,0]],"id":42845264}],"con":true,"img":false}]}
{"op":"mcm","clk":"5346820445","pt":1646097906513,"mc":[{"id":"1.195395453","rc":[{"atl":[[740,0],[750,1]],"id":39586887}],"con":true,"img":false}]}
{"op":"mcm","clk":"5346820515","pt":1646097907909,"mc":[{"id":"1.195395453","rc":[{"atb":[[5.6,27.17]],"id":40612296},{"atl":[[240,1]],"id":43154432}],"con":true,"img":false}]}
{"op":"mcm","clk":"5346820557","pt":1646097908726,"mc":[{"id":"1.195395453","rc":[{"atb":[[1.27,0]],"id":42845264}],"con":true,"img":false}]}
{"op":"mcm","clk":"5346820580","pt":1646097909239,"mc":[{"id":"1.195395453","rc":[{"atb":[[1.24,118.82]],"id":42845264}],"con":true,"img":false}]}
{"op":"mcm","clk":"5346820676","pt":1646097911244,"mc":[{"id":"1.195395453","rc":[{"atb":[[11,0]],"id":43154432}],"con":true,"img":false}]}
{"op":"mcm","clk":"5346820682","pt":1646097911295,"mc":[{"id":"1.195395453","rc":[{"atb":[[10,13.46]],"id":43154432}],"con":true,"img":false}]}
{"op":"mcm","clk":"5346820715","pt":1646097912219,"mc":[{"id":"1.195395453","rc":[{"spn":14.5,"spf":1.0,"id":40612296},{"spn":9.25,"spf":1.0,"id":43066392},{"spn":1.55,"spf":1.0,"id":42845264},{"atl":[[750,0],[740,1]],"id":39586887}],"con":true,"img":false}]}
{"op":"mcm","clk":"5346820786","pt":1646097914012,"mc":[{"id":"1.195395453","rc":[{"atb":[[1.25,86.57]],"id":42845264}],"con":true,"img":false}]}
{"op":"mcm","clk":"5346820850","pt":1646097915605,"mc":[{"id":"1.195395453","rc":[{"atb":[[12.5,0]],"id":43154432}],"con":true,"img":false}]}
{"op":"mcm","clk":"5346820856","pt":1646097915708,"mc":[{"id":"1.195395453","rc":[{"atb":[[13.5,4.74]],"id":43154432}],"con":true,"img":false}]}
{"op":"mcm","clk":"5346820960","pt":1646097918536,"mc":[{"id":"1.195395453","rc":[{"atb":[[13,0]],"id":43154432}],"con":true,"img":false}]}
{"op":"mcm","clk":"5346820982","pt":1646097919255,"mc":[{"id":"1.195395453","rc":[{"atl":[[740,0],[750,1]],"id":39586887}],"con":true,"img":false}]}
{"op":"mcm","clk":"5346821057","pt":1646097921260,"mc":[{"id":"1.195395453","rc":[{"atb":[[1.23,0]],"id":42845264},{"atb":[[13.5,0.81]],"id":43154432}],"con":true,"img":false}]}
{"op":"mcm","clk":"5346821062","pt":1646097921312,"mc":[{"id":"1.195395453","rc":[{"atb":[[1.25,129.84]],"id":42845264},{"atb":[[12,7.62]],"id":43154432}],"con":true,"img":false}]}
{"op":"mcm","clk":"5346821101","pt":1646097922341,"mc":[{"id":"1.195395453","rc":[{"atb":[[12.5,8.04]],"id":43154432}],"con":true,"img":false}]}
{"op":"mcm","clk":"5346821172","pt":1646097924039,"mc":[{"id":"1.195395453","rc":[{"atl":[[750,0],[740,1]],"id":39586887}],"con":true,"img":false}]}
{"op":"mcm","clk":"5346821181","pt":1646097924244,"mc":[{"id":"1.195395453","rc":[{"atb":[[1.24,0]],"id":42845264},{"atl":[[2.02,0]],"id":42845264}],"con":true,"img":false}]}
{"op":"mcm","clk":"5346821320","pt":1646097927332,"mc":[{"id":"1.195395453","rc":[{"atb":[[13.5,0],[15,8.65]],"id":40324412},{"atb":[[18.5,0]],"id":39586887}],"con":true,"img":false}]}
{"op":"mcm","clk":"5346821324","pt":1646097927433,"mc":[{"id":"1.195395453","rc":[{"atb":[[19.5,6.5]],"id":39586887}],"con":true,"img":false}]}
{"op":"mcm","clk":"5346821341","pt":1646097928049,"mc":[{"id":"1.195395453","rc":[{"atb":[[1.26,194.76]],"id":42845264}],"con":true,"img":false}]}
{"op":"mcm","clk":"5346821383","pt":1646097928923,"mc":[{"id":"1.195395453","rc":[{"atb":[[1.25,45.26]],"id":42845264}],"con":true,"img":false}]}
{"op":"mcm","clk":"5346821424","pt":1646097929846,"mc":[{"id":"1.195395453","rc":[{"atb":[[14.5,0]],"id":40324412},{"atb":[[19,0]],"id":39586887}],"con":true,"img":false}]}
{"op":"mcm","clk":"5346821473","pt":1646097931239,"mc":[{"id":"1.195395453","rc":[{"atb":[[12.5,10.81]],"id":40324412},{"atb":[[19.5,0]],"id":39586887}],"con":true,"img":false}]}
{"op":"mcm","clk":"5346821477","pt":1646097931341,"mc":[{"id":"1.195395453","rc":[{"atb":[[15,0]],"id":40324412},{"atb":[[18.5,6.5]],"id":39586887}],"con":true,"img":false}]}
{"op":"mcm","clk":"5346821552","pt":1646097934169,"mc":[{"id":"1.195395453","rc":[{"atb":[[1.23,98.31]],"id":42845264}],"con":true,"img":false}]}
{"op":"mcm","clk":"5346821605","pt":1646097935453,"mc":[{"id":"1.195395453","rc":[{"atb":[[14.5,6.85]],"id":40324412},{"atb":[[19,5.14]],"id":39586887}],"con":true,"img":false}]}
{"op":"mcm","clk":"5346821802","pt":1646097941381,"mc":[{"id":"1.195395453","rc":[{"atb":[[1.25,2]],"id":42845264}],"con":true,"img":false}]}
{"op":"mcm","clk":"5346821806","pt":1646097941484,"mc":[{"id":"1.195395453","rc":[{"atb":[[1.24,43.26]],"id":42845264}],"con":true,"img":false}]}
{"op":"mcm","clk":"5346821877","pt":1646097943548,"mc":[{"id":"1.195395453","rc":[{"atb":[[4.3,0],[3.85,35.09]],"id":40612296},{"atl":[[16,0],[17.5,6.06]],"id":43066392},{"atl":[[740,0],[760,1]],"id":39586887}],"con":true,"img":false}]}
{"op":"mcm","clk":"5346821882","pt":1646097943653,"mc":[{"id":"1.195395453","rc":[{"atb":[[7,13.52]],"id":40612296}],"con":true,"img":false}]}
{"op":"mcm","clk":"5346821889","pt":1646097943860,"mc":[{"id":"1.195395453","rc":[{"atb":[[6.8,1.73]],"id":40612296}],"con":true,"img":false}]}
{"op":"mcm","clk":"5346821907","pt":1646097944272,"mc":[{"id":"1.195395453","rc":[{"atb":[[1.23,0]],"id":42845264}],"con":true,"img":false}]}
{"op":"mcm","clk":"5346822015","pt":1646097946582,"mc":[{"id":"1.195395453","rc":[{"atb":[[1.26,0]],"id":42845264}],"con":true,"img":false}]}
{"op":"mcm","clk":"5346822131","pt":1646097949871,"mc":[{"id":"1.195395453","rc":[{"atb":[[1.27,83.75]],"id":42845264}],"con":true,"img":false}]}
{"op":"mcm","clk":"5346822146","pt":1646097950280,"mc":[{"id":"1.195395453","rc":[{"atb":[[1.25,69.89]],"id":42845264}],"con":true,"img":false}]}
{"op":"mcm","clk":"5346822285","pt":1646097953567,"mc":[{"id":"1.195395453","rc":[{"atl":[[780,1]],"id":39586887}],"con":true,"img":false}]}
{"op":"mcm","clk":"5346822302","pt":1646097953977,"mc":[{"id":"1.195395453","rc":[{"atb":[[1.25,2]],"id":42845264}],"con":true,"img":false}]}
{"op":"mcm","clk":"5346822338","pt":1646097955104,"mc":[{"id":"1.195395453","rc":[{"atl":[[220,0],[230,1.86]],"id":40324412},{"atl":[[770,0],[790,0],[810,0]],"id":39586887}],"con":true,"img":false}]}
{"op":"mcm","clk":"5346822443","pt":1646097957778,"mc":[{"id":"1.195395453","rc":[{"atb":[[1.27,0],[1.25,190.44]],"id":42845264}],"con":true,"img":false}]}
{"op":"mcm","clk":"5346822545","pt":1646097960292,"mc":[{"id":"1.195395453","rc":[{"atl":[[220,1]],"id":40324412}],"con":true,"img":false}]}
{"op":"mcm","clk":"5346822554","pt":1646097960394,"mc":[{"id":"1.195395453","rc":[{"atl":[[230,0.86]],"id":40324412}],"con":true,"img":false}]}
{"op":"mcm","clk":"5346822593","pt":1646097961372,"mc":[{"id":"1.195395453","rc":[{"atb":[[1.24,0]],"id":42845264},{"atb":[[12,3.68]],"id":43154432}],"con":true,"img":false}]}
{"op":"mcm","clk":"5346822597","pt":1646097961473,"mc":[{"id":"1.195395453","rc":[{"atb":[[1.23,43.26]],"id":42845264},{"atb":[[13,3.93]],"id":43154432}],"con":true,"img":false}]}
{"op":"mcm","clk":"5346822641","pt":1646097962809,"mc":[{"id":"1.195395453","rc":[{"atb":[[1.26,86.97]],"id":42845264}],"con":true,"img":false}]}
{"op":"mcm","clk":"5346822669","pt":1646097963578,"mc":[{"id":"1.195395453","rc":[{"atl":[[800,1]],"id":39586887}],"con":true,"img":false}]}
{"op":"mcm","clk":"5346822722","pt":1646097965220,"mc":[{"id":"1.195395453","rc":[{"atb":[[1.25,2]],"id":42845264}],"con":true,"img":false}]}
{"op":"mcm","clk":"5346822789","pt":1646097967332,"mc":[{"id":"1.195395453","rc":[{"atl":[[230,1.86]],"id":40324412}],"con":true,"img":false}]}
{"op":"mcm","clk":"5346822792","pt":1646097967385,"mc":[{"id":"1.195395453","rc":[{"atl":[[220,0]],"id":40324412}],"con":true,"img":false}]}
{"op":"mcm","clk":"5346822872","pt":1646097969024,"mc":[{"id":"1.195395453","rc":[{"atb":[[1.27,130.45]],"id":42845264}],"con":true,"img":false}]}
{"op":"mcm","clk":"5346822931","pt":1646097970510,"mc":[{"id":"1.195395453","rc":[{"atb":[[1.26,0]],"id":42845264}],"con":true,"img":false}]}
{"op":"mcm","clk":"5346823021","pt":1646097973229,"mc":[{"id":"1.195395453","rc":[{"atl":[[220,1],[230,0.86]],"id":40324412},{"spn":1.56,"spf":1.0,"id":42845264}],"con":true,"img":false}]}
{"op":"mcm","clk":"5346823037","pt":1646097973587,"mc":[{"id":"1.195395453","rc":[{"atl":[[820,1]],"id":39586887}],"con":true,"img":false}]}
{"op":"mcm","clk":"5346823138","pt":1646097976316,"mc":[{"id":"1.195395453","rc":[{"atb":[[1.24,94.21]],"id":42845264}],"con":true,"img":false}]}
{"op":"mcm","clk":"5346823206","pt":1646097978416,"mc":[{"id":"1.195395453","rc":[{"atb":[[1.27,0]],"id":42845264}],"con":true,"img":false}]}
{"op":"mcm","clk":"5346823241","pt":1646097979799,"mc":[{"id":"1.195395453","rc":[{"atl":[[220,0],[230,1.86]],"id":40324412}],"con":true,"img":false}]}
{"op":"mcm","clk":"5346823309","pt":1646097981242,"mc":[{"id":"1.195395453","rc":[{"atb":[[15,8.65]],"id":40324412}],"con":true,"img":false}]}
{"op":"mcm","clk":"5346823314","pt":1646097981296,"mc":[{"id":"1.195395453","rc":[{"atb":[[12.5,0]],"id":40324412},{"atb":[[18.5,0]],"id":39586887}],"con":true,"img":false}]}
{"op":"mcm","clk":"5346823317","pt":1646097981397,"mc":[{"id":"1.195395453","rc":[{"atb":[[19.5,6.5]],"id":39586887}],"con":true,"img":false}]}
{"op":"mcm","clk":"5346823345","pt":1646097982116,"mc":[{"id":"1.195395453","rc":[{"atb":[[1.25,146.32]],"id":42845264}],"con":true,"img":false}]}
{"op":"mcm","clk":"5346823394","pt":1646097984015,"mc":[{"id":"1.195395453","rc":[{"atb":[[14.5,0]],"id":40324412},{"atb":[[19,0]],"id":39586887}],"con":true,"img":false}]}
{"op":"mcm","clk":"5346823451","pt":1646097986122,"mc":[{"id":"1.195395453","rc":[{"atl":[[220,1]],"id":40324412}],"con":true,"img":false}]}
{"op":"mcm","clk":"5346823452","pt":1646097986226,"mc":[{"id":"1.195395453","rc":[{"atl":[[230,0.86]],"id":40324412}],"con":true,"img":false}]}
{"op":"mcm","clk":"5346823517","pt":1646097987714,"mc":[{"id":"1.195395453","rc":[{"atb":[[16,5.4]],"id":40324412}],"con":true,"img":false}]}
{"op":"mcm","clk":"5346823643","pt":1646097991248,"mc":[{"id":"1.195395453","rc":[{"atb":[[12.5,10.81]],"id":40324412}],"con":true,"img":false}]}
{"op":"mcm","clk":"5346823649","pt":1646097991351,"mc":[{"id":"1.195395453","rc":[{"atb":[[15,0]],"id":40324412},{"atb":[[1.23,0]],"id":42845264},{"atb":[[19.5,0]],"id":39586887}],"con":true,"img":false}]}
{"op":"mcm","clk":"5346823652","pt":1646097991453,"mc":[{"id":"1.195395453","rc":[{"atb":[[1.25,189.59]],"id":42845264},{"atb":[[18.5,6.5]],"id":39586887}],"con":true,"img":false}]}
{"op":"mcm","clk":"5346823655","pt":1646097991659,"mc":[{"id":"1.195395453","rc":[{"atl":[[220,0],[230,1.86]],"id":40324412}],"con":true,"img":false}]}
{"op":"mcm","clk":"5346823725","pt":1646097994015,"mc":[{"id":"1.195395453","rc":[{"atb":[[1.24,0]],"id":42845264}],"con":true,"img":false}]}
{"op":"mcm","clk":"5346823753","pt":1646097995039,"mc":[{"id":"1.195395453","rc":[{"atb":[[16,0]],"id":40324412},{"atb":[[19,5.14]],"id":39586887}],"con":true,"img":false}]}
{"op":"mcm","clk":"5346823814","pt":1646097996939,"mc":[{"id":"1.195395453","rc":[{"atb":[[1.25,45.26]],"id":42845264}],"con":true,"img":false}]}
{"op":"mcm","clk":"5346823891","pt":1646097998735,"mc":[{"id":"1.195395453","rc":[{"atl":[[220,1],[230,0.86]],"id":40324412}],"con":true,"img":false}]}
{"op":"mcm","clk":"5346823894","pt":1646097998837,"mc":[{"id":"1.195395453","rc":[{"atb":[[1.26,86.97]],"id":42845264}],"con":true,"img":false}]}
{"op":"mcm","clk":"5346823897","pt":1646097998941,"mc":[{"id":"1.195395453","rc":[{"atb":[[14.5,6.85]],"id":40324412}],"con":true,"img":false}]}
{"op":"mcm","clk":"5346823967","pt":1646098000946,"mc":[{"id":"1.195395453","rc":[{"atb":[[1.23,217.42]],"id":42845264}],"con":true,"img":false}]}
{"op":"mcm","clk":"5346823980","pt":1646098001358,"mc":[{"id":"1.195395453","rc":[{"atb":[[1.25,2]],"id":42845264}],"con":true,"img":false}]}
{"op":"mcm","clk":"5346823983","pt":1646098001461,"mc":[{"id":"1.195395453","rc":[{"atb":[[1.24,43.26]],"id":42845264}],"con":true,"img":false}]}
{"op":"mcm","clk":"5346824046","pt":1646098003055,"mc":[{"id":"1.195395453","rc":[{"atl":[[220,0],[230,1.86]],"id":40324412}],"con":true,"img":false}]}
{"op":"mcm","clk":"5346824322","pt":1646098010340,"mc":[{"id":"1.195395453","rc":[{"atl":[[220,1],[230,0.86]],"id":40324412}],"con":true,"img":false}]}
{"op":"mcm","clk":"5346824466","pt":1646098014759,"mc":[{"id":"1.195395453","rc":[{"atl":[[220,0],[230,1.86]],"id":40324412}],"con":true,"img":false}]}
{"op":"mcm","clk":"5346824638","pt":1646098021177,"mc":[{"id":"1.195395453","rc":[{"atl":[[1.85,0]],"id":42845264}],"con":true,"img":false}]}
{"op":"mcm","clk":"5346824689","pt":1646098022769,"mc":[{"id":"1.195395453","rc":[{"atl":[[220,1],[230,0.86]],"id":40324412}],"con":true,"img":false}]}
{"op":"mcm","clk":"5346824760","pt":1646098024981,"mc":[{"id":"1.195395453","rc":[{"atb":[[1.23,0]],"id":42845264}],"con":true,"img":false}]}
{"op":"mcm","clk":"5346824771","pt":1646098025185,"mc":[{"id":"1.195395453","rc":[{"atl":[[1.86,0]],"id":42845264}],"con":true,"img":false}]}
{"op":"mcm","clk":"5346824812","pt":1646098026366,"mc":[{"id":"1.195395453","rc":[{"atl":[[220,0],[230,1.86]],"id":40324412}],"con":true,"img":false}]}
{"op":"mcm","clk":"5346824840","pt":1646098027696,"mc":[{"id":"1.195395453","rc":[{"atb":[[1.26,0]],"id":42845264}],"con":true,"img":false}]}
{"op":"mcm","clk":"5346824872","pt":1646098028670,"mc":[{"id":"1.195395453","rc":[{"atb":[[1.27,130.45]],"id":42845264}],"con":true,"img":false}]}
{"op":"mcm","clk":"5346824919","pt":1646098030003,"mc":[{"id":"1.195395453","rc":[{"atl":[[1.85,9.74]],"id":42845264}],"con":true,"img":false}]}
{"op":"mcm","clk":"5346824938","pt":1646098030570,"mc":[{"id":"1.195395453","rc":[{"atl":[[1.86,9.87]],"id":42845264}],"con":true,"img":false}]}
{"op":"mcm","clk":"5346824963","pt":1646098031285,"mc":[{"id":"1.195395453","rc":[{"atb":[[1.24,0]],"id":42845264}],"con":true,"img":false}]}
{"op":"mcm","clk":"5346824968","pt":1646098031388,"mc":[{"id":"1.195395453","rc":[{"atb":[[1.23,43.26]],"id":42845264}],"con":true,"img":false}]}
{"op":"mcm","clk":"5346825015","pt":1646098033286,"mc":[{"id":"1.195395453","rc":[{"atb":[[1.25,92.44]],"id":42845264}],"con":true,"img":false}]}
{"op":"mcm","clk":"5346825041","pt":1646098034410,"mc":[{"id":"1.195395453","rc":[{"atb":[[1.27,0]],"id":42845264}],"con":true,"img":false}]}
{"op":"mcm","clk":"5346825053","pt":1646098034718,"mc":[{"id":"1.195395453","rc":[{"atl":[[220,1],[230,0.86]],"id":40324412}],"con":true,"img":false}]}
{"op":"mcm","clk":"5346825167","pt":1646098038216,"mc":[{"id":"1.195395453","rc":[{"atb":[[1.26,138.66]],"id":42845264}],"con":true,"img":false}]}
{"op":"mcm","clk":"5346825268","pt":1646098041190,"mc":[{"id":"1.195395453","rc":[{"atb":[[15,8.65]],"id":40324412}],"con":true,"img":false}]}
{"op":"mcm","clk":"5346825272","pt":1646098041294,"mc":[{"id":"1.195395453","rc":[{"atb":[[12.5,0]],"id":40324412}],"con":true,"img":false}]}
{"op":"mcm","clk":"5346825276","pt":1646098041396,"mc":[{"id":"1.195395453","rc":[{"atb":[[18.5,0]],"id":39586887}],"con":true,"img":false}]}
{"op":"mcm","clk":"5346825277","pt":1646098041499,"mc":[{"id":"1.195395453","rc":[{"atb":[[19.5,6.5]],"id":39586887}],"con":true,"img":false}]}
{"op":"mcm","clk":"5346825337","pt":1646098043224,"mc":[{"id":"1.195395453","rc":[{"atb":[[1.25,2]],"id":42845264}],"con":true,"img":false}]}
{"op":"mcm","clk":"5346825371","pt":1646098043895,"mc":[{"id":"1.195395453","rc":[{"atb":[[14.5,0]],"id":40324412},{"atb":[[19,0]],"id":39586887}],"con":true,"img":false}]}
{"op":"mcm","clk":"5346825440","pt":1646098045689,"mc":[{"id":"1.195395453","rc":[{"atb":[[1.26,0]],"id":42845264}],"con":true,"img":false}]}
{"op":"mcm","clk":"5346825500","pt":1646098047589,"mc":[{"id":"1.195395453","rc":[{"atb":[[16,5.4]],"id":40324412}],"con":true,"img":false}]}
{"op":"mcm","clk":"5346825534","pt":1646098048517,"mc":[{"id":"1.195395453","rc":[{"atb":[[1.27,83.75]],"id":42845264}],"con":true,"img":false}]}
{"op":"mcm","clk":"5346825593","pt":1646098049595,"mc":[{"id":"1.195395453","rc":[{"atb":[[1.24,67.89]],"id":42845264}],"con":true,"img":false}]}
{"op":"mcm","clk":"5346825658","pt":1646098051131,"mc":[{"id":"1.195395453","rc":[{"atl":[[230,1.86]],"id":40324412}],"con":true,"img":false}]}
{"op":"mcm","clk":"5346825664","pt":1646098051234,"mc":[{"id":"1.195395453","rc":[{"atb":[[12.5,10.81]],"id":40324412},{"atl":[[220,0]],"id":40324412}],"con":true,"img":false}]}
{"op":"mcm","clk":"5346825670","pt":1646098051336,"mc":[{"id":"1.195395453","rc":[{"atb":[[15,0]],"id":40324412},{"atb":[[19.5,0]],"id":39586887}],"con":true,"img":false}]}
{"op":"mcm","clk":"5346825674","pt":1646098051439,"mc":[{"id":"1.195395453","rc":[{"atb":[[18.5,6.5]],"id":39586887}],"con":true,"img":false}]}
{"op":"mcm","clk":"5346825745","pt":1646098053340,"mc":[{"id":"1.195395453","rc":[{"atb":[[1.24,0]],"id":42845264}],"con":true,"img":false}]}
{"op":"mcm","clk":"5346825818","pt":1646098055239,"mc":[{"id":"1.195395453","rc":[{"atb":[[16,0]],"id":40324412},{"atb":[[19,5.14]],"id":39586887}],"con":true,"img":false}]}
{"op":"mcm","clk":"5346825852","pt":1646098056317,"mc":[{"id":"1.195395453","rc":[{"atb":[[1.27,0]],"id":42845264}],"con":true,"img":false}]}
{"op":"mcm","clk":"5346825890","pt":1646098057140,"mc":[{"id":"1.195395453","rc":[{"atb":[[1.24,209.37]],"id":42845264}],"con":true,"img":false}]}
{"op":"mcm","clk":"5346825933","pt":1646098058017,"mc":[{"id":"1.195395453","rc":[{"atl":[[220,1],[230,0.86]],"id":40324412}],"con":true,"img":false}]}
{"op":"mcm","clk":"5346825981","pt":1646098059142,"mc":[{"id":"1.195395453","rc":[{"atb":[[14.5,6.86]],"id":40324412}],"con":true,"img":false}]}
{"op":"mcm","clk":"5346826070","pt":1646098061350,"mc":[{"id":"1.195395453","rc":[{"atb":[[1.23,0]],"id":42845264}],"con":true,"img":false}]}
{"op":"mcm","clk":"5346826077","pt":1646098061452,"mc":[{"id":"1.195395453","rc":[{"atb":[[1.25,135.71]],"id":42845264}],"con":true,"img":false}]}
{"op":"mcm","clk":"5346826126","pt":1646098062640,"mc":[{"id":"1.195395453","rc":[{"atl":[[220,0],[230,1.86]],"id":40324412}],"con":true,"img":false}]}
{"op":"mcm","clk":"5346826216","pt":1646098064851,"mc":[{"id":"1.195395453","rc":[{"atb":[[1.24,0]],"id":42845264}],"con":true,"img":false}]}
{"op":"mcm","clk":"5346826366","pt":1646098068553,"mc":[{"id":"1.195395453","rc":[{"atb":[[1.25,45.26],[1.26,203.57]],"id":42845264}],"con":true,"img":false}]}
{"op":"mcm","clk":"5346826408","pt":1646098069733,"mc":[{"id":"1.195395453","rc":[{"atl":[[220,1],[230,0.86]],"id":40324412}],"con":true,"img":false}]}
{"op":"mcm","clk":"5346826584","pt":1646098073443,"mc":[{"id":"1.195395453","rc":[{"atb":[[1.23,98.31]],"id":42845264}],"con":true,"img":false}]}
{"op":"mcm","clk":"5346826645","pt":1646098074728,"mc":[{"id":"1.195395453","rc":[{"atl":[[220,0],[230,1.86]],"id":40324412}],"con":true,"img":false}]}
{"op":"mcm","clk":"5346826905","pt":1646098081350,"mc":[{"id":"1.195395453","rc":[{"atb":[[1.25,2]],"id":42845264}],"con":true,"img":false}]}
{"op":"mcm","clk":"5346826910","pt":1646098081453,"mc":[{"id":"1.195395453","rc":[{"atb":[[1.24,43.26]],"id":42845264}],"con":true,"img":false}]}
{"op":"mcm","clk":"5346826924","pt":1646098081659,"mc":[{"id":"1.195395453","rc":[{"atl":[[220,1]],"id":40324412}],"con":true,"img":false}]}
{"op":"mcm","clk":"5346826931","pt":1646098081762,"mc":[{"id":"1.195395453","rc":[{"atl":[[230,0.86]],"id":40324412}],"con":true,"img":false}]}
{"op":"mcm","clk":"5346827060","pt":1646098084744,"mc":[{"id":"1.195395453","rc":[{"atb":[[1.23,0]],"id":42845264}],"con":true,"img":false}]}
{"op":"mcm","clk":"5346827132","pt":1646098086746,"mc":[{"id":"1.195395453","rc":[{"atl":[[220,0],[230,1.86]],"id":40324412}],"con":true,"img":false}]}
{"op":"mcm","clk":"5346827169","pt":1646098087363,"mc":[{"id":"1.195395453","rc":[{"atb":[[1.26,0]],"id":42845264}],"con":true,"img":false}]}
{"op":"mcm","clk":"5346827284","pt":1646098090188,"mc":[{"id":"1.195395453","rc":[{"atb":[[1.25,33.68]],"id":42845264}],"con":true,"img":false}]}
{"op":"mcm","clk":"5346827304","pt":1646098091170,"mc":[{"id":"1.195395453","rc":[{"atb":[[1.25,101.58]],"id":42845264}],"con":true,"img":false}]}
{"op":"mcm","clk":"5346827313","pt":1646098091377,"mc":[{"id":"1.195395453","rc":[{"atb":[[1.24,0]],"id":42845264}],"con":true,"img":false}]}
{"op":"mcm","clk":"5346827319","pt":1646098091480,"mc":[{"id":"1.195395453","rc":[{"atb":[[1.23,43.26]],"id":42845264}],"con":true,"img":false}]}
{"op":"mcm","clk":"5346827441","pt":1646098093755,"mc":[{"id":"1.195395453","rc":[{"atl":[[220,1]],"id":40324412},{"spn":1.55,"spf":1.0,"id":42845264}],"con":true,"img":false}]}
{"op":"mcm","clk":"5346827450","pt":1646098093857,"mc":[{"id":"1.195395453","rc":[{"atl":[[230,0.86]],"id":40324412}],"con":true,"img":false}]}
{"op":"mcm","clk":"5346827817","pt":1646098101304,"mc":[{"id":"1.195395453","rc":[{"atb":[[15,8.65]],"id":40324412},{"atb":[[18.5,0]],"id":39586887}],"con":true,"img":false}]}
{"op":"mcm","clk":"5346827821","pt":1646098101409,"mc":[{"id":"1.195395453","rc":[{"atb":[[12.5,0]],"id":40324412},{"atb":[[19.5,6.5]],"id":39586887}],"con":true,"img":false}]}
{"op":"mcm","clk":"5346827933","pt":1646098104176,"mc":[{"id":"1.195395453","rc":[{"atb":[[14.5,0]],"id":40324412},{"atb":[[19,0]],"id":39586887}],"con":true,"img":false}]}
{"op":"mcm","clk":"5346828112","pt":1646098107876,"mc":[{"id":"1.195395453","rc":[{"atb":[[16,5.4]],"id":40324412}],"con":true,"img":false}]}
{"op":"mcm","clk":"5346828247","pt":1646098111210,"mc":[{"id":"1.195395453","rc":[{"atb":[[12.5,10.81]],"id":40324412}],"con":true,"img":false}]}
{"op":"mcm","clk":"5346828253","pt":1646098111313,"mc":[{"id":"1.195395453","rc":[{"atb":[[15,0]],"id":40324412},{"atb":[[19.5,0]],"id":39586887}],"con":true,"img":false}]}
{"op":"mcm","clk":"5346828257","pt":1646098111417,"mc":[{"id":"1.195395453","rc":[{"atb":[[18.5,6.5]],"id":39586887}],"con":true,"img":false}]}
{"op":"mcm","clk":"5346828333","pt":1646098113521,"mc":[{"id":"1.195395453","rc":[{"atb":[[16,0]],"id":40324412},{"atb":[[19,5.14]],"id":39586887}],"con":true,"img":false}]}
{"op":"mcm","clk":"5346828457","pt":1646098117322,"mc":[{"id":"1.195395453","rc":[{"atb":[[14.5,6.86]],"id":40324412}],"con":true,"img":false}]}
{"op":"mcm","clk":"5346828614","pt":1646098122710,"mc":[{"id":"1.195395453","rc":[{"atl":[[230,1.86]],"id":40324412}],"con":true,"img":false}]}
{"op":"mcm","clk":"5346828616","pt":1646098122812,"mc":[{"id":"1.195395453","rc":[{"atl":[[220,0]],"id":40324412}],"con":true,"img":false}]}
{"op":"mcm","clk":"5346828797","pt":1646098129022,"mc":[{"id":"1.195395453","rc":[{"atl":[[220,1],[230,0.86]],"id":40324412}],"con":true,"img":false}]}
{"op":"mcm","clk":"5346828975","pt":1646098135328,"mc":[{"id":"1.195395453","rc":[{"atl":[[220,0],[230,1.86]],"id":40324412}],"con":true,"img":false}]}
{"op":"mcm","clk":"5346829127","pt":1646098140163,"mc":[{"id":"1.195395453","rc":[{"atl":[[21,0],[23,1]],"id":40612296},{"atl":[[220,1],[230,0.86]],"id":40324412},{"atl":[[12.5,0],[13.5,1.6]],"id":43066392}],"con":true,"img":false}]}
{"op":"mcm","clk":"5346829132","pt":1646098140266,"mc":[{"id":"1.195395453","rc":[{"atl":[[27,8.66]],"id":40612296}],"con":true,"img":false}]}
{"op":"mcm","clk":"5346829135","pt":1646098140368,"mc":[{"id":"1.195395453","rc":[{"atl":[[25,3.12]],"id":40612296}],"con":true,"img":false}]}
{"op":"mcm","clk":"5346829248","pt":1646098143448,"mc":[{"id":"1.195395453","rc":[{"atb":[[5.8,18.25]],"id":43066392}],"con":true,"img":false}]}
{"op":"mcm","clk":"5346829333","pt":1646098146169,"mc":[{"id":"1.195395453","rc":[{"atb":[[5.7,0]],"id":43066392}],"con":true,"img":false}]}
{"op":"mcm","clk":"5346829376","pt":1646098147351,"mc":[{"id":"1.195395453","rc":[{"atl":[[1.85,0]],"id":42845264}],"con":true,"img":false}]}
{"op":"mcm","clk":"5346829386","pt":1646098147658,"mc":[{"id":"1.195395453","rc":[{"atl":[[220,0],[230,1.86]],"id":40324412}],"con":true,"img":false}]}
{"op":"mcm","clk":"5346829440","pt":1646098149248,"mc":[{"id":"1.195395453","rc":[{"atb":[[5.8,0]],"id":43066392}],"con":true,"img":false}]}
{"op":"mcm","clk":"5346829477","pt":1646098150172,"mc":[{"id":"1.195395453","rc":[{"atl":[[25,2.08]],"id":40612296},{"atl":[[14.5,3.7]],"id":43066392}],"con":true,"img":false}]}
{"op":"mcm","clk":"5346829504","pt":1646098151046,"mc":[{"id":"1.195395453","rc":[{"atl":[[1.86,0]],"id":42845264}],"con":true,"img":false}]}
{"op":"mcm","clk":"5346829511","pt":1646098151251,"mc":[{"id":"1.195395453","rc":[{"atl":[[28,0]],"id":40612296},{"atb":[[6.2,4.35]],"id":43066392},{"atl":[[160,0]],"id":39586887}],"con":true,"img":false}]}
{"op":"mcm","clk":"5346829515","pt":1646098151355,"mc":[{"id":"1.195395453","rc":[{"atl":[[26,2.7]],"id":40612296},{"atl":[[150,1.2]],"id":39586887}],"con":true,"img":false}]}
{"op":"mcm","clk":"5346829518","pt":1646098151458,"mc":[{"id":"1.195395453","rc":[{"atl":[[25,4.78],[27,4.81]],"id":40612296}],"con":true,"img":false}]}
{"op":"mcm","clk":"5346829556","pt":1646098152793,"mc":[{"id":"1.195395453","rc":[{"spl":[[1.01,5.4]],"id":40612296}],"con":true,"img":false}]}
{"op":"mcm","clk":"5346829565","pt":1646098152950,"mc":[{"id":"1.195395453","rc":[{"atl":[[220,1],[230,0.86]],"id":40324412}],"con":true,"img":false}]}
{"op":"mcm","clk":"5346829568","pt":1646098153052,"mc":[{"id":"1.195395453","rc":[{"atl":[[1.86,4.3]],"id":42845264}],"con":true,"img":false}]}
{"op":"mcm","clk":"5346829574","pt":1646098153155,"mc":[{"id":"1.195395453","rc":[{"atb":[[5.7,19.72]],"id":43066392}],"con":true,"img":false}]}
{"op":"mcm","clk":"5346829674","pt":1646098156389,"mc":[{"id":"1.195395453","rc":[{"spn":8.0,"spf":1.0,"id":40612296},{"atb":[[5.6,1.99]],"id":43066392},{"spn":9.85,"spf":1.0,"id":43066392},{"spn":1.55,"spf":1.0,"id":42845264}],"con":true,"img":false}]}
{"op":"mcm","clk":"5346829689","pt":1646098156851,"mc":[{"id":"1.195395453","rc":[{"atb":[[5.6,0]],"id":43066392}],"con":true,"img":false}]}
{"op":"mcm","clk":"5346829695","pt":1646098157057,"mc":[{"id":"1.195395453","rc":[{"atb":[[5.7,0]],"id":43066392}],"con":true,"img":false}]}
{"op":"mcm","clk":"5346829784","pt":1646098160189,"mc":[{"id":"1.195395453","rc":[{"atl":[[27,7.69]],"id":40612296},{"atl":[[15.5,13.79]],"id":43066392}],"con":true,"img":false}]}
{"op":"mcm","clk":"5346829785","pt":1646098160292,"mc":[{"id":"1.195395453","rc":[{"atl":[[27,2.88]],"id":40612296},{"atl":[[15.5,5.17]],"id":43066392}],"con":true,"img":false}]}
{"op":"mcm","clk":"5346829788","pt":1646098160396,"mc":[{"id":"1.195395453","rc":[{"atl":[[230,1.86]],"id":40324412}],"con":true,"img":false}]}
{"op":"mcm","clk":"5346829792","pt":1646098160499,"mc":[{"id":"1.195395453","rc":[{"atl":[[220,0]],"id":40324412}],"con":true,"img":false}]}
{"op":"mcm","clk":"5346829796","pt":1646098160601,"mc":[{"id":"1.195395453","rc":[{"spl":[[1.01,5.4]],"id":43066392}],"con":true,"img":false}]}
{"op":"mcm","clk":"5346829813","pt":1646098161063,"mc":[{"id":"1.195395453","rc":[{"atb":[[6.2,0]],"id":43066392}],"con":true,"img":false}]}
{"op":"mcm","clk":"5346829821","pt":1646098161271,"mc":[{"id":"1.195395453","rc":[{"atb":[[12.5,0],[15,8.65]],"id":40324412}],"con":true,"img":false}]}
{"op":"mcm","clk":"5346829824","pt":1646098161372,"mc":[{"id":"1.195395453","rc":[{"atl":[[26,0]],"id":40612296},{"atb":[[18.5,0]],"id":39586887}],"con":true,"img":false}]}
{"op":"mcm","clk":"5346829827","pt":1646098161475,"mc":[{"id":"1.195395453","rc":[{"atl":[[34,2.7],[25,2.08],[27,6.73]],"id":40612296},{"atb":[[19.5,6.5]],"id":39586887}],"con":true,"img":false}]}
{"op":"mcm","clk":"5346829920","pt":1646098164604,"mc":[{"id":"1.195395453","rc":[{"atl":[[220,1]],"id":40324412}],"con":true,"img":false}]}
{"op":"mcm","clk":"5346829924","pt":1646098164706,"mc":[{"id":"1.195395453","rc":[{"atl":[[230,0.86]],"id":40324412}],"con":true,"img":false}]}
{"op":"mcm","clk":"5346829928","pt":1646098164861,"mc":[{"id":"1.195395453","rc":[{"atb":[[14.5,0]],"id":40324412},{"atb":[[5.6,20.15]],"id":43066392},{"atb":[[19,0]],"id":39586887}],"con":true,"img":false}]}
{"op":"mcm","clk":"5346829966","pt":1646098166396,"mc":[{"id":"1.195395453","rc":[{"atb":[[5.6,25.06]],"id":43066392}],"con":true,"img":false}]}
{"op":"mcm","clk":"5346830038","pt":1646098168907,"mc":[{"id":"1.195395453","rc":[{"atb":[[16,5.4]],"id":40324412}],"con":true,"img":false}]}
{"op":"mcm","clk":"5346830078","pt":1646098170191,"mc":[{"id":"1.195395453","rc":[{"atl":[[29,9.18]],"id":40612296},{"atl":[[16.5,8.06]],"id":43066392}],"con":true,"img":false}]}
{"op":"mcm","clk":"5346830114","pt":1646098171317,"mc":[{"id":"1.195395453","rc":[{"atb":[[12.5,10.81],[15,0]],"id":40324412},{"atb":[[19.5,0]],"id":39586887}],"con":true,"img":false}]}
{"op":"mcm","clk":"5346830118","pt":1646098171371,"mc":[{"id":"1.195395453","rc":[{"atb":[[18.5,6.5]],"id":39586887}],"con":true,"img":false}]}
{"op":"mcm","clk":"5346830149","pt":1646098172601,"mc":[{"id":"1.195395453","rc":[{"atl":[[230,1.86]],"id":40324412}],"con":true,"img":false}]}
{"op":"mcm","clk":"5346830154","pt":1646098172703,"mc":[{"id":"1.195395453","rc":[{"atl":[[220,0]],"id":40324412}],"con":true,"img":false}]}
{"op":"mcm","clk":"5346830198","pt":1646098174816,"mc":[{"id":"1.195395453","rc":[{"atb":[[16,0]],"id":40324412},{"atb":[[19,5.14]],"id":39586887}],"con":true,"img":false}]}
{"op":"mcm","clk":"5346830242","pt":1646098176411,"mc":[{"id":"1.195395453","rc":[{"atl":[[220,1],[230,0.86]],"id":40324412}],"con":true,"img":false}]}
{"op":"mcm","clk":"5346830322","pt":1646098178726,"mc":[{"id":"1.195395453","rc":[{"atb":[[14.5,6.86]],"id":40324412},{"atl":[[220,0],[230,1.86]],"id":40324412},{"atl":[[760,0]],"id":39586887}],"con":true,"img":false}]}
{"op":"mcm","clk":"5346830373","pt":1646098180731,"mc":[{"id":"1.195395453","rc":[{"atb":[[5.7,1.95]],"id":43066392}],"con":true,"img":false}]}
{"op":"mcm","clk":"5346830439","pt":1646098183306,"mc":[{"id":"1.195395453","rc":[{"atb":[[1.01,2.23]],"id":43066392}],"con":true,"img":false}]}
{"op":"mcm","clk":"5346830444","pt":1646098183512,"mc":[{"id":"1.195395453","rc":[{"atb":[[1.01,1.92]],"id":43066392}],"con":true,"img":false}]}
{"op":"mcm","clk":"5346830451","pt":1646098183717,"mc":[{"id":"1.195395453","rc":[{"atb":[[1.01,0]],"id":43066392}],"con":true,"img":false}]}
{"op":"mcm","clk":"5346830455","pt":1646098183819,"mc":[{"id":"1.195395453","rc":[{"atb":[[5.7,3.87]],"id":43066392}],"con":true,"img":false}]}
{"op":"mcm","clk":"5346830526","pt":1646098186440,"mc":[{"id":"1.195395453","rc":[{"atb":[[5.6,4.91]],"id":43066392},{"atl":[[840,1]],"id":39586887}],"con":true,"img":false}]}
{"op":"mcm","clk":"5346830589","pt":1646098188145,"mc":[{"id":"1.195395453","rc":[{"atb":[[5.6,0]],"id":43066392}],"con":true,"img":false}]}
{"op":"mcm","clk":"5346830612","pt":1646098188701,"mc":[{"id":"1.195395453","rc":[{"atl":[[250,1]],"id":40324412}],"con":true,"img":false}]}
{"op":"mcm","clk":"5346830666","pt":1646098190551,"mc":[{"id":"1.195395453","rc":[{"atb":[[5.8,18.25]],"id":43066392}],"con":true,"img":false}]}
{"op":"mcm","clk":"5346830745","pt":1646098193536,"mc":[{"id":"1.195395453","rc":[{"atb":[[6.2,4.35]],"id":43066392}],"con":true,"img":false}]}
{"op":"mcm","clk":"5346830788","pt":1646098195644,"mc":[{"id":"1.195395453","rc":[{"atb":[[5.7,1.95]],"id":43066392}],"con":true,"img":false}]}
{"op":"mcm","clk":"5346830812","pt":1646098196417,"mc":[{"id":"1.195395453","rc":[{"atb":[[5.8,0]],"id":43066392}],"con":true,"img":false}]}
{"op":"mcm","clk":"5346830822","pt":1646098196830,"mc":[{"id":"1.195395453","rc":[{"atl":[[260,0],[280,0],[240,0]],"id":40324412}],"con":true,"img":false}]}
{"op":"mcm","clk":"5346830865","pt":1646098198733,"mc":[{"id":"1.195395453","rc":[{"atl":[[270,1]],"id":40324412}],"con":true,"img":false}]}
{"op":"mcm","clk":"5346830933","pt":1646098201049,"mc":[{"id":"1.195395453","rc":[{"atb":[[6.2,0]],"id":43066392}],"con":true,"img":false}]}
{"op":"mcm","clk":"5346830943","pt":1646098201360,"mc":[{"id":"1.195395453","rc":[{"atl":[[34,0]],"id":40612296}],"con":true,"img":false}]}
{"op":"mcm","clk":"5346830950","pt":1646098201463,"mc":[{"id":"1.195395453","rc":[{"atl":[[28,2.7]],"id":40612296}],"con":true,"img":false}]}
{"op":"mcm","clk":"5346831060","pt":1646098204046,"mc":[{"id":"1.195395453","rc":[{"atb":[[5.6,20.15]],"id":43066392}],"con":true,"img":false}]}
{"op":"mcm","clk":"5346831135","pt":1646098206052,"mc":[{"id":"1.195395453","rc":[{"atb":[[5.6,25.06]],"id":43066392}],"con":true,"img":false}]}
{"op":"mcm","clk":"5346831210","pt":1646098208777,"mc":[{"id":"1.195395453","rc":[{"atl":[[290,1]],"id":40324412}],"con":true,"img":false}]}
{"op":"mcm","clk":"5346831229","pt":1646098209292,"mc":[{"id":"1.195395453","rc":[{"atb":[[9,0],[11.5,17.35],[12.5,8.7],[8.8,0]],"id":37076607},{"atb":[[9,12.5],[9.2,2.44],[6.6,0]],"id":42901530},{"atl":[[23,0],[25,0],[27,3.85],[29,4.72],[30,1]],"id":40612296},{"atl":[[13.5,0],[14.5,0],[15,1.43]],"id":43066392},{"atb":[[1.2,100],[1.21,685.09],[1.17,1315.46]],"id":42845264},{"atl":[[1.87,0],[1.81,24.69]],"id":42845264},{"atb":[[10.5,0],[11.5,1.9]],"id":43154432},{"atb":[[8,0],[10.5,19.19],[11.5,9.52]],"id":39586887}],"con":true,"img":false}]}
{"op":"mcm","clk":"5346831234","pt":1646098209446,"mc":[{"id":"1.195395453","rc":[{"atl":[[27,0],[28,6.4]],"id":40612296}],"con":true,"img":false}]}
{"op":"mcm","clk":"5346831261","pt":1646098210370,"mc":[{"id":"1.195395453","rc":[{"atl":[[1.86,0]],"id":42845264}],"con":true,"img":false}]}
{"op":"mcm","clk":"5346831290","pt":1646098211344,"mc":[{"id":"1.195395453","rc":[{"atl":[[28,3.7]],"id":40612296}],"con":true,"img":false}]}
{"op":"mcm","clk":"5346831293","pt":1646098211446,"mc":[{"id":"1.195395453","rc":[{"atl":[[34,2.7]],"id":40612296}],"con":true,"img":false}]}
{"op":"mcm","clk":"5346831337","pt":1646098213247,"mc":[{"id":"1.195395453","rc":[{"atl":[[1.8,4.38]],"id":42845264}],"con":true,"img":false}]}
{"op":"mcm","clk":"5346831351","pt":1646098213658,"mc":[{"id":"1.195395453","rc":[{"atl":[[1.82,24.39],[1.81,0]],"id":42845264}],"con":true,"img":false}]}
{"op":"mcm","clk":"5346831456","pt":1646098217253,"mc":[{"id":"1.195395453","rc":[{"spn":6.0,"spf":1.0,"id":43066392},{"atl":[[1.81,24.69]],"id":42845264},{"spn":1.52,"spf":1.0,"id":42845264}],"con":true,"img":false}]}
{"op":"mcm","clk":"5346831460","pt":1646098217354,"mc":[{"id":"1.195395453","rc":[{"atl":[[1.82,0]],"id":42845264}],"con":true,"img":false}]}
{"op":"mcm","clk":"5346831518","pt":1646098219254,"mc":[{"id":"1.195395453","rc":[{"atb":[[10.5,5.26]],"id":37076607},{"atb":[[8.8,6.41]],"id":42901530},{"atl":[[34,4.22]],"id":40612296},{"atl":[[16,3.33]],"id":43066392},{"atb":[[10.5,5.26]],"id":43154432},{"atb":[[9.8,5.68]],"id":39586887}],"con":true,"img":false}]}
{"op":"mcm","clk":"5346831524","pt":1646098219460,"mc":[{"id":"1.195395453","rc":[{"atb":[[1.01,2.23]],"id":43066392}],"con":true,"img":false}]}
{"op":"mcm","clk":"5346831532","pt":1646098219664,"mc":[{"id":"1.195395453","rc":[{"atb":[[1.01,1.92]],"id":43066392}],"con":true,"img":false}]}
{"op":"mcm","clk":"5346831534","pt":1646098219869,"mc":[{"id":"1.195395453","rc":[{"atb":[[1.01,0]],"id":43066392}],"con":true,"img":false}]}
{"op":"mcm","clk":"5346831537","pt":1646098219971,"mc":[{"id":"1.195395453","rc":[{"atb":[[5.7,3.87]],"id":43066392}],"con":true,"img":false}]}
{"op":"mcm","clk":"5346831574","pt":1646098221305,"mc":[{"id":"1.195395453","rc":[{"atb":[[15,8.65]],"id":40324412},{"atb":[[18.5,0]],"id":39586887}],"con":true,"img":false}]}
{"op":"mcm","clk":"5346831577","pt":1646098221356,"mc":[{"id":"1.195395453","rc":[{"atb":[[12.5,0]],"id":40324412},{"atb":[[19.5,6.5]],"id":39586887}],"con":true,"img":false}]}
{"op":"mcm","clk":"5346831600","pt":1646098222394,"mc":[{"id":"1.195395453","rc":[{"atb":[[8,0],[8.4,0],[7.6,0]],"id":37076607},{"atb":[[5.9,0],[6.2,0],[5.7,0]],"id":42901530},{"atl":[[1.82,24.39],[1.81,0]],"id":42845264},{"atb":[[9,0]],"id":43154432},{"atb":[[6.8,0],[7.2,0],[7.6,0]],"id":39586887}],"con":true,"img":false}]}
{"op":"mcm","clk":"5346831636","pt":1646098223371,"mc":[{"id":"1.195395453","rc":[{"atb":[[5.6,4.91]],"id":43066392}],"con":true,"img":false}]}
{"op":"mcm","clk":"5346831663","pt":1646098223986,"mc":[{"id":"1.195395453","rc":[{"atb":[[5.6,0]],"id":43066392}],"con":true,"img":false}]}
{"op":"mcm","clk":"5346831712","pt":1646098225378,"mc":[{"id":"1.195395453","rc":[{"atb":[[14.5,0]],"id":40324412},{"atb":[[19,0]],"id":39586887}],"con":true,"img":false}]}
{"op":"mcm","clk":"5346831725","pt":1646098225789,"mc":[{"id":"1.195395453","rc":[{"atl":[[1.82,0],[1.81,24.69]],"id":42845264}],"con":true,"img":false}]}
{"op":"mcm","clk":"5346831765","pt":1646098227383,"mc":[{"id":"1.195395453","rc":[{"atb":[[5.8,18.25]],"id":43066392}],"con":true,"img":false}]}
{"op":"mcm","clk":"5346831815","pt":1646098228971,"mc":[{"id":"1.195395453","rc":[{"atb":[[5.7,1.92]],"id":43066392}],"con":true,"img":false}]}
{"op":"mcm","clk":"5346831826","pt":1646098229277,"mc":[{"id":"1.195395453","rc":[{"atb":[[9.8,8.52]],"id":37076607},{"atb":[[8.4,10.14]],"id":42901530},{"atl":[[38,5.6]],"id":40612296},{"atl":[[17,4.69]],"id":43066392},{"atb":[[9.8,17.74]],"id":43154432},{"atb":[[9.4,8.93]],"id":39586887}],"con":true,"img":false}]}
{"op":"mcm","clk":"5346831829","pt":1646098229380,"mc":[{"id":"1.195395453","rc":[{"atb":[[16,5.4]],"id":40324412}],"con":true,"img":false}]}
{"op":"mcm","clk":"5346831835","pt":1646098229481,"mc":[{"id":"1.195395453","rc":[{"atb":[[5.8,22.96]],"id":43066392}],"con":true,"img":false}]}
{"op":"mcm","clk":"5346831880","pt":1646098231277,"mc":[{"id":"1.195395453","rc":[{"atb":[[12.5,10.81]],"id":40324412},{"atb":[[19.5,0]],"id":39586887}],"con":true,"img":false}]}
{"op":"mcm","clk":"5346831884","pt":1646098231381,"mc":[{"id":"1.195395453","rc":[{"atb":[[15,0]],"id":40324412},{"atb":[[18.5,6.5]],"id":39586887}],"con":true,"img":false}]}
{"op":"mcm","clk":"5346831890","pt":1646098231692,"mc":[{"id":"1.195395453","rc":[{"atb":[[5.7,0]],"id":43066392}],"con":true,"img":false}]}
{"op":"mcm","clk":"5346831954","pt":1646098233798,"mc":[{"id":"1.195395453","rc":[{"atl":[[15.5,0],[16.5,0]],"id":43066392}],"con":true,"img":false}]}
{"op":"mcm","clk":"5346831995","pt":1646098235286,"mc":[{"id":"1.195395453","rc":[{"atb":[[16,0]],"id":40324412},{"atb":[[19,5.14]],"id":39586887}],"con":true,"img":false}]}
{"op":"mcm","clk":"5346832019","pt":1646098235801,"mc":[{"id":"1.195395453","rc":[{"atb":[[1.18,250]],"id":42845264},{"atl":[[1.83,60.24]],"id":42845264}],"con":true,"img":false}]}
{"op":"mcm","clk":"5346832048","pt":1646098237287,"mc":[{"id":"1.195395453","rc":[{"atb":[[5.8,0]],"id":43066392}],"con":true,"img":false}]}
{"op":"mcm","clk":"5346832093","pt":1646098238821,"mc":[{"id":"1.195395453","rc":[{"atb":[[1.15,0],[1.19,0],[1.17,1065.46]],"id":42845264},{"atl":[[1.83,0],[1.89,0],[1.93,0],[1.82,24.39],[1.81,0],[1.91,0]],"id":42845264}],"con":true,"img":false}]}
{"op":"mcm","clk":"5346832109","pt":1646098239328,"mc":[{"id":"1.195395453","rc":[{"atb":[[9.4,14.88]],"id":37076607},{"atb":[[8,17.86]],"id":42901530},{"atl":[[42,3.05]],"id":40612296},{"atb":[[14.5,6.86]],"id":40324412},{"atl":[[18,7.35]],"id":43066392},{"atb":[[9.4,14.88]],"id":43154432},{"atb":[[9,15.62]],"id":39586887}],"con":true,"img":false}]}
{"op":"mcm","clk":"5346832163","pt":1646098241226,"mc":[{"id":"1.195395453","rc":[{"atb":[[12,14.7]],"id":43154432}],"con":true,"img":false}]}
{"op":"mcm","clk":"5346832166","pt":1646098241328,"mc":[{"id":"1.195395453","rc":[{"atl":[[1.88,0]],"id":42845264}],"con":true,"img":false}]}
{"op":"mcm","clk":"5346832170","pt":1646098241430,"mc":[{"id":"1.195395453","rc":[{"atb":[[5.6,20.15]],"id":43066392},{"atl":[[1.81,24.69],[2.04,43.26]],"id":42845264},{"atb":[[10,0]],"id":43154432}],"con":true,"img":false}]}
{"op":"mcm","clk":"5346832171","pt":1646098241485,"mc":[{"id":"1.195395453","rc":[{"atb":[[12,3.68]],"id":43154432}],"con":true,"img":false}]}
{"op":"mcm","clk":"5346832174","pt":1646098241586,"mc":[{"id":"1.195395453","rc":[{"atb":[[11,11.01]],"id":43154432}],"con":true,"img":false}]}
{"op":"mcm","clk":"5346832198","pt":1646098242405,"mc":[{"id":"1.195395453","rc":[{"atb":[[6.8,0]],"id":40612296}],"con":true,"img":false}]}
{"op":"mcm","clk":"5346832202","pt":1646098242510,"mc":[{"id":"1.195395453","rc":[{"atb":[[7,15.2]],"id":40612296}],"con":true,"img":false}]}
{"op":"mcm","clk":"5346832207","pt":1646098242612,"mc":[{"id":"1.195395453","rc":[{"atb":[[5.6,25.06]],"id":43066392}],"con":true,"img":false}]}
{"op":"mcm","clk":"5346832331","pt":1646098246718,"mc":[{"id":"1.195395453","rc":[{"atl":[[1.81,0]],"id":42845264}],"con":true,"img":false}]}
{"op":"mcm","clk":"5346832434","pt":1646098249747,"mc":[{"id":"1.195395453","rc":[{"atl":[[1.81,24.69]],"id":42845264}],"con":true,"img":false}]}
{"op":"mcm","clk":"5346832477","pt":1646098251337,"mc":[{"id":"1.195395453","rc":[{"atl":[[21,0]],"id":43066392}],"con":true,"img":false}]}
{"op":"mcm","clk":"5346832481","pt":1646098251439,"mc":[{"id":"1.195395453","rc":[{"atl":[[17,7.39]],"id":43066392}],"con":true,"img":false}]}
{"op":"mcm","clk":"5346832562","pt":1646098254110,"mc":[{"id":"1.195395453","rc":[{"atl":[[1.81,0]],"id":42845264}],"con":true,"img":false}]}
{"op":"mcm","clk":"5346832640","pt":1646098257751,"mc":[{"id":"1.195395453","rc":[{"atl":[[1.81,24.69]],"id":42845264}],"con":true,"img":false}]}
{"op":"mcm","clk":"5346832668","pt":1646098258516,"mc":[{"id":"1.195395453","rc":[{"atb":[[1.01,2.23]],"id":43066392}],"con":true,"img":false}]}
{"op":"mcm","clk":"5346832678","pt":1646098258720,"mc":[{"id":"1.195395453","rc":[{"atb":[[1.01,1.92]],"id":43066392}],"con":true,"img":false}]}
{"op":"mcm","clk":"5346832685","pt":1646098258926,"mc":[{"id":"1.195395453","rc":[{"atb":[[1.01,0]],"id":43066392}],"con":true,"img":false}]}
{"op":"mcm","clk":"5346832688","pt":1646098259029,"mc":[{"id":"1.195395453","rc":[{"atb":[[5.7,1.92]],"id":43066392}],"con":true,"img":false}]}
{"op":"mcm","clk":"5346832698","pt":1646098259438,"mc":[{"id":"1.195395453","rc":[{"atb":[[5.7,3.87]],"id":43066392}],"con":true,"img":false}]}
{"op":"mcm","clk":"5346832743","pt":1646098261229,"mc":[{"id":"1.195395453","rc":[{"atl":[[36,3.78]],"id":40612296}],"con":true,"img":false}]}
{"op":"mcm","clk":"5346832746","pt":1646098261331,"mc":[{"id":"1.195395453","rc":[{"atl":[[160,0.83]],"id":42901530},{"atl":[[34,1.52],[46,0]],"id":40612296},{"atl":[[75,0]],"id":43154432}],"con":true,"img":false}]}
{"op":"mcm","clk":"5346832749","pt":1646098261433,"mc":[{"id":"1.195395453","rc":[{"atl":[[150,0.27],[170,0],[210,2.63]],"id":42901530},{"atl":[[27,2.7]],"id":40612296},{"atl":[[65,0.62]],"id":43154432}],"con":true,"img":false}]}
{"op":"mcm","clk":"5346832752","pt":1646098261536,"mc":[{"id":"1.195395453","rc":[{"atl":[[170,2]],"id":42901530}],"con":true,"img":false}]}
{"op":"mcm","clk":"5346832754","pt":1646098261640,"mc":[{"id":"1.195395453","rc":[{"atl":[[210,0.63]],"id":42901530}],"con":true,"img":false}]}
{"op":"mcm","clk":"5346832762","pt":1646098261948,"mc":[{"id":"1.195395453","rc":[{"atl":[[1.81,0]],"id":42845264}],"con":true,"img":false}]}
{"op":"mcm","clk":"5346832799","pt":1646098262823,"mc":[{"id":"1.195395453","rc":[{"atb":[[5.6,20.15]],"id":43066392}],"con":true,"img":false}]}
{"op":"mcm","clk":"5346832809","pt":1646098263028,"mc":[{"id":"1.195395453","rc":[{"atb":[[5.6,0]],"id":43066392}],"con":true,"img":false}]}
{"op":"mcm","clk":"5346832881","pt":1646098265025,"mc":[{"id":"1.195395453","rc":[{"atl":[[1.81,24.69]],"id":42845264}],"con":true,"img":false}]}
{"op":"mcm","clk":"5346832896","pt":1646098265640,"mc":[{"id":"1.195395453","rc":[{"atl":[[1000,1.67]],"id":40324412},{"atl":[[1000,1.67]],"id":43066392}],"con":true,"img":false}]}
{"op":"mcm","clk":"5346832905","pt":1646098265948,"mc":[{"id":"1.195395453","rc":[{"atl":[[1000,0.1]],"id":40324412},{"atl":[[1000,0.57]],"id":43066392}],"con":true,"img":false}]}
{"op":"mcm","clk":"5346832916","pt":1646098266360,"mc":[{"id":"1.195395453","rc":[{"atl":[[1000,0]],"id":43066392}],"con":true,"img":false}]}
{"op":"mcm","clk":"5346832920","pt":1646098266463,"mc":[{"id":"1.195395453","rc":[{"atl":[[14.5,0.57]],"id":43066392}],"con":true,"img":false}]}
{"op":"mcm","clk":"5346832927","pt":1646098266667,"mc":[{"id":"1.195395453","rc":[{"atl":[[1000,0]],"id":40324412}],"con":true,"img":false}]}
{"op":"mcm","clk":"5346832928","pt":1646098266769,"mc":[{"id":"1.195395453","rc":[{"atl":[[85,0.1]],"id":40324412}],"con":true,"img":false}]}
{"op":"mcm","clk":"5346832935","pt":1646098266926,"mc":[{"id":"1.195395453","rc":[{"atb":[[5.8,18.25]],"id":43066392}],"con":true,"img":false}]}
{"op":"mcm","clk":"5346832988","pt":1646098268260,"mc":[{"id":"1.195395453","rc":[{"atb":[[5.8,22.96]],"id":43066392}],"con":true,"img":false}]}
{"op":"mcm","clk":"5346833015","pt":1646098268876,"mc":[{"id":"1.195395453","rc":[{"atl":[[27,0]],"id":40612296}],"con":true,"img":false}]}
{"op":"mcm","clk":"5346833019","pt":1646098268942,"mc":[{"id":"1.195395453","rc":[{"atl":[[28,6.4]],"id":40612296}],"con":true,"img":false}]}
{"op":"mcm","clk":"5346833037","pt":1646098269462,"mc":[{"id":"1.195395453","rc":[{"atl":[[1.81,0]],"id":42845264}],"con":true,"img":false}]}
{"op":"mcm","clk":"5346833074","pt":1646098270645,"mc":[{"id":"1.195395453","rc":[{"atb":[[5.7,1.95]],"id":43066392}],"con":true,"img":false}]}
{"op":"mcm","clk":"5346833154","pt":1646098272850,"mc":[{"id":"1.195395453","rc":[{"atb":[[5.8,4.7]],"id":43066392},{"atl":[[1.81,24.69]],"id":42845264}],"con":true,"img":false}]}
{"op":"mcm","clk":"5346833245","pt":1646098275875,"mc":[{"id":"1.195395453","rc":[{"atb":[[5.8,0]],"id":43066392}],"con":true,"img":false}]}
{"op":"mcm","clk":"5346833276","pt":1646098276746,"mc":[{"id":"1.195395453","rc":[{"atb":[[6.2,12.16]],"id":43066392}],"con":true,"img":false}]}
{"op":"mcm","clk":"5346833293","pt":1646098277155,"mc":[{"id":"1.195395453","rc":[{"atl":[[1.81,0]],"id":42845264}],"con":true,"img":false}]}
{"op":"mcm","clk":"5346833302","pt":1646098277360,"mc":[{"id":"1.195395453","rc":[{"spn":51.25,"spf":1.0,"id":40324412},{"atb":[[5.7,0]],"id":43066392},{"spn":6.2,"spf":1.0,"id":43066392},{"spn":39.25,"spf":1.0,"id":43154432}],"con":true,"img":false}]}
{"op":"mcm","clk":"5346833395","pt":1646098280648,"mc":[{"id":"1.195395453","rc":[{"atl":[[1.81,24.69]],"id":42845264}],"con":true,"img":false}]}
{"op":"mcm","clk":"5346833409","pt":1646098281265,"mc":[{"id":"1.195395453","rc":[{"atl":[[250,0]],"id":37076607},{"atl":[[250,0]],"id":42901530},{"atb":[[12.5,0],[15,8.65]],"id":40324412},{"atl":[[170,0]],"id":40324412},{"atb":[[6.4,4.18]],"id":43066392},{"atl":[[21,6.1],[26,0]],"id":43066392},{"atl":[[130,0]],"id":43154432},{"atb":[[18.5,0]],"id":39586887},{"atl":[[240,0]],"id":39586887}],"con":true,"img":false}]}
{"op":"mcm","clk":"5346833411","pt":1646098281370,"mc":[{"id":"1.195395453","rc":[{"atl":[[200,2.7]],"id":37076607},{"atl":[[200,2.7]],"id":42901530},{"atl":[[120,2.7]],"id":40324412},{"atl":[[90,2.7]],"id":43154432},{"atb":[[19.5,6.5]],"id":39586887},{"atl":[[190,2.7]],"id":39586887}],"con":true,"img":false}]}
{"op":"mcm","clk":"5346833489","pt":1646098284497,"mc":[{"id":"1.195395453","rc":[{"atl":[[1.81,0]],"id":42845264}],"con":true,"img":false}]}
{"op":"mcm","clk":"5346833492","pt":1646098284597,"mc":[{"id":"1.195395453","rc":[{"atb":[[14.5,0]],"id":40324412},{"atb":[[6.2,0]],"id":43066392},{"atb":[[19,0]],"id":39586887}],"con":true,"img":false}]}
{"op":"mcm","clk":"5346833603","pt":1646098288290,"mc":[{"id":"1.195395453","rc":[{"atl":[[1.81,24.69]],"id":42845264}],"con":true,"img":false}]}
{"op":"mcm","clk":"5346833618","pt":1646098288597,"mc":[{"id":"1.195395453","rc":[{"atb":[[16,5.4]],"id":40324412},{"atb":[[6.6,6.28]],"id":43066392}],"con":true,"img":false}]}
{"op":"mcm","clk":"5346833622","pt":1646098288802,"mc":[{"id":"1.195395453","rc":[{"atb":[[1.04,2.82]],"id":40612296},{"atb":[[1.03,2.86]],"id":43066392},{"atb":[[1.02,8116.35]],"id":42845264},{"atb":[[1.06,2.78]],"id":43154432}],"con":true,"img":false}]}
{"op":"mcm","clk":"5346833627","pt":1646098288904,"mc":[{"id":"1.195395453","rc":[{"atb":[[6.4,0]],"id":43066392}],"con":true,"img":false}]}
{"op":"mcm","clk":"5346833650","pt":1646098289265,"mc":[{"id":"1.195395453","rc":[{"atb":[[1.04,0.11]],"id":40612296},{"atb":[[1.03,0.16],[5.6,1.99]],"id":43066392},{"atb":[[1.02,8113.65]],"id":42845264},{"atb":[[1.06,0.08]],"id":43154432}],"con":true,"img":false}]}
{"op":"mcm","clk":"5346833672","pt":1646098289679,"mc":[{"id":"1.195395453","rc":[{"atb":[[1.04,0]],"id":40612296},{"atb":[[1.03,0]],"id":43066392},{"atb":[[1.02,8112.93]],"id":42845264},{"atb":[[1.06,0]],"id":43154432}],"con":true,"img":false}]}
{"op":"mcm","clk":"5346833679","pt":1646098289779,"mc":[{"id":"1.195395453","rc":[{"atb":[[8.8,0.11]],"id":40612296},{"atb":[[6.6,6.44]],"id":43066392},{"atb":[[1.48,0.71]],"id":42845264},{"atb":[[13,4.01]],"id":43154432}],"con":true,"img":false}]}
{"op":"mcm","clk":"5346833730","pt":1646098291369,"mc":[{"id":"1.195395453","rc":[{"atl":[[28,3.7]],"id":40612296},{"atb":[[15,0]],"id":40324412},{"atl":[[17,4.69]],"id":43066392},{"atb":[[19.5,0]],"id":39586887}],"con":true,"img":false}]}
{"op":"mcm","clk":"5346833733","pt":1646098291470,"mc":[{"id":"1.195395453","rc":[{"atl":[[27,2.7]],"id":40612296},{"atb":[[13.5,8.65]],"id":40324412},{"atl":[[16.5,2.7]],"id":43066392},{"atb":[[18.5,6.5]],"id":39586887}],"con":true,"img":false}]}
{"op":"mcm","clk":"5346833736","pt":1646098291571,"mc":[{"id":"1.195395453","rc":[{"atl":[[2,9.01]],"id":42845264}],"con":true,"img":false}]}
{"op":"mcm","clk":"5346833778","pt":1646098293211,"mc":[{"id":"1.195395453","rc":[{"atl":[[16,6.66]],"id":43066392},{"atl":[[1.81,0]],"id":42845264}],"con":true,"img":false}]}
{"op":"mcm","clk":"5346833785","pt":1646098293369,"mc":[{"id":"1.195395453","rc":[{"atl":[[17.5,0]],"id":43066392}],"con":true,"img":false}]}
{"op":"mcm","clk":"5346833816","pt":1646098294393,"mc":[{"id":"1.195395453","rc":[{"atb":[[6.2,4.35]],"id":43066392}],"con":true,"img":false}]}
{"op":"mcm","clk":"5346833820","pt":1646098294495,"mc":[{"id":"1.195395453","rc":[{"atb":[[16,0]],"id":40324412},{"atb":[[6.6,0.16]],"id":43066392},{"atb":[[19,5.14]],"id":39586887}],"con":true,"img":false}]}
{"op":"mcm","clk":"5346833848","pt":1646098295312,"mc":[{"id":"1.195395453","rc":[{"atl":[[2,18.2]],"id":42845264}],"con":true,"img":false}]}
{"op":"mcm","clk":"5346833859","pt":1646098295673,"mc":[{"id":"1.195395453","rc":[{"atb":[[1.02,1.67]],"id":43066392},{"atl":[[1000,1.67]],"id":43154432}],"con":true,"img":false}]}
{"op":"mcm","clk":"5346833867","pt":1646098295878,"mc":[{"id":"1.195395453","rc":[{"atb":[[1.02,1.22]],"id":43066392},{"atl":[[1000,0.14]],"id":43154432}],"con":true,"img":false}]}
{"op":"mcm","clk":"5346833876","pt":1646098296085,"mc":[{"id":"1.195395453","rc":[{"atb":[[1.02,0]],"id":43066392}],"con":true,"img":false}]}
{"op":"mcm","clk":"5346833878","pt":1646098296187,"mc":[{"id":"1.195395453","rc":[{"atb":[[6.8,1.22]],"id":43066392}],"con":true,"img":false}]}
{"op":"mcm","clk":"5346833882","pt":1646098296393,"mc":[{"id":"1.195395453","rc":[{"atl":[[1.81,24.69]],"id":42845264}],"con":true,"img":false}]}
{"op":"mcm","clk":"5346833891","pt":1646098296700,"mc":[{"id":"1.195395453","rc":[{"atl":[[1000,0]],"id":43154432}],"con":true,"img":false}]}
{"op":"mcm","clk":"5346833893","pt":1646098296802,"mc":[{"id":"1.195395453","rc":[{"atl":[[60,0.14]],"id":43154432}],"con":true,"img":false}]}
{"op":"mcm","clk":"5346833896","pt":1646098296904,"mc":[{"id":"1.195395453","rc":[{"atb":[[6.8,0],[1.02,1.67]],"id":43066392}],"con":true,"img":false}]}
{"op":"mcm","clk":"5346833899","pt":1646098297006,"mc":[{"id":"1.195395453","rc":[{"atb":[[1.02,1.22]],"id":43066392}],"con":true,"img":false}]}
{"op":"mcm","clk":"5346833904","pt":1646098297212,"mc":[{"id":"1.195395453","rc":[{"atb":[[1.02,0]],"id":43066392}],"con":true,"img":false}]}
{"op":"mcm","clk":"5346833908","pt":1646098297313,"mc":[{"id":"1.195395453","rc":[{"atb":[[6.4,1.22]],"id":43066392}],"con":true,"img":false}]}
{"op":"mcm","clk":"5346833947","pt":1646098298496,"mc":[{"id":"1.195395453","rc":[{"atl":[[260,2]],"id":39586887}],"con":true,"img":false}]}
{"op":"mcm","clk":"5346833953","pt":1646098298599,"mc":[{"id":"1.195395453","rc":[{"atl":[[530,1],[550,1],[570,1],[310,2.64],[510,1]],"id":37076607},{"atb":[[9,0],[7,16.67]],"id":42901530},{"atb":[[4.3,30.3],[3.85,0]],"id":40612296},{"atl":[[130,3.02],[190,0],[220,1]],"id":40324412},{"atb":[[3.6,0],[4.4,29.41]],"id":43066392},{"atl":[[16,3.33],[18,13.23]],"id":43066392},{"atl":[[1.83,24.1],[1.81,0]],"id":42845264},{"atb":[[11.5,0],[9.8,11.49]],"id":43154432},{"atl":[[360,1],[780,0]],"id":39586887}],"con":true,"img":false}]}
{"op":"mcm","clk":"5346833957","pt":1646098298701,"mc":[{"id":"1.195395453","rc":[{"atl":[[230,0.86]],"id":40324412},{"atl":[[570,0]],"id":39586887}],"con":true,"img":false}]}
{"op":"mcm","clk":"5346833988","pt":1646098299623,"mc":[{"id":"1.195395453","rc":[{"atl":[[1.84,23.81],[1.82,0]],"id":42845264},{"atb":[[10.5,0]],"id":43154432}],"con":true,"img":false}]}
{"op":"mcm","clk":"5346834013","pt":1646098300291,"mc":[{"id":"1.195395453","rc":[{"atb":[[14.5,6.86]],"id":40324412},{"atb":[[6.4,9.84]],"id":43066392}],"con":true,"img":false}]}
{"op":"mcm","clk":"5346834039","pt":1646098301315,"mc":[{"id":"1.195395453","rc":[{"atb":[[10,13.46],[11,0]],"id":43154432}],"con":true,"img":false}]}
{"op":"mcm","clk":"5346834056","pt":1646098301828,"mc":[{"id":"1.195395453","rc":[{"atl":[[1.83,0]],"id":42845264}],"con":true,"img":false}]}
{"op":"mcm","clk":"5346834317","pt":1646098308493,"mc":[{"id":"1.195395453","rc":[{"atb":[[9.4,0]],"id":43154432},{"atl":[[380,1]],"id":39586887}],"con":true,"img":false}]}
{"op":"mcm","clk":"5346834319","pt":1646098308597,"mc":[{"id":"1.195395453","rc":[{"atb":[[9.4,5.95]],"id":43154432}],"con":true,"img":false}]}
{"op":"mcm","clk":"5346834342","pt":1646098309413,"mc":[{"id":"1.195395453","rc":[{"atl":[[840,0]],"id":39586887}],"con":true,"img":false}]}
{"op":"mcm","clk":"5346834354","pt":1646098309619,"mc":[{"id":"1.195395453","rc":[{"atb":[[1.16,250]],"id":42845264},{"atl":[[1.86,58.14]],"id":42845264}],"con":true,"img":false}]}
{"op":"mcm","clk":"5346834418","pt":1646098311314,"mc":[{"id":"1.195395453","rc":[{"atl":[[2.04,0]],"id":42845264}],"con":true,"img":false}]}
{"op":"mcm","clk":"5346834421","pt":1646098311414,"mc":[{"id":"1.195395453","rc":[{"atl":[[1.99,43.26]],"id":42845264}],"con":true,"img":false}]}
{"op":"mcm","clk":"5346834690","pt":1646098318501,"mc":[{"id":"1.195395453","rc":[{"atb":[[9,9.38]],"id":43154432},{"atl":[[400,1]],"id":39586887}],"con":true,"img":false}]}
{"op":"mcm","clk":"5346834727","pt":1646098319628,"mc":[{"id":"1.195395453","rc":[{"atb":[[1.14,250]],"id":42845264},{"atl":[[1.88,85.23]],"id":42845264}],"con":true,"img":false}]}
{"op":"mcm","clk":"5346834756","pt":1646098320753,"mc":[{"id":"1.195395453","rc":[{"atb":[[9.2,2.44],[10.5,0],[11.5,15.45],[12.5,0],[9.6,11.63]],"id":37076607},{"atb":[[9.2,0],[9.4,2.38]],"id":42901530},{"atl":[[34,0],[38,3.57],[42,0],[44,2.33],[190,1],[28,0],[30,0]],"id":40612296},{"atl":[[15,0],[16,0],[17,0],[17.5,1.21],[18,7.35],[20,5.26]],"id":43066392},{"atb":[[1.2,0],[1.18,0],[1.08,1250],[1.16,125],[1.17,477.22]],"id":42845264},{"atb":[[4.6,27.78]],"id":43154432},{"atb":[[10.5,17.08],[15.5,9.77]],"id":39586887},{"atl":[[820,0]],"id":39586887}],"con":true,"img":false}]}
{"op":"mcm","clk":"5346834761","pt":1646098320809,"mc":[{"id":"1.195395453","rc":[{"atb":[[5.4,0]],"id":43154432}],"con":true,"img":false}]}
{"op":"mcm","clk":"5346834779","pt":1646098321321,"mc":[{"id":"1.195395453","rc":[{"atl":[[27,0]],"id":40612296},{"atl":[[100,0]],"id":40324412},{"atl":[[16.5,0]],"id":43066392},{"atb":[[1.21,0]],"id":42845264}],"con":true,"img":false}]}
{"op":"mcm","clk":"5346834782","pt":1646098321425,"mc":[{"id":"1.195395453","rc":[{"atl":[[34,2.7]],"id":40612296},{"atl":[[95,0.48]],"id":40324412},{"atl":[[17.5,3.91]],"id":43066392},{"atb":[[1.18,685.09]],"id":42845264}],"con":true,"img":false}]}
{"op":"mcm","clk":"5346834910","pt":1646098325626,"mc":[{"id":"1.195395453","rc":[{"atb":[[9.8,0]],"id":37076607}],"con":true,"img":false}]}
{"op":"mcm","clk":"5346834913","pt":1646098325751,"mc":[{"id":"1.195395453","rc":[{"atl":[[14.5,0],[1000,1.67]],"id":43066392}],"con":true,"img":false}]}
{"op":"mcm","clk":"5346834920","pt":1646098325937,"mc":[{"id":"1.195395453","rc":[{"atl":[[1000,0.57]],"id":43066392}],"con":true,"img":false}]}
{"op":"mcm","clk":"5346834927","pt":1646098326137,"mc":[{"id":"1.195395453","rc":[{"atl":[[1000,0]],"id":43066392}],"con":true,"img":false}]}
{"op":"mcm","clk":"5346834932","pt":1646098326240,"mc":[{"id":"1.195395453","rc":[{"atl":[[17,0.57]],"id":43066392}],"con":true,"img":false}]}
{"op":"mcm","clk":"5346834973","pt":1646098327223,"mc":[{"id":"1.195395453","rc":[{"atl":[[21,0],[26,4.87]],"id":43066392}],"con":true,"img":false}]}
{"op":"mcm","clk":"5346834978","pt":1646098327324,"mc":[{"id":"1.195395453","rc":[{"atl":[[200,0]],"id":37076607},{"atl":[[200,0]],"id":42901530},{"atl":[[190,0]],"id":39586887}],"con":true,"img":false}]}
{"op":"mcm","clk":"5346834982","pt":1646098327477,"mc":[{"id":"1.195395453","rc":[{"atl":[[250,2.7]],"id":37076607},{"atl":[[250,2.7]],"id":42901530},{"atl":[[240,2.7]],"id":39586887}],"con":true,"img":false}]}
{"op":"mcm","clk":"5346835030","pt":1646098328453,"mc":[{"id":"1.195395453","rc":[{"atb":[[9.4,0]],"id":37076607}],"con":true,"img":false}]}
{"op":"mcm","clk":"5346835036","pt":1646098328555,"mc":[{"id":"1.195395453","rc":[{"atb":[[8.6,16.45]],"id":43154432}],"con":true,"img":false}]}
{"op":"mcm","clk":"5346835121","pt":1646098330759,"mc":[{"id":"1.195395453","rc":[{"atb":[[8.8,6.41]],"id":37076607},{"atl":[[210,1]],"id":40612296},{"atl":[[18.5,10.41]],"id":43066392},{"atb":[[1.12,1264.11]],"id":42845264},{"atl":[[1.9,138.89]],"id":42845264},{"atb":[[14.5,3.7]],"id":39586887},{"atl":[[420,1]],"id":39586887}],"con":true,"img":false}]}
{"op":"mcm","clk":"5346835135","pt":1646098331223,"mc":[{"id":"1.195395453","rc":[{"atl":[[150,0]],"id":42901530},{"atl":[[36,0]],"id":40612296},{"atl":[[90,0]],"id":43154432}],"con":true,"img":false}]}
{"op":"mcm","clk":"5346835138","pt":1646098331325,"mc":[{"id":"1.195395453","rc":[{"atl":[[160,1.1],[210,2.63]],"id":42901530},{"atl":[[42,3.78]],"id":40612296},{"atl":[[130,2.7]],"id":43154432}],"con":true,"img":false}]}
{"op":"mcm","clk":"5346835142","pt":1646098331428,"mc":[{"id":"1.195395453","rc":[{"atl":[[170,0]],"id":42901530}],"con":true,"img":false}]}
{"op":"mcm","clk":"5346835217","pt":1646098333129,"mc":[{"id":"1.195395453","rc":[{"atb":[[9,0]],"id":39586887},{"atl":[[800,0]],"id":39586887}],"con":true,"img":false}]}
{"op":"mcm","clk":"5346835479","pt":1646098340160,"mc":[{"id":"1.195395453","rc":[{"atl":[[160,3.1],[210,0.63]],"id":42901530},{"spn":8.01,"spf":1.0,"id":40612296},{"spn":6.4,"spf":1.0,"id":43066392},{"spn":1.64,"spf":1.0,"id":42845264},{"spn":36.75,"spf":1.0,"id":43154432}],"con":true,"img":false}]}
{"op":"mcm","clk":"5346835503","pt":1646098340773,"mc":[{"id":"1.195395453","rc":[{"atb":[[8.4,10.14]],"id":37076607},{"atl":[[230,1]],"id":40612296},{"atl":[[19.5,4.05]],"id":43066392},{"atb":[[1.1,250]],"id":42845264},{"atb":[[9.6,2.33],[9.8,9.22]],"id":43154432},{"atb":[[13.5,6]],"id":39586887}],"con":true,"img":false}]}
{"op":"mcm","clk":"5346835531","pt":1646098341361,"mc":[{"id":"1.195395453","rc":[{"atb":[[13.5,0]],"id":40324412},{"atl":[[17.5,1.21]],"id":43066392},{"atl":[[1.99,0]],"id":42845264},{"atb":[[18.5,0]],"id":39586887}],"con":true,"img":false}]}
{"op":"mcm","clk":"5346835536","pt":1646098341462,"mc":[{"id":"1.195395453","rc":[{"atb":[[15,8.65]],"id":40324412},{"atl":[[18,10.05]],"id":43066392},{"atl":[[1.87,43.26]],"id":42845264},{"atb":[[19.5,6.5]],"id":39586887}],"con":true,"img":false}]}
{"op":"mcm","clk":"5346835676","pt":1646098345264,"mc":[{"id":"1.195395453","rc":[{"atb":[[9.6,0],[9.8,11.49]],"id":43154432},{"atb":[[9.4,0]],"id":39586887}],"con":true,"img":false}]}
{"op":"mcm","clk":"5346835683","pt":1646098345465,"mc":[{"id":"1.195395453","rc":[{"atb":[[14.5,0]],"id":40324412},{"atb":[[19,0]],"id":39586887}],"con":true,"img":false}]}
{"op":"mcm","clk":"5346835831","pt":1646098348750,"mc":[{"id":"1.195395453","rc":[{"atb":[[9.6,2.33],[9.8,9.22]],"id":43154432}],"con":true,"img":false}]}
{"op":"mcm","clk":"5346835854","pt":1646098349465,"mc":[{"id":"1.195395453","rc":[{"atb":[[16,5.4]],"id":40324412}],"con":true,"img":false}]}
{"op":"mcm","clk":"5346835899","pt":1646098350749,"mc":[{"id":"1.195395453","rc":[{"atb":[[8,17.86]],"id":37076607},{"atl":[[250,1]],"id":40612296},{"atl":[[21,6.25]],"id":43066392},{"atb":[[12.5,10.87]],"id":39586887}],"con":true,"img":false}]}
{"op":"mcm","clk":"5346835924","pt":1646098351362,"mc":[{"id":"1.195395453","rc":[{"atb":[[15,0]],"id":40324412},{"atb":[[19.5,0]],"id":39586887}],"con":true,"img":false}]}
{"op":"mcm","clk":"5346835928","pt":1646098351466,"mc":[{"id":"1.195395453","rc":[{"atb":[[13.5,8.65]],"id":40324412},{"atb":[[18.5,6.5]],"id":39586887}],"con":true,"img":false}]}
{"op":"mcm","clk":"5346836020","pt":1646098353776,"mc":[{"id":"1.195395453","rc":[{"atl":[[18,2.7]],"id":43066392},{"atb":[[9.6,0],[9.8,11.49]],"id":43154432},{"atb":[[9.8,0]],"id":39586887}],"con":true,"img":false}]}
{"op":"mcm","clk":"5346836076","pt":1646098355470,"mc":[{"id":"1.195395453","rc":[{"atb":[[16,0]],"id":40324412},{"atb":[[19,5.14]],"id":39586887}],"con":true,"img":false}]}
{"op":"mcm","clk":"5346836085","pt":1646098355776,"mc":[{"id":"1.195395453","rc":[{"atl":[[1000,1.67]],"id":40612296},{"atb":[[6.4,8.61],[1.02,1.67]],"id":43066392}],"con":true,"img":false}]}
{"op":"mcm","clk":"5346836094","pt":1646098355980,"mc":[{"id":"1.195395453","rc":[{"atl":[[1000,0.3]],"id":40612296},{"atb":[[1.02,1.22]],"id":43066392}],"con":true,"img":false}]}
{"op":"mcm","clk":"5346836099","pt":1646098356083,"mc":[{"id":"1.195395453","rc":[{"atl":[[1000,0]],"id":40612296}],"con":true,"img":false}]}
{"op":"mcm","clk":"5346836108","pt":1646098356186,"mc":[{"id":"1.195395453","rc":[{"atl":[[28,0.3]],"id":40612296}],"con":true,"img":false}]}
{"op":"mcm","clk":"5346836117","pt":1646098356390,"mc":[{"id":"1.195395453","rc":[{"atb":[[1.02,0]],"id":43066392}],"con":true,"img":false}]}
{"op":"mcm","clk":"5346836122","pt":1646098356494,"mc":[{"id":"1.195395453","rc":[{"atb":[[6.8,1.22]],"id":43066392},{"atb":[[9.6,2.33],[9.8,9.22]],"id":43154432}],"con":true,"img":false}]}
{"op":"mcm","clk":"5346836246","pt":1646098359576,"mc":[{"id":"1.195395453","rc":[{"atb":[[14.5,6.86]],"id":40324412}],"con":true,"img":false}]}
{"op":"mcm","clk":"5346836294","pt":1646098361061,"mc":[{"id":"1.195395453","rc":[{"atl":[[1.83,24.1]],"id":42845264},{"atb":[[10,15.68],[9.6,0],[9.8,11.49]],"id":43154432}],"con":true,"img":false}]}
{"op":"mcm","clk":"5346836298","pt":1646098361166,"mc":[{"id":"1.195395453","rc":[{"atl":[[1.84,0]],"id":42845264}],"con":true,"img":false}]}
{"op":"mcm","clk":"5346836305","pt":1646098361269,"mc":[{"id":"1.195395453","rc":[{"atl":[[160,2.83]],"id":42901530}],"con":true,"img":false}]}
{"op":"mcm","clk":"5346836308","pt":1646098361370,"mc":[{"id":"1.195395453","rc":[{"atl":[[150,0.27],[160,0.83],[240,2]],"id":42901530}],"con":true,"img":false}]}
{"op":"mcm","clk":"5346836329","pt":1646098362086,"mc":[{"id":"1.195395453","rc":[{"atl":[[130,1.02],[110,2]],"id":40324412},{"atb":[[4.4,0],[3.9,34.48]],"id":43066392},{"atl":[[18,6.75],[20,0]],"id":43066392},{"atl":[[1.83,0],[1.9,22.22]],"id":42845264},{"atb":[[10,13.46],[9.6,2.33]],"id":43154432},{"atl":[[260,0],[220,2]],"id":39586887}],"con":true,"img":false}]}
{"op":"mcm","clk":"5346836399","pt":1646098363675,"mc":[{"id":"1.195395453","rc":[{"atl":[[1.86,0]],"id":42845264},{"atb":[[9.8,9.22]],"id":43154432}],"con":true,"img":false}]}
{"op":"mcm","clk":"5346836424","pt":1646098364396,"mc":[{"id":"1.195395453","rc":[{"atl":[[2.06,0],[1.88,0],[1.91,21.98],[2.18,84.75]],"id":42845264},{"atb":[[9.4,2.38],[9.6,0]],"id":43154432}],"con":true,"img":false}]}
{"op":"mcm","clk":"5346836613","pt":1646098368710,"mc":[{"id":"1.195395453","rc":[{"atb":[[9.6,2.33]],"id":43154432}],"con":true,"img":false}]}
{"op":"mcm","clk":"5346836649","pt":1646098369894,"mc":[{"id":"1.195395453","rc":[{"atl":[[210,2.63]],"id":42901530}],"con":true,"img":false}]}
{"op":"mcm","clk":"5346836653","pt":1646098369997,"mc":[{"id":"1.195395453","rc":[{"atl":[[240,0]],"id":42901530}],"con":true,"img":false}]}
{"op":"mcm","clk":"5346836700","pt":1646098371282,"mc":[{"id":"1.195395453","rc":[{"atl":[[150,0]],"id":42901530},{"atb":[[4.6,0]],"id":43066392},{"atl":[[1.87,0]],"id":42845264}],"con":true,"img":false}]}
{"op":"mcm","clk":"5346836704","pt":1646098371385,"mc":[{"id":"1.195395453","rc":[{"atl":[[170,0.27]],"id":42901530},{"atb":[[4.8,32.09]],"id":43066392},{"atl":[[1.89,43.26]],"id":42845264}],"con":true,"img":false}]}
{"op":"mcm","clk":"5346836755","pt":1646098372823,"mc":[{"id":"1.195395453","rc":[{"atl":[[1.9,0]],"id":42845264},{"atb":[[9.6,0]],"id":43154432}],"con":true,"img":false}]}
{"op":"mcm","clk":"5346836817","pt":1646098374420,"mc":[{"id":"1.195395453","rc":[{"atl":[[1.9,22.22]],"id":42845264}],"con":true,"img":false}]}
{"op":"mcm","clk":"5346836900","pt":1646098376791,"mc":[{"id":"1.195395453","rc":[{"atb":[[9.6,2.33]],"id":43154432}],"con":true,"img":false}]}
{"op":"mcm","clk":"5346837089","pt":1646098381320,"mc":[{"id":"1.195395453","rc":[{"atl":[[1.9,0]],"id":42845264},{"atb":[[9.6,0]],"id":43154432},{"atb":[[22,0.49]],"id":39586887}],"con":true,"img":false}]}
{"op":"mcm","clk":"5346837092","pt":1646098381421,"mc":[{"id":"1.195395453","rc":[{"atb":[[23,2.7]],"id":39586887}],"con":true,"img":false}]}
{"op":"mcm","clk":"5346837209","pt":1646098384402,"mc":[{"id":"1.195395453","rc":[{"atl":[[1.9,22.22]],"id":42845264},{"atb":[[9.6,2.33]],"id":43154432}],"con":true,"img":false}]}
{"op":"mcm","clk":"5346837236","pt":1646098385221,"mc":[{"id":"1.195395453","rc":[{"atb":[[19,0]],"id":39586887}],"con":true,"img":false}]}
{"op":"mcm","clk":"5346837435","pt":1646098389832,"mc":[{"id":"1.195395453","rc":[{"atl":[[1.9,0]],"id":42845264}],"con":true,"img":false}]}
{"op":"mcm","clk":"5346837442","pt":1646098389932,"mc":[{"id":"1.195395453","rc":[{"atb":[[9.6,0]],"id":43154432}],"con":true,"img":false}]}
{"op":"mcm","clk":"5346837495","pt":1646098391320,"mc":[{"id":"1.195395453","rc":[{"atl":[[95,0]],"id":40324412},{"atl":[[1.89,0]],"id":42845264}],"con":true,"img":false}]}
{"op":"mcm","clk":"5346837498","pt":1646098391422,"mc":[{"id":"1.195395453","rc":[{"atl":[[85,0.58]],"id":40324412},{"atl":[[1.9,43.26]],"id":42845264}],"con":true,"img":false}]}
{"op":"mcm","clk":"5346837550","pt":1646098392609,"mc":[{"id":"1.195395453","rc":[{"atl":[[1.9,65.48]],"id":42845264},{"atb":[[9.6,2.33]],"id":43154432}],"con":true,"img":false}]}
{"op":"mcm","clk":"5346837714","pt":1646098397838,"mc":[{"id":"1.195395453","rc":[{"atb":[[9.6,0]],"id":43154432}],"con":true,"img":false}]}
{"op":"mcm","clk":"5346837718","pt":1646098397942,"mc":[{"id":"1.195395453","rc":[{"atl":[[1.9,43.26]],"id":42845264}],"con":true,"img":false}]}
{"op":"mcm","clk":"5346837823","pt":1646098400524,"mc":[{"id":"1.195395453","rc":[{"spn":6.49,"spf":1.0,"id":43066392},{"atl":[[1.9,65.48]],"id":42845264},{"atb":[[9.6,2.33]],"id":43154432},{"spn":61.5,"spf":1.0,"id":39586887}],"con":true,"img":false}]}
{"op":"mcm","clk":"5346837843","pt":1646098401240,"mc":[{"id":"1.195395453","rc":[{"atl":[[34,0]],"id":40612296},{"atb":[[13.5,0]],"id":40324412},{"atl":[[2.24,0]],"id":42845264},{"atb":[[18.5,0],[22,5.9]],"id":39586887}],"con":true,"img":false}]}
{"op":"mcm","clk":"5346837846","pt":1646098401343,"mc":[{"id":"1.195395453","rc":[{"atl":[[28,3]],"id":40612296},{"atb":[[15,8.65]],"id":40324412},{"atl":[[2.16,99.44]],"id":42845264},{"atb":[[22,0.49]],"id":39586887}],"con":true,"img":false}]}
{"op":"mcm","clk":"5346837850","pt":1646098401444,"mc":[{"id":"1.195395453","rc":[{"atb":[[19,5.41]],"id":39586887}],"con":true,"img":false}]}
{"op":"mcm","clk":"5346837951","pt":1646098404833,"mc":[{"id":"1.195395453","rc":[{"atb":[[14.5,0]],"id":40324412}],"con":true,"img":false}]}
{"op":"mcm","clk":"5346837980","pt":1646098405855,"mc":[{"id":"1.195395453","rc":[{"atl":[[1.9,43.26]],"id":42845264},{"atb":[[9.6,0]],"id":43154432}],"con":true,"img":false}]}
{"op":"mcm","clk":"5346838076","pt":1646098408632,"mc":[{"id":"1.195395453","rc":[{"atb":[[16,5.4]],"id":40324412}],"con":true,"img":false}]}
{"op":"mcm","clk":"5346838080","pt":1646098408760,"mc":[{"id":"1.195395453","rc":[{"atl":[[1.9,65.48]],"id":42845264},{"atb":[[9.6,2.33]],"id":43154432}],"con":true,"img":false}]}
{"op":"mcm","clk":"5346838087","pt":1646098408961,"mc":[{"id":"1.195395453","rc":[{"atl":[[2,9.19]],"id":42845264}],"con":true,"img":false}]}
{"op":"mcm","clk":"5346838101","pt":1646098409220,"mc":[{"id":"1.195395453","rc":[{"atb":[[6.8,0],[1.02,1.67]],"id":43066392}],"con":true,"img":false}]}
{"op":"mcm","clk":"5346838106","pt":1646098409322,"mc":[{"id":"1.195395453","rc":[{"atb":[[1.02,3.34]],"id":43066392}],"con":true,"img":false}]}
{"op":"mcm","clk":"5346838118","pt":1646098409630,"mc":[{"id":"1.195395453","rc":[{"atb":[[1.02,2.86]],"id":43066392}],"con":true,"img":false}]}
{"op":"mcm","clk":"5346838128","pt":1646098409834,"mc":[{"id":"1.195395453","rc":[{"atb":[[1.02,1.67]],"id":43066392}],"con":true,"img":false}]}
{"op":"mcm","clk":"5346838132","pt":1646098409938,"mc":[{"id":"1.195395453","rc":[{"atb":[[7,1.19]],"id":43066392}],"con":true,"img":false}]}
{"op":"mcm","clk":"5346838174","pt":1646098411324,"mc":[{"id":"1.195395453","rc":[{"atl":[[180,0],[250,0]],"id":37076607},{"atl":[[250,0]],"id":42901530},{"atl":[[42,0]],"id":40612296},{"atb":[[15,0]],"id":40324412},{"atl":[[120,0]],"id":40324412},{"atl":[[130,0]],"id":43154432},{"atl":[[240,0]],"id":39586887}],"con":true,"img":false}]}
{"op":"mcm","clk":"5346838177","pt":1646098411428,"mc":[{"id":"1.195395453","rc":[{"atl":[[170,0.27],[200,2.7]],"id":37076607},{"atl":[[200,2.7]],"id":42901530},{"atl":[[36,3.78]],"id":40612296},{"atb":[[14.5,8.65]],"id":40324412},{"atl":[[100,2.7]],"id":40324412},{"atl":[[90,2.7]],"id":43154432},{"atl":[[140,2.7]],"id":39586887}],"con":true,"img":false}]}
{"op":"mcm","clk":"5346838181","pt":1646098411529,"mc":[{"id":"1.195395453","rc":[{"atl":[[190,2],[210,0.63]],"id":42901530}],"con":true,"img":false}]}
{"op":"mcm","clk":"5346838191","pt":1646098411839,"mc":[{"id":"1.195395453","rc":[{"atl":[[1.87,9.64]],"id":42845264}],"con":true,"img":false}]}
{"op":"mcm","clk":"5346838235","pt":1646098412867,"mc":[{"id":"1.195395453","rc":[{"atl":[[2,0]],"id":42845264}],"con":true,"img":false}]}
{"op":"mcm","clk":"5346838246","pt":1646098413131,"mc":[{"id":"1.195395453","rc":[{"atl":[[1.9,43.26]],"id":42845264},{"atb":[[9.6,0]],"id":43154432}],"con":true,"img":false}]}
{"op":"mcm","clk":"5346838314","pt":1646098415026,"mc":[{"id":"1.195395453","rc":[{"atl":[[1.8,0]],"id":42845264}],"con":true,"img":false}]}
{"op":"mcm","clk":"5346838371","pt":1646098416668,"mc":[{"id":"1.195395453","rc":[{"atl":[[1.9,65.48]],"id":42845264},{"atb":[[9.6,2.33]],"id":43154432}],"con":true,"img":false}]}
{"op":"mcm","clk":"5346838442","pt":1646098418674,"mc":[{"id":"1.195395453","rc":[{"atl":[[1.97,20.62],[1.9,43.26],[1.87,19.48]],"id":42845264},{"atb":[[9.2,2.44],[9.6,0]],"id":43154432}],"con":true,"img":false}]}
{"op":"mcm","clk":"5346838475","pt":1646098419539,"mc":[{"id":"1.195395453","rc":[{"atl":[[1.96,20.83],[1.91,0]],"id":42845264}],"con":true,"img":false}]}
{"op":"mcm","clk":"5346838479","pt":1646098419641,"mc":[{"id":"1.195395453","rc":[{"atb":[[1.02,3.34],[7,0]],"id":43066392}],"con":true,"img":false}]}
{"op":"mcm","clk":"5346838483","pt":1646098419744,"mc":[{"id":"1.195395453","rc":[{"atb":[[1.02,2.86]],"id":43066392}],"con":true,"img":false}]}
{"op":"mcm","clk":"5346838490","pt":1646098419949,"mc":[{"id":"1.195395453","rc":[{"atb":[[1.02,1.67]],"id":43066392}],"con":true,"img":false}]}
{"op":"mcm","clk":"5346838496","pt":1646098420052,"mc":[{"id":"1.195395453","rc":[{"atb":[[6.8,1.19]],"id":43066392}],"con":true,"img":false}]}
{"op":"mcm","clk":"5346838499","pt":1646098420153,"mc":[{"id":"1.195395453","rc":[{"atb":[[1.02,3.34]],"id":43066392}],"con":true,"img":false}]}
{"op":"mcm","clk":"5346838503","pt":1646098420256,"mc":[{"id":"1.195395453","rc":[{"atb":[[6.8,0]],"id":43066392}],"con":true,"img":false}]}
{"op":"mcm","clk":"5346838507","pt":1646098420359,"mc":[{"id":"1.195395453","rc":[{"atb":[[1.02,4.5]],"id":43066392}],"con":true,"img":false}]}
{"op":"mcm","clk":"5346838512","pt":1646098420460,"mc":[{"id":"1.195395453","rc":[{"atb":[[1.02,2.83]],"id":43066392}],"con":true,"img":false}]}
{"op":"mcm","clk":"5346838515","pt":1646098420561,"mc":[{"id":"1.195395453","rc":[{"atb":[[1.02,1.67]],"id":43066392}],"con":true,"img":false}]}
{"op":"mcm","clk":"5346838519","pt":1646098420666,"mc":[{"id":"1.195395453","rc":[{"atl":[[110,0],[120,2]],"id":40324412},{"atb":[[7.2,1.16]],"id":43066392}],"con":true,"img":false}]}
{"op":"mcm","clk":"5346838526","pt":1646098420768,"mc":[{"id":"1.195395453","rc":[{"atb":[[9.4,0]],"id":43154432}],"con":true,"img":false}]}
{"op":"mcm","clk":"5346838528","pt":1646098420867,"mc":[{"id":"1.195395453","rc":[{"atb":[[1.02,1.16]],"id":43066392}],"con":true,"img":false}]}
{"op":"mcm","clk":"5346838534","pt":1646098420971,"mc":[{"id":"1.195395453","rc":[{"atl":[[1.86,4.4]],"id":42845264}],"con":true,"img":false}]}
{"op":"mcm","clk":"5346838539","pt":1646098421073,"mc":[{"id":"1.195395453","rc":[{"atb":[[1.02,0]],"id":43066392}],"con":true,"img":false}]}
{"op":"mcm","clk":"5346838545","pt":1646098421175,"mc":[{"id":"1.195395453","rc":[{"atb":[[7.2,2.32]],"id":43066392}],"con":true,"img":false}]}
{"op":"mcm","clk":"5346838553","pt":1646098421331,"mc":[{"id":"1.195395453","rc":[{"atl":[[100,0]],"id":40324412},{"atl":[[1.9,0]],"id":42845264}],"con":true,"img":false}]}
{"op":"mcm","clk":"5346838557","pt":1646098421434,"mc":[{"id":"1.195395453","rc":[{"atl":[[110,2.7]],"id":40324412},{"atl":[[1.89,43.26]],"id":42845264}],"con":true,"img":false}]}
{"op":"mcm","clk":"5346838596","pt":1646098422361,"mc":[{"id":"1.195395453","rc":[{"atb":[[9.4,2.38]],"id":43154432}],"con":true,"img":false}]}
{"op":"mcm","clk":"5346838677","pt":1646098424158,"mc":[{"id":"1.195395453","rc":[{"atb":[[6.4,0]],"id":43066392}],"con":true,"img":false}]}
{"op":"mcm","clk":"5346838684","pt":1646098424262,"mc":[{"id":"1.195395453","rc":[{"atb":[[6.2,0]],"id":43066392}],"con":true,"img":false}]}
{"op":"mcm","clk":"5346838830","pt":1646098428056,"mc":[{"id":"1.195395453","rc":[{"atb":[[6.2,6.97]],"id":43066392}],"con":true,"img":false}]}
{"op":"mcm","clk":"5346838860","pt":1646098428567,"mc":[{"id":"1.195395453","rc":[{"atl":[[110,4.7],[120,0]],"id":40324412}],"con":true,"img":false}]}
{"op":"mcm","clk":"5346838882","pt":1646098428980,"mc":[{"id":"1.195395453","rc":[{"atb":[[9.4,0]],"id":43154432}],"con":true,"img":false}]}
{"op":"mcm","clk":"5346838908","pt":1646098429547,"mc":[{"id":"1.195395453","rc":[{"atb":[[6.2,9.99]],"id":43066392},{"atl":[[1.98,51.02]],"id":42845264}],"con":true,"img":false}]}
{"op":"mcm","clk":"5346838982","pt":1646098431386,"mc":[{"id":"1.195395453","rc":[{"atl":[[28,0.3]],"id":40612296},{"atl":[[1.89,0]],"id":42845264}],"con":true,"img":false}]}
{"op":"mcm","clk":"5346838985","pt":1646098431488,"mc":[{"id":"1.195395453","rc":[{"atl":[[34,2.7]],"id":40612296},{"atl":[[1.95,43.26]],"id":42845264}],"con":true,"img":false}]}
{"op":"mcm","clk":"5346839021","pt":1646098432365,"mc":[{"id":"1.195395453","rc":[{"atb":[[9.4,2.38]],"id":43154432}],"con":true,"img":false}]}
{"op":"mcm","clk":"5346839028","pt":1646098432469,"mc":[{"id":"1.195395453","rc":[{"atb":[[9.2,0],[8.6,2.63]],"id":37076607},{"atl":[[32,1],[44,0],[190,0],[29,8.29]],"id":40612296},{"atl":[[17.5,0],[14,1.54]],"id":43066392},{"atb":[[1.2,577.23],[1.08,0],[1.16,0]],"id":42845264},{"atb":[[14.5,1.48],[15.5,8.39]],"id":39586887}],"con":true,"img":false}]}
{"op":"mcm","clk":"5346839033","pt":1646098432570,"mc":[{"id":"1.195395453","rc":[{"atl":[[16,6.67],[18,2.7]],"id":43066392}],"con":true,"img":false}]}
{"op":"mcm","clk":"5346839075","pt":1646098433693,"mc":[{"id":"1.195395453","rc":[{"atl":[[130,3.02],[110,2.7]],"id":40324412}],"con":true,"img":false}]}
{"op":"mcm","clk":"5346839203","pt":1646098436882,"mc":[{"id":"1.195395453","rc":[{"atb":[[8.8,0]],"id":37076607},{"atb":[[9.4,0]],"id":43154432}],"con":true,"img":false}]}
{"op":"mcm","clk":"5346839241","pt":1646098437701,"mc":[{"id":"1.195395453","rc":[{"atl":[[17,6.82]],"id":43066392}],"con":true,"img":false}]}
{"op":"mcm","clk":"5346839249","pt":1646098437861,"mc":[{"id":"1.195395453","rc":[{"atl":[[16,0]],"id":43066392}],"con":true,"img":false}]}
{"op":"mcm","clk":"5346839388","pt":1646098441297,"mc":[{"id":"1.195395453","rc":[{"atb":[[9.4,2.38]],"id":43154432}],"con":true,"img":false}]}
{"op":"mcm","clk":"5346839394","pt":1646098441398,"mc":[{"id":"1.195395453","rc":[{"atl":[[170,0]],"id":42901530},{"atb":[[15.5,0]],"id":40324412},{"atl":[[110,0]],"id":40324412}],"con":true,"img":false}]}
{"op":"mcm","clk":"5346839399","pt":1646098441501,"mc":[{"id":"1.195395453","rc":[{"atl":[[150,0.27]],"id":42901530},{"atb":[[16.5,2.98]],"id":40324412},{"atl":[[120,2.7]],"id":40324412}],"con":true,"img":false}]}
{"op":"mcm","clk":"5346839451","pt":1646098442481,"mc":[{"id":"1.195395453","rc":[{"atb":[[8.2,6.94]],"id":37076607},{"atl":[[36,5.21]],"id":40612296},{"atl":[[15,3.57]],"id":43066392},{"atb":[[1.18,935.09]],"id":42845264},{"atl":[[2,75]],"id":42845264},{"atb":[[13.5,4]],"id":39586887}],"con":true,"img":false}]}
{"op":"mcm","clk":"5346839550","pt":1646098444586,"mc":[{"id":"1.195395453","rc":[{"atl":[[250,0]],"id":40612296},{"atl":[[18.5,7.55],[19.5,0],[21,0]],"id":43066392},{"atb":[[1.1,0]],"id":42845264},{"atb":[[9.4,0]],"id":43154432}],"con":true,"img":false}]}
{"op":"mcm","clk":"5346839579","pt":1646098445200,"mc":[{"id":"1.195395453","rc":[{"atb":[[16,0]],"id":40324412}],"con":true,"img":false}]}
{"op":"mcm","clk":"5346839767","pt":1646098449206,"mc":[{"id":"1.195395453","rc":[{"atb":[[15,6.62]],"id":40324412}],"con":true,"img":false}]}
{"op":"mcm","clk":"5346839772","pt":1646098449310,"mc":[{"id":"1.195395453","rc":[{"atb":[[9.4,2.38]],"id":43154432}],"con":true,"img":false}]}
{"op":"mcm","clk":"5346839851","pt":1646098451307,"mc":[{"id":"1.195395453","rc":[{"atl":[[200,0]],"id":42901530},{"atb":[[6.2,0]],"id":40612296},{"atb":[[16.5,0]],"id":40324412},{"atb":[[19,0]],"id":39586887}],"con":true,"img":false}]}
{"op":"mcm","clk":"5346839856","pt":1646098451408,"mc":[{"id":"1.195395453","rc":[{"atl":[[180,2.7]],"id":42901530},{"atb":[[6.6,24.87]],"id":40612296},{"atb":[[15.5,2.98]],"id":40324412},{"atb":[[22,5.9]],"id":39586887}],"con":true,"img":false}]}
{"op":"mcm","clk":"5346839863","pt":1646098451510,"mc":[{"id":"1.195395453","rc":[{"atl":[[170,2]],"id":42901530}],"con":true,"img":false}]}
{"op":"mcm","clk":"5346839867","pt":1646098451613,"mc":[{"id":"1.195395453","rc":[{"atl":[[190,0]],"id":42901530}],"con":true,"img":false}]}
{"op":"mcm","clk":"5346839908","pt":1646098452491,"mc":[{"id":"1.195395453","rc":[{"atb":[[7.8,11.03]],"id":37076607},{"atl":[[40,1.92]],"id":40612296},{"atl":[[16,5]],"id":43066392},{"atb":[[1.16,250]],"id":42845264},{"atl":[[2.04,120.19]],"id":42845264},{"atb":[[12.5,6.52]],"id":39586887}],"con":true,"img":false}]}
{"op":"mcm","clk":"5346839912","pt":1646098452592,"mc":[{"id":"1.195395453","rc":[{"atl":[[16,11.67],[17,0.57]],"id":43066392}],"con":true,"img":false}]}
{"op":"mcm","clk":"5346839921","pt":1646098452696,"mc":[{"id":"1.195395453","rc":[{"atb":[[8,0],[8.4,0]],"id":37076607},{"atl":[[230,0]],"id":40612296},{"atb":[[1.12,1014.11]],"id":42845264},{"atl":[[1.97,0]],"id":42845264},{"atb":[[9.4,0]],"id":43154432}],"con":true,"img":false}]}
{"op":"mcm","clk":"5346839976","pt":1646098453821,"mc":[{"id":"1.195395453","rc":[{"atb":[[9.4,2.38]],"id":43154432}],"con":true,"img":false}]}
{"op":"mcm","clk":"5346840324","pt":1646098461311,"mc":[{"id":"1.195395453","rc":[{"atl":[[200,0]],"id":37076607},{"atl":[[150,0]],"id":42901530},{"atl":[[85,0.1]],"id":40324412},{"atl":[[18,0]],"id":43066392},{"spn":6.64,"spf":1.0,"id":43066392},{"spn":1.67,"spf":1.0,"id":42845264},{"atl":[[90,0]],"id":43154432},{"atl":[[140,0]],"id":39586887}],"con":true,"img":false}]}
{"op":"mcm","clk":"5346840328","pt":1646098461416,"mc":[{"id":"1.195395453","rc":[{"atl":[[250,2.7]],"id":37076607},{"atl":[[160,1.1]],"id":42901530},{"atl":[[95,0.48]],"id":40324412},{"atl":[[16.5,2.7]],"id":43066392},{"atb":[[9.4,0]],"id":43154432},{"atl":[[130,2.7]],"id":43154432},{"atl":[[210,4.7],[220,0]],"id":39586887}],"con":true,"img":false}]}
{"op":"mcm","clk":"5346840333","pt":1646098461517,"mc":[{"id":"1.195395453","rc":[{"atl":[[1000,1.67]],"id":43154432}],"con":true,"img":false}]}
{"op":"mcm","clk":"5346840339","pt":1646098461619,"mc":[{"id":"1.195395453","rc":[{"atl":[[60,0]],"id":43154432}],"con":true,"img":false}]}
{"op":"mcm","clk":"5346840343","pt":1646098461721,"mc":[{"id":"1.195395453","rc":[{"atl":[[1000,0.14]],"id":43154432}],"con":true,"img":false}]}
{"op":"mcm","clk":"5346840353","pt":1646098461927,"mc":[{"id":"1.195395453","rc":[{"atl":[[1000,0]],"id":43154432}],"con":true,"img":false}]}
{"op":"mcm","clk":"5346840357","pt":1646098462028,"mc":[{"id":"1.195395453","rc":[{"atl":[[90,0.14]],"id":43154432}],"con":true,"img":false}]}
{"op":"mcm","clk":"5346840384","pt":1646098462492,"mc":[{"id":"1.195395453","rc":[{"atb":[[7.4,19.53]],"id":37076607},{"atl":[[44,2.91]],"id":40612296},{"atl":[[17,8.38]],"id":43066392},{"atb":[[11.5,21.42]],"id":39586887}],"con":true,"img":false}]}
{"op":"mcm","clk":"5346840438","pt":1646098463835,"mc":[{"id":"1.195395453","rc":[{"atb":[[9.4,2.38]],"id":43154432}],"con":true,"img":false}]}
{"op":"mcm","clk":"5346840520","pt":1646098465740,"mc":[{"id":"1.195395453","rc":[{"atl":[[210,0]],"id":40612296}],"con":true,"img":false}]}
{"op":"mcm","clk":"5346840712","pt":1646098469801,"mc":[{"id":"1.195395453","rc":[{"atb":[[9.4,0]],"id":43154432}],"con":true,"img":false}]}
{"op":"mcm","clk":"5346840759","pt":1646098471339,"mc":[{"id":"1.195395453","rc":[{"atl":[[34,0]],"id":40612296},{"atb":[[1.18,250]],"id":42845264}],"con":true,"img":false}]}
{"op":"mcm","clk":"5346840763","pt":1646098471445,"mc":[{"id":"1.195395453","rc":[{"atb":[[11.5,0],[16.5,0],[19,0],[23,0]],"id":37076607},{"atl":[[260,0],[310,2],[160,0],[210,0]],"id":37076607},{"atb":[[11.5,0],[16.5,0],[19,0],[23,0]],"id":42901530},{"atl":[[260,0],[310,0],[160,0.27],[210,0]],"id":42901530},{"atb":[[8,0],[5,0],[6,10],[7,1.68]],"id":40612296},{"atl":[[70,8.2],[38,0],[48,0],[28,3],[29,3.57]],"id":40612296},{"atb":[[11.5,0],[14,0],[9.6,11.63],[7.6,0]],"id":40324412},{"atl":[[130,2],[90,0],[180,0],[230,0]],"id":40324412},{"atb":[[4,0],[5,0],[5.5,0],[6,0]],"id":43066392},{"atl":[[34,0],[18.5,0],[22,0],[27,0]],"id":43066392},{"atb":[[1.12,0],[1.21,685.09],[1.02,0],[1.22,0],[1.17,0]],"id":42845264},{"atl":[[2.26,0],[2.36,0],[2.56,0],[2.46,0]],"id":42845264},{"atb":[[12,0],[6.8,0],[9.8,0],[8.8,0]],"id":43154432},{"atl":[[70,2],[140,0],[95,0],[190,0]],"id":43154432},{"atb":[[10.5,0],[15.5,0],[18,0],[21,0]],"id":39586887},{"atl":[[150,0.31],[300,0],[200,0],[250,0]],"id":39586887}],"con":true,"img":false}]}
{"op":"mcm","clk":"5346840770","pt":1646098471649,"mc":[{"id":"1.195395453","rc":[{"atl":[[280,2],[310,0]],"id":37076607},{"atl":[[70,0],[90,2.14]],"id":43154432}],"con":true,"img":false}]}
{"op":"mcm","clk":"5346840778","pt":1646098471808,"mc":[{"id":"1.195395453","rc":[{"atl":[[90,0.14],[120,2]],"id":43154432}],"con":true,"img":false}]}
{"op":"mcm","clk":"5346840844","pt":1646098473344,"mc":[{"id":"1.195395453","rc":[{"atb":[[9.4,2.38]],"id":43154432}],"con":true,"img":false}]}
{"op":"mcm","clk":"5346840883","pt":1646098474224,"mc":[{"id":"1.195395453","rc":[{"atb":[[11.5,15.45],[16.5,7.85],[19,4.5],[23,1.84]],"id":37076607},{"atl":[[260,0.76],[310,0.64],[160,0.83],[210,0.63]],"id":37076607},{"atb":[[11.5,15.45],[16.5,7.85],[19,4.5],[23,1.84]],"id":42901530},{"atl":[[260,0.76],[310,0.64],[160,1.1],[210,0.63]],"id":42901530},{"atb":[[8,5.79],[5,40.56],[6,34.33],[7,15.2]],"id":40612296},{"atl":[[70,11.07],[38,3.57],[48,4.21],[29,8.29]],"id":40612296},{"atb":[[11.5,7.72],[14,3.12],[9.6,25.77],[7.6,24.58]],"id":40324412},{"atl":[[130,3.02],[90,1.48],[180,1.1],[230,0.86]],"id":40324412},{"atb":[[4,54.08],[5,30.42],[5.5,18.02],[6,8.11]],"id":43066392},{"atl":[[34,6],[18.5,7.55],[22,6.29],[27,7.62]],"id":43066392},{"atb":[[1.12,1014.11],[1.02,8112.93],[1.22,184.38],[1.17,477.22]],"id":42845264},{"atl":[[2.26,104.91],[2.36,97.19],[2.56,127.1],[2.46,135.81]],"id":42845264},{"atb":[[12,3.68],[6.8,27.97],[9.8,9.22],[8.8,15.6]],"id":43154432},{"atl":[[70,1.91],[140,1.42],[95,1.4],[190,1.04]],"id":43154432},{"atb":[[10.5,17.08],[15.5,8.39],[18,4.77],[21,2.02]],"id":39586887},{"atl":[[150,1.2],[300,0.66],[200,0.66],[250,0.79]],"id":39586887}],"con":true,"img":false}]}
{"op":"mcm","clk":"5346840886","pt":1646098474327,"mc":[{"id":"1.195395453","rc":[{"atb":[[6.2,3.02]],"id":43066392},{"atb":[[1.25,33.68]],"id":42845264},{"atb":[[12.5,0]],"id":43154432},{"atl":[[70,3.91],[120,0]],"id":43154432}],"con":true,"img":false}]}
{"op":"mcm","clk":"5346840924","pt":1646098475150,"mc":[{"id":"1.195395453","rc":[{"atb":[[6.2,0]],"id":43066392},{"atb":[[1.25,2]],"id":42845264}],"con":true,"img":false}]}
{"op":"mcm","clk":"5346840956","pt":1646098475919,"mc":[{"id":"1.195395453","rc":[{"atl":[[17,7.81],[1000,1.67]],"id":43066392}],"con":true,"img":false}]}
{"op":"mcm","clk":"5346840966","pt":1646098476121,"mc":[{"id":"1.195395453","rc":[{"atl":[[1000,0.61]],"id":43066392}],"con":true,"img":false}]}
{"op":"mcm","clk":"5346840975","pt":1646098476327,"mc":[{"id":"1.195395453","rc":[{"atl":[[1000,0]],"id":43066392}],"con":true,"img":false}]}
{"op":"mcm","clk":"5346840979","pt":1646098476430,"mc":[{"id":"1.195395453","rc":[{"atl":[[13.5,0.61]],"id":43066392}],"con":true,"img":false}]}
{"op":"mcm","clk":"5346841062","pt":1646098478229,"mc":[{"id":"1.195395453","rc":[{"atb":[[1.26,4.07]],"id":42845264},{"atb":[[13.5,8.03]],"id":43154432}],"con":true,"img":false}]}
{"op":"mcm","clk":"5346841068","pt":1646098478329,"mc":[{"id":"1.195395453","rc":[{"atb":[[9.4,0]],"id":43154432}],"con":true,"img":false}]}
{"op":"mcm","clk":"5346841128","pt":1646098480125,"mc":[{"id":"1.195395453","rc":[{"atb":[[1.2,579.46]],"id":42845264}],"con":true,"img":false}]}
{"op":"mcm","clk":"5346841140","pt":1646098480429,"mc":[{"id":"1.195395453","rc":[{"atb":[[1.2,579.13]],"id":42845264}],"con":true,"img":false}]}
{"op":"mcm","clk":"5346841154","pt":1646098480738,"mc":[{"id":"1.195395453","rc":[{"atb":[[1.2,577.23]],"id":42845264}],"con":true,"img":false}]}
{"op":"mcm","clk":"5346841159","pt":1646098480841,"mc":[{"id":"1.195395453","rc":[{"atb":[[1.26,5.98]],"id":42845264}],"con":true,"img":false}]}
{"op":"mcm","clk":"5346841164","pt":1646098481045,"mc":[{"id":"1.195395453","rc":[{"atb":[[6.2,3.02]],"id":43066392}],"con":true,"img":false}]}
{"op":"mcm","clk":"5346841192","pt":1646098481765,"mc":[{"id":"1.195395453","rc":[{"atb":[[9.4,2.38]],"id":43154432}],"con":true,"img":false}]}
{"op":"mcm","clk":"5346841370","pt":1646098486435,"mc":[{"id":"1.195395453","rc":[{"atb":[[9.4,0]],"id":43154432}],"con":true,"img":false}]}
{"op":"mcm","clk":"5346841517","pt":1646098489672,"mc":[{"id":"1.195395453","rc":[{"atb":[[9.4,2.38]],"id":43154432}],"con":true,"img":false}]}
{"op":"mcm","clk":"5346841566","pt":1646098491265,"mc":[{"id":"1.195395453","rc":[{"atl":[[180,0]],"id":42901530},{"atb":[[14.5,0]],"id":40324412},{"atb":[[13,0.08]],"id":43154432}],"con":true,"img":false}]}
{"op":"mcm","clk":"5346841571","pt":1646098491368,"mc":[{"id":"1.195395453","rc":[{"atl":[[160,3.8]],"id":42901530},{"atb":[[15.5,11.63]],"id":40324412},{"atb":[[12.5,3.93]],"id":43154432}],"con":true,"img":false}]}
{"op":"mcm","clk":"5346841577","pt":1646098491470,"mc":[{"id":"1.195395453","rc":[{"atl":[[150,2]],"id":42901530}],"con":true,"img":false}]}
{"op":"mcm","clk":"5346841580","pt":1646098491573,"mc":[{"id":"1.195395453","rc":[{"atl":[[170,0]],"id":42901530}],"con":true,"img":false}]}
{"op":"mcm","clk":"5346841691","pt":1646098494561,"mc":[{"id":"1.195395453","rc":[{"atb":[[15,0]],"id":40324412}],"con":true,"img":false}]}
{"op":"mcm","clk":"5346841833","pt":1646098498366,"mc":[{"id":"1.195395453","rc":[{"atb":[[14.5,6.86]],"id":40324412}],"con":true,"img":false}]}
{"op":"mcm","clk":"5346841889","pt":1646098499655,"mc":[{"id":"1.195395453","rc":[{"atb":[[9,6.25]],"id":43154432}],"con":true,"img":false}]}
{"op":"mcm","clk":"5346841943","pt":1646098501249,"mc":[{"id":"1.195395453","rc":[{"atl":[[160,1.1]],"id":42901530},{"atb":[[15.5,2.98]],"id":40324412},{"atl":[[21,6.1],[26,0]],"id":43066392},{"atl":[[210,2]],"id":39586887}],"con":true,"img":false}]}
{"op":"mcm","clk":"5346841948","pt":1646098501353,"mc":[{"id":"1.195395453","rc":[{"atl":[[150,0],[160,3.1],[250,2.7]],"id":42901530},{"atb":[[15,8.65]],"id":40324412},{"atl":[[200,3.36]],"id":39586887}],"con":true,"img":false}]}
{"op":"mcm","clk":"5346842012","pt":1646098503255,"mc":[{"id":"1.195395453","rc":[{"atb":[[9.4,0]],"id":43154432}],"con":true,"img":false}]}
{"op":"mcm","clk":"5346842029","pt":1646098503869,"mc":[{"id":"1.195395453","rc":[{"atb":[[14.5,0]],"id":40324412},{"atb":[[9.4,2.38]],"id":43154432}],"con":true,"img":false}]}
{"op":"mcm","clk":"5346842097","pt":1646098505979,"mc":[{"id":"1.195395453","rc":[{"atl":[[1000,1.67]],"id":43154432}],"con":true,"img":false}]}
{"op":"mcm","clk":"5346842102","pt":1646098506080,"mc":[{"id":"1.195395453","rc":[{"atl":[[90,0]],"id":43154432}],"con":true,"img":false}]}
{"op":"mcm","clk":"5346842105","pt":1646098506184,"mc":[{"id":"1.195395453","rc":[{"atl":[[1000,0.14]],"id":43154432}],"con":true,"img":false}]}
{"op":"mcm","clk":"5346842113","pt":1646098506387,"mc":[{"id":"1.195395453","rc":[{"atl":[[1000,0]],"id":43154432}],"con":true,"img":false}]}
{"op":"mcm","clk":"5346842116","pt":1646098506491,"mc":[{"id":"1.195395453","rc":[{"atl":[[60,0.14]],"id":43154432}],"con":true,"img":false}]}
{"op":"mcm","clk":"5346842153","pt":1646098507571,"mc":[{"id":"1.195395453","rc":[{"atb":[[16,5.4]],"id":40324412}],"con":true,"img":false}]}
{"op":"mcm","clk":"5346842273","pt":1646098511268,"mc":[{"id":"1.195395453","rc":[{"atb":[[15,0]],"id":40324412}],"con":true,"img":false}]}
{"op":"mcm","clk":"5346842279","pt":1646098511370,"mc":[{"id":"1.195395453","rc":[{"atb":[[14.5,8.65]],"id":40324412}],"con":true,"img":false}]}
{"op":"mcm","clk":"5346842410","pt":1646098514864,"mc":[{"id":"1.195395453","rc":[{"atb":[[8.6,9.87]],"id":43154432}],"con":true,"img":false}]}
{"op":"mcm","clk":"5346842498","pt":1646098517173,"mc":[{"id":"1.195395453","rc":[{"atb":[[9.4,0]],"id":43154432}],"con":true,"img":false}]}
{"op":"mcm","clk":"5346842518","pt":1646098517788,"mc":[{"id":"1.195395453","rc":[{"atb":[[9.4,2.38]],"id":43154432}],"con":true,"img":false}]}
{"op":"mcm","clk":"5346842604","pt":1646098520405,"mc":[{"id":"1.195395453","rc":[{"atb":[[1.19,16.22]],"id":42845264},{"atb":[[22,22.13]],"id":39586887}],"con":true,"img":false}]}
{"op":"mcm","clk":"5346842607","pt":1646098520509,"mc":[{"id":"1.195395453","rc":[{"atb":[[29,18.93]],"id":37076607},{"atb":[[27,18.93]],"id":42901530},{"atb":[[6.8,16.22]],"id":40612296},{"atb":[[16,21.63]],"id":40324412},{"atb":[[4.6,16.22]],"id":43066392},{"atb":[[12,19.91]],"id":43154432}],"con":true,"img":false}]}
{"op":"mcm","clk":"5346842637","pt":1646098521283,"mc":[{"id":"1.195395453","rc":[{"atb":[[12.5,10.81]],"id":40324412}],"con":true,"img":false}]}
{"op":"mcm","clk":"5346842641","pt":1646098521384,"mc":[{"id":"1.195395453","rc":[{"spn":29.26,"spf":1.0,"id":37076607},{"atb":[[6.6,0]],"id":40612296},{"atb":[[14.5,0]],"id":40324412}],"con":true,"img":false}]}
{"op":"mcm","clk":"5346842645","pt":1646098521485,"mc":[{"id":"1.195395453","rc":[{"atb":[[6.2,24.87]],"id":40612296}],"con":true,"img":false}]}
{"op":"mcm","clk":"5346842719","pt":1646098523689,"mc":[{"id":"1.195395453","rc":[{"atb":[[9.4,0]],"id":43154432}],"con":true,"img":false}]}
{"op":"mcm","clk":"5346842728","pt":1646098523899,"mc":[{"id":"1.195395453","rc":[{"atb":[[9.4,2.38]],"id":43154432}],"con":true,"img":false}]}
{"op":"mcm","clk":"5346842742","pt":1646098524307,"mc":[{"id":"1.195395453","rc":[{"atb":[[16,16.22]],"id":40324412}],"con":true,"img":false}]}
{"op":"mcm","clk":"5346842774","pt":1646098525490,"mc":[{"id":"1.195395453","rc":[{"atb":[[6.8,32.45]],"id":40612296},{"atb":[[4.6,32.45]],"id":43066392},{"atb":[[1.19,32.45]],"id":42845264},{"atb":[[12,30.73]],"id":43154432}],"con":true,"img":false}]}
{"op":"mcm","clk":"5346842859","pt":1646098527908,"mc":[{"id":"1.195395453","rc":[{"atb":[[16.5,5.98]],"id":40324412}],"con":true,"img":false}]}
{"op":"mcm","clk":"5346842914","pt":1646098528888,"mc":[{"id":"1.195395453","rc":[{"atb":[[32,0]],"id":42901530},{"atb":[[13.5,7.22]],"id":43154432}],"con":true,"img":false}]}
{"op":"mcm","clk":"5346842917","pt":1646098528992,"mc":[{"id":"1.195395453","rc":[{"atb":[[30,0.35]],"id":42901530},{"atl":[[1.87,9.83]],"id":42845264},{"atb":[[14,0.78]],"id":43154432}],"con":true,"img":false}]}
{"op":"mcm","clk":"5346842942","pt":1646098529507,"mc":[{"id":"1.195395453","rc":[{"atl":[[1.86,0]],"id":42845264}],"con":true,"img":false}]}
{"op":"mcm","clk":"5346842959","pt":1646098530025,"mc":[{"id":"1.195395453","rc":[{"atb":[[9.4,0]],"id":43154432}],"con":true,"img":false}]}
{"op":"mcm","clk":"5346842979","pt":1646098530491,"mc":[{"id":"1.195395453","rc":[{"atl":[[520,1],[510,0]],"id":37076607},{"atl":[[220,0],[230,1.86]],"id":40324412},{"atb":[[14,0],[9.4,2.38]],"id":43154432},{"atl":[[170,1],[180,0]],"id":43154432},{"atl":[[360,0],[370,1]],"id":39586887}],"con":true,"img":false}]}
{"op":"mcm","clk":"5346842984","pt":1646098530593,"mc":[{"id":"1.195395453","rc":[{"atb":[[12.5,4.81]],"id":43154432}],"con":true,"img":false}]}
{"op":"mcm","clk":"5346843018","pt":1646098531311,"mc":[{"id":"1.195395453","rc":[{"atb":[[1.27,1.67]],"id":42845264}],"con":true,"img":false}]}
{"op":"mcm","clk":"5346843032","pt":1646098531721,"mc":[{"id":"1.195395453","rc":[{"atb":[[1.26,1.9]],"id":42845264}],"con":true,"img":false}]}
{"op":"mcm","clk":"5346843041","pt":1646098531980,"mc":[{"id":"1.195395453","rc":[{"atl":[[1.92,9.39]],"id":42845264},{"atb":[[12,3.68]],"id":43154432}],"con":true,"img":false}]}
{"op":"mcm","clk":"5346843067","pt":1646098532494,"mc":[{"id":"1.195395453","rc":[{"atl":[[460,0],[470,1]],"id":42901530},{"atb":[[1.26,0],[1.25,0]],"id":42845264},{"atl":[[160,1],[170,0]],"id":43154432}],"con":true,"img":false}]}
{"op":"mcm","clk":"5346843072","pt":1646098532594,"mc":[{"id":"1.195395453","rc":[{"atl":[[520,0]],"id":37076607},{"atb":[[1.26,2]],"id":42845264},{"atb":[[22,21.64]],"id":39586887}],"con":true,"img":false}]}
{"op":"mcm","clk":"5346843074","pt":1646098532700,"mc":[{"id":"1.195395453","rc":[{"atb":[[27,0.39]],"id":39586887}],"con":true,"img":false}]}
{"op":"mcm","clk":"5346843142","pt":1646098534191,"mc":[{"id":"1.195395453","rc":[{"atb":[[1.27,43.44]],"id":42845264}],"con":true,"img":false}]}
{"op":"mcm","clk":"5346843176","pt":1646098535418,"mc":[{"id":"1.195395453","rc":[{"atb":[[1.24,5.97]],"id":42845264}],"con":true,"img":false}]}
{"op":"mcm","clk":"5346843183","pt":1646098535621,"mc":[{"id":"1.195395453","rc":[{"atb":[[10.5,16.22]],"id":43154432}],"con":true,"img":false}]}
{"op":"mcm","clk":"5346843258","pt":1646098537420,"mc":[{"id":"1.195395453","rc":[{"atb":[[1.24,54.55]],"id":42845264}],"con":true,"img":false}]}
{"op":"mcm","clk":"5346843314","pt":1646098539014,"mc":[{"id":"1.195395453","rc":[{"atl":[[1.87,0]],"id":42845264}],"con":true,"img":false}]}
{"op":"mcm","clk":"5346843337","pt":1646098539731,"mc":[{"id":"1.195395453","rc":[{"atl":[[1.98,20.41],[1.96,0]],"id":42845264},{"atl":[[210,0],[250,2.79]],"id":39586887}],"con":true,"img":false}]}
{"op":"mcm","clk":"5346843391","pt":1646098541017,"mc":[{"id":"1.195395453","rc":[{"atl":[[590,1]],"id":37076607},{"atl":[[390,1]],"id":39586887}],"con":true,"img":false}]}
{"op":"mcm","clk":"5346843404","pt":1646098541321,"mc":[{"id":"1.195395453","rc":[{"atb":[[15.5,0]],"id":40324412},{"atl":[[1.95,0],[1.92,13.82]],"id":42845264},{"atl":[[200,0.66]],"id":39586887}],"con":true,"img":false}]}
{"op":"mcm","clk":"5346843409","pt":1646098541422,"mc":[{"id":"1.195395453","rc":[{"atb":[[17,2.98]],"id":40324412},{"atl":[[1.97,43.26]],"id":42845264},{"atl":[[240,2.7]],"id":39586887}],"con":true,"img":false}]}
{"op":"mcm","clk":"5346843445","pt":1646098542298,"mc":[{"id":"1.195395453","rc":[{"atl":[[2.3,76.92]],"id":42845264},{"atl":[[380,0],[400,0],[420,0]],"id":39586887}],"con":true,"img":false}]}
{"op":"mcm","clk":"5346843448","pt":1646098542400,"mc":[{"id":"1.195395453","rc":[{"atl":[[2.18,0]],"id":42845264},{"atb":[[9.4,0]],"id":43154432}],"con":true,"img":false}]}
{"op":"mcm","clk":"5346843468","pt":1646098543013,"mc":[{"id":"1.195395453","rc":[{"atl":[[490,1]],"id":42901530},{"atb":[[9.4,2.38]],"id":43154432},{"atl":[[180,1]],"id":43154432}],"con":true,"img":false}]}
{"op":"mcm","clk":"5346843534","pt":1646098544599,"mc":[{"id":"1.195395453","rc":[{"atb":[[16.5,0]],"id":40324412}],"con":true,"img":false}]}
{"op":"mcm","clk":"5346843550","pt":1646098545014,"mc":[{"id":"1.195395453","rc":[{"atl":[[1.94,9.47]],"id":42845264}],"con":true,"img":false}]}
{"op":"mcm","clk":"5346843568","pt":1646098545319,"mc":[{"id":"1.195395453","rc":[{"atl":[[520,0],[480,0],[500,0]],"id":42901530},{"atl":[[150,1],[160,0],[180,0],[200,0],[220,0],[240,0]],"id":43154432},{"atl":[[370,0],[430,1]],"id":39586887}],"con":true,"img":false}]}
{"op":"mcm","clk":"5346843579","pt":1646098545626,"mc":[{"id":"1.195395453","rc":[{"atb":[[1.27,85.22]],"id":42845264}],"con":true,"img":false}]}
{"op":"mcm","clk":"5346843673","pt":1646098547934,"mc":[{"id":"1.195395453","rc":[{"atb":[[9.4,0]],"id":43154432},{"atl":[[390,0]],"id":39586887}],"con":true,"img":false}]}
{"op":"mcm","clk":"5346843690","pt":1646098548344,"mc":[{"id":"1.195395453","rc":[{"atb":[[17.5,6.02]],"id":40324412},{"atb":[[9.4,2.38]],"id":43154432}],"con":true,"img":false}]}
{"op":"mcm","clk":"5346843706","pt":1646098548701,"mc":[{"id":"1.195395453","rc":[{"atl":[[530,0],[510,1]],"id":37076607},{"atl":[[450,1]],"id":42901530},{"atl":[[220,1],[230,0.86]],"id":40324412},{"atb":[[1.2,477.23],[1.21,780.33]],"id":42845264},{"atl":[[420,1]],"id":39586887}],"con":true,"img":false}]}
{"op":"mcm","clk":"5346843792","pt":1646098551218,"mc":[{"id":"1.195395453","rc":[{"atl":[[65,2.7]],"id":43154432}],"con":true,"img":false}]}
{"op":"mcm","clk":"5346843798","pt":1646098551316,"mc":[{"id":"1.195395453","rc":[{"atl":[[2.16,0]],"id":42845264}],"con":true,"img":false}]}
{"op":"mcm","clk":"5346843801","pt":1646098551420,"mc":[{"id":"1.195395453","rc":[{"atl":[[2.24,99.44]],"id":42845264}],"con":true,"img":false}]}
{"op":"mcm","clk":"5346843882","pt":1646098554311,"mc":[{"id":"1.195395453","rc":[{"atb":[[9.4,0]],"id":43154432}],"con":true,"img":false}]}
{"op":"mcm","clk":"5346843901","pt":1646098554925,"mc":[{"id":"1.195395453","rc":[{"atb":[[9.4,2.38]],"id":43154432}],"con":true,"img":false}]}
{"op":"mcm","clk":"5346844019","pt":1646098558923,"mc":[{"id":"1.195395453","rc":[{"atl":[[530,1]],"id":37076607},{"atl":[[510,1]],"id":42901530},{"atl":[[2,125]],"id":42845264},{"atl":[[440,1]],"id":39586887}],"con":true,"img":false}]}
{"op":"mcm","clk":"5346844023","pt":1646098559022,"mc":[{"id":"1.195395453","rc":[{"atl":[[2,50]],"id":42845264}],"con":true,"img":false}]}
{"op":"mcm","clk":"5346844092","pt":1646098561328,"mc":[{"id":"1.195395453","rc":[{"atl":[[590,0]],"id":37076607},{"atb":[[17,0]],"id":40324412},{"atb":[[1.23,0]],"id":42845264},{"atl":[[150,0.88],[420,0],[450,1]],"id":39586887}],"con":true,"img":false}]}
{"op":"mcm","clk":"5346844095","pt":1646098561429,"mc":[{"id":"1.195395453","rc":[{"atb":[[16.5,2.98]],"id":40324412},{"atb":[[1.25,43.26]],"id":42845264},{"atl":[[140,0.31]],"id":39586887}],"con":true,"img":false}]}
{"op":"mcm","clk":"5346844113","pt":1646098562149,"mc":[{"id":"1.195395453","rc":[{"atl":[[1.94,12.43]],"id":42845264}],"con":true,"img":false}]}
{"op":"mcm","clk":"5346844125","pt":1646098562454,"mc":[{"id":"1.195395453","rc":[{"atl":[[430,0]],"id":39586887}],"con":true,"img":false}]}
{"op":"mcm","clk":"5346844161","pt":1646098563535,"mc":[{"id":"1.195395453","rc":[{"atb":[[32,0]],"id":37076607},{"atl":[[520,1],[510,0]],"id":37076607},{"atl":[[450,0],[460,1]],"id":42901530},{"atb":[[12.5,3.93]],"id":43154432},{"atl":[[34,1]],"id":43154432},{"atl":[[440,0],[460,1]],"id":39586887}],"con":true,"img":false}]}
{"op":"mcm","clk":"5346844164","pt":1646098563636,"mc":[{"id":"1.195395453","rc":[{"atb":[[36,0.3]],"id":37076607},{"atb":[[11.5,0.96]],"id":43154432},{"atl":[[70,1.91],[60,2.14]],"id":43154432}],"con":true,"img":false}]}
{"op":"mcm","clk":"5346844166","pt":1646098563743,"mc":[{"id":"1.195395453","rc":[{"atb":[[1.03,1.67]],"id":43154432}],"con":true,"img":false}]}
{"op":"mcm","clk":"5346844172","pt":1646098563945,"mc":[{"id":"1.195395453","rc":[{"atb":[[1.03,0.59]],"id":43154432}],"con":true,"img":false}]}
{"op":"mcm","clk":"5346844182","pt":1646098564149,"mc":[{"id":"1.195395453","rc":[{"atb":[[1.03,0]],"id":43154432}],"con":true,"img":false}]}
{"op":"mcm","clk":"5346844185","pt":1646098564252,"mc":[{"id":"1.195395453","rc":[{"atb":[[14,0.59]],"id":43154432}],"con":true,"img":false}]}
{"op":"mcm","clk":"5346844203","pt":1646098564867,"mc":[{"id":"1.195395453","rc":[{"atb":[[1.24,0]],"id":42845264}],"con":true,"img":false}]}
{"op":"mcm","clk":"5346844232","pt":1646098565739,"mc":[{"id":"1.195395453","rc":[{"atb":[[27,21.63]],"id":42901530},{"atb":[[16,32.45]],"id":40324412},{"atb":[[4.6,48.67]],"id":43066392},{"atb":[[1.22,200.61]],"id":42845264},{"atb":[[27,3.09]],"id":39586887}],"con":true,"img":false}]}
{"op":"mcm","clk":"5346844234","pt":1646098565842,"mc":[{"id":"1.195395453","rc":[{"atb":[[6.8,48.67]],"id":40612296},{"atb":[[10.5,24.33]],"id":43154432}],"con":true,"img":false}]}
{"op":"mcm","clk":"5346844326","pt":1646098568050,"mc":[{"id":"1.195395453","rc":[{"atb":[[9.4,0]],"id":43154432},{"atl":[[450,0]],"id":39586887}],"con":true,"img":false}]}
{"op":"mcm","clk":"5346844349","pt":1646098568665,"mc":[{"id":"1.195395453","rc":[{"atb":[[9.4,2.38]],"id":43154432}],"con":true,"img":false}]}
{"op":"mcm","clk":"5346844354","pt":1646098568767,"mc":[{"id":"1.195395453","rc":[{"atb":[[1.23,236.34]],"id":42845264}],"con":true,"img":false}]}
{"op":"mcm","clk":"5346844360","pt":1646098568970,"mc":[{"id":"1.195395453","rc":[{"atl":[[2.04,192.31]],"id":42845264}],"con":true,"img":false}]}
{"op":"mcm","clk":"5346844366","pt":1646098569075,"mc":[{"id":"1.195395453","rc":[{"atl":[[2.04,72.12]],"id":42845264}],"con":true,"img":false}]}
{"op":"mcm","clk":"5346844422","pt":1646098570156,"mc":[{"id":"1.195395453","rc":[{"atb":[[1.23,334.65]],"id":42845264}],"con":true,"img":false}]}
{"op":"mcm","clk":"5346844458","pt":1646098570875,"mc":[{"id":"1.195395453","rc":[{"atb":[[10.5,27.04]],"id":43154432}],"con":true,"img":false}]}
{"op":"mcm","clk":"5346844539","pt":1646098573434,"mc":[{"id":"1.195395453","rc":[{"atl":[[540,1],[170,0]],"id":37076607},{"atl":[[480,1]],"id":42901530},{"atb":[[9.4,0]],"id":43154432},{"atl":[[480,1]],"id":39586887}],"con":true,"img":false}]}
{"op":"mcm","clk":"5346844546","pt":1646098573538,"mc":[{"id":"1.195395453","rc":[{"atl":[[180,0.27]],"id":37076607}],"con":true,"img":false}]}
{"op":"mcm","clk":"5346844611","pt":1646098575277,"mc":[{"id":"1.195395453","rc":[{"atb":[[9,2.5],[8.6,0]],"id":37076607},{"atl":[[530,0],[550,0],[570,0]],"id":37076607},{"atb":[[9.2,2.44],[9.4,0]],"id":42901530},{"atl":[[470,0],[490,0],[510,0]],"id":42901530},{"atl":[[32,0],[27,3.01],[28,4],[29,4.72]],"id":40612296},{"atl":[[12,1.82],[14,0],[15,7.14],[16,5]],"id":43066392},{"atb":[[9.4,2.38]],"id":43154432},{"atb":[[14.5,0],[15.5,9.77]],"id":39586887}],"con":true,"img":false}]}
{"op":"mcm","clk":"5346844673","pt":1646098577533,"mc":[{"id":"1.195395453","rc":[{"atb":[[10,0],[12.5,0]],"id":43154432}],"con":true,"img":false}]}
{"op":"mcm","clk":"5346844677","pt":1646098577637,"mc":[{"id":"1.195395453","rc":[{"atb":[[1.03,1.67],[11,13.46],[11.5,4.89]],"id":43154432}],"con":true,"img":false}]}
{"op":"mcm","clk":"5346844683","pt":1646098577741,"mc":[{"id":"1.195395453","rc":[{"atb":[[1.03,0.59],[14,0]],"id":43154432}],"con":true,"img":false}]}
{"op":"mcm","clk":"5346844689","pt":1646098577943,"mc":[{"id":"1.195395453","rc":[{"atb":[[1.03,0]],"id":43154432}],"con":true,"img":false}]}
{"op":"mcm","clk":"5346844692","pt":1646098578043,"mc":[{"id":"1.195395453","rc":[{"atb":[[12.5,0.59]],"id":43154432}],"con":true,"img":false}]}
{"op":"mcm","clk":"5346844711","pt":1646098578759,"mc":[{"id":"1.195395453","rc":[{"atl":[[2.08,115.74]],"id":42845264}],"con":true,"img":false}]}
{"op":"mcm","clk":"5346844714","pt":1646098578862,"mc":[{"id":"1.195395453","rc":[{"atb":[[1.03,1.67],[12.5,0]],"id":43154432}],"con":true,"img":false}]}
{"op":"mcm","clk":"5346844723","pt":1646098579068,"mc":[{"id":"1.195395453","rc":[{"atb":[[1.03,0.57]],"id":43154432}],"con":true,"img":false}]}
{"op":"mcm","clk":"5346844731","pt":1646098579275,"mc":[{"id":"1.195395453","rc":[{"atb":[[1.03,0]],"id":43154432}],"con":true,"img":false}]}
{"op":"mcm","clk":"5346844735","pt":1646098579375,"mc":[{"id":"1.195395453","rc":[{"atb":[[14.5,0.57]],"id":43154432}],"con":true,"img":false}]}
{"op":"mcm","clk":"5346844747","pt":1646098579684,"mc":[{"id":"1.195395453","rc":[{"atb":[[6.2,0]],"id":43066392}],"con":true,"img":false}]}
{"op":"mcm","clk":"5346844752","pt":1646098579786,"mc":[{"id":"1.195395453","rc":[{"atb":[[9.4,0]],"id":43154432}],"con":true,"img":false}]}
{"op":"mcm","clk":"5346844758","pt":1646098579889,"mc":[{"id":"1.195395453","rc":[{"atb":[[13.5,0]],"id":43154432}],"con":true,"img":false}]}
{"op":"mcm","clk":"5346844772","pt":1646098580250,"mc":[{"id":"1.195395453","rc":[{"atl":[[1.94,9.47]],"id":42845264}],"con":true,"img":false}]}
{"op":"mcm","clk":"5346844776","pt":1646098580351,"mc":[{"id":"1.195395453","rc":[{"atl":[[14.5,2]],"id":43066392},{"atl":[[1.91,3]],"id":42845264}],"con":true,"img":false}]}
{"op":"mcm","clk":"5346844797","pt":1646098580963,"mc":[{"id":"1.195395453","rc":[{"atb":[[10.5,40.56]],"id":43154432}],"con":true,"img":false}]}
{"op":"mcm","clk":"5346844801","pt":1646098581170,"mc":[{"id":"1.195395453","rc":[{"atl":[[110,0.28]],"id":39586887}],"con":true,"img":false}]}
{"op":"mcm","clk":"5346844805","pt":1646098581272,"mc":[{"id":"1.195395453","rc":[{"atl":[[28,1.3]],"id":40612296}],"con":true,"img":false}]}
{"op":"mcm","clk":"5346844809","pt":1646098581374,"mc":[{"id":"1.195395453","rc":[{"atl":[[34,2.7],[28,5]],"id":40612296}],"con":true,"img":false}]}
{"op":"mcm","clk":"5346844811","pt":1646098581475,"mc":[{"id":"1.195395453","rc":[{"spn":29.55,"spf":1.0,"id":37076607},{"spn":65.0,"spf":1.0,"id":42901530},{"atl":[[27,0]],"id":40612296},{"spn":6.53,"spf":1.0,"id":43066392},{"spn":1.69,"spf":1.0,"id":42845264},{"spn":24.25,"spf":1.0,"id":43154432},{"spn":63.5,"spf":1.0,"id":39586887}],"con":true,"img":false}]}
{"op":"mcm","clk":"5346844816","pt":1646098581683,"mc":[{"id":"1.195395453","rc":[{"atl":[[14.5,7],[15,3.57]],"id":43066392},{"atb":[[9.4,2.38]],"id":43154432}],"con":true,"img":false}]}
{"op":"mcm","clk":"5346844851","pt":1646098583064,"mc":[{"id":"1.195395453","rc":[{"atl":[[140,0]],"id":39586887}],"con":true,"img":false}]}
{"op":"mcm","clk":"5346844855","pt":1646098583165,"mc":[{"id":"1.195395453","rc":[{"atl":[[160,0.31]],"id":39586887}],"con":true,"img":false}]}
{"op":"mcm","clk":"5346844860","pt":1646098583371,"mc":[{"id":"1.195395453","rc":[{"atl":[[1.92,9.39]],"id":42845264}],"con":true,"img":false}]}
{"op":"mcm","clk":"5346844869","pt":1646098583679,"mc":[{"id":"1.195395453","rc":[{"atb":[[1.23,98.31]],"id":42845264}],"con":true,"img":false}]}
{"op":"mcm","clk":"5346844874","pt":1646098583780,"mc":[{"id":"1.195395453","rc":[{"atb":[[12.5,6.51]],"id":43154432}],"con":true,"img":false}]}
{"op":"mcm","clk":"5346844906","pt":1646098584860,"mc":[{"id":"1.195395453","rc":[{"atb":[[1.23,0]],"id":42845264},{"atb":[[1.2,2.23]],"id":43154432}],"con":true,"img":false}]}
{"op":"mcm","clk":"5346844909","pt":1646098584962,"mc":[{"id":"1.195395453","rc":[{"atb":[[8.6,6.58]],"id":37076607},{"atl":[[560,1]],"id":37076607},{"atl":[[500,1]],"id":42901530},{"atl":[[30,1.72]],"id":40612296},{"atl":[[13,4.17]],"id":43066392},{"atb":[[14.5,3.7]],"id":39586887},{"atl":[[500,1]],"id":39586887}],"con":true,"img":false}]}
{"op":"mcm","clk":"5346844916","pt":1646098585169,"mc":[{"id":"1.195395453","rc":[{"atb":[[1.2,1.96]],"id":43154432}],"con":true,"img":false}]}
{"op":"mcm","clk":"5346844926","pt":1646098585476,"mc":[{"id":"1.195395453","rc":[{"atb":[[1.2,0]],"id":43154432}],"con":true,"img":false}]}
{"op":"mcm","clk":"5346844931","pt":1646098585579,"mc":[{"id":"1.195395453","rc":[{"atb":[[7.4,0]],"id":37076607},{"atl":[[36,3.78],[40,0],[44,0]],"id":40612296},{"atl":[[17,0]],"id":43066392},{"atb":[[12.5,8.47],[9.4,0]],"id":43154432},{"atb":[[11.5,9.52]],"id":39586887}],"con":true,"img":false}]}
{"op":"mcm","clk":"5346844935","pt":1646098585681,"mc":[{"id":"1.195395453","rc":[{"atb":[[1.28,128.91]],"id":42845264}],"con":true,"img":false}]}
{"op":"mcm","clk":"5346845002","pt":1646098587370,"mc":[{"id":"1.195395453","rc":[{"atb":[[9.4,2.38]],"id":43154432}],"con":true,"img":false}]}
{"op":"mcm","clk":"5346845125","pt":1646098590492,"mc":[{"id":"1.195395453","rc":[{"atb":[[1.29,78.02]],"id":42845264}],"con":true,"img":false}]}
{"op":"mcm","clk":"5346845159","pt":1646098591264,"mc":[{"id":"1.195395453","rc":[{"atl":[[36,0],[46,2.7]],"id":40612296},{"atl":[[16.5,0]],"id":43066392}],"con":true,"img":false}]}
{"op":"mcm","clk":"5346845166","pt":1646098591367,"mc":[{"id":"1.195395453","rc":[{"atl":[[18,2.7]],"id":43066392}],"con":true,"img":false}]}
{"op":"mcm","clk":"5346845172","pt":1646098591470,"mc":[{"id":"1.195395453","rc":[{"atb":[[4.8,0]],"id":43066392}],"con":true,"img":false}]}
{"op":"mcm","clk":"5346845176","pt":1646098591572,"mc":[{"id":"1.195395453","rc":[{"atb":[[4.7,45.6]],"id":43066392}],"con":true,"img":false}]}
{"op":"mcm","clk":"5346845182","pt":1646098591673,"mc":[{"id":"1.195395453","rc":[{"atb":[[9.4,0]],"id":43154432}],"con":true,"img":false}]}
{"op":"mcm","clk":"5346845231","pt":1646098593102,"mc":[{"id":"1.195395453","rc":[{"atb":[[1.28,0]],"id":42845264}],"con":true,"img":false}]}
{"op":"mcm","clk":"5346845239","pt":1646098593408,"mc":[{"id":"1.195395453","rc":[{"atb":[[29,16.22]],"id":37076607},{"atl":[[250,0]],"id":37076607},{"atl":[[250,0]],"id":42901530},{"atb":[[5.9,17.31]],"id":40612296},{"atl":[[120,0]],"id":40324412},{"atb":[[4.4,20.06]],"id":43066392},{"atl":[[2.34,76.85]],"id":42845264},{"atb":[[10,10.54]],"id":43154432},{"atb":[[23,0]],"id":39586887},{"atl":[[240,0]],"id":39586887}],"con":true,"img":false}]}
{"op":"mcm","clk":"5346845241","pt":1646098593463,"mc":[{"id":"1.195395453","rc":[{"atb":[[34,2.7]],"id":37076607},{"atl":[[990,2.7]],"id":37076607},{"atl":[[470,2.7]],"id":42901530},{"atb":[[6.2,0]],"id":40612296},{"atl":[[210,2.7]],"id":40324412},{"atb":[[4.7,13.51]],"id":43066392},{"atb":[[1.21,158.34]],"id":42845264},{"atl":[[2.24,0]],"id":42845264},{"atb":[[11,0]],"id":43154432},{"atb":[[27,5.79]],"id":39586887},{"atl":[[450,2.7]],"id":39586887}],"con":true,"img":false}]}
{"op":"mcm","clk":"5346845244","pt":1646098593565,"mc":[{"id":"1.195395453","rc":[{"atl":[[85,0],[1000,1.67]],"id":40324412}],"con":true,"img":false}]}
{"op":"mcm","clk":"5346845250","pt":1646098593771,"mc":[{"id":"1.195395453","rc":[{"atl":[[22,0.28]],"id":40612296},{"atl":[[1000,0.1]],"id":40324412}],"con":true,"img":false}]}
{"op":"mcm","clk":"5346845257","pt":1646098593974,"mc":[{"id":"1.195395453","rc":[{"atl":[[1000,0]],"id":40324412}],"con":true,"img":false}]}
{"op":"mcm","clk":"5346845260","pt":1646098594077,"mc":[{"id":"1.195395453","rc":[{"atl":[[120,0.1]],"id":40324412}],"con":true,"img":false}]}
{"op":"mcm","clk":"5346845269","pt":1646098594283,"mc":[{"id":"1.195395453","rc":[{"atb":[[9.4,2.38]],"id":43154432}],"con":true,"img":false}]}
{"op":"mcm","clk":"5346845281","pt":1646098594589,"mc":[{"id":"1.195395453","rc":[{"atb":[[8.2,10.42]],"id":37076607},{"atl":[[580,1]],"id":37076607},{"atl":[[520,1]],"id":42901530},{"atl":[[34,4.97]],"id":40612296},{"atl":[[14,5.77]],"id":43066392},{"atb":[[13.5,6]],"id":39586887},{"atl":[[520,1]],"id":39586887}],"con":true,"img":false}]}
{"op":"mcm","clk":"5346845337","pt":1646098596076,"mc":[{"id":"1.195395453","rc":[{"atb":[[1.03,1.67]],"id":43154432}],"con":true,"img":false}]}
{"op":"mcm","clk":"5346845338","pt":1646098596179,"mc":[{"id":"1.195395453","rc":[{"atb":[[14.5,0]],"id":43154432}],"con":true,"img":false}]}
{"op":"mcm","clk":"5346845360","pt":1646098596794,"mc":[{"id":"1.195395453","rc":[{"atb":[[1.3,118.11]],"id":42845264}],"con":true,"img":false}]}
{"op":"mcm","clk":"5346845368","pt":1646098596997,"mc":[{"id":"1.195395453","rc":[{"atb":[[1.01,1.67]],"id":40612296},{"atl":[[60,2],[1000,1.67]],"id":43154432}],"con":true,"img":false}]}
{"op":"mcm","clk":"5346845373","pt":1646098597102,"mc":[{"id":"1.195395453","rc":[{"atl":[[130,0.28]],"id":37076607},{"atb":[[1.01,0.92]],"id":40612296},{"atb":[[1.03,0.57]],"id":43154432},{"atl":[[1000,0.25]],"id":43154432}],"con":true,"img":false}]}
{"op":"mcm","clk":"5346845380","pt":1646098597304,"mc":[{"id":"1.195395453","rc":[{"atb":[[1.03,0]],"id":43154432}],"con":true,"img":false}]}
{"op":"mcm","clk":"5346845384","pt":1646098597408,"mc":[{"id":"1.195395453","rc":[{"atb":[[13.5,0.57]],"id":43154432}],"con":true,"img":false}]}
{"op":"mcm","clk":"5346845395","pt":1646098597563,"mc":[{"id":"1.195395453","rc":[{"atl":[[1000,0]],"id":43154432}],"con":true,"img":false}]}
{"op":"mcm","clk":"5346845399","pt":1646098597684,"mc":[{"id":"1.195395453","rc":[{"atl":[[32,0.25]],"id":43154432}],"con":true,"img":false}]}
{"op":"mcm","clk":"5346845404","pt":1646098597786,"mc":[{"id":"1.195395453","rc":[{"atb":[[1.01,0]],"id":40612296},{"atb":[[1.29,0]],"id":42845264}],"con":true,"img":false}]}
{"op":"mcm","clk":"5346845407","pt":1646098597890,"mc":[{"id":"1.195395453","rc":[{"atb":[[9,0.92]],"id":40612296}],"con":true,"img":false}]}
{"op":"mcm","clk":"5346845413","pt":1646098598093,"mc":[{"id":"1.195395453","rc":[{"atb":[[9,0],[1.01,1.67]],"id":40612296}],"con":true,"img":false}]}
{"op":"mcm","clk":"5346845417","pt":1646098598195,"mc":[{"id":"1.195395453","rc":[{"atb":[[1.01,0.92]],"id":40612296}],"con":true,"img":false}]}
{"op":"mcm","clk":"5346845419","pt":1646098598297,"mc":[{"id":"1.195395453","rc":[{"atl":[[14.5,5],[16,0]],"id":43066392},{"atl":[[1.91,0]],"id":42845264},{"atb":[[9.4,0]],"id":43154432}],"con":true,"img":false}]}
{"op":"mcm","clk":"5346845422","pt":1646098598400,"mc":[{"id":"1.195395453","rc":[{"atb":[[1.01,0]],"id":40612296}],"con":true,"img":false}]}
{"op":"mcm","clk":"5346845425","pt":1646098598502,"mc":[{"id":"1.195395453","rc":[{"atb":[[8.2,0.92]],"id":40612296}],"con":true,"img":false}]}
{"op":"mcm","clk":"5346845432","pt":1646098598706,"mc":[{"id":"1.195395453","rc":[{"atb":[[1.01,1.67],[8.2,0]],"id":40612296}],"con":true,"img":false}]}
{"op":"mcm","clk":"5346845436","pt":1646098598913,"mc":[{"id":"1.195395453","rc":[{"atb":[[1.01,0.92]],"id":40612296}],"con":true,"img":false}]}
{"op":"mcm","clk":"5346845439","pt":1646098599016,"mc":[{"id":"1.195395453","rc":[{"atb":[[29,0]],"id":37076607},{"atb":[[27,5.4]],"id":42901530},{"atb":[[6.8,16.22]],"id":40612296},{"atb":[[16,16.22]],"id":40324412},{"atb":[[4.6,16.22]],"id":43066392},{"atb":[[1.19,0]],"id":42845264},{"atb":[[10.5,24.33]],"id":43154432},{"atb":[[22,5.41]],"id":39586887}],"con":true,"img":false}]}
{"op":"mcm","clk":"5346845444","pt":1646098599069,"mc":[{"id":"1.195395453","rc":[{"atb":[[1.01,0]],"id":40612296}],"con":true,"img":false}]}
{"op":"mcm","clk":"5346845449","pt":1646098599172,"mc":[{"id":"1.195395453","rc":[{"atb":[[9,0.92]],"id":40612296}],"con":true,"img":false}]}
{"op":"mcm","clk":"5346845510","pt":1646098600808,"mc":[{"id":"1.195395453","rc":[{"atb":[[9.4,2.38]],"id":43154432}],"con":true,"img":false}]}
{"op":"mcm","clk":"5346845516","pt":1646098601011,"mc":[{"id":"1.195395453","rc":[{"atb":[[36,16.52]],"id":37076607},{"atb":[[27,18.93]],"id":42901530},{"atb":[[6.8,32.45]],"id":40612296},{"atb":[[27,19.32]],"id":39586887}],"con":true,"img":false}]}
{"op":"mcm","clk":"5346845519","pt":1646098601114,"mc":[{"id":"1.195395453","rc":[{"atb":[[4.6,32.45]],"id":43066392},{"atb":[[1.22,216.83]],"id":42845264},{"atb":[[10.5,27.04]],"id":43154432}],"con":true,"img":false}]}
{"op":"mcm","clk":"5346845572","pt":1646098602396,"mc":[{"id":"1.195395453","rc":[{"atl":[[520,0],[660,1]],"id":37076607},{"atl":[[460,0],[450,1]],"id":42901530},{"atb":[[1.3,0]],"id":42845264},{"atl":[[450,3.7],[460,0]],"id":39586887}],"con":true,"img":false}]}
{"op":"mcm","clk":"5346845600","pt":1646098603317,"mc":[{"id":"1.195395453","rc":[{"atb":[[1.28,80.8]],"id":42845264}],"con":true,"img":false}]}
{"op":"mcm","clk":"5346845616","pt":1646098603986,"mc":[{"id":"1.195395453","rc":[{"atl":[[38,6.95]],"id":40612296},{"atl":[[15,8.93]],"id":43066392}],"con":true,"img":false}]}
{"op":"mcm","clk":"5346845626","pt":1646098604287,"mc":[{"id":"1.195395453","rc":[{"atb":[[1.27,0]],"id":42845264}],"con":true,"img":false}]}
{"op":"mcm","clk":"5346845628","pt":1646098604391,"mc":[{"id":"1.195395453","rc":[{"atb":[[1.3,85.22]],"id":42845264}],"con":true,"img":false}]}
{"op":"mcm","clk":"5346845634","pt":1646098604494,"mc":[{"id":"1.195395453","rc":[{"atb":[[7.2,0.87]],"id":43066392},{"trd":[[7.2,2.88]],"ltp":7.2,"tv":2.88,"id":43066392}],"con":true,"img":false}]}
{"op":"mcm","clk":"5346845637","pt":1646098604599,"mc":[{"id":"1.195395453","rc":[{"atb":[[1.01,1.67],[7.2,0]],"id":43066392}],"con":true,"img":false}]}
{"op":"mcm","clk":"5346845645","pt":1646098604800,"mc":[{"id":"1.195395453","rc":[{"atb":[[1.01,0.87]],"id":43066392}],"con":true,"img":false}]}
{"op":"mcm","clk":"5346845652","pt":1646098605003,"mc":[{"id":"1.195395453","rc":[{"atl":[[540,0]],"id":37076607},{"atb":[[1.01,0]],"id":43066392},{"atb":[[9.4,0]],"id":43154432}],"con":true,"img":false}]}
{"op":"mcm","clk":"5346845656","pt":1646098605106,"mc":[{"id":"1.195395453","rc":[{"atb":[[6.2,0.87]],"id":43066392}],"con":true,"img":false}]}
{"op":"mcm","clk":"5346845664","pt":1646098605411,"mc":[{"id":"1.195395453","rc":[{"atl":[[46,6.45]],"id":40612296},{"atl":[[21,8.96]],"id":43066392},{"atb":[[10,0]],"id":43154432},{"atl":[[450,1]],"id":39586887}],"con":true,"img":false}]}
{"op":"mcm","clk":"5346845665","pt":1646098605513,"mc":[{"id":"1.195395453","rc":[{"atb":[[9.2,12.98]],"id":43154432},{"atl":[[470,2.7]],"id":39586887}],"con":true,"img":false}]}
{"op":"mcm","clk":"5346845680","pt":1646098606077,"mc":[{"id":"1.195395453","rc":[{"atb":[[1.29,122.29]],"id":42845264}],"con":true,"img":false}]}
{"op":"mcm","clk":"5346845722","pt":1646098607305,"mc":[{"id":"1.195395453","rc":[{"atb":[[9.4,2.38]],"id":43154432}],"con":true,"img":false}]}
{"op":"mcm","clk":"5346845726","pt":1646098607407,"mc":[{"id":"1.195395453","rc":[{"atl":[[560,0]],"id":37076607}],"con":true,"img":false}]}
{"op":"mcm","clk":"5346845768","pt":1646098608278,"mc":[{"id":"1.195395453","rc":[{"spl":[[1.01,5.78]],"id":37076607},{"spl":[[1.01,2]],"id":42901530},{"spl":[[1.01,2]],"id":40324412},{"spl":[[1.01,2]],"id":39586887}],"con":true,"img":false}]}
{"op":"mcm","clk":"5346845808","pt":1646098609711,"mc":[{"id":"1.195395453","rc":[{"atb":[[1.48,0],[1.3,71.53]],"id":42845264},{"trd":[[1.3,27.36],[1.48,1.43]],"ltp":1.3,"tv":28.79,"id":42845264}],"con":true,"img":false}]}
{"op":"mcm","clk":"5346845813","pt":1646098609812,"mc":[{"id":"1.195395453","rc":[{"atb":[[1.26,0]],"id":42845264}],"con":true,"img":false}]}
{"op":"mcm","clk":"5346845817","pt":1646098609914,"mc":[{"id":"1.195395453","rc":[{"atl":[[14.5,0],[16,6.67]],"id":43066392},{"atl":[[2.3,0],[2.42,70.42]],"id":42845264}],"con":true,"img":false}]}
{"op":"mcm","clk":"5346845822","pt":1646098610119,"mc":[{"id":"1.195395453","rc":[{"atl":[[580,0]],"id":37076607},{"atb":[[1.29,0]],"id":42845264},{"atb":[[9.4,0]],"id":43154432}],"con":true,"img":false}]}
{"op":"mcm","clk":"5346845844","pt":1646098610890,"mc":[{"id":"1.195395453","rc":[{"atb":[[1.28,0]],"id":42845264}],"con":true,"img":false}]}
{"op":"mcm","clk":"5346845846","pt":1646098610993,"mc":[{"id":"1.195395453","rc":[{"atb":[[16,32.45]],"id":40324412}],"con":true,"img":false}]}
{"op":"mcm","clk":"5346845851","pt":1646098611094,"mc":[{"id":"1.195395453","rc":[{"atb":[[6.8,48.67]],"id":40612296},{"atb":[[4.6,48.67]],"id":43066392},{"atb":[[1.22,233.06]],"id":42845264}],"con":true,"img":false}]}
{"op":"mcm","clk":"5346845856","pt":1646098611197,"mc":[{"id":"1.195395453","rc":[{"atb":[[10.5,32.45]],"id":43154432}],"con":true,"img":false}]}
{"op":"mcm","clk":"5346845860","pt":1646098611298,"mc":[{"id":"1.195395453","rc":[{"atb":[[19.5,0],[26,5.08]],"id":37076607},{"atb":[[1.25,0]],"id":42845264},{"atb":[[11.5,0.96]],"id":43154432}],"con":true,"img":false}]}
{"op":"mcm","clk":"5346845864","pt":1646098611402,"mc":[{"id":"1.195395453","rc":[{"atb":[[1.24,43.26]],"id":42845264},{"atb":[[11,3.93]],"id":43154432}],"con":true,"img":false}]}
{"op":"mcm","clk":"5346845873","pt":1646098611707,"mc":[{"id":"1.195395453","rc":[{"atb":[[7.8,18.38]],"id":37076607},{"atl":[[680,1]],"id":37076607},{"atb":[[12.5,10.87]],"id":39586887}],"con":true,"img":false}]}
{"op":"mcm","clk":"5346845914","pt":1646098612989,"mc":[{"id":"1.195395453","rc":[{"atb":[[9.4,2.38]],"id":43154432}],"con":true,"img":false}]}
{"op":"mcm","clk":"5346845962","pt":1646098614320,"mc":[{"id":"1.195395453","rc":[{"atb":[[1.3,0]],"id":42845264}],"con":true,"img":false}]}
{"op":"mcm","clk":"5346845967","pt":1646098614424,"mc":[{"id":"1.195395453","rc":[{"atb":[[1.2,0],[1.27,71.53],[1.21,434.67]],"id":42845264}],"con":true,"img":false}]}
{"op":"mcm","clk":"5346846000","pt":1646098615095,"mc":[{"id":"1.195395453","rc":[{"atb":[[9.4,0]],"id":43154432}],"con":true,"img":false}]}
{"op":"mcm","clk":"5346846007","pt":1646098615299,"mc":[{"id":"1.195395453","rc":[{"atl":[[27,1.32]],"id":40612296},{"atl":[[12,3.22]],"id":43066392},{"atl":[[1.91,1.25]],"id":42845264},{"atl":[[60,3.3]],"id":43154432}],"con":true,"img":false}]}
{"op":"mcm","clk":"5346846011","pt":1646098615399,"mc":[{"id":"1.195395453","rc":[{"atl":[[1000,1.67]],"id":43154432}],"con":true,"img":false}]}
{"op":"mcm","clk":"5346846013","pt":1646098615503,"mc":[{"id":"1.195395453","rc":[{"atl":[[32,0]],"id":43154432}],"con":true,"img":false}]}
{"op":"mcm","clk":"5346846016","pt":1646098615608,"mc":[{"id":"1.195395453","rc":[{"atl":[[1000,0.25]],"id":43154432}],"con":true,"img":false}]}
{"op":"mcm","clk":"5346846021","pt":1646098615708,"mc":[{"id":"1.195395453","rc":[{"atl":[[1000,0]],"id":43154432}],"con":true,"img":false}]}
{"op":"mcm","clk":"5346846025","pt":1646098615811,"mc":[{"id":"1.195395453","rc":[{"atl":[[55,0.25]],"id":43154432}],"con":true,"img":false}]}
{"op":"mcm","clk":"5346846033","pt":1646098616014,"mc":[{"id":"1.195395453","rc":[{"atb":[[1.27,113.3],[1.25,90.5]],"id":42845264}],"con":true,"img":false}]}
{"op":"mcm","clk":"5346846051","pt":1646098616424,"mc":[{"id":"1.195395453","rc":[{"atb":[[38,1.48]],"id":37076607},{"atb":[[8.2,1.56]],"id":40612296},{"atb":[[18,1.52]],"id":40324412},{"atb":[[6.2,2.38]],"id":43066392},{"atb":[[13,1.67]],"id":43154432},{"atb":[[28,1.5]],"id":39586887}],"con":true,"img":false}]}
{"op":"mcm","clk":"5346846062","pt":1646098616630,"mc":[{"id":"1.195395453","rc":[{"atb":[[9,0],[1.01,1.67]],"id":40612296}],"con":true,"img":false}]}
{"op":"mcm","clk":"5346846069","pt":1646098616733,"mc":[{"id":"1.195395453","rc":[{"atb":[[1.01,0.92]],"id":40612296}],"con":true,"img":false}]}
{"op":"mcm","clk":"5346846077","pt":1646098616889,"mc":[{"id":"1.195395453","rc":[{"atb":[[1.01,0]],"id":40612296}],"con":true,"img":false}]}
{"op":"mcm","clk":"5346846081","pt":1646098616991,"mc":[{"id":"1.195395453","rc":[{"atb":[[8.4,0.92]],"id":40612296}],"con":true,"img":false}]}
{"op":"mcm","clk":"5346846091","pt":1646098617197,"mc":[{"id":"1.195395453","rc":[{"atl":[[12,1.82]],"id":43066392}],"con":true,"img":false}]}
{"op":"mcm","clk":"5346846096","pt":1646098617300,"mc":[{"id":"1.195395453","rc":[{"atl":[[1000,1.4]],"id":43066392},{"spl":[[1.01,2.7]],"id":42845264}],"con":true,"img":false}]}
{"op":"mcm","clk":"5346846138","pt":1646098618935,"mc":[{"id":"1.195395453","rc":[{"atb":[[9.4,2.38]],"id":43154432}],"con":true,"img":false}]}
{"op":"mcm","clk":"5346846181","pt":1646098619911,"mc":[{"id":"1.195395453","rc":[{"atb":[[7.4,3.53]],"id":40612296},{"atb":[[12.5,1.96]],"id":43154432}],"con":true,"img":false}]}
{"op":"mcm","clk":"5346846188","pt":1646098620119,"mc":[{"id":"1.195395453","rc":[{"atl":[[130,0]],"id":37076607},{"atl":[[22,0]],"id":40612296},{"atl":[[110,0]],"id":39586887}],"con":true,"img":false}]}
{"op":"mcm","clk":"5346846204","pt":1646098620628,"mc":[{"id":"1.195395453","rc":[{"atb":[[13,0.08],[9.4,0]],"id":43154432}],"con":true,"img":false}]}
{"op":"mcm","clk":"5346846207","pt":1646098620731,"mc":[{"id":"1.195395453","rc":[{"atl":[[21,6.1]],"id":43066392},{"atb":[[12.5,3.56]],"id":43154432}],"con":true,"img":false}]}
{"op":"mcm","clk":"5346846211","pt":1646098620934,"mc":[{"id":"1.195395453","rc":[{"atl":[[700,1]],"id":37076607}],"con":true,"img":false}]}
{"op":"mcm","clk":"5346846214","pt":1646098621036,"mc":[{"id":"1.195395453","rc":[{"atb":[[7.4,0]],"id":40612296},{"atb":[[12.5,1.59]],"id":43154432}],"con":true,"img":false}]}
{"op":"mcm","clk":"5346846252","pt":1646098622014,"mc":[{"id":"1.195395453","rc":[{"atl":[[1.89,41.77]],"id":42845264}],"con":true,"img":false}]}
{"op":"mcm","clk":"5346846275","pt":1646098622627,"mc":[{"id":"1.195395453","rc":[{"atl":[[1.91,0]],"id":42845264}],"con":true,"img":false}]}
{"op":"mcm","clk":"5346846277","pt":1646098622733,"mc":[{"id":"1.195395453","rc":[{"atl":[[1.88,1.25]],"id":42845264}],"con":true,"img":false}]}
{"op":"mcm","clk":"5346846284","pt":1646098622935,"mc":[{"id":"1.195395453","rc":[{"spl":[[1.01,5.24]],"id":39586887}],"con":true,"img":false}]}
{"op":"mcm","clk":"5346846287","pt":1646098623036,"mc":[{"id":"1.195395453","rc":[{"atl":[[140,0.28]],"id":39586887}],"con":true,"img":false}]}
{"op":"mcm","clk":"5346846296","pt":1646098623341,"mc":[{"id":"1.195395453","rc":[{"atl":[[1.89,83.54]],"id":42845264}],"con":true,"img":false}]}
{"op":"mcm","clk":"5346846315","pt":1646098623907,"mc":[{"id":"1.195395453","rc":[{"atb":[[8.4,4.83]],"id":40612296},{"atb":[[13,3.45]],"id":43154432}],"con":true,"img":false}]}
{"op":"mcm","clk":"5346846319","pt":1646098624112,"mc":[{"id":"1.195395453","rc":[{"atb":[[32,0.02]],"id":42901530},{"atl":[[1.89,0]],"id":42845264}],"con":true,"img":false}]}
{"op":"mcm","clk":"5346846321","pt":1646098624216,"mc":[{"id":"1.195395453","rc":[{"atb":[[8.2,0]],"id":40612296},{"atl":[[1.87,83.54]],"id":42845264},{"atb":[[12.5,0]],"id":43154432}],"con":true,"img":false}]}
{"op":"mcm","clk":"5346846324","pt":1646098624319,"mc":[{"id":"1.195395453","rc":[{"atb":[[8.6,1.56]],"id":40612296},{"atb":[[13.5,2.17]],"id":43154432}],"con":true,"img":false}]}
{"op":"mcm","clk":"5346846326","pt":1646098624421,"mc":[{"id":"1.195395453","rc":[{"atl":[[1.88,0]],"id":42845264}],"con":true,"img":false}]}
{"op":"mcm","clk":"5346846329","pt":1646098624524,"mc":[{"id":"1.195395453","rc":[{"atl":[[1.91,1.25]],"id":42845264}],"con":true,"img":false}]}
{"op":"mcm","clk":"5346846333","pt":1646098624626,"mc":[{"id":"1.195395453","rc":[{"atl":[[130,1.44]],"id":42901530}],"con":true,"img":false}]}
{"op":"mcm","clk":"5346846335","pt":1646098624730,"mc":[{"id":"1.195395453","rc":[{"atl":[[130,3.44],[160,1.1]],"id":42901530}],"con":true,"img":false}]}
{"op":"mcm","clk":"5346846341","pt":1646098624937,"mc":[{"id":"1.195395453","rc":[{"atl":[[1.91,0]],"id":42845264}],"con":true,"img":false}]}
{"op":"mcm","clk":"5346846344","pt":1646098625036,"mc":[{"id":"1.195395453","rc":[{"atl":[[1.86,1.25]],"id":42845264}],"con":true,"img":false}]}
{"op":"mcm","clk":"5346846353","pt":1646098625242,"mc":[{"id":"1.195395453","rc":[{"atb":[[9.4,2.38]],"id":43154432}],"con":true,"img":false}]}
{"op":"mcm","clk":"5346846366","pt":1646098625548,"mc":[{"id":"1.195395453","rc":[{"atl":[[1.86,5.74]],"id":42845264}],"con":true,"img":false}]}
{"op":"mcm","clk":"5346846377","pt":1646098625805,"mc":[{"id":"1.195395453","rc":[{"atb":[[34,0]],"id":37076607},{"atb":[[27,16.61]],"id":39586887}],"con":true,"img":false}]}
{"op":"mcm","clk":"5346846379","pt":1646098625908,"mc":[{"id":"1.195395453","rc":[{"atb":[[38,2.7]],"id":37076607},{"atb":[[28,4.2]],"id":39586887}],"con":true,"img":false}]}
{"op":"mcm","clk":"5346846384","pt":1646098626012,"mc":[{"id":"1.195395453","rc":[{"atb":[[1.01,1.48]],"id":37076607},{"atb":[[1.2,2.23]],"id":40612296},{"atl":[[1.85,12.88]],"id":42845264},{"atb":[[1.2,2.23],[9.4,0]],"id":43154432}],"con":true,"img":false}]}
{"op":"mcm","clk":"5346846386","pt":1646098626114,"mc":[{"id":"1.195395453","rc":[{"atb":[[1.02,1.67]],"id":40324412},{"atl":[[1000,1.67]],"id":40324412},{"atl":[[13.5,0],[1000,3.07]],"id":43066392},{"atb":[[1.03,1.67]],"id":39586887}],"con":true,"img":false}]}
