{"op":"mcm","clk":"5346195398","pt":1646178339832,"mc":[{"id":"1.195453754","marketDefinition":{"bspMarket":false,"turnInPlayEnabled":false,"persistenceEnabled":false,"marketBaseRate":7.0,"eventId":"31272494","eventTypeId":"4339","numberOfWinners":1,"bettingType":"ODDS","marketType":"QUINELLA","marketTime":"2022-03-02T10:11:00.000Z","suspendTime":"2022-03-02T10:11:00.000Z","bspReconciled":false,"complete":true,"inPlay":false,"crossMatching":false,"runnersVoidable":false,"numberOfActiveRunners":28,"betDelay":0,"status":"OPEN","runners":[{"status":"ACTIVE","sortPriority":1,"id":522741,"name":"1 - 2 / 2 - 1"},{"status":"ACTIVE","sortPriority":2,"id":522742,"name":"1 - 3 / 3 - 1"},{"status":"ACTIVE","sortPriority":3,"id":522743,"name":"1 - 4 / 4 - 1"},{"status":"ACTIVE","sortPriority":4,"id":7607472,"name":"1 - 5 / 5 - 1"},{"status":"ACTIVE","sortPriority":5,"id":522745,"name":"1 - 6 / 6 - 1"},{"status":"ACTIVE","sortPriority":6,"id":3805731,"name":"1 - 8 / 8 - 1"},{"status":"ACTIVE","sortPriority":7,"id":3805732,"name":"1 - 9 / 9 - 1"},{"status":"ACTIVE","sortPriority":8,"id":522746,"name":"2 - 3 / 3 - 2"},{"status":"ACTIVE","sortPriority":9,"id":522747,"name":"2 - 4 / 4 - 2"},{"status":"ACTIVE","sortPriority":10,"id":522748,"name":"2 - 5 / 5 - 2"},{"status":"ACTIVE","sortPriority":11,"id":522749,"name":"2 - 6 / 6 - 2"},{"status":"ACTIVE","sortPriority":12,"id":3805740,"name":"2 - 8 / 8 - 2"},{"status":"ACTIVE","sortPriority":13,"id":3805741,"name":"2 - 9 / 9 - 2"},{"status":"ACTIVE","sortPriority":14,"id":522750,"name":"3 - 4 / 4 - 3"},{"status":"ACTIVE","sortPriority":15,"id":522751,"name":"3 - 5 / 5 - 3"},{"status":"ACTIVE","sortPriority":16,"id":522752,"name":"3 - 6 / 6 - 3"},{"status":"ACTIVE","sortPriority":17,"id":3805747,"name":"3 - 8 / 8 - 3"},{"status":"ACTIVE","sortPriority":18,"id":3805748,"name":"3 - 9 / 9 - 3"},{"status":"ACTIVE","sortPriority":19,"id":522754,"name":"4 - 5 / 5 - 4"},{"status":"ACTIVE","sortPriority":20,"id":522753,"name":"4 - 6 / 6 - 4"},{"status":"ACTIVE","sortPriority":21,"id":3805762,"name":"4 - 8 / 8 - 4"},{"status":"ACTIVE","sortPriority":22,"id":3805763,"name":"4 - 9 / 9 - 4"},{"status":"ACTIVE","sortPriority":23,"id":522755,"name":"5 - 6 / 6 - 5"},{"status":"ACTIVE","sortPriority":24,"id":3805772,"name":"5 - 8 / 8 - 5"},{"status":"ACTIVE","sortPriority":25,"id":3805777,"name":"5 - 9 / 9 - 5"},{"status":"ACTIVE","sortPriority":26,"id":3805784,"name":"6 - 8 / 8 - 6"},{"status":"ACTIVE","sortPriority":27,"id":3805785,"name":"6 - 9 / 9 - 6"},{"status":"ACTIVE","sortPriority":28,"id":3805799,"name":"8 - 9 / 9 - 8"}],"regulators":["MR_INT"],"venue":"Traralgon","countryCode":"AU","discountAllowed":true,"timezone":"Australia/Sydney","openDate":"2022-03-02T08:31:00.000Z","version":4382480603,"name":"Quinella","eventName":"Traralgon (AUS) 2nd Mar"},"rc":[],"con":true,"img":false}]}
{"op":"mcm","clk":"5346200445","pt":1646178438495,"mc":[{"id":"1.195453754","rc":[{"atb":[[42,4.86],[21,9.97],[15.5,18.35]],"id":3805785},{"atb":[[40,5.11],[100,2.01],[25,11.08]],"id":3805748},{"atb":[[38,5.39],[95,2.12],[24,11.56]],"id":522754},{"atb":[[5.3,46.41],[3.4,110.87],[3.9,68.81]],"id":522747},{"atb":[[3.45,81.45],[2.88,106.15],[2.68,158.38]],"id":522749},{"atb":[[65,3.11],[36,7.6],[180,1.11]],"id":522751},{"atb":[[600,0.44],[700,0.28],[850,0.23]],"id":3805732},{"atb":[[65,3.11],[19,14.78],[28,7.39]],"id":3805763},{"atb":[[11,19.95],[7.4,31.18],[5.7,56.61]],"id":522753},{"atb":[[600,0.44],[700,0.28],[850,0.23]],"id":3805777},{"atb":[[16,13.3],[11,26.6],[27,7.67]],"id":522741},{"atb":[[38,5.39],[95,2.12],[24,11.56]],"id":522743},{"atb":[[3.6,76.75],[3.1,126.7],[4.7,53.93]],"id":3805740},{"atb":[[600,0.44],[700,0.28],[850,0.23]],"id":7607472},{"atb":[[17,16.63],[48,4.24],[24,8.67]],"id":522745},{"atb":[[5.1,64.89],[9.2,24.33],[6.2,38.37]],"id":3805784},{"atb":[[8.6,35.01],[19,11.08],[11.5,19]],"id":3805747},{"atb":[[17,16.63],[48,4.24],[24,8.67]],"id":522755},{"atb":[[7.2,32.18],[5.1,48.67],[4.1,85.83]],"id":522746},{"atb":[[16,13.3],[11,26.6],[27,7.67]],"id":522748},{"atb":[[17.5,16.12],[50,4.07],[25,8.31]],"id":3805799},{"atb":[[22,9.5],[13.5,15.96],[9.4,31.67]],"id":522750},{"atb":[[75,2.69],[20,14],[30,6.88]],"id":3805731},{"atb":[[9,24.94],[7,44.34],[15,14.25]],"id":522752},{"atb":[[16,13.3],[7.4,41.57],[9.4,23.75]],"id":3805762},{"atb":[[65,3.11],[36,7.6],[180,1.11]],"id":522742},{"atb":[[9.2,32.44],[21,9.97],[13,16.63]],"id":3805741},{"atb":[[75,2.69],[20,14],[30,6.88]],"id":3805772}],"con":true,"img":false}]}
{"op":"mcm","clk":"5346401298","pt":1646182002775,"mc":[{"id":"1.195453754","marketDefinition":{"bspMarket":false,"turnInPlayEnabled":false,"persistenceEnabled":false,"marketBaseRate":7.0,"eventId":"31272494","eventTypeId":"4339","numberOfWinners":1,"bettingType":"ODDS","marketType":"QUINELLA","marketTime":"2022-03-02T10:11:00.000Z","suspendTime":"2022-03-02T10:11:00.000Z","bspReconciled":false,"complete":true,"inPlay":false,"crossMatching":false,"runnersVoidable":false,"numberOfActiveRunners":28,"betDelay":0,"status":"OPEN","runners":[{"status":"ACTIVE","sortPriority":1,"id":522741,"name":"1 - 2 / 2 - 1"},{"status":"ACTIVE","sortPriority":2,"id":522742,"name":"1 - 3 / 3 - 1"},{"status":"ACTIVE","sortPriority":3,"id":522743,"name":"1 - 4 / 4 - 1"},{"status":"ACTIVE","sortPriority":4,"id":7607472,"name":"1 - 5 / 5 - 1"},{"status":"ACTIVE","sortPriority":5,"id":522745,"name":"1 - 6 / 6 - 1"},{"status":"ACTIVE","sortPriority":6,"id":3805731,"name":"1 - 8 / 8 - 1"},{"status":"ACTIVE","sortPriority":7,"id":3805732,"name":"1 - 9 / 9 - 1"},{"status":"ACTIVE","sortPriority":8,"id":522746,"name":"2 - 3 / 3 - 2"},{"status":"ACTIVE","sortPriority":9,"id":522747,"name":"2 - 4 / 4 - 2"},{"status":"ACTIVE","sortPriority":10,"id":522748,"name":"2 - 5 / 5 - 2"},{"status":"ACTIVE","sortPriority":11,"id":522749,"name":"2 - 6 / 6 - 2"},{"status":"ACTIVE","sortPriority":12,"id":3805740,"name":"2 - 8 / 8 - 2"},{"status":"ACTIVE","sortPriority":13,"id":3805741,"name":"2 - 9 / 9 - 2"},{"status":"ACTIVE","sortPriority":14,"id":522750,"name":"3 - 4 / 4 - 3"},{"status":"ACTIVE","sortPriority":15,"id":522751,"name":"3 - 5 / 5 - 3"},{"status":"ACTIVE","sortPriority":16,"id":522752,"name":"3 - 6 / 6 - 3"},{"status":"ACTIVE","sortPriority":17,"id":3805747,"name":"3 - 8 / 8 - 3"},{"status":"ACTIVE","sortPriority":18,"id":3805748,"name":"3 - 9 / 9 - 3"},{"status":"ACTIVE","sortPriority":19,"id":522754,"name":"4 - 5 / 5 - 4"},{"status":"ACTIVE","sortPriority":20,"id":522753,"name":"4 - 6 / 6 - 4"},{"status":"ACTIVE","sortPriority":21,"id":3805762,"name":"4 - 8 / 8 - 4"},{"status":"ACTIVE","sortPriority":22,"id":3805763,"name":"4 - 9 / 9 - 4"},{"status":"ACTIVE","sortPriority":23,"id":522755,"name":"5 - 6 / 6 - 5"},{"status":"ACTIVE","sortPriority":24,"id":3805772,"name":"5 - 8 / 8 - 5"},{"status":"ACTIVE","sortPriority":25,"id":3805777,"name":"5 - 9 / 9 - 5"},{"status":"ACTIVE","sortPriority":26,"id":3805784,"name":"6 - 8 / 8 - 6"},{"status":"ACTIVE","sortPriority":27,"id":3805785,"name":"6 - 9 / 9 - 6"},{"status":"ACTIVE","sortPriority":28,"id":3805799,"name":"8 - 9 / 9 - 8"}],"regulators":["MR_INT"],"venue":"Traralgon","countryCode":"AU","discountAllowed":true,"timezone":"Australia/Sydney","openDate":"2022-03-02T08:31:00.000Z","version":4382480603,"name":"Quinella","eventName":"Traralgon (AUS) 2nd Mar"},"rc":[{"atb":[[42,4.86],[21,9.97],[15.5,18.35]],"id":3805785},{"atb":[[40,5.11],[100,2.01],[25,11.08]],"id":3805748},{"atb":[[38,5.39],[95,2.12],[24,11.56]],"id":522754},{"atb":[[5.3,46.41],[3.4,110.88],[3.9,68.82]],"id":522747},{"atb":[[3.45,81.46],[2.88,106.16],[2.68,158.4]],"id":522749},{"atb":[[65,3.11],[36,7.6],[180,1.11]],"id":522751},{"atb":[[600,0.44],[700,0.28],[850,0.23]],"id":3805732},{"atb":[[65,3.11],[19,14.78],[28,7.39]],"id":3805763},{"atb":[[11,19.95],[7.4,31.18],[5.7,56.62]],"id":522753},{"atb":[[600,0.44],[700,0.28],[850,0.23]],"id":3805777},{"atb":[[16,13.3],[11,26.61],[27,7.67]],"id":522741},{"atb":[[38,5.39],[95,2.12],[24,11.56]],"id":522743},{"atb":[[3.6,76.76],[3.1,126.72],[4.7,53.94]],"id":3805740},{"atb":[[600,0.44],[700,0.28],[850,0.23]],"id":7607472},{"atb":[[17,16.63],[48,4.24],[24,8.67]],"id":522745},{"atb":[[5.1,64.9],[9.2,24.34],[6.2,38.38]],"id":3805784},{"atb":[[8.6,35.01],[19,11.08],[11.5,19]],"id":3805747},{"atb":[[17,16.63],[48,4.24],[24,8.67]],"id":522755},{"atb":[[7.2,32.19],[5.1,48.67],[4.1,85.84]],"id":522746},{"atb":[[16,13.3],[11,26.61],[27,7.67]],"id":522748},{"atb":[[17.5,16.12],[50,4.07],[25,8.31]],"id":3805799},{"atb":[[22,9.5],[13.5,15.96],[9.4,31.68]],"id":522750},{"atb":[[75,2.69],[20,14],[30,6.88]],"id":3805731},{"atb":[[9,24.94],[7,44.35],[15,14.25]],"id":522752},{"atb":[[16,13.3],[7.4,41.58],[9.4,23.75]],"id":3805762},{"atb":[[65,3.11],[36,7.6],[180,1.11]],"id":522742},{"atb":[[9.2,32.45],[21,9.97],[13,16.63]],"id":3805741},{"atb":[[75,2.69],[20,14],[30,6.88]],"id":3805772}],"con":true,"img":true}]}
{"op":"mcm","clk":"5346767659","pt":1646187402719,"mc":[{"id":"1.195453754","marketDefinition":{"bspMarket":false,"turnInPlayEnabled":false,"persistenceEnabled":false,"marketBaseRate":7.0,"eventId":"31272494","eventTypeId":"4339","numberOfWinners":1,"bettingType":"ODDS","marketType":"QUINELLA","marketTime":"2022-03-02T10:11:00.000Z","suspendTime":"2022-03-02T10:11:00.000Z","bspReconciled":false,"complete":true,"inPlay":false,"crossMatching":false,"runnersVoidable":false,"numberOfActiveRunners":28,"betDelay":0,"status":"OPEN","runners":[{"status":"ACTIVE","sortPriority":1,"id":522741,"name":"1 - 2 / 2 - 1"},{"status":"ACTIVE","sortPriority":2,"id":522742,"name":"1 - 3 / 3 - 1"},{"status":"ACTIVE","sortPriority":3,"id":522743,"name":"1 - 4 / 4 - 1"},{"status":"ACTIVE","sortPriority":4,"id":7607472,"name":"1 - 5 / 5 - 1"},{"status":"ACTIVE","sortPriority":5,"id":522745,"name":"1 - 6 / 6 - 1"},{"status":"ACTIVE","sortPriority":6,"id":3805731,"name":"1 - 8 / 8 - 1"},{"status":"ACTIVE","sortPriority":7,"id":3805732,"name":"1 - 9 / 9 - 1"},{"status":"ACTIVE","sortPriority":8,"id":522746,"name":"2 - 3 / 3 - 2"},{"status":"ACTIVE","sortPriority":9,"id":522747,"name":"2 - 4 / 4 - 2"},{"status":"ACTIVE","sortPriority":10,"id":522748,"name":"2 - 5 / 5 - 2"},{"status":"ACTIVE","sortPriority":11,"id":522749,"name":"2 - 6 / 6 - 2"},{"status":"ACTIVE","sortPriority":12,"id":3805740,"name":"2 - 8 / 8 - 2"},{"status":"ACTIVE","sortPriority":13,"id":3805741,"name":"2 - 9 / 9 - 2"},{"status":"ACTIVE","sortPriority":14,"id":522750,"name":"3 - 4 / 4 - 3"},{"status":"ACTIVE","sortPriority":15,"id":522751,"name":"3 - 5 / 5 - 3"},{"status":"ACTIVE","sortPriority":16,"id":522752,"name":"3 - 6 / 6 - 3"},{"status":"ACTIVE","sortPriority":17,"id":3805747,"name":"3 - 8 / 8 - 3"},{"status":"ACTIVE","sortPriority":18,"id":3805748,"name":"3 - 9 / 9 - 3"},{"status":"ACTIVE","sortPriority":19,"id":522754,"name":"4 - 5 / 5 - 4"},{"status":"ACTIVE","sortPriority":20,"id":522753,"name":"4 - 6 / 6 - 4"},{"status":"ACTIVE","sortPriority":21,"id":3805762,"name":"4 - 8 / 8 - 4"},{"status":"ACTIVE","sortPriority":22,"id":3805763,"name":"4 - 9 / 9 - 4"},{"status":"ACTIVE","sortPriority":23,"id":522755,"name":"5 - 6 / 6 - 5"},{"status":"ACTIVE","sortPriority":24,"id":3805772,"name":"5 - 8 / 8 - 5"},{"status":"ACTIVE","sortPriority":25,"id":3805777,"name":"5 - 9 / 9 - 5"},{"status":"ACTIVE","sortPriority":26,"id":3805784,"name":"6 - 8 / 8 - 6"},{"status":"ACTIVE","sortPriority":27,"id":3805785,"name":"6 - 9 / 9 - 6"},{"status":"ACTIVE","sortPriority":28,"id":3805799,"name":"8 - 9 / 9 - 8"}],"regulators":["MR_INT"],"venue":"Traralgon","countryCode":"AU","discountAllowed":true,"timezone":"Australia/Sydney","openDate":"2022-03-02T08:31:00.000Z","version":4382480603,"name":"Quinella","eventName":"Traralgon (AUS) 2nd Mar"},"rc":[{"atb":[[42,4.87],[21,9.99],[15.5,18.38]],"id":3805785},{"atb":[[40,5.12],[100,2.01],[25,11.1]],"id":3805748},{"atb":[[38,5.4],[95,2.12],[24,11.58]],"id":522754},{"atb":[[5.3,46.49],[3.4,111.05],[3.9,68.92]],"id":522747},{"atb":[[3.45,81.59],[2.88,106.33],[2.68,158.65]],"id":522749},{"atb":[[65,3.12],[36,7.61],[180,1.11]],"id":522751},{"atb":[[600,0.44],[700,0.28],[850,0.23]],"id":3805732},{"atb":[[65,3.12],[19,14.8],[28,7.4]],"id":3805763},{"atb":[[11,19.99],[7.4,31.23],[5.7,56.7]],"id":522753},{"atb":[[600,0.44],[700,0.28],[850,0.23]],"id":3805777},{"atb":[[16,13.32],[11,26.65],[27,7.68]],"id":522741},{"atb":[[38,5.4],[95,2.12],[24,11.58]],"id":522743},{"atb":[[3.6,76.88],[3.1,126.92],[4.7,54.02]],"id":3805740},{"atb":[[600,0.44],[700,0.28],[850,0.23]],"id":7607472},{"atb":[[17,16.65],[48,4.25],[24,8.69]],"id":522745},{"atb":[[5.1,65],[9.2,24.37],[6.2,38.44]],"id":3805784},{"atb":[[8.6,35.07],[19,11.1],[11.5,19.03]],"id":3805747},{"atb":[[17,16.65],[48,4.25],[24,8.69]],"id":522755},{"atb":[[7.2,32.24],[5.1,48.75],[4.1,85.98]],"id":522746},{"atb":[[16,13.32],[11,26.65],[27,7.68]],"id":522748},{"atb":[[17.5,16.15],[50,4.07],[25,8.32]],"id":3805799},{"atb":[[22,9.52],[13.5,15.99],[9.4,31.73]],"id":522750},{"atb":[[75,2.69],[20,14.03],[30,6.89]],"id":3805731},{"atb":[[9,24.98],[7,44.42],[15,14.28]],"id":522752},{"atb":[[16,13.32],[7.4,41.64],[9.4,23.79]],"id":3805762},{"atb":[[65,3.12],[36,7.61],[180,1.11]],"id":522742},{"atb":[[9.2,32.5],[21,9.99],[13,16.65]],"id":3805741},{"atb":[[75,2.69],[20,14.03],[30,6.89]],"id":3805772}],"con":true,"img":true}]}
{"op":"mcm","clk":"5347092223","pt":1646192802701,"mc":[{"id":"1.195453754","marketDefinition":{"bspMarket":false,"turnInPlayEnabled":false,"persistenceEnabled":false,"marketBaseRate":7.0,"eventId":"31272494","eventTypeId":"4339","numberOfWinners":1,"bettingType":"ODDS","marketType":"QUINELLA","marketTime":"2022-03-02T10:11:00.000Z","suspendTime":"2022-03-02T10:11:00.000Z","bspReconciled":false,"complete":true,"inPlay":false,"crossMatching":false,"runnersVoidable":false,"numberOfActiveRunners":28,"betDelay":0,"status":"OPEN","runners":[{"status":"ACTIVE","sortPriority":1,"id":522741,"name":"1 - 2 / 2 - 1"},{"status":"ACTIVE","sortPriority":2,"id":522742,"name":"1 - 3 / 3 - 1"},{"status":"ACTIVE","sortPriority":3,"id":522743,"name":"1 - 4 / 4 - 1"},{"status":"ACTIVE","sortPriority":4,"id":7607472,"name":"1 - 5 / 5 - 1"},{"status":"ACTIVE","sortPriority":5,"id":522745,"name":"1 - 6 / 6 - 1"},{"status":"ACTIVE","sortPriority":6,"id":3805731,"name":"1 - 8 / 8 - 1"},{"status":"ACTIVE","sortPriority":7,"id":3805732,"name":"1 - 9 / 9 - 1"},{"status":"ACTIVE","sortPriority":8,"id":522746,"name":"2 - 3 / 3 - 2"},{"status":"ACTIVE","sortPriority":9,"id":522747,"name":"2 - 4 / 4 - 2"},{"status":"ACTIVE","sortPriority":10,"id":522748,"name":"2 - 5 / 5 - 2"},{"status":"ACTIVE","sortPriority":11,"id":522749,"name":"2 - 6 / 6 - 2"},{"status":"ACTIVE","sortPriority":12,"id":3805740,"name":"2 - 8 / 8 - 2"},{"status":"ACTIVE","sortPriority":13,"id":3805741,"name":"2 - 9 / 9 - 2"},{"status":"ACTIVE","sortPriority":14,"id":522750,"name":"3 - 4 / 4 - 3"},{"status":"ACTIVE","sortPriority":15,"id":522751,"name":"3 - 5 / 5 - 3"},{"status":"ACTIVE","sortPriority":16,"id":522752,"name":"3 - 6 / 6 - 3"},{"status":"ACTIVE","sortPriority":17,"id":3805747,"name":"3 - 8 / 8 - 3"},{"status":"ACTIVE","sortPriority":18,"id":3805748,"name":"3 - 9 / 9 - 3"},{"status":"ACTIVE","sortPriority":19,"id":522754,"name":"4 - 5 / 5 - 4"},{"status":"ACTIVE","sortPriority":20,"id":522753,"name":"4 - 6 / 6 - 4"},{"status":"ACTIVE","sortPriority":21,"id":3805762,"name":"4 - 8 / 8 - 4"},{"status":"ACTIVE","sortPriority":22,"id":3805763,"name":"4 - 9 / 9 - 4"},{"status":"ACTIVE","sortPriority":23,"id":522755,"name":"5 - 6 / 6 - 5"},{"status":"ACTIVE","sortPriority":24,"id":3805772,"name":"5 - 8 / 8 - 5"},{"status":"ACTIVE","sortPriority":25,"id":3805777,"name":"5 - 9 / 9 - 5"},{"status":"ACTIVE","sortPriority":26,"id":3805784,"name":"6 - 8 / 8 - 6"},{"status":"ACTIVE","sortPriority":27,"id":3805785,"name":"6 - 9 / 9 - 6"},{"status":"ACTIVE","sortPriority":28,"id":3805799,"name":"8 - 9 / 9 - 8"}],"regulators":["MR_INT"],"venue":"Traralgon","countryCode":"AU","discountAllowed":true,"timezone":"Australia/Sydney","openDate":"2022-03-02T08:31:00.000Z","version":4382480603,"name":"Quinella","eventName":"Traralgon (AUS) 2nd Mar"},"rc":[{"atb":[[42,4.88],[21,10.01],[15.5,18.41]],"id":3805785},{"atb":[[40,5.13],[100,2.02],[25,11.12]],"id":3805748},{"atb":[[38,5.41],[95,2.13],[24,11.6]],"id":522754},{"atb":[[5.3,46.56],[3.4,111.24],[3.9,69.04]],"id":522747},{"atb":[[3.45,81.72],[2.88,106.51],[2.68,158.91]],"id":522749},{"atb":[[65,3.12],[36,7.63],[180,1.11]],"id":522751},{"atb":[[600,0.44],[700,0.28],[850,0.23]],"id":3805732},{"atb":[[65,3.12],[19,14.83],[28,7.41]],"id":3805763},{"atb":[[11,20.02],[7.4,31.28],[5.7,56.8]],"id":522753},{"atb":[[600,0.44],[700,0.28],[850,0.23]],"id":3805777},{"atb":[[16,13.34],[11,26.69],[27,7.7]],"id":522741},{"atb":[[38,5.41],[95,2.13],[24,11.6]],"id":522743},{"atb":[[3.6,77.01],[3.1,127.13],[4.7,54.11]],"id":3805740},{"atb":[[600,0.44],[700,0.28],[850,0.23]],"id":7607472},{"atb":[[17,16.68],[48,4.26],[24,8.7]],"id":522745},{"atb":[[5.1,65.11],[9.2,24.42],[6.2,38.5]],"id":3805784},{"atb":[[8.6,35.13],[19,11.12],[11.5,19.06]],"id":3805747},{"atb":[[17,16.68],[48,4.26],[24,8.7]],"id":522755},{"atb":[[7.2,32.29],[5.1,48.83],[4.1,86.12]],"id":522746},{"atb":[[16,13.34],[11,26.69],[27,7.7]],"id":522748},{"atb":[[17.5,16.17],[50,4.08],[25,8.34]],"id":3805799},{"atb":[[22,9.53],[13.5,16.02],[9.4,31.78]],"id":522750},{"atb":[[75,2.7],[20,14.05],[30,6.9]],"id":3805731},{"atb":[[9,25.02],[7,44.49],[15,14.3]],"id":522752},{"atb":[[16,13.34],[7.4,41.71],[9.4,23.83]],"id":3805762},{"atb":[[65,3.12],[36,7.63],[180,1.11]],"id":522742},{"atb":[[9.2,32.55],[21,10.01],[13,16.68]],"id":3805741},{"atb":[[75,2.7],[20,14.05],[30,6.9]],"id":3805772}],"con":true,"img":true}]}
{"op":"mcm","clk":"5347381096","pt":1646198202719,"mc":[{"id":"1.195453754","marketDefinition":{"bspMarket":false,"turnInPlayEnabled":false,"persistenceEnabled":false,"marketBaseRate":7.0,"eventId":"31272494","eventTypeId":"4339","numberOfWinners":1,"bettingType":"ODDS","marketType":"QUINELLA","marketTime":"2022-03-02T10:11:00.000Z","suspendTime":"2022-03-02T10:11:00.000Z","bspReconciled":false,"complete":true,"inPlay":false,"crossMatching":false,"runnersVoidable":false,"numberOfActiveRunners":28,"betDelay":0,"status":"OPEN","runners":[{"status":"ACTIVE","sortPriority":1,"id":522741,"name":"1 - 2 / 2 - 1"},{"status":"ACTIVE","sortPriority":2,"id":522742,"name":"1 - 3 / 3 - 1"},{"status":"ACTIVE","sortPriority":3,"id":522743,"name":"1 - 4 / 4 - 1"},{"status":"ACTIVE","sortPriority":4,"id":7607472,"name":"1 - 5 / 5 - 1"},{"status":"ACTIVE","sortPriority":5,"id":522745,"name":"1 - 6 / 6 - 1"},{"status":"ACTIVE","sortPriority":6,"id":3805731,"name":"1 - 8 / 8 - 1"},{"status":"ACTIVE","sortPriority":7,"id":3805732,"name":"1 - 9 / 9 - 1"},{"status":"ACTIVE","sortPriority":8,"id":522746,"name":"2 - 3 / 3 - 2"},{"status":"ACTIVE","sortPriority":9,"id":522747,"name":"2 - 4 / 4 - 2"},{"status":"ACTIVE","sortPriority":10,"id":522748,"name":"2 - 5 / 5 - 2"},{"status":"ACTIVE","sortPriority":11,"id":522749,"name":"2 - 6 / 6 - 2"},{"status":"ACTIVE","sortPriority":12,"id":3805740,"name":"2 - 8 / 8 - 2"},{"status":"ACTIVE","sortPriority":13,"id":3805741,"name":"2 - 9 / 9 - 2"},{"status":"ACTIVE","sortPriority":14,"id":522750,"name":"3 - 4 / 4 - 3"},{"status":"ACTIVE","sortPriority":15,"id":522751,"name":"3 - 5 / 5 - 3"},{"status":"ACTIVE","sortPriority":16,"id":522752,"name":"3 - 6 / 6 - 3"},{"status":"ACTIVE","sortPriority":17,"id":3805747,"name":"3 - 8 / 8 - 3"},{"status":"ACTIVE","sortPriority":18,"id":3805748,"name":"3 - 9 / 9 - 3"},{"status":"ACTIVE","sortPriority":19,"id":522754,"name":"4 - 5 / 5 - 4"},{"status":"ACTIVE","sortPriority":20,"id":522753,"name":"4 - 6 / 6 - 4"},{"status":"ACTIVE","sortPriority":21,"id":3805762,"name":"4 - 8 / 8 - 4"},{"status":"ACTIVE","sortPriority":22,"id":3805763,"name":"4 - 9 / 9 - 4"},{"status":"ACTIVE","sortPriority":23,"id":522755,"name":"5 - 6 / 6 - 5"},{"status":"ACTIVE","sortPriority":24,"id":3805772,"name":"5 - 8 / 8 - 5"},{"status":"ACTIVE","sortPriority":25,"id":3805777,"name":"5 - 9 / 9 - 5"},{"status":"ACTIVE","sortPriority":26,"id":3805784,"name":"6 - 8 / 8 - 6"},{"status":"ACTIVE","sortPriority":27,"id":3805785,"name":"6 - 9 / 9 - 6"},{"status":"ACTIVE","sortPriority":28,"id":3805799,"name":"8 - 9 / 9 - 8"}],"regulators":["MR_INT"],"venue":"Traralgon","countryCode":"AU","discountAllowed":true,"timezone":"Australia/Sydney","openDate":"2022-03-02T08:31:00.000Z","version":4382480603,"name":"Quinella","eventName":"Traralgon (AUS) 2nd Mar"},"rc":[{"atb":[[42,4.88],[21,10],[15.5,18.4]],"id":3805785},{"atb":[[40,5.13],[100,2.02],[25,11.12]],"id":3805748},{"atb":[[38,5.41],[95,2.12],[24,11.6]],"id":522754},{"atb":[[5.3,46.55],[3.4,111.2],[3.9,69.01]],"id":522747},{"atb":[[3.45,81.69],[2.88,106.47],[2.68,158.85]],"id":522749},{"atb":[[65,3.12],[36,7.62],[180,1.11]],"id":522751},{"atb":[[600,0.44],[700,0.28],[850,0.23]],"id":3805732},{"atb":[[65,3.12],[19,14.82],[28,7.41]],"id":3805763},{"atb":[[11,20.01],[7.4,31.27],[5.7,56.78]],"id":522753},{"atb":[[600,0.44],[700,0.28],[850,0.23]],"id":3805777},{"atb":[[16,13.34],[11,26.68],[27,7.69]],"id":522741},{"atb":[[38,5.41],[95,2.12],[24,11.6]],"id":522743},{"atb":[[3.6,76.98],[3.1,127.08],[4.7,54.09]],"id":3805740},{"atb":[[600,0.44],[700,0.28],[850,0.23]],"id":7607472},{"atb":[[17,16.68],[48,4.25],[24,8.7]],"id":522745},{"atb":[[5.1,65.09],[9.2,24.41],[6.2,38.49]],"id":3805784},{"atb":[[8.6,35.11],[19,11.12],[11.5,19.06]],"id":3805747},{"atb":[[17,16.68],[48,4.25],[24,8.7]],"id":522755},{"atb":[[7.2,32.28],[5.1,48.81],[4.1,86.09]],"id":522746},{"atb":[[16,13.34],[11,26.68],[27,7.69]],"id":522748},{"atb":[[17.5,16.17],[50,4.08],[25,8.33]],"id":3805799},{"atb":[[22,9.53],[13.5,16.01],[9.4,31.77]],"id":522750},{"atb":[[75,2.7],[20,14.04],[30,6.9]],"id":3805731},{"atb":[[9,25.01],[7,44.48],[15,14.29]],"id":522752},{"atb":[[16,13.34],[7.4,41.7],[9.4,23.82]],"id":3805762},{"atb":[[65,3.12],[36,7.62],[180,1.11]],"id":522742},{"atb":[[9.2,32.54],[21,10],[13,16.68]],"id":3805741},{"atb":[[75,2.7],[20,14.04],[30,6.9]],"id":3805772}],"con":true,"img":true}]}
{"op":"mcm","clk":"5347412439","pt":1646198874961,"mc":[{"id":"1.195453754","rc":[{"atb":[[42,0],[21,0],[15.5,0]],"id":3805785},{"atb":[[40,0],[100,0],[25,0]],"id":3805748},{"atb":[[38,0],[95,0],[24,0]],"id":522754},{"atb":[[5.3,0],[3.4,0],[3.9,0]],"id":522747},{"atb":[[3.45,0],[2.88,0],[2.68,0]],"id":522749},{"atb":[[65,0],[36,0],[180,0]],"id":522751},{"atb":[[600,0],[700,0],[850,0]],"id":3805732},{"atb":[[65,0],[19,0],[28,0]],"id":3805763},{"atb":[[11,0],[7.4,0],[5.7,0]],"id":522753},{"atb":[[600,0],[700,0],[850,0]],"id":3805777},{"atb":[[16,0],[11,0],[27,0]],"id":522741},{"atb":[[38,0],[95,0],[24,0]],"id":522743},{"atb":[[3.6,0],[3.1,0],[4.7,0]],"id":3805740},{"atb":[[600,0],[700,0],[850,0]],"id":7607472},{"atb":[[17,0],[48,0],[24,0]],"id":522745},{"atb":[[5.1,0],[9.2,0],[6.2,0]],"id":3805784},{"atb":[[8.6,0],[19,0],[11.5,0]],"id":3805747},{"atb":[[17,0],[48,0],[24,0]],"id":522755},{"atb":[[7.2,0],[5.1,0],[4.1,0]],"id":522746},{"atb":[[16,0],[11,0],[27,0]],"id":522748},{"atb":[[17.5,0],[50,0],[25,0]],"id":3805799},{"atb":[[22,0],[13.5,0],[9.4,0]],"id":522750},{"atb":[[75,0],[20,0],[30,0]],"id":3805731},{"atb":[[9,0],[7,0],[15,0]],"id":522752},{"atb":[[16,0],[7.4,0],[9.4,0]],"id":3805762},{"atb":[[65,0],[36,0],[180,0]],"id":522742},{"atb":[[9.2,0],[21,0],[13,0]],"id":3805741},{"atb":[[75,0],[20,0],[30,0]],"id":3805772}],"con":true,"img":false}]}
{"op":"mcm","clk":"5347413175","pt":1646198892094,"mc":[{"id":"1.195453754","rc":[{"atb":[[40,5.13],[20,10.53],[15,19.06]],"id":3805785},{"atb":[[42,4.88],[26,10.67],[110,1.83]],"id":3805748},{"atb":[[44,4.65],[27,10.26],[120,1.68]],"id":522754},{"atb":[[5.6,43.51],[4.1,64.57],[3.55,104.66]],"id":522747},{"atb":[[2.8,111.2],[2.6,166.8],[3.25,88.95]],"id":522749},{"atb":[[70,2.89],[38,7.21],[190,1.05]],"id":522751},{"atb":[[600,0.44],[700,0.28],[850,0.23]],"id":3805732},{"atb":[[75,2.7],[20,14.04],[30,6.9]],"id":3805763},{"atb":[[8.6,26.33],[14,15.39],[6.6,47.66]],"id":522753},{"atb":[[600,0.44],[700,0.28],[850,0.23]],"id":3805777},{"atb":[[24,8.7],[9.8,30.33],[14.5,14.82]],"id":522741},{"atb":[[44,4.65],[27,10.26],[120,1.68]],"id":522743},{"atb":[[4.3,60.65],[3.4,83.4],[2.96,136.16]],"id":3805740},{"atb":[[600,0.44],[700,0.28],[850,0.23]],"id":7607472},{"atb":[[16.5,17.22],[46,4.44],[23,9.09]],"id":522745},{"atb":[[6.4,37.06],[5.2,63.54],[9.4,23.82]],"id":3805784},{"atb":[[9.2,32.54],[21,10],[13,16.68]],"id":3805747},{"atb":[[16.5,17.22],[46,4.44],[23,9.09]],"id":522755},{"atb":[[7.2,32.28],[5.1,48.81],[4.1,86.09]],"id":522746},{"atb":[[24,8.7],[9.8,30.33],[14.5,14.82]],"id":522748},{"atb":[[17.5,16.17],[50,4.08],[25,8.33]],"id":3805799},{"atb":[[16,13.34],[11,26.68],[27,7.69]],"id":522750},{"atb":[[70,2.89],[19.5,14.42],[29,7.14]],"id":3805731},{"atb":[[17,12.5],[9.8,22.74],[7.8,39.24]],"id":522752},{"atb":[[18.5,11.43],[11,20.01],[8.4,36.06]],"id":3805762},{"atb":[[70,2.89],[38,7.21],[190,1.05]],"id":522742},{"atb":[[8.6,35.11],[19,11.12],[11.5,19.06]],"id":3805741},{"atb":[[70,2.89],[19.5,14.42],[29,7.14]],"id":3805772}],"con":true,"img":false}]}
{"op":"mcm","clk":"5347825026","pt":1646208660453,"mc":[{"id":"1.195453754","rc":[{"atb":[[40,7.86],[20,10.52],[15,19.05],[30,3.27]],"id":3805785},{"atb":[[75,2.72],[42,4.87],[50,3.27],[26,10.67],[110,1.83]],"id":3805748},{"atb":[[42,3.27],[44,4.65],[27,10.26],[55,2.72],[120,1.68]],"id":522754},{"atb":[[5.6,43.5],[4.1,64.55],[3.55,104.63],[5.9,2.72],[5.4,3.27]],"id":522747},{"atb":[[2.8,111.17],[3.6,3.27],[3.85,2.72],[2.6,166.75],[3.25,88.93]],"id":522749},{"atb":[[65,2.72],[70,2.89],[38,7.21],[190,1.05],[46,3.27]],"id":522751},{"atb":[[600,0.44],[160,2.72],[110,3.27]],"id":3805732},{"atb":[[75,2.7],[20,14.04],[44,3.27],[30,6.89],[60,2.72]],"id":3805763},{"atb":[[8.6,26.33],[11,3.27],[13.5,2.72],[14,15.39],[6.6,47.64]],"id":522753},{"atb":[[130,3.27],[600,0.44],[180,2.72]],"id":3805777},{"atb":[[17,2.72],[24,8.7],[9.8,30.32],[14.5,18.1]],"id":522741},{"atb":[[36,3.27],[44,4.65],[46,2.72],[27,10.26],[120,1.68]],"id":522743},{"atb":[[4,3.27],[4.3,60.63],[4.5,2.72],[3.4,83.37],[2.96,136.12]],"id":3805740},{"atb":[[140,2.72],[600,0.44],[95,3.27]],"id":7607472},{"atb":[[16.5,17.21],[32,2.72],[46,4.44],[23,9.09],[26,3.27]],"id":522745},{"atb":[[6.4,37.05],[9.2,3.27],[10.5,2.72],[5.2,63.52],[9.4,23.82]],"id":3805784},{"atb":[[18,2.72],[9.2,32.53],[21,10],[13,16.67],[15.5,3.27]],"id":3805747},{"atb":[[16.5,17.21],[36,2.72],[46,4.44],[23,9.09],[28,3.27]],"id":522755},{"atb":[[7.2,32.27],[5.1,48.8],[5.8,3.27],[4.1,86.06],[6.6,2.72]],"id":522746},{"atb":[[16.5,3.27],[19,2.72],[24,8.7],[9.8,30.32],[14.5,14.82]],"id":522748},{"atb":[[17.5,16.16],[36,3.27],[46,2.72],[50,4.08],[25,8.33]],"id":3805799},{"atb":[[16,13.34],[19,3.27],[11,26.68],[23,2.72],[27,7.69]],"id":522750},{"atb":[[70,2.89],[19.5,14.42],[38,2.72],[29,10.42]],"id":3805731},{"atb":[[16,2.72],[17,12.5],[9.8,22.74],[13.5,3.27],[7.8,39.23]],"id":522752},{"atb":[[18.5,11.43],[11,20.01],[12.5,3.27],[8.4,36.05],[15,2.72]],"id":3805762},{"atb":[[70,2.89],[38,7.21],[44,3.27],[190,1.05],[60,2.72]],"id":522742},{"atb":[[8.6,35.1],[18,3.27],[19,11.11],[21,2.72],[11.5,19.05]],"id":3805741},{"atb":[[32,3.27],[70,2.89],[19.5,14.42],[42,2.72],[29,7.14]],"id":3805772}],"con":true,"img":false}]}
{"op":"mcm","clk":"5347828728","pt":1646208743046,"mc":[{"id":"1.195453754","rc":[{"atb":[[40,2.72],[20,0],[15,0]],"id":3805785},{"atb":[[42,0],[26,0],[110,0]],"id":3805748},{"atb":[[44,0],[27,0],[120,0]],"id":522754},{"atb":[[5.6,0],[4.1,0],[3.55,0]],"id":522747},{"atb":[[2.8,0],[2.6,0],[3.25,0]],"id":522749},{"atb":[[70,0],[38,0],[190,0]],"id":522751},{"atb":[[600,0],[700,0],[850,0]],"id":3805732},{"atb":[[75,0],[20,0],[30,0]],"id":3805763},{"atb":[[8.6,0],[14,0],[6.6,0]],"id":522753},{"atb":[[600,0],[700,0],[850,0]],"id":3805777},{"atb":[[24,0],[9.8,0],[14.5,3.27]],"id":522741},{"atb":[[44,0],[27,0],[120,0]],"id":522743},{"atb":[[4.3,0],[3.4,0],[2.96,0]],"id":3805740},{"atb":[[600,0],[700,0],[850,0]],"id":7607472},{"atb":[[16.5,0],[46,0],[23,0]],"id":522745},{"atb":[[6.4,0],[5.2,0],[9.4,0]],"id":3805784},{"atb":[[9.2,0],[21,0],[13,0]],"id":3805747},{"atb":[[16.5,0],[46,0],[23,0]],"id":522755},{"atb":[[7.2,0],[5.1,0],[4.1,0]],"id":522746},{"atb":[[24,0],[9.8,0],[14.5,0]],"id":522748},{"atb":[[17.5,0],[50,0],[25,0]],"id":3805799},{"atb":[[16,0],[11,0],[27,0]],"id":522750},{"atb":[[70,0],[19.5,0],[29,3.27]],"id":3805731},{"atb":[[17,0],[9.8,0],[7.8,0]],"id":522752},{"atb":[[18.5,0],[11,0],[8.4,0]],"id":3805762},{"atb":[[70,0],[38,0],[190,0]],"id":522742},{"atb":[[8.6,0],[19,0],[11.5,0]],"id":3805741},{"atb":[[70,0],[19.5,0],[29,0]],"id":3805772}],"con":true,"img":false}]}
{"op":"mcm","clk":"5347829392","pt":1646208757342,"mc":[{"id":"1.195453754","rc":[{"atb":[[38,5.4],[19.5,10.81],[14.5,19.76]],"id":3805785},{"atb":[[42,4.87],[26,10.67],[110,1.83]],"id":3805748},{"atb":[[44,4.65],[27,10.26],[120,1.68]],"id":522754},{"atb":[[3.6,102.62],[5.7,42.57],[4.2,62.53]],"id":522747},{"atb":[[3.2,90.96],[2.58,168.87],[2.78,112.42]],"id":522749},{"atb":[[70,2.89],[38,7.21],[190,1.05]],"id":522751},{"atb":[[600,0.44],[700,0.28],[850,0.23]],"id":3805732},{"atb":[[32,6.45],[80,2.53],[21,13.34]],"id":3805763},{"atb":[[6.4,49.41],[13.5,18.73],[8.4,27.04]],"id":522753},{"atb":[[600,0.44],[700,0.28],[850,0.23]],"id":3805777},{"atb":[[24,8.7],[9.8,30.32],[14.5,18.1]],"id":522741},{"atb":[[44,4.65],[27,10.26],[120,1.68]],"id":522743},{"atb":[[3.45,81.67],[2.98,134.75],[4.4,58.85]],"id":3805740},{"atb":[[600,0.44],[700,0.28],[850,0.23]],"id":7607472},{"atb":[[16.5,17.21],[46,4.44],[23,9.09]],"id":522745},{"atb":[[5.1,65.07],[9.2,27.68],[6.2,38.48]],"id":3805784},{"atb":[[9.2,32.53],[21,10],[13,16.67]],"id":3805747},{"atb":[[16.5,17.21],[46,4.44],[23,9.09]],"id":522755},{"atb":[[7.2,32.27],[5.1,48.8],[4.1,86.06]],"id":522746},{"atb":[[24,8.7],[9.8,30.32],[14.5,14.82]],"id":522748},{"atb":[[17.5,16.16],[50,4.08],[25,8.33]],"id":3805799},{"atb":[[16,13.34],[11,26.68],[27,7.69]],"id":522750},{"atb":[[70,2.89],[19.5,14.42],[29,10.42]],"id":3805731},{"atb":[[16.5,12.9],[9.6,23.26],[7.6,40.42]],"id":522752},{"atb":[[18.5,11.43],[11,20.01],[8.4,36.05]],"id":3805762},{"atb":[[70,2.89],[38,7.21],[190,1.05]],"id":522742},{"atb":[[8.6,35.1],[19,11.11],[11.5,19.05]],"id":3805741},{"atb":[[70,2.89],[19.5,14.42],[29,7.14]],"id":3805772}],"con":true,"img":false}]}
{"op":"mcm","clk":"5347830688","pt":1646208783754,"mc":[{"id":"1.195453754","rc":[{"atb":[[3.6,0],[3.85,0]],"id":522749}],"con":true,"img":false}]}
{"op":"mcm","clk":"5347830732","pt":1646208784685,"mc":[{"id":"1.195453754","rc":[{"atb":[[3.8,2.72],[3.55,3.27]],"id":522749}],"con":true,"img":false}]}
{"op":"mcm","clk":"5347871794","pt":1646209386256,"mc":[{"id":"1.195453754","rc":[{"atb":[[5.9,0],[5.4,0]],"id":522747}],"con":true,"img":false}]}
{"op":"mcm","clk":"5347871829","pt":1646209387022,"mc":[{"id":"1.195453754","rc":[{"atb":[[5.5,3.27],[6,2.72]],"id":522747}],"con":true,"img":false}]}
{"op":"mcm","clk":"5347971035","pt":1646211575716,"mc":[{"id":"1.195453754","rc":[{"atb":[[5.8,0],[6.6,0]],"id":522746}],"con":true,"img":false}]}
{"op":"mcm","clk":"5347971071","pt":1646211576548,"mc":[{"id":"1.195453754","rc":[{"atb":[[6.8,2.72],[5.9,3.27]],"id":522746}],"con":true,"img":false}]}
{"op":"mcm","clk":"5348005517","pt":1646212271991,"mc":[{"id":"1.195453754","rc":[{"atb":[[16,6.67],[38,5.4],[19.5,10.8],[40,2.72],[14.5,19.73],[30,3.26]],"id":3805785},{"atl":[[1000,2]],"id":3805785},{"atb":[[75,2.72],[42,4.87],[24,4.35],[50,3.26],[26,10.65],[110,1.83]],"id":3805748},{"atb":[[42,3.26],[44,4.64],[23,4.55],[55,2.72],[27,10.24],[120,1.67]],"id":522754},{"atl":[[1000,2]],"id":522754},{"atb":[[3.6,102.45],[2.88,53.19],[5.5,3.26],[6,2.72],[5.7,42.5],[4.2,62.43]],"id":522747},{"atl":[[330,2]],"id":522747},{"atb":[[2.4,71.43],[3.2,90.81],[3.8,2.72],[3.55,3.26],[2.58,168.6],[2.78,112.24]],"id":522749},{"atl":[[330,2]],"id":522749},{"atb":[[65,2.72],[70,2.89],[38,7.19],[190,1.05],[46,3.26],[23,4.55]],"id":522751},{"atl":[[1000,2]],"id":522751},{"atb":[[600,0.44],[160,2.72],[700,0.28],[850,0.23],[110,3.26],[27,2]],"id":3805732},{"atb":[[32,6.44],[80,2.52],[21,18.31],[44,3.26],[60,2.72]],"id":3805763},{"atb":[[4.8,26.32],[6.4,49.33],[11,3.26],[13.5,18.7],[8.4,26.99]],"id":522753},{"atl":[[530,2]],"id":522753},{"atb":[[130,3.26],[600,0.44],[700,0.28],[180,2.72],[850,0.23],[26,2]],"id":3805777},{"atb":[[17,2.72],[24,8.68],[6,20],[9.8,30.27],[14.5,18.07]],"id":522741},{"atl":[[610,2]],"id":522741},{"atb":[[36,3.26],[44,4.64],[46,2.72],[24,4.35],[27,10.24],[120,1.67]],"id":522743},{"atb":[[4,3.26],[3.45,81.54],[2.72,58.14],[4.5,2.72],[2.98,134.54],[4.4,58.76]],"id":3805740},{"atl":[[160,2]],"id":3805740},{"atb":[[140,2.72],[600,0.44],[700,0.28],[95,3.26],[850,0.23],[27,2]],"id":7607472},{"atb":[[32,2.72],[16.5,17.18],[46,4.44],[23,9.07],[6.8,8.9],[26,3.26]],"id":522745},{"atl":[[1000,2]],"id":522745},{"atb":[[3.6,38.46],[5.1,64.97],[9.2,27.63],[10.5,2.72],[6.2,38.42]],"id":3805784},{"atl":[[480,2]],"id":3805784},{"atb":[[4.8,20.02],[18,2.72],[9.2,32.48],[21,9.98],[13,16.64],[15.5,3.26]],"id":3805747},{"atl":[[540,2]],"id":3805747},{"atb":[[16.5,17.18],[36,2.72],[46,4.44],[23,9.07],[11.5,8.9],[28,3.26]],"id":522755},{"atl":[[1000,2]],"id":522755},{"atb":[[7.2,32.22],[5.1,48.72],[4.1,85.93],[6.8,2.72],[2.64,60.98],[5.9,3.26]],"id":522746},{"atl":[[270,2]],"id":522746},{"atb":[[16.5,3.26],[19,2.72],[5,17.4],[24,8.68],[9.8,30.27],[14.5,14.8]],"id":522748},{"atl":[[540,2]],"id":522748},{"atb":[[17.5,22.2],[36,3.26],[46,2.72],[50,4.07],[25,8.32]],"id":3805799},{"atl":[[1000,2]],"id":3805799},{"atb":[[16,13.31],[19,3.26],[11,26.63],[23,2.72],[27,7.68],[5.7,15.4]],"id":522750},{"atl":[[570,2]],"id":522750},{"atb":[[70,2.89],[38,2.72],[19.5,14.39],[23,4.55],[29,10.4]],"id":3805731},{"atl":[[1000,2]],"id":3805731},{"atb":[[16.5,12.88],[16,2.72],[9.6,23.23],[4.1,25.82],[7.6,40.36],[13.5,3.26]],"id":522752},{"atl":[[530,2]],"id":522752},{"atb":[[18.5,11.41],[11,19.97],[5.3,22.88],[12.5,3.26],[8.4,35.99],[15,2.72]],"id":3805762},{"atl":[[560,2]],"id":3805762},{"atb":[[70,2.89],[38,7.19],[21,5],[44,3.26],[190,1.05],[60,2.72]],"id":522742},{"atb":[[18,3.26],[8.6,35.05],[19,11.1],[21,2.72],[11.5,19.02],[6,20]],"id":3805741},{"atl":[[600,2]],"id":3805741},{"atb":[[32,3.26],[70,2.89],[19.5,14.39],[42,2.72],[29,7.13],[3.65,6.56]],"id":3805772},{"atl":[[1000,2]],"id":3805772}],"con":true,"img":false}]}
{"op":"mcm","clk":"5348006675","pt":1646212293930,"mc":[{"id":"1.195453754","rc":[{"atb":[[4,0],[4.5,0]],"id":3805740}],"con":true,"img":false}]}
{"op":"mcm","clk":"5348006718","pt":1646212294605,"mc":[{"id":"1.195453754","rc":[{"atb":[[4.6,2.72],[4.1,3.26]],"id":3805740}],"con":true,"img":false}]}
{"op":"mcm","clk":"5348008637","pt":1646212339415,"mc":[{"id":"1.195453754","rc":[{"atb":[[3.8,0],[3.55,0]],"id":522749},{"atb":[[9.2,24.36],[10.5,0]],"id":3805784}],"con":true,"img":false}]}
{"op":"mcm","clk":"5348008674","pt":1646212340085,"mc":[{"id":"1.195453754","rc":[{"atb":[[3.5,3.26],[3.75,2.72]],"id":522749},{"atb":[[9,3.26],[10,2.72]],"id":3805784}],"con":true,"img":false}]}
{"op":"mcm","clk":"5348011488","pt":1646212393290,"mc":[{"id":"1.195453754","rc":[{"atl":[[330,0],[95,2]],"id":522749},{"atb":[[6.8,0],[8.8,8.9]],"id":522745},{"atl":[[970,2],[1000,0]],"id":522755},{"atl":[[270,0],[220,2]],"id":522746},{"atb":[[3.65,0],[4.7,6.56]],"id":3805772}],"con":true,"img":false}]}
{"op":"mcm","clk":"5348030693","pt":1646212754828,"mc":[{"id":"1.195453754","rc":[{"atl":[[1000,2]],"id":3805748},{"atb":[[2.88,0],[3,50]],"id":522747},{"atl":[[80,2],[95,0]],"id":522749},{"atb":[[21,13.31],[26,4]],"id":3805763},{"atl":[[530,0],[520,2]],"id":522753},{"atl":[[590,2],[610,0]],"id":522741},{"atb":[[2.72,0],[2.86,53.76]],"id":3805740},{"atl":[[140,2],[160,0]],"id":3805740},{"atb":[[4,33.33],[3.6,0]],"id":3805784},{"atl":[[450,2],[480,0]],"id":3805784},{"atl":[[540,0],[530,2]],"id":3805747},{"atb":[[11.5,0],[14,7.69]],"id":522755},{"atl":[[930,2],[970,0]],"id":522755},{"atb":[[2.64,0],[2.78,56.18]],"id":522746},{"atb":[[5,0],[5.7,17.4]],"id":522748},{"atl":[[570,0],[560,2]],"id":522750},{"atl":[[530,0],[510,2]],"id":522752},{"atb":[[5.8,20.83],[5.3,0]],"id":3805762},{"atl":[[560,0],[550,2]],"id":3805762},{"atb":[[21,0],[26,4]],"id":522742},{"atl":[[1000,2]],"id":522742}],"con":true,"img":false}]}
{"op":"mcm","clk":"5348032816","pt":1646212794686,"mc":[{"id":"1.195453754","rc":[{"atb":[[4.8,0],[5.3,20.02]],"id":3805747},{"atl":[[930,0]],"id":522755},{"atb":[[17.5,16.14]],"id":3805799},{"atl":[[1000,0]],"id":3805731},{"atl":[[1000,0]],"id":522742}],"con":true,"img":false}]}
{"op":"mcm","clk":"5348032819","pt":1646212794748,"mc":[{"id":"1.195453754","rc":[{"atl":[[1000,0]],"id":3805748},{"atl":[[70,2],[80,0]],"id":522749},{"atl":[[920,2]],"id":522755},{"atb":[[23,4.55]],"id":3805799}],"con":true,"img":false}]}
{"op":"mcm","clk":"5348036128","pt":1646212852136,"mc":[{"id":"1.195453754","rc":[{"atb":[[4.6,0],[4.1,0]],"id":3805740},{"atb":[[18,0],[15.5,0]],"id":3805747},{"atb":[[12.5,0],[15,0]],"id":3805762}],"con":true,"img":false}]}
{"op":"mcm","clk":"5348036167","pt":1646212852807,"mc":[{"id":"1.195453754","rc":[{"atb":[[4.2,3.26],[4.7,2.72]],"id":3805740}],"con":true,"img":false}]}
{"op":"mcm","clk":"5348036173","pt":1646212852917,"mc":[{"id":"1.195453754","rc":[{"atb":[[16,3.26],[18.5,2.72]],"id":3805747},{"atb":[[13,3.26],[15.5,2.72]],"id":3805762}],"con":true,"img":false}]}
{"op":"mcm","clk":"5348036287","pt":1646212855041,"mc":[{"id":"1.195453754","rc":[{"atb":[[3.5,0],[3.75,0]],"id":522749}],"con":true,"img":false}]}
{"op":"mcm","clk":"5348036321","pt":1646212855758,"mc":[{"id":"1.195453754","rc":[{"atb":[[3.4,3.26],[3.65,2.72]],"id":522749}],"con":true,"img":false}]}
{"op":"mcm","clk":"5348038460","pt":1646212893211,"mc":[{"id":"1.195453754","rc":[{"atl":[[1000,2]],"id":3805748},{"atb":[[2.4,0],[2.5,66.67]],"id":522749},{"atl":[[130,2],[140,0]],"id":3805740},{"atl":[[540,0],[530,2]],"id":522748},{"atl":[[1000,2]],"id":3805731},{"atl":[[1000,2]],"id":522742}],"con":true,"img":false}]}
{"op":"mcm","clk":"5348039681","pt":1646212916031,"mc":[{"id":"1.195453754","rc":[{"atl":[[1000,0]],"id":3805748},{"atl":[[1000,0]],"id":3805731},{"atl":[[1000,0]],"id":522742}],"con":true,"img":false}]}
{"op":"mcm","clk":"5348039693","pt":1646212916386,"mc":[{"id":"1.195453754","rc":[{"atb":[[6.8,0],[5.9,0]],"id":522746}],"con":true,"img":false}]}
{"op":"mcm","clk":"5348039740","pt":1646212917105,"mc":[{"id":"1.195453754","rc":[{"atb":[[5.8,3.26],[6.6,2.72]],"id":522746}],"con":true,"img":false}]}
{"op":"mcm","clk":"5348041085","pt":1646212942873,"mc":[{"id":"1.195453754","rc":[{"atb":[[5.5,0],[6,0]],"id":522747},{"atb":[[160,0],[110,0]],"id":3805732},{"atb":[[17,0],[14.5,14.8]],"id":522741},{"atb":[[36,0],[46,0]],"id":522743},{"atb":[[140,0],[95,0]],"id":7607472},{"atb":[[16.5,0],[19,0]],"id":522748},{"atb":[[36,0],[46,0]],"id":3805799},{"atb":[[38,0],[29,7.13]],"id":3805731},{"atb":[[18,0],[21,0]],"id":3805741}],"con":true,"img":false}]}
{"op":"mcm","clk":"5348041124","pt":1646212943545,"mc":[{"id":"1.195453754","rc":[{"atb":[[5.6,3.26],[6.2,2.72]],"id":522747},{"atb":[[170,2.72],[120,3.26]],"id":3805732},{"atb":[[18,2.72],[15.5,3.26]],"id":522741},{"atb":[[38,3.26],[48,2.72]],"id":522743},{"atb":[[150,2.72],[100,3.26]],"id":7607472},{"atb":[[38,3.26],[48,2.72]],"id":3805799},{"atb":[[40,2.72],[30,3.26]],"id":3805731}],"con":true,"img":false}]}
{"op":"mcm","clk":"5348041136","pt":1646212943749,"mc":[{"id":"1.195453754","rc":[{"atb":[[17,3.26],[19.5,2.72]],"id":522748},{"atb":[[18.5,3.26],[22,2.72]],"id":3805741}],"con":true,"img":false}]}
{"op":"mcm","clk":"5348041668","pt":1646212953178,"mc":[{"id":"1.195453754","rc":[{"atl":[[1000,2]],"id":3805748},{"atl":[[1000,2]],"id":3805731},{"atl":[[1000,2]],"id":522742}],"con":true,"img":false}]}
{"op":"mcm","clk":"5348042777","pt":1646212973808,"mc":[{"id":"1.195453754","rc":[{"atb":[[38,0],[19.5,0],[14.5,0]],"id":3805785},{"atb":[[42,0],[26,0],[110,0]],"id":3805748},{"atb":[[44,0],[27,0],[120,0]],"id":522754},{"atb":[[3.6,0],[5.7,0],[4.2,0]],"id":522747},{"atb":[[3.2,0],[2.58,0],[2.78,0]],"id":522749},{"atb":[[70,0],[38,0],[190,0]],"id":522751},{"atb":[[600,0],[700,0],[850,0]],"id":3805732},{"atb":[[32,0],[80,0],[21,0]],"id":3805763},{"atb":[[6.4,0],[13.5,2.72],[8.4,0]],"id":522753},{"atb":[[600,0],[700,0],[850,0]],"id":3805777},{"atb":[[24,0],[9.8,0],[14.5,0]],"id":522741},{"atb":[[44,0],[27,0],[120,0]],"id":522743},{"atb":[[3.45,0],[2.98,0],[4.4,0]],"id":3805740},{"atb":[[600,0],[700,0],[850,0]],"id":7607472},{"atb":[[16.5,0],[46,0],[23,0]],"id":522745},{"atb":[[5.1,0],[9.2,0],[6.2,0]],"id":3805784},{"atb":[[9.2,0],[21,0],[13,0]],"id":3805747},{"atb":[[16.5,0],[46,0],[23,0]],"id":522755},{"atb":[[7.2,0],[5.1,0],[4.1,0]],"id":522746},{"atb":[[24,0],[9.8,0],[14.5,0]],"id":522748},{"atb":[[17.5,0],[50,0],[25,0]],"id":3805799},{"atb":[[16,0],[11,0],[27,0]],"id":522750},{"atb":[[70,0],[19.5,0],[29,0]],"id":3805731},{"atb":[[16.5,0],[9.6,0],[7.6,0]],"id":522752},{"atb":[[18.5,0],[11,0],[8.4,0]],"id":3805762},{"atb":[[70,0],[38,0],[190,0]],"id":522742},{"atb":[[8.6,0],[19,0],[11.5,0]],"id":3805741},{"atb":[[70,0],[19.5,0],[29,0]],"id":3805772}],"con":true,"img":false}]}
{"op":"mcm","clk":"5348043367","pt":1646212985357,"mc":[{"id":"1.195453754","rc":[{"atb":[[36,5.7],[90,2.24],[23,12.1]],"id":3805785},{"atb":[[320,0.62],[220,1.21],[470,0.42]],"id":3805748},{"atb":[[140,1.43],[48,4.25],[29,9.51]],"id":522754},{"atb":[[5.3,46.46],[3.4,110.99],[3.9,68.89]],"id":522747},{"atb":[[2.46,182.45],[2.66,120.35],[2.96,101.93]],"id":522749},{"atb":[[85,2.37],[44,6.19],[220,0.91]],"id":522751},{"atb":[[600,0.44],[700,0.28],[850,0.23]],"id":3805732},{"atb":[[340,0.58],[190,1.05],[95,2.83]],"id":3805763},{"atb":[[6.8,45.93],[8.8,25.61],[14.5,14.8]],"id":522753},{"atb":[[600,0.44],[700,0.28],[850,0.23]],"id":3805777},{"atb":[[16,13.31],[11,26.63],[27,7.68]],"id":522741},{"atb":[[90,2.24],[46,5.91],[230,0.87]],"id":522743},{"atb":[[3.2,90.81],[2.88,141.69],[3.95,67.72]],"id":3805740},{"atb":[[600,0.44],[700,0.28],[850,0.23]],"id":7607472},{"atb":[[65,3.12],[19,14.8],[28,7.4]],"id":522745},{"atb":[[6.8,34.44],[9.8,22.7],[5.4,60.54]],"id":3805784},{"atb":[[9.6,30.97],[23,9.07],[14,15.36]],"id":3805747},{"atb":[[17,16.64],[48,4.25],[24,8.68]],"id":522755},{"atb":[[3.95,90.29],[6.8,34.44],[4.9,51.22]],"id":522746},{"atb":[[22,9.51],[13.5,15.98],[9.4,31.71]],"id":522748},{"atb":[[75,2.69],[40,6.82],[200,1]],"id":3805799},{"atb":[[16.5,12.88],[11.5,25.36],[28,7.4]],"id":522750},{"atb":[[44,4.64],[27,10.24],[120,1.67]],"id":3805731},{"atb":[[18,11.74],[10.5,21.03],[8.2,36.99]],"id":522752},{"atb":[[8.6,35.05],[19,11.1],[11.5,19.02]],"id":3805762},{"atb":[[340,0.58],[190,1.05],[95,2.83]],"id":522742},{"atb":[[17.5,12.1],[12.5,23.16],[30,6.88]],"id":3805741},{"atb":[[32,9.71],[80,2.52],[21,13.31]],"id":3805772}],"con":true,"img":false}]}
{"op":"mcm","clk":"5348045118","pt":1646213017162,"mc":[{"id":"1.195453754","rc":[{"atb":[[11,0],[13.5,0]],"id":522753}],"con":true,"img":false}]}
{"op":"mcm","clk":"5348045181","pt":1646213017945,"mc":[{"id":"1.195453754","rc":[{"atb":[[10.5,3.26],[13,2.72]],"id":522753}],"con":true,"img":false}]}
{"op":"mcm","clk":"5348045685","pt":1646213026652,"mc":[{"id":"1.195453754","rc":[{"atb":[[130,0],[180,0]],"id":3805777},{"atb":[[32,6.44],[42,0]],"id":3805772}],"con":true,"img":false}]}
{"op":"mcm","clk":"5348045733","pt":1646213027575,"mc":[{"id":"1.195453754","rc":[{"atb":[[140,3.26],[190,2.72]],"id":3805777},{"atb":[[34,3.26],[44,2.72]],"id":3805772}],"con":true,"img":false}]}
{"op":"mcm","clk":"5348048285","pt":1646213073222,"mc":[{"id":"1.195453754","rc":[{"atl":[[1000,0]],"id":3805748},{"atb":[[2.88,53.19],[3,0]],"id":522747},{"atb":[[2.72,58.14],[2.86,0]],"id":3805740},{"atb":[[4,0],[3.6,38.46]],"id":3805784},{"atb":[[2.64,60.98],[2.78,0]],"id":522746},{"atb":[[5,25],[5.7,0]],"id":522748},{"atb":[[17.5,5.99],[23,0]],"id":3805799},{"atl":[[1000,0]],"id":522742}],"con":true,"img":false}]}
{"op":"mcm","clk":"5348049109","pt":1646213087053,"mc":[{"id":"1.195453754","rc":[{"atb":[[9,0],[10,0]],"id":3805784}],"con":true,"img":false}]}
{"op":"mcm","clk":"5348049146","pt":1646213087736,"mc":[{"id":"1.195453754","rc":[{"atb":[[9.2,3.26],[10.5,2.72]],"id":3805784}],"con":true,"img":false}]}
{"op":"mcm","clk":"5348049927","pt":1646213102252,"mc":[{"id":"1.195453754","rc":[{"atb":[[2.88,0],[3,50]],"id":522747},{"atb":[[2.72,0],[2.84,54.35]],"id":3805740},{"atb":[[3.6,0],[3.85,35.09]],"id":3805784},{"atb":[[2.74,57.47],[2.64,0]],"id":522746},{"atb":[[5,0],[5.5,22.22]],"id":522748},{"atb":[[17.5,0],[22,4.76]],"id":3805799}],"con":true,"img":false}]}
{"op":"mcm","clk":"5348053203","pt":1646213159435,"mc":[{"id":"1.195453754","rc":[{"atb":[[4.2,0],[4.7,0]],"id":3805740}],"con":true,"img":false}]}
{"op":"mcm","clk":"5348053249","pt":1646213160254,"mc":[{"id":"1.195453754","rc":[{"atb":[[4.8,2.72],[4.3,3.26]],"id":3805740}],"con":true,"img":false}]}
{"op":"mcm","clk":"5348056927","pt":1646213227994,"mc":[{"id":"1.195453754","rc":[{"atb":[[16,0]],"id":3805785},{"atl":[[1000,0]],"id":3805785},{"atb":[[24,0]],"id":522743},{"atb":[[3.85,0]],"id":3805784},{"atl":[[450,0]],"id":3805784},{"atb":[[5.3,0]],"id":3805747},{"atl":[[530,0]],"id":3805747}],"con":true,"img":false}]}
{"op":"mcm","clk":"5348056937","pt":1646213228204,"mc":[{"id":"1.195453754","rc":[{"atb":[[23,0]],"id":522754},{"atl":[[1000,0]],"id":522754},{"atb":[[27,0]],"id":3805732},{"atb":[[26,0]],"id":3805763},{"atb":[[2.74,0]],"id":522746},{"atl":[[220,0]],"id":522746},{"atb":[[22,0]],"id":3805799},{"atl":[[1000,0]],"id":3805799},{"atb":[[4.1,0]],"id":522752},{"atl":[[510,0]],"id":522752}],"con":true,"img":false}]}
{"op":"mcm","clk":"5348056947","pt":1646213228308,"mc":[{"id":"1.195453754","rc":[{"atb":[[38,2.72],[40,0],[29,3.26],[30,0]],"id":3805785},{"atb":[[6,0]],"id":522741},{"atl":[[590,0]],"id":522741},{"atb":[[2.84,0]],"id":3805740},{"atl":[[130,0]],"id":3805740},{"atb":[[9.2,0],[10.5,0]],"id":3805784},{"atb":[[16,0],[18.5,0]],"id":3805747}],"con":true,"img":false}]}
{"op":"mcm","clk":"5348056949","pt":1646213228418,"mc":[{"id":"1.195453754","rc":[{"atb":[[23,0]],"id":522751},{"atl":[[1000,0]],"id":522751},{"atb":[[4.8,0]],"id":522753},{"atl":[[520,0]],"id":522753},{"atb":[[38,0],[48,0]],"id":522743},{"atb":[[8.8,0]],"id":522745},{"atl":[[1000,0]],"id":522745},{"atb":[[14,0]],"id":522755},{"atl":[[920,0]],"id":522755},{"atb":[[5.8,0],[6.8,37.17],[6.6,0],[5.9,3.26]],"id":522746},{"atb":[[5.5,0]],"id":522748},{"atl":[[530,0]],"id":522748},{"atb":[[5.7,0]],"id":522750},{"atl":[[560,0]],"id":522750},{"atb":[[23,0]],"id":3805731},{"atl":[[1000,0]],"id":3805731},{"atb":[[5.8,0]],"id":3805762},{"atl":[[550,0]],"id":3805762},{"atb":[[6,0]],"id":3805741},{"atl":[[600,0]],"id":3805741},{"atb":[[4.7,0]],"id":3805772},{"atl":[[1000,0]],"id":3805772}],"con":true,"img":false}]}
{"op":"mcm","clk":"5348056954","pt":1646213228520,"mc":[{"id":"1.195453754","rc":[{"atb":[[170,0],[120,0]],"id":3805732},{"atb":[[38,0],[48,0]],"id":3805799},{"atb":[[13,3.26],[15.5,2.72]],"id":522752}],"con":true,"img":false}]}
{"op":"mcm","clk":"5348056960","pt":1646213228624,"mc":[{"id":"1.195453754","rc":[{"atb":[[24,0]],"id":3805748},{"atb":[[3,0]],"id":522747},{"atl":[[330,0]],"id":522747},{"atb":[[2.5,0]],"id":522749},{"atl":[[70,0]],"id":522749},{"atb":[[44,0],[60,0]],"id":3805763},{"atb":[[26,0]],"id":3805777},{"atb":[[17.5,2.72],[18,0],[15,3.26],[15.5,0]],"id":522741},{"atb":[[27,0]],"id":7607472},{"atb":[[19,0],[23,0]],"id":522750},{"atb":[[38,2.72],[40,0],[29,3.26],[30,0]],"id":3805731},{"atb":[[16,0],[13.5,0]],"id":522752},{"atb":[[13,0],[15.5,0]],"id":3805762},{"atb":[[26,0]],"id":522742}],"con":true,"img":false}]}
{"op":"mcm","clk":"5348056965","pt":1646213228729,"mc":[{"id":"1.195453754","rc":[{"atb":[[10.5,0],[13,0]],"id":522753},{"atb":[[32,0],[26,0]],"id":522745},{"atb":[[34,2.72],[36,0],[27,3.26],[28,0]],"id":522755}],"con":true,"img":false}]}
{"op":"mcm","clk":"5348056968","pt":1646213228834,"mc":[{"id":"1.195453754","rc":[{"atb":[[75,0],[50,0]],"id":3805748},{"atb":[[3.4,0],[3.5,3.26],[3.65,0],[3.75,2.72]],"id":522749},{"atb":[[130,3.26],[140,0],[180,2.72],[190,0]],"id":3805777},{"atb":[[44,0],[60,0]],"id":522742},{"atb":[[32,9.71],[34,0],[42,2.72],[44,0]],"id":3805772}],"con":true,"img":false}]}
{"op":"mcm","clk":"5348056973","pt":1646213228889,"mc":[{"id":"1.195453754","rc":[{"atb":[[5.6,0],[6.2,0]],"id":522747},{"atb":[[150,0],[100,0]],"id":7607472}],"con":true,"img":false}]}
{"op":"mcm","clk":"5348056976","pt":1646213228995,"mc":[{"id":"1.195453754","rc":[{"atb":[[9.2,3.26],[10.5,2.72]],"id":3805784},{"atb":[[16,3.26],[18.5,2.72]],"id":3805747}],"con":true,"img":false}]}
{"op":"mcm","clk":"5348056979","pt":1646213229097,"mc":[{"id":"1.195453754","rc":[{"atb":[[38,3.26],[48,2.72]],"id":522743}],"con":true,"img":false}]}
{"op":"mcm","clk":"5348056987","pt":1646213229303,"mc":[{"id":"1.195453754","rc":[{"atb":[[170,2.72],[120,3.26]],"id":3805732},{"atb":[[44,3.26],[60,2.72]],"id":3805763},{"atb":[[38,3.26],[48,2.72]],"id":3805799},{"atb":[[19,3.26],[23,2.72]],"id":522750},{"atb":[[13,3.26],[15.5,2.72]],"id":3805762}],"con":true,"img":false}]}
{"op":"mcm","clk":"5348056991","pt":1646213229407,"mc":[{"id":"1.195453754","rc":[{"atb":[[10.5,3.26],[13,2.72]],"id":522753}],"con":true,"img":false}]}
{"op":"mcm","clk":"5348056994","pt":1646213229511,"mc":[{"id":"1.195453754","rc":[{"atb":[[75,2.72],[50,3.26]],"id":3805748},{"atb":[[32,2.72],[26,3.26]],"id":522745},{"atb":[[44,3.26],[60,2.72]],"id":522742}],"con":true,"img":false}]}
{"op":"mcm","clk":"5348057000","pt":1646213229614,"mc":[{"id":"1.195453754","rc":[{"atb":[[5.6,3.26],[6.2,2.72]],"id":522747},{"atb":[[150,2.72],[100,3.26]],"id":7607472}],"con":true,"img":false}]}
{"op":"mcm","clk":"5348060179","pt":1646213294310,"mc":[{"id":"1.195453754","rc":[{"atb":[[150,0],[100,0]],"id":7607472},{"atb":[[32,0],[26,0]],"id":522745},{"atb":[[44,0],[60,0]],"id":522742}],"con":true,"img":false}]}
{"op":"mcm","clk":"5348060207","pt":1646213294983,"mc":[{"id":"1.195453754","rc":[{"atb":[[34,2.72],[27,3.26]],"id":522745},{"atb":[[65,2.72],[46,3.26]],"id":522742}],"con":true,"img":false}]}
{"op":"mcm","clk":"5348060215","pt":1646213295191,"mc":[{"id":"1.195453754","rc":[{"atb":[[160,2.72],[110,3.26]],"id":7607472}],"con":true,"img":false}]}
{"op":"mcm","clk":"5348062699","pt":1646213341688,"mc":[{"id":"1.195453754","rc":[{"atb":[[6.8,34.44],[5.9,0]],"id":522746}],"con":true,"img":false}]}
{"op":"mcm","clk":"5348062747","pt":1646213342371,"mc":[{"id":"1.195453754","rc":[{"atb":[[5.8,3.26],[6.6,2.72]],"id":522746}],"con":true,"img":false}]}
{"op":"mcm","clk":"5348063876","pt":1646213363494,"mc":[{"id":"1.195453754","rc":[{"atb":[[36,0],[90,0],[23,0]],"id":3805785},{"atb":[[320,0],[220,0],[470,0]],"id":3805748},{"atb":[[140,0],[48,0],[29,0]],"id":522754},{"atb":[[5.3,0],[3.4,0],[3.9,0]],"id":522747},{"atb":[[2.46,0],[2.66,0],[2.96,0]],"id":522749},{"atb":[[85,0],[44,0],[220,0]],"id":522751},{"atb":[[600,0],[700,0],[850,0]],"id":3805732},{"atb":[[340,0],[190,0],[95,0]],"id":3805763},{"atb":[[6.8,0],[8.8,0],[14.5,0]],"id":522753},{"atb":[[600,0],[700,0],[850,0]],"id":3805777},{"atb":[[16,0],[11,0],[27,0]],"id":522741},{"atb":[[90,0],[46,0],[230,0]],"id":522743},{"atb":[[3.2,0],[2.88,0],[3.95,0]],"id":3805740},{"atb":[[600,0],[700,0],[850,0]],"id":7607472},{"atb":[[65,0],[19,0],[28,0]],"id":522745},{"atb":[[6.8,0],[9.8,0],[5.4,0]],"id":3805784},{"atb":[[9.6,0],[23,0],[14,0]],"id":3805747},{"atb":[[17,0],[48,0],[24,0]],"id":522755},{"atb":[[3.95,0],[6.8,0],[4.9,0]],"id":522746},{"atb":[[22,0],[13.5,0],[9.4,0]],"id":522748},{"atb":[[75,0],[40,0],[200,0]],"id":3805799},{"atb":[[16.5,0],[11.5,0],[28,0]],"id":522750},{"atb":[[44,0],[27,0],[120,0]],"id":3805731},{"atb":[[18,0],[10.5,0],[8.2,0]],"id":522752},{"atb":[[8.6,0],[19,0],[11.5,0]],"id":3805762},{"atb":[[340,0],[190,0],[95,0]],"id":522742},{"atb":[[17.5,0],[12.5,0],[30,0]],"id":3805741},{"atb":[[32,3.26],[80,0],[21,0]],"id":3805772}],"con":true,"img":false}]}
{"op":"mcm","clk":"5348064705","pt":1646213378233,"mc":[{"id":"1.195453754","rc":[{"atb":[[36,5.7],[90,2.24],[23,12.1]],"id":3805785},{"atb":[[520,0.38],[270,0.99],[370,0.53]],"id":3805748},{"atb":[[150,1.34],[50,4.07],[30,9.18]],"id":522754},{"atb":[[3.45,108.73],[3.95,67.72],[5.4,45.4]],"id":522747},{"atb":[[2.54,129.73],[2.84,108.58],[2.34,198.8]],"id":522749},{"atb":[[90,2.24],[46,9.18],[230,0.87]],"id":522751},{"atb":[[600,0.44],[700,0.28],[850,0.23]],"id":3805732},{"atb":[[370,0.53],[220,0.91],[120,2.23]],"id":3805763},{"atb":[[6.4,49.33],[13.5,15.98],[8.4,26.99]],"id":522753},{"atb":[[600,0.44],[700,0.28],[850,0.23]],"id":3805777},{"atb":[[16,13.31],[11,26.63],[27,7.68]],"id":522741},{"atb":[[95,2.12],[48,8.39],[240,0.83]],"id":522743},{"atb":[[4.5,57.08],[3,133.19],[3.5,79.91]],"id":3805740},{"atb":[[600,0.44],[700,0.28],[850,0.23]],"id":7607472},{"atb":[[18.5,15.22],[27,10.95],[60,3.38]],"id":522745},{"atb":[[6.8,34.44],[9.8,22.7],[5.4,60.54]],"id":3805784},{"atb":[[10.5,28.03],[26,7.98],[15.5,13.77]],"id":3805747},{"atb":[[16.5,17.18],[46,4.44],[23,9.07]],"id":522755},{"atb":[[3.95,90.29],[6.8,34.44],[4.9,51.22]],"id":522746},{"atb":[[22,9.51],[13.5,15.98],[9.4,31.71]],"id":522748},{"atb":[[260,0.77],[110,1.83],[55,4.93]],"id":3805799},{"atb":[[16.5,12.88],[11.5,25.36],[28,7.4]],"id":522750},{"atb":[[150,1.34],[50,4.07],[30,9.18]],"id":3805731},{"atb":[[16.5,12.88],[9.6,23.23],[7.6,40.36]],"id":522752},{"atb":[[9,33.29],[20,10.51],[12.5,17.37]],"id":3805762},{"atb":[[340,0.58],[190,1.05],[95,2.83]],"id":522742},{"atb":[[32,6.44],[18,11.74],[13,22.19]],"id":3805741},{"atb":[[36,5.7],[90,2.24],[23,12.1]],"id":3805772}],"con":true,"img":false}]}
{"op":"mcm","clk":"5348067421","pt":1646213424501,"mc":[{"id":"1.195453754","rc":[{"atb":[[520,0],[270,0],[370,0]],"id":3805748},{"atb":[[150,0],[50,0],[30,0]],"id":522754},{"atb":[[3.45,0],[3.95,0],[5.4,0]],"id":522747},{"atb":[[2.54,0],[2.84,0],[2.34,0]],"id":522749},{"atb":[[90,0],[46,3.26],[230,0]],"id":522751},{"atb":[[600,0],[700,0],[850,0]],"id":3805732},{"atb":[[6.4,0],[13.5,0],[8.4,0]],"id":522753},{"atb":[[16,0],[11,0],[27,0]],"id":522741},{"atb":[[95,0],[48,2.72],[240,0]],"id":522743},{"atb":[[4.5,0],[3,0],[3.5,0]],"id":3805740},{"atb":[[18.5,0],[27,3.26],[60,0]],"id":522745},{"atb":[[10.5,0],[26,0],[15.5,0]],"id":3805747},{"atb":[[16.5,0],[46,0],[23,0]],"id":522755},{"atb":[[3.95,0],[6.8,0],[4.9,0]],"id":522746},{"atb":[[22,0],[13.5,0],[9.4,0]],"id":522748},{"atb":[[16.5,0],[11.5,0],[28,0]],"id":522750},{"atb":[[150,0],[50,0],[30,0]],"id":3805731},{"atb":[[16.5,0],[9.6,0],[7.6,0]],"id":522752},{"atb":[[340,0],[190,0],[95,0]],"id":522742},{"atb":[[32,0],[18,0],[13,0]],"id":3805741}],"con":true,"img":false}]}
{"op":"mcm","clk":"5348067426","pt":1646213424604,"mc":[{"id":"1.195453754","rc":[{"atb":[[36,0],[90,0],[23,0]],"id":3805785},{"atb":[[370,0],[220,0],[120,0]],"id":3805763},{"atb":[[600,0],[700,0],[850,0]],"id":3805777},{"atb":[[600,0],[700,0],[850,0]],"id":7607472},{"atb":[[6.8,0],[9.8,0],[5.4,0]],"id":3805784},{"atb":[[260,0],[110,0],[55,0]],"id":3805799},{"atb":[[9,0],[20,0],[12.5,0]],"id":3805762},{"atb":[[36,0],[90,0],[23,0]],"id":3805772}],"con":true,"img":false}]}
{"op":"mcm","clk":"5348067863","pt":1646213433587,"mc":[{"id":"1.195453754","rc":[{"atb":[[3.5,0],[3.75,0]],"id":522749},{"atb":[[9.2,0],[10.5,0]],"id":3805784}],"con":true,"img":false}]}
{"op":"mcm","clk":"5348067901","pt":1646213434310,"mc":[{"id":"1.195453754","rc":[{"atb":[[3.25,3.26],[3.5,2.72]],"id":522749}],"con":true,"img":false}]}
{"op":"mcm","clk":"5348067915","pt":1646213434518,"mc":[{"id":"1.195453754","rc":[{"atb":[[9.6,2.72],[8.6,3.26]],"id":3805784}],"con":true,"img":false}]}
{"op":"mcm","clk":"5348068374","pt":1646213442820,"mc":[{"id":"1.195453754","rc":[{"atb":[[4.3,60.54],[5.8,41.62],[3.65,100.52]],"id":522747},{"atb":[[2.82,109.77],[2.32,201.8],[2.52,131.44]],"id":522749},{"atb":[[600,0.44],[700,0.28],[850,0.23]],"id":3805732},{"atb":[[16,13.31],[11,26.63],[27,7.68]],"id":522741},{"atb":[[270,0.74],[120,1.67],[60,4.51]],"id":522743},{"atb":[[3.45,81.54],[2.98,134.54],[4.4,58.76]],"id":3805740},{"atb":[[600,0.44],[700,0.28],[850,0.23]],"id":7607472},{"atb":[[18,15.66],[26,7.98],[55,3.7]],"id":522745},{"atb":[[4.8,52.57],[6.6,38.39],[3.9,91.85]],"id":522746},{"atb":[[22,9.51],[13.5,15.98],[9.4,31.71]],"id":522748},{"atb":[[17,12.48],[12,24.21],[29,7.13]],"id":522750},{"atb":[[140,1.43],[48,4.25],[29,12.78]],"id":3805731},{"atb":[[320,0.62],[170,1.18],[85,3.17]],"id":522742},{"atb":[[32,6.44],[18,11.74],[13,22.19]],"id":3805741}],"con":true,"img":false}]}
{"op":"mcm","clk":"5348068380","pt":1646213442982,"mc":[{"id":"1.195453754","rc":[{"atb":[[34,6.05],[85,2.37],[22,12.68]],"id":3805785},{"atb":[[330,0.6],[230,1.16],[480,0.41]],"id":3805748},{"atb":[[34,8.07],[170,1.18],[60,3.38]],"id":522754},{"atb":[[80,2.52],[42,6.49],[210,0.95]],"id":522751},{"atb":[[270,0.74],[170,1.57],[420,0.47]],"id":3805763},{"atb":[[6.8,45.93],[8.8,25.61],[14.5,14.8]],"id":522753},{"atb":[[600,0.44],[700,0.28],[850,0.23]],"id":3805777},{"atb":[[6.4,36.99],[5.2,63.42],[9.4,23.78]],"id":3805784},{"atb":[[24,8.68],[9.8,30.27],[14.5,14.8]],"id":3805747},{"atb":[[16,17.76],[44,4.64],[22,9.51]],"id":522755},{"atb":[[95,2.12],[48,8.39],[240,0.83]],"id":3805799},{"atb":[[16,13.31],[7.4,41.62],[9.4,23.78]],"id":522752},{"atb":[[22,9.51],[13.5,15.98],[9.4,31.71]],"id":3805762},{"atb":[[34,6.05],[85,2.37],[22,12.68]],"id":3805772}],"con":true,"img":false}]}
{"op":"mcm","clk":"5348069073","pt":1646213455426,"mc":[{"id":"1.195453754","rc":[{"atb":[[18,5.88]],"id":3805785},{"atl":[[1000,2]],"id":3805785},{"atb":[[26,2.32]],"id":3805748},{"atb":[[25,4.17]],"id":522754},{"atl":[[1000,2]],"id":522754},{"atb":[[3,50]],"id":522747},{"atl":[[380,2]],"id":522747},{"atb":[[2.46,68.49]],"id":522749},{"atl":[[80,2]],"id":522749},{"atb":[[25,4.17]],"id":522751},{"atl":[[1000,2]],"id":522751},{"atb":[[29,2]],"id":3805732},{"atb":[[26,3.16]],"id":3805763},{"atb":[[5,25]],"id":522753},{"atl":[[520,2]],"id":522753},{"atb":[[29,2]],"id":3805777},{"atb":[[6.6,15.36]],"id":522741},{"atl":[[600,2]],"id":522741},{"atb":[[21,5]],"id":522743},{"atb":[[2.84,54.35]],"id":3805740},{"atl":[[140,2]],"id":3805740},{"atb":[[29,2]],"id":7607472},{"atb":[[8.8,7.4]],"id":522745},{"atl":[[1000,2]],"id":522745},{"atb":[[3.85,35.09]],"id":3805784},{"atl":[[470,2]],"id":3805784},{"atb":[[5.3,17.38]],"id":3805747},{"atl":[[530,2]],"id":3805747},{"atb":[[14,7.69]],"id":522755},{"atl":[[930,2]],"id":522755},{"atb":[[2.74,57.47]],"id":522746},{"atl":[[220,2]],"id":522746},{"atb":[[5.5,19.04]],"id":522748},{"atl":[[540,2]],"id":522748},{"atb":[[22,4.76]],"id":3805799},{"atl":[[1000,2]],"id":3805799},{"atb":[[6,14.26]],"id":522750},{"atl":[[560,2]],"id":522750},{"atb":[[26,4]],"id":3805731},{"atl":[[1000,2]],"id":3805731},{"atb":[[4.4,26.64]],"id":522752},{"atl":[[520,2]],"id":522752},{"atb":[[5.8,19.04]],"id":3805762},{"atl":[[550,2]],"id":3805762},{"atb":[[26,4]],"id":522742},{"atb":[[6,12.9]],"id":3805741},{"atl":[[610,2]],"id":3805741},{"atb":[[4.7,6.54]],"id":3805772},{"atl":[[1000,2]],"id":3805772}],"con":true,"img":false}]}
{"op":"mcm","clk":"5348069529","pt":1646213462529,"mc":[{"id":"1.195453754","rc":[{"atb":[[2.46,0],[2.34,74.63]],"id":522749},{"atl":[[1000,0]],"id":3805731}],"con":true,"img":false}]}
{"op":"mcm","clk":"5348070567","pt":1646213480691,"mc":[{"id":"1.195453754","rc":[{"atl":[[70,2],[80,0]],"id":522749},{"atl":[[920,2],[930,0]],"id":522755},{"atl":[[520,0],[500,2]],"id":522752}],"con":true,"img":false}]}
{"op":"mcm","clk":"5348071353","pt":1646213497500,"mc":[{"id":"1.195453754","rc":[{"atb":[[17.5,0],[15,0]],"id":522741},{"atb":[[38,0],[29,9.51]],"id":3805731}],"con":true,"img":false}]}
{"op":"mcm","clk":"5348071377","pt":1646213498016,"mc":[{"id":"1.195453754","rc":[{"atb":[[38,0],[48,0]],"id":522743}],"con":true,"img":false}]}
{"op":"mcm","clk":"5348071381","pt":1646213498118,"mc":[{"id":"1.195453754","rc":[{"atb":[[170,0],[120,0]],"id":3805732}],"con":true,"img":false}]}
{"op":"mcm","clk":"5348071384","pt":1646213498223,"mc":[{"id":"1.195453754","rc":[{"atb":[[19,2.72]],"id":522741}],"con":true,"img":false}]}
{"op":"mcm","clk":"5348071387","pt":1646213498326,"mc":[{"id":"1.195453754","rc":[{"atb":[[16.5,3.26]],"id":522741},{"atb":[[32,3.26],[42,2.72]],"id":3805731}],"con":true,"img":false}]}
{"op":"mcm","clk":"5348071402","pt":1646213498789,"mc":[{"id":"1.195453754","rc":[{"atb":[[130,3.26],[180,2.72]],"id":3805732},{"atb":[[40,3.26],[50,2.72]],"id":522743}],"con":true,"img":false}]}
{"op":"mcm","clk":"5348072225","pt":1646213515019,"mc":[{"id":"1.195453754","rc":[{"atb":[[34,0],[85,0],[22,0]],"id":3805785},{"atb":[[330,0],[230,0],[480,0]],"id":3805748},{"atb":[[34,0],[170,0],[60,0]],"id":522754},{"atb":[[4.3,0],[5.8,0],[3.65,0]],"id":522747},{"atb":[[2.82,0],[2.32,0],[2.52,0]],"id":522749},{"atb":[[80,0],[42,0],[210,0]],"id":522751},{"atb":[[600,0],[700,0],[850,0]],"id":3805732},{"atb":[[270,0],[170,0],[420,0]],"id":3805763},{"atb":[[6.8,0],[8.8,0],[14.5,0]],"id":522753},{"atb":[[600,0],[700,0],[850,0]],"id":3805777},{"atb":[[16,0],[11,0],[27,0]],"id":522741},{"atb":[[270,0],[120,0],[60,0]],"id":522743},{"atb":[[3.45,0],[2.98,0],[4.4,0]],"id":3805740},{"atb":[[600,0],[700,0],[850,0]],"id":7607472},{"atb":[[18,0],[26,0],[55,0]],"id":522745},{"atb":[[6.4,0],[5.2,0],[9.4,0]],"id":3805784},{"atb":[[24,0],[9.8,0],[14.5,0]],"id":3805747},{"atb":[[16,0],[44,0],[22,0]],"id":522755},{"atb":[[4.8,0],[6.6,2.72],[3.9,0]],"id":522746},{"atb":[[22,0],[13.5,0],[9.4,0]],"id":522748},{"atb":[[95,0],[48,2.72],[240,0]],"id":3805799},{"atb":[[17,0],[12,0],[29,0]],"id":522750},{"atb":[[140,0],[48,0],[29,0]],"id":3805731},{"atb":[[16,0],[7.4,0],[9.4,0]],"id":522752},{"atb":[[22,0],[13.5,0],[9.4,0]],"id":3805762},{"atb":[[320,0],[170,0],[85,0]],"id":522742},{"atb":[[32,0],[18,0],[13,0]],"id":3805741},{"atb":[[34,0],[85,0],[22,0]],"id":3805772}],"con":true,"img":false}]}
{"op":"mcm","clk":"5348072621","pt":1646213522952,"mc":[{"id":"1.195453754","rc":[{"atb":[[10.5,0],[13,0]],"id":522753}],"con":true,"img":false}]}
{"op":"mcm","clk":"5348072638","pt":1646213523162,"mc":[{"id":"1.195453754","rc":[{"atb":[[5,0],[4.9,25.64]],"id":522753}],"con":true,"img":false}]}
{"op":"mcm","clk":"5348072662","pt":1646213523732,"mc":[{"id":"1.195453754","rc":[{"atb":[[38,0],[29,0]],"id":3805785},{"atb":[[75,0],[50,0]],"id":3805748},{"atb":[[42,0],[55,0]],"id":522754},{"atb":[[5.6,0],[6.2,0]],"id":522747},{"atb":[[3.25,0],[3.5,0]],"id":522749},{"atb":[[65,0],[46,0]],"id":522751},{"atb":[[44,0],[60,0]],"id":3805763},{"atb":[[10,3.26],[12.5,2.72]],"id":522753},{"atb":[[130,0],[180,0]],"id":3805777},{"atb":[[16,0],[18.5,0]],"id":3805747},{"atb":[[34,0],[27,0]],"id":522755},{"atb":[[17,0],[19.5,0]],"id":522748},{"atb":[[38,0],[48,0]],"id":3805799},{"atb":[[19,0],[23,0]],"id":522750},{"atb":[[13,0],[15.5,0]],"id":3805762},{"atb":[[18.5,0],[22,0]],"id":3805741},{"atb":[[32,0],[42,0]],"id":3805772}],"con":true,"img":false}]}
{"op":"mcm","clk":"5348072665","pt":1646213523938,"mc":[{"id":"1.195453754","rc":[{"atb":[[16,6.67],[18,0]],"id":3805785},{"atb":[[13,8.33],[14,0]],"id":522755}],"con":true,"img":false}]}
{"op":"mcm","clk":"5348072686","pt":1646213524457,"mc":[{"id":"1.195453754","rc":[{"atb":[[34,3.26],[44,2.72]],"id":3805785},{"atb":[[65,3.26],[90,2.72]],"id":3805748},{"atb":[[65,2.72],[46,3.26]],"id":522754},{"atb":[[6.4,2.72],[5.7,3.26]],"id":522747},{"atb":[[3.45,2.72],[3.2,3.26]],"id":522749},{"atb":[[75,2.72],[50,3.26]],"id":522751},{"atb":[[75,2.72],[50,3.26]],"id":3805763},{"atb":[[200,3.26],[250,2.72]],"id":3805777},{"atb":[[17,3.26],[19.5,2.72]],"id":3805747},{"atb":[[38,2.72],[29,3.26]],"id":522755},{"atb":[[18,3.26],[21,2.72]],"id":522748},{"atb":[[42,3.26],[55,2.72]],"id":3805799},{"atb":[[20,3.26],[25,2.72]],"id":522750},{"atb":[[17,2.72],[14.5,3.26]],"id":3805762},{"atb":[[19.5,3.26],[24,2.72]],"id":3805741},{"atb":[[38,3.26],[48,2.72]],"id":3805772}],"con":true,"img":false}]}
{"op":"mcm","clk":"5348072988","pt":1646213528762,"mc":[{"id":"1.195453754","rc":[{"atb":[[34,9.32],[85,2.37],[22,12.68]],"id":3805785},{"atb":[[330,0.6],[230,1.16],[480,0.41]],"id":3805748},{"atb":[[34,8.07],[170,1.18],[60,3.38]],"id":522754},{"atb":[[80,2.52],[42,6.49],[210,0.95]],"id":522751},{"atb":[[270,0.74],[170,1.57],[420,0.47]],"id":3805763},{"atb":[[6.8,45.93],[8.8,25.61],[14.5,14.8]],"id":522753},{"atb":[[600,0.44],[700,0.28],[850,0.23]],"id":3805777},{"atb":[[6.4,36.99],[5.2,63.42],[9.4,23.78]],"id":3805784},{"atb":[[24,8.68],[9.8,30.27],[14.5,14.8]],"id":3805747},{"atb":[[16,17.76],[44,4.64],[22,9.51]],"id":522755},{"atb":[[95,2.12],[48,5.66],[240,0.83]],"id":3805799},{"atb":[[16,13.31],[7.4,41.62],[9.4,23.78]],"id":522752},{"atb":[[22,9.51],[13.5,15.98],[9.4,31.71]],"id":3805762},{"atb":[[34,6.05],[85,2.37],[22,12.68]],"id":3805772}],"con":true,"img":false}]}
{"op":"mcm","clk":"5348072994","pt":1646213528869,"mc":[{"id":"1.195453754","rc":[{"atb":[[4.3,60.54],[5.8,41.62],[3.65,100.52]],"id":522747},{"atb":[[2.82,109.77],[2.32,201.8],[2.52,131.44]],"id":522749},{"atb":[[600,0.44],[700,0.28],[850,0.23]],"id":3805732},{"atb":[[16,13.31],[11,26.63],[27,7.68]],"id":522741},{"atb":[[270,0.74],[120,1.67],[60,4.51]],"id":522743},{"atb":[[3.45,81.54],[2.98,134.54],[4.4,58.76]],"id":3805740},{"atb":[[600,0.44],[700,0.28],[850,0.23]],"id":7607472},{"atb":[[18,15.66],[26,7.98],[55,3.7]],"id":522745},{"atb":[[4.8,52.57],[6.6,38.39],[3.9,91.85]],"id":522746},{"atb":[[22,9.51],[13.5,15.98],[9.4,31.71]],"id":522748},{"atb":[[17,12.48],[12,24.21],[29,7.13]],"id":522750},{"atb":[[140,1.43],[48,4.25],[29,9.51]],"id":3805731},{"atb":[[320,0.62],[170,1.18],[85,3.17]],"id":522742},{"atb":[[32,6.44],[18,11.74],[13,22.19]],"id":3805741}],"con":true,"img":false}]}
{"op":"mcm","clk":"5348074534","pt":1646213557179,"mc":[{"id":"1.195453754","rc":[{"atb":[[65,0],[46,0]],"id":522742}],"con":true,"img":false}]}
{"op":"mcm","clk":"5348074552","pt":1646213557487,"mc":[{"id":"1.195453754","rc":[{"atb":[[160,0],[110,0]],"id":7607472}],"con":true,"img":false}]}
{"op":"mcm","clk":"5348074576","pt":1646213557900,"mc":[{"id":"1.195453754","rc":[{"atb":[[70,2.72],[48,3.26]],"id":522742}],"con":true,"img":false}]}
{"op":"mcm","clk":"5348074598","pt":1646213558163,"mc":[{"id":"1.195453754","rc":[{"atb":[[140,3.26],[190,2.72]],"id":7607472}],"con":true,"img":false}]}
{"op":"mcm","clk":"5348076129","pt":1646213582564,"mc":[{"id":"1.195453754","rc":[{"atl":[[1000,0]],"id":522754},{"atl":[[1000,0]],"id":522751},{"atb":[[2.74,0],[2.62,61.73]],"id":522746},{"atb":[[3.8,35.71],[4.4,0]],"id":522752}],"con":true,"img":false}]}
{"op":"mcm","clk":"5348078312","pt":1646213613218,"mc":[{"id":"1.195453754","rc":[{"atl":[[1000,2]],"id":522754},{"atb":[[2.46,68.49],[2.34,0]],"id":522749},{"atl":[[1000,2]],"id":522751},{"atb":[[2.74,57.47],[2.62,0]],"id":522746},{"atl":[[1000,2]],"id":3805731},{"atb":[[3.8,0],[4.4,29.41]],"id":522752}],"con":true,"img":false}]}
{"op":"mcm","clk":"5348078331","pt":1646213613524,"mc":[{"id":"1.195453754","rc":[{"atb":[[5.8,0],[6.6,35.67]],"id":522746}],"con":true,"img":false}]}
{"op":"mcm","clk":"5348078386","pt":1646213614305,"mc":[{"id":"1.195453754","rc":[{"atb":[[6.8,2.72],[5.9,3.26]],"id":522746}],"con":true,"img":false}]}
{"op":"mcm","clk":"5348078407","pt":1646213614722,"mc":[{"id":"1.195453754","rc":[{"atl":[[1000,0]],"id":3805731}],"con":true,"img":false}]}
{"op":"mcm","clk":"5348078429","pt":1646213615125,"mc":[{"id":"1.195453754","rc":[{"atb":[[6.8,0],[5.9,0]],"id":522746}],"con":true,"img":false}]}
{"op":"mcm","clk":"5348078472","pt":1646213615806,"mc":[{"id":"1.195453754","rc":[{"atb":[[5.8,3.26],[6.6,38.39]],"id":522746}],"con":true,"img":false}]}
{"op":"mcm","clk":"5348082735","pt":1646213682930,"mc":[{"id":"1.195453754","rc":[{"atb":[[9.6,0],[8.6,0]],"id":3805784}],"con":true,"img":false}]}
{"op":"mcm","clk":"5348082773","pt":1646213683617,"mc":[{"id":"1.195453754","rc":[{"atb":[[9,3.26]],"id":3805784}],"con":true,"img":false}]}
{"op":"mcm","clk":"5348082790","pt":1646213683920,"mc":[{"id":"1.195453754","rc":[{"atb":[[10,2.72]],"id":3805784}],"con":true,"img":false}]}
{"op":"mcm","clk":"5348083895","pt":1646213703170,"mc":[{"id":"1.195453754","rc":[{"atl":[[1000,2]],"id":3805731}],"con":true,"img":false}]}
{"op":"mcm","clk":"5348086127","pt":1646213740205,"mc":[{"id":"1.195453754","rc":[{"atb":[[32,0],[42,0]],"id":3805731}],"con":true,"img":false}]}
{"op":"mcm","clk":"5348086159","pt":1646213740720,"mc":[{"id":"1.195453754","rc":[{"atb":[[180,0]],"id":3805732},{"atb":[[50,0]],"id":522743}],"con":true,"img":false}]}
{"op":"mcm","clk":"5348086164","pt":1646213740821,"mc":[{"id":"1.195453754","rc":[{"atb":[[130,0]],"id":3805732},{"atb":[[40,0]],"id":522743}],"con":true,"img":false}]}
{"op":"mcm","clk":"5348086175","pt":1646213741026,"mc":[{"id":"1.195453754","rc":[{"atb":[[34,3.26],[44,2.72]],"id":3805731}],"con":true,"img":false}]}
{"op":"mcm","clk":"5348086211","pt":1646213741639,"mc":[{"id":"1.195453754","rc":[{"atb":[[170,3.26],[220,2.72]],"id":3805732},{"atb":[[44,3.26],[60,7.23]],"id":522743}],"con":true,"img":false}]}
{"op":"mcm","clk":"5348087487","pt":1646213763065,"mc":[{"id":"1.195453754","rc":[{"atb":[[12.5,0]],"id":522753}],"con":true,"img":false}]}
{"op":"mcm","clk":"5348087503","pt":1646213763429,"mc":[{"id":"1.195453754","rc":[{"atb":[[10,0]],"id":522753}],"con":true,"img":false}]}
{"op":"mcm","clk":"5348087517","pt":1646213763789,"mc":[{"id":"1.195453754","rc":[{"atb":[[38,0],[48,0]],"id":3805772}],"con":true,"img":false}]}
{"op":"mcm","clk":"5348087523","pt":1646213763839,"mc":[{"id":"1.195453754","rc":[{"atb":[[3.45,0],[3.2,0]],"id":522749},{"atb":[[42,0],[55,0]],"id":3805799}],"con":true,"img":false}]}
{"op":"mcm","clk":"5348087537","pt":1646213764044,"mc":[{"id":"1.195453754","rc":[{"atb":[[13.5,2.72]],"id":522753}],"con":true,"img":false}]}
{"op":"mcm","clk":"5348087552","pt":1646213764354,"mc":[{"id":"1.195453754","rc":[{"atb":[[11,3.26]],"id":522753}],"con":true,"img":false}]}
{"op":"mcm","clk":"5348087561","pt":1646213764559,"mc":[{"id":"1.195453754","rc":[{"atb":[[40,3.26],[50,2.72]],"id":3805772}],"con":true,"img":false}]}
{"op":"mcm","clk":"5348087568","pt":1646213764664,"mc":[{"id":"1.195453754","rc":[{"atb":[[3.55,2.72]],"id":522749}],"con":true,"img":false}]}
{"op":"mcm","clk":"5348087575","pt":1646213764766,"mc":[{"id":"1.195453754","rc":[{"atb":[[3.3,3.26]],"id":522749},{"atb":[[44,3.26],[60,2.72]],"id":3805799}],"con":true,"img":false}]}
{"op":"mcm","clk":"5348091028","pt":1646213823154,"mc":[{"id":"1.195453754","rc":[{"atb":[[2.86,53.76],[3,0]],"id":522747},{"atb":[[2.72,58.14],[2.84,0]],"id":3805740},{"atl":[[1000,0]],"id":3805731}],"con":true,"img":false}]}
{"op":"mcm","clk":"5348092273","pt":1646213844703,"mc":[{"id":"1.195453754","rc":[{"atb":[[3.55,0],[3.3,0]],"id":522749},{"atb":[[75,0],[50,0]],"id":522751},{"atb":[[200,0],[250,0]],"id":3805777},{"atb":[[4.8,0],[4.3,0]],"id":3805740},{"atb":[[17,0],[19.5,0]],"id":3805747},{"atb":[[34,0],[44,0]],"id":3805731},{"atb":[[17,0],[14.5,0]],"id":3805762}],"con":true,"img":false}]}
{"op":"mcm","clk":"5348092312","pt":1646213845376,"mc":[{"id":"1.195453754","rc":[{"atb":[[3.25,3.26],[3.5,2.72]],"id":522749},{"atb":[[80,5.25],[55,3.26]],"id":522751},{"atb":[[260,2.72],[210,3.26]],"id":3805777},{"atb":[[4.9,2.72],[4.4,62.03]],"id":3805740},{"atb":[[17.5,3.26],[20,2.72]],"id":3805747},{"atb":[[36,3.26],[46,2.72]],"id":3805731},{"atb":[[17.5,2.72],[15,3.26]],"id":3805762}],"con":true,"img":false}]}
{"op":"mcm","clk":"5348092355","pt":1646213845995,"mc":[{"id":"1.195453754","rc":[{"atb":[[5.8,0],[6.6,35.67]],"id":522746}],"con":true,"img":false}]}
{"op":"mcm","clk":"5348092399","pt":1646213846718,"mc":[{"id":"1.195453754","rc":[{"atb":[[5.9,3.26]],"id":522746}],"con":true,"img":false}]}
{"op":"mcm","clk":"5348092405","pt":1646213846772,"mc":[{"id":"1.195453754","rc":[{"atb":[[6.8,2.72]],"id":522746}],"con":true,"img":false}]}
{"op":"mcm","clk":"5348095770","pt":1646213907062,"mc":[{"id":"1.195453754","rc":[{"atb":[[9,0]],"id":3805784}],"con":true,"img":false}]}
{"op":"mcm","clk":"5348095787","pt":1646213907371,"mc":[{"id":"1.195453754","rc":[{"atb":[[10,0]],"id":3805784}],"con":true,"img":false}]}
{"op":"mcm","clk":"5348095825","pt":1646213908091,"mc":[{"id":"1.195453754","rc":[{"atb":[[9.2,3.26]],"id":3805784}],"con":true,"img":false}]}
{"op":"mcm","clk":"5348095845","pt":1646213908402,"mc":[{"id":"1.195453754","rc":[{"atb":[[10.5,2.72]],"id":3805784}],"con":true,"img":false}]}
{"op":"mcm","clk":"5348098607","pt":1646213954893,"mc":[{"id":"1.195453754","rc":[{"atb":[[2.86,0],[3,50]],"id":522747},{"atb":[[2.72,0],[2.92,52.08]],"id":3805740}],"con":true,"img":false}]}
{"op":"mcm","clk":"5348098634","pt":1646213955256,"mc":[{"id":"1.195453754","rc":[{"atb":[[6.8,0],[5.9,0]],"id":522746}],"con":true,"img":false}]}
{"op":"mcm","clk":"5348098691","pt":1646213955975,"mc":[{"id":"1.195453754","rc":[{"atb":[[5.8,3.26],[6.6,38.39]],"id":522746}],"con":true,"img":false}]}
{"op":"mcm","clk":"5348098871","pt":1646213959087,"mc":[{"id":"1.195453754","rc":[{"atb":[[170,0],[220,0]],"id":3805732}],"con":true,"img":false}]}
{"op":"mcm","clk":"5348098918","pt":1646213959914,"mc":[{"id":"1.195453754","rc":[{"atb":[[180,3.26],[230,2.72]],"id":3805732}],"con":true,"img":false}]}
{"op":"mcm","clk":"5348100028","pt":1646213980024,"mc":[{"id":"1.195453754","rc":[{"atb":[[40,0],[50,0]],"id":3805772}],"con":true,"img":false}]}
{"op":"mcm","clk":"5348100064","pt":1646213980698,"mc":[{"id":"1.195453754","rc":[{"atb":[[42,3.26],[55,2.72]],"id":3805772}],"con":true,"img":false}]}
{"op":"mcm","clk":"5348104871","pt":1646214062290,"mc":[{"id":"1.195453754","rc":[{"atb":[[4.9,0],[4.4,58.76]],"id":3805740},{"atb":[[140,0],[190,0]],"id":7607472},{"atb":[[17.5,0],[20,0]],"id":3805747},{"atb":[[44,0],[60,0]],"id":3805799},{"atb":[[36,0],[46,0]],"id":3805731},{"atb":[[17.5,0],[15,0]],"id":3805762}],"con":true,"img":false}]}
{"op":"mcm","clk":"5348104917","pt":1646214062961,"mc":[{"id":"1.195453754","rc":[{"atb":[[4.5,3.26],[5,2.72]],"id":3805740},{"atb":[[150,3.26],[200,2.72]],"id":7607472},{"atb":[[18,3.26],[21,2.72]],"id":3805747},{"atb":[[65,2.72],[46,3.26]],"id":3805799},{"atb":[[38,3.26],[48,6.97]],"id":3805731},{"atb":[[18,2.72],[15.5,3.26]],"id":3805762}],"con":true,"img":false}]}
{"op":"mcm","clk":"5348105682","pt":1646214074887,"mc":[{"id":"1.195453754","rc":[{"atb":[[2.86,53.76],[3,0]],"id":522747},{"atb":[[2.46,0],[2.28,78.13]],"id":522749},{"atl":[[1000,0]],"id":522751},{"atb":[[2.92,0],[2.78,56.18]],"id":3805740},{"atb":[[2.74,0],[2.6,62.5]],"id":522746},{"atb":[[4.4,0],[3.9,34.48]],"id":522752}],"con":true,"img":false}]}
{"op":"mcm","clk":"5348105696","pt":1646214075093,"mc":[{"id":"1.195453754","rc":[{"atb":[[16,0],[18.5,5.71]],"id":3805785},{"atb":[[2.86,0],[2.96,51.02]],"id":522747},{"atl":[[520,0],[510,2]],"id":522753},{"atb":[[2.92,52.08],[2.78,0]],"id":3805740},{"atl":[[460,2],[470,0]],"id":3805784},{"atb":[[5.5,0],[6,19.04]],"id":522748}],"con":true,"img":false}]}
{"op":"mcm","clk":"5348106976","pt":1646214093235,"mc":[{"id":"1.195453754","rc":[{"atl":[[1000,2]],"id":522751},{"atl":[[560,0],[550,2]],"id":522750}],"con":true,"img":false}]}
{"op":"mcm","clk":"5348107013","pt":1646214093909,"mc":[{"id":"1.195453754","rc":[{"atb":[[2.4,71.43],[2.28,0]],"id":522749},{"atb":[[2.74,57.47],[2.6,0]],"id":522746}],"con":true,"img":false}]}
{"op":"mcm","clk":"5348107542","pt":1646214103343,"mc":[{"id":"1.195453754","rc":[{"atb":[[34,6.05],[44,0]],"id":3805785},{"atb":[[75,0],[50,0]],"id":3805763},{"atb":[[11,0],[13.5,0]],"id":522753}],"con":true,"img":false}]}
{"op":"mcm","clk":"5348107548","pt":1646214103446,"mc":[{"id":"1.195453754","rc":[{"atb":[[65,0],[46,0]],"id":522754},{"atb":[[3.25,0],[3.5,0]],"id":522749},{"atb":[[260,0],[210,0]],"id":3805777},{"atb":[[34,0],[27,0]],"id":522745},{"atb":[[38,0],[29,0]],"id":522755},{"atb":[[13,0],[15.5,0]],"id":522752}],"con":true,"img":false}]}
{"op":"mcm","clk":"5348107584","pt":1646214104071,"mc":[{"id":"1.195453754","rc":[{"atb":[[36,3.26],[46,2.72]],"id":3805785},{"atb":[[80,2.72],[55,3.26]],"id":3805763},{"atb":[[11.5,3.26],[14,2.72]],"id":522753}],"con":true,"img":false}]}
{"op":"mcm","clk":"5348107593","pt":1646214104127,"mc":[{"id":"1.195453754","rc":[{"atb":[[70,2.72],[48,3.26]],"id":522754},{"atb":[[3.6,2.72],[3.35,3.26]],"id":522749},{"atb":[[270,2.72],[220,3.26]],"id":3805777},{"atb":[[36,2.72],[28,3.26]],"id":522745},{"atb":[[40,2.72],[30,3.26]],"id":522755},{"atb":[[16,16.04],[13.5,3.26]],"id":522752}],"con":true,"img":false}]}
{"op":"mcm","clk":"5348107829","pt":1646214109034,"mc":[{"id":"1.195453754","rc":[{"atb":[[9.2,0]],"id":3805784}],"con":true,"img":false}]}
{"op":"mcm","clk":"5348107837","pt":1646214109237,"mc":[{"id":"1.195453754","rc":[{"atb":[[10.5,0]],"id":3805784}],"con":true,"img":false}]}
{"op":"mcm","clk":"5348107866","pt":1646214109854,"mc":[{"id":"1.195453754","rc":[{"atb":[[9.6,3.26]],"id":3805784}],"con":true,"img":false}]}
{"op":"mcm","clk":"5348107878","pt":1646214110061,"mc":[{"id":"1.195453754","rc":[{"atb":[[11.5,2.72]],"id":3805784}],"con":true,"img":false}]}
{"op":"mcm","clk":"5348107954","pt":1646214111869,"mc":[{"id":"1.195453754","rc":[{"atl":[[960,2],[1000,0]],"id":3805785},{"atl":[[1000,2]],"id":3805763},{"atl":[[480,2],[510,0]],"id":522753},{"atl":[[140,0]],"id":3805740},{"atl":[[460,0],[450,2]],"id":3805784},{"atl":[[530,0],[520,2]],"id":3805747},{"atl":[[840,2],[920,0]],"id":522755},{"atl":[[520,2]],"id":522748},{"atl":[[530,2],[550,0]],"id":522750},{"atl":[[480,2],[500,0]],"id":522752},{"atl":[[530,2],[550,0]],"id":3805762},{"atl":[[590,2]],"id":3805741},{"atl":[[990,2]],"id":3805772}],"con":true,"img":false}]}
{"op":"mcm","clk":"5348107960","pt":1646214111972,"mc":[{"id":"1.195453754","rc":[{"atl":[[1000,2]],"id":3805748},{"atl":[[120,2]],"id":3805740},{"atl":[[540,0]],"id":522748},{"atl":[[610,0]],"id":3805741},{"atl":[[1000,0]],"id":3805772}],"con":true,"img":false}]}
{"op":"mcm","clk":"5348110394","pt":1646214155600,"mc":[{"id":"1.195453754","rc":[{"atb":[[180,0],[230,0]],"id":3805732}],"con":true,"img":false}]}
{"op":"mcm","clk":"5348110437","pt":1646214156327,"mc":[{"id":"1.195453754","rc":[{"atb":[[190,3.26],[240,2.72]],"id":3805732}],"con":true,"img":false}]}
{"op":"mcm","clk":"5348113862","pt":1646214213212,"mc":[{"id":"1.195453754","rc":[{"atl":[[1000,0]],"id":3805748},{"atb":[[2.8,55.56],[2.96,0]],"id":522747},{"atl":[[1000,0]],"id":3805763},{"atb":[[4.3,30.3],[4.9,0]],"id":522753},{"atb":[[2.8,55.56],[2.92,0]],"id":3805740},{"atl":[[520,0],[530,2]],"id":3805747},{"atb":[[2.74,0],[2.62,61.73]],"id":522746},{"atb":[[5.3,23.26],[6,0]],"id":522748},{"atb":[[6,0],[5.4,19.62]],"id":522750}],"con":true,"img":false}]}
{"op":"mcm","clk":"5348113885","pt":1646214213623,"mc":[{"id":"1.195453754","rc":[{"atb":[[4.5,0],[5,0]],"id":3805740}],"con":true,"img":false}]}
{"op":"mcm","clk":"5348113947","pt":1646214214291,"mc":[{"id":"1.195453754","rc":[{"atb":[[4.9,2.72],[4.4,62.03]],"id":3805740}],"con":true,"img":false}]}
{"op":"mcm","clk":"5348116449","pt":1646214255416,"mc":[{"id":"1.195453754","rc":[{"atb":[[2.8,0],[2.92,52.08]],"id":522747},{"atl":[[1000,2]],"id":3805763},{"atb":[[2.8,0],[2.92,52.08]],"id":3805740},{"atl":[[530,0],[520,2]],"id":3805747},{"atb":[[2.72,58.14],[2.62,0]],"id":522746},{"atb":[[5.9,19.62],[5.4,0]],"id":522750}],"con":true,"img":false}]}
{"op":"mcm","clk":"5348124696","pt":1646214375420,"mc":[{"id":"1.195453754","rc":[{"atb":[[2.8,55.56],[2.92,0]],"id":522747},{"atl":[[1000,0]],"id":3805763},{"atb":[[2.8,55.56],[2.92,0]],"id":3805740},{"atl":[[520,0],[530,2]],"id":3805747}],"con":true,"img":false}]}
{"op":"mcm","clk":"5348137382","pt":1646214435531,"mc":[{"id":"1.195453754","rc":[{"atb":[[2.8,0],[2.92,52.08]],"id":522747},{"atb":[[2.8,0],[2.92,52.08]],"id":3805740},{"atl":[[530,0],[520,2]],"id":3805747}],"con":true,"img":false}]}
{"op":"mcm","clk":"5348138414","pt":1646214450994,"mc":[{"id":"1.195453754","rc":[{"atb":[[5.8,0],[6.6,35.67]],"id":522746}],"con":true,"img":false}]}
{"op":"mcm","clk":"5348138476","pt":1646214451771,"mc":[{"id":"1.195453754","rc":[{"atb":[[6.4,2.72],[5.7,3.26]],"id":522746}],"con":true,"img":false}]}
{"op":"mcm","clk":"5348139704","pt":1646214468652,"mc":[{"id":"1.195453754","rc":[{"atb":[[5.8,20.83],[5.3,0]],"id":522748},{"atl":[[530,0],[520,2]],"id":522750}],"con":true,"img":false}]}
{"op":"mcm","clk":"5348143085","pt":1646214513896,"mc":[{"id":"1.195453754","rc":[{"atb":[[13,0],[15.5,6.9]],"id":522755}],"con":true,"img":false}]}
{"op":"mcm","clk":"5348151152","pt":1646214625699,"mc":[{"id":"1.195453754","rc":[{"atl":[[1000,2]],"id":3805763}],"con":true,"img":false}]}
{"op":"mcm","clk":"5348152374","pt":1646214641840,"mc":[{"id":"1.195453754","rc":[{"atb":[[18.5,0],[26,4]],"id":3805785},{"atb":[[26,0]],"id":3805748},{"atl":[[990,2],[1000,0]],"id":522754},{"atl":[[1000,0]],"id":3805763},{"atb":[[4.3,0],[5,25]],"id":522753},{"atb":[[2.92,0],[2.54,64.94]],"id":3805740},{"atl":[[55,2],[120,0]],"id":3805740},{"atl":[[390,2]],"id":3805784},{"atb":[[9,11.55]],"id":522755},{"atl":[[740,2]],"id":522755},{"atb":[[2.72,0],[3.05,48.78]],"id":522746},{"atb":[[5.8,0],[4.2,25.5]],"id":522748},{"atl":[[520,0],[480,2]],"id":522748},{"atb":[[7.2,16.13],[5.9,0]],"id":522750},{"atl":[[1000,2]],"id":3805731},{"atb":[[5,25],[3.9,0]],"id":522752},{"atb":[[5.8,0],[4.6,25.5]],"id":3805762},{"atl":[[530,0],[510,2]],"id":3805762},{"atb":[[6,0],[7.6,12.9]],"id":3805741},{"atl":[[790,2],[990,0]],"id":3805772}],"con":true,"img":false}]}
{"op":"mcm","clk":"5348152383","pt":1646214641941,"mc":[{"id":"1.195453754","rc":[{"atb":[[38,2.32]],"id":3805748},{"atb":[[2.92,0],[3.5,40]],"id":522747},{"atb":[[2.4,0],[2.8,55.56]],"id":522749},{"atb":[[34,3.03],[25,0]],"id":522751},{"atb":[[40,2],[29,0]],"id":3805732},{"atl":[[440,2],[480,0]],"id":522753},{"atb":[[40,2],[29,0]],"id":3805777},{"atb":[[9.8,11.36],[6.6,0]],"id":522741},{"atl":[[550,2],[600,0]],"id":522741},{"atl":[[940,2],[1000,0]],"id":522745},{"atb":[[4.8,26.32],[3.85,0]],"id":3805784},{"atl":[[450,0]],"id":3805784},{"atb":[[7.2,16.13],[5.3,0]],"id":3805747},{"atl":[[520,0],[460,2]],"id":3805747},{"atb":[[15.5,0]],"id":522755},{"atl":[[840,0]],"id":522755},{"atb":[[34,3.03],[22,0]],"id":3805799},{"atl":[[980,2],[1000,0]],"id":3805799},{"atb":[[34,3.03],[26,0]],"id":3805731},{"atl":[[570,2],[590,0]],"id":3805741}],"con":true,"img":false}]}
{"op":"mcm","clk":"5348153109","pt":1646214653131,"mc":[{"id":"1.195453754","rc":[{"atl":[[920,2],[960,0]],"id":3805785},{"atl":[[430,2],[440,0]],"id":522753}],"con":true,"img":false}]}
{"op":"mcm","clk":"5348153249","pt":1646214655143,"mc":[{"id":"1.195453754","rc":[{"atb":[[34,9.08],[26,0]],"id":3805785},{"atl":[[820,2],[990,0]],"id":522754},{"atb":[[5,0],[6.2,19.23]],"id":522753},{"atb":[[2.92,52.08],[2.54,0]],"id":3805740},{"atl":[[32,2],[55,0]],"id":3805740},{"atl":[[330,2],[390,0]],"id":3805784},{"atb":[[9,0],[12,9.09]],"id":522755},{"atl":[[630,2],[740,0]],"id":522755},{"atb":[[3.05,0],[3.65,37.74]],"id":522746},{"atb":[[4.2,0]],"id":522748},{"atl":[[480,0]],"id":522748},{"atb":[[7.2,0],[9.8,11.36]],"id":522750},{"atl":[[970,2],[1000,0]],"id":3805731},{"atb":[[6.4,18.52],[5,0]],"id":522752},{"atb":[[4.6,0],[5.8,20.83]],"id":3805762},{"atl":[[450,2],[510,0]],"id":3805762},{"atb":[[10,11.11],[7.6,0]],"id":3805741},{"atl":[[670,2],[790,0]],"id":3805772}],"con":true,"img":false}]}
{"op":"mcm","clk":"5348153254","pt":1646214655244,"mc":[{"id":"1.195453754","rc":[{"atb":[[5.3,23.26]],"id":522748},{"atl":[[430,2]],"id":522748}],"con":true,"img":false}]}
{"op":"mcm","clk":"5348153261","pt":1646214655300,"mc":[{"id":"1.195453754","rc":[{"atl":[[900,2],[940,0]],"id":522745},{"atl":[[930,2],[980,0]],"id":3805799}],"con":true,"img":false}]}
{"op":"mcm","clk":"5348153780","pt":1646214663543,"mc":[{"id":"1.195453754","rc":[{"atl":[[180,2],[220,0]],"id":522746}],"con":true,"img":false}]}
{"op":"mcm","clk":"5348163693","pt":1646214813178,"mc":[{"id":"1.195453754","rc":[{"atl":[[540,2],[550,0]],"id":522741},{"atl":[[900,0]],"id":522745},{"atl":[[910,2],[970,0]],"id":3805731}],"con":true,"img":false}]}
{"op":"mcm","clk":"5348163699","pt":1646214813278,"mc":[{"id":"1.195453754","rc":[{"atl":[[860,2]],"id":522745}],"con":true,"img":false}]}
{"op":"mcm","clk":"5348163916","pt":1646214816884,"mc":[{"id":"1.195453754","rc":[{"atl":[[860,0],[850,2]],"id":522745}],"con":true,"img":false}]}
{"op":"mcm","clk":"5348164393","pt":1646214823426,"mc":[{"id":"1.195453754","rc":[{"atl":[[850,0],[860,2]],"id":522745}],"con":true,"img":false}]}
{"op":"mcm","clk":"5348165202","pt":1646214834942,"mc":[{"id":"1.195453754","rc":[{"atl":[[860,0],[850,2]],"id":522745}],"con":true,"img":false}]}
{"op":"mcm","clk":"5348172435","pt":1646214941967,"mc":[{"id":"1.195453754","rc":[{"atl":[[990,2],[1000,0]],"id":522751},{"atl":[[160,2]],"id":522746},{"atl":[[470,2],[480,0]],"id":522752}],"con":true,"img":false}]}
{"op":"mcm","clk":"5348172442","pt":1646214942070,"mc":[{"id":"1.195453754","rc":[{"atl":[[180,0]],"id":522746}],"con":true,"img":false}]}
{"op":"mcm","clk":"5348173668","pt":1646214962703,"mc":[{"id":"1.195453754","rc":[{"atl":[[990,0],[980,2]],"id":522751}],"con":true,"img":false}]}
{"op":"mcm","clk":"5348177228","pt":1646215017445,"mc":[{"id":"1.195453754","rc":[{"atb":[[34,3.03],[85,0],[22,0]],"id":3805785},{"atb":[[330,0],[230,0],[480,0]],"id":3805748},{"atb":[[34,0],[170,0],[60,0]],"id":522754},{"atb":[[4.3,0],[5.8,0],[3.65,0]],"id":522747},{"atb":[[2.82,0],[2.32,0],[2.52,0]],"id":522749},{"atb":[[80,2.72],[42,0],[210,0]],"id":522751},{"atb":[[600,0],[700,0],[850,0]],"id":3805732},{"atb":[[270,0],[170,0],[420,0]],"id":3805763},{"atb":[[6.8,0],[8.8,0],[14.5,0]],"id":522753},{"atb":[[600,0],[700,0],[850,0]],"id":3805777},{"atb":[[16,0],[11,0],[27,0]],"id":522741},{"atb":[[270,0],[120,0],[60,2.72]],"id":522743},{"atb":[[3.45,0],[2.98,0],[4.4,3.26]],"id":3805740},{"atb":[[600,0],[700,0],[850,0]],"id":7607472},{"atb":[[18,0],[26,0],[55,0]],"id":522745},{"atb":[[6.4,0],[5.2,0],[9.4,0]],"id":3805784},{"atb":[[24,0],[9.8,0],[14.5,0]],"id":3805747},{"atb":[[16,0],[44,0],[22,0]],"id":522755},{"atb":[[4.8,0],[6.6,0],[3.9,0]],"id":522746},{"atb":[[22,0],[13.5,0],[9.4,0]],"id":522748},{"atb":[[95,0],[48,0],[240,0]],"id":3805799},{"atb":[[17,0],[12,0],[29,0]],"id":522750},{"atb":[[140,0],[48,2.72],[29,0]],"id":3805731},{"atb":[[16,2.72],[7.4,0],[9.4,0]],"id":522752},{"atb":[[22,0],[13.5,0],[9.4,0]],"id":3805762},{"atb":[[320,0],[170,0],[85,0]],"id":522742},{"atb":[[32,0],[18,0],[13,0]],"id":3805741},{"atb":[[34,0],[85,0],[22,0]],"id":3805772}],"con":true,"img":false}]}
{"op":"mcm","clk":"5348177463","pt":1646215021013,"mc":[{"id":"1.195453754","rc":[{"atb":[[4.3,40.36],[2.86,143.22],[3.15,123.9]],"id":522747},{"atl":[[380,0],[240,2]],"id":522747},{"atb":[[2.52,87.62],[2.12,237.84],[1.96,277.49]],"id":522749},{"atb":[[700,0.19],[400,0.67],[500,0.53]],"id":3805732},{"atb":[[16,8.87],[6.4,49.33],[8.4,35.99]],"id":522741},{"atb":[[34,8.07],[22,12.68],[120,1.11]],"id":522743},{"atb":[[3.45,54.36],[2.58,168.6],[2.78,149.65]],"id":3805740},{"atb":[[700,0.19],[400,0.67],[500,0.53]],"id":7607472},{"atb":[[9.2,32.48],[26,5.32],[13,22.19]],"id":522745},{"atb":[[4.8,35.05],[3.4,110.99],[2.96,135.91]],"id":522746},{"atb":[[7.4,41.62],[13.5,10.65],[5.7,56.67]],"id":522748},{"atb":[[17,8.32],[6.8,45.93],[8.8,34.15]],"id":522750},{"atb":[[34,0],[19.5,14.39],[21,5],[48,5.55],[14.5,19.73]],"id":3805731},{"atb":[[170,0.79],[44,6.19],[27,10.24]],"id":522742},{"atb":[[7.2,42.96],[18,7.83],[9.2,32.48]],"id":3805741}],"con":true,"img":false}]}
{"op":"mcm","clk":"5348177471","pt":1646215021125,"mc":[{"id":"1.195453754","rc":[{"atb":[[16,17.76],[34,7.06],[11,26.63]],"id":3805785},{"atb":[[65,7.43],[130,2.06],[330,0.4]],"id":3805748},{"atb":[[16,17.76],[22,12.68],[60,2.25]],"id":522754},{"atb":[[18,15.66],[80,4.4],[26,10.65]],"id":522751},{"atb":[[270,0.49],[85,3.17],[44,6.19]],"id":3805763},{"atb":[[8.8,17.07],[4.4,78.34],[5.4,60.54]],"id":522753},{"atb":[[700,0.19],[400,0.67],[500,0.53]],"id":3805777},{"atb":[[3.6,102.45],[6.4,24.66],[4.2,83.24]],"id":3805784},{"atb":[[7.8,39.17],[14.5,9.86],[5.9,54.36]],"id":3805747},{"atb":[[22,6.34],[11,26.63],[8.4,35.99]],"id":522755},{"atb":[[19.5,14.39],[95,1.41],[29,9.51]],"id":3805799},{"atb":[[5.7,56.67],[9.4,15.85],[4.7,71.99]],"id":522752},{"atb":[[7.4,41.62],[13.5,10.65],[5.7,56.67]],"id":3805762},{"atb":[[16,17.76],[34,4.03],[11,26.63]],"id":3805772}],"con":true,"img":false}]}
{"op":"mcm","clk":"5348177478","pt":1646215021229,"mc":[{"id":"1.195453754","rc":[{"atb":[[10.5,10.53],[8.8,0]],"id":522745}],"con":true,"img":false}]}
{"op":"mcm","clk":"5348177486","pt":1646215021328,"mc":[{"id":"1.195453754","rc":[{"atb":[[32,3.23],[26,0]],"id":3805763},{"atb":[[5.2,8.08],[4.7,0]],"id":3805772}],"con":true,"img":false}]}
{"op":"mcm","clk":"5348178421","pt":1646215034818,"mc":[{"id":"1.195453754","rc":[{"atb":[[8.6,13.16],[9.8,0]],"id":522741}],"con":true,"img":false}]}
{"op":"mcm","clk":"5348180285","pt":1646215065672,"mc":[{"id":"1.195453754","rc":[{"atb":[[9.6,11.63]],"id":522741}],"con":true,"img":false}]}
{"op":"mcm","clk":"5348180289","pt":1646215065772,"mc":[{"id":"1.195453754","rc":[{"atb":[[8.6,0]],"id":522741}],"con":true,"img":false}]}
{"op":"mcm","clk":"5348183298","pt":1646215118255,"mc":[{"id":"1.195453754","rc":[{"atb":[[32,3.23],[25,0]],"id":522754},{"atl":[[910,0],[930,2]],"id":3805731},{"atb":[[5.8,0],[6.8,17.24]],"id":3805762}],"con":true,"img":false}]}
{"op":"mcm","clk":"5348183309","pt":1646215118463,"mc":[{"id":"1.195453754","rc":[{"atb":[[18,0],[21,0]],"id":3805747},{"atb":[[38,0],[48,2.83]],"id":3805731},{"atb":[[18,0],[15.5,0]],"id":3805762}],"con":true,"img":false}]}
{"op":"mcm","clk":"5348183355","pt":1646215119135,"mc":[{"id":"1.195453754","rc":[{"atb":[[18.5,3.26],[22,2.72]],"id":3805747},{"atb":[[40,3.26],[50,2.72]],"id":3805731},{"atb":[[16.5,3.26],[19,2.72]],"id":3805762}],"con":true,"img":false}]}
{"op":"mcm","clk":"5348183449","pt":1646215120741,"mc":[{"id":"1.195453754","rc":[{"atb":[[6.4,0],[5.7,0]],"id":522747}],"con":true,"img":false}]}
{"op":"mcm","clk":"5348183455","pt":1646215120844,"mc":[{"id":"1.195453754","rc":[{"atl":[[930,0]],"id":3805731}],"con":true,"img":false}]}
{"op":"mcm","clk":"5348183510","pt":1646215121569,"mc":[{"id":"1.195453754","rc":[{"atb":[[5.8,3.26],[6.6,2.72]],"id":522747}],"con":true,"img":false}]}
{"op":"mcm","clk":"5348183641","pt":1646215123889,"mc":[{"id":"1.195453754","rc":[{"atb":[[5.8,20.83],[5.3,0]],"id":522748}],"con":true,"img":false}]}
{"op":"mcm","clk":"5348184054","pt":1646215129859,"mc":[{"id":"1.195453754","rc":[{"atl":[[1000,2]],"id":3805731}],"con":true,"img":false}]}
{"op":"mcm","clk":"5348184411","pt":1646215135068,"mc":[{"id":"1.195453754","rc":[{"atb":[[130,0],[65,3.26],[330,0]],"id":3805748},{"atb":[[16,0],[22,0],[60,0]],"id":522754},{"atb":[[4.3,0],[2.86,0],[3.15,0]],"id":522747},{"atb":[[2.52,0],[2.12,0],[1.96,0]],"id":522749},{"atb":[[18,0],[80,2.72],[26,0]],"id":522751},{"atb":[[700,0],[400,0],[500,0]],"id":3805732},{"atb":[[8.8,0],[4.4,0],[5.4,0]],"id":522753},{"atb":[[16,0],[6.4,0],[8.4,0]],"id":522741},{"atb":[[34,0],[22,0],[120,0]],"id":522743},{"atb":[[3.45,0],[2.58,0],[2.78,0]],"id":3805740},{"atb":[[9.2,0],[26,0],[13,0]],"id":522745},{"atb":[[7.8,0],[14.5,0],[5.9,0]],"id":3805747},{"atb":[[22,0],[11,0],[8.4,0]],"id":522755},{"atb":[[4.8,0],[3.4,0],[2.96,0]],"id":522746},{"atb":[[7.4,0],[13.5,0],[5.7,0]],"id":522748},{"atb":[[17,0],[6.8,0],[8.8,0]],"id":522750},{"atb":[[19.5,0],[48,0],[14.5,0]],"id":3805731},{"atb":[[5.7,0],[9.4,0],[4.7,0]],"id":522752},{"atb":[[170,0],[44,0],[27,0]],"id":522742},{"atb":[[7.2,0],[18,0],[9.2,0]],"id":3805741}],"con":true,"img":false}]}
{"op":"mcm","clk":"5348184416","pt":1646215135175,"mc":[{"id":"1.195453754","rc":[{"atb":[[16,0],[34,3.03],[11,0]],"id":3805785},{"atb":[[270,0],[85,0],[44,0]],"id":3805763},{"atb":[[700,0],[400,0],[500,0]],"id":3805777},{"atb":[[700,0],[400,0],[500,0]],"id":7607472},{"atb":[[3.6,0],[6.4,0],[4.2,0]],"id":3805784},{"atb":[[19.5,0],[95,0],[29,0]],"id":3805799},{"atb":[[7.4,0],[13.5,0],[5.7,0]],"id":3805762},{"atb":[[16,0],[34,0],[11,0]],"id":3805772}],"con":true,"img":false}]}
{"op":"mcm","clk":"5348184554","pt":1646215137694,"mc":[{"id":"1.195453754","rc":[{"atb":[[190,0],[240,0]],"id":3805732},{"atb":[[16.5,0],[19,0]],"id":522741},{"atb":[[44,0],[60,0]],"id":522743},{"atb":[[150,0],[200,0]],"id":7607472},{"atb":[[70,0],[48,0]],"id":522742}],"con":true,"img":false}]}
{"op":"mcm","clk":"5348184566","pt":1646215137900,"mc":[{"id":"1.195453754","rc":[{"atb":[[9.6,0],[9.4,11.9]],"id":522741},{"atb":[[25,4.17],[26,0]],"id":522742}],"con":true,"img":false}]}
{"op":"mcm","clk":"5348184598","pt":1646215138371,"mc":[{"id":"1.195453754","rc":[{"atb":[[200,3.26],[250,2.72]],"id":3805732},{"atb":[[18,3.26],[21,2.72]],"id":522741},{"atb":[[65,2.72],[46,3.26]],"id":522743},{"atb":[[170,3.26],[220,2.72]],"id":7607472},{"atb":[[75,2.72],[50,3.26]],"id":522742}],"con":true,"img":false}]}
{"op":"mcm","clk":"5348184685","pt":1646215139866,"mc":[{"id":"1.195453754","rc":[{"atb":[[18,0],[21,0]],"id":522748}],"con":true,"img":false}]}
{"op":"mcm","clk":"5348184751","pt":1646215140901,"mc":[{"id":"1.195453754","rc":[{"atb":[[17.5,3.26],[20,2.72]],"id":522748}],"con":true,"img":false}]}
{"op":"mcm","clk":"5348185074","pt":1646215145843,"mc":[{"id":"1.195453754","rc":[{"atl":[[70,0],[55,2]],"id":522749}],"con":true,"img":false}]}
{"op":"mcm","clk":"5348185080","pt":1646215145897,"mc":[{"id":"1.195453754","rc":[{"atb":[[9.8,30.27],[29,4.75],[14.5,19.73]],"id":3805785},{"atb":[[150,1.78],[75,3.6],[350,0.38]],"id":3805748},{"atb":[[70,6.58],[38,7.19],[240,0.55]],"id":522754},{"atb":[[3.1,126.85],[2.84,144.77],[4.2,41.62]],"id":522747},{"atb":[[1.99,269.08],[1.89,299.31],[2.38,96.51]],"id":522749},{"atb":[[150,1.78],[75,3.6],[350,0.38]],"id":522751},{"atb":[[700,0.19],[400,0.67],[500,0.53]],"id":3805732},{"atb":[[70,3.85],[38,7.19],[240,0.55]],"id":3805763},{"atb":[[3.95,90.29],[4.9,68.3],[7.8,19.58]],"id":522753},{"atb":[[700,0.19],[400,0.67],[500,0.53]],"id":3805777},{"atb":[[16,8.87],[6.4,49.33],[8.4,35.99]],"id":522741},{"atb":[[20,14.02],[100,1.34],[30,9.18]],"id":522743},{"atb":[[2.88,141.69],[3.7,49.33],[2.68,158.56]],"id":3805740},{"atb":[[700,0.19],[400,0.67],[500,0.53]],"id":7607472},{"atb":[[24,5.79],[12,24.21],[8.8,34.15]],"id":522745},{"atb":[[3.6,102.45],[6.4,24.66],[4.2,83.24]],"id":3805784},{"atb":[[6.2,51.22],[8.2,36.99],[15.5,9.18]],"id":3805747},{"atb":[[9.8,30.27],[29,4.75],[14.5,19.73]],"id":522755},{"atb":[[5,33.29],[3,133.19],[3.5,106.55]],"id":522746},{"atb":[[7.2,42.96],[18,7.83],[9.2,32.48]],"id":522748},{"atb":[[140,0.95],[38,7.19],[24,11.58]],"id":3805799},{"atb":[[17,8.32],[6.8,45.93],[8.8,34.15]],"id":522750},{"atb":[[65,2.08],[16.5,17.18],[23,12.1]],"id":3805731},{"atb":[[8.8,17.07],[4.4,78.34],[5.4,60.54]],"id":522752},{"atb":[[5.8,55.49],[7.6,40.36],[14,10.24]],"id":3805762},{"atb":[[180,0.74],[46,5.91],[28,9.86]],"id":522742},{"atb":[[7.2,42.96],[18,7.83],[9.2,32.48]],"id":3805741},{"atb":[[140,0.95],[38,7.19],[24,11.58]],"id":3805772}],"con":true,"img":false}]}
{"op":"mcm","clk":"5348185098","pt":1646215146104,"mc":[{"id":"1.195453754","rc":[{"atb":[[21,0],[29,3.57]],"id":522743}],"con":true,"img":false}]}
{"op":"mcm","clk":"5348187964","pt":1646215189244,"mc":[{"id":"1.195453754","rc":[{"atl":[[1000,0]],"id":3805731}],"con":true,"img":false}]}
{"op":"mcm","clk":"5348187981","pt":1646215189757,"mc":[{"id":"1.195453754","rc":[{"atb":[[5.8,0],[6.6,0]],"id":522747}],"con":true,"img":false}]}
{"op":"mcm","clk":"5348188006","pt":1646215190487,"mc":[{"id":"1.195453754","rc":[{"atb":[[5.6,3.26],[6.2,2.72]],"id":522747}],"con":true,"img":false}]}
{"op":"mcm","clk":"5348188217","pt":1646215193801,"mc":[{"id":"1.195453754","rc":[{"atb":[[9.8,0],[29,0],[14.5,0]],"id":3805785},{"atb":[[150,0],[75,0],[350,0]],"id":3805748},{"atb":[[70,2.72],[38,0],[240,0]],"id":522754},{"atb":[[3.1,0],[2.84,0],[4.2,0]],"id":522747},{"atb":[[1.99,0],[1.89,0],[2.38,0]],"id":522749},{"atb":[[150,0],[75,0],[350,0]],"id":522751},{"atb":[[700,0],[400,0],[500,0]],"id":3805732},{"atb":[[70,0],[38,0],[240,0]],"id":3805763},{"atb":[[3.95,0],[4.9,0],[7.8,0]],"id":522753},{"atb":[[700,0],[400,0],[500,0]],"id":3805777},{"atb":[[16,0],[6.4,0],[8.4,0]],"id":522741},{"atb":[[20,0],[100,0],[30,0]],"id":522743},{"atb":[[2.88,0],[3.7,0],[2.68,0]],"id":3805740},{"atb":[[700,0],[400,0],[500,0]],"id":7607472},{"atb":[[24,0],[12,0],[8.8,0]],"id":522745},{"atb":[[3.6,0],[6.4,0],[4.2,0]],"id":3805784},{"atb":[[6.2,0],[8.2,0],[15.5,0]],"id":3805747},{"atb":[[9.8,0],[29,0],[14.5,0]],"id":522755},{"atb":[[5,0],[3,0],[3.5,0]],"id":522746},{"atb":[[7.2,0],[18,0],[9.2,0]],"id":522748},{"atb":[[140,0],[38,0],[24,0]],"id":3805799},{"atb":[[17,0],[6.8,0],[8.8,0]],"id":522750},{"atb":[[65,0],[16.5,0],[23,0]],"id":3805731},{"atb":[[8.8,0],[4.4,0],[5.4,0]],"id":522752},{"atb":[[5.8,0],[7.6,0],[14,0]],"id":3805762},{"atb":[[180,0],[46,0],[28,0]],"id":522742},{"atb":[[7.2,0],[18,0],[9.2,0]],"id":3805741},{"atb":[[140,0],[38,0],[24,0]],"id":3805772}],"con":true,"img":false}]}
{"op":"mcm","clk":"5348188247","pt":1646215194265,"mc":[{"id":"1.195453754","rc":[{"atl":[[1000,2]],"id":3805731}],"con":true,"img":false}]}
{"op":"mcm","clk":"5348189264","pt":1646215205293,"mc":[{"id":"1.195453754","rc":[{"atb":[[16.5,17.18],[36,7.07],[11.5,25.36]],"id":3805785},{"atb":[[420,0.31],[220,1.21],[120,2.23]],"id":3805748},{"atb":[[150,0.89],[40,6.82],[25,11.1]],"id":522754},{"atb":[[4,44.4],[2.8,147.99],[3,133.19]],"id":522747},{"atb":[[1.92,289.55],[2.04,256.14],[2.44,92.49]],"id":522749},{"atb":[[75,3.6],[40,6.82],[250,0.53]],"id":522751},{"atb":[[700,0.19],[400,0.67],[500,0.53]],"id":3805732},{"atb":[[290,0.46],[95,2.83],[48,5.66]],"id":3805763},{"atb":[[5.1,64.97],[8.2,18.49],[4.1,85.93]],"id":522753},{"atb":[[700,0.19],[400,0.67],[500,0.53]],"id":3805777},{"atb":[[17,8.32],[6.8,45.93],[8.8,34.15]],"id":522741},{"atb":[[150,0.89],[40,6.82],[25,11.1]],"id":522743},{"atb":[[2.86,143.22],[2.66,160.47],[3.65,50.26]],"id":3805740},{"atb":[[700,0.19],[400,0.67],[500,0.53]],"id":7607472},{"atb":[[9.6,30.97],[28,8.2],[14,20.49]],"id":522745},{"atb":[[4.3,80.72],[6.6,23.78],[3.65,100.52]],"id":3805784},{"atb":[[6.2,51.22],[8.2,36.99],[15.5,9.18]],"id":3805747},{"atb":[[9.6,30.97],[28,4.93],[14,20.49]],"id":522755},{"atb":[[4.8,35.05],[3.4,110.99],[2.96,135.91]],"id":522746},{"atb":[[17,8.32],[6.8,45.93],[8.8,34.15]],"id":522748},{"atb":[[180,0.74],[46,9.18],[28,9.86]],"id":3805799},{"atb":[[16.5,8.59],[8.6,35.05],[6.6,47.57]],"id":522750},{"atb":[[18.5,15.22],[85,1.58],[27,10.24]],"id":3805731},{"atb":[[9,16.64],[4.5,76.11],[5.5,59.19]],"id":522752},{"atb":[[7.4,41.62],[13.5,10.65],[5.7,56.67]],"id":3805762},{"atb":[[75,6.32],[40,6.82],[250,0.53]],"id":522742},{"atb":[[9.6,30.97],[19,7.4],[7.6,40.36]],"id":3805741},{"atb":[[18.5,15.22],[85,1.58],[27,10.24]],"id":3805772}],"con":true,"img":false}]}
{"op":"mcm","clk":"5348189297","pt":1646215205710,"mc":[{"id":"1.195453754","rc":[{"atl":[[1000,0]],"id":3805731}],"con":true,"img":false}]}
{"op":"mcm","clk":"5348190387","pt":1646215218701,"mc":[{"id":"1.195453754","rc":[{"atb":[[17.5,0],[20,0]],"id":522748}],"con":true,"img":false}]}
{"op":"mcm","clk":"5348190438","pt":1646215219425,"mc":[{"id":"1.195453754","rc":[{"atb":[[80,0],[55,0]],"id":522751},{"atb":[[4.9,0],[4.4,0]],"id":3805740},{"atb":[[170,0],[220,0]],"id":7607472},{"atb":[[18,3.26]],"id":522748}],"con":true,"img":false}]}
{"op":"mcm","clk":"5348190457","pt":1646215219735,"mc":[{"id":"1.195453754","rc":[{"atb":[[21,2.72]],"id":522748}],"con":true,"img":false}]}
{"op":"mcm","clk":"5348190487","pt":1646215220202,"mc":[{"id":"1.195453754","rc":[{"atb":[[85,2.72],[60,3.26]],"id":522751},{"atb":[[4.8,2.72],[4.3,3.26]],"id":3805740},{"atb":[[180,3.26],[230,2.72]],"id":7607472}],"con":true,"img":false}]}
{"op":"mcm","clk":"5348193630","pt":1646215260878,"mc":[{"id":"1.195453754","rc":[{"atb":[[75,10.61]],"id":522751},{"atl":[[1000,1.22]],"id":522751},{"atl":[[1000,0.15]],"id":3805763},{"atb":[[8.2,27.4]],"id":522753},{"atl":[[450,2.73]],"id":522753},{"atb":[[3.65,59.16]],"id":3805740},{"atl":[[36,8.9]],"id":3805740},{"atb":[[10.5,4.95],[9.4,9.9]],"id":3805784},{"atl":[[18,4.95],[20,9.9]],"id":3805784},{"atb":[[40,6.79],[28,13.83]],"id":522755},{"atl":[[620,0.25],[650,1.88]],"id":522755},{"atb":[[17,17.23]],"id":522748},{"atl":[[450,2.73]],"id":522748},{"atb":[[16.5,17.49]],"id":522750},{"atl":[[540,2.27]],"id":522750},{"atb":[[16,11.63]],"id":522752},{"atl":[[460,0.34]],"id":522752},{"atb":[[42,10.28]],"id":3805772},{"atl":[[690,1.77]],"id":3805772}],"con":true,"img":false}]}
{"op":"mcm","clk":"5348193637","pt":1646215260984,"mc":[{"id":"1.195453754","rc":[{"atb":[[34,11.57],[80,9.9],[48,3.37],[100,4.95]],"id":3805785},{"atl":[[220,4.95],[910,0.17],[940,1.3]],"id":3805785},{"atb":[[160,4.95],[120,15.77]],"id":3805748},{"atb":[[75,9.9],[95,4.95],[48,10.28]],"id":522754},{"atl":[[810,0.19],[840,1.45]],"id":522754},{"atb":[[4,53.3],[6.4,4.95],[5.8,9.9]],"id":522747},{"atl":[[260,4.73],[11.5,9.9],[9.8,4.95]],"id":522747},{"atb":[[3.6,11.63]],"id":522749},{"atl":[[50,3.23]],"id":522749},{"atb":[[85,12.63],[110,4.95]],"id":522751},{"atl":[[970,0.16]],"id":522751},{"atb":[[80,10.81],[160,4.95],[120,9.9]],"id":3805763},{"atb":[[14,11.63]],"id":522753},{"atl":[[420,0.37]],"id":522753},{"atb":[[32,4.95],[17,17.23],[27,9.9]],"id":522741},{"atl":[[560,2.19],[75,4.95],[95,9.9]],"id":522741},{"atb":[[160,5.95],[46,11.35],[120,9.9]],"id":522743},{"atl":[[1000,0.15]],"id":522743},{"atb":[[4.8,11.63],[4.6,4.95],[4.2,9.9]],"id":3805740},{"atl":[[7.2,9.9],[6.4,4.95],[30,5.46]],"id":3805740},{"atb":[[38,4.28],[14,36.72]],"id":522745},{"atl":[[840,0.19],[870,1.4]],"id":522745},{"atb":[[6.6,32.68]],"id":3805784},{"atl":[[320,0.49],[350,3.5]],"id":3805784},{"atb":[[18,9.9],[20,4.95],[15.5,18.09]],"id":3805747},{"atl":[[80,9.9],[450,0.35],[60,4.95],[480,2.55]],"id":3805747},{"atb":[[32,9.9],[40,11.74]],"id":522755},{"atl":[[140,4.95]],"id":522755},{"atb":[[4.8,43.95],[6.2,9.9],[7,4.95]],"id":522746},{"atl":[[180,6.83],[13,4.95],[15,9.9]],"id":522746},{"atb":[[13.5,9.9],[15.5,4.95]],"id":522748},{"atl":[[65,9.9],[48,4.95]],"id":522748},{"atb":[[90,9.9],[46,16.2],[120,4.95]],"id":3805799},{"atl":[[920,0.17],[950,1.28]],"id":3805799},{"atb":[[25,9.33],[26,9.9],[30,4.95]],"id":522750},{"atl":[[80,4.95],[100,9.9],[510,0.31]],"id":522750},{"atb":[[40,11.35]],"id":3805731},{"atb":[[16.5,4.95],[9,25.55],[14.5,9.9]],"id":522752},{"atl":[[36,4.95],[44,9.9],[490,2.5]],"id":522752},{"atb":[[19,11.53],[13.5,19.55]],"id":3805762},{"atl":[[440,0.35],[470,2.61]],"id":3805762},{"atb":[[160,4.95],[50,12.99],[120,9.9]],"id":522742},{"atl":[[1000,0.15]],"id":522742},{"atb":[[19,16.3],[25,6.6]],"id":3805741},{"atl":[[560,0.28],[590,2.08]],"id":3805741},{"atb":[[42,20.19],[50,4.95]],"id":3805772},{"atl":[[660,0.23],[230,4.95]],"id":3805772}],"con":true,"img":false}]}
{"op":"mcm","clk":"5348193646","pt":1646215261091,"mc":[{"id":"1.195453754","rc":[{"atl":[[980,0],[1000,3.22]],"id":522751},{"atl":[[430,0],[450,4.73]],"id":522753},{"atb":[[22,7.54]],"id":522741},{"atl":[[530,0.29]],"id":522741},{"atl":[[32,0],[34,3.03]],"id":3805740},{"atl":[[330,0],[42,2.44]],"id":3805784},{"atl":[[630,0],[640,2]],"id":522755},{"atl":[[430,0],[450,4.73]],"id":522748},{"atl":[[520,0],[540,4.27]],"id":522750},{"atl":[[670,0],[690,3.77]],"id":3805772}],"con":true,"img":false}]}
{"op":"mcm","clk":"5348193654","pt":1646215261191,"mc":[{"id":"1.195453754","rc":[{"atl":[[720,2],[920,0]],"id":3805785},{"atl":[[820,0],[830,2]],"id":522754},{"atl":[[27,3.85],[240,0]],"id":522747},{"atl":[[48,2.13],[55,0]],"id":522749},{"atl":[[540,0],[280,2]],"id":522741},{"atl":[[850,0],[860,2]],"id":522745},{"atl":[[110,2],[460,0]],"id":3805747},{"atl":[[160,0],[22,4.76]],"id":522746},{"atl":[[930,0],[940,2]],"id":3805799},{"atl":[[100,2],[470,0]],"id":522752},{"atl":[[450,0],[460,2]],"id":3805762},{"atl":[[570,0],[580,2]],"id":3805741}],"con":true,"img":false}]}
{"op":"mcm","clk":"5348193666","pt":1646215261296,"mc":[{"id":"1.195453754","rc":[{"atl":[[540,2.27],[190,2]],"id":522750}],"con":true,"img":false}]}
{"op":"mcm","clk":"5348193699","pt":1646215261676,"mc":[{"id":"1.195453754","rc":[{"atl":[[1000,0.15]],"id":3805748},{"atb":[[6.2,11.63]],"id":522747},{"atl":[[230,0.69]],"id":522747},{"atb":[[2.8,64.46],[3.45,9.9],[3.65,4.95]],"id":522749},{"atl":[[65,8.9],[6.2,4.95],[7,9.9]],"id":522749},{"atb":[[12.5,9.9],[14.5,4.95]],"id":522753},{"atl":[[34,9.9],[28,4.95]],"id":522753},{"atb":[[85,9.9],[110,4.95]],"id":522745},{"atl":[[230,4.95]],"id":522745},{"atb":[[6.4,11.63]],"id":522746},{"atl":[[150,1.06]],"id":522746},{"atl":[[65,0],[70,9.9],[48,0],[50,4.95],[420,0.37]],"id":522748},{"atb":[[90,11.69],[120,4.95]],"id":3805731},{"atl":[[1000,0.15]],"id":3805731},{"atb":[[16,4.95],[14,9.9]],"id":3805762},{"atl":[[32,4.95],[40,9.9]],"id":3805762},{"atb":[[32,4.95],[27,9.9]],"id":3805741},{"atl":[[75,4.95],[95,9.9]],"id":3805741},{"atl":[[230,0]],"id":3805772}],"con":true,"img":false}]}
{"op":"mcm","clk":"5348193704","pt":1646215261773,"mc":[{"id":"1.195453754","rc":[{"atl":[[240,4.95]],"id":3805772}],"con":true,"img":false}]}
{"op":"mcm","clk":"5348193797","pt":1646215263071,"mc":[{"id":"1.195453754","rc":[{"atl":[[80,0],[100,0]],"id":522750}],"con":true,"img":false}]}
{"op":"mcm","clk":"5348193809","pt":1646215263283,"mc":[{"id":"1.195453754","rc":[{"atl":[[85,4.95],[110,9.9]],"id":522750}],"con":true,"img":false}]}
{"op":"mcm","clk":"5348194021","pt":1646215266391,"mc":[{"id":"1.195453754","rc":[{"atl":[[720,0],[910,2.17]],"id":3805785},{"atl":[[940,0],[950,3.28]],"id":3805799}],"con":true,"img":false}]}
{"op":"mcm","clk":"5348194038","pt":1646215266599,"mc":[{"id":"1.195453754","rc":[{"atb":[[34,8.54],[46,4.94]],"id":3805785},{"atb":[[38,0],[55,2]],"id":3805748},{"atb":[[32,0],[44,2.33]],"id":522754},{"atb":[[3.5,0],[4.2,31.25]],"id":522747},{"atb":[[2.8,8.9],[3.15,46.51]],"id":522749},{"atb":[[34,0],[48,2.13]],"id":522751},{"atb":[[40,0],[60,2]],"id":3805732},{"atb":[[8,14.29],[6.2,0]],"id":522753},{"atb":[[13,8.33],[9.4,0]],"id":522741},{"atb":[[2.92,0],[3.55,39.22]],"id":3805740},{"atb":[[4.8,0],[6.2,19.23]],"id":3805784},{"atb":[[7.2,0],[10,11.11]],"id":3805747},{"atb":[[18,5.88],[12,0]],"id":522755},{"atb":[[4.3,30.3],[3.65,0]],"id":522746},{"atb":[[8.6,13.16],[5.8,0]],"id":522748},{"atb":[[9.8,0],[14,7.69]],"id":522750},{"atl":[[1000,2.15]],"id":3805731},{"atb":[[6.4,0],[7.8,14.71]],"id":522752},{"atb":[[9.2,12.2]],"id":3805762},{"atb":[[10,0],[15.5,6.9]],"id":3805741}],"con":true,"img":false}]}
{"op":"mcm","clk":"5348194045","pt":1646215266713,"mc":[{"id":"1.195453754","rc":[{"atb":[[6.8,0]],"id":3805762}],"con":true,"img":false}]}
{"op":"mcm","clk":"5348194058","pt":1646215266800,"mc":[{"id":"1.195453754","rc":[{"atl":[[830,0],[840,3.45]],"id":522754}],"con":true,"img":false}]}
{"op":"mcm","clk":"5348194717","pt":1646215275078,"mc":[{"id":"1.195453754","rc":[{"atb":[[11.5,14.94]],"id":3805784}],"con":true,"img":false}]}
{"op":"mcm","clk":"5348194833","pt":1646215276586,"mc":[{"id":"1.195453754","rc":[{"atb":[[75,3.6],[85,22.2]],"id":522751},{"atl":[[990,1.28],[1000,2]],"id":522751},{"atb":[[8.2,18.49],[12.5,31.99]],"id":522753},{"atl":[[420,3.4],[450,2]],"id":522753},{"atb":[[4.3,18.75],[3.65,50.26]],"id":3805740},{"atl":[[36,0],[30,20.95]],"id":3805740},{"atb":[[28,4.93],[30,15.48]],"id":522755},{"atl":[[140,6.09],[640,3.98],[650,0]],"id":522755},{"atl":[[420,3.4],[450,2]],"id":522748},{"atb":[[16.5,8.59],[25,30.55]],"id":522750},{"atl":[[540,0],[190,8.71]],"id":522750},{"atb":[[16.5,15.18]],"id":522752},{"atl":[[36,9.48]],"id":522752},{"atb":[[42,13.17],[50,14.61]],"id":3805772}],"con":true,"img":false}]}
{"op":"mcm","clk":"5348194840","pt":1646215276688,"mc":[{"id":"1.195453754","rc":[{"atb":[[34,0],[48,15.73],[100,6.55]],"id":3805785},{"atl":[[220,5.67]],"id":3805785},{"atb":[[160,7.24]],"id":3805748},{"atb":[[75,20.19],[48,3.26]],"id":522754},{"atl":[[830,1.53],[840,2]],"id":522754},{"atb":[[4,44.4],[5.8,31.99]],"id":522747},{"atl":[[260,0],[27,25.93]],"id":522747},{"atb":[[3.65,27.04]],"id":522749},{"atl":[[6.2,27.04]],"id":522749},{"atb":[[80,2.72],[120,17.94]],"id":3805763},{"atb":[[14.5,16.69]],"id":522753},{"atl":[[28,10.82]],"id":522753},{"atb":[[17,8.32],[22,26.12]],"id":522741},{"atl":[[280,6.55],[560,0]],"id":522741},{"atb":[[46,3.26],[120,20.07]],"id":522743},{"atl":[[6.4,20.44]],"id":3805740},{"atb":[[38,18],[110,6.4],[14,20.49]],"id":522745},{"atl":[[860,3.47],[870,0],[230,5.64]],"id":522745},{"atb":[[9.6,17.98],[6.6,23.78]],"id":3805784},{"atl":[[18,14.27],[42,17.15],[350,0]],"id":3805784},{"atb":[[18.5,15.48],[15.5,9.18]],"id":3805747},{"atl":[[110,13.6],[60,7.64],[480,0]],"id":3805747},{"atb":[[4.8,35.05],[6.2,31.99]],"id":522746},{"atl":[[22,26.84],[180,0]],"id":522746},{"atb":[[90,19.69],[46,9.18]],"id":3805799},{"atl":[[950,2],[940,1.35]],"id":3805799},{"atb":[[30,10.42]],"id":522750},{"atl":[[85,6.83]],"id":522750},{"atb":[[40,3.26]],"id":3805731},{"atb":[[9,16.64],[14.5,31.99]],"id":522752},{"atl":[[100,14.76],[490,0]],"id":522752},{"atb":[[16,19.66],[13.5,10.65]],"id":3805762},{"atl":[[32,10.06],[440,3.25],[470,0]],"id":3805762},{"atb":[[50,3.26],[120,18.05]],"id":522742},{"atb":[[32,10.06],[19,7.4]],"id":3805741},{"atl":[[560,2.55],[75,7.09],[590,0]],"id":3805741},{"atl":[[650,0.24]],"id":3805772}],"con":true,"img":false}]}
{"op":"mcm","clk":"5348194846","pt":1646215276791,"mc":[{"id":"1.195453754","rc":[{"atl":[[10.5,10.53],[48,0]],"id":522749},{"atl":[[450,0]],"id":522753}],"con":true,"img":false}]}
{"op":"mcm","clk":"5348194852","pt":1646215276901,"mc":[{"id":"1.195453754","rc":[{"atl":[[60,2]],"id":522753},{"atb":[[32,10.06]],"id":522741},{"atl":[[75,7.09]],"id":522741},{"atl":[[34,0],[8.8,12.82]],"id":3805740}],"con":true,"img":false}]}
{"op":"mcm","clk":"5348194867","pt":1646215277208,"mc":[{"id":"1.195453754","rc":[{"atl":[[660,2.16],[690,2]],"id":3805772}],"con":true,"img":false}]}
{"op":"mcm","clk":"5348194876","pt":1646215277324,"mc":[{"id":"1.195453754","rc":[{"atl":[[9.8,22.97]],"id":522747},{"atl":[[65,0]],"id":522749},{"atl":[[990,0]],"id":522751},{"atl":[[620,0]],"id":522755},{"atb":[[7,31.37]],"id":522746},{"atl":[[13,18.16]],"id":522746},{"atl":[[48,3.37]],"id":522748},{"atb":[[16,2.72]],"id":522752},{"atl":[[460,0]],"id":522752}],"con":true,"img":false}]}
{"op":"mcm","clk":"5348194883","pt":1646215277422,"mc":[{"id":"1.195453754","rc":[{"atb":[[48,12.36]],"id":3805785},{"atl":[[910,2]],"id":3805785},{"atb":[[6.4,34.31]],"id":522747},{"atb":[[2.8,0],[3.6,2.72],[3.45,42.84]],"id":522749},{"atl":[[10.5,43.46],[50,0]],"id":522749},{"atb":[[14,2.72]],"id":522753},{"atl":[[420,3.03],[28,4.95]],"id":522753},{"atb":[[38,13.71]],"id":522745},{"atl":[[840,0]],"id":522745},{"atl":[[320,0]],"id":3805784},{"atl":[[450,0]],"id":3805747},{"atb":[[25,23.95]],"id":522750},{"atl":[[510,0]],"id":522750},{"atb":[[120,6.28]],"id":3805731},{"atl":[[440,2.89]],"id":3805762},{"atb":[[25,0]],"id":3805741},{"atl":[[560,2.27]],"id":3805741},{"atl":[[660,1.92]],"id":3805772}],"con":true,"img":false}]}
{"op":"mcm","clk":"5348194887","pt":1646215277466,"mc":[{"id":"1.195453754","rc":[{"atb":[[120,12.14]],"id":3805748},{"atl":[[65,2],[450,0]],"id":522748},{"atb":[[85,12.15]],"id":3805731},{"atb":[[25,17.18]],"id":3805741}],"con":true,"img":false}]}
{"op":"mcm","clk":"5348194893","pt":1646215277568,"mc":[{"id":"1.195453754","rc":[{"atl":[[30,15.48]],"id":3805740}],"con":true,"img":false}]}
{"op":"mcm","clk":"5348194898","pt":1646215277679,"mc":[{"id":"1.195453754","rc":[{"atb":[[22,18.57]],"id":522741},{"atl":[[530,0]],"id":522741}],"con":true,"img":false}]}
{"op":"mcm","clk":"5348194919","pt":1646215278086,"mc":[{"id":"1.195453754","rc":[{"atl":[[230,0]],"id":522747},{"atl":[[150,0]],"id":522746},{"atl":[[420,3.03]],"id":522748}],"con":true,"img":false}]}
{"op":"mcm","clk":"5348194923","pt":1646215278191,"mc":[{"id":"1.195453754","rc":[{"atb":[[6.2,2.72]],"id":522747},{"atl":[[34,14.71]],"id":522753},{"atb":[[6.4,2.72]],"id":522746},{"atb":[[90,9.9]],"id":3805731}],"con":true,"img":false}]}
{"op":"mcm","clk":"5348195318","pt":1646215284180,"mc":[{"id":"1.195453754","rc":[{"atl":[[940,0]],"id":3805799}],"con":true,"img":false}]}
{"op":"mcm","clk":"5348195323","pt":1646215284284,"mc":[{"id":"1.195453754","rc":[{"atl":[[840,3.53]],"id":522754},{"atl":[[950,3.35]],"id":3805799}],"con":true,"img":false}]}
{"op":"mcm","clk":"5348195331","pt":1646215284384,"mc":[{"id":"1.195453754","rc":[{"atl":[[830,0]],"id":522754}],"con":true,"img":false}]}
{"op":"mcm","clk":"5348195386","pt":1646215285217,"mc":[{"id":"1.195453754","rc":[{"atl":[[840,2]],"id":522754}],"con":true,"img":false}]}
{"op":"mcm","clk":"5348195825","pt":1646215292007,"mc":[{"id":"1.195453754","rc":[{"atl":[[990,1.32]],"id":522751},{"atl":[[420,0],[60,24]],"id":522753},{"atl":[[8.8,49.15],[30,0]],"id":3805740},{"atl":[[65,11.86],[420,0]],"id":522748}],"con":true,"img":false}]}
{"op":"mcm","clk":"5348195831","pt":1646215292106,"mc":[{"id":"1.195453754","rc":[{"atl":[[830,1.58]],"id":522754},{"atl":[[28,10.82]],"id":522753},{"atl":[[860,2],[250,5.27]],"id":522745},{"atl":[[640,2],[160,8.24]],"id":522755},{"atl":[[950,2],[940,1.39]],"id":3805799},{"atl":[[230,0.69]],"id":3805772}],"con":true,"img":false}]}
{"op":"mcm","clk":"5348195844","pt":1646215292312,"mc":[{"id":"1.195453754","rc":[{"atl":[[590,2],[860,0]],"id":522745},{"atl":[[640,0],[230,2]],"id":522755}],"con":true,"img":false}]}
{"op":"mcm","clk":"5348195853","pt":1646215292516,"mc":[{"id":"1.195453754","rc":[{"atl":[[650,2.27]],"id":3805772}],"con":true,"img":false}]}
{"op":"mcm","clk":"5348195860","pt":1646215292622,"mc":[{"id":"1.195453754","rc":[{"atl":[[660,0],[640,2],[690,0]],"id":3805772}],"con":true,"img":false}]}
{"op":"mcm","clk":"5348195877","pt":1646215292929,"mc":[{"id":"1.195453754","rc":[{"atl":[[34,9.9],[28,4.95]],"id":522753},{"atl":[[650,2.02]],"id":3805772}],"con":true,"img":false}]}
{"op":"mcm","clk":"5348195929","pt":1646215293609,"mc":[{"id":"1.195453754","rc":[{"atl":[[34,14.71]],"id":522753}],"con":true,"img":false}]}
{"op":"mcm","clk":"5348196291","pt":1646215299135,"mc":[{"id":"1.195453754","rc":[{"atl":[[260,4.95]],"id":3805799},{"atl":[[270,4.95]],"id":3805731},{"atl":[[36,0],[40,4.95],[44,0],[48,9.9]],"id":522752}],"con":true,"img":false}]}
{"op":"mcm","clk":"5348196297","pt":1646215299332,"mc":[{"id":"1.195453754","rc":[{"atl":[[730,2],[950,0]],"id":3805799},{"atl":[[800,2],[1000,0.15]],"id":3805731},{"atl":[[80,2],[100,12.76]],"id":522752}],"con":true,"img":false}]}
{"op":"mcm","clk":"5348196308","pt":1646215299537,"mc":[{"id":"1.195453754","rc":[{"atl":[[1000,3.32]],"id":522751},{"atl":[[940,0],[950,1.4]],"id":3805799}],"con":true,"img":false}]}
{"op":"mcm","clk":"5348196313","pt":1646215299652,"mc":[{"id":"1.195453754","rc":[{"atl":[[830,0],[840,3.58]],"id":522754},{"atl":[[990,0]],"id":522751},{"atl":[[590,4.26],[250,0]],"id":522745},{"atl":[[160,0],[230,7.82]],"id":522755},{"atl":[[260,0.61]],"id":3805731}],"con":true,"img":false}]}
{"op":"mcm","clk":"5348196323","pt":1646215299846,"mc":[{"id":"1.195453754","rc":[{"atl":[[1000,1.49]],"id":3805731},{"atl":[[80,18.78],[100,0]],"id":522752}],"con":true,"img":false}]}
{"op":"mcm","clk":"5348196332","pt":1646215299954,"mc":[{"id":"1.195453754","rc":[{"atl":[[75,2.14]],"id":522752}],"con":true,"img":false}]}
{"op":"mcm","clk":"5348196345","pt":1646215300104,"mc":[{"id":"1.195453754","rc":[{"atl":[[260,0],[270,4.95]],"id":3805799}],"con":true,"img":false}]}
{"op":"mcm","clk":"5348196354","pt":1646215300314,"mc":[{"id":"1.195453754","rc":[{"atl":[[1000,2]],"id":522751}],"con":true,"img":false}]}
{"op":"mcm","clk":"5348196358","pt":1646215300412,"mc":[{"id":"1.195453754","rc":[{"atl":[[590,2]],"id":522745},{"atl":[[1000,1.33]],"id":3805731}],"con":true,"img":false}]}
{"op":"mcm","clk":"5348196364","pt":1646215300515,"mc":[{"id":"1.195453754","rc":[{"atl":[[840,2]],"id":522754}],"con":true,"img":false}]}
{"op":"mcm","clk":"5348196369","pt":1646215300618,"mc":[{"id":"1.195453754","rc":[{"atl":[[32,5.11],[34,4.95],[40,0],[42,9.9]],"id":3805762}],"con":true,"img":false}]}
{"op":"mcm","clk":"5348196373","pt":1646215300721,"mc":[{"id":"1.195453754","rc":[{"atl":[[70,2],[460,0]],"id":3805762}],"con":true,"img":false}]}
{"op":"mcm","clk":"5348196381","pt":1646215300827,"mc":[{"id":"1.195453754","rc":[{"atl":[[720,0.21]],"id":3805799}],"con":true,"img":false}]}
{"op":"mcm","clk":"5348196398","pt":1646215301133,"mc":[{"id":"1.195453754","rc":[{"atl":[[42,32.23],[440,0]],"id":3805762}],"con":true,"img":false}]}
{"op":"mcm","clk":"5348196423","pt":1646215301649,"mc":[{"id":"1.195453754","rc":[{"atl":[[920,0]],"id":3805799}],"con":true,"img":false}]}
{"op":"mcm","clk":"5348196552","pt":1646215303507,"mc":[{"id":"1.195453754","rc":[{"atb":[[3.35,13.17],[3.55,4.95],[3.65,4.95]],"id":522749},{"atl":[[85,4.95]],"id":522750},{"atl":[[36,4.95],[44,9.9]],"id":3805762}],"con":true,"img":false}]}
{"op":"mcm","clk":"5348196560","pt":1646215303610,"mc":[{"id":"1.195453754","rc":[{"atb":[[3.45,32.93],[3.65,0]],"id":522749},{"atl":[[130,9.9],[85,0],[95,4.95],[110,0]],"id":522750},{"atl":[[32,0],[34,0],[42,22.32]],"id":3805762}],"con":true,"img":false}]}
{"op":"mcm","clk":"5348196566","pt":1646215303713,"mc":[{"id":"1.195453754","rc":[{"atl":[[150,2],[190,6.71]],"id":522750}],"con":true,"img":false}]}
{"op":"mcm","clk":"5348196578","pt":1646215303920,"mc":[{"id":"1.195453754","rc":[{"atb":[[3.45,0],[3.55,27.04]],"id":522749},{"atl":[[42,0]],"id":3805762}],"con":true,"img":false}]}
{"op":"mcm","clk":"5348196600","pt":1646215304228,"mc":[{"id":"1.195453754","rc":[{"atl":[[150,11.02],[190,0]],"id":522750}],"con":true,"img":false}]}
{"op":"mcm","clk":"5348196605","pt":1646215304331,"mc":[{"id":"1.195453754","rc":[{"atb":[[3.55,49.13]],"id":522749},{"atl":[[95,6.63]],"id":522750},{"atl":[[40,4.06]],"id":3805762}],"con":true,"img":false}]}
{"op":"mcm","clk":"5348196633","pt":1646215304853,"mc":[{"id":"1.195453754","rc":[{"atb":[[3.55,27.04]],"id":522749}],"con":true,"img":false}]}
{"op":"mcm","clk":"5348196803","pt":1646215307123,"mc":[{"id":"1.195453754","rc":[{"atl":[[990,1.36]],"id":522751},{"atl":[[250,5.44]],"id":522745},{"atl":[[950,0]],"id":3805799}],"con":true,"img":false}]}
{"op":"mcm","clk":"5348196809","pt":1646215307224,"mc":[{"id":"1.195453754","rc":[{"atl":[[830,1.63]],"id":522754},{"atl":[[28,10.82]],"id":522753},{"atl":[[160,8.51],[230,2]],"id":522755},{"atl":[[730,3.85]],"id":3805799}],"con":true,"img":false}]}
{"op":"mcm","clk":"5348196838","pt":1646215307640,"mc":[{"id":"1.195453754","rc":[{"atl":[[640,4.12],[650,0]],"id":3805772}],"con":true,"img":false}]}
{"op":"mcm","clk":"5348196870","pt":1646215308006,"mc":[{"id":"1.195453754","rc":[{"atl":[[34,9.9],[28,4.95]],"id":522753}],"con":true,"img":false}]}
{"op":"mcm","clk":"5348196921","pt":1646215308932,"mc":[{"id":"1.195453754","rc":[{"atl":[[34,14.71]],"id":522753}],"con":true,"img":false}]}
{"op":"mcm","clk":"5348197325","pt":1646215314360,"mc":[{"id":"1.195453754","rc":[{"atl":[[590,4.33],[250,0]],"id":522745}],"con":true,"img":false}]}
{"op":"mcm","clk":"5348197334","pt":1646215314411,"mc":[{"id":"1.195453754","rc":[{"atl":[[830,0],[840,3.64]],"id":522754},{"atl":[[990,0],[1000,3.37]],"id":522751}],"con":true,"img":false}]}
{"op":"mcm","clk":"5348197341","pt":1646215314515,"mc":[{"id":"1.195453754","rc":[{"atl":[[160,0],[230,8.01]],"id":522755}],"con":true,"img":false}]}
{"op":"mcm","clk":"5348197358","pt":1646215314722,"mc":[{"id":"1.195453754","rc":[{"atl":[[800,3.72],[1000,0]],"id":3805731},{"atl":[[75,20.6],[80,2]],"id":522752}],"con":true,"img":false}]}
{"op":"mcm","clk":"5348197365","pt":1646215314825,"mc":[{"id":"1.195453754","rc":[{"atl":[[38,4.28]],"id":522752}],"con":true,"img":false}]}
{"op":"mcm","clk":"5348197383","pt":1646215315135,"mc":[{"id":"1.195453754","rc":[{"atl":[[590,2]],"id":522745}],"con":true,"img":false}]}
{"op":"mcm","clk":"5348197406","pt":1646215315547,"mc":[{"id":"1.195453754","rc":[{"atl":[[75,18.45]],"id":522752}],"con":true,"img":false}]}
{"op":"mcm","clk":"5348197437","pt":1646215316114,"mc":[{"id":"1.195453754","rc":[{"atl":[[44,31.99]],"id":3805762}],"con":true,"img":false}]}
{"op":"mcm","clk":"5348197617","pt":1646215318956,"mc":[{"id":"1.195453754","rc":[{"atb":[[3.35,72.95]],"id":522749}],"con":true,"img":false}]}
{"op":"mcm","clk":"5348197634","pt":1646215319264,"mc":[{"id":"1.195453754","rc":[{"atl":[[36,9.48]],"id":3805762}],"con":true,"img":false}]}
{"op":"mcm","clk":"5348197687","pt":1646215320037,"mc":[{"id":"1.195453754","rc":[{"atl":[[40,0]],"id":3805762}],"con":true,"img":false}]}
{"op":"mcm","clk":"5348197746","pt":1646215320877,"mc":[{"id":"1.195453754","rc":[{"atl":[[130,4.95],[140,1.13]],"id":522755},{"atl":[[70,0],[44,4.95],[50,0],[55,9.9]],"id":522748},{"atl":[[270,0],[260,4.95]],"id":3805799},{"atl":[[130,0],[90,4.95],[95,1.68],[120,9.9]],"id":522750},{"atl":[[260,5.56],[270,0]],"id":3805731},{"atb":[[16.5,10.22],[17,4.95],[14.5,22.08],[15,9.9]],"id":522752},{"atb":[[16.5,8.22],[16,14.71],[14,0],[14.5,9.9]],"id":3805762},{"atl":[[210,4.95],[240,0]],"id":3805772}],"con":true,"img":false}]}
{"op":"mcm","clk":"5348197761","pt":1646215321039,"mc":[{"id":"1.195453754","rc":[{"atl":[[70,4.95],[75,2.14],[90,9.9],[95,0]],"id":522741},{"atl":[[300,2],[640,2.12]],"id":3805772}],"con":true,"img":false}]}
{"op":"mcm","clk":"5348197771","pt":1646215321139,"mc":[{"id":"1.195453754","rc":[{"atl":[[280,4.55],[210,2]],"id":522741}],"con":true,"img":false}]}
{"op":"mcm","clk":"5348197790","pt":1646215321349,"mc":[{"id":"1.195453754","rc":[{"atl":[[130,6.18]],"id":522755},{"atl":[[65,2],[44,8.64],[55,22.27]],"id":522748},{"atl":[[150,2],[90,6.73],[120,21.59]],"id":522750},{"atl":[[800,2]],"id":3805731},{"atb":[[16,17.43],[17.5,9.6],[14.5,0]],"id":522752},{"atl":[[210,5.71]],"id":3805772}],"con":true,"img":false}]}
{"op":"mcm","clk":"5348197805","pt":1646215321555,"mc":[{"id":"1.195453754","rc":[{"atl":[[65,2.49],[280,0],[90,25.5]],"id":522741},{"atl":[[40,0],[48,0]],"id":522752}],"con":true,"img":false}]}
{"op":"mcm","clk":"5348197812","pt":1646215321659,"mc":[{"id":"1.195453754","rc":[{"atl":[[36,4.95],[44,9.9]],"id":522752}],"con":true,"img":false}]}
{"op":"mcm","clk":"5348197835","pt":1646215321972,"mc":[{"id":"1.195453754","rc":[{"atl":[[830,1.68],[840,2]],"id":522754},{"atl":[[990,1.41],[1000,2]],"id":522751},{"atl":[[250,5.61]],"id":522745}],"con":true,"img":false}]}
{"op":"mcm","clk":"5348197842","pt":1646215322074,"mc":[{"id":"1.195453754","rc":[{"atl":[[28,10.82]],"id":522753},{"atl":[[140,0]],"id":522755},{"atl":[[48,0]],"id":522748},{"atl":[[95,0]],"id":522750},{"atb":[[16.5,0]],"id":522752},{"atl":[[75,0],[80,19.56]],"id":522752}],"con":true,"img":false}]}
{"op":"mcm","clk":"5348197858","pt":1646215322229,"mc":[{"id":"1.195453754","rc":[{"atl":[[230,0]],"id":3805772}],"con":true,"img":false}]}
{"op":"mcm","clk":"5348197867","pt":1646215322331,"mc":[{"id":"1.195453754","rc":[{"atl":[[75,0],[90,9.9]],"id":522741}],"con":true,"img":false}]}
{"op":"mcm","clk":"5348197878","pt":1646215322537,"mc":[{"id":"1.195453754","rc":[{"atl":[[150,9.37],[230,2]],"id":522755},{"atl":[[300,6.68],[640,0],[210,0],[220,4.95]],"id":3805772}],"con":true,"img":false}]}
{"op":"mcm","clk":"5348197885","pt":1646215322644,"mc":[{"id":"1.195453754","rc":[{"atb":[[3.6,68.65],[3.35,63.04],[3.4,9.9],[3.55,22.08]],"id":522749}],"con":true,"img":false}]}
{"op":"mcm","clk":"5348197903","pt":1646215322849,"mc":[{"id":"1.195453754","rc":[{"atl":[[830,0]],"id":522754},{"atl":[[990,0]],"id":522751},{"atl":[[34,9.9],[28,4.95]],"id":522753},{"atl":[[80,2]],"id":522752}],"con":true,"img":false}]}
{"op":"mcm","clk":"5348197919","pt":1646215323060,"mc":[{"id":"1.195453754","rc":[{"atl":[[36,4.52],[44,22.08]],"id":3805762}],"con":true,"img":false}]}
{"op":"mcm","clk":"5348197928","pt":1646215323163,"mc":[{"id":"1.195453754","rc":[{"atl":[[34,4.95],[42,9.9]],"id":3805762}],"con":true,"img":false}]}
{"op":"mcm","clk":"5348197939","pt":1646215323373,"mc":[{"id":"1.195453754","rc":[{"atl":[[220,5.67]],"id":3805772}],"con":true,"img":false}]}
{"op":"mcm","clk":"5348197948","pt":1646215323423,"mc":[{"id":"1.195453754","rc":[{"atb":[[3.55,0]],"id":522749},{"atl":[[44,0]],"id":3805762}],"con":true,"img":false}]}
{"op":"mcm","clk":"5348197957","pt":1646215323580,"mc":[{"id":"1.195453754","rc":[{"atl":[[70,22.12]],"id":3805762}],"con":true,"img":false}]}
{"op":"mcm","clk":"5348197963","pt":1646215323630,"mc":[{"id":"1.195453754","rc":[{"atl":[[34,14.71]],"id":522753}],"con":true,"img":false}]}
{"op":"mcm","clk":"5348198023","pt":1646215324562,"mc":[{"id":"1.195453754","rc":[{"atl":[[260,0],[270,4.95]],"id":3805799}],"con":true,"img":false}]}
{"op":"mcm","clk":"5348198061","pt":1646215325231,"mc":[{"id":"1.195453754","rc":[{"atl":[[710,0.22]],"id":3805799}],"con":true,"img":false}]}
{"op":"mcm","clk":"5348198111","pt":1646215325958,"mc":[{"id":"1.195453754","rc":[{"atl":[[720,2.17],[730,2]],"id":3805799}],"con":true,"img":false}]}
{"op":"mcm","clk":"5348198132","pt":1646215326267,"mc":[{"id":"1.195453754","rc":[{"atl":[[720,1.95]],"id":3805799}],"con":true,"img":false}]}
{"op":"mcm","clk":"5348198266","pt":1646215328062,"mc":[{"id":"1.195453754","rc":[{"atb":[[22,10.27]],"id":3805747}],"con":true,"img":false}]}
{"op":"mcm","clk":"5348198288","pt":1646215328481,"mc":[{"id":"1.195453754","rc":[{"atl":[[65,19.7],[55,9.9]],"id":522748},{"atl":[[150,11.48],[120,9.9]],"id":522750}],"con":true,"img":false}]}
{"op":"mcm","clk":"5348198329","pt":1646215329051,"mc":[{"id":"1.195453754","rc":[{"atl":[[830,1.7]],"id":522754},{"atl":[[990,1.42]],"id":522751},{"atl":[[590,4.4],[250,0]],"id":522745}],"con":true,"img":false}]}
{"op":"mcm","clk":"5348198365","pt":1646215329468,"mc":[{"id":"1.195453754","rc":[{"atl":[[36,9.48],[44,31.54]],"id":522752}],"con":true,"img":false}]}
{"op":"mcm","clk":"5348198387","pt":1646215329776,"mc":[{"id":"1.195453754","rc":[{"atl":[[230,8.19]],"id":522755}],"con":true,"img":false}]}
{"op":"mcm","clk":"5348198395","pt":1646215329879,"mc":[{"id":"1.195453754","rc":[{"atl":[[590,2]],"id":522745},{"atl":[[150,0]],"id":522755}],"con":true,"img":false}]}
{"op":"mcm","clk":"5348198442","pt":1646215330451,"mc":[{"id":"1.195453754","rc":[{"atl":[[38,0]],"id":522752}],"con":true,"img":false}]}
{"op":"mcm","clk":"5348198466","pt":1646215330765,"mc":[{"id":"1.195453754","rc":[{"atl":[[230,2]],"id":522755}],"con":true,"img":false}]}
{"op":"mcm","clk":"5348198483","pt":1646215330970,"mc":[{"id":"1.195453754","rc":[{"atl":[[70,2],[42,36.85]],"id":3805762}],"con":true,"img":false}]}
{"op":"mcm","clk":"5348198657","pt":1646215333254,"mc":[{"id":"1.195453754","rc":[{"atb":[[400,2.24]],"id":3805732}],"con":true,"img":false}]}
{"op":"mcm","clk":"5348198695","pt":1646215333871,"mc":[{"id":"1.195453754","rc":[{"atl":[[34,9.76]],"id":3805762}],"con":true,"img":false}]}
{"op":"mcm","clk":"5348198733","pt":1646215334572,"mc":[{"id":"1.195453754","rc":[{"atl":[[36,0]],"id":3805762}],"con":true,"img":false}]}
{"op":"mcm","clk":"5348198828","pt":1646215336077,"mc":[{"id":"1.195453754","rc":[{"atl":[[830,0],[840,3.71]],"id":522754},{"atl":[[990,0],[1000,3.43]],"id":522751},{"atl":[[90,25.95]],"id":522741}],"con":true,"img":false}]}
{"op":"mcm","clk":"5348198857","pt":1646215336542,"mc":[{"id":"1.195453754","rc":[{"atl":[[28,10.82]],"id":522753},{"atl":[[250,5.77]],"id":522745},{"atl":[[80,20.07],[44,9.9]],"id":522752}],"con":true,"img":false}]}
{"op":"mcm","clk":"5348198918","pt":1646215337274,"mc":[{"id":"1.195453754","rc":[{"atl":[[150,9.64]],"id":522755},{"atl":[[300,2],[240,6.02]],"id":3805772}],"con":true,"img":false}]}
{"op":"mcm","clk":"5348198944","pt":1646215337582,"mc":[{"id":"1.195453754","rc":[{"atl":[[34,9.9],[28,4.95]],"id":522753}],"con":true,"img":false}]}
{"op":"mcm","clk":"5348198993","pt":1646215338258,"mc":[{"id":"1.195453754","rc":[{"atl":[[34,14.71]],"id":522753},{"atl":[[44,0],[46,4.95],[55,0],[60,9.9]],"id":522748},{"atl":[[70,22.72],[42,9.9]],"id":3805762}],"con":true,"img":false}]}
{"op":"mcm","clk":"5348199060","pt":1646215339242,"mc":[{"id":"1.195453754","rc":[{"atl":[[60,12.59]],"id":522748}],"con":true,"img":false}]}
{"op":"mcm","clk":"5348199322","pt":1646215342668,"mc":[{"id":"1.195453754","rc":[{"atl":[[65,29.6],[46,0],[48,4.95],[60,2.68]],"id":522748}],"con":true,"img":false}]}
{"op":"mcm","clk":"5348199337","pt":1646215342874,"mc":[{"id":"1.195453754","rc":[{"atl":[[270,0],[280,4.95]],"id":3805799},{"atl":[[220,0],[230,4.95]],"id":3805772}],"con":true,"img":false}]}
{"op":"mcm","clk":"5348199347","pt":1646215342982,"mc":[{"id":"1.195453754","rc":[{"atb":[[3.6,2.72],[3.35,72.95],[3.4,0],[3.55,4.95]],"id":522749},{"atl":[[36,0],[38,4.95],[44,0],[46,9.9]],"id":522752}],"con":true,"img":false}]}
{"op":"mcm","clk":"5348199372","pt":1646215343292,"mc":[{"id":"1.195453754","rc":[{"atl":[[280,5.52]],"id":3805799}],"con":true,"img":false}]}
{"op":"mcm","clk":"5348199379","pt":1646215343396,"mc":[{"id":"1.195453754","rc":[{"atl":[[830,1.75],[840,2]],"id":522754}],"con":true,"img":false}]}
{"op":"mcm","clk":"5348199387","pt":1646215343501,"mc":[{"id":"1.195453754","rc":[{"atl":[[990,1.47],[1000,2]],"id":522751},{"atl":[[590,4.47]],"id":522745}],"con":true,"img":false}]}
{"op":"mcm","clk":"5348199398","pt":1646215343608,"mc":[{"id":"1.195453754","rc":[{"atl":[[250,0]],"id":522745},{"atl":[[220,0.72]],"id":3805772}],"con":true,"img":false}]}
{"op":"mcm","clk":"5348199412","pt":1646215343759,"mc":[{"id":"1.195453754","rc":[{"atb":[[3.55,27.04]],"id":522749},{"atl":[[12.5,4.95],[13,13.21],[14.5,9.9],[15,0]],"id":522746},{"atl":[[44,3.68]],"id":522752}],"con":true,"img":false}]}
{"op":"mcm","clk":"5348199432","pt":1646215344071,"mc":[{"id":"1.195453754","rc":[{"atl":[[830,0]],"id":522754},{"atl":[[710,0]],"id":3805799}],"con":true,"img":false}]}
{"op":"mcm","clk":"5348199439","pt":1646215344176,"mc":[{"id":"1.195453754","rc":[{"atl":[[590,2]],"id":522745},{"atl":[[65,4.95],[80,0],[85,9.9],[60,0]],"id":3805747},{"atl":[[150,0],[230,8.37]],"id":522755},{"atl":[[22,4.76],[14.5,44.26]],"id":522746},{"atl":[[80,2],[46,31.54]],"id":522752},{"atl":[[230,0],[240,4.95]],"id":3805772}],"con":true,"img":false}]}
{"op":"mcm","clk":"5348199447","pt":1646215344281,"mc":[{"id":"1.195453754","rc":[{"atl":[[85,11.9],[110,11.6]],"id":3805747}],"con":true,"img":false}]}
{"op":"mcm","clk":"5348199457","pt":1646215344384,"mc":[{"id":"1.195453754","rc":[{"atl":[[12.5,18.74]],"id":522746},{"atl":[[220,0]],"id":3805772}],"con":true,"img":false}]}
{"op":"mcm","clk":"5348199464","pt":1646215344487,"mc":[{"id":"1.195453754","rc":[{"atl":[[730,4]],"id":3805799},{"atl":[[34,0],[36,4.95],[42,0],[44,9.9]],"id":3805762}],"con":true,"img":false}]}
{"op":"mcm","clk":"5348199475","pt":1646215344590,"mc":[{"id":"1.195453754","rc":[{"atl":[[720,0]],"id":3805799},{"atl":[[300,6.88]],"id":3805772}],"con":true,"img":false}]}
{"op":"mcm","clk":"5348199492","pt":1646215344799,"mc":[{"id":"1.195453754","rc":[{"atb":[[6.4,29.35],[5.8,22.08],[6.6,4.95],[5.9,9.9]],"id":522747},{"atb":[[80,9.9],[85,0],[100,4.95],[110,0]],"id":522745}],"con":true,"img":false}]}
{"op":"mcm","clk":"5348199498","pt":1646215344905,"mc":[{"id":"1.195453754","rc":[{"atl":[[60,2.68]],"id":3805747}],"con":true,"img":false}]}
{"op":"mcm","clk":"5348199507","pt":1646215344957,"mc":[{"id":"1.195453754","rc":[{"atl":[[80,9.9],[60,7.64]],"id":3805747}],"con":true,"img":false}]}
{"op":"mcm","clk":"5348199516","pt":1646215345059,"mc":[{"id":"1.195453754","rc":[{"atl":[[65,0],[85,2]],"id":3805747},{"atl":[[13,0]],"id":522746},{"atl":[[230,0.69]],"id":3805772}],"con":true,"img":false}]}
{"op":"mcm","clk":"5348199523","pt":1646215345167,"mc":[{"id":"1.195453754","rc":[{"atb":[[5.8,0],[6.2,51.59],[6.8,27.33]],"id":522747},{"atl":[[730,2]],"id":3805799},{"atl":[[130,9.9],[90,0],[95,4.95],[120,0]],"id":522750},{"atl":[[36,0],[38,4.95],[42,3.86],[44,0],[46,9.9]],"id":3805762}],"con":true,"img":false}]}
{"op":"mcm","clk":"5348199537","pt":1646215345371,"mc":[{"id":"1.195453754","rc":[{"atl":[[85,19.3],[110,0]],"id":3805747}],"con":true,"img":false}]}
{"op":"mcm","clk":"5348199543","pt":1646215345477,"mc":[{"id":"1.195453754","rc":[{"atb":[[100,6.55]],"id":522745}],"con":true,"img":false}]}
{"op":"mcm","clk":"5348199558","pt":1646215345684,"mc":[{"id":"1.195453754","rc":[{"atl":[[70,2],[46,36.85]],"id":3805762}],"con":true,"img":false}]}
{"op":"mcm","clk":"5348199583","pt":1646215346000,"mc":[{"id":"1.195453754","rc":[{"atb":[[6.4,0]],"id":522747},{"atl":[[95,6.63]],"id":522750}],"con":true,"img":false}]}
{"op":"mcm","clk":"5348199735","pt":1646215348182,"mc":[{"id":"1.195453754","rc":[{"atl":[[38,9.23]],"id":3805762}],"con":true,"img":false}]}
{"op":"mcm","clk":"5348199793","pt":1646215348964,"mc":[{"id":"1.195453754","rc":[{"atl":[[42,0]],"id":3805762}],"con":true,"img":false}]}
{"op":"mcm","clk":"5348199813","pt":1646215349175,"mc":[{"id":"1.195453754","rc":[{"atb":[[12.5,22.08],[13,9.9],[14.5,11.74],[15,4.95]],"id":522753}],"con":true,"img":false}]}
{"op":"mcm","clk":"5348199845","pt":1646215349588,"mc":[{"id":"1.195453754","rc":[{"atb":[[14,27.53],[15.5,10.93]],"id":522753}],"con":true,"img":false}]}
{"op":"mcm","clk":"5348199858","pt":1646215349690,"mc":[{"id":"1.195453754","rc":[{"atb":[[12.5,0]],"id":522753}],"con":true,"img":false}]}
{"op":"mcm","clk":"5348199907","pt":1646215350366,"mc":[{"id":"1.195453754","rc":[{"atl":[[830,1.78]],"id":522754},{"atl":[[990,0]],"id":522751},{"atb":[[14.5,0]],"id":522753}],"con":true,"img":false}]}
{"op":"mcm","clk":"5348199921","pt":1646215350573,"mc":[{"id":"1.195453754","rc":[{"atl":[[1000,3.47]],"id":522751}],"con":true,"img":false}]}
{"op":"mcm","clk":"5348199941","pt":1646215350781,"mc":[{"id":"1.195453754","rc":[{"atl":[[28,10.82]],"id":522753},{"atl":[[250,5.94]],"id":522745}],"con":true,"img":false}]}
{"op":"mcm","clk":"5348199959","pt":1646215351090,"mc":[{"id":"1.195453754","rc":[{"atl":[[22,72.39],[14.5,9.9]],"id":522746}],"con":true,"img":false}]}
{"op":"mcm","clk":"5348200001","pt":1646215351607,"mc":[{"id":"1.195453754","rc":[{"atl":[[34,9.9],[28,4.95]],"id":522753},{"atl":[[150,9.91],[230,2]],"id":522755}],"con":true,"img":false}]}
{"op":"mcm","clk":"5348200062","pt":1646215352285,"mc":[{"id":"1.195453754","rc":[{"atl":[[34,14.71]],"id":522753},{"atl":[[150,0]],"id":522755}],"con":true,"img":false}]}
{"op":"mcm","clk":"5348200073","pt":1646215352590,"mc":[{"id":"1.195453754","rc":[{"atl":[[70,23.3],[46,9.9]],"id":3805762}],"con":true,"img":false}]}
{"op":"mcm","clk":"5348200337","pt":1646215357024,"mc":[{"id":"1.195453754","rc":[{"atb":[[32,0],[34,9.9],[40,6.79],[42,4.95]],"id":522755},{"atb":[[90,9.78],[120,0]],"id":3805799}],"con":true,"img":false}]}
{"op":"mcm","clk":"5348200341","pt":1646215357126,"mc":[{"id":"1.195453754","rc":[{"atb":[[130,4.95],[95,9.9]],"id":3805799}],"con":true,"img":false}]}
{"op":"mcm","clk":"5348200346","pt":1646215357177,"mc":[{"id":"1.195453754","rc":[{"atl":[[260,0.61],[270,4.95]],"id":3805731}],"con":true,"img":false}]}
{"op":"mcm","clk":"5348200352","pt":1646215357282,"mc":[{"id":"1.195453754","rc":[{"atl":[[840,3.78]],"id":522754}],"con":true,"img":false}]}
{"op":"mcm","clk":"5348200358","pt":1646215357390,"mc":[{"id":"1.195453754","rc":[{"atl":[[830,0]],"id":522754},{"atb":[[34,28.3],[30,3.26]],"id":522755}],"con":true,"img":false}]}
{"op":"mcm","clk":"5348200366","pt":1646215357493,"mc":[{"id":"1.195453754","rc":[{"atl":[[1000,2]],"id":522751},{"atb":[[44,3.68]],"id":522755},{"atb":[[65,10.81],[90,0]],"id":3805799}],"con":true,"img":false}]}
{"op":"mcm","clk":"5348200371","pt":1646215357598,"mc":[{"id":"1.195453754","rc":[{"atl":[[990,1.5]],"id":522751},{"atl":[[590,4.54],[250,0]],"id":522745},{"atl":[[800,3.87]],"id":3805731}],"con":true,"img":false}]}
{"op":"mcm","clk":"5348200388","pt":1646215357802,"mc":[{"id":"1.195453754","rc":[{"atb":[[3.6,63.7]],"id":522749},{"atl":[[260,4.95],[280,0.56]],"id":3805799}],"con":true,"img":false}]}
{"op":"mcm","clk":"5348200395","pt":1646215357902,"mc":[{"id":"1.195453754","rc":[{"atl":[[38,9.23]],"id":522752}],"con":true,"img":false}]}
{"op":"mcm","clk":"5348200412","pt":1646215358112,"mc":[{"id":"1.195453754","rc":[{"atl":[[840,2]],"id":522754}],"con":true,"img":false}]}
{"op":"mcm","clk":"5348200428","pt":1646215358319,"mc":[{"id":"1.195453754","rc":[{"atb":[[40,2.72]],"id":522755},{"atl":[[150,10.04]],"id":522755}],"con":true,"img":false}]}
{"op":"mcm","clk":"5348200441","pt":1646215358524,"mc":[{"id":"1.195453754","rc":[{"atb":[[3.55,4.95]],"id":522749},{"atl":[[730,4.06]],"id":3805799}],"con":true,"img":false}]}
{"op":"mcm","clk":"5348200446","pt":1646215358575,"mc":[{"id":"1.195453754","rc":[{"atl":[[44,0]],"id":522752}],"con":true,"img":false}]}
{"op":"mcm","clk":"5348200480","pt":1646215359201,"mc":[{"id":"1.195453754","rc":[{"atl":[[80,20.87],[46,9.9]],"id":522752}],"con":true,"img":false}]}
{"op":"mcm","clk":"5348200571","pt":1646215360494,"mc":[{"id":"1.195453754","rc":[{"atb":[[85,12.29],[90,9.9],[110,0],[120,4.95]],"id":522751}],"con":true,"img":false}]}
{"op":"mcm","clk":"5348200590","pt":1646215360801,"mc":[{"id":"1.195453754","rc":[{"atb":[[80,0],[85,9.9],[100,1.6],[110,4.95]],"id":522745}],"con":true,"img":false}]}
{"op":"mcm","clk":"5348200602","pt":1646215361110,"mc":[{"id":"1.195453754","rc":[{"atb":[[85,2.72],[90,15.12]],"id":522751}],"con":true,"img":false}]}
{"op":"mcm","clk":"5348200617","pt":1646215361419,"mc":[{"id":"1.195453754","rc":[{"atb":[[38,0],[85,24.62],[110,6.4]],"id":522745}],"con":true,"img":false}]}
{"op":"mcm","clk":"5348200681","pt":1646215362509,"mc":[{"id":"1.195453754","rc":[{"atb":[[100,0]],"id":522745}],"con":true,"img":false}]}
{"op":"mcm","clk":"5348200780","pt":1646215364320,"mc":[{"id":"1.195453754","rc":[{"atl":[[830,1.82]],"id":522754}],"con":true,"img":false}]}
{"op":"mcm","clk":"5348200787","pt":1646215364424,"mc":[{"id":"1.195453754","rc":[{"atl":[[990,0],[1000,3.51]],"id":522751}],"con":true,"img":false}]}
{"op":"mcm","clk":"5348200799","pt":1646215364681,"mc":[{"id":"1.195453754","rc":[{"atl":[[28,10.82]],"id":522753},{"atl":[[590,2],[250,6.09]],"id":522745}],"con":true,"img":false}]}
{"op":"mcm","clk":"5348200811","pt":1646215364990,"mc":[{"id":"1.195453754","rc":[{"atl":[[150,0],[230,8.63]],"id":522755}],"con":true,"img":false}]}
{"op":"mcm","clk":"5348200842","pt":1646215365511,"mc":[{"id":"1.195453754","rc":[{"atl":[[34,9.9],[28,4.95]],"id":522753}],"con":true,"img":false}]}
{"op":"mcm","clk":"5348200877","pt":1646215366024,"mc":[{"id":"1.195453754","rc":[{"atl":[[300,4.95]],"id":522754}],"con":true,"img":false}]}
{"op":"mcm","clk":"5348200889","pt":1646215366229,"mc":[{"id":"1.195453754","rc":[{"atl":[[840,0],[460,2]],"id":522754}],"con":true,"img":false}]}
{"op":"mcm","clk":"5348200892","pt":1646215366279,"mc":[{"id":"1.195453754","rc":[{"atl":[[34,14.71]],"id":522753}],"con":true,"img":false}]}
{"op":"mcm","clk":"5348200921","pt":1646215366696,"mc":[{"id":"1.195453754","rc":[{"atl":[[300,0]],"id":522754}],"con":true,"img":false}]}
{"op":"mcm","clk":"5348200950","pt":1646215367315,"mc":[{"id":"1.195453754","rc":[{"atl":[[450,0.35]],"id":522754}],"con":true,"img":false}]}
{"op":"mcm","clk":"5348200988","pt":1646215367994,"mc":[{"id":"1.195453754","rc":[{"atl":[[810,0]],"id":522754}],"con":true,"img":false}]}
{"op":"mcm","clk":"5348200995","pt":1646215368099,"mc":[{"id":"1.195453754","rc":[{"atb":[[36,20.19],[85,9.9]],"id":522745}],"con":true,"img":false}]}
{"op":"mcm","clk":"5348201021","pt":1646215368507,"mc":[{"id":"1.195453754","rc":[{"atl":[[310,4.95]],"id":522754}],"con":true,"img":false}]}
{"op":"mcm","clk":"5348201185","pt":1646215371192,"mc":[{"id":"1.195453754","rc":[{"atl":[[310,0],[830,0],[460,5.34]],"id":522754},{"atb":[[34,9.9]],"id":522755}],"con":true,"img":false}]}
{"op":"mcm","clk":"5348201192","pt":1646215371295,"mc":[{"id":"1.195453754","rc":[{"atb":[[40,17.43]],"id":522755},{"atb":[[65,2.72],[95,23.29]],"id":3805799}],"con":true,"img":false}]}
{"op":"mcm","clk":"5348201199","pt":1646215371398,"mc":[{"id":"1.195453754","rc":[{"atl":[[990,1.55],[1000,2]],"id":522751},{"atl":[[590,4.61],[250,0]],"id":522745}],"con":true,"img":false}]}
{"op":"mcm","clk":"5348201236","pt":1646215372018,"mc":[{"id":"1.195453754","rc":[{"atl":[[460,2]],"id":522754}],"con":true,"img":false}]}
{"op":"mcm","clk":"5348201256","pt":1646215372329,"mc":[{"id":"1.195453754","rc":[{"atl":[[150,10.3],[230,2]],"id":522755}],"con":true,"img":false}]}
{"op":"mcm","clk":"5348201522","pt":1646215376315,"mc":[{"id":"1.195453754","rc":[{"atl":[[310,4.95]],"id":522754}],"con":true,"img":false}]}
{"op":"mcm","clk":"5348201611","pt":1646215377819,"mc":[{"id":"1.195453754","rc":[{"atl":[[90,4.95],[120,9.9]],"id":522750},{"atl":[[200,4.95]],"id":3805772}],"con":true,"img":false}]}
{"op":"mcm","clk":"5348201617","pt":1646215377921,"mc":[{"id":"1.195453754","rc":[{"atl":[[460,5.38]],"id":522754},{"atl":[[130,1.23],[120,4.95]],"id":522755},{"atl":[[65,19.7],[40,4.95]],"id":522748},{"atl":[[130,0],[95,1.68]],"id":522750}],"con":true,"img":false}]}
{"op":"mcm","clk":"5348201628","pt":1646215378126,"mc":[{"id":"1.195453754","rc":[{"atl":[[990,0],[1000,3.55]],"id":522751}],"con":true,"img":false}]}
{"op":"mcm","clk":"5348201633","pt":1646215378231,"mc":[{"id":"1.195453754","rc":[{"atl":[[150,2],[90,6.73],[120,22.93]],"id":522750},{"atl":[[300,2],[200,5.74],[240,11.46]],"id":3805772}],"con":true,"img":false}]}
{"op":"mcm","clk":"5348201638","pt":1646215378333,"mc":[{"id":"1.195453754","rc":[{"atl":[[28,10.82]],"id":522753},{"atl":[[590,2],[250,6.25]],"id":522745},{"atl":[[65,2],[40,9.01],[60,14.9]],"id":522748}],"con":true,"img":false}]}
{"op":"mcm","clk":"5348201647","pt":1646215378436,"mc":[{"id":"1.195453754","rc":[{"atl":[[120,6.28]],"id":522755}],"con":true,"img":false}]}
{"op":"mcm","clk":"5348201651","pt":1646215378540,"mc":[{"id":"1.195453754","rc":[{"atl":[[36,4.95],[38,4.28],[44,9.9],[46,0]],"id":522752}],"con":true,"img":false}]}
{"op":"mcm","clk":"5348201683","pt":1646215378901,"mc":[{"id":"1.195453754","rc":[{"atl":[[95,0]],"id":522750},{"atl":[[80,2],[44,31.54]],"id":522752},{"atl":[[230,0]],"id":3805772}],"con":true,"img":false}]}
{"op":"mcm","clk":"5348201688","pt":1646215379004,"mc":[{"id":"1.195453754","rc":[{"atl":[[36,9.48]],"id":522752}],"con":true,"img":false}]}
{"op":"mcm","clk":"5348201695","pt":1646215379110,"mc":[{"id":"1.195453754","rc":[{"atl":[[34,9.9],[28,4.95]],"id":522753},{"atl":[[130,0]],"id":522755},{"atl":[[60,12.21]],"id":522748}],"con":true,"img":false}]}
{"op":"mcm","clk":"5348201716","pt":1646215379421,"mc":[{"id":"1.195453754","rc":[{"atb":[[3.6,68.65],[3.35,63.04],[3.4,9.9],[3.55,0]],"id":522749}],"con":true,"img":false}]}
{"op":"mcm","clk":"5348201733","pt":1646215379729,"mc":[{"id":"1.195453754","rc":[{"atl":[[150,0],[230,8.81]],"id":522755}],"con":true,"img":false}]}
{"op":"mcm","clk":"5348201748","pt":1646215379938,"mc":[{"id":"1.195453754","rc":[{"atl":[[34,14.71]],"id":522753},{"atl":[[38,0]],"id":522752},{"atl":[[36,4.95],[38,4.28],[44,9.9],[46,0]],"id":3805762}],"con":true,"img":false}]}
{"op":"mcm","clk":"5348201782","pt":1646215380401,"mc":[{"id":"1.195453754","rc":[{"atl":[[230,2]],"id":522755},{"atl":[[70,2],[36,9.48],[44,36.85]],"id":3805762}],"con":true,"img":false}]}
{"op":"mcm","clk":"5348201815","pt":1646215380813,"mc":[{"id":"1.195453754","rc":[{"atl":[[310,5.46]],"id":522754}],"con":true,"img":false}]}
{"op":"mcm","clk":"5348201838","pt":1646215381228,"mc":[{"id":"1.195453754","rc":[{"atl":[[38,0]],"id":3805762}],"con":true,"img":false}]}
{"op":"mcm","clk":"5348201863","pt":1646215381541,"mc":[{"id":"1.195453754","rc":[{"atl":[[450,0]],"id":522754}],"con":true,"img":false}]}
{"op":"mcm","clk":"5348201886","pt":1646215381851,"mc":[{"id":"1.195453754","rc":[{"atb":[[40,0]],"id":3805777},{"atb":[[19.5,5.41]],"id":522743},{"atb":[[55,2]],"id":7607472},{"atl":[[28,3.7]],"id":522746},{"atb":[[7.4,15.62]],"id":3805772}],"con":true,"img":false}]}
{"op":"mcm","clk":"5348201894","pt":1646215381908,"mc":[{"id":"1.195453754","rc":[{"atl":[[10.5,32.93],[14.5,7.41]],"id":522749},{"atb":[[55,2]],"id":3805777},{"atb":[[29,0]],"id":522743},{"atb":[[3.55,0],[3.15,46.51]],"id":3805740},{"atb":[[29,0]],"id":7607472},{"atb":[[10.5,0],[15,7.14]],"id":522745},{"atl":[[22,67.63]],"id":522746},{"atb":[[7.2,16.13],[8.6,0]],"id":522748},{"atl":[[150,0],[180,2]],"id":522750},{"atb":[[21,0],[7.4,15.62]],"id":3805731},{"atb":[[44,2.33],[25,0]],"id":522742},{"atb":[[5.2,0]],"id":3805772}],"con":true,"img":false}]}
{"op":"mcm","clk":"5348202104","pt":1646215384711,"mc":[{"id":"1.195453754","rc":[{"atl":[[330,4.79],[460,2]],"id":522754},{"atl":[[180,10.78],[120,9.9]],"id":522750},{"atl":[[300,7.27]],"id":3805772}],"con":true,"img":false}]}
{"op":"mcm","clk":"5348202111","pt":1646215384810,"mc":[{"id":"1.195453754","rc":[{"atl":[[400,2]],"id":522754},{"atl":[[250,0]],"id":522745},{"atl":[[240,4.95]],"id":3805772}],"con":true,"img":false}]}
{"op":"mcm","clk":"5348202118","pt":1646215384921,"mc":[{"id":"1.195453754","rc":[{"atl":[[460,0]],"id":522754},{"atl":[[990,1.59],[1000,2]],"id":522751},{"atl":[[590,4.67]],"id":522745}],"con":true,"img":false}]}
{"op":"mcm","clk":"5348202155","pt":1646215385539,"mc":[{"id":"1.195453754","rc":[{"atl":[[80,21.81],[44,9.9]],"id":522752}],"con":true,"img":false}]}
{"op":"mcm","clk":"5348202176","pt":1646215385850,"mc":[{"id":"1.195453754","rc":[{"atb":[[8,14.29],[9.2,0]],"id":3805762}],"con":true,"img":false}]}
{"op":"mcm","clk":"5348202182","pt":1646215385953,"mc":[{"id":"1.195453754","rc":[{"atl":[[990,0]],"id":522751},{"atl":[[140,11.32]],"id":522755}],"con":true,"img":false}]}
{"op":"mcm","clk":"5348202209","pt":1646215386320,"mc":[{"id":"1.195453754","rc":[{"atl":[[310,0]],"id":522754},{"atl":[[36,0],[38,4.95],[44,26.94],[46,9.9]],"id":3805762}],"con":true,"img":false}]}
{"op":"mcm","clk":"5348202216","pt":1646215386421,"mc":[{"id":"1.195453754","rc":[{"atl":[[320,4.95]],"id":522754},{"atl":[[130,9.9],[90,0],[95,4.95],[120,0]],"id":522750}],"con":true,"img":false}]}
{"op":"mcm","clk":"5348202243","pt":1646215386937,"mc":[{"id":"1.195453754","rc":[{"atl":[[44,0],[46,41.77]],"id":3805762}],"con":true,"img":false}]}
{"op":"mcm","clk":"5348202256","pt":1646215387140,"mc":[{"id":"1.195453754","rc":[{"atl":[[320,5.44]],"id":522754},{"atl":[[95,6.63]],"id":522750},{"atl":[[42,3.86]],"id":3805762}],"con":true,"img":false}]}
{"op":"mcm","clk":"5348202430","pt":1646215388769,"mc":[{"id":"1.195453754","rc":[{"atb":[[250,1.17]],"id":522742}],"con":true,"img":false}]}
{"op":"mcm","clk":"5348202494","pt":1646215389538,"mc":[{"id":"1.195453754","rc":[{"atb":[[250,0.53]],"id":522742}],"con":true,"img":false}]}
{"op":"mcm","clk":"5348202584","pt":1646215390520,"mc":[{"id":"1.195453754","rc":[{"atb":[[170,0.93]],"id":522742}],"con":true,"img":false}]}
{"op":"mcm","clk":"5348202709","pt":1646215391254,"mc":[{"id":"1.195453754","rc":[{"atl":[[330,0],[400,5.99]],"id":522754},{"atb":[[160,7.13],[120,9.9]],"id":522742}],"con":true,"img":false}]}
{"op":"mcm","clk":"5348202737","pt":1646215391667,"mc":[{"id":"1.195453754","rc":[{"atl":[[990,1.6]],"id":522751}],"con":true,"img":false}]}
{"op":"mcm","clk":"5348202745","pt":1646215391726,"mc":[{"id":"1.195453754","rc":[{"atl":[[28,10.82]],"id":522753},{"atl":[[590,2],[250,6.4]],"id":522745}],"con":true,"img":false}]}
{"op":"mcm","clk":"5348202794","pt":1646215392657,"mc":[{"id":"1.195453754","rc":[{"atl":[[34,9.9],[28,4.95]],"id":522753},{"atl":[[140,0],[230,8.97]],"id":522755}],"con":true,"img":false}]}
{"op":"mcm","clk":"5348202871","pt":1646215393645,"mc":[{"id":"1.195453754","rc":[{"atl":[[34,14.71]],"id":522753}],"con":true,"img":false}]}
{"op":"mcm","clk":"5348202919","pt":1646215393747,"mc":[{"id":"1.195453754","rc":[{"atl":[[230,2]],"id":522755}],"con":true,"img":false}]}
{"op":"mcm","clk":"5348202933","pt":1646215393953,"mc":[{"id":"1.195453754","rc":[{"atl":[[38,9.23]],"id":3805762}],"con":true,"img":false}]}
{"op":"mcm","clk":"5348203011","pt":1646215394946,"mc":[{"id":"1.195453754","rc":[{"atl":[[42,0]],"id":3805762}],"con":true,"img":false}]}
{"op":"mcm","clk":"5348203062","pt":1646215395626,"mc":[{"id":"1.195453754","rc":[{"atl":[[70,25.04],[46,9.9]],"id":3805762}],"con":true,"img":false}]}
{"op":"mcm","clk":"5348203242","pt":1646215398132,"mc":[{"id":"1.195453754","rc":[{"atl":[[340,4.75],[400,2]],"id":522754},{"atl":[[990,0],[1000,3.61]],"id":522751},{"atl":[[590,4.73],[250,0]],"id":522745}],"con":true,"img":false}]}
{"op":"mcm","clk":"5348203322","pt":1646215399168,"mc":[{"id":"1.195453754","rc":[{"atl":[[340,0]],"id":522754},{"atl":[[1000,2]],"id":522751},{"atl":[[590,2]],"id":522745},{"atl":[[140,11.59]],"id":522755}],"con":true,"img":false}]}
{"op":"mcm","clk":"5348203374","pt":1646215399846,"mc":[{"id":"1.195453754","rc":[{"atl":[[200,4.95],[210,4.95]],"id":3805772}],"con":true,"img":false}]}
{"op":"mcm","clk":"5348203379","pt":1646215399950,"mc":[{"id":"1.195453754","rc":[{"atl":[[200,0],[240,0]],"id":3805772}],"con":true,"img":false}]}
{"op":"mcm","clk":"5348203411","pt":1646215400365,"mc":[{"id":"1.195453754","rc":[{"atl":[[240,6.77]],"id":3805772}],"con":true,"img":false}]}
{"op":"mcm","clk":"5348203421","pt":1646215400470,"mc":[{"id":"1.195453754","rc":[{"atl":[[300,2]],"id":3805772}],"con":true,"img":false}]}
{"op":"mcm","clk":"5348203452","pt":1646215400732,"mc":[{"id":"1.195453754","rc":[{"atl":[[210,5.71]],"id":3805772}],"con":true,"img":false}]}
{"op":"mcm","clk":"5348203486","pt":1646215401147,"mc":[{"id":"1.195453754","rc":[{"atl":[[240,0]],"id":3805772}],"con":true,"img":false}]}
{"op":"mcm","clk":"5348203547","pt":1646215402086,"mc":[{"id":"1.195453754","rc":[{"atb":[[250,1.17]],"id":522742}],"con":true,"img":false}]}
{"op":"mcm","clk":"5348203615","pt":1646215402974,"mc":[{"id":"1.195453754","rc":[{"atb":[[170,0],[250,0.53]],"id":522742}],"con":true,"img":false}]}
{"op":"mcm","clk":"5348203670","pt":1646215403550,"mc":[{"id":"1.195453754","rc":[{"atb":[[120,21.3]],"id":522742}],"con":true,"img":false}]}
{"op":"mcm","clk":"5348203679","pt":1646215403654,"mc":[{"id":"1.195453754","rc":[{"atb":[[160,4.95],[170,0.93]],"id":522742}],"con":true,"img":false}]}
{"op":"mcm","clk":"5348203718","pt":1646215404383,"mc":[{"id":"1.195453754","rc":[{"atl":[[340,4.81]],"id":522754},{"atb":[[160,7.13],[120,9.9]],"id":522742}],"con":true,"img":false}]}
{"op":"mcm","clk":"5348203744","pt":1646215404751,"mc":[{"id":"1.195453754","rc":[{"atl":[[990,1.64]],"id":522751}],"con":true,"img":false}]}
{"op":"mcm","clk":"5348203749","pt":1646215404854,"mc":[{"id":"1.195453754","rc":[{"atl":[[28,10.82]],"id":522753},{"atl":[[250,6.55]],"id":522745}],"con":true,"img":false}]}
{"op":"mcm","clk":"5348203762","pt":1646215405065,"mc":[{"id":"1.195453754","rc":[{"atb":[[4.8,8.9],[4.3,15.48]],"id":3805740}],"con":true,"img":false}]}
{"op":"mcm","clk":"5348203798","pt":1646215405588,"mc":[{"id":"1.195453754","rc":[{"atl":[[140,0],[230,9.12]],"id":522755}],"con":true,"img":false}]}
{"op":"mcm","clk":"5348203805","pt":1646215405643,"mc":[{"id":"1.195453754","rc":[{"atl":[[34,9.9],[28,4.95]],"id":522753}],"con":true,"img":false}]}
{"op":"mcm","clk":"5348203825","pt":1646215405849,"mc":[{"id":"1.195453754","rc":[{"atb":[[4.9,2.72],[4.4,3.26]],"id":3805740}],"con":true,"img":false}]}
{"op":"mcm","clk":"5348203846","pt":1646215406164,"mc":[{"id":"1.195453754","rc":[{"atl":[[65,2],[60,22]],"id":522753}],"con":true,"img":false}]}
{"op":"mcm","clk":"5348203855","pt":1646215406370,"mc":[{"id":"1.195453754","rc":[{"atl":[[55,2.93]],"id":522753},{"atb":[[4.3,0],[4.6,32.92]],"id":3805740}],"con":true,"img":false}]}
{"op":"mcm","clk":"5348203905","pt":1646215406946,"mc":[{"id":"1.195453754","rc":[{"atl":[[55,25.02],[60,0]],"id":522753}],"con":true,"img":false}]}
{"op":"mcm","clk":"5348204166","pt":1646215410651,"mc":[{"id":"1.195453754","rc":[{"atl":[[340,0],[400,6.13]],"id":522754}],"con":true,"img":false}]}
{"op":"mcm","clk":"5348204192","pt":1646215411067,"mc":[{"id":"1.195453754","rc":[{"atl":[[990,0],[1000,3.64]],"id":522751}],"con":true,"img":false}]}
{"op":"mcm","clk":"5348204200","pt":1646215411172,"mc":[{"id":"1.195453754","rc":[{"atl":[[590,4.8]],"id":522745}],"con":true,"img":false}]}
{"op":"mcm","clk":"5348204211","pt":1646215411277,"mc":[{"id":"1.195453754","rc":[{"atl":[[250,0]],"id":522745}],"con":true,"img":false}]}
{"op":"mcm","clk":"5348204234","pt":1646215411595,"mc":[{"id":"1.195453754","rc":[{"atl":[[400,2]],"id":522754}],"con":true,"img":false}]}
{"op":"mcm","clk":"5348204278","pt":1646215411966,"mc":[{"id":"1.195453754","rc":[{"atb":[[4.9,0],[4.4,0]],"id":3805740}],"con":true,"img":false}]}
{"op":"mcm","clk":"5348204295","pt":1646215412172,"mc":[{"id":"1.195453754","rc":[{"atl":[[590,2]],"id":522745},{"atl":[[140,11.85],[230,2]],"id":522755}],"con":true,"img":false}]}
{"op":"mcm","clk":"5348204334","pt":1646215412589,"mc":[{"id":"1.195453754","rc":[{"atl":[[130,4.95],[120,0]],"id":522755},{"atl":[[40,0],[42,4.95],[48,0],[50,9.9]],"id":522748}],"con":true,"img":false}]}
{"op":"mcm","clk":"5348204343","pt":1646215412646,"mc":[{"id":"1.195453754","rc":[{"atb":[[4.8,11.63],[4.3,3.26],[4.6,4.95],[4.2,55.01]],"id":3805740}],"con":true,"img":false}]}
{"op":"mcm","clk":"5348204405","pt":1646215412956,"mc":[{"id":"1.195453754","rc":[{"atl":[[320,4.95],[330,4.95]],"id":522754}],"con":true,"img":false}]}
{"op":"mcm","clk":"5348204411","pt":1646215413057,"mc":[{"id":"1.195453754","rc":[{"atl":[[320,0]],"id":522754}],"con":true,"img":false}]}
{"op":"mcm","clk":"5348204428","pt":1646215413270,"mc":[{"id":"1.195453754","rc":[{"atl":[[130,6.18]],"id":522755},{"atl":[[230,7.22]],"id":3805772}],"con":true,"img":false}]}
{"op":"mcm","clk":"5348204440","pt":1646215413477,"mc":[{"id":"1.195453754","rc":[{"atl":[[48,3.37]],"id":522748}],"con":true,"img":false}]}
{"op":"mcm","clk":"5348204462","pt":1646215413742,"mc":[{"id":"1.195453754","rc":[{"atl":[[330,5.43]],"id":522754}],"con":true,"img":false}]}
{"op":"mcm","clk":"5348204514","pt":1646215413950,"mc":[{"id":"1.195453754","rc":[{"atl":[[50,22.27]],"id":522748}],"con":true,"img":false}]}
{"op":"mcm","clk":"5348204521","pt":1646215414052,"mc":[{"id":"1.195453754","rc":[{"atl":[[60,0]],"id":522748}],"con":true,"img":false}]}
{"op":"mcm","clk":"5348204607","pt":1646215415152,"mc":[{"id":"1.195453754","rc":[{"atb":[[250,1.17]],"id":522742}],"con":true,"img":false}]}
{"op":"mcm","clk":"5348204657","pt":1646215415989,"mc":[{"id":"1.195453754","rc":[{"atb":[[170,0],[250,0.53]],"id":522742}],"con":true,"img":false}]}
{"op":"mcm","clk":"5348204699","pt":1646215416560,"mc":[{"id":"1.195453754","rc":[{"atl":[[330,0.47]],"id":522754},{"atb":[[160,4.95],[120,21.3]],"id":522742}],"con":true,"img":false}]}
{"op":"mcm","clk":"5348204705","pt":1646215416674,"mc":[{"id":"1.195453754","rc":[{"atl":[[330,0]],"id":522754}],"con":true,"img":false}]}
{"op":"mcm","clk":"5348204714","pt":1646215416771,"mc":[{"id":"1.195453754","rc":[{"atb":[[170,0.93]],"id":522742}],"con":true,"img":false}]}
{"op":"mcm","clk":"5348204747","pt":1646215417195,"mc":[{"id":"1.195453754","rc":[{"atl":[[420,3.97]],"id":522754}],"con":true,"img":false}]}
{"op":"mcm","clk":"5348204762","pt":1646215417363,"mc":[{"id":"1.195453754","rc":[{"atl":[[400,0],[410,2],[1000,0.15]],"id":522754},{"atb":[[120,9.9]],"id":522742}],"con":true,"img":false}]}
{"op":"mcm","clk":"5348204786","pt":1646215417673,"mc":[{"id":"1.195453754","rc":[{"atl":[[990,1.68],[1000,2]],"id":522751},{"atl":[[28,10.82]],"id":522753},{"atl":[[250,6.69]],"id":522745}],"con":true,"img":false}]}
{"op":"mcm","clk":"5348204842","pt":1646215418361,"mc":[{"id":"1.195453754","rc":[{"atl":[[55,22.08],[28,4.95]],"id":522753},{"atl":[[140,0],[230,9.28]],"id":522755}],"con":true,"img":false}]}
{"op":"mcm","clk":"5348204885","pt":1646215419083,"mc":[{"id":"1.195453754","rc":[{"atl":[[34,14.71]],"id":522753}],"con":true,"img":false}]}
{"op":"mcm","clk":"5348204900","pt":1646215419290,"mc":[{"id":"1.195453754","rc":[{"atb":[[4.3,35.28],[4.2,9.9]],"id":3805740}],"con":true,"img":false}]}
{"op":"mcm","clk":"5348204907","pt":1646215419391,"mc":[{"id":"1.195453754","rc":[{"atl":[[290,2],[230,7.28]],"id":522755}],"con":true,"img":false}]}
{"op":"mcm","clk":"5348204917","pt":1646215419498,"mc":[{"id":"1.195453754","rc":[{"atl":[[300,7.59],[230,0]],"id":3805772}],"con":true,"img":false}]}
{"op":"mcm","clk":"5348204933","pt":1646215419709,"mc":[{"id":"1.195453754","rc":[{"atb":[[80,0],[85,9.9],[100,1.6],[110,4.95]],"id":3805785},{"atl":[[220,0.72],[240,4.95]],"id":3805785},{"atb":[[75,10.28],[80,9.9],[95,0],[100,4.95]],"id":522754},{"atl":[[11.5,0],[9.8,18.01]],"id":522747},{"atl":[[6.2,22.08],[6,4.95],[6.8,9.9],[7,0]],"id":522749},{"atb":[[16,4.95],[13,0],[14,37.44],[15,0]],"id":522753},{"atl":[[32,4.95],[34,4.8],[40,9.9],[28,0]],"id":522753},{"atb":[[4.8,2.72]],"id":3805740},{"atl":[[7.2,0],[6.4,15.48],[6.2,4.95],[7,9.9]],"id":3805740},{"atl":[[17.5,4.95],[18,9.32],[19.5,9.9],[20,0]],"id":3805784},{"atb":[[34,0],[36,9.9],[42,0],[44,8.64]],"id":522755},{"atb":[[16,4.95],[13.5,0],[15.5,0]],"id":522748},{"atl":[[280,0]],"id":3805799},{"atb":[[32,4.95],[26,0],[27,9.9],[30,5.46]],"id":522750},{"atl":[[260,5.56],[270,0]],"id":3805731},{"atb":[[16.5,3.26],[17.5,4.95],[14.5,0],[15.5,9.9]],"id":3805762},{"atb":[[42,3.26],[44,9.9],[50,9.66],[55,7.67]],"id":3805772}],"con":true,"img":false}]}
{"op":"mcm","clk":"5348204940","pt":1646215419763,"mc":[{"id":"1.195453754","rc":[{"atl":[[10.5,4.95],[12.5,9.9]],"id":522747}],"con":true,"img":false}]}
{"op":"mcm","clk":"5348204946","pt":1646215419868,"mc":[{"id":"1.195453754","rc":[{"atl":[[660,2],[910,0]],"id":3805785},{"atl":[[8.2,13.89],[8.8,36.33]],"id":3805740}],"con":true,"img":false}]}
{"op":"mcm","clk":"5348204954","pt":1646215419969,"mc":[{"id":"1.195453754","rc":[{"atl":[[22,4.76],[27,22.08]],"id":522747}],"con":true,"img":false}]}
{"op":"mcm","clk":"5348204970","pt":1646215420185,"mc":[{"id":"1.195453754","rc":[{"atb":[[85,20.23],[48,0],[120,1.32]],"id":3805785},{"atl":[[910,1.84],[940,0]],"id":3805785},{"atb":[[75,0],[80,18.79]],"id":522754},{"atl":[[10.5,82.06],[27,0]],"id":522747},{"atl":[[10.5,0],[6.8,57.46],[5.9,32.35]],"id":522749},{"atb":[[16.5,10.22]],"id":522753},{"atl":[[40,31.99],[55,0]],"id":522753},{"atl":[[6,22.08],[8.8,0],[7,31.99]],"id":3805740},{"atl":[[17.5,14.56],[19.5,38.49],[42,2.44]],"id":3805784},{"atb":[[36,33.58],[40,2.72]],"id":522755},{"atl":[[730,2]],"id":3805799},{"atb":[[34,4.8],[25,2.72],[27,34.5]],"id":522750},{"atl":[[800,2]],"id":3805731},{"atb":[[16.5,31.73],[16,0]],"id":3805762}],"con":true,"img":false}]}
{"op":"mcm","clk":"5348204976","pt":1646215420289,"mc":[{"id":"1.195453754","rc":[{"atl":[[300,2]],"id":3805772}],"con":true,"img":false}]}
{"op":"mcm","clk":"5348204982","pt":1646215420390,"mc":[{"id":"1.195453754","rc":[{"atl":[[340,4.95]],"id":522754},{"atb":[[4.6,27.04]],"id":3805740}],"con":true,"img":false}]}
{"op":"mcm","clk":"5348204994","pt":1646215420605,"mc":[{"id":"1.195453754","rc":[{"atb":[[8,0],[9,12.5]],"id":522753},{"atl":[[730,0],[790,2]],"id":3805799},{"atb":[[9.2,12.2],[7.8,0]],"id":522752}],"con":true,"img":false}]}
{"op":"mcm","clk":"5348205000","pt":1646215420654,"mc":[{"id":"1.195453754","rc":[{"atb":[[14,12.63],[15.5,33.49]],"id":522753}],"con":true,"img":false}]}
{"op":"mcm","clk":"5348205016","pt":1646215420874,"mc":[{"id":"1.195453754","rc":[{"atb":[[100,0]],"id":3805785},{"atl":[[10,4.95],[10.5,0],[12,9.9],[12.5,0]],"id":522747},{"atb":[[15.5,22.56]],"id":522753},{"atb":[[4.3,40.24],[4.6,22.08],[4.2,0]],"id":3805740},{"atl":[[6.4,0]],"id":3805740},{"atl":[[18,0]],"id":3805784},{"atl":[[280,6.01]],"id":3805731},{"atb":[[32,5.11],[34,4.95],[27,0],[28,9.9]],"id":3805741}],"con":true,"img":false}]}
{"op":"mcm","clk":"5348205027","pt":1646215420968,"mc":[{"id":"1.195453754","rc":[{"atl":[[6.2,0]],"id":522749},{"atb":[[30,0]],"id":522750},{"atl":[[36,0],[38,4.95],[44,0],[46,9.9]],"id":522752}],"con":true,"img":false}]}
{"op":"mcm","clk":"5348205035","pt":1646215421082,"mc":[{"id":"1.195453754","rc":[{"atl":[[330,4.95],[340,0]],"id":522754},{"atl":[[790,4.12]],"id":3805799},{"atl":[[720,2],[800,0]],"id":3805731},{"atl":[[70,2]],"id":522752}],"con":true,"img":false}]}
{"op":"mcm","clk":"5348205040","pt":1646215421179,"mc":[{"id":"1.195453754","rc":[{"atl":[[80,19.81]],"id":522752}],"con":true,"img":false}]}
{"op":"mcm","clk":"5348205049","pt":1646215421285,"mc":[{"id":"1.195453754","rc":[{"atb":[[28,28.05]],"id":3805741}],"con":true,"img":false}]}
{"op":"mcm","clk":"5348205061","pt":1646215421392,"mc":[{"id":"1.195453754","rc":[{"atb":[[36,4.52],[25,0]],"id":3805741}],"con":true,"img":false}]}
{"op":"mcm","clk":"5348205069","pt":1646215421496,"mc":[{"id":"1.195453754","rc":[{"atl":[[85,17.3],[100,2]],"id":3805747}],"con":true,"img":false}]}
{"op":"mcm","clk":"5348205079","pt":1646215421551,"mc":[{"id":"1.195453754","rc":[{"atl":[[70,23.64],[80,0]],"id":522752}],"con":true,"img":false}]}
{"op":"mcm","clk":"5348205089","pt":1646215421655,"mc":[{"id":"1.195453754","rc":[{"atb":[[3.95,9.9]],"id":3805740},{"atl":[[44,3.68]],"id":522752}],"con":true,"img":false}]}
{"op":"mcm","clk":"5348205106","pt":1646215421870,"mc":[{"id":"1.195453754","rc":[{"atb":[[46,2.72],[55,2]],"id":3805785},{"atb":[[4.2,0],[4.7,27.03]],"id":522747},{"atl":[[22,0],[15.5,6.9]],"id":522747},{"atb":[[32,0],[42,2.44]],"id":3805763},{"atb":[[400,2.24]],"id":7607472},{"atl":[[790,2]],"id":3805799},{"atb":[[8,14.29],[9.2,0]],"id":522752}],"con":true,"img":false}]}
{"op":"mcm","clk":"5348205119","pt":1646215422079,"mc":[{"id":"1.195453754","rc":[{"atb":[[32,0]],"id":3805741}],"con":true,"img":false}]}
{"op":"mcm","clk":"5348205125","pt":1646215422178,"mc":[{"id":"1.195453754","rc":[{"atl":[[340,4.95]],"id":522754}],"con":true,"img":false}]}
{"op":"mcm","clk":"5348205134","pt":1646215422283,"mc":[{"id":"1.195453754","rc":[{"atl":[[330,0]],"id":522754}],"con":true,"img":false}]}
{"op":"mcm","clk":"5348205151","pt":1646215422600,"mc":[{"id":"1.195453754","rc":[{"atl":[[410,0],[490,2]],"id":522754}],"con":true,"img":false}]}
{"op":"mcm","clk":"5348205183","pt":1646215422974,"mc":[{"id":"1.195453754","rc":[{"atl":[[330,4.95]],"id":522754}],"con":true,"img":false}]}
{"op":"mcm","clk":"5348205192","pt":1646215423078,"mc":[{"id":"1.195453754","rc":[{"atl":[[340,0]],"id":522754}],"con":true,"img":false}]}
{"op":"mcm","clk":"5348205206","pt":1646215423291,"mc":[{"id":"1.195453754","rc":[{"atl":[[420,0],[490,5.44]],"id":522754}],"con":true,"img":false}]}
{"op":"mcm","clk":"5348205251","pt":1646215423772,"mc":[{"id":"1.195453754","rc":[{"atl":[[990,0]],"id":522751},{"atl":[[590,4.86]],"id":522745}],"con":true,"img":false}]}
{"op":"mcm","clk":"5348205263","pt":1646215423874,"mc":[{"id":"1.195453754","rc":[{"atl":[[1000,3.68]],"id":522751},{"atl":[[250,0]],"id":522745}],"con":true,"img":false}]}
{"op":"mcm","clk":"5348205313","pt":1646215424593,"mc":[{"id":"1.195453754","rc":[{"atl":[[590,2]],"id":522745},{"atl":[[290,7.83],[230,0]],"id":522755}],"con":true,"img":false}]}
{"op":"mcm","clk":"5348205338","pt":1646215424915,"mc":[{"id":"1.195453754","rc":[{"atb":[[400,2.24]],"id":3805777}],"con":true,"img":false}]}
{"op":"mcm","clk":"5348205426","pt":1646215426004,"mc":[{"id":"1.195453754","rc":[{"atl":[[230,7.38]],"id":3805772}],"con":true,"img":false}]}
{"op":"mcm","clk":"5348205433","pt":1646215426056,"mc":[{"id":"1.195453754","rc":[{"atl":[[42,8.82]],"id":522748}],"con":true,"img":false}]}
{"op":"mcm","clk":"5348205457","pt":1646215426372,"mc":[{"id":"1.195453754","rc":[{"atl":[[330,5.43]],"id":522754},{"atl":[[19.5,9.9],[42,42.93]],"id":3805784}],"con":true,"img":false}]}
{"op":"mcm","clk":"5348205466","pt":1646215426476,"mc":[{"id":"1.195453754","rc":[{"atl":[[890,2]],"id":522754}],"con":true,"img":false}]}
{"op":"mcm","clk":"5348205473","pt":1646215426579,"mc":[{"id":"1.195453754","rc":[{"atl":[[490,3.44]],"id":522754}],"con":true,"img":false}]}
{"op":"mcm","clk":"5348205499","pt":1646215426995,"mc":[{"id":"1.195453754","rc":[{"atl":[[48,0]],"id":522748}],"con":true,"img":false}]}
{"op":"mcm","clk":"5348205511","pt":1646215427200,"mc":[{"id":"1.195453754","rc":[{"atl":[[720,4.35]],"id":3805731}],"con":true,"img":false}]}
{"op":"mcm","clk":"5348205519","pt":1646215427305,"mc":[{"id":"1.195453754","rc":[{"atl":[[340,4.95],[1000,0]],"id":522754},{"atl":[[280,0]],"id":3805731}],"con":true,"img":false}]}
{"op":"mcm","clk":"5348205526","pt":1646215427410,"mc":[{"id":"1.195453754","rc":[{"atl":[[330,0.47]],"id":522754}],"con":true,"img":false}]}
{"op":"mcm","clk":"5348205532","pt":1646215427467,"mc":[{"id":"1.195453754","rc":[{"atl":[[330,0]],"id":522754}],"con":true,"img":false}]}
{"op":"mcm","clk":"5348205539","pt":1646215427576,"mc":[{"id":"1.195453754","rc":[{"atl":[[65,19.96],[50,9.9]],"id":522748}],"con":true,"img":false}]}
{"op":"mcm","clk":"5348205558","pt":1646215427888,"mc":[{"id":"1.195453754","rc":[{"atb":[[260,0.61]],"id":522742}],"con":true,"img":false}]}
{"op":"mcm","clk":"5348205572","pt":1646215428097,"mc":[{"id":"1.195453754","rc":[{"atl":[[720,2]],"id":3805731}],"con":true,"img":false}]}
{"op":"mcm","clk":"5348205586","pt":1646215428301,"mc":[{"id":"1.195453754","rc":[{"atl":[[480,0.33]],"id":522754}],"con":true,"img":false}]}
{"op":"mcm","clk":"5348205627","pt":1646215428785,"mc":[{"id":"1.195453754","rc":[{"atb":[[170,0]],"id":522742}],"con":true,"img":false}]}
{"op":"mcm","clk":"5348205657","pt":1646215429206,"mc":[{"id":"1.195453754","rc":[{"atb":[[170,1.69]],"id":522742}],"con":true,"img":false}]}
{"op":"mcm","clk":"5348205719","pt":1646215429989,"mc":[{"id":"1.195453754","rc":[{"atl":[[340,5.42]],"id":522754}],"con":true,"img":false}]}
{"op":"mcm","clk":"5348205733","pt":1646215430197,"mc":[{"id":"1.195453754","rc":[{"atl":[[1000,2]],"id":522751},{"atl":[[250,6.83]],"id":522745}],"con":true,"img":false}]}
{"op":"mcm","clk":"5348205741","pt":1646215430299,"mc":[{"id":"1.195453754","rc":[{"atl":[[990,1.72]],"id":522751},{"atl":[[32,10.06]],"id":522753}],"con":true,"img":false}]}
{"op":"mcm","clk":"5348205777","pt":1646215430778,"mc":[{"id":"1.195453754","rc":[{"atl":[[480,0]],"id":522754}],"con":true,"img":false}]}
{"op":"mcm","clk":"5348205784","pt":1646215430888,"mc":[{"id":"1.195453754","rc":[{"atl":[[290,2],[150,11.41]],"id":522755}],"con":true,"img":false}]}
{"op":"mcm","clk":"5348205796","pt":1646215431127,"mc":[{"id":"1.195453754","rc":[{"atl":[[34,0]],"id":522753}],"con":true,"img":false}]}
{"op":"mcm","clk":"5348205805","pt":1646215431196,"mc":[{"id":"1.195453754","rc":[{"atl":[[890,3.91]],"id":522754}],"con":true,"img":false}]}
{"op":"mcm","clk":"5348205812","pt":1646215431313,"mc":[{"id":"1.195453754","rc":[{"atl":[[490,0]],"id":522754}],"con":true,"img":false}]}
{"op":"mcm","clk":"5348205825","pt":1646215431508,"mc":[{"id":"1.195453754","rc":[{"atl":[[330,4.95],[340,0.46]],"id":522754},{"atb":[[3.6,2.72],[3.35,72.95],[3.4,0],[3.55,4.95]],"id":522749}],"con":true,"img":false}]}
{"op":"mcm","clk":"5348205833","pt":1646215431616,"mc":[{"id":"1.195453754","rc":[{"atb":[[70,0],[48,0]],"id":522754},{"atb":[[85,0],[60,0]],"id":522751},{"atl":[[65,28.38],[40,9.9]],"id":522753},{"atb":[[270,0],[220,0]],"id":3805777},{"atb":[[180,0],[230,0]],"id":7607472},{"atb":[[40,0],[30,0]],"id":522755},{"atb":[[18,0],[21,0]],"id":522748},{"atb":[[42,0],[55,4.95]],"id":3805772}],"con":true,"img":false}]}
{"op":"mcm","clk":"5348205857","pt":1646215431879,"mc":[{"id":"1.195453754","rc":[{"atl":[[890,2]],"id":522754},{"atb":[[5.6,0],[6.2,48.86]],"id":522747},{"atb":[[20,0],[25,0]],"id":522750}],"con":true,"img":false}]}
{"op":"mcm","clk":"5348205864","pt":1646215431982,"mc":[{"id":"1.195453754","rc":[{"atb":[[160,4.95],[120,9.9]],"id":3805777},{"atb":[[36,9.9],[28,26.97]],"id":522755},{"atl":[[130,1.23],[160,9.9],[120,4.95]],"id":522755},{"atl":[[40,4.95],[42,3.86],[48,9.9],[50,0]],"id":522748},{"atl":[[200,4.95],[210,0.75]],"id":3805772}],"con":true,"img":false}]}
{"op":"mcm","clk":"5348205873","pt":1646215432084,"mc":[{"id":"1.195453754","rc":[{"atb":[[160,4.95],[120,9.9]],"id":7607472},{"atb":[[17,18.23],[8.8,74.49]],"id":522748},{"atl":[[300,7.71],[230,0]],"id":3805772}],"con":true,"img":false}]}
{"op":"mcm","clk":"5348205887","pt":1646215432294,"mc":[{"id":"1.195453754","rc":[{"atb":[[80,21.52],[55,3.26]],"id":522754},{"atb":[[3.55,19.66]],"id":522749},{"atb":[[65,3.26],[90,17.84]],"id":522751},{"atb":[[300,2.72],[250,3.26]],"id":3805777},{"atb":[[200,3.26],[250,2.72]],"id":7607472},{"atb":[[32,3.26],[42,2.72]],"id":522755},{"atb":[[19,3.26],[23,2.72]],"id":522748},{"atl":[[260,0],[280,4.95]],"id":3805799},{"atb":[[44,13.17],[60,2.72]],"id":3805772}],"con":true,"img":false}]}
{"op":"mcm","clk":"5348205895","pt":1646215432398,"mc":[{"id":"1.195453754","rc":[{"atl":[[120,6.28]],"id":522755},{"atl":[[200,5.74]],"id":3805772}],"con":true,"img":false}]}
{"op":"mcm","clk":"5348205915","pt":1646215432606,"mc":[{"id":"1.195453754","rc":[{"atb":[[6.4,2.72],[5.7,3.26]],"id":522747},{"atb":[[21,3.26],[26,2.72]],"id":522750},{"atl":[[36,4.95],[38,0],[44,13.59],[46,0]],"id":522752}],"con":true,"img":false}]}
{"op":"mcm","clk":"5348205923","pt":1646215432708,"mc":[{"id":"1.195453754","rc":[{"atl":[[660,4.59]],"id":3805785},{"atl":[[12,51.41]],"id":522747},{"atb":[[28,4.93]],"id":522755},{"atb":[[50,0],[55,16.35]],"id":3805772}],"con":true,"img":false}]}
{"op":"mcm","clk":"5348205932","pt":1646215432813,"mc":[{"id":"1.195453754","rc":[{"atl":[[910,0]],"id":3805785},{"atb":[[36,30.1]],"id":522755}],"con":true,"img":false}]}
{"op":"mcm","clk":"5348205946","pt":1646215432974,"mc":[{"id":"1.195453754","rc":[{"atl":[[780,0.2]],"id":3805799}],"con":true,"img":false}]}
{"op":"mcm","clk":"5348205953","pt":1646215433074,"mc":[{"id":"1.195453754","rc":[{"atb":[[6.4,24.81],[6.2,0]],"id":522747}],"con":true,"img":false}]}
{"op":"mcm","clk":"5348205970","pt":1646215433284,"mc":[{"id":"1.195453754","rc":[{"atl":[[130,0]],"id":522755},{"atl":[[210,0]],"id":3805772}],"con":true,"img":false}]}
{"op":"mcm","clk":"5348205998","pt":1646215433602,"mc":[{"id":"1.195453754","rc":[{"atl":[[790,4.16]],"id":3805799}],"con":true,"img":false}]}
{"op":"mcm","clk":"5348206037","pt":1646215434072,"mc":[{"id":"1.195453754","rc":[{"atl":[[36,9.48]],"id":522752}],"con":true,"img":false}]}
{"op":"mcm","clk":"5348206101","pt":1646215434905,"mc":[{"id":"1.195453754","rc":[{"atl":[[44,9.9]],"id":522752}],"con":true,"img":false}]}
{"op":"mcm","clk":"5348206162","pt":1646215435694,"mc":[{"id":"1.195453754","rc":[{"atl":[[890,3.92]],"id":522754}],"con":true,"img":false}]}
{"op":"mcm","clk":"5348206208","pt":1646215436214,"mc":[{"id":"1.195453754","rc":[{"atl":[[590,4.92],[250,0]],"id":522745}],"con":true,"img":false}]}
{"op":"mcm","clk":"5348206214","pt":1646215436315,"mc":[{"id":"1.195453754","rc":[{"atl":[[990,0],[1000,3.72]],"id":522751}],"con":true,"img":false}]}
{"op":"mcm","clk":"5348206274","pt":1646215437003,"mc":[{"id":"1.195453754","rc":[{"atl":[[1000,2]],"id":522751},{"atl":[[150,0],[160,20.72]],"id":522755}],"con":true,"img":false}]}
{"op":"mcm","clk":"5348206302","pt":1646215437316,"mc":[{"id":"1.195453754","rc":[{"atl":[[12,4.95],[12.5,13.78],[14,9.9],[14.5,0]],"id":522746}],"con":true,"img":false}]}
{"op":"mcm","clk":"5348206311","pt":1646215437418,"mc":[{"id":"1.195453754","rc":[{"atl":[[330,0],[340,5.42]],"id":522754},{"atl":[[130,0],[140,9.9],[95,1.68],[100,4.95]],"id":522750}],"con":true,"img":false}]}
{"op":"mcm","clk":"5348206321","pt":1646215437521,"mc":[{"id":"1.195453754","rc":[{"atl":[[95,0]],"id":522750}],"con":true,"img":false}]}
{"op":"mcm","clk":"5348206331","pt":1646215437577,"mc":[{"id":"1.195453754","rc":[{"atl":[[890,1.92],[500,2]],"id":522754}],"con":true,"img":false}]}
{"op":"mcm","clk":"5348206347","pt":1646215437786,"mc":[{"id":"1.195453754","rc":[{"atl":[[12,19.36],[14,45.13]],"id":522746},{"atl":[[140,22.28]],"id":522750}],"con":true,"img":false}]}
{"op":"mcm","clk":"5348206354","pt":1646215437888,"mc":[{"id":"1.195453754","rc":[{"atl":[[890,0]],"id":522754},{"atl":[[22,0]],"id":522746}],"con":true,"img":false}]}
{"op":"mcm","clk":"5348206360","pt":1646215437997,"mc":[{"id":"1.195453754","rc":[{"atl":[[890,2],[500,0]],"id":522754},{"atl":[[180,2]],"id":522750}],"con":true,"img":false}]}
{"op":"mcm","clk":"5348206371","pt":1646215438102,"mc":[{"id":"1.195453754","rc":[{"atb":[[19,0],[23,0]],"id":522748}],"con":true,"img":false}]}
{"op":"mcm","clk":"5348206392","pt":1646215438309,"mc":[{"id":"1.195453754","rc":[{"atl":[[170,0.93]],"id":522750}],"con":true,"img":false}]}
{"op":"mcm","clk":"5348206411","pt":1646215438514,"mc":[{"id":"1.195453754","rc":[{"atl":[[38,4.28]],"id":522748},{"atl":[[300,2],[220,7.88]],"id":3805772}],"con":true,"img":false}]}
{"op":"mcm","clk":"5348206420","pt":1646215438616,"mc":[{"id":"1.195453754","rc":[{"atl":[[12.5,0]],"id":522746},{"atl":[[140,9.9]],"id":522750}],"con":true,"img":false}]}
{"op":"mcm","clk":"5348206443","pt":1646215438824,"mc":[{"id":"1.195453754","rc":[{"atb":[[18.5,3.26],[22,2.72]],"id":522748}],"con":true,"img":false}]}
{"op":"mcm","clk":"5348206455","pt":1646215438881,"mc":[{"id":"1.195453754","rc":[{"atl":[[130,9.9],[140,0],[95,4.95],[100,0]],"id":522750}],"con":true,"img":false}]}
{"op":"mcm","clk":"5348206465","pt":1646215438988,"mc":[{"id":"1.195453754","rc":[{"atb":[[17,8.32]],"id":522748}],"con":true,"img":false}]}
{"op":"mcm","clk":"5348206493","pt":1646215439402,"mc":[{"id":"1.195453754","rc":[{"atl":[[38,0],[42,0]],"id":522748}],"con":true,"img":false}]}
{"op":"mcm","clk":"5348206578","pt":1646215440392,"mc":[{"id":"1.195453754","rc":[{"atl":[[46,3.52]],"id":522748}],"con":true,"img":false}]}
{"op":"mcm","clk":"5348206624","pt":1646215441015,"mc":[{"id":"1.195453754","rc":[{"atl":[[65,2],[48,22.49]],"id":522748}],"con":true,"img":false}]}
{"op":"mcm","clk":"5348206747","pt":1646215442533,"mc":[{"id":"1.195453754","rc":[{"atl":[[590,2]],"id":522745},{"atl":[[12,0],[12.5,4.95],[14,35.22],[14.5,9.9]],"id":522746}],"con":true,"img":false}]}
{"op":"mcm","clk":"5348206754","pt":1646215442585,"mc":[{"id":"1.195453754","rc":[{"atl":[[990,1.75]],"id":522751},{"atl":[[250,6.97]],"id":522745}],"con":true,"img":false}]}
{"op":"mcm","clk":"5348206763","pt":1646215442690,"mc":[{"id":"1.195453754","rc":[{"atl":[[140,9.9],[100,4.95]],"id":522750}],"con":true,"img":false}]}
{"op":"mcm","clk":"5348206770","pt":1646215442795,"mc":[{"id":"1.195453754","rc":[{"atl":[[130,0],[95,0]],"id":522750}],"con":true,"img":false}]}
{"op":"mcm","clk":"5348206778","pt":1646215442900,"mc":[{"id":"1.195453754","rc":[{"atl":[[290,8.01],[160,9.9]],"id":522755}],"con":true,"img":false}]}
{"op":"mcm","clk":"5348206813","pt":1646215443325,"mc":[{"id":"1.195453754","rc":[{"atl":[[13.5,12.68]],"id":522746}],"con":true,"img":false}]}
{"op":"mcm","clk":"5348206850","pt":1646215443734,"mc":[{"id":"1.195453754","rc":[{"atl":[[14.5,71.27]],"id":522746}],"con":true,"img":false}]}
{"op":"mcm","clk":"5348206857","pt":1646215443838,"mc":[{"id":"1.195453754","rc":[{"atl":[[360,4.85]],"id":522754},{"atl":[[14,0]],"id":522746}],"con":true,"img":false}]}
{"op":"mcm","clk":"5348206865","pt":1646215443942,"mc":[{"id":"1.195453754","rc":[{"atb":[[3.6,7.67],[3.35,63.04],[3.4,9.9],[3.55,14.71]],"id":522749},{"atl":[[36,4.95],[38,4.28],[44,9.9],[46,0]],"id":3805762}],"con":true,"img":false}]}
{"op":"mcm","clk":"5348206872","pt":1646215443999,"mc":[{"id":"1.195453754","rc":[{"atl":[[890,0],[500,2]],"id":522754}],"con":true,"img":false}]}
{"op":"mcm","clk":"5348206889","pt":1646215444307,"mc":[{"id":"1.195453754","rc":[{"atb":[[3.4,46.5]],"id":522749}],"con":true,"img":false}]}
{"op":"mcm","clk":"5348206898","pt":1646215444408,"mc":[{"id":"1.195453754","rc":[{"atb":[[3.35,3.26]],"id":522749},{"atb":[[17,20.91],[8.8,34.15]],"id":522748},{"atl":[[70,2],[36,9.48],[44,31.99]],"id":3805762},{"atl":[[300,7.83]],"id":3805772}],"con":true,"img":false}]}
{"op":"mcm","clk":"5348206908","pt":1646215444511,"mc":[{"id":"1.195453754","rc":[{"atl":[[220,0]],"id":3805772}],"con":true,"img":false}]}
{"op":"mcm","clk":"5348206926","pt":1646215444747,"mc":[{"id":"1.195453754","rc":[{"atb":[[3.6,44.27]],"id":522749}],"con":true,"img":false}]}
{"op":"mcm","clk":"5348206967","pt":1646215445121,"mc":[{"id":"1.195453754","rc":[{"atl":[[300,2]],"id":3805772}],"con":true,"img":false}]}
{"op":"mcm","clk":"5348206985","pt":1646215445325,"mc":[{"id":"1.195453754","rc":[{"atl":[[38,0]],"id":3805762}],"con":true,"img":false}]}
{"op":"mcm","clk":"5348206990","pt":1646215445430,"mc":[{"id":"1.195453754","rc":[{"atb":[[3.55,0]],"id":522749}],"con":true,"img":false}]}
{"op":"mcm","clk":"5348207144","pt":1646215447212,"mc":[{"id":"1.195453754","rc":[{"atl":[[590,0],[650,2]],"id":522745}],"con":true,"img":false}]}
{"op":"mcm","clk":"5348207240","pt":1646215448529,"mc":[{"id":"1.195453754","rc":[{"atl":[[990,0],[1000,3.75]],"id":522751},{"atl":[[650,4.7],[250,0]],"id":522745}],"con":true,"img":false}]}
{"op":"mcm","clk":"5348207341","pt":1646215449716,"mc":[{"id":"1.195453754","rc":[{"atl":[[360,0],[500,5.52]],"id":522754},{"atl":[[75,9.9],[80,0],[55,4.95],[60,2.68]],"id":3805747},{"atl":[[36,0],[38,4.95],[44,0],[46,9.9]],"id":522752}],"con":true,"img":false}]}
{"op":"mcm","clk":"5348207367","pt":1646215450027,"mc":[{"id":"1.195453754","rc":[{"atl":[[12.5,18.74]],"id":522746},{"atl":[[170,11.33]],"id":522750}],"con":true,"img":false}]}
{"op":"mcm","clk":"5348207387","pt":1646215450234,"mc":[{"id":"1.195453754","rc":[{"atb":[[3.35,117.16],[3.4,9.9]],"id":522749},{"atl":[[75,31.99],[85,0],[55,7.89]],"id":3805747}],"con":true,"img":false}]}
{"op":"mcm","clk":"5348207397","pt":1646215450338,"mc":[{"id":"1.195453754","rc":[{"atl":[[70,27.26],[44,9.9]],"id":3805762}],"con":true,"img":false}]}
{"op":"mcm","clk":"5348207404","pt":1646215450417,"mc":[{"id":"1.195453754","rc":[{"atl":[[500,2]],"id":522754},{"atl":[[44,3.68]],"id":522752}],"con":true,"img":false}]}
{"op":"mcm","clk":"5348207409","pt":1646215450495,"mc":[{"id":"1.195453754","rc":[{"atl":[[160,0.99]],"id":522750}],"con":true,"img":false}]}
{"op":"mcm","clk":"5348207416","pt":1646215450601,"mc":[{"id":"1.195453754","rc":[{"atl":[[38,4.28]],"id":522748},{"atl":[[220,8.03]],"id":3805772}],"con":true,"img":false}]}
{"op":"mcm","clk":"5348207433","pt":1646215450810,"mc":[{"id":"1.195453754","rc":[{"atl":[[13.5,0]],"id":522746}],"con":true,"img":false}]}
{"op":"mcm","clk":"5348207441","pt":1646215450916,"mc":[{"id":"1.195453754","rc":[{"atl":[[70,2],[46,31.54]],"id":522752}],"con":true,"img":false}]}
{"op":"mcm","clk":"5348207451","pt":1646215451032,"mc":[{"id":"1.195453754","rc":[{"atl":[[60,0]],"id":3805747}],"con":true,"img":false}]}
{"op":"mcm","clk":"5348207473","pt":1646215451340,"mc":[{"id":"1.195453754","rc":[{"atl":[[28,66.96],[14.5,9.9]],"id":522746},{"atl":[[170,10.39]],"id":522750}],"con":true,"img":false}]}
{"op":"mcm","clk":"5348207482","pt":1646215451446,"mc":[{"id":"1.195453754","rc":[{"atl":[[46,0]],"id":522748}],"con":true,"img":false}]}
{"op":"mcm","clk":"5348207609","pt":1646215452908,"mc":[{"id":"1.195453754","rc":[{"atl":[[75,22.08],[80,9.9],[55,0],[60,4.95]],"id":3805747}],"con":true,"img":false}]}
{"op":"mcm","clk":"5348207675","pt":1646215453637,"mc":[{"id":"1.195453754","rc":[{"atl":[[70,2.29]],"id":3805747}],"con":true,"img":false}]}
{"op":"mcm","clk":"5348207778","pt":1646215454732,"mc":[{"id":"1.195453754","rc":[{"atl":[[990,1.78],[1000,2]],"id":522751},{"atl":[[650,2],[250,7.11]],"id":522745}],"con":true,"img":false}]}
{"op":"mcm","clk":"5348207882","pt":1646215455935,"mc":[{"id":"1.195453754","rc":[{"atl":[[360,4.94]],"id":522754}],"con":true,"img":false}]}
{"op":"mcm","clk":"5348207915","pt":1646215456412,"mc":[{"id":"1.195453754","rc":[{"atl":[[300,7.94],[220,0]],"id":3805772}],"con":true,"img":false}]}
{"op":"mcm","clk":"5348207965","pt":1646215457048,"mc":[{"id":"1.195453754","rc":[{"atl":[[8.2,0],[7.8,14.71]],"id":3805740}],"con":true,"img":false}]}
{"op":"mcm","clk":"5348207976","pt":1646215457156,"mc":[{"id":"1.195453754","rc":[{"atl":[[300,2]],"id":3805772}],"con":true,"img":false}]}
{"op":"mcm","clk":"5348208289","pt":1646215460535,"mc":[{"id":"1.195453754","rc":[{"atl":[[990,0],[1000,3.78]],"id":522751},{"atl":[[650,4.75],[250,0]],"id":522745}],"con":true,"img":false}]}
{"op":"mcm","clk":"5348208372","pt":1646215461626,"mc":[{"id":"1.195453754","rc":[{"atl":[[500,5.59]],"id":522754}],"con":true,"img":false}]}
{"op":"mcm","clk":"5348208383","pt":1646215461735,"mc":[{"id":"1.195453754","rc":[{"atl":[[360,0]],"id":522754}],"con":true,"img":false}]}
{"op":"mcm","clk":"5348208403","pt":1646215462044,"mc":[{"id":"1.195453754","rc":[{"atl":[[160,12.25],[170,0]],"id":522750}],"con":true,"img":false}]}
{"op":"mcm","clk":"5348208419","pt":1646215462247,"mc":[{"id":"1.195453754","rc":[{"atl":[[60,7.64]],"id":3805747}],"con":true,"img":false}]}
{"op":"mcm","clk":"5348208426","pt":1646215462354,"mc":[{"id":"1.195453754","rc":[{"atl":[[500,2]],"id":522754},{"atl":[[38,9.23]],"id":522752}],"con":true,"img":false}]}
{"op":"mcm","clk":"5348208442","pt":1646215462523,"mc":[{"id":"1.195453754","rc":[{"atl":[[95,1.68]],"id":522750},{"atl":[[220,8.08]],"id":3805772}],"con":true,"img":false}]}
{"op":"mcm","clk":"5348208478","pt":1646215463042,"mc":[{"id":"1.195453754","rc":[{"atl":[[70,0]],"id":3805747}],"con":true,"img":false}]}
{"op":"mcm","clk":"5348208487","pt":1646215463142,"mc":[{"id":"1.195453754","rc":[{"atl":[[44,0]],"id":522752}],"con":true,"img":false}]}
{"op":"mcm","clk":"5348208507","pt":1646215463348,"mc":[{"id":"1.195453754","rc":[{"atl":[[160,11.25]],"id":522750}],"con":true,"img":false}]}
{"op":"mcm","clk":"5348208517","pt":1646215463454,"mc":[{"id":"1.195453754","rc":[{"atb":[[3.6,2.72],[3.35,127.07],[3.4,0],[3.55,4.95]],"id":522749},{"atl":[[38,0]],"id":522748},{"atl":[[260,0.61],[270,4.95]],"id":3805731}],"con":true,"img":false}]}
{"op":"mcm","clk":"5348208525","pt":1646215463506,"mc":[{"id":"1.195453754","rc":[{"atl":[[75,0],[80,32.48]],"id":3805747}],"con":true,"img":false}]}
{"op":"mcm","clk":"5348208534","pt":1646215463612,"mc":[{"id":"1.195453754","rc":[{"atl":[[70,27.79],[46,9.9]],"id":522752}],"con":true,"img":false}]}
{"op":"mcm","clk":"5348208563","pt":1646215463937,"mc":[{"id":"1.195453754","rc":[{"atl":[[65,14.21],[48,9.9]],"id":522748},{"atl":[[720,4.5]],"id":3805731}],"con":true,"img":false}]}
{"op":"mcm","clk":"5348208584","pt":1646215464137,"mc":[{"id":"1.195453754","rc":[{"atb":[[3.55,19.66]],"id":522749},{"atl":[[46,3.52]],"id":522748}],"con":true,"img":false}]}
{"op":"mcm","clk":"5348208768","pt":1646215466525,"mc":[{"id":"1.195453754","rc":[{"atl":[[990,1.82]],"id":522751},{"atl":[[250,7.24]],"id":522745}],"con":true,"img":false}]}
{"op":"mcm","clk":"5348208775","pt":1646215466633,"mc":[{"id":"1.195453754","rc":[{"atl":[[1000,2]],"id":522751},{"atl":[[650,2]],"id":522745}],"con":true,"img":false}]}
{"op":"mcm","clk":"5348208830","pt":1646215467364,"mc":[{"id":"1.195453754","rc":[{"atl":[[990,0]],"id":522751},{"atl":[[250,0]],"id":522745}],"con":true,"img":false}]}
{"op":"mcm","clk":"5348208901","pt":1646215468153,"mc":[{"id":"1.195453754","rc":[{"atl":[[220,0]],"id":3805772}],"con":true,"img":false}]}
{"op":"mcm","clk":"5348208912","pt":1646215468257,"mc":[{"id":"1.195453754","rc":[{"atl":[[300,8.05]],"id":3805772}],"con":true,"img":false}]}
{"op":"mcm","clk":"5348209013","pt":1646215469253,"mc":[{"id":"1.195453754","rc":[{"atl":[[80,9.9],[100,20.21]],"id":3805747}],"con":true,"img":false}]}
{"op":"mcm","clk":"5348209221","pt":1646215471648,"mc":[{"id":"1.195453754","rc":[{"atl":[[6.2,0],[7,22.08],[6.6,9.9],[5.9,4.95]],"id":3805740}],"con":true,"img":false}]}
{"op":"mcm","clk":"5348209259","pt":1646215472173,"mc":[{"id":"1.195453754","rc":[{"atl":[[5.8,33.03],[6.6,57.46],[7,0]],"id":3805740}],"con":true,"img":false}]}
{"op":"mcm","clk":"5348209267","pt":1646215472228,"mc":[{"id":"1.195453754","rc":[{"atl":[[990,1.84]],"id":522751},{"atl":[[250,7.31]],"id":522745}],"con":true,"img":false}]}
{"op":"mcm","clk":"5348209337","pt":1646215472949,"mc":[{"id":"1.195453754","rc":[{"atl":[[6,0]],"id":3805740}],"con":true,"img":false}]}
{"op":"mcm","clk":"5348209366","pt":1646215473263,"mc":[{"id":"1.195453754","rc":[{"atl":[[36,4.52],[44,0]],"id":3805762}],"con":true,"img":false}]}
{"op":"mcm","clk":"5348209374","pt":1646215473317,"mc":[{"id":"1.195453754","rc":[{"atl":[[36,0],[38,4.95],[46,9.9]],"id":3805762}],"con":true,"img":false}]}
{"op":"mcm","clk":"5348209412","pt":1646215473839,"mc":[{"id":"1.195453754","rc":[{"atl":[[140,23],[160,0]],"id":522750},{"atl":[[70,2],[40,34.27]],"id":3805762}],"con":true,"img":false}]}
{"op":"mcm","clk":"5348209439","pt":1646215474147,"mc":[{"id":"1.195453754","rc":[{"atl":[[65,2.47]],"id":3805762}],"con":true,"img":false}]}
{"op":"mcm","clk":"5348209448","pt":1646215474255,"mc":[{"id":"1.195453754","rc":[{"atl":[[300,2],[220,8.33]],"id":3805772}],"con":true,"img":false}]}
{"op":"mcm","clk":"5348209519","pt":1646215474930,"mc":[{"id":"1.195453754","rc":[{"atl":[[220,0]],"id":3805772}],"con":true,"img":false}]}
{"op":"mcm","clk":"5348209576","pt":1646215475658,"mc":[{"id":"1.195453754","rc":[{"atl":[[65,2],[48,22.49]],"id":522748}],"con":true,"img":false}]}
{"op":"mcm","clk":"5348209598","pt":1646215475918,"mc":[{"id":"1.195453754","rc":[{"atl":[[40,9.01]],"id":522748}],"con":true,"img":false}]}
{"op":"mcm","clk":"5348209656","pt":1646215476746,"mc":[{"id":"1.195453754","rc":[{"atl":[[46,0]],"id":522748}],"con":true,"img":false}]}
{"op":"mcm","clk":"5348209751","pt":1646215477847,"mc":[{"id":"1.195453754","rc":[{"atl":[[990,0],[1000,3.83]],"id":522751},{"atl":[[650,4.83],[250,0]],"id":522745}],"con":true,"img":false}]}
{"op":"mcm","clk":"5348209804","pt":1646215478620,"mc":[{"id":"1.195453754","rc":[{"atl":[[1000,2]],"id":522751},{"atl":[[720,2.5],[780,2]],"id":3805731}],"con":true,"img":false}]}
{"op":"mcm","clk":"5348209830","pt":1646215478931,"mc":[{"id":"1.195453754","rc":[{"atb":[[36,20.19],[44,3.68]],"id":522755},{"atb":[[17.5,14.56],[17,0],[15,0],[15.5,9.9]],"id":522752}],"con":true,"img":false}]}
{"op":"mcm","clk":"5348209838","pt":1646215479036,"mc":[{"id":"1.195453754","rc":[{"atl":[[9.6,4.95],[10,0],[11,9.9],[12,41.51]],"id":522747},{"atb":[[38,9.9],[46,4.95]],"id":522755}],"con":true,"img":false}]}
{"op":"mcm","clk":"5348209859","pt":1646215479349,"mc":[{"id":"1.195453754","rc":[{"atb":[[16,2.72],[15.5,46.28]],"id":522752}],"con":true,"img":false}]}
{"op":"mcm","clk":"5348209867","pt":1646215479452,"mc":[{"id":"1.195453754","rc":[{"atl":[[11,51.41],[12,0],[9.4,18.87]],"id":522747},{"atb":[[36,0],[42,19.41],[48,3.37]],"id":522755},{"atl":[[40,0],[46,41.77]],"id":3805762}],"con":true,"img":false}]}
{"op":"mcm","clk":"5348209912","pt":1646215479972,"mc":[{"id":"1.195453754","rc":[{"atl":[[220,8.08]],"id":3805772}],"con":true,"img":false}]}
{"op":"mcm","clk":"5348209944","pt":1646215480338,"mc":[{"id":"1.195453754","rc":[{"atl":[[9.8,0]],"id":522747},{"atb":[[44,0]],"id":522755}],"con":true,"img":false}]}
{"op":"mcm","clk":"5348210021","pt":1646215481231,"mc":[{"id":"1.195453754","rc":[{"atl":[[65,20.26]],"id":522748}],"con":true,"img":false}]}
{"op":"mcm","clk":"5348210030","pt":1646215481387,"mc":[{"id":"1.195453754","rc":[{"atl":[[48,9.9]],"id":522748}],"con":true,"img":false}]}
{"op":"mcm","clk":"5348210189","pt":1646215483470,"mc":[{"id":"1.195453754","rc":[{"atl":[[190,4.95],[200,0.79]],"id":3805772}],"con":true,"img":false}]}
{"op":"mcm","clk":"5348210216","pt":1646215483733,"mc":[{"id":"1.195453754","rc":[{"atl":[[330,4.95],[340,0.46],[360,5.16]],"id":522754},{"atb":[[3.6,63.7]],"id":522749},{"atl":[[990,1.87]],"id":522751},{"atl":[[650,2],[250,7.44]],"id":522745}],"con":true,"img":false}]}
{"op":"mcm","clk":"5348210242","pt":1646215484046,"mc":[{"id":"1.195453754","rc":[{"atl":[[36,4.95],[38,4.28],[44,9.9],[46,0]],"id":522752},{"atl":[[190,5.79]],"id":3805772}],"con":true,"img":false}]}
{"op":"mcm","clk":"5348210258","pt":1646215484254,"mc":[{"id":"1.195453754","rc":[{"atl":[[330,5.43]],"id":522754}],"con":true,"img":false}]}
{"op":"mcm","clk":"5348210276","pt":1646215484566,"mc":[{"id":"1.195453754","rc":[{"atb":[[3.55,4.95]],"id":522749},{"atl":[[70,2],[36,9.48],[44,31.99]],"id":522752}],"con":true,"img":false}]}
{"op":"mcm","clk":"5348210311","pt":1646215484988,"mc":[{"id":"1.195453754","rc":[{"atl":[[65,26.97]],"id":3805762},{"atl":[[200,0]],"id":3805772}],"con":true,"img":false}]}
{"op":"mcm","clk":"5348210321","pt":1646215485043,"mc":[{"id":"1.195453754","rc":[{"atl":[[340,0]],"id":522754},{"atl":[[46,9.9]],"id":3805762}],"con":true,"img":false}]}
{"op":"mcm","clk":"5348210341","pt":1646215485247,"mc":[{"id":"1.195453754","rc":[{"atl":[[38,0]],"id":522752}],"con":true,"img":false}]}
{"op":"mcm","clk":"5348210364","pt":1646215485560,"mc":[{"id":"1.195453754","rc":[{"atl":[[38,9.23]],"id":3805762},{"atl":[[300,8.21],[220,0]],"id":3805772}],"con":true,"img":false}]}
{"op":"mcm","clk":"5348210422","pt":1646215486338,"mc":[{"id":"1.195453754","rc":[{"atl":[[65,24.49]],"id":3805762}],"con":true,"img":false}]}
{"op":"mcm","clk":"5348210436","pt":1646215486548,"mc":[{"id":"1.195453754","rc":[{"atl":[[150,9.9],[160,0],[110,4.95],[120,1.32]],"id":522755},{"atl":[[36,4.95],[40,4.06],[44,9.9],[48,0]],"id":522748}],"con":true,"img":false}]}
{"op":"mcm","clk":"5348210442","pt":1646215486651,"mc":[{"id":"1.195453754","rc":[{"atl":[[260,5.56],[270,0]],"id":3805731}],"con":true,"img":false}]}
{"op":"mcm","clk":"5348210449","pt":1646215486755,"mc":[{"id":"1.195453754","rc":[{"atb":[[18.5,0],[22,0]],"id":522748}],"con":true,"img":false}]}
{"op":"mcm","clk":"5348210472","pt":1646215487064,"mc":[{"id":"1.195453754","rc":[{"atl":[[150,22.38],[110,6.4]],"id":522755}],"con":true,"img":false}]}
{"op":"mcm","clk":"5348210481","pt":1646215487167,"mc":[{"id":"1.195453754","rc":[{"atl":[[290,2]],"id":522755},{"atb":[[17,18.23],[8.8,56.24]],"id":522748},{"atl":[[65,2],[44,23.31]],"id":522748},{"atl":[[720,0],[780,4.39]],"id":3805731}],"con":true,"img":false}]}
{"op":"mcm","clk":"5348210493","pt":1646215487374,"mc":[{"id":"1.195453754","rc":[{"atl":[[36,9.48]],"id":522748}],"con":true,"img":false}]}
{"op":"mcm","clk":"5348210504","pt":1646215487429,"mc":[{"id":"1.195453754","rc":[{"atl":[[150,12.47],[160,9.9],[110,1.45],[120,6.28]],"id":522755},{"atb":[[17,21.5],[19.5,2.72]],"id":522748}],"con":true,"img":false}]}
{"op":"mcm","clk":"5348210543","pt":1646215487946,"mc":[{"id":"1.195453754","rc":[{"atl":[[110,0],[120,4.95]],"id":522755},{"atb":[[17,11.59]],"id":522748}],"con":true,"img":false}]}
{"op":"mcm","clk":"5348210548","pt":1646215488050,"mc":[{"id":"1.195453754","rc":[{"atl":[[40,0]],"id":522748},{"atl":[[780,2]],"id":3805731}],"con":true,"img":false}]}
{"op":"mcm","clk":"5348210584","pt":1646215488461,"mc":[{"id":"1.195453754","rc":[{"atl":[[12,4.95],[12.5,13.78],[14,9.9],[14.5,0]],"id":522746}],"con":true,"img":false}]}
{"op":"mcm","clk":"5348210605","pt":1646215488772,"mc":[{"id":"1.195453754","rc":[{"atl":[[140,1.13]],"id":522755}],"con":true,"img":false}]}
{"op":"mcm","clk":"5348210627","pt":1646215489031,"mc":[{"id":"1.195453754","rc":[{"atl":[[14,45.13],[28,3.7]],"id":522746}],"con":true,"img":false}]}
{"op":"mcm","clk":"5348210635","pt":1646215489137,"mc":[{"id":"1.195453754","rc":[{"atl":[[12,19.36]],"id":522746}],"con":true,"img":false}]}
{"op":"mcm","clk":"5348210643","pt":1646215489249,"mc":[{"id":"1.195453754","rc":[{"atl":[[360,0],[500,5.74]],"id":522754},{"atl":[[250,0]],"id":522745}],"con":true,"img":false}]}
{"op":"mcm","clk":"5348210660","pt":1646215489450,"mc":[{"id":"1.195453754","rc":[{"atl":[[1000,3.86]],"id":522751},{"atl":[[650,4.88]],"id":522745}],"con":true,"img":false}]}
{"op":"mcm","clk":"5348210667","pt":1646215489554,"mc":[{"id":"1.195453754","rc":[{"atl":[[660,2.59],[720,2]],"id":3805785},{"atl":[[990,0]],"id":522751}],"con":true,"img":false}]}
{"op":"mcm","clk":"5348210690","pt":1646215489866,"mc":[{"id":"1.195453754","rc":[{"atl":[[260,4.95],[240,0]],"id":3805785},{"atl":[[230,0.69],[250,4.95]],"id":522745},{"atl":[[12.5,0]],"id":522746}],"con":true,"img":false}]}
{"op":"mcm","clk":"5348210710","pt":1646215490075,"mc":[{"id":"1.195453754","rc":[{"atl":[[36,0],[38,4.95],[44,13.4],[46,9.9]],"id":522748},{"atl":[[130,9.9],[140,13.1],[95,6.63],[100,0]],"id":522750},{"atl":[[70,28.87],[44,9.9]],"id":522752}],"con":true,"img":false}]}
{"op":"mcm","clk":"5348210721","pt":1646215490177,"mc":[{"id":"1.195453754","rc":[{"atl":[[1000,2]],"id":522751}],"con":true,"img":false}]}
{"op":"mcm","clk":"5348210773","pt":1646215490812,"mc":[{"id":"1.195453754","rc":[{"atl":[[42,3.86]],"id":522748}],"con":true,"img":false}]}
{"op":"mcm","clk":"5348210780","pt":1646215490854,"mc":[{"id":"1.195453754","rc":[{"atl":[[260,0.61],[270,4.95]],"id":3805731}],"con":true,"img":false}]}
{"op":"mcm","clk":"5348210806","pt":1646215491176,"mc":[{"id":"1.195453754","rc":[{"atl":[[500,2]],"id":522754},{"atl":[[38,0],[40,4.95],[46,0],[48,9.9]],"id":522748}],"con":true,"img":false}]}
{"op":"mcm","clk":"5348210821","pt":1646215491380,"mc":[{"id":"1.195453754","rc":[{"atl":[[300,2],[210,8.96]],"id":3805772}],"con":true,"img":false}]}
{"op":"mcm","clk":"5348210843","pt":1646215491639,"mc":[{"id":"1.195453754","rc":[{"atl":[[270,0],[280,4.95]],"id":3805731}],"con":true,"img":false}]}
{"op":"mcm","clk":"5348211083","pt":1646215494546,"mc":[{"id":"1.195453754","rc":[{"atl":[[14,9.9],[28,71.33]],"id":522746}],"con":true,"img":false}]}
{"op":"mcm","clk":"5348211090","pt":1646215494650,"mc":[{"id":"1.195453754","rc":[{"atb":[[3.45,9.9],[3.65,4.95]],"id":522749},{"atl":[[38,4.28],[46,0]],"id":3805762}],"con":true,"img":false}]}
{"op":"mcm","clk":"5348211102","pt":1646215494755,"mc":[{"id":"1.195453754","rc":[{"atb":[[3.35,117.16],[3.55,0]],"id":522749},{"atl":[[36,4.95],[44,9.9]],"id":3805762}],"con":true,"img":false}]}
{"op":"mcm","clk":"5348211135","pt":1646215495171,"mc":[{"id":"1.195453754","rc":[{"atb":[[3.35,3.26],[3.55,55.45],[3.65,60.4]],"id":522749},{"atl":[[990,1.9]],"id":522751},{"atl":[[65,0],[70,26.49]],"id":3805762}],"con":true,"img":false}]}
{"op":"mcm","clk":"5348211194","pt":1646215495955,"mc":[{"id":"1.195453754","rc":[{"atb":[[3.6,2.72]],"id":522749}],"con":true,"img":false}]}
{"op":"mcm","clk":"5348211214","pt":1646215496267,"mc":[{"id":"1.195453754","rc":[{"atl":[[70,2],[44,31.99]],"id":3805762}],"con":true,"img":false}]}
{"op":"mcm","clk":"5348211259","pt":1646215496783,"mc":[{"id":"1.195453754","rc":[{"atl":[[36,9.48]],"id":3805762},{"atl":[[300,8.32]],"id":3805772}],"con":true,"img":false}]}
{"op":"mcm","clk":"5348211268","pt":1646215496884,"mc":[{"id":"1.195453754","rc":[{"atl":[[210,0]],"id":3805772}],"con":true,"img":false}]}
{"op":"mcm","clk":"5348211328","pt":1646215497563,"mc":[{"id":"1.195453754","rc":[{"atl":[[38,0]],"id":3805762},{"atl":[[300,2]],"id":3805772}],"con":true,"img":false}]}
{"op":"mcm","clk":"5348211344","pt":1646215497768,"mc":[{"id":"1.195453754","rc":[{"atb":[[21,0],[26,0]],"id":522750}],"con":true,"img":false}]}
{"op":"mcm","clk":"5348211352","pt":1646215497871,"mc":[{"id":"1.195453754","rc":[{"atb":[[6.4,22.08],[5.7,0]],"id":522747},{"atb":[[80,0],[55,0]],"id":3805763},{"atb":[[65,0],[46,0]],"id":522743},{"atl":[[36,4.52],[38,4.95],[44,22.08],[46,9.9]],"id":3805762}],"con":true,"img":false}]}
{"op":"mcm","clk":"5348211359","pt":1646215497973,"mc":[{"id":"1.195453754","rc":[{"atl":[[36,0]],"id":3805762}],"con":true,"img":false}]}
{"op":"mcm","clk":"5348211384","pt":1646215498287,"mc":[{"id":"1.195453754","rc":[{"atl":[[120,6.28]],"id":522755},{"atl":[[780,4.43]],"id":3805731}],"con":true,"img":false}]}
{"op":"mcm","clk":"5348211393","pt":1646215498390,"mc":[{"id":"1.195453754","rc":[{"atb":[[16,19.66],[8.8,34.15]],"id":522748}],"con":true,"img":false}]}
{"op":"mcm","clk":"5348211400","pt":1646215498501,"mc":[{"id":"1.195453754","rc":[{"atb":[[22,3.26],[27,37.23]],"id":522750}],"con":true,"img":false}]}
{"op":"mcm","clk":"5348211411","pt":1646215498550,"mc":[{"id":"1.195453754","rc":[{"atb":[[85,2.72],[60,3.26]],"id":3805763},{"atb":[[70,2.72],[48,3.26]],"id":522743},{"atl":[[40,9.01]],"id":522748}],"con":true,"img":false}]}
{"op":"mcm","clk":"5348211426","pt":1646215498756,"mc":[{"id":"1.195453754","rc":[{"atb":[[5.8,3.26],[6.6,7.67]],"id":522747},{"atl":[[42,3.86]],"id":3805762}],"con":true,"img":false}]}
{"op":"mcm","clk":"5348211455","pt":1646215499068,"mc":[{"id":"1.195453754","rc":[{"atl":[[140,0]],"id":522755}],"con":true,"img":false}]}
{"op":"mcm","clk":"5348211479","pt":1646215499379,"mc":[{"id":"1.195453754","rc":[{"atl":[[42,0]],"id":522748}],"con":true,"img":false}]}
{"op":"mcm","clk":"5348211490","pt":1646215499582,"mc":[{"id":"1.195453754","rc":[{"atl":[[150,0],[160,21.82]],"id":522755}],"con":true,"img":false}]}
{"op":"mcm","clk":"5348211508","pt":1646215499847,"mc":[{"id":"1.195453754","rc":[{"atl":[[44,0],[48,41.87]],"id":522748}],"con":true,"img":false}]}
{"op":"mcm","clk":"5348211530","pt":1646215500263,"mc":[{"id":"1.195453754","rc":[{"atl":[[75,9.9],[80,0],[55,4.95],[60,2.68]],"id":3805747}],"con":true,"img":false}]}
{"op":"mcm","clk":"5348211557","pt":1646215500674,"mc":[{"id":"1.195453754","rc":[{"atl":[[990,0],[1000,3.9]],"id":522751}],"con":true,"img":false}]}
{"op":"mcm","clk":"5348211562","pt":1646215500778,"mc":[{"id":"1.195453754","rc":[{"atl":[[75,31.99],[100,2],[55,7.89]],"id":3805747}],"con":true,"img":false}]}
{"op":"mcm","clk":"5348211608","pt":1646215501413,"mc":[{"id":"1.195453754","rc":[{"atl":[[1000,2]],"id":522751}],"con":true,"img":false}]}
{"op":"mcm","clk":"5348211616","pt":1646215501516,"mc":[{"id":"1.195453754","rc":[{"atl":[[330,4.95]],"id":522754},{"atl":[[60,0]],"id":3805747},{"atl":[[120,4.95]],"id":522755},{"atl":[[190,4.95],[200,4.95]],"id":3805772}],"con":true,"img":false}]}
{"op":"mcm","clk":"5348211625","pt":1646215501575,"mc":[{"id":"1.195453754","rc":[{"atl":[[330,0],[350,4.95]],"id":522754},{"atl":[[130,4.95],[160,11.91],[170,9.9],[120,0]],"id":522755},{"atl":[[190,0]],"id":3805772}],"con":true,"img":false}]}
{"op":"mcm","clk":"5348211651","pt":1646215501881,"mc":[{"id":"1.195453754","rc":[{"atl":[[17.5,6.06],[14.5,0]],"id":522749},{"atb":[[9,0],[7.8,14.71]],"id":522753},{"atb":[[19.5,0],[13,8.33]],"id":522743},{"atb":[[18.5,5.71],[15,0]],"id":522745},{"atb":[[34,0],[50,2.04]],"id":3805799},{"atb":[[8,0]],"id":3805762}],"con":true,"img":false}]}
{"op":"mcm","clk":"5348211658","pt":1646215501985,"mc":[{"id":"1.195453754","rc":[{"atb":[[9.8,11.36]],"id":3805762}],"con":true,"img":false}]}
{"op":"mcm","clk":"5348211663","pt":1646215502087,"mc":[{"id":"1.195453754","rc":[{"atl":[[370,5.16]],"id":522754}],"con":true,"img":false}]}
{"op":"mcm","clk":"5348211669","pt":1646215502194,"mc":[{"id":"1.195453754","rc":[{"atl":[[340,0.46]],"id":522754}],"con":true,"img":false}]}
{"op":"mcm","clk":"5348211673","pt":1646215502295,"mc":[{"id":"1.195453754","rc":[{"atl":[[130,6.18]],"id":522755},{"atl":[[190,0.83],[200,0]],"id":3805772}],"con":true,"img":false}]}
{"op":"mcm","clk":"5348211687","pt":1646215502455,"mc":[{"id":"1.195453754","rc":[{"atl":[[220,8.08]],"id":3805772}],"con":true,"img":false}]}
{"op":"mcm","clk":"5348211725","pt":1646215502976,"mc":[{"id":"1.195453754","rc":[{"atl":[[190,5.79]],"id":3805772}],"con":true,"img":false}]}
{"op":"mcm","clk":"5348211898","pt":1646215504861,"mc":[{"id":"1.195453754","rc":[{"atl":[[160,0],[170,21.21]],"id":522755}],"con":true,"img":false}]}
{"op":"mcm","clk":"5348211944","pt":1646215505277,"mc":[{"id":"1.195453754","rc":[{"atl":[[65,31.59],[48,9.9]],"id":522748}],"con":true,"img":false}]}
{"op":"mcm","clk":"5348212019","pt":1646215506164,"mc":[{"id":"1.195453754","rc":[{"atl":[[75,9.9],[100,21.25]],"id":3805747}],"con":true,"img":false}]}
{"op":"mcm","clk":"5348212029","pt":1646215506269,"mc":[{"id":"1.195453754","rc":[{"atl":[[990,1.93]],"id":522751}],"con":true,"img":false}]}
{"op":"mcm","clk":"5348212160","pt":1646215507780,"mc":[{"id":"1.195453754","rc":[{"atl":[[38,9.23]],"id":3805762},{"atl":[[300,8.43],[220,0]],"id":3805772}],"con":true,"img":false}]}
