{"op":"mcm","clk":"5345904397","pt":1646079078742,"mc":[{"id":"1.195395451","marketDefinition":{"bspMarket":true,"turnInPlayEnabled":false,"persistenceEnabled":false,"marketBaseRate":5.0,"eventId":"31270459","eventTypeId":"4339","numberOfWinners":1,"bettingType":"ODDS","marketType":"WIN","marketTime":"2022-03-01T01:25:00.000Z","suspendTime":"2022-03-01T01:25:00.000Z","bspReconciled":false,"complete":true,"inPlay":false,"crossMatching":false,"runnersVoidable":false,"numberOfActiveRunners":8,"betDelay":0,"status":"OPEN","runners":[{"status":"ACTIVE","sortPriority":1,"id":40251221,"name":"1. Elsa Blueblood"},{"status":"ACTIVE","sortPriority":2,"id":42492389,"name":"3. Emilys Perfect"},{"status":"ACTIVE","sortPriority":3,"id":43154431,"name":"4. Lonely Gemma"},{"status":"ACTIVE","sortPriority":4,"id":39979879,"name":"5. Goldstar Smiles"},{"status":"ACTIVE","sortPriority":5,"id":27151693,"name":"6. Hustle Ace"},{"status":"ACTIVE","sortPriority":6,"id":41921674,"name":"7. Sozins Queen"},{"status":"ACTIVE","sortPriority":7,"id":36899924,"name":"8. Horse Range Gold"},{"status":"ACTIVE","sortPriority":8,"id":39722911,"name":"9. Know Pops"}],"regulators":["MR_INT"],"venue":"Addington","countryCode":"NZ","discountAllowed":false,"timezone":"NZ","openDate":"2022-02-28T23:02:00.000Z","version":4380660687,"name":"R9 295m C2","eventName":"Addington (NZL) 1st Mar"},"rc":[],"con":true,"img":false}]}
{"op":"mcm","clk":"5345904621","pt":1646079080740,"mc":[{"id":"1.195395451","marketDefinition":{"bspMarket":true,"turnInPlayEnabled":false,"persistenceEnabled":false,"marketBaseRate":5.0,"eventId":"31270459","eventTypeId":"4339","numberOfWinners":1,"bettingType":"ODDS","marketType":"WIN","marketTime":"2022-03-01T01:25:00.000Z","suspendTime":"2022-03-01T01:25:00.000Z","bspReconciled":false,"complete":true,"inPlay":false,"crossMatching":false,"runnersVoidable":false,"numberOfActiveRunners":8,"betDelay":0,"status":"OPEN","runners":[{"status":"ACTIVE","sortPriority":1,"id":40251221,"name":"1. Elsa Blueblood"},{"status":"ACTIVE","sortPriority":2,"id":42492389,"name":"3. Emilys Perfect"},{"status":"ACTIVE","sortPriority":3,"id":43154431,"name":"4. Lonely Gemma"},{"status":"ACTIVE","sortPriority":4,"id":39979879,"name":"5. Goldstar Smiles"},{"status":"ACTIVE","sortPriority":5,"id":27151693,"name":"6. Hustle Ace"},{"status":"ACTIVE","sortPriority":6,"id":41921674,"name":"7. Sozins Queen"},{"status":"ACTIVE","sortPriority":7,"id":36899924,"name":"8. Horse Range Gold"},{"status":"ACTIVE","sortPriority":8,"id":39722911,"name":"9. Know Pops"}],"regulators":["MR_INT"],"venue":"Addington","countryCode":"NZ","discountAllowed":true,"timezone":"NZ","openDate":"2022-02-28T23:02:00.000Z","version":4380660687,"name":"R9 295m C2","eventName":"Addington (NZL) 1st Mar"},"rc":[],"con":true,"img":false}]}
{"op":"mcm","clk":"5346140304","pt":1646081718873,"mc":[{"id":"1.195395451","rc":[{"atb":[[8,17.39],[9,10.14],[10,4.5],[6,32.47]],"id":41921674},{"atl":[[75,1.78],[150,1.33],[50,2.7],[100,2]],"id":41921674},{"spn":30.0,"spf":"NaN","id":41921674},{"atb":[[16,2.7],[11,12.17],[13.5,6.49],[8.4,21.94]],"id":36899924},{"atl":[[260,0.76],[160,0.83],[210,0.94],[110,1.21]],"id":36899924},{"spn":63.0,"spf":"NaN","id":36899924},{"atb":[[18,2.38],[9.2,19.8],[13,10.14],[15.5,5.59]],"id":40251221},{"atl":[[130,1.02],[280,0.7],[180,0.74],[230,0.86]],"id":40251221},{"spn":74.0,"spf":"NaN","id":40251221},{"atb":[[7.2,26.19],[9.2,14.85],[10.5,8.54],[13,3.38]],"id":39979879},{"atl":[[80,1.67],[160,1.25],[210,0.94],[110,1.21]],"id":39979879},{"spn":46.5,"spf":"NaN","id":39979879},{"atb":[[17,2.53],[12,11.06],[8.8,20.81],[14.5,6.01]],"id":39722911},{"atl":[[270,0.73],[170,0.78],[220,0.9],[120,1.1]],"id":39722911},{"spn":68.5,"spf":"NaN","id":39722911},{"atb":[[1.01,16239.03],[1.15,270.65],[1.1,811.95],[1.05,2435.85]],"id":42492389},{"atl":[[2.24,106.69],[2.44,137.8],[2.14,116.04],[2.34,148.08]],"id":42492389},{"spn":1.64,"spf":"NaN","id":42492389},{"atb":[[18,4.77],[21,2.02],[10.5,17.09],[15.5,8.4]],"id":27151693},{"atl":[[150,0.88],[300,0.66],[200,0.66],[250,0.79]],"id":27151693},{"spn":85.5,"spf":"NaN","id":27151693},{"atb":[[17,2.53],[12,11.06],[8.8,20.81],[14.5,6.01]],"id":43154431},{"atl":[[270,0.73],[170,0.78],[220,0.9],[120,1.1]],"id":43154431},{"spn":68.5,"spf":"NaN","id":43154431}],"con":true,"img":false}]}
{"op":"mcm","clk":"5346143128","pt":1646081761493,"mc":[{"id":"1.195395451","rc":[{"atb":[[8,0],[9,0],[10,0],[6,0]],"id":41921674},{"atl":[[75,0],[150,0],[50,0],[100,0]],"id":41921674},{"atb":[[16,0],[11,0],[13.5,0],[8.4,0]],"id":36899924},{"atl":[[260,0],[160,0],[210,0],[110,0]],"id":36899924},{"atb":[[18,0],[9.2,0],[13,0],[15.5,0]],"id":40251221},{"atl":[[130,0],[280,0],[180,0],[230,0]],"id":40251221},{"atb":[[7.2,0],[9.2,0],[10.5,0],[13,0]],"id":39979879},{"atl":[[80,0],[160,0],[210,0],[110,0]],"id":39979879},{"atb":[[17,0],[12,0],[8.8,0],[14.5,0]],"id":39722911},{"atl":[[270,0],[170,0],[220,0],[120,0]],"id":39722911},{"atb":[[1.01,0],[1.15,0],[1.1,0],[1.05,0]],"id":42492389},{"atl":[[2.24,0],[2.44,0],[2.14,0],[2.34,0]],"id":42492389},{"atb":[[18,0],[21,0],[10.5,0],[15.5,0]],"id":27151693},{"atl":[[150,0],[300,0],[200,0],[250,0]],"id":27151693},{"atb":[[17,0],[12,0],[8.8,0],[14.5,0]],"id":43154431},{"atl":[[270,0],[170,0],[220,0],[120,0]],"id":43154431}],"con":true,"img":false}]}
{"op":"mcm","clk":"5346143339","pt":1646081763933,"mc":[{"id":"1.195395451","rc":[{"atb":[[8,17.39],[9,10.14],[10,4.5],[6,32.47]],"id":41921674},{"atl":[[75,1.78],[150,1.33],[50,2.7],[100,2]],"id":41921674},{"atb":[[16,2.7],[11,12.17],[13.5,6.49],[8.4,21.94]],"id":36899924},{"atl":[[260,0.76],[160,0.83],[210,0.94],[110,1.21]],"id":36899924},{"atb":[[18,2.38],[9.2,19.8],[13,10.14],[15.5,5.59]],"id":40251221},{"atl":[[130,1.02],[280,0.7],[180,0.74],[230,0.86]],"id":40251221},{"atb":[[7.2,26.19],[9.2,14.85],[10.5,8.54],[13,3.38]],"id":39979879},{"atl":[[80,1.67],[160,1.25],[210,0.94],[110,1.21]],"id":39979879},{"atb":[[17,2.53],[12,11.06],[8.8,20.81],[14.5,6.01]],"id":39722911},{"atl":[[270,0.73],[170,0.78],[220,0.9],[120,1.1]],"id":39722911},{"atb":[[1.01,16239.03],[1.15,270.65],[1.1,811.95],[1.05,2435.85]],"id":42492389},{"atl":[[2.24,106.69],[2.44,137.8],[2.14,116.04],[2.34,148.08]],"id":42492389},{"atb":[[18,4.77],[21,2.02],[10.5,17.09],[15.5,8.4]],"id":27151693},{"atl":[[150,0.88],[300,0.66],[200,0.66],[250,0.79]],"id":27151693},{"atb":[[17,2.53],[12,11.06],[8.8,20.81],[14.5,6.01]],"id":43154431},{"atl":[[270,0.73],[170,0.78],[220,0.9],[120,1.1]],"id":43154431}],"con":true,"img":false}]}
{"op":"mcm","clk":"5346183390","pt":1646082292654,"mc":[{"id":"1.195395451","rc":[{"atb":[[8,0],[9,0],[10,0],[6,0]],"id":41921674},{"atl":[[75,0],[150,0],[50,0],[100,0]],"id":41921674},{"spn":"NaN","spf":"NaN","id":41921674},{"atb":[[16,0],[11,0],[13.5,0],[8.4,0]],"id":36899924},{"atl":[[260,0],[160,0],[210,0],[110,0]],"id":36899924},{"spn":"NaN","spf":"NaN","id":36899924},{"atb":[[18,0],[9.2,0],[13,0],[15.5,0]],"id":40251221},{"atl":[[130,0],[280,0],[180,0],[230,0]],"id":40251221},{"spn":"NaN","spf":"NaN","id":40251221},{"atb":[[7.2,0],[9.2,0],[10.5,0],[13,0]],"id":39979879},{"atl":[[80,0],[160,0],[210,0],[110,0]],"id":39979879},{"spn":"NaN","spf":"NaN","id":39979879},{"atb":[[17,0],[12,0],[8.8,0],[14.5,0]],"id":39722911},{"atl":[[270,0],[170,0],[220,0],[120,0]],"id":39722911},{"spn":"NaN","spf":"NaN","id":39722911},{"atb":[[1.01,0],[1.15,0],[1.1,0],[1.05,0]],"id":42492389},{"atl":[[2.24,0],[2.44,0],[2.14,0],[2.34,0]],"id":42492389},{"spn":"NaN","spf":"NaN","id":42492389},{"atb":[[18,0],[21,0],[10.5,0],[15.5,0]],"id":27151693},{"atl":[[150,0],[300,0],[200,0],[250,0]],"id":27151693},{"spn":"NaN","spf":"NaN","id":27151693},{"atb":[[17,0],[12,0],[8.8,0],[14.5,0]],"id":43154431},{"atl":[[270,0],[170,0],[220,0],[120,0]],"id":43154431},{"spn":"NaN","spf":"NaN","id":43154431}],"con":true,"img":false}]}
{"op":"mcm","clk":"5346184036","pt":1646082300481,"mc":[{"id":"1.195395451","rc":[{"atb":[[8,17.39],[9,10.14],[10,4.5],[6,32.47]],"id":41921674},{"atl":[[75,1.78],[150,1.33],[50,2.7],[100,2]],"id":41921674},{"atb":[[16,2.7],[11,12.17],[13.5,6.49],[8.4,21.94]],"id":36899924},{"atl":[[260,0.76],[160,0.83],[210,0.94],[110,1.21]],"id":36899924},{"atb":[[16.5,5.23],[9.6,18.88],[19,2.25],[14,9.36]],"id":40251221},{"atl":[[140,0.95],[290,0.68],[190,0.69],[240,0.82]],"id":40251221},{"atb":[[7.2,26.19],[9.2,14.85],[10.5,8.54],[13,3.38]],"id":39979879},{"atl":[[80,1.67],[160,1.25],[210,0.94],[110,1.21]],"id":39979879},{"atb":[[17,2.53],[12,11.06],[8.8,20.81],[14.5,6.01]],"id":39722911},{"atl":[[270,0.73],[170,0.78],[220,0.9],[120,1.1]],"id":39722911},{"atb":[[18,4.77],[21,2.02],[10.5,17.09],[15.5,8.4]],"id":27151693},{"atl":[[150,0.88],[300,0.66],[200,0.66],[250,0.79]],"id":27151693},{"atb":[[1.18,225.54],[1.01,16239.03],[1.13,624.58],[1.08,1522.4]],"id":42492389},{"atl":[[2.4,141.74],[2.3,101.76],[2.5,132.29],[2.2,110.24]],"id":42492389},{"atb":[[18,2.38],[9.2,19.8],[13,10.14],[15.5,5.59]],"id":43154431},{"atl":[[130,1.02],[280,0.7],[180,0.74],[230,0.86]],"id":43154431}],"con":true,"img":false}]}
{"op":"mcm","clk":"5346201580","pt":1646082500923,"mc":[{"id":"1.195395451","rc":[{"spn":30.0,"spf":"NaN","id":41921674},{"atb":[[16,0],[11,0],[13.5,0],[8.4,0]],"id":36899924},{"atl":[[260,0],[160,0],[210,0],[110,0]],"id":36899924},{"atb":[[16.5,0],[9.6,0],[19,0],[14,0]],"id":40251221},{"atl":[[140,0],[290,0],[190,0],[240,0]],"id":40251221},{"atb":[[7.2,0],[9.2,0],[10.5,0],[13,0]],"id":39979879},{"atl":[[80,0],[160,0],[210,0],[110,0]],"id":39979879},{"atb":[[17,0],[12,0],[8.8,0],[14.5,0]],"id":39722911},{"atl":[[270,0],[170,0],[220,0],[120,0]],"id":39722911},{"spn":85.5,"spf":"NaN","id":27151693},{"spn":1.69,"spf":"NaN","id":42492389},{"spn":74.0,"spf":"NaN","id":43154431}],"con":true,"img":false}]}
{"op":"mcm","clk":"5346201925","pt":1646082504526,"mc":[{"id":"1.195395451","rc":[{"atb":[[17,2.53],[12,11.06],[8.8,20.81],[14.5,6.01]],"id":36899924},{"atl":[[270,0.73],[170,0.78],[220,0.9],[120,1.1]],"id":36899924},{"atb":[[16,2.7],[11,12.17],[13.5,6.49],[8.4,21.94]],"id":40251221},{"atl":[[260,0.76],[160,0.83],[210,0.94],[110,1.21]],"id":40251221},{"atb":[[9.6,14.16],[11.5,7.73],[7.6,24.6],[14,3.12]],"id":39979879},{"atl":[[130,1.02],[90,1.48],[180,1.1],[230,0.86]],"id":39979879},{"atb":[[17,2.53],[12,11.06],[8.8,20.81],[14.5,6.01]],"id":39722911},{"atl":[[270,0.73],[170,0.78],[220,0.9],[120,1.1]],"id":39722911}],"con":true,"img":false}]}
{"op":"mcm","clk":"5346223589","pt":1646082745859,"mc":[{"id":"1.195395451","rc":[{"atb":[[8,0],[9,0],[10,0],[6,0]],"id":41921674},{"atl":[[75,0],[150,0],[50,0],[100,0]],"id":41921674},{"spn":"NaN","spf":"NaN","id":41921674},{"atb":[[17,0],[12,0],[8.8,0],[14.5,0]],"id":36899924},{"atl":[[270,0],[170,0],[220,0],[120,0]],"id":36899924},{"atb":[[16,0],[11,0],[13.5,0],[8.4,0]],"id":40251221},{"atl":[[260,0],[160,0],[210,0],[110,0]],"id":40251221},{"atb":[[9.6,0],[11.5,0],[7.6,0],[14,0]],"id":39979879},{"atl":[[130,0],[90,0],[180,0],[230,0]],"id":39979879},{"atb":[[17,0],[12,0],[8.8,0],[14.5,0]],"id":39722911},{"atl":[[270,0],[170,0],[220,0],[120,0]],"id":39722911},{"atb":[[18,0],[21,0],[10.5,0],[15.5,0]],"id":27151693},{"atl":[[150,0],[300,0],[200,0],[250,0]],"id":27151693},{"spn":"NaN","spf":"NaN","id":27151693},{"atb":[[1.18,0],[1.01,0],[1.13,0],[1.08,0]],"id":42492389},{"atl":[[2.4,0],[2.3,0],[2.5,0],[2.2,0]],"id":42492389},{"spn":"NaN","spf":"NaN","id":42492389},{"atb":[[18,0],[9.2,0],[13,0],[15.5,0]],"id":43154431},{"atl":[[130,0],[280,0],[180,0],[230,0]],"id":43154431},{"spn":"NaN","spf":"NaN","id":43154431}],"con":true,"img":false}]}
{"op":"mcm","clk":"5346226100","pt":1646082775428,"mc":[{"id":"1.195395451","rc":[{"atb":[[8,17.39],[9,10.14],[10,4.5],[6,32.47]],"id":41921674},{"atl":[[75,1.78],[150,1.33],[50,2.7],[100,2]],"id":41921674},{"atb":[[16,2.7],[11,12.17],[13.5,6.49],[8.4,21.94]],"id":36899924},{"atl":[[260,0.76],[160,0.83],[210,0.94],[110,1.21]],"id":36899924},{"atb":[[8,23.2],[10,13.53],[12.5,7.05],[15,2.9]],"id":40251221},{"atl":[[150,0.88],[100,1.33],[200,0.99],[250,0.79]],"id":40251221},{"atb":[[7.2,26.19],[9.2,14.85],[10.5,8.54],[13,3.38]],"id":39979879},{"atl":[[80,1.67],[160,1.25],[210,0.94],[110,1.21]],"id":39979879},{"atb":[[17,2.53],[12,11.06],[8.8,20.81],[14.5,6.01]],"id":39722911},{"atl":[[270,0.73],[170,0.78],[220,0.9],[120,1.1]],"id":39722911},{"atb":[[18,4.77],[21,2.02],[10.5,17.09],[15.5,8.4]],"id":27151693},{"atl":[[150,0.88],[300,0.66],[200,0.66],[250,0.79]],"id":27151693},{"atb":[[1.01,16239.03],[1.15,270.65],[1.1,811.95],[1.05,2435.85]],"id":42492389},{"atl":[[2.24,106.69],[2.44,137.8],[2.14,116.04],[2.34,148.08]],"id":42492389},{"atb":[[18,2.38],[9.2,19.8],[13,10.14],[15.5,5.59]],"id":43154431},{"atl":[[130,1.02],[280,0.7],[180,0.74],[230,0.86]],"id":43154431}],"con":true,"img":false}]}
{"op":"mcm","clk":"5346252987","pt":1646083002680,"mc":[{"id":"1.195395451","marketDefinition":{"bspMarket":true,"turnInPlayEnabled":false,"persistenceEnabled":false,"marketBaseRate":5.0,"eventId":"31270459","eventTypeId":"4339","numberOfWinners":1,"bettingType":"ODDS","marketType":"WIN","marketTime":"2022-03-01T01:25:00.000Z","suspendTime":"2022-03-01T01:25:00.000Z","bspReconciled":false,"complete":true,"inPlay":false,"crossMatching":false,"runnersVoidable":false,"numberOfActiveRunners":8,"betDelay":0,"status":"OPEN","runners":[{"status":"ACTIVE","sortPriority":1,"id":40251221,"name":"1. Elsa Blueblood"},{"status":"ACTIVE","sortPriority":2,"id":42492389,"name":"3. Emilys Perfect"},{"status":"ACTIVE","sortPriority":3,"id":43154431,"name":"4. Lonely Gemma"},{"status":"ACTIVE","sortPriority":4,"id":39979879,"name":"5. Goldstar Smiles"},{"status":"ACTIVE","sortPriority":5,"id":27151693,"name":"6. Hustle Ace"},{"status":"ACTIVE","sortPriority":6,"id":41921674,"name":"7. Sozins Queen"},{"status":"ACTIVE","sortPriority":7,"id":36899924,"name":"8. Horse Range Gold"},{"status":"ACTIVE","sortPriority":8,"id":39722911,"name":"9. Know Pops"}],"regulators":["MR_INT"],"venue":"Addington","countryCode":"NZ","discountAllowed":true,"timezone":"NZ","openDate":"2022-02-28T23:02:00.000Z","version":4380660687,"name":"R9 295m C2","eventName":"Addington (NZL) 1st Mar"},"rc":[{"atb":[[8,17.39],[9,10.14],[10,4.5],[6,32.47]],"id":41921674},{"atl":[[75,1.78],[150,1.33],[50,2.7],[100,2]],"id":41921674},{"spn":30.0,"spf":"NaN","id":41921674},{"atb":[[16,2.7],[11,12.17],[13.5,6.49],[8.4,21.94]],"id":36899924},{"atl":[[260,0.76],[160,0.83],[210,0.94],[110,1.21]],"id":36899924},{"spn":63.0,"spf":"NaN","id":36899924},{"atb":[[8,23.2],[10,13.53],[12.5,7.05],[15,2.9]],"id":40251221},{"atl":[[150,0.88],[100,1.33],[200,0.99],[250,0.79]],"id":40251221},{"spn":57.5,"spf":"NaN","id":40251221},{"atb":[[7.2,26.19],[9.2,14.85],[10.5,8.54],[13,3.38]],"id":39979879},{"atl":[[80,1.67],[160,1.25],[210,0.94],[110,1.21]],"id":39979879},{"spn":46.5,"spf":"NaN","id":39979879},{"atb":[[17,2.53],[12,11.06],[8.8,20.81],[14.5,6.01]],"id":39722911},{"atl":[[270,0.73],[170,0.78],[220,0.9],[120,1.1]],"id":39722911},{"spn":68.5,"spf":"NaN","id":39722911},{"atb":[[1.01,16239.03],[1.15,270.65],[1.1,811.95],[1.05,2435.85]],"id":42492389},{"atl":[[2.24,106.69],[2.44,137.8],[2.14,116.04],[2.34,148.08]],"id":42492389},{"spn":1.64,"spf":"NaN","id":42492389},{"atb":[[18,4.77],[21,2.02],[10.5,17.09],[15.5,8.4]],"id":27151693},{"atl":[[150,0.88],[300,0.66],[200,0.66],[250,0.79]],"id":27151693},{"spn":85.5,"spf":"NaN","id":27151693},{"atb":[[18,2.38],[9.2,19.8],[13,10.14],[15.5,5.59]],"id":43154431},{"atl":[[130,1.02],[280,0.7],[180,0.74],[230,0.86]],"id":43154431},{"spn":74.0,"spf":"NaN","id":43154431}],"con":true,"img":true}]}
{"op":"mcm","clk":"5346420860","pt":1646085920165,"mc":[{"id":"1.195395451","rc":[{"atb":[[8,17.39],[9,10.14],[10,4.5],[6,32.47]],"id":41921674},{"atl":[[75,1.78],[150,1.33],[50,2.7],[100,2]],"id":41921674},{"spn":30.0,"spf":"NaN","id":41921674},{"atb":[[16,2.7],[11,12.17],[13.5,6.49],[8.4,21.94]],"id":36899924},{"atl":[[260,0.76],[160,0.83],[210,0.94],[110,1.21]],"id":36899924},{"spn":63.0,"spf":"NaN","id":36899924},{"atb":[[8,23.19],[10,13.53],[12.5,7.05],[15,2.9]],"id":40251221},{"atl":[[150,0.88],[100,1.33],[200,0.99],[250,0.79]],"id":40251221},{"spn":57.5,"spf":"NaN","id":40251221},{"atb":[[7.2,26.18],[9.2,14.85],[10.5,8.54],[13,3.38]],"id":39979879},{"atl":[[80,1.67],[160,1.25],[210,0.94],[110,1.21]],"id":39979879},{"spn":46.5,"spf":"NaN","id":39979879},{"atb":[[17,2.53],[12,11.06],[8.8,20.81],[14.5,6.01]],"id":39722911},{"atl":[[270,0.73],[170,0.78],[220,0.9],[120,1.1]],"id":39722911},{"spn":68.5,"spf":"NaN","id":39722911},{"atb":[[1.01,16236.4],[1.15,270.6],[1.1,811.82],[1.05,2435.46]],"id":42492389},{"atl":[[2.24,106.67],[1.79,35.72],[2.44,137.78],[2.14,116.03],[2.34,148.06]],"id":42492389},{"spn":1.47,"spf":"NaN","id":42492389},{"atb":[[18,4.77],[21,2.02],[10.5,17.09],[15.5,8.39]],"id":27151693},{"atl":[[150,0.88],[300,0.66],[200,0.66],[250,0.79]],"id":27151693},{"spn":85.5,"spf":"NaN","id":27151693},{"atb":[[18,2.38],[9.2,19.8],[13,10.14],[15.5,5.59]],"id":43154431},{"atl":[[130,1.02],[280,0.7],[180,0.74],[230,0.86]],"id":43154431},{"spn":74.0,"spf":"NaN","id":43154431}],"con":true,"img":false}]}
{"op":"mcm","clk":"5346427235","pt":1646086102107,"mc":[{"id":"1.195395451","rc":[{"atb":[[8,0],[9,0],[10,0],[6,0]],"id":41921674},{"atl":[[75,0],[150,0],[50,0],[100,0]],"id":41921674},{"spn":"NaN","spf":"NaN","id":41921674},{"atb":[[16,0],[11,0],[13.5,0],[8.4,0]],"id":36899924},{"atl":[[260,0],[160,0],[210,0],[110,0]],"id":36899924},{"spn":"NaN","spf":"NaN","id":36899924},{"atb":[[8,0],[10,0],[12.5,0],[15,0]],"id":40251221},{"atl":[[150,0],[100,0],[200,0],[250,0]],"id":40251221},{"spn":"NaN","spf":"NaN","id":40251221},{"atb":[[7.2,0],[9.2,0],[10.5,0],[13,0]],"id":39979879},{"atl":[[80,0],[160,0],[210,0],[110,0]],"id":39979879},{"spn":"NaN","spf":"NaN","id":39979879}],"con":true,"img":false}]}
{"op":"mcm","clk":"5346427444","pt":1646086108526,"mc":[{"id":"1.195395451","rc":[{"atb":[[8,17.39],[9,10.14],[10,4.5],[6,32.47]],"id":41921674},{"atl":[[75,1.78],[150,1.33],[50,2.7],[100,2]],"id":41921674},{"atb":[[16,2.7],[11,12.17],[13.5,6.49],[8.4,21.94]],"id":36899924},{"atl":[[260,0.76],[160,0.83],[210,0.94],[110,1.21]],"id":36899924},{"atb":[[8,23.19],[10,13.53],[12.5,7.05],[15,2.9]],"id":40251221},{"atl":[[150,0.88],[100,1.33],[200,0.99],[250,0.79]],"id":40251221},{"atb":[[7.2,26.18],[9.2,14.85],[10.5,8.54],[13,3.38]],"id":39979879},{"atl":[[80,1.67],[160,1.25],[210,0.94],[110,1.21]],"id":39979879}],"con":true,"img":false}]}
{"op":"mcm","clk":"5346492653","pt":1646088262065,"mc":[{"id":"1.195395451","rc":[{"spn":30.0,"spf":"NaN","id":41921674},{"atb":[[16,0],[11,0],[13.5,0],[8.4,0]],"id":36899924},{"atl":[[260,0],[160,0],[210,0],[110,0]],"id":36899924},{"spn":57.5,"spf":"NaN","id":40251221},{"spn":46.5,"spf":"NaN","id":39979879}],"con":true,"img":false}]}
{"op":"mcm","clk":"5346492782","pt":1646088266492,"mc":[{"id":"1.195395451","rc":[{"atb":[[17,2.53],[12,11.06],[8.8,20.81],[14.5,6.01]],"id":36899924},{"atl":[[270,0.73],[170,0.78],[220,0.9],[120,1.1]],"id":36899924}],"con":true,"img":false}]}
{"op":"mcm","clk":"5346502882","pt":1646088402669,"mc":[{"id":"1.195395451","marketDefinition":{"bspMarket":true,"turnInPlayEnabled":false,"persistenceEnabled":false,"marketBaseRate":5.0,"eventId":"31270459","eventTypeId":"4339","numberOfWinners":1,"bettingType":"ODDS","marketType":"WIN","marketTime":"2022-03-01T01:25:00.000Z","suspendTime":"2022-03-01T01:25:00.000Z","bspReconciled":false,"complete":true,"inPlay":false,"crossMatching":false,"runnersVoidable":false,"numberOfActiveRunners":8,"betDelay":0,"status":"OPEN","runners":[{"status":"ACTIVE","sortPriority":1,"id":40251221,"name":"1. Elsa Blueblood"},{"status":"ACTIVE","sortPriority":2,"id":42492389,"name":"3. Emilys Perfect"},{"status":"ACTIVE","sortPriority":3,"id":43154431,"name":"4. Lonely Gemma"},{"status":"ACTIVE","sortPriority":4,"id":39979879,"name":"5. Goldstar Smiles"},{"status":"ACTIVE","sortPriority":5,"id":27151693,"name":"6. Hustle Ace"},{"status":"ACTIVE","sortPriority":6,"id":41921674,"name":"7. Sozins Queen"},{"status":"ACTIVE","sortPriority":7,"id":36899924,"name":"8. Horse Range Gold"},{"status":"ACTIVE","sortPriority":8,"id":39722911,"name":"9. Know Pops"}],"regulators":["MR_INT"],"venue":"Addington","countryCode":"NZ","discountAllowed":true,"timezone":"NZ","openDate":"2022-02-28T23:02:00.000Z","version":4380660687,"name":"R9 295m C2","eventName":"Addington (NZL) 1st Mar"},"rc":[{"atb":[[8,17.39],[9,10.14],[10,4.5],[6,32.47]],"id":41921674},{"atl":[[75,1.78],[150,1.33],[50,2.7],[100,2]],"id":41921674},{"spn":30.0,"spf":"NaN","id":41921674},{"atb":[[17,2.53],[12,11.06],[8.8,20.81],[14.5,6.01]],"id":36899924},{"atl":[[270,0.73],[170,0.78],[220,0.9],[120,1.1]],"id":36899924},{"spn":68.5,"spf":"NaN","id":36899924},{"atb":[[8,23.19],[10,13.53],[12.5,7.05],[15,2.9]],"id":40251221},{"atl":[[150,0.88],[100,1.33],[200,0.99],[250,0.79]],"id":40251221},{"spn":57.5,"spf":"NaN","id":40251221},{"atb":[[7.2,26.18],[9.2,14.85],[10.5,8.54],[13,3.38]],"id":39979879},{"atl":[[80,1.67],[160,1.25],[210,0.94],[110,1.21]],"id":39979879},{"spn":46.5,"spf":"NaN","id":39979879},{"atb":[[17,2.53],[12,11.06],[8.8,20.81],[14.5,6.01]],"id":39722911},{"atl":[[270,0.73],[170,0.78],[220,0.9],[120,1.1]],"id":39722911},{"spn":68.5,"spf":"NaN","id":39722911},{"atb":[[1.01,16236.4],[1.15,270.6],[1.1,811.82],[1.05,2435.46]],"id":42492389},{"atl":[[2.24,106.67],[1.79,35.72],[2.44,137.78],[2.14,116.03],[2.34,148.06]],"id":42492389},{"spn":1.47,"spf":"NaN","id":42492389},{"atb":[[18,4.77],[21,2.02],[10.5,17.09],[15.5,8.39]],"id":27151693},{"atl":[[150,0.88],[300,0.66],[200,0.66],[250,0.79]],"id":27151693},{"spn":85.5,"spf":"NaN","id":27151693},{"atb":[[18,2.38],[9.2,19.8],[13,10.14],[15.5,5.59]],"id":43154431},{"atl":[[130,1.02],[280,0.7],[180,0.74],[230,0.86]],"id":43154431},{"spn":74.0,"spf":"NaN","id":43154431}],"con":true,"img":true}]}
{"op":"mcm","clk":"5346529673","pt":1646089281209,"mc":[{"id":"1.195395451","rc":[{"spl":[[100,2]],"id":41921674},{"spn":30.0,"spf":1.0,"id":41921674},{"spl":[[100,2]],"id":36899924},{"spn":58.5,"spf":1.0,"id":36899924},{"spl":[[100,2]],"id":40251221},{"spn":57.5,"spf":1.0,"id":40251221},{"spl":[[100,2]],"id":39979879},{"spn":46.5,"spf":1.0,"id":39979879},{"spl":[[100,2]],"id":39722911},{"spn":58.5,"spf":1.0,"id":39722911},{"spl":[[100,2]],"id":42492389},{"spn":1.47,"spf":1.0,"id":42492389},{"spl":[[100,2]],"id":27151693},{"spn":60.5,"spf":1.0,"id":27151693},{"spl":[[100,2]],"id":43154431},{"spn":59.0,"spf":1.0,"id":43154431}],"con":true,"img":false}]}
{"op":"mcm","clk":"5346563916","pt":1646090700170,"mc":[{"id":"1.195395451","rc":[{"atb":[[11,1.01]],"id":41921674},{"spn":30.5,"spf":1.0,"id":41921674},{"atb":[[17.5,0.62]],"id":36899924},{"spn":58.75,"spf":1.0,"id":36899924},{"atb":[[13.5,0.81]],"id":40251221},{"atb":[[12,0.92]],"id":39979879},{"atb":[[19.5,0.55]],"id":39722911},{"spn":59.75,"spf":1.0,"id":39722911},{"atb":[[1.18,2]],"id":42492389},{"spn":1.48,"spf":1.0,"id":42492389},{"atb":[[19.5,0.55]],"id":27151693},{"atb":[[21,0.51]],"id":43154431},{"spn":60.5,"spf":1.0,"id":43154431}],"con":true,"img":false}]}
{"op":"mcm","clk":"5346578998","pt":1646091195131,"mc":[{"id":"1.195395451","rc":[{"spl":[[1.01,10.82]],"id":42492389},{"spn":1.15,"spf":1.0,"id":42492389}],"con":true,"img":false}]}
{"op":"mcm","clk":"5346600192","pt":1646091931426,"mc":[{"id":"1.195395451","rc":[{"atb":[[1.18,0]],"id":42492389},{"spn":1.15,"spf":1.0,"id":42492389}],"con":true,"img":false}]}
{"op":"mcm","clk":"5346600194","pt":1646091931480,"mc":[{"id":"1.195395451","rc":[{"atb":[[1.19,2]],"id":42492389}],"con":true,"img":false}]}
{"op":"mcm","clk":"5346605866","pt":1646092115022,"mc":[{"id":"1.195395451","rc":[{"atl":[[2.1,7.8]],"id":42492389},{"spn":1.15,"spf":1.0,"id":42492389}],"con":true,"img":false}]}
{"op":"mcm","clk":"5346606589","pt":1646092137163,"mc":[{"id":"1.195395451","marketDefinition":{"bspMarket":true,"turnInPlayEnabled":false,"persistenceEnabled":false,"marketBaseRate":5.0,"eventId":"31270459","eventTypeId":"4339","numberOfWinners":1,"bettingType":"ODDS","marketType":"WIN","marketTime":"2022-03-01T01:25:00.000Z","suspendTime":"2022-03-01T01:25:00.000Z","bspReconciled":false,"complete":true,"inPlay":false,"crossMatching":true,"runnersVoidable":false,"numberOfActiveRunners":8,"betDelay":0,"status":"OPEN","runners":[{"status":"ACTIVE","sortPriority":1,"id":40251221,"name":"1. Elsa Blueblood"},{"status":"ACTIVE","sortPriority":2,"id":42492389,"name":"3. Emilys Perfect"},{"status":"ACTIVE","sortPriority":3,"id":43154431,"name":"4. Lonely Gemma"},{"status":"ACTIVE","sortPriority":4,"id":39979879,"name":"5. Goldstar Smiles"},{"status":"ACTIVE","sortPriority":5,"id":27151693,"name":"6. Hustle Ace"},{"status":"ACTIVE","sortPriority":6,"id":41921674,"name":"7. Sozins Queen"},{"status":"ACTIVE","sortPriority":7,"id":36899924,"name":"8. Horse Range Gold"},{"status":"ACTIVE","sortPriority":8,"id":39722911,"name":"9. Know Pops"}],"regulators":["MR_INT"],"venue":"Addington","countryCode":"NZ","discountAllowed":true,"timezone":"NZ","openDate":"2022-02-28T23:02:00.000Z","version":4380660687,"name":"R9 295m C2","eventName":"Addington (NZL) 1st Mar"},"rc":[],"con":true,"img":false}]}
{"op":"mcm","clk":"5346608645","pt":1646092193147,"mc":[{"id":"1.195395451","rc":[{"atl":[[2.1,16.55]],"id":42492389}],"con":true,"img":false}]}
{"op":"mcm","clk":"5346610370","pt":1646092232279,"mc":[{"id":"1.195395451","rc":[{"atl":[[2.1,8.75]],"id":42492389}],"con":true,"img":false}]}
{"op":"mcm","clk":"5346610491","pt":1646092235219,"mc":[{"id":"1.195395451","rc":[{"atl":[[2.1,16.55]],"id":42492389}],"con":true,"img":false}]}
{"op":"mcm","clk":"5346613517","pt":1646092313128,"mc":[{"id":"1.195395451","rc":[{"atl":[[2.1,7.8]],"id":42492389}],"con":true,"img":false}]}
{"op":"mcm","clk":"5346613725","pt":1646092319100,"mc":[{"id":"1.195395451","rc":[{"atl":[[2.1,16.55]],"id":42492389}],"con":true,"img":false}]}
{"op":"mcm","clk":"5346614840","pt":1646092352637,"mc":[{"id":"1.195395451","rc":[{"atl":[[2.1,8.75]],"id":42492389}],"con":true,"img":false}]}
{"op":"mcm","clk":"5346614958","pt":1646092355458,"mc":[{"id":"1.195395451","rc":[{"atl":[[2.1,16.55]],"id":42492389}],"con":true,"img":false}]}
{"op":"mcm","clk":"5346619279","pt":1646092472830,"mc":[{"id":"1.195395451","rc":[{"atl":[[2.1,8.75]],"id":42492389}],"con":true,"img":false}]}
{"op":"mcm","clk":"5346619377","pt":1646092475701,"mc":[{"id":"1.195395451","rc":[{"atl":[[2.1,16.55]],"id":42492389}],"con":true,"img":false}]}
{"op":"mcm","clk":"5346620343","pt":1646092509381,"mc":[{"id":"1.195395451","rc":[{"atb":[[5,18]],"id":41921674},{"atb":[[9,9]],"id":36899924},{"atb":[[8,33.48]],"id":40251221},{"atb":[[7,12]],"id":39979879},{"atb":[[9,9]],"id":39722911},{"atb":[[9.4,8.57]],"id":43154431}],"con":true,"img":false}]}
{"op":"mcm","clk":"5346620346","pt":1646092509484,"mc":[{"id":"1.195395451","rc":[{"atb":[[2.62,46.3]],"id":41921674},{"atb":[[2.62,46.3]],"id":36899924},{"atb":[[2.62,46.3],[4.2,26.56]],"id":40251221},{"atb":[[2.62,46.3],[4.2,26.56]],"id":39979879},{"atb":[[2.62,46.3],[4.2,26.56]],"id":39722911},{"atb":[[2.62,46.3],[4.2,26.56]],"id":27151693},{"atb":[[2.62,46.3],[4.2,26.56]],"id":43154431}],"con":true,"img":false}]}
{"op":"mcm","clk":"5346620352","pt":1646092509534,"mc":[{"id":"1.195395451","rc":[{"atb":[[4.2,26.56]],"id":36899924},{"atl":[[17,8.5],[34,13.5]],"id":42492389}],"con":true,"img":false}]}
{"op":"mcm","clk":"5346621297","pt":1646092538812,"mc":[{"id":"1.195395451","rc":[{"atb":[[9.2,13.13],[10.5,4.55]],"id":41921674},{"atl":[[48,5.41]],"id":41921674},{"spn":29.5,"spf":1.0,"id":41921674},{"atb":[[12.5,10.82],[15,3.09]],"id":36899924},{"atl":[[90,0.48],[180,2.7]],"id":36899924},{"spn":53.75,"spf":1.0,"id":36899924},{"atb":[[10.5,14.07],[11.5,4.12]],"id":40251221},{"atl":[[70,0.62],[140,2.7]],"id":40251221},{"spn":42.5,"spf":1.0,"id":40251221},{"atb":[[11,4.32],[9.4,14.07]],"id":39979879},{"atl":[[60,0.73],[120,2.7]],"id":39979879},{"spn":36.5,"spf":1.0,"id":39979879},{"atb":[[17.5,2.7],[15,8.23]],"id":39722911},{"atl":[[95,0.46],[190,2.7]],"id":39722911},{"spn":57.25,"spf":1.0,"id":39722911},{"atb":[[1.16,43.29],[1.11,1187.96]],"id":42492389},{"atl":[[1.78,43.29],[2.08,121.23]],"id":42492389},{"spn":1.16,"spf":1.0,"id":42492389},{"atb":[[16,7.1],[18.5,2.7]],"id":27151693},{"atl":[[110,0.39],[220,2.7]],"id":27151693},{"atb":[[16,7.73],[18.5,2.7]],"id":43154431},{"atl":[[210,2.7],[110,0.39]],"id":43154431}],"con":true,"img":false}]}
{"op":"mcm","clk":"5346622106","pt":1646092562416,"mc":[{"id":"1.195395451","rc":[{"atl":[[2.1,7.8]],"id":42492389}],"con":true,"img":false}]}
{"op":"mcm","clk":"5346622333","pt":1646092568420,"mc":[{"id":"1.195395451","rc":[{"atl":[[1.76,10.45]],"id":42492389}],"con":true,"img":false}]}
{"op":"mcm","clk":"5346623060","pt":1646092593068,"mc":[{"id":"1.195395451","rc":[{"atl":[[2.1,0]],"id":42492389}],"con":true,"img":false}]}
{"op":"mcm","clk":"5346623161","pt":1646092595987,"mc":[{"id":"1.195395451","rc":[{"atl":[[1.76,19.76]],"id":42492389}],"con":true,"img":false}]}
{"op":"mcm","clk":"5346624211","pt":1646092626531,"mc":[{"id":"1.195395451","rc":[{"atl":[[180,0]],"id":36899924},{"atl":[[140,0]],"id":40251221},{"atl":[[120,0]],"id":39979879},{"atl":[[190,0]],"id":39722911},{"atl":[[1.78,0],[2.08,0]],"id":42492389},{"atl":[[220,0]],"id":27151693},{"atl":[[210,0]],"id":43154431}],"con":true,"img":false}]}
{"op":"mcm","clk":"5346624215","pt":1646092626632,"mc":[{"id":"1.195395451","rc":[{"atl":[[110,2.7]],"id":36899924},{"atl":[[95,2.7]],"id":40251221},{"atl":[[75,2.7]],"id":39979879},{"atl":[[110,2.7]],"id":39722911},{"atl":[[2.12,121.23],[1.75,43.29]],"id":42492389},{"atl":[[140,2.7]],"id":27151693},{"atl":[[120,2.7]],"id":43154431}],"con":true,"img":false}]}
{"op":"mcm","clk":"5346626090","pt":1646092688672,"mc":[{"id":"1.195395451","rc":[{"atl":[[1.76,9.31]],"id":42492389}],"con":true,"img":false}]}
{"op":"mcm","clk":"5346626248","pt":1646092694618,"mc":[{"id":"1.195395451","rc":[{"atl":[[2.08,8.84]],"id":42492389}],"con":true,"img":false}]}
{"op":"mcm","clk":"5346626802","pt":1646092713235,"mc":[{"id":"1.195395451","rc":[{"atl":[[1.76,0]],"id":42492389}],"con":true,"img":false}]}
{"op":"mcm","clk":"5346626908","pt":1646092716103,"mc":[{"id":"1.195395451","rc":[{"atl":[[1.73,9.47]],"id":42492389}],"con":true,"img":false}]}
{"op":"mcm","clk":"5346628870","pt":1646092774475,"mc":[{"id":"1.195395451","rc":[{"atl":[[2.12,0]],"id":42492389}],"con":true,"img":false}]}
{"op":"mcm","clk":"5346628873","pt":1646092774578,"mc":[{"id":"1.195395451","rc":[{"atl":[[2.06,121.23]],"id":42492389}],"con":true,"img":false}]}
{"op":"mcm","clk":"5346629598","pt":1646092800600,"mc":[{"id":"1.195395451","rc":[{"atl":[[1.75,0]],"id":42492389}],"con":true,"img":false}]}
{"op":"mcm","clk":"5346629604","pt":1646092800706,"mc":[{"id":"1.195395451","rc":[{"atl":[[1.72,43.29]],"id":42492389}],"con":true,"img":false}]}
{"op":"mcm","clk":"5346630129","pt":1646092814937,"mc":[{"id":"1.195395451","rc":[{"atb":[[8,17.38],[9,10.14],[10,4.5],[9.2,13.12],[10.5,4.55],[6,32.45]],"id":41921674},{"atl":[[75,1.78],[150,1.33],[48,5.4],[50,2.69],[100,2]],"id":41921674},{"atb":[[17,2.53],[12,11.06],[12.5,10.81],[8.8,20.8],[14.5,6],[15,3.08]],"id":36899924},{"atl":[[270,0.73],[170,0.78],[90,0.48],[110,2.7],[220,0.9],[120,1.1]],"id":36899924},{"atb":[[8,33.47],[10,13.52],[10.5,14.06],[11.5,4.12],[12.5,7.05],[15,2.89]],"id":40251221},{"atl":[[70,0.62],[150,0.88],[95,2.7],[100,1.33],[200,0.99],[250,0.79]],"id":40251221},{"atb":[[7.2,26.17],[9.2,14.84],[10.5,8.54],[11,4.32],[13,3.38],[9.4,14.06]],"id":39979879},{"atl":[[75,2.7],[80,1.67],[160,1.24],[210,0.94],[110,1.21],[60,0.73]],"id":39979879},{"atb":[[17.5,2.7],[17,2.53],[12,11.06],[8.8,20.8],[14.5,6],[15,8.22]],"id":39722911},{"atl":[[270,0.73],[170,0.78],[95,0.45],[110,2.7],[220,0.9],[120,1.1]],"id":39722911},{"atb":[[1.01,16225.86],[1.16,43.26],[1.15,270.43],[1.11,1187.19],[1.1,811.29],[1.05,2433.87]],"id":42492389},{"spl":[[1.01,10.81]],"id":42492389},{"atl":[[1.73,9.47],[2.24,106.6],[1.72,43.26],[1.79,35.69],[2.06,121.15],[2.44,137.69],[2.14,115.95],[2.08,0],[2.34,147.96]],"id":42492389},{"atb":[[16,7.1],[18.5,2.7],[18,4.77],[21,2.02],[10.5,17.08],[15.5,8.39]],"id":27151693},{"atl":[[140,2.7],[150,0.88],[300,0.66],[200,0.66],[110,0.39],[250,0.79]],"id":27151693},{"atb":[[16,7.73],[18.5,2.7],[18,2.38],[9.2,19.79],[13,10.14],[15.5,5.59]],"id":43154431},{"atl":[[130,1.02],[280,0.7],[180,0.74],[110,0.39],[230,0.86],[120,2.7]],"id":43154431}],"con":true,"img":false}]}
{"op":"mcm","clk":"5346630342","pt":1646092820928,"mc":[{"id":"1.195395451","rc":[{"atl":[[2.02,9.09]],"id":42492389}],"con":true,"img":false}]}
{"op":"mcm","clk":"5346630847","pt":1646092833442,"mc":[{"id":"1.195395451","rc":[{"atl":[[1.73,0]],"id":42492389}],"con":true,"img":false}]}
{"op":"mcm","clk":"5346630949","pt":1646092836367,"mc":[{"id":"1.195395451","rc":[{"atl":[[2.02,17.21]],"id":42492389}],"con":true,"img":false}]}
{"op":"mcm","clk":"5346631875","pt":1646092863719,"mc":[{"id":"1.195395451","rc":[{"atl":[[1.72,0],[2.06,0]],"id":42492389}],"con":true,"img":false}]}
{"op":"mcm","clk":"5346631876","pt":1646092863825,"mc":[{"id":"1.195395451","rc":[{"atl":[[2,121.15],[1.78,43.26]],"id":42492389}],"con":true,"img":false}]}
{"op":"mcm","clk":"5346634960","pt":1646092941086,"mc":[{"id":"1.195395451","rc":[{"atl":[[2.02,8.11]],"id":42492389}],"con":true,"img":false}]}
{"op":"mcm","clk":"5346635194","pt":1646092947200,"mc":[{"id":"1.195395451","rc":[{"atl":[[1.76,10.44]],"id":42492389}],"con":true,"img":false}]}
{"op":"mcm","clk":"5346635416","pt":1646092953621,"mc":[{"id":"1.195395451","rc":[{"atl":[[2.02,0]],"id":42492389}],"con":true,"img":false}]}
{"op":"mcm","clk":"5346635435","pt":1646092954085,"mc":[{"id":"1.195395451","rc":[{"atl":[[2,0]],"id":42492389}],"con":true,"img":false}]}
{"op":"mcm","clk":"5346635437","pt":1646092954187,"mc":[{"id":"1.195395451","rc":[{"atl":[[2.12,121.15]],"id":42492389}],"con":true,"img":false}]}
{"op":"mcm","clk":"5346635523","pt":1646092956498,"mc":[{"id":"1.195395451","rc":[{"atl":[[1.76,19.75]],"id":42492389}],"con":true,"img":false}]}
{"op":"mcm","clk":"5346637798","pt":1646093012758,"mc":[{"id":"1.195395451","rc":[{"atl":[[1.78,0]],"id":42492389}],"con":true,"img":false}]}
{"op":"mcm","clk":"5346637803","pt":1646093012858,"mc":[{"id":"1.195395451","rc":[{"atl":[[1.75,43.26]],"id":42492389}],"con":true,"img":false}]}
{"op":"mcm","clk":"5346639778","pt":1646093067423,"mc":[{"id":"1.195395451","rc":[{"atl":[[1.76,9.31]],"id":42492389}],"con":true,"img":false}]}
{"op":"mcm","clk":"5346639976","pt":1646093073365,"mc":[{"id":"1.195395451","rc":[{"atl":[[2.08,8.83]],"id":42492389}],"con":true,"img":false}]}
{"op":"mcm","clk":"5346639993","pt":1646093073825,"mc":[{"id":"1.195395451","rc":[{"atl":[[1.76,0]],"id":42492389}],"con":true,"img":false}]}
{"op":"mcm","clk":"5346640101","pt":1646093076863,"mc":[{"id":"1.195395451","rc":[{"atl":[[1.73,9.47]],"id":42492389}],"con":true,"img":false}]}
{"op":"mcm","clk":"5346643159","pt":1646093153751,"mc":[{"id":"1.195395451","rc":[{"atl":[[2.12,0],[1.75,0]],"id":42492389}],"con":true,"img":false}]}
{"op":"mcm","clk":"5346643163","pt":1646093153854,"mc":[{"id":"1.195395451","rc":[{"atl":[[1.72,43.26],[2.06,121.15]],"id":42492389}],"con":true,"img":false}]}
{"op":"mcm","clk":"5346644556","pt":1646093193598,"mc":[{"id":"1.195395451","rc":[{"atl":[[2.08,0]],"id":42492389}],"con":true,"img":false}]}
{"op":"mcm","clk":"5346644578","pt":1646093194162,"mc":[{"id":"1.195395451","rc":[{"atl":[[1.73,0]],"id":42492389}],"con":true,"img":false}]}
{"op":"mcm","clk":"5346644672","pt":1646093197092,"mc":[{"id":"1.195395451","rc":[{"atl":[[2.02,8.11]],"id":42492389}],"con":true,"img":false}]}
{"op":"mcm","clk":"5346644739","pt":1646093199503,"mc":[{"id":"1.195395451","rc":[{"atl":[[2.02,17.21]],"id":42492389}],"con":true,"img":false}]}
{"op":"mcm","clk":"5346644998","pt":1646093208024,"mc":[{"id":"1.195395451","rc":[{"atl":[[1.72,0]],"id":42492389}],"con":true,"img":false}]}
{"op":"mcm","clk":"5346645000","pt":1646093208126,"mc":[{"id":"1.195395451","rc":[{"atl":[[1.78,43.26]],"id":42492389}],"con":true,"img":false}]}
{"op":"mcm","clk":"5346646928","pt":1646093261173,"mc":[{"id":"1.195395451","rc":[{"atl":[[2.06,0]],"id":42492389}],"con":true,"img":false}]}
{"op":"mcm","clk":"5346646931","pt":1646093261283,"mc":[{"id":"1.195395451","rc":[{"atl":[[2,121.15]],"id":42492389}],"con":true,"img":false}]}
{"op":"mcm","clk":"5346649018","pt":1646093314368,"mc":[{"id":"1.195395451","rc":[{"atl":[[2.02,9.09]],"id":42492389}],"con":true,"img":false}]}
{"op":"mcm","clk":"5346649150","pt":1646093317352,"mc":[{"id":"1.195395451","rc":[{"atl":[[1.76,9.31]],"id":42492389}],"con":true,"img":false}]}
{"op":"mcm","clk":"5346649213","pt":1646093319716,"mc":[{"id":"1.195395451","rc":[{"atl":[[2.02,0]],"id":42492389}],"con":true,"img":false}]}
{"op":"mcm","clk":"5346649410","pt":1646093325775,"mc":[{"id":"1.195395451","rc":[{"atl":[[1.76,19.75]],"id":42492389}],"con":true,"img":false}]}
{"op":"mcm","clk":"5346649888","pt":1646093338959,"mc":[{"id":"1.195395451","rc":[{"atl":[[2,0]],"id":42492389}],"con":true,"img":false}]}
{"op":"mcm","clk":"5346649891","pt":1646093339061,"mc":[{"id":"1.195395451","rc":[{"atl":[[2.12,121.15]],"id":42492389}],"con":true,"img":false}]}
{"op":"mcm","clk":"5346651559","pt":1646093389543,"mc":[{"id":"1.195395451","rc":[{"atl":[[1.78,0]],"id":42492389}],"con":true,"img":false}]}
{"op":"mcm","clk":"5346651562","pt":1646093389646,"mc":[{"id":"1.195395451","rc":[{"atl":[[1.75,43.26]],"id":42492389}],"con":true,"img":false}]}
{"op":"mcm","clk":"5346653111","pt":1646093434467,"mc":[{"id":"1.195395451","rc":[{"atl":[[1.76,10.44]],"id":42492389}],"con":true,"img":false}]}
{"op":"mcm","clk":"5346653304","pt":1646093437504,"mc":[{"id":"1.195395451","rc":[{"atl":[[1.73,9.47]],"id":42492389}],"con":true,"img":false}]}
{"op":"mcm","clk":"5346653720","pt":1646093446398,"mc":[{"id":"1.195395451","rc":[{"atl":[[1.76,0]],"id":42492389}],"con":true,"img":false}]}
{"op":"mcm","clk":"5346653895","pt":1646093452109,"mc":[{"id":"1.195395451","rc":[{"atl":[[2.08,8.83]],"id":42492389}],"con":true,"img":false}]}
{"op":"mcm","clk":"5346654828","pt":1646093487941,"mc":[{"id":"1.195395451","rc":[{"atl":[[1.75,0]],"id":42492389}],"con":true,"img":false}]}
{"op":"mcm","clk":"5346654831","pt":1646093488044,"mc":[{"id":"1.195395451","rc":[{"atl":[[1.72,43.26]],"id":42492389}],"con":true,"img":false}]}
{"op":"mcm","clk":"5346655568","pt":1646093511900,"mc":[{"id":"1.195395451","rc":[{"atl":[[2.12,0]],"id":42492389}],"con":true,"img":false}]}
{"op":"mcm","clk":"5346655571","pt":1646093512002,"mc":[{"id":"1.195395451","rc":[{"atl":[[2.06,121.15]],"id":42492389}],"con":true,"img":false}]}
{"op":"mcm","clk":"5346656898","pt":1646093554646,"mc":[{"id":"1.195395451","rc":[{"atl":[[1.73,0]],"id":42492389}],"con":true,"img":false}]}
{"op":"mcm","clk":"5346656979","pt":1646093557624,"mc":[{"id":"1.195395451","rc":[{"atl":[[2.02,8.11]],"id":42492389}],"con":true,"img":false}]}
{"op":"mcm","clk":"5346657019","pt":1646093559163,"mc":[{"id":"1.195395451","rc":[{"atl":[[1.72,0]],"id":42492389}],"con":true,"img":false}]}
{"op":"mcm","clk":"5346657022","pt":1646093559265,"mc":[{"id":"1.195395451","rc":[{"atl":[[1.78,43.26]],"id":42492389}],"con":true,"img":false}]}
{"op":"mcm","clk":"5346657391","pt":1646093572466,"mc":[{"id":"1.195395451","rc":[{"atl":[[2.08,0]],"id":42492389}],"con":true,"img":false}]}
{"op":"mcm","clk":"5346657544","pt":1646093578276,"mc":[{"id":"1.195395451","rc":[{"atl":[[1.76,10.44]],"id":42492389}],"con":true,"img":false}]}
{"op":"mcm","clk":"5346658391","pt":1646093605786,"mc":[{"id":"1.195395451","rc":[{"atl":[[2.06,0]],"id":42492389}],"con":true,"img":false}]}
{"op":"mcm","clk":"5346658395","pt":1646093605889,"mc":[{"id":"1.195395451","rc":[{"atl":[[2,121.15]],"id":42492389}],"con":true,"img":false}]}
{"op":"mcm","clk":"5346659069","pt":1646093628756,"mc":[{"id":"1.195395451","rc":[{"atl":[[1.78,0]],"id":42492389}],"con":true,"img":false}]}
{"op":"mcm","clk":"5346659076","pt":1646093628859,"mc":[{"id":"1.195395451","rc":[{"atl":[[1.75,43.26]],"id":42492389}],"con":true,"img":false}]}
{"op":"mcm","clk":"5346660580","pt":1646093675110,"mc":[{"id":"1.195395451","rc":[{"atl":[[2.02,0]],"id":42492389}],"con":true,"img":false}]}
{"op":"mcm","clk":"5346660658","pt":1646093678036,"mc":[{"id":"1.195395451","rc":[{"atl":[[1.73,10.42]],"id":42492389}],"con":true,"img":false}]}
{"op":"mcm","clk":"5346661367","pt":1646093696235,"mc":[{"id":"1.195395451","rc":[{"atl":[[2,0]],"id":42492389}],"con":true,"img":false}]}
{"op":"mcm","clk":"5346661371","pt":1646093696338,"mc":[{"id":"1.195395451","rc":[{"atl":[[2.12,121.15]],"id":42492389}],"con":true,"img":false}]}
{"op":"mcm","clk":"5346661449","pt":1646093698640,"mc":[{"id":"1.195395451","rc":[{"atl":[[1.76,0]],"id":42492389}],"con":true,"img":false}]}
{"op":"mcm","clk":"5346661699","pt":1646093704542,"mc":[{"id":"1.195395451","rc":[{"atl":[[2.08,8.83]],"id":42492389}],"con":true,"img":false}]}
{"op":"mcm","clk":"5346662985","pt":1646093740397,"mc":[{"id":"1.195395451","rc":[{"atl":[[1.75,0]],"id":42492389}],"con":true,"img":false}]}
{"op":"mcm","clk":"5346662991","pt":1646093740499,"mc":[{"id":"1.195395451","rc":[{"atl":[[1.72,43.26]],"id":42492389}],"con":true,"img":false}]}
{"op":"mcm","clk":"5346663236","pt":1646093748304,"mc":[{"id":"1.195395451","rc":[{"atb":[[1.19,0]],"id":42492389}],"con":true,"img":false}]}
{"op":"mcm","clk":"5346663238","pt":1646093748405,"mc":[{"id":"1.195395451","rc":[{"atb":[[1.18,2]],"id":42492389}],"con":true,"img":false}]}
{"op":"mcm","clk":"5346663626","pt":1646093762167,"mc":[{"id":"1.195395451","rc":[{"atl":[[2.12,0]],"id":42492389},{"spn":1.16,"spf":1.0,"id":42492389}],"con":true,"img":false}]}
{"op":"mcm","clk":"5346663628","pt":1646093762220,"mc":[{"id":"1.195395451","rc":[{"atl":[[2.06,121.15]],"id":42492389}],"con":true,"img":false}]}
{"op":"mcm","clk":"5346664695","pt":1646093795313,"mc":[{"id":"1.195395451","rc":[{"atl":[[1.73,0]],"id":42492389}],"con":true,"img":false}]}
{"op":"mcm","clk":"5346664826","pt":1646093798186,"mc":[{"id":"1.195395451","rc":[{"atl":[[2.02,8.92]],"id":42492389}],"con":true,"img":false}]}
{"op":"mcm","clk":"5346672477","pt":1646093805116,"mc":[{"id":"1.195395451","rc":[{"atl":[[1.72,0]],"id":42492389}],"con":true,"img":false}]}
{"op":"mcm","clk":"5346672479","pt":1646093805216,"mc":[{"id":"1.195395451","rc":[{"atl":[[1.78,43.26]],"id":42492389}],"con":true,"img":false}]}
{"op":"mcm","clk":"5346673250","pt":1646093825261,"mc":[{"id":"1.195395451","rc":[{"atl":[[2.08,0]],"id":42492389}],"con":true,"img":false}]}
{"op":"mcm","clk":"5346673531","pt":1646093831172,"mc":[{"id":"1.195395451","rc":[{"atl":[[1.76,10.44]],"id":42492389}],"con":true,"img":false}]}
{"op":"mcm","clk":"5346674129","pt":1646093847501,"mc":[{"id":"1.195395451","rc":[{"atl":[[2.06,0]],"id":42492389}],"con":true,"img":false}]}
{"op":"mcm","clk":"5346674134","pt":1646093847603,"mc":[{"id":"1.195395451","rc":[{"atl":[[2,121.15]],"id":42492389}],"con":true,"img":false}]}
{"op":"mcm","clk":"5346675548","pt":1646093888959,"mc":[{"id":"1.195395451","rc":[{"atl":[[1.78,0]],"id":42492389}],"con":true,"img":false}]}
{"op":"mcm","clk":"5346675552","pt":1646093889063,"mc":[{"id":"1.195395451","rc":[{"atl":[[1.75,43.26]],"id":42492389}],"con":true,"img":false}]}
{"op":"mcm","clk":"5346675713","pt":1646093893983,"mc":[{"id":"1.195395451","rc":[{"spl":[[8.6,2.7]],"id":40251221}],"con":true,"img":false}]}
{"op":"mcm","clk":"5346676490","pt":1646093915595,"mc":[{"id":"1.195395451","rc":[{"atl":[[2.02,0]],"id":42492389}],"con":true,"img":false}]}
{"op":"mcm","clk":"5346676610","pt":1646093918522,"mc":[{"id":"1.195395451","rc":[{"atl":[[1.73,10.42]],"id":42492389}],"con":true,"img":false}]}
{"op":"mcm","clk":"5346677019","pt":1646093929920,"mc":[{"id":"1.195395451","rc":[{"atl":[[2,0]],"id":42492389}],"con":true,"img":false}]}
{"op":"mcm","clk":"5346677023","pt":1646093930023,"mc":[{"id":"1.195395451","rc":[{"atl":[[2.12,121.15]],"id":42492389}],"con":true,"img":false}]}
{"op":"mcm","clk":"5346677750","pt":1646093951436,"mc":[{"id":"1.195395451","rc":[{"spn":15.0,"spf":1.0,"id":40251221},{"atl":[[1.76,0]],"id":42492389}],"con":true,"img":false}]}
{"op":"mcm","clk":"5346677946","pt":1646093957348,"mc":[{"id":"1.195395451","rc":[{"atl":[[2.08,8.83]],"id":42492389}],"con":true,"img":false}]}
{"op":"mcm","clk":"5346678407","pt":1646093970199,"mc":[{"id":"1.195395451","rc":[{"atl":[[1.75,0]],"id":42492389}],"con":true,"img":false}]}
{"op":"mcm","clk":"5346678409","pt":1646093970301,"mc":[{"id":"1.195395451","rc":[{"atl":[[1.72,43.26]],"id":42492389}],"con":true,"img":false}]}
{"op":"mcm","clk":"5346680790","pt":1646094035910,"mc":[{"id":"1.195395451","rc":[{"atl":[[1.73,0]],"id":42492389}],"con":true,"img":false}]}
{"op":"mcm","clk":"5346680880","pt":1646094038684,"mc":[{"id":"1.195395451","rc":[{"atl":[[2.08,17.51]],"id":42492389}],"con":true,"img":false}]}
{"op":"mcm","clk":"5346681333","pt":1646094050821,"mc":[{"id":"1.195395451","rc":[{"atl":[[1.72,0]],"id":42492389}],"con":true,"img":false}]}
{"op":"mcm","clk":"5346681336","pt":1646094050922,"mc":[{"id":"1.195395451","rc":[{"atl":[[1.78,43.26]],"id":42492389}],"con":true,"img":false}]}
{"op":"mcm","clk":"5346682136","pt":1646094071280,"mc":[{"id":"1.195395451","rc":[{"atl":[[2.12,0]],"id":42492389}],"con":true,"img":false}]}
{"op":"mcm","clk":"5346682141","pt":1646094071331,"mc":[{"id":"1.195395451","rc":[{"atl":[[2.06,121.15]],"id":42492389}],"con":true,"img":false}]}
{"op":"mcm","clk":"5346682425","pt":1646094077739,"mc":[{"id":"1.195395451","rc":[{"atl":[[2.08,8.67]],"id":42492389}],"con":true,"img":false}]}
{"op":"mcm","clk":"5346682660","pt":1646094083795,"mc":[{"id":"1.195395451","rc":[{"atl":[[1.76,10.44]],"id":42492389}],"con":true,"img":false}]}
{"op":"mcm","clk":"5346685235","pt":1646094146061,"mc":[{"id":"1.195395451","rc":[{"atl":[[1.78,0]],"id":42492389}],"con":true,"img":false}]}
{"op":"mcm","clk":"5346685242","pt":1646094146162,"mc":[{"id":"1.195395451","rc":[{"atl":[[1.75,43.26]],"id":42492389}],"con":true,"img":false}]}
{"op":"mcm","clk":"5346685657","pt":1646094155876,"mc":[{"id":"1.195395451","rc":[{"atl":[[2.08,0]],"id":42492389}],"con":true,"img":false}]}
{"op":"mcm","clk":"5346685767","pt":1646094158911,"mc":[{"id":"1.195395451","rc":[{"atl":[[1.73,10.42]],"id":42492389}],"con":true,"img":false}]}
{"op":"mcm","clk":"5346686025","pt":1646094165807,"mc":[{"id":"1.195395451","rc":[{"atl":[[2.06,0]],"id":42492389}],"con":true,"img":false}]}
{"op":"mcm","clk":"5346686030","pt":1646094165909,"mc":[{"id":"1.195395451","rc":[{"atl":[[2.12,121.15]],"id":42492389}],"con":true,"img":false}]}
{"op":"mcm","clk":"5346687391","pt":1646094199568,"mc":[{"id":"1.195395451","rc":[{"atl":[[1.75,0]],"id":42492389}],"con":true,"img":false}]}
{"op":"mcm","clk":"5346687396","pt":1646094199671,"mc":[{"id":"1.195395451","rc":[{"atl":[[1.72,43.26]],"id":42492389}],"con":true,"img":false}]}
{"op":"mcm","clk":"5346687572","pt":1646094204045,"mc":[{"id":"1.195395451","rc":[{"atl":[[1.76,0]],"id":42492389}],"con":true,"img":false}]}
{"op":"mcm","clk":"5346687839","pt":1646094209900,"mc":[{"id":"1.195395451","rc":[{"atl":[[2.08,8.83]],"id":42492389}],"con":true,"img":false}]}
{"op":"mcm","clk":"5346689855","pt":1646094276081,"mc":[{"id":"1.195395451","rc":[{"atl":[[1.73,0]],"id":42492389}],"con":true,"img":false}]}
{"op":"mcm","clk":"5346689941","pt":1646094279114,"mc":[{"id":"1.195395451","rc":[{"atl":[[2.08,17.51]],"id":42492389}],"con":true,"img":false}]}
{"op":"mcm","clk":"5346690191","pt":1646094289311,"mc":[{"id":"1.195395451","rc":[{"atl":[[1.72,0],[2.12,0]],"id":42492389}],"con":true,"img":false}]}
{"op":"mcm","clk":"5346690195","pt":1646094289414,"mc":[{"id":"1.195395451","rc":[{"atl":[[2.06,121.15],[1.78,43.26]],"id":42492389}],"con":true,"img":false}]}
{"op":"mcm","clk":"5346691103","pt":1646094315743,"mc":[{"id":"1.195395451","rc":[{"atb":[[4.6,27.78]],"id":41921674},{"atl":[[46,2.22]],"id":41921674},{"atb":[[11,10]],"id":36899924},{"atl":[[260,2]],"id":36899924},{"atb":[[9.8,11.36]],"id":40251221},{"atl":[[190,2]],"id":40251221},{"atb":[[8.6,13.16]],"id":39979879},{"atl":[[140,2]],"id":39979879},{"atb":[[11.5,9.52]],"id":39722911},{"atl":[[300,2]],"id":39722911},{"atl":[[1.77,43.27]],"id":42492389},{"atb":[[21,4.05]],"id":27151693},{"atl":[[440,2]],"id":27151693},{"atb":[[7,16.67]],"id":43154431},{"atl":[[120,4.7]],"id":43154431}],"con":true,"img":false}]}
{"op":"mcm","clk":"5346691555","pt":1646094326980,"mc":[{"id":"1.195395451","rc":[{"atb":[[11,7.2]],"id":27151693}],"con":true,"img":false}]}
{"op":"mcm","clk":"5346691682","pt":1646094330158,"mc":[{"id":"1.195395451","rc":[{"atl":[[2.08,8.67]],"id":42492389}],"con":true,"img":false}]}
{"op":"mcm","clk":"5346691905","pt":1646094336165,"mc":[{"id":"1.195395451","rc":[{"spn":28.5,"spf":1.0,"id":41921674},{"atl":[[1.76,10.44]],"id":42492389}],"con":true,"img":false}]}
{"op":"mcm","clk":"5346692553","pt":1646094352705,"mc":[{"id":"1.195395451","rc":[{"atl":[[1.77,0],[1.75,43.27]],"id":42492389}],"con":true,"img":false}]}
{"op":"mcm","clk":"5346692819","pt":1646094358816,"mc":[{"id":"1.195395451","rc":[{"atl":[[48,2.7]],"id":41921674},{"atl":[[1.78,0]],"id":42492389},{"atl":[[110,0]],"id":43154431}],"con":true,"img":false}]}
{"op":"mcm","clk":"5346692821","pt":1646094358922,"mc":[{"id":"1.195395451","rc":[{"atl":[[44,2.7],[46,0],[48,4.83]],"id":41921674},{"atl":[[1.74,43.26]],"id":42492389},{"atl":[[100,0.39]],"id":43154431}],"con":true,"img":false}]}
{"op":"mcm","clk":"5346692825","pt":1646094359025,"mc":[{"id":"1.195395451","rc":[{"atl":[[1.73,43.27],[1.75,0]],"id":42492389}],"con":true,"img":false}]}
{"op":"mcm","clk":"5346692829","pt":1646094359125,"mc":[{"id":"1.195395451","rc":[{"atl":[[44,5.03],[48,2.7]],"id":41921674}],"con":true,"img":false}]}
{"op":"mcm","clk":"5346694157","pt":1646094396481,"mc":[{"id":"1.195395451","rc":[{"spn":27.5,"spf":1.0,"id":41921674},{"atl":[[2.08,0]],"id":42492389}],"con":true,"img":false}]}
{"op":"mcm","clk":"5346694277","pt":1646094399309,"mc":[{"id":"1.195395451","rc":[{"atl":[[1.71,10.54]],"id":42492389}],"con":true,"img":false}]}
{"op":"mcm","clk":"5346694282","pt":1646094399411,"mc":[{"id":"1.195395451","rc":[{"atl":[[1.73,0],[1.7,43.27]],"id":42492389}],"con":true,"img":false}]}
{"op":"mcm","clk":"5346694660","pt":1646094409822,"mc":[{"id":"1.195395451","rc":[{"atl":[[44,2.33]],"id":41921674},{"atl":[[2.06,0],[1.74,0]],"id":42492389}],"con":true,"img":false}]}
{"op":"mcm","clk":"5346694662","pt":1646094409924,"mc":[{"id":"1.195395451","rc":[{"atl":[[42,2.7],[44,0],[48,4.83]],"id":41921674},{"atl":[[2.12,121.15],[1.69,43.26]],"id":42492389}],"con":true,"img":false}]}
{"op":"mcm","clk":"5346695434","pt":1646094428561,"mc":[{"id":"1.195395451","rc":[{"atl":[[42,0]],"id":41921674}],"con":true,"img":false}]}
{"op":"mcm","clk":"5346695440","pt":1646094428661,"mc":[{"id":"1.195395451","rc":[{"atl":[[46,2.7]],"id":41921674}],"con":true,"img":false}]}
{"op":"mcm","clk":"5346695750","pt":1646094435539,"mc":[{"id":"1.195395451","rc":[{"atl":[[1.7,0],[1.68,43.27]],"id":42492389}],"con":true,"img":false}]}
{"op":"mcm","clk":"5346696593","pt":1646094456601,"mc":[{"id":"1.195395451","rc":[{"spn":28.5,"spf":1.0,"id":41921674},{"atl":[[1.76,0]],"id":42492389}],"con":true,"img":false}]}
{"op":"mcm","clk":"5346696796","pt":1646094462401,"mc":[{"id":"1.195395451","rc":[{"atl":[[2.08,8.83]],"id":42492389}],"con":true,"img":false}]}
{"op":"mcm","clk":"5346698487","pt":1646094508881,"mc":[{"id":"1.195395451","rc":[{"atl":[[1.69,0]],"id":42492389}],"con":true,"img":false}]}
{"op":"mcm","clk":"5346698491","pt":1646094508985,"mc":[{"id":"1.195395451","rc":[{"atl":[[1.7,86.54],[1.67,43.26]],"id":42492389}],"con":true,"img":false}]}
{"op":"mcm","clk":"5346698495","pt":1646094509087,"mc":[{"id":"1.195395451","rc":[{"atl":[[1.68,0],[1.7,0],[1.66,43.27]],"id":42492389}],"con":true,"img":false}]}
{"op":"mcm","clk":"5346698718","pt":1646094516478,"mc":[{"id":"1.195395451","rc":[{"atl":[[1.71,0]],"id":42492389}],"con":true,"img":false}]}
{"op":"mcm","clk":"5346698814","pt":1646094519607,"mc":[{"id":"1.195395451","rc":[{"atl":[[2.08,17.51]],"id":42492389}],"con":true,"img":false}]}
{"op":"mcm","clk":"5346699120","pt":1646094527128,"mc":[{"id":"1.195395451","rc":[{"atl":[[2.12,0]],"id":42492389}],"con":true,"img":false}]}
{"op":"mcm","clk":"5346699122","pt":1646094527229,"mc":[{"id":"1.195395451","rc":[{"atl":[[2.06,121.15]],"id":42492389}],"con":true,"img":false}]}
{"op":"mcm","clk":"5346699405","pt":1646094534726,"mc":[{"id":"1.195395451","rc":[{"atl":[[140,0],[110,3.21]],"id":39979879}],"con":true,"img":false}]}
{"op":"mcm","clk":"5346700203","pt":1646094557083,"mc":[{"id":"1.195395451","rc":[{"atl":[[1.67,0]],"id":42492389},{"atl":[[110,0]],"id":27151693},{"atl":[[100,0]],"id":43154431}],"con":true,"img":false}]}
{"op":"mcm","clk":"5346700208","pt":1646094557191,"mc":[{"id":"1.195395451","rc":[{"atl":[[1.65,43.26]],"id":42492389},{"atl":[[120,0.39]],"id":27151693},{"atl":[[110,0.39]],"id":43154431}],"con":true,"img":false}]}
{"op":"mcm","clk":"5346700213","pt":1646094557289,"mc":[{"id":"1.195395451","rc":[{"atl":[[1.78,86.54],[1.66,0]],"id":42492389}],"con":true,"img":false}]}
{"op":"mcm","clk":"5346700215","pt":1646094557390,"mc":[{"id":"1.195395451","rc":[{"atl":[[1.64,43.27],[1.78,0]],"id":42492389}],"con":true,"img":false}]}
{"op":"mcm","clk":"5346701015","pt":1646094582790,"mc":[{"id":"1.195395451","rc":[{"atl":[[2.08,8.67]],"id":42492389}],"con":true,"img":false}]}
{"op":"mcm","clk":"5346701235","pt":1646094589228,"mc":[{"id":"1.195395451","rc":[{"atl":[[2.02,9.09]],"id":42492389}],"con":true,"img":false}]}
{"op":"mcm","clk":"5346701821","pt":1646094604416,"mc":[{"id":"1.195395451","rc":[{"atl":[[48,2.13]],"id":41921674},{"atl":[[1.78,167.66],[2.06,0],[1.65,0]],"id":42492389}],"con":true,"img":false}]}
{"op":"mcm","clk":"5346701823","pt":1646094604518,"mc":[{"id":"1.195395451","rc":[{"atl":[[70,2.7]],"id":41921674},{"atl":[[1.64,0],[1.63,43.26],[1.77,86.54]],"id":42492389}],"con":true,"img":false}]}
{"op":"mcm","clk":"5346702511","pt":1646094621886,"mc":[{"id":"1.195395451","rc":[{"atl":[[2,130.88],[1.78,0],[1.63,0]],"id":42492389}],"con":true,"img":false}]}
{"op":"mcm","clk":"5346702517","pt":1646094621989,"mc":[{"id":"1.195395451","rc":[{"atl":[[110,0]],"id":36899924},{"atl":[[95,0]],"id":40251221},{"atl":[[75,0]],"id":39979879},{"atl":[[110,0]],"id":39722911},{"atl":[[2,0],[1.76,43.26]],"id":42492389},{"atl":[[140,0]],"id":27151693}],"con":true,"img":false}]}
{"op":"mcm","clk":"5346702523","pt":1646094622093,"mc":[{"id":"1.195395451","rc":[{"atl":[[190,2.7]],"id":36899924},{"atl":[[150,3.59]],"id":40251221},{"atl":[[100,2.7]],"id":39979879},{"atl":[[210,2.7]],"id":39722911},{"atl":[[240,2.7]],"id":27151693},{"atl":[[1.78,128.21],[2.06,130.88],[1.77,0]],"id":42492389}],"con":true,"img":false}]}
{"op":"mcm","clk":"5346703109","pt":1646094636704,"mc":[{"id":"1.195395451","rc":[{"atl":[[2.08,0]],"id":42492389}],"con":true,"img":false}]}
{"op":"mcm","clk":"5346703216","pt":1646094639683,"mc":[{"id":"1.195395451","rc":[{"atl":[[1.74,10.35]],"id":42492389}],"con":true,"img":false}]}
{"op":"mcm","clk":"5346703650","pt":1646094650619,"mc":[{"id":"1.195395451","rc":[{"atl":[[2.06,0]],"id":42492389}],"con":true,"img":false}]}
{"op":"mcm","clk":"5346703654","pt":1646094650721,"mc":[{"id":"1.195395451","rc":[{"atl":[[2.12,130.88]],"id":42492389}],"con":true,"img":false}]}
{"op":"mcm","clk":"5346703840","pt":1646094656051,"mc":[{"id":"1.195395451","rc":[{"atl":[[1.73,43.27]],"id":42492389}],"con":true,"img":false}]}
{"op":"mcm","clk":"5346703843","pt":1646094656103,"mc":[{"id":"1.195395451","rc":[{"atl":[[1.78,0]],"id":42492389}],"con":true,"img":false}]}
{"op":"mcm","clk":"5346704303","pt":1646094668051,"mc":[{"id":"1.195395451","rc":[{"atl":[[70,0]],"id":41921674}],"con":true,"img":false}]}
{"op":"mcm","clk":"5346704308","pt":1646094668155,"mc":[{"id":"1.195395451","rc":[{"atl":[[48,4.83]],"id":41921674}],"con":true,"img":false}]}
{"op":"mcm","clk":"5346705360","pt":1646094696495,"mc":[{"id":"1.195395451","rc":[{"atl":[[190,0]],"id":36899924},{"atl":[[150,0.88]],"id":40251221},{"atl":[[100,0]],"id":39979879},{"atl":[[210,0]],"id":39722911},{"atl":[[1.76,0]],"id":42492389}],"con":true,"img":false}]}
{"op":"mcm","clk":"5346705366","pt":1646094696597,"mc":[{"id":"1.195395451","rc":[{"atl":[[110,2.7]],"id":36899924},{"atl":[[95,2.7]],"id":40251221},{"atl":[[75,2.7]],"id":39979879},{"atl":[[110,2.7]],"id":39722911},{"atl":[[1.72,43.26]],"id":42492389}],"con":true,"img":false}]}
{"op":"mcm","clk":"5346705370","pt":1646094696701,"mc":[{"id":"1.195395451","rc":[{"atl":[[1.73,0],[1.71,43.27]],"id":42492389}],"con":true,"img":false}]}
{"op":"mcm","clk":"5346705877","pt":1646094708921,"mc":[{"id":"1.195395451","rc":[{"atl":[[2.02,0]],"id":42492389}],"con":true,"img":false}]}
{"op":"mcm","clk":"5346706021","pt":1646094713532,"mc":[{"id":"1.195395451","rc":[{"atb":[[1.18,0]],"id":42492389},{"spn":1.16,"spf":1.0,"id":42492389},{"atl":[[240,0]],"id":27151693}],"con":true,"img":false}]}
{"op":"mcm","clk":"5346706022","pt":1646094713634,"mc":[{"id":"1.195395451","rc":[{"atb":[[1.19,2]],"id":42492389},{"atl":[[140,2.7]],"id":27151693}],"con":true,"img":false}]}
{"op":"mcm","clk":"5346706073","pt":1646094714917,"mc":[{"id":"1.195395451","rc":[{"atl":[[2.08,8.83]],"id":42492389}],"con":true,"img":false}]}
{"op":"mcm","clk":"5346706898","pt":1646094741173,"mc":[{"id":"1.195395451","rc":[{"atl":[[1.72,0]],"id":42492389}],"con":true,"img":false}]}
{"op":"mcm","clk":"5346706902","pt":1646094741272,"mc":[{"id":"1.195395451","rc":[{"atl":[[1.73,86.54],[1.7,43.26],[1.71,0]],"id":42492389}],"con":true,"img":false}]}
{"op":"mcm","clk":"5346707476","pt":1646094757132,"mc":[{"id":"1.195395451","rc":[{"atl":[[1.74,0]],"id":42492389}],"con":true,"img":false}]}
{"op":"mcm","clk":"5346707566","pt":1646094760003,"mc":[{"id":"1.195395451","rc":[{"atl":[[1.71,10.54]],"id":42492389}],"con":true,"img":false}]}
{"op":"mcm","clk":"5346707928","pt":1646094770697,"mc":[{"id":"1.195395451","rc":[{"atl":[[1.7,0]],"id":42492389}],"con":true,"img":false}]}
{"op":"mcm","clk":"5346707932","pt":1646094770801,"mc":[{"id":"1.195395451","rc":[{"atl":[[1.72,43.26]],"id":42492389}],"con":true,"img":false}]}
{"op":"mcm","clk":"5346707990","pt":1646094772440,"mc":[{"id":"1.195395451","rc":[{"atb":[[1.19,0]],"id":42492389}],"con":true,"img":false}]}
{"op":"mcm","clk":"5346707995","pt":1646094772543,"mc":[{"id":"1.195395451","rc":[{"atb":[[1.18,2]],"id":42492389}],"con":true,"img":false}]}
{"op":"mcm","clk":"5346708055","pt":1646094774036,"mc":[{"id":"1.195395451","rc":[{"atl":[[1.7,43.27]],"id":42492389},{"spn":1.16,"spf":1.0,"id":42492389}],"con":true,"img":false}]}
{"op":"mcm","clk":"5346708059","pt":1646094774140,"mc":[{"id":"1.195395451","rc":[{"atl":[[1.73,0]],"id":42492389}],"con":true,"img":false}]}
{"op":"mcm","clk":"5346710401","pt":1646094828521,"mc":[{"id":"1.195395451","rc":[{"atl":[[1.72,0]],"id":42492389}],"con":true,"img":false}]}
{"op":"mcm","clk":"5346710406","pt":1646094828625,"mc":[{"id":"1.195395451","rc":[{"atl":[[1.69,43.26]],"id":42492389}],"con":true,"img":false}]}
{"op":"mcm","clk":"5346710411","pt":1646094828730,"mc":[{"id":"1.195395451","rc":[{"atl":[[1.7,0],[1.68,43.27]],"id":42492389}],"con":true,"img":false}]}
{"op":"mcm","clk":"5346710608","pt":1646094835210,"mc":[{"id":"1.195395451","rc":[{"atl":[[2.08,0]],"id":42492389}],"con":true,"img":false}]}
{"op":"mcm","clk":"5346710853","pt":1646094841421,"mc":[{"id":"1.195395451","rc":[{"atl":[[2.08,8.83]],"id":42492389}],"con":true,"img":false}]}
{"op":"mcm","clk":"5346711454","pt":1646094856670,"mc":[{"id":"1.195395451","rc":[{"atl":[[2.12,0]],"id":42492389}],"con":true,"img":false}]}
{"op":"mcm","clk":"5346711459","pt":1646094856771,"mc":[{"id":"1.195395451","rc":[{"atl":[[2.06,130.88]],"id":42492389}],"con":true,"img":false}]}
{"op":"mcm","clk":"5346712242","pt":1646094877396,"mc":[{"id":"1.195395451","rc":[{"atl":[[1.71,0]],"id":42492389}],"con":true,"img":false}]}
{"op":"mcm","clk":"5346712279","pt":1646094878829,"mc":[{"id":"1.195395451","rc":[{"atb":[[8.6,13.16],[9.8,0]],"id":40251221},{"atl":[[440,0],[510,2]],"id":27151693}],"con":true,"img":false}]}
{"op":"mcm","clk":"5346712328","pt":1646094880319,"mc":[{"id":"1.195395451","rc":[{"atl":[[2.02,8.92]],"id":42492389}],"con":true,"img":false}]}
{"op":"mcm","clk":"5346712402","pt":1646094882422,"mc":[{"id":"1.195395451","rc":[{"atb":[[9.6,11.63]],"id":40251221},{"atl":[[460,2],[510,0]],"id":27151693}],"con":true,"img":false}]}
{"op":"mcm","clk":"5346712406","pt":1646094882523,"mc":[{"id":"1.195395451","rc":[{"atb":[[8.6,0]],"id":40251221}],"con":true,"img":false}]}
{"op":"mcm","clk":"5346712440","pt":1646094883196,"mc":[{"id":"1.195395451","rc":[{"atb":[[8,14.29]],"id":43154431}],"con":true,"img":false}]}
{"op":"mcm","clk":"5346712446","pt":1646094883295,"mc":[{"id":"1.195395451","rc":[{"atb":[[7,0]],"id":43154431}],"con":true,"img":false}]}
{"op":"mcm","clk":"5346712499","pt":1646094884831,"mc":[{"id":"1.195395451","rc":[{"atl":[[1.69,0]],"id":42492389}],"con":true,"img":false}]}
{"op":"mcm","clk":"5346712501","pt":1646094884933,"mc":[{"id":"1.195395451","rc":[{"atl":[[1.78,86.54],[1.67,43.26]],"id":42492389}],"con":true,"img":false}]}
{"op":"mcm","clk":"5346712505","pt":1646094885036,"mc":[{"id":"1.195395451","rc":[{"atl":[[1.68,0]],"id":42492389}],"con":true,"img":false}]}
{"op":"mcm","clk":"5346713453","pt":1646094912562,"mc":[{"id":"1.195395451","rc":[{"atl":[[1.67,0]],"id":42492389}],"con":true,"img":false}]}
{"op":"mcm","clk":"5346713457","pt":1646094912664,"mc":[{"id":"1.195395451","rc":[{"atl":[[1.77,43.26]],"id":42492389}],"con":true,"img":false}]}
{"op":"mcm","clk":"5346713556","pt":1646094916163,"mc":[{"id":"1.195395451","rc":[{"atl":[[1.78,0],[1.76,43.27]],"id":42492389}],"con":true,"img":false}]}
{"op":"mcm","clk":"5346715963","pt":1646094980886,"mc":[{"id":"1.195395451","rc":[{"atl":[[2.06,0],[1.77,0]],"id":42492389}],"con":true,"img":false}]}
{"op":"mcm","clk":"5346715969","pt":1646094980988,"mc":[{"id":"1.195395451","rc":[{"atl":[[2,130.88],[1.78,86.54],[1.76,0],[1.75,43.26]],"id":42492389}],"con":true,"img":false}]}
{"op":"mcm","clk":"5346716566","pt":1646094997436,"mc":[{"id":"1.195395451","rc":[{"atl":[[2.08,0]],"id":42492389}],"con":true,"img":false}]}
{"op":"mcm","clk":"5346716571","pt":1646094997641,"mc":[{"id":"1.195395451","rc":[{"atl":[[2.02,0]],"id":42492389}],"con":true,"img":false}]}
{"op":"mcm","clk":"5346716665","pt":1646095000568,"mc":[{"id":"1.195395451","rc":[{"atl":[[1.73,10.42]],"id":42492389}],"con":true,"img":false}]}
{"op":"mcm","clk":"5346716792","pt":1646095003968,"mc":[{"id":"1.195395451","rc":[{"atl":[[1.76,10.44]],"id":42492389}],"con":true,"img":false}]}
{"op":"mcm","clk":"5346716928","pt":1646095007690,"mc":[{"id":"1.195395451","rc":[{"atl":[[2,0],[1.75,0]],"id":42492389}],"con":true,"img":false}]}
{"op":"mcm","clk":"5346716934","pt":1646095007794,"mc":[{"id":"1.195395451","rc":[{"atl":[[2.12,130.88],[1.77,43.26]],"id":42492389}],"con":true,"img":false}]}
{"op":"mcm","clk":"5346717070","pt":1646095011388,"mc":[{"id":"1.195395451","rc":[{"atl":[[1.78,0],[1.72,10.44]],"id":42492389}],"con":true,"img":false}]}
{"op":"mcm","clk":"5346719705","pt":1646095086609,"mc":[{"id":"1.195395451","rc":[{"atl":[[1.77,0]],"id":42492389}],"con":true,"img":false}]}
{"op":"mcm","clk":"5346719708","pt":1646095086712,"mc":[{"id":"1.195395451","rc":[{"atl":[[1.71,43.26]],"id":42492389}],"con":true,"img":false}]}
{"op":"mcm","clk":"5346719711","pt":1646095086814,"mc":[{"id":"1.195395451","rc":[{"atl":[[1.7,10.44],[1.72,0]],"id":42492389}],"con":true,"img":false}]}
{"op":"mcm","clk":"5346720892","pt":1646095117881,"mc":[{"id":"1.195395451","rc":[{"atl":[[1.73,0]],"id":42492389}],"con":true,"img":false}]}
{"op":"mcm","clk":"5346720998","pt":1646095120762,"mc":[{"id":"1.195395451","rc":[{"atl":[[2.08,8.67]],"id":42492389}],"con":true,"img":false}]}
{"op":"mcm","clk":"5346722795","pt":1646095162850,"mc":[{"id":"1.195395451","rc":[{"atl":[[1.71,0]],"id":42492389}],"con":true,"img":false}]}
{"op":"mcm","clk":"5346722799","pt":1646095162954,"mc":[{"id":"1.195395451","rc":[{"atl":[[1.69,43.26],[1.75,20.88]],"id":42492389}],"con":true,"img":false}]}
{"op":"mcm","clk":"5346722803","pt":1646095163057,"mc":[{"id":"1.195395451","rc":[{"atl":[[1.7,0]],"id":42492389}],"con":true,"img":false}]}
{"op":"mcm","clk":"5346723872","pt":1646095187866,"mc":[{"id":"1.195395451","rc":[{"atl":[[2.12,0],[1.69,0]],"id":42492389}],"con":true,"img":false}]}
{"op":"mcm","clk":"5346723879","pt":1646095187970,"mc":[{"id":"1.195395451","rc":[{"atl":[[2.06,130.88],[1.74,43.26]],"id":42492389}],"con":true,"img":false}]}
{"op":"mcm","clk":"5346724059","pt":1646095191534,"mc":[{"id":"1.195395451","rc":[{"atl":[[1.73,20.88],[1.75,0]],"id":42492389}],"con":true,"img":false}]}
{"op":"mcm","clk":"5346726014","pt":1646095238007,"mc":[{"id":"1.195395451","rc":[{"atl":[[2.08,0]],"id":42492389}],"con":true,"img":false}]}
{"op":"mcm","clk":"5346726109","pt":1646095240978,"mc":[{"id":"1.195395451","rc":[{"atl":[[1.72,10.48]],"id":42492389}],"con":true,"img":false}]}
{"op":"mcm","clk":"5346726112","pt":1646095241089,"mc":[{"id":"1.195395451","rc":[{"atl":[[1.73,0],[1.71,20.88]],"id":42492389}],"con":true,"img":false}]}
{"op":"mcm","clk":"5346726554","pt":1646095254533,"mc":[{"id":"1.195395451","rc":[{"atl":[[85,2],[110,1.21]],"id":39979879},{"atl":[[300,0],[250,2]],"id":39722911}],"con":true,"img":false}]}
{"op":"mcm","clk":"5346726559","pt":1646095254686,"mc":[{"id":"1.195395451","rc":[{"spl":[[1.01,16.22]],"id":42492389}],"con":true,"img":false}]}
{"op":"mcm","clk":"5346726797","pt":1646095261620,"mc":[{"id":"1.195395451","rc":[{"atl":[[2.06,0],[1.74,0]],"id":42492389}],"con":true,"img":false}]}
{"op":"mcm","clk":"5346726802","pt":1646095261723,"mc":[{"id":"1.195395451","rc":[{"atl":[[1.72,53.75],[2.12,130.88]],"id":42492389}],"con":true,"img":false}]}
{"op":"mcm","clk":"5346727237","pt":1646095273824,"mc":[{"id":"1.195395451","rc":[{"atl":[[1.76,0]],"id":42492389}],"con":true,"img":false}]}
{"op":"mcm","clk":"5346727435","pt":1646095279767,"mc":[{"id":"1.195395451","rc":[{"atl":[[1.7,10.81]],"id":42492389}],"con":true,"img":false}]}
{"op":"mcm","clk":"5346727437","pt":1646095279871,"mc":[{"id":"1.195395451","rc":[{"atl":[[1.71,0],[1.69,20.88]],"id":42492389}],"con":true,"img":false}]}
{"op":"mcm","clk":"5346728285","pt":1646095309443,"mc":[{"id":"1.195395451","rc":[{"atl":[[1.72,10.48]],"id":42492389},{"spn":1.16,"spf":1.0,"id":42492389}],"con":true,"img":false}]}
{"op":"mcm","clk":"5346728289","pt":1646095309493,"mc":[{"id":"1.195395451","rc":[{"atl":[[1.68,43.26]],"id":42492389}],"con":true,"img":false}]}
{"op":"mcm","clk":"5346728292","pt":1646095309650,"mc":[{"id":"1.195395451","rc":[{"atl":[[1.69,0],[1.67,20.88]],"id":42492389}],"con":true,"img":false}]}
{"op":"mcm","clk":"5346728407","pt":1646095313402,"mc":[{"id":"1.195395451","rc":[{"atb":[[8.6,0],[7.4,15.62]],"id":39979879},{"atl":[[80,3.67],[85,0]],"id":39979879}],"con":true,"img":false}]}
{"op":"mcm","clk":"5346728572","pt":1646095318514,"mc":[{"id":"1.195395451","rc":[{"atl":[[85,2]],"id":39979879}],"con":true,"img":false}]}
{"op":"mcm","clk":"5346728577","pt":1646095318615,"mc":[{"id":"1.195395451","rc":[{"atl":[[80,1.67]],"id":39979879}],"con":true,"img":false}]}
{"op":"mcm","clk":"5346730003","pt":1646095358232,"mc":[{"id":"1.195395451","rc":[{"atl":[[1.72,0]],"id":42492389}],"con":true,"img":false}]}
{"op":"mcm","clk":"5346730105","pt":1646095361207,"mc":[{"id":"1.195395451","rc":[{"atl":[[2.08,8.67]],"id":42492389}],"con":true,"img":false}]}
{"op":"mcm","clk":"5346730553","pt":1646095373863,"mc":[{"id":"1.195395451","rc":[{"atl":[[80,3.67],[85,0]],"id":39979879}],"con":true,"img":false}]}
{"op":"mcm","clk":"5346730741","pt":1646095378960,"mc":[{"id":"1.195395451","rc":[{"atl":[[80,1.67],[85,2]],"id":39979879}],"con":true,"img":false}]}
{"op":"mcm","clk":"5346730763","pt":1646095379680,"mc":[{"id":"1.195395451","rc":[{"atl":[[1.68,0]],"id":42492389}],"con":true,"img":false}]}
{"op":"mcm","clk":"5346730766","pt":1646095379783,"mc":[{"id":"1.195395451","rc":[{"atl":[[1.66,43.26]],"id":42492389}],"con":true,"img":false}]}
{"op":"mcm","clk":"5346730770","pt":1646095379835,"mc":[{"id":"1.195395451","rc":[{"atl":[[1.69,41.76],[1.67,0]],"id":42492389}],"con":true,"img":false}]}
{"op":"mcm","clk":"5346731308","pt":1646095397683,"mc":[{"id":"1.195395451","rc":[{"atl":[[1.7,0]],"id":42492389}],"con":true,"img":false}]}
{"op":"mcm","clk":"5346731482","pt":1646095402475,"mc":[{"id":"1.195395451","rc":[{"atl":[[1.66,0]],"id":42492389}],"con":true,"img":false}]}
{"op":"mcm","clk":"5346731487","pt":1646095402578,"mc":[{"id":"1.195395451","rc":[{"atl":[[1.68,43.26],[1.78,83.52]],"id":42492389}],"con":true,"img":false}]}
{"op":"mcm","clk":"5346731492","pt":1646095402682,"mc":[{"id":"1.195395451","rc":[{"atl":[[1.69,0]],"id":42492389}],"con":true,"img":false}]}
{"op":"mcm","clk":"5346731519","pt":1646095403813,"mc":[{"id":"1.195395451","rc":[{"atl":[[1.76,10.44]],"id":42492389}],"con":true,"img":false}]}
{"op":"mcm","clk":"5346732164","pt":1646095425135,"mc":[{"id":"1.195395451","rc":[{"atl":[[1.68,0]],"id":42492389}],"con":true,"img":false}]}
{"op":"mcm","clk":"5346732167","pt":1646095425239,"mc":[{"id":"1.195395451","rc":[{"atl":[[1.77,43.26]],"id":42492389}],"con":true,"img":false}]}
{"op":"mcm","clk":"5346732273","pt":1646095428739,"mc":[{"id":"1.195395451","rc":[{"atl":[[1.78,0],[1.75,43.27]],"id":42492389}],"con":true,"img":false}]}
{"op":"mcm","clk":"5346732293","pt":1646095429456,"mc":[{"id":"1.195395451","rc":[{"atl":[[90,2]],"id":39979879}],"con":true,"img":false}]}
{"op":"mcm","clk":"5346732296","pt":1646095429560,"mc":[{"id":"1.195395451","rc":[{"atl":[[85,0]],"id":39979879}],"con":true,"img":false}]}
{"op":"mcm","clk":"5346733891","pt":1646095478454,"mc":[{"id":"1.195395451","rc":[{"atl":[[2.08,0]],"id":42492389}],"con":true,"img":false}]}
{"op":"mcm","clk":"5346733987","pt":1646095481441,"mc":[{"id":"1.195395451","rc":[{"atl":[[1.73,10.42]],"id":42492389}],"con":true,"img":false}]}
{"op":"mcm","clk":"5346733992","pt":1646095481542,"mc":[{"id":"1.195395451","rc":[{"atl":[[1.72,10.44],[1.75,0]],"id":42492389}],"con":true,"img":false}]}
{"op":"mcm","clk":"5346734435","pt":1646095492262,"mc":[{"id":"1.195395451","rc":[{"atl":[[1.77,0]],"id":42492389}],"con":true,"img":false}]}
{"op":"mcm","clk":"5346734440","pt":1646095492365,"mc":[{"id":"1.195395451","rc":[{"atl":[[1.74,43.26]],"id":42492389}],"con":true,"img":false}]}
{"op":"mcm","clk":"5346735787","pt":1646095523923,"mc":[{"id":"1.195395451","rc":[{"atl":[[1.76,0]],"id":42492389}],"con":true,"img":false}]}
{"op":"mcm","clk":"5346736030","pt":1646095529631,"mc":[{"id":"1.195395451","rc":[{"atl":[[2.08,8.83]],"id":42492389}],"con":true,"img":false}]}
{"op":"mcm","clk":"5346736304","pt":1646095536169,"mc":[{"id":"1.195395451","rc":[{"atl":[[1.74,0]],"id":42492389}],"con":true,"img":false}]}
{"op":"mcm","clk":"5346736312","pt":1646095536221,"mc":[{"id":"1.195395451","rc":[{"atl":[[1.71,43.26]],"id":42492389}],"con":true,"img":false}]}
{"op":"mcm","clk":"5346736316","pt":1646095536323,"mc":[{"id":"1.195395451","rc":[{"atl":[[1.7,10.44],[1.72,0]],"id":42492389}],"con":true,"img":false}]}
{"op":"mcm","clk":"5346738051","pt":1646095579046,"mc":[{"id":"1.195395451","rc":[{"atl":[[2.12,0]],"id":42492389}],"con":true,"img":false}]}
{"op":"mcm","clk":"5346738057","pt":1646095579149,"mc":[{"id":"1.195395451","rc":[{"atl":[[2.06,130.88]],"id":42492389}],"con":true,"img":false}]}
{"op":"mcm","clk":"5346738897","pt":1646095598672,"mc":[{"id":"1.195395451","rc":[{"atl":[[1.73,0]],"id":42492389}],"con":true,"img":false}]}
{"op":"mcm","clk":"5346738978","pt":1646095600374,"mc":[{"id":"1.195395451","rc":[{"atl":[[1.71,0]],"id":42492389}],"con":true,"img":false}]}
{"op":"mcm","clk":"5346738983","pt":1646095600477,"mc":[{"id":"1.195395451","rc":[{"atl":[[1.7,0],[1.78,35.7],[1.69,43.26]],"id":42492389}],"con":true,"img":false}]}
{"op":"mcm","clk":"5346738994","pt":1646095600787,"mc":[{"id":"1.195395451","rc":[{"atl":[[1.78,0],[1.68,35.7]],"id":42492389}],"con":true,"img":false}]}
{"op":"mcm","clk":"5346739034","pt":1646095601610,"mc":[{"id":"1.195395451","rc":[{"atl":[[2.02,8.92]],"id":42492389}],"con":true,"img":false}]}
{"op":"mcm","clk":"5346739399","pt":1646095609387,"mc":[{"id":"1.195395451","rc":[{"atl":[[85,2],[90,0]],"id":39979879}],"con":true,"img":false}]}
{"op":"mcm","clk":"5346740971","pt":1646095649974,"mc":[{"id":"1.195395451","rc":[{"atl":[[2.08,0]],"id":42492389}],"con":true,"img":false}]}
{"op":"mcm","clk":"5346741162","pt":1646095655880,"mc":[{"id":"1.195395451","rc":[{"atl":[[2.02,18.02]],"id":42492389}],"con":true,"img":false}]}
{"op":"mcm","clk":"5346741389","pt":1646095663062,"mc":[{"id":"1.195395451","rc":[{"atl":[[2.06,0],[1.69,0]],"id":42492389}],"con":true,"img":false}]}
{"op":"mcm","clk":"5346741391","pt":1646095663215,"mc":[{"id":"1.195395451","rc":[{"atl":[[2,130.88],[1.67,43.26],[1.78,71.4]],"id":42492389}],"con":true,"img":false}]}
{"op":"mcm","clk":"5346741394","pt":1646095663269,"mc":[{"id":"1.195395451","rc":[{"atl":[[1.68,0]],"id":42492389}],"con":true,"img":false}]}
{"op":"mcm","clk":"5346741870","pt":1646095683430,"mc":[{"id":"1.195395451","rc":[{"atl":[[1.67,0]],"id":42492389}],"con":true,"img":false}]}
{"op":"mcm","clk":"5346741875","pt":1646095683532,"mc":[{"id":"1.195395451","rc":[{"atl":[[1.77,43.26]],"id":42492389}],"con":true,"img":false}]}
{"op":"mcm","clk":"5346741996","pt":1646095686735,"mc":[{"id":"1.195395451","rc":[{"atl":[[1.78,0],[1.76,43.27]],"id":42492389}],"con":true,"img":false}]}
{"op":"mcm","clk":"5346742855","pt":1646095718974,"mc":[{"id":"1.195395451","rc":[{"atl":[[2.02,9.09]],"id":42492389}],"con":true,"img":false}]}
{"op":"mcm","clk":"5346742942","pt":1646095721789,"mc":[{"id":"1.195395451","rc":[{"atl":[[1.74,10.35]],"id":42492389}],"con":true,"img":false}]}
{"op":"mcm","clk":"5346742948","pt":1646095721895,"mc":[{"id":"1.195395451","rc":[{"atl":[[1.73,43.27],[1.76,0]],"id":42492389}],"con":true,"img":false}]}
{"op":"mcm","clk":"5346743416","pt":1646095737439,"mc":[{"id":"1.195395451","rc":[{"atb":[[6.8,17.24]],"id":43154431}],"con":true,"img":false}]}
{"op":"mcm","clk":"5346743421","pt":1646095737539,"mc":[{"id":"1.195395451","rc":[{"atl":[[85,0],[100,2]],"id":39979879},{"atb":[[8,0]],"id":43154431}],"con":true,"img":false}]}
{"op":"mcm","clk":"5346743608","pt":1646095744737,"mc":[{"id":"1.195395451","rc":[{"atl":[[1.77,0]],"id":42492389}],"con":true,"img":false}]}
{"op":"mcm","clk":"5346743612","pt":1646095744839,"mc":[{"id":"1.195395451","rc":[{"atl":[[1.72,43.26]],"id":42492389}],"con":true,"img":false}]}
{"op":"mcm","clk":"5346743617","pt":1646095744940,"mc":[{"id":"1.195395451","rc":[{"atl":[[1.71,43.27]],"id":42492389}],"con":true,"img":false}]}
{"op":"mcm","clk":"5346743620","pt":1646095745046,"mc":[{"id":"1.195395451","rc":[{"atl":[[1.73,0]],"id":42492389}],"con":true,"img":false}]}
{"op":"mcm","clk":"5346744090","pt":1646095760154,"mc":[{"id":"1.195395451","rc":[{"atb":[[6.8,0],[7.8,14.71]],"id":43154431}],"con":true,"img":false}]}
{"op":"mcm","clk":"5346744093","pt":1646095760257,"mc":[{"id":"1.195395451","rc":[{"atl":[[85,2],[100,0]],"id":39979879}],"con":true,"img":false}]}
{"op":"mcm","clk":"5346744533","pt":1646095776210,"mc":[{"id":"1.195395451","rc":[{"atl":[[2.02,0]],"id":42492389}],"con":true,"img":false}]}
{"op":"mcm","clk":"5346744708","pt":1646095782187,"mc":[{"id":"1.195395451","rc":[{"atl":[[1.97,9.32]],"id":42492389}],"con":true,"img":false}]}
{"op":"mcm","clk":"5346745361","pt":1646095803833,"mc":[{"id":"1.195395451","rc":[{"atl":[[1.72,0]],"id":42492389}],"con":true,"img":false}]}
{"op":"mcm","clk":"5346745364","pt":1646095803936,"mc":[{"id":"1.195395451","rc":[{"atl":[[1.73,86.54],[1.7,43.26],[1.71,0]],"id":42492389}],"con":true,"img":false}]}
{"op":"mcm","clk":"5346745720","pt":1646095815482,"mc":[{"id":"1.195395451","rc":[{"atl":[[2,0]],"id":42492389}],"con":true,"img":false}]}
{"op":"mcm","clk":"5346745725","pt":1646095815583,"mc":[{"id":"1.195395451","rc":[{"atl":[[2.12,130.88]],"id":42492389}],"con":true,"img":false}]}
{"op":"mcm","clk":"5346746041","pt":1646095825994,"mc":[{"id":"1.195395451","rc":[{"atl":[[1.69,43.27]],"id":42492389}],"con":true,"img":false}]}
{"op":"mcm","clk":"5346746045","pt":1646095826095,"mc":[{"id":"1.195395451","rc":[{"atl":[[1.73,0]],"id":42492389}],"con":true,"img":false}]}
{"op":"mcm","clk":"5346746417","pt":1646095839117,"mc":[{"id":"1.195395451","rc":[{"atl":[[1.74,0]],"id":42492389}],"con":true,"img":false}]}
{"op":"mcm","clk":"5346746469","pt":1646095841121,"mc":[{"id":"1.195395451","rc":[{"atb":[[12,0]],"id":39979879}],"con":true,"img":false}]}
{"op":"mcm","clk":"5346746472","pt":1646095841222,"mc":[{"id":"1.195395451","rc":[{"atb":[[12.5,0.88]],"id":39979879}],"con":true,"img":false}]}
{"op":"mcm","clk":"5346746488","pt":1646095842042,"mc":[{"id":"1.195395451","rc":[{"atl":[[2.08,8.67]],"id":42492389}],"con":true,"img":false}]}
{"op":"mcm","clk":"5346746498","pt":1646095842403,"mc":[{"id":"1.195395451","rc":[{"atl":[[1.7,0]],"id":42492389}],"con":true,"img":false}]}
{"op":"mcm","clk":"5346746502","pt":1646095842504,"mc":[{"id":"1.195395451","rc":[{"atl":[[1.78,86.54],[1.69,0],[1.72,43.26]],"id":42492389}],"con":true,"img":false}]}
{"op":"mcm","clk":"5346747060","pt":1646095861664,"mc":[{"id":"1.195395451","rc":[{"atl":[[1.72,0]],"id":42492389}],"con":true,"img":false}]}
{"op":"mcm","clk":"5346747067","pt":1646095861766,"mc":[{"id":"1.195395451","rc":[{"atl":[[1.77,43.26]],"id":42492389}],"con":true,"img":false}]}
{"op":"mcm","clk":"5346747135","pt":1646095864277,"mc":[{"id":"1.195395451","rc":[{"atl":[[1.78,0],[1.76,43.27]],"id":42492389}],"con":true,"img":false}]}
{"op":"mcm","clk":"5346747718","pt":1646095880786,"mc":[{"id":"1.195395451","rc":[{"atl":[[2.12,0]],"id":42492389}],"con":true,"img":false}]}
{"op":"mcm","clk":"5346747724","pt":1646095880942,"mc":[{"id":"1.195395451","rc":[{"atl":[[1.96,130.88]],"id":42492389}],"con":true,"img":false}]}
{"op":"mcm","clk":"5346748503","pt":1646095902626,"mc":[{"id":"1.195395451","rc":[{"atl":[[1.97,0]],"id":42492389}],"con":true,"img":false}]}
{"op":"mcm","clk":"5346748676","pt":1646095908366,"mc":[{"id":"1.195395451","rc":[{"atl":[[1.93,9.52]],"id":42492389}],"con":true,"img":false}]}
{"op":"mcm","clk":"5346748967","pt":1646095918371,"mc":[{"id":"1.195395451","rc":[{"atl":[[1.77,0]],"id":42492389}],"con":true,"img":false}]}
{"op":"mcm","clk":"5346748972","pt":1646095918464,"mc":[{"id":"1.195395451","rc":[{"atl":[[1.78,86.54],[1.75,43.26]],"id":42492389}],"con":true,"img":false}]}
{"op":"mcm","clk":"5346748976","pt":1646095918564,"mc":[{"id":"1.195395451","rc":[{"atl":[[1.78,0],[1.76,0],[1.74,43.27]],"id":42492389}],"con":true,"img":false}]}
{"op":"mcm","clk":"5346750052","pt":1646095955540,"mc":[{"id":"1.195395451","rc":[{"atl":[[1.96,0]],"id":42492389}],"con":true,"img":false}]}
{"op":"mcm","clk":"5346750056","pt":1646095955645,"mc":[{"id":"1.195395451","rc":[{"atl":[[1.92,130.88]],"id":42492389}],"con":true,"img":false}]}
{"op":"mcm","clk":"5346750163","pt":1646095959349,"mc":[{"id":"1.195395451","rc":[{"atl":[[2.08,0]],"id":42492389}],"con":true,"img":false}]}
{"op":"mcm","clk":"5346750237","pt":1646095962370,"mc":[{"id":"1.195395451","rc":[{"atl":[[1.72,10.48]],"id":42492389}],"con":true,"img":false}]}
{"op":"mcm","clk":"5346750240","pt":1646095962576,"mc":[{"id":"1.195395451","rc":[{"atl":[[1.71,43.27],[1.74,0]],"id":42492389}],"con":true,"img":false}]}
{"op":"mcm","clk":"5346750560","pt":1646095974156,"mc":[{"id":"1.195395451","rc":[{"atl":[[1.75,0]],"id":42492389}],"con":true,"img":false}]}
{"op":"mcm","clk":"5346750561","pt":1646095974256,"mc":[{"id":"1.195395451","rc":[{"atl":[[1.73,43.26]],"id":42492389}],"con":true,"img":false}]}
{"op":"mcm","clk":"5346751664","pt":1646096010274,"mc":[{"id":"1.195395451","rc":[{"atl":[[1.73,0]],"id":42492389}],"con":true,"img":false}]}
{"op":"mcm","clk":"5346751668","pt":1646096010370,"mc":[{"id":"1.195395451","rc":[{"atl":[[1.7,43.26]],"id":42492389}],"con":true,"img":false}]}
{"op":"mcm","clk":"5346751675","pt":1646096010525,"mc":[{"id":"1.195395451","rc":[{"atl":[[1.71,0],[1.69,43.27]],"id":42492389}],"con":true,"img":false}]}
{"op":"mcm","clk":"5346751971","pt":1646096020675,"mc":[{"id":"1.195395451","rc":[{"atb":[[4.6,0],[5.2,23.81]],"id":41921674},{"atl":[[260,0],[170,2.78]],"id":36899924},{"atb":[[5.8,20.83],[7.4,0]],"id":39979879},{"atl":[[75,4.7],[85,0]],"id":39979879},{"atb":[[9.2,12.2],[11.5,0]],"id":39722911},{"atl":[[160,2],[250,0]],"id":39722911}],"con":true,"img":false}]}
{"op":"mcm","clk":"5346752203","pt":1646096028661,"mc":[{"id":"1.195395451","rc":[{"atl":[[1.93,0]],"id":42492389}],"con":true,"img":false}]}
{"op":"mcm","clk":"5346752321","pt":1646096033592,"mc":[{"id":"1.195395451","rc":[{"atb":[[4.3,30.3],[5.2,0]],"id":41921674},{"atl":[[130,2],[170,0.78]],"id":36899924},{"atb":[[9.6,0],[8.2,13.89]],"id":40251221},{"atl":[[130,2],[190,0]],"id":40251221},{"atb":[[5.8,0],[4.9,25.64]],"id":39979879},{"atl":[[140,2],[160,0]],"id":39722911},{"atl":[[1.82,115.96],[1.69,0]],"id":42492389},{"atb":[[18.5,7.47],[21,2.02]],"id":27151693},{"atl":[[400,2],[460,0]],"id":27151693},{"atb":[[7.8,0],[6.6,17.86]],"id":43154431}],"con":true,"img":false}]}
{"op":"mcm","clk":"5346752362","pt":1646096034889,"mc":[{"id":"1.195395451","rc":[{"atl":[[1.8,10.2]],"id":42492389}],"con":true,"img":false}]}
{"op":"mcm","clk":"5346752716","pt":1646096046207,"mc":[{"id":"1.195395451","rc":[{"atl":[[1.92,0],[1.7,0]],"id":42492389}],"con":true,"img":false}]}
{"op":"mcm","clk":"5346752720","pt":1646096046312,"mc":[{"id":"1.195395451","rc":[{"atl":[[1.78,43.26],[2.12,130.88]],"id":42492389}],"con":true,"img":false}]}
{"op":"mcm","clk":"5346752812","pt":1646096048494,"mc":[{"id":"1.195395451","rc":[{"atb":[[9,21.5],[11,0]],"id":36899924},{"atb":[[1.12,833.33]],"id":42492389}],"con":true,"img":false}]}
{"op":"mcm","clk":"5346752974","pt":1646096053424,"mc":[{"id":"1.195395451","rc":[{"atb":[[4.9,0],[5.4,22.73]],"id":39979879}],"con":true,"img":false}]}
{"op":"mcm","clk":"5346753899","pt":1646096079647,"mc":[{"id":"1.195395451","rc":[{"atl":[[1.72,0]],"id":42492389}],"con":true,"img":false}]}
{"op":"mcm","clk":"5346754019","pt":1646096082573,"mc":[{"id":"1.195395451","rc":[{"atl":[[1.76,10.24]],"id":42492389}],"con":true,"img":false}]}
{"op":"mcm","clk":"5346754703","pt":1646096100712,"mc":[{"id":"1.195395451","rc":[{"atb":[[1.11,0]],"id":42492389}],"con":true,"img":false}]}
{"op":"mcm","clk":"5346754707","pt":1646096100812,"mc":[{"id":"1.195395451","rc":[{"atb":[[1.13,1187.19]],"id":42492389}],"con":true,"img":false}]}
{"op":"mcm","clk":"5346754811","pt":1646096103229,"mc":[{"id":"1.195395451","rc":[{"atb":[[8,20.24],[6.8,21.55],[7.2,12.1],[7.6,7.58]],"id":41921674},{"atl":[[32,2.42],[36,3.57],[27,1],[29,1.79]],"id":41921674},{"atb":[[9,9],[10,11.11],[10.5,7.89],[11.5,4.76],[12.5,12.55],[9.8,14.2]],"id":36899924},{"atl":[[190,1],[210,1],[230,1],[250,1]],"id":36899924},{"atb":[[10,15.74],[9.2,9.15],[9.6,5.81],[8.8,16.03]],"id":40251221},{"atl":[[38,1],[42,1.22],[46,1.67],[50,2.55]],"id":40251221},{"atb":[[9.2,23.99],[10,2.22],[9.6,5.81],[8.8,16.03]],"id":39979879},{"atl":[[34,1],[38,1.35],[42,1.83],[46,2.78]],"id":39979879},{"atb":[[11,12.5],[12,17.88],[13,4.17],[14,1.54]],"id":39722911},{"atl":[[260,1],[280,1],[220,1.9],[240,1]],"id":39722911},{"atb":[[1.15,403.76],[1.11,250],[1.09,250],[1.13,1437.19]],"id":42492389},{"atl":[[1.68,73.53],[1.7,107.14],[1.71,176.06],[1.69,108.7],[1.72,173.61],[1.67,74.63],[1.65,30.77],[1.66,30.3]],"id":42492389},{"atb":[[12,11.36],[13,6.25],[14,3.85],[15,1.43],[18.5,2.7],[19,5.56]],"id":27151693},{"atl":[[450,1],[470,1],[490,1],[510,1]],"id":27151693},{"atb":[[10.5,7.89],[11.5,4.76],[12.5,1.74],[9.8,14.2]],"id":43154431},{"atl":[[270,1],[290,1],[230,1.86],[250,1]],"id":43154431}],"con":true,"img":false}]}
{"op":"mcm","clk":"5346754818","pt":1646096103435,"mc":[{"id":"1.195395451","rc":[{"atl":[[48,2.7],[29,4.21]],"id":41921674},{"atl":[[75,2.7],[38,3.35]],"id":39979879},{"atb":[[18.5,7.47],[19,0]],"id":27151693}],"con":true,"img":false}]}
{"op":"mcm","clk":"5346754937","pt":1646096106103,"mc":[{"id":"1.195395451","rc":[{"atl":[[1.68,0],[1.7,0],[1.72,0],[1.66,0]],"id":42492389}],"con":true,"img":false}]}
{"op":"mcm","clk":"5346755042","pt":1646096108517,"mc":[{"id":"1.195395451","rc":[{"atl":[[32,5.65],[29,1.79]],"id":41921674},{"atl":[[42,4.27]],"id":39979879}],"con":true,"img":false}]}
{"op":"mcm","clk":"5346755045","pt":1646096108620,"mc":[{"id":"1.195395451","rc":[{"atl":[[38,1.35]],"id":39979879}],"con":true,"img":false}]}
{"op":"mcm","clk":"5346755127","pt":1646096110725,"mc":[{"id":"1.195395451","rc":[{"atl":[[48,0]],"id":41921674},{"atl":[[110,0]],"id":36899924},{"atl":[[95,0]],"id":40251221},{"atl":[[75,0]],"id":39979879},{"atb":[[17.5,0]],"id":39722911},{"atl":[[110,0]],"id":39722911},{"atl":[[140,0]],"id":27151693}],"con":true,"img":false}]}
{"op":"mcm","clk":"5346755132","pt":1646096110827,"mc":[{"id":"1.195395451","rc":[{"atl":[[95,2.7]],"id":41921674},{"atl":[[120,3.81]],"id":36899924},{"atl":[[120,2.7]],"id":40251221},{"atl":[[120,2.7]],"id":39979879},{"atb":[[16.5,2.7]],"id":39722911},{"atl":[[130,2.7]],"id":39722911},{"atl":[[240,2.7]],"id":27151693}],"con":true,"img":false}]}
{"op":"mcm","clk":"5346755484","pt":1646096120748,"mc":[{"id":"1.195395451","rc":[{"atb":[[9.2,0]],"id":41921674},{"atl":[[90,0]],"id":36899924},{"atl":[[95,0]],"id":39722911},{"atl":[[120,0]],"id":27151693}],"con":true,"img":false}]}
{"op":"mcm","clk":"5346755489","pt":1646096120851,"mc":[{"id":"1.195395451","rc":[{"atb":[[8.2,13.12]],"id":41921674},{"atl":[[110,0.48]],"id":36899924},{"atl":[[120,1.56]],"id":39722911},{"atl":[[140,0.39]],"id":27151693}],"con":true,"img":false}]}
{"op":"mcm","clk":"5346755492","pt":1646096120954,"mc":[{"id":"1.195395451","rc":[{"atl":[[150,2]],"id":36899924}],"con":true,"img":false}]}
{"op":"mcm","clk":"5346755495","pt":1646096121057,"mc":[{"id":"1.195395451","rc":[{"atl":[[130,0]],"id":36899924}],"con":true,"img":false}]}
{"op":"mcm","clk":"5346755848","pt":1646096130765,"mc":[{"id":"1.195395451","rc":[{"atl":[[46,0]],"id":41921674},{"atl":[[120,1.1]],"id":36899924},{"atl":[[70,0]],"id":40251221}],"con":true,"img":false}]}
{"op":"mcm","clk":"5346755853","pt":1646096130867,"mc":[{"id":"1.195395451","rc":[{"atl":[[44,2.7]],"id":41921674},{"atl":[[140,2.7]],"id":36899924},{"atl":[[65,0.62]],"id":40251221}],"con":true,"img":false}]}
{"op":"mcm","clk":"5346756187","pt":1646096140278,"mc":[{"id":"1.195395451","rc":[{"atl":[[130,2],[150,0]],"id":36899924},{"atb":[[18.5,2.7],[19,5.56]],"id":27151693},{"atl":[[450,0],[460,1]],"id":27151693}],"con":true,"img":false}]}
{"op":"mcm","clk":"5346756199","pt":1646096140637,"mc":[{"id":"1.195395451","rc":[{"atl":[[40,2.7],[60,0]],"id":39979879},{"atb":[[1.14,932.98],[1.13,250]],"id":42492389},{"atl":[[1.78,0]],"id":42492389}],"con":true,"img":false}]}
{"op":"mcm","clk":"5346756203","pt":1646096140743,"mc":[{"id":"1.195395451","rc":[{"atl":[[38,4.05],[42,1.83]],"id":39979879},{"atl":[[1.64,43.26]],"id":42492389}],"con":true,"img":false}]}
{"op":"mcm","clk":"5346756350","pt":1646096145359,"mc":[{"id":"1.195395451","rc":[{"atl":[[130,0],[150,2]],"id":36899924},{"atb":[[18.5,7.47],[19,0]],"id":27151693}],"con":true,"img":false}]}
{"op":"mcm","clk":"5346756530","pt":1646096150295,"mc":[{"id":"1.195395451","rc":[{"atl":[[460,0],[450,1]],"id":27151693}],"con":true,"img":false}]}
{"op":"mcm","clk":"5346756549","pt":1646096150704,"mc":[{"id":"1.195395451","rc":[{"atb":[[9.4,0]],"id":39979879},{"atl":[[40,0],[55,0.8]],"id":39979879}],"con":true,"img":false}]}
{"op":"mcm","clk":"5346756552","pt":1646096150808,"mc":[{"id":"1.195395451","rc":[{"atb":[[9.8,14.06]],"id":39979879},{"atl":[[38,1.35],[42,4.27]],"id":39979879}],"con":true,"img":false}]}
{"op":"mcm","clk":"5346756581","pt":1646096151884,"mc":[{"id":"1.195395451","rc":[{"atl":[[450,0],[460,1]],"id":27151693}],"con":true,"img":false}]}
{"op":"mcm","clk":"5346756603","pt":1646096152710,"mc":[{"id":"1.195395451","rc":[{"atl":[[460,0],[450,1]],"id":27151693}],"con":true,"img":false}]}
{"op":"mcm","clk":"5346756681","pt":1646096155181,"mc":[{"id":"1.195395451","rc":[{"atl":[[1.8,0]],"id":42492389}],"con":true,"img":false}]}
{"op":"mcm","clk":"5346756898","pt":1646096161008,"mc":[{"id":"1.195395451","rc":[{"spn":19.0,"spf":1.0,"id":41921674},{"spn":58.75,"spf":1.0,"id":36899924},{"spn":23.5,"spf":1.0,"id":39979879},{"spn":59.75,"spf":1.0,"id":39722911},{"atl":[[1.65,41.9]],"id":42492389}],"con":true,"img":false}]}
{"op":"mcm","clk":"5346756980","pt":1646096163681,"mc":[{"id":"1.195395451","rc":[{"atl":[[130,2],[150,0]],"id":36899924},{"atb":[[18.5,2.7],[19,5.56]],"id":27151693},{"atl":[[460,1]],"id":27151693}],"con":true,"img":false}]}
{"op":"mcm","clk":"5346756982","pt":1646096163782,"mc":[{"id":"1.195395451","rc":[{"atl":[[130,0],[150,2]],"id":36899924},{"atb":[[18.5,7.47],[19,0]],"id":27151693},{"atl":[[450,0]],"id":27151693}],"con":true,"img":false}]}
{"op":"mcm","clk":"5346757017","pt":1646096164909,"mc":[{"id":"1.195395451","rc":[{"atl":[[450,1]],"id":27151693}],"con":true,"img":false}]}
{"op":"mcm","clk":"5346757020","pt":1646096165012,"mc":[{"id":"1.195395451","rc":[{"atl":[[460,0]],"id":27151693}],"con":true,"img":false}]}
{"op":"mcm","clk":"5346757038","pt":1646096165525,"mc":[{"id":"1.195395451","rc":[{"atb":[[12.5,0]],"id":39979879}],"con":true,"img":false}]}
{"op":"mcm","clk":"5346757044","pt":1646096165627,"mc":[{"id":"1.195395451","rc":[{"atb":[[11.5,0.96]],"id":39979879}],"con":true,"img":false}]}
{"op":"mcm","clk":"5346757768","pt":1646096187454,"mc":[{"id":"1.195395451","rc":[{"atl":[[130,2],[150,0]],"id":36899924},{"atb":[[18.5,2.7],[19,5.56]],"id":27151693},{"atl":[[450,0],[460,1]],"id":27151693}],"con":true,"img":false}]}
{"op":"mcm","clk":"5346757847","pt":1646096189658,"mc":[{"id":"1.195395451","rc":[{"atl":[[460,0],[450,1]],"id":27151693}],"con":true,"img":false}]}
{"op":"mcm","clk":"5346757951","pt":1646096192533,"mc":[{"id":"1.195395451","rc":[{"atl":[[130,0],[150,2]],"id":36899924},{"atb":[[18.5,7.47],[19,0]],"id":27151693}],"con":true,"img":false}]}
{"op":"mcm","clk":"5346758198","pt":1646096199783,"mc":[{"id":"1.195395451","rc":[{"atl":[[450,0],[460,1]],"id":27151693}],"con":true,"img":false}]}
{"op":"mcm","clk":"5346758200","pt":1646096199886,"mc":[{"id":"1.195395451","rc":[{"atl":[[1.76,0]],"id":42492389}],"con":true,"img":false}]}
{"op":"mcm","clk":"5346758227","pt":1646096200658,"mc":[{"id":"1.195395451","rc":[{"atl":[[140,0]],"id":27151693}],"con":true,"img":false}]}
{"op":"mcm","clk":"5346758233","pt":1646096200760,"mc":[{"id":"1.195395451","rc":[{"atl":[[130,0.39]],"id":27151693}],"con":true,"img":false}]}
{"op":"mcm","clk":"5346758285","pt":1646096202257,"mc":[{"id":"1.195395451","rc":[{"atl":[[460,0],[450,1]],"id":27151693}],"con":true,"img":false}]}
{"op":"mcm","clk":"5346758302","pt":1646096202768,"mc":[{"id":"1.195395451","rc":[{"atl":[[1.65,52.83]],"id":42492389}],"con":true,"img":false}]}
{"op":"mcm","clk":"5346758682","pt":1646096211876,"mc":[{"id":"1.195395451","rc":[{"atl":[[130,2],[150,0]],"id":36899924},{"atb":[[18.5,2.7],[19,5.56]],"id":27151693},{"atl":[[460,1]],"id":27151693}],"con":true,"img":false}]}
{"op":"mcm","clk":"5346758686","pt":1646096211979,"mc":[{"id":"1.195395451","rc":[{"atl":[[450,0]],"id":27151693}],"con":true,"img":false}]}
{"op":"mcm","clk":"5346758810","pt":1646096214708,"mc":[{"id":"1.195395451","rc":[{"atl":[[460,0],[450,1]],"id":27151693}],"con":true,"img":false}]}
{"op":"mcm","clk":"5346758921","pt":1646096217018,"mc":[{"id":"1.195395451","rc":[{"atl":[[150,2]],"id":36899924},{"atb":[[18.5,7.47],[19,0]],"id":27151693}],"con":true,"img":false}]}
{"op":"mcm","clk":"5346758930","pt":1646096217226,"mc":[{"id":"1.195395451","rc":[{"atl":[[130,0]],"id":36899924}],"con":true,"img":false}]}
{"op":"mcm","clk":"5346759224","pt":1646096223411,"mc":[{"id":"1.195395451","rc":[{"atl":[[450,0],[460,1]],"id":27151693}],"con":true,"img":false}]}
{"op":"mcm","clk":"5346759388","pt":1646096226724,"mc":[{"id":"1.195395451","rc":[{"atl":[[450,1]],"id":27151693}],"con":true,"img":false}]}
{"op":"mcm","clk":"5346759394","pt":1646096226825,"mc":[{"id":"1.195395451","rc":[{"atl":[[460,0]],"id":27151693}],"con":true,"img":false}]}
{"op":"mcm","clk":"5346759841","pt":1646096235719,"mc":[{"id":"1.195395451","rc":[{"atl":[[130,2],[150,0]],"id":36899924},{"atb":[[18.5,2.7],[19,5.56]],"id":27151693},{"atl":[[460,1]],"id":27151693}],"con":true,"img":false}]}
{"op":"mcm","clk":"5346759847","pt":1646096235825,"mc":[{"id":"1.195395451","rc":[{"atl":[[450,0]],"id":27151693}],"con":true,"img":false}]}
{"op":"mcm","clk":"5346759939","pt":1646096238033,"mc":[{"id":"1.195395451","rc":[{"atl":[[460,0],[450,1]],"id":27151693}],"con":true,"img":false}]}
{"op":"mcm","clk":"5346760050","pt":1646096240806,"mc":[{"id":"1.195395451","rc":[{"atl":[[130,0],[150,2]],"id":36899924},{"atb":[[18.5,7.47],[19,0]],"id":27151693}],"con":true,"img":false}]}
{"op":"mcm","clk":"5346760377","pt":1646096247750,"mc":[{"id":"1.195395451","rc":[{"atl":[[460,1]],"id":27151693}],"con":true,"img":false}]}
{"op":"mcm","clk":"5346760384","pt":1646096247849,"mc":[{"id":"1.195395451","rc":[{"atl":[[450,0]],"id":27151693}],"con":true,"img":false}]}
{"op":"mcm","clk":"5346760481","pt":1646096249957,"mc":[{"id":"1.195395451","rc":[{"atl":[[460,0],[450,1]],"id":27151693}],"con":true,"img":false}]}
{"op":"mcm","clk":"5346760875","pt":1646096259666,"mc":[{"id":"1.195395451","rc":[{"atl":[[130,2],[150,0]],"id":36899924},{"atb":[[18.5,2.7],[19,5.56]],"id":27151693},{"atl":[[450,0],[460,1]],"id":27151693}],"con":true,"img":false}]}
{"op":"mcm","clk":"5346761002","pt":1646096262284,"mc":[{"id":"1.195395451","rc":[{"atl":[[450,1]],"id":27151693}],"con":true,"img":false}]}
{"op":"mcm","clk":"5346761006","pt":1646096262387,"mc":[{"id":"1.195395451","rc":[{"atl":[[460,0]],"id":27151693}],"con":true,"img":false}]}
{"op":"mcm","clk":"5346761088","pt":1646096264754,"mc":[{"id":"1.195395451","rc":[{"atl":[[150,2]],"id":36899924},{"atb":[[18.5,7.47],[19,0]],"id":27151693}],"con":true,"img":false}]}
{"op":"mcm","clk":"5346761091","pt":1646096264904,"mc":[{"id":"1.195395451","rc":[{"atl":[[130,0]],"id":36899924}],"con":true,"img":false}]}
{"op":"mcm","clk":"5346761384","pt":1646096272099,"mc":[{"id":"1.195395451","rc":[{"atl":[[450,0],[460,1]],"id":27151693}],"con":true,"img":false}]}
{"op":"mcm","clk":"5346761478","pt":1646096274315,"mc":[{"id":"1.195395451","rc":[{"atl":[[460,0],[450,1]],"id":27151693}],"con":true,"img":false}]}
{"op":"mcm","clk":"5346761729","pt":1646096281312,"mc":[{"id":"1.195395451","rc":[{"atl":[[1.65,41.69]],"id":42492389}],"con":true,"img":false}]}
{"op":"mcm","clk":"5346761808","pt":1646096283419,"mc":[{"id":"1.195395451","rc":[{"atl":[[130,2],[150,0]],"id":36899924},{"atb":[[18.5,2.7],[19,5.56]],"id":27151693},{"atl":[[450,0],[460,1]],"id":27151693}],"con":true,"img":false}]}
{"op":"mcm","clk":"5346761811","pt":1646096283521,"mc":[{"id":"1.195395451","rc":[{"atl":[[130,0],[150,2]],"id":36899924},{"atb":[[18.5,8.41],[19,0]],"id":27151693}],"con":true,"img":false}]}
{"op":"mcm","clk":"5346761929","pt":1646096286613,"mc":[{"id":"1.195395451","rc":[{"atl":[[460,0],[450,1]],"id":27151693}],"con":true,"img":false}]}
{"op":"mcm","clk":"5346761970","pt":1646096287437,"mc":[{"id":"1.195395451","rc":[{"atl":[[1.65,52.83]],"id":42492389}],"con":true,"img":false}]}
{"op":"mcm","clk":"5346762266","pt":1646096295744,"mc":[{"id":"1.195395451","rc":[{"atl":[[130,2],[150,0]],"id":36899924},{"atb":[[18.5,2.7],[19,5.56]],"id":27151693},{"atl":[[450,0],[460,1]],"id":27151693}],"con":true,"img":false}]}
{"op":"mcm","clk":"5346762377","pt":1646096298628,"mc":[{"id":"1.195395451","rc":[{"atl":[[460,0],[450,1]],"id":27151693}],"con":true,"img":false}]}
{"op":"mcm","clk":"5346762451","pt":1646096300843,"mc":[{"id":"1.195395451","rc":[{"atl":[[130,0],[150,2]],"id":36899924},{"atb":[[18.5,7.47],[19,0]],"id":27151693}],"con":true,"img":false}]}
{"op":"mcm","clk":"5346763059","pt":1646096320070,"mc":[{"id":"1.195395451","rc":[{"atl":[[1.65,41.9]],"id":42492389}],"con":true,"img":false}]}
{"op":"mcm","clk":"5346763069","pt":1646096320380,"mc":[{"id":"1.195395451","rc":[{"atl":[[130,2],[150,0]],"id":36899924},{"atb":[[18.5,2.7],[19,5.56]],"id":27151693},{"atl":[[450,0],[460,1]],"id":27151693}],"con":true,"img":false}]}
{"op":"mcm","clk":"5346763142","pt":1646096322992,"mc":[{"id":"1.195395451","rc":[{"atl":[[1.65,52.83]],"id":42492389}],"con":true,"img":false}]}
{"op":"mcm","clk":"5346763150","pt":1646096323298,"mc":[{"id":"1.195395451","rc":[{"atl":[[450,1]],"id":27151693}],"con":true,"img":false}]}
{"op":"mcm","clk":"5346763152","pt":1646096323400,"mc":[{"id":"1.195395451","rc":[{"atl":[[460,0]],"id":27151693}],"con":true,"img":false}]}
{"op":"mcm","clk":"5346763200","pt":1646096325506,"mc":[{"id":"1.195395451","rc":[{"atl":[[150,2]],"id":36899924},{"atb":[[18.5,7.47],[19,0]],"id":27151693}],"con":true,"img":false}]}
{"op":"mcm","clk":"5346763204","pt":1646096325607,"mc":[{"id":"1.195395451","rc":[{"atl":[[130,0]],"id":36899924}],"con":true,"img":false}]}
{"op":"mcm","clk":"5346763375","pt":1646096332082,"mc":[{"id":"1.195395451","rc":[{"atl":[[450,0],[460,1]],"id":27151693}],"con":true,"img":false}]}
{"op":"mcm","clk":"5346763463","pt":1646096335002,"mc":[{"id":"1.195395451","rc":[{"atl":[[450,1]],"id":27151693}],"con":true,"img":false}]}
{"op":"mcm","clk":"5346763466","pt":1646096335104,"mc":[{"id":"1.195395451","rc":[{"atl":[[460,0]],"id":27151693}],"con":true,"img":false}]}
{"op":"mcm","clk":"5346763660","pt":1646096343513,"mc":[{"id":"1.195395451","rc":[{"atl":[[130,2]],"id":36899924},{"atb":[[18.5,2.7],[19,5.56]],"id":27151693},{"atl":[[450,0],[460,1]],"id":27151693}],"con":true,"img":false}]}
{"op":"mcm","clk":"5346763663","pt":1646096343616,"mc":[{"id":"1.195395451","rc":[{"atl":[[150,0]],"id":36899924},{"atb":[[18.5,8.41]],"id":27151693}],"con":true,"img":false}]}
{"op":"mcm","clk":"5346763666","pt":1646096343717,"mc":[{"id":"1.195395451","rc":[{"atl":[[130,0],[150,2]],"id":36899924},{"atb":[[19,0]],"id":27151693}],"con":true,"img":false}]}
{"op":"mcm","clk":"5346763739","pt":1646096346335,"mc":[{"id":"1.195395451","rc":[{"atl":[[460,0],[450,1]],"id":27151693}],"con":true,"img":false}]}
{"op":"mcm","clk":"5346763995","pt":1646096355757,"mc":[{"id":"1.195395451","rc":[{"atl":[[130,2],[150,0]],"id":36899924},{"atb":[[18.5,2.7],[19,5.56]],"id":27151693},{"atl":[[450,0],[460,1]],"id":27151693}],"con":true,"img":false}]}
{"op":"mcm","clk":"5346763996","pt":1646096355861,"mc":[{"id":"1.195395451","rc":[{"atl":[[130,0],[150,2]],"id":36899924},{"atb":[[18.5,8.41],[19,0]],"id":27151693}],"con":true,"img":false}]}
{"op":"mcm","clk":"5346764070","pt":1646096358020,"mc":[{"id":"1.195395451","rc":[{"atl":[[460,0],[450,1]],"id":27151693}],"con":true,"img":false}]}
{"op":"mcm","clk":"5346764401","pt":1646096367880,"mc":[{"id":"1.195395451","rc":[{"atl":[[130,2],[150,0]],"id":36899924},{"atb":[[18.5,2.7],[19,5.56]],"id":27151693},{"atl":[[450,0],[460,1]],"id":27151693}],"con":true,"img":false}]}
{"op":"mcm","clk":"5346764456","pt":1646096369783,"mc":[{"id":"1.195395451","rc":[{"atl":[[460,0],[450,1]],"id":27151693}],"con":true,"img":false}]}
{"op":"mcm","clk":"5346764544","pt":1646096372966,"mc":[{"id":"1.195395451","rc":[{"atl":[[150,2]],"id":36899924},{"atb":[[18.5,7.47]],"id":27151693}],"con":true,"img":false}]}
{"op":"mcm","clk":"5346764547","pt":1646096373071,"mc":[{"id":"1.195395451","rc":[{"atl":[[130,0]],"id":36899924},{"atb":[[19,0]],"id":27151693}],"con":true,"img":false}]}
{"op":"mcm","clk":"5346764757","pt":1646096379695,"mc":[{"id":"1.195395451","rc":[{"atl":[[450,0],[460,1]],"id":27151693}],"con":true,"img":false}]}
{"op":"mcm","clk":"5346764804","pt":1646096381698,"mc":[{"id":"1.195395451","rc":[{"atl":[[460,0],[450,1]],"id":27151693}],"con":true,"img":false}]}
{"op":"mcm","clk":"5346765102","pt":1646096391494,"mc":[{"id":"1.195395451","rc":[{"atl":[[130,2],[150,0]],"id":36899924},{"atb":[[18.5,2.7],[19,5.56]],"id":27151693},{"atl":[[450,0],[460,1]],"id":27151693}],"con":true,"img":false}]}
{"op":"mcm","clk":"5346765158","pt":1646096393696,"mc":[{"id":"1.195395451","rc":[{"atl":[[460,0],[450,1]],"id":27151693}],"con":true,"img":false}]}
{"op":"mcm","clk":"5346765242","pt":1646096396617,"mc":[{"id":"1.195395451","rc":[{"atl":[[130,0],[150,2]],"id":36899924},{"atb":[[18.5,7.47],[19,0]],"id":27151693}],"con":true,"img":false}]}
{"op":"mcm","clk":"5346765510","pt":1646096403829,"mc":[{"id":"1.195395451","rc":[{"atl":[[450,0],[460,1]],"id":27151693}],"con":true,"img":false}]}
{"op":"mcm","clk":"5346765593","pt":1646096405425,"mc":[{"id":"1.195395451","rc":[{"atl":[[460,0],[450,1]],"id":27151693}],"con":true,"img":false}]}
{"op":"mcm","clk":"5346765667","pt":1646096407528,"mc":[{"id":"1.195395451","rc":[{"atl":[[1.65,41.69]],"id":42492389}],"con":true,"img":false}]}
{"op":"mcm","clk":"5346765871","pt":1646096413542,"mc":[{"id":"1.195395451","rc":[{"atl":[[1.65,52.83]],"id":42492389}],"con":true,"img":false}]}
{"op":"mcm","clk":"5346765913","pt":1646096415034,"mc":[{"id":"1.195395451","rc":[{"atl":[[130,2],[150,0]],"id":36899924},{"atb":[[18.5,2.7]],"id":27151693},{"atl":[[460,1]],"id":27151693}],"con":true,"img":false}]}
{"op":"mcm","clk":"5346765917","pt":1646096415134,"mc":[{"id":"1.195395451","rc":[{"atl":[[130,0],[150,2]],"id":36899924},{"atb":[[19,5.56]],"id":27151693},{"atl":[[450,0]],"id":27151693}],"con":true,"img":false}]}
{"op":"mcm","clk":"5346765988","pt":1646096417751,"mc":[{"id":"1.195395451","rc":[{"atl":[[460,0],[450,1]],"id":27151693}],"con":true,"img":false}]}
{"op":"mcm","clk":"5346766076","pt":1646096420229,"mc":[{"id":"1.195395451","rc":[{"atb":[[18.5,7.47]],"id":27151693}],"con":true,"img":false}]}
{"op":"mcm","clk":"5346766079","pt":1646096420331,"mc":[{"id":"1.195395451","rc":[{"atb":[[19,0]],"id":27151693}],"con":true,"img":false}]}
{"op":"mcm","clk":"5346766321","pt":1646096426962,"mc":[{"id":"1.195395451","rc":[{"atl":[[460,1]],"id":27151693}],"con":true,"img":false}]}
{"op":"mcm","clk":"5346766324","pt":1646096427066,"mc":[{"id":"1.195395451","rc":[{"atl":[[450,0]],"id":27151693}],"con":true,"img":false}]}
{"op":"mcm","clk":"5346766394","pt":1646096429477,"mc":[{"id":"1.195395451","rc":[{"atl":[[460,0],[450,1]],"id":27151693}],"con":true,"img":false}]}
{"op":"mcm","clk":"5346766786","pt":1646096439198,"mc":[{"id":"1.195395451","rc":[{"atb":[[19,5.56]],"id":27151693}],"con":true,"img":false}]}
{"op":"mcm","clk":"5346766789","pt":1646096439302,"mc":[{"id":"1.195395451","rc":[{"atl":[[130,2],[150,0]],"id":36899924},{"atb":[[18.5,2.7]],"id":27151693}],"con":true,"img":false}]}
{"op":"mcm","clk":"5346766834","pt":1646096440177,"mc":[{"id":"1.195395451","rc":[{"atl":[[1.65,41.9]],"id":42492389}],"con":true,"img":false}]}
{"op":"mcm","clk":"5346766945","pt":1646096443162,"mc":[{"id":"1.195395451","rc":[{"atl":[[1.65,52.83]],"id":42492389}],"con":true,"img":false}]}
{"op":"mcm","clk":"5346766982","pt":1646096444292,"mc":[{"id":"1.195395451","rc":[{"atb":[[18.5,7.47],[19,0]],"id":27151693}],"con":true,"img":false}]}
{"op":"mcm","clk":"5346766986","pt":1646096444394,"mc":[{"id":"1.195395451","rc":[{"atl":[[130,0],[150,2]],"id":36899924}],"con":true,"img":false}]}
{"op":"mcm","clk":"5346767647","pt":1646096463126,"mc":[{"id":"1.195395451","rc":[{"atl":[[130,2]],"id":36899924},{"atb":[[18.5,2.7],[19,5.56]],"id":27151693}],"con":true,"img":false}]}
{"op":"mcm","clk":"5346767655","pt":1646096463233,"mc":[{"id":"1.195395451","rc":[{"atl":[[150,0]],"id":36899924},{"atb":[[18.5,7.47]],"id":27151693}],"con":true,"img":false}]}
{"op":"mcm","clk":"5346767661","pt":1646096463334,"mc":[{"id":"1.195395451","rc":[{"atl":[[130,0],[150,2]],"id":36899924},{"atb":[[19,0]],"id":27151693}],"con":true,"img":false}]}
{"op":"mcm","clk":"5346768078","pt":1646096474534,"mc":[{"id":"1.195395451","rc":[{"atb":[[18.5,2.7],[19,5.56]],"id":27151693}],"con":true,"img":false}]}
{"op":"mcm","clk":"5346768285","pt":1646096479732,"mc":[{"id":"1.195395451","rc":[{"atb":[[18.5,7.47],[19,0]],"id":27151693}],"con":true,"img":false}]}
{"op":"mcm","clk":"5346768551","pt":1646096486064,"mc":[{"id":"1.195395451","rc":[{"atl":[[130,2],[150,0]],"id":36899924}],"con":true,"img":false}]}
{"op":"mcm","clk":"5346768559","pt":1646096486168,"mc":[{"id":"1.195395451","rc":[{"atl":[[130,0],[150,2]],"id":36899924}],"con":true,"img":false}]}
{"op":"mcm","clk":"5346769053","pt":1646096498046,"mc":[{"id":"1.195395451","rc":[{"atl":[[130,2],[150,0]],"id":36899924},{"atb":[[18.5,2.7],[19,5.56]],"id":27151693}],"con":true,"img":false}]}
{"op":"mcm","clk":"5346769060","pt":1646096498251,"mc":[{"id":"1.195395451","rc":[{"atl":[[130,0],[150,2]],"id":36899924},{"atb":[[18.5,7.47]],"id":27151693}],"con":true,"img":false}]}
{"op":"mcm","clk":"5346769064","pt":1646096498353,"mc":[{"id":"1.195395451","rc":[{"atb":[[19,0]],"id":27151693}],"con":true,"img":false}]}
{"op":"mcm","clk":"5346769834","pt":1646096521423,"mc":[{"id":"1.195395451","rc":[{"atl":[[130,2],[150,0]],"id":36899924},{"atb":[[18.5,2.7],[19,5.56]],"id":27151693}],"con":true,"img":false}]}
{"op":"mcm","clk":"5346769994","pt":1646096526498,"mc":[{"id":"1.195395451","rc":[{"atl":[[150,2]],"id":36899924}],"con":true,"img":false}]}
{"op":"mcm","clk":"5346769998","pt":1646096526601,"mc":[{"id":"1.195395451","rc":[{"atl":[[130,0]],"id":36899924},{"atb":[[18.5,7.47],[19,0]],"id":27151693}],"con":true,"img":false}]}
{"op":"mcm","clk":"5346770147","pt":1646096531222,"mc":[{"id":"1.195395451","rc":[{"atl":[[1.65,41.69]],"id":42492389}],"con":true,"img":false}]}
{"op":"mcm","clk":"5346770338","pt":1646096537036,"mc":[{"id":"1.195395451","rc":[{"atl":[[1.65,52.83]],"id":42492389}],"con":true,"img":false}]}
{"op":"mcm","clk":"5346770669","pt":1646096545720,"mc":[{"id":"1.195395451","rc":[{"atl":[[130,2],[150,0]],"id":36899924},{"atb":[[18.5,2.7],[19,5.56]],"id":27151693}],"con":true,"img":false}]}
{"op":"mcm","clk":"5346770860","pt":1646096550934,"mc":[{"id":"1.195395451","rc":[{"atl":[[130,0],[150,2]],"id":36899924},{"atb":[[18.5,7.47],[19,0]],"id":27151693}],"con":true,"img":false}]}
{"op":"mcm","clk":"5346771207","pt":1646096560454,"mc":[{"id":"1.195395451","rc":[{"atl":[[1.65,41.9]],"id":42492389}],"con":true,"img":false}]}
{"op":"mcm","clk":"5346771309","pt":1646096563388,"mc":[{"id":"1.195395451","rc":[{"atl":[[1.65,52.83]],"id":42492389}],"con":true,"img":false}]}
{"op":"mcm","clk":"5346771328","pt":1646096564055,"mc":[{"id":"1.195395451","rc":[{"atl":[[450,0],[460,1]],"id":27151693}],"con":true,"img":false}]}
{"op":"mcm","clk":"5346771385","pt":1646096565596,"mc":[{"id":"1.195395451","rc":[{"atb":[[18.5,2.7],[19,5.56]],"id":27151693}],"con":true,"img":false}]}
{"op":"mcm","clk":"5346771530","pt":1646096569697,"mc":[{"id":"1.195395451","rc":[{"atb":[[19.5,4.6],[19,0]],"id":27151693},{"atl":[[1.65,22.06],[1.66,30.3]],"id":42492389}],"con":true,"img":false}]}
{"op":"mcm","clk":"5346771574","pt":1646096570673,"mc":[{"id":"1.195395451","rc":[{"atl":[[1.64,0]],"id":42492389}],"con":true,"img":false}]}
{"op":"mcm","clk":"5346771578","pt":1646096570778,"mc":[{"id":"1.195395451","rc":[{"atl":[[1.65,65.33]],"id":42492389}],"con":true,"img":false}]}
{"op":"mcm","clk":"5346771663","pt":1646096572885,"mc":[{"id":"1.195395451","rc":[{"atl":[[1.65,96.1]],"id":42492389}],"con":true,"img":false}]}
{"op":"mcm","clk":"5346771668","pt":1646096572990,"mc":[{"id":"1.195395451","rc":[{"atl":[[1.66,0]],"id":42492389}],"con":true,"img":false}]}
{"op":"mcm","clk":"5346771716","pt":1646096574073,"mc":[{"id":"1.195395451","rc":[{"atl":[[480,1]],"id":27151693}],"con":true,"img":false}]}
{"op":"mcm","clk":"5346771736","pt":1646096574790,"mc":[{"id":"1.195395451","rc":[{"atb":[[19.5,0.55],[19,5.56]],"id":27151693}],"con":true,"img":false}]}
{"op":"mcm","clk":"5346772002","pt":1646096581497,"mc":[{"id":"1.195395451","rc":[{"atl":[[1.65,65.33]],"id":42492389}],"con":true,"img":false}]}
{"op":"mcm","clk":"5346772005","pt":1646096581598,"mc":[{"id":"1.195395451","rc":[{"atl":[[1.66,30.3]],"id":42492389},{"atl":[[470,0],[490,0],[510,0]],"id":27151693}],"con":true,"img":false}]}
{"op":"mcm","clk":"5346772080","pt":1646096584111,"mc":[{"id":"1.195395451","rc":[{"atl":[[500,1]],"id":27151693}],"con":true,"img":false}]}
{"op":"mcm","clk":"5346772119","pt":1646096585188,"mc":[{"id":"1.195395451","rc":[{"atl":[[1.65,96.1],[1.66,0]],"id":42492389}],"con":true,"img":false}]}
{"op":"mcm","clk":"5346772492","pt":1646096593703,"mc":[{"id":"1.195395451","rc":[{"atl":[[1.65,65.33],[1.66,30.3]],"id":42492389},{"atb":[[19.5,4.6],[19,0]],"id":27151693}],"con":true,"img":false}]}
{"op":"mcm","clk":"5346772501","pt":1646096593910,"mc":[{"id":"1.195395451","rc":[{"atb":[[19.5,0.55],[19,5.56]],"id":27151693}],"con":true,"img":false}]}
{"op":"mcm","clk":"5346772508","pt":1646096594114,"mc":[{"id":"1.195395451","rc":[{"atl":[[520,1]],"id":27151693}],"con":true,"img":false}]}
{"op":"mcm","clk":"5346772663","pt":1646096597454,"mc":[{"id":"1.195395451","rc":[{"atl":[[1.65,96.1],[1.66,0]],"id":42492389}],"con":true,"img":false}]}
{"op":"mcm","clk":"5346772805","pt":1646096600743,"mc":[{"id":"1.195395451","rc":[{"atl":[[1.65,52.83]],"id":42492389},{"atb":[[18.5,0]],"id":27151693}],"con":true,"img":false}]}
{"op":"mcm","clk":"5346772811","pt":1646096600848,"mc":[{"id":"1.195395451","rc":[{"atb":[[19.5,3.25]],"id":27151693},{"atl":[[1.64,43.26]],"id":42492389}],"con":true,"img":false}]}
{"op":"mcm","clk":"5346773568","pt":1646096617762,"mc":[{"id":"1.195395451","rc":[{"atb":[[19.5,8.02],[19,0]],"id":27151693},{"atl":[[1.65,22.06],[1.66,30.3]],"id":42492389}],"con":true,"img":false}]}
{"op":"mcm","clk":"5346773682","pt":1646096620643,"mc":[{"id":"1.195395451","rc":[{"atl":[[1.64,0]],"id":42492389}],"con":true,"img":false}]}
{"op":"mcm","clk":"5346773686","pt":1646096620800,"mc":[{"id":"1.195395451","rc":[{"atl":[[1.65,65.33]],"id":42492389}],"con":true,"img":false}]}
{"op":"mcm","clk":"5346773757","pt":1646096622344,"mc":[{"id":"1.195395451","rc":[{"atl":[[1.65,96.1],[1.66,0]],"id":42492389}],"con":true,"img":false}]}
{"op":"mcm","clk":"5346773772","pt":1646096622857,"mc":[{"id":"1.195395451","rc":[{"atb":[[19.5,3.25],[19,5.56]],"id":27151693}],"con":true,"img":false}]}
{"op":"mcm","clk":"5346774035","pt":1646096630056,"mc":[{"id":"1.195395451","rc":[{"atl":[[1.65,65.33],[1.66,30.3]],"id":42492389}],"con":true,"img":false}]}
{"op":"mcm","clk":"5346774163","pt":1646096634166,"mc":[{"id":"1.195395451","rc":[{"atl":[[34,1]],"id":40251221},{"atl":[[1.89,112.36],[1.69,28.99],[1.82,0],[1.66,0]],"id":42492389},{"atb":[[18,10.65],[19,0]],"id":27151693},{"atl":[[440,1]],"id":27151693}],"con":true,"img":false}]}
{"op":"mcm","clk":"5346774166","pt":1646096634268,"mc":[{"id":"1.195395451","rc":[{"atl":[[38,0]],"id":40251221},{"atl":[[460,0]],"id":27151693}],"con":true,"img":false}]}
{"op":"mcm","clk":"5346774176","pt":1646096634680,"mc":[{"id":"1.195395451","rc":[{"atl":[[1.67,0]],"id":42492389}],"con":true,"img":false}]}
{"op":"mcm","clk":"5346774372","pt":1646096640598,"mc":[{"id":"1.195395451","rc":[{"atb":[[19.5,0.55]],"id":27151693}],"con":true,"img":false}]}
{"op":"mcm","clk":"5346774376","pt":1646096640699,"mc":[{"id":"1.195395451","rc":[{"atb":[[18.5,2.7]],"id":27151693}],"con":true,"img":false}]}
{"op":"mcm","clk":"5346774401","pt":1646096641422,"mc":[{"id":"1.195395451","rc":[{"atl":[[130,2],[150,0]],"id":36899924}],"con":true,"img":false}]}
{"op":"mcm","clk":"5346774406","pt":1646096641474,"mc":[{"id":"1.195395451","rc":[{"atl":[[130,0],[150,2]],"id":36899924}],"con":true,"img":false}]}
{"op":"mcm","clk":"5346774504","pt":1646096644212,"mc":[{"id":"1.195395451","rc":[{"atl":[[38,1.35]],"id":40251221},{"atl":[[460,1]],"id":27151693},{"atl":[[1.71,70.42]],"id":42492389}],"con":true,"img":false}]}
{"op":"mcm","clk":"5346774616","pt":1646096647296,"mc":[{"id":"1.195395451","rc":[{"atb":[[8,17.38],[7.6,3.03]],"id":41921674},{"atl":[[130,2],[150,0]],"id":36899924},{"atb":[[10,13.52],[8.8,2.56]],"id":40251221},{"atl":[[50,0]],"id":40251221},{"atb":[[13,1.67],[14,0]],"id":39722911},{"atl":[[520,0]],"id":27151693},{"atb":[[10.5,2.11],[11.5,0],[12.5,0],[5.6,21.74],[6.6,0]],"id":43154431}],"con":true,"img":false}]}
{"op":"mcm","clk":"5346774848","pt":1646096654238,"mc":[{"id":"1.195395451","rc":[{"atb":[[9.6,0]],"id":40251221},{"atl":[[1.73,102.74]],"id":42492389}],"con":true,"img":false}]}
{"op":"mcm","clk":"5346774950","pt":1646096657337,"mc":[{"id":"1.195395451","rc":[{"atb":[[7.2,8.06]],"id":41921674},{"atb":[[9.2,0],[8.4,6.76]],"id":40251221},{"atl":[[46,2.78]],"id":40251221},{"atb":[[12,15.61]],"id":39722911},{"atb":[[9.8,5.68]],"id":43154431}],"con":true,"img":false}]}
{"op":"mcm","clk":"5346774958","pt":1646096657543,"mc":[{"id":"1.195395451","rc":[{"atl":[[1.65,54.19]],"id":42492389}],"con":true,"img":false}]}
{"op":"mcm","clk":"5346775059","pt":1646096660642,"mc":[{"id":"1.195395451","rc":[{"atl":[[1.65,10.92]],"id":42492389}],"con":true,"img":false}]}
{"op":"mcm","clk":"5346775064","pt":1646096660738,"mc":[{"id":"1.195395451","rc":[{"atl":[[1.68,43.26]],"id":42492389}],"con":true,"img":false}]}
{"op":"mcm","clk":"5346775174","pt":1646096663012,"mc":[{"id":"1.195395451","rc":[{"atl":[[1.69,39.85]],"id":42492389}],"con":true,"img":false}]}
{"op":"mcm","clk":"5346775215","pt":1646096664246,"mc":[{"id":"1.195395451","rc":[{"atl":[[1.75,166.67]],"id":42492389}],"con":true,"img":false}]}
{"op":"mcm","clk":"5346775334","pt":1646096667325,"mc":[{"id":"1.195395451","rc":[{"atb":[[6.8,12.93]],"id":41921674},{"atb":[[8,44.18]],"id":40251221},{"atb":[[11,7.5]],"id":39722911},{"atb":[[9.4,17.5]],"id":43154431}],"con":true,"img":false}]}
{"op":"mcm","clk":"5346775483","pt":1646096670620,"mc":[{"id":"1.195395451","rc":[{"atl":[[65,0]],"id":40251221},{"atl":[[40,2.7],[55,0]],"id":39979879}],"con":true,"img":false}]}
{"op":"mcm","clk":"5346775488","pt":1646096670720,"mc":[{"id":"1.195395451","rc":[{"atl":[[60,0.62]],"id":40251221},{"atl":[[38,4.05],[42,1.83]],"id":39979879}],"con":true,"img":false}]}
{"op":"mcm","clk":"5346775741","pt":1646096677351,"mc":[{"id":"1.195395451","rc":[{"atb":[[6.4,23.15]],"id":41921674},{"atb":[[7.6,18.94]],"id":40251221},{"atb":[[10,13.89]],"id":39722911},{"atb":[[9,15.62]],"id":43154431}],"con":true,"img":false}]}
{"op":"mcm","clk":"5346775845","pt":1646096680537,"mc":[{"id":"1.195395451","rc":[{"atl":[[140,0]],"id":36899924},{"atl":[[2.12,0],[1.65,0]],"id":42492389}],"con":true,"img":false}]}
{"op":"mcm","clk":"5346775848","pt":1646096680641,"mc":[{"id":"1.195395451","rc":[{"atl":[[120,3.81]],"id":36899924},{"atl":[[40,0],[55,0.8]],"id":39979879},{"atl":[[1.88,130.88]],"id":42492389}],"con":true,"img":false}]}
{"op":"mcm","clk":"5346775851","pt":1646096680744,"mc":[{"id":"1.195395451","rc":[{"atl":[[38,1.35],[42,4.27]],"id":39979879},{"atb":[[18.5,8.41],[18,4.77]],"id":27151693}],"con":true,"img":false}]}
{"op":"mcm","clk":"5346775953","pt":1646096683670,"mc":[{"id":"1.195395451","rc":[{"atl":[[1.69,50.52]],"id":42492389}],"con":true,"img":false}]}
{"op":"mcm","clk":"5346775967","pt":1646096684081,"mc":[{"id":"1.195395451","rc":[{"atb":[[18.5,2.7],[18,10.65]],"id":27151693}],"con":true,"img":false}]}
{"op":"mcm","clk":"5346776225","pt":1646096690869,"mc":[{"id":"1.195395451","rc":[{"atb":[[8.2,0],[7,16.67]],"id":40251221},{"atl":[[440,0],[450,1]],"id":27151693},{"atl":[[1.7,28.57],[1.69,21.53]],"id":42492389}],"con":true,"img":false}]}
{"op":"mcm","clk":"5346776365","pt":1646096694373,"mc":[{"id":"1.195395451","rc":[{"atl":[[1.7,0],[1.69,50.52]],"id":42492389},{"atl":[[440,1],[450,0]],"id":27151693}],"con":true,"img":false}]}
{"op":"mcm","clk":"5346776601","pt":1646096701514,"mc":[{"id":"1.195395451","rc":[{"atb":[[1.18,0],[1.15,270.43],[1.14,1075.84]],"id":42492389},{"atl":[[230,0.86],[240,1]],"id":43154431}],"con":true,"img":false}]}
{"op":"mcm","clk":"5346776603","pt":1646096701619,"mc":[{"id":"1.195395451","rc":[{"atb":[[1.12,0],[1.11,903.76],[1.17,2]],"id":42492389}],"con":true,"img":false}]}
{"op":"mcm","clk":"5346776636","pt":1646096702393,"mc":[{"id":"1.195395451","rc":[{"atl":[[1.7,28.57],[1.69,21.53]],"id":42492389},{"atb":[[18.5,8.41],[18,4.77]],"id":27151693},{"atl":[[440,0],[450,1]],"id":27151693}],"con":true,"img":false}]}
{"op":"mcm","clk":"5346776638","pt":1646096702494,"mc":[{"id":"1.195395451","rc":[{"atb":[[18.5,2.7],[18,10.65]],"id":27151693}],"con":true,"img":false}]}
{"op":"mcm","clk":"5346776940","pt":1646096708879,"mc":[{"id":"1.195395451","rc":[{"atl":[[440,1],[450,0]],"id":27151693},{"atl":[[1.7,0],[1.69,50.52]],"id":42492389}],"con":true,"img":false}]}
{"op":"mcm","clk":"5346777014","pt":1646096710577,"mc":[{"id":"1.195395451","rc":[{"atb":[[15.5,6.38]],"id":36899924},{"atb":[[13,7.71]],"id":40251221},{"atb":[[11.5,9.41]],"id":39979879},{"atb":[[17.5,4.62]],"id":39722911},{"atb":[[1.17,69.89]],"id":42492389},{"atb":[[19,4.82]],"id":43154431}],"con":true,"img":false}]}
{"op":"mcm","clk":"5346777056","pt":1646096711506,"mc":[{"id":"1.195395451","rc":[{"atl":[[260,1]],"id":43154431}],"con":true,"img":false}]}
{"op":"mcm","clk":"5346777154","pt":1646096714427,"mc":[{"id":"1.195395451","rc":[{"atl":[[1.7,28.57],[1.69,21.53]],"id":42492389},{"atb":[[18.5,8.41],[18,4.77]],"id":27151693},{"atl":[[440,0],[450,1]],"id":27151693},{"atl":[[270,0],[290,0],[250,0]],"id":43154431}],"con":true,"img":false}]}
{"op":"mcm","clk":"5346777162","pt":1646096714585,"mc":[{"id":"1.195395451","rc":[{"atb":[[18,10.65]],"id":27151693}],"con":true,"img":false}]}
{"op":"mcm","clk":"5346777165","pt":1646096714685,"mc":[{"id":"1.195395451","rc":[{"atb":[[18.5,2.7]],"id":27151693}],"con":true,"img":false}]}
{"op":"mcm","clk":"5346777358","pt":1646096720507,"mc":[{"id":"1.195395451","rc":[{"atl":[[440,1],[450,0]],"id":27151693},{"atl":[[1.7,0],[1.69,50.52]],"id":42492389},{"spn":1.17,"spf":1.0,"id":42492389}],"con":true,"img":false}]}
{"op":"mcm","clk":"5346777403","pt":1646096721533,"mc":[{"id":"1.195395451","rc":[{"atl":[[280,1.7]],"id":43154431}],"con":true,"img":false}]}
{"op":"mcm","clk":"5346777764","pt":1646096730528,"mc":[{"id":"1.195395451","rc":[{"atb":[[1.12,250]],"id":42492389}],"con":true,"img":false}]}
{"op":"mcm","clk":"5346777768","pt":1646096730632,"mc":[{"id":"1.195395451","rc":[{"atl":[[1.68,0]],"id":42492389}],"con":true,"img":false}]}
{"op":"mcm","clk":"5346777773","pt":1646096730738,"mc":[{"id":"1.195395451","rc":[{"atl":[[1.69,93.78]],"id":42492389}],"con":true,"img":false}]}
{"op":"mcm","clk":"5346777805","pt":1646096731556,"mc":[{"id":"1.195395451","rc":[{"atl":[[300,1]],"id":43154431}],"con":true,"img":false}]}
{"op":"mcm","clk":"5346777858","pt":1646096732944,"mc":[{"id":"1.195395451","rc":[{"atb":[[1.11,653.76],[1.09,0],[1.13,0]],"id":42492389}],"con":true,"img":false}]}
{"op":"mcm","clk":"5346778058","pt":1646096739268,"mc":[{"id":"1.195395451","rc":[{"atl":[[1.7,28.57],[1.69,64.79]],"id":42492389},{"atb":[[18.5,8.41],[18,4.77]],"id":27151693},{"atl":[[440,0],[450,1]],"id":27151693}],"con":true,"img":false}]}
{"op":"mcm","clk":"5346778062","pt":1646096739319,"mc":[{"id":"1.195395451","rc":[{"atb":[[18,10.65]],"id":27151693}],"con":true,"img":false}]}
{"op":"mcm","clk":"5346778067","pt":1646096739421,"mc":[{"id":"1.195395451","rc":[{"atb":[[18.5,2.7]],"id":27151693}],"con":true,"img":false}]}
{"op":"mcm","clk":"5346778110","pt":1646096740662,"mc":[{"id":"1.195395451","rc":[{"atl":[[110,0]],"id":36899924},{"atl":[[120,1.1]],"id":39722911}],"con":true,"img":false}]}
{"op":"mcm","clk":"5346778113","pt":1646096740764,"mc":[{"id":"1.195395451","rc":[{"atl":[[100,0.48]],"id":36899924},{"atl":[[110,0.45]],"id":39722911}],"con":true,"img":false}]}
{"op":"mcm","clk":"5346778235","pt":1646096744671,"mc":[{"id":"1.195395451","rc":[{"atl":[[440,1],[450,0]],"id":27151693},{"atl":[[1.7,0],[1.69,93.78]],"id":42492389}],"con":true,"img":false}]}
{"op":"mcm","clk":"5346778264","pt":1646096745645,"mc":[{"id":"1.195395451","rc":[{"atb":[[15,0]],"id":36899924},{"atb":[[16.5,0]],"id":39722911},{"atb":[[18.5,0]],"id":43154431}],"con":true,"img":false}]}
{"op":"mcm","clk":"5346778268","pt":1646096745751,"mc":[{"id":"1.195395451","rc":[{"atb":[[16,3.08]],"id":36899924},{"atb":[[18,2.7]],"id":39722911},{"atb":[[19.5,2.7]],"id":43154431}],"con":true,"img":false}]}
{"op":"mcm","clk":"5346778334","pt":1646096748162,"mc":[{"id":"1.195395451","rc":[{"atb":[[15.5,0]],"id":36899924},{"atb":[[17.5,0]],"id":39722911},{"atb":[[19,0]],"id":43154431}],"con":true,"img":false}]}
{"op":"mcm","clk":"5346778417","pt":1646096750675,"mc":[{"id":"1.195395451","rc":[{"atb":[[18,0]],"id":39722911},{"atb":[[19.5,0]],"id":43154431}],"con":true,"img":false}]}
{"op":"mcm","clk":"5346778419","pt":1646096750780,"mc":[{"id":"1.195395451","rc":[{"atb":[[16.5,2.7]],"id":39722911},{"atb":[[18,5.08]],"id":43154431}],"con":true,"img":false}]}
{"op":"mcm","clk":"5346778448","pt":1646096751551,"mc":[{"id":"1.195395451","rc":[{"atl":[[1.7,28.57],[1.69,64.79]],"id":42492389},{"atb":[[18.5,8.41],[18,4.77]],"id":27151693},{"atl":[[450,1]],"id":27151693}],"con":true,"img":false}]}
{"op":"mcm","clk":"5346778452","pt":1646096751653,"mc":[{"id":"1.195395451","rc":[{"atl":[[440,0]],"id":27151693}],"con":true,"img":false}]}
{"op":"mcm","clk":"5346778473","pt":1646096752265,"mc":[{"id":"1.195395451","rc":[{"atb":[[17.5,5.35]],"id":36899924},{"atb":[[18.5,4.87]],"id":39722911},{"atb":[[18.5,5.28]],"id":43154431}],"con":true,"img":false}]}
{"op":"mcm","clk":"5346778594","pt":1646096756469,"mc":[{"id":"1.195395451","rc":[{"atl":[[440,1],[450,0]],"id":27151693},{"atl":[[1.7,0],[1.69,93.78]],"id":42492389}],"con":true,"img":false}]}
{"op":"mcm","clk":"5346778597","pt":1646096756673,"mc":[{"id":"1.195395451","rc":[{"atb":[[18,10.65]],"id":27151693}],"con":true,"img":false}]}
{"op":"mcm","clk":"5346778600","pt":1646096756775,"mc":[{"id":"1.195395451","rc":[{"atb":[[18.5,2.7]],"id":27151693}],"con":true,"img":false}]}
{"op":"mcm","clk":"5346778727","pt":1646096760681,"mc":[{"id":"1.195395451","rc":[{"atl":[[44,0]],"id":41921674},{"atb":[[16,0]],"id":36899924}],"con":true,"img":false}]}
{"op":"mcm","clk":"5346778730","pt":1646096760784,"mc":[{"id":"1.195395451","rc":[{"atl":[[42,2.7]],"id":41921674},{"atb":[[15,3.08]],"id":36899924}],"con":true,"img":false}]}
{"op":"mcm","clk":"5346778814","pt":1646096763356,"mc":[{"id":"1.195395451","rc":[{"atl":[[440,0],[450,1]],"id":27151693},{"atl":[[1.7,28.57],[1.69,64.79]],"id":42492389}],"con":true,"img":false}]}
{"op":"mcm","clk":"5346778827","pt":1646096763764,"mc":[{"id":"1.195395451","rc":[{"atb":[[17.5,0.62]],"id":36899924}],"con":true,"img":false}]}
{"op":"mcm","clk":"5346778912","pt":1646096767608,"mc":[{"id":"1.195395451","rc":[{"atb":[[15.5,6.38]],"id":36899924}],"con":true,"img":false}]}
{"op":"mcm","clk":"5346778941","pt":1646096768692,"mc":[{"id":"1.195395451","rc":[{"atl":[[440,1],[450,0]],"id":27151693},{"atl":[[1.7,0],[1.69,93.78]],"id":42492389}],"con":true,"img":false}]}
{"op":"mcm","clk":"5346779147","pt":1646096775716,"mc":[{"id":"1.195395451","rc":[{"atb":[[18.5,8.41]],"id":27151693},{"atl":[[440,0],[450,1]],"id":27151693},{"atl":[[1.7,28.57],[1.69,64.79]],"id":42492389}],"con":true,"img":false}]}
{"op":"mcm","clk":"5346779149","pt":1646096775819,"mc":[{"id":"1.195395451","rc":[{"atb":[[18,4.77]],"id":27151693}],"con":true,"img":false}]}
{"op":"mcm","clk":"5346779279","pt":1646096780230,"mc":[{"id":"1.195395451","rc":[{"atl":[[440,1],[450,0]],"id":27151693},{"atl":[[1.7,0]],"id":42492389}],"con":true,"img":false}]}
{"op":"mcm","clk":"5346779282","pt":1646096780331,"mc":[{"id":"1.195395451","rc":[{"atl":[[1.69,93.78]],"id":42492389}],"con":true,"img":false}]}
{"op":"mcm","clk":"5346779292","pt":1646096780642,"mc":[{"id":"1.195395451","rc":[{"atl":[[40,2.7],[55,0]],"id":39979879}],"con":true,"img":false}]}
{"op":"mcm","clk":"5346779300","pt":1646096780797,"mc":[{"id":"1.195395451","rc":[{"atl":[[38,4.05],[42,1.83]],"id":39979879},{"atb":[[17.5,6.06],[18.5,2.7]],"id":27151693}],"con":true,"img":false}]}
{"op":"mcm","clk":"5346779361","pt":1646096783315,"mc":[{"id":"1.195395451","rc":[{"atl":[[1.69,82.91]],"id":42492389}],"con":true,"img":false}]}
{"op":"mcm","clk":"5346779489","pt":1646096788035,"mc":[{"id":"1.195395451","rc":[{"atl":[[1.7,28.57],[1.69,53.92]],"id":42492389}],"con":true,"img":false}]}
{"op":"mcm","clk":"5346779506","pt":1646096788549,"mc":[{"id":"1.195395451","rc":[{"atl":[[1.7,0],[1.69,82.91]],"id":42492389}],"con":true,"img":false}]}
{"op":"mcm","clk":"5346779530","pt":1646096789318,"mc":[{"id":"1.195395451","rc":[{"atl":[[1.67,11.01]],"id":42492389}],"con":true,"img":false}]}
{"op":"mcm","clk":"5346779555","pt":1646096790648,"mc":[{"id":"1.195395451","rc":[{"atl":[[55,0.8]],"id":39979879}],"con":true,"img":false}]}
{"op":"mcm","clk":"5346779557","pt":1646096790752,"mc":[{"id":"1.195395451","rc":[{"atb":[[15,0]],"id":36899924},{"atl":[[40,0]],"id":39979879},{"atb":[[16.5,0]],"id":39722911},{"atb":[[18,2.38]],"id":43154431}],"con":true,"img":false}]}
{"op":"mcm","clk":"5346779560","pt":1646096790854,"mc":[{"id":"1.195395451","rc":[{"atb":[[16,3.08]],"id":36899924},{"atb":[[17,5.24]],"id":39722911},{"atb":[[19,2.7]],"id":43154431}],"con":true,"img":false}]}
{"op":"mcm","clk":"5346779562","pt":1646096790907,"mc":[{"id":"1.195395451","rc":[{"atl":[[38,1.35],[42,4.27]],"id":39979879}],"con":true,"img":false}]}
{"op":"mcm","clk":"5346779612","pt":1646096793118,"mc":[{"id":"1.195395451","rc":[{"atb":[[17.5,0],[18,10.65]],"id":27151693}],"con":true,"img":false}]}
{"op":"mcm","clk":"5346779634","pt":1646096794143,"mc":[{"id":"1.195395451","rc":[{"atb":[[15.5,0]],"id":36899924},{"atb":[[18.5,0]],"id":39722911}],"con":true,"img":false}]}
{"op":"mcm","clk":"5346779723","pt":1646096798042,"mc":[{"id":"1.195395451","rc":[{"atb":[[17.5,5.35]],"id":36899924},{"atb":[[15.5,6.38]],"id":39722911}],"con":true,"img":false}]}
{"op":"mcm","clk":"5346779733","pt":1646096798452,"mc":[{"id":"1.195395451","rc":[{"atb":[[1.1,1061.29]],"id":42492389}],"con":true,"img":false}]}
{"op":"mcm","clk":"5346779766","pt":1646096799740,"mc":[{"id":"1.195395451","rc":[{"atl":[[1.7,28.57],[1.69,53.92]],"id":42492389}],"con":true,"img":false}]}
{"op":"mcm","clk":"5346779792","pt":1646096800971,"mc":[{"id":"1.195395451","rc":[{"atl":[[1.69,43.26]],"id":42492389}],"con":true,"img":false}]}
{"op":"mcm","clk":"5346779859","pt":1646096803844,"mc":[{"id":"1.195395451","rc":[{"atl":[[1.69,53.92]],"id":42492389}],"con":true,"img":false}]}
{"op":"mcm","clk":"5346779873","pt":1646096804667,"mc":[{"id":"1.195395451","rc":[{"atl":[[1.7,0],[1.69,82.91]],"id":42492389}],"con":true,"img":false}]}
{"op":"mcm","clk":"5346780015","pt":1646096810765,"mc":[{"id":"1.195395451","rc":[{"atb":[[16,0]],"id":36899924}],"con":true,"img":false}]}
{"op":"mcm","clk":"5346780018","pt":1646096810868,"mc":[{"id":"1.195395451","rc":[{"atb":[[15,3.08]],"id":36899924}],"con":true,"img":false}]}
{"op":"mcm","clk":"5346780042","pt":1646096812045,"mc":[{"id":"1.195395451","rc":[{"atl":[[1.7,28.57]],"id":42492389}],"con":true,"img":false}]}
{"op":"mcm","clk":"5346780044","pt":1646096812147,"mc":[{"id":"1.195395451","rc":[{"atl":[[1.69,53.92]],"id":42492389}],"con":true,"img":false}]}
{"op":"mcm","clk":"5346780061","pt":1646096813172,"mc":[{"id":"1.195395451","rc":[{"atb":[[17.5,0.62]],"id":36899924}],"con":true,"img":false}]}
{"op":"mcm","clk":"5346780147","pt":1646096816665,"mc":[{"id":"1.195395451","rc":[{"atl":[[1.7,0],[1.69,82.91]],"id":42492389}],"con":true,"img":false}]}
{"op":"mcm","clk":"5346780164","pt":1646096817084,"mc":[{"id":"1.195395451","rc":[{"atb":[[15.5,6.38]],"id":36899924}],"con":true,"img":false}]}
{"op":"mcm","clk":"5346780372","pt":1646096824312,"mc":[{"id":"1.195395451","rc":[{"atl":[[1.7,28.57],[1.69,53.92]],"id":42492389}],"con":true,"img":false}]}
{"op":"mcm","clk":"5346780522","pt":1646096828726,"mc":[{"id":"1.195395451","rc":[{"atl":[[1.7,0],[1.69,82.91]],"id":42492389}],"con":true,"img":false}]}
{"op":"mcm","clk":"5346780584","pt":1646096830626,"mc":[{"id":"1.195395451","rc":[{"atl":[[40,2.7]],"id":39979879}],"con":true,"img":false}]}
{"op":"mcm","clk":"5346780587","pt":1646096830732,"mc":[{"id":"1.195395451","rc":[{"atl":[[55,0]],"id":39979879}],"con":true,"img":false}]}
{"op":"mcm","clk":"5346780590","pt":1646096830783,"mc":[{"id":"1.195395451","rc":[{"atl":[[38,4.05]],"id":39979879}],"con":true,"img":false}]}
{"op":"mcm","clk":"5346780595","pt":1646096830886,"mc":[{"id":"1.195395451","rc":[{"atl":[[42,1.83]],"id":39979879}],"con":true,"img":false}]}
{"op":"mcm","clk":"5346780806","pt":1646096836734,"mc":[{"id":"1.195395451","rc":[{"atl":[[1.7,28.57],[1.69,53.92]],"id":42492389}],"con":true,"img":false}]}
{"op":"mcm","clk":"5346780928","pt":1646096840640,"mc":[{"id":"1.195395451","rc":[{"atb":[[15,0]],"id":36899924},{"atl":[[40,0],[55,0.8]],"id":39979879},{"atb":[[15,0]],"id":39722911},{"atl":[[1.7,0],[1.69,82.91]],"id":42492389}],"con":true,"img":false}]}
{"op":"mcm","clk":"5346780934","pt":1646096840691,"mc":[{"id":"1.195395451","rc":[{"atb":[[16,3.08]],"id":36899924},{"atb":[[16,8.22]],"id":39722911}],"con":true,"img":false}]}
{"op":"mcm","clk":"5346780936","pt":1646096840795,"mc":[{"id":"1.195395451","rc":[{"atl":[[38,1.35],[42,4.27]],"id":39979879}],"con":true,"img":false}]}
{"op":"mcm","clk":"5346781010","pt":1646096843524,"mc":[{"id":"1.195395451","rc":[{"atb":[[15.5,0]],"id":36899924},{"atb":[[15.5,0]],"id":39722911}],"con":true,"img":false}]}
{"op":"mcm","clk":"5346781151","pt":1646096847531,"mc":[{"id":"1.195395451","rc":[{"atb":[[17.5,5.35]],"id":36899924},{"atb":[[17.5,5.6]],"id":39722911}],"con":true,"img":false}]}
{"op":"mcm","clk":"5346781188","pt":1646096848814,"mc":[{"id":"1.195395451","rc":[{"atl":[[1.7,28.57],[1.69,53.92]],"id":42492389}],"con":true,"img":false}]}
{"op":"mcm","clk":"5346781241","pt":1646096850663,"mc":[{"id":"1.195395451","rc":[{"atb":[[16,0]],"id":39722911}],"con":true,"img":false}]}
{"op":"mcm","clk":"5346781245","pt":1646096850718,"mc":[{"id":"1.195395451","rc":[{"atb":[[15,8.22]],"id":39722911}],"con":true,"img":false}]}
{"op":"mcm","clk":"5346781297","pt":1646096852721,"mc":[{"id":"1.195395451","rc":[{"atl":[[1.69,82.91]],"id":42492389}],"con":true,"img":false}]}
{"op":"mcm","clk":"5346781299","pt":1646096852828,"mc":[{"id":"1.195395451","rc":[{"atl":[[1.7,0]],"id":42492389}],"con":true,"img":false}]}
{"op":"mcm","clk":"5346781313","pt":1646096853234,"mc":[{"id":"1.195395451","rc":[{"atb":[[17.5,0]],"id":39722911}],"con":true,"img":false}]}
{"op":"mcm","clk":"5346781434","pt":1646096857040,"mc":[{"id":"1.195395451","rc":[{"atb":[[15.5,6.38]],"id":39722911}],"con":true,"img":false}]}
{"op":"mcm","clk":"5346781546","pt":1646096860678,"mc":[{"id":"1.195395451","rc":[{"atb":[[16,0]],"id":36899924},{"atl":[[1.7,28.57],[1.69,53.92]],"id":42492389}],"con":true,"img":false}]}
{"op":"mcm","clk":"5346781548","pt":1646096860733,"mc":[{"id":"1.195395451","rc":[{"atb":[[15,3.08]],"id":36899924}],"con":true,"img":false}]}
{"op":"mcm","clk":"5346781621","pt":1646096862885,"mc":[{"id":"1.195395451","rc":[{"atb":[[17.5,0.62]],"id":36899924}],"con":true,"img":false}]}
{"op":"mcm","clk":"5346781707","pt":1646096865296,"mc":[{"id":"1.195395451","rc":[{"atl":[[1.7,0],[1.69,82.91]],"id":42492389}],"con":true,"img":false}]}
{"op":"mcm","clk":"5346781753","pt":1646096866789,"mc":[{"id":"1.195395451","rc":[{"atb":[[15.5,6.38]],"id":36899924}],"con":true,"img":false}]}
{"op":"mcm","clk":"5346781960","pt":1646096872867,"mc":[{"id":"1.195395451","rc":[{"atl":[[1.7,28.57],[1.69,53.92]],"id":42492389}],"con":true,"img":false}]}
{"op":"mcm","clk":"5346782121","pt":1646096876978,"mc":[{"id":"1.195395451","rc":[{"atl":[[1.7,0],[1.69,82.91]],"id":42492389}],"con":true,"img":false}]}
{"op":"mcm","clk":"5346782158","pt":1646096878001,"mc":[{"id":"1.195395451","rc":[{"atl":[[1.67,15.44]],"id":42492389}],"con":true,"img":false}]}
{"op":"mcm","clk":"5346782265","pt":1646096880580,"mc":[{"id":"1.195395451","rc":[{"atl":[[40,2.7]],"id":39979879}],"con":true,"img":false}]}
{"op":"mcm","clk":"5346782270","pt":1646096880685,"mc":[{"id":"1.195395451","rc":[{"atl":[[38,4.05],[42,1.83],[55,0]],"id":39979879}],"con":true,"img":false}]}
{"op":"mcm","clk":"5346782440","pt":1646096885208,"mc":[{"id":"1.195395451","rc":[{"atl":[[1.7,28.57],[1.69,53.92]],"id":42492389}],"con":true,"img":false}]}
{"op":"mcm","clk":"5346782579","pt":1646096888698,"mc":[{"id":"1.195395451","rc":[{"atl":[[1.7,0],[1.69,82.91]],"id":42492389}],"con":true,"img":false}]}
{"op":"mcm","clk":"5346782652","pt":1646096890603,"mc":[{"id":"1.195395451","rc":[{"atl":[[40,0],[55,0.8]],"id":39979879}],"con":true,"img":false}]}
{"op":"mcm","clk":"5346782657","pt":1646096890706,"mc":[{"id":"1.195395451","rc":[{"atb":[[15,0]],"id":36899924},{"atl":[[42,4.27]],"id":39979879}],"con":true,"img":false}]}
{"op":"mcm","clk":"5346782661","pt":1646096890808,"mc":[{"id":"1.195395451","rc":[{"atb":[[16,3.08]],"id":36899924},{"atl":[[38,1.35]],"id":39979879}],"con":true,"img":false}]}
{"op":"mcm","clk":"5346782757","pt":1646096893538,"mc":[{"id":"1.195395451","rc":[{"atb":[[15.5,0]],"id":36899924}],"con":true,"img":false}]}
{"op":"mcm","clk":"5346782882","pt":1646096897343,"mc":[{"id":"1.195395451","rc":[{"atb":[[17.5,5.35]],"id":36899924}],"con":true,"img":false}]}
{"op":"mcm","clk":"5346782896","pt":1646096897706,"mc":[{"id":"1.195395451","rc":[{"atl":[[1.7,28.57]],"id":42492389}],"con":true,"img":false}]}
{"op":"mcm","clk":"5346782900","pt":1646096897807,"mc":[{"id":"1.195395451","rc":[{"atl":[[1.69,53.92]],"id":42492389}],"con":true,"img":false}]}
{"op":"mcm","clk":"5346782983","pt":1646096900334,"mc":[{"id":"1.195395451","rc":[{"atl":[[1.69,82.91]],"id":42492389}],"con":true,"img":false}]}
{"op":"mcm","clk":"5346782984","pt":1646096900439,"mc":[{"id":"1.195395451","rc":[{"atl":[[1.7,0]],"id":42492389}],"con":true,"img":false}]}
{"op":"mcm","clk":"5346782996","pt":1646096900751,"mc":[{"id":"1.195395451","rc":[{"atb":[[15,0]],"id":39722911}],"con":true,"img":false}]}
{"op":"mcm","clk":"5346783000","pt":1646096900853,"mc":[{"id":"1.195395451","rc":[{"atb":[[16,8.22]],"id":39722911}],"con":true,"img":false}]}
{"op":"mcm","clk":"5346783082","pt":1646096903119,"mc":[{"id":"1.195395451","rc":[{"atb":[[15.5,0]],"id":39722911}],"con":true,"img":false}]}
{"op":"mcm","clk":"5346783135","pt":1646096904612,"mc":[{"id":"1.195395451","rc":[{"atl":[[1.67,4.43]],"id":42492389}],"con":true,"img":false}]}
{"op":"mcm","clk":"5346783206","pt":1646096907029,"mc":[{"id":"1.195395451","rc":[{"atb":[[17.5,5.6]],"id":39722911}],"con":true,"img":false}]}
{"op":"mcm","clk":"5346783269","pt":1646096909045,"mc":[{"id":"1.195395451","rc":[{"atl":[[1.7,28.57],[1.69,53.92]],"id":42492389}],"con":true,"img":false}]}
{"op":"mcm","clk":"5346783287","pt":1646096909553,"mc":[{"id":"1.195395451","rc":[{"atb":[[1.18,5.94]],"id":42492389}],"con":true,"img":false}]}
{"op":"mcm","clk":"5346783297","pt":1646096909862,"mc":[{"id":"1.195395451","rc":[{"atl":[[1.67,15.44]],"id":42492389}],"con":true,"img":false}]}
{"op":"mcm","clk":"5346783321","pt":1646096910634,"mc":[{"id":"1.195395451","rc":[{"atb":[[16,0]],"id":36899924},{"atb":[[16,0]],"id":39722911}],"con":true,"img":false}]}
{"op":"mcm","clk":"5346783326","pt":1646096910734,"mc":[{"id":"1.195395451","rc":[{"atb":[[15,3.08]],"id":36899924},{"atb":[[15,8.22]],"id":39722911}],"con":true,"img":false}]}
{"op":"mcm","clk":"5346783387","pt":1646096912738,"mc":[{"id":"1.195395451","rc":[{"atb":[[17.5,0.62]],"id":36899924},{"atb":[[17.5,0]],"id":39722911},{"atb":[[1.17,2]],"id":42492389},{"atl":[[1.7,0],[1.69,82.91]],"id":42492389}],"con":true,"img":false}]}
{"op":"mcm","clk":"5346783523","pt":1646096916853,"mc":[{"id":"1.195395451","rc":[{"atb":[[15.5,6.38]],"id":36899924},{"atb":[[15.5,6.38]],"id":39722911},{"atb":[[1.19,8.92]],"id":42492389}],"con":true,"img":false}]}
{"op":"mcm","clk":"5346783681","pt":1646096921273,"mc":[{"id":"1.195395451","rc":[{"atl":[[1.69,72.25]],"id":42492389}],"con":true,"img":false}]}
{"op":"mcm","clk":"5346783744","pt":1646096922767,"mc":[{"id":"1.195395451","rc":[{"atb":[[1.08,250]],"id":42492389}],"con":true,"img":false}]}
{"op":"mcm","clk":"5346783810","pt":1646096924155,"mc":[{"id":"1.195395451","rc":[{"atl":[[1.67,26.24]],"id":42492389}],"con":true,"img":false}]}
{"op":"mcm","clk":"5346784031","pt":1646096930583,"mc":[{"id":"1.195395451","rc":[{"atl":[[40,2.7]],"id":39979879}],"con":true,"img":false}]}
{"op":"mcm","clk":"5346784036","pt":1646096930686,"mc":[{"id":"1.195395451","rc":[{"atl":[[38,4.05],[42,1.83],[55,0]],"id":39979879}],"con":true,"img":false}]}
{"op":"mcm","clk":"5346784044","pt":1646096930892,"mc":[{"id":"1.195395451","rc":[{"atb":[[17,2.53]],"id":39722911}],"con":true,"img":false}]}
{"op":"mcm","clk":"5346784051","pt":1646096930994,"mc":[{"id":"1.195395451","rc":[{"atb":[[17.5,2.7]],"id":39722911}],"con":true,"img":false}]}
{"op":"mcm","clk":"5346784105","pt":1646096932902,"mc":[{"id":"1.195395451","rc":[{"atl":[[130,0],[160,2]],"id":36899924},{"atl":[[140,0],[150,2]],"id":39722911},{"atl":[[1.68,29.41],[1.69,43.26],[1.67,56.09]],"id":42492389}],"con":true,"img":false}]}
{"op":"mcm","clk":"5346784145","pt":1646096933882,"mc":[{"id":"1.195395451","rc":[{"atb":[[15.5,0]],"id":39722911}],"con":true,"img":false}]}
{"op":"mcm","clk":"5346784246","pt":1646096936917,"mc":[{"id":"1.195395451","rc":[{"atl":[[1.68,0]],"id":42492389}],"con":true,"img":false}]}
{"op":"mcm","clk":"5346784263","pt":1646096937281,"mc":[{"id":"1.195395451","rc":[{"atl":[[27,0],[28,1]],"id":41921674},{"atl":[[190,0],[200,1]],"id":36899924},{"atl":[[220,0.9],[230,1]],"id":39722911},{"atl":[[240,0]],"id":43154431}],"con":true,"img":false}]}
{"op":"mcm","clk":"5346784272","pt":1646096937381,"mc":[{"id":"1.195395451","rc":[{"atl":[[29,5.36]],"id":41921674}],"con":true,"img":false}]}
{"op":"mcm","clk":"5346784276","pt":1646096937485,"mc":[{"id":"1.195395451","rc":[{"atl":[[32,2.42]],"id":41921674}],"con":true,"img":false}]}
{"op":"mcm","clk":"5346784283","pt":1646096937694,"mc":[{"id":"1.195395451","rc":[{"atb":[[18,4.87]],"id":39722911}],"con":true,"img":false}]}
{"op":"mcm","clk":"5346784371","pt":1646096940112,"mc":[{"id":"1.195395451","rc":[{"atl":[[27,1]],"id":41921674},{"atl":[[190,1],[200,0]],"id":36899924},{"atl":[[34,0],[36,1]],"id":39979879},{"atl":[[220,1.9],[230,0]],"id":39722911},{"atb":[[1.14,932.98],[1.13,153.85]],"id":42492389}],"con":true,"img":false}]}
{"op":"mcm","clk":"5346784378","pt":1646096940213,"mc":[{"id":"1.195395451","rc":[{"atl":[[28,0]],"id":41921674}],"con":true,"img":false}]}
{"op":"mcm","clk":"5346784395","pt":1646096940576,"mc":[{"id":"1.195395451","rc":[{"atl":[[55,0.8]],"id":39979879}],"con":true,"img":false}]}
{"op":"mcm","clk":"5346784401","pt":1646096940680,"mc":[{"id":"1.195395451","rc":[{"atb":[[15,0]],"id":36899924},{"atl":[[120,1.1]],"id":36899924},{"atl":[[40,0]],"id":39979879},{"atl":[[130,0]],"id":39722911},{"atl":[[1.69,0]],"id":42492389}],"con":true,"img":false}]}
{"op":"mcm","clk":"5346784404","pt":1646096940783,"mc":[{"id":"1.195395451","rc":[{"atb":[[16,3.08]],"id":36899924},{"atl":[[150,2.7]],"id":36899924},{"atl":[[38,1.35],[42,4.27]],"id":39979879},{"atl":[[140,2.7]],"id":39722911},{"atl":[[1.66,43.26]],"id":42492389}],"con":true,"img":false}]}
{"op":"mcm","clk":"5346784420","pt":1646096941195,"mc":[{"id":"1.195395451","rc":[{"atl":[[1.67,51.66]],"id":42492389}],"con":true,"img":false}]}
{"op":"mcm","clk":"5346784431","pt":1646096941505,"mc":[{"id":"1.195395451","rc":[{"atb":[[21,0]],"id":43154431}],"con":true,"img":false}]}
{"op":"mcm","clk":"5346784436","pt":1646096941605,"mc":[{"id":"1.195395451","rc":[{"atb":[[22,0.49]],"id":43154431}],"con":true,"img":false}]}
{"op":"mcm","clk":"5346784470","pt":1646096942480,"mc":[{"id":"1.195395451","rc":[{"atl":[[32,5.65],[29,1.79]],"id":41921674}],"con":true,"img":false}]}
{"op":"mcm","clk":"5346784502","pt":1646096943405,"mc":[{"id":"1.195395451","rc":[{"atb":[[15.5,0]],"id":36899924}],"con":true,"img":false}]}
{"op":"mcm","clk":"5346784535","pt":1646096944176,"mc":[{"id":"1.195395451","rc":[{"atl":[[1.65,4.43]],"id":42492389}],"con":true,"img":false}]}
{"op":"mcm","clk":"5346784555","pt":1646096944692,"mc":[{"id":"1.195395451","rc":[{"atl":[[1.68,29.41],[1.67,21.81]],"id":42492389}],"con":true,"img":false}]}
{"op":"mcm","clk":"5346784632","pt":1646096946800,"mc":[{"id":"1.195395451","rc":[{"atl":[[320,1]],"id":43154431}],"con":true,"img":false}]}
{"op":"mcm","clk":"5346784658","pt":1646096947315,"mc":[{"id":"1.195395451","rc":[{"atb":[[17.5,5.35]],"id":36899924}],"con":true,"img":false}]}
{"op":"mcm","clk":"5346784735","pt":1646096948907,"mc":[{"id":"1.195395451","rc":[{"atl":[[1.68,0],[1.67,51.66]],"id":42492389}],"con":true,"img":false}]}
{"op":"mcm","clk":"5346784791","pt":1646096950140,"mc":[{"id":"1.195395451","rc":[{"atl":[[40,1.28]],"id":39979879}],"con":true,"img":false}]}
{"op":"mcm","clk":"5346784820","pt":1646096950706,"mc":[{"id":"1.195395451","rc":[{"atb":[[16,0]],"id":36899924}],"con":true,"img":false}]}
{"op":"mcm","clk":"5346784823","pt":1646096950808,"mc":[{"id":"1.195395451","rc":[{"atb":[[15,3.08]],"id":36899924}],"con":true,"img":false}]}
{"op":"mcm","clk":"5346784923","pt":1646096953019,"mc":[{"id":"1.195395451","rc":[{"atb":[[17.5,0.62]],"id":36899924}],"con":true,"img":false}]}
{"op":"mcm","clk":"5346785072","pt":1646096956732,"mc":[{"id":"1.195395451","rc":[{"atl":[[38,0],[42,2.44],[46,0]],"id":39979879},{"atl":[[1.68,29.41],[1.67,21.81]],"id":42492389}],"con":true,"img":false}]}
{"op":"mcm","clk":"5346785083","pt":1646096956936,"mc":[{"id":"1.195395451","rc":[{"atb":[[15.5,6.38]],"id":36899924}],"con":true,"img":false}]}
{"op":"mcm","clk":"5346785208","pt":1646096960134,"mc":[{"id":"1.195395451","rc":[{"atl":[[44,1.74]],"id":39979879}],"con":true,"img":false}]}
{"op":"mcm","clk":"5346785234","pt":1646096960750,"mc":[{"id":"1.195395451","rc":[{"atl":[[1.66,0]],"id":42492389}],"con":true,"img":false}]}
{"op":"mcm","clk":"5346785240","pt":1646096960856,"mc":[{"id":"1.195395451","rc":[{"spn":24.5,"spf":1.0,"id":39979879},{"atl":[[1.67,65.08]],"id":42492389},{"spn":1.18,"spf":1.0,"id":42492389},{"spn":61.0,"spf":1.0,"id":43154431}],"con":true,"img":false}]}
{"op":"mcm","clk":"5346785249","pt":1646096961065,"mc":[{"id":"1.195395451","rc":[{"atl":[[1.68,0],[1.67,94.93]],"id":42492389}],"con":true,"img":false}]}
{"op":"mcm","clk":"5346785498","pt":1646096965862,"mc":[{"id":"1.195395451","rc":[{"atl":[[27,0],[28,1]],"id":41921674},{"atl":[[190,0],[200,1]],"id":36899924},{"atl":[[220,0.9],[230,1]],"id":39722911}],"con":true,"img":false}]}
{"op":"mcm","clk":"5346785506","pt":1646096965917,"mc":[{"id":"1.195395451","rc":[{"atl":[[32,2.42],[29,5.36]],"id":41921674}],"con":true,"img":false}]}
{"op":"mcm","clk":"5346785533","pt":1646096966435,"mc":[{"id":"1.195395451","rc":[{"atb":[[17.5,0]],"id":39722911}],"con":true,"img":false}]}
{"op":"mcm","clk":"5346785542","pt":1646096966539,"mc":[{"id":"1.195395451","rc":[{"atb":[[18.5,2.7]],"id":39722911}],"con":true,"img":false}]}
{"op":"mcm","clk":"5346785645","pt":1646096968861,"mc":[{"id":"1.195395451","rc":[{"atl":[[1.68,29.41],[1.67,65.08]],"id":42492389}],"con":true,"img":false}]}
{"op":"mcm","clk":"5346785707","pt":1646096970247,"mc":[{"id":"1.195395451","rc":[{"atl":[[48,2.66]],"id":39979879},{"atb":[[18,0]],"id":39722911}],"con":true,"img":false}]}
{"op":"mcm","clk":"5346785742","pt":1646096971068,"mc":[{"id":"1.195395451","rc":[{"atl":[[32,5.65],[29,1.79]],"id":41921674}],"con":true,"img":false}]}
{"op":"mcm","clk":"5346785824","pt":1646096973225,"mc":[{"id":"1.195395451","rc":[{"atl":[[1.67,94.93]],"id":42492389}],"con":true,"img":false}]}
{"op":"mcm","clk":"5346785827","pt":1646096973329,"mc":[{"id":"1.195395451","rc":[{"atl":[[1.68,0]],"id":42492389}],"con":true,"img":false}]}
{"op":"mcm","clk":"5346785858","pt":1646096974252,"mc":[{"id":"1.195395451","rc":[{"atb":[[15,0]],"id":36899924}],"con":true,"img":false}]}
{"op":"mcm","clk":"5346785860","pt":1646096974357,"mc":[{"id":"1.195395451","rc":[{"atb":[[16,3.08]],"id":36899924},{"atb":[[17.5,5.6]],"id":39722911}],"con":true,"img":false}]}
{"op":"mcm","clk":"5346785901","pt":1646096975230,"mc":[{"id":"1.195395451","rc":[{"atb":[[18.5,0]],"id":39722911}],"con":true,"img":false}]}
{"op":"mcm","clk":"5346785907","pt":1646096975333,"mc":[{"id":"1.195395451","rc":[{"atb":[[17.5,8.31]],"id":39722911}],"con":true,"img":false}]}
{"op":"mcm","clk":"5346785924","pt":1646096975848,"mc":[{"id":"1.195395451","rc":[{"atl":[[30,1.72]],"id":41921674},{"atl":[[220,1.9]],"id":36899924},{"atl":[[250,1]],"id":39722911}],"con":true,"img":false}]}
{"op":"mcm","clk":"5346785941","pt":1646096976364,"mc":[{"id":"1.195395451","rc":[{"atb":[[15.5,0]],"id":36899924}],"con":true,"img":false}]}
{"op":"mcm","clk":"5346786046","pt":1646096978780,"mc":[{"id":"1.195395451","rc":[{"atl":[[32,3.23],[36,0],[29,0]],"id":41921674},{"atl":[[130,2],[160,0],[210,0],[230,0],[250,0]],"id":36899924},{"atl":[[260,0],[140,4.7],[280,0],[150,0],[240,0]],"id":39722911},{"atl":[[1.7,28.57],[1.67,65.08]],"id":42492389},{"atl":[[420,1],[440,0]],"id":27151693}],"con":true,"img":false}]}
{"op":"mcm","clk":"5346786086","pt":1646096979754,"mc":[{"id":"1.195395451","rc":[{"atb":[[10,0],[9.8,16.33]],"id":39979879},{"atb":[[16.5,6.45],[18,4.77]],"id":27151693},{"atl":[[1.7,0],[1.71,28.17]],"id":42492389}],"con":true,"img":false}]}
{"op":"mcm","clk":"5346786103","pt":1646096980267,"mc":[{"id":"1.195395451","rc":[{"atb":[[17.5,5.35]],"id":36899924}],"con":true,"img":false}]}
{"op":"mcm","clk":"5346786122","pt":1646096980680,"mc":[{"id":"1.195395451","rc":[{"atb":[[9.6,2.33],[9.8,14.06]],"id":39979879},{"atl":[[1.71,0],[1.72,27.78]],"id":42492389}],"con":true,"img":false}]}
{"op":"mcm","clk":"5346786161","pt":1646096981350,"mc":[{"id":"1.195395451","rc":[{"atb":[[9.8,16.33]],"id":39979879},{"atl":[[1.71,28.17]],"id":42492389},{"atl":[[410,1],[420,0]],"id":27151693}],"con":true,"img":false}]}
{"op":"mcm","clk":"5346786330","pt":1646096985467,"mc":[{"id":"1.195395451","rc":[{"atb":[[16,0]],"id":36899924}],"con":true,"img":false}]}
{"op":"mcm","clk":"5346786335","pt":1646096985570,"mc":[{"id":"1.195395451","rc":[{"atb":[[15,3.08]],"id":36899924}],"con":true,"img":false}]}
{"op":"mcm","clk":"5346786345","pt":1646096985777,"mc":[{"id":"1.195395451","rc":[{"atb":[[6.8,3.45],[7.2,0],[7.6,0]],"id":41921674},{"atl":[[130,0],[150,4.7]],"id":36899924},{"atb":[[11,9.5]],"id":39722911},{"atb":[[10.5,0],[11,2]],"id":43154431}],"con":true,"img":false}]}
{"op":"mcm","clk":"5346786348","pt":1646096985879,"mc":[{"id":"1.195395451","rc":[{"atl":[[240,1]],"id":36899924},{"atb":[[11,2],[12,11.06],[13,0]],"id":39722911}],"con":true,"img":false}]}
{"op":"mcm","clk":"5346786433","pt":1646096987988,"mc":[{"id":"1.195395451","rc":[{"atb":[[17.5,0.62]],"id":36899924}],"con":true,"img":false}]}
{"op":"mcm","clk":"5346786542","pt":1646096991384,"mc":[{"id":"1.195395451","rc":[{"atb":[[9.4,5.95]],"id":39979879},{"atl":[[430,1]],"id":27151693},{"atb":[[1.11,903.76]],"id":42492389},{"atl":[[1.73,68.49]],"id":42492389}],"con":true,"img":false}]}
{"op":"mcm","clk":"5346786550","pt":1646096991798,"mc":[{"id":"1.195395451","rc":[{"atb":[[15.5,6.38]],"id":36899924}],"con":true,"img":false}]}
{"op":"mcm","clk":"5346786589","pt":1646096992878,"mc":[{"id":"1.195395451","rc":[{"atb":[[9.8,14.06]],"id":39979879},{"atl":[[410,0],[430,0],[420,1]],"id":27151693},{"atb":[[1.12,0],[1.1,811.29],[1.08,0]],"id":42492389},{"atl":[[1.71,0]],"id":42492389}],"con":true,"img":false}]}
{"op":"mcm","clk":"5346786594","pt":1646096993082,"mc":[{"id":"1.195395451","rc":[{"atb":[[9.2,14.84],[9.6,0],[8.8,0]],"id":39979879},{"atl":[[460,0],[480,0],[500,0]],"id":27151693}],"con":true,"img":false}]}
{"op":"mcm","clk":"5346786610","pt":1646096993595,"mc":[{"id":"1.195395451","rc":[{"atb":[[1.14,0]],"id":42492389},{"atl":[[1.67,21.81]],"id":42492389}],"con":true,"img":false}]}
{"op":"mcm","clk":"5346786615","pt":1646096993699,"mc":[{"id":"1.195395451","rc":[{"atb":[[1.13,1086.83]],"id":42492389},{"atl":[[1.7,43.26]],"id":42492389}],"con":true,"img":false}]}
{"op":"mcm","clk":"5346786682","pt":1646096995808,"mc":[{"id":"1.195395451","rc":[{"atb":[[6.4,9.26]],"id":41921674},{"atl":[[34,2.27]],"id":41921674},{"atb":[[10,5.56]],"id":39722911},{"atl":[[270,1.73]],"id":39722911}],"con":true,"img":false}]}
{"op":"mcm","clk":"5346786688","pt":1646096995859,"mc":[{"id":"1.195395451","rc":[{"atl":[[260,1]],"id":36899924}],"con":true,"img":false}]}
{"op":"mcm","clk":"5346786743","pt":1646096997710,"mc":[{"id":"1.195395451","rc":[{"atb":[[9.8,16.33]],"id":39979879},{"atl":[[1.71,28.17]],"id":42492389},{"atl":[[410,1]],"id":27151693}],"con":true,"img":false}]}
{"op":"mcm","clk":"5346786756","pt":1646096998174,"mc":[{"id":"1.195395451","rc":[{"atl":[[410,0]],"id":27151693}],"con":true,"img":false}]}
{"op":"mcm","clk":"5346786805","pt":1646096999612,"mc":[{"id":"1.195395451","rc":[{"atb":[[1.16,0]],"id":42492389}],"con":true,"img":false}]}
{"op":"mcm","clk":"5346786809","pt":1646096999713,"mc":[{"id":"1.195395451","rc":[{"atb":[[1.15,313.7]],"id":42492389}],"con":true,"img":false}]}
{"op":"mcm","clk":"5346786840","pt":1646097000700,"mc":[{"id":"1.195395451","rc":[{"atb":[[9.8,2.27]],"id":39979879},{"atb":[[1.13,153.85]],"id":42492389}],"con":true,"img":false}]}
{"op":"mcm","clk":"5346786845","pt":1646097000805,"mc":[{"id":"1.195395451","rc":[{"atb":[[9.6,14.06]],"id":39979879},{"atb":[[1.12,932.98]],"id":42492389}],"con":true,"img":false}]}
{"op":"mcm","clk":"5346786870","pt":1646097001476,"mc":[{"id":"1.195395451","rc":[{"atl":[[34,0],[36,1]],"id":40251221}],"con":true,"img":false}]}
{"op":"mcm","clk":"5346786930","pt":1646097002917,"mc":[{"id":"1.195395451","rc":[{"atb":[[9.6,16.39],[9.8,0]],"id":39979879},{"atl":[[1.71,0]],"id":42492389}],"con":true,"img":false}]}
{"op":"mcm","clk":"5346786945","pt":1646097003384,"mc":[{"id":"1.195395451","rc":[{"atb":[[1.19,0]],"id":42492389}],"con":true,"img":false}]}
{"op":"mcm","clk":"5346787024","pt":1646097005796,"mc":[{"id":"1.195395451","rc":[{"atb":[[6,47.45]],"id":41921674},{"atl":[[38,3.38]],"id":41921674},{"atb":[[9.8,2.27]],"id":39979879},{"atb":[[9.6,8.72]],"id":39722911},{"atl":[[290,1]],"id":39722911},{"atl":[[1.71,28.17]],"id":42492389}],"con":true,"img":false}]}
{"op":"mcm","clk":"5346787070","pt":1646097007289,"mc":[{"id":"1.195395451","rc":[{"atb":[[1.19,8.92]],"id":42492389}],"con":true,"img":false}]}
{"op":"mcm","clk":"5346787087","pt":1646097007700,"mc":[{"id":"1.195395451","rc":[{"atl":[[440,1]],"id":27151693}],"con":true,"img":false}]}
{"op":"mcm","clk":"5346787184","pt":1646097010695,"mc":[{"id":"1.195395451","rc":[{"atb":[[9.8,0]],"id":39979879},{"atb":[[17.5,5.6]],"id":39722911},{"atb":[[1.15,270.43]],"id":42492389}],"con":true,"img":false}]}
{"op":"mcm","clk":"5346787195","pt":1646097010797,"mc":[{"id":"1.195395451","rc":[{"atb":[[18,2.7]],"id":39722911},{"atb":[[1.14,43.26]],"id":42492389},{"atl":[[1.71,0]],"id":42492389}],"con":true,"img":false}]}
{"op":"mcm","clk":"5346787209","pt":1646097011310,"mc":[{"id":"1.195395451","rc":[{"atb":[[11.5,8.45]],"id":39979879}],"con":true,"img":false}]}
{"op":"mcm","clk":"5346787212","pt":1646097011413,"mc":[{"id":"1.195395451","rc":[{"atb":[[12,0.92]],"id":39979879}],"con":true,"img":false}]}
{"op":"mcm","clk":"5346787216","pt":1646097011516,"mc":[{"id":"1.195395451","rc":[{"atl":[[40,1.28]],"id":40251221}],"con":true,"img":false}]}
{"op":"mcm","clk":"5346787282","pt":1646097013419,"mc":[{"id":"1.195395451","rc":[{"atb":[[9.8,2.27]],"id":39979879},{"atl":[[1.71,28.17]],"id":42492389}],"con":true,"img":false}]}
{"op":"mcm","clk":"5346787285","pt":1646097013522,"mc":[{"id":"1.195395451","rc":[{"atl":[[38,0],[42,0],[46,0]],"id":40251221}],"con":true,"img":false}]}
{"op":"mcm","clk":"5346787335","pt":1646097015018,"mc":[{"id":"1.195395451","rc":[{"atb":[[13,0]],"id":40251221}],"con":true,"img":false}]}
{"op":"mcm","clk":"5346787359","pt":1646097015795,"mc":[{"id":"1.195395451","rc":[{"atb":[[5.8,26.04]],"id":41921674},{"atb":[[9.2,27.44]],"id":39722911}],"con":true,"img":false}]}
{"op":"mcm","clk":"5346787408","pt":1646097017696,"mc":[{"id":"1.195395451","rc":[{"atl":[[460,1]],"id":27151693}],"con":true,"img":false}]}
{"op":"mcm","clk":"5346787437","pt":1646097018619,"mc":[{"id":"1.195395451","rc":[{"atb":[[9.8,0]],"id":39979879}],"con":true,"img":false}]}
{"op":"mcm","clk":"5346787439","pt":1646097018721,"mc":[{"id":"1.195395451","rc":[{"atl":[[1.71,0]],"id":42492389}],"con":true,"img":false}]}
{"op":"mcm","clk":"5346787444","pt":1646097018826,"mc":[{"id":"1.195395451","rc":[{"atb":[[13,7.71]],"id":40251221}],"con":true,"img":false}]}
{"op":"mcm","clk":"5346787505","pt":1646097020735,"mc":[{"id":"1.195395451","rc":[{"atl":[[1.7,0]],"id":42492389},{"atb":[[16,0]],"id":27151693}],"con":true,"img":false}]}
{"op":"mcm","clk":"5346787509","pt":1646097020834,"mc":[{"id":"1.195395451","rc":[{"atb":[[17,7.1]],"id":27151693},{"atl":[[1.66,43.26]],"id":42492389}],"con":true,"img":false}]}
{"op":"mcm","clk":"5346787534","pt":1646097021499,"mc":[{"id":"1.195395451","rc":[{"spn":19.5,"spf":1.0,"id":41921674},{"atl":[[44,1.74]],"id":40251221}],"con":true,"img":false}]}
{"op":"mcm","clk":"5346787558","pt":1646097022628,"mc":[{"id":"1.195395451","rc":[{"atb":[[9.8,2.27]],"id":39979879},{"atl":[[1.71,28.17]],"id":42492389}],"con":true,"img":false}]}
{"op":"mcm","clk":"5346787614","pt":1646097024534,"mc":[{"id":"1.195395451","rc":[{"atb":[[1.19,0]],"id":42492389}],"con":true,"img":false}]}
{"op":"mcm","clk":"5346787682","pt":1646097026549,"mc":[{"id":"1.195395451","rc":[{"atl":[[1.71,0]],"id":42492389}],"con":true,"img":false}]}
{"op":"mcm","clk":"5346787688","pt":1646097026652,"mc":[{"id":"1.195395451","rc":[{"atb":[[9.8,0]],"id":39979879}],"con":true,"img":false}]}
{"op":"mcm","clk":"5346787747","pt":1646097027737,"mc":[{"id":"1.195395451","rc":[{"atl":[[480,1]],"id":27151693}],"con":true,"img":false}]}
{"op":"mcm","clk":"5346787767","pt":1646097028454,"mc":[{"id":"1.195395451","rc":[{"atb":[[1.19,8.92]],"id":42492389}],"con":true,"img":false}]}
{"op":"mcm","clk":"5346787857","pt":1646097030360,"mc":[{"id":"1.195395451","rc":[{"atb":[[9.8,2.27]],"id":39979879},{"atl":[[1.71,28.17],[1.67,10.8]],"id":42492389}],"con":true,"img":false}]}
{"op":"mcm","clk":"5346787872","pt":1646097030772,"mc":[{"id":"1.195395451","rc":[{"atb":[[15,0]],"id":36899924},{"atl":[[1.66,0]],"id":42492389}],"con":true,"img":false}]}
{"op":"mcm","clk":"5346787877","pt":1646097030875,"mc":[{"id":"1.195395451","rc":[{"atb":[[16,3.08]],"id":36899924},{"atl":[[1.7,43.26]],"id":42492389}],"con":true,"img":false}]}
{"op":"mcm","clk":"5346787895","pt":1646097031441,"mc":[{"id":"1.195395451","rc":[{"atl":[[48,2.66]],"id":40251221}],"con":true,"img":false}]}
{"op":"mcm","clk":"5346787992","pt":1646097034267,"mc":[{"id":"1.195395451","rc":[{"atb":[[15.5,0]],"id":36899924},{"atb":[[1.19,0]],"id":42492389}],"con":true,"img":false}]}
{"op":"mcm","clk":"5346788012","pt":1646097034733,"mc":[{"id":"1.195395451","rc":[{"atb":[[9.8,0]],"id":39979879},{"atl":[[1.71,0]],"id":42492389}],"con":true,"img":false}]}
{"op":"mcm","clk":"5346788062","pt":1646097036170,"mc":[{"id":"1.195395451","rc":[{"atl":[[1.71,10.75]],"id":42492389}],"con":true,"img":false}]}
{"op":"mcm","clk":"5346788088","pt":1646097036838,"mc":[{"id":"1.195395451","rc":[{"atl":[[75,9.98]],"id":41921674}],"con":true,"img":false}]}
{"op":"mcm","clk":"5346788091","pt":1646097036940,"mc":[{"id":"1.195395451","rc":[{"atl":[[1000,1.67]],"id":41921674},{"atl":[[1000,1.67]],"id":40251221},{"atl":[[1000,1.67]],"id":39979879}],"con":true,"img":false}]}
{"op":"mcm","clk":"5346788097","pt":1646097037144,"mc":[{"id":"1.195395451","rc":[{"atl":[[1000,0.3]],"id":41921674}],"con":true,"img":false}]}
{"op":"mcm","clk":"5346788099","pt":1646097037249,"mc":[{"id":"1.195395451","rc":[{"atl":[[1000,0.24]],"id":40251221},{"atl":[[1000,0.24]],"id":39979879}],"con":true,"img":false}]}
{"op":"mcm","clk":"5346788107","pt":1646097037454,"mc":[{"id":"1.195395451","rc":[{"atl":[[1000,0]],"id":41921674}],"con":true,"img":false}]}
{"op":"mcm","clk":"5346788112","pt":1646097037558,"mc":[{"id":"1.195395451","rc":[{"atl":[[27,0.3]],"id":41921674}],"con":true,"img":false}]}
{"op":"mcm","clk":"5346788116","pt":1646097037661,"mc":[{"id":"1.195395451","rc":[{"atl":[[1000,0]],"id":40251221}],"con":true,"img":false}]}
{"op":"mcm","clk":"5346788120","pt":1646097037763,"mc":[{"id":"1.195395451","rc":[{"atl":[[34,0.24]],"id":40251221}],"con":true,"img":false}]}
{"op":"mcm","clk":"5346788127","pt":1646097037967,"mc":[{"id":"1.195395451","rc":[{"atl":[[1000,0]],"id":39979879}],"con":true,"img":false}]}
{"op":"mcm","clk":"5346788133","pt":1646097038074,"mc":[{"id":"1.195395451","rc":[{"atb":[[9.8,2.27]],"id":39979879},{"atl":[[34,0.24]],"id":39979879},{"atl":[[1.71,38.92]],"id":42492389}],"con":true,"img":false}]}
{"op":"mcm","clk":"5346788141","pt":1646097038276,"mc":[{"id":"1.195395451","rc":[{"atb":[[17.5,5.35]],"id":36899924},{"atb":[[1.19,8.92]],"id":42492389}],"con":true,"img":false}]}
{"op":"mcm","clk":"5346788248","pt":1646097040648,"mc":[{"id":"1.195395451","rc":[{"atb":[[16,0]],"id":36899924}],"con":true,"img":false}]}
{"op":"mcm","clk":"5346788254","pt":1646097040748,"mc":[{"id":"1.195395451","rc":[{"atb":[[15,3.08]],"id":36899924}],"con":true,"img":false}]}
{"op":"mcm","clk":"5346788279","pt":1646097041467,"mc":[{"id":"1.195395451","rc":[{"atl":[[1.67,0]],"id":42492389}],"con":true,"img":false}]}
{"op":"mcm","clk":"5346788302","pt":1646097042083,"mc":[{"id":"1.195395451","rc":[{"atb":[[9.8,0]],"id":39979879},{"atl":[[1.71,10.75]],"id":42492389}],"con":true,"img":false}]}
{"op":"mcm","clk":"5346788389","pt":1646097043983,"mc":[{"id":"1.195395451","rc":[{"atb":[[17.5,0.62]],"id":36899924},{"atb":[[1.19,0]],"id":42492389}],"con":true,"img":false}]}
{"op":"mcm","clk":"5346788401","pt":1646097044346,"mc":[{"id":"1.195395451","rc":[{"atl":[[1.71,21.3]],"id":42492389}],"con":true,"img":false}]}
{"op":"mcm","clk":"5346788468","pt":1646097046245,"mc":[{"id":"1.195395451","rc":[{"atb":[[9.8,2.27]],"id":39979879},{"atl":[[1.71,49.47]],"id":42492389}],"con":true,"img":false}]}
{"op":"mcm","clk":"5346788518","pt":1646097047885,"mc":[{"id":"1.195395451","rc":[{"atb":[[15.5,6.38]],"id":36899924},{"atb":[[1.19,8.92]],"id":42492389}],"con":true,"img":false}]}
{"op":"mcm","clk":"5346788583","pt":1646097049891,"mc":[{"id":"1.195395451","rc":[{"atl":[[1.71,21.3]],"id":42492389}],"con":true,"img":false}]}
{"op":"mcm","clk":"5346788587","pt":1646097049991,"mc":[{"id":"1.195395451","rc":[{"atb":[[9.8,0]],"id":39979879}],"con":true,"img":false}]}
{"op":"mcm","clk":"5346788726","pt":1646097054604,"mc":[{"id":"1.195395451","rc":[{"atb":[[9.8,2.27]],"id":39979879},{"atl":[[1.71,49.47]],"id":42492389}],"con":true,"img":false}]}
{"op":"mcm","clk":"5346788831","pt":1646097057685,"mc":[{"id":"1.195395451","rc":[{"atb":[[9.8,0]],"id":39979879},{"atl":[[1.71,21.3]],"id":42492389}],"con":true,"img":false}]}
{"op":"mcm","clk":"5346788984","pt":1646097062287,"mc":[{"id":"1.195395451","rc":[{"atb":[[1.05,2.8]],"id":41921674},{"atb":[[1.06,2.78]],"id":40251221},{"atb":[[1.05,2.79]],"id":39979879},{"atb":[[1.02,3.51]],"id":42492389}],"con":true,"img":false}]}
{"op":"mcm","clk":"5346788996","pt":1646097062703,"mc":[{"id":"1.195395451","rc":[{"atb":[[1.05,0.1]],"id":41921674},{"atb":[[9.8,2.27],[1.05,0.08]],"id":39979879},{"atb":[[1.02,0.81]],"id":42492389},{"atl":[[1.71,49.47]],"id":42492389}],"con":true,"img":false}]}
{"op":"mcm","clk":"5346788998","pt":1646097062803,"mc":[{"id":"1.195395451","rc":[{"atb":[[1.06,0.08]],"id":40251221}],"con":true,"img":false}]}
{"op":"mcm","clk":"5346789017","pt":1646097063172,"mc":[{"id":"1.195395451","rc":[{"atb":[[1.05,0]],"id":41921674},{"atb":[[1.06,0]],"id":40251221},{"atb":[[1.05,0]],"id":39979879},{"atb":[[1.02,0]],"id":42492389}],"con":true,"img":false}]}
{"op":"mcm","clk":"5346789024","pt":1646097063273,"mc":[{"id":"1.195395451","rc":[{"atb":[[10.5,4.65]],"id":41921674},{"atb":[[13,7.79]],"id":40251221},{"atb":[[12,1]],"id":39979879},{"atb":[[1.31,0.81]],"id":42492389}],"con":true,"img":false}]}
{"op":"mcm","clk":"5346789073","pt":1646097064679,"mc":[{"id":"1.195395451","rc":[{"atb":[[15,0]],"id":36899924}],"con":true,"img":false}]}
{"op":"mcm","clk":"5346789078","pt":1646097064781,"mc":[{"id":"1.195395451","rc":[{"atb":[[16,3.08]],"id":36899924}],"con":true,"img":false}]}
{"op":"mcm","clk":"5346789140","pt":1646097066383,"mc":[{"id":"1.195395451","rc":[{"atl":[[130,2],[150,2.7]],"id":36899924},{"atl":[[85,2]],"id":40251221},{"atb":[[9.8,0]],"id":39979879},{"atl":[[130,2]],"id":39722911},{"atl":[[1.71,21.3]],"id":42492389},{"atl":[[330,2],[400,0]],"id":27151693}],"con":true,"img":false}]}
{"op":"mcm","clk":"5346789143","pt":1646097066485,"mc":[{"id":"1.195395451","rc":[{"atl":[[130,0]],"id":40251221},{"atl":[[140,2.7]],"id":39722911}],"con":true,"img":false}]}
{"op":"mcm","clk":"5346789166","pt":1646097067000,"mc":[{"id":"1.195395451","rc":[{"atb":[[15.5,0]],"id":36899924},{"atb":[[1.03,1.67]],"id":40251221},{"atl":[[1000,1.67]],"id":43154431}],"con":true,"img":false}]}
{"op":"mcm","clk":"5346789169","pt":1646097067100,"mc":[{"id":"1.195395451","rc":[{"atb":[[1.01,1.67]],"id":41921674},{"atb":[[1.03,1.67]],"id":39979879}],"con":true,"img":false}]}
{"op":"mcm","clk":"5346789171","pt":1646097067204,"mc":[{"id":"1.195395451","rc":[{"atl":[[1000,1.67]],"id":36899924},{"atl":[[1000,1.67]],"id":39722911}],"con":true,"img":false}]}
{"op":"mcm","clk":"5346789176","pt":1646097067307,"mc":[{"id":"1.195395451","rc":[{"atb":[[1.03,0.54]],"id":40251221},{"atl":[[1000,0.08]],"id":43154431}],"con":true,"img":false}]}
{"op":"mcm","clk":"5346789177","pt":1646097067411,"mc":[{"id":"1.195395451","rc":[{"atb":[[1.01,0.72]],"id":41921674},{"atb":[[1.03,0.61]],"id":39979879}],"con":true,"img":false}]}
{"op":"mcm","clk":"5346789180","pt":1646097067512,"mc":[{"id":"1.195395451","rc":[{"atl":[[1000,0.09]],"id":36899924},{"atl":[[1000,0.08]],"id":39722911},{"atl":[[1000,0]],"id":43154431}],"con":true,"img":false}]}
{"op":"mcm","clk":"5346789184","pt":1646097067615,"mc":[{"id":"1.195395451","rc":[{"atl":[[100,0.08]],"id":43154431}],"con":true,"img":false}]}
{"op":"mcm","clk":"5346789188","pt":1646097067819,"mc":[{"id":"1.195395451","rc":[{"atb":[[1.03,0]],"id":40251221}],"con":true,"img":false}]}
{"op":"mcm","clk":"5346789194","pt":1646097067922,"mc":[{"id":"1.195395451","rc":[{"atb":[[15.5,0.54]],"id":40251221}],"con":true,"img":false}]}
{"op":"mcm","clk":"5346789202","pt":1646097068082,"mc":[{"id":"1.195395451","rc":[{"atb":[[1.01,0]],"id":41921674}],"con":true,"img":false}]}
{"op":"mcm","clk":"5346789209","pt":1646097068191,"mc":[{"id":"1.195395451","rc":[{"atb":[[11.5,0.72]],"id":41921674}],"con":true,"img":false}]}
{"op":"mcm","clk":"5346789218","pt":1646097068389,"mc":[{"id":"1.195395451","rc":[{"atb":[[1.03,0]],"id":39979879}],"con":true,"img":false}]}
{"op":"mcm","clk":"5346789221","pt":1646097068492,"mc":[{"id":"1.195395451","rc":[{"atb":[[13.5,0.61]],"id":39979879}],"con":true,"img":false}]}
{"op":"mcm","clk":"5346789227","pt":1646097068698,"mc":[{"id":"1.195395451","rc":[{"atl":[[1000,0]],"id":36899924}],"con":true,"img":false}]}
{"op":"mcm","clk":"5346789234","pt":1646097068804,"mc":[{"id":"1.195395451","rc":[{"atl":[[95,0.09]],"id":36899924}],"con":true,"img":false}]}
{"op":"mcm","clk":"5346789238","pt":1646097068908,"mc":[{"id":"1.195395451","rc":[{"atl":[[1000,0]],"id":39722911}],"con":true,"img":false}]}
{"op":"mcm","clk":"5346789241","pt":1646097069005,"mc":[{"id":"1.195395451","rc":[{"atl":[[100,0.08]],"id":39722911}],"con":true,"img":false}]}
{"op":"mcm","clk":"5346789309","pt":1646097070909,"mc":[{"id":"1.195395451","rc":[{"atb":[[17.5,5.35]],"id":36899924}],"con":true,"img":false}]}
{"op":"mcm","clk":"5346789321","pt":1646097071213,"mc":[{"id":"1.195395451","rc":[{"atb":[[9.8,2.27]],"id":39979879},{"atl":[[1.71,49.47]],"id":42492389}],"con":true,"img":false}]}
{"op":"mcm","clk":"5346789451","pt":1646097074395,"mc":[{"id":"1.195395451","rc":[{"atb":[[9.8,0]],"id":39979879}],"con":true,"img":false}]}
{"op":"mcm","clk":"5346789455","pt":1646097074495,"mc":[{"id":"1.195395451","rc":[{"atl":[[1.71,21.3]],"id":42492389}],"con":true,"img":false}]}
{"op":"mcm","clk":"5346789495","pt":1646097075724,"mc":[{"id":"1.195395451","rc":[{"atl":[[95,0]],"id":41921674},{"atb":[[16,0]],"id":36899924}],"con":true,"img":false}]}
{"op":"mcm","clk":"5346789502","pt":1646097075827,"mc":[{"id":"1.195395451","rc":[{"atl":[[48,2.7]],"id":41921674},{"atb":[[15,3.08]],"id":36899924}],"con":true,"img":false}]}
{"op":"mcm","clk":"5346789594","pt":1646097078706,"mc":[{"id":"1.195395451","rc":[{"atb":[[17.5,0.62]],"id":36899924}],"con":true,"img":false}]}
{"op":"mcm","clk":"5346789640","pt":1646097080508,"mc":[{"id":"1.195395451","rc":[{"atb":[[9.8,2.27]],"id":39979879},{"atl":[[1.71,49.47]],"id":42492389}],"con":true,"img":false}]}
{"op":"mcm","clk":"5346789712","pt":1646097082625,"mc":[{"id":"1.195395451","rc":[{"spn":19.25,"spf":1.0,"id":41921674},{"atb":[[15.5,6.38]],"id":36899924},{"spn":56.25,"spf":1.0,"id":36899924},{"spn":15.1,"spf":1.0,"id":40251221},{"spn":23.75,"spf":1.0,"id":39979879},{"spn":1.19,"spf":1.0,"id":42492389}],"con":true,"img":false}]}
{"op":"mcm","clk":"5346789722","pt":1646097082929,"mc":[{"id":"1.195395451","rc":[{"atb":[[9.8,0]],"id":39979879}],"con":true,"img":false}]}
{"op":"mcm","clk":"5346789725","pt":1646097083030,"mc":[{"id":"1.195395451","rc":[{"atl":[[1.71,21.3]],"id":42492389}],"con":true,"img":false}]}
{"op":"mcm","clk":"5346789946","pt":1646097088748,"mc":[{"id":"1.195395451","rc":[{"atb":[[9.8,2.27]],"id":39979879},{"atl":[[1.71,49.47]],"id":42492389}],"con":true,"img":false}]}
{"op":"mcm","clk":"5346789997","pt":1646097090135,"mc":[{"id":"1.195395451","rc":[{"atb":[[9.8,0]],"id":39979879},{"atl":[[1.71,21.3]],"id":42492389}],"con":true,"img":false}]}
{"op":"mcm","clk":"5346790234","pt":1646097096449,"mc":[{"id":"1.195395451","rc":[{"atb":[[9.8,2.27]],"id":39979879},{"atl":[[1.71,49.47]],"id":42492389}],"con":true,"img":false}]}
{"op":"mcm","clk":"5346790288","pt":1646097098247,"mc":[{"id":"1.195395451","rc":[{"atb":[[9.8,0]],"id":39979879},{"atl":[[1.71,21.3]],"id":42492389}],"con":true,"img":false}]}
{"op":"mcm","clk":"5346790309","pt":1646097098656,"mc":[{"id":"1.195395451","rc":[{"atl":[[130,0],[150,4.7],[200,0],[210,1]],"id":36899924},{"atb":[[8.4,20.27],[7,0]],"id":40251221},{"atl":[[36,0],[42,1]],"id":40251221},{"atb":[[10,2.22]],"id":39979879},{"atl":[[130,0],[140,4.7]],"id":39722911},{"atb":[[1.17,0]],"id":42492389},{"atl":[[1.89,0],[1.74,130.89],[1.65,35.2]],"id":42492389},{"atb":[[16.5,0],[18.5,7.47]],"id":27151693},{"atl":[[420,0],[450,1]],"id":27151693}],"con":true,"img":false}]}
{"op":"mcm","clk":"5346790314","pt":1646097098760,"mc":[{"id":"1.195395451","rc":[{"atl":[[95,0],[1000,1.67]],"id":36899924},{"atb":[[1.16,2]],"id":42492389}],"con":true,"img":false}]}
{"op":"mcm","clk":"5346790325","pt":1646097098967,"mc":[{"id":"1.195395451","rc":[{"atl":[[1000,0.09]],"id":36899924},{"atl":[[100,0],[1000,1.67]],"id":39722911}],"con":true,"img":false}]}
{"op":"mcm","clk":"5346790334","pt":1646097099174,"mc":[{"id":"1.195395451","rc":[{"atl":[[1000,0]],"id":36899924}],"con":true,"img":false}]}
{"op":"mcm","clk":"5346790341","pt":1646097099230,"mc":[{"id":"1.195395451","rc":[{"atl":[[140,0.09]],"id":36899924}],"con":true,"img":false}]}
{"op":"mcm","clk":"5346790354","pt":1646097099432,"mc":[{"id":"1.195395451","rc":[{"atl":[[1000,0.08]],"id":39722911}],"con":true,"img":false}]}
{"op":"mcm","clk":"5346790357","pt":1646097099534,"mc":[{"id":"1.195395451","rc":[{"atl":[[40,0]],"id":40251221},{"atl":[[440,0]],"id":27151693}],"con":true,"img":false}]}
{"op":"mcm","clk":"5346790366","pt":1646097099740,"mc":[{"id":"1.195395451","rc":[{"atl":[[1000,0]],"id":39722911}],"con":true,"img":false}]}
{"op":"mcm","clk":"5346790370","pt":1646097099844,"mc":[{"id":"1.195395451","rc":[{"atl":[[130,0.08]],"id":39722911}],"con":true,"img":false}]}
{"op":"mcm","clk":"5346790380","pt":1646097100149,"mc":[{"id":"1.195395451","rc":[{"atl":[[450,0],[470,1]],"id":27151693}],"con":true,"img":false}]}
{"op":"mcm","clk":"5346790402","pt":1646097100766,"mc":[{"id":"1.195395451","rc":[{"atl":[[48,0]],"id":41921674},{"atb":[[17,0]],"id":27151693},{"atl":[[1.88,0]],"id":42492389}],"con":true,"img":false}]}
{"op":"mcm","clk":"5346790407","pt":1646097100870,"mc":[{"id":"1.195395451","rc":[{"atl":[[70,2.7]],"id":41921674},{"atl":[[2.12,130.88]],"id":42492389},{"atb":[[16,7.1]],"id":27151693}],"con":true,"img":false}]}
{"op":"mcm","clk":"5346790565","pt":1646097104776,"mc":[{"id":"1.195395451","rc":[{"atl":[[460,0]],"id":27151693}],"con":true,"img":false}]}
{"op":"mcm","clk":"5346790632","pt":1646097106679,"mc":[{"id":"1.195395451","rc":[{"atl":[[150,2.7],[160,2]],"id":36899924}],"con":true,"img":false}]}
{"op":"mcm","clk":"5346790677","pt":1646097107758,"mc":[{"id":"1.195395451","rc":[{"atb":[[18.5,2.7],[20,4.77]],"id":27151693},{"atl":[[1.72,98.18],[1.74,0]],"id":42492389}],"con":true,"img":false}]}
{"op":"mcm","clk":"5346790710","pt":1646097108576,"mc":[{"id":"1.195395451","rc":[{"atl":[[230,1]],"id":36899924},{"atl":[[46,1.11]],"id":40251221},{"atb":[[9.6,19.87]],"id":39979879},{"atb":[[1.09,250]],"id":42492389},{"atl":[[1.67,74.63]],"id":42492389}],"con":true,"img":false}]}
{"op":"mcm","clk":"5346790777","pt":1646097110173,"mc":[{"id":"1.195395451","rc":[{"atl":[[490,1]],"id":27151693}],"con":true,"img":false}]}
{"op":"mcm","clk":"5346790804","pt":1646097110684,"mc":[{"id":"1.195395451","rc":[{"atb":[[15,0]],"id":36899924},{"atl":[[120,0]],"id":40251221},{"atl":[[120,2]],"id":43154431}],"con":true,"img":false}]}
{"op":"mcm","clk":"5346790807","pt":1646097110787,"mc":[{"id":"1.195395451","rc":[{"atb":[[16,3.08]],"id":36899924},{"atl":[[95,2.7]],"id":40251221},{"atl":[[220,2.7]],"id":43154431}],"con":true,"img":false}]}
{"op":"mcm","clk":"5346790830","pt":1646097111562,"mc":[{"id":"1.195395451","rc":[{"atb":[[1.19,0]],"id":42492389}],"con":true,"img":false}]}
{"op":"mcm","clk":"5346790870","pt":1646097112788,"mc":[{"id":"1.195395451","rc":[{"atl":[[260,0],[220,0.9],[240,0]],"id":36899924}],"con":true,"img":false}]}
{"op":"mcm","clk":"5346790876","pt":1646097112892,"mc":[{"id":"1.195395451","rc":[{"atl":[[1.72,70.4]],"id":42492389}],"con":true,"img":false}]}
{"op":"mcm","clk":"5346790898","pt":1646097113458,"mc":[{"id":"1.195395451","rc":[{"atb":[[15.5,0]],"id":36899924}],"con":true,"img":false}]}
{"op":"mcm","clk":"5346790971","pt":1646097115473,"mc":[{"id":"1.195395451","rc":[{"atb":[[1.19,10.13]],"id":42492389}],"con":true,"img":false}]}
{"op":"mcm","clk":"5346790985","pt":1646097115782,"mc":[{"id":"1.195395451","rc":[{"atl":[[150,4.7],[160,0]],"id":36899924}],"con":true,"img":false}]}
{"op":"mcm","clk":"5346791049","pt":1646097117478,"mc":[{"id":"1.195395451","rc":[{"atb":[[17.5,5.35]],"id":36899924}],"con":true,"img":false}]}
{"op":"mcm","clk":"5346791093","pt":1646097118560,"mc":[{"id":"1.195395451","rc":[{"atl":[[250,1]],"id":36899924},{"atl":[[50,1.53]],"id":40251221},{"atb":[[9.2,23.99]],"id":39979879},{"atb":[[1.07,250]],"id":42492389},{"atl":[[1.69,108.7]],"id":42492389}],"con":true,"img":false}]}
{"op":"mcm","clk":"5346791123","pt":1646097119382,"mc":[{"id":"1.195395451","rc":[{"atl":[[44,0],[48,0]],"id":40251221},{"atl":[[1.75,0]],"id":42492389}],"con":true,"img":false}]}
{"op":"mcm","clk":"5346791164","pt":1646097120204,"mc":[{"id":"1.195395451","rc":[{"atl":[[510,1]],"id":27151693}],"con":true,"img":false}]}
{"op":"mcm","clk":"5346791176","pt":1646097120411,"mc":[{"id":"1.195395451","rc":[{"atb":[[8,20.24],[6.8,0]],"id":41921674},{"atb":[[10,15.74],[8.8,0]],"id":40251221},{"atb":[[11,0],[12,12.88]],"id":39722911},{"atb":[[1.12,1099.65]],"id":42492389},{"atl":[[1.63,31.75],[1.65,4.43]],"id":42492389},{"atb":[[11,0],[6.8,17.24],[12.5,1.74],[5.6,0]],"id":43154431}],"con":true,"img":false}]}
{"op":"mcm","clk":"5346791182","pt":1646097120462,"mc":[{"id":"1.195395451","rc":[{"atb":[[1.13,0]],"id":42492389}],"con":true,"img":false}]}
{"op":"mcm","clk":"5346791193","pt":1646097120668,"mc":[{"id":"1.195395451","rc":[{"atb":[[16,0]],"id":36899924},{"atl":[[1.7,0]],"id":42492389}],"con":true,"img":false}]}
{"op":"mcm","clk":"5346791196","pt":1646097120771,"mc":[{"id":"1.195395451","rc":[{"atb":[[15,3.08]],"id":36899924},{"atl":[[1.64,43.26]],"id":42492389}],"con":true,"img":false}]}
{"op":"mcm","clk":"5346791233","pt":1646097121694,"mc":[{"id":"1.195395451","rc":[{"atl":[[1.65,0]],"id":42492389}],"con":true,"img":false}]}
{"op":"mcm","clk":"5346791266","pt":1646097122679,"mc":[{"id":"1.195395451","rc":[{"atl":[[470,0]],"id":27151693}],"con":true,"img":false}]}
{"op":"mcm","clk":"5346791292","pt":1646097123294,"mc":[{"id":"1.195395451","rc":[{"atb":[[17.5,0.62]],"id":36899924},{"atb":[[1.19,0]],"id":42492389}],"con":true,"img":false}]}
{"op":"mcm","clk":"5346791352","pt":1646097124789,"mc":[{"id":"1.195395451","rc":[{"atl":[[140,2.09]],"id":36899924}],"con":true,"img":false}]}
{"op":"mcm","clk":"5346791360","pt":1646097124891,"mc":[{"id":"1.195395451","rc":[{"atl":[[150,2.7]],"id":36899924}],"con":true,"img":false}]}
{"op":"mcm","clk":"5346791448","pt":1646097127001,"mc":[{"id":"1.195395451","rc":[{"atl":[[34,0],[1000,1.67]],"id":40251221}],"con":true,"img":false}]}
{"op":"mcm","clk":"5346791459","pt":1646097127307,"mc":[{"id":"1.195395451","rc":[{"atb":[[15.5,6.38]],"id":36899924},{"atl":[[1000,0.24]],"id":40251221},{"atb":[[1.19,10.13]],"id":42492389}],"con":true,"img":false}]}
{"op":"mcm","clk":"5346791467","pt":1646097127515,"mc":[{"id":"1.195395451","rc":[{"atl":[[1000,0]],"id":40251221}],"con":true,"img":false}]}
{"op":"mcm","clk":"5346791470","pt":1646097127617,"mc":[{"id":"1.195395451","rc":[{"atl":[[40,0.24]],"id":40251221},{"atl":[[1.62,4.41]],"id":42492389}],"con":true,"img":false}]}
{"op":"mcm","clk":"5346791501","pt":1646097128391,"mc":[{"id":"1.195395451","rc":[{"atl":[[470,1]],"id":27151693}],"con":true,"img":false}]}
{"op":"mcm","clk":"5346791511","pt":1646097128597,"mc":[{"id":"1.195395451","rc":[{"atb":[[8.8,16.03]],"id":39979879}],"con":true,"img":false}]}
{"op":"mcm","clk":"5346791516","pt":1646097128698,"mc":[{"id":"1.195395451","rc":[{"atl":[[270,1.73]],"id":36899924}],"con":true,"img":false}]}
{"op":"mcm","clk":"5346791542","pt":1646097129317,"mc":[{"id":"1.195395451","rc":[{"atb":[[17.5,0],[17,0]],"id":36899924},{"atl":[[17,2.24]],"id":36899924},{"trd":[[17,5.07],[17.5,1.24]],"ltp":17.0,"tv":6.31,"id":36899924}],"con":true,"img":false}]}
{"op":"mcm","clk":"5346791588","pt":1646097130399,"mc":[{"id":"1.195395451","rc":[{"atb":[[7.6,7.58]],"id":41921674},{"atb":[[9.6,5.81]],"id":40251221},{"atl":[[60,2.74]],"id":40251221},{"atb":[[11,5]],"id":39722911},{"atb":[[1.1,1061.29]],"id":42492389},{"atl":[[1.65,76.92]],"id":42492389},{"atb":[[11.5,4.76]],"id":43154431}],"con":true,"img":false}]}
{"op":"mcm","clk":"5346791599","pt":1646097130605,"mc":[{"id":"1.195395451","rc":[{"atb":[[4.3,0],[5.8,0],[4.9,25.64]],"id":41921674},{"atl":[[200,1],[210,0]],"id":36899924},{"atb":[[7.6,0]],"id":40251221},{"atl":[[130,2],[42,0],[85,0]],"id":40251221},{"atb":[[9.4,0],[9.6,5.81]],"id":39979879},{"atb":[[9.2,12.2]],"id":39722911},{"atl":[[140,2.7],[170,2.78]],"id":39722911},{"atb":[[1.09,0],[1.11,653.76],[1.07,0]],"id":42492389},{"atl":[[1.73,0],[1.6,33.33],[1.68,86.54],[1.69,0],[1.72,0],[1.63,0],[1.67,0],[1.65,0]],"id":42492389},{"atb":[[18,10.65],[20,0]],"id":27151693},{"atl":[[440,1],[470,0]],"id":27151693},{"atb":[[9,0]],"id":43154431}],"con":true,"img":false}]}
{"op":"mcm","clk":"5346791604","pt":1646097130706,"mc":[{"id":"1.195395451","rc":[{"atb":[[9.8,14.06]],"id":39979879}],"con":true,"img":false}]}
{"op":"mcm","clk":"5346791613","pt":1646097130913,"mc":[{"id":"1.195395451","rc":[{"atb":[[8.4,6.76],[9.4,11.9]],"id":40251221},{"atl":[[44,1]],"id":40251221},{"atb":[[17.5,3]],"id":39979879},{"atb":[[9.2,0],[10.5,10.53]],"id":39722911},{"atl":[[1.41,2]],"id":42492389}],"con":true,"img":false}]}
{"op":"mcm","clk":"5346791706","pt":1646097133119,"mc":[{"id":"1.195395451","rc":[{"atb":[[15.5,0]],"id":36899924},{"atb":[[11.5,0]],"id":39979879},{"atb":[[1.19,0]],"id":42492389}],"con":true,"img":false}]}
{"op":"mcm","clk":"5346791730","pt":1646097133683,"mc":[{"id":"1.195395451","rc":[{"atl":[[1.62,0]],"id":42492389}],"con":true,"img":false}]}
{"op":"mcm","clk":"5346791850","pt":1646097136611,"mc":[{"id":"1.195395451","rc":[{"atl":[[44,0]],"id":40251221},{"atb":[[18,3]],"id":39979879},{"atl":[[1.4,3]],"id":42492389}],"con":true,"img":false}]}
{"op":"mcm","clk":"5346791861","pt":1646097136816,"mc":[{"id":"1.195395451","rc":[{"atb":[[18.5,4]],"id":39979879},{"atl":[[1.58,34.48],[1.39,2]],"id":42492389},{"atl":[[440,0],[460,1]],"id":27151693}],"con":true,"img":false}]}
{"op":"mcm","clk":"5346791872","pt":1646097137123,"mc":[{"id":"1.195395451","rc":[{"atb":[[20,3.86]],"id":27151693},{"atb":[[1.22,11.57]],"id":42492389}],"con":true,"img":false}]}
{"op":"mcm","clk":"5346791882","pt":1646097137329,"mc":[{"id":"1.195395451","rc":[{"atb":[[11,0]],"id":41921674},{"atb":[[12,0.08]],"id":39979879}],"con":true,"img":false}]}
{"op":"mcm","clk":"5346791893","pt":1646097137535,"mc":[{"id":"1.195395451","rc":[{"atb":[[11.5,1.68]],"id":41921674},{"atb":[[12.5,0.88]],"id":39979879}],"con":true,"img":false}]}
{"op":"mcm","clk":"5346791962","pt":1646097139433,"mc":[{"id":"1.195395451","rc":[{"atb":[[18,4.77],[20,7.92]],"id":27151693}],"con":true,"img":false}]}
{"op":"mcm","clk":"5346791996","pt":1646097140409,"mc":[{"id":"1.195395451","rc":[{"atb":[[7.2,12.1]],"id":41921674},{"atb":[[10,8.33]],"id":39722911},{"atb":[[10.5,7.89]],"id":43154431}],"con":true,"img":false}]}
{"op":"mcm","clk":"5346792001","pt":1646097140613,"mc":[{"id":"1.195395451","rc":[{"atl":[[140,0]],"id":39722911},{"atl":[[1.64,0]],"id":42492389}],"con":true,"img":false}]}
{"op":"mcm","clk":"5346792007","pt":1646097140716,"mc":[{"id":"1.195395451","rc":[{"atl":[[160,2.7]],"id":39722911},{"atl":[[1.62,43.26]],"id":42492389}],"con":true,"img":false}]}
{"op":"mcm","clk":"5346792014","pt":1646097140920,"mc":[{"id":"1.195395451","rc":[{"atb":[[9.2,9.15]],"id":40251221},{"atl":[[70,1.81]],"id":40251221}],"con":true,"img":false}]}
{"op":"mcm","clk":"5346792097","pt":1646097142723,"mc":[{"id":"1.195395451","rc":[{"spn":16.0,"spf":1.0,"id":36899924},{"atb":[[17,11.05]],"id":39979879},{"spn":26.25,"spf":1.0,"id":39979879},{"spn":1.21,"spf":1.0,"id":42492389}],"con":true,"img":false}]}
{"op":"mcm","clk":"5346792105","pt":1646097142928,"mc":[{"id":"1.195395451","rc":[{"atb":[[6,32.45]],"id":41921674},{"atb":[[8,33.47]],"id":40251221},{"atb":[[19,2]],"id":39979879},{"atl":[[1.38,3]],"id":42492389},{"atb":[[9.4,8.57]],"id":43154431}],"con":true,"img":false}]}
{"op":"mcm","clk":"5346792250","pt":1646097146832,"mc":[{"id":"1.195395451","rc":[{"atb":[[1.08,250]],"id":42492389},{"atl":[[1.6,83.33]],"id":42492389},{"atl":[[500,1]],"id":27151693}],"con":true,"img":false}]}
{"op":"mcm","clk":"5346792260","pt":1646097147143,"mc":[{"id":"1.195395451","rc":[{"atl":[[490,0],[510,0]],"id":27151693},{"atb":[[1.22,0]],"id":42492389}],"con":true,"img":false}]}
{"op":"mcm","clk":"5346792335","pt":1646097149349,"mc":[{"id":"1.195395451","rc":[{"atb":[[19.5,0]],"id":39722911},{"atl":[[19,4.85]],"id":39722911},{"trd":[[19.5,1.1]],"ltp":19.5,"tv":1.1,"id":39722911}],"con":true,"img":false}]}
{"op":"mcm","clk":"5346792339","pt":1646097149554,"mc":[{"id":"1.195395451","rc":[{"atb":[[8,17.38],[7.2,3.23],[7.6,0]],"id":41921674},{"atl":[[14,4]],"id":41921674},{"atl":[[46,0],[48,1]],"id":40251221},{"atl":[[460,0]],"id":27151693},{"atl":[[1.57,35.09]],"id":42492389},{"atb":[[7.8,14.71]],"id":43154431}],"con":true,"img":false}]}
{"op":"mcm","clk":"5346792342","pt":1646097149658,"mc":[{"id":"1.195395451","rc":[{"atl":[[28,3]],"id":41921674},{"atb":[[6.8,0]],"id":43154431}],"con":true,"img":false}]}
{"op":"mcm","clk":"5346792344","pt":1646097149761,"mc":[{"id":"1.195395451","rc":[{"atl":[[32,0]],"id":41921674}],"con":true,"img":false}]}
{"op":"mcm","clk":"5346792366","pt":1646097150433,"mc":[{"id":"1.195395451","rc":[{"atb":[[9.6,14.13]],"id":39722911},{"atb":[[9.8,14.2]],"id":43154431}],"con":true,"img":false}]}
{"op":"mcm","clk":"5346792374","pt":1646097150641,"mc":[{"id":"1.195395451","rc":[{"atl":[[70,0],[95,4.14]],"id":41921674},{"atl":[[150,0]],"id":36899924},{"atb":[[10.5,10.26]],"id":40251221},{"atl":[[95,0],[120,3.26]],"id":40251221},{"atb":[[9.8,0]],"id":39979879},{"atl":[[55,0]],"id":39979879},{"atb":[[12.5,9.94],[15,0]],"id":39722911},{"atl":[[160,0]],"id":39722911},{"atb":[[1.12,258.17]],"id":42492389},{"atl":[[2.12,96.3]],"id":42492389},{"atl":[[220,0]],"id":43154431}],"con":true,"img":false}]}
{"op":"mcm","clk":"5346792378","pt":1646097150744,"mc":[{"id":"1.195395451","rc":[{"atl":[[190,2.7]],"id":36899924},{"atb":[[9.4,14.06]],"id":39979879},{"atl":[[65,0.8]],"id":39979879},{"atl":[[210,2.7]],"id":39722911},{"atb":[[1.02,1.67]],"id":27151693},{"atl":[[270,2.7]],"id":43154431}],"con":true,"img":false}]}
{"op":"mcm","clk":"5346792384","pt":1646097150950,"mc":[{"id":"1.195395451","rc":[{"atb":[[1.02,0.37]],"id":27151693}],"con":true,"img":false}]}
{"op":"mcm","clk":"5346792390","pt":1646097151154,"mc":[{"id":"1.195395451","rc":[{"atb":[[1.02,0]],"id":27151693}],"con":true,"img":false}]}
{"op":"mcm","clk":"5346792392","pt":1646097151256,"mc":[{"id":"1.195395451","rc":[{"atb":[[22,0.37]],"id":27151693}],"con":true,"img":false}]}
{"op":"mcm","clk":"5346792452","pt":1646097152953,"mc":[{"id":"1.195395451","rc":[{"atb":[[17.5,0]],"id":39722911},{"atb":[[20,4.06]],"id":27151693}],"con":true,"img":false}]}
{"op":"mcm","clk":"5346792480","pt":1646097153621,"mc":[{"id":"1.195395451","rc":[{"atl":[[13.5,4]],"id":41921674}],"con":true,"img":false}]}
{"op":"mcm","clk":"5346792485","pt":1646097153726,"mc":[{"id":"1.195395451","rc":[{"atl":[[190,1],[48,0]],"id":40251221},{"atl":[[36,0],[150,1],[40,0]],"id":39979879},{"atb":[[1.16,0]],"id":42492389},{"atl":[[260,0],[270,3.7]],"id":43154431}],"con":true,"img":false}]}
{"op":"mcm","clk":"5346792489","pt":1646097153827,"mc":[{"id":"1.195395451","rc":[{"atb":[[1.15,272.43]],"id":42492389}],"con":true,"img":false}]}
{"op":"mcm","clk":"5346792510","pt":1646097154548,"mc":[{"id":"1.195395451","rc":[{"atl":[[1.71,10.54]],"id":42492389}],"con":true,"img":false}]}
{"op":"mcm","clk":"5346792515","pt":1646097154757,"mc":[{"id":"1.195395451","rc":[{"atb":[[4.9,0],[5.4,22.73]],"id":41921674},{"atl":[[13,2]],"id":41921674},{"atl":[[50,0]],"id":40251221},{"atl":[[44,0]],"id":39979879},{"atl":[[1.57,0]],"id":42492389}],"con":true,"img":false}]}
{"op":"mcm","clk":"5346792518","pt":1646097154856,"mc":[{"id":"1.195395451","rc":[{"atb":[[8,20.24]],"id":41921674},{"atl":[[13.5,0],[14,0]],"id":41921674},{"atb":[[10,26.85],[9.4,0]],"id":40251221},{"atl":[[200,1.99]],"id":40251221},{"atb":[[5.9,20.41],[5.4,0],[17.5,0],[18.5,0],[18,0],[19,0]],"id":39979879},{"atl":[[140,1]],"id":39979879},{"atl":[[520,1],[330,0],[390,2],[480,0]],"id":27151693}],"con":true,"img":false}]}
{"op":"mcm","clk":"5346792520","pt":1646097154960,"mc":[{"id":"1.195395451","rc":[{"atl":[[42,0],[48,4.79]],"id":39979879}],"con":true,"img":false}]}
{"op":"mcm","clk":"5346792522","pt":1646097155061,"mc":[{"id":"1.195395451","rc":[{"atl":[[65,2.8],[48,2.66]],"id":39979879}],"con":true,"img":false}]}
{"op":"mcm","clk":"5346792601","pt":1646097157064,"mc":[{"id":"1.195395451","rc":[{"atl":[[1000,1.67]],"id":40251221}],"con":true,"img":false}]}
{"op":"mcm","clk":"5346792604","pt":1646097157166,"mc":[{"id":"1.195395451","rc":[{"atl":[[40,0]],"id":40251221}],"con":true,"img":false}]}
{"op":"mcm","clk":"5346792609","pt":1646097157219,"mc":[{"id":"1.195395451","rc":[{"atl":[[1000,0.24]],"id":40251221},{"atl":[[34,0]],"id":39979879}],"con":true,"img":false}]}
{"op":"mcm","clk":"5346792612","pt":1646097157374,"mc":[{"id":"1.195395451","rc":[{"atl":[[65,0.8],[75,2],[1000,1.67]],"id":39979879}],"con":true,"img":false}]}
{"op":"mcm","clk":"5346792617","pt":1646097157424,"mc":[{"id":"1.195395451","rc":[{"atl":[[1000,0]],"id":40251221}],"con":true,"img":false}]}
{"op":"mcm","clk":"5346792620","pt":1646097157529,"mc":[{"id":"1.195395451","rc":[{"atl":[[55,0.24]],"id":40251221}],"con":true,"img":false}]}
{"op":"mcm","clk":"5346792626","pt":1646097157735,"mc":[{"id":"1.195395451","rc":[{"atl":[[1000,0.24]],"id":39979879}],"con":true,"img":false}]}
{"op":"mcm","clk":"5346792631","pt":1646097157841,"mc":[{"id":"1.195395451","rc":[{"atl":[[1000,0]],"id":39979879}],"con":true,"img":false}]}
{"op":"mcm","clk":"5346792636","pt":1646097157944,"mc":[{"id":"1.195395451","rc":[{"atl":[[46,0.24]],"id":39979879}],"con":true,"img":false}]}
{"op":"mcm","clk":"5346792639","pt":1646097158045,"mc":[{"id":"1.195395451","rc":[{"atl":[[65,2.8],[75,0]],"id":39979879}],"con":true,"img":false}]}
{"op":"mcm","clk":"5346792673","pt":1646097158866,"mc":[{"id":"1.195395451","rc":[{"atb":[[13.5,8.02]],"id":39979879}],"con":true,"img":false}]}
{"op":"mcm","clk":"5346792682","pt":1646097159022,"mc":[{"id":"1.195395451","rc":[{"atb":[[1.15,270.43]],"id":42492389}],"con":true,"img":false}]}
{"op":"mcm","clk":"5346792687","pt":1646097159123,"mc":[{"id":"1.195395451","rc":[{"atb":[[1.13,2]],"id":42492389}],"con":true,"img":false}]}
{"op":"mcm","clk":"5346792703","pt":1646097159535,"mc":[{"id":"1.195395451","rc":[{"atb":[[1.06,250]],"id":42492389},{"atl":[[1.62,164.23]],"id":42492389}],"con":true,"img":false}]}
{"op":"mcm","clk":"5346792758","pt":1646097160669,"mc":[{"id":"1.195395451","rc":[{"atl":[[100,0]],"id":36899924},{"atb":[[12.5,0],[18,0],[9.8,13.08]],"id":39722911},{"atl":[[1.62,120.97]],"id":42492389},{"atl":[[130,0]],"id":27151693}],"con":true,"img":false}]}
{"op":"mcm","clk":"5346792763","pt":1646097160771,"mc":[{"id":"1.195395451","rc":[{"atl":[[13,0],[28,2],[29,1]],"id":41921674},{"atl":[[200,0],[210,1],[110,0.48]],"id":36899924},{"atl":[[60,0.62]],"id":40251221},{"atl":[[48,0]],"id":39979879},{"atb":[[12.5,2.7]],"id":39722911},{"atl":[[230,0],[240,1]],"id":39722911},{"atl":[[140,0.39],[500,0]],"id":27151693},{"atb":[[1.12,91.5],[1.11,835.58]],"id":42492389},{"atl":[[1.67,43.26]],"id":42492389}],"con":true,"img":false}]}
{"op":"mcm","clk":"5346792767","pt":1646097160822,"mc":[{"id":"1.195395451","rc":[{"atl":[[210,1]],"id":40251221}],"con":true,"img":false}]}
{"op":"mcm","clk":"5346792771","pt":1646097160924,"mc":[{"id":"1.195395451","rc":[{"atl":[[28,0],[29,3.31]],"id":41921674}],"con":true,"img":false}]}
{"op":"mcm","clk":"5346792790","pt":1646097161391,"mc":[{"id":"1.195395451","rc":[{"atl":[[70,0]],"id":40251221},{"atl":[[140,0]],"id":39979879},{"atl":[[1.57,35.09]],"id":42492389}],"con":true,"img":false}]}
{"op":"mcm","clk":"5346792803","pt":1646097161647,"mc":[{"id":"1.195395451","rc":[{"atl":[[1.71,0]],"id":42492389}],"con":true,"img":false}]}
{"op":"mcm","clk":"5346792809","pt":1646097161752,"mc":[{"id":"1.195395451","rc":[{"atl":[[190,0]],"id":40251221}],"con":true,"img":false}]}
{"op":"mcm","clk":"5346792816","pt":1646097161958,"mc":[{"id":"1.195395451","rc":[{"atb":[[12.5,3.58]],"id":39722911}],"con":true,"img":false}]}
{"op":"mcm","clk":"5346792839","pt":1646097162473,"mc":[{"id":"1.195395451","rc":[{"atl":[[200,0.99]],"id":40251221},{"atl":[[520,0],[530,1]],"id":27151693}],"con":true,"img":false}]}
{"op":"mcm","clk":"5346792843","pt":1646097162575,"mc":[{"id":"1.195395451","rc":[{"atl":[[1.57,0]],"id":42492389}],"con":true,"img":false}]}
{"op":"mcm","clk":"5346792891","pt":1646097163753,"mc":[{"id":"1.195395451","rc":[{"atl":[[290,1]],"id":43154431}],"con":true,"img":false}]}
{"op":"mcm","clk":"5346792935","pt":1646097164882,"mc":[{"id":"1.195395451","rc":[{"atl":[[170,1]],"id":39979879}],"con":true,"img":false}]}
{"op":"mcm","clk":"5346792958","pt":1646097165241,"mc":[{"id":"1.195395451","rc":[{"atb":[[11.5,0.72]],"id":41921674},{"atb":[[10,0],[11,6.32]],"id":39979879},{"atl":[[150,0],[160,2.24]],"id":39979879},{"atl":[[1.57,35.09]],"id":42492389},{"atl":[[520,1]],"id":27151693},{"atl":[[280,0.7],[300,0],[320,0]],"id":43154431}],"con":true,"img":false}]}
{"op":"mcm","clk":"5346792961","pt":1646097165345,"mc":[{"id":"1.195395451","rc":[{"atb":[[10,5.62]],"id":41921674},{"atl":[[29,1],[30,5.17]],"id":41921674}],"con":true,"img":false}]}
{"op":"mcm","clk":"5346793002","pt":1646097166376,"mc":[{"id":"1.195395451","rc":[{"atl":[[42,0]],"id":41921674}],"con":true,"img":false}]}
{"op":"mcm","clk":"5346793009","pt":1646097166505,"mc":[{"id":"1.195395451","rc":[{"atl":[[36,2.7]],"id":41921674}],"con":true,"img":false}]}
{"op":"mcm","clk":"5346793018","pt":1646097166659,"mc":[{"id":"1.195395451","rc":[{"atl":[[200,1.99]],"id":40251221},{"atl":[[490,1]],"id":27151693}],"con":true,"img":false}]}
{"op":"mcm","clk":"5346793163","pt":1646097170563,"mc":[{"id":"1.195395451","rc":[{"atb":[[10.5,14.06]],"id":40251221},{"atb":[[1.12,1088.21]],"id":42492389}],"con":true,"img":false}]}
{"op":"mcm","clk":"5346793167","pt":1646097170666,"mc":[{"id":"1.195395451","rc":[{"atl":[[60,0]],"id":40251221},{"atl":[[65,2]],"id":39979879}],"con":true,"img":false}]}
{"op":"mcm","clk":"5346793170","pt":1646097170771,"mc":[{"id":"1.195395451","rc":[{"atb":[[7.6,7.58]],"id":41921674},{"atl":[[32,1.61]],"id":41921674},{"atl":[[70,0.62]],"id":40251221},{"atl":[[60,0.8]],"id":39979879},{"atl":[[260,1]],"id":39722911}],"con":true,"img":false}]}
{"op":"mcm","clk":"5346793217","pt":1646097172163,"mc":[{"id":"1.195395451","rc":[{"atb":[[8,2.86],[9,0],[10,1.12],[6,0]],"id":41921674},{"atl":[[75,8.2],[150,0],[50,0],[100,0]],"id":41921674},{"atb":[[12,0],[8.8,0],[14.5,0]],"id":36899924},{"atl":[[270,1],[170,0],[220,0],[120,0]],"id":36899924},{"atb":[[8,10.29],[10,13.33],[12.5,0],[15,0]],"id":40251221},{"atl":[[150,0],[100,0],[200,1],[250,0]],"id":40251221},{"atb":[[9.2,9.15],[10.5,0],[13,0],[7.2,0]],"id":39979879},{"atl":[[80,0],[160,1],[210,0],[110,0]],"id":39979879},{"atb":[[12,1.82],[14.5,0],[17,0],[8.8,0]],"id":39722911},{"atl":[[270,1],[170,2],[220,0],[120,0]],"id":39722911},{"atb":[[1.01,0],[1.15,0],[1.1,250],[1.05,0]],"id":42492389},{"atl":[[2.44,0],[2.14,0],[2.34,0],[2.24,0]],"id":42492389},{"atb":[[9.2,0],[13,0],[15.5,0],[18,0]],"id":43154431},{"atl":[[130,0],[280,0],[180,0],[230,0]],"id":43154431}],"con":true,"img":false}]}
{"op":"mcm","clk":"5346793220","pt":1646097172269,"mc":[{"id":"1.195395451","rc":[{"atb":[[10,12.23]],"id":36899924},{"atb":[[10.5,0],[9.8,24.44]],"id":39722911}],"con":true,"img":false}]}
{"op":"mcm","clk":"5346793223","pt":1646097172367,"mc":[{"id":"1.195395451","rc":[{"atl":[[34,0],[38,0],[30,3.45]],"id":41921674},{"atl":[[270,0],[290,0],[250,0]],"id":39722911},{"atl":[[260,0.08],[100,0]],"id":43154431}],"con":true,"img":false}]}
{"op":"mcm","clk":"5346793230","pt":1646097172472,"mc":[{"id":"1.195395451","rc":[{"atl":[[260,2.08],[120,0]],"id":43154431}],"con":true,"img":false}]}
{"op":"mcm","clk":"5346793278","pt":1646097173759,"mc":[{"id":"1.195395451","rc":[{"atl":[[310,1]],"id":43154431}],"con":true,"img":false}]}
{"op":"mcm","clk":"5346793317","pt":1646097174791,"mc":[{"id":"1.195395451","rc":[{"atb":[[8.6,12.17]],"id":41921674},{"atb":[[13,0.08]],"id":40251221},{"atb":[[13.5,0.61]],"id":39979879},{"atb":[[11.5,8.06]],"id":39722911},{"atb":[[18.5,0]],"id":43154431}],"con":true,"img":false}]}
{"op":"mcm","clk":"5346793341","pt":1646097175304,"mc":[{"id":"1.195395451","rc":[{"atb":[[10,5.56]],"id":39979879},{"atl":[[180,1]],"id":39979879},{"atl":[[220,1]],"id":39722911},{"atb":[[1.09,250]],"id":42492389},{"atl":[[1.59,84.75]],"id":42492389}],"con":true,"img":false}]}
{"op":"mcm","clk":"5346793350","pt":1646097175461,"mc":[{"id":"1.195395451","rc":[{"atb":[[8.8,0]],"id":39979879},{"atb":[[1.06,0],[1.1,0],[1.08,0]],"id":42492389},{"atl":[[1.6,0],[1.58,0],[1.62,0]],"id":42492389},{"atb":[[14.5,1.48],[15,0]],"id":27151693}],"con":true,"img":false}]}
{"op":"mcm","clk":"5346793403","pt":1646097176692,"mc":[{"id":"1.195395451","rc":[{"atb":[[8.8,16.03]],"id":40251221},{"atl":[[220,1]],"id":40251221}],"con":true,"img":false}]}
{"op":"mcm","clk":"5346793416","pt":1646097177005,"mc":[{"id":"1.195395451","rc":[{"atb":[[8,0],[7.6,0]],"id":41921674},{"atl":[[14,4],[28,1]],"id":41921674},{"atb":[[12.5,10.81],[13,1.62]],"id":36899924},{"atl":[[210,0],[220,1]],"id":36899924},{"atb":[[8.4,0]],"id":40251221},{"atl":[[50,1]],"id":40251221},{"atb":[[1.12,1254.88]],"id":42492389},{"atl":[[260,3.08]],"id":43154431}],"con":true,"img":false}]}
{"op":"mcm","clk":"5346793426","pt":1646097177209,"mc":[{"id":"1.195395451","rc":[{"atl":[[29,3],[30,0]],"id":41921674}],"con":true,"img":false}]}
{"op":"mcm","clk":"5346793438","pt":1646097177367,"mc":[{"id":"1.195395451","rc":[{"atb":[[8,2.86]],"id":41921674},{"atl":[[13.5,3],[14,0]],"id":41921674},{"atl":[[50,0],[55,1.24]],"id":40251221},{"atl":[[490,0]],"id":27151693}],"con":true,"img":false}]}
{"op":"mcm","clk":"5346793515","pt":1646097178858,"mc":[{"id":"1.195395451","rc":[{"atb":[[12,8.33]],"id":40251221},{"atb":[[11.5,8.81]],"id":39979879},{"atb":[[16.5,5.96]],"id":43154431}],"con":true,"img":false}]}
{"op":"mcm","clk":"5346793579","pt":1646097179994,"mc":[{"id":"1.195395451","rc":[{"atl":[[13.5,0]],"id":41921674},{"atl":[[50,1],[55,0.24]],"id":40251221},{"atl":[[1.58,34.48],[1.57,0]],"id":42492389}],"con":true,"img":false}]}
{"op":"mcm","clk":"5346793582","pt":1646097180097,"mc":[{"id":"1.195395451","rc":[{"atb":[[17,5.64]],"id":39979879},{"trd":[[17,10.81]],"ltp":17.0,"tv":10.81,"id":39979879}],"con":true,"img":false}]}
{"op":"mcm","clk":"5346793611","pt":1646097180564,"mc":[{"id":"1.195395451","rc":[{"atl":[[65,0.67],[110,0]],"id":39722911},{"atl":[[2.82,71.93],[2.12,0]],"id":42492389}],"con":true,"img":false}]}
{"op":"mcm","clk":"5346793618","pt":1646097180667,"mc":[{"id":"1.195395451","rc":[{"atb":[[8.6,0],[10.5,0.1]],"id":41921674},{"atl":[[36,0]],"id":41921674},{"atb":[[12.5,0],[15,0]],"id":36899924},{"atl":[[240,0]],"id":27151693},{"atl":[[110,0]],"id":43154431}],"con":true,"img":false}]}
{"op":"mcm","clk":"5346793622","pt":1646097180769,"mc":[{"id":"1.195395451","rc":[{"atb":[[9.6,4.55]],"id":41921674},{"atl":[[46,2.7]],"id":41921674},{"atb":[[12,10.81],[14,3.08]],"id":36899924},{"atl":[[190,2.7]],"id":27151693},{"atl":[[270,5.7],[140,0.39]],"id":43154431}],"con":true,"img":false}]}
{"op":"mcm","clk":"5346793625","pt":1646097180871,"mc":[{"id":"1.195395451","rc":[{"atl":[[260,1.08]],"id":43154431}],"con":true,"img":false}]}
{"op":"mcm","clk":"5346793727","pt":1646097182875,"mc":[{"id":"1.195395451","rc":[{"atb":[[11.5,0]],"id":39979879}],"con":true,"img":false}]}
{"op":"mcm","clk":"5346793749","pt":1646097183498,"mc":[{"id":"1.195395451","rc":[{"atb":[[12,3.71],[6.8,28.15],[9.8,9.27],[8.8,15.7]],"id":41921674},{"atl":[[70,1.9],[140,1.42],[95,5.54],[190,1.04]],"id":41921674},{"atb":[[12,20.77],[14.5,5.4],[17,0.03],[8.8,18.71]],"id":36899924},{"atl":[[270,1.78],[17,0],[170,0.82],[220,1.96],[120,1.17]],"id":36899924},{"trd":[[17,9.57]],"ltp":17.0,"tv":9.57,"id":36899924},{"atb":[[9.2,24.08],[10.5,22.65],[13,3.48],[7.2,26.33]],"id":40251221},{"atl":[[80,1.66],[160,1.24],[210,1.94],[110,1.2]],"id":40251221},{"atb":[[11.5,7.77],[14,3.14],[9.6,20.05],[7.6,24.73]],"id":39979879},{"atl":[[130,1.02],[180,2.1],[90,1.48],[230,0.85]],"id":39979879},{"atb":[[9.6,33.11],[16.5,5.26],[14,9.42]],"id":39722911},{"atl":[[140,0.94],[290,0.68],[19,2.59],[190,0.69],[240,1.82]],"id":39722911},{"trd":[[19,4.53]],"ltp":19.0,"tv":4.53,"id":39722911},{"atb":[[1.12,1595.03],[1.01,16327.32],[1.02,6122.74],[1.07,1166.23]],"id":42492389},{"atl":[[2.08,121.92],[2.38,143.12],[2.28,154.31],[2.18,111.59]],"id":42492389},{"atb":[[11.5,20.3],[16.5,13.86],[19,7.24],[23,1.85]],"id":43154431},{"atl":[[260,1.84],[310,1.63],[160,0.82],[210,0.62]],"id":43154431}],"con":true,"img":false}]}
{"op":"mcm","clk":"5346793756","pt":1646097183701,"mc":[{"id":"1.195395451","rc":[{"atb":[[10,1.12],[11.5,12.65]],"id":36899924},{"atl":[[140,0.09],[120,3.17]],"id":36899924},{"atl":[[48,1],[50,0]],"id":40251221},{"atb":[[12.5,0],[17.5,2]],"id":39979879},{"atl":[[1.57,35.09]],"id":42492389},{"atl":[[460,1]],"id":27151693}],"con":true,"img":false}]}
{"op":"mcm","clk":"5346793763","pt":1646097183802,"mc":[{"id":"1.195395451","rc":[{"atl":[[130,2],[120,1.17]],"id":36899924}],"con":true,"img":false}]}
{"op":"mcm","clk":"5346793776","pt":1646097184114,"mc":[{"id":"1.195395451","rc":[{"atb":[[1.01,2.53]],"id":36899924},{"atb":[[1.03,1.67],[15.5,0]],"id":40251221},{"atb":[[1.01,2.53]],"id":39722911}],"con":true,"img":false}]}
{"op":"mcm","clk":"5346793784","pt":1646097184322,"mc":[{"id":"1.195395451","rc":[{"atb":[[1.01,1.69]],"id":36899924},{"atb":[[1.03,0.54]],"id":40251221},{"atl":[[46,0],[1000,1.67]],"id":39979879},{"atb":[[1.01,1.69]],"id":39722911}],"con":true,"img":false}]}
{"op":"mcm","clk":"5346793792","pt":1646097184474,"mc":[{"id":"1.195395451","rc":[{"atb":[[1.01,0]],"id":36899924},{"atb":[[1.03,0]],"id":40251221},{"atl":[[65,0],[85,2]],"id":39979879},{"atb":[[1.01,0]],"id":39722911}],"con":true,"img":false}]}
{"op":"mcm","clk":"5346793797","pt":1646097184576,"mc":[{"id":"1.195395451","rc":[{"atb":[[15,1.69]],"id":36899924},{"atb":[[14,0.54]],"id":40251221},{"atb":[[17,1.69]],"id":39722911}],"con":true,"img":false}]}
{"op":"mcm","clk":"5346793801","pt":1646097184677,"mc":[{"id":"1.195395451","rc":[{"atb":[[1.01,1.67]],"id":41921674}],"con":true,"img":false}]}
{"op":"mcm","clk":"5346793807","pt":1646097184780,"mc":[{"id":"1.195395451","rc":[{"atb":[[11.5,0]],"id":41921674},{"atl":[[1000,0.24]],"id":39979879}],"con":true,"img":false}]}
{"op":"mcm","clk":"5346793813","pt":1646097184891,"mc":[{"id":"1.195395451","rc":[{"atb":[[1.01,0.66],[8.4,12.5]],"id":41921674},{"atb":[[16.5,7.9]],"id":43154431}],"con":true,"img":false}]}
{"op":"mcm","clk":"5346793820","pt":1646097184985,"mc":[{"id":"1.195395451","rc":[{"atl":[[1000,0]],"id":39979879}],"con":true,"img":false}]}
{"op":"mcm","clk":"5346793825","pt":1646097185089,"mc":[{"id":"1.195395451","rc":[{"atl":[[55,0.24]],"id":39979879}],"con":true,"img":false}]}
{"op":"mcm","clk":"5346793836","pt":1646097185295,"mc":[{"id":"1.195395451","rc":[{"atb":[[1.01,0]],"id":41921674},{"atb":[[9.6,22.96]],"id":39979879},{"atl":[[200,1]],"id":39979879},{"atl":[[280,1]],"id":39722911}],"con":true,"img":false}]}
{"op":"mcm","clk":"5346793840","pt":1646097185398,"mc":[{"id":"1.195395451","rc":[{"atb":[[12.5,0.66]],"id":41921674}],"con":true,"img":false}]}
{"op":"mcm","clk":"5346793899","pt":1646097186987,"mc":[{"id":"1.195395451","rc":[{"atl":[[240,1]],"id":36899924},{"atb":[[12,0]],"id":40251221},{"atb":[[11.5,0]],"id":39722911},{"atl":[[280,1]],"id":43154431}],"con":true,"img":false}]}
{"op":"mcm","clk":"5346793914","pt":1646097187401,"mc":[{"id":"1.195395451","rc":[{"atb":[[7.6,7.58]],"id":41921674},{"atl":[[30,1.72]],"id":41921674}],"con":true,"img":false}]}
{"op":"mcm","clk":"5346793939","pt":1646097188116,"mc":[{"id":"1.195395451","rc":[{"atl":[[270,0.78],[230,0],[250,0]],"id":36899924},{"atl":[[46,1],[48,0]],"id":40251221},{"atb":[[18,2]],"id":39979879},{"atl":[[460,0],[470,1]],"id":27151693},{"atl":[[270,4.7],[290,0],[310,0.63]],"id":43154431}],"con":true,"img":false}]}
{"op":"mcm","clk":"5346793966","pt":1646097188580,"mc":[{"id":"1.195395451","rc":[{"atb":[[1.14,0]],"id":42492389}],"con":true,"img":false}]}
{"op":"mcm","clk":"5346793970","pt":1646097188686,"mc":[{"id":"1.195395451","rc":[{"atb":[[1.13,45.26]],"id":42492389}],"con":true,"img":false}]}
{"op":"mcm","clk":"5346793979","pt":1646097188890,"mc":[{"id":"1.195395451","rc":[{"atb":[[17.5,0],[18,0],[18.5,2]],"id":39979879},{"atl":[[460,1]],"id":27151693}],"con":true,"img":false}]}
{"op":"mcm","clk":"5346793985","pt":1646097188993,"mc":[{"id":"1.195395451","rc":[{"atb":[[8.4,0]],"id":41921674}],"con":true,"img":false}]}
