{"op":"mcm","clk":"5317728518","pt":1646251399899,"mc":[{"id":"1.195532870","marketDefinition":{"bspMarket":true,"turnInPlayEnabled":false,"persistenceEnabled":false,"marketBaseRate":5.0,"eventId":"31275720","eventTypeId":"4339","numberOfWinners":1,"bettingType":"ODDS","marketType":"WIN","marketTime":"2022-03-03T16:48:00.000Z","suspendTime":"2022-03-03T16:48:00.000Z","bspReconciled":false,"complete":true,"inPlay":false,"crossMatching":false,"runnersVoidable":false,"numberOfActiveRunners":6,"betDelay":0,"status":"OPEN","runners":[{"status":"ACTIVE","sortPriority":1,"id":40214166,"name":"1. Mayses Scotty"},{"status":"ACTIVE","sortPriority":2,"id":43189003,"name":"2. Passage West Fox"},{"status":"ACTIVE","sortPriority":3,"id":40214168,"name":"3. Gonewiththedays"},{"status":"ACTIVE","sortPriority":4,"id":42931076,"name":"4. Comeragh Jet"},{"status":"ACTIVE","sortPriority":5,"id":41793694,"name":"5. Ogs Lady"},{"status":"ACTIVE","sortPriority":6,"id":5677052,"name":"6. Wichita Lineman"}],"regulators":["MR_INT"],"venue":"Romford","countryCode":"GB","discountAllowed":false,"timezone":"Europe/London","openDate":"2022-03-03T13:57:00.000Z","version":4384107322,"name":"A9 400m","eventName":"Romford 3rd Mar"},"rc":[],"con":true,"img":false}]}
{"op":"mcm","clk":"5317728867","pt":1646251401773,"mc":[{"id":"1.195532870","marketDefinition":{"bspMarket":true,"turnInPlayEnabled":false,"persistenceEnabled":false,"marketBaseRate":5.0,"eventId":"31275720","eventTypeId":"4339","numberOfWinners":1,"bettingType":"ODDS","marketType":"WIN","marketTime":"2022-03-03T16:48:00.000Z","suspendTime":"2022-03-03T16:48:00.000Z","bspReconciled":false,"complete":true,"inPlay":false,"crossMatching":false,"runnersVoidable":false,"numberOfActiveRunners":6,"betDelay":0,"status":"OPEN","runners":[{"status":"ACTIVE","sortPriority":1,"id":40214166,"name":"1. Mayses Scotty"},{"status":"ACTIVE","sortPriority":2,"id":43189003,"name":"2. Passage West Fox"},{"status":"ACTIVE","sortPriority":3,"id":40214168,"name":"3. Gonewiththedays"},{"status":"ACTIVE","sortPriority":4,"id":42931076,"name":"4. Comeragh Jet"},{"status":"ACTIVE","sortPriority":5,"id":41793694,"name":"5. Ogs Lady"},{"status":"ACTIVE","sortPriority":6,"id":5677052,"name":"6. Wichita Lineman"}],"regulators":["MR_INT"],"venue":"Romford","countryCode":"GB","discountAllowed":true,"timezone":"Europe/London","openDate":"2022-03-03T13:57:00.000Z","version":4384107322,"name":"A9 400m","eventName":"Romford 3rd Mar"},"rc":[],"con":true,"img":false}]}
{"op":"mcm","clk":"5318486346","pt":1646259100952,"mc":[{"id":"1.195532870","rc":[{"atb":[[1.12,30]],"id":40214166},{"atl":[[370,3]],"id":40214166},{"spn":185.56,"spf":"NaN","id":40214166},{"atb":[[1.12,30]],"id":40214168},{"atl":[[550,3]],"id":40214168},{"spn":275.56,"spf":"NaN","id":40214168},{"atl":[[500,3]],"id":5677052},{"spn":1.0,"spf":"NaN","id":5677052},{"atb":[[1.12,30]],"id":41793694},{"atl":[[560,3]],"id":41793694},{"spn":280.56,"spf":"NaN","id":41793694},{"atb":[[1.12,30]],"id":43189003},{"atl":[[390,3]],"id":43189003},{"spn":195.56,"spf":"NaN","id":43189003},{"atb":[[1.12,30]],"id":42931076},{"atl":[[270,3]],"id":42931076},{"spn":135.56,"spf":"NaN","id":42931076}],"con":true,"img":false}]}
{"op":"mcm","clk":"5318486356","pt":1646259101058,"mc":[{"id":"1.195532870","rc":[{"atb":[[1.14,30]],"id":5677052}],"con":true,"img":false}]}
{"op":"mcm","clk":"5318509080","pt":1646259402465,"mc":[{"id":"1.195532870","marketDefinition":{"bspMarket":true,"turnInPlayEnabled":false,"persistenceEnabled":false,"marketBaseRate":5.0,"eventId":"31275720","eventTypeId":"4339","numberOfWinners":1,"bettingType":"ODDS","marketType":"WIN","marketTime":"2022-03-03T16:48:00.000Z","suspendTime":"2022-03-03T16:48:00.000Z","bspReconciled":false,"complete":true,"inPlay":false,"crossMatching":false,"runnersVoidable":false,"numberOfActiveRunners":6,"betDelay":0,"status":"OPEN","runners":[{"status":"ACTIVE","sortPriority":1,"id":40214166,"name":"1. Mayses Scotty"},{"status":"ACTIVE","sortPriority":2,"id":43189003,"name":"2. Passage West Fox"},{"status":"ACTIVE","sortPriority":3,"id":40214168,"name":"3. Gonewiththedays"},{"status":"ACTIVE","sortPriority":4,"id":42931076,"name":"4. Comeragh Jet"},{"status":"ACTIVE","sortPriority":5,"id":41793694,"name":"5. Ogs Lady"},{"status":"ACTIVE","sortPriority":6,"id":5677052,"name":"6. Wichita Lineman"}],"regulators":["MR_INT"],"venue":"Romford","countryCode":"GB","discountAllowed":true,"timezone":"Europe/London","openDate":"2022-03-03T13:57:00.000Z","version":4384107322,"name":"A9 400m","eventName":"Romford 3rd Mar"},"rc":[{"atb":[[1.12,30]],"id":40214166},{"atl":[[370,3]],"id":40214166},{"spn":185.56,"spf":"NaN","id":40214166},{"atb":[[1.12,30]],"id":40214168},{"atl":[[550,3]],"id":40214168},{"spn":275.56,"spf":"NaN","id":40214168},{"atb":[[1.14,30]],"id":5677052},{"atl":[[500,3]],"id":5677052},{"spn":250.57,"spf":"NaN","id":5677052},{"atb":[[1.12,30]],"id":41793694},{"atl":[[560,3]],"id":41793694},{"spn":280.56,"spf":"NaN","id":41793694},{"atb":[[1.12,30]],"id":43189003},{"atl":[[390,3]],"id":43189003},{"spn":195.56,"spf":"NaN","id":43189003},{"atb":[[1.12,30]],"id":42931076},{"atl":[[270,3]],"id":42931076},{"spn":135.56,"spf":"NaN","id":42931076}],"con":true,"img":true}]}
{"op":"mcm","clk":"5320234538","pt":1646290699613,"mc":[{"id":"1.195532870","rc":[{"spb":[[1000,50]],"id":5677052},{"spn":500.0,"spf":"Infinity","id":5677052}],"con":true,"img":false}]}
{"op":"mcm","clk":"5320255934","pt":1646291303013,"mc":[{"id":"1.195532870","rc":[{"atb":[[2.04,8.52]],"id":40214166},{"spn":186.02,"spf":"NaN","id":40214166},{"atb":[[2,12.54]],"id":40214168},{"spn":276.0,"spf":"NaN","id":40214168},{"atb":[[2.02,12.66]],"id":5677052},{"atb":[[2,12.54]],"id":41793694},{"spn":281.0,"spf":"NaN","id":41793694},{"atb":[[2.02,9.29]],"id":43189003},{"spn":196.01,"spf":"NaN","id":43189003},{"atb":[[2.08,11.3]],"id":42931076},{"spn":136.04,"spf":"NaN","id":42931076}],"con":true,"img":false}]}
{"op":"mcm","clk":"5320538830","pt":1646297202606,"mc":[{"id":"1.195532870","marketDefinition":{"bspMarket":true,"turnInPlayEnabled":false,"persistenceEnabled":false,"marketBaseRate":5.0,"eventId":"31275720","eventTypeId":"4339","numberOfWinners":1,"bettingType":"ODDS","marketType":"WIN","marketTime":"2022-03-03T16:48:00.000Z","suspendTime":"2022-03-03T16:48:00.000Z","bspReconciled":false,"complete":true,"inPlay":false,"crossMatching":false,"runnersVoidable":false,"numberOfActiveRunners":6,"betDelay":0,"status":"OPEN","runners":[{"status":"ACTIVE","sortPriority":1,"id":40214166,"name":"1. Mayses Scotty"},{"status":"ACTIVE","sortPriority":2,"id":43189003,"name":"2. Passage West Fox"},{"status":"ACTIVE","sortPriority":3,"id":40214168,"name":"3. Gonewiththedays"},{"status":"ACTIVE","sortPriority":4,"id":42931076,"name":"4. Comeragh Jet"},{"status":"ACTIVE","sortPriority":5,"id":41793694,"name":"5. Ogs Lady"},{"status":"ACTIVE","sortPriority":6,"id":5677052,"name":"6. Wichita Lineman"}],"regulators":["MR_INT"],"venue":"Romford","countryCode":"GB","discountAllowed":true,"timezone":"Europe/London","openDate":"2022-03-03T13:57:00.000Z","version":4384107322,"name":"A9 400m","eventName":"Romford 3rd Mar"},"rc":[{"atb":[[1.12,30],[2.04,8.53]],"id":40214166},{"atl":[[370,3]],"id":40214166},{"spn":186.02,"spf":"NaN","id":40214166},{"atb":[[2,12.55],[1.12,30]],"id":40214168},{"atl":[[550,3]],"id":40214168},{"spn":276.0,"spf":"NaN","id":40214168},{"atb":[[2.02,12.67],[1.14,30]],"id":5677052},{"atl":[[500,3]],"id":5677052},{"spb":[[1000,50]],"id":5677052},{"spn":500.0,"spf":"Infinity","id":5677052},{"atb":[[2,12.55],[1.12,30]],"id":41793694},{"atl":[[560,3]],"id":41793694},{"spn":281.0,"spf":"NaN","id":41793694},{"atb":[[1.12,30],[2.02,9.29]],"id":43189003},{"atl":[[390,3]],"id":43189003},{"spn":196.01,"spf":"NaN","id":43189003},{"atb":[[1.12,30],[2.08,11.3]],"id":42931076},{"atl":[[270,3]],"id":42931076},{"spn":136.04,"spf":"NaN","id":42931076}],"con":true,"img":true}]}
{"op":"mcm","clk":"5320690474","pt":1646299991272,"mc":[{"id":"1.195532870","rc":[{"atb":[[2.04,8.53]],"id":40214166},{"spl":[[21,1]],"id":40214166},{"spn":11.52,"spf":1.0,"id":40214166},{"atb":[[2,12.55]],"id":40214168},{"spl":[[21,1]],"id":40214168},{"spn":11.5,"spf":1.0,"id":40214168},{"atb":[[2.02,12.67]],"id":5677052},{"spl":[[21,1]],"id":5677052},{"spn":51.0,"spf":51.0,"id":5677052},{"atb":[[2,12.55]],"id":41793694},{"spl":[[21,1]],"id":41793694},{"spn":11.5,"spf":1.0,"id":41793694},{"atb":[[2.02,9.29]],"id":43189003},{"spl":[[21,1]],"id":43189003},{"spn":11.51,"spf":1.0,"id":43189003},{"atb":[[2.08,11.3]],"id":42931076},{"spl":[[21,1]],"id":42931076},{"spn":11.54,"spf":1.0,"id":42931076}],"con":true,"img":false}]}
{"op":"mcm","clk":"5320700636","pt":1646300172296,"mc":[{"id":"1.195532870","rc":[{"spl":[[18,10]],"id":40214166},{"spn":10.02,"spf":1.0,"id":40214166},{"spl":[[10,10]],"id":40214168},{"spn":6.0,"spf":1.0,"id":40214168},{"spl":[[34,10]],"id":5677052},{"spn":34.0,"spf":34.0,"id":5677052},{"spl":[[6.6,10]],"id":41793694},{"spn":4.3,"spf":1.0,"id":41793694},{"spl":[[6.8,10]],"id":43189003},{"spn":4.41,"spf":1.0,"id":43189003},{"spl":[[10,10]],"id":42931076},{"spn":6.04,"spf":1.0,"id":42931076}],"con":true,"img":false}]}
{"op":"mcm","clk":"5320830303","pt":1646302602598,"mc":[{"id":"1.195532870","marketDefinition":{"bspMarket":true,"turnInPlayEnabled":false,"persistenceEnabled":false,"marketBaseRate":5.0,"eventId":"31275720","eventTypeId":"4339","numberOfWinners":1,"bettingType":"ODDS","marketType":"WIN","marketTime":"2022-03-03T16:48:00.000Z","suspendTime":"2022-03-03T16:48:00.000Z","bspReconciled":false,"complete":true,"inPlay":false,"crossMatching":false,"runnersVoidable":false,"numberOfActiveRunners":6,"betDelay":0,"status":"OPEN","runners":[{"status":"ACTIVE","sortPriority":1,"id":40214166,"name":"1. Mayses Scotty"},{"status":"ACTIVE","sortPriority":2,"id":43189003,"name":"2. Passage West Fox"},{"status":"ACTIVE","sortPriority":3,"id":40214168,"name":"3. Gonewiththedays"},{"status":"ACTIVE","sortPriority":4,"id":42931076,"name":"4. Comeragh Jet"},{"status":"ACTIVE","sortPriority":5,"id":41793694,"name":"5. Ogs Lady"},{"status":"ACTIVE","sortPriority":6,"id":5677052,"name":"6. Wichita Lineman"}],"regulators":["MR_INT"],"venue":"Romford","countryCode":"GB","discountAllowed":true,"timezone":"Europe/London","openDate":"2022-03-03T13:57:00.000Z","version":4384107322,"name":"A9 400m","eventName":"Romford 3rd Mar"},"rc":[{"atb":[[1.12,30],[2.04,8.53]],"id":40214166},{"spl":[[18,10],[21,1]],"id":40214166},{"atl":[[370,3]],"id":40214166},{"spn":10.02,"spf":1.0,"id":40214166},{"atb":[[2,12.54],[1.12,30]],"id":40214168},{"spl":[[10,10],[21,1]],"id":40214168},{"atl":[[550,3]],"id":40214168},{"spn":6.0,"spf":1.0,"id":40214168},{"atb":[[2.02,12.67],[1.14,30]],"id":5677052},{"spl":[[34,10],[21,1]],"id":5677052},{"atl":[[500,3]],"id":5677052},{"spb":[[1000,50]],"id":5677052},{"spn":34.0,"spf":34.0,"id":5677052},{"atb":[[2,12.54],[1.12,30]],"id":41793694},{"spl":[[21,1],[6.6,10]],"id":41793694},{"atl":[[560,3]],"id":41793694},{"spn":4.3,"spf":1.0,"id":41793694},{"atb":[[1.12,30],[2.02,9.29]],"id":43189003},{"spl":[[21,1],[6.8,10]],"id":43189003},{"atl":[[390,3]],"id":43189003},{"spn":4.41,"spf":1.0,"id":43189003},{"atb":[[1.12,30],[2.08,11.3]],"id":42931076},{"spl":[[10,10],[21,1]],"id":42931076},{"atl":[[270,3]],"id":42931076},{"spn":6.04,"spf":1.0,"id":42931076}],"con":true,"img":true}]}
{"op":"mcm","clk":"5321039345","pt":1646305449095,"mc":[{"id":"1.195532870","marketDefinition":{"bspMarket":true,"turnInPlayEnabled":false,"persistenceEnabled":false,"marketBaseRate":5.0,"eventId":"31275720","eventTypeId":"4339","numberOfWinners":1,"bettingType":"ODDS","marketType":"WIN","marketTime":"2022-03-03T16:48:00.000Z","suspendTime":"2022-03-03T16:48:00.000Z","bspReconciled":false,"complete":true,"inPlay":false,"crossMatching":false,"runnersVoidable":false,"numberOfActiveRunners":6,"betDelay":0,"status":"OPEN","runners":[{"status":"ACTIVE","sortPriority":1,"id":40214166,"name":"1. Mayses Scotty"},{"status":"ACTIVE","sortPriority":2,"id":43189003,"name":"2. Passage West Fox"},{"status":"ACTIVE","sortPriority":3,"id":40214168,"name":"3. Gonewiththedays"},{"status":"ACTIVE","sortPriority":4,"id":42931076,"name":"4. Comeragh Jet"},{"status":"ACTIVE","sortPriority":5,"id":41793694,"name":"5. Ogs Lady"},{"status":"ACTIVE","sortPriority":6,"id":5677052,"name":"6. Wichita Lineman"}],"regulators":["MR_INT"],"venue":"Romford","countryCode":"GB","discountAllowed":true,"timezone":"Europe/London","openDate":"2022-03-03T13:57:00.000Z","version":4384107322,"name":"A9 400m","eventName":"Romford 3rd Mar"},"rc":[{"atb":[[1.12,30],[2.04,8.53]],"id":40214166},{"spl":[[18,10],[21,1]],"id":40214166},{"atl":[[370,3]],"id":40214166},{"spn":10.02,"spf":1.0,"id":40214166},{"atb":[[2,12.55],[1.12,30]],"id":40214168},{"spl":[[10,10],[21,1]],"id":40214168},{"atl":[[550,3]],"id":40214168},{"spn":6.0,"spf":1.0,"id":40214168},{"atb":[[2.02,12.67],[1.14,30]],"id":5677052},{"spl":[[34,10],[21,1]],"id":5677052},{"atl":[[500,3]],"id":5677052},{"spb":[[1000,50]],"id":5677052},{"spn":34.0,"spf":34.0,"id":5677052},{"atb":[[2,12.55],[1.12,30]],"id":41793694},{"spl":[[21,1],[6.6,10]],"id":41793694},{"atl":[[560,3]],"id":41793694},{"spn":4.3,"spf":1.0,"id":41793694},{"atb":[[1.12,30],[2.02,9.29]],"id":43189003},{"spl":[[21,1],[6.8,10]],"id":43189003},{"atl":[[390,3]],"id":43189003},{"spn":4.41,"spf":1.0,"id":43189003},{"atb":[[1.12,30],[2.08,11.3]],"id":42931076},{"spl":[[10,10],[21,1]],"id":42931076},{"atl":[[270,3]],"id":42931076},{"spn":6.04,"spf":1.0,"id":42931076}],"con":true,"img":true}]}
{"op":"mcm","clk":"5321081216","pt":1646305940721,"mc":[{"id":"1.195532870","rc":[{"atb":[[8,2],[2.04,8.53]],"id":40214166},{"spn":13.0,"spf":1.0,"id":40214166},{"atb":[[2,12.55],[9,2]],"id":40214168},{"spn":9.5,"spf":1.0,"id":40214168},{"atb":[[2.02,12.67],[3.3,2]],"id":5677052},{"atb":[[2,12.55],[3.7,2]],"id":41793694},{"spn":5.15,"spf":1.0,"id":41793694},{"atb":[[2.02,9.29],[4.7,2]],"id":43189003},{"spn":5.75,"spf":1.0,"id":43189003},{"atb":[[10,2],[2.08,11.3]],"id":42931076},{"spn":10.0,"spf":1.0,"id":42931076}],"con":true,"img":false}]}
{"op":"mcm","clk":"5321081868","pt":1646305949564,"mc":[{"id":"1.195532870","marketDefinition":{"bspMarket":true,"turnInPlayEnabled":false,"persistenceEnabled":false,"marketBaseRate":5.0,"eventId":"31275720","eventTypeId":"4339","numberOfWinners":1,"bettingType":"ODDS","marketType":"WIN","marketTime":"2022-03-03T16:48:00.000Z","suspendTime":"2022-03-03T16:48:00.000Z","bspReconciled":false,"complete":true,"inPlay":false,"crossMatching":true,"runnersVoidable":false,"numberOfActiveRunners":6,"betDelay":0,"status":"OPEN","runners":[{"status":"ACTIVE","sortPriority":1,"id":40214166,"name":"1. Mayses Scotty"},{"status":"ACTIVE","sortPriority":2,"id":43189003,"name":"2. Passage West Fox"},{"status":"ACTIVE","sortPriority":3,"id":40214168,"name":"3. Gonewiththedays"},{"status":"ACTIVE","sortPriority":4,"id":42931076,"name":"4. Comeragh Jet"},{"status":"ACTIVE","sortPriority":5,"id":41793694,"name":"5. Ogs Lady"},{"status":"ACTIVE","sortPriority":6,"id":5677052,"name":"6. Wichita Lineman"}],"regulators":["MR_INT"],"venue":"Romford","countryCode":"GB","discountAllowed":true,"timezone":"Europe/London","openDate":"2022-03-03T13:57:00.000Z","version":4384107322,"name":"A9 400m","eventName":"Romford 3rd Mar"},"rc":[],"con":true,"img":false}]}
{"op":"mcm","clk":"5321090339","pt":1646306054419,"mc":[{"id":"1.195532870","rc":[{"atb":[[10,5]],"id":42931076}],"con":true,"img":false}]}
{"op":"mcm","clk":"5321090503","pt":1646306056478,"mc":[{"id":"1.195532870","rc":[{"atb":[[10,3]],"id":42931076}],"con":true,"img":false}]}
{"op":"mcm","clk":"5321111708","pt":1646306282579,"mc":[{"id":"1.195532870","rc":[{"atb":[[6.2,1.93]],"id":40214166},{"atl":[[13.5,0.81]],"id":40214166},{"spn":10.75,"spf":1.0,"id":40214166},{"atb":[[6.6,1.8]],"id":40214168},{"atl":[[15,0.72]],"id":40214168},{"atb":[[3.05,2]],"id":5677052},{"atl":[[5.1,2]],"id":5677052},{"spn":21.0,"spf":34.0,"id":5677052},{"atb":[[3.3,2]],"id":41793694},{"atl":[[5.6,2]],"id":41793694},{"spn":4.65,"spf":1.0,"id":41793694},{"atb":[[4.1,2]],"id":43189003},{"atl":[[8,1.44]],"id":43189003},{"atb":[[9.2,1.23]],"id":42931076},{"atl":[[28,0.38]],"id":42931076}],"con":true,"img":false}]}
{"op":"mcm","clk":"5321275656","pt":1646307939237,"mc":[{"id":"1.195532870","rc":[{"atl":[[13.5,0]],"id":40214166},{"spn":13.0,"spf":1.0,"id":40214166},{"atl":[[8,0]],"id":43189003},{"atl":[[28,0]],"id":42931076}],"con":true,"img":false}]}
{"op":"mcm","clk":"5321275667","pt":1646307939341,"mc":[{"id":"1.195532870","rc":[{"atl":[[13,0.84]],"id":40214166},{"atl":[[15,0]],"id":40214168},{"atl":[[7.6,1.53]],"id":43189003},{"atl":[[26,0.41]],"id":42931076}],"con":true,"img":false}]}
{"op":"mcm","clk":"5321275679","pt":1646307939395,"mc":[{"id":"1.195532870","rc":[{"atl":[[14.5,0.75]],"id":40214168}],"con":true,"img":false}]}
{"op":"mcm","clk":"5321282978","pt":1646308002574,"mc":[{"id":"1.195532870","marketDefinition":{"bspMarket":true,"turnInPlayEnabled":false,"persistenceEnabled":false,"marketBaseRate":5.0,"eventId":"31275720","eventTypeId":"4339","numberOfWinners":1,"bettingType":"ODDS","marketType":"WIN","marketTime":"2022-03-03T16:48:00.000Z","suspendTime":"2022-03-03T16:48:00.000Z","bspReconciled":false,"complete":true,"inPlay":false,"crossMatching":true,"runnersVoidable":false,"numberOfActiveRunners":6,"betDelay":0,"status":"OPEN","runners":[{"status":"ACTIVE","sortPriority":1,"id":40214166,"name":"1. Mayses Scotty"},{"status":"ACTIVE","sortPriority":2,"id":43189003,"name":"2. Passage West Fox"},{"status":"ACTIVE","sortPriority":3,"id":40214168,"name":"3. Gonewiththedays"},{"status":"ACTIVE","sortPriority":4,"id":42931076,"name":"4. Comeragh Jet"},{"status":"ACTIVE","sortPriority":5,"id":41793694,"name":"5. Ogs Lady"},{"status":"ACTIVE","sortPriority":6,"id":5677052,"name":"6. Wichita Lineman"}],"regulators":["MR_INT"],"venue":"Romford","countryCode":"GB","discountAllowed":true,"timezone":"Europe/London","openDate":"2022-03-03T13:57:00.000Z","version":4384107322,"name":"A9 400m","eventName":"Romford 3rd Mar"},"rc":[{"atb":[[8,2],[1.12,30],[6.2,1.93],[2.04,8.53]],"id":40214166},{"spl":[[18,10],[21,1]],"id":40214166},{"atl":[[370,3],[13,0.84]],"id":40214166},{"spn":10.5,"spf":1.0,"id":40214166},{"atb":[[2,12.55],[1.12,30],[9,2],[6.6,1.8]],"id":40214168},{"spl":[[10,10],[21,1]],"id":40214168},{"atl":[[550,3],[14.5,0.75]],"id":40214168},{"spn":9.5,"spf":1.0,"id":40214168},{"atb":[[2.02,12.67],[1.14,30],[3.3,2],[3.05,2]],"id":5677052},{"spl":[[34,10],[21,1]],"id":5677052},{"atl":[[5.1,2],[500,3]],"id":5677052},{"spb":[[1000,50]],"id":5677052},{"spn":21.0,"spf":34.0,"id":5677052},{"atb":[[2,12.55],[1.12,30],[3.7,2],[3.3,2]],"id":41793694},{"spl":[[21,1],[6.6,10]],"id":41793694},{"atl":[[5.6,2],[560,3]],"id":41793694},{"spn":4.65,"spf":1.0,"id":41793694},{"atb":[[1.12,30],[2.02,9.29],[4.1,2],[4.7,2]],"id":43189003},{"spl":[[21,1],[6.8,10]],"id":43189003},{"atl":[[7.6,1.53],[390,3]],"id":43189003},{"spn":5.75,"spf":1.0,"id":43189003},{"atb":[[1.12,30],[10,3],[9.2,1.23],[2.08,11.3]],"id":42931076},{"spl":[[10,10],[21,1]],"id":42931076},{"atl":[[270,3],[26,0.41]],"id":42931076},{"spn":10.0,"spf":1.0,"id":42931076}],"con":true,"img":true}]}
{"op":"mcm","clk":"5321704878","pt":1646312448459,"mc":[{"id":"1.195532870","rc":[{"atb":[[2.04,8.52]],"id":40214166},{"atl":[[1000,2]],"id":40214166},{"spn":10.5,"spf":1.0,"id":40214166},{"atb":[[2,12.54]],"id":40214168},{"atb":[[2.02,12.66]],"id":5677052},{"atb":[[2,12.54]],"id":41793694},{"atb":[[2.02,9.28]],"id":43189003},{"atb":[[2.08,11.3]],"id":42931076}],"con":true,"img":false}]}
{"op":"mcm","clk":"5321704998","pt":1646312449706,"mc":[{"id":"1.195532870","rc":[{"atl":[[1000,2.2]],"id":40214166}],"con":true,"img":false}]}
{"op":"mcm","clk":"5321705141","pt":1646312451213,"mc":[{"id":"1.195532870","rc":[{"atl":[[1000,2]],"id":40214166}],"con":true,"img":false}]}
{"op":"mcm","clk":"5321705154","pt":1646312451321,"mc":[{"id":"1.195532870","rc":[{"atl":[[16.5,0.2]],"id":40214166}],"con":true,"img":false}]}
{"op":"mcm","clk":"5321705250","pt":1646312452665,"mc":[{"id":"1.195532870","rc":[{"atl":[[1000,2]],"id":43189003}],"con":true,"img":false}]}
{"op":"mcm","clk":"5321710748","pt":1646312514015,"mc":[{"id":"1.195532870","rc":[{"atl":[[1000,2.2]],"id":43189003}],"con":true,"img":false}]}
{"op":"mcm","clk":"5321710887","pt":1646312515422,"mc":[{"id":"1.195532870","rc":[{"atl":[[1000,2]],"id":43189003}],"con":true,"img":false}]}
{"op":"mcm","clk":"5321710898","pt":1646312515522,"mc":[{"id":"1.195532870","rc":[{"atl":[[10.5,0.2]],"id":43189003}],"con":true,"img":false}]}
{"op":"mcm","clk":"5321715391","pt":1646312564009,"mc":[{"id":"1.195532870","rc":[{"atl":[[1000,2]],"id":40214168}],"con":true,"img":false}]}
{"op":"mcm","clk":"5321720872","pt":1646312625489,"mc":[{"id":"1.195532870","rc":[{"atl":[[1000,2.2]],"id":40214168}],"con":true,"img":false}]}
{"op":"mcm","clk":"5321721010","pt":1646312626744,"mc":[{"id":"1.195532870","rc":[{"atl":[[1000,2]],"id":40214168}],"con":true,"img":false}]}
{"op":"mcm","clk":"5321721018","pt":1646312626844,"mc":[{"id":"1.195532870","rc":[{"atl":[[18,0.2]],"id":40214168}],"con":true,"img":false}]}
{"op":"mcm","clk":"5321721133","pt":1646312628150,"mc":[{"id":"1.195532870","rc":[{"atl":[[1000,2]],"id":42931076}],"con":true,"img":false}]}
{"op":"mcm","clk":"5321721248","pt":1646312629452,"mc":[{"id":"1.195532870","rc":[{"atl":[[1000,2.2]],"id":42931076}],"con":true,"img":false}]}
{"op":"mcm","clk":"5321721365","pt":1646312630855,"mc":[{"id":"1.195532870","rc":[{"atl":[[1000,2]],"id":42931076}],"con":true,"img":false}]}
{"op":"mcm","clk":"5321721376","pt":1646312630958,"mc":[{"id":"1.195532870","rc":[{"atl":[[26,0.61]],"id":42931076}],"con":true,"img":false}]}
{"op":"mcm","clk":"5321721491","pt":1646312632261,"mc":[{"id":"1.195532870","rc":[{"atl":[[1000,2]],"id":41793694}],"con":true,"img":false}]}
{"op":"mcm","clk":"5321728256","pt":1646312697009,"mc":[{"id":"1.195532870","rc":[{"atl":[[1000,2.2]],"id":41793694}],"con":true,"img":false}]}
{"op":"mcm","clk":"5321728402","pt":1646312698312,"mc":[{"id":"1.195532870","rc":[{"atl":[[1000,2]],"id":41793694}],"con":true,"img":false}]}
{"op":"mcm","clk":"5321728411","pt":1646312698410,"mc":[{"id":"1.195532870","rc":[{"atl":[[9.4,0.2]],"id":41793694}],"con":true,"img":false}]}
{"op":"mcm","clk":"5321728545","pt":1646312699715,"mc":[{"id":"1.195532870","rc":[{"atl":[[1000,2]],"id":5677052}],"con":true,"img":false}]}
{"op":"mcm","clk":"5321728686","pt":1646312701021,"mc":[{"id":"1.195532870","rc":[{"atl":[[1000,2.2]],"id":5677052}],"con":true,"img":false}]}
{"op":"mcm","clk":"5321728847","pt":1646312702391,"mc":[{"id":"1.195532870","rc":[{"atl":[[1000,2]],"id":5677052}],"con":true,"img":false}]}
{"op":"mcm","clk":"5321728859","pt":1646312702536,"mc":[{"id":"1.195532870","rc":[{"atl":[[8,0.2]],"id":5677052}],"con":true,"img":false}]}
{"op":"mcm","clk":"5321868376","pt":1646313943544,"mc":[{"id":"1.195532870","rc":[{"atl":[[1000,2.5]],"id":5677052}],"con":true,"img":false}]}
{"op":"mcm","clk":"5321868390","pt":1646313943746,"mc":[{"id":"1.195532870","rc":[{"atl":[[1000,2]],"id":5677052}],"con":true,"img":false}]}
{"op":"mcm","clk":"5321868398","pt":1646313943853,"mc":[{"id":"1.195532870","rc":[{"atb":[[3.3,1.5]],"id":5677052},{"trd":[[3.3,1]],"ltp":3.3,"tv":1.0,"id":5677052}],"con":true,"img":false}]}
{"op":"mcm","clk":"5321868527","pt":1646313945772,"mc":[{"id":"1.195532870","rc":[{"atb":[[2.62,6.92]],"id":40214166}],"con":true,"img":false}]}
{"op":"mcm","clk":"5321868544","pt":1646313946027,"mc":[{"id":"1.195532870","rc":[{"atb":[[2.08,10.38]],"id":41793694}],"con":true,"img":false}]}
{"op":"mcm","clk":"5321868551","pt":1646313946139,"mc":[{"id":"1.195532870","rc":[{"atb":[[2.3,8.62]],"id":43189003}],"con":true,"img":false}]}
{"op":"mcm","clk":"5321868561","pt":1646313946343,"mc":[{"id":"1.195532870","rc":[{"atb":[[2.06,10.57]],"id":5677052}],"con":true,"img":false}]}
{"op":"mcm","clk":"5321868565","pt":1646313946445,"mc":[{"id":"1.195532870","rc":[{"atb":[[2.68,6.67]],"id":40214168},{"atb":[[2.9,5.89]],"id":42931076}],"con":true,"img":false}]}
{"op":"mcm","clk":"5321868666","pt":1646313947845,"mc":[{"id":"1.195532870","rc":[{"atb":[[3.3,2]],"id":5677052}],"con":true,"img":false}]}
{"op":"mcm","clk":"5321869330","pt":1646313955939,"mc":[{"id":"1.195532870","rc":[{"atb":[[2.34,9.26]],"id":43189003}],"con":true,"img":false}]}
{"op":"mcm","clk":"5321869379","pt":1646313956458,"mc":[{"id":"1.195532870","rc":[{"atb":[[2.94,6.4]],"id":42931076}],"con":true,"img":false}]}
{"op":"mcm","clk":"5321869386","pt":1646313956564,"mc":[{"id":"1.195532870","rc":[{"atb":[[2.72,7.21]],"id":40214168}],"con":true,"img":false}]}
{"op":"mcm","clk":"5321869412","pt":1646313956880,"mc":[{"id":"1.195532870","rc":[{"atb":[[2.66,7.48]],"id":40214166}],"con":true,"img":false}]}
{"op":"mcm","clk":"5321869418","pt":1646313956979,"mc":[{"id":"1.195532870","rc":[{"atb":[[2.12,11.08]],"id":41793694}],"con":true,"img":false}]}
{"op":"mcm","clk":"5321869429","pt":1646313957142,"mc":[{"id":"1.195532870","rc":[{"atb":[[2.1,11.29]],"id":5677052}],"con":true,"img":false}]}
{"op":"mcm","clk":"5321876701","pt":1646314041370,"mc":[{"id":"1.195532870","rc":[{"atb":[[4.7,0]],"id":43189003},{"trd":[[4.7,4]],"ltp":4.7,"tv":4.0,"id":43189003},{"spn":5.45,"spf":1.0,"id":43189003}],"con":true,"img":false}]}
{"op":"mcm","clk":"5321876720","pt":1646314041679,"mc":[{"id":"1.195532870","rc":[{"atb":[[4.1,0]],"id":43189003}],"con":true,"img":false}]}
{"op":"mcm","clk":"5321876729","pt":1646314041782,"mc":[{"id":"1.195532870","rc":[{"atb":[[2.56,2]],"id":43189003}],"con":true,"img":false}]}
{"op":"mcm","clk":"5321879133","pt":1646314072007,"mc":[{"id":"1.195532870","rc":[{"atb":[[2.14,5.89]],"id":5677052}],"con":true,"img":false}]}
{"op":"mcm","clk":"5321879139","pt":1646314072111,"mc":[{"id":"1.195532870","rc":[{"atb":[[2.16,5.8]],"id":41793694}],"con":true,"img":false}]}
{"op":"mcm","clk":"5321879149","pt":1646314072215,"mc":[{"id":"1.195532870","rc":[{"atb":[[2.38,4.87]],"id":43189003}],"con":true,"img":false}]}
{"op":"mcm","clk":"5321881379","pt":1646314098157,"mc":[{"id":"1.195532870","rc":[{"atb":[[2.02,0]],"id":5677052},{"atb":[[2,0]],"id":41793694},{"atb":[[2.02,0]],"id":43189003}],"con":true,"img":false}]}
{"op":"mcm","clk":"5321881389","pt":1646314098261,"mc":[{"id":"1.195532870","rc":[{"atb":[[2.16,12.66]],"id":5677052},{"atb":[[2.18,12.54]],"id":41793694},{"atb":[[2.36,9.28]],"id":43189003}],"con":true,"img":false}]}
{"op":"mcm","clk":"5321882017","pt":1646314105461,"mc":[{"id":"1.195532870","rc":[{"atb":[[2.14,0]],"id":5677052},{"atb":[[2.16,0]],"id":41793694},{"atb":[[2.38,0]],"id":43189003},{"spn":4.68,"spf":1.0,"id":43189003}],"con":true,"img":false}]}
{"op":"mcm","clk":"5321883559","pt":1646314126276,"mc":[{"id":"1.195532870","rc":[{"atb":[[2.4,4.8]],"id":43189003}],"con":true,"img":false}]}
{"op":"mcm","clk":"5321883567","pt":1646314126382,"mc":[{"id":"1.195532870","rc":[{"atb":[[2.22,5.51]],"id":41793694}],"con":true,"img":false}]}
{"op":"mcm","clk":"5321883574","pt":1646314126482,"mc":[{"id":"1.195532870","rc":[{"atb":[[2.2,5.6]],"id":5677052}],"con":true,"img":false}]}
{"op":"mcm","clk":"5321885373","pt":1646314148448,"mc":[{"id":"1.195532870","rc":[{"atb":[[2.42,6.98]],"id":43189003}],"con":true,"img":false}]}
{"op":"mcm","clk":"5321885998","pt":1646314156151,"mc":[{"id":"1.195532870","rc":[{"atb":[[2.4,0]],"id":43189003}],"con":true,"img":false}]}
{"op":"mcm","clk":"5321888804","pt":1646314189283,"mc":[{"id":"1.195532870","rc":[{"atb":[[2.62,0]],"id":40214166},{"atb":[[2.68,0]],"id":40214168},{"atb":[[2.06,0]],"id":5677052},{"atb":[[2.08,0]],"id":41793694},{"atb":[[2.3,0]],"id":43189003},{"atb":[[2.9,0]],"id":42931076}],"con":true,"img":false}]}
{"op":"mcm","clk":"5321889881","pt":1646314201681,"mc":[{"id":"1.195532870","rc":[{"atb":[[2.7,6.59]],"id":40214166},{"atb":[[2.76,6.36]],"id":40214168}],"con":true,"img":false}]}
{"op":"mcm","clk":"5321889888","pt":1646314201782,"mc":[{"id":"1.195532870","rc":[{"atb":[[2.46,4.6]],"id":43189003}],"con":true,"img":false}]}
{"op":"mcm","clk":"5321889900","pt":1646314201887,"mc":[{"id":"1.195532870","rc":[{"atb":[[2.2,14.95]],"id":5677052}],"con":true,"img":false}]}
{"op":"mcm","clk":"5321889909","pt":1646314201990,"mc":[{"id":"1.195532870","rc":[{"atb":[[2.98,5.66]],"id":42931076}],"con":true,"img":false}]}
{"op":"mcm","clk":"5321889916","pt":1646314202096,"mc":[{"id":"1.195532870","rc":[{"atb":[[2.22,14.71]],"id":41793694}],"con":true,"img":false}]}
{"op":"mcm","clk":"5321890438","pt":1646314207596,"mc":[{"id":"1.195532870","rc":[{"atb":[[2.24,7.99]],"id":5677052}],"con":true,"img":false}]}
{"op":"mcm","clk":"5321890458","pt":1646314207823,"mc":[{"id":"1.195532870","rc":[{"atb":[[2.26,7.86]],"id":41793694}],"con":true,"img":false}]}
{"op":"mcm","clk":"5321890464","pt":1646314207908,"mc":[{"id":"1.195532870","rc":[{"atb":[[2.42,0]],"id":43189003}],"con":true,"img":false}]}
{"op":"mcm","clk":"5321891168","pt":1646314216505,"mc":[{"id":"1.195532870","rc":[{"atb":[[2.2,9.34]],"id":5677052},{"atb":[[2.22,9.19]],"id":41793694},{"atb":[[2.46,0]],"id":43189003}],"con":true,"img":false}]}
{"op":"mcm","clk":"5321893131","pt":1646314237864,"mc":[{"id":"1.195532870","rc":[{"atb":[[2.4,4.8]],"id":43189003}],"con":true,"img":false}]}
{"op":"mcm","clk":"5321893142","pt":1646314237969,"mc":[{"id":"1.195532870","rc":[{"atb":[[2.3,5.17]],"id":41793694}],"con":true,"img":false}]}
{"op":"mcm","clk":"5321893156","pt":1646314238187,"mc":[{"id":"1.195532870","rc":[{"atb":[[2.28,5.25]],"id":5677052}],"con":true,"img":false}]}
{"op":"mcm","clk":"5321905883","pt":1646314398084,"mc":[{"id":"1.195532870","rc":[{"atb":[[2.16,0]],"id":5677052},{"atb":[[2.18,0]],"id":41793694}],"con":true,"img":false}]}
{"op":"mcm","clk":"5321905895","pt":1646314398183,"mc":[{"id":"1.195532870","rc":[{"atb":[[2.3,12.66]],"id":5677052},{"atb":[[2.32,12.54]],"id":41793694}],"con":true,"img":false}]}
{"op":"mcm","clk":"5321906346","pt":1646314403116,"mc":[{"id":"1.195532870","rc":[{"atb":[[2.24,0]],"id":5677052},{"atb":[[2.26,0]],"id":41793694}],"con":true,"img":false}]}
{"op":"mcm","clk":"5321906372","pt":1646314403376,"mc":[{"id":"1.195532870","rc":[{"atb":[[2.1,0]],"id":5677052},{"atb":[[2.12,0]],"id":41793694},{"atb":[[2.34,0]],"id":43189003}],"con":true,"img":false}]}
{"op":"mcm","clk":"5321906435","pt":1646314404101,"mc":[{"id":"1.195532870","rc":[{"atb":[[2.44,6.88]],"id":43189003}],"con":true,"img":false}]}
{"op":"mcm","clk":"5321906689","pt":1646314406484,"mc":[{"id":"1.195532870","rc":[{"atb":[[2.28,0]],"id":5677052},{"atb":[[2.3,0]],"id":41793694}],"con":true,"img":false}]}
{"op":"mcm","clk":"5321907238","pt":1646314412688,"mc":[{"id":"1.195532870","rc":[{"atb":[[2.4,0]],"id":43189003}],"con":true,"img":false}]}
{"op":"mcm","clk":"5321908254","pt":1646314425128,"mc":[{"id":"1.195532870","rc":[{"atb":[[2.36,9.13]],"id":41793694}],"con":true,"img":false}]}
{"op":"mcm","clk":"5321908270","pt":1646314425230,"mc":[{"id":"1.195532870","rc":[{"atb":[[2.34,9.26]],"id":5677052}],"con":true,"img":false}]}
{"op":"mcm","clk":"5321909039","pt":1646314434039,"mc":[{"id":"1.195532870","rc":[{"atb":[[2.48,4.54]],"id":43189003}],"con":true,"img":false}]}
{"op":"mcm","clk":"5321909791","pt":1646314442869,"mc":[{"id":"1.195532870","rc":[{"atb":[[2.2,0]],"id":5677052},{"atb":[[2.22,0]],"id":41793694}],"con":true,"img":false}]}
{"op":"mcm","clk":"5321910051","pt":1646314445875,"mc":[{"id":"1.195532870","rc":[{"atb":[[2.38,8.12]],"id":5677052}],"con":true,"img":false}]}
{"op":"mcm","clk":"5321910067","pt":1646314446037,"mc":[{"id":"1.195532870","rc":[{"atb":[[2.4,8]],"id":41793694}],"con":true,"img":false}]}
{"op":"mcm","clk":"5321910209","pt":1646314447448,"mc":[{"id":"1.195532870","rc":[{"atb":[[2.44,0]],"id":43189003}],"con":true,"img":false}]}
{"op":"mcm","clk":"5321910221","pt":1646314447542,"mc":[{"id":"1.195532870","rc":[{"atb":[[2.34,16.66]],"id":5677052}],"con":true,"img":false}]}
{"op":"mcm","clk":"5321910248","pt":1646314447858,"mc":[{"id":"1.195532870","rc":[{"atb":[[2.66,0]],"id":40214166},{"atb":[[2.72,0]],"id":40214168},{"atb":[[2.94,0]],"id":42931076}],"con":true,"img":false}]}
{"op":"mcm","clk":"5321910380","pt":1646314449371,"mc":[{"id":"1.195532870","rc":[{"atb":[[2.36,16.42]],"id":41793694}],"con":true,"img":false}]}
{"op":"mcm","clk":"5321910869","pt":1646314454778,"mc":[{"id":"1.195532870","rc":[{"atb":[[2.4,12.81]],"id":41793694},{"atb":[[2.48,0]],"id":43189003}],"con":true,"img":false}]}
{"op":"mcm","clk":"5321910887","pt":1646314454977,"mc":[{"id":"1.195532870","rc":[{"atb":[[2.38,13]],"id":5677052}],"con":true,"img":false}]}
{"op":"mcm","clk":"5321911772","pt":1646314465356,"mc":[{"id":"1.195532870","rc":[{"atb":[[3.05,6.06]],"id":42931076}],"con":true,"img":false}]}
{"op":"mcm","clk":"5321911802","pt":1646314465665,"mc":[{"id":"1.195532870","rc":[{"atb":[[2.8,6.89]],"id":40214168}],"con":true,"img":false}]}
{"op":"mcm","clk":"5321911814","pt":1646314465768,"mc":[{"id":"1.195532870","rc":[{"atb":[[2.74,7.13]],"id":40214166}],"con":true,"img":false}]}
{"op":"mcm","clk":"5321912787","pt":1646314476111,"mc":[{"id":"1.195532870","rc":[{"atb":[[2.4,4.8]],"id":43189003}],"con":true,"img":false}]}
{"op":"mcm","clk":"5321913511","pt":1646314482215,"mc":[{"id":"1.195532870","rc":[{"atb":[[2.34,9.26]],"id":5677052},{"atb":[[2.36,9.13]],"id":41793694}],"con":true,"img":false}]}
{"op":"mcm","clk":"5321915001","pt":1646314496823,"mc":[{"id":"1.195532870","rc":[{"atb":[[2.44,6.88]],"id":41793694}],"con":true,"img":false}]}
{"op":"mcm","clk":"5321915027","pt":1646314497032,"mc":[{"id":"1.195532870","rc":[{"atb":[[2.42,6.98]],"id":5677052}],"con":true,"img":false}]}
{"op":"mcm","clk":"5321916218","pt":1646314507844,"mc":[{"id":"1.195532870","rc":[{"atb":[[2.38,8.12]],"id":5677052},{"atb":[[2.4,8]],"id":41793694}],"con":true,"img":false}]}
{"op":"mcm","clk":"5321916540","pt":1646314510832,"mc":[{"id":"1.195532870","rc":[{"atb":[[2.44,6.88]],"id":43189003}],"con":true,"img":false}]}
{"op":"mcm","clk":"5321917309","pt":1646314517633,"mc":[{"id":"1.195532870","rc":[{"atb":[[2.4,0]],"id":43189003}],"con":true,"img":false}]}
{"op":"mcm","clk":"5321918131","pt":1646314524969,"mc":[{"id":"1.195532870","rc":[{"atb":[[2.48,4.54]],"id":41793694}],"con":true,"img":false}]}
{"op":"mcm","clk":"5321918157","pt":1646314525175,"mc":[{"id":"1.195532870","rc":[{"atb":[[2.46,4.6]],"id":5677052}],"con":true,"img":false}]}
{"op":"mcm","clk":"5321919718","pt":1646314540087,"mc":[{"id":"1.195532870","rc":[{"atb":[[2.48,4.54]],"id":43189003}],"con":true,"img":false}]}
{"op":"mcm","clk":"5321920050","pt":1646314543478,"mc":[{"id":"1.195532870","rc":[{"atb":[[2.42,0]],"id":5677052},{"atb":[[2.44,0]],"id":41793694},{"atb":[[2.44,0]],"id":43189003}],"con":true,"img":false}]}
{"op":"mcm","clk":"5321920844","pt":1646314551787,"mc":[{"id":"1.195532870","rc":[{"atb":[[2.46,0]],"id":5677052},{"atb":[[2.48,0]],"id":41793694},{"atb":[[2.48,0]],"id":43189003}],"con":true,"img":false}]}
{"op":"mcm","clk":"5321922895","pt":1646314571930,"mc":[{"id":"1.195532870","rc":[{"atb":[[2.4,12.81]],"id":41793694}],"con":true,"img":false}]}
{"op":"mcm","clk":"5321922923","pt":1646314572138,"mc":[{"id":"1.195532870","rc":[{"atb":[[2.38,13]],"id":5677052},{"atb":[[2.4,4.8]],"id":43189003}],"con":true,"img":false}]}
{"op":"mcm","clk":"5321924823","pt":1646314589857,"mc":[{"id":"1.195532870","rc":[{"atb":[[2.44,6.88]],"id":41793694}],"con":true,"img":false}]}
{"op":"mcm","clk":"5321924852","pt":1646314590130,"mc":[{"id":"1.195532870","rc":[{"atb":[[2.42,6.98]],"id":5677052}],"con":true,"img":false}]}
{"op":"mcm","clk":"5321925729","pt":1646314598865,"mc":[{"id":"1.195532870","rc":[{"atb":[[2.38,8.12]],"id":5677052},{"atb":[[2.4,8]],"id":41793694}],"con":true,"img":false}]}
{"op":"mcm","clk":"5321927638","pt":1646314616177,"mc":[{"id":"1.195532870","rc":[{"atb":[[2.44,6.88]],"id":43189003}],"con":true,"img":false}]}
{"op":"mcm","clk":"5321928029","pt":1646314619983,"mc":[{"id":"1.195532870","rc":[{"atb":[[2.48,4.54]],"id":41793694}],"con":true,"img":false}]}
{"op":"mcm","clk":"5321928052","pt":1646314620187,"mc":[{"id":"1.195532870","rc":[{"atb":[[2.46,4.6]],"id":5677052}],"con":true,"img":false}]}
{"op":"mcm","clk":"5321928365","pt":1646314623123,"mc":[{"id":"1.195532870","rc":[{"atb":[[2.4,0]],"id":43189003}],"con":true,"img":false}]}
{"op":"mcm","clk":"5321930759","pt":1646314644750,"mc":[{"id":"1.195532870","rc":[{"atb":[[2.48,4.54]],"id":43189003}],"con":true,"img":false}]}
{"op":"mcm","clk":"5321931730","pt":1646314653547,"mc":[{"id":"1.195532870","rc":[{"atb":[[2.42,0]],"id":5677052},{"atb":[[2.44,0]],"id":41793694},{"atb":[[2.44,0]],"id":43189003}],"con":true,"img":false}]}
{"op":"mcm","clk":"5321932705","pt":1646314662445,"mc":[{"id":"1.195532870","rc":[{"atb":[[2.46,0]],"id":5677052},{"atb":[[2.48,0]],"id":41793694},{"atb":[[2.48,0]],"id":43189003}],"con":true,"img":false}]}
{"op":"mcm","clk":"5321934832","pt":1646314680550,"mc":[{"id":"1.195532870","rc":[{"atb":[[2.7,0]],"id":40214166},{"atb":[[2.76,0]],"id":40214168},{"atb":[[2.98,0]],"id":42931076}],"con":true,"img":false}]}
{"op":"mcm","clk":"5321935246","pt":1646314683646,"mc":[{"id":"1.195532870","rc":[{"atb":[[2.4,4.8]],"id":43189003}],"con":true,"img":false}]}
{"op":"mcm","clk":"5321935276","pt":1646314683831,"mc":[{"id":"1.195532870","rc":[{"atb":[[2.38,13]],"id":5677052}],"con":true,"img":false}]}
{"op":"mcm","clk":"5321935287","pt":1646314683920,"mc":[{"id":"1.195532870","rc":[{"atb":[[2.84,6.09]],"id":40214168}],"con":true,"img":false}]}
{"op":"mcm","clk":"5321935293","pt":1646314684014,"mc":[{"id":"1.195532870","rc":[{"atb":[[2.4,12.81]],"id":41793694}],"con":true,"img":false}]}
{"op":"mcm","clk":"5321935313","pt":1646314684129,"mc":[{"id":"1.195532870","rc":[{"atb":[[2.78,6.3]],"id":40214166}],"con":true,"img":false}]}
{"op":"mcm","clk":"5321935335","pt":1646314684331,"mc":[{"id":"1.195532870","rc":[{"atb":[[3.15,5.21]],"id":42931076}],"con":true,"img":false}]}
{"op":"mcm","clk":"5321936587","pt":1646314695659,"mc":[{"id":"1.195532870","rc":[{"atb":[[2.3,0]],"id":5677052}],"con":true,"img":false}]}
{"op":"mcm","clk":"5321936613","pt":1646314695816,"mc":[{"id":"1.195532870","rc":[{"atb":[[2.36,12.66]],"id":5677052}],"con":true,"img":false}]}
{"op":"mcm","clk":"5321937538","pt":1646314703058,"mc":[{"id":"1.195532870","rc":[{"atb":[[2.42,6.98]],"id":5677052}],"con":true,"img":false}]}
{"op":"mcm","clk":"5321937546","pt":1646314703164,"mc":[{"id":"1.195532870","rc":[{"atb":[[2.44,6.88]],"id":41793694}],"con":true,"img":false}]}
{"op":"mcm","clk":"5321937587","pt":1646314703679,"mc":[{"id":"1.195532870","rc":[{"atb":[[2.34,0]],"id":5677052},{"atb":[[2.36,0]],"id":41793694}],"con":true,"img":false}]}
{"op":"mcm","clk":"5321937683","pt":1646314704464,"mc":[{"id":"1.195532870","rc":[{"atb":[[2.38,8.12]],"id":5677052}],"con":true,"img":false}]}
{"op":"mcm","clk":"5321938336","pt":1646314710355,"mc":[{"id":"1.195532870","rc":[{"atb":[[2.4,8]],"id":41793694}],"con":true,"img":false}]}
{"op":"mcm","clk":"5321939194","pt":1646314717579,"mc":[{"id":"1.195532870","rc":[{"atb":[[2.44,6.88]],"id":43189003}],"con":true,"img":false}]}
{"op":"mcm","clk":"5321939235","pt":1646314717889,"mc":[{"id":"1.195532870","rc":[{"atb":[[2.44,15.51]],"id":41793694}],"con":true,"img":false}]}
{"op":"mcm","clk":"5321939257","pt":1646314718097,"mc":[{"id":"1.195532870","rc":[{"atb":[[2.42,15.73]],"id":5677052}],"con":true,"img":false}]}
{"op":"mcm","clk":"5321940410","pt":1646314729292,"mc":[{"id":"1.195532870","rc":[{"atb":[[2.4,0]],"id":43189003}],"con":true,"img":false}]}
{"op":"mcm","clk":"5321940672","pt":1646314731877,"mc":[{"id":"1.195532870","rc":[{"atb":[[2.48,4.54]],"id":41793694}],"con":true,"img":false}]}
{"op":"mcm","clk":"5321940680","pt":1646314731979,"mc":[{"id":"1.195532870","rc":[{"atb":[[2.46,4.6]],"id":5677052}],"con":true,"img":false}]}
{"op":"mcm","clk":"5321940698","pt":1646314732192,"mc":[{"id":"1.195532870","rc":[{"atb":[[2.38,0]],"id":5677052},{"atb":[[2.4,0]],"id":41793694}],"con":true,"img":false}]}
{"op":"mcm","clk":"5321940899","pt":1646314734396,"mc":[{"id":"1.195532870","rc":[{"atb":[[2.48,12.12]],"id":41793694}],"con":true,"img":false}]}
{"op":"mcm","clk":"5321940913","pt":1646314734501,"mc":[{"id":"1.195532870","rc":[{"atb":[[2.46,12.28]],"id":5677052}],"con":true,"img":false}]}
{"op":"mcm","clk":"5321942592","pt":1646314749197,"mc":[{"id":"1.195532870","rc":[{"atb":[[2.42,8.74]],"id":5677052},{"atb":[[2.44,8.62]],"id":41793694},{"atb":[[2.44,0]],"id":43189003}],"con":true,"img":false}]}
{"op":"mcm","clk":"5321942700","pt":1646314750190,"mc":[{"id":"1.195532870","rc":[{"atb":[[2.48,4.54]],"id":43189003}],"con":true,"img":false}]}
{"op":"mcm","clk":"5321943651","pt":1646314758403,"mc":[{"id":"1.195532870","rc":[{"atb":[[2.48,0]],"id":43189003}],"con":true,"img":false}]}
{"op":"mcm","clk":"5321944111","pt":1646314762423,"mc":[{"id":"1.195532870","rc":[{"atb":[[2.5,6.61]],"id":5677052}],"con":true,"img":false}]}
{"op":"mcm","clk":"5321944135","pt":1646314762630,"mc":[{"id":"1.195532870","rc":[{"atb":[[2.52,6.52]],"id":41793694}],"con":true,"img":false}]}
{"op":"mcm","clk":"5321944146","pt":1646314762693,"mc":[{"id":"1.195532870","rc":[{"atb":[[2.4,7.08]],"id":43189003}],"con":true,"img":false}]}
{"op":"mcm","clk":"5321945024","pt":1646314770409,"mc":[{"id":"1.195532870","rc":[{"atb":[[2.46,7.67]],"id":5677052},{"atb":[[2.48,7.58]],"id":41793694}],"con":true,"img":false}]}
{"op":"mcm","clk":"5321947506","pt":1646314791421,"mc":[{"id":"1.195532870","rc":[{"atb":[[2.58,4.26]],"id":41793694}],"con":true,"img":false}]}
{"op":"mcm","clk":"5321947524","pt":1646314791529,"mc":[{"id":"1.195532870","rc":[{"atb":[[2.44,4.67]],"id":43189003}],"con":true,"img":false}]}
{"op":"mcm","clk":"5321947548","pt":1646314791730,"mc":[{"id":"1.195532870","rc":[{"atb":[[2.56,4.31]],"id":5677052}],"con":true,"img":false}]}
{"op":"mcm","clk":"5321950216","pt":1646314815007,"mc":[{"id":"1.195532870","rc":[{"atb":[[2.5,0]],"id":5677052},{"atb":[[2.52,0]],"id":41793694},{"atb":[[2.4,0]],"id":43189003}],"con":true,"img":false}]}
{"op":"mcm","clk":"5321950993","pt":1646314821900,"mc":[{"id":"1.195532870","rc":[{"atb":[[2.56,0]],"id":5677052},{"atb":[[2.58,0]],"id":41793694},{"atb":[[2.44,0]],"id":43189003}],"con":true,"img":false}]}
{"op":"mcm","clk":"5321953422","pt":1646314842987,"mc":[{"id":"1.195532870","rc":[{"atb":[[2.4,4.8]],"id":43189003}],"con":true,"img":false}]}
{"op":"mcm","clk":"5321953436","pt":1646314843106,"mc":[{"id":"1.195532870","rc":[{"atb":[[2.48,12.12]],"id":41793694}],"con":true,"img":false}]}
{"op":"mcm","clk":"5321953451","pt":1646314843202,"mc":[{"id":"1.195532870","rc":[{"atb":[[2.46,12.28]],"id":5677052}],"con":true,"img":false}]}
{"op":"mcm","clk":"5321955523","pt":1646314863201,"mc":[{"id":"1.195532870","rc":[{"atb":[[2.5,6.61]],"id":5677052}],"con":true,"img":false}]}
{"op":"mcm","clk":"5321955541","pt":1646314863407,"mc":[{"id":"1.195532870","rc":[{"atb":[[2.52,6.52]],"id":41793694}],"con":true,"img":false}]}
{"op":"mcm","clk":"5321956704","pt":1646314875310,"mc":[{"id":"1.195532870","rc":[{"atb":[[2.46,7.67]],"id":5677052},{"atb":[[2.48,7.58]],"id":41793694}],"con":true,"img":false}]}
{"op":"mcm","clk":"5321958058","pt":1646314890050,"mc":[{"id":"1.195532870","rc":[{"atb":[[2.44,6.88]],"id":43189003}],"con":true,"img":false}]}
{"op":"mcm","clk":"5321958156","pt":1646314891131,"mc":[{"id":"1.195532870","rc":[{"atb":[[2.56,4.31]],"id":5677052}],"con":true,"img":false}]}
{"op":"mcm","clk":"5321958162","pt":1646314891235,"mc":[{"id":"1.195532870","rc":[{"atb":[[2.58,4.26]],"id":41793694}],"con":true,"img":false}]}
{"op":"mcm","clk":"5321958699","pt":1646314897147,"mc":[{"id":"1.195532870","rc":[{"atb":[[2.4,0]],"id":43189003}],"con":true,"img":false}]}
{"op":"mcm","clk":"5321960598","pt":1646314918464,"mc":[{"id":"1.195532870","rc":[{"atb":[[2.48,4.54]],"id":43189003}],"con":true,"img":false}]}
{"op":"mcm","clk":"5321961851","pt":1646314931182,"mc":[{"id":"1.195532870","rc":[{"atb":[[2.5,0]],"id":5677052},{"atb":[[2.52,0]],"id":41793694},{"atb":[[2.44,0]],"id":43189003}],"con":true,"img":false}]}
{"op":"mcm","clk":"5321961867","pt":1646314931286,"mc":[{"id":"1.195532870","rc":[{"atb":[[2.74,0]],"id":40214166},{"atb":[[2.8,0]],"id":40214168},{"atb":[[3.05,0]],"id":42931076}],"con":true,"img":false}]}
{"op":"mcm","clk":"5321962681","pt":1646314939186,"mc":[{"id":"1.195532870","rc":[{"atb":[[2.56,0]],"id":5677052},{"atb":[[2.58,0]],"id":41793694},{"atb":[[2.48,0]],"id":43189003}],"con":true,"img":false}]}
{"op":"mcm","clk":"5321963361","pt":1646314946098,"mc":[{"id":"1.195532870","rc":[{"atb":[[2.82,6.82]],"id":40214166}],"con":true,"img":false}]}
{"op":"mcm","clk":"5321963409","pt":1646314946617,"mc":[{"id":"1.195532870","rc":[{"atb":[[3.25,5.52]],"id":42931076}],"con":true,"img":false}]}
{"op":"mcm","clk":"5321963419","pt":1646314946720,"mc":[{"id":"1.195532870","rc":[{"atb":[[2.88,6.6]],"id":40214168}],"con":true,"img":false}]}
{"op":"mcm","clk":"5321964781","pt":1646314959907,"mc":[{"id":"1.195532870","rc":[{"atb":[[2.48,12.12]],"id":41793694}],"con":true,"img":false}]}
{"op":"mcm","clk":"5321964799","pt":1646314960009,"mc":[{"id":"1.195532870","rc":[{"atb":[[2.4,4.8]],"id":43189003}],"con":true,"img":false}]}
{"op":"mcm","clk":"5321964827","pt":1646314960217,"mc":[{"id":"1.195532870","rc":[{"atb":[[2.46,12.28]],"id":5677052}],"con":true,"img":false}]}
{"op":"mcm","clk":"5321965508","pt":1646314966717,"mc":[{"id":"1.195532870","rc":[{"atb":[[2.42,0]],"id":5677052},{"atb":[[2.44,0]],"id":41793694}],"con":true,"img":false}]}
{"op":"mcm","clk":"5321966385","pt":1646314975246,"mc":[{"id":"1.195532870","rc":[{"atb":[[2.46,7.67]],"id":5677052},{"atb":[[2.48,7.58]],"id":41793694}],"con":true,"img":false}]}
{"op":"mcm","clk":"5321967021","pt":1646314982361,"mc":[{"id":"1.195532870","rc":[{"atb":[[2.52,6.52]],"id":41793694}],"con":true,"img":false}]}
{"op":"mcm","clk":"5321967051","pt":1646314982674,"mc":[{"id":"1.195532870","rc":[{"atb":[[2.52,14.69]],"id":41793694}],"con":true,"img":false}]}
{"op":"mcm","clk":"5321967134","pt":1646314983351,"mc":[{"id":"1.195532870","rc":[{"atb":[[2.5,6.61]],"id":5677052}],"con":true,"img":false}]}
{"op":"mcm","clk":"5321967144","pt":1646314983457,"mc":[{"id":"1.195532870","rc":[{"atb":[[2.5,14.89]],"id":5677052}],"con":true,"img":false}]}
{"op":"mcm","clk":"5321968537","pt":1646314996181,"mc":[{"id":"1.195532870","rc":[{"atb":[[2.46,0]],"id":5677052},{"atb":[[2.48,0]],"id":41793694}],"con":true,"img":false}]}
{"op":"mcm","clk":"5321968812","pt":1646314998886,"mc":[{"id":"1.195532870","rc":[{"atb":[[2.56,7.19]],"id":41793694}],"con":true,"img":false}]}
{"op":"mcm","clk":"5321968837","pt":1646314999092,"mc":[{"id":"1.195532870","rc":[{"atb":[[2.54,7.28]],"id":5677052}],"con":true,"img":false}]}
{"op":"mcm","clk":"5321969003","pt":1646315000659,"mc":[{"id":"1.195532870","rc":[{"atb":[[2.44,6.88]],"id":43189003}],"con":true,"img":false}]}
{"op":"mcm","clk":"5321969696","pt":1646315008195,"mc":[{"id":"1.195532870","rc":[{"atb":[[2.4,0]],"id":43189003}],"con":true,"img":false}]}
{"op":"mcm","clk":"5321970027","pt":1646315012301,"mc":[{"id":"1.195532870","rc":[{"atb":[[2.58,4.26]],"id":41793694}],"con":true,"img":false}]}
{"op":"mcm","clk":"5321970044","pt":1646315012510,"mc":[{"id":"1.195532870","rc":[{"atb":[[2.56,4.31]],"id":5677052}],"con":true,"img":false}]}
{"op":"mcm","clk":"5321970363","pt":1646315016296,"mc":[{"id":"1.195532870","rc":[{"atb":[[2.5,8.27]],"id":5677052},{"atb":[[2.52,8.17]],"id":41793694}],"con":true,"img":false}]}
{"op":"mcm","clk":"5321971485","pt":1646315029038,"mc":[{"id":"1.195532870","rc":[{"atb":[[2.44,0]],"id":43189003}],"con":true,"img":false}]}
{"op":"mcm","clk":"5321971502","pt":1646315029202,"mc":[{"id":"1.195532870","rc":[{"atb":[[2.48,4.54]],"id":43189003}],"con":true,"img":false}]}
{"op":"mcm","clk":"5321972399","pt":1646315038219,"mc":[{"id":"1.195532870","rc":[{"atb":[[2.48,0]],"id":43189003}],"con":true,"img":false}]}
{"op":"mcm","clk":"5321974018","pt":1646315053636,"mc":[{"id":"1.195532870","rc":[{"atb":[[2.4,7.08]],"id":43189003}],"con":true,"img":false}]}
{"op":"mcm","clk":"5321974023","pt":1646315053739,"mc":[{"id":"1.195532870","rc":[{"atb":[[2.62,6.12]],"id":5677052}],"con":true,"img":false}]}
{"op":"mcm","clk":"5321974040","pt":1646315053949,"mc":[{"id":"1.195532870","rc":[{"atb":[[2.64,6.05]],"id":41793694}],"con":true,"img":false}]}
{"op":"mcm","clk":"5321974945","pt":1646315062274,"mc":[{"id":"1.195532870","rc":[{"atb":[[2.56,0]],"id":5677052},{"atb":[[2.58,0]],"id":41793694}],"con":true,"img":false}]}
{"op":"mcm","clk":"5321976692","pt":1646315081605,"mc":[{"id":"1.195532870","rc":[{"atb":[[2.62,0]],"id":5677052},{"atb":[[2.64,0]],"id":41793694}],"con":true,"img":false}]}
{"op":"mcm","clk":"5321976913","pt":1646315084152,"mc":[{"id":"1.195532870","rc":[{"atb":[[2.44,4.67]],"id":43189003}],"con":true,"img":false}]}
{"op":"mcm","clk":"5321978076","pt":1646315097675,"mc":[{"id":"1.195532870","rc":[{"atb":[[2.6,6.19]],"id":5677052}],"con":true,"img":false}]}
{"op":"mcm","clk":"5321978093","pt":1646315097882,"mc":[{"id":"1.195532870","rc":[{"atb":[[2.62,6.12]],"id":41793694}],"con":true,"img":false}]}
{"op":"mcm","clk":"5321979473","pt":1646315112790,"mc":[{"id":"1.195532870","rc":[{"atb":[[2.4,0]],"id":43189003}],"con":true,"img":false}]}
{"op":"mcm","clk":"5321980682","pt":1646315119601,"mc":[{"id":"1.195532870","rc":[{"atb":[[2.44,0]],"id":43189003}],"con":true,"img":false}]}
{"op":"mcm","clk":"5321980814","pt":1646315120290,"mc":[{"id":"1.195532870","rc":[{"atl":[[1000,4.5]],"id":40214166},{"atl":[[1000,4.5]],"id":40214168},{"atl":[[1000,4.5]],"id":5677052},{"atl":[[1000,4.5]],"id":41793694},{"atl":[[1000,4.5]],"id":43189003},{"atl":[[1000,4.5]],"id":42931076}],"con":true,"img":false}]}
{"op":"mcm","clk":"5321980845","pt":1646315120490,"mc":[{"id":"1.195532870","rc":[{"atl":[[1000,14.5]],"id":40214166},{"atl":[[1000,14.5]],"id":40214168},{"atl":[[1000,14.5]],"id":5677052},{"atl":[[1000,14.5]],"id":41793694},{"atl":[[1000,14.5]],"id":43189003},{"atl":[[1000,14.5]],"id":42931076}],"con":true,"img":false}]}
{"op":"mcm","clk":"5321980874","pt":1646315120708,"mc":[{"id":"1.195532870","rc":[{"atb":[[1.01,1000]],"id":40214166},{"atb":[[1.01,1000]],"id":40214168},{"atb":[[1.01,1000]],"id":5677052},{"atb":[[1.01,1000]],"id":41793694},{"atb":[[1.01,1000]],"id":43189003},{"atb":[[1.01,1000]],"id":42931076}],"con":true,"img":false}]}
{"op":"mcm","clk":"5321980922","pt":1646315120966,"mc":[{"id":"1.195532870","rc":[{"atb":[[1.01,11000]],"id":40214166},{"atb":[[1.01,11000]],"id":40214168},{"atb":[[1.01,11000]],"id":5677052},{"atb":[[1.01,11000]],"id":41793694},{"atb":[[1.01,11000]],"id":43189003},{"atb":[[1.01,11000]],"id":42931076}],"con":true,"img":false}]}
{"op":"mcm","clk":"5321981780","pt":1646315126294,"mc":[{"id":"1.195532870","rc":[{"atb":[[2.66,4.05]],"id":5677052}],"con":true,"img":false}]}
{"op":"mcm","clk":"5321982129","pt":1646315128814,"mc":[{"id":"1.195532870","rc":[{"atb":[[2.68,4]],"id":41793694}],"con":true,"img":false}]}
{"op":"mcm","clk":"5321983514","pt":1646315141214,"mc":[{"id":"1.195532870","rc":[{"atb":[[2.4,4.8]],"id":43189003}],"con":true,"img":false}]}
{"op":"mcm","clk":"5321985234","pt":1646315157715,"mc":[{"id":"1.195532870","rc":[{"atb":[[2.6,0]],"id":5677052},{"atb":[[2.62,0]],"id":41793694}],"con":true,"img":false}]}
{"op":"mcm","clk":"5321985964","pt":1646315164949,"mc":[{"id":"1.195532870","rc":[{"atb":[[2.66,0]],"id":5677052},{"atb":[[2.68,0]],"id":41793694}],"con":true,"img":false}]}
{"op":"mcm","clk":"5321985974","pt":1646315165040,"mc":[{"id":"1.195532870","rc":[{"atb":[[2.78,0]],"id":40214166},{"atb":[[2.84,0]],"id":40214168},{"atb":[[3.15,0]],"id":42931076}],"con":true,"img":false}]}
{"op":"mcm","clk":"5321986041","pt":1646315165724,"mc":[{"id":"1.195532870","rc":[{"spl":[[1.01,10]],"id":5677052}],"con":true,"img":false}]}
{"op":"mcm","clk":"5321986268","pt":1646315167848,"mc":[{"id":"1.195532870","rc":[{"atb":[[3.35,4.76]],"id":42931076}],"con":true,"img":false}]}
{"op":"mcm","clk":"5321986277","pt":1646315167945,"mc":[{"id":"1.195532870","rc":[{"atb":[[2.86,6.02]],"id":40214166}],"con":true,"img":false}]}
{"op":"mcm","clk":"5321986288","pt":1646315168053,"mc":[{"id":"1.195532870","rc":[{"atb":[[2.92,5.83]],"id":40214168}],"con":true,"img":false}]}
{"op":"mcm","clk":"5321988418","pt":1646315185683,"mc":[{"id":"1.195532870","rc":[{"atb":[[2.56,4.31]],"id":5677052},{"atb":[[2.58,4.26]],"id":41793694}],"con":true,"img":false}]}
{"op":"mcm","clk":"5321988892","pt":1646315190280,"mc":[{"id":"1.195532870","rc":[{"spn":5.15,"spf":6.0,"id":5677052},{"atb":[[2.44,6.88]],"id":43189003}],"con":true,"img":false}]}
{"op":"mcm","clk":"5321989888","pt":1646315201467,"mc":[{"id":"1.195532870","rc":[{"atb":[[2.4,0]],"id":43189003}],"con":true,"img":false}]}
{"op":"mcm","clk":"5321991687","pt":1646315222021,"mc":[{"id":"1.195532870","rc":[{"atb":[[2.48,4.54]],"id":43189003}],"con":true,"img":false}]}
{"op":"mcm","clk":"5321991752","pt":1646315222499,"mc":[{"id":"1.195532870","rc":[{"atb":[[2.44,0]],"id":43189003}],"con":true,"img":false}]}
{"op":"mcm","clk":"5321991786","pt":1646315222807,"mc":[{"id":"1.195532870","rc":[{"atb":[[2.64,6.05]],"id":41793694}],"con":true,"img":false}]}
{"op":"mcm","clk":"5321991809","pt":1646315223014,"mc":[{"id":"1.195532870","rc":[{"atb":[[2.62,6.12]],"id":5677052}],"con":true,"img":false}]}
{"op":"mcm","clk":"5321992547","pt":1646315230806,"mc":[{"id":"1.195532870","rc":[{"atb":[[2.56,0]],"id":5677052},{"atb":[[2.58,0]],"id":41793694},{"atb":[[2.48,0]],"id":43189003}],"con":true,"img":false}]}
{"op":"mcm","clk":"5321992807","pt":1646315233719,"mc":[{"id":"1.195532870","rc":[{"atb":[[2.5,0]],"id":5677052},{"atb":[[2.52,0]],"id":41793694}],"con":true,"img":false}]}
{"op":"mcm","clk":"5321992837","pt":1646315234028,"mc":[{"id":"1.195532870","rc":[{"atb":[[2.4,7.08]],"id":43189003}],"con":true,"img":false}]}
{"op":"mcm","clk":"5321994144","pt":1646315245663,"mc":[{"id":"1.195532870","rc":[{"atb":[[2.62,0]],"id":5677052},{"atb":[[2.64,0]],"id":41793694}],"con":true,"img":false}]}
{"op":"mcm","clk":"5321994175","pt":1646315245861,"mc":[{"id":"1.195532870","rc":[{"atb":[[2.68,7.39]],"id":41793694}],"con":true,"img":false}]}
{"op":"mcm","clk":"5321994226","pt":1646315246236,"mc":[{"id":"1.195532870","rc":[{"atb":[[2.66,7.48]],"id":5677052}],"con":true,"img":false}]}
{"op":"mcm","clk":"5321996016","pt":1646315259922,"mc":[{"id":"1.195532870","rc":[{"atb":[[2.6,6.19]],"id":5677052}],"con":true,"img":false}]}
{"op":"mcm","clk":"5321996077","pt":1646315260392,"mc":[{"id":"1.195532870","rc":[{"atb":[[2.62,6.12]],"id":41793694}],"con":true,"img":false}]}
{"op":"mcm","clk":"5321996432","pt":1646315263715,"mc":[{"id":"1.195532870","rc":[{"atb":[[2.44,4.67]],"id":43189003}],"con":true,"img":false}]}
{"op":"mcm","clk":"5321998030","pt":1646315276746,"mc":[{"id":"1.195532870","rc":[{"atb":[[2.74,3.86]],"id":41793694}],"con":true,"img":false}]}
{"op":"mcm","clk":"5321998041","pt":1646315276850,"mc":[{"id":"1.195532870","rc":[{"atb":[[2.72,3.9]],"id":5677052}],"con":true,"img":false}]}
{"op":"mcm","clk":"5321999471","pt":1646315288726,"mc":[{"id":"1.195532870","rc":[{"atb":[[2.54,0]],"id":5677052},{"atb":[[2.56,0]],"id":41793694}],"con":true,"img":false}]}
{"op":"mcm","clk":"5321999732","pt":1646315290620,"mc":[{"id":"1.195532870","rc":[{"atb":[[2.4,0]],"id":43189003}],"con":true,"img":false}]}
{"op":"mcm","clk":"5322000303","pt":1646315295060,"mc":[{"id":"1.195532870","rc":[{"atb":[[2.72,6.51]],"id":41793694}],"con":true,"img":false}]}
{"op":"mcm","clk":"5322000315","pt":1646315295166,"mc":[{"id":"1.195532870","rc":[{"atb":[[2.7,6.59]],"id":5677052}],"con":true,"img":false}]}
{"op":"mcm","clk":"5322001365","pt":1646315303477,"mc":[{"id":"1.195532870","rc":[{"atb":[[2.44,0]],"id":43189003}],"con":true,"img":false}]}
{"op":"mcm","clk":"5322001443","pt":1646315304142,"mc":[{"id":"1.195532870","rc":[{"atb":[[2.48,6.69]],"id":43189003}],"con":true,"img":false}]}
{"op":"mcm","clk":"5322001488","pt":1646315304556,"mc":[{"id":"1.195532870","rc":[{"atb":[[2.6,0]],"id":5677052},{"atb":[[2.62,0]],"id":41793694}],"con":true,"img":false}]}
{"op":"mcm","clk":"5322002848","pt":1646315317310,"mc":[{"id":"1.195532870","rc":[{"atb":[[2.8,5.51]],"id":41793694}],"con":true,"img":false}]}
{"op":"mcm","clk":"5322002873","pt":1646315317616,"mc":[{"id":"1.195532870","rc":[{"atb":[[2.78,5.57]],"id":5677052}],"con":true,"img":false}]}
{"op":"mcm","clk":"5322003603","pt":1646315324141,"mc":[{"id":"1.195532870","rc":[{"atb":[[2.72,0]],"id":5677052},{"atb":[[2.74,0]],"id":41793694}],"con":true,"img":false}]}
{"op":"mcm","clk":"5322004248","pt":1646315330148,"mc":[{"id":"1.195532870","rc":[{"atb":[[2.48,0]],"id":43189003}],"con":true,"img":false}]}
{"op":"mcm","clk":"5322005655","pt":1646315343755,"mc":[{"id":"1.195532870","rc":[{"atb":[[2.4,7.08]],"id":43189003}],"con":true,"img":false}]}
{"op":"mcm","clk":"5322005709","pt":1646315344334,"mc":[{"id":"1.195532870","rc":[{"atb":[[2.78,0]],"id":5677052},{"atb":[[2.8,0]],"id":41793694}],"con":true,"img":false}]}
{"op":"mcm","clk":"5322007373","pt":1646315360536,"mc":[{"id":"1.195532870","rc":[{"atb":[[2.78,5.57]],"id":41793694}],"con":true,"img":false}]}
{"op":"mcm","clk":"5322007392","pt":1646315360845,"mc":[{"id":"1.195532870","rc":[{"atb":[[2.76,5.63]],"id":5677052}],"con":true,"img":false}]}
{"op":"mcm","clk":"5322008440","pt":1646315372394,"mc":[{"id":"1.195532870","rc":[{"atb":[[2.44,4.67]],"id":43189003}],"con":true,"img":false}]}
{"op":"mcm","clk":"5322010295","pt":1646315390390,"mc":[{"id":"1.195532870","rc":[{"atb":[[2.84,3.65]],"id":41793694}],"con":true,"img":false}]}
{"op":"mcm","clk":"5322010308","pt":1646315390491,"mc":[{"id":"1.195532870","rc":[{"atb":[[2.82,3.7]],"id":5677052}],"con":true,"img":false}]}
{"op":"mcm","clk":"5322010513","pt":1646315392801,"mc":[{"id":"1.195532870","rc":[{"atb":[[2.4,0]],"id":43189003}],"con":true,"img":false}]}
{"op":"mcm","clk":"5322011072","pt":1646315399197,"mc":[{"id":"1.195532870","rc":[{"atb":[[2.44,0]],"id":43189003}],"con":true,"img":false}]}
{"op":"mcm","clk":"5322011796","pt":1646315406603,"mc":[{"id":"1.195532870","rc":[{"atb":[[2.76,0]],"id":5677052},{"atb":[[2.78,0]],"id":41793694}],"con":true,"img":false}]}
{"op":"mcm","clk":"5322011830","pt":1646315406917,"mc":[{"id":"1.195532870","rc":[{"atb":[[2.82,0]],"id":40214166},{"atb":[[2.88,0]],"id":40214168},{"atb":[[3.25,0]],"id":42931076}],"con":true,"img":false}]}
{"op":"mcm","clk":"5322013231","pt":1646315414817,"mc":[{"id":"1.195532870","rc":[{"atb":[[2.82,0]],"id":5677052},{"atb":[[2.84,0]],"id":41793694}],"con":true,"img":false}]}
{"op":"mcm","clk":"5322014029","pt":1646315420431,"mc":[{"id":"1.195532870","rc":[{"atb":[[2.4,4.8]],"id":43189003}],"con":true,"img":false}]}
{"op":"mcm","clk":"5322014350","pt":1646315422820,"mc":[{"id":"1.195532870","rc":[{"atb":[[2.9,6.53]],"id":40214166}],"con":true,"img":false}]}
{"op":"mcm","clk":"5322014382","pt":1646315423025,"mc":[{"id":"1.195532870","rc":[{"atb":[[2.96,6.33]],"id":40214168}],"con":true,"img":false}]}
{"op":"mcm","clk":"5322014397","pt":1646315423125,"mc":[{"id":"1.195532870","rc":[{"atb":[[3.45,5.06]],"id":42931076}],"con":true,"img":false}]}
{"op":"mcm","clk":"5322015716","pt":1646315436716,"mc":[{"id":"1.195532870","rc":[{"atb":[[2.74,3.86]],"id":41793694}],"con":true,"img":false}]}
{"op":"mcm","clk":"5322015738","pt":1646315436922,"mc":[{"id":"1.195532870","rc":[{"atb":[[2.72,3.9]],"id":5677052}],"con":true,"img":false}]}
{"op":"mcm","clk":"5322017834","pt":1646315455080,"mc":[{"id":"1.195532870","rc":[{"atb":[[2.44,6.88]],"id":43189003}],"con":true,"img":false}]}
{"op":"mcm","clk":"5322018938","pt":1646315462595,"mc":[{"id":"1.195532870","rc":[{"atb":[[2.4,0]],"id":43189003}],"con":true,"img":false}]}
{"op":"mcm","clk":"5322020655","pt":1646315482216,"mc":[{"id":"1.195532870","rc":[{"atb":[[2.44,0]],"id":43189003}],"con":true,"img":false}]}
{"op":"mcm","clk":"5322020674","pt":1646315482526,"mc":[{"id":"1.195532870","rc":[{"atb":[[2.78,5.57]],"id":5677052}],"con":true,"img":false}]}
{"op":"mcm","clk":"5322020694","pt":1646315482835,"mc":[{"id":"1.195532870","rc":[{"atb":[[2.8,5.51]],"id":41793694}],"con":true,"img":false}]}
{"op":"mcm","clk":"5322021247","pt":1646315489742,"mc":[{"id":"1.195532870","rc":[{"atb":[[2.72,0]],"id":5677052},{"atb":[[2.74,0]],"id":41793694}],"con":true,"img":false}]}
{"op":"mcm","clk":"5322021797","pt":1646315496925,"mc":[{"id":"1.195532870","rc":[{"atb":[[2.4,7.08]],"id":43189003}],"con":true,"img":false}]}
{"op":"mcm","clk":"5322021804","pt":1646315497029,"mc":[{"id":"1.195532870","rc":[{"atb":[[2.66,0]],"id":5677052},{"atb":[[2.68,0]],"id":41793694}],"con":true,"img":false}]}
{"op":"mcm","clk":"5322022903","pt":1646315510524,"mc":[{"id":"1.195532870","rc":[{"atb":[[2.78,0]],"id":5677052},{"atb":[[2.8,0]],"id":41793694}],"con":true,"img":false}]}
{"op":"mcm","clk":"5322022934","pt":1646315510835,"mc":[{"id":"1.195532870","rc":[{"atb":[[2.84,6.74]],"id":41793694}],"con":true,"img":false}]}
{"op":"mcm","clk":"5322022939","pt":1646315510940,"mc":[{"id":"1.195532870","rc":[{"atb":[[2.4,8.86]],"id":5677052}],"con":true,"img":false}]}
{"op":"mcm","clk":"5322024123","pt":1646315524366,"mc":[{"id":"1.195532870","rc":[{"atb":[[2.78,5.57]],"id":41793694}],"con":true,"img":false}]}
{"op":"mcm","clk":"5322024135","pt":1646315524472,"mc":[{"id":"1.195532870","rc":[{"atb":[[2.76,5.63]],"id":5677052}],"con":true,"img":false}]}
{"op":"mcm","clk":"5322024539","pt":1646315528787,"mc":[{"id":"1.195532870","rc":[{"atb":[[2.44,4.67]],"id":43189003}],"con":true,"img":false}]}
{"op":"mcm","clk":"5322025687","pt":1646315540648,"mc":[{"id":"1.195532870","rc":[{"atb":[[2.9,3.54]],"id":41793694}],"con":true,"img":false}]}
{"op":"mcm","clk":"5322026465","pt":1646315549628,"mc":[{"id":"1.195532870","rc":[{"atb":[[2.72,0]],"id":41793694}],"con":true,"img":false}]}
{"op":"mcm","clk":"5322026718","pt":1646315552733,"mc":[{"id":"1.195532870","rc":[{"atb":[[2.82,3.7]],"id":5677052}],"con":true,"img":false}]}
{"op":"mcm","clk":"5322026736","pt":1646315552949,"mc":[{"id":"1.195532870","rc":[{"atb":[[2.88,5.96]],"id":41793694}],"con":true,"img":false}]}
{"op":"mcm","clk":"5322026763","pt":1646315553357,"mc":[{"id":"1.195532870","rc":[{"atb":[[2.4,0]],"id":43189003}],"con":true,"img":false}]}
{"op":"mcm","clk":"5322027469","pt":1646315561774,"mc":[{"id":"1.195532870","rc":[{"atb":[[2.44,0]],"id":43189003}],"con":true,"img":false}]}
{"op":"mcm","clk":"5322027637","pt":1646315564159,"mc":[{"id":"1.195532870","rc":[{"atb":[[2.78,0]],"id":41793694}],"con":true,"img":false}]}
{"op":"mcm","clk":"5322028692","pt":1646315577490,"mc":[{"id":"1.195532870","rc":[{"atb":[[2.76,0]],"id":5677052}],"con":true,"img":false}]}
{"op":"mcm","clk":"5322029124","pt":1646315582782,"mc":[{"id":"1.195532870","rc":[{"atb":[[2.4,4.8]],"id":43189003}],"con":true,"img":false}]}
{"op":"mcm","clk":"5322029515","pt":1646315587571,"mc":[{"id":"1.195532870","rc":[{"atb":[[2.82,0]],"id":5677052}],"con":true,"img":false}]}
{"op":"mcm","clk":"5322029593","pt":1646315588698,"mc":[{"id":"1.195532870","rc":[{"atb":[[2.96,5.05]],"id":41793694}],"con":true,"img":false}]}
{"op":"mcm","clk":"5322030384","pt":1646315597812,"mc":[{"id":"1.195532870","rc":[{"atb":[[2.9,0]],"id":41793694}],"con":true,"img":false}]}
{"op":"mcm","clk":"5322031156","pt":1646315607113,"mc":[{"id":"1.195532870","rc":[{"atb":[[2.44,4.67]],"id":5677052}],"con":true,"img":false}]}
{"op":"mcm","clk":"5322032045","pt":1646315618596,"mc":[{"id":"1.195532870","rc":[{"atb":[[3,3.36]],"id":41793694}],"con":true,"img":false}]}
{"op":"mcm","clk":"5322032470","pt":1646315624307,"mc":[{"id":"1.195532870","rc":[{"atb":[[2.44,6.88]],"id":43189003}],"con":true,"img":false}]}
{"op":"mcm","clk":"5322032494","pt":1646315624618,"mc":[{"id":"1.195532870","rc":[{"atb":[[2.96,0]],"id":41793694}],"con":true,"img":false}]}
{"op":"mcm","clk":"5322033033","pt":1646315630710,"mc":[{"id":"1.195532870","rc":[{"atb":[[2.4,0]],"id":43189003}],"con":true,"img":false}]}
{"op":"mcm","clk":"5322033251","pt":1646315633804,"mc":[{"id":"1.195532870","rc":[{"atb":[[3,0]],"id":41793694}],"con":true,"img":false}]}
{"op":"mcm","clk":"5322033559","pt":1646315637942,"mc":[{"id":"1.195532870","rc":[{"atb":[[2.76,5.63]],"id":5677052}],"con":true,"img":false}]}
{"op":"mcm","clk":"5322033739","pt":1646315640022,"mc":[{"id":"1.195532870","rc":[{"atb":[[2.86,0]],"id":40214166},{"atb":[[2.92,0]],"id":40214168},{"atb":[[3.35,0]],"id":42931076}],"con":true,"img":false}]}
{"op":"mcm","clk":"5322033951","pt":1646315643031,"mc":[{"id":"1.195532870","rc":[{"atb":[[2.94,5.77]],"id":40214166},{"atb":[[3.55,4.39]],"id":42931076}],"con":true,"img":false}]}
{"op":"mcm","clk":"5322033957","pt":1646315643141,"mc":[{"id":"1.195532870","rc":[{"atb":[[3,5.6]],"id":40214168}],"con":true,"img":false}]}
{"op":"mcm","clk":"5322034188","pt":1646315646052,"mc":[{"id":"1.195532870","rc":[{"atb":[[2.44,0]],"id":5677052}],"con":true,"img":false}]}
{"op":"mcm","clk":"5322034683","pt":1646315651933,"mc":[{"id":"1.195532870","rc":[{"atb":[[2.44,0]],"id":43189003}],"con":true,"img":false}]}
{"op":"mcm","clk":"5322034764","pt":1646315652967,"mc":[{"id":"1.195532870","rc":[{"atb":[[2.9,3.54]],"id":41793694}],"con":true,"img":false}]}
{"op":"mcm","clk":"5322035830","pt":1646315665273,"mc":[{"id":"1.195532870","rc":[{"atb":[[2.4,7.08]],"id":43189003}],"con":true,"img":false}]}
{"op":"mcm","clk":"5322035964","pt":1646315666884,"mc":[{"id":"1.195532870","rc":[{"atb":[[2.82,3.7]],"id":5677052}],"con":true,"img":false}]}
{"op":"mcm","clk":"5322037777","pt":1646315689184,"mc":[{"id":"1.195532870","rc":[{"atb":[[2.76,0]],"id":5677052}],"con":true,"img":false}]}
{"op":"mcm","clk":"5322038144","pt":1646315694080,"mc":[{"id":"1.195532870","rc":[{"atb":[[2.44,4.67]],"id":43189003}],"con":true,"img":false}]}
{"op":"mcm","clk":"5322038324","pt":1646315696781,"mc":[{"id":"1.195532870","rc":[{"atb":[[2.82,0]],"id":5677052}],"con":true,"img":false}]}
{"op":"mcm","clk":"5322038683","pt":1646315701377,"mc":[{"id":"1.195532870","rc":[{"atb":[[2.96,5.05]],"id":41793694}],"con":true,"img":false}]}
{"op":"mcm","clk":"5322039423","pt":1646315708965,"mc":[{"id":"1.195532870","rc":[{"atb":[[2.9,0]],"id":41793694}],"con":true,"img":false}]}
{"op":"mcm","clk":"5322040196","pt":1646315717308,"mc":[{"id":"1.195532870","rc":[{"atb":[[2.4,0]],"id":43189003}],"con":true,"img":false}]}
{"op":"mcm","clk":"5322040261","pt":1646315717889,"mc":[{"id":"1.195532870","rc":[{"atb":[[2.44,4.67]],"id":5677052}],"con":true,"img":false}]}
{"op":"mcm","clk":"5322040915","pt":1646315724002,"mc":[{"id":"1.195532870","rc":[{"atb":[[2.44,0]],"id":43189003}],"con":true,"img":false}]}
{"op":"mcm","clk":"5322041522","pt":1646315730216,"mc":[{"id":"1.195532870","rc":[{"atb":[[3,3.36]],"id":41793694}],"con":true,"img":false}]}
{"op":"mcm","clk":"5322041644","pt":1646315731722,"mc":[{"id":"1.195532870","rc":[{"atb":[[2.96,0]],"id":41793694}],"con":true,"img":false}]}
{"op":"mcm","clk":"5322041656","pt":1646315731785,"mc":[{"id":"1.195532870","rc":[{"atb":[[2.76,5.63]],"id":5677052}],"con":true,"img":false}]}
{"op":"mcm","clk":"5322041780","pt":1646315732890,"mc":[{"id":"1.195532870","rc":[{"atb":[[2.7,0]],"id":5677052}],"con":true,"img":false}]}
{"op":"mcm","clk":"5322042069","pt":1646315735923,"mc":[{"id":"1.195532870","rc":[{"atb":[[2.44,12.46]],"id":5677052}],"con":true,"img":false}]}
{"op":"mcm","clk":"5322042376","pt":1646315739029,"mc":[{"id":"1.195532870","rc":[{"atb":[[2.44,7.79]],"id":5677052},{"atb":[[3,0]],"id":41793694}],"con":true,"img":false}]}
{"op":"mcm","clk":"5322042862","pt":1646315744921,"mc":[{"id":"1.195532870","rc":[{"atb":[[2.4,4.8]],"id":43189003}],"con":true,"img":false}]}
{"op":"mcm","clk":"5322043689","pt":1646315754840,"mc":[{"id":"1.195532870","rc":[{"atb":[[2.76,0]],"id":5677052}],"con":true,"img":false}]}
{"op":"mcm","clk":"5322043696","pt":1646315754941,"mc":[{"id":"1.195532870","rc":[{"atb":[[2.84,0]],"id":41793694}],"con":true,"img":false}]}
{"op":"mcm","clk":"5322044730","pt":1646315767321,"mc":[{"id":"1.195532870","rc":[{"atb":[[2.48,6.69]],"id":5677052},{"atb":[[2.94,5.11]],"id":41793694}],"con":true,"img":false}]}
{"op":"mcm","clk":"5322044758","pt":1646315767633,"mc":[{"id":"1.195532870","rc":[{"atb":[[2.36,9.13]],"id":41793694}],"con":true,"img":false}]}
{"op":"mcm","clk":"5322045916","pt":1646315780684,"mc":[{"id":"1.195532870","rc":[{"atb":[[2.44,6.88]],"id":43189003}],"con":true,"img":false}]}
{"op":"mcm","clk":"5322046703","pt":1646315790384,"mc":[{"id":"1.195532870","rc":[{"atb":[[2.4,0]],"id":43189003}],"con":true,"img":false}]}
{"op":"mcm","clk":"5322047185","pt":1646315796112,"mc":[{"id":"1.195532870","rc":[{"atb":[[2.52,4.42]],"id":5677052},{"atb":[[3,3.36]],"id":41793694}],"con":true,"img":false}]}
{"op":"mcm","clk":"5322047868","pt":1646315804024,"mc":[{"id":"1.195532870","rc":[{"atb":[[2.44,0]],"id":43189003}],"con":true,"img":false}]}
{"op":"mcm","clk":"5322049250","pt":1646315819927,"mc":[{"id":"1.195532870","rc":[{"atb":[[2.48,0]],"id":5677052},{"atb":[[2.94,0]],"id":41793694}],"con":true,"img":false}]}
{"op":"mcm","clk":"5322049265","pt":1646315820131,"mc":[{"id":"1.195532870","rc":[{"atb":[[2.4,7.08]],"id":43189003}],"con":true,"img":false}]}
{"op":"mcm","clk":"5322050135","pt":1646315829044,"mc":[{"id":"1.195532870","rc":[{"atb":[[2.52,0]],"id":5677052},{"atb":[[3,0]],"id":41793694}],"con":true,"img":false}]}
{"op":"mcm","clk":"5322052202","pt":1646315853676,"mc":[{"id":"1.195532870","rc":[{"atb":[[2.44,4.67]],"id":43189003}],"con":true,"img":false}]}
{"op":"mcm","clk":"5322052215","pt":1646315853776,"mc":[{"id":"1.195532870","rc":[{"atb":[[2.4,4.8]],"id":41793694}],"con":true,"img":false}]}
{"op":"mcm","clk":"5322052238","pt":1646315853979,"mc":[{"id":"1.195532870","rc":[{"atb":[[2.44,12.46]],"id":5677052}],"con":true,"img":false}]}
{"op":"mcm","clk":"5322052862","pt":1646315862586,"mc":[{"id":"1.195532870","rc":[{"atb":[[2.48,6.69]],"id":5677052}],"con":true,"img":false}]}
{"op":"mcm","clk":"5322052939","pt":1646315863475,"mc":[{"id":"1.195532870","rc":[{"atb":[[2.94,5.11]],"id":41793694}],"con":true,"img":false}]}
{"op":"mcm","clk":"5322052952","pt":1646315863688,"mc":[{"id":"1.195532870","rc":[{"atb":[[2.4,0]],"id":5677052}],"con":true,"img":false}]}
{"op":"mcm","clk":"5322053544","pt":1646315871498,"mc":[{"id":"1.195532870","rc":[{"atb":[[2.44,7.79]],"id":5677052},{"atb":[[2.4,0]],"id":41793694}],"con":true,"img":false}]}
{"op":"mcm","clk":"5322054408","pt":1646315882289,"mc":[{"id":"1.195532870","rc":[{"atb":[[2.9,0]],"id":40214166},{"atb":[[2.96,0]],"id":40214168},{"atb":[[2.4,0]],"id":43189003},{"atb":[[3.45,0]],"id":42931076}],"con":true,"img":false}]}
{"op":"mcm","clk":"5322054431","pt":1646315882601,"mc":[{"id":"1.195532870","rc":[{"atb":[[2.48,15.09]],"id":5677052}],"con":true,"img":false}]}
{"op":"mcm","clk":"5322054970","pt":1646315889786,"mc":[{"id":"1.195532870","rc":[{"atb":[[2.44,0]],"id":43189003}],"con":true,"img":false}]}
{"op":"mcm","clk":"5322055249","pt":1646315893076,"mc":[{"id":"1.195532870","rc":[{"atb":[[3,3.36]],"id":41793694}],"con":true,"img":false}]}
{"op":"mcm","clk":"5322055260","pt":1646315893185,"mc":[{"id":"1.195532870","rc":[{"atb":[[2.52,4.42]],"id":5677052}],"con":true,"img":false}]}
{"op":"mcm","clk":"5322055500","pt":1646315896312,"mc":[{"id":"1.195532870","rc":[{"atb":[[3.1,5.91]],"id":40214168}],"con":true,"img":false}]}
{"op":"mcm","clk":"5322055516","pt":1646315896521,"mc":[{"id":"1.195532870","rc":[{"atb":[[2.98,6.27]],"id":40214166}],"con":true,"img":false}]}
{"op":"mcm","clk":"5322055534","pt":1646315896678,"mc":[{"id":"1.195532870","rc":[{"atb":[[3.65,4.68]],"id":42931076}],"con":true,"img":false}]}
{"op":"mcm","clk":"5322056599","pt":1646315910502,"mc":[{"id":"1.195532870","rc":[{"atb":[[2.4,4.8]],"id":43189003}],"con":true,"img":false}]}
{"op":"mcm","clk":"5322056660","pt":1646315911334,"mc":[{"id":"1.195532870","rc":[{"atb":[[2.48,8.39]],"id":5677052},{"atb":[[2.94,0]],"id":41793694}],"con":true,"img":false}]}
{"op":"mcm","clk":"5322057203","pt":1646315919346,"mc":[{"id":"1.195532870","rc":[{"atb":[[3,0]],"id":41793694}],"con":true,"img":false}]}
{"op":"mcm","clk":"5322057739","pt":1646315926467,"mc":[{"id":"1.195532870","rc":[{"atb":[[2.58,6.28]],"id":5677052}],"con":true,"img":false}]}
{"op":"mcm","clk":"5322058547","pt":1646315937575,"mc":[{"id":"1.195532870","rc":[{"atb":[[2.52,0]],"id":5677052}],"con":true,"img":false}]}
{"op":"mcm","clk":"5322058790","pt":1646315940396,"mc":[{"id":"1.195532870","rc":[{"atb":[[2.4,4.8]],"id":41793694}],"con":true,"img":false}]}
{"op":"mcm","clk":"5322060127","pt":1646315955320,"mc":[{"id":"1.195532870","rc":[{"atb":[[2.64,4.1]],"id":5677052}],"con":true,"img":false}]}
{"op":"mcm","clk":"5322060230","pt":1646315956420,"mc":[{"id":"1.195532870","rc":[{"atb":[[2.58,0]],"id":5677052}],"con":true,"img":false}]}
{"op":"mcm","clk":"5322060237","pt":1646315956522,"mc":[{"id":"1.195532870","rc":[{"atb":[[2.44,6.88]],"id":43189003}],"con":true,"img":false}]}
{"op":"mcm","clk":"5322060250","pt":1646315956733,"mc":[{"id":"1.195532870","rc":[{"atb":[[2.94,5.11]],"id":41793694}],"con":true,"img":false}]}
{"op":"mcm","clk":"5322060985","pt":1646315964510,"mc":[{"id":"1.195532870","rc":[{"atb":[[2.64,0]],"id":5677052},{"atb":[[2.4,0]],"id":41793694},{"atb":[[2.4,0]],"id":43189003}],"con":true,"img":false}]}
{"op":"mcm","clk":"5322061429","pt":1646315969905,"mc":[{"id":"1.195532870","rc":[{"atb":[[2.48,15.09]],"id":5677052}],"con":true,"img":false}]}
{"op":"mcm","clk":"5322061477","pt":1646315970634,"mc":[{"id":"1.195532870","rc":[{"atb":[[2.44,0]],"id":5677052}],"con":true,"img":false}]}
{"op":"mcm","clk":"5322061664","pt":1646315973412,"mc":[{"id":"1.195532870","rc":[{"atb":[[2.52,7.37]],"id":5677052}],"con":true,"img":false}]}
{"op":"mcm","clk":"5322062480","pt":1646315982930,"mc":[{"id":"1.195532870","rc":[{"atb":[[2.44,0]],"id":43189003}],"con":true,"img":false}]}
{"op":"mcm","clk":"5322062665","pt":1646315985474,"mc":[{"id":"1.195532870","rc":[{"atb":[[2.52,11.8]],"id":5677052}],"con":true,"img":false}]}
{"op":"mcm","clk":"5322062674","pt":1646315985530,"mc":[{"id":"1.195532870","rc":[{"atb":[[3,3.36]],"id":41793694}],"con":true,"img":false}]}
{"op":"mcm","clk":"5322062924","pt":1646315988354,"mc":[{"id":"1.195532870","rc":[{"atb":[[2.88,0]],"id":41793694}],"con":true,"img":false}]}
{"op":"mcm","clk":"5322063367","pt":1646315991345,"mc":[{"id":"1.195532870","rc":[{"atb":[[2.4,8]],"id":41793694}],"con":true,"img":false}]}
{"op":"mcm","clk":"5322064009","pt":1646315995854,"mc":[{"id":"1.195532870","rc":[{"atb":[[2.48,8.39]],"id":5677052}],"con":true,"img":false}]}
{"op":"mcm","clk":"5322064044","pt":1646315996170,"mc":[{"id":"1.195532870","rc":[{"atb":[[2.4,7.08]],"id":43189003}],"con":true,"img":false}]}
{"op":"mcm","clk":"5322065475","pt":1646316007613,"mc":[{"id":"1.195532870","rc":[{"atb":[[2.94,0]],"id":41793694}],"con":true,"img":false}]}
{"op":"mcm","clk":"5322066176","pt":1646316015656,"mc":[{"id":"1.195532870","rc":[{"atb":[[3,0]],"id":41793694}],"con":true,"img":false}]}
{"op":"mcm","clk":"5322066727","pt":1646316020615,"mc":[{"id":"1.195532870","rc":[{"atb":[[2.58,6.28]],"id":5677052}],"con":true,"img":false}]}
{"op":"mcm","clk":"5322067088","pt":1646316024588,"mc":[{"id":"1.195532870","rc":[{"atb":[[2.44,4.67]],"id":43189003}],"con":true,"img":false}]}
{"op":"mcm","clk":"5322067395","pt":1646316027801,"mc":[{"id":"1.195532870","rc":[{"atb":[[2.52,7.37]],"id":5677052}],"con":true,"img":false}]}
{"op":"mcm","clk":"5322068163","pt":1646316036487,"mc":[{"id":"1.195532870","rc":[{"atb":[[2.4,12.81]],"id":41793694}],"con":true,"img":false}]}
{"op":"mcm","clk":"5322069204","pt":1646316048782,"mc":[{"id":"1.195532870","rc":[{"atb":[[2.64,4.1]],"id":5677052}],"con":true,"img":false}]}
{"op":"mcm","clk":"5322069257","pt":1646316049509,"mc":[{"id":"1.195532870","rc":[{"atb":[[2.44,6.88]],"id":41793694}],"con":true,"img":false}]}
{"op":"mcm","clk":"5322069276","pt":1646316049769,"mc":[{"id":"1.195532870","rc":[{"atb":[[2.4,0]],"id":43189003}],"con":true,"img":false}]}
{"op":"mcm","clk":"5322070183","pt":1646316060894,"mc":[{"id":"1.195532870","rc":[{"atb":[[2.4,8]],"id":41793694},{"atb":[[2.44,0]],"id":43189003}],"con":true,"img":false}]}
{"op":"mcm","clk":"5322071237","pt":1646316074149,"mc":[{"id":"1.195532870","rc":[{"atb":[[2.58,0]],"id":5677052}],"con":true,"img":false}]}
{"op":"mcm","clk":"5322071595","pt":1646316078716,"mc":[{"id":"1.195532870","rc":[{"atb":[[2.48,4.54]],"id":41793694}],"con":true,"img":false}]}
{"op":"mcm","clk":"5322071626","pt":1646316079026,"mc":[{"id":"1.195532870","rc":[{"atb":[[2.4,4.8]],"id":43189003}],"con":true,"img":false}]}
{"op":"mcm","clk":"5322071938","pt":1646316082207,"mc":[{"id":"1.195532870","rc":[{"atb":[[2.64,0]],"id":5677052}],"con":true,"img":false}]}
{"op":"mcm","clk":"5322074017","pt":1646316102852,"mc":[{"id":"1.195532870","rc":[{"atb":[[2.52,11.8]],"id":5677052},{"atb":[[2.44,0]],"id":41793694}],"con":true,"img":false}]}
{"op":"mcm","clk":"5322074060","pt":1646316103488,"mc":[{"id":"1.195532870","rc":[{"atb":[[2.36,0]],"id":41793694}],"con":true,"img":false}]}
{"op":"mcm","clk":"5322074810","pt":1646316111913,"mc":[{"id":"1.195532870","rc":[{"atb":[[2.48,0]],"id":41793694}],"con":true,"img":false}]}
{"op":"mcm","clk":"5322075117","pt":1646316115294,"mc":[{"id":"1.195532870","rc":[{"atb":[[2.94,0]],"id":40214166},{"atb":[[3,0]],"id":40214168},{"atb":[[3.55,0]],"id":42931076}],"con":true,"img":false}]}
{"op":"mcm","clk":"5322075364","pt":1646316117790,"mc":[{"id":"1.195532870","rc":[{"atb":[[3.05,5.47]],"id":40214166}],"con":true,"img":false}]}
{"op":"mcm","clk":"5322075376","pt":1646316117886,"mc":[{"id":"1.195532870","rc":[{"atb":[[3.2,5.09]],"id":40214168},{"atb":[[3.75,4.07]],"id":42931076}],"con":true,"img":false}]}
{"op":"mcm","clk":"5322075404","pt":1646316118095,"mc":[{"id":"1.195532870","rc":[{"atb":[[2.44,6.88]],"id":43189003}],"con":true,"img":false}]}
{"op":"mcm","clk":"5322075427","pt":1646316118304,"mc":[{"id":"1.195532870","rc":[{"atb":[[2.44,8.62]],"id":41793694}],"con":true,"img":false}]}
{"op":"mcm","clk":"5322075455","pt":1646316118614,"mc":[{"id":"1.195532870","rc":[{"atb":[[2.58,6.28]],"id":5677052}],"con":true,"img":false}]}
{"op":"mcm","clk":"5322076645","pt":1646316130132,"mc":[{"id":"1.195532870","rc":[{"atb":[[2.52,7.37]],"id":5677052},{"atb":[[2.4,0]],"id":43189003}],"con":true,"img":false}]}
{"op":"mcm","clk":"5322076813","pt":1646316131908,"mc":[{"id":"1.195532870","rc":[{"atb":[[2.48,0]],"id":5677052}],"con":true,"img":false}]}
{"op":"mcm","clk":"5322078088","pt":1646316147847,"mc":[{"id":"1.195532870","rc":[{"atb":[[2.64,4.1]],"id":5677052},{"atb":[[2.48,4.54]],"id":43189003}],"con":true,"img":false}]}
{"op":"mcm","clk":"5322078107","pt":1646316148013,"mc":[{"id":"1.195532870","rc":[{"atb":[[2.48,4.54]],"id":41793694}],"con":true,"img":false}]}
{"op":"mcm","clk":"5322078157","pt":1646316148542,"mc":[{"id":"1.195532870","rc":[{"atb":[[2.56,7.96]],"id":5677052}],"con":true,"img":false}]}
{"op":"mcm","clk":"5322078196","pt":1646316149050,"mc":[{"id":"1.195532870","rc":[{"atb":[[2.44,15.51]],"id":41793694},{"atb":[[2.44,0]],"id":43189003}],"con":true,"img":false}]}
{"op":"mcm","clk":"5322079248","pt":1646316161263,"mc":[{"id":"1.195532870","rc":[{"atb":[[2.48,0]],"id":43189003}],"con":true,"img":false}]}
{"op":"mcm","clk":"5322080435","pt":1646316173758,"mc":[{"id":"1.195532870","rc":[{"atb":[[2.58,0]],"id":5677052},{"atb":[[2.44,8.62]],"id":41793694}],"con":true,"img":false}]}
{"op":"mcm","clk":"5322081248","pt":1646316183781,"mc":[{"id":"1.195532870","rc":[{"atb":[[2.64,0]],"id":5677052}],"con":true,"img":false}]}
{"op":"mcm","clk":"5322081258","pt":1646316183882,"mc":[{"id":"1.195532870","rc":[{"atb":[[2.4,4.8]],"id":43189003}],"con":true,"img":false}]}
{"op":"mcm","clk":"5322082244","pt":1646316196902,"mc":[{"id":"1.195532870","rc":[{"atb":[[2.52,6.52]],"id":41793694}],"con":true,"img":false}]}
{"op":"mcm","clk":"5322082660","pt":1646316201934,"mc":[{"id":"1.195532870","rc":[{"atb":[[2.62,4.15]],"id":5677052}],"con":true,"img":false}]}
{"op":"mcm","clk":"5322082870","pt":1646316204745,"mc":[{"id":"1.195532870","rc":[{"atb":[[2.48,0]],"id":41793694}],"con":true,"img":false}]}
{"op":"mcm","clk":"5322084498","pt":1646316224263,"mc":[{"id":"1.195532870","rc":[{"atb":[[2.44,6.88]],"id":43189003}],"con":true,"img":false}]}
{"op":"mcm","clk":"5322084511","pt":1646316224461,"mc":[{"id":"1.195532870","rc":[{"atb":[[2.52,0]],"id":41793694}],"con":true,"img":false}]}
{"op":"mcm","clk":"5322085368","pt":1646316235043,"mc":[{"id":"1.195532870","rc":[{"atb":[[2.4,0]],"id":43189003}],"con":true,"img":false}]}
{"op":"mcm","clk":"5322085564","pt":1646316237663,"mc":[{"id":"1.195532870","rc":[{"atb":[[2.44,15.51]],"id":41793694}],"con":true,"img":false}]}
{"op":"mcm","clk":"5322085585","pt":1646316237969,"mc":[{"id":"1.195532870","rc":[{"atb":[[2.68,5.9]],"id":5677052}],"con":true,"img":false}]}
{"op":"mcm","clk":"5322086554","pt":1646316250265,"mc":[{"id":"1.195532870","rc":[{"atb":[[2.62,0]],"id":5677052}],"con":true,"img":false}]}
{"op":"mcm","clk":"5322086793","pt":1646316252885,"mc":[{"id":"1.195532870","rc":[{"atb":[[2.52,0]],"id":5677052}],"con":true,"img":false}]}
{"op":"mcm","clk":"5322086878","pt":1646316253774,"mc":[{"id":"1.195532870","rc":[{"atb":[[2.44,0]],"id":43189003}],"con":true,"img":false}]}
{"op":"mcm","clk":"5322087069","pt":1646316255907,"mc":[{"id":"1.195532870","rc":[{"atb":[[2.72,6.51]],"id":5677052}],"con":true,"img":false}]}
{"op":"mcm","clk":"5322087083","pt":1646316256018,"mc":[{"id":"1.195532870","rc":[{"atb":[[2.48,4.54]],"id":41793694}],"con":true,"img":false}]}
{"op":"mcm","clk":"5322087905","pt":1646316265012,"mc":[{"id":"1.195532870","rc":[{"atb":[[2.4,7.08]],"id":43189003}],"con":true,"img":false}]}
{"op":"mcm","clk":"5322087922","pt":1646316265230,"mc":[{"id":"1.195532870","rc":[{"atb":[[2.68,0]],"id":5677052}],"con":true,"img":false}]}
{"op":"mcm","clk":"5322088879","pt":1646316277014,"mc":[{"id":"1.195532870","rc":[{"atb":[[2.44,8.62]],"id":41793694}],"con":true,"img":false}]}
{"op":"mcm","clk":"5322089304","pt":1646316282914,"mc":[{"id":"1.195532870","rc":[{"atb":[[2.4,0]],"id":41793694}],"con":true,"img":false}]}
{"op":"mcm","clk":"5322089558","pt":1646316286251,"mc":[{"id":"1.195532870","rc":[{"atb":[[2.48,12.12]],"id":41793694}],"con":true,"img":false}]}
{"op":"mcm","clk":"5322089957","pt":1646316291046,"mc":[{"id":"1.195532870","rc":[{"atb":[[2.78,5.57]],"id":5677052},{"atb":[[2.52,6.52]],"id":41793694}],"con":true,"img":false}]}
{"op":"mcm","clk":"5322090380","pt":1646316296432,"mc":[{"id":"1.195532870","rc":[{"atb":[[2.44,4.67]],"id":43189003}],"con":true,"img":false}]}
{"op":"mcm","clk":"5322090814","pt":1646316301549,"mc":[{"id":"1.195532870","rc":[{"atb":[[2.48,7.58]],"id":41793694}],"con":true,"img":false}]}
{"op":"mcm","clk":"5322092414","pt":1646316318987,"mc":[{"id":"1.195532870","rc":[{"atb":[[2.4,0]],"id":43189003}],"con":true,"img":false}]}
{"op":"mcm","clk":"5322092504","pt":1646316320081,"mc":[{"id":"1.195532870","rc":[{"atb":[[2.84,3.65]],"id":5677052}],"con":true,"img":false}]}
{"op":"mcm","clk":"5322092589","pt":1646316321072,"mc":[{"id":"1.195532870","rc":[{"atb":[[2.58,4.26]],"id":41793694}],"con":true,"img":false}]}
{"op":"mcm","clk":"5322092998","pt":1646316325859,"mc":[{"id":"1.195532870","rc":[{"atb":[[2.44,0]],"id":43189003}],"con":true,"img":false}]}
{"op":"mcm","clk":"5322094907","pt":1646316346348,"mc":[{"id":"1.195532870","rc":[{"atb":[[2.4,4.8]],"id":43189003}],"con":true,"img":false}]}
{"op":"mcm","clk":"5322095327","pt":1646316350152,"mc":[{"id":"1.195532870","rc":[{"atb":[[2.98,0]],"id":40214166},{"atb":[[3.1,0]],"id":40214168},{"atb":[[3.65,0]],"id":42931076}],"con":true,"img":false}]}
{"op":"mcm","clk":"5322095354","pt":1646316350410,"mc":[{"id":"1.195532870","rc":[{"atb":[[2.78,0]],"id":5677052},{"atb":[[2.52,0]],"id":41793694}],"con":true,"img":false}]}
{"op":"mcm","clk":"5322096134","pt":1646316358256,"mc":[{"id":"1.195532870","rc":[{"atb":[[2.84,0]],"id":5677052},{"atb":[[2.58,0]],"id":41793694}],"con":true,"img":false}]}
{"op":"mcm","clk":"5322096956","pt":1646316365984,"mc":[{"id":"1.195532870","rc":[{"atb":[[3.15,5.77]],"id":40214166}],"con":true,"img":false}]}
{"op":"mcm","clk":"5322097001","pt":1646316366351,"mc":[{"id":"1.195532870","rc":[{"atb":[[3.85,4.35]],"id":42931076}],"con":true,"img":false}]}
{"op":"mcm","clk":"5322097036","pt":1646316366875,"mc":[{"id":"1.195532870","rc":[{"atb":[[3.3,5.39]],"id":40214168}],"con":true,"img":false}]}
{"op":"mcm","clk":"5322098448","pt":1646316380978,"mc":[{"id":"1.195532870","rc":[{"atb":[[2.44,6.88]],"id":43189003}],"con":true,"img":false}]}
{"op":"mcm","clk":"5322098588","pt":1646316382562,"mc":[{"id":"1.195532870","rc":[{"atb":[[2.62,4.15]],"id":5677052}],"con":true,"img":false}]}
{"op":"mcm","clk":"5322098627","pt":1646316382985,"mc":[{"id":"1.195532870","rc":[{"atb":[[2.48,12.12]],"id":41793694}],"con":true,"img":false}]}
{"op":"mcm","clk":"5322099107","pt":1646316388199,"mc":[{"id":"1.195532870","rc":[{"atb":[[2.4,0]],"id":43189003}],"con":true,"img":false}]}
{"op":"mcm","clk":"5322099900","pt":1646316396097,"mc":[{"id":"1.195532870","rc":[{"atb":[[2.56,0]],"id":5677052},{"atb":[[2.52,6.52],[2.44,0]],"id":41793694}],"con":true,"img":false}]}
{"op":"mcm","clk":"5322099924","pt":1646316396418,"mc":[{"id":"1.195532870","rc":[{"atb":[[2.78,5.57]],"id":5677052}],"con":true,"img":false}]}
{"op":"mcm","clk":"5322100596","pt":1646316403111,"mc":[{"id":"1.195532870","rc":[{"atb":[[2.62,0]],"id":5677052},{"atb":[[2.48,7.58]],"id":41793694}],"con":true,"img":false}]}
{"op":"mcm","clk":"5322101205","pt":1646316409366,"mc":[{"id":"1.195532870","rc":[{"atb":[[2.48,4.54]],"id":43189003}],"con":true,"img":false}]}
{"op":"mcm","clk":"5322101599","pt":1646316413254,"mc":[{"id":"1.195532870","rc":[{"atb":[[2.4,8.86]],"id":5677052},{"atb":[[2.44,0]],"id":43189003}],"con":true,"img":false}]}
{"op":"mcm","clk":"5322101638","pt":1646316413562,"mc":[{"id":"1.195532870","rc":[{"atb":[[2.52,14.69]],"id":41793694}],"con":true,"img":false}]}
{"op":"mcm","clk":"5322102351","pt":1646316421165,"mc":[{"id":"1.195532870","rc":[{"atb":[[2.48,0]],"id":43189003}],"con":true,"img":false}]}
{"op":"mcm","clk":"5322102954","pt":1646316427383,"mc":[{"id":"1.195532870","rc":[{"atb":[[2.84,3.65]],"id":5677052}],"con":true,"img":false}]}
{"op":"mcm","clk":"5322102973","pt":1646316427551,"mc":[{"id":"1.195532870","rc":[{"atb":[[2.58,4.26]],"id":41793694}],"con":true,"img":false}]}
{"op":"mcm","clk":"5322104547","pt":1646316442697,"mc":[{"id":"1.195532870","rc":[{"atb":[[2.4,4.8]],"id":43189003}],"con":true,"img":false}]}
{"op":"mcm","clk":"5322105806","pt":1646316457032,"mc":[{"id":"1.195532870","rc":[{"atb":[[2.78,0]],"id":5677052},{"atb":[[2.52,8.17]],"id":41793694}],"con":true,"img":false}]}
{"op":"mcm","clk":"5322106825","pt":1646316468023,"mc":[{"id":"1.195532870","rc":[{"atb":[[2.64,6.05]],"id":41793694}],"con":true,"img":false}]}
{"op":"mcm","clk":"5322106849","pt":1646316468340,"mc":[{"id":"1.195532870","rc":[{"atb":[[2.9,5.22]],"id":5677052}],"con":true,"img":false}]}
{"op":"mcm","clk":"5322106939","pt":1646316469337,"mc":[{"id":"1.195532870","rc":[{"atb":[[2.84,0]],"id":5677052}],"con":true,"img":false}]}
{"op":"mcm","clk":"5322107544","pt":1646316475556,"mc":[{"id":"1.195532870","rc":[{"atb":[[2.58,0]],"id":41793694}],"con":true,"img":false}]}
{"op":"mcm","clk":"5322108124","pt":1646316482068,"mc":[{"id":"1.195532870","rc":[{"atb":[[2.44,6.88]],"id":43189003}],"con":true,"img":false}]}
{"op":"mcm","clk":"5322108874","pt":1646316490277,"mc":[{"id":"1.195532870","rc":[{"atb":[[2.4,0]],"id":43189003}],"con":true,"img":false}]}
{"op":"mcm","clk":"5322109265","pt":1646316494593,"mc":[{"id":"1.195532870","rc":[{"atb":[[2.9,0]],"id":5677052},{"atb":[[2.64,0]],"id":41793694}],"con":true,"img":false}]}
{"op":"mcm","clk":"5322109703","pt":1646316499367,"mc":[{"id":"1.195532870","rc":[{"atb":[[2.72,0]],"id":5677052}],"con":true,"img":false}]}
{"op":"mcm","clk":"5322109956","pt":1646316502367,"mc":[{"id":"1.195532870","rc":[{"atb":[[2.44,7.79]],"id":5677052}],"con":true,"img":false}]}
{"op":"mcm","clk":"5322110449","pt":1646316507083,"mc":[{"id":"1.195532870","rc":[{"atb":[[2.44,0]],"id":43189003}],"con":true,"img":false}]}
{"op":"mcm","clk":"5322111512","pt":1646316519001,"mc":[{"id":"1.195532870","rc":[{"atb":[[2.52,14.69]],"id":41793694}],"con":true,"img":false}]}
{"op":"mcm","clk":"5322111884","pt":1646316523417,"mc":[{"id":"1.195532870","rc":[{"atb":[[2.58,4.26]],"id":41793694}],"con":true,"img":false}]}
{"op":"mcm","clk":"5322111893","pt":1646316523522,"mc":[{"id":"1.195532870","rc":[{"atb":[[2.44,12.46]],"id":5677052},{"atb":[[2.48,0]],"id":41793694}],"con":true,"img":false}]}
{"op":"mcm","clk":"5322112409","pt":1646316529421,"mc":[{"id":"1.195532870","rc":[{"atb":[[2.56,7.19]],"id":41793694}],"con":true,"img":false}]}
{"op":"mcm","clk":"5322112625","pt":1646316531807,"mc":[{"id":"1.195532870","rc":[{"atb":[[2.4,7.08]],"id":43189003}],"con":true,"img":false}]}
{"op":"mcm","clk":"5322113763","pt":1646316546238,"mc":[{"id":"1.195532870","rc":[{"atb":[[2.48,6.69]],"id":5677052}],"con":true,"img":false}]}
{"op":"mcm","clk":"5322113774","pt":1646316546343,"mc":[{"id":"1.195532870","rc":[{"atb":[[2.52,8.17]],"id":41793694}],"con":true,"img":false}]}
{"op":"mcm","clk":"5322114465","pt":1646316553754,"mc":[{"id":"1.195532870","rc":[{"atb":[[2.44,7.79]],"id":5677052}],"con":true,"img":false}]}
{"op":"mcm","clk":"5322114921","pt":1646316559073,"mc":[{"id":"1.195532870","rc":[{"atb":[[2.64,6.05]],"id":41793694}],"con":true,"img":false}]}
{"op":"mcm","clk":"5322114984","pt":1646316559756,"mc":[{"id":"1.195532870","rc":[{"atb":[[2.44,4.67]],"id":43189003}],"con":true,"img":false}]}
{"op":"mcm","clk":"5322115520","pt":1646316565672,"mc":[{"id":"1.195532870","rc":[{"atb":[[2.58,0]],"id":41793694}],"con":true,"img":false}]}
{"op":"mcm","clk":"5322116322","pt":1646316574789,"mc":[{"id":"1.195532870","rc":[{"atb":[[2.52,4.42]],"id":5677052}],"con":true,"img":false}]}
{"op":"mcm","clk":"5322117091","pt":1646316583670,"mc":[{"id":"1.195532870","rc":[{"atb":[[3.05,0]],"id":40214166},{"atb":[[3.2,0]],"id":40214168},{"atb":[[3.75,0]],"id":42931076}],"con":true,"img":false}]}
{"op":"mcm","clk":"5322117406","pt":1646316587108,"mc":[{"id":"1.195532870","rc":[{"atb":[[3.4,4.67]],"id":40214168}],"con":true,"img":false}]}
{"op":"mcm","clk":"5322117430","pt":1646316587274,"mc":[{"id":"1.195532870","rc":[{"atb":[[3.95,3.79]],"id":42931076}],"con":true,"img":false}]}
{"op":"mcm","clk":"5322117443","pt":1646316587380,"mc":[{"id":"1.195532870","rc":[{"atb":[[2.7,3.95]],"id":41793694}],"con":true,"img":false}]}
{"op":"mcm","clk":"5322117450","pt":1646316587481,"mc":[{"id":"1.195532870","rc":[{"atb":[[3.25,4.98]],"id":40214166}],"con":true,"img":false}]}
{"op":"mcm","clk":"5322117557","pt":1646316588682,"mc":[{"id":"1.195532870","rc":[{"atb":[[2.64,0]],"id":41793694},{"atb":[[2.4,0]],"id":43189003}],"con":true,"img":false}]}
{"op":"mcm","clk":"5322118252","pt":1646316596088,"mc":[{"id":"1.195532870","rc":[{"atb":[[2.7,0]],"id":41793694},{"atb":[[2.44,0]],"id":43189003}],"con":true,"img":false}]}
{"op":"mcm","clk":"5322118761","pt":1646316601708,"mc":[{"id":"1.195532870","rc":[{"atb":[[2.62,6.12]],"id":41793694}],"con":true,"img":false}]}
{"op":"mcm","clk":"5322118787","pt":1646316601918,"mc":[{"id":"1.195532870","rc":[{"atb":[[2.48,0]],"id":5677052}],"con":true,"img":false}]}
{"op":"mcm","clk":"5322119949","pt":1646316614219,"mc":[{"id":"1.195532870","rc":[{"atb":[[2.52,0]],"id":5677052}],"con":true,"img":false}]}
{"op":"mcm","clk":"5322120228","pt":1646316617316,"mc":[{"id":"1.195532870","rc":[{"atb":[[2.4,4.8]],"id":43189003}],"con":true,"img":false}]}
{"op":"mcm","clk":"5322121334","pt":1646316629836,"mc":[{"id":"1.195532870","rc":[{"atb":[[2.68,4]],"id":41793694}],"con":true,"img":false}]}
{"op":"mcm","clk":"5322121805","pt":1646316635014,"mc":[{"id":"1.195532870","rc":[{"atb":[[2.44,12.46]],"id":5677052}],"con":true,"img":false}]}
{"op":"mcm","clk":"5322123438","pt":1646316653650,"mc":[{"id":"1.195532870","rc":[{"atb":[[2.48,6.69]],"id":5677052},{"atb":[[2.62,0]],"id":41793694}],"con":true,"img":false}]}
{"op":"mcm","clk":"5322123471","pt":1646316653971,"mc":[{"id":"1.195532870","rc":[{"atb":[[2.44,6.88]],"id":43189003}],"con":true,"img":false}]}
{"op":"mcm","clk":"5322124233","pt":1646316662174,"mc":[{"id":"1.195532870","rc":[{"atb":[[2.44,7.79]],"id":5677052},{"atb":[[2.68,0]],"id":41793694},{"atb":[[2.4,0]],"id":43189003}],"con":true,"img":false}]}
{"op":"mcm","clk":"5322125948","pt":1646316679109,"mc":[{"id":"1.195532870","rc":[{"atb":[[2.52,0]],"id":41793694},{"atb":[[2.44,0]],"id":43189003}],"con":true,"img":false}]}
{"op":"mcm","clk":"5322126357","pt":1646316682923,"mc":[{"id":"1.195532870","rc":[{"atb":[[2.52,4.42]],"id":5677052}],"con":true,"img":false}]}
{"op":"mcm","clk":"5322127340","pt":1646316692521,"mc":[{"id":"1.195532870","rc":[{"atb":[[2.6,7.76]],"id":41793694}],"con":true,"img":false}]}
{"op":"mcm","clk":"5322128439","pt":1646316703837,"mc":[{"id":"1.195532870","rc":[{"atb":[[2.48,0]],"id":5677052},{"atb":[[2.62,6.12]],"id":41793694}],"con":true,"img":false}]}
{"op":"mcm","clk":"5322128462","pt":1646316704153,"mc":[{"id":"1.195532870","rc":[{"atb":[[2.4,7.08]],"id":43189003}],"con":true,"img":false}]}
{"op":"mcm","clk":"5322129297","pt":1646316712766,"mc":[{"id":"1.195532870","rc":[{"atb":[[2.52,0]],"id":5677052}],"con":true,"img":false}]}
{"op":"mcm","clk":"5322131403","pt":1646316733846,"mc":[{"id":"1.195532870","rc":[{"atb":[[2.68,4]],"id":41793694}],"con":true,"img":false}]}
{"op":"mcm","clk":"5322131411","pt":1646316733953,"mc":[{"id":"1.195532870","rc":[{"atb":[[2.44,12.46]],"id":5677052}],"con":true,"img":false}]}
{"op":"mcm","clk":"5322131429","pt":1646316734162,"mc":[{"id":"1.195532870","rc":[{"atb":[[2.44,4.67]],"id":43189003}],"con":true,"img":false}]}
{"op":"mcm","clk":"5322131849","pt":1646316738371,"mc":[{"id":"1.195532870","rc":[{"atb":[[2.4,0]],"id":5677052}],"con":true,"img":false}]}
{"op":"mcm","clk":"5322132807","pt":1646316749688,"mc":[{"id":"1.195532870","rc":[{"atb":[[2.62,0]],"id":41793694},{"atb":[[2.4,0]],"id":43189003}],"con":true,"img":false}]}
{"op":"mcm","clk":"5322132831","pt":1646316749998,"mc":[{"id":"1.195532870","rc":[{"atb":[[2.48,6.69]],"id":5677052}],"con":true,"img":false}]}
{"op":"mcm","clk":"5322132883","pt":1646316750589,"mc":[{"id":"1.195532870","rc":[{"atb":[[2.48,15.09]],"id":5677052}],"con":true,"img":false}]}
{"op":"mcm","clk":"5322133008","pt":1646316751904,"mc":[{"id":"1.195532870","rc":[{"atb":[[2.44,7.79]],"id":5677052}],"con":true,"img":false}]}
{"op":"mcm","clk":"5322133506","pt":1646316758092,"mc":[{"id":"1.195532870","rc":[{"atb":[[2.68,0]],"id":41793694},{"atb":[[2.44,0]],"id":43189003}],"con":true,"img":false}]}
{"op":"mcm","clk":"5322135274","pt":1646316779451,"mc":[{"id":"1.195532870","rc":[{"atb":[[2.52,4.42]],"id":5677052},{"atb":[[2.4,4.8]],"id":43189003}],"con":true,"img":false}]}
{"op":"mcm","clk":"5322135289","pt":1646316779660,"mc":[{"id":"1.195532870","rc":[{"atb":[[2.44,0]],"id":5677052},{"atb":[[2.66,4.05]],"id":41793694}],"con":true,"img":false}]}
{"op":"mcm","clk":"5322135489","pt":1646316782082,"mc":[{"id":"1.195532870","rc":[{"atb":[[2.52,11.8]],"id":5677052}],"con":true,"img":false}]}
{"op":"mcm","clk":"5322136208","pt":1646316790989,"mc":[{"id":"1.195532870","rc":[{"atb":[[2.56,0]],"id":41793694}],"con":true,"img":false}]}
{"op":"mcm","clk":"5322136442","pt":1646316794025,"mc":[{"id":"1.195532870","rc":[{"atb":[[2.64,6.84]],"id":41793694}],"con":true,"img":false}]}
{"op":"mcm","clk":"5322142236","pt":1646316861875,"mc":[{"id":"1.195532870","rc":[{"atb":[[3.15,0]],"id":40214166},{"atb":[[3.3,0]],"id":40214168},{"atb":[[3.85,0]],"id":42931076}],"con":true,"img":false}]}
{"op":"mcm","clk":"5322144136","pt":1646316882345,"mc":[{"id":"1.195532870","rc":[{"atb":[[4.1,4]],"id":42931076}],"con":true,"img":false}]}
{"op":"mcm","clk":"5322144150","pt":1646316882556,"mc":[{"id":"1.195532870","rc":[{"atb":[[2.48,8.39]],"id":5677052}],"con":true,"img":false}]}
{"op":"mcm","clk":"5322144163","pt":1646316882661,"mc":[{"id":"1.195532870","rc":[{"atb":[[3.35,5.28]],"id":40214166}],"con":true,"img":false}]}
{"op":"mcm","clk":"5322144175","pt":1646316882867,"mc":[{"id":"1.195532870","rc":[{"atb":[[3.5,4.96]],"id":40214168}],"con":true,"img":false}]}
{"op":"mcm","clk":"5322146248","pt":1646316905397,"mc":[{"id":"1.195532870","rc":[{"atb":[[2.72,5.76]],"id":41793694}],"con":true,"img":false}]}
{"op":"mcm","clk":"5322146261","pt":1646316905563,"mc":[{"id":"1.195532870","rc":[{"atb":[[2.58,6.28]],"id":5677052}],"con":true,"img":false}]}
{"op":"mcm","clk":"5322146288","pt":1646316905874,"mc":[{"id":"1.195532870","rc":[{"atb":[[2.44,6.88]],"id":43189003}],"con":true,"img":false}]}
{"op":"mcm","clk":"5322147068","pt":1646316914459,"mc":[{"id":"1.195532870","rc":[{"atb":[[2.52,7.37]],"id":5677052},{"atb":[[2.66,0]],"id":41793694},{"atb":[[2.4,0]],"id":43189003}],"con":true,"img":false}]}
{"op":"mcm","clk":"5322148963","pt":1646316935528,"mc":[{"id":"1.195532870","rc":[{"atb":[[2.48,4.54]],"id":43189003}],"con":true,"img":false}]}
{"op":"mcm","clk":"5322148972","pt":1646316935632,"mc":[{"id":"1.195532870","rc":[{"atb":[[2.64,4.1]],"id":5677052},{"atb":[[2.78,3.78]],"id":41793694}],"con":true,"img":false}]}
{"op":"mcm","clk":"5322159643","pt":1646317056268,"mc":[{"id":"1.195532870","rc":[{"atb":[[2.6,0]],"id":41793694}],"con":true,"img":false}]}
{"op":"mcm","clk":"5322159727","pt":1646317057162,"mc":[{"id":"1.195532870","rc":[{"atb":[[2.72,0]],"id":41793694},{"atb":[[2.44,0]],"id":43189003}],"con":true,"img":false}]}
{"op":"mcm","clk":"5322160467","pt":1646317065357,"mc":[{"id":"1.195532870","rc":[{"atb":[[2.78,0]],"id":41793694},{"atb":[[2.48,0]],"id":43189003}],"con":true,"img":false}]}
{"op":"mcm","clk":"5322161127","pt":1646317072363,"mc":[{"id":"1.195532870","rc":[{"atb":[[2.58,0]],"id":5677052}],"con":true,"img":false}]}
{"op":"mcm","clk":"5322161155","pt":1646317072680,"mc":[{"id":"1.195532870","rc":[{"atb":[[2.68,7.39]],"id":41793694}],"con":true,"img":false}]}
{"op":"mcm","clk":"5322161870","pt":1646317079879,"mc":[{"id":"1.195532870","rc":[{"atb":[[2.64,0]],"id":5677052}],"con":true,"img":false}]}
{"op":"mcm","clk":"5322162414","pt":1646317086095,"mc":[{"id":"1.195532870","rc":[{"atb":[[2.4,4.8]],"id":43189003}],"con":true,"img":false}]}
{"op":"mcm","clk":"5322163538","pt":1646317098177,"mc":[{"id":"1.195532870","rc":[{"atb":[[2.48,0]],"id":5677052},{"atb":[[2.7,5.82]],"id":41793694}],"con":true,"img":false}]}
{"op":"mcm","clk":"5322163547","pt":1646317098275,"mc":[{"id":"1.195532870","rc":[{"atb":[[3.25,0]],"id":40214166},{"atb":[[3.4,0]],"id":40214168},{"atb":[[3.95,0]],"id":42931076}],"con":true,"img":false}]}
{"op":"mcm","clk":"5322163854","pt":1646317101788,"mc":[{"id":"1.195532870","rc":[{"atb":[[3.6,4.31]],"id":40214168}],"con":true,"img":false}]}
{"op":"mcm","clk":"5322163889","pt":1646317102204,"mc":[{"id":"1.195532870","rc":[{"atb":[[3.45,4.57]],"id":40214166}],"con":true,"img":false}]}
{"op":"mcm","clk":"5322163898","pt":1646317102310,"mc":[{"id":"1.195532870","rc":[{"atb":[[4.3,3.4]],"id":42931076}],"con":true,"img":false}]}
{"op":"mcm","clk":"5322164943","pt":1646317114207,"mc":[{"id":"1.195532870","rc":[{"atb":[[2.58,6.28]],"id":5677052}],"con":true,"img":false}]}
{"op":"mcm","clk":"5322164965","pt":1646317114522,"mc":[{"id":"1.195532870","rc":[{"atb":[[2.56,7.96]],"id":5677052}],"con":true,"img":false}]}
{"op":"mcm","clk":"5322165946","pt":1646317126745,"mc":[{"id":"1.195532870","rc":[{"atb":[[2.44,6.88]],"id":43189003}],"con":true,"img":false}]}
{"op":"mcm","clk":"5322166070","pt":1646317128058,"mc":[{"id":"1.195532870","rc":[{"atb":[[2.76,3.82]],"id":41793694}],"con":true,"img":false}]}
{"op":"mcm","clk":"5322166494","pt":1646317133976,"mc":[{"id":"1.195532870","rc":[{"atb":[[2.4,0]],"id":43189003}],"con":true,"img":false}]}
{"op":"mcm","clk":"5322167111","pt":1646317140886,"mc":[{"id":"1.195532870","rc":[{"atb":[[2.52,0]],"id":5677052},{"atb":[[2.64,0]],"id":41793694}],"con":true,"img":false}]}
{"op":"mcm","clk":"5322167433","pt":1646317143158,"mc":[{"id":"1.195532870","rc":[{"atb":[[2.64,4.1],[2.62,6.92]],"id":5677052}],"con":true,"img":false}]}
{"op":"mcm","clk":"5322167449","pt":1646317143367,"mc":[{"id":"1.195532870","rc":[{"atb":[[2.74,6.44]],"id":41793694}],"con":true,"img":false}]}
{"op":"mcm","clk":"5322168400","pt":1646317151183,"mc":[{"id":"1.195532870","rc":[{"atb":[[2.7,0]],"id":41793694},{"atb":[[2.44,0]],"id":43189003}],"con":true,"img":false}]}
{"op":"mcm","clk":"5322169024","pt":1646317158095,"mc":[{"id":"1.195532870","rc":[{"atb":[[2.76,0]],"id":41793694}],"con":true,"img":false}]}
{"op":"mcm","clk":"5322169931","pt":1646317168630,"mc":[{"id":"1.195532870","rc":[{"atb":[[2.58,0]],"id":5677052}],"con":true,"img":false}]}
{"op":"mcm","clk":"5322169964","pt":1646317169015,"mc":[{"id":"1.195532870","rc":[{"atb":[[2.4,7.08]],"id":43189003}],"con":true,"img":false}]}
{"op":"mcm","clk":"5322170543","pt":1646317176093,"mc":[{"id":"1.195532870","rc":[{"atb":[[2.64,0]],"id":5677052}],"con":true,"img":false}]}
{"op":"mcm","clk":"5322170841","pt":1646317179334,"mc":[{"id":"1.195532870","rc":[{"atb":[[2.74,10.3]],"id":41793694}],"con":true,"img":false}]}
{"op":"mcm","clk":"5322172412","pt":1646317197163,"mc":[{"id":"1.195532870","rc":[{"atb":[[2.44,4.67]],"id":43189003}],"con":true,"img":false}]}
{"op":"mcm","clk":"5322172433","pt":1646317197372,"mc":[{"id":"1.195532870","rc":[{"atb":[[2.62,11.07]],"id":5677052}],"con":true,"img":false}]}
{"op":"mcm","clk":"5322172977","pt":1646317203152,"mc":[{"id":"1.195532870","rc":[{"atb":[[2.8,5.51]],"id":41793694}],"con":true,"img":false}]}
{"op":"mcm","clk":"5322173994","pt":1646317215255,"mc":[{"id":"1.195532870","rc":[{"atb":[[2.4,0]],"id":43189003}],"con":true,"img":false}]}
{"op":"mcm","clk":"5322174005","pt":1646317215361,"mc":[{"id":"1.195532870","rc":[{"atb":[[2.68,5.9]],"id":5677052},{"atb":[[2.74,6.44]],"id":41793694}],"con":true,"img":false}]}
{"op":"mcm","clk":"5322174793","pt":1646317224166,"mc":[{"id":"1.195532870","rc":[{"atb":[[2.62,6.92]],"id":5677052},{"atb":[[2.44,0]],"id":43189003}],"con":true,"img":false}]}
{"op":"mcm","clk":"5322175884","pt":1646317236087,"mc":[{"id":"1.195532870","rc":[{"atb":[[2.86,3.61]],"id":41793694}],"con":true,"img":false}]}
{"op":"mcm","clk":"5322176643","pt":1646317245304,"mc":[{"id":"1.195532870","rc":[{"atb":[[2.4,4.8]],"id":43189003}],"con":true,"img":false}]}
{"op":"mcm","clk":"5322176649","pt":1646317245409,"mc":[{"id":"1.195532870","rc":[{"atb":[[2.74,3.86]],"id":5677052}],"con":true,"img":false}]}
{"op":"mcm","clk":"5322177094","pt":1646317251391,"mc":[{"id":"1.195532870","rc":[{"atb":[[2.8,0]],"id":41793694}],"con":true,"img":false}]}
{"op":"mcm","clk":"5322177735","pt":1646317260196,"mc":[{"id":"1.195532870","rc":[{"atb":[[2.86,0]],"id":41793694}],"con":true,"img":false}]}
{"op":"mcm","clk":"5322177742","pt":1646317260351,"mc":[{"id":"1.195532870","rc":[{"atb":[[2.68,0]],"id":5677052}],"con":true,"img":false}]}
{"op":"mcm","clk":"5322178553","pt":1646317269352,"mc":[{"id":"1.195532870","rc":[{"atb":[[2.74,0]],"id":5677052}],"con":true,"img":false}]}
{"op":"mcm","clk":"5322179381","pt":1646317278966,"mc":[{"id":"1.195532870","rc":[{"atb":[[2.44,6.88]],"id":43189003}],"con":true,"img":false}]}
{"op":"mcm","clk":"5322179601","pt":1646317281468,"mc":[{"id":"1.195532870","rc":[{"atb":[[2.74,10.3]],"id":41793694}],"con":true,"img":false}]}
{"op":"mcm","clk":"5322180124","pt":1646317287362,"mc":[{"id":"1.195532870","rc":[{"atb":[[2.4,0]],"id":43189003}],"con":true,"img":false}]}
{"op":"mcm","clk":"5322180391","pt":1646317290741,"mc":[{"id":"1.195532870","rc":[{"atb":[[2.62,11.07]],"id":5677052}],"con":true,"img":false}]}
{"op":"mcm","clk":"5322181399","pt":1646317302991,"mc":[{"id":"1.195532870","rc":[{"atb":[[2.44,0]],"id":43189003}],"con":true,"img":false}]}
{"op":"mcm","clk":"5322181417","pt":1646317303201,"mc":[{"id":"1.195532870","rc":[{"atb":[[2.8,5.51]],"id":41793694}],"con":true,"img":false}]}
{"op":"mcm","clk":"5322182225","pt":1646317311400,"mc":[{"id":"1.195532870","rc":[{"atb":[[2.74,6.44]],"id":41793694}],"con":true,"img":false}]}
{"op":"mcm","clk":"5322182498","pt":1646317314541,"mc":[{"id":"1.195532870","rc":[{"atb":[[2.68,5.9]],"id":5677052}],"con":true,"img":false}]}
{"op":"mcm","clk":"5322183256","pt":1646317323537,"mc":[{"id":"1.195532870","rc":[{"atb":[[2.62,6.92]],"id":5677052}],"con":true,"img":false}]}
{"op":"mcm","clk":"5322183532","pt":1646317326471,"mc":[{"id":"1.195532870","rc":[{"atb":[[2.4,7.08]],"id":43189003}],"con":true,"img":false}]}
{"op":"mcm","clk":"5322184177","pt":1646317333060,"mc":[{"id":"1.195532870","rc":[{"atb":[[2.86,3.61]],"id":41793694}],"con":true,"img":false}]}
{"op":"mcm","clk":"5322185293","pt":1646317345072,"mc":[{"id":"1.195532870","rc":[{"atb":[[2.74,3.86]],"id":5677052}],"con":true,"img":false}]}
{"op":"mcm","clk":"5322186087","pt":1646317353499,"mc":[{"id":"1.195532870","rc":[{"atb":[[2.8,0]],"id":41793694}],"con":true,"img":false}]}
{"op":"mcm","clk":"5322186134","pt":1646317354014,"mc":[{"id":"1.195532870","rc":[{"atb":[[3.35,0]],"id":40214166},{"atb":[[3.5,0]],"id":40214168},{"atb":[[4.1,0]],"id":42931076}],"con":true,"img":false}]}
{"op":"mcm","clk":"5322186348","pt":1646317356532,"mc":[{"id":"1.195532870","rc":[{"atb":[[2.44,4.67]],"id":43189003}],"con":true,"img":false}]}
{"op":"mcm","clk":"5322187146","pt":1646317365031,"mc":[{"id":"1.195532870","rc":[{"atb":[[2.86,0]],"id":41793694}],"con":true,"img":false}]}
{"op":"mcm","clk":"5322187532","pt":1646317369141,"mc":[{"id":"1.195532870","rc":[{"atb":[[2.68,0]],"id":5677052}],"con":true,"img":false}]}
{"op":"mcm","clk":"5322187555","pt":1646317369304,"mc":[{"id":"1.195532870","rc":[{"atb":[[2.68,0]],"id":41793694}],"con":true,"img":false}]}
{"op":"mcm","clk":"5322187567","pt":1646317369409,"mc":[{"id":"1.195532870","rc":[{"atb":[[3.55,4.86]],"id":40214166}],"con":true,"img":false}]}
{"op":"mcm","clk":"5322187597","pt":1646317369716,"mc":[{"id":"1.195532870","rc":[{"atb":[[3.7,4.6]],"id":40214168}],"con":true,"img":false}]}
{"op":"mcm","clk":"5322187643","pt":1646317370148,"mc":[{"id":"1.195532870","rc":[{"atb":[[4.5,3.55]],"id":42931076}],"con":true,"img":false}]}
{"op":"mcm","clk":"5322188331","pt":1646317377714,"mc":[{"id":"1.195532870","rc":[{"atb":[[2.74,0]],"id":5677052}],"con":true,"img":false}]}
{"op":"mcm","clk":"5322188933","pt":1646317383837,"mc":[{"id":"1.195532870","rc":[{"atb":[[2.74,0]],"id":41793694}],"con":true,"img":false}]}
{"op":"mcm","clk":"5322189193","pt":1646317386920,"mc":[{"id":"1.195532870","rc":[{"atb":[[2.36,8.24]],"id":41793694}],"con":true,"img":false}]}
{"op":"mcm","clk":"5322189211","pt":1646317387134,"mc":[{"id":"1.195532870","rc":[{"atb":[[2.4,0]],"id":43189003}],"con":true,"img":false}]}
{"op":"mcm","clk":"5322189232","pt":1646317387339,"mc":[{"id":"1.195532870","rc":[{"atb":[[2.56,0]],"id":5677052}],"con":true,"img":false}]}
{"op":"mcm","clk":"5322189242","pt":1646317387445,"mc":[{"id":"1.195532870","rc":[{"atb":[[2.36,17.37]],"id":41793694}],"con":true,"img":false}]}
{"op":"mcm","clk":"5322189992","pt":1646317395673,"mc":[{"id":"1.195532870","rc":[{"atb":[[2.44,0]],"id":43189003}],"con":true,"img":false}]}
{"op":"mcm","clk":"5322190569","pt":1646317401654,"mc":[{"id":"1.195532870","rc":[{"atb":[[2.66,7.48],[2.62,0]],"id":5677052}],"con":true,"img":false}]}
{"op":"mcm","clk":"5322190847","pt":1646317404685,"mc":[{"id":"1.195532870","rc":[{"atb":[[2.7,6.59]],"id":5677052}],"con":true,"img":false}]}
{"op":"mcm","clk":"5322191974","pt":1646317416583,"mc":[{"id":"1.195532870","rc":[{"atb":[[2.4,4.8]],"id":43189003}],"con":true,"img":false}]}
{"op":"mcm","clk":"5322191998","pt":1646317416788,"mc":[{"id":"1.195532870","rc":[{"atb":[[2.4,4.8]],"id":41793694}],"con":true,"img":false}]}
{"op":"mcm","clk":"5322193329","pt":1646317431969,"mc":[{"id":"1.195532870","rc":[{"atb":[[2.72,3.9]],"id":5677052}],"con":true,"img":false}]}
{"op":"mcm","clk":"5322195861","pt":1646317459766,"mc":[{"id":"1.195532870","rc":[{"atb":[[2.44,6.88]],"id":41793694}],"con":true,"img":false}]}
{"op":"mcm","clk":"5322195870","pt":1646317459871,"mc":[{"id":"1.195532870","rc":[{"atb":[[2.44,6.88]],"id":43189003}],"con":true,"img":false}]}
{"op":"mcm","clk":"5322196613","pt":1646317467733,"mc":[{"id":"1.195532870","rc":[{"atb":[[2.4,0]],"id":41793694},{"atb":[[2.4,0]],"id":43189003}],"con":true,"img":false}]}
{"op":"mcm","clk":"5322196946","pt":1646317471774,"mc":[{"id":"1.195532870","rc":[{"atb":[[2.78,5.57]],"id":5677052}],"con":true,"img":false}]}
{"op":"mcm","clk":"5322197672","pt":1646317479790,"mc":[{"id":"1.195532870","rc":[{"atb":[[2.72,0]],"id":5677052}],"con":true,"img":false}]}
{"op":"mcm","clk":"5322198058","pt":1646317483807,"mc":[{"id":"1.195532870","rc":[{"atb":[[2.44,0]],"id":41793694},{"atb":[[2.44,0]],"id":43189003}],"con":true,"img":false}]}
{"op":"mcm","clk":"5322199226","pt":1646317495932,"mc":[{"id":"1.195532870","rc":[{"atb":[[2.78,0]],"id":5677052}],"con":true,"img":false}]}
{"op":"mcm","clk":"5322200321","pt":1646317507838,"mc":[{"id":"1.195532870","rc":[{"atb":[[2.4,7.08]],"id":43189003}],"con":true,"img":false}]}
{"op":"mcm","clk":"5322200353","pt":1646317508107,"mc":[{"id":"1.195532870","rc":[{"atb":[[2.4,7.08]],"id":41793694}],"con":true,"img":false}]}
{"op":"mcm","clk":"5322201482","pt":1646317520439,"mc":[{"id":"1.195532870","rc":[{"atb":[[2.76,5.63]],"id":5677052}],"con":true,"img":false}]}
{"op":"mcm","clk":"5322202978","pt":1646317537012,"mc":[{"id":"1.195532870","rc":[{"atb":[[2.44,4.67]],"id":41793694}],"con":true,"img":false}]}
{"op":"mcm","clk":"5322203007","pt":1646317537275,"mc":[{"id":"1.195532870","rc":[{"atb":[[2.44,4.67]],"id":43189003}],"con":true,"img":false}]}
{"op":"mcm","clk":"5322204119","pt":1646317549007,"mc":[{"id":"1.195532870","rc":[{"atb":[[2.82,3.7]],"id":5677052}],"con":true,"img":false}]}
{"op":"mcm","clk":"5322204742","pt":1646317556041,"mc":[{"id":"1.195532870","rc":[{"atb":[[2.4,0]],"id":41793694},{"atb":[[2.4,0]],"id":43189003}],"con":true,"img":false}]}
{"op":"mcm","clk":"5322205514","pt":1646317564061,"mc":[{"id":"1.195532870","rc":[{"atb":[[2.44,0]],"id":41793694},{"atb":[[2.44,0]],"id":43189003}],"con":true,"img":false}]}
{"op":"mcm","clk":"5322205944","pt":1646317568363,"mc":[{"id":"1.195532870","rc":[{"atb":[[2.76,0]],"id":5677052}],"con":true,"img":false}]}
{"op":"mcm","clk":"5322206633","pt":1646317576062,"mc":[{"id":"1.195532870","rc":[{"atb":[[2.82,0]],"id":5677052}],"con":true,"img":false}]}
{"op":"mcm","clk":"5322207561","pt":1646317585780,"mc":[{"id":"1.195532870","rc":[{"atb":[[2.4,4.8]],"id":41793694},{"atb":[[2.4,4.8]],"id":43189003}],"con":true,"img":false}]}
{"op":"mcm","clk":"5322207777","pt":1646317588050,"mc":[{"id":"1.195532870","rc":[{"atb":[[3.45,0]],"id":40214166},{"atb":[[3.6,0]],"id":40214168},{"atb":[[4.3,0]],"id":42931076}],"con":true,"img":false}]}
{"op":"mcm","clk":"5322208075","pt":1646317591280,"mc":[{"id":"1.195532870","rc":[{"atb":[[3.8,4]],"id":40214168}],"con":true,"img":false}]}
{"op":"mcm","clk":"5322208120","pt":1646317591875,"mc":[{"id":"1.195532870","rc":[{"atb":[[3.65,4.23]],"id":40214166}],"con":true,"img":false}]}
{"op":"mcm","clk":"5322208195","pt":1646317592481,"mc":[{"id":"1.195532870","rc":[{"atb":[[4.7,3.02]],"id":42931076}],"con":true,"img":false}]}
{"op":"mcm","clk":"5322208758","pt":1646317597903,"mc":[{"id":"1.195532870","rc":[{"atb":[[2.72,3.9]],"id":5677052}],"con":true,"img":false}]}
{"op":"mcm","clk":"5322211349","pt":1646317625047,"mc":[{"id":"1.195532870","rc":[{"atb":[[2.36,9.13]],"id":41793694}],"con":true,"img":false}]}
{"op":"mcm","clk":"5322211561","pt":1646317627344,"mc":[{"id":"1.195532870","rc":[{"atb":[[2.4,12.81]],"id":41793694}],"con":true,"img":false}]}
{"op":"mcm","clk":"5322211659","pt":1646317628337,"mc":[{"id":"1.195532870","rc":[{"atb":[[2.44,6.88]],"id":43189003}],"con":true,"img":false}]}
{"op":"mcm","clk":"5322211677","pt":1646317628545,"mc":[{"id":"1.195532870","rc":[{"atb":[[2.44,6.88]],"id":41793694}],"con":true,"img":false}]}
{"op":"mcm","clk":"5322212482","pt":1646317636973,"mc":[{"id":"1.195532870","rc":[{"atb":[[2.4,8]],"id":41793694},{"atb":[[2.4,0]],"id":43189003}],"con":true,"img":false}]}
{"op":"mcm","clk":"5322212909","pt":1646317640695,"mc":[{"id":"1.195532870","rc":[{"atb":[[2.78,5.57]],"id":5677052}],"con":true,"img":false}]}
{"op":"mcm","clk":"5322212931","pt":1646317640853,"mc":[{"id":"1.195532870","rc":[{"atb":[[2.36,0]],"id":41793694}],"con":true,"img":false}]}
{"op":"mcm","clk":"5322213656","pt":1646317648096,"mc":[{"id":"1.195532870","rc":[{"atb":[[2.72,0]],"id":5677052}],"con":true,"img":false}]}
{"op":"mcm","clk":"5322214037","pt":1646317652208,"mc":[{"id":"1.195532870","rc":[{"atb":[[2.44,0]],"id":43189003}],"con":true,"img":false}]}
{"op":"mcm","clk":"5322214049","pt":1646317652313,"mc":[{"id":"1.195532870","rc":[{"atb":[[2.44,15.51]],"id":41793694}],"con":true,"img":false}]}
{"op":"mcm","clk":"5322214072","pt":1646317652483,"mc":[{"id":"1.195532870","rc":[{"atb":[[2.66,0]],"id":5677052}],"con":true,"img":false}]}
{"op":"mcm","clk":"5322214599","pt":1646317657890,"mc":[{"id":"1.195532870","rc":[{"atb":[[2.48,4.54]],"id":41793694}],"con":true,"img":false}]}
{"op":"mcm","clk":"5322215161","pt":1646317664178,"mc":[{"id":"1.195532870","rc":[{"atb":[[2.78,0]],"id":5677052}],"con":true,"img":false}]}
{"op":"mcm","clk":"5322215195","pt":1646317664493,"mc":[{"id":"1.195532870","rc":[{"atb":[[2.4,8.86]],"id":5677052}],"con":true,"img":false}]}
{"op":"mcm","clk":"5322216475","pt":1646317676735,"mc":[{"id":"1.195532870","rc":[{"atb":[[2.44,8.62]],"id":41793694}],"con":true,"img":false}]}
{"op":"mcm","clk":"5322216484","pt":1646317676842,"mc":[{"id":"1.195532870","rc":[{"atb":[[2.4,7.08]],"id":43189003}],"con":true,"img":false}]}
{"op":"mcm","clk":"5322217685","pt":1646317688715,"mc":[{"id":"1.195532870","rc":[{"atb":[[2.76,5.63]],"id":5677052}],"con":true,"img":false}]}
{"op":"mcm","clk":"5322218731","pt":1646317700248,"mc":[{"id":"1.195532870","rc":[{"atb":[[2.52,6.52]],"id":41793694}],"con":true,"img":false}]}
{"op":"mcm","clk":"5322219183","pt":1646317705283,"mc":[{"id":"1.195532870","rc":[{"atb":[[2.44,4.67]],"id":43189003}],"con":true,"img":false}]}
{"op":"mcm","clk":"5322219463","pt":1646317708277,"mc":[{"id":"1.195532870","rc":[{"atb":[[2.48,0]],"id":41793694}],"con":true,"img":false}]}
{"op":"mcm","clk":"5322220301","pt":1646317717186,"mc":[{"id":"1.195532870","rc":[{"atb":[[2.82,3.7]],"id":5677052}],"con":true,"img":false}]}
{"op":"mcm","clk":"5322220970","pt":1646317724295,"mc":[{"id":"1.195532870","rc":[{"atb":[[2.52,0]],"id":41793694},{"atb":[[2.4,0]],"id":43189003}],"con":true,"img":false}]}
{"op":"mcm","clk":"5322221781","pt":1646317733317,"mc":[{"id":"1.195532870","rc":[{"atb":[[2.44,0]],"id":43189003}],"con":true,"img":false}]}
{"op":"mcm","clk":"5322222087","pt":1646317736414,"mc":[{"id":"1.195532870","rc":[{"atb":[[2.76,0]],"id":5677052}],"con":true,"img":false}]}
{"op":"mcm","clk":"5322222793","pt":1646317744353,"mc":[{"id":"1.195532870","rc":[{"atb":[[2.82,0]],"id":5677052}],"con":true,"img":false}]}
{"op":"mcm","clk":"5322223159","pt":1646317748425,"mc":[{"id":"1.195532870","rc":[{"atb":[[2.44,15.51]],"id":41793694}],"con":true,"img":false}]}
{"op":"mcm","clk":"5322223581","pt":1646317753337,"mc":[{"id":"1.195532870","rc":[{"atb":[[2.48,4.54]],"id":41793694}],"con":true,"img":false}]}
{"op":"mcm","clk":"5322223592","pt":1646317753445,"mc":[{"id":"1.195532870","rc":[{"atb":[[2.4,4.8]],"id":43189003}],"con":true,"img":false}]}
{"op":"mcm","clk":"5322224641","pt":1646317765379,"mc":[{"id":"1.195532870","rc":[{"atb":[[2.44,4.67]],"id":5677052}],"con":true,"img":false}]}
{"op":"mcm","clk":"5322225312","pt":1646317773196,"mc":[{"id":"1.195532870","rc":[{"atb":[[2.44,8.62]],"id":41793694}],"con":true,"img":false}]}
{"op":"mcm","clk":"5322226523","pt":1646317787571,"mc":[{"id":"1.195532870","rc":[{"atb":[[2.44,6.88]],"id":43189003}],"con":true,"img":false}]}
{"op":"mcm","clk":"5322226541","pt":1646317787780,"mc":[{"id":"1.195532870","rc":[{"atb":[[2.52,6.52]],"id":41793694}],"con":true,"img":false}]}
{"op":"mcm","clk":"5322226576","pt":1646317788091,"mc":[{"id":"1.195532870","rc":[{"atb":[[2.76,5.63]],"id":5677052}],"con":true,"img":false}]}
{"op":"mcm","clk":"5322227199","pt":1646317795512,"mc":[{"id":"1.195532870","rc":[{"atb":[[2.44,0]],"id":5677052},{"atb":[[2.48,0]],"id":41793694},{"atb":[[2.4,0]],"id":43189003}],"con":true,"img":false}]}
{"op":"mcm","clk":"5322228702","pt":1646317811633,"mc":[{"id":"1.195532870","rc":[{"atb":[[2.52,0]],"id":41793694},{"atb":[[2.44,0]],"id":43189003}],"con":true,"img":false}]}
{"op":"mcm","clk":"5322229067","pt":1646317815548,"mc":[{"id":"1.195532870","rc":[{"atb":[[2.82,3.7]],"id":5677052}],"con":true,"img":false}]}
{"op":"mcm","clk":"5322230112","pt":1646317826661,"mc":[{"id":"1.195532870","rc":[{"atb":[[2.4,7.08]],"id":43189003}],"con":true,"img":false}]}
{"op":"mcm","clk":"5322230140","pt":1646317826939,"mc":[{"id":"1.195532870","rc":[{"atb":[[3.55,0]],"id":40214166},{"atb":[[3.7,0]],"id":40214168},{"atb":[[4.5,0]],"id":42931076}],"con":true,"img":false}]}
{"op":"mcm","clk":"5322230176","pt":1646317827343,"mc":[{"id":"1.195532870","rc":[{"atb":[[2.44,15.51]],"id":41793694}],"con":true,"img":false}]}
{"op":"mcm","clk":"5322231531","pt":1646317841079,"mc":[{"id":"1.195532870","rc":[{"atb":[[2.48,4.54]],"id":41793694}],"con":true,"img":false}]}
{"op":"mcm","clk":"5322231679","pt":1646317842504,"mc":[{"id":"1.195532870","rc":[{"atb":[[3.75,4.51]],"id":40214166},{"atb":[[3.9,4.28]],"id":40214168}],"con":true,"img":false}]}
{"op":"mcm","clk":"5322231704","pt":1646317842802,"mc":[{"id":"1.195532870","rc":[{"atb":[[2.76,0]],"id":5677052}],"con":true,"img":false}]}
{"op":"mcm","clk":"5322232345","pt":1646317849819,"mc":[{"id":"1.195532870","rc":[{"atb":[[2.82,0]],"id":5677052}],"con":true,"img":false}]}
{"op":"mcm","clk":"5322232965","pt":1646317856095,"mc":[{"id":"1.195532870","rc":[{"atb":[[2.44,4.67]],"id":43189003}],"con":true,"img":false}]}
{"op":"mcm","clk":"5322233060","pt":1646317857214,"mc":[{"id":"1.195532870","rc":[{"atb":[[2.44,8.62]],"id":41793694}],"con":true,"img":false}]}
{"op":"mcm","clk":"5322233574","pt":1646317862802,"mc":[{"id":"1.195532870","rc":[{"atb":[[2.4,0]],"id":41793694}],"con":true,"img":false}]}
{"op":"mcm","clk":"5322234057","pt":1646317869050,"mc":[{"id":"1.195532870","rc":[{"atb":[[2.48,12.12]],"id":41793694}],"con":true,"img":false}]}
{"op":"mcm","clk":"5322234297","pt":1646317871319,"mc":[{"id":"1.195532870","rc":[{"atb":[[2.44,4.67]],"id":5677052}],"con":true,"img":false}]}
{"op":"mcm","clk":"5322234359","pt":1646317872111,"mc":[{"id":"1.195532870","rc":[{"atb":[[2.4,0]],"id":43189003}],"con":true,"img":false}]}
{"op":"mcm","clk":"5322234373","pt":1646317872316,"mc":[{"id":"1.195532870","rc":[{"atb":[[2.52,6.52]],"id":41793694}],"con":true,"img":false}]}
{"op":"mcm","clk":"5322235005","pt":1646317880434,"mc":[{"id":"1.195532870","rc":[{"atb":[[2.48,7.58]],"id":41793694},{"atb":[[2.44,0]],"id":43189003}],"con":true,"img":false}]}
{"op":"mcm","clk":"5322235528","pt":1646317886116,"mc":[{"id":"1.195532870","rc":[{"atb":[[2.7,0]],"id":5677052}],"con":true,"img":false}]}
{"op":"mcm","clk":"5322235765","pt":1646317889046,"mc":[{"id":"1.195532870","rc":[{"atb":[[2.44,12.46]],"id":5677052}],"con":true,"img":false}]}
{"op":"mcm","clk":"5322236745","pt":1646317900671,"mc":[{"id":"1.195532870","rc":[{"atb":[[2.58,4.26]],"id":41793694}],"con":true,"img":false}]}
{"op":"mcm","clk":"5322236755","pt":1646317900733,"mc":[{"id":"1.195532870","rc":[{"atb":[[2.4,4.8]],"id":43189003}],"con":true,"img":false}]}
{"op":"mcm","clk":"5322236874","pt":1646317902042,"mc":[{"id":"1.195532870","rc":[{"atb":[[2.44,0]],"id":41793694}],"con":true,"img":false}]}
{"op":"mcm","clk":"5322237865","pt":1646317913859,"mc":[{"id":"1.195532870","rc":[{"atb":[[2.52,0]],"id":41793694}],"con":true,"img":false}]}
{"op":"mcm","clk":"5322237893","pt":1646317914172,"mc":[{"id":"1.195532870","rc":[{"atb":[[2.62,7.66]],"id":41793694}],"con":true,"img":false}]}
{"op":"mcm","clk":"5322238594","pt":1646317921693,"mc":[{"id":"1.195532870","rc":[{"atb":[[2.58,0]],"id":41793694}],"con":true,"img":false}]}
{"op":"mcm","clk":"5322239039","pt":1646317926465,"mc":[{"id":"1.195532870","rc":[{"atb":[[2.48,6.69]],"id":5677052}],"con":true,"img":false}]}
{"op":"mcm","clk":"5322239695","pt":1646317934177,"mc":[{"id":"1.195532870","rc":[{"atb":[[2.44,7.79]],"id":5677052}],"con":true,"img":false}]}
{"op":"mcm","clk":"5322240043","pt":1646317938289,"mc":[{"id":"1.195532870","rc":[{"atb":[[2.44,6.88]],"id":43189003}],"con":true,"img":false}]}
{"op":"mcm","clk":"5322240406","pt":1646317943111,"mc":[{"id":"1.195532870","rc":[{"atb":[[2.68,4]],"id":41793694}],"con":true,"img":false}]}
{"op":"mcm","clk":"5322240658","pt":1646317945790,"mc":[{"id":"1.195532870","rc":[{"atb":[[2.4,0]],"id":43189003}],"con":true,"img":false}]}
{"op":"mcm","clk":"5322241307","pt":1646317954718,"mc":[{"id":"1.195532870","rc":[{"atb":[[2.52,4.42]],"id":5677052}],"con":true,"img":false}]}
{"op":"mcm","clk":"5322241815","pt":1646317961949,"mc":[{"id":"1.195532870","rc":[{"atb":[[2.44,0]],"id":43189003}],"con":true,"img":false}]}
{"op":"mcm","clk":"5322242705","pt":1646317974056,"mc":[{"id":"1.195532870","rc":[{"atb":[[2.48,0]],"id":5677052}],"con":true,"img":false}]}
{"op":"mcm","clk":"5322243354","pt":1646317982029,"mc":[{"id":"1.195532870","rc":[{"atb":[[2.52,0]],"id":5677052}],"con":true,"img":false}]}
{"op":"mcm","clk":"5322243694","pt":1646317986041,"mc":[{"id":"1.195532870","rc":[{"atb":[[2.4,7.08]],"id":43189003}],"con":true,"img":false}]}
{"op":"mcm","clk":"5322243707","pt":1646317986147,"mc":[{"id":"1.195532870","rc":[{"atb":[[2.74,5.69]],"id":41793694}],"con":true,"img":false}]}
{"op":"mcm","clk":"5322244280","pt":1646317994051,"mc":[{"id":"1.195532870","rc":[{"atb":[[2.68,0]],"id":41793694}],"con":true,"img":false}]}
{"op":"mcm","clk":"5322244934","pt":1646318003158,"mc":[{"id":"1.195532870","rc":[{"atb":[[2.44,12.46]],"id":5677052}],"con":true,"img":false}]}
{"op":"mcm","clk":"5322245462","pt":1646318010779,"mc":[{"id":"1.195532870","rc":[{"atb":[[2.74,0]],"id":41793694}],"con":true,"img":false}]}
{"op":"mcm","clk":"5322245478","pt":1646318011098,"mc":[{"id":"1.195532870","rc":[{"atb":[[2.4,0]],"id":5677052}],"con":true,"img":false}]}
{"op":"mcm","clk":"5322245595","pt":1646318012879,"mc":[{"id":"1.195532870","rc":[{"atb":[[2.44,4.67]],"id":43189003}],"con":true,"img":false}]}
{"op":"mcm","clk":"5322245984","pt":1646318017897,"mc":[{"id":"1.195532870","rc":[{"atb":[[2.44,7.79]],"id":5677052}],"con":true,"img":false}]}
{"op":"mcm","clk":"5322246383","pt":1646318022490,"mc":[{"id":"1.195532870","rc":[{"atb":[[2.48,6.69]],"id":5677052}],"con":true,"img":false}]}
{"op":"mcm","clk":"5322246392","pt":1646318022597,"mc":[{"id":"1.195532870","rc":[{"atb":[[2.48,15.09]],"id":5677052}],"con":true,"img":false}]}
{"op":"mcm","clk":"5322247389","pt":1646318034231,"mc":[{"id":"1.195532870","rc":[{"atb":[[2.4,0]],"id":43189003}],"con":true,"img":false}]}
{"op":"mcm","clk":"5322247398","pt":1646318034336,"mc":[{"id":"1.195532870","rc":[{"atb":[[2.52,6.52]],"id":41793694}],"con":true,"img":false}]}
{"op":"mcm","clk":"5322247776","pt":1646318038931,"mc":[{"id":"1.195532870","rc":[{"atb":[[2.68,4]],"id":41793694}],"con":true,"img":false}]}
{"op":"mcm","clk":"5322248048","pt":1646318042637,"mc":[{"id":"1.195532870","rc":[{"atb":[[2.44,0]],"id":43189003}],"con":true,"img":false}]}
{"op":"mcm","clk":"5322248701","pt":1646318051064,"mc":[{"id":"1.195532870","rc":[{"atb":[[2.52,4.42]],"id":5677052}],"con":true,"img":false}]}
{"op":"mcm","clk":"5322249349","pt":1646318060072,"mc":[{"id":"1.195532870","rc":[{"atb":[[3.65,0]],"id":40214166},{"atb":[[3.8,0]],"id":40214168},{"atb":[[4.7,0]],"id":42931076}],"con":true,"img":false}]}
{"op":"mcm","clk":"5322249566","pt":1646318062781,"mc":[{"id":"1.195532870","rc":[{"atb":[[2.9,6.53]],"id":42931076}],"con":true,"img":false}]}
{"op":"mcm","clk":"5322249576","pt":1646318062835,"mc":[{"id":"1.195532870","rc":[{"atb":[[2.52,0]],"id":41793694}],"con":true,"img":false}]}
{"op":"mcm","clk":"5322249658","pt":1646318063879,"mc":[{"id":"1.195532870","rc":[{"atb":[[3.85,3.93]],"id":40214166}],"con":true,"img":false}]}
{"op":"mcm","clk":"5322249662","pt":1646318063931,"mc":[{"id":"1.195532870","rc":[{"atb":[[4,3.73]],"id":40214168},{"atb":[[2.4,4.8]],"id":43189003}],"con":true,"img":false}]}
{"op":"mcm","clk":"5322249673","pt":1646318064044,"mc":[{"id":"1.195532870","rc":[{"atb":[[2.9,12.43]],"id":42931076}],"con":true,"img":false}]}
{"op":"mcm","clk":"5322250643","pt":1646318077260,"mc":[{"id":"1.195532870","rc":[{"atb":[[2.48,8.39]],"id":5677052}],"con":true,"img":false}]}
{"op":"mcm","clk":"5322250669","pt":1646318077690,"mc":[{"id":"1.195532870","rc":[{"atb":[[2.74,5.69]],"id":41793694}],"con":true,"img":false}]}
{"op":"mcm","clk":"5322251498","pt":1646318087015,"mc":[{"id":"1.195532870","rc":[{"atb":[[2.68,0]],"id":41793694}],"con":true,"img":false}]}
{"op":"mcm","clk":"5322251897","pt":1646318091998,"mc":[{"id":"1.195532870","rc":[{"atb":[[2.58,6.28]],"id":5677052}],"con":true,"img":false}]}
{"op":"mcm","clk":"5322252556","pt":1646318099615,"mc":[{"id":"1.195532870","rc":[{"atb":[[2.52,0]],"id":5677052}],"con":true,"img":false}]}
{"op":"mcm","clk":"5322253057","pt":1646318105700,"mc":[{"id":"1.195532870","rc":[{"atb":[[2.48,0]],"id":41793694}],"con":true,"img":false}]}
{"op":"mcm","clk":"5322253173","pt":1646318107218,"mc":[{"id":"1.195532870","rc":[{"atb":[[2.74,0]],"id":41793694}],"con":true,"img":false}]}
{"op":"mcm","clk":"5322253186","pt":1646318107323,"mc":[{"id":"1.195532870","rc":[{"atb":[[2.44,6.88]],"id":43189003}],"con":true,"img":false}]}
{"op":"mcm","clk":"5322253264","pt":1646318108419,"mc":[{"id":"1.195532870","rc":[{"atb":[[2.66,6.75]],"id":41793694}],"con":true,"img":false}]}
{"op":"mcm","clk":"5322253693","pt":1646318114205,"mc":[{"id":"1.195532870","rc":[{"atb":[[2.4,0]],"id":43189003}],"con":true,"img":false}]}
{"op":"mcm","clk":"5322254088","pt":1646318119146,"mc":[{"id":"1.195532870","rc":[{"atb":[[2.58,0]],"id":5677052}],"con":true,"img":false}]}
{"op":"mcm","clk":"5322255135","pt":1646318130862,"mc":[{"id":"1.195532870","rc":[{"atb":[[2.44,0]],"id":43189003}],"con":true,"img":false}]}
{"op":"mcm","clk":"5322255441","pt":1646318134844,"mc":[{"id":"1.195532870","rc":[{"atb":[[2.68,4]],"id":41793694}],"con":true,"img":false}]}
{"op":"mcm","clk":"5322256098","pt":1646318142974,"mc":[{"id":"1.195532870","rc":[{"atb":[[2.48,15.09]],"id":5677052}],"con":true,"img":false}]}
{"op":"mcm","clk":"5322256545","pt":1646318148600,"mc":[{"id":"1.195532870","rc":[{"atb":[[2.52,4.42]],"id":5677052}],"con":true,"img":false}]}
{"op":"mcm","clk":"5322257162","pt":1646318155972,"mc":[{"id":"1.195532870","rc":[{"atb":[[2.4,7.08]],"id":43189003}],"con":true,"img":false}]}
{"op":"mcm","clk":"5322257458","pt":1646318159585,"mc":[{"id":"1.195532870","rc":[{"atb":[[2.44,0]],"id":5677052}],"con":true,"img":false}]}
{"op":"mcm","clk":"5322257712","pt":1646318162313,"mc":[{"id":"1.195532870","rc":[{"atb":[[2.52,11.8]],"id":5677052}],"con":true,"img":false}]}
{"op":"mcm","clk":"5322258383","pt":1646318170085,"mc":[{"id":"1.195532870","rc":[{"atb":[[2.74,5.69]],"id":41793694}],"con":true,"img":false}]}
{"op":"mcm","clk":"5322258392","pt":1646318170189,"mc":[{"id":"1.195532870","rc":[{"atb":[[2.62,0]],"id":41793694}],"con":true,"img":false}]}
{"op":"mcm","clk":"5322258419","pt":1646318170506,"mc":[{"id":"1.195532870","rc":[{"atb":[[2.48,8.39]],"id":5677052}],"con":true,"img":false}]}
{"op":"mcm","clk":"5322258907","pt":1646318177113,"mc":[{"id":"1.195532870","rc":[{"atb":[[2.68,0]],"id":41793694}],"con":true,"img":false}]}
{"op":"mcm","clk":"5322259254","pt":1646318181511,"mc":[{"id":"1.195532870","rc":[{"atb":[[2.7,7.3]],"id":41793694}],"con":true,"img":false}]}
{"op":"mcm","clk":"5322259270","pt":1646318181718,"mc":[{"id":"1.195532870","rc":[{"atb":[[2.58,6.28]],"id":5677052}],"con":true,"img":false}]}
{"op":"mcm","clk":"5322259608","pt":1646318186033,"mc":[{"id":"1.195532870","rc":[{"atb":[[2.44,4.67]],"id":43189003}],"con":true,"img":false}]}
{"op":"mcm","clk":"5322259978","pt":1646318189112,"mc":[{"id":"1.195532870","rc":[{"atb":[[2.52,7.37]],"id":5677052}],"con":true,"img":false}]}
{"op":"mcm","clk":"5322260389","pt":1646318194139,"mc":[{"id":"1.195532870","rc":[{"atb":[[2.74,0]],"id":41793694}],"con":true,"img":false}]}
{"op":"mcm","clk":"5322261412","pt":1646318206761,"mc":[{"id":"1.195532870","rc":[{"atb":[[2.4,0]],"id":43189003}],"con":true,"img":false}]}
{"op":"mcm","clk":"5322261423","pt":1646318206862,"mc":[{"id":"1.195532870","rc":[{"atb":[[2.72,5.76]],"id":41793694}],"con":true,"img":false}]}
{"op":"mcm","clk":"5322261698","pt":1646318210195,"mc":[{"id":"1.195532870","rc":[{"atb":[[2.64,4.1]],"id":5677052}],"con":true,"img":false}]}
{"op":"mcm","clk":"5322261946","pt":1646318213385,"mc":[{"id":"1.195532870","rc":[{"atb":[[2.44,0]],"id":43189003}],"con":true,"img":false}]}
{"op":"mcm","clk":"5322263543","pt":1646318233626,"mc":[{"id":"1.195532870","rc":[{"atb":[[2.58,0]],"id":5677052}],"con":true,"img":false}]}
{"op":"mcm","clk":"5322263645","pt":1646318234726,"mc":[{"id":"1.195532870","rc":[{"atb":[[2.4,4.8]],"id":43189003}],"con":true,"img":false}]}
{"op":"mcm","clk":"5322263974","pt":1646318238287,"mc":[{"id":"1.195532870","rc":[{"atb":[[2.78,3.78]],"id":41793694}],"con":true,"img":false}]}
{"op":"mcm","clk":"5322264184","pt":1646318240536,"mc":[{"id":"1.195532870","rc":[{"atb":[[2.64,0]],"id":5677052}],"con":true,"img":false}]}
{"op":"mcm","clk":"5322266179","pt":1646318260049,"mc":[{"id":"1.195532870","rc":[{"atb":[[2.72,0]],"id":41793694}],"con":true,"img":false}]}
{"op":"mcm","clk":"5322266188","pt":1646318260152,"mc":[{"id":"1.195532870","rc":[{"atb":[[2.52,11.8]],"id":5677052}],"con":true,"img":false}]}
{"op":"mcm","clk":"5322267094","pt":1646318270649,"mc":[{"id":"1.195532870","rc":[{"atb":[[2.78,0]],"id":41793694}],"con":true,"img":false}]}
{"op":"mcm","clk":"5322268298","pt":1646318284004,"mc":[{"id":"1.195532870","rc":[{"atb":[[2.58,6.28]],"id":5677052},{"atb":[[2.44,6.88]],"id":43189003}],"con":true,"img":false}]}
{"op":"mcm","clk":"5322269079","pt":1646318291792,"mc":[{"id":"1.195532870","rc":[{"atb":[[2.52,7.37]],"id":5677052},{"atb":[[2.4,0]],"id":43189003}],"con":true,"img":false}]}
{"op":"mcm","clk":"5322269107","pt":1646318292105,"mc":[{"id":"1.195532870","rc":[{"atb":[[2.76,3.82]],"id":41793694}],"con":true,"img":false}]}
{"op":"mcm","clk":"5322270182","pt":1646318303124,"mc":[{"id":"1.195532870","rc":[{"atb":[[3.75,0]],"id":40214166},{"atb":[[3.9,0]],"id":40214168},{"atb":[[2.48,0]],"id":5677052}],"con":true,"img":false}]}
{"op":"mcm","clk":"5322271089","pt":1646318312704,"mc":[{"id":"1.195532870","rc":[{"atb":[[2.64,4.1]],"id":5677052},{"atb":[[2.48,4.54]],"id":43189003}],"con":true,"img":false}]}
{"op":"mcm","clk":"5322271568","pt":1646318317439,"mc":[{"id":"1.195532870","rc":[{"atb":[[2.44,0]],"id":43189003}],"con":true,"img":false}]}
{"op":"mcm","clk":"5322271589","pt":1646318317706,"mc":[{"id":"1.195532870","rc":[{"atb":[[3.95,4.2]],"id":40214166}],"con":true,"img":false}]}
{"op":"mcm","clk":"5322271598","pt":1646318317801,"mc":[{"id":"1.195532870","rc":[{"atb":[[4.2,3.88]],"id":40214168}],"con":true,"img":false}]}
{"op":"mcm","clk":"5322271628","pt":1646318318123,"mc":[{"id":"1.195532870","rc":[{"atb":[[2.68,7.39]],"id":5677052}],"con":true,"img":false}]}
{"op":"mcm","clk":"5322272377","pt":1646318325041,"mc":[{"id":"1.195532870","rc":[{"atb":[[2.64,0]],"id":5677052},{"atb":[[2.48,0]],"id":43189003}],"con":true,"img":false}]}
{"op":"mcm","clk":"5322273152","pt":1646318333022,"mc":[{"id":"1.195532870","rc":[{"atb":[[2.82,5.45]],"id":41793694}],"con":true,"img":false}]}
{"op":"mcm","clk":"5322273840","pt":1646318339967,"mc":[{"id":"1.195532870","rc":[{"atb":[[2.76,0]],"id":41793694}],"con":true,"img":false}]}
{"op":"mcm","clk":"5322274419","pt":1646318345991,"mc":[{"id":"1.195532870","rc":[{"atb":[[2.4,4.8]],"id":43189003}],"con":true,"img":false}]}
{"op":"mcm","clk":"5322274439","pt":1646318346149,"mc":[{"id":"1.195532870","rc":[{"atb":[[2.74,3.86]],"id":5677052}],"con":true,"img":false}]}
{"op":"mcm","clk":"5322275615","pt":1646318359390,"mc":[{"id":"1.195532870","rc":[{"atb":[[2.58,0]],"id":5677052},{"atb":[[2.82,0]],"id":41793694}],"con":true,"img":false}]}
{"op":"mcm","clk":"5322277051","pt":1646318374627,"mc":[{"id":"1.195532870","rc":[{"atb":[[2.44,6.88]],"id":43189003}],"con":true,"img":false}]}
{"op":"mcm","clk":"5322277109","pt":1646318375149,"mc":[{"id":"1.195532870","rc":[{"atb":[[2.72,5.76]],"id":41793694}],"con":true,"img":false}]}
{"op":"mcm","clk":"5322277742","pt":1646318381940,"mc":[{"id":"1.195532870","rc":[{"atb":[[2.4,0]],"id":43189003}],"con":true,"img":false}]}
{"op":"mcm","clk":"5322278198","pt":1646318386538,"mc":[{"id":"1.195532870","rc":[{"atb":[[2.8,5.51]],"id":5677052}],"con":true,"img":false}]}
{"op":"mcm","clk":"5322279172","pt":1646318396737,"mc":[{"id":"1.195532870","rc":[{"atb":[[2.74,0]],"id":5677052}],"con":true,"img":false}]}
{"op":"mcm","clk":"5322279305","pt":1646318398547,"mc":[{"id":"1.195532870","rc":[{"atb":[[2.44,0]],"id":43189003}],"con":true,"img":false}]}
{"op":"mcm","clk":"5322279665","pt":1646318402833,"mc":[{"id":"1.195532870","rc":[{"atb":[[2.78,3.78]],"id":41793694}],"con":true,"img":false}]}
{"op":"mcm","clk":"5322279683","pt":1646318403041,"mc":[{"id":"1.195532870","rc":[{"atb":[[2.66,0]],"id":41793694}],"con":true,"img":false}]}
{"op":"mcm","clk":"5322279902","pt":1646318405870,"mc":[{"id":"1.195532870","rc":[{"atb":[[2.76,6.36]],"id":41793694}],"con":true,"img":false}]}
{"op":"mcm","clk":"5322280322","pt":1646318410075,"mc":[{"id":"1.195532870","rc":[{"atb":[[2.8,0]],"id":5677052}],"con":true,"img":false}]}
{"op":"mcm","clk":"5322280791","pt":1646318415090,"mc":[{"id":"1.195532870","rc":[{"atb":[[2.52,0]],"id":5677052}],"con":true,"img":false}]}
{"op":"mcm","clk":"5322281049","pt":1646318418184,"mc":[{"id":"1.195532870","rc":[{"atb":[[2.72,6.51]],"id":5677052}],"con":true,"img":false}]}
{"op":"mcm","clk":"5322281417","pt":1646318422284,"mc":[{"id":"1.195532870","rc":[{"atb":[[2.4,7.08]],"id":43189003}],"con":true,"img":false}]}
{"op":"mcm","clk":"5322281434","pt":1646318422495,"mc":[{"id":"1.195532870","rc":[{"atb":[[2.72,0]],"id":41793694}],"con":true,"img":false}]}
{"op":"mcm","clk":"5322282100","pt":1646318430022,"mc":[{"id":"1.195532870","rc":[{"atb":[[2.78,0]],"id":41793694}],"con":true,"img":false}]}
{"op":"mcm","clk":"5322282535","pt":1646318434707,"mc":[{"id":"1.195532870","rc":[{"atb":[[2.7,0]],"id":41793694}],"con":true,"img":false}]}
{"op":"mcm","clk":"5322282933","pt":1646318438724,"mc":[{"id":"1.195532870","rc":[{"atb":[[2.74,3.86]],"id":5677052}],"con":true,"img":false}]}
{"op":"mcm","clk":"5322283405","pt":1646318443643,"mc":[{"id":"1.195532870","rc":[{"atb":[[2.8,6.89]],"id":41793694}],"con":true,"img":false}]}
{"op":"mcm","clk":"5322284071","pt":1646318451037,"mc":[{"id":"1.195532870","rc":[{"atb":[[2.44,4.67]],"id":43189003}],"con":true,"img":false}]}
{"op":"mcm","clk":"5322285700","pt":1646318467740,"mc":[{"id":"1.195532870","rc":[{"atb":[[2.82,5.45]],"id":41793694}],"con":true,"img":false}]}
{"op":"mcm","clk":"5322285715","pt":1646318467943,"mc":[{"id":"1.195532870","rc":[{"atb":[[2.4,0]],"id":43189003}],"con":true,"img":false}]}
{"op":"mcm","clk":"5322286431","pt":1646318474850,"mc":[{"id":"1.195532870","rc":[{"atb":[[2.44,0]],"id":43189003}],"con":true,"img":false}]}
{"op":"mcm","clk":"5322286935","pt":1646318479564,"mc":[{"id":"1.195532870","rc":[{"atb":[[2.8,5.51]],"id":5677052}],"con":true,"img":false}]}
{"op":"mcm","clk":"5322287732","pt":1646318487078,"mc":[{"id":"1.195532870","rc":[{"atb":[[2.74,0]],"id":5677052}],"con":true,"img":false}]}
{"op":"mcm","clk":"5322288645","pt":1646318495878,"mc":[{"id":"1.195532870","rc":[{"atb":[[2.88,3.58]],"id":41793694}],"con":true,"img":false}]}
{"op":"mcm","clk":"5322288655","pt":1646318495980,"mc":[{"id":"1.195532870","rc":[{"atb":[[2.4,4.8]],"id":43189003}],"con":true,"img":false}]}
{"op":"mcm","clk":"5322289396","pt":1646318503496,"mc":[{"id":"1.195532870","rc":[{"atb":[[2.8,0]],"id":5677052}],"con":true,"img":false}]}
{"op":"mcm","clk":"5322290674","pt":1646318516298,"mc":[{"id":"1.195532870","rc":[{"atb":[[2.82,0]],"id":41793694}],"con":true,"img":false}]}
{"op":"mcm","clk":"5322291311","pt":1646318522983,"mc":[{"id":"1.195532870","rc":[{"atb":[[2.88,0]],"id":41793694}],"con":true,"img":false}]}
{"op":"mcm","clk":"5322291864","pt":1646318527999,"mc":[{"id":"1.195532870","rc":[{"atb":[[2.78,5.57]],"id":5677052}],"con":true,"img":false}]}
{"op":"mcm","clk":"5322292910","pt":1646318538026,"mc":[{"id":"1.195532870","rc":[{"atb":[[3.85,0]],"id":40214166},{"atb":[[4,0]],"id":40214168}],"con":true,"img":false}]}
{"op":"mcm","clk":"5322293132","pt":1646318540017,"mc":[{"id":"1.195532870","rc":[{"atb":[[2.44,6.88]],"id":43189003}],"con":true,"img":false}]}
{"op":"mcm","clk":"5322293230","pt":1646318541038,"mc":[{"id":"1.195532870","rc":[{"atb":[[4.1,3.61]],"id":40214166}],"con":true,"img":false}]}
{"op":"mcm","clk":"5322293276","pt":1646318541402,"mc":[{"id":"1.195532870","rc":[{"atb":[[4.4,3.29]],"id":40214168}],"con":true,"img":false}]}
{"op":"mcm","clk":"5322293525","pt":1646318543903,"mc":[{"id":"1.195532870","rc":[{"atb":[[2.86,3.61]],"id":41793694}],"con":true,"img":false}]}
{"op":"mcm","clk":"5322293809","pt":1646318547120,"mc":[{"id":"1.195532870","rc":[{"atb":[[2.4,0]],"id":43189003}],"con":true,"img":false}]}
{"op":"mcm","clk":"5322294669","pt":1646318555962,"mc":[{"id":"1.195532870","rc":[{"atb":[[2.84,3.65]],"id":5677052}],"con":true,"img":false}]}
{"op":"mcm","clk":"5322295831","pt":1646318567236,"mc":[{"id":"1.195532870","rc":[{"atb":[[2.68,0]],"id":5677052}],"con":true,"img":false}]}
{"op":"mcm","clk":"5322295873","pt":1646318567549,"mc":[{"id":"1.195532870","rc":[{"atb":[[2.44,0]],"id":43189003}],"con":true,"img":false}]}
{"op":"mcm","clk":"5322297216","pt":1646318581889,"mc":[{"id":"1.195532870","rc":[{"atb":[[2.92,5.16]],"id":41793694},{"atb":[[2.4,7.08]],"id":43189003}],"con":true,"img":false}]}
{"op":"mcm","clk":"5322297275","pt":1646318582510,"mc":[{"id":"1.195532870","rc":[{"atb":[[2.4,8.86],[2.78,0]],"id":5677052}],"con":true,"img":false}]}
{"op":"mcm","clk":"5322297894","pt":1646318589121,"mc":[{"id":"1.195532870","rc":[{"atb":[[2.84,0]],"id":5677052},{"atb":[[2.86,0]],"id":41793694}],"con":true,"img":false}]}
{"op":"mcm","clk":"5322299552","pt":1646318607934,"mc":[{"id":"1.195532870","rc":[{"atb":[[2.92,0]],"id":41793694}],"con":true,"img":false}]}
{"op":"mcm","clk":"5322299760","pt":1646318610162,"mc":[{"id":"1.195532870","rc":[{"atb":[[2.44,4.67]],"id":5677052}],"con":true,"img":false}]}
{"op":"mcm","clk":"5322299776","pt":1646318610359,"mc":[{"id":"1.195532870","rc":[{"atb":[[2.44,4.67]],"id":43189003}],"con":true,"img":false}]}
{"op":"mcm","clk":"5322301603","pt":1646318629561,"mc":[{"id":"1.195532870","rc":[{"atb":[[2.4,0]],"id":43189003}],"con":true,"img":false}]}
{"op":"mcm","clk":"5322301632","pt":1646318629871,"mc":[{"id":"1.195532870","rc":[{"atb":[[2.82,5.45]],"id":41793694}],"con":true,"img":false}]}
{"op":"mcm","clk":"5322301644","pt":1646318629977,"mc":[{"id":"1.195532870","rc":[{"atb":[[2.78,5.57]],"id":5677052}],"con":true,"img":false}]}
{"op":"mcm","clk":"5322302374","pt":1646318637419,"mc":[{"id":"1.195532870","rc":[{"atb":[[2.44,0]],"id":5677052},{"atb":[[2.44,0]],"id":43189003}],"con":true,"img":false}]}
{"op":"mcm","clk":"5322304090","pt":1646318655382,"mc":[{"id":"1.195532870","rc":[{"atb":[[2.76,0]],"id":41793694}],"con":true,"img":false}]}
{"op":"mcm","clk":"5322304374","pt":1646318658506,"mc":[{"id":"1.195532870","rc":[{"atb":[[2.4,4.8]],"id":43189003}],"con":true,"img":false}]}
{"op":"mcm","clk":"5322304384","pt":1646318658610,"mc":[{"id":"1.195532870","rc":[{"atb":[[2.84,3.65]],"id":5677052},{"atb":[[2.88,3.58]],"id":41793694}],"con":true,"img":false}]}
{"op":"mcm","clk":"5322304409","pt":1646318658876,"mc":[{"id":"1.195532870","rc":[{"atb":[[2.86,6.02]],"id":41793694}],"con":true,"img":false}]}
{"op":"mcm","clk":"5322305358","pt":1646318669026,"mc":[{"id":"1.195532870","rc":[{"atb":[[2.82,0]],"id":41793694}],"con":true,"img":false}]}
{"op":"mcm","clk":"5322306047","pt":1646318676816,"mc":[{"id":"1.195532870","rc":[{"atb":[[2.88,0]],"id":41793694}],"con":true,"img":false}]}
{"op":"mcm","clk":"5322306489","pt":1646318681450,"mc":[{"id":"1.195532870","rc":[{"atb":[[2.78,0]],"id":5677052}],"con":true,"img":false}]}
{"op":"mcm","clk":"5322307171","pt":1646318688748,"mc":[{"id":"1.195532870","rc":[{"atb":[[2.84,0]],"id":5677052}],"con":true,"img":false}]}
{"op":"mcm","clk":"5322308005","pt":1646318697359,"mc":[{"id":"1.195532870","rc":[{"atb":[[2.86,9.64]],"id":41793694}],"con":true,"img":false}]}
{"op":"mcm","clk":"5322308610","pt":1646318703068,"mc":[{"id":"1.195532870","rc":[{"atb":[[2.44,6.88]],"id":43189003}],"con":true,"img":false}]}
{"op":"mcm","clk":"5322309048","pt":1646318707394,"mc":[{"id":"1.195532870","rc":[{"atb":[[2.44,4.67]],"id":5677052}],"con":true,"img":false}]}
{"op":"mcm","clk":"5322309553","pt":1646318712648,"mc":[{"id":"1.195532870","rc":[{"atb":[[2.4,0]],"id":43189003}],"con":true,"img":false}]}
{"op":"mcm","clk":"5322309825","pt":1646318714998,"mc":[{"id":"1.195532870","rc":[{"atb":[[2.92,5.16]],"id":41793694}],"con":true,"img":false}]}
{"op":"mcm","clk":"5322310757","pt":1646318724677,"mc":[{"id":"1.195532870","rc":[{"atb":[[2.86,6.02]],"id":41793694}],"con":true,"img":false}]}
{"op":"mcm","clk":"5322310935","pt":1646318726499,"mc":[{"id":"1.195532870","rc":[{"atb":[[2.44,0]],"id":43189003}],"con":true,"img":false}]}
{"op":"mcm","clk":"5322310953","pt":1646318726708,"mc":[{"id":"1.195532870","rc":[{"atb":[[2.78,5.57]],"id":5677052}],"con":true,"img":false}]}
{"op":"mcm","clk":"5322311628","pt":1646318733524,"mc":[{"id":"1.195532870","rc":[{"atb":[[2.44,0]],"id":5677052}],"con":true,"img":false}]}
{"op":"mcm","clk":"5322312422","pt":1646318741692,"mc":[{"id":"1.195532870","rc":[{"atb":[[2.4,7.08]],"id":43189003}],"con":true,"img":false}]}
{"op":"mcm","clk":"5322312787","pt":1646318745340,"mc":[{"id":"1.195532870","rc":[{"atb":[[2.98,3.4]],"id":41793694}],"con":true,"img":false}]}
{"op":"mcm","clk":"5322313579","pt":1646318753617,"mc":[{"id":"1.195532870","rc":[{"atb":[[2.8,0]],"id":41793694}],"con":true,"img":false}]}
{"op":"mcm","clk":"5322313668","pt":1646318754650,"mc":[{"id":"1.195532870","rc":[{"atb":[[2.84,3.65]],"id":5677052}],"con":true,"img":false}]}
{"op":"mcm","clk":"5322314681","pt":1646318765328,"mc":[{"id":"1.195532870","rc":[{"atb":[[2.92,0]],"id":41793694}],"con":true,"img":false}]}
{"op":"mcm","clk":"5322314687","pt":1646318765439,"mc":[{"id":"1.195532870","rc":[{"atb":[[2.36,9.13]],"id":41793694}],"con":true,"img":false}]}
{"op":"mcm","clk":"5322315083","pt":1646318769779,"mc":[{"id":"1.195532870","rc":[{"atb":[[2.44,4.67]],"id":43189003}],"con":true,"img":false}]}
{"op":"mcm","clk":"5322315381","pt":1646318773063,"mc":[{"id":"1.195532870","rc":[{"atb":[[2.98,0]],"id":41793694}],"con":true,"img":false}]}
{"op":"mcm","clk":"5322315851","pt":1646318778350,"mc":[{"id":"1.195532870","rc":[{"atb":[[2.78,0]],"id":5677052}],"con":true,"img":false}]}
{"op":"mcm","clk":"5322315861","pt":1646318778453,"mc":[{"id":"1.195532870","rc":[{"atb":[[3.95,0]],"id":40214166},{"atb":[[4.2,0]],"id":40214168}],"con":true,"img":false}]}
{"op":"mcm","clk":"5322316824","pt":1646318788559,"mc":[{"id":"1.195532870","rc":[{"atb":[[2.84,0]],"id":5677052}],"con":true,"img":false}]}
{"op":"mcm","clk":"5322316948","pt":1646318790079,"mc":[{"id":"1.195532870","rc":[{"atb":[[2.4,0]],"id":43189003}],"con":true,"img":false}]}
{"op":"mcm","clk":"5322316959","pt":1646318790185,"mc":[{"id":"1.195532870","rc":[{"atb":[[4.6,3.45]],"id":40214168}],"con":true,"img":false}]}
{"op":"mcm","clk":"5322316980","pt":1646318790395,"mc":[{"id":"1.195532870","rc":[{"atb":[[4.3,3.76]],"id":40214166}],"con":true,"img":false}]}
{"op":"mcm","clk":"5322317370","pt":1646318794496,"mc":[{"id":"1.195532870","rc":[{"atb":[[2.4,4.8]],"id":41793694}],"con":true,"img":false}]}
{"op":"mcm","clk":"5322317719","pt":1646318798316,"mc":[{"id":"1.195532870","rc":[{"atb":[[2.72,0]],"id":5677052}],"con":true,"img":false}]}
{"op":"mcm","clk":"5322327289","pt":1646318803931,"mc":[{"id":"1.195532870","rc":[{"atb":[[2.44,7.79]],"id":5677052}],"con":true,"img":false}]}
{"op":"mcm","clk":"5322327314","pt":1646318804189,"mc":[{"id":"1.195532870","rc":[{"atb":[[2.44,0]],"id":43189003}],"con":true,"img":false}]}
{"op":"mcm","clk":"5322327702","pt":1646318808925,"mc":[{"id":"1.195532870","rc":[{"atb":[[2.44,12.46]],"id":5677052}],"con":true,"img":false}]}
{"op":"mcm","clk":"5322328092","pt":1646318813616,"mc":[{"id":"1.195532870","rc":[{"atb":[[2.92,5.16]],"id":41793694}],"con":true,"img":false}]}
{"op":"mcm","clk":"5322328754","pt":1646318821037,"mc":[{"id":"1.195532870","rc":[{"atb":[[2.4,0]],"id":41793694}],"con":true,"img":false}]}
{"op":"mcm","clk":"5322330120","pt":1646318835960,"mc":[{"id":"1.195532870","rc":[{"atb":[[2.4,4.8]],"id":43189003}],"con":true,"img":false}]}
{"op":"mcm","clk":"5322330693","pt":1646318841949,"mc":[{"id":"1.195532870","rc":[{"atb":[[2.98,3.4]],"id":41793694}],"con":true,"img":false}]}
{"op":"mcm","clk":"5322330947","pt":1646318844846,"mc":[{"id":"1.195532870","rc":[{"atb":[[2.48,6.69]],"id":5677052}],"con":true,"img":false}]}
{"op":"mcm","clk":"5322331777","pt":1646318853969,"mc":[{"id":"1.195532870","rc":[{"atb":[[2.44,7.79]],"id":5677052}],"con":true,"img":false}]}
{"op":"mcm","clk":"5322331972","pt":1646318855800,"mc":[{"id":"1.195532870","rc":[{"atb":[[2.4,0]],"id":5677052}],"con":true,"img":false}]}
{"op":"mcm","clk":"5322331995","pt":1646318856109,"mc":[{"id":"1.195532870","rc":[{"atb":[[2.92,0]],"id":41793694}],"con":true,"img":false}]}
{"op":"mcm","clk":"5322332597","pt":1646318862983,"mc":[{"id":"1.195532870","rc":[{"atb":[[2.98,0]],"id":41793694}],"con":true,"img":false}]}
{"op":"mcm","clk":"5322332977","pt":1646318867832,"mc":[{"id":"1.195532870","rc":[{"atb":[[2.48,15.09]],"id":5677052}],"con":true,"img":false}]}
{"op":"mcm","clk":"5322333566","pt":1646318874901,"mc":[{"id":"1.195532870","rc":[{"atb":[[2.52,4.42]],"id":5677052}],"con":true,"img":false}]}
{"op":"mcm","clk":"5322333797","pt":1646318877721,"mc":[{"id":"1.195532870","rc":[{"atb":[[2.44,6.88]],"id":43189003}],"con":true,"img":false}]}
{"op":"mcm","clk":"5322334052","pt":1646318880849,"mc":[{"id":"1.195532870","rc":[{"atb":[[4.6,25.56]],"id":42931076}],"con":true,"img":false}]}
{"op":"mcm","clk":"5322334059","pt":1646318880949,"mc":[{"id":"1.195532870","rc":[{"atb":[[2.62,64.81]],"id":40214166},{"atb":[[2.62,64.81]],"id":40214168},{"atl":[[17,9.5]],"id":5677052},{"atl":[[17,9.5]],"id":41793694},{"atl":[[34,15.5]],"id":43189003},{"atb":[[3.7,37.78],[2.62,64.81]],"id":42931076}],"con":true,"img":false}]}
{"op":"mcm","clk":"5322334066","pt":1646318881000,"mc":[{"id":"1.195532870","rc":[{"atl":[[34,15.5]],"id":5677052},{"atl":[[34,15.5]],"id":41793694}],"con":true,"img":false}]}
{"op":"mcm","clk":"5322334324","pt":1646318883954,"mc":[{"id":"1.195532870","rc":[{"atb":[[2.4,4.8]],"id":41793694}],"con":true,"img":false}]}
{"op":"mcm","clk":"5322334585","pt":1646318886935,"mc":[{"id":"1.195532870","rc":[{"atb":[[2.48,8.39]],"id":5677052}],"con":true,"img":false}]}
{"op":"mcm","clk":"5322334604","pt":1646318887142,"mc":[{"id":"1.195532870","rc":[{"atb":[[2.4,0]],"id":43189003}],"con":true,"img":false}]}
{"op":"mcm","clk":"5322335596","pt":1646318898751,"mc":[{"id":"1.195532870","rc":[{"atb":[[2.92,5.16]],"id":41793694}],"con":true,"img":false}]}
{"op":"mcm","clk":"5322335608","pt":1646318898849,"mc":[{"id":"1.195532870","rc":[{"atl":[[5,1.65]],"id":5677052},{"atb":[[2.58,1.65]],"id":43189003}],"con":true,"img":false}]}
{"op":"mcm","clk":"5322335926","pt":1646318902180,"mc":[{"id":"1.195532870","rc":[{"atb":[[2.86,0]],"id":41793694}],"con":true,"img":false}]}
{"op":"mcm","clk":"5322336159","pt":1646318904939,"mc":[{"id":"1.195532870","rc":[{"atb":[[2.4,12.81]],"id":41793694}],"con":true,"img":false}]}
{"op":"mcm","clk":"5322336454","pt":1646318908065,"mc":[{"id":"1.195532870","rc":[{"atb":[[2.4,8]],"id":41793694}],"con":true,"img":false}]}
{"op":"mcm","clk":"5322336466","pt":1646318908170,"mc":[{"id":"1.195532870","rc":[{"atb":[[2.48,4.54]],"id":43189003}],"con":true,"img":false}]}
{"op":"mcm","clk":"5322336686","pt":1646318910885,"mc":[{"id":"1.195532870","rc":[{"atb":[[2.44,0]],"id":43189003}],"con":true,"img":false}]}
{"op":"mcm","clk":"5322336700","pt":1646318911049,"mc":[{"id":"1.195532870","rc":[{"atb":[[2.58,6.28]],"id":5677052}],"con":true,"img":false}]}
{"op":"mcm","clk":"5322337166","pt":1646318916467,"mc":[{"id":"1.195532870","rc":[{"atb":[[1.43,237.21],[1.57,161.4]],"id":43189003}],"con":true,"img":false}]}
{"op":"mcm","clk":"5322337181","pt":1646318916569,"mc":[{"id":"1.195532870","rc":[{"atl":[[8.6,9.2],[11,15.2]],"id":5677052}],"con":true,"img":false}]}
{"op":"mcm","clk":"5322337223","pt":1646318917101,"mc":[{"id":"1.195532870","rc":[{"atb":[[1.59,19]],"id":43189003}],"con":true,"img":false}]}
{"op":"mcm","clk":"5322337460","pt":1646318919998,"mc":[{"id":"1.195532870","rc":[{"atb":[[2.52,0]],"id":5677052},{"atb":[[2.48,0]],"id":43189003}],"con":true,"img":false}]}
{"op":"mcm","clk":"5322337757","pt":1646318923486,"mc":[{"id":"1.195532870","rc":[{"atb":[[2.92,0]],"id":41793694},{"atb":[[1.61,20.35]],"id":43189003}],"con":true,"img":false}]}
{"op":"mcm","clk":"5322338720","pt":1646318934714,"mc":[{"id":"1.195532870","rc":[{"atb":[[2.58,0]],"id":5677052}],"con":true,"img":false}]}
{"op":"mcm","clk":"5322339324","pt":1646318942126,"mc":[{"id":"1.195532870","rc":[{"atb":[[2.4,4.8]],"id":43189003}],"con":true,"img":false}]}
{"op":"mcm","clk":"5322339729","pt":1646318946648,"mc":[{"id":"1.195532870","rc":[{"atb":[[2.44,6.88]],"id":41793694}],"con":true,"img":false}]}
{"op":"mcm","clk":"5322340517","pt":1646318955463,"mc":[{"id":"1.195532870","rc":[{"atb":[[2.48,15.09]],"id":5677052}],"con":true,"img":false}]}
{"op":"mcm","clk":"5322341310","pt":1646318965165,"mc":[{"id":"1.195532870","rc":[{"atb":[[2.52,4.42]],"id":5677052},{"spn":5.03,"spf":6.0,"id":5677052},{"spn":4.69,"spf":1.0,"id":43189003}],"con":true,"img":false}]}
{"op":"mcm","clk":"5322342022","pt":1646318974542,"mc":[{"id":"1.195532870","rc":[{"atb":[[2.48,4.54]],"id":41793694}],"con":true,"img":false}]}
{"op":"mcm","clk":"5322342386","pt":1646318979733,"mc":[{"id":"1.195532870","rc":[{"atb":[[2.48,8.39]],"id":5677052}],"con":true,"img":false}]}
{"op":"mcm","clk":"5322342397","pt":1646318979838,"mc":[{"id":"1.195532870","rc":[{"atb":[[2.44,6.88]],"id":43189003}],"con":true,"img":false}]}
{"op":"mcm","clk":"5322342929","pt":1646318986479,"mc":[{"id":"1.195532870","rc":[{"atb":[[2.4,0]],"id":43189003}],"con":true,"img":false}]}
{"op":"mcm","clk":"5322343377","pt":1646318992394,"mc":[{"id":"1.195532870","rc":[{"atb":[[2.44,0]],"id":41793694}],"con":true,"img":false}]}
{"op":"mcm","clk":"5322344143","pt":1646319001664,"mc":[{"id":"1.195532870","rc":[{"atb":[[2.48,0]],"id":41793694}],"con":true,"img":false}]}
{"op":"mcm","clk":"5322344357","pt":1646319004076,"mc":[{"id":"1.195532870","rc":[{"atb":[[2.44,0]],"id":43189003}],"con":true,"img":false}]}
{"op":"mcm","clk":"5322344371","pt":1646319004284,"mc":[{"id":"1.195532870","rc":[{"atb":[[2.58,6.28]],"id":5677052}],"con":true,"img":false}]}
{"op":"mcm","clk":"5322345132","pt":1646319013793,"mc":[{"id":"1.195532870","rc":[{"atb":[[4.1,0]],"id":40214166},{"atb":[[4.4,0]],"id":40214168}],"con":true,"img":false}]}
{"op":"mcm","clk":"5322345139","pt":1646319013899,"mc":[{"id":"1.195532870","rc":[{"atb":[[2.52,0]],"id":5677052}],"con":true,"img":false}]}
{"op":"mcm","clk":"5322345318","pt":1646319016298,"mc":[{"id":"1.195532870","rc":[{"atb":[[4.5,3.2]],"id":40214166}],"con":true,"img":false}]}
{"op":"mcm","clk":"5322345334","pt":1646319016508,"mc":[{"id":"1.195532870","rc":[{"atb":[[4.8,2.95]],"id":40214168}],"con":true,"img":false}]}
{"op":"mcm","clk":"5322345571","pt":1646319019004,"mc":[{"id":"1.195532870","rc":[{"atb":[[2.4,7.08]],"id":43189003}],"con":true,"img":false}]}
{"op":"mcm","clk":"5322345834","pt":1646319022402,"mc":[{"id":"1.195532870","rc":[{"atb":[[2.4,12.81]],"id":41793694}],"con":true,"img":false}]}
{"op":"mcm","clk":"5322346760","pt":1646319034243,"mc":[{"id":"1.195532870","rc":[{"atb":[[2.58,0]],"id":5677052}],"con":true,"img":false}]}
{"op":"mcm","clk":"5322346779","pt":1646319034556,"mc":[{"id":"1.195532870","rc":[{"atb":[[2.64,4.1]],"id":5677052}],"con":true,"img":false}]}
{"op":"mcm","clk":"5322346789","pt":1646319034660,"mc":[{"id":"1.195532870","rc":[{"atb":[[2.44,6.88]],"id":41793694}],"con":true,"img":false}]}
{"op":"mcm","clk":"5322346794","pt":1646319034764,"mc":[{"id":"1.195532870","rc":[{"atb":[[2.36,0]],"id":41793694}],"con":true,"img":false}]}
{"op":"mcm","clk":"5322347551","pt":1646319043760,"mc":[{"id":"1.195532870","rc":[{"atb":[[2.64,0]],"id":5677052},{"atb":[[2.4,8]],"id":41793694}],"con":true,"img":false}]}
{"op":"mcm","clk":"5322347975","pt":1646319049168,"mc":[{"id":"1.195532870","rc":[{"atb":[[2.48,15.09]],"id":5677052}],"con":true,"img":false}]}
{"op":"mcm","clk":"5322348001","pt":1646319049480,"mc":[{"id":"1.195532870","rc":[{"atb":[[2.44,4.67]],"id":43189003}],"con":true,"img":false}]}
{"op":"mcm","clk":"5322348019","pt":1646319049642,"mc":[{"id":"1.195532870","rc":[{"atb":[[2.44,15.51]],"id":41793694}],"con":true,"img":false}]}
{"op":"mcm","clk":"5322349258","pt":1646319064565,"mc":[{"id":"1.195532870","rc":[{"atb":[[2.48,4.54]],"id":41793694}],"con":true,"img":false}]}
{"op":"mcm","clk":"5322349498","pt":1646319067589,"mc":[{"id":"1.195532870","rc":[{"atb":[[2.52,4.42]],"id":5677052}],"con":true,"img":false}]}
{"op":"mcm","clk":"5322350175","pt":1646319076869,"mc":[{"id":"1.195532870","rc":[{"atb":[[2.4,0]],"id":43189003}],"con":true,"img":false}]}
{"op":"mcm","clk":"5322350383","pt":1646319079271,"mc":[{"id":"1.195532870","rc":[{"atb":[[2.44,0]],"id":5677052}],"con":true,"img":false}]}
{"op":"mcm","clk":"5322350622","pt":1646319082330,"mc":[{"id":"1.195532870","rc":[{"atb":[[2.52,11.8]],"id":5677052}],"con":true,"img":false}]}
{"op":"mcm","clk":"5322350853","pt":1646319085346,"mc":[{"id":"1.195532870","rc":[{"atb":[[2.44,0]],"id":43189003}],"con":true,"img":false}]}
{"op":"mcm","clk":"5322351369","pt":1646319091346,"mc":[{"id":"1.195532870","rc":[{"atb":[[2.48,8.39]],"id":5677052},{"atb":[[2.44,8.62]],"id":41793694}],"con":true,"img":false}]}
{"op":"mcm","clk":"5322352577","pt":1646319105992,"mc":[{"id":"1.195532870","rc":[{"atb":[[2.52,6.52]],"id":41793694}],"con":true,"img":false}]}
{"op":"mcm","clk":"5322352598","pt":1646319106199,"mc":[{"id":"1.195532870","rc":[{"atb":[[2.58,6.28]],"id":5677052}],"con":true,"img":false}]}
{"op":"mcm","clk":"5322352607","pt":1646319106303,"mc":[{"id":"1.195532870","rc":[{"atb":[[2.4,4.8]],"id":43189003}],"con":true,"img":false}]}
{"op":"mcm","clk":"5322353344","pt":1646319115385,"mc":[{"id":"1.195532870","rc":[{"atb":[[2.52,7.37]],"id":5677052},{"atb":[[2.48,0]],"id":41793694}],"con":true,"img":false}]}
{"op":"mcm","clk":"5322353359","pt":1646319115596,"mc":[{"id":"1.195532870","rc":[{"atb":[[2.9,6.53]],"id":42931076}],"con":true,"img":false}]}
{"op":"mcm","clk":"5322353566","pt":1646319118024,"mc":[{"id":"1.195532870","rc":[{"atb":[[2.48,0]],"id":5677052},{"atb":[[2.9,0]],"id":42931076}],"con":true,"img":false}]}
{"op":"mcm","clk":"5322353602","pt":1646319118392,"mc":[{"id":"1.195532870","rc":[{"atb":[[4.8,2.95]],"id":42931076}],"con":true,"img":false}]}
{"op":"mcm","clk":"5322354612","pt":1646319130615,"mc":[{"id":"1.195532870","rc":[{"atb":[[2.56,7.96]],"id":5677052},{"atb":[[2.52,0]],"id":41793694}],"con":true,"img":false}]}
{"op":"mcm","clk":"5322355172","pt":1646319136929,"mc":[{"id":"1.195532870","rc":[{"atb":[[2.64,4.1]],"id":5677052}],"con":true,"img":false}]}
{"op":"mcm","clk":"5322355414","pt":1646319139837,"mc":[{"id":"1.195532870","rc":[{"atb":[[2.4,0]],"id":41793694}],"con":true,"img":false}]}
{"op":"mcm","clk":"5322355603","pt":1646319142342,"mc":[{"id":"1.195532870","rc":[{"atb":[[2.48,7.58]],"id":41793694}],"con":true,"img":false}]}
{"op":"mcm","clk":"5322356526","pt":1646319154469,"mc":[{"id":"1.195532870","rc":[{"atb":[[2.58,0]],"id":5677052}],"con":true,"img":false}]}
{"op":"mcm","clk":"5322356584","pt":1646319155045,"mc":[{"id":"1.195532870","rc":[{"atb":[[2.44,6.88]],"id":43189003}],"con":true,"img":false}]}
{"op":"mcm","clk":"5322356795","pt":1646319157559,"mc":[{"id":"1.195532870","rc":[{"atb":[[1.59,0]],"id":43189003}],"con":true,"img":false}]}
{"op":"mcm","clk":"5322357015","pt":1646319160780,"mc":[{"id":"1.195532870","rc":[{"atb":[[2.48,12.12]],"id":41793694}],"con":true,"img":false}]}
{"op":"mcm","clk":"5322357029","pt":1646319160991,"mc":[{"id":"1.195532870","rc":[{"atb":[[1.63,17.8]],"id":43189003}],"con":true,"img":false}]}
{"op":"mcm","clk":"5322357224","pt":1646319163595,"mc":[{"id":"1.195532870","rc":[{"atb":[[2.64,0]],"id":5677052},{"atb":[[2.4,0]],"id":43189003}],"con":true,"img":false}]}
{"op":"mcm","clk":"5322358454","pt":1646319181391,"mc":[{"id":"1.195532870","rc":[{"atb":[[2.44,0]],"id":43189003}],"con":true,"img":false}]}
{"op":"mcm","clk":"5322358464","pt":1646319181493,"mc":[{"id":"1.195532870","rc":[{"atb":[[2.52,6.52]],"id":41793694}],"con":true,"img":false}]}
{"op":"mcm","clk":"5322358665","pt":1646319185077,"mc":[{"id":"1.195532870","rc":[{"atb":[[2.62,4.15]],"id":5677052}],"con":true,"img":false}]}
{"op":"mcm","clk":"5322359038","pt":1646319190804,"mc":[{"id":"1.195532870","rc":[{"atb":[[2.48,7.58]],"id":41793694}],"con":true,"img":false}]}
{"op":"mcm","clk":"5322359184","pt":1646319192989,"mc":[{"id":"1.195532870","rc":[{"atb":[[2.4,7.08]],"id":43189003}],"con":true,"img":false}]}
{"op":"mcm","clk":"5322360305","pt":1646319211312,"mc":[{"id":"1.195532870","rc":[{"atb":[[2.58,4.26]],"id":41793694}],"con":true,"img":false}]}
{"op":"mcm","clk":"5322360855","pt":1646319220556,"mc":[{"id":"1.195532870","rc":[{"atb":[[2.44,4.67]],"id":43189003}],"con":true,"img":false}]}
{"op":"mcm","clk":"5322361445","pt":1646319230685,"mc":[{"id":"1.195532870","rc":[{"atb":[[2.68,5.9]],"id":5677052}],"con":true,"img":false}]}
{"op":"mcm","clk":"5322361467","pt":1646319231057,"mc":[{"id":"1.195532870","rc":[{"atb":[[2.52,0]],"id":41793694}],"con":true,"img":false}]}
{"op":"mcm","clk":"5322361986","pt":1646319238771,"mc":[{"id":"1.195532870","rc":[{"atb":[[2.62,0]],"id":5677052},{"atb":[[2.58,0]],"id":41793694}],"con":true,"img":false}]}
{"op":"mcm","clk":"5322362124","pt":1646319241290,"mc":[{"id":"1.195532870","rc":[{"atb":[[2.4,0]],"id":43189003}],"con":true,"img":false}]}
{"op":"mcm","clk":"5322362668","pt":1646319250971,"mc":[{"id":"1.195532870","rc":[{"atb":[[2.44,0]],"id":43189003}],"con":true,"img":false}]}
{"op":"mcm","clk":"5322362793","pt":1646319253677,"mc":[{"id":"1.195532870","rc":[{"atb":[[2.68,0]],"id":5677052}],"con":true,"img":false}]}
{"op":"mcm","clk":"5322362848","pt":1646319254815,"mc":[{"id":"1.195532870","rc":[{"atb":[[4.3,0]],"id":40214166},{"atb":[[4.6,0]],"id":40214168}],"con":true,"img":false}]}
{"op":"mcm","clk":"5322363193","pt":1646319260002,"mc":[{"id":"1.195532870","rc":[{"atb":[[2.48,12.12]],"id":41793694}],"con":true,"img":false}]}
{"op":"mcm","clk":"5322363569","pt":1646319265691,"mc":[{"id":"1.195532870","rc":[{"atb":[[4.7,3.35]],"id":40214166}],"con":true,"img":false}]}
{"op":"mcm","clk":"5322363924","pt":1646319271831,"mc":[{"id":"1.195532870","rc":[{"atb":[[2.4,4.8]],"id":43189003}],"con":true,"img":false}]}
{"op":"mcm","clk":"5322364510","pt":1646319281815,"mc":[{"id":"1.195532870","rc":[{"atb":[[2.52,6.52]],"id":41793694}],"con":true,"img":false}]}
{"op":"mcm","clk":"5322364519","pt":1646319281916,"mc":[{"id":"1.195532870","rc":[{"atb":[[2.58,6.28]],"id":5677052}],"con":true,"img":false}]}
{"op":"mcm","clk":"5322365210","pt":1646319292634,"mc":[{"id":"1.195532870","rc":[{"atb":[[2.48,7.58]],"id":41793694}],"con":true,"img":false}]}
{"op":"mcm","clk":"5322366362","pt":1646319311176,"mc":[{"id":"1.195532870","rc":[{"atb":[[2.64,4.1]],"id":5677052}],"con":true,"img":false}]}
{"op":"mcm","clk":"5322366385","pt":1646319311337,"mc":[{"id":"1.195532870","rc":[{"atb":[[2.58,4.26]],"id":41793694}],"con":true,"img":false}]}
{"op":"mcm","clk":"5322366444","pt":1646319312069,"mc":[{"id":"1.195532870","rc":[{"atb":[[2.44,0]],"id":41793694}],"con":true,"img":false}]}
{"op":"mcm","clk":"5322366462","pt":1646319312273,"mc":[{"id":"1.195532870","rc":[{"atb":[[2.44,6.88]],"id":43189003}],"con":true,"img":false}]}
{"op":"mcm","clk":"5322366955","pt":1646319319999,"mc":[{"id":"1.195532870","rc":[{"atb":[[2.4,0]],"id":43189003}],"con":true,"img":false}]}
{"op":"mcm","clk":"5322367134","pt":1646319322769,"mc":[{"id":"1.195532870","rc":[{"atb":[[2.62,7.66]],"id":41793694}],"con":true,"img":false}]}
{"op":"mcm","clk":"5322367751","pt":1646319332003,"mc":[{"id":"1.195532870","rc":[{"atb":[[2.58,0]],"id":41793694}],"con":true,"img":false}]}
{"op":"mcm","clk":"5322367961","pt":1646319335543,"mc":[{"id":"1.195532870","rc":[{"atb":[[2.58,0]],"id":5677052},{"atb":[[2.44,0]],"id":43189003}],"con":true,"img":false}]}
{"op":"mcm","clk":"5322368294","pt":1646319341127,"mc":[{"id":"1.195532870","rc":[{"atb":[[2.52,0]],"id":5677052}],"con":true,"img":false}]}
{"op":"mcm","clk":"5322368497","pt":1646319343838,"mc":[{"id":"1.195532870","rc":[{"atb":[[2.68,6.67]],"id":5677052}],"con":true,"img":false}]}
{"op":"mcm","clk":"5322368515","pt":1646319344134,"mc":[{"id":"1.195532870","rc":[{"atb":[[2.64,0]],"id":5677052}],"con":true,"img":false}]}
{"op":"mcm","clk":"5322369179","pt":1646319353845,"mc":[{"id":"1.195532870","rc":[{"atb":[[2.68,4]],"id":41793694}],"con":true,"img":false}]}
{"op":"mcm","clk":"5322369477","pt":1646319359137,"mc":[{"id":"1.195532870","rc":[{"atb":[[2.52,0]],"id":41793694}],"con":true,"img":false}]}
{"op":"mcm","clk":"5322369486","pt":1646319359240,"mc":[{"id":"1.195532870","rc":[{"atb":[[2.4,7.08]],"id":43189003}],"con":true,"img":false}]}
{"op":"mcm","clk":"5322369795","pt":1646319365076,"mc":[{"id":"1.195532870","rc":[{"atb":[[2.62,4.15]],"id":5677052}],"con":true,"img":false}]}
{"op":"mcm","clk":"5322370946","pt":1646319383895,"mc":[{"id":"1.195532870","rc":[{"atb":[[2.56,0]],"id":5677052}],"con":true,"img":false}]}
{"op":"mcm","clk":"5322370960","pt":1646319384097,"mc":[{"id":"1.195532870","rc":[{"atb":[[2.74,5.69]],"id":5677052}],"con":true,"img":false}]}
{"op":"mcm","clk":"5322371272","pt":1646319389017,"mc":[{"id":"1.195532870","rc":[{"atb":[[2.44,4.67]],"id":43189003}],"con":true,"img":false}]}
{"op":"mcm","clk":"5322371444","pt":1646319392028,"mc":[{"id":"1.195532870","rc":[{"atb":[[2.62,0]],"id":5677052}],"con":true,"img":false}]}
{"op":"mcm","clk":"5322371702","pt":1646319395718,"mc":[{"id":"1.195532870","rc":[{"atb":[[2.74,5.69]],"id":41793694}],"con":true,"img":false}]}
{"op":"mcm","clk":"5322371723","pt":1646319396033,"mc":[{"id":"1.195532870","rc":[{"atb":[[2.72,7.21]],"id":5677052}],"con":true,"img":false}]}
{"op":"mcm","clk":"5322372237","pt":1646319403925,"mc":[{"id":"1.195532870","rc":[{"atb":[[2.68,0]],"id":41793694}],"con":true,"img":false}]}
{"op":"mcm","clk":"5322372617","pt":1646319410456,"mc":[{"id":"1.195532870","rc":[{"atb":[[1.61,0]],"id":43189003}],"con":true,"img":false}]}
{"op":"mcm","clk":"5322372627","pt":1646319410588,"mc":[{"id":"1.195532870","rc":[{"atb":[[2.4,0]],"id":43189003}],"con":true,"img":false}]}
{"op":"mcm","clk":"5322372861","pt":1646319414066,"mc":[{"id":"1.195532870","rc":[{"atb":[[2.8,3.73]],"id":5677052}],"con":true,"img":false}]}
{"op":"mcm","clk":"5322372973","pt":1646319415772,"mc":[{"id":"1.195532870","rc":[{"atb":[[2.48,0]],"id":41793694}],"con":true,"img":false}]}
{"op":"mcm","clk":"5322373169","pt":1646319418852,"mc":[{"id":"1.195532870","rc":[{"atb":[[2.78,6.3]],"id":41793694}],"con":true,"img":false}]}
{"op":"mcm","clk":"5322373205","pt":1646319419266,"mc":[{"id":"1.195532870","rc":[{"atb":[[2.44,0]],"id":43189003}],"con":true,"img":false}]}
{"op":"mcm","clk":"5322373448","pt":1646319422581,"mc":[{"id":"1.195532870","rc":[{"atb":[[2.74,0]],"id":41793694}],"con":true,"img":false}]}
{"op":"mcm","clk":"5322373474","pt":1646319422953,"mc":[{"id":"1.195532870","rc":[{"atb":[[1.65,19.1]],"id":43189003}],"con":true,"img":false}]}
{"op":"mcm","clk":"5322374396","pt":1646319434799,"mc":[{"id":"1.195532870","rc":[{"atb":[[2.74,0]],"id":5677052}],"con":true,"img":false}]}
{"op":"mcm","clk":"5322374817","pt":1646319440477,"mc":[{"id":"1.195532870","rc":[{"atb":[[2.4,4.8]],"id":43189003}],"con":true,"img":false}]}
{"op":"mcm","clk":"5322375022","pt":1646319443491,"mc":[{"id":"1.195532870","rc":[{"atb":[[2.8,0]],"id":5677052}],"con":true,"img":false}]}
{"op":"mcm","clk":"5322375861","pt":1646319455319,"mc":[{"id":"1.195532870","rc":[{"atb":[[2.68,4]],"id":41793694}],"con":true,"img":false}]}
{"op":"mcm","clk":"5322376121","pt":1646319459296,"mc":[{"id":"1.195532870","rc":[{"atb":[[2.84,5.38]],"id":41793694}],"con":true,"img":false}]}
{"op":"mcm","clk":"5322376440","pt":1646319464221,"mc":[{"id":"1.195532870","rc":[{"atb":[[2.78,3.78]],"id":5677052}],"con":true,"img":false}]}
{"op":"mcm","clk":"5322376633","pt":1646319467221,"mc":[{"id":"1.195532870","rc":[{"atb":[[2.68,0]],"id":41793694}],"con":true,"img":false}]}
{"op":"mcm","clk":"5322377067","pt":1646319474646,"mc":[{"id":"1.195532870","rc":[{"atb":[[2.44,6.88]],"id":43189003}],"con":true,"img":false}]}
{"op":"mcm","clk":"5322377579","pt":1646319482554,"mc":[{"id":"1.195532870","rc":[{"atb":[[2.4,0]],"id":43189003}],"con":true,"img":false}]}
{"op":"mcm","clk":"5322378057","pt":1646319488920,"mc":[{"id":"1.195532870","rc":[{"atb":[[4.5,0]],"id":40214166},{"atb":[[4.8,0]],"id":40214168}],"con":true,"img":false}]}
{"op":"mcm","clk":"5322378066","pt":1646319489133,"mc":[{"id":"1.195532870","rc":[{"atb":[[2.9,3.54]],"id":41793694}],"con":true,"img":false}]}
{"op":"mcm","clk":"5322378200","pt":1646319491337,"mc":[{"id":"1.195532870","rc":[{"atb":[[2.7,6.59]],"id":40214168}],"con":true,"img":false}]}
{"op":"mcm","clk":"5322378953","pt":1646319503449,"mc":[{"id":"1.195532870","rc":[{"atb":[[2.48,4.54]],"id":43189003}],"con":true,"img":false}]}
{"op":"mcm","clk":"5322383777","pt":1646319570933,"mc":[{"id":"1.195532870","rc":[{"atb":[[2.84,5.38]],"id":5677052}],"con":true,"img":false}]}
{"op":"mcm","clk":"5322383834","pt":1646319571666,"mc":[{"id":"1.195532870","rc":[{"atb":[[2.74,7.13]],"id":40214168}],"con":true,"img":false}]}
{"op":"mcm","clk":"5322383894","pt":1646319572345,"mc":[{"id":"1.195532870","rc":[{"atb":[[2.62,0]],"id":41793694}],"con":true,"img":false}]}
{"op":"mcm","clk":"5322384405","pt":1646319578576,"mc":[{"id":"1.195532870","rc":[{"atb":[[2.78,0]],"id":5677052}],"con":true,"img":false}]}
{"op":"mcm","clk":"5322384414","pt":1646319578685,"mc":[{"id":"1.195532870","rc":[{"atb":[[2.68,0]],"id":5677052}],"con":true,"img":false}]}
{"op":"mcm","clk":"5322384602","pt":1646319581348,"mc":[{"id":"1.195532870","rc":[{"atb":[[2.4,8]],"id":5677052}],"con":true,"img":false}]}
{"op":"mcm","clk":"5322385320","pt":1646319592091,"mc":[{"id":"1.195532870","rc":[{"atb":[[2.84,0]],"id":41793694},{"atb":[[2.44,0]],"id":43189003}],"con":true,"img":false}]}
{"op":"mcm","clk":"5322385347","pt":1646319592358,"mc":[{"id":"1.195532870","rc":[{"atb":[[2.88,6.6]],"id":41793694}],"con":true,"img":false}]}
{"op":"mcm","clk":"5322385840","pt":1646319599281,"mc":[{"id":"1.195532870","rc":[{"atb":[[2.9,0]],"id":41793694},{"atb":[[2.48,0]],"id":43189003}],"con":true,"img":false}]}
{"op":"mcm","clk":"5322385849","pt":1646319599384,"mc":[{"id":"1.195532870","rc":[{"atb":[[2.9,3.54]],"id":5677052}],"con":true,"img":false}]}
{"op":"mcm","clk":"5322386793","pt":1646319609918,"mc":[{"id":"1.195532870","rc":[{"atb":[[2.06,165.09],[2.04,8.53],[4.7,3.35]],"id":40214166},{"atl":[[150,5]],"id":40214166},{"atb":[[2,12.56],[2.74,7.14],[2.06,165.09],[2.7,6.6]],"id":40214168},{"atl":[[150,5]],"id":40214168},{"atb":[[2.4,8.01],[2.36,12.68],[2.72,7.22],[2.9,3.54],[2.84,5.39]],"id":5677052},{"atl":[[150,5],[5,1.65]],"id":5677052},{"atb":[[2.88,6.61],[2.32,12.56],[2.78,6.3]],"id":41793694},{"atl":[[150,5]],"id":41793694},{"atb":[[2.36,9.3],[1.63,17.82],[2.58,1.65],[1.65,19.13]],"id":43189003},{"atl":[[150,5]],"id":43189003},{"atb":[[4.8,2.95],[2.06,165.09],[2.08,11.31]],"id":42931076},{"atl":[[150,5]],"id":42931076}],"con":true,"img":false}]}
{"op":"mcm","clk":"5322387179","pt":1646319614936,"mc":[{"id":"1.195532870","rc":[{"atb":[[2.84,0]],"id":5677052}],"con":true,"img":false}]}
{"op":"mcm","clk":"5322387648","pt":1646319620434,"mc":[{"id":"1.195532870","rc":[{"atb":[[2.4,4.81]],"id":43189003}],"con":true,"img":false}]}
{"op":"mcm","clk":"5322387654","pt":1646319620539,"mc":[{"id":"1.195532870","rc":[{"atb":[[2.94,3.47]],"id":41793694}],"con":true,"img":false}]}
{"op":"mcm","clk":"5322387855","pt":1646319623526,"mc":[{"id":"1.195532870","rc":[{"atb":[[2.9,0]],"id":5677052}],"con":true,"img":false}]}
{"op":"mcm","clk":"5322389434","pt":1646319644668,"mc":[{"id":"1.195532870","rc":[{"atb":[[1.63,0]],"id":43189003}],"con":true,"img":false}]}
{"op":"mcm","clk":"5322389443","pt":1646319644782,"mc":[{"id":"1.195532870","rc":[{"atb":[[2.78,3.78]],"id":5677052}],"con":true,"img":false}]}
{"op":"mcm","clk":"5322389685","pt":1646319647640,"mc":[{"id":"1.195532870","rc":[{"atb":[[1.67,16.75]],"id":43189003}],"con":true,"img":false}]}
{"op":"mcm","clk":"5322390389","pt":1646319656457,"mc":[{"id":"1.195532870","rc":[{"atb":[[2.78,0]],"id":41793694}],"con":true,"img":false}]}
{"op":"mcm","clk":"5322390613","pt":1646319659486,"mc":[{"id":"1.195532870","rc":[{"atb":[[2.36,8.25]],"id":41793694}],"con":true,"img":false}]}
{"op":"mcm","clk":"5322400699","pt":1646319783773,"mc":[{"id":"1.195532870","rc":[{"atb":[[3,4.96]],"id":41793694}],"con":true,"img":false}]}
{"op":"mcm","clk":"5322400728","pt":1646319784084,"mc":[{"id":"1.195532870","rc":[{"atb":[[2.44,6.89]],"id":43189003}],"con":true,"img":false}]}
{"op":"mcm","clk":"5322401410","pt":1646319792090,"mc":[{"id":"1.195532870","rc":[{"atb":[[2.94,0]],"id":41793694},{"atb":[[2.4,0]],"id":43189003}],"con":true,"img":false}]}
{"op":"mcm","clk":"5322401690","pt":1646319795410,"mc":[{"id":"1.195532870","rc":[{"atb":[[2.04,0]],"id":40214166},{"atb":[[2,0]],"id":40214168}],"con":true,"img":false}]}
{"op":"mcm","clk":"5322401694","pt":1646319795513,"mc":[{"id":"1.195532870","rc":[{"atb":[[2.08,8.53]],"id":40214166},{"atb":[[2.08,12.56]],"id":40214168}],"con":true,"img":false}]}
{"op":"mcm","clk":"5322402410","pt":1646319803989,"mc":[{"id":"1.195532870","rc":[{"atb":[[2.7,0]],"id":40214168}],"con":true,"img":false}]}
{"op":"mcm","clk":"5322402544","pt":1646319806057,"mc":[{"id":"1.195532870","rc":[{"atb":[[4.7,0]],"id":40214166}],"con":true,"img":false}]}
{"op":"mcm","clk":"5322402587","pt":1646319806629,"mc":[{"id":"1.195532870","rc":[{"atb":[[2.78,6.3]],"id":40214168}],"con":true,"img":false}]}
{"op":"mcm","clk":"5322402617","pt":1646319807048,"mc":[{"id":"1.195532870","rc":[{"atb":[[2.66,6.76]],"id":40214166}],"con":true,"img":false}]}
{"op":"mcm","clk":"5322403288","pt":1646319816341,"mc":[{"id":"1.195532870","rc":[{"atb":[[2.48,4.55]],"id":43189003}],"con":true,"img":false}]}
{"op":"mcm","clk":"5322403307","pt":1646319816655,"mc":[{"id":"1.195532870","rc":[{"atb":[[3.05,3.28]],"id":41793694}],"con":true,"img":false}]}
{"op":"mcm","clk":"5322405244","pt":1646319840904,"mc":[{"id":"1.195532870","rc":[{"atb":[[2.84,5.39]],"id":5677052}],"con":true,"img":false}]}
{"op":"mcm","clk":"5322405273","pt":1646319841219,"mc":[{"id":"1.195532870","rc":[{"atb":[[2.7,7.31]],"id":40214166}],"con":true,"img":false}]}
{"op":"mcm","clk":"5322405374","pt":1646319842428,"mc":[{"id":"1.195532870","rc":[{"atb":[[3,0]],"id":41793694},{"atb":[[2.44,0]],"id":43189003}],"con":true,"img":false}]}
{"op":"mcm","clk":"5322405410","pt":1646319842885,"mc":[{"id":"1.195532870","rc":[{"atb":[[2.72,0]],"id":5677052}],"con":true,"img":false}]}
{"op":"mcm","clk":"5322405984","pt":1646319849508,"mc":[{"id":"1.195532870","rc":[{"atb":[[2.78,0]],"id":5677052},{"atb":[[3.05,0]],"id":41793694},{"atb":[[2.48,0]],"id":43189003}],"con":true,"img":false}]}
{"op":"mcm","clk":"5322407038","pt":1646319862424,"mc":[{"id":"1.195532870","rc":[{"atb":[[2.44,8.63]],"id":5677052}],"con":true,"img":false}]}
{"op":"mcm","clk":"5322407099","pt":1646319863210,"mc":[{"id":"1.195532870","rc":[{"atb":[[2.88,0]],"id":41793694}],"con":true,"img":false}]}
{"op":"mcm","clk":"5322407644","pt":1646319870339,"mc":[{"id":"1.195532870","rc":[{"atb":[[2.9,3.54]],"id":5677052}],"con":true,"img":false}]}
{"op":"mcm","clk":"5322407667","pt":1646319870633,"mc":[{"id":"1.195532870","rc":[{"atb":[[2.4,4.81]],"id":43189003}],"con":true,"img":false}]}
{"op":"mcm","clk":"5322408266","pt":1646319878578,"mc":[{"id":"1.195532870","rc":[{"atb":[[2.84,0]],"id":5677052}],"con":true,"img":false}]}
{"op":"mcm","clk":"5322408308","pt":1646319879099,"mc":[{"id":"1.195532870","rc":[{"atb":[[2.4,8.87]],"id":41793694}],"con":true,"img":false}]}
{"op":"mcm","clk":"5322408981","pt":1646319888082,"mc":[{"id":"1.195532870","rc":[{"atb":[[2.9,0]],"id":5677052}],"con":true,"img":false}]}
{"op":"mcm","clk":"5322409359","pt":1646319892900,"mc":[{"id":"1.195532870","rc":[{"atb":[[2.4,15.97]],"id":41793694}],"con":true,"img":false}]}
{"op":"mcm","clk":"5322410379","pt":1646319904950,"mc":[{"id":"1.195532870","rc":[{"atb":[[2.44,6.89]],"id":43189003}],"con":true,"img":false}]}
{"op":"mcm","clk":"5322410765","pt":1646319909342,"mc":[{"id":"1.195532870","rc":[{"atb":[[2.48,4.55]],"id":5677052},{"atb":[[2.44,4.67]],"id":41793694}],"con":true,"img":false}]}
{"op":"mcm","clk":"5322411029","pt":1646319912117,"mc":[{"id":"1.195532870","rc":[{"atb":[[2.4,0]],"id":43189003}],"con":true,"img":false}]}
{"op":"mcm","clk":"5322412163","pt":1646319925377,"mc":[{"id":"1.195532870","rc":[{"atb":[[2.4,8.87]],"id":41793694},{"atb":[[2.44,0]],"id":43189003}],"con":true,"img":false}]}
{"op":"mcm","clk":"5322413604","pt":1646319943226,"mc":[{"id":"1.195532870","rc":[{"atb":[[2.48,6.7]],"id":41793694}],"con":true,"img":false}]}
{"op":"mcm","clk":"5322413629","pt":1646319943488,"mc":[{"id":"1.195532870","rc":[{"atb":[[2.4,7.09]],"id":43189003}],"con":true,"img":false}]}
{"op":"mcm","clk":"5322413655","pt":1646319943904,"mc":[{"id":"1.195532870","rc":[{"atb":[[2.52,6.53]],"id":5677052}],"con":true,"img":false}]}
{"op":"mcm","clk":"5322414424","pt":1646319954225,"mc":[{"id":"1.195532870","rc":[{"atb":[[2.48,0]],"id":5677052},{"atb":[[2.44,0]],"id":41793694}],"con":true,"img":false}]}
{"op":"mcm","clk":"5322415504","pt":1646319965725,"mc":[{"id":"1.195532870","rc":[{"atb":[[2.52,0]],"id":5677052},{"atb":[[2.48,0]],"id":41793694}],"con":true,"img":false}]}
{"op":"mcm","clk":"5322416066","pt":1646319972848,"mc":[{"id":"1.195532870","rc":[{"atb":[[2.44,4.67]],"id":43189003}],"con":true,"img":false}]}
{"op":"mcm","clk":"5322417434","pt":1646319988865,"mc":[{"id":"1.195532870","rc":[{"atb":[[2.4,15.97]],"id":41793694}],"con":true,"img":false}]}
{"op":"mcm","clk":"5322417446","pt":1646319989072,"mc":[{"id":"1.195532870","rc":[{"atb":[[2.4,0]],"id":43189003}],"con":true,"img":false}]}
{"op":"mcm","clk":"5322417464","pt":1646319989383,"mc":[{"id":"1.195532870","rc":[{"atb":[[2.44,15.53]],"id":5677052}],"con":true,"img":false}]}
{"op":"mcm","clk":"5322417733","pt":1646319993058,"mc":[{"id":"1.195532870","rc":[{"atb":[[2.44,4.67]],"id":41793694}],"con":true,"img":false}]}
{"op":"mcm","clk":"5322417740","pt":1646319993167,"mc":[{"id":"1.195532870","rc":[{"atb":[[2.48,4.55]],"id":5677052}],"con":true,"img":false}]}
{"op":"mcm","clk":"5322417972","pt":1646319996505,"mc":[{"id":"1.195532870","rc":[{"atb":[[2.44,0]],"id":43189003}],"con":true,"img":false}]}
{"op":"mcm","clk":"5322419257","pt":1646320011023,"mc":[{"id":"1.195532870","rc":[{"atb":[[2.44,8.63]],"id":5677052},{"atb":[[2.4,8.87]],"id":41793694}],"con":true,"img":false}]}
{"op":"mcm","clk":"5322419716","pt":1646320017424,"mc":[{"id":"1.195532870","rc":[{"atb":[[2.4,4.81]],"id":43189003}],"con":true,"img":false}]}
{"op":"mcm","clk":"5322420110","pt":1646320021862,"mc":[{"id":"1.195532870","rc":[{"atb":[[1.65,0]],"id":43189003}],"con":true,"img":false}]}
{"op":"mcm","clk":"5322421308","pt":1646320035070,"mc":[{"id":"1.195532870","rc":[{"atb":[[1.69,18.02]],"id":43189003}],"con":true,"img":false}]}
{"op":"mcm","clk":"5322421317","pt":1646320035173,"mc":[{"id":"1.195532870","rc":[{"atb":[[2.48,6.7]],"id":41793694}],"con":true,"img":false}]}
{"op":"mcm","clk":"5322421351","pt":1646320035482,"mc":[{"id":"1.195532870","rc":[{"atb":[[2.52,6.53]],"id":5677052}],"con":true,"img":false}]}
{"op":"mcm","clk":"5322421929","pt":1646320041849,"mc":[{"id":"1.195532870","rc":[{"atb":[[2.44,0]],"id":41793694}],"con":true,"img":false}]}
{"op":"mcm","clk":"5322422124","pt":1646320044446,"mc":[{"id":"1.195532870","rc":[{"atb":[[2.48,0]],"id":5677052}],"con":true,"img":false}]}
{"op":"mcm","clk":"5322422540","pt":1646320049491,"mc":[{"id":"1.195532870","rc":[{"atb":[[2.74,0]],"id":40214168},{"atb":[[2.44,6.89]],"id":43189003}],"con":true,"img":false}]}
{"op":"mcm","clk":"5322423156","pt":1646320056799,"mc":[{"id":"1.195532870","rc":[{"atb":[[2.4,0]],"id":43189003}],"con":true,"img":false}]}
{"op":"mcm","clk":"5322423645","pt":1646320062888,"mc":[{"id":"1.195532870","rc":[{"atb":[[2.52,4.43]],"id":41793694}],"con":true,"img":false}]}
{"op":"mcm","clk":"5322423772","pt":1646320064108,"mc":[{"id":"1.195532870","rc":[{"atb":[[2.52,0]],"id":5677052},{"atb":[[2.48,0]],"id":41793694}],"con":true,"img":false}]}
{"op":"mcm","clk":"5322423806","pt":1646320064377,"mc":[{"id":"1.195532870","rc":[{"atb":[[2.82,6.83]],"id":40214168}],"con":true,"img":false}]}
{"op":"mcm","clk":"5322424503","pt":1646320072294,"mc":[{"id":"1.195532870","rc":[{"atb":[[2.52,0]],"id":41793694}],"con":true,"img":false}]}
{"op":"mcm","clk":"5322424665","pt":1646320074689,"mc":[{"id":"1.195532870","rc":[{"atb":[[2.66,0]],"id":40214166}],"con":true,"img":false}]}
{"op":"mcm","clk":"5322424893","pt":1646320077605,"mc":[{"id":"1.195532870","rc":[{"atb":[[2.48,4.55]],"id":43189003}],"con":true,"img":false}]}
{"op":"mcm","clk":"5322424923","pt":1646320078021,"mc":[{"id":"1.195532870","rc":[{"atb":[[2.74,6.45]],"id":40214166}],"con":true,"img":false}]}
{"op":"mcm","clk":"5322425103","pt":1646320080008,"mc":[{"id":"1.195532870","rc":[{"atb":[[2.44,15.53]],"id":5677052}],"con":true,"img":false}]}
{"op":"mcm","clk":"5322425129","pt":1646320080325,"mc":[{"id":"1.195532870","rc":[{"atb":[[2.44,0]],"id":43189003}],"con":true,"img":false}]}
{"op":"mcm","clk":"5322425159","pt":1646320080651,"mc":[{"id":"1.195532870","rc":[{"atb":[[2.4,15.97]],"id":41793694}],"con":true,"img":false}]}
{"op":"mcm","clk":"5322425834","pt":1646320089742,"mc":[{"id":"1.195532870","rc":[{"atb":[[2.48,0]],"id":43189003}],"con":true,"img":false}]}
{"op":"mcm","clk":"5322426012","pt":1646320092455,"mc":[{"id":"1.195532870","rc":[{"atb":[[2.48,4.55]],"id":5677052}],"con":true,"img":false}]}
{"op":"mcm","clk":"5322426293","pt":1646320096036,"mc":[{"id":"1.195532870","rc":[{"atb":[[2.4,0]],"id":5677052},{"atb":[[2.44,4.67]],"id":41793694}],"con":true,"img":false}]}
{"op":"mcm","clk":"5322426528","pt":1646320098745,"mc":[{"id":"1.195532870","rc":[{"atb":[[2.48,12.13]],"id":5677052}],"con":true,"img":false}]}
{"op":"mcm","clk":"5322427431","pt":1646320110350,"mc":[{"id":"1.195532870","rc":[{"atb":[[2.4,4.81]],"id":43189003}],"con":true,"img":false}]}
{"op":"mcm","clk":"5322427537","pt":1646320111869,"mc":[{"id":"1.195532870","rc":[{"atb":[[2.44,8.63]],"id":5677052},{"atb":[[2.4,8.87]],"id":41793694}],"con":true,"img":false}]}
{"op":"mcm","clk":"5322427664","pt":1646320113487,"mc":[{"id":"1.195532870","rc":[{"atb":[[2.36,0]],"id":41793694}],"con":true,"img":false}]}
{"op":"mcm","clk":"5322427900","pt":1646320116460,"mc":[{"id":"1.195532870","rc":[{"atb":[[2.44,12.47]],"id":41793694}],"con":true,"img":false}]}
{"op":"mcm","clk":"5322428526","pt":1646320124305,"mc":[{"id":"1.195532870","rc":[{"atb":[[2.52,6.53]],"id":5677052}],"con":true,"img":false}]}
{"op":"mcm","clk":"5322428530","pt":1646320124410,"mc":[{"id":"1.195532870","rc":[{"atb":[[2.48,6.7]],"id":41793694}],"con":true,"img":false}]}
{"op":"mcm","clk":"5322429220","pt":1646320131985,"mc":[{"id":"1.195532870","rc":[{"atb":[[2.48,7.58]],"id":5677052},{"atb":[[2.44,7.79]],"id":41793694}],"con":true,"img":false}]}
{"op":"mcm","clk":"5322430617","pt":1646320148819,"mc":[{"id":"1.195532870","rc":[{"atb":[[2.44,6.89]],"id":43189003}],"con":true,"img":false}]}
{"op":"mcm","clk":"5322430637","pt":1646320149132,"mc":[{"id":"1.195532870","rc":[{"atb":[[2.44,0]],"id":5677052},{"atb":[[2.4,0]],"id":41793694}],"con":true,"img":false}]}
{"op":"mcm","clk":"5322430994","pt":1646320153670,"mc":[{"id":"1.195532870","rc":[{"atb":[[2.52,4.43]],"id":41793694}],"con":true,"img":false}]}
{"op":"mcm","clk":"5322431013","pt":1646320153878,"mc":[{"id":"1.195532870","rc":[{"atb":[[2.58,4.26]],"id":5677052}],"con":true,"img":false}]}
{"op":"mcm","clk":"5322431154","pt":1646320155445,"mc":[{"id":"1.195532870","rc":[{"atb":[[2.4,0]],"id":43189003}],"con":true,"img":false}]}
{"op":"mcm","clk":"5322431518","pt":1646320159990,"mc":[{"id":"1.195532870","rc":[{"atb":[[2.56,7.97]],"id":41793694}],"con":true,"img":false}]}
{"op":"mcm","clk":"5322431529","pt":1646320160089,"mc":[{"id":"1.195532870","rc":[{"atb":[[2.62,7.67]],"id":5677052}],"con":true,"img":false}]}
{"op":"mcm","clk":"5322432183","pt":1646320167829,"mc":[{"id":"1.195532870","rc":[{"atb":[[2.58,0]],"id":5677052},{"atb":[[2.52,0]],"id":41793694}],"con":true,"img":false}]}
{"op":"mcm","clk":"5322432493","pt":1646320171809,"mc":[{"id":"1.195532870","rc":[{"atb":[[2.44,0]],"id":43189003}],"con":true,"img":false}]}
{"op":"mcm","clk":"5322433920","pt":1646320188924,"mc":[{"id":"1.195532870","rc":[{"atb":[[2.62,4.16]],"id":41793694}],"con":true,"img":false}]}
{"op":"mcm","clk":"5322433929","pt":1646320189031,"mc":[{"id":"1.195532870","rc":[{"atb":[[2.68,4.01]],"id":5677052}],"con":true,"img":false}]}
{"op":"mcm","clk":"5322434548","pt":1646320196667,"mc":[{"id":"1.195532870","rc":[{"atb":[[2.52,0]],"id":5677052},{"atb":[[2.48,0]],"id":41793694}],"con":true,"img":false}]}
{"op":"mcm","clk":"5322434556","pt":1646320196766,"mc":[{"id":"1.195532870","rc":[{"atb":[[2.4,7.09]],"id":43189003}],"con":true,"img":false}]}
{"op":"mcm","clk":"5322437364","pt":1646320229021,"mc":[{"id":"1.195532870","rc":[{"atb":[[2.44,4.67]],"id":43189003}],"con":true,"img":false}]}
{"op":"mcm","clk":"5322437490","pt":1646320230428,"mc":[{"id":"1.195532870","rc":[{"atb":[[2.68,5.91]],"id":41793694}],"con":true,"img":false}]}
{"op":"mcm","clk":"5322437544","pt":1646320231010,"mc":[{"id":"1.195532870","rc":[{"atb":[[2.74,5.7]],"id":5677052}],"con":true,"img":false}]}
{"op":"mcm","clk":"5322438374","pt":1646320239918,"mc":[{"id":"1.195532870","rc":[{"atb":[[2.68,0]],"id":5677052},{"atb":[[2.62,0]],"id":41793694}],"con":true,"img":false}]}
{"op":"mcm","clk":"5322438520","pt":1646320241809,"mc":[{"id":"1.195532870","rc":[{"atb":[[2.4,0]],"id":43189003}],"con":true,"img":false}]}
{"op":"mcm","clk":"5322439133","pt":1646320248857,"mc":[{"id":"1.195532870","rc":[{"atb":[[2.44,0]],"id":43189003}],"con":true,"img":false}]}
{"op":"mcm","clk":"5322439528","pt":1646320253421,"mc":[{"id":"1.195532870","rc":[{"atb":[[2.74,0]],"id":5677052},{"atb":[[2.68,0]],"id":41793694}],"con":true,"img":false}]}
{"op":"mcm","clk":"5322439642","pt":1646320254830,"mc":[{"id":"1.195532870","rc":[{"atb":[[1.67,0]],"id":43189003}],"con":true,"img":false}]}
{"op":"mcm","clk":"5322439956","pt":1646320258737,"mc":[{"id":"1.195532870","rc":[{"atb":[[1.71,15.81]],"id":43189003}],"con":true,"img":false}]}
{"op":"mcm","clk":"5322440989","pt":1646320269968,"mc":[{"id":"1.195532870","rc":[{"atb":[[2.4,4.81]],"id":43189003}],"con":true,"img":false}]}
{"op":"mcm","clk":"5322441758","pt":1646320277876,"mc":[{"id":"1.195532870","rc":[{"atb":[[2.48,6.7]],"id":41793694}],"con":true,"img":false}]}
{"op":"mcm","clk":"5322441781","pt":1646320278102,"mc":[{"id":"1.195532870","rc":[{"atb":[[2.52,6.53]],"id":5677052}],"con":true,"img":false}]}
{"op":"mcm","clk":"5322442111","pt":1646320281881,"mc":[{"id":"1.195532870","rc":[{"atb":[[2.68,4.01]],"id":5677052}],"con":true,"img":false}]}
{"op":"mcm","clk":"5322442124","pt":1646320281992,"mc":[{"id":"1.195532870","rc":[{"atb":[[2.62,4.16]],"id":41793694}],"con":true,"img":false}]}
{"op":"mcm","clk":"5322442147","pt":1646320282197,"mc":[{"id":"1.195532870","rc":[{"atb":[[2.78,0]],"id":40214168}],"con":true,"img":false}]}
{"op":"mcm","clk":"5322442485","pt":1646320285277,"mc":[{"id":"1.195532870","rc":[{"atb":[[2.86,6.03]],"id":40214168}],"con":true,"img":false}]}
{"op":"mcm","clk":"5322446028","pt":1646320305745,"mc":[{"id":"1.195532870","rc":[{"atb":[[2.52,0]],"id":5677052},{"atb":[[2.48,0]],"id":41793694}],"con":true,"img":false}]}
{"op":"mcm","clk":"5322446075","pt":1646320306169,"mc":[{"id":"1.195532870","rc":[{"atb":[[2.44,6.89]],"id":43189003}],"con":true,"img":false}]}
{"op":"mcm","clk":"5322446970","pt":1646320315756,"mc":[{"id":"1.195532870","rc":[{"atb":[[2.4,0]],"id":43189003}],"con":true,"img":false}]}
{"op":"mcm","clk":"5322447166","pt":1646320317944,"mc":[{"id":"1.195532870","rc":[{"atb":[[2.68,5.91]],"id":41793694}],"con":true,"img":false}]}
{"op":"mcm","clk":"5322447186","pt":1646320318252,"mc":[{"id":"1.195532870","rc":[{"atb":[[2.7,0]],"id":40214166},{"atb":[[2.74,5.7]],"id":5677052}],"con":true,"img":false}]}
{"op":"mcm","clk":"5322447959","pt":1646320327497,"mc":[{"id":"1.195532870","rc":[{"atb":[[2.68,0]],"id":5677052},{"atb":[[2.62,0]],"id":41793694}],"con":true,"img":false}]}
{"op":"mcm","clk":"5322448409","pt":1646320333073,"mc":[{"id":"1.195532870","rc":[{"atb":[[2.44,0]],"id":43189003}],"con":true,"img":false}]}
{"op":"mcm","clk":"5322448464","pt":1646320333654,"mc":[{"id":"1.195532870","rc":[{"atb":[[2.78,6.98]],"id":40214166}],"con":true,"img":false}]}
{"op":"mcm","clk":"5322449710","pt":1646320347869,"mc":[{"id":"1.195532870","rc":[{"atb":[[2.74,3.86]],"id":41793694}],"con":true,"img":false}]}
{"op":"mcm","clk":"5322449717","pt":1646320347977,"mc":[{"id":"1.195532870","rc":[{"atb":[[2.8,3.74]],"id":5677052}],"con":true,"img":false}]}
{"op":"mcm","clk":"5322449765","pt":1646320348505,"mc":[{"id":"1.195532870","rc":[{"atb":[[2.74,0]],"id":5677052},{"atb":[[2.68,0]],"id":41793694},{"atb":[[2.4,7.09]],"id":43189003}],"con":true,"img":false}]}
{"op":"mcm","clk":"5322450528","pt":1646320357225,"mc":[{"id":"1.195532870","rc":[{"atb":[[2.48,0]],"id":5677052},{"atb":[[2.44,0]],"id":41793694}],"con":true,"img":false}]}
{"op":"mcm","clk":"5322450534","pt":1646320357336,"mc":[{"id":"1.195532870","rc":[{"atb":[[2.8,0]],"id":5677052},{"atb":[[2.74,0]],"id":41793694}],"con":true,"img":false}]}
{"op":"mcm","clk":"5322450754","pt":1646320360112,"mc":[{"id":"1.195532870","rc":[{"atb":[[2.66,6.76]],"id":5677052},{"atb":[[2.6,7.02]],"id":41793694}],"con":true,"img":false}]}
{"op":"mcm","clk":"5322452310","pt":1646320378236,"mc":[{"id":"1.195532870","rc":[{"atb":[[2.68,4.01]],"id":5677052},{"atb":[[2.44,4.67]],"id":43189003}],"con":true,"img":false}]}
{"op":"mcm","clk":"5322452334","pt":1646320378441,"mc":[{"id":"1.195532870","rc":[{"atb":[[2.62,4.16]],"id":41793694}],"con":true,"img":false}]}
{"op":"mcm","clk":"5322453814","pt":1646320395377,"mc":[{"id":"1.195532870","rc":[{"atb":[[2.4,0]],"id":43189003}],"con":true,"img":false}]}
{"op":"mcm","clk":"5322454462","pt":1646320403176,"mc":[{"id":"1.195532870","rc":[{"atb":[[2.44,0]],"id":43189003}],"con":true,"img":false}]}
{"op":"mcm","clk":"5322454575","pt":1646320404579,"mc":[{"id":"1.195532870","rc":[{"atb":[[2.62,0]],"id":5677052},{"atb":[[2.56,0]],"id":41793694}],"con":true,"img":false}]}
{"op":"mcm","clk":"5322455134","pt":1646320411574,"mc":[{"id":"1.195532870","rc":[{"atb":[[2.68,0]],"id":5677052},{"atb":[[2.62,0]],"id":41793694}],"con":true,"img":false}]}
{"op":"mcm","clk":"5322455544","pt":1646320416675,"mc":[{"id":"1.195532870","rc":[{"atb":[[2.64,7.58]],"id":41793694}],"con":true,"img":false}]}
{"op":"mcm","clk":"5322455577","pt":1646320416993,"mc":[{"id":"1.195532870","rc":[{"atb":[[2.7,7.31]],"id":5677052}],"con":true,"img":false}]}
{"op":"mcm","clk":"5322456128","pt":1646320423417,"mc":[{"id":"1.195532870","rc":[{"atb":[[2.4,4.81]],"id":43189003}],"con":true,"img":false}]}
{"op":"mcm","clk":"5322457976","pt":1646320444555,"mc":[{"id":"1.195532870","rc":[{"atb":[[2.7,3.95]],"id":41793694}],"con":true,"img":false}]}
{"op":"mcm","clk":"5322458196","pt":1646320447301,"mc":[{"id":"1.195532870","rc":[{"atb":[[2.76,3.82]],"id":5677052}],"con":true,"img":false}]}
{"op":"mcm","clk":"5322458776","pt":1646320453964,"mc":[{"id":"1.195532870","rc":[{"atb":[[2.44,6.89]],"id":43189003}],"con":true,"img":false}]}
{"op":"mcm","clk":"5322459504","pt":1646320462378,"mc":[{"id":"1.195532870","rc":[{"atb":[[2.4,0]],"id":43189003}],"con":true,"img":false}]}
{"op":"mcm","clk":"5322460658","pt":1646320476700,"mc":[{"id":"1.195532870","rc":[{"atb":[[2.44,0]],"id":43189003}],"con":true,"img":false}]}
{"op":"mcm","clk":"5322461405","pt":1646320486119,"mc":[{"id":"1.195532870","rc":[{"atb":[[2.76,5.63]],"id":41793694}],"con":true,"img":false}]}
{"op":"mcm","clk":"5322461431","pt":1646320486488,"mc":[{"id":"1.195532870","rc":[{"atb":[[2.82,5.46]],"id":5677052}],"con":true,"img":false}]}
{"op":"mcm","clk":"5322462082","pt":1646320495425,"mc":[{"id":"1.195532870","rc":[{"atb":[[2.76,0]],"id":5677052},{"atb":[[2.7,0]],"id":41793694}],"con":true,"img":false}]}
{"op":"mcm","clk":"5322462325","pt":1646320498608,"mc":[{"id":"1.195532870","rc":[{"atb":[[2.4,7.09]],"id":43189003}],"con":true,"img":false}]}
{"op":"mcm","clk":"5322462363","pt":1646320499023,"mc":[{"id":"1.195532870","rc":[{"atb":[[1.69,0]],"id":43189003}],"con":true,"img":false}]}
{"op":"mcm","clk":"5322463446","pt":1646320513240,"mc":[{"id":"1.195532870","rc":[{"atb":[[2.82,0]],"id":5677052},{"atb":[[2.76,0]],"id":41793694}],"con":true,"img":false}]}
{"op":"mcm","clk":"5322463469","pt":1646320513553,"mc":[{"id":"1.195532870","rc":[{"atb":[[1.73,17.03]],"id":43189003}],"con":true,"img":false}]}
{"op":"mcm","clk":"5322464675","pt":1646320527853,"mc":[{"id":"1.195532870","rc":[{"atb":[[2.72,5.77]],"id":5677052}],"con":true,"img":false}]}
{"op":"mcm","clk":"5322464704","pt":1646320528166,"mc":[{"id":"1.195532870","rc":[{"atb":[[2.66,5.97]],"id":41793694}],"con":true,"img":false}]}
{"op":"mcm","clk":"5322464713","pt":1646320528270,"mc":[{"id":"1.195532870","rc":[{"atb":[[2.82,0]],"id":40214168}],"con":true,"img":false}]}
{"op":"mcm","clk":"5322464805","pt":1646320529281,"mc":[{"id":"1.195532870","rc":[{"atb":[[2.44,4.67]],"id":43189003}],"con":true,"img":false}]}
{"op":"mcm","clk":"5322465664","pt":1646320540011,"mc":[{"id":"1.195532870","rc":[{"atb":[[2.9,6.54]],"id":40214168}],"con":true,"img":false}]}
{"op":"mcm","clk":"5322466671","pt":1646320552117,"mc":[{"id":"1.195532870","rc":[{"atb":[[2.4,0]],"id":43189003}],"con":true,"img":false}]}
{"op":"mcm","clk":"5322466836","pt":1646320554000,"mc":[{"id":"1.195532870","rc":[{"atb":[[2.74,0]],"id":40214166}],"con":true,"img":false}]}
{"op":"mcm","clk":"5322467224","pt":1646320558208,"mc":[{"id":"1.195532870","rc":[{"atb":[[2.72,3.91]],"id":41793694}],"con":true,"img":false}]}
{"op":"mcm","clk":"5322467231","pt":1646320558313,"mc":[{"id":"1.195532870","rc":[{"atb":[[2.78,3.78]],"id":5677052}],"con":true,"img":false}]}
{"op":"mcm","clk":"5322467257","pt":1646320558625,"mc":[{"id":"1.195532870","rc":[{"atb":[[2.82,6.16]],"id":40214166}],"con":true,"img":false}]}
{"op":"mcm","clk":"5322467697","pt":1646320563300,"mc":[{"id":"1.195532870","rc":[{"atb":[[2.44,0]],"id":43189003}],"con":true,"img":false}]}
{"op":"mcm","clk":"5322468843","pt":1646320576632,"mc":[{"id":"1.195532870","rc":[{"atb":[[2.72,0]],"id":5677052},{"atb":[[2.66,0]],"id":41793694}],"con":true,"img":false}]}
{"op":"mcm","clk":"5322469152","pt":1646320580172,"mc":[{"id":"1.195532870","rc":[{"atb":[[2.4,4.81]],"id":43189003}],"con":true,"img":false}]}
{"op":"mcm","clk":"5322469595","pt":1646320585971,"mc":[{"id":"1.195532870","rc":[{"atb":[[2.78,0]],"id":5677052},{"atb":[[2.72,0]],"id":41793694}],"con":true,"img":false}]}
{"op":"mcm","clk":"5322471304","pt":1646320607079,"mc":[{"id":"1.195532870","rc":[{"atb":[[2.76,3.82]],"id":5677052}],"con":true,"img":false}]}
{"op":"mcm","clk":"5322471313","pt":1646320607182,"mc":[{"id":"1.195532870","rc":[{"atb":[[2.7,3.95]],"id":41793694}],"con":true,"img":false}]}
{"op":"mcm","clk":"5322472244","pt":1646320618727,"mc":[{"id":"1.195532870","rc":[{"atb":[[2.44,6.89]],"id":43189003}],"con":true,"img":false}]}
{"op":"mcm","clk":"5322472995","pt":1646320628202,"mc":[{"id":"1.195532870","rc":[{"atb":[[2.4,0]],"id":43189003}],"con":true,"img":false}]}
{"op":"mcm","clk":"5322473728","pt":1646320636840,"mc":[{"id":"1.195532870","rc":[{"atb":[[2.66,0]],"id":5677052},{"atb":[[2.6,0]],"id":41793694}],"con":true,"img":false}]}
{"op":"mcm","clk":"5322473972","pt":1646320639817,"mc":[{"id":"1.195532870","rc":[{"atb":[[2.68,6.68]],"id":41793694}],"con":true,"img":false}]}
{"op":"mcm","clk":"5322473989","pt":1646320640024,"mc":[{"id":"1.195532870","rc":[{"atb":[[2.4,8.01]],"id":5677052}],"con":true,"img":false}]}
{"op":"mcm","clk":"5322474186","pt":1646320642524,"mc":[{"id":"1.195532870","rc":[{"atb":[[2.44,0]],"id":43189003}],"con":true,"img":false}]}
{"op":"mcm","clk":"5322474878","pt":1646320651359,"mc":[{"id":"1.195532870","rc":[{"atb":[[2.82,5.46]],"id":5677052}],"con":true,"img":false}]}
{"op":"mcm","clk":"5322474885","pt":1646320651464,"mc":[{"id":"1.195532870","rc":[{"atb":[[2.76,5.63]],"id":41793694}],"con":true,"img":false}]}
{"op":"mcm","clk":"5322475660","pt":1646320661084,"mc":[{"id":"1.195532870","rc":[{"atb":[[2.76,0]],"id":5677052},{"atb":[[2.7,0]],"id":41793694}],"con":true,"img":false}]}
{"op":"mcm","clk":"5322475881","pt":1646320663855,"mc":[{"id":"1.195532870","rc":[{"atb":[[2.4,7.09]],"id":43189003}],"con":true,"img":false}]}
{"op":"mcm","clk":"5322476646","pt":1646320673174,"mc":[{"id":"1.195532870","rc":[{"atb":[[2.82,0]],"id":5677052},{"atb":[[2.76,0]],"id":41793694}],"con":true,"img":false}]}
{"op":"mcm","clk":"5322477607","pt":1646320684745,"mc":[{"id":"1.195532870","rc":[{"atb":[[2.64,0]],"id":41793694}],"con":true,"img":false}]}
{"op":"mcm","clk":"5322478377","pt":1646320694011,"mc":[{"id":"1.195532870","rc":[{"atb":[[2.44,4.67]],"id":43189003}],"con":true,"img":false}]}
{"op":"mcm","clk":"5322478585","pt":1646320696417,"mc":[{"id":"1.195532870","rc":[{"atb":[[2.74,5.7]],"id":41793694}],"con":true,"img":false}]}
{"op":"mcm","clk":"5322478609","pt":1646320696625,"mc":[{"id":"1.195532870","rc":[{"atb":[[2.72,7.22]],"id":41793694}],"con":true,"img":false}]}
{"op":"mcm","clk":"5322478616","pt":1646320696729,"mc":[{"id":"1.195532870","rc":[{"atb":[[2.44,6.89]],"id":5677052}],"con":true,"img":false}]}
{"op":"mcm","clk":"5322479137","pt":1646320703261,"mc":[{"id":"1.195532870","rc":[{"atb":[[2.76,3.82]],"id":5677052}],"con":true,"img":false}]}
{"op":"mcm","clk":"5322479297","pt":1646320705864,"mc":[{"id":"1.195532870","rc":[{"atb":[[2.4,0]],"id":43189003}],"con":true,"img":false}]}
{"op":"mcm","clk":"5322479917","pt":1646320715177,"mc":[{"id":"1.195532870","rc":[{"atb":[[2.44,0]],"id":43189003}],"con":true,"img":false}]}
{"op":"mcm","clk":"5322479923","pt":1646320715279,"mc":[{"id":"1.195532870","rc":[{"atb":[[2.44,0]],"id":5677052}],"con":true,"img":false}]}
{"op":"mcm","clk":"5322480581","pt":1646320724284,"mc":[{"id":"1.195532870","rc":[{"atb":[[2.8,3.74]],"id":41793694}],"con":true,"img":false}]}
{"op":"mcm","clk":"5322481200","pt":1646320732465,"mc":[{"id":"1.195532870","rc":[{"atb":[[2.82,5.46]],"id":5677052}],"con":true,"img":false}]}
{"op":"mcm","clk":"5322481243","pt":1646320733091,"mc":[{"id":"1.195532870","rc":[{"atb":[[1.71,0]],"id":43189003}],"con":true,"img":false}]}
{"op":"mcm","clk":"5322481480","pt":1646320736191,"mc":[{"id":"1.195532870","rc":[{"atb":[[2.4,4.81]],"id":43189003}],"con":true,"img":false}]}
{"op":"mcm","clk":"5322481489","pt":1646320736294,"mc":[{"id":"1.195532870","rc":[{"atb":[[1.75,14.96]],"id":43189003}],"con":true,"img":false}]}
{"op":"mcm","clk":"5322481707","pt":1646320739248,"mc":[{"id":"1.195532870","rc":[{"atb":[[2.76,0]],"id":5677052}],"con":true,"img":false}]}
{"op":"mcm","clk":"5322481925","pt":1646320741701,"mc":[{"id":"1.195532870","rc":[{"atb":[[2.74,0]],"id":41793694}],"con":true,"img":false}]}
{"op":"mcm","clk":"5322482415","pt":1646320748286,"mc":[{"id":"1.195532870","rc":[{"atb":[[2.8,0]],"id":41793694}],"con":true,"img":false}]}
{"op":"mcm","clk":"5322482837","pt":1646320753872,"mc":[{"id":"1.195532870","rc":[{"atb":[[2.82,0]],"id":5677052}],"con":true,"img":false}]}
{"op":"mcm","clk":"5322483386","pt":1646320760272,"mc":[{"id":"1.195532870","rc":[{"atb":[[2.86,0]],"id":40214168}],"con":true,"img":false}]}
{"op":"mcm","clk":"5322483616","pt":1646320762990,"mc":[{"id":"1.195532870","rc":[{"atb":[[2.94,5.78]],"id":40214168}],"con":true,"img":false}]}
{"op":"mcm","clk":"5322483908","pt":1646320766864,"mc":[{"id":"1.195532870","rc":[{"atb":[[2.44,6.89]],"id":43189003}],"con":true,"img":false}]}
{"op":"mcm","clk":"5322483927","pt":1646320767180,"mc":[{"id":"1.195532870","rc":[{"atb":[[2.44,6.89]],"id":5677052}],"con":true,"img":false}]}
{"op":"mcm","clk":"5322484194","pt":1646320770276,"mc":[{"id":"1.195532870","rc":[{"atb":[[2.78,3.78]],"id":41793694}],"con":true,"img":false}]}
{"op":"mcm","clk":"5322484773","pt":1646320778325,"mc":[{"id":"1.195532870","rc":[{"atb":[[2.4,0]],"id":43189003}],"con":true,"img":false}]}
{"op":"mcm","clk":"5322485266","pt":1646320784936,"mc":[{"id":"1.195532870","rc":[{"atb":[[2.76,3.82]],"id":5677052}],"con":true,"img":false}]}
{"op":"mcm","clk":"5322486251","pt":1646320796156,"mc":[{"id":"1.195532870","rc":[{"atb":[[2.48,4.55]],"id":43189003}],"con":true,"img":false}]}
{"op":"mcm","clk":"5322486863","pt":1646320803163,"mc":[{"id":"1.195532870","rc":[{"atb":[[2.44,0]],"id":43189003}],"con":true,"img":false}]}
{"op":"mcm","clk":"5322486917","pt":1646320803852,"mc":[{"id":"1.195532870","rc":[{"atb":[[2.78,0]],"id":40214166}],"con":true,"img":false}]}
{"op":"mcm","clk":"5322487480","pt":1646320811259,"mc":[{"id":"1.195532870","rc":[{"atb":[[2.48,0]],"id":43189003}],"con":true,"img":false}]}
{"op":"mcm","clk":"5322488272","pt":1646320820474,"mc":[{"id":"1.195532870","rc":[{"atb":[[2.44,0]],"id":5677052}],"con":true,"img":false}]}
{"op":"mcm","clk":"5322488294","pt":1646320820781,"mc":[{"id":"1.195532870","rc":[{"atb":[[2.86,6.68]],"id":40214166},{"atb":[[2.84,5.39]],"id":41793694}],"con":true,"img":false}]}
{"op":"mcm","clk":"5322488969","pt":1646320829655,"mc":[{"id":"1.195532870","rc":[{"atb":[[2.78,0]],"id":41793694}],"con":true,"img":false}]}
{"op":"mcm","clk":"5322489159","pt":1646320832158,"mc":[{"id":"1.195532870","rc":[{"atb":[[2.82,5.46]],"id":5677052}],"con":true,"img":false}]}
{"op":"mcm","clk":"5322489172","pt":1646320832361,"mc":[{"id":"1.195532870","rc":[{"atb":[[2.4,4.81]],"id":43189003}],"con":true,"img":false}]}
{"op":"mcm","clk":"5322489989","pt":1646320842384,"mc":[{"id":"1.195532870","rc":[{"atb":[[2.76,0]],"id":5677052}],"con":true,"img":false}]}
{"op":"mcm","clk":"5322490156","pt":1646320844064,"mc":[{"id":"1.195532870","rc":[{"atb":[[2.84,0]],"id":41793694}],"con":true,"img":false}]}
{"op":"mcm","clk":"5322491239","pt":1646320857013,"mc":[{"id":"1.195532870","rc":[{"atb":[[2.82,0]],"id":5677052}],"con":true,"img":false}]}
