{"op":"mcm","clk":"5346220775","pt":1646178839810,"mc":[{"id":"1.195453678","marketDefinition":{"bspMarket":false,"turnInPlayEnabled":false,"persistenceEnabled":false,"marketBaseRate":7.0,"eventId":"31272494","eventTypeId":"4339","numberOfWinners":1,"bettingType":"ODDS","marketType":"MATCH_BET","marketTime":"2022-03-02T11:32:00.000Z","suspendTime":"2022-03-02T11:32:00.000Z","bspReconciled":false,"complete":true,"inPlay":false,"crossMatching":true,"runnersVoidable":false,"numberOfActiveRunners":2,"betDelay":0,"status":"OPEN","runners":[{"status":"ACTIVE","sortPriority":1,"id":40324291,"name":"4. Reiko Langer"},{"status":"ACTIVE","sortPriority":2,"id":38214982,"name":"7. Two Phones"}],"regulators":["MR_INT"],"venue":"Traralgon","countryCode":"AU","discountAllowed":true,"timezone":"Australia/Sydney","openDate":"2022-03-02T08:31:00.000Z","version":4382489955,"name":"Reiko Langer v Two Phones","eventName":"Traralgon (AUS) 2nd Mar"},"rc":[],"con":true,"img":false}]}
{"op":"mcm","clk":"5346224660","pt":1646178919306,"mc":[{"id":"1.195453678","rc":[{"atb":[[1.51,10.56],[1.71,7.58],[1.61,8.83]],"id":38214982},{"atb":[[1.85,6.34],[1.75,7.18],[1.65,8.29]],"id":40324291}],"con":true,"img":false}]}
{"op":"mcm","clk":"5346316482","pt":1646180692729,"mc":[{"id":"1.195453678","rc":[{"atb":[[1.51,0],[1.71,0],[1.61,0]],"id":38214982},{"atb":[[1.85,0],[1.75,0],[1.65,0]],"id":40324291}],"con":true,"img":false}]}
{"op":"mcm","clk":"5346317059","pt":1646180703371,"mc":[{"id":"1.195453678","rc":[{"atb":[[1.51,10.56],[1.71,7.58],[1.61,8.83]],"id":38214982},{"atb":[[1.85,6.34],[1.75,7.18],[1.65,8.29]],"id":40324291}],"con":true,"img":false}]}
{"op":"mcm","clk":"5346591720","pt":1646184894416,"mc":[{"id":"1.195453678","rc":[{"atb":[[1.51,0],[1.71,0],[1.61,0]],"id":38214982},{"atb":[[1.85,0],[1.75,0],[1.65,0]],"id":40324291}],"con":true,"img":false}]}
{"op":"mcm","clk":"5346593216","pt":1646184920641,"mc":[{"id":"1.195453678","rc":[{"atb":[[1.51,10.58],[1.71,7.6],[1.61,8.84]],"id":38214982},{"atb":[[1.85,6.35],[1.75,7.19],[1.65,8.3]],"id":40324291}],"con":true,"img":false}]}
{"op":"mcm","clk":"5347092392","pt":1646192802708,"mc":[{"id":"1.195453678","marketDefinition":{"bspMarket":false,"turnInPlayEnabled":false,"persistenceEnabled":false,"marketBaseRate":7.0,"eventId":"31272494","eventTypeId":"4339","numberOfWinners":1,"bettingType":"ODDS","marketType":"MATCH_BET","marketTime":"2022-03-02T11:32:00.000Z","suspendTime":"2022-03-02T11:32:00.000Z","bspReconciled":false,"complete":true,"inPlay":false,"crossMatching":true,"runnersVoidable":false,"numberOfActiveRunners":2,"betDelay":0,"status":"OPEN","runners":[{"status":"ACTIVE","sortPriority":1,"id":40324291,"name":"4. Reiko Langer"},{"status":"ACTIVE","sortPriority":2,"id":38214982,"name":"7. Two Phones"}],"regulators":["MR_INT"],"venue":"Traralgon","countryCode":"AU","discountAllowed":true,"timezone":"Australia/Sydney","openDate":"2022-03-02T08:31:00.000Z","version":4382489955,"name":"Reiko Langer v Two Phones","eventName":"Traralgon (AUS) 2nd Mar"},"rc":[{"atb":[[1.51,10.6],[1.71,7.61],[1.61,8.86]],"id":38214982},{"atb":[[1.85,6.36],[1.75,7.2],[1.65,8.31]],"id":40324291}],"con":true,"img":true}]}
{"op":"mcm","clk":"5347381253","pt":1646198202726,"mc":[{"id":"1.195453678","marketDefinition":{"bspMarket":false,"turnInPlayEnabled":false,"persistenceEnabled":false,"marketBaseRate":7.0,"eventId":"31272494","eventTypeId":"4339","numberOfWinners":1,"bettingType":"ODDS","marketType":"MATCH_BET","marketTime":"2022-03-02T11:32:00.000Z","suspendTime":"2022-03-02T11:32:00.000Z","bspReconciled":false,"complete":true,"inPlay":false,"crossMatching":true,"runnersVoidable":false,"numberOfActiveRunners":2,"betDelay":0,"status":"OPEN","runners":[{"status":"ACTIVE","sortPriority":1,"id":40324291,"name":"4. Reiko Langer"},{"status":"ACTIVE","sortPriority":2,"id":38214982,"name":"7. Two Phones"}],"regulators":["MR_INT"],"venue":"Traralgon","countryCode":"AU","discountAllowed":true,"timezone":"Australia/Sydney","openDate":"2022-03-02T08:31:00.000Z","version":4382489955,"name":"Reiko Langer v Two Phones","eventName":"Traralgon (AUS) 2nd Mar"},"rc":[{"atb":[[1.51,10.59],[1.71,7.61],[1.61,8.86]],"id":38214982},{"atb":[[1.85,6.36],[1.75,7.2],[1.65,8.31]],"id":40324291}],"con":true,"img":true}]}
{"op":"mcm","clk":"5347848925","pt":1646209002729,"mc":[{"id":"1.195453678","marketDefinition":{"bspMarket":false,"turnInPlayEnabled":false,"persistenceEnabled":false,"marketBaseRate":7.0,"eventId":"31272494","eventTypeId":"4339","numberOfWinners":1,"bettingType":"ODDS","marketType":"MATCH_BET","marketTime":"2022-03-02T11:32:00.000Z","suspendTime":"2022-03-02T11:32:00.000Z","bspReconciled":false,"complete":true,"inPlay":false,"crossMatching":true,"runnersVoidable":false,"numberOfActiveRunners":2,"betDelay":0,"status":"OPEN","runners":[{"status":"ACTIVE","sortPriority":1,"id":40324291,"name":"4. Reiko Langer"},{"status":"ACTIVE","sortPriority":2,"id":38214982,"name":"7. Two Phones"}],"regulators":["MR_INT"],"venue":"Traralgon","countryCode":"AU","discountAllowed":true,"timezone":"Australia/Sydney","openDate":"2022-03-02T08:31:00.000Z","version":4382489955,"name":"Reiko Langer v Two Phones","eventName":"Traralgon (AUS) 2nd Mar"},"rc":[{"atb":[[1.51,10.59],[1.71,7.6],[1.61,8.85]],"id":38214982},{"atb":[[1.85,6.35],[1.75,7.2],[1.65,8.31]],"id":40324291}],"con":true,"img":true}]}
{"op":"mcm","clk":"5348049363","pt":1646213092428,"mc":[{"id":"1.195453678","rc":[{"atb":[[1.51,0],[1.71,0],[1.61,0]],"id":38214982},{"atb":[[1.85,0],[1.75,0],[1.65,0]],"id":40324291}],"con":true,"img":false}]}
{"op":"mcm","clk":"5348049923","pt":1646213102143,"mc":[{"id":"1.195453678","rc":[{"atb":[[1.51,10.57],[1.71,7.59],[1.61,8.84]],"id":38214982},{"atb":[[1.85,6.34],[1.75,7.19],[1.65,8.3]],"id":40324291}],"con":true,"img":false}]}
{"op":"mcm","clk":"5348650608","pt":1646219627088,"mc":[{"id":"1.195453678","rc":[{"atb":[[1.72,2],[1.51,10.57],[1.71,7.59],[1.61,8.84]],"id":38214982},{"atl":[[2.58,2]],"id":38214982},{"atb":[[1.85,6.34],[1.75,7.19],[1.65,8.3],[1.76,2]],"id":40324291},{"atl":[[2.7,2]],"id":40324291}],"con":true,"img":false}]}
{"op":"mcm","clk":"5348657319","pt":1646219687223,"mc":[{"id":"1.195453678","rc":[{"atb":[[1.72,0]],"id":38214982},{"atl":[[2.58,0]],"id":38214982},{"atb":[[1.76,0]],"id":40324291},{"atl":[[2.7,0]],"id":40324291}],"con":true,"img":false}]}
{"op":"mcm","clk":"5348658088","pt":1646219694545,"mc":[{"id":"1.195453678","rc":[{"atb":[[1.72,2]],"id":38214982},{"atl":[[2.58,2]],"id":38214982},{"atb":[[1.76,2]],"id":40324291},{"atl":[[2.72,2]],"id":40324291}],"con":true,"img":false}]}
{"op":"mcm","clk":"5348689561","pt":1646219879485,"mc":[{"id":"1.195453678","rc":[{"atb":[[1.51,0],[1.71,0],[1.61,0]],"id":38214982},{"atb":[[1.85,0],[1.75,0],[1.65,0]],"id":40324291}],"con":true,"img":false}]}
{"op":"mcm","clk":"5348690076","pt":1646219883170,"mc":[{"id":"1.195453678","rc":[{"atb":[[1.51,10.57],[1.71,7.59],[1.61,8.84]],"id":38214982},{"atb":[[1.85,6.34],[1.75,7.19],[1.65,8.3]],"id":40324291}],"con":true,"img":false}]}
{"op":"mcm","clk":"5348694580","pt":1646219917835,"mc":[{"id":"1.195453678","rc":[{"atb":[[1.72,0]],"id":38214982},{"atl":[[2.58,0]],"id":38214982},{"atb":[[1.76,0]],"id":40324291},{"atl":[[2.72,0]],"id":40324291}],"con":true,"img":false}]}
{"op":"mcm","clk":"5348695661","pt":1646219926049,"mc":[{"id":"1.195453678","rc":[{"atb":[[1.72,2]],"id":38214982},{"atl":[[2.7,2]],"id":38214982},{"atb":[[1.76,2]],"id":40324291},{"atl":[[2.8,2]],"id":40324291}],"con":true,"img":false}]}
{"op":"mcm","clk":"5348697227","pt":1646219938059,"mc":[{"id":"1.195453678","rc":[{"atl":[[2.8,0],[2.78,2]],"id":40324291}],"con":true,"img":false}]}
{"op":"mcm","clk":"5348697843","pt":1646219943285,"mc":[{"id":"1.195453678","rc":[{"atl":[[2.78,0],[2.68,2]],"id":40324291}],"con":true,"img":false}]}
{"op":"mcm","clk":"5348705262","pt":1646220001353,"mc":[{"id":"1.195453678","rc":[{"atl":[[2.64,2],[2.7,0]],"id":38214982}],"con":true,"img":false}]}
{"op":"mcm","clk":"5348710602","pt":1646220042658,"mc":[{"id":"1.195453678","rc":[{"atl":[[2.64,0],[2.62,2]],"id":38214982}],"con":true,"img":false}]}
{"op":"mcm","clk":"5348717693","pt":1646220099818,"mc":[{"id":"1.195453678","rc":[{"atl":[[2.58,2],[2.62,0]],"id":38214982}],"con":true,"img":false}]}
{"op":"mcm","clk":"5348718492","pt":1646220106055,"mc":[{"id":"1.195453678","rc":[{"atl":[[2.58,2],[2.68,0]],"id":40324291}],"con":true,"img":false}]}
{"op":"mcm","clk":"5348720105","pt":1646220118581,"mc":[{"id":"1.195453678","rc":[{"atl":[[2.54,2],[2.58,0]],"id":40324291}],"con":true,"img":false}]}
{"op":"mcm","clk":"5348721434","pt":1646220128762,"mc":[{"id":"1.195453678","rc":[{"atl":[[2.44,2]],"id":38214982}],"con":true,"img":false}]}
{"op":"mcm","clk":"5348721451","pt":1646220128875,"mc":[{"id":"1.195453678","rc":[{"atl":[[2.58,0]],"id":38214982}],"con":true,"img":false}]}
{"op":"mcm","clk":"5348724240","pt":1646220151051,"mc":[{"id":"1.195453678","rc":[{"atb":[[1.73,2],[1.72,0]],"id":38214982},{"atl":[[2.54,0]],"id":40324291}],"con":true,"img":false}]}
{"op":"mcm","clk":"5348724251","pt":1646220151137,"mc":[{"id":"1.195453678","rc":[{"atl":[[2.32,2]],"id":40324291}],"con":true,"img":false}]}
{"op":"mcm","clk":"5348724890","pt":1646220156128,"mc":[{"id":"1.195453678","rc":[{"atb":[[1.73,0],[1.78,2]],"id":38214982}],"con":true,"img":false}]}
{"op":"mcm","clk":"5348724902","pt":1646220156232,"mc":[{"id":"1.195453678","rc":[{"atl":[[2.26,2]],"id":40324291}],"con":true,"img":false}]}
{"op":"mcm","clk":"5348724913","pt":1646220156338,"mc":[{"id":"1.195453678","rc":[{"atl":[[2.32,0]],"id":40324291}],"con":true,"img":false}]}
{"op":"mcm","clk":"5348725536","pt":1646220161219,"mc":[{"id":"1.195453678","rc":[{"atb":[[1.85,2],[1.78,0]],"id":38214982}],"con":true,"img":false}]}
{"op":"mcm","clk":"5348725552","pt":1646220161325,"mc":[{"id":"1.195453678","rc":[{"atl":[[2.18,2],[2.26,0]],"id":40324291}],"con":true,"img":false}]}
{"op":"mcm","clk":"5348726183","pt":1646220166342,"mc":[{"id":"1.195453678","rc":[{"atb":[[1.72,2]],"id":38214982}],"con":true,"img":false}]}
{"op":"mcm","clk":"5348726202","pt":1646220166551,"mc":[{"id":"1.195453678","rc":[{"atb":[[1.85,0]],"id":38214982}],"con":true,"img":false}]}
{"op":"mcm","clk":"5348728750","pt":1646220187487,"mc":[{"id":"1.195453678","rc":[{"atb":[[1.72,0],[1.79,2]],"id":38214982}],"con":true,"img":false}]}
{"op":"mcm","clk":"5348729364","pt":1646220192590,"mc":[{"id":"1.195453678","rc":[{"atb":[[1.83,2],[1.79,0]],"id":38214982}],"con":true,"img":false}]}
{"op":"mcm","clk":"5348730255","pt":1646220200099,"mc":[{"id":"1.195453678","rc":[{"atb":[[1.83,0],[1.8,2]],"id":38214982}],"con":true,"img":false}]}
{"op":"mcm","clk":"5348730889","pt":1646220205295,"mc":[{"id":"1.195453678","rc":[{"atb":[[1.8,0],[1.81,2]],"id":38214982}],"con":true,"img":false}]}
{"op":"mcm","clk":"5348730911","pt":1646220205538,"mc":[{"id":"1.195453678","rc":[{"atb":[[1.8,2]],"id":38214982}],"con":true,"img":false}]}
{"op":"mcm","clk":"5348730923","pt":1646220205618,"mc":[{"id":"1.195453678","rc":[{"atb":[[1.81,0]],"id":38214982}],"con":true,"img":false}]}
{"op":"mcm","clk":"5348731423","pt":1646220209718,"mc":[{"id":"1.195453678","rc":[{"atb":[[1.79,2]],"id":38214982}],"con":true,"img":false}]}
{"op":"mcm","clk":"5348731435","pt":1646220209824,"mc":[{"id":"1.195453678","rc":[{"atb":[[1.8,0]],"id":38214982}],"con":true,"img":false}]}
{"op":"mcm","clk":"5348732346","pt":1646220217308,"mc":[{"id":"1.195453678","rc":[{"atb":[[1.76,0]],"id":40324291}],"con":true,"img":false}]}
{"op":"mcm","clk":"5348732357","pt":1646220217410,"mc":[{"id":"1.195453678","rc":[{"atb":[[1.71,2]],"id":40324291}],"con":true,"img":false}]}
{"op":"mcm","clk":"5348732613","pt":1646220219506,"mc":[{"id":"1.195453678","rc":[{"atb":[[1.8,2],[1.79,0]],"id":38214982}],"con":true,"img":false}]}
{"op":"mcm","clk":"5348733502","pt":1646220226832,"mc":[{"id":"1.195453678","rc":[{"atb":[[1.82,2]],"id":38214982}],"con":true,"img":false}]}
{"op":"mcm","clk":"5348733513","pt":1646220226930,"mc":[{"id":"1.195453678","rc":[{"atb":[[1.8,0]],"id":38214982}],"con":true,"img":false}]}
{"op":"mcm","clk":"5348733807","pt":1646220229331,"mc":[{"id":"1.195453678","rc":[{"atl":[[2.18,0],[2.16,2]],"id":40324291}],"con":true,"img":false}]}
{"op":"mcm","clk":"5348734102","pt":1646220231956,"mc":[{"id":"1.195453678","rc":[{"atb":[[1.82,0],[1.85,2]],"id":38214982}],"con":true,"img":false}]}
{"op":"mcm","clk":"5348734983","pt":1646220239760,"mc":[{"id":"1.195453678","rc":[{"atb":[[1.83,2],[1.85,0]],"id":38214982}],"con":true,"img":false}]}
{"op":"mcm","clk":"5348736418","pt":1646220251760,"mc":[{"id":"1.195453678","rc":[{"atb":[[1.83,0],[1.82,2]],"id":38214982}],"con":true,"img":false}]}
{"op":"mcm","clk":"5348737007","pt":1646220256878,"mc":[{"id":"1.195453678","rc":[{"atb":[[1.82,0],[1.85,2]],"id":38214982}],"con":true,"img":false}]}
{"op":"mcm","clk":"5348737181","pt":1646220258293,"mc":[{"id":"1.195453678","rc":[{"atb":[[1.72,2],[1.85,0]],"id":38214982}],"con":true,"img":false}]}
{"op":"mcm","clk":"5348737775","pt":1646220263391,"mc":[{"id":"1.195453678","rc":[{"atb":[[1.72,0],[1.76,2]],"id":38214982}],"con":true,"img":false}]}
{"op":"mcm","clk":"5348738332","pt":1646220268489,"mc":[{"id":"1.195453678","rc":[{"atb":[[1.77,2]],"id":38214982}],"con":true,"img":false}]}
{"op":"mcm","clk":"5348738345","pt":1646220268596,"mc":[{"id":"1.195453678","rc":[{"atb":[[1.76,0]],"id":38214982}],"con":true,"img":false}]}
{"op":"mcm","clk":"5348738840","pt":1646220273610,"mc":[{"id":"1.195453678","rc":[{"atb":[[1.72,2],[1.77,0]],"id":38214982}],"con":true,"img":false}]}
{"op":"mcm","clk":"5348738995","pt":1646220274896,"mc":[{"id":"1.195453678","rc":[{"atb":[[1.72,0],[1.75,2]],"id":38214982}],"con":true,"img":false}]}
{"op":"mcm","clk":"5348739547","pt":1646220280136,"mc":[{"id":"1.195453678","rc":[{"atb":[[1.72,2],[1.75,0]],"id":38214982}],"con":true,"img":false}]}
{"op":"mcm","clk":"5348741061","pt":1646220293249,"mc":[{"id":"1.195453678","rc":[{"atb":[[1.51,0],[1.71,0],[1.61,0]],"id":38214982},{"atb":[[1.85,0],[1.75,0],[1.65,0]],"id":40324291}],"con":true,"img":false}]}
{"op":"mcm","clk":"5348742030","pt":1646220302586,"mc":[{"id":"1.195453678","rc":[{"atb":[[1.51,10.57],[1.71,7.59],[1.61,8.84]],"id":38214982},{"atb":[[1.85,6.34],[1.75,7.19],[1.65,8.3]],"id":40324291}],"con":true,"img":false}]}
{"op":"mcm","clk":"5348746272","pt":1646220343900,"mc":[{"id":"1.195453678","rc":[{"atb":[[1.83,2],[1.84,38],[1.78,2],[1.72,131],[1.82,2],[1.8,2],[1.81,57],[1.74,2],[1.86,25],[1.77,86],[1.75,2]],"id":38214982}],"con":true,"img":false}]}
{"op":"mcm","clk":"5348746285","pt":1646220343996,"mc":[{"id":"1.195453678","rc":[{"atb":[[1.72,129]],"id":38214982}],"con":true,"img":false}]}
{"op":"mcm","clk":"5348746295","pt":1646220344110,"mc":[{"id":"1.195453678","rc":[{"atb":[[1.87,2]],"id":38214982}],"con":true,"img":false}]}
{"op":"mcm","clk":"5348746484","pt":1646220346295,"mc":[{"id":"1.195453678","rc":[{"atl":[[2.8,2],[2.82,60],[2.72,2],[2.92,90],[2.88,2],[2.74,40],[2.86,2],[2.64,18],[2.68,27],[2.7,2],[2.76,2]],"id":38214982}],"con":true,"img":false}]}
{"op":"mcm","clk":"5348746494","pt":1646220346398,"mc":[{"id":"1.195453678","rc":[{"atl":[[2.44,0],[2.56,2]],"id":38214982}],"con":true,"img":false}]}
{"op":"mcm","clk":"5348746714","pt":1646220348601,"mc":[{"id":"1.195453678","rc":[{"atb":[[1.46,141],[1.6,28],[1.58,42],[1.51,94],[1.48,2],[1.56,2],[1.57,2],[1.55,63],[1.54,2],[1.49,2],[1.52,2]],"id":40324291}],"con":true,"img":false}]}
{"op":"mcm","clk":"5348746781","pt":1646220349335,"mc":[{"id":"1.195453678","rc":[{"atb":[[1.84,40],[1.87,0]],"id":38214982}],"con":true,"img":false}]}
{"op":"mcm","clk":"5348746926","pt":1646220350698,"mc":[{"id":"1.195453678","rc":[{"atl":[[2.24,24],[2.36,2],[2.3,2],[2.32,36],[2.22,2],[2.42,54],[2.38,2],[2.18,16],[2.2,2],[2.26,2],[2.14,11]],"id":40324291}],"con":true,"img":false}]}
{"op":"mcm","clk":"5348746933","pt":1646220350814,"mc":[{"id":"1.195453678","rc":[{"atl":[[2.18,18]],"id":40324291}],"con":true,"img":false}]}
{"op":"mcm","clk":"5348746941","pt":1646220350903,"mc":[{"id":"1.195453678","rc":[{"atl":[[2.16,0]],"id":40324291}],"con":true,"img":false}]}
{"op":"mcm","clk":"5348746947","pt":1646220351006,"mc":[{"id":"1.195453678","rc":[{"atl":[[2.2,4]],"id":40324291}],"con":true,"img":false}]}
{"op":"mcm","clk":"5348746957","pt":1646220351109,"mc":[{"id":"1.195453678","rc":[{"atl":[[2.18,16]],"id":40324291}],"con":true,"img":false}]}
{"op":"mcm","clk":"5348746995","pt":1646220351628,"mc":[{"id":"1.195453678","rc":[{"atl":[[2.54,2],[2.56,0]],"id":38214982}],"con":true,"img":false}]}
{"op":"mcm","clk":"5348747254","pt":1646220354436,"mc":[{"id":"1.195453678","rc":[{"atb":[[1.83,4],[1.84,38]],"id":38214982}],"con":true,"img":false}]}
{"op":"mcm","clk":"5348747531","pt":1646220357706,"mc":[{"id":"1.195453678","rc":[{"atl":[[2.54,0],[2.52,2]],"id":38214982}],"con":true,"img":false}]}
{"op":"mcm","clk":"5348750202","pt":1646220380759,"mc":[{"id":"1.195453678","rc":[{"atl":[[2.5,2],[2.52,0]],"id":38214982}],"con":true,"img":false}]}
{"op":"mcm","clk":"5348750220","pt":1646220380967,"mc":[{"id":"1.195453678","rc":[{"atb":[[1.87,9.63]],"id":38214982},{"atl":[[2.5,11.46]],"id":38214982},{"atb":[[1.86,9]],"id":40324291},{"atl":[[2.16,8.6]],"id":40324291}],"con":true,"img":false}]}
{"op":"mcm","clk":"5348750238","pt":1646220381177,"mc":[{"id":"1.195453678","rc":[{"atb":[[1.83,2],[1.88,2]],"id":38214982},{"atl":[[2.2,2],[2.14,13]],"id":40324291}],"con":true,"img":false}]}
{"op":"mcm","clk":"5348750336","pt":1646220382173,"mc":[{"id":"1.195453678","rc":[{"atb":[[1.51,0],[1.71,0],[1.61,0]],"id":38214982},{"atb":[[1.85,0],[1.75,0],[1.65,0]],"id":40324291}],"con":true,"img":false}]}
{"op":"mcm","clk":"5348751773","pt":1646220395091,"mc":[{"id":"1.195453678","rc":[{"atb":[[1.51,10.57],[1.71,7.59],[1.61,8.84]],"id":38214982},{"atb":[[1.85,6.34],[1.75,7.19],[1.65,8.3]],"id":40324291}],"con":true,"img":false}]}
{"op":"mcm","clk":"5348752316","pt":1646220400201,"mc":[{"id":"1.195453678","rc":[{"atb":[[1.88,11.5]],"id":38214982},{"atl":[[2.12,8.76]],"id":40324291}],"con":true,"img":false}]}
{"op":"mcm","clk":"5348752339","pt":1646220400398,"mc":[{"id":"1.195453678","rc":[{"atl":[[2.14,11],[2.1,2]],"id":40324291}],"con":true,"img":false}]}
{"op":"mcm","clk":"5348752364","pt":1646220400615,"mc":[{"id":"1.195453678","rc":[{"atb":[[1.71,0],[1.75,9.19]],"id":40324291}],"con":true,"img":false}]}
{"op":"mcm","clk":"5348752388","pt":1646220400829,"mc":[{"id":"1.195453678","rc":[{"atl":[[2.1,10.86]],"id":40324291}],"con":true,"img":false}]}
{"op":"mcm","clk":"5348762279","pt":1646220457009,"mc":[{"id":"1.195453678","rc":[{"atb":[[1.75,7.19]],"id":40324291}],"con":true,"img":false}]}
{"op":"mcm","clk":"5348762304","pt":1646220457216,"mc":[{"id":"1.195453678","rc":[{"atb":[[1.71,2]],"id":40324291}],"con":true,"img":false}]}
{"op":"mcm","clk":"5348762733","pt":1646220460908,"mc":[{"id":"1.195453678","rc":[{"atl":[[2.5,9.46],[2.42,2]],"id":38214982}],"con":true,"img":false}]}
{"op":"mcm","clk":"5348762765","pt":1646220461179,"mc":[{"id":"1.195453678","rc":[{"atl":[[2.42,11.25]],"id":38214982}],"con":true,"img":false}]}
{"op":"mcm","clk":"5348763393","pt":1646220466028,"mc":[{"id":"1.195453678","rc":[{"atl":[[2.36,2],[2.42,9.25]],"id":38214982}],"con":true,"img":false}]}
{"op":"mcm","clk":"5348763478","pt":1646220466914,"mc":[{"id":"1.195453678","rc":[{"atl":[[2.36,11.32]],"id":38214982}],"con":true,"img":false}]}
{"op":"mcm","clk":"5348763759","pt":1646220469702,"mc":[{"id":"1.195453678","rc":[{"atl":[[2.1,2]],"id":40324291}],"con":true,"img":false}]}
{"op":"mcm","clk":"5348763901","pt":1646220471223,"mc":[{"id":"1.195453678","rc":[{"atl":[[2.34,2],[2.36,9.32]],"id":38214982}],"con":true,"img":false}]}
{"op":"mcm","clk":"5348763970","pt":1646220471905,"mc":[{"id":"1.195453678","rc":[{"atl":[[2.34,11.52]],"id":38214982}],"con":true,"img":false}]}
{"op":"mcm","clk":"5348764041","pt":1646220472689,"mc":[{"id":"1.195453678","rc":[{"atl":[[2.12,0]],"id":40324291}],"con":true,"img":false}]}
{"op":"mcm","clk":"5348764053","pt":1646220472844,"mc":[{"id":"1.195453678","rc":[{"atl":[[2.1,0]],"id":40324291}],"con":true,"img":false}]}
{"op":"mcm","clk":"5348764063","pt":1646220472895,"mc":[{"id":"1.195453678","rc":[{"atl":[[2.14,13]],"id":40324291}],"con":true,"img":false}]}
{"op":"mcm","clk":"5348764205","pt":1646220474222,"mc":[{"id":"1.195453678","rc":[{"atl":[[2.16,10.35]],"id":38214982}],"con":true,"img":false}]}
{"op":"mcm","clk":"5348764401","pt":1646220476212,"mc":[{"id":"1.195453678","rc":[{"atb":[[1.87,0],[1.88,2]],"id":38214982},{"atl":[[2.5,0],[2.14,9.79]],"id":38214982}],"con":true,"img":false}]}
{"op":"mcm","clk":"5348764423","pt":1646220476421,"mc":[{"id":"1.195453678","rc":[{"atb":[[1.84,40],[1.88,0]],"id":38214982}],"con":true,"img":false}]}
{"op":"mcm","clk":"5348764445","pt":1646220476628,"mc":[{"id":"1.195453678","rc":[{"atb":[[1.83,4],[1.84,38]],"id":38214982}],"con":true,"img":false}]}
{"op":"mcm","clk":"5348764608","pt":1646220477999,"mc":[{"id":"1.195453678","rc":[{"atl":[[2.16,0]],"id":40324291}],"con":true,"img":false}]}
{"op":"mcm","clk":"5348764632","pt":1646220478208,"mc":[{"id":"1.195453678","rc":[{"atl":[[2.2,4],[2.14,11]],"id":40324291}],"con":true,"img":false}]}
{"op":"mcm","clk":"5348765182","pt":1646220483138,"mc":[{"id":"1.195453678","rc":[{"atl":[[2.16,0]],"id":38214982}],"con":true,"img":false}]}
{"op":"mcm","clk":"5348765195","pt":1646220483245,"mc":[{"id":"1.195453678","rc":[{"atl":[[2.12,10.35]],"id":38214982}],"con":true,"img":false}]}
{"op":"mcm","clk":"5348765335","pt":1646220484249,"mc":[{"id":"1.195453678","rc":[{"atl":[[2.1,9.94],[2.42,0]],"id":38214982}],"con":true,"img":false}]}
{"op":"mcm","clk":"5348766108","pt":1646220491520,"mc":[{"id":"1.195453678","rc":[{"atl":[[2.12,0]],"id":38214982}],"con":true,"img":false}]}
{"op":"mcm","clk":"5348766117","pt":1646220491623,"mc":[{"id":"1.195453678","rc":[{"atl":[[2.08,10.35]],"id":38214982}],"con":true,"img":false}]}
{"op":"mcm","clk":"5348766311","pt":1646220494021,"mc":[{"id":"1.195453678","rc":[{"atl":[[2.06,10]],"id":38214982}],"con":true,"img":false}]}
{"op":"mcm","clk":"5348766328","pt":1646220494228,"mc":[{"id":"1.195453678","rc":[{"atl":[[2.36,0]],"id":38214982}],"con":true,"img":false}]}
{"op":"mcm","clk":"5348766476","pt":1646220495923,"mc":[{"id":"1.195453678","rc":[{"atl":[[2.08,0]],"id":38214982}],"con":true,"img":false}]}
{"op":"mcm","clk":"5348766482","pt":1646220496027,"mc":[{"id":"1.195453678","rc":[{"atl":[[2.04,10.35]],"id":38214982}],"con":true,"img":false}]}
{"op":"mcm","clk":"5348766901","pt":1646220500847,"mc":[{"id":"1.195453678","rc":[{"atl":[[2.04,0]],"id":38214982}],"con":true,"img":false}]}
{"op":"mcm","clk":"5348766910","pt":1646220500950,"mc":[{"id":"1.195453678","rc":[{"atl":[[2,10.35]],"id":38214982}],"con":true,"img":false}]}
{"op":"mcm","clk":"5348766954","pt":1646220501420,"mc":[{"id":"1.195453678","rc":[{"atb":[[1.82,12.08]],"id":38214982},{"atl":[[2.34,2],[1.99,10]],"id":38214982},{"atl":[[2.22,10.38]],"id":40324291}],"con":true,"img":false}]}
{"op":"mcm","clk":"5348767357","pt":1646220505925,"mc":[{"id":"1.195453678","rc":[{"atl":[[2,0]],"id":38214982}],"con":true,"img":false}]}
{"op":"mcm","clk":"5348767364","pt":1646220506032,"mc":[{"id":"1.195453678","rc":[{"atl":[[4,10.35]],"id":38214982}],"con":true,"img":false}]}
{"op":"mcm","clk":"5348768386","pt":1646220516262,"mc":[{"id":"1.195453678","rc":[{"atb":[[1.71,0],[1.75,9.19]],"id":40324291}],"con":true,"img":false}]}
{"op":"mcm","clk":"5348768747","pt":1646220519766,"mc":[{"id":"1.195453678","rc":[{"atb":[[1.77,2]],"id":40324291}],"con":true,"img":false}]}
{"op":"mcm","clk":"5348768756","pt":1646220519870,"mc":[{"id":"1.195453678","rc":[{"atb":[[1.75,7.19]],"id":40324291}],"con":true,"img":false}]}
{"op":"mcm","clk":"5348768854","pt":1646220520882,"mc":[{"id":"1.195453678","rc":[{"atb":[[1.82,2]],"id":38214982},{"atl":[[2.22,2]],"id":40324291}],"con":true,"img":false}]}
{"op":"mcm","clk":"5348769947","pt":1646220532732,"mc":[{"id":"1.195453678","rc":[{"atb":[[1.51,0],[1.71,0],[1.61,0]],"id":38214982},{"atb":[[1.85,0],[1.75,0],[1.65,0]],"id":40324291}],"con":true,"img":false}]}
{"op":"mcm","clk":"5348771189","pt":1646220545159,"mc":[{"id":"1.195453678","rc":[{"atb":[[1.64,8.43],[1.44,12.26],[1.54,9.99]],"id":38214982},{"atb":[[1.7,7.7],[1.8,6.74],[1.9,5.99]],"id":40324291}],"con":true,"img":false}]}
{"op":"mcm","clk":"5348771310","pt":1646220546525,"mc":[{"id":"1.195453678","rc":[{"atb":[[1.91,8.3]],"id":40324291}],"con":true,"img":false}]}
{"op":"mcm","clk":"5348772712","pt":1646220561969,"mc":[{"id":"1.195453678","rc":[{"atb":[[1.64,0],[1.44,0],[1.54,0]],"id":38214982},{"atb":[[1.7,0],[1.8,0],[1.9,0]],"id":40324291}],"con":true,"img":false}]}
{"op":"mcm","clk":"5348773020","pt":1646220565647,"mc":[{"id":"1.195453678","rc":[{"atb":[[1.86,0]],"id":38214982}],"con":true,"img":false}]}
{"op":"mcm","clk":"5348773050","pt":1646220565962,"mc":[{"id":"1.195453678","rc":[{"atb":[[1.84,0]],"id":38214982}],"con":true,"img":false}]}
{"op":"mcm","clk":"5348773072","pt":1646220566161,"mc":[{"id":"1.195453678","rc":[{"atb":[[1.83,2],[1.81,59]],"id":38214982}],"con":true,"img":false}]}
{"op":"mcm","clk":"5348773222","pt":1646220567756,"mc":[{"id":"1.195453678","rc":[{"atb":[[1.83,6]],"id":38214982},{"atl":[[2.14,29.62]],"id":40324291}],"con":true,"img":false}]}
{"op":"mcm","clk":"5348773236","pt":1646220567960,"mc":[{"id":"1.195453678","rc":[{"atl":[[2.2,2],[2.14,22.89]],"id":40324291},{"trd":[[2.14,17.46]],"ltp":2.14,"tv":17.46,"id":40324291}],"con":true,"img":false}]}
{"op":"mcm","clk":"5348773244","pt":1646220568065,"mc":[{"id":"1.195453678","rc":[{"atb":[[1.83,21]],"id":38214982}],"con":true,"img":false}]}
{"op":"mcm","clk":"5348773252","pt":1646220568164,"mc":[{"id":"1.195453678","rc":[{"atb":[[1.82,12.31]],"id":38214982},{"atl":[[2.22,10.19]],"id":40324291}],"con":true,"img":false}]}
{"op":"mcm","clk":"5348773264","pt":1646220568274,"mc":[{"id":"1.195453678","rc":[{"atl":[[2.14,12.81]],"id":40324291}],"con":true,"img":false}]}
{"op":"mcm","clk":"5348773479","pt":1646220570775,"mc":[{"id":"1.195453678","rc":[{"atb":[[1.81,2]],"id":38214982}],"con":true,"img":false}]}
{"op":"mcm","clk":"5348773490","pt":1646220570883,"mc":[{"id":"1.195453678","rc":[{"atb":[[1.84,34.7],[1.77,143]],"id":38214982},{"atb":[[1.91,40.34]],"id":40324291}],"con":true,"img":false}]}
{"op":"mcm","clk":"5348773520","pt":1646220571198,"mc":[{"id":"1.195453678","rc":[{"atb":[[1.64,8.43],[1.83,17],[1.44,12.26],[1.54,9.99]],"id":38214982},{"atb":[[1.7,7.7],[1.8,6.74],[1.9,5.99]],"id":40324291}],"con":true,"img":false}]}
{"op":"mcm","clk":"5348773540","pt":1646220571371,"mc":[{"id":"1.195453678","rc":[{"atb":[[1.85,2],[1.81,0]],"id":38214982}],"con":true,"img":false}]}
{"op":"mcm","clk":"5348773550","pt":1646220571474,"mc":[{"id":"1.195453678","rc":[{"atb":[[1.92,8.25]],"id":40324291}],"con":true,"img":false}]}
{"op":"mcm","clk":"5348773570","pt":1646220571777,"mc":[{"id":"1.195453678","rc":[{"atb":[[1.84,60.41]],"id":38214982}],"con":true,"img":false}]}
{"op":"mcm","clk":"5348773596","pt":1646220572090,"mc":[{"id":"1.195453678","rc":[{"atb":[[1.84,34.7]],"id":38214982}],"con":true,"img":false}]}
{"op":"mcm","clk":"5348773602","pt":1646220572162,"mc":[{"id":"1.195453678","rc":[{"atb":[[1.85,27.71]],"id":38214982}],"con":true,"img":false}]}
{"op":"mcm","clk":"5348773629","pt":1646220572470,"mc":[{"id":"1.195453678","rc":[{"atb":[[1.88,1.42]],"id":38214982},{"atl":[[2.16,1.42]],"id":40324291}],"con":true,"img":false}]}
{"op":"mcm","clk":"5348773634","pt":1646220572575,"mc":[{"id":"1.195453678","rc":[{"atb":[[1.85,6]],"id":38214982}],"con":true,"img":false}]}
{"op":"mcm","clk":"5348773643","pt":1646220572672,"mc":[{"id":"1.195453678","rc":[{"atb":[[1.88,0]],"id":38214982},{"trd":[[1.88,2.84]],"ltp":1.88,"tv":2.84,"id":38214982}],"con":true,"img":false}]}
{"op":"mcm","clk":"5348773660","pt":1646220572878,"mc":[{"id":"1.195453678","rc":[{"atb":[[1.85,2]],"id":38214982}],"con":true,"img":false}]}
{"op":"mcm","clk":"5348773666","pt":1646220572979,"mc":[{"id":"1.195453678","rc":[{"atb":[[1.88,4]],"id":38214982}],"con":true,"img":false}]}
{"op":"mcm","clk":"5348773683","pt":1646220573191,"mc":[{"id":"1.195453678","rc":[{"atl":[[2.2,10.22]],"id":40324291}],"con":true,"img":false}]}
{"op":"mcm","clk":"5348773693","pt":1646220573261,"mc":[{"id":"1.195453678","rc":[{"atb":[[1.88,0]],"id":38214982}],"con":true,"img":false}]}
{"op":"mcm","clk":"5348773707","pt":1646220573463,"mc":[{"id":"1.195453678","rc":[{"atb":[[1.88,8]],"id":38214982}],"con":true,"img":false}]}
{"op":"mcm","clk":"5348773729","pt":1646220573778,"mc":[{"id":"1.195453678","rc":[{"atb":[[1.88,0]],"id":38214982}],"con":true,"img":false}]}
{"op":"mcm","clk":"5348773738","pt":1646220573876,"mc":[{"id":"1.195453678","rc":[{"atb":[[1.85,10]],"id":38214982}],"con":true,"img":false}]}
{"op":"mcm","clk":"5348773745","pt":1646220573978,"mc":[{"id":"1.195453678","rc":[{"atb":[[1.89,15]],"id":38214982}],"con":true,"img":false}]}
{"op":"mcm","clk":"5348773755","pt":1646220574082,"mc":[{"id":"1.195453678","rc":[{"atb":[[1.89,16.42]],"id":38214982},{"atl":[[2.28,1.42]],"id":40324291}],"con":true,"img":false}]}
{"op":"mcm","clk":"5348773776","pt":1646220574291,"mc":[{"id":"1.195453678","rc":[{"atb":[[1.85,2]],"id":38214982},{"atl":[[2.18,24.3]],"id":40324291}],"con":true,"img":false}]}
{"op":"mcm","clk":"5348773807","pt":1646220574569,"mc":[{"id":"1.195453678","rc":[{"atb":[[1.89,34.28]],"id":38214982}],"con":true,"img":false}]}
{"op":"mcm","clk":"5348773826","pt":1646220574775,"mc":[{"id":"1.195453678","rc":[{"atb":[[1.85,12.11]],"id":38214982}],"con":true,"img":false}]}
{"op":"mcm","clk":"5348773833","pt":1646220574878,"mc":[{"id":"1.195453678","rc":[{"atb":[[1.9,32.39]],"id":38214982}],"con":true,"img":false}]}
{"op":"mcm","clk":"5348773862","pt":1646220575179,"mc":[{"id":"1.195453678","rc":[{"atb":[[1.89,16.42]],"id":38214982}],"con":true,"img":false}]}
{"op":"mcm","clk":"5348773871","pt":1646220575282,"mc":[{"id":"1.195453678","rc":[{"atb":[[1.9,50.25]],"id":38214982}],"con":true,"img":false}]}
{"op":"mcm","clk":"5348773881","pt":1646220575374,"mc":[{"id":"1.195453678","rc":[{"atb":[[1.9,17.86]],"id":38214982}],"con":true,"img":false}]}
{"op":"mcm","clk":"5348773921","pt":1646220575761,"mc":[{"id":"1.195453678","rc":[{"atb":[[1.88,1.42],[1.9,0]],"id":38214982}],"con":true,"img":false}]}
{"op":"mcm","clk":"5348773931","pt":1646220575865,"mc":[{"id":"1.195453678","rc":[{"atb":[[1.9,32.39]],"id":38214982}],"con":true,"img":false}]}
{"op":"mcm","clk":"5348773947","pt":1646220575981,"mc":[{"id":"1.195453678","rc":[{"atl":[[2.16,9.82]],"id":40324291}],"con":true,"img":false}]}
{"op":"mcm","clk":"5348773962","pt":1646220576081,"mc":[{"id":"1.195453678","rc":[{"atb":[[1.89,34.68]],"id":38214982}],"con":true,"img":false}]}
{"op":"mcm","clk":"5348773996","pt":1646220576385,"mc":[{"id":"1.195453678","rc":[{"atb":[[1.89,16.42],[1.9,0]],"id":38214982}],"con":true,"img":false}]}
{"op":"mcm","clk":"5348774006","pt":1646220576489,"mc":[{"id":"1.195453678","rc":[{"atb":[[1.9,18.26]],"id":38214982}],"con":true,"img":false}]}
{"op":"mcm","clk":"5348774035","pt":1646220576759,"mc":[{"id":"1.195453678","rc":[{"atb":[[1.9,0]],"id":38214982}],"con":true,"img":false}]}
{"op":"mcm","clk":"5348774042","pt":1646220576871,"mc":[{"id":"1.195453678","rc":[{"atb":[[1.9,32.39]],"id":38214982},{"atl":[[2.12,1.42]],"id":40324291}],"con":true,"img":false}]}
{"op":"mcm","clk":"5348774060","pt":1646220577079,"mc":[{"id":"1.195453678","rc":[{"atb":[[1.89,34.79]],"id":38214982}],"con":true,"img":false}]}
{"op":"mcm","clk":"5348774070","pt":1646220577183,"mc":[{"id":"1.195453678","rc":[{"atl":[[2.14,4.27]],"id":40324291}],"con":true,"img":false}]}
{"op":"mcm","clk":"5348774079","pt":1646220577275,"mc":[{"id":"1.195453678","rc":[{"atl":[[2.12,9.96]],"id":40324291}],"con":true,"img":false}]}
{"op":"mcm","clk":"5348774089","pt":1646220577377,"mc":[{"id":"1.195453678","rc":[{"atb":[[1.89,16.42],[1.9,0]],"id":38214982}],"con":true,"img":false}]}
{"op":"mcm","clk":"5348774097","pt":1646220577481,"mc":[{"id":"1.195453678","rc":[{"atb":[[1.88,11.33],[1.9,18.37]],"id":38214982},{"atl":[[2.14,12.75]],"id":40324291}],"con":true,"img":false}]}
{"op":"mcm","clk":"5348774105","pt":1646220577585,"mc":[{"id":"1.195453678","rc":[{"atl":[[2.22,2],[2.12,4.26]],"id":40324291}],"con":true,"img":false}]}
{"op":"mcm","clk":"5348774122","pt":1646220577798,"mc":[{"id":"1.195453678","rc":[{"atb":[[1.9,0]],"id":38214982}],"con":true,"img":false}]}
{"op":"mcm","clk":"5348774131","pt":1646220577906,"mc":[{"id":"1.195453678","rc":[{"atb":[[1.9,32.39]],"id":38214982}],"con":true,"img":false}]}
{"op":"mcm","clk":"5348774158","pt":1646220578111,"mc":[{"id":"1.195453678","rc":[{"atb":[[1.89,36.31]],"id":38214982}],"con":true,"img":false}]}
{"op":"mcm","clk":"5348774199","pt":1646220578373,"mc":[{"id":"1.195453678","rc":[{"atb":[[1.9,0]],"id":38214982}],"con":true,"img":false}]}
{"op":"mcm","clk":"5348774218","pt":1646220578584,"mc":[{"id":"1.195453678","rc":[{"atb":[[1.89,16.42]],"id":38214982}],"con":true,"img":false}]}
{"op":"mcm","clk":"5348774227","pt":1646220578682,"mc":[{"id":"1.195453678","rc":[{"atb":[[1.9,19.89]],"id":38214982}],"con":true,"img":false}]}
{"op":"mcm","clk":"5348774238","pt":1646220578789,"mc":[{"id":"1.195453678","rc":[{"atb":[[1.88,44.45]],"id":38214982}],"con":true,"img":false}]}
{"op":"mcm","clk":"5348774262","pt":1646220578997,"mc":[{"id":"1.195453678","rc":[{"atb":[[1.9,0]],"id":38214982}],"con":true,"img":false}]}
{"op":"mcm","clk":"5348774280","pt":1646220579265,"mc":[{"id":"1.195453678","rc":[{"atb":[[1.89,36.65]],"id":38214982}],"con":true,"img":false}]}
{"op":"mcm","clk":"5348774327","pt":1646220579778,"mc":[{"id":"1.195453678","rc":[{"atb":[[1.9,32.39]],"id":38214982}],"con":true,"img":false}]}
{"op":"mcm","clk":"5348774364","pt":1646220580197,"mc":[{"id":"1.195453678","rc":[{"atb":[[1.89,16.42]],"id":38214982}],"con":true,"img":false}]}
{"op":"mcm","clk":"5348774375","pt":1646220580259,"mc":[{"id":"1.195453678","rc":[{"atb":[[1.9,52.62]],"id":38214982}],"con":true,"img":false}]}
{"op":"mcm","clk":"5348774384","pt":1646220580365,"mc":[{"id":"1.195453678","rc":[{"atb":[[1.88,11.33],[1.9,20.23]],"id":38214982}],"con":true,"img":false}]}
{"op":"mcm","clk":"5348774392","pt":1646220580468,"mc":[{"id":"1.195453678","rc":[{"atl":[[2.12,12.83],[2.2,2]],"id":40324291}],"con":true,"img":false}]}
{"op":"mcm","clk":"5348774413","pt":1646220580781,"mc":[{"id":"1.195453678","rc":[{"atb":[[1.85,46.41],[1.9,0]],"id":38214982}],"con":true,"img":false}]}
{"op":"mcm","clk":"5348774418","pt":1646220580877,"mc":[{"id":"1.195453678","rc":[{"atb":[[1.89,36.65]],"id":38214982}],"con":true,"img":false}]}
{"op":"mcm","clk":"5348774433","pt":1646220581085,"mc":[{"id":"1.195453678","rc":[{"atb":[[1.9,9.76]],"id":38214982}],"con":true,"img":false}]}
{"op":"mcm","clk":"5348774457","pt":1646220581361,"mc":[{"id":"1.195453678","rc":[{"atb":[[1.89,16.42]],"id":38214982}],"con":true,"img":false}]}
{"op":"mcm","clk":"5348774466","pt":1646220581474,"mc":[{"id":"1.195453678","rc":[{"atb":[[1.9,29.99]],"id":38214982}],"con":true,"img":false}]}
{"op":"mcm","clk":"5348774518","pt":1646220582194,"mc":[{"id":"1.195453678","rc":[{"atb":[[1.9,20.23]],"id":38214982}],"con":true,"img":false}]}
{"op":"mcm","clk":"5348774548","pt":1646220582499,"mc":[{"id":"1.195453678","rc":[{"atb":[[1.9,0]],"id":38214982}],"con":true,"img":false}]}
{"op":"mcm","clk":"5348774576","pt":1646220582768,"mc":[{"id":"1.195453678","rc":[{"atb":[[1.89,69.91]],"id":38214982}],"con":true,"img":false}]}
{"op":"mcm","clk":"5348774939","pt":1646220586464,"mc":[{"id":"1.195453678","rc":[{"atl":[[2.12,4.26]],"id":40324291}],"con":true,"img":false}]}
{"op":"mcm","clk":"5348775786","pt":1646220595121,"mc":[{"id":"1.195453678","rc":[{"atl":[[2.34,0],[4,0],[2.24,2]],"id":38214982}],"con":true,"img":false}]}
{"op":"mcm","clk":"5348775798","pt":1646220595207,"mc":[{"id":"1.195453678","rc":[{"atl":[[2,10.35]],"id":38214982}],"con":true,"img":false}]}
{"op":"mcm","clk":"5348775864","pt":1646220595786,"mc":[{"id":"1.195453678","rc":[{"atb":[[1.95,30.68]],"id":40324291}],"con":true,"img":false}]}
{"op":"mcm","clk":"5348775964","pt":1646220596783,"mc":[{"id":"1.195453678","rc":[{"atb":[[1.96,8.55]],"id":40324291}],"con":true,"img":false}]}
{"op":"mcm","clk":"5348775999","pt":1646220597200,"mc":[{"id":"1.195453678","rc":[{"atb":[[1.88,1.42]],"id":38214982},{"atl":[[2.14,4.27],[2.16,1.42]],"id":40324291}],"con":true,"img":false}]}
{"op":"mcm","clk":"5348776017","pt":1646220597404,"mc":[{"id":"1.195453678","rc":[{"atb":[[1.97,1.42]],"id":40324291}],"con":true,"img":false}]}
{"op":"mcm","clk":"5348776088","pt":1646220598295,"mc":[{"id":"1.195453678","rc":[{"atb":[[1.97,9.79]],"id":40324291}],"con":true,"img":false}]}
{"op":"mcm","clk":"5348776102","pt":1646220598498,"mc":[{"id":"1.195453678","rc":[{"atb":[[1.99,1.42],[1.86,0]],"id":40324291}],"con":true,"img":false}]}
{"op":"mcm","clk":"5348776136","pt":1646220598802,"mc":[{"id":"1.195453678","rc":[{"atb":[[1.98,29.74]],"id":40324291}],"con":true,"img":false}]}
{"op":"mcm","clk":"5348776208","pt":1646220599487,"mc":[{"id":"1.195453678","rc":[{"atb":[[1.98,31.16]],"id":40324291}],"con":true,"img":false}]}
{"op":"mcm","clk":"5348776290","pt":1646220600480,"mc":[{"id":"1.195453678","rc":[{"atb":[[1.93,1.42]],"id":40324291}],"con":true,"img":false}]}
{"op":"mcm","clk":"5348776931","pt":1646220605522,"mc":[{"id":"1.195453678","rc":[{"atb":[[1.85,36.29]],"id":38214982},{"atb":[[1.99,9.76],[1.91,32.03]],"id":40324291},{"atl":[[2.18,16]],"id":40324291}],"con":true,"img":false}]}
{"op":"mcm","clk":"5348776957","pt":1646220605795,"mc":[{"id":"1.195453678","rc":[{"atb":[[1.91,0]],"id":40324291}],"con":true,"img":false}]}
{"op":"mcm","clk":"5348777869","pt":1646220614318,"mc":[{"id":"1.195453678","rc":[{"atb":[[1.9,1.42]],"id":38214982}],"con":true,"img":false}]}
{"op":"mcm","clk":"5348777886","pt":1646220614521,"mc":[{"id":"1.195453678","rc":[{"atb":[[1.9,0]],"id":38214982},{"trd":[[1.9,2.84]],"ltp":1.9,"tv":2.84,"id":38214982}],"con":true,"img":false}]}
{"op":"mcm","clk":"5348777894","pt":1646220614624,"mc":[{"id":"1.195453678","rc":[{"atb":[[1.89,49.18]],"id":38214982}],"con":true,"img":false}]}
{"op":"mcm","clk":"5348777903","pt":1646220614731,"mc":[{"id":"1.195453678","rc":[{"atb":[[1.9,20.73]],"id":38214982}],"con":true,"img":false}]}
{"op":"mcm","clk":"5348777911","pt":1646220614795,"mc":[{"id":"1.195453678","rc":[{"atb":[[1.89,16.42]],"id":38214982},{"atb":[[2,29.15]],"id":40324291}],"con":true,"img":false}]}
{"op":"mcm","clk":"5348777917","pt":1646220614896,"mc":[{"id":"1.195453678","rc":[{"atb":[[1.9,3.98]],"id":38214982},{"trd":[[1.9,36.34]],"ltp":1.9,"tv":36.34,"id":38214982}],"con":true,"img":false}]}
{"op":"mcm","clk":"5348777927","pt":1646220615005,"mc":[{"id":"1.195453678","rc":[{"atb":[[1.9,0]],"id":38214982}],"con":true,"img":false}]}
{"op":"mcm","clk":"5348777936","pt":1646220615104,"mc":[{"id":"1.195453678","rc":[{"atl":[[2.2,10.24]],"id":40324291}],"con":true,"img":false}]}
{"op":"mcm","clk":"5348778004","pt":1646220615935,"mc":[{"id":"1.195453678","rc":[{"atb":[[1.89,15],[1.88,0]],"id":38214982}],"con":true,"img":false}]}
{"op":"mcm","clk":"5348778025","pt":1646220616098,"mc":[{"id":"1.195453678","rc":[{"atl":[[2.2,2]],"id":40324291}],"con":true,"img":false}]}
{"op":"mcm","clk":"5348778035","pt":1646220616218,"mc":[{"id":"1.195453678","rc":[{"atb":[[1.89,31.9]],"id":38214982}],"con":true,"img":false}]}
{"op":"mcm","clk":"5348778055","pt":1646220616424,"mc":[{"id":"1.195453678","rc":[{"atl":[[2.2,10.22]],"id":40324291}],"con":true,"img":false}]}
{"op":"mcm","clk":"5348778359","pt":1646220619133,"mc":[{"id":"1.195453678","rc":[{"atb":[[1.85,34.29],[1.86,2]],"id":38214982}],"con":true,"img":false}]}
{"op":"mcm","clk":"5348778369","pt":1646220619236,"mc":[{"id":"1.195453678","rc":[{"atl":[[2.2,2]],"id":40324291}],"con":true,"img":false}]}
{"op":"mcm","clk":"5348779240","pt":1646220626730,"mc":[{"id":"1.195453678","rc":[{"atb":[[1.85,36.29],[1.86,0]],"id":38214982}],"con":true,"img":false}]}
{"op":"mcm","clk":"5348779886","pt":1646220633341,"mc":[{"id":"1.195453678","rc":[{"atb":[[1.82,2]],"id":38214982}],"con":true,"img":false}]}
{"op":"mcm","clk":"5348780197","pt":1646220635935,"mc":[{"id":"1.195453678","rc":[{"atb":[[1.77,0]],"id":40324291}],"con":true,"img":false}]}
{"op":"mcm","clk":"5348780207","pt":1646220636029,"mc":[{"id":"1.195453678","rc":[{"atb":[[1.82,2]],"id":40324291}],"con":true,"img":false}]}
{"op":"mcm","clk":"5348781439","pt":1646220647852,"mc":[{"id":"1.195453678","rc":[{"atl":[[2.2,10.22]],"id":40324291}],"con":true,"img":false}]}
{"op":"mcm","clk":"5348781603","pt":1646220649666,"mc":[{"id":"1.195453678","rc":[{"atl":[[2.2,2]],"id":40324291}],"con":true,"img":false}]}
{"op":"mcm","clk":"5348781636","pt":1646220650044,"mc":[{"id":"1.195453678","rc":[{"atl":[[2.2,10.27]],"id":40324291}],"con":true,"img":false}]}
{"op":"mcm","clk":"5348781815","pt":1646220652132,"mc":[{"id":"1.195453678","rc":[{"atl":[[2.18,24.3]],"id":40324291}],"con":true,"img":false}]}
{"op":"mcm","clk":"5348782169","pt":1646220656259,"mc":[{"id":"1.195453678","rc":[{"atl":[[2.18,16]],"id":40324291}],"con":true,"img":false}]}
{"op":"mcm","clk":"5348782235","pt":1646220657052,"mc":[{"id":"1.195453678","rc":[{"atl":[[2.18,24.33]],"id":40324291}],"con":true,"img":false}]}
{"op":"mcm","clk":"5348782271","pt":1646220657471,"mc":[{"id":"1.195453678","rc":[{"atb":[[1.64,0],[1.44,0],[1.54,0]],"id":38214982},{"atb":[[1.7,0],[1.8,0],[1.9,0]],"id":40324291}],"con":true,"img":false}]}
{"op":"mcm","clk":"5348782381","pt":1646220658666,"mc":[{"id":"1.195453678","rc":[{"atl":[[2.12,1.42]],"id":38214982}],"con":true,"img":false}]}
{"op":"mcm","clk":"5348782560","pt":1646220660555,"mc":[{"id":"1.195453678","rc":[{"atb":[[1.64,8.43],[1.44,12.26],[1.54,9.99]],"id":38214982},{"atb":[[1.7,7.7],[1.8,6.74],[1.9,5.99]],"id":40324291}],"con":true,"img":false}]}
{"op":"mcm","clk":"5348782569","pt":1646220660661,"mc":[{"id":"1.195453678","rc":[{"atb":[[1.86,10.05]],"id":38214982}],"con":true,"img":false}]}
{"op":"mcm","clk":"5348782588","pt":1646220660867,"mc":[{"id":"1.195453678","rc":[{"atb":[[1.86,0]],"id":38214982}],"con":true,"img":false}]}
{"op":"mcm","clk":"5348782604","pt":1646220661081,"mc":[{"id":"1.195453678","rc":[{"atb":[[2.02,1.42]],"id":40324291}],"con":true,"img":false}]}
{"op":"mcm","clk":"5348782631","pt":1646220661353,"mc":[{"id":"1.195453678","rc":[{"atb":[[1.89,64.65]],"id":38214982}],"con":true,"img":false}]}
{"op":"mcm","clk":"5348782804","pt":1646220663273,"mc":[{"id":"1.195453678","rc":[{"atl":[[2.18,16]],"id":40324291}],"con":true,"img":false}]}
{"op":"mcm","clk":"5348782852","pt":1646220663653,"mc":[{"id":"1.195453678","rc":[{"atl":[[1.98,1.42]],"id":38214982}],"con":true,"img":false}]}
{"op":"mcm","clk":"5348782922","pt":1646220664478,"mc":[{"id":"1.195453678","rc":[{"atb":[[1.83,15],[1.89,49.65],[1.84,36.7],[1.85,34.29],[1.82,0],[1.8,0]],"id":38214982},{"atl":[[2.12,3.42],[2.24,0]],"id":38214982},{"atb":[[1.87,2],[1.82,0]],"id":40324291},{"atl":[[2.22,0],[2.14,0],[2.18,0],[2.2,8.27],[2.16,3.42]],"id":40324291}],"con":true,"img":false}]}
{"op":"mcm","clk":"5348782954","pt":1646220664882,"mc":[{"id":"1.195453678","rc":[{"atb":[[1.89,16.9],[1.85,0]],"id":38214982}],"con":true,"img":false}]}
{"op":"mcm","clk":"5348782980","pt":1646220665164,"mc":[{"id":"1.195453678","rc":[{"atb":[[1.89,0]],"id":38214982}],"con":true,"img":false}]}
{"op":"mcm","clk":"5348783018","pt":1646220665578,"mc":[{"id":"1.195453678","rc":[{"atb":[[1.84,59.77]],"id":38214982}],"con":true,"img":false}]}
{"op":"mcm","clk":"5348783039","pt":1646220665735,"mc":[{"id":"1.195453678","rc":[{"atb":[[1.83,25.19],[1.78,12.19]],"id":38214982}],"con":true,"img":false}]}
{"op":"mcm","clk":"5348783276","pt":1646220668154,"mc":[{"id":"1.195453678","rc":[{"atl":[[2.18,1.42]],"id":40324291}],"con":true,"img":false}]}
{"op":"mcm","clk":"5348783292","pt":1646220668362,"mc":[{"id":"1.195453678","rc":[{"atb":[[1.83,15]],"id":38214982},{"atl":[[2.2,0]],"id":40324291}],"con":true,"img":false}]}
{"op":"mcm","clk":"5348783489","pt":1646220670044,"mc":[{"id":"1.195453678","rc":[{"atb":[[1.78,2]],"id":38214982}],"con":true,"img":false}]}
{"op":"mcm","clk":"5348783534","pt":1646220670357,"mc":[{"id":"1.195453678","rc":[{"atb":[[1.78,12.54]],"id":38214982}],"con":true,"img":false}]}
{"op":"mcm","clk":"5348783627","pt":1646220671244,"mc":[{"id":"1.195453678","rc":[{"atb":[[1.83,0]],"id":38214982},{"atl":[[2.18,11.42],[2.16,1.42]],"id":40324291}],"con":true,"img":false}]}
{"op":"mcm","clk":"5348784225","pt":1646220676278,"mc":[{"id":"1.195453678","rc":[{"atb":[[1.78,10.54],[1.77,57]],"id":38214982}],"con":true,"img":false}]}
{"op":"mcm","clk":"5348784229","pt":1646220676375,"mc":[{"id":"1.195453678","rc":[{"atb":[[1.83,22.9],[1.84,57.77]],"id":38214982},{"atl":[[2.24,0]],"id":40324291}],"con":true,"img":false}]}
{"op":"mcm","clk":"5348784534","pt":1646220678387,"mc":[{"id":"1.195453678","rc":[{"atb":[[1.84,34.7]],"id":38214982},{"atl":[[2.12,1.42]],"id":40324291}],"con":true,"img":false}]}
{"op":"mcm","clk":"5348784625","pt":1646220678978,"mc":[{"id":"1.195453678","rc":[{"atb":[[1.84,52.67]],"id":38214982},{"atl":[[2.24,1.42],[2.12,4.26]],"id":40324291}],"con":true,"img":false}]}
{"op":"mcm","clk":"5348784819","pt":1646220680201,"mc":[{"id":"1.195453678","rc":[{"atl":[[2.24,2.84]],"id":40324291}],"con":true,"img":false}]}
{"op":"mcm","clk":"5348784907","pt":1646220680776,"mc":[{"id":"1.195453678","rc":[{"atl":[[1.98,4.26]],"id":38214982},{"atb":[[2.02,4.26]],"id":40324291}],"con":true,"img":false}]}
{"op":"mcm","clk":"5348784917","pt":1646220680879,"mc":[{"id":"1.195453678","rc":[{"atb":[[1.84,34.7]],"id":38214982},{"atl":[[2.12,1.42]],"id":40324291}],"con":true,"img":false}]}
{"op":"mcm","clk":"5348784988","pt":1646220681364,"mc":[{"id":"1.195453678","rc":[{"atl":[[2.18,1.42],[2.16,11.42]],"id":40324291}],"con":true,"img":false}]}
{"op":"mcm","clk":"5348785003","pt":1646220681465,"mc":[{"id":"1.195453678","rc":[{"atl":[[2,0]],"id":38214982}],"con":true,"img":false}]}
{"op":"mcm","clk":"5348785016","pt":1646220681581,"mc":[{"id":"1.195453678","rc":[{"atb":[[1.83,0],[1.84,55.6]],"id":38214982}],"con":true,"img":false}]}
{"op":"mcm","clk":"5348785029","pt":1646220681714,"mc":[{"id":"1.195453678","rc":[{"atl":[[1.89,8.75]],"id":38214982},{"trd":[[1.89,1.59]],"ltp":1.89,"tv":1.59,"id":38214982},{"atl":[[2.12,0]],"id":40324291},{"trd":[[2.12,1.42]],"ltp":2.12,"tv":1.42,"id":40324291}],"con":true,"img":false}]}
{"op":"mcm","clk":"5348785056","pt":1646220681891,"mc":[{"id":"1.195453678","rc":[{"atb":[[2,0]],"id":40324291}],"con":true,"img":false}]}
{"op":"mcm","clk":"5348785067","pt":1646220681996,"mc":[{"id":"1.195453678","rc":[{"atl":[[1.89,0.02]],"id":38214982},{"trd":[[1.89,10.33]],"ltp":1.89,"tv":10.33,"id":38214982},{"trd":[[2.12,9.21]],"ltp":2.12,"tv":9.21,"id":40324291}],"con":true,"img":false}]}
{"op":"mcm","clk":"5348785098","pt":1646220682160,"mc":[{"id":"1.195453678","rc":[{"atl":[[1.89,0]],"id":38214982},{"trd":[[1.89,10.37]],"ltp":1.89,"tv":10.37,"id":38214982},{"atl":[[2.26,10.04]],"id":40324291}],"con":true,"img":false}]}
{"op":"mcm","clk":"5348785184","pt":1646220682787,"mc":[{"id":"1.195453678","rc":[{"atl":[[2.14,1.42]],"id":40324291}],"con":true,"img":false}]}
{"op":"mcm","clk":"5348785204","pt":1646220682998,"mc":[{"id":"1.195453678","rc":[{"atl":[[2.24,10.95]],"id":40324291}],"con":true,"img":false}]}
{"op":"mcm","clk":"5348785246","pt":1646220683263,"mc":[{"id":"1.195453678","rc":[{"atl":[[2.22,8.22]],"id":40324291}],"con":true,"img":false}]}
{"op":"mcm","clk":"5348785361","pt":1646220684162,"mc":[{"id":"1.195453678","rc":[{"atl":[[1.97,1.42]],"id":38214982},{"atl":[[2.14,0]],"id":40324291}],"con":true,"img":false}]}
{"op":"mcm","clk":"5348785412","pt":1646220684476,"mc":[{"id":"1.195453678","rc":[{"atl":[[1.98,1.42]],"id":38214982}],"con":true,"img":false}]}
{"op":"mcm","clk":"5348785438","pt":1646220684593,"mc":[{"id":"1.195453678","rc":[{"atl":[[1.97,4.26]],"id":38214982}],"con":true,"img":false}]}
{"op":"mcm","clk":"5348785486","pt":1646220684904,"mc":[{"id":"1.195453678","rc":[{"atb":[[2,29.15]],"id":40324291}],"con":true,"img":false}]}
{"op":"mcm","clk":"5348785695","pt":1646220686294,"mc":[{"id":"1.195453678","rc":[{"atl":[[1.96,1.42]],"id":38214982},{"atb":[[2.04,1.42]],"id":40324291},{"atl":[[2.14,1.42]],"id":40324291}],"con":true,"img":false}]}
{"op":"mcm","clk":"5348785758","pt":1646220686671,"mc":[{"id":"1.195453678","rc":[{"atl":[[1.97,1.42]],"id":38214982},{"atb":[[2.02,1.42]],"id":40324291}],"con":true,"img":false}]}
{"op":"mcm","clk":"5348785771","pt":1646220686772,"mc":[{"id":"1.195453678","rc":[{"atl":[[1.96,4.26]],"id":38214982},{"atb":[[2.04,4.26]],"id":40324291}],"con":true,"img":false}]}
{"op":"mcm","clk":"5348785811","pt":1646220687088,"mc":[{"id":"1.195453678","rc":[{"atl":[[2.12,1.42]],"id":38214982}],"con":true,"img":false}]}
{"op":"mcm","clk":"5348785830","pt":1646220687297,"mc":[{"id":"1.195453678","rc":[{"atl":[[2.16,14.8]],"id":38214982}],"con":true,"img":false}]}
{"op":"mcm","clk":"5348785860","pt":1646220687512,"mc":[{"id":"1.195453678","rc":[{"atl":[[1.96,5.68]],"id":38214982},{"atb":[[2.04,5.68]],"id":40324291},{"atl":[[2.14,2.84]],"id":40324291}],"con":true,"img":false}]}
{"op":"mcm","clk":"5348785948","pt":1646220688158,"mc":[{"id":"1.195453678","rc":[{"atl":[[2.14,1.42]],"id":40324291}],"con":true,"img":false}]}
{"op":"mcm","clk":"5348786026","pt":1646220688689,"mc":[{"id":"1.195453678","rc":[{"atb":[[1.85,10.06]],"id":38214982},{"atl":[[2.18,9.79]],"id":40324291}],"con":true,"img":false}]}
{"op":"mcm","clk":"5348786049","pt":1646220688895,"mc":[{"id":"1.195453678","rc":[{"atb":[[1.84,34.7],[1.86,15.74]],"id":38214982}],"con":true,"img":false}]}
{"op":"mcm","clk":"5348786077","pt":1646220689064,"mc":[{"id":"1.195453678","rc":[{"atb":[[1.86,25.76]],"id":38214982},{"atl":[[2.26,2],[2.16,19.82]],"id":40324291}],"con":true,"img":false}]}
{"op":"mcm","clk":"5348786093","pt":1646220689178,"mc":[{"id":"1.195453678","rc":[{"atl":[[1.96,2.84]],"id":38214982},{"atb":[[2.04,2.84]],"id":40324291}],"con":true,"img":false}]}
{"op":"mcm","clk":"5348786205","pt":1646220689859,"mc":[{"id":"1.195453678","rc":[{"atb":[[1.87,33.5]],"id":38214982}],"con":true,"img":false}]}
{"op":"mcm","clk":"5348786229","pt":1646220690067,"mc":[{"id":"1.195453678","rc":[{"atb":[[1.86,10.02],[1.87,46.36]],"id":38214982}],"con":true,"img":false}]}
{"op":"mcm","clk":"5348786281","pt":1646220690500,"mc":[{"id":"1.195453678","rc":[{"atl":[[1.96,0]],"id":38214982},{"atl":[[2.14,0]],"id":40324291}],"con":true,"img":false}]}
{"op":"mcm","clk":"5348786327","pt":1646220690763,"mc":[{"id":"1.195453678","rc":[{"atl":[[1.97,4.26]],"id":38214982}],"con":true,"img":false}]}
{"op":"mcm","clk":"5348786340","pt":1646220690880,"mc":[{"id":"1.195453678","rc":[{"atb":[[2,0]],"id":40324291}],"con":true,"img":false}]}
{"op":"mcm","clk":"5348786527","pt":1646220691987,"mc":[{"id":"1.195453678","rc":[{"atb":[[2.04,8.52]],"id":40324291}],"con":true,"img":false}]}
{"op":"mcm","clk":"5348786595","pt":1646220692398,"mc":[{"id":"1.195453678","rc":[{"atl":[[1.96,1.42]],"id":38214982},{"atb":[[2,29.15],[2.04,5.68]],"id":40324291},{"atl":[[2.14,1.42]],"id":40324291}],"con":true,"img":false}]}
{"op":"mcm","clk":"5348786638","pt":1646220692666,"mc":[{"id":"1.195453678","rc":[{"atl":[[1.97,1.42]],"id":38214982},{"atb":[[2.04,0]],"id":40324291}],"con":true,"img":false}]}
{"op":"mcm","clk":"5348786647","pt":1646220692773,"mc":[{"id":"1.195453678","rc":[{"atl":[[1.96,4.26]],"id":38214982},{"atb":[[2.02,7.1]],"id":40324291}],"con":true,"img":false}]}
{"op":"mcm","clk":"5348786658","pt":1646220692881,"mc":[{"id":"1.195453678","rc":[{"atb":[[1.88,25]],"id":38214982}],"con":true,"img":false}]}
{"op":"mcm","clk":"5348786727","pt":1646220693303,"mc":[{"id":"1.195453678","rc":[{"atb":[[1.86,0]],"id":38214982},{"atl":[[2.16,11.42]],"id":40324291}],"con":true,"img":false}]}
{"op":"mcm","clk":"5348786779","pt":1646220693675,"mc":[{"id":"1.195453678","rc":[{"atl":[[2.24,15],[2.52,75],[2.28,22],[2.46,2],[2.3,2],[2.32,2],[2.34,33],[2.48,2],[2.36,2],[2.4,2],[2.42,50]],"id":38214982}],"con":true,"img":false}]}
{"op":"mcm","clk":"5348786973","pt":1646220695229,"mc":[{"id":"1.195453678","rc":[{"atl":[[2.16,19.86]],"id":40324291}],"con":true,"img":false}]}
{"op":"mcm","clk":"5348787150","pt":1646220696475,"mc":[{"id":"1.195453678","rc":[{"atl":[[2.16,11.42]],"id":40324291}],"con":true,"img":false}]}
{"op":"mcm","clk":"5348787266","pt":1646220697168,"mc":[{"id":"1.195453678","rc":[{"atl":[[2.16,19.81]],"id":40324291}],"con":true,"img":false}]}
{"op":"mcm","clk":"5348787320","pt":1646220697583,"mc":[{"id":"1.195453678","rc":[{"atl":[[2.16,11.42]],"id":40324291}],"con":true,"img":false}]}
{"op":"mcm","clk":"5348787509","pt":1646220698999,"mc":[{"id":"1.195453678","rc":[{"atb":[[1.87,33.5],[1.86,14.32]],"id":38214982}],"con":true,"img":false}]}
{"op":"mcm","clk":"5348787783","pt":1646220700975,"mc":[{"id":"1.195453678","rc":[{"atb":[[1.89,9.69],[1.86,24.01]],"id":38214982},{"atl":[[2.14,10.09]],"id":40324291}],"con":true,"img":false}]}
{"op":"mcm","clk":"5348787797","pt":1646220701080,"mc":[{"id":"1.195453678","rc":[{"atl":[[2.14,29.66],[2.16,1.42]],"id":40324291}],"con":true,"img":false}]}
{"op":"mcm","clk":"5348787837","pt":1646220701388,"mc":[{"id":"1.195453678","rc":[{"atb":[[1.89,42.44]],"id":38214982}],"con":true,"img":false}]}
{"op":"mcm","clk":"5348787880","pt":1646220701709,"mc":[{"id":"1.195453678","rc":[{"atl":[[2.14,20.99]],"id":40324291}],"con":true,"img":false}]}
{"op":"mcm","clk":"5348788064","pt":1646220702978,"mc":[{"id":"1.195453678","rc":[{"atb":[[1.9,9.7]],"id":38214982},{"atl":[[2.12,8.67],[2.16,10.09]],"id":40324291}],"con":true,"img":false}]}
{"op":"mcm","clk":"5348788077","pt":1646220703077,"mc":[{"id":"1.195453678","rc":[{"atb":[[1.89,14],[1.9,0]],"id":38214982},{"trd":[[1.89,67.27],[1.9,55.74]],"ltp":1.89,"tv":123.0,"id":38214982}],"con":true,"img":false}]}
{"op":"mcm","clk":"5348788100","pt":1646220703293,"mc":[{"id":"1.195453678","rc":[{"atl":[[1.95,9.74]],"id":38214982},{"atb":[[2.04,8.62]],"id":40324291}],"con":true,"img":false}]}
{"op":"mcm","clk":"5348788114","pt":1646220703393,"mc":[{"id":"1.195453678","rc":[{"atb":[[1.89,0],[1.86,14.32]],"id":38214982},{"atl":[[2.14,0]],"id":38214982},{"atb":[[1.92,0]],"id":40324291},{"atl":[[2.12,0],[2.16,1.42]],"id":40324291}],"con":true,"img":false}]}
{"op":"mcm","clk":"5348788140","pt":1646220703601,"mc":[{"id":"1.195453678","rc":[{"atl":[[1.96,1.42]],"id":38214982},{"atb":[[2.02,1.42]],"id":40324291}],"con":true,"img":false}]}
{"op":"mcm","clk":"5348788169","pt":1646220703817,"mc":[{"id":"1.195453678","rc":[{"atb":[[1.86,24.19]],"id":38214982},{"atl":[[2.16,9.97]],"id":40324291}],"con":true,"img":false}]}
{"op":"mcm","clk":"5348788187","pt":1646220703912,"mc":[{"id":"1.195453678","rc":[{"atl":[[1.95,20.93]],"id":38214982},{"atb":[[2.04,20.06],[1.95,0]],"id":40324291}],"con":true,"img":false}]}
{"op":"mcm","clk":"5348788234","pt":1646220704179,"mc":[{"id":"1.195453678","rc":[{"atl":[[1.95,9.74]],"id":38214982},{"atb":[[2.04,8.62]],"id":40324291}],"con":true,"img":false}]}
{"op":"mcm","clk":"5348788245","pt":1646220704284,"mc":[{"id":"1.195453678","rc":[{"atl":[[1.96,12.61]],"id":38214982},{"atb":[[2.02,12.86]],"id":40324291}],"con":true,"img":false}]}
{"op":"mcm","clk":"5348788260","pt":1646220704387,"mc":[{"id":"1.195453678","rc":[{"atb":[[1.87,0],[1.86,58.09]],"id":38214982},{"atb":[[2.02,41.43]],"id":40324291}],"con":true,"img":false}]}
{"op":"mcm","clk":"5348788301","pt":1646220704700,"mc":[{"id":"1.195453678","rc":[{"atl":[[1.96,1.42]],"id":38214982},{"atb":[[2.02,29.99]],"id":40324291}],"con":true,"img":false}]}
{"op":"mcm","clk":"5348788316","pt":1646220704805,"mc":[{"id":"1.195453678","rc":[{"atl":[[1.95,20.93]],"id":38214982},{"atb":[[2.04,20.06]],"id":40324291}],"con":true,"img":false}]}
{"op":"mcm","clk":"5348788330","pt":1646220704911,"mc":[{"id":"1.195453678","rc":[{"atb":[[1.89,9.76]],"id":38214982},{"atl":[[1.95,11.19]],"id":38214982},{"atl":[[2.12,8.64],[2.24,2.84]],"id":40324291}],"con":true,"img":false}]}
{"op":"mcm","clk":"5348788360","pt":1646220705120,"mc":[{"id":"1.195453678","rc":[{"atl":[[1.96,11.09]],"id":38214982}],"con":true,"img":false}]}
{"op":"mcm","clk":"5348788366","pt":1646220705182,"mc":[{"id":"1.195453678","rc":[{"atl":[[1.95,0]],"id":38214982},{"atb":[[2.04,8.62]],"id":40324291}],"con":true,"img":false}]}
{"op":"mcm","clk":"5348788398","pt":1646220705404,"mc":[{"id":"1.195453678","rc":[{"atb":[[1.84,0]],"id":38214982}],"con":true,"img":false}]}
{"op":"mcm","clk":"5348788410","pt":1646220705498,"mc":[{"id":"1.195453678","rc":[{"atl":[[1.96,22.84]],"id":38214982},{"atb":[[2.04,20.01]],"id":40324291}],"con":true,"img":false}]}
{"op":"mcm","clk":"5348788444","pt":1646220705726,"mc":[{"id":"1.195453678","rc":[{"atl":[[1000,0.07]],"id":38214982}],"con":true,"img":false}]}
{"op":"mcm","clk":"5348788468","pt":1646220705886,"mc":[{"id":"1.195453678","rc":[{"atl":[[1000,0]],"id":38214982}],"con":true,"img":false}]}
{"op":"mcm","clk":"5348788482","pt":1646220705988,"mc":[{"id":"1.195453678","rc":[{"atb":[[1.89,9.69]],"id":38214982},{"trd":[[1.89,67.41]],"ltp":1.89,"tv":67.41,"id":38214982}],"con":true,"img":false}]}
{"op":"mcm","clk":"5348788528","pt":1646220706404,"mc":[{"id":"1.195453678","rc":[{"atb":[[1.87,33.5]],"id":38214982}],"con":true,"img":false}]}
{"op":"mcm","clk":"5348788605","pt":1646220706988,"mc":[{"id":"1.195453678","rc":[{"atl":[[1.96,11.09]],"id":38214982},{"atb":[[2.04,8.62]],"id":40324291}],"con":true,"img":false}]}
{"op":"mcm","clk":"5348788619","pt":1646220707089,"mc":[{"id":"1.195453678","rc":[{"atb":[[1.89,16.97]],"id":38214982},{"atb":[[1.95,1.42]],"id":40324291},{"atl":[[2.12,14.94]],"id":40324291}],"con":true,"img":false}]}
{"op":"mcm","clk":"5348788662","pt":1646220707408,"mc":[{"id":"1.195453678","rc":[{"atb":[[2.02,1.42]],"id":40324291}],"con":true,"img":false}]}
{"op":"mcm","clk":"5348788690","pt":1646220707618,"mc":[{"id":"1.195453678","rc":[{"atb":[[1.78,0],[1.9,9.7]],"id":38214982}],"con":true,"img":false}]}
{"op":"mcm","clk":"5348788706","pt":1646220707715,"mc":[{"id":"1.195453678","rc":[{"atl":[[2.1,8.66]],"id":40324291}],"con":true,"img":false}]}
{"op":"mcm","clk":"5348788723","pt":1646220707820,"mc":[{"id":"1.195453678","rc":[{"atl":[[2.22,0]],"id":40324291}],"con":true,"img":false}]}
{"op":"mcm","clk":"5348788738","pt":1646220707933,"mc":[{"id":"1.195453678","rc":[{"atl":[[1.96,1.42]],"id":38214982},{"atb":[[2.04,0]],"id":40324291}],"con":true,"img":false}]}
{"op":"mcm","clk":"5348788750","pt":1646220707983,"mc":[{"id":"1.195453678","rc":[{"atb":[[1.89,9.69]],"id":38214982}],"con":true,"img":false}]}
{"op":"mcm","clk":"5348788765","pt":1646220708084,"mc":[{"id":"1.195453678","rc":[{"atb":[[1.9,16.98]],"id":38214982}],"con":true,"img":false}]}
{"op":"mcm","clk":"5348788776","pt":1646220708191,"mc":[{"id":"1.195453678","rc":[{"atb":[[1.91,9.66]],"id":38214982},{"atb":[[2.06,1]],"id":40324291}],"con":true,"img":false}]}
{"op":"mcm","clk":"5348788789","pt":1646220708296,"mc":[{"id":"1.195453678","rc":[{"atb":[[1.85,0]],"id":38214982}],"con":true,"img":false}]}
{"op":"mcm","clk":"5348788811","pt":1646220708502,"mc":[{"id":"1.195453678","rc":[{"atb":[[1.9,9.7]],"id":38214982},{"atl":[[1.96,4.26]],"id":38214982},{"atb":[[2.02,4.26]],"id":40324291}],"con":true,"img":false}]}
{"op":"mcm","clk":"5348788822","pt":1646220708609,"mc":[{"id":"1.195453678","rc":[{"atb":[[1.95,2.84],[2.02,13]],"id":40324291},{"atl":[[2.2,1.42]],"id":40324291}],"con":true,"img":false}]}
{"op":"mcm","clk":"5348788836","pt":1646220708711,"mc":[{"id":"1.195453678","rc":[{"atl":[[2.14,1.42],[2.16,22.89]],"id":40324291}],"con":true,"img":false}]}
{"op":"mcm","clk":"5348788846","pt":1646220708815,"mc":[{"id":"1.195453678","rc":[{"atb":[[2.02,10.16]],"id":40324291}],"con":true,"img":false}]}
{"op":"mcm","clk":"5348788863","pt":1646220708926,"mc":[{"id":"1.195453678","rc":[{"atb":[[2.06,3.84]],"id":40324291}],"con":true,"img":false}]}
{"op":"mcm","clk":"5348788897","pt":1646220709088,"mc":[{"id":"1.195453678","rc":[{"atb":[[2.06,0.01]],"id":40324291},{"trd":[[2.06,7.66]],"ltp":2.06,"tv":7.66,"id":40324291}],"con":true,"img":false}]}
{"op":"mcm","clk":"5348788955","pt":1646220709504,"mc":[{"id":"1.195453678","rc":[{"atb":[[2.06,0]],"id":40324291}],"con":true,"img":false}]}
{"op":"mcm","clk":"5348788970","pt":1646220709607,"mc":[{"id":"1.195453678","rc":[{"atl":[[1.96,2.84]],"id":38214982}],"con":true,"img":false}]}
{"op":"mcm","clk":"5348788981","pt":1646220709714,"mc":[{"id":"1.195453678","rc":[{"atl":[[1.97,11.02]],"id":38214982}],"con":true,"img":false}]}
{"op":"mcm","clk":"5348788995","pt":1646220709818,"mc":[{"id":"1.195453678","rc":[{"atl":[[1.96,0]],"id":38214982}],"con":true,"img":false}]}
{"op":"mcm","clk":"5348789004","pt":1646220709874,"mc":[{"id":"1.195453678","rc":[{"atl":[[1000,1.69]],"id":40324291}],"con":true,"img":false}]}
{"op":"mcm","clk":"5348789020","pt":1646220709979,"mc":[{"id":"1.195453678","rc":[{"atl":[[1000,1.69]],"id":38214982}],"con":true,"img":false}]}
{"op":"mcm","clk":"5348789038","pt":1646220710083,"mc":[{"id":"1.195453678","rc":[{"atl":[[1000,0.02]],"id":40324291}],"con":true,"img":false}]}
{"op":"mcm","clk":"5348789049","pt":1646220710190,"mc":[{"id":"1.195453678","rc":[{"atl":[[1000,0.02]],"id":38214982}],"con":true,"img":false}]}
{"op":"mcm","clk":"5348789060","pt":1646220710291,"mc":[{"id":"1.195453678","rc":[{"atl":[[1000,0]],"id":38214982},{"atl":[[1000,0]],"id":40324291}],"con":true,"img":false}]}
{"op":"mcm","clk":"5348789076","pt":1646220710396,"mc":[{"id":"1.195453678","rc":[{"atl":[[1.96,0.02],[1.97,1.42]],"id":38214982},{"atl":[[2.14,1.44]],"id":40324291}],"con":true,"img":false}]}
{"op":"mcm","clk":"5348789120","pt":1646220710709,"mc":[{"id":"1.195453678","rc":[{"atb":[[2.02,16.25]],"id":40324291}],"con":true,"img":false}]}
{"op":"mcm","clk":"5348789135","pt":1646220710813,"mc":[{"id":"1.195453678","rc":[{"atb":[[2.02,7.51]],"id":40324291}],"con":true,"img":false}]}
{"op":"mcm","clk":"5348789196","pt":1646220711190,"mc":[{"id":"1.195453678","rc":[{"atb":[[2.02,4.26]],"id":40324291}],"con":true,"img":false}]}
{"op":"mcm","clk":"5348789251","pt":1646220711613,"mc":[{"id":"1.195453678","rc":[{"atb":[[2.02,1.42]],"id":40324291}],"con":true,"img":false}]}
{"op":"mcm","clk":"5348789267","pt":1646220711719,"mc":[{"id":"1.195453678","rc":[{"atl":[[1.97,0]],"id":38214982},{"atb":[[1.98,29.74]],"id":40324291},{"atl":[[2.22,1.42]],"id":40324291}],"con":true,"img":false}]}
{"op":"mcm","clk":"5348789289","pt":1646220711882,"mc":[{"id":"1.195453678","rc":[{"atb":[[1.86,24.19]],"id":38214982},{"atb":[[2,0]],"id":40324291}],"con":true,"img":false}]}
{"op":"mcm","clk":"5348789351","pt":1646220712403,"mc":[{"id":"1.195453678","rc":[{"atb":[[1.9,42.09]],"id":38214982}],"con":true,"img":false}]}
{"op":"mcm","clk":"5348789418","pt":1646220712926,"mc":[{"id":"1.195453678","rc":[{"atb":[[1.64,0],[1.44,0],[1.54,0],[1.9,9.7]],"id":38214982},{"atb":[[1.7,0],[1.8,0],[1.9,0]],"id":40324291}],"con":true,"img":false}]}
{"op":"mcm","clk":"5348789474","pt":1646220713405,"mc":[{"id":"1.195453678","rc":[{"atb":[[1.9,42.09]],"id":38214982}],"con":true,"img":false}]}
{"op":"mcm","clk":"5348789487","pt":1646220713507,"mc":[{"id":"1.195453678","rc":[{"atl":[[2.12,0]],"id":38214982},{"atb":[[1.95,0],[1.93,0],[1.97,8.37]],"id":40324291}],"con":true,"img":false}]}
{"op":"mcm","clk":"5348789538","pt":1646220713880,"mc":[{"id":"1.195453678","rc":[{"atb":[[1.9,9.7]],"id":38214982},{"atl":[[1.98,4.3]],"id":38214982},{"atb":[[2.02,4.26]],"id":40324291},{"atl":[[2.14,19.87],[2.16,9.97]],"id":40324291}],"con":true,"img":false}]}
{"op":"mcm","clk":"5348789609","pt":1646220714406,"mc":[{"id":"1.195453678","rc":[{"atb":[[1.9,42.09]],"id":38214982}],"con":true,"img":false}]}
{"op":"mcm","clk":"5348789680","pt":1646220714996,"mc":[{"id":"1.195453678","rc":[{"atl":[[1.99,0]],"id":38214982}],"con":true,"img":false}]}
{"op":"mcm","clk":"5348789728","pt":1646220715310,"mc":[{"id":"1.195453678","rc":[{"atl":[[1.98,1.42]],"id":38214982},{"atb":[[2.02,1.42]],"id":40324291}],"con":true,"img":false}]}
{"op":"mcm","clk":"5348789740","pt":1646220715417,"mc":[{"id":"1.195453678","rc":[{"atb":[[1.98,0],[1.97,38.42]],"id":40324291}],"con":true,"img":false}]}
{"op":"mcm","clk":"5348789781","pt":1646220715693,"mc":[{"id":"1.195453678","rc":[{"atb":[[1.91,1.49]],"id":38214982},{"trd":[[1.91,16.35]],"ltp":1.91,"tv":16.35,"id":38214982}],"con":true,"img":false}]}
{"op":"mcm","clk":"5348789806","pt":1646220715941,"mc":[{"id":"1.195453678","rc":[{"atb":[[1.97,8.37]],"id":40324291}],"con":true,"img":false}]}
{"op":"mcm","clk":"5348789871","pt":1646220716421,"mc":[{"id":"1.195453678","rc":[{"atb":[[1.95,30.68]],"id":40324291}],"con":true,"img":false}]}
{"op":"mcm","clk":"5348790015","pt":1646220717795,"mc":[{"id":"1.195453678","rc":[{"atb":[[2.02,10.25]],"id":40324291}],"con":true,"img":false}]}
{"op":"mcm","clk":"5348790040","pt":1646220718000,"mc":[{"id":"1.195453678","rc":[{"atl":[[1.98,4.3]],"id":38214982},{"atb":[[2.02,13.09]],"id":40324291}],"con":true,"img":false}]}
{"op":"mcm","clk":"5348790051","pt":1646220718115,"mc":[{"id":"1.195453678","rc":[{"atb":[[2.02,4.26]],"id":40324291}],"con":true,"img":false}]}
{"op":"mcm","clk":"5348790083","pt":1646220718417,"mc":[{"id":"1.195453678","rc":[{"atb":[[1.97,38.42]],"id":40324291}],"con":true,"img":false}]}
{"op":"mcm","clk":"5348790526","pt":1646220721798,"mc":[{"id":"1.195453678","rc":[{"atb":[[1.99,8.34],[2.02,2.84]],"id":40324291},{"atl":[[2.14,18.45]],"id":40324291}],"con":true,"img":false}]}
{"op":"mcm","clk":"5348790570","pt":1646220722112,"mc":[{"id":"1.195453678","rc":[{"atl":[[1.98,1.42]],"id":38214982},{"atb":[[2.02,0]],"id":40324291}],"con":true,"img":false}]}
{"op":"mcm","clk":"5348790612","pt":1646220722421,"mc":[{"id":"1.195453678","rc":[{"atb":[[1.99,15.38],[1.97,8.37]],"id":40324291}],"con":true,"img":false}]}
{"op":"mcm","clk":"5348790653","pt":1646220722693,"mc":[{"id":"1.195453678","rc":[{"atb":[[1.03,2.87]],"id":38214982},{"atb":[[2,8.86]],"id":40324291}],"con":true,"img":false}]}
{"op":"mcm","clk":"5348790672","pt":1646220722900,"mc":[{"id":"1.195453678","rc":[{"atb":[[1.03,0.14]],"id":38214982}],"con":true,"img":false}]}
{"op":"mcm","clk":"5348790685","pt":1646220723004,"mc":[{"id":"1.195453678","rc":[{"atb":[[1.99,8.34]],"id":40324291}],"con":true,"img":false}]}
{"op":"mcm","clk":"5348790693","pt":1646220723102,"mc":[{"id":"1.195453678","rc":[{"atb":[[1.03,0]],"id":38214982},{"atb":[[2,15.9]],"id":40324291}],"con":true,"img":false}]}
{"op":"mcm","clk":"5348790707","pt":1646220723212,"mc":[{"id":"1.195453678","rc":[{"atl":[[1.96,0],[1.98,1.3]],"id":38214982},{"trd":[[1.98,0.23],[1.96,0.05]],"ltp":1.98,"tv":0.28,"id":38214982}],"con":true,"img":false}]}
{"op":"mcm","clk":"5348790729","pt":1646220723422,"mc":[{"id":"1.195453678","rc":[{"atb":[[1.98,29.74]],"id":40324291}],"con":true,"img":false}]}
{"op":"mcm","clk":"5348790781","pt":1646220723796,"mc":[{"id":"1.195453678","rc":[{"atb":[[1.85,19.64]],"id":38214982},{"atl":[[2.14,0.02]],"id":40324291}],"con":true,"img":false}]}
{"op":"mcm","clk":"5348790794","pt":1646220723903,"mc":[{"id":"1.195453678","rc":[{"atb":[[1.86,9.87]],"id":38214982},{"atl":[[2.22,0],[2.24,0],[2.28,0],[2.18,8.37],[2.2,0],[2.16,32.16]],"id":40324291}],"con":true,"img":false}]}
{"op":"mcm","clk":"5348790827","pt":1646220724117,"mc":[{"id":"1.195453678","rc":[{"atb":[[1.62,8.7],[1.72,136.49],[1.52,10.37]],"id":38214982},{"atb":[[1.85,6.34],[1.75,7.19],[1.65,8.3]],"id":40324291}],"con":true,"img":false}]}
{"op":"mcm","clk":"5348790926","pt":1646220724894,"mc":[{"id":"1.195453678","rc":[{"atl":[[1.98,3.9]],"id":38214982}],"con":true,"img":false}]}
{"op":"mcm","clk":"5348790955","pt":1646220725105,"mc":[{"id":"1.195453678","rc":[{"atl":[[1.97,2.82]],"id":38214982}],"con":true,"img":false}]}
{"op":"mcm","clk":"5348790993","pt":1646220725416,"mc":[{"id":"1.195453678","rc":[{"atl":[[1.98,1.3]],"id":38214982},{"atb":[[2,45.05]],"id":40324291}],"con":true,"img":false}]}
{"op":"mcm","clk":"5348791046","pt":1646220725834,"mc":[{"id":"1.195453678","rc":[{"atl":[[1.97,8.48]],"id":38214982}],"con":true,"img":false}]}
{"op":"mcm","clk":"5348791062","pt":1646220725898,"mc":[{"id":"1.195453678","rc":[{"atb":[[2,15.9]],"id":40324291}],"con":true,"img":false}]}
{"op":"mcm","clk":"5348791096","pt":1646220726212,"mc":[{"id":"1.195453678","rc":[{"atl":[[1.97,2.82]],"id":38214982}],"con":true,"img":false}]}
{"op":"mcm","clk":"5348791115","pt":1646220726319,"mc":[{"id":"1.195453678","rc":[{"atl":[[2.06,0],[1.97,0]],"id":38214982},{"trd":[[1.97,5.65]],"ltp":1.97,"tv":5.65,"id":38214982},{"atb":[[2,7.04],[1.96,0],[1.99,0],[1.97,0]],"id":40324291}],"con":true,"img":false}]}
{"op":"mcm","clk":"5348791124","pt":1646220726426,"mc":[{"id":"1.195453678","rc":[{"atb":[[1.89,42.44],[1.9,9.7]],"id":38214982},{"atb":[[2,36.19]],"id":40324291}],"con":true,"img":false}]}
{"op":"mcm","clk":"5348791152","pt":1646220726642,"mc":[{"id":"1.195453678","rc":[{"atl":[[1.98,3.9]],"id":38214982},{"atb":[[2,29.15],[1.96,9.37]],"id":40324291}],"con":true,"img":false}]}
{"op":"mcm","clk":"5348791178","pt":1646220726809,"mc":[{"id":"1.195453678","rc":[{"atl":[[1.98,1.18]],"id":38214982},{"trd":[[1.98,5.68]],"ltp":1.98,"tv":5.68,"id":38214982}],"con":true,"img":false}]}
{"op":"mcm","clk":"5348791194","pt":1646220726912,"mc":[{"id":"1.195453678","rc":[{"atb":[[2,0],[1.98,0],[1.95,0]],"id":40324291}],"con":true,"img":false}]}
{"op":"mcm","clk":"5348791211","pt":1646220727031,"mc":[{"id":"1.195453678","rc":[{"atb":[[2,7.99]],"id":40324291}],"con":true,"img":false}]}
{"op":"mcm","clk":"5348791240","pt":1646220727225,"mc":[{"id":"1.195453678","rc":[{"atl":[[1.98,0]],"id":38214982}],"con":true,"img":false}]}
{"op":"mcm","clk":"5348791253","pt":1646220727329,"mc":[{"id":"1.195453678","rc":[{"atb":[[2,0]],"id":40324291}],"con":true,"img":false}]}
{"op":"mcm","clk":"5348791261","pt":1646220727435,"mc":[{"id":"1.195453678","rc":[{"atb":[[1.89,9.69],[1.87,0],[1.86,43.77]],"id":38214982},{"atl":[[2.14,2],[2.16,0]],"id":38214982},{"atb":[[1.88,33.12]],"id":40324291}],"con":true,"img":false}]}
{"op":"mcm","clk":"5348791292","pt":1646220727601,"mc":[{"id":"1.195453678","rc":[{"atb":[[1.96,21.07]],"id":40324291}],"con":true,"img":false}]}
{"op":"mcm","clk":"5348791341","pt":1646220728023,"mc":[{"id":"1.195453678","rc":[{"atb":[[1.97,9.06]],"id":40324291}],"con":true,"img":false}]}
{"op":"mcm","clk":"5348791375","pt":1646220728294,"mc":[{"id":"1.195453678","rc":[{"atb":[[1.96,9.37]],"id":40324291}],"con":true,"img":false}]}
{"op":"mcm","clk":"5348791386","pt":1646220728398,"mc":[{"id":"1.195453678","rc":[{"atb":[[1.9,42.09]],"id":38214982},{"atb":[[1.97,20.76],[1.91,32.03]],"id":40324291}],"con":true,"img":false}]}
{"op":"mcm","clk":"5348791395","pt":1646220728499,"mc":[{"id":"1.195453678","rc":[{"atl":[[2.1,24.11]],"id":38214982}],"con":true,"img":false}]}
{"op":"mcm","clk":"5348791437","pt":1646220728814,"mc":[{"id":"1.195453678","rc":[{"atl":[[2.08,9.23]],"id":38214982}],"con":true,"img":false}]}
{"op":"mcm","clk":"5348791449","pt":1646220728917,"mc":[{"id":"1.195453678","rc":[{"atl":[[2.08,18.47]],"id":38214982}],"con":true,"img":false}]}
{"op":"mcm","clk":"5348791459","pt":1646220729022,"mc":[{"id":"1.195453678","rc":[{"atb":[[1.85,0],[1.87,37]],"id":38214982},{"atl":[[2.14,24.35],[2.16,8.55]],"id":40324291}],"con":true,"img":false}]}
{"op":"mcm","clk":"5348791472","pt":1646220729130,"mc":[{"id":"1.195453678","rc":[{"atl":[[2.1,9.94],[2.14,0],[2.16,2]],"id":38214982}],"con":true,"img":false}]}
{"op":"mcm","clk":"5348791498","pt":1646220729344,"mc":[{"id":"1.195453678","rc":[{"atb":[[1.98,9.1]],"id":40324291}],"con":true,"img":false}]}
{"op":"mcm","clk":"5348791511","pt":1646220729406,"mc":[{"id":"1.195453678","rc":[{"atl":[[2.08,36.93]],"id":38214982},{"atb":[[1.93,31.34]],"id":40324291}],"con":true,"img":false}]}
{"op":"mcm","clk":"5348791558","pt":1646220729724,"mc":[{"id":"1.195453678","rc":[{"atb":[[1.97,9.06]],"id":40324291}],"con":true,"img":false}]}
{"op":"mcm","clk":"5348791585","pt":1646220729930,"mc":[{"id":"1.195453678","rc":[{"atb":[[1.88,0]],"id":40324291}],"con":true,"img":false}]}
{"op":"mcm","clk":"5348791599","pt":1646220729993,"mc":[{"id":"1.195453678","rc":[{"atb":[[1.98,24.89]],"id":40324291}],"con":true,"img":false}]}
{"op":"mcm","clk":"5348791613","pt":1646220730105,"mc":[{"id":"1.195453678","rc":[{"atl":[[2.06,18.48]],"id":38214982}],"con":true,"img":false}]}
{"op":"mcm","clk":"5348791629","pt":1646220730201,"mc":[{"id":"1.195453678","rc":[{"atb":[[1.99,9.08]],"id":40324291}],"con":true,"img":false}]}
{"op":"mcm","clk":"5348791663","pt":1646220730409,"mc":[{"id":"1.195453678","rc":[{"atl":[[2.08,18.47]],"id":38214982},{"atb":[[1.98,54.64]],"id":40324291}],"con":true,"img":false}]}
{"op":"mcm","clk":"5348791674","pt":1646220730513,"mc":[{"id":"1.195453678","rc":[{"atl":[[2.06,36.94]],"id":38214982},{"atb":[[1.98,38.85]],"id":40324291}],"con":true,"img":false}]}
{"op":"mcm","clk":"5348791690","pt":1646220730624,"mc":[{"id":"1.195453678","rc":[{"atb":[[1.99,24.87]],"id":40324291}],"con":true,"img":false}]}
{"op":"mcm","clk":"5348791718","pt":1646220730828,"mc":[{"id":"1.195453678","rc":[{"atl":[[2.06,18.48]],"id":38214982}],"con":true,"img":false}]}
{"op":"mcm","clk":"5348791731","pt":1646220730930,"mc":[{"id":"1.195453678","rc":[{"atb":[[1.99,9.08]],"id":40324291}],"con":true,"img":false}]}
{"op":"mcm","clk":"5348791742","pt":1646220731035,"mc":[{"id":"1.195453678","rc":[{"atb":[[1.98,54.64]],"id":40324291}],"con":true,"img":false}]}
{"op":"mcm","clk":"5348791776","pt":1646220731203,"mc":[{"id":"1.195453678","rc":[{"atl":[[2.06,31.46]],"id":38214982}],"con":true,"img":false}]}
{"op":"mcm","clk":"5348791791","pt":1646220731305,"mc":[{"id":"1.195453678","rc":[{"atb":[[1.98,38.85]],"id":40324291}],"con":true,"img":false}]}
{"op":"mcm","clk":"5348791807","pt":1646220731409,"mc":[{"id":"1.195453678","rc":[{"atb":[[1.99,24.87]],"id":40324291}],"con":true,"img":false}]}
{"op":"mcm","clk":"5348791852","pt":1646220731722,"mc":[{"id":"1.195453678","rc":[{"atb":[[1.03,3.12]],"id":40324291}],"con":true,"img":false}]}
{"op":"mcm","clk":"5348791868","pt":1646220731822,"mc":[{"id":"1.195453678","rc":[{"atl":[[2.06,24.27]],"id":38214982},{"atb":[[1.99,9.08]],"id":40324291}],"con":true,"img":false}]}
{"op":"mcm","clk":"5348791882","pt":1646220731931,"mc":[{"id":"1.195453678","rc":[{"atl":[[2.04,9.26]],"id":38214982},{"atb":[[2,9.06],[1.03,0.4],[1.96,0]],"id":40324291}],"con":true,"img":false}]}
{"op":"mcm","clk":"5348791911","pt":1646220732138,"mc":[{"id":"1.195453678","rc":[{"atb":[[1.03,0]],"id":40324291}],"con":true,"img":false}]}
{"op":"mcm","clk":"5348791941","pt":1646220732310,"mc":[{"id":"1.195453678","rc":[{"atl":[[2.1,8.25]],"id":40324291},{"trd":[[2.1,0.8]],"ltp":2.1,"tv":0.8,"id":40324291}],"con":true,"img":false}]}
{"op":"mcm","clk":"5348792044","pt":1646220733135,"mc":[{"id":"1.195453678","rc":[{"atl":[[2.06,18.48]],"id":38214982}],"con":true,"img":false}]}
{"op":"mcm","clk":"5348792091","pt":1646220733506,"mc":[{"id":"1.195453678","rc":[{"atl":[[2.04,15.95]],"id":38214982}],"con":true,"img":false}]}
{"op":"mcm","clk":"5348792214","pt":1646220734511,"mc":[{"id":"1.195453678","rc":[{"atl":[[2.04,9.26]],"id":38214982},{"atl":[[2.12,8.64]],"id":40324291}],"con":true,"img":false}]}
{"op":"mcm","clk":"5348792252","pt":1646220734825,"mc":[{"id":"1.195453678","rc":[{"atl":[[2.04,16.17]],"id":38214982}],"con":true,"img":false}]}
{"op":"mcm","clk":"5348792302","pt":1646220735247,"mc":[{"id":"1.195453678","rc":[{"atl":[[2.02,9.22]],"id":38214982}],"con":true,"img":false}]}
{"op":"mcm","clk":"5348792401","pt":1646220736038,"mc":[{"id":"1.195453678","rc":[{"atb":[[2,3.61]],"id":40324291},{"trd":[[2,10.9]],"ltp":2.0,"tv":10.9,"id":40324291}],"con":true,"img":false}]}
{"op":"mcm","clk":"5348792431","pt":1646220736246,"mc":[{"id":"1.195453678","rc":[{"atb":[[2,0]],"id":40324291}],"con":true,"img":false}]}
{"op":"mcm","clk":"5348792553","pt":1646220737137,"mc":[{"id":"1.195453678","rc":[{"atb":[[1.99,0]],"id":40324291}],"con":true,"img":false}]}
{"op":"mcm","clk":"5348792577","pt":1646220737347,"mc":[{"id":"1.195453678","rc":[{"atb":[[1.91,0],[1.9,27.56]],"id":38214982},{"trd":[[1.9,84.8],[1.91,25.29]],"ltp":1.9,"tv":110.09,"id":38214982},{"atl":[[2.1,14.88]],"id":40324291}],"con":true,"img":false}]}
{"op":"mcm","clk":"5348792596","pt":1646220737408,"mc":[{"id":"1.195453678","rc":[{"atb":[[1.98,9.1]],"id":40324291}],"con":true,"img":false}]}
{"op":"mcm","clk":"5348792609","pt":1646220737513,"mc":[{"id":"1.195453678","rc":[{"atb":[[1.99,9.1]],"id":40324291},{"atl":[[2.08,9.06]],"id":40324291}],"con":true,"img":false}]}
{"op":"mcm","clk":"5348792656","pt":1646220737935,"mc":[{"id":"1.195453678","rc":[{"atb":[[1.98,38.85]],"id":40324291}],"con":true,"img":false}]}
{"op":"mcm","clk":"5348792720","pt":1646220738612,"mc":[{"id":"1.195453678","rc":[{"atb":[[1.91,9.32]],"id":38214982}],"con":true,"img":false}]}
{"op":"mcm","clk":"5348792736","pt":1646220738822,"mc":[{"id":"1.195453678","rc":[{"atl":[[2.1,8.25]],"id":40324291}],"con":true,"img":false}]}
{"op":"mcm","clk":"5348792747","pt":1646220738923,"mc":[{"id":"1.195453678","rc":[{"atb":[[1.86,45.77],[1.87,0]],"id":38214982},{"atl":[[2.14,2],[2.16,0]],"id":38214982},{"atl":[[2.08,15.69]],"id":40324291}],"con":true,"img":false}]}
{"op":"mcm","clk":"5348792895","pt":1646220740135,"mc":[{"id":"1.195453678","rc":[{"atl":[[2.08,9.06]],"id":40324291}],"con":true,"img":false}]}
{"op":"mcm","clk":"5348793073","pt":1646220741554,"mc":[{"id":"1.195453678","rc":[{"atb":[[1.72,129],[1.62,0],[1.52,0]],"id":38214982},{"atb":[[1.85,0],[1.75,0],[1.65,0]],"id":40324291}],"con":true,"img":false}]}
{"op":"mcm","clk":"5348793519","pt":1646220745343,"mc":[{"id":"1.195453678","rc":[{"atb":[[1.85,2],[1.86,43.77]],"id":38214982},{"atl":[[2.14,0.02],[2.16,10.55]],"id":40324291}],"con":true,"img":false}]}
{"op":"mcm","clk":"5348793737","pt":1646220747048,"mc":[{"id":"1.195453678","rc":[{"atb":[[1.85,0],[1.86,45.77]],"id":38214982}],"con":true,"img":false}]}
{"op":"mcm","clk":"5348793960","pt":1646220749025,"mc":[{"id":"1.195453678","rc":[{"atb":[[1.32,16.86],[1.42,12.84],[1.52,10.37]],"id":38214982},{"atb":[[2,5.39],[1.8,6.74],[1.9,5.99]],"id":40324291}],"con":true,"img":false}]}
{"op":"mcm","clk":"5348793968","pt":1646220749126,"mc":[{"id":"1.195453678","rc":[{"atb":[[2,14.48]],"id":40324291}],"con":true,"img":false}]}
{"op":"mcm","clk":"5348794002","pt":1646220749544,"mc":[{"id":"1.195453678","rc":[{"atb":[[2,5.39]],"id":40324291}],"con":true,"img":false}]}
{"op":"mcm","clk":"5348794016","pt":1646220749655,"mc":[{"id":"1.195453678","rc":[{"atb":[[1.99,0]],"id":40324291}],"con":true,"img":false}]}
{"op":"mcm","clk":"5348794041","pt":1646220749863,"mc":[{"id":"1.195453678","rc":[{"atb":[[1.99,9.15]],"id":40324291}],"con":true,"img":false}]}
{"op":"mcm","clk":"5348794057","pt":1646220749923,"mc":[{"id":"1.195453678","rc":[{"atb":[[2,14.53]],"id":40324291}],"con":true,"img":false}]}
{"op":"mcm","clk":"5348794201","pt":1646220751136,"mc":[{"id":"1.195453678","rc":[{"atl":[[2.04,9.26]],"id":38214982}],"con":true,"img":false}]}
{"op":"mcm","clk":"5348794290","pt":1646220751756,"mc":[{"id":"1.195453678","rc":[{"atl":[[2.02,16.67]],"id":38214982},{"atb":[[2,20.82]],"id":40324291}],"con":true,"img":false}]}
{"op":"mcm","clk":"5348794319","pt":1646220751925,"mc":[{"id":"1.195453678","rc":[{"atl":[[2,9.23]],"id":38214982}],"con":true,"img":false}]}
{"op":"mcm","clk":"5348794347","pt":1646220752164,"mc":[{"id":"1.195453678","rc":[{"atl":[[2.08,9.23]],"id":38214982}],"con":true,"img":false}]}
{"op":"mcm","clk":"5348794361","pt":1646220752236,"mc":[{"id":"1.195453678","rc":[{"atb":[[1.85,2],[1.86,43.77]],"id":38214982},{"atl":[[2.02,9.22]],"id":38214982}],"con":true,"img":false}]}
{"op":"mcm","clk":"5348794377","pt":1646220752336,"mc":[{"id":"1.195453678","rc":[{"atl":[[2,16.68]],"id":38214982}],"con":true,"img":false}]}
{"op":"mcm","clk":"5348794390","pt":1646220752442,"mc":[{"id":"1.195453678","rc":[{"atb":[[1.89,42.44],[1.9,0]],"id":38214982},{"atb":[[1.91,0]],"id":40324291}],"con":true,"img":false}]}
{"op":"mcm","clk":"5348794491","pt":1646220753239,"mc":[{"id":"1.195453678","rc":[{"atl":[[2,9.23]],"id":38214982},{"atb":[[2,14.53]],"id":40324291}],"con":true,"img":false}]}
{"op":"mcm","clk":"5348794577","pt":1646220753927,"mc":[{"id":"1.195453678","rc":[{"atb":[[2,43.68]],"id":40324291}],"con":true,"img":false}]}
{"op":"mcm","clk":"5348795049","pt":1646220757760,"mc":[{"id":"1.195453678","rc":[{"atb":[[2.02,9],[1.97,0]],"id":40324291}],"con":true,"img":false}]}
{"op":"mcm","clk":"5348795072","pt":1646220757925,"mc":[{"id":"1.195453678","rc":[{"atl":[[2.08,0]],"id":40324291}],"con":true,"img":false}]}
{"op":"mcm","clk":"5348795246","pt":1646220759383,"mc":[{"id":"1.195453678","rc":[{"atb":[[2.02,0]],"id":40324291}],"con":true,"img":false}]}
{"op":"mcm","clk":"5348795293","pt":1646220759756,"mc":[{"id":"1.195453678","rc":[{"atb":[[1.85,0],[1.86,45.77]],"id":38214982}],"con":true,"img":false}]}
{"op":"mcm","clk":"5348795588","pt":1646220762270,"mc":[{"id":"1.195453678","rc":[{"atl":[[2.14,2.02],[2.16,8.55]],"id":40324291}],"con":true,"img":false}]}
{"op":"mcm","clk":"5348795961","pt":1646220765436,"mc":[{"id":"1.195453678","rc":[{"atb":[[2.02,9.02]],"id":40324291}],"con":true,"img":false}]}
{"op":"mcm","clk":"5348796210","pt":1646220767368,"mc":[{"id":"1.195453678","rc":[{"atb":[[1.85,2],[1.86,43.77]],"id":38214982}],"con":true,"img":false}]}
{"op":"mcm","clk":"5348796223","pt":1646220767473,"mc":[{"id":"1.195453678","rc":[{"atl":[[2.14,0.02],[2.16,10.55]],"id":40324291}],"con":true,"img":false}]}
{"op":"mcm","clk":"5348796536","pt":1646220770188,"mc":[{"id":"1.195453678","marketDefinition":{"bspMarket":false,"turnInPlayEnabled":false,"persistenceEnabled":false,"marketBaseRate":7.0,"eventId":"31272494","eventTypeId":"4339","numberOfWinners":1,"bettingType":"ODDS","marketType":"MATCH_BET","marketTime":"2022-03-02T11:32:00.000Z","suspendTime":"2022-03-02T11:32:00.000Z","bspReconciled":false,"complete":true,"inPlay":false,"crossMatching":true,"runnersVoidable":false,"numberOfActiveRunners":2,"betDelay":0,"status":"SUSPENDED","runners":[{"status":"ACTIVE","sortPriority":1,"id":40324291,"name":"4. Reiko Langer"},{"status":"ACTIVE","sortPriority":2,"id":38214982,"name":"7. Two Phones"}],"regulators":["MR_INT"],"venue":"Traralgon","countryCode":"AU","discountAllowed":true,"timezone":"Australia/Sydney","openDate":"2022-03-02T08:31:00.000Z","version":4383013670,"name":"Reiko Langer v Two Phones","eventName":"Traralgon (AUS) 2nd Mar"},"rc":[],"con":true,"img":false}]}
{"op":"mcm","clk":"5348796536","pt":1646220770188,"mc":[{"id":"1.195453678","rc":[{"atb":[[1.72,0],[1.89,0],[1.74,0],[1.88,0],[1.85,0],[1.91,0],[1.86,0],[1.32,0],[1.42,0],[1.77,0],[1.75,0],[1.52,0]],"id":38214982},{"atl":[[2,0],[2.64,0],[2.1,0],[2.14,0],[2.08,0],[2.24,0],[2.02,0],[2.88,0],[2.74,0],[2.52,0],[2.28,0],[2.46,0],[2.68,0],[2.7,0],[2.8,0],[2.82,0],[2.72,0],[2.3,0],[2.32,0],[2.04,0],[2.34,0],[2.48,0],[2.76,0],[2.36,0],[2.4,0],[2.92,0],[2.06,0],[2.86,0],[2.42,0]],"id":38214982},{"atb":[[2,0],[1.46,0],[1.6,0],[1.98,0],[1.58,0],[1.51,0],[1.93,0],[1.87,0],[1.48,0],[1.56,0],[1.8,0],[1.99,0],[2.02,0],[1.57,0],[1.55,0],[1.54,0],[1.9,0],[1.49,0],[1.52,0]],"id":40324291},{"atl":[[2.36,0],[2.3,0],[2.32,0],[2.42,0],[2.38,0],[2.12,0],[2.18,0],[2.26,0],[2.1,0],[2.14,0],[2.16,0]],"id":40324291}],"con":true,"img":false}]}
{"op":"mcm","clk":"5348804617","pt":1646220838250,"mc":[{"id":"1.195453678","rc":[{"trd":[[1.89,0],[1.98,0],[1.97,0],[1.88,0],[1.9,0],[1.91,0],[1.96,0]],"ltp":1.89,"tv":0.0,"id":38214982},{"trd":[[2,0],[2.06,0],[2.12,0],[2.1,0],[2.14,0]],"ltp":2.0,"tv":0.0,"id":40324291}],"con":true,"img":false}]}
{"op":"mcm","clk":"5348804778","pt":1646220839480,"mc":[{"id":"1.195453678","marketDefinition":{"bspMarket":false,"turnInPlayEnabled":false,"persistenceEnabled":false,"marketBaseRate":7.0,"eventId":"31272494","eventTypeId":"4339","numberOfWinners":1,"bettingType":"ODDS","marketType":"MATCH_BET","marketTime":"2022-03-02T11:32:00.000Z","suspendTime":"2022-03-02T11:32:00.000Z","bspReconciled":false,"complete":true,"inPlay":false,"crossMatching":false,"runnersVoidable":false,"numberOfActiveRunners":0,"betDelay":0,"status":"CLOSED","settledTime":"2022-03-02T11:33:56.000Z","runners":[{"status":"LOSER","sortPriority":1,"id":40324291,"name":"4. Reiko Langer"},{"status":"WINNER","sortPriority":2,"id":38214982,"name":"7. Two Phones"}],"regulators":["MR_INT"],"venue":"Traralgon","countryCode":"AU","discountAllowed":true,"timezone":"Australia/Sydney","openDate":"2022-03-02T08:31:00.000Z","version":4383014151,"name":"Reiko Langer v Two Phones","eventName":"Traralgon (AUS) 2nd Mar"},"rc":[],"con":true,"img":false}]}
