{"op":"mcm","clk":"5352134789","pt":1646183310066,"mc":[{"id":"1.195503852","marketDefinition":{"bspMarket":false,"turnInPlayEnabled":false,"persistenceEnabled":false,"marketBaseRate":7.0,"eventId":"31272499","eventTypeId":"4339","numberOfWinners":1,"bettingType":"ODDS","marketType":"MATCH_BET","marketTime":"2022-03-02T09:54:00.000Z","suspendTime":"2022-03-02T09:54:00.000Z","bspReconciled":false,"complete":true,"inPlay":false,"crossMatching":true,"runnersVoidable":false,"numberOfActiveRunners":2,"betDelay":0,"status":"OPEN","runners":[{"status":"ACTIVE","sortPriority":1,"id":26051221,"name":"7. Farmor Crownies"},{"status":"ACTIVE","sortPriority":2,"id":28338255,"name":"8. Until Late"}],"regulators":["MR_INT"],"venue":"Rockhampton","countryCode":"AU","discountAllowed":true,"timezone":"Australia/Queensland","openDate":"2022-03-02T08:34:00.000Z","version":4382585398,"name":"Farmor Crownies v Until Late","eventName":"Rockhampton (AUS) 2nd Mar"},"rc":[],"con":true,"img":false}]}
{"op":"mcm","clk":"5352139712","pt":1646183422125,"mc":[{"id":"1.195503852","rc":[{"atb":[[1.74,7.29],[2.28,4.21],[1.94,5.74]],"id":28338255},{"atb":[[1.4,13.49],[1.2,26.99],[1.01,539.83]],"id":26051221}],"con":true,"img":false}]}
{"op":"mcm","clk":"5352146170","pt":1646183572635,"mc":[{"id":"1.195503852","marketDefinition":{"bspMarket":false,"turnInPlayEnabled":false,"persistenceEnabled":false,"marketBaseRate":7.0,"eventId":"31272499","eventTypeId":"4339","numberOfWinners":1,"bettingType":"ODDS","marketType":"MATCH_BET","marketTime":"2022-03-02T09:54:00.000Z","suspendTime":"2022-03-02T09:54:00.000Z","bspReconciled":false,"complete":true,"inPlay":false,"crossMatching":true,"runnersVoidable":false,"numberOfActiveRunners":2,"betDelay":0,"status":"OPEN","runners":[{"status":"ACTIVE","sortPriority":1,"id":26051221,"name":"7. Farmor Crownies"},{"status":"ACTIVE","sortPriority":2,"id":28338255,"name":"8. Until Late"}],"regulators":["MR_INT"],"venue":"Rockhampton","countryCode":"AU","discountAllowed":true,"timezone":"Australia/Queensland","openDate":"2022-03-02T08:28:00.000Z","version":4382597872,"name":"Farmor Crownies v Until Late","eventName":"Rockhampton (AUS) 2nd Mar"},"rc":[],"con":true,"img":false}]}
{"op":"mcm","clk":"5352156224","pt":1646183846227,"mc":[{"id":"1.195503852","marketDefinition":{"bspMarket":false,"turnInPlayEnabled":false,"persistenceEnabled":false,"marketBaseRate":7.0,"eventId":"31272499","eventTypeId":"4339","numberOfWinners":1,"bettingType":"ODDS","marketType":"MATCH_BET","marketTime":"2022-03-02T09:47:00.000Z","suspendTime":"2022-03-02T09:47:00.000Z","bspReconciled":false,"complete":true,"inPlay":false,"crossMatching":true,"runnersVoidable":false,"numberOfActiveRunners":2,"betDelay":0,"status":"OPEN","runners":[{"status":"ACTIVE","sortPriority":1,"id":26051221,"name":"7. Farmor Crownies"},{"status":"ACTIVE","sortPriority":2,"id":28338255,"name":"8. Until Late"}],"regulators":["MR_INT"],"venue":"Rockhampton","countryCode":"AU","discountAllowed":true,"timezone":"Australia/Queensland","openDate":"2022-03-02T08:28:00.000Z","version":4382601926,"name":"Farmor Crownies v Until Late","eventName":"Rockhampton (AUS) 2nd Mar"},"rc":[],"con":true,"img":false}]}
{"op":"mcm","clk":"5352466698","pt":1646191002690,"mc":[{"id":"1.195503852","marketDefinition":{"bspMarket":false,"turnInPlayEnabled":false,"persistenceEnabled":false,"marketBaseRate":7.0,"eventId":"31272499","eventTypeId":"4339","numberOfWinners":1,"bettingType":"ODDS","marketType":"MATCH_BET","marketTime":"2022-03-02T09:47:00.000Z","suspendTime":"2022-03-02T09:47:00.000Z","bspReconciled":false,"complete":true,"inPlay":false,"crossMatching":true,"runnersVoidable":false,"numberOfActiveRunners":2,"betDelay":0,"status":"OPEN","runners":[{"status":"ACTIVE","sortPriority":1,"id":26051221,"name":"7. Farmor Crownies"},{"status":"ACTIVE","sortPriority":2,"id":28338255,"name":"8. Until Late"}],"regulators":["MR_INT"],"venue":"Rockhampton","countryCode":"AU","discountAllowed":true,"timezone":"Australia/Queensland","openDate":"2022-03-02T08:28:00.000Z","version":4382601926,"name":"Farmor Crownies v Until Late","eventName":"Rockhampton (AUS) 2nd Mar"},"rc":[{"atb":[[1.74,7.3],[2.28,4.22],[1.94,5.75]],"id":28338255},{"atb":[[1.4,13.51],[1.2,27.03],[1.01,540.74]],"id":26051221}],"con":true,"img":true}]}
{"op":"mcm","clk":"5352823506","pt":1646201802741,"mc":[{"id":"1.195503852","marketDefinition":{"bspMarket":false,"turnInPlayEnabled":false,"persistenceEnabled":false,"marketBaseRate":7.0,"eventId":"31272499","eventTypeId":"4339","numberOfWinners":1,"bettingType":"ODDS","marketType":"MATCH_BET","marketTime":"2022-03-02T09:47:00.000Z","suspendTime":"2022-03-02T09:47:00.000Z","bspReconciled":false,"complete":true,"inPlay":false,"crossMatching":true,"runnersVoidable":false,"numberOfActiveRunners":2,"betDelay":0,"status":"OPEN","runners":[{"status":"ACTIVE","sortPriority":1,"id":26051221,"name":"7. Farmor Crownies"},{"status":"ACTIVE","sortPriority":2,"id":28338255,"name":"8. Until Late"}],"regulators":["MR_INT"],"venue":"Rockhampton","countryCode":"AU","discountAllowed":true,"timezone":"Australia/Queensland","openDate":"2022-03-02T08:28:00.000Z","version":4382601926,"name":"Farmor Crownies v Until Late","eventName":"Rockhampton (AUS) 2nd Mar"},"rc":[{"atb":[[1.74,7.3],[2.28,4.22],[1.94,5.74]],"id":28338255},{"atb":[[1.4,13.51],[1.2,27.02],[1.01,540.54]],"id":26051221}],"con":true,"img":true}]}
{"op":"mcm","clk":"5353028876","pt":1646207202758,"mc":[{"id":"1.195503852","marketDefinition":{"bspMarket":false,"turnInPlayEnabled":false,"persistenceEnabled":false,"marketBaseRate":7.0,"eventId":"31272499","eventTypeId":"4339","numberOfWinners":1,"bettingType":"ODDS","marketType":"MATCH_BET","marketTime":"2022-03-02T09:47:00.000Z","suspendTime":"2022-03-02T09:47:00.000Z","bspReconciled":false,"complete":true,"inPlay":false,"crossMatching":true,"runnersVoidable":false,"numberOfActiveRunners":2,"betDelay":0,"status":"OPEN","runners":[{"status":"ACTIVE","sortPriority":1,"id":26051221,"name":"7. Farmor Crownies"},{"status":"ACTIVE","sortPriority":2,"id":28338255,"name":"8. Until Late"}],"regulators":["MR_INT"],"venue":"Rockhampton","countryCode":"AU","discountAllowed":true,"timezone":"Australia/Queensland","openDate":"2022-03-02T08:28:00.000Z","version":4382601926,"name":"Farmor Crownies v Until Late","eventName":"Rockhampton (AUS) 2nd Mar"},"rc":[{"atb":[[1.74,7.3],[2.28,4.21],[1.94,5.74]],"id":28338255},{"atb":[[1.4,13.5],[1.2,27.01],[1.01,540.39]],"id":26051221}],"con":true,"img":true}]}
{"op":"mcm","clk":"5353300262","pt":1646212602761,"mc":[{"id":"1.195503852","marketDefinition":{"bspMarket":false,"turnInPlayEnabled":false,"persistenceEnabled":false,"marketBaseRate":7.0,"eventId":"31272499","eventTypeId":"4339","numberOfWinners":1,"bettingType":"ODDS","marketType":"MATCH_BET","marketTime":"2022-03-02T09:47:00.000Z","suspendTime":"2022-03-02T09:47:00.000Z","bspReconciled":false,"complete":true,"inPlay":false,"crossMatching":true,"runnersVoidable":false,"numberOfActiveRunners":2,"betDelay":0,"status":"OPEN","runners":[{"status":"ACTIVE","sortPriority":1,"id":26051221,"name":"7. Farmor Crownies"},{"status":"ACTIVE","sortPriority":2,"id":28338255,"name":"8. Until Late"}],"regulators":["MR_INT"],"venue":"Rockhampton","countryCode":"AU","discountAllowed":true,"timezone":"Australia/Queensland","openDate":"2022-03-02T08:28:00.000Z","version":4382601926,"name":"Farmor Crownies v Until Late","eventName":"Rockhampton (AUS) 2nd Mar"},"rc":[{"atb":[[1.74,7.29],[2.28,4.21],[1.94,5.73]],"id":28338255},{"atb":[[1.4,13.48],[1.2,26.97],[1.01,539.53]],"id":26051221}],"con":true,"img":true}]}
{"op":"mcm","clk":"5353337184","pt":1646213224468,"mc":[{"id":"1.195503852","rc":[{"atb":[[1.74,7.29],[2.28,4.21],[1.94,5.73]],"id":28338255},{"atb":[[1.4,13.48],[1.2,26.97],[1.41,2],[1.01,539.53]],"id":26051221},{"atl":[[1.86,2]],"id":26051221}],"con":true,"img":false}]}
{"op":"mcm","clk":"5353337189","pt":1646213224574,"mc":[{"id":"1.195503852","rc":[{"atb":[[2.3,2]],"id":28338255},{"atl":[[4.5,2]],"id":28338255}],"con":true,"img":false}]}
{"op":"mcm","clk":"5353337459","pt":1646213229668,"mc":[{"id":"1.195503852","rc":[{"atl":[[4.5,0],[4.2,2]],"id":28338255}],"con":true,"img":false}]}
{"op":"mcm","clk":"5353340476","pt":1646213284654,"mc":[{"id":"1.195503852","rc":[{"atb":[[2.3,0]],"id":28338255},{"atl":[[4.2,0]],"id":28338255},{"atb":[[1.41,0]],"id":26051221},{"atl":[[1.86,0]],"id":26051221}],"con":true,"img":false}]}
{"op":"mcm","clk":"5353343772","pt":1646213354856,"mc":[{"id":"1.195503852","rc":[{"atb":[[1.41,2]],"id":26051221},{"atl":[[1.88,2]],"id":26051221},{"atb":[[2.3,2]],"id":28338255},{"atl":[[4.5,2]],"id":28338255}],"con":true,"img":false}]}
{"op":"mcm","clk":"5353344033","pt":1646213360068,"mc":[{"id":"1.195503852","rc":[{"atl":[[4.4,2]],"id":28338255}],"con":true,"img":false}]}
{"op":"mcm","clk":"5353344038","pt":1646213360171,"mc":[{"id":"1.195503852","rc":[{"atl":[[4.5,0]],"id":28338255}],"con":true,"img":false}]}
{"op":"mcm","clk":"5353346086","pt":1646213402305,"mc":[{"id":"1.195503852","rc":[{"atl":[[1.88,0],[1.87,2]],"id":26051221}],"con":true,"img":false}]}
{"op":"mcm","clk":"5353346486","pt":1646213407718,"mc":[{"id":"1.195503852","rc":[{"atl":[[1.88,2],[1.87,0]],"id":26051221}],"con":true,"img":false}]}
{"op":"mcm","clk":"5353346919","pt":1646213416047,"mc":[{"id":"1.195503852","rc":[{"atl":[[1.88,0],[1.87,2]],"id":26051221}],"con":true,"img":false}]}
{"op":"mcm","clk":"5353352315","pt":1646213523163,"mc":[{"id":"1.195503852","rc":[{"atl":[[4.4,0],[4.2,2]],"id":28338255}],"con":true,"img":false}]}
{"op":"mcm","clk":"5353352373","pt":1646213524041,"mc":[{"id":"1.195503852","rc":[{"atl":[[4.1,2],[4.2,0]],"id":28338255}],"con":true,"img":false}]}
{"op":"mcm","clk":"5353355339","pt":1646213577456,"mc":[{"id":"1.195503852","rc":[{"atb":[[1.74,0],[2.28,0],[1.94,0]],"id":28338255},{"atb":[[1.4,0],[1.2,0],[1.01,0]],"id":26051221}],"con":true,"img":false}]}
{"op":"mcm","clk":"5353355350","pt":1646213577604,"mc":[{"id":"1.195503852","rc":[{"atl":[[1.84,2],[1.87,0]],"id":26051221}],"con":true,"img":false}]}
{"op":"mcm","clk":"5353355534","pt":1646213581040,"mc":[{"id":"1.195503852","rc":[{"atb":[[1.4,13.48],[1.2,26.97],[1.01,539.53]],"id":26051221},{"atb":[[1.74,7.29],[2.28,4.21],[1.94,5.73]],"id":28338255}],"con":true,"img":false}]}
{"op":"mcm","clk":"5353360993","pt":1646213683711,"mc":[{"id":"1.195503852","rc":[{"atl":[[1.84,0],[1.77,2]],"id":26051221},{"atb":[[2.3,0],[2.38,2]],"id":28338255}],"con":true,"img":false}]}
{"op":"mcm","clk":"5353361386","pt":1646213688836,"mc":[{"id":"1.195503852","rc":[{"atl":[[1.77,0],[1.75,2]],"id":26051221},{"atb":[[2.42,2],[2.38,0]],"id":28338255}],"con":true,"img":false}]}
{"op":"mcm","clk":"5353361758","pt":1646213694024,"mc":[{"id":"1.195503852","rc":[{"atl":[[1.74,2],[1.75,0]],"id":26051221},{"atb":[[2.42,0],[2.44,2]],"id":28338255}],"con":true,"img":false}]}
{"op":"mcm","clk":"5353362220","pt":1646213701043,"mc":[{"id":"1.195503852","rc":[{"atb":[[2.46,2],[2.44,0]],"id":28338255},{"atl":[[1.72,2],[1.74,0]],"id":26051221}],"con":true,"img":false}]}
{"op":"mcm","clk":"5353362572","pt":1646213706162,"mc":[{"id":"1.195503852","rc":[{"atb":[[2.3,2]],"id":28338255}],"con":true,"img":false}]}
{"op":"mcm","clk":"5353362580","pt":1646213706265,"mc":[{"id":"1.195503852","rc":[{"atb":[[2.46,0]],"id":28338255}],"con":true,"img":false}]}
{"op":"mcm","clk":"5353362669","pt":1646213707465,"mc":[{"id":"1.195503852","rc":[{"atl":[[1.73,2],[1.72,0]],"id":26051221}],"con":true,"img":false}]}
{"op":"mcm","clk":"5353363656","pt":1646213724796,"mc":[{"id":"1.195503852","rc":[{"atb":[[2.3,0],[2.32,2]],"id":28338255}],"con":true,"img":false}]}
{"op":"mcm","clk":"5353363948","pt":1646213729875,"mc":[{"id":"1.195503852","rc":[{"atb":[[2.3,2]],"id":28338255}],"con":true,"img":false}]}
{"op":"mcm","clk":"5353363954","pt":1646213729973,"mc":[{"id":"1.195503852","rc":[{"atb":[[2.32,0]],"id":28338255}],"con":true,"img":false}]}
{"op":"mcm","clk":"5353364764","pt":1646213743082,"mc":[{"id":"1.195503852","rc":[{"atl":[[4.1,0],[3.7,2]],"id":28338255}],"con":true,"img":false}]}
{"op":"mcm","clk":"5353368224","pt":1646213801583,"mc":[{"id":"1.195503852","rc":[{"atl":[[1.73,0],[1.74,2]],"id":26051221}],"con":true,"img":false}]}
{"op":"mcm","clk":"5353369162","pt":1646213817522,"mc":[{"id":"1.195503852","rc":[{"atb":[[1.4,0],[1.2,0],[1.01,0]],"id":26051221},{"atb":[[1.74,0],[2.28,0],[1.94,0]],"id":28338255}],"con":true,"img":false}]}
{"op":"mcm","clk":"5353369184","pt":1646213817885,"mc":[{"id":"1.195503852","rc":[{"atb":[[2.3,0],[2.32,2]],"id":28338255}],"con":true,"img":false}]}
{"op":"mcm","clk":"5353369376","pt":1646213821035,"mc":[{"id":"1.195503852","rc":[{"atb":[[1.74,7.29],[2.28,4.21],[1.94,5.73]],"id":28338255},{"atb":[[1.4,13.48],[1.2,26.97],[1.01,539.53]],"id":26051221}],"con":true,"img":false}]}
{"op":"mcm","clk":"5353369518","pt":1646213823029,"mc":[{"id":"1.195503852","rc":[{"atb":[[2.3,2]],"id":28338255}],"con":true,"img":false}]}
{"op":"mcm","clk":"5353369527","pt":1646213823103,"mc":[{"id":"1.195503852","rc":[{"atb":[[2.32,0]],"id":28338255}],"con":true,"img":false}]}
{"op":"mcm","clk":"5353371152","pt":1646213850128,"mc":[{"id":"1.195503852","rc":[{"atb":[[2.3,0],[2.42,2]],"id":28338255}],"con":true,"img":false}]}
{"op":"mcm","clk":"5353371468","pt":1646213855274,"mc":[{"id":"1.195503852","rc":[{"atb":[[2.4,2]],"id":28338255}],"con":true,"img":false}]}
{"op":"mcm","clk":"5353371477","pt":1646213855378,"mc":[{"id":"1.195503852","rc":[{"atb":[[2.42,0]],"id":28338255}],"con":true,"img":false}]}
{"op":"mcm","clk":"5353371605","pt":1646213857647,"mc":[{"id":"1.195503852","rc":[{"atb":[[2.4,0],[2.38,2]],"id":28338255},{"atl":[[1.74,0],[1.75,2]],"id":26051221}],"con":true,"img":false}]}
{"op":"mcm","clk":"5353371936","pt":1646213862747,"mc":[{"id":"1.195503852","rc":[{"atb":[[2.3,2]],"id":28338255}],"con":true,"img":false}]}
{"op":"mcm","clk":"5353371944","pt":1646213862858,"mc":[{"id":"1.195503852","rc":[{"atb":[[2.38,0]],"id":28338255}],"con":true,"img":false}]}
{"op":"mcm","clk":"5353373872","pt":1646213893908,"mc":[{"id":"1.195503852","rc":[{"atl":[[1.75,0],[1.76,2]],"id":26051221}],"con":true,"img":false}]}
{"op":"mcm","clk":"5353378918","pt":1646213974547,"mc":[{"id":"1.195503852","rc":[{"atl":[[3.7,0],[3.65,2]],"id":28338255}],"con":true,"img":false}]}
{"op":"mcm","clk":"5353380259","pt":1646213993961,"mc":[{"id":"1.195503852","rc":[{"atb":[[2.3,0],[2.38,2]],"id":28338255}],"con":true,"img":false}]}
{"op":"mcm","clk":"5353380488","pt":1646213997482,"mc":[{"id":"1.195503852","rc":[{"atb":[[2.38,0],[2.34,2]],"id":28338255}],"con":true,"img":false}]}
{"op":"mcm","clk":"5353380834","pt":1646214002585,"mc":[{"id":"1.195503852","rc":[{"atb":[[2.38,2],[2.34,0]],"id":28338255}],"con":true,"img":false}]}
{"op":"mcm","clk":"5353380869","pt":1646214003094,"mc":[{"id":"1.195503852","rc":[{"atl":[[14,1.42]],"id":28338255},{"atl":[[14.5,1.42]],"id":26051221}],"con":true,"img":false}]}
{"op":"mcm","clk":"5353380877","pt":1646214003199,"mc":[{"id":"1.195503852","rc":[{"atl":[[4.9,2],[3.65,0]],"id":28338255},{"atl":[[1.77,2]],"id":26051221}],"con":true,"img":false}]}
{"op":"mcm","clk":"5353380887","pt":1646214003302,"mc":[{"id":"1.195503852","rc":[{"atl":[[1.76,0]],"id":26051221}],"con":true,"img":false}]}
{"op":"mcm","clk":"5353381022","pt":1646214005380,"mc":[{"id":"1.195503852","rc":[{"atl":[[15,1.42]],"id":26051221},{"atl":[[14.5,1.42]],"id":28338255}],"con":true,"img":false}]}
{"op":"mcm","clk":"5353381121","pt":1646214006785,"mc":[{"id":"1.195503852","rc":[{"atl":[[15,2.84]],"id":26051221},{"atl":[[14.5,2.84]],"id":28338255}],"con":true,"img":false}]}
{"op":"mcm","clk":"5353381210","pt":1646214008221,"mc":[{"id":"1.195503852","rc":[{"atl":[[15.5,1.42]],"id":26051221},{"atl":[[15,1.42]],"id":28338255}],"con":true,"img":false}]}
{"op":"mcm","clk":"5353381218","pt":1646214008324,"mc":[{"id":"1.195503852","rc":[{"atl":[[1.78,2],[1.77,0]],"id":26051221},{"atl":[[4.8,2],[4.9,0]],"id":28338255}],"con":true,"img":false}]}
{"op":"mcm","clk":"5353381339","pt":1646214009830,"mc":[{"id":"1.195503852","rc":[{"atl":[[15,2.84]],"id":28338255},{"atl":[[16,1.42]],"id":26051221}],"con":true,"img":false}]}
{"op":"mcm","clk":"5353381511","pt":1646214012328,"mc":[{"id":"1.195503852","rc":[{"atb":[[2.36,2],[2.38,0]],"id":28338255}],"con":true,"img":false}]}
{"op":"mcm","clk":"5353381547","pt":1646214012904,"mc":[{"id":"1.195503852","rc":[{"atb":[[2.36,0],[2.38,2]],"id":28338255},{"atl":[[15.5,1.42]],"id":28338255},{"atl":[[16.5,1.42]],"id":26051221}],"con":true,"img":false}]}
{"op":"mcm","clk":"5353381615","pt":1646214013931,"mc":[{"id":"1.195503852","rc":[{"atl":[[17,1.42]],"id":26051221},{"atl":[[16,1.42]],"id":28338255}],"con":true,"img":false}]}
{"op":"mcm","clk":"5353381716","pt":1646214015702,"mc":[{"id":"1.195503852","rc":[{"atl":[[16,2.84]],"id":28338255},{"atl":[[17,2.84]],"id":26051221}],"con":true,"img":false}]}
{"op":"mcm","clk":"5353381801","pt":1646214017203,"mc":[{"id":"1.195503852","rc":[{"atl":[[16.5,1.42]],"id":28338255},{"atl":[[17.5,1.42]],"id":26051221}],"con":true,"img":false}]}
{"op":"mcm","clk":"5353381817","pt":1646214017542,"mc":[{"id":"1.195503852","rc":[{"atl":[[1.78,0],[1.77,2]],"id":26051221}],"con":true,"img":false}]}
{"op":"mcm","clk":"5353381825","pt":1646214017610,"mc":[{"id":"1.195503852","rc":[{"atl":[[4.8,0],[4.7,2]],"id":28338255}],"con":true,"img":false}]}
{"op":"mcm","clk":"5353381841","pt":1646214017814,"mc":[{"id":"1.195503852","rc":[{"atl":[[14.5,0]],"id":26051221}],"con":true,"img":false}]}
{"op":"mcm","clk":"5353381859","pt":1646214018125,"mc":[{"id":"1.195503852","rc":[{"atb":[[2.4,2],[2.38,0]],"id":28338255}],"con":true,"img":false}]}
{"op":"mcm","clk":"5353381897","pt":1646214018707,"mc":[{"id":"1.195503852","rc":[{"atl":[[17,1.42]],"id":28338255},{"atl":[[18,1.42]],"id":26051221}],"con":true,"img":false}]}
{"op":"mcm","clk":"5353381929","pt":1646214019216,"mc":[{"id":"1.195503852","rc":[{"atb":[[2.4,0],[2.38,2]],"id":28338255}],"con":true,"img":false}]}
{"op":"mcm","clk":"5353381944","pt":1646214019421,"mc":[{"id":"1.195503852","rc":[{"atb":[[2.36,2],[2.38,0]],"id":28338255}],"con":true,"img":false}]}
{"op":"mcm","clk":"5353381990","pt":1646214020143,"mc":[{"id":"1.195503852","rc":[{"atl":[[17.5,1.42]],"id":28338255},{"atl":[[18.5,1.42]],"id":26051221}],"con":true,"img":false}]}
{"op":"mcm","clk":"5353382085","pt":1646214021438,"mc":[{"id":"1.195503852","rc":[{"atl":[[19,1.42]],"id":26051221},{"atl":[[18,1.42]],"id":28338255}],"con":true,"img":false}]}
{"op":"mcm","clk":"5353382167","pt":1646214022630,"mc":[{"id":"1.195503852","rc":[{"atl":[[1.78,2],[1.77,0]],"id":26051221}],"con":true,"img":false}]}
{"op":"mcm","clk":"5353382175","pt":1646214022731,"mc":[{"id":"1.195503852","rc":[{"atl":[[14.5,1.42]],"id":26051221},{"atl":[[18.5,1.42],[4.9,2]],"id":28338255}],"con":true,"img":false}]}
{"op":"mcm","clk":"5353382182","pt":1646214022838,"mc":[{"id":"1.195503852","rc":[{"atl":[[4.7,0]],"id":28338255}],"con":true,"img":false}]}
{"op":"mcm","clk":"5353382279","pt":1646214024747,"mc":[{"id":"1.195503852","rc":[{"atl":[[1.79,2],[1.78,0]],"id":26051221}],"con":true,"img":false}]}
{"op":"mcm","clk":"5353382444","pt":1646214027435,"mc":[{"id":"1.195503852","rc":[{"atl":[[1.79,0],[1.78,2]],"id":26051221}],"con":true,"img":false}]}
{"op":"mcm","clk":"5353382472","pt":1646214027849,"mc":[{"id":"1.195503852","rc":[{"atl":[[4.8,2],[4.9,0]],"id":28338255}],"con":true,"img":false}]}
{"op":"mcm","clk":"5353382501","pt":1646214028327,"mc":[{"id":"1.195503852","rc":[{"atl":[[4.8,0],[4.9,2]],"id":28338255}],"con":true,"img":false}]}
{"op":"mcm","clk":"5353382600","pt":1646214030026,"mc":[{"id":"1.195503852","rc":[{"atl":[[14,1.42]],"id":26051221}],"con":true,"img":false}]}
{"op":"mcm","clk":"5353382608","pt":1646214030230,"mc":[{"id":"1.195503852","rc":[{"atb":[[2.36,0],[2.38,2]],"id":28338255}],"con":true,"img":false}]}
{"op":"mcm","clk":"5353382675","pt":1646214031261,"mc":[{"id":"1.195503852","rc":[{"atl":[[14,2.84]],"id":26051221}],"con":true,"img":false}]}
{"op":"mcm","clk":"5353382821","pt":1646214033429,"mc":[{"id":"1.195503852","rc":[{"atl":[[5.1,2],[4.9,0]],"id":28338255}],"con":true,"img":false}]}
{"op":"mcm","clk":"5353382848","pt":1646214033835,"mc":[{"id":"1.195503852","rc":[{"atl":[[5.1,0],[5.2,2]],"id":28338255}],"con":true,"img":false}]}
{"op":"mcm","clk":"5353382871","pt":1646214034349,"mc":[{"id":"1.195503852","rc":[{"atb":[[2.36,2],[2.38,0]],"id":28338255},{"atl":[[1.78,0],[1.79,2]],"id":26051221}],"con":true,"img":false}]}
{"op":"mcm","clk":"5353383139","pt":1646214039422,"mc":[{"id":"1.195503852","rc":[{"atb":[[2.36,0],[2.38,2]],"id":28338255},{"atl":[[1.79,0],[1.77,2]],"id":26051221}],"con":true,"img":false}]}
{"op":"mcm","clk":"5353383171","pt":1646214040249,"mc":[{"id":"1.195503852","rc":[{"atl":[[1.78,2]],"id":26051221}],"con":true,"img":false}]}
{"op":"mcm","clk":"5353383176","pt":1646214040352,"mc":[{"id":"1.195503852","rc":[{"atl":[[1.77,0]],"id":26051221}],"con":true,"img":false}]}
{"op":"mcm","clk":"5353383327","pt":1646214043148,"mc":[{"id":"1.195503852","rc":[{"atb":[[2.4,2],[2.38,0]],"id":28338255}],"con":true,"img":false}]}
{"op":"mcm","clk":"5353383370","pt":1646214043767,"mc":[{"id":"1.195503852","rc":[{"atl":[[14,0]],"id":26051221}],"con":true,"img":false}]}
{"op":"mcm","clk":"5353383485","pt":1646214045368,"mc":[{"id":"1.195503852","rc":[{"atl":[[1.78,0],[1.77,2]],"id":26051221}],"con":true,"img":false}]}
{"op":"mcm","clk":"5353383660","pt":1646214048157,"mc":[{"id":"1.195503852","rc":[{"atl":[[5.2,0],[5.4,2]],"id":28338255}],"con":true,"img":false}]}
{"op":"mcm","clk":"5353383665","pt":1646214048297,"mc":[{"id":"1.195503852","rc":[{"atb":[[2.4,0],[2.38,2]],"id":28338255}],"con":true,"img":false}]}
{"op":"mcm","clk":"5353383707","pt":1646214048983,"mc":[{"id":"1.195503852","rc":[{"atl":[[5.2,2],[5.4,0]],"id":28338255}],"con":true,"img":false}]}
{"op":"mcm","clk":"5353383775","pt":1646214050270,"mc":[{"id":"1.195503852","rc":[{"atb":[[2.4,2],[2.38,0]],"id":28338255}],"con":true,"img":false}]}
{"op":"mcm","clk":"5353383920","pt":1646214052179,"mc":[{"id":"1.195503852","rc":[{"atl":[[1.78,2],[1.77,0]],"id":26051221}],"con":true,"img":false}]}
{"op":"mcm","clk":"5353384014","pt":1646214053574,"mc":[{"id":"1.195503852","rc":[{"atl":[[14,0]],"id":28338255}],"con":true,"img":false}]}
{"op":"mcm","clk":"5353384058","pt":1646214054257,"mc":[{"id":"1.195503852","rc":[{"atl":[[19,1.42]],"id":28338255}],"con":true,"img":false}]}
{"op":"mcm","clk":"5353384141","pt":1646214055386,"mc":[{"id":"1.195503852","rc":[{"atb":[[2.4,0],[2.38,2]],"id":28338255}],"con":true,"img":false}]}
{"op":"mcm","clk":"5353384277","pt":1646214057368,"mc":[{"id":"1.195503852","rc":[{"atl":[[1.78,0],[1.77,2]],"id":26051221}],"con":true,"img":false}]}
{"op":"mcm","clk":"5353384323","pt":1646214058088,"mc":[{"id":"1.195503852","rc":[{"atl":[[5.3,2],[5.2,0]],"id":28338255}],"con":true,"img":false}]}
{"op":"mcm","clk":"5353384504","pt":1646214060584,"mc":[{"id":"1.195503852","rc":[{"atb":[[2.4,2],[2.38,0]],"id":28338255}],"con":true,"img":false}]}
{"op":"mcm","clk":"5353384835","pt":1646214064875,"mc":[{"id":"1.195503852","rc":[{"atl":[[5.3,0],[5.2,2]],"id":28338255}],"con":true,"img":false}]}
{"op":"mcm","clk":"5353384889","pt":1646214065708,"mc":[{"id":"1.195503852","rc":[{"atb":[[2.4,0],[2.38,2]],"id":28338255}],"con":true,"img":false}]}
{"op":"mcm","clk":"5353384908","pt":1646214065969,"mc":[{"id":"1.195503852","rc":[{"atl":[[1.77,0],[1.76,2]],"id":26051221}],"con":true,"img":false}]}
{"op":"mcm","clk":"5353385235","pt":1646214070017,"mc":[{"id":"1.195503852","rc":[{"atl":[[5.3,2],[5.2,0]],"id":28338255}],"con":true,"img":false}]}
{"op":"mcm","clk":"5353385293","pt":1646214070899,"mc":[{"id":"1.195503852","rc":[{"atb":[[2.4,2],[2.38,0]],"id":28338255}],"con":true,"img":false}]}
{"op":"mcm","clk":"5353385343","pt":1646214071517,"mc":[{"id":"1.195503852","rc":[{"atl":[[14,1.42]],"id":28338255}],"con":true,"img":false}]}
{"op":"mcm","clk":"5353385360","pt":1646214071676,"mc":[{"id":"1.195503852","rc":[{"atl":[[1.77,2],[1.76,0]],"id":26051221}],"con":true,"img":false}]}
{"op":"mcm","clk":"5353385367","pt":1646214071828,"mc":[{"id":"1.195503852","rc":[{"atb":[[2.4,0],[2.38,2]],"id":28338255}],"con":true,"img":false}]}
{"op":"mcm","clk":"5353385473","pt":1646214073433,"mc":[{"id":"1.195503852","rc":[{"atl":[[14,0]],"id":28338255}],"con":true,"img":false}]}
{"op":"mcm","clk":"5353385634","pt":1646214075713,"mc":[{"id":"1.195503852","rc":[{"atl":[[5.3,0],[5.2,2]],"id":28338255}],"con":true,"img":false}]}
{"op":"mcm","clk":"5353385772","pt":1646214077421,"mc":[{"id":"1.195503852","rc":[{"atl":[[14,1.42]],"id":28338255}],"con":true,"img":false}]}
{"op":"mcm","clk":"5353385789","pt":1646214077629,"mc":[{"id":"1.195503852","rc":[{"atl":[[1.78,2],[1.77,0]],"id":26051221}],"con":true,"img":false}]}
{"op":"mcm","clk":"5353385869","pt":1646214078612,"mc":[{"id":"1.195503852","rc":[{"atl":[[1.78,0],[1.77,2]],"id":26051221}],"con":true,"img":false}]}
{"op":"mcm","clk":"5353386236","pt":1646214082906,"mc":[{"id":"1.195503852","rc":[{"atl":[[5,2],[5.2,0]],"id":28338255}],"con":true,"img":false}]}
{"op":"mcm","clk":"5353386297","pt":1646214084002,"mc":[{"id":"1.195503852","rc":[{"atb":[[2.4,2],[2.38,0]],"id":28338255}],"con":true,"img":false}]}
{"op":"mcm","clk":"5353386475","pt":1646214086833,"mc":[{"id":"1.195503852","rc":[{"atl":[[1.78,2],[1.77,0]],"id":26051221}],"con":true,"img":false}]}
{"op":"mcm","clk":"5353386570","pt":1646214088135,"mc":[{"id":"1.195503852","rc":[{"atl":[[4.9,2],[5,0]],"id":28338255}],"con":true,"img":false}]}
{"op":"mcm","clk":"5353386612","pt":1646214088712,"mc":[{"id":"1.195503852","rc":[{"atl":[[14,0]],"id":28338255}],"con":true,"img":false}]}
{"op":"mcm","clk":"5353386619","pt":1646214088813,"mc":[{"id":"1.195503852","rc":[{"atl":[[4.8,2],[4.9,0]],"id":28338255}],"con":true,"img":false}]}
{"op":"mcm","clk":"5353386657","pt":1646214089228,"mc":[{"id":"1.195503852","rc":[{"atb":[[2.4,0],[2.38,2]],"id":28338255}],"con":true,"img":false}]}
{"op":"mcm","clk":"5353386854","pt":1646214091420,"mc":[{"id":"1.195503852","rc":[{"atb":[[2.4,2],[2.38,0]],"id":28338255}],"con":true,"img":false}]}
{"op":"mcm","clk":"5353386904","pt":1646214092036,"mc":[{"id":"1.195503852","rc":[{"atl":[[1.78,0],[1.77,2]],"id":26051221}],"con":true,"img":false}]}
{"op":"mcm","clk":"5353386908","pt":1646214092140,"mc":[{"id":"1.195503852","rc":[{"atb":[[2.4,0],[2.38,2]],"id":28338255}],"con":true,"img":false}]}
{"op":"mcm","clk":"5353387047","pt":1646214093956,"mc":[{"id":"1.195503852","rc":[{"atl":[[4.7,2]],"id":28338255}],"con":true,"img":false}]}
{"op":"mcm","clk":"5353387057","pt":1646214094013,"mc":[{"id":"1.195503852","rc":[{"atl":[[4.8,0]],"id":28338255}],"con":true,"img":false}]}
{"op":"mcm","clk":"5353387268","pt":1646214097226,"mc":[{"id":"1.195503852","rc":[{"atl":[[1.78,2],[1.77,0]],"id":26051221}],"con":true,"img":false}]}
{"op":"mcm","clk":"5353387271","pt":1646214097334,"mc":[{"id":"1.195503852","rc":[{"atb":[[2.36,2],[2.38,0]],"id":28338255}],"con":true,"img":false}]}
{"op":"mcm","clk":"5353387475","pt":1646214100241,"mc":[{"id":"1.195503852","rc":[{"atl":[[4.4,2],[4.7,0]],"id":28338255}],"con":true,"img":false}]}
{"op":"mcm","clk":"5353387568","pt":1646214101538,"mc":[{"id":"1.195503852","rc":[{"atl":[[14,1.42]],"id":28338255}],"con":true,"img":false}]}
{"op":"mcm","clk":"5353387705","pt":1646214103452,"mc":[{"id":"1.195503852","rc":[{"atl":[[1.79,2],[1.78,0]],"id":26051221}],"con":true,"img":false}]}
{"op":"mcm","clk":"5353387837","pt":1646214105359,"mc":[{"id":"1.195503852","rc":[{"atl":[[4.6,2]],"id":28338255}],"con":true,"img":false}]}
{"op":"mcm","clk":"5353387844","pt":1646214105464,"mc":[{"id":"1.195503852","rc":[{"atl":[[4.4,0]],"id":28338255}],"con":true,"img":false}]}
{"op":"mcm","clk":"5353387885","pt":1646214106142,"mc":[{"id":"1.195503852","rc":[{"atb":[[2.36,0],[2.38,2]],"id":28338255}],"con":true,"img":false}]}
{"op":"mcm","clk":"5353388020","pt":1646214108363,"mc":[{"id":"1.195503852","rc":[{"atl":[[14,1.42]],"id":26051221}],"con":true,"img":false}]}
{"op":"mcm","clk":"5353388031","pt":1646214108569,"mc":[{"id":"1.195503852","rc":[{"atl":[[1.78,2]],"id":26051221}],"con":true,"img":false}]}
{"op":"mcm","clk":"5353388036","pt":1646214108678,"mc":[{"id":"1.195503852","rc":[{"atl":[[1.79,0]],"id":26051221}],"con":true,"img":false}]}
{"op":"mcm","clk":"5353388102","pt":1646214109759,"mc":[{"id":"1.195503852","rc":[{"atl":[[14,2.84]],"id":26051221}],"con":true,"img":false}]}
{"op":"mcm","clk":"5353388140","pt":1646214110479,"mc":[{"id":"1.195503852","rc":[{"atl":[[4.6,0],[4.7,2]],"id":28338255}],"con":true,"img":false}]}
{"op":"mcm","clk":"5353388305","pt":1646214113268,"mc":[{"id":"1.195503852","rc":[{"atl":[[14,0]],"id":26051221}],"con":true,"img":false}]}
{"op":"mcm","clk":"5353388419","pt":1646214114979,"mc":[{"id":"1.195503852","rc":[{"atb":[[1.4,0],[1.2,0],[1.01,0]],"id":26051221},{"atb":[[1.74,0],[2.28,0],[1.94,0]],"id":28338255}],"con":true,"img":false}]}
{"op":"mcm","clk":"5353388460","pt":1646214115551,"mc":[{"id":"1.195503852","rc":[{"atl":[[4.8,2],[4.7,0]],"id":28338255}],"con":true,"img":false}]}
{"op":"mcm","clk":"5353388579","pt":1646214117263,"mc":[{"id":"1.195503852","rc":[{"atl":[[14.5,0]],"id":26051221}],"con":true,"img":false}]}
{"op":"mcm","clk":"5353388660","pt":1646214118497,"mc":[{"id":"1.195503852","rc":[{"atl":[[19.5,1.42]],"id":26051221},{"atl":[[13.5,1.42]],"id":28338255}],"con":true,"img":false}]}
{"op":"mcm","clk":"5353388741","pt":1646214119788,"mc":[{"id":"1.195503852","rc":[{"atl":[[13,1.42]],"id":28338255},{"atl":[[19.5,2.84]],"id":26051221}],"con":true,"img":false}]}
{"op":"mcm","clk":"5353388864","pt":1646214121400,"mc":[{"id":"1.195503852","rc":[{"atl":[[11.5,1.42]],"id":28338255}],"con":true,"img":false}]}
{"op":"mcm","clk":"5353388900","pt":1646214121869,"mc":[{"id":"1.195503852","rc":[{"atl":[[4.8,0],[4.6,2]],"id":28338255}],"con":true,"img":false}]}
{"op":"mcm","clk":"5353388909","pt":1646214122078,"mc":[{"id":"1.195503852","rc":[{"atl":[[1.81,2],[1.78,0]],"id":26051221}],"con":true,"img":false}]}
{"op":"mcm","clk":"5353388944","pt":1646214122593,"mc":[{"id":"1.195503852","rc":[{"atl":[[12,1.42]],"id":28338255}],"con":true,"img":false}]}
{"op":"mcm","clk":"5353389035","pt":1646214123990,"mc":[{"id":"1.195503852","rc":[{"atl":[[11,1.42]],"id":28338255}],"con":true,"img":false}]}
{"op":"mcm","clk":"5353389155","pt":1646214125902,"mc":[{"id":"1.195503852","rc":[{"atl":[[10.5,1.42]],"id":28338255}],"con":true,"img":false}]}
{"op":"mcm","clk":"5353389226","pt":1646214126989,"mc":[{"id":"1.195503852","rc":[{"atl":[[4.3,2],[4.6,0]],"id":28338255}],"con":true,"img":false}]}
{"op":"mcm","clk":"5353389237","pt":1646214127194,"mc":[{"id":"1.195503852","rc":[{"atl":[[1.81,0],[1.86,2]],"id":26051221}],"con":true,"img":false}]}
{"op":"mcm","clk":"5353389242","pt":1646214127301,"mc":[{"id":"1.195503852","rc":[{"atl":[[4.3,0],[12.5,1.42],[4.2,2]],"id":28338255}],"con":true,"img":false}]}
{"op":"mcm","clk":"5353389319","pt":1646214128698,"mc":[{"id":"1.195503852","rc":[{"atl":[[10,1.42]],"id":28338255},{"atl":[[1.85,2],[1.86,0]],"id":26051221}],"con":true,"img":false}]}
{"op":"mcm","clk":"5353389429","pt":1646214130206,"mc":[{"id":"1.195503852","rc":[{"atl":[[9.8,1.42]],"id":28338255}],"con":true,"img":false}]}
{"op":"mcm","clk":"5353389512","pt":1646214131502,"mc":[{"id":"1.195503852","rc":[{"atl":[[9.4,1.42]],"id":28338255}],"con":true,"img":false}]}
{"op":"mcm","clk":"5353389620","pt":1646214132997,"mc":[{"id":"1.195503852","rc":[{"atl":[[9.6,1.42]],"id":28338255}],"con":true,"img":false}]}
{"op":"mcm","clk":"5353389645","pt":1646214133310,"mc":[{"id":"1.195503852","rc":[{"atb":[[1.74,7.29],[2.28,4.21],[1.94,5.73]],"id":28338255},{"atl":[[9.4,0]],"id":28338255},{"atb":[[1.4,13.48],[1.2,26.97],[1.01,539.53]],"id":26051221}],"con":true,"img":false}]}
{"op":"mcm","clk":"5353389660","pt":1646214133518,"mc":[{"id":"1.195503852","rc":[{"atb":[[2.3,2],[2.38,0]],"id":28338255}],"con":true,"img":false}]}
{"op":"mcm","clk":"5353389798","pt":1646214135383,"mc":[{"id":"1.195503852","rc":[{"atl":[[14.5,1.42]],"id":26051221}],"con":true,"img":false}]}
{"op":"mcm","clk":"5353389834","pt":1646214135897,"mc":[{"id":"1.195503852","rc":[{"atl":[[9.6,0],[9.8,0]],"id":28338255}],"con":true,"img":false}]}
{"op":"mcm","clk":"5353389863","pt":1646214136311,"mc":[{"id":"1.195503852","rc":[{"atl":[[4.1,2],[4.2,0]],"id":28338255}],"con":true,"img":false}]}
{"op":"mcm","clk":"5353389910","pt":1646214137031,"mc":[{"id":"1.195503852","rc":[{"atl":[[14,1.42]],"id":26051221}],"con":true,"img":false}]}
{"op":"mcm","clk":"5353389918","pt":1646214137085,"mc":[{"id":"1.195503852","rc":[{"atl":[[4,2],[4.1,0]],"id":28338255}],"con":true,"img":false}]}
{"op":"mcm","clk":"5353389936","pt":1646214137397,"mc":[{"id":"1.195503852","rc":[{"atl":[[10,0]],"id":28338255}],"con":true,"img":false}]}
{"op":"mcm","clk":"5353390003","pt":1646214138429,"mc":[{"id":"1.195503852","rc":[{"atl":[[14,2.84]],"id":26051221}],"con":true,"img":false}]}
{"op":"mcm","clk":"5353390097","pt":1646214139831,"mc":[{"id":"1.195503852","rc":[{"atl":[[10.5,0]],"id":28338255}],"con":true,"img":false}]}
{"op":"mcm","clk":"5353390112","pt":1646214140037,"mc":[{"id":"1.195503852","rc":[{"atl":[[1.84,2],[1.85,0]],"id":26051221}],"con":true,"img":false}]}
{"op":"mcm","clk":"5353390198","pt":1646214141331,"mc":[{"id":"1.195503852","rc":[{"atl":[[11,0]],"id":28338255}],"con":true,"img":false}]}
{"op":"mcm","clk":"5353390226","pt":1646214141742,"mc":[{"id":"1.195503852","rc":[{"atl":[[13.5,1.42]],"id":26051221}],"con":true,"img":false}]}
{"op":"mcm","clk":"5353390261","pt":1646214142215,"mc":[{"id":"1.195503852","rc":[{"atl":[[4,0],[3.9,2]],"id":28338255}],"con":true,"img":false}]}
{"op":"mcm","clk":"5353390289","pt":1646214142730,"mc":[{"id":"1.195503852","rc":[{"atl":[[3.85,2],[3.9,0]],"id":28338255}],"con":true,"img":false}]}
{"op":"mcm","clk":"5353390314","pt":1646214143139,"mc":[{"id":"1.195503852","rc":[{"atl":[[3.85,0],[3.9,2]],"id":28338255}],"con":true,"img":false}]}
{"op":"mcm","clk":"5353390329","pt":1646214143347,"mc":[{"id":"1.195503852","rc":[{"atl":[[3.85,2],[3.9,0]],"id":28338255}],"con":true,"img":false}]}
{"op":"mcm","clk":"5353390338","pt":1646214143516,"mc":[{"id":"1.195503852","rc":[{"atl":[[11.5,0]],"id":28338255}],"con":true,"img":false}]}
{"op":"mcm","clk":"5353390427","pt":1646214145214,"mc":[{"id":"1.195503852","rc":[{"atl":[[3.8,2]],"id":28338255}],"con":true,"img":false}]}
{"op":"mcm","clk":"5353390432","pt":1646214145315,"mc":[{"id":"1.195503852","rc":[{"atl":[[3.85,0]],"id":28338255}],"con":true,"img":false}]}
{"op":"mcm","clk":"5353390450","pt":1646214145626,"mc":[{"id":"1.195503852","rc":[{"atl":[[3.85,2],[3.8,0]],"id":28338255}],"con":true,"img":false}]}
{"op":"mcm","clk":"5353390515","pt":1646214146405,"mc":[{"id":"1.195503852","rc":[{"atl":[[12,0]],"id":28338255}],"con":true,"img":false}]}
{"op":"mcm","clk":"5353390650","pt":1646214148725,"mc":[{"id":"1.195503852","rc":[{"atl":[[13,1.42]],"id":26051221}],"con":true,"img":false}]}
{"op":"mcm","clk":"5353390794","pt":1646214150743,"mc":[{"id":"1.195503852","rc":[{"atl":[[3.85,0],[4.1,2]],"id":28338255}],"con":true,"img":false}]}
{"op":"mcm","clk":"5353390852","pt":1646214151624,"mc":[{"id":"1.195503852","rc":[{"atl":[[1.83,2],[1.84,0]],"id":26051221}],"con":true,"img":false}]}
{"op":"mcm","clk":"5353390911","pt":1646214152651,"mc":[{"id":"1.195503852","rc":[{"atl":[[4.1,0],[4.2,2]],"id":28338255}],"con":true,"img":false}]}
{"op":"mcm","clk":"5353391184","pt":1646214156541,"mc":[{"id":"1.195503852","rc":[{"atl":[[1.83,0],[1.82,2]],"id":26051221}],"con":true,"img":false}]}
{"op":"mcm","clk":"5353391263","pt":1646214157732,"mc":[{"id":"1.195503852","rc":[{"atl":[[4.1,2],[4.2,0]],"id":28338255}],"con":true,"img":false}]}
{"op":"mcm","clk":"5353391504","pt":1646214161627,"mc":[{"id":"1.195503852","rc":[{"atl":[[1.85,2],[1.82,0]],"id":26051221}],"con":true,"img":false}]}
{"op":"mcm","clk":"5353391584","pt":1646214162967,"mc":[{"id":"1.195503852","rc":[{"atl":[[4,2],[4.1,0]],"id":28338255}],"con":true,"img":false}]}
{"op":"mcm","clk":"5353391867","pt":1646214166648,"mc":[{"id":"1.195503852","rc":[{"atb":[[2.3,0],[2.32,2]],"id":28338255}],"con":true,"img":false}]}
{"op":"mcm","clk":"5353391873","pt":1646214166749,"mc":[{"id":"1.195503852","rc":[{"atl":[[1.85,0],[1.82,2]],"id":26051221}],"con":true,"img":false}]}
{"op":"mcm","clk":"5353391978","pt":1646214168366,"mc":[{"id":"1.195503852","rc":[{"atl":[[13,0]],"id":26051221}],"con":true,"img":false}]}
{"op":"mcm","clk":"5353392096","pt":1646214170064,"mc":[{"id":"1.195503852","rc":[{"atl":[[4,0],[3.95,2]],"id":28338255}],"con":true,"img":false}]}
{"op":"mcm","clk":"5353392227","pt":1646214171975,"mc":[{"id":"1.195503852","rc":[{"atl":[[1.82,0],[1.81,2]],"id":26051221}],"con":true,"img":false}]}
{"op":"mcm","clk":"5353392312","pt":1646214173484,"mc":[{"id":"1.195503852","rc":[{"atb":[[1.4,0],[1.2,0],[1.01,0]],"id":26051221},{"atb":[[1.74,0],[2.28,0],[1.94,0]],"id":28338255}],"con":true,"img":false}]}
{"op":"mcm","clk":"5353392407","pt":1646214174679,"mc":[{"id":"1.195503852","rc":[{"atl":[[12.5,0]],"id":28338255}],"con":true,"img":false}]}
{"op":"mcm","clk":"5353392438","pt":1646214175195,"mc":[{"id":"1.195503852","rc":[{"atb":[[2.32,0],[2.34,2]],"id":28338255},{"atl":[[3.95,0],[4.1,2]],"id":28338255}],"con":true,"img":false}]}
{"op":"mcm","clk":"5353392573","pt":1646214177061,"mc":[{"id":"1.195503852","rc":[{"atl":[[12.5,1.42]],"id":28338255}],"con":true,"img":false}]}
{"op":"mcm","clk":"5353392577","pt":1646214177163,"mc":[{"id":"1.195503852","rc":[{"atl":[[1.8,2],[1.81,0]],"id":26051221}],"con":true,"img":false}]}
{"op":"mcm","clk":"5353392631","pt":1646214177890,"mc":[{"id":"1.195503852","rc":[{"atl":[[13.5,0]],"id":26051221}],"con":true,"img":false}]}
{"op":"mcm","clk":"5353392696","pt":1646214178866,"mc":[{"id":"1.195503852","rc":[{"atl":[[12,1.42]],"id":28338255}],"con":true,"img":false}]}
{"op":"mcm","clk":"5353392787","pt":1646214180305,"mc":[{"id":"1.195503852","rc":[{"atl":[[4.4,2]],"id":28338255}],"con":true,"img":false}]}
{"op":"mcm","clk":"5353392792","pt":1646214180359,"mc":[{"id":"1.195503852","rc":[{"atl":[[4.1,0]],"id":28338255}],"con":true,"img":false}]}
{"op":"mcm","clk":"5353392950","pt":1646214182994,"mc":[{"id":"1.195503852","rc":[{"atl":[[4.3,2],[11,1.42],[4.4,0]],"id":28338255}],"con":true,"img":false}]}
{"op":"mcm","clk":"5353393040","pt":1646214184185,"mc":[{"id":"1.195503852","rc":[{"atl":[[11.5,1.42]],"id":28338255}],"con":true,"img":false}]}
{"op":"mcm","clk":"5353393144","pt":1646214185689,"mc":[{"id":"1.195503852","rc":[{"atl":[[11.5,2.84]],"id":28338255}],"con":true,"img":false}]}
{"op":"mcm","clk":"5353393150","pt":1646214185789,"mc":[{"id":"1.195503852","rc":[{"atl":[[1.8,0],[1.81,2]],"id":26051221}],"con":true,"img":false}]}
{"op":"mcm","clk":"5353393160","pt":1646214185894,"mc":[{"id":"1.195503852","rc":[{"atb":[[1.44,12.26],[1.24,22.48],[1.04,134.88]],"id":26051221},{"atb":[[1.89,6.06],[2.18,4.57],[1.69,7.82]],"id":28338255}],"con":true,"img":false}]}
{"op":"mcm","clk":"5353393175","pt":1646214186107,"mc":[{"id":"1.195503852","rc":[{"atb":[[1.41,0],[1.45,2]],"id":26051221}],"con":true,"img":false}]}
{"op":"mcm","clk":"5353393322","pt":1646214188071,"mc":[{"id":"1.195503852","rc":[{"atl":[[4.3,0]],"id":28338255}],"con":true,"img":false}]}
{"op":"mcm","clk":"5353393328","pt":1646214188181,"mc":[{"id":"1.195503852","rc":[{"atl":[[4.4,2]],"id":28338255}],"con":true,"img":false}]}
{"op":"mcm","clk":"5353393353","pt":1646214188486,"mc":[{"id":"1.195503852","rc":[{"atl":[[10,1.42]],"id":28338255}],"con":true,"img":false}]}
{"op":"mcm","clk":"5353393500","pt":1646214190917,"mc":[{"id":"1.195503852","rc":[{"atl":[[10.5,1.42]],"id":28338255}],"con":true,"img":false}]}
{"op":"mcm","clk":"5353393505","pt":1646214191018,"mc":[{"id":"1.195503852","rc":[{"atl":[[1.8,2],[1.81,0]],"id":26051221}],"con":true,"img":false}]}
{"op":"mcm","clk":"5353393543","pt":1646214191592,"mc":[{"id":"1.195503852","rc":[{"atl":[[10,0]],"id":28338255}],"con":true,"img":false}]}
{"op":"mcm","clk":"5353393700","pt":1646214194014,"mc":[{"id":"1.195503852","rc":[{"atl":[[10.5,0]],"id":28338255},{"atl":[[14,0]],"id":26051221}],"con":true,"img":false}]}
{"op":"mcm","clk":"5353393993","pt":1646214198384,"mc":[{"id":"1.195503852","rc":[{"atl":[[14.5,0]],"id":26051221},{"atl":[[11,0]],"id":28338255}],"con":true,"img":false}]}
{"op":"mcm","clk":"5353394133","pt":1646214200509,"mc":[{"id":"1.195503852","rc":[{"atl":[[11.5,0]],"id":28338255}],"con":true,"img":false}]}
{"op":"mcm","clk":"5353394296","pt":1646214202524,"mc":[{"id":"1.195503852","rc":[{"atl":[[12,0]],"id":28338255}],"con":true,"img":false}]}
{"op":"mcm","clk":"5353394363","pt":1646214203604,"mc":[{"id":"1.195503852","rc":[{"atl":[[4.4,0],[4.5,2]],"id":28338255}],"con":true,"img":false}]}
{"op":"mcm","clk":"5353394433","pt":1646214204798,"mc":[{"id":"1.195503852","rc":[{"atb":[[2.36,2],[2.34,0]],"id":28338255},{"atl":[[1.8,0],[1.79,2]],"id":26051221}],"con":true,"img":false}]}
{"op":"mcm","clk":"5353394442","pt":1646214205006,"mc":[{"id":"1.195503852","rc":[{"atl":[[12.5,0]],"id":28338255},{"atl":[[15,0]],"id":26051221}],"con":true,"img":false}]}
{"op":"mcm","clk":"5353394470","pt":1646214205622,"mc":[{"id":"1.195503852","rc":[{"atl":[[20,1.42]],"id":26051221}],"con":true,"img":false}]}
{"op":"mcm","clk":"5353394518","pt":1646214206341,"mc":[{"id":"1.195503852","rc":[{"atl":[[4.4,2],[4.5,0]],"id":28338255}],"con":true,"img":false}]}
{"op":"mcm","clk":"5353394573","pt":1646214207122,"mc":[{"id":"1.195503852","rc":[{"atl":[[13,0],[13.5,0],[14,0]],"id":28338255},{"atl":[[15.5,0]],"id":26051221}],"con":true,"img":false}]}
{"op":"mcm","clk":"5353394697","pt":1646214208924,"mc":[{"id":"1.195503852","rc":[{"atl":[[21,1.42]],"id":26051221}],"con":true,"img":false}]}
{"op":"mcm","clk":"5353394725","pt":1646214209440,"mc":[{"id":"1.195503852","rc":[{"atl":[[16,0]],"id":26051221},{"atl":[[14.5,0]],"id":28338255}],"con":true,"img":false}]}
{"op":"mcm","clk":"5353394769","pt":1646214210010,"mc":[{"id":"1.195503852","rc":[{"atb":[[2.36,0],[2.3,2]],"id":28338255},{"atl":[[1.83,2],[1.79,0]],"id":26051221}],"con":true,"img":false}]}
{"op":"mcm","clk":"5353394884","pt":1646214211250,"mc":[{"id":"1.195503852","rc":[{"atl":[[22,1.42]],"id":26051221},{"atl":[[19.5,1.42]],"id":28338255}],"con":true,"img":false}]}
{"op":"mcm","clk":"5353395155","pt":1646214215124,"mc":[{"id":"1.195503852","rc":[{"atl":[[1.83,0],[1.82,2]],"id":26051221},{"atb":[[2.3,0],[2.32,2]],"id":28338255}],"con":true,"img":false}]}
{"op":"mcm","clk":"5353395222","pt":1646214216155,"mc":[{"id":"1.195503852","rc":[{"atl":[[16,1.42]],"id":26051221}],"con":true,"img":false}]}
{"op":"mcm","clk":"5353395484","pt":1646214220361,"mc":[{"id":"1.195503852","rc":[{"atl":[[15.5,1.42]],"id":26051221}],"con":true,"img":false}]}
{"op":"mcm","clk":"5353395553","pt":1646214221459,"mc":[{"id":"1.195503852","rc":[{"atl":[[15.5,2.84]],"id":26051221}],"con":true,"img":false}]}
{"op":"mcm","clk":"5353395725","pt":1646214224233,"mc":[{"id":"1.195503852","rc":[{"atl":[[4.5,2]],"id":28338255}],"con":true,"img":false}]}
{"op":"mcm","clk":"5353395733","pt":1646214224341,"mc":[{"id":"1.195503852","rc":[{"atl":[[4.4,0]],"id":28338255}],"con":true,"img":false}]}
{"op":"mcm","clk":"5353395793","pt":1646214225273,"mc":[{"id":"1.195503852","rc":[{"atl":[[1.82,0],[1.81,2]],"id":26051221}],"con":true,"img":false}]}
{"op":"mcm","clk":"5353396109","pt":1646214229357,"mc":[{"id":"1.195503852","rc":[{"atl":[[4.6,2]],"id":28338255}],"con":true,"img":false}]}
{"op":"mcm","clk":"5353396118","pt":1646214229454,"mc":[{"id":"1.195503852","rc":[{"atl":[[4.5,0]],"id":28338255}],"con":true,"img":false}]}
{"op":"mcm","clk":"5353396181","pt":1646214230481,"mc":[{"id":"1.195503852","rc":[{"atl":[[1.82,2],[1.81,0]],"id":26051221}],"con":true,"img":false}]}
{"op":"mcm","clk":"5353396242","pt":1646214231463,"mc":[{"id":"1.195503852","rc":[{"atl":[[1.78,2],[1.82,0]],"id":26051221},{"atb":[[2.38,2]],"id":28338255}],"con":true,"img":false}]}
{"op":"mcm","clk":"5353396248","pt":1646214231567,"mc":[{"id":"1.195503852","rc":[{"atb":[[2.32,0]],"id":28338255}],"con":true,"img":false}]}
{"op":"mcm","clk":"5353396366","pt":1646214233684,"mc":[{"id":"1.195503852","rc":[{"atb":[[1.89,0],[2.18,0],[1.69,0]],"id":28338255},{"atb":[[1.44,0],[1.24,0],[1.04,0]],"id":26051221}],"con":true,"img":false}]}
{"op":"mcm","clk":"5353396419","pt":1646214234566,"mc":[{"id":"1.195503852","rc":[{"atl":[[4.6,0],[4.9,2]],"id":28338255}],"con":true,"img":false}]}
{"op":"mcm","clk":"5353396494","pt":1646214235651,"mc":[{"id":"1.195503852","rc":[{"atl":[[14,1.42]],"id":28338255}],"con":true,"img":false}]}
{"op":"mcm","clk":"5353396515","pt":1646214235962,"mc":[{"id":"1.195503852","rc":[{"atl":[[15.5,0]],"id":26051221}],"con":true,"img":false}]}
{"op":"mcm","clk":"5353396546","pt":1646214236476,"mc":[{"id":"1.195503852","rc":[{"atl":[[4.9,0],[5,2]],"id":28338255}],"con":true,"img":false}]}
{"op":"mcm","clk":"5353396552","pt":1646214236581,"mc":[{"id":"1.195503852","rc":[{"atl":[[1.81,2]],"id":26051221}],"con":true,"img":false}]}
{"op":"mcm","clk":"5353396557","pt":1646214236686,"mc":[{"id":"1.195503852","rc":[{"atl":[[1.78,0]],"id":26051221}],"con":true,"img":false}]}
{"op":"mcm","clk":"5353396570","pt":1646214236891,"mc":[{"id":"1.195503852","rc":[{"atl":[[5.2,2]],"id":28338255}],"con":true,"img":false}]}
{"op":"mcm","clk":"5353396580","pt":1646214236991,"mc":[{"id":"1.195503852","rc":[{"atl":[[5,0]],"id":28338255}],"con":true,"img":false}]}
{"op":"mcm","clk":"5353396645","pt":1646214237870,"mc":[{"id":"1.195503852","rc":[{"atl":[[14,2.84]],"id":28338255}],"con":true,"img":false}]}
{"op":"mcm","clk":"5353396848","pt":1646214240668,"mc":[{"id":"1.195503852","rc":[{"atl":[[13,1.42]],"id":28338255}],"con":true,"img":false}]}
{"op":"mcm","clk":"5353396908","pt":1646214241390,"mc":[{"id":"1.195503852","rc":[{"atl":[[16,0]],"id":26051221}],"con":true,"img":false}]}
{"op":"mcm","clk":"5353396930","pt":1646214241699,"mc":[{"id":"1.195503852","rc":[{"atl":[[1.8,2]],"id":26051221}],"con":true,"img":false}]}
{"op":"mcm","clk":"5353396935","pt":1646214241815,"mc":[{"id":"1.195503852","rc":[{"atl":[[1.81,0]],"id":26051221}],"con":true,"img":false}]}
{"op":"mcm","clk":"5353396949","pt":1646214241957,"mc":[{"id":"1.195503852","rc":[{"atl":[[5.1,2],[5.2,0]],"id":28338255}],"con":true,"img":false}]}
{"op":"mcm","clk":"5353397000","pt":1646214242791,"mc":[{"id":"1.195503852","rc":[{"atl":[[1.8,0],[1.79,2]],"id":26051221}],"con":true,"img":false}]}
{"op":"mcm","clk":"5353397021","pt":1646214243200,"mc":[{"id":"1.195503852","rc":[{"atl":[[12.5,1.42]],"id":28338255}],"con":true,"img":false}]}
{"op":"mcm","clk":"5353397211","pt":1646214245998,"mc":[{"id":"1.195503852","rc":[{"atb":[[2.4,2],[2.38,0]],"id":28338255}],"con":true,"img":false}]}
{"op":"mcm","clk":"5353397283","pt":1646214247079,"mc":[{"id":"1.195503852","rc":[{"atl":[[5.6,2],[5.1,0]],"id":28338255},{"atl":[[16.5,0]],"id":26051221}],"con":true,"img":false}]}
{"op":"mcm","clk":"5353397334","pt":1646214247909,"mc":[{"id":"1.195503852","rc":[{"atl":[[1.79,0],[1.81,2]],"id":26051221}],"con":true,"img":false}]}
{"op":"mcm","clk":"5353397347","pt":1646214248113,"mc":[{"id":"1.195503852","rc":[{"atl":[[23,1.42]],"id":26051221},{"atl":[[11,1.42]],"id":28338255}],"con":true,"img":false}]}
{"op":"mcm","clk":"5353397494","pt":1646214250081,"mc":[{"id":"1.195503852","rc":[{"atb":[[1.01,539.53],[1.02,269.76],[1.22,24.52]],"id":26051221},{"atb":[[2.36,3.96],[1.98,5.5],[2.76,3.06]],"id":28338255}],"con":true,"img":false}]}
{"op":"mcm","clk":"5353397509","pt":1646214250239,"mc":[{"id":"1.195503852","rc":[{"atb":[[1.23,2]],"id":26051221}],"con":true,"img":false}]}
{"op":"mcm","clk":"5353397516","pt":1646214250299,"mc":[{"id":"1.195503852","rc":[{"atb":[[1.45,0]],"id":26051221}],"con":true,"img":false}]}
{"op":"mcm","clk":"5353397619","pt":1646214251691,"mc":[{"id":"1.195503852","rc":[{"atb":[[1.14,1.42]],"id":26051221},{"atl":[[10.5,1.42]],"id":28338255}],"con":true,"img":false}]}
{"op":"mcm","clk":"5353397652","pt":1646214252203,"mc":[{"id":"1.195503852","rc":[{"atl":[[5.9,2],[5.6,0]],"id":28338255}],"con":true,"img":false}]}
{"op":"mcm","clk":"5353397723","pt":1646214253083,"mc":[{"id":"1.195503852","rc":[{"atl":[[1.81,0],[1.76,2]],"id":26051221}],"con":true,"img":false}]}
{"op":"mcm","clk":"5353397742","pt":1646214253291,"mc":[{"id":"1.195503852","rc":[{"atb":[[1.26,1.42]],"id":26051221},{"atl":[[16,1.42]],"id":26051221},{"atl":[[9.6,1.42]],"id":28338255}],"con":true,"img":false}]}
{"op":"mcm","clk":"5353397893","pt":1646214255101,"mc":[{"id":"1.195503852","rc":[{"atl":[[1.76,0],[1.75,2]],"id":26051221}],"con":true,"img":false}]}
{"op":"mcm","clk":"5353397913","pt":1646214255411,"mc":[{"id":"1.195503852","rc":[{"atb":[[1.26,3.42],[1.23,0]],"id":26051221}],"con":true,"img":false}]}
{"op":"mcm","clk":"5353397970","pt":1646214256230,"mc":[{"id":"1.195503852","rc":[{"atb":[[1.25,1.42]],"id":26051221},{"atl":[[15.5,1.42]],"id":26051221},{"atl":[[9.4,1.42]],"id":28338255}],"con":true,"img":false}]}
{"op":"mcm","clk":"5353398021","pt":1646214256905,"mc":[{"id":"1.195503852","rc":[{"atb":[[1.26,2]],"id":26051221}],"con":true,"img":false}]}
{"op":"mcm","clk":"5353398056","pt":1646214257319,"mc":[{"id":"1.195503852","rc":[{"atl":[[5.9,0],[6.6,2]],"id":28338255}],"con":true,"img":false}]}
{"op":"mcm","clk":"5353398163","pt":1646214259027,"mc":[{"id":"1.195503852","rc":[{"atl":[[1.74,2],[1.75,0]],"id":26051221}],"con":true,"img":false}]}
{"op":"mcm","clk":"5353398209","pt":1646214259702,"mc":[{"id":"1.195503852","rc":[{"atl":[[1.74,0],[1.75,2]],"id":26051221}],"con":true,"img":false}]}
{"op":"mcm","clk":"5353398232","pt":1646214259914,"mc":[{"id":"1.195503852","rc":[{"atb":[[1.28,1.42]],"id":26051221},{"atl":[[14.5,1.42]],"id":26051221},{"atb":[[2.4,0],[2.5,2]],"id":28338255},{"atl":[[9,1.42]],"id":28338255}],"con":true,"img":false}]}
{"op":"mcm","clk":"5353398266","pt":1646214260532,"mc":[{"id":"1.195503852","rc":[{"atb":[[1.28,3.42],[1.26,0]],"id":26051221}],"con":true,"img":false}]}
{"op":"mcm","clk":"5353398280","pt":1646214260740,"mc":[{"id":"1.195503852","rc":[{"atb":[[1.28,1.42],[1.26,2]],"id":26051221}],"con":true,"img":false}]}
{"op":"mcm","clk":"5353398298","pt":1646214260947,"mc":[{"id":"1.195503852","rc":[{"atb":[[1.28,3.42],[1.26,0]],"id":26051221}],"con":true,"img":false}]}
{"op":"mcm","clk":"5353398414","pt":1646214262544,"mc":[{"id":"1.195503852","rc":[{"atl":[[6.8,2],[6.6,0]],"id":28338255}],"con":true,"img":false}]}
{"op":"mcm","clk":"5353398471","pt":1646214263219,"mc":[{"id":"1.195503852","rc":[{"atl":[[9.2,1.42]],"id":28338255},{"atb":[[1.24,1.42]],"id":26051221},{"atl":[[14,1.42]],"id":26051221}],"con":true,"img":false}]}
{"op":"mcm","clk":"5353398529","pt":1646214264040,"mc":[{"id":"1.195503852","rc":[{"atl":[[9,0]],"id":28338255},{"atb":[[1.28,2]],"id":26051221}],"con":true,"img":false}]}
{"op":"mcm","clk":"5353398582","pt":1646214264820,"mc":[{"id":"1.195503852","rc":[{"atl":[[1.7,2]],"id":26051221}],"con":true,"img":false}]}
{"op":"mcm","clk":"5353398588","pt":1646214264915,"mc":[{"id":"1.195503852","rc":[{"atl":[[1.75,0]],"id":26051221}],"con":true,"img":false}]}
{"op":"mcm","clk":"5353398616","pt":1646214265345,"mc":[{"id":"1.195503852","rc":[{"atb":[[1.24,2.84]],"id":26051221},{"atl":[[13.5,1.42]],"id":26051221},{"atl":[[9.2,2.84]],"id":28338255}],"con":true,"img":false}]}
{"op":"mcm","clk":"5353398660","pt":1646214266041,"mc":[{"id":"1.195503852","rc":[{"atb":[[1.28,0],[1.25,3.42]],"id":26051221}],"con":true,"img":false}]}
{"op":"mcm","clk":"5353398708","pt":1646214266712,"mc":[{"id":"1.195503852","rc":[{"atl":[[9.2,1.42]],"id":28338255}],"con":true,"img":false}]}
{"op":"mcm","clk":"5353398770","pt":1646214267647,"mc":[{"id":"1.195503852","rc":[{"atl":[[6.8,6]],"id":28338255},{"atb":[[1.25,10.26]],"id":26051221},{"atl":[[1.7,6]],"id":26051221}],"con":true,"img":false}]}
{"op":"mcm","clk":"5353398772","pt":1646214267744,"mc":[{"id":"1.195503852","rc":[{"atl":[[6.4,2],[6.8,4],[9.8,1.42]],"id":28338255},{"atb":[[1.23,1.42]],"id":26051221},{"atl":[[13,1.42]],"id":26051221}],"con":true,"img":false}]}
{"op":"mcm","clk":"5353398847","pt":1646214269043,"mc":[{"id":"1.195503852","rc":[{"atl":[[9.2,0],[9.4,0]],"id":28338255},{"atb":[[1.25,8.84]],"id":26051221}],"con":true,"img":false}]}
{"op":"mcm","clk":"5353398956","pt":1646214270747,"mc":[{"id":"1.195503852","rc":[{"atb":[[1.3,1.42]],"id":26051221},{"atl":[[13,2.84]],"id":26051221},{"atl":[[9.8,2.84]],"id":28338255}],"con":true,"img":false}]}
{"op":"mcm","clk":"5353398982","pt":1646214271160,"mc":[{"id":"1.195503852","rc":[{"atb":[[1.25,6.84],[1.3,3.42]],"id":26051221}],"con":true,"img":false}]}
{"op":"mcm","clk":"5353399033","pt":1646214271935,"mc":[{"id":"1.195503852","rc":[{"atl":[[9.6,0]],"id":28338255}],"con":true,"img":false}]}
{"op":"mcm","clk":"5353399090","pt":1646214272960,"mc":[{"id":"1.195503852","rc":[{"atl":[[6.4,0],[6.6,2]],"id":28338255}],"con":true,"img":false}]}
{"op":"mcm","clk":"5353399121","pt":1646214273327,"mc":[{"id":"1.195503852","rc":[{"atl":[[6.8,0]],"id":28338255}],"con":true,"img":false}]}
{"op":"mcm","clk":"5353399126","pt":1646214273430,"mc":[{"id":"1.195503852","rc":[{"atl":[[6.8,2],[6.6,4]],"id":28338255}],"con":true,"img":false}]}
{"op":"mcm","clk":"5353399138","pt":1646214273630,"mc":[{"id":"1.195503852","rc":[{"atl":[[6.8,0],[6.6,6]],"id":28338255}],"con":true,"img":false}]}
{"op":"mcm","clk":"5353399144","pt":1646214273733,"mc":[{"id":"1.195503852","rc":[{"atl":[[6.6,2]],"id":28338255}],"con":true,"img":false}]}
{"op":"mcm","clk":"5353399151","pt":1646214273842,"mc":[{"id":"1.195503852","rc":[{"atl":[[10,1.42]],"id":28338255},{"atb":[[1.27,1.42]],"id":26051221},{"atl":[[12.5,1.42]],"id":26051221}],"con":true,"img":false}]}
{"op":"mcm","clk":"5353399165","pt":1646214274043,"mc":[{"id":"1.195503852","rc":[{"atl":[[6.6,6]],"id":28338255}],"con":true,"img":false}]}
{"op":"mcm","clk":"5353399187","pt":1646214274453,"mc":[{"id":"1.195503852","rc":[{"atl":[[9.8,0]],"id":28338255},{"atb":[[1.3,2]],"id":26051221}],"con":true,"img":false}]}
{"op":"mcm","clk":"5353399248","pt":1646214275332,"mc":[{"id":"1.195503852","rc":[{"atb":[[1.29,1.42]],"id":26051221},{"atl":[[12,1.42]],"id":26051221},{"atl":[[11.5,1.42]],"id":28338255}],"con":true,"img":false}]}
{"op":"mcm","clk":"5353399306","pt":1646214276263,"mc":[{"id":"1.195503852","rc":[{"atb":[[1.3,0],[1.29,3.42]],"id":26051221}],"con":true,"img":false}]}
{"op":"mcm","clk":"5353399314","pt":1646214276370,"mc":[{"id":"1.195503852","rc":[{"atl":[[1.7,4],[1.71,2]],"id":26051221},{"atb":[[2.5,0]],"id":28338255}],"con":true,"img":false}]}
{"op":"mcm","clk":"5353399319","pt":1646214276468,"mc":[{"id":"1.195503852","rc":[{"atb":[[2.46,2]],"id":28338255}],"con":true,"img":false}]}
{"op":"mcm","clk":"5353399326","pt":1646214276577,"mc":[{"id":"1.195503852","rc":[{"atl":[[10,0]],"id":28338255}],"con":true,"img":false}]}
{"op":"mcm","clk":"5353399335","pt":1646214276675,"mc":[{"id":"1.195503852","rc":[{"atl":[[1.7,0]],"id":26051221}],"con":true,"img":false}]}
{"op":"mcm","clk":"5353399357","pt":1646214276937,"mc":[{"id":"1.195503852","rc":[{"atl":[[1.7,8]],"id":26051221}],"con":true,"img":false}]}
{"op":"mcm","clk":"5353399376","pt":1646214277247,"mc":[{"id":"1.195503852","rc":[{"atl":[[1.7,0]],"id":26051221}],"con":true,"img":false}]}
{"op":"mcm","clk":"5353399384","pt":1646214277359,"mc":[{"id":"1.195503852","rc":[{"atb":[[1.28,1.42],[1.25,0]],"id":26051221},{"atl":[[1.71,10],[15,1.42]],"id":26051221},{"atl":[[11.5,2.84]],"id":28338255}],"con":true,"img":false}]}
{"op":"mcm","clk":"5353399390","pt":1646214277454,"mc":[{"id":"1.195503852","rc":[{"atb":[[1.29,10.26]],"id":26051221}],"con":true,"img":false}]}
{"op":"mcm","clk":"5353399458","pt":1646214278541,"mc":[{"id":"1.195503852","rc":[{"atl":[[12,0],[12.5,0]],"id":26051221}],"con":true,"img":false}]}
{"op":"mcm","clk":"5353399569","pt":1646214280247,"mc":[{"id":"1.195503852","rc":[{"atl":[[10.5,0]],"id":28338255}],"con":true,"img":false}]}
{"op":"mcm","clk":"5353399629","pt":1646214281378,"mc":[{"id":"1.195503852","rc":[{"atl":[[12,1.42]],"id":28338255},{"atb":[[1.26,1.42]],"id":26051221},{"atl":[[16.5,1.42]],"id":26051221}],"con":true,"img":false}]}
{"op":"mcm","clk":"5353399736","pt":1646214283182,"mc":[{"id":"1.195503852","rc":[{"atb":[[1.26,2.84]],"id":26051221},{"atl":[[16.5,2.84]],"id":26051221},{"atl":[[12,2.84]],"id":28338255}],"con":true,"img":false}]}
{"op":"mcm","clk":"5353399793","pt":1646214284268,"mc":[{"id":"1.195503852","rc":[{"atl":[[13,0]],"id":26051221},{"atl":[[11,0]],"id":28338255}],"con":true,"img":false}]}
{"op":"mcm","clk":"5353399835","pt":1646214284865,"mc":[{"id":"1.195503852","rc":[{"atl":[[6.4,2],[6.6,4]],"id":28338255}],"con":true,"img":false}]}
{"op":"mcm","clk":"5353399851","pt":1646214285174,"mc":[{"id":"1.195503852","rc":[{"atl":[[6.6,0]],"id":28338255}],"con":true,"img":false}]}
{"op":"mcm","clk":"5353399857","pt":1646214285281,"mc":[{"id":"1.195503852","rc":[{"atl":[[6.4,6]],"id":28338255}],"con":true,"img":false}]}
{"op":"mcm","clk":"5353399874","pt":1646214285582,"mc":[{"id":"1.195503852","rc":[{"atl":[[6.4,2]],"id":28338255}],"con":true,"img":false}]}
{"op":"mcm","clk":"5353399895","pt":1646214285844,"mc":[{"id":"1.195503852","rc":[{"atl":[[6.4,6]],"id":28338255}],"con":true,"img":false}]}
{"op":"mcm","clk":"5353399963","pt":1646214286673,"mc":[{"id":"1.195503852","rc":[{"atl":[[13.5,1.42]],"id":28338255},{"atb":[[1.25,1.42]],"id":26051221}],"con":true,"img":false}]}
{"op":"mcm","clk":"5353400058","pt":1646214288174,"mc":[{"id":"1.195503852","rc":[{"atl":[[13.5,2.84]],"id":28338255},{"atb":[[1.25,2.84]],"id":26051221}],"con":true,"img":false}]}
{"op":"mcm","clk":"5353400148","pt":1646214289667,"mc":[{"id":"1.195503852","rc":[{"atl":[[11.5,0]],"id":28338255}],"con":true,"img":false}]}
{"op":"mcm","clk":"5353400254","pt":1646214291381,"mc":[{"id":"1.195503852","rc":[{"atl":[[14.5,1.42]],"id":28338255}],"con":true,"img":false}]}
{"op":"mcm","clk":"5353400373","pt":1646214293395,"mc":[{"id":"1.195503852","rc":[{"atb":[[2.36,0],[1.98,0],[2.76,0]],"id":28338255},{"atb":[[1.01,0],[1.02,0],[1.22,0]],"id":26051221}],"con":true,"img":false}]}
{"op":"mcm","clk":"5353400400","pt":1646214293805,"mc":[{"id":"1.195503852","rc":[{"atb":[[2.46,6]],"id":28338255}],"con":true,"img":false}]}
{"op":"mcm","clk":"5353400425","pt":1646214294169,"mc":[{"id":"1.195503852","rc":[{"atb":[[2.46,2]],"id":28338255}],"con":true,"img":false}]}
{"op":"mcm","clk":"5353400431","pt":1646214294272,"mc":[{"id":"1.195503852","rc":[{"atl":[[14.5,2.84]],"id":28338255}],"con":true,"img":false}]}
{"op":"mcm","clk":"5353400440","pt":1646214294477,"mc":[{"id":"1.195503852","rc":[{"atb":[[2.46,6]],"id":28338255}],"con":true,"img":false}]}
{"op":"mcm","clk":"5353400468","pt":1646214294888,"mc":[{"id":"1.195503852","rc":[{"atb":[[2.46,4],[2.48,2]],"id":28338255},{"atl":[[1.7,2],[1.71,8]],"id":26051221}],"con":true,"img":false}]}
{"op":"mcm","clk":"5353400488","pt":1646214295195,"mc":[{"id":"1.195503852","rc":[{"atb":[[2.46,0]],"id":28338255},{"atl":[[1.71,0]],"id":26051221}],"con":true,"img":false}]}
{"op":"mcm","clk":"5353400491","pt":1646214295251,"mc":[{"id":"1.195503852","rc":[{"atb":[[2.48,6]],"id":28338255},{"atl":[[1.7,10]],"id":26051221}],"con":true,"img":false}]}
{"op":"mcm","clk":"5353400764","pt":1646214299887,"mc":[{"id":"1.195503852","rc":[{"atl":[[13,1.42]],"id":26051221}],"con":true,"img":false}]}
{"op":"mcm","clk":"5353400806","pt":1646214300513,"mc":[{"id":"1.195503852","rc":[{"atl":[[6.4,4],[6.2,2]],"id":28338255}],"con":true,"img":false}]}
{"op":"mcm","clk":"5353400830","pt":1646214300792,"mc":[{"id":"1.195503852","rc":[{"atl":[[6.4,0]],"id":28338255}],"con":true,"img":false}]}
{"op":"mcm","clk":"5353400836","pt":1646214300879,"mc":[{"id":"1.195503852","rc":[{"atl":[[6.2,6]],"id":28338255}],"con":true,"img":false}]}
{"op":"mcm","clk":"5353400841","pt":1646214300986,"mc":[{"id":"1.195503852","rc":[{"atl":[[6.4,2],[6.2,4]],"id":28338255}],"con":true,"img":false}]}
{"op":"mcm","clk":"5353400852","pt":1646214301190,"mc":[{"id":"1.195503852","rc":[{"atl":[[6.2,0]],"id":28338255}],"con":true,"img":false}]}
{"op":"mcm","clk":"5353400873","pt":1646214301499,"mc":[{"id":"1.195503852","rc":[{"atl":[[6.4,6]],"id":28338255}],"con":true,"img":false}]}
{"op":"mcm","clk":"5353400916","pt":1646214302169,"mc":[{"id":"1.195503852","rc":[{"atl":[[12.5,1.42]],"id":26051221}],"con":true,"img":false}]}
{"op":"mcm","clk":"5353400970","pt":1646214303009,"mc":[{"id":"1.195503852","rc":[{"atb":[[2.48,2]],"id":28338255}],"con":true,"img":false}]}
{"op":"mcm","clk":"5353401008","pt":1646214303415,"mc":[{"id":"1.195503852","rc":[{"atb":[[1.26,0],[1.23,0],[1.24,0]],"id":26051221}],"con":true,"img":false}]}
{"op":"mcm","clk":"5353401114","pt":1646214304816,"mc":[{"id":"1.195503852","rc":[{"atb":[[2.48,6]],"id":28338255}],"con":true,"img":false}]}
{"op":"mcm","clk":"5353401139","pt":1646214305123,"mc":[{"id":"1.195503852","rc":[{"atb":[[2.48,2]],"id":28338255},{"atl":[[11.5,1.42]],"id":28338255}],"con":true,"img":false}]}
{"op":"mcm","clk":"5353401161","pt":1646214305383,"mc":[{"id":"1.195503852","rc":[{"atb":[[2.48,6]],"id":28338255}],"con":true,"img":false}]}
{"op":"mcm","clk":"5353401300","pt":1646214307302,"mc":[{"id":"1.195503852","rc":[{"atb":[[2.36,3.96],[1.98,5.5],[2.76,3.06]],"id":28338255},{"atb":[[1.01,539.53],[1.02,269.76],[1.22,24.52]],"id":26051221}],"con":true,"img":false}]}
{"op":"mcm","clk":"5353401328","pt":1646214307613,"mc":[{"id":"1.195503852","rc":[{"atl":[[12,1.42]],"id":26051221}],"con":true,"img":false}]}
{"op":"mcm","clk":"5353401340","pt":1646214307819,"mc":[{"id":"1.195503852","rc":[{"atl":[[1.68,33]],"id":26051221}],"con":true,"img":false}]}
{"op":"mcm","clk":"5353401374","pt":1646214308189,"mc":[{"id":"1.195503852","rc":[{"atl":[[1.7,2]],"id":26051221}],"con":true,"img":false}]}
{"op":"mcm","clk":"5353401401","pt":1646214308601,"mc":[{"id":"1.195503852","rc":[{"atl":[[1.68,45.37]],"id":26051221}],"con":true,"img":false}]}
{"op":"mcm","clk":"5353401550","pt":1646214310726,"mc":[{"id":"1.195503852","rc":[{"atl":[[12,2.84]],"id":26051221},{"atl":[[11,1.42]],"id":28338255}],"con":true,"img":false}]}
{"op":"mcm","clk":"5353401755","pt":1646214313421,"mc":[{"id":"1.195503852","rc":[{"atb":[[1.3,15]],"id":26051221}],"con":true,"img":false}]}
{"op":"mcm","clk":"5353401792","pt":1646214313832,"mc":[{"id":"1.195503852","rc":[{"atb":[[1.29,3.42]],"id":26051221}],"con":true,"img":false}]}
{"op":"mcm","clk":"5353401815","pt":1646214314101,"mc":[{"id":"1.195503852","rc":[{"atb":[[1.3,45]],"id":26051221}],"con":true,"img":false}]}
{"op":"mcm","clk":"5353401825","pt":1646214314207,"mc":[{"id":"1.195503852","rc":[{"atb":[[1.3,46.42],[1.31,2]],"id":26051221},{"atl":[[11,1.42]],"id":26051221},{"atl":[[11,2.84]],"id":28338255}],"con":true,"img":false}]}
{"op":"mcm","clk":"5353401835","pt":1646214314309,"mc":[{"id":"1.195503852","rc":[{"atb":[[1.29,1.42]],"id":26051221}],"con":true,"img":false}]}
{"op":"mcm","clk":"5353401851","pt":1646214314515,"mc":[{"id":"1.195503852","rc":[{"atb":[[1.3,16.42]],"id":26051221}],"con":true,"img":false}]}
{"op":"mcm","clk":"5353401860","pt":1646214314623,"mc":[{"id":"1.195503852","rc":[{"atb":[[1.31,32]],"id":26051221}],"con":true,"img":false}]}
{"op":"mcm","clk":"5353401900","pt":1646214315040,"mc":[{"id":"1.195503852","rc":[{"atb":[[1.31,6]],"id":26051221}],"con":true,"img":false}]}
{"op":"mcm","clk":"5353402083","pt":1646214317229,"mc":[{"id":"1.195503852","rc":[{"atb":[[1.31,2]],"id":26051221},{"atl":[[1.68,33]],"id":26051221},{"atb":[[2.48,2]],"id":28338255},{"atl":[[6.4,2]],"id":28338255}],"con":true,"img":false}]}
{"op":"mcm","clk":"5353402101","pt":1646214317430,"mc":[{"id":"1.195503852","rc":[{"atl":[[6.4,0],[6.6,2]],"id":28338255}],"con":true,"img":false}]}
{"op":"mcm","clk":"5353402112","pt":1646214317536,"mc":[{"id":"1.195503852","rc":[{"atb":[[1.26,1.42]],"id":26051221},{"atl":[[11.5,1.42]],"id":26051221}],"con":true,"img":false}]}
{"op":"mcm","clk":"5353402142","pt":1646214317796,"mc":[{"id":"1.195503852","rc":[{"atb":[[1.31,6]],"id":26051221},{"atl":[[1.68,42.98]],"id":26051221},{"atl":[[6.6,6]],"id":28338255}],"con":true,"img":false}]}
{"op":"mcm","clk":"5353402175","pt":1646214318315,"mc":[{"id":"1.195503852","rc":[{"atl":[[1.68,33]],"id":26051221}],"con":true,"img":false}]}
{"op":"mcm","clk":"5353402272","pt":1646214319719,"mc":[{"id":"1.195503852","rc":[{"atb":[[1.35,1.42]],"id":26051221},{"atl":[[11.5,2.84]],"id":26051221}],"con":true,"img":false}]}
{"op":"mcm","clk":"5353402289","pt":1646214319925,"mc":[{"id":"1.195503852","rc":[{"atb":[[1.31,4],[1.35,3.42]],"id":26051221}],"con":true,"img":false}]}
{"op":"mcm","clk":"5353402298","pt":1646214320033,"mc":[{"id":"1.195503852","rc":[{"atb":[[1.32,2]],"id":26051221}],"con":true,"img":false}]}
{"op":"mcm","clk":"5353402306","pt":1646214320135,"mc":[{"id":"1.195503852","rc":[{"atb":[[1.35,1.42]],"id":26051221}],"con":true,"img":false}]}
{"op":"mcm","clk":"5353402319","pt":1646214320346,"mc":[{"id":"1.195503852","rc":[{"atb":[[1.36,2],[1.32,0]],"id":26051221}],"con":true,"img":false}]}
{"op":"mcm","clk":"5353402357","pt":1646214320922,"mc":[{"id":"1.195503852","rc":[{"atl":[[11,0]],"id":26051221}],"con":true,"img":false}]}
{"op":"mcm","clk":"5353402414","pt":1646214321699,"mc":[{"id":"1.195503852","rc":[{"atl":[[1.68,43.24]],"id":26051221}],"con":true,"img":false}]}
{"op":"mcm","clk":"5353402512","pt":1646214323124,"mc":[{"id":"1.195503852","rc":[{"atb":[[1.34,1.42]],"id":26051221}],"con":true,"img":false}]}
{"op":"mcm","clk":"5353402557","pt":1646214323742,"mc":[{"id":"1.195503852","rc":[{"atl":[[11.5,0]],"id":26051221},{"atl":[[11,0]],"id":28338255}],"con":true,"img":false}]}
{"op":"mcm","clk":"5353402640","pt":1646214324935,"mc":[{"id":"1.195503852","rc":[{"atb":[[1.34,2.84]],"id":26051221}],"con":true,"img":false}]}
{"op":"mcm","clk":"5353402673","pt":1646214325448,"mc":[{"id":"1.195503852","rc":[{"atb":[[1.35,3.42],[1.36,0]],"id":26051221}],"con":true,"img":false}]}
{"op":"mcm","clk":"5353402761","pt":1646214326744,"mc":[{"id":"1.195503852","rc":[{"atb":[[1.28,0],[1.29,0]],"id":26051221},{"atl":[[1.68,33],[12,0]],"id":26051221},{"atl":[[11.5,0]],"id":28338255}],"con":true,"img":false}]}
{"op":"mcm","clk":"5353402770","pt":1646214326849,"mc":[{"id":"1.195503852","rc":[{"atb":[[1.31,0]],"id":26051221}],"con":true,"img":false}]}
{"op":"mcm","clk":"5353402796","pt":1646214327114,"mc":[{"id":"1.195503852","rc":[{"atb":[[1.35,10.26]],"id":26051221},{"atl":[[6.2,10],[6.6,4]],"id":28338255}],"con":true,"img":false}]}
{"op":"mcm","clk":"5353402919","pt":1646214328456,"mc":[{"id":"1.195503852","rc":[{"atl":[[1.68,41.53]],"id":26051221}],"con":true,"img":false}]}
{"op":"mcm","clk":"5353403043","pt":1646214330056,"mc":[{"id":"1.195503852","rc":[{"atl":[[12.5,0]],"id":26051221},{"atl":[[12,0]],"id":28338255}],"con":true,"img":false}]}
{"op":"mcm","clk":"5353403130","pt":1646214331246,"mc":[{"id":"1.195503852","rc":[{"atl":[[1.71,2]],"id":26051221}],"con":true,"img":false}]}
{"op":"mcm","clk":"5353403134","pt":1646214331351,"mc":[{"id":"1.195503852","rc":[{"atl":[[1.7,0]],"id":26051221}],"con":true,"img":false}]}
{"op":"mcm","clk":"5353403150","pt":1646214331565,"mc":[{"id":"1.195503852","rc":[{"atb":[[1.32,1.42]],"id":26051221}],"con":true,"img":false}]}
{"op":"mcm","clk":"5353403206","pt":1646214332241,"mc":[{"id":"1.195503852","rc":[{"atl":[[5.9,2],[6.2,0]],"id":28338255}],"con":true,"img":false}]}
{"op":"mcm","clk":"5353403293","pt":1646214333227,"mc":[{"id":"1.195503852","rc":[{"atl":[[12.5,0]],"id":28338255},{"atl":[[13,0]],"id":26051221}],"con":true,"img":false}]}
{"op":"mcm","clk":"5353403352","pt":1646214334055,"mc":[{"id":"1.195503852","rc":[{"atl":[[6.6,0]],"id":28338255}],"con":true,"img":false}]}
{"op":"mcm","clk":"5353403358","pt":1646214334157,"mc":[{"id":"1.195503852","rc":[{"atl":[[5.9,6]],"id":28338255}],"con":true,"img":false}]}
{"op":"mcm","clk":"5353403418","pt":1646214335249,"mc":[{"id":"1.195503852","rc":[{"atb":[[1.31,1.42]],"id":26051221}],"con":true,"img":false}]}
{"op":"mcm","clk":"5353403442","pt":1646214335671,"mc":[{"id":"1.195503852","rc":[{"atl":[[1.7,2],[1.71,0]],"id":26051221}],"con":true,"img":false}]}
{"op":"mcm","clk":"5353403507","pt":1646214336454,"mc":[{"id":"1.195503852","rc":[{"atb":[[1.27,0]],"id":26051221},{"atl":[[13.5,0],[14,0]],"id":26051221},{"atl":[[13,0]],"id":28338255}],"con":true,"img":false}]}
{"op":"mcm","clk":"5353403779","pt":1646214339974,"mc":[{"id":"1.195503852","rc":[{"atb":[[1.26,0],[1.32,0]],"id":26051221},{"atl":[[14.5,0]],"id":26051221},{"atl":[[13.5,0],[14,0]],"id":28338255}],"con":true,"img":false}]}
{"op":"mcm","clk":"5353403826","pt":1646214340554,"mc":[{"id":"1.195503852","rc":[{"atl":[[5.9,4],[5.7,2]],"id":28338255}],"con":true,"img":false}]}
{"op":"mcm","clk":"5353403847","pt":1646214340862,"mc":[{"id":"1.195503852","rc":[{"atl":[[5.9,0]],"id":28338255}],"con":true,"img":false}]}
{"op":"mcm","clk":"5353403853","pt":1646214340962,"mc":[{"id":"1.195503852","rc":[{"atl":[[5.7,6]],"id":28338255}],"con":true,"img":false}]}
{"op":"mcm","clk":"5353404035","pt":1646214343564,"mc":[{"id":"1.195503852","rc":[{"atl":[[14.5,0]],"id":28338255},{"atb":[[1.14,0],[1.34,0]],"id":26051221},{"atl":[[15,0]],"id":26051221}],"con":true,"img":false}]}
{"op":"mcm","clk":"5353404084","pt":1646214344179,"mc":[{"id":"1.195503852","rc":[{"atl":[[5.7,2]],"id":28338255},{"atb":[[1.35,3.42]],"id":26051221},{"atl":[[1.68,33]],"id":26051221}],"con":true,"img":false}]}
{"op":"mcm","clk":"5353404127","pt":1646214344749,"mc":[{"id":"1.195503852","rc":[{"atb":[[1.35,10.26]],"id":26051221},{"atl":[[1.68,47.33]],"id":26051221},{"atl":[[5.7,6]],"id":28338255}],"con":true,"img":false}]}
{"op":"mcm","clk":"5353404284","pt":1646214346879,"mc":[{"id":"1.195503852","rc":[{"atb":[[2.76,7.9]],"id":28338255}],"con":true,"img":false}]}
{"op":"mcm","clk":"5353404323","pt":1646214347352,"mc":[{"id":"1.195503852","rc":[{"atl":[[15.5,0]],"id":26051221}],"con":true,"img":false}]}
{"op":"mcm","clk":"5353404409","pt":1646214348592,"mc":[{"id":"1.195503852","rc":[{"atb":[[2.76,3.06]],"id":28338255}],"con":true,"img":false}]}
{"op":"mcm","clk":"5353404548","pt":1646214350611,"mc":[{"id":"1.195503852","rc":[{"atl":[[15,0]],"id":28338255},{"atb":[[1.25,0]],"id":26051221},{"atl":[[16,0]],"id":26051221}],"con":true,"img":false}]}
{"op":"mcm","clk":"5353404641","pt":1646214351901,"mc":[{"id":"1.195503852","rc":[{"atl":[[1.7,0],[1.71,2]],"id":26051221}],"con":true,"img":false}]}
{"op":"mcm","clk":"5353404672","pt":1646214352379,"mc":[{"id":"1.195503852","rc":[{"atl":[[20,1.42]],"id":28338255}],"con":true,"img":false}]}
{"op":"mcm","clk":"5353404759","pt":1646214353396,"mc":[{"id":"1.195503852","rc":[{"atl":[[15.5,0]],"id":28338255}],"con":true,"img":false}]}
{"op":"mcm","clk":"5353404999","pt":1646214356969,"mc":[{"id":"1.195503852","rc":[{"atl":[[1.7,2],[1.71,0]],"id":26051221}],"con":true,"img":false}]}
{"op":"mcm","clk":"5353405040","pt":1646214357602,"mc":[{"id":"1.195503852","rc":[{"atb":[[1.01,0],[1.02,0],[1.22,0]],"id":26051221},{"atb":[[2.36,0],[1.98,0],[2.76,0]],"id":28338255}],"con":true,"img":false}]}
{"op":"mcm","clk":"5353405055","pt":1646214357910,"mc":[{"id":"1.195503852","rc":[{"atb":[[2.48,6]],"id":28338255}],"con":true,"img":false}]}
{"op":"mcm","clk":"5353405061","pt":1646214358114,"mc":[{"id":"1.195503852","rc":[{"atl":[[21,1.42]],"id":28338255}],"con":true,"img":false}]}
{"op":"mcm","clk":"5353405141","pt":1646214359198,"mc":[{"id":"1.195503852","rc":[{"atl":[[5.7,4],[5.4,2]],"id":28338255}],"con":true,"img":false}]}
{"op":"mcm","clk":"5353405146","pt":1646214359302,"mc":[{"id":"1.195503852","rc":[{"atl":[[16,0]],"id":28338255}],"con":true,"img":false}]}
{"op":"mcm","clk":"5353405164","pt":1646214359613,"mc":[{"id":"1.195503852","rc":[{"atl":[[5.6,2],[5.4,0]],"id":28338255}],"con":true,"img":false}]}
{"op":"mcm","clk":"5353405178","pt":1646214359931,"mc":[{"id":"1.195503852","rc":[{"atl":[[5.7,0]],"id":28338255}],"con":true,"img":false}]}
{"op":"mcm","clk":"5353405189","pt":1646214360027,"mc":[{"id":"1.195503852","rc":[{"atl":[[5.6,6]],"id":28338255}],"con":true,"img":false}]}
{"op":"mcm","clk":"5353405293","pt":1646214361333,"mc":[{"id":"1.195503852","rc":[{"atl":[[21,2.84]],"id":28338255}],"con":true,"img":false}]}
{"op":"mcm","clk":"5353405370","pt":1646214362525,"mc":[{"id":"1.195503852","rc":[{"atl":[[16.5,0]],"id":28338255},{"atb":[[1.3,15],[1.31,0]],"id":26051221}],"con":true,"img":false}]}
{"op":"mcm","clk":"5353405391","pt":1646214362844,"mc":[{"id":"1.195503852","rc":[{"atb":[[1.35,10.06]],"id":26051221},{"trd":[[1.35,0.4]],"ltp":1.35,"tv":0.4,"id":26051221}],"con":true,"img":false}]}
{"op":"mcm","clk":"5353405506","pt":1646214364540,"mc":[{"id":"1.195503852","rc":[{"atl":[[16,1.42]],"id":26051221},{"atl":[[22,1.42]],"id":28338255}],"con":true,"img":false}]}
{"op":"mcm","clk":"5353405517","pt":1646214364741,"mc":[{"id":"1.195503852","rc":[{"atl":[[5.6,4],[5.3,2]],"id":28338255}],"con":true,"img":false}]}
{"op":"mcm","clk":"5353405707","pt":1646214367947,"mc":[{"id":"1.195503852","rc":[{"atl":[[16.5,1.42]],"id":28338255},{"atl":[[15.5,1.42]],"id":26051221}],"con":true,"img":false}]}
{"op":"mcm","clk":"5353405841","pt":1646214369926,"mc":[{"id":"1.195503852","rc":[{"atl":[[5.3,0],[5.5,2]],"id":28338255}],"con":true,"img":false}]}
{"op":"mcm","clk":"5353405863","pt":1646214370231,"mc":[{"id":"1.195503852","rc":[{"atl":[[5.6,0]],"id":28338255}],"con":true,"img":false}]}
{"op":"mcm","clk":"5353405870","pt":1646214370334,"mc":[{"id":"1.195503852","rc":[{"atl":[[5.5,6]],"id":28338255}],"con":true,"img":false}]}
{"op":"mcm","clk":"5353405897","pt":1646214370746,"mc":[{"id":"1.195503852","rc":[{"atl":[[16,1.42]],"id":28338255},{"atl":[[15,1.42]],"id":26051221}],"con":true,"img":false}]}
{"op":"mcm","clk":"5353406026","pt":1646214372724,"mc":[{"id":"1.195503852","rc":[{"atl":[[15.5,1.42]],"id":28338255},{"atl":[[14.5,1.42]],"id":26051221}],"con":true,"img":false}]}
{"op":"mcm","clk":"5353406243","pt":1646214375155,"mc":[{"id":"1.195503852","rc":[{"atl":[[5,2],[5.5,4]],"id":28338255}],"con":true,"img":false}]}
{"op":"mcm","clk":"5353406356","pt":1646214376346,"mc":[{"id":"1.195503852","rc":[{"atl":[[15,1.42]],"id":28338255},{"atl":[[14,1.42]],"id":26051221}],"con":true,"img":false}]}
{"op":"mcm","clk":"5353406396","pt":1646214376818,"mc":[{"id":"1.195503852","rc":[{"atl":[[1.71,2]],"id":26051221}],"con":true,"img":false}]}
{"op":"mcm","clk":"5353406407","pt":1646214376931,"mc":[{"id":"1.195503852","rc":[{"atl":[[1.7,0]],"id":26051221},{"atb":[[2.46,2],[2.48,4]],"id":28338255}],"con":true,"img":false}]}
{"op":"mcm","clk":"5353406426","pt":1646214377237,"mc":[{"id":"1.195503852","rc":[{"atb":[[2.48,0]],"id":28338255}],"con":true,"img":false}]}
{"op":"mcm","clk":"5353406458","pt":1646214377651,"mc":[{"id":"1.195503852","rc":[{"atb":[[2.46,6]],"id":28338255}],"con":true,"img":false}]}
{"op":"mcm","clk":"5353406509","pt":1646214378472,"mc":[{"id":"1.195503852","rc":[{"atb":[[2.9,2.83],[2.5,3.59],[2.1,4.9]],"id":28338255},{"atb":[[1.01,1079.07],[1.17,31.74]],"id":26051221}],"con":true,"img":false}]}
{"op":"mcm","clk":"5353406542","pt":1646214378943,"mc":[{"id":"1.195503852","rc":[{"atb":[[1.36,1.42]],"id":26051221},{"atl":[[13.5,1.42]],"id":26051221},{"atl":[[14.5,1.42]],"id":28338255}],"con":true,"img":false}]}
{"op":"mcm","clk":"5353406564","pt":1646214379258,"mc":[{"id":"1.195503852","rc":[{"atb":[[1.35,3.22]],"id":26051221}],"con":true,"img":false}]}
{"op":"mcm","clk":"5353406573","pt":1646214379365,"mc":[{"id":"1.195503852","rc":[{"atb":[[1.36,8.26]],"id":26051221}],"con":true,"img":false}]}
{"op":"mcm","clk":"5353406587","pt":1646214379569,"mc":[{"id":"1.195503852","rc":[{"atb":[[1.37,2],[1.35,1.22]],"id":26051221}],"con":true,"img":false}]}
{"op":"mcm","clk":"5353406591","pt":1646214379613,"mc":[{"id":"1.195503852","rc":[{"atb":[[1.36,4.26]],"id":26051221}],"con":true,"img":false}]}
{"op":"mcm","clk":"5353406613","pt":1646214379942,"mc":[{"id":"1.195503852","rc":[{"atb":[[1.36,1.42]],"id":26051221}],"con":true,"img":false}]}
{"op":"mcm","clk":"5353406636","pt":1646214380251,"mc":[{"id":"1.195503852","rc":[{"atb":[[1.37,6]],"id":26051221},{"atl":[[5,0]],"id":28338255}],"con":true,"img":false}]}
{"op":"mcm","clk":"5353406643","pt":1646214380356,"mc":[{"id":"1.195503852","rc":[{"atl":[[4.9,2]],"id":28338255}],"con":true,"img":false}]}
{"op":"mcm","clk":"5353406664","pt":1646214380655,"mc":[{"id":"1.195503852","rc":[{"atl":[[5.5,0]],"id":28338255}],"con":true,"img":false}]}
{"op":"mcm","clk":"5353406680","pt":1646214380861,"mc":[{"id":"1.195503852","rc":[{"atl":[[14,1.42]],"id":28338255}],"con":true,"img":false}]}
{"op":"mcm","clk":"5353406688","pt":1646214380962,"mc":[{"id":"1.195503852","rc":[{"atl":[[4.9,6]],"id":28338255}],"con":true,"img":false}]}
{"op":"mcm","clk":"5353406776","pt":1646214382150,"mc":[{"id":"1.195503852","rc":[{"atb":[[1.36,0],[1.35,0]],"id":26051221}],"con":true,"img":false}]}
{"op":"mcm","clk":"5353406908","pt":1646214384168,"mc":[{"id":"1.195503852","rc":[{"atb":[[1.32,1.42]],"id":26051221},{"atl":[[13,1.42]],"id":28338255}],"con":true,"img":false}]}
{"op":"mcm","clk":"5353406964","pt":1646214384943,"mc":[{"id":"1.195503852","rc":[{"atl":[[13.5,0]],"id":26051221}],"con":true,"img":false}]}
{"op":"mcm","clk":"5353406987","pt":1646214385457,"mc":[{"id":"1.195503852","rc":[{"atl":[[4.9,4],[4.5,2]],"id":28338255}],"con":true,"img":false}]}
{"op":"mcm","clk":"5353407094","pt":1646214387058,"mc":[{"id":"1.195503852","rc":[{"atl":[[13.5,1.42]],"id":28338255},{"atb":[[1.31,1.42]],"id":26051221},{"atl":[[1.71,0],[1.72,2]],"id":26051221}],"con":true,"img":false}]}
{"op":"mcm","clk":"5353407140","pt":1646214387778,"mc":[{"id":"1.195503852","rc":[{"atl":[[13,0]],"id":28338255}],"con":true,"img":false}]}
{"op":"mcm","clk":"5353407356","pt":1646214390672,"mc":[{"id":"1.195503852","rc":[{"atl":[[13.5,0],[14,0]],"id":28338255},{"atl":[[14,0],[14.5,0]],"id":26051221}],"con":true,"img":false}]}
{"op":"mcm","clk":"5353407432","pt":1646214391665,"mc":[{"id":"1.195503852","rc":[{"atl":[[4.5,0],[4.6,2]],"id":28338255}],"con":true,"img":false}]}
{"op":"mcm","clk":"5353407470","pt":1646214392084,"mc":[{"id":"1.195503852","rc":[{"atl":[[4.6,0],[4.7,2]],"id":28338255}],"con":true,"img":false}]}
{"op":"mcm","clk":"5353407494","pt":1646214392385,"mc":[{"id":"1.195503852","rc":[{"atb":[[1.04,1.45]],"id":28338255},{"atl":[[1000,1.45]],"id":28338255}],"con":true,"img":false}]}
{"op":"mcm","clk":"5353407511","pt":1646214392595,"mc":[{"id":"1.195503852","rc":[{"atb":[[1.04,0.05]],"id":28338255},{"atl":[[1000,0.03]],"id":28338255}],"con":true,"img":false}]}
{"op":"mcm","clk":"5353407525","pt":1646214392701,"mc":[{"id":"1.195503852","rc":[{"atb":[[1.04,0]],"id":28338255},{"atl":[[1000,0]],"id":28338255}],"con":true,"img":false}]}
{"op":"mcm","clk":"5353407534","pt":1646214392803,"mc":[{"id":"1.195503852","rc":[{"atl":[[3.7,0.03]],"id":28338255},{"trd":[[3.75,0.05]],"ltp":3.75,"tv":0.05,"id":28338255},{"atb":[[1.37,5.84]],"id":26051221},{"trd":[[1.37,0.16]],"ltp":1.37,"tv":0.16,"id":26051221}],"con":true,"img":false}]}
{"op":"mcm","clk":"5353407551","pt":1646214392971,"mc":[{"id":"1.195503852","rc":[{"atb":[[1.37,4]],"id":26051221}],"con":true,"img":false}]}
{"op":"mcm","clk":"5353407568","pt":1646214393179,"mc":[{"id":"1.195503852","rc":[{"atl":[[4.9,0]],"id":28338255}],"con":true,"img":false}]}
{"op":"mcm","clk":"5353407579","pt":1646214393281,"mc":[{"id":"1.195503852","rc":[{"atl":[[4.7,6]],"id":28338255},{"atb":[[1.37,0]],"id":26051221}],"con":true,"img":false}]}
{"op":"mcm","clk":"5353407621","pt":1646214393690,"mc":[{"id":"1.195503852","rc":[{"atl":[[14.5,0]],"id":28338255},{"atb":[[1.32,4.26]],"id":26051221},{"atl":[[15,0]],"id":26051221}],"con":true,"img":false}]}
{"op":"mcm","clk":"5353407640","pt":1646214393897,"mc":[{"id":"1.195503852","rc":[{"atl":[[1000,0.07]],"id":28338255}],"con":true,"img":false}]}
{"op":"mcm","clk":"5353407657","pt":1646214394061,"mc":[{"id":"1.195503852","rc":[{"atl":[[1000,0]],"id":28338255}],"con":true,"img":false}]}
{"op":"mcm","clk":"5353407667","pt":1646214394168,"mc":[{"id":"1.195503852","rc":[{"atb":[[2.9,2.76]],"id":28338255},{"trd":[[2.9,0.14]],"ltp":2.9,"tv":0.14,"id":28338255}],"con":true,"img":false}]}
{"op":"mcm","clk":"5353407774","pt":1646214395612,"mc":[{"id":"1.195503852","rc":[{"atb":[[2.46,2]],"id":28338255},{"atl":[[4.7,2]],"id":28338255},{"atb":[[1.32,1.42]],"id":26051221},{"atl":[[1.68,33]],"id":26051221}],"con":true,"img":false}]}
{"op":"mcm","clk":"5353407794","pt":1646214395772,"mc":[{"id":"1.195503852","rc":[{"atl":[[3.2,24.52]],"id":28338255}],"con":true,"img":false}]}
{"op":"mcm","clk":"5353407815","pt":1646214396088,"mc":[{"id":"1.195503852","rc":[{"atl":[[15,0],[3.2,31.59]],"id":28338255},{"atb":[[1.32,4.26]],"id":26051221},{"atl":[[1.68,49.55],[15.5,0]],"id":26051221}],"con":true,"img":false}]}
{"op":"mcm","clk":"5353407884","pt":1646214397173,"mc":[{"id":"1.195503852","rc":[{"atl":[[3.15,2],[4.7,0]],"id":28338255}],"con":true,"img":false}]}
{"op":"mcm","clk":"5353407916","pt":1646214397588,"mc":[{"id":"1.195503852","rc":[{"atl":[[3.2,24.52]],"id":28338255}],"con":true,"img":false}]}
{"op":"mcm","clk":"5353407921","pt":1646214397692,"mc":[{"id":"1.195503852","rc":[{"atl":[[3.15,9.07]],"id":28338255}],"con":true,"img":false}]}
{"op":"mcm","clk":"5353407941","pt":1646214398004,"mc":[{"id":"1.195503852","rc":[{"atb":[[1.33,1.42]],"id":26051221}],"con":true,"img":false}]}
{"op":"mcm","clk":"5353407970","pt":1646214398364,"mc":[{"id":"1.195503852","rc":[{"atb":[[1.32,1.42]],"id":26051221}],"con":true,"img":false}]}
{"op":"mcm","clk":"5353407977","pt":1646214398469,"mc":[{"id":"1.195503852","rc":[{"atb":[[1.33,4.26]],"id":26051221}],"con":true,"img":false}]}
{"op":"mcm","clk":"5353408013","pt":1646214399086,"mc":[{"id":"1.195503852","rc":[{"atb":[[1.32,0],[1.31,0]],"id":26051221},{"atl":[[16,0],[16.5,0],[17,0]],"id":26051221},{"atl":[[15.5,0],[1000,0.07],[16,0],[16.5,0]],"id":28338255}],"con":true,"img":false}]}
{"op":"mcm","clk":"5353408025","pt":1646214399299,"mc":[{"id":"1.195503852","rc":[{"atl":[[1000,0]],"id":28338255}],"con":true,"img":false}]}
{"op":"mcm","clk":"5353408035","pt":1646214399395,"mc":[{"id":"1.195503852","rc":[{"atb":[[2.9,2.69]],"id":28338255},{"trd":[[2.9,0.28]],"ltp":2.9,"tv":0.28,"id":28338255}],"con":true,"img":false}]}
{"op":"mcm","clk":"5353408058","pt":1646214399761,"mc":[{"id":"1.195503852","rc":[{"atb":[[2.48,19.71]],"id":28338255},{"atb":[[1.43,67.85]],"id":26051221}],"con":true,"img":false}]}
{"op":"mcm","clk":"5353408070","pt":1646214399871,"mc":[{"id":"1.195503852","rc":[{"atl":[[3.2,0]],"id":28338255}],"con":true,"img":false}]}
{"op":"mcm","clk":"5353408076","pt":1646214399972,"mc":[{"id":"1.195503852","rc":[{"atb":[[2.9,0]],"id":28338255},{"atl":[[2.9,21.82]],"id":28338255},{"trd":[[2.9,5.67]],"ltp":2.9,"tv":5.67,"id":28338255}],"con":true,"img":false}]}
{"op":"mcm","clk":"5353408080","pt":1646214400076,"mc":[{"id":"1.195503852","rc":[{"atb":[[2.46,0]],"id":28338255}],"con":true,"img":false}]}
{"op":"mcm","clk":"5353408086","pt":1646214400186,"mc":[{"id":"1.195503852","rc":[{"atb":[[2.44,2]],"id":28338255}],"con":true,"img":false}]}
{"op":"mcm","clk":"5353408093","pt":1646214400289,"mc":[{"id":"1.195503852","rc":[{"atb":[[2.5,10.79]],"id":28338255},{"atb":[[1.43,0]],"id":26051221}],"con":true,"img":false}]}
{"op":"mcm","clk":"5353408124","pt":1646214400835,"mc":[{"id":"1.195503852","rc":[{"atb":[[1.47,62.07]],"id":26051221}],"con":true,"img":false}]}
{"op":"mcm","clk":"5353408140","pt":1646214401003,"mc":[{"id":"1.195503852","rc":[{"atb":[[1.46,1.42]],"id":26051221},{"atl":[[24,1.42]],"id":26051221},{"atl":[[23,1.42]],"id":28338255}],"con":true,"img":false}]}
{"op":"mcm","clk":"5353408180","pt":1646214401478,"mc":[{"id":"1.195503852","rc":[{"atl":[[1.73,2],[1.72,0]],"id":26051221}],"con":true,"img":false}]}
{"op":"mcm","clk":"5353408217","pt":1646214402096,"mc":[{"id":"1.195503852","rc":[{"atb":[[1.33,2.84]],"id":26051221},{"atl":[[17.5,0],[18,0],[18.5,0]],"id":26051221},{"atl":[[17,0],[17.5,0]],"id":28338255}],"con":true,"img":false}]}
{"op":"mcm","clk":"5353408238","pt":1646214402774,"mc":[{"id":"1.195503852","rc":[{"atl":[[2.88,2],[3.15,7.07]],"id":28338255}],"con":true,"img":false}]}
{"op":"mcm","clk":"5353408376","pt":1646214404208,"mc":[{"id":"1.195503852","rc":[{"atb":[[2.5,0],[2.48,7.51]],"id":28338255},{"trd":[[2.48,24.4],[2.5,21.59]],"ltp":2.48,"tv":45.98,"id":28338255}],"con":true,"img":false}]}
{"op":"mcm","clk":"5353408405","pt":1646214404512,"mc":[{"id":"1.195503852","rc":[{"atl":[[23,2.84]],"id":28338255},{"atb":[[1.56,1.42]],"id":26051221},{"atl":[[24,2.84]],"id":26051221}],"con":true,"img":false}]}
{"op":"mcm","clk":"5353408420","pt":1646214404680,"mc":[{"id":"1.195503852","rc":[{"atb":[[1.56,0.58]],"id":26051221},{"trd":[[1.56,1.66]],"ltp":1.56,"tv":1.66,"id":26051221}],"con":true,"img":false}]}
{"op":"mcm","clk":"5353408439","pt":1646214404888,"mc":[{"id":"1.195503852","rc":[{"atb":[[1.52,2]],"id":26051221}],"con":true,"img":false}]}
{"op":"mcm","clk":"5353408495","pt":1646214405408,"mc":[{"id":"1.195503852","rc":[{"atb":[[2.42,2],[2.44,0]],"id":28338255}],"con":true,"img":false}]}
{"op":"mcm","clk":"5353408501","pt":1646214405511,"mc":[{"id":"1.195503852","rc":[{"atb":[[2.48,16.96]],"id":28338255}],"con":true,"img":false}]}
{"op":"mcm","clk":"5353408542","pt":1646214405876,"mc":[{"id":"1.195503852","rc":[{"atl":[[2.9,0]],"id":28338255}],"con":true,"img":false}]}
{"op":"mcm","clk":"5353408551","pt":1646214405979,"mc":[{"id":"1.195503852","rc":[{"atl":[[18,0],[18.5,0],[19,0],[19.5,0],[2.7,21.82]],"id":28338255},{"atb":[[1.46,0]],"id":26051221},{"atl":[[19,0],[19.5,0],[20,0]],"id":26051221}],"con":true,"img":false}]}
{"op":"mcm","clk":"5353408640","pt":1646214407311,"mc":[{"id":"1.195503852","rc":[{"atb":[[1.56,2.01]],"id":26051221},{"atl":[[25,1.42]],"id":26051221},{"atl":[[24,1.42]],"id":28338255}],"con":true,"img":false}]}
{"op":"mcm","clk":"5353408652","pt":1646214407517,"mc":[{"id":"1.195503852","rc":[{"atl":[[2.88,0],[2.76,2]],"id":28338255}],"con":true,"img":false}]}
{"op":"mcm","clk":"5353408675","pt":1646214407892,"mc":[{"id":"1.195503852","rc":[{"atl":[[1000,0.07]],"id":28338255}],"con":true,"img":false}]}
{"op":"mcm","clk":"5353408692","pt":1646214408097,"mc":[{"id":"1.195503852","rc":[{"atl":[[1000,0]],"id":28338255}],"con":true,"img":false}]}
{"op":"mcm","clk":"5353408702","pt":1646214408204,"mc":[{"id":"1.195503852","rc":[{"atb":[[2.48,16.89]],"id":28338255},{"trd":[[2.48,24.54]],"ltp":2.48,"tv":24.54,"id":28338255}],"con":true,"img":false}]}
{"op":"mcm","clk":"5353408721","pt":1646214408413,"mc":[{"id":"1.195503852","rc":[{"atb":[[2.48,7.44]],"id":28338255},{"atl":[[3.15,0]],"id":28338255},{"atb":[[1.33,0]],"id":26051221},{"atl":[[1.68,33]],"id":26051221}],"con":true,"img":false}]}
{"op":"mcm","clk":"5353408747","pt":1646214408817,"mc":[{"id":"1.195503852","rc":[{"atb":[[1.47,0]],"id":26051221},{"atb":[[2.48,0]],"id":28338255}],"con":true,"img":false}]}
{"op":"mcm","clk":"5353408761","pt":1646214409024,"mc":[{"id":"1.195503852","rc":[{"atb":[[2.48,10.08]],"id":28338255},{"atl":[[1.68,48.38]],"id":26051221}],"con":true,"img":false}]}
{"op":"mcm","clk":"5353408774","pt":1646214409197,"mc":[{"id":"1.195503852","rc":[{"atb":[[1.56,1.42]],"id":26051221},{"atl":[[21,0],[22,0]],"id":26051221},{"atl":[[20,0],[21,0],[22,0]],"id":28338255}],"con":true,"img":false}]}
{"op":"mcm","clk":"5353408780","pt":1646214409298,"mc":[{"id":"1.195503852","rc":[{"atb":[[2.48,0]],"id":28338255}],"con":true,"img":false}]}
{"op":"mcm","clk":"5353408786","pt":1646214409396,"mc":[{"id":"1.195503852","rc":[{"atb":[[2.42,12.08]],"id":28338255}],"con":true,"img":false}]}
{"op":"mcm","clk":"5353408807","pt":1646214409704,"mc":[{"id":"1.195503852","rc":[{"atb":[[2.42,2]],"id":28338255}],"con":true,"img":false}]}
{"op":"mcm","clk":"5353408815","pt":1646214409804,"mc":[{"id":"1.195503852","rc":[{"atl":[[1000,1.69]],"id":28338255}],"con":true,"img":false}]}
{"op":"mcm","clk":"5353408828","pt":1646214410012,"mc":[{"id":"1.195503852","rc":[{"atb":[[2.42,6]],"id":28338255},{"atl":[[2.7,0],[1000,0.02]],"id":28338255}],"con":true,"img":false}]}
{"op":"mcm","clk":"5353408833","pt":1646214410110,"mc":[{"id":"1.195503852","rc":[{"atl":[[2.5,21.82]],"id":28338255}],"con":true,"img":false}]}
{"op":"mcm","clk":"5353408840","pt":1646214410213,"mc":[{"id":"1.195503852","rc":[{"atl":[[1000,0]],"id":28338255}],"con":true,"img":false}]}
{"op":"mcm","clk":"5353408845","pt":1646214410318,"mc":[{"id":"1.195503852","rc":[{"atl":[[2.56,0.02],[2.5,0]],"id":28338255},{"trd":[[2.5,65.25]],"ltp":2.5,"tv":65.25,"id":28338255},{"atb":[[1.53,2],[1.52,0]],"id":26051221}],"con":true,"img":false}]}
{"op":"mcm","clk":"5353408952","pt":1646214412028,"mc":[{"id":"1.195503852","rc":[{"atl":[[23,0],[24,0]],"id":28338255},{"atb":[[1.56,0]],"id":26051221},{"atl":[[23,0],[24,0],[25,0]],"id":26051221}],"con":true,"img":false}]}
{"op":"mcm","clk":"5353408974","pt":1646214412445,"mc":[{"id":"1.195503852","rc":[{"atl":[[2.5,5.44]],"id":28338255}],"con":true,"img":false}]}
{"op":"mcm","clk":"5353408984","pt":1646214412609,"mc":[{"id":"1.195503852","rc":[{"atl":[[2.5,0.01]],"id":28338255},{"trd":[[2.5,76.12]],"ltp":2.5,"tv":76.12,"id":28338255}],"con":true,"img":false}]}
{"op":"mcm","clk":"5353408989","pt":1646214412712,"mc":[{"id":"1.195503852","rc":[{"atl":[[2.56,0],[2.5,0]],"id":28338255},{"trd":[[2.56,0.05],[2.5,76.15]],"ltp":2.56,"tv":76.2,"id":28338255}],"con":true,"img":false}]}
{"op":"mcm","clk":"5353409003","pt":1646214412917,"mc":[{"id":"1.195503852","rc":[{"atl":[[3.7,2.03],[2.76,0]],"id":28338255}],"con":true,"img":false}]}
{"op":"mcm","clk":"5353409022","pt":1646214413228,"mc":[{"id":"1.195503852","rc":[{"atl":[[3.7,6.09]],"id":28338255}],"con":true,"img":false}]}
{"op":"mcm","clk":"5353409043","pt":1646214413497,"mc":[{"id":"1.195503852","rc":[{"atl":[[28,1.42]],"id":28338255},{"atl":[[32,1.42]],"id":26051221}],"con":true,"img":false}]}
{"op":"mcm","clk":"5353409055","pt":1646214413704,"mc":[{"id":"1.195503852","rc":[{"atb":[[2.18,4.78]],"id":28338255}],"con":true,"img":false}]}
{"op":"mcm","clk":"5353409075","pt":1646214414009,"mc":[{"id":"1.195503852","rc":[{"atl":[[2.7,5.44]],"id":28338255}],"con":true,"img":false}]}
{"op":"mcm","clk":"5353409080","pt":1646214414116,"mc":[{"id":"1.195503852","rc":[{"atl":[[2.7,0]],"id":28338255},{"trd":[[2.7,10.89]],"ltp":2.7,"tv":10.89,"id":28338255}],"con":true,"img":false}]}
{"op":"mcm","clk":"5353409090","pt":1646214414216,"mc":[{"id":"1.195503852","rc":[{"atl":[[3.7,4.09],[2.76,2]],"id":28338255}],"con":true,"img":false}]}
{"op":"mcm","clk":"5353409176","pt":1646214415512,"mc":[{"id":"1.195503852","rc":[{"atb":[[1.53,0],[1.31,2]],"id":26051221}],"con":true,"img":false}]}
{"op":"mcm","clk":"5353409196","pt":1646214415822,"mc":[{"id":"1.195503852","rc":[{"atb":[[1.31,6]],"id":26051221}],"con":true,"img":false}]}
{"op":"mcm","clk":"5353409223","pt":1646214416129,"mc":[{"id":"1.195503852","rc":[{"atb":[[1.41,11.27]],"id":26051221}],"con":true,"img":false}]}
{"op":"mcm","clk":"5353409231","pt":1646214416234,"mc":[{"id":"1.195503852","rc":[{"atb":[[2.18,0]],"id":28338255}],"con":true,"img":false}]}
{"op":"mcm","clk":"5353409238","pt":1646214416295,"mc":[{"id":"1.195503852","rc":[{"atb":[[2.14,4.78]],"id":28338255},{"atb":[[1.42,2],[1.31,4]],"id":26051221}],"con":true,"img":false}]}
{"op":"mcm","clk":"5353409244","pt":1646214416398,"mc":[{"id":"1.195503852","rc":[{"atb":[[1.31,0]],"id":26051221}],"con":true,"img":false}]}
{"op":"mcm","clk":"5353409260","pt":1646214416714,"mc":[{"id":"1.195503852","rc":[{"atb":[[1.42,6]],"id":26051221}],"con":true,"img":false}]}
{"op":"mcm","clk":"5353409270","pt":1646214416916,"mc":[{"id":"1.195503852","rc":[{"atl":[[34,1.42]],"id":26051221},{"atl":[[30,1.36]],"id":28338255}],"con":true,"img":false}]}
{"op":"mcm","clk":"5353409295","pt":1646214417326,"mc":[{"id":"1.195503852","rc":[{"atb":[[2.4,2],[2.42,4]],"id":28338255},{"atl":[[1.73,0],[1.74,2]],"id":26051221}],"con":true,"img":false}]}
{"op":"mcm","clk":"5353409314","pt":1646214417630,"mc":[{"id":"1.195503852","rc":[{"atb":[[2.42,0]],"id":28338255},{"atl":[[28,0]],"id":28338255}],"con":true,"img":false}]}
{"op":"mcm","clk":"5353409336","pt":1646214418046,"mc":[{"id":"1.195503852","rc":[{"atb":[[2.4,6]],"id":28338255}],"con":true,"img":false}]}
{"op":"mcm","clk":"5353409429","pt":1646214419340,"mc":[{"id":"1.195503852","rc":[{"atl":[[3.65,2],[2.76,0]],"id":28338255}],"con":true,"img":false}]}
{"op":"mcm","clk":"5353409450","pt":1646214419607,"mc":[{"id":"1.195503852","rc":[{"atl":[[3.7,0.03]],"id":28338255}],"con":true,"img":false}]}
{"op":"mcm","clk":"5353409462","pt":1646214419714,"mc":[{"id":"1.195503852","rc":[{"atl":[[3.65,6.06]],"id":28338255},{"trd":[[2.46,5.99]],"ltp":2.46,"tv":5.99,"id":28338255},{"atl":[[1.68,39.6]],"id":26051221},{"trd":[[1.68,8.78]],"ltp":1.68,"tv":8.78,"id":26051221}],"con":true,"img":false}]}
{"op":"mcm","clk":"5353409466","pt":1646214419816,"mc":[{"id":"1.195503852","rc":[{"atl":[[3.95,2],[3.65,4.06]],"id":28338255}],"con":true,"img":false}]}
{"op":"mcm","clk":"5353409471","pt":1646214419919,"mc":[{"id":"1.195503852","rc":[{"atl":[[32,1.27]],"id":28338255},{"atl":[[36,1.41]],"id":26051221}],"con":true,"img":false}]}
{"op":"mcm","clk":"5353409482","pt":1646214420136,"mc":[{"id":"1.195503852","rc":[{"atl":[[3.65,0]],"id":28338255}],"con":true,"img":false}]}
{"op":"mcm","clk":"5353409506","pt":1646214420434,"mc":[{"id":"1.195503852","rc":[{"atl":[[30,0]],"id":28338255}],"con":true,"img":false}]}
{"op":"mcm","clk":"5353409516","pt":1646214420537,"mc":[{"id":"1.195503852","rc":[{"atl":[[3.95,6.06]],"id":28338255}],"con":true,"img":false}]}
{"op":"mcm","clk":"5353409534","pt":1646214420804,"mc":[{"id":"1.195503852","rc":[{"atb":[[2.42,6.88]],"id":28338255},{"atl":[[3.7,6.78]],"id":28338255},{"atb":[[1.43,13.01]],"id":26051221},{"atl":[[1.67,12.82]],"id":26051221}],"con":true,"img":false}]}
{"op":"mcm","clk":"5353409552","pt":1646214421110,"mc":[{"id":"1.195503852","rc":[{"atb":[[1.42,2]],"id":26051221},{"atl":[[1.68,24.22]],"id":26051221},{"atb":[[2.4,2]],"id":28338255}],"con":true,"img":false}]}
{"op":"mcm","clk":"5353409556","pt":1646214421219,"mc":[{"id":"1.195503852","rc":[{"atl":[[1.67,28.2]],"id":26051221}],"con":true,"img":false}]}
{"op":"mcm","clk":"5353409568","pt":1646214421430,"mc":[{"id":"1.195503852","rc":[{"atb":[[1.43,37.02]],"id":26051221},{"atb":[[2.42,18.06]],"id":28338255}],"con":true,"img":false}]}
{"op":"mcm","clk":"5353409575","pt":1646214421530,"mc":[{"id":"1.195503852","rc":[{"atb":[[1.44,2],[1.42,0]],"id":26051221},{"atl":[[1.66,12.86]],"id":26051221}],"con":true,"img":false}]}
{"op":"mcm","clk":"5353409592","pt":1646214421758,"mc":[{"id":"1.195503852","rc":[{"atb":[[1.44,14.99]],"id":26051221},{"atb":[[2.44,6.87]],"id":28338255}],"con":true,"img":false}]}
{"op":"mcm","clk":"5353409601","pt":1646214421834,"mc":[{"id":"1.195503852","rc":[{"atb":[[1.43,13.01]],"id":26051221},{"atl":[[1.67,12.82]],"id":26051221},{"atb":[[2.5,19.44]],"id":28338255}],"con":true,"img":false}]}
{"op":"mcm","clk":"5353409609","pt":1646214421943,"mc":[{"id":"1.195503852","rc":[{"atb":[[1.44,39]],"id":26051221},{"atl":[[1.66,28.24]],"id":26051221}],"con":true,"img":false}]}
{"op":"mcm","clk":"5353409619","pt":1646214422046,"mc":[{"id":"1.195503852","rc":[{"atb":[[2.42,6.88]],"id":28338255},{"atl":[[3.45,8],[3.6,12],[4.1,27],[3.35,5],[3.8,18]],"id":28338255}],"con":true,"img":false}]}
{"op":"mcm","clk":"5353409629","pt":1646214422143,"mc":[{"id":"1.195503852","rc":[{"atb":[[2.44,18.05]],"id":28338255}],"con":true,"img":false}]}
{"op":"mcm","clk":"5353409634","pt":1646214422205,"mc":[{"id":"1.195503852","rc":[{"atb":[[1.44,14.99],[1.45,12.87]],"id":26051221},{"atl":[[1.66,12.86],[1.65,12.81]],"id":26051221}],"con":true,"img":false}]}
{"op":"mcm","clk":"5353409639","pt":1646214422349,"mc":[{"id":"1.195503852","rc":[{"atb":[[1.46,2],[1.44,12.99],[1.43,37.02]],"id":26051221},{"atl":[[1.67,28.2]],"id":26051221},{"atb":[[2.52,6.89]],"id":28338255}],"con":true,"img":false}]}
{"op":"mcm","clk":"5353409658","pt":1646214422529,"mc":[{"id":"1.195503852","rc":[{"atb":[[1.8,27],[1.89,8],[1.84,18],[2.44,6.87],[1.87,12],[1.75,40]],"id":28338255}],"con":true,"img":false}]}
{"op":"mcm","clk":"5353409667","pt":1646214422624,"mc":[{"id":"1.195503852","rc":[{"atb":[[2.5,30.62]],"id":28338255},{"atl":[[3.3,6.79]],"id":28338255},{"atl":[[1.67,12.82]],"id":26051221}],"con":true,"img":false}]}
{"op":"mcm","clk":"5353409675","pt":1646214422728,"mc":[{"id":"1.195503852","rc":[{"atb":[[1.46,14.69]],"id":26051221},{"atl":[[1.65,15.38]],"id":26051221}],"con":true,"img":false}]}
{"op":"mcm","clk":"5353409683","pt":1646214422831,"mc":[{"id":"1.195503852","rc":[{"atb":[[1.44,79.31],[1.43,13.01]],"id":26051221},{"atl":[[1.65,0]],"id":26051221},{"atb":[[2.5,19.44]],"id":28338255},{"atl":[[3.95,2]],"id":28338255}],"con":true,"img":false}]}
{"op":"mcm","clk":"5353409690","pt":1646214422927,"mc":[{"id":"1.195503852","rc":[{"atl":[[1.65,12.58]],"id":26051221}],"con":true,"img":false}]}
{"op":"mcm","clk":"5353409723","pt":1646214423339,"mc":[{"id":"1.195503852","rc":[{"atb":[[1.46,32.55]],"id":26051221},{"atl":[[3.3,16.68]],"id":28338255}],"con":true,"img":false}]}
{"op":"mcm","clk":"5353409743","pt":1646214423610,"mc":[{"id":"1.195503852","rc":[{"atb":[[1.43,0],[1.47,12.72]],"id":26051221},{"atl":[[3.25,6.87]],"id":28338255}],"con":true,"img":false}]}
{"op":"mcm","clk":"5353409758","pt":1646214423917,"mc":[{"id":"1.195503852","rc":[{"atl":[[3.3,6.79]],"id":28338255},{"atb":[[1.46,14.69]],"id":26051221}],"con":true,"img":false}]}
{"op":"mcm","clk":"5353409762","pt":1646214424018,"mc":[{"id":"1.195503852","rc":[{"atl":[[3.25,16.76]],"id":28338255},{"atb":[[1.47,30.58]],"id":26051221}],"con":true,"img":false}]}
{"op":"mcm","clk":"5353409768","pt":1646214424129,"mc":[{"id":"1.195503852","rc":[{"atb":[[1.48,12.69]],"id":26051221}],"con":true,"img":false}]}
{"op":"mcm","clk":"5353409782","pt":1646214424334,"mc":[{"id":"1.195503852","rc":[{"atb":[[1.44,66.31]],"id":26051221}],"con":true,"img":false}]}
{"op":"mcm","clk":"5353409790","pt":1646214424440,"mc":[{"id":"1.195503852","rc":[{"atb":[[1.47,12.72]],"id":26051221},{"atl":[[3.2,6.87]],"id":28338255}],"con":true,"img":false}]}
{"op":"mcm","clk":"5353409803","pt":1646214424537,"mc":[{"id":"1.195503852","rc":[{"atb":[[1.48,30.55]],"id":26051221}],"con":true,"img":false}]}
{"op":"mcm","clk":"5353409821","pt":1646214424742,"mc":[{"id":"1.195503852","rc":[{"atl":[[3.25,6.87]],"id":28338255}],"con":true,"img":false}]}
{"op":"mcm","clk":"5353409829","pt":1646214424848,"mc":[{"id":"1.195503852","rc":[{"atb":[[1.46,78.12],[1.45,0]],"id":26051221}],"con":true,"img":false}]}
{"op":"mcm","clk":"5353409834","pt":1646214424945,"mc":[{"id":"1.195503852","rc":[{"atb":[[1.49,12.68]],"id":26051221},{"atl":[[3.95,0],[3.15,2]],"id":28338255}],"con":true,"img":false}]}
{"op":"mcm","clk":"5353409847","pt":1646214425117,"mc":[{"id":"1.195503852","rc":[{"atl":[[3.2,17.05]],"id":28338255}],"con":true,"img":false}]}
{"op":"mcm","clk":"5353409852","pt":1646214425221,"mc":[{"id":"1.195503852","rc":[{"atb":[[1.48,12.69]],"id":26051221}],"con":true,"img":false}]}
{"op":"mcm","clk":"5353409863","pt":1646214425325,"mc":[{"id":"1.195503852","rc":[{"atb":[[1.49,30.54]],"id":26051221}],"con":true,"img":false}]}
{"op":"mcm","clk":"5353409871","pt":1646214425426,"mc":[{"id":"1.195503852","rc":[{"atl":[[3.2,6.87]],"id":28338255}],"con":true,"img":false}]}
{"op":"mcm","clk":"5353409879","pt":1646214425527,"mc":[{"id":"1.195503852","rc":[{"atl":[[3.15,12.18]],"id":28338255}],"con":true,"img":false}]}
{"op":"mcm","clk":"5353409930","pt":1646214426111,"mc":[{"id":"1.195503852","rc":[{"atl":[[3.15,6]],"id":28338255}],"con":true,"img":false}]}
{"op":"mcm","clk":"5353409937","pt":1646214426218,"mc":[{"id":"1.195503852","rc":[{"atl":[[32,0]],"id":28338255},{"atl":[[32,0],[34,0],[36,0]],"id":26051221}],"con":true,"img":false}]}
{"op":"mcm","clk":"5353409943","pt":1646214426322,"mc":[{"id":"1.195503852","rc":[{"atb":[[2.4,0],[2.42,8.88]],"id":28338255}],"con":true,"img":false}]}
{"op":"mcm","clk":"5353409954","pt":1646214426535,"mc":[{"id":"1.195503852","rc":[{"atl":[[3.1,6.87]],"id":28338255},{"atb":[[1.46,65.42],[1.5,12.7]],"id":26051221}],"con":true,"img":false}]}
{"op":"mcm","clk":"5353409960","pt":1646214426634,"mc":[{"id":"1.195503852","rc":[{"atb":[[1.02,3.03]],"id":26051221},{"atl":[[3.7,0.03]],"id":28338255}],"con":true,"img":false}]}
{"op":"mcm","clk":"5353409975","pt":1646214426839,"mc":[{"id":"1.195503852","rc":[{"atb":[[1.02,0.3],[1.48,73.48]],"id":26051221}],"con":true,"img":false}]}
{"op":"mcm","clk":"5353409996","pt":1646214427041,"mc":[{"id":"1.195503852","rc":[{"atb":[[1.02,0],[1.49,12.68]],"id":26051221},{"atl":[[3.15,2]],"id":28338255}],"con":true,"img":false}]}
{"op":"mcm","clk":"5353410001","pt":1646214427146,"mc":[{"id":"1.195503852","rc":[{"atb":[[1.5,30.56]],"id":26051221},{"atl":[[1.65,12.28]],"id":26051221},{"trd":[[1.65,0.61]],"ltp":1.65,"tv":0.61,"id":26051221}],"con":true,"img":false}]}
{"op":"mcm","clk":"5353410012","pt":1646214427353,"mc":[{"id":"1.195503852","rc":[{"atb":[[1.51,12.69],[1.47,0]],"id":26051221}],"con":true,"img":false}]}
{"op":"mcm","clk":"5353410021","pt":1646214427453,"mc":[{"id":"1.195503852","rc":[{"atl":[[3.1,14.46]],"id":28338255}],"con":true,"img":false}]}
{"op":"mcm","clk":"5353410030","pt":1646214427557,"mc":[{"id":"1.195503852","rc":[{"atb":[[1.46,63.42],[1.51,14.69]],"id":26051221}],"con":true,"img":false}]}
{"op":"mcm","clk":"5353410036","pt":1646214427618,"mc":[{"id":"1.195503852","rc":[{"atb":[[1.5,12.7]],"id":26051221}],"con":true,"img":false}]}
{"op":"mcm","clk":"5353410043","pt":1646214427721,"mc":[{"id":"1.195503852","rc":[{"atb":[[1.51,32.55]],"id":26051221}],"con":true,"img":false}]}
{"op":"mcm","clk":"5353410055","pt":1646214427930,"mc":[{"id":"1.195503852","rc":[{"atl":[[3.05,13.78]],"id":28338255}],"con":true,"img":false}]}
{"op":"mcm","clk":"5353410060","pt":1646214428033,"mc":[{"id":"1.195503852","rc":[{"atb":[[1.52,12.67]],"id":26051221}],"con":true,"img":false}]}
{"op":"mcm","clk":"5353410068","pt":1646214428135,"mc":[{"id":"1.195503852","rc":[{"atb":[[1.48,60.78]],"id":26051221},{"atl":[[3.3,0]],"id":28338255}],"con":true,"img":false}]}
{"op":"mcm","clk":"5353410073","pt":1646214428238,"mc":[{"id":"1.195503852","rc":[{"atb":[[1.51,22.74]],"id":26051221},{"atl":[[3.1,6.87]],"id":28338255}],"con":true,"img":false}]}
{"op":"mcm","clk":"5353410079","pt":1646214428335,"mc":[{"id":"1.195503852","rc":[{"atb":[[2.52,14.92]],"id":28338255},{"atl":[[3.05,21.37]],"id":28338255},{"atb":[[1.44,0]],"id":26051221},{"atl":[[1.68,0],[1.65,23.58]],"id":26051221}],"con":true,"img":false}]}
{"op":"mcm","clk":"5353410094","pt":1646214428543,"mc":[{"id":"1.195503852","rc":[{"atl":[[1.65,11.3]],"id":26051221}],"con":true,"img":false}]}
{"op":"mcm","clk":"5353410112","pt":1646214428755,"mc":[{"id":"1.195503852","rc":[{"atl":[[3,6.92]],"id":28338255}],"con":true,"img":false}]}
{"op":"mcm","clk":"5353410119","pt":1646214428856,"mc":[{"id":"1.195503852","rc":[{"atb":[[2.54,18.94]],"id":28338255},{"atb":[[1.5,71.05]],"id":26051221},{"atl":[[1.65,0]],"id":26051221}],"con":true,"img":false}]}
{"op":"mcm","clk":"5353410133","pt":1646214429023,"mc":[{"id":"1.195503852","rc":[{"atl":[[3.05,13.78]],"id":28338255}],"con":true,"img":false}]}
{"op":"mcm","clk":"5353410139","pt":1646214429166,"mc":[{"id":"1.195503852","rc":[{"atb":[[2.52,6.89]],"id":28338255},{"atl":[[3,14.51]],"id":28338255},{"atl":[[1.66,25.3]],"id":26051221}],"con":true,"img":false}]}
{"op":"mcm","clk":"5353410155","pt":1646214429335,"mc":[{"id":"1.195503852","rc":[{"atb":[[2.54,8.03],[2.56,6.89]],"id":28338255},{"atl":[[1.65,12.73]],"id":26051221}],"con":true,"img":false}]}
{"op":"mcm","clk":"5353410176","pt":1646214429646,"mc":[{"id":"1.195503852","rc":[{"atl":[[1.66,12.86]],"id":26051221},{"atb":[[2.54,0]],"id":28338255}],"con":true,"img":false}]}
{"op":"mcm","clk":"5353410181","pt":1646214429754,"mc":[{"id":"1.195503852","rc":[{"atb":[[2.56,14.92],[1.04,2.86]],"id":28338255},{"atl":[[1.65,25.17]],"id":26051221}],"con":true,"img":false}]}
{"op":"mcm","clk":"5353410185","pt":1646214429854,"mc":[{"id":"1.195503852","rc":[{"atb":[[2.54,18.94]],"id":28338255}],"con":true,"img":false}]}
{"op":"mcm","clk":"5353410191","pt":1646214429957,"mc":[{"id":"1.195503852","rc":[{"atb":[[1.04,0.14]],"id":28338255}],"con":true,"img":false}]}
{"op":"mcm","clk":"5353410202","pt":1646214430058,"mc":[{"id":"1.195503852","rc":[{"atl":[[2.98,2]],"id":28338255},{"atb":[[1.41,0]],"id":26051221},{"atl":[[1.64,13.12]],"id":26051221}],"con":true,"img":false}]}
{"op":"mcm","clk":"5353410208","pt":1646214430126,"mc":[{"id":"1.195503852","rc":[{"atb":[[2.58,6.71],[2.42,2]],"id":28338255},{"atl":[[3.15,0]],"id":28338255},{"atb":[[1.4,11.27]],"id":26051221}],"con":true,"img":false}]}
{"op":"mcm","clk":"5353410218","pt":1646214430267,"mc":[{"id":"1.195503852","rc":[{"atb":[[1.04,0]],"id":28338255}],"con":true,"img":false}]}
{"op":"mcm","clk":"5353410225","pt":1646214430333,"mc":[{"id":"1.195503852","rc":[{"atb":[[2.5,0]],"id":28338255},{"atl":[[3,6.92]],"id":28338255},{"trd":[[2.94,0.14]],"ltp":2.94,"tv":0.14,"id":28338255},{"atb":[[1.52,12.39]],"id":26051221},{"atl":[[1.65,12.73]],"id":26051221},{"trd":[[1.52,0.27]],"ltp":1.52,"tv":0.27,"id":26051221}],"con":true,"img":false}]}
{"op":"mcm","clk":"5353410236","pt":1646214430476,"mc":[{"id":"1.195503852","rc":[{"atb":[[2.56,6.89]],"id":28338255},{"atl":[[2.98,16.29],[3.25,0]],"id":28338255},{"atl":[[1.64,25.56]],"id":26051221}],"con":true,"img":false}]}
{"op":"mcm","clk":"5353410240","pt":1646214430540,"mc":[{"id":"1.195503852","rc":[{"atb":[[2.58,14.74]],"id":28338255}],"con":true,"img":false}]}
{"op":"mcm","clk":"5353410253","pt":1646214430749,"mc":[{"id":"1.195503852","rc":[{"atl":[[3.2,0],[2.96,13.42]],"id":28338255}],"con":true,"img":false}]}
{"op":"mcm","clk":"5353410259","pt":1646214430845,"mc":[{"id":"1.195503852","rc":[{"atb":[[2.58,33.21]],"id":28338255}],"con":true,"img":false}]}
{"op":"mcm","clk":"5353410264","pt":1646214430953,"mc":[{"id":"1.195503852","rc":[{"atb":[[2.44,0],[2.6,6.75]],"id":28338255},{"atl":[[1.63,13.06],[1.67,0]],"id":26051221}],"con":true,"img":false}]}
{"op":"mcm","clk":"5353410289","pt":1646214431362,"mc":[{"id":"1.195503852","rc":[{"atb":[[1.46,0]],"id":26051221},{"atl":[[1.64,13.12]],"id":26051221},{"atb":[[2.58,25.18]],"id":28338255},{"atl":[[2.98,8.7]],"id":28338255}],"con":true,"img":false}]}
{"op":"mcm","clk":"5353410298","pt":1646214431467,"mc":[{"id":"1.195503852","rc":[{"atl":[[1.63,25.5]],"id":26051221},{"atb":[[2.6,14.78]],"id":28338255},{"atl":[[2.96,21.01]],"id":28338255}],"con":true,"img":false}]}
{"op":"mcm","clk":"5353410317","pt":1646214431781,"mc":[{"id":"1.195503852","rc":[{"atl":[[2.96,13.42]],"id":28338255}],"con":true,"img":false}]}
{"op":"mcm","clk":"5353410329","pt":1646214431841,"mc":[{"id":"1.195503852","rc":[{"atb":[[1.52,68.5]],"id":26051221},{"atl":[[1.62,13.07]],"id":26051221}],"con":true,"img":false}]}
{"op":"mcm","clk":"5353410339","pt":1646214431943,"mc":[{"id":"1.195503852","rc":[{"atl":[[1.66,0]],"id":26051221}],"con":true,"img":false}]}
{"op":"mcm","clk":"5353410357","pt":1646214432156,"mc":[{"id":"1.195503852","rc":[{"atl":[[1.63,13.06]],"id":26051221}],"con":true,"img":false}]}
{"op":"mcm","clk":"5353410364","pt":1646214432248,"mc":[{"id":"1.195503852","rc":[{"atl":[[1.62,25.51]],"id":26051221}],"con":true,"img":false}]}
{"op":"mcm","clk":"5353410369","pt":1646214432353,"mc":[{"id":"1.195503852","rc":[{"atb":[[2.54,0]],"id":28338255}],"con":true,"img":false}]}
{"op":"mcm","clk":"5353410398","pt":1646214432763,"mc":[{"id":"1.195503852","rc":[{"atb":[[1.51,20.74],[1.53,2]],"id":26051221}],"con":true,"img":false}]}
{"op":"mcm","clk":"5353410406","pt":1646214432867,"mc":[{"id":"1.195503852","rc":[{"atb":[[2.62,18]],"id":28338255}],"con":true,"img":false}]}
{"op":"mcm","clk":"5353410421","pt":1646214433033,"mc":[{"id":"1.195503852","rc":[{"atb":[[1.53,15.24]],"id":26051221}],"con":true,"img":false}]}
{"op":"mcm","clk":"5353410426","pt":1646214433133,"mc":[{"id":"1.195503852","rc":[{"atb":[[2.6,6.75]],"id":28338255}],"con":true,"img":false}]}
{"op":"mcm","clk":"5353410436","pt":1646214433240,"mc":[{"id":"1.195503852","rc":[{"atb":[[2.62,26.03]],"id":28338255}],"con":true,"img":false}]}
{"op":"mcm","clk":"5353410486","pt":1646214433966,"mc":[{"id":"1.195503852","rc":[{"atl":[[1.63,14.03]],"id":26051221}],"con":true,"img":false}]}
{"op":"mcm","clk":"5353410504","pt":1646214434167,"mc":[{"id":"1.195503852","rc":[{"atl":[[1.62,12.44]],"id":26051221}],"con":true,"img":false}]}
{"op":"mcm","clk":"5353410525","pt":1646214434540,"mc":[{"id":"1.195503852","rc":[{"atb":[[1.51,12.69]],"id":26051221},{"atl":[[1.62,0]],"id":26051221},{"atb":[[2.62,18]],"id":28338255}],"con":true,"img":false}]}
{"op":"mcm","clk":"5353410532","pt":1646214434650,"mc":[{"id":"1.195503852","rc":[{"atl":[[1.63,26.47]],"id":26051221}],"con":true,"img":false}]}
{"op":"mcm","clk":"5353410545","pt":1646214434857,"mc":[{"id":"1.195503852","rc":[{"atb":[[2.62,0]],"id":28338255}],"con":true,"img":false}]}
{"op":"mcm","clk":"5353410562","pt":1646214435163,"mc":[{"id":"1.195503852","rc":[{"atb":[[2.6,12.15]],"id":28338255},{"atl":[[2.98,6.7],[2.94,2]],"id":28338255},{"atl":[[1.63,14.03]],"id":26051221}],"con":true,"img":false}]}
{"op":"mcm","clk":"5353410588","pt":1646214435471,"mc":[{"id":"1.195503852","rc":[{"atl":[[1.63,23.28]],"id":26051221}],"con":true,"img":false}]}
{"op":"mcm","clk":"5353410601","pt":1646214435643,"mc":[{"id":"1.195503852","rc":[{"atl":[[3.1,0],[2.94,8.77]],"id":28338255}],"con":true,"img":false}]}
{"op":"mcm","clk":"5353410670","pt":1646214436470,"mc":[{"id":"1.195503852","rc":[{"atb":[[2.6,5.4]],"id":28338255}],"con":true,"img":false}]}
{"op":"mcm","clk":"5353410674","pt":1646214436575,"mc":[{"id":"1.195503852","rc":[{"atb":[[2.42,0]],"id":28338255}],"con":true,"img":false}]}
{"op":"mcm","clk":"5353410679","pt":1646214436640,"mc":[{"id":"1.195503852","rc":[{"atb":[[2.38,2]],"id":28338255}],"con":true,"img":false}]}
{"op":"mcm","clk":"5353410686","pt":1646214436744,"mc":[{"id":"1.195503852","rc":[{"atb":[[2.6,0]],"id":28338255}],"con":true,"img":false}]}
{"op":"mcm","clk":"5353410712","pt":1646214437165,"mc":[{"id":"1.195503852","rc":[{"atb":[[2.58,30.92]],"id":28338255}],"con":true,"img":false}]}
{"op":"mcm","clk":"5353410777","pt":1646214438253,"mc":[{"id":"1.195503852","rc":[{"atb":[[2.6,6.81]],"id":28338255}],"con":true,"img":false}]}
{"op":"mcm","clk":"5353410782","pt":1646214438348,"mc":[{"id":"1.195503852","rc":[{"atb":[[2.58,25.18]],"id":28338255},{"atl":[[2.94,15.71]],"id":28338255},{"atb":[[1.53,26.38]],"id":26051221},{"atl":[[1.63,14.03]],"id":26051221}],"con":true,"img":false}]}
{"op":"mcm","clk":"5353410829","pt":1646214439171,"mc":[{"id":"1.195503852","rc":[{"atb":[[1.54,26.08]],"id":26051221},{"atl":[[2.92,13.52]],"id":28338255}],"con":true,"img":false}]}
{"op":"mcm","clk":"5353410841","pt":1646214439377,"mc":[{"id":"1.195503852","rc":[{"atb":[[1.55,2],[1.49,0],[1.53,24.38]],"id":26051221},{"atl":[[3.05,6.89]],"id":28338255}],"con":true,"img":false}]}
{"op":"mcm","clk":"5353410847","pt":1646214439439,"mc":[{"id":"1.195503852","rc":[{"atb":[[1.53,13.24]],"id":26051221},{"atl":[[2.94,8.77]],"id":28338255}],"con":true,"img":false}]}
{"op":"mcm","clk":"5353410856","pt":1646214439542,"mc":[{"id":"1.195503852","rc":[{"atl":[[2.92,20.46]],"id":28338255},{"atb":[[1.54,37.22]],"id":26051221}],"con":true,"img":false}]}
{"op":"mcm","clk":"5353410884","pt":1646214439955,"mc":[{"id":"1.195503852","rc":[{"atb":[[1.54,26.08]],"id":26051221}],"con":true,"img":false}]}
{"op":"mcm","clk":"5353410890","pt":1646214440056,"mc":[{"id":"1.195503852","rc":[{"atb":[[1.55,13.14]],"id":26051221}],"con":true,"img":false}]}
{"op":"mcm","clk":"5353410896","pt":1646214440157,"mc":[{"id":"1.195503852","rc":[{"atb":[[1.55,2]],"id":26051221},{"atl":[[2.92,13.52]],"id":28338255}],"con":true,"img":false}]}
{"op":"mcm","clk":"5353410909","pt":1646214440371,"mc":[{"id":"1.195503852","rc":[{"atl":[[2.94,6.77],[2.9,2]],"id":28338255}],"con":true,"img":false}]}
{"op":"mcm","clk":"5353410958","pt":1646214440986,"mc":[{"id":"1.195503852","rc":[{"atl":[[2.9,12.76]],"id":28338255},{"atb":[[1.55,15.05]],"id":26051221}],"con":true,"img":false}]}
{"op":"mcm","clk":"5353410972","pt":1646214441150,"mc":[{"id":"1.195503852","rc":[{"atl":[[2.98,0]],"id":28338255},{"atb":[[1.5,58.35]],"id":26051221}],"con":true,"img":false}]}
{"op":"mcm","clk":"5353410993","pt":1646214441358,"mc":[{"id":"1.195503852","rc":[{"atb":[[1.48,0]],"id":26051221}],"con":true,"img":false}]}
{"op":"mcm","clk":"5353411028","pt":1646214441968,"mc":[{"id":"1.195503852","rc":[{"atb":[[2.6,0]],"id":28338255},{"atl":[[2.88,6.76]],"id":28338255}],"con":true,"img":false}]}
{"op":"mcm","clk":"5353411035","pt":1646214442068,"mc":[{"id":"1.195503852","rc":[{"atl":[[2.96,6.71]],"id":28338255}],"con":true,"img":false}]}
{"op":"mcm","clk":"5353411046","pt":1646214442276,"mc":[{"id":"1.195503852","rc":[{"atl":[[2.9,8.76]],"id":28338255}],"con":true,"img":false}]}
{"op":"mcm","clk":"5353411050","pt":1646214442338,"mc":[{"id":"1.195503852","rc":[{"atb":[[1.54,80.1]],"id":26051221}],"con":true,"img":false}]}
{"op":"mcm","clk":"5353411061","pt":1646214442543,"mc":[{"id":"1.195503852","rc":[{"atl":[[2.88,14.61]],"id":28338255}],"con":true,"img":false}]}
{"op":"mcm","clk":"5353411121","pt":1646214443577,"mc":[{"id":"1.195503852","rc":[{"atl":[[2.88,6.76]],"id":28338255}],"con":true,"img":false}]}
{"op":"mcm","clk":"5353411171","pt":1646214444459,"mc":[{"id":"1.195503852","rc":[{"atb":[[2.6,6.81]],"id":28338255},{"atb":[[1.55,13.05],[1.54,82.1]],"id":26051221}],"con":true,"img":false}]}
{"op":"mcm","clk":"5353411174","pt":1646214444562,"mc":[{"id":"1.195503852","rc":[{"atb":[[1.55,0]],"id":26051221}],"con":true,"img":false}]}
{"op":"mcm","clk":"5353411180","pt":1646214444770,"mc":[{"id":"1.195503852","rc":[{"atb":[[1.56,13.36],[1.55,13.36]],"id":26051221}],"con":true,"img":false}]}
{"op":"mcm","clk":"5353411188","pt":1646214444876,"mc":[{"id":"1.195503852","rc":[{"atb":[[1.54,28.08]],"id":26051221},{"atl":[[2.88,14.89]],"id":28338255}],"con":true,"img":false}]}
{"op":"mcm","clk":"5353411220","pt":1646214445495,"mc":[{"id":"1.195503852","rc":[{"atl":[[2.9,6.76],[2.86,2]],"id":28338255}],"con":true,"img":false}]}
{"op":"mcm","clk":"5353411228","pt":1646214445703,"mc":[{"id":"1.195503852","rc":[{"atb":[[1.56,24.38]],"id":26051221}],"con":true,"img":false}]}
{"op":"mcm","clk":"5353411236","pt":1646214445868,"mc":[{"id":"1.195503852","rc":[{"atb":[[1.55,66.41]],"id":26051221},{"atl":[[2.88,6.76]],"id":28338255}],"con":true,"img":false}]}
{"op":"mcm","clk":"5353411242","pt":1646214445965,"mc":[{"id":"1.195503852","rc":[{"atl":[[2.86,10.13]],"id":28338255}],"con":true,"img":false}]}
{"op":"mcm","clk":"5353411256","pt":1646214446282,"mc":[{"id":"1.195503852","rc":[{"atl":[[2.86,6]],"id":28338255}],"con":true,"img":false}]}
{"op":"mcm","clk":"5353411316","pt":1646214447165,"mc":[{"id":"1.195503852","rc":[{"atl":[[2.84,6.66]],"id":28338255},{"atb":[[1.57,13.35]],"id":26051221}],"con":true,"img":false}]}
{"op":"mcm","clk":"5353411331","pt":1646214447369,"mc":[{"id":"1.195503852","rc":[{"atb":[[1.53,0]],"id":26051221},{"atl":[[3.05,0]],"id":28338255}],"con":true,"img":false}]}
{"op":"mcm","clk":"5353411342","pt":1646214447572,"mc":[{"id":"1.195503852","rc":[{"atl":[[2.86,2]],"id":28338255},{"atb":[[1.56,13.36]],"id":26051221}],"con":true,"img":false}]}
{"op":"mcm","clk":"5353411371","pt":1646214448087,"mc":[{"id":"1.195503852","rc":[{"atl":[[2.84,18.41]],"id":28338255},{"atb":[[1.57,31]],"id":26051221}],"con":true,"img":false}]}
{"op":"mcm","clk":"5353411395","pt":1646214448397,"mc":[{"id":"1.195503852","rc":[{"atb":[[2.58,6.71]],"id":28338255}],"con":true,"img":false}]}
{"op":"mcm","clk":"5353411422","pt":1646214448769,"mc":[{"id":"1.195503852","rc":[{"atb":[[2.56,25.6]],"id":28338255}],"con":true,"img":false}]}
{"op":"mcm","clk":"5353411472","pt":1646214449589,"mc":[{"id":"1.195503852","rc":[{"atb":[[1.55,68.41],[1.54,26.08]],"id":26051221}],"con":true,"img":false}]}
{"op":"mcm","clk":"5353411516","pt":1646214450374,"mc":[{"id":"1.195503852","rc":[{"atl":[[2.82,6.68]],"id":28338255}],"con":true,"img":false}]}
{"op":"mcm","clk":"5353411524","pt":1646214450474,"mc":[{"id":"1.195503852","rc":[{"atl":[[2.94,0]],"id":28338255}],"con":true,"img":false}]}
{"op":"mcm","clk":"5353411532","pt":1646214450582,"mc":[{"id":"1.195503852","rc":[{"atl":[[2.8,2]],"id":28338255}],"con":true,"img":false}]}
{"op":"mcm","clk":"5353411538","pt":1646214450685,"mc":[{"id":"1.195503852","rc":[{"atl":[[2.84,6.66],[2.86,0]],"id":28338255}],"con":true,"img":false}]}
{"op":"mcm","clk":"5353411546","pt":1646214450787,"mc":[{"id":"1.195503852","rc":[{"atl":[[2.82,18.43]],"id":28338255}],"con":true,"img":false}]}
{"op":"mcm","clk":"5353411560","pt":1646214451094,"mc":[{"id":"1.195503852","rc":[{"atl":[[2.82,17.68]],"id":28338255}],"con":true,"img":false}]}
{"op":"mcm","clk":"5353411565","pt":1646214451200,"mc":[{"id":"1.195503852","rc":[{"atl":[[2.8,13.75]],"id":28338255}],"con":true,"img":false}]}
{"op":"mcm","clk":"5353411581","pt":1646214451510,"mc":[{"id":"1.195503852","rc":[{"atl":[[2.8,6],[2.78,6.68]],"id":28338255}],"con":true,"img":false}]}
{"op":"mcm","clk":"5353411595","pt":1646214451674,"mc":[{"id":"1.195503852","rc":[{"atl":[[3,0]],"id":28338255}],"con":true,"img":false}]}
{"op":"mcm","clk":"5353411604","pt":1646214451775,"mc":[{"id":"1.195503852","rc":[{"atl":[[2.8,2]],"id":28338255}],"con":true,"img":false}]}
{"op":"mcm","clk":"5353411610","pt":1646214451879,"mc":[{"id":"1.195503852","rc":[{"atb":[[1.5,0]],"id":26051221}],"con":true,"img":false}]}
{"op":"mcm","clk":"5353411624","pt":1646214452087,"mc":[{"id":"1.195503852","rc":[{"atl":[[2.78,15.67]],"id":28338255}],"con":true,"img":false}]}
{"op":"mcm","clk":"5353411646","pt":1646214452393,"mc":[{"id":"1.195503852","rc":[{"atb":[[2.14,0]],"id":28338255},{"atb":[[1.4,0],[1.57,82.18]],"id":26051221}],"con":true,"img":false}]}
{"op":"mcm","clk":"5353411655","pt":1646214452499,"mc":[{"id":"1.195503852","rc":[{"atl":[[2.76,6.68]],"id":28338255}],"con":true,"img":false}]}
{"op":"mcm","clk":"5353411663","pt":1646214452598,"mc":[{"id":"1.195503852","rc":[{"atl":[[2.96,0]],"id":28338255}],"con":true,"img":false}]}
{"op":"mcm","clk":"5353411687","pt":1646214452866,"mc":[{"id":"1.195503852","rc":[{"atl":[[2.78,6.68]],"id":28338255}],"con":true,"img":false}]}
{"op":"mcm","clk":"5353411692","pt":1646214452970,"mc":[{"id":"1.195503852","rc":[{"atl":[[2.76,15.67]],"id":28338255}],"con":true,"img":false}]}
{"op":"mcm","clk":"5353411695","pt":1646214453070,"mc":[{"id":"1.195503852","rc":[{"atb":[[1.58,13.09]],"id":26051221}],"con":true,"img":false}]}
{"op":"mcm","clk":"5353411700","pt":1646214453173,"mc":[{"id":"1.195503852","rc":[{"atl":[[2.92,6.76],[2.74,6.75]],"id":28338255}],"con":true,"img":false}]}
{"op":"mcm","clk":"5353411705","pt":1646214453274,"mc":[{"id":"1.195503852","rc":[{"atb":[[1.54,13.04]],"id":26051221}],"con":true,"img":false}]}
{"op":"mcm","clk":"5353411714","pt":1646214453378,"mc":[{"id":"1.195503852","rc":[{"atb":[[2.6,0]],"id":28338255}],"con":true,"img":false}]}
{"op":"mcm","clk":"5353411718","pt":1646214453481,"mc":[{"id":"1.195503852","rc":[{"atl":[[2.76,6.68]],"id":28338255},{"atb":[[1.57,64.53]],"id":26051221}],"con":true,"img":false}]}
{"op":"mcm","clk":"5353411724","pt":1646214453587,"mc":[{"id":"1.195503852","rc":[{"atb":[[1.58,30.74]],"id":26051221},{"atl":[[2.74,15.74]],"id":28338255}],"con":true,"img":false}]}
{"op":"mcm","clk":"5353411744","pt":1646214453900,"mc":[{"id":"1.195503852","rc":[{"atb":[[1.58,13.09]],"id":26051221},{"atb":[[2.56,6.89]],"id":28338255},{"atl":[[2.74,11.12]],"id":28338255}],"con":true,"img":false}]}
{"op":"mcm","clk":"5353411767","pt":1646214454270,"mc":[{"id":"1.195503852","rc":[{"atb":[[2.54,18.94]],"id":28338255}],"con":true,"img":false}]}
{"op":"mcm","clk":"5353411771","pt":1646214454374,"mc":[{"id":"1.195503852","rc":[{"atl":[[2.72,6.75],[2.84,0]],"id":28338255}],"con":true,"img":false}]}
{"op":"mcm","clk":"5353411855","pt":1646214455712,"mc":[{"id":"1.195503852","rc":[{"atl":[[2.7,2]],"id":28338255}],"con":true,"img":false}]}
{"op":"mcm","clk":"5353411860","pt":1646214455776,"mc":[{"id":"1.195503852","rc":[{"atl":[[2.8,0]],"id":28338255}],"con":true,"img":false}]}
{"op":"mcm","clk":"5353411867","pt":1646214455878,"mc":[{"id":"1.195503852","rc":[{"atl":[[2.78,0],[2.7,8.76]],"id":28338255}],"con":true,"img":false}]}
{"op":"mcm","clk":"5353411999","pt":1646214458114,"mc":[{"id":"1.195503852","rc":[{"atb":[[2.56,0],[2.58,0]],"id":28338255},{"atl":[[1.64,0],[1.63,0.96]],"id":26051221}],"con":true,"img":false}]}
{"op":"mcm","clk":"5353412012","pt":1646214458315,"mc":[{"id":"1.195503852","rc":[{"atb":[[2.12,26.05]],"id":28338255}],"con":true,"img":false}]}
{"op":"mcm","clk":"5353412019","pt":1646214458375,"mc":[{"id":"1.195503852","rc":[{"atb":[[2.54,0]],"id":28338255}],"con":true,"img":false}]}
{"op":"mcm","clk":"5353412045","pt":1646214458893,"mc":[{"id":"1.195503852","rc":[{"atb":[[1.57,13.35]],"id":26051221}],"con":true,"img":false}]}
{"op":"mcm","clk":"5353412125","pt":1646214460291,"mc":[{"id":"1.195503852","rc":[{"atl":[[1.65,0]],"id":26051221}],"con":true,"img":false}]}
{"op":"mcm","clk":"5353412138","pt":1646214460615,"mc":[{"id":"1.195503852","marketDefinition":{"bspMarket":false,"turnInPlayEnabled":false,"persistenceEnabled":false,"marketBaseRate":7.0,"eventId":"31272499","eventTypeId":"4339","numberOfWinners":1,"bettingType":"ODDS","marketType":"MATCH_BET","marketTime":"2022-03-02T09:47:00.000Z","suspendTime":"2022-03-02T09:47:00.000Z","bspReconciled":false,"complete":true,"inPlay":false,"crossMatching":true,"runnersVoidable":false,"numberOfActiveRunners":2,"betDelay":0,"status":"SUSPENDED","runners":[{"status":"ACTIVE","sortPriority":1,"id":26051221,"name":"7. Farmor Crownies"},{"status":"ACTIVE","sortPriority":2,"id":28338255,"name":"8. Until Late"}],"regulators":["MR_INT"],"venue":"Rockhampton","countryCode":"AU","discountAllowed":true,"timezone":"Australia/Queensland","openDate":"2022-03-02T08:28:00.000Z","version":4382892377,"name":"Farmor Crownies v Until Late","eventName":"Rockhampton (AUS) 2nd Mar"},"rc":[],"con":true,"img":false}]}
{"op":"mcm","clk":"5353412138","pt":1646214460615,"mc":[{"id":"1.195503852","rc":[{"atb":[[1.56,0],[1.01,0],[1.58,0],[1.57,0],[1.55,0],[1.54,0],[1.3,0],[1.51,0],[1.17,0],[1.52,0]],"id":26051221},{"atl":[[1.63,0],[1.74,0]],"id":26051221},{"atb":[[1.8,0],[1.89,0],[1.84,0],[2.52,0],[2.38,0],[2.12,0],[1.87,0],[1.75,0],[2.1,0]],"id":28338255},{"atl":[[2.82,0],[2.72,0],[3.6,0],[3.35,0],[3.8,0],[2.76,0],[2.92,0],[3.45,0],[2.88,0],[2.74,0],[2.9,0],[4.1,0],[3.7,0],[2.7,0]],"id":28338255}],"con":true,"img":false}]}
{"op":"mcm","clk":"5353414595","pt":1646214504655,"mc":[{"id":"1.195503852","rc":[{"trd":[[1.56,0],[1.37,0],[1.68,0],[1.65,0],[1.35,0],[1.52,0]],"ltp":1.56,"tv":0.0,"id":26051221},{"trd":[[2.56,0],[2.5,0],[2.9,0],[2.46,0],[2.94,0],[2.48,0],[3.75,0],[2.7,0]],"ltp":2.56,"tv":0.0,"id":28338255}],"con":true,"img":false}]}
{"op":"mcm","clk":"5353414677","pt":1646214505803,"mc":[{"id":"1.195503852","marketDefinition":{"bspMarket":false,"turnInPlayEnabled":false,"persistenceEnabled":false,"marketBaseRate":7.0,"eventId":"31272499","eventTypeId":"4339","numberOfWinners":1,"bettingType":"ODDS","marketType":"MATCH_BET","marketTime":"2022-03-02T09:47:00.000Z","suspendTime":"2022-03-02T09:47:00.000Z","bspReconciled":false,"complete":true,"inPlay":false,"crossMatching":false,"runnersVoidable":false,"numberOfActiveRunners":0,"betDelay":0,"status":"CLOSED","settledTime":"2022-03-02T09:48:23.000Z","runners":[{"status":"LOSER","sortPriority":1,"id":26051221,"name":"7. Farmor Crownies"},{"status":"WINNER","sortPriority":2,"id":28338255,"name":"8. Until Late"}],"regulators":["MR_INT"],"venue":"Rockhampton","countryCode":"AU","discountAllowed":true,"timezone":"Australia/Queensland","openDate":"2022-03-02T08:28:00.000Z","version":4382893042,"name":"Farmor Crownies v Until Late","eventName":"Rockhampton (AUS) 2nd Mar"},"rc":[],"con":true,"img":false}]}
