{"op":"mcm","clk":"5351767855","pt":1646175389019,"mc":[{"id":"1.195453775","marketDefinition":{"bspMarket":true,"turnInPlayEnabled":false,"persistenceEnabled":false,"marketBaseRate":7.0,"eventId":"31272499","eventTypeId":"4339","numberOfWinners":2,"bettingType":"ODDS","marketType":"PLACE","marketTime":"2022-03-02T10:32:00.000Z","suspendTime":"2022-03-02T10:32:00.000Z","bspReconciled":false,"complete":true,"inPlay":false,"crossMatching":false,"runnersVoidable":false,"numberOfActiveRunners":7,"betDelay":0,"status":"OPEN","runners":[{"status":"ACTIVE","sortPriority":1,"id":38247334,"name":"1. Noise Works"},{"status":"ACTIVE","sortPriority":2,"id":39790958,"name":"2. Wise Decisions"},{"status":"ACTIVE","sortPriority":3,"id":38745817,"name":"3. Redeemers Kid"},{"status":"ACTIVE","sortPriority":4,"id":42688799,"name":"4. Velocity Kayla"},{"status":"ACTIVE","sortPriority":5,"id":41632950,"name":"6. Swift Anna"},{"status":"ACTIVE","sortPriority":6,"id":41132571,"name":"7. Dr Xena"},{"status":"ACTIVE","sortPriority":7,"id":42256451,"name":"8. Swift Twitch"}],"regulators":["MR_INT"],"venue":"Rockhampton","countryCode":"AU","discountAllowed":true,"timezone":"Australia/Queensland","openDate":"2022-03-02T08:34:00.000Z","version":4382437859,"name":"To Be Placed","eventName":"Rockhampton (AUS) 2nd Mar"},"rc":[],"con":true,"img":false}]}
{"op":"mcm","clk":"5351835883","pt":1646176787551,"mc":[{"id":"1.195453775","rc":[{"atb":[[1.2,604.24],[1.25,483.39],[1.3,201.41]],"id":38247334},{"atl":[[2.54,7.84],[3.85,16.96],[2.74,6.94],[3.35,10.28],[2.94,12.46]],"id":38247334},{"spn":1.92,"spf":"NaN","id":38247334},{"atb":[[1.98,61.66],[1.88,137.32],[1.93,129.94]],"id":42688799},{"atl":[[4.9,3.09],[9.8,2.74],[7.8,3.55],[5.9,2.46],[14.5,3.58]],"id":42688799},{"spn":3.44,"spf":"NaN","id":42688799},{"atb":[[2.82,66.4],[2.92,62.94],[3.05,29.47]],"id":39790958},{"atl":[[32,1.55],[10.5,1.27],[21,1.2],[8.2,1.67],[15.5,1.66]],"id":39790958},{"spn":5.62,"spf":"NaN","id":39790958},{"atb":[[4.1,19.49],[3.8,43.16],[3.55,47.39]],"id":41632950},{"atl":[[19.5,0.65],[95,0.51],[48,0.51],[14.5,0.89],[29,0.86]],"id":41632950},{"spn":9.3,"spf":"NaN","id":41632950},{"atb":[[3.25,53.71],[3.5,48.33],[3.75,21.97]],"id":41132571},{"atl":[[16.5,0.77],[65,0.75],[36,0.69],[11.5,1.14],[23,1.09]],"id":41132571},{"spn":7.62,"spf":"NaN","id":41132571},{"atb":[[1.6,100.7],[1.55,219.72],[1.5,241.69]],"id":42256451},{"atl":[[2.88,6.42],[3.2,5.49],[3.7,8.94],[4.4,7.1],[5.4,10.98]],"id":42256451},{"spn":2.24,"spf":"NaN","id":42256451},{"atb":[[4.8,31.8],[5.8,12.59],[5.3,28.1]],"id":38745817},{"atl":[[19,0.66],[90,0.27],[180,0.27],[46,0.53],[28,0.44]],"id":38745817},{"spn":12.4,"spf":"NaN","id":38745817}],"con":true,"img":false}]}
{"op":"mcm","clk":"5351837296","pt":1646176822544,"mc":[{"id":"1.195453775","rc":[{"atb":[[1.98,0],[1.88,0],[1.93,0]],"id":42688799},{"atl":[[4.9,0],[9.8,0],[7.8,0],[5.9,0],[14.5,0]],"id":42688799},{"atb":[[2.82,0],[2.92,0],[3.05,0]],"id":39790958},{"atl":[[32,0],[10.5,0],[21,0],[8.2,0],[15.5,0]],"id":39790958},{"atb":[[3.25,0],[3.5,0],[3.75,0]],"id":41132571},{"atl":[[16.5,0],[65,0],[36,0],[11.5,0],[23,0]],"id":41132571},{"atb":[[4.8,0],[5.8,0],[5.3,0]],"id":38745817},{"atl":[[19,0],[90,0],[180,0],[46,0],[28,0]],"id":38745817}],"con":true,"img":false}]}
{"op":"mcm","clk":"5351837809","pt":1646176834572,"mc":[{"id":"1.195453775","rc":[{"atb":[[1.8,151.06],[1.85,142.17],[1.9,67.13]],"id":42688799},{"atl":[[4,4.02],[8,3.45],[5,3.02],[10,5.37],[6,4.83]],"id":42688799},{"atb":[[2.4,86.32],[2.5,40.28],[2.3,92.96]],"id":39790958},{"atl":[[8,1.72],[10,2.68],[20,2.54],[6,2.41],[15,1.72]],"id":39790958},{"atb":[[3.45,49.32],[3.95,20.48],[3.7,44.75]],"id":41132571},{"atl":[[18.5,0.69],[85,0.57],[44,0.56],[13.5,0.96],[27,0.93]],"id":41132571},{"atb":[[5,30.21],[5.5,26.85],[6,12.08]],"id":38745817},{"atl":[[19.5,0.65],[95,0.25],[190,0.25],[48,0.51],[29,0.43]],"id":38745817}],"con":true,"img":false}]}
{"op":"mcm","clk":"5351846221","pt":1646177033057,"mc":[{"id":"1.195453775","rc":[{"atb":[[1.2,0],[1.25,0],[1.3,0]],"id":38247334},{"atl":[[2.54,0],[3.85,0],[2.74,0],[3.35,0],[2.94,0]],"id":38247334},{"spn":"NaN","spf":"NaN","id":38247334},{"spn":2.95,"spf":"NaN","id":42688799},{"spn":4.25,"spf":"NaN","id":39790958},{"spn":8.72,"spf":"NaN","id":41132571},{"atb":[[1.6,0],[1.55,0],[1.5,0]],"id":42256451},{"atl":[[2.88,0],[3.2,0],[3.7,0],[4.4,0],[5.4,0]],"id":42256451},{"spn":"NaN","spf":"NaN","id":42256451},{"spn":12.75,"spf":"NaN","id":38745817}],"con":true,"img":false}]}
{"op":"mcm","clk":"5351846461","pt":1646177038468,"mc":[{"id":"1.195453775","rc":[{"atb":[[1.2,604.24],[1.25,483.39],[1.3,201.41]],"id":38247334},{"atl":[[2.54,7.84],[3.85,16.96],[2.74,6.94],[3.35,10.28],[2.94,12.46]],"id":38247334},{"atb":[[1.6,100.7],[1.55,219.72],[1.5,241.69]],"id":42256451},{"atl":[[2.88,6.42],[3.2,5.49],[3.7,8.94],[4.4,7.1],[5.4,10.98]],"id":42256451}],"con":true,"img":false}]}
{"op":"mcm","clk":"5351867346","pt":1646177513884,"mc":[{"id":"1.195453775","rc":[{"spn":1.92,"spf":"NaN","id":38247334},{"atb":[[1.8,0],[1.85,0],[1.9,0]],"id":42688799},{"atl":[[4,0],[8,0],[5,0],[10,0],[6,0]],"id":42688799},{"spn":"NaN","spf":"NaN","id":42688799},{"atb":[[4.1,0],[3.8,0],[3.55,0]],"id":41632950},{"atl":[[19.5,0],[95,0],[48,0],[14.5,0],[29,0]],"id":41632950},{"spn":"NaN","spf":"NaN","id":41632950},{"atb":[[3.45,0],[3.95,0],[3.7,0]],"id":41132571},{"atl":[[18.5,0],[85,0],[44,0],[13.5,0],[27,0]],"id":41132571},{"spn":"NaN","spf":"NaN","id":41132571},{"atb":[[1.6,0],[1.55,0],[1.5,0]],"id":42256451},{"atl":[[2.88,0],[3.2,0],[3.7,0],[4.4,0],[5.4,0]],"id":42256451},{"atb":[[5,0],[5.5,0],[6,0]],"id":38745817},{"atl":[[19.5,0],[95,0],[190,0],[48,0],[29,0]],"id":38745817},{"spn":"NaN","spf":"NaN","id":38745817}],"con":true,"img":false}]}
{"op":"mcm","clk":"5351867764","pt":1646177524687,"mc":[{"id":"1.195453775","rc":[{"atb":[[1.85,142.17],[1.9,134.27],[1.95,63.6]],"id":42688799},{"atl":[[5.6,2.62],[7.2,3.89],[4.6,3.35],[9.2,2.94],[13,4.02]],"id":42688799},{"atb":[[4.3,18.31],[3.9,41.67],[3.65,45.6]],"id":41632950},{"atl":[[32,0.77],[21,0.6],[55,0.44],[110,0.44],[15.5,0.83]],"id":41632950},{"atb":[[3.6,46.47],[3.85,21.2],[3.35,51.42]],"id":41132571},{"atl":[[17.5,0.73],[75,0.65],[40,0.62],[12.5,1.05],[25,1]],"id":41132571},{"atb":[[1.6,201.41],[1.7,86.32],[1.65,185.92]],"id":42256451},{"atl":[[3.2,5.49],[3.7,4.47],[6.8,8.33],[4.4,7.1],[5.4,5.49]],"id":42256451},{"atb":[[8,8.63],[6,24.16],[7,20.14]],"id":38745817},{"atl":[[75,0.16],[150,0.16],[40,0.31],[350,0.13],[250,0.09]],"id":38745817}],"con":true,"img":false}]}
{"op":"mcm","clk":"5351869726","pt":1646177573150,"mc":[{"id":"1.195453775","rc":[{"atb":[[4.3,0],[3.9,0],[3.65,0]],"id":41632950},{"atl":[[32,0],[21,0],[55,0],[110,0],[15.5,0]],"id":41632950},{"atb":[[3.6,0],[3.85,0],[3.35,0]],"id":41132571},{"atl":[[17.5,0],[75,0],[40,0],[12.5,0],[25,0]],"id":41132571}],"con":true,"img":false}]}
{"op":"mcm","clk":"5351870292","pt":1646177583506,"mc":[{"id":"1.195453775","rc":[{"spn":3.27,"spf":"NaN","id":42688799},{"atb":[[4,40.28],[4.5,34.52],[5,15.1]],"id":41632950},{"atl":[[17,0.75],[70,0.34],[140,0.34],[38,0.65],[24,0.52]],"id":41632950},{"spn":11.0,"spf":"NaN","id":41632950},{"atb":[[3.45,49.32],[3.95,20.48],[3.7,44.75]],"id":41132571},{"atl":[[18.5,0.69],[85,0.57],[44,0.56],[13.5,0.96],[27,0.93]],"id":41132571},{"spn":8.72,"spf":"NaN","id":41132571},{"spn":2.45,"spf":"NaN","id":42256451},{"spn":24.0,"spf":"NaN","id":38745817}],"con":true,"img":false}]}
{"op":"mcm","clk":"5351942655","pt":1646178953274,"mc":[{"id":"1.195453775","rc":[{"atb":[[1.2,0],[1.25,0],[1.3,0]],"id":38247334},{"atl":[[2.54,0],[3.85,0],[2.74,0],[3.35,0],[2.94,0]],"id":38247334},{"spn":"NaN","spf":"NaN","id":38247334},{"atb":[[1.85,0],[1.9,0],[1.95,0]],"id":42688799},{"atl":[[5.6,0],[7.2,0],[4.6,0],[9.2,0],[13,0]],"id":42688799},{"spn":"NaN","spf":"NaN","id":42688799},{"atb":[[2.4,0],[2.5,0],[2.3,0]],"id":39790958},{"atl":[[8,0],[10,0],[20,0],[6,0],[15,0]],"id":39790958},{"spn":"NaN","spf":"NaN","id":39790958},{"atb":[[4,0],[4.5,0],[5,0]],"id":41632950},{"atl":[[17,0],[70,0],[140,0],[38,0],[24,0]],"id":41632950},{"spn":"NaN","spf":"NaN","id":41632950},{"atb":[[3.45,0],[3.95,0],[3.7,0]],"id":41132571},{"atl":[[18.5,0],[85,0],[44,0],[13.5,0],[27,0]],"id":41132571},{"spn":"NaN","spf":"NaN","id":41132571},{"atb":[[1.6,0],[1.7,0],[1.65,0]],"id":42256451},{"atl":[[3.2,0],[3.7,0],[6.8,0],[4.4,0],[5.4,0]],"id":42256451},{"spn":"NaN","spf":"NaN","id":42256451},{"atb":[[8,0],[6,0],[7,0]],"id":38745817},{"atl":[[75,0],[150,0],[40,0],[350,0],[250,0]],"id":38745817},{"spn":"NaN","spf":"NaN","id":38745817}],"con":true,"img":false}]}
{"op":"mcm","clk":"5351943008","pt":1646178960500,"mc":[{"id":"1.195453775","rc":[{"atb":[[1.4,151.06],[1.3,402.83],[1.35,345.28]],"id":38247334},{"atl":[[4.3,14.64],[2.86,6.49],[2.66,7.27],[3.15,11.24],[3.65,9.11]],"id":38247334},{"atb":[[1.85,142.17],[1.9,134.27],[1.95,63.6]],"id":42688799},{"atl":[[5.6,2.62],[7.2,3.89],[4.6,3.35],[9.2,2.94],[13,4.02]],"id":42688799},{"atb":[[2.5,80.56],[2.6,75.53],[2.7,35.54]],"id":39790958},{"atl":[[16.5,1.55],[8.6,1.58],[11.5,2.3],[23,2.19],[6.6,2.15]],"id":39790958},{"atb":[[4.3,18.31],[3.9,41.67],[3.65,45.6]],"id":41632950},{"atl":[[32,0.77],[21,0.6],[55,0.44],[110,0.44],[15.5,0.83]],"id":41632950},{"atb":[[4.3,18.31],[3.9,41.67],[3.65,45.6]],"id":41132571},{"atl":[[32,0.77],[21,0.6],[55,0.44],[110,0.44],[15.5,0.83]],"id":41132571},{"atb":[[1.6,201.41],[1.55,219.72],[1.65,92.96]],"id":42256451},{"atl":[[3.45,4.93],[3.95,8.19],[4.9,6.19],[2.98,6.1],[5.9,9.86]],"id":42256451},{"atb":[[7.4,18.88],[8.4,16.33],[9.4,7.19]],"id":38745817},{"atl":[[310,0.07],[410,0.11],[210,0.11],[55,0.22],[110,0.1]],"id":38745817}],"con":true,"img":false}]}
{"op":"mcm","clk":"5352003873","pt":1646180202622,"mc":[{"id":"1.195453775","marketDefinition":{"bspMarket":true,"turnInPlayEnabled":false,"persistenceEnabled":false,"marketBaseRate":7.0,"eventId":"31272499","eventTypeId":"4339","numberOfWinners":2,"bettingType":"ODDS","marketType":"PLACE","marketTime":"2022-03-02T10:32:00.000Z","suspendTime":"2022-03-02T10:32:00.000Z","bspReconciled":false,"complete":true,"inPlay":false,"crossMatching":false,"runnersVoidable":false,"numberOfActiveRunners":7,"betDelay":0,"status":"OPEN","runners":[{"status":"ACTIVE","sortPriority":1,"id":38247334,"name":"1. Noise Works"},{"status":"ACTIVE","sortPriority":2,"id":39790958,"name":"2. Wise Decisions"},{"status":"ACTIVE","sortPriority":3,"id":38745817,"name":"3. Redeemers Kid"},{"status":"ACTIVE","sortPriority":4,"id":42688799,"name":"4. Velocity Kayla"},{"status":"ACTIVE","sortPriority":5,"id":41632950,"name":"6. Swift Anna"},{"status":"ACTIVE","sortPriority":6,"id":41132571,"name":"7. Dr Xena"},{"status":"ACTIVE","sortPriority":7,"id":42256451,"name":"8. Swift Twitch"}],"regulators":["MR_INT"],"venue":"Rockhampton","countryCode":"AU","discountAllowed":true,"timezone":"Australia/Queensland","openDate":"2022-03-02T08:34:00.000Z","version":4382437859,"name":"To Be Placed","eventName":"Rockhampton (AUS) 2nd Mar"},"rc":[{"atb":[[1.4,151.07],[1.3,402.87],[1.35,345.32]],"id":38247334},{"atl":[[4.3,14.65],[2.86,6.5],[2.66,7.27],[3.15,11.24],[3.65,9.11]],"id":38247334},{"spn":2.03,"spf":"NaN","id":38247334},{"atb":[[1.85,142.19],[1.9,134.29],[1.95,63.61]],"id":42688799},{"atl":[[5.6,2.62],[7.2,3.89],[4.6,3.35],[9.2,2.94],[13,4.02]],"id":42688799},{"spn":3.27,"spf":"NaN","id":42688799},{"atb":[[2.5,80.57],[2.6,75.53],[2.7,35.54]],"id":39790958},{"atl":[[16.5,1.55],[8.6,1.58],[11.5,2.3],[23,2.19],[6.6,2.15]],"id":39790958},{"spn":4.65,"spf":"NaN","id":39790958},{"atb":[[4.3,18.31],[3.9,41.67],[3.65,45.6]],"id":41632950},{"atl":[[32,0.77],[21,0.6],[55,0.44],[110,0.44],[15.5,0.83]],"id":41632950},{"spn":9.9,"spf":"NaN","id":41632950},{"atb":[[4.3,18.31],[3.9,41.67],[3.65,45.6]],"id":41132571},{"atl":[[32,0.77],[21,0.6],[55,0.44],[110,0.44],[15.5,0.83]],"id":41132571},{"spn":9.9,"spf":"NaN","id":41132571},{"atb":[[1.6,201.43],[1.55,219.75],[1.65,92.97]],"id":42256451},{"atl":[[3.45,4.93],[3.95,8.19],[4.9,6.19],[2.98,6.1],[5.9,9.86]],"id":42256451},{"spn":2.31,"spf":"NaN","id":42256451},{"atb":[[7.4,18.88],[8.4,16.33],[9.4,7.19]],"id":38745817},{"atl":[[310,0.07],[410,0.11],[210,0.11],[55,0.22],[110,0.1]],"id":38745817},{"spn":32.2,"spf":"NaN","id":38745817}],"con":true,"img":true}]}
{"op":"mcm","clk":"5352146206","pt":1646183572661,"mc":[{"id":"1.195453775","marketDefinition":{"bspMarket":true,"turnInPlayEnabled":false,"persistenceEnabled":false,"marketBaseRate":7.0,"eventId":"31272499","eventTypeId":"4339","numberOfWinners":2,"bettingType":"ODDS","marketType":"PLACE","marketTime":"2022-03-02T10:32:00.000Z","suspendTime":"2022-03-02T10:32:00.000Z","bspReconciled":false,"complete":true,"inPlay":false,"crossMatching":false,"runnersVoidable":false,"numberOfActiveRunners":7,"betDelay":0,"status":"OPEN","runners":[{"status":"ACTIVE","sortPriority":1,"id":38247334,"name":"1. Noise Works"},{"status":"ACTIVE","sortPriority":2,"id":39790958,"name":"2. Wise Decisions"},{"status":"ACTIVE","sortPriority":3,"id":38745817,"name":"3. Redeemers Kid"},{"status":"ACTIVE","sortPriority":4,"id":42688799,"name":"4. Velocity Kayla"},{"status":"ACTIVE","sortPriority":5,"id":41632950,"name":"6. Swift Anna"},{"status":"ACTIVE","sortPriority":6,"id":41132571,"name":"7. Dr Xena"},{"status":"ACTIVE","sortPriority":7,"id":42256451,"name":"8. Swift Twitch"}],"regulators":["MR_INT"],"venue":"Rockhampton","countryCode":"AU","discountAllowed":true,"timezone":"Australia/Queensland","openDate":"2022-03-02T08:28:00.000Z","version":4382597842,"name":"To Be Placed","eventName":"Rockhampton (AUS) 2nd Mar"},"rc":[],"con":true,"img":false}]}
{"op":"mcm","clk":"5352161237","pt":1646183970487,"mc":[{"id":"1.195453775","marketDefinition":{"bspMarket":true,"turnInPlayEnabled":false,"persistenceEnabled":false,"marketBaseRate":7.0,"eventId":"31272499","eventTypeId":"4339","numberOfWinners":2,"bettingType":"ODDS","marketType":"PLACE","marketTime":"2022-03-02T10:24:00.000Z","suspendTime":"2022-03-02T10:24:00.000Z","bspReconciled":false,"complete":true,"inPlay":false,"crossMatching":false,"runnersVoidable":false,"numberOfActiveRunners":7,"betDelay":0,"status":"OPEN","runners":[{"status":"ACTIVE","sortPriority":1,"id":38247334,"name":"1. Noise Works"},{"status":"ACTIVE","sortPriority":2,"id":39790958,"name":"2. Wise Decisions"},{"status":"ACTIVE","sortPriority":3,"id":38745817,"name":"3. Redeemers Kid"},{"status":"ACTIVE","sortPriority":4,"id":42688799,"name":"4. Velocity Kayla"},{"status":"ACTIVE","sortPriority":5,"id":41632950,"name":"6. Swift Anna"},{"status":"ACTIVE","sortPriority":6,"id":41132571,"name":"7. Dr Xena"},{"status":"ACTIVE","sortPriority":7,"id":42256451,"name":"8. Swift Twitch"}],"regulators":["MR_INT"],"venue":"Rockhampton","countryCode":"AU","discountAllowed":true,"timezone":"Australia/Queensland","openDate":"2022-03-02T08:28:00.000Z","version":4382604991,"name":"To Be Placed","eventName":"Rockhampton (AUS) 2nd Mar"},"rc":[],"con":true,"img":false}]}
{"op":"mcm","clk":"5352237993","pt":1646185602657,"mc":[{"id":"1.195453775","marketDefinition":{"bspMarket":true,"turnInPlayEnabled":false,"persistenceEnabled":false,"marketBaseRate":7.0,"eventId":"31272499","eventTypeId":"4339","numberOfWinners":2,"bettingType":"ODDS","marketType":"PLACE","marketTime":"2022-03-02T10:24:00.000Z","suspendTime":"2022-03-02T10:24:00.000Z","bspReconciled":false,"complete":true,"inPlay":false,"crossMatching":false,"runnersVoidable":false,"numberOfActiveRunners":7,"betDelay":0,"status":"OPEN","runners":[{"status":"ACTIVE","sortPriority":1,"id":38247334,"name":"1. Noise Works"},{"status":"ACTIVE","sortPriority":2,"id":39790958,"name":"2. Wise Decisions"},{"status":"ACTIVE","sortPriority":3,"id":38745817,"name":"3. Redeemers Kid"},{"status":"ACTIVE","sortPriority":4,"id":42688799,"name":"4. Velocity Kayla"},{"status":"ACTIVE","sortPriority":5,"id":41632950,"name":"6. Swift Anna"},{"status":"ACTIVE","sortPriority":6,"id":41132571,"name":"7. Dr Xena"},{"status":"ACTIVE","sortPriority":7,"id":42256451,"name":"8. Swift Twitch"}],"regulators":["MR_INT"],"venue":"Rockhampton","countryCode":"AU","discountAllowed":true,"timezone":"Australia/Queensland","openDate":"2022-03-02T08:28:00.000Z","version":4382604991,"name":"To Be Placed","eventName":"Rockhampton (AUS) 2nd Mar"},"rc":[{"atb":[[1.4,151.31],[1.3,403.51],[1.35,345.86]],"id":38247334},{"atl":[[4.3,14.67],[2.86,6.51],[2.66,7.29],[3.15,11.26],[3.65,9.13]],"id":38247334},{"spn":2.03,"spf":"NaN","id":38247334},{"atb":[[1.85,142.41],[1.9,134.5],[1.95,63.71]],"id":42688799},{"atl":[[5.6,2.63],[7.2,3.9],[4.6,3.36],[9.2,2.94],[13,4.03]],"id":42688799},{"spn":3.27,"spf":"NaN","id":42688799},{"atb":[[2.5,80.7],[2.6,75.65],[2.7,35.6]],"id":39790958},{"atl":[[16.5,1.55],[8.6,1.59],[11.5,2.3],[23,2.2],[6.6,2.15]],"id":39790958},{"spn":4.65,"spf":"NaN","id":39790958},{"atb":[[4.3,18.34],[3.9,41.74],[3.65,45.67]],"id":41632950},{"atl":[[32,0.77],[21,0.6],[55,0.44],[110,0.44],[15.5,0.83]],"id":41632950},{"spn":9.9,"spf":"NaN","id":41632950},{"atb":[[4.3,18.34],[3.9,41.74],[3.65,45.67]],"id":41132571},{"atl":[[32,0.77],[21,0.6],[55,0.44],[110,0.44],[15.5,0.83]],"id":41132571},{"spn":9.9,"spf":"NaN","id":41132571},{"atb":[[1.6,201.75],[1.55,220.09],[1.65,93.11]],"id":42256451},{"atl":[[3.45,4.94],[3.95,8.2],[4.9,6.2],[2.98,6.11],[5.9,9.88]],"id":42256451},{"spn":2.31,"spf":"NaN","id":42256451},{"atb":[[7.4,18.91],[8.4,16.35],[9.4,7.2]],"id":38745817},{"atl":[[310,0.07],[410,0.11],[210,0.11],[55,0.22],[110,0.1]],"id":38745817},{"spn":32.2,"spf":"NaN","id":38745817}],"con":true,"img":true}]}
{"op":"mcm","clk":"5352465290","pt":1646191002606,"mc":[{"id":"1.195453775","marketDefinition":{"bspMarket":true,"turnInPlayEnabled":false,"persistenceEnabled":false,"marketBaseRate":7.0,"eventId":"31272499","eventTypeId":"4339","numberOfWinners":2,"bettingType":"ODDS","marketType":"PLACE","marketTime":"2022-03-02T10:24:00.000Z","suspendTime":"2022-03-02T10:24:00.000Z","bspReconciled":false,"complete":true,"inPlay":false,"crossMatching":false,"runnersVoidable":false,"numberOfActiveRunners":7,"betDelay":0,"status":"OPEN","runners":[{"status":"ACTIVE","sortPriority":1,"id":38247334,"name":"1. Noise Works"},{"status":"ACTIVE","sortPriority":2,"id":39790958,"name":"2. Wise Decisions"},{"status":"ACTIVE","sortPriority":3,"id":38745817,"name":"3. Redeemers Kid"},{"status":"ACTIVE","sortPriority":4,"id":42688799,"name":"4. Velocity Kayla"},{"status":"ACTIVE","sortPriority":5,"id":41632950,"name":"6. Swift Anna"},{"status":"ACTIVE","sortPriority":6,"id":41132571,"name":"7. Dr Xena"},{"status":"ACTIVE","sortPriority":7,"id":42256451,"name":"8. Swift Twitch"}],"regulators":["MR_INT"],"venue":"Rockhampton","countryCode":"AU","discountAllowed":true,"timezone":"Australia/Queensland","openDate":"2022-03-02T08:28:00.000Z","version":4382604991,"name":"To Be Placed","eventName":"Rockhampton (AUS) 2nd Mar"},"rc":[{"atb":[[1.4,151.57],[1.3,404.19],[1.35,346.45]],"id":38247334},{"atl":[[4.3,14.69],[2.86,6.52],[2.66,7.3],[3.15,11.27],[3.65,9.14]],"id":38247334},{"spn":2.03,"spf":"NaN","id":38247334},{"atb":[[1.85,142.65],[1.9,134.73],[1.95,63.81]],"id":42688799},{"atl":[[5.6,2.63],[7.2,3.91],[4.6,3.37],[9.2,2.95],[13,4.04]],"id":42688799},{"spn":3.27,"spf":"NaN","id":42688799},{"atb":[[2.5,80.83],[2.6,75.78],[2.7,35.66]],"id":39790958},{"atl":[[16.5,1.56],[8.6,1.59],[11.5,2.31],[23,2.2],[6.6,2.16]],"id":39790958},{"spn":4.65,"spf":"NaN","id":39790958},{"atb":[[4.3,18.37],[3.9,41.81],[3.65,45.75]],"id":41632950},{"atl":[[32,0.78],[21,0.6],[55,0.44],[110,0.44],[15.5,0.83]],"id":41632950},{"spn":9.9,"spf":"NaN","id":41632950},{"atb":[[4.3,18.37],[3.9,41.81],[3.65,45.75]],"id":41132571},{"atl":[[32,0.78],[21,0.6],[55,0.44],[110,0.44],[15.5,0.83]],"id":41132571},{"spn":9.9,"spf":"NaN","id":41132571},{"atb":[[1.6,202.09],[1.55,220.47],[1.65,93.27]],"id":42256451},{"atl":[[3.45,4.94],[3.95,8.22],[4.9,6.21],[2.98,6.12],[5.9,9.89]],"id":42256451},{"spn":2.31,"spf":"NaN","id":42256451},{"atb":[[7.4,18.94],[8.4,16.38],[9.4,7.21]],"id":38745817},{"atl":[[310,0.07],[410,0.12],[210,0.11],[55,0.22],[110,0.1]],"id":38745817},{"spn":32.2,"spf":"NaN","id":38745817}],"con":true,"img":true}]}
{"op":"mcm","clk":"5352606085","pt":1646194853959,"mc":[{"id":"1.195453775","rc":[{"atb":[[1.4,151.57],[1.3,404.19],[1.35,346.45]],"id":38247334},{"atl":[[4.3,14.69],[2.86,6.52],[2.66,7.3],[3.15,11.27],[3.65,9.14]],"id":38247334},{"spn":2.03,"spf":"NaN","id":38247334},{"atb":[[1.85,142.65],[1.9,134.73],[1.95,63.81]],"id":42688799},{"atl":[[5.6,2.63],[7.2,3.91],[4.6,3.37],[9.2,2.95],[13,4.04]],"id":42688799},{"spn":3.27,"spf":"NaN","id":42688799},{"atb":[[2.5,80.83],[2.6,75.78],[2.7,35.66]],"id":39790958},{"atl":[[16.5,1.56],[8.6,1.59],[11.5,2.31],[23,2.2],[6.6,2.16]],"id":39790958},{"spn":4.65,"spf":"NaN","id":39790958},{"atb":[[4.3,0],[3.9,0],[3.65,0]],"id":41632950},{"atl":[[32,0],[21,0],[55,0],[110,0],[15.5,0]],"id":41632950},{"atb":[[4.3,18.37],[3.9,41.81],[3.65,45.75]],"id":41132571},{"atl":[[32,0.78],[21,0.6],[55,0.44],[110,0.44],[15.5,0.83]],"id":41132571},{"spn":9.9,"spf":"NaN","id":41132571},{"atb":[[1.6,202.09],[1.55,220.47],[1.65,93.27]],"id":42256451},{"atl":[[3.45,4.94],[3.95,8.22],[4.9,6.21],[2.98,6.12],[5.9,9.89]],"id":42256451},{"spn":2.31,"spf":"NaN","id":42256451},{"atb":[[7.4,18.94],[8.4,16.38],[9.4,7.21]],"id":38745817},{"atl":[[310,0.07],[410,0.12],[210,0.11],[55,0.22],[110,0.1]],"id":38745817},{"spn":32.2,"spf":"NaN","id":38745817}],"con":true,"img":false}]}
{"op":"mcm","clk":"5352606640","pt":1646194869169,"mc":[{"id":"1.195453775","rc":[{"atb":[[4.3,18.37],[3.9,41.81],[3.65,45.75]],"id":41632950},{"atl":[[32,0.78],[21,0.6],[55,0.44],[110,0.44],[15.5,0.83]],"id":41632950}],"con":true,"img":false}]}
{"op":"mcm","clk":"5352664632","pt":1646196402630,"mc":[{"id":"1.195453775","marketDefinition":{"bspMarket":true,"turnInPlayEnabled":false,"persistenceEnabled":false,"marketBaseRate":7.0,"eventId":"31272499","eventTypeId":"4339","numberOfWinners":2,"bettingType":"ODDS","marketType":"PLACE","marketTime":"2022-03-02T10:24:00.000Z","suspendTime":"2022-03-02T10:24:00.000Z","bspReconciled":false,"complete":true,"inPlay":false,"crossMatching":false,"runnersVoidable":false,"numberOfActiveRunners":7,"betDelay":0,"status":"OPEN","runners":[{"status":"ACTIVE","sortPriority":1,"id":38247334,"name":"1. Noise Works"},{"status":"ACTIVE","sortPriority":2,"id":39790958,"name":"2. Wise Decisions"},{"status":"ACTIVE","sortPriority":3,"id":38745817,"name":"3. Redeemers Kid"},{"status":"ACTIVE","sortPriority":4,"id":42688799,"name":"4. Velocity Kayla"},{"status":"ACTIVE","sortPriority":5,"id":41632950,"name":"6. Swift Anna"},{"status":"ACTIVE","sortPriority":6,"id":41132571,"name":"7. Dr Xena"},{"status":"ACTIVE","sortPriority":7,"id":42256451,"name":"8. Swift Twitch"}],"regulators":["MR_INT"],"venue":"Rockhampton","countryCode":"AU","discountAllowed":true,"timezone":"Australia/Queensland","openDate":"2022-03-02T08:28:00.000Z","version":4382604991,"name":"To Be Placed","eventName":"Rockhampton (AUS) 2nd Mar"},"rc":[{"atb":[[1.4,151.57],[1.3,404.19],[1.35,346.45]],"id":38247334},{"atl":[[4.3,14.69],[2.86,6.52],[2.66,7.3],[3.15,11.27],[3.65,9.14]],"id":38247334},{"spn":2.03,"spf":"NaN","id":38247334},{"atb":[[1.85,142.65],[1.9,134.73],[1.95,63.81]],"id":42688799},{"atl":[[5.6,2.63],[7.2,3.91],[4.6,3.37],[9.2,2.95],[13,4.04]],"id":42688799},{"spn":3.27,"spf":"NaN","id":42688799},{"atb":[[2.5,80.83],[2.6,75.78],[2.7,35.66]],"id":39790958},{"atl":[[16.5,1.56],[8.6,1.59],[11.5,2.31],[23,2.2],[6.6,2.16]],"id":39790958},{"spn":4.65,"spf":"NaN","id":39790958},{"atb":[[4.3,18.37],[3.9,41.81],[3.65,45.75]],"id":41632950},{"atl":[[32,0.78],[21,0.6],[55,0.44],[110,0.44],[15.5,0.83]],"id":41632950},{"spn":9.9,"spf":"NaN","id":41632950},{"atb":[[4.3,18.37],[3.9,41.81],[3.65,45.75]],"id":41132571},{"atl":[[32,0.78],[21,0.6],[55,0.44],[110,0.44],[15.5,0.83]],"id":41132571},{"spn":9.9,"spf":"NaN","id":41132571},{"atb":[[1.6,202.09],[1.55,220.47],[1.65,93.27]],"id":42256451},{"atl":[[3.45,4.94],[3.95,8.22],[4.9,6.21],[2.98,6.12],[5.9,9.89]],"id":42256451},{"spn":2.31,"spf":"NaN","id":42256451},{"atb":[[7.4,18.94],[8.4,16.38],[9.4,7.21]],"id":38745817},{"atl":[[310,0.07],[410,0.12],[210,0.11],[55,0.22],[110,0.1]],"id":38745817},{"spn":32.2,"spf":"NaN","id":38745817}],"con":true,"img":true}]}
{"op":"mcm","clk":"5352822084","pt":1646201802637,"mc":[{"id":"1.195453775","marketDefinition":{"bspMarket":true,"turnInPlayEnabled":false,"persistenceEnabled":false,"marketBaseRate":7.0,"eventId":"31272499","eventTypeId":"4339","numberOfWinners":2,"bettingType":"ODDS","marketType":"PLACE","marketTime":"2022-03-02T10:24:00.000Z","suspendTime":"2022-03-02T10:24:00.000Z","bspReconciled":false,"complete":true,"inPlay":false,"crossMatching":false,"runnersVoidable":false,"numberOfActiveRunners":7,"betDelay":0,"status":"OPEN","runners":[{"status":"ACTIVE","sortPriority":1,"id":38247334,"name":"1. Noise Works"},{"status":"ACTIVE","sortPriority":2,"id":39790958,"name":"2. Wise Decisions"},{"status":"ACTIVE","sortPriority":3,"id":38745817,"name":"3. Redeemers Kid"},{"status":"ACTIVE","sortPriority":4,"id":42688799,"name":"4. Velocity Kayla"},{"status":"ACTIVE","sortPriority":5,"id":41632950,"name":"6. Swift Anna"},{"status":"ACTIVE","sortPriority":6,"id":41132571,"name":"7. Dr Xena"},{"status":"ACTIVE","sortPriority":7,"id":42256451,"name":"8. Swift Twitch"}],"regulators":["MR_INT"],"venue":"Rockhampton","countryCode":"AU","discountAllowed":true,"timezone":"Australia/Queensland","openDate":"2022-03-02T08:28:00.000Z","version":4382604991,"name":"To Be Placed","eventName":"Rockhampton (AUS) 2nd Mar"},"rc":[{"atb":[[1.4,151.51],[1.3,404.04],[1.35,346.32]],"id":38247334},{"atl":[[4.3,14.69],[2.86,6.51],[2.66,7.3],[3.15,11.27],[3.65,9.14]],"id":38247334},{"spn":2.03,"spf":"NaN","id":38247334},{"atb":[[1.85,142.6],[1.9,134.68],[1.95,63.79]],"id":42688799},{"atl":[[5.6,2.63],[7.2,3.9],[4.6,3.36],[9.2,2.95],[13,4.04]],"id":42688799},{"spn":3.27,"spf":"NaN","id":42688799},{"atb":[[2.5,80.8],[2.6,75.75],[2.7,35.64]],"id":39790958},{"atl":[[16.5,1.56],[8.6,1.59],[11.5,2.3],[23,2.2],[6.6,2.16]],"id":39790958},{"spn":4.65,"spf":"NaN","id":39790958},{"atb":[[4.3,18.36],[3.9,41.79],[3.65,45.73]],"id":41632950},{"atl":[[32,0.78],[21,0.6],[55,0.44],[110,0.44],[15.5,0.83]],"id":41632950},{"spn":9.9,"spf":"NaN","id":41632950},{"atb":[[4.3,18.36],[3.9,41.79],[3.65,45.73]],"id":41132571},{"atl":[[32,0.78],[21,0.6],[55,0.44],[110,0.44],[15.5,0.83]],"id":41132571},{"spn":9.9,"spf":"NaN","id":41132571},{"atb":[[1.6,202.02],[1.55,220.38],[1.65,93.24]],"id":42256451},{"atl":[[3.45,4.94],[3.95,8.21],[4.9,6.21],[2.98,6.12],[5.9,9.89]],"id":42256451},{"spn":2.31,"spf":"NaN","id":42256451},{"atb":[[7.4,18.94],[8.4,16.38],[9.4,7.21]],"id":38745817},{"atl":[[310,0.07],[410,0.12],[210,0.11],[55,0.22],[110,0.1]],"id":38745817},{"spn":32.2,"spf":"NaN","id":38745817}],"con":true,"img":true}]}
{"op":"mcm","clk":"5353027459","pt":1646207202673,"mc":[{"id":"1.195453775","marketDefinition":{"bspMarket":true,"turnInPlayEnabled":false,"persistenceEnabled":false,"marketBaseRate":7.0,"eventId":"31272499","eventTypeId":"4339","numberOfWinners":2,"bettingType":"ODDS","marketType":"PLACE","marketTime":"2022-03-02T10:24:00.000Z","suspendTime":"2022-03-02T10:24:00.000Z","bspReconciled":false,"complete":true,"inPlay":false,"crossMatching":false,"runnersVoidable":false,"numberOfActiveRunners":7,"betDelay":0,"status":"OPEN","runners":[{"status":"ACTIVE","sortPriority":1,"id":38247334,"name":"1. Noise Works"},{"status":"ACTIVE","sortPriority":2,"id":39790958,"name":"2. Wise Decisions"},{"status":"ACTIVE","sortPriority":3,"id":38745817,"name":"3. Redeemers Kid"},{"status":"ACTIVE","sortPriority":4,"id":42688799,"name":"4. Velocity Kayla"},{"status":"ACTIVE","sortPriority":5,"id":41632950,"name":"6. Swift Anna"},{"status":"ACTIVE","sortPriority":6,"id":41132571,"name":"7. Dr Xena"},{"status":"ACTIVE","sortPriority":7,"id":42256451,"name":"8. Swift Twitch"}],"regulators":["MR_INT"],"venue":"Rockhampton","countryCode":"AU","discountAllowed":true,"timezone":"Australia/Queensland","openDate":"2022-03-02T08:28:00.000Z","version":4382604991,"name":"To Be Placed","eventName":"Rockhampton (AUS) 2nd Mar"},"rc":[{"atb":[[1.4,151.47],[1.3,403.93],[1.35,346.22]],"id":38247334},{"atl":[[4.3,14.68],[2.86,6.51],[2.66,7.29],[3.15,11.27],[3.65,9.14]],"id":38247334},{"spn":2.03,"spf":"NaN","id":38247334},{"atb":[[1.85,142.56],[1.9,134.64],[1.95,63.77]],"id":42688799},{"atl":[[5.6,2.63],[7.2,3.9],[4.6,3.36],[9.2,2.95],[13,4.03]],"id":42688799},{"spn":3.27,"spf":"NaN","id":42688799},{"atb":[[2.5,80.78],[2.6,75.73],[2.7,35.63]],"id":39790958},{"atl":[[16.5,1.56],[8.6,1.59],[11.5,2.3],[23,2.2],[6.6,2.16]],"id":39790958},{"spn":4.65,"spf":"NaN","id":39790958},{"atb":[[4.3,18.36],[3.9,41.78],[3.65,45.72]],"id":41632950},{"atl":[[32,0.78],[21,0.6],[55,0.44],[110,0.44],[15.5,0.83]],"id":41632950},{"spn":9.9,"spf":"NaN","id":41632950},{"atb":[[4.3,18.36],[3.9,41.78],[3.65,45.72]],"id":41132571},{"atl":[[32,0.78],[21,0.6],[55,0.44],[110,0.44],[15.5,0.83]],"id":41132571},{"spn":9.9,"spf":"NaN","id":41132571},{"atb":[[1.6,201.96],[1.55,220.32],[1.65,93.21]],"id":42256451},{"atl":[[3.45,4.94],[3.95,8.21],[4.9,6.21],[2.98,6.11],[5.9,9.89]],"id":42256451},{"spn":2.31,"spf":"NaN","id":42256451},{"atb":[[7.4,18.93],[8.4,16.37],[9.4,7.21]],"id":38745817},{"atl":[[310,0.07],[410,0.12],[210,0.11],[55,0.22],[110,0.1]],"id":38745817},{"spn":32.2,"spf":"NaN","id":38745817}],"con":true,"img":true}]}
{"op":"mcm","clk":"5353219865","pt":1646211298992,"mc":[{"id":"1.195453775","rc":[{"atb":[[1.4,151.47],[1.36,83.04],[1.3,403.93],[1.24,230.28],[1.35,346.22]],"id":38247334},{"atl":[[4.3,14.68],[2.86,6.51],[3.1,26.31],[2.66,7.29],[3.15,11.27],[2.78,24.53],[3.65,9.14]],"id":38247334},{"atb":[[1.67,93.88],[1.85,142.56],[1.9,134.64],[1.91,47.98],[1.95,63.77]],"id":42688799},{"atl":[[5.6,2.63],[7.2,3.9],[4.6,3.36],[9.2,2.95],[6.2,8.39],[6.8,10.91],[13,4.03]],"id":42688799},{"atb":[[2.5,80.78],[2.6,75.73],[2.2,54.03],[2.62,26.95],[2.7,35.63]],"id":39790958},{"atl":[[16.5,1.56],[8.6,1.59],[10.5,4.59],[11,6.55],[11.5,2.3],[23,2.2],[6.6,2.16]],"id":39790958},{"atb":[[4.3,31.59],[3.95,21.28],[3.9,41.78],[3.65,45.72]],"id":41632950},{"atl":[[32,0.78],[21,0.6],[24,2.72],[26,2.72],[55,0.44],[110,0.44],[15.5,0.83]],"id":41632950},{"spn":9.9,"spf":"NaN","id":41632950},{"atb":[[4.3,18.36],[4.1,14.08],[3.7,20.21],[3.9,41.78],[3.65,45.72]],"id":41132571},{"atl":[[32,0.78],[21,0.6],[22,2.72],[25,2.72],[55,0.44],[110,0.44],[15.5,0.83]],"id":41132571},{"atb":[[1.4,164.84],[1.6,201.96],[1.55,220.32],[1.65,93.21],[1.61,70.14]],"id":42256451},{"atl":[[3.45,4.94],[4.5,17.46],[3.95,8.21],[4.1,14.08],[4.9,6.21],[2.98,6.11],[5.9,9.89]],"id":42256451},{"atb":[[8.2,6.06],[7.4,18.93],[6.8,10.28],[8.4,16.37],[9.4,7.21]],"id":38745817},{"atl":[[65,2.72],[70,2.72],[55,0.22]],"id":38745817}],"con":true,"img":false}]}
{"op":"mcm","clk":"5353222288","pt":1646211354499,"mc":[{"id":"1.195453775","rc":[{"atb":[[8.2,0]],"id":38745817}],"con":true,"img":false}]}
{"op":"mcm","clk":"5353222292","pt":1646211354601,"mc":[{"id":"1.195453775","rc":[{"atb":[[8.6,6.06]],"id":38745817}],"con":true,"img":false}]}
{"op":"mcm","clk":"5353222922","pt":1646211368122,"mc":[{"id":"1.195453775","rc":[{"atb":[[1.91,0]],"id":42688799},{"atb":[[3.7,0]],"id":41132571},{"atb":[[6.8,0]],"id":38745817}],"con":true,"img":false}]}
{"op":"mcm","clk":"5353222926","pt":1646211368225,"mc":[{"id":"1.195453775","rc":[{"atb":[[1.96,47.98]],"id":42688799},{"atb":[[3.95,20.21]],"id":41132571},{"atb":[[7.6,10.28]],"id":38745817}],"con":true,"img":false}]}
{"op":"mcm","clk":"5353298812","pt":1646212602692,"mc":[{"id":"1.195453775","marketDefinition":{"bspMarket":true,"turnInPlayEnabled":false,"persistenceEnabled":false,"marketBaseRate":7.0,"eventId":"31272499","eventTypeId":"4339","numberOfWinners":2,"bettingType":"ODDS","marketType":"PLACE","marketTime":"2022-03-02T10:24:00.000Z","suspendTime":"2022-03-02T10:24:00.000Z","bspReconciled":false,"complete":true,"inPlay":false,"crossMatching":false,"runnersVoidable":false,"numberOfActiveRunners":7,"betDelay":0,"status":"OPEN","runners":[{"status":"ACTIVE","sortPriority":1,"id":38247334,"name":"1. Noise Works"},{"status":"ACTIVE","sortPriority":2,"id":39790958,"name":"2. Wise Decisions"},{"status":"ACTIVE","sortPriority":3,"id":38745817,"name":"3. Redeemers Kid"},{"status":"ACTIVE","sortPriority":4,"id":42688799,"name":"4. Velocity Kayla"},{"status":"ACTIVE","sortPriority":5,"id":41632950,"name":"6. Swift Anna"},{"status":"ACTIVE","sortPriority":6,"id":41132571,"name":"7. Dr Xena"},{"status":"ACTIVE","sortPriority":7,"id":42256451,"name":"8. Swift Twitch"}],"regulators":["MR_INT"],"venue":"Rockhampton","countryCode":"AU","discountAllowed":true,"timezone":"Australia/Queensland","openDate":"2022-03-02T08:28:00.000Z","version":4382604991,"name":"To Be Placed","eventName":"Rockhampton (AUS) 2nd Mar"},"rc":[{"atb":[[1.4,151.23],[1.36,82.9],[1.3,403.29],[1.24,229.91],[1.35,345.68]],"id":38247334},{"atl":[[4.3,14.66],[2.86,6.5],[3.1,26.27],[2.66,7.28],[3.15,11.25],[2.78,24.49],[3.65,9.12]],"id":38247334},{"spn":2.03,"spf":"NaN","id":38247334},{"atb":[[1.67,93.73],[1.85,142.34],[1.9,134.43],[1.96,47.9],[1.95,63.67]],"id":42688799},{"atl":[[5.6,2.63],[7.2,3.9],[4.6,3.36],[9.2,2.94],[6.2,8.38],[6.8,10.89],[13,4.03]],"id":42688799},{"spn":3.28,"spf":"NaN","id":42688799},{"atb":[[2.5,80.65],[2.6,75.61],[2.2,53.95],[2.62,26.91],[2.7,35.58]],"id":39790958},{"atl":[[16.5,1.55],[8.6,1.59],[10.5,4.58],[11,6.53],[11.5,2.3],[23,2.2],[6.6,2.15]],"id":39790958},{"spn":4.65,"spf":"NaN","id":39790958},{"atb":[[4.3,31.54],[3.95,21.25],[3.9,41.71],[3.65,45.65]],"id":41632950},{"atl":[[32,0.77],[21,0.6],[24,2.72],[26,2.72],[55,0.44],[110,0.44],[15.5,0.83]],"id":41632950},{"spn":9.9,"spf":"NaN","id":41632950},{"atb":[[4.3,18.33],[3.95,20.18],[4.1,14.06],[3.9,41.71],[3.65,45.65]],"id":41132571},{"atl":[[32,0.77],[21,0.6],[22,2.72],[25,2.72],[55,0.44],[110,0.44],[15.5,0.83]],"id":41132571},{"spn":9.9,"spf":"NaN","id":41132571},{"atb":[[1.4,164.58],[1.6,201.64],[1.55,219.97],[1.65,93.06],[1.61,70.03]],"id":42256451},{"atl":[[3.45,4.93],[4.5,17.43],[3.95,8.2],[4.1,14.06],[4.9,6.2],[2.98,6.1],[5.9,9.87]],"id":42256451},{"spn":2.31,"spf":"NaN","id":42256451},{"atb":[[8.6,6.05],[7.4,18.9],[7.6,10.26],[8.4,16.34],[9.4,7.19]],"id":38745817},{"atl":[[65,2.72],[70,2.72],[310,0.07],[410,0.11],[210,0.11],[55,0.22],[110,0.1]],"id":38745817},{"spn":32.2,"spf":"NaN","id":38745817}],"con":true,"img":true}]}
{"op":"mcm","clk":"5353329914","pt":1646213097448,"mc":[{"id":"1.195453775","rc":[{"atb":[[1.4,151.23],[1.36,82.9],[1.3,403.29],[1.24,646.58],[1.35,345.68]],"id":38247334},{"atl":[[4.3,14.66],[2.86,6.5],[3.1,26.27],[2.66,7.28],[3.15,11.25],[2.84,31.78],[2.78,24.49],[3.65,9.12]],"id":38247334},{"atb":[[1.67,93.73],[1.85,142.34],[1.9,134.43],[1.96,47.9],[1.95,63.67],[1.08,187.48]],"id":42688799},{"atl":[[5.6,2.63],[7.2,3.9],[4.5,3.36],[4.6,3.36],[9.2,2.94],[6.2,8.38],[6.8,10.89],[13,4.03]],"id":42688799},{"spn":3.23,"spf":"NaN","id":42688799},{"atb":[[2.5,80.65],[2.6,75.61],[2.2,53.95],[2.62,26.91],[1.53,107.9],[2.7,35.58]],"id":39790958},{"atl":[[16.5,1.55],[8.6,1.59],[10.5,4.58],[11,6.53],[11.5,2.3],[23,2.2],[13,4.62],[6.6,2.15]],"id":39790958},{"atb":[[4.3,31.54],[3.95,21.25],[3.9,41.71],[3.65,45.65],[3.75,36.36]],"id":41632950},{"atl":[[32,0.77],[21,0.6],[24,2.72],[26,2.72],[55,0.44],[110,0.44],[60,2],[15.5,0.83]],"id":41632950},{"atb":[[4.3,18.33],[2.74,40.38],[3.95,20.18],[4.1,14.06],[3.9,41.71],[3.65,45.65]],"id":41132571},{"atl":[[32,0.77],[21,3.32],[22,2.72],[25,2.72],[55,0.44],[110,0.44],[15.5,0.83]],"id":41132571},{"atb":[[1.4,164.58],[1.36,277.78],[1.6,201.64],[1.55,219.97],[1.65,93.06],[1.61,70.03]],"id":42256451},{"atl":[[3.45,4.93],[4.5,17.43],[3.95,8.2],[4.1,14.06],[4.9,6.2],[9.8,11.36],[2.98,6.1],[5.9,9.87]],"id":42256451},{"atb":[[8.6,6.05],[7.4,18.9],[7.6,10.26],[3.9,20.54],[8.4,16.34],[9.4,7.19]],"id":38745817},{"atl":[[65,2.72],[70,4.72],[310,0.07],[410,0.11],[210,0.11],[55,0.22],[110,0.1]],"id":38745817}],"con":true,"img":false}]}
{"op":"mcm","clk":"5353332976","pt":1646213148785,"mc":[{"id":"1.195453775","rc":[{"atl":[[3.1,0]],"id":38247334},{"atl":[[22,0]],"id":41132571}],"con":true,"img":false}]}
{"op":"mcm","clk":"5353332983","pt":1646213148888,"mc":[{"id":"1.195453775","rc":[{"atl":[[2.82,26.27]],"id":38247334},{"atl":[[20,2.72]],"id":41132571}],"con":true,"img":false}]}
{"op":"mcm","clk":"5353334119","pt":1646213167902,"mc":[{"id":"1.195453775","rc":[{"atl":[[25,0]],"id":41132571}],"con":true,"img":false}]}
{"op":"mcm","clk":"5353334123","pt":1646213168005,"mc":[{"id":"1.195453775","rc":[{"atl":[[20,5.44]],"id":41132571}],"con":true,"img":false}]}
{"op":"mcm","clk":"5353334130","pt":1646213168107,"mc":[{"id":"1.195453775","rc":[{"atl":[[19.5,3.32],[21,0.6]],"id":41132571}],"con":true,"img":false}]}
{"op":"mcm","clk":"5353335095","pt":1646213186825,"mc":[{"id":"1.195453775","rc":[{"atl":[[20,2.72]],"id":41132571}],"con":true,"img":false}]}
{"op":"mcm","clk":"5353335099","pt":1646213186928,"mc":[{"id":"1.195453775","rc":[{"atl":[[24,2.72]],"id":41132571}],"con":true,"img":false}]}
{"op":"mcm","clk":"5353337179","pt":1646213224362,"mc":[{"id":"1.195453775","rc":[{"atl":[[20,0]],"id":41132571}],"con":true,"img":false}]}
{"op":"mcm","clk":"5353337184","pt":1646213224468,"mc":[{"id":"1.195453775","rc":[{"atl":[[19,2.72]],"id":41132571}],"con":true,"img":false}]}
{"op":"mcm","clk":"5353337758","pt":1646213235304,"mc":[{"id":"1.195453775","rc":[{"atb":[[1.24,229.91]],"id":38247334},{"atl":[[2.84,0]],"id":38247334},{"atb":[[1.08,0]],"id":42688799},{"atl":[[4.5,0]],"id":42688799},{"spn":3.28,"spf":"NaN","id":42688799},{"atb":[[1.53,0]],"id":39790958},{"atl":[[13,0]],"id":39790958},{"atb":[[3.75,0]],"id":41632950},{"atl":[[60,0]],"id":41632950},{"atb":[[2.74,0]],"id":41132571},{"atl":[[19.5,0]],"id":41132571},{"atb":[[1.36,0]],"id":42256451},{"atl":[[9.8,0]],"id":42256451},{"atb":[[3.9,0]],"id":38745817},{"atl":[[70,2.72]],"id":38745817}],"con":true,"img":false}]}
{"op":"mcm","clk":"5353338428","pt":1646213245613,"mc":[{"id":"1.195453775","rc":[{"atl":[[2.82,0]],"id":38247334}],"con":true,"img":false}]}
{"op":"mcm","clk":"5353338437","pt":1646213245715,"mc":[{"id":"1.195453775","rc":[{"atl":[[2.84,26.27]],"id":38247334}],"con":true,"img":false}]}
{"op":"mcm","clk":"5353340399","pt":1646213282948,"mc":[{"id":"1.195453775","rc":[{"atl":[[4.5,0],[4.1,0],[3.9,22.88]],"id":42256451}],"con":true,"img":false}]}
{"op":"mcm","clk":"5353340406","pt":1646213283050,"mc":[{"id":"1.195453775","rc":[{"atl":[[3.9,36.95]],"id":42256451}],"con":true,"img":false}]}
{"op":"mcm","clk":"5353348048","pt":1646213437165,"mc":[{"id":"1.195453775","rc":[{"atl":[[2.84,0]],"id":38247334}],"con":true,"img":false}]}
{"op":"mcm","clk":"5353348055","pt":1646213437274,"mc":[{"id":"1.195453775","rc":[{"atl":[[3.05,26.27]],"id":38247334}],"con":true,"img":false}]}
{"op":"mcm","clk":"5353355914","pt":1646213589040,"mc":[{"id":"1.195453775","rc":[{"atl":[[19,0]],"id":41132571}],"con":true,"img":false}]}
{"op":"mcm","clk":"5353355919","pt":1646213589141,"mc":[{"id":"1.195453775","rc":[{"atl":[[22,2.72]],"id":41132571}],"con":true,"img":false}]}
{"op":"mcm","clk":"5353377435","pt":1646213951323,"mc":[{"id":"1.195453775","rc":[{"atb":[[2.72,1.66]],"id":39790958},{"spn":4.66,"spf":"NaN","id":39790958},{"atb":[[4.4,1.66]],"id":41632950},{"spn":9.95,"spf":"NaN","id":41632950},{"atb":[[4.4,1.66]],"id":41132571},{"spn":9.95,"spf":"NaN","id":41132571},{"atb":[[9.6,1.66]],"id":38745817},{"spn":32.3,"spf":"NaN","id":38745817}],"con":true,"img":false}]}
{"op":"mcm","clk":"5353380935","pt":1646214003986,"mc":[{"id":"1.195453775","rc":[{"atb":[[2.62,0]],"id":39790958}],"con":true,"img":false}]}
{"op":"mcm","clk":"5353380944","pt":1646214004087,"mc":[{"id":"1.195453775","rc":[{"atb":[[2.72,28.57]],"id":39790958}],"con":true,"img":false}]}
{"op":"mcm","clk":"5353387770","pt":1646214104436,"mc":[{"id":"1.195453775","rc":[{"atb":[[1.43,19.38]],"id":38247334},{"spn":2.04,"spf":"NaN","id":38247334}],"con":true,"img":false}]}
{"op":"mcm","clk":"5353387778","pt":1646214104540,"mc":[{"id":"1.195453775","rc":[{"atb":[[2.76,4.73]],"id":39790958}],"con":true,"img":false}]}
{"op":"mcm","clk":"5353387796","pt":1646214104746,"mc":[{"id":"1.195453775","rc":[{"atb":[[2,8.33]],"id":42688799}],"con":true,"img":false}]}
{"op":"mcm","clk":"5353387803","pt":1646214104851,"mc":[{"id":"1.195453775","rc":[{"atb":[[1.69,12.07]],"id":42256451}],"con":true,"img":false}]}
{"op":"mcm","clk":"5353387837","pt":1646214105359,"mc":[{"id":"1.195453775","rc":[{"atb":[[2.72,26.91]],"id":39790958}],"con":true,"img":false}]}
{"op":"mcm","clk":"5353387844","pt":1646214105464,"mc":[{"id":"1.195453775","rc":[{"atb":[[2.02,1.66]],"id":42688799},{"atb":[[2.78,1.66]],"id":39790958}],"con":true,"img":false}]}
{"op":"mcm","clk":"5353388977","pt":1646214123016,"mc":[{"id":"1.195453775","marketDefinition":{"bspMarket":true,"turnInPlayEnabled":false,"persistenceEnabled":false,"marketBaseRate":7.0,"eventId":"31272499","eventTypeId":"4339","numberOfWinners":2,"bettingType":"ODDS","marketType":"PLACE","marketTime":"2022-03-02T10:24:00.000Z","suspendTime":"2022-03-02T10:24:00.000Z","bspReconciled":false,"complete":true,"inPlay":false,"crossMatching":true,"runnersVoidable":false,"numberOfActiveRunners":7,"betDelay":0,"status":"OPEN","runners":[{"status":"ACTIVE","sortPriority":1,"id":38247334,"name":"1. Noise Works"},{"status":"ACTIVE","sortPriority":2,"id":39790958,"name":"2. Wise Decisions"},{"status":"ACTIVE","sortPriority":3,"id":38745817,"name":"3. Redeemers Kid"},{"status":"ACTIVE","sortPriority":4,"id":42688799,"name":"4. Velocity Kayla"},{"status":"ACTIVE","sortPriority":5,"id":41632950,"name":"6. Swift Anna"},{"status":"ACTIVE","sortPriority":6,"id":41132571,"name":"7. Dr Xena"},{"status":"ACTIVE","sortPriority":7,"id":42256451,"name":"8. Swift Twitch"}],"regulators":["MR_INT"],"venue":"Rockhampton","countryCode":"AU","discountAllowed":true,"timezone":"Australia/Queensland","openDate":"2022-03-02T08:28:00.000Z","version":4382604991,"name":"To Be Placed","eventName":"Rockhampton (AUS) 2nd Mar"},"rc":[],"con":true,"img":false}]}
{"op":"mcm","clk":"5353389328","pt":1646214128803,"mc":[{"id":"1.195453775","rc":[{"atb":[[1.24,532.37]],"id":38247334},{"atl":[[3.65,31.62]],"id":38247334},{"atb":[[1.62,127.36]],"id":42688799},{"atl":[[4.5,3.36]],"id":42688799},{"atb":[[2.34,62.49]],"id":39790958},{"atl":[[13,4.62]],"id":39790958},{"atb":[[4.4,22.91]],"id":41632950},{"atl":[[55,2.44]],"id":41632950},{"atb":[[2.98,38.52]],"id":41132571},{"atl":[[21,3.32]],"id":41132571},{"atb":[[1.08,257.66]],"id":42256451},{"atl":[[3.45,17.15]],"id":42256451},{"atb":[[4.3,17.47]],"id":38745817},{"atl":[[75,2]],"id":38745817}],"con":true,"img":false}]}
{"op":"mcm","clk":"5353389429","pt":1646214130206,"mc":[{"id":"1.195453775","rc":[{"atl":[[4.5,17.43],[3.9,14.06]],"id":42256451}],"con":true,"img":false}]}
{"op":"mcm","clk":"5353390506","pt":1646214146298,"mc":[{"id":"1.195453775","rc":[{"atb":[[4.3,18.33]],"id":41632950},{"atb":[[4.1,0]],"id":41132571}],"con":true,"img":false}]}
{"op":"mcm","clk":"5353390515","pt":1646214146405,"mc":[{"id":"1.195453775","rc":[{"atb":[[4.5,13.21]],"id":41632950},{"atb":[[4.4,15.73]],"id":41132571}],"con":true,"img":false}]}
{"op":"mcm","clk":"5353390701","pt":1646214149507,"mc":[{"id":"1.195453775","rc":[{"atb":[[4.4,21.25]],"id":41632950}],"con":true,"img":false}]}
{"op":"mcm","clk":"5353390712","pt":1646214149713,"mc":[{"id":"1.195453775","rc":[{"atb":[[4.6,1.66]],"id":41632950}],"con":true,"img":false}]}
{"op":"mcm","clk":"5353391654","pt":1646214163958,"mc":[{"id":"1.195453775","rc":[{"atl":[[3.45,4.93],[3.1,14.07]],"id":42256451},{"atl":[[65,4.72],[75,0]],"id":38745817}],"con":true,"img":false}]}
{"op":"mcm","clk":"5353391685","pt":1646214164469,"mc":[{"id":"1.195453775","rc":[{"atb":[[1.43,36.87]],"id":38247334},{"atb":[[2,15.85]],"id":42688799},{"spn":3.26,"spf":"NaN","id":42688799},{"atb":[[2.78,5.89]],"id":39790958},{"spn":4.69,"spf":"NaN","id":39790958},{"spn":10.05,"spf":"NaN","id":41632950},{"atb":[[1.69,22.97]],"id":42256451},{"spn":2.33,"spf":"NaN","id":42256451}],"con":true,"img":false}]}
{"op":"mcm","clk":"5353391703","pt":1646214164677,"mc":[{"id":"1.195453775","rc":[{"atb":[[2.2,0]],"id":39790958},{"atl":[[22,0]],"id":41132571},{"atl":[[3.9,0]],"id":42256451}],"con":true,"img":false}]}
{"op":"mcm","clk":"5353391711","pt":1646214164780,"mc":[{"id":"1.195453775","rc":[{"atb":[[2.36,53.95]],"id":39790958},{"atl":[[20,2.72]],"id":41132571},{"atl":[[3.4,14.06]],"id":42256451}],"con":true,"img":false}]}
{"op":"mcm","clk":"5353393773","pt":1646214195005,"mc":[{"id":"1.195453775","rc":[{"atb":[[4.1,32.26],[4.4,0]],"id":41632950},{"atb":[[2.98,0],[2.84,54.35]],"id":41132571},{"atl":[[3.1,0],[3.25,20.18]],"id":42256451},{"atl":[[65,2.72],[70,4.72]],"id":38745817}],"con":true,"img":false}]}
{"op":"mcm","clk":"5353397088","pt":1646214244187,"mc":[{"id":"1.195453775","rc":[{"atb":[[1.36,0],[1.24,302.46]],"id":38247334},{"atl":[[2.78,0],[3.05,0]],"id":38247334},{"atb":[[1.67,0],[1.96,0]],"id":42688799},{"atl":[[6.2,0],[6.8,0]],"id":42688799},{"atb":[[2.36,0],[2.72,0]],"id":39790958},{"atl":[[10.5,0],[11,0]],"id":39790958},{"atb":[[4.5,0],[3.95,0]],"id":41632950},{"atl":[[24,0],[26,0]],"id":41632950},{"atb":[[3.95,0],[4.4,1.66]],"id":41132571},{"atl":[[20,0],[24,0]],"id":41132571},{"atb":[[1.4,0],[1.61,0]],"id":42256451},{"atl":[[4.5,0],[3.4,0]],"id":42256451},{"atb":[[8.6,0],[7.6,0]],"id":38745817},{"atl":[[65,0],[70,2]],"id":38745817}],"con":true,"img":false}]}
{"op":"mcm","clk":"5353397099","pt":1646214244394,"mc":[{"id":"1.195453775","rc":[{"atl":[[32,4],[21,0.6]],"id":41132571},{"atl":[[70,0],[110,2.1]],"id":38745817}],"con":true,"img":false}]}
{"op":"mcm","clk":"5353397122","pt":1646214244709,"mc":[{"id":"1.195453775","rc":[{"atb":[[2,8.33]],"id":42688799},{"atb":[[2.78,1.66]],"id":39790958}],"con":true,"img":false}]}
{"op":"mcm","clk":"5353397184","pt":1646214245586,"mc":[{"id":"1.195453775","rc":[{"atb":[[4.6,0]],"id":41632950}],"con":true,"img":false}]}
{"op":"mcm","clk":"5353397198","pt":1646214245796,"mc":[{"id":"1.195453775","rc":[{"atb":[[4.4,1.66]],"id":41632950}],"con":true,"img":false}]}
{"op":"mcm","clk":"5353397456","pt":1646214249614,"mc":[{"id":"1.195453775","rc":[{"atl":[[210,2.11],[110,0.1]],"id":38745817}],"con":true,"img":false}]}
{"op":"mcm","clk":"5353397487","pt":1646214250025,"mc":[{"id":"1.195453775","rc":[{"atl":[[3.6,12.22],[3.25,0]],"id":42256451}],"con":true,"img":false}]}
{"op":"mcm","clk":"5353397547","pt":1646214250812,"mc":[{"id":"1.195453775","rc":[{"atb":[[1.99,7.59]],"id":42688799},{"atb":[[2.76,9]],"id":39790958}],"con":true,"img":false}]}
{"op":"mcm","clk":"5353397822","pt":1646214254225,"mc":[{"id":"1.195453775","rc":[{"atb":[[3.45,40.82],[4.1,0]],"id":41632950},{"atb":[[2.84,0],[2.98,50.51]],"id":41132571}],"con":true,"img":false}]}
{"op":"mcm","clk":"5353398138","pt":1646214258616,"mc":[{"id":"1.195453775","rc":[{"atb":[[1.36,82.9],[1.25,220.72]],"id":38247334},{"atl":[[2.8,24.21],[3.1,26.27]],"id":38247334},{"atb":[[1.96,45.41],[1.66,99.73]],"id":42688799},{"atl":[[6.2,8.38],[6.8,10.89]],"id":42688799},{"atb":[[2.36,47.95],[2.72,25.34]],"id":39790958},{"atl":[[10.5,4.58],[11,5.44]],"id":39790958},{"atb":[[4.3,31.54],[3.95,21.25]],"id":41632950},{"atl":[[24,2.72],[26,2.72]],"id":41632950},{"atb":[[3.95,18.47],[4.1,14.06]],"id":41132571},{"atl":[[22,2.72],[25,2.72]],"id":41132571},{"atb":[[1.4,164.58],[1.61,70.03]],"id":42256451},{"atl":[[3.55,17.09],[4.4,17.43]],"id":42256451},{"atb":[[8.6,5.73],[7.6,9.01]],"id":38745817},{"atl":[[65,2.72],[70,2.72]],"id":38745817}],"con":true,"img":false}]}
{"op":"mcm","clk":"5353398200","pt":1646214259598,"mc":[{"id":"1.195453775","rc":[{"atb":[[1.99,0]],"id":42688799}],"con":true,"img":false}]}
{"op":"mcm","clk":"5353398641","pt":1646214265749,"mc":[{"id":"1.195453775","rc":[{"atb":[[2,15.85]],"id":42688799}],"con":true,"img":false}]}
{"op":"mcm","clk":"5353398877","pt":1646214269554,"mc":[{"id":"1.195453775","rc":[{"atl":[[32,0.77],[21,3.32]],"id":41132571}],"con":true,"img":false}]}
{"op":"mcm","clk":"5353399195","pt":1646214274657,"mc":[{"id":"1.195453775","rc":[{"atl":[[80,2],[210,0.11]],"id":38745817}],"con":true,"img":false}]}
{"op":"mcm","clk":"5353399226","pt":1646214275023,"mc":[{"id":"1.195453775","rc":[{"atl":[[3.45,17.15],[3.6,0]],"id":42256451}],"con":true,"img":false}]}
{"op":"mcm","clk":"5353399503","pt":1646214279259,"mc":[{"id":"1.195453775","rc":[{"atb":[[3.45,0],[4.1,32.26]],"id":41632950}],"con":true,"img":false}]}
{"op":"mcm","clk":"5353400136","pt":1646214289460,"mc":[{"id":"1.195453775","rc":[{"atb":[[3.85,35.09],[4.1,0]],"id":41632950}],"con":true,"img":false}]}
{"op":"mcm","clk":"5353401024","pt":1646214303578,"mc":[{"id":"1.195453775","rc":[{"atl":[[80,0],[85,2]],"id":38745817}],"con":true,"img":false}]}
{"op":"mcm","clk":"5353401825","pt":1646214314207,"mc":[{"id":"1.195453775","rc":[{"atb":[[3.85,0],[4.1,32.26]],"id":41632950},{"spn":9.95,"spf":"NaN","id":41632950}],"con":true,"img":false}]}
{"op":"mcm","clk":"5353402487","pt":1646214322711,"mc":[{"id":"1.195453775","rc":[{"atb":[[4.3,18.33],[3.95,0]],"id":41632950},{"atb":[[4.1,0]],"id":41132571},{"atl":[[22,0]],"id":41132571},{"atl":[[3.55,0]],"id":42256451}],"con":true,"img":false}]}
{"op":"mcm","clk":"5353402494","pt":1646214322818,"mc":[{"id":"1.195453775","rc":[{"atb":[[4.4,14.87],[4.2,21.25]],"id":41632950},{"atb":[[4.4,15.73]],"id":41132571},{"atl":[[20,2.72]],"id":41132571},{"atl":[[3.4,17.09]],"id":42256451}],"con":true,"img":false}]}
{"op":"mcm","clk":"5353403684","pt":1646214338643,"mc":[{"id":"1.195453775","rc":[{"atb":[[4.1,0],[4.2,52.5]],"id":41632950}],"con":true,"img":false}]}
{"op":"mcm","clk":"5353404219","pt":1646214345948,"mc":[{"id":"1.195453775","rc":[{"atl":[[25,0]],"id":41132571}],"con":true,"img":false}]}
{"op":"mcm","clk":"5353404227","pt":1646214346054,"mc":[{"id":"1.195453775","rc":[{"atl":[[20,5.44]],"id":41132571}],"con":true,"img":false}]}
{"op":"mcm","clk":"5353404234","pt":1646214346165,"mc":[{"id":"1.195453775","rc":[{"atl":[[19.5,3.32],[21,0.6]],"id":41132571}],"con":true,"img":false}]}
{"op":"mcm","clk":"5353405782","pt":1646214369148,"mc":[{"id":"1.195453775","rc":[{"atl":[[20,2.72]],"id":41132571}],"con":true,"img":false}]}
{"op":"mcm","clk":"5353405788","pt":1646214369249,"mc":[{"id":"1.195453775","rc":[{"atl":[[24,2.72]],"id":41132571}],"con":true,"img":false}]}
{"op":"mcm","clk":"5353406990","pt":1646214385559,"mc":[{"id":"1.195453775","rc":[{"atb":[[4.2,31.25]],"id":41632950}],"con":true,"img":false}]}
{"op":"mcm","clk":"5353406998","pt":1646214385665,"mc":[{"id":"1.195453775","rc":[{"atb":[[4.3,39.58]],"id":41632950}],"con":true,"img":false}]}
{"op":"mcm","clk":"5353407568","pt":1646214393179,"mc":[{"id":"1.195453775","rc":[{"atb":[[4.1,32.26],[4.2,0]],"id":41632950}],"con":true,"img":false}]}
{"op":"mcm","clk":"5353407579","pt":1646214393281,"mc":[{"id":"1.195453775","rc":[{"atb":[[4.2,31.25]],"id":41632950}],"con":true,"img":false}]}
{"op":"mcm","clk":"5353407591","pt":1646214393389,"mc":[{"id":"1.195453775","rc":[{"atb":[[4.1,0]],"id":41632950}],"con":true,"img":false}]}
{"op":"mcm","clk":"5353408261","pt":1646214402808,"mc":[{"id":"1.195453775","rc":[{"atl":[[20,0]],"id":41132571}],"con":true,"img":false}]}
{"op":"mcm","clk":"5353408268","pt":1646214402818,"mc":[{"id":"1.195453775","rc":[{"atl":[[19,2.72]],"id":41132571}],"con":true,"img":false}]}
{"op":"mcm","clk":"5353408849","pt":1646214410418,"mc":[{"id":"1.195453775","rc":[{"atb":[[4,33.33],[4.2,0]],"id":41632950}],"con":true,"img":false}]}
{"op":"mcm","clk":"5353409270","pt":1646214416916,"mc":[{"id":"1.195453775","rc":[{"atb":[[4,0],[4.2,31.25]],"id":41632950}],"con":true,"img":false}]}
{"op":"mcm","clk":"5353409790","pt":1646214424440,"mc":[{"id":"1.195453775","rc":[{"atb":[[3.7,37.04],[4.2,0]],"id":41632950}],"con":true,"img":false}]}
{"op":"mcm","clk":"5353410412","pt":1646214432972,"mc":[{"id":"1.195453775","rc":[{"atb":[[4.3,18.33]],"id":41632950}],"con":true,"img":false}]}
{"op":"mcm","clk":"5353410421","pt":1646214433033,"mc":[{"id":"1.195453775","rc":[{"atb":[[3.95,21.25]],"id":41632950}],"con":true,"img":false}]}
{"op":"mcm","clk":"5353411354","pt":1646214447778,"mc":[{"id":"1.195453775","rc":[{"atb":[[4.1,32.26],[3.7,0]],"id":41632950}],"con":true,"img":false}]}
{"op":"mcm","clk":"5353412147","pt":1646214460781,"mc":[{"id":"1.195453775","rc":[{"atb":[[4.1,0],[2.78,53.51]],"id":41632950},{"atb":[[2.32,60.2],[2.98,0]],"id":41132571},{"atl":[[3.45,4.93],[3.35,17.1]],"id":42256451},{"atb":[[4.3,0],[3.25,18.04]],"id":38745817}],"con":true,"img":false}]}
{"op":"mcm","clk":"5353412250","pt":1646214462472,"mc":[{"id":"1.195453775","rc":[{"atl":[[4.4,0],[3.9,22.88]],"id":42256451}],"con":true,"img":false}]}
{"op":"mcm","clk":"5353413441","pt":1646214483827,"mc":[{"id":"1.195453775","rc":[{"atb":[[3.1,47.62],[2.78,0]],"id":41632950},{"atb":[[2.32,0],[2.52,60.2]],"id":41132571},{"atl":[[3.2,17.1],[3.35,0]],"id":42256451},{"atb":[[3.25,0],[3.65,18.04]],"id":38745817}],"con":true,"img":false}]}
{"op":"mcm","clk":"5353413461","pt":1646214484239,"mc":[{"id":"1.195453775","rc":[{"atl":[[3.1,0]],"id":38247334}],"con":true,"img":false}]}
{"op":"mcm","clk":"5353413466","pt":1646214484343,"mc":[{"id":"1.195453775","rc":[{"atl":[[2.84,26.27]],"id":38247334}],"con":true,"img":false}]}
{"op":"mcm","clk":"5353414590","pt":1646214504562,"mc":[{"id":"1.195453775","rc":[{"atl":[[3.4,0]],"id":42256451}],"con":true,"img":false}]}
{"op":"mcm","clk":"5353414595","pt":1646214504655,"mc":[{"id":"1.195453775","rc":[{"atl":[[3.15,17.09]],"id":42256451}],"con":true,"img":false}]}
{"op":"mcm","clk":"5353418603","pt":1646214580712,"mc":[{"id":"1.195453775","rc":[{"atb":[[3.1,0],[2.78,56.18]],"id":41632950},{"atb":[[2.32,60.2],[2.52,0]],"id":41132571},{"atl":[[3.2,0],[3.35,34.2]],"id":42256451},{"atb":[[3.25,18.04],[3.65,0]],"id":38745817}],"con":true,"img":false}]}
{"op":"mcm","clk":"5353419098","pt":1646214589522,"mc":[{"id":"1.195453775","rc":[{"atl":[[3.15,0]],"id":42256451}],"con":true,"img":false}]}
{"op":"mcm","clk":"5353419102","pt":1646214589627,"mc":[{"id":"1.195453775","rc":[{"atl":[[3.3,17.09]],"id":42256451}],"con":true,"img":false}]}
{"op":"mcm","clk":"5353419922","pt":1646214605309,"mc":[{"id":"1.195453775","rc":[{"atl":[[2.84,0]],"id":38247334}],"con":true,"img":false}]}
{"op":"mcm","clk":"5353419929","pt":1646214605412,"mc":[{"id":"1.195453775","rc":[{"atl":[[3.1,26.27]],"id":38247334}],"con":true,"img":false}]}
{"op":"mcm","clk":"5353420621","pt":1646214620049,"mc":[{"id":"1.195453775","rc":[{"atl":[[4.5,17.43],[3.9,0]],"id":42256451}],"con":true,"img":false}]}
{"op":"mcm","clk":"5353421013","pt":1646214628190,"mc":[{"id":"1.195453775","rc":[{"atb":[[1.14,441.44],[1.24,0]],"id":38247334},{"atl":[[10.5,9.17],[13,0]],"id":39790958},{"atb":[[2.78,0]],"id":41632950},{"atl":[[55,0.44]],"id":41632950},{"atb":[[2.32,0]],"id":41132571},{"atl":[[3.35,0],[3.65,23.21]],"id":42256451},{"atb":[[3.25,0],[4.7,18.04]],"id":38745817},{"atl":[[75,2],[85,0]],"id":38745817}],"con":true,"img":false}]}
{"op":"mcm","clk":"5353421017","pt":1646214628282,"mc":[{"id":"1.195453775","rc":[{"atb":[[4,33.33]],"id":41632950},{"atl":[[32,4]],"id":41632950},{"atb":[[2.92,52.08]],"id":41132571}],"con":true,"img":false}]}
{"op":"mcm","clk":"5353421324","pt":1646214634097,"mc":[{"id":"1.195453775","rc":[{"atl":[[3.3,0]],"id":42256451}],"con":true,"img":false}]}
{"op":"mcm","clk":"5353421331","pt":1646214634201,"mc":[{"id":"1.195453775","rc":[{"atl":[[3.6,17.09]],"id":42256451}],"con":true,"img":false}]}
{"op":"mcm","clk":"5353422046","pt":1646214649536,"mc":[{"id":"1.195453775","rc":[{"atb":[[1.2,441.44],[1.14,0]],"id":38247334},{"atb":[[4,0],[4.5,18.33]],"id":41632950},{"spn":10.0,"spf":"NaN","id":41632950},{"atb":[[3.4,41.67]],"id":41132571},{"atl":[[3.3,17.1],[3.65,0]],"id":42256451},{"atb":[[5.7,18.04],[4.7,0]],"id":38745817},{"atl":[[65,4.72],[75,0]],"id":38745817}],"con":true,"img":false}]}
{"op":"mcm","clk":"5353422049","pt":1646214649583,"mc":[{"id":"1.195453775","rc":[{"atb":[[2.92,0]],"id":41132571}],"con":true,"img":false}]}
{"op":"mcm","clk":"5353422256","pt":1646214654623,"mc":[{"id":"1.195453775","rc":[{"atb":[[4.4,13.21]],"id":41632950}],"con":true,"img":false}]}
{"op":"mcm","clk":"5353422264","pt":1646214654828,"mc":[{"id":"1.195453775","rc":[{"atb":[[4.6,1.66]],"id":41632950}],"con":true,"img":false}]}
{"op":"mcm","clk":"5353423217","pt":1646214675545,"mc":[{"id":"1.195453775","rc":[{"atl":[[10,7.08],[11,0]],"id":39790958}],"con":true,"img":false}]}
{"op":"mcm","clk":"5353423801","pt":1646214689393,"mc":[{"id":"1.195453775","rc":[{"atb":[[4.4,0]],"id":41632950},{"atl":[[3.6,0]],"id":42256451}],"con":true,"img":false}]}
{"op":"mcm","clk":"5353423804","pt":1646214689450,"mc":[{"id":"1.195453775","rc":[{"atb":[[4.6,14.87]],"id":41632950},{"atl":[[3.25,17.09]],"id":42256451}],"con":true,"img":false}]}
{"op":"mcm","clk":"5353423812","pt":1646214689558,"mc":[{"id":"1.195453775","rc":[{"atb":[[4.5,0],[4.7,18.33]],"id":41632950}],"con":true,"img":false}]}
{"op":"mcm","clk":"5353423859","pt":1646214690795,"mc":[{"id":"1.195453775","rc":[{"atb":[[4.6,13.21]],"id":41632950}],"con":true,"img":false}]}
{"op":"mcm","clk":"5353423870","pt":1646214690999,"mc":[{"id":"1.195453775","rc":[{"atb":[[4.8,1.66]],"id":41632950}],"con":true,"img":false}]}
{"op":"mcm","clk":"5353424527","pt":1646214702906,"mc":[{"id":"1.195453775","rc":[{"atl":[[10.5,4.58],[8.2,7.08]],"id":39790958},{"atl":[[32,0.77],[24,5.44]],"id":41632950},{"atl":[[3.3,0]],"id":42256451}],"con":true,"img":false}]}
{"op":"mcm","clk":"5353424533","pt":1646214703009,"mc":[{"id":"1.195453775","rc":[{"atl":[[2.96,17.1]],"id":42256451}],"con":true,"img":false}]}
{"op":"mcm","clk":"5353424696","pt":1646214707020,"mc":[{"id":"1.195453775","rc":[{"atl":[[10,0]],"id":39790958},{"atl":[[70,0]],"id":38745817}],"con":true,"img":false}]}
{"op":"mcm","clk":"5353424706","pt":1646214707080,"mc":[{"id":"1.195453775","rc":[{"atl":[[11,7.08]],"id":39790958},{"atl":[[60,2.72]],"id":38745817}],"con":true,"img":false}]}
{"op":"mcm","clk":"5353426297","pt":1646214737475,"mc":[{"id":"1.195453775","rc":[{"atl":[[10.5,0]],"id":39790958},{"atb":[[4.6,0]],"id":41632950},{"spn":10.15,"spf":"NaN","id":41632950},{"atl":[[3.25,0]],"id":42256451},{"spn":2.32,"spf":"NaN","id":42256451}],"con":true,"img":false}]}
{"op":"mcm","clk":"5353426302","pt":1646214737577,"mc":[{"id":"1.195453775","rc":[{"atl":[[8,4.58]],"id":39790958},{"atb":[[4.8,14.87]],"id":41632950},{"atl":[[2.94,17.09]],"id":42256451}],"con":true,"img":false}]}
{"op":"mcm","clk":"5353426313","pt":1646214737740,"mc":[{"id":"1.195453775","rc":[{"atb":[[4.8,33.2],[4.7,0]],"id":41632950},{"atl":[[2.96,0],[2.94,34.19]],"id":42256451}],"con":true,"img":false}]}
{"op":"mcm","clk":"5353427172","pt":1646214754503,"mc":[{"id":"1.195453775","rc":[{"atl":[[26,0]],"id":41632950}],"con":true,"img":false}]}
{"op":"mcm","clk":"5353427178","pt":1646214754561,"mc":[{"id":"1.195453775","rc":[{"atl":[[23,2.72]],"id":41632950}],"con":true,"img":false}]}
{"op":"mcm","clk":"5353427638","pt":1646214762911,"mc":[{"id":"1.195453775","rc":[{"atb":[[4.8,14.87],[4.3,48.63]],"id":41632950},{"atb":[[3.1,47.62],[3.4,0]],"id":41132571},{"atl":[[3.15,40.31],[2.94,17.09]],"id":42256451},{"atb":[[5.1,18.04],[5.7,0]],"id":38745817}],"con":true,"img":false}]}
{"op":"mcm","clk":"5353428028","pt":1646214769517,"mc":[{"id":"1.195453775","rc":[{"atb":[[4.8,1.66]],"id":41632950},{"atl":[[2.94,0]],"id":42256451}],"con":true,"img":false}]}
{"op":"mcm","clk":"5353428037","pt":1646214769618,"mc":[{"id":"1.195453775","rc":[{"atb":[[4.4,13.21]],"id":41632950},{"atl":[[3.1,17.09]],"id":42256451}],"con":true,"img":false}]}
{"op":"mcm","clk":"5353428333","pt":1646214775338,"mc":[{"id":"1.195453775","rc":[{"atb":[[4.8,0]],"id":41632950}],"con":true,"img":false}]}
{"op":"mcm","clk":"5353428338","pt":1646214775440,"mc":[{"id":"1.195453775","rc":[{"atb":[[4.5,1.66]],"id":41632950}],"con":true,"img":false}]}
{"op":"mcm","clk":"5353431000","pt":1646214827513,"mc":[{"id":"1.195453775","rc":[{"atl":[[7.2,4.59],[8.2,0]],"id":39790958},{"atb":[[4.5,14.87],[4.3,18.33]],"id":41632950},{"spn":10.0,"spf":"NaN","id":41632950},{"atb":[[3.1,0],[3.65,83.39]],"id":41132571},{"atl":[[2.98,23.2],[3.15,0]],"id":42256451},{"spn":2.33,"spf":"NaN","id":42256451}],"con":true,"img":false}]}
{"op":"mcm","clk":"5353431276","pt":1646214831689,"mc":[{"id":"1.195453775","rc":[{"atl":[[8,0]],"id":39790958}],"con":true,"img":false}]}
{"op":"mcm","clk":"5353431281","pt":1646214831791,"mc":[{"id":"1.195453775","rc":[{"atl":[[10,4.58]],"id":39790958}],"con":true,"img":false}]}
{"op":"mcm","clk":"5353431748","pt":1646214840299,"mc":[{"id":"1.195453775","rc":[{"atb":[[1.72,27.78],[1.7,71.43],[1.68,110.29],[1.66,289.12]],"id":42688799},{"atl":[[3.45,51.02],[3.35,31.91],[3.15,9.3],[3.25,22.22]],"id":42688799},{"atb":[[2.5,93.98],[2.42,52.82],[2.38,90.58],[2.46,34.25]],"id":39790958},{"atl":[[5.6,27.17],[5,5],[5.2,11.9],[5.4,17.05]],"id":39790958},{"atb":[[4.5,20.58],[4.3,33.48],[3.95,63.62],[4.1,24.19]],"id":41632950},{"atl":[[12,1.82],[13,4.17],[14,5.77],[15,8.93]],"id":41632950},{"atb":[[4.3,24.39],[3.85,43.86],[3.95,43.89],[4.1,16.13]],"id":41132571},{"atl":[[16,3.33],[17,4.69],[18,7.35],[15,1.43]],"id":41132571},{"atb":[[1.18,111.11],[1.12,250],[1.16,250],[1.14,250]],"id":42256451},{"atl":[[2.5,83.33],[2.42,35.21],[2.38,14.49],[2.46,51.37]],"id":42256451},{"atb":[[7.4,26.71],[7.8,2.94],[7,12.5],[6.6,22.32]],"id":38745817},{"atl":[[34,2.27],[38,3.38],[28,1],[30,1.72]],"id":38745817}],"con":true,"img":false}]}
{"op":"mcm","clk":"5353431753","pt":1646214840402,"mc":[{"id":"1.195453775","rc":[{"atb":[[1.33,151.52],[1.29,250],[1.31,241.94],[1.35,402.82]],"id":38247334},{"atl":[[3.85,26.32],[3.95,42.37],[3.65,39.17],[3.75,18.18]],"id":38247334},{"atl":[[4.5,0],[3.2,31.91]],"id":42688799},{"atl":[[19.5,0],[15,3.43]],"id":41132571}],"con":true,"img":false}]}
{"op":"mcm","clk":"5353431759","pt":1646214840504,"mc":[{"id":"1.195453775","rc":[{"atb":[[5.8,18.04]],"id":38745817}],"con":true,"img":false}]}
{"op":"mcm","clk":"5353431764","pt":1646214840607,"mc":[{"id":"1.195453775","rc":[{"atb":[[5.1,0]],"id":38745817}],"con":true,"img":false}]}
{"op":"mcm","clk":"5353431779","pt":1646214840819,"mc":[{"id":"1.195453775","rc":[{"atl":[[23,0]],"id":41632950},{"atl":[[3.1,0]],"id":42256451}],"con":true,"img":false}]}
{"op":"mcm","clk":"5353431786","pt":1646214840923,"mc":[{"id":"1.195453775","rc":[{"atl":[[25,2.72]],"id":41632950},{"atl":[[3.4,17.09]],"id":42256451}],"con":true,"img":false}]}
{"op":"mcm","clk":"5353431836","pt":1646214841801,"mc":[{"id":"1.195453775","rc":[{"atl":[[11.5,1.9],[12,0]],"id":41632950},{"atb":[[5.8,0],[5.2,21.52]],"id":38745817}],"con":true,"img":false}]}
{"op":"mcm","clk":"5353432017","pt":1646214845503,"mc":[{"id":"1.195453775","rc":[{"atl":[[3.2,0],[3.25,63.43]],"id":42688799},{"atl":[[16,8.02]],"id":41132571}],"con":true,"img":false}]}
{"op":"mcm","clk":"5353432024","pt":1646214845606,"mc":[{"id":"1.195453775","rc":[{"atl":[[15,1.43]],"id":41132571}],"con":true,"img":false}]}
{"op":"mcm","clk":"5353432085","pt":1646214846692,"mc":[{"id":"1.195453775","rc":[{"atb":[[3.9,76.19],[3.65,45.65]],"id":41132571}],"con":true,"img":false}]}
{"op":"mcm","clk":"5353432297","pt":1646214850737,"mc":[{"id":"1.195453775","rc":[{"atl":[[3.6,21.22]],"id":38247334},{"atb":[[2.06,61.03]],"id":39790958}],"con":true,"img":false}]}
{"op":"mcm","clk":"5353432307","pt":1646214850945,"mc":[{"id":"1.195453775","rc":[{"atl":[[2.8,0],[3.1,0]],"id":38247334},{"atb":[[2.36,0]],"id":39790958}],"con":true,"img":false}]}
{"op":"mcm","clk":"5353432313","pt":1646214850999,"mc":[{"id":"1.195453775","rc":[{"atl":[[3.35,24.21]],"id":38247334}],"con":true,"img":false}]}
{"op":"mcm","clk":"5353432833","pt":1646214860923,"mc":[{"id":"1.195453775","rc":[{"atb":[[6,20],[5.2,0]],"id":38745817}],"con":true,"img":false}]}
{"op":"mcm","clk":"5353433346","pt":1646214870765,"mc":[{"id":"1.195453775","rc":[{"atl":[[3.2,19.81]],"id":42688799},{"atl":[[5.3,10.13]],"id":39790958},{"atb":[[4.4,0]],"id":41632950},{"atl":[[24,2.72]],"id":41632950},{"atl":[[19,0]],"id":41132571},{"atl":[[2.44,30.27]],"id":42256451},{"atl":[[65,2]],"id":38745817}],"con":true,"img":false}]}
{"op":"mcm","clk":"5353433350","pt":1646214870868,"mc":[{"id":"1.195453775","rc":[{"atl":[[3.2,51.72],[6.2,0],[3.25,22.22]],"id":42688799},{"atl":[[10,0]],"id":39790958},{"atb":[[4.6,13.21]],"id":41632950},{"atl":[[14.5,2.72]],"id":41632950},{"atl":[[15.5,3.55]],"id":41132571},{"atl":[[3.4,0]],"id":42256451},{"atl":[[36,2.72]],"id":38745817}],"con":true,"img":false}]}
{"op":"mcm","clk":"5353433356","pt":1646214870973,"mc":[{"id":"1.195453775","rc":[{"atl":[[3.2,19.81],[3.25,66.66]],"id":42688799},{"atl":[[15,4.99]],"id":41132571}],"con":true,"img":false}]}
{"op":"mcm","clk":"5353433361","pt":1646214871023,"mc":[{"id":"1.195453775","rc":[{"atl":[[3.2,51.72],[3.25,22.22]],"id":42688799},{"atb":[[4.5,7.37],[4.7,20.59]],"id":41632950},{"atl":[[16,3.32]],"id":41132571}],"con":true,"img":false}]}
{"op":"mcm","clk":"5353433370","pt":1646214871230,"mc":[{"id":"1.195453775","rc":[{"atb":[[4.5,5.71]],"id":41632950}],"con":true,"img":false}]}
{"op":"mcm","clk":"5353433381","pt":1646214871437,"mc":[{"id":"1.195453775","rc":[{"atb":[[4.7,22.25]],"id":41632950}],"con":true,"img":false}]}
{"op":"mcm","clk":"5353433851","pt":1646214880884,"mc":[{"id":"1.195453775","rc":[{"atb":[[1.66,189.39]],"id":42688799}],"con":true,"img":false}]}
{"op":"mcm","clk":"5353433861","pt":1646214880995,"mc":[{"id":"1.195453775","rc":[{"atb":[[1.71,99.73]],"id":42688799}],"con":true,"img":false}]}
{"op":"mcm","clk":"5353434375","pt":1646214890808,"mc":[{"id":"1.195453775","rc":[{"atb":[[1.25,0],[1.32,172.43]],"id":38247334},{"atl":[[5,15.8],[6.8,0]],"id":42688799},{"spn":2.58,"spf":"NaN","id":42688799},{"atl":[[11,0],[8.2,9.26]],"id":39790958},{"spn":3.89,"spf":"NaN","id":39790958},{"atl":[[18,3.81],[25,0]],"id":41632950},{"spn":8.1,"spf":"NaN","id":41632950},{"atl":[[16.5,3.51],[24,0]],"id":41132571},{"spn":9.7,"spf":"NaN","id":41132571},{"atl":[[4.5,0],[3.75,23.97]],"id":42256451},{"spn":2.03,"spf":"NaN","id":42256451},{"atl":[[60,0]],"id":38745817},{"spn":18.8,"spf":"NaN","id":38745817}],"con":true,"img":false}]}
{"op":"mcm","clk":"5353434381","pt":1646214890911,"mc":[{"id":"1.195453775","rc":[{"atl":[[36,5.44]],"id":38745817}],"con":true,"img":false}]}
{"op":"mcm","clk":"5353434828","pt":1646214900810,"mc":[{"id":"1.195453775","rc":[{"atl":[[3.2,31.91]],"id":42688799},{"atl":[[14.5,0]],"id":41632950}],"con":true,"img":false}]}
{"op":"mcm","clk":"5353434831","pt":1646214900915,"mc":[{"id":"1.195453775","rc":[{"atl":[[3.2,0],[3.15,29.11],[3.25,63.43]],"id":42688799},{"atl":[[13.5,2.72]],"id":41632950}],"con":true,"img":false}]}
{"op":"mcm","clk":"5353435392","pt":1646214910837,"mc":[{"id":"1.195453775","rc":[{"atl":[[3.15,9.3]],"id":42688799},{"atb":[[4.6,0]],"id":41632950}],"con":true,"img":false}]}
{"op":"mcm","clk":"5353435400","pt":1646214910941,"mc":[{"id":"1.195453775","rc":[{"atl":[[3.2,19.81],[3.25,22.22]],"id":42688799},{"atb":[[4.8,13.21]],"id":41632950}],"con":true,"img":false}]}
{"op":"mcm","clk":"5353435410","pt":1646214911044,"mc":[{"id":"1.195453775","rc":[{"atl":[[3.35,74.46]],"id":42688799},{"atb":[[4.9,13.21],[4.7,1.66]],"id":41632950}],"con":true,"img":false}]}
{"op":"mcm","clk":"5353435535","pt":1646214913314,"mc":[{"id":"1.195453775","rc":[{"atb":[[4.7,0]],"id":41632950}],"con":true,"img":false}]}
{"op":"mcm","clk":"5353435539","pt":1646214913417,"mc":[{"id":"1.195453775","rc":[{"atb":[[5,1.66]],"id":41632950}],"con":true,"img":false}]}
{"op":"mcm","clk":"5353435860","pt":1646214919459,"mc":[{"id":"1.195453775","rc":[{"atl":[[3.2,42.03],[3.35,31.91]],"id":42688799}],"con":true,"img":false}]}
{"op":"mcm","clk":"5353435869","pt":1646214919561,"mc":[{"id":"1.195453775","rc":[{"atl":[[3.25,66.66]],"id":42688799}],"con":true,"img":false}]}
{"op":"mcm","clk":"5353435880","pt":1646214919666,"mc":[{"id":"1.195453775","rc":[{"atl":[[3.2,19.81]],"id":42688799}],"con":true,"img":false}]}
{"op":"mcm","clk":"5353435891","pt":1646214919719,"mc":[{"id":"1.195453775","rc":[{"atl":[[3.2,61.85]],"id":42688799}],"con":true,"img":false}]}
{"op":"mcm","clk":"5353435902","pt":1646214919822,"mc":[{"id":"1.195453775","rc":[{"atl":[[3.25,22.22]],"id":42688799}],"con":true,"img":false}]}
{"op":"mcm","clk":"5353435956","pt":1646214920848,"mc":[{"id":"1.195453775","rc":[{"atb":[[4.8,0]],"id":41632950}],"con":true,"img":false}]}
{"op":"mcm","clk":"5353435963","pt":1646214920952,"mc":[{"id":"1.195453775","rc":[{"atb":[[4.4,13.21]],"id":41632950}],"con":true,"img":false}]}
{"op":"mcm","clk":"5353437189","pt":1646214940877,"mc":[{"id":"1.195453775","rc":[{"atl":[[3.2,42.04]],"id":42688799}],"con":true,"img":false}]}
{"op":"mcm","clk":"5353437195","pt":1646214940981,"mc":[{"id":"1.195453775","rc":[{"atl":[[3.2,0],[3.15,29.11],[3.25,66.66]],"id":42688799}],"con":true,"img":false}]}
{"op":"mcm","clk":"5353437730","pt":1646214950808,"mc":[{"id":"1.195453775","rc":[{"atl":[[3.15,9.3]],"id":42688799}],"con":true,"img":false}]}
{"op":"mcm","clk":"5353437735","pt":1646214950862,"mc":[{"id":"1.195453775","rc":[{"atl":[[3.2,19.81]],"id":42688799},{"spn":8.25,"spf":"NaN","id":41632950}],"con":true,"img":false}]}
{"op":"mcm","clk":"5353437744","pt":1646214950965,"mc":[{"id":"1.195453775","rc":[{"atl":[[3.35,74.46],[3.25,22.22]],"id":42688799}],"con":true,"img":false}]}
{"op":"mcm","clk":"5353438397","pt":1646214963013,"mc":[{"id":"1.195453775","rc":[{"atb":[[4.6,14.88],[4.9,0]],"id":41632950},{"atb":[[3.9,41.71],[3.65,83.39]],"id":41132571},{"atl":[[15,1.43],[15.5,10.45]],"id":41132571},{"atb":[[5.3,21.52],[6,0]],"id":38745817}],"con":true,"img":false}]}
{"op":"mcm","clk":"5353438666","pt":1646214968327,"mc":[{"id":"1.195453775","rc":[{"atb":[[5,0]],"id":41632950}],"con":true,"img":false}]}
{"op":"mcm","clk":"5353438669","pt":1646214968383,"mc":[{"id":"1.195453775","rc":[{"atb":[[4.7,1.66]],"id":41632950}],"con":true,"img":false}]}
{"op":"mcm","clk":"5353438672","pt":1646214968486,"mc":[{"id":"1.195453775","rc":[{"atb":[[4.5,34.28]],"id":41632950}],"con":true,"img":false}]}
{"op":"mcm","clk":"5353438677","pt":1646214968589,"mc":[{"id":"1.195453775","rc":[{"atb":[[4.6,0]],"id":41632950}],"con":true,"img":false}]}
{"op":"mcm","clk":"5353438923","pt":1646214974207,"mc":[{"id":"1.195453775","rc":[{"atb":[[4.7,0]],"id":41632950}],"con":true,"img":false}]}
{"op":"mcm","clk":"5353438941","pt":1646214974517,"mc":[{"id":"1.195453775","rc":[{"atb":[[4.6,1.66]],"id":41632950}],"con":true,"img":false}]}
{"op":"mcm","clk":"5353440239","pt":1646215000832,"mc":[{"id":"1.195453775","rc":[{"atb":[[4.4,0]],"id":41632950}],"con":true,"img":false}]}
{"op":"mcm","clk":"5353440244","pt":1646215000934,"mc":[{"id":"1.195453775","rc":[{"atb":[[4.6,14.87]],"id":41632950}],"con":true,"img":false}]}
{"op":"mcm","clk":"5353440250","pt":1646215001039,"mc":[{"id":"1.195453775","rc":[{"atb":[[4.5,5.71],[4.6,42.65]],"id":41632950}],"con":true,"img":false}]}
{"op":"mcm","clk":"5353441816","pt":1646215030880,"mc":[{"id":"1.195453775","rc":[{"atb":[[4.6,29.44]],"id":41632950},{"spn":8.05,"spf":"NaN","id":41632950}],"con":true,"img":false}]}
{"op":"mcm","clk":"5353441820","pt":1646215030983,"mc":[{"id":"1.195453775","rc":[{"atb":[[4.7,13.21]],"id":41632950}],"con":true,"img":false}]}
{"op":"mcm","clk":"5353442019","pt":1646215035280,"mc":[{"id":"1.195453775","rc":[{"atb":[[4.6,27.78]],"id":41632950}],"con":true,"img":false}]}
{"op":"mcm","clk":"5353442022","pt":1646215035384,"mc":[{"id":"1.195453775","rc":[{"atb":[[4.8,1.66]],"id":41632950}],"con":true,"img":false}]}
{"op":"mcm","clk":"5353457247","pt":1646215269321,"mc":[{"id":"1.195453775","rc":[{"atl":[[3.2,42.03],[3.35,31.91]],"id":42688799},{"atb":[[4.8,14.87]],"id":41632950},{"spn":8.15,"spf":"NaN","id":41632950},{"atb":[[3.9,76.19],[3.65,45.65]],"id":41132571},{"atb":[[5.3,0],[6,20]],"id":38745817}],"con":true,"img":false}]}
{"op":"mcm","clk":"5353457253","pt":1646215269422,"mc":[{"id":"1.195453775","rc":[{"atb":[[4.6,0]],"id":41632950}],"con":true,"img":false}]}
{"op":"mcm","clk":"5353457387","pt":1646215270830,"mc":[{"id":"1.195453775","rc":[{"atb":[[4.7,0]],"id":41632950}],"con":true,"img":false}]}
{"op":"mcm","clk":"5353457396","pt":1646215270928,"mc":[{"id":"1.195453775","rc":[{"atb":[[4.4,13.21]],"id":41632950}],"con":true,"img":false}]}
{"op":"mcm","clk":"5353468582","pt":1646215421653,"mc":[{"id":"1.195453775","rc":[{"atl":[[3.2,19.81],[3.35,74.46]],"id":42688799},{"atb":[[4.8,1.66],[4.6,27.78]],"id":41632950},{"atb":[[3.9,41.71],[3.65,83.39]],"id":41132571},{"atb":[[5.3,21.52],[6,0]],"id":38745817}],"con":true,"img":false}]}
{"op":"mcm","clk":"5353468629","pt":1646215422280,"mc":[{"id":"1.195453775","rc":[{"atl":[[2.12,17.86],[3.65,31.62]],"id":38247334},{"atb":[[1.72,0],[1.62,0],[1.96,66.24]],"id":42688799},{"atb":[[2.82,10.99],[2.34,0]],"id":39790958},{"atl":[[16,0],[17.5,6.06],[15,0]],"id":41132571},{"atb":[[1.18,0],[1.26,257.66],[1.08,0],[1.36,55.56]],"id":42256451},{"atb":[[7.8,0],[7,3.33]],"id":38745817}],"con":true,"img":false}]}
{"op":"mcm","clk":"5353468636","pt":1646215422388,"mc":[{"id":"1.195453775","rc":[{"atl":[[2.64,7.29],[3.65,9.12]],"id":38247334},{"atb":[[1.8,109.09]],"id":42688799},{"atb":[[2.5,80.65],[2.7,94.4]],"id":39790958},{"atl":[[17.5,7.27],[15.5,3.55]],"id":41132571}],"con":true,"img":false}]}
{"op":"mcm","clk":"5353468655","pt":1646215422652,"mc":[{"id":"1.195453775","rc":[{"atb":[[2.78,0]],"id":39790958},{"atb":[[4.8,0]],"id":41632950}],"con":true,"img":false}]}
{"op":"mcm","clk":"5353468671","pt":1646215422864,"mc":[{"id":"1.195453775","rc":[{"atb":[[2.84,1.66]],"id":39790958},{"atb":[[4.7,1.66]],"id":41632950}],"con":true,"img":false}]}
{"op":"mcm","clk":"5353468807","pt":1646215424590,"mc":[{"id":"1.195453775","rc":[{"atb":[[1.8,0],[1.88,113.64]],"id":42688799},{"atb":[[2.78,25.35],[2.7,35.58]],"id":39790958},{"atl":[[17,0]],"id":41132571},{"atl":[[2.8,55.56],[2.98,6.1]],"id":42256451}],"con":true,"img":false}]}
{"op":"mcm","clk":"5353468816","pt":1646215424694,"mc":[{"id":"1.195453775","rc":[{"atb":[[7.4,18.9]],"id":38745817}],"con":true,"img":false}]}
{"op":"mcm","clk":"5353469307","pt":1646215430774,"mc":[{"id":"1.195453775","rc":[{"atl":[[3.2,0]],"id":42688799},{"atl":[[13.5,0]],"id":41632950},{"atl":[[16.5,0]],"id":41132571}],"con":true,"img":false}]}
{"op":"mcm","clk":"5353469315","pt":1646215430885,"mc":[{"id":"1.195453775","rc":[{"atl":[[3.3,19.81]],"id":42688799},{"atl":[[14.5,2.72]],"id":41632950},{"atl":[[17,3.51]],"id":41132571}],"con":true,"img":false}]}
{"op":"mcm","clk":"5353469431","pt":1646215432292,"mc":[{"id":"1.195453775","rc":[{"atb":[[1.94,53.19]],"id":42688799},{"atb":[[2.78,53.44]],"id":39790958},{"atl":[[18.5,2.86]],"id":41132571},{"atb":[[1.34,147.06]],"id":42256451},{"atb":[[6.6,8.93]],"id":38745817}],"con":true,"img":false}]}
{"op":"mcm","clk":"5353469439","pt":1646215432395,"mc":[{"id":"1.195453775","rc":[{"atl":[[2.16,43.1]],"id":38247334}],"con":true,"img":false}]}
{"op":"mcm","clk":"5353469468","pt":1646215432765,"mc":[{"id":"1.195453775","rc":[{"atl":[[3.85,0],[3.75,0],[3.95,0]],"id":38247334},{"atb":[[1.66,0]],"id":42688799},{"atb":[[2.38,0]],"id":39790958},{"atb":[[1.12,0]],"id":42256451}],"con":true,"img":false}]}
{"op":"mcm","clk":"5353469641","pt":1646215435009,"mc":[{"id":"1.195453775","rc":[{"atl":[[3.35,31.91],[3.25,44.44]],"id":42688799},{"atb":[[3.95,77.79],[3.65,45.65]],"id":41132571},{"atb":[[5.3,0],[6,20]],"id":38745817}],"con":true,"img":false}]}
{"op":"mcm","clk":"5353469667","pt":1646215435316,"mc":[{"id":"1.195453775","rc":[{"atb":[[2.76,4.73]],"id":39790958}],"con":true,"img":false}]}
{"op":"mcm","clk":"5353470181","pt":1646215441383,"mc":[{"id":"1.195453775","rc":[{"atb":[[2.84,5.74]],"id":39790958}],"con":true,"img":false}]}
{"op":"mcm","clk":"5353470260","pt":1646215442276,"mc":[{"id":"1.195453775","rc":[{"atl":[[2.2,62.5]],"id":38247334},{"atb":[[1.92,81.52]],"id":42688799},{"atb":[[2.74,43.1]],"id":39790958},{"atl":[[19.5,4.05]],"id":41132571},{"atb":[[1.32,234.37]],"id":42256451}],"con":true,"img":false}]}
{"op":"mcm","clk":"5353470270","pt":1646215442376,"mc":[{"id":"1.195453775","rc":[{"atl":[[2.64,0],[2.44,60.96]],"id":38247334},{"atb":[[6.2,14.42]],"id":38745817}],"con":true,"img":false}]}
{"op":"mcm","clk":"5353470305","pt":1646215442793,"mc":[{"id":"1.195453775","rc":[{"atb":[[2.42,0]],"id":39790958},{"atb":[[1.14,0]],"id":42256451}],"con":true,"img":false}]}
{"op":"mcm","clk":"5353470310","pt":1646215442896,"mc":[{"id":"1.195453775","rc":[{"atb":[[1.68,0]],"id":42688799}],"con":true,"img":false}]}
{"op":"mcm","clk":"5353470974","pt":1646215450915,"mc":[{"id":"1.195453775","rc":[{"atl":[[2.44,0]],"id":42256451},{"atl":[[36,2.72]],"id":38745817}],"con":true,"img":false}]}
{"op":"mcm","clk":"5353470984","pt":1646215451023,"mc":[{"id":"1.195453775","rc":[{"atl":[[2.48,30.27]],"id":42256451},{"atl":[[44,2.72]],"id":38745817}],"con":true,"img":false}]}
{"op":"mcm","clk":"5353471026","pt":1646215451500,"mc":[{"id":"1.195453775","rc":[{"atb":[[2.76,0]],"id":39790958}],"con":true,"img":false}]}
{"op":"mcm","clk":"5353471102","pt":1646215452285,"mc":[{"id":"1.195453775","rc":[{"atb":[[2.7,109.11]],"id":39790958},{"atb":[[1.3,250]],"id":42256451},{"atb":[[5.9,25.51]],"id":38745817}],"con":true,"img":false}]}
{"op":"mcm","clk":"5353471110","pt":1646215452385,"mc":[{"id":"1.195453775","rc":[{"atl":[[2.24,100.81]],"id":38247334},{"atb":[[1.9,273.32]],"id":42688799},{"atl":[[21,6.85]],"id":41132571}],"con":true,"img":false}]}
{"op":"mcm","clk":"5353471151","pt":1646215453011,"mc":[{"id":"1.195453775","rc":[{"atb":[[1.7,0]],"id":42688799},{"atb":[[2.46,0]],"id":39790958},{"atl":[[18,0]],"id":41132571},{"atb":[[1.16,0]],"id":42256451}],"con":true,"img":false}]}
{"op":"mcm","clk":"5353471778","pt":1646215460790,"mc":[{"id":"1.195453775","rc":[{"atl":[[3.3,0]],"id":42688799},{"atb":[[2.72,0]],"id":39790958},{"atb":[[4.4,0]],"id":41632950}],"con":true,"img":false}]}
{"op":"mcm","clk":"5353471789","pt":1646215460897,"mc":[{"id":"1.195453775","rc":[{"atl":[[3.2,19.81],[3.35,74.46],[3.25,22.22]],"id":42688799},{"atb":[[2.8,25.34]],"id":39790958},{"atb":[[4.7,14.87]],"id":41632950}],"con":true,"img":false}]}
{"op":"mcm","clk":"5353471796","pt":1646215461002,"mc":[{"id":"1.195453775","rc":[{"atb":[[4.8,14.88],[4.6,0]],"id":41632950}],"con":true,"img":false}]}
{"op":"mcm","clk":"5353471986","pt":1646215463607,"mc":[{"id":"1.195453775","rc":[{"atb":[[2.84,10.27]],"id":39790958}],"con":true,"img":false}]}
{"op":"mcm","clk":"5353472336","pt":1646215468200,"mc":[{"id":"1.195453775","rc":[{"atb":[[4.7,13.21]],"id":41632950}],"con":true,"img":false}]}
{"op":"mcm","clk":"5353472356","pt":1646215468408,"mc":[{"id":"1.195453775","rc":[{"atb":[[4.9,1.66]],"id":41632950}],"con":true,"img":false}]}
{"op":"mcm","clk":"5353472547","pt":1646215470810,"mc":[{"id":"1.195453775","rc":[{"atl":[[3.35,0],[2.14,38.24]],"id":38247334},{"atl":[[3.2,0]],"id":42688799},{"atb":[[4.7,0]],"id":41632950}],"con":true,"img":false}]}
{"op":"mcm","clk":"5353472555","pt":1646215470913,"mc":[{"id":"1.195453775","rc":[{"atl":[[3.3,19.81]],"id":42688799},{"atb":[[4.4,13.21]],"id":41632950}],"con":true,"img":false}]}
{"op":"mcm","clk":"5353472796","pt":1646215473835,"mc":[{"id":"1.195453775","rc":[{"atl":[[3.25,44.44]],"id":42688799}],"con":true,"img":false}]}
{"op":"mcm","clk":"5353472803","pt":1646215473938,"mc":[{"id":"1.195453775","rc":[{"atl":[[3.35,31.91]],"id":42688799}],"con":true,"img":false}]}
{"op":"mcm","clk":"5353474295","pt":1646215490746,"mc":[{"id":"1.195453775","rc":[{"atl":[[2.42,38.85]],"id":38247334},{"spn":1.77,"spf":"NaN","id":38247334},{"atl":[[5,0]],"id":42688799},{"atb":[[2.06,0]],"id":39790958},{"spn":3.92,"spf":"NaN","id":39790958},{"atl":[[14.5,7.62]],"id":41632950},{"spn":8.2,"spf":"NaN","id":41632950},{"spn":9.95,"spf":"NaN","id":41132571},{"atl":[[3.75,0]],"id":42256451}],"con":true,"img":false}]}
{"op":"mcm","clk":"5353474301","pt":1646215490852,"mc":[{"id":"1.195453775","rc":[{"atl":[[3.6,0]],"id":38247334},{"atl":[[4.5,15.8]],"id":42688799},{"atb":[[2.18,61.03]],"id":39790958},{"atl":[[18,0]],"id":41632950},{"atl":[[3.35,23.97]],"id":42256451}],"con":true,"img":false}]}
{"op":"mcm","clk":"5353475070","pt":1646215500730,"mc":[{"id":"1.195453775","rc":[{"atl":[[3.3,0]],"id":42688799}],"con":true,"img":false}]}
{"op":"mcm","clk":"5353475079","pt":1646215500834,"mc":[{"id":"1.195453775","rc":[{"atl":[[3.2,19.81],[3.35,74.46]],"id":42688799}],"con":true,"img":false}]}
{"op":"mcm","clk":"5353475089","pt":1646215500940,"mc":[{"id":"1.195453775","rc":[{"atl":[[3.25,22.22]],"id":42688799}],"con":true,"img":false}]}
{"op":"mcm","clk":"5353475099","pt":1646215501045,"mc":[{"id":"1.195453775","rc":[{"atl":[[3.2,64.25],[3.35,31.91]],"id":42688799}],"con":true,"img":false}]}
{"op":"mcm","clk":"5353476812","pt":1646215520851,"mc":[{"id":"1.195453775","rc":[{"atb":[[1.71,0]],"id":42688799},{"atl":[[3.2,44.44]],"id":42688799}],"con":true,"img":false}]}
{"op":"mcm","clk":"5353476820","pt":1646215520957,"mc":[{"id":"1.195453775","rc":[{"atb":[[1.63,99.73]],"id":42688799},{"atl":[[3.2,0],[3.3,19.81]],"id":42688799}],"con":true,"img":false}]}
{"op":"mcm","clk":"5353476832","pt":1646215521058,"mc":[{"id":"1.195453775","rc":[{"atl":[[3.25,66.66]],"id":42688799}],"con":true,"img":false}]}
{"op":"mcm","clk":"5353478361","pt":1646215540082,"mc":[{"id":"1.195453775","rc":[{"atb":[[3.95,43.89],[3.9,76.19]],"id":41132571}],"con":true,"img":false}]}
{"op":"mcm","clk":"5353478419","pt":1646215540808,"mc":[{"id":"1.195453775","rc":[{"atl":[[3.3,0]],"id":42688799}],"con":true,"img":false}]}
{"op":"mcm","clk":"5353478426","pt":1646215540911,"mc":[{"id":"1.195453775","rc":[{"atl":[[3.2,19.81]],"id":42688799}],"con":true,"img":false}]}
{"op":"mcm","clk":"5353478432","pt":1646215541014,"mc":[{"id":"1.195453775","rc":[{"atl":[[3.35,74.46],[3.25,22.22]],"id":42688799}],"con":true,"img":false}]}
{"op":"mcm","clk":"5353478442","pt":1646215541120,"mc":[{"id":"1.195453775","rc":[{"atl":[[3.2,51.72],[3.35,31.91]],"id":42688799},{"atl":[[24,0],[13.5,1.6]],"id":41632950},{"atl":[[2.38,0]],"id":42256451}],"con":true,"img":false}]}
{"op":"mcm","clk":"5353478449","pt":1646215541176,"mc":[{"id":"1.195453775","rc":[{"atb":[[1.8,125],[1.88,0]],"id":42688799},{"atl":[[3.2,19.81]],"id":42688799},{"atl":[[11.5,0],[13,0],[30,3.45]],"id":41632950},{"atl":[[2.4,14.29]],"id":42256451}],"con":true,"img":false}]}
{"op":"mcm","clk":"5353478452","pt":1646215541279,"mc":[{"id":"1.195453775","rc":[{"atl":[[3.25,66.66]],"id":42688799}],"con":true,"img":false}]}
{"op":"mcm","clk":"5353478468","pt":1646215541392,"mc":[{"id":"1.195453775","rc":[{"atl":[[3.2,51.72]],"id":42688799}],"con":true,"img":false}]}
{"op":"mcm","clk":"5353478477","pt":1646215541489,"mc":[{"id":"1.195453775","rc":[{"atl":[[3.25,22.22]],"id":42688799}],"con":true,"img":false}]}
{"op":"mcm","clk":"5353478759","pt":1646215545210,"mc":[{"id":"1.195453775","rc":[{"atb":[[3.6,38.46]],"id":41132571}],"con":true,"img":false}]}
{"op":"mcm","clk":"5353478768","pt":1646215545313,"mc":[{"id":"1.195453775","rc":[{"atb":[[3.9,41.71]],"id":41132571}],"con":true,"img":false}]}
{"op":"mcm","clk":"5353479292","pt":1646215551111,"mc":[{"id":"1.195453775","rc":[{"atl":[[14.5,11.32]],"id":41632950},{"spn":9.2,"spf":"NaN","id":41632950},{"atl":[[2.44,34.72]],"id":42256451},{"spn":2.04,"spf":"NaN","id":42256451}],"con":true,"img":false}]}
{"op":"mcm","clk":"5353480167","pt":1646215560834,"mc":[{"id":"1.195453775","rc":[{"atl":[[3.2,31.91]],"id":42688799}],"con":true,"img":false}]}
{"op":"mcm","clk":"5353480177","pt":1646215560890,"mc":[{"id":"1.195453775","rc":[{"atl":[[3.3,19.81]],"id":42688799}],"con":true,"img":false}]}
{"op":"mcm","clk":"5353480185","pt":1646215560995,"mc":[{"id":"1.195453775","rc":[{"atl":[[3.2,0],[3.25,63.43]],"id":42688799}],"con":true,"img":false}]}
{"op":"mcm","clk":"5353480195","pt":1646215561101,"mc":[{"id":"1.195453775","rc":[{"atl":[[2.48,80.95]],"id":42256451}],"con":true,"img":false}]}
{"op":"mcm","clk":"5353480199","pt":1646215561203,"mc":[{"id":"1.195453775","rc":[{"atl":[[15.5,6]],"id":41632950},{"atl":[[2.5,0],[2.42,0],[2.46,0]],"id":42256451}],"con":true,"img":false}]}
{"op":"mcm","clk":"5353480261","pt":1646215561933,"mc":[{"id":"1.195453775","rc":[{"atb":[[1.46,2.16]],"id":38247334},{"atb":[[2.06,2.16]],"id":42688799},{"atb":[[1.72,2.16]],"id":42256451}],"con":true,"img":false}]}
{"op":"mcm","clk":"5353480755","pt":1646215567431,"mc":[{"id":"1.195453775","rc":[{"atb":[[2.02,0]],"id":42688799}],"con":true,"img":false}]}
{"op":"mcm","clk":"5353480774","pt":1646215567641,"mc":[{"id":"1.195453775","rc":[{"atb":[[2.08,1.66]],"id":42688799}],"con":true,"img":false}]}
{"op":"mcm","clk":"5353481101","pt":1646215571138,"mc":[{"id":"1.195453775","rc":[{"atl":[[16.5,8.06]],"id":41632950}],"con":true,"img":false}]}
{"op":"mcm","clk":"5353481110","pt":1646215571242,"mc":[{"id":"1.195453775","rc":[{"atl":[[14,0],[15,0]],"id":41632950},{"atl":[[2.52,82.24]],"id":42256451}],"con":true,"img":false}]}
{"op":"mcm","clk":"5353481953","pt":1646215580734,"mc":[{"id":"1.195453775","rc":[{"atl":[[3.3,0]],"id":42688799},{"atl":[[14.5,6.42]],"id":41632950}],"con":true,"img":false}]}
{"op":"mcm","clk":"5353481961","pt":1646215580840,"mc":[{"id":"1.195453775","rc":[{"atl":[[3.2,19.81],[3.35,74.46]],"id":42688799},{"atl":[[15,4.9]],"id":41632950}],"con":true,"img":false}]}
{"op":"mcm","clk":"5353481970","pt":1646215580939,"mc":[{"id":"1.195453775","rc":[{"atl":[[3.25,22.22]],"id":42688799}],"con":true,"img":false}]}
{"op":"mcm","clk":"5353482778","pt":1646215590764,"mc":[{"id":"1.195453775","rc":[{"atl":[[3.2,0]],"id":42688799}],"con":true,"img":false}]}
{"op":"mcm","clk":"5353482788","pt":1646215590868,"mc":[{"id":"1.195453775","rc":[{"atl":[[3.3,19.81]],"id":42688799}],"con":true,"img":false}]}
{"op":"mcm","clk":"5353482932","pt":1646215592540,"mc":[{"id":"1.195453775","rc":[{"atl":[[3.35,31.91],[3.25,44.44]],"id":42688799}],"con":true,"img":false}]}
{"op":"mcm","clk":"5353484607","pt":1646215610795,"mc":[{"id":"1.195453775","rc":[{"atb":[[3.95,42.37]],"id":41632950}],"con":true,"img":false}]}
{"op":"mcm","clk":"5353484619","pt":1646215610899,"mc":[{"id":"1.195453775","rc":[{"atb":[[4.2,21.25]],"id":41632950}],"con":true,"img":false}]}
{"op":"mcm","clk":"5353485534","pt":1646215620761,"mc":[{"id":"1.195453775","rc":[{"spn":1.79,"spf":"NaN","id":38247334},{"atl":[[3.3,0]],"id":42688799},{"spn":2.61,"spf":"NaN","id":42688799},{"spn":2.06,"spf":"NaN","id":42256451}],"con":true,"img":false}]}
{"op":"mcm","clk":"5353485543","pt":1646215620914,"mc":[{"id":"1.195453775","rc":[{"atl":[[3.2,19.81],[3.35,74.46],[3.25,22.22]],"id":42688799}],"con":true,"img":false}]}
{"op":"mcm","clk":"5353486438","pt":1646215630784,"mc":[{"id":"1.195453775","rc":[{"atl":[[3.2,0]],"id":42688799}],"con":true,"img":false}]}
{"op":"mcm","clk":"5353486446","pt":1646215630890,"mc":[{"id":"1.195453775","rc":[{"atl":[[3.3,19.81]],"id":42688799}],"con":true,"img":false}]}
{"op":"mcm","clk":"5353486565","pt":1646215632195,"mc":[{"id":"1.195453775","rc":[{"atl":[[3.35,31.91]],"id":42688799}],"con":true,"img":false}]}
{"op":"mcm","clk":"5353486574","pt":1646215632300,"mc":[{"id":"1.195453775","rc":[{"atl":[[3.25,44.44]],"id":42688799}],"con":true,"img":false}]}
{"op":"mcm","clk":"5353489190","pt":1646215660717,"mc":[{"id":"1.195453775","rc":[{"atl":[[3.3,0]],"id":42688799}],"con":true,"img":false}]}
{"op":"mcm","clk":"5353489198","pt":1646215660822,"mc":[{"id":"1.195453775","rc":[{"atl":[[3.2,19.81]],"id":42688799}],"con":true,"img":false}]}
{"op":"mcm","clk":"5353489204","pt":1646215660925,"mc":[{"id":"1.195453775","rc":[{"atl":[[3.35,74.46],[3.25,22.22]],"id":42688799}],"con":true,"img":false}]}
{"op":"mcm","clk":"5353489210","pt":1646215661031,"mc":[{"id":"1.195453775","rc":[{"atl":[[3.2,51.72],[3.35,31.91]],"id":42688799}],"con":true,"img":false}]}
{"op":"mcm","clk":"5353490986","pt":1646215680726,"mc":[{"id":"1.195453775","rc":[{"atl":[[3.2,31.91]],"id":42688799}],"con":true,"img":false}]}
{"op":"mcm","clk":"5353490995","pt":1646215680830,"mc":[{"id":"1.195453775","rc":[{"atl":[[3.2,0],[3.25,63.43],[3.3,19.81]],"id":42688799}],"con":true,"img":false}]}
{"op":"mcm","clk":"5353492720","pt":1646215700771,"mc":[{"id":"1.195453775","rc":[{"atl":[[3.3,0]],"id":42688799}],"con":true,"img":false}]}
{"op":"mcm","clk":"5353492728","pt":1646215700875,"mc":[{"id":"1.195453775","rc":[{"atl":[[3.2,19.81]],"id":42688799}],"con":true,"img":false}]}
{"op":"mcm","clk":"5353492737","pt":1646215700978,"mc":[{"id":"1.195453775","rc":[{"atl":[[3.35,74.46],[3.25,22.22]],"id":42688799}],"con":true,"img":false}]}
{"op":"mcm","clk":"5353492745","pt":1646215701082,"mc":[{"id":"1.195453775","rc":[{"atl":[[3.2,51.72],[3.35,31.91]],"id":42688799}],"con":true,"img":false}]}
{"op":"mcm","clk":"5353492753","pt":1646215701186,"mc":[{"id":"1.195453775","rc":[{"atl":[[3.2,19.81],[3.25,66.66]],"id":42688799}],"con":true,"img":false}]}
{"op":"mcm","clk":"5353492765","pt":1646215701292,"mc":[{"id":"1.195453775","rc":[{"atl":[[3.2,51.72],[3.25,22.22]],"id":42688799}],"con":true,"img":false}]}
{"op":"mcm","clk":"5353492787","pt":1646215701457,"mc":[{"id":"1.195453775","rc":[{"atl":[[3.2,19.81],[3.25,66.66]],"id":42688799}],"con":true,"img":false}]}
{"op":"mcm","clk":"5353493756","pt":1646215711997,"mc":[{"id":"1.195453775","rc":[{"atl":[[3.2,51.72]],"id":42688799}],"con":true,"img":false}]}
{"op":"mcm","clk":"5353493766","pt":1646215712101,"mc":[{"id":"1.195453775","rc":[{"atl":[[3.25,22.22]],"id":42688799}],"con":true,"img":false}]}
{"op":"mcm","clk":"5353495009","pt":1646215727788,"mc":[{"id":"1.195453775","rc":[{"atb":[[2.86,10.99],[2.78,28.09]],"id":39790958},{"atl":[[17.5,1.21],[18,7.06]],"id":41132571},{"atb":[[7.2,3.23],[7,0]],"id":38745817}],"con":true,"img":false}]}
{"op":"mcm","clk":"5353495020","pt":1646215727892,"mc":[{"id":"1.195453775","rc":[{"atl":[[17.5,0]],"id":41132571}],"con":true,"img":false}]}
{"op":"mcm","clk":"5353495131","pt":1646215729407,"mc":[{"id":"1.195453775","rc":[{"atb":[[2.84,8.6]],"id":39790958}],"con":true,"img":false}]}
{"op":"mcm","clk":"5353495149","pt":1646215729575,"mc":[{"id":"1.195453775","rc":[{"atb":[[2.88,1.66]],"id":39790958}],"con":true,"img":false}]}
{"op":"mcm","clk":"5353495244","pt":1646215730885,"mc":[{"id":"1.195453775","rc":[{"atl":[[44,0]],"id":38745817}],"con":true,"img":false}]}
{"op":"mcm","clk":"5353495251","pt":1646215730992,"mc":[{"id":"1.195453775","rc":[{"atl":[[36,5.44]],"id":38745817}],"con":true,"img":false}]}
{"op":"mcm","clk":"5353495559","pt":1646215734781,"mc":[{"id":"1.195453775","rc":[{"atb":[[1.37,54.66]],"id":38247334},{"atb":[[1.97,5.36]],"id":42688799},{"atb":[[1.62,37.71]],"id":42256451}],"con":true,"img":false}]}
{"op":"mcm","clk":"5353495786","pt":1646215737813,"mc":[{"id":"1.195453775","rc":[{"atl":[[19,2.78]],"id":41132571}],"con":true,"img":false}]}
{"op":"mcm","clk":"5353495821","pt":1646215738282,"mc":[{"id":"1.195453775","rc":[{"atl":[[18.5,0],[19.5,0],[21,0.6]],"id":41132571}],"con":true,"img":false}]}
{"op":"mcm","clk":"5353495937","pt":1646215739905,"mc":[{"id":"1.195453775","rc":[{"atb":[[1.92,103.26]],"id":42688799},{"atl":[[5.2,16.66]],"id":39790958},{"atb":[[1.33,60.61]],"id":42256451}],"con":true,"img":false}]}
{"op":"mcm","clk":"5353495946","pt":1646215740010,"mc":[{"id":"1.195453775","rc":[{"atb":[[1.92,21.74],[1.96,45.41],[1.94,0]],"id":42688799},{"atl":[[5,0],[5.2,4.76]],"id":39790958},{"atb":[[1.34,0],[1.36,0]],"id":42256451}],"con":true,"img":false}]}
{"op":"mcm","clk":"5353495963","pt":1646215740222,"mc":[{"id":"1.195453775","rc":[{"atl":[[3,4]],"id":42688799},{"atb":[[3.2,3]],"id":39790958},{"atl":[[2.1,2]],"id":42256451}],"con":true,"img":false}]}
{"op":"mcm","clk":"5353496008","pt":1646215740803,"mc":[{"id":"1.195453775","rc":[{"atl":[[17,0]],"id":41132571}],"con":true,"img":false}]}
{"op":"mcm","clk":"5353496020","pt":1646215740907,"mc":[{"id":"1.195453775","rc":[{"spn":2.54,"spf":"NaN","id":42688799},{"spn":4.2,"spf":"NaN","id":39790958},{"atl":[[17.5,3.51]],"id":41132571},{"spn":1.91,"spf":"NaN","id":42256451}],"con":true,"img":false}]}
{"op":"mcm","clk":"5353496053","pt":1646215741323,"mc":[{"id":"1.195453775","rc":[{"atb":[[1.2,0],[1.27,370.37]],"id":38247334},{"atb":[[1.8,0],[1.85,259.99]],"id":42688799},{"atb":[[3.6,0],[3.75,36.36]],"id":41132571}],"con":true,"img":false}]}
{"op":"mcm","clk":"5353496272","pt":1646215743890,"mc":[{"id":"1.195453775","rc":[{"atb":[[2.84,4.08]],"id":39790958}],"con":true,"img":false}]}
{"op":"mcm","clk":"5353496334","pt":1646215744613,"mc":[{"id":"1.195453775","rc":[{"atb":[[1.97,0]],"id":42688799}],"con":true,"img":false}]}
{"op":"mcm","clk":"5353496468","pt":1646215746134,"mc":[{"id":"1.195453775","rc":[{"atb":[[1.96,66.24]],"id":42688799},{"atl":[[3,0],[2.98,4]],"id":42688799},{"atb":[[3.25,2],[3.2,0]],"id":39790958},{"atl":[[5,5]],"id":39790958},{"atb":[[1.36,55.56]],"id":42256451},{"atl":[[2.1,0],[2.08,3]],"id":42256451}],"con":true,"img":false}]}
{"op":"mcm","clk":"5353496477","pt":1646215746187,"mc":[{"id":"1.195453775","rc":[{"atb":[[2.88,7.66],[2.86,0]],"id":39790958}],"con":true,"img":false}]}
{"op":"mcm","clk":"5353496487","pt":1646215746295,"mc":[{"id":"1.195453775","rc":[{"atl":[[2.08,0]],"id":42256451}],"con":true,"img":false}]}
{"op":"mcm","clk":"5353496497","pt":1646215746399,"mc":[{"id":"1.195453775","rc":[{"atl":[[2.98,0]],"id":42688799},{"atb":[[3.25,0]],"id":39790958}],"con":true,"img":false}]}
{"op":"mcm","clk":"5353496587","pt":1646215747395,"mc":[{"id":"1.195453775","rc":[{"atb":[[1.96,45.41]],"id":42688799},{"atl":[[3.1,4]],"id":42688799},{"atb":[[3.2,4]],"id":39790958},{"atb":[[1.36,0]],"id":42256451},{"atl":[[2.1,3]],"id":42256451}],"con":true,"img":false}]}
{"op":"mcm","clk":"5353496598","pt":1646215747498,"mc":[{"id":"1.195453775","rc":[{"atb":[[3.25,3]],"id":39790958},{"atl":[[5,0]],"id":39790958}],"con":true,"img":false}]}
{"op":"mcm","clk":"5353496608","pt":1646215747600,"mc":[{"id":"1.195453775","rc":[{"atl":[[3.05,2]],"id":42688799},{"atl":[[2.1,0],[2.06,2]],"id":42256451}],"con":true,"img":false}]}
{"op":"mcm","clk":"5353496623","pt":1646215747808,"mc":[{"id":"1.195453775","rc":[{"atl":[[20,3.95]],"id":41132571}],"con":true,"img":false}]}
{"op":"mcm","clk":"5353496663","pt":1646215748223,"mc":[{"id":"1.195453775","rc":[{"atb":[[1.33,60.61],[1.35,345.68]],"id":38247334},{"atb":[[1.96,66.24]],"id":42688799},{"atl":[[3.1,0],[3.05,0]],"id":42688799},{"atb":[[3.2,0],[3.25,0]],"id":39790958},{"atl":[[5,5]],"id":39790958},{"atb":[[1.36,55.56]],"id":42256451},{"atl":[[2.06,0]],"id":42256451}],"con":true,"img":false}]}
{"op":"mcm","clk":"5353496670","pt":1646215748326,"mc":[{"id":"1.195453775","rc":[{"atl":[[1.65,2]],"id":38247334}],"con":true,"img":false}]}
{"op":"mcm","clk":"5353496690","pt":1646215748607,"mc":[{"id":"1.195453775","rc":[{"atl":[[1.64,4]],"id":38247334}],"con":true,"img":false}]}
{"op":"mcm","clk":"5353496785","pt":1646215750006,"mc":[{"id":"1.195453775","rc":[{"atb":[[1.97,5.36]],"id":42688799}],"con":true,"img":false}]}
{"op":"mcm","clk":"5353497023","pt":1646215752727,"mc":[{"id":"1.195453775","rc":[{"atb":[[1.37,0]],"id":38247334}],"con":true,"img":false}]}
{"op":"mcm","clk":"5353497381","pt":1646215756504,"mc":[{"id":"1.195453775","rc":[{"atl":[[1.63,2]],"id":38247334}],"con":true,"img":false}]}
{"op":"mcm","clk":"5353497460","pt":1646215757445,"mc":[{"id":"1.195453775","rc":[{"atb":[[2.8,29.98]],"id":39790958}],"con":true,"img":false}]}
{"op":"mcm","clk":"5353497494","pt":1646215757822,"mc":[{"id":"1.195453775","rc":[{"atl":[[22,5.95]],"id":41132571}],"con":true,"img":false}]}
{"op":"mcm","clk":"5353497524","pt":1646215758236,"mc":[{"id":"1.195453775","rc":[{"atb":[[1.31,403.23]],"id":38247334},{"atb":[[1.94,53.19]],"id":42688799},{"atl":[[5.2,11.9]],"id":39790958}],"con":true,"img":false}]}
{"op":"mcm","clk":"5353497534","pt":1646215758338,"mc":[{"id":"1.195453775","rc":[{"atb":[[1.31,161.29]],"id":38247334}],"con":true,"img":false}]}
{"op":"mcm","clk":"5353497612","pt":1646215759331,"mc":[{"id":"1.195453775","rc":[{"atb":[[2.84,0]],"id":39790958}],"con":true,"img":false}]}
{"op":"mcm","clk":"5353498171","pt":1646215765634,"mc":[{"id":"1.195453775","rc":[{"atb":[[2.86,4.04]],"id":39790958}],"con":true,"img":false}]}
{"op":"mcm","clk":"5353498244","pt":1646215766534,"mc":[{"id":"1.195453775","rc":[{"atl":[[1.62,4]],"id":38247334}],"con":true,"img":false}]}
{"op":"mcm","clk":"5353498378","pt":1646215768256,"mc":[{"id":"1.195453775","rc":[{"atb":[[1.27,620.37]],"id":38247334},{"atb":[[1.92,103.26]],"id":42688799}],"con":true,"img":false}]}
{"op":"mcm","clk":"5353498385","pt":1646215768360,"mc":[{"id":"1.195453775","rc":[{"atb":[[1.92,81.52]],"id":42688799}],"con":true,"img":false}]}
{"op":"mcm","clk":"5353498503","pt":1646215769829,"mc":[{"id":"1.195453775","rc":[{"atb":[[2.9,5.36]],"id":39790958}],"con":true,"img":false}]}
{"op":"mcm","clk":"5353499274","pt":1646215779451,"mc":[{"id":"1.195453775","rc":[{"atb":[[2.88,6]],"id":39790958}],"con":true,"img":false}]}
{"op":"mcm","clk":"5353499296","pt":1646215779668,"mc":[{"id":"1.195453775","rc":[{"atb":[[1.4,0],[1.3,0],[1.35,0]],"id":38247334},{"atl":[[4.3,0],[2.86,0],[2.66,0],[3.15,0],[3.65,0]],"id":38247334},{"atb":[[1.85,117.65],[1.9,138.89],[1.95,0]],"id":42688799},{"atl":[[5.6,0],[7.2,0],[4.6,0],[9.2,0],[13,0]],"id":42688799},{"atb":[[2.92,1.66],[2.5,0],[2.6,0],[2.7,73.53]],"id":39790958},{"atl":[[16.5,0],[8.6,0],[11.5,0],[23,0],[6.6,0]],"id":39790958},{"atb":[[4.3,15.15],[3.9,0],[3.65,0]],"id":41632950},{"atl":[[32,0],[21,0],[55,0],[110,0],[15.5,5.17]],"id":41632950},{"atb":[[4.3,6.06],[3.9,0],[3.65,0]],"id":41132571},{"atl":[[32,0],[21,0],[55,0],[110,0],[15.5,2.72]],"id":41132571},{"atb":[[1.6,0],[1.55,0],[1.65,0]],"id":42256451},{"atl":[[3.45,0],[3.95,0],[4.9,0],[2.98,0],[5.9,0]],"id":42256451},{"atb":[[7.4,0],[8.4,0],[9.4,0]],"id":38745817},{"atl":[[310,0],[410,0],[210,0],[55,0],[110,0]],"id":38745817}],"con":true,"img":false}]}
{"op":"mcm","clk":"5353499354","pt":1646215780344,"mc":[{"id":"1.195453775","rc":[{"atb":[[1.43,19.38]],"id":38247334},{"atb":[[1.69,12.07]],"id":42256451}],"con":true,"img":false}]}
{"op":"mcm","clk":"5353499390","pt":1646215780862,"mc":[{"id":"1.195453775","rc":[{"atb":[[1.36,0]],"id":38247334},{"atb":[[1.96,20.83]],"id":42688799},{"atb":[[4.4,1.66]],"id":41132571},{"atb":[[1.61,0]],"id":42256451},{"atb":[[8.6,0]],"id":38745817}],"con":true,"img":false}]}
{"op":"mcm","clk":"5353499397","pt":1646215780965,"mc":[{"id":"1.195453775","rc":[{"atb":[[1.34,82.9]],"id":38247334},{"atb":[[1.95,45.41]],"id":42688799},{"atb":[[4.2,14.06]],"id":41132571},{"atb":[[1.54,70.03]],"id":42256451},{"atb":[[8.2,5.73]],"id":38745817}],"con":true,"img":false}]}
{"op":"mcm","clk":"5353499582","pt":1646215783458,"mc":[{"id":"1.195453775","rc":[{"atb":[[2,8.33]],"id":42688799}],"con":true,"img":false}]}
{"op":"mcm","clk":"5353499644","pt":1646215784198,"mc":[{"id":"1.195453775","rc":[{"atb":[[1.4,151.23],[1.3,403.29],[1.35,345.68]],"id":38247334},{"atl":[[4.3,14.66],[2.86,6.5],[2.66,7.28],[3.15,11.25],[3.65,9.12]],"id":38247334},{"atb":[[1.85,259.99],[1.9,273.32],[1.95,109.09]],"id":42688799},{"atl":[[5.6,2.63],[7.2,3.9],[4.6,3.36],[9.2,2.94],[13,4.03]],"id":42688799},{"atb":[[2.5,80.65],[2.6,75.61],[2.7,109.11]],"id":39790958},{"atl":[[16.5,1.55],[8.6,1.59],[11.5,2.3],[23,2.2],[6.6,2.15]],"id":39790958},{"atb":[[4.3,33.48],[3.9,41.71],[3.65,45.65]],"id":41632950},{"atl":[[32,0.77],[21,0.6],[55,0.44],[110,0.44],[15.5,6]],"id":41632950},{"atb":[[4.3,24.39],[3.9,41.71],[3.65,45.65]],"id":41132571},{"atl":[[32,0.77],[21,0.6],[55,0.44],[110,0.44],[15.5,3.55]],"id":41132571},{"atb":[[1.6,201.64],[1.55,219.97],[1.65,93.06]],"id":42256451},{"atl":[[3.45,4.93],[3.95,8.2],[4.9,6.2],[2.98,6.1],[5.9,9.87]],"id":42256451},{"atb":[[7.4,18.9],[8.4,16.34],[9.4,7.19]],"id":38745817},{"atl":[[310,0.07],[410,0.11],[210,0.11],[55,0.22],[110,0.1]],"id":38745817}],"con":true,"img":false}]}
{"op":"mcm","clk":"5353499695","pt":1646215784777,"mc":[{"id":"1.195453775","rc":[{"atb":[[1.62,0]],"id":42256451}],"con":true,"img":false}]}
{"op":"mcm","clk":"5353499741","pt":1646215785362,"mc":[{"id":"1.195453775","rc":[{"atb":[[2,0]],"id":42688799}],"con":true,"img":false}]}
{"op":"mcm","clk":"5353499820","pt":1646215786563,"mc":[{"id":"1.195453775","rc":[{"atb":[[1.99,2.16]],"id":42688799}],"con":true,"img":false}]}
{"op":"mcm","clk":"5353499828","pt":1646215786664,"mc":[{"id":"1.195453775","rc":[{"atb":[[2.06,0]],"id":42688799}],"con":true,"img":false}]}
{"op":"mcm","clk":"5353500032","pt":1646215789265,"mc":[{"id":"1.195453775","rc":[{"atb":[[1.99,9.76]],"id":42688799}],"con":true,"img":false}]}
{"op":"mcm","clk":"5353500048","pt":1646215789472,"mc":[{"id":"1.195453775","rc":[{"atb":[[2.08,0]],"id":42688799}],"con":true,"img":false}]}
{"op":"mcm","clk":"5353500075","pt":1646215789887,"mc":[{"id":"1.195453775","rc":[{"atb":[[1.61,22.79]],"id":42256451}],"con":true,"img":false}]}
{"op":"mcm","clk":"5353500250","pt":1646215792355,"mc":[{"id":"1.195453775","rc":[{"atb":[[1.69,22.97]],"id":42256451}],"con":true,"img":false}]}
{"op":"mcm","clk":"5353500969","pt":1646215800772,"mc":[{"id":"1.195453775","rc":[{"atl":[[36,2.72]],"id":38745817}],"con":true,"img":false}]}
{"op":"mcm","clk":"5353500975","pt":1646215800875,"mc":[{"id":"1.195453775","rc":[{"atl":[[32,2.72]],"id":38745817}],"con":true,"img":false}]}
{"op":"mcm","clk":"5353501047","pt":1646215801867,"mc":[{"id":"1.195453775","rc":[{"spn":1.54,"spf":"NaN","id":38247334},{"atb":[[1.99,18.18]],"id":42688799},{"spn":2.57,"spf":"NaN","id":42688799},{"spn":3.96,"spf":"NaN","id":39790958},{"spn":2.06,"spf":"NaN","id":42256451}],"con":true,"img":false}]}
{"op":"mcm","clk":"5353501241","pt":1646215804275,"mc":[{"id":"1.195453775","rc":[{"atl":[[1.62,0],[1.66,3]],"id":38247334}],"con":true,"img":false}]}
{"op":"mcm","clk":"5353501745","pt":1646215810905,"mc":[{"id":"1.195453775","rc":[{"atb":[[1.34,0]],"id":38247334},{"atb":[[1.95,63.67]],"id":42688799},{"atb":[[1.54,0]],"id":42256451}],"con":true,"img":false}]}
{"op":"mcm","clk":"5353501750","pt":1646215811004,"mc":[{"id":"1.195453775","rc":[{"atb":[[1.36,82.9]],"id":38247334},{"atb":[[1.96,66.24]],"id":42688799},{"atb":[[1.61,92.83]],"id":42256451}],"con":true,"img":false}]}
{"op":"mcm","clk":"5353501941","pt":1646215813577,"mc":[{"id":"1.195453775","rc":[{"atb":[[1.99,10.58]],"id":42688799}],"con":true,"img":false}]}
{"op":"mcm","clk":"5353501994","pt":1646215814307,"mc":[{"id":"1.195453775","rc":[{"atl":[[1.62,3],[1.66,0]],"id":38247334}],"con":true,"img":false}]}
{"op":"mcm","clk":"5353502376","pt":1646215819407,"mc":[{"id":"1.195453775","rc":[{"atb":[[2,7.51]],"id":42688799}],"con":true,"img":false}]}
{"op":"mcm","clk":"5353502480","pt":1646215820878,"mc":[{"id":"1.195453775","rc":[{"atb":[[4.2,0]],"id":41132571},{"atb":[[8.2,0]],"id":38745817}],"con":true,"img":false}]}
{"op":"mcm","clk":"5353502488","pt":1646215820982,"mc":[{"id":"1.195453775","rc":[{"atb":[[4.4,15.73]],"id":41132571},{"atb":[[8.6,5.73]],"id":38745817}],"con":true,"img":false}]}
{"op":"mcm","clk":"5353502728","pt":1646215824217,"mc":[{"id":"1.195453775","rc":[{"atb":[[1.97,0]],"id":42688799}],"con":true,"img":false}]}
{"op":"mcm","clk":"5353502898","pt":1646215826389,"mc":[{"id":"1.195453775","rc":[{"atb":[[2.02,1.66]],"id":42688799}],"con":true,"img":false}]}
{"op":"mcm","clk":"5353503115","pt":1646215829326,"mc":[{"id":"1.195453775","rc":[{"atb":[[1.97,10.1]],"id":42688799}],"con":true,"img":false}]}
{"op":"mcm","clk":"5353503138","pt":1646215829597,"mc":[{"id":"1.195453775","rc":[{"atb":[[1.99,2.16]],"id":42688799}],"con":true,"img":false}]}
{"op":"mcm","clk":"5353504507","pt":1646215846228,"mc":[{"id":"1.195453775","rc":[{"atb":[[2,15.85]],"id":42688799}],"con":true,"img":false}]}
{"op":"mcm","clk":"5353504574","pt":1646215847053,"mc":[{"id":"1.195453775","rc":[{"atb":[[1.99,0],[2.06,2.16]],"id":42688799}],"con":true,"img":false}]}
{"op":"mcm","clk":"5353504947","pt":1646215851456,"mc":[{"id":"1.195453775","rc":[{"atb":[[1.97,0]],"id":42688799}],"con":true,"img":false}]}
{"op":"mcm","clk":"5353505111","pt":1646215853555,"mc":[{"id":"1.195453775","rc":[{"atb":[[2.02,0]],"id":42688799}],"con":true,"img":false}]}
{"op":"mcm","clk":"5353505122","pt":1646215853616,"mc":[{"id":"1.195453775","rc":[{"atb":[[2.08,1.66]],"id":42688799}],"con":true,"img":false}]}
{"op":"mcm","clk":"5353505399","pt":1646215856755,"mc":[{"id":"1.195453775","rc":[{"atb":[[1.97,19.82]],"id":42688799}],"con":true,"img":false}]}
{"op":"mcm","clk":"5353505883","pt":1646215861929,"mc":[{"id":"1.195453775","rc":[{"atb":[[1.97,0]],"id":42688799},{"spn":2.61,"spf":"NaN","id":42688799}],"con":true,"img":false}]}
{"op":"mcm","clk":"5353506409","pt":1646215866972,"mc":[{"id":"1.195453775","rc":[{"atb":[[1.97,5.36]],"id":42688799}],"con":true,"img":false}]}
{"op":"mcm","clk":"5353509398","pt":1646215901824,"mc":[{"id":"1.195453775","rc":[{"atb":[[1.33,0],[1.35,402.82]],"id":38247334},{"atl":[[1.64,0],[1.62,0],[1.63,0],[1.65,0]],"id":38247334},{"atb":[[3.2,3]],"id":39790958},{"atl":[[5,0],[5.2,4.76]],"id":39790958}],"con":true,"img":false}]}
{"op":"mcm","clk":"5353509416","pt":1646215901980,"mc":[{"id":"1.195453775","rc":[{"atb":[[3.25,2]],"id":39790958}],"con":true,"img":false}]}
{"op":"mcm","clk":"5353509477","pt":1646215902663,"mc":[{"id":"1.195453775","rc":[{"atb":[[3.3,3]],"id":39790958}],"con":true,"img":false}]}
{"op":"mcm","clk":"5353509504","pt":1646215902973,"mc":[{"id":"1.195453775","rc":[{"atl":[[5,5]],"id":39790958}],"con":true,"img":false}]}
{"op":"mcm","clk":"5353509512","pt":1646215903078,"mc":[{"id":"1.195453775","rc":[{"atb":[[3.25,0],[3.3,0],[3.2,0]],"id":39790958}],"con":true,"img":false}]}
{"op":"mcm","clk":"5353509556","pt":1646215903602,"mc":[{"id":"1.195453775","rc":[{"atl":[[2.12,0],[2.1,18.18]],"id":38247334},{"atl":[[13.5,0],[14,1.54]],"id":41632950},{"atl":[[2.4,0],[2.42,14.08]],"id":42256451},{"atl":[[46,2.22],[65,0]],"id":38745817}],"con":true,"img":false}]}
{"op":"mcm","clk":"5353509654","pt":1646215904693,"mc":[{"id":"1.195453775","rc":[{"atb":[[2.9,0]],"id":39790958}],"con":true,"img":false}]}
{"op":"mcm","clk":"5353509664","pt":1646215904798,"mc":[{"id":"1.195453775","rc":[{"atb":[[1.36,0]],"id":42256451},{"atl":[[2.12,3]],"id":42256451}],"con":true,"img":false}]}
{"op":"mcm","clk":"5353509682","pt":1646215905003,"mc":[{"id":"1.195453775","rc":[{"atl":[[2.12,0],[2.08,2]],"id":42256451}],"con":true,"img":false}]}
{"op":"mcm","clk":"5353509707","pt":1646215905311,"mc":[{"id":"1.195453775","rc":[{"atl":[[2.06,4]],"id":42256451}],"con":true,"img":false}]}
{"op":"mcm","clk":"5353509864","pt":1646215907092,"mc":[{"id":"1.195453775","rc":[{"atb":[[1.61,70.03]],"id":42256451}],"con":true,"img":false}]}
{"op":"mcm","clk":"5353509903","pt":1646215907507,"mc":[{"id":"1.195453775","rc":[{"atb":[[2.92,0]],"id":39790958}],"con":true,"img":false}]}
{"op":"mcm","clk":"5353509926","pt":1646215907718,"mc":[{"id":"1.195453775","rc":[{"atb":[[2.9,1.66]],"id":39790958}],"con":true,"img":false}]}
{"op":"mcm","clk":"5353510101","pt":1646215909590,"mc":[{"id":"1.195453775","rc":[{"atb":[[1.43,36.87]],"id":38247334}],"con":true,"img":false}]}
{"op":"mcm","clk":"5353510131","pt":1646215909902,"mc":[{"id":"1.195453775","rc":[{"atb":[[1.37,30.18]],"id":38247334}],"con":true,"img":false}]}
{"op":"mcm","clk":"5353510302","pt":1646215912080,"mc":[{"id":"1.195453775","rc":[{"atl":[[2.04,4]],"id":42256451}],"con":true,"img":false}]}
{"op":"mcm","clk":"5353510319","pt":1646215912285,"mc":[{"id":"1.195453775","rc":[{"atl":[[2.08,0]],"id":42256451}],"con":true,"img":false}]}
{"op":"mcm","clk":"5353510359","pt":1646215912707,"mc":[{"id":"1.195453775","rc":[{"atb":[[1.62,37.71]],"id":42256451}],"con":true,"img":false}]}
{"op":"mcm","clk":"5353510394","pt":1646215913024,"mc":[{"id":"1.195453775","rc":[{"atl":[[5.2,11.9]],"id":39790958}],"con":true,"img":false}]}
{"op":"mcm","clk":"5353510455","pt":1646215913600,"mc":[{"id":"1.195453775","rc":[{"atb":[[1.33,151.52]],"id":38247334},{"atl":[[15,8.47]],"id":41632950},{"atb":[[1.31,161.29]],"id":42256451},{"atl":[[2.46,34.25]],"id":42256451}],"con":true,"img":false}]}
{"op":"mcm","clk":"5353511079","pt":1646215920812,"mc":[{"id":"1.195453775","rc":[{"atl":[[32,0]],"id":38745817}],"con":true,"img":false}]}
{"op":"mcm","clk":"5353511094","pt":1646215920918,"mc":[{"id":"1.195453775","rc":[{"atb":[[9.6,4.65],[8.6,11.71]],"id":38745817},{"atl":[[34,8.25],[36,5.44],[24,2.5],[27,2.99],[28,6]],"id":38745817}],"con":true,"img":false}]}
{"op":"mcm","clk":"5353511101","pt":1646215921023,"mc":[{"id":"1.195453775","rc":[{"atb":[[1.46,58.51],[1.37,40.18],[1.45,2.5],[1.4,263.93],[1.41,5]],"id":38247334},{"atl":[[2.1,74.53],[2.16,147.57]],"id":38247334},{"atb":[[2.82,37.71],[2.94,5],[3.05,2.5],[2.88,14.25],[2.86,14.04]],"id":39790958},{"atl":[[5,13.25]],"id":39790958},{"atb":[[5.1,2.5],[4.9,10.76],[4.4,35.55],[4.7,5]],"id":41632950},{"atl":[[14,7.69]],"id":41632950},{"atb":[[4.1,50.31],[4.4,32.82]],"id":41132571},{"atl":[[18,19.59],[15,5.71]],"id":41132571},{"atb":[[1.73,5],[1.69,32.97],[1.72,15.72],[1.77,2.5],[1.65,120.18]],"id":42256451},{"atl":[[2.42,41.2]],"id":42256451}],"con":true,"img":false}]}
{"op":"mcm","clk":"5353511111","pt":1646215921127,"mc":[{"id":"1.195453775","rc":[{"atb":[[5.1,13.27]],"id":41632950},{"atb":[[4,5],[4.4,35.32]],"id":41132571},{"atl":[[11,2.5],[13,5],[15,15.71]],"id":41132571}],"con":true,"img":false}]}
{"op":"mcm","clk":"5353511120","pt":1646215921228,"mc":[{"id":"1.195453775","rc":[{"atb":[[4.8,0]],"id":41632950}],"con":true,"img":false}]}
{"op":"mcm","clk":"5353511160","pt":1646215921646,"mc":[{"id":"1.195453775","rc":[{"atb":[[1.43,19.38]],"id":38247334},{"atb":[[2.86,10]],"id":39790958}],"con":true,"img":false}]}
{"op":"mcm","clk":"5353511202","pt":1646215922013,"mc":[{"id":"1.195453775","rc":[{"atb":[[1.27,370.37]],"id":38247334},{"spn":1.78,"spf":"NaN","id":38247334},{"atb":[[2.06,21.02],[1.97,43.08]],"id":42688799},{"atl":[[3.15,28.16],[3.25,59.94]],"id":42688799},{"spn":4.02,"spf":"NaN","id":39790958},{"atl":[[16.5,0],[14.5,2.72],[15.5,0.83]],"id":41632950},{"spn":9.55,"spf":"NaN","id":41632950},{"spn":7.7,"spf":"NaN","id":41132571},{"atl":[[2.02,4]],"id":42256451},{"spn":1.89,"spf":"NaN","id":42256451},{"spn":16.8,"spf":"NaN","id":38745817}],"con":true,"img":false}]}
{"op":"mcm","clk":"5353511208","pt":1646215922118,"mc":[{"id":"1.195453775","rc":[{"atl":[[2.44,0],[2.48,30.27],[2.52,0]],"id":42256451}],"con":true,"img":false}]}
{"op":"mcm","clk":"5353511216","pt":1646215922224,"mc":[{"id":"1.195453775","rc":[{"atl":[[2.06,0],[2.42,14.08]],"id":42256451}],"con":true,"img":false}]}
{"op":"mcm","clk":"5353511327","pt":1646215923529,"mc":[{"id":"1.195453775","rc":[{"atb":[[1.31,0]],"id":38247334},{"atl":[[16,5]],"id":41632950},{"atb":[[1.29,250]],"id":42256451},{"atl":[[2.5,50]],"id":42256451}],"con":true,"img":false}]}
{"op":"mcm","clk":"5353511338","pt":1646215923630,"mc":[{"id":"1.195453775","rc":[{"atb":[[1.31,241.94]],"id":38247334}],"con":true,"img":false}]}
{"op":"mcm","clk":"5353511442","pt":1646215924510,"mc":[{"id":"1.195453775","rc":[{"atb":[[2,8.33]],"id":42688799}],"con":true,"img":false}]}
{"op":"mcm","clk":"5353511554","pt":1646215925546,"mc":[{"id":"1.195453775","rc":[{"atb":[[1.37,10]],"id":38247334},{"atb":[[2.9,0]],"id":39790958},{"atb":[[4.9,9.1]],"id":41632950},{"atb":[[1.62,0]],"id":42256451}],"con":true,"img":false}]}
{"op":"mcm","clk":"5353511576","pt":1646215925753,"mc":[{"id":"1.195453775","rc":[{"atb":[[3.1,1.66]],"id":39790958},{"atb":[[5.2,1.66]],"id":41632950}],"con":true,"img":false}]}
{"op":"mcm","clk":"5353511768","pt":1646215927526,"mc":[{"id":"1.195453775","rc":[{"atb":[[1.49,15.34]],"id":38247334},{"atb":[[2.88,18.25]],"id":39790958}],"con":true,"img":false}]}
{"op":"mcm","clk":"5353511808","pt":1646215927938,"mc":[{"id":"1.195453775","rc":[{"atb":[[1.46,56.35],[1.52,2.16]],"id":38247334}],"con":true,"img":false}]}
{"op":"mcm","clk":"5353511903","pt":1646215928934,"mc":[{"id":"1.195453775","rc":[{"atb":[[1.32,0],[1.3,0]],"id":42256451},{"atl":[[2,2]],"id":42256451}],"con":true,"img":false}]}
{"op":"mcm","clk":"5353511954","pt":1646215929348,"mc":[{"id":"1.195453775","rc":[{"atl":[[1.99,4]],"id":42256451}],"con":true,"img":false}]}
{"op":"mcm","clk":"5353512092","pt":1646215930649,"mc":[{"id":"1.195453775","rc":[{"atb":[[2.02,7.36]],"id":42688799}],"con":true,"img":false}]}
{"op":"mcm","clk":"5353512110","pt":1646215930856,"mc":[{"id":"1.195453775","rc":[{"atb":[[1.32,0],[1.22,125.72]],"id":38247334},{"atl":[[3.1,51.98],[2.42,0]],"id":38247334},{"atb":[[1.63,0]],"id":42688799},{"atl":[[4.5,0],[6.6,28.3]],"id":42688799},{"atl":[[8.2,0],[11.5,21.46]],"id":39790958},{"atb":[[4.2,0]],"id":41632950},{"atl":[[29,9.5],[15,3.57]],"id":41632950},{"atl":[[17.5,0],[21,9.25]],"id":41132571},{"atb":[[1.4,92.59]],"id":42256451},{"atl":[[3.35,0],[4.5,40.31]],"id":42256451},{"atl":[[36,1.16],[90,4]],"id":38745817}],"con":true,"img":false}]}
{"op":"mcm","clk":"5353512120","pt":1646215930911,"mc":[{"id":"1.195453775","rc":[{"atb":[[1.56,99.73]],"id":42688799},{"atb":[[4,21.25]],"id":41632950}],"con":true,"img":false}]}
{"op":"mcm","clk":"5353512141","pt":1646215931225,"mc":[{"id":"1.195453775","rc":[{"atb":[[1.5,10.74]],"id":38247334},{"atb":[[2.96,4.57]],"id":39790958}],"con":true,"img":false}]}
{"op":"mcm","clk":"5353512156","pt":1646215931435,"mc":[{"id":"1.195453775","rc":[{"atb":[[1.4,151.23]],"id":38247334}],"con":true,"img":false}]}
{"op":"mcm","clk":"5353512222","pt":1646215932222,"mc":[{"id":"1.195453775","rc":[{"atb":[[1.36,55.56]],"id":42256451},{"atl":[[2,0],[2.04,0],[1.99,0],[2.02,0]],"id":42256451}],"con":true,"img":false}]}
{"op":"mcm","clk":"5353512231","pt":1646215932325,"mc":[{"id":"1.195453775","rc":[{"atl":[[2.42,16.08]],"id":42256451}],"con":true,"img":false}]}
{"op":"mcm","clk":"5353512325","pt":1646215933524,"mc":[{"id":"1.195453775","rc":[{"atl":[[17,7.81]],"id":41632950}],"con":true,"img":false}]}
{"op":"mcm","clk":"5353512344","pt":1646215933841,"mc":[{"id":"1.195453775","rc":[{"atb":[[1.97,37.72]],"id":42688799}],"con":true,"img":false}]}
{"op":"mcm","clk":"5353512837","pt":1646215938453,"mc":[{"id":"1.195453775","rc":[{"atl":[[34,2.27],[24,5.98],[28,14.49]],"id":38745817}],"con":true,"img":false}]}
{"op":"mcm","clk":"5353512849","pt":1646215938559,"mc":[{"id":"1.195453775","rc":[{"atb":[[2.82,10.99],[2.94,27.71],[3.05,13.54]],"id":39790958},{"atb":[[5.2,10.1],[4.4,13.21],[4.7,24.04]],"id":41632950},{"atl":[[10.5,8.42],[15,31.58],[18,7.06]],"id":41132571},{"atb":[[1.72,63.44],[1.77,26.36],[1.65,93.06]],"id":42256451},{"atl":[[2.48,77.99]],"id":42256451},{"atl":[[27,0]],"id":38745817}],"con":true,"img":false}]}
{"op":"mcm","clk":"5353512858","pt":1646215938663,"mc":[{"id":"1.195453775","rc":[{"atb":[[2.88,10]],"id":39790958},{"atb":[[4.9,24.04]],"id":41632950},{"atl":[[15,25.87]],"id":41132571},{"atb":[[1.72,49.88]],"id":42256451}],"con":true,"img":false}]}
{"op":"mcm","clk":"5353512869","pt":1646215938767,"mc":[{"id":"1.195453775","rc":[{"atb":[[5.1,2.5],[4.9,14.94]],"id":41632950}],"con":true,"img":false}]}
{"op":"mcm","clk":"5353512935","pt":1646215939418,"mc":[{"id":"1.195453775","rc":[{"atb":[[1.74,2.75]],"id":42256451}],"con":true,"img":false}]}
{"op":"mcm","clk":"5353512943","pt":1646215939526,"mc":[{"id":"1.195453775","rc":[{"atb":[[2,84.62],[1.97,0]],"id":42688799},{"atb":[[1.72,47.72],[1.8,2.16]],"id":42256451}],"con":true,"img":false}]}
{"op":"mcm","clk":"5353512966","pt":1646215939735,"mc":[{"id":"1.195453775","rc":[{"atb":[[2.88,6]],"id":39790958},{"atb":[[1.69,22.07]],"id":42256451}],"con":true,"img":false}]}
{"op":"mcm","clk":"5353513074","pt":1646215940828,"mc":[{"id":"1.195453775","rc":[{"atl":[[5.3,0]],"id":39790958},{"atb":[[4.4,0]],"id":41632950},{"atl":[[2.48,47.72]],"id":42256451},{"atb":[[7.6,12.2]],"id":38745817}],"con":true,"img":false}]}
{"op":"mcm","clk":"5353513084","pt":1646215940932,"mc":[{"id":"1.195453775","rc":[{"atl":[[5.5,10.13]],"id":39790958},{"atb":[[4.8,13.21]],"id":41632950},{"atl":[[2.78,30.27]],"id":42256451}],"con":true,"img":false}]}
{"op":"mcm","clk":"5353513217","pt":1646215942249,"mc":[{"id":"1.195453775","rc":[{"atl":[[2.54,81.17]],"id":42256451}],"con":true,"img":false}]}
{"op":"mcm","clk":"5353513280","pt":1646215942733,"mc":[{"id":"1.195453775","rc":[{"atb":[[2.02,0]],"id":42688799}],"con":true,"img":false}]}
{"op":"mcm","clk":"5353513575","pt":1646215945629,"mc":[{"id":"1.195453775","rc":[{"atb":[[3,3.75]],"id":39790958},{"atb":[[1.76,9.89]],"id":42256451}],"con":true,"img":false}]}
{"op":"mcm","clk":"5353513591","pt":1646215945733,"mc":[{"id":"1.195453775","rc":[{"atb":[[1.43,0]],"id":38247334},{"atb":[[2,76.29]],"id":42688799},{"atb":[[2.8,25.34]],"id":39790958}],"con":true,"img":false}]}
{"op":"mcm","clk":"5353513677","pt":1646215946565,"mc":[{"id":"1.195453775","rc":[{"atl":[[30,9.83]],"id":38745817}],"con":true,"img":false}]}
{"op":"mcm","clk":"5353513686","pt":1646215946668,"mc":[{"id":"1.195453775","rc":[{"atl":[[28,6]],"id":38745817}],"con":true,"img":false}]}
{"op":"mcm","clk":"5353513706","pt":1646215946828,"mc":[{"id":"1.195453775","rc":[{"atb":[[5.2,20.21],[4.9,0]],"id":41632950}],"con":true,"img":false}]}
{"op":"mcm","clk":"5353513786","pt":1646215947759,"mc":[{"id":"1.195453775","rc":[{"atb":[[2,0],[1.96,191.08]],"id":42688799}],"con":true,"img":false}]}
{"op":"mcm","clk":"5353513948","pt":1646215949470,"mc":[{"id":"1.195453775","rc":[{"atb":[[2.96,0]],"id":39790958},{"atb":[[1.74,0]],"id":42256451}],"con":true,"img":false}]}
{"op":"mcm","clk":"5353514067","pt":1646215950731,"mc":[{"id":"1.195453775","rc":[{"atb":[[2.8,0]],"id":39790958},{"atl":[[15.5,0.83]],"id":41132571},{"atl":[[36,0]],"id":38745817}],"con":true,"img":false}]}
{"op":"mcm","clk":"5353514083","pt":1646215950835,"mc":[{"id":"1.195453775","rc":[{"atb":[[2.96,25.34]],"id":39790958},{"atl":[[12,2.72]],"id":41132571},{"atl":[[27,1.16]],"id":38745817}],"con":true,"img":false}]}
{"op":"mcm","clk":"5353514191","pt":1646215951933,"mc":[{"id":"1.195453775","rc":[{"atb":[[3,0]],"id":39790958}],"con":true,"img":false}]}
{"op":"mcm","clk":"5353514464","pt":1646215954743,"mc":[{"id":"1.195453775","rc":[{"atb":[[2,7.51]],"id":42688799}],"con":true,"img":false}]}
{"op":"mcm","clk":"5353514510","pt":1646215955244,"mc":[{"id":"1.195453775","rc":[{"atb":[[1.97,31.76]],"id":42688799},{"atb":[[1.74,31.37]],"id":42256451}],"con":true,"img":false}]}
{"op":"mcm","clk":"5353514547","pt":1646215955664,"mc":[{"id":"1.195453775","rc":[{"atb":[[4.8,30.1]],"id":41632950},{"atl":[[12,23.58],[15,10]],"id":41132571},{"atb":[[1.76,73.55]],"id":42256451},{"atl":[[28,14.93],[30,1.72]],"id":38745817}],"con":true,"img":false}]}
{"op":"mcm","clk":"5353514557","pt":1646215955769,"mc":[{"id":"1.195453775","rc":[{"atb":[[4.7,5]],"id":41632950},{"atb":[[1.72,0]],"id":42256451}],"con":true,"img":false}]}
{"op":"mcm","clk":"5353514652","pt":1646215956755,"mc":[{"id":"1.195453775","rc":[{"atb":[[1.97,121.66],[1.96,66.24]],"id":42688799}],"con":true,"img":false}]}
{"op":"mcm","clk":"5353514739","pt":1646215957787,"mc":[{"id":"1.195453775","rc":[{"atb":[[3.05,17.2]],"id":39790958}],"con":true,"img":false}]}
{"op":"mcm","clk":"5353514749","pt":1646215957843,"mc":[{"id":"1.195453775","rc":[{"atb":[[2,0]],"id":42688799},{"atb":[[1.76,63.66]],"id":42256451}],"con":true,"img":false}]}
{"op":"mcm","clk":"5353514907","pt":1646215959563,"mc":[{"id":"1.195453775","rc":[{"atb":[[1.69,10]],"id":42256451}],"con":true,"img":false}]}
{"op":"mcm","clk":"5353514918","pt":1646215959667,"mc":[{"id":"1.195453775","rc":[{"atb":[[1.49,32.35]],"id":38247334}],"con":true,"img":false}]}
{"op":"mcm","clk":"5353514947","pt":1646215959979,"mc":[{"id":"1.195453775","rc":[{"atb":[[3,4.16]],"id":39790958}],"con":true,"img":false}]}
{"op":"mcm","clk":"5353514958","pt":1646215960084,"mc":[{"id":"1.195453775","rc":[{"atb":[[2.96,70.79]],"id":39790958}],"con":true,"img":false}]}
{"op":"mcm","clk":"5353514967","pt":1646215960189,"mc":[{"id":"1.195453775","rc":[{"atb":[[2.94,5]],"id":39790958}],"con":true,"img":false}]}
{"op":"mcm","clk":"5353515011","pt":1646215960560,"mc":[{"id":"1.195453775","rc":[{"atb":[[1.97,89.9]],"id":42688799}],"con":true,"img":false}]}
{"op":"mcm","clk":"5353515344","pt":1646215963773,"mc":[{"id":"1.195453775","rc":[{"atb":[[2.02,7.36]],"id":42688799},{"atb":[[1.8,11.56]],"id":42256451}],"con":true,"img":false}]}
{"op":"mcm","clk":"5353515549","pt":1646215965766,"mc":[{"id":"1.195453775","rc":[{"atb":[[1.98,29.49]],"id":42688799}],"con":true,"img":false}]}
{"op":"mcm","clk":"5353515559","pt":1646215965872,"mc":[{"id":"1.195453775","rc":[{"atb":[[1.98,115.98],[1.97,0]],"id":42688799}],"con":true,"img":false}]}
{"op":"mcm","clk":"5353515846","pt":1646215968383,"mc":[{"id":"1.195453775","rc":[{"atb":[[1.74,0]],"id":42256451}],"con":true,"img":false}]}
{"op":"mcm","clk":"5353516081","pt":1646215970796,"mc":[{"id":"1.195453775","rc":[{"atl":[[2.14,0]],"id":38247334}],"con":true,"img":false}]}
{"op":"mcm","clk":"5353516094","pt":1646215970897,"mc":[{"id":"1.195453775","rc":[{"atl":[[2.2,181.26],[2.08,38.24]],"id":38247334}],"con":true,"img":false}]}
{"op":"mcm","clk":"5353516105","pt":1646215971000,"mc":[{"id":"1.195453775","rc":[{"atl":[[2.16,43.1]],"id":38247334},{"atb":[[1.98,86.49]],"id":42688799}],"con":true,"img":false}]}
{"op":"mcm","clk":"5353516116","pt":1646215971056,"mc":[{"id":"1.195453775","rc":[{"atl":[[2.2,62.5],[2.08,91.2]],"id":38247334}],"con":true,"img":false}]}
{"op":"mcm","clk":"5353516139","pt":1646215971269,"mc":[{"id":"1.195453775","rc":[{"atl":[[2.1,18.18]],"id":38247334}],"con":true,"img":false}]}
{"op":"mcm","clk":"5353516349","pt":1646215972999,"mc":[{"id":"1.195453775","rc":[{"atb":[[1.8,21.98]],"id":42256451}],"con":true,"img":false}]}
{"op":"mcm","clk":"5353516432","pt":1646215973891,"mc":[{"id":"1.195453775","rc":[{"atb":[[1.5,0]],"id":38247334},{"atb":[[1.81,8.09]],"id":42256451}],"con":true,"img":false}]}
{"op":"mcm","clk":"5353516444","pt":1646215973995,"mc":[{"id":"1.195453775","rc":[{"atb":[[1.46,169.54]],"id":38247334},{"atb":[[1.76,0]],"id":42256451}],"con":true,"img":false}]}
{"op":"mcm","clk":"5353516452","pt":1646215974100,"mc":[{"id":"1.195453775","rc":[{"atb":[[1.77,98.88]],"id":42256451}],"con":true,"img":false}]}
{"op":"mcm","clk":"5353516616","pt":1646215975882,"mc":[{"id":"1.195453775","rc":[{"atb":[[1.8,12.58]],"id":42256451}],"con":true,"img":false}]}
{"op":"mcm","clk":"5353516670","pt":1646215976576,"mc":[{"id":"1.195453775","rc":[{"atb":[[1.99,27.23]],"id":42688799}],"con":true,"img":false}]}
{"op":"mcm","clk":"5353516678","pt":1646215976667,"mc":[{"id":"1.195453775","rc":[{"atb":[[1.99,110.31],[1.98,0]],"id":42688799}],"con":true,"img":false}]}
{"op":"mcm","clk":"5353517065","pt":1646215978873,"mc":[{"id":"1.195453775","rc":[{"atb":[[2.02,0]],"id":42688799}],"con":true,"img":false}]}
{"op":"mcm","clk":"5353517112","pt":1646215979393,"mc":[{"id":"1.195453775","rc":[{"atb":[[1.5,24.16]],"id":38247334}],"con":true,"img":false}]}
{"op":"mcm","clk":"5353517126","pt":1646215979601,"mc":[{"id":"1.195453775","rc":[{"atb":[[1.46,56.35]],"id":38247334}],"con":true,"img":false}]}
{"op":"mcm","clk":"5353517231","pt":1646215980819,"mc":[{"id":"1.195453775","rc":[{"atb":[[1.96,20.83]],"id":42688799},{"atb":[[2.96,45.45]],"id":39790958},{"atl":[[11.5,3.89],[12,20.86]],"id":41132571},{"atl":[[23,1.85],[27,0]],"id":38745817}],"con":true,"img":false}]}
{"op":"mcm","clk":"5353517242","pt":1646215980872,"mc":[{"id":"1.195453775","rc":[{"atb":[[1.99,155.72]],"id":42688799},{"atb":[[2.98,25.34]],"id":39790958}],"con":true,"img":false}]}
{"op":"mcm","clk":"5353517254","pt":1646215980985,"mc":[{"id":"1.195453775","rc":[{"atb":[[2.98,70.79],[2.96,0]],"id":39790958},{"atl":[[11.5,27.22],[12,0]],"id":41132571},{"atl":[[23,5.49]],"id":38745817}],"con":true,"img":false}]}
{"op":"mcm","clk":"5353517279","pt":1646215981195,"mc":[{"id":"1.195453775","rc":[{"atl":[[24,2.5]],"id":38745817}],"con":true,"img":false}]}
{"op":"mcm","clk":"5353517354","pt":1646215981981,"mc":[{"id":"1.195453775","rc":[{"atb":[[1.81,17.38]],"id":42256451}],"con":true,"img":false}]}
{"op":"mcm","clk":"5353517370","pt":1646215982187,"mc":[{"id":"1.195453775","rc":[{"spn":1.8,"spf":"NaN","id":38247334},{"atb":[[1.99,128.49]],"id":42688799},{"spn":4.05,"spf":"NaN","id":39790958},{"spn":9.6,"spf":"NaN","id":41632950},{"spn":7.45,"spf":"NaN","id":41132571},{"spn":2.11,"spf":"NaN","id":42256451},{"spn":16.3,"spf":"NaN","id":38745817}],"con":true,"img":false}]}
{"op":"mcm","clk":"5353517461","pt":1646215983084,"mc":[{"id":"1.195453775","rc":[{"atb":[[1.84,2.16],[1.8,10.42]],"id":42256451}],"con":true,"img":false}]}
{"op":"mcm","clk":"5353517490","pt":1646215983408,"mc":[{"id":"1.195453775","rc":[{"atb":[[1.77,26.36]],"id":42256451}],"con":true,"img":false}]}
{"op":"mcm","clk":"5353517506","pt":1646215983614,"mc":[{"id":"1.195453775","rc":[{"atb":[[3,0]],"id":39790958}],"con":true,"img":false}]}
{"op":"mcm","clk":"5353517579","pt":1646215984398,"mc":[{"id":"1.195453775","rc":[{"atb":[[1.99,45.41],[1.96,140.67]],"id":42688799}],"con":true,"img":false}]}
{"op":"mcm","clk":"5353517613","pt":1646215984769,"mc":[{"id":"1.195453775","rc":[{"atb":[[2.04,7.23]],"id":42688799},{"atb":[[1.81,8.09]],"id":42256451}],"con":true,"img":false}]}
{"op":"mcm","clk":"5353517837","pt":1646215987389,"mc":[{"id":"1.195453775","rc":[{"atl":[[2.16,127.9]],"id":38247334}],"con":true,"img":false}]}
{"op":"mcm","clk":"5353517957","pt":1646215988699,"mc":[{"id":"1.195453775","rc":[{"atb":[[2.94,50.45]],"id":39790958}],"con":true,"img":false}]}
{"op":"mcm","clk":"5353517967","pt":1646215988805,"mc":[{"id":"1.195453775","rc":[{"atb":[[2.98,25.34]],"id":39790958}],"con":true,"img":false}]}
{"op":"mcm","clk":"5353518086","pt":1646215990422,"mc":[{"id":"1.195453775","rc":[{"atb":[[1.49,117.15]],"id":38247334}],"con":true,"img":false}]}
{"op":"mcm","clk":"5353518116","pt":1646215990789,"mc":[{"id":"1.195453775","rc":[{"atb":[[2,24.96]],"id":42688799}],"con":true,"img":false}]}
{"op":"mcm","clk":"5353518123","pt":1646215990896,"mc":[{"id":"1.195453775","rc":[{"atl":[[2.08,52.96]],"id":38247334},{"atb":[[1.99,0]],"id":42688799},{"atb":[[2.98,0]],"id":39790958},{"atl":[[23,3.64]],"id":38745817}],"con":true,"img":false}]}
{"op":"mcm","clk":"5353518132","pt":1646215990998,"mc":[{"id":"1.195453775","rc":[{"atl":[[2.14,38.24]],"id":38247334},{"atb":[[1.97,45.41]],"id":42688799},{"atb":[[2.96,25.34]],"id":39790958},{"atl":[[27,1.85]],"id":38745817}],"con":true,"img":false}]}
{"op":"mcm","clk":"5353518139","pt":1646215991106,"mc":[{"id":"1.195453775","rc":[{"atb":[[1.49,101.81]],"id":38247334},{"atb":[[1.69,20.89]],"id":42256451},{"atl":[[27,12.05]],"id":38745817}],"con":true,"img":false}]}
{"op":"mcm","clk":"5353518149","pt":1646215991205,"mc":[{"id":"1.195453775","rc":[{"atl":[[28,6]],"id":38745817}],"con":true,"img":false}]}
{"op":"mcm","clk":"5353518317","pt":1646215993099,"mc":[{"id":"1.195453775","rc":[{"atb":[[2,104.64],[1.96,20.83]],"id":42688799}],"con":true,"img":false}]}
{"op":"mcm","clk":"5353518662","pt":1646215996935,"mc":[{"id":"1.195453775","rc":[{"atb":[[1.52,16.62]],"id":38247334}],"con":true,"img":false}]}
{"op":"mcm","clk":"5353518877","pt":1646215999412,"mc":[{"id":"1.195453775","rc":[{"atb":[[1.8,0]],"id":42256451}],"con":true,"img":false}]}
{"op":"mcm","clk":"5353518891","pt":1646215999521,"mc":[{"id":"1.195453775","rc":[{"atb":[[1.77,90.02]],"id":42256451}],"con":true,"img":false}]}
{"op":"mcm","clk":"5353518947","pt":1646216000096,"mc":[{"id":"1.195453775","rc":[{"atb":[[1.69,10]],"id":42256451}],"con":true,"img":false}]}
{"op":"mcm","clk":"5353519014","pt":1646216000935,"mc":[{"id":"1.195453775","rc":[{"atb":[[1.5,0]],"id":38247334}],"con":true,"img":false}]}
{"op":"mcm","clk":"5353519025","pt":1646216001045,"mc":[{"id":"1.195453775","rc":[{"atb":[[1.46,193.17],[1.49,17.01]],"id":38247334}],"con":true,"img":false}]}
{"op":"mcm","clk":"5353519240","pt":1646216003344,"mc":[{"id":"1.195453775","rc":[{"atb":[[1.52,2.16]],"id":38247334}],"con":true,"img":false}]}
{"op":"mcm","clk":"5353519261","pt":1646216003605,"mc":[{"id":"1.195453775","rc":[{"atl":[[2.14,122.88]],"id":38247334}],"con":true,"img":false}]}
{"op":"mcm","clk":"5353519270","pt":1646216003708,"mc":[{"id":"1.195453775","rc":[{"atl":[[2.16,43.1]],"id":38247334}],"con":true,"img":false}]}
{"op":"mcm","clk":"5353519309","pt":1646216004222,"mc":[{"id":"1.195453775","rc":[{"atb":[[1.47,21.6]],"id":38247334},{"atb":[[1.81,0]],"id":42256451}],"con":true,"img":false}]}
{"op":"mcm","clk":"5353519461","pt":1646216006104,"mc":[{"id":"1.195453775","rc":[{"atb":[[1.81,9.28]],"id":42256451}],"con":true,"img":false}]}
{"op":"mcm","clk":"5353519493","pt":1646216006523,"mc":[{"id":"1.195453775","rc":[{"atb":[[1.46,56.35],[1.47,81.28]],"id":38247334}],"con":true,"img":false}]}
{"op":"mcm","clk":"5353519832","pt":1646216009654,"mc":[{"id":"1.195453775","rc":[{"atb":[[1.74,17.17]],"id":42256451}],"con":true,"img":false}]}
{"op":"mcm","clk":"5353519954","pt":1646216010860,"mc":[{"id":"1.195453775","rc":[{"atl":[[11.5,23.33]],"id":41132571}],"con":true,"img":false}]}
{"op":"mcm","clk":"5353519966","pt":1646216010913,"mc":[{"id":"1.195453775","rc":[{"atl":[[11,6.39]],"id":41132571}],"con":true,"img":false}]}
{"op":"mcm","clk":"5353520348","pt":1646216014949,"mc":[{"id":"1.195453775","rc":[{"atb":[[1.5,15.03]],"id":38247334}],"con":true,"img":false}]}
{"op":"mcm","clk":"5353520420","pt":1646216015738,"mc":[{"id":"1.195453775","rc":[{"atb":[[1.49,0]],"id":38247334}],"con":true,"img":false}]}
{"op":"mcm","clk":"5353520451","pt":1646216016043,"mc":[{"id":"1.195453775","rc":[{"atb":[[2.04,15.25]],"id":42688799},{"atb":[[3,4.16]],"id":39790958}],"con":true,"img":false}]}
{"op":"mcm","clk":"5353520459","pt":1646216016151,"mc":[{"id":"1.195453775","rc":[{"atb":[[2.94,5],[2.96,70.79]],"id":39790958}],"con":true,"img":false}]}
{"op":"mcm","clk":"5353520597","pt":1646216017664,"mc":[{"id":"1.195453775","rc":[{"atb":[[1.47,59.68]],"id":38247334}],"con":true,"img":false}]}
{"op":"mcm","clk":"5353520920","pt":1646216020863,"mc":[{"id":"1.195453775","rc":[{"atb":[[1.97,0]],"id":42688799},{"atl":[[27,10.2]],"id":38745817}],"con":true,"img":false}]}
{"op":"mcm","clk":"5353520929","pt":1646216020967,"mc":[{"id":"1.195453775","rc":[{"atb":[[2.02,45.41]],"id":42688799},{"atl":[[26,1.85]],"id":38745817}],"con":true,"img":false}]}
{"op":"mcm","clk":"5353520942","pt":1646216021068,"mc":[{"id":"1.195453775","rc":[{"atb":[[2.02,155.76]],"id":42688799}],"con":true,"img":false}]}
{"op":"mcm","clk":"5353520953","pt":1646216021171,"mc":[{"id":"1.195453775","rc":[{"atb":[[2,24.96]],"id":42688799},{"atl":[[26,13.27],[27,0]],"id":38745817}],"con":true,"img":false}]}
{"op":"mcm","clk":"5353521087","pt":1646216022740,"mc":[{"id":"1.195453775","rc":[{"atb":[[1.51,12.04]],"id":38247334}],"con":true,"img":false}]}
{"op":"mcm","clk":"5353521110","pt":1646216022951,"mc":[{"id":"1.195453775","rc":[{"atb":[[1.47,0]],"id":38247334}],"con":true,"img":false}]}
{"op":"mcm","clk":"5353521213","pt":1646216024046,"mc":[{"id":"1.195453775","rc":[{"atb":[[1.5,0]],"id":38247334},{"atb":[[2.04,8.01]],"id":42688799}],"con":true,"img":false}]}
{"op":"mcm","clk":"5353521221","pt":1646216024148,"mc":[{"id":"1.195453775","rc":[{"atb":[[1.46,163.06]],"id":38247334}],"con":true,"img":false}]}
{"op":"mcm","clk":"5353521322","pt":1646216025447,"mc":[{"id":"1.195453775","rc":[{"atb":[[2,0]],"id":42688799}],"con":true,"img":false}]}
{"op":"mcm","clk":"5353521646","pt":1646216029567,"mc":[{"id":"1.195453775","rc":[{"atb":[[1.81,19.58]],"id":42256451}],"con":true,"img":false}]}
{"op":"mcm","clk":"5353521684","pt":1646216029981,"mc":[{"id":"1.195453775","rc":[{"atb":[[1.49,15.34]],"id":38247334},{"atb":[[2.06,28.11]],"id":42688799}],"con":true,"img":false}]}
{"op":"mcm","clk":"5353522077","pt":1646216034074,"mc":[{"id":"1.195453775","rc":[{"atb":[[1.51,0]],"id":38247334},{"atb":[[2.08,22.51]],"id":42688799}],"con":true,"img":false}]}
{"op":"mcm","clk":"5353522087","pt":1646216034177,"mc":[{"id":"1.195453775","rc":[{"atb":[[2.08,64.72]],"id":42688799}],"con":true,"img":false}]}
{"op":"mcm","clk":"5353522108","pt":1646216034384,"mc":[{"id":"1.195453775","rc":[{"atb":[[2.06,9.25]],"id":42688799}],"con":true,"img":false}]}
{"op":"mcm","clk":"5353522162","pt":1646216034968,"mc":[{"id":"1.195453775","rc":[{"atb":[[2.06,7.09],[2.14,2.16]],"id":42688799}],"con":true,"img":false}]}
{"op":"mcm","clk":"5353522206","pt":1646216035483,"mc":[{"id":"1.195453775","rc":[{"atb":[[2.08,63.05]],"id":42688799}],"con":true,"img":false}]}
{"op":"mcm","clk":"5353522224","pt":1646216035694,"mc":[{"id":"1.195453775","rc":[{"atb":[[2.16,1.66]],"id":42688799}],"con":true,"img":false}]}
{"op":"mcm","clk":"5353522258","pt":1646216036069,"mc":[{"id":"1.195453775","rc":[{"atb":[[2.06,0]],"id":42688799}],"con":true,"img":false}]}
{"op":"mcm","clk":"5353522344","pt":1646216036585,"mc":[{"id":"1.195453775","rc":[{"atb":[[2.02,45.41],[2.04,127.85]],"id":42688799}],"con":true,"img":false}]}
{"op":"mcm","clk":"5353522619","pt":1646216039626,"mc":[{"id":"1.195453775","rc":[{"atb":[[1.35,57.14],[1.4,0],[1.3,0]],"id":38247334},{"atl":[[4.3,0],[2.86,0],[2.66,0],[3.15,0],[3.65,0]],"id":38247334},{"atb":[[1.85,117.65],[1.9,138.89],[1.95,0]],"id":42688799},{"atl":[[5.6,0],[7.2,0],[4.6,0],[9.2,0],[13,0]],"id":42688799},{"atb":[[2.5,0],[2.6,0],[2.7,73.53]],"id":39790958},{"atl":[[16.5,0],[8.6,0],[11.5,19.15],[23,0],[6.6,0]],"id":39790958},{"atb":[[4.3,15.15],[3.9,0],[3.65,0]],"id":41632950},{"atl":[[32,0],[21,0],[55,0],[110,0],[15.5,0]],"id":41632950},{"atb":[[4.3,6.06],[3.9,0],[3.65,0]],"id":41132571},{"atl":[[32,0],[55,0],[15.5,0],[21,8.65],[110,0]],"id":41132571},{"atb":[[1.6,0],[1.55,0],[1.65,0]],"id":42256451},{"atl":[[4.9,0],[2.98,0],[5.9,0],[3.45,0],[3.95,0]],"id":42256451},{"atb":[[7.4,0],[8.4,0],[9.4,0]],"id":38745817},{"atl":[[210,0],[55,0],[310,0],[410,0],[110,0]],"id":38745817}],"con":true,"img":false}]}
{"op":"mcm","clk":"5353522631","pt":1646216039785,"mc":[{"id":"1.195453775","rc":[{"atb":[[1.5,12.25]],"id":38247334},{"atb":[[2.08,42.21]],"id":42688799},{"atb":[[8.6,5.73],[7.6,39.27]],"id":38745817}],"con":true,"img":false}]}
{"op":"mcm","clk":"5353522652","pt":1646216039992,"mc":[{"id":"1.195453775","rc":[{"atb":[[1.46,56.35],[1.49,65.64]],"id":38247334},{"atl":[[10.5,10.92],[11,3.89],[12.5,5],[13,0],[15,0]],"id":41132571}],"con":true,"img":false}]}
{"op":"mcm","clk":"5353522725","pt":1646216040885,"mc":[{"id":"1.195453775","rc":[{"atl":[[2.14,84.64]],"id":38247334},{"atl":[[3.2,31.91]],"id":42688799},{"atb":[[1.61,0]],"id":42256451},{"atb":[[8.6,0]],"id":38745817}],"con":true,"img":false}]}
{"op":"mcm","clk":"5353522735","pt":1646216040990,"mc":[{"id":"1.195453775","rc":[{"atl":[[2.06,38.24]],"id":38247334},{"atl":[[3.2,0],[3.4,19.81],[3.25,104.38]],"id":42688799},{"atb":[[1.57,70.03]],"id":42256451},{"atb":[[8.2,5.73]],"id":38745817}],"con":true,"img":false}]}
{"op":"mcm","clk":"5353522751","pt":1646216041199,"mc":[{"id":"1.195453775","rc":[{"atl":[[2.06,80.56],[2.1,102.82],[2.14,0]],"id":38247334},{"atl":[[3.35,167.42],[3.25,22.22]],"id":42688799}],"con":true,"img":false}]}
{"op":"mcm","clk":"5353522770","pt":1646216041409,"mc":[{"id":"1.195453775","rc":[{"atl":[[2.08,0]],"id":38247334}],"con":true,"img":false}]}
{"op":"mcm","clk":"5353522823","pt":1646216041988,"mc":[{"id":"1.195453775","rc":[{"atb":[[1.49,50.3]],"id":38247334}],"con":true,"img":false}]}
{"op":"mcm","clk":"5353522834","pt":1646216042098,"mc":[{"id":"1.195453775","rc":[{"atb":[[2.12,6.71]],"id":42688799}],"con":true,"img":false}]}
{"op":"mcm","clk":"5353522939","pt":1646216043302,"mc":[{"id":"1.195453775","rc":[{"atb":[[1.35,402.82],[1.4,151.23],[1.3,403.29]],"id":38247334},{"atl":[[2.86,0.29],[2.66,0.32],[3.15,2.02]],"id":38247334},{"spn":1.79,"spf":"NaN","id":38247334},{"atb":[[1.85,259.99],[1.95,63.67],[1.9,273.32]],"id":42688799},{"atl":[[5.6,0.11],[7.2,0.7],[4.6,0.15]],"id":42688799},{"spn":2.65,"spf":"NaN","id":42688799},{"atb":[[2.5,80.65],[2.6,75.61],[2.7,109.11]],"id":39790958},{"atl":[[8.6,0.07],[11.5,19.57],[6.6,0.09]],"id":39790958},{"atb":[[4.3,33.48],[3.9,41.71],[3.65,45.65]],"id":41632950},{"atl":[[32,0.14],[21,0.02],[15.5,0.03]],"id":41632950},{"atb":[[4.3,24.39],[3.9,41.71],[3.65,45.65]],"id":41132571},{"atl":[[32,0.14],[21,8.68],[15.5,0.03]],"id":41132571},{"atb":[[1.6,201.64],[1.55,219.97],[1.65,93.06]],"id":42256451},{"atl":[[3.45,0.22],[3.95,1.47],[2.98,0.27]],"id":42256451},{"spn":2.13,"spf":"NaN","id":42256451},{"atb":[[7.4,18.9],[8.4,16.34],[9.4,7.19]],"id":38745817},{"atl":[[210,0.02],[55,0.01],[110,0]],"id":38745817}],"con":true,"img":false}]}
{"op":"mcm","clk":"5353523066","pt":1646216044571,"mc":[{"id":"1.195453775","rc":[{"atb":[[2.04,119.84]],"id":42688799},{"atb":[[3,0]],"id":39790958}],"con":true,"img":false}]}
{"op":"mcm","clk":"5353523085","pt":1646216044780,"mc":[{"id":"1.195453775","rc":[{"atb":[[1.49,67.31]],"id":38247334},{"atb":[[2.94,50.45],[2.96,25.34]],"id":39790958}],"con":true,"img":false}]}
{"op":"mcm","clk":"5353523358","pt":1646216047695,"mc":[{"id":"1.195453775","rc":[{"atb":[[2.16,4.35]],"id":42688799}],"con":true,"img":false}]}
{"op":"mcm","clk":"5353523387","pt":1646216048066,"mc":[{"id":"1.195453775","rc":[{"atb":[[1.52,16.62]],"id":38247334}],"con":true,"img":false}]}
{"op":"mcm","clk":"5353523413","pt":1646216048379,"mc":[{"id":"1.195453775","rc":[{"atl":[[2.1,18.18],[2.16,189.66]],"id":38247334}],"con":true,"img":false}]}
{"op":"mcm","clk":"5353523528","pt":1646216049476,"mc":[{"id":"1.195453775","rc":[{"atb":[[2.16,26.05]],"id":42688799}],"con":true,"img":false}]}
{"op":"mcm","clk":"5353523546","pt":1646216049683,"mc":[{"id":"1.195453775","rc":[{"atb":[[2.08,0]],"id":42688799}],"con":true,"img":false}]}
{"op":"mcm","clk":"5353523657","pt":1646216050782,"mc":[{"id":"1.195453775","rc":[{"atl":[[2.06,42.32]],"id":38247334},{"atb":[[2.22,2.16],[2.14,0],[2.02,0]],"id":42688799},{"atl":[[25,2.72],[26,11.42]],"id":38745817}],"con":true,"img":false}]}
{"op":"mcm","clk":"5353523670","pt":1646216050883,"mc":[{"id":"1.195453775","rc":[{"atl":[[2.14,38.24]],"id":38247334},{"atb":[[2.1,45.41]],"id":42688799}],"con":true,"img":false}]}
{"op":"mcm","clk":"5353523679","pt":1646216050991,"mc":[{"id":"1.195453775","rc":[{"atl":[[25,15.17]],"id":38745817}],"con":true,"img":false}]}
{"op":"mcm","clk":"5353523690","pt":1646216051091,"mc":[{"id":"1.195453775","rc":[{"atl":[[2.06,0]],"id":38247334},{"atb":[[2.12,0]],"id":42688799},{"atl":[[26,0]],"id":38745817}],"con":true,"img":false}]}
{"op":"mcm","clk":"5353523715","pt":1646216051297,"mc":[{"id":"1.195453775","rc":[{"atl":[[2.14,64.35]],"id":38247334}],"con":true,"img":false}]}
{"op":"mcm","clk":"5353523763","pt":1646216051819,"mc":[{"id":"1.195453775","rc":[{"atb":[[2.04,0],[2.1,126.73]],"id":42688799}],"con":true,"img":false}]}
{"op":"mcm","clk":"5353523841","pt":1646216052502,"mc":[{"id":"1.195453775","rc":[{"atb":[[1.5,0]],"id":38247334}],"con":true,"img":false}]}
{"op":"mcm","clk":"5353523866","pt":1646216052707,"mc":[{"id":"1.195453775","rc":[{"atb":[[1.46,237.41],[1.49,17.01]],"id":38247334}],"con":true,"img":false}]}
{"op":"mcm","clk":"5353524003","pt":1646216054109,"mc":[{"id":"1.195453775","rc":[{"atb":[[1.52,2.16]],"id":38247334}],"con":true,"img":false}]}
{"op":"mcm","clk":"5353524073","pt":1646216054793,"mc":[{"id":"1.195453775","rc":[{"atl":[[2.12,17.86],[2.1,0]],"id":38247334},{"atl":[[13.5,1.6],[14,6.15]],"id":41632950},{"atb":[[1.73,0],[1.78,2.5],[1.69,0],[1.74,22.17],[1.77,87.52]],"id":42256451},{"atl":[[2.42,2],[2.44,13.89]],"id":42256451}],"con":true,"img":false}]}
{"op":"mcm","clk":"5353524082","pt":1646216054893,"mc":[{"id":"1.195453775","rc":[{"atb":[[2.16,23.36]],"id":42688799},{"atl":[[13.5,8]],"id":41632950},{"atb":[[1.78,27.08]],"id":42256451},{"atl":[[2.46,58.83]],"id":42256451}],"con":true,"img":false}]}
{"op":"mcm","clk":"5353524093","pt":1646216054996,"mc":[{"id":"1.195453775","rc":[{"atb":[[1.77,23.86]],"id":42256451},{"atl":[[2.48,0]],"id":42256451},{"atb":[[8.4,34.13]],"id":38745817}],"con":true,"img":false}]}
{"op":"mcm","clk":"5353524102","pt":1646216055103,"mc":[{"id":"1.195453775","rc":[{"atl":[[14,0]],"id":41632950},{"atb":[[7.6,14.7]],"id":38745817}],"con":true,"img":false}]}
{"op":"mcm","clk":"5353524316","pt":1646216058000,"mc":[{"id":"1.195453775","rc":[{"atb":[[1.5,13.42]],"id":38247334},{"atb":[[1.74,5]],"id":42256451}],"con":true,"img":false}]}
{"op":"mcm","clk":"5353524550","pt":1646216061109,"mc":[{"id":"1.195453775","rc":[{"atb":[[1.97,36.67]],"id":42688799}],"con":true,"img":false}]}
{"op":"mcm","clk":"5353524777","pt":1646216064012,"mc":[{"id":"1.195453775","rc":[{"atb":[[1.82,15.22]],"id":42256451}],"con":true,"img":false}]}
{"op":"mcm","clk":"5353525232","pt":1646216065534,"mc":[{"id":"1.195453775","rc":[{"atl":[[2.48,33.78]],"id":42256451}],"con":true,"img":false}]}
{"op":"mcm","clk":"5353525730","pt":1646216067905,"mc":[{"id":"1.195453775","rc":[{"atb":[[1.64,73.76]],"id":42688799}],"con":true,"img":false}]}
{"op":"mcm","clk":"5353525751","pt":1646216068022,"mc":[{"id":"1.195453775","rc":[{"atb":[[1.56,0],[2.1,81.32]],"id":42688799},{"atl":[[3.4,0]],"id":42688799},{"atb":[[1.57,0]],"id":42256451},{"atb":[[8.2,0]],"id":38745817}],"con":true,"img":false}]}
{"op":"mcm","clk":"5353525772","pt":1646216068126,"mc":[{"id":"1.195453775","rc":[{"atb":[[2.12,45.41]],"id":42688799},{"atl":[[3.3,19.81]],"id":42688799},{"atb":[[1.61,70.03]],"id":42256451},{"atb":[[8.6,5.73]],"id":38745817}],"con":true,"img":false}]}
{"op":"mcm","clk":"5353526240","pt":1646216070402,"mc":[{"id":"1.195453775","rc":[{"atl":[[2.12,79.52]],"id":38247334}],"con":true,"img":false}]}
{"op":"mcm","clk":"5353526412","pt":1646216071426,"mc":[{"id":"1.195453775","rc":[{"atb":[[1.49,32.35]],"id":38247334}],"con":true,"img":false}]}
{"op":"mcm","clk":"5353526435","pt":1646216071448,"mc":[{"id":"1.195453775","rc":[{"atb":[[1.97,0]],"id":42688799},{"atb":[[1.81,10.29]],"id":42256451}],"con":true,"img":false}]}
{"op":"mcm","clk":"5353526573","pt":1646216072012,"mc":[{"id":"1.195453775","rc":[{"atb":[[2.16,21.7]],"id":42688799}],"con":true,"img":false}]}
{"op":"mcm","clk":"5353526605","pt":1646216072223,"mc":[{"id":"1.195453775","rc":[{"atb":[[2.24,1.66]],"id":42688799}],"con":true,"img":false}]}
{"op":"mcm","clk":"5353526738","pt":1646216073327,"mc":[{"id":"1.195453775","rc":[{"atb":[[1.46,56.35]],"id":38247334}],"con":true,"img":false}]}
{"op":"mcm","clk":"5353526794","pt":1646216073699,"mc":[{"id":"1.195453775","rc":[{"atb":[[1.49,84.66]],"id":38247334}],"con":true,"img":false}]}
{"op":"mcm","clk":"5353526889","pt":1646216074441,"mc":[{"id":"1.195453775","rc":[{"atb":[[2.18,17.87]],"id":42688799}],"con":true,"img":false}]}
{"op":"mcm","clk":"5353526995","pt":1646216075216,"mc":[{"id":"1.195453775","rc":[{"atb":[[1.49,69.32]],"id":38247334}],"con":true,"img":false}]}
{"op":"mcm","clk":"5353527125","pt":1646216076124,"mc":[{"id":"1.195453775","rc":[{"atl":[[2.54,0],[2.5,0],[2.52,49.34],[2.46,24.58]],"id":42256451}],"con":true,"img":false}]}
{"op":"mcm","clk":"5353527172","pt":1646216076407,"mc":[{"id":"1.195453775","rc":[{"atl":[[2.14,38.24]],"id":38247334}],"con":true,"img":false}]}
{"op":"mcm","clk":"5353527424","pt":1646216078056,"mc":[{"id":"1.195453775","rc":[{"atl":[[2.12,61.66],[2.1,18.18]],"id":38247334},{"atb":[[1.85,142.34],[1.9,384.43],[2.16,28.18]],"id":42688799},{"atl":[[13.5,6.4],[14,1.54]],"id":41632950},{"atb":[[1.69,10.89]],"id":42256451},{"atl":[[22,2.5],[24,0],[26,5],[28,1]],"id":38745817}],"con":true,"img":false}]}
{"op":"mcm","clk":"5353527479","pt":1646216078230,"mc":[{"id":"1.195453775","rc":[{"atl":[[2.36,73.53]],"id":38247334}],"con":true,"img":false}]}
{"op":"mcm","clk":"5353527513","pt":1646216078335,"mc":[{"id":"1.195453775","rc":[{"atl":[[2.44,0]],"id":38247334},{"atl":[[22,6.31]],"id":38745817}],"con":true,"img":false}]}
{"op":"mcm","clk":"5353527583","pt":1646216078551,"mc":[{"id":"1.195453775","rc":[{"atl":[[23,0]],"id":38745817}],"con":true,"img":false}]}
{"op":"mcm","clk":"5353527652","pt":1646216078719,"mc":[{"id":"1.195453775","rc":[{"atl":[[40,2.56]],"id":38745817}],"con":true,"img":false}]}
{"op":"mcm","clk":"5353527669","pt":1646216078826,"mc":[{"id":"1.195453775","rc":[{"atl":[[46,0]],"id":38745817}],"con":true,"img":false}]}
{"op":"mcm","clk":"5353527729","pt":1646216079159,"mc":[{"id":"1.195453775","rc":[{"atb":[[2.18,0]],"id":42688799}],"con":true,"img":false}]}
{"op":"mcm","clk":"5353527773","pt":1646216079536,"mc":[{"id":"1.195453775","rc":[{"atb":[[1.33,0],[1.35,345.68],[1.27,74.07],[1.29,0],[1.31,0],[1.17,276.95]],"id":38247334},{"atb":[[3.05,42.55],[2.88,0]],"id":39790958},{"atl":[[18,5.88],[19,0],[21,9.68]],"id":41132571},{"atb":[[1.45,44.44],[1.35,161.29],[1.36,0]],"id":42256451},{"atb":[[8,2.86],[7.2,0]],"id":38745817}],"con":true,"img":false}]}
{"op":"mcm","clk":"5353527783","pt":1646216079640,"mc":[{"id":"1.195453775","rc":[{"atb":[[1.26,0]],"id":42256451}],"con":true,"img":false}]}
{"op":"mcm","clk":"5353527899","pt":1646216080268,"mc":[{"id":"1.195453775","rc":[{"atb":[[1.92,21.74],[1.96,0],[1.94,0]],"id":42688799},{"atl":[[2.92,2]],"id":42688799},{"atb":[[3.6,3]],"id":39790958},{"atl":[[5,8.25],[5.2,4.76]],"id":39790958},{"atl":[[20,0]],"id":41132571}],"con":true,"img":false}]}
{"op":"mcm","clk":"5353527933","pt":1646216080436,"mc":[{"id":"1.195453775","rc":[{"atl":[[3.35,124.87],[3.25,66.66]],"id":42688799}],"con":true,"img":false}]}
{"op":"mcm","clk":"5353527964","pt":1646216080714,"mc":[{"id":"1.195453775","rc":[{"atb":[[1.96,20.83]],"id":42688799},{"atl":[[2.92,0]],"id":42688799},{"atb":[[3.6,0]],"id":39790958},{"atl":[[5,13.25]],"id":39790958}],"con":true,"img":false}]}
{"op":"mcm","clk":"5353527995","pt":1646216080849,"mc":[{"id":"1.195453775","rc":[{"atb":[[2.12,120.98],[2.1,0]],"id":42688799},{"atl":[[3.35,31.91],[3.3,95.38]],"id":42688799},{"atb":[[1.81,46.58]],"id":42256451},{"atb":[[8.6,23.81],[8.4,16.34]],"id":38745817},{"atl":[[25,2.72],[26,18.06]],"id":38745817}],"con":true,"img":false}]}
{"op":"mcm","clk":"5353528014","pt":1646216080920,"mc":[{"id":"1.195453775","rc":[{"atl":[[2.14,122.88],[2.16,43.1]],"id":38247334},{"atb":[[3.6,9.76],[2.94,5],[2.96,63.29]],"id":39790958},{"atl":[[5,5]],"id":39790958},{"atb":[[1.78,2.5]],"id":42256451}],"con":true,"img":false}]}
{"op":"mcm","clk":"5353528083","pt":1646216081200,"mc":[{"id":"1.195453775","rc":[{"atl":[[5.2,15.83]],"id":39790958}],"con":true,"img":false}]}
{"op":"mcm","clk":"5353528091","pt":1646216081313,"mc":[{"id":"1.195453775","rc":[{"atb":[[1.52,16.62]],"id":38247334},{"atb":[[3.6,0],[3.05,27.85]],"id":39790958}],"con":true,"img":false}]}
{"op":"mcm","clk":"5353528128","pt":1646216081514,"mc":[{"id":"1.195453775","rc":[{"atb":[[3.05,47.04]],"id":39790958}],"con":true,"img":false}]}
{"op":"mcm","clk":"5353528169","pt":1646216081815,"mc":[{"id":"1.195453775","rc":[{"atb":[[1.45,0],[1.41,48.78]],"id":42256451},{"atl":[[2.1,3]],"id":42256451}],"con":true,"img":false}]}
{"op":"mcm","clk":"5353528207","pt":1646216082001,"mc":[{"id":"1.195453775","rc":[{"atl":[[2.46,0],[2.44,39.23]],"id":42256451}],"con":true,"img":false}]}
{"op":"mcm","clk":"5353528266","pt":1646216082391,"mc":[{"id":"1.195453775","rc":[{"atb":[[1.5,0]],"id":38247334}],"con":true,"img":false}]}
{"op":"mcm","clk":"5353528284","pt":1646216082439,"mc":[{"id":"1.195453775","rc":[{"atb":[[2.18,3.83]],"id":42688799}],"con":true,"img":false}]}
{"op":"mcm","clk":"5353528344","pt":1646216082589,"mc":[{"id":"1.195453775","rc":[{"atb":[[1.46,233.37],[1.49,17.01]],"id":38247334}],"con":true,"img":false}]}
{"op":"mcm","clk":"5353528375","pt":1646216082802,"mc":[{"id":"1.195453775","rc":[{"atl":[[2.92,4]],"id":42688799},{"atb":[[3.6,3]],"id":39790958}],"con":true,"img":false}]}
{"op":"mcm","clk":"5353528393","pt":1646216082907,"mc":[{"id":"1.195453775","rc":[{"atb":[[1.96,0]],"id":42688799},{"atl":[[5,0]],"id":39790958},{"atb":[[1.45,44.44],[1.41,0]],"id":42256451},{"atl":[[2.1,0]],"id":42256451}],"con":true,"img":false}]}
{"op":"mcm","clk":"5353528433","pt":1646216083088,"mc":[{"id":"1.195453775","rc":[{"atl":[[5.5,59.45]],"id":39790958}],"con":true,"img":false}]}
{"op":"mcm","clk":"5353528657","pt":1646216083832,"mc":[{"id":"1.195453775","rc":[{"atb":[[1.96,20.83]],"id":42688799},{"atl":[[2.92,0]],"id":42688799},{"atb":[[3.65,4]],"id":39790958}],"con":true,"img":false}]}
{"op":"mcm","clk":"5353528721","pt":1646216084096,"mc":[{"id":"1.195453775","rc":[{"atb":[[1.52,2.16]],"id":38247334},{"atb":[[1.69,0]],"id":42256451}],"con":true,"img":false}]}
{"op":"mcm","clk":"5353528860","pt":1646216084620,"mc":[{"id":"1.195453775","rc":[{"atb":[[1.82,0]],"id":42256451}],"con":true,"img":false}]}
{"op":"mcm","clk":"5353529012","pt":1646216085036,"mc":[{"id":"1.195453775","rc":[{"atl":[[2.1,78.06]],"id":38247334}],"con":true,"img":false}]}
{"op":"mcm","clk":"5353529086","pt":1646216085244,"mc":[{"id":"1.195453775","rc":[{"atl":[[2.12,0]],"id":38247334}],"con":true,"img":false}]}
{"op":"mcm","clk":"5353529254","pt":1646216085737,"mc":[{"id":"1.195453775","rc":[{"atl":[[3.15,9.3]],"id":42688799},{"atb":[[3.7,2]],"id":39790958}],"con":true,"img":false}]}
{"op":"mcm","clk":"5353529637","pt":1646216087192,"mc":[{"id":"1.195453775","rc":[{"atb":[[3.1,5.24]],"id":39790958}],"con":true,"img":false}]}
{"op":"mcm","clk":"5353529696","pt":1646216087498,"mc":[{"id":"1.195453775","rc":[{"atb":[[1.5,13.42]],"id":38247334}],"con":true,"img":false}]}
{"op":"mcm","clk":"5353529789","pt":1646216087921,"mc":[{"id":"1.195453775","rc":[{"atl":[[2.14,38.24],[2.16,133.26]],"id":38247334},{"atb":[[1.78,56.92],[1.81,10.29]],"id":42256451}],"con":true,"img":false}]}
{"op":"mcm","clk":"5353529908","pt":1646216088200,"mc":[{"id":"1.195453775","rc":[{"atb":[[1.46,56.35],[1.49,99.9]],"id":38247334}],"con":true,"img":false}]}
{"op":"mcm","clk":"5353530089","pt":1646216088853,"mc":[{"id":"1.195453775","rc":[{"atl":[[2.44,13.89],[2.48,99.9]],"id":42256451}],"con":true,"img":false}]}
{"op":"mcm","clk":"5353530379","pt":1646216089903,"mc":[{"id":"1.195453775","rc":[{"atb":[[1.25,200]],"id":38247334},{"atl":[[3.3,19.81]],"id":42688799},{"atb":[[3.75,2],[2.96,25.34]],"id":39790958},{"atl":[[23,2.27]],"id":41132571},{"atb":[[7.6,22.28]],"id":38745817}],"con":true,"img":false}]}
{"op":"mcm","clk":"5353530461","pt":1646216090223,"mc":[{"id":"1.195453775","rc":[{"atb":[[1.82,34.12]],"id":42256451}],"con":true,"img":false}]}
{"op":"mcm","clk":"5353530600","pt":1646216090714,"mc":[{"id":"1.195453775","rc":[{"atb":[[6.2,0],[6.6,0],[5.9,0]],"id":38745817}],"con":true,"img":false}]}
{"op":"mcm","clk":"5353530627","pt":1646216090814,"mc":[{"id":"1.195453775","rc":[{"atl":[[2.14,0]],"id":38247334},{"atl":[[3.3,0]],"id":42688799}],"con":true,"img":false}]}
{"op":"mcm","clk":"5353530656","pt":1646216090925,"mc":[{"id":"1.195453775","rc":[{"atl":[[2.1,116.3]],"id":38247334},{"atl":[[3.4,19.81]],"id":42688799},{"atl":[[5.4,0]],"id":39790958}],"con":true,"img":false}]}
{"op":"mcm","clk":"5353530679","pt":1646216090982,"mc":[{"id":"1.195453775","rc":[{"atl":[[3.35,74.46],[3.25,22.22]],"id":42688799},{"atl":[[5.4,11.36]],"id":39790958}],"con":true,"img":false}]}
{"op":"mcm","clk":"5353530705","pt":1646216091095,"mc":[{"id":"1.195453775","rc":[{"atl":[[5.6,56.91],[5.5,10.13],[6.6,2.59]],"id":39790958}],"con":true,"img":false}]}
{"op":"mcm","clk":"5353531273","pt":1646216093108,"mc":[{"id":"1.195453775","rc":[{"atb":[[3.55,4],[3.75,0]],"id":39790958},{"atb":[[1.43,116.28]],"id":42256451},{"atl":[[2.56,80.13]],"id":42256451}],"con":true,"img":false}]}
{"op":"mcm","clk":"5353531504","pt":1646216093893,"mc":[{"id":"1.195453775","rc":[{"atb":[[3.1,3.57]],"id":39790958}],"con":true,"img":false}]}
{"op":"mcm","clk":"5353531557","pt":1646216094102,"mc":[{"id":"1.195453775","rc":[{"atb":[[1.94,53.19]],"id":42688799}],"con":true,"img":false}]}
{"op":"mcm","clk":"5353531587","pt":1646216094204,"mc":[{"id":"1.195453775","rc":[{"atb":[[1.29,0]],"id":42256451}],"con":true,"img":false}]}
{"op":"mcm","clk":"5353531688","pt":1646216094629,"mc":[{"id":"1.195453775","rc":[{"atl":[[2.2,221.42],[2.16,43.1]],"id":38247334}],"con":true,"img":false}]}
{"op":"mcm","clk":"5353531847","pt":1646216095217,"mc":[{"id":"1.195453775","rc":[{"atb":[[1.5,0]],"id":38247334}],"con":true,"img":false}]}
{"op":"mcm","clk":"5353531879","pt":1646216095324,"mc":[{"id":"1.195453775","rc":[{"atb":[[2.12,45.41],[2.16,75.46]],"id":42688799},{"atb":[[1.78,2.5],[1.81,46.58]],"id":42256451}],"con":true,"img":false}]}
{"op":"mcm","clk":"5353531903","pt":1646216095429,"mc":[{"id":"1.195453775","rc":[{"atb":[[1.46,290.73],[1.49,17.01]],"id":38247334}],"con":true,"img":false}]}
{"op":"mcm","clk":"5353531968","pt":1646216095699,"mc":[{"id":"1.195453775","rc":[{"atb":[[3.6,24.21],[3.55,0],[3.75,4]],"id":39790958}],"con":true,"img":false}]}
{"op":"mcm","clk":"5353532017","pt":1646216095912,"mc":[{"id":"1.195453775","rc":[{"atb":[[3.6,3]],"id":39790958}],"con":true,"img":false}]}
{"op":"mcm","clk":"5353532048","pt":1646216096022,"mc":[{"id":"1.195453775","rc":[{"atb":[[2.16,68.98]],"id":42688799}],"con":true,"img":false}]}
{"op":"mcm","clk":"5353532118","pt":1646216096197,"mc":[{"id":"1.195453775","rc":[{"atl":[[3.35,31.91],[3.5,40]],"id":42688799}],"con":true,"img":false}]}
{"op":"mcm","clk":"5353532172","pt":1646216096395,"mc":[{"id":"1.195453775","rc":[{"atl":[[3.35,79.19]],"id":42688799}],"con":true,"img":false}]}
{"op":"mcm","clk":"5353532371","pt":1646216097293,"mc":[{"id":"1.195453775","rc":[{"atl":[[3.35,31.91]],"id":42688799}],"con":true,"img":false}]}
{"op":"mcm","clk":"5353532392","pt":1646216097404,"mc":[{"id":"1.195453775","rc":[{"atl":[[5.6,27.17],[5.5,31.34]],"id":39790958}],"con":true,"img":false}]}
{"op":"mcm","clk":"5353532424","pt":1646216097602,"mc":[{"id":"1.195453775","rc":[{"atb":[[1.81,36.29]],"id":42256451}],"con":true,"img":false}]}
{"op":"mcm","clk":"5353532542","pt":1646216098345,"mc":[{"id":"1.195453775","rc":[{"atb":[[1.96,0],[1.94,0]],"id":42688799},{"atl":[[3.25,25.22]],"id":42688799}],"con":true,"img":false}]}
{"op":"mcm","clk":"5353532571","pt":1646216098413,"mc":[{"id":"1.195453775","rc":[{"atl":[[3.15,19.15]],"id":42688799}],"con":true,"img":false}]}
{"op":"mcm","clk":"5353532687","pt":1646216099019,"mc":[{"id":"1.195453775","rc":[{"atl":[[3.35,74.46],[3.5,0]],"id":42688799}],"con":true,"img":false}]}
{"op":"mcm","clk":"5353532739","pt":1646216099333,"mc":[{"id":"1.195453775","rc":[{"atl":[[3.25,22.22],[2.96,4]],"id":42688799}],"con":true,"img":false}]}
{"op":"mcm","clk":"5353532924","pt":1646216100090,"mc":[{"id":"1.195453775","rc":[{"atb":[[1.23,250]],"id":38247334},{"atl":[[25,3.12]],"id":41132571},{"atb":[[7.2,12.1]],"id":38745817}],"con":true,"img":false}]}
{"op":"mcm","clk":"5353532962","pt":1646216100296,"mc":[{"id":"1.195453775","rc":[{"atb":[[1.5,13.42]],"id":38247334}],"con":true,"img":false}]}
{"op":"mcm","clk":"5353532979","pt":1646216100400,"mc":[{"id":"1.195453775","rc":[{"atb":[[1.46,56.35],[1.49,107.17]],"id":38247334}],"con":true,"img":false}]}
{"op":"mcm","clk":"5353533057","pt":1646216100828,"mc":[{"id":"1.195453775","rc":[{"atb":[[2.12,0]],"id":42688799},{"atb":[[2.96,0]],"id":39790958}],"con":true,"img":false}]}
{"op":"mcm","clk":"5353533087","pt":1646216100940,"mc":[{"id":"1.195453775","rc":[{"atb":[[2.18,49.24]],"id":42688799},{"atb":[[3.1,28.92]],"id":39790958}],"con":true,"img":false}]}
{"op":"mcm","clk":"5353533147","pt":1646216101115,"mc":[{"id":"1.195453775","rc":[{"atl":[[5.6,16.3]],"id":39790958}],"con":true,"img":false}]}
{"op":"mcm","clk":"5353533176","pt":1646216101214,"mc":[{"id":"1.195453775","rc":[{"atl":[[3.2,4],[3.15,9.3],[2.96,0]],"id":42688799}],"con":true,"img":false}]}
{"op":"mcm","clk":"5353533398","pt":1646216102002,"mc":[{"id":"1.195453775","rc":[{"atb":[[1.96,20.83]],"id":42688799},{"atl":[[3.2,0]],"id":42688799}],"con":true,"img":false}]}
{"op":"mcm","clk":"5353533431","pt":1646216102211,"mc":[{"id":"1.195453775","rc":[{"atb":[[3.1,25.34]],"id":39790958}],"con":true,"img":false}]}
{"op":"mcm","clk":"5353533605","pt":1646216103226,"mc":[{"id":"1.195453775","rc":[{"atb":[[1.41,182.93]],"id":42256451}],"con":true,"img":false}]}
{"op":"mcm","clk":"5353533833","pt":1646216104032,"mc":[{"id":"1.195453775","rc":[{"spn":1.81,"spf":"NaN","id":38247334},{"spn":2.69,"spf":"NaN","id":42688799},{"spn":4.47,"spf":"NaN","id":39790958},{"spn":9.35,"spf":"NaN","id":41632950},{"atb":[[1.31,0]],"id":42256451},{"spn":15.8,"spf":"NaN","id":38745817}],"con":true,"img":false}]}
{"op":"mcm","clk":"5353534094","pt":1646216105019,"mc":[{"id":"1.195453775","rc":[{"atl":[[3.15,32.94]],"id":42688799},{"atb":[[1.69,10.89]],"id":42256451}],"con":true,"img":false}]}
{"op":"mcm","clk":"5353534292","pt":1646216105672,"mc":[{"id":"1.195453775","rc":[{"atl":[[2.1,78.06]],"id":38247334},{"atl":[[5.5,21.21]],"id":39790958}],"con":true,"img":false}]}
{"op":"mcm","clk":"5353534449","pt":1646216105967,"mc":[{"id":"1.195453775","rc":[{"atl":[[2.08,38.24]],"id":38247334},{"atl":[[6.4,10.13]],"id":39790958}],"con":true,"img":false}]}
{"op":"mcm","clk":"5353534541","pt":1646216106235,"mc":[{"id":"1.195453775","rc":[{"atl":[[2.2,62.5],[2.16,165.12],[2.08,99.25]],"id":38247334}],"con":true,"img":false}]}
{"op":"mcm","clk":"5353534616","pt":1646216106483,"mc":[{"id":"1.195453775","rc":[{"atl":[[2.1,18.18]],"id":38247334}],"con":true,"img":false}]}
{"op":"mcm","clk":"5353535067","pt":1646216107650,"mc":[{"id":"1.195453775","rc":[{"atb":[[1.96,0]],"id":42688799},{"atl":[[2.94,4]],"id":42688799}],"con":true,"img":false}]}
{"op":"mcm","clk":"5353535166","pt":1646216107866,"mc":[{"id":"1.195453775","rc":[{"atl":[[3.35,31.91],[3.15,65.88]],"id":42688799}],"con":true,"img":false}]}
{"op":"mcm","clk":"5353535253","pt":1646216108045,"mc":[{"id":"1.195453775","rc":[{"atb":[[1.52,16.62]],"id":38247334},{"atb":[[2.24,7.72]],"id":42688799},{"atl":[[2.92,2]],"id":42688799},{"atb":[[3.15,3.49]],"id":39790958}],"con":true,"img":false}]}
{"op":"mcm","clk":"5353535310","pt":1646216108156,"mc":[{"id":"1.195453775","rc":[{"atl":[[2.94,0]],"id":42688799}],"con":true,"img":false}]}
{"op":"mcm","clk":"5353535828","pt":1646216109465,"mc":[{"id":"1.195453775","rc":[{"atb":[[2.18,94.16],[2.16,21.7]],"id":42688799}],"con":true,"img":false}]}
{"op":"mcm","clk":"5353535904","pt":1646216109629,"mc":[{"id":"1.195453775","rc":[{"atb":[[1.96,20.83]],"id":42688799},{"atl":[[2.92,0],[3.15,42.24]],"id":42688799}],"con":true,"img":false}]}
{"op":"mcm","clk":"5353535974","pt":1646216109847,"mc":[{"id":"1.195453775","rc":[{"atl":[[3.15,9.3],[3.25,66.66]],"id":42688799}],"con":true,"img":false}]}
{"op":"mcm","clk":"5353536068","pt":1646216110116,"mc":[{"id":"1.195453775","rc":[{"atb":[[1.21,250]],"id":38247334},{"atl":[[27,4.81]],"id":41132571},{"atb":[[6.8,21.55]],"id":38745817}],"con":true,"img":false}]}
{"op":"mcm","clk":"5353536140","pt":1646216110432,"mc":[{"id":"1.195453775","rc":[{"atl":[[3.35,93.73]],"id":42688799}],"con":true,"img":false}]}
{"op":"mcm","clk":"5353536161","pt":1646216110542,"mc":[{"id":"1.195453775","rc":[{"atb":[[1.5,0]],"id":38247334}],"con":true,"img":false}]}
{"op":"mcm","clk":"5353536207","pt":1646216110761,"mc":[{"id":"1.195453775","rc":[{"atb":[[1.46,289.77],[1.49,17.01]],"id":38247334}],"con":true,"img":false}]}
{"op":"mcm","clk":"5353536314","pt":1646216111136,"mc":[{"id":"1.195453775","rc":[{"atl":[[5.8,26.04]],"id":39790958}],"con":true,"img":false}]}
{"op":"mcm","clk":"5353536820","pt":1646216113192,"mc":[{"id":"1.195453775","rc":[{"atl":[[3.35,31.91]],"id":42688799},{"atl":[[22,0]],"id":41132571}],"con":true,"img":false}]}
{"op":"mcm","clk":"5353536852","pt":1646216113268,"mc":[{"id":"1.195453775","rc":[{"atb":[[1.39,250]],"id":42256451}],"con":true,"img":false}]}
{"op":"mcm","clk":"5353537293","pt":1646216115017,"mc":[{"id":"1.195453775","rc":[{"atl":[[3.35,74.46],[3.25,22.22]],"id":42688799}],"con":true,"img":false}]}
{"op":"mcm","clk":"5353537333","pt":1646216115126,"mc":[{"id":"1.195453775","rc":[{"atb":[[1.52,2.16]],"id":38247334}],"con":true,"img":false}]}
{"op":"mcm","clk":"5353537419","pt":1646216115544,"mc":[{"id":"1.195453775","rc":[{"atb":[[1.26,92.68],[1.22,0],[1.47,21.6]],"id":38247334},{"atl":[[21,1.02]],"id":41132571}],"con":true,"img":false}]}
{"op":"mcm","clk":"5353537446","pt":1646216115608,"mc":[{"id":"1.195453775","rc":[{"atl":[[24,8.65]],"id":41132571}],"con":true,"img":false}]}
{"op":"mcm","clk":"5353537468","pt":1646216115713,"mc":[{"id":"1.195453775","rc":[{"atb":[[1.46,56.35],[1.47,81.28]],"id":38247334}],"con":true,"img":false}]}
{"op":"mcm","clk":"5353537676","pt":1646216116647,"mc":[{"id":"1.195453775","rc":[{"atb":[[3.1,29.31]],"id":39790958}],"con":true,"img":false}]}
{"op":"mcm","clk":"5353537724","pt":1646216116816,"mc":[{"id":"1.195453775","rc":[{"atb":[[1.69,22.97]],"id":42256451}],"con":true,"img":false}]}
{"op":"mcm","clk":"5353537909","pt":1646216117652,"mc":[{"id":"1.195453775","rc":[{"atb":[[1.33,0]],"id":42256451}],"con":true,"img":false}]}
{"op":"mcm","clk":"5353538050","pt":1646216118129,"mc":[{"id":"1.195453775","rc":[{"atb":[[3.55,3],[3.75,0]],"id":39790958}],"con":true,"img":false}]}
{"op":"mcm","clk":"5353538347","pt":1646216119455,"mc":[{"id":"1.195453775","rc":[{"atb":[[1.94,53.19]],"id":42688799}],"con":true,"img":false}]}
{"op":"mcm","clk":"5353539038","pt":1646216123143,"mc":[{"id":"1.195453775","rc":[{"atb":[[1.5,15.03]],"id":38247334}],"con":true,"img":false}]}
{"op":"mcm","clk":"5353539338","pt":1646216124343,"mc":[{"id":"1.195453775","rc":[{"atb":[[1.36,0]],"id":38247334},{"atb":[[4.8,16.89]],"id":41632950},{"atb":[[1.61,0]],"id":42256451},{"atb":[[8.6,18.08]],"id":38745817}],"con":true,"img":false}]}
{"op":"mcm","clk":"5353539361","pt":1646216124450,"mc":[{"id":"1.195453775","rc":[{"atb":[[1.48,82.9],[1.49,69.79],[1.47,21.6]],"id":38247334},{"atb":[[5.3,13.21]],"id":41632950},{"atb":[[1.83,70.03],[1.46,67.58],[1.4,0]],"id":42256451},{"atb":[[9.6,10.39]],"id":38745817}],"con":true,"img":false}]}
{"op":"mcm","clk":"5353539408","pt":1646216124668,"mc":[{"id":"1.195453775","rc":[{"atb":[[4.8,0],[5.4,20.05],[5.1,16.18],[5.2,10.1]],"id":41632950},{"atb":[[1.46,0],[1.81,0]],"id":42256451}],"con":true,"img":false}]}
{"op":"mcm","clk":"5353539429","pt":1646216124736,"mc":[{"id":"1.195453775","rc":[{"atb":[[5.2,1.66]],"id":41632950},{"atb":[[1.44,67.58]],"id":42256451}],"con":true,"img":false}]}
{"op":"mcm","clk":"5353539617","pt":1646216125544,"mc":[{"id":"1.195453775","rc":[{"atl":[[2.08,61.01]],"id":38247334}],"con":true,"img":false}]}
{"op":"mcm","clk":"5353539653","pt":1646216125657,"mc":[{"id":"1.195453775","rc":[{"atl":[[2.06,38.24]],"id":38247334}],"con":true,"img":false}]}
{"op":"mcm","clk":"5353539755","pt":1646216126042,"mc":[{"id":"1.195453775","rc":[{"atb":[[1.5,0]],"id":38247334},{"atb":[[1.69,12.07]],"id":42256451}],"con":true,"img":false}]}
{"op":"mcm","clk":"5353539812","pt":1646216126257,"mc":[{"id":"1.195453775","rc":[{"atl":[[2.06,106.46],[2.1,167.07],[2.16,43.1]],"id":38247334}],"con":true,"img":false}]}
{"op":"mcm","clk":"5353539864","pt":1646216126432,"mc":[{"id":"1.195453775","rc":[{"atl":[[2.08,0]],"id":38247334}],"con":true,"img":false}]}
{"op":"mcm","clk":"5353539985","pt":1646216126977,"mc":[{"id":"1.195453775","rc":[{"atb":[[5.2,0]],"id":41632950}],"con":true,"img":false}]}
{"op":"mcm","clk":"5353540043","pt":1646216127143,"mc":[{"id":"1.195453775","rc":[{"atb":[[5.5,1.66]],"id":41632950}],"con":true,"img":false}]}
{"op":"mcm","clk":"5353540241","pt":1646216128063,"mc":[{"id":"1.195453775","rc":[{"atb":[[1.47,0]],"id":38247334},{"atb":[[1.82,0]],"id":42256451}],"con":true,"img":false}]}
{"op":"mcm","clk":"5353540285","pt":1646216128244,"mc":[{"id":"1.195453775","rc":[{"atl":[[3.35,31.91],[3.4,61.48]],"id":42688799},{"atb":[[1.78,27.08]],"id":42256451}],"con":true,"img":false}]}
{"op":"mcm","clk":"5353540547","pt":1646216129153,"mc":[{"id":"1.195453775","rc":[{"atb":[[1.92,81.52]],"id":42688799}],"con":true,"img":false}]}
{"op":"mcm","clk":"5353540815","pt":1646216130740,"mc":[{"id":"1.195453775","rc":[{"atb":[[1.48,311.95],[1.49,17.01]],"id":38247334}],"con":true,"img":false}]}
{"op":"mcm","clk":"5353540960","pt":1646216131739,"mc":[{"id":"1.195453775","rc":[{"atb":[[2.18,49.24],[2.16,0]],"id":42688799},{"atb":[[3.6,0],[3.55,0],[3.05,21.69],[3.2,29.32],[3.7,0],[3.65,0]],"id":39790958},{"atl":[[2.42,16.08],[2.44,0]],"id":42256451}],"con":true,"img":false}]}
{"op":"mcm","clk":"5353540991","pt":1646216131948,"mc":[{"id":"1.195453775","rc":[{"atb":[[2.24,14.44]],"id":42688799},{"atb":[[3.1,84.87],[3.15,15.01]],"id":39790958},{"atl":[[2.52,163.97],[2.48,33.78]],"id":42256451}],"con":true,"img":false}]}
{"op":"mcm","clk":"5353541019","pt":1646216132157,"mc":[{"id":"1.195453775","rc":[{"atb":[[3.05,2.49]],"id":39790958}],"con":true,"img":false}]}
{"op":"mcm","clk":"5353541031","pt":1646216132212,"mc":[{"id":"1.195453775","rc":[{"atb":[[1.49,0]],"id":38247334},{"atb":[[3.15,11.52]],"id":39790958},{"atb":[[1.87,8.63]],"id":42256451}],"con":true,"img":false}]}
{"op":"mcm","clk":"5353541047","pt":1646216132321,"mc":[{"id":"1.195453775","rc":[{"atb":[[1.78,2.5]],"id":42256451}],"con":true,"img":false}]}
{"op":"mcm","clk":"5353541078","pt":1646216132530,"mc":[{"id":"1.195453775","rc":[{"atl":[[2.1,18.18],[2.16,217.5]],"id":38247334},{"atl":[[3.35,86.91]],"id":42688799}],"con":true,"img":false}]}
{"op":"mcm","clk":"5353541092","pt":1646216132631,"mc":[{"id":"1.195453775","rc":[{"atl":[[3.4,19.81]],"id":42688799}],"con":true,"img":false}]}
{"op":"mcm","clk":"5353541106","pt":1646216132738,"mc":[{"id":"1.195453775","rc":[{"atl":[[3.3,43.48]],"id":42688799}],"con":true,"img":false}]}
{"op":"mcm","clk":"5353541135","pt":1646216132945,"mc":[{"id":"1.195453775","rc":[{"atl":[[3.35,31.91]],"id":42688799}],"con":true,"img":false}]}
{"op":"mcm","clk":"5353541370","pt":1646216134535,"mc":[{"id":"1.195453775","rc":[{"atl":[[3.15,36.8]],"id":42688799}],"con":true,"img":false}]}
{"op":"mcm","clk":"5353541500","pt":1646216135427,"mc":[{"id":"1.195453775","rc":[{"atl":[[6.4,0]],"id":39790958},{"atb":[[1.83,0]],"id":42256451}],"con":true,"img":false}]}
{"op":"mcm","clk":"5353541513","pt":1646216135532,"mc":[{"id":"1.195453775","rc":[{"atb":[[2.18,45.41]],"id":42688799},{"atl":[[5.7,10.13]],"id":39790958},{"atb":[[1.66,70.03]],"id":42256451}],"con":true,"img":false}]}
{"op":"mcm","clk":"5353541527","pt":1646216135640,"mc":[{"id":"1.195453775","rc":[{"atb":[[1.49,72.6]],"id":38247334},{"atb":[[1.79,13.81]],"id":42256451}],"con":true,"img":false}]}
{"op":"mcm","clk":"5353541704","pt":1646216137021,"mc":[{"id":"1.195453775","rc":[{"atb":[[3.2,0],[3.15,58.03]],"id":39790958}],"con":true,"img":false}]}
{"op":"mcm","clk":"5353541716","pt":1646216137055,"mc":[{"id":"1.195453775","rc":[{"atb":[[1.97,2.5],[2.18,133.94]],"id":42688799},{"atb":[[3.6,3]],"id":39790958},{"atl":[[5,5],[5.2,11.07]],"id":39790958},{"atl":[[12,1.82],[14,0],[23,4.55],[30,0]],"id":41632950},{"atb":[[4,0],[4.5,2.5],[3.85,78.95],[4.1,55.31],[4.4,32.82],[3.75,0]],"id":41132571},{"atb":[[1.82,2.5]],"id":42256451},{"atl":[[2.42,2],[2.48,13.51]],"id":42256451},{"atb":[[7.6,19.78]],"id":38745817}],"con":true,"img":false}]}
{"op":"mcm","clk":"5353541746","pt":1646216137269,"mc":[{"id":"1.195453775","rc":[{"atb":[[1.92,21.74],[1.96,0],[1.94,0]],"id":42688799},{"atl":[[2.86,3]],"id":42688799},{"atb":[[3.65,2]],"id":39790958},{"atl":[[5,16.82],[5.5,0]],"id":39790958},{"atl":[[12,8.66]],"id":41632950},{"atb":[[4.1,21.13]],"id":41132571},{"atl":[[2.42,0]],"id":42256451}],"con":true,"img":false}]}
{"op":"mcm","clk":"5353541755","pt":1646216137319,"mc":[{"id":"1.195453775","rc":[{"atl":[[5.2,15.83]],"id":39790958},{"atl":[[13.5,0]],"id":41632950},{"atb":[[4.5,25.36],[4.3,75.77]],"id":41132571},{"atl":[[2.5,13.33],[2.48,8.36]],"id":42256451}],"con":true,"img":false}]}
{"op":"mcm","clk":"5353541768","pt":1646216137422,"mc":[{"id":"1.195453775","rc":[{"atl":[[5,0],[5.2,4.76]],"id":39790958}],"con":true,"img":false}]}
{"op":"mcm","clk":"5353541783","pt":1646216137528,"mc":[{"id":"1.195453775","rc":[{"atl":[[5.6,40.48],[7.2,0],[6.8,17.24],[5.4,17.18]],"id":39790958},{"atb":[[4.4,15.73]],"id":41132571}],"con":true,"img":false}]}
{"op":"mcm","clk":"5353541846","pt":1646216137945,"mc":[{"id":"1.195453775","rc":[{"atb":[[4.4,14.06]],"id":41132571}],"con":true,"img":false}]}
{"op":"mcm","clk":"5353541874","pt":1646216138151,"mc":[{"id":"1.195453775","rc":[{"atb":[[4.6,1.66]],"id":41132571}],"con":true,"img":false}]}
{"op":"mcm","clk":"5353541891","pt":1646216138257,"mc":[{"id":"1.195453775","rc":[{"atb":[[1.87,0]],"id":42256451}],"con":true,"img":false}]}
{"op":"mcm","clk":"5353541904","pt":1646216138313,"mc":[{"id":"1.195453775","rc":[{"atb":[[2.18,88.53]],"id":42688799},{"atb":[[5.3,0]],"id":41632950}],"con":true,"img":false}]}
{"op":"mcm","clk":"5353541919","pt":1646216138416,"mc":[{"id":"1.195453775","rc":[{"atb":[[1.97,35.71],[1.96,45.41]],"id":42688799},{"atb":[[5.1,2.5],[4.5,18.92],[4.7,25.49]],"id":41632950}],"con":true,"img":false}]}
{"op":"mcm","clk":"5353541991","pt":1646216138938,"mc":[{"id":"1.195453775","rc":[{"atb":[[1.96,66.24]],"id":42688799},{"atl":[[2.86,0]],"id":42688799},{"atb":[[3.7,2]],"id":39790958}],"con":true,"img":false}]}
{"op":"mcm","clk":"5353542060","pt":1646216139518,"mc":[{"id":"1.195453775","rc":[{"atb":[[3.75,2]],"id":39790958}],"con":true,"img":false}]}
{"op":"mcm","clk":"5353542318","pt":1646216141640,"mc":[{"id":"1.195453775","rc":[{"atb":[[1.79,46.34]],"id":42256451}],"con":true,"img":false}]}
{"op":"mcm","clk":"5353542402","pt":1646216142255,"mc":[{"id":"1.195453775","rc":[{"atb":[[1.48,229.05]],"id":38247334},{"atb":[[1.66,0]],"id":42256451},{"atb":[[9.6,4.65]],"id":38745817}],"con":true,"img":false}]}
{"op":"mcm","clk":"5353542417","pt":1646216142361,"mc":[{"id":"1.195453775","rc":[{"atb":[[1.36,82.9]],"id":38247334},{"atb":[[2.64,2]],"id":42688799},{"atl":[[3.15,27.5],[3.25,0],[3.3,52.18]],"id":42688799},{"atb":[[3.6,0],[3.75,0],[3.7,0],[3.65,0]],"id":39790958},{"atl":[[5,5]],"id":39790958},{"atb":[[1.61,70.03]],"id":42256451},{"atb":[[8.8,5.73]],"id":38745817}],"con":true,"img":false}]}
{"op":"mcm","clk":"5353542436","pt":1646216142468,"mc":[{"id":"1.195453775","rc":[{"atb":[[3,10],[3.15,11.52]],"id":39790958},{"atl":[[5.2,0]],"id":39790958}],"con":true,"img":false}]}
{"op":"mcm","clk":"5353542452","pt":1646216142574,"mc":[{"id":"1.195453775","rc":[{"atb":[[2.18,0],[2.66,3]],"id":42688799},{"atl":[[3.35,74.46],[3.15,0],[3.3,8.7]],"id":42688799},{"atb":[[3.1,29.31],[3.05,35.77]],"id":39790958},{"atl":[[5.6,16.3],[5.8,0]],"id":39790958},{"atb":[[8.6,0],[8.8,23.81]],"id":38745817}],"con":true,"img":false}]}
{"op":"mcm","clk":"5353542472","pt":1646216142728,"mc":[{"id":"1.195453775","rc":[{"atl":[[3.3,40.16]],"id":42688799}],"con":true,"img":false}]}
{"op":"mcm","clk":"5353542500","pt":1646216142932,"mc":[{"id":"1.195453775","rc":[{"atb":[[2,147.14]],"id":38745817}],"con":true,"img":false}]}
{"op":"mcm","clk":"5353542649","pt":1646216144233,"mc":[{"id":"1.195453775","rc":[{"atl":[[2.36,0],[2.28,78.13]],"id":38247334},{"atl":[[5.7,0]],"id":39790958}],"con":true,"img":false}]}
{"op":"mcm","clk":"5353542661","pt":1646216144337,"mc":[{"id":"1.195453775","rc":[{"atb":[[1.52,16.62]],"id":38247334},{"atb":[[2.24,8.38]],"id":42688799},{"atl":[[6.4,10.13]],"id":39790958}],"con":true,"img":false}]}
{"op":"mcm","clk":"5353542692","pt":1646216144649,"mc":[{"id":"1.195453775","rc":[{"atb":[[2.68,4]],"id":42688799}],"con":true,"img":false}]}
{"op":"mcm","clk":"5353542794","pt":1646216145434,"mc":[{"id":"1.195453775","rc":[{"atb":[[2.7,2]],"id":42688799}],"con":true,"img":false}]}
{"op":"mcm","clk":"5353542842","pt":1646216145847,"mc":[{"id":"1.195453775","rc":[{"atl":[[3.4,55.54]],"id":42688799}],"con":true,"img":false}]}
{"op":"mcm","clk":"5353542863","pt":1646216146053,"mc":[{"id":"1.195453775","rc":[{"atb":[[1.97,2.5]],"id":42688799}],"con":true,"img":false}]}
{"op":"mcm","clk":"5353542889","pt":1646216146263,"mc":[{"id":"1.195453775","rc":[{"atl":[[2.06,68.22]],"id":38247334}],"con":true,"img":false}]}
{"op":"mcm","clk":"5353542898","pt":1646216146361,"mc":[{"id":"1.195453775","rc":[{"atl":[[2.14,38.24]],"id":38247334},{"atl":[[13,4.17]],"id":41632950}],"con":true,"img":false}]}
{"op":"mcm","clk":"5353542910","pt":1646216146465,"mc":[{"id":"1.195453775","rc":[{"atl":[[2.06,0],[2.14,197.94],[2.16,43.1]],"id":38247334}],"con":true,"img":false}]}
{"op":"mcm","clk":"5353542919","pt":1646216146574,"mc":[{"id":"1.195453775","rc":[{"atl":[[2.1,90.91]],"id":38247334}],"con":true,"img":false}]}
{"op":"mcm","clk":"5353542926","pt":1646216146672,"mc":[{"id":"1.195453775","rc":[{"atl":[[2.54,32.47]],"id":42256451}],"con":true,"img":false}]}
{"op":"mcm","clk":"5353543016","pt":1646216147400,"mc":[{"id":"1.195453775","rc":[{"atl":[[17,0]],"id":41632950}],"con":true,"img":false}]}
{"op":"mcm","clk":"5353543138","pt":1646216148342,"mc":[{"id":"1.195453775","rc":[{"atb":[[8.8,18.08]],"id":38745817}],"con":true,"img":false}]}
{"op":"mcm","clk":"5353543151","pt":1646216148445,"mc":[{"id":"1.195453775","rc":[{"atb":[[1.46,58.85],[1.45,0],[1.37,0],[1.41,0],[1.49,0]],"id":38247334},{"atb":[[8.6,5.73]],"id":38745817}],"con":true,"img":false}]}
{"op":"mcm","clk":"5353543160","pt":1646216148544,"mc":[{"id":"1.195453775","rc":[{"atb":[[1.46,283.49],[1.48,0]],"id":38247334}],"con":true,"img":false}]}
{"op":"mcm","clk":"5353543190","pt":1646216148855,"mc":[{"id":"1.195453775","rc":[{"atb":[[2.24,6.71]],"id":42688799}],"con":true,"img":false}]}
{"op":"mcm","clk":"5353543201","pt":1646216148960,"mc":[{"id":"1.195453775","rc":[{"atb":[[2.72,1.66]],"id":42688799},{"atb":[[3.2,1.66]],"id":39790958}],"con":true,"img":false}]}
{"op":"mcm","clk":"5353543324","pt":1646216150160,"mc":[{"id":"1.195453775","rc":[{"atb":[[1.52,2.16]],"id":38247334},{"atb":[[1.83,9.06]],"id":42256451}],"con":true,"img":false}]}
{"op":"mcm","clk":"5353543349","pt":1646216150369,"mc":[{"id":"1.195453775","rc":[{"atb":[[1.79,13.81]],"id":42256451}],"con":true,"img":false}]}
{"op":"mcm","clk":"5353543370","pt":1646216150476,"mc":[{"id":"1.195453775","rc":[{"atl":[[5,25]],"id":39790958}],"con":true,"img":false}]}
{"op":"mcm","clk":"5353543390","pt":1646216150686,"mc":[{"id":"1.195453775","rc":[{"atl":[[5.4,11.36]],"id":39790958}],"con":true,"img":false}]}
{"op":"mcm","clk":"5353543403","pt":1646216150736,"mc":[{"id":"1.195453775","rc":[{"atl":[[5.6,79.57]],"id":39790958}],"con":true,"img":false}]}
{"op":"mcm","clk":"5353543476","pt":1646216151359,"mc":[{"id":"1.195453775","rc":[{"atb":[[3.2,9.72]],"id":39790958}],"con":true,"img":false}]}
{"op":"mcm","clk":"5353543484","pt":1646216151465,"mc":[{"id":"1.195453775","rc":[{"atb":[[3.1,84.09],[3.05,2.49],[3.2,37.11]],"id":39790958}],"con":true,"img":false}]}
{"op":"mcm","clk":"5353543509","pt":1646216151674,"mc":[{"id":"1.195453775","rc":[{"atb":[[1.94,53.19]],"id":42688799},{"atl":[[3.4,76.37]],"id":42688799},{"atb":[[3.15,0]],"id":39790958},{"atl":[[5.2,11.9]],"id":39790958}],"con":true,"img":false}]}
{"op":"mcm","clk":"5353543523","pt":1646216151778,"mc":[{"id":"1.195453775","rc":[{"atl":[[3.35,31.91],[3.4,118.04]],"id":42688799}],"con":true,"img":false}]}
{"op":"mcm","clk":"5353543534","pt":1646216151882,"mc":[{"id":"1.195453775","rc":[{"atl":[[5.6,16.3]],"id":39790958}],"con":true,"img":false}]}
{"op":"mcm","clk":"5353543623","pt":1646216152563,"mc":[{"id":"1.195453775","rc":[{"atl":[[2.14,38.24],[2.16,224.12]],"id":38247334}],"con":true,"img":false}]}
{"op":"mcm","clk":"5353543684","pt":1646216153144,"mc":[{"id":"1.195453775","rc":[{"atb":[[1.83,0]],"id":42256451}],"con":true,"img":false}]}
{"op":"mcm","clk":"5353543791","pt":1646216154077,"mc":[{"id":"1.195453775","rc":[{"atb":[[1.37,96.14]],"id":38247334},{"atb":[[1.79,0]],"id":42256451}],"con":true,"img":false}]}
{"op":"mcm","clk":"5353543803","pt":1646216154181,"mc":[{"id":"1.195453775","rc":[{"atb":[[2.64,0],[2.66,0],[2.68,0],[2.7,0]],"id":42688799}],"con":true,"img":false}]}
{"op":"mcm","clk":"5353543823","pt":1646216154342,"mc":[{"id":"1.195453775","rc":[{"atb":[[1.97,62.95]],"id":42688799},{"atb":[[4.5,5.71]],"id":41632950},{"atl":[[14.5,0]],"id":41632950}],"con":true,"img":false}]}
{"op":"mcm","clk":"5353543833","pt":1646216154446,"mc":[{"id":"1.195453775","rc":[{"atb":[[4.4,13.21]],"id":41632950},{"atl":[[13.5,2.72]],"id":41632950}],"con":true,"img":false}]}
{"op":"mcm","clk":"5353543857","pt":1646216154659,"mc":[{"id":"1.195453775","rc":[{"atb":[[1.46,58.85],[1.4,431.58]],"id":38247334}],"con":true,"img":false}]}
{"op":"mcm","clk":"5353543870","pt":1646216154762,"mc":[{"id":"1.195453775","rc":[{"atb":[[1.78,18.79]],"id":42256451}],"con":true,"img":false}]}
{"op":"mcm","clk":"5353543979","pt":1646216155650,"mc":[{"id":"1.195453775","rc":[{"atl":[[14,5.77]],"id":41632950}],"con":true,"img":false}]}
{"op":"mcm","clk":"5353544003","pt":1646216155853,"mc":[{"id":"1.195453775","rc":[{"atl":[[2.58,47.47]],"id":42256451}],"con":true,"img":false}]}
{"op":"mcm","clk":"5353544057","pt":1646216156271,"mc":[{"id":"1.195453775","rc":[{"atb":[[1.49,15.34]],"id":38247334}],"con":true,"img":false}]}
{"op":"mcm","clk":"5353544205","pt":1646216157490,"mc":[{"id":"1.195453775","rc":[{"atb":[[3.1,29.31],[3.05,57.85]],"id":39790958}],"con":true,"img":false}]}
{"op":"mcm","clk":"5353544277","pt":1646216157971,"mc":[{"id":"1.195453775","rc":[{"atl":[[16,0]],"id":41632950},{"atl":[[2.56,0],[2.52,114.63]],"id":42256451}],"con":true,"img":false}]}
{"op":"mcm","clk":"5353544340","pt":1646216158579,"mc":[{"id":"1.195453775","rc":[{"atb":[[3.95,25.42]],"id":41132571}],"con":true,"img":false}]}
{"op":"mcm","clk":"5353544354","pt":1646216158688,"mc":[{"id":"1.195453775","rc":[{"atb":[[3.9,60.19]],"id":41132571}],"con":true,"img":false}]}
{"op":"mcm","clk":"5353544403","pt":1646216159154,"mc":[{"id":"1.195453775","rc":[{"atb":[[1.69,22.97]],"id":42256451}],"con":true,"img":false}]}
{"op":"mcm","clk":"5353544408","pt":1646216159257,"mc":[{"id":"1.195453775","rc":[{"atb":[[1.79,5.13]],"id":42256451}],"con":true,"img":false}]}
{"op":"mcm","clk":"5353544484","pt":1646216159849,"mc":[{"id":"1.195453775","rc":[{"atb":[[2.72,0]],"id":42688799}],"con":true,"img":false}]}
{"op":"mcm","clk":"5353544519","pt":1646216160063,"mc":[{"id":"1.195453775","rc":[{"atb":[[2.26,1.66]],"id":42688799}],"con":true,"img":false}]}
{"op":"mcm","clk":"5353544542","pt":1646216160270,"mc":[{"id":"1.195453775","rc":[{"atb":[[2,2.16],[2.22,0]],"id":42688799}],"con":true,"img":false}]}
{"op":"mcm","clk":"5353544641","pt":1646216160866,"mc":[{"id":"1.195453775","rc":[{"atb":[[1.92,81.52]],"id":42688799},{"atl":[[3.5,30]],"id":42688799},{"atl":[[5.4,17.05]],"id":39790958}],"con":true,"img":false}]}
{"op":"mcm","clk":"5353544715","pt":1646216161588,"mc":[{"id":"1.195453775","rc":[{"atb":[[1.46,204.5],[1.4,151.23]],"id":38247334}],"con":true,"img":false}]}
{"op":"mcm","clk":"5353544751","pt":1646216161861,"mc":[{"id":"1.195453775","rc":[{"atb":[[1.37,0]],"id":38247334}],"con":true,"img":false}]}
{"op":"mcm","clk":"5353545104","pt":1646216164347,"mc":[{"id":"1.195453775","rc":[{"atl":[[2.14,0]],"id":38247334},{"spn":2.78,"spf":"NaN","id":42688799},{"spn":4.1,"spf":"NaN","id":39790958},{"spn":8.75,"spf":"NaN","id":41632950},{"spn":7.55,"spf":"NaN","id":41132571},{"spn":2.16,"spf":"NaN","id":42256451}],"con":true,"img":false}]}
{"op":"mcm","clk":"5353545124","pt":1646216164508,"mc":[{"id":"1.195453775","rc":[{"atl":[[2.2,244.1],[2.16,43.1],[2.08,38.24]],"id":38247334}],"con":true,"img":false}]}
{"op":"mcm","clk":"5353545155","pt":1646216164674,"mc":[{"id":"1.195453775","rc":[{"atl":[[2.08,99.25]],"id":38247334},{"atl":[[3.45,0],[3.35,0]],"id":42688799},{"atl":[[15,8.93]],"id":41632950}],"con":true,"img":false}]}
{"op":"mcm","clk":"5353545168","pt":1646216164774,"mc":[{"id":"1.195453775","rc":[{"atl":[[2.1,18.18]],"id":38247334}],"con":true,"img":false}]}
{"op":"mcm","clk":"5353545182","pt":1646216164877,"mc":[{"id":"1.195453775","rc":[{"atl":[[3.4,82.31],[4.4,2.5],[3.5,135.24]],"id":42688799}],"con":true,"img":false}]}
{"op":"mcm","clk":"5353545195","pt":1646216164983,"mc":[{"id":"1.195453775","rc":[{"atl":[[2.62,77.16]],"id":42256451}],"con":true,"img":false}]}
{"op":"mcm","clk":"5353545256","pt":1646216165458,"mc":[{"id":"1.195453775","rc":[{"atl":[[2.2,62.5],[2.16,135.02]],"id":38247334}],"con":true,"img":false}]}
{"op":"mcm","clk":"5353545388","pt":1646216166456,"mc":[{"id":"1.195453775","rc":[{"atb":[[2.24,0]],"id":42688799}],"con":true,"img":false}]}
{"op":"mcm","clk":"5353545402","pt":1646216166611,"mc":[{"id":"1.195453775","rc":[{"atb":[[2,72.93],[1.96,260.02]],"id":42688799}],"con":true,"img":false}]}
{"op":"mcm","clk":"5353545412","pt":1646216166665,"mc":[{"id":"1.195453775","rc":[{"atb":[[1.49,32.35]],"id":38247334}],"con":true,"img":false}]}
{"op":"mcm","clk":"5353545436","pt":1646216166826,"mc":[{"id":"1.195453775","rc":[{"atb":[[1.97,2.5]],"id":42688799}],"con":true,"img":false}]}
{"op":"mcm","clk":"5353545480","pt":1646216167299,"mc":[{"id":"1.195453775","rc":[{"atb":[[1.41,28.01]],"id":38247334}],"con":true,"img":false}]}
{"op":"mcm","clk":"5353545536","pt":1646216167667,"mc":[{"id":"1.195453775","rc":[{"atb":[[1.78,2.5],[1.79,25.38]],"id":42256451}],"con":true,"img":false}]}
{"op":"mcm","clk":"5353545819","pt":1646216169888,"mc":[{"id":"1.195453775","rc":[{"atl":[[3.6,48.08]],"id":42688799},{"atl":[[5.6,27.17]],"id":39790958}],"con":true,"img":false}]}
{"op":"mcm","clk":"5353545868","pt":1646216170262,"mc":[{"id":"1.195453775","rc":[{"atl":[[2.08,61.01]],"id":38247334}],"con":true,"img":false}]}
{"op":"mcm","clk":"5353545884","pt":1646216170368,"mc":[{"id":"1.195453775","rc":[{"atl":[[2.14,38.24]],"id":38247334}],"con":true,"img":false}]}
{"op":"mcm","clk":"5353545968","pt":1646216170891,"mc":[{"id":"1.195453775","rc":[{"atb":[[2.26,0]],"id":42688799}],"con":true,"img":false}]}
{"op":"mcm","clk":"5353545999","pt":1646216171102,"mc":[{"id":"1.195453775","rc":[{"atb":[[2.02,1.66]],"id":42688799}],"con":true,"img":false}]}
{"op":"mcm","clk":"5353546035","pt":1646216171374,"mc":[{"id":"1.195453775","rc":[{"atl":[[2.28,0],[2.44,69.44]],"id":38247334},{"atl":[[2.8,0],[2.92,52.08]],"id":42256451}],"con":true,"img":false}]}
{"op":"mcm","clk":"5353546182","pt":1646216172274,"mc":[{"id":"1.195453775","rc":[{"atb":[[1.96,214.61]],"id":42688799}],"con":true,"img":false}]}
{"op":"mcm","clk":"5353546191","pt":1646216172374,"mc":[{"id":"1.195453775","rc":[{"atb":[[2.02,47.08]],"id":42688799}],"con":true,"img":false}]}
{"op":"mcm","clk":"5353546206","pt":1646216172482,"mc":[{"id":"1.195453775","rc":[{"atb":[[1.97,182.53],[1.96,20.83]],"id":42688799}],"con":true,"img":false}]}
{"op":"mcm","clk":"5353546284","pt":1646216172901,"mc":[{"id":"1.195453775","rc":[{"atb":[[2,70.77],[2.08,2.16]],"id":42688799}],"con":true,"img":false}]}
{"op":"mcm","clk":"5353546904","pt":1646216177167,"mc":[{"id":"1.195453775","rc":[{"atl":[[2.14,144.16],[2.16,43.1]],"id":38247334}],"con":true,"img":false}]}
{"op":"mcm","clk":"5353547173","pt":1646216179186,"mc":[{"id":"1.195453775","rc":[{"atb":[[2,247.54],[1.97,2.5],[2.08,50.04]],"id":42688799}],"con":true,"img":false}]}
{"op":"mcm","clk":"5353547201","pt":1646216179394,"mc":[{"id":"1.195453775","rc":[{"atb":[[2,176.77]],"id":42688799}],"con":true,"img":false}]}
{"op":"mcm","clk":"5353547309","pt":1646216180282,"mc":[{"id":"1.195453775","rc":[{"atl":[[2.78,0]],"id":42256451}],"con":true,"img":false}]}
{"op":"mcm","clk":"5353547321","pt":1646216180387,"mc":[{"id":"1.195453775","rc":[{"atl":[[2.6,30.27]],"id":42256451}],"con":true,"img":false}]}
{"op":"mcm","clk":"5353547443","pt":1646216181396,"mc":[{"id":"1.195453775","rc":[{"atb":[[3.1,25.34]],"id":39790958}],"con":true,"img":false}]}
{"op":"mcm","clk":"5353547649","pt":1646216182929,"mc":[{"id":"1.195453775","rc":[{"atb":[[2.02,45.41]],"id":42688799}],"con":true,"img":false}]}
{"op":"mcm","clk":"5353547670","pt":1646216183086,"mc":[{"id":"1.195453775","rc":[{"atb":[[2.1,1.66]],"id":42688799}],"con":true,"img":false}]}
{"op":"mcm","clk":"5353548129","pt":1646216186419,"mc":[{"id":"1.195453775","rc":[{"atb":[[2.12,6.71]],"id":42688799}],"con":true,"img":false}]}
{"op":"mcm","clk":"5353548169","pt":1646216186585,"mc":[{"id":"1.195453775","rc":[{"atb":[[2,0],[2.02,191.11]],"id":42688799}],"con":true,"img":false}]}
{"op":"mcm","clk":"5353548746","pt":1646216190301,"mc":[{"id":"1.195453775","rc":[{"atl":[[6.4,0]],"id":39790958}],"con":true,"img":false}]}
{"op":"mcm","clk":"5353548761","pt":1646216190407,"mc":[{"id":"1.195453775","rc":[{"atl":[[5.5,10.13]],"id":39790958}],"con":true,"img":false}]}
{"op":"mcm","clk":"5353548899","pt":1646216191508,"mc":[{"id":"1.195453775","rc":[{"atb":[[2.12,47.21]],"id":42688799}],"con":true,"img":false}]}
{"op":"mcm","clk":"5353548917","pt":1646216191715,"mc":[{"id":"1.195453775","rc":[{"atb":[[2.08,2.16]],"id":42688799}],"con":true,"img":false}]}
{"op":"mcm","clk":"5353548945","pt":1646216191876,"mc":[{"id":"1.195453775","rc":[{"atb":[[2.08,0],[2.18,2.16]],"id":42688799}],"con":true,"img":false}]}
{"op":"mcm","clk":"5353548987","pt":1646216192289,"mc":[{"id":"1.195453775","rc":[{"atb":[[2.12,40.5]],"id":42688799}],"con":true,"img":false}]}
{"op":"mcm","clk":"5353549389","pt":1646216194934,"mc":[{"id":"1.195453775","rc":[{"atb":[[2.1,0]],"id":42688799}],"con":true,"img":false}]}
{"op":"mcm","clk":"5353549417","pt":1646216195092,"mc":[{"id":"1.195453775","rc":[{"atb":[[2.2,1.66]],"id":42688799}],"con":true,"img":false}]}
{"op":"mcm","clk":"5353549604","pt":1646216196317,"mc":[{"id":"1.195453775","rc":[{"atb":[[2.02,145.7]],"id":42688799},{"atb":[[8.6,0]],"id":38745817}],"con":true,"img":false}]}
{"op":"mcm","clk":"5353549625","pt":1646216196520,"mc":[{"id":"1.195453775","rc":[{"atl":[[2.12,17.86],[2.1,0]],"id":38247334},{"atb":[[2.14,45.41]],"id":42688799},{"atb":[[3.6,2]],"id":39790958},{"atl":[[5,20],[5.2,4.76],[6.6,0.09]],"id":39790958},{"atl":[[2.82,54.95],[2.5,0],[2.48,21.87],[2.92,0]],"id":42256451},{"atb":[[9,5.73]],"id":38745817}],"con":true,"img":false}]}
{"op":"mcm","clk":"5353549645","pt":1646216196729,"mc":[{"id":"1.195453775","rc":[{"atl":[[2.08,0]],"id":38247334},{"atb":[[2.12,169.36],[2.02,0]],"id":42688799},{"atb":[[3.6,25.69],[3.1,80.92],[3.05,2.5]],"id":39790958},{"atl":[[5,0]],"id":39790958},{"atl":[[2.54,103.36],[2.52,0]],"id":42256451},{"atb":[[9,23.81],[8.8,0]],"id":38745817}],"con":true,"img":false}]}
{"op":"mcm","clk":"5353549666","pt":1646216196888,"mc":[{"id":"1.195453775","rc":[{"atl":[[2.12,87.89],[2.14,38.24],[2.16,156.29]],"id":38247334},{"atb":[[3.2,9.72]],"id":39790958},{"atl":[[5,20],[5.5,74.24]],"id":39790958}],"con":true,"img":false}]}
{"op":"mcm","clk":"5353549678","pt":1646216196994,"mc":[{"id":"1.195453775","rc":[{"atl":[[5,0],[5.5,10.13]],"id":39790958}],"con":true,"img":false}]}
{"op":"mcm","clk":"5353549701","pt":1646216197205,"mc":[{"id":"1.195453775","rc":[{"atl":[[3.15,9.3],[3.3,31.46]],"id":42688799},{"atb":[[3.65,3]],"id":39790958},{"atl":[[5.4,35.23]],"id":39790958}],"con":true,"img":false}]}
{"op":"mcm","clk":"5353549711","pt":1646216197307,"mc":[{"id":"1.195453775","rc":[{"atb":[[1.83,106.38]],"id":42688799},{"atb":[[5.4,6.84]],"id":41632950}],"con":true,"img":false}]}
{"op":"mcm","clk":"5353549725","pt":1646216197413,"mc":[{"id":"1.195453775","rc":[{"atb":[[1.88,108.06],[1.9,273.32]],"id":42688799},{"atl":[[3.4,197.61],[3.15,39.87],[3.5,30]],"id":42688799},{"atb":[[3.7,2]],"id":39790958},{"atb":[[5.3,21.72]],"id":41632950}],"con":true,"img":false}]}
{"op":"mcm","clk":"5353549736","pt":1646216197517,"mc":[{"id":"1.195453775","rc":[{"atb":[[1.83,0]],"id":42688799}],"con":true,"img":false}]}
{"op":"mcm","clk":"5353549748","pt":1646216197625,"mc":[{"id":"1.195453775","rc":[{"atl":[[3.3,0]],"id":42688799},{"atb":[[3.75,2]],"id":39790958},{"atb":[[5.3,0],[5.1,21.52],[5.5,4.16],[4.7,5]],"id":41632950}],"con":true,"img":false}]}
{"op":"mcm","clk":"5353549768","pt":1646216197786,"mc":[{"id":"1.195453775","rc":[{"atb":[[3.1,25.34]],"id":39790958},{"atl":[[5.4,17.05]],"id":39790958},{"atb":[[5.5,12.42]],"id":41632950}],"con":true,"img":false}]}
{"op":"mcm","clk":"5353549789","pt":1646216197992,"mc":[{"id":"1.195453775","rc":[{"atb":[[5.4,0]],"id":41632950}],"con":true,"img":false}]}
{"op":"mcm","clk":"5353549814","pt":1646216198285,"mc":[{"id":"1.195453775","rc":[{"atb":[[4.4,0]],"id":41632950}],"con":true,"img":false}]}
{"op":"mcm","clk":"5353549831","pt":1646216198392,"mc":[{"id":"1.195453775","rc":[{"atb":[[4.5,18.92]],"id":41632950}],"con":true,"img":false}]}
{"op":"mcm","clk":"5353549853","pt":1646216198598,"mc":[{"id":"1.195453775","rc":[{"atl":[[3.15,9.3]],"id":42688799}],"con":true,"img":false}]}
{"op":"mcm","clk":"5353549866","pt":1646216198703,"mc":[{"id":"1.195453775","rc":[{"atl":[[3.4,227.09]],"id":42688799}],"con":true,"img":false}]}
{"op":"mcm","clk":"5353549893","pt":1646216198915,"mc":[{"id":"1.195453775","rc":[{"atl":[[3.15,0],[3.3,8.7]],"id":42688799}],"con":true,"img":false}]}
{"op":"mcm","clk":"5353550012","pt":1646216199908,"mc":[{"id":"1.195453775","rc":[{"atb":[[2.82,0],[3.6,23.69],[3.75,0],[2.76,11.36],[3.7,0],[2.78,0],[3.65,0]],"id":39790958},{"atl":[[5,5],[4.2,2]],"id":39790958}],"con":true,"img":false}]}
{"op":"mcm","clk":"5353550022","pt":1646216200014,"mc":[{"id":"1.195453775","rc":[{"atb":[[1.8,116.87],[1.88,0]],"id":42688799},{"atl":[[12,6.84],[13,1.67]],"id":41632950},{"atb":[[4.5,22.86],[4.6,4.16],[4.1,16.13]],"id":41132571}],"con":true,"img":false}]}
{"op":"mcm","clk":"5353550041","pt":1646216200223,"mc":[{"id":"1.195453775","rc":[{"atb":[[1.85,259.21],[1.8,0]],"id":42688799},{"atl":[[12,0]],"id":41632950},{"atb":[[4.3,24.39],[3.85,43.86],[4.6,22.9],[3.95,59.32],[4.4,51.54]],"id":41132571}],"con":true,"img":false}]}
{"op":"mcm","clk":"5353550054","pt":1646216200329,"mc":[{"id":"1.195453775","rc":[{"atl":[[3.15,9.3],[3.3,0]],"id":42688799},{"atb":[[2.82,10.99],[3.6,25.69]],"id":39790958},{"atl":[[5,0],[4.2,0]],"id":39790958},{"atl":[[13,8.34]],"id":41632950},{"atb":[[1.45,0],[1.43,0],[1.41,48.78]],"id":42256451},{"atl":[[2.1,4]],"id":42256451}],"con":true,"img":false}]}
{"op":"mcm","clk":"5353550069","pt":1646216200393,"mc":[{"id":"1.195453775","rc":[{"atb":[[1.41,0]],"id":38247334},{"atb":[[3.2,1.66]],"id":39790958},{"atb":[[4.5,0]],"id":41132571}],"con":true,"img":false}]}
{"op":"mcm","clk":"5353550083","pt":1646216200488,"mc":[{"id":"1.195453775","rc":[{"atl":[[5.2,23.81]],"id":39790958}],"con":true,"img":false}]}
{"op":"mcm","clk":"5353550096","pt":1646216200594,"mc":[{"id":"1.195453775","rc":[{"atb":[[3.65,4]],"id":39790958},{"atl":[[2.08,3]],"id":42256451}],"con":true,"img":false}]}
{"op":"mcm","clk":"5353550127","pt":1646216200801,"mc":[{"id":"1.195453775","rc":[{"atl":[[3.15,0],[3.3,8.7]],"id":42688799},{"atb":[[3.6,23.69],[3.65,0]],"id":39790958},{"atl":[[4,4]],"id":39790958},{"atl":[[2.06,2]],"id":42256451}],"con":true,"img":false}]}
{"op":"mcm","clk":"5353550138","pt":1646216200905,"mc":[{"id":"1.195453775","rc":[{"atb":[[2.82,0]],"id":39790958},{"atl":[[5,5]],"id":39790958}],"con":true,"img":false}]}
{"op":"mcm","clk":"5353550153","pt":1646216201009,"mc":[{"id":"1.195453775","rc":[{"atl":[[3.4,185.42],[3.25,30]],"id":42688799},{"atb":[[3.6,0]],"id":39790958},{"atl":[[2.54,32.47]],"id":42256451}],"con":true,"img":false}]}
{"op":"mcm","clk":"5353550165","pt":1646216201113,"mc":[{"id":"1.195453775","rc":[{"atb":[[3.1,46.86]],"id":39790958}],"con":true,"img":false}]}
{"op":"mcm","clk":"5353550211","pt":1646216201478,"mc":[{"id":"1.195453775","rc":[{"atl":[[4,0],[3.75,2]],"id":39790958},{"atl":[[2.12,4]],"id":42256451}],"con":true,"img":false}]}
{"op":"mcm","clk":"5353550275","pt":1646216202102,"mc":[{"id":"1.195453775","rc":[{"atl":[[3.4,40.64]],"id":42688799},{"atl":[[3.7,2]],"id":39790958},{"atl":[[2.04,4],[2.12,0],[2.1,0]],"id":42256451}],"con":true,"img":false}]}
{"op":"mcm","clk":"5353550293","pt":1646216202314,"mc":[{"id":"1.195453775","rc":[{"atb":[[1.44,0],[1.4,88.47]],"id":42256451}],"con":true,"img":false}]}
{"op":"mcm","clk":"5353550384","pt":1646216202894,"mc":[{"id":"1.195453775","rc":[{"atl":[[2.1,18.18]],"id":38247334},{"atb":[[3,0]],"id":39790958},{"atl":[[2.02,2]],"id":42256451}],"con":true,"img":false}]}
{"op":"mcm","clk":"5353550395","pt":1646216202996,"mc":[{"id":"1.195453775","rc":[{"atl":[[2.12,70.03]],"id":38247334},{"atb":[[2.98,12.5]],"id":39790958},{"atl":[[3.65,2]],"id":39790958}],"con":true,"img":false}]}
{"op":"mcm","clk":"5353550407","pt":1646216203098,"mc":[{"id":"1.195453775","rc":[{"atl":[[2.24,0],[2.2,0],[2.16,113.19]],"id":38247334}],"con":true,"img":false}]}
{"op":"mcm","clk":"5353550423","pt":1646216203203,"mc":[{"id":"1.195453775","rc":[{"atb":[[5.1,2.5],[4.7,26.16]],"id":41632950}],"con":true,"img":false}]}
{"op":"mcm","clk":"5353550499","pt":1646216203831,"mc":[{"id":"1.195453775","rc":[{"atl":[[3.6,3]],"id":39790958}],"con":true,"img":false}]}
{"op":"mcm","clk":"5353550593","pt":1646216204421,"mc":[{"id":"1.195453775","rc":[{"atb":[[2.18,8.53]],"id":42688799}],"con":true,"img":false}]}
{"op":"mcm","clk":"5353550655","pt":1646216204797,"mc":[{"id":"1.195453775","rc":[{"atl":[[3.3,0]],"id":42688799},{"atb":[[4.3,18.33],[4.5,5.71]],"id":41132571},{"atl":[[28,0]],"id":38745817}],"con":true,"img":false}]}
{"op":"mcm","clk":"5353550671","pt":1646216204904,"mc":[{"id":"1.195453775","rc":[{"atb":[[2.18,37.55]],"id":42688799},{"atl":[[3.25,38.89]],"id":42688799},{"atb":[[2.82,10.99]],"id":39790958},{"atl":[[3.6,0],[3.75,0],[3.7,0],[3.65,0]],"id":39790958},{"atb":[[1.79,5.13]],"id":42256451},{"atl":[[2.48,8.36],[2.46,13.7]],"id":42256451},{"atl":[[27,1]],"id":38745817}],"con":true,"img":false}]}
{"op":"mcm","clk":"5353550695","pt":1646216205107,"mc":[{"id":"1.195453775","rc":[{"atb":[[2.12,128.86]],"id":42688799}],"con":true,"img":false}]}
{"op":"mcm","clk":"5353550769","pt":1646216205735,"mc":[{"id":"1.195453775","rc":[{"atb":[[1.85,142.34],[1.9,384.43]],"id":42688799}],"con":true,"img":false}]}
{"op":"mcm","clk":"5353550782","pt":1646216205838,"mc":[{"id":"1.195453775","rc":[{"atb":[[1.41,55.24]],"id":38247334},{"atb":[[2.2,4.35]],"id":42688799},{"atb":[[1.79,0]],"id":42256451}],"con":true,"img":false}]}
{"op":"mcm","clk":"5353550793","pt":1646216205894,"mc":[{"id":"1.195453775","rc":[{"atl":[[3.25,30],[3.3,8.7]],"id":42688799},{"atb":[[2.82,0],[2.72,11.63]],"id":39790958},{"atl":[[4.8,5.26],[5,0]],"id":39790958},{"atl":[[27,0],[28,1]],"id":38745817}],"con":true,"img":false}]}
{"op":"mcm","clk":"5353550807","pt":1646216206003,"mc":[{"id":"1.195453775","rc":[{"atb":[[2.12,0],[2.14,160.09]],"id":42688799},{"atb":[[1.78,9.5]],"id":42256451}],"con":true,"img":false}]}
{"op":"mcm","clk":"5353550816","pt":1646216206105,"mc":[{"id":"1.195453775","rc":[{"atl":[[3.4,81.29],[3.25,0]],"id":42688799}],"con":true,"img":false}]}
{"op":"mcm","clk":"5353550907","pt":1646216206895,"mc":[{"id":"1.195453775","rc":[{"atb":[[3.2,0]],"id":39790958}],"con":true,"img":false}]}
{"op":"mcm","clk":"5353550921","pt":1646216206999,"mc":[{"id":"1.195453775","rc":[{"atb":[[3.15,1.66]],"id":39790958}],"con":true,"img":false}]}
{"op":"mcm","clk":"5353551032","pt":1646216208095,"mc":[{"id":"1.195453775","rc":[{"atb":[[2.96,15]],"id":39790958}],"con":true,"img":false}]}
{"op":"mcm","clk":"5353551043","pt":1646216208196,"mc":[{"id":"1.195453775","rc":[{"atb":[[2.98,0]],"id":39790958}],"con":true,"img":false}]}
{"op":"mcm","clk":"5353551054","pt":1646216208305,"mc":[{"id":"1.195453775","rc":[{"atb":[[2.76,0]],"id":39790958}],"con":true,"img":false}]}
{"op":"mcm","clk":"5353551070","pt":1646216208406,"mc":[{"id":"1.195453775","rc":[{"atl":[[14,3.85]],"id":41632950}],"con":true,"img":false}]}
{"op":"mcm","clk":"5353551108","pt":1646216208724,"mc":[{"id":"1.195453775","rc":[{"atb":[[2.96,63.08]],"id":39790958}],"con":true,"img":false}]}
{"op":"mcm","clk":"5353551138","pt":1646216208936,"mc":[{"id":"1.195453775","rc":[{"atl":[[2.1,71.14],[2.14,144.16],[2.16,0]],"id":38247334},{"atl":[[4.8,21.99],[5.4,78.34]],"id":39790958}],"con":true,"img":false}]}
{"op":"mcm","clk":"5353551161","pt":1646216209096,"mc":[{"id":"1.195453775","rc":[{"atl":[[2.12,0]],"id":38247334},{"atl":[[5.2,4.76]],"id":39790958}],"con":true,"img":false}]}
{"op":"mcm","clk":"5353551198","pt":1646216209404,"mc":[{"id":"1.195453775","rc":[{"atb":[[2.74,0]],"id":39790958},{"atl":[[2,3],[2.08,0],[2.06,0]],"id":42256451}],"con":true,"img":false}]}
{"op":"mcm","clk":"5353551395","pt":1646216211230,"mc":[{"id":"1.195453775","rc":[{"atb":[[4.7,9.61]],"id":41132571}],"con":true,"img":false}]}
{"op":"mcm","clk":"5353551411","pt":1646216211335,"mc":[{"id":"1.195453775","rc":[{"atl":[[2.14,188.02]],"id":38247334}],"con":true,"img":false}]}
{"op":"mcm","clk":"5353551499","pt":1646216212118,"mc":[{"id":"1.195453775","rc":[{"atb":[[4.5,36.52],[4.4,14.06],[4.7,25.01]],"id":41132571}],"con":true,"img":false}]}
{"op":"mcm","clk":"5353551517","pt":1646216212327,"mc":[{"id":"1.195453775","rc":[{"atb":[[4.6,4.16],[3.9,41.71]],"id":41132571},{"atb":[[9,18.08]],"id":38745817}],"con":true,"img":false}]}
{"op":"mcm","clk":"5353551533","pt":1646216212433,"mc":[{"id":"1.195453775","rc":[{"atb":[[4,18.47]],"id":41132571},{"atb":[[9.2,5.73]],"id":38745817}],"con":true,"img":false}]}
{"op":"mcm","clk":"5353551560","pt":1646216212645,"mc":[{"id":"1.195453775","rc":[{"atb":[[9,0],[9.2,23.81]],"id":38745817}],"con":true,"img":false}]}
{"op":"mcm","clk":"5353551611","pt":1646216213121,"mc":[{"id":"1.195453775","rc":[{"atb":[[4.3,33.48]],"id":41132571}],"con":true,"img":false}]}
{"op":"mcm","clk":"5353551620","pt":1646216213229,"mc":[{"id":"1.195453775","rc":[{"atb":[[2.72,0],[2.98,10],[2.96,48.08],[2.68,11.9],[2.7,35.58]],"id":39790958},{"atl":[[3.75,2]],"id":39790958},{"atb":[[1.39,128.21]],"id":42256451},{"atl":[[2.5,33.33],[1.99,3]],"id":42256451}],"con":true,"img":false}]}
{"op":"mcm","clk":"5353551650","pt":1646216213448,"mc":[{"id":"1.195453775","rc":[{"atl":[[3.7,3],[3.75,4],[5.4,17.05]],"id":39790958},{"atb":[[3.85,0]],"id":41132571},{"atl":[[2,0],[2.62,0],[2.08,3],[1.99,0]],"id":42256451}],"con":true,"img":false}]}
{"op":"mcm","clk":"5353551672","pt":1646216213612,"mc":[{"id":"1.195453775","rc":[{"atb":[[1.41,0]],"id":38247334},{"atl":[[4.8,5.26]],"id":39790958}],"con":true,"img":false}]}
{"op":"mcm","clk":"5353551757","pt":1646216214344,"mc":[{"id":"1.195453775","rc":[{"atl":[[2.14,149.78]],"id":38247334}],"con":true,"img":false}]}
{"op":"mcm","clk":"5353551771","pt":1646216214450,"mc":[{"id":"1.195453775","rc":[{"atl":[[2.44,247.79],[2.14,43.86],[2.08,38.24]],"id":38247334}],"con":true,"img":false}]}
{"op":"mcm","clk":"5353551787","pt":1646216214503,"mc":[{"id":"1.195453775","rc":[{"atl":[[3.65,2]],"id":39790958},{"atl":[[2.06,3]],"id":42256451}],"con":true,"img":false}]}
{"op":"mcm","clk":"5353552105","pt":1646216216517,"mc":[{"id":"1.195453775","rc":[{"atl":[[3.5,131.34]],"id":42688799},{"atl":[[3.6,2]],"id":39790958}],"con":true,"img":false}]}
{"op":"mcm","clk":"5353552123","pt":1646216216618,"mc":[{"id":"1.195453775","rc":[{"atl":[[15,5.36]],"id":41632950}],"con":true,"img":false}]}
{"op":"mcm","clk":"5353552148","pt":1646216216831,"mc":[{"id":"1.195453775","rc":[{"atb":[[2.2,31.32]],"id":42688799}],"con":true,"img":false}]}
{"op":"mcm","clk":"5353552171","pt":1646216217040,"mc":[{"id":"1.195453775","rc":[{"atb":[[2.18,8.53]],"id":42688799}],"con":true,"img":false}]}
{"op":"mcm","clk":"5353552350","pt":1646216218343,"mc":[{"id":"1.195453775","rc":[{"atb":[[9.2,18.08]],"id":38745817}],"con":true,"img":false}]}
{"op":"mcm","clk":"5353552365","pt":1646216218398,"mc":[{"id":"1.195453775","rc":[{"atb":[[8.6,5.73]],"id":38745817}],"con":true,"img":false}]}
{"op":"mcm","clk":"5353552398","pt":1646216218711,"mc":[{"id":"1.195453775","rc":[{"atb":[[1.41,55.24]],"id":38247334}],"con":true,"img":false}]}
{"op":"mcm","clk":"5353552422","pt":1646216218921,"mc":[{"id":"1.195453775","rc":[{"atb":[[3.15,0]],"id":39790958},{"atb":[[4.6,2.5]],"id":41132571}],"con":true,"img":false}]}
