{"op":"mcm","clk":"5317728508","pt":1646251399891,"mc":[{"id":"1.195532866","marketDefinition":{"bspMarket":true,"turnInPlayEnabled":false,"persistenceEnabled":false,"marketBaseRate":5.0,"eventId":"31275720","eventTypeId":"4339","numberOfWinners":1,"bettingType":"ODDS","marketType":"WIN","marketTime":"2022-03-03T16:08:00.000Z","suspendTime":"2022-03-03T16:08:00.000Z","bspReconciled":false,"complete":true,"inPlay":false,"crossMatching":false,"runnersVoidable":false,"numberOfActiveRunners":6,"betDelay":0,"status":"OPEN","runners":[{"status":"ACTIVE","sortPriority":1,"id":41529439,"name":"1. Puttfor Daisy"},{"status":"ACTIVE","sortPriority":2,"id":26648132,"name":"2. Trapstyle Brae"},{"status":"ACTIVE","sortPriority":3,"id":35676762,"name":"3. Seven Of Nine"},{"status":"ACTIVE","sortPriority":4,"id":39213014,"name":"4. Watford Lad"},{"status":"ACTIVE","sortPriority":5,"id":43094640,"name":"5. Droopys Solution"},{"status":"ACTIVE","sortPriority":6,"id":28791281,"name":"6. Our Bill"}],"regulators":["MR_INT"],"venue":"Romford","countryCode":"GB","discountAllowed":false,"timezone":"Europe/London","openDate":"2022-03-03T13:57:00.000Z","version":4384107306,"name":"A2 400m","eventName":"Romford 3rd Mar"},"rc":[],"con":true,"img":false}]}
{"op":"mcm","clk":"5317728858","pt":1646251401765,"mc":[{"id":"1.195532866","marketDefinition":{"bspMarket":true,"turnInPlayEnabled":false,"persistenceEnabled":false,"marketBaseRate":5.0,"eventId":"31275720","eventTypeId":"4339","numberOfWinners":1,"bettingType":"ODDS","marketType":"WIN","marketTime":"2022-03-03T16:08:00.000Z","suspendTime":"2022-03-03T16:08:00.000Z","bspReconciled":false,"complete":true,"inPlay":false,"crossMatching":false,"runnersVoidable":false,"numberOfActiveRunners":6,"betDelay":0,"status":"OPEN","runners":[{"status":"ACTIVE","sortPriority":1,"id":41529439,"name":"1. Puttfor Daisy"},{"status":"ACTIVE","sortPriority":2,"id":26648132,"name":"2. Trapstyle Brae"},{"status":"ACTIVE","sortPriority":3,"id":35676762,"name":"3. Seven Of Nine"},{"status":"ACTIVE","sortPriority":4,"id":39213014,"name":"4. Watford Lad"},{"status":"ACTIVE","sortPriority":5,"id":43094640,"name":"5. Droopys Solution"},{"status":"ACTIVE","sortPriority":6,"id":28791281,"name":"6. Our Bill"}],"regulators":["MR_INT"],"venue":"Romford","countryCode":"GB","discountAllowed":true,"timezone":"Europe/London","openDate":"2022-03-03T13:57:00.000Z","version":4384107306,"name":"A2 400m","eventName":"Romford 3rd Mar"},"rc":[],"con":true,"img":false}]}
{"op":"mcm","clk":"5318440827","pt":1646258364084,"mc":[{"id":"1.195532866","rc":[{"spl":[[1.01,10]],"id":35676762},{"spn":1.0,"spf":1.0,"id":35676762}],"con":true,"img":false}]}
{"op":"mcm","clk":"5318486258","pt":1646259099653,"mc":[{"id":"1.195532866","rc":[{"atb":[[1.12,30]],"id":41529439},{"spn":"Infinity","spf":"NaN","id":41529439}],"con":true,"img":false}]}
{"op":"mcm","clk":"5318486262","pt":1646259099757,"mc":[{"id":"1.195532866","rc":[{"atb":[[1.12,30]],"id":26648132},{"atl":[[390,3]],"id":26648132},{"atb":[[1.12,30]],"id":43094640},{"atl":[[560,3]],"id":43094640},{"atb":[[1.14,30]],"id":28791281},{"atl":[[500,3]],"id":28791281},{"atb":[[1.12,30]],"id":35676762},{"atl":[[550,3]],"id":35676762},{"atl":[[370,3]],"id":41529439},{"atb":[[1.12,30]],"id":39213014},{"atl":[[270,3]],"id":39213014}],"con":true,"img":false}]}
{"op":"mcm","clk":"5318509028","pt":1646259402463,"mc":[{"id":"1.195532866","marketDefinition":{"bspMarket":true,"turnInPlayEnabled":false,"persistenceEnabled":false,"marketBaseRate":5.0,"eventId":"31275720","eventTypeId":"4339","numberOfWinners":1,"bettingType":"ODDS","marketType":"WIN","marketTime":"2022-03-03T16:08:00.000Z","suspendTime":"2022-03-03T16:08:00.000Z","bspReconciled":false,"complete":true,"inPlay":false,"crossMatching":false,"runnersVoidable":false,"numberOfActiveRunners":6,"betDelay":0,"status":"OPEN","runners":[{"status":"ACTIVE","sortPriority":1,"id":41529439,"name":"1. Puttfor Daisy"},{"status":"ACTIVE","sortPriority":2,"id":26648132,"name":"2. Trapstyle Brae"},{"status":"ACTIVE","sortPriority":3,"id":35676762,"name":"3. Seven Of Nine"},{"status":"ACTIVE","sortPriority":4,"id":39213014,"name":"4. Watford Lad"},{"status":"ACTIVE","sortPriority":5,"id":43094640,"name":"5. Droopys Solution"},{"status":"ACTIVE","sortPriority":6,"id":28791281,"name":"6. Our Bill"}],"regulators":["MR_INT"],"venue":"Romford","countryCode":"GB","discountAllowed":true,"timezone":"Europe/London","openDate":"2022-03-03T13:57:00.000Z","version":4384107306,"name":"A2 400m","eventName":"Romford 3rd Mar"},"rc":[{"atb":[[1.12,30]],"id":26648132},{"atl":[[390,3]],"id":26648132},{"spn":195.56,"spf":"NaN","id":26648132},{"atb":[[1.12,30]],"id":43094640},{"atl":[[560,3]],"id":43094640},{"spn":280.56,"spf":"NaN","id":43094640},{"atb":[[1.14,30]],"id":28791281},{"atl":[[500,3]],"id":28791281},{"spn":250.57,"spf":"NaN","id":28791281},{"atb":[[1.12,30]],"id":35676762},{"spl":[[1.01,10]],"id":35676762},{"atl":[[550,3]],"id":35676762},{"spn":1.12,"spf":1.0,"id":35676762},{"atb":[[1.12,30]],"id":41529439},{"atl":[[370,3]],"id":41529439},{"spn":185.56,"spf":"NaN","id":41529439},{"atb":[[1.12,30]],"id":39213014},{"atl":[[270,3]],"id":39213014},{"spn":135.56,"spf":"NaN","id":39213014}],"con":true,"img":true}]}
{"op":"mcm","clk":"5320139877","pt":1646287410951,"mc":[{"id":"1.195532866","rc":[{"atb":[[2.04,12.79]],"id":26648132},{"spn":196.02,"spf":"NaN","id":26648132},{"atb":[[2.04,11.94]],"id":43094640},{"spn":281.02,"spf":"NaN","id":43094640},{"atb":[[2,10.03]],"id":28791281},{"spn":251.0,"spf":"NaN","id":28791281},{"atb":[[2.06,8.61]],"id":35676762},{"spn":1.92,"spf":1.0,"id":35676762},{"atb":[[2.06,9.47]],"id":41529439},{"spn":186.03,"spf":"NaN","id":41529439},{"atb":[[2.1,13.16]],"id":39213014},{"spn":136.05,"spf":"NaN","id":39213014}],"con":true,"img":false}]}
{"op":"mcm","clk":"5320522281","pt":1646296909008,"mc":[{"id":"1.195532866","rc":[{"atb":[[2.04,12.8]],"id":26648132},{"atb":[[2.04,11.94]],"id":43094640},{"spl":[[4,10]],"id":43094640},{"spn":3.02,"spf":1.0,"id":43094640},{"atb":[[2,10.04]],"id":28791281},{"spl":[[28,10]],"id":28791281},{"spn":15.0,"spf":1.0,"id":28791281},{"atb":[[2.06,8.61]],"id":35676762},{"spl":[[14,10]],"id":35676762},{"spn":1.92,"spf":1.0,"id":35676762},{"atb":[[2.06,9.47]],"id":41529439},{"spl":[[10,10]],"id":41529439},{"spn":6.03,"spf":1.0,"id":41529439},{"atb":[[2.1,13.17]],"id":39213014},{"spl":[[8.6,10]],"id":39213014},{"spn":5.35,"spf":1.0,"id":39213014}],"con":true,"img":false}]}
{"op":"mcm","clk":"5320633390","pt":1646298862767,"mc":[{"id":"1.195532866","rc":[{"atl":[[44,1]],"id":28791281},{"atl":[[44,1]],"id":35676762},{"atl":[[44,1]],"id":41529439},{"atl":[[44,1]],"id":39213014}],"con":true,"img":false}]}
{"op":"mcm","clk":"5320634630","pt":1646298880491,"mc":[{"id":"1.195532866","rc":[{"atl":[[44,1.1]],"id":28791281},{"atl":[[44,1.1]],"id":35676762},{"atl":[[44,1.1]],"id":41529439},{"atl":[[44,1.1]],"id":39213014}],"con":true,"img":false}]}
{"op":"mcm","clk":"5320635552","pt":1646298894843,"mc":[{"id":"1.195532866","rc":[{"atl":[[44,0.1]],"id":28791281},{"atl":[[44,0.1]],"id":35676762},{"atl":[[44,0.1]],"id":41529439},{"atl":[[44,0.1]],"id":39213014}],"con":true,"img":false}]}
{"op":"mcm","clk":"5320680132","pt":1646299808181,"mc":[{"id":"1.195532866","rc":[{"spl":[[21,1]],"id":26648132},{"spn":11.52,"spf":1.0,"id":26648132},{"spl":[[21,1]],"id":43094640},{"spl":[[21,1]],"id":28791281},{"spn":11.5,"spf":1.0,"id":28791281},{"spl":[[21,1]],"id":35676762},{"spl":[[21,1]],"id":41529439},{"spl":[[21,1]],"id":39213014}],"con":true,"img":false}]}
{"op":"mcm","clk":"5320830256","pt":1646302602578,"mc":[{"id":"1.195532866","marketDefinition":{"bspMarket":true,"turnInPlayEnabled":false,"persistenceEnabled":false,"marketBaseRate":5.0,"eventId":"31275720","eventTypeId":"4339","numberOfWinners":1,"bettingType":"ODDS","marketType":"WIN","marketTime":"2022-03-03T16:08:00.000Z","suspendTime":"2022-03-03T16:08:00.000Z","bspReconciled":false,"complete":true,"inPlay":false,"crossMatching":false,"runnersVoidable":false,"numberOfActiveRunners":6,"betDelay":0,"status":"OPEN","runners":[{"status":"ACTIVE","sortPriority":1,"id":41529439,"name":"1. Puttfor Daisy"},{"status":"ACTIVE","sortPriority":2,"id":26648132,"name":"2. Trapstyle Brae"},{"status":"ACTIVE","sortPriority":3,"id":35676762,"name":"3. Seven Of Nine"},{"status":"ACTIVE","sortPriority":4,"id":39213014,"name":"4. Watford Lad"},{"status":"ACTIVE","sortPriority":5,"id":43094640,"name":"5. Droopys Solution"},{"status":"ACTIVE","sortPriority":6,"id":28791281,"name":"6. Our Bill"}],"regulators":["MR_INT"],"venue":"Romford","countryCode":"GB","discountAllowed":true,"timezone":"Europe/London","openDate":"2022-03-03T13:57:00.000Z","version":4384107306,"name":"A2 400m","eventName":"Romford 3rd Mar"},"rc":[{"atb":[[1.12,30],[2.04,12.79]],"id":26648132},{"spl":[[21,1]],"id":26648132},{"atl":[[390,3]],"id":26648132},{"spn":11.52,"spf":1.0,"id":26648132},{"atb":[[1.12,30],[2.04,11.94]],"id":43094640},{"spl":[[4,10],[21,1]],"id":43094640},{"atl":[[560,3]],"id":43094640},{"spn":3.02,"spf":1.0,"id":43094640},{"atb":[[2,10.03],[1.14,30]],"id":28791281},{"spl":[[21,1],[28,10]],"id":28791281},{"atl":[[44,0.1],[500,3]],"id":28791281},{"spn":11.5,"spf":1.0,"id":28791281},{"atb":[[1.12,30],[2.06,8.61]],"id":35676762},{"spl":[[1.01,10],[21,1],[14,10]],"id":35676762},{"atl":[[550,3],[44,0.1]],"id":35676762},{"spn":1.92,"spf":1.0,"id":35676762},{"atb":[[1.12,30],[2.06,9.47]],"id":41529439},{"spl":[[10,10],[21,1]],"id":41529439},{"atl":[[44,0.1],[370,3]],"id":41529439},{"spn":6.03,"spf":1.0,"id":41529439},{"atb":[[1.12,30],[2.1,13.16]],"id":39213014},{"spl":[[8.6,10],[21,1]],"id":39213014},{"atl":[[270,3],[44,0.1]],"id":39213014},{"spn":5.35,"spf":1.0,"id":39213014}],"con":true,"img":true}]}
{"op":"mcm","clk":"5321039298","pt":1646305449078,"mc":[{"id":"1.195532866","marketDefinition":{"bspMarket":true,"turnInPlayEnabled":false,"persistenceEnabled":false,"marketBaseRate":5.0,"eventId":"31275720","eventTypeId":"4339","numberOfWinners":1,"bettingType":"ODDS","marketType":"WIN","marketTime":"2022-03-03T16:08:00.000Z","suspendTime":"2022-03-03T16:08:00.000Z","bspReconciled":false,"complete":true,"inPlay":false,"crossMatching":false,"runnersVoidable":false,"numberOfActiveRunners":6,"betDelay":0,"status":"OPEN","runners":[{"status":"ACTIVE","sortPriority":1,"id":41529439,"name":"1. Puttfor Daisy"},{"status":"ACTIVE","sortPriority":2,"id":26648132,"name":"2. Trapstyle Brae"},{"status":"ACTIVE","sortPriority":3,"id":35676762,"name":"3. Seven Of Nine"},{"status":"ACTIVE","sortPriority":4,"id":39213014,"name":"4. Watford Lad"},{"status":"ACTIVE","sortPriority":5,"id":43094640,"name":"5. Droopys Solution"},{"status":"ACTIVE","sortPriority":6,"id":28791281,"name":"6. Our Bill"}],"regulators":["MR_INT"],"venue":"Romford","countryCode":"GB","discountAllowed":true,"timezone":"Europe/London","openDate":"2022-03-03T13:57:00.000Z","version":4384107306,"name":"A2 400m","eventName":"Romford 3rd Mar"},"rc":[{"atb":[[1.12,30],[2.04,12.79]],"id":26648132},{"spl":[[21,1]],"id":26648132},{"atl":[[390,3]],"id":26648132},{"spn":11.52,"spf":1.0,"id":26648132},{"atb":[[1.12,30],[2.04,11.94]],"id":43094640},{"spl":[[4,10],[21,1]],"id":43094640},{"atl":[[560,3]],"id":43094640},{"spn":3.02,"spf":1.0,"id":43094640},{"atb":[[2,10.04],[1.14,30]],"id":28791281},{"spl":[[21,1],[28,10]],"id":28791281},{"atl":[[44,0.1],[500,3]],"id":28791281},{"spn":11.5,"spf":1.0,"id":28791281},{"atb":[[1.12,30],[2.06,8.61]],"id":35676762},{"spl":[[1.01,10],[21,1],[14,10]],"id":35676762},{"atl":[[550,3],[44,0.1]],"id":35676762},{"spn":1.92,"spf":1.0,"id":35676762},{"atb":[[1.12,30],[2.06,9.47]],"id":41529439},{"spl":[[10,10],[21,1]],"id":41529439},{"atl":[[44,0.1],[370,3]],"id":41529439},{"spn":6.03,"spf":1.0,"id":41529439},{"atb":[[1.12,30],[2.1,13.17]],"id":39213014},{"spl":[[8.6,10],[21,1]],"id":39213014},{"atl":[[270,3],[44,0.1]],"id":39213014},{"spn":5.35,"spf":1.0,"id":39213014}],"con":true,"img":true}]}
{"op":"mcm","clk":"5321068890","pt":1646305769525,"mc":[{"id":"1.195532866","rc":[{"atb":[[2.04,12.79],[5.9,2]],"id":26648132},{"spn":13.45,"spf":1.0,"id":26648132},{"atb":[[5.5,2],[2.04,11.94]],"id":43094640},{"spn":4.0,"spf":1.0,"id":43094640},{"atb":[[2,10.04],[3.9,2]],"id":28791281},{"spn":12.45,"spf":1.0,"id":28791281},{"atb":[[2.06,8.61],[10,2]],"id":35676762},{"spn":3.64,"spf":1.0,"id":35676762},{"atb":[[2.06,9.47],[4.6,2]],"id":41529439},{"spn":7.3,"spf":1.0,"id":41529439},{"atb":[[4.6,2],[2.1,13.17]],"id":39213014},{"spn":6.6,"spf":1.0,"id":39213014}],"con":true,"img":false}]}
{"op":"mcm","clk":"5321070951","pt":1646305800253,"mc":[{"id":"1.195532866","marketDefinition":{"bspMarket":true,"turnInPlayEnabled":false,"persistenceEnabled":false,"marketBaseRate":5.0,"eventId":"31275720","eventTypeId":"4339","numberOfWinners":1,"bettingType":"ODDS","marketType":"WIN","marketTime":"2022-03-03T16:08:00.000Z","suspendTime":"2022-03-03T16:08:00.000Z","bspReconciled":false,"complete":true,"inPlay":false,"crossMatching":true,"runnersVoidable":false,"numberOfActiveRunners":6,"betDelay":0,"status":"OPEN","runners":[{"status":"ACTIVE","sortPriority":1,"id":41529439,"name":"1. Puttfor Daisy"},{"status":"ACTIVE","sortPriority":2,"id":26648132,"name":"2. Trapstyle Brae"},{"status":"ACTIVE","sortPriority":3,"id":35676762,"name":"3. Seven Of Nine"},{"status":"ACTIVE","sortPriority":4,"id":39213014,"name":"4. Watford Lad"},{"status":"ACTIVE","sortPriority":5,"id":43094640,"name":"5. Droopys Solution"},{"status":"ACTIVE","sortPriority":6,"id":28791281,"name":"6. Our Bill"}],"regulators":["MR_INT"],"venue":"Romford","countryCode":"GB","discountAllowed":true,"timezone":"Europe/London","openDate":"2022-03-03T13:57:00.000Z","version":4384107306,"name":"A2 400m","eventName":"Romford 3rd Mar"},"rc":[],"con":true,"img":false}]}
{"op":"mcm","clk":"5321097181","pt":1646306132838,"mc":[{"id":"1.195532866","rc":[{"atb":[[5.1,2]],"id":26648132},{"atl":[[10.5,1.06]],"id":26648132},{"spn":8.2,"spf":1.0,"id":26648132},{"atb":[[4.6,2]],"id":43094640},{"atl":[[9.2,1.23]],"id":43094640},{"atb":[[3.55,2]],"id":28791281},{"atl":[[6.2,1.93]],"id":28791281},{"spn":5.05,"spf":1.0,"id":28791281},{"atb":[[9.2,1.23]],"id":35676762},{"atl":[[27,0.39]],"id":35676762},{"spn":4.52,"spf":1.0,"id":35676762},{"atb":[[4.1,2]],"id":41529439},{"atl":[[7.8,1.48]],"id":41529439},{"spn":6.2,"spf":1.0,"id":41529439},{"atb":[[4.1,2]],"id":39213014},{"atl":[[7.8,1.48]],"id":39213014},{"spn":6.2,"spf":1.0,"id":39213014}],"con":true,"img":false}]}
{"op":"mcm","clk":"5321611050","pt":1646311524848,"mc":[{"id":"1.195532866","rc":[{"atb":[[1.01,1000]],"id":26648132},{"atb":[[1.01,1000]],"id":43094640},{"atb":[[1.01,1000]],"id":28791281},{"atb":[[1.01,1000]],"id":35676762},{"atb":[[1.01,1000]],"id":41529439},{"atb":[[1.01,1000]],"id":39213014}],"con":true,"img":false}]}
{"op":"mcm","clk":"5321651704","pt":1646311904331,"mc":[{"id":"1.195532866","rc":[{"atl":[[1000,2]],"id":41529439}],"con":true,"img":false}]}
{"op":"mcm","clk":"5321651827","pt":1646311905625,"mc":[{"id":"1.195532866","rc":[{"atl":[[1000,2.2]],"id":41529439}],"con":true,"img":false}]}
{"op":"mcm","clk":"5321651944","pt":1646311906969,"mc":[{"id":"1.195532866","rc":[{"atl":[[1000,2]],"id":41529439}],"con":true,"img":false}]}
{"op":"mcm","clk":"5321651954","pt":1646311907027,"mc":[{"id":"1.195532866","rc":[{"atl":[[10.5,0.2]],"id":41529439}],"con":true,"img":false}]}
{"op":"mcm","clk":"5321652052","pt":1646311908365,"mc":[{"id":"1.195532866","rc":[{"atl":[[1000,2]],"id":26648132}],"con":true,"img":false}]}
{"op":"mcm","clk":"5321652172","pt":1646311909652,"mc":[{"id":"1.195532866","rc":[{"atl":[[1000,2.2]],"id":26648132}],"con":true,"img":false}]}
{"op":"mcm","clk":"5321652269","pt":1646311910947,"mc":[{"id":"1.195532866","rc":[{"atl":[[1000,2]],"id":26648132}],"con":true,"img":false}]}
{"op":"mcm","clk":"5321652277","pt":1646311911041,"mc":[{"id":"1.195532866","rc":[{"atl":[[13.5,0.2]],"id":26648132}],"con":true,"img":false}]}
{"op":"mcm","clk":"5321652394","pt":1646311912333,"mc":[{"id":"1.195532866","rc":[{"atl":[[1000,2]],"id":35676762}],"con":true,"img":false}]}
{"op":"mcm","clk":"5321652528","pt":1646311913678,"mc":[{"id":"1.195532866","rc":[{"atl":[[1000,2.2]],"id":35676762}],"con":true,"img":false}]}
{"op":"mcm","clk":"5321653095","pt":1646311919259,"mc":[{"id":"1.195532866","rc":[{"atl":[[1000,2]],"id":35676762}],"con":true,"img":false}]}
{"op":"mcm","clk":"5321653109","pt":1646311919368,"mc":[{"id":"1.195532866","rc":[{"atl":[[26,0.2]],"id":35676762}],"con":true,"img":false}]}
{"op":"mcm","clk":"5321653232","pt":1646311920658,"mc":[{"id":"1.195532866","rc":[{"atl":[[1000,2]],"id":39213014}],"con":true,"img":false}]}
{"op":"mcm","clk":"5321653377","pt":1646311921959,"mc":[{"id":"1.195532866","rc":[{"atl":[[1000,2.2]],"id":39213014}],"con":true,"img":false}]}
{"op":"mcm","clk":"5321653548","pt":1646311923268,"mc":[{"id":"1.195532866","rc":[{"atl":[[1000,2]],"id":39213014}],"con":true,"img":false}]}
{"op":"mcm","clk":"5321653562","pt":1646311923369,"mc":[{"id":"1.195532866","rc":[{"atl":[[10.5,0.2]],"id":39213014}],"con":true,"img":false}]}
{"op":"mcm","clk":"5321653709","pt":1646311924666,"mc":[{"id":"1.195532866","rc":[{"atl":[[1000,2]],"id":43094640}],"con":true,"img":false}]}
{"op":"mcm","clk":"5321653862","pt":1646311925973,"mc":[{"id":"1.195532866","rc":[{"atl":[[1000,2.2]],"id":43094640}],"con":true,"img":false}]}
{"op":"mcm","clk":"5321654019","pt":1646311927269,"mc":[{"id":"1.195532866","rc":[{"atl":[[1000,2]],"id":43094640}],"con":true,"img":false}]}
{"op":"mcm","clk":"5321654028","pt":1646311927370,"mc":[{"id":"1.195532866","rc":[{"atl":[[13.5,0.2]],"id":43094640}],"con":true,"img":false}]}
{"op":"mcm","clk":"5321654237","pt":1646311928765,"mc":[{"id":"1.195532866","rc":[{"atl":[[1000,2]],"id":28791281}],"con":true,"img":false}]}
{"op":"mcm","clk":"5321654453","pt":1646311930066,"mc":[{"id":"1.195532866","rc":[{"atl":[[1000,2.2]],"id":28791281}],"con":true,"img":false}]}
{"op":"mcm","clk":"5321654656","pt":1646311931367,"mc":[{"id":"1.195532866","rc":[{"atl":[[1000,2]],"id":28791281}],"con":true,"img":false}]}
{"op":"mcm","clk":"5321654672","pt":1646311931473,"mc":[{"id":"1.195532866","rc":[{"atl":[[8.8,0.2]],"id":28791281}],"con":true,"img":false}]}
{"op":"mcm","clk":"5321699620","pt":1646312395296,"mc":[{"id":"1.195532866","rc":[{"atl":[[4,2]],"id":28791281},{"spn":3.95,"spf":1.0,"id":28791281}],"con":true,"img":false}]}
{"op":"mcm","clk":"5321701895","pt":1646312415797,"mc":[{"id":"1.195532866","rc":[{"atb":[[2.04,12.79]],"id":26648132},{"atb":[[2.04,11.93]],"id":43094640},{"atb":[[2,10.03]],"id":28791281},{"atl":[[4,0]],"id":28791281},{"atb":[[2.06,8.61]],"id":35676762},{"atb":[[2.06,9.47]],"id":41529439},{"atb":[[2.1,13.16]],"id":39213014}],"con":true,"img":false}]}
{"op":"mcm","clk":"5321701902","pt":1646312415902,"mc":[{"id":"1.195532866","rc":[{"atb":[[3.9,0]],"id":28791281},{"trd":[[3.9,4]],"ltp":3.9,"tv":4.0,"id":28791281}],"con":true,"img":false}]}
{"op":"mcm","clk":"5321702161","pt":1646312418483,"mc":[{"id":"1.195532866","rc":[{"atb":[[2.32,8.49]],"id":26648132},{"atb":[[2.16,9.66]],"id":41529439}],"con":true,"img":false}]}
{"op":"mcm","clk":"5321702169","pt":1646312418585,"mc":[{"id":"1.195532866","rc":[{"atb":[[2.68,6.67]],"id":35676762}],"con":true,"img":false}]}
{"op":"mcm","clk":"5321702176","pt":1646312418687,"mc":[{"id":"1.195532866","rc":[{"atb":[[2.16,9.66]],"id":39213014}],"con":true,"img":false}]}
{"op":"mcm","clk":"5321702188","pt":1646312418796,"mc":[{"id":"1.195532866","rc":[{"atb":[[2.26,8.89]],"id":43094640}],"con":true,"img":false}]}
{"op":"mcm","clk":"5321702196","pt":1646312418899,"mc":[{"id":"1.195532866","rc":[{"atb":[[2.04,10.78]],"id":28791281}],"con":true,"img":false}]}
{"op":"mcm","clk":"5321703274","pt":1646312430388,"mc":[{"id":"1.195532866","rc":[{"atb":[[2.72,7.21]],"id":35676762}],"con":true,"img":false}]}
{"op":"mcm","clk":"5321703316","pt":1646312430903,"mc":[{"id":"1.195532866","rc":[{"atb":[[2.08,11.5]],"id":28791281}],"con":true,"img":false}]}
{"op":"mcm","clk":"5321703325","pt":1646312431008,"mc":[{"id":"1.195532866","rc":[{"atb":[[2.36,9.13]],"id":26648132}],"con":true,"img":false}]}
{"op":"mcm","clk":"5321703334","pt":1646312431112,"mc":[{"id":"1.195532866","rc":[{"atb":[[2.2,10.34]],"id":41529439}],"con":true,"img":false}]}
{"op":"mcm","clk":"5321703351","pt":1646312431318,"mc":[{"id":"1.195532866","rc":[{"atb":[[2.2,10.34]],"id":39213014}],"con":true,"img":false}]}
{"op":"mcm","clk":"5321703374","pt":1646312431578,"mc":[{"id":"1.195532866","rc":[{"atb":[[2.3,9.55]],"id":43094640}],"con":true,"img":false}]}
{"op":"mcm","clk":"5321718471","pt":1646312598427,"mc":[{"id":"1.195532866","rc":[{"atb":[[2.04,0]],"id":26648132},{"atb":[[2.04,0]],"id":43094640},{"atb":[[2,0]],"id":28791281},{"spn":4.87,"spf":1.0,"id":28791281},{"spn":4.97,"spf":1.0,"id":35676762},{"atb":[[2.06,0]],"id":41529439},{"atb":[[2.1,0]],"id":39213014}],"con":true,"img":false}]}
{"op":"mcm","clk":"5321718481","pt":1646312598531,"mc":[{"id":"1.195532866","rc":[{"atb":[[2.34,12.79]],"id":26648132},{"atb":[[2.32,11.93]],"id":43094640},{"atb":[[2.1,10.03]],"id":28791281},{"atb":[[2.22,9.47]],"id":41529439},{"atb":[[2.22,13.16]],"id":39213014}],"con":true,"img":false}]}
{"op":"mcm","clk":"5321724889","pt":1646312664557,"mc":[{"id":"1.195532866","rc":[{"atb":[[2.32,0]],"id":26648132},{"atb":[[2.26,0]],"id":43094640},{"atb":[[2.04,0]],"id":28791281},{"atb":[[2.68,0]],"id":35676762},{"atb":[[2.16,0]],"id":41529439},{"atb":[[2.16,0]],"id":39213014}],"con":true,"img":false}]}
{"op":"mcm","clk":"5321725178","pt":1646312667559,"mc":[{"id":"1.195532866","rc":[{"atb":[[2.14,9.83]],"id":28791281}],"con":true,"img":false}]}
{"op":"mcm","clk":"5321725190","pt":1646312667662,"mc":[{"id":"1.195532866","rc":[{"atb":[[2.76,6.36]],"id":35676762}],"con":true,"img":false}]}
{"op":"mcm","clk":"5321725204","pt":1646312667765,"mc":[{"id":"1.195532866","rc":[{"atb":[[2.26,8.89]],"id":39213014}],"con":true,"img":false}]}
{"op":"mcm","clk":"5321725215","pt":1646312667827,"mc":[{"id":"1.195532866","rc":[{"atb":[[2.26,8.89]],"id":41529439}],"con":true,"img":false}]}
{"op":"mcm","clk":"5321725225","pt":1646312667929,"mc":[{"id":"1.195532866","rc":[{"atb":[[2.4,8]],"id":26648132},{"atb":[[2.36,8.24]],"id":43094640}],"con":true,"img":false}]}
{"op":"mcm","clk":"5321744879","pt":1646312847134,"mc":[{"id":"1.195532866","rc":[{"atb":[[2.36,0]],"id":26648132},{"atb":[[2.3,0]],"id":43094640},{"atb":[[2.08,0]],"id":28791281},{"spn":4.99,"spf":1.0,"id":35676762},{"atb":[[2.2,0]],"id":41529439},{"atb":[[2.2,0]],"id":39213014}],"con":true,"img":false}]}
{"op":"mcm","clk":"5321746966","pt":1646312861513,"mc":[{"id":"1.195532866","rc":[{"atb":[[2.3,9.55]],"id":39213014}],"con":true,"img":false}]}
{"op":"mcm","clk":"5321747005","pt":1646312861671,"mc":[{"id":"1.195532866","rc":[{"atb":[[2.44,8.62]],"id":26648132}],"con":true,"img":false}]}
{"op":"mcm","clk":"5321747038","pt":1646312861777,"mc":[{"id":"1.195532866","rc":[{"atb":[[2.3,9.55]],"id":41529439}],"con":true,"img":false}]}
{"op":"mcm","clk":"5321747053","pt":1646312861877,"mc":[{"id":"1.195532866","rc":[{"atb":[[2.4,8.86]],"id":43094640}],"con":true,"img":false}]}
{"op":"mcm","clk":"5321747116","pt":1646312862161,"mc":[{"id":"1.195532866","rc":[{"atb":[[2.18,10.52]],"id":28791281}],"con":true,"img":false}]}
{"op":"mcm","clk":"5321750952","pt":1646312898111,"mc":[{"id":"1.195532866","rc":[{"atb":[[2.1,0]],"id":28791281},{"atb":[[2.22,0]],"id":41529439},{"atb":[[2.22,0]],"id":39213014}],"con":true,"img":false}]}
{"op":"mcm","clk":"5321750969","pt":1646312898213,"mc":[{"id":"1.195532866","rc":[{"atb":[[2.2,10.03]],"id":28791281},{"atb":[[2.32,9.47]],"id":41529439},{"atb":[[2.32,13.16]],"id":39213014}],"con":true,"img":false}]}
{"op":"mcm","clk":"5321752182","pt":1646312908026,"mc":[{"id":"1.195532866","rc":[{"atb":[[2.72,0]],"id":35676762},{"spn":4.97,"spf":1.0,"id":35676762}],"con":true,"img":false}]}
{"op":"mcm","clk":"5321753989","pt":1646312922972,"mc":[{"id":"1.195532866","rc":[{"atb":[[2.8,6.89]],"id":35676762}],"con":true,"img":false}]}
{"op":"mcm","clk":"5321772898","pt":1646313080218,"mc":[{"id":"1.195532866","rc":[{"atb":[[2.4,0]],"id":26648132},{"spn":5.02,"spf":1.0,"id":35676762}],"con":true,"img":false}]}
{"op":"mcm","clk":"5321773166","pt":1646313083241,"mc":[{"id":"1.195532866","rc":[{"atb":[[2.48,7.58]],"id":26648132}],"con":true,"img":false}]}
{"op":"mcm","clk":"5321774309","pt":1646313095387,"mc":[{"id":"1.195532866","rc":[{"atb":[[2.36,0]],"id":43094640},{"atb":[[2.14,0]],"id":28791281},{"atb":[[2.26,0]],"id":41529439},{"atb":[[2.26,0]],"id":39213014}],"con":true,"img":false}]}
{"op":"mcm","clk":"5321774605","pt":1646313098452,"mc":[{"id":"1.195532866","rc":[{"atb":[[2.24,9.04]],"id":28791281}],"con":true,"img":false}]}
{"op":"mcm","clk":"5321774619","pt":1646313098556,"mc":[{"id":"1.195532866","rc":[{"atb":[[2.36,8.24]],"id":39213014}],"con":true,"img":false}]}
{"op":"mcm","clk":"5321774630","pt":1646313098661,"mc":[{"id":"1.195532866","rc":[{"atb":[[2.44,7.79]],"id":43094640}],"con":true,"img":false}]}
{"op":"mcm","clk":"5321774643","pt":1646313098764,"mc":[{"id":"1.195532866","rc":[{"atb":[[2.36,8.24]],"id":41529439}],"con":true,"img":false}]}
{"op":"mcm","clk":"5321780532","pt":1646313139532,"mc":[{"id":"1.195532866","rc":[{"atb":[[2.18,0]],"id":28791281},{"atb":[[2.3,0]],"id":41529439},{"atb":[[2.3,0]],"id":39213014}],"con":true,"img":false}]}
{"op":"mcm","clk":"5321780926","pt":1646313143250,"mc":[{"id":"1.195532866","rc":[{"atb":[[2.76,0]],"id":35676762}],"con":true,"img":false}]}
{"op":"mcm","clk":"5321781348","pt":1646313147210,"mc":[{"id":"1.195532866","rc":[{"atb":[[2.84,6.09]],"id":35676762}],"con":true,"img":false}]}
{"op":"mcm","clk":"5321782084","pt":1646313154769,"mc":[{"id":"1.195532866","rc":[{"atb":[[2.4,8.86]],"id":39213014}],"con":true,"img":false}]}
{"op":"mcm","clk":"5321782115","pt":1646313155033,"mc":[{"id":"1.195532866","rc":[{"atb":[[2.4,8.86]],"id":41529439}],"con":true,"img":false}]}
{"op":"mcm","clk":"5321782132","pt":1646313155241,"mc":[{"id":"1.195532866","rc":[{"atb":[[2.28,9.7]],"id":28791281}],"con":true,"img":false}]}
{"op":"mcm","clk":"5321786343","pt":1646313198227,"mc":[{"id":"1.195532866","rc":[{"atb":[[2.2,0]],"id":28791281}],"con":true,"img":false}]}
{"op":"mcm","clk":"5321786352","pt":1646313198330,"mc":[{"id":"1.195532866","rc":[{"atb":[[2.3,10.03]],"id":28791281}],"con":true,"img":false}]}
{"op":"mcm","clk":"5321799503","pt":1646313327337,"mc":[{"id":"1.195532866","rc":[{"atb":[[2.44,0]],"id":26648132},{"spn":5.05,"spf":1.0,"id":35676762}],"con":true,"img":false}]}
{"op":"mcm","clk":"5321800531","pt":1646313338849,"mc":[{"id":"1.195532866","rc":[{"atb":[[2.52,8.17]],"id":26648132}],"con":true,"img":false}]}
{"op":"mcm","clk":"5321801918","pt":1646313353564,"mc":[{"id":"1.195532866","rc":[{"atb":[[2.4,0]],"id":43094640}],"con":true,"img":false}]}
{"op":"mcm","clk":"5321803917","pt":1646313368972,"mc":[{"id":"1.195532866","rc":[{"atb":[[2.48,8.39]],"id":43094640}],"con":true,"img":false}]}
{"op":"mcm","clk":"5321805689","pt":1646313386634,"mc":[{"id":"1.195532866","rc":[{"atb":[[2.24,0]],"id":28791281},{"atb":[[2.36,0]],"id":41529439},{"atb":[[2.36,0]],"id":39213014}],"con":true,"img":false}]}
{"op":"mcm","clk":"5321805984","pt":1646313389695,"mc":[{"id":"1.195532866","rc":[{"atb":[[2.34,8.36]],"id":28791281},{"atb":[[2.44,7.79]],"id":39213014}],"con":true,"img":false}]}
{"op":"mcm","clk":"5321805995","pt":1646313389796,"mc":[{"id":"1.195532866","rc":[{"atb":[[2.44,7.79]],"id":41529439}],"con":true,"img":false}]}
{"op":"mcm","clk":"5321806937","pt":1646313399647,"mc":[{"id":"1.195532866","rc":[{"atb":[[2.8,0]],"id":35676762}],"con":true,"img":false}]}
{"op":"mcm","clk":"5321816909","pt":1646313415651,"mc":[{"id":"1.195532866","rc":[{"atb":[[2.88,6.6]],"id":35676762}],"con":true,"img":false}]}
{"op":"mcm","clk":"5321819606","pt":1646313444581,"mc":[{"id":"1.195532866","rc":[{"atb":[[2.28,0]],"id":28791281}],"con":true,"img":false}]}
{"op":"mcm","clk":"5321820675","pt":1646313456191,"mc":[{"id":"1.195532866","rc":[{"atb":[[2.38,8.99]],"id":28791281},{"spn":5.08,"spf":1.0,"id":35676762}],"con":true,"img":false}]}
{"op":"mcm","clk":"5321824634","pt":1646313498648,"mc":[{"id":"1.195532866","rc":[{"atb":[[2.3,0]],"id":28791281}],"con":true,"img":false}]}
{"op":"mcm","clk":"5321824647","pt":1646313498752,"mc":[{"id":"1.195532866","rc":[{"atb":[[2.36,10.03]],"id":28791281}],"con":true,"img":false}]}
{"op":"mcm","clk":"5321830720","pt":1646313562541,"mc":[{"id":"1.195532866","rc":[{"atb":[[2.48,0]],"id":26648132}],"con":true,"img":false}]}
{"op":"mcm","clk":"5321831203","pt":1646313567159,"mc":[{"id":"1.195532866","rc":[{"atb":[[2.56,7.19]],"id":26648132}],"con":true,"img":false}]}
{"op":"mcm","clk":"5321833491","pt":1646313588286,"mc":[{"id":"1.195532866","rc":[{"atb":[[2.44,0]],"id":43094640}],"con":true,"img":false}]}
{"op":"mcm","clk":"5321833836","pt":1646313591309,"mc":[{"id":"1.195532866","rc":[{"atb":[[2.52,7.37]],"id":43094640}],"con":true,"img":false}]}
{"op":"mcm","clk":"5321838519","pt":1646313633782,"mc":[{"id":"1.195532866","rc":[{"atb":[[2.84,0]],"id":35676762},{"spn":5.06,"spf":1.0,"id":35676762}],"con":true,"img":false}]}
{"op":"mcm","clk":"5321838816","pt":1646313636364,"mc":[{"id":"1.195532866","rc":[{"atb":[[2.92,5.83]],"id":35676762}],"con":true,"img":false}]}
{"op":"mcm","clk":"5321839215","pt":1646313639702,"mc":[{"id":"1.195532866","rc":[{"atb":[[2.4,0]],"id":41529439},{"atb":[[2.4,0]],"id":39213014}],"con":true,"img":false}]}
{"op":"mcm","clk":"5321840824","pt":1646313654920,"mc":[{"id":"1.195532866","rc":[{"atb":[[2.48,8.39]],"id":41529439}],"con":true,"img":false}]}
{"op":"mcm","clk":"5321840940","pt":1646313655812,"mc":[{"id":"1.195532866","rc":[{"atb":[[2.48,8.39]],"id":39213014}],"con":true,"img":false}]}
{"op":"mcm","clk":"5321844647","pt":1646313690752,"mc":[{"id":"1.195532866","rc":[{"atb":[[2.34,0]],"id":28791281}],"con":true,"img":false}]}
{"op":"mcm","clk":"5321844908","pt":1646313693538,"mc":[{"id":"1.195532866","rc":[{"atb":[[2.42,7.89]],"id":28791281}],"con":true,"img":false}]}
{"op":"mcm","clk":"5321849634","pt":1646313739705,"mc":[{"id":"1.195532866","rc":[{"atb":[[2.38,0]],"id":28791281},{"spn":5.1,"spf":1.0,"id":35676762}],"con":true,"img":false}]}
{"op":"mcm","clk":"5321851535","pt":1646313757800,"mc":[{"id":"1.195532866","rc":[{"atb":[[2.46,8.5]],"id":28791281}],"con":true,"img":false}]}
{"op":"mcm","clk":"5321856300","pt":1646313807264,"mc":[{"id":"1.195532866","rc":[{"atb":[[2.52,0]],"id":26648132}],"con":true,"img":false}]}
{"op":"mcm","clk":"5321857711","pt":1646313820466,"mc":[{"id":"1.195532866","rc":[{"atb":[[2.6,7.76]],"id":26648132}],"con":true,"img":false}]}
{"op":"mcm","clk":"5321859669","pt":1646313837489,"mc":[{"id":"1.195532866","rc":[{"atb":[[2.48,0]],"id":43094640}],"con":true,"img":false}]}
{"op":"mcm","clk":"5321860996","pt":1646313851014,"mc":[{"id":"1.195532866","rc":[{"atb":[[2.56,7.96]],"id":43094640}],"con":true,"img":false}]}
{"op":"mcm","clk":"5321862843","pt":1646313874247,"mc":[{"id":"1.195532866","rc":[{"atb":[[2.44,0]],"id":41529439},{"atb":[[2.44,0]],"id":39213014}],"con":true,"img":false}]}
{"op":"mcm","clk":"5321862988","pt":1646313876673,"mc":[{"id":"1.195532866","rc":[{"atb":[[2.52,7.37]],"id":41529439},{"atb":[[2.52,7.37]],"id":39213014}],"con":true,"img":false}]}
{"op":"mcm","clk":"5321863286","pt":1646313880960,"mc":[{"id":"1.195532866","rc":[{"atb":[[2.88,0]],"id":35676762}],"con":true,"img":false}]}
{"op":"mcm","clk":"5321863331","pt":1646313881582,"mc":[{"id":"1.195532866","rc":[{"atl":[[1000,2.3]],"id":28791281}],"con":true,"img":false}]}
{"op":"mcm","clk":"5321863348","pt":1646313881788,"mc":[{"id":"1.195532866","rc":[{"atl":[[1000,2]],"id":28791281}],"con":true,"img":false}]}
{"op":"mcm","clk":"5321863357","pt":1646313881843,"mc":[{"id":"1.195532866","rc":[{"atb":[[3.55,1.7]],"id":28791281},{"trd":[[3.55,0.6]],"ltp":3.55,"tv":0.6,"id":28791281}],"con":true,"img":false}]}
{"op":"mcm","clk":"5321864402","pt":1646313895771,"mc":[{"id":"1.195532866","rc":[{"atb":[[2.96,6.33]],"id":35676762}],"con":true,"img":false}]}
{"op":"mcm","clk":"5321871697","pt":1646313976604,"mc":[{"id":"1.195532866","rc":[{"atb":[[2.42,0]],"id":28791281},{"spn":5.13,"spf":1.0,"id":35676762}],"con":true,"img":false}]}
{"op":"mcm","clk":"5321872157","pt":1646313982732,"mc":[{"id":"1.195532866","rc":[{"atb":[[2.5,7.47]],"id":28791281}],"con":true,"img":false}]}
{"op":"mcm","clk":"5321876802","pt":1646314042613,"mc":[{"id":"1.195532866","rc":[{"atb":[[2.56,0]],"id":26648132}],"con":true,"img":false}]}
{"op":"mcm","clk":"5321876998","pt":1646314045206,"mc":[{"id":"1.195532866","rc":[{"atb":[[2.64,6.84]],"id":26648132}],"con":true,"img":false}]}
{"op":"mcm","clk":"5321879206","pt":1646314072741,"mc":[{"id":"1.195532866","rc":[{"atb":[[2.52,0]],"id":43094640}],"con":true,"img":false}]}
{"op":"mcm","clk":"5321879450","pt":1646314075406,"mc":[{"id":"1.195532866","rc":[{"atb":[[2.6,7.01]],"id":43094640}],"con":true,"img":false}]}
{"op":"mcm","clk":"5321882724","pt":1646314114660,"mc":[{"id":"1.195532866","rc":[{"atb":[[2.92,0]],"id":35676762},{"spn":5.09,"spf":1.0,"id":35676762}],"con":true,"img":false}]}
{"op":"mcm","clk":"5321882921","pt":1646314117372,"mc":[{"id":"1.195532866","rc":[{"atb":[[3,5.6]],"id":35676762}],"con":true,"img":false}]}
{"op":"mcm","clk":"5321888881","pt":1646314190117,"mc":[{"id":"1.195532866","rc":[{"spn":5.15,"spf":1.0,"id":35676762},{"atb":[[2.48,0]],"id":41529439},{"atb":[[2.48,0]],"id":39213014}],"con":true,"img":false}]}
{"op":"mcm","clk":"5321890580","pt":1646314209210,"mc":[{"id":"1.195532866","rc":[{"atb":[[2.56,7.96]],"id":41529439}],"con":true,"img":false}]}
{"op":"mcm","clk":"5321890618","pt":1646314209627,"mc":[{"id":"1.195532866","rc":[{"atb":[[2.56,7.96]],"id":39213014}],"con":true,"img":false}]}
{"op":"mcm","clk":"5321892032","pt":1646314226067,"mc":[{"id":"1.195532866","rc":[{"atb":[[2.46,0]],"id":28791281}],"con":true,"img":false}]}
{"op":"mcm","clk":"5321893482","pt":1646314242004,"mc":[{"id":"1.195532866","rc":[{"atb":[[2.54,8.06]],"id":28791281}],"con":true,"img":false}]}
{"op":"mcm","clk":"5321906491","pt":1646314404620,"mc":[{"id":"1.195532866","rc":[{"atb":[[2.6,0]],"id":26648132},{"atb":[[2.56,0]],"id":43094640}],"con":true,"img":false}]}
{"op":"mcm","clk":"5321908222","pt":1646314424818,"mc":[{"id":"1.195532866","rc":[{"atb":[[2.52,0]],"id":41529439},{"atb":[[2.52,0]],"id":39213014}],"con":true,"img":false}]}
{"op":"mcm","clk":"5321908403","pt":1646314426729,"mc":[{"id":"1.195532866","rc":[{"atb":[[2.64,7.57]],"id":43094640}],"con":true,"img":false}]}
{"op":"mcm","clk":"5321908433","pt":1646314427045,"mc":[{"id":"1.195532866","rc":[{"atb":[[2.68,7.39]],"id":26648132}],"con":true,"img":false}]}
{"op":"mcm","clk":"5321908506","pt":1646314427719,"mc":[{"id":"1.195532866","rc":[{"atb":[[2.96,0]],"id":35676762}],"con":true,"img":false}]}
{"op":"mcm","clk":"5321908514","pt":1646314427824,"mc":[{"id":"1.195532866","rc":[{"atb":[[2.6,7.01]],"id":41529439}],"con":true,"img":false}]}
{"op":"mcm","clk":"5321908544","pt":1646314428129,"mc":[{"id":"1.195532866","rc":[{"atb":[[2.6,7.01]],"id":39213014}],"con":true,"img":false}]}
{"op":"mcm","clk":"5321910406","pt":1646314449679,"mc":[{"id":"1.195532866","rc":[{"atb":[[3.1,5.91]],"id":35676762}],"con":true,"img":false}]}
{"op":"mcm","clk":"5321910414","pt":1646314449732,"mc":[{"id":"1.195532866","rc":[{"atb":[[2.56,0]],"id":41529439},{"atb":[[2.56,0]],"id":39213014}],"con":true,"img":false}]}
{"op":"mcm","clk":"5321911376","pt":1646314460765,"mc":[{"id":"1.195532866","rc":[{"atb":[[2.5,0]],"id":28791281}],"con":true,"img":false}]}
{"op":"mcm","clk":"5321911684","pt":1646314464470,"mc":[{"id":"1.195532866","rc":[{"atb":[[2.58,7.09]],"id":28791281}],"con":true,"img":false}]}
{"op":"mcm","clk":"5321911895","pt":1646314466652,"mc":[{"id":"1.195532866","rc":[{"spn":5.22,"spf":1.0,"id":35676762},{"atb":[[2.64,7.57]],"id":41529439},{"atb":[[2.64,7.57]],"id":39213014}],"con":true,"img":false}]}
{"op":"mcm","clk":"5321930368","pt":1646314641250,"mc":[{"id":"1.195532866","rc":[{"atb":[[2.64,0]],"id":26648132},{"atb":[[2.6,0]],"id":43094640}],"con":true,"img":false}]}
{"op":"mcm","clk":"5321930839","pt":1646314645322,"mc":[{"id":"1.195532866","rc":[{"atb":[[2.72,6.51]],"id":26648132}],"con":true,"img":false}]}
{"op":"mcm","clk":"5321930852","pt":1646314645426,"mc":[{"id":"1.195532866","rc":[{"atb":[[2.68,6.67]],"id":43094640}],"con":true,"img":false}]}
{"op":"mcm","clk":"5321932772","pt":1646314663072,"mc":[{"id":"1.195532866","rc":[{"atb":[[3,0]],"id":35676762}],"con":true,"img":false}]}
{"op":"mcm","clk":"5321933095","pt":1646314665835,"mc":[{"id":"1.195532866","rc":[{"atb":[[3.2,5.09]],"id":35676762}],"con":true,"img":false}]}
{"op":"mcm","clk":"5321935347","pt":1646314684434,"mc":[{"id":"1.195532866","rc":[{"atb":[[2.6,0]],"id":41529439},{"atb":[[2.6,0]],"id":39213014}],"con":true,"img":false}]}
{"op":"mcm","clk":"5321935916","pt":1646314689822,"mc":[{"id":"1.195532866","rc":[{"atb":[[2.68,6.67]],"id":41529439},{"atb":[[2.68,6.67]],"id":39213014}],"con":true,"img":false}]}
{"op":"mcm","clk":"5321937690","pt":1646314704569,"mc":[{"id":"1.195532866","rc":[{"atb":[[2.54,0]],"id":28791281},{"spn":5.28,"spf":1.0,"id":35676762}],"con":true,"img":false}]}
{"op":"mcm","clk":"5321937990","pt":1646314707375,"mc":[{"id":"1.195532866","rc":[{"atb":[[2.62,7.66]],"id":28791281}],"con":true,"img":false}]}
{"op":"mcm","clk":"5321958484","pt":1646314894521,"mc":[{"id":"1.195532866","rc":[{"atb":[[2.68,0]],"id":26648132},{"atb":[[2.64,0]],"id":43094640}],"con":true,"img":false}]}
{"op":"mcm","clk":"5321958539","pt":1646314895231,"mc":[{"id":"1.195532866","rc":[{"atb":[[10,1]],"id":35676762},{"trd":[[10,2]],"ltp":10.0,"tv":2.0,"id":35676762}],"con":true,"img":false}]}
{"op":"mcm","clk":"5321958806","pt":1646314898649,"mc":[{"id":"1.195532866","rc":[{"atb":[[3.65,2]],"id":28791281},{"atb":[[10,0]],"id":35676762}],"con":true,"img":false}]}
{"op":"mcm","clk":"5321960263","pt":1646314914959,"mc":[{"id":"1.195532866","rc":[{"atb":[[2.76,7.05]],"id":26648132},{"atb":[[3.1,0]],"id":35676762}],"con":true,"img":false}]}
{"op":"mcm","clk":"5321960295","pt":1646314915266,"mc":[{"id":"1.195532866","rc":[{"atb":[[2.72,7.21]],"id":43094640}],"con":true,"img":false}]}
{"op":"mcm","clk":"5321962335","pt":1646314936106,"mc":[{"id":"1.195532866","rc":[{"atb":[[3.3,5.39]],"id":35676762},{"atb":[[2.64,0]],"id":41529439},{"atb":[[2.64,0]],"id":39213014}],"con":true,"img":false}]}
{"op":"mcm","clk":"5321962705","pt":1646314939395,"mc":[{"id":"1.195532866","rc":[{"atb":[[2.58,0]],"id":28791281}],"con":true,"img":false}]}
{"op":"mcm","clk":"5321962981","pt":1646314942196,"mc":[{"id":"1.195532866","rc":[{"atb":[[2.66,6.75]],"id":28791281}],"con":true,"img":false}]}
{"op":"mcm","clk":"5321963868","pt":1646314951494,"mc":[{"id":"1.195532866","rc":[{"atb":[[2.72,7.21]],"id":41529439}],"con":true,"img":false}]}
{"op":"mcm","clk":"5321963893","pt":1646314951708,"mc":[{"id":"1.195532866","rc":[{"atb":[[2.72,7.21]],"id":39213014}],"con":true,"img":false}]}
{"op":"mcm","clk":"5321982295","pt":1646315130209,"mc":[{"id":"1.195532866","rc":[{"atb":[[2.72,0]],"id":26648132},{"atb":[[2.68,0]],"id":43094640},{"spn":4.92,"spf":1.0,"id":28791281},{"spn":3.99,"spf":1.0,"id":35676762}],"con":true,"img":false}]}
{"op":"mcm","clk":"5321982678","pt":1646315133580,"mc":[{"id":"1.195532866","rc":[{"atb":[[2.76,6.36]],"id":43094640}],"con":true,"img":false}]}
{"op":"mcm","clk":"5321982694","pt":1646315133691,"mc":[{"id":"1.195532866","rc":[{"atb":[[2.8,6.22]],"id":26648132}],"con":true,"img":false}]}
{"op":"mcm","clk":"5321984413","pt":1646315150005,"mc":[{"id":"1.195532866","rc":[{"atb":[[3.2,0]],"id":35676762}],"con":true,"img":false}]}
{"op":"mcm","clk":"5321984750","pt":1646315152903,"mc":[{"id":"1.195532866","rc":[{"atb":[[3.4,4.67]],"id":35676762}],"con":true,"img":false}]}
{"op":"mcm","clk":"5321986710","pt":1646315171842,"mc":[{"id":"1.195532866","rc":[{"atb":[[2.68,0]],"id":41529439},{"atb":[[2.68,0]],"id":39213014}],"con":true,"img":false}]}
{"op":"mcm","clk":"5321987578","pt":1646315176962,"mc":[{"id":"1.195532866","rc":[{"atb":[[2.76,6.36]],"id":41529439}],"con":true,"img":false}]}
{"op":"mcm","clk":"5321987600","pt":1646315177163,"mc":[{"id":"1.195532866","rc":[{"atb":[[2.76,6.36]],"id":39213014}],"con":true,"img":false}]}
{"op":"mcm","clk":"5321989296","pt":1646315194883,"mc":[{"id":"1.195532866","rc":[{"atb":[[2.62,0]],"id":28791281},{"spn":4.07,"spf":1.0,"id":35676762}],"con":true,"img":false}]}
{"op":"mcm","clk":"5321990869","pt":1646315213078,"mc":[{"id":"1.195532866","rc":[{"atb":[[2.7,7.3]],"id":28791281}],"con":true,"img":false}]}
{"op":"mcm","clk":"5322007734","pt":1646315364546,"mc":[{"id":"1.195532866","rc":[{"atb":[[2.76,0]],"id":26648132},{"atb":[[2.72,0]],"id":43094640}],"con":true,"img":false}]}
{"op":"mcm","clk":"5322009220","pt":1646315379902,"mc":[{"id":"1.195532866","rc":[{"atb":[[2.8,6.89]],"id":43094640}],"con":true,"img":false}]}
{"op":"mcm","clk":"5322009257","pt":1646315380273,"mc":[{"id":"1.195532866","rc":[{"atb":[[2.84,6.74]],"id":26648132}],"con":true,"img":false}]}
{"op":"mcm","clk":"5322010896","pt":1646315397283,"mc":[{"id":"1.195532866","rc":[{"atb":[[3.3,0]],"id":35676762}],"con":true,"img":false}]}
{"op":"mcm","clk":"5322012827","pt":1646315412297,"mc":[{"id":"1.195532866","rc":[{"atb":[[3.5,4.96]],"id":35676762}],"con":true,"img":false}]}
{"op":"mcm","clk":"5322012846","pt":1646315412406,"mc":[{"id":"1.195532866","rc":[{"atb":[[2.72,0]],"id":41529439},{"atb":[[2.72,0]],"id":39213014}],"con":true,"img":false}]}
{"op":"mcm","clk":"5322014983","pt":1646315428720,"mc":[{"id":"1.195532866","rc":[{"spn":4.16,"spf":1.0,"id":35676762},{"atb":[[2.8,6.89]],"id":41529439}],"con":true,"img":false}]}
{"op":"mcm","clk":"5322014995","pt":1646315428927,"mc":[{"id":"1.195532866","rc":[{"atb":[[2.8,6.89]],"id":39213014}],"con":true,"img":false}]}
{"op":"mcm","clk":"5322015065","pt":1646315429667,"mc":[{"id":"1.195532866","rc":[{"atb":[[2.66,0]],"id":28791281}],"con":true,"img":false}]}
{"op":"mcm","clk":"5322015351","pt":1646315432736,"mc":[{"id":"1.195532866","rc":[{"atb":[[2.74,6.44]],"id":28791281}],"con":true,"img":false}]}
{"op":"mcm","clk":"5322030446","pt":1646315598494,"mc":[{"id":"1.195532866","rc":[{"atb":[[2.8,0]],"id":26648132},{"atb":[[2.76,0]],"id":43094640}],"con":true,"img":false}]}
{"op":"mcm","clk":"5322030634","pt":1646315600822,"mc":[{"id":"1.195532866","rc":[{"atb":[[2.88,5.96]],"id":26648132}],"con":true,"img":false}]}
{"op":"mcm","clk":"5322030648","pt":1646315601025,"mc":[{"id":"1.195532866","rc":[{"atb":[[2.84,6.09]],"id":43094640}],"con":true,"img":false}]}
{"op":"mcm","clk":"5322033064","pt":1646315631124,"mc":[{"id":"1.195532866","rc":[{"atb":[[3.4,0]],"id":35676762}],"con":true,"img":false}]}
{"op":"mcm","clk":"5322033259","pt":1646315633908,"mc":[{"id":"1.195532866","rc":[{"atb":[[3.6,4.31]],"id":35676762}],"con":true,"img":false}]}
{"op":"mcm","clk":"5322034204","pt":1646315646216,"mc":[{"id":"1.195532866","rc":[{"atb":[[2.76,0]],"id":41529439},{"atb":[[2.76,0]],"id":39213014}],"con":true,"img":false}]}
{"op":"mcm","clk":"5322034438","pt":1646315649028,"mc":[{"id":"1.195532866","rc":[{"atb":[[2.84,6.09]],"id":41529439},{"atb":[[2.84,6.09]],"id":39213014}],"con":true,"img":false}]}
{"op":"mcm","clk":"5322037147","pt":1646315680894,"mc":[{"id":"1.195532866","rc":[{"atb":[[2.7,0]],"id":28791281},{"spn":4.24,"spf":1.0,"id":35676762}],"con":true,"img":false}]}
{"op":"mcm","clk":"5322037990","pt":1646315691682,"mc":[{"id":"1.195532866","rc":[{"atb":[[2.78,6.97]],"id":28791281}],"con":true,"img":false}]}
{"op":"mcm","clk":"5322052099","pt":1646315852480,"mc":[{"id":"1.195532866","rc":[{"atb":[[2.84,0]],"id":26648132},{"atb":[[2.8,0]],"id":43094640}],"con":true,"img":false}]}
{"op":"mcm","clk":"5322053364","pt":1646315869370,"mc":[{"id":"1.195532866","rc":[{"atb":[[2.92,6.46]],"id":26648132}],"con":true,"img":false}]}
{"op":"mcm","clk":"5322053409","pt":1646315870093,"mc":[{"id":"1.195532866","rc":[{"atb":[[2.88,6.6]],"id":43094640}],"con":true,"img":false}]}
{"op":"mcm","clk":"5322054573","pt":1646315884476,"mc":[{"id":"1.195532866","rc":[{"atb":[[3.5,0]],"id":35676762}],"con":true,"img":false}]}
{"op":"mcm","clk":"5322055713","pt":1646315898710,"mc":[{"id":"1.195532866","rc":[{"atb":[[3.7,4.6]],"id":35676762}],"con":true,"img":false}]}
{"op":"mcm","clk":"5322055734","pt":1646315899024,"mc":[{"id":"1.195532866","rc":[{"atb":[[2.8,0]],"id":41529439},{"atb":[[2.8,0]],"id":39213014}],"con":true,"img":false}]}
{"op":"mcm","clk":"5322056904","pt":1646315914403,"mc":[{"id":"1.195532866","rc":[{"atb":[[2.74,0]],"id":28791281},{"spn":4.33,"spf":1.0,"id":35676762}],"con":true,"img":false}]}
{"op":"mcm","clk":"5322056916","pt":1646315914610,"mc":[{"id":"1.195532866","rc":[{"atb":[[2.88,6.6]],"id":39213014}],"con":true,"img":false}]}
{"op":"mcm","clk":"5322056930","pt":1646315914819,"mc":[{"id":"1.195532866","rc":[{"atb":[[2.88,6.6]],"id":41529439}],"con":true,"img":false}]}
{"op":"mcm","clk":"5322057230","pt":1646315919607,"mc":[{"id":"1.195532866","rc":[{"atb":[[2.82,6.16]],"id":28791281}],"con":true,"img":false}]}
{"op":"mcm","clk":"5322072158","pt":1646316085244,"mc":[{"id":"1.195532866","rc":[{"atb":[[2.88,0]],"id":26648132},{"atb":[[2.84,0]],"id":43094640}],"con":true,"img":false}]}
{"op":"mcm","clk":"5322072440","pt":1646316088629,"mc":[{"id":"1.195532866","rc":[{"atb":[[2.96,5.71]],"id":26648132}],"con":true,"img":false}]}
{"op":"mcm","clk":"5322072464","pt":1646316089043,"mc":[{"id":"1.195532866","rc":[{"atb":[[2.92,5.83]],"id":43094640}],"con":true,"img":false}]}
{"op":"mcm","clk":"5322075427","pt":1646316118304,"mc":[{"id":"1.195532866","rc":[{"atb":[[3.6,0]],"id":35676762}],"con":true,"img":false}]}
{"op":"mcm","clk":"5322075657","pt":1646316120905,"mc":[{"id":"1.195532866","rc":[{"atb":[[3.8,4]],"id":35676762}],"con":true,"img":false}]}
{"op":"mcm","clk":"5322076926","pt":1646316133217,"mc":[{"id":"1.195532866","rc":[{"atb":[[2.84,0]],"id":41529439},{"atb":[[2.84,0]],"id":39213014}],"con":true,"img":false}]}
{"op":"mcm","clk":"5322077125","pt":1646316135929,"mc":[{"id":"1.195532866","rc":[{"atb":[[2.92,5.83]],"id":41529439}],"con":true,"img":false}]}
{"op":"mcm","clk":"5322077157","pt":1646316136442,"mc":[{"id":"1.195532866","rc":[{"atb":[[2.92,5.83]],"id":39213014}],"con":true,"img":false}]}
{"op":"mcm","clk":"5322079571","pt":1646316164654,"mc":[{"id":"1.195532866","rc":[{"atb":[[2.78,0]],"id":28791281},{"spn":4.39,"spf":1.0,"id":35676762}],"con":true,"img":false}]}
{"op":"mcm","clk":"5322080687","pt":1646316176792,"mc":[{"id":"1.195532866","rc":[{"atb":[[2.86,6.67]],"id":28791281}],"con":true,"img":false}]}
{"op":"mcm","clk":"5322092849","pt":1646316324377,"mc":[{"id":"1.195532866","rc":[{"atb":[[2.92,0]],"id":26648132},{"atb":[[2.88,0]],"id":43094640}],"con":true,"img":false}]}
{"op":"mcm","clk":"5322094323","pt":1646316340110,"mc":[{"id":"1.195532866","rc":[{"atb":[[2.96,6.33]],"id":43094640}],"con":true,"img":false}]}
{"op":"mcm","clk":"5322094373","pt":1646316340587,"mc":[{"id":"1.195532866","rc":[{"atb":[[3,6.2]],"id":26648132}],"con":true,"img":false}]}
{"op":"mcm","clk":"5322095729","pt":1646316354118,"mc":[{"id":"1.195532866","rc":[{"atb":[[3.7,0]],"id":35676762}],"con":true,"img":false}]}
{"op":"mcm","clk":"5322097244","pt":1646316369076,"mc":[{"id":"1.195532866","rc":[{"atb":[[3.9,4.28]],"id":35676762},{"atb":[[2.88,0]],"id":41529439},{"atb":[[2.88,0]],"id":39213014}],"con":true,"img":false}]}
{"op":"mcm","clk":"5322098891","pt":1646316385770,"mc":[{"id":"1.195532866","rc":[{"spn":4.42,"spf":1.0,"id":35676762},{"atb":[[2.96,6.33]],"id":41529439}],"con":true,"img":false}]}
{"op":"mcm","clk":"5322098919","pt":1646316386090,"mc":[{"id":"1.195532866","rc":[{"atb":[[2.96,6.33]],"id":39213014}],"con":true,"img":false}]}
{"op":"mcm","clk":"5322100014","pt":1646316397377,"mc":[{"id":"1.195532866","rc":[{"atb":[[2.82,0]],"id":28791281}],"con":true,"img":false}]}
{"op":"mcm","clk":"5322100291","pt":1646316400226,"mc":[{"id":"1.195532866","rc":[{"atb":[[2.4,8]],"id":28791281}],"con":true,"img":false}]}
{"op":"mcm","clk":"5322108928","pt":1646316490979,"mc":[{"id":"1.195532866","rc":[{"atb":[[2.62,64.81]],"id":26648132},{"atb":[[2.62,64.81]],"id":43094640},{"atb":[[1.79,129.11],[2.04,88.46]],"id":28791281},{"atl":[[17,9.5]],"id":28791281},{"atb":[[2.62,64.81]],"id":35676762},{"spn":4.45,"spf":1.0,"id":35676762},{"atl":[[34,15.5]],"id":41529439}],"con":true,"img":false}]}
{"op":"mcm","clk":"5322108935","pt":1646316491073,"mc":[{"id":"1.195532866","rc":[{"atl":[[34,15.5]],"id":26648132},{"atl":[[34,15.5]],"id":43094640},{"atl":[[34,15.5]],"id":28791281},{"atl":[[34,15.5]],"id":39213014}],"con":true,"img":false}]}
{"op":"mcm","clk":"5322109821","pt":1646316500893,"mc":[{"id":"1.195532866","rc":[{"atl":[[10,1.65]],"id":26648132},{"atl":[[6,1.65]],"id":28791281},{"atl":[[7.6,1.65]],"id":41529439}],"con":true,"img":false}]}
{"op":"mcm","clk":"5322109830","pt":1646316500965,"mc":[{"id":"1.195532866","rc":[{"atb":[[4.7,1.65]],"id":39213014}],"con":true,"img":false}]}
{"op":"mcm","clk":"5322110777","pt":1646316511009,"mc":[{"id":"1.195532866","rc":[{"atl":[[10.5,9.2],[13.5,15.2]],"id":28791281},{"atl":[[17.5,15.2],[14,9.2]],"id":41529439},{"atb":[[2.1,92.73],[2.48,62.16]],"id":39213014}],"con":true,"img":false}]}
{"op":"mcm","clk":"5322114760","pt":1646316557234,"mc":[{"id":"1.195532866","rc":[{"atb":[[2.96,0]],"id":26648132},{"spn":7.95,"spf":1.0,"id":26648132},{"atb":[[2.92,0]],"id":43094640},{"spn":4.82,"spf":1.0,"id":28791281},{"spn":6.1,"spf":1.0,"id":41529439},{"spn":6.25,"spf":1.0,"id":39213014}],"con":true,"img":false}]}
{"op":"mcm","clk":"5322115012","pt":1646316560071,"mc":[{"id":"1.195532866","rc":[{"atb":[[3.1,5.33]],"id":26648132}],"con":true,"img":false}]}
{"op":"mcm","clk":"5322115021","pt":1646316560168,"mc":[{"id":"1.195532866","rc":[{"atb":[[3,5.6]],"id":43094640}],"con":true,"img":false}]}
{"op":"mcm","clk":"5322117457","pt":1646316587585,"mc":[{"id":"1.195532866","rc":[{"atb":[[3.8,0]],"id":35676762}],"con":true,"img":false}]}
{"op":"mcm","clk":"5322117715","pt":1646316590301,"mc":[{"id":"1.195532866","rc":[{"atb":[[4,3.73]],"id":35676762}],"con":true,"img":false}]}
{"op":"mcm","clk":"5322118866","pt":1646316602601,"mc":[{"id":"1.195532866","rc":[{"atb":[[2.92,0]],"id":41529439},{"atb":[[2.92,0]],"id":39213014}],"con":true,"img":false}]}
{"op":"mcm","clk":"5322119395","pt":1646316608398,"mc":[{"id":"1.195532866","rc":[{"atb":[[3,5.6]],"id":41529439}],"con":true,"img":false}]}
{"op":"mcm","clk":"5322119482","pt":1646316609297,"mc":[{"id":"1.195532866","rc":[{"atb":[[3,5.6]],"id":39213014}],"con":true,"img":false}]}
{"op":"mcm","clk":"5322122732","pt":1646316645650,"mc":[{"id":"1.195532866","rc":[{"atb":[[2.86,0]],"id":28791281},{"spn":4.49,"spf":1.0,"id":35676762}],"con":true,"img":false}]}
{"op":"mcm","clk":"5322123947","pt":1646316659468,"mc":[{"id":"1.195532866","rc":[{"atb":[[2.44,8.62]],"id":28791281}],"con":true,"img":false}]}
{"op":"mcm","clk":"5322142622","pt":1646316866380,"mc":[{"id":"1.195532866","rc":[{"atb":[[3,0]],"id":26648132},{"atb":[[2.96,0]],"id":43094640},{"atb":[[3.9,0]],"id":35676762},{"spn":3.94,"spf":1.0,"id":35676762},{"atb":[[2.96,0]],"id":41529439},{"atb":[[2.96,0]],"id":39213014}],"con":true,"img":false}]}
{"op":"mcm","clk":"5322144619","pt":1646316887671,"mc":[{"id":"1.195532866","rc":[{"atb":[[3.2,5.64]],"id":26648132}],"con":true,"img":false}]}
{"op":"mcm","clk":"5322144660","pt":1646316888085,"mc":[{"id":"1.195532866","rc":[{"atb":[[3.1,5.91]],"id":43094640}],"con":true,"img":false}]}
{"op":"mcm","clk":"5322144679","pt":1646316888251,"mc":[{"id":"1.195532866","rc":[{"atb":[[3.1,5.91]],"id":41529439}],"con":true,"img":false}]}
{"op":"mcm","clk":"5322144689","pt":1646316888356,"mc":[{"id":"1.195532866","rc":[{"atb":[[4.2,3.88]],"id":35676762}],"con":true,"img":false}]}
{"op":"mcm","clk":"5322144717","pt":1646316888664,"mc":[{"id":"1.195532866","rc":[{"atb":[[3.1,5.91]],"id":39213014}],"con":true,"img":false}]}
{"op":"mcm","clk":"5322145467","pt":1646316896280,"mc":[{"id":"1.195532866","rc":[{"atb":[[2.4,0]],"id":28791281}],"con":true,"img":false}]}
{"op":"mcm","clk":"5322145729","pt":1646316899475,"mc":[{"id":"1.195532866","rc":[{"atb":[[2.48,7.58]],"id":28791281}],"con":true,"img":false}]}
{"op":"mcm","clk":"5322163983","pt":1646317103303,"mc":[{"id":"1.195532866","rc":[{"atb":[[3.1,0]],"id":26648132},{"atb":[[3,0]],"id":43094640},{"atb":[[4,0]],"id":35676762},{"spn":4.04,"spf":1.0,"id":35676762},{"atb":[[3,0]],"id":41529439},{"atb":[[3,0]],"id":39213014}],"con":true,"img":false}]}
{"op":"mcm","clk":"5322164317","pt":1646317107293,"mc":[{"id":"1.195532866","rc":[{"atb":[[3.2,5.09]],"id":43094640}],"con":true,"img":false}]}
{"op":"mcm","clk":"5322164545","pt":1646317109929,"mc":[{"id":"1.195532866","rc":[{"atb":[[4.4,3.29]],"id":35676762}],"con":true,"img":false}]}
{"op":"mcm","clk":"5322164562","pt":1646317110134,"mc":[{"id":"1.195532866","rc":[{"atb":[[3.2,5.09]],"id":41529439}],"con":true,"img":false}]}
{"op":"mcm","clk":"5322164572","pt":1646317110240,"mc":[{"id":"1.195532866","rc":[{"atb":[[3.3,4.87]],"id":26648132}],"con":true,"img":false}]}
{"op":"mcm","clk":"5322164592","pt":1646317110452,"mc":[{"id":"1.195532866","rc":[{"atb":[[3.2,5.09]],"id":39213014}],"con":true,"img":false}]}
{"op":"mcm","clk":"5322167157","pt":1646317141366,"mc":[{"id":"1.195532866","rc":[{"atb":[[2.44,0]],"id":28791281}],"con":true,"img":false}]}
{"op":"mcm","clk":"5322168863","pt":1646317156472,"mc":[{"id":"1.195532866","rc":[{"atb":[[2.52,8.17]],"id":28791281}],"con":true,"img":false}]}
{"op":"mcm","clk":"5322186250","pt":1646317355425,"mc":[{"id":"1.195532866","rc":[{"atb":[[3.2,0]],"id":26648132},{"atb":[[3.1,0]],"id":43094640},{"atb":[[4.2,0]],"id":35676762},{"spn":4.01,"spf":1.0,"id":35676762},{"atb":[[3.1,0]],"id":41529439},{"atb":[[3.1,0]],"id":39213014}],"con":true,"img":false}]}
{"op":"mcm","clk":"5322187739","pt":1646317371134,"mc":[{"id":"1.195532866","rc":[{"atb":[[3.3,5.39]],"id":43094640}],"con":true,"img":false}]}
{"op":"mcm","clk":"5322187768","pt":1646317371447,"mc":[{"id":"1.195532866","rc":[{"atb":[[3.4,5.17]],"id":26648132}],"con":true,"img":false}]}
{"op":"mcm","clk":"5322187796","pt":1646317371709,"mc":[{"id":"1.195532866","rc":[{"atb":[[3.3,5.39]],"id":41529439}],"con":true,"img":false}]}
{"op":"mcm","clk":"5322187805","pt":1646317371813,"mc":[{"id":"1.195532866","rc":[{"atb":[[4.6,3.45]],"id":35676762}],"con":true,"img":false}]}
{"op":"mcm","clk":"5322187821","pt":1646317372021,"mc":[{"id":"1.195532866","rc":[{"atb":[[3.3,5.39]],"id":39213014}],"con":true,"img":false}]}
{"op":"mcm","clk":"5322188075","pt":1646317374842,"mc":[{"id":"1.195532866","rc":[{"atb":[[2.48,0]],"id":28791281}],"con":true,"img":false}]}
{"op":"mcm","clk":"5322188346","pt":1646317377919,"mc":[{"id":"1.195532866","rc":[{"atb":[[2.56,7.19]],"id":28791281}],"con":true,"img":false}]}
{"op":"mcm","clk":"5322207802","pt":1646317588261,"mc":[{"id":"1.195532866","rc":[{"atb":[[3.3,0]],"id":26648132},{"atb":[[3.2,0]],"id":43094640},{"atb":[[4.4,0]],"id":35676762},{"spn":4.11,"spf":1.0,"id":35676762},{"atb":[[3.2,0]],"id":41529439},{"atb":[[3.2,0]],"id":39213014}],"con":true,"img":false}]}
{"op":"mcm","clk":"5322208109","pt":1646317591856,"mc":[{"id":"1.195532866","rc":[{"atb":[[2.52,7.37]],"id":39213014}],"con":true,"img":false}]}
{"op":"mcm","clk":"5322208131","pt":1646317591895,"mc":[{"id":"1.195532866","rc":[{"atb":[[3.4,4.67]],"id":43094640}],"con":true,"img":false}]}
{"op":"mcm","clk":"5322208168","pt":1646317592169,"mc":[{"id":"1.195532866","rc":[{"atb":[[3.5,4.48]],"id":26648132}],"con":true,"img":false}]}
{"op":"mcm","clk":"5322208202","pt":1646317592583,"mc":[{"id":"1.195532866","rc":[{"atb":[[2.36,8.24]],"id":41529439}],"con":true,"img":false}]}
{"op":"mcm","clk":"5322208211","pt":1646317592686,"mc":[{"id":"1.195532866","rc":[{"atb":[[4.8,2.95]],"id":35676762}],"con":true,"img":false}]}
{"op":"mcm","clk":"5322211803","pt":1646317629961,"mc":[{"id":"1.195532866","rc":[{"atb":[[2.52,0]],"id":28791281}],"con":true,"img":false}]}
{"op":"mcm","clk":"5322213060","pt":1646317642197,"mc":[{"id":"1.195532866","rc":[{"atb":[[2.6,7.76]],"id":28791281}],"con":true,"img":false}]}
{"op":"mcm","clk":"5322230420","pt":1646317829758,"mc":[{"id":"1.195532866","rc":[{"atb":[[3.4,0]],"id":26648132},{"atb":[[3.3,0]],"id":43094640},{"atb":[[4.6,0]],"id":35676762},{"spn":4.07,"spf":1.0,"id":35676762},{"atb":[[3.3,0]],"id":41529439},{"atb":[[3.3,0]],"id":39213014}],"con":true,"img":false}]}
{"op":"mcm","clk":"5322231812","pt":1646317844011,"mc":[{"id":"1.195532866","rc":[{"atb":[[2.56,7.96]],"id":39213014}],"con":true,"img":false}]}
{"op":"mcm","clk":"5322231830","pt":1646317844180,"mc":[{"id":"1.195532866","rc":[{"atb":[[3.5,4.96]],"id":43094640}],"con":true,"img":false}]}
{"op":"mcm","clk":"5322231853","pt":1646317844390,"mc":[{"id":"1.195532866","rc":[{"atb":[[2.4,8.86]],"id":41529439}],"con":true,"img":false}]}
{"op":"mcm","clk":"5322231860","pt":1646317844488,"mc":[{"id":"1.195532866","rc":[{"atb":[[3.6,4.77]],"id":26648132}],"con":true,"img":false}]}
{"op":"mcm","clk":"5322233591","pt":1646317863016,"mc":[{"id":"1.195532866","rc":[{"atb":[[2.56,0]],"id":28791281}],"con":true,"img":false}]}
{"op":"mcm","clk":"5322234068","pt":1646317869086,"mc":[{"id":"1.195532866","rc":[{"atb":[[2.64,6.84]],"id":28791281}],"con":true,"img":false}]}
{"op":"mcm","clk":"5322249734","pt":1646318064773,"mc":[{"id":"1.195532866","rc":[{"atb":[[3.5,0]],"id":26648132},{"atb":[[3.4,0]],"id":43094640},{"spn":4.02,"spf":1.0,"id":43094640},{"atb":[[4.8,0]],"id":35676762},{"spn":3.42,"spf":1.0,"id":35676762}],"con":true,"img":false}]}
{"op":"mcm","clk":"5322249893","pt":1646318067263,"mc":[{"id":"1.195532866","rc":[{"atb":[[2.78,6.3]],"id":35676762}],"con":true,"img":false}]}
{"op":"mcm","clk":"5322249902","pt":1646318067365,"mc":[{"id":"1.195532866","rc":[{"atb":[[3.6,4.31]],"id":43094640}],"con":true,"img":false}]}
{"op":"mcm","clk":"5322249915","pt":1646318067574,"mc":[{"id":"1.195532866","rc":[{"atb":[[3.7,4.15]],"id":26648132}],"con":true,"img":false}]}
{"op":"mcm","clk":"5322250754","pt":1646318078780,"mc":[{"id":"1.195532866","rc":[{"atb":[[2.36,0]],"id":41529439},{"atb":[[2.52,0]],"id":39213014}],"con":true,"img":false}]}
{"op":"mcm","clk":"5322250786","pt":1646318079203,"mc":[{"id":"1.195532866","rc":[{"atb":[[2.82,6.82]],"id":35676762}],"con":true,"img":false}]}
{"op":"mcm","clk":"5322250955","pt":1646318081089,"mc":[{"id":"1.195532866","rc":[{"atb":[[2.44,7.79]],"id":41529439},{"atb":[[2.6,7.01]],"id":39213014}],"con":true,"img":false}]}
{"op":"mcm","clk":"5322253250","pt":1646318108213,"mc":[{"id":"1.195532866","rc":[{"atb":[[2.6,0]],"id":28791281}],"con":true,"img":false}]}
{"op":"mcm","clk":"5322254186","pt":1646318120244,"mc":[{"id":"1.195532866","rc":[{"atb":[[2.68,7.39]],"id":28791281}],"con":true,"img":false}]}
{"op":"mcm","clk":"5322271154","pt":1646318313315,"mc":[{"id":"1.195532866","rc":[{"spn":4.16,"spf":1.0,"id":43094640},{"atb":[[2.78,0]],"id":35676762},{"spn":3.56,"spf":1.0,"id":35676762}],"con":true,"img":false}]}
{"op":"mcm","clk":"5322271459","pt":1646318316331,"mc":[{"id":"1.195532866","rc":[{"atb":[[2.86,6.02]],"id":35676762}],"con":true,"img":false}]}
{"op":"mcm","clk":"5322271819","pt":1646318319836,"mc":[{"id":"1.195532866","rc":[{"atb":[[3.6,0]],"id":26648132},{"atb":[[3.5,0]],"id":43094640}],"con":true,"img":false}]}
{"op":"mcm","clk":"5322273288","pt":1646318334327,"mc":[{"id":"1.195532866","rc":[{"atb":[[3.8,4.43]],"id":26648132}],"con":true,"img":false}]}
{"op":"mcm","clk":"5322273314","pt":1646318334541,"mc":[{"id":"1.195532866","rc":[{"atb":[[2.4,0]],"id":41529439},{"atb":[[2.56,0]],"id":39213014}],"con":true,"img":false}]}
{"op":"mcm","clk":"5322273358","pt":1646318334963,"mc":[{"id":"1.195532866","rc":[{"atb":[[3.7,4.6]],"id":43094640}],"con":true,"img":false}]}
{"op":"mcm","clk":"5322274120","pt":1646318342958,"mc":[{"id":"1.195532866","rc":[{"atb":[[2.64,0]],"id":28791281}],"con":true,"img":false}]}
{"op":"mcm","clk":"5322274428","pt":1646318346097,"mc":[{"id":"1.195532866","rc":[{"atb":[[2.72,6.51]],"id":28791281}],"con":true,"img":false}]}
{"op":"mcm","clk":"5322274672","pt":1646318348768,"mc":[{"id":"1.195532866","rc":[{"atb":[[2.48,8.39]],"id":41529439}],"con":true,"img":false}]}
{"op":"mcm","clk":"5322274694","pt":1646318349082,"mc":[{"id":"1.195532866","rc":[{"atb":[[2.64,7.57]],"id":39213014}],"con":true,"img":false}]}
{"op":"mcm","clk":"5322294461","pt":1646318553659,"mc":[{"id":"1.195532866","rc":[{"atb":[[3.7,0]],"id":26648132},{"atb":[[3.6,0]],"id":43094640},{"spn":4.08,"spf":1.0,"id":43094640},{"spn":3.62,"spf":1.0,"id":35676762}],"con":true,"img":false}]}
{"op":"mcm","clk":"5322294510","pt":1646318554235,"mc":[{"id":"1.195532866","rc":[{"atb":[[2.82,0]],"id":35676762}],"con":true,"img":false}]}
{"op":"mcm","clk":"5322294690","pt":1646318556122,"mc":[{"id":"1.195532866","rc":[{"atb":[[3.9,3.86]],"id":26648132}],"con":true,"img":false}]}
{"op":"mcm","clk":"5322294704","pt":1646318556226,"mc":[{"id":"1.195532866","rc":[{"atb":[[2.66,6.75]],"id":43094640}],"con":true,"img":false}]}
{"op":"mcm","clk":"5322295945","pt":1646318568380,"mc":[{"id":"1.195532866","rc":[{"atb":[[2.44,0]],"id":41529439},{"atb":[[2.6,0]],"id":39213014}],"con":true,"img":false}]}
{"op":"mcm","clk":"5322296093","pt":1646318569849,"mc":[{"id":"1.195532866","rc":[{"atb":[[2.9,6.53]],"id":35676762}],"con":true,"img":false}]}
{"op":"mcm","clk":"5322296217","pt":1646318571144,"mc":[{"id":"1.195532866","rc":[{"atb":[[2.52,7.37]],"id":41529439}],"con":true,"img":false}]}
{"op":"mcm","clk":"5322296233","pt":1646318571352,"mc":[{"id":"1.195532866","rc":[{"atb":[[2.68,6.67]],"id":39213014}],"con":true,"img":false}]}
{"op":"mcm","clk":"5322297419","pt":1646318583881,"mc":[{"id":"1.195532866","rc":[{"atb":[[2.68,0]],"id":28791281}],"con":true,"img":false}]}
{"op":"mcm","clk":"5322298697","pt":1646318597905,"mc":[{"id":"1.195532866","rc":[{"atb":[[2.76,7.05]],"id":28791281}],"con":true,"img":false}]}
{"op":"mcm","clk":"5322316908","pt":1646318789601,"mc":[{"id":"1.195532866","rc":[{"spn":4.09,"spf":1.0,"id":43094640},{"atb":[[2.86,0]],"id":35676762},{"spn":3.61,"spf":1.0,"id":35676762}],"con":true,"img":false}]}
{"op":"mcm","clk":"5322317360","pt":1646318794393,"mc":[{"id":"1.195532866","rc":[{"atb":[[2.94,5.77]],"id":35676762}],"con":true,"img":false}]}
{"op":"mcm","clk":"5322327220","pt":1646318803129,"mc":[{"id":"1.195532866","rc":[{"atb":[[3.8,0]],"id":26648132},{"atb":[[3.7,0]],"id":43094640}],"con":true,"img":false}]}
{"op":"mcm","clk":"5322328160","pt":1646318814539,"mc":[{"id":"1.195532866","rc":[{"atb":[[2.66,7.48]],"id":26648132}],"con":true,"img":false}]}
{"op":"mcm","clk":"5322328188","pt":1646318814810,"mc":[{"id":"1.195532866","rc":[{"atb":[[2.7,7.3]],"id":43094640}],"con":true,"img":false}]}
{"op":"mcm","clk":"5322328223","pt":1646318815133,"mc":[{"id":"1.195532866","rc":[{"atb":[[2.48,0]],"id":41529439},{"atb":[[2.64,0]],"id":39213014}],"con":true,"img":false}]}
{"op":"mcm","clk":"5322328523","pt":1646318818321,"mc":[{"id":"1.195532866","rc":[{"atb":[[2.72,0]],"id":28791281}],"con":true,"img":false}]}
{"op":"mcm","clk":"5322328811","pt":1646318821466,"mc":[{"id":"1.195532866","rc":[{"atb":[[2.8,6.22]],"id":28791281}],"con":true,"img":false}]}
{"op":"mcm","clk":"5322329661","pt":1646318830759,"mc":[{"id":"1.195532866","rc":[{"atb":[[2.56,7.96]],"id":41529439}],"con":true,"img":false}]}
{"op":"mcm","clk":"5322329675","pt":1646318830964,"mc":[{"id":"1.195532866","rc":[{"atb":[[2.72,7.21]],"id":39213014}],"con":true,"img":false}]}
{"op":"mcm","clk":"5322346885","pt":1646319035757,"mc":[{"id":"1.195532866","rc":[{"spn":4.0,"spf":1.0,"id":43094640},{"atb":[[2.9,0]],"id":35676762},{"spn":3.61,"spf":1.0,"id":35676762}],"con":true,"img":false}]}
{"op":"mcm","clk":"5322347322","pt":1646319040861,"mc":[{"id":"1.195532866","rc":[{"atb":[[3.9,0]],"id":26648132}],"con":true,"img":false}]}
{"op":"mcm","clk":"5322347543","pt":1646319043656,"mc":[{"id":"1.195532866","rc":[{"atb":[[2.7,6.59]],"id":26648132}],"con":true,"img":false}]}
{"op":"mcm","clk":"5322347801","pt":1646319046932,"mc":[{"id":"1.195532866","rc":[{"atb":[[2.66,0]],"id":43094640},{"atb":[[2.52,0]],"id":41529439},{"atb":[[2.68,0]],"id":39213014}],"con":true,"img":false}]}
{"op":"mcm","clk":"5322348019","pt":1646319049642,"mc":[{"id":"1.195532866","rc":[{"atb":[[2.74,6.44]],"id":43094640}],"con":true,"img":false}]}
{"op":"mcm","clk":"5322348053","pt":1646319050056,"mc":[{"id":"1.195532866","rc":[{"atb":[[2.76,6.36]],"id":39213014}],"con":true,"img":false}]}
{"op":"mcm","clk":"5322348071","pt":1646319050370,"mc":[{"id":"1.195532866","rc":[{"atb":[[2.6,7.01]],"id":41529439}],"con":true,"img":false}]}
{"op":"mcm","clk":"5322348113","pt":1646319050967,"mc":[{"id":"1.195532866","rc":[{"atb":[[2.98,6.27]],"id":35676762}],"con":true,"img":false}]}
{"op":"mcm","clk":"5322349283","pt":1646319064876,"mc":[{"id":"1.195532866","rc":[{"atb":[[2.76,0]],"id":28791281}],"con":true,"img":false}]}
{"op":"mcm","clk":"5322350256","pt":1646319077754,"mc":[{"id":"1.195532866","rc":[{"atb":[[2.84,6.74]],"id":28791281}],"con":true,"img":false}]}
{"op":"mcm","clk":"5322363796","pt":1646319269534,"mc":[{"id":"1.195532866","rc":[{"atb":[[2.94,0]],"id":35676762},{"spn":3.65,"spf":1.0,"id":35676762}],"con":true,"img":false}]}
{"op":"mcm","clk":"5322363953","pt":1646319272204,"mc":[{"id":"1.195532866","rc":[{"atb":[[3.05,5.47]],"id":35676762}],"con":true,"img":false}]}
{"op":"mcm","clk":"5322364632","pt":1646319283829,"mc":[{"id":"1.195532866","rc":[{"atb":[[2.66,0]],"id":26648132},{"atb":[[2.7,0]],"id":43094640},{"atb":[[2.56,0]],"id":41529439},{"atb":[[2.72,0]],"id":39213014}],"con":true,"img":false}]}
{"op":"mcm","clk":"5322365533","pt":1646319298228,"mc":[{"id":"1.195532866","rc":[{"atb":[[2.64,7.57]],"id":41529439}],"con":true,"img":false}]}
{"op":"mcm","clk":"5322365538","pt":1646319298269,"mc":[{"id":"1.195532866","rc":[{"atb":[[2.74,7.13]],"id":26648132}],"con":true,"img":false}]}
{"op":"mcm","clk":"5322365567","pt":1646319298537,"mc":[{"id":"1.195532866","rc":[{"atb":[[2.78,6.97]],"id":43094640}],"con":true,"img":false}]}
{"op":"mcm","clk":"5322365604","pt":1646319298950,"mc":[{"id":"1.195532866","rc":[{"atb":[[2.8,6.89]],"id":39213014}],"con":true,"img":false}]}
{"op":"mcm","clk":"5322365612","pt":1646319299051,"mc":[{"id":"1.195532866","rc":[{"atb":[[2.8,0]],"id":28791281}],"con":true,"img":false}]}
{"op":"mcm","clk":"5322365824","pt":1646319302834,"mc":[{"id":"1.195532866","rc":[{"atb":[[2.4,8]],"id":28791281}],"con":true,"img":false}]}
{"op":"mcm","clk":"5322379959","pt":1646319518783,"mc":[{"id":"1.195532866","rc":[{"atb":[[2.7,0]],"id":26648132},{"atb":[[2.74,0]],"id":43094640},{"spn":3.78,"spf":1.0,"id":35676762},{"atb":[[2.6,0]],"id":41529439},{"atb":[[2.76,0]],"id":39213014}],"con":true,"img":false}]}
{"op":"mcm","clk":"5322380163","pt":1646319521386,"mc":[{"id":"1.195532866","rc":[{"atb":[[2.68,6.67]],"id":41529439},{"atb":[[2.84,6.09]],"id":39213014}],"con":true,"img":false}]}
{"op":"mcm","clk":"5322380175","pt":1646319521597,"mc":[{"id":"1.195532866","rc":[{"atb":[[2.78,6.3]],"id":26648132}],"con":true,"img":false}]}
{"op":"mcm","clk":"5322380195","pt":1646319521817,"mc":[{"id":"1.195532866","rc":[{"atb":[[2.82,6.16]],"id":43094640}],"con":true,"img":false}]}
{"op":"mcm","clk":"5322384024","pt":1646319574066,"mc":[{"id":"1.195532866","rc":[{"atb":[[2.84,0]],"id":28791281},{"atb":[[2.98,0]],"id":35676762}],"con":true,"img":false}]}
{"op":"mcm","clk":"5322385551","pt":1646319595274,"mc":[{"id":"1.195532866","rc":[{"atb":[[2.44,8.62]],"id":28791281},{"spn":3.66,"spf":1.0,"id":35676762}],"con":true,"img":false}]}
{"op":"mcm","clk":"5322385595","pt":1646319595794,"mc":[{"id":"1.195532866","rc":[{"atb":[[3.15,5.77]],"id":35676762}],"con":true,"img":false}]}
{"op":"mcm","clk":"5322386656","pt":1646319608292,"mc":[{"id":"1.195532866","rc":[{"atb":[[2.74,7.14],[2.06,165.09],[2.78,6.3],[2.34,12.8]],"id":26648132},{"atl":[[150,5],[10,1.65]],"id":26648132},{"atb":[[2.82,6.16],[2.32,11.95],[2.06,165.09],[2.78,6.98]],"id":43094640},{"atl":[[150,5]],"id":43094640},{"atb":[[2.4,8.01],[2.36,10.04],[2.44,8.63]],"id":28791281},{"atl":[[150,5],[6,1.65]],"id":28791281},{"atb":[[2.06,173.71],[3.15,5.78],[3.05,5.47]],"id":35676762},{"atl":[[150,5]],"id":35676762},{"atb":[[2.32,9.48],[2.06,165.09],[2.64,7.58],[2.68,6.68]],"id":41529439},{"atl":[[150,5],[7.6,1.65]],"id":41529439},{"atb":[[2.8,6.9],[2.32,13.18],[2.06,165.09],[2.84,6.09],[4.7,1.65]],"id":39213014},{"atl":[[150,5]],"id":39213014}],"con":true,"img":false}]}
{"op":"mcm","clk":"5322402644","pt":1646319807464,"mc":[{"id":"1.195532866","rc":[{"atb":[[3.05,0]],"id":35676762},{"spn":3.73,"spf":1.0,"id":35676762}],"con":true,"img":false}]}
{"op":"mcm","clk":"5322402857","pt":1646319810158,"mc":[{"id":"1.195532866","rc":[{"atb":[[3.25,4.99]],"id":35676762}],"con":true,"img":false}]}
{"op":"mcm","clk":"5322402890","pt":1646319810574,"mc":[{"id":"1.195532866","rc":[{"atb":[[2.74,0]],"id":26648132},{"atb":[[2.78,0]],"id":43094640},{"atb":[[2.64,0]],"id":41529439},{"atb":[[2.8,0]],"id":39213014}],"con":true,"img":false}]}
{"op":"mcm","clk":"5322404502","pt":1646319832071,"mc":[{"id":"1.195532866","rc":[{"atb":[[2.4,0]],"id":28791281}],"con":true,"img":false}]}
{"op":"mcm","clk":"5322404921","pt":1646319837171,"mc":[{"id":"1.195532866","rc":[{"atb":[[2.48,7.58]],"id":28791281}],"con":true,"img":false}]}
{"op":"mcm","clk":"5322405544","pt":1646319844497,"mc":[{"id":"1.195532866","rc":[{"atb":[[2.88,6.61]],"id":39213014}],"con":true,"img":false}]}
{"op":"mcm","clk":"5322405639","pt":1646319845697,"mc":[{"id":"1.195532866","rc":[{"atb":[[2.82,6.83]],"id":26648132}],"con":true,"img":false}]}
{"op":"mcm","clk":"5322405703","pt":1646319846376,"mc":[{"id":"1.195532866","rc":[{"atb":[[2.72,7.22]],"id":41529439}],"con":true,"img":false}]}
{"op":"mcm","clk":"5322405754","pt":1646319846894,"mc":[{"id":"1.195532866","rc":[{"atb":[[2.86,6.68]],"id":43094640}],"con":true,"img":false}]}
{"op":"mcm","clk":"5322422358","pt":1646320047469,"mc":[{"id":"1.195532866","rc":[{"atb":[[2.78,0]],"id":26648132},{"atb":[[2.82,0]],"id":43094640},{"spn":3.94,"spf":1.0,"id":35676762},{"atb":[[2.68,0]],"id":41529439},{"atb":[[2.84,0]],"id":39213014}],"con":true,"img":false}]}
{"op":"mcm","clk":"5322422624","pt":1646320050481,"mc":[{"id":"1.195532866","rc":[{"atb":[[3.15,0]],"id":35676762}],"con":true,"img":false}]}
{"op":"mcm","clk":"5322422635","pt":1646320050585,"mc":[{"id":"1.195532866","rc":[{"atb":[[2.86,6.03]],"id":26648132},{"atb":[[2.92,5.84]],"id":39213014}],"con":true,"img":false}]}
{"op":"mcm","clk":"5322422646","pt":1646320050695,"mc":[{"id":"1.195532866","rc":[{"atb":[[2.9,5.9]],"id":43094640},{"atb":[[2.76,6.37]],"id":41529439}],"con":true,"img":false}]}
{"op":"mcm","clk":"5322423884","pt":1646320065207,"mc":[{"id":"1.195532866","rc":[{"atb":[[3.35,5.28]],"id":35676762}],"con":true,"img":false}]}
{"op":"mcm","clk":"5322425328","pt":1646320082600,"mc":[{"id":"1.195532866","rc":[{"atb":[[2.44,0]],"id":28791281}],"con":true,"img":false}]}
{"op":"mcm","clk":"5322426687","pt":1646320101050,"mc":[{"id":"1.195532866","rc":[{"atb":[[2.52,8.18]],"id":28791281}],"con":true,"img":false}]}
{"op":"mcm","clk":"5322442467","pt":1646320285123,"mc":[{"id":"1.195532866","rc":[{"atb":[[3.25,0]],"id":35676762},{"spn":3.81,"spf":1.0,"id":35676762}],"con":true,"img":false}]}
{"op":"mcm","clk":"5322442864","pt":1646320288090,"mc":[{"id":"1.195532866","rc":[{"atb":[[3.45,4.58]],"id":35676762}],"con":true,"img":false}]}
{"op":"mcm","clk":"5322443823","pt":1646320292153,"mc":[{"id":"1.195532866","rc":[{"atb":[[2.82,0]],"id":26648132},{"atb":[[2.86,0]],"id":43094640},{"atb":[[2.72,0]],"id":41529439},{"atb":[[2.88,0]],"id":39213014}],"con":true,"img":false}]}
{"op":"mcm","clk":"5322446200","pt":1646320307363,"mc":[{"id":"1.195532866","rc":[{"atb":[[2.9,6.54]],"id":26648132}],"con":true,"img":false}]}
{"op":"mcm","clk":"5322446232","pt":1646320307640,"mc":[{"id":"1.195532866","rc":[{"atb":[[2.8,6.9]],"id":41529439}],"con":true,"img":false}]}
{"op":"mcm","clk":"5322446265","pt":1646320307948,"mc":[{"id":"1.195532866","rc":[{"atb":[[2.94,6.4]],"id":43094640}],"con":true,"img":false}]}
{"op":"mcm","clk":"5322446302","pt":1646320308270,"mc":[{"id":"1.195532866","rc":[{"atb":[[2.96,6.34]],"id":39213014}],"con":true,"img":false}]}
{"op":"mcm","clk":"5322447029","pt":1646320316478,"mc":[{"id":"1.195532866","rc":[{"atb":[[2.48,0]],"id":28791281}],"con":true,"img":false}]}
{"op":"mcm","clk":"5322447524","pt":1646320322466,"mc":[{"id":"1.195532866","rc":[{"atb":[[2.56,7.2]],"id":28791281}],"con":true,"img":false}]}
{"op":"mcm","clk":"5322455111","pt":1646320411364,"mc":[{"id":"1.195532866","rc":[{"atl":[[1000,4.24]],"id":35676762},{"spn":4.11,"spf":1.0,"id":35676762}],"con":true,"img":false}]}
{"op":"mcm","clk":"5322455134","pt":1646320411574,"mc":[{"id":"1.195532866","rc":[{"atl":[[1000,2.14]],"id":35676762}],"con":true,"img":false}]}
{"op":"mcm","clk":"5322455168","pt":1646320411989,"mc":[{"id":"1.195532866","rc":[{"atl":[[1000,2]],"id":35676762}],"con":true,"img":false}]}
{"op":"mcm","clk":"5322455180","pt":1646320412095,"mc":[{"id":"1.195532866","rc":[{"atl":[[25,0.14]],"id":35676762}],"con":true,"img":false}]}
{"op":"mcm","clk":"5322464613","pt":1646320526962,"mc":[{"id":"1.195532866","rc":[{"atb":[[2.86,0]],"id":26648132},{"atb":[[2.9,0]],"id":43094640},{"atb":[[2.76,0]],"id":41529439},{"atb":[[2.92,0]],"id":39213014}],"con":true,"img":false}]}
{"op":"mcm","clk":"5322464805","pt":1646320529281,"mc":[{"id":"1.195532866","rc":[{"atb":[[3.35,0]],"id":35676762}],"con":true,"img":false}]}
{"op":"mcm","clk":"5322464821","pt":1646320529477,"mc":[{"id":"1.195532866","rc":[{"atb":[[2.84,6.09]],"id":41529439}],"con":true,"img":false}]}
{"op":"mcm","clk":"5322464835","pt":1646320529591,"mc":[{"id":"1.195532866","rc":[{"atb":[[2.94,5.78]],"id":26648132},{"atb":[[3,5.61]],"id":39213014}],"con":true,"img":false}]}
{"op":"mcm","clk":"5322464865","pt":1646320529908,"mc":[{"id":"1.195532866","rc":[{"atb":[[2.98,5.67]],"id":43094640}],"con":true,"img":false}]}
{"op":"mcm","clk":"5322465731","pt":1646320540792,"mc":[{"id":"1.195532866","rc":[{"atb":[[3.55,4.87]],"id":35676762}],"con":true,"img":false}]}
{"op":"mcm","clk":"5322466806","pt":1646320553634,"mc":[{"id":"1.195532866","rc":[{"atb":[[2.52,0]],"id":28791281}],"con":true,"img":false}]}
{"op":"mcm","clk":"5322468004","pt":1646320567135,"mc":[{"id":"1.195532866","rc":[{"atb":[[2.6,7.77]],"id":28791281}],"con":true,"img":false}]}
{"op":"mcm","clk":"5322483637","pt":1646320763297,"mc":[{"id":"1.195532866","rc":[{"atb":[[3.45,0]],"id":35676762},{"spn":3.88,"spf":1.0,"id":35676762}],"con":true,"img":false}]}
{"op":"mcm","clk":"5322483908","pt":1646320766864,"mc":[{"id":"1.195532866","rc":[{"atb":[[3.65,4.23]],"id":35676762}],"con":true,"img":false}]}
{"op":"mcm","clk":"5322484059","pt":1646320768804,"mc":[{"id":"1.195532866","rc":[{"atb":[[2.9,0]],"id":26648132},{"atb":[[2.94,0]],"id":43094640},{"atb":[[2.8,0]],"id":41529439},{"atb":[[2.96,0]],"id":39213014}],"con":true,"img":false}]}
{"op":"mcm","clk":"5322485315","pt":1646320785527,"mc":[{"id":"1.195532866","rc":[{"atb":[[2.56,0]],"id":28791281}],"con":true,"img":false}]}
{"op":"mcm","clk":"5322485401","pt":1646320786639,"mc":[{"id":"1.195532866","rc":[{"atb":[[3.1,5.91]],"id":39213014}],"con":true,"img":false}]}
{"op":"mcm","clk":"5322485408","pt":1646320786694,"mc":[{"id":"1.195532866","rc":[{"atb":[[2.88,6.61]],"id":41529439}],"con":true,"img":false}]}
{"op":"mcm","clk":"5322485464","pt":1646320787341,"mc":[{"id":"1.195532866","rc":[{"atb":[[3.05,6.06]],"id":43094640}],"con":true,"img":false}]}
{"op":"mcm","clk":"5322485506","pt":1646320787824,"mc":[{"id":"1.195532866","rc":[{"atb":[[2.64,6.84]],"id":28791281}],"con":true,"img":false}]}
{"op":"mcm","clk":"5322485552","pt":1646320788441,"mc":[{"id":"1.195532866","rc":[{"atb":[[2.98,6.28]],"id":26648132}],"con":true,"img":false}]}
{"op":"mcm","clk":"5322501559","pt":1646320981848,"mc":[{"id":"1.195532866","rc":[{"atl":[[27,0]],"id":35676762},{"spn":4.28,"spf":1.0,"id":35676762},{"atl":[[7.8,0]],"id":41529439}],"con":true,"img":false}]}
{"op":"mcm","clk":"5322501566","pt":1646320981900,"mc":[{"id":"1.195532866","rc":[{"atl":[[26,0.61]],"id":35676762},{"atl":[[7,1.68]],"id":41529439}],"con":true,"img":false}]}
{"op":"mcm","clk":"5322502595","pt":1646320994914,"mc":[{"id":"1.195532866","rc":[{"atl":[[7.6,0]],"id":41529439}],"con":true,"img":false}]}
{"op":"mcm","clk":"5322503109","pt":1646321001437,"mc":[{"id":"1.195532866","rc":[{"atb":[[2.94,0]],"id":26648132},{"atb":[[2.98,0]],"id":43094640},{"atb":[[2.84,0]],"id":41529439},{"atb":[[3,0]],"id":39213014}],"con":true,"img":false}]}
{"op":"mcm","clk":"5322503189","pt":1646321002426,"mc":[{"id":"1.195532866","rc":[{"atb":[[3.55,0]],"id":35676762}],"con":true,"img":false}]}
{"op":"mcm","clk":"5322503283","pt":1646321003871,"mc":[{"id":"1.195532866","rc":[{"atb":[[3.05,5.47]],"id":26648132}],"con":true,"img":false}]}
{"op":"mcm","clk":"5322503289","pt":1646321003975,"mc":[{"id":"1.195532866","rc":[{"atb":[[3.2,5.1]],"id":39213014}],"con":true,"img":false}]}
{"op":"mcm","clk":"5322503298","pt":1646321004030,"mc":[{"id":"1.195532866","rc":[{"atb":[[2.92,5.84]],"id":41529439}],"con":true,"img":false}]}
{"op":"mcm","clk":"5322503315","pt":1646321004234,"mc":[{"id":"1.195532866","rc":[{"atb":[[3.15,5.22]],"id":43094640}],"con":true,"img":false}]}
{"op":"mcm","clk":"5322503967","pt":1646321013751,"mc":[{"id":"1.195532866","rc":[{"atb":[[3.75,4.51]],"id":35676762}],"con":true,"img":false}]}
{"op":"mcm","clk":"5322505752","pt":1646321039013,"mc":[{"id":"1.195532866","rc":[{"atb":[[2.6,0]],"id":28791281}],"con":true,"img":false}]}
{"op":"mcm","clk":"5322506674","pt":1646321051211,"mc":[{"id":"1.195532866","rc":[{"atb":[[2.68,7.4]],"id":28791281},{"spn":4.37,"spf":1.0,"id":35676762},{"spn":5.8,"spf":1.0,"id":41529439}],"con":true,"img":false}]}
{"op":"mcm","clk":"5322510452","pt":1646321104109,"mc":[{"id":"1.195532866","rc":[{"atl":[[34,25.5]],"id":26648132}],"con":true,"img":false}]}
{"op":"mcm","clk":"5322519866","pt":1646321235718,"mc":[{"id":"1.195532866","rc":[{"atb":[[3.65,0]],"id":35676762},{"spn":3.93,"spf":1.0,"id":35676762}],"con":true,"img":false}]}
{"op":"mcm","clk":"5322520021","pt":1646321237917,"mc":[{"id":"1.195532866","rc":[{"atb":[[3.85,3.93]],"id":35676762}],"con":true,"img":false}]}
{"op":"mcm","clk":"5322521087","pt":1646321251147,"mc":[{"id":"1.195532866","rc":[{"atb":[[2.98,0]],"id":26648132},{"atb":[[3.05,0]],"id":43094640},{"atb":[[2.88,0]],"id":41529439},{"atb":[[3.1,0]],"id":39213014}],"con":true,"img":false}]}
{"op":"mcm","clk":"5322521943","pt":1646321262242,"mc":[{"id":"1.195532866","rc":[{"atb":[[2.96,6.34]],"id":41529439}],"con":true,"img":false}]}
{"op":"mcm","clk":"5322521966","pt":1646321262445,"mc":[{"id":"1.195532866","rc":[{"atb":[[3.25,5.53]],"id":43094640}],"con":true,"img":false}]}
{"op":"mcm","clk":"5322522037","pt":1646321263443,"mc":[{"id":"1.195532866","rc":[{"atb":[[3.3,5.4]],"id":39213014}],"con":true,"img":false}]}
{"op":"mcm","clk":"5322522043","pt":1646321263542,"mc":[{"id":"1.195532866","rc":[{"atb":[[3.15,5.78]],"id":26648132}],"con":true,"img":false}]}
{"op":"mcm","clk":"5322522672","pt":1646321271641,"mc":[{"id":"1.195532866","rc":[{"atb":[[2.64,0]],"id":28791281}],"con":true,"img":false}]}
{"op":"mcm","clk":"5322522892","pt":1646321274237,"mc":[{"id":"1.195532866","rc":[{"atb":[[2.72,6.52]],"id":28791281}],"con":true,"img":false}]}
{"op":"mcm","clk":"5322534386","pt":1646321425565,"mc":[{"id":"1.195532866","rc":[{"spn":4.42,"spf":1.0,"id":35676762},{"spl":[[1.01,8.24]],"id":41529439},{"spn":3.63,"spf":1.0,"id":41529439}],"con":true,"img":false}]}
{"op":"mcm","clk":"5322538247","pt":1646321475636,"mc":[{"id":"1.195532866","rc":[{"atb":[[3.75,0]],"id":35676762}],"con":true,"img":false}]}
{"op":"mcm","clk":"5322538929","pt":1646321484651,"mc":[{"id":"1.195532866","rc":[{"atb":[[3.05,0]],"id":26648132},{"atb":[[3.15,0]],"id":43094640},{"atb":[[2.92,0]],"id":41529439},{"atb":[[3.2,0]],"id":39213014}],"con":true,"img":false}]}
{"op":"mcm","clk":"5322539121","pt":1646321487559,"mc":[{"id":"1.195532866","rc":[{"spn":3.91,"spf":1.0,"id":35676762},{"atb":[[3,5.61]],"id":41529439},{"spn":3.65,"spf":1.0,"id":41529439},{"atb":[[2.52,7.38]],"id":39213014}],"con":true,"img":false}]}
{"op":"mcm","clk":"5322539140","pt":1646321487763,"mc":[{"id":"1.195532866","rc":[{"atb":[[3.25,4.99]],"id":26648132},{"atb":[[3.35,4.77]],"id":43094640}],"con":true,"img":false}]}
{"op":"mcm","clk":"5322539341","pt":1646321490155,"mc":[{"id":"1.195532866","rc":[{"atb":[[3.95,4.21]],"id":35676762}],"con":true,"img":false}]}
{"op":"mcm","clk":"5322540335","pt":1646321503950,"mc":[{"id":"1.195532866","rc":[{"atb":[[2.68,0]],"id":28791281}],"con":true,"img":false}]}
{"op":"mcm","clk":"5322541392","pt":1646321518358,"mc":[{"id":"1.195532866","rc":[{"atb":[[2.76,7.06]],"id":28791281}],"con":true,"img":false}]}
{"op":"mcm","clk":"5322556915","pt":1646321710623,"mc":[{"id":"1.195532866","rc":[{"spn":4.01,"spf":1.0,"id":43094640},{"atb":[[3.85,0]],"id":35676762},{"spn":3.98,"spf":1.0,"id":35676762}],"con":true,"img":false}]}
{"op":"mcm","clk":"5322557122","pt":1646321713240,"mc":[{"id":"1.195532866","rc":[{"atb":[[4.1,3.62]],"id":35676762}],"con":true,"img":false}]}
{"op":"mcm","clk":"5322558199","pt":1646321727647,"mc":[{"id":"1.195532866","rc":[{"atb":[[3.15,0]],"id":26648132},{"atb":[[3.25,0]],"id":43094640},{"atb":[[2.96,0]],"id":41529439},{"atb":[[3.3,0]],"id":39213014}],"con":true,"img":false}]}
{"op":"mcm","clk":"5322558953","pt":1646321737157,"mc":[{"id":"1.195532866","rc":[{"atb":[[2.72,0]],"id":28791281}],"con":true,"img":false}]}
{"op":"mcm","clk":"5322559226","pt":1646321740441,"mc":[{"id":"1.195532866","rc":[{"atb":[[2.8,6.23]],"id":28791281}],"con":true,"img":false}]}
{"op":"mcm","clk":"5322559234","pt":1646321740546,"mc":[{"id":"1.195532866","rc":[{"atb":[[3.35,5.28]],"id":26648132}],"con":true,"img":false}]}
{"op":"mcm","clk":"5322559254","pt":1646321740756,"mc":[{"id":"1.195532866","rc":[{"atb":[[3.1,5.91]],"id":41529439}],"con":true,"img":false}]}
{"op":"mcm","clk":"5322559260","pt":1646321740856,"mc":[{"id":"1.195532866","rc":[{"atb":[[3.45,5.07]],"id":43094640}],"con":true,"img":false}]}
{"op":"mcm","clk":"5322559286","pt":1646321741269,"mc":[{"id":"1.195532866","rc":[{"atb":[[2.56,7.97]],"id":39213014}],"con":true,"img":false}]}
{"op":"mcm","clk":"5322570856","pt":1646321885388,"mc":[{"id":"1.195532866","rc":[{"atb":[[4.4,29.41],[4,83.33],[4.6,11.11],[4.2,46.88]],"id":26648132},{"atl":[[11,4],[12,9.09],[13,12.5],[14,19.23]],"id":26648132},{"atb":[[3.8,89.29],[4,33.33],[3.9,51.72],[4.2,12.5]],"id":43094640},{"atl":[[9.6,4.65],[10,11.11],[11,15],[12,22.73]],"id":43094640},{"spn":4.54,"spf":1.0,"id":43094640},{"atb":[[3.1,71.33],[3,124.83],[3.3,17.37],[3.2,45.39]],"id":28791281},{"atl":[[6.4,7.41],[6.8,17.24],[7.2,24.19],[7.6,37.88]],"id":28791281},{"atb":[[7.2,6.45],[6.4,27.78],[6.8,17.24],[6,50]],"id":35676762},{"atl":[[32,4.84],[36,7.14],[27,1.54],[29,3.57]],"id":35676762},{"spn":7.35,"spf":1.0,"id":35676762},{"atb":[[3.45,40.82],[3.35,63.83],[3.55,15.69],[3.25,111.11]],"id":41529439},{"atl":[[8.2,20.83],[7.4,6.25],[7.8,14.71],[8.6,32.89]],"id":41529439},{"spn":3.93,"spf":1.0,"id":41529439},{"atb":[[3.55,58.82],[3.75,14.55],[3.45,102.04],[3.65,37.74]],"id":39213014},{"atl":[[8.6,13.16],[9,18.75],[8.2,5.56],[9.4,29.76]],"id":39213014}],"con":true,"img":false}]}
{"op":"mcm","clk":"5322571445","pt":1646321892325,"mc":[{"id":"1.195532866","rc":[{"atl":[[18.5,9.2],[24,15.2]],"id":26648132},{"atl":[[17,9.2],[22,15.2]],"id":43094640},{"atl":[[14,9.2],[18,15.2]],"id":39213014}],"con":true,"img":false}]}
{"op":"mcm","clk":"5322571556","pt":1646321893539,"mc":[{"id":"1.195532866","rc":[{"atb":[[4.6,0]],"id":43094640}],"con":true,"img":false}]}
{"op":"mcm","clk":"5322571573","pt":1646321893739,"mc":[{"id":"1.195532866","rc":[{"atb":[[4.1,2]],"id":43094640}],"con":true,"img":false}]}
{"op":"mcm","clk":"5322573972","pt":1646321924048,"mc":[{"id":"1.195532866","rc":[{"atb":[[7.4,5.76]],"id":35676762}],"con":true,"img":false}]}
{"op":"mcm","clk":"5322576342","pt":1646321951474,"mc":[{"id":"1.195532866","rc":[{"spn":4.46,"spf":1.0,"id":43094640},{"atb":[[3.95,0]],"id":35676762},{"spn":7.56,"spf":1.0,"id":35676762}],"con":true,"img":false}]}
{"op":"mcm","clk":"5322576877","pt":1646321957490,"mc":[{"id":"1.195532866","rc":[{"atb":[[3.95,3.75]],"id":43094640}],"con":true,"img":false}]}
{"op":"mcm","clk":"5322577083","pt":1646321959891,"mc":[{"id":"1.195532866","rc":[{"atb":[[3.25,0]],"id":26648132},{"atb":[[3.35,0]],"id":43094640},{"atb":[[3,0]],"id":41529439}],"con":true,"img":false}]}
{"op":"mcm","clk":"5322577333","pt":1646321963122,"mc":[{"id":"1.195532866","rc":[{"atb":[[3.2,5.1]],"id":41529439}],"con":true,"img":false}]}
{"op":"mcm","clk":"5322577342","pt":1646321963175,"mc":[{"id":"1.195532866","rc":[{"atb":[[3.45,4.58]],"id":26648132},{"atb":[[3.55,4.4]],"id":43094640}],"con":true,"img":false}]}
{"op":"mcm","clk":"5322577490","pt":1646321965109,"mc":[{"id":"1.195532866","rc":[{"atb":[[4.3,3.77]],"id":35676762}],"con":true,"img":false}]}
{"op":"mcm","clk":"5322577532","pt":1646321965588,"mc":[{"id":"1.195532866","rc":[{"atb":[[3.95,0]],"id":43094640}],"con":true,"img":false}]}
{"op":"mcm","clk":"5322578268","pt":1646321974595,"mc":[{"id":"1.195532866","rc":[{"atb":[[2.52,0]],"id":39213014}],"con":true,"img":false}]}
{"op":"mcm","clk":"5322578545","pt":1646321977933,"mc":[{"id":"1.195532866","rc":[{"atb":[[2.6,7.02]],"id":39213014}],"con":true,"img":false}]}
{"op":"mcm","clk":"5322578617","pt":1646321978822,"mc":[{"id":"1.195532866","rc":[{"atb":[[2.76,0]],"id":28791281}],"con":true,"img":false}]}
{"op":"mcm","clk":"5322579791","pt":1646321993321,"mc":[{"id":"1.195532866","rc":[{"atb":[[2.84,6.75]],"id":28791281}],"con":true,"img":false}]}
{"op":"mcm","clk":"5322595481","pt":1646322185631,"mc":[{"id":"1.195532866","rc":[{"atb":[[4.1,0]],"id":35676762}],"con":true,"img":false}]}
{"op":"mcm","clk":"5322595741","pt":1646322188313,"mc":[{"id":"1.195532866","rc":[{"atb":[[4.5,3.21]],"id":35676762}],"con":true,"img":false}]}
{"op":"mcm","clk":"5322597123","pt":1646322203356,"mc":[{"id":"1.195532866","rc":[{"atb":[[3.35,0]],"id":26648132},{"atb":[[3.45,0]],"id":43094640},{"atb":[[3.1,0]],"id":41529439}],"con":true,"img":false}]}
{"op":"mcm","clk":"5322597906","pt":1646322212750,"mc":[{"id":"1.195532866","rc":[{"atb":[[2.8,0]],"id":28791281}],"con":true,"img":false}]}
{"op":"mcm","clk":"5322598099","pt":1646322215077,"mc":[{"id":"1.195532866","rc":[{"atb":[[3.3,5.4]],"id":41529439}],"con":true,"img":false}]}
{"op":"mcm","clk":"5322598114","pt":1646322215238,"mc":[{"id":"1.195532866","rc":[{"atb":[[2.4,8.01]],"id":28791281}],"con":true,"img":false}]}
{"op":"mcm","clk":"5322598120","pt":1646322215337,"mc":[{"id":"1.195532866","rc":[{"atb":[[2.56,0]],"id":39213014}],"con":true,"img":false}]}
{"op":"mcm","clk":"5322598133","pt":1646322215563,"mc":[{"id":"1.195532866","rc":[{"atb":[[3.55,4.87]],"id":26648132},{"atb":[[3.65,4.69]],"id":43094640}],"con":true,"img":false}]}
{"op":"mcm","clk":"5322599155","pt":1646322226912,"mc":[{"id":"1.195532866","rc":[{"atb":[[2.64,7.58]],"id":39213014}],"con":true,"img":false}]}
{"op":"mcm","clk":"5322599444","pt":1646322229811,"mc":[{"id":"1.195532866","rc":[{"atb":[[1.01,1002]],"id":41529439}],"con":true,"img":false}]}
{"op":"mcm","clk":"5322599460","pt":1646322229915,"mc":[{"id":"1.195532866","rc":[{"atb":[[1.01,1003.99]],"id":41529439}],"con":true,"img":false}]}
{"op":"mcm","clk":"5322599475","pt":1646322230082,"mc":[{"id":"1.195532866","rc":[{"atb":[[1.01,1002]],"id":41529439}],"con":true,"img":false}]}
{"op":"mcm","clk":"5322599486","pt":1646322230180,"mc":[{"id":"1.195532866","rc":[{"atb":[[1.02,1.99]],"id":41529439}],"con":true,"img":false}]}
{"op":"mcm","clk":"5322599505","pt":1646322230390,"mc":[{"id":"1.195532866","rc":[{"atb":[[1.01,1002]],"id":26648132}],"con":true,"img":false}]}
{"op":"mcm","clk":"5322599520","pt":1646322230600,"mc":[{"id":"1.195532866","rc":[{"atb":[[1.01,1003.99]],"id":26648132}],"con":true,"img":false}]}
{"op":"mcm","clk":"5322599541","pt":1646322230811,"mc":[{"id":"1.195532866","rc":[{"atb":[[1.01,1002]],"id":26648132}],"con":true,"img":false}]}
{"op":"mcm","clk":"5322599554","pt":1646322230912,"mc":[{"id":"1.195532866","rc":[{"atb":[[6,1.99]],"id":26648132}],"con":true,"img":false}]}
{"op":"mcm","clk":"5322599574","pt":1646322231081,"mc":[{"id":"1.195532866","rc":[{"atb":[[4.5,4.99]],"id":26648132},{"atb":[[1.01,1002]],"id":35676762}],"con":true,"img":false}]}
{"op":"mcm","clk":"5322599590","pt":1646322231282,"mc":[{"id":"1.195532866","rc":[{"atb":[[1.01,1003.99]],"id":35676762}],"con":true,"img":false}]}
{"op":"mcm","clk":"5322599612","pt":1646322231601,"mc":[{"id":"1.195532866","rc":[{"atb":[[1.01,1002]],"id":35676762}],"con":true,"img":false}]}
{"op":"mcm","clk":"5322599621","pt":1646322231705,"mc":[{"id":"1.195532866","rc":[{"atb":[[7.6,1.99]],"id":35676762}],"con":true,"img":false}]}
{"op":"mcm","clk":"5322599642","pt":1646322231917,"mc":[{"id":"1.195532866","rc":[{"atb":[[7,3.22]],"id":35676762},{"atb":[[1.01,1002]],"id":39213014}],"con":true,"img":false}]}
{"op":"mcm","clk":"5322599658","pt":1646322232124,"mc":[{"id":"1.195532866","rc":[{"atb":[[1.01,1003.99]],"id":39213014}],"con":true,"img":false}]}
{"op":"mcm","clk":"5322599695","pt":1646322232398,"mc":[{"id":"1.195532866","rc":[{"atb":[[1.01,1002]],"id":39213014}],"con":true,"img":false}]}
{"op":"mcm","clk":"5322599698","pt":1646322232496,"mc":[{"id":"1.195532866","rc":[{"atb":[[4.7,3.64]],"id":39213014}],"con":true,"img":false}]}
{"op":"mcm","clk":"5322599719","pt":1646322232719,"mc":[{"id":"1.195532866","rc":[{"atb":[[1.01,1002]],"id":43094640}],"con":true,"img":false}]}
{"op":"mcm","clk":"5322599738","pt":1646322232930,"mc":[{"id":"1.195532866","rc":[{"atb":[[1.01,1003.99]],"id":43094640}],"con":true,"img":false}]}
{"op":"mcm","clk":"5322599775","pt":1646322233309,"mc":[{"id":"1.195532866","rc":[{"atb":[[1.01,1002]],"id":43094640}],"con":true,"img":false}]}
{"op":"mcm","clk":"5322599799","pt":1646322233506,"mc":[{"id":"1.195532866","rc":[{"atb":[[5.6,1.99]],"id":43094640}],"con":true,"img":false}]}
{"op":"mcm","clk":"5322599818","pt":1646322233714,"mc":[{"id":"1.195532866","rc":[{"atb":[[1.01,1002]],"id":28791281}],"con":true,"img":false}]}
{"op":"mcm","clk":"5322599828","pt":1646322233824,"mc":[{"id":"1.195532866","rc":[{"atb":[[7.4,0]],"id":35676762}],"con":true,"img":false}]}
{"op":"mcm","clk":"5322599849","pt":1646322234034,"mc":[{"id":"1.195532866","rc":[{"atb":[[1.01,1003.99]],"id":28791281}],"con":true,"img":false}]}
{"op":"mcm","clk":"5322599855","pt":1646322234085,"mc":[{"id":"1.195532866","rc":[{"atb":[[7,0]],"id":35676762}],"con":true,"img":false}]}
{"op":"mcm","clk":"5322599863","pt":1646322234186,"mc":[{"id":"1.195532866","rc":[{"atb":[[1.01,1002]],"id":28791281}],"con":true,"img":false}]}
{"op":"mcm","clk":"5322599873","pt":1646322234294,"mc":[{"id":"1.195532866","rc":[{"atb":[[1.02,1.99]],"id":28791281}],"con":true,"img":false}]}
{"op":"mcm","clk":"5322600042","pt":1646322236292,"mc":[{"id":"1.195532866","rc":[{"atb":[[4.5,0]],"id":26648132},{"atb":[[7.6,0]],"id":35676762}],"con":true,"img":false}]}
{"op":"mcm","clk":"5322600052","pt":1646322236398,"mc":[{"id":"1.195532866","rc":[{"atb":[[7.4,1.99]],"id":35676762}],"con":true,"img":false}]}
{"op":"mcm","clk":"5322600098","pt":1646322237027,"mc":[{"id":"1.195532866","rc":[{"atb":[[2.5,68],[3,46]],"id":26648132},{"atb":[[2.84,50],[2.36,75]],"id":43094640}],"con":true,"img":false}]}
{"op":"mcm","clk":"5322600135","pt":1646322237405,"mc":[{"id":"1.195532866","rc":[{"atb":[[7.8,2.4]],"id":35676762}],"con":true,"img":false}]}
{"op":"mcm","clk":"5322600236","pt":1646322238521,"mc":[{"id":"1.195532866","rc":[{"atb":[[7.4,0]],"id":35676762}],"con":true,"img":false}]}
{"op":"mcm","clk":"5322600243","pt":1646322238616,"mc":[{"id":"1.195532866","rc":[{"atb":[[8,1.99]],"id":35676762}],"con":true,"img":false}]}
{"op":"mcm","clk":"5322600432","pt":1646322240534,"mc":[{"id":"1.195532866","rc":[{"atb":[[7.8,0]],"id":35676762}],"con":true,"img":false}]}
{"op":"mcm","clk":"5322600497","pt":1646322241121,"mc":[{"id":"1.195532866","rc":[{"atb":[[8,0]],"id":35676762}],"con":true,"img":false}]}
{"op":"mcm","clk":"5322600507","pt":1646322241228,"mc":[{"id":"1.195532866","rc":[{"atb":[[7.4,1.99]],"id":35676762}],"con":true,"img":false}]}
{"op":"mcm","clk":"5322600812","pt":1646322244110,"mc":[{"id":"1.195532866","rc":[{"atb":[[7.6,2.4]],"id":35676762}],"con":true,"img":false}]}
{"op":"mcm","clk":"5322600946","pt":1646322245745,"mc":[{"id":"1.195532866","rc":[{"spn":8.0,"spf":1.0,"id":26648132},{"spn":4.73,"spf":1.0,"id":43094640},{"atb":[[7.4,0]],"id":35676762},{"spn":7.54,"spf":1.0,"id":35676762}],"con":true,"img":false}]}
{"op":"mcm","clk":"5322600955","pt":1646322245841,"mc":[{"id":"1.195532866","rc":[{"atb":[[7.8,1.99]],"id":35676762}],"con":true,"img":false}]}
{"op":"mcm","clk":"5322601236","pt":1646322248914,"mc":[{"id":"1.195532866","rc":[{"atb":[[7.6,0]],"id":35676762}],"con":true,"img":false}]}
{"op":"mcm","clk":"5322601351","pt":1646322250015,"mc":[{"id":"1.195532866","rc":[{"atb":[[7.8,0]],"id":35676762}],"con":true,"img":false}]}
{"op":"mcm","clk":"5322601361","pt":1646322250123,"mc":[{"id":"1.195532866","rc":[{"atb":[[7.4,1.99]],"id":35676762}],"con":true,"img":false}]}
{"op":"mcm","clk":"5322601587","pt":1646322252528,"mc":[{"id":"1.195532866","rc":[{"atb":[[7.6,2.4]],"id":35676762}],"con":true,"img":false}]}
{"op":"mcm","clk":"5322601658","pt":1646322253226,"mc":[{"id":"1.195532866","rc":[{"atb":[[7.4,0]],"id":35676762}],"con":true,"img":false}]}
{"op":"mcm","clk":"5322601671","pt":1646322253332,"mc":[{"id":"1.195532866","rc":[{"atb":[[7.8,1.99]],"id":35676762}],"con":true,"img":false}]}
{"op":"mcm","clk":"5322601893","pt":1646322255739,"mc":[{"id":"1.195532866","rc":[{"atb":[[7.6,0]],"id":35676762}],"con":true,"img":false}]}
{"op":"mcm","clk":"5322602093","pt":1646322257538,"mc":[{"id":"1.195532866","rc":[{"atb":[[7.8,0]],"id":35676762}],"con":true,"img":false}]}
{"op":"mcm","clk":"5322602104","pt":1646322257629,"mc":[{"id":"1.195532866","rc":[{"atb":[[7.4,1.99]],"id":35676762}],"con":true,"img":false}]}
{"op":"mcm","clk":"5322602305","pt":1646322259333,"mc":[{"id":"1.195532866","rc":[{"atb":[[7.4,6.81]],"id":35676762}],"con":true,"img":false}]}
{"op":"mcm","clk":"5322604314","pt":1646322280281,"mc":[{"id":"1.195532866","rc":[{"spb":[[1000,11]],"id":35676762}],"con":true,"img":false}]}
{"op":"mcm","clk":"5322617584","pt":1646322423183,"mc":[{"id":"1.195532866","rc":[{"atb":[[4.3,0]],"id":35676762},{"spn":7.65,"spf":2.1,"id":35676762}],"con":true,"img":false}]}
{"op":"mcm","clk":"5322618921","pt":1646322438016,"mc":[{"id":"1.195532866","rc":[{"atb":[[3.45,0]],"id":26648132},{"atb":[[3.55,0]],"id":43094640},{"atb":[[3.2,0]],"id":41529439}],"con":true,"img":false}]}
{"op":"mcm","clk":"5322618948","pt":1646322438329,"mc":[{"id":"1.195532866","rc":[{"atb":[[4.7,3.35]],"id":35676762}],"con":true,"img":false}]}
{"op":"mcm","clk":"5322619197","pt":1646322440797,"mc":[{"id":"1.195532866","rc":[{"atb":[[3.65,4.23]],"id":26648132},{"atb":[[2.36,8.25]],"id":41529439}],"con":true,"img":false}]}
{"op":"mcm","clk":"5322619203","pt":1646322440898,"mc":[{"id":"1.195532866","rc":[{"atb":[[3.75,4.07]],"id":43094640}],"con":true,"img":false}]}
{"op":"mcm","clk":"5322619974","pt":1646322449641,"mc":[{"id":"1.195532866","rc":[{"atb":[[2.6,0]],"id":39213014}],"con":true,"img":false}]}
{"op":"mcm","clk":"5322620242","pt":1646322452627,"mc":[{"id":"1.195532866","rc":[{"atb":[[2.68,6.68]],"id":39213014}],"con":true,"img":false}]}
{"op":"mcm","clk":"5322637607","pt":1646322593520,"mc":[{"id":"1.195532866","rc":[{"atb":[[2.84,0]],"id":28791281}],"con":true,"img":false}]}
{"op":"mcm","clk":"5322639721","pt":1646322621220,"mc":[{"id":"1.195532866","rc":[{"atb":[[2.44,8.63]],"id":28791281}],"con":true,"img":false}]}
{"op":"mcm","clk":"5322644695","pt":1646322657200,"mc":[{"id":"1.195532866","rc":[{"atb":[[4.5,0]],"id":35676762}],"con":true,"img":false}]}
{"op":"mcm","clk":"5322645730","pt":1646322664128,"mc":[{"id":"1.195532866","rc":[{"atb":[[4.7,0.65]],"id":39213014},{"trd":[[4.7,5.99]],"ltp":4.7,"tv":5.99,"id":39213014}],"con":true,"img":false}]}
{"op":"mcm","clk":"5322645773","pt":1646322664441,"mc":[{"id":"1.195532866","rc":[{"atb":[[4.8,1.65]],"id":39213014}],"con":true,"img":false}]}
{"op":"mcm","clk":"5322645895","pt":1646322665443,"mc":[{"id":"1.195532866","rc":[{"atl":[[1000,4.52]],"id":39213014}],"con":true,"img":false}]}
{"op":"mcm","clk":"5322645916","pt":1646322665606,"mc":[{"id":"1.195532866","rc":[{"atl":[[1000,4.1]],"id":39213014}],"con":true,"img":false}]}
{"op":"mcm","clk":"5322645943","pt":1646322665809,"mc":[{"id":"1.195532866","rc":[{"atl":[[1000,2]],"id":39213014}],"con":true,"img":false}]}
{"op":"mcm","clk":"5322645981","pt":1646322666032,"mc":[{"id":"1.195532866","rc":[{"atl":[[7.6,2.1]],"id":39213014}],"con":true,"img":false}]}
{"op":"mcm","clk":"5322647250","pt":1646322675137,"mc":[{"id":"1.195532866","rc":[{"atb":[[3.55,0]],"id":26648132},{"atb":[[3.65,0]],"id":43094640},{"atb":[[3.3,0]],"id":41529439},{"atb":[[2.64,0]],"id":39213014}],"con":true,"img":false}]}
{"op":"mcm","clk":"5322647265","pt":1646322675239,"mc":[{"id":"1.195532866","rc":[{"atb":[[2.44,0]],"id":28791281},{"atb":[[4.7,0]],"id":35676762}],"con":true,"img":false}]}
{"op":"mcm","clk":"5322647762","pt":1646322679053,"mc":[{"id":"1.195532866","rc":[{"atb":[[2.88,5.97]],"id":35676762}],"con":true,"img":false}]}
{"op":"mcm","clk":"5322652621","pt":1646322726731,"mc":[{"id":"1.195532866","rc":[{"atb":[[4.8,0]],"id":39213014},{"spn":6.15,"spf":1.0,"id":39213014}],"con":true,"img":false}]}
{"op":"mcm","clk":"5322652643","pt":1646322727042,"mc":[{"id":"1.195532866","rc":[{"atb":[[4.9,1.65]],"id":39213014}],"con":true,"img":false}]}
{"op":"mcm","clk":"5322653833","pt":1646322739392,"mc":[{"id":"1.195532866","rc":[{"atb":[[4.9,0]],"id":39213014},{"atl":[[4.8,0.34]],"id":39213014},{"trd":[[4.9,3.31]],"ltp":4.9,"tv":3.31,"id":39213014}],"con":true,"img":false}]}
{"op":"mcm","clk":"5322653854","pt":1646322739603,"mc":[{"id":"1.195532866","rc":[{"atb":[[3.55,0]],"id":28791281},{"atb":[[4.1,0]],"id":39213014},{"atl":[[8.2,0],[6.6,7.14]],"id":39213014}],"con":true,"img":false}]}
{"op":"mcm","clk":"5322653872","pt":1646322739707,"mc":[{"id":"1.195532866","rc":[{"atb":[[2.5,2]],"id":28791281},{"atl":[[8.4,4.35]],"id":39213014}],"con":true,"img":false}]}
{"op":"mcm","clk":"5322653928","pt":1646322740180,"mc":[{"id":"1.195532866","rc":[{"atl":[[7.6,0]],"id":39213014}],"con":true,"img":false}]}
{"op":"mcm","clk":"5322654090","pt":1646322741697,"mc":[{"id":"1.195532866","rc":[{"atl":[[8.4,0]],"id":39213014}],"con":true,"img":false}]}
{"op":"mcm","clk":"5322655002","pt":1646322749601,"mc":[{"id":"1.195532866","rc":[{"atl":[[7,16.67]],"id":39213014}],"con":true,"img":false}]}
{"op":"mcm","clk":"5322655094","pt":1646322750386,"mc":[{"id":"1.195532866","rc":[{"atl":[[4.8,0]],"id":39213014}],"con":true,"img":false}]}
{"op":"mcm","clk":"5322655109","pt":1646322750491,"mc":[{"id":"1.195532866","rc":[{"atb":[[4.7,0.31]],"id":39213014},{"trd":[[4.7,6.67]],"ltp":4.7,"tv":6.67,"id":39213014}],"con":true,"img":false}]}
{"op":"mcm","clk":"5322655564","pt":1646322754608,"mc":[{"id":"1.195532866","rc":[{"atb":[[7.8,2],[5.9,0]],"id":26648132},{"atb":[[4.6,0],[3.7,2]],"id":41529439}],"con":true,"img":false}]}
{"op":"mcm","clk":"5322655589","pt":1646322754819,"mc":[{"id":"1.195532866","rc":[{"atl":[[7,0]],"id":41529439},{"atl":[[9.4,0],[6.6,0],[7,6.67]],"id":39213014}],"con":true,"img":false}]}
{"op":"mcm","clk":"5322655605","pt":1646322754924,"mc":[{"id":"1.195532866","rc":[{"atl":[[6.8,1.73]],"id":41529439}],"con":true,"img":false}]}
{"op":"mcm","clk":"5322655643","pt":1646322755295,"mc":[{"id":"1.195532866","rc":[{"atb":[[6,0]],"id":26648132}],"con":true,"img":false}]}
{"op":"mcm","clk":"5322655654","pt":1646322755400,"mc":[{"id":"1.195532866","rc":[{"atb":[[1.02,1.99]],"id":26648132}],"con":true,"img":false}]}
{"op":"mcm","clk":"5322656590","pt":1646322764817,"mc":[{"id":"1.195532866","rc":[{"atl":[[7.4,0],[7.2,6.45]],"id":41529439},{"atl":[[7.4,15.62]],"id":39213014}],"con":true,"img":false}]}
{"op":"mcm","clk":"5322657470","pt":1646322774851,"mc":[{"id":"1.195532866","rc":[{"atl":[[7.4,6.25],[7,0]],"id":39213014}],"con":true,"img":false}]}
{"op":"mcm","clk":"5322657610","pt":1646322776727,"mc":[{"id":"1.195532866","rc":[{"atb":[[7.2,0],[7.6,6.06]],"id":35676762}],"con":true,"img":false}]}
{"op":"mcm","clk":"5322657630","pt":1646322776935,"mc":[{"id":"1.195532866","rc":[{"atb":[[7,3.46]],"id":35676762}],"con":true,"img":false}]}
{"op":"mcm","clk":"5322657686","pt":1646322777463,"mc":[{"id":"1.195532866","rc":[{"atb":[[7.4,4.82]],"id":35676762}],"con":true,"img":false}]}
{"op":"mcm","clk":"5322657701","pt":1646322777566,"mc":[{"id":"1.195532866","rc":[{"atb":[[7.8,1.99]],"id":35676762}],"con":true,"img":false}]}
{"op":"mcm","clk":"5322657763","pt":1646322778137,"mc":[{"id":"1.195532866","rc":[{"atb":[[7,0]],"id":35676762}],"con":true,"img":false}]}
{"op":"mcm","clk":"5322657798","pt":1646322778555,"mc":[{"id":"1.195532866","rc":[{"atb":[[7.4,0]],"id":35676762}],"con":true,"img":false}]}
{"op":"mcm","clk":"5322657932","pt":1646322780407,"mc":[{"id":"1.195532866","rc":[{"atb":[[3.7,17.69]],"id":41529439},{"atl":[[7.4,15.62]],"id":41529439}],"con":true,"img":false}]}
{"op":"mcm","clk":"5322657944","pt":1646322780426,"mc":[{"id":"1.195532866","rc":[{"atb":[[6.6,17.86]],"id":35676762},{"atl":[[27,5.11]],"id":35676762},{"atb":[[3.7,2],[3.55,54.91]],"id":41529439},{"atb":[[3.65,75.48]],"id":39213014},{"atl":[[8.6,26.32]],"id":39213014}],"con":true,"img":false}]}
{"op":"mcm","clk":"5322657965","pt":1646322780542,"mc":[{"id":"1.195532866","rc":[{"atb":[[3.55,15.69],[3.75,17.69]],"id":41529439}],"con":true,"img":false}]}
{"op":"mcm","clk":"5322658035","pt":1646322781225,"mc":[{"id":"1.195532866","rc":[{"atl":[[1000,4.52]],"id":35676762}],"con":true,"img":false}]}
{"op":"mcm","clk":"5322658055","pt":1646322781434,"mc":[{"id":"1.195532866","rc":[{"atl":[[1000,3.26]],"id":35676762}],"con":true,"img":false}]}
{"op":"mcm","clk":"5322658064","pt":1646322781543,"mc":[{"id":"1.195532866","rc":[{"atl":[[1000,2]],"id":35676762}],"con":true,"img":false}]}
{"op":"mcm","clk":"5322658075","pt":1646322781645,"mc":[{"id":"1.195532866","rc":[{"atl":[[26,1.87]],"id":35676762}],"con":true,"img":false}]}
{"op":"mcm","clk":"5322658108","pt":1646322782035,"mc":[{"id":"1.195532866","rc":[{"atb":[[4.9,25.64]],"id":26648132},{"atl":[[11.5,9.09]],"id":26648132},{"atb":[[3.45,40.82]],"id":43094640},{"atl":[[10,22.22]],"id":43094640},{"atb":[[3.4,41.67]],"id":28791281},{"atl":[[6.4,24.65]],"id":28791281},{"atb":[[3.55,0],[3.3,17.39],[3.75,0],[3.45,0],[4.1,0]],"id":41529439},{"atl":[[7.4,0],[7.8,7.36]],"id":39213014}],"con":true,"img":false}]}
{"op":"mcm","clk":"5322658125","pt":1646322782173,"mc":[{"id":"1.195532866","rc":[{"atb":[[8,2.4]],"id":35676762},{"atl":[[8.6,13.16],[7.6,15.15]],"id":39213014}],"con":true,"img":false}]}
{"op":"mcm","clk":"5322658136","pt":1646322782282,"mc":[{"id":"1.195532866","rc":[{"atb":[[4.5,5]],"id":26648132},{"atb":[[3.15,9.08]],"id":28791281},{"atb":[[3.6,38.46],[3.3,19.39]],"id":41529439}],"con":true,"img":false}]}
{"op":"mcm","clk":"5322658147","pt":1646322782352,"mc":[{"id":"1.195532866","rc":[{"atl":[[8.6,26.32],[7.6,0]],"id":39213014}],"con":true,"img":false}]}
{"op":"mcm","clk":"5322658156","pt":1646322782448,"mc":[{"id":"1.195532866","rc":[{"atb":[[4.5,0]],"id":26648132}],"con":true,"img":false}]}
{"op":"mcm","clk":"5322658193","pt":1646322782779,"mc":[{"id":"1.195532866","rc":[{"atb":[[1.02,0]],"id":41529439}],"con":true,"img":false}]}
{"op":"mcm","clk":"5322658203","pt":1646322782871,"mc":[{"id":"1.195532866","rc":[{"atb":[[3.75,1.99]],"id":41529439}],"con":true,"img":false}]}
{"op":"mcm","clk":"5322658229","pt":1646322783137,"mc":[{"id":"1.195532866","rc":[{"atb":[[7.8,0]],"id":35676762}],"con":true,"img":false}]}
{"op":"mcm","clk":"5322658236","pt":1646322783254,"mc":[{"id":"1.195532866","rc":[{"atb":[[8.2,1.99]],"id":35676762}],"con":true,"img":false}]}
{"op":"mcm","clk":"5322658305","pt":1646322783879,"mc":[{"id":"1.195532866","rc":[{"atb":[[3.4,39.33]],"id":41529439}],"con":true,"img":false}]}
{"op":"mcm","clk":"5322658350","pt":1646322784348,"mc":[{"id":"1.195532866","rc":[{"atb":[[3.15,0]],"id":28791281}],"con":true,"img":false}]}
{"op":"mcm","clk":"5322658437","pt":1646322785661,"mc":[{"id":"1.195532866","rc":[{"atb":[[8,0]],"id":35676762}],"con":true,"img":false}]}
{"op":"mcm","clk":"5322658523","pt":1646322786665,"mc":[{"id":"1.195532866","rc":[{"atb":[[8.2,0],[7.2,16.13]],"id":35676762}],"con":true,"img":false}]}
{"op":"mcm","clk":"5322658533","pt":1646322786768,"mc":[{"id":"1.195532866","rc":[{"spn":8.9,"spf":1.0,"id":26648132},{"atb":[[7.8,1.99]],"id":35676762},{"spn":7.88,"spf":2.1,"id":35676762},{"spn":3.66,"spf":1.0,"id":41529439},{"spn":6.25,"spf":1.0,"id":39213014}],"con":true,"img":false}]}
{"op":"mcm","clk":"5322658573","pt":1646322787284,"mc":[{"id":"1.195532866","rc":[{"atl":[[11.5,0],[12,18.18]],"id":26648132}],"con":true,"img":false}]}
{"op":"mcm","clk":"5322658589","pt":1646322787456,"mc":[{"id":"1.195532866","rc":[{"atb":[[3.4,0]],"id":41529439},{"atl":[[8.6,13.16],[9,31.25]],"id":39213014}],"con":true,"img":false}]}
{"op":"mcm","clk":"5322658752","pt":1646322789388,"mc":[{"id":"1.195532866","rc":[{"atb":[[8,2.4]],"id":35676762}],"con":true,"img":false}]}
{"op":"mcm","clk":"5322658847","pt":1646322790495,"mc":[{"id":"1.195532866","rc":[{"atb":[[7.8,0]],"id":35676762}],"con":true,"img":false}]}
{"op":"mcm","clk":"5322658857","pt":1646322790563,"mc":[{"id":"1.195532866","rc":[{"atb":[[8.2,1.99]],"id":35676762}],"con":true,"img":false}]}
{"op":"mcm","clk":"5322658974","pt":1646322791978,"mc":[{"id":"1.195532866","rc":[{"atb":[[3.2,45.45],[3.35,0]],"id":41529439},{"atl":[[8.2,5.56],[7.8,1.48]],"id":39213014}],"con":true,"img":false}]}
{"op":"mcm","clk":"5322658994","pt":1646322792186,"mc":[{"id":"1.195532866","rc":[{"atb":[[3.4,0]],"id":28791281},{"atl":[[9.2,9.37]],"id":39213014}],"con":true,"img":false}]}
{"op":"mcm","clk":"5322659004","pt":1646322792291,"mc":[{"id":"1.195532866","rc":[{"atb":[[3.45,40.82]],"id":28791281}],"con":true,"img":false}]}
{"op":"mcm","clk":"5322659015","pt":1646322792401,"mc":[{"id":"1.195532866","rc":[{"atl":[[9.2,0]],"id":39213014}],"con":true,"img":false}]}
{"op":"mcm","clk":"5322659060","pt":1646322792760,"mc":[{"id":"1.195532866","rc":[{"atb":[[8,0]],"id":35676762}],"con":true,"img":false}]}
{"op":"mcm","clk":"5322659088","pt":1646322793068,"mc":[{"id":"1.195532866","rc":[{"atb":[[8.2,0]],"id":35676762}],"con":true,"img":false}]}
{"op":"mcm","clk":"5322659095","pt":1646322793175,"mc":[{"id":"1.195532866","rc":[{"atb":[[7.8,1.99]],"id":35676762}],"con":true,"img":false}]}
{"op":"mcm","clk":"5322659456","pt":1646322796372,"mc":[{"id":"1.195532866","rc":[{"atb":[[8,2.4]],"id":35676762}],"con":true,"img":false}]}
{"op":"mcm","clk":"5322659501","pt":1646322796686,"mc":[{"id":"1.195532866","rc":[{"atb":[[6.8,43.1]],"id":35676762}],"con":true,"img":false}]}
{"op":"mcm","clk":"5322659513","pt":1646322796789,"mc":[{"id":"1.195532866","rc":[{"atb":[[6.8,25.86],[6,0]],"id":35676762}],"con":true,"img":false}]}
{"op":"mcm","clk":"5322659594","pt":1646322797583,"mc":[{"id":"1.195532866","rc":[{"atl":[[8.6,26.32],[9,18.75]],"id":39213014}],"con":true,"img":false}]}
{"op":"mcm","clk":"5322659638","pt":1646322797994,"mc":[{"id":"1.195532866","rc":[{"atb":[[7.8,0]],"id":35676762}],"con":true,"img":false}]}
{"op":"mcm","clk":"5322659644","pt":1646322798102,"mc":[{"id":"1.195532866","rc":[{"atb":[[8.2,1.99]],"id":35676762}],"con":true,"img":false}]}
{"op":"mcm","clk":"5322659983","pt":1646322801175,"mc":[{"id":"1.195532866","rc":[{"atb":[[8,0]],"id":35676762}],"con":true,"img":false}]}
{"op":"mcm","clk":"5322660028","pt":1646322801596,"mc":[{"id":"1.195532866","rc":[{"atb":[[8.2,0]],"id":35676762}],"con":true,"img":false}]}
{"op":"mcm","clk":"5322660039","pt":1646322801697,"mc":[{"id":"1.195532866","rc":[{"atb":[[7.8,1.99]],"id":35676762}],"con":true,"img":false}]}
{"op":"mcm","clk":"5322660069","pt":1646322802021,"mc":[{"id":"1.195532866","rc":[{"atb":[[3.1,71.43]],"id":41529439},{"atl":[[9.4,29.76]],"id":39213014}],"con":true,"img":false}]}
{"op":"mcm","clk":"5322660337","pt":1646322804679,"mc":[{"id":"1.195532866","rc":[{"atb":[[8,2.4]],"id":35676762}],"con":true,"img":false}]}
{"op":"mcm","clk":"5322660386","pt":1646322805299,"mc":[{"id":"1.195532866","rc":[{"atb":[[7.8,0]],"id":35676762}],"con":true,"img":false}]}
{"op":"mcm","clk":"5322660396","pt":1646322805408,"mc":[{"id":"1.195532866","rc":[{"atb":[[8.2,1.99]],"id":35676762}],"con":true,"img":false}]}
{"op":"mcm","clk":"5322660511","pt":1646322806807,"mc":[{"id":"1.195532866","rc":[{"atb":[[6.4,46.3]],"id":35676762}],"con":true,"img":false}]}
{"op":"mcm","clk":"5322660620","pt":1646322808016,"mc":[{"id":"1.195532866","rc":[{"atb":[[8,0]],"id":35676762}],"con":true,"img":false}]}
{"op":"mcm","clk":"5322660813","pt":1646322809698,"mc":[{"id":"1.195532866","rc":[{"atb":[[8.2,0]],"id":35676762}],"con":true,"img":false}]}
{"op":"mcm","clk":"5322660825","pt":1646322809803,"mc":[{"id":"1.195532866","rc":[{"atb":[[7.8,1.99]],"id":35676762}],"con":true,"img":false}]}
{"op":"mcm","clk":"5322660963","pt":1646322811317,"mc":[{"id":"1.195532866","rc":[{"atb":[[5.1,9.76],[4.6,0]],"id":26648132},{"atb":[[3.5,40],[3.45,0]],"id":28791281},{"atb":[[7.6,0]],"id":35676762},{"atb":[[3.6,0],[3.2,18.18],[3.3,2]],"id":41529439}],"con":true,"img":false}]}
{"op":"mcm","clk":"5322660973","pt":1646322811386,"mc":[{"id":"1.195532866","rc":[{"atb":[[5.6,2]],"id":26648132},{"atl":[[10.5,0],[12,9.09],[13.5,8.2]],"id":26648132},{"atb":[[8,5.71]],"id":35676762},{"atb":[[3.55,9.61],[3.5,40]],"id":41529439}],"con":true,"img":false}]}
{"op":"mcm","clk":"5322660984","pt":1646322811488,"mc":[{"id":"1.195532866","rc":[{"atl":[[12.5,0.88]],"id":26648132}],"con":true,"img":false}]}
{"op":"mcm","clk":"5322661113","pt":1646322812795,"mc":[{"id":"1.195532866","rc":[{"atb":[[3.55,0]],"id":41529439}],"con":true,"img":false}]}
{"op":"mcm","clk":"5322661134","pt":1646322813006,"mc":[{"id":"1.195532866","rc":[{"atb":[[8,8.11],[7.8,0]],"id":35676762}],"con":true,"img":false}]}
{"op":"mcm","clk":"5322661144","pt":1646322813108,"mc":[{"id":"1.195532866","rc":[{"atb":[[8.2,1.99]],"id":35676762}],"con":true,"img":false}]}
{"op":"mcm","clk":"5322661373","pt":1646322816183,"mc":[{"id":"1.195532866","rc":[{"atb":[[8,5.71]],"id":35676762}],"con":true,"img":false}]}
{"op":"mcm","clk":"5322661388","pt":1646322816390,"mc":[{"id":"1.195532866","rc":[{"atb":[[3.5,0],[3.45,40.82]],"id":28791281}],"con":true,"img":false}]}
{"op":"mcm","clk":"5322661403","pt":1646322816595,"mc":[{"id":"1.195532866","rc":[{"atb":[[3.5,0],[3.45,18.18]],"id":41529439}],"con":true,"img":false}]}
{"op":"mcm","clk":"5322661797","pt":1646322821321,"mc":[{"id":"1.195532866","rc":[{"atb":[[4.9,51.28]],"id":26648132},{"atb":[[7.6,15.15]],"id":35676762},{"atb":[[3.1,47.62],[3.25,0]],"id":41529439}],"con":true,"img":false}]}
{"op":"mcm","clk":"5322662726","pt":1646322831336,"mc":[{"id":"1.195532866","rc":[{"atb":[[4.4,0],[4,0],[4.2,0],[4.7,40.54]],"id":26648132},{"atb":[[6.4,0],[7.2,24.19]],"id":35676762},{"atb":[[3,75],[3.05,10.56]],"id":41529439}],"con":true,"img":false}]}
{"op":"mcm","clk":"5322662751","pt":1646322831611,"mc":[{"id":"1.195532866","rc":[{"atb":[[3.05,0]],"id":41529439}],"con":true,"img":false}]}
{"op":"mcm","clk":"5322663167","pt":1646322836225,"mc":[{"id":"1.195532866","rc":[{"atb":[[2.72,7.22]],"id":39213014}],"con":true,"img":false}]}
{"op":"mcm","clk":"5322663183","pt":1646322836434,"mc":[{"id":"1.195532866","rc":[{"atb":[[3.55,4.87]],"id":43094640}],"con":true,"img":false}]}
{"op":"mcm","clk":"5322663207","pt":1646322836741,"mc":[{"id":"1.195532866","rc":[{"atb":[[2.4,8.87]],"id":41529439}],"con":true,"img":false}]}
{"op":"mcm","clk":"5322663528","pt":1646322840056,"mc":[{"id":"1.195532866","rc":[{"atb":[[1.04,2.89]],"id":28791281},{"atb":[[1.04,2.89]],"id":41529439}],"con":true,"img":false}]}
{"op":"mcm","clk":"5322663538","pt":1646322840166,"mc":[{"id":"1.195532866","rc":[{"atb":[[1.04,2.87]],"id":43094640},{"atb":[[1.04,2.88]],"id":39213014}],"con":true,"img":false}]}
{"op":"mcm","clk":"5322663597","pt":1646322840573,"mc":[{"id":"1.195532866","rc":[{"atb":[[1.04,0.14]],"id":28791281},{"atb":[[1.04,0.14]],"id":41529439}],"con":true,"img":false}]}
{"op":"mcm","clk":"5322663609","pt":1646322840636,"mc":[{"id":"1.195532866","rc":[{"atb":[[1.04,0.12]],"id":43094640},{"atb":[[1.04,0.13]],"id":39213014}],"con":true,"img":false}]}
{"op":"mcm","clk":"5322663642","pt":1646322840948,"mc":[{"id":"1.195532866","rc":[{"atb":[[1.04,0]],"id":28791281},{"atb":[[1.04,0]],"id":41529439}],"con":true,"img":false}]}
{"op":"mcm","clk":"5322663652","pt":1646322841045,"mc":[{"id":"1.195532866","rc":[{"atb":[[1.04,0]],"id":43094640},{"atb":[[3.75,0.14]],"id":28791281},{"atb":[[3.75,2.13]],"id":41529439},{"atb":[[1.04,0]],"id":39213014}],"con":true,"img":false}]}
{"op":"mcm","clk":"5322663661","pt":1646322841158,"mc":[{"id":"1.195532866","rc":[{"atb":[[4.3,0.12]],"id":43094640},{"atb":[[3.95,0.13]],"id":39213014}],"con":true,"img":false}]}
{"op":"mcm","clk":"5322663674","pt":1646322841254,"mc":[{"id":"1.195532866","rc":[{"atb":[[3.25,4.91]],"id":28791281}],"con":true,"img":false}]}
{"op":"mcm","clk":"5322663684","pt":1646322841370,"mc":[{"id":"1.195532866","rc":[{"atb":[[4.5,71.43]],"id":26648132},{"atb":[[4.1,6.99]],"id":43094640},{"atb":[[6.8,43.1]],"id":35676762},{"atb":[[2.96,127.55]],"id":41529439}],"con":true,"img":false}]}
{"op":"mcm","clk":"5322663878","pt":1646322843044,"mc":[{"id":"1.195532866","rc":[{"atb":[[4.1,2]],"id":43094640},{"atb":[[3.25,0]],"id":28791281}],"con":true,"img":false}]}
{"op":"mcm","clk":"5322664415","pt":1646322848052,"mc":[{"id":"1.195532866","rc":[{"spn":4.73,"spf":1.0,"id":43094640},{"atb":[[2.54,8.07]],"id":28791281},{"spn":4.87,"spf":1.0,"id":28791281},{"spn":8.22,"spf":2.1,"id":35676762},{"spn":3.58,"spf":1.0,"id":41529439}],"con":true,"img":false}]}
{"op":"mcm","clk":"5322664451","pt":1646322848366,"mc":[{"id":"1.195532866","rc":[{"atb":[[2.92,6.47]],"id":35676762}],"con":true,"img":false}]}
{"op":"mcm","clk":"5322664701","pt":1646322850568,"mc":[{"id":"1.195532866","rc":[{"atl":[[7,15]],"id":39213014}],"con":true,"img":false}]}
{"op":"mcm","clk":"5322664717","pt":1646322850774,"mc":[{"id":"1.195532866","rc":[{"atl":[[8.6,13.16],[8.8,4.35],[7,20.56]],"id":39213014}],"con":true,"img":false}]}
{"op":"mcm","clk":"5322664763","pt":1646322851186,"mc":[{"id":"1.195532866","rc":[{"atl":[[8.8,0]],"id":39213014}],"con":true,"img":false}]}
{"op":"mcm","clk":"5322664806","pt":1646322851552,"mc":[{"id":"1.195532866","rc":[{"atl":[[6.8,2.88]],"id":39213014}],"con":true,"img":false}]}
{"op":"mcm","clk":"5322664901","pt":1646322852588,"mc":[{"id":"1.195532866","rc":[{"atl":[[6.8,0]],"id":41529439}],"con":true,"img":false}]}
{"op":"mcm","clk":"5322664913","pt":1646322852652,"mc":[{"id":"1.195532866","rc":[{"atl":[[6,2]],"id":41529439}],"con":true,"img":false}]}
{"op":"mcm","clk":"5322664920","pt":1646322852757,"mc":[{"id":"1.195532866","rc":[{"atl":[[7.4,0],[7.8,29.42]],"id":41529439}],"con":true,"img":false}]}
{"op":"mcm","clk":"5322664945","pt":1646322852958,"mc":[{"id":"1.195532866","rc":[{"atl":[[7.8,33.08]],"id":41529439}],"con":true,"img":false}]}
{"op":"mcm","clk":"5322664964","pt":1646322853167,"mc":[{"id":"1.195532866","rc":[{"atb":[[2.5,0]],"id":28791281},{"atl":[[7.8,29.42]],"id":41529439}],"con":true,"img":false}]}
{"op":"mcm","clk":"5322665284","pt":1646322856480,"mc":[{"id":"1.195532866","rc":[{"atb":[[2.4,0]],"id":28791281}],"con":true,"img":false}]}
{"op":"mcm","clk":"5322665484","pt":1646322858259,"mc":[{"id":"1.195532866","rc":[{"atl":[[1000,3.65]],"id":35676762}],"con":true,"img":false}]}
{"op":"mcm","clk":"5322665495","pt":1646322858357,"mc":[{"id":"1.195532866","rc":[{"atl":[[1000,2.17]],"id":35676762}],"con":true,"img":false}]}
{"op":"mcm","clk":"5322665522","pt":1646322858576,"mc":[{"id":"1.195532866","rc":[{"atl":[[1000,2]],"id":35676762}],"con":true,"img":false}]}
{"op":"mcm","clk":"5322665536","pt":1646322858677,"mc":[{"id":"1.195532866","rc":[{"atl":[[24,0.17]],"id":35676762}],"con":true,"img":false}]}
{"op":"mcm","clk":"5322665561","pt":1646322858885,"mc":[{"id":"1.195532866","rc":[{"atl":[[25,2.14],[27,1.54]],"id":35676762}],"con":true,"img":false}]}
{"op":"mcm","clk":"5322665574","pt":1646322859094,"mc":[{"id":"1.195532866","rc":[{"atb":[[2.58,7.1]],"id":28791281}],"con":true,"img":false}]}
{"op":"mcm","clk":"5322665620","pt":1646322859675,"mc":[{"id":"1.195532866","rc":[{"atl":[[26,0.61]],"id":35676762}],"con":true,"img":false}]}
{"op":"mcm","clk":"5322666010","pt":1646322864064,"mc":[{"id":"1.195532866","rc":[{"atl":[[25,0.14],[26,2.93]],"id":35676762}],"con":true,"img":false}]}
{"op":"mcm","clk":"5322668015","pt":1646322888406,"mc":[{"id":"1.195532866","rc":[{"atl":[[1000,3.65]],"id":39213014}],"con":true,"img":false}]}
{"op":"mcm","clk":"5322668026","pt":1646322888512,"mc":[{"id":"1.195532866","rc":[{"atl":[[1000,2.63]],"id":39213014}],"con":true,"img":false}]}
{"op":"mcm","clk":"5322668051","pt":1646322888721,"mc":[{"id":"1.195532866","rc":[{"atl":[[1000,2]],"id":39213014}],"con":true,"img":false}]}
{"op":"mcm","clk":"5322668060","pt":1646322888824,"mc":[{"id":"1.195532866","rc":[{"atl":[[6.6,0.63]],"id":39213014}],"con":true,"img":false}]}
{"op":"mcm","clk":"5322668395","pt":1646322892331,"mc":[{"id":"1.195532866","rc":[{"atl":[[8.6,16.45]],"id":39213014}],"con":true,"img":false}]}
{"op":"mcm","clk":"5322668424","pt":1646322892598,"mc":[{"id":"1.195532866","rc":[{"atl":[[8.6,13.16]],"id":39213014}],"con":true,"img":false}]}
{"op":"mcm","clk":"5322669956","pt":1646322908406,"mc":[{"id":"1.195532866","rc":[{"atb":[[2.92,0]],"id":35676762},{"spn":5.65,"spf":1.0,"id":39213014}],"con":true,"img":false}]}
{"op":"mcm","clk":"5322670091","pt":1646322910135,"mc":[{"id":"1.195532866","rc":[{"atl":[[26,4.53],[27,0]],"id":35676762},{"atb":[[3.1,19.05],[3.05,5.95],[3.2,0]],"id":41529439},{"atl":[[6.4,7.41],[7.4,3.22],[7.2,0]],"id":41529439},{"atl":[[8.2,0],[7.2,5.76],[7,21.67]],"id":39213014}],"con":true,"img":false}]}
{"op":"mcm","clk":"5322670101","pt":1646322910240,"mc":[{"id":"1.195532866","rc":[{"atl":[[7.4,18.84],[7.8,14.71]],"id":41529439}],"con":true,"img":false}]}
{"op":"mcm","clk":"5322670110","pt":1646322910343,"mc":[{"id":"1.195532866","rc":[{"atb":[[3.05,0]],"id":41529439},{"atl":[[7.4,15.62]],"id":41529439}],"con":true,"img":false}]}
{"op":"mcm","clk":"5322670251","pt":1646322911811,"mc":[{"id":"1.195532866","rc":[{"atl":[[1000,4.52]],"id":35676762}],"con":true,"img":false}]}
{"op":"mcm","clk":"5322670272","pt":1646322912025,"mc":[{"id":"1.195532866","rc":[{"atl":[[1000,3.26]],"id":35676762}],"con":true,"img":false}]}
{"op":"mcm","clk":"5322670279","pt":1646322912122,"mc":[{"id":"1.195532866","rc":[{"atl":[[1000,2]],"id":35676762}],"con":true,"img":false}]}
{"op":"mcm","clk":"5322670291","pt":1646322912233,"mc":[{"id":"1.195532866","rc":[{"atl":[[25,1.41]],"id":35676762}],"con":true,"img":false}]}
{"op":"mcm","clk":"5322670339","pt":1646322912649,"mc":[{"id":"1.195532866","rc":[{"atb":[[3.65,0]],"id":26648132},{"atb":[[3.75,0]],"id":43094640},{"atb":[[2.68,0]],"id":39213014}],"con":true,"img":false}]}
{"op":"mcm","clk":"5322670995","pt":1646322920048,"mc":[{"id":"1.195532866","rc":[{"atl":[[7.4,15.62]],"id":39213014}],"con":true,"img":false}]}
{"op":"mcm","clk":"5322671005","pt":1646322920153,"mc":[{"id":"1.195532866","rc":[{"atb":[[3,50]],"id":41529439},{"atl":[[6.8,17.24]],"id":41529439}],"con":true,"img":false}]}
{"op":"mcm","clk":"5322671024","pt":1646322920316,"mc":[{"id":"1.195532866","rc":[{"atl":[[7.4,0],[6.8,32.86]],"id":41529439}],"con":true,"img":false}]}
{"op":"mcm","clk":"5322671126","pt":1646322921633,"mc":[{"id":"1.195532866","rc":[{"atb":[[2.76,6.37]],"id":39213014}],"con":true,"img":false}]}
{"op":"mcm","clk":"5322671135","pt":1646322921736,"mc":[{"id":"1.195532866","rc":[{"atb":[[3.65,4.23]],"id":43094640}],"con":true,"img":false}]}
{"op":"mcm","clk":"5322671193","pt":1646322922528,"mc":[{"id":"1.195532866","rc":[{"atb":[[3.35,5.28]],"id":35676762}],"con":true,"img":false}]}
{"op":"mcm","clk":"5322671793","pt":1646322930153,"mc":[{"id":"1.195532866","rc":[{"atb":[[2.96,76.53]],"id":41529439},{"atl":[[8.2,0],[7.4,4.03],[7.8,0],[7.2,24.19],[8.6,0]],"id":41529439},{"atl":[[7.8,23.54],[9.4,0]],"id":39213014}],"con":true,"img":false}]}
{"op":"mcm","clk":"5322671821","pt":1646322930578,"mc":[{"id":"1.195532866","rc":[{"atl":[[7.4,0]],"id":41529439}],"con":true,"img":false}]}
{"op":"mcm","clk":"5322672597","pt":1646322940181,"mc":[{"id":"1.195532866","rc":[{"atb":[[2.92,130.21]],"id":41529439},{"atl":[[7.6,37.88]],"id":41529439},{"atl":[[9,0],[8.2,34.72]],"id":39213014}],"con":true,"img":false}]}
{"op":"mcm","clk":"5322672629","pt":1646322940552,"mc":[{"id":"1.195532866","rc":[{"atl":[[6,0]],"id":41529439}],"con":true,"img":false}]}
{"op":"mcm","clk":"5322672639","pt":1646322940656,"mc":[{"id":"1.195532866","rc":[{"atl":[[5.8,2]],"id":41529439}],"con":true,"img":false}]}
{"op":"mcm","clk":"5322672648","pt":1646322940763,"mc":[{"id":"1.195532866","rc":[{"atl":[[6.8,17.24],[7.2,40.32]],"id":41529439}],"con":true,"img":false}]}
{"op":"mcm","clk":"5322673343","pt":1646322949285,"mc":[{"id":"1.195532866","rc":[{"atl":[[6.8,34.48],[7.2,24.19]],"id":41529439}],"con":true,"img":false}]}
{"op":"mcm","clk":"5322673414","pt":1646322950182,"mc":[{"id":"1.195532866","rc":[{"atl":[[6.4,0],[6,8],[6.6,3.7]],"id":41529439},{"atl":[[8.6,0]],"id":39213014}],"con":true,"img":false}]}
{"op":"mcm","clk":"5322673436","pt":1646322950393,"mc":[{"id":"1.195532866","rc":[{"atl":[[6.6,0]],"id":41529439}],"con":true,"img":false}]}
{"op":"mcm","clk":"5322673930","pt":1646322956005,"mc":[{"id":"1.195532866","rc":[{"atb":[[3.3,21.05],[3.45,0]],"id":41529439}],"con":true,"img":false}]}
{"op":"mcm","clk":"5322673938","pt":1646322956055,"mc":[{"id":"1.195532866","rc":[{"atb":[[3.4,8.59],[2.96,89.16]],"id":41529439}],"con":true,"img":false}]}
{"op":"mcm","clk":"5322673964","pt":1646322956371,"mc":[{"id":"1.195532866","rc":[{"atb":[[2.96,76.53]],"id":41529439}],"con":true,"img":false}]}
{"op":"mcm","clk":"5322673977","pt":1646322956470,"mc":[{"id":"1.195532866","rc":[{"atb":[[3.4,0]],"id":41529439}],"con":true,"img":false}]}
{"op":"mcm","clk":"5322674295","pt":1646322960168,"mc":[{"id":"1.195532866","rc":[{"atl":[[6.4,18.52]],"id":41529439}],"con":true,"img":false}]}
{"op":"mcm","clk":"5322674304","pt":1646322960274,"mc":[{"id":"1.195532866","rc":[{"atl":[[6.8,17.24],[6.2,19.23]],"id":41529439}],"con":true,"img":false}]}
{"op":"mcm","clk":"5322675168","pt":1646322970213,"mc":[{"id":"1.195532866","rc":[{"atl":[[6.8,0],[7.6,0]],"id":41529439},{"spn":3.51,"spf":1.0,"id":41529439}],"con":true,"img":false}]}
{"op":"mcm","clk":"5322675181","pt":1646322970319,"mc":[{"id":"1.195532866","rc":[{"atl":[[6.8,25.86]],"id":41529439}],"con":true,"img":false}]}
{"op":"mcm","clk":"5322675444","pt":1646322973178,"mc":[{"id":"1.195532866","rc":[{"atb":[[2.88,0]],"id":35676762}],"con":true,"img":false}]}
{"op":"mcm","clk":"5322675683","pt":1646322976086,"mc":[{"id":"1.195532866","rc":[{"atb":[[3.45,4.58]],"id":35676762}],"con":true,"img":false}]}
{"op":"mcm","clk":"5322675720","pt":1646322976604,"mc":[{"id":"1.195532866","rc":[{"atb":[[4.3,7.49]],"id":43094640},{"atb":[[3.35,10.35]],"id":28791281},{"atb":[[3.35,6.19]],"id":41529439}],"con":true,"img":false}]}
{"op":"mcm","clk":"5322676049","pt":1646322980207,"mc":[{"id":"1.195532866","rc":[{"atl":[[6.8,29.43],[7.2,40.32]],"id":41529439}],"con":true,"img":false}]}
{"op":"mcm","clk":"5322676057","pt":1646322980310,"mc":[{"id":"1.195532866","rc":[{"atl":[[6.8,25.86]],"id":41529439}],"con":true,"img":false}]}
{"op":"mcm","clk":"5322676536","pt":1646322986614,"mc":[{"id":"1.195532866","rc":[{"atb":[[2.54,0]],"id":28791281}],"con":true,"img":false}]}
{"op":"mcm","clk":"5322676544","pt":1646322986817,"mc":[{"id":"1.195532866","rc":[{"atb":[[3.05,4.91]],"id":28791281}],"con":true,"img":false}]}
{"op":"mcm","clk":"5322676570","pt":1646322987229,"mc":[{"id":"1.195532866","rc":[{"atb":[[3.05,0]],"id":28791281}],"con":true,"img":false}]}
{"op":"mcm","clk":"5322677401","pt":1646322998261,"mc":[{"id":"1.195532866","rc":[{"atb":[[2.62,7.67]],"id":28791281}],"con":true,"img":false}]}
{"op":"mcm","clk":"5322678170","pt":1646323007869,"mc":[{"id":"1.195532866","rc":[{"atb":[[2.98,10.41]],"id":41529439}],"con":true,"img":false}]}
{"op":"mcm","clk":"5322678181","pt":1646323008079,"mc":[{"id":"1.195532866","rc":[{"atb":[[2.98,0]],"id":41529439}],"con":true,"img":false}]}
{"op":"mcm","clk":"5322678221","pt":1646323008647,"mc":[{"id":"1.195532866","rc":[{"atb":[[1.01,1003.65]],"id":41529439}],"con":true,"img":false}]}
{"op":"mcm","clk":"5322678234","pt":1646323008855,"mc":[{"id":"1.195532866","rc":[{"atb":[[1.01,1002.04]],"id":41529439}],"con":true,"img":false}]}
{"op":"mcm","clk":"5322678245","pt":1646323009061,"mc":[{"id":"1.195532866","rc":[{"atb":[[1.01,1002]],"id":41529439}],"con":true,"img":false}]}
{"op":"mcm","clk":"5322678251","pt":1646323009165,"mc":[{"id":"1.195532866","rc":[{"atb":[[4.8,0.04]],"id":41529439}],"con":true,"img":false}]}
{"op":"mcm","clk":"5322678856","pt":1646323016578,"mc":[{"id":"1.195532866","rc":[{"atl":[[10.5,0]],"id":41529439}],"con":true,"img":false}]}
{"op":"mcm","clk":"5322678862","pt":1646323016682,"mc":[{"id":"1.195532866","rc":[{"atl":[[8.8,0.2]],"id":41529439}],"con":true,"img":false}]}
{"op":"mcm","clk":"5322678960","pt":1646323017986,"mc":[{"id":"1.195532866","rc":[{"atl":[[13.5,8]],"id":26648132}],"con":true,"img":false}]}
{"op":"mcm","clk":"5322678970","pt":1646323018083,"mc":[{"id":"1.195532866","rc":[{"atl":[[16.5,0.2]],"id":26648132}],"con":true,"img":false}]}
{"op":"mcm","clk":"5322678978","pt":1646323018189,"mc":[{"id":"1.195532866","rc":[{"atb":[[4.6,6.76]],"id":26648132}],"con":true,"img":false}]}
{"op":"mcm","clk":"5322679010","pt":1646323018457,"mc":[{"id":"1.195532866","rc":[{"atb":[[4.6,0]],"id":26648132}],"con":true,"img":false}]}
{"op":"mcm","clk":"5322679080","pt":1646323019389,"mc":[{"id":"1.195532866","rc":[{"atl":[[26,4.33]],"id":35676762}],"con":true,"img":false}]}
{"op":"mcm","clk":"5322679088","pt":1646323019491,"mc":[{"id":"1.195532866","rc":[{"atl":[[36,7.34]],"id":35676762}],"con":true,"img":false}]}
{"op":"mcm","clk":"5322679112","pt":1646323019771,"mc":[{"id":"1.195532866","rc":[{"atl":[[5.8,0]],"id":41529439}],"con":true,"img":false}]}
{"op":"mcm","clk":"5322679119","pt":1646323019859,"mc":[{"id":"1.195532866","rc":[{"atl":[[5.7,2]],"id":41529439}],"con":true,"img":false}]}
{"op":"mcm","clk":"5322679124","pt":1646323019964,"mc":[{"id":"1.195532866","rc":[{"atl":[[6.4,37.04],[6.2,0]],"id":41529439}],"con":true,"img":false}]}
{"op":"mcm","clk":"5322679139","pt":1646323020173,"mc":[{"id":"1.195532866","rc":[{"atl":[[6.4,40.44]],"id":41529439}],"con":true,"img":false}]}
{"op":"mcm","clk":"5322679168","pt":1646323020696,"mc":[{"id":"1.195532866","rc":[{"atl":[[6.4,37.04]],"id":41529439}],"con":true,"img":false}]}
{"op":"mcm","clk":"5322679219","pt":1646323021278,"mc":[{"id":"1.195532866","rc":[{"atl":[[1000,4.24]],"id":35676762}],"con":true,"img":false}]}
{"op":"mcm","clk":"5322679233","pt":1646323021487,"mc":[{"id":"1.195532866","rc":[{"atl":[[25,1.26]],"id":35676762}],"con":true,"img":false}]}
{"op":"mcm","clk":"5322679248","pt":1646323021690,"mc":[{"id":"1.195532866","rc":[{"atl":[[1000,2.16]],"id":35676762}],"con":true,"img":false}]}
{"op":"mcm","clk":"5322679276","pt":1646323021961,"mc":[{"id":"1.195532866","rc":[{"atl":[[1000,2]],"id":35676762}],"con":true,"img":false}]}
{"op":"mcm","clk":"5322679288","pt":1646323022067,"mc":[{"id":"1.195532866","rc":[{"atl":[[23,0.16]],"id":35676762}],"con":true,"img":false}]}
{"op":"mcm","clk":"5322679296","pt":1646323022172,"mc":[{"id":"1.195532866","rc":[{"atl":[[25,4.83],[26,2.01]],"id":35676762}],"con":true,"img":false}]}
{"op":"mcm","clk":"5322680466","pt":1646323036604,"mc":[{"id":"1.195532866","rc":[{"spn":4.79,"spf":1.0,"id":43094640},{"atb":[[3.25,4.94]],"id":41529439},{"spn":3.54,"spf":1.0,"id":41529439}],"con":true,"img":false}]}
{"op":"mcm","clk":"5322680478","pt":1646323036658,"mc":[{"id":"1.195532866","rc":[{"atb":[[3.25,0]],"id":41529439}],"con":true,"img":false}]}
{"op":"mcm","clk":"5322682956","pt":1646323068705,"mc":[{"id":"1.195532866","rc":[{"atl":[[1000,3.65]],"id":35676762}],"con":true,"img":false}]}
{"op":"mcm","clk":"5322682964","pt":1646323068810,"mc":[{"id":"1.195532866","rc":[{"atl":[[24,0]],"id":35676762}],"con":true,"img":false}]}
{"op":"mcm","clk":"5322682979","pt":1646323068923,"mc":[{"id":"1.195532866","rc":[{"atl":[[1000,2.19]],"id":35676762}],"con":true,"img":false}]}
{"op":"mcm","clk":"5322682994","pt":1646323069127,"mc":[{"id":"1.195532866","rc":[{"atl":[[1000,2]],"id":35676762}],"con":true,"img":false}]}
{"op":"mcm","clk":"5322683002","pt":1646323069232,"mc":[{"id":"1.195532866","rc":[{"atl":[[22,0.19]],"id":35676762}],"con":true,"img":false}]}
{"op":"mcm","clk":"5322683009","pt":1646323069335,"mc":[{"id":"1.195532866","rc":[{"atb":[[2.36,0]],"id":41529439}],"con":true,"img":false}]}
{"op":"mcm","clk":"5322683242","pt":1646323072312,"mc":[{"id":"1.195532866","rc":[{"atb":[[3.4,4.67]],"id":41529439}],"con":true,"img":false}]}
{"op":"mcm","clk":"5322683399","pt":1646323074716,"mc":[{"id":"1.195532866","rc":[{"atb":[[3.35,0]],"id":41529439}],"con":true,"img":false}]}
{"op":"mcm","clk":"5322683480","pt":1646323076019,"mc":[{"id":"1.195532866","rc":[{"atl":[[13.5,0],[15.5,6.9]],"id":26648132},{"atb":[[3.25,4.91],[3.45,0],[3.2,90.84],[3.4,4.91]],"id":28791281},{"atl":[[6.4,7.41],[7,16.67]],"id":28791281},{"atl":[[25,1.26],[29,7.14]],"id":35676762},{"atl":[[6.4,22.33],[6.6,22.49]],"id":41529439},{"atl":[[7.4,18.91],[7.8,38.25],[7.2,0]],"id":39213014}],"con":true,"img":false}]}
{"op":"mcm","clk":"5322683493","pt":1646323076228,"mc":[{"id":"1.195532866","rc":[{"atb":[[3.25,0],[3.4,0]],"id":28791281},{"atl":[[6.4,18.52],[6.6,17.86]],"id":41529439},{"atl":[[7.4,15.62]],"id":39213014}],"con":true,"img":false}]}
{"op":"mcm","clk":"5322683556","pt":1646323077217,"mc":[{"id":"1.195532866","rc":[{"atb":[[2.5,0]],"id":26648132}],"con":true,"img":false}]}
{"op":"mcm","clk":"5322683692","pt":1646323079549,"mc":[{"id":"1.195532866","rc":[{"atb":[[3.45,5.42]],"id":41529439}],"con":true,"img":false}]}
{"op":"mcm","clk":"5322683743","pt":1646323080235,"mc":[{"id":"1.195532866","rc":[{"atb":[[1.02,2]],"id":43094640},{"atl":[[1000,2.39]],"id":41529439}],"con":true,"img":false}]}
{"op":"mcm","clk":"5322683763","pt":1646323080438,"mc":[{"id":"1.195532866","rc":[{"atl":[[1000,4]],"id":26648132},{"atb":[[1.02,2.5]],"id":43094640},{"atl":[[1000,4]],"id":43094640},{"atl":[[1000,4]],"id":28791281},{"atl":[[1000,4]],"id":35676762},{"atl":[[1000,4]],"id":41529439},{"atl":[[1000,4]],"id":39213014}],"con":true,"img":false}]}
{"op":"mcm","clk":"5322683772","pt":1646323080544,"mc":[{"id":"1.195532866","rc":[{"atb":[[1.02,0.5]],"id":43094640},{"atl":[[5.8,0.39]],"id":41529439}],"con":true,"img":false}]}
{"op":"mcm","clk":"5322683781","pt":1646323080649,"mc":[{"id":"1.195532866","rc":[{"atl":[[1000,3]],"id":26648132},{"atb":[[1.02,0]],"id":43094640},{"atl":[[1000,3]],"id":43094640},{"atl":[[1000,3]],"id":28791281},{"atl":[[1000,3]],"id":35676762},{"atl":[[1000,3]],"id":41529439},{"atl":[[1000,3]],"id":39213014}],"con":true,"img":false}]}
{"op":"mcm","clk":"5322683794","pt":1646323080754,"mc":[{"id":"1.195532866","rc":[{"atb":[[5.5,2.5]],"id":43094640}],"con":true,"img":false}]}
{"op":"mcm","clk":"5322683804","pt":1646323080857,"mc":[{"id":"1.195532866","rc":[{"atl":[[1000,2]],"id":26648132},{"atl":[[1000,2]],"id":43094640},{"atl":[[1000,2]],"id":28791281},{"atl":[[1000,2]],"id":35676762},{"atl":[[1000,2]],"id":41529439},{"atl":[[1000,2]],"id":39213014}],"con":true,"img":false}]}
{"op":"mcm","clk":"5322683809","pt":1646323080912,"mc":[{"id":"1.195532866","rc":[{"atl":[[9.8,1]],"id":26648132},{"atl":[[9.4,1]],"id":43094640},{"atl":[[5.9,1]],"id":28791281},{"atl":[[25,2.26]],"id":35676762},{"atl":[[5.6,1]],"id":41529439},{"atl":[[6.6,1.63]],"id":39213014}],"con":true,"img":false}]}
{"op":"mcm","clk":"5322683818","pt":1646323081016,"mc":[{"id":"1.195532866","rc":[{"atl":[[9.6,16.28]],"id":43094640}],"con":true,"img":false}]}
{"op":"mcm","clk":"5322683826","pt":1646323081124,"mc":[{"id":"1.195532866","rc":[{"atl":[[10,11.11]],"id":43094640}],"con":true,"img":false}]}
{"op":"mcm","clk":"5322683865","pt":1646323081544,"mc":[{"id":"1.195532866","rc":[{"atb":[[4.9,25.64],[5.5,22.22]],"id":26648132},{"atl":[[10.5,4.21],[11,0]],"id":26648132},{"atb":[[3,50],[3.45,0]],"id":43094640},{"atl":[[6.4,0],[6.2,9.62]],"id":28791281},{"atb":[[9.2,0]],"id":35676762},{"atl":[[24,1.74],[26,0.41]],"id":35676762},{"atl":[[5.8,8.72],[7.2,56.32],[6,0],[6.6,0]],"id":41529439}],"con":true,"img":false}]}
{"op":"mcm","clk":"5322683886","pt":1646323081759,"mc":[{"id":"1.195532866","rc":[{"atb":[[7,1.68]],"id":35676762},{"atl":[[25,1.26]],"id":35676762}],"con":true,"img":false}]}
{"op":"mcm","clk":"5322683894","pt":1646323081857,"mc":[{"id":"1.195532866","rc":[{"atl":[[23,1.16],[27,3.3]],"id":35676762}],"con":true,"img":false}]}
{"op":"mcm","clk":"5322683910","pt":1646323082018,"mc":[{"id":"1.195532866","rc":[{"atl":[[27,0]],"id":35676762}],"con":true,"img":false}]}
{"op":"mcm","clk":"5322683931","pt":1646323082330,"mc":[{"id":"1.195532866","rc":[{"atl":[[25,0]],"id":35676762}],"con":true,"img":false}]}
{"op":"mcm","clk":"5322683941","pt":1646323082539,"mc":[{"id":"1.195532866","rc":[{"atb":[[1.01,1004.52]],"id":35676762}],"con":true,"img":false}]}
{"op":"mcm","clk":"5322683954","pt":1646323082746,"mc":[{"id":"1.195532866","rc":[{"atb":[[1.01,1003.26]],"id":35676762}],"con":true,"img":false}]}
{"op":"mcm","clk":"5322683969","pt":1646323082951,"mc":[{"id":"1.195532866","rc":[{"atb":[[1.01,1002]],"id":35676762}],"con":true,"img":false}]}
{"op":"mcm","clk":"5322683976","pt":1646323083054,"mc":[{"id":"1.195532866","rc":[{"atb":[[8.4,1.26]],"id":35676762}],"con":true,"img":false}]}
{"op":"mcm","clk":"5322683995","pt":1646323083217,"mc":[{"id":"1.195532866","rc":[{"atl":[[13,20.83],[15.5,0]],"id":26648132},{"atl":[[6,11.27],[7,0]],"id":28791281},{"atl":[[23,3.16],[29,3.57]],"id":35676762},{"atl":[[7.8,23.54],[6.6,4.51]],"id":39213014}],"con":true,"img":false}]}
{"op":"mcm","clk":"5322684001","pt":1646323083319,"mc":[{"id":"1.195532866","rc":[{"atl":[[6.8,0]],"id":39213014}],"con":true,"img":false}]}
{"op":"mcm","clk":"5322684122","pt":1646323084939,"mc":[{"id":"1.195532866","rc":[{"atl":[[10,0]],"id":26648132},{"atl":[[6,9.62]],"id":28791281}],"con":true,"img":false}]}
{"op":"mcm","clk":"5322684130","pt":1646323085037,"mc":[{"id":"1.195532866","rc":[{"atl":[[6.2,26.86]],"id":28791281}],"con":true,"img":false}]}
{"op":"mcm","clk":"5322684140","pt":1646323085143,"mc":[{"id":"1.195532866","rc":[{"atl":[[9.8,0]],"id":26648132},{"atl":[[6,0]],"id":28791281}],"con":true,"img":false}]}
{"op":"mcm","clk":"5322684152","pt":1646323085351,"mc":[{"id":"1.195532866","rc":[{"atl":[[10,1]],"id":26648132}],"con":true,"img":false}]}
{"op":"mcm","clk":"5322684172","pt":1646323085662,"mc":[{"id":"1.195532866","rc":[{"atb":[[3.45,0]],"id":41529439}],"con":true,"img":false}]}
{"op":"mcm","clk":"5322684196","pt":1646323085928,"mc":[{"id":"1.195532866","rc":[{"atl":[[5.9,0]],"id":28791281}],"con":true,"img":false}]}
{"op":"mcm","clk":"5322684206","pt":1646323086032,"mc":[{"id":"1.195532866","rc":[{"atl":[[6,1]],"id":28791281}],"con":true,"img":false}]}
{"op":"mcm","clk":"5322684239","pt":1646323086344,"mc":[{"id":"1.195532866","rc":[{"atl":[[6,3.97]],"id":28791281}],"con":true,"img":false}]}
{"op":"mcm","clk":"5322684257","pt":1646323086554,"mc":[{"id":"1.195532866","rc":[{"atl":[[10.5,0],[11,4]],"id":26648132},{"atl":[[6.4,7.41],[6.2,19.17]],"id":28791281},{"atl":[[5.8,0.39],[5.9,8.16]],"id":41529439}],"con":true,"img":false}]}
{"op":"mcm","clk":"5322684283","pt":1646323086763,"mc":[{"id":"1.195532866","rc":[{"atl":[[10,0]],"id":26648132}],"con":true,"img":false}]}
{"op":"mcm","clk":"5322684291","pt":1646323086867,"mc":[{"id":"1.195532866","rc":[{"atl":[[10.5,1]],"id":26648132}],"con":true,"img":false}]}
{"op":"mcm","clk":"5322684468","pt":1646323088633,"mc":[{"id":"1.195532866","rc":[{"atl":[[6.8,43.1],[7.2,40.32]],"id":41529439}],"con":true,"img":false}]}
{"op":"mcm","clk":"5322684587","pt":1646323089931,"mc":[{"id":"1.195532866","rc":[{"atb":[[8.4,3.54]],"id":35676762}],"con":true,"img":false}]}
{"op":"mcm","clk":"5322684618","pt":1646323090346,"mc":[{"id":"1.195532866","rc":[{"atb":[[8.2,0]],"id":35676762}],"con":true,"img":false}]}
{"op":"mcm","clk":"5322684629","pt":1646323090448,"mc":[{"id":"1.195532866","rc":[{"atb":[[8.6,1.99]],"id":35676762},{"atl":[[5.8,0],[1000,2.25]],"id":41529439}],"con":true,"img":false}]}
{"op":"mcm","clk":"5322684640","pt":1646323090555,"mc":[{"id":"1.195532866","rc":[{"atl":[[1000,2]],"id":41529439}],"con":true,"img":false}]}
{"op":"mcm","clk":"5322684647","pt":1646323090659,"mc":[{"id":"1.195532866","rc":[{"atl":[[5.7,2.25]],"id":41529439}],"con":true,"img":false}]}
{"op":"mcm","clk":"5322684737","pt":1646323091546,"mc":[{"id":"1.195532866","rc":[{"atb":[[8.4,2.28]],"id":35676762}],"con":true,"img":false}]}
{"op":"mcm","clk":"5322684782","pt":1646323092225,"mc":[{"id":"1.195532866","rc":[{"atl":[[5.9,7.41],[6.2,1.93]],"id":28791281}],"con":true,"img":false}]}
{"op":"mcm","clk":"5322684806","pt":1646323092440,"mc":[{"id":"1.195532866","rc":[{"atl":[[6,2.97]],"id":28791281},{"atl":[[26,4.41]],"id":35676762}],"con":true,"img":false}]}
{"op":"mcm","clk":"5322684815","pt":1646323092540,"mc":[{"id":"1.195532866","rc":[{"atl":[[5.8,1]],"id":28791281}],"con":true,"img":false}]}
{"op":"mcm","clk":"5322684882","pt":1646323093380,"mc":[{"id":"1.195532866","rc":[{"atb":[[1.25,20]],"id":26648132},{"atb":[[1.25,20]],"id":43094640},{"atb":[[1.25,20]],"id":28791281},{"atb":[[1.25,20]],"id":35676762},{"atb":[[1.25,20]],"id":41529439},{"atb":[[1.25,20]],"id":39213014}],"con":true,"img":false}]}
{"op":"mcm","clk":"5322685026","pt":1646323095373,"mc":[{"id":"1.195532866","rc":[{"atl":[[6,0]],"id":28791281}],"con":true,"img":false}]}
{"op":"mcm","clk":"5322685093","pt":1646323096253,"mc":[{"id":"1.195532866","rc":[{"atb":[[8.4,0]],"id":35676762}],"con":true,"img":false}]}
{"op":"mcm","clk":"5322685174","pt":1646323097259,"mc":[{"id":"1.195532866","rc":[{"spn":9.15,"spf":1.0,"id":26648132},{"spn":4.85,"spf":1.0,"id":43094640},{"spn":4.77,"spf":1.0,"id":28791281},{"atb":[[8.6,0]],"id":35676762},{"spn":7.87,"spf":2.1,"id":35676762},{"spn":3.57,"spf":1.0,"id":41529439}],"con":true,"img":false}]}
{"op":"mcm","clk":"5322685181","pt":1646323097360,"mc":[{"id":"1.195532866","rc":[{"atl":[[6.2,10.34]],"id":28791281},{"atb":[[8.2,1.99]],"id":35676762}],"con":true,"img":false}]}
{"op":"mcm","clk":"5322685185","pt":1646323097464,"mc":[{"id":"1.195532866","rc":[{"atl":[[11,0],[11.5,3.81]],"id":26648132},{"atl":[[6.4,0],[5.9,0]],"id":28791281}],"con":true,"img":false}]}
{"op":"mcm","clk":"5322685191","pt":1646323097569,"mc":[{"id":"1.195532866","rc":[{"atl":[[13,12.5],[13.5,8]],"id":26648132},{"atl":[[6,8]],"id":28791281},{"atb":[[8,0],[7.8,5.88]],"id":35676762},{"atl":[[32,0],[36,0.2],[29,0]],"id":35676762}],"con":true,"img":false}]}
{"op":"mcm","clk":"5322685199","pt":1646323097677,"mc":[{"id":"1.195532866","rc":[{"atl":[[10.5,0]],"id":26648132},{"atl":[[5.8,0]],"id":28791281}],"con":true,"img":false}]}
{"op":"mcm","clk":"5322685208","pt":1646323097775,"mc":[{"id":"1.195532866","rc":[{"atl":[[11,1]],"id":26648132},{"atl":[[6,9]],"id":28791281},{"atb":[[7.4,6.44]],"id":35676762}],"con":true,"img":false}]}
{"op":"mcm","clk":"5322685219","pt":1646323097854,"mc":[{"id":"1.195532866","rc":[{"atl":[[6.8,34.48],[6.2,1.93]],"id":28791281}],"con":true,"img":false}]}
{"op":"mcm","clk":"5322685225","pt":1646323097946,"mc":[{"id":"1.195532866","rc":[{"atb":[[7.4,0]],"id":35676762}],"con":true,"img":false}]}
{"op":"mcm","clk":"5322685282","pt":1646323098882,"mc":[{"id":"1.195532866","rc":[{"atb":[[8.2,0]],"id":35676762}],"con":true,"img":false}]}
{"op":"mcm","clk":"5322685291","pt":1646323099021,"mc":[{"id":"1.195532866","rc":[{"atb":[[8,1.99]],"id":35676762}],"con":true,"img":false}]}
{"op":"mcm","clk":"5322685438","pt":1646323100753,"mc":[{"id":"1.195532866","rc":[{"atb":[[8,5.47]],"id":35676762}],"con":true,"img":false}]}
{"op":"mcm","clk":"5322685558","pt":1646323102470,"mc":[{"id":"1.195532866","rc":[{"atb":[[1.01,1004.52]],"id":35676762}],"con":true,"img":false}]}
{"op":"mcm","clk":"5322685565","pt":1646323102578,"mc":[{"id":"1.195532866","rc":[{"atb":[[1.01,1003.26]],"id":35676762}],"con":true,"img":false}]}
{"op":"mcm","clk":"5322685579","pt":1646323102782,"mc":[{"id":"1.195532866","rc":[{"atb":[[1.01,1002]],"id":35676762}],"con":true,"img":false}]}
{"op":"mcm","clk":"5322685589","pt":1646323102887,"mc":[{"id":"1.195532866","rc":[{"atb":[[8.2,1.26]],"id":35676762}],"con":true,"img":false}]}
{"op":"mcm","clk":"5322685686","pt":1646323104455,"mc":[{"id":"1.195532866","rc":[{"atb":[[8,1]],"id":26648132},{"atb":[[5.7,1]],"id":43094640},{"atb":[[3.7,1]],"id":28791281},{"atb":[[8.2,2.26]],"id":35676762},{"atb":[[3.8,1]],"id":41529439},{"atb":[[4.7,1.31]],"id":39213014}],"con":true,"img":false}]}
{"op":"mcm","clk":"5322685701","pt":1646323104667,"mc":[{"id":"1.195532866","rc":[{"atb":[[5.4,4.44]],"id":26648132}],"con":true,"img":false}]}
{"op":"mcm","clk":"5322685712","pt":1646323104773,"mc":[{"id":"1.195532866","rc":[{"atb":[[4.8,5]],"id":26648132},{"atl":[[1000,4.52]],"id":39213014}],"con":true,"img":false}]}
{"op":"mcm","clk":"5322685726","pt":1646323104875,"mc":[{"id":"1.195532866","rc":[{"atl":[[1000,4.52]],"id":28791281}],"con":true,"img":false}]}
{"op":"mcm","clk":"5322685737","pt":1646323104976,"mc":[{"id":"1.195532866","rc":[{"atb":[[4.8,0]],"id":26648132},{"atl":[[1000,4.1]],"id":28791281}],"con":true,"img":false}]}
{"op":"mcm","clk":"5322685748","pt":1646323105083,"mc":[{"id":"1.195532866","rc":[{"atb":[[5.4,0]],"id":26648132},{"atl":[[1000,4.1]],"id":39213014}],"con":true,"img":false}]}
{"op":"mcm","clk":"5322685761","pt":1646323105186,"mc":[{"id":"1.195532866","rc":[{"atl":[[1000,2]],"id":28791281}],"con":true,"img":false}]}
{"op":"mcm","clk":"5322685771","pt":1646323105291,"mc":[{"id":"1.195532866","rc":[{"atl":[[5.9,2.1]],"id":28791281},{"atl":[[8.8,0]],"id":41529439},{"atl":[[1000,2]],"id":39213014}],"con":true,"img":false}]}
{"op":"mcm","clk":"5322685792","pt":1646323105498,"mc":[{"id":"1.195532866","rc":[{"atl":[[6.8,17.24],[5.9,4.21],[6,8]],"id":28791281},{"atl":[[8,0.2]],"id":41529439},{"atl":[[6.4,2.1]],"id":39213014}],"con":true,"img":false}]}
{"op":"mcm","clk":"5322685801","pt":1646323105554,"mc":[{"id":"1.195532866","rc":[{"atl":[[5.8,1]],"id":28791281}],"con":true,"img":false}]}
{"op":"mcm","clk":"5322685811","pt":1646323105663,"mc":[{"id":"1.195532866","rc":[{"atl":[[1000,3.65],[6.6,3.88]],"id":39213014}],"con":true,"img":false}]}
{"op":"mcm","clk":"5322685818","pt":1646323105768,"mc":[{"id":"1.195532866","rc":[{"atb":[[8,3.48]],"id":35676762}],"con":true,"img":false}]}
{"op":"mcm","clk":"5322685827","pt":1646323105876,"mc":[{"id":"1.195532866","rc":[{"atb":[[8.4,1.99]],"id":35676762},{"atl":[[1000,2.67],[6.6,2.88]],"id":39213014}],"con":true,"img":false}]}
{"op":"mcm","clk":"5322685837","pt":1646323105976,"mc":[{"id":"1.195532866","rc":[{"atl":[[1000,2],[6.2,1]],"id":39213014}],"con":true,"img":false}]}
{"op":"mcm","clk":"5322685845","pt":1646323106083,"mc":[{"id":"1.195532866","rc":[{"atl":[[6.2,1.67]],"id":39213014}],"con":true,"img":false}]}
{"op":"mcm","clk":"5322685860","pt":1646323106286,"mc":[{"id":"1.195532866","rc":[{"atl":[[7.2,4.51]],"id":39213014}],"con":true,"img":false}]}
{"op":"mcm","clk":"5322685872","pt":1646323106497,"mc":[{"id":"1.195532866","rc":[{"atb":[[8.2,1.26]],"id":35676762}],"con":true,"img":false}]}
{"op":"mcm","clk":"5322685882","pt":1646323106596,"mc":[{"id":"1.195532866","rc":[{"atb":[[8.6,1]],"id":35676762},{"atl":[[7.2,0]],"id":39213014}],"con":true,"img":false}]}
{"op":"mcm","clk":"5322685920","pt":1646323107281,"mc":[{"id":"1.195532866","rc":[{"atb":[[4.3,0.12]],"id":43094640},{"atb":[[8,0]],"id":35676762}],"con":true,"img":false}]}
{"op":"mcm","clk":"5322685930","pt":1646323107532,"mc":[{"id":"1.195532866","rc":[{"atb":[[8.4,0]],"id":35676762}],"con":true,"img":false}]}
{"op":"mcm","clk":"5322685941","pt":1646323107588,"mc":[{"id":"1.195532866","rc":[{"atb":[[8.2,3.25]],"id":35676762}],"con":true,"img":false}]}
{"op":"mcm","clk":"5322685954","pt":1646323107788,"mc":[{"id":"1.195532866","rc":[{"atl":[[11.5,0],[12,3.64]],"id":26648132},{"atb":[[8,5.71],[7.8,0]],"id":35676762},{"atl":[[6.8,6.9],[7,15]],"id":39213014}],"con":true,"img":false}]}
{"op":"mcm","clk":"5322685960","pt":1646323107891,"mc":[{"id":"1.195532866","rc":[{"atl":[[7.4,19.65]],"id":39213014}],"con":true,"img":false}]}
{"op":"mcm","clk":"5322685967","pt":1646323107995,"mc":[{"id":"1.195532866","rc":[{"atl":[[11,0]],"id":26648132}],"con":true,"img":false}]}
{"op":"mcm","clk":"5322685973","pt":1646323108053,"mc":[{"id":"1.195532866","rc":[{"atl":[[11.5,1]],"id":26648132},{"atl":[[7.4,15.62]],"id":39213014}],"con":true,"img":false}]}
{"op":"mcm","clk":"5322685979","pt":1646323108157,"mc":[{"id":"1.195532866","rc":[{"atl":[[6.4,18.52]],"id":28791281}],"con":true,"img":false}]}
{"op":"mcm","clk":"5322686008","pt":1646323108572,"mc":[{"id":"1.195532866","rc":[{"atb":[[8.6,0]],"id":35676762}],"con":true,"img":false}]}
{"op":"mcm","clk":"5322686017","pt":1646323108674,"mc":[{"id":"1.195532866","rc":[{"atb":[[8.4,1]],"id":35676762}],"con":true,"img":false}]}
{"op":"mcm","clk":"5322686071","pt":1646323109392,"mc":[{"id":"1.195532866","rc":[{"atl":[[6.8,20.99]],"id":28791281}],"con":true,"img":false}]}
{"op":"mcm","clk":"5322686085","pt":1646323109562,"mc":[{"id":"1.195532866","rc":[{"atl":[[6.8,17.24]],"id":28791281}],"con":true,"img":false}]}
{"op":"mcm","clk":"5322686164","pt":1646323110760,"mc":[{"id":"1.195532866","rc":[{"atb":[[5.5,2]],"id":43094640}],"con":true,"img":false}]}
{"op":"mcm","clk":"5322686180","pt":1646323110967,"mc":[{"id":"1.195532866","rc":[{"atb":[[1.04,2]],"id":43094640}],"con":true,"img":false}]}
{"op":"mcm","clk":"5322686189","pt":1646323111071,"mc":[{"id":"1.195532866","rc":[{"atb":[[1.04,2.25]],"id":43094640}],"con":true,"img":false}]}
{"op":"mcm","clk":"5322686196","pt":1646323111171,"mc":[{"id":"1.195532866","rc":[{"atb":[[1.04,0.25]],"id":43094640},{"atb":[[8.2,1.99]],"id":35676762}],"con":true,"img":false}]}
{"op":"mcm","clk":"5322686202","pt":1646323111279,"mc":[{"id":"1.195532866","rc":[{"atb":[[1.04,0]],"id":43094640}],"con":true,"img":false}]}
{"op":"mcm","clk":"5322686211","pt":1646323111386,"mc":[{"id":"1.195532866","rc":[{"atb":[[5.6,2.24]],"id":43094640}],"con":true,"img":false}]}
{"op":"mcm","clk":"5322686230","pt":1646323111599,"mc":[{"id":"1.195532866","rc":[{"atb":[[8.4,3.97]],"id":35676762}],"con":true,"img":false}]}
{"op":"mcm","clk":"5322686259","pt":1646323112068,"mc":[{"id":"1.195532866","rc":[{"atl":[[5.9,2.11]],"id":28791281},{"atl":[[6.4,0]],"id":39213014}],"con":true,"img":false}]}
{"op":"mcm","clk":"5322686263","pt":1646323112204,"mc":[{"id":"1.195532866","rc":[{"atl":[[5.9,0],[6,16]],"id":28791281}],"con":true,"img":false}]}
{"op":"mcm","clk":"5322686272","pt":1646323112277,"mc":[{"id":"1.195532866","rc":[{"atl":[[6.2,0.67]],"id":39213014}],"con":true,"img":false}]}
{"op":"mcm","clk":"5322686282","pt":1646323112382,"mc":[{"id":"1.195532866","rc":[{"atl":[[6.4,1]],"id":39213014}],"con":true,"img":false}]}
{"op":"mcm","clk":"5322686290","pt":1646323112486,"mc":[{"id":"1.195532866","rc":[{"atl":[[6.8,21.9],[6.6,0]],"id":39213014}],"con":true,"img":false}]}
{"op":"mcm","clk":"5322686304","pt":1646323112699,"mc":[{"id":"1.195532866","rc":[{"atl":[[5.8,0]],"id":28791281},{"atl":[[6.4,0]],"id":39213014}],"con":true,"img":false}]}
{"op":"mcm","clk":"5322686314","pt":1646323112788,"mc":[{"id":"1.195532866","rc":[{"atl":[[5.9,1]],"id":28791281},{"atb":[[8.2,0]],"id":35676762},{"atl":[[6.6,1]],"id":39213014}],"con":true,"img":false}]}
{"op":"mcm","clk":"5322686326","pt":1646323112899,"mc":[{"id":"1.195532866","rc":[{"atb":[[8.6,1.99]],"id":35676762}],"con":true,"img":false}]}
{"op":"mcm","clk":"5322686353","pt":1646323113166,"mc":[{"id":"1.195532866","rc":[{"atl":[[12,0],[12.5,4.36],[13.5,0],[14,26.92]],"id":26648132},{"atl":[[6.4,0],[6.8,0],[7.2,0],[6.2,9.62],[6,8],[7.6,0],[6.6,3.66]],"id":28791281}],"con":true,"img":false}]}
{"op":"mcm","clk":"5322686371","pt":1646323113371,"mc":[{"id":"1.195532866","rc":[{"atl":[[11.5,0],[12.5,9.36]],"id":26648132}],"con":true,"img":false}]}
{"op":"mcm","clk":"5322686380","pt":1646323113473,"mc":[{"id":"1.195532866","rc":[{"atl":[[12,1]],"id":26648132},{"atb":[[8.4,2.97]],"id":35676762}],"con":true,"img":false}]}
{"op":"mcm","clk":"5322686387","pt":1646323113579,"mc":[{"id":"1.195532866","rc":[{"atl":[[12.5,4.36]],"id":26648132},{"atl":[[6.6,0]],"id":28791281},{"atb":[[8.8,1]],"id":35676762}],"con":true,"img":false}]}
{"op":"mcm","clk":"5322686396","pt":1646323113685,"mc":[{"id":"1.195532866","rc":[{"atl":[[1000,4.52]],"id":39213014}],"con":true,"img":false}]}
{"op":"mcm","clk":"5322686412","pt":1646323113891,"mc":[{"id":"1.195532866","rc":[{"atb":[[4.3,6.92]],"id":43094640},{"atl":[[1000,4.1]],"id":39213014}],"con":true,"img":false}]}
{"op":"mcm","clk":"5322686424","pt":1646323114097,"mc":[{"id":"1.195532866","rc":[{"atl":[[1000,2]],"id":39213014}],"con":true,"img":false}]}
{"op":"mcm","clk":"5322686432","pt":1646323114194,"mc":[{"id":"1.195532866","rc":[{"atl":[[6.4,2.1]],"id":39213014}],"con":true,"img":false}]}
{"op":"mcm","clk":"5322686444","pt":1646323114367,"mc":[{"id":"1.195532866","rc":[{"atl":[[6.6,0]],"id":39213014}],"con":true,"img":false}]}
{"op":"mcm","clk":"5322686449","pt":1646323114467,"mc":[{"id":"1.195532866","rc":[{"atl":[[6.2,1.67]],"id":39213014}],"con":true,"img":false}]}
{"op":"mcm","clk":"5322686527","pt":1646323115877,"mc":[{"id":"1.195532866","rc":[{"atl":[[1000,4.52]],"id":35676762},{"atl":[[6.4,0]],"id":39213014}],"con":true,"img":false}]}
{"op":"mcm","clk":"5322686545","pt":1646323116081,"mc":[{"id":"1.195532866","rc":[{"atl":[[1000,3.26]],"id":35676762}],"con":true,"img":false}]}
{"op":"mcm","clk":"5322686549","pt":1646323116186,"mc":[{"id":"1.195532866","rc":[{"atb":[[8.4,0]],"id":35676762},{"atl":[[6.2,0.67]],"id":39213014}],"con":true,"img":false}]}
{"op":"mcm","clk":"5322686559","pt":1646323116291,"mc":[{"id":"1.195532866","rc":[{"atl":[[1000,2]],"id":35676762},{"atl":[[6.6,1]],"id":39213014}],"con":true,"img":false}]}
{"op":"mcm","clk":"5322686566","pt":1646323116397,"mc":[{"id":"1.195532866","rc":[{"atl":[[22,1.45]],"id":35676762}],"con":true,"img":false}]}
{"op":"mcm","clk":"5322686630","pt":1646323117291,"mc":[{"id":"1.195532866","rc":[{"atl":[[6.2,18.82],[6,0]],"id":28791281}],"con":true,"img":false}]}
{"op":"mcm","clk":"5322686643","pt":1646323117495,"mc":[{"id":"1.195532866","rc":[{"atb":[[8,4.11]],"id":26648132},{"atl":[[12,2.98]],"id":26648132},{"atl":[[9.2,3.89]],"id":43094640},{"atl":[[5.9,5.45]],"id":28791281},{"atb":[[8.8,3.79]],"id":35676762},{"atl":[[22,2.49]],"id":35676762},{"atb":[[3.85,7.65]],"id":41529439},{"atl":[[5.8,4.54]],"id":41529439},{"atl":[[6.4,4.03]],"id":39213014}],"con":true,"img":false}]}
{"op":"mcm","clk":"5322686650","pt":1646323117595,"mc":[{"id":"1.195532866","rc":[{"atl":[[5.9,4.45]],"id":28791281},{"atb":[[8.6,0]],"id":35676762}],"con":true,"img":false}]}
{"op":"mcm","clk":"5322686658","pt":1646323117694,"mc":[{"id":"1.195532866","rc":[{"atl":[[9.2,7.78],[9.6,4.65]],"id":43094640},{"atl":[[6,1]],"id":28791281},{"atb":[[8.2,1.99]],"id":35676762}],"con":true,"img":false}]}
{"op":"mcm","clk":"5322686667","pt":1646323117799,"mc":[{"id":"1.195532866","rc":[{"atl":[[6,3.96]],"id":41529439}],"con":true,"img":false}]}
{"op":"mcm","clk":"5322686671","pt":1646323117858,"mc":[{"id":"1.195532866","rc":[{"atl":[[10.5,4.28]],"id":43094640},{"atl":[[6,0]],"id":41529439}],"con":true,"img":false}]}
{"op":"mcm","clk":"5322686679","pt":1646323117967,"mc":[{"id":"1.195532866","rc":[{"atl":[[9.4,0]],"id":43094640},{"atl":[[6,0]],"id":28791281},{"atl":[[23,2.16]],"id":35676762},{"atb":[[3.5,2.89]],"id":39213014},{"atl":[[6.6,0]],"id":39213014}],"con":true,"img":false}]}
{"op":"mcm","clk":"5322686686","pt":1646323118068,"mc":[{"id":"1.195532866","rc":[{"atl":[[9,1]],"id":43094640},{"atl":[[5.8,1]],"id":28791281},{"atl":[[21,1]],"id":35676762},{"atl":[[6.2,1.67]],"id":39213014}],"con":true,"img":false}]}
{"op":"mcm","clk":"5322686693","pt":1646323118177,"mc":[{"id":"1.195532866","rc":[{"atl":[[10.5,0]],"id":43094640},{"atl":[[1000,3.65]],"id":35676762}],"con":true,"img":false}]}
{"op":"mcm","clk":"5322686697","pt":1646323118274,"mc":[{"id":"1.195532866","rc":[{"atl":[[9.2,5.12]],"id":43094640},{"atl":[[5.8,3.52],[5.9,0]],"id":28791281},{"atl":[[22,1.26],[1000,2.2]],"id":35676762},{"atl":[[6.4,0]],"id":39213014}],"con":true,"img":false}]}
{"op":"mcm","clk":"5322686702","pt":1646323118369,"mc":[{"id":"1.195532866","rc":[{"atl":[[23,3.98]],"id":35676762}],"con":true,"img":false}]}
{"op":"mcm","clk":"5322686712","pt":1646323118482,"mc":[{"id":"1.195532866","rc":[{"atb":[[8.8,2.79]],"id":35676762},{"atl":[[21,0],[1000,2]],"id":35676762},{"atb":[[3.8,0]],"id":41529439},{"atb":[[3.5,0]],"id":39213014},{"atl":[[6.2,0.67]],"id":39213014}],"con":true,"img":false}]}
{"op":"mcm","clk":"5322686721","pt":1646323118585,"mc":[{"id":"1.195532866","rc":[{"atb":[[9,1]],"id":35676762},{"atl":[[20,0.2],[22,2.26]],"id":35676762},{"atb":[[3.9,1]],"id":41529439},{"atl":[[6.6,1]],"id":39213014}],"con":true,"img":false}]}
{"op":"mcm","clk":"5322686744","pt":1646323118900,"mc":[{"id":"1.195532866","rc":[{"atl":[[1000,4.52]],"id":39213014}],"con":true,"img":false}]}
{"op":"mcm","clk":"5322686761","pt":1646323119098,"mc":[{"id":"1.195532866","rc":[{"atl":[[9,3.72]],"id":43094640},{"atl":[[5.8,8.06]],"id":28791281},{"atl":[[21,1.09]],"id":35676762},{"atb":[[3.75,0.14]],"id":41529439},{"atl":[[6.4,4.03],[1000,4.1]],"id":39213014}],"con":true,"img":false}]}
{"op":"mcm","clk":"5322686767","pt":1646323119202,"mc":[{"id":"1.195532866","rc":[{"atb":[[1.02,1.99]],"id":41529439}],"con":true,"img":false}]}
{"op":"mcm","clk":"5322686778","pt":1646323119268,"mc":[{"id":"1.195532866","rc":[{"atl":[[21,3.35],[23,1.98]],"id":35676762},{"atb":[[3.7,5.36],[3.65,3.44]],"id":41529439},{"atl":[[1000,2],[6.6,15]],"id":39213014}],"con":true,"img":false}]}
{"op":"mcm","clk":"5322686786","pt":1646323119366,"mc":[{"id":"1.195532866","rc":[{"atb":[[8.2,0]],"id":35676762},{"atl":[[6.8,6.9],[6.2,3.77]],"id":39213014}],"con":true,"img":false}]}
{"op":"mcm","clk":"5322686798","pt":1646323119481,"mc":[{"id":"1.195532866","rc":[{"atb":[[9,2.99]],"id":35676762},{"atb":[[3.7,2],[3.65,0]],"id":41529439}],"con":true,"img":false}]}
{"op":"mcm","clk":"5322686806","pt":1646323119588,"mc":[{"id":"1.195532866","rc":[{"atl":[[22,1.26]],"id":35676762}],"con":true,"img":false}]}
{"op":"mcm","clk":"5322686812","pt":1646323119687,"mc":[{"id":"1.195532866","rc":[{"atl":[[20,1.2]],"id":35676762}],"con":true,"img":false}]}
{"op":"mcm","clk":"5322686825","pt":1646323119890,"mc":[{"id":"1.195532866","rc":[{"atl":[[21,2.26]],"id":35676762},{"atl":[[6.4,0]],"id":39213014}],"con":true,"img":false}]}
{"op":"mcm","clk":"5322686874","pt":1646323120781,"mc":[{"id":"1.195532866","rc":[{"atb":[[8.2,3.38]],"id":35676762}],"con":true,"img":false}]}
{"op":"mcm","clk":"5322686884","pt":1646323120993,"mc":[{"id":"1.195532866","rc":[{"atl":[[20,2.35]],"id":35676762},{"atl":[[6.2,7.97]],"id":39213014}],"con":true,"img":false}]}
{"op":"mcm","clk":"5322686927","pt":1646323121495,"mc":[{"id":"1.195532866","rc":[{"atb":[[7.8,0]],"id":26648132},{"atb":[[3.7,0]],"id":41529439}],"con":true,"img":false}]}
{"op":"mcm","clk":"5322687022","pt":1646323122586,"mc":[{"id":"1.195532866","rc":[{"atb":[[8,3.11]],"id":26648132}],"con":true,"img":false}]}
{"op":"mcm","clk":"5322687027","pt":1646323122686,"mc":[{"id":"1.195532866","rc":[{"atb":[[8.2,1]],"id":26648132}],"con":true,"img":false}]}
{"op":"mcm","clk":"5322687039","pt":1646323122799,"mc":[{"id":"1.195532866","rc":[{"atb":[[8,0]],"id":26648132}],"con":true,"img":false}]}
{"op":"mcm","clk":"5322687069","pt":1646323123204,"mc":[{"id":"1.195532866","rc":[{"atl":[[22,0]],"id":35676762}],"con":true,"img":false}]}
{"op":"mcm","clk":"5322687077","pt":1646323123260,"mc":[{"id":"1.195532866","rc":[{"atb":[[8.2,0]],"id":35676762}],"con":true,"img":false}]}
{"op":"mcm","clk":"5322687105","pt":1646323123578,"mc":[{"id":"1.195532866","rc":[{"atb":[[8.2,0]],"id":26648132},{"atl":[[12.5,0.88],[13,3.33]],"id":26648132},{"atl":[[9.4,4.76],[9.6,0]],"id":43094640},{"atl":[[6,8]],"id":28791281}],"con":true,"img":false}]}
{"op":"mcm","clk":"5322687114","pt":1646323123672,"mc":[{"id":"1.195532866","rc":[{"atb":[[5.6,6.74],[5.7,1]],"id":26648132}],"con":true,"img":false}]}
{"op":"mcm","clk":"5322687121","pt":1646323123777,"mc":[{"id":"1.195532866","rc":[{"atb":[[5.1,34.15],[5.5,0]],"id":26648132},{"atl":[[12,5.96],[14,19.23]],"id":26648132},{"atb":[[3.3,60.85],[3.2,45.39]],"id":28791281},{"atl":[[22,1.9]],"id":35676762}],"con":true,"img":false}]}
{"op":"mcm","clk":"5322687138","pt":1646323124087,"mc":[{"id":"1.195532866","rc":[{"atl":[[5.9,16.14]],"id":28791281}],"con":true,"img":false}]}
{"op":"mcm","clk":"5322687146","pt":1646323124191,"mc":[{"id":"1.195532866","rc":[{"atl":[[6.2,9.62]],"id":28791281}],"con":true,"img":false}]}
{"op":"mcm","clk":"5322687169","pt":1646323124504,"mc":[{"id":"1.195532866","rc":[{"atl":[[9.2,1.23],[8.8,4.76]],"id":43094640}],"con":true,"img":false}]}
{"op":"mcm","clk":"5322687189","pt":1646323124677,"mc":[{"id":"1.195532866","rc":[{"atb":[[5.6,6.64]],"id":26648132},{"atl":[[9,0]],"id":43094640}],"con":true,"img":false}]}
{"op":"mcm","clk":"5322687195","pt":1646323124775,"mc":[{"id":"1.195532866","rc":[{"atl":[[8.6,1]],"id":43094640}],"con":true,"img":false}]}
{"op":"mcm","clk":"5322687201","pt":1646323124872,"mc":[{"id":"1.195532866","rc":[{"atb":[[5.6,2],[1.02,0]],"id":26648132}],"con":true,"img":false}]}
{"op":"mcm","clk":"5322687212","pt":1646323124977,"mc":[{"id":"1.195532866","rc":[{"atb":[[5.7,7.63]],"id":26648132}],"con":true,"img":false}]}
{"op":"mcm","clk":"5322687253","pt":1646323125396,"mc":[{"id":"1.195532866","rc":[{"atl":[[5.8,5.54]],"id":28791281}],"con":true,"img":false}]}
{"op":"mcm","clk":"5322687267","pt":1646323125603,"mc":[{"id":"1.195532866","rc":[{"atl":[[8.6,3.86]],"id":43094640}],"con":true,"img":false}]}
{"op":"mcm","clk":"5322687290","pt":1646323125766,"mc":[{"id":"1.195532866","rc":[{"atl":[[5.7,2.52]],"id":28791281}],"con":true,"img":false}]}
{"op":"mcm","clk":"5322687303","pt":1646323125972,"mc":[{"id":"1.195532866","rc":[{"atl":[[5.8,4.54]],"id":28791281},{"atl":[[6.2,5.86]],"id":39213014}],"con":true,"img":false}]}
{"op":"mcm","clk":"5322687312","pt":1646323126075,"mc":[{"id":"1.195532866","rc":[{"atl":[[5.6,1]],"id":28791281}],"con":true,"img":false}]}
{"op":"mcm","clk":"5322687331","pt":1646323126386,"mc":[{"id":"1.195532866","rc":[{"atb":[[7.8,2]],"id":26648132},{"atl":[[1000,4.52]],"id":39213014}],"con":true,"img":false}]}
{"op":"mcm","clk":"5322687340","pt":1646323126488,"mc":[{"id":"1.195532866","rc":[{"atl":[[5.8,0]],"id":28791281},{"atl":[[1000,4.1]],"id":39213014}],"con":true,"img":false}]}
{"op":"mcm","clk":"5322687346","pt":1646323126595,"mc":[{"id":"1.195532866","rc":[{"atb":[[3.2,5.1]],"id":26648132}],"con":true,"img":false}]}
{"op":"mcm","clk":"5322687354","pt":1646323126697,"mc":[{"id":"1.195532866","rc":[{"atl":[[1000,2]],"id":39213014}],"con":true,"img":false}]}
{"op":"mcm","clk":"5322687363","pt":1646323126801,"mc":[{"id":"1.195532866","rc":[{"atl":[[6,2.1]],"id":39213014}],"con":true,"img":false}]}
{"op":"mcm","clk":"5322687382","pt":1646323126960,"mc":[{"id":"1.195532866","rc":[{"atl":[[6.2,4.86]],"id":39213014}],"con":true,"img":false}]}
{"op":"mcm","clk":"5322687387","pt":1646323127068,"mc":[{"id":"1.195532866","rc":[{"atl":[[5.9,1]],"id":39213014}],"con":true,"img":false}]}
{"op":"mcm","clk":"5322687392","pt":1646323127169,"mc":[{"id":"1.195532866","rc":[{"atb":[[5.7,5.64]],"id":26648132}],"con":true,"img":false}]}
{"op":"mcm","clk":"5322687399","pt":1646323127276,"mc":[{"id":"1.195532866","rc":[{"atb":[[1.02,1.99]],"id":26648132}],"con":true,"img":false}]}
{"op":"mcm","clk":"5322687405","pt":1646323127382,"mc":[{"id":"1.195532866","rc":[{"atl":[[6.2,0.67]],"id":39213014}],"con":true,"img":false}]}
{"op":"mcm","clk":"5322687412","pt":1646323127495,"mc":[{"id":"1.195532866","rc":[{"atb":[[5.7,4.64]],"id":26648132},{"atl":[[5.6,5.74]],"id":28791281}],"con":true,"img":false}]}
{"op":"mcm","clk":"5322687417","pt":1646323127586,"mc":[{"id":"1.195532866","rc":[{"atb":[[8,1]],"id":26648132}],"con":true,"img":false}]}
{"op":"mcm","clk":"5322687450","pt":1646323128006,"mc":[{"id":"1.195532866","rc":[{"atb":[[5.2,5.79]],"id":26648132}],"con":true,"img":false}]}
{"op":"mcm","clk":"5322687473","pt":1646323128173,"mc":[{"id":"1.195532866","rc":[{"atb":[[5.7,3.11]],"id":26648132}],"con":true,"img":false}]}
{"op":"mcm","clk":"5322687485","pt":1646323128377,"mc":[{"id":"1.195532866","rc":[{"atb":[[5.7,0]],"id":26648132},{"atl":[[5.9,5.45]],"id":39213014}],"con":true,"img":false}]}
{"op":"mcm","clk":"5322687492","pt":1646323128479,"mc":[{"id":"1.195532866","rc":[{"atb":[[8,4.11]],"id":26648132}],"con":true,"img":false}]}
{"op":"mcm","clk":"5322687500","pt":1646323128684,"mc":[{"id":"1.195532866","rc":[{"atl":[[7,0]],"id":39213014}],"con":true,"img":false}]}
{"op":"mcm","clk":"5322687705","pt":1646323131172,"mc":[{"id":"1.195532866","rc":[{"atl":[[8.4,3.87],[8.8,0]],"id":43094640}],"con":true,"img":false}]}
{"op":"mcm","clk":"5322687726","pt":1646323131381,"mc":[{"id":"1.195532866","rc":[{"atl":[[12,2.98],[14,26.92]],"id":26648132},{"atb":[[3,0],[3.25,44.44]],"id":43094640},{"atl":[[9.4,0],[8.6,0],[8.8,5.13]],"id":43094640},{"atl":[[5.8,17.95],[5.9,0]],"id":28791281}],"con":true,"img":false}]}
{"op":"mcm","clk":"5322687740","pt":1646323131484,"mc":[{"id":"1.195532866","rc":[{"atb":[[7.8,0]],"id":26648132},{"atl":[[8.2,1]],"id":43094640}],"con":true,"img":false}]}
{"op":"mcm","clk":"5322687828","pt":1646323132478,"mc":[{"id":"1.195532866","rc":[{"atb":[[8,3.11],[5.2,0]],"id":26648132}],"con":true,"img":false}]}
{"op":"mcm","clk":"5322687840","pt":1646323132581,"mc":[{"id":"1.195532866","rc":[{"atb":[[8,0],[8.2,1]],"id":26648132}],"con":true,"img":false}]}
{"op":"mcm","clk":"5322687849","pt":1646323132687,"mc":[{"id":"1.195532866","rc":[{"atl":[[8.2,4.02]],"id":43094640}],"con":true,"img":false}]}
{"op":"mcm","clk":"5322687919","pt":1646323133473,"mc":[{"id":"1.195532866","rc":[{"atb":[[8.2,0]],"id":26648132}],"con":true,"img":false}]}
{"op":"mcm","clk":"5322687926","pt":1646323133582,"mc":[{"id":"1.195532866","rc":[{"atb":[[5.7,1]],"id":26648132},{"atl":[[1000,3.65]],"id":26648132}],"con":true,"img":false}]}
{"op":"mcm","clk":"5322687952","pt":1646323133787,"mc":[{"id":"1.195532866","rc":[{"atl":[[1000,2.35]],"id":26648132}],"con":true,"img":false}]}
{"op":"mcm","clk":"5322687964","pt":1646323133894,"mc":[{"id":"1.195532866","rc":[{"atl":[[14,34.61]],"id":26648132}],"con":true,"img":false}]}
{"op":"mcm","clk":"5322687972","pt":1646323133993,"mc":[{"id":"1.195532866","rc":[{"atl":[[14,15.38],[1000,2]],"id":26648132}],"con":true,"img":false}]}
{"op":"mcm","clk":"5322687979","pt":1646323134097,"mc":[{"id":"1.195532866","rc":[{"atl":[[11.5,0.35]],"id":26648132},{"atl":[[24,4.35]],"id":35676762}],"con":true,"img":false}]}
{"op":"mcm","clk":"5322688014","pt":1646323134574,"mc":[{"id":"1.195532866","rc":[{"atl":[[5.7,0]],"id":28791281},{"atl":[[6,0]],"id":39213014}],"con":true,"img":false}]}
{"op":"mcm","clk":"5322688023","pt":1646323134678,"mc":[{"id":"1.195532866","rc":[{"atb":[[5.7,5.64]],"id":26648132}],"con":true,"img":false}]}
{"op":"mcm","clk":"5322688043","pt":1646323134888,"mc":[{"id":"1.195532866","rc":[{"atl":[[5.5,2.52]],"id":28791281},{"atl":[[5.8,2.52]],"id":39213014}],"con":true,"img":false}]}
{"op":"mcm","clk":"5322688049","pt":1646323134988,"mc":[{"id":"1.195532866","rc":[{"atl":[[6.2,4.23]],"id":39213014}],"con":true,"img":false}]}
{"op":"mcm","clk":"5322688056","pt":1646323135096,"mc":[{"id":"1.195532866","rc":[{"atl":[[5.6,4.74]],"id":28791281},{"atl":[[5.9,4.45]],"id":39213014}],"con":true,"img":false}]}
{"op":"mcm","clk":"5322688067","pt":1646323135198,"mc":[{"id":"1.195532866","rc":[{"atl":[[5.4,1]],"id":28791281},{"atl":[[6.2,0.67],[5.7,1]],"id":39213014}],"con":true,"img":false}]}
{"op":"mcm","clk":"5322688164","pt":1646323136498,"mc":[{"id":"1.195532866","rc":[{"atb":[[7.8,2]],"id":26648132}],"con":true,"img":false}]}
{"op":"mcm","clk":"5322688172","pt":1646323136706,"mc":[{"id":"1.195532866","rc":[{"atb":[[5,9.27]],"id":26648132},{"atl":[[12.5,4.36]],"id":26648132},{"atl":[[8.6,5.26],[8.8,0]],"id":43094640},{"atl":[[5.6,8.7]],"id":28791281},{"atl":[[5.9,0]],"id":39213014}],"con":true,"img":false}]}
{"op":"mcm","clk":"5322688188","pt":1646323137070,"mc":[{"id":"1.195532866","rc":[{"atb":[[5.2,3.6]],"id":26648132},{"atb":[[4.3,0.12]],"id":43094640}],"con":true,"img":false}]}
{"op":"mcm","clk":"5322688198","pt":1646323137177,"mc":[{"id":"1.195532866","rc":[{"atb":[[5,5]],"id":26648132},{"atb":[[4.8,11.04]],"id":41529439}],"con":true,"img":false}]}
{"op":"mcm","clk":"5322688205","pt":1646323137279,"mc":[{"id":"1.195532866","rc":[{"atb":[[5,0]],"id":26648132}],"con":true,"img":false}]}
{"op":"mcm","clk":"5322688215","pt":1646323137388,"mc":[{"id":"1.195532866","rc":[{"atl":[[5.4,5.95]],"id":28791281},{"atl":[[5.7,5.64]],"id":39213014}],"con":true,"img":false}]}
{"op":"mcm","clk":"5322688225","pt":1646323137591,"mc":[{"id":"1.195532866","rc":[{"atb":[[5.7,4.64]],"id":26648132},{"atb":[[3.9,0]],"id":41529439}],"con":true,"img":false}]}
{"op":"mcm","clk":"5322688233","pt":1646323137697,"mc":[{"id":"1.195532866","rc":[{"atb":[[8,1]],"id":26648132},{"atb":[[4.9,1]],"id":41529439}],"con":true,"img":false}]}
{"op":"mcm","clk":"5322688240","pt":1646323137800,"mc":[{"id":"1.195532866","rc":[{"atl":[[8,4.03],[8.4,0]],"id":43094640}],"con":true,"img":false}]}
{"op":"mcm","clk":"5322688260","pt":1646323138116,"mc":[{"id":"1.195532866","rc":[{"atl":[[8.2,3.02]],"id":43094640}],"con":true,"img":false}]}
{"op":"mcm","clk":"5322688267","pt":1646323138169,"mc":[{"id":"1.195532866","rc":[{"atl":[[7.8,1]],"id":43094640}],"con":true,"img":false}]}
{"op":"mcm","clk":"5322688275","pt":1646323138324,"mc":[{"id":"1.195532866","rc":[{"atb":[[5.7,3.11]],"id":26648132},{"atl":[[8.2,0]],"id":43094640},{"atb":[[4.7,0]],"id":39213014},{"atl":[[4.7,5.69]],"id":39213014},{"trd":[[4.7,9.29]],"ltp":4.7,"tv":9.29,"id":39213014}],"con":true,"img":false}]}
{"op":"mcm","clk":"5322688284","pt":1646323138376,"mc":[{"id":"1.195532866","rc":[{"atb":[[4.6,0]],"id":39213014},{"trd":[[4.6,4]],"ltp":4.6,"tv":4.0,"id":39213014}],"con":true,"img":false}]}
{"op":"mcm","clk":"5322688297","pt":1646323138586,"mc":[{"id":"1.195532866","rc":[{"atb":[[5.7,0]],"id":26648132},{"atl":[[5.7,4.64]],"id":39213014}],"con":true,"img":false}]}
{"op":"mcm","clk":"5322688306","pt":1646323138687,"mc":[{"id":"1.195532866","rc":[{"atb":[[8,4.11]],"id":26648132}],"con":true,"img":false}]}
{"op":"mcm","clk":"5322688322","pt":1646323138896,"mc":[{"id":"1.195532866","rc":[{"atl":[[1000,4]],"id":39213014}],"con":true,"img":false}]}
{"op":"mcm","clk":"5322688333","pt":1646323139100,"mc":[{"id":"1.195532866","rc":[{"atb":[[3.85,5.58]],"id":41529439},{"atl":[[1000,3]],"id":39213014}],"con":true,"img":false}]}
{"op":"mcm","clk":"5322688337","pt":1646323139205,"mc":[{"id":"1.195532866","rc":[{"atl":[[7.8,4.2]],"id":43094640},{"atb":[[3.35,0],[3.75,8.06]],"id":28791281}],"con":true,"img":false}]}
{"op":"mcm","clk":"5322688345","pt":1646323139308,"mc":[{"id":"1.195532866","rc":[{"atb":[[3.85,0]],"id":41529439},{"atl":[[1000,2]],"id":39213014}],"con":true,"img":false}]}
{"op":"mcm","clk":"5322688351","pt":1646323139413,"mc":[{"id":"1.195532866","rc":[{"atb":[[3.15,5.94]],"id":28791281},{"atb":[[4.9,6.58],[1.02,5]],"id":41529439},{"atl":[[4.6,1]],"id":39213014}],"con":true,"img":false}]}
{"op":"mcm","clk":"5322688364","pt":1646323139516,"mc":[{"id":"1.195532866","rc":[{"atb":[[1.03,2.93]],"id":26648132},{"atb":[[1.02,2.98]],"id":43094640},{"atb":[[1.02,5.04]],"id":28791281},{"atb":[[1.04,2.87]],"id":35676762},{"atb":[[1.02,3.02]],"id":39213014},{"atl":[[4.6,2]],"id":39213014}],"con":true,"img":false}]}
{"op":"mcm","clk":"5322688378","pt":1646323139677,"mc":[{"id":"1.195532866","rc":[{"atb":[[3.7,0],[3.15,0]],"id":28791281}],"con":true,"img":false}]}
{"op":"mcm","clk":"5322688386","pt":1646323139781,"mc":[{"id":"1.195532866","rc":[{"atb":[[3.8,1]],"id":28791281},{"atb":[[1.02,2.25]],"id":41529439}],"con":true,"img":false}]}
{"op":"mcm","clk":"5322688391","pt":1646323139883,"mc":[{"id":"1.195532866","rc":[{"atb":[[1.03,0.19]],"id":26648132},{"atb":[[1.02,0.24]],"id":43094640},{"atb":[[1.02,2.29]],"id":28791281},{"atb":[[1.04,0.12]],"id":35676762},{"atb":[[1.02,0.27]],"id":39213014}],"con":true,"img":false}]}
{"op":"mcm","clk":"5322688420","pt":1646323140305,"mc":[{"id":"1.195532866","rc":[{"atb":[[1.02,0]],"id":43094640},{"atb":[[1.02,1.99]],"id":28791281},{"atb":[[1.04,0]],"id":35676762},{"atb":[[1.02,1.99]],"id":41529439}],"con":true,"img":false}]}
{"op":"mcm","clk":"5322688432","pt":1646323140401,"mc":[{"id":"1.195532866","rc":[{"atb":[[1.03,0]],"id":26648132},{"atb":[[4.5,0.24]],"id":43094640},{"atb":[[3.6,0.3]],"id":28791281},{"atb":[[8.6,0.12]],"id":35676762},{"atb":[[4.2,0.26]],"id":41529439},{"atb":[[1.02,0]],"id":39213014}],"con":true,"img":false}]}
{"op":"mcm","clk":"5322688440","pt":1646323140510,"mc":[{"id":"1.195532866","rc":[{"atb":[[5.7,0.19]],"id":26648132},{"atb":[[4,0.27]],"id":39213014}],"con":true,"img":false}]}
{"op":"mcm","clk":"5322688447","pt":1646323140608,"mc":[{"id":"1.195532866","rc":[{"atb":[[3.75,17.54]],"id":39213014}],"con":true,"img":false}]}
{"op":"mcm","clk":"5322688456","pt":1646323140715,"mc":[{"id":"1.195532866","rc":[{"atb":[[3.75,7.92]],"id":28791281},{"atb":[[8.8,2.72]],"id":35676762}],"con":true,"img":false}]}
{"op":"mcm","clk":"5322688462","pt":1646323140823,"mc":[{"id":"1.195532866","rc":[{"atl":[[1000,2.5]],"id":39213014}],"con":true,"img":false}]}
{"op":"mcm","clk":"5322688480","pt":1646323140979,"mc":[{"id":"1.195532866","rc":[{"atb":[[3.75,0.14]],"id":28791281},{"atb":[[8.8,0]],"id":35676762},{"atl":[[1000,2]],"id":39213014}],"con":true,"img":false}]}
{"op":"mcm","clk":"5322688488","pt":1646323141083,"mc":[{"id":"1.195532866","rc":[{"atb":[[3.8,8.78]],"id":28791281},{"atb":[[9,5.71]],"id":35676762},{"atl":[[4.7,6.19]],"id":39213014}],"con":true,"img":false}]}
{"op":"mcm","clk":"5322688499","pt":1646323141188,"mc":[{"id":"1.195532866","rc":[{"atb":[[8.6,3.12]],"id":35676762}],"con":true,"img":false}]}
{"op":"mcm","clk":"5322688520","pt":1646323141399,"mc":[{"id":"1.195532866","rc":[{"atb":[[8.6,0.12]],"id":35676762}],"con":true,"img":false}]}
{"op":"mcm","clk":"5322688526","pt":1646323141502,"mc":[{"id":"1.195532866","rc":[{"atb":[[7.8,0]],"id":26648132},{"atb":[[3.8,7.78],[3.65,0]],"id":28791281},{"atb":[[9,4.71]],"id":35676762},{"atb":[[4.1,2]],"id":39213014}],"con":true,"img":false}]}
{"op":"mcm","clk":"5322688537","pt":1646323141606,"mc":[{"id":"1.195532866","rc":[{"atb":[[5.2,0]],"id":26648132},{"atb":[[3.85,1]],"id":28791281},{"atb":[[9.2,1]],"id":35676762}],"con":true,"img":false}]}
{"op":"mcm","clk":"5322688545","pt":1646323141713,"mc":[{"id":"1.195532866","rc":[{"atl":[[14,7.69],[14.5,7.41]],"id":26648132},{"atl":[[8.2,5.56],[8.6,0]],"id":43094640},{"atb":[[3.6,3.8],[3.3,17.37],[3.5,40]],"id":28791281},{"atl":[[5.8,8.33],[5.9,14.66]],"id":28791281},{"atb":[[7.4,15.62],[6.6,0]],"id":35676762},{"atl":[[6.2,7.69]],"id":41529439},{"atb":[[3.65,37.74]],"id":39213014},{"atl":[[4.6,1]],"id":39213014}],"con":true,"img":false}]}
{"op":"mcm","clk":"5322688553","pt":1646323141826,"mc":[{"id":"1.195532866","rc":[{"atl":[[5.9,18.62]],"id":28791281},{"atb":[[1.01,1004.52]],"id":35676762},{"atl":[[5.9,0]],"id":41529439}],"con":true,"img":false}]}
{"op":"mcm","clk":"5322688562","pt":1646323141924,"mc":[{"id":"1.195532866","rc":[{"atb":[[3.6,0.3]],"id":28791281},{"atb":[[3.4,35.08]],"id":39213014}],"con":true,"img":false}]}
{"op":"mcm","clk":"5322688570","pt":1646323141979,"mc":[{"id":"1.195532866","rc":[{"atl":[[5.9,14.66]],"id":28791281},{"atb":[[1.01,1003.26]],"id":35676762}],"con":true,"img":false}]}
{"op":"mcm","clk":"5322688578","pt":1646323142133,"mc":[{"id":"1.195532866","rc":[{"atl":[[5.5,0]],"id":28791281},{"atl":[[5.8,0]],"id":39213014}],"con":true,"img":false}]}
{"op":"mcm","clk":"5322688601","pt":1646323142298,"mc":[{"id":"1.195532866","rc":[{"atb":[[1.01,1002]],"id":35676762},{"atb":[[3.8,2.52]],"id":39213014}],"con":true,"img":false}]}
{"op":"mcm","clk":"5322688609","pt":1646323142400,"mc":[{"id":"1.195532866","rc":[{"atb":[[9.2,2.26]],"id":35676762}],"con":true,"img":false}]}
{"op":"mcm","clk":"5322688615","pt":1646323142500,"mc":[{"id":"1.195532866","rc":[{"atb":[[9.2,1.26]],"id":35676762}],"con":true,"img":false}]}
{"op":"mcm","clk":"5322688623","pt":1646323142607,"mc":[{"id":"1.195532866","rc":[{"atb":[[8,1]],"id":26648132},{"atb":[[3.8,7.65]],"id":28791281},{"atb":[[9,4.65]],"id":35676762}],"con":true,"img":false}]}
{"op":"mcm","clk":"5322688638","pt":1646323142816,"mc":[{"id":"1.195532866","rc":[{"atb":[[8,0]],"id":26648132}],"con":true,"img":false}]}
{"op":"mcm","clk":"5322688647","pt":1646323142915,"mc":[{"id":"1.195532866","rc":[{"atb":[[8.2,1]],"id":26648132}],"con":true,"img":false}]}
{"op":"mcm","clk":"5322688661","pt":1646323143123,"mc":[{"id":"1.195532866","rc":[{"atb":[[1.02,0]],"id":26648132},{"atb":[[3.8,0]],"id":28791281},{"atb":[[9,1.99]],"id":35676762}],"con":true,"img":false}]}
{"op":"mcm","clk":"5322688670","pt":1646323143228,"mc":[{"id":"1.195532866","rc":[{"atb":[[5.7,2.18]],"id":26648132},{"atb":[[3.85,8.65]],"id":28791281},{"atb":[[9.2,3.92]],"id":35676762}],"con":true,"img":false}]}
{"op":"mcm","clk":"5322688693","pt":1646323143493,"mc":[{"id":"1.195532866","rc":[{"atb":[[8.2,0]],"id":26648132},{"atb":[[3.85,7.65]],"id":28791281}],"con":true,"img":false}]}
{"op":"mcm","clk":"5322688704","pt":1646323143591,"mc":[{"id":"1.195532866","rc":[{"atb":[[5.8,1],[5.4,22.73],[5.1,9.76]],"id":26648132},{"atb":[[3.9,1]],"id":28791281}],"con":true,"img":false}]}
{"op":"mcm","clk":"5322688745","pt":1646323144009,"mc":[{"id":"1.195532866","rc":[{"atb":[[5.8,3.48]],"id":26648132}],"con":true,"img":false}]}
{"op":"mcm","clk":"5322688764","pt":1646323144212,"mc":[{"id":"1.195532866","rc":[{"atb":[[3.85,7.52]],"id":28791281},{"atl":[[26,10.41]],"id":35676762}],"con":true,"img":false}]}
{"op":"mcm","clk":"5322688771","pt":1646323144319,"mc":[{"id":"1.195532866","rc":[{"atb":[[5.8,8.03]],"id":26648132},{"atl":[[8,0],[7.8,8.41]],"id":43094640},{"atl":[[26,6.41]],"id":35676762}],"con":true,"img":false}]}
{"op":"mcm","clk":"5322688784","pt":1646323144526,"mc":[{"id":"1.195532866","rc":[{"atl":[[8.2,13.8],[7.8,4.2]],"id":43094640},{"atb":[[3.85,0]],"id":28791281}],"con":true,"img":false}]}
{"op":"mcm","clk":"5322688793","pt":1646323144585,"mc":[{"id":"1.195532866","rc":[{"atb":[[3.9,8.52]],"id":28791281},{"atl":[[7,5.79]],"id":41529439}],"con":true,"img":false}]}
{"op":"mcm","clk":"5322688803","pt":1646323144691,"mc":[{"id":"1.195532866","rc":[{"atb":[[5.7,0.19]],"id":26648132}],"con":true,"img":false}]}
{"op":"mcm","clk":"5322688809","pt":1646323144793,"mc":[{"id":"1.195532866","rc":[{"atb":[[5.9,1.99]],"id":26648132},{"atl":[[7,0]],"id":41529439}],"con":true,"img":false}]}
{"op":"mcm","clk":"5322688823","pt":1646323145000,"mc":[{"id":"1.195532866","rc":[{"atb":[[5.8,7.93]],"id":26648132},{"atb":[[9,0]],"id":35676762}],"con":true,"img":false}]}
{"op":"mcm","clk":"5322688833","pt":1646323145101,"mc":[{"id":"1.195532866","rc":[{"atb":[[9.4,1.99]],"id":35676762}],"con":true,"img":false}]}
{"op":"mcm","clk":"5322688839","pt":1646323145207,"mc":[{"id":"1.195532866","rc":[{"atb":[[5.8,3.48]],"id":26648132}],"con":true,"img":false}]}
{"op":"mcm","clk":"5322688847","pt":1646323145314,"mc":[{"id":"1.195532866","rc":[{"atb":[[5.9,6.44]],"id":26648132}],"con":true,"img":false}]}
{"op":"mcm","clk":"5322688861","pt":1646323145516,"mc":[{"id":"1.195532866","rc":[{"atb":[[5.8,2.48]],"id":26648132},{"atb":[[3.9,7.52]],"id":28791281}],"con":true,"img":false}]}
{"op":"mcm","clk":"5322688871","pt":1646323145618,"mc":[{"id":"1.195532866","rc":[{"atb":[[6,1]],"id":26648132},{"atb":[[3.95,1]],"id":28791281}],"con":true,"img":false}]}
{"op":"mcm","clk":"5322688888","pt":1646323145826,"mc":[{"id":"1.195532866","rc":[{"atb":[[5.9,6.35]],"id":26648132},{"atb":[[9.2,3.85]],"id":35676762}],"con":true,"img":false}]}
{"op":"mcm","clk":"5322688906","pt":1646323145986,"mc":[{"id":"1.195532866","rc":[{"atb":[[5.9,1.99],[5.2,5.02]],"id":26648132},{"atb":[[9.2,1.26]],"id":35676762}],"con":true,"img":false}]}
{"op":"mcm","clk":"5322688914","pt":1646323146095,"mc":[{"id":"1.195532866","rc":[{"atb":[[6,5.36]],"id":26648132},{"atb":[[9.4,4.58]],"id":35676762}],"con":true,"img":false}]}
{"op":"mcm","clk":"5322688923","pt":1646323146194,"mc":[{"id":"1.195532866","rc":[{"atb":[[5.8,0]],"id":26648132}],"con":true,"img":false}]}
{"op":"mcm","clk":"5322688948","pt":1646323146507,"mc":[{"id":"1.195532866","rc":[{"atb":[[7.8,2]],"id":26648132}],"con":true,"img":false}]}
{"op":"mcm","clk":"5322688967","pt":1646323146712,"mc":[{"id":"1.195532866","rc":[{"atb":[[5.9,0]],"id":26648132},{"atb":[[7,0]],"id":35676762}],"con":true,"img":false}]}
{"op":"mcm","clk":"5322688972","pt":1646323146814,"mc":[{"id":"1.195532866","rc":[{"atb":[[6.2,1.99]],"id":26648132},{"atl":[[13.5,8]],"id":26648132},{"atl":[[5.8,20.83]],"id":28791281},{"atb":[[7.6,16.68]],"id":35676762}],"con":true,"img":false}]}
{"op":"mcm","clk":"5322689037","pt":1646323147597,"mc":[{"id":"1.195532866","rc":[{"atb":[[6.2,0],[6,4.36]],"id":26648132}],"con":true,"img":false}]}
{"op":"mcm","clk":"5322689048","pt":1646323147701,"mc":[{"id":"1.195532866","rc":[{"atb":[[8,1],[1.02,1.99]],"id":26648132}],"con":true,"img":false}]}
{"op":"mcm","clk":"5322689059","pt":1646323147906,"mc":[{"id":"1.195532866","rc":[{"atb":[[9.4,2.59]],"id":35676762}],"con":true,"img":false}]}
{"op":"mcm","clk":"5322689070","pt":1646323148014,"mc":[{"id":"1.195532866","rc":[{"atb":[[1.02,1.99]],"id":35676762}],"con":true,"img":false}]}
{"op":"mcm","clk":"5322689087","pt":1646323148220,"mc":[{"id":"1.195532866","rc":[{"atb":[[5.6,0.25]],"id":43094640}],"con":true,"img":false}]}
{"op":"mcm","clk":"5322689095","pt":1646323148323,"mc":[{"id":"1.195532866","rc":[{"atb":[[1.02,1.99]],"id":43094640}],"con":true,"img":false}]}
{"op":"mcm","clk":"5322689113","pt":1646323148534,"mc":[{"id":"1.195532866","rc":[{"atb":[[5.7,0]],"id":43094640}],"con":true,"img":false}]}
{"op":"mcm","clk":"5322689125","pt":1646323148636,"mc":[{"id":"1.195532866","rc":[{"atb":[[5.6,1.25]],"id":43094640}],"con":true,"img":false}]}
{"op":"mcm","clk":"5322689134","pt":1646323148740,"mc":[{"id":"1.195532866","rc":[{"atb":[[6,3.11]],"id":26648132}],"con":true,"img":false}]}
{"op":"mcm","clk":"5322689153","pt":1646323148905,"mc":[{"id":"1.195532866","rc":[{"atb":[[6,0]],"id":26648132}],"con":true,"img":false}]}
{"op":"mcm","clk":"5322689164","pt":1646323149010,"mc":[{"id":"1.195532866","rc":[{"atb":[[8,4.11]],"id":26648132}],"con":true,"img":false}]}
{"op":"mcm","clk":"5322689311","pt":1646323150318,"mc":[{"id":"1.195532866","rc":[{"atb":[[1.03,2],[5.6,1]],"id":43094640},{"atl":[[4.7,5.94]],"id":39213014}],"con":true,"img":false}]}
{"op":"mcm","clk":"5322689332","pt":1646323150554,"mc":[{"id":"1.195532866","rc":[{"atb":[[1.03,2.35]],"id":43094640},{"atb":[[9.2,0]],"id":35676762},{"atb":[[3.8,0]],"id":39213014}],"con":true,"img":false}]}
{"op":"mcm","clk":"5322689346","pt":1646323150609,"mc":[{"id":"1.195532866","rc":[{"atb":[[1.03,0.35]],"id":43094640}],"con":true,"img":false}]}
{"op":"mcm","clk":"5322689363","pt":1646323150811,"mc":[{"id":"1.195532866","rc":[{"atb":[[1.03,0]],"id":43094640}],"con":true,"img":false}]}
{"op":"mcm","clk":"5322689374","pt":1646323150921,"mc":[{"id":"1.195532866","rc":[{"atb":[[5.5,2.35]],"id":43094640}],"con":true,"img":false}]}
{"op":"mcm","clk":"5322689386","pt":1646323151024,"mc":[{"id":"1.195532866","rc":[{"atl":[[8.2,5.56],[7.8,8.41]],"id":43094640}],"con":true,"img":false}]}
{"op":"mcm","clk":"5322689393","pt":1646323151124,"mc":[{"id":"1.195532866","rc":[{"atl":[[9.2,13.43],[7.8,4.2]],"id":43094640}],"con":true,"img":false}]}
{"op":"mcm","clk":"5322689403","pt":1646323151228,"mc":[{"id":"1.195532866","rc":[{"atl":[[7.8,9.76]],"id":43094640}],"con":true,"img":false}]}
{"op":"mcm","clk":"5322689412","pt":1646323151331,"mc":[{"id":"1.195532866","rc":[{"atl":[[9.2,1.23]],"id":43094640},{"atb":[[9.4,0]],"id":35676762}],"con":true,"img":false}]}
{"op":"mcm","clk":"5322689440","pt":1646323151642,"mc":[{"id":"1.195532866","rc":[{"atb":[[7.8,0],[5.2,0]],"id":26648132}],"con":true,"img":false}]}
{"op":"mcm","clk":"5322689456","pt":1646323151745,"mc":[{"id":"1.195532866","rc":[{"atl":[[8.6,13.16]],"id":43094640},{"atl":[[6.6,17.86]],"id":41529439}],"con":true,"img":false}]}
{"op":"mcm","clk":"5322689483","pt":1646323151911,"mc":[{"id":"1.195532866","rc":[{"atb":[[3.95,4.17]],"id":43094640},{"atl":[[10,0],[11,0],[12,0]],"id":43094640},{"atl":[[6.4,0],[6.8,17.24],[7.2,0]],"id":41529439}],"con":true,"img":false}]}
{"op":"mcm","clk":"5322689494","pt":1646323152011,"mc":[{"id":"1.195532866","rc":[{"atb":[[3.95,0]],"id":43094640}],"con":true,"img":false}]}
{"op":"mcm","clk":"5322689503","pt":1646323152116,"mc":[{"id":"1.195532866","rc":[{"atb":[[8,1]],"id":26648132}],"con":true,"img":false}]}
{"op":"mcm","clk":"5322689516","pt":1646323152229,"mc":[{"id":"1.195532866","rc":[{"atb":[[8.2,3.02]],"id":35676762}],"con":true,"img":false}]}
{"op":"mcm","clk":"5322689539","pt":1646323152531,"mc":[{"id":"1.195532866","rc":[{"atb":[[8.2,4.02]],"id":35676762}],"con":true,"img":false}]}
{"op":"mcm","clk":"5322689553","pt":1646323152640,"mc":[{"id":"1.195532866","rc":[{"atb":[[3.75,14.55]],"id":39213014}],"con":true,"img":false}]}
{"op":"mcm","clk":"5322689572","pt":1646323152845,"mc":[{"id":"1.195532866","rc":[{"atb":[[8,0]],"id":26648132},{"atb":[[1.01,1004.52]],"id":35676762},{"atb":[[4.2,2.52]],"id":39213014}],"con":true,"img":false}]}
{"op":"mcm","clk":"5322689584","pt":1646323152947,"mc":[{"id":"1.195532866","rc":[{"atb":[[5.7,1.19]],"id":26648132},{"atb":[[1.01,1003.26]],"id":35676762}],"con":true,"img":false}]}
{"op":"mcm","clk":"5322689595","pt":1646323153011,"mc":[{"id":"1.195532866","rc":[{"atb":[[5.7,5.83]],"id":26648132},{"atb":[[1.01,1002]],"id":35676762}],"con":true,"img":false}]}
{"op":"mcm","clk":"5322689604","pt":1646323153112,"mc":[{"id":"1.195532866","rc":[{"atb":[[8.4,1.26]],"id":35676762}],"con":true,"img":false}]}
{"op":"mcm","clk":"5322689634","pt":1646323153422,"mc":[{"id":"1.195532866","rc":[{"atb":[[1.02,0]],"id":26648132}],"con":true,"img":false}]}
{"op":"mcm","clk":"5322689646","pt":1646323153528,"mc":[{"id":"1.195532866","rc":[{"atb":[[5.8,1.99]],"id":26648132}],"con":true,"img":false}]}
{"op":"mcm","clk":"5322689665","pt":1646323153735,"mc":[{"id":"1.195532866","rc":[{"atb":[[8.2,7.4]],"id":35676762}],"con":true,"img":false}]}
{"op":"mcm","clk":"5322689686","pt":1646323153942,"mc":[{"id":"1.195532866","rc":[{"atb":[[5.7,5.73]],"id":26648132},{"atb":[[1.02,0]],"id":35676762}],"con":true,"img":false}]}
{"op":"mcm","clk":"5322689695","pt":1646323154044,"mc":[{"id":"1.195532866","rc":[{"atb":[[8.4,3.25]],"id":35676762}],"con":true,"img":false}]}
{"op":"mcm","clk":"5322689706","pt":1646323154096,"mc":[{"id":"1.195532866","rc":[{"atb":[[5.7,1.19]],"id":26648132},{"atl":[[28,9.26]],"id":35676762}],"con":true,"img":false}]}
{"op":"mcm","clk":"5322689713","pt":1646323154209,"mc":[{"id":"1.195532866","rc":[{"atb":[[5.8,6.53]],"id":26648132},{"atb":[[2.72,0]],"id":39213014}],"con":true,"img":false}]}
{"op":"mcm","clk":"5322689722","pt":1646323154313,"mc":[{"id":"1.195532866","rc":[{"atb":[[5.4,34.35]],"id":26648132},{"atl":[[12,3.76]],"id":26648132},{"atb":[[1.02,0],[4.2,19.68]],"id":43094640},{"atl":[[7.8,14.64]],"id":43094640},{"atl":[[5.4,14.66]],"id":28791281},{"atb":[[9.2,3.45]],"id":35676762},{"atl":[[20,5.8]],"id":35676762},{"atb":[[4.9,8.54]],"id":41529439},{"atl":[[5.8,6.31]],"id":41529439},{"atb":[[3.75,21.92]],"id":39213014}],"con":true,"img":false}]}
{"op":"mcm","clk":"5322689735","pt":1646323154413,"mc":[{"id":"1.195532866","rc":[{"atb":[[5.6,2.99]],"id":43094640},{"atl":[[20,8.06],[21,0]],"id":35676762}],"con":true,"img":false}]}
{"op":"mcm","clk":"5322689746","pt":1646323154515,"mc":[{"id":"1.195532866","rc":[{"atb":[[5.9,2.48],[5.7,0.19]],"id":26648132},{"atb":[[8.2,6.4]],"id":35676762}],"con":true,"img":false}]}
{"op":"mcm","clk":"5322689759","pt":1646323154619,"mc":[{"id":"1.195532866","rc":[{"atb":[[5.9,3.48]],"id":26648132},{"atb":[[8.6,1.12]],"id":35676762},{"atl":[[22,5.49]],"id":35676762}],"con":true,"img":false}]}
{"op":"mcm","clk":"5322689769","pt":1646323154725,"mc":[{"id":"1.195532866","rc":[{"atb":[[5.8,6.44]],"id":26648132},{"atb":[[8.2,6.04]],"id":35676762}],"con":true,"img":false}]}
{"op":"mcm","clk":"5322689791","pt":1646323154932,"mc":[{"id":"1.195532866","rc":[{"atb":[[5.8,1.99]],"id":26648132},{"atb":[[8.2,3.38]],"id":35676762},{"atl":[[22,1.9]],"id":35676762}],"con":true,"img":false}]}
{"op":"mcm","clk":"5322689804","pt":1646323155034,"mc":[{"id":"1.195532866","rc":[{"atb":[[5.9,7.93]],"id":26648132},{"atb":[[9.2,6.11]],"id":35676762}],"con":true,"img":false}]}
{"op":"mcm","clk":"5322689855","pt":1646323155553,"mc":[{"id":"1.195532866","rc":[{"atb":[[5.8,0]],"id":26648132},{"atl":[[5.3,2.52]],"id":28791281},{"atb":[[8.6,0.12]],"id":35676762}],"con":true,"img":false}]}
{"op":"mcm","clk":"5322689866","pt":1646323155608,"mc":[{"id":"1.195532866","rc":[{"atb":[[6,1.99]],"id":26648132}],"con":true,"img":false}]}
{"op":"mcm","clk":"5322689875","pt":1646323155709,"mc":[{"id":"1.195532866","rc":[{"atl":[[5.4,8.7]],"id":28791281}],"con":true,"img":false}]}
{"op":"mcm","clk":"5322689881","pt":1646323155814,"mc":[{"id":"1.195532866","rc":[{"atl":[[5.2,1]],"id":28791281},{"atb":[[8.4,1.26]],"id":35676762}],"con":true,"img":false}]}
{"op":"mcm","clk":"5322689889","pt":1646323155921,"mc":[{"id":"1.195532866","rc":[{"atb":[[9.4,1.99]],"id":35676762}],"con":true,"img":false}]}
{"op":"mcm","clk":"5322689931","pt":1646323156437,"mc":[{"id":"1.195532866","rc":[{"atb":[[5.9,6.93]],"id":26648132}],"con":true,"img":false}]}
{"op":"mcm","clk":"5322689942","pt":1646323156543,"mc":[{"id":"1.195532866","rc":[{"atb":[[7.8,2],[6.2,1]],"id":26648132}],"con":true,"img":false}]}
{"op":"mcm","clk":"5322689953","pt":1646323156646,"mc":[{"id":"1.195532866","rc":[{"atb":[[5.9,6.84]],"id":26648132},{"atb":[[3.9,0]],"id":28791281},{"atl":[[6,38]],"id":28791281},{"atb":[[9.2,6.04]],"id":35676762}],"con":true,"img":false}]}
{"op":"mcm","clk":"5322689971","pt":1646323156762,"mc":[{"id":"1.195532866","rc":[{"atb":[[5.9,4.36]],"id":26648132},{"atl":[[14.5,18.52]],"id":26648132},{"atl":[[6,30],[5.2,6.19]],"id":28791281},{"atb":[[4.2,9.34]],"id":39213014}],"con":true,"img":false}]}
{"op":"mcm","clk":"5322689982","pt":1646323156856,"mc":[{"id":"1.195532866","rc":[{"atb":[[5.9,0]],"id":26648132},{"atb":[[9.2,3.45]],"id":35676762}],"con":true,"img":false}]}
{"op":"mcm","clk":"5322689992","pt":1646323156912,"mc":[{"id":"1.195532866","rc":[{"atb":[[6,6.35]],"id":26648132},{"atb":[[9.4,4.58]],"id":35676762}],"con":true,"img":false}]}
{"op":"mcm","clk":"5322690017","pt":1646323157130,"mc":[{"id":"1.195532866","rc":[{"atl":[[13,0],[14,0]],"id":26648132},{"atl":[[23,0.16]],"id":35676762},{"atb":[[3.6,4.72]],"id":39213014}],"con":true,"img":false}]}
{"op":"mcm","clk":"5322690047","pt":1646323157336,"mc":[{"id":"1.195532866","rc":[{"atl":[[13.5,12.12],[14.5,22.33]],"id":26648132},{"spn":9.65,"spf":1.0,"id":26648132},{"spn":4.93,"spf":1.0,"id":43094640},{"spn":4.57,"spf":1.0,"id":28791281},{"spn":9.25,"spf":2.1,"id":35676762},{"spn":4.9,"spf":1.0,"id":41529439},{"atb":[[3.6,0]],"id":39213014},{"spn":4.4,"spf":1.0,"id":39213014}],"con":true,"img":false}]}
{"op":"mcm","clk":"5322690068","pt":1646323157534,"mc":[{"id":"1.195532866","rc":[{"atb":[[6.2,0]],"id":26648132},{"atl":[[14.5,18.52]],"id":26648132},{"atb":[[3.95,0]],"id":28791281},{"atb":[[8.2,0]],"id":35676762}],"con":true,"img":false}]}
{"op":"mcm","clk":"5322690083","pt":1646323157644,"mc":[{"id":"1.195532866","rc":[{"atb":[[8,1]],"id":26648132},{"atl":[[13.5,8]],"id":26648132},{"atb":[[3.55,1]],"id":28791281}],"con":true,"img":false}]}
{"op":"mcm","clk":"5322690099","pt":1646323157751,"mc":[{"id":"1.195532866","rc":[{"atb":[[6,4.36]],"id":26648132}],"con":true,"img":false}]}
{"op":"mcm","clk":"5322690111","pt":1646323157851,"mc":[{"id":"1.195532866","rc":[{"atb":[[1.02,1.99]],"id":26648132}],"con":true,"img":false}]}
{"op":"mcm","clk":"5322690129","pt":1646323158060,"mc":[{"id":"1.195532866","rc":[{"atb":[[9.4,2.59]],"id":35676762}],"con":true,"img":false}]}
{"op":"mcm","clk":"5322690140","pt":1646323158120,"mc":[{"id":"1.195532866","rc":[{"atb":[[1.02,1.99]],"id":35676762}],"con":true,"img":false}]}
{"op":"mcm","clk":"5322690160","pt":1646323158324,"mc":[{"id":"1.195532866","rc":[{"atb":[[6,3.11]],"id":26648132},{"atb":[[5.6,1]],"id":43094640}],"con":true,"img":false}]}
{"op":"mcm","clk":"5322690175","pt":1646323158431,"mc":[{"id":"1.195532866","rc":[{"atb":[[1.02,1.99]],"id":43094640},{"atb":[[3.55,3.86]],"id":28791281}],"con":true,"img":false}]}
{"op":"mcm","clk":"5322690182","pt":1646323158531,"mc":[{"id":"1.195532866","rc":[{"atb":[[6,0]],"id":26648132}],"con":true,"img":false}]}
{"op":"mcm","clk":"5322690191","pt":1646323158634,"mc":[{"id":"1.195532866","rc":[{"atb":[[8,4.11]],"id":26648132}],"con":true,"img":false}]}
{"op":"mcm","clk":"5322690198","pt":1646323158738,"mc":[{"id":"1.195532866","rc":[{"atb":[[5.8,11.01]],"id":26648132},{"atb":[[4.2,22.58]],"id":43094640},{"atl":[[7.8,23.25]],"id":43094640},{"atl":[[5.4,17.41]],"id":28791281},{"atb":[[9.2,7.91]],"id":35676762},{"atl":[[20,10.91]],"id":35676762},{"atl":[[5.8,8.81]],"id":41529439},{"atb":[[3.75,32.56]],"id":39213014}],"con":true,"img":false}]}
{"op":"mcm","clk":"5322690266","pt":1646323159531,"mc":[{"id":"1.195532866","rc":[{"atl":[[20,8.65],[21,5]],"id":35676762}],"con":true,"img":false}]}
{"op":"mcm","clk":"5322690300","pt":1646323159938,"mc":[{"id":"1.195532866","rc":[{"atb":[[5.5,2.25]],"id":43094640},{"atb":[[4.2,11.68]],"id":39213014}],"con":true,"img":false}]}
{"op":"mcm","clk":"5322690450","pt":1646323161546,"mc":[{"id":"1.195532866","rc":[{"atl":[[9,18.75]],"id":43094640},{"atb":[[8.4,0]],"id":35676762},{"atl":[[7,25]],"id":41529439}],"con":true,"img":false}]}
{"op":"mcm","clk":"5322690458","pt":1646323161645,"mc":[{"id":"1.195532866","rc":[{"atb":[[7.8,0]],"id":26648132},{"atb":[[3.65,2]],"id":28791281},{"atb":[[4.1,0]],"id":39213014}],"con":true,"img":false}]}
{"op":"mcm","clk":"5322690466","pt":1646323161748,"mc":[{"id":"1.195532866","rc":[{"atl":[[7.6,2.86]],"id":43094640}],"con":true,"img":false}]}
{"op":"mcm","clk":"5322690477","pt":1646323161852,"mc":[{"id":"1.195532866","rc":[{"atl":[[1000,4.52]],"id":35676762}],"con":true,"img":false}]}
{"op":"mcm","clk":"5322690485","pt":1646323161957,"mc":[{"id":"1.195532866","rc":[{"atl":[[7.8,22.25],[8.8,6.39]],"id":43094640}],"con":true,"img":false}]}
{"op":"mcm","clk":"5322690495","pt":1646323162059,"mc":[{"id":"1.195532866","rc":[{"atl":[[7.4,1]],"id":43094640},{"atl":[[1000,3.26]],"id":35676762}],"con":true,"img":false}]}
{"op":"mcm","clk":"5322690505","pt":1646323162163,"mc":[{"id":"1.195532866","rc":[{"atl":[[8,5.71],[8.8,0]],"id":43094640},{"atb":[[3.5,0],[3.45,40.82]],"id":28791281}],"con":true,"img":false}]}
{"op":"mcm","clk":"5322690510","pt":1646323162220,"mc":[{"id":"1.195532866","rc":[{"atl":[[1000,2]],"id":35676762}],"con":true,"img":false}]}
{"op":"mcm","clk":"5322690519","pt":1646323162323,"mc":[{"id":"1.195532866","rc":[{"spl":[[10,5]],"id":26648132},{"spl":[[10,5]],"id":43094640},{"spl":[[10,5]],"id":28791281},{"spl":[[10,5]],"id":35676762},{"atl":[[19.5,1.26]],"id":35676762},{"spl":[[10,15]],"id":41529439},{"spl":[[10,5]],"id":39213014}],"con":true,"img":false}]}
{"op":"mcm","clk":"5322690534","pt":1646323162526,"mc":[{"id":"1.195532866","rc":[{"atb":[[8,1]],"id":26648132},{"atl":[[7.8,19.04]],"id":43094640},{"atl":[[1000,3.65],[20,7.3]],"id":35676762}],"con":true,"img":false}]}
{"op":"mcm","clk":"5322690545","pt":1646323162632,"mc":[{"id":"1.195532866","rc":[{"atb":[[8,0]],"id":26648132},{"atb":[[3.55,2.86]],"id":28791281},{"atl":[[5.3,0]],"id":28791281},{"atl":[[1000,2.21]],"id":35676762}],"con":true,"img":false}]}
{"op":"mcm","clk":"5322690554","pt":1646323162734,"mc":[{"id":"1.195532866","rc":[{"atb":[[8.2,1]],"id":26648132},{"atb":[[3.7,1]],"id":28791281},{"atl":[[1000,2]],"id":35676762}],"con":true,"img":false}]}
{"op":"mcm","clk":"5322690570","pt":1646323162848,"mc":[{"id":"1.195532866","rc":[{"atl":[[19,0.21]],"id":35676762}],"con":true,"img":false}]}
{"op":"mcm","clk":"5322690642","pt":1646323163461,"mc":[{"id":"1.195532866","rc":[{"atb":[[7.4,19.46]],"id":35676762}],"con":true,"img":false}]}
{"op":"mcm","clk":"5322690661","pt":1646323163622,"mc":[{"id":"1.195532866","rc":[{"atl":[[7.4,4.4]],"id":43094640},{"atl":[[5.1,2.52]],"id":28791281},{"atb":[[7.4,15.62]],"id":35676762},{"atl":[[19,1.42]],"id":35676762},{"atb":[[3.05,5.95]],"id":41529439}],"con":true,"img":false}]}
{"op":"mcm","clk":"5322690682","pt":1646323163831,"mc":[{"id":"1.195532866","rc":[{"atb":[[8.2,0]],"id":26648132},{"atl":[[5.2,5.19]],"id":28791281},{"atl":[[21,7],[22,0]],"id":35676762}],"con":true,"img":false}]}
{"op":"mcm","clk":"5322690694","pt":1646323163930,"mc":[{"id":"1.195532866","rc":[{"atb":[[5.9,1]],"id":26648132},{"atl":[[5,1]],"id":28791281},{"atb":[[3.05,0]],"id":41529439}],"con":true,"img":false}]}
{"op":"mcm","clk":"5322690724","pt":1646323164239,"mc":[{"id":"1.195532866","rc":[{"atb":[[4.2,9.15]],"id":39213014}],"con":true,"img":false}]}
{"op":"mcm","clk":"5322690732","pt":1646323164342,"mc":[{"id":"1.195532866","rc":[{"atb":[[5.9,5.45]],"id":26648132}],"con":true,"img":false}]}
{"op":"mcm","clk":"5322690739","pt":1646323164447,"mc":[{"id":"1.195532866","rc":[{"atl":[[7.6,0]],"id":43094640}],"con":true,"img":false}]}
{"op":"mcm","clk":"5322690794","pt":1646323165067,"mc":[{"id":"1.195532866","rc":[{"atb":[[1.02,0]],"id":26648132}],"con":true,"img":false}]}
{"op":"mcm","clk":"5322690806","pt":1646323165170,"mc":[{"id":"1.195532866","rc":[{"atb":[[6,1.99]],"id":26648132}],"con":true,"img":false}]}
{"op":"mcm","clk":"5322690816","pt":1646323165228,"mc":[{"id":"1.195532866","rc":[{"atb":[[6,4.47]],"id":26648132},{"atb":[[1.02,0]],"id":35676762}],"con":true,"img":false}]}
{"op":"mcm","clk":"5322690824","pt":1646323165331,"mc":[{"id":"1.195532866","rc":[{"atb":[[5.9,5.36]],"id":26648132},{"atb":[[9.6,1.99]],"id":35676762}],"con":true,"img":false}]}
{"op":"mcm","clk":"5322690841","pt":1646323165540,"mc":[{"id":"1.195532866","rc":[{"atb":[[5.9,0]],"id":26648132},{"atb":[[1.02,0]],"id":43094640}],"con":true,"img":false}]}
{"op":"mcm","clk":"5322690849","pt":1646323165639,"mc":[{"id":"1.195532866","rc":[{"atb":[[6.2,1],[6,8.83]],"id":26648132},{"atb":[[5.6,2.99]],"id":43094640}],"con":true,"img":false}]}
{"op":"mcm","clk":"5322690859","pt":1646323165744,"mc":[{"id":"1.195532866","rc":[{"atb":[[5.8,14.59]],"id":26648132}],"con":true,"img":false}]}
{"op":"mcm","clk":"5322690880","pt":1646323165951,"mc":[{"id":"1.195532866","rc":[{"atb":[[5.4,39.91]],"id":26648132}],"con":true,"img":false}]}
{"op":"mcm","clk":"5322690921","pt":1646323166367,"mc":[{"id":"1.195532866","rc":[{"atb":[[5.8,11.01]],"id":26648132}],"con":true,"img":false}]}
{"op":"mcm","clk":"5322690931","pt":1646323166421,"mc":[{"id":"1.195532866","rc":[{"atb":[[5.4,34.35]],"id":26648132},{"atl":[[15.5,17.24]],"id":26648132},{"atl":[[6.4,46.3]],"id":28791281}],"con":true,"img":false}]}
{"op":"mcm","clk":"5322690939","pt":1646323166537,"mc":[{"id":"1.195532866","rc":[{"atb":[[6,8.67]],"id":26648132},{"atb":[[9.4,2.53]],"id":35676762}],"con":true,"img":false}]}
{"op":"mcm","clk":"5322690947","pt":1646323166656,"mc":[{"id":"1.195532866","rc":[{"atb":[[7.8,2]],"id":26648132}],"con":true,"img":false}]}
{"op":"mcm","clk":"5322690952","pt":1646323166757,"mc":[{"id":"1.195532866","rc":[{"atb":[[6,4.47]],"id":26648132},{"atb":[[9.4,0]],"id":35676762}],"con":true,"img":false}]}
{"op":"mcm","clk":"5322690961","pt":1646323166860,"mc":[{"id":"1.195532866","rc":[{"atb":[[6.2,5.19]],"id":26648132},{"atb":[[9.6,4.52]],"id":35676762}],"con":true,"img":false}]}
{"op":"mcm","clk":"5322690975","pt":1646323167069,"mc":[{"id":"1.195532866","rc":[{"atb":[[6,2.48]],"id":26648132}],"con":true,"img":false}]}
{"op":"mcm","clk":"5322690984","pt":1646323167137,"mc":[{"id":"1.195532866","rc":[{"atb":[[1.02,1.99]],"id":26648132},{"atl":[[6.2,1.93]],"id":28791281},{"atb":[[7.6,15.15]],"id":35676762}],"con":true,"img":false}]}
{"op":"mcm","clk":"5322690994","pt":1646323167344,"mc":[{"id":"1.195532866","rc":[{"atb":[[7.8,1.48],[9.6,2.53]],"id":35676762}],"con":true,"img":false}]}
{"op":"mcm","clk":"5322691003","pt":1646323167446,"mc":[{"id":"1.195532866","rc":[{"atb":[[1.02,1.99]],"id":35676762}],"con":true,"img":false}]}
{"op":"mcm","clk":"5322691011","pt":1646323167548,"mc":[{"id":"1.195532866","rc":[{"atb":[[6.2,4.19]],"id":26648132}],"con":true,"img":false}]}
{"op":"mcm","clk":"5322691017","pt":1646323167651,"mc":[{"id":"1.195532866","rc":[{"atb":[[8,1],[6,0]],"id":26648132},{"atb":[[5.6,1]],"id":43094640}],"con":true,"img":false}]}
{"op":"mcm","clk":"5322691023","pt":1646323167744,"mc":[{"id":"1.195532866","rc":[{"atb":[[1.02,1.99]],"id":43094640}],"con":true,"img":false}]}
{"op":"mcm","clk":"5322691043","pt":1646323168055,"mc":[{"id":"1.195532866","rc":[{"atb":[[2.82,6.83]],"id":39213014}],"con":true,"img":false}]}
{"op":"mcm","clk":"5322691057","pt":1646323168270,"mc":[{"id":"1.195532866","rc":[{"atb":[[6.2,3.11]],"id":26648132}],"con":true,"img":false}]}
{"op":"mcm","clk":"5322691079","pt":1646323168426,"mc":[{"id":"1.195532866","rc":[{"atb":[[6.2,0]],"id":26648132}],"con":true,"img":false}]}
{"op":"mcm","clk":"5322691091","pt":1646323168528,"mc":[{"id":"1.195532866","rc":[{"atb":[[8,4.11]],"id":26648132}],"con":true,"img":false}]}
{"op":"mcm","clk":"5322691212","pt":1646323169828,"mc":[{"id":"1.195532866","rc":[{"atb":[[4.2,9.1]],"id":39213014}],"con":true,"img":false}]}
{"op":"mcm","clk":"5322691268","pt":1646323170660,"mc":[{"id":"1.195532866","rc":[{"atl":[[19.5,0]],"id":35676762}],"con":true,"img":false}]}
{"op":"mcm","clk":"5322691277","pt":1646323170764,"mc":[{"id":"1.195532866","rc":[{"atb":[[3.55,0]],"id":28791281}],"con":true,"img":false}]}
{"op":"mcm","clk":"5322691308","pt":1646323171133,"mc":[{"id":"1.195532866","rc":[{"atl":[[5.1,0]],"id":28791281},{"atl":[[7.4,39.06]],"id":41529439}],"con":true,"img":false}]}
{"op":"mcm","clk":"5322691330","pt":1646323171343,"mc":[{"id":"1.195532866","rc":[{"atl":[[5,0]],"id":28791281}],"con":true,"img":false}]}
{"op":"mcm","clk":"5322691341","pt":1646323171446,"mc":[{"id":"1.195532866","rc":[{"atl":[[5.1,1]],"id":28791281}],"con":true,"img":false}]}
{"op":"mcm","clk":"5322691350","pt":1646323171570,"mc":[{"id":"1.195532866","rc":[{"atl":[[5.8,41.66],[5.9,0]],"id":28791281}],"con":true,"img":false}]}
