{"op":"mcm","clk":"5305619418","pt":1646080581421,"mc":[{"id":"1.195395426","marketDefinition":{"bspMarket":true,"turnInPlayEnabled":false,"persistenceEnabled":false,"marketBaseRate":7.0,"eventId":"31270458","eventTypeId":"4339","numberOfWinners":2,"bettingType":"ODDS","marketType":"PLACE","marketTime":"2022-03-01T02:54:00.000Z","suspendTime":"2022-03-01T02:54:00.000Z","bspReconciled":false,"complete":true,"inPlay":false,"crossMatching":false,"runnersVoidable":false,"numberOfActiveRunners":7,"betDelay":0,"status":"OPEN","runners":[{"status":"ACTIVE","sortPriority":1,"id":43154454,"name":"1. Buckle Up Iveta"},{"status":"ACTIVE","sortPriority":2,"id":38859241,"name":"2. Theo Dragonet"},{"status":"ACTIVE","sortPriority":3,"id":39318320,"name":"3. Engage The Rage"},{"status":"ACTIVE","sortPriority":4,"id":42189480,"name":"4. Toxic Turtle"},{"status":"ACTIVE","sortPriority":5,"id":36104892,"name":"5. Bridwood Ali"},{"status":"ACTIVE","sortPriority":6,"id":38256919,"name":"6. Warramunga"},{"status":"ACTIVE","sortPriority":7,"id":43154455,"name":"8. Strait Sambuca"}],"regulators":["MR_INT"],"venue":"Devonport","countryCode":"AU","discountAllowed":true,"timezone":"Australia/Sydney","openDate":"2022-03-01T02:00:00.000Z","version":4380714786,"name":"To Be Placed","eventName":"Devonport (AUS) 1st Mar"},"rc":[],"con":true,"img":false}]}
{"op":"mcm","clk":"5305743109","pt":1646082027013,"mc":[{"id":"1.195395426","rc":[{"atb":[[1.85,142.14],[1.9,134.24],[1.95,63.58]],"id":36104892},{"atl":[[5.6,2.61],[7.2,3.87],[4.6,3.33],[9.2,2.92],[13,4]],"id":36104892},{"spn":3.27,"spf":"NaN","id":36104892},{"atb":[[4.3,18.3],[3.9,41.66],[3.65,45.59]],"id":38859241},{"atl":[[32,0.77],[21,0.6],[55,0.44],[110,0.43],[15.5,0.82]],"id":38859241},{"spn":9.9,"spf":"NaN","id":38859241},{"atb":[[1.15,402.72],[1.1,1208.18],[1.05,2416.36]],"id":43154454},{"atl":[[2.82,13.2],[2.22,9.85],[2.42,8.46],[2.62,14.83],[3.05,23.44]],"id":43154454},{"spn":1.68,"spf":"NaN","id":43154454},{"atb":[[4.5,34.51],[5,30.2],[5.5,13.42]],"id":39318320},{"atl":[[18.5,0.68],[85,0.28],[170,0.28],[44,0.55],[27,0.46]],"id":39318320},{"spn":12.0,"spf":"NaN","id":39318320},{"atb":[[4.1,19.48],[3.8,43.14],[3.55,47.38]],"id":43154455},{"atl":[[19.5,0.64],[95,0.5],[48,0.5],[14.5,0.88],[29,0.86]],"id":43154455},{"spn":9.3,"spf":"NaN","id":43154455},{"atb":[[8,17.26],[9,7.55],[7,20.13]],"id":38256919},{"atl":[[300,0.08],[50,0.24],[100,0.11],[200,0.11],[400,0.11]],"id":38256919},{"spn":29.5,"spf":"NaN","id":38256919},{"atb":[[1.2,604.09],[1.25,483.27],[1.3,201.36]],"id":42189480},{"atl":[[2.54,7.8],[3.85,16.86],[2.74,6.9],[3.35,10.22],[2.94,12.39]],"id":42189480},{"spn":1.92,"spf":"NaN","id":42189480}],"con":true,"img":false}]}
{"op":"mcm","clk":"5305747392","pt":1646082083712,"mc":[{"id":"1.195395426","rc":[{"atb":[[1.85,0],[1.9,0],[1.95,0]],"id":36104892},{"atl":[[5.6,0],[7.2,0],[4.6,0],[9.2,0],[13,0]],"id":36104892},{"atb":[[4.3,0],[3.9,0],[3.65,0]],"id":38859241},{"atl":[[32,0],[21,0],[55,0],[110,0],[15.5,0]],"id":38859241},{"atb":[[1.15,0],[1.1,0],[1.05,0]],"id":43154454},{"atl":[[2.82,0],[2.22,0],[2.42,0],[2.62,0],[3.05,0]],"id":43154454},{"atb":[[4.5,0],[5,0],[5.5,0]],"id":39318320},{"atl":[[18.5,0],[85,0],[170,0],[44,0],[27,0]],"id":39318320},{"atb":[[4.1,0],[3.8,0],[3.55,0]],"id":43154455},{"atl":[[19.5,0],[95,0],[48,0],[14.5,0],[29,0]],"id":43154455},{"atb":[[8,0],[9,0],[7,0]],"id":38256919},{"atl":[[300,0],[50,0],[100,0],[200,0],[400,0]],"id":38256919},{"atb":[[1.2,0],[1.25,0],[1.3,0]],"id":42189480},{"atl":[[2.54,0],[3.85,0],[2.74,0],[3.35,0],[2.94,0]],"id":42189480}],"con":true,"img":false}]}
{"op":"mcm","clk":"5305747684","pt":1646082087094,"mc":[{"id":"1.195395426","rc":[{"atb":[[1.85,142.14],[1.9,134.24],[1.95,63.58]],"id":36104892},{"atl":[[5.6,2.61],[7.2,3.87],[4.6,3.33],[9.2,2.92],[13,4]],"id":36104892},{"atb":[[4.3,18.3],[3.9,41.66],[3.65,45.59]],"id":38859241},{"atl":[[32,0.77],[21,0.6],[55,0.44],[110,0.43],[15.5,0.82]],"id":38859241},{"atb":[[1.15,402.72],[1.1,1208.18],[1.05,2416.36]],"id":43154454},{"atl":[[2.82,13.2],[2.22,9.85],[2.42,8.46],[2.62,14.83],[3.05,23.44]],"id":43154454},{"atb":[[4.5,34.51],[5,30.2],[5.5,13.42]],"id":39318320},{"atl":[[18.5,0.68],[85,0.28],[170,0.28],[44,0.55],[27,0.46]],"id":39318320},{"atb":[[4.1,19.48],[3.8,43.14],[3.55,47.38]],"id":43154455},{"atl":[[19.5,0.64],[95,0.5],[48,0.5],[14.5,0.88],[29,0.86]],"id":43154455},{"atb":[[8,17.26],[9,7.55],[7,20.13]],"id":38256919},{"atl":[[300,0.08],[50,0.24],[100,0.11],[200,0.11],[400,0.11]],"id":38256919},{"atb":[[1.2,604.09],[1.25,483.27],[1.3,201.36]],"id":42189480},{"atl":[[2.54,7.8],[3.85,16.86],[2.74,6.9],[3.35,10.22],[2.94,12.39]],"id":42189480}],"con":true,"img":false}]}
{"op":"mcm","clk":"5305990538","pt":1646086602700,"mc":[{"id":"1.195395426","marketDefinition":{"bspMarket":true,"turnInPlayEnabled":false,"persistenceEnabled":false,"marketBaseRate":7.0,"eventId":"31270458","eventTypeId":"4339","numberOfWinners":2,"bettingType":"ODDS","marketType":"PLACE","marketTime":"2022-03-01T02:54:00.000Z","suspendTime":"2022-03-01T02:54:00.000Z","bspReconciled":false,"complete":true,"inPlay":false,"crossMatching":false,"runnersVoidable":false,"numberOfActiveRunners":7,"betDelay":0,"status":"OPEN","runners":[{"status":"ACTIVE","sortPriority":1,"id":43154454,"name":"1. Buckle Up Iveta"},{"status":"ACTIVE","sortPriority":2,"id":38859241,"name":"2. Theo Dragonet"},{"status":"ACTIVE","sortPriority":3,"id":39318320,"name":"3. Engage The Rage"},{"status":"ACTIVE","sortPriority":4,"id":42189480,"name":"4. Toxic Turtle"},{"status":"ACTIVE","sortPriority":5,"id":36104892,"name":"5. Bridwood Ali"},{"status":"ACTIVE","sortPriority":6,"id":38256919,"name":"6. Warramunga"},{"status":"ACTIVE","sortPriority":7,"id":43154455,"name":"8. Strait Sambuca"}],"regulators":["MR_INT"],"venue":"Devonport","countryCode":"AU","discountAllowed":true,"timezone":"Australia/Sydney","openDate":"2022-03-01T02:00:00.000Z","version":4380714786,"name":"To Be Placed","eventName":"Devonport (AUS) 1st Mar"},"rc":[{"atb":[[1.85,142.11],[1.9,134.22],[1.95,63.57]],"id":36104892},{"atl":[[5.6,2.61],[7.2,3.87],[4.6,3.33],[9.2,2.92],[13,4]],"id":36104892},{"spn":3.27,"spf":"NaN","id":36104892},{"atb":[[4.3,18.3],[3.9,41.65],[3.65,45.58]],"id":38859241},{"atl":[[32,0.77],[21,0.6],[55,0.44],[110,0.43],[15.5,0.82]],"id":38859241},{"spn":9.9,"spf":"NaN","id":38859241},{"atb":[[1.15,402.66],[1.1,1207.98],[1.05,2415.97]],"id":43154454},{"atl":[[2.82,13.2],[2.22,9.85],[2.42,8.45],[2.62,14.83],[3.05,23.44]],"id":43154454},{"spn":1.68,"spf":"NaN","id":43154454},{"atb":[[4.5,34.51],[5,30.19],[5.5,13.42]],"id":39318320},{"atl":[[18.5,0.68],[85,0.28],[170,0.28],[44,0.55],[27,0.46]],"id":39318320},{"spn":12.0,"spf":"NaN","id":39318320},{"atb":[[4.1,19.48],[3.8,43.14],[3.55,47.37]],"id":43154455},{"atl":[[19.5,0.64],[95,0.5],[48,0.5],[14.5,0.88],[29,0.86]],"id":43154455},{"spn":9.3,"spf":"NaN","id":43154455},{"atb":[[8,17.25],[9,7.54],[7,20.13]],"id":38256919},{"atl":[[300,0.08],[50,0.24],[100,0.11],[200,0.11],[400,0.11]],"id":38256919},{"spn":29.5,"spf":"NaN","id":38256919},{"atb":[[1.2,603.99],[1.25,483.19],[1.3,201.33]],"id":42189480},{"atl":[[2.54,7.8],[3.85,16.86],[2.74,6.9],[3.35,10.22],[2.94,12.38]],"id":42189480},{"spn":1.92,"spf":"NaN","id":42189480}],"con":true,"img":true}]}
{"op":"mcm","clk":"5306079975","pt":1646088802450,"mc":[{"id":"1.195395426","rc":[{"atb":[[1.85,0],[1.9,0],[1.95,0]],"id":36104892},{"atl":[[5.6,0],[7.2,0],[4.6,0],[9.2,0],[13,0]],"id":36104892},{"spn":"NaN","spf":"NaN","id":36104892},{"atb":[[4.3,0],[3.9,0],[3.65,0]],"id":38859241},{"atl":[[32,0],[21,0],[55,0],[110,0],[15.5,0]],"id":38859241},{"spn":"NaN","spf":"NaN","id":38859241},{"atb":[[1.15,402.66],[1.1,1207.98],[1.05,2415.97]],"id":43154454},{"atl":[[2.82,13.2],[2.22,9.85],[2.42,8.45],[2.62,14.83],[3.05,23.44]],"id":43154454},{"atb":[[4.5,0],[5,0],[5.5,0]],"id":39318320},{"atl":[[18.5,0],[85,0],[170,0],[44,0],[27,0]],"id":39318320},{"spn":"NaN","spf":"NaN","id":39318320},{"atb":[[4.1,0],[3.8,0],[3.55,0]],"id":43154455},{"atl":[[19.5,0],[95,0],[48,0],[14.5,0],[29,0]],"id":43154455},{"spn":"NaN","spf":"NaN","id":43154455},{"atb":[[8,17.25],[9,7.54],[7,20.13]],"id":38256919},{"atb":[[1.2,0],[1.25,0],[1.3,0]],"id":42189480},{"atl":[[2.54,0],[3.85,0],[2.74,0],[3.35,0],[2.94,0]],"id":42189480},{"spn":"NaN","spf":"NaN","id":42189480}],"con":true,"img":false}]}
{"op":"mcm","clk":"5306080184","pt":1646088808513,"mc":[{"id":"1.195395426","rc":[{"atb":[[1.85,142.11],[1.9,134.22],[1.95,63.57]],"id":36104892},{"atl":[[5.6,2.61],[7.2,3.87],[4.6,3.33],[9.2,2.92],[13,4]],"id":36104892},{"atb":[[4.3,18.3],[3.9,41.65],[3.65,45.58]],"id":38859241},{"atl":[[32,0.77],[21,0.6],[55,0.44],[110,0.43],[15.5,0.82]],"id":38859241},{"atb":[[4.5,34.51],[5,30.19],[5.5,13.42]],"id":39318320},{"atl":[[18.5,0.68],[85,0.28],[170,0.28],[44,0.55],[27,0.46]],"id":39318320},{"atb":[[4,40.26],[4.5,17.25],[3.75,43.92]],"id":43154455},{"atl":[[16,0.8],[34,0.73],[22,0.57],[60,0.4],[120,0.4]],"id":43154455},{"atb":[[1.4,150.99],[1.3,402.66],[1.35,345.13]],"id":42189480},{"atl":[[4.3,14.56],[2.86,6.46],[2.66,7.23],[3.15,11.17],[3.65,9.06]],"id":42189480}],"con":true,"img":false}]}
{"op":"mcm","clk":"5306083562","pt":1646088893632,"mc":[{"id":"1.195395426","rc":[{"spn":3.27,"spf":"NaN","id":36104892},{"atb":[[4.3,0],[3.9,0],[3.65,0]],"id":38859241},{"atl":[[32,0],[21,0],[55,0],[110,0],[15.5,0]],"id":38859241},{"spn":12.0,"spf":"NaN","id":39318320},{"atb":[[4,0],[4.5,0],[3.75,0]],"id":43154455},{"atl":[[16,0],[34,0],[22,0],[60,0],[120,0]],"id":43154455},{"atb":[[8,0],[9,0],[7,0]],"id":38256919},{"atl":[[300,0],[50,0],[100,0],[200,0],[400,0]],"id":38256919},{"spn":"NaN","spf":"NaN","id":38256919},{"spn":2.03,"spf":"NaN","id":42189480}],"con":true,"img":false}]}
{"op":"mcm","clk":"5306083952","pt":1646088902638,"mc":[{"id":"1.195395426","rc":[{"atb":[[2.74,69.42],[2.84,65.64],[2.94,31.13]],"id":38859241},{"atl":[[8,1.71],[10,1.33],[20,1.26],[15,1.71],[30,1.65]],"id":38859241},{"atb":[[4,40.26],[4.5,34.51],[5,15.09]],"id":43154455},{"atl":[[17,0.75],[70,0.34],[140,0.34],[38,0.64],[24,0.52]],"id":43154455},{"atb":[[7.4,18.87],[8.4,16.32],[9.4,7.19]],"id":38256919},{"atl":[[310,0.07],[410,0.11],[210,0.11],[55,0.22],[110,0.1]],"id":38256919}],"con":true,"img":false}]}
{"op":"mcm","clk":"5306161822","pt":1646091262073,"mc":[{"id":"1.195395426","rc":[{"atb":[[1.85,0],[1.9,0],[1.95,0]],"id":36104892},{"atl":[[5.6,0],[7.2,0],[4.6,0],[9.2,0],[13,0]],"id":36104892},{"spn":"NaN","spf":"NaN","id":36104892},{"atb":[[2.74,0],[2.84,0],[2.94,0]],"id":38859241},{"atl":[[8,0],[10,0],[20,0],[15,0],[30,0]],"id":38859241},{"atb":[[1.15,0],[1.1,0],[1.05,0]],"id":43154454},{"atl":[[2.82,0],[2.22,0],[2.42,0],[2.62,0],[3.05,0]],"id":43154454},{"spn":"NaN","spf":"NaN","id":43154454},{"atb":[[4,0],[4.5,0],[5,0]],"id":43154455},{"atl":[[17,0],[70,0],[140,0],[38,0],[24,0]],"id":43154455},{"atb":[[7.4,0],[8.4,0],[9.4,0]],"id":38256919},{"atl":[[310,0],[410,0],[210,0],[55,0],[110,0]],"id":38256919},{"atb":[[1.4,0],[1.3,0],[1.35,0]],"id":42189480},{"atl":[[4.3,0],[2.86,0],[2.66,0],[3.15,0],[3.65,0]],"id":42189480},{"spn":"NaN","spf":"NaN","id":42189480}],"con":true,"img":false}]}
{"op":"mcm","clk":"5306162001","pt":1646091266482,"mc":[{"id":"1.195395426","rc":[{"atb":[[1.85,142.11],[1.9,134.22],[1.95,63.57]],"id":36104892},{"atl":[[5.6,2.61],[7.2,3.87],[4.6,3.33],[9.2,2.92],[13,4]],"id":36104892},{"atb":[[2.74,69.42],[2.84,65.64],[2.94,31.13]],"id":38859241},{"atl":[[8,1.71],[10,1.33],[20,1.26],[15,1.71],[30,1.65]],"id":38859241},{"atb":[[1.15,402.66],[1.1,1207.98],[1.05,2415.97]],"id":43154454},{"atl":[[2.82,13.2],[2.22,9.85],[2.42,8.45],[2.62,14.83],[3.05,23.44]],"id":43154454},{"atb":[[4,40.26],[4.5,34.51],[5,15.09]],"id":43154455},{"atl":[[17,0.75],[70,0.34],[140,0.34],[38,0.64],[24,0.52]],"id":43154455},{"atb":[[7.4,18.87],[8.4,16.32],[9.4,7.19]],"id":38256919},{"atl":[[310,0.07],[410,0.11],[210,0.11],[55,0.22],[110,0.1]],"id":38256919},{"atb":[[1.4,150.99],[1.3,402.66],[1.35,345.13]],"id":42189480},{"atl":[[4.3,14.56],[2.86,6.46],[2.66,7.23],[3.15,11.17],[3.65,9.06]],"id":42189480}],"con":true,"img":false}]}
{"op":"mcm","clk":"5306165600","pt":1646091353676,"mc":[{"id":"1.195395426","rc":[{"spn":3.27,"spf":"NaN","id":36104892},{"spn":5.47,"spf":"NaN","id":38859241},{"atb":[[1.15,0],[1.1,0],[1.05,0]],"id":43154454},{"atl":[[2.82,0],[2.22,0],[2.42,0],[2.62,0],[3.05,0]],"id":43154454},{"spn":11.0,"spf":"NaN","id":43154455},{"atb":[[7.4,0],[8.4,0],[9.4,0]],"id":38256919},{"atl":[[310,0],[410,0],[210,0],[55,0],[110,0]],"id":38256919},{"spn":2.03,"spf":"NaN","id":42189480}],"con":true,"img":false}]}
{"op":"mcm","clk":"5306165874","pt":1646091361214,"mc":[{"id":"1.195395426","rc":[{"atb":[[1.15,402.66],[1.1,1207.98],[1.05,2415.97]],"id":43154454},{"atl":[[2.82,13.2],[2.22,9.85],[2.42,8.45],[2.62,14.83],[3.05,23.44]],"id":43154454},{"atb":[[8.6,7.94],[7.6,18.3],[6.6,21.57]],"id":38256919},{"atl":[[280,0.08],[90,0.13],[180,0.13],[46,0.26],[380,0.12]],"id":38256919}],"con":true,"img":false}]}
{"op":"mcm","clk":"5306196794","pt":1646092002687,"mc":[{"id":"1.195395426","marketDefinition":{"bspMarket":true,"turnInPlayEnabled":false,"persistenceEnabled":false,"marketBaseRate":7.0,"eventId":"31270458","eventTypeId":"4339","numberOfWinners":2,"bettingType":"ODDS","marketType":"PLACE","marketTime":"2022-03-01T02:54:00.000Z","suspendTime":"2022-03-01T02:54:00.000Z","bspReconciled":false,"complete":true,"inPlay":false,"crossMatching":false,"runnersVoidable":false,"numberOfActiveRunners":7,"betDelay":0,"status":"OPEN","runners":[{"status":"ACTIVE","sortPriority":1,"id":43154454,"name":"1. Buckle Up Iveta"},{"status":"ACTIVE","sortPriority":2,"id":38859241,"name":"2. Theo Dragonet"},{"status":"ACTIVE","sortPriority":3,"id":39318320,"name":"3. Engage The Rage"},{"status":"ACTIVE","sortPriority":4,"id":42189480,"name":"4. Toxic Turtle"},{"status":"ACTIVE","sortPriority":5,"id":36104892,"name":"5. Bridwood Ali"},{"status":"ACTIVE","sortPriority":6,"id":38256919,"name":"6. Warramunga"},{"status":"ACTIVE","sortPriority":7,"id":43154455,"name":"8. Strait Sambuca"}],"regulators":["MR_INT"],"venue":"Devonport","countryCode":"AU","discountAllowed":true,"timezone":"Australia/Sydney","openDate":"2022-03-01T02:00:00.000Z","version":4380714786,"name":"To Be Placed","eventName":"Devonport (AUS) 1st Mar"},"rc":[{"atb":[[1.85,142.11],[1.9,134.22],[1.95,63.57]],"id":36104892},{"atl":[[5.6,2.61],[7.2,3.87],[4.6,3.33],[9.2,2.92],[13,4]],"id":36104892},{"spn":3.27,"spf":"NaN","id":36104892},{"atb":[[2.74,69.42],[2.84,65.64],[2.94,31.13]],"id":38859241},{"atl":[[8,1.71],[10,1.33],[20,1.26],[15,1.71],[30,1.65]],"id":38859241},{"spn":5.47,"spf":"NaN","id":38859241},{"atb":[[1.15,402.66],[1.1,1207.98],[1.05,2415.97]],"id":43154454},{"atl":[[2.82,13.2],[2.22,9.85],[2.42,8.45],[2.62,14.83],[3.05,23.44]],"id":43154454},{"spn":1.68,"spf":"NaN","id":43154454},{"atb":[[4.5,34.51],[5,30.19],[5.5,13.42]],"id":39318320},{"atl":[[18.5,0.68],[85,0.28],[170,0.28],[44,0.55],[27,0.46]],"id":39318320},{"spn":12.0,"spf":"NaN","id":39318320},{"atb":[[4,40.26],[4.5,34.51],[5,15.09]],"id":43154455},{"atl":[[17,0.75],[70,0.34],[140,0.34],[38,0.64],[24,0.52]],"id":43154455},{"spn":11.0,"spf":"NaN","id":43154455},{"atb":[[8.6,7.94],[7.6,18.3],[6.6,21.57]],"id":38256919},{"atl":[[280,0.08],[90,0.13],[180,0.13],[46,0.26],[380,0.12]],"id":38256919},{"spn":27.3,"spf":"NaN","id":38256919},{"atb":[[1.4,150.99],[1.3,402.66],[1.35,345.13]],"id":42189480},{"atl":[[4.3,14.56],[2.86,6.46],[2.66,7.23],[3.15,11.17],[3.65,9.06]],"id":42189480},{"spn":2.03,"spf":"NaN","id":42189480}],"con":true,"img":true}]}
{"op":"mcm","clk":"5306280781","pt":1646094293974,"mc":[{"id":"1.195395426","rc":[{"atb":[[1.85,0],[1.9,0],[1.95,0]],"id":36104892},{"atl":[[5.6,0],[7.2,0],[4.6,0],[9.2,0],[13,0]],"id":36104892},{"spn":"NaN","spf":"NaN","id":36104892},{"atb":[[2.74,0],[2.84,0],[2.94,0]],"id":38859241},{"atl":[[8,0],[10,0],[20,0],[15,0],[30,0]],"id":38859241},{"spn":"NaN","spf":"NaN","id":38859241},{"atb":[[1.15,402.4],[1.1,1207.2],[1.05,2414.4]],"id":43154454},{"atl":[[2.82,13.19],[2.22,9.84],[2.42,8.45],[2.62,14.82],[3.05,23.43]],"id":43154454},{"spn":1.68,"spf":"NaN","id":43154454},{"atb":[[4.5,0],[5,0],[5.5,0]],"id":39318320},{"atl":[[18.5,0],[85,0],[170,0],[44,0],[27,0]],"id":39318320},{"spn":"NaN","spf":"NaN","id":39318320},{"atb":[[4,40.24],[4.5,34.49],[5,15.09]],"id":43154455},{"atl":[[17,0.75],[70,0.34],[140,0.34],[38,0.64],[24,0.52]],"id":43154455},{"atb":[[8.6,0],[7.6,0],[6.6,0]],"id":38256919},{"atl":[[280,0],[90,0],[180,0],[46,0],[380,0]],"id":38256919},{"atb":[[1.4,0],[1.3,0],[1.35,0]],"id":42189480},{"atl":[[4.3,0],[2.86,0],[2.66,0],[3.15,0],[3.65,0]],"id":42189480},{"spn":"NaN","spf":"NaN","id":42189480}],"con":true,"img":false}]}
{"op":"mcm","clk":"5306280958","pt":1646094301361,"mc":[{"id":"1.195395426","rc":[{"atb":[[1.85,142.02],[1.9,134.13],[1.95,63.53]],"id":36104892},{"atl":[[5.6,2.61],[7.2,3.87],[4.6,3.33],[9.2,2.92],[13,4]],"id":36104892},{"atb":[[3.1,57.48],[3.35,25.68],[2.94,62.22]],"id":38859241},{"atl":[[17,1.5],[38,1.29],[12,1.09],[24,1.04],[8.8,1.54]],"id":38859241},{"atb":[[5.8,25.15],[5.3,28.07],[6.6,10.77]],"id":39318320},{"atl":[[70,0.34],[140,0.17],[38,0.32],[24,0.52],[240,0.2]],"id":39318320},{"atb":[[9.8,6.85],[8.8,15.47],[7.8,17.75]],"id":38256919},{"atl":[[70,0.17],[140,0.08],[340,0.07],[440,0.1],[240,0.1]],"id":38256919},{"atb":[[1.2,603.6],[1.25,482.88],[1.3,201.2]],"id":42189480},{"atl":[[2.54,7.79],[3.85,16.85],[2.74,6.9],[3.35,10.21],[2.94,12.38]],"id":42189480}],"con":true,"img":false}]}
{"op":"mcm","clk":"5306404707","pt":1646097402655,"mc":[{"id":"1.195395426","marketDefinition":{"bspMarket":true,"turnInPlayEnabled":false,"persistenceEnabled":false,"marketBaseRate":7.0,"eventId":"31270458","eventTypeId":"4339","numberOfWinners":2,"bettingType":"ODDS","marketType":"PLACE","marketTime":"2022-03-01T02:54:00.000Z","suspendTime":"2022-03-01T02:54:00.000Z","bspReconciled":false,"complete":true,"inPlay":false,"crossMatching":false,"runnersVoidable":false,"numberOfActiveRunners":7,"betDelay":0,"status":"OPEN","runners":[{"status":"ACTIVE","sortPriority":1,"id":43154454,"name":"1. Buckle Up Iveta"},{"status":"ACTIVE","sortPriority":2,"id":38859241,"name":"2. Theo Dragonet"},{"status":"ACTIVE","sortPriority":3,"id":39318320,"name":"3. Engage The Rage"},{"status":"ACTIVE","sortPriority":4,"id":42189480,"name":"4. Toxic Turtle"},{"status":"ACTIVE","sortPriority":5,"id":36104892,"name":"5. Bridwood Ali"},{"status":"ACTIVE","sortPriority":6,"id":38256919,"name":"6. Warramunga"},{"status":"ACTIVE","sortPriority":7,"id":43154455,"name":"8. Strait Sambuca"}],"regulators":["MR_INT"],"venue":"Devonport","countryCode":"AU","discountAllowed":true,"timezone":"Australia/Sydney","openDate":"2022-03-01T02:00:00.000Z","version":4380714786,"name":"To Be Placed","eventName":"Devonport (AUS) 1st Mar"},"rc":[{"atb":[[1.85,142.02],[1.9,134.13],[1.95,63.53]],"id":36104892},{"atl":[[5.6,2.61],[7.2,3.87],[4.6,3.33],[9.2,2.92],[13,4]],"id":36104892},{"spn":3.27,"spf":"NaN","id":36104892},{"atb":[[3.1,57.48],[3.35,25.68],[2.94,62.22]],"id":38859241},{"atl":[[17,1.5],[38,1.29],[12,1.09],[24,1.04],[8.8,1.54]],"id":38859241},{"spn":6.07,"spf":"NaN","id":38859241},{"atb":[[1.15,402.4],[1.1,1207.2],[1.05,2414.4]],"id":43154454},{"atl":[[2.82,13.19],[2.22,9.84],[2.42,8.45],[2.62,14.82],[3.05,23.43]],"id":43154454},{"spn":1.68,"spf":"NaN","id":43154454},{"atb":[[5.8,25.15],[5.3,28.07],[6.6,10.77]],"id":39318320},{"atl":[[70,0.34],[140,0.17],[38,0.32],[24,0.52],[240,0.2]],"id":39318320},{"spn":15.3,"spf":"NaN","id":39318320},{"atb":[[4,40.24],[4.5,34.49],[5,15.09]],"id":43154455},{"atl":[[17,0.75],[70,0.34],[140,0.34],[38,0.64],[24,0.52]],"id":43154455},{"spn":11.0,"spf":"NaN","id":43154455},{"atb":[[9.8,6.85],[8.8,15.47],[7.8,17.75]],"id":38256919},{"atl":[[70,0.17],[140,0.08],[340,0.07],[440,0.1],[240,0.1]],"id":38256919},{"spn":39.9,"spf":"NaN","id":38256919},{"atb":[[1.2,603.6],[1.25,482.88],[1.3,201.2]],"id":42189480},{"atl":[[2.54,7.79],[3.85,16.85],[2.74,6.9],[3.35,10.21],[2.94,12.38]],"id":42189480},{"spn":1.92,"spf":"NaN","id":42189480}],"con":true,"img":true}]}
{"op":"mcm","clk":"5306431887","pt":1646098024215,"mc":[{"id":"1.195395426","rc":[{"atb":[[1.63,85.85],[1.91,47.54]],"id":36104892},{"atl":[[6.6,9.01],[5.9,8.83]],"id":36104892},{"spn":3.27,"spf":"NaN","id":36104892},{"atb":[[3.15,20.12],[2.96,31.18]],"id":38859241},{"atl":[[14,3.32],[15.5,4.21]],"id":38859241},{"spn":6.07,"spf":"NaN","id":38859241},{"atb":[[1.16,378.6],[1.19,94.03]],"id":43154454},{"atl":[[2.4,43.26],[2.22,45.3]],"id":43154454},{"spn":1.7,"spf":"NaN","id":43154454},{"atb":[[6.6,22.13],[7.8,6.36]],"id":39318320},{"atl":[[46,2.7],[50,2.7]],"id":39318320},{"spn":15.9,"spf":"NaN","id":39318320},{"atb":[[4.1,18.53],[4.7,11.69]],"id":43154455},{"atl":[[26,2.7],[28,2.7]],"id":43154455},{"atb":[[9,6.91],[11,4.32]],"id":38256919},{"atl":[[100,0.43],[110,2.7]],"id":38256919},{"spn":40.5,"spf":"NaN","id":38256919},{"atb":[[1.41,105.53],[1.34,173.6]],"id":42189480},{"atl":[[3.8,19.22],[3.65,15.45]],"id":42189480},{"spn":1.97,"spf":"NaN","id":42189480}],"con":true,"img":false}]}
{"op":"mcm","clk":"5306435152","pt":1646098088291,"mc":[{"id":"1.195395426","rc":[{"atb":[[1.91,0]],"id":36104892},{"atb":[[4.1,0],[4.7,0]],"id":43154455}],"con":true,"img":false}]}
{"op":"mcm","clk":"5306435157","pt":1646098088396,"mc":[{"id":"1.195395426","rc":[{"atb":[[1.96,47.54]],"id":36104892},{"atb":[[5.1,11.69],[4.6,18.53]],"id":43154455}],"con":true,"img":false}]}
{"op":"mcm","clk":"5306499471","pt":1646099640364,"mc":[{"id":"1.195395426","rc":[{"atl":[[8.6,7.74]],"id":36104892},{"spn":3.28,"spf":"NaN","id":36104892},{"spn":11.05,"spf":"NaN","id":43154455},{"atl":[[30,3.45]],"id":42189480}],"con":true,"img":false}]}
{"op":"mcm","clk":"5306499537","pt":1646099641752,"mc":[{"id":"1.195395426","rc":[{"atb":[[1.62,62.36]],"id":38859241},{"atl":[[16.5,4.87]],"id":38859241},{"atl":[[4.3,30.3]],"id":43154454},{"atb":[[3.5,40]],"id":39318320},{"atl":[[46,4.92]],"id":39318320},{"atb":[[2.5,37.08]],"id":43154455},{"atl":[[27,2]],"id":43154455},{"atb":[[6,13.82]],"id":38256919},{"atl":[[100,2.43]],"id":38256919}],"con":true,"img":false}]}
{"op":"mcm","clk":"5306501921","pt":1646099694222,"mc":[{"id":"1.195395426","rc":[{"atl":[[50,0]],"id":39318320},{"atl":[[28,0]],"id":43154455},{"atl":[[110,0]],"id":38256919}],"con":true,"img":false}]}
{"op":"mcm","clk":"5306501925","pt":1646099694324,"mc":[{"id":"1.195395426","rc":[{"atl":[[44,2.7]],"id":39318320},{"atl":[[26,5.4]],"id":43154455},{"atl":[[140,2.08],[95,2.7],[100,0.43]],"id":38256919}],"con":true,"img":false}]}
{"op":"mcm","clk":"5306501932","pt":1646099694426,"mc":[{"id":"1.195395426","rc":[{"atl":[[95,4.7]],"id":38256919}],"con":true,"img":false}]}
{"op":"mcm","clk":"5306501936","pt":1646099694527,"mc":[{"id":"1.195395426","rc":[{"atl":[[140,0.08],[95,2.7],[100,2.43]],"id":38256919}],"con":true,"img":false}]}
{"op":"mcm","clk":"5306502184","pt":1646099701013,"mc":[{"id":"1.195395426","rc":[{"atl":[[10.5,10.53],[30,0]],"id":42189480}],"con":true,"img":false}]}
{"op":"mcm","clk":"5306512615","pt":1646099938430,"mc":[{"id":"1.195395426","rc":[{"atl":[[4.5,3.34]],"id":36104892},{"spn":3.23,"spf":"NaN","id":36104892},{"atb":[[1.62,0],[3.05,48.78]],"id":38859241},{"atl":[[4.3,0],[2.7,58.1]],"id":43154454},{"atb":[[4.3,30.3]],"id":39318320},{"atb":[[2.5,0],[3.35,37.08]],"id":43154455},{"atb":[[6,0],[4.4,20.73]],"id":38256919},{"atb":[[1.36,211.06]],"id":42189480}],"con":true,"img":false}]}
{"op":"mcm","clk":"5306512618","pt":1646099938482,"mc":[{"id":"1.195395426","rc":[{"atl":[[8.6,0]],"id":36104892},{"atb":[[3.5,0]],"id":39318320}],"con":true,"img":false}]}
{"op":"mcm","clk":"5306512812","pt":1646099943201,"mc":[{"id":"1.195395426","rc":[{"atb":[[1.36,0],[1.35,285.71]],"id":42189480}],"con":true,"img":false}]}
{"op":"mcm","clk":"5306512822","pt":1646099943408,"mc":[{"id":"1.195395426","rc":[{"atb":[[1.36,211.06],[1.35,0]],"id":42189480}],"con":true,"img":false}]}
{"op":"mcm","clk":"5306515088","pt":1646099993564,"mc":[{"id":"1.195395426","rc":[{"atb":[[1.34,0]],"id":42189480},{"atl":[[2.92,22.53],[3.65,0]],"id":42189480}],"con":true,"img":false}]}
{"op":"mcm","clk":"5306515091","pt":1646099993667,"mc":[{"id":"1.195395426","rc":[{"atb":[[1.37,173.6]],"id":42189480}],"con":true,"img":false}]}
{"op":"mcm","clk":"5306515186","pt":1646099995363,"mc":[{"id":"1.195395426","rc":[{"atb":[[2.94,113.77],[3.05,0]],"id":38859241},{"atb":[[4.3,0],[3.85,35.09]],"id":39318320},{"atb":[[4.4,0],[3.75,22.39]],"id":38256919},{"atb":[[1.36,0],[1.22,454.55]],"id":42189480}],"con":true,"img":false}]}
{"op":"mcm","clk":"5306515193","pt":1646099995465,"mc":[{"id":"1.195395426","rc":[{"atl":[[16.5,0],[14,7.53]],"id":38859241}],"con":true,"img":false}]}
{"op":"mcm","clk":"5306515202","pt":1646099995568,"mc":[{"id":"1.195395426","rc":[{"atb":[[1.22,0],[1.42,173.6]],"id":42189480}],"con":true,"img":false}]}
{"op":"mcm","clk":"5306515468","pt":1646100000607,"mc":[{"id":"1.195395426","rc":[{"atb":[[2.78,56.18],[2.94,62.22]],"id":38859241},{"spn":1.98,"spf":"NaN","id":42189480}],"con":true,"img":false}]}
{"op":"mcm","clk":"5306517443","pt":1646100036690,"mc":[{"id":"1.195395426","rc":[{"atb":[[1.63,85.88],[1.85,142.08],[1.9,134.19],[1.96,47.56],[1.95,63.56]],"id":36104892},{"atl":[[5.6,2.61],[7.2,3.87],[4.6,3.33],[9.2,2.92],[13,4],[6.6,9.02],[5.9,8.83]],"id":36104892},{"atb":[[2.9,52.63],[3.1,57.51],[3.35,25.69],[3.15,20.13],[2.96,31.19],[2.78,0],[2.94,62.25]],"id":38859241},{"atl":[[17,1.5],[38,1.29],[12,1.09],[24,1.04],[8.8,1.54],[14,7.53],[15.5,4.21]],"id":38859241},{"atb":[[1.16,378.76],[1.15,402.57],[1.19,94.07],[1.1,1207.72],[1.05,2415.45]],"id":43154454},{"atl":[[2.4,43.28],[2.82,13.2],[2.9,52.63],[2.22,45.32],[2.42,8.45],[2.62,14.83],[3.05,23.44],[2.7,0]],"id":43154454},{"atb":[[3.85,0],[5.8,25.16],[5.3,28.08],[2.64,50.3],[7.8,6.36],[6.6,22.14]],"id":39318320},{"atl":[[70,0.34],[38,0.32],[44,2.7],[46,4.92],[24,0.52]],"id":39318320},{"atb":[[4,40.25],[5.1,11.69],[4.5,34.5],[5,15.09],[4.6,18.54],[3.35,0],[2.62,53.03]],"id":43154455},{"atl":[[17,0.75],[70,0.34],[140,0.34],[38,0.64],[24,0.52],[26,5.41]],"id":43154455},{"atb":[[9,6.91],[11,4.32],[9.8,6.86],[8.8,15.48],[7.8,17.75],[1.31,22.39],[3.75,0]],"id":38256919},{"atl":[[95,2.7],[100,2.43]],"id":38256919},{"atb":[[1.41,105.57],[1.2,603.86],[1.37,173.67],[1.25,483.09],[1.3,201.28],[1.42,0],[1.34,294.12]],"id":42189480},{"atl":[[2.92,22.54],[2.54,7.8],[3.85,16.86],[2.74,6.9],[3.35,10.22],[3.8,19.23],[2.94,12.38]],"id":42189480}],"con":true,"img":false}]}
{"op":"mcm","clk":"5306518194","pt":1646100052299,"mc":[{"id":"1.195395426","rc":[{"atl":[[15.5,0]],"id":38859241}],"con":true,"img":false}]}
{"op":"mcm","clk":"5306518199","pt":1646100052403,"mc":[{"id":"1.195395426","rc":[{"atl":[[13.5,4.21]],"id":38859241}],"con":true,"img":false}]}
{"op":"mcm","clk":"5306519027","pt":1646100069875,"mc":[{"id":"1.195395426","rc":[{"atl":[[2.9,0],[2.78,56.18]],"id":43154454},{"atb":[[2.64,0],[2.94,50.3]],"id":39318320},{"atb":[[2.82,53.03],[2.62,0]],"id":43154455},{"atb":[[1.62,22.39],[1.31,0]],"id":38256919},{"atb":[[1.37,384.83],[1.34,0]],"id":42189480},{"spn":1.97,"spf":"NaN","id":42189480}],"con":true,"img":false}]}
{"op":"mcm","clk":"5306522927","pt":1646100156722,"mc":[{"id":"1.195395426","rc":[{"atb":[[2.9,0],[2.74,57.47]],"id":38859241},{"atl":[[2.9,52.63],[2.78,0]],"id":43154454},{"atb":[[2.64,50.32],[2.94,0]],"id":39318320},{"atb":[[2.82,0],[2.62,53.05]],"id":43154455},{"atb":[[1.62,0],[1.31,22.41]],"id":38256919},{"atb":[[1.37,173.67],[1.34,294.12]],"id":42189480}],"con":true,"img":false}]}
{"op":"mcm","clk":"5306542914","pt":1646100550891,"mc":[{"id":"1.195395426","rc":[{"atl":[[4.5,0],[8.4,7.21]],"id":36104892},{"spn":3.28,"spf":"NaN","id":36104892},{"atb":[[2.74,0],[1.62,88.66]],"id":38859241},{"atl":[[11.5,4.22],[14,3.32]],"id":38859241},{"atl":[[2.9,0],[2.7,58.12]],"id":43154454},{"atb":[[2.64,0],[3.5,40]],"id":39318320},{"atl":[[46,2.7]],"id":39318320},{"atb":[[2.9,52.63],[2.62,0]],"id":43154455},{"atb":[[6,20],[1.31,0]],"id":38256919},{"atl":[[100,0.43]],"id":38256919},{"atb":[[1.34,0]],"id":42189480}],"con":true,"img":false}]}
{"op":"mcm","clk":"5306542922","pt":1646100551090,"mc":[{"id":"1.195395426","rc":[{"atl":[[17,7.75],[11.5,0]],"id":38859241},{"atl":[[4.3,30.3],[2.7,0]],"id":43154454},{"atl":[[44,5.03]],"id":39318320},{"atb":[[2.9,0],[2.5,53.05]],"id":43154455}],"con":true,"img":false}]}
{"op":"mcm","clk":"5306543046","pt":1646100553605,"mc":[{"id":"1.195395426","rc":[{"atb":[[3.4,1.66]],"id":38859241},{"atb":[[5.2,1.66]],"id":43154455}],"con":true,"img":false}]}
{"op":"mcm","clk":"5306543813","pt":1646100568281,"mc":[{"id":"1.195395426","marketDefinition":{"bspMarket":true,"turnInPlayEnabled":false,"persistenceEnabled":false,"marketBaseRate":7.0,"eventId":"31270458","eventTypeId":"4339","numberOfWinners":2,"bettingType":"ODDS","marketType":"PLACE","marketTime":"2022-03-01T02:54:00.000Z","suspendTime":"2022-03-01T02:54:00.000Z","bspReconciled":false,"complete":true,"inPlay":false,"crossMatching":true,"runnersVoidable":false,"numberOfActiveRunners":7,"betDelay":0,"status":"OPEN","runners":[{"status":"ACTIVE","sortPriority":1,"id":43154454,"name":"1. Buckle Up Iveta"},{"status":"ACTIVE","sortPriority":2,"id":38859241,"name":"2. Theo Dragonet"},{"status":"ACTIVE","sortPriority":3,"id":39318320,"name":"3. Engage The Rage"},{"status":"ACTIVE","sortPriority":4,"id":42189480,"name":"4. Toxic Turtle"},{"status":"ACTIVE","sortPriority":5,"id":36104892,"name":"5. Bridwood Ali"},{"status":"ACTIVE","sortPriority":6,"id":38256919,"name":"6. Warramunga"},{"status":"ACTIVE","sortPriority":7,"id":43154455,"name":"8. Strait Sambuca"}],"regulators":["MR_INT"],"venue":"Devonport","countryCode":"AU","discountAllowed":true,"timezone":"Australia/Sydney","openDate":"2022-03-01T02:00:00.000Z","version":4380714786,"name":"To Be Placed","eventName":"Devonport (AUS) 1st Mar"},"rc":[],"con":true,"img":false}]}
{"op":"mcm","clk":"5306544485","pt":1646100583066,"mc":[{"id":"1.195395426","rc":[{"atl":[[13.5,0]],"id":38859241},{"atl":[[95,0]],"id":38256919}],"con":true,"img":false}]}
{"op":"mcm","clk":"5306544487","pt":1646100583168,"mc":[{"id":"1.195395426","rc":[{"atl":[[15.5,4.21]],"id":38859241},{"atl":[[110,2.7]],"id":38256919}],"con":true,"img":false}]}
{"op":"mcm","clk":"5306544742","pt":1646100588865,"mc":[{"id":"1.195395426","rc":[{"atb":[[3.45,3.4]],"id":38859241}],"con":true,"img":false}]}
{"op":"mcm","clk":"5306544749","pt":1646100588967,"mc":[{"id":"1.195395426","rc":[{"atb":[[2,8.34]],"id":36104892}],"con":true,"img":false}]}
{"op":"mcm","clk":"5306544756","pt":1646100589081,"mc":[{"id":"1.195395426","rc":[{"atb":[[1.44,18.97]],"id":42189480}],"con":true,"img":false}]}
{"op":"mcm","clk":"5306545063","pt":1646100595681,"mc":[{"id":"1.195395426","rc":[{"atb":[[3.4,0]],"id":38859241}],"con":true,"img":false}]}
{"op":"mcm","clk":"5306545068","pt":1646100595783,"mc":[{"id":"1.195395426","rc":[{"atb":[[2.02,1.66]],"id":36104892},{"atb":[[3.5,1.66]],"id":38859241}],"con":true,"img":false}]}
{"op":"mcm","clk":"5306545226","pt":1646100600082,"mc":[{"id":"1.195395426","rc":[{"atb":[[3.45,6.44]],"id":38859241},{"atb":[[1.44,35.91]],"id":42189480}],"con":true,"img":false}]}
{"op":"mcm","clk":"5306545234","pt":1646100600139,"mc":[{"id":"1.195395426","rc":[{"atb":[[2,15.8]],"id":36104892}],"con":true,"img":false}]}
{"op":"mcm","clk":"5306545434","pt":1646100603777,"mc":[{"id":"1.195395426","rc":[{"atb":[[6.6,10.78]],"id":39318320},{"atl":[[46,0]],"id":39318320}],"con":true,"img":false}]}
{"op":"mcm","clk":"5306545440","pt":1646100603878,"mc":[{"id":"1.195395426","rc":[{"atb":[[6.8,11.36]],"id":39318320},{"atl":[[42,2.7]],"id":39318320}],"con":true,"img":false}]}
{"op":"mcm","clk":"5306547440","pt":1646100644117,"mc":[{"id":"1.195395426","rc":[{"spn":3.31,"spf":"NaN","id":36104892},{"spn":6.15,"spf":"NaN","id":38859241},{"spn":11.1,"spf":"NaN","id":43154455},{"atb":[[9,0]],"id":38256919},{"atb":[[1.41,0]],"id":42189480},{"spn":1.99,"spf":"NaN","id":42189480}],"con":true,"img":false}]}
{"op":"mcm","clk":"5306547442","pt":1646100644218,"mc":[{"id":"1.195395426","rc":[{"atb":[[10,6.91]],"id":38256919},{"atb":[[1.45,105.57]],"id":42189480}],"con":true,"img":false}]}
{"op":"mcm","clk":"5306547522","pt":1646100646013,"mc":[{"id":"1.195395426","rc":[{"atb":[[1.44,18.97]],"id":42189480}],"con":true,"img":false}]}
{"op":"mcm","clk":"5306547747","pt":1646100651401,"mc":[{"id":"1.195395426","rc":[{"atb":[[1.48,15.52]],"id":42189480}],"con":true,"img":false}]}
{"op":"mcm","clk":"5306548165","pt":1646100660848,"mc":[{"id":"1.195395426","rc":[{"atb":[[1.44,0]],"id":42189480}],"con":true,"img":false}]}
{"op":"mcm","clk":"5306548291","pt":1646100663523,"mc":[{"id":"1.195395426","rc":[{"atb":[[1.45,0]],"id":42189480}],"con":true,"img":false}]}
{"op":"mcm","clk":"5306548298","pt":1646100663625,"mc":[{"id":"1.195395426","rc":[{"atb":[[1.41,105.57]],"id":42189480}],"con":true,"img":false}]}
{"op":"mcm","clk":"5306548322","pt":1646100664035,"mc":[{"id":"1.195395426","rc":[{"atb":[[1.48,0]],"id":42189480}],"con":true,"img":false}]}
{"op":"mcm","clk":"5306548661","pt":1646100673140,"mc":[{"id":"1.195395426","rc":[{"atb":[[1.44,16.94]],"id":42189480}],"con":true,"img":false}]}
{"op":"mcm","clk":"5306548908","pt":1646100679654,"mc":[{"id":"1.195395426","rc":[{"atb":[[1.44,35.91]],"id":42189480}],"con":true,"img":false}]}
{"op":"mcm","clk":"5306550516","pt":1646100715808,"mc":[{"id":"1.195395426","rc":[{"atl":[[4.5,3.34],[8.4,0]],"id":36104892},{"spn":3.26,"spf":"NaN","id":36104892},{"atb":[[2.9,52.63],[1.62,0]],"id":38859241},{"atl":[[17,1.5],[14,7.54]],"id":38859241},{"atl":[[4.3,0],[2.78,56.18]],"id":43154454},{"atb":[[3.5,0],[2.94,36.52]],"id":39318320},{"atb":[[2.82,53.05],[2.5,0]],"id":43154455},{"atb":[[6,0],[1.62,22.41]],"id":38256919},{"atl":[[100,2.43]],"id":38256919},{"atb":[[1.37,374.96]],"id":42189480}],"con":true,"img":false}]}
{"op":"mcm","clk":"5306550688","pt":1646100719608,"mc":[{"id":"1.195395426","rc":[{"atb":[[8,1.66]],"id":39318320}],"con":true,"img":false}]}
{"op":"mcm","clk":"5306550872","pt":1646100723620,"mc":[{"id":"1.195395426","rc":[{"atb":[[1.41,0]],"id":42189480}],"con":true,"img":false}]}
{"op":"mcm","clk":"5306550880","pt":1646100723723,"mc":[{"id":"1.195395426","rc":[{"atb":[[1.45,105.57]],"id":42189480}],"con":true,"img":false}]}
{"op":"mcm","clk":"5306550903","pt":1646100724085,"mc":[{"id":"1.195395426","rc":[{"atb":[[1.44,18.97]],"id":42189480}],"con":true,"img":false}]}
{"op":"mcm","clk":"5306551162","pt":1646100729995,"mc":[{"id":"1.195395426","rc":[{"atb":[[1.48,15.52]],"id":42189480}],"con":true,"img":false}]}
{"op":"mcm","clk":"5306551639","pt":1646100739711,"mc":[{"id":"1.195395426","rc":[{"atb":[[1.44,0]],"id":42189480}],"con":true,"img":false}]}
{"op":"mcm","clk":"5306551732","pt":1646100741712,"mc":[{"id":"1.195395426","rc":[{"atb":[[2.9,0],[2.58,56.89]],"id":38859241},{"atl":[[2.98,50.51],[2.78,0]],"id":43154454},{"atb":[[1.89,22.72],[2.94,0]],"id":39318320},{"atb":[[2.82,0],[2.58,37.08]],"id":43154455},{"atb":[[1.62,0],[1.23,22.41]],"id":38256919}],"con":true,"img":false}]}
{"op":"mcm","clk":"5306551753","pt":1646100742227,"mc":[{"id":"1.195395426","rc":[{"atl":[[10.5,4.22],[14,3.32]],"id":38859241},{"atb":[[2.8,22.72],[1.89,0]],"id":39318320},{"atb":[[2.8,37.08],[2.58,0]],"id":43154455}],"con":true,"img":false}]}
{"op":"mcm","clk":"5306551802","pt":1646100743104,"mc":[{"id":"1.195395426","rc":[{"atb":[[1.45,0]],"id":42189480}],"con":true,"img":false}]}
{"op":"mcm","clk":"5306551806","pt":1646100743206,"mc":[{"id":"1.195395426","rc":[{"atb":[[1.41,105.57]],"id":42189480}],"con":true,"img":false}]}
{"op":"mcm","clk":"5306551889","pt":1646100745002,"mc":[{"id":"1.195395426","rc":[{"atb":[[1.48,0]],"id":42189480}],"con":true,"img":false}]}
{"op":"mcm","clk":"5306551894","pt":1646100745103,"mc":[{"id":"1.195395426","rc":[{"atb":[[1.38,263.16]],"id":42189480}],"con":true,"img":false}]}
{"op":"mcm","clk":"5306551899","pt":1646100745207,"mc":[{"id":"1.195395426","rc":[{"atb":[[1.37,173.67]],"id":42189480}],"con":true,"img":false}]}
{"op":"mcm","clk":"5306552179","pt":1646100750944,"mc":[{"id":"1.195395426","rc":[{"atb":[[1.44,16.94]],"id":42189480}],"con":true,"img":false}]}
{"op":"mcm","clk":"5306552283","pt":1646100753251,"mc":[{"id":"1.195395426","rc":[{"atb":[[2.9,52.63],[2.58,0]],"id":38859241},{"atl":[[10.5,0],[14,6.65]],"id":38859241},{"atl":[[2.78,56.18]],"id":43154454},{"atb":[[2.8,0],[1.89,22.72]],"id":39318320},{"atb":[[2.8,0],[2.58,37.08]],"id":43154455},{"atb":[[1.62,22.41]],"id":38256919}],"con":true,"img":false}]}
{"op":"mcm","clk":"5306552287","pt":1646100753353,"mc":[{"id":"1.195395426","rc":[{"atl":[[2.98,0]],"id":43154454},{"atb":[[1.23,0]],"id":38256919}],"con":true,"img":false}]}
{"op":"mcm","clk":"5306552481","pt":1646100757717,"mc":[{"id":"1.195395426","rc":[{"atb":[[1.44,35.91]],"id":42189480}],"con":true,"img":false}]}
{"op":"mcm","clk":"5306552658","pt":1646100762146,"mc":[{"id":"1.195395426","rc":[{"atl":[[110,0]],"id":38256919}],"con":true,"img":false}]}
{"op":"mcm","clk":"5306552663","pt":1646100762248,"mc":[{"id":"1.195395426","rc":[{"atl":[[140,2.08],[95,2.7],[100,0.43]],"id":38256919}],"con":true,"img":false}]}
{"op":"mcm","clk":"5306552902","pt":1646100768344,"mc":[{"id":"1.195395426","rc":[{"atb":[[1.89,0],[2.94,22.72]],"id":39318320},{"atb":[[2.82,37.08],[2.58,0]],"id":43154455}],"con":true,"img":false}]}
{"op":"mcm","clk":"5306553501","pt":1646100782041,"mc":[{"id":"1.195395426","rc":[{"spn":16.0,"spf":"NaN","id":39318320},{"atl":[[95,0]],"id":38256919}],"con":true,"img":false}]}
{"op":"mcm","clk":"5306553504","pt":1646100782137,"mc":[{"id":"1.195395426","rc":[{"atl":[[110,2.7]],"id":38256919}],"con":true,"img":false}]}
{"op":"mcm","clk":"5306553806","pt":1646100788145,"mc":[{"id":"1.195395426","rc":[{"atl":[[100,2.43]],"id":38256919}],"con":true,"img":false}]}
{"op":"mcm","clk":"5306553811","pt":1646100788294,"mc":[{"id":"1.195395426","rc":[{"atl":[[140,0.08]],"id":38256919}],"con":true,"img":false}]}
{"op":"mcm","clk":"5306554427","pt":1646100800802,"mc":[{"id":"1.195395426","rc":[{"atl":[[15.5,0]],"id":38859241},{"atb":[[1.41,0],[1.37,0],[1.39,138.04]],"id":42189480}],"con":true,"img":false}]}
{"op":"mcm","clk":"5306554431","pt":1646100800906,"mc":[{"id":"1.195395426","rc":[{"atl":[[13.5,4.21]],"id":38859241},{"atb":[[1.45,105.57]],"id":42189480}],"con":true,"img":false}]}
{"op":"mcm","clk":"5306554481","pt":1646100802191,"mc":[{"id":"1.195395426","rc":[{"atb":[[1.44,18.97]],"id":42189480}],"con":true,"img":false}]}
{"op":"mcm","clk":"5306554821","pt":1646100807987,"mc":[{"id":"1.195395426","rc":[{"atb":[[1.48,15.52]],"id":42189480}],"con":true,"img":false}]}
{"op":"mcm","clk":"5306555330","pt":1646100817829,"mc":[{"id":"1.195395426","rc":[{"atb":[[1.44,0]],"id":42189480}],"con":true,"img":false}]}
{"op":"mcm","clk":"5306555412","pt":1646100819726,"mc":[{"id":"1.195395426","rc":[{"atb":[[1.45,0]],"id":42189480}],"con":true,"img":false}]}
{"op":"mcm","clk":"5306555417","pt":1646100819827,"mc":[{"id":"1.195395426","rc":[{"atb":[[1.41,105.57]],"id":42189480}],"con":true,"img":false}]}
{"op":"mcm","clk":"5306555425","pt":1646100820030,"mc":[{"id":"1.195395426","rc":[{"atb":[[1.48,0]],"id":42189480}],"con":true,"img":false}]}
{"op":"mcm","clk":"5306555433","pt":1646100820236,"mc":[{"id":"1.195395426","rc":[{"atb":[[1.37,270.27],[1.38,0]],"id":42189480}],"con":true,"img":false}]}
{"op":"mcm","clk":"5306555852","pt":1646100829014,"mc":[{"id":"1.195395426","rc":[{"atb":[[1.44,16.94]],"id":42189480}],"con":true,"img":false}]}
{"op":"mcm","clk":"5306556205","pt":1646100836044,"mc":[{"id":"1.195395426","rc":[{"atb":[[1.44,35.91]],"id":42189480}],"con":true,"img":false}]}
{"op":"mcm","clk":"5306556316","pt":1646100838607,"mc":[{"id":"1.195395426","rc":[{"atl":[[110,0]],"id":38256919},{"atb":[[1.39,0]],"id":42189480}],"con":true,"img":false}]}
{"op":"mcm","clk":"5306556321","pt":1646100838712,"mc":[{"id":"1.195395426","rc":[{"atl":[[140,2.08],[95,2.7],[100,0.43]],"id":38256919},{"atb":[[1.38,138.04]],"id":42189480}],"con":true,"img":false}]}
{"op":"mcm","clk":"5306557213","pt":1646100857676,"mc":[{"id":"1.195395426","rc":[{"atl":[[95,0]],"id":38256919}],"con":true,"img":false}]}
{"op":"mcm","clk":"5306557217","pt":1646100857732,"mc":[{"id":"1.195395426","rc":[{"atl":[[110,2.7]],"id":38256919}],"con":true,"img":false}]}
{"op":"mcm","clk":"5306557519","pt":1646100863881,"mc":[{"id":"1.195395426","rc":[{"atl":[[140,0.08],[100,2.43]],"id":38256919}],"con":true,"img":false}]}
{"op":"mcm","clk":"5306557986","pt":1646100873186,"mc":[{"id":"1.195395426","rc":[{"atb":[[2.9,0]],"id":38859241},{"atl":[[2.9,52.63]],"id":43154454},{"atb":[[2.64,22.72],[2.94,0]],"id":39318320},{"atb":[[2.82,0],[2.62,37.08]],"id":43154455},{"atb":[[1.62,0],[1.31,22.41]],"id":38256919},{"atb":[[1.37,0],[1.34,294.12]],"id":42189480}],"con":true,"img":false}]}
{"op":"mcm","clk":"5306557991","pt":1646100873289,"mc":[{"id":"1.195395426","rc":[{"atb":[[2.74,56.89]],"id":38859241},{"atl":[[2.78,0]],"id":43154454}],"con":true,"img":false}]}
{"op":"mcm","clk":"5306558136","pt":1646100875761,"mc":[{"id":"1.195395426","rc":[{"atb":[[1.41,0]],"id":42189480}],"con":true,"img":false}]}
{"op":"mcm","clk":"5306558142","pt":1646100875863,"mc":[{"id":"1.195395426","rc":[{"atb":[[1.45,105.57]],"id":42189480}],"con":true,"img":false}]}
{"op":"mcm","clk":"5306558199","pt":1646100877093,"mc":[{"id":"1.195395426","rc":[{"atb":[[1.44,18.97]],"id":42189480}],"con":true,"img":false}]}
{"op":"mcm","clk":"5306558495","pt":1646100883058,"mc":[{"id":"1.195395426","rc":[{"atb":[[1.48,15.52]],"id":42189480}],"con":true,"img":false}]}
{"op":"mcm","clk":"5306558880","pt":1646100890196,"mc":[{"id":"1.195395426","rc":[{"atb":[[1.44,0]],"id":42189480}],"con":true,"img":false}]}
{"op":"mcm","clk":"5306559139","pt":1646100894775,"mc":[{"id":"1.195395426","rc":[{"atb":[[1.45,0]],"id":42189480}],"con":true,"img":false}]}
{"op":"mcm","clk":"5306559144","pt":1646100894878,"mc":[{"id":"1.195395426","rc":[{"atb":[[1.41,105.57]],"id":42189480}],"con":true,"img":false}]}
{"op":"mcm","clk":"5306559156","pt":1646100895185,"mc":[{"id":"1.195395426","rc":[{"atb":[[1.48,0]],"id":42189480}],"con":true,"img":false}]}
{"op":"mcm","clk":"5306559471","pt":1646100901308,"mc":[{"id":"1.195395426","rc":[{"atb":[[1.44,16.94]],"id":42189480}],"con":true,"img":false}]}
{"op":"mcm","clk":"5306559811","pt":1646100907993,"mc":[{"id":"1.195395426","rc":[{"atb":[[1.44,35.91]],"id":42189480}],"con":true,"img":false}]}
{"op":"mcm","clk":"5306560020","pt":1646100912301,"mc":[{"id":"1.195395426","rc":[{"atl":[[110,0]],"id":38256919}],"con":true,"img":false}]}
{"op":"mcm","clk":"5306560023","pt":1646100912404,"mc":[{"id":"1.195395426","rc":[{"atl":[[140,2.08],[95,2.7],[100,0.43]],"id":38256919}],"con":true,"img":false}]}
{"op":"mcm","clk":"5306560883","pt":1646100931237,"mc":[{"id":"1.195395426","rc":[{"atl":[[95,0]],"id":38256919}],"con":true,"img":false}]}
{"op":"mcm","clk":"5306560889","pt":1646100931338,"mc":[{"id":"1.195395426","rc":[{"atl":[[110,2.7]],"id":38256919}],"con":true,"img":false}]}
{"op":"mcm","clk":"5306561151","pt":1646100936828,"mc":[{"id":"1.195395426","rc":[{"atl":[[140,0.08],[100,2.43]],"id":38256919}],"con":true,"img":false}]}
{"op":"mcm","clk":"5306561733","pt":1646100949298,"mc":[{"id":"1.195395426","rc":[{"atb":[[1.41,0]],"id":42189480}],"con":true,"img":false}]}
{"op":"mcm","clk":"5306561737","pt":1646100949349,"mc":[{"id":"1.195395426","rc":[{"atb":[[1.45,105.57]],"id":42189480}],"con":true,"img":false}]}
{"op":"mcm","clk":"5306561751","pt":1646100949658,"mc":[{"id":"1.195395426","rc":[{"atb":[[1.44,18.97]],"id":42189480}],"con":true,"img":false}]}
{"op":"mcm","clk":"5306562168","pt":1646100958486,"mc":[{"id":"1.195395426","rc":[{"atb":[[1.48,15.52]],"id":42189480}],"con":true,"img":false}]}
{"op":"mcm","clk":"5306562339","pt":1646100961972,"mc":[{"id":"1.195395426","rc":[{"atb":[[1.44,0]],"id":42189480}],"con":true,"img":false}]}
{"op":"mcm","clk":"5306562636","pt":1646100967832,"mc":[{"id":"1.195395426","rc":[{"atb":[[1.45,0]],"id":42189480}],"con":true,"img":false}]}
{"op":"mcm","clk":"5306562644","pt":1646100967935,"mc":[{"id":"1.195395426","rc":[{"atb":[[1.41,105.57]],"id":42189480}],"con":true,"img":false}]}
{"op":"mcm","clk":"5306562652","pt":1646100967976,"mc":[{"id":"1.195395426","rc":[{"atb":[[1.48,32.91]],"id":42189480}],"con":true,"img":false}]}
{"op":"mcm","clk":"5306562777","pt":1646100970480,"mc":[{"id":"1.195395426","rc":[{"atb":[[1.48,17.39]],"id":42189480}],"con":true,"img":false}]}
{"op":"mcm","clk":"5306563067","pt":1646100976731,"mc":[{"id":"1.195395426","rc":[{"atb":[[1.44,16.94]],"id":42189480}],"con":true,"img":false}]}
{"op":"mcm","clk":"5306563491","pt":1646100985707,"mc":[{"id":"1.195395426","rc":[{"atl":[[110,0]],"id":38256919}],"con":true,"img":false}]}
{"op":"mcm","clk":"5306563499","pt":1646100985812,"mc":[{"id":"1.195395426","rc":[{"atl":[[140,2.08],[95,2.7]],"id":38256919}],"con":true,"img":false}]}
{"op":"mcm","clk":"5306563503","pt":1646100985912,"mc":[{"id":"1.195395426","rc":[{"atl":[[100,0.43]],"id":38256919}],"con":true,"img":false}]}
{"op":"mcm","clk":"5306563508","pt":1646100986018,"mc":[{"id":"1.195395426","rc":[{"atb":[[1.48,0]],"id":42189480}],"con":true,"img":false}]}
{"op":"mcm","clk":"5306563834","pt":1646100992044,"mc":[{"id":"1.195395426","rc":[{"atb":[[1.44,35.91]],"id":42189480}],"con":true,"img":false}]}
{"op":"mcm","clk":"5306564364","pt":1646101003335,"mc":[{"id":"1.195395426","rc":[{"atl":[[95,0]],"id":38256919}],"con":true,"img":false}]}
{"op":"mcm","clk":"5306564365","pt":1646101003436,"mc":[{"id":"1.195395426","rc":[{"atl":[[110,2.7]],"id":38256919}],"con":true,"img":false}]}
{"op":"mcm","clk":"5306564614","pt":1646101009437,"mc":[{"id":"1.195395426","rc":[{"atl":[[100,2.43]],"id":38256919}],"con":true,"img":false}]}
{"op":"mcm","clk":"5306564617","pt":1646101009538,"mc":[{"id":"1.195395426","rc":[{"atl":[[140,0.08]],"id":38256919}],"con":true,"img":false}]}
{"op":"mcm","clk":"5306565833","pt":1646101039017,"mc":[{"id":"1.195395426","rc":[{"atb":[[1.41,0]],"id":42189480}],"con":true,"img":false}]}
{"op":"mcm","clk":"5306565838","pt":1646101039121,"mc":[{"id":"1.195395426","rc":[{"atb":[[1.45,105.57]],"id":42189480}],"con":true,"img":false}]}
{"op":"mcm","clk":"5306565865","pt":1646101039686,"mc":[{"id":"1.195395426","rc":[{"atb":[[1.44,18.97]],"id":42189480}],"con":true,"img":false}]}
{"op":"mcm","clk":"5306566124","pt":1646101045783,"mc":[{"id":"1.195395426","rc":[{"atb":[[1.48,15.52]],"id":42189480}],"con":true,"img":false}]}
{"op":"mcm","clk":"5306566409","pt":1646101052816,"mc":[{"id":"1.195395426","rc":[{"atb":[[1.44,0]],"id":42189480},{"spn":2.01,"spf":"NaN","id":42189480}],"con":true,"img":false}]}
{"op":"mcm","clk":"5306566413","pt":1646101052919,"mc":[{"id":"1.195395426","rc":[{"atb":[[2.74,0],[2.9,52.63]],"id":38859241},{"atl":[[2.9,0],[2.78,56.18]],"id":43154454},{"atb":[[2.64,0],[2.94,22.72]],"id":39318320},{"atb":[[2.82,37.08],[2.62,0]],"id":43154455},{"atb":[[1.62,22.41],[1.31,0]],"id":38256919},{"atb":[[1.37,270.27],[1.34,0]],"id":42189480}],"con":true,"img":false}]}
{"op":"mcm","clk":"5306566555","pt":1646101056205,"mc":[{"id":"1.195395426","rc":[{"atl":[[110,0]],"id":38256919},{"atb":[[1.45,0]],"id":42189480}],"con":true,"img":false}]}
{"op":"mcm","clk":"5306566558","pt":1646101056305,"mc":[{"id":"1.195395426","rc":[{"atl":[[140,2.08],[95,2.7]],"id":38256919},{"atb":[[1.41,105.57]],"id":42189480}],"con":true,"img":false}]}
{"op":"mcm","clk":"5306566561","pt":1646101056409,"mc":[{"id":"1.195395426","rc":[{"atl":[[100,0.43]],"id":38256919}],"con":true,"img":false}]}
{"op":"mcm","clk":"5306566622","pt":1646101057794,"mc":[{"id":"1.195395426","rc":[{"atb":[[1.48,0]],"id":42189480}],"con":true,"img":false}]}
{"op":"mcm","clk":"5306566870","pt":1646101063739,"mc":[{"id":"1.195395426","rc":[{"atb":[[1.44,16.94]],"id":42189480}],"con":true,"img":false}]}
{"op":"mcm","clk":"5306567209","pt":1646101070714,"mc":[{"id":"1.195395426","rc":[{"atb":[[1.44,35.91]],"id":42189480}],"con":true,"img":false}]}
{"op":"mcm","clk":"5306567325","pt":1646101073335,"mc":[{"id":"1.195395426","rc":[{"atl":[[95,0]],"id":38256919}],"con":true,"img":false}]}
{"op":"mcm","clk":"5306567329","pt":1646101073438,"mc":[{"id":"1.195395426","rc":[{"atl":[[110,2.7]],"id":38256919}],"con":true,"img":false}]}
{"op":"mcm","clk":"5306568163","pt":1646101091257,"mc":[{"id":"1.195395426","rc":[{"atl":[[140,0.08],[100,2.43]],"id":38256919}],"con":true,"img":false}]}
{"op":"mcm","clk":"5306568908","pt":1646101108298,"mc":[{"id":"1.195395426","rc":[{"atb":[[1.41,0]],"id":42189480}],"con":true,"img":false}]}
{"op":"mcm","clk":"5306568911","pt":1646101108400,"mc":[{"id":"1.195395426","rc":[{"atb":[[1.45,105.57]],"id":42189480}],"con":true,"img":false}]}
{"op":"mcm","clk":"5306568937","pt":1646101108964,"mc":[{"id":"1.195395426","rc":[{"atb":[[1.44,18.97]],"id":42189480}],"con":true,"img":false}]}
{"op":"mcm","clk":"5306569228","pt":1646101114818,"mc":[{"id":"1.195395426","rc":[{"atb":[[1.48,15.52]],"id":42189480}],"con":true,"img":false}]}
{"op":"mcm","clk":"5306569683","pt":1646101124713,"mc":[{"id":"1.195395426","rc":[{"atb":[[1.44,0]],"id":42189480}],"con":true,"img":false}]}
{"op":"mcm","clk":"5306569714","pt":1646101125433,"mc":[{"id":"1.195395426","rc":[{"atb":[[1.45,0]],"id":42189480}],"con":true,"img":false}]}
{"op":"mcm","clk":"5306569720","pt":1646101125484,"mc":[{"id":"1.195395426","rc":[{"atb":[[1.41,105.57]],"id":42189480}],"con":true,"img":false}]}
{"op":"mcm","clk":"5306569787","pt":1646101126918,"mc":[{"id":"1.195395426","rc":[{"atb":[[1.48,0]],"id":42189480}],"con":true,"img":false}]}
{"op":"mcm","clk":"5306570088","pt":1646101132928,"mc":[{"id":"1.195395426","rc":[{"atb":[[1.44,16.94]],"id":42189480}],"con":true,"img":false}]}
{"op":"mcm","clk":"5306570580","pt":1646101142744,"mc":[{"id":"1.195395426","rc":[{"atb":[[1.44,35.91]],"id":42189480}],"con":true,"img":false}]}
{"op":"mcm","clk":"5306571299","pt":1646101159156,"mc":[{"id":"1.195395426","rc":[{"atl":[[110,0]],"id":38256919}],"con":true,"img":false}]}
{"op":"mcm","clk":"5306571304","pt":1646101159259,"mc":[{"id":"1.195395426","rc":[{"atl":[[140,2.08],[95,2.7],[100,0.43]],"id":38256919}],"con":true,"img":false}]}
{"op":"mcm","clk":"5306571309","pt":1646101159361,"mc":[{"id":"1.195395426","rc":[{"atl":[[95,4.7]],"id":38256919}],"con":true,"img":false}]}
{"op":"mcm","clk":"5306571313","pt":1646101159463,"mc":[{"id":"1.195395426","rc":[{"atl":[[140,0.08],[100,2.43]],"id":38256919}],"con":true,"img":false}]}
{"op":"mcm","clk":"5306571315","pt":1646101159565,"mc":[{"id":"1.195395426","rc":[{"atl":[[95,2.7]],"id":38256919}],"con":true,"img":false}]}
{"op":"mcm","clk":"5306571912","pt":1646101174397,"mc":[{"id":"1.195395426","marketDefinition":{"bspMarket":true,"turnInPlayEnabled":false,"persistenceEnabled":false,"marketBaseRate":7.0,"eventId":"31270458","eventTypeId":"4339","numberOfWinners":2,"bettingType":"ODDS","marketType":"PLACE","marketTime":"2022-03-01T03:14:00.000Z","suspendTime":"2022-03-01T03:14:00.000Z","bspReconciled":false,"complete":true,"inPlay":false,"crossMatching":true,"runnersVoidable":false,"numberOfActiveRunners":7,"betDelay":0,"status":"OPEN","runners":[{"status":"ACTIVE","sortPriority":1,"id":43154454,"name":"1. Buckle Up Iveta"},{"status":"ACTIVE","sortPriority":2,"id":38859241,"name":"2. Theo Dragonet"},{"status":"ACTIVE","sortPriority":3,"id":39318320,"name":"3. Engage The Rage"},{"status":"ACTIVE","sortPriority":4,"id":42189480,"name":"4. Toxic Turtle"},{"status":"ACTIVE","sortPriority":5,"id":36104892,"name":"5. Bridwood Ali"},{"status":"ACTIVE","sortPriority":6,"id":38256919,"name":"6. Warramunga"},{"status":"ACTIVE","sortPriority":7,"id":43154455,"name":"8. Strait Sambuca"}],"regulators":["MR_INT"],"venue":"Devonport","countryCode":"AU","discountAllowed":true,"timezone":"Australia/Sydney","openDate":"2022-03-01T02:00:00.000Z","version":4381058495,"name":"To Be Placed","eventName":"Devonport (AUS) 1st Mar"},"rc":[],"con":true,"img":false}]}
{"op":"mcm","clk":"5306572720","pt":1646101192378,"mc":[{"id":"1.195395426","rc":[{"atb":[[1.41,0]],"id":42189480},{"spn":1.99,"spf":"NaN","id":42189480}],"con":true,"img":false}]}
{"op":"mcm","clk":"5306572726","pt":1646101192482,"mc":[{"id":"1.195395426","rc":[{"atb":[[1.45,105.57]],"id":42189480}],"con":true,"img":false}]}
{"op":"mcm","clk":"5306572758","pt":1646101193096,"mc":[{"id":"1.195395426","rc":[{"atb":[[1.44,18.97]],"id":42189480}],"con":true,"img":false}]}
{"op":"mcm","clk":"5306573059","pt":1646101199093,"mc":[{"id":"1.195395426","rc":[{"atb":[[1.48,15.52]],"id":42189480}],"con":true,"img":false}]}
{"op":"mcm","clk":"5306573531","pt":1646101208994,"mc":[{"id":"1.195395426","rc":[{"atb":[[1.44,0]],"id":42189480}],"con":true,"img":false}]}
{"op":"mcm","clk":"5306573564","pt":1646101209612,"mc":[{"id":"1.195395426","rc":[{"atb":[[1.45,0]],"id":42189480}],"con":true,"img":false}]}
{"op":"mcm","clk":"5306573569","pt":1646101209713,"mc":[{"id":"1.195395426","rc":[{"atb":[[1.41,105.57]],"id":42189480}],"con":true,"img":false}]}
{"op":"mcm","clk":"5306573659","pt":1646101211108,"mc":[{"id":"1.195395426","rc":[{"atb":[[1.48,0]],"id":42189480}],"con":true,"img":false}]}
{"op":"mcm","clk":"5306573968","pt":1646101217095,"mc":[{"id":"1.195395426","rc":[{"atb":[[1.44,16.94]],"id":42189480}],"con":true,"img":false}]}
{"op":"mcm","clk":"5306574462","pt":1646101226736,"mc":[{"id":"1.195395426","rc":[{"atb":[[1.44,35.91]],"id":42189480}],"con":true,"img":false}]}
{"op":"mcm","clk":"5306576729","pt":1646101275153,"mc":[{"id":"1.195395426","rc":[{"atb":[[1.41,0]],"id":42189480}],"con":true,"img":false}]}
{"op":"mcm","clk":"5306576732","pt":1646101275256,"mc":[{"id":"1.195395426","rc":[{"atb":[[1.45,105.57]],"id":42189480}],"con":true,"img":false}]}
{"op":"mcm","clk":"5306576806","pt":1646101277259,"mc":[{"id":"1.195395426","rc":[{"atb":[[1.44,18.97]],"id":42189480}],"con":true,"img":false}]}
{"op":"mcm","clk":"5306577057","pt":1646101283216,"mc":[{"id":"1.195395426","rc":[{"atb":[[1.48,15.52]],"id":42189480}],"con":true,"img":false}]}
{"op":"mcm","clk":"5306577342","pt":1646101290606,"mc":[{"id":"1.195395426","rc":[{"atb":[[1.44,0]],"id":42189480}],"con":true,"img":false}]}
{"op":"mcm","clk":"5306577366","pt":1646101291328,"mc":[{"id":"1.195395426","rc":[{"atb":[[1.45,0]],"id":42189480}],"con":true,"img":false}]}
{"op":"mcm","clk":"5306577370","pt":1646101291378,"mc":[{"id":"1.195395426","rc":[{"atb":[[1.41,105.57]],"id":42189480}],"con":true,"img":false}]}
{"op":"mcm","clk":"5306577410","pt":1646101292303,"mc":[{"id":"1.195395426","rc":[{"atb":[[1.48,0]],"id":42189480}],"con":true,"img":false}]}
{"op":"mcm","clk":"5306577751","pt":1646101299294,"mc":[{"id":"1.195395426","rc":[{"atb":[[1.44,16.94]],"id":42189480}],"con":true,"img":false}]}
{"op":"mcm","clk":"5306578144","pt":1646101308522,"mc":[{"id":"1.195395426","rc":[{"atb":[[1.44,35.91]],"id":42189480}],"con":true,"img":false}]}
{"op":"mcm","clk":"5306580171","pt":1646101355197,"mc":[{"id":"1.195395426","rc":[{"atb":[[1.41,0]],"id":42189480}],"con":true,"img":false}]}
{"op":"mcm","clk":"5306580179","pt":1646101355298,"mc":[{"id":"1.195395426","rc":[{"atb":[[1.45,105.57]],"id":42189480}],"con":true,"img":false}]}
{"op":"mcm","clk":"5306580299","pt":1646101357665,"mc":[{"id":"1.195395426","rc":[{"atb":[[1.44,18.97]],"id":42189480}],"con":true,"img":false}]}
{"op":"mcm","clk":"5306580574","pt":1646101363577,"mc":[{"id":"1.195395426","rc":[{"atb":[[1.48,15.52]],"id":42189480}],"con":true,"img":false}]}
{"op":"mcm","clk":"5306580794","pt":1646101368702,"mc":[{"id":"1.195395426","rc":[{"atb":[[1.44,0]],"id":42189480}],"con":true,"img":false}]}
{"op":"mcm","clk":"5306580876","pt":1646101370706,"mc":[{"id":"1.195395426","rc":[{"atb":[[1.45,0]],"id":42189480}],"con":true,"img":false}]}
{"op":"mcm","clk":"5306580883","pt":1646101370808,"mc":[{"id":"1.195395426","rc":[{"atb":[[1.41,105.57]],"id":42189480}],"con":true,"img":false}]}
{"op":"mcm","clk":"5306580951","pt":1646101372703,"mc":[{"id":"1.195395426","rc":[{"atb":[[1.48,0]],"id":42189480}],"con":true,"img":false}]}
{"op":"mcm","clk":"5306581193","pt":1646101378610,"mc":[{"id":"1.195395426","rc":[{"atb":[[1.44,16.94]],"id":42189480}],"con":true,"img":false}]}
{"op":"mcm","clk":"5306581537","pt":1646101386822,"mc":[{"id":"1.195395426","rc":[{"atb":[[1.44,35.91]],"id":42189480}],"con":true,"img":false}]}
{"op":"mcm","clk":"5306582842","pt":1646101417767,"mc":[{"id":"1.195395426","rc":[{"atb":[[1.41,0]],"id":42189480}],"con":true,"img":false}]}
{"op":"mcm","clk":"5306582847","pt":1646101417869,"mc":[{"id":"1.195395426","rc":[{"atb":[[1.45,105.57]],"id":42189480}],"con":true,"img":false}]}
{"op":"mcm","clk":"5306582977","pt":1646101420748,"mc":[{"id":"1.195395426","rc":[{"atb":[[1.44,18.97]],"id":42189480}],"con":true,"img":false}]}
{"op":"mcm","clk":"5306583212","pt":1646101426750,"mc":[{"id":"1.195395426","rc":[{"atb":[[1.48,15.52]],"id":42189480}],"con":true,"img":false}]}
{"op":"mcm","clk":"5306583473","pt":1646101432907,"mc":[{"id":"1.195395426","rc":[{"atb":[[1.45,0]],"id":42189480}],"con":true,"img":false}]}
{"op":"mcm","clk":"5306583477","pt":1646101432959,"mc":[{"id":"1.195395426","rc":[{"atb":[[1.41,105.57]],"id":42189480}],"con":true,"img":false}]}
{"op":"mcm","clk":"5306583596","pt":1646101435788,"mc":[{"id":"1.195395426","rc":[{"atb":[[1.48,0]],"id":42189480}],"con":true,"img":false}]}
{"op":"mcm","clk":"5306583853","pt":1646101441801,"mc":[{"id":"1.195395426","rc":[{"atb":[[1.44,35.91]],"id":42189480}],"con":true,"img":false}]}
{"op":"mcm","clk":"5306583932","pt":1646101443197,"mc":[{"id":"1.195395426","rc":[{"atb":[[2.9,0],[2.64,56.89]],"id":38859241},{"atl":[[11.5,4.22],[14,3.32]],"id":38859241},{"atb":[[2.66,22.72],[2.94,0]],"id":39318320},{"atb":[[2.82,0],[2.7,37.08]],"id":43154455},{"atb":[[1.62,0],[1.29,22.41]],"id":38256919},{"atb":[[1.37,0],[1.38,339.33]],"id":42189480}],"con":true,"img":false}]}
{"op":"mcm","clk":"5306583938","pt":1646101443299,"mc":[{"id":"1.195395426","rc":[{"atl":[[10.5,4.22]],"id":38859241},{"atb":[[2.8,37.08]],"id":43154455}],"con":true,"img":false}]}
{"op":"mcm","clk":"5306583944","pt":1646101443401,"mc":[{"id":"1.195395426","rc":[{"atl":[[11.5,0]],"id":38859241},{"atb":[[2.7,0]],"id":43154455}],"con":true,"img":false}]}
{"op":"mcm","clk":"5306584099","pt":1646101446691,"mc":[{"id":"1.195395426","rc":[{"atl":[[13.5,0]],"id":38859241}],"con":true,"img":false}]}
{"op":"mcm","clk":"5306584106","pt":1646101446813,"mc":[{"id":"1.195395426","rc":[{"atl":[[15.5,4.21]],"id":38859241}],"con":true,"img":false}]}
{"op":"mcm","clk":"5306584974","pt":1646101466823,"mc":[{"id":"1.195395426","rc":[{"atb":[[1.41,0]],"id":42189480}],"con":true,"img":false}]}
{"op":"mcm","clk":"5306584981","pt":1646101466925,"mc":[{"id":"1.195395426","rc":[{"atb":[[1.45,105.57]],"id":42189480}],"con":true,"img":false}]}
{"op":"mcm","clk":"5306585066","pt":1646101468831,"mc":[{"id":"1.195395426","rc":[{"atb":[[1.44,18.97]],"id":42189480}],"con":true,"img":false}]}
{"op":"mcm","clk":"5306585173","pt":1646101470932,"mc":[{"id":"1.195395426","rc":[{"atb":[[1.44,0]],"id":42189480}],"con":true,"img":false}]}
{"op":"mcm","clk":"5306585393","pt":1646101475250,"mc":[{"id":"1.195395426","rc":[{"atb":[[1.48,15.52]],"id":42189480}],"con":true,"img":false}]}
{"op":"mcm","clk":"5306585466","pt":1646101476745,"mc":[{"id":"1.195395426","rc":[{"atl":[[14,0]],"id":38859241}],"con":true,"img":false}]}
{"op":"mcm","clk":"5306585471","pt":1646101476849,"mc":[{"id":"1.195395426","rc":[{"atb":[[1.45,0]],"id":42189480}],"con":true,"img":false}]}
{"op":"mcm","clk":"5306585476","pt":1646101476947,"mc":[{"id":"1.195395426","rc":[{"atb":[[1.41,105.57]],"id":42189480}],"con":true,"img":false}]}
{"op":"mcm","clk":"5306585527","pt":1646101477825,"mc":[{"id":"1.195395426","rc":[{"atb":[[1.48,0]],"id":42189480},{"spn":1.97,"spf":"NaN","id":42189480}],"con":true,"img":false}]}
{"op":"mcm","clk":"5306585782","pt":1646101483931,"mc":[{"id":"1.195395426","rc":[{"atb":[[1.44,16.94]],"id":42189480}],"con":true,"img":false}]}
{"op":"mcm","clk":"5306586137","pt":1646101491662,"mc":[{"id":"1.195395426","rc":[{"atb":[[1.44,35.91]],"id":42189480}],"con":true,"img":false}]}
{"op":"mcm","clk":"5306586391","pt":1646101496688,"mc":[{"id":"1.195395426","rc":[{"atl":[[10,4.81]],"id":38859241}],"con":true,"img":false}]}
{"op":"mcm","clk":"5306587757","pt":1646101524789,"mc":[{"id":"1.195395426","rc":[{"atb":[[1.41,0]],"id":42189480}],"con":true,"img":false}]}
{"op":"mcm","clk":"5306587761","pt":1646101524891,"mc":[{"id":"1.195395426","rc":[{"atb":[[1.45,105.57]],"id":42189480}],"con":true,"img":false}]}
{"op":"mcm","clk":"5306587816","pt":1646101526021,"mc":[{"id":"1.195395426","rc":[{"atb":[[1.44,18.97]],"id":42189480}],"con":true,"img":false}]}
{"op":"mcm","clk":"5306587854","pt":1646101526795,"mc":[{"id":"1.195395426","rc":[{"atb":[[1.45,0]],"id":42189480}],"con":true,"img":false}]}
{"op":"mcm","clk":"5306587857","pt":1646101526898,"mc":[{"id":"1.195395426","rc":[{"atb":[[1.41,105.57]],"id":42189480}],"con":true,"img":false}]}
{"op":"mcm","clk":"5306588158","pt":1646101534897,"mc":[{"id":"1.195395426","rc":[{"atb":[[1.44,35.91]],"id":42189480}],"con":true,"img":false}]}
{"op":"mcm","clk":"5306589267","pt":1646101563136,"mc":[{"id":"1.195395426","rc":[{"atl":[[2.92,52.08]],"id":43154454},{"atb":[[1.29,0]],"id":38256919},{"atb":[[1.35,285.71]],"id":42189480},{"spn":1.99,"spf":"NaN","id":42189480}],"con":true,"img":false}]}
{"op":"mcm","clk":"5306589274","pt":1646101563238,"mc":[{"id":"1.195395426","rc":[{"atb":[[2.52,56.89],[2.64,0]],"id":38859241},{"atl":[[2.78,0]],"id":43154454},{"atb":[[2.3,22.72],[2.66,0]],"id":39318320},{"atb":[[2.8,0],[2.6,37.08]],"id":43154455},{"atb":[[1.38,138.04]],"id":42189480}],"con":true,"img":false}]}
{"op":"mcm","clk":"5306589684","pt":1646101572173,"mc":[{"id":"1.195395426","rc":[{"atb":[[1.41,0]],"id":42189480}],"con":true,"img":false}]}
{"op":"mcm","clk":"5306589692","pt":1646101572277,"mc":[{"id":"1.195395426","rc":[{"atb":[[1.45,105.57]],"id":42189480}],"con":true,"img":false}]}
{"op":"mcm","clk":"5306589826","pt":1646101575049,"mc":[{"id":"1.195395426","rc":[{"atb":[[1.44,18.97]],"id":42189480}],"con":true,"img":false}]}
{"op":"mcm","clk":"5306590083","pt":1646101580085,"mc":[{"id":"1.195395426","rc":[{"atb":[[1.48,15.52]],"id":42189480}],"con":true,"img":false}]}
{"op":"mcm","clk":"5306590489","pt":1646101588193,"mc":[{"id":"1.195395426","rc":[{"atb":[[1.44,0]],"id":42189480}],"con":true,"img":false}]}
{"op":"mcm","clk":"5306590659","pt":1646101592194,"mc":[{"id":"1.195395426","rc":[{"atb":[[1.45,0]],"id":42189480}],"con":true,"img":false}]}
{"op":"mcm","clk":"5306590665","pt":1646101592299,"mc":[{"id":"1.195395426","rc":[{"atb":[[1.41,105.57]],"id":42189480}],"con":true,"img":false}]}
{"op":"mcm","clk":"5306590814","pt":1646101595322,"mc":[{"id":"1.195395426","rc":[{"atb":[[1.48,0]],"id":42189480}],"con":true,"img":false}]}
{"op":"mcm","clk":"5306591106","pt":1646101601206,"mc":[{"id":"1.195395426","rc":[{"atb":[[1.44,16.94]],"id":42189480}],"con":true,"img":false}]}
{"op":"mcm","clk":"5306591340","pt":1646101605622,"mc":[{"id":"1.195395426","rc":[{"atb":[[1.44,35.91]],"id":42189480}],"con":true,"img":false}]}
{"op":"mcm","clk":"5306593401","pt":1646101651676,"mc":[{"id":"1.195395426","rc":[{"atb":[[1.41,0]],"id":42189480}],"con":true,"img":false}]}
{"op":"mcm","clk":"5306593407","pt":1646101651779,"mc":[{"id":"1.195395426","rc":[{"atb":[[1.45,105.57]],"id":42189480}],"con":true,"img":false}]}
{"op":"mcm","clk":"5306593425","pt":1646101652292,"mc":[{"id":"1.195395426","rc":[{"atb":[[1.44,18.97]],"id":42189480}],"con":true,"img":false}]}
{"op":"mcm","clk":"5306593646","pt":1646101658998,"mc":[{"id":"1.195395426","rc":[{"atb":[[1.48,15.52]],"id":42189480}],"con":true,"img":false}]}
{"op":"mcm","clk":"5306593919","pt":1646101666373,"mc":[{"id":"1.195395426","rc":[{"atb":[[1.44,0]],"id":42189480}],"con":true,"img":false}]}
{"op":"mcm","clk":"5306594092","pt":1646101670724,"mc":[{"id":"1.195395426","rc":[{"atb":[[1.45,0]],"id":42189480}],"con":true,"img":false}]}
{"op":"mcm","clk":"5306594100","pt":1646101670826,"mc":[{"id":"1.195395426","rc":[{"atb":[[1.41,105.57]],"id":42189480}],"con":true,"img":false}]}
{"op":"mcm","clk":"5306594122","pt":1646101671296,"mc":[{"id":"1.195395426","rc":[{"atb":[[1.48,0]],"id":42189480}],"con":true,"img":false}]}
{"op":"mcm","clk":"5306594358","pt":1646101676892,"mc":[{"id":"1.195395426","rc":[{"atb":[[1.44,16.94]],"id":42189480}],"con":true,"img":false}]}
{"op":"mcm","clk":"5306594640","pt":1646101683703,"mc":[{"id":"1.195395426","rc":[{"atb":[[1.44,35.91]],"id":42189480}],"con":true,"img":false}]}
{"op":"mcm","clk":"5306596341","pt":1646101728668,"mc":[{"id":"1.195395426","rc":[{"atb":[[1.41,0]],"id":42189480}],"con":true,"img":false}]}
{"op":"mcm","clk":"5306596343","pt":1646101728768,"mc":[{"id":"1.195395426","rc":[{"atb":[[1.45,105.57]],"id":42189480}],"con":true,"img":false}]}
{"op":"mcm","clk":"5306596467","pt":1646101732202,"mc":[{"id":"1.195395426","rc":[{"atb":[[1.44,18.97]],"id":42189480}],"con":true,"img":false}]}
{"op":"mcm","clk":"5306596638","pt":1646101737172,"mc":[{"id":"1.195395426","rc":[{"atb":[[1.48,15.52]],"id":42189480}],"con":true,"img":false}]}
{"op":"mcm","clk":"5306596939","pt":1646101744313,"mc":[{"id":"1.195395426","rc":[{"atb":[[1.44,0]],"id":42189480}],"con":true,"img":false}]}
{"op":"mcm","clk":"5306597086","pt":1646101748100,"mc":[{"id":"1.195395426","rc":[{"atb":[[1.45,0]],"id":42189480}],"con":true,"img":false}]}
{"op":"mcm","clk":"5306597090","pt":1646101748204,"mc":[{"id":"1.195395426","rc":[{"atb":[[1.41,105.57]],"id":42189480}],"con":true,"img":false}]}
{"op":"mcm","clk":"5306597141","pt":1646101749222,"mc":[{"id":"1.195395426","rc":[{"atb":[[1.48,0]],"id":42189480}],"con":true,"img":false}]}
{"op":"mcm","clk":"5306597387","pt":1646101755127,"mc":[{"id":"1.195395426","rc":[{"atb":[[1.44,16.94]],"id":42189480}],"con":true,"img":false}]}
{"op":"mcm","clk":"5306597688","pt":1646101762449,"mc":[{"id":"1.195395426","rc":[{"atb":[[1.44,35.91]],"id":42189480}],"con":true,"img":false}]}
{"op":"mcm","clk":"5306599429","pt":1646101803473,"mc":[{"id":"1.195395426","rc":[{"atb":[[1.41,0]],"id":42189480}],"con":true,"img":false}]}
{"op":"mcm","clk":"5306599437","pt":1646101803573,"mc":[{"id":"1.195395426","rc":[{"atb":[[1.45,105.57]],"id":42189480}],"con":true,"img":false}]}
{"op":"mcm","clk":"5306599581","pt":1646101806401,"mc":[{"id":"1.195395426","rc":[{"atb":[[1.44,18.97]],"id":42189480}],"con":true,"img":false}]}
{"op":"mcm","clk":"5306599866","pt":1646101812202,"mc":[{"id":"1.195395426","rc":[{"atb":[[1.48,15.52]],"id":42189480}],"con":true,"img":false}]}
{"op":"mcm","clk":"5306600163","pt":1646101817081,"mc":[{"id":"1.195395426","rc":[{"atb":[[1.44,0]],"id":42189480}],"con":true,"img":false}]}
{"op":"mcm","clk":"5306600441","pt":1646101822320,"mc":[{"id":"1.195395426","rc":[{"atb":[[1.45,0]],"id":42189480}],"con":true,"img":false}]}
{"op":"mcm","clk":"5306600447","pt":1646101822421,"mc":[{"id":"1.195395426","rc":[{"atb":[[1.41,105.57]],"id":42189480}],"con":true,"img":false}]}
{"op":"mcm","clk":"5306600528","pt":1646101824316,"mc":[{"id":"1.195395426","rc":[{"atb":[[1.48,0]],"id":42189480}],"con":true,"img":false}]}
{"op":"mcm","clk":"5306600797","pt":1646101830413,"mc":[{"id":"1.195395426","rc":[{"atb":[[1.44,16.94]],"id":42189480}],"con":true,"img":false}]}
{"op":"mcm","clk":"5306601247","pt":1646101840718,"mc":[{"id":"1.195395426","rc":[{"atb":[[1.44,35.91]],"id":42189480}],"con":true,"img":false}]}
{"op":"mcm","clk":"5306603588","pt":1646101895285,"mc":[{"id":"1.195395426","rc":[{"atb":[[1.41,0]],"id":42189480}],"con":true,"img":false}]}
{"op":"mcm","clk":"5306603590","pt":1646101895386,"mc":[{"id":"1.195395426","rc":[{"atb":[[1.45,105.57]],"id":42189480}],"con":true,"img":false}]}
{"op":"mcm","clk":"5306603635","pt":1646101896510,"mc":[{"id":"1.195395426","rc":[{"atb":[[1.44,18.97]],"id":42189480}],"con":true,"img":false}]}
{"op":"mcm","clk":"5306603898","pt":1646101902404,"mc":[{"id":"1.195395426","rc":[{"atb":[[1.48,15.52]],"id":42189480}],"con":true,"img":false}]}
{"op":"mcm","clk":"5306604207","pt":1646101910129,"mc":[{"id":"1.195395426","rc":[{"atb":[[1.44,0]],"id":42189480}],"con":true,"img":false}]}
{"op":"mcm","clk":"5306604335","pt":1646101913303,"mc":[{"id":"1.195395426","rc":[{"atb":[[1.45,0]],"id":42189480}],"con":true,"img":false}]}
{"op":"mcm","clk":"5306604340","pt":1646101913403,"mc":[{"id":"1.195395426","rc":[{"atb":[[1.41,105.57]],"id":42189480}],"con":true,"img":false}]}
{"op":"mcm","clk":"5306604381","pt":1646101914122,"mc":[{"id":"1.195395426","rc":[{"atb":[[2.52,0],[2.64,56.89]],"id":38859241},{"atl":[[2.92,0],[2.78,56.18]],"id":43154454},{"atb":[[2.3,0],[2.66,22.72]],"id":39318320},{"atb":[[2.8,37.08],[2.6,0]],"id":43154455},{"atb":[[1.29,13.84]],"id":38256919},{"atb":[[1.38,339.33],[1.35,0]],"id":42189480}],"con":true,"img":false}]}
{"op":"mcm","clk":"5306604415","pt":1646101914733,"mc":[{"id":"1.195395426","rc":[{"atb":[[1.48,0]],"id":42189480}],"con":true,"img":false}]}
{"op":"mcm","clk":"5306604701","pt":1646101920420,"mc":[{"id":"1.195395426","rc":[{"atb":[[1.44,16.94]],"id":42189480}],"con":true,"img":false}]}
{"op":"mcm","clk":"5306605062","pt":1646101927741,"mc":[{"id":"1.195395426","rc":[{"atb":[[1.44,35.91]],"id":42189480}],"con":true,"img":false}]}
{"op":"mcm","clk":"5306606296","pt":1646101955277,"mc":[{"id":"1.195395426","rc":[{"atl":[[10,9.03],[10.5,0]],"id":38859241},{"atl":[[2.98,50.51]],"id":43154454},{"atb":[[1.8,22.72],[2.66,0]],"id":39318320},{"atb":[[2.8,0],[2.92,37.08]],"id":43154455},{"atb":[[1.29,0],[1.47,13.84]],"id":38256919}],"con":true,"img":false}]}
{"op":"mcm","clk":"5306606302","pt":1646101955380,"mc":[{"id":"1.195395426","rc":[{"atl":[[2.78,0]],"id":43154454},{"atb":[[2.8,22.72],[1.8,0]],"id":39318320},{"atb":[[2.8,37.08],[2.92,0]],"id":43154455},{"atb":[[1.23,20.76],[1.47,0]],"id":38256919}],"con":true,"img":false}]}
{"op":"mcm","clk":"5306606945","pt":1646101967076,"mc":[{"id":"1.195395426","rc":[{"atb":[[1.41,0]],"id":42189480}],"con":true,"img":false}]}
{"op":"mcm","clk":"5306606949","pt":1646101967177,"mc":[{"id":"1.195395426","rc":[{"atb":[[1.45,105.57]],"id":42189480}],"con":true,"img":false}]}
{"op":"mcm","clk":"5306607014","pt":1646101968609,"mc":[{"id":"1.195395426","rc":[{"atb":[[1.44,18.97]],"id":42189480}],"con":true,"img":false}]}
{"op":"mcm","clk":"5306607302","pt":1646101974601,"mc":[{"id":"1.195395426","rc":[{"atb":[[1.48,15.52]],"id":42189480}],"con":true,"img":false}]}
{"op":"mcm","clk":"5306607725","pt":1646101983317,"mc":[{"id":"1.195395426","rc":[{"atl":[[2.98,0],[2.78,56.18]],"id":43154454},{"atb":[[2.8,0],[3.65,22.72]],"id":39318320},{"atb":[[1.23,0],[1.04,22.41]],"id":38256919}],"con":true,"img":false}]}
{"op":"mcm","clk":"5306607733","pt":1646101983420,"mc":[{"id":"1.195395426","rc":[{"atb":[[3.65,0]],"id":39318320}],"con":true,"img":false}]}
{"op":"mcm","clk":"5306607740","pt":1646101983523,"mc":[{"id":"1.195395426","rc":[{"atb":[[2.66,22.72]],"id":39318320}],"con":true,"img":false}]}
{"op":"mcm","clk":"5306607753","pt":1646101983726,"mc":[{"id":"1.195395426","rc":[{"atb":[[1.45,0]],"id":42189480}],"con":true,"img":false}]}
{"op":"mcm","clk":"5306607757","pt":1646101983828,"mc":[{"id":"1.195395426","rc":[{"atb":[[1.41,105.57]],"id":42189480}],"con":true,"img":false}]}
{"op":"mcm","clk":"5306607882","pt":1646101986595,"mc":[{"id":"1.195395426","rc":[{"atb":[[1.48,0]],"id":42189480}],"con":true,"img":false}]}
{"op":"mcm","clk":"5306608183","pt":1646101992643,"mc":[{"id":"1.195395426","rc":[{"atb":[[1.44,35.91]],"id":42189480}],"con":true,"img":false}]}
{"op":"mcm","clk":"5306609030","pt":1646102009036,"mc":[{"id":"1.195395426","rc":[{"atb":[[1.29,22.41],[1.04,0]],"id":38256919}],"con":true,"img":false}]}
{"op":"mcm","clk":"5306610257","pt":1646102035986,"mc":[{"id":"1.195395426","rc":[{"atb":[[1.41,0]],"id":42189480}],"con":true,"img":false}]}
{"op":"mcm","clk":"5306610263","pt":1646102036087,"mc":[{"id":"1.195395426","rc":[{"atb":[[1.45,105.57]],"id":42189480}],"con":true,"img":false}]}
{"op":"mcm","clk":"5306610329","pt":1646102037679,"mc":[{"id":"1.195395426","rc":[{"atb":[[1.44,18.97]],"id":42189480}],"con":true,"img":false}]}
{"op":"mcm","clk":"5306610440","pt":1646102040295,"mc":[{"id":"1.195395426","rc":[{"atb":[[1.19,0]],"id":43154454}],"con":true,"img":false}]}
{"op":"mcm","clk":"5306610448","pt":1646102040397,"mc":[{"id":"1.195395426","rc":[{"atb":[[1.17,94.07]],"id":43154454}],"con":true,"img":false}]}
{"op":"mcm","clk":"5306610605","pt":1646102043678,"mc":[{"id":"1.195395426","rc":[{"atb":[[1.48,15.52]],"id":42189480}],"con":true,"img":false}]}
{"op":"mcm","clk":"5306610682","pt":1646102045267,"mc":[{"id":"1.195395426","rc":[{"atb":[[1.97,19.21]],"id":36104892},{"atb":[[1.18,65.84]],"id":43154454},{"atb":[[1.39,87.03]],"id":42189480}],"con":true,"img":false}]}
{"op":"mcm","clk":"5306610962","pt":1646102050188,"mc":[{"id":"1.195395426","rc":[{"atb":[[1.39,0]],"id":42189480}],"con":true,"img":false}]}
{"op":"mcm","clk":"5306611255","pt":1646102055576,"mc":[{"id":"1.195395426","rc":[{"atb":[[1.49,10.86]],"id":42189480}],"con":true,"img":false}]}
{"op":"mcm","clk":"5306611649","pt":1646102062414,"mc":[{"id":"1.195395426","rc":[{"atb":[[1.44,0]],"id":42189480}],"con":true,"img":false}]}
{"op":"mcm","clk":"5306612021","pt":1646102069184,"mc":[{"id":"1.195395426","rc":[{"atb":[[1.48,32.91]],"id":42189480}],"con":true,"img":false}]}
{"op":"mcm","clk":"5306612082","pt":1646102070415,"mc":[{"id":"1.195395426","rc":[{"atb":[[3.15,0]],"id":38859241}],"con":true,"img":false}]}
{"op":"mcm","clk":"5306612086","pt":1646102070518,"mc":[{"id":"1.195395426","rc":[{"atb":[[3.4,20.13]],"id":38859241}],"con":true,"img":false}]}
{"op":"mcm","clk":"5306612960","pt":1646102087127,"mc":[{"id":"1.195395426","rc":[{"atb":[[1.17,0]],"id":43154454}],"con":true,"img":false}]}
{"op":"mcm","clk":"5306612965","pt":1646102087229,"mc":[{"id":"1.195395426","rc":[{"atb":[[1.19,94.07]],"id":43154454}],"con":true,"img":false}]}
{"op":"mcm","clk":"5306613226","pt":1646102092417,"mc":[{"id":"1.195395426","rc":[{"atb":[[1.18,0]],"id":43154454}],"con":true,"img":false}]}
{"op":"mcm","clk":"5306613478","pt":1646102097918,"mc":[{"id":"1.195395426","rc":[{"atb":[[1.2,65.84]],"id":43154454},{"spn":1.71,"spf":"NaN","id":43154454},{"spn":2.01,"spf":"NaN","id":42189480}],"con":true,"img":false}]}
{"op":"mcm","clk":"5306613734","pt":1646102103374,"mc":[{"id":"1.195395426","rc":[{"atb":[[2.52,56.89]],"id":38859241},{"atl":[[9.8,4.22]],"id":38859241},{"atl":[[2.66,58.12],[2.78,0]],"id":43154454},{"atb":[[2.3,22.72],[2.66,0]],"id":39318320},{"atb":[[2.8,0],[2.6,37.08]],"id":43154455}],"con":true,"img":false}]}
{"op":"mcm","clk":"5306613737","pt":1646102103426,"mc":[{"id":"1.195395426","rc":[{"atb":[[2.64,0]],"id":38859241},{"atl":[[10,4.81]],"id":38859241},{"atb":[[1.29,0]],"id":38256919}],"con":true,"img":false}]}
{"op":"mcm","clk":"5306614299","pt":1646102115489,"mc":[{"id":"1.195395426","rc":[{"atl":[[4.5,0]],"id":36104892},{"atb":[[2.52,0]],"id":38859241},{"atl":[[9.8,0]],"id":38859241},{"atl":[[2.66,0]],"id":43154454},{"atb":[[2.3,0]],"id":39318320},{"atl":[[44,2.7]],"id":39318320},{"atb":[[2.6,0]],"id":43154455},{"atl":[[27,0]],"id":43154455},{"atl":[[100,0.43]],"id":38256919},{"atb":[[1.38,138.04]],"id":42189480},{"atl":[[10.5,0]],"id":42189480}],"con":true,"img":false}]}
{"op":"mcm","clk":"5306614526","pt":1646102120253,"mc":[{"id":"1.195395426","rc":[{"atl":[[10,0],[14,3.32]],"id":38859241},{"atb":[[1.19,0]],"id":43154454},{"atl":[[44,0]],"id":39318320},{"atl":[[26,2.7]],"id":43154455},{"atl":[[95,0]],"id":38256919}],"con":true,"img":false}]}
{"op":"mcm","clk":"5306614531","pt":1646102120352,"mc":[{"id":"1.195395426","rc":[{"atb":[[1.17,94.07]],"id":43154454},{"atl":[[50,2.7]],"id":39318320},{"atl":[[28,2.7]],"id":43154455},{"atl":[[110,2.7]],"id":38256919}],"con":true,"img":false}]}
{"op":"mcm","clk":"5306614746","pt":1646102124151,"mc":[{"id":"1.195395426","rc":[{"atb":[[1.2,0]],"id":43154454}],"con":true,"img":false}]}
{"op":"mcm","clk":"5306615039","pt":1646102129892,"mc":[{"id":"1.195395426","rc":[{"atb":[[1.18,65.84]],"id":43154454}],"con":true,"img":false}]}
{"op":"mcm","clk":"5306615888","pt":1646102145822,"mc":[{"id":"1.195395426","rc":[{"atb":[[1.45,0]],"id":42189480}],"con":true,"img":false}]}
{"op":"mcm","clk":"5306615891","pt":1646102145925,"mc":[{"id":"1.195395426","rc":[{"atb":[[1.41,105.57]],"id":42189480}],"con":true,"img":false}]}
{"op":"mcm","clk":"5306616032","pt":1646102148790,"mc":[{"id":"1.195395426","rc":[{"atb":[[1.48,17.39]],"id":42189480}],"con":true,"img":false}]}
{"op":"mcm","clk":"5306616074","pt":1646102149711,"mc":[{"id":"1.195395426","rc":[{"atb":[[1.49,0]],"id":42189480}],"con":true,"img":false}]}
{"op":"mcm","clk":"5306616312","pt":1646102153907,"mc":[{"id":"1.195395426","rc":[{"atb":[[3.4,0]],"id":38859241},{"atb":[[1.17,0]],"id":43154454}],"con":true,"img":false}]}
{"op":"mcm","clk":"5306616316","pt":1646102154009,"mc":[{"id":"1.195395426","rc":[{"atb":[[3.15,20.13]],"id":38859241},{"atb":[[1.19,94.07]],"id":43154454}],"con":true,"img":false}]}
{"op":"mcm","clk":"5306616357","pt":1646102154827,"mc":[{"id":"1.195395426","rc":[{"atb":[[1.44,16.94]],"id":42189480}],"con":true,"img":false}]}
{"op":"mcm","clk":"5306616417","pt":1646102156107,"mc":[{"id":"1.195395426","rc":[{"atb":[[1.39,29.55]],"id":42189480}],"con":true,"img":false}]}
{"op":"mcm","clk":"5306616543","pt":1646102158510,"mc":[{"id":"1.195395426","rc":[{"spn":3.31,"spf":"NaN","id":36104892},{"atb":[[1.18,0]],"id":43154454},{"spn":1.7,"spf":"NaN","id":43154454},{"spn":2.01,"spf":"NaN","id":42189480}],"con":true,"img":false}]}
{"op":"mcm","clk":"5306616702","pt":1646102161149,"mc":[{"id":"1.195395426","marketDefinition":{"bspMarket":true,"turnInPlayEnabled":false,"persistenceEnabled":false,"marketBaseRate":7.0,"eventId":"31270458","eventTypeId":"4339","numberOfWinners":2,"bettingType":"ODDS","marketType":"PLACE","marketTime":"2022-03-01T03:29:00.000Z","suspendTime":"2022-03-01T03:29:00.000Z","bspReconciled":false,"complete":true,"inPlay":false,"crossMatching":true,"runnersVoidable":false,"numberOfActiveRunners":7,"betDelay":0,"status":"OPEN","runners":[{"status":"ACTIVE","sortPriority":1,"id":43154454,"name":"1. Buckle Up Iveta"},{"status":"ACTIVE","sortPriority":2,"id":38859241,"name":"2. Theo Dragonet"},{"status":"ACTIVE","sortPriority":3,"id":39318320,"name":"3. Engage The Rage"},{"status":"ACTIVE","sortPriority":4,"id":42189480,"name":"4. Toxic Turtle"},{"status":"ACTIVE","sortPriority":5,"id":36104892,"name":"5. Bridwood Ali"},{"status":"ACTIVE","sortPriority":6,"id":38256919,"name":"6. Warramunga"},{"status":"ACTIVE","sortPriority":7,"id":43154455,"name":"8. Strait Sambuca"}],"regulators":["MR_INT"],"venue":"Devonport","countryCode":"AU","discountAllowed":true,"timezone":"Australia/Sydney","openDate":"2022-03-01T02:00:00.000Z","version":4381069194,"name":"To Be Placed","eventName":"Devonport (AUS) 1st Mar"},"rc":[],"con":true,"img":false}]}
{"op":"mcm","clk":"5306616729","pt":1646102161633,"mc":[{"id":"1.195395426","rc":[{"atb":[[1.39,0]],"id":42189480}],"con":true,"img":false}]}
{"op":"mcm","clk":"5306616892","pt":1646102164907,"mc":[{"id":"1.195395426","rc":[{"atb":[[1.2,65.84]],"id":43154454}],"con":true,"img":false}]}
{"op":"mcm","clk":"5306617073","pt":1646102168540,"mc":[{"id":"1.195395426","rc":[{"atb":[[1.42,24.34]],"id":42189480}],"con":true,"img":false}]}
{"op":"mcm","clk":"5306619009","pt":1646102202984,"mc":[{"id":"1.195395426","rc":[{"atb":[[1.19,0]],"id":43154454}],"con":true,"img":false}]}
{"op":"mcm","clk":"5306619014","pt":1646102203085,"mc":[{"id":"1.195395426","rc":[{"atb":[[1.21,94.07]],"id":43154454}],"con":true,"img":false}]}
{"op":"mcm","clk":"5306619183","pt":1646102206362,"mc":[{"id":"1.195395426","rc":[{"atb":[[1.2,0]],"id":43154454}],"con":true,"img":false}]}
{"op":"mcm","clk":"5306619468","pt":1646102212297,"mc":[{"id":"1.195395426","rc":[{"atb":[[1.17,112.88]],"id":43154454}],"con":true,"img":false}]}
{"op":"mcm","clk":"5306619861","pt":1646102219818,"mc":[{"id":"1.195395426","rc":[{"atb":[[1.21,0]],"id":43154454},{"spn":1.69,"spf":"NaN","id":43154454}],"con":true,"img":false}]}
{"op":"mcm","clk":"5306619869","pt":1646102219868,"mc":[{"id":"1.195395426","rc":[{"atb":[[1.19,94.07]],"id":43154454}],"con":true,"img":false}]}
{"op":"mcm","clk":"5306622310","pt":1646102267366,"mc":[{"id":"1.195395426","rc":[{"atb":[[1.16,0]],"id":43154454}],"con":true,"img":false}]}
{"op":"mcm","clk":"5306622315","pt":1646102267462,"mc":[{"id":"1.195395426","rc":[{"atb":[[1.18,378.76]],"id":43154454}],"con":true,"img":false}]}
{"op":"mcm","clk":"5306622485","pt":1646102270640,"mc":[{"id":"1.195395426","rc":[{"atb":[[1.17,0]],"id":43154454}],"con":true,"img":false}]}
{"op":"mcm","clk":"5306622812","pt":1646102277049,"mc":[{"id":"1.195395426","rc":[{"atb":[[1.16,103.48]],"id":43154454}],"con":true,"img":false}]}
{"op":"mcm","clk":"5306623190","pt":1646102283681,"mc":[{"id":"1.195395426","rc":[{"atb":[[1.18,0]],"id":43154454},{"spn":1.7,"spf":"NaN","id":43154454}],"con":true,"img":false}]}
{"op":"mcm","clk":"5306623197","pt":1646102283783,"mc":[{"id":"1.195395426","rc":[{"atb":[[1.17,378.76]],"id":43154454}],"con":true,"img":false}]}
{"op":"mcm","clk":"5306623364","pt":1646102286798,"mc":[{"id":"1.195395426","rc":[{"atb":[[1.16,0]],"id":43154454}],"con":true,"img":false}]}
{"op":"mcm","clk":"5306623664","pt":1646102292184,"mc":[{"id":"1.195395426","rc":[{"atb":[[1.2,65.84]],"id":43154454}],"con":true,"img":false}]}
{"op":"mcm","clk":"5306624589","pt":1646102307633,"mc":[{"id":"1.195395426","rc":[{"atb":[[1.48,0]],"id":42189480}],"con":true,"img":false}]}
{"op":"mcm","clk":"5306625066","pt":1646102316121,"mc":[{"id":"1.195395426","rc":[{"atb":[[1.44,35.91]],"id":42189480}],"con":true,"img":false}]}
{"op":"mcm","clk":"5306625658","pt":1646102327336,"mc":[{"id":"1.195395426","rc":[{"atb":[[1.98,5]],"id":36104892},{"atb":[[3.55,3.33]],"id":38859241},{"atb":[[1.21,131.69]],"id":43154454},{"atb":[[5.3,3.33]],"id":43154455},{"atb":[[1.45,71.83]],"id":42189480}],"con":true,"img":false}]}
{"op":"mcm","clk":"5306625738","pt":1646102329024,"mc":[{"id":"1.195395426","rc":[{"atb":[[1.44,18.97]],"id":42189480}],"con":true,"img":false}]}
{"op":"mcm","clk":"5306625829","pt":1646102330864,"mc":[{"id":"1.195395426","rc":[{"atb":[[1.19,0]],"id":43154454}],"con":true,"img":false}]}
{"op":"mcm","clk":"5306625836","pt":1646102330967,"mc":[{"id":"1.195395426","rc":[{"atb":[[1.21,225.77]],"id":43154454}],"con":true,"img":false}]}
{"op":"mcm","clk":"5306625888","pt":1646102332042,"mc":[{"id":"1.195395426","rc":[{"atb":[[1.97,0]],"id":36104892},{"atb":[[1.2,0]],"id":43154454},{"atb":[[1.42,0]],"id":42189480}],"con":true,"img":false}]}
{"op":"mcm","clk":"5306625983","pt":1646102333932,"mc":[{"id":"1.195395426","rc":[{"atb":[[3.5,0]],"id":38859241},{"atb":[[5.2,0]],"id":43154455}],"con":true,"img":false}]}
{"op":"mcm","clk":"5306625989","pt":1646102334034,"mc":[{"id":"1.195395426","rc":[{"atb":[[3.6,1.66]],"id":38859241},{"atb":[[5.4,1.66]],"id":43154455}],"con":true,"img":false}]}
{"op":"mcm","clk":"5306626016","pt":1646102334545,"mc":[{"id":"1.195395426","rc":[{"atb":[[1.21,94.07]],"id":43154454},{"atb":[[1.45,0]],"id":42189480}],"con":true,"img":false}]}
{"op":"mcm","clk":"5306626113","pt":1646102336441,"mc":[{"id":"1.195395426","rc":[{"atb":[[3.55,0]],"id":38859241},{"atb":[[5.3,0]],"id":43154455}],"con":true,"img":false}]}
{"op":"mcm","clk":"5306626173","pt":1646102337522,"mc":[{"id":"1.195395426","rc":[{"atb":[[2.02,13.9]],"id":36104892},{"atb":[[1.18,188.56]],"id":43154454},{"atb":[[1.42,79.01]],"id":42189480}],"con":true,"img":false}]}
{"op":"mcm","clk":"5306626220","pt":1646102338555,"mc":[{"id":"1.195395426","rc":[{"atb":[[1.18,446.07]],"id":43154454},{"atb":[[1.39,66.41]],"id":42189480}],"con":true,"img":false}]}
{"op":"mcm","clk":"5306626330","pt":1646102340762,"mc":[{"id":"1.195395426","rc":[{"atb":[[3.5,4.59]],"id":38859241},{"atb":[[5.2,4.59]],"id":43154455}],"con":true,"img":false}]}
{"op":"mcm","clk":"5306626333","pt":1646102340864,"mc":[{"id":"1.195395426","rc":[{"atb":[[3.6,0]],"id":38859241},{"atb":[[5.4,0]],"id":43154455}],"con":true,"img":false}]}
{"op":"mcm","clk":"5306626338","pt":1646102340967,"mc":[{"id":"1.195395426","rc":[{"atb":[[3.5,6.26]],"id":38859241},{"atb":[[5.2,6.26]],"id":43154455}],"con":true,"img":false}]}
{"op":"mcm","clk":"5306626433","pt":1646102342760,"mc":[{"id":"1.195395426","rc":[{"atb":[[1.39,0]],"id":42189480}],"con":true,"img":false}]}
{"op":"mcm","clk":"5306626505","pt":1646102344042,"mc":[{"id":"1.195395426","rc":[{"spn":1.71,"spf":"NaN","id":43154454},{"atb":[[1.45,16.56]],"id":42189480},{"spn":1.99,"spf":"NaN","id":42189480}],"con":true,"img":false}]}
{"op":"mcm","clk":"5306626554","pt":1646102345167,"mc":[{"id":"1.195395426","rc":[{"atb":[[1.21,0]],"id":43154454}],"con":true,"img":false}]}
{"op":"mcm","clk":"5306626560","pt":1646102345269,"mc":[{"id":"1.195395426","rc":[{"atb":[[1.19,94.07]],"id":43154454},{"atb":[[1.44,0]],"id":42189480}],"con":true,"img":false}]}
{"op":"mcm","clk":"5306626632","pt":1646102346649,"mc":[{"id":"1.195395426","rc":[{"atb":[[1.46,33.12]],"id":42189480}],"con":true,"img":false}]}
{"op":"mcm","clk":"5306626670","pt":1646102347363,"mc":[{"id":"1.195395426","rc":[{"atb":[[1.42,0]],"id":42189480}],"con":true,"img":false}]}
{"op":"mcm","clk":"5306626825","pt":1646102350280,"mc":[{"id":"1.195395426","rc":[{"atb":[[1.45,0]],"id":42189480}],"con":true,"img":false}]}
{"op":"mcm","clk":"5306626921","pt":1646102352376,"mc":[{"id":"1.195395426","rc":[{"atb":[[1.46,0]],"id":42189480}],"con":true,"img":false}]}
{"op":"mcm","clk":"5306626935","pt":1646102352684,"mc":[{"id":"1.195395426","rc":[{"atb":[[1.42,39.74]],"id":42189480}],"con":true,"img":false}]}
{"op":"mcm","clk":"5306627109","pt":1646102356162,"mc":[{"id":"1.195395426","rc":[{"atb":[[1.44,16.94]],"id":42189480}],"con":true,"img":false}]}
{"op":"mcm","clk":"5306627118","pt":1646102356263,"mc":[{"id":"1.195395426","rc":[{"atb":[[1.39,118.84]],"id":42189480}],"con":true,"img":false}]}
{"op":"mcm","clk":"5306627181","pt":1646102357488,"mc":[{"id":"1.195395426","rc":[{"atb":[[1.42,0]],"id":42189480}],"con":true,"img":false}]}
{"op":"mcm","clk":"5306627347","pt":1646102360610,"mc":[{"id":"1.195395426","rc":[{"atb":[[1.42,16.94]],"id":42189480}],"con":true,"img":false}]}
{"op":"mcm","clk":"5306627513","pt":1646102363782,"mc":[{"id":"1.195395426","rc":[{"atb":[[1.44,35.91],[1.39,0]],"id":42189480}],"con":true,"img":false}]}
{"op":"mcm","clk":"5306627717","pt":1646102367775,"mc":[{"id":"1.195395426","rc":[{"atb":[[1.45,71.83]],"id":42189480}],"con":true,"img":false}]}
{"op":"mcm","clk":"5306627732","pt":1646102368185,"mc":[{"id":"1.195395426","rc":[{"atb":[[1.44,18.97]],"id":42189480}],"con":true,"img":false}]}
{"op":"mcm","clk":"5306627842","pt":1646102370395,"mc":[{"id":"1.195395426","rc":[{"atb":[[1.42,0]],"id":42189480}],"con":true,"img":false}]}
{"op":"mcm","clk":"5306628002","pt":1646102373590,"mc":[{"id":"1.195395426","rc":[{"atb":[[1.45,0]],"id":42189480}],"con":true,"img":false}]}
{"op":"mcm","clk":"5306628118","pt":1646102376099,"mc":[{"id":"1.195395426","rc":[{"atb":[[1.42,79.01]],"id":42189480}],"con":true,"img":false}]}
{"op":"mcm","clk":"5306628162","pt":1646102377323,"mc":[{"id":"1.195395426","rc":[{"atb":[[1.39,66.41]],"id":42189480}],"con":true,"img":false}]}
{"op":"mcm","clk":"5306628319","pt":1646102381112,"mc":[{"id":"1.195395426","rc":[{"atb":[[1.39,0]],"id":42189480}],"con":true,"img":false}]}
{"op":"mcm","clk":"5306628410","pt":1646102383310,"mc":[{"id":"1.195395426","rc":[{"atb":[[1.45,16.56]],"id":42189480}],"con":true,"img":false}]}
{"op":"mcm","clk":"5306628448","pt":1646102384229,"mc":[{"id":"1.195395426","rc":[{"atb":[[1.44,0]],"id":42189480}],"con":true,"img":false}]}
{"op":"mcm","clk":"5306628481","pt":1646102384945,"mc":[{"id":"1.195395426","rc":[{"atb":[[1.45,54.51]],"id":42189480}],"con":true,"img":false}]}
{"op":"mcm","clk":"5306628535","pt":1646102386021,"mc":[{"id":"1.195395426","rc":[{"atb":[[1.42,0]],"id":42189480}],"con":true,"img":false}]}
{"op":"mcm","clk":"5306628554","pt":1646102386530,"mc":[{"id":"1.195395426","rc":[{"atb":[[1.45,37.95]],"id":42189480}],"con":true,"img":false}]}
{"op":"mcm","clk":"5306628773","pt":1646102391213,"mc":[{"id":"1.195395426","rc":[{"atb":[[1.39,53.13]],"id":42189480}],"con":true,"img":false}]}
{"op":"mcm","clk":"5306628786","pt":1646102391519,"mc":[{"id":"1.195395426","rc":[{"atb":[[1.17,0]],"id":43154454}],"con":true,"img":false}]}
{"op":"mcm","clk":"5306628789","pt":1646102391622,"mc":[{"id":"1.195395426","rc":[{"atb":[[1.19,472.84]],"id":43154454}],"con":true,"img":false}]}
{"op":"mcm","clk":"5306628818","pt":1646102392237,"mc":[{"id":"1.195395426","rc":[{"atb":[[1.44,16.94]],"id":42189480}],"con":true,"img":false}]}
{"op":"mcm","clk":"5306628939","pt":1646102394447,"mc":[{"id":"1.195395426","rc":[{"atb":[[1.18,188.56]],"id":43154454},{"atb":[[1.45,0]],"id":42189480}],"con":true,"img":false}]}
{"op":"mcm","clk":"5306629031","pt":1646102396244,"mc":[{"id":"1.195395426","rc":[{"atb":[[1.18,0]],"id":43154454},{"atb":[[1.39,0]],"id":42189480}],"con":true,"img":false}]}
{"op":"mcm","clk":"5306629142","pt":1646102398648,"mc":[{"id":"1.195395426","rc":[{"atb":[[1.16,289.69]],"id":43154454},{"atb":[[1.42,46.59]],"id":42189480}],"con":true,"img":false}]}
{"op":"mcm","clk":"5306629224","pt":1646102400235,"mc":[{"id":"1.195395426","rc":[{"atb":[[1.44,35.91]],"id":42189480}],"con":true,"img":false}]}
{"op":"mcm","clk":"5306629286","pt":1646102401361,"mc":[{"id":"1.195395426","rc":[{"atb":[[1.11,308.56]],"id":43154454},{"atb":[[1.39,22.02]],"id":42189480}],"con":true,"img":false}]}
{"op":"mcm","clk":"5306629525","pt":1646102406373,"mc":[{"id":"1.195395426","rc":[{"atb":[[1.11,0]],"id":43154454},{"spn":1.7,"spf":"NaN","id":43154454},{"atb":[[1.39,0]],"id":42189480},{"spn":1.99,"spf":"NaN","id":42189480}],"con":true,"img":false}]}
{"op":"mcm","clk":"5306629564","pt":1646102407147,"mc":[{"id":"1.195395426","rc":[{"atb":[[1.19,94.07]],"id":43154454},{"atb":[[1.41,0]],"id":42189480}],"con":true,"img":false}]}
{"op":"mcm","clk":"5306629572","pt":1646102407246,"mc":[{"id":"1.195395426","rc":[{"atb":[[1.17,378.76]],"id":43154454},{"atb":[[1.45,105.57]],"id":42189480}],"con":true,"img":false}]}
{"op":"mcm","clk":"5306629670","pt":1646102409750,"mc":[{"id":"1.195395426","rc":[{"atb":[[1.16,0]],"id":43154454},{"atb":[[1.42,0]],"id":42189480}],"con":true,"img":false}]}
{"op":"mcm","clk":"5306629694","pt":1646102410360,"mc":[{"id":"1.195395426","rc":[{"atb":[[1.44,18.97]],"id":42189480}],"con":true,"img":false}]}
{"op":"mcm","clk":"5306629781","pt":1646102412357,"mc":[{"id":"1.195395426","rc":[{"atb":[[1.2,65.84]],"id":43154454},{"atb":[[1.46,73.78]],"id":42189480}],"con":true,"img":false}]}
{"op":"mcm","clk":"5306629847","pt":1646102413689,"mc":[{"id":"1.195395426","rc":[{"atb":[[1.2,253.99]],"id":43154454},{"atb":[[1.39,118.84]],"id":42189480}],"con":true,"img":false}]}
{"op":"mcm","clk":"5306630016","pt":1646102417374,"mc":[{"id":"1.195395426","rc":[{"atb":[[1.39,0]],"id":42189480}],"con":true,"img":false}]}
{"op":"mcm","clk":"5306630122","pt":1646102419372,"mc":[{"id":"1.195395426","rc":[{"atb":[[1.49,15.21]],"id":42189480}],"con":true,"img":false}]}
{"op":"mcm","clk":"5306630207","pt":1646102421173,"mc":[{"id":"1.195395426","rc":[{"atb":[[1.47,98.62]],"id":42189480}],"con":true,"img":false}]}
{"op":"mcm","clk":"5306630262","pt":1646102422258,"mc":[{"id":"1.195395426","rc":[{"atb":[[1.46,0]],"id":42189480}],"con":true,"img":false}]}
{"op":"mcm","clk":"5306630274","pt":1646102422459,"mc":[{"id":"1.195395426","rc":[{"atb":[[1.49,0]],"id":42189480}],"con":true,"img":false}]}
{"op":"mcm","clk":"5306630469","pt":1646102426255,"mc":[{"id":"1.195395426","rc":[{"atb":[[1.44,0]],"id":42189480}],"con":true,"img":false}]}
{"op":"mcm","clk":"5306630538","pt":1646102427380,"mc":[{"id":"1.195395426","rc":[{"atb":[[1.48,69.03]],"id":42189480}],"con":true,"img":false}]}
{"op":"mcm","clk":"5306630595","pt":1646102428406,"mc":[{"id":"1.195395426","rc":[{"atb":[[1.47,0]],"id":42189480}],"con":true,"img":false}]}
{"op":"mcm","clk":"5306630791","pt":1646102432099,"mc":[{"id":"1.195395426","rc":[{"atb":[[1.39,118.84]],"id":42189480}],"con":true,"img":false}]}
{"op":"mcm","clk":"5306630934","pt":1646102434406,"mc":[{"id":"1.195395426","rc":[{"atb":[[1.51,14.61]],"id":42189480}],"con":true,"img":false}]}
{"op":"mcm","clk":"5306631102","pt":1646102437179,"mc":[{"id":"1.195395426","rc":[{"atb":[[1.48,0]],"id":42189480}],"con":true,"img":false}]}
{"op":"mcm","clk":"5306631142","pt":1646102437790,"mc":[{"id":"1.195395426","rc":[{"atb":[[1.39,0]],"id":42189480}],"con":true,"img":false}]}
{"op":"mcm","clk":"5306631148","pt":1646102437893,"mc":[{"id":"1.195395426","rc":[{"atb":[[1.45,0]],"id":42189480}],"con":true,"img":false}]}
{"op":"mcm","clk":"5306631154","pt":1646102437996,"mc":[{"id":"1.195395426","rc":[{"atb":[[1.42,105.57]],"id":42189480}],"con":true,"img":false}]}
{"op":"mcm","clk":"5306631287","pt":1646102440607,"mc":[{"id":"1.195395426","rc":[{"atb":[[1.51,0]],"id":42189480}],"con":true,"img":false}]}
{"op":"mcm","clk":"5306631326","pt":1646102441524,"mc":[{"id":"1.195395426","rc":[{"atb":[[1.39,76.73]],"id":42189480}],"con":true,"img":false}]}
{"op":"mcm","clk":"5306631387","pt":1646102442607,"mc":[{"id":"1.195395426","rc":[{"atb":[[1.39,105.96]],"id":42189480}],"con":true,"img":false}]}
{"op":"mcm","clk":"5306631599","pt":1646102446400,"mc":[{"id":"1.195395426","rc":[{"atb":[[1.45,16.56]],"id":42189480}],"con":true,"img":false}]}
{"op":"mcm","clk":"5306631746","pt":1646102449008,"mc":[{"id":"1.195395426","rc":[{"atb":[[1.39,29.23]],"id":42189480}],"con":true,"img":false}]}
{"op":"mcm","clk":"5306631798","pt":1646102450134,"mc":[{"id":"1.195395426","rc":[{"atb":[[1.39,0]],"id":42189480}],"con":true,"img":false}]}
{"op":"mcm","clk":"5306631916","pt":1646102452334,"mc":[{"id":"1.195395426","rc":[{"atb":[[1.19,0]],"id":43154454}],"con":true,"img":false}]}
{"op":"mcm","clk":"5306631920","pt":1646102452438,"mc":[{"id":"1.195395426","rc":[{"atb":[[1.21,94.07]],"id":43154454}],"con":true,"img":false}]}
{"op":"mcm","clk":"5306631936","pt":1646102452701,"mc":[{"id":"1.195395426","rc":[{"atb":[[1.39,62.1]],"id":42189480}],"con":true,"img":false}]}
{"op":"mcm","clk":"5306632022","pt":1646102454538,"mc":[{"id":"1.195395426","rc":[{"atb":[[1.2,65.84]],"id":43154454}],"con":true,"img":false}]}
{"op":"mcm","clk":"5306632065","pt":1646102455616,"mc":[{"id":"1.195395426","rc":[{"atb":[[1.45,35.11]],"id":42189480}],"con":true,"img":false}]}
{"op":"mcm","clk":"5306632083","pt":1646102455922,"mc":[{"id":"1.195395426","rc":[{"atb":[[1.2,0]],"id":43154454},{"atb":[[1.39,85.28]],"id":42189480}],"con":true,"img":false}]}
{"op":"mcm","clk":"5306632194","pt":1646102458329,"mc":[{"id":"1.195395426","rc":[{"atb":[[1.18,257.5]],"id":43154454}],"con":true,"img":false}]}
{"op":"mcm","clk":"5306632329","pt":1646102461343,"mc":[{"id":"1.195395426","rc":[{"atb":[[1.18,360.98]],"id":43154454}],"con":true,"img":false}]}
{"op":"mcm","clk":"5306632607","pt":1646102467634,"mc":[{"id":"1.195395426","rc":[{"atb":[[1.21,0]],"id":43154454},{"spn":1.7,"spf":"NaN","id":43154454},{"spn":1.99,"spf":"NaN","id":42189480}],"con":true,"img":false}]}
{"op":"mcm","clk":"5306632609","pt":1646102467736,"mc":[{"id":"1.195395426","rc":[{"atb":[[1.19,94.07]],"id":43154454}],"con":true,"img":false}]}
{"op":"mcm","clk":"5306633945","pt":1646102497095,"mc":[{"id":"1.195395426","rc":[{"atb":[[1.42,0]],"id":42189480}],"con":true,"img":false}]}
{"op":"mcm","clk":"5306633948","pt":1646102497198,"mc":[{"id":"1.195395426","rc":[{"atb":[[1.46,105.57]],"id":42189480}],"con":true,"img":false}]}
{"op":"mcm","clk":"5306634041","pt":1646102499758,"mc":[{"id":"1.195395426","rc":[{"atb":[[1.45,18.55]],"id":42189480}],"con":true,"img":false}]}
{"op":"mcm","clk":"5306634065","pt":1646102500268,"mc":[{"id":"1.195395426","rc":[{"atb":[[1.39,62.1]],"id":42189480}],"con":true,"img":false}]}
{"op":"mcm","clk":"5306634077","pt":1646102500575,"mc":[{"id":"1.195395426","rc":[{"atb":[[1.39,0]],"id":42189480}],"con":true,"img":false}]}
{"op":"mcm","clk":"5306634238","pt":1646102504366,"mc":[{"id":"1.195395426","rc":[{"atb":[[1.39,118.84]],"id":42189480}],"con":true,"img":false}]}
{"op":"mcm","clk":"5306634294","pt":1646102505696,"mc":[{"id":"1.195395426","rc":[{"atb":[[1.39,205.88]],"id":42189480}],"con":true,"img":false}]}
{"op":"mcm","clk":"5306634299","pt":1646102505797,"mc":[{"id":"1.195395426","rc":[{"atb":[[1.49,15.21]],"id":42189480}],"con":true,"img":false}]}
{"op":"mcm","clk":"5306634386","pt":1646102508097,"mc":[{"id":"1.195395426","rc":[{"atb":[[1.39,87.03]],"id":42189480}],"con":true,"img":false}]}
{"op":"mcm","clk":"5306634509","pt":1646102510508,"mc":[{"id":"1.195395426","rc":[{"atb":[[1.45,0]],"id":42189480}],"con":true,"img":false}]}
{"op":"mcm","clk":"5306634531","pt":1646102511176,"mc":[{"id":"1.195395426","rc":[{"atb":[[1.39,0]],"id":42189480}],"con":true,"img":false}]}
{"op":"mcm","clk":"5306634558","pt":1646102511994,"mc":[{"id":"1.195395426","rc":[{"atb":[[1.5,30.42]],"id":42189480}],"con":true,"img":false}]}
{"op":"mcm","clk":"5306634590","pt":1646102512811,"mc":[{"id":"1.195395426","rc":[{"atb":[[1.17,0]],"id":43154454},{"atb":[[1.46,0]],"id":42189480}],"con":true,"img":false}]}
{"op":"mcm","clk":"5306634594","pt":1646102512914,"mc":[{"id":"1.195395426","rc":[{"atb":[[1.19,472.84]],"id":43154454},{"atb":[[1.42,105.57]],"id":42189480}],"con":true,"img":false}]}
{"op":"mcm","clk":"5306634713","pt":1646102515585,"mc":[{"id":"1.195395426","rc":[{"atb":[[1.49,0]],"id":42189480}],"con":true,"img":false}]}
{"op":"mcm","clk":"5306634720","pt":1646102515786,"mc":[{"id":"1.195395426","rc":[{"atb":[[1.18,103.48]],"id":43154454}],"con":true,"img":false}]}
{"op":"mcm","clk":"5306634768","pt":1646102517322,"mc":[{"id":"1.195395426","rc":[{"atb":[[1.18,0]],"id":43154454},{"atb":[[1.43,45.63]],"id":42189480}],"con":true,"img":false}]}
{"op":"mcm","clk":"5306634777","pt":1646102517580,"mc":[{"id":"1.195395426","rc":[{"atb":[[1.5,0]],"id":42189480}],"con":true,"img":false}]}
{"op":"mcm","clk":"5306634859","pt":1646102519481,"mc":[{"id":"1.195395426","rc":[{"atb":[[1.11,421.37]],"id":43154454}],"con":true,"img":false}]}
{"op":"mcm","clk":"5306634937","pt":1646102521530,"mc":[{"id":"1.195395426","rc":[{"atb":[[1.39,118.84]],"id":42189480}],"con":true,"img":false}]}
{"op":"mcm","clk":"5306634944","pt":1646102521587,"mc":[{"id":"1.195395426","rc":[{"atb":[[1.45,16.56]],"id":42189480}],"con":true,"img":false}]}
{"op":"mcm","clk":"5306634948","pt":1646102521686,"mc":[{"id":"1.195395426","rc":[{"atl":[[4.5,3.34]],"id":36104892},{"atb":[[2.64,51.4]],"id":38859241},{"atl":[[10.5,3.33]],"id":38859241},{"atl":[[2.78,56.18]],"id":43154454},{"atb":[[2.66,22.14]],"id":39318320},{"atl":[[40,2.56]],"id":39318320},{"atb":[[2.8,33.64]],"id":43154455},{"atl":[[34,3.03]],"id":43154455},{"atb":[[1.29,13.84]],"id":38256919},{"atl":[[100,2.43]],"id":38256919},{"atb":[[1.38,339.33]],"id":42189480},{"atl":[[11,10]],"id":42189480}],"con":true,"img":false}]}
{"op":"mcm","clk":"5306634993","pt":1646102522813,"mc":[{"id":"1.195395426","rc":[{"atb":[[1.11,729.93]],"id":43154454},{"atb":[[1.43,0]],"id":42189480}],"con":true,"img":false}]}
{"op":"mcm","clk":"5306635090","pt":1646102525317,"mc":[{"id":"1.195395426","rc":[{"atb":[[1.98,0]],"id":36104892}],"con":true,"img":false}]}
{"op":"mcm","clk":"5306635196","pt":1646102527827,"mc":[{"id":"1.195395426","rc":[{"spn":3.26,"spf":"NaN","id":36104892},{"spn":1.7,"spf":"NaN","id":43154454},{"atb":[[1.45,35.11]],"id":42189480}],"con":true,"img":false}]}
{"op":"mcm","clk":"5306635204","pt":1646102528032,"mc":[{"id":"1.195395426","rc":[{"atb":[[1.4,21.53]],"id":42189480}],"con":true,"img":false}]}
{"op":"mcm","clk":"5306635249","pt":1646102529109,"mc":[{"id":"1.195395426","rc":[{"atb":[[1.97,45.17]],"id":36104892}],"con":true,"img":false}]}
{"op":"mcm","clk":"5306635303","pt":1646102530539,"mc":[{"id":"1.195395426","rc":[{"atb":[[2.02,1.66]],"id":36104892}],"con":true,"img":false}]}
{"op":"mcm","clk":"5306635315","pt":1646102530694,"mc":[{"id":"1.195395426","rc":[{"atb":[[2,8.34]],"id":36104892}],"con":true,"img":false}]}
{"op":"mcm","clk":"5306635332","pt":1646102531002,"mc":[{"id":"1.195395426","rc":[{"atb":[[1.19,94.07]],"id":43154454},{"atb":[[1.39,0]],"id":42189480}],"con":true,"img":false}]}
{"op":"mcm","clk":"5306635338","pt":1646102531103,"mc":[{"id":"1.195395426","rc":[{"atb":[[1.16,378.76]],"id":43154454}],"con":true,"img":false}]}
{"op":"mcm","clk":"5306635513","pt":1646102535101,"mc":[{"id":"1.195395426","rc":[{"atb":[[1.11,308.56]],"id":43154454},{"atb":[[1.43,96.55]],"id":42189480}],"con":true,"img":false}]}
{"op":"mcm","clk":"5306635537","pt":1646102535613,"mc":[{"id":"1.195395426","rc":[{"atb":[[2.02,8.68]],"id":36104892},{"atb":[[1.11,0]],"id":43154454}],"con":true,"img":false}]}
{"op":"mcm","clk":"5306635573","pt":1646102536531,"mc":[{"id":"1.195395426","rc":[{"atb":[[2.02,15.98]],"id":36104892},{"atb":[[1.45,18.55]],"id":42189480}],"con":true,"img":false}]}
{"op":"mcm","clk":"5306635627","pt":1646102538121,"mc":[{"id":"1.195395426","rc":[{"atb":[[1.4,0]],"id":42189480}],"con":true,"img":false}]}
{"op":"mcm","clk":"5306635658","pt":1646102539039,"mc":[{"id":"1.195395426","rc":[{"atb":[[1.2,188.14]],"id":43154454}],"con":true,"img":false}]}
{"op":"mcm","clk":"5306635740","pt":1646102541141,"mc":[{"id":"1.195395426","rc":[{"atb":[[1.2,253.99]],"id":43154454}],"con":true,"img":false}]}
{"op":"mcm","clk":"5306635782","pt":1646102542525,"mc":[{"id":"1.195395426","rc":[{"atb":[[1.46,16.2]],"id":42189480}],"con":true,"img":false}]}
{"op":"mcm","clk":"5306635841","pt":1646102543908,"mc":[{"id":"1.195395426","rc":[{"atb":[[1.46,29.18]],"id":42189480}],"con":true,"img":false}]}
{"op":"mcm","clk":"5306635868","pt":1646102544729,"mc":[{"id":"1.195395426","rc":[{"atb":[[1.43,0]],"id":42189480}],"con":true,"img":false}]}
{"op":"mcm","clk":"5306635910","pt":1646102545651,"mc":[{"id":"1.195395426","rc":[{"atb":[[1.46,12.98]],"id":42189480}],"con":true,"img":false}]}
{"op":"mcm","clk":"5306635932","pt":1646102546318,"mc":[{"id":"1.195395426","rc":[{"atb":[[2,0]],"id":36104892}],"con":true,"img":false}]}
{"op":"mcm","clk":"5306636084","pt":1646102548655,"mc":[{"id":"1.195395426","rc":[{"atb":[[1.43,38.95]],"id":42189480}],"con":true,"img":false}]}
{"op":"mcm","clk":"5306636111","pt":1646102549119,"mc":[{"id":"1.195395426","rc":[{"atb":[[2.02,8.97]],"id":36104892}],"con":true,"img":false}]}
{"op":"mcm","clk":"5306636239","pt":1646102551627,"mc":[{"id":"1.195395426","rc":[{"atb":[[1.45,35.11]],"id":42189480}],"con":true,"img":false}]}
{"op":"mcm","clk":"5306636256","pt":1646102552034,"mc":[{"id":"1.195395426","rc":[{"atb":[[2.02,17.15]],"id":36104892}],"con":true,"img":false}]}
{"op":"mcm","clk":"5306636382","pt":1646102554752,"mc":[{"id":"1.195395426","rc":[{"atb":[[1.98,9.86]],"id":36104892}],"con":true,"img":false}]}
{"op":"mcm","clk":"5306636534","pt":1646102558235,"mc":[{"id":"1.195395426","rc":[{"atb":[[1.97,0]],"id":36104892}],"con":true,"img":false}]}
{"op":"mcm","clk":"5306636643","pt":1646102560645,"mc":[{"id":"1.195395426","rc":[{"atb":[[2.02,9.85]],"id":36104892}],"con":true,"img":false}]}
{"op":"mcm","clk":"5306636709","pt":1646102562074,"mc":[{"id":"1.195395426","rc":[{"atb":[[1.99,46.82]],"id":36104892}],"con":true,"img":false}]}
{"op":"mcm","clk":"5306636727","pt":1646102562333,"mc":[{"id":"1.195395426","rc":[{"atb":[[1.98,0]],"id":36104892}],"con":true,"img":false}]}
{"op":"mcm","clk":"5306636981","pt":1646102568069,"mc":[{"id":"1.195395426","rc":[{"atb":[[1.97,11.82]],"id":36104892},{"atl":[[42,0]],"id":39318320},{"atl":[[110,0]],"id":38256919}],"con":true,"img":false}]}
{"op":"mcm","clk":"5306636989","pt":1646102568172,"mc":[{"id":"1.195395426","rc":[{"atl":[[38,3.03]],"id":39318320},{"atl":[[140,2.08],[95,2.7]],"id":38256919}],"con":true,"img":false}]}
{"op":"mcm","clk":"5306636993","pt":1646102568274,"mc":[{"id":"1.195395426","rc":[{"atl":[[95,4.7],[100,0.43]],"id":38256919}],"con":true,"img":false}]}
{"op":"mcm","clk":"5306636999","pt":1646102568377,"mc":[{"id":"1.195395426","rc":[{"atl":[[140,0.08]],"id":38256919}],"con":true,"img":false}]}
{"op":"mcm","clk":"5306637065","pt":1646102569661,"mc":[{"id":"1.195395426","rc":[{"atb":[[2.04,7.17]],"id":36104892}],"con":true,"img":false}]}
{"op":"mcm","clk":"5306637156","pt":1646102571354,"mc":[{"id":"1.195395426","rc":[{"atb":[[1.99,0]],"id":36104892}],"con":true,"img":false}]}
{"op":"mcm","clk":"5306637186","pt":1646102572171,"mc":[{"id":"1.195395426","rc":[{"atb":[[2.02,8.18]],"id":36104892}],"con":true,"img":false}]}
{"op":"mcm","clk":"5306637190","pt":1646102572272,"mc":[{"id":"1.195395426","rc":[{"atb":[[2.06,1.66]],"id":36104892}],"con":true,"img":false}]}
{"op":"mcm","clk":"5306637204","pt":1646102572578,"mc":[{"id":"1.195395426","rc":[{"atb":[[2.04,0]],"id":36104892}],"con":true,"img":false}]}
{"op":"mcm","clk":"5306637215","pt":1646102572783,"mc":[{"id":"1.195395426","rc":[{"atb":[[1.97,0]],"id":36104892}],"con":true,"img":false}]}
{"op":"mcm","clk":"5306637339","pt":1646102575150,"mc":[{"id":"1.195395426","rc":[{"atb":[[1.97,6.26]],"id":36104892}],"con":true,"img":false}]}
{"op":"mcm","clk":"5306637390","pt":1646102576378,"mc":[{"id":"1.195395426","rc":[{"atb":[[2.02,0]],"id":36104892}],"con":true,"img":false}]}
{"op":"mcm","clk":"5306637479","pt":1646102578174,"mc":[{"id":"1.195395426","rc":[{"atb":[[1.98,10.83]],"id":36104892}],"con":true,"img":false}]}
{"op":"mcm","clk":"5306637500","pt":1646102578584,"mc":[{"id":"1.195395426","rc":[{"atb":[[2,7.45]],"id":36104892}],"con":true,"img":false}]}
{"op":"mcm","clk":"5306637517","pt":1646102579097,"mc":[{"id":"1.195395426","rc":[{"atb":[[2.06,0]],"id":36104892}],"con":true,"img":false}]}
{"op":"mcm","clk":"5306637524","pt":1646102579199,"mc":[{"id":"1.195395426","rc":[{"atb":[[2.02,1.66]],"id":36104892}],"con":true,"img":false}]}
{"op":"mcm","clk":"5306637605","pt":1646102580996,"mc":[{"id":"1.195395426","rc":[{"atb":[[1.97,0]],"id":36104892}],"con":true,"img":false}]}
{"op":"mcm","clk":"5306637787","pt":1646102584990,"mc":[{"id":"1.195395426","rc":[{"atb":[[2.04,3.33]],"id":36104892}],"con":true,"img":false}]}
{"op":"mcm","clk":"5306637798","pt":1646102585195,"mc":[{"id":"1.195395426","rc":[{"atb":[[1.19,0]],"id":43154454},{"atl":[[95,2]],"id":38256919}],"con":true,"img":false}]}
{"op":"mcm","clk":"5306637803","pt":1646102585297,"mc":[{"id":"1.195395426","rc":[{"atb":[[1.21,94.07]],"id":43154454},{"atl":[[95,0],[100,2.43],[110,2.7]],"id":38256919}],"con":true,"img":false}]}
{"op":"mcm","clk":"5306637825","pt":1646102585706,"mc":[{"id":"1.195395426","rc":[{"atl":[[9.2,3.33],[10.5,0]],"id":38859241},{"atl":[[2.54,64.94],[2.78,0]],"id":43154454},{"atl":[[36,2.71],[40,0]],"id":39318320}],"con":true,"img":false}]}
{"op":"mcm","clk":"5306637850","pt":1646102586170,"mc":[{"id":"1.195395426","rc":[{"atb":[[1.98,0]],"id":36104892}],"con":true,"img":false}]}
{"op":"mcm","clk":"5306637947","pt":1646102588375,"mc":[{"id":"1.195395426","rc":[{"atb":[[2,15.8]],"id":36104892},{"spn":3.27,"spf":"NaN","id":36104892},{"spn":1.71,"spf":"NaN","id":43154454},{"spn":2.0,"spf":"NaN","id":42189480}],"con":true,"img":false}]}
{"op":"mcm","clk":"5306637966","pt":1646102588681,"mc":[{"id":"1.195395426","rc":[{"atb":[[1.2,188.14]],"id":43154454}],"con":true,"img":false}]}
{"op":"mcm","clk":"5306637971","pt":1646102588790,"mc":[{"id":"1.195395426","rc":[{"atb":[[1.2,0]],"id":43154454}],"con":true,"img":false}]}
{"op":"mcm","clk":"5306638072","pt":1646102591089,"mc":[{"id":"1.195395426","rc":[{"atb":[[2.02,0]],"id":36104892}],"con":true,"img":false}]}
{"op":"mcm","clk":"5306638085","pt":1646102591295,"mc":[{"id":"1.195395426","rc":[{"atb":[[2.06,1.66]],"id":36104892}],"con":true,"img":false}]}
{"op":"mcm","clk":"5306638092","pt":1646102591501,"mc":[{"id":"1.195395426","rc":[{"atb":[[1.97,4.33]],"id":36104892}],"con":true,"img":false}]}
{"op":"mcm","clk":"5306638140","pt":1646102592680,"mc":[{"id":"1.195395426","rc":[{"atb":[[1.17,272.65]],"id":43154454}],"con":true,"img":false}]}
{"op":"mcm","clk":"5306638228","pt":1646102594477,"mc":[{"id":"1.195395426","rc":[{"atb":[[1.17,385.54]],"id":43154454}],"con":true,"img":false}]}
{"op":"mcm","clk":"5306638234","pt":1646102594574,"mc":[{"id":"1.195395426","rc":[{"atb":[[2.04,0]],"id":36104892}],"con":true,"img":false}]}
{"op":"mcm","clk":"5306638338","pt":1646102597087,"mc":[{"id":"1.195395426","rc":[{"atb":[[2.06,0]],"id":36104892}],"con":true,"img":false}]}
{"op":"mcm","clk":"5306638340","pt":1646102597189,"mc":[{"id":"1.195395426","rc":[{"atb":[[2.02,1.66]],"id":36104892}],"con":true,"img":false}]}
{"op":"mcm","clk":"5306638385","pt":1646102598419,"mc":[{"id":"1.195395426","rc":[{"atb":[[1.98,5.84]],"id":36104892}],"con":true,"img":false}]}
{"op":"mcm","clk":"5306638555","pt":1646102602010,"mc":[{"id":"1.195395426","rc":[{"atb":[[1.97,0]],"id":36104892}],"con":true,"img":false}]}
{"op":"mcm","clk":"5306638613","pt":1646102603391,"mc":[{"id":"1.195395426","rc":[{"atb":[[1.21,0]],"id":43154454}],"con":true,"img":false}]}
{"op":"mcm","clk":"5306638617","pt":1646102603493,"mc":[{"id":"1.195395426","rc":[{"atb":[[1.19,94.07]],"id":43154454}],"con":true,"img":false}]}
{"op":"mcm","clk":"5306638772","pt":1646102607385,"mc":[{"id":"1.195395426","rc":[{"atb":[[2.02,13.9]],"id":36104892}],"con":true,"img":false}]}
{"op":"mcm","clk":"5306639234","pt":1646102620054,"mc":[{"id":"1.195395426","rc":[{"atl":[[9.2,0],[10.5,4.87]],"id":38859241},{"atl":[[2.54,0],[2.78,56.18]],"id":43154454}],"con":true,"img":false}]}
{"op":"mcm","clk":"5306640098","pt":1646102633576,"mc":[{"id":"1.195395426","rc":[{"atb":[[1.85,0],[1.9,0],[1.95,0]],"id":36104892},{"atl":[[5.6,0],[7.2,0],[4.6,0],[9.2,0],[13,0]],"id":36104892},{"atb":[[3.1,0],[3.35,0],[2.94,0]],"id":38859241},{"atl":[[17,0],[38,0],[12,0],[24,0],[8.8,0]],"id":38859241},{"atb":[[1.15,0],[1.1,0],[1.05,0]],"id":43154454},{"atl":[[2.82,0],[2.22,35.47],[2.42,0],[2.62,0],[3.05,0]],"id":43154454},{"atb":[[5.8,0],[5.3,0],[6.6,0]],"id":39318320},{"atl":[[70,0],[140,0],[38,2.7],[24,0],[240,0]],"id":39318320},{"atb":[[4,0],[4.5,0],[5,0]],"id":43154455},{"atl":[[17,0],[70,0],[140,0],[38,0],[24,0]],"id":43154455},{"atb":[[9.8,0],[8.8,0],[7.8,0]],"id":38256919},{"atl":[[70,0],[140,0],[340,0],[440,0],[240,0]],"id":38256919},{"atb":[[1.2,0],[1.25,0],[1.3,0]],"id":42189480},{"atl":[[2.54,0],[3.85,0],[2.74,0],[3.35,0],[2.94,0]],"id":42189480}],"con":true,"img":false}]}
{"op":"mcm","clk":"5306640105","pt":1646102633728,"mc":[{"id":"1.195395426","rc":[{"atl":[[4.5,0],[5.8,8.93]],"id":36104892},{"atl":[[10.5,0],[13.5,8]],"id":38859241},{"atl":[[36,0],[40,2.56]],"id":39318320},{"atl":[[100,0.43],[110,4.7]],"id":38256919}],"con":true,"img":false}]}
{"op":"mcm","clk":"5306640205","pt":1646102635883,"mc":[{"id":"1.195395426","rc":[{"atb":[[1.85,141.32],[1.9,133.47],[1.95,63.22]],"id":36104892},{"atl":[[5.6,0.11],[7.2,0.69],[4.6,0.15]],"id":36104892},{"atb":[[3.45,3.4],[3.1,57.19],[3.35,25.55],[2.94,61.91]],"id":38859241},{"atl":[[17,0.27],[12,0.04],[8.8,0.07]],"id":38859241},{"atb":[[1.15,400.41],[1.1,1201.23],[1.05,2402.46]],"id":43154454},{"atl":[[2.22,35.92],[2.42,0.37],[2.62,2.67]],"id":43154454},{"atb":[[5.8,25.02],[5.3,27.93],[6.6,10.72]],"id":39318320},{"atl":[[70,0.06],[38,2.72],[24,0.02]],"id":39318320},{"atb":[[4,40.04],[4.5,34.32],[5,15.01]],"id":43154455},{"atl":[[17,0.03],[38,0.11],[24,0.02]],"id":43154455},{"atb":[[9.8,6.82],[8.8,15.39],[7.8,17.66]],"id":38256919},{"atl":[[70,0],[140,0],[240,0.01]],"id":38256919},{"atb":[[1.2,600.61],[1.25,480.49],[1.3,200.2]],"id":42189480},{"atl":[[2.54,0.35],[2.74,0.3],[2.94,2.22]],"id":42189480}],"con":true,"img":false}]}
{"op":"mcm","clk":"5306640286","pt":1646102637366,"mc":[{"id":"1.195395426","rc":[{"atb":[[1.98,0]],"id":36104892},{"atb":[[1.43,0]],"id":42189480}],"con":true,"img":false}]}
{"op":"mcm","clk":"5306640398","pt":1646102639365,"mc":[{"id":"1.195395426","rc":[{"atl":[[2.92,0]],"id":42189480}],"con":true,"img":false}]}
{"op":"mcm","clk":"5306640407","pt":1646102639571,"mc":[{"id":"1.195395426","rc":[{"atl":[[3.8,0]],"id":42189480}],"con":true,"img":false}]}
{"op":"mcm","clk":"5306640412","pt":1646102639622,"mc":[{"id":"1.195395426","rc":[{"atl":[[4.1,19.23]],"id":42189480}],"con":true,"img":false}]}
{"op":"mcm","clk":"5306640431","pt":1646102640133,"mc":[{"id":"1.195395426","rc":[{"atb":[[2.02,1.66]],"id":36104892},{"atb":[[1.46,0]],"id":42189480}],"con":true,"img":false}]}
{"op":"mcm","clk":"5306640486","pt":1646102641263,"mc":[{"id":"1.195395426","rc":[{"atb":[[1.97,45.17]],"id":36104892},{"atb":[[1.43,38.95]],"id":42189480}],"con":true,"img":false}]}
{"op":"mcm","clk":"5306640520","pt":1646102641930,"mc":[{"id":"1.195395426","rc":[{"atb":[[2,8.34]],"id":36104892}],"con":true,"img":false}]}
{"op":"mcm","clk":"5306640653","pt":1646102644754,"mc":[{"id":"1.195395426","rc":[{"atb":[[3.45,6.44]],"id":38859241}],"con":true,"img":false}]}
{"op":"mcm","clk":"5306640699","pt":1646102645729,"mc":[{"id":"1.195395426","rc":[{"atb":[[2.02,8.68]],"id":36104892},{"atb":[[1.46,24.58]],"id":42189480}],"con":true,"img":false}]}
{"op":"mcm","clk":"5306640811","pt":1646102647883,"mc":[{"id":"1.195395426","rc":[{"atb":[[2.02,15.98]],"id":36104892}],"con":true,"img":false}]}
{"op":"mcm","clk":"5306640854","pt":1646102648552,"mc":[{"id":"1.195395426","rc":[{"spn":3.31,"spf":"NaN","id":36104892},{"spn":1.7,"spf":"NaN","id":43154454},{"atb":[[1.43,0]],"id":42189480}],"con":true,"img":false}]}
{"op":"mcm","clk":"5306641054","pt":1646102652348,"mc":[{"id":"1.195395426","rc":[{"atb":[[1.43,73.74]],"id":42189480}],"con":true,"img":false}]}
{"op":"mcm","clk":"5306641093","pt":1646102653061,"mc":[{"id":"1.195395426","rc":[{"atb":[[1.46,0]],"id":42189480}],"con":true,"img":false}]}
{"op":"mcm","clk":"5306641135","pt":1646102653879,"mc":[{"id":"1.195395426","rc":[{"atb":[[1.45,18.55]],"id":42189480}],"con":true,"img":false}]}
{"op":"mcm","clk":"5306641172","pt":1646102654492,"mc":[{"id":"1.195395426","rc":[{"atb":[[2,0]],"id":36104892},{"atb":[[1.45,0]],"id":42189480}],"con":true,"img":false}]}
{"op":"mcm","clk":"5306641352","pt":1646102657874,"mc":[{"id":"1.195395426","rc":[{"atl":[[14,0]],"id":38859241}],"con":true,"img":false}]}
{"op":"mcm","clk":"5306641357","pt":1646102657974,"mc":[{"id":"1.195395426","rc":[{"atl":[[13,3.32]],"id":38859241},{"atb":[[1.43,0]],"id":42189480}],"con":true,"img":false}]}
{"op":"mcm","clk":"5306641374","pt":1646102658384,"mc":[{"id":"1.195395426","rc":[{"atb":[[2.02,8.97]],"id":36104892},{"atb":[[1.39,87.03]],"id":42189480}],"con":true,"img":false}]}
{"op":"mcm","clk":"5306641500","pt":1646102660897,"mc":[{"id":"1.195395426","rc":[{"atb":[[2.02,17.15]],"id":36104892}],"con":true,"img":false}]}
{"op":"mcm","clk":"5306641541","pt":1646102661766,"mc":[{"id":"1.195395426","rc":[{"atb":[[1.43,107.79]],"id":42189480}],"con":true,"img":false}]}
{"op":"mcm","clk":"5306641618","pt":1646102663402,"mc":[{"id":"1.195395426","rc":[{"atb":[[1.98,9.86]],"id":36104892}],"con":true,"img":false}]}
{"op":"mcm","clk":"5306641707","pt":1646102665508,"mc":[{"id":"1.195395426","rc":[{"atb":[[1.97,0]],"id":36104892}],"con":true,"img":false}]}
{"op":"mcm","clk":"5306641732","pt":1646102665968,"mc":[{"id":"1.195395426","rc":[{"atb":[[2.02,9.85]],"id":36104892},{"atb":[[1.39,0]],"id":42189480}],"con":true,"img":false}]}
{"op":"mcm","clk":"5306641858","pt":1646102668779,"mc":[{"id":"1.195395426","rc":[{"atb":[[1.46,16.2]],"id":42189480}],"con":true,"img":false}]}
{"op":"mcm","clk":"5306641871","pt":1646102669086,"mc":[{"id":"1.195395426","rc":[{"atb":[[1.43,0]],"id":42189480}],"con":true,"img":false}]}
{"op":"mcm","clk":"5306641955","pt":1646102671088,"mc":[{"id":"1.195395426","rc":[{"atb":[[1.99,27.09]],"id":36104892}],"con":true,"img":false}]}
{"op":"mcm","clk":"5306641967","pt":1646102671288,"mc":[{"id":"1.195395426","rc":[{"atb":[[1.39,87.03]],"id":42189480}],"con":true,"img":false}]}
{"op":"mcm","clk":"5306641999","pt":1646102671905,"mc":[{"id":"1.195395426","rc":[{"atb":[[2,7.45]],"id":36104892},{"atb":[[1.46,0]],"id":42189480}],"con":true,"img":false}]}
{"op":"mcm","clk":"5306642069","pt":1646102672989,"mc":[{"id":"1.195395426","rc":[{"atb":[[1.39,151.84]],"id":42189480}],"con":true,"img":false}]}
{"op":"mcm","clk":"5306642108","pt":1646102673704,"mc":[{"id":"1.195395426","rc":[{"atb":[[1.98,0]],"id":36104892}],"con":true,"img":false}]}
{"op":"mcm","clk":"5306642158","pt":1646102674677,"mc":[{"id":"1.195395426","rc":[{"atl":[[3.7,16.03]],"id":42189480}],"con":true,"img":false}]}
{"op":"mcm","clk":"5306642161","pt":1646102674780,"mc":[{"id":"1.195395426","rc":[{"atl":[[5.9,0]],"id":36104892}],"con":true,"img":false}]}
{"op":"mcm","clk":"5306642164","pt":1646102674881,"mc":[{"id":"1.195395426","rc":[{"atb":[[1.99,0]],"id":36104892},{"atl":[[5.7,8.83]],"id":36104892}],"con":true,"img":false}]}
{"op":"mcm","clk":"5306642169","pt":1646102674985,"mc":[{"id":"1.195395426","rc":[{"atl":[[5.6,8.95],[5.8,0]],"id":36104892}],"con":true,"img":false}]}
{"op":"mcm","clk":"5306642256","pt":1646102677902,"mc":[{"id":"1.195395426","rc":[{"atb":[[1.45,16.56]],"id":42189480}],"con":true,"img":false}]}
{"op":"mcm","clk":"5306642287","pt":1646102678718,"mc":[{"id":"1.195395426","rc":[{"atb":[[2.02,1.66],[1.97,32.02]],"id":36104892}],"con":true,"img":false}]}
{"op":"mcm","clk":"5306642308","pt":1646102679178,"mc":[{"id":"1.195395426","rc":[{"atb":[[1.97,43.84]],"id":36104892}],"con":true,"img":false}]}
{"op":"mcm","clk":"5306642364","pt":1646102680506,"mc":[{"id":"1.195395426","rc":[{"atb":[[1.39,87.03]],"id":42189480}],"con":true,"img":false}]}
{"op":"mcm","clk":"5306642377","pt":1646102680923,"mc":[{"id":"1.195395426","rc":[{"atb":[[2,0]],"id":36104892}],"con":true,"img":false}]}
{"op":"mcm","clk":"5306642410","pt":1646102681985,"mc":[{"id":"1.195395426","rc":[{"atb":[[1.39,0]],"id":42189480}],"con":true,"img":false}]}
{"op":"mcm","clk":"5306642482","pt":1646102684330,"mc":[{"id":"1.195395426","rc":[{"atb":[[1.97,32.02]],"id":36104892},{"atb":[[1.39,62.1]],"id":42189480}],"con":true,"img":false}]}
{"op":"mcm","clk":"5306642489","pt":1646102684586,"mc":[{"id":"1.195395426","rc":[{"atb":[[1.45,35.11]],"id":42189480}],"con":true,"img":false}]}
{"op":"mcm","clk":"5306642555","pt":1646102687092,"mc":[{"id":"1.195395426","rc":[{"atb":[[2.02,0]],"id":36104892}],"con":true,"img":false}]}
{"op":"mcm","clk":"5306642564","pt":1646102687396,"mc":[{"id":"1.195395426","rc":[{"atb":[[1.39,85.28]],"id":42189480}],"con":true,"img":false}]}
{"op":"mcm","clk":"5306642635","pt":1646102689898,"mc":[{"id":"1.195395426","rc":[{"atb":[[1.97,0]],"id":36104892}],"con":true,"img":false}]}
{"op":"mcm","clk":"5306642643","pt":1646102690100,"mc":[{"id":"1.195395426","rc":[{"atb":[[1.98,22.41]],"id":36104892}],"con":true,"img":false}]}
{"op":"mcm","clk":"5306642750","pt":1646102692920,"mc":[{"id":"1.195395426","rc":[{"atb":[[2,7.45]],"id":36104892},{"atb":[[1.16,0]],"id":43154454}],"con":true,"img":false}]}
{"op":"mcm","clk":"5306642756","pt":1646102693014,"mc":[{"id":"1.195395426","rc":[{"atb":[[1.18,378.76]],"id":43154454}],"con":true,"img":false}]}
{"op":"mcm","clk":"5306642792","pt":1646102693736,"mc":[{"id":"1.195395426","rc":[{"atb":[[1.99,44.83]],"id":36104892}],"con":true,"img":false}]}
{"op":"mcm","clk":"5306642863","pt":1646102695628,"mc":[{"id":"1.195395426","rc":[{"atb":[[1.17,112.88]],"id":43154454}],"con":true,"img":false}]}
{"op":"mcm","clk":"5306642874","pt":1646102696038,"mc":[{"id":"1.195395426","rc":[{"atb":[[2,0]],"id":36104892}],"con":true,"img":false}]}
{"op":"mcm","clk":"5306642925","pt":1646102697420,"mc":[{"id":"1.195395426","rc":[{"atb":[[1.99,0]],"id":36104892}],"con":true,"img":false}]}
{"op":"mcm","clk":"5306642931","pt":1646102697623,"mc":[{"id":"1.195395426","rc":[{"atb":[[1.98,0]],"id":36104892},{"atb":[[1.17,0]],"id":43154454}],"con":true,"img":false}]}
{"op":"mcm","clk":"5306642975","pt":1646102699316,"mc":[{"id":"1.195395426","rc":[{"atb":[[1.2,188.14]],"id":43154454}],"con":true,"img":false}]}
{"op":"mcm","clk":"5306643050","pt":1646102701365,"mc":[{"id":"1.195395426","rc":[{"atb":[[1.91,50.93]],"id":36104892}],"con":true,"img":false}]}
{"op":"mcm","clk":"5306643126","pt":1646102703057,"mc":[{"id":"1.195395426","rc":[{"atb":[[1.91,88.23]],"id":36104892},{"atb":[[1.21,131.7]],"id":43154454}],"con":true,"img":false}]}
{"op":"mcm","clk":"5306643205","pt":1646102704940,"mc":[{"id":"1.195395426","rc":[{"atb":[[2,7.45]],"id":36104892}],"con":true,"img":false}]}
{"op":"mcm","clk":"5306643303","pt":1646102706842,"mc":[{"id":"1.195395426","rc":[{"atb":[[1.2,0]],"id":43154454}],"con":true,"img":false}]}
{"op":"mcm","clk":"5306643352","pt":1646102707966,"mc":[{"id":"1.195395426","rc":[{"atb":[[1.91,50.93]],"id":36104892}],"con":true,"img":false}]}
{"op":"mcm","clk":"5306643389","pt":1646102708679,"mc":[{"id":"1.195395426","rc":[{"atb":[[1.91,0]],"id":36104892},{"spn":3.3,"spf":"NaN","id":36104892},{"spn":1.71,"spf":"NaN","id":43154454},{"spn":1.99,"spf":"NaN","id":42189480}],"con":true,"img":false}]}
{"op":"mcm","clk":"5306643424","pt":1646102709344,"mc":[{"id":"1.195395426","rc":[{"atb":[[1.18,0]],"id":43154454}],"con":true,"img":false}]}
{"op":"mcm","clk":"5306643431","pt":1646102709445,"mc":[{"id":"1.195395426","rc":[{"atb":[[1.16,378.76]],"id":43154454}],"con":true,"img":false}]}
{"op":"mcm","clk":"5306643485","pt":1646102710675,"mc":[{"id":"1.195395426","rc":[{"atb":[[1.22,210.68]],"id":43154454}],"con":true,"img":false}]}
{"op":"mcm","clk":"5306643500","pt":1646102711017,"mc":[{"id":"1.195395426","rc":[{"atb":[[2.02,1.66]],"id":36104892}],"con":true,"img":false}]}
{"op":"mcm","clk":"5306643554","pt":1646102712565,"mc":[{"id":"1.195395426","rc":[{"atb":[[1.97,22.35]],"id":36104892}],"con":true,"img":false}]}
{"op":"mcm","clk":"5306643592","pt":1646102713521,"mc":[{"id":"1.195395426","rc":[{"atb":[[1.97,30.55]],"id":36104892},{"atb":[[1.21,0]],"id":43154454}],"con":true,"img":false}]}
{"op":"mcm","clk":"5306643617","pt":1646102714644,"mc":[{"id":"1.195395426","rc":[{"atb":[[2,15.8]],"id":36104892}],"con":true,"img":false}]}
{"op":"mcm","clk":"5306643666","pt":1646102716328,"mc":[{"id":"1.195395426","rc":[{"atb":[[1.97,8.19]],"id":36104892},{"atb":[[1.22,0]],"id":43154454}],"con":true,"img":false}]}
{"op":"mcm","clk":"5306643690","pt":1646102717042,"mc":[{"id":"1.195395426","rc":[{"atb":[[1.17,199.65]],"id":43154454}],"con":true,"img":false}]}
{"op":"mcm","clk":"5306643806","pt":1646102720260,"mc":[{"id":"1.195395426","rc":[{"atb":[[1.98,5]],"id":36104892},{"atb":[[1.2,188.14]],"id":43154454}],"con":true,"img":false}]}
{"op":"mcm","clk":"5306643960","pt":1646102724448,"mc":[{"id":"1.195395426","rc":[{"atb":[[1.97,0]],"id":36104892},{"atb":[[1.17,0]],"id":43154454}],"con":true,"img":false}]}
{"op":"mcm","clk":"5306644068","pt":1646102727468,"mc":[{"id":"1.195395426","rc":[{"atb":[[1.2,0]],"id":43154454}],"con":true,"img":false}]}
{"op":"mcm","clk":"5306644082","pt":1646102727775,"mc":[{"id":"1.195395426","rc":[{"atl":[[5.7,0]],"id":36104892},{"atb":[[1.38,201.29]],"id":42189480}],"con":true,"img":false}]}
{"op":"mcm","clk":"5306644088","pt":1646102727879,"mc":[{"id":"1.195395426","rc":[{"atl":[[6.4,9.11],[5.5,8.83]],"id":36104892},{"atb":[[1.4,138.04]],"id":42189480}],"con":true,"img":false}]}
{"op":"mcm","clk":"5306644093","pt":1646102727980,"mc":[{"id":"1.195395426","rc":[{"atl":[[5.6,0.11],[6.4,0],[5.4,8.96]],"id":36104892}],"con":true,"img":false}]}
{"op":"mcm","clk":"5306644176","pt":1646102729974,"mc":[{"id":"1.195395426","rc":[{"atb":[[2.02,13.9]],"id":36104892},{"atb":[[1.17,199.65]],"id":43154454}],"con":true,"img":false}]}
{"op":"mcm","clk":"5306644215","pt":1646102731249,"mc":[{"id":"1.195395426","rc":[{"atb":[[1.98,0]],"id":36104892},{"atb":[[1.2,188.14]],"id":43154454},{"atb":[[1.39,23.18]],"id":42189480}],"con":true,"img":false}]}
{"op":"mcm","clk":"5306644246","pt":1646102732678,"mc":[{"id":"1.195395426","rc":[{"atb":[[1.39,0]],"id":42189480}],"con":true,"img":false}]}
{"op":"mcm","clk":"5306644357","pt":1646102734978,"mc":[{"id":"1.195395426","rc":[{"atb":[[2.02,1.66]],"id":36104892},{"atb":[[1.17,0]],"id":43154454}],"con":true,"img":false}]}
{"op":"mcm","clk":"5306644364","pt":1646102735181,"mc":[{"id":"1.195395426","rc":[{"atb":[[1.97,45.17]],"id":36104892},{"atb":[[1.43,96.55]],"id":42189480}],"con":true,"img":false}]}
{"op":"mcm","clk":"5306644419","pt":1646102736969,"mc":[{"id":"1.195395426","rc":[{"atb":[[1.2,0]],"id":43154454}],"con":true,"img":false}]}
{"op":"mcm","clk":"5306644455","pt":1646102737893,"mc":[{"id":"1.195395426","rc":[{"atb":[[1.43,131.66]],"id":42189480}],"con":true,"img":false}]}
{"op":"mcm","clk":"5306644459","pt":1646102737995,"mc":[{"id":"1.195395426","rc":[{"atb":[[2,8.34]],"id":36104892},{"atb":[[1.45,18.55]],"id":42189480}],"con":true,"img":false}]}
{"op":"mcm","clk":"5306644541","pt":1646102740757,"mc":[{"id":"1.195395426","rc":[{"atb":[[1.2,188.14]],"id":43154454}],"con":true,"img":false}]}
{"op":"mcm","clk":"5306644555","pt":1646102741065,"mc":[{"id":"1.195395426","rc":[{"atb":[[2.02,13.9]],"id":36104892},{"atb":[[1.2,253.99]],"id":43154454}],"con":true,"img":false}]}
{"op":"mcm","clk":"5306644606","pt":1646102742700,"mc":[{"id":"1.195395426","rc":[{"atb":[[2.64,0],[2.48,56.75]],"id":38859241},{"atl":[[2.44,69.44],[2.78,0]],"id":43154454},{"atb":[[4.1,22.14],[2.66,0]],"id":39318320},{"atb":[[2.8,0],[1.39,37.08]],"id":43154455},{"atb":[[1.29,0],[1.69,13.84]],"id":38256919},{"atb":[[1.46,105.58],[1.38,0]],"id":42189480}],"con":true,"img":false}]}
{"op":"mcm","clk":"5306644658","pt":1646102744080,"mc":[{"id":"1.195395426","rc":[{"atb":[[2.02,21.2]],"id":36104892}],"con":true,"img":false}]}
{"op":"mcm","clk":"5306644682","pt":1646102744800,"mc":[{"id":"1.195395426","rc":[{"atb":[[1.4,0],[1.34,173.67]],"id":42189480}],"con":true,"img":false}]}
{"op":"mcm","clk":"5306644724","pt":1646102746173,"mc":[{"id":"1.195395426","rc":[{"atb":[[1.43,96.55]],"id":42189480}],"con":true,"img":false}]}
{"op":"mcm","clk":"5306644728","pt":1646102746276,"mc":[{"id":"1.195395426","rc":[{"atb":[[1.43,0]],"id":42189480}],"con":true,"img":false}]}
{"op":"mcm","clk":"5306644842","pt":1646102750012,"mc":[{"id":"1.195395426","rc":[{"atb":[[1.43,107.79]],"id":42189480}],"con":true,"img":false}]}
{"op":"mcm","clk":"5306644846","pt":1646102750113,"mc":[{"id":"1.195395426","rc":[{"atb":[[1.49,15.21]],"id":42189480}],"con":true,"img":false}]}
{"op":"mcm","clk":"5306644880","pt":1646102751491,"mc":[{"id":"1.195395426","rc":[{"atb":[[2,0]],"id":36104892},{"atb":[[1.45,0],[1.43,186.73]],"id":42189480}],"con":true,"img":false}]}
{"op":"mcm","clk":"5306644984","pt":1646102753911,"mc":[{"id":"1.195395426","rc":[{"atb":[[2.02,8.97]],"id":36104892}],"con":true,"img":false}]}
{"op":"mcm","clk":"5306645133","pt":1646102757799,"mc":[{"id":"1.195395426","rc":[{"atb":[[2.02,17.15]],"id":36104892}],"con":true,"img":false}]}
{"op":"mcm","clk":"5306645139","pt":1646102757900,"mc":[{"id":"1.195395426","rc":[{"atb":[[1.49,32.25]],"id":42189480}],"con":true,"img":false}]}
{"op":"mcm","clk":"5306645171","pt":1646102759026,"mc":[{"id":"1.195395426","rc":[{"atb":[[1.98,9.86]],"id":36104892}],"con":true,"img":false}]}
{"op":"mcm","clk":"5306645263","pt":1646102761543,"mc":[{"id":"1.195395426","rc":[{"atb":[[1.42,0]],"id":42189480}],"con":true,"img":false}]}
{"op":"mcm","clk":"5306645266","pt":1646102761637,"mc":[{"id":"1.195395426","rc":[{"atb":[[1.47,105.57]],"id":42189480}],"con":true,"img":false}]}
{"op":"mcm","clk":"5306645295","pt":1646102762300,"mc":[{"id":"1.195395426","rc":[{"atb":[[1.49,17.04]],"id":42189480}],"con":true,"img":false}]}
{"op":"mcm","clk":"5306645308","pt":1646102762708,"mc":[{"id":"1.195395426","rc":[{"atb":[[1.97,0]],"id":36104892}],"con":true,"img":false}]}
{"op":"mcm","clk":"5306645376","pt":1646102764447,"mc":[{"id":"1.195395426","rc":[{"atb":[[1.43,78.93]],"id":42189480}],"con":true,"img":false}]}
{"op":"mcm","clk":"5306645403","pt":1646102765217,"mc":[{"id":"1.195395426","rc":[{"atb":[[2.02,9.85]],"id":36104892}],"con":true,"img":false}]}
{"op":"mcm","clk":"5306645440","pt":1646102766340,"mc":[{"id":"1.195395426","rc":[{"atb":[[1.99,46.82]],"id":36104892}],"con":true,"img":false}]}
{"op":"mcm","clk":"5306645479","pt":1646102767109,"mc":[{"id":"1.195395426","rc":[{"atb":[[1.98,0]],"id":36104892},{"atb":[[1.43,0]],"id":42189480}],"con":true,"img":false}]}
{"op":"mcm","clk":"5306645521","pt":1646102768333,"mc":[{"id":"1.195395426","rc":[{"atb":[[1.5,34.07]],"id":42189480}],"con":true,"img":false}]}
{"op":"mcm","clk":"5306645559","pt":1646102769460,"mc":[{"id":"1.195395426","rc":[{"spn":3.31,"spf":"NaN","id":36104892},{"spn":1.71,"spf":"NaN","id":43154454},{"atb":[[1.5,48.98]],"id":42189480},{"spn":2.02,"spf":"NaN","id":42189480}],"con":true,"img":false}]}
{"op":"mcm","clk":"5306645655","pt":1646102772326,"mc":[{"id":"1.195395426","rc":[{"atb":[[1.97,11.82]],"id":36104892},{"atb":[[1.51,23.85]],"id":42189480}],"con":true,"img":false}]}
{"op":"mcm","clk":"5306645763","pt":1646102774937,"mc":[{"id":"1.195395426","rc":[{"atb":[[1.49,0]],"id":42189480}],"con":true,"img":false}]}
{"op":"mcm","clk":"5306645793","pt":1646102775652,"mc":[{"id":"1.195395426","rc":[{"atb":[[1.99,0]],"id":36104892},{"atb":[[1.5,14.9]],"id":42189480}],"con":true,"img":false}]}
{"op":"mcm","clk":"5306645871","pt":1646102777644,"mc":[{"id":"1.195395426","rc":[{"atb":[[2.74,56.75],[2.48,0]],"id":38859241},{"atl":[[2.44,0],[2.2,35.92]],"id":43154454},{"atb":[[5,22.14],[4.1,0]],"id":39318320},{"atb":[[2.04,37.08],[1.39,0]],"id":43154455},{"atb":[[1.46,0],[1.52,23.85]],"id":42189480}],"con":true,"img":false}]}
{"op":"mcm","clk":"5306645904","pt":1646102778460,"mc":[{"id":"1.195395426","rc":[{"atb":[[1.19,0]],"id":43154454},{"atb":[[1.47,0]],"id":42189480}],"con":true,"img":false}]}
{"op":"mcm","clk":"5306645908","pt":1646102778562,"mc":[{"id":"1.195395426","rc":[{"atb":[[1.21,94.07]],"id":43154454},{"atb":[[1.42,105.57]],"id":42189480}],"con":true,"img":false}]}
{"op":"mcm","clk":"5306645950","pt":1646102779433,"mc":[{"id":"1.195395426","rc":[{"atb":[[1.5,0]],"id":42189480}],"con":true,"img":false}]}
{"op":"mcm","clk":"5306645955","pt":1646102779536,"mc":[{"id":"1.195395426","rc":[{"atb":[[1.98,29.55]],"id":36104892},{"atb":[[1.51,0],[1.48,71.55]],"id":42189480}],"con":true,"img":false}]}
{"op":"mcm","clk":"5306645960","pt":1646102779636,"mc":[{"id":"1.195395426","rc":[{"atb":[[1.49,105.58],[1.52,0]],"id":42189480}],"con":true,"img":false}]}
{"op":"mcm","clk":"5306646019","pt":1646102781224,"mc":[{"id":"1.195395426","rc":[{"atb":[[1.2,65.84]],"id":43154454}],"con":true,"img":false}]}
{"op":"mcm","clk":"5306646048","pt":1646102781735,"mc":[{"id":"1.195395426","rc":[{"atb":[[2.02,1.66]],"id":36104892}],"con":true,"img":false}]}
{"op":"mcm","clk":"5306646052","pt":1646102781838,"mc":[{"id":"1.195395426","rc":[{"atb":[[1.2,0]],"id":43154454}],"con":true,"img":false}]}
{"op":"mcm","clk":"5306646063","pt":1646102782255,"mc":[{"id":"1.195395426","rc":[{"atb":[[2,7.45]],"id":36104892}],"con":true,"img":false}]}
{"op":"mcm","clk":"5306646108","pt":1646102783226,"mc":[{"id":"1.195395426","rc":[{"atb":[[1.48,0]],"id":42189480}],"con":true,"img":false}]}
{"op":"mcm","clk":"5306646146","pt":1646102784448,"mc":[{"id":"1.195395426","rc":[{"atb":[[1.43,78.93]],"id":42189480}],"con":true,"img":false}]}
{"op":"mcm","clk":"5306646152","pt":1646102784755,"mc":[{"id":"1.195395426","rc":[{"atb":[[1.44,211.16]],"id":42189480}],"con":true,"img":false}]}
{"op":"mcm","clk":"5306646156","pt":1646102784858,"mc":[{"id":"1.195395426","rc":[{"atb":[[1.49,0]],"id":42189480}],"con":true,"img":false}]}
{"op":"mcm","clk":"5306646170","pt":1646102785164,"mc":[{"id":"1.195395426","rc":[{"atb":[[1.98,0]],"id":36104892},{"atb":[[1.17,272.65]],"id":43154454}],"con":true,"img":false}]}
{"op":"mcm","clk":"5306646185","pt":1646102785622,"mc":[{"id":"1.195395426","rc":[{"atl":[[2.2,0],[2.26,71.84]],"id":43154454}],"con":true,"img":false}]}
{"op":"mcm","clk":"5306646230","pt":1646102787153,"mc":[{"id":"1.195395426","rc":[{"atb":[[1.45,103]],"id":42189480}],"con":true,"img":false}]}
{"op":"mcm","clk":"5306646235","pt":1646102787358,"mc":[{"id":"1.195395426","rc":[{"atb":[[1.97,0]],"id":36104892},{"atb":[[1.17,385.54]],"id":43154454}],"con":true,"img":false}]}
{"op":"mcm","clk":"5306646301","pt":1646102789151,"mc":[{"id":"1.195395426","rc":[{"atb":[[1.98,5]],"id":36104892}],"con":true,"img":false}]}
{"op":"mcm","clk":"5306646344","pt":1646102790531,"mc":[{"id":"1.195395426","rc":[{"atb":[[1.97,10.03]],"id":36104892}],"con":true,"img":false}]}
{"op":"mcm","clk":"5306646445","pt":1646102792942,"mc":[{"id":"1.195395426","rc":[{"atb":[[2,15.8]],"id":36104892}],"con":true,"img":false}]}
{"op":"mcm","clk":"5306646501","pt":1646102794581,"mc":[{"id":"1.195395426","rc":[{"atb":[[1.48,15.52]],"id":42189480}],"con":true,"img":false}]}
{"op":"mcm","clk":"5306646522","pt":1646102795347,"mc":[{"id":"1.195395426","rc":[{"atb":[[1.97,0]],"id":36104892}],"con":true,"img":false}]}
{"op":"mcm","clk":"5306646528","pt":1646102795552,"mc":[{"id":"1.195395426","rc":[{"atb":[[1.21,0]],"id":43154454}],"con":true,"img":false}]}
{"op":"mcm","clk":"5306646530","pt":1646102795653,"mc":[{"id":"1.195395426","rc":[{"atb":[[1.19,94.07]],"id":43154454}],"con":true,"img":false}]}
{"op":"mcm","clk":"5306646594","pt":1646102797856,"mc":[{"id":"1.195395426","rc":[{"atb":[[1.43,0]],"id":42189480}],"con":true,"img":false}]}
{"op":"mcm","clk":"5306646602","pt":1646102798165,"mc":[{"id":"1.195395426","rc":[{"atb":[[1.45,0]],"id":42189480}],"con":true,"img":false}]}
{"op":"mcm","clk":"5306646678","pt":1646102800367,"mc":[{"id":"1.195395426","rc":[{"atb":[[1.48,0]],"id":42189480}],"con":true,"img":false}]}
{"op":"mcm","clk":"5306646681","pt":1646102800467,"mc":[{"id":"1.195395426","rc":[{"atb":[[1.44,0],[1.43,232.56]],"id":42189480}],"con":true,"img":false}]}
{"op":"mcm","clk":"5306646685","pt":1646102800571,"mc":[{"id":"1.195395426","rc":[{"atb":[[2.02,13.9]],"id":36104892}],"con":true,"img":false}]}
{"op":"mcm","clk":"5306646725","pt":1646102801872,"mc":[{"id":"1.195395426","rc":[{"atb":[[1.45,46.57]],"id":42189480}],"con":true,"img":false}]}
{"op":"mcm","clk":"5306654528","pt":1646102803197,"mc":[{"id":"1.195395426","rc":[{"atb":[[1.35,96.97]],"id":42189480}],"con":true,"img":false}]}
{"op":"mcm","clk":"5306654781","pt":1646102808278,"mc":[{"id":"1.195395426","rc":[{"atb":[[1.35,0]],"id":42189480}],"con":true,"img":false}]}
{"op":"mcm","clk":"5306654824","pt":1646102809402,"mc":[{"id":"1.195395426","rc":[{"atb":[[1.46,16.2]],"id":42189480}],"con":true,"img":false}]}
{"op":"mcm","clk":"5306654980","pt":1646102812988,"mc":[{"id":"1.195395426","rc":[{"atb":[[1.45,0]],"id":42189480}],"con":true,"img":false}]}
{"op":"mcm","clk":"5306654992","pt":1646102813399,"mc":[{"id":"1.195395426","rc":[{"atb":[[1.47,11.34]],"id":42189480}],"con":true,"img":false}]}
{"op":"mcm","clk":"5306655102","pt":1646102816668,"mc":[{"id":"1.195395426","rc":[{"atb":[[1.44,34.03]],"id":42189480}],"con":true,"img":false}]}
{"op":"mcm","clk":"5306655126","pt":1646102817386,"mc":[{"id":"1.195395426","rc":[{"atb":[[1.46,34.35]],"id":42189480}],"con":true,"img":false}]}
{"op":"mcm","clk":"5306655591","pt":1646102829261,"mc":[{"id":"1.195395426","rc":[{"atb":[[1.42,0]],"id":42189480}],"con":true,"img":false}]}
{"op":"mcm","clk":"5306655596","pt":1646102829365,"mc":[{"id":"1.195395426","rc":[{"atb":[[1.44,139.61]],"id":42189480}],"con":true,"img":false}]}
{"op":"mcm","clk":"5306655641","pt":1646102830539,"mc":[{"id":"1.195395426","rc":[{"spn":1.7,"spf":"NaN","id":43154454},{"atb":[[1.46,18.15]],"id":42189480},{"spn":2.0,"spf":"NaN","id":42189480}],"con":true,"img":false}]}
{"op":"mcm","clk":"5306655808","pt":1646102834783,"mc":[{"id":"1.195395426","rc":[{"atb":[[1.48,18.15]],"id":42189480}],"con":true,"img":false}]}
{"op":"mcm","clk":"5306655812","pt":1646102834884,"mc":[{"id":"1.195395426","rc":[{"atb":[[1.43,0]],"id":42189480}],"con":true,"img":false}]}
{"op":"mcm","clk":"5306655887","pt":1646102836474,"mc":[{"id":"1.195395426","rc":[{"atb":[[1.47,27.2]],"id":42189480}],"con":true,"img":false}]}
{"op":"mcm","clk":"5306655935","pt":1646102837755,"mc":[{"id":"1.195395426","rc":[{"atb":[[1.47,15.86]],"id":42189480}],"con":true,"img":false}]}
{"op":"mcm","clk":"5306655960","pt":1646102838368,"mc":[{"id":"1.195395426","rc":[{"atb":[[1.44,105.57]],"id":42189480}],"con":true,"img":false}]}
{"op":"mcm","clk":"5306656142","pt":1646102842263,"mc":[{"id":"1.195395426","rc":[{"atb":[[1.49,36.29]],"id":42189480}],"con":true,"img":false}]}
{"op":"mcm","clk":"5306656145","pt":1646102842365,"mc":[{"id":"1.195395426","rc":[{"atb":[[1.5,18.15],[1.48,0]],"id":42189480}],"con":true,"img":false}]}
{"op":"mcm","clk":"5306656162","pt":1646102842877,"mc":[{"id":"1.195395426","rc":[{"atb":[[1.49,49]],"id":42189480}],"con":true,"img":false}]}
{"op":"mcm","clk":"5306656233","pt":1646102844769,"mc":[{"id":"1.195395426","rc":[{"atl":[[2.2,43.29]],"id":43154454}],"con":true,"img":false}]}
{"op":"mcm","clk":"5306656236","pt":1646102844872,"mc":[{"id":"1.195395426","rc":[{"atl":[[2.26,0]],"id":43154454}],"con":true,"img":false}]}
{"op":"mcm","clk":"5306656260","pt":1646102845484,"mc":[{"id":"1.195395426","rc":[{"atb":[[1.16,0]],"id":43154454},{"atb":[[1.47,0]],"id":42189480}],"con":true,"img":false}]}
{"op":"mcm","clk":"5306656264","pt":1646102845585,"mc":[{"id":"1.195395426","rc":[{"atb":[[1.18,378.76]],"id":43154454}],"con":true,"img":false}]}
{"op":"mcm","clk":"5306656277","pt":1646102845997,"mc":[{"id":"1.195395426","rc":[{"atb":[[1.49,12.7]],"id":42189480}],"con":true,"img":false}]}
{"op":"mcm","clk":"5306656339","pt":1646102847791,"mc":[{"id":"1.195395426","rc":[{"atb":[[1.17,112.88]],"id":43154454}],"con":true,"img":false}]}
{"op":"mcm","clk":"5306656350","pt":1646102848102,"mc":[{"id":"1.195395426","rc":[{"atb":[[1.49,0]],"id":42189480}],"con":true,"img":false}]}
{"op":"mcm","clk":"5306656358","pt":1646102848301,"mc":[{"id":"1.195395426","rc":[{"atb":[[1.5,0],[1.47,105.58]],"id":42189480}],"con":true,"img":false}]}
{"op":"mcm","clk":"5306656408","pt":1646102849684,"mc":[{"id":"1.195395426","rc":[{"atb":[[1.47,160.02]],"id":42189480}],"con":true,"img":false}]}
{"op":"mcm","clk":"5306656456","pt":1646102850655,"mc":[{"id":"1.195395426","rc":[{"atb":[[1.17,0]],"id":43154454}],"con":true,"img":false}]}
{"op":"mcm","clk":"5306656463","pt":1646102850961,"mc":[{"id":"1.195395426","rc":[{"atb":[[1.46,0]],"id":42189480}],"con":true,"img":false}]}
{"op":"mcm","clk":"5306656494","pt":1646102851676,"mc":[{"id":"1.195395426","rc":[{"atb":[[1.2,188.14]],"id":43154454}],"con":true,"img":false}]}
{"op":"mcm","clk":"5306656558","pt":1646102853468,"mc":[{"id":"1.195395426","rc":[{"atb":[[1.48,70.71]],"id":42189480}],"con":true,"img":false}]}
{"op":"mcm","clk":"5306656562","pt":1646102853569,"mc":[{"id":"1.195395426","rc":[{"atb":[[1.49,105.58],[1.47,0]],"id":42189480}],"con":true,"img":false}]}
{"op":"mcm","clk":"5306656667","pt":1646102856384,"mc":[{"id":"1.195395426","rc":[{"atb":[[1.21,131.7]],"id":43154454}],"con":true,"img":false}]}
{"op":"mcm","clk":"5306656714","pt":1646102857486,"mc":[{"id":"1.195395426","rc":[{"atb":[[1.45,103]],"id":42189480}],"con":true,"img":false}]}
{"op":"mcm","clk":"5306656757","pt":1646102858768,"mc":[{"id":"1.195395426","rc":[{"atb":[[1.48,0]],"id":42189480}],"con":true,"img":false}]}
{"op":"mcm","clk":"5306656762","pt":1646102858870,"mc":[{"id":"1.195395426","rc":[{"atb":[[1.46,211.16],[1.49,0]],"id":42189480}],"con":true,"img":false}]}
{"op":"mcm","clk":"5306656780","pt":1646102859281,"mc":[{"id":"1.195395426","rc":[{"atb":[[1.2,0]],"id":43154454}],"con":true,"img":false}]}
{"op":"mcm","clk":"5306656794","pt":1646102859694,"mc":[{"id":"1.195395426","rc":[{"atl":[[2.2,0],[2.26,79.21]],"id":43154454}],"con":true,"img":false}]}
{"op":"mcm","clk":"5306656904","pt":1646102862818,"mc":[{"id":"1.195395426","rc":[{"atb":[[1.18,0]],"id":43154454}],"con":true,"img":false}]}
{"op":"mcm","clk":"5306656906","pt":1646102862921,"mc":[{"id":"1.195395426","rc":[{"atb":[[1.16,378.76]],"id":43154454}],"con":true,"img":false}]}
{"op":"mcm","clk":"5306656909","pt":1646102863023,"mc":[{"id":"1.195395426","rc":[{"atb":[[1.22,210.68]],"id":43154454}],"con":true,"img":false}]}
{"op":"mcm","clk":"5306656930","pt":1646102863687,"mc":[{"id":"1.195395426","rc":[{"atb":[[1.47,72.21]],"id":42189480}],"con":true,"img":false}]}
{"op":"mcm","clk":"5306657029","pt":1646102866293,"mc":[{"id":"1.195395426","rc":[{"atb":[[1.21,0]],"id":43154454}],"con":true,"img":false}]}
{"op":"mcm","clk":"5306657047","pt":1646102866702,"mc":[{"id":"1.195395426","rc":[{"atb":[[1.45,0]],"id":42189480}],"con":true,"img":false}]}
{"op":"mcm","clk":"5306657126","pt":1646102868493,"mc":[{"id":"1.195395426","rc":[{"atb":[[1.22,0]],"id":43154454}],"con":true,"img":false}]}
{"op":"mcm","clk":"5306657194","pt":1646102870384,"mc":[{"id":"1.195395426","rc":[{"atb":[[1.48,96.56]],"id":42189480}],"con":true,"img":false}]}
{"op":"mcm","clk":"5306657222","pt":1646102871408,"mc":[{"id":"1.195395426","rc":[{"atb":[[1.2,65.84]],"id":43154454}],"con":true,"img":false}]}
{"op":"mcm","clk":"5306657264","pt":1646102872384,"mc":[{"id":"1.195395426","rc":[{"atb":[[1.2,253.99]],"id":43154454}],"con":true,"img":false}]}
{"op":"mcm","clk":"5306657312","pt":1646102873714,"mc":[{"id":"1.195395426","rc":[{"atb":[[1.47,0]],"id":42189480}],"con":true,"img":false}]}
{"op":"mcm","clk":"5306657383","pt":1646102876118,"mc":[{"id":"1.195395426","rc":[{"atb":[[1.48,0]],"id":42189480}],"con":true,"img":false}]}
{"op":"mcm","clk":"5306657387","pt":1646102876222,"mc":[{"id":"1.195395426","rc":[{"atb":[[1.46,0],[1.45,222.22]],"id":42189480}],"con":true,"img":false}]}
{"op":"mcm","clk":"5306657487","pt":1646102878988,"mc":[{"id":"1.195395426","rc":[{"atb":[[1.44,0],[1.49,67.59]],"id":42189480}],"con":true,"img":false}]}
{"op":"mcm","clk":"5306657492","pt":1646102879091,"mc":[{"id":"1.195395426","rc":[{"atb":[[1.46,105.57]],"id":42189480}],"con":true,"img":false}]}
{"op":"mcm","clk":"5306657515","pt":1646102879910,"mc":[{"id":"1.195395426","rc":[{"atb":[[1.35,132.43]],"id":42189480}],"con":true,"img":false}]}
{"op":"mcm","clk":"5306657678","pt":1646102883514,"mc":[{"id":"1.195395426","rc":[{"atb":[[1.35,0]],"id":42189480}],"con":true,"img":false}]}
{"op":"mcm","clk":"5306657829","pt":1646102887208,"mc":[{"id":"1.195395426","rc":[{"atb":[[1.5,92.7]],"id":42189480}],"con":true,"img":false}]}
{"op":"mcm","clk":"5306657993","pt":1646102891605,"mc":[{"id":"1.195395426","rc":[{"spn":1.71,"spf":"NaN","id":43154454},{"atb":[[1.49,0]],"id":42189480},{"spn":2.02,"spf":"NaN","id":42189480}],"con":true,"img":false}]}
{"op":"mcm","clk":"5306658097","pt":1646102893454,"mc":[{"id":"1.195395426","rc":[{"atl":[[2.26,0],[2.2,43.29]],"id":43154454}],"con":true,"img":false}]}
{"op":"mcm","clk":"5306658100","pt":1646102893556,"mc":[{"id":"1.195395426","rc":[{"atb":[[1.53,14.06]],"id":42189480}],"con":true,"img":false}]}
{"op":"mcm","clk":"5306658143","pt":1646102894430,"mc":[{"id":"1.195395426","rc":[{"atb":[[1.5,0]],"id":42189480}],"con":true,"img":false}]}
{"op":"mcm","clk":"5306658186","pt":1646102895348,"mc":[{"id":"1.195395426","rc":[{"atb":[[1.19,0]],"id":43154454}],"con":true,"img":false}]}
{"op":"mcm","clk":"5306658189","pt":1646102895450,"mc":[{"id":"1.195395426","rc":[{"atb":[[1.21,94.07]],"id":43154454}],"con":true,"img":false}]}
{"op":"mcm","clk":"5306658224","pt":1646102896219,"mc":[{"id":"1.195395426","rc":[{"atb":[[1.2,65.84]],"id":43154454}],"con":true,"img":false}]}
{"op":"mcm","clk":"5306658238","pt":1646102896628,"mc":[{"id":"1.195395426","rc":[{"atb":[[1.2,0]],"id":43154454},{"atb":[[1.53,0],[1.47,19.69]],"id":42189480}],"con":true,"img":false}]}
{"op":"mcm","clk":"5306658295","pt":1646102898162,"mc":[{"id":"1.195395426","rc":[{"atb":[[1.47,72.43]],"id":42189480}],"con":true,"img":false}]}
{"op":"mcm","clk":"5306658387","pt":1646102900159,"mc":[{"id":"1.195395426","rc":[{"atb":[[1.17,272.65]],"id":43154454}],"con":true,"img":false}]}
{"op":"mcm","clk":"5306658457","pt":1646102901649,"mc":[{"id":"1.195395426","rc":[{"atb":[[1.17,385.54]],"id":43154454},{"atb":[[1.47,52.73]],"id":42189480}],"con":true,"img":false}]}
{"op":"mcm","clk":"5306658634","pt":1646102905550,"mc":[{"id":"1.195395426","rc":[{"atb":[[1.5,14.9]],"id":42189480}],"con":true,"img":false}]}
{"op":"mcm","clk":"5306658738","pt":1646102907457,"mc":[{"id":"1.195395426","rc":[{"atb":[[1.48,36.91]],"id":42189480}],"con":true,"img":false}]}
{"op":"mcm","clk":"5306658821","pt":1646102909765,"mc":[{"id":"1.195395426","rc":[{"atb":[[1.45,0],[1.51,36.92]],"id":42189480}],"con":true,"img":false}]}
{"op":"mcm","clk":"5306658878","pt":1646102911147,"mc":[{"id":"1.195395426","rc":[{"atb":[[1.47,0]],"id":42189480}],"con":true,"img":false}]}
{"op":"mcm","clk":"5306658888","pt":1646102911351,"mc":[{"id":"1.195395426","rc":[{"atb":[[1.21,0]],"id":43154454}],"con":true,"img":false}]}
{"op":"mcm","clk":"5306658894","pt":1646102911455,"mc":[{"id":"1.195395426","rc":[{"atb":[[1.19,94.07]],"id":43154454}],"con":true,"img":false}]}
{"op":"mcm","clk":"5306658903","pt":1646102911660,"mc":[{"id":"1.195395426","rc":[{"atb":[[1.5,0]],"id":42189480}],"con":true,"img":false}]}
{"op":"mcm","clk":"5306658930","pt":1646102912276,"mc":[{"id":"1.195395426","rc":[{"atb":[[1.48,0]],"id":42189480}],"con":true,"img":false}]}
{"op":"mcm","clk":"5306659043","pt":1646102914886,"mc":[{"id":"1.195395426","rc":[{"atb":[[1.47,173.68]],"id":42189480}],"con":true,"img":false}]}
{"op":"mcm","clk":"5306659048","pt":1646102914987,"mc":[{"id":"1.195395426","rc":[{"atb":[[1.51,0],[1.35,132.43]],"id":42189480}],"con":true,"img":false}]}
{"op":"mcm","clk":"5306659162","pt":1646102917449,"mc":[{"id":"1.195395426","rc":[{"atb":[[1.35,221.05]],"id":42189480}],"con":true,"img":false}]}
{"op":"mcm","clk":"5306659196","pt":1646102918474,"mc":[{"id":"1.195395426","rc":[{"atl":[[2.2,0],[2.26,79.21]],"id":43154454}],"con":true,"img":false}]}
{"op":"mcm","clk":"5306659414","pt":1646102923701,"mc":[{"id":"1.195395426","rc":[{"atb":[[1.5,14.9]],"id":42189480}],"con":true,"img":false}]}
{"op":"mcm","clk":"5306659498","pt":1646102925803,"mc":[{"id":"1.195395426","rc":[{"atb":[[1.35,88.61]],"id":42189480}],"con":true,"img":false}]}
{"op":"mcm","clk":"5306659563","pt":1646102927389,"mc":[{"id":"1.195395426","rc":[{"atb":[[1.35,0]],"id":42189480}],"con":true,"img":false}]}
{"op":"mcm","clk":"5306659642","pt":1646102929590,"mc":[{"id":"1.195395426","rc":[{"atb":[[1.51,29.81]],"id":42189480}],"con":true,"img":false}]}
{"op":"mcm","clk":"5306659726","pt":1646102931562,"mc":[{"id":"1.195395426","rc":[{"atb":[[1.5,31.6]],"id":42189480}],"con":true,"img":false}]}
{"op":"mcm","clk":"5306659767","pt":1646102932690,"mc":[{"id":"1.195395426","rc":[{"atb":[[1.48,32.79]],"id":42189480}],"con":true,"img":false}]}
{"op":"mcm","clk":"5306660050","pt":1646102940423,"mc":[{"id":"1.195395426","rc":[{"atb":[[1.23,250]],"id":36104892},{"atb":[[1.23,250]],"id":38859241},{"atb":[[1.23,250]],"id":39318320},{"atb":[[1.23,250]],"id":43154455},{"atb":[[1.23,250]],"id":38256919}],"con":true,"img":false}]}
{"op":"mcm","clk":"5306660169","pt":1646102942991,"mc":[{"id":"1.195395426","rc":[{"atb":[[1.52,31.61]],"id":42189480}],"con":true,"img":false}]}
{"op":"mcm","clk":"5306660174","pt":1646102943095,"mc":[{"id":"1.195395426","rc":[{"atb":[[1.47,0]],"id":42189480}],"con":true,"img":false}]}
{"op":"mcm","clk":"5306660185","pt":1646102943403,"mc":[{"id":"1.195395426","rc":[{"atb":[[1.46,0]],"id":42189480}],"con":true,"img":false}]}
{"op":"mcm","clk":"5306660189","pt":1646102943505,"mc":[{"id":"1.195395426","rc":[{"atb":[[1.41,105.57]],"id":42189480}],"con":true,"img":false}]}
{"op":"mcm","clk":"5306660235","pt":1646102944892,"mc":[{"id":"1.195395426","rc":[{"atb":[[1.5,16.69]],"id":42189480}],"con":true,"img":false}]}
{"op":"mcm","clk":"5306660274","pt":1646102946020,"mc":[{"id":"1.195395426","rc":[{"atb":[[1.51,0]],"id":42189480}],"con":true,"img":false}]}
{"op":"mcm","clk":"5306660333","pt":1646102947709,"mc":[{"id":"1.195395426","rc":[{"atb":[[1.48,0]],"id":42189480}],"con":true,"img":false}]}
{"op":"mcm","clk":"5306660343","pt":1646102948119,"mc":[{"id":"1.195395426","rc":[{"atb":[[1.51,105.58],[1.52,0]],"id":42189480}],"con":true,"img":false}]}
{"op":"mcm","clk":"5306660397","pt":1646102949809,"mc":[{"id":"1.195395426","rc":[{"atb":[[1.42,110.35]],"id":42189480}],"con":true,"img":false}]}
{"op":"mcm","clk":"5306660474","pt":1646102951600,"mc":[{"id":"1.195395426","rc":[{"atl":[[2.26,0],[2.2,43.29]],"id":43154454}],"con":true,"img":false}]}
{"op":"mcm","clk":"5306660538","pt":1646102953133,"mc":[{"id":"1.195395426","rc":[{"spn":1.69,"spf":"NaN","id":43154454},{"atb":[[1.43,78.93]],"id":42189480},{"spn":2.02,"spf":"NaN","id":42189480}],"con":true,"img":false}]}
{"op":"mcm","clk":"5306660630","pt":1646102955338,"mc":[{"id":"1.195395426","rc":[{"atb":[[1.42,0]],"id":42189480}],"con":true,"img":false}]}
{"op":"mcm","clk":"5306660704","pt":1646102956832,"mc":[{"id":"1.195395426","rc":[{"atb":[[1.54,13.8]],"id":42189480}],"con":true,"img":false}]}
{"op":"mcm","clk":"5306660806","pt":1646102959035,"mc":[{"id":"1.195395426","rc":[{"atb":[[1.55,27.6]],"id":42189480}],"con":true,"img":false}]}
{"op":"mcm","clk":"5306660832","pt":1646102959653,"mc":[{"id":"1.195395426","rc":[{"atb":[[1.16,0]],"id":43154454}],"con":true,"img":false}]}
{"op":"mcm","clk":"5306660835","pt":1646102959754,"mc":[{"id":"1.195395426","rc":[{"atb":[[1.18,378.76]],"id":43154454}],"con":true,"img":false}]}
{"op":"mcm","clk":"5306660879","pt":1646102960853,"mc":[{"id":"1.195395426","rc":[{"atb":[[1.43,0]],"id":42189480}],"con":true,"img":false}]}
{"op":"mcm","clk":"5306660910","pt":1646102961418,"mc":[{"id":"1.195395426","rc":[{"atb":[[1.5,0]],"id":42189480}],"con":true,"img":false}]}
{"op":"mcm","clk":"5306660972","pt":1646102962862,"mc":[{"id":"1.195395426","rc":[{"atb":[[1.17,112.88]],"id":43154454}],"con":true,"img":false}]}
{"op":"mcm","clk":"5306660990","pt":1646102963431,"mc":[{"id":"1.195395426","rc":[{"atb":[[1.17,0]],"id":43154454}],"con":true,"img":false}]}
{"op":"mcm","clk":"5306661090","pt":1646102966147,"mc":[{"id":"1.195395426","rc":[{"atb":[[1.52,30.36]],"id":42189480}],"con":true,"img":false}]}
{"op":"mcm","clk":"5306661099","pt":1646102966454,"mc":[{"id":"1.195395426","rc":[{"atb":[[1.16,282.22]],"id":43154454}],"con":true,"img":false}]}
{"op":"mcm","clk":"5306661155","pt":1646102967939,"mc":[{"id":"1.195395426","rc":[{"atb":[[1.54,29.26]],"id":42189480}],"con":true,"img":false}]}
{"op":"mcm","clk":"5306661193","pt":1646102968859,"mc":[{"id":"1.195395426","rc":[{"atb":[[1.16,385.7]],"id":43154454}],"con":true,"img":false}]}
{"op":"mcm","clk":"5306661451","pt":1646102975374,"mc":[{"id":"1.195395426","rc":[{"atb":[[1.18,0]],"id":43154454}],"con":true,"img":false}]}
{"op":"mcm","clk":"5306661455","pt":1646102975477,"mc":[{"id":"1.195395426","rc":[{"atb":[[1.17,378.76]],"id":43154454}],"con":true,"img":false}]}
{"op":"mcm","clk":"5306661519","pt":1646102977167,"mc":[{"id":"1.195395426","rc":[{"atb":[[1.23,0]],"id":36104892},{"atb":[[1.23,0]],"id":38859241},{"atb":[[1.23,0]],"id":39318320},{"atb":[[1.23,0]],"id":43154455},{"atb":[[1.23,0]],"id":38256919}],"con":true,"img":false}]}
{"op":"mcm","clk":"5306661553","pt":1646102977987,"mc":[{"id":"1.195395426","rc":[{"atb":[[1.23,250]],"id":36104892},{"atb":[[1.23,250]],"id":38859241},{"atb":[[1.23,250]],"id":39318320},{"atb":[[1.23,250]],"id":43154455},{"atb":[[1.23,250]],"id":38256919}],"con":true,"img":false}]}
{"op":"mcm","clk":"5306661593","pt":1646102978860,"mc":[{"id":"1.195395426","rc":[{"atb":[[1.16,282.22]],"id":43154454}],"con":true,"img":false}]}
{"op":"mcm","clk":"5306661611","pt":1646102979166,"mc":[{"id":"1.195395426","rc":[{"atb":[[1.16,0]],"id":43154454}],"con":true,"img":false}]}
{"op":"mcm","clk":"5306661698","pt":1646102980969,"mc":[{"id":"1.195395426","rc":[{"atb":[[1.56,29.27],[1.51,0]],"id":42189480}],"con":true,"img":false}]}
{"op":"mcm","clk":"5306661810","pt":1646102983180,"mc":[{"id":"1.195395426","rc":[{"atb":[[1.2,188.14]],"id":43154454},{"atb":[[1.55,0]],"id":42189480}],"con":true,"img":false}]}
{"op":"mcm","clk":"5306661842","pt":1646102983849,"mc":[{"id":"1.195395426","rc":[{"atb":[[1.54,15.46]],"id":42189480}],"con":true,"img":false}]}
{"op":"mcm","clk":"5306661882","pt":1646102984773,"mc":[{"id":"1.195395426","rc":[{"atb":[[1.2,253.99]],"id":43154454},{"atb":[[1.52,0]],"id":42189480}],"con":true,"img":false}]}
{"op":"mcm","clk":"5306661937","pt":1646102986058,"mc":[{"id":"1.195395426","rc":[{"atb":[[1.56,0],[1.55,105.58]],"id":42189480}],"con":true,"img":false}]}
{"op":"mcm","clk":"5306661967","pt":1646102986882,"mc":[{"id":"1.195395426","rc":[{"atb":[[1.42,110.35]],"id":42189480}],"con":true,"img":false}]}
{"op":"mcm","clk":"5306662116","pt":1646102990071,"mc":[{"id":"1.195395426","rc":[{"atb":[[1.43,78.93]],"id":42189480}],"con":true,"img":false}]}
{"op":"mcm","clk":"5306662175","pt":1646102991359,"mc":[{"id":"1.195395426","rc":[{"atl":[[2.22,0.44]],"id":43154454},{"atb":[[1.41,0]],"id":42189480}],"con":true,"img":false}]}
{"op":"mcm","clk":"5306662179","pt":1646102991462,"mc":[{"id":"1.195395426","rc":[{"atl":[[2.38,43.73],[2.18,35.47],[2.2,0]],"id":43154454},{"atb":[[1.44,105.57]],"id":42189480}],"con":true,"img":false}]}
{"op":"mcm","clk":"5306662244","pt":1646102992387,"mc":[{"id":"1.195395426","rc":[{"atb":[[1.42,0]],"id":42189480}],"con":true,"img":false}]}
{"op":"mcm","clk":"5306662278","pt":1646102992800,"mc":[{"id":"1.195395426","rc":[{"atb":[[1.59,12.63]],"id":42189480}],"con":true,"img":false}]}
{"op":"mcm","clk":"5306662368","pt":1646102994398,"mc":[{"id":"1.195395426","rc":[{"atb":[[1.54,0]],"id":42189480}],"con":true,"img":false}]}
{"op":"mcm","clk":"5306662401","pt":1646102995067,"mc":[{"id":"1.195395426","rc":[{"atb":[[1.43,0]],"id":42189480}],"con":true,"img":false}]}
{"op":"mcm","clk":"5306662461","pt":1646102996200,"mc":[{"id":"1.195395426","rc":[{"atb":[[1.56,37.89]],"id":42189480}],"con":true,"img":false}]}
{"op":"mcm","clk":"5306662605","pt":1646103000098,"mc":[{"id":"1.195395426","rc":[{"atb":[[1.6,8.83]],"id":42189480}],"con":true,"img":false}]}
{"op":"mcm","clk":"5306662620","pt":1646103000406,"mc":[{"id":"1.195395426","rc":[{"atb":[[1.59,26.78]],"id":42189480}],"con":true,"img":false}]}
{"op":"mcm","clk":"5306662741","pt":1646103003488,"mc":[{"id":"1.195395426","rc":[{"atb":[[1.56,0]],"id":42189480}],"con":true,"img":false}]}
{"op":"mcm","clk":"5306662928","pt":1646103007285,"mc":[{"id":"1.195395426","rc":[{"atb":[[1.56,28.72]],"id":42189480}],"con":true,"img":false}]}
{"op":"mcm","clk":"5306662965","pt":1646103008003,"mc":[{"id":"1.195395426","rc":[{"atb":[[1.6,0]],"id":42189480}],"con":true,"img":false}]}
{"op":"mcm","clk":"5306663195","pt":1646103013487,"mc":[{"id":"1.195395426","rc":[{"spn":1.69,"spf":"NaN","id":43154454},{"atb":[[1.6,18.75]],"id":42189480},{"spn":2.07,"spf":"NaN","id":42189480}],"con":true,"img":false}]}
{"op":"mcm","clk":"5306663306","pt":1646103016510,"mc":[{"id":"1.195395426","rc":[{"atb":[[1.56,0]],"id":42189480}],"con":true,"img":false}]}
{"op":"mcm","clk":"5306663389","pt":1646103018512,"mc":[{"id":"1.195395426","rc":[{"atb":[[1.55,0],[1.61,26.79]],"id":42189480}],"con":true,"img":false}]}
{"op":"mcm","clk":"5306663443","pt":1646103019894,"mc":[{"id":"1.195395426","rc":[{"atb":[[1.59,14.15]],"id":42189480}],"con":true,"img":false}]}
{"op":"mcm","clk":"5306663458","pt":1646103020304,"mc":[{"id":"1.195395426","rc":[{"atb":[[1.56,60.94]],"id":42189480}],"con":true,"img":false}]}
{"op":"mcm","clk":"5306663474","pt":1646103020818,"mc":[{"id":"1.195395426","rc":[{"atb":[[1.6,0]],"id":42189480}],"con":true,"img":false}]}
{"op":"mcm","clk":"5306663477","pt":1646103020919,"mc":[{"id":"1.195395426","rc":[{"atb":[[1.6,60.95],[1.61,0]],"id":42189480}],"con":true,"img":false}]}
{"op":"mcm","clk":"5306663576","pt":1646103023336,"mc":[{"id":"1.195395426","rc":[{"atb":[[1.19,0]],"id":43154454},{"atl":[[2.4,0]],"id":43154454}],"con":true,"img":false}]}
{"op":"mcm","clk":"5306663581","pt":1646103023438,"mc":[{"id":"1.195395426","rc":[{"atb":[[1.21,94.07]],"id":43154454},{"atl":[[2.36,43.28]],"id":43154454}],"con":true,"img":false}]}
{"op":"mcm","clk":"5306663601","pt":1646103023898,"mc":[{"id":"1.195395426","rc":[{"atl":[[2.38,0],[2.16,35.48]],"id":43154454}],"con":true,"img":false}]}
{"op":"mcm","clk":"5306663689","pt":1646103025803,"mc":[{"id":"1.195395426","rc":[{"atb":[[1.2,65.84]],"id":43154454}],"con":true,"img":false}]}
{"op":"mcm","clk":"5306663714","pt":1646103026417,"mc":[{"id":"1.195395426","rc":[{"atb":[[1.2,0]],"id":43154454},{"atb":[[1.57,59.54]],"id":42189480}],"con":true,"img":false}]}
{"op":"mcm","clk":"5306663813","pt":1646103028829,"mc":[{"id":"1.195395426","rc":[{"atb":[[1.64,11.64]],"id":42189480}],"con":true,"img":false}]}
{"op":"mcm","clk":"5306663845","pt":1646103029546,"mc":[{"id":"1.195395426","rc":[{"atb":[[1.18,257.5]],"id":43154454},{"atb":[[1.56,0]],"id":42189480}],"con":true,"img":false}]}
{"op":"mcm","clk":"5306663941","pt":1646103032050,"mc":[{"id":"1.195395426","rc":[{"atb":[[1.18,360.98]],"id":43154454}],"con":true,"img":false}]}
{"op":"mcm","clk":"5306663982","pt":1646103033024,"mc":[{"id":"1.195395426","rc":[{"atb":[[2.74,0],[2.84,54.35]],"id":38859241},{"atb":[[2.24,80.65],[2.04,0]],"id":43154455},{"atb":[[2.04,96.15],[1.69,0]],"id":38256919}],"con":true,"img":false}]}
{"op":"mcm","clk":"5306663991","pt":1646103033332,"mc":[{"id":"1.195395426","rc":[{"atb":[[1.61,34.92]],"id":42189480}],"con":true,"img":false}]}
{"op":"mcm","clk":"5306664029","pt":1646103034355,"mc":[{"id":"1.195395426","rc":[{"atb":[[1.57,0]],"id":42189480}],"con":true,"img":false}]}
{"op":"mcm","clk":"5306664155","pt":1646103037270,"mc":[{"id":"1.195395426","rc":[{"atb":[[1.59,0]],"id":42189480}],"con":true,"img":false}]}
{"op":"mcm","clk":"5306664253","pt":1646103038776,"mc":[{"id":"1.195395426","rc":[{"atl":[[5.5,0]],"id":36104892},{"atl":[[13,8.42],[15.5,0]],"id":38859241}],"con":true,"img":false}]}
{"op":"mcm","clk":"5306664260","pt":1646103038836,"mc":[{"id":"1.195395426","rc":[{"atl":[[5.3,8.83]],"id":36104892}],"con":true,"img":false}]}
{"op":"mcm","clk":"5306664265","pt":1646103038938,"mc":[{"id":"1.195395426","rc":[{"atl":[[5.2,8.84],[5.4,0]],"id":36104892}],"con":true,"img":false}]}
{"op":"mcm","clk":"5306664307","pt":1646103039559,"mc":[{"id":"1.195395426","rc":[{"atb":[[1.65,8.14]],"id":42189480}],"con":true,"img":false}]}
{"op":"mcm","clk":"5306664407","pt":1646103042380,"mc":[{"id":"1.195395426","rc":[{"atb":[[1.98,0]],"id":36104892},{"atb":[[1.61,0]],"id":42189480}],"con":true,"img":false}]}
{"op":"mcm","clk":"5306664420","pt":1646103042638,"mc":[{"id":"1.195395426","rc":[{"atb":[[1.64,24.68]],"id":42189480}],"con":true,"img":false}]}
{"op":"mcm","clk":"5306664557","pt":1646103046282,"mc":[{"id":"1.195395426","rc":[{"atb":[[1.97,45.17]],"id":36104892},{"atb":[[1.61,26.47]],"id":42189480}],"con":true,"img":false}]}
{"op":"mcm","clk":"5306664573","pt":1646103046641,"mc":[{"id":"1.195395426","rc":[{"atb":[[2.02,1.66]],"id":36104892},{"atb":[[1.65,0]],"id":42189480}],"con":true,"img":false}]}
{"op":"mcm","clk":"5306664585","pt":1646103046947,"mc":[{"id":"1.195395426","rc":[{"atb":[[2,8.34]],"id":36104892}],"con":true,"img":false}]}
{"op":"mcm","clk":"5306664805","pt":1646103051966,"mc":[{"id":"1.195395426","rc":[{"atb":[[2.02,8.68]],"id":36104892},{"atb":[[1.65,17.27]],"id":42189480}],"con":true,"img":false}]}
{"op":"mcm","clk":"5306664844","pt":1646103052785,"mc":[{"id":"1.195395426","rc":[{"atb":[[2.02,15.98]],"id":36104892}],"con":true,"img":false}]}
{"op":"mcm","clk":"5306664862","pt":1646103053091,"mc":[{"id":"1.195395426","rc":[{"atb":[[1.6,0],[1.66,24.68]],"id":42189480}],"con":true,"img":false}]}
{"op":"mcm","clk":"5306664929","pt":1646103054779,"mc":[{"id":"1.195395426","rc":[{"atb":[[3.15,0]],"id":38859241},{"atb":[[11,0],[15.5,2.98]],"id":38256919}],"con":true,"img":false}]}
{"op":"mcm","clk":"5306664932","pt":1646103054878,"mc":[{"id":"1.195395426","rc":[{"atb":[[3.4,20.13]],"id":38859241}],"con":true,"img":false}]}
{"op":"mcm","clk":"5306664947","pt":1646103055287,"mc":[{"id":"1.195395426","rc":[{"atb":[[1.61,0]],"id":42189480}],"con":true,"img":false}]}
{"op":"mcm","clk":"5306664975","pt":1646103055954,"mc":[{"id":"1.195395426","rc":[{"atb":[[1.64,13.04]],"id":42189480}],"con":true,"img":false}]}
{"op":"mcm","clk":"5306665013","pt":1646103057077,"mc":[{"id":"1.195395426","rc":[{"atb":[[1.65,0]],"id":42189480}],"con":true,"img":false}]}
{"op":"mcm","clk":"5306665053","pt":1646103058150,"mc":[{"id":"1.195395426","rc":[{"atb":[[1.66,0],[1.65,105.58]],"id":42189480}],"con":true,"img":false}]}
{"op":"mcm","clk":"5306665084","pt":1646103059069,"mc":[{"id":"1.195395426","rc":[{"atb":[[1.67,49.35]],"id":42189480}],"con":true,"img":false}]}
{"op":"mcm","clk":"5306665178","pt":1646103061372,"mc":[{"id":"1.195395426","rc":[{"atb":[[2,0]],"id":36104892}],"con":true,"img":false}]}
{"op":"mcm","clk":"5306665204","pt":1646103061986,"mc":[{"id":"1.195395426","rc":[{"atb":[[1.68,34.54]],"id":42189480}],"con":true,"img":false}]}
{"op":"mcm","clk":"5306665295","pt":1646103064290,"mc":[{"id":"1.195395426","rc":[{"atb":[[2.02,8.97]],"id":36104892}],"con":true,"img":false}]}
{"op":"mcm","clk":"5306665306","pt":1646103064597,"mc":[{"id":"1.195395426","rc":[{"atb":[[1.67,0]],"id":42189480}],"con":true,"img":false}]}
{"op":"mcm","clk":"5306665451","pt":1646103067572,"mc":[{"id":"1.195395426","rc":[{"atb":[[1.64,0]],"id":42189480}],"con":true,"img":false}]}
{"op":"mcm","clk":"5306665459","pt":1646103067877,"mc":[{"id":"1.195395426","rc":[{"atb":[[2.02,17.15]],"id":36104892}],"con":true,"img":false}]}
{"op":"mcm","clk":"5306665491","pt":1646103068695,"mc":[{"id":"1.195395426","rc":[{"atb":[[1.69,67.17]],"id":42189480}],"con":true,"img":false}]}
{"op":"mcm","clk":"5306665522","pt":1646103069311,"mc":[{"id":"1.195395426","rc":[{"atl":[[8.8,22.09],[6.6,0]],"id":36104892},{"atb":[[2.5,42.7],[2.96,0]],"id":38859241},{"atl":[[21,9.25],[13,3.32]],"id":38859241},{"atb":[[1.13,171.17],[1.17,0]],"id":43154454},{"atl":[[2.36,0],[2.88,67.51],[2.18,0]],"id":43154454},{"atb":[[6.8,0],[7.8,0],[5.9,15.69]],"id":39318320},{"atl":[[38,1.11],[50,0]],"id":39318320},{"atb":[[4.6,0]],"id":43154455},{"atl":[[32,6.07],[26,1.62],[28,0]],"id":43154455},{"atb":[[10,11.28],[15.5,0]],"id":38256919},{"atb":[[1.34,114.5]],"id":42189480},{"atl":[[4.1,0],[5.2,37.38]],"id":42189480}],"con":true,"img":false}]}
{"op":"mcm","clk":"5306665526","pt":1646103069361,"mc":[{"id":"1.195395426","rc":[{"atl":[[2.14,35.47]],"id":43154454},{"atb":[[6.8,6.36]],"id":39318320},{"atl":[[75,2.7]],"id":39318320},{"atb":[[4.1,18.54]],"id":43154455},{"atb":[[12.5,2.98]],"id":38256919}],"con":true,"img":false}]}
{"op":"mcm","clk":"5306665530","pt":1646103069462,"mc":[{"id":"1.195395426","rc":[{"atl":[[2.42,36.29],[2.16,0]],"id":43154454}],"con":true,"img":false}]}
{"op":"mcm","clk":"5306665535","pt":1646103069618,"mc":[{"id":"1.195395426","rc":[{"atl":[[2.12,35.48]],"id":43154454}],"con":true,"img":false}]}
{"op":"mcm","clk":"5306665540","pt":1646103069667,"mc":[{"id":"1.195395426","rc":[{"atl":[[2.42,0.37]],"id":43154454}],"con":true,"img":false}]}
{"op":"mcm","clk":"5306665574","pt":1646103070586,"mc":[{"id":"1.195395426","rc":[{"atb":[[1.98,9.86]],"id":36104892},{"atb":[[1.68,0]],"id":42189480}],"con":true,"img":false}]}
{"op":"mcm","clk":"5306665595","pt":1646103071098,"mc":[{"id":"1.195395426","rc":[{"atb":[[8,0]],"id":39318320}],"con":true,"img":false}]}
{"op":"mcm","clk":"5306665599","pt":1646103071200,"mc":[{"id":"1.195395426","rc":[{"atb":[[5,0],[5.3,51.19]],"id":39318320}],"con":true,"img":false}]}
{"op":"mcm","clk":"5306665605","pt":1646103071302,"mc":[{"id":"1.195395426","rc":[{"atb":[[7,1.66]],"id":39318320}],"con":true,"img":false}]}
{"op":"mcm","clk":"5306665646","pt":1646103072477,"mc":[{"id":"1.195395426","rc":[{"atb":[[1.18,103.48]],"id":43154454}],"con":true,"img":false}]}
{"op":"mcm","clk":"5306665661","pt":1646103072989,"mc":[{"id":"1.195395426","rc":[{"atb":[[1.18,0]],"id":43154454}],"con":true,"img":false}]}
{"op":"mcm","clk":"5306665700","pt":1646103074318,"mc":[{"id":"1.195395426","rc":[{"atb":[[1.97,0]],"id":36104892},{"spn":1.66,"spf":"NaN","id":43154454},{"spn":15.5,"spf":"NaN","id":39318320},{"spn":41.25,"spf":"NaN","id":38256919},{"atb":[[1.69,0]],"id":42189480},{"spn":2.09,"spf":"NaN","id":42189480}],"con":true,"img":false}]}
{"op":"mcm","clk":"5306665706","pt":1646103074472,"mc":[{"id":"1.195395426","rc":[{"atb":[[1.45,211.16],[1.65,0]],"id":42189480}],"con":true,"img":false}]}
{"op":"mcm","clk":"5306665758","pt":1646103075801,"mc":[{"id":"1.195395426","rc":[{"atb":[[1.45,286.58]],"id":42189480}],"con":true,"img":false}]}
{"op":"mcm","clk":"5306665774","pt":1646103076209,"mc":[{"id":"1.195395426","rc":[{"atb":[[1.16,289.69]],"id":43154454}],"con":true,"img":false}]}
{"op":"mcm","clk":"5306665805","pt":1646103076878,"mc":[{"id":"1.195395426","rc":[{"atb":[[2.02,9.85]],"id":36104892}],"con":true,"img":false}]}
{"op":"mcm","clk":"5306665813","pt":1646103077082,"mc":[{"id":"1.195395426","rc":[{"atl":[[2.12,0],[2.26,70.96]],"id":43154454}],"con":true,"img":false}]}
{"op":"mcm","clk":"5306665883","pt":1646103078417,"mc":[{"id":"1.195395426","rc":[{"atb":[[1.99,46.82]],"id":36104892},{"atb":[[1.35,132.43]],"id":42189480}],"con":true,"img":false}]}
{"op":"mcm","clk":"5306665889","pt":1646103078619,"mc":[{"id":"1.195395426","rc":[{"atb":[[1.98,0]],"id":36104892}],"con":true,"img":false}]}
{"op":"mcm","clk":"5306665893","pt":1646103078722,"mc":[{"id":"1.195395426","rc":[{"atb":[[1.16,411.99]],"id":43154454}],"con":true,"img":false}]}
{"op":"mcm","clk":"5306665984","pt":1646103081129,"mc":[{"id":"1.195395426","rc":[{"atb":[[1.45,211.16]],"id":42189480}],"con":true,"img":false}]}
{"op":"mcm","clk":"5306666059","pt":1646103082919,"mc":[{"id":"1.195395426","rc":[{"atb":[[1.48,15.52]],"id":42189480}],"con":true,"img":false}]}
{"op":"mcm","clk":"5306666099","pt":1646103083791,"mc":[{"id":"1.195395426","rc":[{"atb":[[1.97,11.82]],"id":36104892}],"con":true,"img":false}]}
{"op":"mcm","clk":"5306666154","pt":1646103085323,"mc":[{"id":"1.195395426","rc":[{"atb":[[1.96,0]],"id":36104892},{"atl":[[5.3,0]],"id":36104892},{"atl":[[32,2.7]],"id":43154455}],"con":true,"img":false}]}
{"op":"mcm","clk":"5306666157","pt":1646103085427,"mc":[{"id":"1.195395426","rc":[{"atb":[[1.98,47.56]],"id":36104892},{"atl":[[5.6,9.1],[6,8.83]],"id":36104892}],"con":true,"img":false}]}
{"op":"mcm","clk":"5306666161","pt":1646103085529,"mc":[{"id":"1.195395426","rc":[{"atl":[[5.2,0]],"id":36104892}],"con":true,"img":false}]}
{"op":"mcm","clk":"5306666174","pt":1646103085836,"mc":[{"id":"1.195395426","rc":[{"atb":[[1.35,0]],"id":42189480}],"con":true,"img":false}]}
{"op":"mcm","clk":"5306666178","pt":1646103085935,"mc":[{"id":"1.195395426","rc":[{"atb":[[2.04,7.17]],"id":36104892}],"con":true,"img":false}]}
{"op":"mcm","clk":"5306666207","pt":1646103086501,"mc":[{"id":"1.195395426","rc":[{"atb":[[1.49,10.86]],"id":42189480}],"con":true,"img":false}]}
{"op":"mcm","clk":"5306666318","pt":1646103089002,"mc":[{"id":"1.195395426","rc":[{"atb":[[1.97,0]],"id":36104892}],"con":true,"img":false}]}
{"op":"mcm","clk":"5306666322","pt":1646103089105,"mc":[{"id":"1.195395426","rc":[{"atb":[[2.02,8.18]],"id":36104892}],"con":true,"img":false}]}
{"op":"mcm","clk":"5306666332","pt":1646103089310,"mc":[{"id":"1.195395426","rc":[{"atb":[[2.06,1.66]],"id":36104892}],"con":true,"img":false}]}
{"op":"mcm","clk":"5306666346","pt":1646103089719,"mc":[{"id":"1.195395426","rc":[{"atb":[[1.99,0]],"id":36104892},{"atb":[[1.46,32.6]],"id":42189480}],"con":true,"img":false}]}
{"op":"mcm","clk":"5306666401","pt":1646103090944,"mc":[{"id":"1.195395426","rc":[{"atb":[[1.48,32.91]],"id":42189480}],"con":true,"img":false}]}
{"op":"mcm","clk":"5306666446","pt":1646103091917,"mc":[{"id":"1.195395426","rc":[{"atb":[[2.04,0]],"id":36104892}],"con":true,"img":false}]}
{"op":"mcm","clk":"5306666513","pt":1646103093505,"mc":[{"id":"1.195395426","rc":[{"atb":[[2.08,3.33]],"id":36104892}],"con":true,"img":false}]}
{"op":"mcm","clk":"5306666541","pt":1646103094223,"mc":[{"id":"1.195395426","rc":[{"atb":[[1.99,9.72]],"id":36104892}],"con":true,"img":false}]}
{"op":"mcm","clk":"5306666578","pt":1646103095143,"mc":[{"id":"1.195395426","rc":[{"atb":[[2.06,0]],"id":36104892}],"con":true,"img":false}]}
{"op":"mcm","clk":"5306666588","pt":1646103095348,"mc":[{"id":"1.195395426","rc":[{"atb":[[2.1,1.66]],"id":36104892}],"con":true,"img":false}]}
{"op":"mcm","clk":"5306666691","pt":1646103098022,"mc":[{"id":"1.195395426","rc":[{"atb":[[2.02,15.48]],"id":36104892}],"con":true,"img":false}]}
{"op":"mcm","clk":"5306666751","pt":1646103099151,"mc":[{"id":"1.195395426","rc":[{"atb":[[2.08,0]],"id":36104892}],"con":true,"img":false}]}
{"op":"mcm","clk":"5306666801","pt":1646103100334,"mc":[{"id":"1.195395426","rc":[{"atb":[[1.98,0]],"id":36104892},{"atb":[[6.8,0]],"id":39318320},{"atl":[[38,2.72]],"id":39318320},{"atl":[[26,2.7]],"id":43154455},{"atb":[[12.5,0]],"id":38256919},{"atb":[[1.44,0]],"id":42189480}],"con":true,"img":false}]}
{"op":"mcm","clk":"5306666810","pt":1646103100436,"mc":[{"id":"1.195395426","rc":[{"atb":[[1.96,47.56]],"id":36104892},{"atb":[[7.8,6.36]],"id":39318320},{"atb":[[15,2.98]],"id":38256919},{"atb":[[1.46,138.17]],"id":42189480}],"con":true,"img":false}]}
{"op":"mcm","clk":"5306666843","pt":1646103101048,"mc":[{"id":"1.195395426","rc":[{"atb":[[2.02,8.18],[2.1,0]],"id":36104892},{"atb":[[7,0]],"id":39318320},{"atb":[[1.48,17.39]],"id":42189480}],"con":true,"img":false}]}
{"op":"mcm","clk":"5306666854","pt":1646103101257,"mc":[{"id":"1.195395426","rc":[{"atb":[[2.04,1.66]],"id":36104892},{"atb":[[8,1.66]],"id":39318320}],"con":true,"img":false}]}
{"op":"mcm","clk":"5306666918","pt":1646103102946,"mc":[{"id":"1.195395426","rc":[{"atb":[[2.04,6.67]],"id":36104892}],"con":true,"img":false}]}
{"op":"mcm","clk":"5306666971","pt":1646103104222,"mc":[{"id":"1.195395426","rc":[{"atb":[[1.99,0]],"id":36104892}],"con":true,"img":false}]}
{"op":"mcm","clk":"5306667059","pt":1646103106019,"mc":[{"id":"1.195395426","rc":[{"atb":[[1.45,0],[1.5,17.39]],"id":42189480}],"con":true,"img":false}]}
{"op":"mcm","clk":"5306667083","pt":1646103106632,"mc":[{"id":"1.195395426","rc":[{"atb":[[2.04,1.66]],"id":36104892}],"con":true,"img":false}]}
{"op":"mcm","clk":"5306667105","pt":1646103107246,"mc":[{"id":"1.195395426","rc":[{"atb":[[2,7.45]],"id":36104892},{"atb":[[1.49,26.07]],"id":42189480}],"con":true,"img":false}]}
{"op":"mcm","clk":"5306667152","pt":1646103108427,"mc":[{"id":"1.195395426","rc":[{"atb":[[1.46,105.57]],"id":42189480}],"con":true,"img":false}]}
{"op":"mcm","clk":"5306667159","pt":1646103108633,"mc":[{"id":"1.195395426","rc":[{"atl":[[2.12,35.48],[2.26,0]],"id":43154454}],"con":true,"img":false}]}
{"op":"mcm","clk":"5306667187","pt":1646103109349,"mc":[{"id":"1.195395426","rc":[{"atb":[[2.02,0],[1.97,8.68]],"id":36104892},{"atb":[[1.49,15.21]],"id":42189480}],"con":true,"img":false}]}
{"op":"mcm","clk":"5306667240","pt":1646103110431,"mc":[{"id":"1.195395426","rc":[{"atb":[[2.06,3.33]],"id":36104892}],"con":true,"img":false}]}
{"op":"mcm","clk":"5306667322","pt":1646103112380,"mc":[{"id":"1.195395426","rc":[{"atb":[[1.51,34.77]],"id":42189480}],"con":true,"img":false}]}
{"op":"mcm","clk":"5306667353","pt":1646103113044,"mc":[{"id":"1.195395426","rc":[{"atb":[[2.04,0]],"id":36104892}],"con":true,"img":false}]}
{"op":"mcm","clk":"5306667358","pt":1646103113147,"mc":[{"id":"1.195395426","rc":[{"atb":[[2.08,1.66]],"id":36104892}],"con":true,"img":false}]}
{"op":"mcm","clk":"5306667405","pt":1646103114882,"mc":[{"id":"1.195395426","rc":[{"atb":[[1.51,46.94]],"id":42189480}],"con":true,"img":false}]}
{"op":"mcm","clk":"5306667462","pt":1646103116168,"mc":[{"id":"1.195395426","rc":[{"atb":[[2.06,0]],"id":36104892}],"con":true,"img":false}]}
{"op":"mcm","clk":"5306667492","pt":1646103116835,"mc":[{"id":"1.195395426","rc":[{"atb":[[1.49,0]],"id":42189480}],"con":true,"img":false}]}
{"op":"mcm","clk":"5306667599","pt":1646103119043,"mc":[{"id":"1.195395426","rc":[{"atb":[[2.08,0]],"id":36104892}],"con":true,"img":false}]}
{"op":"mcm","clk":"5306667605","pt":1646103119144,"mc":[{"id":"1.195395426","rc":[{"atb":[[2.02,1.66]],"id":36104892}],"con":true,"img":false}]}
{"op":"mcm","clk":"5306667633","pt":1646103119965,"mc":[{"id":"1.195395426","rc":[{"atb":[[1.98,6.26]],"id":36104892}],"con":true,"img":false}]}
{"op":"mcm","clk":"5306667730","pt":1646103121967,"mc":[{"id":"1.195395426","rc":[{"atb":[[1.48,0]],"id":42189480}],"con":true,"img":false}]}
{"op":"mcm","clk":"5306667734","pt":1646103122070,"mc":[{"id":"1.195395426","rc":[{"atb":[[2,15.8]],"id":36104892}],"con":true,"img":false}]}
{"op":"mcm","clk":"5306667766","pt":1646103122788,"mc":[{"id":"1.195395426","rc":[{"atb":[[1.54,13.8]],"id":42189480}],"con":true,"img":false}]}
{"op":"mcm","clk":"5306667847","pt":1646103124784,"mc":[{"id":"1.195395426","rc":[{"atb":[[1.97,0]],"id":36104892},{"atb":[[1.51,34.77]],"id":42189480}],"con":true,"img":false}]}
{"op":"mcm","clk":"5306667881","pt":1646103125550,"mc":[{"id":"1.195395426","rc":[{"atb":[[1.51,0]],"id":42189480}],"con":true,"img":false}]}
{"op":"mcm","clk":"5306667885","pt":1646103125654,"mc":[{"id":"1.195395426","rc":[{"atb":[[1.49,17.04]],"id":42189480}],"con":true,"img":false}]}
{"op":"mcm","clk":"5306667889","pt":1646103125756,"mc":[{"id":"1.195395426","rc":[{"atb":[[1.54,0]],"id":42189480}],"con":true,"img":false}]}
{"op":"mcm","clk":"5306668028","pt":1646103129387,"mc":[{"id":"1.195395426","rc":[{"atb":[[1.47,52.16]],"id":42189480}],"con":true,"img":false}]}
{"op":"mcm","clk":"5306668071","pt":1646103130359,"mc":[{"id":"1.195395426","rc":[{"atl":[[6.8,9.32]],"id":36104892},{"atb":[[2.96,31.19]],"id":38859241},{"atl":[[13,8.42]],"id":38859241},{"atb":[[1.17,356.48]],"id":43154454},{"atl":[[2.44,42.08]],"id":43154454},{"atb":[[6.8,10.82]],"id":39318320},{"atb":[[12.5,4.81]],"id":38256919},{"atl":[[4.1,17.36]],"id":42189480}],"con":true,"img":false}]}
{"op":"mcm","clk":"5306668075","pt":1646103130463,"mc":[{"id":"1.195395426","rc":[{"atl":[[8.8,0]],"id":36104892},{"atb":[[2.5,0]],"id":38859241},{"atl":[[21,0]],"id":38859241},{"atb":[[1.13,0]],"id":43154454},{"atl":[[2.88,0]],"id":43154454},{"atb":[[5.9,0]],"id":39318320},{"atl":[[75,0]],"id":39318320},{"atb":[[4.1,0]],"id":43154455},{"atb":[[10,0]],"id":38256919},{"atl":[[5.2,0]],"id":42189480}],"con":true,"img":false}]}
{"op":"mcm","clk":"5306668080","pt":1646103130566,"mc":[{"id":"1.195395426","rc":[{"atl":[[50,2.7]],"id":39318320},{"atb":[[4.6,18.54]],"id":43154455}],"con":true,"img":false}]}
{"op":"mcm","clk":"5306668177","pt":1646103133077,"mc":[{"id":"1.195395426","rc":[{"atb":[[1.16,122.3]],"id":43154454}],"con":true,"img":false}]}
{"op":"mcm","clk":"5306668251","pt":1646103134764,"mc":[{"id":"1.195395426","rc":[{"atb":[[1.16,0]],"id":43154454},{"spn":16.0,"spf":"NaN","id":39318320},{"spn":42.5,"spf":"NaN","id":38256919},{"spn":2.02,"spf":"NaN","id":42189480}],"con":true,"img":false}]}
{"op":"mcm","clk":"5306668329","pt":1646103136860,"mc":[{"id":"1.195395426","rc":[{"atb":[[1.18,257.5]],"id":43154454}],"con":true,"img":false}]}
{"op":"mcm","clk":"5306668368","pt":1646103137784,"mc":[{"id":"1.195395426","rc":[{"atb":[[1.5,32.29]],"id":42189480}],"con":true,"img":false}]}
{"op":"mcm","clk":"5306668592","pt":1646103142701,"mc":[{"id":"1.195395426","rc":[{"atl":[[5.6,0.11]],"id":36104892},{"atb":[[2.84,0]],"id":38859241},{"atl":[[13.5,0]],"id":38859241},{"atl":[[2.12,0]],"id":43154454},{"atb":[[5.3,27.93]],"id":39318320},{"atl":[[40,0]],"id":39318320},{"atb":[[2.24,0]],"id":43154455},{"atl":[[34,0]],"id":43154455},{"atb":[[2.04,0]],"id":38256919},{"atl":[[110,2.7]],"id":38256919},{"atb":[[1.5,14.9]],"id":42189480},{"atl":[[11,0]],"id":42189480}],"con":true,"img":false}]}
{"op":"mcm","clk":"5306668718","pt":1646103145617,"mc":[{"id":"1.195395426","rc":[{"atl":[[15.5,4.21]],"id":38859241},{"atl":[[46,2.7]],"id":39318320}],"con":true,"img":false}]}
{"op":"mcm","clk":"5306668721","pt":1646103145720,"mc":[{"id":"1.195395426","rc":[{"atl":[[13,3.32]],"id":38859241},{"atl":[[38,0.01]],"id":39318320},{"atb":[[1.46,0]],"id":42189480}],"con":true,"img":false}]}
{"op":"mcm","clk":"5306668725","pt":1646103145822,"mc":[{"id":"1.195395426","rc":[{"atb":[[1.48,105.57]],"id":42189480}],"con":true,"img":false}]}
{"op":"mcm","clk":"5306668757","pt":1646103146796,"mc":[{"id":"1.195395426","rc":[{"atb":[[1.5,0]],"id":42189480}],"con":true,"img":false}]}
{"op":"mcm","clk":"5306668801","pt":1646103147714,"mc":[{"id":"1.195395426","rc":[{"atb":[[1.47,0]],"id":42189480}],"con":true,"img":false}]}
{"op":"mcm","clk":"5306668985","pt":1646103151503,"mc":[{"id":"1.195395426","rc":[{"atb":[[1.35,97.97]],"id":42189480}],"con":true,"img":false}]}
{"op":"mcm","clk":"5306669042","pt":1646103152931,"mc":[{"id":"1.195395426","rc":[{"atb":[[1.51,14.61]],"id":42189480}],"con":true,"img":false}]}
{"op":"mcm","clk":"5306669155","pt":1646103155392,"mc":[{"id":"1.195395426","rc":[{"atb":[[1.35,0]],"id":42189480}],"con":true,"img":false}]}
{"op":"mcm","clk":"5306669320","pt":1646103159231,"mc":[{"id":"1.195395426","rc":[{"atb":[[1.52,29.23]],"id":42189480}],"con":true,"img":false}]}
{"op":"mcm","clk":"5306669389","pt":1646103160821,"mc":[{"id":"1.195395426","rc":[{"atb":[[1.48,0]],"id":42189480}],"con":true,"img":false}]}
{"op":"mcm","clk":"5306669392","pt":1646103160923,"mc":[{"id":"1.195395426","rc":[{"atb":[[1.42,105.57]],"id":42189480}],"con":true,"img":false}]}
{"op":"mcm","clk":"5306669435","pt":1646103161901,"mc":[{"id":"1.195395426","rc":[{"atb":[[1.51,0]],"id":42189480}],"con":true,"img":false}]}
{"op":"mcm","clk":"5306669510","pt":1646103163744,"mc":[{"id":"1.195395426","rc":[{"atb":[[1.49,0]],"id":42189480}],"con":true,"img":false}]}
{"op":"mcm","clk":"5306669557","pt":1646103164922,"mc":[{"id":"1.195395426","rc":[{"atb":[[1.52,0]],"id":42189480}],"con":true,"img":false}]}
{"op":"mcm","clk":"5306669690","pt":1646103168042,"mc":[{"id":"1.195395426","rc":[{"atb":[[1.45,16.56]],"id":42189480}],"con":true,"img":false}]}
{"op":"mcm","clk":"5306669716","pt":1646103168606,"mc":[{"id":"1.195395426","rc":[{"atb":[[1.31,149.51]],"id":42189480}],"con":true,"img":false}]}
{"op":"mcm","clk":"5306669869","pt":1646103172349,"mc":[{"id":"1.195395426","rc":[{"atb":[[1.31,0]],"id":42189480}],"con":true,"img":false}]}
{"op":"mcm","clk":"5306670018","pt":1646103176235,"mc":[{"id":"1.195395426","rc":[{"atb":[[1.35,78.66]],"id":42189480}],"con":true,"img":false}]}
{"op":"mcm","clk":"5306670068","pt":1646103177569,"mc":[{"id":"1.195395426","rc":[{"atb":[[1.85,0],[1.9,0],[1.95,0]],"id":36104892},{"atl":[[5.6,0],[7.2,0],[4.6,0]],"id":36104892},{"atb":[[3.1,0],[3.35,0],[2.94,0]],"id":38859241},{"atl":[[17,0],[12,0],[8.8,0]],"id":38859241},{"atb":[[1.15,0],[1.1,0],[1.05,0]],"id":43154454},{"atl":[[2.22,0],[2.42,0],[2.62,0]],"id":43154454},{"atb":[[5.8,0],[5.3,0],[6.6,0]],"id":39318320},{"atl":[[70,0],[38,0],[24,0]],"id":39318320},{"atb":[[4,0],[4.5,0],[5,0]],"id":43154455},{"atl":[[17,0],[38,0],[24,0]],"id":43154455},{"atb":[[9.8,0],[8.8,0],[7.8,0]],"id":38256919},{"atl":[[70,0],[140,0],[240,0]],"id":38256919},{"atb":[[1.2,0],[1.25,0],[1.3,0]],"id":42189480},{"atl":[[2.54,0],[2.74,0],[2.94,0]],"id":42189480}],"con":true,"img":false}]}
{"op":"mcm","clk":"5306670152","pt":1646103179667,"mc":[{"id":"1.195395426","rc":[{"atb":[[1.85,141.32],[1.9,133.47],[1.95,63.22]],"id":36104892},{"atl":[[5.6,0.11],[7.2,0.69],[4.6,0.15]],"id":36104892},{"atb":[[3.1,57.19],[3.35,25.55],[2.94,61.91]],"id":38859241},{"atl":[[17,0.27],[12,0.04],[8.8,0.07]],"id":38859241},{"atb":[[1.15,400.41],[1.1,1201.23],[1.05,2402.46]],"id":43154454},{"atl":[[2.22,0.44],[2.42,0.37],[2.62,2.67]],"id":43154454},{"atb":[[5.8,25.02],[5.3,27.93],[6.6,10.72]],"id":39318320},{"atl":[[70,0.06],[38,0.01],[24,0.02]],"id":39318320},{"atb":[[4,40.04],[4.5,34.32],[5,15.01]],"id":43154455},{"atl":[[17,0.03],[38,0.11],[24,0.02]],"id":43154455},{"atb":[[9.8,6.82],[8.8,15.39],[7.8,17.66]],"id":38256919},{"atl":[[70,0],[140,0],[240,0.01]],"id":38256919},{"atb":[[1.2,600.61],[1.25,480.49],[1.3,200.2]],"id":42189480},{"atl":[[2.54,0.35],[2.74,0.3],[2.94,2.22]],"id":42189480}],"con":true,"img":false}]}
{"op":"mcm","clk":"5306670159","pt":1646103179868,"mc":[{"id":"1.195395426","rc":[{"atb":[[3.45,3.4]],"id":38859241}],"con":true,"img":false}]}
{"op":"mcm","clk":"5306670168","pt":1646103180022,"mc":[{"id":"1.195395426","rc":[{"atb":[[1.98,0]],"id":36104892}],"con":true,"img":false}]}
{"op":"mcm","clk":"5306670223","pt":1646103181454,"mc":[{"id":"1.195395426","rc":[{"atb":[[1.45,35.11]],"id":42189480}],"con":true,"img":false}]}
{"op":"mcm","clk":"5306670234","pt":1646103181861,"mc":[{"id":"1.195395426","rc":[{"atb":[[1.35,0]],"id":42189480}],"con":true,"img":false}]}
{"op":"mcm","clk":"5306670317","pt":1646103183858,"mc":[{"id":"1.195395426","rc":[{"atb":[[1.97,5.42]],"id":36104892}],"con":true,"img":false}]}
{"op":"mcm","clk":"5306670380","pt":1646103185854,"mc":[{"id":"1.195395426","rc":[{"atb":[[1.35,132.58]],"id":42189480}],"con":true,"img":false}]}
{"op":"mcm","clk":"5306670494","pt":1646103188668,"mc":[{"id":"1.195395426","rc":[{"atb":[[3.45,6.44]],"id":38859241}],"con":true,"img":false}]}
{"op":"mcm","clk":"5306670571","pt":1646103190772,"mc":[{"id":"1.195395426","rc":[{"atb":[[1.17,0]],"id":43154454},{"atl":[[32,0]],"id":43154455}],"con":true,"img":false}]}
{"op":"mcm","clk":"5306670578","pt":1646103190874,"mc":[{"id":"1.195395426","rc":[{"atb":[[1.19,356.48]],"id":43154454},{"atl":[[28,2.7]],"id":43154455}],"con":true,"img":false}]}
{"op":"mcm","clk":"5306670667","pt":1646103193072,"mc":[{"id":"1.195395426","rc":[{"atb":[[1.18,0]],"id":43154454}],"con":true,"img":false}]}
{"op":"mcm","clk":"5306671080","pt":1646103203365,"mc":[{"id":"1.195395426","rc":[{"atb":[[1.97,0]],"id":36104892},{"atb":[[3.5,1.66]],"id":38859241},{"spn":1.67,"spf":"NaN","id":43154454},{"atb":[[5.2,1.66]],"id":43154455},{"atb":[[1.35,0]],"id":42189480},{"spn":1.99,"spf":"NaN","id":42189480}],"con":true,"img":false}]}
{"op":"mcm","clk":"5306671162","pt":1646103205358,"mc":[{"id":"1.195395426","rc":[{"atb":[[1.19,0]],"id":43154454}],"con":true,"img":false}]}
{"op":"mcm","clk":"5306671166","pt":1646103205460,"mc":[{"id":"1.195395426","rc":[{"atb":[[1.16,356.48]],"id":43154454}],"con":true,"img":false}]}
{"op":"mcm","clk":"5306671741","pt":1646103220112,"mc":[{"id":"1.195395426","rc":[{"atb":[[1.42,0]],"id":42189480}],"con":true,"img":false}]}
{"op":"mcm","clk":"5306671748","pt":1646103220214,"mc":[{"id":"1.195395426","rc":[{"atb":[[1.46,105.57]],"id":42189480}],"con":true,"img":false}]}
{"op":"mcm","clk":"5306671812","pt":1646103221906,"mc":[{"id":"1.195395426","rc":[{"atb":[[1.45,18.55]],"id":42189480}],"con":true,"img":false}]}
{"op":"mcm","clk":"5306672065","pt":1646103228048,"mc":[{"id":"1.195395426","rc":[{"atb":[[1.49,15.21]],"id":42189480}],"con":true,"img":false}]}
{"op":"mcm","clk":"5306672287","pt":1646103233324,"mc":[{"id":"1.195395426","rc":[{"atb":[[1.45,0]],"id":42189480}],"con":true,"img":false}]}
{"op":"mcm","clk":"5306672359","pt":1646103235323,"mc":[{"id":"1.195395426","rc":[{"atb":[[1.03,2.7]],"id":43154454},{"atb":[[1.03,2.7]],"id":42189480}],"con":true,"img":false}]}
{"op":"mcm","clk":"5306672368","pt":1646103235529,"mc":[{"id":"1.195395426","rc":[{"atb":[[1.03,3.24]],"id":43154454},{"atb":[[1.03,3.24]],"id":42189480}],"con":true,"img":false}]}
{"op":"mcm","clk":"5306672377","pt":1646103235835,"mc":[{"id":"1.195395426","rc":[{"atb":[[1.03,0.54]],"id":43154454},{"atb":[[1.03,0.54]],"id":42189480}],"con":true,"img":false}]}
{"op":"mcm","clk":"5306672393","pt":1646103236141,"mc":[{"id":"1.195395426","rc":[{"atb":[[1.03,0]],"id":43154454},{"atb":[[1.03,0]],"id":42189480}],"con":true,"img":false}]}
{"op":"mcm","clk":"5306672397","pt":1646103236245,"mc":[{"id":"1.195395426","rc":[{"atl":[[2.14,34.93]],"id":43154454},{"trd":[[2.14,1.08]],"ltp":2.14,"tv":1.08,"id":43154454},{"atl":[[2.54,0],[2.74,0.11]],"id":42189480},{"trd":[[2.74,0.37],[2.54,0.7]],"ltp":2.74,"tv":1.06,"id":42189480}],"con":true,"img":false}]}
{"op":"mcm","clk":"5306672558","pt":1646103240450,"mc":[{"id":"1.195395426","rc":[{"atb":[[1.49,32.25]],"id":42189480}],"con":true,"img":false}]}
{"op":"mcm","clk":"5306672892","pt":1646103249572,"mc":[{"id":"1.195395426","rc":[{"atb":[[1.63,0]],"id":36104892},{"atb":[[2.42,43.06],[2.96,0]],"id":38859241},{"atl":[[2.44,0],[2.14,0]],"id":43154454},{"atb":[[6.8,0],[7.8,0]],"id":39318320},{"atb":[[4.6,0]],"id":43154455},{"atb":[[10.5,6.14],[12.5,0],[15,0]],"id":38256919},{"atb":[[1.46,0],[1.31,173.67],[1.34,0]],"id":42189480}],"con":true,"img":false}]}
{"op":"mcm","clk":"5306672899","pt":1646103249675,"mc":[{"id":"1.195395426","rc":[{"atb":[[1.54,85.88]],"id":36104892},{"atl":[[2.42,35.31],[2.66,42.08]],"id":43154454},{"atb":[[6.8,6.36],[5.9,10.82]],"id":39318320},{"atb":[[4.1,18.54]],"id":43154455},{"atb":[[13,2.98]],"id":38256919},{"atb":[[1.35,105.57]],"id":42189480}],"con":true,"img":false}]}
{"op":"mcm","clk":"5306672999","pt":1646103252084,"mc":[{"id":"1.195395426","rc":[{"atb":[[1.49,17.04]],"id":42189480}],"con":true,"img":false}]}
{"op":"mcm","clk":"5306673071","pt":1646103254181,"mc":[{"id":"1.195395426","rc":[{"atb":[[8,0]],"id":39318320}],"con":true,"img":false}]}
{"op":"mcm","clk":"5306673077","pt":1646103254383,"mc":[{"id":"1.195395426","rc":[{"atb":[[7,1.66]],"id":39318320},{"atb":[[13.5,1.66]],"id":38256919}],"con":true,"img":false}]}
{"op":"mcm","clk":"5306673219","pt":1646103257969,"mc":[{"id":"1.195395426","rc":[{"atb":[[1.38,19.61]],"id":42189480}],"con":true,"img":false}]}
{"op":"mcm","clk":"5306673423","pt":1646103263388,"mc":[{"id":"1.195395426","rc":[{"spn":1.71,"spf":"NaN","id":43154454},{"spn":15.5,"spf":"NaN","id":39318320},{"spn":41.75,"spf":"NaN","id":38256919},{"atb":[[1.49,0]],"id":42189480},{"spn":2.06,"spf":"NaN","id":42189480}],"con":true,"img":false}]}
{"op":"mcm","clk":"5306673430","pt":1646103263591,"mc":[{"id":"1.195395426","rc":[{"atl":[[21,2.7]],"id":43154455}],"con":true,"img":false}]}
{"op":"mcm","clk":"5306673432","pt":1646103263695,"mc":[{"id":"1.195395426","rc":[{"atl":[[6,0]],"id":36104892},{"atl":[[13,0]],"id":38859241},{"atl":[[2.42,30.86]],"id":43154454},{"atl":[[46,0]],"id":39318320},{"atl":[[26,0]],"id":43154455},{"atl":[[100,0]],"id":38256919},{"atl":[[3.7,0]],"id":42189480}],"con":true,"img":false}]}
{"op":"mcm","clk":"5306673435","pt":1646103263796,"mc":[{"id":"1.195395426","rc":[{"atl":[[5,8.83]],"id":36104892},{"atl":[[11.5,3.32]],"id":38859241},{"atl":[[38,2.72]],"id":39318320},{"atl":[[80,0.43]],"id":38256919},{"atl":[[3.2,16.03]],"id":42189480}],"con":true,"img":false}]}
{"op":"mcm","clk":"5306673716","pt":1646103270877,"mc":[{"id":"1.195395426","rc":[{"atb":[[1.38,41.59]],"id":42189480}],"con":true,"img":false}]}
{"op":"mcm","clk":"5306674534","pt":1646103292530,"mc":[{"id":"1.195395426","rc":[{"atl":[[6.8,0],[5.7,11.51]],"id":36104892},{"atl":[[13,5.09],[15.5,0]],"id":38859241}],"con":true,"img":false}]}
{"op":"mcm","clk":"5306674536","pt":1646103292633,"mc":[{"id":"1.195395426","rc":[{"atb":[[1.16,0]],"id":43154454},{"atl":[[50,0]],"id":39318320},{"atl":[[28,0]],"id":43154455},{"atl":[[110,0]],"id":38256919},{"atl":[[4.1,0]],"id":42189480}],"con":true,"img":false}]}
{"op":"mcm","clk":"5306674539","pt":1646103292735,"mc":[{"id":"1.195395426","rc":[{"atb":[[1.19,356.48]],"id":43154454},{"atl":[[42,2.7]],"id":39318320},{"atl":[[23,2.7]],"id":43154455},{"atl":[[90,2.7]],"id":38256919},{"atl":[[3.6,17.36]],"id":42189480}],"con":true,"img":false}]}
{"op":"mcm","clk":"5306675218","pt":1646103307112,"mc":[{"id":"1.195395426","rc":[{"atb":[[1.35,0]],"id":42189480}],"con":true,"img":false}]}
{"op":"mcm","clk":"5306675226","pt":1646103307213,"mc":[{"id":"1.195395426","rc":[{"atb":[[1.39,105.57]],"id":42189480}],"con":true,"img":false}]}
{"op":"mcm","clk":"5306675310","pt":1646103309112,"mc":[{"id":"1.195395426","rc":[{"atb":[[1.38,21.97]],"id":42189480}],"con":true,"img":false}]}
{"op":"mcm","clk":"5306675550","pt":1646103315365,"mc":[{"id":"1.195395426","rc":[{"atb":[[1.42,17.74]],"id":42189480}],"con":true,"img":false}]}
{"op":"mcm","clk":"5306675957","pt":1646103325247,"mc":[{"id":"1.195395426","rc":[{"atb":[[1.38,0]],"id":42189480},{"spn":2.08,"spf":"NaN","id":42189480}],"con":true,"img":false}]}
{"op":"mcm","clk":"5306676265","pt":1646103332258,"mc":[{"id":"1.195395426","rc":[{"atb":[[1.42,37.62]],"id":42189480}],"con":true,"img":false}]}
{"op":"mcm","clk":"5306677617","pt":1646103363286,"mc":[{"id":"1.195395426","rc":[{"atb":[[1.39,0]],"id":42189480}],"con":true,"img":false}]}
{"op":"mcm","clk":"5306677620","pt":1646103363388,"mc":[{"id":"1.195395426","rc":[{"atb":[[1.43,105.57]],"id":42189480}],"con":true,"img":false}]}
{"op":"mcm","clk":"5306677822","pt":1646103367194,"mc":[{"id":"1.195395426","rc":[{"atb":[[1.42,19.87]],"id":42189480}],"con":true,"img":false}]}
{"op":"mcm","clk":"5306678148","pt":1646103375111,"mc":[{"id":"1.195395426","rc":[{"atb":[[1.46,16.2]],"id":42189480}],"con":true,"img":false}]}
{"op":"mcm","clk":"5306678305","pt":1646103378858,"mc":[{"id":"1.195395426","rc":[{"atb":[[1.42,0]],"id":42189480}],"con":true,"img":false}]}
{"op":"mcm","clk":"5306678602","pt":1646103385229,"mc":[{"id":"1.195395426","rc":[{"atb":[[1.46,34.35]],"id":42189480}],"con":true,"img":false}]}
{"op":"mcm","clk":"5306679805","pt":1646103415444,"mc":[{"id":"1.195395426","marketDefinition":{"bspMarket":true,"turnInPlayEnabled":false,"persistenceEnabled":false,"marketBaseRate":7.0,"eventId":"31270458","eventTypeId":"4339","numberOfWinners":2,"bettingType":"ODDS","marketType":"PLACE","marketTime":"2022-03-01T03:57:00.000Z","suspendTime":"2022-03-01T03:57:00.000Z","bspReconciled":false,"complete":true,"inPlay":false,"crossMatching":true,"runnersVoidable":false,"numberOfActiveRunners":7,"betDelay":0,"status":"OPEN","runners":[{"status":"ACTIVE","sortPriority":1,"id":43154454,"name":"1. Buckle Up Iveta"},{"status":"ACTIVE","sortPriority":2,"id":38859241,"name":"2. Theo Dragonet"},{"status":"ACTIVE","sortPriority":3,"id":39318320,"name":"3. Engage The Rage"},{"status":"ACTIVE","sortPriority":4,"id":42189480,"name":"4. Toxic Turtle"},{"status":"ACTIVE","sortPriority":5,"id":36104892,"name":"5. Bridwood Ali"},{"status":"ACTIVE","sortPriority":6,"id":38256919,"name":"6. Warramunga"},{"status":"ACTIVE","sortPriority":7,"id":43154455,"name":"8. Strait Sambuca"}],"regulators":["MR_INT"],"venue":"Devonport","countryCode":"AU","discountAllowed":true,"timezone":"Australia/Sydney","openDate":"2022-03-01T02:00:00.000Z","version":4381084679,"name":"To Be Placed","eventName":"Devonport (AUS) 1st Mar"},"rc":[],"con":true,"img":false}]}
{"op":"mcm","clk":"5306679909","pt":1646103418418,"mc":[{"id":"1.195395426","rc":[{"atb":[[1.43,0]],"id":42189480},{"spn":2.1,"spf":"NaN","id":42189480}],"con":true,"img":false}]}
{"op":"mcm","clk":"5306679913","pt":1646103418471,"mc":[{"id":"1.195395426","rc":[{"atb":[[1.47,105.57]],"id":42189480}],"con":true,"img":false}]}
{"op":"mcm","clk":"5306679948","pt":1646103419599,"mc":[{"id":"1.195395426","rc":[{"atb":[[1.46,18.15]],"id":42189480}],"con":true,"img":false}]}
{"op":"mcm","clk":"5306680180","pt":1646103425510,"mc":[{"id":"1.195395426","rc":[{"atb":[[1.5,14.9]],"id":42189480}],"con":true,"img":false}]}
{"op":"mcm","clk":"5306680181","pt":1646103425612,"mc":[{"id":"1.195395426","rc":[{"atl":[[4.9,8.84]],"id":36104892},{"atb":[[2.72,58.14]],"id":38859241},{"atl":[[11,3.33]],"id":38859241},{"atl":[[2.4,30.86]],"id":43154454},{"atb":[[4.7,27.03]],"id":39318320},{"atl":[[40,2.56]],"id":39318320},{"atb":[[2.22,81.97]],"id":43154455},{"atl":[[34,2.74]],"id":43154455},{"atb":[[1.41,243.9]],"id":38256919},{"atl":[[85,2]],"id":38256919},{"atb":[[1.48,105.58]],"id":42189480},{"atl":[[11,10]],"id":42189480}],"con":true,"img":false}]}
{"op":"mcm","clk":"5306680260","pt":1646103428507,"mc":[{"id":"1.195395426","rc":[{"atb":[[1.5,0]],"id":42189480}],"con":true,"img":false}]}
{"op":"mcm","clk":"5306680356","pt":1646103431226,"mc":[{"id":"1.195395426","rc":[{"atb":[[1.46,0]],"id":42189480}],"con":true,"img":false}]}
{"op":"mcm","clk":"5306680450","pt":1646103434506,"mc":[{"id":"1.195395426","rc":[{"atb":[[1.51,14.61]],"id":42189480}],"con":true,"img":false}]}
{"op":"mcm","clk":"5306680737","pt":1646103443215,"mc":[{"id":"1.195395426","rc":[{"atb":[[1.51,30.98]],"id":42189480}],"con":true,"img":false}]}
{"op":"mcm","clk":"5306681283","pt":1646103459736,"mc":[{"id":"1.195395426","rc":[{"atl":[[2.42,0.37]],"id":43154454}],"con":true,"img":false}]}
{"op":"mcm","clk":"5306681287","pt":1646103459839,"mc":[{"id":"1.195395426","rc":[{"atl":[[2.38,30.48]],"id":43154454}],"con":true,"img":false}]}
{"op":"mcm","clk":"5306681385","pt":1646103462656,"mc":[{"id":"1.195395426","rc":[{"atl":[[2.4,0],[2.36,30.49]],"id":43154454},{"atb":[[1.52,105.58]],"id":42189480}],"con":true,"img":false}]}
{"op":"mcm","clk":"5306681389","pt":1646103462758,"mc":[{"id":"1.195395426","rc":[{"atb":[[1.48,0]],"id":42189480}],"con":true,"img":false}]}
{"op":"mcm","clk":"5306681467","pt":1646103464656,"mc":[{"id":"1.195395426","rc":[{"atb":[[1.51,16.37]],"id":42189480}],"con":true,"img":false}]}
{"op":"mcm","clk":"5306681676","pt":1646103470543,"mc":[{"id":"1.195395426","rc":[{"atb":[[1.55,13.54]],"id":42189480}],"con":true,"img":false}]}
{"op":"mcm","clk":"5306681777","pt":1646103473160,"mc":[{"id":"1.195395426","rc":[{"atb":[[1.52,179.23]],"id":42189480}],"con":true,"img":false}]}
{"op":"mcm","clk":"5306681780","pt":1646103473262,"mc":[{"id":"1.195395426","rc":[{"atl":[[42,0]],"id":39318320},{"atl":[[90,0]],"id":38256919},{"atb":[[1.47,0]],"id":42189480}],"con":true,"img":false}]}
{"op":"mcm","clk":"5306681782","pt":1646103473366,"mc":[{"id":"1.195395426","rc":[{"atl":[[38,5.42]],"id":39318320},{"atl":[[80,3.14]],"id":38256919}],"con":true,"img":false}]}
{"op":"mcm","clk":"5306681786","pt":1646103473467,"mc":[{"id":"1.195395426","rc":[{"atl":[[36,2.56]],"id":39318320},{"atl":[[75,2],[85,0]],"id":38256919}],"con":true,"img":false}]}
{"op":"mcm","clk":"5306681790","pt":1646103473569,"mc":[{"id":"1.195395426","rc":[{"atl":[[40,0]],"id":39318320}],"con":true,"img":false}]}
{"op":"mcm","clk":"5306681842","pt":1646103475564,"mc":[{"id":"1.195395426","rc":[{"atb":[[1.51,0]],"id":42189480}],"con":true,"img":false}]}
{"op":"mcm","clk":"5306682008","pt":1646103481200,"mc":[{"id":"1.195395426","rc":[{"atb":[[1.55,28.72]],"id":42189480},{"spn":2.14,"spf":"NaN","id":42189480}],"con":true,"img":false}]}
{"op":"mcm","clk":"5306682159","pt":1646103486313,"mc":[{"id":"1.195395426","rc":[{"atl":[[38,2.72]],"id":39318320},{"atl":[[80,0.43]],"id":38256919}],"con":true,"img":false}]}
{"op":"mcm","clk":"5306682164","pt":1646103486364,"mc":[{"id":"1.195395426","rc":[{"atl":[[42,2.7]],"id":39318320},{"atl":[[90,2.7]],"id":38256919}],"con":true,"img":false}]}
{"op":"mcm","clk":"5306682169","pt":1646103486465,"mc":[{"id":"1.195395426","rc":[{"atl":[[75,0],[80,2.43]],"id":38256919}],"con":true,"img":false}]}
{"op":"mcm","clk":"5306682560","pt":1646103499299,"mc":[{"id":"1.195395426","rc":[{"atb":[[1.56,173.68],[1.52,73.65]],"id":42189480}],"con":true,"img":false}]}
{"op":"mcm","clk":"5306682575","pt":1646103500014,"mc":[{"id":"1.195395426","rc":[{"atl":[[2.38,0]],"id":43154454},{"atb":[[1.52,0]],"id":42189480}],"con":true,"img":false}]}
{"op":"mcm","clk":"5306682576","pt":1646103500115,"mc":[{"id":"1.195395426","rc":[{"atl":[[2.42,31.3],[2.34,30.48]],"id":43154454},{"atb":[[1.53,73.65]],"id":42189480}],"con":true,"img":false}]}
{"op":"mcm","clk":"5306682582","pt":1646103500217,"mc":[{"id":"1.195395426","rc":[{"atl":[[2.36,0]],"id":43154454}],"con":true,"img":false}]}
{"op":"mcm","clk":"5306682598","pt":1646103500728,"mc":[{"id":"1.195395426","rc":[{"atb":[[1.55,15.17]],"id":42189480}],"con":true,"img":false}]}
{"op":"mcm","clk":"5306682764","pt":1646103506608,"mc":[{"id":"1.195395426","rc":[{"atb":[[1.6,12.42]],"id":42189480}],"con":true,"img":false}]}
{"op":"mcm","clk":"5306682944","pt":1646103513819,"mc":[{"id":"1.195395426","rc":[{"atl":[[38,0.01]],"id":39318320}],"con":true,"img":false}]}
{"op":"mcm","clk":"5306682950","pt":1646103513922,"mc":[{"id":"1.195395426","rc":[{"atl":[[34,2.7]],"id":39318320}],"con":true,"img":false}]}
{"op":"mcm","clk":"5306683077","pt":1646103518227,"mc":[{"id":"1.195395426","rc":[{"atb":[[1.55,0]],"id":42189480}],"con":true,"img":false}]}
{"op":"mcm","clk":"5306683216","pt":1646103523454,"mc":[{"id":"1.195395426","rc":[{"atb":[[1.6,26.34]],"id":42189480}],"con":true,"img":false}]}
{"op":"mcm","clk":"5306683315","pt":1646103527038,"mc":[{"id":"1.195395426","rc":[{"atb":[[1.53,0]],"id":42189480}],"con":true,"img":false}]}
{"op":"mcm","clk":"5306683318","pt":1646103527141,"mc":[{"id":"1.195395426","rc":[{"atb":[[1.57,73.65]],"id":42189480}],"con":true,"img":false}]}
{"op":"mcm","clk":"5306683348","pt":1646103528371,"mc":[{"id":"1.195395426","rc":[{"atb":[[1.6,13.91]],"id":42189480}],"con":true,"img":false}]}
{"op":"mcm","clk":"5306683509","pt":1646103534766,"mc":[{"id":"1.195395426","rc":[{"atb":[[1.61,12.21]],"id":42189480}],"con":true,"img":false}]}
{"op":"mcm","clk":"5306683541","pt":1646103535637,"mc":[{"id":"1.195395426","rc":[{"atb":[[1.56,0],[1.62,13.92]],"id":42189480}],"con":true,"img":false}]}
{"op":"mcm","clk":"5306683554","pt":1646103536456,"mc":[{"id":"1.195395426","rc":[{"atl":[[2.32,30.49]],"id":43154454}],"con":true,"img":false}]}
{"op":"mcm","clk":"5306683555","pt":1646103536556,"mc":[{"id":"1.195395426","rc":[{"atl":[[2.42,0.37]],"id":43154454}],"con":true,"img":false}]}
{"op":"mcm","clk":"5306683657","pt":1646103541465,"mc":[{"id":"1.195395426","rc":[{"atb":[[1.6,0]],"id":42189480},{"spn":2.18,"spf":"NaN","id":42189480}],"con":true,"img":false}]}
{"op":"mcm","clk":"5306683806","pt":1646103546789,"mc":[{"id":"1.195395426","rc":[{"atl":[[90,0]],"id":38256919},{"atb":[[1.57,0]],"id":42189480}],"con":true,"img":false}]}
{"op":"mcm","clk":"5306683813","pt":1646103546893,"mc":[{"id":"1.195395426","rc":[{"atl":[[75,2.7]],"id":38256919},{"atb":[[1.35,73.65]],"id":42189480}],"con":true,"img":false}]}
{"op":"mcm","clk":"5306683820","pt":1646103546994,"mc":[{"id":"1.195395426","rc":[{"atl":[[140,2],[80,0.43]],"id":38256919}],"con":true,"img":false}]}
{"op":"mcm","clk":"5306683823","pt":1646103547093,"mc":[{"id":"1.195395426","rc":[{"atl":[[140,0],[75,4.7]],"id":38256919}],"con":true,"img":false}]}
{"op":"mcm","clk":"5306683828","pt":1646103547200,"mc":[{"id":"1.195395426","rc":[{"atl":[[80,2.43]],"id":38256919}],"con":true,"img":false}]}
{"op":"mcm","clk":"5306683829","pt":1646103547301,"mc":[{"id":"1.195395426","rc":[{"atl":[[75,2.7]],"id":38256919}],"con":true,"img":false}]}
{"op":"mcm","clk":"5306683899","pt":1646103549404,"mc":[{"id":"1.195395426","rc":[{"atb":[[1.61,0]],"id":42189480}],"con":true,"img":false}]}
{"op":"mcm","clk":"5306683904","pt":1646103549504,"mc":[{"id":"1.195395426","rc":[{"atb":[[1.36,173.68],[1.62,0]],"id":42189480}],"con":true,"img":false}]}
{"op":"mcm","clk":"5306684236","pt":1646103558725,"mc":[{"id":"1.195395426","rc":[{"atb":[[1.39,19.11]],"id":42189480}],"con":true,"img":false}]}
{"op":"mcm","clk":"5306684439","pt":1646103565691,"mc":[{"id":"1.195395426","rc":[{"atb":[[1.39,40.51]],"id":42189480}],"con":true,"img":false}]}
{"op":"mcm","clk":"5306684469","pt":1646103566716,"mc":[{"id":"1.195395426","rc":[{"atl":[[2.34,0]],"id":43154454}],"con":true,"img":false}]}
{"op":"mcm","clk":"5306684473","pt":1646103566817,"mc":[{"id":"1.195395426","rc":[{"atl":[[2.3,30.48]],"id":43154454}],"con":true,"img":false}]}
