{"op":"mcm","clk":"5352134788","pt":1646183310066,"mc":[{"id":"1.195503853","marketDefinition":{"bspMarket":false,"turnInPlayEnabled":false,"persistenceEnabled":false,"marketBaseRate":7.0,"eventId":"31272499","eventTypeId":"4339","numberOfWinners":1,"bettingType":"ODDS","marketType":"MATCH_BET","marketTime":"2022-03-02T10:15:00.000Z","suspendTime":"2022-03-02T10:15:00.000Z","bspReconciled":false,"complete":true,"inPlay":false,"crossMatching":true,"runnersVoidable":false,"numberOfActiveRunners":2,"betDelay":0,"status":"OPEN","runners":[{"status":"ACTIVE","sortPriority":1,"id":39786791,"name":"3. Tiger Talks"},{"status":"ACTIVE","sortPriority":2,"id":43167135,"name":"4. Pereira"}],"regulators":["MR_INT"],"venue":"Rockhampton","countryCode":"AU","discountAllowed":true,"timezone":"Australia/Queensland","openDate":"2022-03-02T08:34:00.000Z","version":4382585408,"name":"Tiger Talks v Pereira","eventName":"Rockhampton (AUS) 2nd Mar"},"rc":[],"con":true,"img":false}]}
{"op":"mcm","clk":"5352139712","pt":1646183422125,"mc":[{"id":"1.195503853","rc":[{"atb":[[1.45,11.99],[1.85,6.35],[1.65,8.3]],"id":43167135},{"atb":[[1.72,7.49],[1.32,16.87],[1.52,10.38]],"id":39786791}],"con":true,"img":false}]}
{"op":"mcm","clk":"5352146174","pt":1646183572636,"mc":[{"id":"1.195503853","marketDefinition":{"bspMarket":false,"turnInPlayEnabled":false,"persistenceEnabled":false,"marketBaseRate":7.0,"eventId":"31272499","eventTypeId":"4339","numberOfWinners":1,"bettingType":"ODDS","marketType":"MATCH_BET","marketTime":"2022-03-02T10:15:00.000Z","suspendTime":"2022-03-02T10:15:00.000Z","bspReconciled":false,"complete":true,"inPlay":false,"crossMatching":true,"runnersVoidable":false,"numberOfActiveRunners":2,"betDelay":0,"status":"OPEN","runners":[{"status":"ACTIVE","sortPriority":1,"id":39786791,"name":"3. Tiger Talks"},{"status":"ACTIVE","sortPriority":2,"id":43167135,"name":"4. Pereira"}],"regulators":["MR_INT"],"venue":"Rockhampton","countryCode":"AU","discountAllowed":true,"timezone":"Australia/Queensland","openDate":"2022-03-02T08:28:00.000Z","version":4382597874,"name":"Tiger Talks v Pereira","eventName":"Rockhampton (AUS) 2nd Mar"},"rc":[],"con":true,"img":false}]}
{"op":"mcm","clk":"5352160129","pt":1646183941426,"mc":[{"id":"1.195503853","marketDefinition":{"bspMarket":false,"turnInPlayEnabled":false,"persistenceEnabled":false,"marketBaseRate":7.0,"eventId":"31272499","eventTypeId":"4339","numberOfWinners":1,"bettingType":"ODDS","marketType":"MATCH_BET","marketTime":"2022-03-02T10:08:00.000Z","suspendTime":"2022-03-02T10:08:00.000Z","bspReconciled":false,"complete":true,"inPlay":false,"crossMatching":true,"runnersVoidable":false,"numberOfActiveRunners":2,"betDelay":0,"status":"OPEN","runners":[{"status":"ACTIVE","sortPriority":1,"id":39786791,"name":"3. Tiger Talks"},{"status":"ACTIVE","sortPriority":2,"id":43167135,"name":"4. Pereira"}],"regulators":["MR_INT"],"venue":"Rockhampton","countryCode":"AU","discountAllowed":true,"timezone":"Australia/Queensland","openDate":"2022-03-02T08:28:00.000Z","version":4382604311,"name":"Tiger Talks v Pereira","eventName":"Rockhampton (AUS) 2nd Mar"},"rc":[],"con":true,"img":false}]}
{"op":"mcm","clk":"5352466699","pt":1646191002690,"mc":[{"id":"1.195503853","marketDefinition":{"bspMarket":false,"turnInPlayEnabled":false,"persistenceEnabled":false,"marketBaseRate":7.0,"eventId":"31272499","eventTypeId":"4339","numberOfWinners":1,"bettingType":"ODDS","marketType":"MATCH_BET","marketTime":"2022-03-02T10:08:00.000Z","suspendTime":"2022-03-02T10:08:00.000Z","bspReconciled":false,"complete":true,"inPlay":false,"crossMatching":true,"runnersVoidable":false,"numberOfActiveRunners":2,"betDelay":0,"status":"OPEN","runners":[{"status":"ACTIVE","sortPriority":1,"id":39786791,"name":"3. Tiger Talks"},{"status":"ACTIVE","sortPriority":2,"id":43167135,"name":"4. Pereira"}],"regulators":["MR_INT"],"venue":"Rockhampton","countryCode":"AU","discountAllowed":true,"timezone":"Australia/Queensland","openDate":"2022-03-02T08:28:00.000Z","version":4382604311,"name":"Tiger Talks v Pereira","eventName":"Rockhampton (AUS) 2nd Mar"},"rc":[{"atb":[[1.45,12.01],[1.85,6.36],[1.65,8.31]],"id":43167135},{"atb":[[1.72,7.51],[1.32,16.89],[1.52,10.39]],"id":39786791}],"con":true,"img":true}]}
{"op":"mcm","clk":"5352823507","pt":1646201802741,"mc":[{"id":"1.195503853","marketDefinition":{"bspMarket":false,"turnInPlayEnabled":false,"persistenceEnabled":false,"marketBaseRate":7.0,"eventId":"31272499","eventTypeId":"4339","numberOfWinners":1,"bettingType":"ODDS","marketType":"MATCH_BET","marketTime":"2022-03-02T10:08:00.000Z","suspendTime":"2022-03-02T10:08:00.000Z","bspReconciled":false,"complete":true,"inPlay":false,"crossMatching":true,"runnersVoidable":false,"numberOfActiveRunners":2,"betDelay":0,"status":"OPEN","runners":[{"status":"ACTIVE","sortPriority":1,"id":39786791,"name":"3. Tiger Talks"},{"status":"ACTIVE","sortPriority":2,"id":43167135,"name":"4. Pereira"}],"regulators":["MR_INT"],"venue":"Rockhampton","countryCode":"AU","discountAllowed":true,"timezone":"Australia/Queensland","openDate":"2022-03-02T08:28:00.000Z","version":4382604311,"name":"Tiger Talks v Pereira","eventName":"Rockhampton (AUS) 2nd Mar"},"rc":[{"atb":[[1.45,12.01],[1.85,6.36],[1.65,8.31]],"id":43167135},{"atb":[[1.72,7.5],[1.32,16.89],[1.52,10.39]],"id":39786791}],"con":true,"img":true}]}
{"op":"mcm","clk":"5353028877","pt":1646207202758,"mc":[{"id":"1.195503853","marketDefinition":{"bspMarket":false,"turnInPlayEnabled":false,"persistenceEnabled":false,"marketBaseRate":7.0,"eventId":"31272499","eventTypeId":"4339","numberOfWinners":1,"bettingType":"ODDS","marketType":"MATCH_BET","marketTime":"2022-03-02T10:08:00.000Z","suspendTime":"2022-03-02T10:08:00.000Z","bspReconciled":false,"complete":true,"inPlay":false,"crossMatching":true,"runnersVoidable":false,"numberOfActiveRunners":2,"betDelay":0,"status":"OPEN","runners":[{"status":"ACTIVE","sortPriority":1,"id":39786791,"name":"3. Tiger Talks"},{"status":"ACTIVE","sortPriority":2,"id":43167135,"name":"4. Pereira"}],"regulators":["MR_INT"],"venue":"Rockhampton","countryCode":"AU","discountAllowed":true,"timezone":"Australia/Queensland","openDate":"2022-03-02T08:28:00.000Z","version":4382604311,"name":"Tiger Talks v Pereira","eventName":"Rockhampton (AUS) 2nd Mar"},"rc":[{"atb":[[1.45,12],[1.85,6.35],[1.65,8.31]],"id":43167135},{"atb":[[1.72,7.5],[1.32,16.88],[1.52,10.39]],"id":39786791}],"con":true,"img":true}]}
{"op":"mcm","clk":"5353300263","pt":1646212602761,"mc":[{"id":"1.195503853","marketDefinition":{"bspMarket":false,"turnInPlayEnabled":false,"persistenceEnabled":false,"marketBaseRate":7.0,"eventId":"31272499","eventTypeId":"4339","numberOfWinners":1,"bettingType":"ODDS","marketType":"MATCH_BET","marketTime":"2022-03-02T10:08:00.000Z","suspendTime":"2022-03-02T10:08:00.000Z","bspReconciled":false,"complete":true,"inPlay":false,"crossMatching":true,"runnersVoidable":false,"numberOfActiveRunners":2,"betDelay":0,"status":"OPEN","runners":[{"status":"ACTIVE","sortPriority":1,"id":39786791,"name":"3. Tiger Talks"},{"status":"ACTIVE","sortPriority":2,"id":43167135,"name":"4. Pereira"}],"regulators":["MR_INT"],"venue":"Rockhampton","countryCode":"AU","discountAllowed":true,"timezone":"Australia/Queensland","openDate":"2022-03-02T08:28:00.000Z","version":4382604311,"name":"Tiger Talks v Pereira","eventName":"Rockhampton (AUS) 2nd Mar"},"rc":[{"atb":[[1.45,11.98],[1.85,6.34],[1.65,8.3]],"id":43167135},{"atb":[[1.72,7.49],[1.32,16.86],[1.52,10.37]],"id":39786791}],"con":true,"img":true}]}
{"op":"mcm","clk":"5353413599","pt":1646214487242,"mc":[{"id":"1.195503853","rc":[{"atb":[[1.45,11.98],[1.85,6.34],[1.86,2],[1.65,8.3]],"id":43167135},{"atl":[[2.44,2]],"id":43167135},{"atb":[[1.73,2],[1.72,7.49],[1.32,16.86],[1.52,10.37]],"id":39786791},{"atl":[[2.28,2]],"id":39786791}],"con":true,"img":false}]}
{"op":"mcm","clk":"5353418313","pt":1646214575313,"mc":[{"id":"1.195503853","rc":[{"atb":[[1.85,8.34],[1.86,0]],"id":43167135}],"con":true,"img":false}]}
{"op":"mcm","clk":"5353420054","pt":1646214608218,"mc":[{"id":"1.195503853","rc":[{"atl":[[2.42,2]],"id":43167135}],"con":true,"img":false}]}
{"op":"mcm","clk":"5353420061","pt":1646214608321,"mc":[{"id":"1.195503853","rc":[{"atl":[[2.44,0]],"id":43167135}],"con":true,"img":false}]}
{"op":"mcm","clk":"5353422620","pt":1646214661841,"mc":[{"id":"1.195503853","rc":[{"atl":[[2.26,2]],"id":39786791}],"con":true,"img":false}]}
{"op":"mcm","clk":"5353422626","pt":1646214661946,"mc":[{"id":"1.195503853","rc":[{"atl":[[2.28,0]],"id":39786791}],"con":true,"img":false}]}
{"op":"mcm","clk":"5353422855","pt":1646214667048,"mc":[{"id":"1.195503853","rc":[{"atl":[[2.22,2],[2.26,0]],"id":39786791}],"con":true,"img":false}]}
{"op":"mcm","clk":"5353424772","pt":1646214708206,"mc":[{"id":"1.195503853","rc":[{"atl":[[2.22,0],[2.2,2]],"id":39786791}],"con":true,"img":false}]}
{"op":"mcm","clk":"5353425035","pt":1646214713429,"mc":[{"id":"1.195503853","rc":[{"atl":[[2.22,2],[2.2,0]],"id":39786791}],"con":true,"img":false}]}
{"op":"mcm","clk":"5353428571","pt":1646214780526,"mc":[{"id":"1.195503853","rc":[{"atl":[[2.22,0],[2.18,2]],"id":39786791}],"con":true,"img":false}]}
{"op":"mcm","clk":"5353428749","pt":1646214784350,"mc":[{"id":"1.195503853","rc":[{"atl":[[2.32,2],[2.42,0]],"id":43167135},{"atl":[[2.22,2],[2.18,0]],"id":39786791}],"con":true,"img":false}]}
{"op":"mcm","clk":"5353428756","pt":1646214784454,"mc":[{"id":"1.195503853","rc":[{"atb":[[1.73,0],[1.76,2]],"id":39786791}],"con":true,"img":false}]}
{"op":"mcm","clk":"5353429007","pt":1646214789460,"mc":[{"id":"1.195503853","rc":[{"atl":[[2.24,2]],"id":43167135}],"con":true,"img":false}]}
{"op":"mcm","clk":"5353429010","pt":1646214789561,"mc":[{"id":"1.195503853","rc":[{"atl":[[2.32,0]],"id":43167135},{"atb":[[1.78,2]],"id":39786791}],"con":true,"img":false}]}
{"op":"mcm","clk":"5353429015","pt":1646214789665,"mc":[{"id":"1.195503853","rc":[{"atb":[[1.76,0]],"id":39786791}],"con":true,"img":false}]}
{"op":"mcm","clk":"5353429065","pt":1646214790646,"mc":[{"id":"1.195503853","rc":[{"atb":[[1.78,0],[1.77,2]],"id":39786791}],"con":true,"img":false}]}
{"op":"mcm","clk":"5353429075","pt":1646214790852,"mc":[{"id":"1.195503853","rc":[{"atb":[[1.78,2],[1.77,0]],"id":39786791}],"con":true,"img":false}]}
{"op":"mcm","clk":"5353429617","pt":1646214800852,"mc":[{"id":"1.195503853","rc":[{"atb":[[1.79,2],[1.78,0]],"id":39786791}],"con":true,"img":false}]}
{"op":"mcm","clk":"5353430125","pt":1646214810852,"mc":[{"id":"1.195503853","rc":[{"atb":[[1.73,2],[1.79,0]],"id":39786791}],"con":true,"img":false}]}
{"op":"mcm","clk":"5353430618","pt":1646214819822,"mc":[{"id":"1.195503853","rc":[{"atb":[[1.45,0],[1.85,2],[1.65,0]],"id":43167135},{"atb":[[1.72,0],[1.32,0],[1.52,0]],"id":39786791}],"con":true,"img":false}]}
{"op":"mcm","clk":"5353430884","pt":1646214825600,"mc":[{"id":"1.195503853","rc":[{"atb":[[1.45,11.98],[1.85,8.34],[1.65,8.3]],"id":43167135},{"atb":[[1.73,0],[1.72,7.49],[1.32,16.86],[1.76,2],[1.52,10.37]],"id":39786791}],"con":true,"img":false}]}
{"op":"mcm","clk":"5353430892","pt":1646214825707,"mc":[{"id":"1.195503853","rc":[{"atb":[[1.77,2]],"id":39786791}],"con":true,"img":false}]}
{"op":"mcm","clk":"5353430894","pt":1646214825808,"mc":[{"id":"1.195503853","rc":[{"atb":[[1.76,0]],"id":39786791}],"con":true,"img":false}]}
{"op":"mcm","clk":"5353431213","pt":1646214830915,"mc":[{"id":"1.195503853","rc":[{"atb":[[1.78,2],[1.77,0]],"id":39786791}],"con":true,"img":false}]}
{"op":"mcm","clk":"5353431502","pt":1646214835921,"mc":[{"id":"1.195503853","rc":[{"atb":[[1.79,2],[1.78,0]],"id":39786791}],"con":true,"img":false}]}
{"op":"mcm","clk":"5353431517","pt":1646214836117,"mc":[{"id":"1.195503853","rc":[{"atb":[[1.73,2],[1.79,0]],"id":39786791}],"con":true,"img":false}]}
{"op":"mcm","clk":"5353432111","pt":1646214847414,"mc":[{"id":"1.195503853","rc":[{"atb":[[1.77,2]],"id":39786791}],"con":true,"img":false}]}
{"op":"mcm","clk":"5353432117","pt":1646214847519,"mc":[{"id":"1.195503853","rc":[{"atb":[[1.73,0]],"id":39786791}],"con":true,"img":false}]}
{"op":"mcm","clk":"5353432337","pt":1646214851512,"mc":[{"id":"1.195503853","rc":[{"atb":[[1.78,2],[1.77,0]],"id":39786791}],"con":true,"img":false}]}
{"op":"mcm","clk":"5353433028","pt":1646214864531,"mc":[{"id":"1.195503853","rc":[{"atb":[[1.79,2],[1.78,0]],"id":39786791}],"con":true,"img":false}]}
{"op":"mcm","clk":"5353433043","pt":1646214864941,"mc":[{"id":"1.195503853","rc":[{"atb":[[1.73,2],[1.79,0]],"id":39786791}],"con":true,"img":false}]}
{"op":"mcm","clk":"5353433559","pt":1646214875198,"mc":[{"id":"1.195503853","rc":[{"atb":[[1.73,0],[1.77,2]],"id":39786791}],"con":true,"img":false}]}
{"op":"mcm","clk":"5353433827","pt":1646214880373,"mc":[{"id":"1.195503853","rc":[{"atb":[[1.78,2],[1.77,0]],"id":39786791}],"con":true,"img":false}]}
{"op":"mcm","clk":"5353433943","pt":1646214882493,"mc":[{"id":"1.195503853","rc":[{"atb":[[1.79,2],[1.78,0]],"id":39786791}],"con":true,"img":false}]}
{"op":"mcm","clk":"5353434601","pt":1646214895394,"mc":[{"id":"1.195503853","rc":[{"atb":[[1.73,2]],"id":39786791}],"con":true,"img":false}]}
{"op":"mcm","clk":"5353434606","pt":1646214895495,"mc":[{"id":"1.195503853","rc":[{"atb":[[1.79,0]],"id":39786791}],"con":true,"img":false}]}
{"op":"mcm","clk":"5353435116","pt":1646214905827,"mc":[{"id":"1.195503853","rc":[{"atb":[[1.73,0],[1.77,2]],"id":39786791}],"con":true,"img":false}]}
{"op":"mcm","clk":"5353435400","pt":1646214910941,"mc":[{"id":"1.195503853","rc":[{"atb":[[1.78,2],[1.77,0]],"id":39786791}],"con":true,"img":false}]}
{"op":"mcm","clk":"5353435692","pt":1646214916051,"mc":[{"id":"1.195503853","rc":[{"atb":[[1.79,2]],"id":39786791}],"con":true,"img":false}]}
{"op":"mcm","clk":"5353435698","pt":1646214916154,"mc":[{"id":"1.195503853","rc":[{"atb":[[1.78,0]],"id":39786791}],"con":true,"img":false}]}
{"op":"mcm","clk":"5353436043","pt":1646214922556,"mc":[{"id":"1.195503853","rc":[{"atb":[[1.73,2],[1.79,0]],"id":39786791}],"con":true,"img":false}]}
{"op":"mcm","clk":"5353436569","pt":1646214932774,"mc":[{"id":"1.195503853","rc":[{"atb":[[1.73,0],[1.77,2]],"id":39786791}],"con":true,"img":false}]}
{"op":"mcm","clk":"5353436956","pt":1646214937885,"mc":[{"id":"1.195503853","rc":[{"atb":[[1.78,2],[1.77,0]],"id":39786791}],"con":true,"img":false}]}
{"op":"mcm","clk":"5353436980","pt":1646214938350,"mc":[{"id":"1.195503853","rc":[{"atb":[[1.79,2]],"id":39786791}],"con":true,"img":false}]}
{"op":"mcm","clk":"5353436985","pt":1646214938456,"mc":[{"id":"1.195503853","rc":[{"atb":[[1.78,0]],"id":39786791}],"con":true,"img":false}]}
{"op":"mcm","clk":"5353437370","pt":1646214943886,"mc":[{"id":"1.195503853","rc":[{"atb":[[1.73,2],[1.79,0]],"id":39786791}],"con":true,"img":false}]}
{"op":"mcm","clk":"5353437411","pt":1646214944558,"mc":[{"id":"1.195503853","rc":[{"atl":[[2.18,2]],"id":39786791}],"con":true,"img":false}]}
{"op":"mcm","clk":"5353437415","pt":1646214944663,"mc":[{"id":"1.195503853","rc":[{"atl":[[2.22,0]],"id":39786791}],"con":true,"img":false}]}
{"op":"mcm","clk":"5353437558","pt":1646214947560,"mc":[{"id":"1.195503853","rc":[{"atb":[[1.85,6.34],[1.86,2]],"id":43167135}],"con":true,"img":false}]}
{"op":"mcm","clk":"5353437674","pt":1646214949677,"mc":[{"id":"1.195503853","rc":[{"atl":[[2.22,2]],"id":39786791}],"con":true,"img":false}]}
{"op":"mcm","clk":"5353437679","pt":1646214949781,"mc":[{"id":"1.195503853","rc":[{"atl":[[2.18,0]],"id":39786791}],"con":true,"img":false}]}
{"op":"mcm","clk":"5353437937","pt":1646214954788,"mc":[{"id":"1.195503853","rc":[{"atl":[[2.18,2]],"id":39786791}],"con":true,"img":false}]}
{"op":"mcm","clk":"5353437943","pt":1646214954891,"mc":[{"id":"1.195503853","rc":[{"atl":[[2.22,0]],"id":39786791}],"con":true,"img":false}]}
{"op":"mcm","clk":"5353438320","pt":1646214961611,"mc":[{"id":"1.195503853","rc":[{"atl":[[2.18,0],[2.16,2]],"id":39786791}],"con":true,"img":false}]}
{"op":"mcm","clk":"5353444311","pt":1646215077685,"mc":[{"id":"1.195503853","rc":[{"atb":[[1.45,0],[1.85,0],[1.65,0]],"id":43167135},{"atb":[[1.72,0],[1.32,0],[1.52,0]],"id":39786791}],"con":true,"img":false}]}
{"op":"mcm","clk":"5353444559","pt":1646215082174,"mc":[{"id":"1.195503853","rc":[{"atb":[[1.45,11.98],[1.85,6.34],[1.65,8.3]],"id":43167135},{"atb":[[1.72,7.49],[1.32,16.86],[1.52,10.37]],"id":39786791}],"con":true,"img":false}]}
{"op":"mcm","clk":"5353445998","pt":1646215109567,"mc":[{"id":"1.195503853","rc":[{"atb":[[1.64,31],[1.6,2],[1.01,118],[1.37,60],[1.7,22],[1.68,2],[1.23,2],[1.53,43],[1.48,2],[1.16,84],[1.57,2],[1.11,2],[1.06,2],[1.3,2],[1.42,2],[1.66,2]],"id":43167135}],"con":true,"img":false}]}
{"op":"mcm","clk":"5353446106","pt":1646215111373,"mc":[{"id":"1.195503853","rc":[{"atl":[[2.8,12],[3.6,2],[4.3,34],[10.5,1],[3.35,24],[3,2],[6.8,48],[2.84,2],[15,67],[2.92,17],[8.6,2],[2.88,2],[5,2],[3.15,2],[5.7,2],[3.9,2]],"id":43167135}],"con":true,"img":false}]}
{"op":"mcm","clk":"5353446119","pt":1646215111476,"mc":[{"id":"1.195503853","rc":[{"atl":[[2.24,0],[2.52,2]],"id":43167135}],"con":true,"img":false}]}
{"op":"mcm","clk":"5353446251","pt":1646215113600,"mc":[{"id":"1.195503853","rc":[{"atb":[[1.2,2],[1.6,22],[1.01,118],[1.43,43],[1.03,2],[1.58,2],[1.56,2],[1.27,60],[1.54,31],[1.5,2],[1.06,84],[1.32,18.86],[1.13,2],[1.47,2],[1.04,2],[1.38,2]],"id":39786791}],"con":true,"img":false}]}
{"op":"mcm","clk":"5353446348","pt":1646215115307,"mc":[{"id":"1.195503853","rc":[{"atl":[[9,67],[2.54,2],[2.5,12],[5.8,2],[4.9,48],[2.58,2],[2.84,24],[2.62,17],[2.94,2],[3.75,2],[2.76,2],[7.2,2],[3.4,34],[3.15,2],[4.2,2],[2.7,2]],"id":39786791}],"con":true,"img":false}]}
{"op":"mcm","clk":"5353446355","pt":1646215115410,"mc":[{"id":"1.195503853","rc":[{"atl":[[2.26,2],[2.16,0]],"id":39786791}],"con":true,"img":false}]}
{"op":"mcm","clk":"5353446423","pt":1646215116705,"mc":[{"id":"1.195503853","rc":[{"atl":[[2.26,0],[2.24,2]],"id":39786791}],"con":true,"img":false}]}
{"op":"mcm","clk":"5353446646","pt":1646215120010,"mc":[{"id":"1.195503853","rc":[{"atl":[[2.56,2]],"id":43167135}],"con":true,"img":false}]}
{"op":"mcm","clk":"5353446652","pt":1646215120110,"mc":[{"id":"1.195503853","rc":[{"atl":[[2.52,0]],"id":43167135}],"con":true,"img":false}]}
{"op":"mcm","clk":"5353446754","pt":1646215121822,"mc":[{"id":"1.195503853","rc":[{"atl":[[2.24,0],[2.28,2]],"id":39786791}],"con":true,"img":false}]}
{"op":"mcm","clk":"5353446757","pt":1646215121926,"mc":[{"id":"1.195503853","rc":[{"atl":[[2.24,2],[2.28,0]],"id":39786791}],"con":true,"img":false}]}
{"op":"mcm","clk":"5353446798","pt":1646215122599,"mc":[{"id":"1.195503853","rc":[{"atl":[[2.26,2],[2.24,0]],"id":39786791}],"con":true,"img":false}]}
{"op":"mcm","clk":"5353446808","pt":1646215122806,"mc":[{"id":"1.195503853","rc":[{"atl":[[2.32,2],[2.26,0]],"id":39786791}],"con":true,"img":false}]}
{"op":"mcm","clk":"5353446818","pt":1646215123010,"mc":[{"id":"1.195503853","rc":[{"atl":[[2.32,0],[2.34,2]],"id":39786791}],"con":true,"img":false}]}
{"op":"mcm","clk":"5353446833","pt":1646215123319,"mc":[{"id":"1.195503853","rc":[{"atl":[[2.34,0],[2.36,2]],"id":39786791}],"con":true,"img":false}]}
{"op":"mcm","clk":"5353446927","pt":1646215125125,"mc":[{"id":"1.195503853","rc":[{"atl":[[2.56,0],[2.46,2]],"id":43167135}],"con":true,"img":false}]}
{"op":"mcm","clk":"5353446963","pt":1646215125798,"mc":[{"id":"1.195503853","rc":[{"atl":[[2.44,2]],"id":43167135}],"con":true,"img":false}]}
{"op":"mcm","clk":"5353446969","pt":1646215125900,"mc":[{"id":"1.195503853","rc":[{"atl":[[2.46,0]],"id":43167135}],"con":true,"img":false}]}
{"op":"mcm","clk":"5353447293","pt":1646215130829,"mc":[{"id":"1.195503853","rc":[{"atl":[[2.36,0],[2.38,2]],"id":39786791}],"con":true,"img":false}]}
{"op":"mcm","clk":"5353447429","pt":1646215132014,"mc":[{"id":"1.195503853","rc":[{"atl":[[2.44,0],[2.46,2]],"id":43167135}],"con":true,"img":false}]}
{"op":"mcm","clk":"5353448182","pt":1646215144124,"mc":[{"id":"1.195503853","rc":[{"atl":[[2.4,2],[2.38,0]],"id":39786791}],"con":true,"img":false}]}
{"op":"mcm","clk":"5353448463","pt":1646215149248,"mc":[{"id":"1.195503853","rc":[{"atl":[[2.4,0],[2.42,2]],"id":39786791}],"con":true,"img":false}]}
{"op":"mcm","clk":"5353448687","pt":1646215152921,"mc":[{"id":"1.195503853","rc":[{"atl":[[2.54,4],[2.42,0]],"id":39786791}],"con":true,"img":false}]}
{"op":"mcm","clk":"5353448695","pt":1646215153027,"mc":[{"id":"1.195503853","rc":[{"atl":[[2.54,2],[2.58,4]],"id":39786791}],"con":true,"img":false}]}
{"op":"mcm","clk":"5353448708","pt":1646215153235,"mc":[{"id":"1.195503853","rc":[{"atl":[[2.42,2],[2.46,0]],"id":43167135}],"con":true,"img":false}]}
{"op":"mcm","clk":"5353449053","pt":1646215158160,"mc":[{"id":"1.195503853","rc":[{"atl":[[2.5,14],[2.58,2]],"id":39786791}],"con":true,"img":false}]}
{"op":"mcm","clk":"5353449071","pt":1646215158368,"mc":[{"id":"1.195503853","rc":[{"atl":[[2.36,2]],"id":43167135}],"con":true,"img":false}]}
{"op":"mcm","clk":"5353449079","pt":1646215158474,"mc":[{"id":"1.195503853","rc":[{"atl":[[2.42,0]],"id":43167135}],"con":true,"img":false}]}
{"op":"mcm","clk":"5353449402","pt":1646215163253,"mc":[{"id":"1.195503853","rc":[{"atl":[[2.5,12],[2.52,2]],"id":39786791}],"con":true,"img":false}]}
{"op":"mcm","clk":"5353449480","pt":1646215164546,"mc":[{"id":"1.195503853","rc":[{"atl":[[2.34,2]],"id":43167135}],"con":true,"img":false}]}
{"op":"mcm","clk":"5353449484","pt":1646215164658,"mc":[{"id":"1.195503853","rc":[{"atl":[[2.36,0]],"id":43167135}],"con":true,"img":false}]}
{"op":"mcm","clk":"5353449707","pt":1646215168387,"mc":[{"id":"1.195503853","rc":[{"atl":[[2.54,4],[2.52,0]],"id":39786791}],"con":true,"img":false}]}
{"op":"mcm","clk":"5353449718","pt":1646215168556,"mc":[{"id":"1.195503853","rc":[{"atl":[[2.54,2],[2.56,2]],"id":39786791}],"con":true,"img":false}]}
{"op":"mcm","clk":"5353449801","pt":1646215170046,"mc":[{"id":"1.195503853","rc":[{"atl":[[2.56,0],[2.52,2]],"id":39786791}],"con":true,"img":false}]}
{"op":"mcm","clk":"5353449837","pt":1646215170670,"mc":[{"id":"1.195503853","rc":[{"atl":[[2.32,2],[2.34,0]],"id":43167135}],"con":true,"img":false}]}
{"op":"mcm","clk":"5353449888","pt":1646215171448,"mc":[{"id":"1.195503853","rc":[{"atl":[[2.32,0],[2.34,2]],"id":43167135}],"con":true,"img":false}]}
{"op":"mcm","clk":"5353450146","pt":1646215175186,"mc":[{"id":"1.195503853","rc":[{"atl":[[2.54,4],[2.52,0]],"id":39786791}],"con":true,"img":false}]}
{"op":"mcm","clk":"5353450173","pt":1646215175711,"mc":[{"id":"1.195503853","rc":[{"atl":[[2.34,0],[2.36,2]],"id":43167135}],"con":true,"img":false}]}
{"op":"mcm","clk":"5353450243","pt":1646215176591,"mc":[{"id":"1.195503853","rc":[{"atb":[[1.85,8.34]],"id":43167135}],"con":true,"img":false}]}
{"op":"mcm","clk":"5353450254","pt":1646215176694,"mc":[{"id":"1.195503853","rc":[{"atb":[[1.86,0]],"id":43167135}],"con":true,"img":false}]}
{"op":"mcm","clk":"5353450495","pt":1646215180370,"mc":[{"id":"1.195503853","rc":[{"atl":[[2.54,2],[2.58,4]],"id":39786791}],"con":true,"img":false}]}
{"op":"mcm","clk":"5353450524","pt":1646215180894,"mc":[{"id":"1.195503853","rc":[{"atl":[[2.34,2],[2.36,0]],"id":43167135}],"con":true,"img":false}]}
{"op":"mcm","clk":"5353450534","pt":1646215181103,"mc":[{"id":"1.195503853","rc":[{"atl":[[2.36,2]],"id":43167135}],"con":true,"img":false}]}
{"op":"mcm","clk":"5353450540","pt":1646215181209,"mc":[{"id":"1.195503853","rc":[{"atl":[[2.34,0]],"id":43167135}],"con":true,"img":false}]}
{"op":"mcm","clk":"5353450580","pt":1646215181674,"mc":[{"id":"1.195503853","rc":[{"atl":[[2.34,2],[2.36,0]],"id":43167135}],"con":true,"img":false}]}
{"op":"mcm","clk":"5353450628","pt":1646215182296,"mc":[{"id":"1.195503853","rc":[{"atl":[[2.34,0],[2.36,2]],"id":43167135}],"con":true,"img":false}]}
{"op":"mcm","clk":"5353451011","pt":1646215187381,"mc":[{"id":"1.195503853","rc":[{"atl":[[2.36,0],[2.4,2]],"id":43167135}],"con":true,"img":false}]}
{"op":"mcm","clk":"5353451092","pt":1646215188677,"mc":[{"id":"1.195503853","rc":[{"atl":[[2.4,0],[2.36,2]],"id":43167135}],"con":true,"img":false}]}
{"op":"mcm","clk":"5353451441","pt":1646215193906,"mc":[{"id":"1.195503853","rc":[{"atl":[[2.36,0],[2.38,2]],"id":43167135}],"con":true,"img":false}]}
{"op":"mcm","clk":"5353451455","pt":1646215194212,"mc":[{"id":"1.195503853","rc":[{"atl":[[2.58,2],[2.56,2]],"id":39786791}],"con":true,"img":false}]}
{"op":"mcm","clk":"5353451804","pt":1646215199104,"mc":[{"id":"1.195503853","rc":[{"atl":[[2.36,2],[2.38,0]],"id":43167135}],"con":true,"img":false}]}
{"op":"mcm","clk":"5353451827","pt":1646215199314,"mc":[{"id":"1.195503853","rc":[{"atl":[[2.54,4],[2.56,0]],"id":39786791}],"con":true,"img":false}]}
{"op":"mcm","clk":"5353451851","pt":1646215199729,"mc":[{"id":"1.195503853","rc":[{"atl":[[2.54,2],[2.56,2]],"id":39786791}],"con":true,"img":false}]}
{"op":"mcm","clk":"5353452322","pt":1646215204030,"mc":[{"id":"1.195503853","rc":[{"atb":[[1.85,0]],"id":43167135},{"atl":[[1.85,0.38]],"id":43167135},{"trd":[[1.85,16.7]],"ltp":1.85,"tv":16.7,"id":43167135}],"con":true,"img":false}]}
{"op":"mcm","clk":"5353452335","pt":1646215204138,"mc":[{"id":"1.195503853","rc":[{"atl":[[1.85,0]],"id":43167135},{"trd":[[1.85,17.47]],"ltp":1.85,"tv":17.47,"id":43167135}],"con":true,"img":false}]}
{"op":"mcm","clk":"5353452347","pt":1646215204240,"mc":[{"id":"1.195503853","rc":[{"atb":[[1.84,2]],"id":43167135}],"con":true,"img":false}]}
{"op":"mcm","clk":"5353452360","pt":1646215204306,"mc":[{"id":"1.195503853","rc":[{"atl":[[2.36,0],[2.38,2]],"id":43167135}],"con":true,"img":false}]}
{"op":"mcm","clk":"5353452404","pt":1646215204814,"mc":[{"id":"1.195503853","rc":[{"atl":[[2.54,4],[2.56,0]],"id":39786791}],"con":true,"img":false}]}
{"op":"mcm","clk":"5353452857","pt":1646215209942,"mc":[{"id":"1.195503853","rc":[{"atl":[[2.54,2],[2.58,4]],"id":39786791}],"con":true,"img":false}]}
{"op":"mcm","clk":"5353452903","pt":1646215210529,"mc":[{"id":"1.195503853","rc":[{"atl":[[2.4,2],[2.38,0]],"id":43167135}],"con":true,"img":false}]}
{"op":"mcm","clk":"5353453031","pt":1646215212447,"mc":[{"id":"1.195503853","rc":[{"atl":[[2.38,2]],"id":43167135}],"con":true,"img":false}]}
{"op":"mcm","clk":"5353453040","pt":1646215212512,"mc":[{"id":"1.195503853","rc":[{"atl":[[2.4,0]],"id":43167135}],"con":true,"img":false}]}
{"op":"mcm","clk":"5353453365","pt":1646215215832,"mc":[{"id":"1.195503853","rc":[{"atl":[[2.58,2],[2.56,2]],"id":39786791}],"con":true,"img":false}]}
{"op":"mcm","clk":"5353453630","pt":1646215218750,"mc":[{"id":"1.195503853","rc":[{"atl":[[2.36,2],[2.38,0]],"id":43167135}],"con":true,"img":false}]}
{"op":"mcm","clk":"5353453634","pt":1646215218853,"mc":[{"id":"1.195503853","rc":[{"atl":[[2.38,2]],"id":43167135}],"con":true,"img":false}]}
{"op":"mcm","clk":"5353453641","pt":1646215218973,"mc":[{"id":"1.195503853","rc":[{"atl":[[2.36,0]],"id":43167135}],"con":true,"img":false}]}
{"op":"mcm","clk":"5353454084","pt":1646215225040,"mc":[{"id":"1.195503853","rc":[{"atl":[[2.36,2],[2.38,0]],"id":43167135}],"con":true,"img":false}]}
{"op":"mcm","clk":"5353454116","pt":1646215225460,"mc":[{"id":"1.195503853","rc":[{"atl":[[2.36,0],[2.38,2]],"id":43167135}],"con":true,"img":false}]}
{"op":"mcm","clk":"5353454431","pt":1646215230526,"mc":[{"id":"1.195503853","rc":[{"atl":[[2.36,2],[2.38,0]],"id":43167135}],"con":true,"img":false}]}
{"op":"mcm","clk":"5353454488","pt":1646215231464,"mc":[{"id":"1.195503853","rc":[{"atl":[[2.36,0],[2.4,2]],"id":43167135}],"con":true,"img":false}]}
{"op":"mcm","clk":"5353454496","pt":1646215231570,"mc":[{"id":"1.195503853","rc":[{"atb":[[1.84,0.22]],"id":43167135},{"trd":[[1.84,3.56]],"ltp":1.84,"tv":3.56,"id":43167135}],"con":true,"img":false}]}
{"op":"mcm","clk":"5353454921","pt":1646215236545,"mc":[{"id":"1.195503853","rc":[{"atl":[[2.4,0],[2.36,2]],"id":43167135}],"con":true,"img":false}]}
{"op":"mcm","clk":"5353455327","pt":1646215241682,"mc":[{"id":"1.195503853","rc":[{"atl":[[2.36,0],[2.52,2]],"id":43167135}],"con":true,"img":false}]}
{"op":"mcm","clk":"5353455674","pt":1646215246982,"mc":[{"id":"1.195503853","rc":[{"atl":[[2.54,2],[2.52,0]],"id":43167135}],"con":true,"img":false}]}
{"op":"mcm","clk":"5353456019","pt":1646215252180,"mc":[{"id":"1.195503853","rc":[{"atl":[[2.54,0],[2.58,2]],"id":43167135}],"con":true,"img":false}]}
{"op":"mcm","clk":"5353456155","pt":1646215253790,"mc":[{"id":"1.195503853","rc":[{"atl":[[2.56,0],[2.52,2]],"id":39786791}],"con":true,"img":false}]}
{"op":"mcm","clk":"5353456162","pt":1646215253893,"mc":[{"id":"1.195503853","rc":[{"atl":[[2.54,4]],"id":39786791}],"con":true,"img":false}]}
{"op":"mcm","clk":"5353456167","pt":1646215253999,"mc":[{"id":"1.195503853","rc":[{"atl":[[2.52,0]],"id":39786791}],"con":true,"img":false}]}
{"op":"mcm","clk":"5353456179","pt":1646215254204,"mc":[{"id":"1.195503853","rc":[{"atb":[[1.45,0],[1.65,0]],"id":43167135},{"atb":[[1.72,0],[1.32,2],[1.52,0]],"id":39786791}],"con":true,"img":false}]}
{"op":"mcm","clk":"5353456191","pt":1646215254413,"mc":[{"id":"1.195503853","rc":[{"atb":[[1.73,0],[1.58,4]],"id":39786791}],"con":true,"img":false}]}
{"op":"mcm","clk":"5353456379","pt":1646215257411,"mc":[{"id":"1.195503853","rc":[{"atl":[[2.58,0],[2.56,2]],"id":43167135}],"con":true,"img":false}]}
{"op":"mcm","clk":"5353456486","pt":1646215259109,"mc":[{"id":"1.195503853","rc":[{"atl":[[2.54,2],[2.56,2]],"id":39786791}],"con":true,"img":false}]}
{"op":"mcm","clk":"5353456515","pt":1646215259477,"mc":[{"id":"1.195503853","rc":[{"atb":[[1.59,2],[1.58,2]],"id":39786791}],"con":true,"img":false}]}
{"op":"mcm","clk":"5353456648","pt":1646215261404,"mc":[{"id":"1.195503853","rc":[{"atb":[[1.97,1.42]],"id":43167135},{"atl":[[2.24,1.42]],"id":43167135},{"atb":[[1.87,1.42]],"id":39786791},{"atl":[[2.06,1.42]],"id":39786791}],"con":true,"img":false}]}
{"op":"mcm","clk":"5353456669","pt":1646215261713,"mc":[{"id":"1.195503853","rc":[{"atb":[[1.84,0],[1.88,2]],"id":43167135}],"con":true,"img":false}]}
{"op":"mcm","clk":"5353456720","pt":1646215262494,"mc":[{"id":"1.195503853","rc":[{"atl":[[2.24,3.42],[2.56,0]],"id":43167135}],"con":true,"img":false}]}
{"op":"mcm","clk":"5353456743","pt":1646215262808,"mc":[{"id":"1.195503853","rc":[{"atb":[[1.97,0]],"id":43167135},{"atl":[[2.24,2]],"id":43167135},{"atb":[[1.87,0]],"id":39786791}],"con":true,"img":false}]}
{"op":"mcm","clk":"5353456753","pt":1646215262909,"mc":[{"id":"1.195503853","rc":[{"atl":[[2.56,2]],"id":43167135}],"con":true,"img":false}]}
{"op":"mcm","clk":"5353456761","pt":1646215263014,"mc":[{"id":"1.195503853","rc":[{"atl":[[2.24,0]],"id":43167135}],"con":true,"img":false}]}
{"op":"mcm","clk":"5353456861","pt":1646215264213,"mc":[{"id":"1.195503853","rc":[{"atl":[[2.12,2],[2.56,0]],"id":39786791}],"con":true,"img":false}]}
{"op":"mcm","clk":"5353456869","pt":1646215264316,"mc":[{"id":"1.195503853","rc":[{"atb":[[2,1.42]],"id":43167135},{"atl":[[2.36,1.42]],"id":43167135},{"atb":[[1.76,1.42]],"id":39786791},{"atl":[[2.06,0],[2.2,1.42]],"id":39786791}],"con":true,"img":false}]}
{"op":"mcm","clk":"5353456882","pt":1646215264521,"mc":[{"id":"1.195503853","rc":[{"atl":[[2.12,0],[2.2,3.42]],"id":39786791}],"con":true,"img":false}]}
{"op":"mcm","clk":"5353456890","pt":1646215264624,"mc":[{"id":"1.195503853","rc":[{"atl":[[2.5,14],[2.2,1.42]],"id":39786791}],"con":true,"img":false}]}
{"op":"mcm","clk":"5353456904","pt":1646215264728,"mc":[{"id":"1.195503853","rc":[{"atb":[[1.59,0],[1.76,3.42]],"id":39786791}],"con":true,"img":false}]}
{"op":"mcm","clk":"5353456909","pt":1646215264785,"mc":[{"id":"1.195503853","rc":[{"atb":[[1.59,2]],"id":39786791},{"atl":[[2.5,12],[2.2,3.42]],"id":39786791}],"con":true,"img":false}]}
{"op":"mcm","clk":"5353456916","pt":1646215264900,"mc":[{"id":"1.195503853","rc":[{"atb":[[1.76,1.42]],"id":39786791}],"con":true,"img":false}]}
{"op":"mcm","clk":"5353456971","pt":1646215265611,"mc":[{"id":"1.195503853","rc":[{"atb":[[1.93,1.42]],"id":43167135},{"atl":[[2.42,1.42]],"id":43167135},{"atb":[[1.77,1.42]],"id":39786791},{"atl":[[2.12,1.42]],"id":39786791}],"con":true,"img":false}]}
{"op":"mcm","clk":"5353456979","pt":1646215265711,"mc":[{"id":"1.195503853","rc":[{"atb":[[2,0]],"id":43167135},{"atb":[[1.76,0]],"id":39786791}],"con":true,"img":false}]}
{"op":"mcm","clk":"5353457068","pt":1646215266908,"mc":[{"id":"1.195503853","rc":[{"atb":[[1.94,1.42]],"id":43167135},{"atl":[[2.46,1.42]],"id":43167135},{"atb":[[1.76,1.42]],"id":39786791},{"atl":[[2.22,1.42]],"id":39786791}],"con":true,"img":false}]}
{"op":"mcm","clk":"5353457081","pt":1646215267009,"mc":[{"id":"1.195503853","rc":[{"atb":[[1.6,10.99],[1.4,13.48],[1.8,6.74]],"id":43167135},{"atb":[[1.6,30.99],[1.4,13.48],[1.8,6.74]],"id":39786791}],"con":true,"img":false}]}
{"op":"mcm","clk":"5353457092","pt":1646215267120,"mc":[{"id":"1.195503853","rc":[{"atb":[[1.93,0]],"id":43167135},{"atb":[[1.77,0]],"id":39786791}],"con":true,"img":false}]}
{"op":"mcm","clk":"5353457160","pt":1646215268001,"mc":[{"id":"1.195503853","rc":[{"atl":[[2.36,3.42],[2.56,0]],"id":43167135}],"con":true,"img":false}]}
{"op":"mcm","clk":"5353457185","pt":1646215268306,"mc":[{"id":"1.195503853","rc":[{"atb":[[1.95,1.42]],"id":43167135},{"atl":[[2.22,1.42]],"id":43167135},{"atb":[[1.86,1.42]],"id":39786791},{"atl":[[2.16,1.42]],"id":39786791}],"con":true,"img":false}]}
{"op":"mcm","clk":"5353457198","pt":1646215268512,"mc":[{"id":"1.195503853","rc":[{"atb":[[1.94,0]],"id":43167135}],"con":true,"img":false}]}
{"op":"mcm","clk":"5353457253","pt":1646215269422,"mc":[{"id":"1.195503853","rc":[{"atb":[[1.94,1.42]],"id":43167135},{"atl":[[2.2,1.42]],"id":43167135},{"atb":[[1.85,1.42]],"id":39786791},{"atl":[[2.18,1.42]],"id":39786791}],"con":true,"img":false}]}
{"op":"mcm","clk":"5353457270","pt":1646215269628,"mc":[{"id":"1.195503853","rc":[{"atb":[[1.95,0]],"id":43167135},{"atb":[[1.86,0]],"id":39786791}],"con":true,"img":false}]}
{"op":"mcm","clk":"5353457292","pt":1646215269892,"mc":[{"id":"1.195503853","rc":[{"atb":[[1.59,0],[1.82,2]],"id":39786791},{"atl":[[2.12,3.42],[2.2,1.42]],"id":39786791}],"con":true,"img":false}]}
{"op":"mcm","clk":"5353457387","pt":1646215270830,"mc":[{"id":"1.195503853","rc":[{"atb":[[1.93,1.42]],"id":43167135},{"atb":[[1.84,1.42]],"id":39786791},{"atl":[[2.24,1.42]],"id":39786791}],"con":true,"img":false}]}
{"op":"mcm","clk":"5353457404","pt":1646215271033,"mc":[{"id":"1.195503853","rc":[{"atb":[[1.94,0]],"id":43167135},{"atl":[[2.36,2]],"id":43167135}],"con":true,"img":false}]}
{"op":"mcm","clk":"5353457487","pt":1646215272121,"mc":[{"id":"1.195503853","rc":[{"atb":[[1.93,0],[1.92,1.42]],"id":43167135},{"atl":[[2.2,0]],"id":43167135},{"atb":[[1.85,0]],"id":39786791}],"con":true,"img":false}]}
{"op":"mcm","clk":"5353457572","pt":1646215273211,"mc":[{"id":"1.195503853","rc":[{"atl":[[2.22,3.42],[2.36,0]],"id":43167135}],"con":true,"img":false}]}
{"op":"mcm","clk":"5353457580","pt":1646215273308,"mc":[{"id":"1.195503853","rc":[{"atb":[[1.94,1.42],[1.92,0]],"id":43167135},{"atl":[[2.22,2],[2.42,0],[2.46,0]],"id":43167135}],"con":true,"img":false}]}
{"op":"mcm","clk":"5353457679","pt":1646215274408,"mc":[{"id":"1.195503853","rc":[{"atb":[[1.94,0]],"id":43167135},{"atb":[[1.76,0]],"id":39786791},{"atl":[[2.12,2],[2.2,0],[2.16,0]],"id":39786791}],"con":true,"img":false}]}
{"op":"mcm","clk":"5353457692","pt":1646215274613,"mc":[{"id":"1.195503853","rc":[{"atb":[[1.81,2],[1.88,0]],"id":43167135},{"atl":[[2.12,0],[2.18,3.42]],"id":39786791}],"con":true,"img":false}]}
{"op":"mcm","clk":"5353457702","pt":1646215274719,"mc":[{"id":"1.195503853","rc":[{"atl":[[2.2,2]],"id":39786791}],"con":true,"img":false}]}
{"op":"mcm","clk":"5353457710","pt":1646215274822,"mc":[{"id":"1.195503853","rc":[{"atl":[[2.18,1.42]],"id":39786791}],"con":true,"img":false}]}
{"op":"mcm","clk":"5353457792","pt":1646215275954,"mc":[{"id":"1.195503853","rc":[{"atb":[[1.87,1.42]],"id":43167135},{"atl":[[2.38,1.42]],"id":39786791}],"con":true,"img":false}]}
{"op":"mcm","clk":"5353457809","pt":1646215276120,"mc":[{"id":"1.195503853","rc":[{"atb":[[1.87,3.42],[1.81,0]],"id":43167135}],"con":true,"img":false}]}
{"op":"mcm","clk":"5353457946","pt":1646215277828,"mc":[{"id":"1.195503853","rc":[{"atb":[[1.87,2],[1.86,1.42]],"id":43167135}],"con":true,"img":false}]}
{"op":"mcm","clk":"5353457992","pt":1646215278315,"mc":[{"id":"1.195503853","rc":[{"atl":[[2.22,0],[2.58,2]],"id":43167135}],"con":true,"img":false}]}
{"op":"mcm","clk":"5353458030","pt":1646215278820,"mc":[{"id":"1.195503853","rc":[{"atb":[[1.88,1.42]],"id":43167135}],"con":true,"img":false}]}
{"op":"mcm","clk":"5353458067","pt":1646215279225,"mc":[{"id":"1.195503853","rc":[{"atl":[[2.56,2]],"id":43167135}],"con":true,"img":false}]}
{"op":"mcm","clk":"5353458073","pt":1646215279329,"mc":[{"id":"1.195503853","rc":[{"atl":[[2.58,0]],"id":43167135}],"con":true,"img":false}]}
{"op":"mcm","clk":"5353458133","pt":1646215280212,"mc":[{"id":"1.195503853","rc":[{"atb":[[1.85,1.42]],"id":43167135}],"con":true,"img":false}]}
{"op":"mcm","clk":"5353458164","pt":1646215280631,"mc":[{"id":"1.195503853","rc":[{"atl":[[2.58,2]],"id":43167135}],"con":true,"img":false}]}
{"op":"mcm","clk":"5353458172","pt":1646215280728,"mc":[{"id":"1.195503853","rc":[{"atl":[[2.56,0]],"id":43167135}],"con":true,"img":false}]}
{"op":"mcm","clk":"5353458207","pt":1646215281203,"mc":[{"id":"1.195503853","rc":[{"atb":[[1.82,1.42]],"id":43167135},{"atl":[[2.34,1.42]],"id":39786791}],"con":true,"img":false}]}
{"op":"mcm","clk":"5353458306","pt":1646215282542,"mc":[{"id":"1.195503853","rc":[{"atl":[[2.58,0],[2.56,2]],"id":43167135}],"con":true,"img":false}]}
{"op":"mcm","clk":"5353458323","pt":1646215282706,"mc":[{"id":"1.195503853","rc":[{"atl":[[2.56,3.42]],"id":43167135},{"atl":[[2.32,1.42]],"id":39786791}],"con":true,"img":false}]}
{"op":"mcm","clk":"5353458428","pt":1646215284435,"mc":[{"id":"1.195503853","rc":[{"atl":[[2.52,1.42]],"id":43167135}],"con":true,"img":false}]}
{"op":"mcm","clk":"5353458528","pt":1646215285729,"mc":[{"id":"1.195503853","rc":[{"atl":[[2.5,1.42]],"id":43167135}],"con":true,"img":false}]}
{"op":"mcm","clk":"5353458604","pt":1646215286728,"mc":[{"id":"1.195503853","rc":[{"atl":[[2.46,15]],"id":43167135}],"con":true,"img":false}]}
{"op":"mcm","clk":"5353458667","pt":1646215287640,"mc":[{"id":"1.195503853","rc":[{"atl":[[2.5,3.42],[2.56,1.42]],"id":43167135}],"con":true,"img":false}]}
{"op":"mcm","clk":"5353458710","pt":1646215288119,"mc":[{"id":"1.195503853","rc":[{"atb":[[1.73,1.42]],"id":39786791}],"con":true,"img":false}]}
{"op":"mcm","clk":"5353458724","pt":1646215288317,"mc":[{"id":"1.195503853","rc":[{"atl":[[2.5,2]],"id":43167135}],"con":true,"img":false}]}
{"op":"mcm","clk":"5353458733","pt":1646215288522,"mc":[{"id":"1.195503853","rc":[{"atb":[[1.7,24],[1.78,35],[1.74,2],[1.67,2],[1.66,4],[1.64,207],[1.73,78],[1.76,52],[1.69,117],[1.72,2],[1.75,2]],"id":43167135}],"con":true,"img":false}]}
{"op":"mcm","clk":"5353458816","pt":1646215289549,"mc":[{"id":"1.195503853","rc":[{"atb":[[1.9,1.42]],"id":43167135},{"atl":[[2.44,1.42]],"id":43167135}],"con":true,"img":false}]}
{"op":"mcm","clk":"5353458828","pt":1646215289960,"mc":[{"id":"1.195503853","rc":[{"atb":[[1.88,3.42],[1.87,0]],"id":43167135}],"con":true,"img":false}]}
{"op":"mcm","clk":"5353458895","pt":1646215290571,"mc":[{"id":"1.195503853","rc":[{"atb":[[1.89,1.42]],"id":43167135}],"con":true,"img":false}]}
{"op":"mcm","clk":"5353458942","pt":1646215291234,"mc":[{"id":"1.195503853","rc":[{"atl":[[2.56,0]],"id":43167135}],"con":true,"img":false}]}
{"op":"mcm","clk":"5353459017","pt":1646215292317,"mc":[{"id":"1.195503853","rc":[{"atb":[[1.91,1.42]],"id":43167135},{"atl":[[2.06,1.42]],"id":39786791}],"con":true,"img":false}]}
{"op":"mcm","clk":"5353459025","pt":1646215292419,"mc":[{"id":"1.195503853","rc":[{"atl":[[2.2,0],[2.12,2]],"id":39786791}],"con":true,"img":false}]}
{"op":"mcm","clk":"5353459033","pt":1646215292524,"mc":[{"id":"1.195503853","rc":[{"atb":[[1.9,0]],"id":43167135}],"con":true,"img":false}]}
{"op":"mcm","clk":"5353459053","pt":1646215292832,"mc":[{"id":"1.195503853","rc":[{"atl":[[2.5,0],[2.44,3.42]],"id":43167135}],"con":true,"img":false}]}
{"op":"mcm","clk":"5353459122","pt":1646215293757,"mc":[{"id":"1.195503853","rc":[{"atb":[[1.9,1.42]],"id":43167135},{"atl":[[2.08,1.42]],"id":39786791}],"con":true,"img":false}]}
{"op":"mcm","clk":"5353459200","pt":1646215294851,"mc":[{"id":"1.195503853","rc":[{"atb":[[1.93,1.42]],"id":43167135},{"atl":[[2.16,1.42],[2.06,0]],"id":39786791}],"con":true,"img":false}]}
{"op":"mcm","clk":"5353459301","pt":1646215296264,"mc":[{"id":"1.195503853","rc":[{"atb":[[1.94,1.42]],"id":43167135},{"atl":[[2.2,1.42]],"id":39786791}],"con":true,"img":false}]}
{"op":"mcm","clk":"5353459310","pt":1646215296350,"mc":[{"id":"1.195503853","rc":[{"atl":[[2.52,0]],"id":43167135}],"con":true,"img":false}]}
{"op":"mcm","clk":"5353459373","pt":1646215297331,"mc":[{"id":"1.195503853","rc":[{"atb":[[1.89,3.42]],"id":43167135}],"con":true,"img":false}]}
{"op":"mcm","clk":"5353459379","pt":1646215297435,"mc":[{"id":"1.195503853","rc":[{"atb":[[1.88,1.42]],"id":43167135}],"con":true,"img":false}]}
{"op":"mcm","clk":"5353459393","pt":1646215297744,"mc":[{"id":"1.195503853","rc":[{"atl":[[2.04,1.42]],"id":39786791}],"con":true,"img":false}]}
{"op":"mcm","clk":"5353459423","pt":1646215298150,"mc":[{"id":"1.195503853","rc":[{"atb":[[1.94,0]],"id":43167135}],"con":true,"img":false}]}
{"op":"mcm","clk":"5353459580","pt":1646215300831,"mc":[{"id":"1.195503853","rc":[{"atb":[[1.94,1.42]],"id":43167135}],"con":true,"img":false}]}
{"op":"mcm","clk":"5353459737","pt":1646215303253,"mc":[{"id":"1.195503853","rc":[{"atl":[[2.44,2]],"id":43167135}],"con":true,"img":false}]}
{"op":"mcm","clk":"5353459755","pt":1646215303456,"mc":[{"id":"1.195503853","rc":[{"atl":[[2.5,2],[2.44,0]],"id":43167135}],"con":true,"img":false}]}
{"op":"mcm","clk":"5353459785","pt":1646215303866,"mc":[{"id":"1.195503853","rc":[{"atl":[[2.5,0],[2.52,2]],"id":43167135}],"con":true,"img":false}]}
{"op":"mcm","clk":"5353459903","pt":1646215305776,"mc":[{"id":"1.195503853","rc":[{"atl":[[2.5,2],[2.52,0]],"id":43167135}],"con":true,"img":false}]}
{"op":"mcm","clk":"5353460294","pt":1646215311361,"mc":[{"id":"1.195503853","rc":[{"atl":[[2.5,0],[2.52,2]],"id":43167135}],"con":true,"img":false}]}
{"op":"mcm","clk":"5353460745","pt":1646215317044,"mc":[{"id":"1.195503853","rc":[{"atl":[[2.5,2],[2.52,0]],"id":43167135}],"con":true,"img":false}]}
{"op":"mcm","clk":"5353460782","pt":1646215317767,"mc":[{"id":"1.195503853","rc":[{"atb":[[1.88,3.42],[1.89,1.42]],"id":43167135}],"con":true,"img":false}]}
{"op":"mcm","clk":"5353460803","pt":1646215318023,"mc":[{"id":"1.195503853","rc":[{"atl":[[2.5,0],[2.52,2]],"id":43167135}],"con":true,"img":false}]}
{"op":"mcm","clk":"5353460872","pt":1646215318856,"mc":[{"id":"1.195503853","rc":[{"atl":[[2.52,0],[2.46,17]],"id":43167135}],"con":true,"img":false}]}
{"op":"mcm","clk":"5353460879","pt":1646215318953,"mc":[{"id":"1.195503853","rc":[{"atb":[[1.81,15]],"id":39786791}],"con":true,"img":false}]}
{"op":"mcm","clk":"5353460912","pt":1646215319467,"mc":[{"id":"1.195503853","rc":[{"atl":[[2.6,2],[2.64,2],[2.58,4],[2.66,2],[2.54,4],[2.62,19],[2.56,2]],"id":39786791}],"con":true,"img":false}]}
{"op":"mcm","clk":"5353461013","pt":1646215320993,"mc":[{"id":"1.195503853","rc":[{"atb":[[1.73,0]],"id":39786791}],"con":true,"img":false}]}
{"op":"mcm","clk":"5353461435","pt":1646215326634,"mc":[{"id":"1.195503853","rc":[{"atl":[[2.44,2],[2.46,15]],"id":43167135}],"con":true,"img":false}]}
{"op":"mcm","clk":"5353461817","pt":1646215331745,"mc":[{"id":"1.195503853","rc":[{"atl":[[2.48,2]],"id":43167135}],"con":true,"img":false}]}
{"op":"mcm","clk":"5353461824","pt":1646215331850,"mc":[{"id":"1.195503853","rc":[{"atl":[[2.44,0]],"id":43167135}],"con":true,"img":false}]}
{"op":"mcm","clk":"5353461986","pt":1646215334261,"mc":[{"id":"1.195503853","rc":[{"atb":[[1.78,37],[1.81,12],[1.74,4],[1.86,6.42],[1.77,18],[1.83,2],[1.84,8],[1.82,3.42],[1.8,8.74],[1.72,29],[1.75,4]],"id":43167135}],"con":true,"img":false}]}
{"op":"mcm","clk":"5353462185","pt":1646215336959,"mc":[{"id":"1.195503853","rc":[{"atl":[[2.48,0],[2.46,17]],"id":43167135}],"con":true,"img":false}]}
{"op":"mcm","clk":"5353462249","pt":1646215337891,"mc":[{"id":"1.195503853","rc":[{"atl":[[2.48,2],[2.46,15]],"id":43167135}],"con":true,"img":false}]}
{"op":"mcm","clk":"5353462520","pt":1646215341986,"mc":[{"id":"1.195503853","rc":[{"atb":[[1.89,3.42]],"id":43167135}],"con":true,"img":false}]}
{"op":"mcm","clk":"5353462533","pt":1646215342093,"mc":[{"id":"1.195503853","rc":[{"atb":[[1.88,1.42]],"id":43167135}],"con":true,"img":false}]}
{"op":"mcm","clk":"5353462594","pt":1646215342979,"mc":[{"id":"1.195503853","rc":[{"atb":[[1.9,3.42],[1.89,1.42]],"id":43167135},{"atl":[[2.1,2],[2.12,0]],"id":39786791}],"con":true,"img":false}]}
{"op":"mcm","clk":"5353462600","pt":1646215343084,"mc":[{"id":"1.195503853","rc":[{"atl":[[2.44,2],[2.48,0]],"id":43167135}],"con":true,"img":false}]}
{"op":"mcm","clk":"5353462610","pt":1646215343192,"mc":[{"id":"1.195503853","rc":[{"atl":[[2.44,0],[2.48,2]],"id":43167135}],"con":true,"img":false}]}
{"op":"mcm","clk":"5353462696","pt":1646215344277,"mc":[{"id":"1.195503853","rc":[{"atl":[[2.44,2],[2.48,0]],"id":43167135}],"con":true,"img":false}]}
{"op":"mcm","clk":"5353462865","pt":1646215346360,"mc":[{"id":"1.195503853","rc":[{"atl":[[2.46,17]],"id":43167135}],"con":true,"img":false}]}
{"op":"mcm","clk":"5353462869","pt":1646215346463,"mc":[{"id":"1.195503853","rc":[{"atl":[[2.44,0]],"id":43167135}],"con":true,"img":false}]}
{"op":"mcm","clk":"5353462987","pt":1646215348179,"mc":[{"id":"1.195503853","rc":[{"atb":[[1.9,1.42],[1.89,3.42]],"id":43167135}],"con":true,"img":false}]}
{"op":"mcm","clk":"5353463205","pt":1646215351608,"mc":[{"id":"1.195503853","rc":[{"atl":[[2.42,2]],"id":43167135}],"con":true,"img":false}]}
{"op":"mcm","clk":"5353463211","pt":1646215351711,"mc":[{"id":"1.195503853","rc":[{"atl":[[2.46,15]],"id":43167135}],"con":true,"img":false}]}
{"op":"mcm","clk":"5353463472","pt":1646215355679,"mc":[{"id":"1.195503853","rc":[{"atb":[[1.9,3.42],[1.89,1.42]],"id":43167135}],"con":true,"img":false}]}
{"op":"mcm","clk":"5353463548","pt":1646215356712,"mc":[{"id":"1.195503853","rc":[{"atl":[[2.34,2],[2.42,0]],"id":43167135}],"con":true,"img":false}]}
{"op":"mcm","clk":"5353464044","pt":1646215364008,"mc":[{"id":"1.195503853","rc":[{"atl":[[2.32,2],[2.34,0]],"id":43167135}],"con":true,"img":false}]}
{"op":"mcm","clk":"5353464391","pt":1646215368716,"mc":[{"id":"1.195503853","rc":[{"atb":[[1.9,1.42],[1.89,3.42]],"id":43167135}],"con":true,"img":false}]}
{"op":"mcm","clk":"5353464424","pt":1646215369332,"mc":[{"id":"1.195503853","rc":[{"atl":[[2.32,0],[2.3,2]],"id":43167135}],"con":true,"img":false}]}
{"op":"mcm","clk":"5353465357","pt":1646215383514,"mc":[{"id":"1.195503853","rc":[{"atl":[[2.3,0],[2.32,2]],"id":43167135}],"con":true,"img":false}]}
{"op":"mcm","clk":"5353465420","pt":1646215384444,"mc":[{"id":"1.195503853","rc":[{"atl":[[2.1,0],[2.12,2]],"id":39786791}],"con":true,"img":false}]}
{"op":"mcm","clk":"5353465839","pt":1646215389946,"mc":[{"id":"1.195503853","rc":[{"atl":[[2.32,0],[2.38,2]],"id":43167135}],"con":true,"img":false}]}
{"op":"mcm","clk":"5353465849","pt":1646215390047,"mc":[{"id":"1.195503853","rc":[{"atl":[[2.32,2],[2.38,0]],"id":43167135}],"con":true,"img":false}]}
{"op":"mcm","clk":"5353466961","pt":1646215402976,"mc":[{"id":"1.195503853","rc":[{"atl":[[2.32,0],[2.34,2]],"id":43167135}],"con":true,"img":false}]}
{"op":"mcm","clk":"5353467374","pt":1646215408152,"mc":[{"id":"1.195503853","rc":[{"atl":[[2.3,2],[2.34,0]],"id":43167135}],"con":true,"img":false}]}
{"op":"mcm","clk":"5353467755","pt":1646215412799,"mc":[{"id":"1.195503853","rc":[{"atl":[[2.3,0],[2.28,2]],"id":43167135}],"con":true,"img":false}]}
{"op":"mcm","clk":"5353468161","pt":1646215417084,"mc":[{"id":"1.195503853","rc":[{"atb":[[1.89,1.42]],"id":43167135},{"atl":[[2.1,2],[2.12,0]],"id":39786791}],"con":true,"img":false}]}
{"op":"mcm","clk":"5353468170","pt":1646215417191,"mc":[{"id":"1.195503853","rc":[{"atb":[[1.91,3.42]],"id":43167135}],"con":true,"img":false}]}
{"op":"mcm","clk":"5353468274","pt":1646215418143,"mc":[{"id":"1.195503853","rc":[{"atl":[[2.26,2],[2.28,0]],"id":43167135}],"con":true,"img":false}]}
{"op":"mcm","clk":"5353468309","pt":1646215418561,"mc":[{"id":"1.195503853","rc":[{"atl":[[2.26,0],[2.28,2]],"id":43167135}],"con":true,"img":false}]}
{"op":"mcm","clk":"5353468622","pt":1646215422176,"mc":[{"id":"1.195503853","rc":[{"atl":[[2.08,3.42]],"id":39786791}],"con":true,"img":false}]}
{"op":"mcm","clk":"5353468629","pt":1646215422280,"mc":[{"id":"1.195503853","rc":[{"atl":[[2.1,0]],"id":39786791}],"con":true,"img":false}]}
{"op":"mcm","clk":"5353468649","pt":1646215422595,"mc":[{"id":"1.195503853","rc":[{"atb":[[1.91,1.42],[1.9,3.42]],"id":43167135},{"atl":[[2.1,2],[2.08,1.42]],"id":39786791}],"con":true,"img":false}]}
{"op":"mcm","clk":"5353468730","pt":1646215423660,"mc":[{"id":"1.195503853","rc":[{"atl":[[2.26,2],[2.28,0]],"id":43167135}],"con":true,"img":false}]}
{"op":"mcm","clk":"5353469079","pt":1646215428093,"mc":[{"id":"1.195503853","rc":[{"atl":[[2.26,0],[2.24,2]],"id":43167135}],"con":true,"img":false}]}
{"op":"mcm","clk":"5353469439","pt":1646215432395,"mc":[{"id":"1.195503853","rc":[{"atb":[[1.91,3.42],[1.9,1.42]],"id":43167135},{"atl":[[2.1,0],[2.08,3.42]],"id":39786791}],"con":true,"img":false}]}
{"op":"mcm","clk":"5353469499","pt":1646215433177,"mc":[{"id":"1.195503853","rc":[{"atl":[[2.22,2]],"id":43167135}],"con":true,"img":false}]}
{"op":"mcm","clk":"5353469508","pt":1646215433281,"mc":[{"id":"1.195503853","rc":[{"atb":[[1.91,1.42]],"id":43167135},{"atl":[[2.24,0]],"id":43167135},{"atb":[[1.84,3.42],[1.82,0]],"id":39786791},{"atl":[[2.08,1.42]],"id":39786791}],"con":true,"img":false}]}
{"op":"mcm","clk":"5353469517","pt":1646215433387,"mc":[{"id":"1.195503853","rc":[{"atl":[[2.16,3.42]],"id":39786791}],"con":true,"img":false}]}
{"op":"mcm","clk":"5353469525","pt":1646215433489,"mc":[{"id":"1.195503853","rc":[{"atb":[[1.85,3.42]],"id":43167135},{"atb":[[1.84,1.42],[1.81,17]],"id":39786791}],"con":true,"img":false}]}
{"op":"mcm","clk":"5353469625","pt":1646215434799,"mc":[{"id":"1.195503853","rc":[{"atb":[[1.82,1.42]],"id":39786791}],"con":true,"img":false}]}
{"op":"mcm","clk":"5353469633","pt":1646215434902,"mc":[{"id":"1.195503853","rc":[{"atb":[[1.84,0]],"id":39786791}],"con":true,"img":false}]}
{"op":"mcm","clk":"5353469641","pt":1646215435009,"mc":[{"id":"1.195503853","rc":[{"atb":[[1.84,2],[1.81,15]],"id":39786791}],"con":true,"img":false}]}
{"op":"mcm","clk":"5353469659","pt":1646215435173,"mc":[{"id":"1.195503853","rc":[{"atb":[[1.84,0],[1.82,3.42]],"id":39786791}],"con":true,"img":false}]}
{"op":"mcm","clk":"5353469816","pt":1646215437313,"mc":[{"id":"1.195503853","rc":[{"atb":[[1.83,1.42]],"id":39786791}],"con":true,"img":false}]}
{"op":"mcm","clk":"5353469912","pt":1646215438407,"mc":[{"id":"1.195503853","rc":[{"atl":[[2.22,0],[2.24,2]],"id":43167135}],"con":true,"img":false}]}
{"op":"mcm","clk":"5353469984","pt":1646215439293,"mc":[{"id":"1.195503853","rc":[{"atb":[[1.83,0]],"id":39786791}],"con":true,"img":false}]}
{"op":"mcm","clk":"5353470092","pt":1646215440495,"mc":[{"id":"1.195503853","rc":[{"atb":[[1.83,1.42]],"id":39786791}],"con":true,"img":false}]}
{"op":"mcm","clk":"5353470234","pt":1646215442012,"mc":[{"id":"1.195503853","rc":[{"atb":[[1.83,0]],"id":39786791}],"con":true,"img":false}]}
{"op":"mcm","clk":"5353470345","pt":1646215443312,"mc":[{"id":"1.195503853","rc":[{"atb":[[1.83,1.42]],"id":39786791}],"con":true,"img":false}]}
{"op":"mcm","clk":"5353470486","pt":1646215444905,"mc":[{"id":"1.195503853","rc":[{"atb":[[1.83,0]],"id":39786791}],"con":true,"img":false}]}
{"op":"mcm","clk":"5353470657","pt":1646215447002,"mc":[{"id":"1.195503853","rc":[{"atb":[[1.83,1.42]],"id":39786791}],"con":true,"img":false}]}
{"op":"mcm","clk":"5353470846","pt":1646215449302,"mc":[{"id":"1.195503853","rc":[{"atb":[[1.83,0],[1.84,1.42]],"id":39786791}],"con":true,"img":false}]}
{"op":"mcm","clk":"5353470861","pt":1646215449507,"mc":[{"id":"1.195503853","rc":[{"atb":[[1.84,3.42],[1.82,1.42]],"id":39786791}],"con":true,"img":false}]}
{"op":"mcm","clk":"5353471899","pt":1646215462404,"mc":[{"id":"1.195503853","rc":[{"atb":[[1.4,0],[1.6,2],[1.8,2]],"id":43167135},{"atb":[[1.6,22],[1.4,0],[1.8,0]],"id":39786791}],"con":true,"img":false}]}
{"op":"mcm","clk":"5353471925","pt":1646215462822,"mc":[{"id":"1.195503853","rc":[{"atl":[[2.22,2],[2.24,0]],"id":43167135}],"con":true,"img":false}]}
{"op":"mcm","clk":"5353471947","pt":1646215463138,"mc":[{"id":"1.195503853","rc":[{"atl":[[2.22,0],[2.24,2]],"id":43167135}],"con":true,"img":false}]}
{"op":"mcm","clk":"5353472547","pt":1646215470810,"mc":[{"id":"1.195503853","rc":[{"atl":[[2.24,0],[2.2,2]],"id":43167135}],"con":true,"img":false}]}
{"op":"mcm","clk":"5353472562","pt":1646215471019,"mc":[{"id":"1.195503853","rc":[{"atb":[[1.28,19.27],[1.68,9.93],[1.48,13.24]],"id":43167135},{"atb":[[1.87,6.2],[1.67,8.05],[1.47,13.47]],"id":39786791}],"con":true,"img":false}]}
{"op":"mcm","clk":"5353472594","pt":1646215471436,"mc":[{"id":"1.195503853","rc":[{"atb":[[1.84,1.42],[1.88,2]],"id":39786791}],"con":true,"img":false}]}
{"op":"mcm","clk":"5353472690","pt":1646215472638,"mc":[{"id":"1.195503853","rc":[{"atb":[[1.84,0],[1.82,0]],"id":39786791}],"con":true,"img":false}]}
{"op":"mcm","clk":"5353472921","pt":1646215475135,"mc":[{"id":"1.195503853","rc":[{"atb":[[1.88,0],[1.86,2]],"id":39786791},{"atl":[[2.14,2],[2.16,1.42]],"id":39786791}],"con":true,"img":false}]}
{"op":"mcm","clk":"5353472991","pt":1646215475916,"mc":[{"id":"1.195503853","rc":[{"atl":[[2.24,2]],"id":43167135}],"con":true,"img":false}]}
{"op":"mcm","clk":"5353473000","pt":1646215476022,"mc":[{"id":"1.195503853","rc":[{"atl":[[2.2,0]],"id":43167135}],"con":true,"img":false}]}
{"op":"mcm","clk":"5353473036","pt":1646215476549,"mc":[{"id":"1.195503853","rc":[{"atl":[[2.14,0],[2.16,3.42]],"id":39786791}],"con":true,"img":false}]}
{"op":"mcm","clk":"5353473205","pt":1646215478515,"mc":[{"id":"1.195503853","rc":[{"atl":[[2.24,0],[2.2,2]],"id":43167135}],"con":true,"img":false}]}
{"op":"mcm","clk":"5353473675","pt":1646215483424,"mc":[{"id":"1.195503853","rc":[{"atb":[[1.87,1.42]],"id":43167135}],"con":true,"img":false}]}
{"op":"mcm","clk":"5353473695","pt":1646215483626,"mc":[{"id":"1.195503853","rc":[{"atl":[[2.26,2]],"id":43167135}],"con":true,"img":false}]}
{"op":"mcm","clk":"5353473702","pt":1646215483729,"mc":[{"id":"1.195503853","rc":[{"atl":[[2.2,0]],"id":43167135}],"con":true,"img":false}]}
{"op":"mcm","clk":"5353474234","pt":1646215490022,"mc":[{"id":"1.195503853","rc":[{"atl":[[2.26,0],[2.24,2]],"id":43167135}],"con":true,"img":false}]}
{"op":"mcm","clk":"5353474474","pt":1646215493134,"mc":[{"id":"1.195503853","rc":[{"atl":[[2.26,2]],"id":43167135}],"con":true,"img":false}]}
{"op":"mcm","clk":"5353474481","pt":1646215493239,"mc":[{"id":"1.195503853","rc":[{"atl":[[2.24,0]],"id":43167135}],"con":true,"img":false}]}
{"op":"mcm","clk":"5353474513","pt":1646215493656,"mc":[{"id":"1.195503853","rc":[{"atb":[[1.28,0],[1.68,2],[1.48,2]],"id":43167135},{"atb":[[1.87,0],[1.67,0],[1.47,2]],"id":39786791}],"con":true,"img":false}]}
{"op":"mcm","clk":"5353474531","pt":1646215493867,"mc":[{"id":"1.195503853","rc":[{"atb":[[1.78,2],[1.86,0]],"id":39786791}],"con":true,"img":false}]}
{"op":"mcm","clk":"5353474566","pt":1646215494234,"mc":[{"id":"1.195503853","rc":[{"atl":[[2.26,0],[2.2,2]],"id":43167135}],"con":true,"img":false}]}
{"op":"mcm","clk":"5353474909","pt":1646215498960,"mc":[{"id":"1.195503853","rc":[{"atb":[[1.78,0],[1.82,2]],"id":39786791}],"con":true,"img":false}]}
{"op":"mcm","clk":"5353475060","pt":1646215500628,"mc":[{"id":"1.195503853","rc":[{"atb":[[1.83,2],[1.82,0]],"id":39786791}],"con":true,"img":false}]}
{"op":"mcm","clk":"5353475299","pt":1646215503138,"mc":[{"id":"1.195503853","rc":[{"atb":[[1.2,26.97],[1.4,13.48],[1.6,10.99]],"id":43167135},{"atb":[[1.73,7.39],[1.93,5.8],[1.53,10.18]],"id":39786791}],"con":true,"img":false}]}
{"op":"mcm","clk":"5353475320","pt":1646215503347,"mc":[{"id":"1.195503853","rc":[{"atb":[[1.93,0]],"id":39786791},{"trd":[[1.93,11.59]],"ltp":1.93,"tv":11.59,"id":39786791}],"con":true,"img":false}]}
{"op":"mcm","clk":"5353475397","pt":1646215504029,"mc":[{"id":"1.195503853","rc":[{"atl":[[2.18,2],[2.2,0]],"id":43167135}],"con":true,"img":false}]}
{"op":"mcm","clk":"5353476110","pt":1646215512256,"mc":[{"id":"1.195503853","rc":[{"atb":[[1.85,1.42]],"id":43167135}],"con":true,"img":false}]}
{"op":"mcm","clk":"5353476119","pt":1646215512358,"mc":[{"id":"1.195503853","rc":[{"atb":[[1.82,5.42]],"id":43167135}],"con":true,"img":false}]}
{"op":"mcm","clk":"5353476145","pt":1646215512674,"mc":[{"id":"1.195503853","rc":[{"atb":[[1.83,0],[1.85,2]],"id":39786791}],"con":true,"img":false}]}
{"op":"mcm","clk":"5353476239","pt":1646215513670,"mc":[{"id":"1.195503853","rc":[{"atl":[[2.18,0],[2.2,2]],"id":43167135}],"con":true,"img":false}]}
{"op":"mcm","clk":"5353476436","pt":1646215516264,"mc":[{"id":"1.195503853","rc":[{"atl":[[2.18,2],[2.2,0]],"id":43167135}],"con":true,"img":false}]}
{"op":"mcm","clk":"5353476548","pt":1646215517569,"mc":[{"id":"1.195503853","rc":[{"atb":[[1.93,0],[1.91,0],[1.94,0]],"id":43167135},{"atl":[[1.96,82.72]],"id":43167135},{"trd":[[1.91,2.84],[1.92,1.54],[1.96,1.48],[1.94,2.84],[1.93,2.84]],"ltp":1.91,"tv":11.54,"id":43167135},{"atl":[[2.08,0],[2.04,0]],"id":39786791},{"trd":[[2.08,1.42],[2.04,1.42]],"ltp":2.08,"tv":2.84,"id":39786791}],"con":true,"img":false}]}
{"op":"mcm","clk":"5353476565","pt":1646215517778,"mc":[{"id":"1.195503853","rc":[{"atl":[[2.2,3.42],[2.16,1.42]],"id":39786791}],"con":true,"img":false}]}
{"op":"mcm","clk":"5353476717","pt":1646215519599,"mc":[{"id":"1.195503853","rc":[{"atb":[[1.9,0]],"id":43167135}],"con":true,"img":false}]}
{"op":"mcm","clk":"5353476875","pt":1646215521578,"mc":[{"id":"1.195503853","rc":[{"atl":[[2.28,1.42]],"id":39786791}],"con":true,"img":false}]}
{"op":"mcm","clk":"5353476922","pt":1646215522050,"mc":[{"id":"1.195503853","rc":[{"atb":[[1.89,0]],"id":43167135}],"con":true,"img":false}]}
{"op":"mcm","clk":"5353477102","pt":1646215524282,"mc":[{"id":"1.195503853","rc":[{"atl":[[1.96,0]],"id":43167135}],"con":true,"img":false}]}
{"op":"mcm","clk":"5353477108","pt":1646215524381,"mc":[{"id":"1.195503853","rc":[{"atb":[[1.88,0],[1.87,0]],"id":43167135},{"atl":[[1.87,79.88]],"id":43167135},{"trd":[[1.87,2.84],[1.88,2.84]],"ltp":1.87,"tv":5.68,"id":43167135}],"con":true,"img":false}]}
{"op":"mcm","clk":"5353477120","pt":1646215524493,"mc":[{"id":"1.195503853","rc":[{"atl":[[1.87,0],[2.18,0],[2.2,2]],"id":43167135},{"trd":[[1.87,162.6]],"ltp":1.87,"tv":162.6,"id":43167135}],"con":true,"img":false}]}
{"op":"mcm","clk":"5353477147","pt":1646215524799,"mc":[{"id":"1.195503853","rc":[{"atb":[[1.83,4],[1.82,3.42]],"id":43167135},{"atl":[[2.2,6]],"id":43167135},{"atb":[[1.85,6.02]],"id":39786791},{"atl":[[2.18,3.42],[2.2,1.42]],"id":39786791}],"con":true,"img":false}]}
{"op":"mcm","clk":"5353477342","pt":1646215527771,"mc":[{"id":"1.195503853","rc":[{"atb":[[1.86,5],[1.85,0],[1.82,2]],"id":43167135},{"atl":[[2.16,0]],"id":39786791}],"con":true,"img":false}]}
{"op":"mcm","clk":"5353477368","pt":1646215528219,"mc":[{"id":"1.195503853","rc":[{"atl":[[2.2,2]],"id":43167135},{"atb":[[1.85,2]],"id":39786791}],"con":true,"img":false}]}
{"op":"mcm","clk":"5353477392","pt":1646215528495,"mc":[{"id":"1.195503853","rc":[{"atl":[[2.2,6]],"id":43167135},{"atb":[[1.85,6.02]],"id":39786791}],"con":true,"img":false}]}
{"op":"mcm","clk":"5353477500","pt":1646215529853,"mc":[{"id":"1.195503853","rc":[{"atb":[[1.81,14],[1.83,2]],"id":43167135},{"atl":[[2.2,3.42]],"id":39786791}],"con":true,"img":false}]}
{"op":"mcm","clk":"5353477508","pt":1646215529962,"mc":[{"id":"1.195503853","rc":[{"atl":[[2.12,1.42]],"id":39786791}],"con":true,"img":false}]}
{"op":"mcm","clk":"5353477513","pt":1646215530064,"mc":[{"id":"1.195503853","rc":[{"atl":[[2.18,1.42]],"id":39786791}],"con":true,"img":false}]}
{"op":"mcm","clk":"5353477811","pt":1646215533601,"mc":[{"id":"1.195503853","rc":[{"atl":[[2.12,0]],"id":39786791}],"con":true,"img":false}]}
{"op":"mcm","clk":"5353478008","pt":1646215535999,"mc":[{"id":"1.195503853","rc":[{"atb":[[1.86,0]],"id":43167135},{"atl":[[2.2,1.42],[2.22,3.42]],"id":39786791}],"con":true,"img":false}]}
{"op":"mcm","clk":"5353478025","pt":1646215536203,"mc":[{"id":"1.195503853","rc":[{"atl":[[2.12,1.42]],"id":39786791}],"con":true,"img":false}]}
{"op":"mcm","clk":"5353478238","pt":1646215538712,"mc":[{"id":"1.195503853","rc":[{"atl":[[2.12,0]],"id":39786791}],"con":true,"img":false}]}
{"op":"mcm","clk":"5353478432","pt":1646215541014,"mc":[{"id":"1.195503853","rc":[{"atb":[[1.86,1.42]],"id":39786791},{"atl":[[2.12,1.42]],"id":39786791}],"con":true,"img":false}]}
{"op":"mcm","clk":"5353478442","pt":1646215541120,"mc":[{"id":"1.195503853","rc":[{"atl":[[2.18,0]],"id":39786791}],"con":true,"img":false}]}
{"op":"mcm","clk":"5353478449","pt":1646215541176,"mc":[{"id":"1.195503853","rc":[{"atl":[[2.18,2],[2.2,4]],"id":43167135}],"con":true,"img":false}]}
{"op":"mcm","clk":"5353478452","pt":1646215541279,"mc":[{"id":"1.195503853","rc":[{"atb":[[1.85,2]],"id":39786791}],"con":true,"img":false}]}
{"op":"mcm","clk":"5353478468","pt":1646215541392,"mc":[{"id":"1.195503853","rc":[{"atb":[[1.86,5.44]],"id":39786791}],"con":true,"img":false}]}
{"op":"mcm","clk":"5353478477","pt":1646215541489,"mc":[{"id":"1.195503853","rc":[{"atl":[[2.2,0]],"id":43167135}],"con":true,"img":false}]}
{"op":"mcm","clk":"5353478483","pt":1646215541595,"mc":[{"id":"1.195503853","rc":[{"atl":[[2.18,6]],"id":43167135}],"con":true,"img":false}]}
{"op":"mcm","clk":"5353478636","pt":1646215543487,"mc":[{"id":"1.195503853","rc":[{"atb":[[1.88,1.42]],"id":39786791}],"con":true,"img":false}]}
{"op":"mcm","clk":"5353478644","pt":1646215543592,"mc":[{"id":"1.195503853","rc":[{"atl":[[2.12,0]],"id":39786791}],"con":true,"img":false}]}
{"op":"mcm","clk":"5353478661","pt":1646215543902,"mc":[{"id":"1.195503853","rc":[{"atb":[[1.86,1.42]],"id":39786791}],"con":true,"img":false}]}
{"op":"mcm","clk":"5353478673","pt":1646215544006,"mc":[{"id":"1.195503853","rc":[{"atb":[[1.88,5.44]],"id":39786791}],"con":true,"img":false}]}
{"op":"mcm","clk":"5353478717","pt":1646215544691,"mc":[{"id":"1.195503853","rc":[{"atb":[[1.88,6.86]],"id":39786791}],"con":true,"img":false}]}
{"op":"mcm","clk":"5353478897","pt":1646215546926,"mc":[{"id":"1.195503853","rc":[{"atb":[[1.9,1.42]],"id":39786791},{"atl":[[2.1,1.42]],"id":39786791}],"con":true,"img":false}]}
{"op":"mcm","clk":"5353478914","pt":1646215547088,"mc":[{"id":"1.195503853","rc":[{"atl":[[2.2,3.42],[2.22,1.42]],"id":39786791}],"con":true,"img":false}]}
{"op":"mcm","clk":"5353478932","pt":1646215547296,"mc":[{"id":"1.195503853","rc":[{"atb":[[1.88,2.84]],"id":39786791}],"con":true,"img":false}]}
{"op":"mcm","clk":"5353478943","pt":1646215547401,"mc":[{"id":"1.195503853","rc":[{"atb":[[1.9,5.44]],"id":39786791}],"con":true,"img":false}]}
{"op":"mcm","clk":"5353478967","pt":1646215547710,"mc":[{"id":"1.195503853","rc":[{"atb":[[1.9,1.42]],"id":39786791}],"con":true,"img":false}]}
{"op":"mcm","clk":"5353479004","pt":1646215547981,"mc":[{"id":"1.195503853","rc":[{"atb":[[1.9,4.28]],"id":39786791}],"con":true,"img":false}]}
{"op":"mcm","clk":"5353479100","pt":1646215548979,"mc":[{"id":"1.195503853","rc":[{"atl":[[2.08,1.42]],"id":39786791}],"con":true,"img":false}]}
{"op":"mcm","clk":"5353479255","pt":1646215550698,"mc":[{"id":"1.195503853","rc":[{"atl":[[2.1,0]],"id":39786791}],"con":true,"img":false}]}
{"op":"mcm","clk":"5353479417","pt":1646215552514,"mc":[{"id":"1.195503853","rc":[{"atl":[[2.18,1.42]],"id":39786791}],"con":true,"img":false}]}
{"op":"mcm","clk":"5353479436","pt":1646215552825,"mc":[{"id":"1.195503853","rc":[{"atl":[[2.08,0]],"id":39786791}],"con":true,"img":false}]}
{"op":"mcm","clk":"5353479447","pt":1646215552986,"mc":[{"id":"1.195503853","rc":[{"atl":[[2.2,1.42],[2.22,3.42]],"id":39786791}],"con":true,"img":false}]}
{"op":"mcm","clk":"5353479514","pt":1646215553721,"mc":[{"id":"1.195503853","rc":[{"atb":[[1.2,0],[1.4,0],[1.6,2]],"id":43167135},{"atb":[[1.73,0],[1.93,0],[1.53,0]],"id":39786791}],"con":true,"img":false}]}
{"op":"mcm","clk":"5353479534","pt":1646215553931,"mc":[{"id":"1.195503853","rc":[{"atb":[[1.85,0],[1.86,3.42]],"id":39786791}],"con":true,"img":false}]}
{"op":"mcm","clk":"5353479615","pt":1646215554934,"mc":[{"id":"1.195503853","rc":[{"atl":[[2.08,1.42]],"id":39786791}],"con":true,"img":false}]}
{"op":"mcm","clk":"5353479648","pt":1646215555298,"mc":[{"id":"1.195503853","rc":[{"atl":[[2.18,0]],"id":39786791}],"con":true,"img":false}]}
{"op":"mcm","clk":"5353479712","pt":1646215555929,"mc":[{"id":"1.195503853","rc":[{"atl":[[2.14,2],[2.18,4]],"id":43167135}],"con":true,"img":false}]}
{"op":"mcm","clk":"5353479746","pt":1646215556288,"mc":[{"id":"1.195503853","rc":[{"atb":[[1.81,12],[1.8,4]],"id":43167135},{"atl":[[2.18,0]],"id":43167135}],"con":true,"img":false}]}
{"op":"mcm","clk":"5353479758","pt":1646215556393,"mc":[{"id":"1.195503853","rc":[{"atl":[[2.14,6]],"id":43167135}],"con":true,"img":false}]}
{"op":"mcm","clk":"5353479866","pt":1646215557496,"mc":[{"id":"1.195503853","rc":[{"atl":[[2.18,1.42]],"id":39786791}],"con":true,"img":false}]}
{"op":"mcm","clk":"5353479934","pt":1646215558430,"mc":[{"id":"1.195503853","rc":[{"atb":[[1.86,2]],"id":39786791},{"atl":[[2.08,0]],"id":39786791}],"con":true,"img":false}]}
{"op":"mcm","clk":"5353480116","pt":1646215560214,"mc":[{"id":"1.195503853","rc":[{"atl":[[2.08,1.42]],"id":39786791}],"con":true,"img":false}]}
{"op":"mcm","clk":"5353480177","pt":1646215560890,"mc":[{"id":"1.195503853","rc":[{"atl":[[2.18,0]],"id":39786791}],"con":true,"img":false}]}
{"op":"mcm","clk":"5353480216","pt":1646215561410,"mc":[{"id":"1.195503853","rc":[{"atb":[[1.81,14],[1.8,2]],"id":43167135}],"con":true,"img":false}]}
{"op":"mcm","clk":"5353480339","pt":1646215562832,"mc":[{"id":"1.195503853","rc":[{"atl":[[2.1,1.42]],"id":39786791}],"con":true,"img":false}]}
{"op":"mcm","clk":"5353480435","pt":1646215563920,"mc":[{"id":"1.195503853","rc":[{"atl":[[2.08,0]],"id":39786791}],"con":true,"img":false}]}
{"op":"mcm","clk":"5353480675","pt":1646215566541,"mc":[{"id":"1.195503853","rc":[{"atl":[[2.1,0]],"id":39786791}],"con":true,"img":false}]}
{"op":"mcm","clk":"5353480852","pt":1646215568425,"mc":[{"id":"1.195503853","rc":[{"atb":[[1.17,31.74],[1.37,74.58],[1.57,11.46]],"id":43167135},{"atb":[[1.96,5.61],[1.76,7.1],[1.56,11.63]],"id":39786791}],"con":true,"img":false}]}
{"op":"mcm","clk":"5353480892","pt":1646215568801,"mc":[{"id":"1.195503853","rc":[{"atl":[[2.12,1.42]],"id":39786791}],"con":true,"img":false}]}
{"op":"mcm","clk":"5353480993","pt":1646215569896,"mc":[{"id":"1.195503853","rc":[{"atl":[[2.12,2.84]],"id":39786791}],"con":true,"img":false}]}
{"op":"mcm","clk":"5353481014","pt":1646215570109,"mc":[{"id":"1.195503853","rc":[{"atb":[[1.81,12],[1.84,0],[1.8,4]],"id":43167135}],"con":true,"img":false}]}
{"op":"mcm","clk":"5353481063","pt":1646215570624,"mc":[{"id":"1.195503853","rc":[{"atb":[[1.83,0],[1.82,0],[1.8,2],[1.79,2]],"id":43167135},{"atl":[[2.24,3.42],[2.22,1.42]],"id":39786791}],"con":true,"img":false}]}
{"op":"mcm","clk":"5353481092","pt":1646215571035,"mc":[{"id":"1.195503853","rc":[{"atb":[[1.88,0]],"id":39786791},{"atl":[[2.12,1.42]],"id":39786791}],"con":true,"img":false}]}
{"op":"mcm","clk":"5353481309","pt":1646215573222,"mc":[{"id":"1.195503853","rc":[{"atl":[[2.12,2],[2.14,4]],"id":43167135}],"con":true,"img":false}]}
{"op":"mcm","clk":"5353481357","pt":1646215573633,"mc":[{"id":"1.195503853","rc":[{"atl":[[2.14,0]],"id":43167135}],"con":true,"img":false}]}
{"op":"mcm","clk":"5353481362","pt":1646215573735,"mc":[{"id":"1.195503853","rc":[{"atl":[[2.12,6]],"id":43167135},{"atl":[[2.12,0]],"id":39786791}],"con":true,"img":false}]}
{"op":"mcm","clk":"5353481536","pt":1646215575721,"mc":[{"id":"1.195503853","rc":[{"atl":[[2.12,4],[2.14,2]],"id":43167135},{"atl":[[2.24,1.42],[2.22,3.42]],"id":39786791}],"con":true,"img":false}]}
{"op":"mcm","clk":"5353481557","pt":1646215576031,"mc":[{"id":"1.195503853","rc":[{"atl":[[2.12,0]],"id":43167135}],"con":true,"img":false}]}
{"op":"mcm","clk":"5353481580","pt":1646215576340,"mc":[{"id":"1.195503853","rc":[{"atl":[[2.14,6]],"id":43167135},{"atb":[[1.9,1.42]],"id":39786791}],"con":true,"img":false}]}
{"op":"mcm","clk":"5353481604","pt":1646215576680,"mc":[{"id":"1.195503853","rc":[{"atl":[[2.2,0]],"id":39786791}],"con":true,"img":false}]}
{"op":"mcm","clk":"5353481610","pt":1646215576704,"mc":[{"id":"1.195503853","rc":[{"atb":[[1.96,16.85]],"id":39786791}],"con":true,"img":false}]}
{"op":"mcm","clk":"5353481780","pt":1646215578740,"mc":[{"id":"1.195503853","rc":[{"atl":[[2.14,1.42]],"id":39786791}],"con":true,"img":false}]}
{"op":"mcm","clk":"5353481816","pt":1646215579160,"mc":[{"id":"1.195503853","rc":[{"atb":[[1.9,0]],"id":39786791},{"atl":[[2.22,2]],"id":39786791}],"con":true,"img":false}]}
{"op":"mcm","clk":"5353481961","pt":1646215580840,"mc":[{"id":"1.195503853","rc":[{"atl":[[2.12,2],[2.14,4]],"id":43167135},{"atl":[[2.24,3.42]],"id":39786791}],"con":true,"img":false}]}
{"op":"mcm","clk":"5353481970","pt":1646215580939,"mc":[{"id":"1.195503853","rc":[{"atl":[[2.22,0]],"id":39786791}],"con":true,"img":false}]}
{"op":"mcm","clk":"5353481997","pt":1646215581259,"mc":[{"id":"1.195503853","rc":[{"atb":[[1.81,0]],"id":43167135},{"atl":[[2.14,0],[1.81,24.52]],"id":43167135},{"trd":[[1.81,23.98],[1.87,164.23]],"ltp":1.81,"tv":188.2,"id":43167135},{"atl":[[2.14,0]],"id":39786791},{"trd":[[2.14,1.42]],"ltp":2.14,"tv":1.42,"id":39786791}],"con":true,"img":false}]}
{"op":"mcm","clk":"5353482003","pt":1646215581361,"mc":[{"id":"1.195503853","rc":[{"atl":[[2.12,6],[1.81,0.01]],"id":43167135},{"trd":[[1.81,73.03]],"ltp":1.81,"tv":73.03,"id":43167135}],"con":true,"img":false}]}
{"op":"mcm","clk":"5353482015","pt":1646215581417,"mc":[{"id":"1.195503853","rc":[{"atl":[[1.81,0]],"id":43167135},{"trd":[[1.81,73.06]],"ltp":1.81,"tv":73.06,"id":43167135}],"con":true,"img":false}]}
{"op":"mcm","clk":"5353482024","pt":1646215581522,"mc":[{"id":"1.195503853","rc":[{"atb":[[1.78,39],[1.79,0]],"id":43167135}],"con":true,"img":false}]}
{"op":"mcm","clk":"5353482072","pt":1646215582040,"mc":[{"id":"1.195503853","rc":[{"atl":[[1.81,2.72]],"id":43167135}],"con":true,"img":false}]}
{"op":"mcm","clk":"5353482092","pt":1646215582245,"mc":[{"id":"1.195503853","rc":[{"atl":[[1.81,0]],"id":43167135},{"trd":[[1.81,78.52]],"ltp":1.81,"tv":78.52,"id":43167135}],"con":true,"img":false}]}
{"op":"mcm","clk":"5353482111","pt":1646215582452,"mc":[{"id":"1.195503853","rc":[{"atb":[[1.76,90.38]],"id":43167135}],"con":true,"img":false}]}
{"op":"mcm","clk":"5353482150","pt":1646215582924,"mc":[{"id":"1.195503853","rc":[{"atb":[[1.76,52]],"id":43167135}],"con":true,"img":false}]}
{"op":"mcm","clk":"5353482240","pt":1646215584114,"mc":[{"id":"1.195503853","rc":[{"atl":[[2.16,1.42]],"id":39786791}],"con":true,"img":false}]}
{"op":"mcm","clk":"5353482386","pt":1646215585940,"mc":[{"id":"1.195503853","rc":[{"atl":[[2.14,2]],"id":43167135},{"atl":[[2.24,1.42],[2.22,2]],"id":39786791}],"con":true,"img":false}]}
{"op":"mcm","clk":"5353482397","pt":1646215586041,"mc":[{"id":"1.195503853","rc":[{"atl":[[2.12,4]],"id":43167135}],"con":true,"img":false}]}
{"op":"mcm","clk":"5353482426","pt":1646215586354,"mc":[{"id":"1.195503853","rc":[{"atl":[[2.12,0]],"id":43167135}],"con":true,"img":false}]}
{"op":"mcm","clk":"5353482452","pt":1646215586622,"mc":[{"id":"1.195503853","rc":[{"atl":[[2.14,6]],"id":43167135}],"con":true,"img":false}]}
{"op":"mcm","clk":"5353482461","pt":1646215586728,"mc":[{"id":"1.195503853","rc":[{"atb":[[1.78,37],[1.77,20]],"id":43167135}],"con":true,"img":false}]}
{"op":"mcm","clk":"5353482473","pt":1646215586933,"mc":[{"id":"1.195503853","rc":[{"atl":[[2.16,0]],"id":39786791}],"con":true,"img":false}]}
{"op":"mcm","clk":"5353482631","pt":1646215589049,"mc":[{"id":"1.195503853","rc":[{"atl":[[2.16,1.42]],"id":39786791}],"con":true,"img":false}]}
{"op":"mcm","clk":"5353482815","pt":1646215591130,"mc":[{"id":"1.195503853","rc":[{"atl":[[2.2,10],[2.22,0]],"id":39786791}],"con":true,"img":false}]}
{"op":"mcm","clk":"5353482914","pt":1646215592333,"mc":[{"id":"1.195503853","rc":[{"atl":[[2.16,0]],"id":39786791}],"con":true,"img":false}]}
{"op":"mcm","clk":"5353483126","pt":1646215594523,"mc":[{"id":"1.195503853","rc":[{"atl":[[2.14,1.42]],"id":39786791}],"con":true,"img":false}]}
{"op":"mcm","clk":"5353483368","pt":1646215597142,"mc":[{"id":"1.195503853","rc":[{"atl":[[2.16,1.42]],"id":39786791}],"con":true,"img":false}]}
{"op":"mcm","clk":"5353483392","pt":1646215597354,"mc":[{"id":"1.195503853","rc":[{"atl":[[2.12,2],[2.14,4]],"id":43167135},{"atb":[[1.88,2],[1.86,0]],"id":39786791},{"atl":[[2.2,0],[2.22,2]],"id":39786791}],"con":true,"img":false}]}
{"op":"mcm","clk":"5353483407","pt":1646215597459,"mc":[{"id":"1.195503853","rc":[{"atl":[[2.14,0]],"id":39786791}],"con":true,"img":false}]}
{"op":"mcm","clk":"5353483438","pt":1646215597770,"mc":[{"id":"1.195503853","rc":[{"atl":[[2.14,0]],"id":43167135}],"con":true,"img":false}]}
{"op":"mcm","clk":"5353483447","pt":1646215597875,"mc":[{"id":"1.195503853","rc":[{"atl":[[2.12,6]],"id":43167135}],"con":true,"img":false}]}
{"op":"mcm","clk":"5353483474","pt":1646215598135,"mc":[{"id":"1.195503853","rc":[{"atl":[[2.12,2]],"id":43167135}],"con":true,"img":false}]}
{"op":"mcm","clk":"5353483483","pt":1646215598243,"mc":[{"id":"1.195503853","rc":[{"atl":[[2.12,0],[2.14,2]],"id":43167135}],"con":true,"img":false}]}
{"op":"mcm","clk":"5353483500","pt":1646215598451,"mc":[{"id":"1.195503853","rc":[{"atl":[[2.12,4]],"id":43167135}],"con":true,"img":false}]}
{"op":"mcm","clk":"5353483519","pt":1646215598662,"mc":[{"id":"1.195503853","rc":[{"atl":[[2.12,6],[2.14,0]],"id":43167135},{"atl":[[2.16,2.84]],"id":39786791}],"con":true,"img":false}]}
{"op":"mcm","clk":"5353483526","pt":1646215598765,"mc":[{"id":"1.195503853","rc":[{"atl":[[2.12,2]],"id":43167135}],"con":true,"img":false}]}
{"op":"mcm","clk":"5353483549","pt":1646215599029,"mc":[{"id":"1.195503853","rc":[{"atl":[[2.12,6]],"id":43167135}],"con":true,"img":false}]}
{"op":"mcm","clk":"5353483596","pt":1646215599549,"mc":[{"id":"1.195503853","rc":[{"atl":[[2.16,1.42]],"id":39786791}],"con":true,"img":false}]}
{"op":"mcm","clk":"5353483739","pt":1646215601471,"mc":[{"id":"1.195503853","rc":[{"atl":[[2.2,2],[2.22,0]],"id":39786791}],"con":true,"img":false}]}
{"op":"mcm","clk":"5353483771","pt":1646215601738,"mc":[{"id":"1.195503853","rc":[{"atl":[[2.16,0]],"id":39786791}],"con":true,"img":false}]}
{"op":"mcm","clk":"5353484254","pt":1646215606534,"mc":[{"id":"1.195503853","rc":[{"atl":[[2.24,3.42]],"id":39786791}],"con":true,"img":false}]}
{"op":"mcm","clk":"5353484263","pt":1646215606637,"mc":[{"id":"1.195503853","rc":[{"atl":[[2.2,0]],"id":39786791}],"con":true,"img":false}]}
{"op":"mcm","clk":"5353484387","pt":1646215608143,"mc":[{"id":"1.195503853","rc":[{"atl":[[1.83,14]],"id":43167135}],"con":true,"img":false}]}
{"op":"mcm","clk":"5353484397","pt":1646215608303,"mc":[{"id":"1.195503853","rc":[{"atl":[[1.83,0]],"id":43167135},{"trd":[[1.83,28]],"ltp":1.83,"tv":28.0,"id":43167135}],"con":true,"img":false}]}
{"op":"mcm","clk":"5353484412","pt":1646215608461,"mc":[{"id":"1.195503853","rc":[{"atb":[[1.76,90.38]],"id":43167135},{"atb":[[1.97,30.07]],"id":39786791}],"con":true,"img":false}]}
{"op":"mcm","clk":"5353484449","pt":1646215608873,"mc":[{"id":"1.195503853","rc":[{"atl":[[2.16,1.42]],"id":39786791}],"con":true,"img":false}]}
{"op":"mcm","clk":"5353484459","pt":1646215608978,"mc":[{"id":"1.195503853","rc":[{"atb":[[1.96,5.61],[1.97,0]],"id":39786791}],"con":true,"img":false}]}
{"op":"mcm","clk":"5353484488","pt":1646215609346,"mc":[{"id":"1.195503853","rc":[{"atb":[[1.96,16.85]],"id":39786791}],"con":true,"img":false}]}
{"op":"mcm","clk":"5353484499","pt":1646215609449,"mc":[{"id":"1.195503853","rc":[{"atb":[[1.76,52]],"id":43167135}],"con":true,"img":false}]}
{"op":"mcm","clk":"5353484693","pt":1646215611679,"mc":[{"id":"1.195503853","rc":[{"atl":[[2.24,1.42],[2.2,2],[2.16,0]],"id":39786791}],"con":true,"img":false}]}
{"op":"mcm","clk":"5353484718","pt":1646215611990,"mc":[{"id":"1.195503853","rc":[{"atb":[[2.02,2.76]],"id":39786791}],"con":true,"img":false}]}
{"op":"mcm","clk":"5353484932","pt":1646215614180,"mc":[{"id":"1.195503853","rc":[{"atb":[[1.17,0],[1.37,60],[1.57,2]],"id":43167135},{"atb":[[1.96,11.24],[1.76,0],[1.56,2]],"id":39786791}],"con":true,"img":false}]}
{"op":"mcm","clk":"5353485104","pt":1646215616013,"mc":[{"id":"1.195503853","rc":[{"atb":[[2.02,0]],"id":39786791}],"con":true,"img":false}]}
{"op":"mcm","clk":"5353485110","pt":1646215616066,"mc":[{"id":"1.195503853","rc":[{"atb":[[1.98,2.76]],"id":39786791}],"con":true,"img":false}]}
{"op":"mcm","clk":"5353485123","pt":1646215616168,"mc":[{"id":"1.195503853","rc":[{"atl":[[2.12,2]],"id":43167135},{"atb":[[1.96,0]],"id":39786791}],"con":true,"img":false}]}
{"op":"mcm","clk":"5353485134","pt":1646215616273,"mc":[{"id":"1.195503853","rc":[{"atl":[[2.12,0]],"id":43167135}],"con":true,"img":false}]}
{"op":"mcm","clk":"5353485149","pt":1646215616376,"mc":[{"id":"1.195503853","rc":[{"atb":[[1.78,74.4]],"id":43167135},{"atl":[[2.2,2]],"id":43167135}],"con":true,"img":false}]}
{"op":"mcm","clk":"5353485160","pt":1646215616481,"mc":[{"id":"1.195503853","rc":[{"atb":[[1.77,18],[1.79,2]],"id":43167135},{"atl":[[2.46,40.9]],"id":43167135},{"atb":[[1.98,8.3]],"id":39786791}],"con":true,"img":false}]}
{"op":"mcm","clk":"5353485187","pt":1646215616689,"mc":[{"id":"1.195503853","rc":[{"atb":[[1.78,37.4],[1.77,20],[1.8,0],[1.79,0]],"id":43167135},{"atb":[[1.98,10.3],[1.88,0]],"id":39786791},{"atl":[[2.2,0]],"id":39786791}],"con":true,"img":false}]}
{"op":"mcm","clk":"5353485195","pt":1646215616795,"mc":[{"id":"1.195503853","rc":[{"atl":[[2.28,3.42]],"id":39786791}],"con":true,"img":false}]}
{"op":"mcm","clk":"5353485207","pt":1646215616898,"mc":[{"id":"1.195503853","rc":[{"atb":[[1.78,0]],"id":43167135}],"con":true,"img":false}]}
{"op":"mcm","clk":"5353485216","pt":1646215617004,"mc":[{"id":"1.195503853","rc":[{"atb":[[1.78,8.03]],"id":43167135}],"con":true,"img":false}]}
{"op":"mcm","clk":"5353485239","pt":1646215617369,"mc":[{"id":"1.195503853","rc":[{"atb":[[1.76,90.38]],"id":43167135}],"con":true,"img":false}]}
{"op":"mcm","clk":"5353485259","pt":1646215617678,"mc":[{"id":"1.195503853","rc":[{"atb":[[1.78,0]],"id":43167135}],"con":true,"img":false}]}
{"op":"mcm","clk":"5353485300","pt":1646215618200,"mc":[{"id":"1.195503853","rc":[{"atl":[[2.46,15]],"id":43167135},{"atb":[[1.98,4.76]],"id":39786791}],"con":true,"img":false}]}
{"op":"mcm","clk":"5353485325","pt":1646215618461,"mc":[{"id":"1.195503853","rc":[{"atb":[[1.77,28.24]],"id":43167135},{"atl":[[2.2,6]],"id":43167135},{"atb":[[1.98,14.3]],"id":39786791}],"con":true,"img":false}]}
{"op":"mcm","clk":"5353485361","pt":1646215618879,"mc":[{"id":"1.195503853","rc":[{"atb":[[1.76,52]],"id":43167135}],"con":true,"img":false}]}
{"op":"mcm","clk":"5353485412","pt":1646215619397,"mc":[{"id":"1.195503853","rc":[{"atl":[[2.18,1.42]],"id":39786791}],"con":true,"img":false}]}
{"op":"mcm","clk":"5353485430","pt":1646215619608,"mc":[{"id":"1.195503853","rc":[{"atb":[[1.77,20]],"id":43167135}],"con":true,"img":false}]}
{"op":"mcm","clk":"5353485609","pt":1646215621797,"mc":[{"id":"1.195503853","rc":[{"atb":[[1.77,18]],"id":43167135},{"atl":[[2.18,0]],"id":39786791}],"con":true,"img":false}]}
{"op":"mcm","clk":"5353485620","pt":1646215621901,"mc":[{"id":"1.195503853","rc":[{"atb":[[1.75,6]],"id":43167135},{"atl":[[2.18,2],[2.2,4]],"id":43167135}],"con":true,"img":false}]}
{"op":"mcm","clk":"5353485631","pt":1646215622004,"mc":[{"id":"1.195503853","rc":[{"atl":[[2.28,1.42],[2.26,2]],"id":39786791}],"con":true,"img":false}]}
{"op":"mcm","clk":"5353485648","pt":1646215622160,"mc":[{"id":"1.195503853","rc":[{"atl":[[2.2,0]],"id":43167135}],"con":true,"img":false}]}
{"op":"mcm","clk":"5353485659","pt":1646215622315,"mc":[{"id":"1.195503853","rc":[{"atl":[[2.18,6]],"id":43167135}],"con":true,"img":false}]}
{"op":"mcm","clk":"5353485700","pt":1646215622785,"mc":[{"id":"1.195503853","rc":[{"trd":[[1.8,0.05]],"ltp":1.8,"tv":0.05,"id":43167135},{"atl":[[2.24,1.37]],"id":39786791},{"trd":[[2.24,0.04]],"ltp":2.24,"tv":0.04,"id":39786791}],"con":true,"img":false}]}
{"op":"mcm","clk":"5353485714","pt":1646215622889,"mc":[{"id":"1.195503853","rc":[{"atb":[[1.77,27.05]],"id":43167135}],"con":true,"img":false}]}
{"op":"mcm","clk":"5353485726","pt":1646215622992,"mc":[{"id":"1.195503853","rc":[{"atb":[[1.77,29.05],[1.75,4]],"id":43167135}],"con":true,"img":false}]}
{"op":"mcm","clk":"5353485837","pt":1646215624302,"mc":[{"id":"1.195503853","rc":[{"atl":[[2.18,1.42]],"id":39786791}],"con":true,"img":false}]}
{"op":"mcm","clk":"5353485958","pt":1646215625888,"mc":[{"id":"1.195503853","rc":[{"atl":[[2.18,4],[2.16,2]],"id":43167135}],"con":true,"img":false}]}
{"op":"mcm","clk":"5353485969","pt":1646215625988,"mc":[{"id":"1.195503853","rc":[{"atl":[[2.28,3.42],[2.26,0]],"id":39786791}],"con":true,"img":false}]}
{"op":"mcm","clk":"5353485985","pt":1646215626198,"mc":[{"id":"1.195503853","rc":[{"atl":[[2.18,0]],"id":43167135}],"con":true,"img":false}]}
{"op":"mcm","clk":"5353485993","pt":1646215626302,"mc":[{"id":"1.195503853","rc":[{"atl":[[2.16,6]],"id":43167135},{"atl":[[2.18,0]],"id":39786791}],"con":true,"img":false}]}
{"op":"mcm","clk":"5353486196","pt":1646215628486,"mc":[{"id":"1.195503853","rc":[{"atl":[[2.16,1.42]],"id":39786791}],"con":true,"img":false}]}
{"op":"mcm","clk":"5353486331","pt":1646215629691,"mc":[{"id":"1.195503853","rc":[{"atb":[[1.77,20]],"id":43167135},{"atb":[[1.98,12.3],[1.97,2]],"id":39786791}],"con":true,"img":false}]}
{"op":"mcm","clk":"5353486349","pt":1646215629898,"mc":[{"id":"1.195503853","rc":[{"atb":[[1.77,18],[1.75,6]],"id":43167135}],"con":true,"img":false}]}
{"op":"mcm","clk":"5353486430","pt":1646215630684,"mc":[{"id":"1.195503853","rc":[{"atl":[[2.16,0]],"id":39786791}],"con":true,"img":false}]}
{"op":"mcm","clk":"5353486478","pt":1646215631203,"mc":[{"id":"1.195503853","rc":[{"atl":[[2.28,1.42],[2.26,2]],"id":39786791}],"con":true,"img":false}]}
{"op":"mcm","clk":"5353486623","pt":1646215632873,"mc":[{"id":"1.195503853","rc":[{"atl":[[2.18,1.42]],"id":39786791}],"con":true,"img":false}]}
{"op":"mcm","clk":"5353486786","pt":1646215635003,"mc":[{"id":"1.195503853","rc":[{"atl":[[2.18,2.84]],"id":39786791}],"con":true,"img":false}]}
{"op":"mcm","clk":"5353486810","pt":1646215635318,"mc":[{"id":"1.195503853","rc":[{"atb":[[1.53,53.18],[1.13,41.5],[1.33,16.34]],"id":43167135},{"atb":[[1.59,9.14],[1.99,5.44],[1.79,6.82]],"id":39786791}],"con":true,"img":false}]}
{"op":"mcm","clk":"5353486835","pt":1646215635586,"mc":[{"id":"1.195503853","rc":[{"atb":[[1.98,2.76]],"id":39786791}],"con":true,"img":false}]}
{"op":"mcm","clk":"5353486856","pt":1646215635897,"mc":[{"id":"1.195503853","rc":[{"atl":[[2.18,1.42]],"id":39786791}],"con":true,"img":false}]}
{"op":"mcm","clk":"5353486863","pt":1646215636002,"mc":[{"id":"1.195503853","rc":[{"atb":[[1.98,4.76],[1.99,16.34]],"id":39786791}],"con":true,"img":false}]}
{"op":"mcm","clk":"5353486868","pt":1646215636107,"mc":[{"id":"1.195503853","rc":[{"atb":[[1.97,0]],"id":39786791}],"con":true,"img":false}]}
{"op":"mcm","clk":"5353486894","pt":1646215636371,"mc":[{"id":"1.195503853","rc":[{"atb":[[1.98,2]],"id":39786791}],"con":true,"img":false}]}
{"op":"mcm","clk":"5353486902","pt":1646215636478,"mc":[{"id":"1.195503853","rc":[{"atb":[[1.77,25.58]],"id":43167135},{"atb":[[2,2.76]],"id":39786791}],"con":true,"img":false}]}
{"op":"mcm","clk":"5353486911","pt":1646215636579,"mc":[{"id":"1.195503853","rc":[{"atb":[[1.77,27.58],[1.75,4]],"id":43167135}],"con":true,"img":false}]}
{"op":"mcm","clk":"5353486941","pt":1646215636893,"mc":[{"id":"1.195503853","rc":[{"atb":[[1.99,5.44]],"id":39786791}],"con":true,"img":false}]}
{"op":"mcm","clk":"5353486953","pt":1646215636995,"mc":[{"id":"1.195503853","rc":[{"atb":[[2,13.66]],"id":39786791}],"con":true,"img":false}]}
{"op":"mcm","clk":"5353487120","pt":1646215638714,"mc":[{"id":"1.195503853","rc":[{"atl":[[2.18,0]],"id":39786791}],"con":true,"img":false}]}
{"op":"mcm","clk":"5353487334","pt":1646215640897,"mc":[{"id":"1.195503853","rc":[{"atl":[[2.18,1.42]],"id":39786791}],"con":true,"img":false}]}
{"op":"mcm","clk":"5353487574","pt":1646215643818,"mc":[{"id":"1.195503853","rc":[{"trd":[[1.84,4.73]],"ltp":1.84,"tv":4.73,"id":43167135},{"atl":[[2.18,0.44]],"id":39786791},{"trd":[[2.18,0.98]],"ltp":2.18,"tv":0.98,"id":39786791}],"con":true,"img":false}]}
{"op":"mcm","clk":"5353487633","pt":1646215644501,"mc":[{"id":"1.195503853","rc":[{"atl":[[2.18,0]],"id":39786791}],"con":true,"img":false}]}
{"op":"mcm","clk":"5353487685","pt":1646215645024,"mc":[{"id":"1.195503853","rc":[{"atb":[[1.77,20]],"id":43167135}],"con":true,"img":false}]}
{"op":"mcm","clk":"5353487697","pt":1646215645227,"mc":[{"id":"1.195503853","rc":[{"atb":[[1.77,18],[1.75,6]],"id":43167135}],"con":true,"img":false}]}
{"op":"mcm","clk":"5353487824","pt":1646215646600,"mc":[{"id":"1.195503853","rc":[{"atb":[[1.77,25.87]],"id":43167135}],"con":true,"img":false}]}
{"op":"mcm","clk":"5353487967","pt":1646215648218,"mc":[{"id":"1.195503853","rc":[{"atl":[[2.18,1.42]],"id":39786791}],"con":true,"img":false}]}
{"op":"mcm","clk":"5353488168","pt":1646215650319,"mc":[{"id":"1.195503853","rc":[{"atb":[[1.77,27.87],[1.75,4]],"id":43167135}],"con":true,"img":false}]}
{"op":"mcm","clk":"5353488374","pt":1646215652420,"mc":[{"id":"1.195503853","rc":[{"atl":[[2.18,0]],"id":39786791}],"con":true,"img":false}]}
{"op":"mcm","clk":"5353488434","pt":1646215653047,"mc":[{"id":"1.195503853","rc":[{"atb":[[1.04,3.45]],"id":39786791}],"con":true,"img":false}]}
{"op":"mcm","clk":"5353488457","pt":1646215653206,"mc":[{"id":"1.195503853","rc":[{"atb":[[1.04,2.62]],"id":39786791}],"con":true,"img":false}]}
{"op":"mcm","clk":"5353488478","pt":1646215653416,"mc":[{"id":"1.195503853","rc":[{"atb":[[1.04,2]],"id":39786791}],"con":true,"img":false}]}
{"op":"mcm","clk":"5353488491","pt":1646215653519,"mc":[{"id":"1.195503853","rc":[{"atl":[[2.24,0.75]],"id":39786791},{"trd":[[2.24,1.29]],"ltp":2.24,"tv":1.29,"id":39786791}],"con":true,"img":false}]}
{"op":"mcm","clk":"5353488529","pt":1646215653832,"mc":[{"id":"1.195503853","rc":[{"atl":[[2.26,7.27]],"id":39786791}],"con":true,"img":false}]}
{"op":"mcm","clk":"5353488641","pt":1646215654831,"mc":[{"id":"1.195503853","rc":[{"atl":[[2.18,1.42]],"id":39786791}],"con":true,"img":false}]}
{"op":"mcm","clk":"5353488717","pt":1646215655415,"mc":[{"id":"1.195503853","rc":[{"atb":[[1.77,20]],"id":43167135},{"atl":[[2.16,2]],"id":43167135},{"atb":[[2,2.76]],"id":39786791},{"atl":[[2.26,2]],"id":39786791}],"con":true,"img":false}]}
{"op":"mcm","clk":"5353488742","pt":1646215655622,"mc":[{"id":"1.195503853","rc":[{"atb":[[1.77,18],[1.75,6]],"id":43167135},{"atl":[[2.2,2],[2.16,0]],"id":43167135}],"con":true,"img":false}]}
{"op":"mcm","clk":"5353488754","pt":1646215655732,"mc":[{"id":"1.195503853","rc":[{"atb":[[1.77,26.84]],"id":43167135},{"atl":[[2.16,4]],"id":43167135},{"atb":[[2,8.3]],"id":39786791}],"con":true,"img":false}]}
{"op":"mcm","clk":"5353488785","pt":1646215656097,"mc":[{"id":"1.195503853","rc":[{"atl":[[2.16,0]],"id":43167135}],"con":true,"img":false}]}
{"op":"mcm","clk":"5353488809","pt":1646215656415,"mc":[{"id":"1.195503853","rc":[{"atl":[[2.2,6]],"id":43167135}],"con":true,"img":false}]}
{"op":"mcm","clk":"5353488960","pt":1646215658249,"mc":[{"id":"1.195503853","rc":[{"atl":[[2.18,0]],"id":39786791}],"con":true,"img":false}]}
{"op":"mcm","clk":"5353488998","pt":1646215658616,"mc":[{"id":"1.195503853","rc":[{"atl":[[2.26,7.5]],"id":39786791}],"con":true,"img":false}]}
{"op":"mcm","clk":"5353489070","pt":1646215659351,"mc":[{"id":"1.195503853","rc":[{"atb":[[1.56,10.06]],"id":43167135},{"atb":[[2,5.54]],"id":39786791}],"con":true,"img":false}]}
{"op":"mcm","clk":"5353489103","pt":1646215659619,"mc":[{"id":"1.195503853","rc":[{"atb":[[2,0]],"id":39786791}],"con":true,"img":false}]}
{"op":"mcm","clk":"5353489127","pt":1646215659931,"mc":[{"id":"1.195503853","rc":[{"atl":[[2.26,2]],"id":39786791}],"con":true,"img":false}]}
{"op":"mcm","clk":"5353489137","pt":1646215660064,"mc":[{"id":"1.195503853","rc":[{"atb":[[1.99,15.51]],"id":39786791}],"con":true,"img":false}]}
{"op":"mcm","clk":"5353489181","pt":1646215660609,"mc":[{"id":"1.195503853","rc":[{"atl":[[2.18,1.42]],"id":39786791}],"con":true,"img":false}]}
{"op":"mcm","clk":"5353489198","pt":1646215660822,"mc":[{"id":"1.195503853","rc":[{"atb":[[1.77,28.84],[1.75,4]],"id":43167135}],"con":true,"img":false}]}
{"op":"mcm","clk":"5353489204","pt":1646215660925,"mc":[{"id":"1.195503853","rc":[{"atl":[[2.18,2],[2.2,4]],"id":43167135},{"trd":[[1.84,5.73]],"ltp":1.84,"tv":5.73,"id":43167135},{"atb":[[2.02,5.52]],"id":39786791},{"atl":[[2.18,0.57]],"id":39786791},{"trd":[[2.18,1.82]],"ltp":2.18,"tv":1.82,"id":39786791}],"con":true,"img":false}]}
{"op":"mcm","clk":"5353489244","pt":1646215661452,"mc":[{"id":"1.195503853","rc":[{"atl":[[2.2,0]],"id":43167135},{"atb":[[1.99,5.44]],"id":39786791}],"con":true,"img":false}]}
{"op":"mcm","clk":"5353489254","pt":1646215661512,"mc":[{"id":"1.195503853","rc":[{"atl":[[2.18,6]],"id":43167135},{"atb":[[2.02,15.59]],"id":39786791}],"con":true,"img":false}]}
{"op":"mcm","clk":"5353489264","pt":1646215661614,"mc":[{"id":"1.195503853","rc":[{"atl":[[2.18,4],[2.2,2]],"id":43167135},{"atl":[[2.24,3.41]],"id":39786791}],"con":true,"img":false}]}
{"op":"mcm","clk":"5353489285","pt":1646215661821,"mc":[{"id":"1.195503853","rc":[{"atb":[[2.02,5.52]],"id":39786791}],"con":true,"img":false}]}
{"op":"mcm","clk":"5353489317","pt":1646215662131,"mc":[{"id":"1.195503853","rc":[{"atl":[[2.18,0]],"id":43167135}],"con":true,"img":false}]}
{"op":"mcm","clk":"5353489346","pt":1646215662445,"mc":[{"id":"1.195503853","rc":[{"atl":[[2.2,6]],"id":43167135}],"con":true,"img":false}]}
{"op":"mcm","clk":"5353489379","pt":1646215662816,"mc":[{"id":"1.195503853","rc":[{"atl":[[2.18,2]],"id":39786791}],"con":true,"img":false}]}
{"op":"mcm","clk":"5353489414","pt":1646215663230,"mc":[{"id":"1.195503853","rc":[{"atl":[[2.28,3.42],[2.26,0]],"id":39786791}],"con":true,"img":false}]}
{"op":"mcm","clk":"5353489479","pt":1646215663856,"mc":[{"id":"1.195503853","rc":[{"atb":[[1.77,8.84],[1.76,0],[1.75,2]],"id":43167135}],"con":true,"img":false}]}
{"op":"mcm","clk":"5353489524","pt":1646215664329,"mc":[{"id":"1.195503853","rc":[{"atb":[[1.77,0]],"id":43167135}],"con":true,"img":false}]}
{"op":"mcm","clk":"5353489537","pt":1646215664432,"mc":[{"id":"1.195503853","rc":[{"atb":[[1.75,10.84]],"id":43167135}],"con":true,"img":false}]}
{"op":"mcm","clk":"5353489579","pt":1646215664848,"mc":[{"id":"1.195503853","rc":[{"atb":[[1.75,6]],"id":43167135}],"con":true,"img":false}]}
{"op":"mcm","clk":"5353489590","pt":1646215664953,"mc":[{"id":"1.195503853","rc":[{"atb":[[2.02,12.31]],"id":39786791}],"con":true,"img":false}]}
{"op":"mcm","clk":"5353489697","pt":1646215666153,"mc":[{"id":"1.195503853","rc":[{"atl":[[2.18,0]],"id":39786791}],"con":true,"img":false}]}
{"op":"mcm","clk":"5353489728","pt":1646215666521,"mc":[{"id":"1.195503853","rc":[{"atl":[[2.24,0.75]],"id":39786791}],"con":true,"img":false}]}
{"op":"mcm","clk":"5353489756","pt":1646215666830,"mc":[{"id":"1.195503853","rc":[{"atb":[[2.02,5.52]],"id":39786791},{"atl":[[2.28,11.76]],"id":39786791}],"con":true,"img":false}]}
{"op":"mcm","clk":"5353489915","pt":1646215668453,"mc":[{"id":"1.195503853","rc":[{"atl":[[2,22]],"id":43167135},{"atl":[[2.3,1.42]],"id":39786791}],"con":true,"img":false}]}
{"op":"mcm","clk":"5353489932","pt":1646215668611,"mc":[{"id":"1.195503853","rc":[{"atl":[[2.02,2],[2.2,4]],"id":43167135}],"con":true,"img":false}]}
{"op":"mcm","clk":"5353489955","pt":1646215668924,"mc":[{"id":"1.195503853","rc":[{"atb":[[1.74,43.42]],"id":43167135},{"atb":[[2,29.17]],"id":39786791}],"con":true,"img":false}]}
{"op":"mcm","clk":"5353489991","pt":1646215669344,"mc":[{"id":"1.195503853","rc":[{"atl":[[1000,1.69]],"id":39786791}],"con":true,"img":false}]}
{"op":"mcm","clk":"5353490000","pt":1646215669448,"mc":[{"id":"1.195503853","rc":[{"atb":[[1.56,0]],"id":43167135},{"atl":[[1000,1.91]],"id":43167135},{"atb":[[2.02,0]],"id":39786791},{"atl":[[1000,0.02]],"id":39786791}],"con":true,"img":false}]}
{"op":"mcm","clk":"5353490009","pt":1646215669552,"mc":[{"id":"1.195503853","rc":[{"atb":[[1.59,10.06]],"id":43167135},{"atl":[[1000,0.25]],"id":43167135},{"atb":[[1.99,10.97]],"id":39786791},{"atl":[[1000,0]],"id":39786791}],"con":true,"img":false}]}
{"op":"mcm","clk":"5353490018","pt":1646215669657,"mc":[{"id":"1.195503853","rc":[{"atl":[[2.12,0.02]],"id":39786791}],"con":true,"img":false}]}
{"op":"mcm","clk":"5353490027","pt":1646215669709,"mc":[{"id":"1.195503853","rc":[{"atl":[[1000,0]],"id":43167135}],"con":true,"img":false}]}
{"op":"mcm","clk":"5353490034","pt":1646215669869,"mc":[{"id":"1.195503853","rc":[{"atl":[[1.85,0.22]],"id":43167135},{"trd":[[1.89,0.02]],"ltp":1.89,"tv":0.02,"id":43167135},{"atl":[[2.12,0]],"id":39786791},{"trd":[[2.12,0.02]],"ltp":2.12,"tv":0.02,"id":39786791}],"con":true,"img":false}]}
{"op":"mcm","clk":"5353490047","pt":1646215670028,"mc":[{"id":"1.195503853","rc":[{"atb":[[1.75,2]],"id":43167135},{"atl":[[1.85,0],[2.2,0]],"id":43167135},{"trd":[[1.85,17.91]],"ltp":1.85,"tv":17.91,"id":43167135},{"atl":[[2.28,3.42]],"id":39786791}],"con":true,"img":false}]}
{"op":"mcm","clk":"5353490073","pt":1646215670324,"mc":[{"id":"1.195503853","rc":[{"atb":[[1.75,6]],"id":43167135},{"atl":[[2.28,11.76]],"id":39786791}],"con":true,"img":false}]}
{"op":"mcm","clk":"5353490102","pt":1646215670746,"mc":[{"id":"1.195503853","rc":[{"atl":[[2.16,16.34]],"id":39786791}],"con":true,"img":false}]}
{"op":"mcm","clk":"5353490116","pt":1646215670955,"mc":[{"id":"1.195503853","rc":[{"atb":[[1.77,37.88]],"id":43167135}],"con":true,"img":false}]}
{"op":"mcm","clk":"5353490142","pt":1646215671217,"mc":[{"id":"1.195503853","rc":[{"atb":[[1.76,2],[1.75,4]],"id":43167135}],"con":true,"img":false}]}
{"op":"mcm","clk":"5353490152","pt":1646215671322,"mc":[{"id":"1.195503853","rc":[{"atb":[[1.75,0]],"id":43167135}],"con":true,"img":false}]}
{"op":"mcm","clk":"5353490188","pt":1646215671742,"mc":[{"id":"1.195503853","rc":[{"atb":[[1.77,50.23]],"id":43167135},{"atl":[[2,27.99]],"id":43167135},{"atb":[[2,35.16]],"id":39786791}],"con":true,"img":false}]}
{"op":"mcm","clk":"5353490204","pt":1646215671950,"mc":[{"id":"1.195503853","rc":[{"atb":[[1.53,43],[1.13,0],[1.33,0]],"id":43167135},{"atb":[[1.59,0],[1.99,5.52],[1.79,0]],"id":39786791}],"con":true,"img":false}]}
{"op":"mcm","clk":"5353490385","pt":1646215673937,"mc":[{"id":"1.195503853","rc":[{"atl":[[1.99,1.42]],"id":43167135},{"atb":[[2.02,1.42]],"id":39786791},{"atl":[[2.12,1.42]],"id":39786791}],"con":true,"img":false}]}
{"op":"mcm","clk":"5353490433","pt":1646215674455,"mc":[{"id":"1.195503853","rc":[{"atb":[[1.79,36.92]],"id":43167135},{"atl":[[2,22]],"id":43167135},{"atb":[[2,0],[1.97,30.07]],"id":39786791}],"con":true,"img":false}]}
{"op":"mcm","clk":"5353490442","pt":1646215674559,"mc":[{"id":"1.195503853","rc":[{"atl":[[1.99,7.41]],"id":43167135},{"atb":[[2.02,7.41]],"id":39786791}],"con":true,"img":false}]}
{"op":"mcm","clk":"5353490477","pt":1646215674927,"mc":[{"id":"1.195503853","rc":[{"atb":[[1.77,37.88]],"id":43167135},{"atl":[[1.99,1.42]],"id":43167135},{"atb":[[2.02,1.42]],"id":39786791}],"con":true,"img":false}]}
{"op":"mcm","clk":"5353490490","pt":1646215675030,"mc":[{"id":"1.195503853","rc":[{"atb":[[1.79,49.27]],"id":43167135}],"con":true,"img":false}]}
{"op":"mcm","clk":"5353490527","pt":1646215675448,"mc":[{"id":"1.195503853","rc":[{"atb":[[2,29.17]],"id":39786791}],"con":true,"img":false}]}
{"op":"mcm","clk":"5353490534","pt":1646215675582,"mc":[{"id":"1.195503853","rc":[{"atl":[[2,0]],"id":43167135}],"con":true,"img":false}]}
{"op":"mcm","clk":"5353490543","pt":1646215675638,"mc":[{"id":"1.195503853","rc":[{"atl":[[1.96,22]],"id":43167135}],"con":true,"img":false}]}
{"op":"mcm","clk":"5353490596","pt":1646215676267,"mc":[{"id":"1.195503853","rc":[{"atl":[[2.14,1.42]],"id":39786791}],"con":true,"img":false}]}
{"op":"mcm","clk":"5353490618","pt":1646215676534,"mc":[{"id":"1.195503853","rc":[{"atb":[[1.7,2],[1.76,0],[1.75,2]],"id":43167135}],"con":true,"img":false}]}
{"op":"mcm","clk":"5353490697","pt":1646215677534,"mc":[{"id":"1.195503853","rc":[{"atb":[[1.59,0]],"id":43167135}],"con":true,"img":false}]}
{"op":"mcm","clk":"5353490707","pt":1646215677639,"mc":[{"id":"1.195503853","rc":[{"atb":[[1.56,10.06],[1.79,36.92]],"id":43167135},{"atb":[[1.99,0]],"id":39786791},{"atl":[[2.28,3.42]],"id":39786791}],"con":true,"img":false}]}
{"op":"mcm","clk":"5353490714","pt":1646215677742,"mc":[{"id":"1.195503853","rc":[{"atb":[[2.02,6.94]],"id":39786791}],"con":true,"img":false}]}
{"op":"mcm","clk":"5353490734","pt":1646215677956,"mc":[{"id":"1.195503853","rc":[{"atb":[[1.77,0],[1.79,9.29]],"id":43167135},{"atb":[[2,0],[1.99,29.46]],"id":39786791}],"con":true,"img":false}]}
{"op":"mcm","clk":"5353490738","pt":1646215678060,"mc":[{"id":"1.195503853","rc":[{"atl":[[2.04,2],[2.02,0]],"id":43167135},{"atb":[[1.98,0],[1.96,2]],"id":39786791}],"con":true,"img":false}]}
{"op":"mcm","clk":"5353490765","pt":1646215678325,"mc":[{"id":"1.195503853","rc":[{"atb":[[1.79,0]],"id":43167135}],"con":true,"img":false}]}
{"op":"mcm","clk":"5353490771","pt":1646215678431,"mc":[{"id":"1.195503853","rc":[{"atb":[[1.75,11.29]],"id":43167135}],"con":true,"img":false}]}
{"op":"mcm","clk":"5353490798","pt":1646215678742,"mc":[{"id":"1.195503853","rc":[{"atb":[[1.75,6]],"id":43167135}],"con":true,"img":false}]}
{"op":"mcm","clk":"5353490817","pt":1646215678951,"mc":[{"id":"1.195503853","rc":[{"atb":[[1.76,38.38]],"id":43167135}],"con":true,"img":false}]}
{"op":"mcm","clk":"5353490842","pt":1646215679265,"mc":[{"id":"1.195503853","rc":[{"atb":[[1.75,2]],"id":43167135},{"atl":[[1.94,29.97]],"id":43167135}],"con":true,"img":false}]}
{"op":"mcm","clk":"5353490865","pt":1646215679476,"mc":[{"id":"1.195503853","rc":[{"atb":[[1.76,0]],"id":43167135}],"con":true,"img":false}]}
{"op":"mcm","clk":"5353490884","pt":1646215679633,"mc":[{"id":"1.195503853","rc":[{"atb":[[1.76,13.09]],"id":43167135}],"con":true,"img":false}]}
{"op":"mcm","clk":"5353490893","pt":1646215679739,"mc":[{"id":"1.195503853","rc":[{"atl":[[2.26,1.42]],"id":39786791}],"con":true,"img":false}]}
{"op":"mcm","clk":"5353490913","pt":1646215679948,"mc":[{"id":"1.195503853","rc":[{"atb":[[1.77,37.88],[1.76,0]],"id":43167135},{"atb":[[2,29.17]],"id":39786791}],"con":true,"img":false}]}
{"op":"mcm","clk":"5353490924","pt":1646215680050,"mc":[{"id":"1.195503853","rc":[{"atb":[[1.1,53.95],[1.5,10.79],[1.3,19.98],[1.75,15.09]],"id":43167135},{"atb":[[1.63,8.56],[1.83,6.5],[2.06,5.09]],"id":39786791}],"con":true,"img":false}]}
{"op":"mcm","clk":"5353490931","pt":1646215680158,"mc":[{"id":"1.195503853","rc":[{"atl":[[1.99,0]],"id":43167135},{"atb":[[2.02,5.52]],"id":39786791},{"atl":[[2.12,0]],"id":39786791}],"con":true,"img":false}]}
{"op":"mcm","clk":"5353490943","pt":1646215680368,"mc":[{"id":"1.195503853","rc":[{"atb":[[1.75,2]],"id":43167135},{"atl":[[2.28,1.42],[2.26,3.42]],"id":39786791}],"con":true,"img":false}]}
{"op":"mcm","clk":"5353490953","pt":1646215680473,"mc":[{"id":"1.195503853","rc":[{"atb":[[1.77,13.09]],"id":43167135}],"con":true,"img":false}]}
{"op":"mcm","clk":"5353490995","pt":1646215680830,"mc":[{"id":"1.195503853","rc":[{"atb":[[1.77,0]],"id":43167135}],"con":true,"img":false}]}
{"op":"mcm","clk":"5353491005","pt":1646215680935,"mc":[{"id":"1.195503853","rc":[{"atb":[[1.78,37.4],[1.75,15.09]],"id":43167135},{"atl":[[1.93,10.59]],"id":43167135},{"atb":[[2.08,7.95]],"id":39786791},{"atl":[[2.14,0]],"id":39786791},{"trd":[[2.14,4.26]],"ltp":2.14,"tv":4.26,"id":39786791}],"con":true,"img":false}]}
{"op":"mcm","clk":"5353491023","pt":1646215681146,"mc":[{"id":"1.195503853","rc":[{"atl":[[2.16,0.57]],"id":39786791},{"trd":[[2.16,31.55]],"ltp":2.16,"tv":31.55,"id":39786791}],"con":true,"img":false}]}
{"op":"mcm","clk":"5353491032","pt":1646215681248,"mc":[{"id":"1.195503853","rc":[{"atb":[[1.75,2]],"id":43167135}],"con":true,"img":false}]}
{"op":"mcm","clk":"5353491042","pt":1646215681353,"mc":[{"id":"1.195503853","rc":[{"atb":[[1.78,50.49]],"id":43167135}],"con":true,"img":false}]}
{"op":"mcm","clk":"5353491057","pt":1646215681460,"mc":[{"id":"1.195503853","rc":[{"atb":[[1.78,13.09]],"id":43167135},{"atb":[[1.97,0]],"id":39786791}],"con":true,"img":false}]}
{"op":"mcm","clk":"5353491078","pt":1646215681675,"mc":[{"id":"1.195503853","rc":[{"atb":[[1.75,13.01]],"id":43167135},{"atl":[[2.24,3.39]],"id":39786791}],"con":true,"img":false}]}
{"op":"mcm","clk":"5353491082","pt":1646215681729,"mc":[{"id":"1.195503853","rc":[{"atb":[[1.78,2],[1.75,11.01]],"id":43167135}],"con":true,"img":false}]}
{"op":"mcm","clk":"5353491094","pt":1646215681834,"mc":[{"id":"1.195503853","rc":[{"atb":[[1.76,2],[1.75,24.1]],"id":43167135}],"con":true,"img":false}]}
{"op":"mcm","clk":"5353491103","pt":1646215681939,"mc":[{"id":"1.195503853","rc":[{"atb":[[1.78,0]],"id":43167135},{"atb":[[2.08,34.97]],"id":39786791}],"con":true,"img":false}]}
{"op":"mcm","clk":"5353491129","pt":1646215682252,"mc":[{"id":"1.195503853","rc":[{"atb":[[1.75,11.01]],"id":43167135}],"con":true,"img":false}]}
{"op":"mcm","clk":"5353491134","pt":1646215682357,"mc":[{"id":"1.195503853","rc":[{"atb":[[1.78,13.09],[1.75,0]],"id":43167135}],"con":true,"img":false}]}
{"op":"mcm","clk":"5353491147","pt":1646215682567,"mc":[{"id":"1.195503853","rc":[{"atb":[[1.78,15.09],[1.76,10.89],[1.75,10.99]],"id":43167135}],"con":true,"img":false}]}
{"op":"mcm","clk":"5353491163","pt":1646215682729,"mc":[{"id":"1.195503853","rc":[{"atb":[[1.78,2]],"id":43167135}],"con":true,"img":false}]}
{"op":"mcm","clk":"5353491174","pt":1646215682889,"mc":[{"id":"1.195503853","rc":[{"atb":[[1.76,23.98]],"id":43167135},{"atl":[[1.85,21.34]],"id":43167135},{"trd":[[1.86,0.66]],"ltp":1.86,"tv":0.66,"id":43167135},{"atl":[[2.16,0]],"id":39786791},{"trd":[[2.16,32.12]],"ltp":2.16,"tv":32.12,"id":39786791}],"con":true,"img":false}]}
{"op":"mcm","clk":"5353491185","pt":1646215682942,"mc":[{"id":"1.195503853","rc":[{"atb":[[1.77,37.88]],"id":43167135}],"con":true,"img":false}]}
{"op":"mcm","clk":"5353491197","pt":1646215683052,"mc":[{"id":"1.195503853","rc":[{"atb":[[1.77,48.7]],"id":43167135},{"atl":[[2.32,9.22]],"id":39786791}],"con":true,"img":false}]}
{"op":"mcm","clk":"5353491223","pt":1646215683258,"mc":[{"id":"1.195503853","rc":[{"atl":[[2.3,9.27]],"id":39786791}],"con":true,"img":false}]}
{"op":"mcm","clk":"5353491242","pt":1646215683468,"mc":[{"id":"1.195503853","rc":[{"atb":[[1.76,10.89]],"id":43167135},{"atl":[[2.24,0.75]],"id":39786791}],"con":true,"img":false}]}
{"op":"mcm","clk":"5353491252","pt":1646215683572,"mc":[{"id":"1.195503853","rc":[{"atb":[[1.78,15.09]],"id":43167135}],"con":true,"img":false}]}
{"op":"mcm","clk":"5353491272","pt":1646215683739,"mc":[{"id":"1.195503853","rc":[{"atb":[[1.78,25.82]],"id":43167135}],"con":true,"img":false}]}
{"op":"mcm","clk":"5353491281","pt":1646215683838,"mc":[{"id":"1.195503853","rc":[{"atl":[[2.26,9.86]],"id":39786791}],"con":true,"img":false}]}
{"op":"mcm","clk":"5353491298","pt":1646215684046,"mc":[{"id":"1.195503853","rc":[{"atb":[[1.78,16.73]],"id":43167135}],"con":true,"img":false}]}
{"op":"mcm","clk":"5353491358","pt":1646215684726,"mc":[{"id":"1.195503853","rc":[{"atl":[[2.26,17.88]],"id":39786791}],"con":true,"img":false}]}
{"op":"mcm","clk":"5353491366","pt":1646215684831,"mc":[{"id":"1.195503853","rc":[{"atb":[[1.79,10.55],[1.75,0]],"id":43167135}],"con":true,"img":false}]}
{"op":"mcm","clk":"5353491389","pt":1646215685144,"mc":[{"id":"1.195503853","rc":[{"atb":[[1.78,12.73]],"id":43167135}],"con":true,"img":false}]}
{"op":"mcm","clk":"5353491414","pt":1646215685469,"mc":[{"id":"1.195503853","rc":[{"atb":[[1.77,10.81],[1.75,38.9]],"id":43167135},{"atl":[[2.24,0],[2.38,0],[2.28,0],[2.3,7.85],[2.32,7.8],[2.26,16.46],[2.34,0]],"id":39786791}],"con":true,"img":false}]}
{"op":"mcm","clk":"5353491435","pt":1646215685630,"mc":[{"id":"1.195503853","rc":[{"atb":[[1.79,20.94]],"id":43167135}],"con":true,"img":false}]}
{"op":"mcm","clk":"5353491444","pt":1646215685736,"mc":[{"id":"1.195503853","rc":[{"atb":[[1.76,0],[1.8,10.55]],"id":43167135}],"con":true,"img":false}]}
{"op":"mcm","clk":"5353491466","pt":1646215686050,"mc":[{"id":"1.195503853","rc":[{"atb":[[1.79,10.55]],"id":43167135}],"con":true,"img":false}]}
{"op":"mcm","clk":"5353491472","pt":1646215686154,"mc":[{"id":"1.195503853","rc":[{"atb":[[1.8,20.94]],"id":43167135}],"con":true,"img":false}]}
{"op":"mcm","clk":"5353491495","pt":1646215686473,"mc":[{"id":"1.195503853","rc":[{"atb":[[1.76,38.38]],"id":43167135}],"con":true,"img":false}]}
{"op":"mcm","clk":"5353491612","pt":1646215687736,"mc":[{"id":"1.195503853","rc":[{"atb":[[1.78,10.73],[1.79,12.55]],"id":43167135}],"con":true,"img":false}]}
{"op":"mcm","clk":"5353491621","pt":1646215687841,"mc":[{"id":"1.195503853","rc":[{"atl":[[1.84,16.84]],"id":43167135}],"con":true,"img":false}]}
{"op":"mcm","clk":"5353491673","pt":1646215688465,"mc":[{"id":"1.195503853","rc":[{"atb":[[1.74,4]],"id":43167135},{"atb":[[1.99,0]],"id":39786791}],"con":true,"img":false}]}
{"op":"mcm","clk":"5353491722","pt":1646215689042,"mc":[{"id":"1.195503853","rc":[{"atb":[[1.8,10.39],[1.79,2]],"id":43167135},{"atl":[[2.26,8.44]],"id":39786791}],"con":true,"img":false}]}
{"op":"mcm","clk":"5353491752","pt":1646215689456,"mc":[{"id":"1.195503853","rc":[{"atb":[[1.8,0]],"id":43167135},{"atb":[[2.14,25.59]],"id":39786791}],"con":true,"img":false}]}
{"op":"mcm","clk":"5353491759","pt":1646215689559,"mc":[{"id":"1.195503853","rc":[{"atb":[[1.79,12.39]],"id":43167135}],"con":true,"img":false}]}
{"op":"mcm","clk":"5353491778","pt":1646215689872,"mc":[{"id":"1.195503853","rc":[{"atb":[[1.79,6]],"id":43167135}],"con":true,"img":false}]}
{"op":"mcm","clk":"5353491864","pt":1646215690867,"mc":[{"id":"1.195503853","rc":[{"atl":[[1.83,16.93]],"id":43167135}],"con":true,"img":false}]}
{"op":"mcm","clk":"5353491890","pt":1646215691180,"mc":[{"id":"1.195503853","rc":[{"atb":[[1.79,2]],"id":43167135},{"atl":[[2.26,2]],"id":39786791}],"con":true,"img":false}]}
{"op":"mcm","clk":"5353491907","pt":1646215691340,"mc":[{"id":"1.195503853","rc":[{"atb":[[1.8,10.44]],"id":43167135},{"atl":[[2.24,8.08],[2.28,2],[2.26,0]],"id":39786791}],"con":true,"img":false}]}
{"op":"mcm","clk":"5353491915","pt":1646215691444,"mc":[{"id":"1.195503853","rc":[{"atb":[[1.79,6]],"id":43167135},{"atb":[[2,0]],"id":39786791},{"atl":[[2.26,4]],"id":39786791}],"con":true,"img":false}]}
{"op":"mcm","clk":"5353491921","pt":1646215691549,"mc":[{"id":"1.195503853","rc":[{"atl":[[2.24,0]],"id":39786791}],"con":true,"img":false}]}
{"op":"mcm","clk":"5353491949","pt":1646215691858,"mc":[{"id":"1.195503853","rc":[{"atb":[[1.79,2]],"id":43167135},{"atb":[[1.04,4.86]],"id":39786791}],"con":true,"img":false}]}
{"op":"mcm","clk":"5353491957","pt":1646215691964,"mc":[{"id":"1.195503853","rc":[{"atl":[[2.26,0]],"id":39786791}],"con":true,"img":false}]}
{"op":"mcm","clk":"5353491965","pt":1646215692070,"mc":[{"id":"1.195503853","rc":[{"atb":[[1.04,2.14]],"id":39786791}],"con":true,"img":false}]}
{"op":"mcm","clk":"5353491973","pt":1646215692172,"mc":[{"id":"1.195503853","rc":[{"atl":[[2.28,10.07]],"id":39786791}],"con":true,"img":false}]}
{"op":"mcm","clk":"5353491979","pt":1646215692278,"mc":[{"id":"1.195503853","rc":[{"atb":[[1.8,17.12]],"id":43167135},{"atb":[[1.04,2]],"id":39786791}],"con":true,"img":false}]}
{"op":"mcm","clk":"5353491981","pt":1646215692382,"mc":[{"id":"1.195503853","rc":[{"atb":[[2.24,0.14]],"id":39786791}],"con":true,"img":false}]}
{"op":"mcm","clk":"5353491995","pt":1646215692438,"mc":[{"id":"1.195503853","rc":[{"atb":[[2.24,0]],"id":39786791},{"atl":[[2.28,14.07]],"id":39786791},{"trd":[[2.24,1.57]],"ltp":2.24,"tv":1.57,"id":39786791}],"con":true,"img":false}]}
{"op":"mcm","clk":"5353492046","pt":1646215693165,"mc":[{"id":"1.195503853","rc":[{"atl":[[2.26,8.07]],"id":39786791}],"con":true,"img":false}]}
{"op":"mcm","clk":"5353492054","pt":1646215693268,"mc":[{"id":"1.195503853","rc":[{"atb":[[1.8,6.68]],"id":43167135}],"con":true,"img":false}]}
{"op":"mcm","clk":"5353492062","pt":1646215693372,"mc":[{"id":"1.195503853","rc":[{"atb":[[1.81,10.45]],"id":43167135}],"con":true,"img":false}]}
{"op":"mcm","clk":"5353492075","pt":1646215693581,"mc":[{"id":"1.195503853","rc":[{"atb":[[1.8,0]],"id":43167135},{"atl":[[1.85,0]],"id":43167135},{"atl":[[2.28,10.07]],"id":39786791}],"con":true,"img":false}]}
{"op":"mcm","clk":"5353492087","pt":1646215693638,"mc":[{"id":"1.195503853","rc":[{"atb":[[1.78,0],[1.81,0],[1.79,0]],"id":43167135},{"trd":[[1.78,30.07],[1.79,4]],"ltp":1.78,"tv":34.07,"id":43167135},{"atl":[[2.26,0],[2.28,3.36]],"id":39786791},{"trd":[[2.28,6.7]],"ltp":2.28,"tv":6.7,"id":39786791}],"con":true,"img":false}]}
{"op":"mcm","clk":"5353492097","pt":1646215693742,"mc":[{"id":"1.195503853","rc":[{"atb":[[1.78,2]],"id":43167135}],"con":true,"img":false}]}
{"op":"mcm","clk":"5353492109","pt":1646215693849,"mc":[{"id":"1.195503853","rc":[{"atb":[[1.78,12.69]],"id":43167135},{"atb":[[2.16,7.96]],"id":39786791},{"atl":[[2.28,0]],"id":39786791}],"con":true,"img":false}]}
{"op":"mcm","clk":"5353492118","pt":1646215693954,"mc":[{"id":"1.195503853","rc":[{"atb":[[1.76,0]],"id":43167135}],"con":true,"img":false}]}
{"op":"mcm","clk":"5353492125","pt":1646215694058,"mc":[{"id":"1.195503853","rc":[{"atb":[[1.77,21.65]],"id":43167135},{"atl":[[2.28,6.74]],"id":39786791}],"con":true,"img":false}]}
{"op":"mcm","clk":"5353492165","pt":1646215694470,"mc":[{"id":"1.195503853","rc":[{"atb":[[1.76,38.38]],"id":43167135},{"atb":[[2.16,33.11]],"id":39786791}],"con":true,"img":false}]}
{"op":"mcm","clk":"5353492173","pt":1646215694574,"mc":[{"id":"1.195503853","rc":[{"atb":[[1.77,10.81]],"id":43167135},{"atl":[[2.26,8],[2.28,0]],"id":39786791}],"con":true,"img":false}]}
{"op":"mcm","clk":"5353492184","pt":1646215694681,"mc":[{"id":"1.195503853","rc":[{"atb":[[1.78,23.53]],"id":43167135}],"con":true,"img":false}]}
{"op":"mcm","clk":"5353492201","pt":1646215694890,"mc":[{"id":"1.195503853","rc":[{"atb":[[1.04,2.86]],"id":43167135}],"con":true,"img":false}]}
{"op":"mcm","clk":"5353492208","pt":1646215694944,"mc":[{"id":"1.195503853","rc":[{"atl":[[1.83,7.1]],"id":43167135},{"trd":[[1.83,37.82]],"ltp":1.83,"tv":37.82,"id":43167135},{"trd":[[2.2,8.17]],"ltp":2.2,"tv":8.17,"id":39786791}],"con":true,"img":false}]}
{"op":"mcm","clk":"5353492216","pt":1646215695050,"mc":[{"id":"1.195503853","rc":[{"atb":[[1.79,10.55],[1.04,0.14]],"id":43167135},{"atl":[[2.26,14.78]],"id":39786791}],"con":true,"img":false}]}
{"op":"mcm","clk":"5353492238","pt":1646215695286,"mc":[{"id":"1.195503853","rc":[{"atb":[[1.04,0]],"id":43167135},{"atl":[[1.84,0]],"id":43167135},{"atb":[[2.18,8.06]],"id":39786791}],"con":true,"img":false}]}
{"op":"mcm","clk":"5353492245","pt":1646215695360,"mc":[{"id":"1.195503853","rc":[{"atb":[[1.78,12.69]],"id":43167135},{"atl":[[1.83,6.96]],"id":43167135},{"trd":[[1.83,38.1]],"ltp":1.83,"tv":38.1,"id":43167135}],"con":true,"img":false}]}
{"op":"mcm","clk":"5353492254","pt":1646215695448,"mc":[{"id":"1.195503853","rc":[{"atb":[[1.77,48.7],[1.79,21.39]],"id":43167135},{"atb":[[2.16,7.96]],"id":39786791}],"con":true,"img":false}]}
{"op":"mcm","clk":"5353492265","pt":1646215695557,"mc":[{"id":"1.195503853","rc":[{"atl":[[1.83,1.76]],"id":43167135},{"trd":[[1.83,48.52]],"ltp":1.83,"tv":48.52,"id":43167135}],"con":true,"img":false}]}
{"op":"mcm","clk":"5353492276","pt":1646215695663,"mc":[{"id":"1.195503853","rc":[{"atb":[[1.8,10.52]],"id":43167135}],"con":true,"img":false}]}
{"op":"mcm","clk":"5353492290","pt":1646215695876,"mc":[{"id":"1.195503853","rc":[{"atl":[[1.83,0]],"id":43167135},{"trd":[[1.83,52.04]],"ltp":1.83,"tv":52.04,"id":43167135}],"con":true,"img":false}]}
{"op":"mcm","clk":"5353492297","pt":1646215695981,"mc":[{"id":"1.195503853","rc":[{"atb":[[1.77,10.81]],"id":43167135},{"atb":[[2.14,0]],"id":39786791}],"con":true,"img":false}]}
{"op":"mcm","clk":"5353492306","pt":1646215696037,"mc":[{"id":"1.195503853","rc":[{"atb":[[1.79,10.55]],"id":43167135}],"con":true,"img":false}]}
{"op":"mcm","clk":"5353492313","pt":1646215696142,"mc":[{"id":"1.195503853","rc":[{"atb":[[1.8,21.36]],"id":43167135}],"con":true,"img":false}]}
{"op":"mcm","clk":"5353492324","pt":1646215696246,"mc":[{"id":"1.195503853","rc":[{"atb":[[2.18,0]],"id":39786791}],"con":true,"img":false}]}
{"op":"mcm","clk":"5353492337","pt":1646215696455,"mc":[{"id":"1.195503853","rc":[{"atb":[[1.8,57.83]],"id":43167135}],"con":true,"img":false}]}
{"op":"mcm","clk":"5353492352","pt":1646215696661,"mc":[{"id":"1.195503853","rc":[{"atl":[[1.92,5.5]],"id":43167135}],"con":true,"img":false}]}
{"op":"mcm","clk":"5353492413","pt":1646215697348,"mc":[{"id":"1.195503853","rc":[{"atl":[[1.96,0],[1.91,10.46]],"id":43167135}],"con":true,"img":false}]}
{"op":"mcm","clk":"5353492424","pt":1646215697454,"mc":[{"id":"1.195503853","rc":[{"atb":[[1.8,46.99]],"id":43167135},{"atl":[[2.26,8]],"id":39786791}],"con":true,"img":false}]}
{"op":"mcm","clk":"5353492444","pt":1646215697665,"mc":[{"id":"1.195503853","rc":[{"atl":[[1.92,0],[1.91,15.99]],"id":43167135}],"con":true,"img":false}]}
{"op":"mcm","clk":"5353492454","pt":1646215697768,"mc":[{"id":"1.195503853","rc":[{"atl":[[2.26,13.46]],"id":39786791}],"con":true,"img":false}]}
{"op":"mcm","clk":"5353492472","pt":1646215697979,"mc":[{"id":"1.195503853","rc":[{"atb":[[1.8,10.52],[1.79,47.47]],"id":43167135}],"con":true,"img":false}]}
{"op":"mcm","clk":"5353492550","pt":1646215698875,"mc":[{"id":"1.195503853","rc":[{"atl":[[1.9,10.44]],"id":43167135}],"con":true,"img":false}]}
{"op":"mcm","clk":"5353492625","pt":1646215699764,"mc":[{"id":"1.195503853","rc":[{"atl":[[1.91,10.46]],"id":43167135},{"atl":[[2.24,8.06]],"id":39786791}],"con":true,"img":false}]}
{"op":"mcm","clk":"5353492753","pt":1646215701186,"mc":[{"id":"1.195503853","rc":[{"atl":[[2.26,8]],"id":39786791}],"con":true,"img":false}]}
{"op":"mcm","clk":"5353492787","pt":1646215701457,"mc":[{"id":"1.195503853","rc":[{"atb":[[1.8,18.25]],"id":43167135},{"atb":[[2.16,0]],"id":39786791},{"atl":[[2.24,13.83]],"id":39786791}],"con":true,"img":false}]}
{"op":"mcm","clk":"5353492796","pt":1646215701562,"mc":[{"id":"1.195503853","rc":[{"atb":[[2.02,0]],"id":39786791}],"con":true,"img":false}]}
{"op":"mcm","clk":"5353492805","pt":1646215701669,"mc":[{"id":"1.195503853","rc":[{"atb":[[1.98,5.52]],"id":39786791}],"con":true,"img":false}]}
{"op":"mcm","clk":"5353492815","pt":1646215701776,"mc":[{"id":"1.195503853","rc":[{"atl":[[2.22,8.21]],"id":39786791}],"con":true,"img":false}]}
{"op":"mcm","clk":"5353492824","pt":1646215701881,"mc":[{"id":"1.195503853","rc":[{"atl":[[2.32,0]],"id":39786791}],"con":true,"img":false}]}
{"op":"mcm","clk":"5353492838","pt":1646215702092,"mc":[{"id":"1.195503853","rc":[{"atb":[[1.78,10.69],[1.77,12.81]],"id":43167135},{"atl":[[1.9,16]],"id":43167135}],"con":true,"img":false}]}
{"op":"mcm","clk":"5353492848","pt":1646215702147,"mc":[{"id":"1.195503853","rc":[{"atb":[[1.81,10.24]],"id":43167135}],"con":true,"img":false}]}
{"op":"mcm","clk":"5353492857","pt":1646215702252,"mc":[{"id":"1.195503853","rc":[{"atb":[[1.77,2]],"id":43167135},{"atb":[[2.1,8.26]],"id":39786791}],"con":true,"img":false}]}
{"op":"mcm","clk":"5353492874","pt":1646215702462,"mc":[{"id":"1.195503853","rc":[{"atb":[[1.75,0]],"id":43167135}],"con":true,"img":false}]}
{"op":"mcm","clk":"5353492886","pt":1646215702567,"mc":[{"id":"1.195503853","rc":[{"atb":[[1.8,10.52]],"id":43167135}],"con":true,"img":false}]}
{"op":"mcm","clk":"5353492893","pt":1646215702671,"mc":[{"id":"1.195503853","rc":[{"atb":[[1.81,17.97]],"id":43167135}],"con":true,"img":false}]}
{"op":"mcm","clk":"5353492925","pt":1646215702988,"mc":[{"id":"1.195503853","rc":[{"atb":[[1.1,0],[1.5,0],[1.3,2]],"id":43167135},{"atb":[[1.83,0],[1.63,0],[2.06,0]],"id":39786791}],"con":true,"img":false}]}
{"op":"mcm","clk":"5353492944","pt":1646215703198,"mc":[{"id":"1.195503853","rc":[{"atb":[[1.81,10.24]],"id":43167135}],"con":true,"img":false}]}
{"op":"mcm","clk":"5353492978","pt":1646215703467,"mc":[{"id":"1.195503853","rc":[{"atb":[[1.81,46.26]],"id":43167135}],"con":true,"img":false}]}
{"op":"mcm","clk":"5353493001","pt":1646215703670,"mc":[{"id":"1.195503853","rc":[{"atb":[[1.56,0]],"id":43167135}],"con":true,"img":false}]}
{"op":"mcm","clk":"5353493006","pt":1646215703775,"mc":[{"id":"1.195503853","rc":[{"atb":[[1.78,0],[1.59,10.06],[1.82,10.24]],"id":43167135},{"atl":[[1.89,10.18]],"id":43167135}],"con":true,"img":false}]}
{"op":"mcm","clk":"5353493024","pt":1646215703983,"mc":[{"id":"1.195503853","rc":[{"atb":[[1.81,10.24]],"id":43167135}],"con":true,"img":false}]}
{"op":"mcm","clk":"5353493066","pt":1646215704455,"mc":[{"id":"1.195503853","rc":[{"atb":[[1.82,17.66],[1.8,46.99]],"id":43167135},{"atb":[[2.1,34.79]],"id":39786791},{"atl":[[2.24,8.06]],"id":39786791}],"con":true,"img":false}]}
{"op":"mcm","clk":"5353493108","pt":1646215704872,"mc":[{"id":"1.195503853","rc":[{"atl":[[2.22,14.32]],"id":39786791}],"con":true,"img":false}]}
{"op":"mcm","clk":"5353493118","pt":1646215704976,"mc":[{"id":"1.195503853","rc":[{"atb":[[1.76,0]],"id":43167135},{"atb":[[2.1,8.26]],"id":39786791}],"con":true,"img":false}]}
{"op":"mcm","clk":"5353493156","pt":1646215705391,"mc":[{"id":"1.195503853","rc":[{"atb":[[1.82,0]],"id":43167135},{"trd":[[1.82,17.66]],"ltp":1.82,"tv":17.66,"id":43167135},{"atl":[[2.22,0],[2.24,4.16]],"id":39786791},{"trd":[[2.24,9.37],[2.22,43.12]],"ltp":2.24,"tv":52.48,"id":39786791}],"con":true,"img":false}]}
{"op":"mcm","clk":"5353493166","pt":1646215705497,"mc":[{"id":"1.195503853","rc":[{"atb":[[1.81,46.26]],"id":43167135}],"con":true,"img":false}]}
{"op":"mcm","clk":"5353493177","pt":1646215705554,"mc":[{"id":"1.195503853","rc":[{"atl":[[1.87,7]],"id":43167135},{"atb":[[2.12,8.23]],"id":39786791},{"atl":[[2.26,10]],"id":39786791}],"con":true,"img":false}]}
{"op":"mcm","clk":"5353493186","pt":1646215705657,"mc":[{"id":"1.195503853","rc":[{"atl":[[1.87,17.31]],"id":43167135}],"con":true,"img":false}]}
{"op":"mcm","clk":"5353493194","pt":1646215705762,"mc":[{"id":"1.195503853","rc":[{"atl":[[1.93,0]],"id":43167135}],"con":true,"img":false}]}
{"op":"mcm","clk":"5353493211","pt":1646215705971,"mc":[{"id":"1.195503853","rc":[{"atb":[[1.81,10.24],[1.8,10.52]],"id":43167135}],"con":true,"img":false}]}
{"op":"mcm","clk":"5353493220","pt":1646215706075,"mc":[{"id":"1.195503853","rc":[{"atb":[[1.78,11.24]],"id":43167135}],"con":true,"img":false}]}
{"op":"mcm","clk":"5353493242","pt":1646215706385,"mc":[{"id":"1.195503853","rc":[{"atb":[[1.77,13.3]],"id":43167135}],"con":true,"img":false}]}
{"op":"mcm","clk":"5353493250","pt":1646215706491,"mc":[{"id":"1.195503853","rc":[{"atb":[[2.12,34.28]],"id":39786791}],"con":true,"img":false}]}
{"op":"mcm","clk":"5353493275","pt":1646215706754,"mc":[{"id":"1.195503853","rc":[{"atl":[[1.9,10.44]],"id":43167135}],"con":true,"img":false}]}
{"op":"mcm","clk":"5353493302","pt":1646215707070,"mc":[{"id":"1.195503853","rc":[{"atl":[[1.86,10.43]],"id":43167135}],"con":true,"img":false}]}
{"op":"mcm","clk":"5353493312","pt":1646215707173,"mc":[{"id":"1.195503853","rc":[{"atb":[[2.14,8.12]],"id":39786791}],"con":true,"img":false}]}
{"op":"mcm","clk":"5353493323","pt":1646215707276,"mc":[{"id":"1.195503853","rc":[{"atl":[[1.91,0]],"id":43167135}],"con":true,"img":false}]}
{"op":"mcm","clk":"5353493344","pt":1646215707483,"mc":[{"id":"1.195503853","rc":[{"atb":[[1.78,48.64],[1.79,10.55]],"id":43167135}],"con":true,"img":false}]}
{"op":"mcm","clk":"5353493355","pt":1646215707587,"mc":[{"id":"1.195503853","rc":[{"atb":[[1.81,0]],"id":43167135},{"atl":[[2.24,0]],"id":39786791}],"con":true,"img":false}]}
{"op":"mcm","clk":"5353493526","pt":1646215709477,"mc":[{"id":"1.195503853","rc":[{"atl":[[1.81,1.5],[1.86,0]],"id":43167135}],"con":true,"img":false}]}
{"op":"mcm","clk":"5353493544","pt":1646215709687,"mc":[{"id":"1.195503853","rc":[{"atl":[[1.87,0],[1.81,0]],"id":43167135},{"trd":[[1.87,181.54],[1.81,80.02]],"ltp":1.87,"tv":261.56,"id":43167135},{"atb":[[2.14,0]],"id":39786791},{"atl":[[2.14,2.78]],"id":39786791},{"trd":[[2.14,35.63],[2.22,44.34]],"ltp":2.14,"tv":79.97,"id":39786791}],"con":true,"img":false}]}
{"op":"mcm","clk":"5353493551","pt":1646215709791,"mc":[{"id":"1.195503853","rc":[{"atl":[[1.86,17.65]],"id":43167135},{"trd":[[1.87,184.73]],"ltp":1.87,"tv":184.73,"id":43167135},{"atl":[[2.14,0]],"id":39786791},{"trd":[[2.14,38.41]],"ltp":2.14,"tv":38.41,"id":39786791}],"con":true,"img":false}]}
{"op":"mcm","clk":"5353493558","pt":1646215709898,"mc":[{"id":"1.195503853","rc":[{"atl":[[1.86,7.23]],"id":43167135}],"con":true,"img":false}]}
{"op":"mcm","clk":"5353493565","pt":1646215710002,"mc":[{"id":"1.195503853","rc":[{"atb":[[1.79,47.47]],"id":43167135},{"atb":[[2.04,28.05],[2.12,8.23],[2.08,7.95]],"id":39786791}],"con":true,"img":false}]}
{"op":"mcm","clk":"5353493636","pt":1646215710792,"mc":[{"id":"1.195503853","rc":[{"atl":[[1.81,5.44]],"id":43167135}],"con":true,"img":false}]}
{"op":"mcm","clk":"5353493645","pt":1646215710898,"mc":[{"id":"1.195503853","rc":[{"atl":[[1.81,0]],"id":43167135},{"trd":[[1.81,90.92]],"ltp":1.81,"tv":90.92,"id":43167135}],"con":true,"img":false}]}
{"op":"mcm","clk":"5353493673","pt":1646215711164,"mc":[{"id":"1.195503853","rc":[{"atl":[[1.81,11]],"id":43167135}],"con":true,"img":false}]}
{"op":"mcm","clk":"5353493694","pt":1646215711373,"mc":[{"id":"1.195503853","rc":[{"atl":[[1.81,0]],"id":43167135},{"trd":[[1.81,101.92]],"ltp":1.81,"tv":101.92,"id":43167135},{"trd":[[2.22,53.31]],"ltp":2.22,"tv":53.31,"id":39786791}],"con":true,"img":false}]}
{"op":"mcm","clk":"5353493705","pt":1646215711477,"mc":[{"id":"1.195503853","rc":[{"atb":[[1.78,11.24],[1.76,38.38],[1.79,10.55]],"id":43167135},{"atb":[[2.12,34.28]],"id":39786791}],"con":true,"img":false}]}
{"op":"mcm","clk":"5353493739","pt":1646215711787,"mc":[{"id":"1.195503853","rc":[{"atb":[[1.59,0]],"id":43167135},{"atb":[[1.98,0]],"id":39786791}],"con":true,"img":false}]}
{"op":"mcm","clk":"5353493756","pt":1646215711997,"mc":[{"id":"1.195503853","rc":[{"atb":[[2.12,8.23]],"id":39786791}],"con":true,"img":false}]}
{"op":"mcm","clk":"5353493807","pt":1646215712470,"mc":[{"id":"1.195503853","rc":[{"atb":[[1.79,47.47]],"id":43167135},{"atb":[[2.1,34.79]],"id":39786791}],"con":true,"img":false}]}
{"op":"mcm","clk":"5353493963","pt":1646215714306,"mc":[{"id":"1.195503853","rc":[{"atl":[[1.89,0]],"id":43167135}],"con":true,"img":false}]}
{"op":"mcm","clk":"5353494039","pt":1646215715193,"mc":[{"id":"1.195503853","rc":[{"atb":[[1.28,19.27],[1.48,13.24],[1.08,67.44]],"id":43167135},{"atb":[[1.85,6.34],[2.1,39.69],[1.65,8.3]],"id":39786791}],"con":true,"img":false}]}
{"op":"mcm","clk":"5353494056","pt":1646215715402,"mc":[{"id":"1.195503853","rc":[{"atl":[[1.86,0]],"id":43167135}],"con":true,"img":false}]}
{"op":"mcm","clk":"5353494183","pt":1646215716812,"mc":[{"id":"1.195503853","rc":[{"atb":[[1.78,13.24],[1.77,11.3]],"id":43167135},{"atl":[[1.9,16]],"id":43167135}],"con":true,"img":false}]}
{"op":"mcm","clk":"5353494221","pt":1646215717183,"mc":[{"id":"1.195503853","marketDefinition":{"bspMarket":false,"turnInPlayEnabled":false,"persistenceEnabled":false,"marketBaseRate":7.0,"eventId":"31272499","eventTypeId":"4339","numberOfWinners":1,"bettingType":"ODDS","marketType":"MATCH_BET","marketTime":"2022-03-02T10:08:00.000Z","suspendTime":"2022-03-02T10:08:00.000Z","bspReconciled":false,"complete":true,"inPlay":false,"crossMatching":true,"runnersVoidable":false,"numberOfActiveRunners":2,"betDelay":0,"status":"SUSPENDED","runners":[{"status":"ACTIVE","sortPriority":1,"id":39786791,"name":"3. Tiger Talks"},{"status":"ACTIVE","sortPriority":2,"id":43167135,"name":"4. Pereira"}],"regulators":["MR_INT"],"venue":"Rockhampton","countryCode":"AU","discountAllowed":true,"timezone":"Australia/Queensland","openDate":"2022-03-02T08:28:00.000Z","version":4382930110,"name":"Tiger Talks v Pereira","eventName":"Rockhampton (AUS) 2nd Mar"},"rc":[],"con":true,"img":false}]}
{"op":"mcm","clk":"5353494221","pt":1646215717183,"mc":[{"id":"1.195503853","rc":[{"atb":[[1.28,0],[1.78,0],[1.7,0],[1.68,0],[1.53,0],[1.16,0],[1.11,0],[1.74,0],[1.67,0],[1.06,0],[1.42,0],[1.77,0],[1.66,0],[1.73,0],[1.64,0],[1.6,0],[1.01,0],[1.37,0],[1.23,0],[1.48,0],[1.08,0],[1.76,0],[1.69,0],[1.8,0],[1.72,0],[1.79,0],[1.57,0],[1.3,0]],"id":43167135},{"atl":[[2.8,0],[3.6,0],[4.3,0],[10.5,0],[2.04,0],[3.35,0],[3,0],[6.8,0],[2.84,0],[1.94,0],[15,0],[2.92,0],[8.6,0],[2.88,0],[5,0],[1.9,0],[2.46,0],[3.15,0],[5.7,0],[3.9,0]],"id":43167135},{"atb":[[1.2,0],[1.6,0],[1.01,0],[1.43,0],[1.03,0],[1.58,0],[2.04,0],[1.85,0],[2.12,0],[1.96,0],[2.1,0],[2.08,0],[1.56,0],[1.27,0],[1.81,0],[1.54,0],[1.5,0],[1.06,0],[1.32,0],[1.13,0],[1.65,0],[1.47,0],[1.04,0],[1.38,0]],"id":39786791},{"atl":[[9,0],[2.54,0],[2.3,0],[2.5,0],[5.8,0],[2.6,0],[2.64,0],[4.9,0],[2.58,0],[2.84,0],[2.26,0],[2.62,0],[2.94,0],[3.75,0],[2.76,0],[2.56,0],[7.2,0],[3.4,0],[2.66,0],[3.15,0],[4.2,0],[2.7,0]],"id":39786791}],"con":true,"img":false}]}
{"op":"mcm","clk":"5353503344","pt":1646215832131,"mc":[{"id":"1.195503853","rc":[{"trd":[[1.83,0],[1.89,0],[1.84,0],[1.85,0],[1.78,0],[1.96,0],[1.94,0],[1.87,0],[1.93,0],[1.8,0],[1.82,0],[1.79,0],[1.92,0],[1.81,0],[1.88,0],[1.91,0],[1.86,0]],"ltp":1.83,"tv":0.0,"id":43167135},{"trd":[[2.24,0],[2.22,0],[2.04,0],[2.12,0],[2.28,0],[2.18,0],[2.2,0],[1.93,0],[2.14,0],[2.16,0],[2.08,0]],"ltp":2.24,"tv":0.0,"id":39786791}],"con":true,"img":false}]}
{"op":"mcm","clk":"5353503392","pt":1646215832768,"mc":[{"id":"1.195503853","marketDefinition":{"bspMarket":false,"turnInPlayEnabled":false,"persistenceEnabled":false,"marketBaseRate":7.0,"eventId":"31272499","eventTypeId":"4339","numberOfWinners":1,"bettingType":"ODDS","marketType":"MATCH_BET","marketTime":"2022-03-02T10:08:00.000Z","suspendTime":"2022-03-02T10:08:00.000Z","bspReconciled":false,"complete":true,"inPlay":false,"crossMatching":false,"runnersVoidable":false,"numberOfActiveRunners":0,"betDelay":0,"status":"CLOSED","settledTime":"2022-03-02T10:10:30.000Z","runners":[{"status":"LOSER","sortPriority":1,"id":39786791,"name":"3. Tiger Talks"},{"status":"WINNER","sortPriority":2,"id":43167135,"name":"4. Pereira"}],"regulators":["MR_INT"],"venue":"Rockhampton","countryCode":"AU","discountAllowed":true,"timezone":"Australia/Queensland","openDate":"2022-03-02T08:28:00.000Z","version":4382931989,"name":"Tiger Talks v Pereira","eventName":"Rockhampton (AUS) 2nd Mar"},"rc":[],"con":true,"img":false}]}
