{"op":"mcm","clk":"5351767859","pt":1646175389025,"mc":[{"id":"1.195453779","marketDefinition":{"bspMarket":true,"turnInPlayEnabled":false,"persistenceEnabled":false,"marketBaseRate":7.0,"eventId":"31272499","eventTypeId":"4339","numberOfWinners":3,"bettingType":"ODDS","marketType":"PLACE","marketTime":"2022-03-02T11:19:00.000Z","suspendTime":"2022-03-02T11:19:00.000Z","bspReconciled":false,"complete":true,"inPlay":false,"crossMatching":false,"runnersVoidable":false,"numberOfActiveRunners":8,"betDelay":0,"status":"OPEN","runners":[{"status":"ACTIVE","sortPriority":1,"id":40622317,"name":"1. Velocity Tamika"},{"status":"ACTIVE","sortPriority":2,"id":40812693,"name":"2. Bailing Out"},{"status":"ACTIVE","sortPriority":3,"id":42256449,"name":"3. Black Baccara"},{"status":"ACTIVE","sortPriority":4,"id":39786303,"name":"4. Destructive Riot"},{"status":"ACTIVE","sortPriority":5,"id":38247337,"name":"5. On The Bayou"},{"status":"ACTIVE","sortPriority":6,"id":40072523,"name":"6. Chrome Cadillac"},{"status":"ACTIVE","sortPriority":7,"id":39832467,"name":"7. Shian Ned"},{"status":"ACTIVE","sortPriority":8,"id":37495332,"name":"9. Siennas Ace"}],"regulators":["MR_INT"],"venue":"Rockhampton","countryCode":"AU","discountAllowed":true,"timezone":"Australia/Queensland","openDate":"2022-03-02T08:34:00.000Z","version":4382437867,"name":"To Be Placed","eventName":"Rockhampton (AUS) 2nd Mar"},"rc":[],"con":true,"img":false}]}
{"op":"mcm","clk":"5351835883","pt":1646176787551,"mc":[{"id":"1.195453779","rc":[{"atb":[[1.2,604.24],[1.25,241.69],[1.15,805.66]],"id":39786303},{"atl":[[3.6,18.59],[3.1,11.5],[2.44,8.39],[2.64,7.37],[2.84,13.13]],"id":39786303},{"spn":1.84,"spf":"NaN","id":39786303},{"atb":[[1.4,151.06],[1.3,402.83],[1.35,345.28]],"id":38247337},{"atl":[[4.3,14.64],[2.86,6.49],[2.66,7.27],[3.15,11.24],[3.65,9.11]],"id":38247337},{"spn":2.03,"spf":"NaN","id":38247337},{"atb":[[2.8,33.57],[2.6,75.53],[2.7,71.08]],"id":42256449},{"atl":[[7.2,1.94],[18,1.42],[9.2,1.47],[13,2.01],[26,1.93]],"id":42256449},{"spn":5.0,"spf":"NaN","id":42256449},{"atb":[[3.45,49.32],[3.95,20.48],[3.7,44.75]],"id":40812693},{"atl":[[18.5,0.69],[85,0.57],[44,0.56],[13.5,0.96],[27,0.93]],"id":40812693},{"spn":8.72,"spf":"NaN","id":40812693},{"atb":[[3.25,53.71],[3.5,48.33],[3.75,21.97]],"id":37495332},{"atl":[[16.5,0.77],[65,0.75],[36,0.69],[11.5,1.14],[23,1.09]],"id":37495332},{"spn":7.62,"spf":"NaN","id":37495332},{"atb":[[1.7,172.64],[1.75,80.56],[1.65,185.92]],"id":39832467},{"atl":[[4,4.02],[8,6.9],[5,6.04],[6,4.83],[3.5,4.83]],"id":39832467},{"spn":2.62,"spf":"NaN","id":39832467},{"atb":[[1.01,12084.92],[1.11,549.31],[1.06,2014.15]],"id":40622317},{"atl":[[2.36,8.88],[2.56,15.49],[2.96,24.66],[2.16,10.41],[2.76,13.73]],"id":40622317},{"spn":1.63,"spf":"NaN","id":40622317},{"atb":[[2.06,57],[1.98,123.31],[1.93,129.94]],"id":40072523},{"atl":[[16,3.22],[6.4,2.23],[11,2.41],[5.2,2.87],[8.4,3.26]],"id":40072523},{"spn":3.63,"spf":"NaN","id":40072523}],"con":true,"img":false}]}
{"op":"mcm","clk":"5351854262","pt":1646177216937,"mc":[{"id":"1.195453779","rc":[{"atb":[[1.2,0],[1.25,0],[1.15,0]],"id":39786303},{"atl":[[3.6,0],[3.1,0],[2.44,0],[2.64,0],[2.84,0]],"id":39786303},{"spn":"NaN","spf":"NaN","id":39786303},{"atb":[[2.8,0],[2.6,0],[2.7,0]],"id":42256449},{"atl":[[7.2,0],[18,0],[9.2,0],[13,0],[26,0]],"id":42256449},{"spn":"NaN","spf":"NaN","id":42256449},{"atb":[[3.45,0],[3.95,0],[3.7,0]],"id":40812693},{"atl":[[18.5,0],[85,0],[44,0],[13.5,0],[27,0]],"id":40812693},{"spn":"NaN","spf":"NaN","id":40812693},{"atb":[[3.25,0],[3.5,0],[3.75,0]],"id":37495332},{"atl":[[16.5,0],[65,0],[36,0],[11.5,0],[23,0]],"id":37495332},{"spn":"NaN","spf":"NaN","id":37495332},{"atb":[[1.7,0],[1.75,0],[1.65,0]],"id":39832467},{"atl":[[4,0],[8,0],[5,0],[6,0],[3.5,0]],"id":39832467},{"spn":"NaN","spf":"NaN","id":39832467},{"atb":[[1.01,0],[1.11,0],[1.06,0]],"id":40622317},{"atl":[[2.36,0],[2.56,0],[2.96,0],[2.16,0],[2.76,0]],"id":40622317},{"spn":"NaN","spf":"NaN","id":40622317},{"atb":[[2.06,0],[1.98,0],[1.93,0]],"id":40072523},{"atl":[[16,0],[6.4,0],[11,0],[5.2,0],[8.4,0]],"id":40072523},{"spn":"NaN","spf":"NaN","id":40072523}],"con":true,"img":false}]}
{"op":"mcm","clk":"5351855583","pt":1646177247960,"mc":[{"id":"1.195453779","rc":[{"atb":[[1.2,604.24],[1.25,241.69],[1.15,805.66]],"id":39786303},{"atl":[[3.6,18.59],[3.1,11.5],[2.44,8.39],[2.64,7.37],[2.84,13.13]],"id":39786303},{"atb":[[2.8,33.57],[2.6,75.53],[2.7,71.08]],"id":42256449},{"atl":[[7.2,1.94],[18,1.42],[9.2,1.47],[13,2.01],[26,1.93]],"id":42256449},{"atb":[[4,40.28],[4.5,17.26],[3.75,43.94]],"id":40812693},{"atl":[[16,0.8],[34,0.73],[22,0.57],[60,0.4],[120,0.4]],"id":40812693},{"atb":[[4.1,19.49],[3.8,43.16],[3.55,47.39]],"id":37495332},{"atl":[[19.5,0.65],[95,0.51],[48,0.51],[14.5,0.89],[29,0.86]],"id":37495332},{"atb":[[1.6,201.41],[1.7,86.32],[1.65,185.92]],"id":39832467},{"atl":[[3.2,5.49],[3.7,4.47],[6.8,8.33],[4.4,7.1],[5.4,5.49]],"id":39832467},{"atb":[[1.01,12084.92],[1.09,671.38],[1.04,3021.23]],"id":40622317},{"atl":[[2.72,14.05],[2.92,25.17],[2.32,9.15],[2.52,15.9],[2.12,10.78]],"id":40622317},{"atb":[[1.8,151.06],[1.85,142.17],[1.9,67.13]],"id":40072523},{"atl":[[4,4.02],[8,3.45],[5,3.02],[10,5.37],[6,4.83]],"id":40072523}],"con":true,"img":false}]}
{"op":"mcm","clk":"5351873761","pt":1646177663695,"mc":[{"id":"1.195453779","rc":[{"atb":[[1.2,0],[1.25,0],[1.15,0]],"id":39786303},{"atl":[[3.6,0],[3.1,0],[2.44,0],[2.64,0],[2.84,0]],"id":39786303},{"atb":[[1.4,0],[1.3,0],[1.35,0]],"id":38247337},{"atl":[[4.3,0],[2.86,0],[2.66,0],[3.15,0],[3.65,0]],"id":38247337},{"spn":"NaN","spf":"NaN","id":38247337},{"atb":[[2.8,0],[2.6,0],[2.7,0]],"id":42256449},{"atl":[[7.2,0],[18,0],[9.2,0],[13,0],[26,0]],"id":42256449},{"atb":[[4,0],[4.5,0],[3.75,0]],"id":40812693},{"atl":[[16,0],[34,0],[22,0],[60,0],[120,0]],"id":40812693},{"atb":[[4.1,0],[3.8,0],[3.55,0]],"id":37495332},{"atl":[[19.5,0],[95,0],[48,0],[14.5,0],[29,0]],"id":37495332},{"atb":[[1.6,0],[1.7,0],[1.65,0]],"id":39832467},{"atl":[[3.2,0],[3.7,0],[6.8,0],[4.4,0],[5.4,0]],"id":39832467},{"atb":[[1.01,0],[1.09,0],[1.04,0]],"id":40622317},{"atl":[[2.72,0],[2.92,0],[2.32,0],[2.52,0],[2.12,0]],"id":40622317},{"atb":[[1.8,0],[1.85,0],[1.9,0]],"id":40072523},{"atl":[[4,0],[8,0],[5,0],[10,0],[6,0]],"id":40072523}],"con":true,"img":false}]}
{"op":"mcm","clk":"5351873991","pt":1646177668420,"mc":[{"id":"1.195453779","rc":[{"atb":[[1.25,483.39],[1.3,402.83],[1.35,172.64]],"id":39786303},{"atl":[[2.8,6.71],[4,16.11],[3,12.08],[2.6,7.55],[3.5,9.66]],"id":39786303},{"atb":[[1.6,201.41],[1.55,219.72],[1.65,92.96]],"id":38247337},{"atl":[[3.45,4.93],[3.95,8.19],[4.9,6.19],[2.98,6.1],[5.9,9.86]],"id":38247337},{"atb":[[2.74,69.45],[2.84,65.67],[2.94,31.14]],"id":42256449},{"atl":[[8,1.72],[10,1.34],[20,1.27],[15,1.72],[30,1.66]],"id":42256449},{"atb":[[4,40.28],[4.5,17.26],[3.75,43.94]],"id":40812693},{"atl":[[16,0.8],[34,0.73],[22,0.57],[60,0.4],[120,0.4]],"id":40812693},{"atb":[[4,40.28],[4.5,17.26],[3.75,43.94]],"id":37495332},{"atl":[[16,0.8],[34,0.73],[22,0.57],[60,0.4],[120,0.4]],"id":37495332},{"atb":[[1.7,172.64],[1.75,80.56],[1.65,185.92]],"id":39832467},{"atl":[[4,4.02],[8,6.9],[5,6.04],[6,4.83],[3.5,4.83]],"id":39832467},{"atb":[[1.03,4028.3],[1.13,464.8],[1.08,1510.61]],"id":40622317},{"atl":[[2.4,8.63],[2.8,13.42],[3,24.16],[2.6,15.1],[2.2,10.07]],"id":40622317},{"atb":[[1.7,172.64],[1.75,80.56],[1.65,185.92]],"id":40072523},{"atl":[[4,4.02],[8,6.9],[5,6.04],[6,4.83],[3.5,4.83]],"id":40072523}],"con":true,"img":false}]}
{"op":"mcm","clk":"5352003868","pt":1646180202622,"mc":[{"id":"1.195453779","marketDefinition":{"bspMarket":true,"turnInPlayEnabled":false,"persistenceEnabled":false,"marketBaseRate":7.0,"eventId":"31272499","eventTypeId":"4339","numberOfWinners":3,"bettingType":"ODDS","marketType":"PLACE","marketTime":"2022-03-02T11:19:00.000Z","suspendTime":"2022-03-02T11:19:00.000Z","bspReconciled":false,"complete":true,"inPlay":false,"crossMatching":false,"runnersVoidable":false,"numberOfActiveRunners":8,"betDelay":0,"status":"OPEN","runners":[{"status":"ACTIVE","sortPriority":1,"id":40622317,"name":"1. Velocity Tamika"},{"status":"ACTIVE","sortPriority":2,"id":40812693,"name":"2. Bailing Out"},{"status":"ACTIVE","sortPriority":3,"id":42256449,"name":"3. Black Baccara"},{"status":"ACTIVE","sortPriority":4,"id":39786303,"name":"4. Destructive Riot"},{"status":"ACTIVE","sortPriority":5,"id":38247337,"name":"5. On The Bayou"},{"status":"ACTIVE","sortPriority":6,"id":40072523,"name":"6. Chrome Cadillac"},{"status":"ACTIVE","sortPriority":7,"id":39832467,"name":"7. Shian Ned"},{"status":"ACTIVE","sortPriority":8,"id":37495332,"name":"9. Siennas Ace"}],"regulators":["MR_INT"],"venue":"Rockhampton","countryCode":"AU","discountAllowed":true,"timezone":"Australia/Queensland","openDate":"2022-03-02T08:34:00.000Z","version":4382437867,"name":"To Be Placed","eventName":"Rockhampton (AUS) 2nd Mar"},"rc":[{"atb":[[1.25,483.44],[1.3,402.87],[1.35,172.65]],"id":39786303},{"atl":[[2.8,6.71],[4,16.11],[3,12.08],[2.6,7.55],[3.5,9.66]],"id":39786303},{"spn":1.97,"spf":"NaN","id":39786303},{"atb":[[1.6,201.43],[1.55,219.75],[1.65,92.97]],"id":38247337},{"atl":[[3.45,4.93],[3.95,8.19],[4.9,6.19],[2.98,6.1],[5.9,9.86]],"id":38247337},{"spn":2.31,"spf":"NaN","id":38247337},{"atb":[[2.74,69.46],[2.84,65.68],[2.94,31.15]],"id":42256449},{"atl":[[8,1.72],[10,1.34],[20,1.27],[15,1.72],[30,1.66]],"id":42256449},{"spn":5.47,"spf":"NaN","id":42256449},{"atb":[[4,40.28],[4.5,17.26],[3.75,43.95]],"id":40812693},{"atl":[[16,0.8],[34,0.73],[22,0.57],[60,0.4],[120,0.4]],"id":40812693},{"spn":10.25,"spf":"NaN","id":40812693},{"atb":[[4,40.28],[4.5,17.26],[3.75,43.95]],"id":37495332},{"atl":[[16,0.8],[34,0.73],[22,0.57],[60,0.4],[120,0.4]],"id":37495332},{"spn":10.25,"spf":"NaN","id":37495332},{"atb":[[1.7,172.65],[1.75,80.57],[1.65,185.94]],"id":39832467},{"atl":[[4,4.02],[8,6.9],[5,6.04],[6,4.83],[3.5,4.83]],"id":39832467},{"spn":2.62,"spf":"NaN","id":39832467},{"atb":[[1.03,4028.74],[1.13,464.85],[1.08,1510.77]],"id":40622317},{"atl":[[2.4,8.63],[2.8,13.43],[3,24.17],[2.6,15.1],[2.2,10.07]],"id":40622317},{"spn":1.66,"spf":"NaN","id":40622317},{"atb":[[1.7,172.65],[1.75,80.57],[1.65,185.94]],"id":40072523},{"atl":[[4,4.02],[8,6.9],[5,6.04],[6,4.83],[3.5,4.83]],"id":40072523},{"spn":2.62,"spf":"NaN","id":40072523}],"con":true,"img":true}]}
{"op":"mcm","clk":"5352146211","pt":1646183572669,"mc":[{"id":"1.195453779","marketDefinition":{"bspMarket":true,"turnInPlayEnabled":false,"persistenceEnabled":false,"marketBaseRate":7.0,"eventId":"31272499","eventTypeId":"4339","numberOfWinners":3,"bettingType":"ODDS","marketType":"PLACE","marketTime":"2022-03-02T11:19:00.000Z","suspendTime":"2022-03-02T11:19:00.000Z","bspReconciled":false,"complete":true,"inPlay":false,"crossMatching":false,"runnersVoidable":false,"numberOfActiveRunners":8,"betDelay":0,"status":"OPEN","runners":[{"status":"ACTIVE","sortPriority":1,"id":40622317,"name":"1. Velocity Tamika"},{"status":"ACTIVE","sortPriority":2,"id":40812693,"name":"2. Bailing Out"},{"status":"ACTIVE","sortPriority":3,"id":42256449,"name":"3. Black Baccara"},{"status":"ACTIVE","sortPriority":4,"id":39786303,"name":"4. Destructive Riot"},{"status":"ACTIVE","sortPriority":5,"id":38247337,"name":"5. On The Bayou"},{"status":"ACTIVE","sortPriority":6,"id":40072523,"name":"6. Chrome Cadillac"},{"status":"ACTIVE","sortPriority":7,"id":39832467,"name":"7. Shian Ned"},{"status":"ACTIVE","sortPriority":8,"id":37495332,"name":"9. Siennas Ace"}],"regulators":["MR_INT"],"venue":"Rockhampton","countryCode":"AU","discountAllowed":true,"timezone":"Australia/Queensland","openDate":"2022-03-02T08:28:00.000Z","version":4382597850,"name":"To Be Placed","eventName":"Rockhampton (AUS) 2nd Mar"},"rc":[],"con":true,"img":false}]}
{"op":"mcm","clk":"5352164288","pt":1646184056665,"mc":[{"id":"1.195453779","marketDefinition":{"bspMarket":true,"turnInPlayEnabled":false,"persistenceEnabled":false,"marketBaseRate":7.0,"eventId":"31272499","eventTypeId":"4339","numberOfWinners":3,"bettingType":"ODDS","marketType":"PLACE","marketTime":"2022-03-02T11:09:00.000Z","suspendTime":"2022-03-02T11:09:00.000Z","bspReconciled":false,"complete":true,"inPlay":false,"crossMatching":false,"runnersVoidable":false,"numberOfActiveRunners":8,"betDelay":0,"status":"OPEN","runners":[{"status":"ACTIVE","sortPriority":1,"id":40622317,"name":"1. Velocity Tamika"},{"status":"ACTIVE","sortPriority":2,"id":40812693,"name":"2. Bailing Out"},{"status":"ACTIVE","sortPriority":3,"id":42256449,"name":"3. Black Baccara"},{"status":"ACTIVE","sortPriority":4,"id":39786303,"name":"4. Destructive Riot"},{"status":"ACTIVE","sortPriority":5,"id":38247337,"name":"5. On The Bayou"},{"status":"ACTIVE","sortPriority":6,"id":40072523,"name":"6. Chrome Cadillac"},{"status":"ACTIVE","sortPriority":7,"id":39832467,"name":"7. Shian Ned"},{"status":"ACTIVE","sortPriority":8,"id":37495332,"name":"9. Siennas Ace"}],"regulators":["MR_INT"],"venue":"Rockhampton","countryCode":"AU","discountAllowed":true,"timezone":"Australia/Queensland","openDate":"2022-03-02T08:28:00.000Z","version":4382606038,"name":"To Be Placed","eventName":"Rockhampton (AUS) 2nd Mar"},"rc":[],"con":true,"img":false}]}
{"op":"mcm","clk":"5352237988","pt":1646185602657,"mc":[{"id":"1.195453779","marketDefinition":{"bspMarket":true,"turnInPlayEnabled":false,"persistenceEnabled":false,"marketBaseRate":7.0,"eventId":"31272499","eventTypeId":"4339","numberOfWinners":3,"bettingType":"ODDS","marketType":"PLACE","marketTime":"2022-03-02T11:09:00.000Z","suspendTime":"2022-03-02T11:09:00.000Z","bspReconciled":false,"complete":true,"inPlay":false,"crossMatching":false,"runnersVoidable":false,"numberOfActiveRunners":8,"betDelay":0,"status":"OPEN","runners":[{"status":"ACTIVE","sortPriority":1,"id":40622317,"name":"1. Velocity Tamika"},{"status":"ACTIVE","sortPriority":2,"id":40812693,"name":"2. Bailing Out"},{"status":"ACTIVE","sortPriority":3,"id":42256449,"name":"3. Black Baccara"},{"status":"ACTIVE","sortPriority":4,"id":39786303,"name":"4. Destructive Riot"},{"status":"ACTIVE","sortPriority":5,"id":38247337,"name":"5. On The Bayou"},{"status":"ACTIVE","sortPriority":6,"id":40072523,"name":"6. Chrome Cadillac"},{"status":"ACTIVE","sortPriority":7,"id":39832467,"name":"7. Shian Ned"},{"status":"ACTIVE","sortPriority":8,"id":37495332,"name":"9. Siennas Ace"}],"regulators":["MR_INT"],"venue":"Rockhampton","countryCode":"AU","discountAllowed":true,"timezone":"Australia/Queensland","openDate":"2022-03-02T08:28:00.000Z","version":4382606038,"name":"To Be Placed","eventName":"Rockhampton (AUS) 2nd Mar"},"rc":[{"atb":[[1.25,484.21],[1.3,403.51],[1.35,172.93]],"id":39786303},{"atl":[[2.8,6.72],[4,16.14],[3,12.1],[2.6,7.56],[3.5,9.68]],"id":39786303},{"spn":1.97,"spf":"NaN","id":39786303},{"atb":[[1.6,201.75],[1.55,220.09],[1.65,93.11]],"id":38247337},{"atl":[[3.45,4.94],[3.95,8.2],[4.9,6.2],[2.98,6.11],[5.9,9.88]],"id":38247337},{"spn":2.31,"spf":"NaN","id":38247337},{"atb":[[2.74,69.57],[2.84,65.78],[2.94,31.2]],"id":42256449},{"atl":[[8,1.72],[10,1.34],[20,1.27],[15,1.72],[30,1.66]],"id":42256449},{"spn":5.47,"spf":"NaN","id":42256449},{"atb":[[4,40.35],[4.5,17.29],[3.75,44.02]],"id":40812693},{"atl":[[16,0.8],[34,0.73],[22,0.57],[60,0.4],[120,0.4]],"id":40812693},{"spn":10.25,"spf":"NaN","id":40812693},{"atb":[[4,40.35],[4.5,17.29],[3.75,44.02]],"id":37495332},{"atl":[[16,0.8],[34,0.73],[22,0.57],[60,0.4],[120,0.4]],"id":37495332},{"spn":10.25,"spf":"NaN","id":37495332},{"atb":[[1.7,172.93],[1.75,80.7],[1.65,186.23]],"id":39832467},{"atl":[[4,4.03],[8,6.91],[5,6.05],[6,4.84],[3.5,4.84]],"id":39832467},{"spn":2.62,"spf":"NaN","id":39832467},{"atb":[[1.03,4035.11],[1.13,465.59],[1.08,1513.16]],"id":40622317},{"atl":[[2.4,8.64],[2.8,13.45],[3,24.21],[2.6,15.13],[2.2,10.08]],"id":40622317},{"spn":1.66,"spf":"NaN","id":40622317},{"atb":[[1.7,172.93],[1.75,80.7],[1.65,186.23]],"id":40072523},{"atl":[[4,4.03],[8,6.91],[5,6.05],[6,4.84],[3.5,4.84]],"id":40072523},{"spn":2.62,"spf":"NaN","id":40072523}],"con":true,"img":true}]}
{"op":"mcm","clk":"5352465285","pt":1646191002605,"mc":[{"id":"1.195453779","marketDefinition":{"bspMarket":true,"turnInPlayEnabled":false,"persistenceEnabled":false,"marketBaseRate":7.0,"eventId":"31272499","eventTypeId":"4339","numberOfWinners":3,"bettingType":"ODDS","marketType":"PLACE","marketTime":"2022-03-02T11:09:00.000Z","suspendTime":"2022-03-02T11:09:00.000Z","bspReconciled":false,"complete":true,"inPlay":false,"crossMatching":false,"runnersVoidable":false,"numberOfActiveRunners":8,"betDelay":0,"status":"OPEN","runners":[{"status":"ACTIVE","sortPriority":1,"id":40622317,"name":"1. Velocity Tamika"},{"status":"ACTIVE","sortPriority":2,"id":40812693,"name":"2. Bailing Out"},{"status":"ACTIVE","sortPriority":3,"id":42256449,"name":"3. Black Baccara"},{"status":"ACTIVE","sortPriority":4,"id":39786303,"name":"4. Destructive Riot"},{"status":"ACTIVE","sortPriority":5,"id":38247337,"name":"5. On The Bayou"},{"status":"ACTIVE","sortPriority":6,"id":40072523,"name":"6. Chrome Cadillac"},{"status":"ACTIVE","sortPriority":7,"id":39832467,"name":"7. Shian Ned"},{"status":"ACTIVE","sortPriority":8,"id":37495332,"name":"9. Siennas Ace"}],"regulators":["MR_INT"],"venue":"Rockhampton","countryCode":"AU","discountAllowed":true,"timezone":"Australia/Queensland","openDate":"2022-03-02T08:28:00.000Z","version":4382606038,"name":"To Be Placed","eventName":"Rockhampton (AUS) 2nd Mar"},"rc":[{"atb":[[1.25,485.03],[1.3,404.19],[1.35,173.22]],"id":39786303},{"atl":[[2.8,6.73],[4,16.16],[3,12.12],[2.6,7.58],[3.5,9.7]],"id":39786303},{"spn":1.97,"spf":"NaN","id":39786303},{"atb":[[1.6,202.09],[1.55,220.47],[1.65,93.27]],"id":38247337},{"atl":[[3.45,4.94],[3.95,8.22],[4.9,6.21],[2.98,6.12],[5.9,9.89]],"id":38247337},{"spn":2.31,"spf":"NaN","id":38247337},{"atb":[[2.74,69.69],[2.84,65.9],[2.94,31.25]],"id":42256449},{"atl":[[8,1.73],[10,1.34],[20,1.27],[15,1.73],[30,1.67]],"id":42256449},{"spn":5.47,"spf":"NaN","id":42256449},{"atb":[[4,40.41],[4.5,17.32],[3.75,44.09]],"id":40812693},{"atl":[[16,0.8],[34,0.73],[22,0.57],[60,0.4],[120,0.4]],"id":40812693},{"spn":10.25,"spf":"NaN","id":40812693},{"atb":[[4,40.41],[4.5,17.32],[3.75,44.09]],"id":37495332},{"atl":[[16,0.8],[34,0.73],[22,0.57],[60,0.4],[120,0.4]],"id":37495332},{"spn":10.25,"spf":"NaN","id":37495332},{"atb":[[1.7,173.22],[1.75,80.83],[1.65,186.55]],"id":39832467},{"atl":[[4,4.04],[8,6.93],[5,6.06],[6,4.85],[3.5,4.85]],"id":39832467},{"spn":2.62,"spf":"NaN","id":39832467},{"atb":[[1.03,4041.94],[1.13,466.38],[1.08,1515.73]],"id":40622317},{"atl":[[2.4,8.66],[2.8,13.47],[3,24.25],[2.6,15.15],[2.2,10.1]],"id":40622317},{"spn":1.66,"spf":"NaN","id":40622317},{"atb":[[1.7,173.22],[1.75,80.83],[1.65,186.55]],"id":40072523},{"atl":[[4,4.04],[8,6.93],[5,6.06],[6,4.85],[3.5,4.85]],"id":40072523},{"spn":2.62,"spf":"NaN","id":40072523}],"con":true,"img":true}]}
{"op":"mcm","clk":"5352822079","pt":1646201802637,"mc":[{"id":"1.195453779","marketDefinition":{"bspMarket":true,"turnInPlayEnabled":false,"persistenceEnabled":false,"marketBaseRate":7.0,"eventId":"31272499","eventTypeId":"4339","numberOfWinners":3,"bettingType":"ODDS","marketType":"PLACE","marketTime":"2022-03-02T11:09:00.000Z","suspendTime":"2022-03-02T11:09:00.000Z","bspReconciled":false,"complete":true,"inPlay":false,"crossMatching":false,"runnersVoidable":false,"numberOfActiveRunners":8,"betDelay":0,"status":"OPEN","runners":[{"status":"ACTIVE","sortPriority":1,"id":40622317,"name":"1. Velocity Tamika"},{"status":"ACTIVE","sortPriority":2,"id":40812693,"name":"2. Bailing Out"},{"status":"ACTIVE","sortPriority":3,"id":42256449,"name":"3. Black Baccara"},{"status":"ACTIVE","sortPriority":4,"id":39786303,"name":"4. Destructive Riot"},{"status":"ACTIVE","sortPriority":5,"id":38247337,"name":"5. On The Bayou"},{"status":"ACTIVE","sortPriority":6,"id":40072523,"name":"6. Chrome Cadillac"},{"status":"ACTIVE","sortPriority":7,"id":39832467,"name":"7. Shian Ned"},{"status":"ACTIVE","sortPriority":8,"id":37495332,"name":"9. Siennas Ace"}],"regulators":["MR_INT"],"venue":"Rockhampton","countryCode":"AU","discountAllowed":true,"timezone":"Australia/Queensland","openDate":"2022-03-02T08:28:00.000Z","version":4382606038,"name":"To Be Placed","eventName":"Rockhampton (AUS) 2nd Mar"},"rc":[{"atb":[[1.25,484.84],[1.3,404.04],[1.35,173.15]],"id":39786303},{"atl":[[2.8,6.73],[4,16.16],[3,12.12],[2.6,7.57],[3.5,9.69]],"id":39786303},{"spn":1.97,"spf":"NaN","id":39786303},{"atb":[[1.6,202.02],[1.55,220.38],[1.65,93.24]],"id":38247337},{"atl":[[3.45,4.94],[3.95,8.21],[4.9,6.21],[2.98,6.12],[5.9,9.89]],"id":38247337},{"spn":2.31,"spf":"NaN","id":38247337},{"atb":[[2.74,69.66],[2.84,65.87],[2.94,31.24]],"id":42256449},{"atl":[[8,1.73],[10,1.34],[20,1.27],[15,1.73],[30,1.67]],"id":42256449},{"spn":5.47,"spf":"NaN","id":42256449},{"atb":[[4,40.4],[4.5,17.31],[3.75,44.07]],"id":40812693},{"atl":[[16,0.8],[34,0.73],[22,0.57],[60,0.4],[120,0.4]],"id":40812693},{"spn":10.25,"spf":"NaN","id":40812693},{"atb":[[4,40.4],[4.5,17.31],[3.75,44.07]],"id":37495332},{"atl":[[16,0.8],[34,0.73],[22,0.57],[60,0.4],[120,0.4]],"id":37495332},{"spn":10.25,"spf":"NaN","id":37495332},{"atb":[[1.7,173.15],[1.75,80.8],[1.65,186.48]],"id":39832467},{"atl":[[4,4.04],[8,6.92],[5,6.06],[6,4.84],[3.5,4.84]],"id":39832467},{"spn":2.62,"spf":"NaN","id":39832467},{"atb":[[1.03,4040.4],[1.13,466.2],[1.08,1515.15]],"id":40622317},{"atl":[[2.4,8.65],[2.8,13.46],[3,24.24],[2.6,15.15],[2.2,10.1]],"id":40622317},{"spn":1.66,"spf":"NaN","id":40622317},{"atb":[[1.7,173.15],[1.75,80.8],[1.65,186.48]],"id":40072523},{"atl":[[4,4.04],[8,6.92],[5,6.06],[6,4.84],[3.5,4.84]],"id":40072523},{"spn":2.62,"spf":"NaN","id":40072523}],"con":true,"img":true}]}
{"op":"mcm","clk":"5352957910","pt":1646205655019,"mc":[{"id":"1.195453779","rc":[{"atb":[[1.25,484.71],[1.3,403.93],[1.35,173.11]],"id":39786303},{"atl":[[2.8,6.73],[4,16.15],[3,12.11],[2.6,7.57],[3.5,9.69]],"id":39786303},{"spn":1.97,"spf":"NaN","id":39786303},{"atb":[[1.6,0],[1.55,0],[1.65,0]],"id":38247337},{"atl":[[3.45,0],[3.95,0],[4.9,0],[2.98,0],[5.9,0]],"id":38247337},{"atb":[[2.74,69.64],[2.84,65.85],[2.94,31.23]],"id":42256449},{"atl":[[8,1.73],[10,1.34],[20,1.27],[15,1.73],[30,1.67]],"id":42256449},{"spn":5.47,"spf":"NaN","id":42256449},{"atb":[[4,40.39],[4.5,17.3],[3.75,44.06]],"id":40812693},{"atl":[[16,0.8],[34,0.73],[22,0.57],[60,0.4],[120,0.4]],"id":40812693},{"spn":10.25,"spf":"NaN","id":40812693},{"atb":[[4,0],[4.5,0],[3.75,0]],"id":37495332},{"atl":[[16,0],[34,0],[22,0],[60,0],[120,0]],"id":37495332},{"atb":[[1.7,0],[1.75,0],[1.65,0]],"id":39832467},{"atl":[[4,0],[8,0],[5,0],[6,0],[3.5,0]],"id":39832467},{"atb":[[1.03,0],[1.13,0],[1.08,0]],"id":40622317},{"atl":[[2.4,0],[2.8,0],[3,0],[2.6,0],[2.2,0]],"id":40622317},{"atb":[[1.7,173.11],[1.75,80.78],[1.65,186.43]],"id":40072523},{"atl":[[4,4.03],[8,6.92],[5,6.05],[6,4.84],[3.5,4.84]],"id":40072523},{"spn":2.62,"spf":"NaN","id":40072523}],"con":true,"img":false}]}
{"op":"mcm","clk":"5352958469","pt":1646205672803,"mc":[{"id":"1.195453779","rc":[{"atb":[[1.6,201.96],[1.55,220.32],[1.65,93.21]],"id":38247337},{"atl":[[3.45,4.94],[3.95,8.21],[4.9,6.21],[2.98,6.11],[5.9,9.89]],"id":38247337},{"atb":[[4.8,31.88],[5.8,12.62],[5.3,28.18]],"id":37495332},{"atl":[[19,0.67],[90,0.27],[180,0.27],[46,0.54],[28,0.44]],"id":37495332},{"atb":[[1.4,151.47],[1.3,403.93],[1.35,346.22]],"id":39832467},{"atl":[[4.3,14.68],[2.86,6.51],[2.66,7.29],[3.15,11.27],[3.65,9.14]],"id":39832467},{"atb":[[1.01,12117.9],[1.11,550.81],[1.06,2019.65]],"id":40622317},{"atl":[[2.36,8.9],[2.56,15.53],[2.96,24.73],[2.16,10.44],[2.76,13.77]],"id":40622317}],"con":true,"img":false}]}
{"op":"mcm","clk":"5353027454","pt":1646207202672,"mc":[{"id":"1.195453779","marketDefinition":{"bspMarket":true,"turnInPlayEnabled":false,"persistenceEnabled":false,"marketBaseRate":7.0,"eventId":"31272499","eventTypeId":"4339","numberOfWinners":3,"bettingType":"ODDS","marketType":"PLACE","marketTime":"2022-03-02T11:09:00.000Z","suspendTime":"2022-03-02T11:09:00.000Z","bspReconciled":false,"complete":true,"inPlay":false,"crossMatching":false,"runnersVoidable":false,"numberOfActiveRunners":8,"betDelay":0,"status":"OPEN","runners":[{"status":"ACTIVE","sortPriority":1,"id":40622317,"name":"1. Velocity Tamika"},{"status":"ACTIVE","sortPriority":2,"id":40812693,"name":"2. Bailing Out"},{"status":"ACTIVE","sortPriority":3,"id":42256449,"name":"3. Black Baccara"},{"status":"ACTIVE","sortPriority":4,"id":39786303,"name":"4. Destructive Riot"},{"status":"ACTIVE","sortPriority":5,"id":38247337,"name":"5. On The Bayou"},{"status":"ACTIVE","sortPriority":6,"id":40072523,"name":"6. Chrome Cadillac"},{"status":"ACTIVE","sortPriority":7,"id":39832467,"name":"7. Shian Ned"},{"status":"ACTIVE","sortPriority":8,"id":37495332,"name":"9. Siennas Ace"}],"regulators":["MR_INT"],"venue":"Rockhampton","countryCode":"AU","discountAllowed":true,"timezone":"Australia/Queensland","openDate":"2022-03-02T08:28:00.000Z","version":4382606038,"name":"To Be Placed","eventName":"Rockhampton (AUS) 2nd Mar"},"rc":[{"atb":[[1.25,484.71],[1.3,403.93],[1.35,173.11]],"id":39786303},{"atl":[[2.8,6.73],[4,16.15],[3,12.11],[2.6,7.57],[3.5,9.69]],"id":39786303},{"spn":1.97,"spf":"NaN","id":39786303},{"atb":[[1.6,201.96],[1.55,220.32],[1.65,93.21]],"id":38247337},{"atl":[[3.45,4.94],[3.95,8.21],[4.9,6.21],[2.98,6.11],[5.9,9.89]],"id":38247337},{"spn":2.31,"spf":"NaN","id":38247337},{"atb":[[2.74,69.64],[2.84,65.85],[2.94,31.23]],"id":42256449},{"atl":[[8,1.73],[10,1.34],[20,1.27],[15,1.73],[30,1.67]],"id":42256449},{"spn":5.47,"spf":"NaN","id":42256449},{"atb":[[4,40.39],[4.5,17.3],[3.75,44.06]],"id":40812693},{"atl":[[16,0.8],[34,0.73],[22,0.57],[60,0.4],[120,0.4]],"id":40812693},{"spn":10.25,"spf":"NaN","id":40812693},{"atb":[[4.8,31.88],[5.8,12.62],[5.3,28.18]],"id":37495332},{"atl":[[19,0.67],[90,0.27],[180,0.27],[46,0.54],[28,0.44]],"id":37495332},{"spn":12.4,"spf":"NaN","id":37495332},{"atb":[[1.4,151.47],[1.3,403.93],[1.35,346.22]],"id":39832467},{"atl":[[4.3,14.68],[2.86,6.51],[2.66,7.29],[3.15,11.27],[3.65,9.14]],"id":39832467},{"spn":2.03,"spf":"NaN","id":39832467},{"atb":[[1.01,12117.9],[1.11,550.81],[1.06,2019.65]],"id":40622317},{"atl":[[2.36,8.9],[2.56,15.53],[2.96,24.73],[2.16,10.44],[2.76,13.77]],"id":40622317},{"spn":1.63,"spf":"NaN","id":40622317},{"atb":[[1.7,173.11],[1.75,80.78],[1.65,186.43]],"id":40072523},{"atl":[[4,4.03],[8,6.92],[5,6.05],[6,4.84],[3.5,4.84]],"id":40072523},{"spn":2.62,"spf":"NaN","id":40072523}],"con":true,"img":true}]}
{"op":"mcm","clk":"5353298807","pt":1646212602692,"mc":[{"id":"1.195453779","marketDefinition":{"bspMarket":true,"turnInPlayEnabled":false,"persistenceEnabled":false,"marketBaseRate":7.0,"eventId":"31272499","eventTypeId":"4339","numberOfWinners":3,"bettingType":"ODDS","marketType":"PLACE","marketTime":"2022-03-02T11:09:00.000Z","suspendTime":"2022-03-02T11:09:00.000Z","bspReconciled":false,"complete":true,"inPlay":false,"crossMatching":false,"runnersVoidable":false,"numberOfActiveRunners":8,"betDelay":0,"status":"OPEN","runners":[{"status":"ACTIVE","sortPriority":1,"id":40622317,"name":"1. Velocity Tamika"},{"status":"ACTIVE","sortPriority":2,"id":40812693,"name":"2. Bailing Out"},{"status":"ACTIVE","sortPriority":3,"id":42256449,"name":"3. Black Baccara"},{"status":"ACTIVE","sortPriority":4,"id":39786303,"name":"4. Destructive Riot"},{"status":"ACTIVE","sortPriority":5,"id":38247337,"name":"5. On The Bayou"},{"status":"ACTIVE","sortPriority":6,"id":40072523,"name":"6. Chrome Cadillac"},{"status":"ACTIVE","sortPriority":7,"id":39832467,"name":"7. Shian Ned"},{"status":"ACTIVE","sortPriority":8,"id":37495332,"name":"9. Siennas Ace"}],"regulators":["MR_INT"],"venue":"Rockhampton","countryCode":"AU","discountAllowed":true,"timezone":"Australia/Queensland","openDate":"2022-03-02T08:28:00.000Z","version":4382606038,"name":"To Be Placed","eventName":"Rockhampton (AUS) 2nd Mar"},"rc":[{"atb":[[1.25,483.95],[1.3,403.29],[1.35,172.83]],"id":39786303},{"atl":[[2.8,6.71],[4,16.13],[3,12.09],[2.6,7.56],[3.5,9.67]],"id":39786303},{"spn":1.97,"spf":"NaN","id":39786303},{"atb":[[1.6,201.64],[1.55,219.97],[1.65,93.06]],"id":38247337},{"atl":[[3.45,4.93],[3.95,8.2],[4.9,6.2],[2.98,6.1],[5.9,9.87]],"id":38247337},{"spn":2.31,"spf":"NaN","id":38247337},{"atb":[[2.74,69.53],[2.84,65.75],[2.94,31.18]],"id":42256449},{"atl":[[8,1.72],[10,1.34],[20,1.27],[15,1.72],[30,1.66]],"id":42256449},{"spn":5.47,"spf":"NaN","id":42256449},{"atb":[[4,40.32],[4.5,17.28],[3.75,43.99]],"id":40812693},{"atl":[[16,0.8],[34,0.73],[22,0.57],[60,0.4],[120,0.4]],"id":40812693},{"spn":10.25,"spf":"NaN","id":40812693},{"atb":[[4.8,31.83],[5.8,12.6],[5.3,28.13]],"id":37495332},{"atl":[[19,0.67],[90,0.27],[180,0.27],[46,0.53],[28,0.44]],"id":37495332},{"spn":12.4,"spf":"NaN","id":37495332},{"atb":[[1.4,151.23],[1.3,403.29],[1.35,345.68]],"id":39832467},{"atl":[[4.3,14.66],[2.86,6.5],[2.66,7.28],[3.15,11.25],[3.65,9.12]],"id":39832467},{"spn":2.03,"spf":"NaN","id":39832467},{"atb":[[1.01,12098.75],[1.11,549.94],[1.06,2016.45]],"id":40622317},{"atl":[[2.36,8.89],[2.56,15.51],[2.96,24.69],[2.16,10.43],[2.76,13.75]],"id":40622317},{"spn":1.63,"spf":"NaN","id":40622317},{"atb":[[1.7,172.83],[1.75,80.65],[1.65,186.13]],"id":40072523},{"atl":[[4,4.03],[8,6.91],[5,6.04],[6,4.83],[3.5,4.83]],"id":40072523},{"spn":2.62,"spf":"NaN","id":40072523}],"con":true,"img":true}]}
{"op":"mcm","clk":"5353305229","pt":1646212672893,"mc":[{"id":"1.195453779","rc":[{"atb":[[1.25,483.95],[1.3,403.29],[1.35,172.83]],"id":39786303},{"atl":[[2.8,6.71],[4,16.13],[3,12.09],[2.6,7.56],[3.5,9.67]],"id":39786303},{"atb":[[1.6,0],[1.55,0],[1.65,0]],"id":38247337},{"atl":[[3.45,0],[3.95,0],[4.9,0],[2.98,0],[5.9,0]],"id":38247337},{"atb":[[2.74,0],[2.84,0],[2.94,0]],"id":42256449},{"atl":[[8,0],[10,0],[20,0],[15,0],[30,0]],"id":42256449},{"spn":"NaN","spf":"NaN","id":42256449},{"atb":[[4,0],[4.5,0],[3.75,0]],"id":40812693},{"atl":[[16,0],[34,0],[22,0],[60,0],[120,0]],"id":40812693},{"spn":"NaN","spf":"NaN","id":40812693},{"atb":[[4.8,0],[5.8,0],[5.3,0]],"id":37495332},{"atl":[[19,0],[90,0],[180,0],[46,0],[28,0]],"id":37495332},{"atb":[[1.4,0],[1.3,0],[1.35,0]],"id":39832467},{"atl":[[4.3,0],[2.86,0],[2.66,0],[3.15,0],[3.65,0]],"id":39832467},{"atb":[[1.01,0],[1.11,0],[1.06,0]],"id":40622317},{"atl":[[2.36,0],[2.56,0],[2.96,0],[2.16,0],[2.76,0]],"id":40622317},{"atb":[[1.7,0],[1.75,0],[1.65,0]],"id":40072523},{"atl":[[4,0],[8,0],[5,0],[6,0],[3.5,0]],"id":40072523},{"spn":"NaN","spf":"NaN","id":40072523}],"con":true,"img":false}]}
{"op":"mcm","clk":"5353305895","pt":1646212685147,"mc":[{"id":"1.195453779","rc":[{"atb":[[1.6,201.64],[1.55,219.97],[1.65,93.06]],"id":38247337},{"atl":[[3.45,4.93],[3.95,8.2],[4.9,6.2],[2.98,6.1],[5.9,9.87]],"id":38247337},{"atb":[[2.82,66.47],[2.92,63.01],[3.05,29.51]],"id":42256449},{"atl":[[32,1.55],[10.5,1.27],[21,1.2],[8.2,1.67],[15.5,1.66]],"id":42256449},{"atb":[[4.3,18.33],[3.9,41.71],[3.65,45.65]],"id":40812693},{"atl":[[32,0.77],[21,0.6],[55,0.44],[110,0.44],[15.5,0.83]],"id":40812693},{"atb":[[4.5,34.56],[5,30.24],[5.5,13.44]],"id":37495332},{"atl":[[18.5,0.69],[85,0.28],[170,0.28],[44,0.56],[27,0.46]],"id":37495332},{"atb":[[1.4,151.23],[1.3,403.29],[1.35,345.68]],"id":39832467},{"atl":[[4.3,14.66],[2.86,6.5],[2.66,7.28],[3.15,11.25],[3.65,9.12]],"id":39832467},{"atb":[[1.01,12098.75],[1.11,549.94],[1.06,2016.45]],"id":40622317},{"atl":[[2.36,8.89],[2.56,15.51],[2.96,24.69],[2.16,10.43],[2.76,13.75]],"id":40622317},{"atb":[[1.8,151.23],[1.85,71.17],[1.75,161.31]],"id":40072523},{"atl":[[4.5,3.45],[9,6.04],[5.5,5.37],[7,4.03],[3.75,4.39]],"id":40072523}],"con":true,"img":false}]}
{"op":"mcm","clk":"5353497548","pt":1646215758547,"mc":[{"id":"1.195453779","rc":[{"atb":[[1.28,357.14]],"id":39786303},{"atl":[[3,26.37]],"id":39786303},{"atb":[[1.48,208.33]],"id":38247337},{"atl":[[4.3,12.22]],"id":38247337},{"spn":2.31,"spf":"NaN","id":38247337},{"atb":[[2.98,50.51]],"id":42256449},{"atl":[[13.5,2.96]],"id":42256449},{"spn":5.62,"spf":"NaN","id":42256449},{"atb":[[3.1,47.62]],"id":40812693},{"atl":[[32,2.77]],"id":40812693},{"spn":9.9,"spf":"NaN","id":40812693},{"atb":[[2.96,51.02]],"id":37495332},{"atl":[[90,2]],"id":37495332},{"spn":12.0,"spf":"NaN","id":37495332},{"atb":[[1.41,243.9]],"id":39832467},{"atl":[[3.95,16.42]],"id":39832467},{"spn":2.03,"spf":"NaN","id":39832467},{"atl":[[2.14,10.43]],"id":40622317},{"spn":1.62,"spf":"NaN","id":40622317},{"atb":[[1.74,135.14]],"id":40072523},{"atl":[[6.4,8.8]],"id":40072523},{"spn":2.8,"spf":"NaN","id":40072523}],"con":true,"img":false}]}
{"op":"mcm","clk":"5353499779","pt":1646215785983,"mc":[{"id":"1.195453779","rc":[{"atb":[[3.15,46.51]],"id":37495332}],"con":true,"img":false}]}
{"op":"mcm","clk":"5353499787","pt":1646215786044,"mc":[{"id":"1.195453779","rc":[{"atb":[[2.96,0]],"id":37495332}],"con":true,"img":false}]}
{"op":"mcm","clk":"5353504602","pt":1646215847323,"mc":[{"id":"1.195453779","rc":[{"atb":[[1.36,82.9],[1.31,128.33]],"id":39786303},{"atl":[[2.98,42.11]],"id":39786303},{"spn":1.98,"spf":"NaN","id":39786303},{"atb":[[1.49,79.71],[1.61,70.03]],"id":38247337},{"atl":[[4.2,25.83]],"id":38247337},{"atb":[[3,17.8],[3.15,20.27]],"id":42256449},{"atl":[[17,2.72],[13,3.63]],"id":42256449},{"spn":5.67,"spf":"NaN","id":42256449},{"atb":[[5.3,10.13],[4.7,10.72]],"id":40812693},{"atl":[[36,2.72],[30,2.72]],"id":40812693},{"spn":10.4,"spf":"NaN","id":40812693},{"atb":[[6.2,8.38],[5.5,21.53]],"id":37495332},{"atl":[[42,2.72],[44,3.28]],"id":37495332},{"spn":12.35,"spf":"NaN","id":37495332},{"atb":[[1.45,96.88],[1.42,86.07]],"id":39832467},{"atl":[[3.9,12.46],[3.75,15.03]],"id":39832467},{"spn":2.05,"spf":"NaN","id":39832467},{"atb":[[1.12,482.71]],"id":40622317},{"atl":[[1.97,43.59],[2.14,41.9]],"id":40622317},{"spn":1.54,"spf":"NaN","id":40622317},{"atb":[[1.64,63.15],[1.81,53.82]],"id":40072523},{"atl":[[5.9,7.77],[5.4,9.9]],"id":40072523}],"con":true,"img":false}]}
{"op":"mcm","clk":"5353504619","pt":1646215847531,"mc":[{"id":"1.195453779","rc":[{"atb":[[1.41,0],[1.46,96.89]],"id":39832467},{"atl":[[2.04,87.2],[2.14,31.47]],"id":40622317}],"con":true,"img":false}]}
{"op":"mcm","clk":"5353504636","pt":1646215847737,"mc":[{"id":"1.195453779","rc":[{"atl":[[13,0]],"id":42256449}],"con":true,"img":false}]}
{"op":"mcm","clk":"5353504643","pt":1646215847836,"mc":[{"id":"1.195453779","rc":[{"atl":[[15.5,5.3]],"id":42256449}],"con":true,"img":false}]}
{"op":"mcm","clk":"5353506303","pt":1646215865926,"mc":[{"id":"1.195453779","rc":[{"atl":[[2.98,22.01]],"id":39786303}],"con":true,"img":false}]}
{"op":"mcm","clk":"5353506312","pt":1646215866030,"mc":[{"id":"1.195453779","rc":[{"atl":[[3.35,20.09]],"id":39786303}],"con":true,"img":false}]}
{"op":"mcm","clk":"5353507964","pt":1646215885492,"mc":[{"id":"1.195453779","rc":[{"atb":[[1.61,0]],"id":38247337},{"atb":[[3.15,0]],"id":42256449},{"atb":[[6.2,0]],"id":37495332},{"atb":[[1.45,0]],"id":39832467},{"atb":[[1.12,298.98],[1.15,98.04]],"id":40622317},{"atb":[[1.81,0]],"id":40072523}],"con":true,"img":false}]}
{"op":"mcm","clk":"5353507972","pt":1646215885544,"mc":[{"id":"1.195453779","rc":[{"atb":[[1.66,70.03]],"id":38247337},{"atb":[[3.4,20.27]],"id":42256449},{"atb":[[7.6,8.38]],"id":37495332},{"atb":[[1.47,96.88]],"id":39832467},{"atb":[[1.86,53.82]],"id":40072523}],"con":true,"img":false}]}
{"op":"mcm","clk":"5353507982","pt":1646215885648,"mc":[{"id":"1.195453779","rc":[{"atb":[[1.46,0],[1.43,193.78]],"id":39832467}],"con":true,"img":false}]}
{"op":"mcm","clk":"5353507989","pt":1646215885754,"mc":[{"id":"1.195453779","rc":[{"atb":[[1.43,0],[1.48,96.89]],"id":39832467}],"con":true,"img":false}]}
{"op":"mcm","clk":"5353509426","pt":1646215902084,"mc":[{"id":"1.195453779","rc":[{"atl":[[3.65,12.22]],"id":38247337},{"atl":[[3.6,14.58]],"id":39832467},{"atl":[[1.96,43.6]],"id":40622317}],"con":true,"img":false}]}
{"op":"mcm","clk":"5353509436","pt":1646215902255,"mc":[{"id":"1.195453779","rc":[{"atl":[[4.3,0]],"id":38247337},{"atl":[[3.95,0]],"id":39832467},{"atl":[[2.04,0]],"id":40622317}],"con":true,"img":false}]}
{"op":"mcm","clk":"5353509590","pt":1646215903911,"mc":[{"id":"1.195453779","rc":[{"atb":[[6.6,6.5]],"id":37495332}],"con":true,"img":false}]}
{"op":"mcm","clk":"5353509599","pt":1646215903970,"mc":[{"id":"1.195453779","rc":[{"atl":[[4.2,13.62]],"id":38247337},{"atb":[[5.5,13.44]],"id":37495332},{"atl":[[3.9,0]],"id":39832467},{"atb":[[1.12,0]],"id":40622317},{"atl":[[2.14,0]],"id":40622317}],"con":true,"img":false}]}
{"op":"mcm","clk":"5353509608","pt":1646215904070,"mc":[{"id":"1.195453779","rc":[{"atl":[[4.7,12.2]],"id":38247337},{"atl":[[4.2,12.46]],"id":39832467},{"atb":[[1.13,298.98]],"id":40622317},{"atl":[[1.95,31.47]],"id":40622317}],"con":true,"img":false}]}
{"op":"mcm","clk":"5353511310","pt":1646215923318,"mc":[{"id":"1.195453779","rc":[{"atl":[[3.95,13.48],[3.35,0]],"id":39786303},{"atl":[[5.2,9.29],[4.7,0]],"id":38247337},{"spn":2.32,"spf":"NaN","id":38247337},{"atb":[[2.4,25.43],[3.4,0],[3,0]],"id":42256449},{"spn":5.62,"spf":"NaN","id":42256449},{"atb":[[3.95,14.78],[5.3,0],[3.15,18.46],[4.7,0]],"id":40812693},{"spn":9.9,"spf":"NaN","id":40812693},{"atb":[[3.2,16.55],[4.6,12.1],[7.6,0],[6.6,0]],"id":37495332},{"spn":12.0,"spf":"NaN","id":37495332},{"spn":2.07,"spf":"NaN","id":39832467},{"atl":[[2.54,23.29],[1.95,0]],"id":40622317},{"spn":1.55,"spf":"NaN","id":40622317},{"atl":[[5.9,0],[5.4,0]],"id":40072523},{"spn":2.8,"spf":"NaN","id":40072523}],"con":true,"img":false}]}
{"op":"mcm","clk":"5353511318","pt":1646215923424,"mc":[{"id":"1.195453779","rc":[{"atb":[[3.1,20.27]],"id":42256449},{"atl":[[6.2,17.67]],"id":40072523}],"con":true,"img":false}]}
{"op":"mcm","clk":"5353512389","pt":1646215934356,"mc":[{"id":"1.195453779","rc":[{"atl":[[4,14.31],[3.65,0]],"id":38247337},{"atl":[[3.6,0],[3.95,20.38]],"id":39832467},{"atl":[[2.04,87.2],[1.96,0]],"id":40622317}],"con":true,"img":false}]}
{"op":"mcm","clk":"5353513358","pt":1646215943462,"mc":[{"id":"1.195453779","rc":[{"atb":[[1.36,0]],"id":39786303},{"atl":[[4.2,0]],"id":38247337},{"atb":[[3.1,0]],"id":42256449},{"atl":[[15.5,1.66]],"id":42256449},{"atl":[[30,0]],"id":40812693},{"atl":[[42,0]],"id":37495332},{"atb":[[1.47,0]],"id":39832467},{"atl":[[3.75,0]],"id":39832467},{"atl":[[2.54,0],[1.97,0]],"id":40622317}],"con":true,"img":false}]}
{"op":"mcm","clk":"5353513372","pt":1646215943569,"mc":[{"id":"1.195453779","rc":[{"atb":[[1.38,82.9]],"id":39786303},{"atl":[[3.95,21.82]],"id":38247337},{"atb":[[3,20.27]],"id":42256449},{"atl":[[11,3.63]],"id":42256449},{"atl":[[15,2.72]],"id":40812693},{"atl":[[16.5,2.72]],"id":37495332},{"atb":[[1.43,193.78],[1.49,96.88],[1.48,0]],"id":39832467},{"atl":[[3.9,15.03]],"id":39832467},{"atl":[[2.02,43.59],[2.74,23.29],[2.14,87.72]],"id":40622317}],"con":true,"img":false}]}
{"op":"mcm","clk":"5353513382","pt":1646215943628,"mc":[{"id":"1.195453779","rc":[{"atl":[[2.04,0]],"id":40622317}],"con":true,"img":false}]}
{"op":"mcm","clk":"5353513393","pt":1646215943790,"mc":[{"id":"1.195453779","rc":[{"atl":[[32,0.77],[15,4.72]],"id":40812693},{"atb":[[1.43,0],[1.5,96.89]],"id":39832467},{"atl":[[2.04,87.2],[2.14,0]],"id":40622317}],"con":true,"img":false}]}
{"op":"mcm","clk":"5353515527","pt":1646215965559,"mc":[{"id":"1.195453779","rc":[{"atb":[[1.31,0]],"id":39786303},{"atb":[[1.49,0]],"id":38247337},{"atl":[[17,0]],"id":42256449},{"atl":[[36,0]],"id":40812693},{"atl":[[44,0.56]],"id":37495332},{"atb":[[1.64,0]],"id":40072523}],"con":true,"img":false}]}
{"op":"mcm","clk":"5353515539","pt":1646215965663,"mc":[{"id":"1.195453779","rc":[{"atb":[[1.36,128.33]],"id":39786303},{"atb":[[1.56,79.71]],"id":38247337},{"atl":[[12,2.72]],"id":42256449},{"atl":[[15,7.44]],"id":40812693},{"atl":[[19.5,2.72]],"id":37495332},{"atb":[[1.76,63.15]],"id":40072523}],"con":true,"img":false}]}
{"op":"mcm","clk":"5353517837","pt":1646215987389,"mc":[{"id":"1.195453779","rc":[{"spn":1.99,"spf":"NaN","id":39786303},{"atl":[[15,4.72]],"id":40812693},{"spn":9.65,"spf":"NaN","id":40812693},{"spn":11.0,"spf":"NaN","id":37495332},{"spn":2.08,"spf":"NaN","id":39832467},{"spn":1.58,"spf":"NaN","id":40622317}],"con":true,"img":false}]}
{"op":"mcm","clk":"5353517850","pt":1646215987493,"mc":[{"id":"1.195453779","rc":[{"atl":[[14.5,2.72]],"id":40812693}],"con":true,"img":false}]}
{"op":"mcm","clk":"5353519566","pt":1646216007249,"mc":[{"id":"1.195453779","rc":[{"atb":[[3,0]],"id":42256449},{"atb":[[1.49,0]],"id":39832467},{"atl":[[2.74,0]],"id":40622317}],"con":true,"img":false}]}
{"op":"mcm","clk":"5353519578","pt":1646216007307,"mc":[{"id":"1.195453779","rc":[{"atb":[[3.1,20.27]],"id":42256449},{"atb":[[1.51,96.88]],"id":39832467},{"atl":[[2.54,23.29]],"id":40622317}],"con":true,"img":false}]}
{"op":"mcm","clk":"5353519595","pt":1646216007414,"mc":[{"id":"1.195453779","rc":[{"atb":[[1.43,193.78],[1.5,0]],"id":39832467}],"con":true,"img":false}]}
{"op":"mcm","clk":"5353522812","pt":1646216041881,"mc":[{"id":"1.195453779","rc":[{"atb":[[1.43,0]],"id":39832467}],"con":true,"img":false}]}
{"op":"mcm","clk":"5353522823","pt":1646216041988,"mc":[{"id":"1.195453779","rc":[{"atb":[[1.52,96.89]],"id":39832467}],"con":true,"img":false}]}
{"op":"mcm","clk":"5353529043","pt":1646216085167,"mc":[{"id":"1.195453779","rc":[{"spn":5.65,"spf":"NaN","id":42256449},{"spn":9.4,"spf":"NaN","id":40812693},{"atb":[[1.51,0]],"id":39832467},{"spn":2.09,"spf":"NaN","id":39832467}],"con":true,"img":false}]}
{"op":"mcm","clk":"5353529120","pt":1646216085342,"mc":[{"id":"1.195453779","rc":[{"atb":[[1.53,96.88]],"id":39832467}],"con":true,"img":false}]}
{"op":"mcm","clk":"5353529154","pt":1646216085403,"mc":[{"id":"1.195453779","rc":[{"atb":[[1.43,193.78],[1.52,0]],"id":39832467}],"con":true,"img":false}]}
{"op":"mcm","clk":"5353529213","pt":1646216085624,"mc":[{"id":"1.195453779","rc":[{"atb":[[1.43,0],[1.54,96.89]],"id":39832467}],"con":true,"img":false}]}
{"op":"mcm","clk":"5353542574","pt":1646216143658,"mc":[{"id":"1.195453779","rc":[{"atb":[[1.53,0]],"id":39832467}],"con":true,"img":false}]}
{"op":"mcm","clk":"5353542583","pt":1646216143763,"mc":[{"id":"1.195453779","rc":[{"atb":[[1.43,193.78],[1.55,96.88],[1.54,0]],"id":39832467}],"con":true,"img":false}]}
{"op":"mcm","clk":"5353545207","pt":1646216165087,"mc":[{"id":"1.195453779","rc":[{"atb":[[1.55,0]],"id":39832467},{"spn":2.04,"spf":"NaN","id":39832467}],"con":true,"img":false}]}
{"op":"mcm","clk":"5353545212","pt":1646216165190,"mc":[{"id":"1.195453779","rc":[{"atb":[[1.49,96.88]],"id":39832467}],"con":true,"img":false}]}
{"op":"mcm","clk":"5353546865","pt":1646216176902,"mc":[{"id":"1.195453779","rc":[{"atb":[[1.43,0],[1.5,96.89]],"id":39832467}],"con":true,"img":false}]}
{"op":"mcm","clk":"5353553107","pt":1646216224440,"mc":[{"id":"1.195453779","rc":[{"atb":[[1.49,0]],"id":39832467}],"con":true,"img":false}]}
{"op":"mcm","clk":"5353553122","pt":1646216224544,"mc":[{"id":"1.195453779","rc":[{"atb":[[1.43,193.78],[1.51,96.88]],"id":39832467}],"con":true,"img":false}]}
{"op":"mcm","clk":"5353553133","pt":1646216224648,"mc":[{"id":"1.195453779","rc":[{"atb":[[1.5,0]],"id":39832467}],"con":true,"img":false}]}
{"op":"mcm","clk":"5353553149","pt":1646216224753,"mc":[{"id":"1.195453779","rc":[{"atb":[[1.43,0],[1.52,96.89]],"id":39832467}],"con":true,"img":false}]}
{"op":"mcm","clk":"5353558948","pt":1646216272377,"mc":[{"id":"1.195453779","rc":[{"atb":[[1.51,0]],"id":39832467},{"spn":2.09,"spf":"NaN","id":39832467}],"con":true,"img":false}]}
{"op":"mcm","clk":"5353558967","pt":1646216272478,"mc":[{"id":"1.195453779","rc":[{"atb":[[1.53,96.88]],"id":39832467}],"con":true,"img":false}]}
{"op":"mcm","clk":"5353558978","pt":1646216272584,"mc":[{"id":"1.195453779","rc":[{"atb":[[1.43,193.78],[1.52,0]],"id":39832467}],"con":true,"img":false}]}
{"op":"mcm","clk":"5353560165","pt":1646216283263,"mc":[{"id":"1.195453779","rc":[{"atb":[[1.53,0]],"id":39832467}],"con":true,"img":false}]}
{"op":"mcm","clk":"5353560174","pt":1646216283363,"mc":[{"id":"1.195453779","rc":[{"atb":[[1.49,96.88]],"id":39832467}],"con":true,"img":false}]}
{"op":"mcm","clk":"5353562506","pt":1646216304112,"mc":[{"id":"1.195453779","rc":[{"atb":[[3.1,0]],"id":42256449}],"con":true,"img":false}]}
{"op":"mcm","clk":"5353562514","pt":1646216304206,"mc":[{"id":"1.195453779","rc":[{"atb":[[3,20.27]],"id":42256449}],"con":true,"img":false}]}
{"op":"mcm","clk":"5353562537","pt":1646216304414,"mc":[{"id":"1.195453779","rc":[{"atb":[[1.5,96.89]],"id":39832467}],"con":true,"img":false}]}
{"op":"mcm","clk":"5353562548","pt":1646216304514,"mc":[{"id":"1.195453779","rc":[{"atb":[[1.43,0]],"id":39832467}],"con":true,"img":false}]}
{"op":"mcm","clk":"5353567068","pt":1646216344538,"mc":[{"id":"1.195453779","rc":[{"atb":[[3,0]],"id":42256449},{"spn":5.62,"spf":"NaN","id":42256449},{"spn":2.08,"spf":"NaN","id":39832467}],"con":true,"img":false}]}
{"op":"mcm","clk":"5353567080","pt":1646216344645,"mc":[{"id":"1.195453779","rc":[{"atb":[[3.1,20.27]],"id":42256449}],"con":true,"img":false}]}
{"op":"mcm","clk":"5353569318","pt":1646216366295,"mc":[{"id":"1.195453779","rc":[{"atb":[[1.49,0]],"id":39832467}],"con":true,"img":false}]}
{"op":"mcm","clk":"5353569326","pt":1646216366361,"mc":[{"id":"1.195453779","rc":[{"atb":[[1.51,96.88]],"id":39832467}],"con":true,"img":false}]}
{"op":"mcm","clk":"5353569333","pt":1646216366464,"mc":[{"id":"1.195453779","rc":[{"atb":[[1.43,193.78],[1.5,0]],"id":39832467}],"con":true,"img":false}]}
{"op":"mcm","clk":"5353572581","pt":1646216397428,"mc":[{"id":"1.195453779","rc":[{"atb":[[1.43,0],[1.52,96.89]],"id":39832467}],"con":true,"img":false}]}
{"op":"mcm","clk":"5353576114","pt":1646216432346,"mc":[{"id":"1.195453779","rc":[{"spn":5.65,"spf":"NaN","id":42256449},{"atb":[[1.51,0]],"id":39832467},{"spn":2.09,"spf":"NaN","id":39832467}],"con":true,"img":false}]}
{"op":"mcm","clk":"5353576121","pt":1646216432445,"mc":[{"id":"1.195453779","rc":[{"atb":[[1.53,96.88]],"id":39832467}],"con":true,"img":false}]}
{"op":"mcm","clk":"5353576132","pt":1646216432556,"mc":[{"id":"1.195453779","rc":[{"atb":[[1.43,193.78],[1.52,0]],"id":39832467}],"con":true,"img":false}]}
{"op":"mcm","clk":"5353577151","pt":1646216441260,"mc":[{"id":"1.195453779","rc":[{"atb":[[1.53,0]],"id":39832467}],"con":true,"img":false}]}
{"op":"mcm","clk":"5353577163","pt":1646216441398,"mc":[{"id":"1.195453779","rc":[{"atb":[[1.49,96.88]],"id":39832467}],"con":true,"img":false}]}
{"op":"mcm","clk":"5353579029","pt":1646216462799,"mc":[{"id":"1.195453779","rc":[{"atb":[[1.43,0],[1.5,96.89]],"id":39832467}],"con":true,"img":false}]}
{"op":"mcm","clk":"5353584449","pt":1646216511625,"mc":[{"id":"1.195453779","rc":[{"atb":[[1.49,0]],"id":39832467},{"spn":2.08,"spf":"NaN","id":39832467}],"con":true,"img":false}]}
{"op":"mcm","clk":"5353584459","pt":1646216511729,"mc":[{"id":"1.195453779","rc":[{"atb":[[1.51,96.88]],"id":39832467}],"con":true,"img":false}]}
{"op":"mcm","clk":"5353585475","pt":1646216521006,"mc":[{"id":"1.195453779","rc":[{"atb":[[1.5,0],[1.52,96.89]],"id":39832467}],"con":true,"img":false}]}
{"op":"mcm","clk":"5353593100","pt":1646216577603,"mc":[{"id":"1.195453779","rc":[{"atb":[[1.51,0]],"id":39832467},{"spn":2.09,"spf":"NaN","id":39832467}],"con":true,"img":false}]}
{"op":"mcm","clk":"5353593107","pt":1646216577708,"mc":[{"id":"1.195453779","rc":[{"atb":[[1.53,96.88]],"id":39832467}],"con":true,"img":false}]}
{"op":"mcm","clk":"5353593113","pt":1646216577816,"mc":[{"id":"1.195453779","rc":[{"atb":[[1.43,193.78],[1.52,0]],"id":39832467}],"con":true,"img":false}]}
{"op":"mcm","clk":"5353595397","pt":1646216598345,"mc":[{"id":"1.195453779","rc":[{"atb":[[1.53,0]],"id":39832467}],"con":true,"img":false}]}
{"op":"mcm","clk":"5353595410","pt":1646216598453,"mc":[{"id":"1.195453779","rc":[{"atb":[[1.49,96.88]],"id":39832467}],"con":true,"img":false}]}
{"op":"mcm","clk":"5353596233","pt":1646216606535,"mc":[{"id":"1.195453779","rc":[{"atb":[[1.43,0],[1.5,96.89]],"id":39832467}],"con":true,"img":false}]}
{"op":"mcm","clk":"5353601667","pt":1646216661953,"mc":[{"id":"1.195453779","rc":[{"atb":[[3.15,1.66]],"id":42256449},{"spn":5.67,"spf":"NaN","id":42256449},{"spn":2.08,"spf":"NaN","id":39832467}],"con":true,"img":false}]}
{"op":"mcm","clk":"5353602385","pt":1646216669584,"mc":[{"id":"1.195453779","marketDefinition":{"bspMarket":true,"turnInPlayEnabled":false,"persistenceEnabled":false,"marketBaseRate":7.0,"eventId":"31272499","eventTypeId":"4339","numberOfWinners":3,"bettingType":"ODDS","marketType":"PLACE","marketTime":"2022-03-02T11:09:00.000Z","suspendTime":"2022-03-02T11:09:00.000Z","bspReconciled":false,"complete":true,"inPlay":false,"crossMatching":true,"runnersVoidable":false,"numberOfActiveRunners":8,"betDelay":0,"status":"OPEN","runners":[{"status":"ACTIVE","sortPriority":1,"id":40622317,"name":"1. Velocity Tamika"},{"status":"ACTIVE","sortPriority":2,"id":40812693,"name":"2. Bailing Out"},{"status":"ACTIVE","sortPriority":3,"id":42256449,"name":"3. Black Baccara"},{"status":"ACTIVE","sortPriority":4,"id":39786303,"name":"4. Destructive Riot"},{"status":"ACTIVE","sortPriority":5,"id":38247337,"name":"5. On The Bayou"},{"status":"ACTIVE","sortPriority":6,"id":40072523,"name":"6. Chrome Cadillac"},{"status":"ACTIVE","sortPriority":7,"id":39832467,"name":"7. Shian Ned"},{"status":"ACTIVE","sortPriority":8,"id":37495332,"name":"9. Siennas Ace"}],"regulators":["MR_INT"],"venue":"Rockhampton","countryCode":"AU","discountAllowed":true,"timezone":"Australia/Queensland","openDate":"2022-03-02T08:28:00.000Z","version":4382606038,"name":"To Be Placed","eventName":"Rockhampton (AUS) 2nd Mar"},"rc":[],"con":true,"img":false}]}
{"op":"mcm","clk":"5353607721","pt":1646216728846,"mc":[{"id":"1.195453779","rc":[{"atb":[[1.49,0]],"id":39832467}],"con":true,"img":false}]}
{"op":"mcm","clk":"5353607729","pt":1646216728953,"mc":[{"id":"1.195453779","rc":[{"atb":[[1.43,193.78],[1.51,96.88]],"id":39832467}],"con":true,"img":false}]}
{"op":"mcm","clk":"5353607738","pt":1646216729055,"mc":[{"id":"1.195453779","rc":[{"atb":[[1.5,0]],"id":39832467}],"con":true,"img":false}]}
{"op":"mcm","clk":"5353607748","pt":1646216729160,"mc":[{"id":"1.195453779","rc":[{"atb":[[1.43,0],[1.52,96.89]],"id":39832467}],"con":true,"img":false}]}
{"op":"mcm","clk":"5353611109","pt":1646216769594,"mc":[{"id":"1.195453779","rc":[{"atb":[[3.1,24.24]],"id":42256449}],"con":true,"img":false}]}
{"op":"mcm","clk":"5353611150","pt":1646216769817,"mc":[{"id":"1.195453779","rc":[{"atb":[[1.55,15.15]],"id":39832467}],"con":true,"img":false}]}
{"op":"mcm","clk":"5353611161","pt":1646216769912,"mc":[{"id":"1.195453779","rc":[{"atb":[[1.7,11.91]],"id":38247337}],"con":true,"img":false}]}
{"op":"mcm","clk":"5353611171","pt":1646216770007,"mc":[{"id":"1.195453779","rc":[{"atb":[[1.56,96.89],[1.52,0]],"id":39832467}],"con":true,"img":false}]}
{"op":"mcm","clk":"5353611182","pt":1646216770109,"mc":[{"id":"1.195453779","rc":[{"atb":[[1.41,20.33]],"id":39786303},{"atb":[[1.9,9.26]],"id":40072523}],"con":true,"img":false}]}
{"op":"mcm","clk":"5353613826","pt":1646216795732,"mc":[{"id":"1.195453779","rc":[{"spn":2.0,"spf":"NaN","id":39786303},{"spn":2.34,"spf":"NaN","id":38247337},{"atb":[[1.55,0]],"id":39832467},{"spn":2.11,"spf":"NaN","id":39832467},{"spn":2.82,"spf":"NaN","id":40072523}],"con":true,"img":false}]}
{"op":"mcm","clk":"5353613849","pt":1646216795940,"mc":[{"id":"1.195453779","rc":[{"atb":[[1.56,0],[1.52,192.31]],"id":39832467}],"con":true,"img":false}]}
{"op":"mcm","clk":"5353614369","pt":1646216800955,"mc":[{"id":"1.195453779","rc":[{"atb":[[1.51,0]],"id":39832467}],"con":true,"img":false}]}
{"op":"mcm","clk":"5353614385","pt":1646216801060,"mc":[{"id":"1.195453779","rc":[{"atb":[[1.43,232.56],[1.53,96.88],[1.52,0]],"id":39832467}],"con":true,"img":false}]}
{"op":"mcm","clk":"5353616255","pt":1646216817389,"mc":[{"id":"1.195453779","rc":[{"atb":[[1.28,0],[1.17,345.68]],"id":39786303},{"atl":[[2.88,22.02],[3,12.09]],"id":39786303},{"atb":[[3.6,38.46],[3.15,0]],"id":37495332},{"atl":[[6.4,0],[7.8,9.78]],"id":40072523}],"con":true,"img":false}]}
{"op":"mcm","clk":"5353616350","pt":1646216818385,"mc":[{"id":"1.195453779","rc":[{"atb":[[1.57,14.62]],"id":39832467}],"con":true,"img":false}]}
{"op":"mcm","clk":"5353616853","pt":1646216823225,"mc":[{"id":"1.195453779","rc":[{"atb":[[1.42,186.14],[1.48,0]],"id":38247337},{"atb":[[3.15,25.91],[2.98,0]],"id":42256449},{"atb":[[3.1,0],[3.5,40]],"id":40812693},{"atl":[[15,2.72],[15.5,7.73]],"id":40812693},{"atb":[[1.36,277.78],[1.43,0]],"id":39832467},{"atl":[[3.95,0],[3.5,15.04]],"id":39832467},{"atl":[[2,43.6],[2.04,0]],"id":40622317},{"atb":[[1.8,276.23],[1.74,0]],"id":40072523}],"con":true,"img":false}]}
{"op":"mcm","clk":"5353616874","pt":1646216823383,"mc":[{"id":"1.195453779","rc":[{"atb":[[1.42,0],[1.48,208.33]],"id":38247337},{"atl":[[16,5.44],[15.5,0.83]],"id":40812693}],"con":true,"img":false}]}
{"op":"mcm","clk":"5353617310","pt":1646216827583,"mc":[{"id":"1.195453779","rc":[{"atb":[[1.47,151.23]],"id":39832467}],"con":true,"img":false}]}
{"op":"mcm","clk":"5353617322","pt":1646216827690,"mc":[{"id":"1.195453779","rc":[{"atb":[[1.36,0]],"id":39832467}],"con":true,"img":false}]}
{"op":"mcm","clk":"5353617370","pt":1646216828110,"mc":[{"id":"1.195453779","rc":[{"atb":[[3.95,0],[3.15,0]],"id":40812693},{"atl":[[15,0]],"id":40812693},{"atb":[[1.53,0]],"id":39832467},{"atl":[[6.2,9.9]],"id":40072523}],"con":true,"img":false}]}
{"op":"mcm","clk":"5353617386","pt":1646216828213,"mc":[{"id":"1.195453779","rc":[{"atb":[[4.4,14.78],[2.96,18.46]],"id":40812693},{"atl":[[15.5,3.55]],"id":40812693},{"atb":[[1.49,96.88]],"id":39832467},{"atl":[[6.6,7.77]],"id":40072523}],"con":true,"img":false}]}
{"op":"mcm","clk":"5353619389","pt":1646216848598,"mc":[{"id":"1.195453779","rc":[{"atb":[[3.1,20.27]],"id":42256449},{"atb":[[1.57,0]],"id":39832467}],"con":true,"img":false}]}
{"op":"mcm","clk":"5353619414","pt":1646216848813,"mc":[{"id":"1.195453779","rc":[{"atb":[[1.36,0],[1.38,0]],"id":39786303},{"atb":[[1.56,0]],"id":38247337},{"atl":[[11,0],[12,0]],"id":42256449},{"atl":[[14.5,0],[15.5,0.83]],"id":40812693},{"atl":[[16.5,0],[19.5,0]],"id":37495332},{"atb":[[1.49,0],[1.42,0]],"id":39832467}],"con":true,"img":false}]}
{"op":"mcm","clk":"5353619424","pt":1646216848921,"mc":[{"id":"1.195453779","rc":[{"atb":[[1.36,82.9],[1.31,128.33]],"id":39786303},{"atb":[[1.49,79.71]],"id":38247337},{"atl":[[20,3.63],[27,2.72]],"id":42256449},{"atl":[[16,0],[21,5.6],[44,2.72],[55,3.17]],"id":40812693},{"atl":[[32,2.72],[34,2.72]],"id":37495332},{"atb":[[1.41,329.97],[1.48,96.88],[1.47,0]],"id":39832467}],"con":true,"img":false}]}
{"op":"mcm","clk":"5353619447","pt":1646216849129,"mc":[{"id":"1.195453779","rc":[{"atl":[[32,4],[21,0.6]],"id":40812693},{"atb":[[1.41,86.07],[1.47,212.77]],"id":39832467}],"con":true,"img":false}]}
{"op":"mcm","clk":"5353619837","pt":1646216853018,"mc":[{"id":"1.195453779","rc":[{"atl":[[2.82,22.02],[2.88,0]],"id":39786303}],"con":true,"img":false}]}
{"op":"mcm","clk":"5353619856","pt":1646216853229,"mc":[{"id":"1.195453779","rc":[{"atl":[[2.82,0],[2.74,22.02]],"id":39786303}],"con":true,"img":false}]}
{"op":"mcm","clk":"5353619947","pt":1646216853914,"mc":[{"id":"1.195453779","rc":[{"atb":[[1.7,22.65]],"id":38247337},{"atb":[[3.2,3.42]],"id":42256449},{"atb":[[1.9,17.61]],"id":40072523}],"con":true,"img":false}]}
{"op":"mcm","clk":"5353620329","pt":1646216856818,"mc":[{"id":"1.195453779","rc":[{"atb":[[1.39,19.27]],"id":39786303},{"spn":5.7,"spf":"NaN","id":42256449},{"spn":9.95,"spf":"NaN","id":40812693},{"spn":12.0,"spf":"NaN","id":37495332},{"atb":[[1.51,14.74]],"id":39832467},{"spn":2.08,"spf":"NaN","id":39832467},{"spn":1.57,"spf":"NaN","id":40622317}],"con":true,"img":false}]}
{"op":"mcm","clk":"5353620676","pt":1646216859922,"mc":[{"id":"1.195453779","rc":[{"atb":[[3.15,24.25]],"id":42256449}],"con":true,"img":false}]}
{"op":"mcm","clk":"5353620700","pt":1646216860130,"mc":[{"id":"1.195453779","rc":[{"atb":[[3.25,1.66]],"id":42256449}],"con":true,"img":false}]}
{"op":"mcm","clk":"5353621314","pt":1646216865852,"mc":[{"id":"1.195453779","rc":[{"atl":[[2.98,0]],"id":39786303},{"atb":[[3.1,0]],"id":42256449},{"atl":[[20,0]],"id":42256449},{"atb":[[4.6,0],[6.2,8.38]],"id":37495332},{"atl":[[3.9,0]],"id":39832467},{"atl":[[2.02,0]],"id":40622317}],"con":true,"img":false}]}
{"op":"mcm","clk":"5353621323","pt":1646216865959,"mc":[{"id":"1.195453779","rc":[{"atl":[[2.86,22.01]],"id":39786303},{"atb":[[3.75,20.27]],"id":42256449},{"atl":[[26,3.63]],"id":42256449},{"atl":[[3.45,15.03]],"id":39832467},{"atl":[[2,0],[1.99,43.59],[2.14,87.2]],"id":40622317}],"con":true,"img":false}]}
{"op":"mcm","clk":"5353621721","pt":1646216869834,"mc":[{"id":"1.195453779","rc":[{"atb":[[3.2,0]],"id":42256449}],"con":true,"img":false}]}
{"op":"mcm","clk":"5353621923","pt":1646216871933,"mc":[{"id":"1.195453779","rc":[{"atb":[[3.25,0]],"id":42256449}],"con":true,"img":false}]}
{"op":"mcm","clk":"5353621940","pt":1646216872043,"mc":[{"id":"1.195453779","rc":[{"atb":[[3.8,1.66]],"id":42256449}],"con":true,"img":false}]}
{"op":"mcm","clk":"5353622204","pt":1646216874934,"mc":[{"id":"1.195453779","rc":[{"atl":[[11,2.96],[13.5,0]],"id":42256449}],"con":true,"img":false}]}
{"op":"mcm","clk":"5353622226","pt":1646216875135,"mc":[{"id":"1.195453779","rc":[{"atb":[[1.47,0],[1.52,96.89]],"id":39832467}],"con":true,"img":false}]}
{"op":"mcm","clk":"5353622510","pt":1646216878161,"mc":[{"id":"1.195453779","rc":[{"atb":[[1.51,0]],"id":39832467}],"con":true,"img":false}]}
{"op":"mcm","clk":"5353622573","pt":1646216878738,"mc":[{"id":"1.195453779","rc":[{"atb":[[1.41,0]],"id":39786303}],"con":true,"img":false}]}
{"op":"mcm","clk":"5353622587","pt":1646216878842,"mc":[{"id":"1.195453779","rc":[{"atb":[[3.1,3.96]],"id":42256449}],"con":true,"img":false}]}
{"op":"mcm","clk":"5353622626","pt":1646216879258,"mc":[{"id":"1.195453779","rc":[{"atl":[[2.58,7.56]],"id":39786303}],"con":true,"img":false}]}
{"op":"mcm","clk":"5353622635","pt":1646216879363,"mc":[{"id":"1.195453779","rc":[{"atl":[[2.74,0]],"id":39786303}],"con":true,"img":false}]}
{"op":"mcm","clk":"5353622747","pt":1646216880372,"mc":[{"id":"1.195453779","rc":[{"atb":[[1.49,193.78],[1.52,0]],"id":39832467}],"con":true,"img":false}]}
{"op":"mcm","clk":"5353623024","pt":1646216882845,"mc":[{"id":"1.195453779","rc":[{"atl":[[3.95,0],[3.25,16.24]],"id":39786303},{"atl":[[44,0]],"id":40812693}],"con":true,"img":false}]}
{"op":"mcm","clk":"5353623038","pt":1646216882948,"mc":[{"id":"1.195453779","rc":[{"atl":[[21,3.32]],"id":40812693}],"con":true,"img":false}]}
{"op":"mcm","clk":"5353623049","pt":1646216883050,"mc":[{"id":"1.195453779","rc":[{"atl":[[20,3.33]],"id":40812693}],"con":true,"img":false}]}
{"op":"mcm","clk":"5353623061","pt":1646216883214,"mc":[{"id":"1.195453779","rc":[{"atl":[[32,0.77]],"id":40812693}],"con":true,"img":false}]}
{"op":"mcm","clk":"5353623446","pt":1646216886989,"mc":[{"id":"1.195453779","rc":[{"atb":[[1.52,14.45]],"id":39832467}],"con":true,"img":false}]}
{"op":"mcm","clk":"5353623884","pt":1646216891761,"mc":[{"id":"1.195453779","rc":[{"atl":[[1.98,43.6]],"id":40622317}],"con":true,"img":false}]}
{"op":"mcm","clk":"5353623893","pt":1646216891852,"mc":[{"id":"1.195453779","rc":[{"atl":[[2.14,0]],"id":40622317}],"con":true,"img":false}]}
{"op":"mcm","clk":"5353624115","pt":1646216894061,"mc":[{"id":"1.195453779","rc":[{"atb":[[1.39,40.65]],"id":39786303}],"con":true,"img":false}]}
{"op":"mcm","clk":"5353624480","pt":1646216897964,"mc":[{"id":"1.195453779","rc":[{"atl":[[3.95,35.06],[5.2,0]],"id":38247337},{"atb":[[2.4,0],[3.4,14.83]],"id":42256449},{"atb":[[4.6,11.02],[2.96,0]],"id":40812693},{"atl":[[21,0.6]],"id":40812693},{"atb":[[5.1,8.88],[3.2,0]],"id":37495332},{"atl":[[2.54,0],[2.18,30.4]],"id":40622317}],"con":true,"img":false}]}
{"op":"mcm","clk":"5353624490","pt":1646216898068,"mc":[{"id":"1.195453779","rc":[{"atl":[[26,2.72]],"id":40812693}],"con":true,"img":false}]}
{"op":"mcm","clk":"5353624800","pt":1646216901005,"mc":[{"id":"1.195453779","rc":[{"atb":[[1.49,0],[1.53,96.89]],"id":39832467}],"con":true,"img":false}]}
{"op":"mcm","clk":"5353624935","pt":1646216901987,"mc":[{"id":"1.195453779","rc":[{"atb":[[1.52,0]],"id":39832467}],"con":true,"img":false}]}
{"op":"mcm","clk":"5353624946","pt":1646216902092,"mc":[{"id":"1.195453779","rc":[{"atb":[[1.49,193.78]],"id":39832467}],"con":true,"img":false}]}
{"op":"mcm","clk":"5353624960","pt":1646216902196,"mc":[{"id":"1.195453779","rc":[{"atb":[[1.53,0]],"id":39832467}],"con":true,"img":false}]}
{"op":"mcm","clk":"5353625453","pt":1646216907717,"mc":[{"id":"1.195453779","rc":[{"atb":[[1.52,16.03]],"id":39832467}],"con":true,"img":false}]}
{"op":"mcm","clk":"5353625472","pt":1646216907916,"mc":[{"id":"1.195453779","rc":[{"atb":[[1.49,0],[1.53,96.89]],"id":39832467}],"con":true,"img":false}]}
{"op":"mcm","clk":"5353625952","pt":1646216913190,"mc":[{"id":"1.195453779","rc":[{"atb":[[4.4,0]],"id":40812693},{"atl":[[55,0.44]],"id":40812693},{"atb":[[1.48,0]],"id":39832467},{"atl":[[6.2,0]],"id":40072523}],"con":true,"img":false}]}
{"op":"mcm","clk":"5353625963","pt":1646216913295,"mc":[{"id":"1.195453779","rc":[{"atb":[[5,14.78]],"id":40812693},{"atl":[[27,2.72]],"id":40812693},{"atb":[[1.5,96.88]],"id":39832467},{"atl":[[5.6,9.9]],"id":40072523}],"con":true,"img":false}]}
{"op":"mcm","clk":"5353626294","pt":1646216917020,"mc":[{"id":"1.195453779","rc":[{"spn":1.98,"spf":"NaN","id":39786303},{"spn":6.0,"spf":"NaN","id":42256449},{"spn":10.25,"spf":"NaN","id":40812693},{"spn":12.35,"spf":"NaN","id":37495332},{"atb":[[1.57,13.18]],"id":39832467},{"spn":2.11,"spf":"NaN","id":39832467},{"spn":1.56,"spf":"NaN","id":40622317}],"con":true,"img":false}]}
{"op":"mcm","clk":"5353627297","pt":1646216927820,"mc":[{"id":"1.195453779","rc":[{"atl":[[26,0]],"id":40812693},{"atl":[[1.99,0]],"id":40622317}],"con":true,"img":false}]}
{"op":"mcm","clk":"5353627305","pt":1646216927926,"mc":[{"id":"1.195453779","rc":[{"atl":[[19.5,2.72]],"id":40812693},{"atl":[[1.97,43.59],[2.14,87.2]],"id":40622317}],"con":true,"img":false}]}
{"op":"mcm","clk":"5353627318","pt":1646216928025,"mc":[{"id":"1.195453779","rc":[{"atl":[[1.98,0]],"id":40622317}],"con":true,"img":false}]}
{"op":"mcm","clk":"5353627873","pt":1646216933433,"mc":[{"id":"1.195453779","rc":[{"atb":[[1.58,16.03]],"id":39832467}],"con":true,"img":false}]}
{"op":"mcm","clk":"5353627882","pt":1646216933534,"mc":[{"id":"1.195453779","rc":[{"atb":[[1.53,0]],"id":39832467}],"con":true,"img":false}]}
{"op":"mcm","clk":"5353628041","pt":1646216935155,"mc":[{"id":"1.195453779","rc":[{"atb":[[1.57,0]],"id":39832467}],"con":true,"img":false}]}
{"op":"mcm","clk":"5353628057","pt":1646216935319,"mc":[{"id":"1.195453779","rc":[{"atb":[[1.58,0],[1.53,86.08]],"id":39832467}],"con":true,"img":false}]}
{"op":"mcm","clk":"5353628350","pt":1646216938538,"mc":[{"id":"1.195453779","rc":[{"atb":[[1.52,0]],"id":39832467}],"con":true,"img":false}]}
{"op":"mcm","clk":"5353628527","pt":1646216940479,"mc":[{"id":"1.195453779","rc":[{"atb":[[1.51,172.16],[1.53,0]],"id":39832467}],"con":true,"img":false}]}
{"op":"mcm","clk":"5353628710","pt":1646216942353,"mc":[{"id":"1.195453779","rc":[{"atb":[[1.5,0]],"id":39832467}],"con":true,"img":false}]}
{"op":"mcm","clk":"5353628722","pt":1646216942454,"mc":[{"id":"1.195453779","rc":[{"atb":[[1.52,96.88]],"id":39832467}],"con":true,"img":false}]}
{"op":"mcm","clk":"5353629439","pt":1646216950141,"mc":[{"id":"1.195453779","rc":[{"atb":[[1.55,13.66]],"id":39832467}],"con":true,"img":false}]}
{"op":"mcm","clk":"5353629713","pt":1646216953165,"mc":[{"id":"1.195453779","rc":[{"atl":[[1.96,43.6],[2.14,0]],"id":40622317}],"con":true,"img":false}]}
{"op":"mcm","clk":"5353630886","pt":1646216965582,"mc":[{"id":"1.195453779","rc":[{"atb":[[1.56,96.89],[1.51,0]],"id":39832467}],"con":true,"img":false}]}
{"op":"mcm","clk":"5353630949","pt":1646216966266,"mc":[{"id":"1.195453779","rc":[{"atb":[[1.55,0]],"id":39832467}],"con":true,"img":false}]}
{"op":"mcm","clk":"5353631361","pt":1646216970703,"mc":[{"id":"1.195453779","rc":[{"atb":[[1.56,0],[1.53,188.68]],"id":39832467}],"con":true,"img":false}]}
{"op":"mcm","clk":"5353631540","pt":1646216972994,"mc":[{"id":"1.195453779","rc":[{"atl":[[2.58,0],[2.62,15.12]],"id":39786303},{"atb":[[3.1,47.62],[3.5,0]],"id":40812693},{"atb":[[1.8,151.23],[1.74,134.33]],"id":40072523}],"con":true,"img":false}]}
{"op":"mcm","clk":"5353631941","pt":1646216977326,"mc":[{"id":"1.195453779","rc":[{"spn":1.99,"spf":"NaN","id":39786303},{"atb":[[1.57,13.18]],"id":39832467},{"spn":1.55,"spf":"NaN","id":40622317}],"con":true,"img":false}]}
{"op":"mcm","clk":"5353632578","pt":1646216984501,"mc":[{"id":"1.195453779","rc":[{"atb":[[1.57,27.8]],"id":39832467}],"con":true,"img":false}]}
{"op":"mcm","clk":"5353633130","pt":1646216990411,"mc":[{"id":"1.195453779","rc":[{"atb":[[1.58,96.89]],"id":39832467}],"con":true,"img":false}]}
{"op":"mcm","clk":"5353633140","pt":1646216990515,"mc":[{"id":"1.195453779","rc":[{"atb":[[1.53,0]],"id":39832467}],"con":true,"img":false}]}
{"op":"mcm","clk":"5353633284","pt":1646216992297,"mc":[{"id":"1.195453779","rc":[{"atb":[[1.57,14.62]],"id":39832467}],"con":true,"img":false}]}
{"op":"mcm","clk":"5353633802","pt":1646216998108,"mc":[{"id":"1.195453779","rc":[{"atb":[[1.62,12.12]],"id":39832467}],"con":true,"img":false}]}
{"op":"mcm","clk":"5353634432","pt":1646217004534,"mc":[{"id":"1.195453779","rc":[{"atl":[[2.98,20.09]],"id":39786303},{"atb":[[5.2,10.38]],"id":40812693}],"con":true,"img":false}]}
{"op":"mcm","clk":"5353634444","pt":1646217004645,"mc":[{"id":"1.195453779","rc":[{"atl":[[2.86,0],[3.25,0]],"id":39786303},{"atb":[[5,0]],"id":40812693},{"atb":[[1.52,0]],"id":39832467},{"atl":[[3.45,0]],"id":39832467},{"atl":[[1.97,0]],"id":40622317}],"con":true,"img":false}]}
{"op":"mcm","clk":"5353634460","pt":1646217004746,"mc":[{"id":"1.195453779","rc":[{"atl":[[2.6,29.58]],"id":39786303},{"atb":[[1.47,96.88]],"id":39832467},{"atl":[[3.1,15.03]],"id":39832467},{"atl":[[1.95,43.59]],"id":40622317}],"con":true,"img":false}]}
{"op":"mcm","clk":"5353634479","pt":1646217004854,"mc":[{"id":"1.195453779","rc":[{"atl":[[1.96,0],[2.14,87.2]],"id":40622317}],"con":true,"img":false}]}
{"op":"mcm","clk":"5353634497","pt":1646217005015,"mc":[{"id":"1.195453779","rc":[{"atl":[[1.94,43.6]],"id":40622317}],"con":true,"img":false}]}
{"op":"mcm","clk":"5353634511","pt":1646217005124,"mc":[{"id":"1.195453779","rc":[{"atl":[[2.14,0]],"id":40622317}],"con":true,"img":false}]}
{"op":"mcm","clk":"5353635509","pt":1646217015041,"mc":[{"id":"1.195453779","rc":[{"atb":[[1.58,0],[1.62,26.74]],"id":39832467}],"con":true,"img":false}]}
{"op":"mcm","clk":"5353635604","pt":1646217015855,"mc":[{"id":"1.195453779","rc":[{"atb":[[1.57,0]],"id":39832467}],"con":true,"img":false}]}
{"op":"mcm","clk":"5353635657","pt":1646217016334,"mc":[{"id":"1.195453779","rc":[{"atb":[[1.62,14.62]],"id":39832467}],"con":true,"img":false}]}
{"op":"mcm","clk":"5353636025","pt":1646217020166,"mc":[{"id":"1.195453779","rc":[{"atb":[[1.62,0],[1.48,96.89]],"id":39832467}],"con":true,"img":false}]}
{"op":"mcm","clk":"5353636327","pt":1646217022967,"mc":[{"id":"1.195453779","rc":[{"atl":[[27,0]],"id":40812693},{"atl":[[3.1,0]],"id":39832467}],"con":true,"img":false}]}
{"op":"mcm","clk":"5353636335","pt":1646217023058,"mc":[{"id":"1.195453779","rc":[{"atl":[[30,2.72]],"id":40812693},{"atl":[[3.45,15.03]],"id":39832467}],"con":true,"img":false}]}
{"op":"mcm","clk":"5353636829","pt":1646217028256,"mc":[{"id":"1.195453779","rc":[{"atb":[[1.51,14.74]],"id":39832467}],"con":true,"img":false}]}
{"op":"mcm","clk":"5353638052","pt":1646217040757,"mc":[{"id":"1.195453779","rc":[{"spn":10.35,"spf":"NaN","id":40812693},{"atb":[[1.47,0]],"id":39832467},{"spn":2.08,"spf":"NaN","id":39832467},{"spn":1.54,"spf":"NaN","id":40622317}],"con":true,"img":false}]}
{"op":"mcm","clk":"5353638064","pt":1646217040861,"mc":[{"id":"1.195453779","rc":[{"atb":[[1.49,96.88]],"id":39832467}],"con":true,"img":false}]}
{"op":"mcm","clk":"5353638291","pt":1646217043266,"mc":[{"id":"1.195453779","rc":[{"atb":[[1.51,0]],"id":39832467}],"con":true,"img":false}]}
{"op":"mcm","clk":"5353638421","pt":1646217044463,"mc":[{"id":"1.195453779","rc":[{"atb":[[1.5,96.89],[1.48,0]],"id":39832467}],"con":true,"img":false}]}
{"op":"mcm","clk":"5353639152","pt":1646217052388,"mc":[{"id":"1.195453779","rc":[{"atb":[[1.53,14.18]],"id":39832467}],"con":true,"img":false}]}
{"op":"mcm","clk":"5353639169","pt":1646217052595,"mc":[{"id":"1.195453779","rc":[{"atb":[[1.54,96.89],[1.5,0]],"id":39832467}],"con":true,"img":false}]}
{"op":"mcm","clk":"5353639419","pt":1646217055287,"mc":[{"id":"1.195453779","rc":[{"atb":[[1.53,0]],"id":39832467}],"con":true,"img":false}]}
{"op":"mcm","clk":"5353639432","pt":1646217055393,"mc":[{"id":"1.195453779","rc":[{"atb":[[1.54,0],[1.5,193.78]],"id":39832467}],"con":true,"img":false}]}
{"op":"mcm","clk":"5353639682","pt":1646217058382,"mc":[{"id":"1.195453779","rc":[{"atl":[[1.95,0]],"id":40622317}],"con":true,"img":false}]}
{"op":"mcm","clk":"5353639693","pt":1646217058482,"mc":[{"id":"1.195453779","rc":[{"atl":[[1.93,43.59],[2.14,87.2]],"id":40622317}],"con":true,"img":false}]}
{"op":"mcm","clk":"5353639703","pt":1646217058585,"mc":[{"id":"1.195453779","rc":[{"atl":[[1.92,43.6],[1.94,0]],"id":40622317}],"con":true,"img":false}]}
{"op":"mcm","clk":"5353639719","pt":1646217058690,"mc":[{"id":"1.195453779","rc":[{"atl":[[2.14,0]],"id":40622317}],"con":true,"img":false}]}
{"op":"mcm","clk":"5353640160","pt":1646217064292,"mc":[{"id":"1.195453779","rc":[{"atb":[[1.53,14.18]],"id":39832467}],"con":true,"img":false}]}
{"op":"mcm","clk":"5353640217","pt":1646217064915,"mc":[{"id":"1.195453779","rc":[{"atb":[[1.54,96.89],[1.5,0]],"id":39832467}],"con":true,"img":false}]}
{"op":"mcm","clk":"5353640480","pt":1646217067418,"mc":[{"id":"1.195453779","rc":[{"atb":[[1.53,0]],"id":39832467}],"con":true,"img":false}]}
{"op":"mcm","clk":"5353640503","pt":1646217067625,"mc":[{"id":"1.195453779","rc":[{"atb":[[1.54,0],[1.5,193.78]],"id":39832467}],"con":true,"img":false}]}
{"op":"mcm","clk":"5353641227","pt":1646217074886,"mc":[{"id":"1.195453779","rc":[{"atl":[[2.98,0]],"id":39786303},{"atl":[[30,0]],"id":40812693}],"con":true,"img":false}]}
{"op":"mcm","clk":"5353641238","pt":1646217074992,"mc":[{"id":"1.195453779","rc":[{"atl":[[3.2,20.09]],"id":39786303},{"atl":[[32,3.5]],"id":40812693}],"con":true,"img":false}]}
{"op":"mcm","clk":"5353641371","pt":1646217076304,"mc":[{"id":"1.195453779","rc":[{"atb":[[1.53,14.18]],"id":39832467}],"con":true,"img":false}]}
{"op":"mcm","clk":"5353642708","pt":1646217090307,"mc":[{"id":"1.195453779","rc":[{"atl":[[2.6,7.56]],"id":39786303},{"atb":[[1.49,0]],"id":39832467}],"con":true,"img":false}]}
{"op":"mcm","clk":"5353642717","pt":1646217090411,"mc":[{"id":"1.195453779","rc":[{"atl":[[2.94,22.01]],"id":39786303},{"atb":[[1.51,96.88]],"id":39832467}],"con":true,"img":false}]}
{"op":"mcm","clk":"5353642797","pt":1646217091409,"mc":[{"id":"1.195453779","rc":[{"atb":[[1.54,96.89]],"id":39832467}],"con":true,"img":false}]}
{"op":"mcm","clk":"5353642810","pt":1646217091517,"mc":[{"id":"1.195453779","rc":[{"atb":[[1.5,0]],"id":39832467}],"con":true,"img":false}]}
{"op":"mcm","clk":"5353642973","pt":1646217093353,"mc":[{"id":"1.195453779","rc":[{"atb":[[1.53,0]],"id":39832467}],"con":true,"img":false}]}
{"op":"mcm","clk":"5353643241","pt":1646217096541,"mc":[{"id":"1.195453779","rc":[{"atb":[[1.52,192.31]],"id":39832467}],"con":true,"img":false}]}
{"op":"mcm","clk":"5353643251","pt":1646217096645,"mc":[{"id":"1.195453779","rc":[{"atb":[[1.54,0]],"id":39832467}],"con":true,"img":false}]}
{"op":"mcm","clk":"5353643870","pt":1646217103432,"mc":[{"id":"1.195453779","rc":[{"atb":[[1.55,13.66]],"id":39832467},{"spn":2.1,"spf":"NaN","id":39832467},{"spn":1.53,"spf":"NaN","id":40622317}],"con":true,"img":false}]}
{"op":"mcm","clk":"5353643999","pt":1646217104946,"mc":[{"id":"1.195453779","rc":[{"atl":[[1.93,0]],"id":40622317}],"con":true,"img":false}]}
{"op":"mcm","clk":"5353644006","pt":1646217105051,"mc":[{"id":"1.195453779","rc":[{"atl":[[1.92,0],[1.91,43.59],[2.14,87.2]],"id":40622317}],"con":true,"img":false}]}
{"op":"mcm","clk":"5353644857","pt":1646217115072,"mc":[{"id":"1.195453779","rc":[{"atb":[[1.56,96.89],[1.52,0]],"id":39832467}],"con":true,"img":false}]}
{"op":"mcm","clk":"5353644903","pt":1646217115543,"mc":[{"id":"1.195453779","rc":[{"atb":[[1.55,0]],"id":39832467}],"con":true,"img":false}]}
{"op":"mcm","clk":"5353645337","pt":1646217120260,"mc":[{"id":"1.195453779","rc":[{"atb":[[1.56,0],[1.52,192.31]],"id":39832467}],"con":true,"img":false}]}
{"op":"mcm","clk":"5353645361","pt":1646217120569,"mc":[{"id":"1.195453779","rc":[{"atl":[[32,0.77]],"id":40812693},{"atl":[[4.2,0]],"id":39832467}],"con":true,"img":false}]}
{"op":"mcm","clk":"5353645373","pt":1646217120671,"mc":[{"id":"1.195453779","rc":[{"atl":[[34,2.72]],"id":40812693},{"atl":[[3.45,27.5]],"id":39832467}],"con":true,"img":false}]}
{"op":"mcm","clk":"5353645962","pt":1646217127377,"mc":[{"id":"1.195453779","rc":[{"atb":[[1.55,13.66]],"id":39832467}],"con":true,"img":false}]}
{"op":"mcm","clk":"5353646052","pt":1646217128573,"mc":[{"id":"1.195453779","rc":[{"atl":[[1.9,43.6],[2.14,0]],"id":40622317}],"con":true,"img":false}]}
{"op":"mcm","clk":"5353646579","pt":1646217134389,"mc":[{"id":"1.195453779","rc":[{"atl":[[2.94,0]],"id":39786303},{"atb":[[1.51,0]],"id":39832467}],"con":true,"img":false}]}
{"op":"mcm","clk":"5353646588","pt":1646217134487,"mc":[{"id":"1.195453779","rc":[{"atl":[[2.6,29.58]],"id":39786303},{"atb":[[1.53,96.88]],"id":39832467}],"con":true,"img":false}]}
{"op":"mcm","clk":"5353646781","pt":1646217136682,"mc":[{"id":"1.195453779","rc":[{"atb":[[1.55,0]],"id":39832467}],"con":true,"img":false}]}
{"op":"mcm","clk":"5353647380","pt":1646217143607,"mc":[{"id":"1.195453779","rc":[{"atb":[[1.54,96.89]],"id":39832467}],"con":true,"img":false}]}
{"op":"mcm","clk":"5353647392","pt":1646217143713,"mc":[{"id":"1.195453779","rc":[{"atb":[[1.57,13.18],[1.52,0]],"id":39832467}],"con":true,"img":false}]}
{"op":"mcm","clk":"5353647554","pt":1646217145498,"mc":[{"id":"1.195453779","rc":[{"atb":[[1.57,0]],"id":39832467}],"con":true,"img":false}]}
{"op":"mcm","clk":"5353647868","pt":1646217148892,"mc":[{"id":"1.195453779","rc":[{"atl":[[2.6,7.56]],"id":39786303}],"con":true,"img":false}]}
{"op":"mcm","clk":"5353647874","pt":1646217148994,"mc":[{"id":"1.195453779","rc":[{"atl":[[2.92,22.01]],"id":39786303}],"con":true,"img":false}]}
{"op":"mcm","clk":"5353648196","pt":1646217152517,"mc":[{"id":"1.195453779","rc":[{"atb":[[1.58,12.96]],"id":39832467}],"con":true,"img":false}]}
{"op":"mcm","clk":"5353649145","pt":1646217163231,"mc":[{"id":"1.195453779","rc":[{"atl":[[3.45,15.03]],"id":39832467},{"atl":[[1.91,0]],"id":40622317},{"atl":[[6.6,0]],"id":40072523}],"con":true,"img":false}]}
{"op":"mcm","clk":"5353649153","pt":1646217163334,"mc":[{"id":"1.195453779","rc":[{"atl":[[4,12.46]],"id":39832467},{"atl":[[1.89,43.59],[2.14,87.2]],"id":40622317},{"atl":[[6,7.77]],"id":40072523}],"con":true,"img":false}]}
{"op":"mcm","clk":"5353649162","pt":1646217163439,"mc":[{"id":"1.195453779","rc":[{"spn":2.12,"spf":"NaN","id":39832467},{"atl":[[1.9,0]],"id":40622317},{"spn":1.52,"spf":"NaN","id":40622317}],"con":true,"img":false}]}
{"op":"mcm","clk":"5353649464","pt":1646217166731,"mc":[{"id":"1.195453779","rc":[{"atb":[[1.59,96.89],[1.54,0]],"id":39832467}],"con":true,"img":false}]}
{"op":"mcm","clk":"5353649718","pt":1646217169550,"mc":[{"id":"1.195453779","rc":[{"atb":[[1.58,0]],"id":39832467}],"con":true,"img":false}]}
{"op":"mcm","clk":"5353649918","pt":1646217171838,"mc":[{"id":"1.195453779","rc":[{"atb":[[1.59,0],[1.54,185.19]],"id":39832467}],"con":true,"img":false}]}
{"op":"mcm","clk":"5353650498","pt":1646217178639,"mc":[{"id":"1.195453779","rc":[{"atb":[[1.58,12.96]],"id":39832467}],"con":true,"img":false}]}
{"op":"mcm","clk":"5353650596","pt":1646217179629,"mc":[{"id":"1.195453779","rc":[{"atb":[[1.53,0]],"id":39832467}],"con":true,"img":false}]}
{"op":"mcm","clk":"5353650606","pt":1646217179735,"mc":[{"id":"1.195453779","rc":[{"atb":[[1.55,96.88]],"id":39832467}],"con":true,"img":false}]}
{"op":"mcm","clk":"5353650788","pt":1646217181874,"mc":[{"id":"1.195453779","rc":[{"atb":[[1.58,0]],"id":39832467}],"con":true,"img":false}]}
{"op":"mcm","clk":"5353651186","pt":1646217186276,"mc":[{"id":"1.195453779","rc":[{"atl":[[1.9,87.2]],"id":40622317}],"con":true,"img":false}]}
{"op":"mcm","clk":"5353651193","pt":1646217186380,"mc":[{"id":"1.195453779","rc":[{"atl":[[2.14,0]],"id":40622317}],"con":true,"img":false}]}
{"op":"mcm","clk":"5353651333","pt":1646217187848,"mc":[{"id":"1.195453779","rc":[{"atb":[[1.59,12.74]],"id":39832467}],"con":true,"img":false}]}
{"op":"mcm","clk":"5353651482","pt":1646217189566,"mc":[{"id":"1.195453779","rc":[{"atb":[[1.6,96.89]],"id":39832467}],"con":true,"img":false}]}
{"op":"mcm","clk":"5353651492","pt":1646217189671,"mc":[{"id":"1.195453779","rc":[{"atb":[[1.54,0]],"id":39832467}],"con":true,"img":false}]}
{"op":"mcm","clk":"5353651613","pt":1646217190987,"mc":[{"id":"1.195453779","rc":[{"atb":[[1.59,0]],"id":39832467}],"con":true,"img":false}]}
{"op":"mcm","clk":"5353651636","pt":1646217191157,"mc":[{"id":"1.195453779","rc":[{"atb":[[1.56,178.57],[1.6,0]],"id":39832467}],"con":true,"img":false}]}
{"op":"mcm","clk":"5353652413","pt":1646217199857,"mc":[{"id":"1.195453779","rc":[{"atb":[[1.6,12.53]],"id":39832467}],"con":true,"img":false}]}
{"op":"mcm","clk":"5353652425","pt":1646217199957,"mc":[{"id":"1.195453779","rc":[{"atb":[[1.61,96.89]],"id":39832467}],"con":true,"img":false}]}
{"op":"mcm","clk":"5353652434","pt":1646217200063,"mc":[{"id":"1.195453779","rc":[{"atb":[[1.56,0]],"id":39832467}],"con":true,"img":false}]}
{"op":"mcm","clk":"5353652783","pt":1646217203787,"mc":[{"id":"1.195453779","rc":[{"atb":[[1.6,0]],"id":39832467}],"con":true,"img":false}]}
{"op":"mcm","clk":"5353652803","pt":1646217203995,"mc":[{"id":"1.195453779","rc":[{"atb":[[1.56,178.57],[1.61,0]],"id":39832467}],"con":true,"img":false}]}
{"op":"mcm","clk":"5353653349","pt":1646217210268,"mc":[{"id":"1.195453779","rc":[{"atl":[[3.9,13.48]],"id":39786303},{"atl":[[5.1,9.52]],"id":38247337},{"atb":[[2.42,25.07]],"id":42256449},{"atb":[[3.15,18.46]],"id":40812693},{"atb":[[4.6,12.1],[3,18.21]],"id":37495332},{"atl":[[2.74,20.62]],"id":40622317}],"con":true,"img":false}]}
{"op":"mcm","clk":"5353653357","pt":1646217210368,"mc":[{"id":"1.195453779","rc":[{"atl":[[2.92,0],[3.2,0]],"id":39786303},{"atl":[[3.95,21.82]],"id":38247337},{"atb":[[3.4,0],[3.75,0]],"id":42256449},{"atb":[[4.6,0],[5.2,0]],"id":40812693},{"atb":[[5.1,0],[6.2,0]],"id":37495332},{"atb":[[1.55,0]],"id":39832467},{"atl":[[4,0]],"id":39832467},{"atl":[[2.18,0]],"id":40622317}],"con":true,"img":false}]}
{"op":"mcm","clk":"5353653365","pt":1646217210472,"mc":[{"id":"1.195453779","rc":[{"atl":[[3.55,22.01]],"id":39786303},{"atb":[[3.2,20.27]],"id":42256449},{"atb":[[4.4,10.38]],"id":40812693},{"atb":[[1.42,238.1],[1.51,96.88]],"id":39832467},{"atl":[[4.2,12.46]],"id":39832467}],"con":true,"img":false}]}
{"op":"mcm","clk":"5353653372","pt":1646217210581,"mc":[{"id":"1.195453779","rc":[{"atb":[[1.56,0]],"id":39832467}],"con":true,"img":false}]}
{"op":"mcm","clk":"5353654062","pt":1646217217800,"mc":[{"id":"1.195453779","rc":[{"atb":[[3.2,23.7]],"id":42256449},{"atb":[[1.54,13.92]],"id":39832467}],"con":true,"img":false}]}
{"op":"mcm","clk":"5353654094","pt":1646217218112,"mc":[{"id":"1.195453779","rc":[{"atb":[[3.8,0]],"id":42256449}],"con":true,"img":false}]}
{"op":"mcm","clk":"5353654110","pt":1646217218283,"mc":[{"id":"1.195453779","rc":[{"atb":[[3.15,0],[3.25,1.66],[2.98,50.51]],"id":42256449}],"con":true,"img":false}]}
{"op":"mcm","clk":"5353654361","pt":1646217220890,"mc":[{"id":"1.195453779","rc":[{"atb":[[3.2,20.27]],"id":42256449}],"con":true,"img":false}]}
{"op":"mcm","clk":"5353654970","pt":1646217226527,"mc":[{"id":"1.195453779","rc":[{"spn":5.72,"spf":"NaN","id":42256449},{"spn":9.95,"spf":"NaN","id":40812693},{"spn":12.0,"spf":"NaN","id":37495332},{"atb":[[1.55,96.89],[1.42,0]],"id":39832467},{"spn":2.1,"spf":"NaN","id":39832467}],"con":true,"img":false}]}
{"op":"mcm","clk":"5353655043","pt":1646217227206,"mc":[{"id":"1.195453779","rc":[{"atb":[[1.36,0]],"id":39786303},{"atb":[[3.2,0],[3.1,7.54]],"id":42256449},{"atl":[[26,0]],"id":42256449},{"atl":[[19.5,0]],"id":40812693},{"atl":[[32,0]],"id":37495332}],"con":true,"img":false}]}
{"op":"mcm","clk":"5353655054","pt":1646217227311,"mc":[{"id":"1.195453779","rc":[{"atb":[[1.38,82.9]],"id":39786303},{"atb":[[3.1,27.82]],"id":42256449},{"atl":[[11,6.59]],"id":42256449},{"atl":[[14,2.72]],"id":40812693},{"atl":[[16.5,2.72]],"id":37495332},{"atb":[[1.54,0]],"id":39832467}],"con":true,"img":false}]}
{"op":"mcm","clk":"5353655065","pt":1646217227415,"mc":[{"id":"1.195453779","rc":[{"atl":[[14,5.44]],"id":40812693}],"con":true,"img":false}]}
{"op":"mcm","clk":"5353655076","pt":1646217227518,"mc":[{"id":"1.195453779","rc":[{"atl":[[20,0]],"id":40812693}],"con":true,"img":false}]}
{"op":"mcm","clk":"5353655336","pt":1646217230202,"mc":[{"id":"1.195453779","rc":[{"atb":[[1.39,21.37]],"id":39786303},{"atb":[[3.1,24.24]],"id":42256449}],"con":true,"img":false}]}
{"op":"mcm","clk":"5353655490","pt":1646217231711,"mc":[{"id":"1.195453779","rc":[{"atb":[[1.55,0],[1.52,192.31]],"id":39832467}],"con":true,"img":false}]}
{"op":"mcm","clk":"5353655520","pt":1646217232025,"mc":[{"id":"1.195453779","rc":[{"atb":[[3.25,0]],"id":42256449}],"con":true,"img":false}]}
{"op":"mcm","clk":"5353655533","pt":1646217232234,"mc":[{"id":"1.195453779","rc":[{"atb":[[3.15,1.66]],"id":42256449}],"con":true,"img":false}]}
{"op":"mcm","clk":"5353655807","pt":1646217235237,"mc":[{"id":"1.195453779","rc":[{"atb":[[1.41,18.33]],"id":39786303},{"atb":[[3.15,5.16]],"id":42256449}],"con":true,"img":false}]}
{"op":"mcm","clk":"5353656082","pt":1646217238226,"mc":[{"id":"1.195453779","rc":[{"atb":[[1.55,13.66]],"id":39832467}],"con":true,"img":false}]}
{"op":"mcm","clk":"5353656457","pt":1646217242024,"mc":[{"id":"1.195453779","rc":[{"atl":[[2.88,15.12],[2.62,0]],"id":39786303},{"atl":[[14,2.72],[15,7.14]],"id":40812693},{"atl":[[3.95,20.38],[3.5,0]],"id":39832467},{"atl":[[2.04,96.15],[1.9,0]],"id":40622317}],"con":true,"img":false}]}
{"op":"mcm","clk":"5353656710","pt":1646217244748,"mc":[{"id":"1.195453779","rc":[{"atb":[[1.38,0]],"id":39786303},{"atl":[[11,2.96]],"id":42256449},{"atl":[[14,0]],"id":40812693},{"atl":[[16.5,0]],"id":37495332},{"atb":[[1.51,0]],"id":39832467},{"atl":[[1.89,0]],"id":40622317}],"con":true,"img":false}]}
{"op":"mcm","clk":"5353656719","pt":1646217244857,"mc":[{"id":"1.195453779","rc":[{"atb":[[1.36,82.9]],"id":39786303},{"atl":[[26,3.63]],"id":42256449},{"atl":[[18,2.72]],"id":40812693},{"atl":[[32,2.72]],"id":37495332},{"atb":[[1.53,96.88]],"id":39832467},{"atl":[[2.02,43.59]],"id":40622317}],"con":true,"img":false}]}
{"op":"mcm","clk":"5353656728","pt":1646217244918,"mc":[{"id":"1.195453779","rc":[{"atl":[[21,5.6],[15,0]],"id":40812693},{"atl":[[2.04,0],[2.14,87.72]],"id":40622317}],"con":true,"img":false}]}
{"op":"mcm","clk":"5353656751","pt":1646217245127,"mc":[{"id":"1.195453779","rc":[{"atl":[[2.04,87.2],[2.14,0]],"id":40622317}],"con":true,"img":false}]}
{"op":"mcm","clk":"5353656985","pt":1646217247437,"mc":[{"id":"1.195453779","rc":[{"atb":[[1.41,0]],"id":39786303},{"atb":[[1.55,0]],"id":39832467}],"con":true,"img":false}]}
{"op":"mcm","clk":"5353657237","pt":1646217249644,"mc":[{"id":"1.195453779","rc":[{"atl":[[17.5,2.72],[21,0.6]],"id":40812693}],"con":true,"img":false}]}
{"op":"mcm","clk":"5353657578","pt":1646217253351,"mc":[{"id":"1.195453779","rc":[{"atb":[[1.39,40.65]],"id":39786303},{"atb":[[1.57,13.18]],"id":39832467}],"con":true,"img":false}]}
{"op":"mcm","clk":"5353657636","pt":1646217253935,"mc":[{"id":"1.195453779","rc":[{"atb":[[1.58,96.89],[1.52,0]],"id":39832467}],"con":true,"img":false}]}
{"op":"mcm","clk":"5353657852","pt":1646217256376,"mc":[{"id":"1.195453779","rc":[{"atb":[[1.57,0]],"id":39832467}],"con":true,"img":false}]}
{"op":"mcm","clk":"5353657869","pt":1646217256538,"mc":[{"id":"1.195453779","rc":[{"atb":[[1.58,0],[1.54,185.19]],"id":39832467}],"con":true,"img":false}]}
{"op":"mcm","clk":"5353658174","pt":1646217259976,"mc":[{"id":"1.195453779","rc":[{"atl":[[3.55,0]],"id":39786303},{"atb":[[3.1,3.96]],"id":42256449},{"atl":[[18,0]],"id":40812693},{"atb":[[4.6,0]],"id":37495332}],"con":true,"img":false}]}
{"op":"mcm","clk":"5353658181","pt":1646217260079,"mc":[{"id":"1.195453779","rc":[{"atl":[[2.92,22.01]],"id":39786303},{"atb":[[3.75,20.27]],"id":42256449},{"atl":[[30,2.72]],"id":40812693},{"atb":[[6,12.1]],"id":37495332}],"con":true,"img":false}]}
{"op":"mcm","clk":"5353658191","pt":1646217260185,"mc":[{"id":"1.195453779","rc":[{"atl":[[17.5,0],[21,4.15]],"id":40812693}],"con":true,"img":false}]}
{"op":"mcm","clk":"5353658387","pt":1646217262380,"mc":[{"id":"1.195453779","rc":[{"atb":[[3.15,1.66]],"id":42256449}],"con":true,"img":false}]}
{"op":"mcm","clk":"5353658667","pt":1646217265266,"mc":[{"id":"1.195453779","rc":[{"atl":[[21,0.6],[29,3.57]],"id":40812693},{"atb":[[1.58,12.96]],"id":39832467}],"con":true,"img":false}]}
{"op":"mcm","clk":"5353659515","pt":1646217274960,"mc":[{"id":"1.195453779","rc":[{"atb":[[3.15,0]],"id":42256449}],"con":true,"img":false}]}
{"op":"mcm","clk":"5353659530","pt":1646217275163,"mc":[{"id":"1.195453779","rc":[{"atb":[[3.8,1.66]],"id":42256449}],"con":true,"img":false}]}
{"op":"mcm","clk":"5353659880","pt":1646217278588,"mc":[{"id":"1.195453779","rc":[{"atb":[[1.59,96.89],[1.54,0]],"id":39832467}],"con":true,"img":false}]}
{"op":"mcm","clk":"5353660046","pt":1646217280378,"mc":[{"id":"1.195453779","rc":[{"atb":[[1.58,0]],"id":39832467}],"con":true,"img":false}]}
{"op":"mcm","clk":"5353660058","pt":1646217280484,"mc":[{"id":"1.195453779","rc":[{"atb":[[1.54,185.19]],"id":39832467}],"con":true,"img":false}]}
{"op":"mcm","clk":"5353660064","pt":1646217280588,"mc":[{"id":"1.195453779","rc":[{"atb":[[1.59,0]],"id":39832467}],"con":true,"img":false}]}
{"op":"mcm","clk":"5353660991","pt":1646217290427,"mc":[{"id":"1.195453779","rc":[{"spn":6.0,"spf":"NaN","id":42256449},{"spn":12.25,"spf":"NaN","id":37495332},{"atb":[[1.58,12.96]],"id":39832467},{"spn":2.12,"spf":"NaN","id":39832467},{"spn":1.58,"spf":"NaN","id":40622317}],"con":true,"img":false}]}
{"op":"mcm","clk":"5353661011","pt":1646217290586,"mc":[{"id":"1.195453779","rc":[{"atb":[[1.59,96.89],[1.54,0]],"id":39832467}],"con":true,"img":false}]}
{"op":"mcm","clk":"5353661097","pt":1646217291415,"mc":[{"id":"1.195453779","rc":[{"atl":[[2.92,0],[3.25,16.24],[3.9,0]],"id":39786303},{"atl":[[5.1,0],[3.95,35.06]],"id":38247337},{"atb":[[2.42,0],[3.4,14.83]],"id":42256449},{"atb":[[3.95,13.45],[3.15,0]],"id":40812693},{"atl":[[30,0]],"id":40812693},{"atb":[[5.3,8.88],[3,0]],"id":37495332},{"atb":[[1.53,0]],"id":39832467},{"atl":[[4.2,0]],"id":39832467},{"atl":[[2.02,78.77],[2.74,0]],"id":40622317}],"con":true,"img":false}]}
{"op":"mcm","clk":"5353661105","pt":1646217291518,"mc":[{"id":"1.195453779","rc":[{"atl":[[2.86,22.01]],"id":39786303},{"atl":[[21,3.32]],"id":40812693},{"atb":[[1.55,96.88]],"id":39832467},{"atl":[[3.9,12.46]],"id":39832467}],"con":true,"img":false}]}
{"op":"mcm","clk":"5353661129","pt":1646217291686,"mc":[{"id":"1.195453779","rc":[{"atl":[[20,3.33],[29,0]],"id":40812693}],"con":true,"img":false}]}
{"op":"mcm","clk":"5353661191","pt":1646217292309,"mc":[{"id":"1.195453779","rc":[{"atb":[[1.58,0]],"id":39832467}],"con":true,"img":false}]}
{"op":"mcm","clk":"5353661496","pt":1646217295727,"mc":[{"id":"1.195453779","rc":[{"atb":[[1.56,178.57],[1.59,0]],"id":39832467}],"con":true,"img":false}]}
{"op":"mcm","clk":"5353662249","pt":1646217303009,"mc":[{"id":"1.195453779","rc":[{"atl":[[2.88,0],[2.62,15.12]],"id":39786303},{"atl":[[3.6,18.54],[3.95,0]],"id":39832467},{"atl":[[2,78.77],[2.04,0]],"id":40622317}],"con":true,"img":false}]}
{"op":"mcm","clk":"5353662368","pt":1646217304416,"mc":[{"id":"1.195453779","rc":[{"atb":[[1.6,12.53]],"id":39832467}],"con":true,"img":false}]}
{"op":"mcm","clk":"5353663089","pt":1646217312051,"mc":[{"id":"1.195453779","rc":[{"atb":[[1.6,26.43]],"id":39832467}],"con":true,"img":false}]}
{"op":"mcm","clk":"5353663347","pt":1646217315020,"mc":[{"id":"1.195453779","rc":[{"atb":[[1.55,0]],"id":39832467}],"con":true,"img":false}]}
{"op":"mcm","clk":"5353663360","pt":1646217315123,"mc":[{"id":"1.195453779","rc":[{"atb":[[1.48,96.88]],"id":39832467}],"con":true,"img":false}]}
{"op":"mcm","clk":"5353663580","pt":1646217317320,"mc":[{"id":"1.195453779","rc":[{"atb":[[1.56,0],[1.61,96.89]],"id":39832467}],"con":true,"img":false}]}
{"op":"mcm","clk":"5353663776","pt":1646217319420,"mc":[{"id":"1.195453779","rc":[{"atb":[[1.6,13.89]],"id":39832467}],"con":true,"img":false}]}
{"op":"mcm","clk":"5353664316","pt":1646217325464,"mc":[{"id":"1.195453779","rc":[{"atb":[[1.65,11.56]],"id":39832467}],"con":true,"img":false}]}
{"op":"mcm","clk":"5353664333","pt":1646217325641,"mc":[{"id":"1.195453779","rc":[{"atb":[[1.62,96.89],[1.61,0]],"id":39832467}],"con":true,"img":false}]}
{"op":"mcm","clk":"5353664595","pt":1646217328559,"mc":[{"id":"1.195453779","rc":[{"atb":[[1.65,0]],"id":39832467}],"con":true,"img":false}]}
{"op":"mcm","clk":"5353664616","pt":1646217328767,"mc":[{"id":"1.195453779","rc":[{"atb":[[1.62,0],[1.61,163.93]],"id":39832467}],"con":true,"img":false}]}
{"op":"mcm","clk":"5353664683","pt":1646217329345,"mc":[{"id":"1.195453779","rc":[{"atb":[[4.4,0]],"id":40812693},{"atl":[[34,0]],"id":40812693}],"con":true,"img":false}]}
{"op":"mcm","clk":"5353664694","pt":1646217329452,"mc":[{"id":"1.195453779","rc":[{"atb":[[4.8,10.38]],"id":40812693},{"atl":[[25,2.72]],"id":40812693}],"con":true,"img":false}]}
{"op":"mcm","clk":"5353665450","pt":1646217337446,"mc":[{"id":"1.195453779","rc":[{"atb":[[1.65,11.56]],"id":39832467}],"con":true,"img":false}]}
{"op":"mcm","clk":"5353665995","pt":1646217342957,"mc":[{"id":"1.195453779","rc":[{"atl":[[21,0.6]],"id":40812693},{"atl":[[3.9,0]],"id":39832467},{"atl":[[2.02,35.17]],"id":40622317}],"con":true,"img":false}]}
{"op":"mcm","clk":"5353666007","pt":1646217343061,"mc":[{"id":"1.195453779","rc":[{"atl":[[19.5,2.72]],"id":40812693},{"atl":[[4.1,12.46]],"id":39832467},{"atl":[[1.97,43.59]],"id":40622317}],"con":true,"img":false}]}
{"op":"mcm","clk":"5353666030","pt":1646217343267,"mc":[{"id":"1.195453779","rc":[{"atl":[[2,0],[1.96,43.6]],"id":40622317}],"con":true,"img":false}]}
{"op":"mcm","clk":"5353666191","pt":1646217345043,"mc":[{"id":"1.195453779","rc":[{"atb":[[1.6,0]],"id":39832467}],"con":true,"img":false}]}
{"op":"mcm","clk":"5353666628","pt":1646217350062,"mc":[{"id":"1.195453779","rc":[{"atb":[[1.62,96.89],[1.61,0]],"id":39832467}],"con":true,"img":false}]}
{"op":"mcm","clk":"5353666876","pt":1646217352576,"mc":[{"id":"1.195453779","rc":[{"spn":10.15,"spf":"NaN","id":40812693},{"atb":[[1.65,0]],"id":39832467},{"spn":2.14,"spf":"NaN","id":39832467},{"spn":1.55,"spf":"NaN","id":40622317}],"con":true,"img":false}]}
{"op":"mcm","clk":"5353666899","pt":1646217352783,"mc":[{"id":"1.195453779","rc":[{"atb":[[1.62,0],[1.49,193.78]],"id":39832467}],"con":true,"img":false}]}
{"op":"mcm","clk":"5353667668","pt":1646217360996,"mc":[{"id":"1.195453779","rc":[{"atb":[[3.95,0]],"id":40812693},{"atb":[[1.48,0]],"id":39832467},{"atl":[[2.02,0]],"id":40622317}],"con":true,"img":false}]}
{"op":"mcm","clk":"5353667678","pt":1646217361097,"mc":[{"id":"1.195453779","rc":[{"atb":[[4.3,31.78]],"id":40812693},{"atb":[[1.5,96.88]],"id":39832467},{"atl":[[2.16,45.6]],"id":40622317}],"con":true,"img":false}]}
{"op":"mcm","clk":"5353667690","pt":1646217361204,"mc":[{"id":"1.195453779","rc":[{"atb":[[1.49,0],[1.42,238.1]],"id":39832467}],"con":true,"img":false}]}
{"op":"mcm","clk":"5353668400","pt":1646217367593,"mc":[{"id":"1.195453779","rc":[{"atb":[[1.53,14.18]],"id":39832467}],"con":true,"img":false}]}
{"op":"mcm","clk":"5353669223","pt":1646217375590,"mc":[{"id":"1.195453779","rc":[{"atb":[[1.5,0]],"id":39832467}],"con":true,"img":false}]}
{"op":"mcm","clk":"5353669233","pt":1646217375695,"mc":[{"id":"1.195453779","rc":[{"atb":[[1.45,96.88]],"id":39832467}],"con":true,"img":false}]}
{"op":"mcm","clk":"5353669324","pt":1646217376528,"mc":[{"id":"1.195453779","rc":[{"atb":[[1.53,0]],"id":39832467}],"con":true,"img":false}]}
{"op":"mcm","clk":"5353669918","pt":1646217382117,"mc":[{"id":"1.195453779","rc":[{"atb":[[1.46,96.89],[1.42,0]],"id":39832467}],"con":true,"img":false}]}
{"op":"mcm","clk":"5353670617","pt":1646217388612,"mc":[{"id":"1.195453779","rc":[{"atb":[[1.49,15.34]],"id":39832467}],"con":true,"img":false}]}
{"op":"mcm","clk":"5353670625","pt":1646217388715,"mc":[{"id":"1.195453779","rc":[{"atb":[[1.5,96.89]],"id":39832467}],"con":true,"img":false}]}
{"op":"mcm","clk":"5353670639","pt":1646217388816,"mc":[{"id":"1.195453779","rc":[{"atb":[[1.46,0]],"id":39832467}],"con":true,"img":false}]}
{"op":"mcm","clk":"5353670902","pt":1646217391637,"mc":[{"id":"1.195453779","rc":[{"atl":[[2.86,0]],"id":39786303},{"atb":[[1.49,0]],"id":39832467},{"atl":[[1.97,0]],"id":40622317}],"con":true,"img":false}]}
{"op":"mcm","clk":"5353670916","pt":1646217391742,"mc":[{"id":"1.195453779","rc":[{"atl":[[2.6,29.58]],"id":39786303},{"atl":[[1.95,43.59]],"id":40622317}],"con":true,"img":false}]}
{"op":"mcm","clk":"5353670927","pt":1646217391802,"mc":[{"id":"1.195453779","rc":[{"atl":[[1.96,0],[2.14,87.2]],"id":40622317}],"con":true,"img":false}]}
{"op":"mcm","clk":"5353670950","pt":1646217392003,"mc":[{"id":"1.195453779","rc":[{"atl":[[1.94,45.6],[2.14,0]],"id":40622317}],"con":true,"img":false}]}
{"op":"mcm","clk":"5353671156","pt":1646217393827,"mc":[{"id":"1.195453779","rc":[{"atb":[[1.46,193.78]],"id":39832467}],"con":true,"img":false}]}
{"op":"mcm","clk":"5353671171","pt":1646217393934,"mc":[{"id":"1.195453779","rc":[{"atb":[[1.5,0]],"id":39832467}],"con":true,"img":false}]}
{"op":"mcm","clk":"5353671795","pt":1646217400649,"mc":[{"id":"1.195453779","rc":[{"atb":[[1.49,15.34]],"id":39832467}],"con":true,"img":false}]}
{"op":"mcm","clk":"5353672216","pt":1646217404631,"mc":[{"id":"1.195453779","rc":[{"atl":[[4.1,0]],"id":39832467}],"con":true,"img":false}]}
{"op":"mcm","clk":"5353672228","pt":1646217404733,"mc":[{"id":"1.195453779","rc":[{"atl":[[3.55,12.46]],"id":39832467}],"con":true,"img":false}]}
{"op":"mcm","clk":"5353672319","pt":1646217405524,"mc":[{"id":"1.195453779","rc":[{"atb":[[1.49,32.35]],"id":39832467}],"con":true,"img":false}]}
{"op":"mcm","clk":"5353673305","pt":1646217414455,"mc":[{"id":"1.195453779","rc":[{"atb":[[1.46,0],[1.5,96.89]],"id":39832467},{"spn":2.08,"spf":"NaN","id":39832467},{"spn":1.54,"spf":"NaN","id":40622317}],"con":true,"img":false}]}
{"op":"mcm","clk":"5353673412","pt":1646217415664,"mc":[{"id":"1.195453779","rc":[{"atb":[[1.49,17.01]],"id":39832467}],"con":true,"img":false}]}
{"op":"mcm","clk":"5353674070","pt":1646217421635,"mc":[{"id":"1.195453779","rc":[{"atb":[[1.53,14.18]],"id":39832467}],"con":true,"img":false}]}
{"op":"mcm","clk":"5353674083","pt":1646217421743,"mc":[{"id":"1.195453779","rc":[{"atb":[[1.54,17.01]],"id":39832467}],"con":true,"img":false}]}
{"op":"mcm","clk":"5353674094","pt":1646217421844,"mc":[{"id":"1.195453779","rc":[{"atb":[[1.5,0]],"id":39832467}],"con":true,"img":false}]}
{"op":"mcm","clk":"5353674359","pt":1646217424757,"mc":[{"id":"1.195453779","rc":[{"atb":[[1.53,0]],"id":39832467}],"con":true,"img":false}]}
{"op":"mcm","clk":"5353674574","pt":1646217426847,"mc":[{"id":"1.195453779","rc":[{"atb":[[1.54,0],[1.5,86.08]],"id":39832467}],"con":true,"img":false}]}
{"op":"mcm","clk":"5353675286","pt":1646217433689,"mc":[{"id":"1.195453779","rc":[{"atb":[[1.49,0]],"id":39832467}],"con":true,"img":false}]}
{"op":"mcm","clk":"5353675297","pt":1646217433755,"mc":[{"id":"1.195453779","rc":[{"atb":[[1.53,14.18]],"id":39832467}],"con":true,"img":false}]}
{"op":"mcm","clk":"5353675310","pt":1646217433863,"mc":[{"id":"1.195453779","rc":[{"atb":[[4.8,0]],"id":40812693},{"atl":[[25,0]],"id":40812693},{"atb":[[1.46,172.16],[1.45,0],[1.5,0]],"id":39832467},{"atl":[[1.95,0]],"id":40622317}],"con":true,"img":false}]}
{"op":"mcm","clk":"5353675320","pt":1646217433991,"mc":[{"id":"1.195453779","rc":[{"atb":[[5.1,10.38]],"id":40812693},{"atl":[[27,2.72]],"id":40812693},{"atb":[[1.51,96.88]],"id":39832467},{"atl":[[1.93,43.59]],"id":40622317}],"con":true,"img":false}]}
{"op":"mcm","clk":"5353675329","pt":1646217434065,"mc":[{"id":"1.195453779","rc":[{"atl":[[1.94,0],[2.14,87.72]],"id":40622317}],"con":true,"img":false}]}
{"op":"mcm","clk":"5353675620","pt":1646217436672,"mc":[{"id":"1.195453779","rc":[{"atb":[[1.53,0]],"id":39832467}],"con":true,"img":false}]}
{"op":"mcm","clk":"5353676332","pt":1646217443908,"mc":[{"id":"1.195453779","rc":[{"atb":[[1.54,13.92]],"id":39832467}],"con":true,"img":false}]}
{"op":"mcm","clk":"5353676650","pt":1646217447201,"mc":[{"id":"1.195453779","rc":[{"atb":[[1.46,0],[1.55,96.89]],"id":39832467}],"con":true,"img":false}]}
{"op":"mcm","clk":"5353676779","pt":1646217448670,"mc":[{"id":"1.195453779","rc":[{"atb":[[1.54,0]],"id":39832467}],"con":true,"img":false}]}
{"op":"mcm","clk":"5353676790","pt":1646217448777,"mc":[{"id":"1.195453779","rc":[{"atb":[[1.52,192.31]],"id":39832467}],"con":true,"img":false}]}
{"op":"mcm","clk":"5353676798","pt":1646217448876,"mc":[{"id":"1.195453779","rc":[{"atb":[[1.55,0]],"id":39832467}],"con":true,"img":false}]}
{"op":"mcm","clk":"5353677107","pt":1646217452283,"mc":[{"id":"1.195453779","rc":[{"atl":[[2.6,7.56]],"id":39786303}],"con":true,"img":false}]}
{"op":"mcm","clk":"5353677114","pt":1646217452386,"mc":[{"id":"1.195453779","rc":[{"atl":[[2.94,22.01]],"id":39786303}],"con":true,"img":false}]}
{"op":"mcm","clk":"5353677296","pt":1646217454311,"mc":[{"id":"1.195453779","rc":[{"atl":[[1.92,45.6],[2.14,0]],"id":40622317}],"con":true,"img":false}]}
{"op":"mcm","clk":"5353677632","pt":1646217457605,"mc":[{"id":"1.195453779","rc":[{"atb":[[1.55,13.66]],"id":39832467}],"con":true,"img":false}]}
{"op":"mcm","clk":"5353677662","pt":1646217457813,"mc":[{"id":"1.195453779","rc":[{"atb":[[1.56,96.89],[1.52,0]],"id":39832467}],"con":true,"img":false}]}
{"op":"mcm","clk":"5353677935","pt":1646217460693,"mc":[{"id":"1.195453779","rc":[{"atb":[[1.55,0]],"id":39832467}],"con":true,"img":false}]}
{"op":"mcm","clk":"5353678165","pt":1646217462893,"mc":[{"id":"1.195453779","rc":[{"atb":[[1.56,0],[1.52,192.31]],"id":39832467}],"con":true,"img":false}]}
{"op":"mcm","clk":"5353678830","pt":1646217469833,"mc":[{"id":"1.195453779","rc":[{"atb":[[1.55,13.66]],"id":39832467}],"con":true,"img":false}]}
{"op":"mcm","clk":"5353679023","pt":1646217471617,"mc":[{"id":"1.195453779","rc":[{"atb":[[5.1,0],[4.3,18.33],[4.7,10.72]],"id":40812693},{"atl":[[27,0]],"id":40812693}],"con":true,"img":false}]}
{"op":"mcm","clk":"5353679043","pt":1646217471826,"mc":[{"id":"1.195453779","rc":[{"atb":[[5.2,10.38]],"id":40812693},{"atl":[[29,2.72]],"id":40812693}],"con":true,"img":false}]}
{"op":"mcm","clk":"5353680096","pt":1646217482834,"mc":[{"id":"1.195453779","rc":[{"spn":10.35,"spf":"NaN","id":40812693},{"atb":[[1.56,96.89],[1.52,0]],"id":39832467},{"spn":2.11,"spf":"NaN","id":39832467},{"spn":1.53,"spf":"NaN","id":40622317}],"con":true,"img":false}]}
{"op":"mcm","clk":"5353680326","pt":1646217484963,"mc":[{"id":"1.195453779","rc":[{"atb":[[1.55,0]],"id":39832467}],"con":true,"img":false}]}
{"op":"mcm","clk":"5353680631","pt":1646217488061,"mc":[{"id":"1.195453779","rc":[{"atb":[[1.56,0],[1.52,192.31]],"id":39832467}],"con":true,"img":false}]}
{"op":"mcm","clk":"5353681174","pt":1646217493772,"mc":[{"id":"1.195453779","rc":[{"atb":[[1.51,0]],"id":39832467}],"con":true,"img":false}]}
{"op":"mcm","clk":"5353681185","pt":1646217493842,"mc":[{"id":"1.195453779","rc":[{"atb":[[1.53,96.88]],"id":39832467}],"con":true,"img":false}]}
{"op":"mcm","clk":"5353681193","pt":1646217493942,"mc":[{"id":"1.195453779","rc":[{"atb":[[1.42,238.1],[1.52,0]],"id":39832467}],"con":true,"img":false}]}
{"op":"mcm","clk":"5353682098","pt":1646217502797,"mc":[{"id":"1.195453779","rc":[{"atb":[[1.57,13.18]],"id":39832467}],"con":true,"img":false}]}
{"op":"mcm","clk":"5353682669","pt":1646217507997,"mc":[{"id":"1.195453779","rc":[{"atl":[[2.94,0]],"id":39786303},{"atl":[[29,0]],"id":40812693},{"atb":[[1.53,0]],"id":39832467},{"atl":[[1.93,0]],"id":40622317}],"con":true,"img":false}]}
{"op":"mcm","clk":"5353682685","pt":1646217508097,"mc":[{"id":"1.195453779","rc":[{"atl":[[2.6,29.58]],"id":39786303},{"atl":[[30,2.72]],"id":40812693},{"atb":[[1.44,96.88]],"id":39832467},{"atl":[[1.91,43.59]],"id":40622317}],"con":true,"img":false}]}
{"op":"mcm","clk":"5353682700","pt":1646217508162,"mc":[{"id":"1.195453779","rc":[{"atl":[[1.92,0],[2.14,87.72]],"id":40622317}],"con":true,"img":false}]}
{"op":"mcm","clk":"5353682710","pt":1646217508266,"mc":[{"id":"1.195453779","rc":[{"atl":[[1.9,45.6],[2.14,0]],"id":40622317}],"con":true,"img":false}]}
{"op":"mcm","clk":"5353682776","pt":1646217508891,"mc":[{"id":"1.195453779","rc":[{"atb":[[1.57,0]],"id":39832467}],"con":true,"img":false}]}
{"op":"mcm","clk":"5353683308","pt":1646217513570,"mc":[{"id":"1.195453779","rc":[{"atb":[[1.45,96.89],[1.42,0]],"id":39832467}],"con":true,"img":false}]}
{"op":"mcm","clk":"5353684083","pt":1646217520797,"mc":[{"id":"1.195453779","rc":[{"atb":[[1.48,15.66]],"id":39832467}],"con":true,"img":false}]}
{"op":"mcm","clk":"5353684232","pt":1646217522116,"mc":[{"id":"1.195453779","rc":[{"atl":[[2.6,7.56]],"id":39786303}],"con":true,"img":false}]}
{"op":"mcm","clk":"5353684250","pt":1646217522223,"mc":[{"id":"1.195453779","rc":[{"atl":[[2.92,22.01]],"id":39786303}],"con":true,"img":false}]}
{"op":"mcm","clk":"5353685144","pt":1646217530200,"mc":[{"id":"1.195453779","rc":[{"atb":[[1.48,33.02]],"id":39832467}],"con":true,"img":false}]}
{"op":"mcm","clk":"5353685452","pt":1646217533016,"mc":[{"id":"1.195453779","rc":[{"atb":[[1.45,0],[1.49,96.89]],"id":39832467}],"con":true,"img":false}]}
{"op":"mcm","clk":"5353685815","pt":1646217535818,"mc":[{"id":"1.195453779","rc":[{"atb":[[1.48,17.36]],"id":39832467}],"con":true,"img":false}]}
{"op":"mcm","clk":"5353685827","pt":1646217535913,"mc":[{"id":"1.195453779","rc":[{"atl":[[30,0]],"id":40812693}],"con":true,"img":false}]}
{"op":"mcm","clk":"5353685841","pt":1646217536024,"mc":[{"id":"1.195453779","rc":[{"atl":[[32,3.5]],"id":40812693}],"con":true,"img":false}]}
{"op":"mcm","clk":"5353686505","pt":1646217542054,"mc":[{"id":"1.195453779","rc":[{"atb":[[1.52,14.45]],"id":39832467}],"con":true,"img":false}]}
{"op":"mcm","clk":"5353686613","pt":1646217543051,"mc":[{"id":"1.195453779","rc":[{"atb":[[1.27,74.07],[1.25,683.95],[1.21,250],[1.23,250]],"id":39786303},{"atl":[[2.04,19.23],[2.12,66.96],[2.16,107.76],[2.08,46.3]],"id":39786303},{"spn":1.71,"spf":"NaN","id":39786303},{"atb":[[1.56,133.93],[1.6,234.97],[1.58,86.21],[1.54,231.48]],"id":38247337},{"atl":[[4.3,37.88],[3.85,7.02],[3.95,52.01],[4.1,24.19]],"id":38247337},{"atb":[[3.2,22.73],[3.1,39.67],[3,62.5],[3.3,8.7]],"id":42256449},{"atl":[[8.2,19.03],[7.4,7.81],[7,3.33],[7.8,11.03]],"id":42256449},{"spn":5.4,"spf":"NaN","id":42256449},{"atb":[[4.3,24.39],[3.85,43.86],[3.1,0],[3.95,25.42],[4.1,16.13],[3.35,42.55]],"id":40812693},{"atl":[[12.5,1.74],[13.5,4],[14.5,5.56],[15.5,9.45]],"id":40812693},{"spn":8.85,"spf":"NaN","id":40812693},{"atb":[[1.41,269],[1.45,44.44],[1.43,116.28],[1.39,250]],"id":39832467},{"atl":[[2.8,27.78],[3.6,0],[2.84,40.76],[3.25,15.04],[2.76,11.36],[2.88,66.49]],"id":39832467},{"spn":2.09,"spf":"NaN","id":39832467},{"atb":[[1.15,231.37],[1.11,799.94],[1.09,250],[1.13,548.98]],"id":40622317},{"atl":[[1.67,74.63],[1.65,30.77],[1.71,176.06],[1.69,108.7]],"id":40622317},{"spn":1.4,"spf":"NaN","id":40622317},{"atb":[[1.74,0],[1.85,142.61]],"id":40072523}],"con":true,"img":false}]}
{"op":"mcm","clk":"5353686621","pt":1646217543153,"mc":[{"id":"1.195453779","rc":[{"atb":[[3.45,51.02],[3.55,29.41],[3.75,7.27],[3.65,18.87]],"id":37495332},{"atl":[[22,1],[24,2.17],[26,3],[28,4.63]],"id":37495332},{"atb":[[1.8,213.73],[1.82,24.39],[1.78,96.15],[1.76,227.62]],"id":40072523},{"atl":[[9,21.66],[8.6,9.87],[8.2,6.94],[7.8,12.72]],"id":40072523}],"con":true,"img":false}]}
{"op":"mcm","clk":"5353686634","pt":1646217543215,"mc":[{"id":"1.195453779","rc":[{"atl":[[20,0],[14.5,8.28]],"id":40812693},{"atl":[[1.89,45.6],[1.9,0]],"id":40622317}],"con":true,"img":false}]}
{"op":"mcm","clk":"5353686810","pt":1646217544944,"mc":[{"id":"1.195453779","rc":[{"atb":[[1.27,0],[1.17,0],[1.35,229.97]],"id":39786303},{"atl":[[2.62,0],[2.74,57.47]],"id":39786303},{"atl":[[4,0],[3.45,25.31],[3.85,0]],"id":38247337},{"atb":[[4.8,5.26],[4.3,18.33]],"id":40812693},{"atb":[[4,26.88],[3.6,0],[4.2,6.25],[3.75,0]],"id":37495332},{"atl":[[2.8,0],[3.1,9.52],[2.84,0],[2.76,0]],"id":39832467},{"atl":[[8.6,2.63],[8.2,0],[7.8,9.78]],"id":40072523}],"con":true,"img":false}]}
{"op":"mcm","clk":"5353686939","pt":1646217546145,"mc":[{"id":"1.195453779","rc":[{"atl":[[2.88,0]],"id":39832467}],"con":true,"img":false}]}
{"op":"mcm","clk":"5353687143","pt":1646217547724,"mc":[{"id":"1.195453779","rc":[{"atb":[[1.44,0]],"id":39832467},{"atl":[[3.55,0]],"id":39832467},{"atl":[[1.91,0]],"id":40622317}],"con":true,"img":false}]}
{"op":"mcm","clk":"5353687159","pt":1646217547828,"mc":[{"id":"1.195453779","rc":[{"atb":[[1.5,96.88]],"id":39832467},{"atl":[[3.95,12.46]],"id":39832467},{"atl":[[1.89,89.19]],"id":40622317}],"con":true,"img":false}]}
{"op":"mcm","clk":"5353687557","pt":1646217550927,"mc":[{"id":"1.195453779","rc":[{"atb":[[1.52,0]],"id":39832467}],"con":true,"img":false}]}
{"op":"mcm","clk":"5353687702","pt":1646217552237,"mc":[{"id":"1.195453779","rc":[{"atb":[[1.49,0],[1.51,96.89]],"id":39832467}],"con":true,"img":false}]}
{"op":"mcm","clk":"5353688005","pt":1646217554955,"mc":[{"id":"1.195453779","rc":[{"atb":[[1.33,151.52]],"id":39786303},{"atl":[[3.55,19.61]],"id":38247337},{"atb":[[4.6,13.89]],"id":40812693},{"atb":[[4,43.55]],"id":37495332},{"atl":[[3.2,22.73]],"id":39832467},{"atl":[[9,12.29]],"id":40072523}],"con":true,"img":false}]}
{"op":"mcm","clk":"5353688320","pt":1646217557666,"mc":[{"id":"1.195453779","rc":[{"atl":[[2.92,0],[2.06,41.13]],"id":39786303},{"atb":[[2.56,22.82],[3.4,0],[3.75,0]],"id":42256449},{"atb":[[5.2,0],[4.7,0]],"id":40812693},{"atl":[[6,0]],"id":40072523}],"con":true,"img":false}]}
{"op":"mcm","clk":"5353688334","pt":1646217557771,"mc":[{"id":"1.195453779","rc":[{"atb":[[3.15,20.27]],"id":42256449},{"atb":[[4.4,10.38],[4.2,10.72]],"id":40812693},{"atl":[[6.4,7.77]],"id":40072523}],"con":true,"img":false}]}
{"op":"mcm","clk":"5353688363","pt":1646217557981,"mc":[{"id":"1.195453779","rc":[{"atb":[[3.1,35.71]],"id":42256449},{"atb":[[1.48,0]],"id":39832467}],"con":true,"img":false}]}
{"op":"mcm","clk":"5353688527","pt":1646217559243,"mc":[{"id":"1.195453779","rc":[{"atb":[[3.8,0]],"id":42256449}],"con":true,"img":false}]}
{"op":"mcm","clk":"5353688548","pt":1646217559452,"mc":[{"id":"1.195453779","rc":[{"atb":[[3.35,1.66],[3.15,51.7],[2.98,0]],"id":42256449},{"atb":[[4.9,1.66]],"id":40812693}],"con":true,"img":false}]}
{"op":"mcm","clk":"5353688598","pt":1646217559974,"mc":[{"id":"1.195453779","rc":[{"atb":[[1.54,13.92]],"id":39832467}],"con":true,"img":false}]}
{"op":"mcm","clk":"5353689133","pt":1646217564977,"mc":[{"id":"1.195453779","rc":[{"atb":[[1.21,0],[1.31,370.27]],"id":39786303},{"atl":[[4.3,0],[3.65,28.3]],"id":38247337},{"atb":[[3.85,0],[3.95,0],[4.1,0],[4.4,32.44]],"id":40812693},{"atb":[[3.45,0],[3.55,0],[3.9,25.86],[3.65,0]],"id":37495332},{"atl":[[3.3,32.61]],"id":39832467},{"atl":[[9.4,8.93]],"id":40072523}],"con":true,"img":false}]}
{"op":"mcm","clk":"5353689238","pt":1646217565972,"mc":[{"id":"1.195453779","rc":[{"atb":[[3.25,3.33]],"id":42256449}],"con":true,"img":false}]}
{"op":"mcm","clk":"5353689842","pt":1646217571254,"mc":[{"id":"1.195453779","rc":[{"atb":[[1.51,0],[1.53,96.89]],"id":39832467}],"con":true,"img":false}]}
{"op":"mcm","clk":"5353689912","pt":1646217571885,"mc":[{"id":"1.195453779","rc":[{"atb":[[1.54,0]],"id":39832467}],"con":true,"img":false}]}
{"op":"mcm","clk":"5353690268","pt":1646217574958,"mc":[{"id":"1.195453779","rc":[{"atb":[[1.23,0],[1.29,250]],"id":39786303},{"atl":[[4.1,0],[3.75,45.45]],"id":38247337},{"atb":[[4.2,49.78]],"id":40812693},{"atb":[[3.8,44.64]],"id":37495332},{"atl":[[3.4,52.08]],"id":39832467},{"atl":[[9.8,14.2]],"id":40072523}],"con":true,"img":false}]}
{"op":"mcm","clk":"5353690441","pt":1646217576480,"mc":[{"id":"1.195453779","rc":[{"atb":[[1.51,193.78],[1.53,0]],"id":39832467}],"con":true,"img":false}]}
{"op":"mcm","clk":"5353690578","pt":1646217577689,"mc":[{"id":"1.195453779","rc":[{"atl":[[8,6.22],[26,0]],"id":42256449},{"atl":[[19.5,0]],"id":40812693},{"atl":[[32,0]],"id":37495332},{"atb":[[1.41,182.93],[1.5,0]],"id":39832467},{"atl":[[1.89,45.6]],"id":40622317}],"con":true,"img":false}]}
{"op":"mcm","clk":"5353690591","pt":1646217577789,"mc":[{"id":"1.195453779","rc":[{"atl":[[14,2.72]],"id":40812693},{"atl":[[25,2.72]],"id":37495332},{"atb":[[1.44,86.07],[1.52,96.88]],"id":39832467},{"atl":[[1.66,43.59]],"id":40622317}],"con":true,"img":false}]}
{"op":"mcm","clk":"5353690604","pt":1646217577894,"mc":[{"id":"1.195453779","rc":[{"atb":[[1.43,348.84],[1.51,0]],"id":39832467}],"con":true,"img":false}]}
{"op":"mcm","clk":"5353690617","pt":1646217577995,"mc":[{"id":"1.195453779","rc":[{"atl":[[13.5,8],[14.5,5.56]],"id":40812693}],"con":true,"img":false}]}
{"op":"mcm","clk":"5353691334","pt":1646217585001,"mc":[{"id":"1.195453779","rc":[{"atb":[[1.25,483.95]],"id":39786303},{"atl":[[3.95,35.06]],"id":38247337}],"con":true,"img":false}]}
{"op":"mcm","clk":"5353691553","pt":1646217586888,"mc":[{"id":"1.195453779","rc":[{"atb":[[1.55,13.66]],"id":39832467}],"con":true,"img":false}]}
{"op":"mcm","clk":"5353691649","pt":1646217587678,"mc":[{"id":"1.195453779","rc":[{"atl":[[3.95,21.82]],"id":38247337},{"atb":[[3.15,31.43]],"id":42256449},{"atb":[[4.4,22.06]],"id":40812693},{"atb":[[1.52,0]],"id":39832467},{"atl":[[3.45,0]],"id":39832467}],"con":true,"img":false}]}
{"op":"mcm","clk":"5353691660","pt":1646217587781,"mc":[{"id":"1.195453779","rc":[{"atl":[[4.3,13.23]],"id":38247337},{"atb":[[3.2,43]],"id":42256449},{"atb":[[4.5,10.38]],"id":40812693},{"atb":[[1.49,96.88]],"id":39832467},{"atl":[[3.25,30.07]],"id":39832467}],"con":true,"img":false}]}
{"op":"mcm","clk":"5353691960","pt":1646217590396,"mc":[{"id":"1.195453779","rc":[{"atb":[[1.55,0]],"id":39832467}],"con":true,"img":false}]}
{"op":"mcm","clk":"5353692553","pt":1646217596007,"mc":[{"id":"1.195453779","rc":[{"atb":[[1.52,14.45]],"id":39832467}],"con":true,"img":false}]}
{"op":"mcm","clk":"5353692629","pt":1646217596687,"mc":[{"id":"1.195453779","rc":[{"atb":[[1.43,116.28],[1.53,44.44]],"id":39832467}],"con":true,"img":false}]}
{"op":"mcm","clk":"5353692748","pt":1646217597684,"mc":[{"id":"1.195453779","rc":[{"atl":[[2.72,23.12],[3.25,0]],"id":39786303},{"atb":[[1.59,66.19],[1.49,0]],"id":38247337},{"atl":[[3.95,8.2]],"id":38247337},{"atl":[[10.5,5.02],[27,0]],"id":42256449},{"atl":[[32,0.77]],"id":40812693},{"atl":[[34,0]],"id":37495332},{"atl":[[2.16,10.43]],"id":40622317}],"con":true,"img":false}]}
{"op":"mcm","clk":"5353692760","pt":1646217597783,"mc":[{"id":"1.195453779","rc":[{"atl":[[3.4,13.62]],"id":38247337},{"atl":[[19,2.72]],"id":40812693},{"atl":[[25,5.44]],"id":37495332},{"atl":[[1.88,35.17]],"id":40622317}],"con":true,"img":false}]}
{"op":"mcm","clk":"5353693902","pt":1646217607606,"mc":[{"id":"1.195453779","rc":[{"atl":[[8,0]],"id":42256449},{"spn":5.17,"spf":"NaN","id":42256449},{"atl":[[14,0]],"id":40812693},{"spn":8.7,"spf":"NaN","id":40812693},{"spn":2.09,"spf":"NaN","id":39832467}],"con":true,"img":false}]}
{"op":"mcm","clk":"5353693912","pt":1646217607708,"mc":[{"id":"1.195453779","rc":[{"atl":[[7.6,6.22]],"id":42256449},{"atl":[[13,2.72]],"id":40812693}],"con":true,"img":false}]}
{"op":"mcm","clk":"5353693930","pt":1646217607816,"mc":[{"id":"1.195453779","rc":[{"atl":[[13.5,4],[14.5,12.97]],"id":40812693}],"con":true,"img":false}]}
{"op":"mcm","clk":"5353694574","pt":1646217612704,"mc":[{"id":"1.195453779","rc":[{"atb":[[3.25,7.03]],"id":42256449},{"atb":[[1.52,30.48]],"id":39832467}],"con":true,"img":false}]}
{"op":"mcm","clk":"5353695220","pt":1646217617638,"mc":[{"id":"1.195453779","rc":[{"atl":[[13,0]],"id":40812693},{"atl":[[3.35,15.38]],"id":39832467}],"con":true,"img":false}]}
{"op":"mcm","clk":"5353695237","pt":1646217617740,"mc":[{"id":"1.195453779","rc":[{"atl":[[14,2.72]],"id":40812693},{"atl":[[3.95,0]],"id":39832467}],"con":true,"img":false}]}
{"op":"mcm","clk":"5353696317","pt":1646217626230,"mc":[{"id":"1.195453779","rc":[{"atl":[[13.5,8],[14.5,5.56]],"id":40812693}],"con":true,"img":false}]}
{"op":"mcm","clk":"5353698920","pt":1646217647691,"mc":[{"id":"1.195453779","rc":[{"atl":[[14,0]],"id":40812693}],"con":true,"img":false}]}
{"op":"mcm","clk":"5353698930","pt":1646217647790,"mc":[{"id":"1.195453779","rc":[{"atl":[[13,2.72]],"id":40812693}],"con":true,"img":false}]}
{"op":"mcm","clk":"5353698940","pt":1646217647890,"mc":[{"id":"1.195453779","rc":[{"atl":[[13.5,4],[14.5,12.97]],"id":40812693}],"con":true,"img":false}]}
{"op":"mcm","clk":"5353700048","pt":1646217657687,"mc":[{"id":"1.195453779","rc":[{"atl":[[13,0]],"id":40812693}],"con":true,"img":false}]}
{"op":"mcm","clk":"5353700057","pt":1646217657796,"mc":[{"id":"1.195453779","rc":[{"atl":[[14,2.72]],"id":40812693}],"con":true,"img":false}]}
{"op":"mcm","clk":"5353700599","pt":1646217663130,"mc":[{"id":"1.195453779","rc":[{"atl":[[2.88,53.19],[2.74,0]],"id":39786303},{"atb":[[3,112.5],[3.15,0]],"id":42256449},{"atb":[[1.53,0],[1.48,88.88]],"id":39832467},{"atl":[[1.89,0],[1.96,91.2]],"id":40622317},{"atb":[[1.8,338.73],[1.85,71.17]],"id":40072523}],"con":true,"img":false}]}
{"op":"mcm","clk":"5353700918","pt":1646217665932,"mc":[{"id":"1.195453779","rc":[{"atl":[[13.5,8],[14.5,5.56]],"id":40812693}],"con":true,"img":false}]}
{"op":"mcm","clk":"5353701166","pt":1646217667711,"mc":[{"id":"1.195453779","rc":[{"atb":[[3.2,22.73]],"id":42256449},{"spn":2.09,"spf":"NaN","id":39832467},{"atl":[[1.88,0]],"id":40622317}],"con":true,"img":false}]}
{"op":"mcm","clk":"5353701181","pt":1646217667814,"mc":[{"id":"1.195453779","rc":[{"atb":[[3.15,20.27]],"id":42256449},{"atl":[[1.95,35.17]],"id":40622317}],"con":true,"img":false}]}
{"op":"mcm","clk":"5353703064","pt":1646217681045,"mc":[{"id":"1.195453779","rc":[{"atb":[[3.25,3.33]],"id":42256449}],"con":true,"img":false}]}
{"op":"mcm","clk":"5353703895","pt":1646217687729,"mc":[{"id":"1.195453779","rc":[{"atl":[[14,0]],"id":40812693}],"con":true,"img":false}]}
{"op":"mcm","clk":"5353703911","pt":1646217687839,"mc":[{"id":"1.195453779","rc":[{"atl":[[13,2.72]],"id":40812693}],"con":true,"img":false}]}
{"op":"mcm","clk":"5353703923","pt":1646217687939,"mc":[{"id":"1.195453779","rc":[{"atl":[[13.5,4],[14.5,12.97]],"id":40812693}],"con":true,"img":false}]}
{"op":"mcm","clk":"5353705070","pt":1646217697678,"mc":[{"id":"1.195453779","rc":[{"atl":[[13,0]],"id":40812693}],"con":true,"img":false}]}
{"op":"mcm","clk":"5353705079","pt":1646217697741,"mc":[{"id":"1.195453779","rc":[{"atl":[[14,2.72]],"id":40812693}],"con":true,"img":false}]}
{"op":"mcm","clk":"5353705355","pt":1646217700151,"mc":[{"id":"1.195453779","rc":[{"atb":[[3.15,24.15]],"id":42256449}],"con":true,"img":false}]}
{"op":"mcm","clk":"5353705975","pt":1646217705554,"mc":[{"id":"1.195453779","rc":[{"atl":[[13.5,8],[14.5,5.56]],"id":40812693}],"con":true,"img":false}]}
{"op":"mcm","clk":"5353706203","pt":1646217707657,"mc":[{"id":"1.195453779","rc":[{"atb":[[1.44,0]],"id":39832467}],"con":true,"img":false}]}
{"op":"mcm","clk":"5353706216","pt":1646217707762,"mc":[{"id":"1.195453779","rc":[{"atb":[[1.49,182.96]],"id":39832467}],"con":true,"img":false}]}
{"op":"mcm","clk":"5353708611","pt":1646217727720,"mc":[{"id":"1.195453779","rc":[{"atl":[[14,0]],"id":40812693}],"con":true,"img":false}]}
{"op":"mcm","clk":"5353708622","pt":1646217727785,"mc":[{"id":"1.195453779","rc":[{"atl":[[13,2.72]],"id":40812693}],"con":true,"img":false}]}
{"op":"mcm","clk":"5353708634","pt":1646217727930,"mc":[{"id":"1.195453779","rc":[{"atl":[[13.5,4],[14.5,12.97]],"id":40812693}],"con":true,"img":false}]}
{"op":"mcm","clk":"5353708654","pt":1646217728095,"mc":[{"id":"1.195453779","rc":[{"atl":[[13.5,12],[14.5,5.56]],"id":40812693}],"con":true,"img":false}]}
{"op":"mcm","clk":"5353757120","pt":1646218128664,"mc":[{"id":"1.195453779","rc":[{"atl":[[2.04,0],[2.08,18.52]],"id":39786303},{"spn":1.72,"spf":"NaN","id":39786303},{"atb":[[3.35,5],[3,62.5]],"id":42256449},{"atl":[[7.2,3.23],[7,0]],"id":42256449},{"spn":5.27,"spf":"NaN","id":42256449},{"atl":[[13.5,4],[14,5.56]],"id":40812693},{"atl":[[22,0],[24,1]],"id":37495332},{"atb":[[1.41,365.86],[1.48,0]],"id":39832467},{"atl":[[1.64,31.25],[1.85,117.65],[1.96,0],[1.65,0]],"id":40622317},{"spn":1.39,"spf":"NaN","id":40622317},{"atb":[[1.73,136.99],[1.8,213.73]],"id":40072523}],"con":true,"img":false}]}
{"op":"mcm","clk":"5353757138","pt":1646218128866,"mc":[{"id":"1.195453779","rc":[{"atb":[[1.41,182.93],[1.47,212.77]],"id":39832467}],"con":true,"img":false}]}
{"op":"mcm","clk":"5353757478","pt":1646218133089,"mc":[{"id":"1.195453779","rc":[{"atl":[[3.45,4.93],[3.2,28.7]],"id":38247337},{"atb":[[4.8,0],[4.9,6.79]],"id":40812693},{"atb":[[4.3,6.06],[4.2,0]],"id":37495332},{"atb":[[1.43,343.68],[1.47,0]],"id":39832467},{"atl":[[3.2,9.09],[3.1,0]],"id":39832467},{"atl":[[8.6,0],[7.8,0],[5.9,13.86]],"id":40072523}],"con":true,"img":false}]}
{"op":"mcm","clk":"5353757841","pt":1646218137775,"mc":[{"id":"1.195453779","rc":[{"atl":[[2.06,0]],"id":39786303},{"atl":[[13,0]],"id":40812693},{"atb":[[1.49,96.88]],"id":39832467}],"con":true,"img":false}]}
{"op":"mcm","clk":"5353757851","pt":1646218137882,"mc":[{"id":"1.195453779","rc":[{"atl":[[2.1,41.13]],"id":39786303},{"atl":[[14,8.28]],"id":40812693},{"atb":[[1.44,86.07]],"id":39832467}],"con":true,"img":false}]}
{"op":"mcm","clk":"5353757912","pt":1646218138660,"mc":[{"id":"1.195453779","rc":[{"atl":[[2.12,44.64]],"id":39786303},{"atl":[[7.6,13.8]],"id":42256449}],"con":true,"img":false}]}
{"op":"mcm","clk":"5353758152","pt":1646218141893,"mc":[{"id":"1.195453779","rc":[{"atb":[[1.73,0],[1.8,338.73]],"id":40072523}],"con":true,"img":false}]}
{"op":"mcm","clk":"5353758238","pt":1646218143002,"mc":[{"id":"1.195453779","rc":[{"atl":[[2.04,19.23],[2.88,0],[2.74,57.47]],"id":39786303},{"atb":[[1.48,0],[1.53,188.68]],"id":38247337},{"atl":[[3.2,9.09],[3.25,34.81]],"id":38247337},{"atb":[[2.82,114.79],[3.35,1.66]],"id":42256449},{"atl":[[7.2,0],[7.6,6.22],[7,3.33]],"id":42256449},{"atb":[[3.35,0],[2.96,44.12]],"id":40812693},{"atb":[[4,16.67],[3.6,38.46]],"id":37495332},{"atl":[[22,1]],"id":37495332},{"atl":[[1.64,0],[1.65,30.77]],"id":40622317}],"con":true,"img":false}]}
{"op":"mcm","clk":"5353758250","pt":1646218143098,"mc":[{"id":"1.195453779","rc":[{"atl":[[3.3,21.74]],"id":38247337},{"atl":[[3.3,21.74]],"id":39832467},{"atl":[[6.2,9.62]],"id":40072523}],"con":true,"img":false}]}
{"op":"mcm","clk":"5353758257","pt":1646218143203,"mc":[{"id":"1.195453779","rc":[{"atb":[[3.35,42.55],[2.96,0]],"id":40812693}],"con":true,"img":false}]}
{"op":"mcm","clk":"5353758533","pt":1646218146292,"mc":[{"id":"1.195453779","rc":[{"atb":[[1.43,116.28],[1.53,44.44]],"id":39832467}],"con":true,"img":false}]}
{"op":"mcm","clk":"5353759119","pt":1646218152980,"mc":[{"id":"1.195453779","rc":[{"atl":[[2.08,46.3]],"id":39786303},{"atl":[[24,2.17]],"id":37495332}],"con":true,"img":false}]}
{"op":"mcm","clk":"5353759129","pt":1646218153086,"mc":[{"id":"1.195453779","rc":[{"atl":[[3.55,0],[3.75,0],[3.4,44.87],[3.65,0]],"id":38247337},{"atl":[[3.4,31.25]],"id":39832467},{"atl":[[9.8,0],[6.6,13.39]],"id":40072523}],"con":true,"img":false}]}
{"op":"mcm","clk":"5353759260","pt":1646218155007,"mc":[{"id":"1.195453779","rc":[{"atb":[[1.8,213.73],[1.85,142.61]],"id":40072523}],"con":true,"img":false}]}
{"op":"mcm","clk":"5353759341","pt":1646218156108,"mc":[{"id":"1.195453779","rc":[{"atb":[[2.82,66.47],[3.15,53.66]],"id":42256449},{"atb":[[3.6,0],[4.1,25.86]],"id":37495332}],"con":true,"img":false}]}
{"op":"mcm","clk":"5353759470","pt":1646218157738,"mc":[{"id":"1.195453779","rc":[{"atl":[[3.4,31.25]],"id":38247337},{"atl":[[14,5.56]],"id":40812693}],"con":true,"img":false}]}
{"op":"mcm","clk":"5353759485","pt":1646218157790,"mc":[{"id":"1.195453779","rc":[{"atl":[[15,2.72]],"id":40812693}],"con":true,"img":false}]}
{"op":"mcm","clk":"5353759572","pt":1646218158897,"mc":[{"id":"1.195453779","rc":[{"atl":[[9.4,0]],"id":40072523}],"con":true,"img":false}]}
{"op":"mcm","clk":"5353759877","pt":1646218163027,"mc":[{"id":"1.195453779","rc":[{"atl":[[2.12,66.96]],"id":39786303}],"con":true,"img":false}]}
{"op":"mcm","clk":"5353759890","pt":1646218163138,"mc":[{"id":"1.195453779","rc":[{"atl":[[3.5,50]],"id":38247337},{"atl":[[3.5,50]],"id":39832467},{"atl":[[7,24.86]],"id":40072523}],"con":true,"img":false}]}
{"op":"mcm","clk":"5353760335","pt":1646218168628,"mc":[{"id":"1.195453779","rc":[{"atb":[[3.15,49.78]],"id":42256449}],"con":true,"img":false}]}
{"op":"mcm","clk":"5353760734","pt":1646218173225,"mc":[{"id":"1.195453779","rc":[{"atl":[[9,6.04]],"id":40072523}],"con":true,"img":false}]}
{"op":"mcm","clk":"5353761124","pt":1646218177623,"mc":[{"id":"1.195453779","rc":[{"atl":[[3.2,28.9]],"id":38247337},{"atl":[[1.84,42.71]],"id":40622317}],"con":true,"img":false}]}
{"op":"mcm","clk":"5353761134","pt":1646218177721,"mc":[{"id":"1.195453779","rc":[{"atl":[[2.1,0]],"id":39786303},{"atl":[[1.95,0]],"id":40622317},{"atl":[[6.4,0]],"id":40072523}],"con":true,"img":false}]}
{"op":"mcm","clk":"5353761143","pt":1646218177828,"mc":[{"id":"1.195453779","rc":[{"atl":[[2.06,41.13]],"id":39786303},{"atl":[[5.8,7.77]],"id":40072523}],"con":true,"img":false}]}
{"op":"mcm","clk":"5353761913","pt":1646218187651,"mc":[{"id":"1.195453779","rc":[{"atb":[[2.56,0]],"id":42256449},{"atb":[[4.2,39.06]],"id":40812693},{"atl":[[15,0]],"id":40812693}],"con":true,"img":false}]}
{"op":"mcm","clk":"5353761922","pt":1646218187755,"mc":[{"id":"1.195453779","rc":[{"atb":[[2.84,22.82]],"id":42256449},{"atb":[[4.4,32.78]],"id":40812693},{"atl":[[14,8.28]],"id":40812693}],"con":true,"img":false}]}
{"op":"mcm","clk":"5353761936","pt":1646218187963,"mc":[{"id":"1.195453779","rc":[{"atb":[[3.2,26.52]],"id":42256449}],"con":true,"img":false}]}
{"op":"mcm","clk":"5353762611","pt":1646218197689,"mc":[{"id":"1.195453779","rc":[{"spn":1.71,"spf":"NaN","id":39786303},{"spn":5.17,"spf":"NaN","id":42256449},{"atl":[[14,5.56]],"id":40812693},{"spn":2.09,"spf":"NaN","id":39832467},{"spn":1.4,"spf":"NaN","id":40622317}],"con":true,"img":false}]}
{"op":"mcm","clk":"5353762617","pt":1646218197751,"mc":[{"id":"1.195453779","rc":[{"atl":[[15,2.72]],"id":40812693}],"con":true,"img":false}]}
{"op":"mcm","clk":"5353765804","pt":1646218227705,"mc":[{"id":"1.195453779","rc":[{"atb":[[3.15,29.51]],"id":42256449},{"atl":[[15,0]],"id":40812693}],"con":true,"img":false}]}
{"op":"mcm","clk":"5353765812","pt":1646218227811,"mc":[{"id":"1.195453779","rc":[{"atb":[[3.25,23.61]],"id":42256449},{"atl":[[14,8.28]],"id":40812693}],"con":true,"img":false}]}
{"op":"mcm","clk":"5353767083","pt":1646218237741,"mc":[{"id":"1.195453779","rc":[{"atl":[[14,5.56]],"id":40812693}],"con":true,"img":false}]}
{"op":"mcm","clk":"5353767093","pt":1646218237846,"mc":[{"id":"1.195453779","rc":[{"atl":[[15,2.72]],"id":40812693}],"con":true,"img":false}]}
{"op":"mcm","clk":"5353769345","pt":1646218262953,"mc":[{"id":"1.195453779","rc":[{"atl":[[2.88,53.19],[2.74,0]],"id":39786303},{"atl":[[3.4,72.92],[3.25,0]],"id":38247337},{"atb":[[3,112.5],[3.15,0]],"id":42256449},{"atb":[[1.48,88.88]],"id":39832467},{"atl":[[1.85,0],[1.96,104.17]],"id":40622317},{"atb":[[1.8,338.73],[1.85,71.17]],"id":40072523}],"con":true,"img":false}]}
{"op":"mcm","clk":"5353769349","pt":1646218263056,"mc":[{"id":"1.195453779","rc":[{"atb":[[1.53,0]],"id":39832467}],"con":true,"img":false}]}
{"op":"mcm","clk":"5353769672","pt":1646218267768,"mc":[{"id":"1.195453779","rc":[{"atl":[[3.2,9.09]],"id":38247337},{"atb":[[3.25,3.33]],"id":42256449},{"atl":[[1.84,0]],"id":40622317}],"con":true,"img":false}]}
{"op":"mcm","clk":"5353769679","pt":1646218267872,"mc":[{"id":"1.195453779","rc":[{"atl":[[3.35,19.81]],"id":38247337},{"atb":[[3.15,20.27]],"id":42256449},{"atl":[[1.95,42.71]],"id":40622317}],"con":true,"img":false}]}
{"op":"mcm","clk":"5353770854","pt":1646218282578,"mc":[{"id":"1.195453779","rc":[{"atb":[[3.2,22.73]],"id":42256449}],"con":true,"img":false}]}
{"op":"mcm","clk":"5353771798","pt":1646218293710,"mc":[{"id":"1.195453779","rc":[{"atb":[[3.15,24.15]],"id":42256449}],"con":true,"img":false}]}
{"op":"mcm","clk":"5353772901","pt":1646218307727,"mc":[{"id":"1.195453779","rc":[{"atb":[[1.44,0]],"id":39832467}],"con":true,"img":false}]}
{"op":"mcm","clk":"5353772908","pt":1646218307830,"mc":[{"id":"1.195453779","rc":[{"atb":[[1.49,182.96]],"id":39832467}],"con":true,"img":false}]}
{"op":"mcm","clk":"5353778612","pt":1646218380218,"mc":[{"id":"1.195453779","rc":[{"atb":[[1.33,60.61],[1.35,172.83]],"id":39786303},{"atb":[[1.6,201.64],[1.58,34.48]],"id":38247337},{"spn":2.09,"spf":"NaN","id":39832467},{"atb":[[1.82,0],[1.8,276.23],[1.79,25.32]],"id":40072523}],"con":true,"img":false}]}
{"op":"mcm","clk":"5353779225","pt":1646218387662,"mc":[{"id":"1.195453779","rc":[{"atb":[[1.59,0]],"id":38247337}],"con":true,"img":false}]}
{"op":"mcm","clk":"5353779233","pt":1646218387769,"mc":[{"id":"1.195453779","rc":[{"atb":[[1.57,66.19]],"id":38247337}],"con":true,"img":false}]}
{"op":"mcm","clk":"5353779468","pt":1646218390175,"mc":[{"id":"1.195453779","rc":[{"atb":[[1.31,289.62]],"id":39786303},{"atb":[[1.56,89.29]],"id":38247337},{"atb":[[1.77,64.94]],"id":40072523}],"con":true,"img":false}]}
{"op":"mcm","clk":"5353780327","pt":1646218400180,"mc":[{"id":"1.195453779","rc":[{"atb":[[1.27,250]],"id":39786303},{"atb":[[1.54,138.89]],"id":38247337},{"atb":[[1.75,261.31]],"id":40072523}],"con":true,"img":false}]}
{"op":"mcm","clk":"5353781219","pt":1646218410212,"mc":[{"id":"1.195453779","rc":[{"atb":[[1.52,240.38]],"id":38247337},{"atb":[[1.73,171.23],[1.78,0],[1.76,63.15]],"id":40072523}],"con":true,"img":false}]}
{"op":"mcm","clk":"5353781974","pt":1646218418875,"mc":[{"id":"1.195453779","rc":[{"atb":[[1.45,0],[1.43,46.51]],"id":39832467}],"con":true,"img":false}]}
{"op":"mcm","clk":"5353782373","pt":1646218423296,"mc":[{"id":"1.195453779","rc":[{"atb":[[1.33,0],[1.35,229.97]],"id":39786303},{"atb":[[1.45,44.44]],"id":39832467},{"atl":[[3.2,0],[3.4,0],[3.3,0],[3.5,8]],"id":39832467},{"atb":[[1.15,98.04],[1.14,142.86]],"id":40622317},{"atb":[[1.82,24.39],[1.79,0]],"id":40072523}],"con":true,"img":false}]}
{"op":"mcm","clk":"5353782646","pt":1646218426832,"mc":[{"id":"1.195453779","rc":[{"atb":[[1.33,60.61],[1.35,172.83]],"id":39786303},{"atb":[[1.15,231.37],[1.14,0]],"id":40622317},{"atb":[[1.82,0],[1.79,25.32]],"id":40072523}],"con":true,"img":false}]}
{"op":"mcm","clk":"5353782721","pt":1646218427615,"mc":[{"id":"1.195453779","rc":[{"atl":[[3.35,0]],"id":39832467}],"con":true,"img":false}]}
{"op":"mcm","clk":"5353782733","pt":1646218427719,"mc":[{"id":"1.195453779","rc":[{"atl":[[3.8,15.38]],"id":39832467},{"atb":[[1.78,51.82],[1.76,0]],"id":40072523}],"con":true,"img":false}]}
{"op":"mcm","clk":"5353783214","pt":1646218433317,"mc":[{"id":"1.195453779","rc":[{"atb":[[1.43,116.28]],"id":39832467},{"atl":[[3.6,19.23]],"id":39832467}],"con":true,"img":false}]}
{"op":"mcm","clk":"5353784046","pt":1646218443319,"mc":[{"id":"1.195453779","rc":[{"atl":[[3.7,27.78]],"id":39832467}],"con":true,"img":false}]}
{"op":"mcm","clk":"5353784155","pt":1646218444515,"mc":[{"id":"1.195453779","rc":[{"atb":[[6.2,1.66]],"id":37495332}],"con":true,"img":false}]}
{"op":"mcm","clk":"5353784859","pt":1646218453366,"mc":[{"id":"1.195453779","rc":[{"atl":[[3.8,60.02]],"id":39832467}],"con":true,"img":false}]}
{"op":"mcm","clk":"5353786103","pt":1646218467670,"mc":[{"id":"1.195453779","rc":[{"atl":[[3.8,44.64]],"id":39832467}],"con":true,"img":false}]}
{"op":"mcm","clk":"5353786115","pt":1646218467770,"mc":[{"id":"1.195453779","rc":[{"atl":[[3.55,15.38]],"id":39832467}],"con":true,"img":false}]}
{"op":"mcm","clk":"5353790116","pt":1646218503660,"mc":[{"id":"1.195453779","rc":[{"atb":[[1.25,0],[1.3,0],[1.35,0]],"id":39786303},{"atl":[[2.8,0],[4,0],[3,0],[2.6,0],[3.5,0]],"id":39786303},{"atb":[[1.6,0],[1.55,0],[1.65,0]],"id":38247337},{"atl":[[3.45,0],[3.95,0],[4.9,0],[2.98,0],[5.9,0]],"id":38247337},{"spn":2.45,"spf":"NaN","id":38247337},{"atb":[[2.82,0],[2.92,0],[3.05,0]],"id":42256449},{"atl":[[32,0],[10.5,3.74],[21,0],[8.2,17.36],[15.5,0]],"id":42256449},{"atb":[[4.3,0],[3.9,0],[3.65,0]],"id":40812693},{"atl":[[32,0],[21,0],[55,0],[110,0],[15.5,8.62]],"id":40812693},{"atb":[[4.5,0],[5,0],[5.5,0]],"id":37495332},{"atl":[[18.5,0],[85,0],[170,0],[44,0],[27,0]],"id":37495332},{"spn":14.1,"spf":"NaN","id":37495332},{"atb":[[1.4,0],[1.3,0],[1.35,0]],"id":39832467},{"atl":[[4.3,0],[2.86,0],[2.66,0],[3.15,0],[3.65,0]],"id":39832467},{"spn":2.38,"spf":"NaN","id":39832467},{"atb":[[1.01,0],[1.11,250],[1.06,0]],"id":40622317},{"atl":[[2.36,0],[2.56,0],[2.96,0],[2.16,0],[2.76,0]],"id":40622317},{"atb":[[1.8,125],[1.85,0],[1.75,100]],"id":40072523},{"atl":[[4.5,0],[9,0],[5.5,0],[7,20.83],[3.75,0]],"id":40072523},{"spn":3.75,"spf":"NaN","id":40072523}],"con":true,"img":false}]}
{"op":"mcm","clk":"5353790135","pt":1646218503816,"mc":[{"id":"1.195453779","rc":[{"atl":[[3.4,41.67],[3.25,15.03]],"id":39832467}],"con":true,"img":false}]}
{"op":"mcm","clk":"5353790527","pt":1646218507718,"mc":[{"id":"1.195453779","rc":[{"atb":[[1.66,0]],"id":38247337},{"atb":[[2.84,0]],"id":42256449},{"atb":[[4.4,22.06]],"id":40812693},{"atb":[[1.86,0]],"id":40072523}],"con":true,"img":false}]}
{"op":"mcm","clk":"5353790540","pt":1646218507815,"mc":[{"id":"1.195453779","rc":[{"atb":[[1.6,70.03]],"id":38247337},{"atb":[[2.6,22.82]],"id":42256449},{"atb":[[4.3,10.72]],"id":40812693},{"atb":[[1.81,53.82]],"id":40072523}],"con":true,"img":false}]}
{"op":"mcm","clk":"5353790606","pt":1646218508393,"mc":[{"id":"1.195453779","rc":[{"atb":[[1.25,483.95],[1.3,403.29],[1.35,172.83]],"id":39786303},{"atl":[[2.8,6.71],[4,16.13],[3,12.09],[2.6,7.56],[3.5,9.67]],"id":39786303},{"atb":[[1.6,271.68],[1.55,219.97],[1.65,93.06]],"id":38247337},{"atl":[[3.45,4.93],[3.95,8.2],[4.9,6.2],[2.98,6.1],[5.9,9.87]],"id":38247337},{"atb":[[2.82,66.47],[2.92,63.01],[3.05,29.51]],"id":42256449},{"atl":[[32,1.55],[10.5,5.02],[21,1.2],[8.2,19.03],[15.5,1.66]],"id":42256449},{"atb":[[4.3,29.05],[3.9,41.71],[3.65,45.65]],"id":40812693},{"atl":[[32,0.77],[21,0.6],[55,0.44],[110,0.44],[15.5,9.45]],"id":40812693},{"atb":[[4.5,34.56],[5,30.24],[5.5,13.44]],"id":37495332},{"atl":[[18.5,0.69],[85,0.28],[170,0.28],[44,0.56],[27,0.46]],"id":37495332},{"atb":[[1.4,151.23],[1.3,403.29],[1.35,345.68]],"id":39832467},{"atl":[[4.3,14.66],[2.86,6.5],[2.66,7.28],[3.15,11.25],[3.65,9.12]],"id":39832467},{"atb":[[1.01,12098.75],[1.11,799.94],[1.06,2016.45]],"id":40622317},{"atl":[[2.36,8.89],[2.56,15.51],[2.96,24.69],[2.16,10.43],[2.76,13.75]],"id":40622317},{"atb":[[1.8,276.23],[1.85,71.17],[1.75,261.31]],"id":40072523},{"atl":[[4.5,3.45],[9,6.04],[5.5,5.37],[7,24.86],[3.75,4.39]],"id":40072523}],"con":true,"img":false}]}
{"op":"mcm","clk":"5353790627","pt":1646218508550,"mc":[{"id":"1.195453779","rc":[{"atl":[[2.04,0],[2.88,0],[2.06,60],[2.52,65.79],[1.86,2]],"id":39786303},{"atb":[[1.63,66.2],[1.53,0]],"id":38247337},{"atl":[[3.35,62.36],[3.4,31.25],[2.96,3]],"id":38247337},{"atb":[[2.92,108.47],[3,62.5]],"id":42256449},{"atl":[[11,0],[8.4,13.51]],"id":42256449},{"atb":[[4.6,5.56],[3.35,0],[3,27.78],[4.9,1.66]],"id":40812693},{"atb":[[4.1,0],[1.29,28.78]],"id":37495332},{"atl":[[22,0],[24,0],[27,1.46]],"id":37495332},{"atb":[[1.48,0],[1.53,88.88]],"id":39832467},{"atl":[[3.5,0],[3.2,9.09]],"id":39832467},{"atl":[[1.96,0],[1.63,31.75],[1.86,116.28],[1.65,0]],"id":40622317},{"atb":[[1.8,151.23],[1.68,118.77]],"id":40072523},{"atl":[[5.4,3]],"id":40072523}],"con":true,"img":false}]}
{"op":"mcm","clk":"5353790651","pt":1646218508757,"mc":[{"id":"1.195453779","rc":[{"atl":[[2.94,3]],"id":38247337},{"atl":[[5.3,3]],"id":40072523}],"con":true,"img":false}]}
{"op":"mcm","clk":"5353790678","pt":1646218508918,"mc":[{"id":"1.195453779","rc":[{"atl":[[1.78,3],[1.86,0]],"id":39786303},{"atl":[[2.92,4]],"id":38247337},{"atl":[[26,0]],"id":37495332},{"atl":[[5.2,4]],"id":40072523}],"con":true,"img":false}]}
{"op":"mcm","clk":"5353791001","pt":1646218511144,"mc":[{"id":"1.195453779","rc":[{"atb":[[1.7,11.91]],"id":38247337},{"atb":[[1.52,16.03]],"id":39832467},{"atb":[[1.9,9.26]],"id":40072523}],"con":true,"img":false}]}
{"op":"mcm","clk":"5353791465","pt":1646218514725,"mc":[{"id":"1.195453779","rc":[{"atl":[[1.78,0]],"id":39786303},{"atl":[[2.9,3]],"id":38247337},{"atl":[[5.1,2]],"id":40072523}],"con":true,"img":false}]}
{"op":"mcm","clk":"5353791475","pt":1646218514833,"mc":[{"id":"1.195453779","rc":[{"atl":[[2.06,41.13],[2.1,18.18]],"id":39786303},{"atb":[[1.6,305.01],[1.58,0]],"id":38247337},{"atl":[[2.94,0],[2.92,0],[2.96,0]],"id":38247337},{"atl":[[5.2,0]],"id":40072523}],"con":true,"img":false}]}
{"op":"mcm","clk":"5353791503","pt":1646218515034,"mc":[{"id":"1.195453779","rc":[{"atl":[[2.08,0]],"id":39786303},{"atl":[[5.6,11.9],[5.1,0]],"id":40072523}],"con":true,"img":false}]}
{"op":"mcm","clk":"5353791523","pt":1646218515135,"mc":[{"id":"1.195453779","rc":[{"atl":[[2.9,0]],"id":38247337}],"con":true,"img":false}]}
{"op":"mcm","clk":"5353791575","pt":1646218515553,"mc":[{"id":"1.195453779","rc":[{"atb":[[4.9,0]],"id":40812693}],"con":true,"img":false}]}
{"op":"mcm","clk":"5353791598","pt":1646218515760,"mc":[{"id":"1.195453779","rc":[{"atb":[[4.7,1.66]],"id":40812693}],"con":true,"img":false}]}
{"op":"mcm","clk":"5353791784","pt":1646218517162,"mc":[{"id":"1.195453779","rc":[{"atb":[[1.69,10.89]],"id":38247337},{"atb":[[1.57,13.18]],"id":39832467},{"atb":[[1.89,8.45]],"id":40072523}],"con":true,"img":false}]}
{"op":"mcm","clk":"5353791854","pt":1646218517737,"mc":[{"id":"1.195453779","rc":[{"atl":[[2.06,0]],"id":39786303},{"atl":[[25,2.72]],"id":37495332},{"atb":[[1.49,96.88]],"id":39832467}],"con":true,"img":false}]}
{"op":"mcm","clk":"5353791865","pt":1646218517842,"mc":[{"id":"1.195453779","rc":[{"atl":[[2.1,59.31]],"id":39786303},{"atl":[[27,4.18]],"id":37495332},{"atb":[[1.44,86.07]],"id":39832467}],"con":true,"img":false}]}
{"op":"mcm","clk":"5353791891","pt":1646218518051,"mc":[{"id":"1.195453779","rc":[{"atb":[[1.63,0],[1.67,93.07]],"id":38247337},{"atl":[[3.2,30.83],[3.35,19.81]],"id":38247337},{"atb":[[2.92,63.01],[3.35,5]],"id":42256449},{"atb":[[3,0],[3.55,39.22]],"id":40812693},{"atb":[[1.29,0],[3.3,30.11]],"id":37495332},{"atb":[[1.58,16.03],[1.53,0]],"id":39832467},{"atl":[[1.73,136.99],[1.86,0]],"id":40622317},{"atb":[[1.82,53.83],[1.68,0]],"id":40072523}],"con":true,"img":false}]}
{"op":"mcm","clk":"5353791957","pt":1646218518467,"mc":[{"id":"1.195453779","rc":[{"atb":[[4.4,36.77]],"id":40812693},{"atl":[[29,1.79]],"id":37495332}],"con":true,"img":false}]}
{"op":"mcm","clk":"5353791973","pt":1646218518570,"mc":[{"id":"1.195453779","rc":[{"atb":[[4.4,14.71]],"id":40812693},{"atl":[[3.3,21.74]],"id":39832467},{"atl":[[1.65,76.92]],"id":40622317}],"con":true,"img":false}]}
{"op":"mcm","clk":"5353792044","pt":1646218519191,"mc":[{"id":"1.195453779","rc":[{"atb":[[1.69,0]],"id":38247337},{"atb":[[1.57,0]],"id":39832467}],"con":true,"img":false}]}
{"op":"mcm","clk":"5353792486","pt":1646218522691,"mc":[{"id":"1.195453779","rc":[{"atl":[[1.71,0]],"id":40622317},{"atl":[[5.5,9.37]],"id":40072523}],"con":true,"img":false}]}
{"op":"mcm","clk":"5353792501","pt":1646218522780,"mc":[{"id":"1.195453779","rc":[{"atl":[[3.8,0]],"id":39832467}],"con":true,"img":false}]}
{"op":"mcm","clk":"5353792558","pt":1646218523147,"mc":[{"id":"1.195453779","rc":[{"atb":[[3.3,0]],"id":37495332}],"con":true,"img":false}]}
{"op":"mcm","clk":"5353792573","pt":1646218523253,"mc":[{"id":"1.195453779","rc":[{"atb":[[1.63,158.73],[1.67,0]],"id":38247337},{"atb":[[3.35,1.66],[3.3,18.72]],"id":42256449},{"atb":[[2.78,33.34]],"id":37495332},{"atb":[[1.58,0],[1.53,44.44]],"id":39832467}],"con":true,"img":false}]}
{"op":"mcm","clk":"5353792786","pt":1646218524861,"mc":[{"id":"1.195453779","rc":[{"atl":[[2.14,43.86]],"id":39786303},{"atb":[[1.58,86.21]],"id":38247337}],"con":true,"img":false}]}
{"op":"mcm","clk":"5353792825","pt":1646218525172,"mc":[{"id":"1.195453779","rc":[{"atb":[[1.52,30.48]],"id":39832467}],"con":true,"img":false}]}
{"op":"mcm","clk":"5353793279","pt":1646218528463,"mc":[{"id":"1.195453779","rc":[{"atb":[[4.2,0]],"id":40812693},{"atl":[[32,2.42]],"id":37495332},{"atl":[[1.67,186.57]],"id":40622317}],"con":true,"img":false}]}
{"op":"mcm","clk":"5353793293","pt":1646218528566,"mc":[{"id":"1.195453779","rc":[{"atb":[[4.2,23.44]],"id":40812693},{"atl":[[3.4,72.92]],"id":39832467},{"atl":[[1.67,111.94]],"id":40622317}],"con":true,"img":false}]}
{"op":"mcm","clk":"5353793310","pt":1646218528671,"mc":[{"id":"1.195453779","rc":[{"atb":[[1.52,0]],"id":38247337},{"atl":[[3.7,0]],"id":39832467},{"atb":[[1.82,78.22],[1.79,0]],"id":40072523}],"con":true,"img":false}]}
{"op":"mcm","clk":"5353793332","pt":1646218528777,"mc":[{"id":"1.195453779","rc":[{"atl":[[5.6,9.9],[5.3,0],[5.5,5.37],[5.4,0]],"id":40072523}],"con":true,"img":false}]}
{"op":"mcm","clk":"5353793457","pt":1646218529559,"mc":[{"id":"1.195453779","rc":[{"atb":[[1.82,53.83],[1.79,25.32]],"id":40072523},{"atl":[[5.6,11.9]],"id":40072523}],"con":true,"img":false}]}
{"op":"mcm","clk":"5353793585","pt":1646218530486,"mc":[{"id":"1.195453779","rc":[{"atl":[[5.5,7.37]],"id":40072523}],"con":true,"img":false}]}
{"op":"mcm","clk":"5353793697","pt":1646218531370,"mc":[{"id":"1.195453779","rc":[{"atb":[[1.69,10.89]],"id":38247337}],"con":true,"img":false}]}
{"op":"mcm","clk":"5353793991","pt":1646218533758,"mc":[{"id":"1.195453779","rc":[{"atl":[[5.4,4]],"id":40072523}],"con":true,"img":false}]}
{"op":"mcm","clk":"5353794124","pt":1646218534792,"mc":[{"id":"1.195453779","rc":[{"atl":[[2.18,63.56]],"id":39786303}],"con":true,"img":false}]}
{"op":"mcm","clk":"5353794141","pt":1646218534897,"mc":[{"id":"1.195453779","rc":[{"atb":[[1.56,133.93]],"id":38247337}],"con":true,"img":false}]}
{"op":"mcm","clk":"5353794495","pt":1646218537572,"mc":[{"id":"1.195453779","rc":[{"atb":[[1.7,0]],"id":38247337},{"atb":[[1.9,0]],"id":40072523}],"con":true,"img":false}]}
{"op":"mcm","clk":"5353794507","pt":1646218537662,"mc":[{"id":"1.195453779","rc":[{"atl":[[3.35,0]],"id":38247337},{"atl":[[3.55,0]],"id":39832467},{"atb":[[1.81,0]],"id":40072523}],"con":true,"img":false}]}
{"op":"mcm","clk":"5353794526","pt":1646218537773,"mc":[{"id":"1.195453779","rc":[{"atl":[[3.15,19.81]],"id":38247337},{"atl":[[3.35,15.38]],"id":39832467},{"atb":[[1.82,0],[1.78,159.48],[1.86,53.82]],"id":40072523}],"con":true,"img":false}]}
{"op":"mcm","clk":"5353794614","pt":1646218538498,"mc":[{"id":"1.195453779","rc":[{"atl":[[36,3.57]],"id":37495332},{"atl":[[3.5,50]],"id":39832467},{"atl":[[1.69,181.16]],"id":40622317}],"con":true,"img":false}]}
{"op":"mcm","clk":"5353794628","pt":1646218538600,"mc":[{"id":"1.195453779","rc":[{"atb":[[4,41.67]],"id":40812693}],"con":true,"img":false}]}
{"op":"mcm","clk":"5353794885","pt":1646218540480,"mc":[{"id":"1.195453779","rc":[{"atl":[[2.12,0],[2.16,0]],"id":39786303},{"atl":[[28,0]],"id":37495332},{"atb":[[1.89,0]],"id":40072523},{"atl":[[5.3,3]],"id":40072523}],"con":true,"img":false}]}
{"op":"mcm","clk":"5353794912","pt":1646218540691,"mc":[{"id":"1.195453779","rc":[{"atl":[[3.6,0]],"id":39832467}],"con":true,"img":false}]}
{"op":"mcm","clk":"5353795368","pt":1646218544796,"mc":[{"id":"1.195453779","rc":[{"atb":[[1.54,0]],"id":38247337}],"con":true,"img":false}]}
{"op":"mcm","clk":"5353795380","pt":1646218544897,"mc":[{"id":"1.195453779","rc":[{"atl":[[2.22,102.46]],"id":39786303},{"atb":[[1.54,231.48]],"id":38247337}],"con":true,"img":false}]}
{"op":"mcm","clk":"5353795559","pt":1646218546302,"mc":[{"id":"1.195453779","rc":[{"atb":[[1.9,8.35]],"id":40072523}],"con":true,"img":false}]}
{"op":"mcm","clk":"5353795698","pt":1646218547392,"mc":[{"id":"1.195453779","rc":[{"atb":[[1.82,24.39],[1.79,0]],"id":40072523},{"atl":[[5.6,9.9],[5.3,0],[5.5,5.37],[5.4,0]],"id":40072523}],"con":true,"img":false}]}
{"op":"mcm","clk":"5353795734","pt":1646218547703,"mc":[{"id":"1.195453779","rc":[{"atl":[[2.1,18.18]],"id":39786303},{"atb":[[1.6,234.97]],"id":38247337},{"atl":[[1.66,0]],"id":40622317},{"atl":[[5.6,0]],"id":40072523}],"con":true,"img":false}]}
{"op":"mcm","clk":"5353795751","pt":1646218547816,"mc":[{"id":"1.195453779","rc":[{"atl":[[2.12,41.13]],"id":39786303},{"atb":[[1.66,70.03]],"id":38247337},{"atl":[[1.64,43.59]],"id":40622317},{"atl":[[5.2,9.9]],"id":40072523}],"con":true,"img":false}]}
{"op":"mcm","clk":"5353795923","pt":1646218549303,"mc":[{"id":"1.195453779","rc":[{"atb":[[1.69,0]],"id":38247337}],"con":true,"img":false}]}
{"op":"mcm","clk":"5353796164","pt":1646218551381,"mc":[{"id":"1.195453779","rc":[{"atl":[[6.8,3.45],[7,0]],"id":42256449},{"atl":[[12.5,0],[13,1.67]],"id":40812693},{"atb":[[1.45,0],[1.48,41.67]],"id":39832467}],"con":true,"img":false}]}
{"op":"mcm","clk":"5353796172","pt":1646218551483,"mc":[{"id":"1.195453779","rc":[{"atl":[[13,5.67],[14,0]],"id":40812693}],"con":true,"img":false}]}
{"op":"mcm","clk":"5353796181","pt":1646218551590,"mc":[{"id":"1.195453779","rc":[{"atl":[[1.62,32.26],[1.63,0]],"id":40622317},{"atb":[[1.82,0],[1.79,25.32]],"id":40072523},{"atl":[[5.6,3]],"id":40072523}],"con":true,"img":false}]}
{"op":"mcm","clk":"5353796192","pt":1646218551691,"mc":[{"id":"1.195453779","rc":[{"atl":[[13,1.67],[14,7.69]],"id":40812693}],"con":true,"img":false}]}
{"op":"mcm","clk":"5353796589","pt":1646218555205,"mc":[{"id":"1.195453779","rc":[{"atb":[[1.7,10.74]],"id":38247337}],"con":true,"img":false}]}
{"op":"mcm","clk":"5353796879","pt":1646218557708,"mc":[{"id":"1.195453779","rc":[{"atl":[[2.72,0]],"id":39786303},{"atb":[[1.57,0]],"id":38247337},{"atb":[[2.6,0]],"id":42256449},{"atb":[[4.3,18.33]],"id":40812693}],"con":true,"img":false}]}
{"op":"mcm","clk":"5353796896","pt":1646218557832,"mc":[{"id":"1.195453779","rc":[{"atl":[[2.5,23.12]],"id":39786303},{"atb":[[1.59,66.19]],"id":38247337},{"atb":[[2.84,22.82]],"id":42256449},{"atb":[[4.4,25.43]],"id":40812693}],"con":true,"img":false}]}
{"op":"mcm","clk":"5353797025","pt":1646218558810,"mc":[{"id":"1.195453779","rc":[{"atl":[[1.63,31.75]],"id":40622317},{"atb":[[1.82,24.39],[1.79,0]],"id":40072523},{"atl":[[5.6,0],[5.5,8.37]],"id":40072523}],"con":true,"img":false}]}
{"op":"mcm","clk":"5353797039","pt":1646218558905,"mc":[{"id":"1.195453779","rc":[{"atl":[[1.62,0]],"id":40622317}],"con":true,"img":false}]}
{"op":"mcm","clk":"5353797050","pt":1646218559013,"mc":[{"id":"1.195453779","rc":[{"atl":[[5.5,5.37]],"id":40072523}],"con":true,"img":false}]}
{"op":"mcm","clk":"5353797279","pt":1646218561310,"mc":[{"id":"1.195453779","rc":[{"atl":[[14,11.54]],"id":40812693},{"atb":[[1.46,108.7]],"id":39832467}],"con":true,"img":false}]}
{"op":"mcm","clk":"5353797816","pt":1646218566231,"mc":[{"id":"1.195453779","rc":[{"spn":1.74,"spf":"NaN","id":39786303},{"spn":2.34,"spf":"NaN","id":38247337},{"spn":5.07,"spf":"NaN","id":42256449},{"atl":[[13.5,0],[14.5,0],[15.5,0.83]],"id":40812693},{"spn":8.85,"spf":"NaN","id":40812693},{"spn":12.35,"spf":"NaN","id":37495332},{"atb":[[1.41,0],[1.43,0],[1.39,0]],"id":39832467},{"spn":2.09,"spf":"NaN","id":39832467},{"spn":1.39,"spf":"NaN","id":40622317},{"spn":2.82,"spf":"NaN","id":40072523}],"con":true,"img":false}]}
{"op":"mcm","clk":"5353797841","pt":1646218566435,"mc":[{"id":"1.195453779","rc":[{"atl":[[14,3.85],[14.5,7.41]],"id":40812693}],"con":true,"img":false}]}
{"op":"mcm","clk":"5353798061","pt":1646218568835,"mc":[{"id":"1.195453779","rc":[{"atb":[[1.8,213.73]],"id":40072523}],"con":true,"img":false}]}
{"op":"mcm","clk":"5353798210","pt":1646218570447,"mc":[{"id":"1.195453779","rc":[{"atb":[[1.73,0],[1.77,0],[1.75,161.31]],"id":40072523}],"con":true,"img":false}]}
{"op":"mcm","clk":"5353798300","pt":1646218571257,"mc":[{"id":"1.195453779","rc":[{"atl":[[1.62,32.26],[1.63,0]],"id":40622317},{"atb":[[1.82,0],[1.8,151.23],[1.79,25.32]],"id":40072523},{"atl":[[5.6,2]],"id":40072523}],"con":true,"img":false}]}
{"op":"mcm","clk":"5353798311","pt":1646218571329,"mc":[{"id":"1.195453779","rc":[{"atl":[[15,8.08]],"id":40812693},{"atb":[[1.44,256.52]],"id":39832467}],"con":true,"img":false}]}
{"op":"mcm","clk":"5353798322","pt":1646218571440,"mc":[{"id":"1.195453779","rc":[{"atl":[[5.5,9.37]],"id":40072523}],"con":true,"img":false}]}
{"op":"mcm","clk":"5353798391","pt":1646218572222,"mc":[{"id":"1.195453779","rc":[{"atb":[[1.54,74.85]],"id":40072523}],"con":true,"img":false}]}
{"op":"mcm","clk":"5353798402","pt":1646218572322,"mc":[{"id":"1.195453779","rc":[{"atb":[[1.78,107.66]],"id":40072523}],"con":true,"img":false}]}
{"op":"mcm","clk":"5353798411","pt":1646218572427,"mc":[{"id":"1.195453779","rc":[{"atl":[[5.4,3]],"id":40072523}],"con":true,"img":false}]}
{"op":"mcm","clk":"5353798552","pt":1646218574041,"mc":[{"id":"1.195453779","rc":[{"atb":[[1.7,22.65]],"id":38247337}],"con":true,"img":false}]}
{"op":"mcm","clk":"5353798561","pt":1646218574148,"mc":[{"id":"1.195453779","rc":[{"atb":[[1.9,17.61]],"id":40072523}],"con":true,"img":false}]}
{"op":"mcm","clk":"5353798908","pt":1646218577661,"mc":[{"id":"1.195453779","rc":[{"atl":[[15,5.36]],"id":40812693},{"atb":[[1.86,0]],"id":40072523}],"con":true,"img":false}]}
{"op":"mcm","clk":"5353798916","pt":1646218577765,"mc":[{"id":"1.195453779","rc":[{"atl":[[14,6.57]],"id":40812693},{"atb":[[1.64,53.82]],"id":40072523}],"con":true,"img":false}]}
{"op":"mcm","clk":"5353798956","pt":1646218578234,"mc":[{"id":"1.195453779","rc":[{"atl":[[6.8,0],[7,3.33]],"id":42256449},{"atl":[[12.5,1.74]],"id":40812693},{"atb":[[1.45,44.44],[1.48,0]],"id":39832467},{"atl":[[5.3,4]],"id":40072523}],"con":true,"img":false}]}
{"op":"mcm","clk":"5353798974","pt":1646218578444,"mc":[{"id":"1.195453779","rc":[{"atl":[[12.5,3.74],[14.5,0]],"id":40812693}],"con":true,"img":false}]}
{"op":"mcm","clk":"5353799003","pt":1646218578753,"mc":[{"id":"1.195453779","rc":[{"atb":[[1.46,0]],"id":39832467},{"atb":[[1.82,24.39]],"id":40072523},{"atl":[[5.3,0],[5.4,0],[5.6,0],[5.5,5.37]],"id":40072523}],"con":true,"img":false}]}
{"op":"mcm","clk":"5353799155","pt":1646218580361,"mc":[{"id":"1.195453779","rc":[{"atb":[[1.9,9.26]],"id":40072523}],"con":true,"img":false}]}
{"op":"mcm","clk":"5353799501","pt":1646218583543,"mc":[{"id":"1.195453779","rc":[{"atl":[[12.5,1.74],[13.5,5.41]],"id":40812693}],"con":true,"img":false}]}
{"op":"mcm","clk":"5353799915","pt":1646218587651,"mc":[{"id":"1.195453779","rc":[{"atl":[[14,3.85]],"id":40812693},{"atb":[[1.49,0]],"id":39832467}],"con":true,"img":false}]}
{"op":"mcm","clk":"5353799924","pt":1646218587754,"mc":[{"id":"1.195453779","rc":[{"atl":[[16.5,2.72]],"id":40812693},{"atb":[[1.53,141.32]],"id":39832467}],"con":true,"img":false}]}
{"op":"mcm","clk":"5353799975","pt":1646218588278,"mc":[{"id":"1.195453779","rc":[{"atl":[[13.5,9.41]],"id":40812693},{"atb":[[1.43,116.28],[1.52,16.03]],"id":39832467},{"atb":[[1.89,8.45]],"id":40072523}],"con":true,"img":false}]}
{"op":"mcm","clk":"5353800016","pt":1646218588651,"mc":[{"id":"1.195453779","rc":[{"atb":[[1.52,0]],"id":39832467}],"con":true,"img":false}]}
{"op":"mcm","clk":"5353800050","pt":1646218588980,"mc":[{"id":"1.195453779","rc":[{"atl":[[13,0],[14,0],[15,0]],"id":40812693}],"con":true,"img":false}]}
{"op":"mcm","clk":"5353800067","pt":1646218589158,"mc":[{"id":"1.195453779","rc":[{"atl":[[13.5,4],[15.5,7.73]],"id":40812693}],"con":true,"img":false}]}
{"op":"mcm","clk":"5353800083","pt":1646218589270,"mc":[{"id":"1.195453779","rc":[{"atb":[[1.82,0]],"id":40072523},{"atl":[[5.6,2]],"id":40072523}],"con":true,"img":false}]}
{"op":"mcm","clk":"5353800103","pt":1646218589473,"mc":[{"id":"1.195453779","rc":[{"atl":[[5.5,8.37]],"id":40072523}],"con":true,"img":false}]}
{"op":"mcm","clk":"5353800143","pt":1646218589744,"mc":[{"id":"1.195453779","rc":[{"atl":[[5.4,4]],"id":40072523}],"con":true,"img":false}]}
{"op":"mcm","clk":"5353800676","pt":1646218595274,"mc":[{"id":"1.195453779","rc":[{"atb":[[1.57,13.18]],"id":39832467}],"con":true,"img":false}]}
{"op":"mcm","clk":"5353800696","pt":1646218595484,"mc":[{"id":"1.195453779","rc":[{"atb":[[1.58,44.44],[1.53,96.88]],"id":39832467}],"con":true,"img":false}]}
{"op":"mcm","clk":"5353800871","pt":1646218597683,"mc":[{"id":"1.195453779","rc":[{"atl":[[7.6,0]],"id":42256449},{"atb":[[1.64,0]],"id":40072523}],"con":true,"img":false}]}
{"op":"mcm","clk":"5353800883","pt":1646218597786,"mc":[{"id":"1.195453779","rc":[{"atl":[[8,6.22]],"id":42256449},{"atb":[[1.67,53.82]],"id":40072523}],"con":true,"img":false}]}
{"op":"mcm","clk":"5353800927","pt":1646218598263,"mc":[{"id":"1.195453779","rc":[{"atl":[[14.5,5.56]],"id":40812693},{"atb":[[1.41,182.93]],"id":39832467}],"con":true,"img":false}]}
{"op":"mcm","clk":"5353800948","pt":1646218598473,"mc":[{"id":"1.195453779","rc":[{"atl":[[14.5,11.3],[15.5,0.83]],"id":40812693}],"con":true,"img":false}]}
{"op":"mcm","clk":"5353800997","pt":1646218598998,"mc":[{"id":"1.195453779","rc":[{"atb":[[1.77,64.94]],"id":40072523}],"con":true,"img":false}]}
{"op":"mcm","clk":"5353801050","pt":1646218599469,"mc":[{"id":"1.195453779","rc":[{"atl":[[1.62,0],[1.63,31.75]],"id":40622317},{"atb":[[1.82,24.39]],"id":40072523},{"atl":[[5.3,4],[5.4,0],[5.6,0],[5.5,5.37]],"id":40072523}],"con":true,"img":false}]}
{"op":"mcm","clk":"5353801069","pt":1646218599686,"mc":[{"id":"1.195453779","rc":[{"atl":[[5.3,0]],"id":40072523}],"con":true,"img":false}]}
{"op":"mcm","clk":"5353801330","pt":1646218602394,"mc":[{"id":"1.195453779","rc":[{"atb":[[1.44,86.07],[1.45,0],[1.43,46.51]],"id":39832467},{"atl":[[2.82,3]],"id":39832467},{"atb":[[2.34,4]],"id":40072523},{"atl":[[6.4,3.7],[6.2,0],[5.9,9.78]],"id":40072523}],"con":true,"img":false}]}
{"op":"mcm","clk":"5353801350","pt":1646218602602,"mc":[{"id":"1.195453779","rc":[{"atl":[[2.8,2]],"id":39832467},{"atb":[[2.58,2],[2.34,0]],"id":40072523}],"con":true,"img":false}]}
{"op":"mcm","clk":"5353801397","pt":1646218602968,"mc":[{"id":"1.195453779","rc":[{"atb":[[1.45,44.44]],"id":39832467},{"atl":[[2.8,0],[2.82,0]],"id":39832467},{"atb":[[2.58,0]],"id":40072523},{"atl":[[5.9,13.86]],"id":40072523}],"con":true,"img":false}]}
{"op":"mcm","clk":"5353801439","pt":1646218603385,"mc":[{"id":"1.195453779","rc":[{"atb":[[4,0],[4.3,0],[3.9,0],[3.75,7.27]],"id":37495332},{"atl":[[6,4],[5.9,9.78]],"id":40072523}],"con":true,"img":false}]}
{"op":"mcm","clk":"5353801533","pt":1646218604326,"mc":[{"id":"1.195453779","rc":[{"atb":[[1.9,0]],"id":40072523}],"con":true,"img":false}]}
{"op":"mcm","clk":"5353801543","pt":1646218604389,"mc":[{"id":"1.195453779","rc":[{"atb":[[1.57,27.8]],"id":39832467}],"con":true,"img":false}]}
{"op":"mcm","clk":"5353801567","pt":1646218604600,"mc":[{"id":"1.195453779","rc":[{"atb":[[3.8,0]],"id":37495332},{"atl":[[1.62,32.26],[1.63,0]],"id":40622317},{"atb":[[1.82,0]],"id":40072523},{"atl":[[5.7,2]],"id":40072523}],"con":true,"img":false}]}
{"op":"mcm","clk":"5353801589","pt":1646218604808,"mc":[{"id":"1.195453779","rc":[{"atl":[[5.6,2]],"id":40072523}],"con":true,"img":false}]}
{"op":"mcm","clk":"5353801760","pt":1646218606491,"mc":[{"id":"1.195453779","rc":[{"atb":[[1.53,0]],"id":39832467}],"con":true,"img":false}]}
{"op":"mcm","clk":"5353801768","pt":1646218606595,"mc":[{"id":"1.195453779","rc":[{"atb":[[1.49,96.88]],"id":39832467}],"con":true,"img":false}]}
{"op":"mcm","clk":"5353801798","pt":1646218606804,"mc":[{"id":"1.195453779","rc":[{"atb":[[1.33,0],[1.35,229.97]],"id":39786303},{"atb":[[1.45,0]],"id":39832467},{"atl":[[2.96,3]],"id":39832467},{"atb":[[1.15,98.04],[1.14,142.86]],"id":40622317},{"atl":[[1.33,3]],"id":40622317},{"atb":[[1.82,24.39],[2.38,2]],"id":40072523},{"atl":[[6.4,0],[5.6,0],[6,0],[5.7,0],[6.6,3.57]],"id":40072523}],"con":true,"img":false}]}
{"op":"mcm","clk":"5353801820","pt":1646218607009,"mc":[{"id":"1.195453779","rc":[{"atl":[[2.94,2]],"id":39832467},{"atl":[[1.32,3]],"id":40622317},{"atb":[[2.38,0],[2.58,2]],"id":40072523}],"con":true,"img":false}]}
{"op":"mcm","clk":"5353801844","pt":1646218607315,"mc":[{"id":"1.195453779","rc":[{"atb":[[1.63,0],[1.67,93.07]],"id":38247337},{"atb":[[2.78,0],[3.3,33.34]],"id":37495332}],"con":true,"img":false}]}
{"op":"mcm","clk":"5353801882","pt":1646218607701,"mc":[{"id":"1.195453779","rc":[{"atl":[[3.35,0]],"id":39832467}],"con":true,"img":false}]}
{"op":"mcm","clk":"5353801892","pt":1646218607805,"mc":[{"id":"1.195453779","rc":[{"atl":[[3.45,15.38]],"id":39832467}],"con":true,"img":false}]}
{"op":"mcm","clk":"5353801940","pt":1646218608312,"mc":[{"id":"1.195453779","rc":[{"atl":[[15.5,9.45]],"id":40812693}],"con":true,"img":false}]}
{"op":"mcm","clk":"5353802072","pt":1646218609422,"mc":[{"id":"1.195453779","rc":[{"atb":[[1.7,11.91]],"id":38247337},{"atb":[[1.57,14.62]],"id":39832467},{"atb":[[1.89,0]],"id":40072523}],"con":true,"img":false}]}
{"op":"mcm","clk":"5353802097","pt":1646218609581,"mc":[{"id":"1.195453779","rc":[{"atl":[[2.92,3]],"id":39832467},{"atl":[[1.31,2]],"id":40622317},{"atb":[[2.6,2]],"id":40072523}],"con":true,"img":false}]}
{"op":"mcm","clk":"5353802117","pt":1646218609784,"mc":[{"id":"1.195453779","rc":[{"atl":[[2.9,2]],"id":39832467}],"con":true,"img":false}]}
{"op":"mcm","clk":"5353802427","pt":1646218613024,"mc":[{"id":"1.195453779","rc":[{"atb":[[1.41,121.95]],"id":39832467}],"con":true,"img":false}]}
{"op":"mcm","clk":"5353802462","pt":1646218613386,"mc":[{"id":"1.195453779","rc":[{"atb":[[3.65,18.87]],"id":37495332}],"con":true,"img":false}]}
{"op":"mcm","clk":"5353802587","pt":1646218614596,"mc":[{"id":"1.195453779","rc":[{"atl":[[1.3,3]],"id":40622317},{"atb":[[2.62,4]],"id":40072523}],"con":true,"img":false}]}
{"op":"mcm","clk":"5353802611","pt":1646218614805,"mc":[{"id":"1.195453779","rc":[{"atb":[[2.64,2]],"id":40072523}],"con":true,"img":false}]}
{"op":"mcm","clk":"5353802683","pt":1646218615521,"mc":[{"id":"1.195453779","rc":[{"atb":[[1.71,10.58]],"id":38247337},{"atb":[[1.52,14.45]],"id":39832467}],"con":true,"img":false}]}
{"op":"mcm","clk":"5353802816","pt":1646218616825,"mc":[{"id":"1.195453779","rc":[{"atb":[[1.33,151.52]],"id":39786303},{"atb":[[1.12,250]],"id":40622317},{"atl":[[7,12.36]],"id":40072523}],"con":true,"img":false}]}
{"op":"mcm","clk":"5353802919","pt":1646218617728,"mc":[{"id":"1.195453779","rc":[{"atb":[[3.15,3.87]],"id":42256449}],"con":true,"img":false}]}
{"op":"mcm","clk":"5353802929","pt":1646218617824,"mc":[{"id":"1.195453779","rc":[{"atb":[[3.25,23.61]],"id":42256449}],"con":true,"img":false}]}
{"op":"mcm","clk":"5353803432","pt":1646218623010,"mc":[{"id":"1.195453779","rc":[{"atb":[[1.58,60.75],[1.39,192.31],[1.52,47.07]],"id":39832467},{"atl":[[2.9,34.62],[2.66,23.59]],"id":39832467}],"con":true,"img":false}]}
{"op":"mcm","clk":"5353803454","pt":1646218623225,"mc":[{"id":"1.195453779","rc":[{"atb":[[1.68,10],[1.76,2.5],[1.72,5]],"id":39832467}],"con":true,"img":false}]}
{"op":"mcm","clk":"5353803460","pt":1646218623329,"mc":[{"id":"1.195453779","rc":[{"atb":[[1.27,0],[1.44,10],[1.39,104.39],[1.48,5],[1.35,357.46],[1.52,2.5]],"id":39786303},{"atl":[[2.1,81.92],[2.14,150.05]],"id":39786303},{"atb":[[1.85,2.5],[1.71,34.38],[1.81,5],[1.67,140.67],[1.77,10]],"id":38247337},{"atl":[[3.2,78.43],[2.98,29.9]],"id":38247337},{"atb":[[3.2,69.86],[3.3,37.85],[3.5,2.5]],"id":42256449},{"atl":[[7,16.66],[7.8,42.66]],"id":42256449},{"atb":[[4.4,51.85]],"id":40812693},{"atl":[[12,7.17],[13.5,6.5],[14.5,26.96],[15.5,14.45]],"id":40812693},{"atb":[[6.2,6.84],[5.3,33.48],[5.7,2.5]],"id":37495332},{"atb":[[1.67,47.08]],"id":39832467},{"atb":[[1.2,5],[1.15,173.83],[1.16,10],[1.11,549.94],[1.09,0],[1.13,450.55],[1.24,2.5]],"id":40622317},{"atl":[[4.6,5],[5,10],[3.7,5.6],[5.2,21.09],[4.2,2.5]],"id":40072523}],"con":true,"img":false}]}
{"op":"mcm","clk":"5353803467","pt":1646218623423,"mc":[{"id":"1.195453779","rc":[{"atb":[[3.55,29.41]],"id":37495332},{"atb":[[1.58,16.31]],"id":39832467}],"con":true,"img":false}]}
{"op":"mcm","clk":"5353803476","pt":1646218623535,"mc":[{"id":"1.195453779","rc":[{"atl":[[13.5,14.5],[14.5,21.22]],"id":40812693}],"con":true,"img":false}]}
{"op":"mcm","clk":"5353803511","pt":1646218623896,"mc":[{"id":"1.195453779","rc":[{"atl":[[8.2,32.92],[8.4,0]],"id":42256449},{"atl":[[65,2],[90,0]],"id":37495332}],"con":true,"img":false}]}
{"op":"mcm","clk":"5353803559","pt":1646218624529,"mc":[{"id":"1.195453779","rc":[{"atb":[[1.39,85.11]],"id":39786303},{"atb":[[3.25,20.27]],"id":42256449},{"atb":[[1.52,32.62]],"id":39832467}],"con":true,"img":false}]}
{"op":"mcm","clk":"5353803568","pt":1646218624632,"mc":[{"id":"1.195453779","rc":[{"atl":[[1.34,4],[1.3,0]],"id":40622317}],"con":true,"img":false}]}
{"op":"mcm","clk":"5353803710","pt":1646218626400,"mc":[{"id":"1.195453779","rc":[{"spn":1.81,"spf":"NaN","id":39786303},{"spn":2.41,"spf":"NaN","id":38247337},{"spn":5.25,"spf":"NaN","id":42256449},{"atl":[[16.5,0]],"id":40812693},{"spn":8.35,"spf":"NaN","id":40812693},{"spn":2.21,"spf":"NaN","id":39832467},{"spn":1.27,"spf":"NaN","id":40622317},{"spn":3.17,"spf":"NaN","id":40072523}],"con":true,"img":false}]}
{"op":"mcm","clk":"5353803722","pt":1646218626504,"mc":[{"id":"1.195453779","rc":[{"atl":[[14,2.72]],"id":40812693}],"con":true,"img":false}]}
{"op":"mcm","clk":"5353803757","pt":1646218626832,"mc":[{"id":"1.195453779","rc":[{"atb":[[1.31,370.27]],"id":39786303},{"atb":[[1.1,250]],"id":40622317},{"atl":[[7.4,11.72]],"id":40072523}],"con":true,"img":false}]}
{"op":"mcm","clk":"5353803825","pt":1646218627602,"mc":[{"id":"1.195453779","rc":[{"atb":[[1.66,0]],"id":38247337},{"atb":[[1.49,0]],"id":39832467}],"con":true,"img":false}]}
{"op":"mcm","clk":"5353803835","pt":1646218627701,"mc":[{"id":"1.195453779","rc":[{"atb":[[1.68,70.03]],"id":38247337},{"atb":[[1.53,96.88]],"id":39832467}],"con":true,"img":false}]}
{"op":"mcm","clk":"5353804087","pt":1646218630456,"mc":[{"id":"1.195453779","rc":[{"atb":[[1.42,17.9]],"id":39786303},{"atb":[[1.71,23.8]],"id":38247337},{"atb":[[3.4,3.13]],"id":42256449},{"atb":[[1.71,10.58]],"id":39832467}],"con":true,"img":false}]}
{"op":"mcm","clk":"5353804107","pt":1646218630617,"mc":[{"id":"1.195453779","rc":[{"atb":[[3.3,27.83],[3.45,5]],"id":42256449}],"con":true,"img":false}]}
{"op":"mcm","clk":"5353804344","pt":1646218633017,"mc":[{"id":"1.195453779","rc":[{"atb":[[1.37,250]],"id":39832467}],"con":true,"img":false}]}
{"op":"mcm","clk":"5353804379","pt":1646218633338,"mc":[{"id":"1.195453779","rc":[{"atb":[[1.39,63.74]],"id":39786303},{"atb":[[1.7,0]],"id":38247337}],"con":true,"img":false}]}
{"op":"mcm","clk":"5353804387","pt":1646218633436,"mc":[{"id":"1.195453779","rc":[{"atb":[[3.45,51.02]],"id":37495332}],"con":true,"img":false}]}
{"op":"mcm","clk":"5353804699","pt":1646218636612,"mc":[{"id":"1.195453779","rc":[{"atb":[[1.72,10.44]],"id":38247337},{"atb":[[3.35,0]],"id":42256449}],"con":true,"img":false}]}
{"op":"mcm","clk":"5353804713","pt":1646218636763,"mc":[{"id":"1.195453779","rc":[{"atb":[[3.55,1.66]],"id":42256449}],"con":true,"img":false}]}
{"op":"mcm","clk":"5353804723","pt":1646218636826,"mc":[{"id":"1.195453779","rc":[{"atb":[[1.08,250]],"id":40622317},{"atl":[[7.8,18.38]],"id":40072523}],"con":true,"img":false}]}
{"op":"mcm","clk":"5353804815","pt":1646218637766,"mc":[{"id":"1.195453779","rc":[{"atb":[[3.25,0]],"id":42256449},{"atl":[[8,0]],"id":42256449}],"con":true,"img":false}]}
{"op":"mcm","clk":"5353804826","pt":1646218637863,"mc":[{"id":"1.195453779","rc":[{"atb":[[3.35,20.27]],"id":42256449},{"atl":[[6.8,6.22]],"id":42256449}],"con":true,"img":false}]}
{"op":"mcm","clk":"5353805095","pt":1646218640554,"mc":[{"id":"1.195453779","rc":[{"atb":[[1.71,36.23],[1.76,15.32],[1.52,0]],"id":39832467}],"con":true,"img":false}]}
{"op":"mcm","clk":"5353805115","pt":1646218640763,"mc":[{"id":"1.195453779","rc":[{"atb":[[1.58,0]],"id":39832467}],"con":true,"img":false}]}
{"op":"mcm","clk":"5353805124","pt":1646218640863,"mc":[{"id":"1.195453779","rc":[{"atb":[[1.44,86.7],[1.52,40.85],[1.35,229.97]],"id":39786303},{"atb":[[1.85,24.86],[1.67,93.07],[1.77,54.73]],"id":38247337},{"atb":[[3.5,10.92],[3.2,22.73],[3.4,19.97]],"id":42256449},{"atl":[[7.4,24.65],[6.8,14.64],[7.8,13.53]],"id":42256449},{"atl":[[13.5,32.25],[14.5,5.56]],"id":40812693},{"atb":[[5.3,13.88],[5.7,12.86]],"id":37495332},{"atb":[[1.16,19],[1.13,298.98],[1.24,7]],"id":40622317},{"atl":[[5.2,9.9],[4.2,12.25]],"id":40072523}],"con":true,"img":false}]}
{"op":"mcm","clk":"5353805142","pt":1646218641028,"mc":[{"id":"1.195453779","rc":[{"atb":[[1.39,0]],"id":39786303},{"atb":[[1.71,0]],"id":38247337},{"atb":[[3.3,13.7]],"id":42256449},{"atl":[[7,3.33]],"id":42256449},{"atb":[[1.15,98.04]],"id":40622317}],"con":true,"img":false}]}
{"op":"mcm","clk":"5353805296","pt":1646218642741,"mc":[{"id":"1.195453779","rc":[{"atb":[[1.42,0]],"id":39786303},{"atb":[[1.72,0]],"id":38247337},{"atb":[[3.4,16.84]],"id":42256449}],"con":true,"img":false}]}
{"op":"mcm","clk":"5353805703","pt":1646218647666,"mc":[{"id":"1.195453779","rc":[{"atb":[[1.31,329.49]],"id":39786303},{"atl":[[3.6,51.69],[2.5,0]],"id":39786303},{"atb":[[1.59,0],[1.44,88.15]],"id":38247337},{"atl":[[4.3,0],[4.9,43.3]],"id":38247337},{"atb":[[2.84,0],[2.4,53.7]],"id":42256449},{"atl":[[10.5,1.27],[21,15.07]],"id":42256449},{"atb":[[4.3,43.36],[4.4,41.13]],"id":40812693},{"atl":[[19,0],[55,7.5]],"id":40812693},{"atb":[[6.4,7.56],[5.3,4.99],[5.6,16.67],[6,0]],"id":37495332},{"atl":[[25,1.7],[27,1.46],[60,5.82]],"id":37495332},{"atl":[[3.25,0],[3.45,0],[2.88,21.73],[4.2,41.1]],"id":39832467},{"atb":[[1.11,729.02],[1.13,0]],"id":40622317},{"atl":[[2.64,74.47],[1.95,0]],"id":40622317},{"atl":[[5.8,32.56]],"id":40072523}],"con":true,"img":false}]}
{"op":"mcm","clk":"5353805713","pt":1646218647768,"mc":[{"id":"1.195453779","rc":[{"atb":[[1.36,0]],"id":39786303},{"atl":[[2.12,0]],"id":39786303},{"atb":[[1.68,0]],"id":38247337},{"atl":[[3.15,0]],"id":38247337},{"atl":[[6.8,8.42]],"id":42256449},{"atl":[[14,0]],"id":40812693},{"atb":[[1.44,0]],"id":39832467},{"atl":[[5.2,0]],"id":40072523}],"con":true,"img":false}]}
{"op":"mcm","clk":"5353805725","pt":1646218647873,"mc":[{"id":"1.195453779","rc":[{"atb":[[1.4,82.9]],"id":39786303},{"atl":[[2.08,41.13]],"id":39786303},{"atb":[[1.72,70.03]],"id":38247337},{"atl":[[2.96,19.81]],"id":38247337},{"atl":[[7.2,6.22]],"id":42256449},{"atl":[[13,2.72]],"id":40812693},{"atb":[[1.41,208.02]],"id":39832467},{"atl":[[4.7,9.9]],"id":40072523}],"con":true,"img":false}]}
{"op":"mcm","clk":"5353805734","pt":1646218647930,"mc":[{"id":"1.195453779","rc":[{"atl":[[2.18,175.89]],"id":39786303},{"atl":[[3.2,30.83],[3.3,95.94]],"id":38247337},{"atb":[[6.6,6.41]],"id":37495332},{"atl":[[2.88,77.32]],"id":39832467}],"con":true,"img":false}]}
{"op":"mcm","clk":"5353805746","pt":1646218648033,"mc":[{"id":"1.195453779","rc":[{"atl":[[2.14,43.86],[2.08,108.07]],"id":39786303},{"atl":[[2.96,60.63]],"id":38247337},{"atl":[[12.5,10.44],[13.5,24.25]],"id":40812693},{"atl":[[2.9,2]],"id":39832467}],"con":true,"img":false}]}
{"op":"mcm","clk":"5353805756","pt":1646218648134,"mc":[{"id":"1.195453779","rc":[{"atl":[[2.18,63.56]],"id":39786303},{"atl":[[3.3,21.74]],"id":38247337},{"atb":[[6.2,1.66]],"id":37495332}],"con":true,"img":false}]}
{"op":"mcm","clk":"5353805767","pt":1646218648240,"mc":[{"id":"1.195453779","rc":[{"atl":[[2.1,18.18]],"id":39786303},{"atl":[[2.98,6.1]],"id":38247337}],"con":true,"img":false}]}
{"op":"mcm","clk":"5353805797","pt":1646218648550,"mc":[{"id":"1.195453779","rc":[{"atb":[[1.47,16]],"id":39786303},{"atb":[[1.81,14.28]],"id":38247337},{"atb":[[3.25,3.33]],"id":42256449}],"con":true,"img":false}]}
{"op":"mcm","clk":"5353806013","pt":1646218650859,"mc":[{"id":"1.195453779","rc":[{"atl":[[2.42,70.42],[2.52,0]],"id":39786303},{"atl":[[8.2,19.03],[7.8,28.18]],"id":42256449},{"atl":[[1.73,0],[1.66,136.99]],"id":40622317}],"con":true,"img":false}]}
{"op":"mcm","clk":"5353806345","pt":1646218654676,"mc":[{"id":"1.195453779","rc":[{"atb":[[6.2,0]],"id":37495332}],"con":true,"img":false}]}
{"op":"mcm","clk":"5353806366","pt":1646218654891,"mc":[{"id":"1.195453779","rc":[{"atb":[[6.8,1.66]],"id":37495332}],"con":true,"img":false}]}
{"op":"mcm","clk":"5353806529","pt":1646218656849,"mc":[{"id":"1.195453779","rc":[{"atb":[[2.64,0],[2.6,0],[2.62,0]],"id":40072523},{"trd":[[2.6,4],[2.64,4],[2.62,7.99]],"ltp":2.6,"tv":15.99,"id":40072523}],"con":true,"img":false}]}
{"op":"mcm","clk":"5353806538","pt":1646218656953,"mc":[{"id":"1.195453779","rc":[{"atb":[[2,2.5],[1.96,5],[1.82,51.17],[1.92,10]],"id":40072523}],"con":true,"img":false}]}
{"op":"mcm","clk":"5353806550","pt":1646218657057,"mc":[{"id":"1.195453779","rc":[{"atb":[[1.85,74.47],[2.58,0]],"id":40072523},{"atl":[[3.8,5.52],[3.65,8]],"id":40072523}],"con":true,"img":false}]}
{"op":"mcm","clk":"5353806562","pt":1646218657177,"mc":[{"id":"1.195453779","rc":[{"atl":[[3.65,13.18]],"id":40072523}],"con":true,"img":false}]}
{"op":"mcm","clk":"5353806575","pt":1646218657283,"mc":[{"id":"1.195453779","rc":[{"atl":[[3.7,0]],"id":40072523}],"con":true,"img":false}]}
{"op":"mcm","clk":"5353806605","pt":1646218657685,"mc":[{"id":"1.195453779","rc":[{"atb":[[1.72,0]],"id":38247337},{"atl":[[2.96,40.82]],"id":38247337}],"con":true,"img":false}]}
{"op":"mcm","clk":"5353806613","pt":1646218657787,"mc":[{"id":"1.195453779","rc":[{"atb":[[1.68,70.03]],"id":38247337},{"atl":[[3.15,19.81]],"id":38247337}],"con":true,"img":false}]}
{"op":"mcm","clk":"5353806628","pt":1646218657945,"mc":[{"id":"1.195453779","rc":[{"atb":[[1.44,10]],"id":39786303},{"atl":[[7.2,28.2]],"id":42256449},{"atl":[[13,22.1],[13.5,6.5]],"id":40812693},{"atl":[[3.8,21.3],[4.2,2.5]],"id":40072523}],"con":true,"img":false}]}
{"op":"mcm","clk":"5353806638","pt":1646218658049,"mc":[{"id":"1.195453779","rc":[{"atb":[[1.47,104.54]],"id":39786303},{"atl":[[7.4,7.81]],"id":42256449},{"atl":[[12.5,1.74],[13,30.43]],"id":40812693}],"con":true,"img":false}]}
{"op":"mcm","clk":"5353806851","pt":1646218660440,"mc":[{"id":"1.195453779","rc":[{"atb":[[1.47,88.54]],"id":39786303}],"con":true,"img":false}]}
{"op":"mcm","clk":"5353806942","pt":1646218661484,"mc":[{"id":"1.195453779","rc":[{"atb":[[1.33,212.13]],"id":39786303},{"atb":[[1.43,0],[1.45,44.44]],"id":39832467},{"atl":[[2.94,0],[2.92,0],[2.9,0],[2.96,0]],"id":39832467},{"atb":[[1.15,231.37],[1.14,0]],"id":40622317},{"atl":[[1.33,0],[1.34,0],[1.32,0],[1.31,0]],"id":40622317},{"atb":[[1.82,26.78],[1.79,23.94]],"id":40072523},{"atl":[[6,4],[6.6,0]],"id":40072523}],"con":true,"img":false}]}
{"op":"mcm","clk":"5353806946","pt":1646218661598,"mc":[{"id":"1.195453779","rc":[{"atb":[[1.33,60.6],[1.35,172.83]],"id":39786303}],"con":true,"img":false}]}
{"op":"mcm","clk":"5353806954","pt":1646218661687,"mc":[{"id":"1.195453779","rc":[{"atl":[[1.62,38.26],[1.65,153.81],[1.66,0],[1.69,245.68]],"id":40622317}],"con":true,"img":false}]}
{"op":"mcm","clk":"5353806963","pt":1646218661790,"mc":[{"id":"1.195453779","rc":[{"atb":[[3.3,35.54],[3.45,0]],"id":42256449},{"atb":[[3.3,0],[2.78,30.12]],"id":37495332},{"atb":[[1.82,49.84]],"id":40072523},{"atl":[[3.8,15.78],[3.7,5.66]],"id":40072523}],"con":true,"img":false}]}
{"op":"mcm","clk":"5353806971","pt":1646218661844,"mc":[{"id":"1.195453779","rc":[{"atl":[[3.2,21.74],[3.3,8.7]],"id":38247337},{"atb":[[3.85,7.02],[3.75,0]],"id":37495332},{"atl":[[3.05,47.2],[3.2,0],[3.4,31.25],[2.78,11.24]],"id":39832467},{"atl":[[6.2,3.85],[6,0]],"id":40072523}],"con":true,"img":false}]}
{"op":"mcm","clk":"5353806975","pt":1646218661950,"mc":[{"id":"1.195453779","rc":[{"atb":[[3.35,64.41],[3.4,0]],"id":42256449}],"con":true,"img":false}]}
{"op":"mcm","clk":"5353807101","pt":1646218663346,"mc":[{"id":"1.195453779","rc":[{"atb":[[3.15,0]],"id":42256449}],"con":true,"img":false}]}
{"op":"mcm","clk":"5353807110","pt":1646218663462,"mc":[{"id":"1.195453779","rc":[{"atb":[[1.81,24.58]],"id":38247337},{"atb":[[3.25,0]],"id":42256449},{"atb":[[1.89,8.45]],"id":40072523}],"con":true,"img":false}]}
{"op":"mcm","clk":"5353807242","pt":1646218664960,"mc":[{"id":"1.195453779","rc":[{"atl":[[2.14,163.95]],"id":39786303},{"atl":[[3.15,93.97]],"id":38247337},{"atb":[[6.8,4.19]],"id":37495332},{"atl":[[2.88,21.73],[2.86,46.34]],"id":39832467}],"con":true,"img":false}]}
{"op":"mcm","clk":"5353807251","pt":1646218665063,"mc":[{"id":"1.195453779","rc":[{"atb":[[6.4,16.41],[6.6,0]],"id":37495332}],"con":true,"img":false}]}
{"op":"mcm","clk":"5353807263","pt":1646218665172,"mc":[{"id":"1.195453779","rc":[{"atb":[[5.7,2.5]],"id":37495332}],"con":true,"img":false}]}
{"op":"mcm","clk":"5353807272","pt":1646218665268,"mc":[{"id":"1.195453779","rc":[{"atb":[[6.4,7.56]],"id":37495332}],"con":true,"img":false}]}
{"op":"mcm","clk":"5353807383","pt":1646218666562,"mc":[{"id":"1.195453779","rc":[{"atb":[[1.5,15.03]],"id":39786303}],"con":true,"img":false}]}
{"op":"mcm","clk":"5353807470","pt":1646218667696,"mc":[{"id":"1.195453779","rc":[{"atb":[[1.67,0]],"id":40072523}],"con":true,"img":false}]}
{"op":"mcm","clk":"5353807481","pt":1646218667798,"mc":[{"id":"1.195453779","rc":[{"atb":[[1.86,53.82]],"id":40072523}],"con":true,"img":false}]}
{"op":"mcm","clk":"5353807632","pt":1646218669472,"mc":[{"id":"1.195453779","rc":[{"atb":[[3.45,3.06]],"id":42256449},{"atb":[[1.89,0]],"id":40072523}],"con":true,"img":false}]}
{"op":"mcm","clk":"5353807789","pt":1646218671483,"mc":[{"id":"1.195453779","rc":[{"atb":[[1.31,248.84]],"id":39786303}],"con":true,"img":false}]}
{"op":"mcm","clk":"5353807802","pt":1646218671693,"mc":[{"id":"1.195453779","rc":[{"atb":[[4.6,15.11]],"id":40812693},{"atl":[[1.63,31.75]],"id":40622317}],"con":true,"img":false}]}
{"op":"mcm","clk":"5353807809","pt":1646218671795,"mc":[{"id":"1.195453779","rc":[{"atl":[[1.62,6]],"id":40622317}],"con":true,"img":false}]}
{"op":"mcm","clk":"5353807818","pt":1646218671897,"mc":[{"id":"1.195453779","rc":[{"atl":[[3.4,20.83]],"id":38247337},{"atb":[[3.75,18.18]],"id":37495332},{"atb":[[1.43,116.28]],"id":39832467},{"atl":[[2.82,27.47]],"id":39832467},{"atl":[[6.6,8.93]],"id":40072523}],"con":true,"img":false}]}
{"op":"mcm","clk":"5353807881","pt":1646218672571,"mc":[{"id":"1.195453779","rc":[{"atb":[[2.02,1.66]],"id":40072523}],"con":true,"img":false}]}
{"op":"mcm","clk":"5353807988","pt":1646218673761,"mc":[{"id":"1.195453779","rc":[{"atb":[[1.82,23.06],[1.92,25.99]],"id":40072523}],"con":true,"img":false}]}
{"op":"mcm","clk":"5353808000","pt":1646218673873,"mc":[{"id":"1.195453779","rc":[{"atb":[[2,9.55]],"id":40072523}],"con":true,"img":false}]}
{"op":"mcm","clk":"5353808017","pt":1646218674071,"mc":[{"id":"1.195453779","rc":[{"atb":[[1.85,71.17]],"id":40072523}],"con":true,"img":false}]}
{"op":"mcm","clk":"5353808090","pt":1646218674799,"mc":[{"id":"1.195453779","rc":[{"atl":[[3.8,0],[3.75,29.71]],"id":40072523}],"con":true,"img":false}]}
{"op":"mcm","clk":"5353808102","pt":1646218674960,"mc":[{"id":"1.195453779","rc":[{"atb":[[1.48,93.54],[1.47,0]],"id":39786303}],"con":true,"img":false}]}
{"op":"mcm","clk":"5353808177","pt":1646218675578,"mc":[{"id":"1.195453779","rc":[{"atb":[[1.5,0]],"id":39786303},{"atb":[[1.9,8.35]],"id":40072523}],"con":true,"img":false}]}
{"op":"mcm","clk":"5353808339","pt":1646218677716,"mc":[{"id":"1.195453779","rc":[{"atl":[[2.08,66.94]],"id":39786303},{"atl":[[3.15,74.16]],"id":38247337},{"atb":[[4.5,0]],"id":40812693},{"atl":[[25,0]],"id":37495332},{"atl":[[2.88,0]],"id":39832467},{"atl":[[3.9,14.09],[4.7,0]],"id":40072523}],"con":true,"img":false}]}
{"op":"mcm","clk":"5353808347","pt":1646218677811,"mc":[{"id":"1.195453779","rc":[{"atl":[[2.12,41.13]],"id":39786303},{"atl":[[2.94,19.81]],"id":38247337},{"atb":[[4.9,10.38]],"id":40812693},{"atl":[[24,1.7]],"id":37495332},{"atl":[[2.84,21.73]],"id":39832467}],"con":true,"img":false}]}
{"op":"mcm","clk":"5353808362","pt":1646218677917,"mc":[{"id":"1.195453779","rc":[{"atb":[[4.3,105.27],[4.4,14.71]],"id":40812693}],"con":true,"img":false}]}
{"op":"mcm","clk":"5353808371","pt":1646218677977,"mc":[{"id":"1.195453779","rc":[{"atl":[[2.94,56.89]],"id":38247337}],"con":true,"img":false}]}
{"op":"mcm","clk":"5353808391","pt":1646218678188,"mc":[{"id":"1.195453779","rc":[{"atl":[[2.96,0]],"id":38247337}],"con":true,"img":false}]}
{"op":"mcm","clk":"5353808408","pt":1646218678396,"mc":[{"id":"1.195453779","rc":[{"atl":[[1.64,82.59],[1.65,76.92]],"id":40622317}],"con":true,"img":false}]}
{"op":"mcm","clk":"5353808449","pt":1646218678909,"mc":[{"id":"1.195453779","rc":[{"atb":[[3.45,6.46]],"id":42256449}],"con":true,"img":false}]}
{"op":"mcm","clk":"5353808501","pt":1646218679278,"mc":[{"id":"1.195453779","rc":[{"atb":[[3.45,0]],"id":37495332},{"atb":[[1.37,0]],"id":39832467},{"atl":[[3.3,0],[3.5,0],[3.4,0]],"id":39832467},{"atl":[[1.63,0],[1.62,38.26]],"id":40622317},{"atb":[[1.82,0]],"id":40072523},{"atl":[[7.8,0]],"id":40072523}],"con":true,"img":false}]}
{"op":"mcm","clk":"5353808716","pt":1646218681530,"mc":[{"id":"1.195453779","rc":[{"atb":[[1.27,250],[1.51,14.74]],"id":39786303}],"con":true,"img":false}]}
{"op":"mcm","clk":"5353808720","pt":1646218681575,"mc":[{"id":"1.195453779","rc":[{"atl":[[2.14,43.86]],"id":39786303},{"atl":[[2.82,85.85],[2.86,6.5]],"id":39832467}],"con":true,"img":false}]}
{"op":"mcm","clk":"5353808733","pt":1646218681687,"mc":[{"id":"1.195453779","rc":[{"atl":[[2.12,164.1]],"id":39786303},{"atb":[[5.7,8.8]],"id":37495332}],"con":true,"img":false}]}
{"op":"mcm","clk":"5353808755","pt":1646218681891,"mc":[{"id":"1.195453779","rc":[{"atl":[[3.5,30]],"id":38247337},{"atb":[[3.65,28.3]],"id":37495332},{"atb":[[1.41,269]],"id":39832467},{"atl":[[2.86,46.82]],"id":39832467},{"atb":[[1.77,61.41]],"id":40072523},{"atl":[[7,16.53]],"id":40072523}],"con":true,"img":false}]}
{"op":"mcm","clk":"5353809152","pt":1646218686194,"mc":[{"id":"1.195453779","rc":[{"atl":[[1.64,43.59],[1.65,162.81]],"id":40622317}],"con":true,"img":false}]}
{"op":"mcm","clk":"5353809163","pt":1646218686302,"mc":[{"id":"1.195453779","rc":[{"atl":[[1.8,3]],"id":39786303},{"atb":[[1.82,23.06]],"id":40072523}],"con":true,"img":false}]}
{"op":"mcm","clk":"5353809189","pt":1646218686612,"mc":[{"id":"1.195453779","rc":[{"atl":[[1.71,4],[1.8,2]],"id":39786303},{"spn":1.61,"spf":"NaN","id":39786303},{"spn":2.39,"spf":"NaN","id":38247337},{"spn":5.17,"spf":"NaN","id":42256449},{"spn":8.45,"spf":"NaN","id":40812693},{"spn":12.65,"spf":"NaN","id":37495332},{"spn":1.43,"spf":"NaN","id":40622317},{"spn":2.83,"spf":"NaN","id":40072523}],"con":true,"img":false}]}
{"op":"mcm","clk":"5353809207","pt":1646218686822,"mc":[{"id":"1.195453779","rc":[{"atl":[[2.08,0]],"id":39786303}],"con":true,"img":false}]}
{"op":"mcm","clk":"5353809385","pt":1646218689005,"mc":[{"id":"1.195453779","rc":[{"atb":[[1.84,5],[1.68,0],[1.76,12.82],[1.72,0],[1.8,10],[1.88,2.5]],"id":39832467}],"con":true,"img":false}]}
{"op":"mcm","clk":"5353809392","pt":1646218689100,"mc":[{"id":"1.195453779","rc":[{"atb":[[1.85,22.36],[1.78,10],[1.82,5],[1.81,19.58],[1.86,2.5],[1.77,44.73]],"id":38247337},{"atb":[[3.35,69.41],[3.55,4.16]],"id":42256449},{"atb":[[5.3,0],[5.6,21.67],[6,2.5],[5.7,6.3]],"id":37495332},{"atb":[[1.21,5],[1.25,2.5],[1.17,10]],"id":40622317},{"atl":[[4.6,0],[5,0],[3.7,8.16],[3.9,19.09]],"id":40072523}],"con":true,"img":false}]}
{"op":"mcm","clk":"5353809401","pt":1646218689207,"mc":[{"id":"1.195453779","rc":[{"atb":[[1.82,47.7],[1.86,23.85]],"id":38247337},{"atb":[[3.45,28.8],[3.35,25.27],[3.55,15.33],[3.5,8.42],[3.3,30.54]],"id":42256449},{"atb":[[1.71,10.58],[1.8,41.86],[1.88,18.43]],"id":39832467},{"atb":[[1.2,0],[1.16,0],[1.24,4.5]],"id":40622317}],"con":true,"img":false}]}
{"op":"mcm","clk":"5353809410","pt":1646218689322,"mc":[{"id":"1.195453779","rc":[{"atb":[[1.77,0]],"id":38247337},{"atb":[[1.25,36.44],[1.21,72.89]],"id":40622317}],"con":true,"img":false}]}
{"op":"mcm","clk":"5353809419","pt":1646218689424,"mc":[{"id":"1.195453779","rc":[{"atb":[[1.85,0]],"id":38247337},{"atb":[[3.5,0]],"id":42256449},{"atb":[[1.76,0]],"id":39832467}],"con":true,"img":false}]}
{"op":"mcm","clk":"5353809432","pt":1646218689521,"mc":[{"id":"1.195453779","rc":[{"atb":[[1.24,0]],"id":40622317}],"con":true,"img":false}]}
{"op":"mcm","clk":"5353809443","pt":1646218689622,"mc":[{"id":"1.195453779","rc":[{"atb":[[4.7,0]],"id":40812693}],"con":true,"img":false}]}
{"op":"mcm","clk":"5353809460","pt":1646218689791,"mc":[{"id":"1.195453779","rc":[{"atb":[[5,1.66]],"id":40812693}],"con":true,"img":false}]}
{"op":"mcm","clk":"5353809544","pt":1646218690715,"mc":[{"id":"1.195453779","rc":[{"atb":[[1.81,10.29]],"id":38247337},{"atb":[[3.45,25.74]],"id":42256449},{"atb":[[1.71,0]],"id":39832467}],"con":true,"img":false}]}
{"op":"mcm","clk":"5353809634","pt":1646218691698,"mc":[{"id":"1.195453779","rc":[{"atl":[[1.7,3],[2.1,0],[2.08,18.52]],"id":39786303},{"atb":[[3.45,56.42],[3.3,8.7]],"id":42256449},{"atb":[[3.3,31.62],[2.78,0]],"id":37495332},{"atl":[[2.8,11.11],[2.78,0]],"id":39832467},{"atl":[[1.63,31.75],[1.62,6]],"id":40622317},{"atb":[[1.82,0]],"id":40072523},{"atl":[[3.7,2.5]],"id":40072523}],"con":true,"img":false}]}
{"op":"mcm","clk":"5353809653","pt":1646218691909,"mc":[{"id":"1.195453779","rc":[{"atl":[[2.12,41.13],[1.71,0],[1.69,2]],"id":39786303},{"atl":[[3.6,48.08]],"id":38247337},{"atb":[[3.55,49.02]],"id":37495332}],"con":true,"img":false}]}
{"op":"mcm","clk":"5353809868","pt":1646218694288,"mc":[{"id":"1.195453779","rc":[{"atb":[[4.3,43.36],[4.4,54.85]],"id":40812693}],"con":true,"img":false}]}
{"op":"mcm","clk":"5353809926","pt":1646218694803,"mc":[{"id":"1.195453779","rc":[{"atl":[[1.64,145.87]],"id":40622317}],"con":true,"img":false}]}
{"op":"mcm","clk":"5353809933","pt":1646218694912,"mc":[{"id":"1.195453779","rc":[{"atb":[[1.57,0]],"id":39832467},{"atl":[[1.65,76.92]],"id":40622317}],"con":true,"img":false}]}
{"op":"mcm","clk":"5353809953","pt":1646218695115,"mc":[{"id":"1.195453779","rc":[{"atb":[[1.9,17.61]],"id":40072523}],"con":true,"img":false}]}
{"op":"mcm","clk":"5353810078","pt":1646218696414,"mc":[{"id":"1.195453779","rc":[{"atb":[[1.75,255.88]],"id":40072523},{"atl":[[7.4,19.53]],"id":40072523}],"con":true,"img":false}]}
{"op":"mcm","clk":"5353810102","pt":1646218696622,"mc":[{"id":"1.195453779","rc":[{"atb":[[1.86,32.59]],"id":38247337},{"atb":[[3.55,18.28]],"id":42256449},{"atb":[[1.84,13.94]],"id":39832467}],"con":true,"img":false}]}
{"op":"mcm","clk":"5353810131","pt":1646218696931,"mc":[{"id":"1.195453779","rc":[{"atb":[[1.82,5],[1.81,130.73]],"id":38247337},{"atb":[[3.45,34.08],[3.35,90.61]],"id":42256449},{"atb":[[1.21,5],[1.17,112.28]],"id":40622317}],"con":true,"img":false}]}
{"op":"mcm","clk":"5353810207","pt":1646218697710,"mc":[{"id":"1.195453779","rc":[{"atl":[[2.12,0]],"id":39786303},{"atb":[[2.4,0],[2.84,34.67]],"id":42256449},{"atb":[[4.3,18.33]],"id":40812693},{"atl":[[3.9,5]],"id":40072523}],"con":true,"img":false}]}
{"op":"mcm","clk":"5353810216","pt":1646218697818,"mc":[{"id":"1.195453779","rc":[{"atl":[[2.16,41.13]],"id":39786303},{"atb":[[4.5,25.03]],"id":40812693},{"atl":[[3.7,16.59]],"id":40072523}],"con":true,"img":false}]}
{"op":"mcm","clk":"5353810236","pt":1646218698017,"mc":[{"id":"1.195453779","rc":[{"atb":[[6,8.8],[5.7,0]],"id":37495332}],"con":true,"img":false}]}
{"op":"mcm","clk":"5353810334","pt":1646218699213,"mc":[{"id":"1.195453779","rc":[{"atl":[[1.68,3]],"id":39786303}],"con":true,"img":false}]}
{"op":"mcm","clk":"5353810351","pt":1646218699425,"mc":[{"id":"1.195453779","rc":[{"atl":[[1.7,0],[1.67,4]],"id":39786303}],"con":true,"img":false}]}
{"op":"mcm","clk":"5353810544","pt":1646218701712,"mc":[{"id":"1.195453779","rc":[{"atb":[[1.39,250]],"id":39832467},{"atl":[[2.84,48.9]],"id":39832467}],"con":true,"img":false}]}
{"op":"mcm","clk":"5353810622","pt":1646218702640,"mc":[{"id":"1.195453779","rc":[{"atb":[[1.86,23.85]],"id":38247337}],"con":true,"img":false}]}
{"op":"mcm","clk":"5353810839","pt":1646218704930,"mc":[{"id":"1.195453779","rc":[{"atl":[[1.66,4]],"id":39786303}],"con":true,"img":false}]}
{"op":"mcm","clk":"5353810861","pt":1646218705138,"mc":[{"id":"1.195453779","rc":[{"atl":[[1.69,0],[1.65,4]],"id":39786303}],"con":true,"img":false}]}
{"op":"mcm","clk":"5353810981","pt":1646218706448,"mc":[{"id":"1.195453779","rc":[{"atb":[[1.73,161.93]],"id":40072523}],"con":true,"img":false}]}
{"op":"mcm","clk":"5353811109","pt":1646218707755,"mc":[{"id":"1.195453779","rc":[{"atl":[[2.94,37.08]],"id":38247337},{"atl":[[2.84,27.17]],"id":39832467}],"con":true,"img":false}]}
{"op":"mcm","clk":"5353811119","pt":1646218707806,"mc":[{"id":"1.195453779","rc":[{"atl":[[2.92,19.81]],"id":38247337},{"atl":[[2.8,32.84]],"id":39832467}],"con":true,"img":false}]}
{"op":"mcm","clk":"5353811131","pt":1646218707915,"mc":[{"id":"1.195453779","rc":[{"atl":[[2.94,0]],"id":38247337}],"con":true,"img":false}]}
{"op":"mcm","clk":"5353811144","pt":1646218708018,"mc":[{"id":"1.195453779","rc":[{"atl":[[2.92,52.56],[2.98,71.6],[3.15,0]],"id":38247337}],"con":true,"img":false}]}
{"op":"mcm","clk":"5353811166","pt":1646218708230,"mc":[{"id":"1.195453779","rc":[{"atl":[[2.98,6.1]],"id":38247337}],"con":true,"img":false}]}
{"op":"mcm","clk":"5353811198","pt":1646218708540,"mc":[{"id":"1.195453779","rc":[{"atb":[[1.85,8.84]],"id":38247337}],"con":true,"img":false}]}
{"op":"mcm","clk":"5353811218","pt":1646218708749,"mc":[{"id":"1.195453779","rc":[{"atb":[[1.82,50.87],[1.81,10.29]],"id":38247337}],"con":true,"img":false}]}
{"op":"mcm","clk":"5353811279","pt":1646218709326,"mc":[{"id":"1.195453779","rc":[{"atl":[[6.8,11.87],[7,0]],"id":42256449},{"atl":[[12.5,0]],"id":40812693},{"atb":[[1.45,0],[1.48,41.67]],"id":39832467}],"con":true,"img":false}]}
{"op":"mcm","clk":"5353811290","pt":1646218709426,"mc":[{"id":"1.195453779","rc":[{"atl":[[13,32.1]],"id":40812693}],"con":true,"img":false}]}
{"op":"mcm","clk":"5353811302","pt":1646218709560,"mc":[{"id":"1.195453779","rc":[{"atl":[[7.2,6.22],[7.4,46.83]],"id":42256449},{"atl":[[13,12.72],[13.5,27.89]],"id":40812693}],"con":true,"img":false}]}
{"op":"mcm","clk":"5353811317","pt":1646218709658,"mc":[{"id":"1.195453779","rc":[{"atl":[[12,0]],"id":40812693}],"con":true,"img":false}]}
{"op":"mcm","clk":"5353811327","pt":1646218709714,"mc":[{"id":"1.195453779","rc":[{"atl":[[12.5,6.96]],"id":40812693}],"con":true,"img":false}]}
{"op":"mcm","clk":"5353811339","pt":1646218709817,"mc":[{"id":"1.195453779","rc":[{"atl":[[12.5,15.66],[13,4.39]],"id":40812693}],"con":true,"img":false}]}
{"op":"mcm","clk":"5353811347","pt":1646218709924,"mc":[{"id":"1.195453779","rc":[{"atb":[[1.81,0]],"id":38247337},{"atb":[[3.45,30.68]],"id":42256449}],"con":true,"img":false}]}
{"op":"mcm","clk":"5353811367","pt":1646218710126,"mc":[{"id":"1.195453779","rc":[{"atb":[[1.82,23.06],[1.79,0]],"id":40072523}],"con":true,"img":false}]}
{"op":"mcm","clk":"5353811396","pt":1646218710443,"mc":[{"id":"1.195453779","rc":[{"atb":[[4.5,71.19],[4.4,14.71]],"id":40812693}],"con":true,"img":false}]}
{"op":"mcm","clk":"5353811514","pt":1646218711741,"mc":[{"id":"1.195453779","rc":[{"atb":[[1.85,0]],"id":38247337}],"con":true,"img":false}]}
{"op":"mcm","clk":"5353811869","pt":1646218715064,"mc":[{"id":"1.195453779","rc":[{"atl":[[12.5,6.96],[13,12.72]],"id":40812693}],"con":true,"img":false}]}
{"op":"mcm","clk":"5353811881","pt":1646218715119,"mc":[{"id":"1.195453779","rc":[{"atl":[[13,4.39],[13.5,35.89]],"id":40812693}],"con":true,"img":false}]}
{"op":"mcm","clk":"5353811990","pt":1646218716158,"mc":[{"id":"1.195453779","rc":[{"atb":[[1.78,78.39]],"id":38247337}],"con":true,"img":false}]}
{"op":"mcm","clk":"5353812001","pt":1646218716264,"mc":[{"id":"1.195453779","rc":[{"atb":[[1.82,5]],"id":38247337}],"con":true,"img":false}]}
{"op":"mcm","clk":"5353812029","pt":1646218716569,"mc":[{"id":"1.195453779","rc":[{"atb":[[3.35,70.34]],"id":42256449},{"atl":[[24,0]],"id":37495332},{"atb":[[1.86,0]],"id":40072523}],"con":true,"img":false}]}
{"op":"mcm","clk":"5353812043","pt":1646218716674,"mc":[{"id":"1.195453779","rc":[{"atb":[[3.6,20.27]],"id":42256449},{"atl":[[23,1.7]],"id":37495332},{"atb":[[1.74,53.82]],"id":40072523}],"con":true,"img":false}]}
{"op":"mcm","clk":"5353812064","pt":1646218716838,"mc":[{"id":"1.195453779","rc":[{"atb":[[3.6,49.19],[3.45,88.52],[3.35,5]],"id":42256449}],"con":true,"img":false}]}
{"op":"mcm","clk":"5353812089","pt":1646218717041,"mc":[{"id":"1.195453779","rc":[{"atb":[[3.55,7.11]],"id":42256449}],"con":true,"img":false}]}
{"op":"mcm","clk":"5353812157","pt":1646218717664,"mc":[{"id":"1.195453779","rc":[{"atl":[[2.92,32.75]],"id":38247337},{"atb":[[3.55,4.16]],"id":42256449},{"atb":[[1.9,9.26]],"id":40072523},{"atl":[[3.7,2.5]],"id":40072523}],"con":true,"img":false}]}
{"op":"mcm","clk":"5353812168","pt":1646218717766,"mc":[{"id":"1.195453779","rc":[{"atl":[[3.3,28.51]],"id":38247337},{"atl":[[3.9,19.09]],"id":40072523}],"con":true,"img":false}]}
{"op":"mcm","clk":"5353812177","pt":1646218717874,"mc":[{"id":"1.195453779","rc":[{"atl":[[2.92,0]],"id":38247337}],"con":true,"img":false}]}
{"op":"mcm","clk":"5353812196","pt":1646218718039,"mc":[{"id":"1.195453779","rc":[{"atl":[[2.98,40.29]],"id":38247337}],"con":true,"img":false}]}
{"op":"mcm","clk":"5353812313","pt":1646218719333,"mc":[{"id":"1.195453779","rc":[{"atl":[[14,3.85]],"id":40812693},{"atb":[[1.46,108.7]],"id":39832467},{"atl":[[2.88,39.89]],"id":39832467}],"con":true,"img":false}]}
{"op":"mcm","clk":"5353812378","pt":1646218720163,"mc":[{"id":"1.195453779","rc":[{"atb":[[1.8,210.33]],"id":40072523}],"con":true,"img":false}]}
{"op":"mcm","clk":"5353812619","pt":1646218722669,"mc":[{"id":"1.195453779","rc":[{"atl":[[13.5,31.89],[14.5,0],[15.5,5.83]],"id":40812693},{"atb":[[1.43,0],[1.39,0],[1.41,86.07]],"id":39832467},{"atl":[[2.8,21.73],[2.88,0],[2.84,0],[2.78,11.24]],"id":39832467},{"atb":[[1.73,0],[1.82,0],[1.8,151.23],[1.79,23.94],[1.77,0],[1.75,161.31]],"id":40072523}],"con":true,"img":false}]}
{"op":"mcm","clk":"5353812642","pt":1646218722876,"mc":[{"id":"1.195453779","rc":[{"atl":[[2.8,81.99],[2.82,27.47]],"id":39832467}],"con":true,"img":false}]}
{"op":"mcm","clk":"5353812710","pt":1646218723763,"mc":[{"id":"1.195453779","rc":[{"atb":[[1.82,14.17]],"id":38247337},{"atb":[[3.7,2.78]],"id":42256449},{"atb":[[1.89,8.45]],"id":40072523}],"con":true,"img":false}]}
{"op":"mcm","clk":"5353812720","pt":1646218723872,"mc":[{"id":"1.195453779","rc":[{"atl":[[3.3,107.07]],"id":38247337}],"con":true,"img":false}]}
{"op":"mcm","clk":"5353812886","pt":1646218725647,"mc":[{"id":"1.195453779","rc":[{"atb":[[3.55,2.5]],"id":42256449}],"con":true,"img":false}]}
{"op":"mcm","clk":"5353812908","pt":1646218725855,"mc":[{"id":"1.195453779","rc":[{"atb":[[3.75,1.66]],"id":42256449}],"con":true,"img":false}]}
{"op":"mcm","clk":"5353812971","pt":1646218726577,"mc":[{"id":"1.195453779","rc":[{"atl":[[1.68,0],[1.67,0],[1.65,0],[1.66,0]],"id":39786303}],"con":true,"img":false}]}
{"op":"mcm","clk":"5353812994","pt":1646218726738,"mc":[{"id":"1.195453779","rc":[{"atl":[[2.14,132.92],[1.8,0]],"id":39786303}],"con":true,"img":false}]}
{"op":"mcm","clk":"5353813015","pt":1646218726958,"mc":[{"id":"1.195453779","rc":[{"atl":[[2.08,63.05]],"id":39786303}],"con":true,"img":false}]}
{"op":"mcm","clk":"5353813081","pt":1646218727677,"mc":[{"id":"1.195453779","rc":[{"atb":[[1.74,0]],"id":40072523}],"con":true,"img":false}]}
{"op":"mcm","clk":"5353813091","pt":1646218727782,"mc":[{"id":"1.195453779","rc":[{"atb":[[1.69,53.82]],"id":40072523}],"con":true,"img":false}]}
{"op":"mcm","clk":"5353813251","pt":1646218729399,"mc":[{"id":"1.195453779","rc":[{"atl":[[15,5.36]],"id":40812693}],"con":true,"img":false}]}
{"op":"mcm","clk":"5353813316","pt":1646218730111,"mc":[{"id":"1.195453779","rc":[{"atl":[[2.1,18.18],[2.08,44.53]],"id":39786303},{"atb":[[3.3,0],[2.78,39.86]],"id":37495332},{"atb":[[1.82,23.06]],"id":40072523}],"con":true,"img":false}]}
{"op":"mcm","clk":"5353813330","pt":1646218730172,"mc":[{"id":"1.195453779","rc":[{"atb":[[3.3,31.43],[3.45,57.84]],"id":42256449}],"con":true,"img":false}]}
{"op":"mcm","clk":"5353813526","pt":1646218732461,"mc":[{"id":"1.195453779","rc":[{"atb":[[3.55,29.65],[3.45,0],[3.7,16.36]],"id":42256449}],"con":true,"img":false}]}
{"op":"mcm","clk":"5353813537","pt":1646218732563,"mc":[{"id":"1.195453779","rc":[{"atb":[[3.6,20.27]],"id":42256449},{"atb":[[1.44,170.45]],"id":39832467},{"atl":[[2.9,65.79]],"id":39832467}],"con":true,"img":false}]}
{"op":"mcm","clk":"5353813675","pt":1646218733965,"mc":[{"id":"1.195453779","rc":[{"atb":[[3.6,0],[2.84,0]],"id":42256449},{"atb":[[4.5,46.16]],"id":40812693}],"con":true,"img":false}]}
{"op":"mcm","clk":"5353813684","pt":1646218734069,"mc":[{"id":"1.195453779","rc":[{"atb":[[2.94,34.67],[3.65,20.27]],"id":42256449},{"atb":[[4.7,25.03]],"id":40812693}],"con":true,"img":false}]}
{"op":"mcm","clk":"5353813694","pt":1646218734173,"mc":[{"id":"1.195453779","rc":[{"atb":[[4.5,0],[4.6,55.85]],"id":40812693}],"con":true,"img":false}]}
{"op":"mcm","clk":"5353813827","pt":1646218735535,"mc":[{"id":"1.195453779","rc":[{"atb":[[1.25,0],[1.3,0],[1.35,0]],"id":39786303},{"atl":[[2.8,0],[3,0],[2.6,0],[3.5,0],[4,0]],"id":39786303},{"atb":[[1.6,33.33],[1.55,0],[1.65,0]],"id":38247337},{"atl":[[3.45,0],[3.95,0],[4.9,37.1],[2.98,34.19],[5.9,0]],"id":38247337},{"atb":[[2.82,0],[3.05,0],[2.92,0]],"id":42256449},{"atl":[[32,0],[10.5,0],[21,13.86],[8.2,17.36],[15.5,0]],"id":42256449},{"atb":[[4.3,0],[3.9,0],[3.65,0]],"id":40812693},{"atl":[[32,0],[21,0],[55,7.06],[110,0],[15.5,5]],"id":40812693},{"atb":[[4.5,0],[5,0],[5.5,0]],"id":37495332},{"atl":[[18.5,0],[85,0],[170,0],[44,0],[27,1]],"id":37495332},{"atb":[[1.4,0],[1.3,0],[1.35,0]],"id":39832467},{"atl":[[4.3,0],[2.86,40.32],[2.66,16.31],[3.15,0],[3.65,0]],"id":39832467},{"atb":[[1.01,0],[1.11,179.08],[1.06,0]],"id":40622317},{"atl":[[2.36,0],[2.56,0],[2.96,0],[2.16,0],[2.76,0]],"id":40622317},{"atb":[[1.85,0],[1.8,0],[1.75,0]],"id":40072523},{"atl":[[9,0],[3.75,25.32],[4.5,0],[5.5,0],[7,12.5]],"id":40072523}],"con":true,"img":false}]}
{"op":"mcm","clk":"5353813833","pt":1646218735588,"mc":[{"id":"1.195453779","rc":[{"atb":[[3.7,13.58]],"id":42256449}],"con":true,"img":false}]}
{"op":"mcm","clk":"5353813841","pt":1646218735690,"mc":[{"id":"1.195453779","rc":[{"atl":[[2.98,0]],"id":38247337},{"atl":[[13,6.89],[13.5,29.39],[15.5,0]],"id":40812693},{"atl":[[23,2.16]],"id":37495332},{"atl":[[2.66,0]],"id":39832467},{"atl":[[3.85,5.44]],"id":40072523}],"con":true,"img":false}]}
{"op":"mcm","clk":"5353813851","pt":1646218735797,"mc":[{"id":"1.195453779","rc":[{"atl":[[3.3,150.55]],"id":38247337}],"con":true,"img":false}]}
{"op":"mcm","clk":"5353813857","pt":1646218735896,"mc":[{"id":"1.195453779","rc":[{"atl":[[3.2,36.36],[3.4,89.22],[3.3,71.99]],"id":38247337},{"atl":[[2.8,21.73],[2.82,96.32],[2.78,37.29]],"id":39832467}],"con":true,"img":false}]}
{"op":"mcm","clk":"5353813873","pt":1646218736056,"mc":[{"id":"1.195453779","rc":[{"atl":[[3.2,0]],"id":38247337}],"con":true,"img":false}]}
{"op":"mcm","clk":"5353813888","pt":1646218736215,"mc":[{"id":"1.195453779","rc":[{"atl":[[3.6,50.58],[3.25,35.56]],"id":38247337}],"con":true,"img":false}]}
{"op":"mcm","clk":"5353813912","pt":1646218736476,"mc":[{"id":"1.195453779","rc":[{"atb":[[1.31,161.29]],"id":39786303}],"con":true,"img":false}]}
{"op":"mcm","clk":"5353813926","pt":1646218736580,"mc":[{"id":"1.195453779","rc":[{"atb":[[1.28,87.55]],"id":39786303}],"con":true,"img":false}]}
{"op":"mcm","clk":"5353814141","pt":1646218738705,"mc":[{"id":"1.195453779","rc":[{"atb":[[1.89,0]],"id":40072523}],"con":true,"img":false}]}
{"op":"mcm","clk":"5353814163","pt":1646218738865,"mc":[{"id":"1.195453779","rc":[{"atb":[[2.62,42.86]],"id":42256449},{"atb":[[4.9,21.53]],"id":37495332},{"atb":[[1.41,0]],"id":39832467}],"con":true,"img":false}]}
{"op":"mcm","clk":"5353814180","pt":1646218738973,"mc":[{"id":"1.195453779","rc":[{"atb":[[2.94,0]],"id":42256449},{"atb":[[5.6,5]],"id":37495332},{"atb":[[1.36,86.07]],"id":39832467}],"con":true,"img":false}]}
{"op":"mcm","clk":"5353814221","pt":1646218739391,"mc":[{"id":"1.195453779","rc":[{"atl":[[16,8.33]],"id":40812693}],"con":true,"img":false}]}
{"op":"mcm","clk":"5353814248","pt":1646218739604,"mc":[{"id":"1.195453779","rc":[{"atb":[[1.35,172.83],[1.25,483.95],[1.3,403.29]],"id":39786303},{"atl":[[2.8,0.3],[3,2.17],[2.6,0.34]],"id":39786303},{"atb":[[1.6,234.97],[1.55,219.97],[1.65,93.06]],"id":38247337},{"atl":[[3.45,0.22],[3.95,1.47],[2.98,0.27]],"id":38247337},{"atb":[[2.82,66.47],[3.05,29.51],[2.92,63.01]],"id":42256449},{"atl":[[10.5,0.05],[8.2,17.43],[15.5,0.29]],"id":42256449},{"atb":[[4.3,18.33],[3.9,41.71],[3.65,45.65]],"id":40812693},{"atl":[[32,0.14],[21,0.02],[15.5,0.03]],"id":40812693},{"atb":[[4.5,34.56],[5,30.24],[5.5,13.44]],"id":37495332},{"atl":[[18.5,0.03],[44,0.1],[27,1.02]],"id":37495332},{"atb":[[1.4,151.23],[1.3,403.29],[1.35,345.68]],"id":39832467},{"atl":[[2.86,40.61],[2.66,0.32],[3.15,2.02]],"id":39832467},{"atb":[[1.01,12098.75],[1.11,729.02],[1.06,2016.45]],"id":40622317},{"atl":[[2.36,0.4],[2.56,2.79],[2.16,0.46]],"id":40622317},{"atb":[[1.85,71.17],[1.8,151.23],[1.75,161.31]],"id":40072523},{"atl":[[3.75,25.51],[4.5,0.15],[5.5,0.97]],"id":40072523}],"con":true,"img":false}]}
{"op":"mcm","clk":"5353814373","pt":1646218740808,"mc":[{"id":"1.195453779","rc":[{"atl":[[1.62,38.26]],"id":40622317},{"atb":[[1.82,0]],"id":40072523}],"con":true,"img":false}]}
{"op":"mcm","clk":"5353814382","pt":1646218740903,"mc":[{"id":"1.195453779","rc":[{"atl":[[1.63,0]],"id":40622317}],"con":true,"img":false}]}
{"op":"mcm","clk":"5353814392","pt":1646218741005,"mc":[{"id":"1.195453779","rc":[{"atl":[[1.67,0],[1.65,0],[1.69,64.52]],"id":40622317}],"con":true,"img":false}]}
{"op":"mcm","clk":"5353814403","pt":1646218741112,"mc":[{"id":"1.195453779","rc":[{"atl":[[1.64,43.59],[1.65,172.77]],"id":40622317}],"con":true,"img":false}]}
{"op":"mcm","clk":"5353814415","pt":1646218741228,"mc":[{"id":"1.195453779","rc":[{"atl":[[2.1,2.5]],"id":40622317}],"con":true,"img":false}]}
{"op":"mcm","clk":"5353814462","pt":1646218741693,"mc":[{"id":"1.195453779","rc":[{"atb":[[3.75,4.4]],"id":42256449}],"con":true,"img":false}]}
{"op":"mcm","clk":"5353814563","pt":1646218742590,"mc":[{"id":"1.195453779","rc":[{"atb":[[1.42,250]],"id":39832467}],"con":true,"img":false}]}
{"op":"mcm","clk":"5353814695","pt":1646218743890,"mc":[{"id":"1.195453779","rc":[{"atb":[[1.4,0]],"id":39786303},{"atl":[[2.16,0]],"id":39786303},{"atl":[[3.3,52.18]],"id":38247337}],"con":true,"img":false}]}
{"op":"mcm","clk":"5353814704","pt":1646218743994,"mc":[{"id":"1.195453779","rc":[{"atb":[[1.36,82.9]],"id":39786303},{"atl":[[2.12,41.13]],"id":39786303},{"atl":[[3.25,55.37]],"id":38247337}],"con":true,"img":false}]}
{"op":"mcm","clk":"5353814725","pt":1646218744208,"mc":[{"id":"1.195453779","rc":[{"atl":[[2.12,164.1],[2.14,43.86]],"id":39786303}],"con":true,"img":false}]}
{"op":"mcm","clk":"5353814928","pt":1646218746033,"mc":[{"id":"1.195453779","rc":[{"atl":[[1.63,31.75],[1.62,6]],"id":40622317},{"atb":[[1.82,23.06]],"id":40072523}],"con":true,"img":false}]}
{"op":"mcm","clk":"5353815014","pt":1646218746972,"mc":[{"id":"1.195453779","rc":[{"atb":[[1.51,31.09]],"id":39786303},{"spn":1.8,"spf":"NaN","id":39786303},{"spn":2.42,"spf":"NaN","id":38247337},{"spn":5.27,"spf":"NaN","id":42256449},{"spn":8.75,"spf":"NaN","id":40812693},{"spn":2.27,"spf":"NaN","id":39832467},{"spn":1.43,"spf":"NaN","id":40622317}],"con":true,"img":false}]}
{"op":"mcm","clk":"5353815073","pt":1646218747599,"mc":[{"id":"1.195453779","rc":[{"atb":[[1.82,24.34]],"id":38247337}],"con":true,"img":false}]}
{"op":"mcm","clk":"5353815086","pt":1646218747704,"mc":[{"id":"1.195453779","rc":[{"atb":[[1.89,8.45],[1.9,0]],"id":40072523}],"con":true,"img":false}]}
{"op":"mcm","clk":"5353815094","pt":1646218747803,"mc":[{"id":"1.195453779","rc":[{"atb":[[3.55,2.5],[3.75,23.49],[3.65,58.44]],"id":42256449}],"con":true,"img":false}]}
{"op":"mcm","clk":"5353815116","pt":1646218748010,"mc":[{"id":"1.195453779","rc":[{"atb":[[3.7,0]],"id":42256449}],"con":true,"img":false}]}
{"op":"mcm","clk":"5353815160","pt":1646218748487,"mc":[{"id":"1.195453779","rc":[{"atb":[[1.28,0],[1.26,113.89]],"id":39786303}],"con":true,"img":false}]}
{"op":"mcm","clk":"5353815185","pt":1646218748707,"mc":[{"id":"1.195453779","rc":[{"atb":[[1.53,0]],"id":39832467}],"con":true,"img":false}]}
{"op":"mcm","clk":"5353815199","pt":1646218748798,"mc":[{"id":"1.195453779","rc":[{"atb":[[1.55,96.88]],"id":39832467}],"con":true,"img":false}]}
{"op":"mcm","clk":"5353815207","pt":1646218748898,"mc":[{"id":"1.195453779","rc":[{"atb":[[3.65,38.17]],"id":42256449},{"atb":[[1.15,133.33]],"id":40622317}],"con":true,"img":false}]}
{"op":"mcm","clk":"5353815216","pt":1646218749001,"mc":[{"id":"1.195453779","rc":[{"atb":[[3.75,43.77]],"id":42256449},{"atb":[[1.18,98.04]],"id":40622317}],"con":true,"img":false}]}
{"op":"mcm","clk":"5353815240","pt":1646218749213,"mc":[{"id":"1.195453779","rc":[{"atb":[[1.18,200.32],[1.17,10]],"id":40622317}],"con":true,"img":false}]}
{"op":"mcm","clk":"5353815403","pt":1646218750683,"mc":[{"id":"1.195453779","rc":[{"atb":[[3.75,41.03]],"id":42256449}],"con":true,"img":false}]}
{"op":"mcm","clk":"5353815628","pt":1646218752992,"mc":[{"id":"1.195453779","rc":[{"atl":[[1.62,38.26]],"id":40622317},{"atb":[[1.82,0]],"id":40072523}],"con":true,"img":false}]}
{"op":"mcm","clk":"5353815708","pt":1646218753920,"mc":[{"id":"1.195453779","rc":[{"atb":[[1.69,0]],"id":40072523}],"con":true,"img":false}]}
{"op":"mcm","clk":"5353815719","pt":1646218754022,"mc":[{"id":"1.195453779","rc":[{"atb":[[1.65,53.82]],"id":40072523}],"con":true,"img":false}]}
{"op":"mcm","clk":"5353815798","pt":1646218754917,"mc":[{"id":"1.195453779","rc":[{"atb":[[3.55,77.56],[3.65,0]],"id":42256449}],"con":true,"img":false}]}
{"op":"mcm","clk":"5353815935","pt":1646218756311,"mc":[{"id":"1.195453779","rc":[{"atl":[[1.64,155.64]],"id":40622317}],"con":true,"img":false}]}
{"op":"mcm","clk":"5353815942","pt":1646218756414,"mc":[{"id":"1.195453779","rc":[{"atl":[[1.65,0]],"id":40622317}],"con":true,"img":false}]}
{"op":"mcm","clk":"5353815983","pt":1646218756936,"mc":[{"id":"1.195453779","rc":[{"atb":[[1.77,61.41]],"id":40072523}],"con":true,"img":false}]}
{"op":"mcm","clk":"5353816131","pt":1646218758212,"mc":[{"id":"1.195453779","rc":[{"atl":[[2.8,32.84],[2.78,26.05]],"id":39832467},{"atl":[[1.62,6]],"id":40622317},{"atb":[[1.82,23.06]],"id":40072523}],"con":true,"img":false}]}
{"op":"mcm","clk":"5353816174","pt":1646218758624,"mc":[{"id":"1.195453779","rc":[{"atb":[[1.49,44.93]],"id":39786303},{"atb":[[1.79,30.02]],"id":38247337},{"atb":[[1.19,51.02]],"id":40622317}],"con":true,"img":false}]}
{"op":"mcm","clk":"5353816189","pt":1646218758830,"mc":[{"id":"1.195453779","rc":[{"atb":[[1.48,5],[1.49,173]],"id":39786303},{"atb":[[1.78,10],[1.79,153.32]],"id":38247337}],"con":true,"img":false}]}
{"op":"mcm","clk":"5353816200","pt":1646218758889,"mc":[{"id":"1.195453779","rc":[{"atl":[[3.9,5]],"id":40072523}],"con":true,"img":false}]}
{"op":"mcm","clk":"5353816215","pt":1646218759041,"mc":[{"id":"1.195453779","rc":[{"atl":[[3.7,16.59]],"id":40072523}],"con":true,"img":false}]}
{"op":"mcm","clk":"5353816286","pt":1646218759735,"mc":[{"id":"1.195453779","rc":[{"atb":[[1.51,16.34]],"id":39786303},{"atb":[[1.82,15.17]],"id":38247337}],"con":true,"img":false}]}
{"op":"mcm","clk":"5353816524","pt":1646218761898,"mc":[{"id":"1.195453779","rc":[{"atb":[[3.35,84.36],[3.55,2.5]],"id":42256449}],"con":true,"img":false}]}
{"op":"mcm","clk":"5353816651","pt":1646218763105,"mc":[{"id":"1.195453779","rc":[{"atb":[[1.89,17.82]],"id":40072523}],"con":true,"img":false}]}
