{"op":"mcm","clk":"5351767856","pt":1646175389021,"mc":[{"id":"1.195453770","marketDefinition":{"bspMarket":true,"turnInPlayEnabled":false,"persistenceEnabled":false,"marketBaseRate":7.0,"eventId":"31272499","eventTypeId":"4339","numberOfWinners":1,"bettingType":"ODDS","marketType":"WIN","marketTime":"2022-03-02T09:54:00.000Z","suspendTime":"2022-03-02T09:54:00.000Z","bspReconciled":false,"complete":true,"inPlay":false,"crossMatching":false,"runnersVoidable":false,"numberOfActiveRunners":8,"betDelay":0,"status":"OPEN","runners":[{"status":"ACTIVE","sortPriority":1,"id":36074638,"name":"1. Just Law"},{"status":"ACTIVE","sortPriority":2,"id":39784543,"name":"2. Surreal"},{"status":"ACTIVE","sortPriority":3,"id":36500377,"name":"3. Mystery Train"},{"status":"ACTIVE","sortPriority":4,"id":42189401,"name":"4. Daisy Cousins"},{"status":"ACTIVE","sortPriority":5,"id":35801684,"name":"5. Zeke The Freak"},{"status":"ACTIVE","sortPriority":6,"id":37127725,"name":"6. Exit Plan"},{"status":"ACTIVE","sortPriority":7,"id":26051221,"name":"7. Farmor Crownies"},{"status":"ACTIVE","sortPriority":8,"id":28338255,"name":"8. Until Late"}],"regulators":["MR_INT"],"venue":"Rockhampton","countryCode":"AU","discountAllowed":true,"timezone":"Australia/Queensland","openDate":"2022-03-02T08:34:00.000Z","version":4382437863,"name":"R5 407m Gr4","eventName":"Rockhampton (AUS) 2nd Mar"},"rc":[],"con":true,"img":false}]}
{"op":"mcm","clk":"5351829775","pt":1646176640937,"mc":[{"id":"1.195453770","rc":[{"atb":[[17,6.42],[12,9.34],[9.8,11.67],[14.5,7.61]],"id":39784543},{"atl":[[270,0.74],[170,0.78],[220,0.9],[120,1.11]],"id":39784543},{"spn":68.5,"spf":"NaN","id":39784543},{"atb":[[9.6,11.94],[8.6,13.52],[11.5,9.78],[14,7.9]],"id":36500377},{"atl":[[130,1.02],[90,1.49],[180,1.11],[230,0.87]],"id":36500377},{"spn":52.0,"spf":"NaN","id":36500377},{"atb":[[9.6,11.94],[8.6,13.52],[11.5,9.78],[14,7.9]],"id":35801684},{"atl":[[130,1.02],[90,1.49],[180,1.11],[230,0.87]],"id":35801684},{"spn":52.0,"spf":"NaN","id":35801684},{"atb":[[16,6.84],[11,10.27],[13.5,8.21],[9.4,12.23]],"id":36074638},{"atl":[[260,0.77],[160,0.83],[210,0.95],[110,1.21]],"id":36074638},{"spn":63.0,"spf":"NaN","id":36074638},{"atb":[[2.4,73.39],[2.3,79.03],[2.2,85.62],[2.1,93.4]],"id":42189401},{"atl":[[5.6,28.92],[7.2,32.18],[6.2,25.58],[8.2,27.71]],"id":42189401},{"spn":4.0,"spf":"NaN","id":42189401},{"atb":[[2.8,57.08],[2.9,54.07],[3,51.37],[2.7,60.44]],"id":37127725},{"atl":[[12,18.14],[9.8,22.67],[8.8,17.05],[7.8,19.56]],"id":37127725},{"spn":5.4,"spf":"NaN","id":37127725},{"atb":[[9.2,12.53],[10.5,10.81],[8.2,14.27],[13,8.56]],"id":28338255},{"atl":[[80,1.68],[160,1.25],[210,0.95],[110,1.21]],"id":28338255},{"spn":46.5,"spf":"NaN","id":28338255},{"atb":[[2.74,59.05],[3.1,48.92],[2.84,55.84],[2.94,52.96]],"id":26051221},{"atl":[[8,19],[9,16.63],[10,22.17],[12.5,17.35]],"id":26051221},{"spn":5.55,"spf":"NaN","id":26051221}],"con":true,"img":false}]}
{"op":"mcm","clk":"5351831312","pt":1646176678387,"mc":[{"id":"1.195453770","rc":[{"atb":[[17,0],[12,0],[9.8,0],[14.5,0]],"id":39784543},{"atl":[[270,0],[170,0],[220,0],[120,0]],"id":39784543},{"atb":[[9.6,0],[8.6,0],[11.5,0],[14,0]],"id":36500377},{"atl":[[130,0],[90,0],[180,0],[230,0]],"id":36500377},{"atb":[[9.6,0],[8.6,0],[11.5,0],[14,0]],"id":35801684},{"atl":[[130,0],[90,0],[180,0],[230,0]],"id":35801684},{"atb":[[16,0],[11,0],[13.5,0],[9.4,0]],"id":36074638},{"atl":[[260,0],[160,0],[210,0],[110,0]],"id":36074638},{"atb":[[2.4,0],[2.3,0],[2.2,0],[2.1,0]],"id":42189401},{"atl":[[5.6,0],[7.2,0],[6.2,0],[8.2,0]],"id":42189401},{"atb":[[2.8,0],[2.9,0],[3,0],[2.7,0]],"id":37127725},{"atl":[[12,0],[9.8,0],[8.8,0],[7.8,0]],"id":37127725},{"atb":[[9.2,0],[10.5,0],[8.2,0],[13,0]],"id":28338255},{"atl":[[80,0],[160,0],[210,0],[110,0]],"id":28338255},{"atb":[[2.74,0],[3.1,0],[2.84,0],[2.94,0]],"id":26051221},{"atl":[[8,0],[9,0],[10,0],[12.5,0]],"id":26051221}],"con":true,"img":false}]}
{"op":"mcm","clk":"5351832836","pt":1646176717930,"mc":[{"id":"1.195453770","rc":[{"atb":[[17,6.42],[12,9.34],[9.8,11.67],[14.5,7.61]],"id":39784543},{"atl":[[270,0.74],[170,0.78],[220,0.9],[120,1.11]],"id":39784543},{"atb":[[9.6,11.94],[8.6,13.52],[11.5,9.78],[14,7.9]],"id":36500377},{"atl":[[130,1.02],[90,1.49],[180,1.11],[230,0.87]],"id":36500377},{"atb":[[9.6,11.94],[8.6,13.52],[11.5,9.78],[14,7.9]],"id":35801684},{"atl":[[130,1.02],[90,1.49],[180,1.11],[230,0.87]],"id":35801684},{"atb":[[16,6.84],[11,10.27],[13.5,8.21],[9.4,12.23]],"id":36074638},{"atl":[[260,0.77],[160,0.83],[210,0.95],[110,1.21]],"id":36074638},{"atb":[[2.4,73.39],[2.3,79.03],[2.2,85.62],[2.1,93.4]],"id":42189401},{"atl":[[5.6,28.92],[7.2,32.18],[6.2,25.58],[8.2,27.71]],"id":42189401},{"atb":[[2.8,57.08],[2.9,54.07],[3,51.37],[2.7,60.44]],"id":37127725},{"atl":[[12,18.14],[9.8,22.67],[8.8,17.05],[7.8,19.56]],"id":37127725},{"atb":[[4,34.25],[4.5,29.35],[5,25.68],[5.5,22.83]],"id":28338255},{"atl":[[17,8.31],[19.5,7.19],[24,8.67],[29,7.12]],"id":28338255},{"spn":11.25,"spf":"NaN","id":28338255},{"atb":[[2.74,59.05],[3.1,48.92],[2.84,55.84],[2.94,52.96]],"id":26051221},{"atl":[[8,19],[9,16.63],[10,22.17],[12.5,17.35]],"id":26051221}],"con":true,"img":false}]}
{"op":"mcm","clk":"5351835009","pt":1646176768084,"mc":[{"id":"1.195453770","rc":[{"atb":[[17,0],[12,0],[9.8,0],[14.5,0]],"id":39784543},{"atl":[[270,0],[170,0],[220,0],[120,0]],"id":39784543},{"atb":[[9.6,0],[8.6,0],[11.5,0],[14,0]],"id":36500377},{"atl":[[130,0],[90,0],[180,0],[230,0]],"id":36500377},{"atb":[[9.6,0],[8.6,0],[11.5,0],[14,0]],"id":35801684},{"atl":[[130,0],[90,0],[180,0],[230,0]],"id":35801684},{"atb":[[16,0],[11,0],[13.5,0],[9.4,0]],"id":36074638},{"atl":[[260,0],[160,0],[210,0],[110,0]],"id":36074638},{"atb":[[2.4,0],[2.3,0],[2.2,0],[2.1,0]],"id":42189401},{"atl":[[5.6,0],[7.2,0],[6.2,0],[8.2,0]],"id":42189401},{"atb":[[2.8,0],[2.9,0],[3,0],[2.7,0]],"id":37127725},{"atl":[[12,0],[9.8,0],[8.8,0],[7.8,0]],"id":37127725},{"atb":[[2.74,0],[3.1,0],[2.84,0],[2.94,0]],"id":26051221},{"atl":[[8,0],[9,0],[10,0],[12.5,0]],"id":26051221},{"atb":[[4,0],[4.5,0],[5,0],[5.5,0]],"id":28338255},{"atl":[[17,0],[19.5,0],[24,0],[29,0]],"id":28338255}],"con":true,"img":false}]}
{"op":"mcm","clk":"5351835810","pt":1646176785738,"mc":[{"id":"1.195453770","rc":[{"atb":[[16.5,6.63],[19,5.71],[11.5,9.78],[14,7.9]],"id":39784543},{"atl":[[140,0.95],[290,0.69],[190,0.7],[240,0.83]],"id":39784543},{"spn":79.5,"spf":"NaN","id":39784543},{"atb":[[9,12.84],[10,11.41],[12.5,8.93],[15,7.33]],"id":36500377},{"atl":[[150,0.89],[100,1.34],[200,1],[250,0.8]],"id":36500377},{"spn":57.5,"spf":"NaN","id":36500377},{"atb":[[16,6.84],[11,10.27],[13.5,8.21],[9.4,12.23]],"id":35801684},{"atl":[[260,0.77],[160,0.83],[210,0.95],[110,1.21]],"id":35801684},{"spn":63.0,"spf":"NaN","id":35801684},{"atb":[[18,6.04],[10.5,10.81],[13,8.56],[15.5,7.08]],"id":36074638},{"atl":[[130,1.02],[280,0.71],[180,0.74],[230,0.87]],"id":36074638},{"spn":74.0,"spf":"NaN","id":36074638},{"atb":[[2.4,73.39],[2.5,68.49],[2.3,79.03],[2.6,64.21]],"id":42189401},{"atl":[[8,28.5],[9,24.94],[6,26.6],[7,22.17]],"id":42189401},{"spn":4.3,"spf":"NaN","id":42189401},{"atb":[[2.8,57.08],[2.9,54.07],[3,51.37],[2.7,60.44]],"id":37127725},{"atl":[[12,18.14],[9.8,22.67],[8.8,17.05],[7.8,19.56]],"id":37127725},{"atb":[[2.82,56.45],[2.92,53.51],[3.3,44.67],[3.05,50.11]],"id":26051221},{"atl":[[9.2,16.22],[10.5,21],[8.2,18.47],[13,16.63]],"id":26051221},{"spn":5.75,"spf":"NaN","id":26051221},{"atb":[[4,34.25],[4.5,29.35],[5,25.68],[5.5,22.83]],"id":28338255},{"atl":[[17,8.31],[19.5,7.19],[24,8.67],[29,7.12]],"id":28338255}],"con":true,"img":false}]}
{"op":"mcm","clk":"5352003878","pt":1646180202624,"mc":[{"id":"1.195453770","marketDefinition":{"bspMarket":true,"turnInPlayEnabled":false,"persistenceEnabled":false,"marketBaseRate":7.0,"eventId":"31272499","eventTypeId":"4339","numberOfWinners":1,"bettingType":"ODDS","marketType":"WIN","marketTime":"2022-03-02T09:54:00.000Z","suspendTime":"2022-03-02T09:54:00.000Z","bspReconciled":false,"complete":true,"inPlay":false,"crossMatching":false,"runnersVoidable":false,"numberOfActiveRunners":8,"betDelay":0,"status":"OPEN","runners":[{"status":"ACTIVE","sortPriority":1,"id":36074638,"name":"1. Just Law"},{"status":"ACTIVE","sortPriority":2,"id":39784543,"name":"2. Surreal"},{"status":"ACTIVE","sortPriority":3,"id":36500377,"name":"3. Mystery Train"},{"status":"ACTIVE","sortPriority":4,"id":42189401,"name":"4. Daisy Cousins"},{"status":"ACTIVE","sortPriority":5,"id":35801684,"name":"5. Zeke The Freak"},{"status":"ACTIVE","sortPriority":6,"id":37127725,"name":"6. Exit Plan"},{"status":"ACTIVE","sortPriority":7,"id":26051221,"name":"7. Farmor Crownies"},{"status":"ACTIVE","sortPriority":8,"id":28338255,"name":"8. Until Late"}],"regulators":["MR_INT"],"venue":"Rockhampton","countryCode":"AU","discountAllowed":true,"timezone":"Australia/Queensland","openDate":"2022-03-02T08:34:00.000Z","version":4382437863,"name":"R5 407m Gr4","eventName":"Rockhampton (AUS) 2nd Mar"},"rc":[{"atb":[[16.5,6.63],[19,5.71],[11.5,9.78],[14,7.9]],"id":39784543},{"atl":[[140,0.95],[290,0.69],[190,0.7],[240,0.83]],"id":39784543},{"spn":79.5,"spf":"NaN","id":39784543},{"atb":[[9,12.84],[10,11.41],[12.5,8.93],[15,7.33]],"id":36500377},{"atl":[[150,0.89],[100,1.34],[200,1],[250,0.8]],"id":36500377},{"spn":57.5,"spf":"NaN","id":36500377},{"atb":[[16,6.84],[11,10.27],[13.5,8.22],[9.4,12.23]],"id":35801684},{"atl":[[260,0.77],[160,0.83],[210,0.95],[110,1.21]],"id":35801684},{"spn":63.0,"spf":"NaN","id":35801684},{"atb":[[18,6.04],[10.5,10.81],[13,8.56],[15.5,7.08]],"id":36074638},{"atl":[[130,1.02],[280,0.71],[180,0.74],[230,0.87]],"id":36074638},{"spn":74.0,"spf":"NaN","id":36074638},{"atb":[[2.4,73.39],[2.5,68.5],[2.3,79.04],[2.6,64.22]],"id":42189401},{"atl":[[8,28.51],[9,24.94],[6,26.61],[7,22.17]],"id":42189401},{"spn":4.3,"spf":"NaN","id":42189401},{"atb":[[2.8,57.08],[2.9,54.08],[3,51.38],[2.7,60.44]],"id":37127725},{"atl":[[12,18.14],[9.8,22.68],[8.8,17.05],[7.8,19.56]],"id":37127725},{"spn":5.4,"spf":"NaN","id":37127725},{"atb":[[4,34.25],[4.5,29.36],[5,25.69],[5.5,22.83]],"id":28338255},{"atl":[[17,8.31],[19.5,7.19],[24,8.67],[29,7.12]],"id":28338255},{"spn":11.25,"spf":"NaN","id":28338255},{"atb":[[2.82,56.46],[2.92,53.52],[3.3,44.68],[3.05,50.12]],"id":26051221},{"atl":[[9.2,16.22],[10.5,21],[8.2,18.47],[13,16.63]],"id":26051221},{"spn":5.75,"spf":"NaN","id":26051221}],"con":true,"img":true}]}
{"op":"mcm","clk":"5352146201","pt":1646183572661,"mc":[{"id":"1.195453770","marketDefinition":{"bspMarket":true,"turnInPlayEnabled":false,"persistenceEnabled":false,"marketBaseRate":7.0,"eventId":"31272499","eventTypeId":"4339","numberOfWinners":1,"bettingType":"ODDS","marketType":"WIN","marketTime":"2022-03-02T09:54:00.000Z","suspendTime":"2022-03-02T09:54:00.000Z","bspReconciled":false,"complete":true,"inPlay":false,"crossMatching":false,"runnersVoidable":false,"numberOfActiveRunners":8,"betDelay":0,"status":"OPEN","runners":[{"status":"ACTIVE","sortPriority":1,"id":36074638,"name":"1. Just Law"},{"status":"ACTIVE","sortPriority":2,"id":39784543,"name":"2. Surreal"},{"status":"ACTIVE","sortPriority":3,"id":36500377,"name":"3. Mystery Train"},{"status":"ACTIVE","sortPriority":4,"id":42189401,"name":"4. Daisy Cousins"},{"status":"ACTIVE","sortPriority":5,"id":35801684,"name":"5. Zeke The Freak"},{"status":"ACTIVE","sortPriority":6,"id":37127725,"name":"6. Exit Plan"},{"status":"ACTIVE","sortPriority":7,"id":26051221,"name":"7. Farmor Crownies"},{"status":"ACTIVE","sortPriority":8,"id":28338255,"name":"8. Until Late"}],"regulators":["MR_INT"],"venue":"Rockhampton","countryCode":"AU","discountAllowed":true,"timezone":"Australia/Queensland","openDate":"2022-03-02T08:28:00.000Z","version":4382597832,"name":"R5 407m Gr4","eventName":"Rockhampton (AUS) 2nd Mar"},"rc":[],"con":true,"img":false}]}
{"op":"mcm","clk":"5352156700","pt":1646183856245,"mc":[{"id":"1.195453770","marketDefinition":{"bspMarket":true,"turnInPlayEnabled":false,"persistenceEnabled":false,"marketBaseRate":7.0,"eventId":"31272499","eventTypeId":"4339","numberOfWinners":1,"bettingType":"ODDS","marketType":"WIN","marketTime":"2022-03-02T09:47:00.000Z","suspendTime":"2022-03-02T09:47:00.000Z","bspReconciled":false,"complete":true,"inPlay":false,"crossMatching":false,"runnersVoidable":false,"numberOfActiveRunners":8,"betDelay":0,"status":"OPEN","runners":[{"status":"ACTIVE","sortPriority":1,"id":36074638,"name":"1. Just Law"},{"status":"ACTIVE","sortPriority":2,"id":39784543,"name":"2. Surreal"},{"status":"ACTIVE","sortPriority":3,"id":36500377,"name":"3. Mystery Train"},{"status":"ACTIVE","sortPriority":4,"id":42189401,"name":"4. Daisy Cousins"},{"status":"ACTIVE","sortPriority":5,"id":35801684,"name":"5. Zeke The Freak"},{"status":"ACTIVE","sortPriority":6,"id":37127725,"name":"6. Exit Plan"},{"status":"ACTIVE","sortPriority":7,"id":26051221,"name":"7. Farmor Crownies"},{"status":"ACTIVE","sortPriority":8,"id":28338255,"name":"8. Until Late"}],"regulators":["MR_INT"],"venue":"Rockhampton","countryCode":"AU","discountAllowed":true,"timezone":"Australia/Queensland","openDate":"2022-03-02T08:28:00.000Z","version":4382601976,"name":"R5 407m Gr4","eventName":"Rockhampton (AUS) 2nd Mar"},"rc":[],"con":true,"img":false}]}
{"op":"mcm","clk":"5352237998","pt":1646185602657,"mc":[{"id":"1.195453770","marketDefinition":{"bspMarket":true,"turnInPlayEnabled":false,"persistenceEnabled":false,"marketBaseRate":7.0,"eventId":"31272499","eventTypeId":"4339","numberOfWinners":1,"bettingType":"ODDS","marketType":"WIN","marketTime":"2022-03-02T09:47:00.000Z","suspendTime":"2022-03-02T09:47:00.000Z","bspReconciled":false,"complete":true,"inPlay":false,"crossMatching":false,"runnersVoidable":false,"numberOfActiveRunners":8,"betDelay":0,"status":"OPEN","runners":[{"status":"ACTIVE","sortPriority":1,"id":36074638,"name":"1. Just Law"},{"status":"ACTIVE","sortPriority":2,"id":39784543,"name":"2. Surreal"},{"status":"ACTIVE","sortPriority":3,"id":36500377,"name":"3. Mystery Train"},{"status":"ACTIVE","sortPriority":4,"id":42189401,"name":"4. Daisy Cousins"},{"status":"ACTIVE","sortPriority":5,"id":35801684,"name":"5. Zeke The Freak"},{"status":"ACTIVE","sortPriority":6,"id":37127725,"name":"6. Exit Plan"},{"status":"ACTIVE","sortPriority":7,"id":26051221,"name":"7. Farmor Crownies"},{"status":"ACTIVE","sortPriority":8,"id":28338255,"name":"8. Until Late"}],"regulators":["MR_INT"],"venue":"Rockhampton","countryCode":"AU","discountAllowed":true,"timezone":"Australia/Queensland","openDate":"2022-03-02T08:28:00.000Z","version":4382601976,"name":"R5 407m Gr4","eventName":"Rockhampton (AUS) 2nd Mar"},"rc":[{"atb":[[16.5,6.64],[19,5.72],[11.5,9.8],[14,7.91]],"id":39784543},{"atl":[[140,0.95],[290,0.69],[190,0.7],[240,0.83]],"id":39784543},{"spn":79.5,"spf":"NaN","id":39784543},{"atb":[[9,12.86],[10,11.43],[12.5,8.94],[15,7.35]],"id":36500377},{"atl":[[150,0.89],[100,1.34],[200,1],[250,0.8]],"id":36500377},{"spn":57.5,"spf":"NaN","id":36500377},{"atb":[[16,6.85],[11,10.29],[13.5,8.23],[9.4,12.25]],"id":35801684},{"atl":[[260,0.77],[160,0.83],[210,0.95],[110,1.22]],"id":35801684},{"spn":63.0,"spf":"NaN","id":35801684},{"atb":[[18,6.05],[10.5,10.83],[13,8.57],[15.5,7.09]],"id":36074638},{"atl":[[130,1.03],[280,0.71],[180,0.74],[230,0.87]],"id":36074638},{"spn":74.0,"spf":"NaN","id":36074638},{"atb":[[2.4,73.51],[2.5,68.61],[2.3,79.17],[2.6,64.32]],"id":42189401},{"atl":[[8,28.55],[9,24.98],[6,26.65],[7,22.2]],"id":42189401},{"spn":4.3,"spf":"NaN","id":42189401},{"atb":[[2.8,57.17],[2.9,54.16],[3,51.46],[2.7,60.54]],"id":37127725},{"atl":[[12,18.17],[9.8,22.71],[8.8,17.08],[7.8,19.59]],"id":37127725},{"spn":5.4,"spf":"NaN","id":37127725},{"atb":[[4,34.3],[4.5,29.4],[5,25.73],[5.5,22.86]],"id":28338255},{"atl":[[17,8.33],[19.5,7.2],[24,8.69],[29,7.13]],"id":28338255},{"spn":11.25,"spf":"NaN","id":28338255},{"atb":[[2.82,56.55],[2.92,53.6],[3.3,44.75],[3.05,50.2]],"id":26051221},{"atl":[[9.2,16.24],[10.5,21.04],[8.2,18.5],[13,16.65]],"id":26051221},{"spn":5.75,"spf":"NaN","id":26051221}],"con":true,"img":true}]}
{"op":"mcm","clk":"5352465295","pt":1646191002606,"mc":[{"id":"1.195453770","marketDefinition":{"bspMarket":true,"turnInPlayEnabled":false,"persistenceEnabled":false,"marketBaseRate":7.0,"eventId":"31272499","eventTypeId":"4339","numberOfWinners":1,"bettingType":"ODDS","marketType":"WIN","marketTime":"2022-03-02T09:47:00.000Z","suspendTime":"2022-03-02T09:47:00.000Z","bspReconciled":false,"complete":true,"inPlay":false,"crossMatching":false,"runnersVoidable":false,"numberOfActiveRunners":8,"betDelay":0,"status":"OPEN","runners":[{"status":"ACTIVE","sortPriority":1,"id":36074638,"name":"1. Just Law"},{"status":"ACTIVE","sortPriority":2,"id":39784543,"name":"2. Surreal"},{"status":"ACTIVE","sortPriority":3,"id":36500377,"name":"3. Mystery Train"},{"status":"ACTIVE","sortPriority":4,"id":42189401,"name":"4. Daisy Cousins"},{"status":"ACTIVE","sortPriority":5,"id":35801684,"name":"5. Zeke The Freak"},{"status":"ACTIVE","sortPriority":6,"id":37127725,"name":"6. Exit Plan"},{"status":"ACTIVE","sortPriority":7,"id":26051221,"name":"7. Farmor Crownies"},{"status":"ACTIVE","sortPriority":8,"id":28338255,"name":"8. Until Late"}],"regulators":["MR_INT"],"venue":"Rockhampton","countryCode":"AU","discountAllowed":true,"timezone":"Australia/Queensland","openDate":"2022-03-02T08:28:00.000Z","version":4382601976,"name":"R5 407m Gr4","eventName":"Rockhampton (AUS) 2nd Mar"},"rc":[{"atb":[[16.5,6.65],[19,5.72],[11.5,9.82],[14,7.93]],"id":39784543},{"atl":[[140,0.96],[290,0.69],[190,0.7],[240,0.83]],"id":39784543},{"spn":79.5,"spf":"NaN","id":39784543},{"atb":[[9,12.88],[10,11.45],[12.5,8.96],[15,7.36]],"id":36500377},{"atl":[[150,0.89],[100,1.34],[200,1],[250,0.8]],"id":36500377},{"spn":57.5,"spf":"NaN","id":36500377},{"atb":[[16,6.87],[11,10.31],[13.5,8.24],[9.4,12.27]],"id":35801684},{"atl":[[260,0.77],[160,0.84],[210,0.95],[110,1.22]],"id":35801684},{"spn":63.0,"spf":"NaN","id":35801684},{"atb":[[18,6.06],[10.5,10.85],[13,8.59],[15.5,7.11]],"id":36074638},{"atl":[[130,1.03],[280,0.71],[180,0.74],[230,0.87]],"id":36074638},{"spn":74.0,"spf":"NaN","id":36074638},{"atb":[[2.4,73.63],[2.5,68.72],[2.3,79.3],[2.6,64.43]],"id":42189401},{"atl":[[8,28.6],[9,25.02],[6,26.69],[7,22.24]],"id":42189401},{"spn":4.3,"spf":"NaN","id":42189401},{"atb":[[2.8,57.27],[2.9,54.26],[3,51.55],[2.7,60.64]],"id":37127725},{"atl":[[12,18.2],[9.8,22.75],[8.8,17.11],[7.8,19.63]],"id":37127725},{"spn":5.4,"spf":"NaN","id":37127725},{"atb":[[4,34.36],[4.5,29.45],[5,25.77],[5.5,22.9]],"id":28338255},{"atl":[[17,8.34],[19.5,7.21],[24,8.7],[29,7.14]],"id":28338255},{"spn":11.25,"spf":"NaN","id":28338255},{"atb":[[2.82,56.64],[2.92,53.69],[3.3,44.82],[3.05,50.28]],"id":26051221},{"atl":[[9.2,16.27],[10.5,21.07],[8.2,18.53],[13,16.68]],"id":26051221},{"spn":5.75,"spf":"NaN","id":26051221}],"con":true,"img":true}]}
{"op":"mcm","clk":"5352712090","pt":1646197861678,"mc":[{"id":"1.195453770","rc":[{"atb":[[16.5,6.65],[19,5.72],[11.5,9.81],[14,7.92]],"id":39784543},{"atl":[[140,0.96],[290,0.69],[190,0.7],[240,0.83]],"id":39784543},{"atb":[[9,12.88],[10,11.44],[12.5,8.95],[15,7.36]],"id":36500377},{"atl":[[150,0.89],[100,1.34],[200,1],[250,0.8]],"id":36500377},{"atb":[[16,6.86],[11,10.3],[13.5,8.24],[9.4,12.26]],"id":35801684},{"atl":[[260,0.77],[160,0.84],[210,0.95],[110,1.22]],"id":35801684},{"atb":[[18,6.06],[10.5,10.84],[13,8.58],[15.5,7.1]],"id":36074638},{"atl":[[130,1.03],[280,0.71],[180,0.74],[230,0.87]],"id":36074638},{"atb":[[2.4,73.61],[2.5,68.7],[2.3,79.27],[2.6,64.41]],"id":42189401},{"atl":[[8,28.59],[9,25.01],[5,4.92],[6,26.68],[7,22.23]],"id":42189401},{"spn":3.8,"spf":"NaN","id":42189401},{"atb":[[2.8,57.25],[2.9,54.23],[3,51.53],[2.7,60.62]],"id":37127725},{"atl":[[12,18.19],[9.8,22.74],[8.8,17.1],[7.8,19.62]],"id":37127725},{"atb":[[4,34.35],[4.5,29.44],[5,25.76],[5.5,22.89]],"id":28338255},{"atl":[[17,8.34],[19.5,7.21],[24,8.7],[29,7.14]],"id":28338255},{"atb":[[2.82,56.62],[2.92,53.67],[3.3,44.81],[3.05,50.27]],"id":26051221},{"atl":[[9.2,16.27],[10.5,21.07],[8.2,18.53],[13,16.68]],"id":26051221}],"con":true,"img":false}]}
{"op":"mcm","clk":"5352787781","pt":1646200575055,"mc":[{"id":"1.195453770","rc":[{"atl":[[2.86,12.01]],"id":42189401},{"spn":2.73,"spf":"NaN","id":42189401},{"atl":[[3.85,12.01]],"id":37127725},{"spn":3.42,"spf":"NaN","id":37127725}],"con":true,"img":false}]}
{"op":"mcm","clk":"5352788669","pt":1646200605598,"mc":[{"id":"1.195453770","rc":[{"atl":[[2.86,0]],"id":42189401},{"atl":[[3.85,0]],"id":37127725}],"con":true,"img":false}]}
{"op":"mcm","clk":"5352788671","pt":1646200605700,"mc":[{"id":"1.195453770","rc":[{"atl":[[3.25,12.01]],"id":42189401},{"atl":[[4.7,12.01]],"id":37127725}],"con":true,"img":false}]}
{"op":"mcm","clk":"5352822089","pt":1646201802639,"mc":[{"id":"1.195453770","marketDefinition":{"bspMarket":true,"turnInPlayEnabled":false,"persistenceEnabled":false,"marketBaseRate":7.0,"eventId":"31272499","eventTypeId":"4339","numberOfWinners":1,"bettingType":"ODDS","marketType":"WIN","marketTime":"2022-03-02T09:47:00.000Z","suspendTime":"2022-03-02T09:47:00.000Z","bspReconciled":false,"complete":true,"inPlay":false,"crossMatching":false,"runnersVoidable":false,"numberOfActiveRunners":8,"betDelay":0,"status":"OPEN","runners":[{"status":"ACTIVE","sortPriority":1,"id":36074638,"name":"1. Just Law"},{"status":"ACTIVE","sortPriority":2,"id":39784543,"name":"2. Surreal"},{"status":"ACTIVE","sortPriority":3,"id":36500377,"name":"3. Mystery Train"},{"status":"ACTIVE","sortPriority":4,"id":42189401,"name":"4. Daisy Cousins"},{"status":"ACTIVE","sortPriority":5,"id":35801684,"name":"5. Zeke The Freak"},{"status":"ACTIVE","sortPriority":6,"id":37127725,"name":"6. Exit Plan"},{"status":"ACTIVE","sortPriority":7,"id":26051221,"name":"7. Farmor Crownies"},{"status":"ACTIVE","sortPriority":8,"id":28338255,"name":"8. Until Late"}],"regulators":["MR_INT"],"venue":"Rockhampton","countryCode":"AU","discountAllowed":true,"timezone":"Australia/Queensland","openDate":"2022-03-02T08:28:00.000Z","version":4382601976,"name":"R5 407m Gr4","eventName":"Rockhampton (AUS) 2nd Mar"},"rc":[{"atb":[[16.5,6.65],[19,5.72],[11.5,9.81],[14,7.92]],"id":39784543},{"atl":[[140,0.96],[290,0.69],[190,0.7],[240,0.83]],"id":39784543},{"spn":79.5,"spf":"NaN","id":39784543},{"atb":[[9,12.88],[10,11.44],[12.5,8.95],[15,7.36]],"id":36500377},{"atl":[[150,0.89],[100,1.34],[200,1],[250,0.8]],"id":36500377},{"spn":57.5,"spf":"NaN","id":36500377},{"atb":[[16,6.86],[11,10.3],[13.5,8.24],[9.4,12.26]],"id":35801684},{"atl":[[260,0.77],[160,0.84],[210,0.95],[110,1.22]],"id":35801684},{"spn":63.0,"spf":"NaN","id":35801684},{"atb":[[18,6.06],[10.5,10.84],[13,8.58],[15.5,7.1]],"id":36074638},{"atl":[[130,1.03],[280,0.71],[180,0.74],[230,0.87]],"id":36074638},{"spn":74.0,"spf":"NaN","id":36074638},{"atb":[[2.4,73.61],[2.5,68.7],[2.3,79.27],[2.6,64.41]],"id":42189401},{"atl":[[8,28.59],[9,25.01],[5,4.92],[6,26.68],[3.25,12.01],[7,22.23]],"id":42189401},{"spn":2.92,"spf":"NaN","id":42189401},{"atb":[[2.8,57.25],[2.9,54.23],[3,51.53],[2.7,60.62]],"id":37127725},{"atl":[[12,18.19],[9.8,22.74],[8.8,17.1],[7.8,19.62],[4.7,12.01]],"id":37127725},{"spn":3.85,"spf":"NaN","id":37127725},{"atb":[[4,34.35],[4.5,29.44],[5,25.76],[5.5,22.89]],"id":28338255},{"atl":[[17,8.34],[19.5,7.21],[24,8.7],[29,7.14]],"id":28338255},{"spn":11.25,"spf":"NaN","id":28338255},{"atb":[[2.82,56.62],[2.92,53.67],[3.3,44.81],[3.05,50.27]],"id":26051221},{"atl":[[9.2,16.27],[10.5,21.07],[8.2,18.53],[13,16.68]],"id":26051221},{"spn":5.75,"spf":"NaN","id":26051221}],"con":true,"img":true}]}
{"op":"mcm","clk":"5352957472","pt":1646205640464,"mc":[{"id":"1.195453770","rc":[{"atb":[[16.5,6.64],[19,5.72],[11.5,9.81],[14,7.92]],"id":39784543},{"atl":[[140,0.96],[290,0.69],[190,0.7],[240,0.83]],"id":39784543},{"atb":[[9,12.87],[10,11.44],[12.5,8.95],[15,7.35]],"id":36500377},{"atl":[[150,0.89],[100,1.34],[200,1],[250,0.8]],"id":36500377},{"atb":[[16,6.86],[11,10.3],[13.5,8.24],[9.4,12.26]],"id":35801684},{"atl":[[260,0.77],[160,0.84],[210,0.95],[110,1.22]],"id":35801684},{"atb":[[18,6.05],[10.5,10.84],[13,8.58],[15.5,7.1]],"id":36074638},{"atl":[[130,1.03],[280,0.71],[180,0.74],[230,0.87]],"id":36074638},{"atb":[[2.4,73.59],[2.5,68.68],[2.3,79.25],[2.6,64.39]],"id":42189401},{"atl":[[8,28.58],[9,25.01],[5,4.93],[6,26.68],[3.25,12],[7,22.23]],"id":42189401},{"spn":2.92,"spf":"NaN","id":42189401},{"atb":[[2.8,57.23],[2.9,54.22],[3,51.51],[3.05,4.92],[2.7,60.6]],"id":37127725},{"atl":[[12,18.19],[9.8,22.74],[8.8,17.1],[7.8,19.61],[4.7,12]],"id":37127725},{"spn":3.87,"spf":"NaN","id":37127725},{"atb":[[4,34.34],[4.5,29.43],[5,25.75],[5.5,22.89]],"id":28338255},{"atl":[[17,8.34],[19.5,7.21],[24,8.7],[29,7.14]],"id":28338255},{"atb":[[2.82,56.61],[2.92,53.66],[3.3,44.79],[3.05,50.25]],"id":26051221},{"atl":[[9.2,16.26],[10.5,21.06],[8.2,18.52],[13,16.67]],"id":26051221}],"con":true,"img":false}]}
{"op":"mcm","clk":"5352957478","pt":1646205640565,"mc":[{"id":"1.195453770","rc":[{"atb":[[3.35,4.3]],"id":26051221}],"con":true,"img":false}]}
{"op":"mcm","clk":"5352957483","pt":1646205640770,"mc":[{"id":"1.195453770","rc":[{"atb":[[5.6,2.19]],"id":28338255}],"con":true,"img":false}]}
{"op":"mcm","clk":"5352958047","pt":1646205659245,"mc":[{"id":"1.195453770","marketDefinition":{"bspMarket":true,"turnInPlayEnabled":false,"persistenceEnabled":false,"marketBaseRate":7.0,"eventId":"31272499","eventTypeId":"4339","numberOfWinners":1,"bettingType":"ODDS","marketType":"WIN","marketTime":"2022-03-02T09:47:00.000Z","suspendTime":"2022-03-02T09:47:00.000Z","bspReconciled":false,"complete":true,"inPlay":false,"crossMatching":true,"runnersVoidable":false,"numberOfActiveRunners":8,"betDelay":0,"status":"OPEN","runners":[{"status":"ACTIVE","sortPriority":1,"id":36074638,"name":"1. Just Law"},{"status":"ACTIVE","sortPriority":2,"id":39784543,"name":"2. Surreal"},{"status":"ACTIVE","sortPriority":3,"id":36500377,"name":"3. Mystery Train"},{"status":"ACTIVE","sortPriority":4,"id":42189401,"name":"4. Daisy Cousins"},{"status":"ACTIVE","sortPriority":5,"id":35801684,"name":"5. Zeke The Freak"},{"status":"ACTIVE","sortPriority":6,"id":37127725,"name":"6. Exit Plan"},{"status":"ACTIVE","sortPriority":7,"id":26051221,"name":"7. Farmor Crownies"},{"status":"ACTIVE","sortPriority":8,"id":28338255,"name":"8. Until Late"}],"regulators":["MR_INT"],"venue":"Rockhampton","countryCode":"AU","discountAllowed":true,"timezone":"Australia/Queensland","openDate":"2022-03-02T08:28:00.000Z","version":4382601976,"name":"R5 407m Gr4","eventName":"Rockhampton (AUS) 2nd Mar"},"rc":[],"con":true,"img":false}]}
{"op":"mcm","clk":"5352958985","pt":1646205689850,"mc":[{"id":"1.195453770","rc":[{"atb":[[2.64,4.59]],"id":42189401}],"con":true,"img":false}]}
{"op":"mcm","clk":"5352958989","pt":1646205689952,"mc":[{"id":"1.195453770","rc":[{"atb":[[3.05,8.6]],"id":37127725},{"atb":[[1.01,2.25]],"id":28338255},{"atb":[[3.35,7.5]],"id":26051221}],"con":true,"img":false}]}
{"op":"mcm","clk":"5352958993","pt":1646205690055,"mc":[{"id":"1.195453770","rc":[{"atb":[[1.01,1.63]],"id":28338255}],"con":true,"img":false}]}
{"op":"mcm","clk":"5352958999","pt":1646205690218,"mc":[{"id":"1.195453770","rc":[{"atb":[[1.01,0]],"id":28338255}],"con":true,"img":false}]}
{"op":"mcm","clk":"5352959002","pt":1646205690316,"mc":[{"id":"1.195453770","rc":[{"atb":[[5.6,3.82]],"id":28338255}],"con":true,"img":false}]}
{"op":"mcm","clk":"5352985301","pt":1646206374105,"mc":[{"id":"1.195453770","rc":[{"atl":[[4.4,8.18]],"id":42189401},{"spn":2.94,"spf":"NaN","id":42189401},{"spn":11.3,"spf":"NaN","id":28338255},{"spn":5.77,"spf":"NaN","id":26051221}],"con":true,"img":false}]}
{"op":"mcm","clk":"5353031159","pt":1646207220114,"mc":[{"id":"1.195453770","rc":[{"atb":[[21,0.51]],"id":39784543},{"atb":[[16.5,0.66]],"id":36500377},{"atb":[[16.5,0.66]],"id":35801684},{"atb":[[16.5,0.66]],"id":36074638},{"atb":[[2.52,2]],"id":42189401},{"atb":[[3.05,10.6]],"id":37127725},{"atb":[[7.6,1.53]],"id":28338255},{"atb":[[3.25,2]],"id":26051221}],"con":true,"img":false}]}
{"op":"mcm","clk":"5353035340","pt":1646207312449,"mc":[{"id":"1.195453770","rc":[{"spn":80.5,"spf":"NaN","id":39784543},{"spn":58.25,"spf":"NaN","id":36500377},{"spn":63.25,"spf":"NaN","id":35801684},{"atb":[[5.6,12.38]],"id":28338255},{"spn":12.3,"spf":"NaN","id":28338255}],"con":true,"img":false}]}
{"op":"mcm","clk":"5353037306","pt":1646207354650,"mc":[{"id":"1.195453770","rc":[{"spl":[[1.01,10.91]],"id":26051221}],"con":true,"img":false}]}
{"op":"mcm","clk":"5353050903","pt":1646207723211,"mc":[{"id":"1.195453770","rc":[{"atb":[[16.5,0]],"id":36074638},{"spn":3.33,"spf":1.0,"id":26051221}],"con":true,"img":false}]}
{"op":"mcm","clk":"5353050908","pt":1646207723312,"mc":[{"id":"1.195453770","rc":[{"atb":[[16,0.68]],"id":36074638}],"con":true,"img":false}]}
{"op":"mcm","clk":"5353102030","pt":1646208868921,"mc":[{"id":"1.195453770","rc":[{"spl":[[1.01,3]],"id":39784543},{"spn":19.34,"spf":1.0,"id":39784543},{"spl":[[1.01,3]],"id":36500377},{"spn":15.33,"spf":1.0,"id":36500377},{"spl":[[1.01,3]],"id":35801684},{"spn":16.11,"spf":1.0,"id":35801684},{"spl":[[1.01,1]],"id":36074638},{"spn":18.0,"spf":1.0,"id":36074638}],"con":true,"img":false}]}
{"op":"mcm","clk":"5353112301","pt":1646209107128,"mc":[{"id":"1.195453770","rc":[{"atb":[[17,7.77],[19.5,3.16]],"id":39784543},{"atl":[[75,2.72],[100,2.72]],"id":39784543},{"spn":19.75,"spf":1.0,"id":39784543},{"atb":[[16.5,4.43],[15.5,8.56]],"id":36500377},{"atl":[[80,2.72],[60,2.72]],"id":36500377},{"spn":16.5,"spf":1.0,"id":36500377},{"atb":[[16.5,11.62]],"id":35801684},{"atl":[[80,2.72],[60,2.72]],"id":35801684},{"spn":16.5,"spf":1.0,"id":35801684},{"atb":[[16,4.58],[13.5,10.37]],"id":36074638},{"atl":[[65,2.72],[48,2.72]],"id":36074638},{"atb":[[2.02,109.97],[2.42,41.22]],"id":42189401},{"atl":[[4.3,17.74],[5.8,22.89]],"id":42189401},{"atb":[[2.92,30.49],[2.72,67.43]],"id":37127725},{"atl":[[5.5,13],[7.4,17.57]],"id":37127725},{"atb":[[3.1,61.68],[3.35,32.41]],"id":26051221},{"atl":[[8,18.55],[6.6,10.45]],"id":26051221},{"spn":3.35,"spf":1.0,"id":26051221},{"atb":[[6.4,21.98],[7.8,8.6]],"id":28338255},{"atl":[[19,3.25],[23,5.39]],"id":28338255},{"spn":12.4,"spf":"NaN","id":28338255}],"con":true,"img":false}]}
{"op":"mcm","clk":"5353112652","pt":1646209116207,"mc":[{"id":"1.195453770","rc":[{"atb":[[5.6,10.75]],"id":28338255},{"atb":[[3.35,29.21]],"id":26051221}],"con":true,"img":false}]}
{"op":"mcm","clk":"5353113070","pt":1646209125247,"mc":[{"id":"1.195453770","rc":[{"atb":[[1.01,2.25]],"id":28338255},{"atb":[[3.4,3.13]],"id":26051221}],"con":true,"img":false}]}
{"op":"mcm","clk":"5353113080","pt":1646209125454,"mc":[{"id":"1.195453770","rc":[{"atb":[[1.01,1.34]],"id":28338255}],"con":true,"img":false}]}
{"op":"mcm","clk":"5353113089","pt":1646209125659,"mc":[{"id":"1.195453770","rc":[{"atb":[[1.01,0]],"id":28338255}],"con":true,"img":false}]}
{"op":"mcm","clk":"5353113094","pt":1646209125762,"mc":[{"id":"1.195453770","rc":[{"atb":[[6.6,1.34]],"id":28338255}],"con":true,"img":false}]}
{"op":"mcm","clk":"5353113331","pt":1646209131734,"mc":[{"id":"1.195453770","rc":[{"atb":[[5.6,8.55]],"id":28338255},{"atb":[[3.35,24.91]],"id":26051221}],"con":true,"img":false}]}
{"op":"mcm","clk":"5353113840","pt":1646209143842,"mc":[{"id":"1.195453770","rc":[{"atb":[[3.4,7.35]],"id":26051221}],"con":true,"img":false}]}
{"op":"mcm","clk":"5353113857","pt":1646209144145,"mc":[{"id":"1.195453770","rc":[{"atb":[[6.6,3.15]],"id":28338255}],"con":true,"img":false}]}
{"op":"mcm","clk":"5353115985","pt":1646209195537,"mc":[{"id":"1.195453770","rc":[{"atl":[[4.9,28.76]],"id":42189401},{"spn":3.38,"spf":1.0,"id":26051221}],"con":true,"img":false}]}
{"op":"mcm","clk":"5353115988","pt":1646209195640,"mc":[{"id":"1.195453770","rc":[{"atl":[[5.8,0]],"id":42189401}],"con":true,"img":false}]}
{"op":"mcm","clk":"5353115994","pt":1646209195743,"mc":[{"id":"1.195453770","rc":[{"atl":[[4.4,0]],"id":42189401}],"con":true,"img":false}]}
{"op":"mcm","clk":"5353117369","pt":1646209224378,"mc":[{"id":"1.195453770","rc":[{"atl":[[5.8,22.89],[4.9,0]],"id":42189401}],"con":true,"img":false}]}
{"op":"mcm","clk":"5353118793","pt":1646209257725,"mc":[{"id":"1.195453770","rc":[{"atb":[[5.6,0]],"id":28338255}],"con":true,"img":false}]}
{"op":"mcm","clk":"5353127760","pt":1646209446593,"mc":[{"id":"1.195453770","rc":[{"atb":[[9.4,8.57]],"id":36074638}],"con":true,"img":false}]}
{"op":"mcm","clk":"5353127775","pt":1646209446796,"mc":[{"id":"1.195453770","rc":[{"atb":[[10,8]],"id":39784543},{"atb":[[8.6,9.47]],"id":36500377},{"atb":[[8.6,9.47]],"id":35801684},{"atb":[[1.75,96]],"id":42189401},{"atb":[[2.02,70.59]],"id":37127725}],"con":true,"img":false}]}
{"op":"mcm","clk":"5353127781","pt":1646209446897,"mc":[{"id":"1.195453770","rc":[{"atb":[[6.4,15.19]],"id":39784543},{"atb":[[5.6,17.83]],"id":36500377},{"atb":[[5.6,17.83]],"id":35801684},{"atb":[[6,16.4]],"id":36074638},{"atb":[[1.45,182.22]],"id":42189401},{"atl":[[5.3,8.2]],"id":42189401},{"atb":[[1.61,134.43]],"id":37127725},{"atl":[[8.2,8.2]],"id":37127725},{"atb":[[3,41],[4.4,21.18]],"id":28338255},{"atl":[[40,8.2]],"id":28338255},{"atb":[[1.72,113.89],[2.2,60]],"id":26051221},{"atl":[[12,8.2]],"id":26051221}],"con":true,"img":false}]}
{"op":"mcm","clk":"5353127787","pt":1646209447002,"mc":[{"id":"1.195453770","rc":[{"atb":[[4.2,26.56]],"id":39784543},{"atb":[[2.62,46.3]],"id":35801684},{"atb":[[2.62,46.3],[4.2,26.56]],"id":36074638},{"atl":[[6.8,14.2]],"id":42189401},{"atl":[[10.5,14.2]],"id":37127725},{"atl":[[15,14.2]],"id":26051221},{"atb":[[2.62,46.3]],"id":28338255},{"atl":[[55,14.2]],"id":28338255}],"con":true,"img":false}]}
{"op":"mcm","clk":"5353127800","pt":1646209447105,"mc":[{"id":"1.195453770","rc":[{"atb":[[2.62,46.3],[4.2,26.56]],"id":36500377},{"atb":[[4.2,26.56]],"id":35801684}],"con":true,"img":false}]}
{"op":"mcm","clk":"5353127813","pt":1646209447311,"mc":[{"id":"1.195453770","rc":[{"atb":[[2.62,46.3]],"id":39784543}],"con":true,"img":false}]}
{"op":"mcm","clk":"5353127821","pt":1646209447517,"mc":[{"id":"1.195453770","rc":[{"atl":[[17,8.5]],"id":42189401}],"con":true,"img":false}]}
{"op":"mcm","clk":"5353127827","pt":1646209447578,"mc":[{"id":"1.195453770","rc":[{"atl":[[34,13.5]],"id":42189401},{"atl":[[17,8.5],[34,13.5]],"id":37127725},{"atl":[[34,13.5]],"id":26051221}],"con":true,"img":false}]}
{"op":"mcm","clk":"5353132529","pt":1646209527086,"mc":[{"id":"1.195453770","rc":[{"atl":[[5.8,0]],"id":42189401}],"con":true,"img":false}]}
{"op":"mcm","clk":"5353132534","pt":1646209527187,"mc":[{"id":"1.195453770","rc":[{"atl":[[5.2,22.89]],"id":42189401}],"con":true,"img":false}]}
{"op":"mcm","clk":"5353160135","pt":1646210037962,"mc":[{"id":"1.195453770","rc":[{"atl":[[240,14.2]],"id":36500377},{"atl":[[240,14.2]],"id":35801684},{"atl":[[190,14.2]],"id":36074638}],"con":true,"img":false}]}
{"op":"mcm","clk":"5353200755","pt":1646210821555,"mc":[{"id":"1.195453770","rc":[{"atb":[[6.2,19.23]],"id":39784543},{"atl":[[150,2]],"id":39784543},{"atb":[[4.3,30.3]],"id":36500377},{"atl":[[65,2]],"id":36500377},{"atb":[[5.6,39.57]],"id":35801684},{"atl":[[230,2]],"id":35801684},{"atb":[[4.3,30.3]],"id":36074638},{"atl":[[80,2]],"id":36074638},{"atb":[[2.32,75.76]],"id":42189401},{"atl":[[7.2,16.13]],"id":42189401},{"atb":[[2.3,76.92]],"id":37127725},{"atl":[[11.5,9.52]],"id":37127725},{"atb":[[1.71,103.92]],"id":26051221},{"atl":[[11.5,9.52]],"id":26051221},{"atb":[[4.6,27.78]],"id":28338255},{"atl":[[60,2]],"id":28338255}],"con":true,"img":false}]}
{"op":"mcm","clk":"5353200944","pt":1646210825562,"mc":[{"id":"1.195453770","rc":[{"atl":[[3.25,0.46]],"id":42189401},{"trd":[[3.25,23.08]],"ltp":3.25,"tv":23.08,"id":42189401},{"atl":[[17,0]],"id":28338255},{"trd":[[17,16.68]],"ltp":17.0,"tv":16.68,"id":28338255}],"con":true,"img":false}]}
{"op":"mcm","clk":"5353200949","pt":1646210825666,"mc":[{"id":"1.195453770","rc":[{"atl":[[4.4,8.18]],"id":42189401}],"con":true,"img":false}]}
{"op":"mcm","clk":"5353201209","pt":1646210831283,"mc":[{"id":"1.195453770","rc":[{"atl":[[5.3,0]],"id":42189401}],"con":true,"img":false}]}
{"op":"mcm","clk":"5353201608","pt":1646210839769,"mc":[{"id":"1.195453770","rc":[{"atb":[[2.64,10.75]],"id":42189401}],"con":true,"img":false}]}
{"op":"mcm","clk":"5353202437","pt":1646210857018,"mc":[{"id":"1.195453770","rc":[{"atl":[[65,0]],"id":36500377}],"con":true,"img":false}]}
{"op":"mcm","clk":"5353202445","pt":1646210857117,"mc":[{"id":"1.195453770","rc":[{"atl":[[70,2]],"id":36500377}],"con":true,"img":false}]}
{"op":"mcm","clk":"5353202532","pt":1646210858714,"mc":[{"id":"1.195453770","rc":[{"atl":[[65,2],[70,0]],"id":36500377},{"atb":[[4.3,0],[5.3,23.26]],"id":36074638},{"atl":[[65,4.72],[80,0]],"id":36074638},{"atb":[[1.8,108.9],[1.71,0]],"id":26051221}],"con":true,"img":false}]}
{"op":"mcm","clk":"5353202842","pt":1646210864336,"mc":[{"id":"1.195453770","rc":[{"atl":[[80,0],[60,0]],"id":36500377},{"atl":[[4.9,28.76]],"id":42189401}],"con":true,"img":false}]}
{"op":"mcm","clk":"5353202849","pt":1646210864438,"mc":[{"id":"1.195453770","rc":[{"atl":[[55,2.72],[60,2.72]],"id":36500377},{"atl":[[5.2,0]],"id":42189401}],"con":true,"img":false}]}
{"op":"mcm","clk":"5353202856","pt":1646210864491,"mc":[{"id":"1.195453770","rc":[{"atl":[[65,0],[100,3.34]],"id":36500377}],"con":true,"img":false}]}
{"op":"mcm","clk":"5353203301","pt":1646210874438,"mc":[{"id":"1.195453770","rc":[{"atl":[[55,0],[60,0]],"id":36500377}],"con":true,"img":false}]}
{"op":"mcm","clk":"5353203305","pt":1646210874541,"mc":[{"id":"1.195453770","rc":[{"atl":[[80,2.72],[60,2.72]],"id":36500377}],"con":true,"img":false}]}
{"op":"mcm","clk":"5353203729","pt":1646210883294,"mc":[{"id":"1.195453770","rc":[{"atl":[[65,2.72],[55,2]],"id":36074638},{"atb":[[2.32,0],[2.44,69.44]],"id":42189401},{"atb":[[2.4,71.43],[2.3,0]],"id":37127725},{"spn":13.4,"spf":"NaN","id":28338255}],"con":true,"img":false}]}
{"op":"mcm","clk":"5353204520","pt":1646210901225,"mc":[{"id":"1.195453770","rc":[{"atl":[[65,2],[100,1.34]],"id":36500377}],"con":true,"img":false}]}
{"op":"mcm","clk":"5353205039","pt":1646210912481,"mc":[{"id":"1.195453770","rc":[{"atb":[[2.42,0]],"id":42189401}],"con":true,"img":false}]}
{"op":"mcm","clk":"5353205047","pt":1646210912584,"mc":[{"id":"1.195453770","rc":[{"atb":[[2.46,41.22]],"id":42189401}],"con":true,"img":false}]}
{"op":"mcm","clk":"5353205107","pt":1646210913869,"mc":[{"id":"1.195453770","rc":[{"atb":[[16.5,4.43]],"id":35801684}],"con":true,"img":false}]}
{"op":"mcm","clk":"5353205110","pt":1646210913975,"mc":[{"id":"1.195453770","rc":[{"atb":[[14,7.18]],"id":35801684}],"con":true,"img":false}]}
{"op":"mcm","clk":"5353206320","pt":1646210947323,"mc":[{"id":"1.195453770","rc":[{"atl":[[60,0]],"id":36500377},{"atl":[[65,0]],"id":36074638},{"atb":[[2.46,0]],"id":42189401}],"con":true,"img":false}]}
{"op":"mcm","clk":"5353206322","pt":1646210947425,"mc":[{"id":"1.195453770","rc":[{"atl":[[80,4.72],[55,2.72]],"id":36500377},{"atl":[[50,2.72]],"id":36074638},{"atb":[[2.52,43.22]],"id":42189401}],"con":true,"img":false}]}
{"op":"mcm","clk":"5353206326","pt":1646210947529,"mc":[{"id":"1.195453770","rc":[{"atl":[[65,0],[80,2.72],[95,2]],"id":36500377}],"con":true,"img":false}]}
{"op":"mcm","clk":"5353206333","pt":1646210947631,"mc":[{"id":"1.195453770","rc":[{"atl":[[65,2]],"id":36500377}],"con":true,"img":false}]}
{"op":"mcm","clk":"5353206338","pt":1646210947733,"mc":[{"id":"1.195453770","rc":[{"atl":[[95,0]],"id":36500377}],"con":true,"img":false}]}
{"op":"mcm","clk":"5353206342","pt":1646210947836,"mc":[{"id":"1.195453770","rc":[{"atl":[[46,1.23]],"id":36074638},{"atl":[[4.2,1.32]],"id":42189401},{"atl":[[4.6,1.23]],"id":37127725},{"atl":[[6.4,1.31]],"id":26051221},{"atl":[[18.5,1.31]],"id":28338255}],"con":true,"img":false}]}
{"op":"mcm","clk":"5353206355","pt":1646210948398,"mc":[{"id":"1.195453770","rc":[{"atl":[[50,1.28]],"id":36500377}],"con":true,"img":false}]}
{"op":"mcm","clk":"5353206667","pt":1646210958258,"mc":[{"id":"1.195453770","rc":[{"atl":[[80,0]],"id":36500377}],"con":true,"img":false}]}
{"op":"mcm","clk":"5353206674","pt":1646210958310,"mc":[{"id":"1.195453770","rc":[{"atl":[[60,2.72]],"id":36500377}],"con":true,"img":false}]}
{"op":"mcm","clk":"5353207084","pt":1646210970848,"mc":[{"id":"1.195453770","rc":[{"atb":[[2.32,84.97]],"id":42189401}],"con":true,"img":false}]}
{"op":"mcm","clk":"5353207088","pt":1646210970951,"mc":[{"id":"1.195453770","rc":[{"atb":[[2.02,0]],"id":42189401}],"con":true,"img":false}]}
{"op":"mcm","clk":"5353207288","pt":1646210976256,"mc":[{"id":"1.195453770","rc":[{"atb":[[7.2,16.13],[6.2,0]],"id":39784543},{"atb":[[4.9,25.64]],"id":36500377},{"atb":[[5.6,17.83],[6.4,18.52]],"id":35801684},{"atb":[[2.5,135.35]],"id":42189401}],"con":true,"img":false}]}
{"op":"mcm","clk":"5353207294","pt":1646210976359,"mc":[{"id":"1.195453770","rc":[{"atb":[[4.3,0]],"id":36500377},{"atb":[[2.44,0]],"id":42189401}],"con":true,"img":false}]}
{"op":"mcm","clk":"5353207690","pt":1646210987902,"mc":[{"id":"1.195453770","rc":[{"atl":[[55,0]],"id":36500377},{"atl":[[48,0]],"id":36074638},{"atl":[[5.5,0]],"id":37127725}],"con":true,"img":false}]}
{"op":"mcm","clk":"5353207692","pt":1646210987953,"mc":[{"id":"1.195453770","rc":[{"atl":[[50,4.01]],"id":36500377},{"atl":[[44,2.72]],"id":36074638},{"atl":[[5.4,13]],"id":37127725}],"con":true,"img":false}]}
{"op":"mcm","clk":"5353207769","pt":1646210990271,"mc":[{"id":"1.195453770","rc":[{"atl":[[46,0]],"id":36074638}],"con":true,"img":false}]}
{"op":"mcm","clk":"5353207775","pt":1646210990374,"mc":[{"id":"1.195453770","rc":[{"atl":[[42,1.23]],"id":36074638}],"con":true,"img":false}]}
{"op":"mcm","clk":"5353208054","pt":1646210997789,"mc":[{"id":"1.195453770","rc":[{"atl":[[5.9,22.89]],"id":42189401}],"con":true,"img":false}]}
{"op":"mcm","clk":"5353208058","pt":1646210997891,"mc":[{"id":"1.195453770","rc":[{"atl":[[44,0]],"id":36074638},{"atl":[[4.9,0]],"id":42189401}],"con":true,"img":false}]}
{"op":"mcm","clk":"5353208063","pt":1646210997995,"mc":[{"id":"1.195453770","rc":[{"atl":[[46,2.72]],"id":36074638}],"con":true,"img":false}]}
{"op":"mcm","clk":"5353208090","pt":1646210998714,"mc":[{"id":"1.195453770","rc":[{"atl":[[42,0]],"id":36074638}],"con":true,"img":false}]}
{"op":"mcm","clk":"5353208095","pt":1646210998817,"mc":[{"id":"1.195453770","rc":[{"atl":[[44,1.23]],"id":36074638}],"con":true,"img":false}]}
{"op":"mcm","clk":"5353208237","pt":1646211003108,"mc":[{"id":"1.195453770","rc":[{"atl":[[55,0],[60,2]],"id":36074638},{"atb":[[2.5,68.68],[2.38,72.46]],"id":42189401}],"con":true,"img":false}]}
{"op":"mcm","clk":"5353208401","pt":1646211007599,"mc":[{"id":"1.195453770","rc":[{"atl":[[50,0]],"id":36074638},{"spn":3.82,"spf":"NaN","id":37127725},{"spn":13.15,"spf":"NaN","id":28338255}],"con":true,"img":false}]}
{"op":"mcm","clk":"5353208404","pt":1646211007702,"mc":[{"id":"1.195453770","rc":[{"atl":[[55,2.72]],"id":36074638}],"con":true,"img":false}]}
{"op":"mcm","clk":"5353208421","pt":1646211008320,"mc":[{"id":"1.195453770","rc":[{"atl":[[44,0]],"id":36074638}],"con":true,"img":false}]}
{"op":"mcm","clk":"5353208425","pt":1646211008424,"mc":[{"id":"1.195453770","rc":[{"atl":[[1000,1.23]],"id":36074638}],"con":true,"img":false}]}
{"op":"mcm","clk":"5353209117","pt":1646211028139,"mc":[{"id":"1.195453770","rc":[{"atl":[[1000,2.25]],"id":39784543},{"atl":[[1000,2.25]],"id":36500377},{"atl":[[1000,2.25]],"id":35801684},{"atb":[[1.03,2.25]],"id":36074638},{"atb":[[1.02,2.25]],"id":28338255}],"con":true,"img":false}]}
{"op":"mcm","clk":"5353209125","pt":1646211028346,"mc":[{"id":"1.195453770","rc":[{"atl":[[1000,0.05]],"id":39784543},{"atl":[[1000,0.07]],"id":36500377},{"atl":[[1000,0.06]],"id":35801684},{"atb":[[1.03,0.2]],"id":36074638},{"atb":[[1.02,0.46]],"id":28338255}],"con":true,"img":false}]}
{"op":"mcm","clk":"5353209132","pt":1646211028553,"mc":[{"id":"1.195453770","rc":[{"atb":[[1.02,0]],"id":28338255}],"con":true,"img":false}]}
{"op":"mcm","clk":"5353209138","pt":1646211028655,"mc":[{"id":"1.195453770","rc":[{"atb":[[8,0.46]],"id":28338255}],"con":true,"img":false}]}
{"op":"mcm","clk":"5353209145","pt":1646211028861,"mc":[{"id":"1.195453770","rc":[{"atl":[[1000,0]],"id":39784543}],"con":true,"img":false}]}
{"op":"mcm","clk":"5353209149","pt":1646211028914,"mc":[{"id":"1.195453770","rc":[{"atl":[[70,0.05]],"id":39784543}],"con":true,"img":false}]}
{"op":"mcm","clk":"5353209156","pt":1646211029119,"mc":[{"id":"1.195453770","rc":[{"atl":[[1000,0]],"id":35801684}],"con":true,"img":false}]}
{"op":"mcm","clk":"5353209162","pt":1646211029222,"mc":[{"id":"1.195453770","rc":[{"atl":[[55,0.06]],"id":35801684}],"con":true,"img":false}]}
{"op":"mcm","clk":"5353209173","pt":1646211029431,"mc":[{"id":"1.195453770","rc":[{"atl":[[1000,0]],"id":36500377}],"con":true,"img":false}]}
{"op":"mcm","clk":"5353209176","pt":1646211029534,"mc":[{"id":"1.195453770","rc":[{"atl":[[48,0.07]],"id":36500377}],"con":true,"img":false}]}
{"op":"mcm","clk":"5353209184","pt":1646211029740,"mc":[{"id":"1.195453770","rc":[{"atb":[[1.03,0]],"id":36074638}],"con":true,"img":false}]}
{"op":"mcm","clk":"5353209192","pt":1646211029844,"mc":[{"id":"1.195453770","rc":[{"atb":[[18.5,0.2]],"id":36074638}],"con":true,"img":false}]}
{"op":"mcm","clk":"5353209263","pt":1646211031552,"mc":[{"id":"1.195453770","rc":[{"atl":[[50,1.28]],"id":36500377}],"con":true,"img":false}]}
{"op":"mcm","clk":"5353209268","pt":1646211031655,"mc":[{"id":"1.195453770","rc":[{"atl":[[48,2.8]],"id":36500377}],"con":true,"img":false}]}
{"op":"mcm","clk":"5353209278","pt":1646211031863,"mc":[{"id":"1.195453770","rc":[{"atb":[[1.03,2.25]],"id":36500377}],"con":true,"img":false}]}
{"op":"mcm","clk":"5353209283","pt":1646211031966,"mc":[{"id":"1.195453770","rc":[{"atb":[[1.03,0.21]],"id":36500377},{"atl":[[50,0]],"id":36500377}],"con":true,"img":false}]}
{"op":"mcm","clk":"5353209290","pt":1646211032017,"mc":[{"id":"1.195453770","rc":[{"atl":[[46,1.28]],"id":36500377}],"con":true,"img":false}]}
{"op":"mcm","clk":"5353209294","pt":1646211032121,"mc":[{"id":"1.195453770","rc":[{"atb":[[1.03,0]],"id":36500377}],"con":true,"img":false}]}
{"op":"mcm","clk":"5353209299","pt":1646211032223,"mc":[{"id":"1.195453770","rc":[{"atb":[[17,0.21]],"id":36500377}],"con":true,"img":false}]}
{"op":"mcm","clk":"5353209492","pt":1646211037330,"mc":[{"id":"1.195453770","rc":[{"atl":[[130,2]],"id":39784543},{"atl":[[60,4.72]],"id":36500377}],"con":true,"img":false}]}
{"op":"mcm","clk":"5353209495","pt":1646211037432,"mc":[{"id":"1.195453770","rc":[{"atl":[[150,0]],"id":39784543},{"atl":[[65,0]],"id":36500377},{"atl":[[48,2.13]],"id":36074638}],"con":true,"img":false}]}
{"op":"mcm","clk":"5353209497","pt":1646211037534,"mc":[{"id":"1.195453770","rc":[{"atl":[[60,0]],"id":36074638}],"con":true,"img":false}]}
{"op":"mcm","clk":"5353209516","pt":1646211037977,"mc":[{"id":"1.195453770","rc":[{"atl":[[1000,0]],"id":36074638}],"con":true,"img":false}]}
{"op":"mcm","clk":"5353209521","pt":1646211038029,"mc":[{"id":"1.195453770","rc":[{"atl":[[44,1.23]],"id":36074638}],"con":true,"img":false}]}
{"op":"mcm","clk":"5353209658","pt":1646211041958,"mc":[{"id":"1.195453770","rc":[{"atl":[[55,0]],"id":36074638}],"con":true,"img":false}]}
{"op":"mcm","clk":"5353209663","pt":1646211042062,"mc":[{"id":"1.195453770","rc":[{"atl":[[65,2.72]],"id":36074638}],"con":true,"img":false}]}
{"op":"mcm","clk":"5353209691","pt":1646211042683,"mc":[{"id":"1.195453770","rc":[{"atl":[[44,0]],"id":36074638}],"con":true,"img":false}]}
{"op":"mcm","clk":"5353209695","pt":1646211042786,"mc":[{"id":"1.195453770","rc":[{"atl":[[1000,1.23]],"id":36074638}],"con":true,"img":false}]}
{"op":"mcm","clk":"5353210056","pt":1646211052482,"mc":[{"id":"1.195453770","rc":[{"atl":[[48,0.07]],"id":36500377}],"con":true,"img":false}]}
{"op":"mcm","clk":"5353210060","pt":1646211052585,"mc":[{"id":"1.195453770","rc":[{"atl":[[55,2.72]],"id":36500377}],"con":true,"img":false}]}
{"op":"mcm","clk":"5353210080","pt":1646211052947,"mc":[{"id":"1.195453770","rc":[{"atl":[[46,0]],"id":36500377}],"con":true,"img":false}]}
{"op":"mcm","clk":"5353210087","pt":1646211053051,"mc":[{"id":"1.195453770","rc":[{"atl":[[50,1.28]],"id":36500377}],"con":true,"img":false}]}
{"op":"mcm","clk":"5353211711","pt":1646211091631,"mc":[{"id":"1.195453770","rc":[{"atl":[[55,0]],"id":36500377},{"spn":16.53,"spf":1.0,"id":36500377},{"spn":18.1,"spf":1.0,"id":36074638},{"spn":13.25,"spf":"NaN","id":28338255}],"con":true,"img":false}]}
{"op":"mcm","clk":"5353211718","pt":1646211091734,"mc":[{"id":"1.195453770","rc":[{"atl":[[48,2.8],[1000,2.25]],"id":36500377}],"con":true,"img":false}]}
{"op":"mcm","clk":"5353211722","pt":1646211091839,"mc":[{"id":"1.195453770","rc":[{"atl":[[48,2.72],[1000,0.07]],"id":36500377}],"con":true,"img":false}]}
{"op":"mcm","clk":"5353211732","pt":1646211092048,"mc":[{"id":"1.195453770","rc":[{"atl":[[1000,0]],"id":36500377}],"con":true,"img":false}]}
{"op":"mcm","clk":"5353211737","pt":1646211092147,"mc":[{"id":"1.195453770","rc":[{"atl":[[55,0.07]],"id":36500377}],"con":true,"img":false}]}
{"op":"mcm","clk":"5353211741","pt":1646211092250,"mc":[{"id":"1.195453770","rc":[{"atl":[[50,0]],"id":36500377}],"con":true,"img":false}]}
{"op":"mcm","clk":"5353211744","pt":1646211092353,"mc":[{"id":"1.195453770","rc":[{"atl":[[46,1.28]],"id":36500377}],"con":true,"img":false}]}
{"op":"mcm","clk":"5353212253","pt":1646211106745,"mc":[{"id":"1.195453770","rc":[{"atb":[[16.5,0.66]],"id":36500377}],"con":true,"img":false}]}
{"op":"mcm","clk":"5353212257","pt":1646211106846,"mc":[{"id":"1.195453770","rc":[{"atb":[[15.5,12.34]],"id":36500377}],"con":true,"img":false}]}
{"op":"mcm","clk":"5353212616","pt":1646211117881,"mc":[{"id":"1.195453770","rc":[{"atl":[[48,0]],"id":36500377}],"con":true,"img":false}]}
{"op":"mcm","clk":"5353212623","pt":1646211117984,"mc":[{"id":"1.195453770","rc":[{"atl":[[55,2.8]],"id":36500377}],"con":true,"img":false}]}
{"op":"mcm","clk":"5353212654","pt":1646211118709,"mc":[{"id":"1.195453770","rc":[{"atl":[[46,0]],"id":36500377}],"con":true,"img":false}]}
{"op":"mcm","clk":"5353212656","pt":1646211118803,"mc":[{"id":"1.195453770","rc":[{"atl":[[50,1.28]],"id":36500377}],"con":true,"img":false}]}
{"op":"mcm","clk":"5353213878","pt":1646211154245,"mc":[{"id":"1.195453770","rc":[{"atl":[[55,0.07]],"id":36500377},{"spn":15.82,"spf":1.0,"id":36500377}],"con":true,"img":false}]}
{"op":"mcm","clk":"5353213881","pt":1646211154347,"mc":[{"id":"1.195453770","rc":[{"atl":[[48,2.72]],"id":36500377}],"con":true,"img":false}]}
{"op":"mcm","clk":"5353219776","pt":1646211296673,"mc":[{"id":"1.195453770","rc":[{"atb":[[15.5,8.56]],"id":36500377},{"atl":[[5.4,0]],"id":37127725}],"con":true,"img":false}]}
{"op":"mcm","clk":"5353219781","pt":1646211296777,"mc":[{"id":"1.195453770","rc":[{"atb":[[16,3.77]],"id":36500377},{"atl":[[5.3,13]],"id":37127725}],"con":true,"img":false}]}
{"op":"mcm","clk":"5353221129","pt":1646211328255,"mc":[{"id":"1.195453770","rc":[{"atb":[[14,0]],"id":35801684}],"con":true,"img":false}]}
{"op":"mcm","clk":"5353221136","pt":1646211328316,"mc":[{"id":"1.195453770","rc":[{"atb":[[16.5,11.62]],"id":35801684}],"con":true,"img":false}]}
{"op":"mcm","clk":"5353222227","pt":1646211353064,"mc":[{"id":"1.195453770","rc":[{"atl":[[50,0]],"id":36500377}],"con":true,"img":false}]}
{"op":"mcm","clk":"5353222232","pt":1646211353162,"mc":[{"id":"1.195453770","rc":[{"atl":[[46,1.28]],"id":36500377}],"con":true,"img":false}]}
{"op":"mcm","clk":"5353223436","pt":1646211379035,"mc":[{"id":"1.195453770","rc":[{"atl":[[48,0]],"id":36500377},{"spn":16.18,"spf":1.0,"id":36500377}],"con":true,"img":false}]}
{"op":"mcm","clk":"5353223441","pt":1646211379139,"mc":[{"id":"1.195453770","rc":[{"atl":[[55,2.8]],"id":36500377}],"con":true,"img":false}]}
{"op":"mcm","clk":"5353223454","pt":1646211379403,"mc":[{"id":"1.195453770","rc":[{"atl":[[46,0]],"id":36500377}],"con":true,"img":false}]}
{"op":"mcm","clk":"5353223462","pt":1646211379507,"mc":[{"id":"1.195453770","rc":[{"atl":[[50,1.28]],"id":36500377}],"con":true,"img":false}]}
{"op":"mcm","clk":"5353224186","pt":1646211395231,"mc":[{"id":"1.195453770","rc":[{"atl":[[55,4.8],[60,2.72]],"id":36500377},{"atb":[[6.4,0],[5.3,23.26]],"id":35801684},{"atb":[[2.38,0],[2.46,68.49]],"id":42189401},{"atl":[[7.2,0],[6,46.68]],"id":42189401},{"atb":[[5.4,22.73],[4.6,0]],"id":28338255},{"atl":[[11.5,0],[9.4,11.9]],"id":26051221}],"con":true,"img":false}]}
{"op":"mcm","clk":"5353224281","pt":1646211397453,"mc":[{"id":"1.195453770","rc":[{"atl":[[60,0]],"id":36500377}],"con":true,"img":false}]}
{"op":"mcm","clk":"5353224288","pt":1646211397557,"mc":[{"id":"1.195453770","rc":[{"atl":[[75,2.72]],"id":36500377}],"con":true,"img":false}]}
{"op":"mcm","clk":"5353224311","pt":1646211398067,"mc":[{"id":"1.195453770","rc":[{"atl":[[50,0]],"id":36500377}],"con":true,"img":false}]}
{"op":"mcm","clk":"5353224315","pt":1646211398170,"mc":[{"id":"1.195453770","rc":[{"atl":[[1000,1.28]],"id":36500377}],"con":true,"img":false}]}
{"op":"mcm","clk":"5353225609","pt":1646211426586,"mc":[{"id":"1.195453770","rc":[{"atb":[[5.3,0],[6.8,17.24]],"id":35801684}],"con":true,"img":false}]}
{"op":"mcm","clk":"5353226110","pt":1646211436331,"mc":[{"id":"1.195453770","rc":[{"atl":[[5.9,0]],"id":42189401}],"con":true,"img":false}]}
{"op":"mcm","clk":"5353226886","pt":1646211454339,"mc":[{"id":"1.195453770","rc":[{"atb":[[16.5,4.43]],"id":35801684}],"con":true,"img":false}]}
{"op":"mcm","clk":"5353226892","pt":1646211454455,"mc":[{"id":"1.195453770","rc":[{"atb":[[14,7.18]],"id":35801684}],"con":true,"img":false}]}
{"op":"mcm","clk":"5353227540","pt":1646211468364,"mc":[{"id":"1.195453770","rc":[{"atl":[[4.9,28.76]],"id":42189401}],"con":true,"img":false}]}
{"op":"mcm","clk":"5353227988","pt":1646211478378,"mc":[{"id":"1.195453770","rc":[{"atl":[[55,2.07]],"id":36500377}],"con":true,"img":false}]}
{"op":"mcm","clk":"5353227993","pt":1646211478483,"mc":[{"id":"1.195453770","rc":[{"atl":[[75,4.72],[50,2.72],[55,0.07]],"id":36500377}],"con":true,"img":false}]}
{"op":"mcm","clk":"5353228545","pt":1646211489403,"mc":[{"id":"1.195453770","rc":[{"atl":[[50,0]],"id":36500377},{"atl":[[4.9,0]],"id":42189401}],"con":true,"img":false}]}
{"op":"mcm","clk":"5353228550","pt":1646211489504,"mc":[{"id":"1.195453770","rc":[{"atl":[[55,2.8]],"id":36500377}],"con":true,"img":false}]}
{"op":"mcm","clk":"5353229497","pt":1646211509062,"mc":[{"id":"1.195453770","rc":[{"atl":[[55,4.8]],"id":36500377}],"con":true,"img":false}]}
{"op":"mcm","clk":"5353229499","pt":1646211509116,"mc":[{"id":"1.195453770","rc":[{"atl":[[75,2.72]],"id":36500377}],"con":true,"img":false}]}
{"op":"mcm","clk":"5353229780","pt":1646211515239,"mc":[{"id":"1.195453770","rc":[{"atl":[[55,2.8],[60,2]],"id":36500377}],"con":true,"img":false}]}
{"op":"mcm","clk":"5353229809","pt":1646211515746,"mc":[{"id":"1.195453770","rc":[{"atl":[[1000,0]],"id":36500377}],"con":true,"img":false}]}
{"op":"mcm","clk":"5353229816","pt":1646211515850,"mc":[{"id":"1.195453770","rc":[{"atl":[[50,1.28]],"id":36500377}],"con":true,"img":false}]}
{"op":"mcm","clk":"5353230155","pt":1646211522346,"mc":[{"id":"1.195453770","rc":[{"atl":[[4.9,28.76]],"id":42189401}],"con":true,"img":false}]}
{"op":"mcm","clk":"5353231198","pt":1646211542288,"mc":[{"id":"1.195453770","rc":[{"atb":[[1.04,1.67]],"id":42189401},{"atb":[[1.04,1.67]],"id":37127725},{"atb":[[1.04,1.67]],"id":26051221}],"con":true,"img":false}]}
{"op":"mcm","clk":"5353231204","pt":1646211542391,"mc":[{"id":"1.195453770","rc":[{"atb":[[1.04,1.66]],"id":42189401},{"atb":[[1.04,1.66]],"id":37127725},{"atb":[[1.04,1.66]],"id":26051221}],"con":true,"img":false}]}
{"op":"mcm","clk":"5353231213","pt":1646211542496,"mc":[{"id":"1.195453770","rc":[{"atb":[[1.04,0]],"id":42189401},{"atb":[[1.04,0]],"id":37127725},{"atb":[[1.04,0]],"id":26051221}],"con":true,"img":false}]}
{"op":"mcm","clk":"5353231219","pt":1646211542597,"mc":[{"id":"1.195453770","rc":[{"atb":[[2.7,1.66]],"id":42189401},{"atb":[[3.2,1.66]],"id":37127725},{"atb":[[3.5,1.66]],"id":26051221}],"con":true,"img":false}]}
{"op":"mcm","clk":"5353231891","pt":1646211553896,"mc":[{"id":"1.195453770","rc":[{"atl":[[55,0.07]],"id":36500377}],"con":true,"img":false}]}
{"op":"mcm","clk":"5353231899","pt":1646211554000,"mc":[{"id":"1.195453770","rc":[{"atl":[[48,2.72]],"id":36500377}],"con":true,"img":false}]}
{"op":"mcm","clk":"5353231910","pt":1646211554207,"mc":[{"id":"1.195453770","rc":[{"atl":[[50,0]],"id":36500377}],"con":true,"img":false}]}
{"op":"mcm","clk":"5353231916","pt":1646211554309,"mc":[{"id":"1.195453770","rc":[{"atl":[[46,1.28]],"id":36500377}],"con":true,"img":false}]}
{"op":"mcm","clk":"5353232345","pt":1646211562712,"mc":[{"id":"1.195453770","rc":[{"atl":[[4.9,0],[5.9,22.89]],"id":42189401}],"con":true,"img":false}]}
{"op":"mcm","clk":"5353232778","pt":1646211570812,"mc":[{"id":"1.195453770","rc":[{"atl":[[75,0]],"id":36500377}],"con":true,"img":false}]}
{"op":"mcm","clk":"5353232784","pt":1646211570909,"mc":[{"id":"1.195453770","rc":[{"atl":[[55,2.8]],"id":36500377}],"con":true,"img":false}]}
{"op":"mcm","clk":"5353233589","pt":1646211587340,"mc":[{"id":"1.195453770","rc":[{"atl":[[48,0]],"id":36500377},{"spn":2.97,"spf":"NaN","id":42189401},{"spn":3.9,"spf":"NaN","id":37127725},{"spn":3.4,"spf":1.0,"id":26051221}],"con":true,"img":false}]}
{"op":"mcm","clk":"5353233592","pt":1646211587440,"mc":[{"id":"1.195453770","rc":[{"atl":[[55,5.53]],"id":36500377}],"con":true,"img":false}]}
{"op":"mcm","clk":"5353233613","pt":1646211588055,"mc":[{"id":"1.195453770","rc":[{"atl":[[46,0]],"id":36500377}],"con":true,"img":false}]}
{"op":"mcm","clk":"5353233617","pt":1646211588157,"mc":[{"id":"1.195453770","rc":[{"atl":[[50,1.28]],"id":36500377}],"con":true,"img":false}]}
{"op":"mcm","clk":"5353235701","pt":1646211619331,"mc":[{"id":"1.195453770","rc":[{"atb":[[16.5,6.63],[17,7.76],[19.5,3.16],[19,5.71],[11.5,9.79],[14,7.91]],"id":39784543},{"atl":[[140,0.95],[75,2.72],[290,0.69],[190,0.7],[100,2.72],[240,0.83]],"id":39784543},{"atb":[[9,12.85],[10,11.42],[12.5,8.94],[15,7.34],[15.5,8.55],[16,3.77],[17,0.21]],"id":36500377},{"atl":[[150,0.89],[50,1.28],[100,1.34],[200,1],[55,2.8],[250,0.8]],"id":36500377},{"atb":[[16.5,4.43],[16,6.85],[11,10.28],[13.5,8.22],[14,7.17],[9.4,12.24]],"id":35801684},{"atl":[[260,0.77],[80,2.72],[160,0.83],[210,0.95],[110,1.22],[60,2.72]],"id":35801684},{"atb":[[16,4.57],[18.5,0.2],[18,6.04],[10.5,10.82],[13,8.57],[13.5,10.35],[15.5,7.09]],"id":36074638},{"atl":[[65,2.72],[130,1.03],[280,0.71],[180,0.74],[46,2.72],[230,0.87],[1000,1.23]],"id":36074638},{"atb":[[2.4,73.47],[2.5,68.57],[2.32,84.84],[2.3,79.12],[2.52,43.16],[2.64,10.73],[2.6,64.29],[2.7,1.65]],"id":42189401},{"atl":[[8,28.54],[4.3,17.71],[9,24.97],[3.25,0.46],[4.4,8.17],[5.9,22.85],[5,4.93],[6,46.63],[7,22.19],[4.2,1.32]],"id":42189401},{"trd":[[3.25,23.05]],"ltp":3.25,"tv":23.05,"id":42189401},{"atb":[[2.8,57.14],[2.92,30.44],[2.72,67.33],[3.2,1.65],[2.9,54.13],[3,51.43],[3.05,10.58],[2.7,60.51]],"id":37127725},{"atl":[[5.3,12.98],[7.4,17.54],[12,18.16],[7.8,19.58],[4.6,1.23],[9.8,22.7],[8.8,17.07],[4.7,11.98]],"id":37127725},{"atb":[[2.82,56.52],[2.92,53.57],[3.1,61.58],[3.35,24.87],[3.4,7.34],[3.5,1.65],[3.3,44.72],[3.05,50.17]],"id":26051221},{"spl":[[1.01,10.89]],"id":26051221},{"atl":[[8,18.52],[6.4,1.3],[9.2,16.24],[10.5,21.03],[8.2,18.49],[13,16.64],[6.6,10.43]],"id":26051221},{"atb":[[8,0.46],[6.4,21.95],[7.8,8.59],[4,34.29],[4.5,29.39],[5,25.71],[5.5,22.85],[6.6,3.15]],"id":28338255},{"atl":[[18.5,1.31],[19,3.24],[19.5,7.19],[23,5.38],[24,8.68],[29,7.13]],"id":28338255},{"trd":[[17,16.65]],"ltp":17.0,"tv":16.65,"id":28338255}],"con":true,"img":false}]}
{"op":"mcm","clk":"5353235705","pt":1646211619434,"mc":[{"id":"1.195453770","rc":[{"atl":[[48,2.72]],"id":36500377}],"con":true,"img":false}]}
{"op":"mcm","clk":"5353235748","pt":1646211620416,"mc":[{"id":"1.195453770","rc":[{"atb":[[20,1.6]],"id":39784543},{"atb":[[16.5,2.32]],"id":36500377},{"atb":[[17,1.6]],"id":35801684},{"atb":[[18.5,1.82]],"id":36074638},{"atb":[[2.66,1.56]],"id":42189401},{"atb":[[3.1,1.65]],"id":37127725},{"atb":[[3.45,1.55]],"id":26051221},{"atb":[[8,2.15]],"id":28338255}],"con":true,"img":false}]}
{"op":"mcm","clk":"5353238515","pt":1646211667503,"mc":[{"id":"1.195453770","rc":[{"spn":20.02,"spf":1.0,"id":39784543},{"spn":16.46,"spf":1.0,"id":36500377},{"atb":[[14,0]],"id":35801684},{"spn":16.76,"spf":1.0,"id":35801684},{"spn":18.5,"spf":1.0,"id":36074638},{"spn":3.42,"spf":1.0,"id":26051221}],"con":true,"img":false}]}
{"op":"mcm","clk":"5353238520","pt":1646211667605,"mc":[{"id":"1.195453770","rc":[{"atb":[[16.5,11.6]],"id":35801684}],"con":true,"img":false}]}
{"op":"mcm","clk":"5353239212","pt":1646211678932,"mc":[{"id":"1.195453770","rc":[{"atb":[[16.5,4.43]],"id":35801684}],"con":true,"img":false}]}
{"op":"mcm","clk":"5353239215","pt":1646211679032,"mc":[{"id":"1.195453770","rc":[{"atb":[[14,7.17]],"id":35801684}],"con":true,"img":false}]}
{"op":"mcm","clk":"5353239251","pt":1646211679805,"mc":[{"id":"1.195453770","rc":[{"atl":[[50,0]],"id":36500377}],"con":true,"img":false}]}
{"op":"mcm","clk":"5353239258","pt":1646211679908,"mc":[{"id":"1.195453770","rc":[{"atl":[[46,1.28]],"id":36500377}],"con":true,"img":false}]}
{"op":"mcm","clk":"5353240754","pt":1646211706154,"mc":[{"id":"1.195453770","rc":[{"atl":[[48,0]],"id":36500377}],"con":true,"img":false}]}
{"op":"mcm","clk":"5353240765","pt":1646211706256,"mc":[{"id":"1.195453770","rc":[{"atl":[[55,5.52]],"id":36500377}],"con":true,"img":false}]}
{"op":"mcm","clk":"5353240825","pt":1646211707084,"mc":[{"id":"1.195453770","rc":[{"atl":[[46,0]],"id":36500377}],"con":true,"img":false}]}
{"op":"mcm","clk":"5353240829","pt":1646211707184,"mc":[{"id":"1.195453770","rc":[{"atl":[[50,1.28]],"id":36500377}],"con":true,"img":false}]}
{"op":"mcm","clk":"5353242674","pt":1646211736903,"mc":[{"id":"1.195453770","rc":[{"atl":[[55,2.8]],"id":36500377}],"con":true,"img":false}]}
{"op":"mcm","clk":"5353242678","pt":1646211737004,"mc":[{"id":"1.195453770","rc":[{"atl":[[48,2.72]],"id":36500377}],"con":true,"img":false}]}
{"op":"mcm","clk":"5353249737","pt":1646211857853,"mc":[{"id":"1.195453770","rc":[{"atl":[[50,0]],"id":36500377}],"con":true,"img":false}]}
{"op":"mcm","clk":"5353249741","pt":1646211857907,"mc":[{"id":"1.195453770","rc":[{"atl":[[46,1.28]],"id":36500377}],"con":true,"img":false}]}
{"op":"mcm","clk":"5353250376","pt":1646211869950,"mc":[{"id":"1.195453770","rc":[{"atl":[[48,0]],"id":36500377}],"con":true,"img":false}]}
{"op":"mcm","clk":"5353250381","pt":1646211870053,"mc":[{"id":"1.195453770","rc":[{"atl":[[55,5.52]],"id":36500377}],"con":true,"img":false}]}
{"op":"mcm","clk":"5353250397","pt":1646211870360,"mc":[{"id":"1.195453770","rc":[{"atl":[[46,0]],"id":36500377}],"con":true,"img":false}]}
{"op":"mcm","clk":"5353250400","pt":1646211870464,"mc":[{"id":"1.195453770","rc":[{"atl":[[50,1.28]],"id":36500377}],"con":true,"img":false}]}
{"op":"mcm","clk":"5353252432","pt":1646211906636,"mc":[{"id":"1.195453770","rc":[{"atl":[[55,2.8]],"id":36500377},{"atb":[[14,0]],"id":35801684}],"con":true,"img":false}]}
{"op":"mcm","clk":"5353252438","pt":1646211906689,"mc":[{"id":"1.195453770","rc":[{"atl":[[48,2.72]],"id":36500377},{"atb":[[16.5,11.6]],"id":35801684}],"con":true,"img":false}]}
{"op":"mcm","clk":"5353252473","pt":1646211907101,"mc":[{"id":"1.195453770","rc":[{"atl":[[50,0]],"id":36500377}],"con":true,"img":false}]}
{"op":"mcm","clk":"5353252480","pt":1646211907202,"mc":[{"id":"1.195453770","rc":[{"atl":[[46,1.28]],"id":36500377}],"con":true,"img":false}]}
{"op":"mcm","clk":"5353253179","pt":1646211919213,"mc":[{"id":"1.195453770","rc":[{"atb":[[1.89,111.4]],"id":26051221}],"con":true,"img":false}]}
{"op":"mcm","clk":"5353253183","pt":1646211919318,"mc":[{"id":"1.195453770","rc":[{"atb":[[16.5,4.43]],"id":35801684},{"atb":[[1.8,0]],"id":26051221}],"con":true,"img":false}]}
{"op":"mcm","clk":"5353253187","pt":1646211919420,"mc":[{"id":"1.195453770","rc":[{"atb":[[14,7.17]],"id":35801684}],"con":true,"img":false}]}
{"op":"mcm","clk":"5353254053","pt":1646211933269,"mc":[{"id":"1.195453770","rc":[{"atl":[[48,0]],"id":36500377}],"con":true,"img":false}]}
{"op":"mcm","clk":"5353254058","pt":1646211933370,"mc":[{"id":"1.195453770","rc":[{"atl":[[55,5.52]],"id":36500377}],"con":true,"img":false}]}
{"op":"mcm","clk":"5353254083","pt":1646211933730,"mc":[{"id":"1.195453770","rc":[{"atl":[[46,0]],"id":36500377}],"con":true,"img":false}]}
{"op":"mcm","clk":"5353254091","pt":1646211933833,"mc":[{"id":"1.195453770","rc":[{"atl":[[50,1.28]],"id":36500377}],"con":true,"img":false}]}
{"op":"mcm","clk":"5353255811","pt":1646211961682,"mc":[{"id":"1.195453770","rc":[{"atl":[[55,2.8]],"id":36500377}],"con":true,"img":false}]}
{"op":"mcm","clk":"5353255815","pt":1646211961786,"mc":[{"id":"1.195453770","rc":[{"atl":[[48,2.72]],"id":36500377}],"con":true,"img":false}]}
{"op":"mcm","clk":"5353258856","pt":1646212010192,"mc":[{"id":"1.195453770","rc":[{"atl":[[230,0],[120,2]],"id":35801684}],"con":true,"img":false}]}
{"op":"mcm","clk":"5353258895","pt":1646212010812,"mc":[{"id":"1.195453770","rc":[{"atl":[[50,0]],"id":36500377}],"con":true,"img":false}]}
{"op":"mcm","clk":"5353258897","pt":1646212010913,"mc":[{"id":"1.195453770","rc":[{"atl":[[46,1.28]],"id":36500377}],"con":true,"img":false}]}
{"op":"mcm","clk":"5353259567","pt":1646212021636,"mc":[{"id":"1.195453770","rc":[{"atb":[[14,0]],"id":35801684}],"con":true,"img":false}]}
{"op":"mcm","clk":"5353259574","pt":1646212021740,"mc":[{"id":"1.195453770","rc":[{"atb":[[16.5,11.6]],"id":35801684}],"con":true,"img":false}]}
{"op":"mcm","clk":"5353260667","pt":1646212040377,"mc":[{"id":"1.195453770","rc":[{"atl":[[48,0]],"id":36500377}],"con":true,"img":false}]}
{"op":"mcm","clk":"5353260670","pt":1646212040478,"mc":[{"id":"1.195453770","rc":[{"atl":[[55,5.52]],"id":36500377}],"con":true,"img":false}]}
{"op":"mcm","clk":"5353260705","pt":1646212040947,"mc":[{"id":"1.195453770","rc":[{"atl":[[46,0]],"id":36500377}],"con":true,"img":false}]}
{"op":"mcm","clk":"5353260711","pt":1646212041046,"mc":[{"id":"1.195453770","rc":[{"atl":[[50,1.28]],"id":36500377}],"con":true,"img":false}]}
{"op":"mcm","clk":"5353262692","pt":1646212073204,"mc":[{"id":"1.195453770","rc":[{"atl":[[55,2.8]],"id":36500377}],"con":true,"img":false}]}
{"op":"mcm","clk":"5353262699","pt":1646212073306,"mc":[{"id":"1.195453770","rc":[{"atl":[[48,2.72]],"id":36500377}],"con":true,"img":false}]}
{"op":"mcm","clk":"5353267564","pt":1646212154764,"mc":[{"id":"1.195453770","rc":[{"atb":[[8.4,13.51]],"id":39784543},{"atl":[[110,2]],"id":39784543},{"atl":[[100,2]],"id":35801684},{"atb":[[5.3,0],[4,33.33]],"id":36074638},{"atl":[[48,0],[50,2.04]],"id":36074638},{"atb":[[3.05,8.58]],"id":37127725}],"con":true,"img":false}]}
{"op":"mcm","clk":"5353267572","pt":1646212154866,"mc":[{"id":"1.195453770","rc":[{"atb":[[7.2,0]],"id":39784543},{"atl":[[130,0]],"id":39784543}],"con":true,"img":false}]}
{"op":"mcm","clk":"5353267576","pt":1646212154964,"mc":[{"id":"1.195453770","rc":[{"atl":[[120,0]],"id":35801684},{"atb":[[2.92,32.44]],"id":37127725}],"con":true,"img":false}]}
{"op":"mcm","clk":"5353267871","pt":1646212159962,"mc":[{"id":"1.195453770","rc":[{"atl":[[50,0],[55,2]],"id":36074638}],"con":true,"img":false}]}
{"op":"mcm","clk":"5353268023","pt":1646212163156,"mc":[{"id":"1.195453770","rc":[{"atl":[[46,0]],"id":36074638}],"con":true,"img":false}]}
{"op":"mcm","clk":"5353268028","pt":1646212163259,"mc":[{"id":"1.195453770","rc":[{"atl":[[65,4.72],[48,2.72]],"id":36074638}],"con":true,"img":false}]}
{"op":"mcm","clk":"5353268035","pt":1646212163363,"mc":[{"id":"1.195453770","rc":[{"atl":[[65,2.72],[55,0],[120,2]],"id":36074638}],"con":true,"img":false}]}
{"op":"mcm","clk":"5353268540","pt":1646212173099,"mc":[{"id":"1.195453770","rc":[{"atl":[[55,4.8],[60,0]],"id":36500377}],"con":true,"img":false}]}
{"op":"mcm","clk":"5353268575","pt":1646212173816,"mc":[{"id":"1.195453770","rc":[{"atl":[[50,0]],"id":36500377}],"con":true,"img":false}]}
{"op":"mcm","clk":"5353268580","pt":1646212173920,"mc":[{"id":"1.195453770","rc":[{"atl":[[46,1.28]],"id":36500377}],"con":true,"img":false}]}
{"op":"mcm","clk":"5353268882","pt":1646212178609,"mc":[{"id":"1.195453770","rc":[{"atb":[[5.3,23.26],[4,0]],"id":36074638},{"atl":[[48,4.85],[120,0]],"id":36074638}],"con":true,"img":false}]}
{"op":"mcm","clk":"5353270856","pt":1646212214068,"mc":[{"id":"1.195453770","rc":[{"atl":[[48,0]],"id":36500377}],"con":true,"img":false}]}
{"op":"mcm","clk":"5353270862","pt":1646212214168,"mc":[{"id":"1.195453770","rc":[{"atl":[[50,2.72]],"id":36500377}],"con":true,"img":false}]}
{"op":"mcm","clk":"5353270898","pt":1646212214685,"mc":[{"id":"1.195453770","rc":[{"atl":[[46,0]],"id":36500377}],"con":true,"img":false}]}
{"op":"mcm","clk":"5353270907","pt":1646212214821,"mc":[{"id":"1.195453770","rc":[{"atl":[[48,1.28]],"id":36500377}],"con":true,"img":false}]}
{"op":"mcm","clk":"5353271732","pt":1646212231107,"mc":[{"id":"1.195453770","rc":[{"atl":[[4.9,28.71],[5.9,0]],"id":42189401}],"con":true,"img":false}]}
{"op":"mcm","clk":"5353275245","pt":1646212293096,"mc":[{"id":"1.195453770","rc":[{"atl":[[55,2.8],[60,2]],"id":36500377}],"con":true,"img":false}]}
{"op":"mcm","clk":"5353275276","pt":1646212293715,"mc":[{"id":"1.195453770","rc":[{"atl":[[50,0]],"id":36500377},{"atl":[[4.9,0],[5.9,22.85]],"id":42189401}],"con":true,"img":false}]}
{"op":"mcm","clk":"5353275283","pt":1646212293818,"mc":[{"id":"1.195453770","rc":[{"atl":[[55,5.52]],"id":36500377}],"con":true,"img":false}]}
{"op":"mcm","clk":"5353275293","pt":1646212293924,"mc":[{"id":"1.195453770","rc":[{"atl":[[48,0]],"id":36500377}],"con":true,"img":false}]}
{"op":"mcm","clk":"5353275304","pt":1646212294028,"mc":[{"id":"1.195453770","rc":[{"atl":[[50,1.28]],"id":36500377}],"con":true,"img":false}]}
{"op":"mcm","clk":"5353277322","pt":1646212327784,"mc":[{"id":"1.195453770","rc":[{"atl":[[55,2.8]],"id":36500377}],"con":true,"img":false}]}
{"op":"mcm","clk":"5353277326","pt":1646212327886,"mc":[{"id":"1.195453770","rc":[{"atl":[[48,2.72]],"id":36500377}],"con":true,"img":false}]}
{"op":"mcm","clk":"5353277349","pt":1646212328296,"mc":[{"id":"1.195453770","rc":[{"atl":[[50,0]],"id":36500377}],"con":true,"img":false}]}
{"op":"mcm","clk":"5353277356","pt":1646212328350,"mc":[{"id":"1.195453770","rc":[{"atl":[[46,1.28]],"id":36500377}],"con":true,"img":false}]}
{"op":"mcm","clk":"5353277479","pt":1646212330866,"mc":[{"id":"1.195453770","rc":[{"atb":[[2.92,30.44]],"id":37127725}],"con":true,"img":false}]}
{"op":"mcm","clk":"5353277485","pt":1646212330970,"mc":[{"id":"1.195453770","rc":[{"atb":[[2.96,2]],"id":37127725}],"con":true,"img":false}]}
{"op":"mcm","clk":"5353277953","pt":1646212339516,"mc":[{"id":"1.195453770","rc":[{"atb":[[16.5,4.43]],"id":35801684},{"atl":[[5.3,0]],"id":37127725}],"con":true,"img":false}]}
{"op":"mcm","clk":"5353277957","pt":1646212339568,"mc":[{"id":"1.195453770","rc":[{"atb":[[14,7.17]],"id":35801684},{"atl":[[5.5,12.98]],"id":37127725}],"con":true,"img":false}]}
{"op":"mcm","clk":"5353279128","pt":1646212357709,"mc":[{"id":"1.195453770","rc":[{"atl":[[48,0]],"id":36500377}],"con":true,"img":false}]}
{"op":"mcm","clk":"5353279134","pt":1646212357811,"mc":[{"id":"1.195453770","rc":[{"atl":[[50,2.72]],"id":36500377}],"con":true,"img":false}]}
{"op":"mcm","clk":"5353279183","pt":1646212358736,"mc":[{"id":"1.195453770","rc":[{"atl":[[46,0]],"id":36500377}],"con":true,"img":false}]}
{"op":"mcm","clk":"5353279190","pt":1646212358839,"mc":[{"id":"1.195453770","rc":[{"atl":[[48,1.28]],"id":36500377}],"con":true,"img":false}]}
{"op":"mcm","clk":"5353279996","pt":1646212371962,"mc":[{"id":"1.195453770","rc":[{"atl":[[48,2.13]],"id":36074638},{"atl":[[5.5,0]],"id":37127725}],"con":true,"img":false}]}
{"op":"mcm","clk":"5353280003","pt":1646212372058,"mc":[{"id":"1.195453770","rc":[{"atl":[[46,2.72]],"id":36074638},{"atl":[[5.4,12.98]],"id":37127725}],"con":true,"img":false}]}
{"op":"mcm","clk":"5353280008","pt":1646212372159,"mc":[{"id":"1.195453770","rc":[{"atl":[[65,4.72],[48,0]],"id":36074638}],"con":true,"img":false}]}
{"op":"mcm","clk":"5353280016","pt":1646212372263,"mc":[{"id":"1.195453770","rc":[{"atl":[[65,2.72],[48,2.13]],"id":36074638}],"con":true,"img":false}]}
{"op":"mcm","clk":"5353281035","pt":1646212389568,"mc":[{"id":"1.195453770","rc":[{"atl":[[50,0]],"id":36500377}],"con":true,"img":false}]}
{"op":"mcm","clk":"5353281041","pt":1646212389671,"mc":[{"id":"1.195453770","rc":[{"atl":[[55,5.52]],"id":36500377}],"con":true,"img":false}]}
{"op":"mcm","clk":"5353281065","pt":1646212390084,"mc":[{"id":"1.195453770","rc":[{"atl":[[48,0]],"id":36500377}],"con":true,"img":false}]}
{"op":"mcm","clk":"5353281071","pt":1646212390187,"mc":[{"id":"1.195453770","rc":[{"atl":[[50,1.28]],"id":36500377}],"con":true,"img":false}]}
{"op":"mcm","clk":"5353282712","pt":1646212417736,"mc":[{"id":"1.195453770","rc":[{"atl":[[55,2.8]],"id":36500377},{"atl":[[5.4,0]],"id":37127725}],"con":true,"img":false}]}
{"op":"mcm","clk":"5353282718","pt":1646212417791,"mc":[{"id":"1.195453770","rc":[{"atl":[[48,2.72]],"id":36500377},{"atl":[[5.3,12.98]],"id":37127725}],"con":true,"img":false}]}
{"op":"mcm","clk":"5353282743","pt":1646212418205,"mc":[{"id":"1.195453770","rc":[{"atl":[[50,0]],"id":36500377}],"con":true,"img":false}]}
{"op":"mcm","clk":"5353282747","pt":1646212418305,"mc":[{"id":"1.195453770","rc":[{"atl":[[46,1.28]],"id":36500377}],"con":true,"img":false}]}
{"op":"mcm","clk":"5353284199","pt":1646212443044,"mc":[{"id":"1.195453770","rc":[{"atl":[[48,0]],"id":36500377}],"con":true,"img":false}]}
{"op":"mcm","clk":"5353284209","pt":1646212443149,"mc":[{"id":"1.195453770","rc":[{"atl":[[55,5.52]],"id":36500377}],"con":true,"img":false}]}
{"op":"mcm","clk":"5353284230","pt":1646212443559,"mc":[{"id":"1.195453770","rc":[{"atl":[[46,0]],"id":36500377}],"con":true,"img":false}]}
{"op":"mcm","clk":"5353284239","pt":1646212443665,"mc":[{"id":"1.195453770","rc":[{"atl":[[50,1.28]],"id":36500377}],"con":true,"img":false}]}
{"op":"mcm","clk":"5353284877","pt":1646212453387,"mc":[{"id":"1.195453770","rc":[{"atb":[[14,0]],"id":35801684}],"con":true,"img":false}]}
{"op":"mcm","clk":"5353284885","pt":1646212453491,"mc":[{"id":"1.195453770","rc":[{"atb":[[16.5,11.6]],"id":35801684}],"con":true,"img":false}]}
{"op":"mcm","clk":"5353286173","pt":1646212475921,"mc":[{"id":"1.195453770","rc":[{"atl":[[55,2.8]],"id":36500377}],"con":true,"img":false}]}
{"op":"mcm","clk":"5353286176","pt":1646212476021,"mc":[{"id":"1.195453770","rc":[{"atl":[[48,2.72]],"id":36500377}],"con":true,"img":false}]}
{"op":"mcm","clk":"5353288635","pt":1646212519368,"mc":[{"id":"1.195453770","rc":[{"atb":[[16.5,4.43]],"id":35801684}],"con":true,"img":false}]}
{"op":"mcm","clk":"5353288643","pt":1646212519466,"mc":[{"id":"1.195453770","rc":[{"atb":[[14,7.17]],"id":35801684}],"con":true,"img":false}]}
{"op":"mcm","clk":"5353301563","pt":1646212605275,"mc":[{"id":"1.195453770","rc":[{"atb":[[14,0]],"id":35801684}],"con":true,"img":false}]}
{"op":"mcm","clk":"5353301571","pt":1646212605380,"mc":[{"id":"1.195453770","rc":[{"atb":[[16.5,11.6]],"id":35801684}],"con":true,"img":false}]}
{"op":"mcm","clk":"5353302208","pt":1646212616822,"mc":[{"id":"1.195453770","rc":[{"atb":[[1.89,0],[1.98,102.04]],"id":26051221}],"con":true,"img":false}]}
{"op":"mcm","clk":"5353302532","pt":1646212622993,"mc":[{"id":"1.195453770","rc":[{"atb":[[12,11.36],[13,6.25],[14,11.76],[15,1.43]],"id":39784543},{"atl":[[260,1],[280,1],[220,1],[240,1.83]],"id":39784543},{"atb":[[10,5.56],[9.2,15.24],[11,2],[9.6,8.72]],"id":36074638},{"atl":[[200,1],[220,1],[240,1],[260,1]],"id":36074638},{"atb":[[2.34,74.63],[2.46,0]],"id":42189401}],"con":true,"img":false}]}
{"op":"mcm","clk":"5353302538","pt":1646212623147,"mc":[{"id":"1.195453770","rc":[{"atb":[[6.4,13.89],[6.8,8.62],[7.2,3.23],[6,25]],"id":36500377},{"atl":[[170,1],[190,1],[210,1],[230,1]],"id":36500377},{"atb":[[10.5,7.89],[11.5,4.76],[12.5,1.74],[9.8,14.2]],"id":35801684},{"atl":[[270,1],[210,1.95],[230,1],[250,1]],"id":35801684},{"atb":[[2.34,167.91],[2.42,35.21],[2.38,54.35],[2.46,13.7]],"id":42189401},{"atl":[[4.8,32.89],[4.4,22.88],[4.6,20.83],[4.2,7.57]],"id":42189401},{"atb":[[2.98,10.1],[2.94,25.77],[2.9,93.6],[2.86,67.2]],"id":37127725},{"atl":[[13,1.67],[14,3.85],[15,5.36],[16,8.33]],"id":37127725},{"atb":[[2.1,18.18],[1.99,126.26],[2.02,73.53],[2.06,47.17]],"id":26051221},{"atl":[[6.4,24.45],[5.8,10.42],[5.6,4.35],[6,15]],"id":26051221},{"atb":[[6.4,35.84],[6.8,8.62],[7.2,3.23],[6,25]],"id":28338255},{"atl":[[18.5,2.45],[19.5,9.89],[21,3.75],[23,11.06]],"id":28338255}],"con":true,"img":false}]}
{"op":"mcm","clk":"5353302562","pt":1646212623713,"mc":[{"id":"1.195453770","rc":[{"atl":[[6.4,23.15]],"id":26051221}],"con":true,"img":false}]}
{"op":"mcm","clk":"5353302568","pt":1646212623816,"mc":[{"id":"1.195453770","rc":[{"atl":[[5.5,1.3]],"id":26051221}],"con":true,"img":false}]}
{"op":"mcm","clk":"5353303579","pt":1646212641837,"mc":[{"id":"1.195453770","rc":[{"atb":[[2.92,0]],"id":37127725}],"con":true,"img":false}]}
{"op":"mcm","clk":"5353303587","pt":1646212641938,"mc":[{"id":"1.195453770","rc":[{"atb":[[2.96,32.44]],"id":37127725}],"con":true,"img":false}]}
{"op":"mcm","clk":"5353303594","pt":1646212642145,"mc":[{"id":"1.195453770","rc":[{"atb":[[2.34,93.28],[2.46,67.6]],"id":42189401}],"con":true,"img":false}]}
{"op":"mcm","clk":"5353303599","pt":1646212642351,"mc":[{"id":"1.195453770","rc":[{"atl":[[50,0]],"id":36500377}],"con":true,"img":false}]}
{"op":"mcm","clk":"5353303603","pt":1646212642454,"mc":[{"id":"1.195453770","rc":[{"atl":[[46,1.28]],"id":36500377}],"con":true,"img":false}]}
{"op":"mcm","clk":"5353304090","pt":1646212651888,"mc":[{"id":"1.195453770","rc":[{"atl":[[48,0]],"id":36500377},{"atl":[[6.6,0]],"id":26051221}],"con":true,"img":false}]}
{"op":"mcm","clk":"5353304096","pt":1646212651943,"mc":[{"id":"1.195453770","rc":[{"atl":[[50,2.72]],"id":36500377},{"atl":[[5.9,10.43]],"id":26051221}],"con":true,"img":false}]}
{"op":"mcm","clk":"5353304102","pt":1646212652045,"mc":[{"id":"1.195453770","rc":[{"atl":[[46,0]],"id":36500377}],"con":true,"img":false}]}
{"op":"mcm","clk":"5353304111","pt":1646212652153,"mc":[{"id":"1.195453770","rc":[{"atl":[[50,4]],"id":36500377}],"con":true,"img":false}]}
{"op":"mcm","clk":"5353304903","pt":1646212666979,"mc":[{"id":"1.195453770","rc":[{"atl":[[5.9,0],[4.5,31.99]],"id":42189401},{"atb":[[6.4,13.89]],"id":28338255}],"con":true,"img":false}]}
{"op":"mcm","clk":"5353304908","pt":1646212667082,"mc":[{"id":"1.195453770","rc":[{"atb":[[7,21.95]],"id":28338255}],"con":true,"img":false}]}
{"op":"mcm","clk":"5353305261","pt":1646212673410,"mc":[{"id":"1.195453770","rc":[{"atb":[[16,3.89]],"id":36074638},{"atb":[[2.96,30.44]],"id":37127725}],"con":true,"img":false}]}
{"op":"mcm","clk":"5353305273","pt":1646212673626,"mc":[{"id":"1.195453770","rc":[{"atb":[[15.5,7.79]],"id":36074638},{"atb":[[3.05,10.58]],"id":37127725}],"con":true,"img":false}]}
{"op":"mcm","clk":"5353305451","pt":1646212676881,"mc":[{"id":"1.195453770","rc":[{"atl":[[50,1.28]],"id":36500377}],"con":true,"img":false}]}
{"op":"mcm","clk":"5353305455","pt":1646212676983,"mc":[{"id":"1.195453770","rc":[{"atl":[[48,2.72]],"id":36500377}],"con":true,"img":false}]}
{"op":"mcm","clk":"5353305493","pt":1646212678123,"mc":[{"id":"1.195453770","rc":[{"atb":[[6.6,1.8]],"id":28338255}],"con":true,"img":false}]}
{"op":"mcm","clk":"5353306010","pt":1646212687331,"mc":[{"id":"1.195453770","rc":[{"atb":[[6.6,0]],"id":28338255}],"con":true,"img":false}]}
{"op":"mcm","clk":"5353306017","pt":1646212687537,"mc":[{"id":"1.195453770","rc":[{"atl":[[4.4,14.71]],"id":42189401}],"con":true,"img":false}]}
{"op":"mcm","clk":"5353306674","pt":1646212699332,"mc":[{"id":"1.195453770","rc":[{"atl":[[5.3,0]],"id":37127725}],"con":true,"img":false}]}
{"op":"mcm","clk":"5353306678","pt":1646212699430,"mc":[{"id":"1.195453770","rc":[{"atl":[[5.5,12.98]],"id":37127725}],"con":true,"img":false}]}
{"op":"mcm","clk":"5353306725","pt":1646212700151,"mc":[{"id":"1.195453770","rc":[{"atl":[[50,0]],"id":36500377}],"con":true,"img":false}]}
{"op":"mcm","clk":"5353306732","pt":1646212700253,"mc":[{"id":"1.195453770","rc":[{"atl":[[46,1.28]],"id":36500377}],"con":true,"img":false}]}
{"op":"mcm","clk":"5353307135","pt":1646212706919,"mc":[{"id":"1.195453770","rc":[{"atl":[[48,0]],"id":36500377},{"atb":[[16,0]],"id":36074638}],"con":true,"img":false}]}
{"op":"mcm","clk":"5353307139","pt":1646212707019,"mc":[{"id":"1.195453770","rc":[{"atl":[[50,2.72]],"id":36500377},{"atb":[[14,3.89]],"id":36074638}],"con":true,"img":false}]}
{"op":"mcm","clk":"5353307171","pt":1646212707536,"mc":[{"id":"1.195453770","rc":[{"atl":[[46,0]],"id":36500377}],"con":true,"img":false}]}
{"op":"mcm","clk":"5353307181","pt":1646212707639,"mc":[{"id":"1.195453770","rc":[{"atl":[[48,1.28]],"id":36500377}],"con":true,"img":false}]}
{"op":"mcm","clk":"5353307467","pt":1646212712735,"mc":[{"id":"1.195453770","rc":[{"atl":[[5,0]],"id":42189401}],"con":true,"img":false}]}
{"op":"mcm","clk":"5353307480","pt":1646212712943,"mc":[{"id":"1.195453770","rc":[{"atl":[[3.95,4.93]],"id":42189401}],"con":true,"img":false}]}
{"op":"mcm","clk":"5353307695","pt":1646212716972,"mc":[{"id":"1.195453770","rc":[{"atb":[[2.96,0]],"id":37127725}],"con":true,"img":false}]}
{"op":"mcm","clk":"5353307700","pt":1646212717075,"mc":[{"id":"1.195453770","rc":[{"atb":[[3.05,41.03]],"id":37127725}],"con":true,"img":false}]}
{"op":"mcm","clk":"5353307916","pt":1646212720685,"mc":[{"id":"1.195453770","rc":[{"atl":[[4.2,6.25]],"id":42189401}],"con":true,"img":false}]}
{"op":"mcm","clk":"5353307923","pt":1646212720791,"mc":[{"id":"1.195453770","rc":[{"atl":[[3.9,1.32]],"id":42189401}],"con":true,"img":false}]}
{"op":"mcm","clk":"5353308256","pt":1646212726266,"mc":[{"id":"1.195453770","rc":[{"atb":[[3.05,37.36]],"id":37127725}],"con":true,"img":false}]}
{"op":"mcm","clk":"5353308578","pt":1646212731879,"mc":[{"id":"1.195453770","rc":[{"atl":[[50,0]],"id":36500377}],"con":true,"img":false}]}
{"op":"mcm","clk":"5353308585","pt":1646212731982,"mc":[{"id":"1.195453770","rc":[{"atl":[[48,4]],"id":36500377}],"con":true,"img":false}]}
{"op":"mcm","clk":"5353308799","pt":1646212735383,"mc":[{"id":"1.195453770","rc":[{"atb":[[3.1,5.22]],"id":37127725}],"con":true,"img":false}]}
{"op":"mcm","clk":"5353308892","pt":1646212736993,"mc":[{"id":"1.195453770","rc":[{"atl":[[4.3,0]],"id":42189401}],"con":true,"img":false}]}
{"op":"mcm","clk":"5353308899","pt":1646212737085,"mc":[{"id":"1.195453770","rc":[{"atl":[[4.4,22.88],[4.1,17.71]],"id":42189401}],"con":true,"img":false}]}
{"op":"mcm","clk":"5353308989","pt":1646212738586,"mc":[{"id":"1.195453770","rc":[{"atb":[[3.05,32.44]],"id":37127725}],"con":true,"img":false}]}
{"op":"mcm","clk":"5353309167","pt":1646212741895,"mc":[{"id":"1.195453770","rc":[{"atl":[[48,1.28]],"id":36500377},{"atl":[[65,0]],"id":36074638},{"atb":[[2.72,0]],"id":37127725},{"atl":[[23,5.68]],"id":28338255}],"con":true,"img":false}]}
{"op":"mcm","clk":"5353309173","pt":1646212741998,"mc":[{"id":"1.195453770","rc":[{"atl":[[50,2.72]],"id":36500377},{"atl":[[46,5.44]],"id":36074638},{"atb":[[2.82,67.33]],"id":37127725},{"atl":[[20,5.38]],"id":28338255}],"con":true,"img":false}]}
{"op":"mcm","clk":"5353309186","pt":1646212742208,"mc":[{"id":"1.195453770","rc":[{"atl":[[46,7.57],[48,0]],"id":36074638}],"con":true,"img":false}]}
{"op":"mcm","clk":"5353309198","pt":1646212742468,"mc":[{"id":"1.195453770","rc":[{"atl":[[1000,0]],"id":36074638}],"con":true,"img":false}]}
{"op":"mcm","clk":"5353309201","pt":1646212742572,"mc":[{"id":"1.195453770","rc":[{"atl":[[44,1.23]],"id":36074638}],"con":true,"img":false}]}
{"op":"mcm","clk":"5353309230","pt":1646212742989,"mc":[{"id":"1.195453770","rc":[{"atl":[[44,0]],"id":36074638}],"con":true,"img":false}]}
{"op":"mcm","clk":"5353309240","pt":1646212743100,"mc":[{"id":"1.195453770","rc":[{"atl":[[60,0],[65,2]],"id":36500377},{"atl":[[1000,1.23]],"id":36074638},{"atb":[[2.34,167.91],[2.46,13.7]],"id":42189401}],"con":true,"img":false}]}
{"op":"mcm","clk":"5353309422","pt":1646212746966,"mc":[{"id":"1.195453770","rc":[{"atl":[[55,0.07]],"id":36500377},{"atl":[[46,4.85]],"id":36074638}],"con":true,"img":false}]}
{"op":"mcm","clk":"5353309429","pt":1646212747069,"mc":[{"id":"1.195453770","rc":[{"atl":[[60,2.72]],"id":36500377},{"atl":[[65,2.72]],"id":36074638}],"con":true,"img":false}]}
{"op":"mcm","clk":"5353309437","pt":1646212747276,"mc":[{"id":"1.195453770","rc":[{"atl":[[48,0]],"id":36500377}],"con":true,"img":false}]}
{"op":"mcm","clk":"5353309444","pt":1646212747379,"mc":[{"id":"1.195453770","rc":[{"atl":[[1000,1.28]],"id":36500377},{"atl":[[46,2.72],[48,2.13]],"id":36074638}],"con":true,"img":false}]}
{"op":"mcm","clk":"5353309450","pt":1646212747483,"mc":[{"id":"1.195453770","rc":[{"atl":[[60,2]],"id":36074638}],"con":true,"img":false}]}
{"op":"mcm","clk":"5353309454","pt":1646212747587,"mc":[{"id":"1.195453770","rc":[{"atl":[[48,0]],"id":36074638}],"con":true,"img":false}]}
{"op":"mcm","clk":"5353309473","pt":1646212747897,"mc":[{"id":"1.195453770","rc":[{"atl":[[1000,0]],"id":36500377}],"con":true,"img":false}]}
{"op":"mcm","clk":"5353309478","pt":1646212747999,"mc":[{"id":"1.195453770","rc":[{"atl":[[48,1.28]],"id":36500377}],"con":true,"img":false}]}
{"op":"mcm","clk":"5353309636","pt":1646212750693,"mc":[{"id":"1.195453770","rc":[{"atb":[[3.1,10.03]],"id":37127725}],"con":true,"img":false}]}
{"op":"mcm","clk":"5353310157","pt":1646212760102,"mc":[{"id":"1.195453770","rc":[{"atl":[[48,2.13]],"id":36074638}],"con":true,"img":false}]}
{"op":"mcm","clk":"5353310163","pt":1646212760204,"mc":[{"id":"1.195453770","rc":[{"atl":[[60,0]],"id":36074638}],"con":true,"img":false}]}
{"op":"mcm","clk":"5353311724","pt":1646212791842,"mc":[{"id":"1.195453770","rc":[{"atl":[[65,0]],"id":36074638}],"con":true,"img":false}]}
{"op":"mcm","clk":"5353311730","pt":1646212791949,"mc":[{"id":"1.195453770","rc":[{"atl":[[46,5.44]],"id":36074638}],"con":true,"img":false}]}
{"op":"mcm","clk":"5353311759","pt":1646212792562,"mc":[{"id":"1.195453770","rc":[{"atl":[[1000,0]],"id":36074638}],"con":true,"img":false}]}
{"op":"mcm","clk":"5353311761","pt":1646212792657,"mc":[{"id":"1.195453770","rc":[{"atl":[[44,1.23]],"id":36074638}],"con":true,"img":false}]}
{"op":"mcm","clk":"5353313377","pt":1646212822003,"mc":[{"id":"1.195453770","rc":[{"atl":[[46,2.72]],"id":36074638}],"con":true,"img":false}]}
{"op":"mcm","clk":"5353313384","pt":1646212822107,"mc":[{"id":"1.195453770","rc":[{"atl":[[42,2.72]],"id":36074638}],"con":true,"img":false}]}
{"op":"mcm","clk":"5353313392","pt":1646212822267,"mc":[{"id":"1.195453770","rc":[{"atl":[[4.4,14.71]],"id":42189401}],"con":true,"img":false}]}
{"op":"mcm","clk":"5353313416","pt":1646212822575,"mc":[{"id":"1.195453770","rc":[{"atl":[[44,0]],"id":36074638}],"con":true,"img":false}]}
{"op":"mcm","clk":"5353313423","pt":1646212822681,"mc":[{"id":"1.195453770","rc":[{"atl":[[40,1.23]],"id":36074638}],"con":true,"img":false}]}
{"op":"mcm","clk":"5353313968","pt":1646212831899,"mc":[{"id":"1.195453770","rc":[{"atl":[[42,0]],"id":36074638}],"con":true,"img":false}]}
{"op":"mcm","clk":"5353313973","pt":1646212832001,"mc":[{"id":"1.195453770","rc":[{"atl":[[46,5.44]],"id":36074638}],"con":true,"img":false}]}
{"op":"mcm","clk":"5353313996","pt":1646212832318,"mc":[{"id":"1.195453770","rc":[{"atl":[[40,0]],"id":36074638}],"con":true,"img":false}]}
{"op":"mcm","clk":"5353314002","pt":1646212832420,"mc":[{"id":"1.195453770","rc":[{"atl":[[44,1.23]],"id":36074638}],"con":true,"img":false}]}
{"op":"mcm","clk":"5353315804","pt":1646212861819,"mc":[{"id":"1.195453770","rc":[{"atl":[[46,2.72]],"id":36074638}],"con":true,"img":false}]}
{"op":"mcm","clk":"5353315810","pt":1646212861922,"mc":[{"id":"1.195453770","rc":[{"atl":[[42,2.72]],"id":36074638}],"con":true,"img":false}]}
{"op":"mcm","clk":"5353317916","pt":1646212896478,"mc":[{"id":"1.195453770","rc":[{"atl":[[55,2.07],[65,0]],"id":36500377},{"atl":[[46,4.94],[48,0]],"id":36074638},{"atb":[[2.34,93.28],[2.46,67.6]],"id":42189401}],"con":true,"img":false}]}
{"op":"mcm","clk":"5353317933","pt":1646212896887,"mc":[{"id":"1.195453770","rc":[{"atl":[[60,0]],"id":36500377}],"con":true,"img":false}]}
{"op":"mcm","clk":"5353317939","pt":1646212896992,"mc":[{"id":"1.195453770","rc":[{"atl":[[75,2.72]],"id":36500377}],"con":true,"img":false}]}
{"op":"mcm","clk":"5353318219","pt":1646212901898,"mc":[{"id":"1.195453770","rc":[{"atl":[[42,0]],"id":36074638}],"con":true,"img":false}]}
{"op":"mcm","clk":"5353318221","pt":1646212901998,"mc":[{"id":"1.195453770","rc":[{"atl":[[44,3.95]],"id":36074638}],"con":true,"img":false}]}
{"op":"mcm","clk":"5353318784","pt":1646212911909,"mc":[{"id":"1.195453770","rc":[{"atl":[[4.1,0]],"id":42189401}],"con":true,"img":false}]}
{"op":"mcm","clk":"5353318789","pt":1646212912010,"mc":[{"id":"1.195453770","rc":[{"atl":[[4.3,17.71],[4.4,22.88]],"id":42189401}],"con":true,"img":false}]}
{"op":"mcm","clk":"5353324901","pt":1646213016434,"mc":[{"id":"1.195453770","rc":[{"atl":[[48,2.13]],"id":36074638}],"con":true,"img":false}]}
{"op":"mcm","clk":"5353324907","pt":1646213016545,"mc":[{"id":"1.195453770","rc":[{"atl":[[55,0.07],[60,2]],"id":36500377},{"atl":[[46,2.72]],"id":36074638},{"atl":[[4.4,14.71]],"id":42189401}],"con":true,"img":false}]}
{"op":"mcm","clk":"5353325884","pt":1646213031863,"mc":[{"id":"1.195453770","rc":[{"atl":[[50,0]],"id":36500377}],"con":true,"img":false}]}
{"op":"mcm","clk":"5353325893","pt":1646213031966,"mc":[{"id":"1.195453770","rc":[{"atl":[[48,4]],"id":36500377}],"con":true,"img":false}]}
{"op":"mcm","clk":"5353326190","pt":1646213036966,"mc":[{"id":"1.195453770","rc":[{"atl":[[44,1.23]],"id":36074638},{"atl":[[4.3,0]],"id":42189401}],"con":true,"img":false}]}
{"op":"mcm","clk":"5353326197","pt":1646213037071,"mc":[{"id":"1.195453770","rc":[{"atl":[[42,2.72]],"id":36074638},{"atl":[[4.4,22.88],[4.1,17.71]],"id":42189401}],"con":true,"img":false}]}
{"op":"mcm","clk":"5353326460","pt":1646213041872,"mc":[{"id":"1.195453770","rc":[{"atl":[[48,1.28]],"id":36500377}],"con":true,"img":false}]}
{"op":"mcm","clk":"5353326466","pt":1646213041979,"mc":[{"id":"1.195453770","rc":[{"atl":[[50,2.72]],"id":36500377}],"con":true,"img":false}]}
{"op":"mcm","clk":"5353326651","pt":1646213044765,"mc":[{"id":"1.195453770","rc":[{"atb":[[21,2.17]],"id":39784543},{"atb":[[17,2.3]],"id":36500377},{"atb":[[17.5,2.08]],"id":35801684},{"atb":[[19,2.08]],"id":36074638},{"atb":[[2.72,2.5]],"id":42189401},{"atb":[[3.25,2.5]],"id":37127725},{"atb":[[8.2,2.5]],"id":28338255},{"atb":[[3.55,2.5]],"id":26051221}],"con":true,"img":false}]}
{"op":"mcm","clk":"5353326679","pt":1646213045382,"mc":[{"id":"1.195453770","rc":[{"atl":[[44,0]],"id":36074638}],"con":true,"img":false}]}
{"op":"mcm","clk":"5353326687","pt":1646213045484,"mc":[{"id":"1.195453770","rc":[{"atl":[[40,1.23]],"id":36074638}],"con":true,"img":false}]}
{"op":"mcm","clk":"5353327006","pt":1646213051881,"mc":[{"id":"1.195453770","rc":[{"atl":[[42,0]],"id":36074638}],"con":true,"img":false}]}
{"op":"mcm","clk":"5353327014","pt":1646213051982,"mc":[{"id":"1.195453770","rc":[{"atl":[[46,5.44]],"id":36074638}],"con":true,"img":false}]}
{"op":"mcm","clk":"5353327046","pt":1646213052494,"mc":[{"id":"1.195453770","rc":[{"atl":[[40,0]],"id":36074638}],"con":true,"img":false}]}
{"op":"mcm","clk":"5353327054","pt":1646213052605,"mc":[{"id":"1.195453770","rc":[{"atl":[[44,1.23]],"id":36074638}],"con":true,"img":false}]}
{"op":"mcm","clk":"5353327366","pt":1646213056905,"mc":[{"id":"1.195453770","rc":[{"atl":[[75,0]],"id":36500377}],"con":true,"img":false}]}
{"op":"mcm","clk":"5353327369","pt":1646213057007,"mc":[{"id":"1.195453770","rc":[{"atl":[[55,2.8]],"id":36500377}],"con":true,"img":false}]}
{"op":"mcm","clk":"5353328015","pt":1646213066912,"mc":[{"id":"1.195453770","rc":[{"atl":[[50,0]],"id":36500377}],"con":true,"img":false}]}
{"op":"mcm","clk":"5353328020","pt":1646213067011,"mc":[{"id":"1.195453770","rc":[{"atl":[[48,4]],"id":36500377}],"con":true,"img":false}]}
{"op":"mcm","clk":"5353328634","pt":1646213076902,"mc":[{"id":"1.195453770","rc":[{"spn":20.72,"spf":1.0,"id":39784543},{"atl":[[48,1.28]],"id":36500377},{"spn":16.88,"spf":1.0,"id":36500377},{"spn":17.34,"spf":1.0,"id":35801684},{"spn":19.0,"spf":1.0,"id":36074638},{"spn":2.98,"spf":"NaN","id":42189401},{"spn":3.92,"spf":"NaN","id":37127725},{"spn":3.45,"spf":1.0,"id":26051221},{"spn":13.35,"spf":"NaN","id":28338255}],"con":true,"img":false}]}
{"op":"mcm","clk":"5353328640","pt":1646213077000,"mc":[{"id":"1.195453770","rc":[{"atl":[[50,2.72]],"id":36500377}],"con":true,"img":false}]}
{"op":"mcm","clk":"5353328975","pt":1646213081918,"mc":[{"id":"1.195453770","rc":[{"atl":[[46,2.72]],"id":36074638}],"con":true,"img":false}]}
{"op":"mcm","clk":"5353328983","pt":1646213082023,"mc":[{"id":"1.195453770","rc":[{"atl":[[42,2.72]],"id":36074638}],"con":true,"img":false}]}
{"op":"mcm","clk":"5353330161","pt":1646213101856,"mc":[{"id":"1.195453770","rc":[{"atl":[[50,0]],"id":36500377}],"con":true,"img":false}]}
{"op":"mcm","clk":"5353330166","pt":1646213101985,"mc":[{"id":"1.195453770","rc":[{"atl":[[48,4]],"id":36500377}],"con":true,"img":false}]}
{"op":"mcm","clk":"5353330170","pt":1646213102038,"mc":[{"id":"1.195453770","rc":[{"atl":[[4.4,14.71]],"id":42189401}],"con":true,"img":false}]}
{"op":"mcm","clk":"5353330178","pt":1646213102245,"mc":[{"id":"1.195453770","rc":[{"atl":[[44,0]],"id":36074638}],"con":true,"img":false}]}
{"op":"mcm","clk":"5353330184","pt":1646213102350,"mc":[{"id":"1.195453770","rc":[{"atl":[[40,1.23]],"id":36074638}],"con":true,"img":false}]}
{"op":"mcm","clk":"5353330751","pt":1646213111876,"mc":[{"id":"1.195453770","rc":[{"atl":[[48,1.28]],"id":36500377},{"atl":[[42,0]],"id":36074638}],"con":true,"img":false}]}
{"op":"mcm","clk":"5353330759","pt":1646213111937,"mc":[{"id":"1.195453770","rc":[{"atl":[[50,2.72]],"id":36500377},{"atl":[[46,5.44]],"id":36074638}],"con":true,"img":false}]}
{"op":"mcm","clk":"5353330762","pt":1646213112035,"mc":[{"id":"1.195453770","rc":[{"atl":[[48,0]],"id":36500377},{"atl":[[40,0]],"id":36074638}],"con":true,"img":false}]}
{"op":"mcm","clk":"5353330768","pt":1646213112141,"mc":[{"id":"1.195453770","rc":[{"atl":[[50,4]],"id":36500377},{"atl":[[1000,1.23]],"id":36074638}],"con":true,"img":false}]}
{"op":"mcm","clk":"5353330806","pt":1646213112656,"mc":[{"id":"1.195453770","rc":[{"atl":[[1000,0]],"id":36074638}],"con":true,"img":false}]}
{"op":"mcm","clk":"5353330815","pt":1646213112867,"mc":[{"id":"1.195453770","rc":[{"atl":[[44,1.23]],"id":36074638}],"con":true,"img":false}]}
{"op":"mcm","clk":"5353331772","pt":1646213128452,"mc":[{"id":"1.195453770","rc":[{"atb":[[18.5,1.62],[1.04,2.25]],"id":36074638},{"atb":[[8,1.68],[1.02,2.25]],"id":28338255}],"con":true,"img":false}]}
{"op":"mcm","clk":"5353331780","pt":1646213128650,"mc":[{"id":"1.195453770","rc":[{"atb":[[1.04,0.19]],"id":36074638},{"atb":[[1.02,0.45]],"id":28338255}],"con":true,"img":false}]}
{"op":"mcm","clk":"5353331790","pt":1646213128857,"mc":[{"id":"1.195453770","rc":[{"atb":[[1.02,0]],"id":28338255}],"con":true,"img":false}]}
{"op":"mcm","clk":"5353331798","pt":1646213128962,"mc":[{"id":"1.195453770","rc":[{"atb":[[8.4,0.45]],"id":28338255}],"con":true,"img":false}]}
{"op":"mcm","clk":"5353331810","pt":1646213129166,"mc":[{"id":"1.195453770","rc":[{"atb":[[1.04,0]],"id":36074638}],"con":true,"img":false}]}
{"op":"mcm","clk":"5353331813","pt":1646213129267,"mc":[{"id":"1.195453770","rc":[{"atb":[[19.5,0.19]],"id":36074638}],"con":true,"img":false}]}
{"op":"mcm","clk":"5353332242","pt":1646213136852,"mc":[{"id":"1.195453770","rc":[{"atl":[[50,1.28]],"id":36500377}],"con":true,"img":false}]}
{"op":"mcm","clk":"5353332248","pt":1646213136960,"mc":[{"id":"1.195453770","rc":[{"atl":[[48,2.72]],"id":36500377},{"spn":19.09,"spf":1.0,"id":36074638},{"spn":13.45,"spf":"NaN","id":28338255}],"con":true,"img":false}]}
{"op":"mcm","clk":"5353332270","pt":1646213137270,"mc":[{"id":"1.195453770","rc":[{"atl":[[50,0]],"id":36500377}],"con":true,"img":false}]}
{"op":"mcm","clk":"5353332272","pt":1646213137369,"mc":[{"id":"1.195453770","rc":[{"atl":[[46,1.28]],"id":36500377}],"con":true,"img":false}]}
{"op":"mcm","clk":"5353332878","pt":1646213146878,"mc":[{"id":"1.195453770","rc":[{"atl":[[48,0]],"id":36500377}],"con":true,"img":false}]}
{"op":"mcm","clk":"5353332882","pt":1646213146982,"mc":[{"id":"1.195453770","rc":[{"atl":[[50,2.72]],"id":36500377}],"con":true,"img":false}]}
{"op":"mcm","clk":"5353332919","pt":1646213147702,"mc":[{"id":"1.195453770","rc":[{"atl":[[46,0]],"id":36500377}],"con":true,"img":false}]}
{"op":"mcm","clk":"5353332923","pt":1646213147806,"mc":[{"id":"1.195453770","rc":[{"atl":[[48,1.28]],"id":36500377}],"con":true,"img":false}]}
{"op":"mcm","clk":"5353334071","pt":1646213166921,"mc":[{"id":"1.195453770","rc":[{"atl":[[46,2.72]],"id":36074638}],"con":true,"img":false}]}
{"op":"mcm","clk":"5353334078","pt":1646213167023,"mc":[{"id":"1.195453770","rc":[{"atl":[[42,2.72]],"id":36074638}],"con":true,"img":false}]}
{"op":"mcm","clk":"5353334098","pt":1646213167493,"mc":[{"id":"1.195453770","rc":[{"atl":[[44,0]],"id":36074638}],"con":true,"img":false}]}
{"op":"mcm","clk":"5353334104","pt":1646213167594,"mc":[{"id":"1.195453770","rc":[{"atl":[[40,1.23]],"id":36074638}],"con":true,"img":false}]}
{"op":"mcm","clk":"5353334316","pt":1646213171925,"mc":[{"id":"1.195453770","rc":[{"atl":[[50,0]],"id":36500377}],"con":true,"img":false}]}
{"op":"mcm","clk":"5353334322","pt":1646213172028,"mc":[{"id":"1.195453770","rc":[{"atl":[[48,4]],"id":36500377}],"con":true,"img":false}]}
{"op":"mcm","clk":"5353334585","pt":1646213176935,"mc":[{"id":"1.195453770","rc":[{"atl":[[42,0]],"id":36074638}],"con":true,"img":false}]}
{"op":"mcm","clk":"5353334592","pt":1646213177039,"mc":[{"id":"1.195453770","rc":[{"atl":[[46,5.44]],"id":36074638}],"con":true,"img":false}]}
{"op":"mcm","clk":"5353334635","pt":1646213177713,"mc":[{"id":"1.195453770","rc":[{"atl":[[40,0]],"id":36074638}],"con":true,"img":false}]}
{"op":"mcm","clk":"5353334642","pt":1646213177817,"mc":[{"id":"1.195453770","rc":[{"atl":[[44,1.23]],"id":36074638}],"con":true,"img":false}]}
{"op":"mcm","clk":"5353334852","pt":1646213181806,"mc":[{"id":"1.195453770","rc":[{"atl":[[48,1.28]],"id":36500377}],"con":true,"img":false}]}
{"op":"mcm","clk":"5353334857","pt":1646213181915,"mc":[{"id":"1.195453770","rc":[{"atl":[[50,2.72]],"id":36500377}],"con":true,"img":false}]}
{"op":"mcm","clk":"5353336182","pt":1646213206973,"mc":[{"id":"1.195453770","rc":[{"atl":[[50,0]],"id":36500377},{"atl":[[46,2.72]],"id":36074638}],"con":true,"img":false}]}
{"op":"mcm","clk":"5353336189","pt":1646213207076,"mc":[{"id":"1.195453770","rc":[{"atl":[[48,4]],"id":36500377},{"atl":[[42,2.72]],"id":36074638}],"con":true,"img":false}]}
{"op":"mcm","clk":"5353336741","pt":1646213216850,"mc":[{"id":"1.195453770","rc":[{"atl":[[48,1.28]],"id":36500377}],"con":true,"img":false}]}
{"op":"mcm","clk":"5353336746","pt":1646213216951,"mc":[{"id":"1.195453770","rc":[{"atl":[[50,2.72]],"id":36500377}],"con":true,"img":false}]}
{"op":"mcm","clk":"5353336751","pt":1646213217055,"mc":[{"id":"1.195453770","rc":[{"atl":[[48,0]],"id":36500377}],"con":true,"img":false}]}
{"op":"mcm","clk":"5353336754","pt":1646213217158,"mc":[{"id":"1.195453770","rc":[{"atl":[[50,4]],"id":36500377}],"con":true,"img":false}]}
{"op":"mcm","clk":"5353337184","pt":1646213224468,"mc":[{"id":"1.195453770","rc":[{"atb":[[12,0],[13,0],[14,7.91],[8.4,0],[15,0],[21,4.17]],"id":39784543},{"atl":[[260,0],[280,0],[75,4.72],[110,0],[220,0],[240,0.83]],"id":39784543},{"atb":[[2.34,0],[2.42,0],[2.52,41.16],[2.38,0],[2.46,0]],"id":42189401},{"atl":[[4.8,0],[4.4,0],[4.6,0],[6,26.63],[4.2,0]],"id":42189401}],"con":true,"img":false}]}
{"op":"mcm","clk":"5353337189","pt":1646213224574,"mc":[{"id":"1.195453770","rc":[{"atl":[[4.4,8.17]],"id":42189401}],"con":true,"img":false}]}
{"op":"mcm","clk":"5353337194","pt":1646213224678,"mc":[{"id":"1.195453770","rc":[{"atb":[[10,0],[9.2,0],[11,0],[5.3,0],[9.6,0]],"id":36074638},{"atl":[[42,4.72],[48,0],[200,0],[220,0],[240,0],[260,0]],"id":36074638},{"atb":[[6.4,0],[8.2,4.5],[7.4,1.57],[6.8,0],[7.2,0],[7.6,0],[6,0]],"id":28338255},{"atl":[[18.5,1.31],[19.5,7.19],[21,0],[23,0]],"id":28338255},{"atb":[[1.98,0],[3.25,0],[2.1,0],[1.99,0],[2.02,0],[2.06,0]],"id":26051221},{"atl":[[6.4,0],[5.8,0],[9.4,0],[5.6,0],[6,0]],"id":26051221}],"con":true,"img":false}]}
{"op":"mcm","clk":"5353337200","pt":1646213224783,"mc":[{"id":"1.195453770","rc":[{"atb":[[6.4,0],[6.8,0],[4.9,0],[16.5,1.66],[7.2,0],[6,0]],"id":36500377},{"atl":[[170,0],[190,0],[48,2],[210,0],[230,0],[60,0]],"id":36500377},{"atb":[[10.5,0],[11.5,0],[6.8,0],[12.5,0],[16.5,10.94],[17.5,4.08],[9.8,0]],"id":35801684},{"atl":[[270,0],[100,0],[210,0.95],[230,0],[60,4.72],[250,0]],"id":35801684},{"atb":[[5.4,0]],"id":28338255},{"atl":[[60,0]],"id":28338255}],"con":true,"img":false}]}
{"op":"mcm","clk":"5353337206","pt":1646213224886,"mc":[{"id":"1.195453770","rc":[{"atb":[[2.98,0],[2.94,0],[2.4,0],[2.9,54.13],[2.86,0]],"id":37127725},{"atl":[[11.5,0],[13,0],[14,0],[15,0],[16,0]],"id":37127725},{"atl":[[5.5,0]],"id":26051221}],"con":true,"img":false}]}
{"op":"mcm","clk":"5353337211","pt":1646213224989,"mc":[{"id":"1.195453770","rc":[{"atb":[[16.5,2.32]],"id":36500377},{"atb":[[16.5,11.6]],"id":35801684},{"atl":[[1000,1.3]],"id":26051221}],"con":true,"img":false}]}
{"op":"mcm","clk":"5353337242","pt":1646213225460,"mc":[{"id":"1.195453770","rc":[{"atl":[[50,2.72]],"id":36500377}],"con":true,"img":false}]}
{"op":"mcm","clk":"5353337247","pt":1646213225565,"mc":[{"id":"1.195453770","rc":[{"atl":[[48,3.28]],"id":36500377}],"con":true,"img":false}]}
{"op":"mcm","clk":"5353337315","pt":1646213226905,"mc":[{"id":"1.195453770","rc":[{"atl":[[55,0.07]],"id":36500377},{"atl":[[42,2],[46,0]],"id":36074638},{"atl":[[5.9,22.85],[4.5,0],[4.1,0]],"id":42189401},{"atl":[[5.9,0]],"id":26051221},{"atl":[[20,0]],"id":28338255}],"con":true,"img":false}]}
{"op":"mcm","clk":"5353337321","pt":1646213226957,"mc":[{"id":"1.195453770","rc":[{"atl":[[75,2.72]],"id":36500377},{"atl":[[65,2.72],[46,2.72]],"id":36074638},{"atl":[[4.4,25.88]],"id":42189401},{"atl":[[23,5.38]],"id":28338255},{"atl":[[6.6,10.43]],"id":26051221}],"con":true,"img":false}]}
{"op":"mcm","clk":"5353337336","pt":1646213227266,"mc":[{"id":"1.195453770","rc":[{"atl":[[1000,0]],"id":26051221}],"con":true,"img":false}]}
{"op":"mcm","clk":"5353337342","pt":1646213227373,"mc":[{"id":"1.195453770","rc":[{"atl":[[6.4,1.3]],"id":26051221}],"con":true,"img":false}]}
{"op":"mcm","clk":"5353337469","pt":1646213229876,"mc":[{"id":"1.195453770","rc":[{"atl":[[42,0],[44,3.23]],"id":36074638}],"con":true,"img":false}]}
{"op":"mcm","clk":"5353337490","pt":1646213230393,"mc":[{"id":"1.195453770","rc":[{"atl":[[44,2]],"id":36074638}],"con":true,"img":false}]}
{"op":"mcm","clk":"5353337495","pt":1646213230522,"mc":[{"id":"1.195453770","rc":[{"atl":[[44,0],[1000,1.23]],"id":36074638}],"con":true,"img":false}]}
{"op":"mcm","clk":"5353337503","pt":1646213230705,"mc":[{"id":"1.195453770","rc":[{"atl":[[46,4.72]],"id":36074638}],"con":true,"img":false}]}
{"op":"mcm","clk":"5353338189","pt":1646213241887,"mc":[{"id":"1.195453770","rc":[{"atl":[[50,0]],"id":36500377}],"con":true,"img":false}]}
{"op":"mcm","clk":"5353338195","pt":1646213241989,"mc":[{"id":"1.195453770","rc":[{"atl":[[55,2.8]],"id":36500377}],"con":true,"img":false}]}
{"op":"mcm","clk":"5353338769","pt":1646213251911,"mc":[{"id":"1.195453770","rc":[{"atb":[[19.5,0]],"id":39784543},{"atl":[[75,2]],"id":39784543},{"atb":[[16.5,7.83]],"id":35801684},{"atl":[[60,2]],"id":35801684},{"atb":[[7.8,0]],"id":28338255}],"con":true,"img":false}]}
{"op":"mcm","clk":"5353338773","pt":1646213252013,"mc":[{"id":"1.195453770","rc":[{"atb":[[22,3.16]],"id":39784543},{"atl":[[70,2.77],[75,0],[100,4.72]],"id":39784543},{"atb":[[18,3.77]],"id":35801684},{"atl":[[80,4.72],[55,2.79]],"id":35801684},{"atb":[[8.2,13.09]],"id":28338255}],"con":true,"img":false}]}
{"op":"mcm","clk":"5353338778","pt":1646213252116,"mc":[{"id":"1.195453770","rc":[{"atb":[[21,2.17],[23,2]],"id":39784543},{"atb":[[17.5,2.08],[18.5,2]],"id":35801684},{"atl":[[80,2.72],[60,0]],"id":35801684}],"con":true,"img":false}]}
{"op":"mcm","clk":"5353338783","pt":1646213252221,"mc":[{"id":"1.195453770","rc":[{"atl":[[100,2.72]],"id":39784543}],"con":true,"img":false}]}
{"op":"mcm","clk":"5353338789","pt":1646213252324,"mc":[{"id":"1.195453770","rc":[{"atb":[[23,0]],"id":39784543},{"atl":[[70,4.77]],"id":39784543},{"atl":[[55,4.79]],"id":35801684}],"con":true,"img":false}]}
{"op":"mcm","clk":"5353338791","pt":1646213252425,"mc":[{"id":"1.195453770","rc":[{"atb":[[23,2]],"id":39784543}],"con":true,"img":false}]}
{"op":"mcm","clk":"5353338879","pt":1646213254038,"mc":[{"id":"1.195453770","rc":[{"atb":[[21,0.51]],"id":39784543},{"atb":[[17.5,0]],"id":35801684}],"con":true,"img":false}]}
{"op":"mcm","clk":"5353338927","pt":1646213255124,"mc":[{"id":"1.195453770","rc":[{"atb":[[24,1.66]],"id":39784543},{"atb":[[19,2.08]],"id":35801684}],"con":true,"img":false}]}
{"op":"mcm","clk":"5353339309","pt":1646213261917,"mc":[{"id":"1.195453770","rc":[{"atb":[[22,0]],"id":39784543},{"atb":[[18,0]],"id":35801684}],"con":true,"img":false}]}
{"op":"mcm","clk":"5353339313","pt":1646213262016,"mc":[{"id":"1.195453770","rc":[{"atb":[[19.5,3.16]],"id":39784543},{"atb":[[16.5,11.6]],"id":35801684}],"con":true,"img":false}]}
{"op":"mcm","clk":"5353340087","pt":1646213276928,"mc":[{"id":"1.195453770","rc":[{"atl":[[70,2.05]],"id":39784543},{"spn":23.55,"spf":1.0,"id":39784543},{"atl":[[55,2.06]],"id":35801684},{"spn":18.84,"spf":1.0,"id":35801684}],"con":true,"img":false}]}
{"op":"mcm","clk":"5353340091","pt":1646213277031,"mc":[{"id":"1.195453770","rc":[{"atl":[[65,2.72]],"id":39784543},{"atl":[[50,2.72]],"id":35801684}],"con":true,"img":false}]}
{"op":"mcm","clk":"5353340096","pt":1646213277230,"mc":[{"id":"1.195453770","rc":[{"atl":[[60,1.25]],"id":39784543},{"atl":[[48,1.32]],"id":35801684}],"con":true,"img":false}]}
{"op":"mcm","clk":"5353340127","pt":1646213277643,"mc":[{"id":"1.195453770","rc":[{"atl":[[100,4.72]],"id":39784543},{"atl":[[80,4.72],[55,0.06]],"id":35801684}],"con":true,"img":false}]}
{"op":"mcm","clk":"5353340133","pt":1646213277746,"mc":[{"id":"1.195453770","rc":[{"atl":[[70,0.05]],"id":39784543}],"con":true,"img":false}]}
{"op":"mcm","clk":"5353340142","pt":1646213277952,"mc":[{"id":"1.195453770","rc":[{"atl":[[48,0]],"id":35801684}],"con":true,"img":false}]}
{"op":"mcm","clk":"5353340149","pt":1646213278055,"mc":[{"id":"1.195453770","rc":[{"atl":[[1000,1.32]],"id":35801684}],"con":true,"img":false}]}
{"op":"mcm","clk":"5353340184","pt":1646213278627,"mc":[{"id":"1.195453770","rc":[{"atl":[[60,0]],"id":39784543}],"con":true,"img":false}]}
{"op":"mcm","clk":"5353340194","pt":1646213278733,"mc":[{"id":"1.195453770","rc":[{"atl":[[1000,1.25]],"id":39784543}],"con":true,"img":false}]}
{"op":"mcm","clk":"5353340348","pt":1646213281967,"mc":[{"id":"1.195453770","rc":[{"atl":[[65,0]],"id":39784543},{"atl":[[50,0]],"id":35801684}],"con":true,"img":false}]}
{"op":"mcm","clk":"5353340354","pt":1646213282070,"mc":[{"id":"1.195453770","rc":[{"atl":[[75,2.72]],"id":39784543},{"atl":[[60,2.72]],"id":35801684}],"con":true,"img":false}]}
{"op":"mcm","clk":"5353340388","pt":1646213282744,"mc":[{"id":"1.195453770","rc":[{"atl":[[75,4.72],[100,2.72]],"id":39784543},{"atl":[[60,4.72]],"id":35801684}],"con":true,"img":false}]}
{"op":"mcm","clk":"5353340393","pt":1646213282843,"mc":[{"id":"1.195453770","rc":[{"atl":[[80,2.72]],"id":35801684}],"con":true,"img":false}]}
{"op":"mcm","clk":"5353340399","pt":1646213282948,"mc":[{"id":"1.195453770","rc":[{"atl":[[60,2.72]],"id":35801684}],"con":true,"img":false}]}
{"op":"mcm","clk":"5353340406","pt":1646213283050,"mc":[{"id":"1.195453770","rc":[{"atl":[[60,4.72]],"id":35801684}],"con":true,"img":false}]}
{"op":"mcm","clk":"5353340468","pt":1646213284551,"mc":[{"id":"1.195453770","rc":[{"atb":[[23,0]],"id":39784543},{"atl":[[75,2.72]],"id":39784543}],"con":true,"img":false}]}
{"op":"mcm","clk":"5353340484","pt":1646213284758,"mc":[{"id":"1.195453770","rc":[{"atl":[[46,2.72]],"id":36074638},{"atb":[[8.2,11.09]],"id":28338255}],"con":true,"img":false}]}
{"op":"mcm","clk":"5353340490","pt":1646213284862,"mc":[{"id":"1.195453770","rc":[{"atl":[[48,1.28]],"id":36500377},{"atb":[[18.5,0]],"id":35801684},{"atl":[[60,2.72]],"id":35801684}],"con":true,"img":false}]}
{"op":"mcm","clk":"5353340501","pt":1646213285172,"mc":[{"id":"1.195453770","rc":[{"atl":[[48,0]],"id":36500377}],"con":true,"img":false}]}
{"op":"mcm","clk":"5353340507","pt":1646213285274,"mc":[{"id":"1.195453770","rc":[{"atl":[[1000,1.28]],"id":36500377}],"con":true,"img":false}]}
{"op":"mcm","clk":"5353340579","pt":1646213286974,"mc":[{"id":"1.195453770","rc":[{"atb":[[8.2,2.5]],"id":28338255}],"con":true,"img":false}]}
{"op":"mcm","clk":"5353340582","pt":1646213287077,"mc":[{"id":"1.195453770","rc":[{"atb":[[7.8,8.59]],"id":28338255}],"con":true,"img":false}]}
{"op":"mcm","clk":"5353340587","pt":1646213287233,"mc":[{"id":"1.195453770","rc":[{"atb":[[8,0]],"id":28338255}],"con":true,"img":false}]}
{"op":"mcm","clk":"5353340594","pt":1646213287337,"mc":[{"id":"1.195453770","rc":[{"atb":[[1.01,1.68]],"id":28338255}],"con":true,"img":false}]}
{"op":"mcm","clk":"5353341094","pt":1646213296684,"mc":[{"id":"1.195453770","rc":[{"atb":[[2.98,37.88],[2.94,64.43],[3.05,74.56],[3.15,9.3]],"id":26051221},{"atl":[[6.4,24.45],[5.8,10.42],[5.6,4.35],[6,15]],"id":26051221}],"con":true,"img":false}]}
{"op":"mcm","clk":"5353341129","pt":1646213297176,"mc":[{"id":"1.195453770","rc":[{"atl":[[6.4,23.15]],"id":26051221}],"con":true,"img":false}]}
{"op":"mcm","clk":"5353341135","pt":1646213297278,"mc":[{"id":"1.195453770","rc":[{"atl":[[5.5,1.3]],"id":26051221}],"con":true,"img":false}]}
{"op":"mcm","clk":"5353341250","pt":1646213299492,"mc":[{"id":"1.195453770","rc":[{"atb":[[16.5,4.43]],"id":35801684}],"con":true,"img":false}]}
{"op":"mcm","clk":"5353341257","pt":1646213299545,"mc":[{"id":"1.195453770","rc":[{"atb":[[14,7.17]],"id":35801684}],"con":true,"img":false}]}
{"op":"mcm","clk":"5353341510","pt":1646213303853,"mc":[{"id":"1.195453770","rc":[{"atb":[[12,11.36],[13,6.25],[14,11.76],[15,1.43]],"id":39784543},{"atl":[[260,1],[280,1],[220,1],[240,1.83]],"id":39784543}],"con":true,"img":false}]}
{"op":"mcm","clk":"5353341861","pt":1646213311961,"mc":[{"id":"1.195453770","rc":[{"atb":[[10.5,16.08],[11.5,1.9],[9.4,23.45],[9.8,8.52]],"id":36074638},{"atl":[[260,1],[200,1],[220,1],[240,1]],"id":36074638}],"con":true,"img":false}]}
{"op":"mcm","clk":"5353342086","pt":1646213316967,"mc":[{"id":"1.195453770","rc":[{"atl":[[60,0]],"id":35801684}],"con":true,"img":false}]}
{"op":"mcm","clk":"5353342090","pt":1646213317070,"mc":[{"id":"1.195453770","rc":[{"atl":[[55,2.79]],"id":35801684}],"con":true,"img":false}]}
{"op":"mcm","clk":"5353342223","pt":1646213319774,"mc":[{"id":"1.195453770","rc":[{"atb":[[2.34,93.28],[2.42,35.21],[2.38,54.35],[2.46,13.7]],"id":42189401},{"atl":[[4.8,32.89],[4.4,40.59],[4.6,20.83],[4.2,6.25]],"id":42189401}],"con":true,"img":false}]}
{"op":"mcm","clk":"5353342305","pt":1646213321998,"mc":[{"id":"1.195453770","rc":[{"atl":[[6.6,0]],"id":26051221}],"con":true,"img":false}]}
{"op":"mcm","clk":"5353342308","pt":1646213322102,"mc":[{"id":"1.195453770","rc":[{"atl":[[5.9,10.43]],"id":26051221}],"con":true,"img":false}]}
{"op":"mcm","clk":"5353342526","pt":1646213327933,"mc":[{"id":"1.195453770","rc":[{"atb":[[23,2]],"id":39784543},{"atl":[[75,4.72]],"id":39784543},{"atl":[[55,4.8]],"id":36500377},{"atb":[[18.5,2]],"id":35801684},{"atl":[[60,2]],"id":35801684},{"atl":[[46,4.72]],"id":36074638},{"atb":[[8.2,4.5]],"id":28338255}],"con":true,"img":false}]}
{"op":"mcm","clk":"5353342545","pt":1646213328503,"mc":[{"id":"1.195453770","rc":[{"atb":[[6.4,13.89],[6.8,8.62],[7.2,3.23],[6,25]],"id":28338255},{"atl":[[18.5,2.45],[19.5,9.89],[21,3.75],[23,11.06]],"id":28338255}],"con":true,"img":false}]}
{"op":"mcm","clk":"5353342548","pt":1646213328606,"mc":[{"id":"1.195453770","rc":[{"atb":[[10.5,7.89],[11.5,4.76],[12.5,10.68],[9.8,14.2]],"id":36500377},{"atl":[[170,1],[190,1],[210,1],[230,1]],"id":36500377}],"con":true,"img":false}]}
{"op":"mcm","clk":"5353342718","pt":1646213332635,"mc":[{"id":"1.195453770","rc":[{"atb":[[2.98,10.1],[2.94,25.77],[2.9,93.6],[2.86,67.2]],"id":37127725},{"atl":[[4.9,19.23],[4.5,5.71],[5.1,30.49],[4.7,25.49]],"id":37127725}],"con":true,"img":false}]}
{"op":"mcm","clk":"5353342861","pt":1646213336103,"mc":[{"id":"1.195453770","rc":[{"atl":[[1000,0]],"id":35801684}],"con":true,"img":false}]}
{"op":"mcm","clk":"5353342866","pt":1646213336206,"mc":[{"id":"1.195453770","rc":[{"atl":[[50,1.32]],"id":35801684}],"con":true,"img":false}]}
{"op":"mcm","clk":"5353342870","pt":1646213336310,"mc":[{"id":"1.195453770","rc":[{"atl":[[50,3.32],[60,0]],"id":35801684}],"con":true,"img":false}]}
{"op":"mcm","clk":"5353342882","pt":1646213336517,"mc":[{"id":"1.195453770","rc":[{"atb":[[15.5,7.09]],"id":36074638},{"atl":[[4.6,0]],"id":37127725}],"con":true,"img":false}]}
{"op":"mcm","clk":"5353342888","pt":1646213336619,"mc":[{"id":"1.195453770","rc":[{"atb":[[16.5,0.66]],"id":36074638},{"atl":[[4.4,1.23]],"id":37127725}],"con":true,"img":false}]}
{"op":"mcm","clk":"5353342977","pt":1646213338838,"mc":[{"id":"1.195453770","rc":[{"atb":[[1.04,2.25]],"id":39784543},{"atb":[[1.04,2.25]],"id":35801684},{"spn":3.82,"spf":"NaN","id":37127725}],"con":true,"img":false}]}
{"op":"mcm","clk":"5353343004","pt":1646213339406,"mc":[{"id":"1.195453770","rc":[{"atb":[[3.1,6.45]],"id":37127725}],"con":true,"img":false}]}
{"op":"mcm","clk":"5353343037","pt":1646213340130,"mc":[{"id":"1.195453770","rc":[{"atb":[[1.04,0.15]],"id":39784543},{"atb":[[1.04,0.19]],"id":35801684}],"con":true,"img":false}]}
{"op":"mcm","clk":"5353343043","pt":1646213340334,"mc":[{"id":"1.195453770","rc":[{"atb":[[1.04,0]],"id":39784543}],"con":true,"img":false}]}
{"op":"mcm","clk":"5353343050","pt":1646213340441,"mc":[{"id":"1.195453770","rc":[{"atb":[[25,0.15]],"id":39784543}],"con":true,"img":false}]}
{"op":"mcm","clk":"5353343057","pt":1646213340649,"mc":[{"id":"1.195453770","rc":[{"atb":[[1.04,0]],"id":35801684}],"con":true,"img":false}]}
{"op":"mcm","clk":"5353343063","pt":1646213340704,"mc":[{"id":"1.195453770","rc":[{"atb":[[10.5,7.89],[11.5,4.76],[12.5,1.74],[19.5,0.19],[9.8,14.2]],"id":35801684},{"atl":[[170,1],[190,1],[210,1.95],[230,1]],"id":35801684}],"con":true,"img":false}]}
{"op":"mcm","clk":"5353343110","pt":1646213341951,"mc":[{"id":"1.195453770","rc":[{"atl":[[4.4,22.88]],"id":42189401}],"con":true,"img":false}]}
{"op":"mcm","clk":"5353343116","pt":1646213342049,"mc":[{"id":"1.195453770","rc":[{"atl":[[4.3,17.71]],"id":42189401}],"con":true,"img":false}]}
{"op":"mcm","clk":"5353343229","pt":1646213344546,"mc":[{"id":"1.195453770","rc":[{"atb":[[3.1,1.65]],"id":37127725}],"con":true,"img":false}]}
{"op":"mcm","clk":"5353343772","pt":1646213354856,"mc":[{"id":"1.195453770","rc":[{"atb":[[12,1.82],[12.5,8.94]],"id":36500377},{"atb":[[11.5,0],[12.5,1.74]],"id":36074638},{"atl":[[4.1,6.45],[4.2,0]],"id":42189401},{"atl":[[18.5,1.31],[18,1.18]],"id":28338255},{"atl":[[5.8,4.17],[5.6,0]],"id":26051221}],"con":true,"img":false}]}
{"op":"mcm","clk":"5353343788","pt":1646213355156,"mc":[{"id":"1.195453770","rc":[{"atl":[[5.5,0]],"id":26051221}],"con":true,"img":false}]}
{"op":"mcm","clk":"5353343795","pt":1646213355267,"mc":[{"id":"1.195453770","rc":[{"atl":[[5.7,1.3]],"id":26051221}],"con":true,"img":false}]}
{"op":"mcm","clk":"5353343894","pt":1646213356966,"mc":[{"id":"1.195453770","rc":[{"atl":[[5.5,0]],"id":37127725}],"con":true,"img":false}]}
{"op":"mcm","clk":"5353343900","pt":1646213357069,"mc":[{"id":"1.195453770","rc":[{"atl":[[5.4,12.98]],"id":37127725}],"con":true,"img":false}]}
{"op":"mcm","clk":"5353344003","pt":1646213359450,"mc":[{"id":"1.195453770","rc":[{"atl":[[46,2]],"id":36074638},{"atl":[[4.5,31.99]],"id":42189401}],"con":true,"img":false}]}
{"op":"mcm","clk":"5353344009","pt":1646213359553,"mc":[{"id":"1.195453770","rc":[{"atl":[[48,2.72],[65,4.72]],"id":36074638},{"atl":[[5.9,0]],"id":42189401}],"con":true,"img":false}]}
{"op":"mcm","clk":"5353344015","pt":1646213359656,"mc":[{"id":"1.195453770","rc":[{"atl":[[130,3.03],[46,0],[65,2.72]],"id":36074638}],"con":true,"img":false}]}
{"op":"mcm","clk":"5353344022","pt":1646213359760,"mc":[{"id":"1.195453770","rc":[{"atl":[[130,1.03],[46,2]],"id":36074638}],"con":true,"img":false}]}
{"op":"mcm","clk":"5353344025","pt":1646213359862,"mc":[{"id":"1.195453770","rc":[{"atl":[[46,0],[48,4.72]],"id":36074638}],"con":true,"img":false}]}
{"op":"mcm","clk":"5353344029","pt":1646213359965,"mc":[{"id":"1.195453770","rc":[{"atl":[[65,4.72]],"id":36074638}],"con":true,"img":false}]}
{"op":"mcm","clk":"5353344033","pt":1646213360068,"mc":[{"id":"1.195453770","rc":[{"atl":[[48,2.72]],"id":36074638}],"con":true,"img":false}]}
{"op":"mcm","clk":"5353344038","pt":1646213360171,"mc":[{"id":"1.195453770","rc":[{"atl":[[65,2.72]],"id":36074638}],"con":true,"img":false}]}
{"op":"mcm","clk":"5353344043","pt":1646213360274,"mc":[{"id":"1.195453770","rc":[{"atl":[[48,4.72]],"id":36074638}],"con":true,"img":false}]}
{"op":"mcm","clk":"5353344276","pt":1646213364885,"mc":[{"id":"1.195453770","rc":[{"atb":[[11,5]],"id":36500377},{"atb":[[11.5,4.76]],"id":36074638},{"atl":[[6,10]],"id":26051221}],"con":true,"img":false}]}
{"op":"mcm","clk":"5353344610","pt":1646213371967,"mc":[{"id":"1.195453770","rc":[{"atl":[[5.9,0]],"id":26051221}],"con":true,"img":false}]}
{"op":"mcm","clk":"5353344616","pt":1646213372071,"mc":[{"id":"1.195453770","rc":[{"atl":[[6.2,10.43]],"id":26051221}],"con":true,"img":false}]}
{"op":"mcm","clk":"5353344649","pt":1646213373102,"mc":[{"id":"1.195453770","rc":[{"atb":[[12,0],[12.5,10.68]],"id":36500377},{"atb":[[11.5,1.9],[12.5,0]],"id":36074638},{"atl":[[4.1,0],[4.2,6.25]],"id":42189401},{"atl":[[5.6,4.35]],"id":26051221},{"atl":[[18,0],[18.5,2.45]],"id":28338255}],"con":true,"img":false}]}
{"op":"mcm","clk":"5353344688","pt":1646213373779,"mc":[{"id":"1.195453770","rc":[{"atl":[[5.7,0]],"id":26051221}],"con":true,"img":false}]}
{"op":"mcm","clk":"5353344696","pt":1646213373883,"mc":[{"id":"1.195453770","rc":[{"atl":[[5.5,1.3]],"id":26051221}],"con":true,"img":false}]}
{"op":"mcm","clk":"5353344840","pt":1646213376986,"mc":[{"id":"1.195453770","rc":[{"atl":[[75,2]],"id":39784543}],"con":true,"img":false}]}
{"op":"mcm","clk":"5353344842","pt":1646213377091,"mc":[{"id":"1.195453770","rc":[{"atl":[[70,2.77]],"id":39784543}],"con":true,"img":false}]}
{"op":"mcm","clk":"5353344847","pt":1646213377193,"mc":[{"id":"1.195453770","rc":[{"atl":[[75,0],[100,4.72]],"id":39784543}],"con":true,"img":false}]}
{"op":"mcm","clk":"5353344860","pt":1646213377402,"mc":[{"id":"1.195453770","rc":[{"atl":[[70,4.77],[100,2.72],[1000,0]],"id":39784543}],"con":true,"img":false}]}
{"op":"mcm","clk":"5353344865","pt":1646213377501,"mc":[{"id":"1.195453770","rc":[{"atl":[[65,1.25]],"id":39784543}],"con":true,"img":false}]}
{"op":"mcm","clk":"5353344868","pt":1646213377555,"mc":[{"id":"1.195453770","rc":[{"atl":[[70,2.77]],"id":39784543}],"con":true,"img":false}]}
{"op":"mcm","clk":"5353344873","pt":1646213377656,"mc":[{"id":"1.195453770","rc":[{"atl":[[70,4.77]],"id":39784543}],"con":true,"img":false}]}
{"op":"mcm","clk":"5353344891","pt":1646213378071,"mc":[{"id":"1.195453770","rc":[{"atl":[[65,0]],"id":39784543}],"con":true,"img":false}]}
{"op":"mcm","clk":"5353344897","pt":1646213378174,"mc":[{"id":"1.195453770","rc":[{"atl":[[1000,1.25]],"id":39784543}],"con":true,"img":false}]}
{"op":"mcm","clk":"5353345085","pt":1646213381964,"mc":[{"id":"1.195453770","rc":[{"atb":[[16,0]],"id":36500377},{"atb":[[14,0]],"id":36074638},{"atl":[[5.4,0]],"id":37127725}],"con":true,"img":false}]}
{"op":"mcm","clk":"5353345090","pt":1646213382068,"mc":[{"id":"1.195453770","rc":[{"atb":[[16.5,6.09]],"id":36500377},{"atb":[[16,3.89]],"id":36074638},{"atl":[[5,12.98]],"id":37127725}],"con":true,"img":false}]}
{"op":"mcm","clk":"5353345136","pt":1646213383078,"mc":[{"id":"1.195453770","rc":[{"atl":[[5.8,14.59]],"id":26051221}],"con":true,"img":false}]}
{"op":"mcm","clk":"5353345141","pt":1646213383183,"mc":[{"id":"1.195453770","rc":[{"atb":[[11,0]],"id":36500377},{"atl":[[5.8,10.42]],"id":26051221}],"con":true,"img":false}]}
{"op":"mcm","clk":"5353345597","pt":1646213393119,"mc":[{"id":"1.195453770","rc":[{"atl":[[6,15]],"id":26051221}],"con":true,"img":false}]}
{"op":"mcm","clk":"5353346068","pt":1646213401999,"mc":[{"id":"1.195453770","rc":[{"atl":[[70,2.05]],"id":39784543},{"spn":23.65,"spf":1.0,"id":39784543},{"atb":[[14,0]],"id":35801684},{"spn":18.91,"spf":1.0,"id":35801684},{"atl":[[23,5.68]],"id":28338255}],"con":true,"img":false}]}
{"op":"mcm","clk":"5353346076","pt":1646213402104,"mc":[{"id":"1.195453770","rc":[{"atl":[[65,2.72],[70,0.05],[100,4.72]],"id":39784543},{"atb":[[16.5,11.6]],"id":35801684},{"atl":[[20,5.38]],"id":28338255}],"con":true,"img":false}]}
{"op":"mcm","clk":"5353346086","pt":1646213402305,"mc":[{"id":"1.195453770","rc":[{"atl":[[4.4,14.71]],"id":42189401}],"con":true,"img":false}]}
{"op":"mcm","clk":"5353346322","pt":1646213405125,"mc":[{"id":"1.195453770","rc":[{"atb":[[1.03,2.87]],"id":39784543},{"atb":[[1.03,2.88]],"id":36500377},{"atb":[[1.03,2.87]],"id":35801684},{"atb":[[1.03,2.88]],"id":36074638},{"atb":[[1.02,3.71]],"id":42189401}],"con":true,"img":false}]}
{"op":"mcm","clk":"5353346333","pt":1646213405232,"mc":[{"id":"1.195453770","rc":[{"atb":[[1.02,3.55]],"id":37127725}],"con":true,"img":false}]}
{"op":"mcm","clk":"5353346350","pt":1646213405590,"mc":[{"id":"1.195453770","rc":[{"atb":[[1.03,0.14]],"id":39784543},{"atb":[[1.03,0.16]],"id":36500377},{"atb":[[1.03,0.15]],"id":35801684},{"atb":[[1.03,0.15]],"id":36074638},{"atb":[[1.02,0.98]],"id":42189401},{"atb":[[1.02,0.82]],"id":37127725}],"con":true,"img":false}]}
{"op":"mcm","clk":"5353346377","pt":1646213406008,"mc":[{"id":"1.195453770","rc":[{"atb":[[1.03,0]],"id":39784543},{"atb":[[1.03,0]],"id":36500377},{"atb":[[1.03,0]],"id":36074638},{"atb":[[1.02,0]],"id":42189401},{"atb":[[1.02,0]],"id":37127725}],"con":true,"img":false}]}
{"op":"mcm","clk":"5353346383","pt":1646213406114,"mc":[{"id":"1.195453770","rc":[{"atb":[[19,5.86]],"id":39784543},{"atb":[[17,2.46]],"id":36500377},{"atb":[[1.03,0]],"id":35801684},{"atb":[[17.5,0.15]],"id":36074638},{"atb":[[2.82,0.98]],"id":42189401},{"atb":[[3.35,0.82]],"id":37127725},{"atb":[[1.03,3.07]],"id":28338255},{"atb":[[1.02,3.47]],"id":26051221}],"con":true,"img":false}]}
{"op":"mcm","clk":"5353346392","pt":1646213406225,"mc":[{"id":"1.195453770","rc":[{"atb":[[18,0.15]],"id":35801684}],"con":true,"img":false}]}
{"op":"mcm","clk":"5353346421","pt":1646213406631,"mc":[{"id":"1.195453770","rc":[{"atb":[[1.02,0.75]],"id":26051221},{"atb":[[1.03,0.35]],"id":28338255}],"con":true,"img":false}]}
{"op":"mcm","clk":"5353346443","pt":1646213406934,"mc":[{"id":"1.195453770","rc":[{"atl":[[65,0]],"id":39784543}],"con":true,"img":false}]}
{"op":"mcm","clk":"5353346451","pt":1646213407043,"mc":[{"id":"1.195453770","rc":[{"atl":[[75,2.72]],"id":39784543},{"atb":[[2.72,0]],"id":42189401},{"atb":[[1.02,0]],"id":26051221},{"atb":[[1.03,0]],"id":28338255}],"con":true,"img":false}]}
{"op":"mcm","clk":"5353346459","pt":1646213407095,"mc":[{"id":"1.195453770","rc":[{"atb":[[7.8,8.94]],"id":28338255},{"atb":[[3.7,0.75]],"id":26051221}],"con":true,"img":false}]}
{"op":"mcm","clk":"5353346465","pt":1646213407304,"mc":[{"id":"1.195453770","rc":[{"atb":[[8.4,0],[1.02,2.25]],"id":28338255}],"con":true,"img":false}]}
{"op":"mcm","clk":"5353346473","pt":1646213407406,"mc":[{"id":"1.195453770","rc":[{"atl":[[75,4.72],[100,2.72]],"id":39784543}],"con":true,"img":false}]}
{"op":"mcm","clk":"5353346478","pt":1646213407513,"mc":[{"id":"1.195453770","rc":[{"atl":[[75,2.72],[95,2]],"id":39784543},{"atb":[[12,1.82],[12.5,8.94]],"id":36500377},{"atb":[[11.5,0],[14,1.54]],"id":36074638},{"atl":[[3.85,7.02],[4.2,0]],"id":42189401},{"atl":[[4.9,0],[4.5,0],[5.1,0],[6.2,3.85],[4.7,11.98]],"id":37127725},{"atb":[[1.02,0.45]],"id":28338255},{"atl":[[17.5,1.21],[18.5,1.31]],"id":28338255},{"atl":[[4.9,5.13],[5.6,0]],"id":26051221}],"con":true,"img":false}]}
{"op":"mcm","clk":"5353346486","pt":1646213407718,"mc":[{"id":"1.195453770","rc":[{"atl":[[75,4.72],[95,0]],"id":39784543},{"atb":[[1.02,0]],"id":28338255}],"con":true,"img":false}]}
{"op":"mcm","clk":"5353346491","pt":1646213407817,"mc":[{"id":"1.195453770","rc":[{"atb":[[8,0.45]],"id":28338255}],"con":true,"img":false}]}
{"op":"mcm","clk":"5353346503","pt":1646213408030,"mc":[{"id":"1.195453770","rc":[{"atl":[[3.9,0]],"id":42189401},{"atl":[[4.4,0]],"id":37127725},{"atl":[[5.5,0]],"id":26051221}],"con":true,"img":false}]}
{"op":"mcm","clk":"5353346513","pt":1646213408131,"mc":[{"id":"1.195453770","rc":[{"atl":[[3.8,1.32]],"id":42189401},{"atl":[[4.6,1.23]],"id":37127725},{"atl":[[4.8,1.3]],"id":26051221}],"con":true,"img":false}]}
{"op":"mcm","clk":"5353346536","pt":1646213408642,"mc":[{"id":"1.195453770","rc":[{"atb":[[3.4,4.2]],"id":26051221}],"con":true,"img":false}]}
{"op":"mcm","clk":"5353346678","pt":1646213411906,"mc":[{"id":"1.195453770","rc":[{"atl":[[5,0]],"id":37127725}],"con":true,"img":false}]}
{"op":"mcm","clk":"5353346689","pt":1646213412013,"mc":[{"id":"1.195453770","rc":[{"atl":[[5.5,12.98]],"id":37127725}],"con":true,"img":false}]}
{"op":"mcm","clk":"5353346704","pt":1646213412324,"mc":[{"id":"1.195453770","rc":[{"atl":[[4.6,0]],"id":37127725}],"con":true,"img":false}]}
{"op":"mcm","clk":"5353346707","pt":1646213412428,"mc":[{"id":"1.195453770","rc":[{"atl":[[1000,1.23]],"id":37127725}],"con":true,"img":false}]}
{"op":"mcm","clk":"5353346718","pt":1646213412637,"mc":[{"id":"1.195453770","rc":[{"atl":[[17.5,0],[17,1.25]],"id":28338255}],"con":true,"img":false}]}
{"op":"mcm","clk":"5353346733","pt":1646213412947,"mc":[{"id":"1.195453770","rc":[{"atl":[[1000,0]],"id":37127725}],"con":true,"img":false}]}
{"op":"mcm","clk":"5353346736","pt":1646213412997,"mc":[{"id":"1.195453770","rc":[{"atl":[[4.6,1.23]],"id":37127725}],"con":true,"img":false}]}
{"op":"mcm","clk":"5353346934","pt":1646213416411,"mc":[{"id":"1.195453770","rc":[{"atl":[[17,0.93]],"id":28338255},{"trd":[[17,17.29]],"ltp":17.0,"tv":17.29,"id":28338255}],"con":true,"img":false}]}
{"op":"mcm","clk":"5353346943","pt":1646213416522,"mc":[{"id":"1.195453770","rc":[{"atl":[[17,0],[18.5,2.44],[19.5,7.19],[21,0],[23,0]],"id":28338255}],"con":true,"img":false}]}
{"op":"mcm","clk":"5353346965","pt":1646213416935,"mc":[{"id":"1.195453770","rc":[{"atl":[[20,0]],"id":28338255},{"atl":[[6.2,0]],"id":26051221}],"con":true,"img":false}]}
{"op":"mcm","clk":"5353346970","pt":1646213417039,"mc":[{"id":"1.195453770","rc":[{"atl":[[23,5.38]],"id":28338255},{"atl":[[5.9,10.43]],"id":26051221}],"con":true,"img":false}]}
{"op":"mcm","clk":"5353346988","pt":1646213417449,"mc":[{"id":"1.195453770","rc":[{"atb":[[16.5,0]],"id":36074638},{"atb":[[3.4,0]],"id":26051221}],"con":true,"img":false}]}
{"op":"mcm","clk":"5353346994","pt":1646213417555,"mc":[{"id":"1.195453770","rc":[{"atb":[[11,5]],"id":36500377},{"atb":[[13,12.74]],"id":36074638},{"atl":[[3.95,21.88]],"id":42189401},{"atl":[[6.6,8.93]],"id":37127725},{"atl":[[5.1,12.2]],"id":26051221}],"con":true,"img":false}]}
{"op":"mcm","clk":"5353347012","pt":1646213417844,"mc":[{"id":"1.195453770","rc":[{"atb":[[10.5,0],[11.5,0],[9.8,0]],"id":36500377},{"atb":[[10.5,10.82],[9.4,8.57],[9.8,0]],"id":36074638},{"atl":[[4.8,0],[4.4,0],[4.6,0]],"id":42189401},{"atl":[[6.4,0],[5.8,0],[6,0]],"id":26051221},{"atl":[[18.5,1.31],[19,4.34]],"id":28338255}],"con":true,"img":false}]}
{"op":"mcm","clk":"5353347225","pt":1646213421848,"mc":[{"id":"1.195453770","rc":[{"atl":[[5.9,22.85]],"id":42189401}],"con":true,"img":false}]}
{"op":"mcm","clk":"5353347228","pt":1646213421953,"mc":[{"id":"1.195453770","rc":[{"atl":[[4.5,0]],"id":42189401}],"con":true,"img":false}]}
{"op":"mcm","clk":"5353347488","pt":1646213426534,"mc":[{"id":"1.195453770","rc":[{"atb":[[3.1,5.22]],"id":37127725}],"con":true,"img":false}]}
{"op":"mcm","clk":"5353347509","pt":1646213426946,"mc":[{"id":"1.195453770","rc":[{"atl":[[5.9,0]],"id":26051221}],"con":true,"img":false}]}
{"op":"mcm","clk":"5353347514","pt":1646213427049,"mc":[{"id":"1.195453770","rc":[{"atl":[[6.4,10.43]],"id":26051221}],"con":true,"img":false}]}
{"op":"mcm","clk":"5353347531","pt":1646213427567,"mc":[{"id":"1.195453770","rc":[{"atb":[[10,19.75]],"id":36500377},{"atb":[[12,6.82]],"id":36074638},{"atl":[[4.1,24.19]],"id":42189401},{"atl":[[7,12.5]],"id":37127725},{"atl":[[5.3,17.44]],"id":26051221}],"con":true,"img":false}]}
{"op":"mcm","clk":"5353347540","pt":1646213427723,"mc":[{"id":"1.195453770","rc":[{"atl":[[20,2.59]],"id":28338255}],"con":true,"img":false}]}
{"op":"mcm","clk":"5353347588","pt":1646213428972,"mc":[{"id":"1.195453770","rc":[{"atb":[[3.1,9.19]],"id":37127725}],"con":true,"img":false}]}
{"op":"mcm","clk":"5353347747","pt":1646213431928,"mc":[{"id":"1.195453770","rc":[{"atl":[[75,2]],"id":39784543}],"con":true,"img":false}]}
{"op":"mcm","clk":"5353347755","pt":1646213432032,"mc":[{"id":"1.195453770","rc":[{"atl":[[70,2.77],[100,4.72]],"id":39784543}],"con":true,"img":false}]}
{"op":"mcm","clk":"5353347760","pt":1646213432138,"mc":[{"id":"1.195453770","rc":[{"atl":[[75,0]],"id":39784543}],"con":true,"img":false}]}
{"op":"mcm","clk":"5353347767","pt":1646213432246,"mc":[{"id":"1.195453770","rc":[{"atl":[[100,2.72]],"id":39784543}],"con":true,"img":false}]}
{"op":"mcm","clk":"5353347783","pt":1646213432450,"mc":[{"id":"1.195453770","rc":[{"atl":[[70,4.77]],"id":39784543}],"con":true,"img":false}]}
{"op":"mcm","clk":"5353348066","pt":1646213437537,"mc":[{"id":"1.195453770","rc":[{"atb":[[9.6,14.53]],"id":36500377},{"atb":[[11,12.5]],"id":36074638},{"atl":[[4.3,55.59]],"id":42189401},{"atl":[[7.4,37.07]],"id":37127725},{"atl":[[5.5,27.78]],"id":26051221}],"con":true,"img":false}]}
{"op":"mcm","clk":"5353348075","pt":1646213437735,"mc":[{"id":"1.195453770","rc":[{"atl":[[22,3.52]],"id":28338255}],"con":true,"img":false}]}
{"op":"mcm","clk":"5353348554","pt":1646213447859,"mc":[{"id":"1.195453770","rc":[{"atl":[[24,14.04]],"id":28338255}],"con":true,"img":false}]}
{"op":"mcm","clk":"5353348611","pt":1646213449359,"mc":[{"id":"1.195453770","rc":[{"atl":[[4.3,37.88]],"id":42189401}],"con":true,"img":false}]}
{"op":"mcm","clk":"5353348616","pt":1646213449461,"mc":[{"id":"1.195453770","rc":[{"atl":[[4,17.71]],"id":42189401}],"con":true,"img":false}]}
{"op":"mcm","clk":"5353348694","pt":1646213450864,"mc":[{"id":"1.195453770","rc":[{"atl":[[190,15.2],[200,0]],"id":36074638},{"atb":[[2.48,13.51],[2.46,0]],"id":42189401},{"atb":[[3.3,46.72]],"id":26051221}],"con":true,"img":false}]}
{"op":"mcm","clk":"5353348706","pt":1646213451024,"mc":[{"id":"1.195453770","rc":[{"atb":[[21,0]],"id":39784543},{"atb":[[16.5,5.43]],"id":36500377},{"atb":[[16.5,10.94]],"id":35801684}],"con":true,"img":false}]}
{"op":"mcm","clk":"5353348720","pt":1646213451180,"mc":[{"id":"1.195453770","rc":[{"atb":[[22,0.49]],"id":39784543},{"atb":[[17.5,0.62]],"id":36500377},{"atb":[[17.5,0.62]],"id":35801684}],"con":true,"img":false}]}
{"op":"mcm","clk":"5353349040","pt":1646213456975,"mc":[{"id":"1.195453770","rc":[{"atl":[[70,2.05]],"id":39784543},{"atb":[[16,0]],"id":36074638}],"con":true,"img":false}]}
{"op":"mcm","clk":"5353349046","pt":1646213457078,"mc":[{"id":"1.195453770","rc":[{"atl":[[65,2.72],[70,0.05],[100,4.72]],"id":39784543},{"atb":[[14,5.43],[15.5,7.79]],"id":36074638}],"con":true,"img":false}]}
{"op":"mcm","clk":"5353349182","pt":1646213460190,"mc":[{"id":"1.195453770","rc":[{"atb":[[2.44,13.89],[2.48,0]],"id":42189401},{"atb":[[2.98,0],[2.94,0],[2.92,10.42]],"id":37127725},{"atl":[[4.9,0],[5.1,4.88]],"id":26051221},{"atb":[[6.8,3.45],[7.2,0]],"id":28338255}],"con":true,"img":false}]}
{"op":"mcm","clk":"5353349221","pt":1646213460871,"mc":[{"id":"1.195453770","rc":[{"atl":[[4.8,0]],"id":26051221}],"con":true,"img":false}]}
{"op":"mcm","clk":"5353349230","pt":1646213460976,"mc":[{"id":"1.195453770","rc":[{"atl":[[5,1.3]],"id":26051221}],"con":true,"img":false}]}
{"op":"mcm","clk":"5353349277","pt":1646213461858,"mc":[{"id":"1.195453770","rc":[{"atl":[[6.4,21.44]],"id":37127725}],"con":true,"img":false}]}
{"op":"mcm","clk":"5353349281","pt":1646213461960,"mc":[{"id":"1.195453770","rc":[{"atl":[[65,0]],"id":39784543},{"atl":[[7.4,19.53]],"id":37127725}],"con":true,"img":false}]}
{"op":"mcm","clk":"5353349294","pt":1646213462074,"mc":[{"id":"1.195453770","rc":[{"atl":[[75,2.72]],"id":39784543},{"spn":17.1,"spf":1.0,"id":36500377},{"spn":3.03,"spf":"NaN","id":42189401},{"spn":3.97,"spf":"NaN","id":37127725},{"spn":3.45,"spf":1.0,"id":26051221},{"spn":13.35,"spf":"NaN","id":28338255}],"con":true,"img":false}]}
{"op":"mcm","clk":"5353349297","pt":1646213462168,"mc":[{"id":"1.195453770","rc":[{"atl":[[75,4.72]],"id":39784543}],"con":true,"img":false}]}
{"op":"mcm","clk":"5353349306","pt":1646213462270,"mc":[{"id":"1.195453770","rc":[{"atl":[[100,2.72]],"id":39784543},{"atl":[[18.5,2.44],[19,3.24]],"id":28338255}],"con":true,"img":false}]}
{"op":"mcm","clk":"5353349704","pt":1646213470182,"mc":[{"id":"1.195453770","rc":[{"atb":[[2.4,109.18]],"id":42189401},{"atb":[[2.88,26.6]],"id":37127725},{"atl":[[5.3,11.63]],"id":26051221}],"con":true,"img":false}]}
{"op":"mcm","clk":"5353349814","pt":1646213472302,"mc":[{"id":"1.195453770","rc":[{"atb":[[6.4,9.26]],"id":28338255}],"con":true,"img":false}]}
{"op":"mcm","clk":"5353350183","pt":1646213480221,"mc":[{"id":"1.195453770","rc":[{"atb":[[2.34,0],[2.42,0],[2.38,0]],"id":42189401},{"atl":[[5.5,16.67]],"id":26051221}],"con":true,"img":false}]}
{"op":"mcm","clk":"5353350190","pt":1646213480278,"mc":[{"id":"1.195453770","rc":[{"atb":[[2.36,55.15]],"id":42189401},{"atb":[[2.84,40.76]],"id":37127725}],"con":true,"img":false}]}
{"op":"mcm","clk":"5353350277","pt":1646213481980,"mc":[{"id":"1.195453770","rc":[{"atl":[[23,0]],"id":28338255}],"con":true,"img":false}]}
{"op":"mcm","clk":"5353350280","pt":1646213482083,"mc":[{"id":"1.195453770","rc":[{"atl":[[21,5.38]],"id":28338255}],"con":true,"img":false}]}
{"op":"mcm","clk":"5353350289","pt":1646213482293,"mc":[{"id":"1.195453770","rc":[{"atb":[[6,15]],"id":28338255},{"atl":[[17,1.23],[18.5,1.31]],"id":28338255}],"con":true,"img":false}]}
{"op":"mcm","clk":"5353350474","pt":1646213486083,"mc":[{"id":"1.195453770","rc":[{"atb":[[8,0],[1.02,2.25]],"id":28338255}],"con":true,"img":false}]}
{"op":"mcm","clk":"5353350485","pt":1646213486289,"mc":[{"id":"1.195453770","rc":[{"atb":[[2.9,54.13],[2.86,0]],"id":37127725},{"atb":[[7.2,3.23],[1.02,0.45]],"id":28338255}],"con":true,"img":false}]}
{"op":"mcm","clk":"5353350494","pt":1646213486498,"mc":[{"id":"1.195453770","rc":[{"atb":[[1.02,0]],"id":28338255}],"con":true,"img":false}]}
{"op":"mcm","clk":"5353350501","pt":1646213486598,"mc":[{"id":"1.195453770","rc":[{"atb":[[8.4,0.45]],"id":28338255}],"con":true,"img":false}]}
{"op":"mcm","clk":"5353350511","pt":1646213486910,"mc":[{"id":"1.195453770","rc":[{"atl":[[75,2]],"id":39784543}],"con":true,"img":false}]}
{"op":"mcm","clk":"5353350520","pt":1646213487008,"mc":[{"id":"1.195453770","rc":[{"atl":[[70,2.77],[75,0],[100,4.72]],"id":39784543}],"con":true,"img":false}]}
{"op":"mcm","clk":"5353350670","pt":1646213490212,"mc":[{"id":"1.195453770","rc":[{"atb":[[2.32,179.54]],"id":42189401},{"atb":[[2.8,126.58]],"id":37127725},{"atl":[[5.7,26.6]],"id":26051221}],"con":true,"img":false}]}
{"op":"mcm","clk":"5353350754","pt":1646213492127,"mc":[{"id":"1.195453770","rc":[{"atl":[[70,4.77],[100,2.72]],"id":39784543}],"con":true,"img":false}]}
{"op":"mcm","clk":"5353350772","pt":1646213492493,"mc":[{"id":"1.195453770","rc":[{"atb":[[7.2,0]],"id":28338255}],"con":true,"img":false}]}
{"op":"mcm","clk":"5353350967","pt":1646213496318,"mc":[{"id":"1.195453770","rc":[{"atb":[[5.8,26.04]],"id":28338255},{"atl":[[18,2.9]],"id":28338255}],"con":true,"img":false}]}
{"op":"mcm","clk":"5353351004","pt":1646213497037,"mc":[{"id":"1.195453770","rc":[{"atl":[[18.5,0]],"id":28338255}],"con":true,"img":false}]}
{"op":"mcm","clk":"5353351009","pt":1646213497139,"mc":[{"id":"1.195453770","rc":[{"atl":[[17.5,1.31]],"id":28338255}],"con":true,"img":false}]}
{"op":"mcm","clk":"5353351354","pt":1646213504232,"mc":[{"id":"1.195453770","rc":[{"atb":[[2.44,0],[2.48,13.51]],"id":42189401},{"atl":[[24,8.68]],"id":28338255},{"atb":[[3.1,71.1],[3.15,0]],"id":26051221},{"atl":[[4.9,5.13],[5.1,0]],"id":26051221}],"con":true,"img":false}]}
{"op":"mcm","clk":"5353351394","pt":1646213504846,"mc":[{"id":"1.195453770","rc":[{"atl":[[5,0]],"id":26051221}],"con":true,"img":false}]}
{"op":"mcm","clk":"5353351406","pt":1646213504950,"mc":[{"id":"1.195453770","rc":[{"atl":[[4.8,1.3]],"id":26051221}],"con":true,"img":false}]}
{"op":"mcm","clk":"5353351437","pt":1646213505710,"mc":[{"id":"1.195453770","rc":[{"atb":[[2.44,13.89],[2.48,0]],"id":42189401},{"atb":[[2.98,10.1],[2.92,0]],"id":37127725},{"atb":[[3.1,61.58],[3.15,9.3]],"id":26051221},{"atl":[[4.9,0],[5.1,4.88]],"id":26051221}],"con":true,"img":false}]}
{"op":"mcm","clk":"5353351460","pt":1646213506149,"mc":[{"id":"1.195453770","rc":[{"atl":[[4.8,0]],"id":26051221}],"con":true,"img":false}]}
{"op":"mcm","clk":"5353351467","pt":1646213506254,"mc":[{"id":"1.195453770","rc":[{"atl":[[5,1.3]],"id":26051221}],"con":true,"img":false}]}
{"op":"mcm","clk":"5353351471","pt":1646213506346,"mc":[{"id":"1.195453770","rc":[{"atl":[[19,7.35]],"id":28338255}],"con":true,"img":false}]}
{"op":"mcm","clk":"5353351521","pt":1646213507642,"mc":[{"id":"1.195453770","rc":[{"atb":[[9.8,11.36]],"id":39784543},{"atl":[[95,2]],"id":39784543},{"atb":[[10,11.42],[11,0],[12,0],[9.6,0],[6.2,19.23],[7.6,3.03]],"id":36500377},{"atl":[[55,6.8]],"id":36500377},{"atb":[[5.6,39.57]],"id":35801684},{"atl":[[95,2]],"id":35801684},{"atb":[[12,1.82],[14,3.89],[3.95,33.9]],"id":36074638},{"atl":[[48,6.85]],"id":36074638},{"atb":[[2.6,126.79],[2.44,0],[2.48,13.51]],"id":42189401},{"atl":[[4.8,26.32]],"id":42189401},{"atb":[[1.88,113.64]],"id":37127725},{"atl":[[7.4,0],[12.5,10.44],[6.2,0],[6.6,0],[7,0]],"id":37127725},{"atb":[[6.8,12.71]],"id":28338255},{"atl":[[34,3.03],[22,0]],"id":28338255},{"atb":[[2.12,17.86],[2.98,0],[2.94,0],[3.05,50.17],[2.06,94.34],[3.15,0],[2.2,76.67]],"id":26051221},{"atl":[[4.9,5.13],[5.1,0],[6.2,19.23]],"id":26051221}],"con":true,"img":false}]}
{"op":"mcm","clk":"5353351529","pt":1646213507742,"mc":[{"id":"1.195453770","rc":[{"atl":[[3.85,0],[3.9,6.9]],"id":42189401}],"con":true,"img":false}]}
{"op":"mcm","clk":"5353351562","pt":1646213508414,"mc":[{"id":"1.195453770","rc":[{"atl":[[3.8,0]],"id":42189401}],"con":true,"img":false}]}
{"op":"mcm","clk":"5353351568","pt":1646213508518,"mc":[{"id":"1.195453770","rc":[{"atl":[[3.85,1.32]],"id":42189401}],"con":true,"img":false}]}
{"op":"mcm","clk":"5353351729","pt":1646213511855,"mc":[{"id":"1.195453770","rc":[{"atl":[[7.6,17.54]],"id":37127725}],"con":true,"img":false}]}
{"op":"mcm","clk":"5353351735","pt":1646213511910,"mc":[{"id":"1.195453770","rc":[{"atl":[[6.4,0]],"id":37127725},{"atl":[[21,0]],"id":28338255}],"con":true,"img":false}]}
{"op":"mcm","clk":"5353351742","pt":1646213512013,"mc":[{"id":"1.195453770","rc":[{"atl":[[23,5.38]],"id":28338255}],"con":true,"img":false}]}
{"op":"mcm","clk":"5353351973","pt":1646213516360,"mc":[{"id":"1.195453770","rc":[{"atl":[[20,6.49]],"id":28338255}],"con":true,"img":false}]}
{"op":"mcm","clk":"5353352036","pt":1646213517663,"mc":[{"id":"1.195453770","rc":[{"atb":[[7.2,8.06]],"id":36500377},{"atb":[[11,5],[13,8.57]],"id":36074638},{"atb":[[2.94,25.77]],"id":37127725},{"atl":[[13.5,4]],"id":37127725},{"atb":[[2.08,46.3],[2.2,60]],"id":26051221},{"atl":[[5.1,12.2]],"id":26051221}],"con":true,"img":false}]}
{"op":"mcm","clk":"5353352042","pt":1646213517768,"mc":[{"id":"1.195453770","rc":[{"atb":[[2.44,34.72]],"id":42189401},{"atl":[[4,34.38]],"id":42189401}],"con":true,"img":false}]}
{"op":"mcm","clk":"5353352054","pt":1646213517925,"mc":[{"id":"1.195453770","rc":[{"atb":[[9.4,24.14],[5.6,17.83]],"id":35801684},{"atl":[[65,2],[95,0]],"id":35801684}],"con":true,"img":false}]}
{"op":"mcm","clk":"5353352301","pt":1646213522957,"mc":[{"id":"1.195453770","rc":[{"atb":[[2.44,13.89],[2.48,0]],"id":42189401},{"atl":[[4.3,0],[3.25,3.46],[3.95,4.93],[4.1,0]],"id":42189401},{"atb":[[2.8,57.14],[2.84,0],[2.88,0]],"id":37127725},{"atb":[[2.34,4],[2.2,76.67]],"id":26051221},{"atl":[[4.9,0],[5.1,4.88]],"id":26051221},{"atl":[[14.5,3]],"id":28338255},{"spn":11.45,"spf":"NaN","id":28338255}],"con":true,"img":false}]}
{"op":"mcm","clk":"5353352326","pt":1646213523263,"mc":[{"id":"1.195453770","rc":[{"atl":[[3.2,3]],"id":42189401},{"atb":[[2.36,2]],"id":26051221},{"atl":[[14,3],[16.5,1.27],[17,0]],"id":28338255}],"con":true,"img":false}]}
{"op":"mcm","clk":"5353352358","pt":1646213523729,"mc":[{"id":"1.195453770","rc":[{"atb":[[2.66,0]],"id":42189401},{"atl":[[17.5,0]],"id":28338255}],"con":true,"img":false}]}
{"op":"mcm","clk":"5353352365","pt":1646213523834,"mc":[{"id":"1.195453770","rc":[{"atb":[[1.01,1.56]],"id":42189401},{"atl":[[13.5,1.31]],"id":28338255}],"con":true,"img":false}]}
{"op":"mcm","clk":"5353352467","pt":1646213525750,"mc":[{"id":"1.195453770","rc":[{"atb":[[2.64,6.15]],"id":42189401}],"con":true,"img":false}]}
{"op":"mcm","clk":"5353352541","pt":1646213526939,"mc":[{"id":"1.195453770","rc":[{"atl":[[6.4,0]],"id":26051221}],"con":true,"img":false}]}
{"op":"mcm","clk":"5353352546","pt":1646213527039,"mc":[{"id":"1.195453770","rc":[{"atl":[[6,10.43]],"id":26051221}],"con":true,"img":false}]}
{"op":"mcm","clk":"5353352576","pt":1646213527668,"mc":[{"id":"1.195453770","rc":[{"atb":[[6.8,12.93]],"id":36500377},{"atb":[[10,8.33]],"id":36074638},{"atb":[[2.9,93.6]],"id":37127725},{"atl":[[14.5,5.56]],"id":37127725}],"con":true,"img":false}]}
{"op":"mcm","clk":"5353352781","pt":1646213531349,"mc":[{"id":"1.195453770","rc":[{"atb":[[2.64,0]],"id":42189401}],"con":true,"img":false}]}
{"op":"mcm","clk":"5353352807","pt":1646213531968,"mc":[{"id":"1.195453770","rc":[{"atl":[[48,4.13]],"id":36074638}],"con":true,"img":false}]}
{"op":"mcm","clk":"5353352811","pt":1646213532071,"mc":[{"id":"1.195453770","rc":[{"atl":[[46,2.72]],"id":36074638}],"con":true,"img":false}]}
{"op":"mcm","clk":"5353352816","pt":1646213532175,"mc":[{"id":"1.195453770","rc":[{"atl":[[65,4.72],[48,2]],"id":36074638},{"atl":[[3.15,4]],"id":42189401},{"atb":[[2.38,3]],"id":26051221},{"atl":[[13.5,3.31]],"id":28338255}],"con":true,"img":false}]}
{"op":"mcm","clk":"5353352874","pt":1646213532949,"mc":[{"id":"1.195453770","rc":[{"atl":[[4.2,23.44]],"id":42189401},{"atb":[[2.16,43.1]],"id":26051221}],"con":true,"img":false}]}
{"op":"mcm","clk":"5353353131","pt":1646213537658,"mc":[{"id":"1.195453770","rc":[{"atb":[[6.4,23.15]],"id":36500377},{"atb":[[9.6,14.53]],"id":36074638},{"atb":[[2.86,67.2]],"id":37127725},{"atl":[[15.5,8.62]],"id":37127725}],"con":true,"img":false}]}
{"op":"mcm","clk":"5353353141","pt":1646213537866,"mc":[{"id":"1.195453770","rc":[{"atl":[[3.1,3]],"id":42189401},{"atb":[[2.4,4]],"id":26051221},{"atl":[[13,2]],"id":28338255}],"con":true,"img":false}]}
{"op":"mcm","clk":"5353353168","pt":1646213538281,"mc":[{"id":"1.195453770","rc":[{"atl":[[13.5,2]],"id":28338255}],"con":true,"img":false}]}
{"op":"mcm","clk":"5353353175","pt":1646213538384,"mc":[{"id":"1.195453770","rc":[{"atl":[[13,3.31]],"id":28338255}],"con":true,"img":false}]}
{"op":"mcm","clk":"5353353383","pt":1646213542166,"mc":[{"id":"1.195453770","rc":[{"atl":[[46,4.94]],"id":36074638}],"con":true,"img":false}]}
{"op":"mcm","clk":"5353353388","pt":1646213542272,"mc":[{"id":"1.195453770","rc":[{"atl":[[44,2],[48,0],[65,2.72]],"id":36074638}],"con":true,"img":false}]}
{"op":"mcm","clk":"5353353395","pt":1646213542374,"mc":[{"id":"1.195453770","rc":[{"atl":[[1000,0]],"id":36074638}],"con":true,"img":false}]}
{"op":"mcm","clk":"5353353401","pt":1646213542476,"mc":[{"id":"1.195453770","rc":[{"atl":[[44,3.23]],"id":36074638}],"con":true,"img":false}]}
{"op":"mcm","clk":"5353353420","pt":1646213542990,"mc":[{"id":"1.195453770","rc":[{"atl":[[4.4,36.76]],"id":42189401},{"atb":[[2.12,66.96]],"id":26051221}],"con":true,"img":false}]}
{"op":"mcm","clk":"5353353434","pt":1646213543253,"mc":[{"id":"1.195453770","rc":[{"atl":[[3.85,8.34],[3.9,0]],"id":42189401}],"con":true,"img":false}]}
{"op":"mcm","clk":"5353353633","pt":1646213546973,"mc":[{"id":"1.195453770","rc":[{"atl":[[100,0]],"id":39784543}],"con":true,"img":false}]}
{"op":"mcm","clk":"5353353639","pt":1646213547079,"mc":[{"id":"1.195453770","rc":[{"atl":[[90,2.72]],"id":39784543}],"con":true,"img":false}]}
{"op":"mcm","clk":"5353353887","pt":1646213551887,"mc":[{"id":"1.195453770","rc":[{"atl":[[5.9,0],[4.7,30.26]],"id":42189401}],"con":true,"img":false}]}
{"op":"mcm","clk":"5353353955","pt":1646213552974,"mc":[{"id":"1.195453770","rc":[{"atb":[[2.08,115.74]],"id":26051221}],"con":true,"img":false}]}
{"op":"mcm","clk":"5353354185","pt":1646213557182,"mc":[{"id":"1.195453770","rc":[{"atl":[[1000,2.92]],"id":39784543},{"atl":[[1000,2.95]],"id":36500377},{"atl":[[1000,1.66]],"id":35801684}],"con":true,"img":false}]}
{"op":"mcm","clk":"5353354198","pt":1646213557386,"mc":[{"id":"1.195453770","rc":[{"atl":[[1000,1.38]],"id":39784543},{"atl":[[1000,1.45]],"id":36500377}],"con":true,"img":false}]}
{"op":"mcm","clk":"5353354203","pt":1646213557488,"mc":[{"id":"1.195453770","rc":[{"atl":[[1000,0.17]],"id":35801684}],"con":true,"img":false}]}
{"op":"mcm","clk":"5353354210","pt":1646213557593,"mc":[{"id":"1.195453770","rc":[{"atl":[[1000,1.28]],"id":36500377}],"con":true,"img":false}]}
{"op":"mcm","clk":"5353354217","pt":1646213557695,"mc":[{"id":"1.195453770","rc":[{"atl":[[50,0.16]],"id":36500377}],"con":true,"img":false}]}
{"op":"mcm","clk":"5353354224","pt":1646213557798,"mc":[{"id":"1.195453770","rc":[{"atl":[[3.1,0.91]],"id":42189401},{"trd":[[3.1,4.18]],"ltp":3.1,"tv":4.18,"id":42189401},{"atl":[[13,0.57]],"id":28338255},{"trd":[[13,5.48]],"ltp":13.0,"tv":5.48,"id":28338255}],"con":true,"img":false}]}
{"op":"mcm","clk":"5353354231","pt":1646213557903,"mc":[{"id":"1.195453770","rc":[{"atl":[[1000,1.25]],"id":39784543}],"con":true,"img":false}]}
{"op":"mcm","clk":"5353354236","pt":1646213558007,"mc":[{"id":"1.195453770","rc":[{"atl":[[65,0.12]],"id":39784543},{"atl":[[3.1,0],[3.25,0.46],[3.2,0],[3.15,0]],"id":42189401},{"atb":[[8.2,5.68]],"id":28338255},{"atl":[[13,0],[13.5,0],[14,0],[14.5,0]],"id":28338255}],"con":true,"img":false}]}
{"op":"mcm","clk":"5353354245","pt":1646213558213,"mc":[{"id":"1.195453770","rc":[{"atl":[[1000,0]],"id":35801684},{"atb":[[8.2,6.97]],"id":28338255}],"con":true,"img":false}]}
{"op":"mcm","clk":"5353354249","pt":1646213558267,"mc":[{"id":"1.195453770","rc":[{"atl":[[48,0.17]],"id":35801684}],"con":true,"img":false}]}
{"op":"mcm","clk":"5353354447","pt":1646213561804,"mc":[{"id":"1.195453770","rc":[{"atb":[[1.01,3.56]],"id":42189401}],"con":true,"img":false}]}
{"op":"mcm","clk":"5353354455","pt":1646213561907,"mc":[{"id":"1.195453770","rc":[{"atl":[[80,0]],"id":35801684},{"atb":[[1.01,5.55]],"id":42189401}],"con":true,"img":false}]}
{"op":"mcm","clk":"5353354463","pt":1646213562043,"mc":[{"id":"1.195453770","rc":[{"atl":[[60,2.72]],"id":35801684}],"con":true,"img":false}]}
{"op":"mcm","clk":"5353354469","pt":1646213562114,"mc":[{"id":"1.195453770","rc":[{"atb":[[1.01,3.56]],"id":42189401}],"con":true,"img":false}]}
{"op":"mcm","clk":"5353354473","pt":1646213562219,"mc":[{"id":"1.195453770","rc":[{"atb":[[2.72,1.99]],"id":42189401}],"con":true,"img":false}]}
{"op":"mcm","clk":"5353354575","pt":1646213564190,"mc":[{"id":"1.195453770","rc":[{"atb":[[1.01,2]],"id":37127725}],"con":true,"img":false}]}
{"op":"mcm","clk":"5353354586","pt":1646213564398,"mc":[{"id":"1.195453770","rc":[{"atb":[[1.01,3.99]],"id":37127725}],"con":true,"img":false}]}
{"op":"mcm","clk":"5353354612","pt":1646213564710,"mc":[{"id":"1.195453770","rc":[{"atb":[[1.01,2]],"id":37127725}],"con":true,"img":false}]}
{"op":"mcm","clk":"5353354618","pt":1646213564811,"mc":[{"id":"1.195453770","rc":[{"atb":[[3.3,1.99]],"id":37127725}],"con":true,"img":false}]}
{"op":"mcm","clk":"5353354672","pt":1646213565698,"mc":[{"id":"1.195453770","rc":[{"atb":[[6.4,0]],"id":39784543}],"con":true,"img":false}]}
{"op":"mcm","clk":"5353354681","pt":1646213565802,"mc":[{"id":"1.195453770","rc":[{"atb":[[1.01,2]],"id":26051221}],"con":true,"img":false}]}
{"op":"mcm","clk":"5353354689","pt":1646213565903,"mc":[{"id":"1.195453770","rc":[{"atb":[[3.25,0]],"id":37127725}],"con":true,"img":false}]}
{"op":"mcm","clk":"5353354704","pt":1646213566108,"mc":[{"id":"1.195453770","rc":[{"atb":[[1.01,3.99]],"id":26051221}],"con":true,"img":false}]}
{"op":"mcm","clk":"5353354717","pt":1646213566419,"mc":[{"id":"1.195453770","rc":[{"atb":[[1.01,2]],"id":26051221}],"con":true,"img":false}]}
{"op":"mcm","clk":"5353354727","pt":1646213566468,"mc":[{"id":"1.195453770","rc":[{"atb":[[1.02,1.99]],"id":26051221}],"con":true,"img":false}]}
{"op":"mcm","clk":"5353354782","pt":1646213567298,"mc":[{"id":"1.195453770","rc":[{"atb":[[3.35,3.32]],"id":37127725},{"atb":[[1.01,3.68]],"id":28338255}],"con":true,"img":false}]}
{"op":"mcm","clk":"5353354796","pt":1646213567504,"mc":[{"id":"1.195453770","rc":[{"atb":[[1.01,5.67]],"id":28338255}],"con":true,"img":false}]}
{"op":"mcm","clk":"5353354811","pt":1646213567710,"mc":[{"id":"1.195453770","rc":[{"atb":[[1.01,3.68]],"id":28338255}],"con":true,"img":false}]}
{"op":"mcm","clk":"5353354817","pt":1646213567815,"mc":[{"id":"1.195453770","rc":[{"atb":[[8.4,2.44]],"id":28338255}],"con":true,"img":false}]}
{"op":"mcm","clk":"5353354862","pt":1646213568587,"mc":[{"id":"1.195453770","rc":[{"atb":[[3.3,0]],"id":37127725}],"con":true,"img":false}]}
{"op":"mcm","clk":"5353354866","pt":1646213568692,"mc":[{"id":"1.195453770","rc":[{"atb":[[3.4,1.99]],"id":37127725},{"atb":[[8.2,4.47]],"id":28338255}],"con":true,"img":false}]}
{"op":"mcm","clk":"5353354891","pt":1646213569213,"mc":[{"id":"1.195453770","rc":[{"atb":[[8.2,3.18]],"id":28338255}],"con":true,"img":false}]}
{"op":"mcm","clk":"5353354899","pt":1646213569318,"mc":[{"id":"1.195453770","rc":[{"atb":[[1.02,1.29]],"id":28338255}],"con":true,"img":false}]}
{"op":"mcm","clk":"5353354911","pt":1646213569525,"mc":[{"id":"1.195453770","rc":[{"atb":[[8.2,2]],"id":28338255}],"con":true,"img":false}]}
{"op":"mcm","clk":"5353354917","pt":1646213569577,"mc":[{"id":"1.195453770","rc":[{"atb":[[8,1.18]],"id":28338255}],"con":true,"img":false}]}
{"op":"mcm","clk":"5353354934","pt":1646213569991,"mc":[{"id":"1.195453770","rc":[{"atb":[[3.35,0.82]],"id":37127725},{"atb":[[8.6,2.5]],"id":28338255}],"con":true,"img":false}]}
{"op":"mcm","clk":"5353354941","pt":1646213570097,"mc":[{"id":"1.195453770","rc":[{"atb":[[8.2,0],[8.6,4.5]],"id":28338255}],"con":true,"img":false}]}
{"op":"mcm","clk":"5353354948","pt":1646213570200,"mc":[{"id":"1.195453770","rc":[{"atb":[[3.1,10.49]],"id":37127725}],"con":true,"img":false}]}
{"op":"mcm","clk":"5353354955","pt":1646213570306,"mc":[{"id":"1.195453770","rc":[{"atb":[[1.02,0]],"id":28338255}],"con":true,"img":false}]}
{"op":"mcm","clk":"5353354962","pt":1646213570409,"mc":[{"id":"1.195453770","rc":[{"atb":[[7.8,10.24]],"id":28338255}],"con":true,"img":false}]}
{"op":"mcm","clk":"5353354981","pt":1646213570719,"mc":[{"id":"1.195453770","rc":[{"atb":[[8,1.13]],"id":28338255}],"con":true,"img":false}]}
{"op":"mcm","clk":"5353355008","pt":1646213571289,"mc":[{"id":"1.195453770","rc":[{"atb":[[8,0]],"id":28338255}],"con":true,"img":false}]}
{"op":"mcm","clk":"5353355012","pt":1646213571393,"mc":[{"id":"1.195453770","rc":[{"atb":[[8.8,1.13]],"id":28338255}],"con":true,"img":false}]}
{"op":"mcm","clk":"5353355024","pt":1646213571601,"mc":[{"id":"1.195453770","rc":[{"atb":[[8.4,0.45]],"id":28338255}],"con":true,"img":false}]}
{"op":"mcm","clk":"5353355031","pt":1646213571704,"mc":[{"id":"1.195453770","rc":[{"atb":[[8.8,3.12]],"id":28338255}],"con":true,"img":false}]}
{"op":"mcm","clk":"5353355039","pt":1646213571909,"mc":[{"id":"1.195453770","rc":[{"atl":[[46,2.22]],"id":36074638}],"con":true,"img":false}]}
{"op":"mcm","clk":"5353355043","pt":1646213572012,"mc":[{"id":"1.195453770","rc":[{"atl":[[42,2.72]],"id":36074638}],"con":true,"img":false}]}
{"op":"mcm","clk":"5353355064","pt":1646213572428,"mc":[{"id":"1.195453770","rc":[{"atl":[[44,2]],"id":36074638}],"con":true,"img":false}]}
{"op":"mcm","clk":"5353355071","pt":1646213572532,"mc":[{"id":"1.195453770","rc":[{"atl":[[40,1.23]],"id":36074638}],"con":true,"img":false}]}
{"op":"mcm","clk":"5353355083","pt":1646213572690,"mc":[{"id":"1.195453770","rc":[{"atb":[[8.6,2]],"id":28338255}],"con":true,"img":false}]}
{"op":"mcm","clk":"5353355100","pt":1646213573100,"mc":[{"id":"1.195453770","rc":[{"atb":[[8.8,1.99]],"id":28338255}],"con":true,"img":false}]}
{"op":"mcm","clk":"5353355107","pt":1646213573202,"mc":[{"id":"1.195453770","rc":[{"atb":[[8,1.13]],"id":28338255}],"con":true,"img":false}]}
{"op":"mcm","clk":"5353355138","pt":1646213573928,"mc":[{"id":"1.195453770","rc":[{"atb":[[2.64,4.58]],"id":42189401}],"con":true,"img":false}]}
{"op":"mcm","clk":"5353355158","pt":1646213574188,"mc":[{"id":"1.195453770","rc":[{"atb":[[9,2.5]],"id":28338255}],"con":true,"img":false}]}
{"op":"mcm","clk":"5353355196","pt":1646213574999,"mc":[{"id":"1.195453770","rc":[{"atb":[[8.8,0]],"id":28338255}],"con":true,"img":false}]}
{"op":"mcm","clk":"5353355200","pt":1646213575102,"mc":[{"id":"1.195453770","rc":[{"atb":[[9.2,1.99]],"id":28338255}],"con":true,"img":false}]}
{"op":"mcm","clk":"5353355205","pt":1646213575205,"mc":[{"id":"1.195453770","rc":[{"atb":[[9.2,3.99]],"id":28338255}],"con":true,"img":false}]}
{"op":"mcm","clk":"5353355210","pt":1646213575310,"mc":[{"id":"1.195453770","rc":[{"atb":[[8.6,0]],"id":28338255}],"con":true,"img":false}]}
{"op":"mcm","clk":"5353355219","pt":1646213575415,"mc":[{"id":"1.195453770","rc":[{"atb":[[9.2,1.99]],"id":28338255}],"con":true,"img":false}]}
{"op":"mcm","clk":"5353355227","pt":1646213575520,"mc":[{"id":"1.195453770","rc":[{"atb":[[9.2,3.99]],"id":28338255}],"con":true,"img":false}]}
{"op":"mcm","clk":"5353355247","pt":1646213575830,"mc":[{"id":"1.195453770","rc":[{"atb":[[9,0]],"id":28338255}],"con":true,"img":false}]}
{"op":"mcm","clk":"5353355339","pt":1646213577456,"mc":[{"id":"1.195453770","rc":[{"atb":[[11.5,0],[14,3.85],[16.5,0],[19,0.14]],"id":39784543},{"atl":[[140,0],[290,0],[190,0],[240,1]],"id":39784543},{"atb":[[9,0],[10,0],[12.5,0],[15,0]],"id":36500377},{"atl":[[150,0],[200,0],[250,0],[100,0]],"id":36500377},{"atb":[[11,0],[13.5,0],[9.4,11.9],[16,0]],"id":35801684},{"atl":[[160,0],[210,1],[260,0],[110,0]],"id":35801684},{"atb":[[10.5,0],[13,0],[15.5,0.7],[18,0]],"id":36074638},{"atl":[[130,0],[180,0],[230,0],[280,0]],"id":36074638},{"atb":[[2.5,0],[2.3,0],[2.6,62.5],[2.4,35.71]],"id":42189401},{"atl":[[8,0],[9,0],[6,0],[7,0]],"id":42189401},{"atb":[[2.8,0],[3,0],[2.9,39.47],[2.7,0]],"id":37127725},{"atl":[[12,0],[7.8,0],[9.8,0],[8.8,0]],"id":37127725},{"atb":[[4,0],[4.5,0],[5,0],[5.5,0]],"id":28338255},{"atl":[[19.5,0],[24,0],[29,0]],"id":28338255},{"atb":[[2.82,0],[3.3,2],[3.05,0],[2.92,0]],"id":26051221},{"atl":[[9.2,0],[10.5,0],[8.2,0],[13,0]],"id":26051221}],"con":true,"img":false}]}
{"op":"mcm","clk":"5353355490","pt":1646213580416,"mc":[{"id":"1.195453770","rc":[{"atb":[[1.03,3.09]],"id":42189401},{"atb":[[1.02,3.03]],"id":37127725},{"atb":[[1.02,4.99]],"id":26051221},{"atb":[[1.04,2.86]],"id":28338255}],"con":true,"img":false}]}
{"op":"mcm","clk":"5353355510","pt":1646213580726,"mc":[{"id":"1.195453770","rc":[{"atb":[[20,0]],"id":39784543},{"atb":[[17,0]],"id":35801684},{"atb":[[18.5,0]],"id":36074638}],"con":true,"img":false}]}
{"op":"mcm","clk":"5353355520","pt":1646213580831,"mc":[{"id":"1.195453770","rc":[{"atb":[[1.01,1.6]],"id":39784543},{"atb":[[1.01,1.6]],"id":35801684},{"atb":[[14.5,1.62]],"id":36074638},{"atb":[[1.03,0.36]],"id":42189401},{"atb":[[1.04,0.13]],"id":28338255},{"atb":[[1.02,2.27]],"id":26051221}],"con":true,"img":false}]}
{"op":"mcm","clk":"5353355525","pt":1646213580937,"mc":[{"id":"1.195453770","rc":[{"atb":[[1.02,0.31]],"id":37127725}],"con":true,"img":false}]}
{"op":"mcm","clk":"5353355541","pt":1646213581150,"mc":[{"id":"1.195453770","rc":[{"atb":[[11.5,9.59],[14,11.6],[16.5,6.5],[19,5.74]],"id":39784543},{"atl":[[140,0.97],[290,0.69],[190,0.71],[240,1.84]],"id":39784543},{"atb":[[9,12.6],[10,11.19],[12.5,8.76],[15,7.19]],"id":36500377},{"atl":[[150,0.9],[200,1.01],[250,0.81],[100,1.36]],"id":36500377},{"atb":[[11,10.07],[13.5,8.06],[9.4,23.9],[16,6.71]],"id":35801684},{"atl":[[160,0.85],[210,1.97],[260,0.77],[110,1.23]],"id":35801684},{"atb":[[10.5,10.61],[13,8.39],[15.5,7.64],[18,5.92]],"id":36074638},{"atl":[[130,1.04],[180,0.75],[230,0.88],[280,0.72]],"id":36074638},{"atb":[[2.5,67.19],[2.3,77.52],[2.6,125.48],[2.4,107.69]],"id":42189401},{"atl":[[8,28.9],[9,25.28],[6,26.97],[7,22.47]],"id":42189401},{"atb":[[2.8,55.99],[3,50.39],[2.9,92.51],[2.7,59.28]],"id":37127725},{"atl":[[12,18.38],[7.8,19.83],[9.8,22.98],[8.8,17.29]],"id":37127725},{"atb":[[4,45.39],[4.5,38.9],[5,34.04],[5.5,30.26]],"id":28338255},{"atl":[[17,6.65],[19.5,5.76],[24,6.94],[29,5.7]],"id":28338255},{"atb":[[2.82,55.37],[3.3,45.81],[3.05,49.16],[2.92,52.49]],"id":26051221},{"atl":[[9.2,16.44],[10.5,21.29],[8.2,18.73],[13,16.85]],"id":26051221}],"con":true,"img":false}]}
{"op":"mcm","clk":"5353355554","pt":1646213581306,"mc":[{"id":"1.195453770","rc":[{"atb":[[1.03,0]],"id":42189401},{"atb":[[1.02,1.99]],"id":26051221}],"con":true,"img":false}]}
{"op":"mcm","clk":"5353355559","pt":1646213581412,"mc":[{"id":"1.195453770","rc":[{"atl":[[1000,0]],"id":39784543},{"atb":[[2.94,0.36]],"id":42189401},{"atb":[[1.02,0]],"id":37127725},{"atb":[[3.8,0.28]],"id":26051221},{"atb":[[1.04,0]],"id":28338255}],"con":true,"img":false}]}
{"op":"mcm","clk":"5353355565","pt":1646213581520,"mc":[{"id":"1.195453770","rc":[{"atl":[[65,1.38]],"id":39784543},{"atb":[[3.45,0.31]],"id":37127725},{"atb":[[8,1.26]],"id":28338255}],"con":true,"img":false}]}
{"op":"mcm","clk":"5353355580","pt":1646213581834,"mc":[{"id":"1.195453770","rc":[{"atb":[[2.64,5.78]],"id":42189401},{"atb":[[3.4,1.25]],"id":26051221}],"con":true,"img":false}]}
{"op":"mcm","clk":"5353355589","pt":1646213582041,"mc":[{"id":"1.195453770","rc":[{"atb":[[3.55,0]],"id":26051221}],"con":true,"img":false}]}
{"op":"mcm","clk":"5353355621","pt":1646213582719,"mc":[{"id":"1.195453770","rc":[{"atb":[[3.45,0]],"id":26051221}],"con":true,"img":false}]}
{"op":"mcm","clk":"5353355625","pt":1646213582824,"mc":[{"id":"1.195453770","rc":[{"atb":[[3.4,2.8]],"id":26051221}],"con":true,"img":false}]}
{"op":"mcm","clk":"5353355637","pt":1646213583031,"mc":[{"id":"1.195453770","rc":[{"atl":[[3.9,6.78]],"id":42189401},{"spn":3.09,"spf":"NaN","id":42189401},{"spn":4.02,"spf":"NaN","id":37127725},{"spn":3.42,"spf":1.0,"id":26051221},{"spn":12.85,"spf":"NaN","id":28338255}],"con":true,"img":false}]}
{"op":"mcm","clk":"5353355641","pt":1646213583135,"mc":[{"id":"1.195453770","rc":[{"atl":[[3.85,1.32]],"id":42189401}],"con":true,"img":false}]}
{"op":"mcm","clk":"5353355838","pt":1646213587310,"mc":[{"id":"1.195453770","rc":[{"atb":[[1.03,1.66]],"id":39784543},{"atb":[[1.02,1.66]],"id":36500377},{"atb":[[1.02,1.66]],"id":35801684},{"atb":[[1.02,1.66]],"id":36074638}],"con":true,"img":false}]}
{"op":"mcm","clk":"5353355851","pt":1646213587630,"mc":[{"id":"1.195453770","rc":[{"atb":[[1.03,0.31]],"id":39784543},{"atb":[[1.02,0.46]],"id":36500377},{"atb":[[1.02,0.41]],"id":35801684},{"atb":[[1.02,0.41]],"id":36074638}],"con":true,"img":false}]}
{"op":"mcm","clk":"5353355857","pt":1646213587838,"mc":[{"id":"1.195453770","rc":[{"atb":[[1.03,0]],"id":39784543}],"con":true,"img":false}]}
{"op":"mcm","clk":"5353355862","pt":1646213587942,"mc":[{"id":"1.195453770","rc":[{"atb":[[26,0.31]],"id":39784543}],"con":true,"img":false}]}
{"op":"mcm","clk":"5353355867","pt":1646213588047,"mc":[{"id":"1.195453770","rc":[{"atb":[[23,0],[25,2.15]],"id":39784543}],"con":true,"img":false}]}
{"op":"mcm","clk":"5353355872","pt":1646213588150,"mc":[{"id":"1.195453770","rc":[{"atb":[[24,3.66],[25,0.15]],"id":39784543},{"atb":[[1.02,0]],"id":36500377}],"con":true,"img":false}]}
{"op":"mcm","clk":"5353355878","pt":1646213588256,"mc":[{"id":"1.195453770","rc":[{"atb":[[22,2.49],[24,1.66]],"id":39784543},{"atb":[[18,0.46]],"id":36500377},{"atl":[[3.85,8.22],[3.9,0]],"id":42189401}],"con":true,"img":false}]}
{"op":"mcm","clk":"5353355886","pt":1646213588416,"mc":[{"id":"1.195453770","rc":[{"atb":[[1.02,0]],"id":36074638}],"con":true,"img":false}]}
{"op":"mcm","clk":"5353355890","pt":1646213588515,"mc":[{"id":"1.195453770","rc":[{"atb":[[20,0.41]],"id":36074638}],"con":true,"img":false}]}
{"op":"mcm","clk":"5353355899","pt":1646213588722,"mc":[{"id":"1.195453770","rc":[{"atb":[[1.02,0]],"id":35801684}],"con":true,"img":false}]}
{"op":"mcm","clk":"5353355905","pt":1646213588826,"mc":[{"id":"1.195453770","rc":[{"atb":[[20,0.41]],"id":35801684}],"con":true,"img":false}]}
{"op":"mcm","clk":"5353355908","pt":1646213588929,"mc":[{"id":"1.195453770","rc":[{"atb":[[17,0.38]],"id":36500377},{"atb":[[19.5,2.19]],"id":35801684}],"con":true,"img":false}]}
{"op":"mcm","clk":"5353355914","pt":1646213589040,"mc":[{"id":"1.195453770","rc":[{"atb":[[18,0],[1.02,1.66]],"id":36500377},{"atb":[[18.5,0],[19.5,0.19],[19,4.08]],"id":35801684}],"con":true,"img":false}]}
{"op":"mcm","clk":"5353355919","pt":1646213589141,"mc":[{"id":"1.195453770","rc":[{"atl":[[95,0]],"id":39784543},{"atl":[[60,4.72],[65,0]],"id":35801684}],"con":true,"img":false}]}
{"op":"mcm","clk":"5353355924","pt":1646213589248,"mc":[{"id":"1.195453770","rc":[{"atl":[[90,4.72]],"id":39784543},{"atb":[[1.02,0.46]],"id":36500377}],"con":true,"img":false}]}
{"op":"mcm","clk":"5353355928","pt":1646213589354,"mc":[{"id":"1.195453770","rc":[{"atb":[[1.02,0]],"id":36500377}],"con":true,"img":false}]}
{"op":"mcm","clk":"5353355933","pt":1646213589458,"mc":[{"id":"1.195453770","rc":[{"atb":[[17.5,1.08]],"id":36500377}],"con":true,"img":false}]}
{"op":"mcm","clk":"5353355990","pt":1646213590707,"mc":[{"id":"1.195453770","rc":[{"atb":[[18,2.08]],"id":36500377}],"con":true,"img":false}]}
{"op":"mcm","clk":"5353356008","pt":1646213591121,"mc":[{"id":"1.195453770","rc":[{"atb":[[17.5,0.62],[1.02,1.66]],"id":36500377}],"con":true,"img":false}]}
{"op":"mcm","clk":"5353356013","pt":1646213591224,"mc":[{"id":"1.195453770","rc":[{"atb":[[1.02,0.45]],"id":36500377}],"con":true,"img":false}]}
{"op":"mcm","clk":"5353356019","pt":1646213591431,"mc":[{"id":"1.195453770","rc":[{"atb":[[1.02,0]],"id":36500377}],"con":true,"img":false}]}
{"op":"mcm","clk":"5353356025","pt":1646213591535,"mc":[{"id":"1.195453770","rc":[{"atb":[[18.5,0.45]],"id":36500377}],"con":true,"img":false}]}
{"op":"mcm","clk":"5353356090","pt":1646213593350,"mc":[{"id":"1.195453770","rc":[{"atb":[[22,0.49],[25,2.15]],"id":39784543}],"con":true,"img":false}]}
{"op":"mcm","clk":"5353356095","pt":1646213593454,"mc":[{"id":"1.195453770","rc":[{"atb":[[24,3.66],[25,0.15]],"id":39784543}],"con":true,"img":false}]}
{"op":"mcm","clk":"5353356103","pt":1646213593558,"mc":[{"id":"1.195453770","rc":[{"atb":[[22,2.49],[24,1.66]],"id":39784543}],"con":true,"img":false}]}
{"op":"mcm","clk":"5353356109","pt":1646213593661,"mc":[{"id":"1.195453770","rc":[{"atb":[[25,2.15]],"id":39784543}],"con":true,"img":false}]}
{"op":"mcm","clk":"5353356117","pt":1646213593713,"mc":[{"id":"1.195453770","rc":[{"atb":[[22,0.49],[24,3.66]],"id":39784543}],"con":true,"img":false}]}
{"op":"mcm","clk":"5353356122","pt":1646213593921,"mc":[{"id":"1.195453770","rc":[{"atb":[[25,0.15]],"id":39784543}],"con":true,"img":false}]}
{"op":"mcm","clk":"5353357232","pt":1646213617402,"mc":[{"id":"1.195453770","rc":[{"atb":[[1.01,5.35]],"id":28338255}],"con":true,"img":false}]}
{"op":"mcm","clk":"5353357245","pt":1646213617557,"mc":[{"id":"1.195453770","rc":[{"atb":[[1.01,4.56]],"id":28338255}],"con":true,"img":false}]}
{"op":"mcm","clk":"5353357256","pt":1646213617763,"mc":[{"id":"1.195453770","rc":[{"atb":[[1.01,3.68]],"id":28338255}],"con":true,"img":false}]}
{"op":"mcm","clk":"5353357261","pt":1646213617866,"mc":[{"id":"1.195453770","rc":[{"atb":[[9.4,0.88]],"id":28338255}],"con":true,"img":false}]}
{"op":"mcm","clk":"5353357280","pt":1646213618177,"mc":[{"id":"1.195453770","rc":[{"atb":[[8,1.2]],"id":28338255}],"con":true,"img":false}]}
{"op":"mcm","clk":"5353357318","pt":1646213618811,"mc":[{"id":"1.195453770","rc":[{"atb":[[8,0.13]],"id":28338255}],"con":true,"img":false}]}
{"op":"mcm","clk":"5353357327","pt":1646213618910,"mc":[{"id":"1.195453770","rc":[{"atb":[[9.4,1.95]],"id":28338255}],"con":true,"img":false}]}
{"op":"mcm","clk":"5353357355","pt":1646213619378,"mc":[{"id":"1.195453770","rc":[{"atb":[[9.4,0.88]],"id":28338255}],"con":true,"img":false}]}
{"op":"mcm","clk":"5353357362","pt":1646213619491,"mc":[{"id":"1.195453770","rc":[{"atb":[[8,1.2]],"id":28338255}],"con":true,"img":false}]}
{"op":"mcm","clk":"5353357367","pt":1646213619588,"mc":[{"id":"1.195453770","rc":[{"atb":[[9.6,2.5]],"id":28338255}],"con":true,"img":false}]}
{"op":"mcm","clk":"5353357372","pt":1646213619697,"mc":[{"id":"1.195453770","rc":[{"atb":[[9.2,1.99],[9.6,4.5]],"id":28338255}],"con":true,"img":false}]}
{"op":"mcm","clk":"5353357379","pt":1646213619797,"mc":[{"id":"1.195453770","rc":[{"atb":[[9.4,2.88],[9.6,2.5]],"id":28338255}],"con":true,"img":false}]}
{"op":"mcm","clk":"5353357388","pt":1646213620006,"mc":[{"id":"1.195453770","rc":[{"atb":[[8,1.16],[9.2,0]],"id":28338255}],"con":true,"img":false}]}
{"op":"mcm","clk":"5353357395","pt":1646213620109,"mc":[{"id":"1.195453770","rc":[{"atb":[[9.8,1.99]],"id":28338255}],"con":true,"img":false}]}
{"op":"mcm","clk":"5353357429","pt":1646213620686,"mc":[{"id":"1.195453770","rc":[{"atb":[[9.8,0]],"id":28338255}],"con":true,"img":false}]}
{"op":"mcm","clk":"5353357434","pt":1646213620791,"mc":[{"id":"1.195453770","rc":[{"atb":[[1.02,1.99]],"id":28338255}],"con":true,"img":false}]}
{"op":"mcm","clk":"5353357446","pt":1646213620905,"mc":[{"id":"1.195453770","rc":[{"atb":[[7.4,0]],"id":28338255}],"con":true,"img":false}]}
{"op":"mcm","clk":"5353357454","pt":1646213621000,"mc":[{"id":"1.195453770","rc":[{"atb":[[7.4,1.57]],"id":28338255}],"con":true,"img":false}]}
{"op":"mcm","clk":"5353358834","pt":1646213646238,"mc":[{"id":"1.195453770","rc":[{"spn":24.26,"spf":1.0,"id":39784543},{"spn":17.99,"spf":1.0,"id":36500377},{"spn":19.17,"spf":1.0,"id":35801684},{"spn":19.51,"spf":1.0,"id":36074638},{"atl":[[3.8,3.36]],"id":42189401},{"spn":13.05,"spf":"NaN","id":28338255}],"con":true,"img":false}]}
{"op":"mcm","clk":"5353358863","pt":1646213646957,"mc":[{"id":"1.195453770","rc":[{"atb":[[7.8,1.64]],"id":28338255}],"con":true,"img":false}]}
{"op":"mcm","clk":"5353358868","pt":1646213647054,"mc":[{"id":"1.195453770","rc":[{"atb":[[8,9.75]],"id":28338255}],"con":true,"img":false}]}
{"op":"mcm","clk":"5353359905","pt":1646213666454,"mc":[{"id":"1.195453770","rc":[{"atb":[[25,0],[1.05,2.25]],"id":39784543},{"atb":[[17,0.16],[1.04,2.25]],"id":36500377},{"atb":[[1.04,2.25]],"id":35801684},{"atb":[[19.5,0],[1.04,2.25]],"id":36074638}],"con":true,"img":false}]}
{"op":"mcm","clk":"5353359910","pt":1646213666560,"mc":[{"id":"1.195453770","rc":[{"atb":[[19.5,0]],"id":35801684}],"con":true,"img":false}]}
{"op":"mcm","clk":"5353359916","pt":1646213666662,"mc":[{"id":"1.195453770","rc":[{"atb":[[1.05,0.14]],"id":39784543},{"atb":[[1.04,0.19]],"id":36500377},{"atb":[[1.04,0.18]],"id":35801684},{"atb":[[1.04,0.18]],"id":36074638}],"con":true,"img":false}]}
{"op":"mcm","clk":"5353359928","pt":1646213666873,"mc":[{"id":"1.195453770","rc":[{"atb":[[1.05,0]],"id":39784543}],"con":true,"img":false}]}
{"op":"mcm","clk":"5353359935","pt":1646213666976,"mc":[{"id":"1.195453770","rc":[{"atb":[[27,0.14]],"id":39784543}],"con":true,"img":false}]}
{"op":"mcm","clk":"5353359951","pt":1646213667188,"mc":[{"id":"1.195453770","rc":[{"atb":[[1.04,0]],"id":35801684}],"con":true,"img":false}]}
{"op":"mcm","clk":"5353359960","pt":1646213667289,"mc":[{"id":"1.195453770","rc":[{"atb":[[21,0.18]],"id":35801684}],"con":true,"img":false}]}
{"op":"mcm","clk":"5353359974","pt":1646213667490,"mc":[{"id":"1.195453770","rc":[{"atb":[[1.04,0]],"id":36500377}],"con":true,"img":false}]}
{"op":"mcm","clk":"5353359981","pt":1646213667594,"mc":[{"id":"1.195453770","rc":[{"atb":[[19,0.19]],"id":36500377}],"con":true,"img":false}]}
{"op":"mcm","clk":"5353360004","pt":1646213667861,"mc":[{"id":"1.195453770","rc":[{"atb":[[1.04,0]],"id":36074638}],"con":true,"img":false}]}
{"op":"mcm","clk":"5353360009","pt":1646213667964,"mc":[{"id":"1.195453770","rc":[{"atb":[[21,0.18]],"id":36074638}],"con":true,"img":false}]}
{"op":"mcm","clk":"5353360609","pt":1646213677505,"mc":[{"id":"1.195453770","rc":[{"atb":[[20,0],[1.02,1.66]],"id":36074638}],"con":true,"img":false}]}
{"op":"mcm","clk":"5353360621","pt":1646213677709,"mc":[{"id":"1.195453770","rc":[{"atb":[[20,0],[1.02,1.66]],"id":35801684}],"con":true,"img":false}]}
{"op":"mcm","clk":"5353360645","pt":1646213678078,"mc":[{"id":"1.195453770","rc":[{"atb":[[1.02,0.37]],"id":35801684},{"atb":[[1.02,0.37]],"id":36074638}],"con":true,"img":false}]}
{"op":"mcm","clk":"5353360657","pt":1646213678285,"mc":[{"id":"1.195453770","rc":[{"atb":[[1.02,0]],"id":35801684}],"con":true,"img":false}]}
{"op":"mcm","clk":"5353360666","pt":1646213678387,"mc":[{"id":"1.195453770","rc":[{"atb":[[22,0.37]],"id":35801684}],"con":true,"img":false}]}
{"op":"mcm","clk":"5353360684","pt":1646213678696,"mc":[{"id":"1.195453770","rc":[{"atb":[[1.02,0]],"id":36074638}],"con":true,"img":false}]}
{"op":"mcm","clk":"5353360692","pt":1646213678800,"mc":[{"id":"1.195453770","rc":[{"atb":[[22,0.37]],"id":36074638}],"con":true,"img":false}]}
{"op":"mcm","clk":"5353360979","pt":1646213683507,"mc":[{"id":"1.195453770","rc":[{"atl":[[75,2],[90,2.72]],"id":39784543},{"atb":[[8.2,2.78],[7.6,0]],"id":36500377},{"atb":[[12,0],[12.5,1.74]],"id":36074638},{"atb":[[2.44,0],[2.48,13.51]],"id":42189401},{"atl":[[3.85,1.32],[4,24.26]],"id":42189401},{"atl":[[12.5,8.7],[13.5,1.6]],"id":37127725},{"atb":[[6.4,0],[5.8,20.83],[6.8,0],[5.5,34.7],[6,0]],"id":28338255},{"atb":[[2.34,14.93],[2.4,14.29],[2.36,0],[2.56,2],[2.24,66.96],[2.06,0],[2.38,0],[2.2,60]],"id":26051221},{"atl":[[4.9,5.13],[5.1,0]],"id":26051221}],"con":true,"img":false}]}
{"op":"mcm","clk":"5353361004","pt":1646213683818,"mc":[{"id":"1.195453770","rc":[{"atb":[[3.95,0],[3.65,37.74]],"id":36074638},{"atb":[[2.56,0],[2.4,0]],"id":26051221},{"atl":[[4.3,3]],"id":26051221}],"con":true,"img":false}]}
{"op":"mcm","clk":"5353361040","pt":1646213684228,"mc":[{"id":"1.195453770","rc":[{"atb":[[1.01,5.35],[9.4,2]],"id":28338255}],"con":true,"img":false}]}
{"op":"mcm","clk":"5353361049","pt":1646213684329,"mc":[{"id":"1.195453770","rc":[{"atb":[[7.4,0]],"id":28338255}],"con":true,"img":false}]}
{"op":"mcm","clk":"5353361059","pt":1646213684389,"mc":[{"id":"1.195453770","rc":[{"atb":[[1.01,4.53],[7.6,1.53]],"id":28338255}],"con":true,"img":false}]}
{"op":"mcm","clk":"5353361081","pt":1646213684704,"mc":[{"id":"1.195453770","rc":[{"atb":[[1.01,3.68]],"id":28338255}],"con":true,"img":false}]}
{"op":"mcm","clk":"5353361090","pt":1646213684858,"mc":[{"id":"1.195453770","rc":[{"atb":[[9.8,0.85]],"id":28338255}],"con":true,"img":false}]}
{"op":"mcm","clk":"5353361104","pt":1646213685016,"mc":[{"id":"1.195453770","rc":[{"atb":[[3.4,1.55]],"id":26051221},{"atl":[[4.2,4]],"id":26051221}],"con":true,"img":false}]}
{"op":"mcm","clk":"5353361112","pt":1646213685119,"mc":[{"id":"1.195453770","rc":[{"atb":[[1.02,3.24]],"id":26051221}],"con":true,"img":false}]}
{"op":"mcm","clk":"5353361188","pt":1646213686111,"mc":[{"id":"1.195453770","rc":[{"atb":[[9.6,0]],"id":28338255}],"con":true,"img":false}]}
{"op":"mcm","clk":"5353361201","pt":1646213686318,"mc":[{"id":"1.195453770","rc":[{"atb":[[8.2,2],[9.4,0]],"id":28338255}],"con":true,"img":false}]}
{"op":"mcm","clk":"5353361213","pt":1646213686418,"mc":[{"id":"1.195453770","rc":[{"atb":[[8.2,0]],"id":28338255}],"con":true,"img":false}]}
{"op":"mcm","clk":"5353361223","pt":1646213686521,"mc":[{"id":"1.195453770","rc":[{"atb":[[8.2,2]],"id":28338255}],"con":true,"img":false}]}
{"op":"mcm","clk":"5353361328","pt":1646213687915,"mc":[{"id":"1.195453770","rc":[{"atb":[[3.4,0]],"id":26051221}],"con":true,"img":false}]}
{"op":"mcm","clk":"5353361337","pt":1646213688020,"mc":[{"id":"1.195453770","rc":[{"atb":[[1.01,3.55]],"id":26051221}],"con":true,"img":false}]}
{"op":"mcm","clk":"5353361610","pt":1646213692046,"mc":[{"id":"1.195453770","rc":[{"atl":[[4,6.55]],"id":42189401}],"con":true,"img":false}]}
{"op":"mcm","clk":"5353361616","pt":1646213692108,"mc":[{"id":"1.195453770","rc":[{"atl":[[4.1,17.71]],"id":42189401}],"con":true,"img":false}]}
{"op":"mcm","clk":"5353361632","pt":1646213692311,"mc":[{"id":"1.195453770","rc":[{"atl":[[4.1,2]],"id":26051221}],"con":true,"img":false}]}
{"op":"mcm","clk":"5353361722","pt":1646213693550,"mc":[{"id":"1.195453770","rc":[{"atb":[[7.8,7.35]],"id":36500377},{"atb":[[2.44,34.72]],"id":42189401},{"atl":[[4.2,15.36]],"id":42189401},{"atl":[[14.5,3.7]],"id":37127725},{"atb":[[2.3,38.46]],"id":26051221},{"atl":[[5.1,12.2]],"id":26051221},{"atb":[[5.3,11.63]],"id":28338255}],"con":true,"img":false}]}
{"op":"mcm","clk":"5353361773","pt":1646213694224,"mc":[{"id":"1.195453770","rc":[{"atb":[[3.45,2.81]],"id":37127725}],"con":true,"img":false}]}
{"op":"mcm","clk":"5353361812","pt":1646213694843,"mc":[{"id":"1.195453770","rc":[{"atb":[[3.4,0]],"id":37127725}],"con":true,"img":false}]}
{"op":"mcm","clk":"5353361823","pt":1646213694944,"mc":[{"id":"1.195453770","rc":[{"atb":[[1.02,1.99]],"id":37127725}],"con":true,"img":false}]}
{"op":"mcm","clk":"5353362303","pt":1646213702236,"mc":[{"id":"1.195453770","rc":[{"atl":[[4,2]],"id":26051221}],"con":true,"img":false}]}
{"op":"mcm","clk":"5353362315","pt":1646213702447,"mc":[{"id":"1.195453770","rc":[{"atb":[[6.4,0],[6.8,0],[7.2,0]],"id":36500377},{"atb":[[2.32,84.84]],"id":42189401},{"atb":[[1.82,100.8],[1.88,0]],"id":37127725},{"atb":[[2.12,0],[2.08,0],[2.16,0]],"id":26051221},{"atl":[[5.7,0]],"id":26051221}],"con":true,"img":false}]}
{"op":"mcm","clk":"5353362343","pt":1646213703016,"mc":[{"id":"1.195453770","rc":[{"atl":[[4.3,0],[4,0],[4.1,0],[4.2,0]],"id":26051221},{"trd":[[4.3,5.99],[4,4],[4.1,4],[4.2,8]],"ltp":4.3,"tv":21.99,"id":26051221}],"con":true,"img":false}]}
{"op":"mcm","clk":"5353362350","pt":1646213703124,"mc":[{"id":"1.195453770","rc":[{"atb":[[3.3,43.81]],"id":26051221}],"con":true,"img":false}]}
{"op":"mcm","clk":"5353362369","pt":1646213703330,"mc":[{"id":"1.195453770","rc":[{"atb":[[3.65,12.58]],"id":26051221},{"atl":[[5,0]],"id":26051221}],"con":true,"img":false}]}
{"op":"mcm","clk":"5353362373","pt":1646213703430,"mc":[{"id":"1.195453770","rc":[{"atl":[[4.8,1.3]],"id":26051221}],"con":true,"img":false}]}
{"op":"mcm","clk":"5353362380","pt":1646213703534,"mc":[{"id":"1.195453770","rc":[{"atb":[[7.4,11.72]],"id":36500377},{"atb":[[2.4,125.55]],"id":42189401},{"atl":[[4.4,21.69]],"id":42189401},{"atl":[[15.5,5.17]],"id":37127725},{"atb":[[2.26,59.52]],"id":26051221},{"atl":[[5.1,10.74]],"id":26051221},{"atb":[[5.1,18.29]],"id":28338255}],"con":true,"img":false}]}
{"op":"mcm","clk":"5353362417","pt":1646213704047,"mc":[{"id":"1.195453770","rc":[{"atl":[[4.8,0]],"id":26051221}],"con":true,"img":false}]}
{"op":"mcm","clk":"5353362425","pt":1646213704151,"mc":[{"id":"1.195453770","rc":[{"atl":[[1000,1.3]],"id":26051221}],"con":true,"img":false}]}
{"op":"mcm","clk":"5353362500","pt":1646213705135,"mc":[{"id":"1.195453770","rc":[{"atl":[[4.8,2.52]],"id":26051221}],"con":true,"img":false}]}
{"op":"mcm","clk":"5353362564","pt":1646213706058,"mc":[{"id":"1.195453770","rc":[{"atb":[[3.5,0],[1.04,1.66]],"id":26051221}],"con":true,"img":false}]}
{"op":"mcm","clk":"5353362580","pt":1646213706265,"mc":[{"id":"1.195453770","rc":[{"spn":24.35,"spf":1.0,"id":39784543},{"spn":18.09,"spf":1.0,"id":36500377},{"spn":19.49,"spf":1.0,"id":35801684},{"spn":20.48,"spf":1.0,"id":36074638},{"atb":[[1.04,1.65]],"id":26051221},{"spn":3.65,"spf":1.0,"id":26051221},{"spn":13.15,"spf":"NaN","id":28338255}],"con":true,"img":false}]}
{"op":"mcm","clk":"5353362593","pt":1646213706422,"mc":[{"id":"1.195453770","rc":[{"atb":[[1.04,0]],"id":26051221}],"con":true,"img":false}]}
{"op":"mcm","clk":"5353362602","pt":1646213706528,"mc":[{"id":"1.195453770","rc":[{"atb":[[3.8,1.94]],"id":26051221}],"con":true,"img":false}]}
{"op":"mcm","clk":"5353362651","pt":1646213707247,"mc":[{"id":"1.195453770","rc":[{"atl":[[65,2.62]],"id":39784543},{"atl":[[40,2.47]],"id":36074638}],"con":true,"img":false}]}
{"op":"mcm","clk":"5353362660","pt":1646213707350,"mc":[{"id":"1.195453770","rc":[{"atl":[[50,1.4]],"id":36500377},{"atl":[[1000,1.24]],"id":42189401}],"con":true,"img":false}]}
{"op":"mcm","clk":"5353362669","pt":1646213707465,"mc":[{"id":"1.195453770","rc":[{"atl":[[48,1.41]],"id":35801684},{"atb":[[4.4,29.41],[3.65,0]],"id":36074638},{"atb":[[2.6,62.98],[2.48,48.23]],"id":42189401},{"atb":[[3.75,12.24],[3.65,0]],"id":26051221},{"atl":[[4.9,0],[5.1,4.3],[6.2,0]],"id":26051221}],"con":true,"img":false}]}
{"op":"mcm","clk":"5353362674","pt":1646213707564,"mc":[{"id":"1.195453770","rc":[{"atl":[[1000,0]],"id":42189401},{"atl":[[1000,1.24]],"id":37127725}],"con":true,"img":false}]}
{"op":"mcm","clk":"5353362680","pt":1646213707667,"mc":[{"id":"1.195453770","rc":[{"atl":[[3.75,1.24]],"id":42189401},{"atl":[[7,16.67]],"id":26051221},{"atb":[[1.01,5.35],[9.8,0]],"id":28338255}],"con":true,"img":false}]}
{"op":"mcm","clk":"5353362686","pt":1646213707767,"mc":[{"id":"1.195453770","rc":[{"atl":[[1000,0]],"id":37127725},{"atl":[[16.5,2.51]],"id":28338255}],"con":true,"img":false}]}
{"op":"mcm","clk":"5353362693","pt":1646213707824,"mc":[{"id":"1.195453770","rc":[{"atl":[[4.6,2.47]],"id":37127725}],"con":true,"img":false}]}
{"op":"mcm","clk":"5353362699","pt":1646213707926,"mc":[{"id":"1.195453770","rc":[{"atb":[[1.03,1.66]],"id":39784543},{"atb":[[1.02,1.66]],"id":36500377}],"con":true,"img":false}]}
{"op":"mcm","clk":"5353362705","pt":1646213708029,"mc":[{"id":"1.195453770","rc":[{"atb":[[26,0]],"id":39784543}],"con":true,"img":false}]}
{"op":"mcm","clk":"5353362710","pt":1646213708131,"mc":[{"id":"1.195453770","rc":[{"atb":[[18.5,0]],"id":36500377},{"atb":[[1.01,4.53]],"id":28338255}],"con":true,"img":false}]}
{"op":"mcm","clk":"5353362721","pt":1646213708340,"mc":[{"id":"1.195453770","rc":[{"atb":[[1.03,0.3]],"id":39784543},{"atb":[[1.02,0.42]],"id":36500377},{"atl":[[50,2]],"id":35801684},{"atb":[[1.01,3.68]],"id":28338255}],"con":true,"img":false}]}
{"op":"mcm","clk":"5353362728","pt":1646213708444,"mc":[{"id":"1.195453770","rc":[{"atl":[[48,2.74]],"id":35801684},{"atb":[[8.6,0.85]],"id":28338255}],"con":true,"img":false}]}
{"op":"mcm","clk":"5353362735","pt":1646213708550,"mc":[{"id":"1.195453770","rc":[{"atl":[[3.8,0]],"id":42189401}],"con":true,"img":false}]}
{"op":"mcm","clk":"5353362742","pt":1646213708652,"mc":[{"id":"1.195453770","rc":[{"atb":[[1.02,0]],"id":36500377}],"con":true,"img":false}]}
{"op":"mcm","clk":"5353362748","pt":1646213708755,"mc":[{"id":"1.195453770","rc":[{"atb":[[19.5,0.42]],"id":36500377}],"con":true,"img":false}]}
{"op":"mcm","clk":"5353362754","pt":1646213708860,"mc":[{"id":"1.195453770","rc":[{"atb":[[1.03,0]],"id":39784543}],"con":true,"img":false}]}
{"op":"mcm","clk":"5353362762","pt":1646213708962,"mc":[{"id":"1.195453770","rc":[{"atb":[[28,0.3]],"id":39784543}],"con":true,"img":false}]}
{"op":"mcm","clk":"5353362770","pt":1646213709166,"mc":[{"id":"1.195453770","rc":[{"atb":[[8.8,2.5]],"id":28338255}],"con":true,"img":false}]}
{"op":"mcm","clk":"5353362785","pt":1646213709374,"mc":[{"id":"1.195453770","rc":[{"atb":[[8.2,0],[8.8,4.5]],"id":28338255}],"con":true,"img":false}]}
{"op":"mcm","clk":"5353362827","pt":1646213710256,"mc":[{"id":"1.195453770","rc":[{"atb":[[8,8.73]],"id":28338255}],"con":true,"img":false}]}
{"op":"mcm","clk":"5353362834","pt":1646213710360,"mc":[{"id":"1.195453770","rc":[{"atb":[[9,1.02]],"id":28338255}],"con":true,"img":false}]}
{"op":"mcm","clk":"5353362852","pt":1646213710769,"mc":[{"id":"1.195453770","rc":[{"atb":[[1.82,0],[1.9,100.8]],"id":37127725}],"con":true,"img":false}]}
{"op":"mcm","clk":"5353362873","pt":1646213711135,"mc":[{"id":"1.195453770","rc":[{"atl":[[1000,2.52]],"id":28338255}],"con":true,"img":false}]}
{"op":"mcm","clk":"5353362881","pt":1646213711341,"mc":[{"id":"1.195453770","rc":[{"atl":[[1000,1.68]],"id":28338255}],"con":true,"img":false}]}
{"op":"mcm","clk":"5353362894","pt":1646213711545,"mc":[{"id":"1.195453770","rc":[{"atl":[[1000,0]],"id":28338255}],"con":true,"img":false}]}
{"op":"mcm","clk":"5353362901","pt":1646213711653,"mc":[{"id":"1.195453770","rc":[{"atl":[[16,1.68]],"id":28338255}],"con":true,"img":false}]}
{"op":"mcm","clk":"5353362918","pt":1646213711963,"mc":[{"id":"1.195453770","rc":[{"atb":[[8.8,2]],"id":28338255}],"con":true,"img":false}]}
{"op":"mcm","clk":"5353362941","pt":1646213712477,"mc":[{"id":"1.195453770","rc":[{"atl":[[4.8,0]],"id":26051221}],"con":true,"img":false}]}
{"op":"mcm","clk":"5353362949","pt":1646213712637,"mc":[{"id":"1.195453770","rc":[{"atb":[[9,0]],"id":28338255}],"con":true,"img":false}]}
{"op":"mcm","clk":"5353362958","pt":1646213712744,"mc":[{"id":"1.195453770","rc":[{"atb":[[8.2,1.02]],"id":28338255}],"con":true,"img":false}]}
{"op":"mcm","clk":"5353363006","pt":1646213713569,"mc":[{"id":"1.195453770","rc":[{"atb":[[7,20.83]],"id":36500377},{"atb":[[2.36,91.91]],"id":42189401},{"atl":[[4.6,34.14]],"id":42189401},{"atl":[[16.5,8.06]],"id":37127725},{"atb":[[4.9,32.05]],"id":28338255}],"con":true,"img":false}]}
{"op":"mcm","clk":"5353363021","pt":1646213713776,"mc":[{"id":"1.195453770","rc":[{"atb":[[9,2.5]],"id":28338255}],"con":true,"img":false}]}
{"op":"mcm","clk":"5353363097","pt":1646213714962,"mc":[{"id":"1.195453770","rc":[{"atl":[[6,0]],"id":26051221}],"con":true,"img":false}]}
{"op":"mcm","clk":"5353363102","pt":1646213715063,"mc":[{"id":"1.195453770","rc":[{"atl":[[6.4,10.43]],"id":26051221}],"con":true,"img":false}]}
{"op":"mcm","clk":"5353363242","pt":1646213717494,"mc":[{"id":"1.195453770","rc":[{"atb":[[2.22,102.46]],"id":26051221},{"atl":[[5.3,10.24]],"id":26051221}],"con":true,"img":false}]}
{"op":"mcm","clk":"5353363391","pt":1646213720091,"mc":[{"id":"1.195453770","rc":[{"atl":[[1000,2.55]],"id":26051221}],"con":true,"img":false}]}
{"op":"mcm","clk":"5353363401","pt":1646213720253,"mc":[{"id":"1.195453770","rc":[{"atl":[[1000,1.3]],"id":26051221}],"con":true,"img":false}]}
{"op":"mcm","clk":"5353363407","pt":1646213720352,"mc":[{"id":"1.195453770","rc":[{"atl":[[5,1.24]],"id":26051221}],"con":true,"img":false}]}
{"op":"mcm","clk":"5353363435","pt":1646213720869,"mc":[{"id":"1.195453770","rc":[{"atb":[[3.85,2.52]],"id":26051221}],"con":true,"img":false}]}
{"op":"mcm","clk":"5353363807","pt":1646213727466,"mc":[{"id":"1.195453770","rc":[{"atb":[[3.8,8.42],[3.75,0]],"id":26051221},{"atl":[[5.5,14.68]],"id":26051221}],"con":true,"img":false}]}
{"op":"mcm","clk":"5353364155","pt":1646213732993,"mc":[{"id":"1.195453770","rc":[{"atl":[[16.5,1.27]],"id":28338255}],"con":true,"img":false}]}
{"op":"mcm","clk":"5353364430","pt":1646213737474,"mc":[{"id":"1.195453770","rc":[{"atl":[[5.7,23.43]],"id":26051221}],"con":true,"img":false}]}
{"op":"mcm","clk":"5353364754","pt":1646213742879,"mc":[{"id":"1.195453770","rc":[{"atb":[[8,0.13]],"id":28338255}],"con":true,"img":false}]}
{"op":"mcm","clk":"5353364758","pt":1646213742978,"mc":[{"id":"1.195453770","rc":[{"atb":[[8.8,10.59]],"id":28338255},{"atl":[[10.5,3]],"id":28338255}],"con":true,"img":false}]}
{"op":"mcm","clk":"5353364764","pt":1646213743082,"mc":[{"id":"1.195453770","rc":[{"atb":[[8.2,0]],"id":28338255}],"con":true,"img":false}]}
{"op":"mcm","clk":"5353364769","pt":1646213743188,"mc":[{"id":"1.195453770","rc":[{"atb":[[7.2,1.02]],"id":28338255}],"con":true,"img":false}]}
{"op":"mcm","clk":"5353364800","pt":1646213743391,"mc":[{"id":"1.195453770","rc":[{"atb":[[7.8,0.35]],"id":28338255}],"con":true,"img":false}]}
{"op":"mcm","clk":"5353364806","pt":1646213743494,"mc":[{"id":"1.195453770","rc":[{"atb":[[1.02,3.28]],"id":28338255}],"con":true,"img":false}]}
{"op":"mcm","clk":"5353364829","pt":1646213743807,"mc":[{"id":"1.195453770","rc":[{"atb":[[7.2,0]],"id":28338255}],"con":true,"img":false}]}
{"op":"mcm","clk":"5353364837","pt":1646213743912,"mc":[{"id":"1.195453770","rc":[{"atb":[[9,3.52]],"id":28338255}],"con":true,"img":false}]}
{"op":"mcm","clk":"5353364842","pt":1646213744017,"mc":[{"id":"1.195453770","rc":[{"atb":[[9.2,2]],"id":28338255},{"atl":[[16,0]],"id":28338255}],"con":true,"img":false}]}
{"op":"mcm","clk":"5353364850","pt":1646213744121,"mc":[{"id":"1.195453770","rc":[{"atb":[[9,1.02],[8.8,8.59]],"id":28338255}],"con":true,"img":false}]}
{"op":"mcm","clk":"5353364912","pt":1646213745018,"mc":[{"id":"1.195453770","rc":[{"atb":[[8.8,0]],"id":28338255}],"con":true,"img":false}]}
{"op":"mcm","clk":"5353364922","pt":1646213745122,"mc":[{"id":"1.195453770","rc":[{"atb":[[7.8,8.94]],"id":28338255},{"atl":[[10.5,0.5]],"id":28338255},{"trd":[[10.5,4.98]],"ltp":10.5,"tv":4.98,"id":28338255}],"con":true,"img":false}]}
{"op":"mcm","clk":"5353364936","pt":1646213745286,"mc":[{"id":"1.195453770","rc":[{"atb":[[8.8,6.21]],"id":28338255},{"atl":[[10.5,0]],"id":28338255}],"con":true,"img":false}]}
{"op":"mcm","clk":"5353365017","pt":1646213746625,"mc":[{"id":"1.195453770","rc":[{"atb":[[9.4,2.5]],"id":28338255}],"con":true,"img":false}]}
{"op":"mcm","clk":"5353365147","pt":1646213748808,"mc":[{"id":"1.195453770","rc":[{"atl":[[6.8,22.34]],"id":26051221}],"con":true,"img":false}]}
{"op":"mcm","clk":"5353365158","pt":1646213749009,"mc":[{"id":"1.195453770","rc":[{"atl":[[8,0]],"id":26051221}],"con":true,"img":false}]}
{"op":"mcm","clk":"5353365162","pt":1646213749114,"mc":[{"id":"1.195453770","rc":[{"atl":[[5.1,0],[5.2,4.2]],"id":26051221},{"atb":[[8.8,0]],"id":28338255}],"con":true,"img":false}]}
{"op":"mcm","clk":"5353365186","pt":1646213749422,"mc":[{"id":"1.195453770","rc":[{"atl":[[1000,0]],"id":26051221},{"atb":[[9,0]],"id":28338255}],"con":true,"img":false}]}
{"op":"mcm","clk":"5353365194","pt":1646213749525,"mc":[{"id":"1.195453770","rc":[{"atb":[[8,1.16]],"id":28338255},{"atl":[[5.1,1.3]],"id":26051221}],"con":true,"img":false}]}
{"op":"mcm","clk":"5353365427","pt":1646213752904,"mc":[{"id":"1.195453770","rc":[{"atl":[[4.7,0]],"id":42189401}],"con":true,"img":false}]}
{"op":"mcm","clk":"5353365434","pt":1646213753006,"mc":[{"id":"1.195453770","rc":[{"atl":[[4.5,30.26]],"id":42189401}],"con":true,"img":false}]}
{"op":"mcm","clk":"5353365551","pt":1646213754723,"mc":[{"id":"1.195453770","rc":[{"atb":[[1.11,1.66]],"id":39784543},{"atb":[[1.09,1.66]],"id":36500377},{"atb":[[1.09,1.66]],"id":35801684},{"atb":[[1.09,1.66]],"id":36074638},{"atb":[[1.03,1.66]],"id":42189401},{"atb":[[1.02,3.65]],"id":37127725},{"atb":[[1.05,1.66]],"id":28338255},{"atb":[[1.02,4.91]],"id":26051221}],"con":true,"img":false}]}
{"op":"mcm","clk":"5353365574","pt":1646213755031,"mc":[{"id":"1.195453770","rc":[{"atb":[[1.11,0.06]],"id":39784543},{"atb":[[1.09,0.08]],"id":36500377},{"atb":[[1.09,0.08]],"id":35801684},{"atb":[[1.09,0.08]],"id":36074638},{"atb":[[1.03,0.58]],"id":42189401},{"atb":[[1.02,2.46]],"id":37127725},{"atb":[[1.05,0.16]],"id":28338255},{"atb":[[1.02,3.67]],"id":26051221}],"con":true,"img":false}]}
{"op":"mcm","clk":"5353365595","pt":1646213755343,"mc":[{"id":"1.195453770","rc":[{"atb":[[1.11,0]],"id":39784543},{"atb":[[1.09,0]],"id":36500377},{"atb":[[1.09,0]],"id":35801684},{"atb":[[1.09,0]],"id":36074638},{"atb":[[1.03,0]],"id":42189401},{"atb":[[1.02,1.99]],"id":37127725},{"atb":[[1.05,0]],"id":28338255},{"atb":[[1.02,3.24]],"id":26051221}],"con":true,"img":false}]}
{"op":"mcm","clk":"5353365604","pt":1646213755399,"mc":[{"id":"1.195453770","rc":[{"atb":[[25,0.06]],"id":39784543},{"atb":[[18.5,0.08]],"id":36500377},{"atb":[[19.5,0.08]],"id":35801684},{"atb":[[19.5,0.08]],"id":36074638},{"atb":[[2.84,0.58]],"id":42189401},{"atb":[[3.5,0.47]],"id":37127725},{"atb":[[9.6,0.16]],"id":28338255},{"atb":[[3.9,0.42]],"id":26051221}],"con":true,"img":false}]}
{"op":"mcm","clk":"5353365832","pt":1646213759108,"mc":[{"id":"1.195453770","rc":[{"atl":[[5.4,10.01]],"id":26051221}],"con":true,"img":false}]}
{"op":"mcm","clk":"5353366428","pt":1646213769124,"mc":[{"id":"1.195453770","rc":[{"spn":24.56,"spf":1.0,"id":39784543},{"spn":18.25,"spf":1.0,"id":36500377},{"spn":19.5,"spf":1.0,"id":35801684},{"spn":20.52,"spf":1.0,"id":36074638},{"spn":4.05,"spf":"NaN","id":37127725},{"atl":[[5.3,0],[5.6,14.36],[5.5,0],[5.7,0]],"id":26051221},{"spn":3.81,"spf":1.0,"id":26051221},{"spn":13.05,"spf":"NaN","id":28338255}],"con":true,"img":false}]}
{"op":"mcm","clk":"5353366785","pt":1646213774925,"mc":[{"id":"1.195453770","rc":[{"atb":[[7.8,0.35]],"id":28338255}],"con":true,"img":false}]}
{"op":"mcm","clk":"5353366789","pt":1646213775028,"mc":[{"id":"1.195453770","rc":[{"atb":[[8.8,8.59]],"id":28338255}],"con":true,"img":false}]}
{"op":"mcm","clk":"5353366812","pt":1646213775345,"mc":[{"id":"1.195453770","rc":[{"atb":[[8,0.13]],"id":28338255}],"con":true,"img":false}]}
{"op":"mcm","clk":"5353366821","pt":1646213775448,"mc":[{"id":"1.195453770","rc":[{"atb":[[9,1.02]],"id":28338255}],"con":true,"img":false}]}
{"op":"mcm","clk":"5353367040","pt":1646213779158,"mc":[{"id":"1.195453770","rc":[{"atl":[[5.8,22.94]],"id":26051221}],"con":true,"img":false}]}
{"op":"mcm","clk":"5353367333","pt":1646213785452,"mc":[{"id":"1.195453770","rc":[{"atb":[[4,8]],"id":26051221}],"con":true,"img":false}]}
{"op":"mcm","clk":"5353367356","pt":1646213785859,"mc":[{"id":"1.195453770","rc":[{"atb":[[3.85,0]],"id":26051221},{"atl":[[5.1,0]],"id":26051221}],"con":true,"img":false}]}
{"op":"mcm","clk":"5353367364","pt":1646213785963,"mc":[{"id":"1.195453770","rc":[{"atl":[[1000,1.3]],"id":26051221}],"con":true,"img":false}]}
{"op":"mcm","clk":"5353367417","pt":1646213786945,"mc":[{"id":"1.195453770","rc":[{"atb":[[8.8,0]],"id":28338255}],"con":true,"img":false}]}
{"op":"mcm","clk":"5353367423","pt":1646213787046,"mc":[{"id":"1.195453770","rc":[{"atb":[[8,8.73]],"id":28338255}],"con":true,"img":false}]}
{"op":"mcm","clk":"5353367527","pt":1646213789155,"mc":[{"id":"1.195453770","rc":[{"atb":[[2.3,0],[2.22,0],[2.26,0],[2.34,0]],"id":26051221},{"atl":[[5.8,0],[5.4,0],[5.6,0],[5.2,0]],"id":26051221}],"con":true,"img":false}]}
{"op":"mcm","clk":"5353367545","pt":1646213789567,"mc":[{"id":"1.195453770","rc":[{"atl":[[1000,0]],"id":26051221}],"con":true,"img":false}]}
{"op":"mcm","clk":"5353367549","pt":1646213789670,"mc":[{"id":"1.195453770","rc":[{"atb":[[1.02,1.99]],"id":26051221},{"atl":[[6.2,1.3]],"id":26051221}],"con":true,"img":false}]}
{"op":"mcm","clk":"5353367554","pt":1646213789772,"mc":[{"id":"1.195453770","rc":[{"atb":[[4,9.25]],"id":26051221}],"con":true,"img":false}]}
{"op":"mcm","clk":"5353367873","pt":1646213796061,"mc":[{"id":"1.195453770","rc":[{"atb":[[12,0],[13,0],[14,7.75],[15,0]],"id":39784543},{"atl":[[260,0],[280,0],[220,0],[240,0.84]],"id":39784543},{"atb":[[8.2,0],[7.4,0],[7.8,0],[7,0]],"id":36500377},{"atl":[[170,0],[190,0],[210,0],[230,0]],"id":36500377},{"atb":[[10.5,0],[11.5,0],[12.5,0],[9.8,0]],"id":35801684},{"atl":[[170,0],[190,0],[210,0.97],[230,0]],"id":35801684},{"atb":[[2.44,0],[2.48,34.72],[2.4,71.98],[2.36,0]],"id":42189401},{"atl":[[4.4,0],[4,0],[4.6,0],[4.2,0]],"id":42189401},{"atb":[[2.98,0],[2.94,0],[2.9,53.04],[2.86,0]],"id":37127725},{"atl":[[13.5,0],[14.5,0],[15.5,0],[16.5,0]],"id":37127725},{"atb":[[5.3,0],[4.9,0],[5.1,0],[5.5,30.26]],"id":28338255},{"atl":[[16.5,0],[18,0],[19,3.24],[20,0]],"id":28338255}],"con":true,"img":false}]}
{"op":"mcm","clk":"5353367899","pt":1646213796370,"mc":[{"id":"1.195453770","rc":[{"atb":[[10,0],[11,0],[12.5,0],[9.6,0]],"id":36074638},{"atl":[[190,14.2],[220,0],[240,0],[260,0]],"id":36074638}],"con":true,"img":false}]}
{"op":"mcm","clk":"5353367942","pt":1646213796883,"mc":[{"id":"1.195453770","rc":[{"atl":[[4.5,0],[4.1,0]],"id":42189401}],"con":true,"img":false}]}
{"op":"mcm","clk":"5353367950","pt":1646213796986,"mc":[{"id":"1.195453770","rc":[{"atl":[[4.4,17.71],[4.7,30.26]],"id":42189401}],"con":true,"img":false}]}
{"op":"mcm","clk":"5353367956","pt":1646213797039,"mc":[{"id":"1.195453770","rc":[{"atl":[[4.4,25.88]],"id":42189401},{"atl":[[1000,2.52]],"id":28338255}],"con":true,"img":false}]}
{"op":"mcm","clk":"5353367965","pt":1646213797246,"mc":[{"id":"1.195453770","rc":[{"atl":[[1000,1.68]],"id":28338255}],"con":true,"img":false}]}
{"op":"mcm","clk":"5353367976","pt":1646213797451,"mc":[{"id":"1.195453770","rc":[{"atl":[[1000,0]],"id":28338255}],"con":true,"img":false}]}
{"op":"mcm","clk":"5353367984","pt":1646213797561,"mc":[{"id":"1.195453770","rc":[{"atl":[[16.5,1.68]],"id":28338255}],"con":true,"img":false}]}
{"op":"mcm","clk":"5353368014","pt":1646213798073,"mc":[{"id":"1.195453770","rc":[{"atl":[[5,0]],"id":26051221}],"con":true,"img":false}]}
{"op":"mcm","clk":"5353368074","pt":1646213799055,"mc":[{"id":"1.195453770","rc":[{"atl":[[6,2.5]],"id":26051221}],"con":true,"img":false}]}
{"op":"mcm","clk":"5353368099","pt":1646213799367,"mc":[{"id":"1.195453770","rc":[{"atl":[[6.2,0]],"id":26051221}],"con":true,"img":false}]}
{"op":"mcm","clk":"5353368106","pt":1646213799471,"mc":[{"id":"1.195453770","rc":[{"atl":[[5.9,1.3]],"id":26051221}],"con":true,"img":false}]}
{"op":"mcm","clk":"5353368168","pt":1646213800558,"mc":[{"id":"1.195453770","rc":[{"atl":[[6,0]],"id":26051221}],"con":true,"img":false}]}
{"op":"mcm","clk":"5353368204","pt":1646213801276,"mc":[{"id":"1.195453770","rc":[{"atl":[[5.9,0]],"id":26051221}],"con":true,"img":false}]}
{"op":"mcm","clk":"5353368210","pt":1646213801377,"mc":[{"id":"1.195453770","rc":[{"atl":[[6.2,1.3]],"id":26051221}],"con":true,"img":false}]}
{"op":"mcm","clk":"5353368219","pt":1646213801482,"mc":[{"id":"1.195453770","rc":[{"atb":[[3.8,1.94],[3.95,11.62]],"id":26051221}],"con":true,"img":false}]}
{"op":"mcm","clk":"5353368224","pt":1646213801583,"mc":[{"id":"1.195453770","rc":[{"atb":[[12,11.36],[13,6.25],[14,11.6],[15,1.43]],"id":39784543},{"atl":[[260,1],[280,1],[220,1],[240,1.84]],"id":39784543},{"atb":[[10.5,7.89],[11.5,4.76],[12.5,1.74],[9.8,14.2]],"id":35801684},{"atl":[[170,1],[190,1],[210,1.97],[230,1]],"id":35801684},{"atb":[[10.5,18.5],[11.5,4.76],[12.5,1.74],[9.8,14.2]],"id":36074638},{"atl":[[190,15.2],[210,1],[230,1.88],[250,1]],"id":36074638},{"atb":[[2.98,10.1],[2.94,25.77],[2.9,92.51],[2.86,67.2]],"id":37127725},{"atl":[[13.5,1.6],[14.5,3.7],[15.5,5.17],[16.5,8.06]],"id":37127725},{"atb":[[2.3,38.46],[2.22,102.46],[2.26,59.52],[2.34,14.93]],"id":26051221},{"atl":[[5.3,4.1],[5.9,22.47],[7.2,16.13],[5.5,9.79],[5.7,14.06],[7,0]],"id":26051221},{"atb":[[5.3,11.63],[4.9,32.05],[5.1,18.29],[5.5,34.7]],"id":28338255},{"atl":[[16.5,2.78],[17.5,2.58],[18.5,3.65],[19.5,11.51]],"id":28338255}],"con":true,"img":false}]}
{"op":"mcm","clk":"5353368231","pt":1646213801684,"mc":[{"id":"1.195453770","rc":[{"atb":[[8.2,2.78],[7.4,11.72],[7.8,7.35],[7,20.83]],"id":36500377},{"atl":[[170,1],[190,1],[210,1],[230,1]],"id":36500377},{"atb":[[2.44,34.72],[2.48,48.23],[2.4,125.55],[2.36,91.91]],"id":42189401},{"atl":[[4.4,47.57],[4,6.55],[4.6,34.14],[4.2,15.36]],"id":42189401}],"con":true,"img":false}]}
{"op":"mcm","clk":"5353368254","pt":1646213802096,"mc":[{"id":"1.195453770","rc":[{"atl":[[6.2,3.8]],"id":26051221}],"con":true,"img":false}]}
{"op":"mcm","clk":"5353368264","pt":1646213802256,"mc":[{"id":"1.195453770","rc":[{"atb":[[4,8]],"id":26051221}],"con":true,"img":false}]}
{"op":"mcm","clk":"5353368271","pt":1646213802361,"mc":[{"id":"1.195453770","rc":[{"atb":[[1.02,3.24]],"id":26051221}],"con":true,"img":false}]}
{"op":"mcm","clk":"5353368301","pt":1646213802972,"mc":[{"id":"1.195453770","rc":[{"atl":[[6.8,0]],"id":26051221}],"con":true,"img":false}]}
{"op":"mcm","clk":"5353368306","pt":1646213803075,"mc":[{"id":"1.195453770","rc":[{"atl":[[7,22.34]],"id":26051221}],"con":true,"img":false}]}
{"op":"mcm","clk":"5353368318","pt":1646213803278,"mc":[{"id":"1.195453770","rc":[{"atl":[[6.2,1.3]],"id":26051221}],"con":true,"img":false}]}
{"op":"mcm","clk":"5353368732","pt":1646213810908,"mc":[{"id":"1.195453770","rc":[{"atl":[[1000,1.24]],"id":26051221}],"con":true,"img":false}]}
{"op":"mcm","clk":"5353368743","pt":1646213811069,"mc":[{"id":"1.195453770","rc":[{"atl":[[5.3,0],[1000,0],[5.2,4.2]],"id":26051221},{"atl":[[16.5,1.68],[17.5,1.03]],"id":28338255}],"con":true,"img":false}]}
{"op":"mcm","clk":"5353368748","pt":1646213811169,"mc":[{"id":"1.195453770","rc":[{"atl":[[5.2,5.44]],"id":26051221}],"con":true,"img":false}]}
{"op":"mcm","clk":"5353368785","pt":1646213811893,"mc":[{"id":"1.195453770","rc":[{"atb":[[9,0]],"id":28338255}],"con":true,"img":false}]}
{"op":"mcm","clk":"5353368792","pt":1646213811997,"mc":[{"id":"1.195453770","rc":[{"atb":[[8.2,1.02]],"id":28338255}],"con":true,"img":false}]}
{"op":"mcm","clk":"5353369099","pt":1646213816593,"mc":[{"id":"1.195453770","rc":[{"atb":[[27,0],[1.05,2.25]],"id":39784543},{"atb":[[1.04,2.25]],"id":36500377},{"atb":[[1.04,2.25]],"id":35801684}],"con":true,"img":false}]}
{"op":"mcm","clk":"5353369106","pt":1646213816700,"mc":[{"id":"1.195453770","rc":[{"atb":[[19,0]],"id":36500377},{"atb":[[21,0]],"id":35801684}],"con":true,"img":false}]}
{"op":"mcm","clk":"5353369115","pt":1646213816800,"mc":[{"id":"1.195453770","rc":[{"atb":[[1.05,0.12]],"id":39784543},{"atl":[[16.5,2.78]],"id":28338255}],"con":true,"img":false}]}
{"op":"mcm","clk":"5353369139","pt":1646213817106,"mc":[{"id":"1.195453770","rc":[{"atb":[[1.04,0.16]],"id":35801684}],"con":true,"img":false}]}
{"op":"mcm","clk":"5353369154","pt":1646213817413,"mc":[{"id":"1.195453770","rc":[{"atb":[[1.05,0]],"id":39784543},{"atb":[[1.04,0.18]],"id":36500377}],"con":true,"img":false}]}
{"op":"mcm","clk":"5353369162","pt":1646213817522,"mc":[{"id":"1.195453770","rc":[{"atb":[[11.5,0],[14,3.85],[16.5,0],[19,0.14],[29,0.12]],"id":39784543},{"atl":[[140,0],[290,0],[190,0],[240,1]],"id":39784543},{"atb":[[9,0],[10,0],[12.5,0],[15,0]],"id":36500377},{"atl":[[150,0],[200,0],[250,0],[100,0]],"id":36500377},{"atb":[[11,0],[13.5,0],[9.4,11.9],[16,0]],"id":35801684},{"atl":[[260,0],[160,0],[210,1],[110,0]],"id":35801684},{"atb":[[10.5,7.89],[13,0],[15.5,0.7],[18,0]],"id":36074638},{"atl":[[130,0],[280,0],[180,0],[230,1]],"id":36074638},{"atb":[[2.5,0],[2.3,0],[2.6,0],[2.4,53.57]],"id":42189401},{"atl":[[8,0],[9,0],[6,0],[7,0]],"id":42189401},{"atb":[[2.8,0],[3,0],[2.9,39.47],[2.7,0]],"id":37127725},{"atl":[[12,0],[7.8,0],[9.8,0],[8.8,0]],"id":37127725},{"atb":[[4,0],[4.5,0],[5,0],[5.5,4.44]],"id":28338255},{"atl":[[17,0],[19.5,5.75],[24,0],[29,0]],"id":28338255},{"atb":[[2.82,0],[3.3,0],[3.05,0],[2.92,0]],"id":26051221},{"atl":[[9.2,0],[10.5,0],[8.2,0],[13,0]],"id":26051221}],"con":true,"img":false}]}
{"op":"mcm","clk":"5353369174","pt":1646213817680,"mc":[{"id":"1.195453770","rc":[{"atb":[[1.04,0]],"id":35801684},{"atb":[[22,0],[1.02,1.66]],"id":36074638}],"con":true,"img":false}]}
{"op":"mcm","clk":"5353369179","pt":1646213817787,"mc":[{"id":"1.195453770","rc":[{"atb":[[23,0.16]],"id":35801684}],"con":true,"img":false}]}
{"op":"mcm","clk":"5353369184","pt":1646213817885,"mc":[{"id":"1.195453770","rc":[{"atb":[[1.04,0]],"id":36500377},{"atb":[[1.02,0.37]],"id":36074638}],"con":true,"img":false}]}
{"op":"mcm","clk":"5353369190","pt":1646213817988,"mc":[{"id":"1.195453770","rc":[{"atb":[[20,0.18]],"id":36500377},{"atb":[[1.02,0]],"id":36074638}],"con":true,"img":false}]}
