{"op":"mcm","clk":"5346220768","pt":1646178839799,"mc":[{"id":"1.195453676","marketDefinition":{"bspMarket":false,"turnInPlayEnabled":false,"persistenceEnabled":false,"marketBaseRate":7.0,"eventId":"31272494","eventTypeId":"4339","numberOfWinners":1,"bettingType":"ODDS","marketType":"MATCH_BET","marketTime":"2022-03-02T10:51:00.000Z","suspendTime":"2022-03-02T10:51:00.000Z","bspReconciled":false,"complete":true,"inPlay":false,"crossMatching":true,"runnersVoidable":false,"numberOfActiveRunners":2,"betDelay":0,"status":"OPEN","runners":[{"status":"ACTIVE","sortPriority":1,"id":41788482,"name":"3. Flossie Ann"},{"status":"ACTIVE","sortPriority":2,"id":37286329,"name":"6. Dr Danika"}],"regulators":["MR_INT"],"venue":"Traralgon","countryCode":"AU","discountAllowed":true,"timezone":"Australia/Sydney","openDate":"2022-03-02T08:31:00.000Z","version":4382489941,"name":"Flossie Ann v Dr Danika","eventName":"Traralgon (AUS) 2nd Mar"},"rc":[],"con":true,"img":false}]}
{"op":"mcm","clk":"5346224660","pt":1646178919306,"mc":[{"id":"1.195453676","rc":[{"atb":[[1.44,12.24],[1.54,9.97],[1.34,15.85]],"id":41788482},{"atb":[[1.99,5.44],[1.79,6.82],[1.89,6.05]],"id":37286329}],"con":true,"img":false}]}
{"op":"mcm","clk":"5346401491","pt":1646182002783,"mc":[{"id":"1.195453676","marketDefinition":{"bspMarket":false,"turnInPlayEnabled":false,"persistenceEnabled":false,"marketBaseRate":7.0,"eventId":"31272494","eventTypeId":"4339","numberOfWinners":1,"bettingType":"ODDS","marketType":"MATCH_BET","marketTime":"2022-03-02T10:51:00.000Z","suspendTime":"2022-03-02T10:51:00.000Z","bspReconciled":false,"complete":true,"inPlay":false,"crossMatching":true,"runnersVoidable":false,"numberOfActiveRunners":2,"betDelay":0,"status":"OPEN","runners":[{"status":"ACTIVE","sortPriority":1,"id":41788482,"name":"3. Flossie Ann"},{"status":"ACTIVE","sortPriority":2,"id":37286329,"name":"6. Dr Danika"}],"regulators":["MR_INT"],"venue":"Traralgon","countryCode":"AU","discountAllowed":true,"timezone":"Australia/Sydney","openDate":"2022-03-02T08:31:00.000Z","version":4382489941,"name":"Flossie Ann v Dr Danika","eventName":"Traralgon (AUS) 2nd Mar"},"rc":[{"atb":[[1.44,12.24],[1.54,9.97],[1.34,15.85]],"id":41788482},{"atb":[[1.99,5.44],[1.79,6.82],[1.89,6.05]],"id":37286329}],"con":true,"img":true}]}
{"op":"mcm","clk":"5346485127","pt":1646183185344,"mc":[{"id":"1.195453676","rc":[{"atb":[[1.44,0],[1.54,0],[1.34,0]],"id":41788482},{"atb":[[1.99,0],[1.79,0],[1.89,0]],"id":37286329}],"con":true,"img":false}]}
{"op":"mcm","clk":"5346487163","pt":1646183210693,"mc":[{"id":"1.195453676","rc":[{"atb":[[1.4,13.49],[1.5,10.79],[1.3,17.99]],"id":41788482},{"atb":[[1.82,6.58],[1.92,5.86],[2.04,5.19]],"id":37286329}],"con":true,"img":false}]}
{"op":"mcm","clk":"5347092397","pt":1646192802708,"mc":[{"id":"1.195453676","marketDefinition":{"bspMarket":false,"turnInPlayEnabled":false,"persistenceEnabled":false,"marketBaseRate":7.0,"eventId":"31272494","eventTypeId":"4339","numberOfWinners":1,"bettingType":"ODDS","marketType":"MATCH_BET","marketTime":"2022-03-02T10:51:00.000Z","suspendTime":"2022-03-02T10:51:00.000Z","bspReconciled":false,"complete":true,"inPlay":false,"crossMatching":true,"runnersVoidable":false,"numberOfActiveRunners":2,"betDelay":0,"status":"OPEN","runners":[{"status":"ACTIVE","sortPriority":1,"id":41788482,"name":"3. Flossie Ann"},{"status":"ACTIVE","sortPriority":2,"id":37286329,"name":"6. Dr Danika"}],"regulators":["MR_INT"],"venue":"Traralgon","countryCode":"AU","discountAllowed":true,"timezone":"Australia/Sydney","openDate":"2022-03-02T08:31:00.000Z","version":4382489941,"name":"Flossie Ann v Dr Danika","eventName":"Traralgon (AUS) 2nd Mar"},"rc":[{"atb":[[1.4,13.51],[1.5,10.81],[1.3,18.02]],"id":41788482},{"atb":[[1.82,6.59],[1.92,5.87],[2.04,5.19]],"id":37286329}],"con":true,"img":true}]}
{"op":"mcm","clk":"5347381258","pt":1646198202726,"mc":[{"id":"1.195453676","marketDefinition":{"bspMarket":false,"turnInPlayEnabled":false,"persistenceEnabled":false,"marketBaseRate":7.0,"eventId":"31272494","eventTypeId":"4339","numberOfWinners":1,"bettingType":"ODDS","marketType":"MATCH_BET","marketTime":"2022-03-02T10:51:00.000Z","suspendTime":"2022-03-02T10:51:00.000Z","bspReconciled":false,"complete":true,"inPlay":false,"crossMatching":true,"runnersVoidable":false,"numberOfActiveRunners":2,"betDelay":0,"status":"OPEN","runners":[{"status":"ACTIVE","sortPriority":1,"id":41788482,"name":"3. Flossie Ann"},{"status":"ACTIVE","sortPriority":2,"id":37286329,"name":"6. Dr Danika"}],"regulators":["MR_INT"],"venue":"Traralgon","countryCode":"AU","discountAllowed":true,"timezone":"Australia/Sydney","openDate":"2022-03-02T08:31:00.000Z","version":4382489941,"name":"Flossie Ann v Dr Danika","eventName":"Traralgon (AUS) 2nd Mar"},"rc":[{"atb":[[1.4,13.51],[1.5,10.81],[1.3,18.01]],"id":41788482},{"atb":[[1.82,6.59],[1.92,5.87],[2.04,5.19]],"id":37286329}],"con":true,"img":true}]}
{"op":"mcm","clk":"5347848930","pt":1646209002729,"mc":[{"id":"1.195453676","marketDefinition":{"bspMarket":false,"turnInPlayEnabled":false,"persistenceEnabled":false,"marketBaseRate":7.0,"eventId":"31272494","eventTypeId":"4339","numberOfWinners":1,"bettingType":"ODDS","marketType":"MATCH_BET","marketTime":"2022-03-02T10:51:00.000Z","suspendTime":"2022-03-02T10:51:00.000Z","bspReconciled":false,"complete":true,"inPlay":false,"crossMatching":true,"runnersVoidable":false,"numberOfActiveRunners":2,"betDelay":0,"status":"OPEN","runners":[{"status":"ACTIVE","sortPriority":1,"id":41788482,"name":"3. Flossie Ann"},{"status":"ACTIVE","sortPriority":2,"id":37286329,"name":"6. Dr Danika"}],"regulators":["MR_INT"],"venue":"Traralgon","countryCode":"AU","discountAllowed":true,"timezone":"Australia/Sydney","openDate":"2022-03-02T08:31:00.000Z","version":4382489941,"name":"Flossie Ann v Dr Danika","eventName":"Traralgon (AUS) 2nd Mar"},"rc":[{"atb":[[1.4,13.5],[1.5,10.8],[1.3,18.01]],"id":41788482},{"atb":[[1.82,6.58],[1.92,5.87],[2.04,5.19]],"id":37286329}],"con":true,"img":true}]}
{"op":"mcm","clk":"5348133113","pt":1646214402739,"mc":[{"id":"1.195453676","marketDefinition":{"bspMarket":false,"turnInPlayEnabled":false,"persistenceEnabled":false,"marketBaseRate":7.0,"eventId":"31272494","eventTypeId":"4339","numberOfWinners":1,"bettingType":"ODDS","marketType":"MATCH_BET","marketTime":"2022-03-02T10:51:00.000Z","suspendTime":"2022-03-02T10:51:00.000Z","bspReconciled":false,"complete":true,"inPlay":false,"crossMatching":true,"runnersVoidable":false,"numberOfActiveRunners":2,"betDelay":0,"status":"OPEN","runners":[{"status":"ACTIVE","sortPriority":1,"id":41788482,"name":"3. Flossie Ann"},{"status":"ACTIVE","sortPriority":2,"id":37286329,"name":"6. Dr Danika"}],"regulators":["MR_INT"],"venue":"Traralgon","countryCode":"AU","discountAllowed":true,"timezone":"Australia/Sydney","openDate":"2022-03-02T08:31:00.000Z","version":4382489941,"name":"Flossie Ann v Dr Danika","eventName":"Traralgon (AUS) 2nd Mar"},"rc":[{"atb":[[1.4,13.48],[1.5,10.79],[1.3,17.98]],"id":41788482},{"atb":[[1.82,6.57],[1.92,5.86],[2.04,5.18]],"id":37286329}],"con":true,"img":true}]}
{"op":"mcm","clk":"5348380809","pt":1646217082370,"mc":[{"id":"1.195453676","rc":[{"atb":[[1.4,13.48],[1.5,10.79],[1.3,17.98],[1.51,2]],"id":41788482},{"atl":[[2.22,2]],"id":41788482},{"atb":[[1.82,6.57],[1.92,5.86],[1.79,11.72],[2.04,5.18]],"id":37286329},{"atl":[[3.2,11.72]],"id":37286329}],"con":true,"img":false}]}
{"op":"mcm","clk":"5348381774","pt":1646217092691,"mc":[{"id":"1.195453676","rc":[{"atl":[[3.2,0],[3.15,11.72]],"id":37286329}],"con":true,"img":false}]}
{"op":"mcm","clk":"5348383139","pt":1646217107921,"mc":[{"id":"1.195453676","rc":[{"atb":[[1.51,0]],"id":41788482},{"atl":[[2.22,0]],"id":41788482},{"atb":[[1.79,0]],"id":37286329},{"atl":[[3.15,0]],"id":37286329}],"con":true,"img":false}]}
{"op":"mcm","clk":"5348387415","pt":1646217157066,"mc":[{"id":"1.195453676","rc":[{"atb":[[1.51,2]],"id":41788482},{"atl":[[2.22,2]],"id":41788482},{"atb":[[1.79,11.72]],"id":37286329},{"atl":[[3.2,11.72]],"id":37286329}],"con":true,"img":false}]}
{"op":"mcm","clk":"5348392086","pt":1646217210313,"mc":[{"id":"1.195453676","rc":[{"atl":[[3.2,0],[3.15,2]],"id":37286329}],"con":true,"img":false}]}
{"op":"mcm","clk":"5348400316","pt":1646217300169,"mc":[{"id":"1.195453676","rc":[{"atl":[[3.1,2]],"id":37286329}],"con":true,"img":false}]}
{"op":"mcm","clk":"5348400326","pt":1646217300272,"mc":[{"id":"1.195453676","rc":[{"atl":[[3.15,0]],"id":37286329}],"con":true,"img":false}]}
{"op":"mcm","clk":"5348411167","pt":1646217417515,"mc":[{"id":"1.195453676","rc":[{"atb":[[1.4,0],[1.5,0],[1.3,0]],"id":41788482},{"atb":[[1.82,0],[1.92,0],[2.04,0]],"id":37286329}],"con":true,"img":false}]}
{"op":"mcm","clk":"5348411290","pt":1646217418791,"mc":[{"id":"1.195453676","rc":[{"atl":[[3.1,0],[3.05,10]],"id":37286329}],"con":true,"img":false}]}
{"op":"mcm","clk":"5348411312","pt":1646217419020,"mc":[{"id":"1.195453676","rc":[{"atl":[[3.1,10],[3.05,0]],"id":37286329}],"con":true,"img":false}]}
{"op":"mcm","clk":"5348411472","pt":1646217420629,"mc":[{"id":"1.195453676","rc":[{"atb":[[1.4,13.48],[1.5,10.79],[1.3,17.98]],"id":41788482},{"atb":[[1.82,6.57],[1.92,5.86],[2.04,5.18]],"id":37286329}],"con":true,"img":false}]}
{"op":"mcm","clk":"5348411844","pt":1646217424204,"mc":[{"id":"1.195453676","rc":[{"atl":[[3.1,0],[2.94,11.72]],"id":37286329}],"con":true,"img":false}]}
{"op":"mcm","clk":"5348412408","pt":1646217430036,"mc":[{"id":"1.195453676","rc":[{"atl":[[2.92,11.72],[2.94,0]],"id":37286329}],"con":true,"img":false}]}
{"op":"mcm","clk":"5348438652","pt":1646217711744,"mc":[{"id":"1.195453676","rc":[{"atb":[[1.28,2],[1.37,2],[1.26,54],[1.34,2],[1.35,24],[1.4,24.48],[1.36,2],[1.32,2],[1.29,2],[1.31,36],[1.38,16]],"id":41788482}],"con":true,"img":false}]}
{"op":"mcm","clk":"5348438809","pt":1646217713531,"mc":[{"id":"1.195453676","rc":[{"atl":[[2.56,2],[2.72,2],[2.54,16],[2.5,11],[2.74,2],[2.6,24],[2.66,2],[2.58,2],[2.62,2],[2.78,54],[2.68,36]],"id":41788482}],"con":true,"img":false}]}
{"op":"mcm","clk":"5348439767","pt":1646217723265,"mc":[{"id":"1.195453676","rc":[{"atb":[[1.64,17],[1.6,2],[1.01,67],[1.37,34],[1.7,12],[1.68,2],[1.23,2],[1.53,24],[1.48,2],[1.16,48],[1.57,2],[1.11,2],[1.06,2],[1.3,2],[1.42,2],[1.66,2]],"id":37286329}],"con":true,"img":false}]}
{"op":"mcm","clk":"5348439940","pt":1646217725163,"mc":[{"id":"1.195453676","rc":[{"atl":[[9,67],[2.54,2],[2.5,12],[5.8,2],[4.9,48],[2.58,2],[2.84,24],[2.62,17],[2.94,2],[3.75,2],[2.76,2],[7.2,2],[3.4,34],[3.15,2],[4.2,2],[2.7,2]],"id":37286329}],"con":true,"img":false}]}
{"op":"mcm","clk":"5348439950","pt":1646217725272,"mc":[{"id":"1.195453676","rc":[{"atl":[[2.58,4],[2.92,0]],"id":37286329}],"con":true,"img":false}]}
{"op":"mcm","clk":"5348449728","pt":1646217819211,"mc":[{"id":"1.195453676","rc":[{"atl":[[2.22,0],[2.2,27]],"id":41788482}],"con":true,"img":false}]}
{"op":"mcm","clk":"5348449741","pt":1646217819316,"mc":[{"id":"1.195453676","rc":[{"atl":[[2.22,2],[2.2,0]],"id":41788482}],"con":true,"img":false}]}
{"op":"mcm","clk":"5348450255","pt":1646217824020,"mc":[{"id":"1.195453676","rc":[{"atb":[[1.51,0],[1.57,2]],"id":41788482}],"con":true,"img":false}]}
{"op":"mcm","clk":"5348450275","pt":1646217824228,"mc":[{"id":"1.195453676","rc":[{"atb":[[1.62,2],[1.57,0]],"id":41788482},{"atl":[[2.5,14],[2.58,2]],"id":37286329}],"con":true,"img":false}]}
{"op":"mcm","clk":"5348450302","pt":1646217824439,"mc":[{"id":"1.195453676","rc":[{"atl":[[2.22,0],[2.24,2]],"id":41788482}],"con":true,"img":false}]}
{"op":"mcm","clk":"5348450864","pt":1646217829415,"mc":[{"id":"1.195453676","rc":[{"atb":[[1.62,0],[1.55,2]],"id":41788482},{"atl":[[2.5,12],[2.58,4]],"id":37286329}],"con":true,"img":false}]}
{"op":"mcm","clk":"5348451126","pt":1646217831607,"mc":[{"id":"1.195453676","rc":[{"atl":[[2.26,2],[2.24,0]],"id":41788482}],"con":true,"img":false}]}
{"op":"mcm","clk":"5348451304","pt":1646217833237,"mc":[{"id":"1.195453676","rc":[{"atb":[[1.4,11],[1.5,0],[1.3,0]],"id":41788482},{"atb":[[2.04,0],[1.82,0],[1.92,0]],"id":37286329}],"con":true,"img":false}]}
{"op":"mcm","clk":"5348451327","pt":1646217833443,"mc":[{"id":"1.195453676","rc":[{"atb":[[1.79,0],[1.77,2]],"id":37286329}],"con":true,"img":false}]}
{"op":"mcm","clk":"5348451347","pt":1646217833658,"mc":[{"id":"1.195453676","rc":[{"atl":[[2.32,2],[2.26,0]],"id":41788482}],"con":true,"img":false}]}
{"op":"mcm","clk":"5348451459","pt":1646217834647,"mc":[{"id":"1.195453676","rc":[{"atb":[[1.58,2],[1.55,0]],"id":41788482}],"con":true,"img":false}]}
{"op":"mcm","clk":"5348451548","pt":1646217835452,"mc":[{"id":"1.195453676","rc":[{"atb":[[1.58,0],[1.56,2]],"id":41788482}],"con":true,"img":false}]}
{"op":"mcm","clk":"5348451893","pt":1646217838552,"mc":[{"id":"1.195453676","rc":[{"atb":[[1.74,2],[1.77,0]],"id":37286329}],"con":true,"img":false}]}
{"op":"mcm","clk":"5348451918","pt":1646217838763,"mc":[{"id":"1.195453676","rc":[{"atl":[[2.32,0],[2.3,2]],"id":41788482}],"con":true,"img":false}]}
{"op":"mcm","clk":"5348452296","pt":1646217842012,"mc":[{"id":"1.195453676","rc":[{"atb":[[1.56,0],[1.55,2]],"id":41788482}],"con":true,"img":false}]}
{"op":"mcm","clk":"5348452452","pt":1646217843653,"mc":[{"id":"1.195453676","rc":[{"atb":[[1.73,2],[1.74,0]],"id":37286329}],"con":true,"img":false}]}
{"op":"mcm","clk":"5348452475","pt":1646217843863,"mc":[{"id":"1.195453676","rc":[{"atl":[[2.3,0],[2.32,2]],"id":41788482}],"con":true,"img":false}]}
{"op":"mcm","clk":"5348452710","pt":1646217845966,"mc":[{"id":"1.195453676","rc":[{"atb":[[1.23,23.45],[1.33,16.34],[1.13,41.5]],"id":41788482},{"atb":[[2.32,4.08],[2.12,4.81]],"id":37286329},{"atl":[[2.5,8.45]],"id":37286329},{"trd":[[2.5,7.09]],"ltp":2.5,"tv":7.09,"id":37286329}],"con":true,"img":false}]}
{"op":"mcm","clk":"5348452846","pt":1646217847133,"mc":[{"id":"1.195453676","rc":[{"atb":[[1.57,2]],"id":41788482}],"con":true,"img":false}]}
{"op":"mcm","clk":"5348452859","pt":1646217847231,"mc":[{"id":"1.195453676","rc":[{"atb":[[1.55,0]],"id":41788482}],"con":true,"img":false}]}
{"op":"mcm","clk":"5348453026","pt":1646217848853,"mc":[{"id":"1.195453676","rc":[{"atb":[[1.73,0],[1.81,2]],"id":37286329}],"con":true,"img":false}]}
{"op":"mcm","clk":"5348453138","pt":1646217849849,"mc":[{"id":"1.195453676","rc":[{"atb":[[1.56,2],[1.57,0]],"id":41788482}],"con":true,"img":false}]}
{"op":"mcm","clk":"5348453682","pt":1646217854989,"mc":[{"id":"1.195453676","rc":[{"atb":[[1.58,2],[1.56,0]],"id":41788482}],"con":true,"img":false}]}
{"op":"mcm","clk":"5348453693","pt":1646217855037,"mc":[{"id":"1.195453676","rc":[{"atl":[[2.32,0],[2.3,2]],"id":41788482}],"con":true,"img":false}]}
{"op":"mcm","clk":"5348454003","pt":1646217858025,"mc":[{"id":"1.195453676","rc":[{"atb":[[2.32,0]],"id":37286329},{"atl":[[2.32,19.89]],"id":37286329},{"trd":[[2.32,8.17]],"ltp":2.32,"tv":8.17,"id":37286329}],"con":true,"img":false}]}
{"op":"mcm","clk":"5348454026","pt":1646217858187,"mc":[{"id":"1.195453676","rc":[{"atl":[[2.3,2],[2.58,2]],"id":37286329}],"con":true,"img":false}]}
{"op":"mcm","clk":"5348454226","pt":1646217860177,"mc":[{"id":"1.195453676","rc":[{"atb":[[1.58,0],[1.54,2]],"id":41788482},{"atl":[[2.3,0],[2.32,2]],"id":41788482}],"con":true,"img":false}]}
{"op":"mcm","clk":"5348454688","pt":1646217864248,"mc":[{"id":"1.195453676","rc":[{"atl":[[2.32,0]],"id":37286329}],"con":true,"img":false}]}
{"op":"mcm","clk":"5348454699","pt":1646217864352,"mc":[{"id":"1.195453676","rc":[{"atl":[[2.54,4],[2.48,19.89]],"id":37286329}],"con":true,"img":false}]}
{"op":"mcm","clk":"5348454713","pt":1646217864455,"mc":[{"id":"1.195453676","rc":[{"atl":[[2.3,0]],"id":37286329}],"con":true,"img":false}]}
{"op":"mcm","clk":"5348454821","pt":1646217865346,"mc":[{"id":"1.195453676","rc":[{"atb":[[1.58,2],[1.54,0]],"id":41788482},{"atl":[[2.32,0],[2.3,2]],"id":41788482}],"con":true,"img":false}]}
{"op":"mcm","clk":"5348455247","pt":1646217869480,"mc":[{"id":"1.195453676","rc":[{"atl":[[2.54,2],[2.46,2]],"id":37286329}],"con":true,"img":false}]}
{"op":"mcm","clk":"5348455356","pt":1646217870459,"mc":[{"id":"1.195453676","rc":[{"atb":[[1.58,0],[1.56,2]],"id":41788482}],"con":true,"img":false}]}
{"op":"mcm","clk":"5348455490","pt":1646217871658,"mc":[{"id":"1.195453676","rc":[{"atb":[[1.58,2],[1.56,0]],"id":41788482}],"con":true,"img":false}]}
{"op":"mcm","clk":"5348455978","pt":1646217875791,"mc":[{"id":"1.195453676","rc":[{"atb":[[1.58,0],[1.57,2]],"id":41788482}],"con":true,"img":false}]}
{"op":"mcm","clk":"5348456558","pt":1646217880885,"mc":[{"id":"1.195453676","rc":[{"atb":[[1.57,0]],"id":41788482}],"con":true,"img":false}]}
{"op":"mcm","clk":"5348456573","pt":1646217880988,"mc":[{"id":"1.195453676","rc":[{"atb":[[1.58,2]],"id":41788482}],"con":true,"img":false}]}
{"op":"mcm","clk":"5348456709","pt":1646217882193,"mc":[{"id":"1.195453676","rc":[{"atb":[[1.6,2],[1.58,0]],"id":41788482}],"con":true,"img":false}]}
{"op":"mcm","clk":"5348456722","pt":1646217882296,"mc":[{"id":"1.195453676","rc":[{"atb":[[1.58,2]],"id":41788482}],"con":true,"img":false}]}
{"op":"mcm","clk":"5348456735","pt":1646217882408,"mc":[{"id":"1.195453676","rc":[{"atb":[[1.6,0]],"id":41788482}],"con":true,"img":false}]}
{"op":"mcm","clk":"5348456904","pt":1646217883911,"mc":[{"id":"1.195453676","rc":[{"atb":[[1.58,0],[1.57,2]],"id":41788482}],"con":true,"img":false}]}
{"op":"mcm","clk":"5348457355","pt":1646217887919,"mc":[{"id":"1.195453676","rc":[{"atl":[[2.28,2]],"id":41788482}],"con":true,"img":false}]}
{"op":"mcm","clk":"5348457368","pt":1646217888023,"mc":[{"id":"1.195453676","rc":[{"atl":[[2.3,0]],"id":41788482}],"con":true,"img":false}]}
{"op":"mcm","clk":"5348457971","pt":1646217893634,"mc":[{"id":"1.195453676","rc":[{"atb":[[1.55,2]],"id":41788482}],"con":true,"img":false}]}
{"op":"mcm","clk":"5348457986","pt":1646217893740,"mc":[{"id":"1.195453676","rc":[{"atb":[[1.57,0]],"id":41788482}],"con":true,"img":false}]}
{"op":"mcm","clk":"5348458855","pt":1646217901142,"mc":[{"id":"1.195453676","rc":[{"atb":[[1.55,0],[1.54,2]],"id":41788482}],"con":true,"img":false}]}
{"op":"mcm","clk":"5348458878","pt":1646217901306,"mc":[{"id":"1.195453676","rc":[{"atb":[[1.54,12.38]],"id":41788482},{"atl":[[2.46,10.1]],"id":37286329}],"con":true,"img":false}]}
{"op":"mcm","clk":"5348458892","pt":1646217901407,"mc":[{"id":"1.195453676","rc":[{"atl":[[2.28,11.79]],"id":41788482},{"atb":[[1.81,10.62]],"id":37286329}],"con":true,"img":false}]}
{"op":"mcm","clk":"5348459486","pt":1646217906350,"mc":[{"id":"1.195453676","rc":[{"atb":[[1.55,2],[1.54,10.38]],"id":41788482}],"con":true,"img":false}]}
{"op":"mcm","clk":"5348459742","pt":1646217908616,"mc":[{"id":"1.195453676","rc":[{"atb":[[1.55,12.39]],"id":41788482}],"con":true,"img":false}]}
{"op":"mcm","clk":"5348461180","pt":1646217919969,"mc":[{"id":"1.195453676","rc":[{"atb":[[1.56,2],[1.55,10.39]],"id":41788482}],"con":true,"img":false}]}
{"op":"mcm","clk":"5348462639","pt":1646217931857,"mc":[{"id":"1.195453676","rc":[{"atb":[[1.56,12.31]],"id":41788482}],"con":true,"img":false}]}
{"op":"mcm","clk":"5348466191","pt":1646217961248,"mc":[{"id":"1.195453676","rc":[{"atl":[[2.48,0]],"id":37286329}],"con":true,"img":false}]}
{"op":"mcm","clk":"5348466200","pt":1646217961354,"mc":[{"id":"1.195453676","rc":[{"atl":[[2.44,19.89]],"id":37286329}],"con":true,"img":false}]}
{"op":"mcm","clk":"5348466223","pt":1646217961546,"mc":[{"id":"1.195453676","rc":[{"atl":[[2.42,2],[2.46,8.1]],"id":37286329}],"con":true,"img":false}]}
{"op":"mcm","clk":"5348466232","pt":1646217961620,"mc":[{"id":"1.195453676","rc":[{"atb":[[1.56,10.31],[1.57,2]],"id":41788482}],"con":true,"img":false}]}
{"op":"mcm","clk":"5348466243","pt":1646217961734,"mc":[{"id":"1.195453676","rc":[{"atl":[[2.42,10.25]],"id":37286329}],"con":true,"img":false}]}
{"op":"mcm","clk":"5348466524","pt":1646217963826,"mc":[{"id":"1.195453676","rc":[{"atb":[[1.57,12.21]],"id":41788482}],"con":true,"img":false}]}
{"op":"mcm","clk":"5348467560","pt":1646217971957,"mc":[{"id":"1.195453676","rc":[{"atb":[[1.58,2],[1.57,10.21]],"id":41788482}],"con":true,"img":false}]}
{"op":"mcm","clk":"5348467618","pt":1646217972371,"mc":[{"id":"1.195453676","rc":[{"atb":[[1.58,12.14],[1.54,0]],"id":41788482}],"con":true,"img":false}]}
{"op":"mcm","clk":"5348469140","pt":1646217985146,"mc":[{"id":"1.195453676","rc":[{"atb":[[1.59,2],[1.58,10.14]],"id":41788482}],"con":true,"img":false}]}
{"op":"mcm","clk":"5348469374","pt":1646217987394,"mc":[{"id":"1.195453676","rc":[{"atb":[[1.59,12.15]],"id":41788482}],"con":true,"img":false}]}
{"op":"mcm","clk":"5348469398","pt":1646217987551,"mc":[{"id":"1.195453676","rc":[{"atb":[[1.55,0]],"id":41788482}],"con":true,"img":false}]}
{"op":"mcm","clk":"5348472901","pt":1646218016723,"mc":[{"id":"1.195453676","rc":[{"atl":[[2.26,2],[2.28,9.79]],"id":41788482}],"con":true,"img":false}]}
{"op":"mcm","clk":"5348473073","pt":1646218018290,"mc":[{"id":"1.195453676","rc":[{"atl":[[2.26,11.95]],"id":41788482}],"con":true,"img":false}]}
{"op":"mcm","clk":"5348473442","pt":1646218021119,"mc":[{"id":"1.195453676","rc":[{"atl":[[2.26,9.95],[2.24,2]],"id":41788482}],"con":true,"img":false}]}
{"op":"mcm","clk":"5348473508","pt":1646218021594,"mc":[{"id":"1.195453676","rc":[{"atl":[[2.24,11.97]],"id":41788482}],"con":true,"img":false}]}
{"op":"mcm","clk":"5348473941","pt":1646218025526,"mc":[{"id":"1.195453676","rc":[{"atb":[[1.6,2]],"id":41788482}],"con":true,"img":false}]}
{"op":"mcm","clk":"5348473953","pt":1646218025638,"mc":[{"id":"1.195453676","rc":[{"atb":[[1.59,10.15]],"id":41788482}],"con":true,"img":false}]}
{"op":"mcm","clk":"5348474054","pt":1646218026314,"mc":[{"id":"1.195453676","rc":[{"atb":[[1.6,12.04]],"id":41788482}],"con":true,"img":false}]}
{"op":"mcm","clk":"5348474069","pt":1646218026418,"mc":[{"id":"1.195453676","rc":[{"atb":[[1.56,0]],"id":41788482}],"con":true,"img":false}]}
{"op":"mcm","clk":"5348474290","pt":1646218028251,"mc":[{"id":"1.195453676","rc":[{"atl":[[2.22,2]],"id":41788482}],"con":true,"img":false}]}
{"op":"mcm","clk":"5348474304","pt":1646218028355,"mc":[{"id":"1.195453676","rc":[{"atl":[[2.24,9.97]],"id":41788482}],"con":true,"img":false}]}
{"op":"mcm","clk":"5348474648","pt":1646218030734,"mc":[{"id":"1.195453676","rc":[{"atb":[[1.6,10.04],[1.61,2]],"id":41788482}],"con":true,"img":false}]}
{"op":"mcm","clk":"5348475237","pt":1646218035351,"mc":[{"id":"1.195453676","rc":[{"atb":[[1.61,12.02]],"id":41788482},{"atl":[[2.22,11.99]],"id":41788482}],"con":true,"img":false}]}
{"op":"mcm","clk":"5348475262","pt":1646218035560,"mc":[{"id":"1.195453676","rc":[{"atb":[[1.57,0]],"id":41788482}],"con":true,"img":false}]}
{"op":"mcm","clk":"5348475478","pt":1646218037332,"mc":[{"id":"1.195453676","rc":[{"atb":[[1.63,2],[1.61,10.02]],"id":41788482}],"con":true,"img":false}]}
{"op":"mcm","clk":"5348475527","pt":1646218037749,"mc":[{"id":"1.195453676","rc":[{"atb":[[1.63,11.84]],"id":41788482}],"con":true,"img":false}]}
{"op":"mcm","clk":"5348475546","pt":1646218037968,"mc":[{"id":"1.195453676","rc":[{"atb":[[1.58,0]],"id":41788482}],"con":true,"img":false}]}
{"op":"mcm","clk":"5348475956","pt":1646218041474,"mc":[{"id":"1.195453676","rc":[{"atb":[[1.23,0],[1.33,0],[1.13,0]],"id":41788482},{"atb":[[2.12,0]],"id":37286329}],"con":true,"img":false}]}
{"op":"mcm","clk":"5348476077","pt":1646218042486,"mc":[{"id":"1.195453676","rc":[{"atb":[[1.65,2]],"id":41788482}],"con":true,"img":false}]}
{"op":"mcm","clk":"5348476086","pt":1646218042545,"mc":[{"id":"1.195453676","rc":[{"atb":[[1.63,9.84]],"id":41788482}],"con":true,"img":false}]}
{"op":"mcm","clk":"5348476126","pt":1646218042862,"mc":[{"id":"1.195453676","rc":[{"atb":[[1.59,0],[1.65,11.86]],"id":41788482}],"con":true,"img":false}]}
{"op":"mcm","clk":"5348476425","pt":1646218045366,"mc":[{"id":"1.195453676","rc":[{"atl":[[2.22,9.99],[2.2,2]],"id":41788482}],"con":true,"img":false}]}
{"op":"mcm","clk":"5348476875","pt":1646218049083,"mc":[{"id":"1.195453676","rc":[{"atb":[[1.37,16.58],[1.27,19.98],[1.17,31.74]],"id":41788482},{"atb":[[1.99,5.44],[2.38,3.9],[2.18,4.57]],"id":37286329}],"con":true,"img":false}]}
{"op":"mcm","clk":"5348476894","pt":1646218049241,"mc":[{"id":"1.195453676","rc":[{"atl":[[2.28,0],[2.2,11.83]],"id":41788482},{"atb":[[2,8.54],[2.38,0]],"id":37286329},{"trd":[[2.38,7.8]],"ltp":2.38,"tv":7.8,"id":37286329}],"con":true,"img":false}]}
{"op":"mcm","clk":"5348476907","pt":1646218049349,"mc":[{"id":"1.195453676","rc":[{"atb":[[2.38,0]],"id":37286329},{"trd":[[2.38,7.81]],"ltp":2.38,"tv":7.81,"id":37286329}],"con":true,"img":false}]}
{"op":"mcm","clk":"5348477710","pt":1646218055688,"mc":[{"id":"1.195453676","rc":[{"atb":[[1.73,1.42]],"id":41788482},{"atl":[[2.38,1.42]],"id":37286329}],"con":true,"img":false}]}
{"op":"mcm","clk":"5348477741","pt":1646218055886,"mc":[{"id":"1.195453676","rc":[{"atb":[[1.73,3.42],[1.65,9.86]],"id":41788482},{"atl":[[2.42,8.25],[2.38,3.42]],"id":37286329}],"con":true,"img":false}]}
{"op":"mcm","clk":"5348477840","pt":1646218056686,"mc":[{"id":"1.195453676","rc":[{"atl":[[2.24,11.97],[2.2,9.83]],"id":41788482}],"con":true,"img":false}]}
{"op":"mcm","clk":"5348478059","pt":1646218058481,"mc":[{"id":"1.195453676","rc":[{"atl":[[2.36,8.51]],"id":37286329}],"con":true,"img":false}]}
{"op":"mcm","clk":"5348478086","pt":1646218058692,"mc":[{"id":"1.195453676","rc":[{"atb":[[1.71,1.42]],"id":41788482},{"atl":[[2.4,1.42]],"id":37286329}],"con":true,"img":false}]}
{"op":"mcm","clk":"5348478267","pt":1646218059996,"mc":[{"id":"1.195453676","rc":[{"atb":[[1.74,9.83]],"id":41788482}],"con":true,"img":false}]}
{"op":"mcm","clk":"5348478295","pt":1646218060164,"mc":[{"id":"1.195453676","rc":[{"atb":[[1.6,0]],"id":41788482}],"con":true,"img":false}]}
{"op":"mcm","clk":"5348478390","pt":1646218060997,"mc":[{"id":"1.195453676","rc":[{"atb":[[1.73,1.42],[1.74,11.25],[1.75,2]],"id":41788482},{"atl":[[2.34,3.42],[2.38,1.42]],"id":37286329}],"con":true,"img":false}]}
{"op":"mcm","clk":"5348478609","pt":1646218062572,"mc":[{"id":"1.195453676","rc":[{"atb":[[1.74,12.68]],"id":41788482},{"atl":[[2.34,4.84]],"id":37286329}],"con":true,"img":false}]}
{"op":"mcm","clk":"5348478800","pt":1646218064087,"mc":[{"id":"1.195453676","rc":[{"atb":[[1.75,11.83]],"id":41788482},{"atl":[[2.32,8.56]],"id":37286329}],"con":true,"img":false}]}
{"op":"mcm","clk":"5348478807","pt":1646218064187,"mc":[{"id":"1.195453676","rc":[{"atb":[[1.61,0]],"id":41788482}],"con":true,"img":false}]}
{"op":"mcm","clk":"5348478830","pt":1646218064397,"mc":[{"id":"1.195453676","rc":[{"atl":[[2.32,9.98]],"id":37286329}],"con":true,"img":false}]}
{"op":"mcm","clk":"5348479077","pt":1646218066180,"mc":[{"id":"1.195453676","rc":[{"atl":[[2.3,2],[2.34,2.84]],"id":37286329}],"con":true,"img":false}]}
{"op":"mcm","clk":"5348479127","pt":1646218066491,"mc":[{"id":"1.195453676","rc":[{"atl":[[2.4,0]],"id":37286329}],"con":true,"img":false}]}
{"op":"mcm","clk":"5348479258","pt":1646218067493,"mc":[{"id":"1.195453676","rc":[{"atl":[[2.32,11.4]],"id":37286329}],"con":true,"img":false}]}
{"op":"mcm","clk":"5348479650","pt":1646218070667,"mc":[{"id":"1.195453676","rc":[{"atl":[[2.3,10.44],[2.46,0]],"id":37286329}],"con":true,"img":false}]}
{"op":"mcm","clk":"5348480014","pt":1646218073496,"mc":[{"id":"1.195453676","rc":[{"atb":[[1.37,2],[1.27,0],[1.17,0]],"id":41788482},{"atb":[[1.99,0],[2.18,0]],"id":37286329}],"con":true,"img":false}]}
{"op":"mcm","clk":"5348480183","pt":1646218074808,"mc":[{"id":"1.195453676","rc":[{"atb":[[1.71,0]],"id":41788482}],"con":true,"img":false}]}
{"op":"mcm","clk":"5348480540","pt":1646218077487,"mc":[{"id":"1.195453676","rc":[{"atl":[[2.38,0]],"id":37286329}],"con":true,"img":false}]}
{"op":"mcm","clk":"5348480681","pt":1646218078579,"mc":[{"id":"1.195453676","rc":[{"atb":[[1.8,1.42]],"id":41788482},{"atl":[[2.28,1.42]],"id":37286329}],"con":true,"img":false}]}
{"op":"mcm","clk":"5348480707","pt":1646218078796,"mc":[{"id":"1.195453676","rc":[{"atb":[[1.8,3.42],[1.75,9.83]],"id":41788482}],"con":true,"img":false}]}
{"op":"mcm","clk":"5348480728","pt":1646218079005,"mc":[{"id":"1.195453676","rc":[{"atb":[[1.76,2],[1.8,1.42]],"id":41788482}],"con":true,"img":false}]}
{"op":"mcm","clk":"5348480866","pt":1646218080203,"mc":[{"id":"1.195453676","rc":[{"atl":[[2.34,0]],"id":37286329}],"con":true,"img":false}]}
{"op":"mcm","clk":"5348480991","pt":1646218081195,"mc":[{"id":"1.195453676","rc":[{"atb":[[1.8,2.84]],"id":41788482},{"atl":[[2.28,2.84]],"id":37286329}],"con":true,"img":false}]}
{"op":"mcm","clk":"5348481178","pt":1646218082819,"mc":[{"id":"1.195453676","rc":[{"atb":[[1.76,12.45],[1.63,0]],"id":41788482},{"atl":[[2.42,0],[2.28,10.97]],"id":37286329}],"con":true,"img":false}]}
{"op":"mcm","clk":"5348481197","pt":1646218082978,"mc":[{"id":"1.195453676","rc":[{"atl":[[2.3,8.44],[2.26,2]],"id":37286329}],"con":true,"img":false}]}
{"op":"mcm","clk":"5348481326","pt":1646218084125,"mc":[{"id":"1.195453676","rc":[{"atb":[[1.76,10.45],[1.8,4.84]],"id":41788482}],"con":true,"img":false}]}
{"op":"mcm","clk":"5348481394","pt":1646218084503,"mc":[{"id":"1.195453676","rc":[{"atb":[[1.81,1.42]],"id":41788482}],"con":true,"img":false}]}
{"op":"mcm","clk":"5348481774","pt":1646218087236,"mc":[{"id":"1.195453676","rc":[{"atb":[[1.28,21.27],[1.18,29.97],[1.8,3.74],[1.81,0],[1.38,30.19]],"id":41788482},{"trd":[[1.8,1.1],[1.81,1.42]],"ltp":1.8,"tv":2.52,"id":41788482},{"atb":[[2.14,4.73],[1.97,5.56]],"id":37286329},{"atl":[[2.26,0]],"id":37286329},{"trd":[[2.26,4.87],[2.24,1.14]],"ltp":2.26,"tv":6.01,"id":37286329}],"con":true,"img":false}]}
{"op":"mcm","clk":"5348481792","pt":1646218087389,"mc":[{"id":"1.195453676","rc":[{"atb":[[2.14,12.91],[2.16,8.18]],"id":37286329}],"con":true,"img":false}]}
{"op":"mcm","clk":"5348481860","pt":1646218088015,"mc":[{"id":"1.195453676","rc":[{"atb":[[1.8,13.98],[1.65,0]],"id":41788482},{"atb":[[2.14,4.73]],"id":37286329},{"atl":[[2.26,8.28],[2.36,0]],"id":37286329}],"con":true,"img":false}]}
{"op":"mcm","clk":"5348481909","pt":1646218088496,"mc":[{"id":"1.195453676","rc":[{"atb":[[1.81,10.19]],"id":41788482},{"atb":[[2.16,0]],"id":37286329}],"con":true,"img":false}]}
{"op":"mcm","clk":"5348481929","pt":1646218088706,"mc":[{"id":"1.195453676","rc":[{"atb":[[1.74,2.84]],"id":41788482}],"con":true,"img":false}]}
{"op":"mcm","clk":"5348481998","pt":1646218089286,"mc":[{"id":"1.195453676","rc":[{"atb":[[1.8,11.98],[1.82,2]],"id":41788482}],"con":true,"img":false}]}
{"op":"mcm","clk":"5348482013","pt":1646218089385,"mc":[{"id":"1.195453676","rc":[{"atb":[[2.14,13.1]],"id":37286329}],"con":true,"img":false}]}
{"op":"mcm","clk":"5348482085","pt":1646218090018,"mc":[{"id":"1.195453676","rc":[{"atb":[[1.84,1.42]],"id":41788482},{"atl":[[2.22,1.42]],"id":37286329}],"con":true,"img":false}]}
{"op":"mcm","clk":"5348482249","pt":1646218091310,"mc":[{"id":"1.195453676","rc":[{"atb":[[1.73,0],[1.74,0]],"id":41788482},{"atl":[[2.28,8.12]],"id":37286329}],"con":true,"img":false}]}
{"op":"mcm","clk":"5348482518","pt":1646218093401,"mc":[{"id":"1.195453676","rc":[{"atl":[[2.32,8.56]],"id":37286329}],"con":true,"img":false}]}
{"op":"mcm","clk":"5348482640","pt":1646218094394,"mc":[{"id":"1.195453676","rc":[{"atb":[[1.84,3.42],[1.82,0]],"id":41788482}],"con":true,"img":false}]}
{"op":"mcm","clk":"5348482653","pt":1646218094496,"mc":[{"id":"1.195453676","rc":[{"atb":[[2.16,8.33]],"id":37286329}],"con":true,"img":false}]}
{"op":"mcm","clk":"5348483088","pt":1646218098113,"mc":[{"id":"1.195453676","rc":[{"atb":[[1.84,2]],"id":41788482},{"atl":[[2.22,0]],"id":37286329}],"con":true,"img":false}]}
{"op":"mcm","clk":"5348483109","pt":1646218098323,"mc":[{"id":"1.195453676","rc":[{"atb":[[1.84,0],[1.82,2]],"id":41788482}],"con":true,"img":false}]}
{"op":"mcm","clk":"5348483246","pt":1646218099428,"mc":[{"id":"1.195453676","rc":[{"atl":[[2.26,11.95],[2.24,9.97]],"id":41788482},{"atb":[[1.81,8.62]],"id":37286329}],"con":true,"img":false}]}
{"op":"mcm","clk":"5348483274","pt":1646218099641,"mc":[{"id":"1.195453676","rc":[{"atb":[[1.76,2]],"id":37286329}],"con":true,"img":false}]}
{"op":"mcm","clk":"5348483865","pt":1646218104527,"mc":[{"id":"1.195453676","rc":[{"atb":[[2.16,0]],"id":37286329}],"con":true,"img":false}]}
{"op":"mcm","clk":"5348483893","pt":1646218104732,"mc":[{"id":"1.195453676","rc":[{"atb":[[1.82,11.92],[1.75,0]],"id":41788482},{"atb":[[2.14,4.73]],"id":37286329}],"con":true,"img":false}]}
{"op":"mcm","clk":"5348483972","pt":1646218105418,"mc":[{"id":"1.195453676","rc":[{"atb":[[2.14,13.16]],"id":37286329}],"con":true,"img":false}]}
{"op":"mcm","clk":"5348483985","pt":1646218105526,"mc":[{"id":"1.195453676","rc":[{"atl":[[2.2,29.51]],"id":41788482},{"atb":[[2.14,22.62]],"id":37286329}],"con":true,"img":false}]}
{"op":"mcm","clk":"5348484005","pt":1646218105732,"mc":[{"id":"1.195453676","rc":[{"atl":[[2.18,19.96]],"id":41788482}],"con":true,"img":false}]}
{"op":"mcm","clk":"5348484014","pt":1646218105836,"mc":[{"id":"1.195453676","rc":[{"atl":[[2.26,2]],"id":41788482}],"con":true,"img":false}]}
{"op":"mcm","clk":"5348484025","pt":1646218105946,"mc":[{"id":"1.195453676","rc":[{"atb":[[1.82,2]],"id":41788482}],"con":true,"img":false}]}
{"op":"mcm","clk":"5348484040","pt":1646218106050,"mc":[{"id":"1.195453676","rc":[{"atl":[[2.2,9.83]],"id":41788482}],"con":true,"img":false}]}
{"op":"mcm","clk":"5348484081","pt":1646218106306,"mc":[{"id":"1.195453676","rc":[{"atl":[[2.18,59.9]],"id":41788482}],"con":true,"img":false}]}
{"op":"mcm","clk":"5348484154","pt":1646218106943,"mc":[{"id":"1.195453676","rc":[{"atl":[[2.16,10.12]],"id":41788482},{"atb":[[2.16,8.32]],"id":37286329}],"con":true,"img":false}]}
{"op":"mcm","clk":"5348484180","pt":1646218107149,"mc":[{"id":"1.195453676","rc":[{"atl":[[2.18,19.96]],"id":41788482},{"atb":[[2.14,13.16]],"id":37286329}],"con":true,"img":false}]}
{"op":"mcm","clk":"5348484245","pt":1646218107621,"mc":[{"id":"1.195453676","rc":[{"atb":[[1.82,6]],"id":41788482},{"atl":[[2.16,20.28]],"id":41788482},{"atl":[[2.26,19.49]],"id":37286329}],"con":true,"img":false}]}
{"op":"mcm","clk":"5348484497","pt":1646218109713,"mc":[{"id":"1.195453676","rc":[{"atb":[[1.8,10.24]],"id":41788482}],"con":true,"img":false}]}
{"op":"mcm","clk":"5348484611","pt":1646218110653,"mc":[{"id":"1.195453676","rc":[{"atb":[[1.77,37.88]],"id":41788482},{"atb":[[2.02,28.6]],"id":37286329}],"con":true,"img":false}]}
{"op":"mcm","clk":"5348484777","pt":1646218112048,"mc":[{"id":"1.195453676","rc":[{"atb":[[1.82,16.13]],"id":41788482},{"atb":[[2.16,0]],"id":37286329},{"atl":[[2.24,8.3]],"id":37286329}],"con":true,"img":false}]}
{"op":"mcm","clk":"5348484804","pt":1646218112249,"mc":[{"id":"1.195453676","rc":[{"atl":[[2.14,10.06],[2.24,0]],"id":41788482},{"atl":[[2.32,0]],"id":37286329}],"con":true,"img":false}]}
{"op":"mcm","clk":"5348484829","pt":1646218112461,"mc":[{"id":"1.195453676","rc":[{"atl":[[2.26,8.28]],"id":37286329}],"con":true,"img":false}]}
{"op":"mcm","clk":"5348484846","pt":1646218112564,"mc":[{"id":"1.195453676","rc":[{"atl":[[2.16,10.12]],"id":41788482}],"con":true,"img":false}]}
{"op":"mcm","clk":"5348484861","pt":1646218112665,"mc":[{"id":"1.195453676","rc":[{"atl":[[2.14,20.22]],"id":41788482},{"atb":[[2.02,0],[1.88,33.15]],"id":37286329}],"con":true,"img":false}]}
{"op":"mcm","clk":"5348484878","pt":1646218112718,"mc":[{"id":"1.195453676","rc":[{"atl":[[2.24,19.16]],"id":37286329}],"con":true,"img":false}]}
{"op":"mcm","clk":"5348484938","pt":1646218113138,"mc":[{"id":"1.195453676","rc":[{"atl":[[2.3,0],[2.22,8.34]],"id":37286329}],"con":true,"img":false}]}
{"op":"mcm","clk":"5348484980","pt":1646218113453,"mc":[{"id":"1.195453676","rc":[{"atl":[[2.24,8.3]],"id":37286329}],"con":true,"img":false}]}
{"op":"mcm","clk":"5348484997","pt":1646218113556,"mc":[{"id":"1.195453676","rc":[{"atl":[[2.22,19.2]],"id":37286329}],"con":true,"img":false}]}
{"op":"mcm","clk":"5348485391","pt":1646218116941,"mc":[{"id":"1.195453676","rc":[{"atb":[[1.83,10.04]],"id":41788482}],"con":true,"img":false}]}
{"op":"mcm","clk":"5348485413","pt":1646218117162,"mc":[{"id":"1.195453676","rc":[{"atb":[[1.84,2],[1.76,0],[1.82,14.13]],"id":41788482},{"atl":[[2.4,1.42]],"id":37286329}],"con":true,"img":false}]}
{"op":"mcm","clk":"5348485418","pt":1646218117239,"mc":[{"id":"1.195453676","rc":[{"atb":[[1.82,10.13]],"id":41788482}],"con":true,"img":false}]}
{"op":"mcm","clk":"5348485432","pt":1646218117344,"mc":[{"id":"1.195453676","rc":[{"atb":[[2.14,4.73]],"id":37286329},{"atl":[[2.28,0],[2.2,8.41]],"id":37286329}],"con":true,"img":false}]}
{"op":"mcm","clk":"5348485441","pt":1646218117508,"mc":[{"id":"1.195453676","rc":[{"atl":[[2.2,10.41]],"id":37286329}],"con":true,"img":false}]}
{"op":"mcm","clk":"5348485451","pt":1646218117552,"mc":[{"id":"1.195453676","rc":[{"atb":[[1.84,6]],"id":41788482}],"con":true,"img":false}]}
{"op":"mcm","clk":"5348485461","pt":1646218117655,"mc":[{"id":"1.195453676","rc":[{"atb":[[1.79,36.92]],"id":41788482},{"atl":[[2.22,8.34]],"id":37286329}],"con":true,"img":false}]}
{"op":"mcm","clk":"5348485476","pt":1646218117760,"mc":[{"id":"1.195453676","rc":[{"atl":[[2.2,21.27]],"id":37286329}],"con":true,"img":false}]}
{"op":"mcm","clk":"5348485513","pt":1646218118020,"mc":[{"id":"1.195453676","rc":[{"atl":[[2.14,10.06]],"id":41788482},{"atl":[[2.2,10.41]],"id":37286329}],"con":true,"img":false}]}
{"op":"mcm","clk":"5348485542","pt":1646218118335,"mc":[{"id":"1.195453676","rc":[{"atl":[[2.2,23.66]],"id":37286329}],"con":true,"img":false}]}
{"op":"mcm","clk":"5348485563","pt":1646218118540,"mc":[{"id":"1.195453676","rc":[{"atl":[[2.4,2.84]],"id":37286329}],"con":true,"img":false}]}
{"op":"mcm","clk":"5348485636","pt":1646218119163,"mc":[{"id":"1.195453676","rc":[{"atb":[[1.84,15.97],[1.8,0]],"id":41788482}],"con":true,"img":false}]}
{"op":"mcm","clk":"5348485651","pt":1646218119276,"mc":[{"id":"1.195453676","rc":[{"atb":[[1.83,0],[1.84,6]],"id":41788482},{"atl":[[2.2,15.25]],"id":37286329}],"con":true,"img":false}]}
{"op":"mcm","clk":"5348485706","pt":1646218119632,"mc":[{"id":"1.195453676","rc":[{"atl":[[2.2,6]],"id":37286329}],"con":true,"img":false}]}
{"op":"mcm","clk":"5348485722","pt":1646218119733,"mc":[{"id":"1.195453676","rc":[{"atl":[[2.14,19.15]],"id":41788482}],"con":true,"img":false}]}
{"op":"mcm","clk":"5348485752","pt":1646218120047,"mc":[{"id":"1.195453676","rc":[{"atl":[[2.14,10.06]],"id":41788482}],"con":true,"img":false}]}
{"op":"mcm","clk":"5348485781","pt":1646218120261,"mc":[{"id":"1.195453676","rc":[{"atl":[[2.14,19.15]],"id":41788482}],"con":true,"img":false}]}
{"op":"mcm","clk":"5348485791","pt":1646218120364,"mc":[{"id":"1.195453676","rc":[{"atb":[[1.78,1.42]],"id":41788482},{"atl":[[2.32,1.42]],"id":37286329}],"con":true,"img":false}]}
{"op":"mcm","clk":"5348485808","pt":1646218120573,"mc":[{"id":"1.195453676","rc":[{"atb":[[1.82,0]],"id":41788482},{"atl":[[2.22,0],[2.12,20.18]],"id":41788482},{"atb":[[2.16,8.34]],"id":37286329},{"atl":[[2.22,0]],"id":37286329}],"con":true,"img":false}]}
{"op":"mcm","clk":"5348485831","pt":1646218120731,"mc":[{"id":"1.195453676","rc":[{"atl":[[2.44,0]],"id":37286329}],"con":true,"img":false}]}
{"op":"mcm","clk":"5348485842","pt":1646218120833,"mc":[{"id":"1.195453676","rc":[{"atb":[[2.14,0],[2.16,0]],"id":37286329},{"atl":[[2.14,6.81]],"id":37286329},{"trd":[[2.14,9.46],[2.16,16.68]],"ltp":2.14,"tv":26.14,"id":37286329}],"con":true,"img":false}]}
{"op":"mcm","clk":"5348485855","pt":1646218120937,"mc":[{"id":"1.195453676","rc":[{"atl":[[2.14,10.06]],"id":41788482}],"con":true,"img":false}]}
{"op":"mcm","clk":"5348485869","pt":1646218121041,"mc":[{"id":"1.195453676","rc":[{"atb":[[1.85,10.09]],"id":41788482},{"atl":[[2.12,29.27]],"id":41788482},{"atl":[[2.18,8.35]],"id":37286329}],"con":true,"img":false}]}
{"op":"mcm","clk":"5348485884","pt":1646218121147,"mc":[{"id":"1.195453676","rc":[{"atb":[[1.9,32.41]],"id":37286329}],"con":true,"img":false}]}
{"op":"mcm","clk":"5348485905","pt":1646218121354,"mc":[{"id":"1.195453676","rc":[{"atb":[[1.84,2]],"id":41788482}],"con":true,"img":false}]}
{"op":"mcm","clk":"5348485940","pt":1646218121667,"mc":[{"id":"1.195453676","rc":[{"atb":[[1.77,0]],"id":41788482}],"con":true,"img":false}]}
{"op":"mcm","clk":"5348485954","pt":1646218121772,"mc":[{"id":"1.195453676","rc":[{"atb":[[1.85,0]],"id":41788482},{"atl":[[2.1,10.08]],"id":41788482}],"con":true,"img":false}]}
{"op":"mcm","clk":"5348485966","pt":1646218121876,"mc":[{"id":"1.195453676","rc":[{"atl":[[2.2,0]],"id":41788482}],"con":true,"img":false}]}
{"op":"mcm","clk":"5348485977","pt":1646218121981,"mc":[{"id":"1.195453676","rc":[{"atb":[[1.78,2.84]],"id":41788482}],"con":true,"img":false}]}
{"op":"mcm","clk":"5348486006","pt":1646218122136,"mc":[{"id":"1.195453676","rc":[{"atb":[[1.82,35.57]],"id":41788482},{"atl":[[2.12,20.18]],"id":41788482}],"con":true,"img":false}]}
{"op":"mcm","clk":"5348486017","pt":1646218122240,"mc":[{"id":"1.195453676","rc":[{"atb":[[1.84,0],[1.82,37.57]],"id":41788482}],"con":true,"img":false}]}
{"op":"mcm","clk":"5348486038","pt":1646218122446,"mc":[{"id":"1.195453676","rc":[{"atl":[[2.1,21.39]],"id":41788482}],"con":true,"img":false}]}
{"op":"mcm","clk":"5348486049","pt":1646218122553,"mc":[{"id":"1.195453676","rc":[{"atb":[[1.82,44.7]],"id":41788482}],"con":true,"img":false}]}
{"op":"mcm","clk":"5348486062","pt":1646218122658,"mc":[{"id":"1.195453676","rc":[{"atl":[[2.32,0],[2.14,8.81],[2.4,0],[2.2,4]],"id":37286329}],"con":true,"img":false}]}
{"op":"mcm","clk":"5348486076","pt":1646218122763,"mc":[{"id":"1.195453676","rc":[{"atl":[[2.08,10.09],[2.18,9.98]],"id":41788482}],"con":true,"img":false}]}
{"op":"mcm","clk":"5348486086","pt":1646218122867,"mc":[{"id":"1.195453676","rc":[{"atb":[[1.83,10.14]],"id":41788482}],"con":true,"img":false}]}
{"op":"mcm","clk":"5348486111","pt":1646218123074,"mc":[{"id":"1.195453676","rc":[{"atb":[[1.84,36.73],[1.82,42.7]],"id":41788482},{"atl":[[2.1,10.08]],"id":41788482}],"con":true,"img":false}]}
{"op":"mcm","clk":"5348486125","pt":1646218123178,"mc":[{"id":"1.195453676","rc":[{"atb":[[1.82,35.57]],"id":41788482},{"atl":[[2.08,21.4]],"id":41788482}],"con":true,"img":false}]}
{"op":"mcm","clk":"5348486134","pt":1646218123231,"mc":[{"id":"1.195453676","rc":[{"atb":[[1.83,17.27]],"id":41788482}],"con":true,"img":false}]}
{"op":"mcm","clk":"5348486171","pt":1646218123654,"mc":[{"id":"1.195453676","rc":[{"atb":[[1.9,33.84]],"id":37286329}],"con":true,"img":false}]}
{"op":"mcm","clk":"5348486182","pt":1646218123752,"mc":[{"id":"1.195453676","rc":[{"atl":[[2.06,10.37]],"id":41788482},{"atl":[[2.26,0],[2.24,0]],"id":37286329}],"con":true,"img":false}]}
{"op":"mcm","clk":"5348486190","pt":1646218123854,"mc":[{"id":"1.195453676","rc":[{"atb":[[1.83,7.13],[1.81,0]],"id":41788482},{"atl":[[2.14,0]],"id":41788482},{"atl":[[2.18,0]],"id":37286329}],"con":true,"img":false}]}
{"op":"mcm","clk":"5348486211","pt":1646218124069,"mc":[{"id":"1.195453676","rc":[{"atb":[[1.84,2],[1.78,0],[1.82,0],[1.79,0]],"id":41788482},{"atl":[[2.08,10.09]],"id":41788482},{"atb":[[1.93,31.36]],"id":37286329}],"con":true,"img":false}]}
{"op":"mcm","clk":"5348486223","pt":1646218124170,"mc":[{"id":"1.195453676","rc":[{"atl":[[2.06,21.68]],"id":41788482}],"con":true,"img":false}]}
{"op":"mcm","clk":"5348486231","pt":1646218124275,"mc":[{"id":"1.195453676","rc":[{"atb":[[1.41,10.51]],"id":41788482}],"con":true,"img":false}]}
{"op":"mcm","clk":"5348486252","pt":1646218124483,"mc":[{"id":"1.195453676","rc":[{"atl":[[2.04,10.49],[2.12,10.09]],"id":41788482}],"con":true,"img":false}]}
{"op":"mcm","clk":"5348486276","pt":1646218124642,"mc":[{"id":"1.195453676","rc":[{"atb":[[1.88,0]],"id":37286329},{"atl":[[2.48,16.06]],"id":37286329}],"con":true,"img":false}]}
{"op":"mcm","clk":"5348486290","pt":1646218124747,"mc":[{"id":"1.195453676","rc":[{"atl":[[2.06,10.37]],"id":41788482}],"con":true,"img":false}]}
{"op":"mcm","clk":"5348486301","pt":1646218124853,"mc":[{"id":"1.195453676","rc":[{"atl":[[2.04,21.8]],"id":41788482}],"con":true,"img":false}]}
{"op":"mcm","clk":"5348486339","pt":1646218125164,"mc":[{"id":"1.195453676","rc":[{"atb":[[1.83,0],[1.68,42.9]],"id":41788482},{"atl":[[2.04,10.49],[2.02,10.43],[2.2,1.42]],"id":41788482},{"atb":[[1.93,32.79],[1.95,30.71]],"id":37286329},{"atl":[[2.2,0]],"id":37286329}],"con":true,"img":false}]}
{"op":"mcm","clk":"5348486348","pt":1646218125266,"mc":[{"id":"1.195453676","rc":[{"atl":[[2.1,0]],"id":41788482}],"con":true,"img":false}]}
{"op":"mcm","clk":"5348486383","pt":1646218125578,"mc":[{"id":"1.195453676","rc":[{"atb":[[1.69,10.5]],"id":41788482}],"con":true,"img":false}]}
{"op":"mcm","clk":"5348486393","pt":1646218125682,"mc":[{"id":"1.195453676","rc":[{"atb":[[1.68,0]],"id":41788482}],"con":true,"img":false}]}
{"op":"mcm","clk":"5348486416","pt":1646218125841,"mc":[{"id":"1.195453676","rc":[{"atb":[[1.84,6]],"id":41788482},{"atl":[[2.14,17.19]],"id":37286329}],"con":true,"img":false}]}
{"op":"mcm","clk":"5348486427","pt":1646218125945,"mc":[{"id":"1.195453676","rc":[{"atl":[[2.14,8.83]],"id":37286329},{"trd":[[2.14,26.19]],"ltp":2.14,"tv":26.19,"id":37286329}],"con":true,"img":false}]}
{"op":"mcm","clk":"5348486450","pt":1646218126155,"mc":[{"id":"1.195453676","rc":[{"atb":[[1.84,2],[1.7,41.68]],"id":41788482},{"atl":[[2.14,0.44]],"id":37286329}],"con":true,"img":false}]}
{"op":"mcm","clk":"5348486482","pt":1646218126466,"mc":[{"id":"1.195453676","rc":[{"atb":[[1.84,6]],"id":41788482},{"atl":[[2.48,36.21]],"id":37286329}],"con":true,"img":false}]}
{"op":"mcm","clk":"5348486492","pt":1646218126573,"mc":[{"id":"1.195453676","rc":[{"atb":[[1.7,0]],"id":41788482},{"atb":[[2,15.93],[1.9,1.42]],"id":37286329}],"con":true,"img":false}]}
{"op":"mcm","clk":"5348486506","pt":1646218126680,"mc":[{"id":"1.195453676","rc":[{"atb":[[1.71,10.41]],"id":41788482},{"atl":[[2.46,8.13]],"id":37286329}],"con":true,"img":false}]}
{"op":"mcm","clk":"5348486519","pt":1646218126780,"mc":[{"id":"1.195453676","rc":[{"atb":[[1.84,2]],"id":41788482},{"atl":[[2.2,2.84]],"id":41788482},{"atb":[[1.93,34.21]],"id":37286329}],"con":true,"img":false}]}
{"op":"mcm","clk":"5348486546","pt":1646218126993,"mc":[{"id":"1.195453676","rc":[{"atl":[[2.48,16.06]],"id":37286329}],"con":true,"img":false}]}
{"op":"mcm","clk":"5348486559","pt":1646218127045,"mc":[{"id":"1.195453676","rc":[{"atl":[[2.46,28.28]],"id":37286329}],"con":true,"img":false}]}
{"op":"mcm","clk":"5348486572","pt":1646218127149,"mc":[{"id":"1.195453676","rc":[{"atb":[[1.68,42.9]],"id":41788482},{"atb":[[1.98,29.76]],"id":37286329}],"con":true,"img":false}]}
{"op":"mcm","clk":"5348486619","pt":1646218127461,"mc":[{"id":"1.195453676","rc":[{"atl":[[2.44,8.13]],"id":37286329}],"con":true,"img":false}]}
{"op":"mcm","clk":"5348486663","pt":1646218127874,"mc":[{"id":"1.195453676","rc":[{"atl":[[2.46,8.13]],"id":37286329}],"con":true,"img":false}]}
{"op":"mcm","clk":"5348486674","pt":1646218127978,"mc":[{"id":"1.195453676","rc":[{"atl":[[2.44,28.28]],"id":37286329}],"con":true,"img":false}]}
{"op":"mcm","clk":"5348486693","pt":1646218128135,"mc":[{"id":"1.195453676","rc":[{"atb":[[1.84,0],[1.72,2]],"id":41788482}],"con":true,"img":false}]}
{"op":"mcm","clk":"5348486707","pt":1646218128238,"mc":[{"id":"1.195453676","rc":[{"atl":[[1.99,1.42]],"id":41788482},{"atb":[[1.99,1.42]],"id":37286329}],"con":true,"img":false}]}
{"op":"mcm","clk":"5348486719","pt":1646218128343,"mc":[{"id":"1.195453676","rc":[{"atb":[[1.84,4]],"id":41788482},{"atb":[[2,8.54]],"id":37286329}],"con":true,"img":false}]}
{"op":"mcm","clk":"5348486729","pt":1646218128444,"mc":[{"id":"1.195453676","rc":[{"atb":[[1.72,12.38]],"id":41788482},{"atl":[[2.42,8.15]],"id":37286329}],"con":true,"img":false}]}
{"op":"mcm","clk":"5348486737","pt":1646218128555,"mc":[{"id":"1.195453676","rc":[{"atb":[[1.68,0]],"id":41788482}],"con":true,"img":false}]}
{"op":"mcm","clk":"5348486751","pt":1646218128660,"mc":[{"id":"1.195453676","rc":[{"atb":[[1.98,0]],"id":37286329}],"con":true,"img":false}]}
{"op":"mcm","clk":"5348486762","pt":1646218128764,"mc":[{"id":"1.195453676","rc":[{"atb":[[1.84,0]],"id":41788482},{"atl":[[2.44,8.13]],"id":37286329}],"con":true,"img":false}]}
{"op":"mcm","clk":"5348486774","pt":1646218128871,"mc":[{"id":"1.195453676","rc":[{"atl":[[2.42,28.3]],"id":37286329}],"con":true,"img":false}]}
{"op":"mcm","clk":"5348486796","pt":1646218129078,"mc":[{"id":"1.195453676","rc":[{"atb":[[1.72,37.14]],"id":41788482}],"con":true,"img":false}]}
{"op":"mcm","clk":"5348486824","pt":1646218129294,"mc":[{"id":"1.195453676","rc":[{"atb":[[1.71,51.51]],"id":41788482},{"atb":[[1.97,35.64]],"id":37286329},{"atl":[[2.48,8.03],[2.4,8.16]],"id":37286329}],"con":true,"img":false}]}
{"op":"mcm","clk":"5348486843","pt":1646218129393,"mc":[{"id":"1.195453676","rc":[{"atb":[[1.72,12.38]],"id":41788482}],"con":true,"img":false}]}
{"op":"mcm","clk":"5348486879","pt":1646218129652,"mc":[{"id":"1.195453676","rc":[{"atb":[[1.73,1.42],[1.72,37.14]],"id":41788482},{"atl":[[1.97,1.42]],"id":41788482},{"atb":[[2.02,1.42]],"id":37286329},{"atl":[[2.42,8.15]],"id":37286329}],"con":true,"img":false}]}
{"op":"mcm","clk":"5348486896","pt":1646218129756,"mc":[{"id":"1.195453676","rc":[{"atl":[[2.4,28.31]],"id":37286329}],"con":true,"img":false}]}
{"op":"mcm","clk":"5348486924","pt":1646218129967,"mc":[{"id":"1.195453676","rc":[{"atb":[[1.72,12.38]],"id":41788482}],"con":true,"img":false}]}
{"op":"mcm","clk":"5348486937","pt":1646218130069,"mc":[{"id":"1.195453676","rc":[{"atb":[[1.73,26.18]],"id":41788482}],"con":true,"img":false}]}
{"op":"mcm","clk":"5348486974","pt":1646218130378,"mc":[{"id":"1.195453676","rc":[{"atb":[[1.73,4.26]],"id":41788482}],"con":true,"img":false}]}
{"op":"mcm","clk":"5348486985","pt":1646218130484,"mc":[{"id":"1.195453676","rc":[{"atb":[[1.41,0],[1.74,20.24]],"id":41788482},{"atl":[[2.38,16.69],[2.46,0]],"id":37286329}],"con":true,"img":false}]}
{"op":"mcm","clk":"5348486997","pt":1646218130586,"mc":[{"id":"1.195453676","rc":[{"atl":[[2.08,0],[1.97,11.39]],"id":41788482}],"con":true,"img":false}]}
{"op":"mcm","clk":"5348487021","pt":1646218130747,"mc":[{"id":"1.195453676","rc":[{"atl":[[2.4,8.16]],"id":37286329}],"con":true,"img":false}]}
{"op":"mcm","clk":"5348487031","pt":1646218130850,"mc":[{"id":"1.195453676","rc":[{"atb":[[1.73,1.42]],"id":41788482},{"atl":[[2.14,8.93],[2.38,36.84]],"id":37286329}],"con":true,"img":false}]}
{"op":"mcm","clk":"5348487042","pt":1646218130964,"mc":[{"id":"1.195453676","rc":[{"atl":[[2.44,0]],"id":37286329}],"con":true,"img":false}]}
{"op":"mcm","clk":"5348487052","pt":1646218131057,"mc":[{"id":"1.195453676","rc":[{"atb":[[1.73,42.81]],"id":41788482},{"atl":[[1.97,12.81]],"id":41788482},{"atb":[[2.04,1.42]],"id":37286329}],"con":true,"img":false}]}
{"op":"mcm","clk":"5348487066","pt":1646218131163,"mc":[{"id":"1.195453676","rc":[{"atb":[[1.74,35.89]],"id":41788482}],"con":true,"img":false}]}
{"op":"mcm","clk":"5348487073","pt":1646218131266,"mc":[{"id":"1.195453676","rc":[{"atl":[[1.96,9.85],[2.06,0]],"id":41788482}],"con":true,"img":false}]}
{"op":"mcm","clk":"5348487086","pt":1646218131370,"mc":[{"id":"1.195453676","rc":[{"atl":[[2.14,0.44]],"id":37286329}],"con":true,"img":false}]}
{"op":"mcm","clk":"5348487114","pt":1646218131682,"mc":[{"id":"1.195453676","rc":[{"atb":[[1.69,0],[1.75,19.9]],"id":41788482},{"atb":[[1.93,2.84]],"id":37286329},{"atl":[[2.36,16.94]],"id":37286329}],"con":true,"img":false}]}
{"op":"mcm","clk":"5348487150","pt":1646218131942,"mc":[{"id":"1.195453676","rc":[{"atb":[[1.74,20.24]],"id":41788482},{"atl":[[2.38,16.69]],"id":37286329}],"con":true,"img":false}]}
{"op":"mcm","clk":"5348487161","pt":1646218132048,"mc":[{"id":"1.195453676","rc":[{"atl":[[2.36,37.09]],"id":37286329}],"con":true,"img":false}]}
{"op":"mcm","clk":"5348487173","pt":1646218132152,"mc":[{"id":"1.195453676","rc":[{"atb":[[1.75,58.8]],"id":41788482},{"atb":[[2.02,30.02]],"id":37286329}],"con":true,"img":false}]}
{"op":"mcm","clk":"5348487184","pt":1646218132258,"mc":[{"id":"1.195453676","rc":[{"atb":[[1.75,80.46]],"id":41788482}],"con":true,"img":false}]}
{"op":"mcm","clk":"5348487238","pt":1646218132672,"mc":[{"id":"1.195453676","rc":[{"atb":[[1.77,1.42]],"id":41788482},{"atl":[[1.95,1.42]],"id":41788482},{"atb":[[2.04,2.84]],"id":37286329},{"atl":[[2.3,1.42]],"id":37286329}],"con":true,"img":false}]}
{"op":"mcm","clk":"5348487283","pt":1646218133088,"mc":[{"id":"1.195453676","rc":[{"atb":[[1.75,58.8]],"id":41788482},{"atl":[[2.36,16.94]],"id":37286329}],"con":true,"img":false}]}
{"op":"mcm","clk":"5348487293","pt":1646218133196,"mc":[{"id":"1.195453676","rc":[{"atb":[[1.71,41.09],[1.77,42.98]],"id":41788482},{"atl":[[2.04,0],[1.95,11.23]],"id":41788482},{"atl":[[2.3,38.52],[2.42,0]],"id":37286329}],"con":true,"img":false}]}
{"op":"mcm","clk":"5348487305","pt":1646218133249,"mc":[{"id":"1.195453676","rc":[{"atb":[[1.28,2],[1.18,0],[1.72,10.38],[1.77,44.98],[1.38,16]],"id":41788482},{"atb":[[1.97,30.07]],"id":37286329}],"con":true,"img":false}]}
{"op":"mcm","clk":"5348487328","pt":1646218133459,"mc":[{"id":"1.195453676","rc":[{"atb":[[1.77,23.32]],"id":41788482},{"atl":[[2.3,18.37]],"id":37286329}],"con":true,"img":false}]}
{"op":"mcm","clk":"5348487341","pt":1646218133562,"mc":[{"id":"1.195453676","rc":[{"atb":[[1.71,0]],"id":41788482},{"atl":[[2.36,37.09]],"id":37286329}],"con":true,"img":false}]}
{"op":"mcm","clk":"5348487364","pt":1646218133770,"mc":[{"id":"1.195453676","rc":[{"atb":[[1.77,45.44]],"id":41788482}],"con":true,"img":false}]}
{"op":"mcm","clk":"5348487376","pt":1646218133876,"mc":[{"id":"1.195453676","rc":[{"atl":[[2.36,16.94]],"id":37286329}],"con":true,"img":false}]}
{"op":"mcm","clk":"5348487388","pt":1646218133983,"mc":[{"id":"1.195453676","rc":[{"atl":[[2.3,38.52]],"id":37286329}],"con":true,"img":false}]}
{"op":"mcm","clk":"5348487403","pt":1646218134085,"mc":[{"id":"1.195453676","rc":[{"atb":[[1.78,37.4],[1.8,1.42],[1.77,25.74]],"id":41788482},{"atl":[[1.93,1.42]],"id":41788482},{"atb":[[2.08,1.42]],"id":37286329},{"atl":[[2.26,1.42]],"id":37286329}],"con":true,"img":false}]}
{"op":"mcm","clk":"5348487424","pt":1646218134291,"mc":[{"id":"1.195453676","rc":[{"atl":[[2.3,18.37]],"id":37286329}],"con":true,"img":false}]}
{"op":"mcm","clk":"5348487436","pt":1646218134397,"mc":[{"id":"1.195453676","rc":[{"atb":[[1.77,23.32]],"id":41788482},{"atl":[[2.36,37.09]],"id":37286329}],"con":true,"img":false}]}
{"op":"mcm","clk":"5348487473","pt":1646218134657,"mc":[{"id":"1.195453676","rc":[{"atb":[[1.78,0],[1.8,24.14],[1.72,0]],"id":41788482},{"atl":[[2.26,9.9],[2.14,8.93],[2.48,0],[2.4,0]],"id":37286329}],"con":true,"img":false}]}
{"op":"mcm","clk":"5348487483","pt":1646218134760,"mc":[{"id":"1.195453676","rc":[{"atb":[[1.81,9.92],[1.74,10.12]],"id":41788482}],"con":true,"img":false}]}
{"op":"mcm","clk":"5348487520","pt":1646218135069,"mc":[{"id":"1.195453676","rc":[{"atb":[[1.8,21.3],[1.81,45.95]],"id":41788482}],"con":true,"img":false}]}
{"op":"mcm","clk":"5348487553","pt":1646218135381,"mc":[{"id":"1.195453676","rc":[{"atb":[[1.82,9.86],[1.74,0]],"id":41788482}],"con":true,"img":false}]}
{"op":"mcm","clk":"5348487592","pt":1646218135694,"mc":[{"id":"1.195453676","rc":[{"atb":[[1.82,20.99],[1.81,47.37]],"id":41788482},{"atl":[[1.91,1.42]],"id":41788482},{"atb":[[2.1,1.42]],"id":37286329},{"atl":[[2.22,1.42]],"id":37286329}],"con":true,"img":false}]}
{"op":"mcm","clk":"5348487604","pt":1646218135798,"mc":[{"id":"1.195453676","rc":[{"atl":[[1.95,1.42]],"id":41788482}],"con":true,"img":false}]}
{"op":"mcm","clk":"5348487626","pt":1646218135955,"mc":[{"id":"1.195453676","rc":[{"atb":[[1.83,9.76],[1.75,48.85]],"id":41788482}],"con":true,"img":false}]}
{"op":"mcm","clk":"5348487664","pt":1646218136270,"mc":[{"id":"1.195453676","rc":[{"atb":[[1.82,9.86]],"id":41788482}],"con":true,"img":false}]}
{"op":"mcm","clk":"5348487677","pt":1646218136375,"mc":[{"id":"1.195453676","rc":[{"atb":[[1.83,20.89]],"id":41788482}],"con":true,"img":false}]}
{"op":"mcm","clk":"5348487699","pt":1646218136583,"mc":[{"id":"1.195453676","rc":[{"atb":[[1.73,2.84],[1.84,19.52]],"id":41788482}],"con":true,"img":false}]}
{"op":"mcm","clk":"5348487723","pt":1646218136791,"mc":[{"id":"1.195453676","rc":[{"atb":[[1.77,13.37],[1.75,38.9]],"id":41788482}],"con":true,"img":false}]}
{"op":"mcm","clk":"5348487736","pt":1646218136894,"mc":[{"id":"1.195453676","rc":[{"atl":[[1.96,0]],"id":41788482}],"con":true,"img":false}]}
{"op":"mcm","clk":"5348487749","pt":1646218137001,"mc":[{"id":"1.195453676","rc":[{"atb":[[1.83,9.76]],"id":41788482}],"con":true,"img":false}]}
{"op":"mcm","clk":"5348487761","pt":1646218137051,"mc":[{"id":"1.195453676","rc":[{"atb":[[1.84,30.65],[1.82,45.44]],"id":41788482}],"con":true,"img":false}]}
{"op":"mcm","clk":"5348487785","pt":1646218137262,"mc":[{"id":"1.195453676","rc":[{"atb":[[1.85,9.76]],"id":41788482}],"con":true,"img":false}]}
{"op":"mcm","clk":"5348487798","pt":1646218137363,"mc":[{"id":"1.195453676","rc":[{"atb":[[1.77,3.42]],"id":41788482}],"con":true,"img":false}]}
{"op":"mcm","clk":"5348487809","pt":1646218137468,"mc":[{"id":"1.195453676","rc":[{"atb":[[1.81,48.79]],"id":41788482},{"atl":[[1.91,2.84]],"id":41788482},{"atb":[[2.1,2.84]],"id":37286329},{"atl":[[2.22,2.84]],"id":37286329}],"con":true,"img":false}]}
{"op":"mcm","clk":"5348487828","pt":1646218137678,"mc":[{"id":"1.195453676","rc":[{"atb":[[1.84,19.52]],"id":41788482}],"con":true,"img":false}]}
{"op":"mcm","clk":"5348487837","pt":1646218137779,"mc":[{"id":"1.195453676","rc":[{"atb":[[1.85,20.89]],"id":41788482}],"con":true,"img":false}]}
{"op":"mcm","clk":"5348487868","pt":1646218138090,"mc":[{"id":"1.195453676","rc":[{"atb":[[2.1,1.42]],"id":37286329}],"con":true,"img":false}]}
{"op":"mcm","clk":"5348487907","pt":1646218138455,"mc":[{"id":"1.195453676","rc":[{"atb":[[1.86,2],[1.77,1.42]],"id":41788482}],"con":true,"img":false}]}
{"op":"mcm","clk":"5348487920","pt":1646218138558,"mc":[{"id":"1.195453676","rc":[{"atb":[[1.8,11.36],[1.86,11.76]],"id":41788482}],"con":true,"img":false}]}
{"op":"mcm","clk":"5348487938","pt":1646218138768,"mc":[{"id":"1.195453676","rc":[{"atb":[[1.85,9.76]],"id":41788482}],"con":true,"img":false}]}
{"op":"mcm","clk":"5348487948","pt":1646218138868,"mc":[{"id":"1.195453676","rc":[{"atb":[[1.86,22.89]],"id":41788482}],"con":true,"img":false}]}
{"op":"mcm","clk":"5348487960","pt":1646218138972,"mc":[{"id":"1.195453676","rc":[{"atb":[[1.85,11.18]],"id":41788482},{"atl":[[1.98,1.42]],"id":41788482},{"atb":[[1.96,1.42]],"id":37286329},{"atl":[[2.18,1.42]],"id":37286329}],"con":true,"img":false}]}
{"op":"mcm","clk":"5348488030","pt":1646218139606,"mc":[{"id":"1.195453676","rc":[{"atb":[[2.1,0]],"id":37286329}],"con":true,"img":false}]}
{"op":"mcm","clk":"5348488062","pt":1646218139858,"mc":[{"id":"1.195453676","rc":[{"atb":[[1.87,9.76],[1.82,35.57]],"id":41788482}],"con":true,"img":false}]}
{"op":"mcm","clk":"5348488097","pt":1646218140224,"mc":[{"id":"1.195453676","rc":[{"atb":[[1.86,11.76]],"id":41788482},{"atl":[[1.98,2.84]],"id":41788482},{"atb":[[1.96,2.84]],"id":37286329},{"atl":[[2.28,1.42]],"id":37286329}],"con":true,"img":false}]}
{"op":"mcm","clk":"5348488121","pt":1646218140382,"mc":[{"id":"1.195453676","rc":[{"atb":[[1.87,20.89]],"id":41788482}],"con":true,"img":false}]}
{"op":"mcm","clk":"5348488162","pt":1646218140700,"mc":[{"id":"1.195453676","rc":[{"atb":[[1.87,9.76]],"id":41788482}],"con":true,"img":false}]}
{"op":"mcm","clk":"5348488277","pt":1646218141577,"mc":[{"id":"1.195453676","rc":[{"atl":[[1.91,12.85]],"id":41788482},{"atl":[[2.14,0.44]],"id":37286329}],"con":true,"img":false}]}
{"op":"mcm","clk":"5348488289","pt":1646218141683,"mc":[{"id":"1.195453676","rc":[{"atb":[[1.83,0],[1.84,9.76],[1.87,0],[1.86,2]],"id":41788482}],"con":true,"img":false}]}
{"op":"mcm","clk":"5348488309","pt":1646218141892,"mc":[{"id":"1.195453676","rc":[{"atb":[[1.73,0],[1.85,0],[1.8,9.94],[1.81,45.95],[1.77,0]],"id":41788482},{"atl":[[1.93,0]],"id":41788482},{"atl":[[2.22,11.17],[2.18,9.75]],"id":37286329}],"con":true,"img":false}]}
{"op":"mcm","clk":"5348488336","pt":1646218142102,"mc":[{"id":"1.195453676","rc":[{"atl":[[2.38,8.34]],"id":37286329}],"con":true,"img":false}]}
{"op":"mcm","clk":"5348488391","pt":1646218142525,"mc":[{"id":"1.195453676","rc":[{"atl":[[2.28,2.84]],"id":37286329}],"con":true,"img":false}]}
{"op":"mcm","clk":"5348488542","pt":1646218143671,"mc":[{"id":"1.195453676","rc":[{"atb":[[1.85,2],[1.86,0]],"id":41788482},{"atl":[[1.9,10.14]],"id":41788482},{"atl":[[2.22,2.84],[2.18,1.42]],"id":37286329}],"con":true,"img":false}]}
{"op":"mcm","clk":"5348488592","pt":1646218144094,"mc":[{"id":"1.195453676","rc":[{"atb":[[1.82,0]],"id":41788482}],"con":true,"img":false}]}
{"op":"mcm","clk":"5348488632","pt":1646218144406,"mc":[{"id":"1.195453676","rc":[{"atl":[[1.96,1.42]],"id":41788482},{"atb":[[2.06,1.42]],"id":37286329},{"atl":[[2.32,1.42]],"id":37286329}],"con":true,"img":false}]}
{"op":"mcm","clk":"5348488699","pt":1646218144978,"mc":[{"id":"1.195453676","rc":[{"atl":[[2.2,8.26]],"id":37286329}],"con":true,"img":false}]}
{"op":"mcm","clk":"5348488711","pt":1646218145087,"mc":[{"id":"1.195453676","rc":[{"atb":[[1.95,0]],"id":37286329}],"con":true,"img":false}]}
{"op":"mcm","clk":"5348488779","pt":1646218145713,"mc":[{"id":"1.195453676","rc":[{"atl":[[1.96,2.84]],"id":41788482},{"atb":[[2.06,2.84]],"id":37286329},{"atl":[[2.32,2.84]],"id":37286329}],"con":true,"img":false}]}
{"op":"mcm","clk":"5348488811","pt":1646218145875,"mc":[{"id":"1.195453676","rc":[{"atl":[[1.9,0]],"id":41788482}],"con":true,"img":false}]}
{"op":"mcm","clk":"5348488834","pt":1646218146081,"mc":[{"id":"1.195453676","rc":[{"atb":[[2.06,30.37]],"id":37286329}],"con":true,"img":false}]}
{"op":"mcm","clk":"5348488884","pt":1646218146604,"mc":[{"id":"1.195453676","rc":[{"atb":[[2.06,2.84]],"id":37286329}],"con":true,"img":false}]}
{"op":"mcm","clk":"5348488910","pt":1646218146866,"mc":[{"id":"1.195453676","rc":[{"atl":[[1.91,10]],"id":41788482}],"con":true,"img":false}]}
{"op":"mcm","clk":"5348488949","pt":1646218147178,"mc":[{"id":"1.195453676","rc":[{"atb":[[1.85,6]],"id":41788482}],"con":true,"img":false}]}
{"op":"mcm","clk":"5348488963","pt":1646218147283,"mc":[{"id":"1.195453676","rc":[{"atl":[[2.18,9.72]],"id":37286329}],"con":true,"img":false}]}
{"op":"mcm","clk":"5348488977","pt":1646218147387,"mc":[{"id":"1.195453676","rc":[{"atl":[[2.38,0]],"id":37286329}],"con":true,"img":false}]}
{"op":"mcm","clk":"5348489062","pt":1646218148071,"mc":[{"id":"1.195453676","rc":[{"atb":[[1.86,9.95]],"id":41788482},{"atl":[[1.91,0]],"id":41788482}],"con":true,"img":false}]}
{"op":"mcm","clk":"5348489070","pt":1646218148176,"mc":[{"id":"1.195453676","rc":[{"atl":[[1.95,11.22]],"id":41788482}],"con":true,"img":false}]}
{"op":"mcm","clk":"5348489095","pt":1646218148541,"mc":[{"id":"1.195453676","rc":[{"atb":[[1.85,2]],"id":41788482},{"atl":[[1.98,0]],"id":41788482},{"atb":[[1.99,0]],"id":37286329}],"con":true,"img":false}]}
{"op":"mcm","clk":"5348489107","pt":1646218148593,"mc":[{"id":"1.195453676","rc":[{"atb":[[1.85,36.32]],"id":41788482}],"con":true,"img":false}]}
{"op":"mcm","clk":"5348489134","pt":1646218148803,"mc":[{"id":"1.195453676","rc":[{"atb":[[1.87,2],[1.86,18.3]],"id":41788482}],"con":true,"img":false}]}
{"op":"mcm","clk":"5348489146","pt":1646218148908,"mc":[{"id":"1.195453676","rc":[{"atb":[[1.85,34.32]],"id":41788482}],"con":true,"img":false}]}
{"op":"mcm","clk":"5348489188","pt":1646218149223,"mc":[{"id":"1.195453676","rc":[{"atb":[[1.2,26.97],[1.87,0],[1.4,24.48],[1.3,17.98]],"id":41788482},{"trd":[[1.87,2]],"ltp":1.87,"tv":2.0,"id":41788482},{"atb":[[2.08,6.41],[1.94,5.73]],"id":37286329},{"atl":[[2.14,0],[2.18,7.7]],"id":37286329},{"trd":[[2.18,4.05],[2.14,27.1],[2.16,18.42]],"ltp":2.18,"tv":49.57,"id":37286329}],"con":true,"img":false}]}
{"op":"mcm","clk":"5348489217","pt":1646218149385,"mc":[{"id":"1.195453676","rc":[{"atb":[[2.06,11.42]],"id":37286329}],"con":true,"img":false}]}
{"op":"mcm","clk":"5348489342","pt":1646218150257,"mc":[{"id":"1.195453676","rc":[{"atl":[[1.99,0]],"id":41788482},{"atb":[[2.08,4.99]],"id":37286329}],"con":true,"img":false}]}
{"op":"mcm","clk":"5348489392","pt":1646218150623,"mc":[{"id":"1.195453676","rc":[{"atb":[[2.04,30.89]],"id":37286329}],"con":true,"img":false}]}
{"op":"mcm","clk":"5348489524","pt":1646218151620,"mc":[{"id":"1.195453676","rc":[{"atb":[[1.95,1.42]],"id":37286329}],"con":true,"img":false}]}
{"op":"mcm","clk":"5348489554","pt":1646218151779,"mc":[{"id":"1.195453676","rc":[{"atl":[[1.97,9.97]],"id":41788482}],"con":true,"img":false}]}
{"op":"mcm","clk":"5348489603","pt":1646218152198,"mc":[{"id":"1.195453676","rc":[{"atl":[[2.36,16.94]],"id":37286329}],"con":true,"img":false}]}
{"op":"mcm","clk":"5348489614","pt":1646218152299,"mc":[{"id":"1.195453676","rc":[{"atl":[[2.18,27.85]],"id":37286329}],"con":true,"img":false}]}
{"op":"mcm","clk":"5348489646","pt":1646218152615,"mc":[{"id":"1.195453676","rc":[{"atb":[[1.95,2.84]],"id":37286329},{"atl":[[2.18,15.54]],"id":37286329}],"con":true,"img":false}]}
{"op":"mcm","clk":"5348489848","pt":1646218154284,"mc":[{"id":"1.195453676","rc":[{"atl":[[1.94,1.42]],"id":41788482},{"atb":[[1.99,1.42]],"id":37286329}],"con":true,"img":false}]}
{"op":"mcm","clk":"5348489908","pt":1646218154804,"mc":[{"id":"1.195453676","rc":[{"atb":[[1.87,9.96]],"id":41788482},{"atl":[[1.94,11.25]],"id":41788482},{"atl":[[2.16,8.45],[2.36,8.47]],"id":37286329}],"con":true,"img":false}]}
{"op":"mcm","clk":"5348489956","pt":1646218155222,"mc":[{"id":"1.195453676","rc":[{"atb":[[1.86,9.95]],"id":41788482},{"atb":[[2.04,2.84]],"id":37286329},{"atl":[[2.18,7.7]],"id":37286329}],"con":true,"img":false}]}
{"op":"mcm","clk":"5348489966","pt":1646218155322,"mc":[{"id":"1.195453676","rc":[{"atb":[[1.87,0]],"id":41788482},{"atb":[[2.08,13.49]],"id":37286329}],"con":true,"img":false}]}
{"op":"mcm","clk":"5348489988","pt":1646218155478,"mc":[{"id":"1.195453676","rc":[{"atb":[[1.87,9.64]],"id":41788482},{"atl":[[2.16,17.32]],"id":37286329}],"con":true,"img":false}]}
{"op":"mcm","clk":"5348490001","pt":1646218155582,"mc":[{"id":"1.195453676","rc":[{"atb":[[1.84,44.49],[1.85,0]],"id":41788482},{"atb":[[2.04,30.89]],"id":37286329}],"con":true,"img":false}]}
{"op":"mcm","clk":"5348490027","pt":1646218155794,"mc":[{"id":"1.195453676","rc":[{"atb":[[1.87,0]],"id":41788482}],"con":true,"img":false}]}
{"op":"mcm","clk":"5348490039","pt":1646218155897,"mc":[{"id":"1.195453676","rc":[{"atb":[[1.86,19.59]],"id":41788482}],"con":true,"img":false}]}
{"op":"mcm","clk":"5348490066","pt":1646218156106,"mc":[{"id":"1.195453676","rc":[{"atb":[[1.75,0]],"id":41788482}],"con":true,"img":false}]}
{"op":"mcm","clk":"5348490535","pt":1646218159840,"mc":[{"id":"1.195453676","rc":[{"atb":[[1.87,9.98]],"id":41788482}],"con":true,"img":false}]}
{"op":"mcm","clk":"5348490559","pt":1646218159997,"mc":[{"id":"1.195453676","rc":[{"atb":[[2.08,4.99]],"id":37286329},{"atl":[[2.14,8.49]],"id":37286329}],"con":true,"img":false}]}
{"op":"mcm","clk":"5348490573","pt":1646218160104,"mc":[{"id":"1.195453676","rc":[{"atb":[[1.85,34.32],[1.86,9.95]],"id":41788482},{"atl":[[2.3,9.89]],"id":37286329}],"con":true,"img":false}]}
{"op":"mcm","clk":"5348490591","pt":1646218160207,"mc":[{"id":"1.195453676","rc":[{"atb":[[1.87,19.62]],"id":41788482}],"con":true,"img":false}]}
{"op":"mcm","clk":"5348490599","pt":1646218160311,"mc":[{"id":"1.195453676","rc":[{"atl":[[2.16,8.45]],"id":37286329}],"con":true,"img":false}]}
{"op":"mcm","clk":"5348490612","pt":1646218160414,"mc":[{"id":"1.195453676","rc":[{"atb":[[1.88,9.9]],"id":41788482},{"atl":[[2.14,17.36]],"id":37286329}],"con":true,"img":false}]}
{"op":"mcm","clk":"5348490641","pt":1646218160624,"mc":[{"id":"1.195453676","rc":[{"atb":[[1.81,9.92]],"id":41788482},{"atb":[[2.04,2.84]],"id":37286329}],"con":true,"img":false}]}
{"op":"mcm","clk":"5348490652","pt":1646218160729,"mc":[{"id":"1.195453676","rc":[{"atb":[[1.87,9.98]],"id":41788482}],"con":true,"img":false}]}
{"op":"mcm","clk":"5348490664","pt":1646218160834,"mc":[{"id":"1.195453676","rc":[{"atb":[[1.88,19.54]],"id":41788482}],"con":true,"img":false}]}
{"op":"mcm","clk":"5348490704","pt":1646218161148,"mc":[{"id":"1.195453676","rc":[{"atb":[[1.89,9.79],[1.84,34.73],[1.86,43.87]],"id":41788482},{"atl":[[1.94,1.42]],"id":41788482},{"atl":[[2.2,0],[2.12,8.58]],"id":37286329}],"con":true,"img":false}]}
{"op":"mcm","clk":"5348490713","pt":1646218161201,"mc":[{"id":"1.195453676","rc":[{"atl":[[1.95,1.42]],"id":41788482},{"atb":[[2.06,2.84]],"id":37286329}],"con":true,"img":false}]}
{"op":"mcm","clk":"5348490739","pt":1646218161410,"mc":[{"id":"1.195453676","rc":[{"atb":[[2.08,0]],"id":37286329},{"trd":[[2.08,9.99]],"ltp":2.08,"tv":9.99,"id":37286329}],"con":true,"img":false}]}
{"op":"mcm","clk":"5348490752","pt":1646218161516,"mc":[{"id":"1.195453676","rc":[{"atb":[[1.88,9.9]],"id":41788482},{"atl":[[2.14,8.49],[2.1,13.46]],"id":37286329}],"con":true,"img":false}]}
{"op":"mcm","clk":"5348490763","pt":1646218161617,"mc":[{"id":"1.195453676","rc":[{"atb":[[1.85,0],[1.86,9.95]],"id":41788482},{"atb":[[2.02,1.42]],"id":37286329}],"con":true,"img":false}]}
{"op":"mcm","clk":"5348490777","pt":1646218161721,"mc":[{"id":"1.195453676","rc":[{"atl":[[2.1,22.12]],"id":37286329}],"con":true,"img":false}]}
{"op":"mcm","clk":"5348490788","pt":1646218161827,"mc":[{"id":"1.195453676","rc":[{"atb":[[1.89,20.06]],"id":41788482},{"atl":[[2.18,0],[2.12,17.55]],"id":37286329}],"con":true,"img":false}]}
{"op":"mcm","clk":"5348490827","pt":1646218162142,"mc":[{"id":"1.195453676","rc":[{"atb":[[1.85,34.32]],"id":41788482},{"atb":[[2,37.72]],"id":37286329},{"atl":[[2.12,8.58]],"id":37286329}],"con":true,"img":false}]}
{"op":"mcm","clk":"5348490838","pt":1646218162195,"mc":[{"id":"1.195453676","rc":[{"atl":[[2.1,31.09]],"id":37286329}],"con":true,"img":false}]}
{"op":"mcm","clk":"5348490850","pt":1646218162300,"mc":[{"id":"1.195453676","rc":[{"atb":[[1.9,9.67]],"id":41788482}],"con":true,"img":false}]}
{"op":"mcm","clk":"5348490862","pt":1646218162403,"mc":[{"id":"1.195453676","rc":[{"atb":[[1.86,0]],"id":41788482},{"atb":[[2.02,10.14]],"id":37286329}],"con":true,"img":false}]}
{"op":"mcm","clk":"5348490875","pt":1646218162509,"mc":[{"id":"1.195453676","rc":[{"atb":[[1.89,9.79]],"id":41788482},{"atl":[[2.1,22.12]],"id":37286329}],"con":true,"img":false}]}
{"op":"mcm","clk":"5348490929","pt":1646218162929,"mc":[{"id":"1.195453676","rc":[{"atl":[[1.94,0]],"id":41788482},{"atb":[[1.99,0]],"id":37286329}],"con":true,"img":false}]}
{"op":"mcm","clk":"5348490953","pt":1646218163137,"mc":[{"id":"1.195453676","rc":[{"atb":[[1.89,42.58]],"id":41788482}],"con":true,"img":false}]}
{"op":"mcm","clk":"5348491163","pt":1646218164929,"mc":[{"id":"1.195453676","rc":[{"atb":[[1.96,0],[2.06,0]],"id":37286329}],"con":true,"img":false}]}
{"op":"mcm","clk":"5348491224","pt":1646218165433,"mc":[{"id":"1.195453676","rc":[{"atl":[[1.97,0]],"id":41788482},{"atl":[[2.08,8.76]],"id":37286329}],"con":true,"img":false}]}
{"op":"mcm","clk":"5348491236","pt":1646218165537,"mc":[{"id":"1.195453676","rc":[{"atl":[[2.16,0]],"id":37286329}],"con":true,"img":false}]}
{"op":"mcm","clk":"5348491246","pt":1646218165644,"mc":[{"id":"1.195453676","rc":[{"atb":[[2.02,1.42]],"id":37286329}],"con":true,"img":false}]}
{"op":"mcm","clk":"5348491290","pt":1646218166016,"mc":[{"id":"1.195453676","rc":[{"atb":[[2.04,8.52]],"id":37286329}],"con":true,"img":false}]}
{"op":"mcm","clk":"5348491303","pt":1646218166116,"mc":[{"id":"1.195453676","rc":[{"atb":[[1.89,9.79]],"id":41788482},{"atb":[[2,8.54],[1.97,0]],"id":37286329}],"con":true,"img":false}]}
{"op":"mcm","clk":"5348491349","pt":1646218166532,"mc":[{"id":"1.195453676","rc":[{"atl":[[1.96,0],[1.95,0]],"id":41788482},{"trd":[[1.96,2.84],[1.95,1.42]],"ltp":1.96,"tv":4.26,"id":41788482},{"atb":[[2.02,1.41],[2.04,0]],"id":37286329},{"trd":[[2.02,0.01],[2.04,21.15]],"ltp":2.02,"tv":21.16,"id":37286329}],"con":true,"img":false}]}
{"op":"mcm","clk":"5348491362","pt":1646218166639,"mc":[{"id":"1.195453676","rc":[{"atb":[[1.87,43.52]],"id":41788482},{"atb":[[1.95,0],[1.93,0],[1.99,29.46],[2.02,0]],"id":37286329},{"trd":[[2.02,2.84]],"ltp":2.02,"tv":2.84,"id":37286329}],"con":true,"img":false}]}
{"op":"mcm","clk":"5348491372","pt":1646218166743,"mc":[{"id":"1.195453676","rc":[{"atl":[[2.1,8.66],[2.08,25.9]],"id":37286329}],"con":true,"img":false}]}
{"op":"mcm","clk":"5348491395","pt":1646218166953,"mc":[{"id":"1.195453676","rc":[{"atl":[[2.02,18.97]],"id":41788482}],"con":true,"img":false}]}
{"op":"mcm","clk":"5348491422","pt":1646218167115,"mc":[{"id":"1.195453676","rc":[{"atb":[[1.84,0]],"id":41788482},{"atb":[[1.99,0]],"id":37286329}],"con":true,"img":false}]}
{"op":"mcm","clk":"5348491489","pt":1646218167633,"mc":[{"id":"1.195453676","rc":[{"atb":[[1.91,32.06]],"id":41788482},{"atl":[[2.02,10.43]],"id":41788482},{"atb":[[1.95,30.71]],"id":37286329}],"con":true,"img":false}]}
{"op":"mcm","clk":"5348491540","pt":1646218168046,"mc":[{"id":"1.195453676","rc":[{"atb":[[1.91,33.48]],"id":41788482}],"con":true,"img":false}]}
{"op":"mcm","clk":"5348491555","pt":1646218168150,"mc":[{"id":"1.195453676","rc":[{"atb":[[1.95,0]],"id":37286329}],"con":true,"img":false}]}
{"op":"mcm","clk":"5348491580","pt":1646218168317,"mc":[{"id":"1.195453676","rc":[{"atb":[[1.87,33.53],[1.92,9.51]],"id":41788482}],"con":true,"img":false}]}
{"op":"mcm","clk":"5348491592","pt":1646218168417,"mc":[{"id":"1.195453676","rc":[{"atl":[[2.2,0]],"id":41788482},{"atb":[[1.9,0]],"id":37286329}],"con":true,"img":false}]}
{"op":"mcm","clk":"5348491615","pt":1646218168625,"mc":[{"id":"1.195453676","rc":[{"atb":[[1.91,1.42]],"id":41788482},{"atb":[[1.9,32.41]],"id":37286329}],"con":true,"img":false}]}
{"op":"mcm","clk":"5348491708","pt":1646218169349,"mc":[{"id":"1.195453676","rc":[{"atb":[[1.92,17.22]],"id":41788482},{"atl":[[2.08,32.63]],"id":37286329}],"con":true,"img":false}]}
{"op":"mcm","clk":"5348491772","pt":1646218169927,"mc":[{"id":"1.195453676","rc":[{"atb":[[1.93,9.5]],"id":41788482}],"con":true,"img":false}]}
{"op":"mcm","clk":"5348491781","pt":1646218170030,"mc":[{"id":"1.195453676","rc":[{"atb":[[1.88,0]],"id":41788482}],"con":true,"img":false}]}
{"op":"mcm","clk":"5348491791","pt":1646218170134,"mc":[{"id":"1.195453676","rc":[{"atl":[[2.14,0],[2.06,8.87]],"id":37286329}],"con":true,"img":false}]}
{"op":"mcm","clk":"5348491807","pt":1646218170242,"mc":[{"id":"1.195453676","rc":[{"atl":[[2.02,0]],"id":41788482},{"trd":[[2.02,10.43]],"ltp":2.02,"tv":10.43,"id":41788482},{"atb":[[2,0],[1.94,3.94]],"id":37286329},{"trd":[[1.94,3.59],[2,17.09],[1.98,10.65]],"ltp":1.94,"tv":31.33,"id":37286329}],"con":true,"img":false}]}
{"op":"mcm","clk":"5348491825","pt":1646218170343,"mc":[{"id":"1.195453676","rc":[{"atb":[[1.92,9.51]],"id":41788482}],"con":true,"img":false}]}
{"op":"mcm","clk":"5348491838","pt":1646218170456,"mc":[{"id":"1.195453676","rc":[{"atb":[[1.93,17.21],[1.91,21.64]],"id":41788482},{"atb":[[1.94,0]],"id":37286329},{"trd":[[1.94,11.47]],"ltp":1.94,"tv":11.47,"id":37286329}],"con":true,"img":false}]}
{"op":"mcm","clk":"5348491863","pt":1646218170660,"mc":[{"id":"1.195453676","rc":[{"atb":[[1.93,48.58]],"id":41788482},{"atb":[[1.85,34.32],[1.9,0]],"id":37286329}],"con":true,"img":false}]}
{"op":"mcm","clk":"5348491912","pt":1646218171036,"mc":[{"id":"1.195453676","rc":[{"atb":[[1.85,42.9]],"id":37286329}],"con":true,"img":false}]}
{"op":"mcm","clk":"5348491925","pt":1646218171130,"mc":[{"id":"1.195453676","rc":[{"atb":[[1.85,0],[1.93,40.87]],"id":41788482},{"atl":[[2.12,20.77]],"id":41788482}],"con":true,"img":false}]}
{"op":"mcm","clk":"5348491968","pt":1646218171448,"mc":[{"id":"1.195453676","rc":[{"atb":[[1.86,1.42]],"id":41788482},{"atl":[[2.2,1.42]],"id":37286329}],"con":true,"img":false}]}
{"op":"mcm","clk":"5348491981","pt":1646218171554,"mc":[{"id":"1.195453676","rc":[{"atb":[[1.86,4.73]],"id":37286329}],"con":true,"img":false}]}
{"op":"mcm","clk":"5348491995","pt":1646218171659,"mc":[{"id":"1.195453676","rc":[{"atb":[[1.87,33.53]],"id":37286329}],"con":true,"img":false}]}
{"op":"mcm","clk":"5348492034","pt":1646218171923,"mc":[{"id":"1.195453676","rc":[{"atb":[[1.85,34.32],[1.86,0]],"id":37286329}],"con":true,"img":false}]}
{"op":"mcm","clk":"5348492076","pt":1646218172237,"mc":[{"id":"1.195453676","rc":[{"atb":[[1.87,47.37]],"id":37286329}],"con":true,"img":false}]}
{"op":"mcm","clk":"5348492150","pt":1646218172860,"mc":[{"id":"1.195453676","rc":[{"atb":[[1.96,1.42]],"id":41788482}],"con":true,"img":false}]}
{"op":"mcm","clk":"5348492172","pt":1646218173019,"mc":[{"id":"1.195453676","rc":[{"atb":[[1.89,0],[1.94,9.4]],"id":41788482}],"con":true,"img":false}]}
{"op":"mcm","clk":"5348492183","pt":1646218173124,"mc":[{"id":"1.195453676","rc":[{"atb":[[1.64,8.81]],"id":41788482},{"atb":[[1.79,7.13]],"id":37286329}],"con":true,"img":false}]}
{"op":"mcm","clk":"5348492297","pt":1646218174226,"mc":[{"id":"1.195453676","rc":[{"atb":[[1.97,1.42]],"id":41788482},{"atl":[[2.04,1.42]],"id":37286329}],"con":true,"img":false}]}
{"op":"mcm","clk":"5348492408","pt":1646218175051,"mc":[{"id":"1.195453676","rc":[{"atb":[[1.96,10.78]],"id":41788482},{"atl":[[2.04,10.4]],"id":37286329}],"con":true,"img":false}]}
{"op":"mcm","clk":"5348492429","pt":1646218175258,"mc":[{"id":"1.195453676","rc":[{"atb":[[1.9,0]],"id":41788482},{"atl":[[2.12,0]],"id":37286329}],"con":true,"img":false}]}
{"op":"mcm","clk":"5348492473","pt":1646218175529,"mc":[{"id":"1.195453676","rc":[{"atb":[[1.98,1.42]],"id":41788482},{"atl":[[2.04,11.82]],"id":37286329}],"con":true,"img":false}]}
{"op":"mcm","clk":"5348492487","pt":1646218175633,"mc":[{"id":"1.195453676","rc":[{"atb":[[1.95,30.71],[1.92,29.62],[1.91,1.42],[1.97,10.72]],"id":41788482}],"con":true,"img":false}]}
{"op":"mcm","clk":"5348492500","pt":1646218175735,"mc":[{"id":"1.195453676","rc":[{"atb":[[1.92,20.11]],"id":41788482}],"con":true,"img":false}]}
{"op":"mcm","clk":"5348492545","pt":1646218176151,"mc":[{"id":"1.195453676","rc":[{"atb":[[1.87,0]],"id":41788482}],"con":true,"img":false}]}
{"op":"mcm","clk":"5348492557","pt":1646218176257,"mc":[{"id":"1.195453676","rc":[{"atb":[[1.88,4.68]],"id":37286329}],"con":true,"img":false}]}
{"op":"mcm","clk":"5348492577","pt":1646218176466,"mc":[{"id":"1.195453676","rc":[{"atb":[[1.97,1.42]],"id":41788482}],"con":true,"img":false}]}
{"op":"mcm","clk":"5348492599","pt":1646218176633,"mc":[{"id":"1.195453676","rc":[{"atb":[[1.97,30.07]],"id":41788482},{"atb":[[1.87,33.53]],"id":37286329}],"con":true,"img":false}]}
{"op":"mcm","clk":"5348492613","pt":1646218176784,"mc":[{"id":"1.195453676","rc":[{"atb":[[1.88,18.52]],"id":37286329}],"con":true,"img":false}]}
{"op":"mcm","clk":"5348492659","pt":1646218177149,"mc":[{"id":"1.195453676","rc":[{"atb":[[1.97,0]],"id":41788482}],"con":true,"img":false}]}
{"op":"mcm","clk":"5348492713","pt":1646218177669,"mc":[{"id":"1.195453676","rc":[{"atb":[[1.89,32.78]],"id":37286329}],"con":true,"img":false}]}
{"op":"mcm","clk":"5348492739","pt":1646218177834,"mc":[{"id":"1.195453676","rc":[{"atb":[[1.99,1.42]],"id":41788482},{"atl":[[2.02,1.42]],"id":37286329}],"con":true,"img":false}]}
{"op":"mcm","clk":"5348492760","pt":1646218178038,"mc":[{"id":"1.195453676","rc":[{"atb":[[1.88,4.68]],"id":37286329}],"con":true,"img":false}]}
{"op":"mcm","clk":"5348492771","pt":1646218178136,"mc":[{"id":"1.195453676","rc":[{"atb":[[1.89,46.62]],"id":37286329}],"con":true,"img":false}]}
{"op":"mcm","clk":"5348492871","pt":1646218179025,"mc":[{"id":"1.195453676","rc":[{"atb":[[1.88,0]],"id":37286329}],"con":true,"img":false}]}
{"op":"mcm","clk":"5348492894","pt":1646218179235,"mc":[{"id":"1.195453676","rc":[{"atb":[[2,1.42]],"id":41788482},{"atl":[[2.02,2.84]],"id":37286329}],"con":true,"img":false}]}
{"op":"mcm","clk":"5348492969","pt":1646218179857,"mc":[{"id":"1.195453676","rc":[{"atb":[[1.99,0]],"id":41788482},{"atl":[[2.02,1.42]],"id":37286329}],"con":true,"img":false}]}
{"op":"mcm","clk":"5348493102","pt":1646218180967,"mc":[{"id":"1.195453676","rc":[{"atb":[[1.9,4.63]],"id":37286329}],"con":true,"img":false}]}
{"op":"mcm","clk":"5348493153","pt":1646218181346,"mc":[{"id":"1.195453676","rc":[{"atb":[[1.89,32.78]],"id":37286329}],"con":true,"img":false}]}
{"op":"mcm","clk":"5348493169","pt":1646218181447,"mc":[{"id":"1.195453676","rc":[{"atb":[[1.9,18.47]],"id":37286329}],"con":true,"img":false}]}
{"op":"mcm","clk":"5348493182","pt":1646218181544,"mc":[{"id":"1.195453676","rc":[{"atb":[[1.99,1.42]],"id":41788482},{"atl":[[2.2,1.42]],"id":41788482},{"atl":[[1.99,1.42]],"id":37286329}],"con":true,"img":false}]}
{"op":"mcm","clk":"5348493290","pt":1646218182444,"mc":[{"id":"1.195453676","rc":[{"atl":[[2.04,2.84]],"id":37286329}],"con":true,"img":false}]}
{"op":"mcm","clk":"5348493317","pt":1646218182647,"mc":[{"id":"1.195453676","rc":[{"atb":[[1.99,2.84]],"id":41788482},{"atl":[[2.2,2.84]],"id":41788482},{"atl":[[1.99,2.84]],"id":37286329}],"con":true,"img":false}]}
{"op":"mcm","clk":"5348493330","pt":1646218182756,"mc":[{"id":"1.195453676","rc":[{"atl":[[2.04,11.87]],"id":37286329}],"con":true,"img":false}]}
{"op":"mcm","clk":"5348493382","pt":1646218183162,"mc":[{"id":"1.195453676","rc":[{"atb":[[1.97,30.07]],"id":41788482}],"con":true,"img":false}]}
{"op":"mcm","clk":"5348493453","pt":1646218183750,"mc":[{"id":"1.195453676","rc":[{"atb":[[2,0]],"id":41788482}],"con":true,"img":false}]}
{"op":"mcm","clk":"5348493633","pt":1646218185155,"mc":[{"id":"1.195453676","rc":[{"atl":[[2.22,1.42]],"id":41788482},{"atl":[[2,1.42]],"id":37286329}],"con":true,"img":false}]}
{"op":"mcm","clk":"5348493728","pt":1646218185992,"mc":[{"id":"1.195453676","rc":[{"atb":[[1.98,10.65]],"id":41788482},{"atl":[[2.02,10.51]],"id":37286329}],"con":true,"img":false}]}
{"op":"mcm","clk":"5348493750","pt":1646218186153,"mc":[{"id":"1.195453676","rc":[{"atl":[[2.1,0]],"id":37286329}],"con":true,"img":false}]}
{"op":"mcm","clk":"5348493802","pt":1646218186668,"mc":[{"id":"1.195453676","rc":[{"atb":[[1.98,1.42]],"id":41788482},{"atl":[[2.02,1.42]],"id":37286329}],"con":true,"img":false}]}
{"op":"mcm","clk":"5348493868","pt":1646218187252,"mc":[{"id":"1.195453676","rc":[{"atl":[[1.99,0]],"id":37286329}],"con":true,"img":false}]}
{"op":"mcm","clk":"5348493913","pt":1646218187655,"mc":[{"id":"1.195453676","rc":[{"atb":[[1.97,0]],"id":41788482}],"con":true,"img":false}]}
{"op":"mcm","clk":"5348493982","pt":1646218188180,"mc":[{"id":"1.195453676","rc":[{"atl":[[2.04,2.84]],"id":37286329}],"con":true,"img":false}]}
{"op":"mcm","clk":"5348494021","pt":1646218188449,"mc":[{"id":"1.195453676","rc":[{"atl":[[2.12,1.42]],"id":37286329}],"con":true,"img":false}]}
{"op":"mcm","clk":"5348494100","pt":1646218189069,"mc":[{"id":"1.195453676","rc":[{"atl":[[2,0]],"id":37286329}],"con":true,"img":false}]}
{"op":"mcm","clk":"5348494110","pt":1646218189174,"mc":[{"id":"1.195453676","rc":[{"atl":[[2.04,11.8]],"id":37286329}],"con":true,"img":false}]}
{"op":"mcm","clk":"5348494156","pt":1646218189593,"mc":[{"id":"1.195453676","rc":[{"atb":[[1.96,1.42]],"id":41788482},{"atl":[[2.04,2.84]],"id":37286329}],"con":true,"img":false}]}
{"op":"mcm","clk":"5348494188","pt":1646218189857,"mc":[{"id":"1.195453676","rc":[{"atl":[[2.06,0]],"id":37286329}],"con":true,"img":false}]}
{"op":"mcm","clk":"5348494200","pt":1646218189960,"mc":[{"id":"1.195453676","rc":[{"atl":[[1.99,1.42]],"id":37286329}],"con":true,"img":false}]}
{"op":"mcm","clk":"5348494223","pt":1646218190165,"mc":[{"id":"1.195453676","rc":[{"atb":[[1.95,0]],"id":41788482}],"con":true,"img":false}]}
{"op":"mcm","clk":"5348494256","pt":1646218190478,"mc":[{"id":"1.195453676","rc":[{"atl":[[2.12,10.09]],"id":41788482},{"atb":[[1.9,4.63]],"id":37286329},{"atl":[[2.08,25.9],[2.06,8.86]],"id":37286329}],"con":true,"img":false}]}
{"op":"mcm","clk":"5348494280","pt":1646218190699,"mc":[{"id":"1.195453676","rc":[{"atb":[[1.99,0]],"id":41788482},{"atl":[[2.06,21.79]],"id":41788482},{"atl":[[2.06,0]],"id":37286329}],"con":true,"img":false}]}
{"op":"mcm","clk":"5348494330","pt":1646218191062,"mc":[{"id":"1.195453676","rc":[{"atl":[[2.06,32.83]],"id":41788482},{"atb":[[1.9,13.89]],"id":37286329}],"con":true,"img":false}]}
{"op":"mcm","clk":"5348494344","pt":1646218191170,"mc":[{"id":"1.195453676","rc":[{"atl":[[2.06,8.86]],"id":37286329}],"con":true,"img":false}]}
{"op":"mcm","clk":"5348494396","pt":1646218191589,"mc":[{"id":"1.195453676","rc":[{"atb":[[2,1.42]],"id":41788482},{"atl":[[2.1,1.42],[2.06,21.79]],"id":41788482},{"atb":[[1.9,4.63]],"id":37286329},{"atl":[[2,1.42],[2.08,8.76]],"id":37286329}],"con":true,"img":false}]}
{"op":"mcm","clk":"5348494408","pt":1646218191644,"mc":[{"id":"1.195453676","rc":[{"atl":[[2.1,16.73]],"id":37286329}],"con":true,"img":false}]}
{"op":"mcm","clk":"5348494436","pt":1646218191900,"mc":[{"id":"1.195453676","rc":[{"atb":[[1.94,0],[1.93,31.36]],"id":41788482},{"atl":[[2.06,0]],"id":37286329}],"con":true,"img":false}]}
{"op":"mcm","clk":"5348494483","pt":1646218192269,"mc":[{"id":"1.195453676","rc":[{"atl":[[2.08,0]],"id":37286329}],"con":true,"img":false}]}
{"op":"mcm","clk":"5348494514","pt":1646218192579,"mc":[{"id":"1.195453676","rc":[{"atb":[[1.91,0]],"id":41788482},{"atl":[[2.12,0]],"id":37286329}],"con":true,"img":false}]}
{"op":"mcm","clk":"5348494571","pt":1646218193059,"mc":[{"id":"1.195453676","rc":[{"atb":[[1.2,0],[1.4,11],[1.3,0]],"id":41788482}],"con":true,"img":false}]}
{"op":"mcm","clk":"5348494592","pt":1646218193262,"mc":[{"id":"1.195453676","rc":[{"atl":[[2.1,2.84]],"id":41788482}],"con":true,"img":false}]}
{"op":"mcm","clk":"5348494630","pt":1646218193575,"mc":[{"id":"1.195453676","rc":[{"atb":[[1.64,0]],"id":41788482},{"atb":[[1.79,0]],"id":37286329}],"con":true,"img":false}]}
{"op":"mcm","clk":"5348494642","pt":1646218193686,"mc":[{"id":"1.195453676","rc":[{"atb":[[1.61,8.81]],"id":41788482},{"atb":[[1.85,41.46]],"id":37286329}],"con":true,"img":false}]}
{"op":"mcm","clk":"5348494735","pt":1646218194350,"mc":[{"id":"1.195453676","rc":[{"atb":[[1.86,0]],"id":41788482},{"atl":[[2,0],[1.99,0],[2.02,0],[2.28,0],[2.2,0],[2.3,8.47],[2.32,0],[2.22,0],[2.26,8.48]],"id":37286329}],"con":true,"img":false}]}
{"op":"mcm","clk":"5348494769","pt":1646218194677,"mc":[{"id":"1.195453676","rc":[{"atb":[[1.93,0],[1.91,32.06]],"id":41788482},{"atl":[[2.08,8.76]],"id":37286329}],"con":true,"img":false}]}
{"op":"mcm","clk":"5348494818","pt":1646218195080,"mc":[{"id":"1.195453676","rc":[{"atb":[[2,4.26]],"id":41788482},{"atl":[[2.04,8.52]],"id":37286329}],"con":true,"img":false}]}
{"op":"mcm","clk":"5348494896","pt":1646218195662,"mc":[{"id":"1.195453676","rc":[{"atb":[[1.93,31.36]],"id":41788482}],"con":true,"img":false}]}
{"op":"mcm","clk":"5348494987","pt":1646218196392,"mc":[{"id":"1.195453676","rc":[{"atb":[[1.98,0]],"id":41788482},{"atl":[[2.04,5.68]],"id":37286329}],"con":true,"img":false}]}
{"op":"mcm","clk":"5348495025","pt":1646218196708,"mc":[{"id":"1.195453676","rc":[{"atb":[[2,1.42]],"id":41788482},{"atl":[[2.04,0]],"id":37286329}],"con":true,"img":false}]}
{"op":"mcm","clk":"5348495054","pt":1646218196876,"mc":[{"id":"1.195453676","rc":[{"atl":[[2.1,0],[2.08,26.02]],"id":37286329}],"con":true,"img":false}]}
{"op":"mcm","clk":"5348495081","pt":1646218197077,"mc":[{"id":"1.195453676","rc":[{"atb":[[1.94,9.45]],"id":41788482},{"atl":[[2.08,14.57],[2.24,16.96],[2.06,8.86]],"id":37286329}],"con":true,"img":false}]}
{"op":"mcm","clk":"5348495348","pt":1646218199267,"mc":[{"id":"1.195453676","rc":[{"atb":[[2,0]],"id":41788482},{"atl":[[2.06,0]],"id":37286329}],"con":true,"img":false}]}
{"op":"mcm","clk":"5348495385","pt":1646218199579,"mc":[{"id":"1.195453676","rc":[{"atl":[[2.08,8.76]],"id":37286329}],"con":true,"img":false}]}
{"op":"mcm","clk":"5348495395","pt":1646218199679,"mc":[{"id":"1.195453676","rc":[{"atb":[[1.94,0]],"id":41788482}],"con":true,"img":false}]}
{"op":"mcm","clk":"5348495455","pt":1646218200202,"mc":[{"id":"1.195453676","rc":[{"atb":[[1.93,0],[1.91,0]],"id":41788482},{"atb":[[1.9,12.32]],"id":37286329}],"con":true,"img":false}]}
{"op":"mcm","clk":"5348495494","pt":1646218200463,"mc":[{"id":"1.195453676","rc":[{"atb":[[1.93,9.53]],"id":41788482}],"con":true,"img":false}]}
{"op":"mcm","clk":"5348495514","pt":1646218200675,"mc":[{"id":"1.195453676","rc":[{"atb":[[1.82,35.57]],"id":41788482},{"atb":[[1.85,7.13]],"id":37286329}],"con":true,"img":false}]}
{"op":"mcm","clk":"5348495548","pt":1646218200985,"mc":[{"id":"1.195453676","rc":[{"atb":[[1.93,0]],"id":41788482},{"atl":[[2.08,0]],"id":37286329}],"con":true,"img":false}]}
{"op":"mcm","clk":"5348495573","pt":1646218201194,"mc":[{"id":"1.195453676","rc":[{"atb":[[1.83,9.71],[1.82,0]],"id":41788482},{"atl":[[2.22,8.62]],"id":37286329}],"con":true,"img":false}]}
{"op":"mcm","clk":"5348495609","pt":1646218201466,"mc":[{"id":"1.195453676","rc":[{"atl":[[2.24,28.28]],"id":37286329}],"con":true,"img":false}]}
{"op":"mcm","clk":"5348495635","pt":1646218201678,"mc":[{"id":"1.195453676","rc":[{"atb":[[1.92,0]],"id":41788482}],"con":true,"img":false}]}
{"op":"mcm","clk":"5348495650","pt":1646218201785,"mc":[{"id":"1.195453676","rc":[{"atb":[[1.91,19.64]],"id":41788482}],"con":true,"img":false}]}
{"op":"mcm","clk":"5348495665","pt":1646218201884,"mc":[{"id":"1.195453676","rc":[{"atb":[[1.96,4.26]],"id":41788482},{"atb":[[1.9,4.63]],"id":37286329},{"atl":[[2.24,16.96]],"id":37286329}],"con":true,"img":false}]}
{"op":"mcm","clk":"5348495692","pt":1646218202095,"mc":[{"id":"1.195453676","rc":[{"atb":[[1.95,1.42]],"id":41788482},{"atl":[[2.22,10.04]],"id":37286329}],"con":true,"img":false}]}
{"op":"mcm","clk":"5348495707","pt":1646218202200,"mc":[{"id":"1.195453676","rc":[{"atb":[[1.84,34.73]],"id":41788482},{"atl":[[2.22,27.3]],"id":37286329}],"con":true,"img":false}]}
{"op":"mcm","clk":"5348495718","pt":1646218202305,"mc":[{"id":"1.195453676","rc":[{"atl":[[2.24,0],[2.2,18.54]],"id":37286329}],"con":true,"img":false}]}
{"op":"mcm","clk":"5348495744","pt":1646218202468,"mc":[{"id":"1.195453676","rc":[{"atb":[[1.85,19.36]],"id":41788482},{"atl":[[2.36,0],[2.2,35.88]],"id":37286329}],"con":true,"img":false}]}
{"op":"mcm","clk":"5348495768","pt":1646218202679,"mc":[{"id":"1.195453676","rc":[{"atl":[[2.22,10.04]],"id":37286329}],"con":true,"img":false}]}
{"op":"mcm","clk":"5348495821","pt":1646218203089,"mc":[{"id":"1.195453676","rc":[{"atl":[[2.2,55.49]],"id":37286329}],"con":true,"img":false}]}
{"op":"mcm","clk":"5348495832","pt":1646218203191,"mc":[{"id":"1.195453676","rc":[{"atb":[[1.86,33.92]],"id":41788482}],"con":true,"img":false}]}
{"op":"mcm","clk":"5348495871","pt":1646218203510,"mc":[{"id":"1.195453676","rc":[{"atl":[[2.06,28.38]],"id":41788482},{"atb":[[1.9,13.89]],"id":37286329}],"con":true,"img":false}]}
{"op":"mcm","clk":"5348495882","pt":1646218203563,"mc":[{"id":"1.195453676","rc":[{"atb":[[1.96,0]],"id":41788482},{"atl":[[2.2,43.37]],"id":37286329}],"con":true,"img":false}]}
{"op":"mcm","clk":"5348495928","pt":1646218203981,"mc":[{"id":"1.195453676","rc":[{"atb":[[1.87,19.37]],"id":41788482}],"con":true,"img":false}]}
{"op":"mcm","clk":"5348495953","pt":1646218204185,"mc":[{"id":"1.195453676","rc":[{"atb":[[1.8,0]],"id":41788482},{"atb":[[1.91,32.06]],"id":37286329}],"con":true,"img":false}]}
{"op":"mcm","clk":"5348495984","pt":1646218204497,"mc":[{"id":"1.195453676","rc":[{"atb":[[1.9,4.63]],"id":37286329}],"con":true,"img":false}]}
{"op":"mcm","clk":"5348496008","pt":1646218204702,"mc":[{"id":"1.195453676","rc":[{"atb":[[1.87,9.68]],"id":41788482}],"con":true,"img":false}]}
{"op":"mcm","clk":"5348496023","pt":1646218204804,"mc":[{"id":"1.195453676","rc":[{"atb":[[1.91,41.53]],"id":37286329}],"con":true,"img":false}]}
{"op":"mcm","clk":"5348496046","pt":1646218204972,"mc":[{"id":"1.195453676","rc":[{"atl":[[2.18,8.62]],"id":37286329}],"con":true,"img":false}]}
{"op":"mcm","clk":"5348496101","pt":1646218205484,"mc":[{"id":"1.195453676","rc":[{"atl":[[2.2,35.88]],"id":37286329}],"con":true,"img":false}]}
{"op":"mcm","clk":"5348496111","pt":1646218205592,"mc":[{"id":"1.195453676","rc":[{"atl":[[2.18,16.11]],"id":37286329}],"con":true,"img":false}]}
{"op":"mcm","clk":"5348496140","pt":1646218205795,"mc":[{"id":"1.195453676","rc":[{"atb":[[1.95,0]],"id":41788482}],"con":true,"img":false}]}
{"op":"mcm","clk":"5348496267","pt":1646218206690,"mc":[{"id":"1.195453676","rc":[{"atb":[[1.92,1.42]],"id":41788482},{"atl":[[2.08,1.42]],"id":41788482},{"atb":[[1.92,4.58],[1.9,0]],"id":37286329},{"atl":[[2.08,1.42],[2.16,8.61]],"id":37286329}],"con":true,"img":false}]}
{"op":"mcm","clk":"5348496279","pt":1646218206796,"mc":[{"id":"1.195453676","rc":[{"atl":[[2.3,0]],"id":37286329}],"con":true,"img":false}]}
{"op":"mcm","clk":"5348496296","pt":1646218206912,"mc":[{"id":"1.195453676","rc":[{"atb":[[1.2,26.97],[1.4,24.48],[1.92,0],[1.91,18],[1.3,17.98]],"id":41788482},{"trd":[[1.91,1.64],[1.92,1.42]],"ltp":1.91,"tv":3.05,"id":41788482},{"atb":[[2.08,4.99],[1.94,5.73]],"id":37286329},{"atl":[[2.08,0]],"id":37286329},{"trd":[[2.1,2.79],[2.08,12.84]],"ltp":2.1,"tv":15.62,"id":37286329}],"con":true,"img":false}]}
{"op":"mcm","clk":"5348496310","pt":1646218207017,"mc":[{"id":"1.195453676","rc":[{"atl":[[2.18,8.62]],"id":37286329}],"con":true,"img":false}]}
{"op":"mcm","clk":"5348496323","pt":1646218207119,"mc":[{"id":"1.195453676","rc":[{"atb":[[1.88,29.06],[1.91,0]],"id":41788482},{"trd":[[1.93,5.39]],"ltp":1.93,"tv":5.39,"id":41788482},{"atb":[[2.08,0],[1.91,32.06]],"id":37286329},{"trd":[[2.08,17.84]],"ltp":2.08,"tv":17.84,"id":37286329}],"con":true,"img":false}]}
{"op":"mcm","clk":"5348496333","pt":1646218207178,"mc":[{"id":"1.195453676","rc":[{"atb":[[1.87,0],[1.92,14.05]],"id":37286329}],"con":true,"img":false}]}
{"op":"mcm","clk":"5348496345","pt":1646218207311,"mc":[{"id":"1.195453676","rc":[{"atb":[[1.89,9.7],[1.88,0]],"id":41788482}],"con":true,"img":false}]}
{"op":"mcm","clk":"5348496368","pt":1646218207488,"mc":[{"id":"1.195453676","rc":[{"atl":[[2.14,22.68],[2.2,17.34]],"id":37286329}],"con":true,"img":false}]}
{"op":"mcm","clk":"5348496380","pt":1646218207591,"mc":[{"id":"1.195453676","rc":[{"atb":[[1.92,4.57]],"id":37286329}],"con":true,"img":false}]}
{"op":"mcm","clk":"5348496412","pt":1646218207898,"mc":[{"id":"1.195453676","rc":[{"atb":[[1.94,15.57]],"id":37286329}],"con":true,"img":false}]}
{"op":"mcm","clk":"5348496448","pt":1646218208212,"mc":[{"id":"1.195453676","rc":[{"atb":[[1.88,33.15],[1.61,0]],"id":41788482},{"atb":[[1.95,30.71]],"id":37286329}],"con":true,"img":false}]}
{"op":"mcm","clk":"5348496463","pt":1646218208317,"mc":[{"id":"1.195453676","rc":[{"atb":[[1.59,8.81]],"id":41788482}],"con":true,"img":false}]}
{"op":"mcm","clk":"5348496492","pt":1646218208579,"mc":[{"id":"1.195453676","rc":[{"atb":[[1.89,17.05]],"id":41788482},{"atl":[[2.06,21.79]],"id":41788482},{"atb":[[1.94,5.73]],"id":37286329},{"atl":[[2.14,30.01]],"id":37286329}],"con":true,"img":false}]}
{"op":"mcm","clk":"5348496504","pt":1646218208692,"mc":[{"id":"1.195453676","rc":[{"atb":[[1.95,40.55]],"id":37286329}],"con":true,"img":false}]}
{"op":"mcm","clk":"5348496516","pt":1646218208785,"mc":[{"id":"1.195453676","rc":[{"atb":[[1.9,9.73]],"id":41788482},{"atl":[[2.12,8.63]],"id":37286329}],"con":true,"img":false}]}
{"op":"mcm","clk":"5348496551","pt":1646218209095,"mc":[{"id":"1.195453676","rc":[{"atb":[[1.89,9.7]],"id":41788482},{"atb":[[1.95,30.71]],"id":37286329},{"atl":[[2.14,22.68]],"id":37286329}],"con":true,"img":false}]}
{"op":"mcm","clk":"5348496562","pt":1646218209202,"mc":[{"id":"1.195453676","rc":[{"atb":[[1.84,0],[1.93,1.42],[1.9,17.08]],"id":41788482},{"atl":[[2.04,1.42]],"id":41788482},{"atl":[[2.12,15.96],[2.1,1.42]],"id":37286329}],"con":true,"img":false}]}
{"op":"mcm","clk":"5348496619","pt":1646218209723,"mc":[{"id":"1.195453676","rc":[{"atb":[[1.89,0],[1.85,9.68],[1.87,0],[1.9,7.35]],"id":41788482},{"atb":[[1.95,0]],"id":37286329},{"atl":[[2.12,7.33],[2.16,0]],"id":37286329}],"con":true,"img":false}]}
{"op":"mcm","clk":"5348496684","pt":1646218210092,"mc":[{"id":"1.195453676","rc":[{"atb":[[1.93,31.36]],"id":37286329}],"con":true,"img":false}]}
{"op":"mcm","clk":"5348496712","pt":1646218210304,"mc":[{"id":"1.195453676","rc":[{"atl":[[2.04,4.26]],"id":41788482},{"atb":[[1.94,21.75],[1.92,0]],"id":37286329}],"con":true,"img":false}]}
{"op":"mcm","clk":"5348496769","pt":1646218210721,"mc":[{"id":"1.195453676","rc":[{"atb":[[1.89,0]],"id":37286329}],"con":true,"img":false}]}
{"op":"mcm","clk":"5348496807","pt":1646218210995,"mc":[{"id":"1.195453676","rc":[{"atb":[[1.59,0]],"id":41788482},{"atb":[[1.85,0]],"id":37286329}],"con":true,"img":false}]}
{"op":"mcm","clk":"5348496819","pt":1646218211100,"mc":[{"id":"1.195453676","rc":[{"atb":[[1.56,8.81]],"id":41788482},{"atb":[[1.92,7.13]],"id":37286329}],"con":true,"img":false}]}
{"op":"mcm","clk":"5348496890","pt":1646218211719,"mc":[{"id":"1.195453676","rc":[{"atb":[[1.91,1.42]],"id":41788482},{"atl":[[2.16,1.42]],"id":37286329}],"con":true,"img":false}]}
{"op":"mcm","clk":"5348496928","pt":1646218212017,"mc":[{"id":"1.195453676","rc":[{"atl":[[2.16,9.93]],"id":37286329}],"con":true,"img":false}]}
{"op":"mcm","clk":"5348496950","pt":1646218212199,"mc":[{"id":"1.195453676","rc":[{"atb":[[1.93,0]],"id":41788482},{"atb":[[1.95,30.71]],"id":37286329}],"con":true,"img":false}]}
{"op":"mcm","clk":"5348496980","pt":1646218212504,"mc":[{"id":"1.195453676","rc":[{"atb":[[1.89,9.84]],"id":41788482}],"con":true,"img":false}]}
{"op":"mcm","clk":"5348496988","pt":1646218212607,"mc":[{"id":"1.195453676","rc":[{"atb":[[1.92,0]],"id":37286329}],"con":true,"img":false}]}
{"op":"mcm","clk":"5348497000","pt":1646218212717,"mc":[{"id":"1.195453676","rc":[{"atb":[[1.89,7.13],[1.94,10.27]],"id":37286329},{"atl":[[2.1,33.12],[2.14,0]],"id":37286329}],"con":true,"img":false}]}
{"op":"mcm","clk":"5348497013","pt":1646218212820,"mc":[{"id":"1.195453676","rc":[{"atl":[[2.12,15.91]],"id":37286329}],"con":true,"img":false}]}
{"op":"mcm","clk":"5348497025","pt":1646218212878,"mc":[{"id":"1.195453676","rc":[{"atb":[[1.92,1.42],[1.9,17.11]],"id":41788482},{"atb":[[1.95,42.19]],"id":37286329},{"atl":[[2.16,11.35]],"id":37286329}],"con":true,"img":false}]}
{"op":"mcm","clk":"5348497061","pt":1646218213192,"mc":[{"id":"1.195453676","rc":[{"atb":[[1.91,33.48]],"id":41788482}],"con":true,"img":false}]}
{"op":"mcm","clk":"5348497094","pt":1646218213501,"mc":[{"id":"1.195453676","rc":[{"atb":[[1.9,7.35]],"id":41788482}],"con":true,"img":false}]}
{"op":"mcm","clk":"5348497130","pt":1646218213807,"mc":[{"id":"1.195453676","rc":[{"atl":[[2.04,1.42]],"id":41788482}],"con":true,"img":false}]}
{"op":"mcm","clk":"5348497157","pt":1646218214014,"mc":[{"id":"1.195453676","rc":[{"atb":[[1.94,5.73],[1.95,46.7]],"id":37286329}],"con":true,"img":false}]}
{"op":"mcm","clk":"5348497230","pt":1646218214592,"mc":[{"id":"1.195453676","rc":[{"atb":[[1.9,9.76]],"id":41788482},{"atb":[[1.95,35.22]],"id":37286329},{"atl":[[2.12,8.58]],"id":37286329}],"con":true,"img":false}]}
{"op":"mcm","clk":"5348497243","pt":1646218214750,"mc":[{"id":"1.195453676","rc":[{"atb":[[1.9,0]],"id":41788482},{"atl":[[1.97,2]],"id":41788482}],"con":true,"img":false}]}
{"op":"mcm","clk":"5348497287","pt":1646218215013,"mc":[{"id":"1.195453676","rc":[{"atb":[[1.93,1.42]],"id":41788482},{"atl":[[2.02,1.42]],"id":41788482},{"atl":[[2.08,1.42]],"id":37286329}],"con":true,"img":false}]}
{"op":"mcm","clk":"5348497307","pt":1646218215230,"mc":[{"id":"1.195453676","rc":[{"atb":[[1.87,33.53],[1.88,0],[1.91,1.42]],"id":41788482},{"atb":[[1.95,41.78]],"id":37286329}],"con":true,"img":false}]}
{"op":"mcm","clk":"5348497366","pt":1646218215641,"mc":[{"id":"1.195453676","rc":[{"atb":[[1.95,35.22]],"id":37286329}],"con":true,"img":false}]}
{"op":"mcm","clk":"5348497447","pt":1646218216217,"mc":[{"id":"1.195453676","rc":[{"atb":[[1.88,33.15]],"id":41788482}],"con":true,"img":false}]}
{"op":"mcm","clk":"5348497458","pt":1646218216322,"mc":[{"id":"1.195453676","rc":[{"atb":[[1.92,0]],"id":41788482}],"con":true,"img":false}]}
{"op":"mcm","clk":"5348497855","pt":1646218218742,"mc":[{"id":"1.195453676","rc":[{"atl":[[2.08,0]],"id":37286329}],"con":true,"img":false}]}
{"op":"mcm","clk":"5348497902","pt":1646218218916,"mc":[{"id":"1.195453676","rc":[{"atl":[[2.08,2.84]],"id":37286329}],"con":true,"img":false}]}
{"op":"mcm","clk":"5348497985","pt":1646218219306,"mc":[{"id":"1.195453676","rc":[{"atl":[[2.08,0]],"id":37286329}],"con":true,"img":false}]}
{"op":"mcm","clk":"5348498042","pt":1646218219635,"mc":[{"id":"1.195453676","rc":[{"atl":[[2.1,39.99]],"id":37286329}],"con":true,"img":false}]}
{"op":"mcm","clk":"5348498058","pt":1646218219698,"mc":[{"id":"1.195453676","rc":[{"atl":[[1.97,0]],"id":41788482}],"con":true,"img":false}]}
{"op":"mcm","clk":"5348498076","pt":1646218219808,"mc":[{"id":"1.195453676","rc":[{"atb":[[1.91,11.11]],"id":41788482},{"atl":[[1.95,2]],"id":41788482}],"con":true,"img":false}]}
{"op":"mcm","clk":"5348498113","pt":1646218220029,"mc":[{"id":"1.195453676","rc":[{"atl":[[1.95,0]],"id":41788482},{"trd":[[1.95,5.42]],"ltp":1.95,"tv":5.42,"id":41788482}],"con":true,"img":false}]}
{"op":"mcm","clk":"5348498231","pt":1646218220639,"mc":[{"id":"1.195453676","rc":[{"atb":[[1.86,0]],"id":41788482}],"con":true,"img":false}]}
{"op":"mcm","clk":"5348498383","pt":1646218221430,"mc":[{"id":"1.195453676","rc":[{"atl":[[2.12,22.9],[2.1,8.29]],"id":37286329}],"con":true,"img":false}]}
{"op":"mcm","clk":"5348498438","pt":1646218221737,"mc":[{"id":"1.195453676","rc":[{"atl":[[2.1,4.26]],"id":37286329}],"con":true,"img":false}]}
{"op":"mcm","clk":"5348498482","pt":1646218221950,"mc":[{"id":"1.195453676","rc":[{"atl":[[2.1,12.99],[2.2,8.67]],"id":37286329}],"con":true,"img":false}]}
{"op":"mcm","clk":"5348498520","pt":1646218222118,"mc":[{"id":"1.195453676","rc":[{"atb":[[1.9,32.41]],"id":41788482}],"con":true,"img":false}]}
{"op":"mcm","clk":"5348498536","pt":1646218222222,"mc":[{"id":"1.195453676","rc":[{"atb":[[1.89,19.84]],"id":41788482}],"con":true,"img":false}]}
{"op":"mcm","clk":"5348498563","pt":1646218222331,"mc":[{"id":"1.195453676","rc":[{"atb":[[1.93,4.26]],"id":41788482}],"con":true,"img":false}]}
{"op":"mcm","clk":"5348498631","pt":1646218222712,"mc":[{"id":"1.195453676","rc":[{"atb":[[1.93,1.42]],"id":41788482}],"con":true,"img":false}]}
{"op":"mcm","clk":"5348498698","pt":1646218223111,"mc":[{"id":"1.195453676","rc":[{"atb":[[1.93,4.26]],"id":41788482},{"atl":[[2.02,0]],"id":41788482}],"con":true,"img":false}]}
{"op":"mcm","clk":"5348498737","pt":1646218223321,"mc":[{"id":"1.195453676","rc":[{"atl":[[2.08,8.76],[2.18,0]],"id":37286329}],"con":true,"img":false}]}
{"op":"mcm","clk":"5348498787","pt":1646218223647,"mc":[{"id":"1.195453676","rc":[{"atl":[[2.1,10.15]],"id":37286329}],"con":true,"img":false}]}
{"op":"mcm","clk":"5348498862","pt":1646218224013,"mc":[{"id":"1.195453676","rc":[{"atb":[[1.93,1.42]],"id":41788482}],"con":true,"img":false}]}
{"op":"mcm","clk":"5348498893","pt":1646218224219,"mc":[{"id":"1.195453676","rc":[{"atb":[[1.92,1.42]],"id":41788482}],"con":true,"img":false}]}
{"op":"mcm","clk":"5348499008","pt":1646218225013,"mc":[{"id":"1.195453676","rc":[{"atb":[[1.92,10.99]],"id":41788482}],"con":true,"img":false}]}
{"op":"mcm","clk":"5348499104","pt":1646218225694,"mc":[{"id":"1.195453676","rc":[{"atb":[[1.87,0]],"id":41788482}],"con":true,"img":false}]}
{"op":"mcm","clk":"5348499206","pt":1646218226464,"mc":[{"id":"1.195453676","rc":[{"atb":[[1.85,0],[1.93,10.98]],"id":41788482}],"con":true,"img":false}]}
{"op":"mcm","clk":"5348499239","pt":1646218226656,"mc":[{"id":"1.195453676","rc":[{"atb":[[1.92,42.7]],"id":41788482}],"con":true,"img":false}]}
{"op":"mcm","clk":"5348499264","pt":1646218226804,"mc":[{"id":"1.195453676","rc":[{"atl":[[2.12,8.58],[2.14,17.1]],"id":37286329}],"con":true,"img":false}]}
{"op":"mcm","clk":"5348499376","pt":1646218227445,"mc":[{"id":"1.195453676","rc":[{"atb":[[1.89,9.84],[1.87,2]],"id":41788482}],"con":true,"img":false}]}
{"op":"mcm","clk":"5348499421","pt":1646218227710,"mc":[{"id":"1.195453676","rc":[{"atl":[[2.06,0]],"id":41788482}],"con":true,"img":false}]}
{"op":"mcm","clk":"5348499435","pt":1646218227817,"mc":[{"id":"1.195453676","rc":[{"atl":[[2.02,21.79]],"id":41788482}],"con":true,"img":false}]}
{"op":"mcm","clk":"5348499652","pt":1646218229297,"mc":[{"id":"1.195453676","rc":[{"atb":[[1.93,19.5]],"id":41788482},{"atl":[[2.08,16.93]],"id":37286329}],"con":true,"img":false}]}
{"op":"mcm","clk":"5348499683","pt":1646218229511,"mc":[{"id":"1.195453676","rc":[{"atb":[[1.89,0],[1.94,9.5]],"id":41788482}],"con":true,"img":false}]}
{"op":"mcm","clk":"5348499728","pt":1646218229924,"mc":[{"id":"1.195453676","rc":[{"atb":[[1.93,10.98]],"id":41788482}],"con":true,"img":false}]}
{"op":"mcm","clk":"5348499737","pt":1646218230029,"mc":[{"id":"1.195453676","rc":[{"atb":[[1.94,18.02]],"id":41788482},{"atl":[[2.16,2.84],[2.06,8.86]],"id":37286329}],"con":true,"img":false}]}
{"op":"mcm","clk":"5348499765","pt":1646218230233,"mc":[{"id":"1.195453676","rc":[{"atb":[[1.95,9.42],[1.91,1.42]],"id":41788482}],"con":true,"img":false}]}
{"op":"mcm","clk":"5348499776","pt":1646218230341,"mc":[{"id":"1.195453676","rc":[{"atb":[[1.94,9.5]],"id":41788482}],"con":true,"img":false}]}
{"op":"mcm","clk":"5348499789","pt":1646218230394,"mc":[{"id":"1.195453676","rc":[{"atl":[[2.08,8.76]],"id":37286329}],"con":true,"img":false}]}
{"op":"mcm","clk":"5348499803","pt":1646218230514,"mc":[{"id":"1.195453676","rc":[{"atl":[[2.06,17.03]],"id":37286329}],"con":true,"img":false}]}
{"op":"mcm","clk":"5348499834","pt":1646218230705,"mc":[{"id":"1.195453676","rc":[{"atb":[[1.95,16.49],[1.88,0]],"id":41788482}],"con":true,"img":false}]}
{"op":"mcm","clk":"5348499848","pt":1646218230818,"mc":[{"id":"1.195453676","rc":[{"atb":[[1.96,9.36]],"id":41788482}],"con":true,"img":false}]}
{"op":"mcm","clk":"5348499863","pt":1646218230918,"mc":[{"id":"1.195453676","rc":[{"atl":[[2.06,18.45]],"id":37286329}],"con":true,"img":false}]}
{"op":"mcm","clk":"5348499880","pt":1646218231024,"mc":[{"id":"1.195453676","rc":[{"atb":[[1.92,33.13]],"id":41788482},{"atl":[[2.04,8.97],[2.12,0],[2.06,10.28]],"id":37286329}],"con":true,"img":false}]}
{"op":"mcm","clk":"5348499919","pt":1646218231337,"mc":[{"id":"1.195453676","rc":[{"atb":[[1.96,0],[1.94,0],[1.95,0],[1.93,0]],"id":41788482},{"atl":[[1.93,478.38]],"id":41788482},{"trd":[[1.93,27.36],[1.96,30.92],[1.94,29.93],[1.95,38.4]],"ltp":1.93,"tv":126.61,"id":41788482},{"atl":[[2.04,0],[2.06,0]],"id":37286329},{"trd":[[2.06,10.28],[2.04,30.13]],"ltp":2.06,"tv":40.41,"id":37286329}],"con":true,"img":false}]}
{"op":"mcm","clk":"5348499942","pt":1646218231549,"mc":[{"id":"1.195453676","rc":[{"atl":[[2,9.39],[2.04,10.81]],"id":41788482},{"atb":[[1.96,17.9]],"id":37286329},{"atl":[[2.08,0]],"id":37286329},{"trd":[[2.08,35.36]],"ltp":2.08,"tv":35.36,"id":37286329}],"con":true,"img":false}]}
{"op":"mcm","clk":"5348499959","pt":1646218231655,"mc":[{"id":"1.195453676","rc":[{"atb":[[1.92,1.42],[1.9,0],[1.86,33.92]],"id":41788482},{"atb":[[1.91,0]],"id":37286329}],"con":true,"img":false}]}
{"op":"mcm","clk":"5348499987","pt":1646218231867,"mc":[{"id":"1.195453676","rc":[{"atl":[[2.08,0]],"id":37286329}],"con":true,"img":false}]}
{"op":"mcm","clk":"5348500008","pt":1646218231973,"mc":[{"id":"1.195453676","rc":[{"atb":[[1.95,30.71],[1.97,4.47]],"id":37286329},{"atl":[[2.1,16.05]],"id":37286329}],"con":true,"img":false}]}
{"op":"mcm","clk":"5348500029","pt":1646218232141,"mc":[{"id":"1.195453676","rc":[{"atb":[[1.86,0]],"id":41788482}],"con":true,"img":false}]}
{"op":"mcm","clk":"5348500060","pt":1646218232352,"mc":[{"id":"1.195453676","rc":[{"atl":[[2.18,1.42]],"id":37286329}],"con":true,"img":false}]}
{"op":"mcm","clk":"5348500097","pt":1646218232556,"mc":[{"id":"1.195453676","rc":[{"atb":[[1.92,0],[1.91,0]],"id":41788482},{"trd":[[1.91,3.06],[1.92,2.84]],"ltp":1.91,"tv":5.9,"id":41788482},{"atl":[[2.1,0]],"id":37286329},{"trd":[[2.1,37.5]],"ltp":2.1,"tv":37.5,"id":37286329}],"con":true,"img":false}]}
{"op":"mcm","clk":"5348500121","pt":1646218232672,"mc":[{"id":"1.195453676","rc":[{"atb":[[1.85,34.32]],"id":41788482},{"atb":[[2,29.17],[1.98,8.83]],"id":37286329}],"con":true,"img":false}]}
{"op":"mcm","clk":"5348500130","pt":1646218232717,"mc":[{"id":"1.195453676","rc":[{"atb":[[1.84,19.64],[1.87,0]],"id":41788482},{"atl":[[2.14,0],[2.16,15.98]],"id":37286329}],"con":true,"img":false}]}
{"op":"mcm","clk":"5348500149","pt":1646218232837,"mc":[{"id":"1.195453676","rc":[{"atb":[[1.84,0],[1.86,31.73]],"id":41788482},{"atb":[[2.02,17.53]],"id":37286329}],"con":true,"img":false}]}
{"op":"mcm","clk":"5348500167","pt":1646218232932,"mc":[{"id":"1.195453676","rc":[{"atb":[[1.87,4]],"id":41788482}],"con":true,"img":false}]}
{"op":"mcm","clk":"5348500198","pt":1646218233151,"mc":[{"id":"1.195453676","rc":[{"atb":[[1.85,0],[1.87,35.51],[1.86,0]],"id":41788482},{"atb":[[1.93,0]],"id":37286329}],"con":true,"img":false}]}
{"op":"mcm","clk":"5348500212","pt":1646218233261,"mc":[{"id":"1.195453676","rc":[{"atb":[[1.87,31.51]],"id":41788482}],"con":true,"img":false}]}
{"op":"mcm","clk":"5348500275","pt":1646218233644,"mc":[{"id":"1.195453676","rc":[{"atb":[[1.85,34.32]],"id":41788482},{"atl":[[1000,0.07]],"id":41788482},{"atb":[[2.04,28.05]],"id":37286329}],"con":true,"img":false}]}
{"op":"mcm","clk":"5348500293","pt":1646218233789,"mc":[{"id":"1.195453676","rc":[{"atb":[[1.87,38.24]],"id":41788482},{"atl":[[1000,0]],"id":41788482}],"con":true,"img":false}]}
{"op":"mcm","clk":"5348500310","pt":1646218233858,"mc":[{"id":"1.195453676","rc":[{"atb":[[1.87,38.17]],"id":41788482},{"trd":[[1.87,2.14]],"ltp":1.87,"tv":2.14,"id":41788482},{"atl":[[2.16,22.33]],"id":37286329}],"con":true,"img":false}]}
{"op":"mcm","clk":"5348500350","pt":1646218234177,"mc":[{"id":"1.195453676","rc":[{"atb":[[2.06,8.77]],"id":37286329}],"con":true,"img":false}]}
{"op":"mcm","clk":"5348500401","pt":1646218234451,"mc":[{"id":"1.195453676","rc":[{"atb":[[1.97,0]],"id":37286329}],"con":true,"img":false}]}
{"op":"mcm","clk":"5348500412","pt":1646218234570,"mc":[{"id":"1.195453676","rc":[{"atl":[[1.93,449.93]],"id":41788482},{"trd":[[1.93,55.81]],"ltp":1.93,"tv":55.81,"id":41788482},{"atb":[[2.06,0]],"id":37286329},{"trd":[[2.06,54.48]],"ltp":2.06,"tv":54.48,"id":37286329}],"con":true,"img":false}]}
{"op":"mcm","clk":"5348500461","pt":1646218234845,"mc":[{"id":"1.195453676","rc":[{"atb":[[2.06,8.78]],"id":37286329}],"con":true,"img":false}]}
{"op":"mcm","clk":"5348500557","pt":1646218235535,"mc":[{"id":"1.195453676","rc":[{"atl":[[1.96,1.42]],"id":41788482},{"atb":[[1.99,1.42]],"id":37286329},{"atl":[[2.28,1.42]],"id":37286329}],"con":true,"img":false}]}
{"op":"mcm","clk":"5348500600","pt":1646218235949,"mc":[{"id":"1.195453676","rc":[{"atl":[[1.96,11]],"id":41788482}],"con":true,"img":false}]}
{"op":"mcm","clk":"5348500614","pt":1646218236059,"mc":[{"id":"1.195453676","rc":[{"atl":[[2.18,0]],"id":41788482}],"con":true,"img":false}]}
{"op":"mcm","clk":"5348500648","pt":1646218236322,"mc":[{"id":"1.195453676","rc":[{"atb":[[1.87,31.44]],"id":41788482},{"atb":[[2.06,3.33]],"id":37286329},{"atl":[[2.16,15.98]],"id":37286329},{"trd":[[2.06,65.38]],"ltp":2.06,"tv":65.38,"id":37286329}],"con":true,"img":false}]}
{"op":"mcm","clk":"5348500659","pt":1646218236429,"mc":[{"id":"1.195453676","rc":[{"atl":[[2.22,8.62],[2.18,0]],"id":37286329}],"con":true,"img":false}]}
{"op":"mcm","clk":"5348500674","pt":1646218236547,"mc":[{"id":"1.195453676","rc":[{"atl":[[2.02,0]],"id":41788482}],"con":true,"img":false}]}
{"op":"mcm","clk":"5348500864","pt":1646218237962,"mc":[{"id":"1.195453676","rc":[{"atl":[[1.94,1.42]],"id":41788482},{"atb":[[1.99,2.84]],"id":37286329}],"con":true,"img":false}]}
{"op":"mcm","clk":"5348500909","pt":1646218238281,"mc":[{"id":"1.195453676","rc":[{"atl":[[1.94,11.06]],"id":41788482}],"con":true,"img":false}]}
{"op":"mcm","clk":"5348500937","pt":1646218238494,"mc":[{"id":"1.195453676","rc":[{"atl":[[2.16,0]],"id":41788482}],"con":true,"img":false}]}
{"op":"mcm","clk":"5348501036","pt":1646218239368,"mc":[{"id":"1.195453676","rc":[{"atl":[[2.28,0]],"id":37286329}],"con":true,"img":false}]}
{"op":"mcm","clk":"5348501061","pt":1646218239527,"mc":[{"id":"1.195453676","rc":[{"atl":[[2.12,0],[1.92,9.68]],"id":41788482}],"con":true,"img":false}]}
{"op":"mcm","clk":"5348501093","pt":1646218239759,"mc":[{"id":"1.195453676","rc":[{"atl":[[1.92,0]],"id":41788482}],"con":true,"img":false}]}
{"op":"mcm","clk":"5348501118","pt":1646218239953,"mc":[{"id":"1.195453676","rc":[{"atl":[[1.92,9.74]],"id":41788482}],"con":true,"img":false}]}
{"op":"mcm","clk":"5348501167","pt":1646218240371,"mc":[{"id":"1.195453676","rc":[{"atb":[[1.87,0]],"id":41788482},{"atl":[[1.87,14.9]],"id":41788482},{"trd":[[1.87,64.99]],"ltp":1.87,"tv":64.99,"id":41788482}],"con":true,"img":false}]}
{"op":"mcm","clk":"5348501190","pt":1646218240585,"mc":[{"id":"1.195453676","rc":[{"atb":[[1.86,21]],"id":41788482},{"atl":[[1.87,6.28],[1.88,8.33]],"id":41788482},{"trd":[[1.87,82.23]],"ltp":1.87,"tv":82.23,"id":41788482}],"con":true,"img":false}]}
{"op":"mcm","clk":"5348501204","pt":1646218240686,"mc":[{"id":"1.195453676","rc":[{"atb":[[1.85,0],[1.86,8.35]],"id":41788482},{"trd":[[1.86,25.31]],"ltp":1.86,"tv":25.31,"id":41788482},{"atb":[[1.95,0]],"id":37286329}],"con":true,"img":false}]}
{"op":"mcm","clk":"5348501216","pt":1646218240740,"mc":[{"id":"1.195453676","rc":[{"atl":[[1.87,0]],"id":41788482},{"trd":[[1.87,94.81]],"ltp":1.87,"tv":94.81,"id":41788482}],"con":true,"img":false}]}
{"op":"mcm","clk":"5348501227","pt":1646218240849,"mc":[{"id":"1.195453676","rc":[{"atb":[[1.86,0]],"id":41788482},{"atl":[[1.87,3.15],[1.88,9.97]],"id":41788482},{"trd":[[1.86,60.6]],"ltp":1.86,"tv":60.6,"id":41788482},{"atl":[[2.2,0],[2.16,0]],"id":37286329},{"trd":[[2.16,34.4]],"ltp":2.16,"tv":34.4,"id":37286329}],"con":true,"img":false}]}
{"op":"mcm","clk":"5348501238","pt":1646218240951,"mc":[{"id":"1.195453676","rc":[{"atl":[[2,0]],"id":41788482}],"con":true,"img":false}]}
{"op":"mcm","clk":"5348501248","pt":1646218241061,"mc":[{"id":"1.195453676","rc":[{"atb":[[1.83,0]],"id":41788482},{"atl":[[1.87,0]],"id":41788482},{"atb":[[2.06,7.84]],"id":37286329}],"con":true,"img":false}]}
{"op":"mcm","clk":"5348501263","pt":1646218241165,"mc":[{"id":"1.195453676","rc":[{"atb":[[1.83,6.97],[1.8,36.47]],"id":41788482},{"atl":[[1.98,1.42]],"id":41788482},{"atb":[[2.08,27.01],[1.97,1.42]],"id":37286329},{"atl":[[2.22,15.07]],"id":37286329}],"con":true,"img":false}]}
{"op":"mcm","clk":"5348501278","pt":1646218241280,"mc":[{"id":"1.195453676","rc":[{"atl":[[1.88,19.81]],"id":41788482}],"con":true,"img":false}]}
{"op":"mcm","clk":"5348501298","pt":1646218241481,"mc":[{"id":"1.195453676","rc":[{"atl":[[1.96,1.42],[1.87,10.04]],"id":41788482},{"atb":[[1.96,8.95],[2.1,16.81]],"id":37286329}],"con":true,"img":false}]}
{"op":"mcm","clk":"5348501314","pt":1646218241530,"mc":[{"id":"1.195453676","rc":[{"atb":[[1.83,0]],"id":41788482}],"con":true,"img":false}]}
{"op":"mcm","clk":"5348501337","pt":1646218241654,"mc":[{"id":"1.195453676","rc":[{"atl":[[2.22,6.45]],"id":37286329}],"con":true,"img":false}]}
{"op":"mcm","clk":"5348501346","pt":1646218241744,"mc":[{"id":"1.195453676","rc":[{"atl":[[1000,0.07]],"id":41788482}],"con":true,"img":false}]}
{"op":"mcm","clk":"5348501359","pt":1646218241850,"mc":[{"id":"1.195453676","rc":[{"atb":[[1.81,20.26]],"id":41788482}],"con":true,"img":false}]}
{"op":"mcm","clk":"5348501367","pt":1646218241955,"mc":[{"id":"1.195453676","rc":[{"atl":[[1000,0],[1.88,9.97],[1.87,15.26]],"id":41788482},{"atb":[[2.1,21.24],[2.06,3.33]],"id":37286329},{"atl":[[2.22,0]],"id":37286329}],"con":true,"img":false}]}
{"op":"mcm","clk":"5348501377","pt":1646218242058,"mc":[{"id":"1.195453676","rc":[{"atl":[[1.83,0.07]],"id":41788482}],"con":true,"img":false}]}
{"op":"mcm","clk":"5348501388","pt":1646218242163,"mc":[{"id":"1.195453676","rc":[{"atb":[[1.8,0],[1.79,36.92]],"id":41788482},{"atb":[[2,0],[1.98,0],[2.12,8.36]],"id":37286329}],"con":true,"img":false}]}
{"op":"mcm","clk":"5348501420","pt":1646218242377,"mc":[{"id":"1.195453676","rc":[{"atl":[[2.26,17.87]],"id":37286329}],"con":true,"img":false}]}
{"op":"mcm","clk":"5348501515","pt":1646218243075,"mc":[{"id":"1.195453676","rc":[{"atl":[[1.87,5.22]],"id":41788482}],"con":true,"img":false}]}
{"op":"mcm","clk":"5348501567","pt":1646218243429,"mc":[{"id":"1.195453676","rc":[{"atl":[[1.87,15.26]],"id":41788482}],"con":true,"img":false}]}
{"op":"mcm","clk":"5348501578","pt":1646218243533,"mc":[{"id":"1.195453676","rc":[{"atl":[[2,1.42]],"id":41788482},{"atb":[[2,1.42]],"id":37286329}],"con":true,"img":false}]}
{"op":"mcm","clk":"5348501641","pt":1646218244059,"mc":[{"id":"1.195453676","rc":[{"atl":[[1.87,24]],"id":41788482}],"con":true,"img":false}]}
{"op":"mcm","clk":"5348501695","pt":1646218244477,"mc":[{"id":"1.195453676","rc":[{"atl":[[1.87,13.96]],"id":41788482}],"con":true,"img":false}]}
{"op":"mcm","clk":"5348501722","pt":1646218244633,"mc":[{"id":"1.195453676","rc":[{"atb":[[2.12,34.41]],"id":37286329}],"con":true,"img":false}]}
{"op":"mcm","clk":"5348501740","pt":1646218244741,"mc":[{"id":"1.195453676","rc":[{"atl":[[1.87,24.04]],"id":41788482}],"con":true,"img":false}]}
{"op":"mcm","clk":"5348501754","pt":1646218244845,"mc":[{"id":"1.195453676","rc":[{"atb":[[2.14,8.37]],"id":37286329}],"con":true,"img":false}]}
{"op":"mcm","clk":"5348501769","pt":1646218244946,"mc":[{"id":"1.195453676","rc":[{"atb":[[2.02,8.76]],"id":37286329}],"con":true,"img":false}]}
{"op":"mcm","clk":"5348501801","pt":1646218245174,"mc":[{"id":"1.195453676","rc":[{"atb":[[1.79,0]],"id":41788482}],"con":true,"img":false}]}
{"op":"mcm","clk":"5348501812","pt":1646218245290,"mc":[{"id":"1.195453676","rc":[{"atl":[[1.89,1.42]],"id":41788482},{"atb":[[2,2.84]],"id":37286329}],"con":true,"img":false}]}
{"op":"mcm","clk":"5348501861","pt":1646218245634,"mc":[{"id":"1.195453676","rc":[{"atb":[[1.78,37.4]],"id":41788482}],"con":true,"img":false}]}
{"op":"mcm","clk":"5348501892","pt":1646218245849,"mc":[{"id":"1.195453676","rc":[{"atb":[[1.81,9.92]],"id":41788482},{"atl":[[2.26,8.48]],"id":37286329}],"con":true,"img":false}]}
{"op":"mcm","clk":"5348501901","pt":1646218245949,"mc":[{"id":"1.195453676","rc":[{"atl":[[1.86,10.14],[1.94,1.42]],"id":41788482}],"con":true,"img":false}]}
{"op":"mcm","clk":"5348501929","pt":1646218246161,"mc":[{"id":"1.195453676","rc":[{"atb":[[1.78,0]],"id":41788482},{"atb":[[2.08,0],[2.12,8.36]],"id":37286329}],"con":true,"img":false}]}
{"op":"mcm","clk":"5348501951","pt":1646218246372,"mc":[{"id":"1.195453676","rc":[{"atb":[[1.81,0]],"id":41788482},{"atl":[[2.26,0]],"id":37286329}],"con":true,"img":false}]}
{"op":"mcm","clk":"5348501964","pt":1646218246477,"mc":[{"id":"1.195453676","rc":[{"atb":[[1.81,9.27]],"id":41788482},{"atl":[[2.26,8.54]],"id":37286329}],"con":true,"img":false}]}
{"op":"mcm","clk":"5348501987","pt":1646218246691,"mc":[{"id":"1.195453676","rc":[{"atb":[[1.59,49.44],[1.81,0]],"id":41788482},{"trd":[[1.81,19.96]],"ltp":1.81,"tv":19.96,"id":41788482},{"atb":[[2.16,25.15],[2.04,0]],"id":37286329}],"con":true,"img":false}]}
{"op":"mcm","clk":"5348502001","pt":1646218246741,"mc":[{"id":"1.195453676","rc":[{"atl":[[1.92,0],[1.83,10.43]],"id":41788482}],"con":true,"img":false}]}
{"op":"mcm","clk":"5348502014","pt":1646218246848,"mc":[{"id":"1.195453676","rc":[{"atb":[[2.18,8.16],[2.06,0]],"id":37286329},{"atl":[[2.26,0]],"id":37286329}],"con":true,"img":false}]}
{"op":"mcm","clk":"5348502054","pt":1646218247159,"mc":[{"id":"1.195453676","rc":[{"atb":[[2.1,16.81]],"id":37286329}],"con":true,"img":false}]}
{"op":"mcm","clk":"5348502093","pt":1646218247474,"mc":[{"id":"1.195453676","rc":[{"atl":[[1.93,0]],"id":41788482}],"con":true,"img":false}]}
{"op":"mcm","clk":"5348502102","pt":1646218247580,"mc":[{"id":"1.195453676","rc":[{"atb":[[1.56,0]],"id":41788482},{"atb":[[1.89,0]],"id":37286329}],"con":true,"img":false}]}
{"op":"mcm","clk":"5348502119","pt":1646218247690,"mc":[{"id":"1.195453676","rc":[{"atb":[[1.53,8.81]],"id":41788482},{"atb":[[1.94,12.87]],"id":37286329}],"con":true,"img":false}]}
{"op":"mcm","clk":"5348502129","pt":1646218247742,"mc":[{"id":"1.195453676","rc":[{"atl":[[2.5,21.05]],"id":37286329}],"con":true,"img":false}]}
{"op":"mcm","clk":"5348502141","pt":1646218247844,"mc":[{"id":"1.195453676","rc":[{"atb":[[1.59,78.37]],"id":41788482}],"con":true,"img":false}]}
{"op":"mcm","clk":"5348502189","pt":1646218248164,"mc":[{"id":"1.195453676","rc":[{"atb":[[1.62,47.05]],"id":41788482}],"con":true,"img":false}]}
{"op":"mcm","clk":"5348502223","pt":1646218248477,"mc":[{"id":"1.195453676","rc":[{"atl":[[1.92,1.42]],"id":41788482},{"atb":[[2.08,1.42]],"id":37286329}],"con":true,"img":false}]}
{"op":"mcm","clk":"5348502235","pt":1646218248529,"mc":[{"id":"1.195453676","rc":[{"atb":[[1.59,49.44]],"id":41788482},{"atl":[[2.5,8.45]],"id":37286329}],"con":true,"img":false}]}
{"op":"mcm","clk":"5348502308","pt":1646218249164,"mc":[{"id":"1.195453676","rc":[{"atb":[[1.62,23.92]],"id":41788482},{"atl":[[2.5,20.48]],"id":37286329}],"con":true,"img":false}]}
{"op":"mcm","clk":"5348502358","pt":1646218249582,"mc":[{"id":"1.195453676","rc":[{"atb":[[1.62,0]],"id":41788482},{"atl":[[1000,1.69]],"id":37286329}],"con":true,"img":false}]}
{"op":"mcm","clk":"5348502385","pt":1646218249794,"mc":[{"id":"1.195453676","rc":[{"atl":[[1000,0.02]],"id":37286329}],"con":true,"img":false}]}
{"op":"mcm","clk":"5348502409","pt":1646218249952,"mc":[{"id":"1.195453676","rc":[{"atl":[[1000,0]],"id":37286329}],"con":true,"img":false}]}
{"op":"mcm","clk":"5348502421","pt":1646218250054,"mc":[{"id":"1.195453676","rc":[{"atb":[[1.59,77.48]],"id":41788482},{"atl":[[2.3,0.02]],"id":37286329}],"con":true,"img":false}]}
{"op":"mcm","clk":"5348502434","pt":1646218250168,"mc":[{"id":"1.195453676","rc":[{"atb":[[1.62,47.05]],"id":41788482}],"con":true,"img":false}]}
{"op":"mcm","clk":"5348502451","pt":1646218250267,"mc":[{"id":"1.195453676","rc":[{"atl":[[2.3,0]],"id":37286329},{"trd":[[2.3,0.04]],"ltp":2.3,"tv":0.04,"id":37286329}],"con":true,"img":false}]}
{"op":"mcm","clk":"5348502474","pt":1646218250472,"mc":[{"id":"1.195453676","rc":[{"atl":[[2.48,16.54]],"id":37286329}],"con":true,"img":false}]}
{"op":"mcm","clk":"5348502485","pt":1646218250575,"mc":[{"id":"1.195453676","rc":[{"atb":[[1.59,49.44]],"id":41788482},{"atl":[[1.82,1.42]],"id":41788482},{"atb":[[2.22,1.42]],"id":37286329}],"con":true,"img":false}]}
{"op":"mcm","clk":"5348502502","pt":1646218250680,"mc":[{"id":"1.195453676","rc":[{"atb":[[1.59,0]],"id":41788482},{"atl":[[1.83,0],[1.82,0]],"id":41788482},{"trd":[[1.83,10.43],[1.82,1.42]],"ltp":1.83,"tv":11.85,"id":41788482},{"atb":[[2.22,0]],"id":37286329},{"atl":[[2.2,83.77]],"id":37286329},{"trd":[[2.2,9.85],[2.22,2.84]],"ltp":2.2,"tv":12.69,"id":37286329}],"con":true,"img":false}]}
{"op":"mcm","clk":"5348502511","pt":1646218250785,"mc":[{"id":"1.195453676","rc":[{"atl":[[1.88,0]],"id":41788482},{"trd":[[1.83,20.98]],"ltp":1.83,"tv":20.98,"id":41788482},{"atb":[[2.1,8.4]],"id":37286329},{"atl":[[2.2,66.95]],"id":37286329},{"trd":[[2.2,34.72]],"ltp":2.2,"tv":34.72,"id":37286329}],"con":true,"img":false}]}
{"op":"mcm","clk":"5348502520","pt":1646218250837,"mc":[{"id":"1.195453676","rc":[{"atl":[[2.5,8.45],[2.2,32.11]],"id":37286329},{"trd":[[2.2,104.42]],"ltp":2.2,"tv":104.42,"id":37286329}],"con":true,"img":false}]}
{"op":"mcm","clk":"5348502538","pt":1646218250995,"mc":[{"id":"1.195453676","rc":[{"atb":[[1.62,80.79],[1.63,55.1]],"id":41788482},{"atb":[[2.18,0]],"id":37286329},{"atl":[[2.46,16.15],[2.2,0]],"id":37286329},{"trd":[[2.18,20.38],[2.2,168.66]],"ltp":2.18,"tv":189.04,"id":37286329}],"con":true,"img":false}]}
{"op":"mcm","clk":"5348502546","pt":1646218251047,"mc":[{"id":"1.195453676","rc":[{"atb":[[1.79,11.17]],"id":41788482},{"atb":[[2.1,18.88]],"id":37286329}],"con":true,"img":false}]}
{"op":"mcm","clk":"5348502558","pt":1646218251151,"mc":[{"id":"1.195453676","rc":[{"atb":[[1.62,33.74],[1.78,37.4]],"id":41788482},{"atb":[[2.1,45.41],[2.16,0]],"id":37286329}],"con":true,"img":false}]}
{"op":"mcm","clk":"5348502584","pt":1646218251357,"mc":[{"id":"1.195453676","rc":[{"atl":[[2.2,8.52]],"id":37286329}],"con":true,"img":false}]}
{"op":"mcm","clk":"5348502598","pt":1646218251463,"mc":[{"id":"1.195453676","rc":[{"atb":[[1.62,0]],"id":41788482}],"con":true,"img":false}]}
{"op":"mcm","clk":"5348502612","pt":1646218251570,"mc":[{"id":"1.195453676","rc":[{"atb":[[1.8,10.4],[1.63,88.84]],"id":41788482},{"atl":[[1.92,0],[1.89,0],[1.94,0]],"id":41788482}],"con":true,"img":false}]}
{"op":"mcm","clk":"5348502620","pt":1646218251671,"mc":[{"id":"1.195453676","rc":[{"atb":[[1.78,0]],"id":41788482},{"atb":[[2.1,18.88]],"id":37286329},{"atl":[[2.2,0]],"id":37286329}],"con":true,"img":false}]}
{"op":"mcm","clk":"5348502678","pt":1646218252101,"mc":[{"id":"1.195453676","rc":[{"atl":[[1000,1.69]],"id":41788482},{"atb":[[2.14,12.21]],"id":37286329}],"con":true,"img":false}]}
{"op":"mcm","clk":"5348502696","pt":1646218252158,"mc":[{"id":"1.195453676","rc":[{"atb":[[1.69,42.28]],"id":41788482},{"atb":[[2.08,28.43]],"id":37286329},{"atl":[[1000,0.07],[2.46,33.08]],"id":37286329}],"con":true,"img":false}]}
{"op":"mcm","clk":"5348502707","pt":1646218252251,"mc":[{"id":"1.195453676","rc":[{"atl":[[1000,0.02]],"id":41788482}],"con":true,"img":false}]}
{"op":"mcm","clk":"5348502721","pt":1646218252360,"mc":[{"id":"1.195453676","rc":[{"atl":[[1000,0]],"id":37286329}],"con":true,"img":false}]}
{"op":"mcm","clk":"5348502737","pt":1646218252459,"mc":[{"id":"1.195453676","rc":[{"atl":[[1000,0],[1.86,10.07]],"id":41788482},{"trd":[[1.86,60.67]],"ltp":1.86,"tv":60.67,"id":41788482},{"atb":[[2.18,0]],"id":37286329},{"trd":[[2.16,34.46],[2.18,20.39]],"ltp":2.16,"tv":54.85,"id":37286329}],"con":true,"img":false}]}
{"op":"mcm","clk":"5348502748","pt":1646218252560,"mc":[{"id":"1.195453676","rc":[{"atl":[[1.85,0.02]],"id":41788482}],"con":true,"img":false}]}
{"op":"mcm","clk":"5348502809","pt":1646218253090,"mc":[{"id":"1.195453676","rc":[{"atb":[[1.2,0],[1.4,11],[1.3,0]],"id":41788482},{"atb":[[1.94,7.13]],"id":37286329}],"con":true,"img":false}]}
{"op":"mcm","clk":"5348502856","pt":1646218253459,"mc":[{"id":"1.195453676","rc":[{"atb":[[2.24,1.42]],"id":37286329}],"con":true,"img":false}]}
{"op":"mcm","clk":"5348502877","pt":1646218253666,"mc":[{"id":"1.195453676","rc":[{"trd":[[1.81,21.72]],"ltp":1.81,"tv":21.72,"id":41788482},{"atb":[[2.24,0]],"id":37286329},{"trd":[[2.24,2.57]],"ltp":2.24,"tv":2.57,"id":37286329}],"con":true,"img":false}]}
{"op":"mcm","clk":"5348502933","pt":1646218254090,"mc":[{"id":"1.195453676","rc":[{"atl":[[1.87,15.3]],"id":41788482}],"con":true,"img":false}]}
{"op":"mcm","clk":"5348502953","pt":1646218254243,"mc":[{"id":"1.195453676","rc":[{"atl":[[2.44,8.12]],"id":37286329}],"con":true,"img":false}]}
{"op":"mcm","clk":"5348502986","pt":1646218254509,"mc":[{"id":"1.195453676","rc":[{"atb":[[1.78,27.24]],"id":41788482}],"con":true,"img":false}]}
{"op":"mcm","clk":"5348502993","pt":1646218254562,"mc":[{"id":"1.195453676","rc":[{"atl":[[2.46,16.15]],"id":37286329}],"con":true,"img":false}]}
{"op":"mcm","clk":"5348503009","pt":1646218254668,"mc":[{"id":"1.195453676","rc":[{"atl":[[1.98,0],[1.96,0]],"id":41788482},{"atb":[[2.08,27.01]],"id":37286329},{"atl":[[2.44,25.05]],"id":37286329}],"con":true,"img":false}]}
{"op":"mcm","clk":"5348503056","pt":1646218254986,"mc":[{"id":"1.195453676","rc":[{"atl":[[2.42,16.21]],"id":37286329}],"con":true,"img":false}]}
{"op":"mcm","clk":"5348503095","pt":1646218255247,"mc":[{"id":"1.195453676","rc":[{"atl":[[2.44,8.12]],"id":37286329}],"con":true,"img":false}]}
{"op":"mcm","clk":"5348503113","pt":1646218255357,"mc":[{"id":"1.195453676","rc":[{"atl":[[2.42,33.14]],"id":37286329}],"con":true,"img":false}]}
{"op":"mcm","clk":"5348503121","pt":1646218255466,"mc":[{"id":"1.195453676","rc":[{"atb":[[1.8,0]],"id":41788482},{"atl":[[1.8,3.22]],"id":41788482},{"trd":[[1.8,21.9]],"ltp":1.8,"tv":21.9,"id":41788482}],"con":true,"img":false}]}
{"op":"mcm","clk":"5348503143","pt":1646218255668,"mc":[{"id":"1.195453676","rc":[{"atb":[[1.75,38.9]],"id":41788482},{"atl":[[1.8,0]],"id":41788482},{"trd":[[1.8,28.34]],"ltp":1.8,"tv":28.34,"id":41788482},{"atb":[[2.16,8.11],[2.12,34.41]],"id":37286329},{"atl":[[2.48,0],[2.4,28.37]],"id":37286329}],"con":true,"img":false}]}
{"op":"mcm","clk":"5348503167","pt":1646218255884,"mc":[{"id":"1.195453676","rc":[{"atb":[[1.8,10.44]],"id":41788482},{"atb":[[1.81,0]],"id":37286329},{"atl":[[2.38,8.1]],"id":37286329}],"con":true,"img":false}]}
{"op":"mcm","clk":"5348503201","pt":1646218256091,"mc":[{"id":"1.195453676","rc":[{"atl":[[2.42,16.21]],"id":37286329}],"con":true,"img":false}]}
{"op":"mcm","clk":"5348503209","pt":1646218256192,"mc":[{"id":"1.195453676","rc":[{"atb":[[1.63,54.64],[1.81,21.61]],"id":41788482},{"atb":[[2.14,8.37]],"id":37286329},{"atl":[[2.4,45.3]],"id":37286329}],"con":true,"img":false}]}
{"op":"mcm","clk":"5348503250","pt":1646218256456,"mc":[{"id":"1.195453676","rc":[{"atb":[[1.79,0]],"id":41788482}],"con":true,"img":false}]}
{"op":"mcm","clk":"5348503280","pt":1646218256670,"mc":[{"id":"1.195453676","rc":[{"atb":[[1.78,64.65]],"id":41788482}],"con":true,"img":false}]}
{"op":"mcm","clk":"5348503290","pt":1646218256769,"mc":[{"id":"1.195453676","rc":[{"atl":[[2.4,28.37]],"id":37286329}],"con":true,"img":false}]}
{"op":"mcm","clk":"5348503306","pt":1646218256877,"mc":[{"id":"1.195453676","rc":[{"atl":[[2.38,25.03]],"id":37286329}],"con":true,"img":false}]}
{"op":"mcm","clk":"5348503446","pt":1646218257967,"mc":[{"id":"1.195453676","rc":[{"atb":[[1.78,75.89]],"id":41788482},{"atb":[[2.1,29.36]],"id":37286329}],"con":true,"img":false}]}
{"op":"mcm","clk":"5348503563","pt":1646218258864,"mc":[{"id":"1.195453676","rc":[{"atl":[[2.36,8.09]],"id":37286329}],"con":true,"img":false}]}
{"op":"mcm","clk":"5348503603","pt":1646218259168,"mc":[{"id":"1.195453676","rc":[{"atl":[[2.38,8.1]],"id":37286329}],"con":true,"img":false}]}
{"op":"mcm","clk":"5348503621","pt":1646218259277,"mc":[{"id":"1.195453676","rc":[{"atl":[[2.36,25.02]],"id":37286329}],"con":true,"img":false}]}
{"op":"mcm","clk":"5348503672","pt":1646218259692,"mc":[{"id":"1.195453676","rc":[{"atb":[[2.06,1.42]],"id":37286329},{"atl":[[2.28,1.42]],"id":37286329}],"con":true,"img":false}]}
{"op":"mcm","clk":"5348503681","pt":1646218259795,"mc":[{"id":"1.195453676","rc":[{"atl":[[2.34,16.14]],"id":37286329}],"con":true,"img":false}]}
{"op":"mcm","clk":"5348503694","pt":1646218259899,"mc":[{"id":"1.195453676","rc":[{"atl":[[2.46,8.07]],"id":37286329}],"con":true,"img":false}]}
{"op":"mcm","clk":"5348503745","pt":1646218260272,"mc":[{"id":"1.195453676","rc":[{"atl":[[2.44,0],[2.28,17.6],[2.46,0]],"id":37286329}],"con":true,"img":false}]}
{"op":"mcm","clk":"5348503819","pt":1646218260898,"mc":[{"id":"1.195453676","rc":[{"atl":[[2.26,33.75],[2.4,0]],"id":37286329}],"con":true,"img":false}]}
{"op":"mcm","clk":"5348503859","pt":1646218261167,"mc":[{"id":"1.195453676","rc":[{"atb":[[1.77,11.3]],"id":41788482}],"con":true,"img":false}]}
{"op":"mcm","clk":"5348503913","pt":1646218261583,"mc":[{"id":"1.195453676","rc":[{"atb":[[1.53,0]],"id":41788482}],"con":true,"img":false}]}
{"op":"mcm","clk":"5348503928","pt":1646218261692,"mc":[{"id":"1.195453676","rc":[{"atb":[[1.51,8.81]],"id":41788482}],"con":true,"img":false}]}
{"op":"mcm","clk":"5348503951","pt":1646218261900,"mc":[{"id":"1.195453676","rc":[{"atb":[[1.78,48.64]],"id":41788482},{"atl":[[2.24,8.09],[2.42,8.1]],"id":37286329}],"con":true,"img":false}]}
{"op":"mcm","clk":"5348503971","pt":1646218262006,"mc":[{"id":"1.195453676","rc":[{"atb":[[1.84,27.24]],"id":41788482}],"con":true,"img":false}]}
{"op":"mcm","clk":"5348503992","pt":1646218262164,"mc":[{"id":"1.195453676","rc":[{"atb":[[1.84,52.99],[1.69,0],[1.81,0]],"id":41788482},{"atl":[[1.85,0]],"id":41788482},{"trd":[[1.85,0.04]],"ltp":1.85,"tv":0.04,"id":41788482}],"con":true,"img":false}]}
{"op":"mcm","clk":"5348504052","pt":1646218262690,"mc":[{"id":"1.195453676","rc":[{"atb":[[1.8,46.91]],"id":41788482},{"atb":[[2.1,55.89],[2.12,8.36]],"id":37286329}],"con":true,"img":false}]}
{"op":"mcm","clk":"5348504088","pt":1646218262956,"mc":[{"id":"1.195453676","rc":[{"atl":[[2.28,16.18]],"id":37286329}],"con":true,"img":false}]}
{"op":"mcm","clk":"5348504097","pt":1646218263061,"mc":[{"id":"1.195453676","rc":[{"atb":[[1.81,10.39]],"id":41788482}],"con":true,"img":false}]}
{"op":"mcm","clk":"5348504144","pt":1646218263483,"mc":[{"id":"1.195453676","rc":[{"atb":[[2.16,0]],"id":37286329}],"con":true,"img":false}]}
{"op":"mcm","clk":"5348504165","pt":1646218263691,"mc":[{"id":"1.195453676","rc":[{"atb":[[1.84,44.26]],"id":41788482},{"trd":[[1.84,17.47]],"ltp":1.84,"tv":17.47,"id":41788482},{"atb":[[2.14,12.21]],"id":37286329}],"con":true,"img":false}]}
{"op":"mcm","clk":"5348504179","pt":1646218263801,"mc":[{"id":"1.195453676","rc":[{"atb":[[1.39,13.83],[1.29,20.6],[1.49,11]],"id":41788482},{"atl":[[1.86,0]],"id":41788482},{"trd":[[1.86,80.84]],"ltp":1.86,"tv":80.84,"id":41788482},{"atb":[[1.93,5.8],[1.83,6.5],[2.06,6.51]],"id":37286329}],"con":true,"img":false}]}
{"op":"mcm","clk":"5348504219","pt":1646218264166,"mc":[{"id":"1.195453676","rc":[{"atb":[[1.75,0]],"id":41788482},{"atb":[[2.1,29.36]],"id":37286329}],"con":true,"img":false}]}
{"op":"mcm","clk":"5348504259","pt":1646218264585,"mc":[{"id":"1.195453676","rc":[{"atb":[[1.63,20.9]],"id":41788482},{"atl":[[2.36,8.09]],"id":37286329}],"con":true,"img":false}]}
{"op":"mcm","clk":"5348504315","pt":1646218265052,"mc":[{"id":"1.195453676","rc":[{"atb":[[1.82,35.42]],"id":41788482}],"con":true,"img":false}]}
{"op":"mcm","clk":"5348504325","pt":1646218265216,"mc":[{"id":"1.195453676","rc":[{"atb":[[1.85,10.13]],"id":41788482},{"atl":[[2.24,14.75]],"id":37286329}],"con":true,"img":false}]}
{"op":"mcm","clk":"5348504354","pt":1646218265427,"mc":[{"id":"1.195453676","rc":[{"atb":[[1.84,18.51],[1.85,36.25]],"id":41788482},{"atl":[[1.87,5.22]],"id":41788482},{"atl":[[2.22,8.36],[2.38,0]],"id":37286329}],"con":true,"img":false}]}
{"op":"mcm","clk":"5348504379","pt":1646218265682,"mc":[{"id":"1.195453676","rc":[{"atb":[[2.08,0],[2.06,34.03]],"id":37286329}],"con":true,"img":false}]}
{"op":"mcm","clk":"5348504394","pt":1646218265789,"mc":[{"id":"1.195453676","rc":[{"atl":[[2.24,8.09]],"id":37286329}],"con":true,"img":false}]}
{"op":"mcm","clk":"5348504406","pt":1646218265892,"mc":[{"id":"1.195453676","rc":[{"atl":[[2.22,15.02]],"id":37286329}],"con":true,"img":false}]}
{"op":"mcm","clk":"5348504417","pt":1646218265998,"mc":[{"id":"1.195453676","rc":[{"atl":[[2,0],[2.22,0],[2.04,9.39],[2.1,0],[2.08,0],[2.2,0]],"id":41788482},{"atb":[[2,0],[1.99,0],[2.06,32.61],[1.97,0]],"id":37286329}],"con":true,"img":false}]}
{"op":"mcm","clk":"5348504427","pt":1646218266099,"mc":[{"id":"1.195453676","rc":[{"atl":[[2.26,0],[2.2,20.59]],"id":37286329}],"con":true,"img":false}]}
{"op":"mcm","clk":"5348504440","pt":1646218266208,"mc":[{"id":"1.195453676","rc":[{"atl":[[2.34,8.07],[2.2,28.96]],"id":37286329}],"con":true,"img":false}]}
{"op":"mcm","clk":"5348504449","pt":1646218266260,"mc":[{"id":"1.195453676","rc":[{"atl":[[2.22,8.36]],"id":37286329}],"con":true,"img":false}]}
{"op":"mcm","clk":"5348504459","pt":1646218266365,"mc":[{"id":"1.195453676","rc":[{"atb":[[1.77,0]],"id":41788482},{"atl":[[2.18,8.37]],"id":37286329}],"con":true,"img":false}]}
{"op":"mcm","clk":"5348504472","pt":1646218266468,"mc":[{"id":"1.195453676","rc":[{"atl":[[2.28,8.09]],"id":37286329}],"con":true,"img":false}]}
{"op":"mcm","clk":"5348504497","pt":1646218266709,"mc":[{"id":"1.195453676","rc":[{"atl":[[1.87,0]],"id":41788482},{"trd":[[1.87,105.26]],"ltp":1.87,"tv":105.26,"id":41788482}],"con":true,"img":false}]}
{"op":"mcm","clk":"5348504523","pt":1646218266887,"mc":[{"id":"1.195453676","rc":[{"atl":[[2.02,14.32]],"id":41788482}],"con":true,"img":false}]}
{"op":"mcm","clk":"5348504565","pt":1646218267096,"mc":[{"id":"1.195453676","rc":[{"atl":[[2.04,20.96]],"id":41788482}],"con":true,"img":false}]}
{"op":"mcm","clk":"5348504627","pt":1646218267563,"mc":[{"id":"1.195453676","rc":[{"atl":[[2.04,9.39]],"id":41788482}],"con":true,"img":false}]}
{"op":"mcm","clk":"5348504637","pt":1646218267667,"mc":[{"id":"1.195453676","rc":[{"atl":[[2.02,25.89]],"id":41788482}],"con":true,"img":false}]}
{"op":"mcm","clk":"5348504942","pt":1646218270377,"mc":[{"id":"1.195453676","rc":[{"atl":[[9,108],[2.54,4],[2.5,16.45],[5.8,4],[4.9,77],[2.58,4],[2.84,39],[2.62,28],[2.94,4],[3.75,4],[2.76,4],[7.2,4],[3.4,55],[3.15,4],[4.2,4],[2.7,4]],"id":37286329}],"con":true,"img":false}]}
{"op":"mcm","clk":"5348505037","pt":1646218271315,"mc":[{"id":"1.195453676","rc":[{"atl":[[2.02,14.32]],"id":41788482},{"atl":[[2.2,8.37],[2.16,16.76]],"id":37286329}],"con":true,"img":false}]}
{"op":"mcm","clk":"5348505049","pt":1646218271376,"mc":[{"id":"1.195453676","rc":[{"atb":[[1.81,21.44]],"id":41788482}],"con":true,"img":false}]}
{"op":"mcm","clk":"5348505061","pt":1646218271482,"mc":[{"id":"1.195453676","rc":[{"atb":[[2.14,0]],"id":37286329},{"trd":[[2.14,51.53]],"ltp":2.14,"tv":51.53,"id":37286329}],"con":true,"img":false}]}
{"op":"mcm","clk":"5348505089","pt":1646218271693,"mc":[{"id":"1.195453676","rc":[{"atb":[[1.83,35.15],[1.63,10.45],[1.86,10.04]],"id":41788482},{"atb":[[2.1,20.96]],"id":37286329}],"con":true,"img":false}]}
{"op":"mcm","clk":"5348505118","pt":1646218271902,"mc":[{"id":"1.195453676","rc":[{"atb":[[1.85,10.13],[1.86,31.17]],"id":41788482}],"con":true,"img":false}]}
{"op":"mcm","clk":"5348505195","pt":1646218272480,"mc":[{"id":"1.195453676","rc":[{"atl":[[2.02,23.72]],"id":41788482}],"con":true,"img":false}]}
{"op":"mcm","clk":"5348505232","pt":1646218272797,"mc":[{"id":"1.195453676","rc":[{"atl":[[1.87,4.08]],"id":41788482}],"con":true,"img":false}]}
{"op":"mcm","clk":"5348505255","pt":1646218273005,"mc":[{"id":"1.195453676","rc":[{"atl":[[1.87,0]],"id":41788482},{"trd":[[1.87,113.43]],"ltp":1.87,"tv":113.43,"id":41788482}],"con":true,"img":false}]}
{"op":"mcm","clk":"5348505281","pt":1646218273165,"mc":[{"id":"1.195453676","rc":[{"atb":[[1.78,37.4]],"id":41788482}],"con":true,"img":false}]}
{"op":"mcm","clk":"5348505293","pt":1646218273273,"mc":[{"id":"1.195453676","rc":[{"atb":[[2.1,10.48]],"id":37286329}],"con":true,"img":false}]}
{"op":"mcm","clk":"5348505332","pt":1646218273690,"mc":[{"id":"1.195453676","rc":[{"atb":[[1.83,0],[1.81,57.46]],"id":41788482},{"atb":[[2.02,37.37],[2.06,5.09]],"id":37286329}],"con":true,"img":false}]}
{"op":"mcm","clk":"5348505351","pt":1646218273898,"mc":[{"id":"1.195453676","rc":[{"atb":[[2.1,0]],"id":37286329}],"con":true,"img":false}]}
{"op":"mcm","clk":"5348505373","pt":1646218274208,"mc":[{"id":"1.195453676","rc":[{"atb":[[2.02,8.76]],"id":37286329}],"con":true,"img":false}]}
{"op":"mcm","clk":"5348505425","pt":1646218274676,"mc":[{"id":"1.195453676","rc":[{"atb":[[1.99,29.46]],"id":37286329}],"con":true,"img":false}]}
{"op":"mcm","clk":"5348505446","pt":1646218274884,"mc":[{"id":"1.195453676","rc":[{"atb":[[2.12,0]],"id":37286329},{"trd":[[2.12,16.74]],"ltp":2.12,"tv":16.74,"id":37286329}],"con":true,"img":false}]}
{"op":"mcm","clk":"5348505479","pt":1646218275197,"mc":[{"id":"1.195453676","rc":[{"atb":[[1.78,0]],"id":41788482}],"con":true,"img":false}]}
{"op":"mcm","clk":"5348505659","pt":1646218276815,"mc":[{"id":"1.195453676","rc":[{"atb":[[1.99,40.52]],"id":37286329}],"con":true,"img":false}]}
{"op":"mcm","clk":"5348505683","pt":1646218276973,"mc":[{"id":"1.195453676","rc":[{"atb":[[1.03,2.87]],"id":41788482}],"con":true,"img":false}]}
{"op":"mcm","clk":"5348505705","pt":1646218277180,"mc":[{"id":"1.195453676","rc":[{"atb":[[1.03,0.14],[1.87,33.53]],"id":41788482}],"con":true,"img":false}]}
{"op":"mcm","clk":"5348505738","pt":1646218277389,"mc":[{"id":"1.195453676","rc":[{"atb":[[1.03,0]],"id":41788482}],"con":true,"img":false}]}
{"op":"mcm","clk":"5348505749","pt":1646218277493,"mc":[{"id":"1.195453676","rc":[{"trd":[[1.95,38.54]],"ltp":1.95,"tv":38.54,"id":41788482},{"atb":[[2.06,4.94]],"id":37286329},{"trd":[[2.06,65.52]],"ltp":2.06,"tv":65.52,"id":37286329}],"con":true,"img":false}]}
{"op":"mcm","clk":"5348505806","pt":1646218278021,"mc":[{"id":"1.195453676","rc":[{"atb":[[1.03,2.87]],"id":37286329}],"con":true,"img":false}]}
{"op":"mcm","clk":"5348505828","pt":1646218278225,"mc":[{"id":"1.195453676","rc":[{"atb":[[1.03,0.14]],"id":37286329}],"con":true,"img":false}]}
{"op":"mcm","clk":"5348505841","pt":1646218278280,"mc":[{"id":"1.195453676","rc":[{"atb":[[1.84,29.38]],"id":41788482},{"atb":[[2,11]],"id":37286329}],"con":true,"img":false}]}
{"op":"mcm","clk":"5348505849","pt":1646218278385,"mc":[{"id":"1.195453676","rc":[{"atb":[[1.03,0]],"id":37286329}],"con":true,"img":false}]}
{"op":"mcm","clk":"5348505859","pt":1646218278489,"mc":[{"id":"1.195453676","rc":[{"atl":[[2.16,16.61]],"id":37286329},{"trd":[[2.16,34.76]],"ltp":2.16,"tv":34.76,"id":37286329}],"con":true,"img":false}]}
{"op":"mcm","clk":"5348505881","pt":1646218278698,"mc":[{"id":"1.195453676","rc":[{"atb":[[1.8,36.47]],"id":41788482},{"atl":[[2.14,8.56]],"id":37286329}],"con":true,"img":false}]}
{"op":"mcm","clk":"5348505894","pt":1646218278806,"mc":[{"id":"1.195453676","rc":[{"atb":[[1.88,9.83]],"id":41788482},{"atl":[[2.24,0]],"id":37286329}],"con":true,"img":false}]}
{"op":"mcm","clk":"5348505986","pt":1646218279697,"mc":[{"id":"1.195453676","rc":[{"atl":[[2.02,14.32]],"id":41788482}],"con":true,"img":false}]}
{"op":"mcm","clk":"5348506041","pt":1646218280116,"mc":[{"id":"1.195453676","rc":[{"atb":[[1.51,0]],"id":41788482}],"con":true,"img":false}]}
{"op":"mcm","clk":"5348506054","pt":1646218280220,"mc":[{"id":"1.195453676","rc":[{"atb":[[1.54,8.81]],"id":41788482}],"con":true,"img":false}]}
{"op":"mcm","clk":"5348506064","pt":1646218280325,"mc":[{"id":"1.195453676","rc":[{"atl":[[2.02,23.08]],"id":41788482}],"con":true,"img":false}]}
{"op":"mcm","clk":"5348506212","pt":1646218281584,"mc":[{"id":"1.195453676","rc":[{"atb":[[1.84,10.87]],"id":41788482}],"con":true,"img":false}]}
{"op":"mcm","clk":"5348506223","pt":1646218281688,"mc":[{"id":"1.195453676","rc":[{"atb":[[1.9,18.51]],"id":41788482}],"con":true,"img":false}]}
{"op":"mcm","clk":"5348506325","pt":1646218282425,"mc":[{"id":"1.195453676","rc":[{"atb":[[2.06,11.11]],"id":37286329}],"con":true,"img":false}]}
{"op":"mcm","clk":"5348506335","pt":1646218282530,"mc":[{"id":"1.195453676","rc":[{"atb":[[1.87,63.05],[1.86,10.04]],"id":41788482}],"con":true,"img":false}]}
{"op":"mcm","clk":"5348506392","pt":1646218282900,"mc":[{"id":"1.195453676","rc":[{"atb":[[2.06,4.94]],"id":37286329}],"con":true,"img":false}]}
{"op":"mcm","clk":"5348506467","pt":1646218283421,"mc":[{"id":"1.195453676","rc":[{"atb":[[2.06,11.11]],"id":37286329}],"con":true,"img":false}]}
{"op":"mcm","clk":"5348506581","pt":1646218284206,"mc":[{"id":"1.195453676","rc":[{"atb":[[2.06,4.94]],"id":37286329}],"con":true,"img":false}]}
{"op":"mcm","clk":"5348506602","pt":1646218284414,"mc":[{"id":"1.195453676","rc":[{"atb":[[2,0],[2.02,0],[2.06,0]],"id":37286329},{"atl":[[2,144.78]],"id":37286329},{"trd":[[2,39.08],[2.02,20.37],[2.06,75.42]],"ltp":2.0,"tv":134.87,"id":37286329}],"con":true,"img":false}]}
{"op":"mcm","clk":"5348506626","pt":1646218284618,"mc":[{"id":"1.195453676","rc":[{"atb":[[1.81,47.07],[1.91,9.55]],"id":41788482},{"trd":[[2,2.48]],"ltp":2.0,"tv":2.48,"id":41788482},{"atl":[[2,131.99],[2.14,25.51],[2.16,0]],"id":37286329},{"trd":[[2,62.19]],"ltp":2.0,"tv":62.19,"id":37286329}],"con":true,"img":false}]}
{"op":"mcm","clk":"5348506635","pt":1646218284723,"mc":[{"id":"1.195453676","rc":[{"atb":[[1.96,30.39],[1.81,11.05],[1.8,0]],"id":41788482},{"atb":[[1.94,38.17],[1.99,11.06]],"id":37286329}],"con":true,"img":false}]}
{"op":"mcm","clk":"5348506645","pt":1646218284827,"mc":[{"id":"1.195453676","rc":[{"atb":[[1.99,29.14]],"id":37286329}],"con":true,"img":false}]}
{"op":"mcm","clk":"5348506657","pt":1646218284935,"mc":[{"id":"1.195453676","rc":[{"atl":[[2.22,0],[2.12,17.64]],"id":37286329}],"con":true,"img":false}]}
{"op":"mcm","clk":"5348506668","pt":1646218284982,"mc":[{"id":"1.195453676","rc":[{"atl":[[2.42,0]],"id":37286329}],"con":true,"img":false}]}
{"op":"mcm","clk":"5348506804","pt":1646218286036,"mc":[{"id":"1.195453676","rc":[{"atb":[[1.99,18.08]],"id":37286329}],"con":true,"img":false}]}
{"op":"mcm","clk":"5348506814","pt":1646218286140,"mc":[{"id":"1.195453676","rc":[{"atb":[[1.81,13.05],[1.87,33.53]],"id":41788482},{"atl":[[2.26,0],[2.18,2]],"id":41788482},{"trd":[[2,26.74]],"ltp":2.0,"tv":26.74,"id":41788482},{"atb":[[1.76,0],[1.82,46.79],[1.99,16.68]],"id":37286329},{"atl":[[2,100.43],[2.14,8.56],[2.22,46.79]],"id":37286329},{"trd":[[2,101.07]],"ltp":2.0,"tv":101.07,"id":37286329}],"con":true,"img":false}]}
{"op":"mcm","clk":"5348506826","pt":1646218286247,"mc":[{"id":"1.195453676","rc":[{"atb":[[1.85,0],[1.97,9.21]],"id":41788482},{"atl":[[2.04,0]],"id":41788482},{"atb":[[1.96,0]],"id":37286329}],"con":true,"img":false}]}
{"op":"mcm","clk":"5348506837","pt":1646218286300,"mc":[{"id":"1.195453676","rc":[{"atb":[[1.99,9.32]],"id":37286329}],"con":true,"img":false}]}
{"op":"mcm","clk":"5348506864","pt":1646218286513,"mc":[{"id":"1.195453676","rc":[{"atb":[[1.99,16.68]],"id":37286329}],"con":true,"img":false}]}
{"op":"mcm","clk":"5348506878","pt":1646218286620,"mc":[{"id":"1.195453676","rc":[{"atb":[[1.9,0]],"id":41788482}],"con":true,"img":false}]}
{"op":"mcm","clk":"5348506892","pt":1646218286722,"mc":[{"id":"1.195453676","rc":[{"atb":[[1.92,18.51]],"id":41788482}],"con":true,"img":false}]}
{"op":"mcm","clk":"5348506944","pt":1646218287142,"mc":[{"id":"1.195453676","rc":[{"atl":[[2.02,8.76]],"id":41788482},{"trd":[[2,35.95]],"ltp":2.0,"tv":35.95,"id":41788482},{"atb":[[1.99,13]],"id":37286329},{"atl":[[2,87.56]],"id":37286329},{"trd":[[2,117.6]],"ltp":2.0,"tv":117.6,"id":37286329}],"con":true,"img":false}]}
{"op":"mcm","clk":"5348506967","pt":1646218287303,"mc":[{"id":"1.195453676","rc":[{"trd":[[2,49.81]],"ltp":2.0,"tv":49.81,"id":41788482},{"atl":[[2,73.71]],"id":37286329},{"trd":[[2,131.45]],"ltp":2.0,"tv":131.45,"id":37286329}],"con":true,"img":false}]}
{"op":"mcm","clk":"5348506995","pt":1646218287514,"mc":[{"id":"1.195453676","rc":[{"atl":[[2.02,0]],"id":41788482}],"con":true,"img":false}]}
{"op":"mcm","clk":"5348507010","pt":1646218287618,"mc":[{"id":"1.195453676","rc":[{"atl":[[2.18,10.76]],"id":41788482},{"atb":[[1.99,0]],"id":37286329},{"trd":[[1.99,26.01]],"ltp":1.99,"tv":26.01,"id":37286329}],"con":true,"img":false}]}
{"op":"mcm","clk":"5348507026","pt":1646218287725,"mc":[{"id":"1.195453676","rc":[{"atb":[[1.96,0],[1.95,30.71]],"id":41788482},{"atb":[[1.94,7.13],[1.91,32.06]],"id":37286329}],"con":true,"img":false}]}
{"op":"mcm","clk":"5348507076","pt":1646218288092,"mc":[{"id":"1.195453676","rc":[{"atl":[[2.18,6]],"id":41788482}],"con":true,"img":false}]}
{"op":"mcm","clk":"5348507089","pt":1646218288194,"mc":[{"id":"1.195453676","rc":[{"atb":[[1.87,0]],"id":41788482},{"atb":[[1.91,0]],"id":37286329}],"con":true,"img":false}]}
{"op":"mcm","clk":"5348507127","pt":1646218288505,"mc":[{"id":"1.195453676","rc":[{"atb":[[1.81,2]],"id":41788482},{"atb":[[1.9,10.53]],"id":37286329}],"con":true,"img":false}]}
{"op":"mcm","clk":"5348507137","pt":1646218288608,"mc":[{"id":"1.195453676","rc":[{"atb":[[1.54,0]],"id":41788482},{"atb":[[1.94,0]],"id":37286329}],"con":true,"img":false}]}
{"op":"mcm","clk":"5348507151","pt":1646218288744,"mc":[{"id":"1.195453676","rc":[{"atb":[[1.57,8.81]],"id":41788482},{"atb":[[1.83,41.65],[1.9,17.66]],"id":37286329}],"con":true,"img":false}]}
{"op":"mcm","clk":"5348507161","pt":1646218288817,"mc":[{"id":"1.195453676","rc":[{"atb":[[1.84,0],[1.92,0]],"id":41788482},{"atl":[[1.96,169.49]],"id":37286329}],"con":true,"img":false}]}
{"op":"mcm","clk":"5348507186","pt":1646218289024,"mc":[{"id":"1.195453676","rc":[{"atb":[[1.93,17.06]],"id":37286329}],"con":true,"img":false}]}
{"op":"mcm","clk":"5348507275","pt":1646218289697,"mc":[{"id":"1.195453676","rc":[{"atb":[[2.02,28.6]],"id":41788482},{"atb":[[1.88,33.15]],"id":37286329}],"con":true,"img":false}]}
{"op":"mcm","clk":"5348507282","pt":1646218289802,"mc":[{"id":"1.195453676","rc":[{"atl":[[1.99,9.25]],"id":37286329}],"con":true,"img":false}]}
{"op":"mcm","clk":"5348507308","pt":1646218290010,"mc":[{"id":"1.195453676","rc":[{"atl":[[2.2,0]],"id":37286329}],"con":true,"img":false}]}
{"op":"mcm","clk":"5348507369","pt":1646218290640,"mc":[{"id":"1.195453676","marketDefinition":{"bspMarket":false,"turnInPlayEnabled":false,"persistenceEnabled":false,"marketBaseRate":7.0,"eventId":"31272494","eventTypeId":"4339","numberOfWinners":1,"bettingType":"ODDS","marketType":"MATCH_BET","marketTime":"2022-03-02T10:51:00.000Z","suspendTime":"2022-03-02T10:51:00.000Z","bspReconciled":false,"complete":true,"inPlay":false,"crossMatching":true,"runnersVoidable":false,"numberOfActiveRunners":2,"betDelay":0,"status":"SUSPENDED","runners":[{"status":"ACTIVE","sortPriority":1,"id":41788482,"name":"3. Flossie Ann"},{"status":"ACTIVE","sortPriority":2,"id":37286329,"name":"6. Dr Danika"}],"regulators":["MR_INT"],"venue":"Traralgon","countryCode":"AU","discountAllowed":true,"timezone":"Australia/Sydney","openDate":"2022-03-02T08:31:00.000Z","version":4382966519,"name":"Flossie Ann v Dr Danika","eventName":"Traralgon (AUS) 2nd Mar"},"rc":[],"con":true,"img":false}]}
{"op":"mcm","clk":"5348507369","pt":1646218290640,"mc":[{"id":"1.195453676","rc":[{"atb":[[1.28,0],[1.37,0],[1.26,0],[1.95,0],[1.39,0],[1.34,0],[1.35,0],[1.4,0],[1.82,0],[1.36,0],[2.02,0],[1.63,0],[1.81,0],[1.97,0],[1.57,0],[1.88,0],[1.91,0],[1.86,0],[1.32,0],[1.49,0],[1.29,0],[1.31,0],[1.38,0]],"id":41788482},{"atl":[[2.56,0],[2.72,0],[2.54,0],[2.5,0],[2.74,0],[2.18,0],[2.6,0],[2.66,0],[2.58,0],[2.62,0],[2.78,0],[2.68,0]],"id":41788482},{"atb":[[1.64,0],[1.83,0],[1.6,0],[1.01,0],[1.37,0],[1.7,0],[1.68,0],[1.23,0],[1.93,0],[1.53,0],[1.48,0],[1.82,0],[1.16,0],[1.57,0],[1.11,0],[1.88,0],[1.9,0],[1.06,0],[1.3,0],[1.42,0],[1.66,0]],"id":37286329},{"atl":[[2,0],[2.5,0],[1.96,0],[4.9,0],[2.58,0],[2.14,0],[2.94,0],[3.75,0],[7.2,0],[1.99,0],[2.28,0],[2.18,0],[4.2,0],[2.7,0],[9,0],[2.54,0],[5.8,0],[2.22,0],[2.12,0],[2.84,0],[2.62,0],[2.34,0],[2.76,0],[2.36,0],[3.4,0],[3.15,0]],"id":37286329}],"con":true,"img":false}]}
{"op":"mcm","clk":"5348520225","pt":1646218407669,"mc":[{"id":"1.195453676","rc":[{"trd":[[2,0],[1.83,0],[1.84,0],[1.85,0],[1.96,0],[1.94,0],[1.87,0],[1.93,0],[1.95,0],[1.8,0],[1.82,0],[1.92,0],[2.02,0],[1.81,0],[1.91,0],[1.86,0]],"ltp":2.0,"tv":0.0,"id":41788482},{"trd":[[2,0],[1.98,0],[2.3,0],[2.32,0],[2.5,0],[2.22,0],[2.04,0],[2.12,0],[1.94,0],[2.26,0],[2.1,0],[2.14,0],[2.08,0],[2.24,0],[1.99,0],[2.02,0],[2.06,0],[2.38,0],[2.18,0],[2.2,0],[2.16,0]],"ltp":2.0,"tv":0.0,"id":37286329}],"con":true,"img":false}]}
{"op":"mcm","clk":"5348520377","pt":1646218409263,"mc":[{"id":"1.195453676","marketDefinition":{"bspMarket":false,"turnInPlayEnabled":false,"persistenceEnabled":false,"marketBaseRate":7.0,"eventId":"31272494","eventTypeId":"4339","numberOfWinners":1,"bettingType":"ODDS","marketType":"MATCH_BET","marketTime":"2022-03-02T10:51:00.000Z","suspendTime":"2022-03-02T10:51:00.000Z","bspReconciled":false,"complete":true,"inPlay":false,"crossMatching":false,"runnersVoidable":false,"numberOfActiveRunners":0,"betDelay":0,"status":"CLOSED","settledTime":"2022-03-02T10:53:26.000Z","runners":[{"status":"LOSER","sortPriority":1,"id":41788482,"name":"3. Flossie Ann"},{"status":"WINNER","sortPriority":2,"id":37286329,"name":"6. Dr Danika"}],"regulators":["MR_INT"],"venue":"Traralgon","countryCode":"AU","discountAllowed":true,"timezone":"Australia/Sydney","openDate":"2022-03-02T08:31:00.000Z","version":4382966793,"name":"Flossie Ann v Dr Danika","eventName":"Traralgon (AUS) 2nd Mar"},"rc":[],"con":true,"img":false}]}
