{"op":"mcm","clk":"5351767861","pt":1646175389025,"mc":[{"id":"1.195453782","marketDefinition":{"bspMarket":true,"turnInPlayEnabled":false,"persistenceEnabled":false,"marketBaseRate":7.0,"eventId":"31272499","eventTypeId":"4339","numberOfWinners":1,"bettingType":"ODDS","marketType":"WIN","marketTime":"2022-03-02T11:55:00.000Z","suspendTime":"2022-03-02T11:55:00.000Z","bspReconciled":false,"complete":true,"inPlay":false,"crossMatching":false,"runnersVoidable":false,"numberOfActiveRunners":7,"betDelay":0,"status":"OPEN","runners":[{"status":"ACTIVE","sortPriority":1,"id":42146659,"name":"2. Pacific Bug"},{"status":"ACTIVE","sortPriority":2,"id":39307895,"name":"3. Calla Ebony"},{"status":"ACTIVE","sortPriority":3,"id":39594698,"name":"4. Star Connie"},{"status":"ACTIVE","sortPriority":4,"id":43167137,"name":"5. What An Outcome"},{"status":"ACTIVE","sortPriority":5,"id":40879966,"name":"6. Burner Express"},{"status":"ACTIVE","sortPriority":6,"id":41419892,"name":"7. Perfect Mate"},{"status":"ACTIVE","sortPriority":7,"id":41738000,"name":"10. Modern Doll"}],"regulators":["MR_INT"],"venue":"Rockhampton","countryCode":"AU","discountAllowed":true,"timezone":"Australia/Queensland","openDate":"2022-03-02T08:34:00.000Z","version":4382437871,"name":"R11 407m Gr5","eventName":"Rockhampton (AUS) 2nd Mar"},"rc":[],"con":true,"img":false}]}
{"op":"mcm","clk":"5351835883","pt":1646176787551,"mc":[{"id":"1.195453782","rc":[{"atb":[[3.8,36.69],[3.55,40.29],[3.3,44.67],[3.05,50.11]],"id":43167137},{"atl":[[17,12.47],[12,12.09],[9.8,15.11],[14.5,14.78]],"id":43167137},{"spn":6.8,"spf":"NaN","id":43167137},{"atb":[[4,34.25],[4.5,29.35],[5,25.68],[5.5,22.83]],"id":41419892},{"atl":[[17,8.31],[19.5,7.19],[24,8.67],[29,7.12]],"id":41419892},{"spn":11.25,"spf":"NaN","id":41419892},{"atb":[[12,9.34],[9.8,11.67],[8.8,13.17],[7.8,15.11]],"id":40879966},{"atl":[[70,1.92],[140,1.43],[95,1.41],[190,1.05]],"id":40879966},{"spn":41.0,"spf":"NaN","id":40879966},{"atb":[[18,6.04],[21,5.13],[13,8.56],[15.5,7.08]],"id":39307895},{"atl":[[150,0.89],[300,0.66],[200,0.66],[250,0.8]],"id":39307895},{"spn":85.5,"spf":"NaN","id":39307895},{"atb":[[3.8,36.69],[3.55,40.29],[3.3,44.67],[3.05,50.11]],"id":41738000},{"atl":[[17,12.47],[12,12.09],[9.8,15.11],[14.5,14.78]],"id":41738000},{"spn":6.8,"spf":"NaN","id":41738000},{"atb":[[2.9,54.07],[3,51.37],[3.25,45.66],[3.5,41.09]],"id":42146659},{"atl":[[11,19.95],[13.5,15.96],[8.4,17.98],[9.4,15.84]],"id":42146659},{"spn":5.95,"spf":"NaN","id":42146659},{"atb":[[2.82,56.45],[2.92,53.51],[3.3,44.67],[3.05,50.11]],"id":39594698},{"atl":[[9.2,16.22],[10.5,21],[8.2,18.47],[13,16.63]],"id":39594698},{"spn":5.75,"spf":"NaN","id":39594698}],"con":true,"img":false}]}
{"op":"mcm","clk":"5351933508","pt":1646178772138,"mc":[{"id":"1.195453782","rc":[{"atb":[[3.8,0],[3.55,0],[3.3,0],[3.05,0]],"id":43167137},{"atl":[[17,0],[12,0],[9.8,0],[14.5,0]],"id":43167137},{"spn":"NaN","spf":"NaN","id":43167137},{"atb":[[4,0],[4.5,0],[5,0],[5.5,0]],"id":41419892},{"atl":[[17,0],[19.5,0],[24,0],[29,0]],"id":41419892},{"spn":"NaN","spf":"NaN","id":41419892},{"atb":[[12,0],[9.8,0],[8.8,0],[7.8,0]],"id":40879966},{"atl":[[70,0],[140,0],[95,0],[190,0]],"id":40879966},{"spn":"NaN","spf":"NaN","id":40879966},{"atb":[[18,0],[21,0],[13,0],[15.5,0]],"id":39307895},{"atl":[[150,0],[300,0],[200,0],[250,0]],"id":39307895},{"spn":"NaN","spf":"NaN","id":39307895},{"atb":[[3.8,0],[3.55,0],[3.3,0],[3.05,0]],"id":41738000},{"atl":[[17,0],[12,0],[9.8,0],[14.5,0]],"id":41738000},{"spn":"NaN","spf":"NaN","id":41738000},{"atb":[[2.9,0],[3,0],[3.25,0],[3.5,0]],"id":42146659},{"atl":[[11,0],[13.5,0],[8.4,0],[9.4,0]],"id":42146659},{"spn":"NaN","spf":"NaN","id":42146659},{"atb":[[2.82,0],[2.92,0],[3.3,0],[3.05,0]],"id":39594698},{"atl":[[9.2,0],[10.5,0],[8.2,0],[13,0]],"id":39594698},{"spn":"NaN","spf":"NaN","id":39594698}],"con":true,"img":false}]}
{"op":"mcm","clk":"5351934016","pt":1646178780637,"mc":[{"id":"1.195453782","rc":[{"atb":[[4,34.25],[4.5,29.35],[3.5,41.09],[3.75,37.36]],"id":43167137},{"atl":[[16.5,8.58],[19,11.08],[23,9.06],[14,10.23]],"id":43167137},{"atb":[[4.8,27.03],[5.8,21.4],[5.3,23.89],[6.6,18.35]],"id":41419892},{"atl":[[36,5.69],[19,7.39],[23,6.04],[28,7.39]],"id":41419892},{"atb":[[9.6,11.94],[8.6,13.52],[11.5,9.78],[14,7.9]],"id":40879966},{"atl":[[130,1.02],[90,1.49],[180,1.11],[230,0.87]],"id":40879966},{"atb":[[32,3.31],[18,6.04],[21,5.13],[26,4.1]],"id":39307895},{"atl":[[290,0.46],[340,0.58],[390,0.51],[240,0.55]],"id":39307895},{"atb":[[2.82,56.45],[2.92,53.51],[3.3,44.67],[3.05,50.11]],"id":41738000},{"atl":[[9.2,16.22],[10.5,21],[8.2,18.47],[13,16.63]],"id":41738000},{"atb":[[2.9,54.07],[3,51.37],[3.25,45.66],[3.5,41.09]],"id":42146659},{"atl":[[11,19.95],[13.5,15.96],[8.4,17.98],[9.4,15.84]],"id":42146659},{"atb":[[3.45,41.93],[3.2,46.7],[3.7,38.05],[2.98,51.89]],"id":39594698},{"atl":[[16,13.3],[11,13.3],[13.5,15.96],[9.4,15.84]],"id":39594698}],"con":true,"img":false}]}
{"op":"mcm","clk":"5351936806","pt":1646178834320,"mc":[{"id":"1.195453782","rc":[{"atb":[[4,0],[4.5,0],[3.5,0],[3.75,0]],"id":43167137},{"atl":[[16.5,0],[19,0],[23,0],[14,0]],"id":43167137},{"spn":12.8,"spf":"NaN","id":41419892},{"atb":[[9.6,0],[8.6,0],[11.5,0],[14,0]],"id":40879966},{"atl":[[130,0],[90,0],[180,0],[230,0]],"id":40879966},{"atb":[[32,0],[18,0],[21,0],[26,0]],"id":39307895},{"atl":[[290,0],[340,0],[390,0],[240,0]],"id":39307895},{"atb":[[2.82,0],[2.92,0],[3.3,0],[3.05,0]],"id":41738000},{"atl":[[9.2,0],[10.5,0],[8.2,0],[13,0]],"id":41738000},{"spn":5.95,"spf":"NaN","id":42146659},{"atb":[[3.45,0],[3.2,0],[3.7,0],[2.98,0]],"id":39594698},{"atl":[[16,0],[11,0],[13.5,0],[9.4,0]],"id":39594698}],"con":true,"img":false}]}
{"op":"mcm","clk":"5351937760","pt":1646178853454,"mc":[{"id":"1.195453782","rc":[{"atb":[[4.6,28.54],[4.1,33.14],[3.8,36.69],[3.55,40.29]],"id":43167137},{"atl":[[17,8.31],[19.5,10.78],[24,8.67],[14.5,9.85]],"id":43167137},{"atb":[[9,12.84],[10,11.41],[12.5,8.93],[15,7.33]],"id":40879966},{"atl":[[150,0.89],[100,1.34],[200,1],[250,0.8]],"id":40879966},{"atb":[[34,3.11],[18.5,5.87],[22,4.89],[27,3.95]],"id":39307895},{"atl":[[300,0.44],[350,0.57],[400,0.5],[250,0.53]],"id":39307895},{"atb":[[2.86,55.24],[3.4,42.81],[3.15,47.78],[2.96,52.42]],"id":41738000},{"atl":[[11,19.95],[13.5,15.96],[8.4,17.98],[9.4,15.84]],"id":41738000},{"atb":[[3.45,41.93],[3.2,46.7],[3.7,38.05],[2.98,51.89]],"id":39594698},{"atl":[[16,13.3],[11,13.3],[13.5,15.96],[9.4,15.84]],"id":39594698}],"con":true,"img":false}]}
{"op":"mcm","clk":"5351939703","pt":1646178893173,"mc":[{"id":"1.195453782","rc":[{"atb":[[9,0],[10,0],[12.5,0],[15,0]],"id":40879966},{"atl":[[150,0],[100,0],[200,0],[250,0]],"id":40879966},{"atb":[[34,0],[18.5,0],[22,0],[27,0]],"id":39307895},{"atl":[[300,0],[350,0],[400,0],[250,0]],"id":39307895},{"atb":[[2.86,0],[3.4,0],[3.15,0],[2.96,0]],"id":41738000},{"atl":[[11,0],[13.5,0],[8.4,0],[9.4,0]],"id":41738000},{"atb":[[2.9,0],[3,0],[3.25,0],[3.5,0]],"id":42146659},{"atl":[[11,0],[13.5,0],[8.4,0],[9.4,0]],"id":42146659},{"atb":[[3.45,0],[3.2,0],[3.7,0],[2.98,0]],"id":39594698},{"atl":[[16,0],[11,0],[13.5,0],[9.4,0]],"id":39594698}],"con":true,"img":false}]}
{"op":"mcm","clk":"5351940136","pt":1646178901209,"mc":[{"id":"1.195453782","rc":[{"spn":9.55,"spf":"NaN","id":43167137},{"atb":[[9.6,11.94],[8.6,13.52],[7.6,15.56],[6.6,18.35]],"id":40879966},{"atl":[[65,2.07],[130,1.54],[90,2.24],[46,2.95]],"id":40879966},{"spn":27.8,"spf":"NaN","id":40879966},{"atb":[[34,3.11],[18.5,5.87],[22,4.89],[27,3.95]],"id":39307895},{"atl":[[300,0.44],[350,0.57],[400,0.5],[250,0.53]],"id":39307895},{"spn":142.0,"spf":"NaN","id":39307895},{"atb":[[2.82,56.45],[2.92,53.51],[3.3,44.67],[3.05,50.11]],"id":41738000},{"atl":[[9.2,16.22],[10.5,21],[8.2,18.47],[13,16.63]],"id":41738000},{"spn":5.75,"spf":"NaN","id":41738000},{"atb":[[3.4,42.81],[3.15,47.78],[3.9,35.43],[3.65,38.77]],"id":42146659},{"atl":[[18,11.73],[10.5,14],[13,11.08],[15.5,13.76]],"id":42146659},{"spn":7.2,"spf":"NaN","id":42146659},{"atb":[[3.45,41.93],[3.2,46.7],[3.7,38.05],[2.98,51.89]],"id":39594698},{"atl":[[16,13.3],[11,13.3],[13.5,15.96],[9.4,15.84]],"id":39594698},{"spn":6.55,"spf":"NaN","id":39594698}],"con":true,"img":false}]}
{"op":"mcm","clk":"5351964478","pt":1646179432323,"mc":[{"id":"1.195453782","rc":[{"atb":[[4.6,0],[4.1,0],[3.8,0],[3.55,0]],"id":43167137},{"atl":[[17,0],[19.5,0],[24,0],[14.5,0]],"id":43167137},{"spn":"NaN","spf":"NaN","id":43167137},{"atb":[[4.8,0],[5.8,0],[5.3,0],[6.6,0]],"id":41419892},{"atl":[[36,0],[19,0],[23,0],[28,0]],"id":41419892},{"spn":"NaN","spf":"NaN","id":41419892},{"atb":[[9.6,11.95],[8.6,13.52],[7.6,15.57],[6.6,18.35]],"id":40879966},{"atl":[[65,2.07],[130,1.54],[90,2.24],[46,2.95]],"id":40879966},{"atb":[[34,3.11],[18.5,5.87],[22,4.89],[27,3.95]],"id":39307895},{"atb":[[2.82,0],[2.92,0],[3.3,0],[3.05,0]],"id":41738000},{"atl":[[9.2,0],[10.5,0],[8.2,0],[13,0]],"id":41738000},{"spn":"NaN","spf":"NaN","id":41738000},{"atb":[[3.4,0],[3.15,0],[3.9,0],[3.65,0]],"id":42146659},{"atl":[[18,0],[10.5,0],[13,0],[15.5,0]],"id":42146659},{"spn":"NaN","spf":"NaN","id":42146659},{"atb":[[3.45,41.94],[3.2,46.71],[3.7,38.06],[2.98,51.9]],"id":39594698},{"atl":[[16,13.3],[11,13.3],[13.5,15.96],[9.4,15.84]],"id":39594698}],"con":true,"img":false}]}
{"op":"mcm","clk":"5351964789","pt":1646179441071,"mc":[{"id":"1.195453782","rc":[{"atb":[[4,34.25],[4.5,29.36],[5,25.69],[3.75,37.36]],"id":43167137},{"atl":[[16,8.86],[18.5,7.6],[22,9.5],[27,7.67]],"id":43167137},{"atb":[[5,25.69],[5.5,22.83],[6,20.55],[7,17.12]],"id":41419892},{"atl":[[19.5,7.19],[38,5.39],[24,5.78],[29,7.12]],"id":41419892},{"atb":[[3.2,46.71],[2.88,54.66],[2.98,51.9],[2.78,57.73]],"id":41738000},{"atl":[[9.2,16.22],[10.5,21],[8.2,18.47],[13,16.63]],"id":41738000},{"atb":[[3.8,36.69],[3.55,40.29],[3.3,44.68],[3.05,50.12]],"id":42146659},{"atl":[[17,12.47],[12,12.09],[9.8,15.11],[14.5,14.78]],"id":42146659}],"con":true,"img":false}]}
{"op":"mcm","clk":"5352003899","pt":1646180202629,"mc":[{"id":"1.195453782","marketDefinition":{"bspMarket":true,"turnInPlayEnabled":false,"persistenceEnabled":false,"marketBaseRate":7.0,"eventId":"31272499","eventTypeId":"4339","numberOfWinners":1,"bettingType":"ODDS","marketType":"WIN","marketTime":"2022-03-02T11:55:00.000Z","suspendTime":"2022-03-02T11:55:00.000Z","bspReconciled":false,"complete":true,"inPlay":false,"crossMatching":false,"runnersVoidable":false,"numberOfActiveRunners":7,"betDelay":0,"status":"OPEN","runners":[{"status":"ACTIVE","sortPriority":1,"id":42146659,"name":"2. Pacific Bug"},{"status":"ACTIVE","sortPriority":2,"id":39307895,"name":"3. Calla Ebony"},{"status":"ACTIVE","sortPriority":3,"id":39594698,"name":"4. Star Connie"},{"status":"ACTIVE","sortPriority":4,"id":43167137,"name":"5. What An Outcome"},{"status":"ACTIVE","sortPriority":5,"id":40879966,"name":"6. Burner Express"},{"status":"ACTIVE","sortPriority":6,"id":41419892,"name":"7. Perfect Mate"},{"status":"ACTIVE","sortPriority":7,"id":41738000,"name":"10. Modern Doll"}],"regulators":["MR_INT"],"venue":"Rockhampton","countryCode":"AU","discountAllowed":true,"timezone":"Australia/Queensland","openDate":"2022-03-02T08:34:00.000Z","version":4382437871,"name":"R11 407m Gr5","eventName":"Rockhampton (AUS) 2nd Mar"},"rc":[{"atb":[[4,34.25],[4.5,29.36],[5,25.69],[3.75,37.36]],"id":43167137},{"atl":[[16,8.86],[18.5,7.6],[22,9.5],[27,7.67]],"id":43167137},{"spn":10.5,"spf":"NaN","id":43167137},{"atb":[[5,25.69],[5.5,22.83],[6,20.55],[7,17.12]],"id":41419892},{"atl":[[19.5,7.19],[38,5.39],[24,5.78],[29,7.12]],"id":41419892},{"spn":13.25,"spf":"NaN","id":41419892},{"atb":[[9.6,11.95],[8.6,13.52],[7.6,15.57],[6.6,18.35]],"id":40879966},{"atl":[[65,2.07],[130,1.54],[90,2.24],[46,2.95]],"id":40879966},{"spn":27.8,"spf":"NaN","id":40879966},{"atb":[[34,3.11],[18.5,5.87],[22,4.89],[27,3.95]],"id":39307895},{"atl":[[300,0.44],[350,0.57],[400,0.5],[250,0.53]],"id":39307895},{"spn":142.0,"spf":"NaN","id":39307895},{"atb":[[3.2,46.71],[2.88,54.66],[2.98,51.9],[2.78,57.73]],"id":41738000},{"atl":[[9.2,16.22],[10.5,21],[8.2,18.47],[13,16.63]],"id":41738000},{"spn":5.7,"spf":"NaN","id":41738000},{"atb":[[3.8,36.69],[3.55,40.29],[3.3,44.68],[3.05,50.12]],"id":42146659},{"atl":[[17,12.47],[12,12.09],[9.8,15.11],[14.5,14.78]],"id":42146659},{"spn":6.8,"spf":"NaN","id":42146659},{"atb":[[3.45,41.94],[3.2,46.71],[3.7,38.06],[2.98,51.9]],"id":39594698},{"atl":[[16,13.3],[11,13.3],[13.5,15.96],[9.4,15.84]],"id":39594698},{"spn":6.55,"spf":"NaN","id":39594698}],"con":true,"img":true}]}
{"op":"mcm","clk":"5352099121","pt":1646182492006,"mc":[{"id":"1.195453782","rc":[{"spn":10.5,"spf":"NaN","id":43167137},{"spn":13.25,"spf":"NaN","id":41419892},{"spn":5.7,"spf":"NaN","id":41738000},{"spn":6.8,"spf":"NaN","id":42146659},{"atb":[[3.45,0],[3.2,0],[3.7,0],[2.98,0]],"id":39594698},{"atl":[[16,0],[11,0],[13.5,0],[9.4,0]],"id":39594698},{"spn":"NaN","spf":"NaN","id":39594698}],"con":true,"img":false}]}
{"op":"mcm","clk":"5352099423","pt":1646182499106,"mc":[{"id":"1.195453782","rc":[{"atb":[[3.4,42.81],[3.15,47.79],[3.9,35.43],[3.65,38.77]],"id":39594698},{"atl":[[18,11.73],[10.5,14],[13,11.08],[15.5,13.76]],"id":39594698}],"con":true,"img":false}]}
{"op":"mcm","clk":"5352146215","pt":1646183572669,"mc":[{"id":"1.195453782","marketDefinition":{"bspMarket":true,"turnInPlayEnabled":false,"persistenceEnabled":false,"marketBaseRate":7.0,"eventId":"31272499","eventTypeId":"4339","numberOfWinners":1,"bettingType":"ODDS","marketType":"WIN","marketTime":"2022-03-02T11:55:00.000Z","suspendTime":"2022-03-02T11:55:00.000Z","bspReconciled":false,"complete":true,"inPlay":false,"crossMatching":false,"runnersVoidable":false,"numberOfActiveRunners":7,"betDelay":0,"status":"OPEN","runners":[{"status":"ACTIVE","sortPriority":1,"id":42146659,"name":"2. Pacific Bug"},{"status":"ACTIVE","sortPriority":2,"id":39307895,"name":"3. Calla Ebony"},{"status":"ACTIVE","sortPriority":3,"id":39594698,"name":"4. Star Connie"},{"status":"ACTIVE","sortPriority":4,"id":43167137,"name":"5. What An Outcome"},{"status":"ACTIVE","sortPriority":5,"id":40879966,"name":"6. Burner Express"},{"status":"ACTIVE","sortPriority":6,"id":41419892,"name":"7. Perfect Mate"},{"status":"ACTIVE","sortPriority":7,"id":41738000,"name":"10. Modern Doll"}],"regulators":["MR_INT"],"venue":"Rockhampton","countryCode":"AU","discountAllowed":true,"timezone":"Australia/Queensland","openDate":"2022-03-02T08:28:00.000Z","version":4382597856,"name":"R11 407m Gr5","eventName":"Rockhampton (AUS) 2nd Mar"},"rc":[],"con":true,"img":false}]}
{"op":"mcm","clk":"5352238019","pt":1646185602659,"mc":[{"id":"1.195453782","marketDefinition":{"bspMarket":true,"turnInPlayEnabled":false,"persistenceEnabled":false,"marketBaseRate":7.0,"eventId":"31272499","eventTypeId":"4339","numberOfWinners":1,"bettingType":"ODDS","marketType":"WIN","marketTime":"2022-03-02T11:55:00.000Z","suspendTime":"2022-03-02T11:55:00.000Z","bspReconciled":false,"complete":true,"inPlay":false,"crossMatching":false,"runnersVoidable":false,"numberOfActiveRunners":7,"betDelay":0,"status":"OPEN","runners":[{"status":"ACTIVE","sortPriority":1,"id":42146659,"name":"2. Pacific Bug"},{"status":"ACTIVE","sortPriority":2,"id":39307895,"name":"3. Calla Ebony"},{"status":"ACTIVE","sortPriority":3,"id":39594698,"name":"4. Star Connie"},{"status":"ACTIVE","sortPriority":4,"id":43167137,"name":"5. What An Outcome"},{"status":"ACTIVE","sortPriority":5,"id":40879966,"name":"6. Burner Express"},{"status":"ACTIVE","sortPriority":6,"id":41419892,"name":"7. Perfect Mate"},{"status":"ACTIVE","sortPriority":7,"id":41738000,"name":"10. Modern Doll"}],"regulators":["MR_INT"],"venue":"Rockhampton","countryCode":"AU","discountAllowed":true,"timezone":"Australia/Queensland","openDate":"2022-03-02T08:28:00.000Z","version":4382597856,"name":"R11 407m Gr5","eventName":"Rockhampton (AUS) 2nd Mar"},"rc":[{"atb":[[4,34.3],[4.5,29.4],[5,25.73],[3.75,37.42]],"id":43167137},{"atl":[[16,8.88],[18.5,7.61],[22,9.52],[27,7.68]],"id":43167137},{"spn":10.5,"spf":"NaN","id":43167137},{"atb":[[5,25.73],[5.5,22.86],[6,20.58],[7,17.15]],"id":41419892},{"atl":[[19.5,7.2],[38,5.4],[24,5.79],[29,7.13]],"id":41419892},{"spn":13.25,"spf":"NaN","id":41419892},{"atb":[[9.6,11.96],[8.6,13.54],[7.6,15.59],[6.6,18.38]],"id":40879966},{"atl":[[65,2.08],[130,1.54],[90,2.24],[46,2.96]],"id":40879966},{"spn":27.8,"spf":"NaN","id":40879966},{"atb":[[34,3.11],[18.5,5.88],[22,4.9],[27,3.95]],"id":39307895},{"atl":[[300,0.44],[350,0.57],[400,0.5],[250,0.53]],"id":39307895},{"spn":142.0,"spf":"NaN","id":39307895},{"atb":[[3.2,46.78],[2.88,54.74],[2.98,51.98],[2.78,57.82]],"id":41738000},{"atl":[[9.2,16.24],[10.5,21.04],[8.2,18.5],[13,16.65]],"id":41738000},{"spn":5.7,"spf":"NaN","id":41738000},{"atb":[[3.8,36.75],[3.55,40.36],[3.3,44.75],[3.05,50.2]],"id":42146659},{"atl":[[17,12.49],[12,12.11],[9.8,15.14],[14.5,14.8]],"id":42146659},{"spn":6.8,"spf":"NaN","id":42146659},{"atb":[[3.4,42.88],[3.15,47.87],[3.9,35.49],[3.65,38.84]],"id":39594698},{"atl":[[18,11.75],[10.5,14.03],[13,11.1],[15.5,13.78]],"id":39594698},{"spn":7.2,"spf":"NaN","id":39594698}],"con":true,"img":true}]}
{"op":"mcm","clk":"5352465316","pt":1646191002608,"mc":[{"id":"1.195453782","marketDefinition":{"bspMarket":true,"turnInPlayEnabled":false,"persistenceEnabled":false,"marketBaseRate":7.0,"eventId":"31272499","eventTypeId":"4339","numberOfWinners":1,"bettingType":"ODDS","marketType":"WIN","marketTime":"2022-03-02T11:55:00.000Z","suspendTime":"2022-03-02T11:55:00.000Z","bspReconciled":false,"complete":true,"inPlay":false,"crossMatching":false,"runnersVoidable":false,"numberOfActiveRunners":7,"betDelay":0,"status":"OPEN","runners":[{"status":"ACTIVE","sortPriority":1,"id":42146659,"name":"2. Pacific Bug"},{"status":"ACTIVE","sortPriority":2,"id":39307895,"name":"3. Calla Ebony"},{"status":"ACTIVE","sortPriority":3,"id":39594698,"name":"4. Star Connie"},{"status":"ACTIVE","sortPriority":4,"id":43167137,"name":"5. What An Outcome"},{"status":"ACTIVE","sortPriority":5,"id":40879966,"name":"6. Burner Express"},{"status":"ACTIVE","sortPriority":6,"id":41419892,"name":"7. Perfect Mate"},{"status":"ACTIVE","sortPriority":7,"id":41738000,"name":"10. Modern Doll"}],"regulators":["MR_INT"],"venue":"Rockhampton","countryCode":"AU","discountAllowed":true,"timezone":"Australia/Queensland","openDate":"2022-03-02T08:28:00.000Z","version":4382597856,"name":"R11 407m Gr5","eventName":"Rockhampton (AUS) 2nd Mar"},"rc":[{"atb":[[4,34.36],[4.5,29.45],[5,25.77],[3.75,37.49]],"id":43167137},{"atl":[[16,8.89],[18.5,7.63],[22,9.53],[27,7.7]],"id":43167137},{"spn":10.5,"spf":"NaN","id":43167137},{"atb":[[5,25.77],[5.5,22.9],[6,20.61],[7,17.18]],"id":41419892},{"atl":[[19.5,7.21],[38,5.41],[24,5.8],[29,7.14]],"id":41419892},{"spn":13.25,"spf":"NaN","id":41419892},{"atb":[[9.6,11.98],[8.6,13.56],[7.6,15.62],[6.6,18.41]],"id":40879966},{"atl":[[65,2.08],[130,1.55],[90,2.25],[46,2.96]],"id":40879966},{"spn":27.8,"spf":"NaN","id":40879966},{"atb":[[34,3.12],[18.5,5.89],[22,4.91],[27,3.96]],"id":39307895},{"atl":[[300,0.44],[350,0.57],[400,0.5],[250,0.53]],"id":39307895},{"spn":142.0,"spf":"NaN","id":39307895},{"atb":[[3.2,46.86],[2.88,54.83],[2.98,52.07],[2.78,57.92]],"id":41738000},{"atl":[[9.2,16.27],[10.5,21.07],[8.2,18.53],[13,16.68]],"id":41738000},{"spn":5.7,"spf":"NaN","id":41738000},{"atb":[[3.8,36.81],[3.55,40.43],[3.3,44.82],[3.05,50.28]],"id":42146659},{"atl":[[17,12.51],[12,12.13],[9.8,15.16],[14.5,14.83]],"id":42146659},{"spn":6.8,"spf":"NaN","id":42146659},{"atb":[[3.4,42.95],[3.15,47.95],[3.9,35.55],[3.65,38.9]],"id":39594698},{"atl":[[18,11.77],[10.5,14.05],[13,11.12],[15.5,13.8]],"id":39594698},{"spn":7.2,"spf":"NaN","id":39594698}],"con":true,"img":true}]}
{"op":"mcm","clk":"5352670730","pt":1646196522806,"mc":[{"id":"1.195453782","rc":[{"atb":[[4,34.36],[4.5,29.45],[5,25.77],[3.75,37.49]],"id":43167137},{"atl":[[16,8.89],[18.5,7.63],[22,9.53],[27,7.7]],"id":43167137},{"atb":[[5,25.77],[5.5,22.9],[6,20.61],[7,17.18]],"id":41419892},{"atl":[[19.5,7.21],[38,5.41],[24,5.8],[29,7.14]],"id":41419892},{"atb":[[9.6,11.98],[8.6,13.56],[7.6,15.62],[6.6,18.41]],"id":40879966},{"atl":[[65,2.08],[130,1.55],[90,2.25],[46,2.96]],"id":40879966},{"atb":[[34,3.12],[18.5,5.89],[22,4.91],[27,3.96]],"id":39307895},{"atl":[[300,0.44],[350,0.57],[400,0.5],[250,0.53]],"id":39307895},{"atb":[[3.2,46.86],[2.88,54.83],[2.98,52.07],[2.78,57.92]],"id":41738000},{"atl":[[9.2,16.27],[10.5,21.07],[8.2,18.53],[5.2,8.19],[13,16.68]],"id":41738000},{"spn":4.2,"spf":"NaN","id":41738000},{"atb":[[3.8,36.81],[3.55,40.43],[3.3,44.82],[3.05,50.28]],"id":42146659},{"atl":[[17,12.51],[12,12.13],[9.8,15.16],[14.5,14.83]],"id":42146659},{"atb":[[3.4,42.95],[3.15,47.95],[3.9,35.55],[3.65,38.9]],"id":39594698},{"atl":[[18,11.77],[10.5,14.05],[13,11.12],[15.5,13.8]],"id":39594698},{"spn":7.2,"spf":"NaN","id":39594698}],"con":true,"img":false}]}
{"op":"mcm","clk":"5352772519","pt":1646200030931,"mc":[{"id":"1.195453782","rc":[{"atb":[[4,34.35],[4.5,29.44],[5,25.76],[3.75,37.47]],"id":43167137},{"atl":[[16,8.89],[18.5,7.62],[22,9.53],[27,7.69]],"id":43167137},{"atb":[[5,25.76],[5.5,22.89],[6,20.61],[7,17.17]],"id":41419892},{"atl":[[19.5,7.21],[38,5.41],[24,5.8],[29,7.14]],"id":41419892},{"atb":[[9.6,11.98],[8.6,13.56],[7.6,15.61],[6.6,18.4]],"id":40879966},{"atl":[[65,2.08],[130,1.55],[90,2.24],[46,2.96]],"id":40879966},{"atb":[[34,3.12],[18.5,5.89],[22,4.9],[27,3.96]],"id":39307895},{"atl":[[300,0.44],[350,0.57],[390,0.49],[400,0.5],[250,0.53]],"id":39307895},{"atb":[[3.2,46.84],[2.88,54.81],[2.98,52.05],[2.78,57.89]],"id":41738000},{"atl":[[9.2,16.27],[10.5,21.07],[8.2,18.53],[5.2,8.19],[13,16.68]],"id":41738000},{"atb":[[3.8,36.8],[3.55,40.41],[3.3,44.81],[3.05,50.27]],"id":42146659},{"atl":[[17,12.5],[12,12.13],[9.8,15.16],[14.5,14.82]],"id":42146659},{"atb":[[3.4,42.94],[3.15,47.93],[3.9,35.53],[3.65,38.89]],"id":39594698},{"atl":[[18,11.77],[10.5,14.04],[13,11.12],[15.5,13.8]],"id":39594698}],"con":true,"img":false}]}
{"op":"mcm","clk":"5352772523","pt":1646200031032,"mc":[{"id":"1.195453782","rc":[{"atl":[[44,0.49]],"id":40879966}],"con":true,"img":false}]}
{"op":"mcm","clk":"5352822112","pt":1646201802646,"mc":[{"id":"1.195453782","marketDefinition":{"bspMarket":true,"turnInPlayEnabled":false,"persistenceEnabled":false,"marketBaseRate":7.0,"eventId":"31272499","eventTypeId":"4339","numberOfWinners":1,"bettingType":"ODDS","marketType":"WIN","marketTime":"2022-03-02T11:55:00.000Z","suspendTime":"2022-03-02T11:55:00.000Z","bspReconciled":false,"complete":true,"inPlay":false,"crossMatching":false,"runnersVoidable":false,"numberOfActiveRunners":7,"betDelay":0,"status":"OPEN","runners":[{"status":"ACTIVE","sortPriority":1,"id":42146659,"name":"2. Pacific Bug"},{"status":"ACTIVE","sortPriority":2,"id":39307895,"name":"3. Calla Ebony"},{"status":"ACTIVE","sortPriority":3,"id":39594698,"name":"4. Star Connie"},{"status":"ACTIVE","sortPriority":4,"id":43167137,"name":"5. What An Outcome"},{"status":"ACTIVE","sortPriority":5,"id":40879966,"name":"6. Burner Express"},{"status":"ACTIVE","sortPriority":6,"id":41419892,"name":"7. Perfect Mate"},{"status":"ACTIVE","sortPriority":7,"id":41738000,"name":"10. Modern Doll"}],"regulators":["MR_INT"],"venue":"Rockhampton","countryCode":"AU","discountAllowed":true,"timezone":"Australia/Queensland","openDate":"2022-03-02T08:28:00.000Z","version":4382597856,"name":"R11 407m Gr5","eventName":"Rockhampton (AUS) 2nd Mar"},"rc":[{"atb":[[4,34.35],[4.5,29.44],[5,25.76],[3.75,37.47]],"id":43167137},{"atl":[[16,8.89],[18.5,7.62],[22,9.53],[27,7.69]],"id":43167137},{"spn":10.5,"spf":"NaN","id":43167137},{"atb":[[5,25.76],[5.5,22.89],[6,20.61],[7,17.17]],"id":41419892},{"atl":[[19.5,7.21],[38,5.41],[24,5.8],[29,7.14]],"id":41419892},{"spn":13.25,"spf":"NaN","id":41419892},{"atb":[[9.6,11.98],[8.6,13.56],[7.6,15.61],[6.6,18.4]],"id":40879966},{"atl":[[65,2.08],[130,1.55],[44,0.49],[90,2.24],[46,2.96]],"id":40879966},{"spn":26.8,"spf":"NaN","id":40879966},{"atb":[[34,3.12],[18.5,5.89],[22,4.9],[27,3.96]],"id":39307895},{"atl":[[300,0.44],[350,0.57],[390,0.49],[400,0.5],[250,0.53]],"id":39307895},{"spn":142.0,"spf":"NaN","id":39307895},{"atb":[[3.2,46.84],[2.88,54.81],[2.98,52.05],[2.78,57.89]],"id":41738000},{"atl":[[9.2,16.27],[10.5,21.07],[8.2,18.53],[5.2,8.19],[13,16.68]],"id":41738000},{"spn":4.2,"spf":"NaN","id":41738000},{"atb":[[3.8,36.8],[3.55,40.41],[3.3,44.81],[3.05,50.27]],"id":42146659},{"atl":[[17,12.5],[12,12.13],[9.8,15.16],[14.5,14.82]],"id":42146659},{"spn":6.8,"spf":"NaN","id":42146659},{"atb":[[3.4,42.94],[3.15,47.93],[3.9,35.53],[3.65,38.89]],"id":39594698},{"atl":[[18,11.77],[10.5,14.04],[13,11.12],[15.5,13.8]],"id":39594698},{"spn":7.2,"spf":"NaN","id":39594698}],"con":true,"img":true}]}
{"op":"mcm","clk":"5353027487","pt":1646207202683,"mc":[{"id":"1.195453782","marketDefinition":{"bspMarket":true,"turnInPlayEnabled":false,"persistenceEnabled":false,"marketBaseRate":7.0,"eventId":"31272499","eventTypeId":"4339","numberOfWinners":1,"bettingType":"ODDS","marketType":"WIN","marketTime":"2022-03-02T11:55:00.000Z","suspendTime":"2022-03-02T11:55:00.000Z","bspReconciled":false,"complete":true,"inPlay":false,"crossMatching":false,"runnersVoidable":false,"numberOfActiveRunners":7,"betDelay":0,"status":"OPEN","runners":[{"status":"ACTIVE","sortPriority":1,"id":42146659,"name":"2. Pacific Bug"},{"status":"ACTIVE","sortPriority":2,"id":39307895,"name":"3. Calla Ebony"},{"status":"ACTIVE","sortPriority":3,"id":39594698,"name":"4. Star Connie"},{"status":"ACTIVE","sortPriority":4,"id":43167137,"name":"5. What An Outcome"},{"status":"ACTIVE","sortPriority":5,"id":40879966,"name":"6. Burner Express"},{"status":"ACTIVE","sortPriority":6,"id":41419892,"name":"7. Perfect Mate"},{"status":"ACTIVE","sortPriority":7,"id":41738000,"name":"10. Modern Doll"}],"regulators":["MR_INT"],"venue":"Rockhampton","countryCode":"AU","discountAllowed":true,"timezone":"Australia/Queensland","openDate":"2022-03-02T08:28:00.000Z","version":4382597856,"name":"R11 407m Gr5","eventName":"Rockhampton (AUS) 2nd Mar"},"rc":[{"atb":[[4,34.34],[4.5,29.43],[5,25.75],[3.75,37.46]],"id":43167137},{"atl":[[16,8.89],[18.5,7.62],[22,9.53],[27,7.69]],"id":43167137},{"spn":10.5,"spf":"NaN","id":43167137},{"atb":[[5,25.75],[5.5,22.89],[6,20.6],[7,17.17]],"id":41419892},{"atl":[[19.5,7.21],[38,5.4],[24,5.8],[29,7.14]],"id":41419892},{"spn":13.25,"spf":"NaN","id":41419892},{"atb":[[9.6,11.98],[8.6,13.55],[7.6,15.61],[6.6,18.4]],"id":40879966},{"atl":[[65,2.08],[130,1.55],[44,0.49],[90,2.24],[46,2.96]],"id":40879966},{"spn":26.8,"spf":"NaN","id":40879966},{"atb":[[34,3.12],[18.5,5.88],[22,4.9],[27,3.96]],"id":39307895},{"atl":[[300,0.44],[350,0.57],[390,0.49],[400,0.5],[250,0.53]],"id":39307895},{"spn":142.0,"spf":"NaN","id":39307895},{"atb":[[3.2,46.83],[2.88,54.8],[2.98,52.03],[2.78,57.88]],"id":41738000},{"atl":[[9.2,16.26],[10.5,21.06],[8.2,18.52],[5.2,8.18],[13,16.67]],"id":41738000},{"spn":4.2,"spf":"NaN","id":41738000},{"atb":[[3.8,36.79],[3.55,40.4],[3.3,44.79],[3.05,50.25]],"id":42146659},{"atl":[[17,12.5],[12,12.12],[9.8,15.15],[14.5,14.82]],"id":42146659},{"spn":6.8,"spf":"NaN","id":42146659},{"atb":[[3.4,42.93],[3.15,47.92],[3.9,35.52],[3.65,38.88]],"id":39594698},{"atl":[[18,11.76],[10.5,14.04],[13,11.11],[15.5,13.79]],"id":39594698},{"spn":7.2,"spf":"NaN","id":39594698}],"con":true,"img":true}]}
{"op":"mcm","clk":"5353298840","pt":1646212602694,"mc":[{"id":"1.195453782","marketDefinition":{"bspMarket":true,"turnInPlayEnabled":false,"persistenceEnabled":false,"marketBaseRate":7.0,"eventId":"31272499","eventTypeId":"4339","numberOfWinners":1,"bettingType":"ODDS","marketType":"WIN","marketTime":"2022-03-02T11:55:00.000Z","suspendTime":"2022-03-02T11:55:00.000Z","bspReconciled":false,"complete":true,"inPlay":false,"crossMatching":false,"runnersVoidable":false,"numberOfActiveRunners":7,"betDelay":0,"status":"OPEN","runners":[{"status":"ACTIVE","sortPriority":1,"id":42146659,"name":"2. Pacific Bug"},{"status":"ACTIVE","sortPriority":2,"id":39307895,"name":"3. Calla Ebony"},{"status":"ACTIVE","sortPriority":3,"id":39594698,"name":"4. Star Connie"},{"status":"ACTIVE","sortPriority":4,"id":43167137,"name":"5. What An Outcome"},{"status":"ACTIVE","sortPriority":5,"id":40879966,"name":"6. Burner Express"},{"status":"ACTIVE","sortPriority":6,"id":41419892,"name":"7. Perfect Mate"},{"status":"ACTIVE","sortPriority":7,"id":41738000,"name":"10. Modern Doll"}],"regulators":["MR_INT"],"venue":"Rockhampton","countryCode":"AU","discountAllowed":true,"timezone":"Australia/Queensland","openDate":"2022-03-02T08:28:00.000Z","version":4382597856,"name":"R11 407m Gr5","eventName":"Rockhampton (AUS) 2nd Mar"},"rc":[{"atb":[[4,34.29],[4.5,29.39],[5,25.71],[3.75,37.4]],"id":43167137},{"atl":[[16,8.87],[18.5,7.61],[22,9.51],[27,7.68]],"id":43167137},{"spn":10.5,"spf":"NaN","id":43167137},{"atb":[[5,25.71],[5.5,22.85],[6,20.57],[7,17.14]],"id":41419892},{"atl":[[19.5,7.19],[38,5.4],[24,5.79],[29,7.13]],"id":41419892},{"spn":13.25,"spf":"NaN","id":41419892},{"atb":[[9.6,11.96],[8.6,13.53],[7.6,15.58],[6.6,18.37]],"id":40879966},{"atl":[[65,2.08],[130,1.54],[44,0.49],[90,2.24],[46,2.95]],"id":40879966},{"spn":26.8,"spf":"NaN","id":40879966},{"atb":[[34,3.11],[18.5,5.88],[22,4.89],[27,3.95]],"id":39307895},{"atl":[[300,0.44],[350,0.57],[390,0.49],[400,0.5],[250,0.53]],"id":39307895},{"spn":142.0,"spf":"NaN","id":39307895},{"atb":[[3.2,46.76],[2.88,54.71],[2.98,51.95],[2.78,57.79]],"id":41738000},{"atl":[[9.2,16.24],[10.5,21.03],[8.2,18.49],[5.2,8.17],[13,16.64]],"id":41738000},{"spn":4.2,"spf":"NaN","id":41738000},{"atb":[[3.8,36.73],[3.55,40.34],[3.3,44.72],[3.05,50.17]],"id":42146659},{"atl":[[17,12.48],[12,12.1],[9.8,15.13],[14.5,14.8]],"id":42146659},{"spn":6.8,"spf":"NaN","id":42146659},{"atb":[[3.4,42.86],[3.15,47.84],[3.9,35.47],[3.65,38.81]],"id":39594698},{"atl":[[18,11.74],[10.5,14.02],[13,11.1],[15.5,13.77]],"id":39594698},{"spn":7.2,"spf":"NaN","id":39594698}],"con":true,"img":true}]}
{"op":"mcm","clk":"5353335533","pt":1646213195667,"mc":[{"id":"1.195453782","rc":[{"atb":[[4,34.29],[4.5,29.39],[1.01,2.25],[5,25.71],[3.75,37.4]],"id":43167137},{"atl":[[16,8.87],[18.5,7.61],[22,9.51],[27,7.68]],"id":43167137},{"atb":[[5,25.71],[5.5,22.85],[6,20.57],[7,17.14]],"id":41419892},{"atl":[[19.5,7.19],[38,5.4],[24,5.79],[29,7.13]],"id":41419892},{"atb":[[9.6,11.96],[8.6,13.53],[7.6,15.58],[6.6,18.37]],"id":40879966},{"atl":[[65,2.08],[130,1.54],[90,2.24],[46,2.95]],"id":40879966},{"spn":26.8,"spf":"NaN","id":40879966},{"atb":[[34,3.11],[18.5,5.88],[22,4.89],[27,3.95]],"id":39307895},{"atl":[[300,0.44],[350,0.57],[400,0.5],[250,0.53]],"id":39307895},{"atb":[[3.2,46.76],[2.88,54.71],[2.98,51.95],[3.25,3.33],[2.78,57.79]],"id":41738000},{"atl":[[9.2,16.24],[10.5,21.03],[8.2,18.49],[5.2,8.17],[13,16.64]],"id":41738000},{"spn":4.22,"spf":"NaN","id":41738000},{"atb":[[3.85,2.63],[3.8,36.73],[3.55,40.34],[3.3,44.72],[3.05,50.17]],"id":42146659},{"atl":[[17,12.48],[12,12.1],[9.8,15.13],[14.5,14.8]],"id":42146659},{"spn":6.82,"spf":"NaN","id":42146659},{"atb":[[3.95,2.54],[3.4,42.86],[3.15,47.84],[3.9,35.47],[3.65,38.81]],"id":39594698},{"atl":[[18,11.74],[10.5,14.02],[13,11.1],[15.5,13.77]],"id":39594698},{"spn":7.22,"spf":"NaN","id":39594698}],"con":true,"img":false}]}
{"op":"mcm","clk":"5353335547","pt":1646213195822,"mc":[{"id":"1.195453782","rc":[{"atb":[[1.01,1.83]],"id":43167137}],"con":true,"img":false}]}
{"op":"mcm","clk":"5353335587","pt":1646213196337,"mc":[{"id":"1.195453782","rc":[{"atb":[[1.01,0]],"id":43167137}],"con":true,"img":false}]}
{"op":"mcm","clk":"5353335591","pt":1646213196440,"mc":[{"id":"1.195453782","rc":[{"atb":[[5.1,1.83]],"id":43167137}],"con":true,"img":false}]}
{"op":"mcm","clk":"5353336496","pt":1646213212568,"mc":[{"id":"1.195453782","rc":[{"atb":[[3.85,6.18]],"id":42146659}],"con":true,"img":false}]}
{"op":"mcm","clk":"5353336506","pt":1646213212776,"mc":[{"id":"1.195453782","rc":[{"atb":[[3.95,5.96]],"id":39594698}],"con":true,"img":false}]}
{"op":"mcm","clk":"5353336515","pt":1646213212982,"mc":[{"id":"1.195453782","rc":[{"atb":[[3.25,7.81]],"id":41738000}],"con":true,"img":false}]}
{"op":"mcm","clk":"5353336519","pt":1646213213085,"mc":[{"id":"1.195453782","rc":[{"atb":[[5.1,4.29]],"id":43167137}],"con":true,"img":false}]}
{"op":"mcm","clk":"5353336869","pt":1646213219193,"mc":[{"id":"1.195453782","marketDefinition":{"bspMarket":true,"turnInPlayEnabled":false,"persistenceEnabled":false,"marketBaseRate":7.0,"eventId":"31272499","eventTypeId":"4339","numberOfWinners":1,"bettingType":"ODDS","marketType":"WIN","marketTime":"2022-03-02T11:55:00.000Z","suspendTime":"2022-03-02T11:55:00.000Z","bspReconciled":false,"complete":true,"inPlay":false,"crossMatching":true,"runnersVoidable":false,"numberOfActiveRunners":7,"betDelay":0,"status":"OPEN","runners":[{"status":"ACTIVE","sortPriority":1,"id":42146659,"name":"2. Pacific Bug"},{"status":"ACTIVE","sortPriority":2,"id":39307895,"name":"3. Calla Ebony"},{"status":"ACTIVE","sortPriority":3,"id":39594698,"name":"4. Star Connie"},{"status":"ACTIVE","sortPriority":4,"id":43167137,"name":"5. What An Outcome"},{"status":"ACTIVE","sortPriority":5,"id":40879966,"name":"6. Burner Express"},{"status":"ACTIVE","sortPriority":6,"id":41419892,"name":"7. Perfect Mate"},{"status":"ACTIVE","sortPriority":7,"id":41738000,"name":"10. Modern Doll"}],"regulators":["MR_INT"],"venue":"Rockhampton","countryCode":"AU","discountAllowed":true,"timezone":"Australia/Queensland","openDate":"2022-03-02T08:28:00.000Z","version":4382597856,"name":"R11 407m Gr5","eventName":"Rockhampton (AUS) 2nd Mar"},"rc":[],"con":true,"img":false}]}
{"op":"mcm","clk":"5353434799","pt":1646214900086,"mc":[{"id":"1.195453782","rc":[{"spn":10.55,"spf":"NaN","id":43167137},{"atb":[[3.05,2]],"id":41738000},{"atb":[[3.6,2]],"id":42146659},{"atb":[[3.9,37.47]],"id":39594698}],"con":true,"img":false}]}
{"op":"mcm","clk":"5353434805","pt":1646214900239,"mc":[{"id":"1.195453782","rc":[{"atb":[[4.9,2]],"id":43167137},{"atb":[[6.6,1.8]],"id":41419892},{"atb":[[8.2,1.4]],"id":40879966},{"atb":[[27,4.34]],"id":39307895}],"con":true,"img":false}]}
{"op":"mcm","clk":"5353435578","pt":1646214914245,"mc":[{"id":"1.195453782","rc":[{"atb":[[8.2,0]],"id":40879966}],"con":true,"img":false}]}
{"op":"mcm","clk":"5353435592","pt":1646214914449,"mc":[{"id":"1.195453782","rc":[{"atb":[[8.6,14.86]],"id":40879966}],"con":true,"img":false}]}
{"op":"mcm","clk":"5353436980","pt":1646214938350,"mc":[{"id":"1.195453782","rc":[{"atb":[[3.6,0]],"id":42146659}],"con":true,"img":false}]}
{"op":"mcm","clk":"5353436985","pt":1646214938456,"mc":[{"id":"1.195453782","rc":[{"atb":[[3.65,2]],"id":42146659}],"con":true,"img":false}]}
{"op":"mcm","clk":"5353605294","pt":1646216700414,"mc":[{"id":"1.195453782","rc":[{"atb":[[3.05,35.12]],"id":43167137},{"atb":[[4,24]],"id":41419892},{"atb":[[5.3,16.74]],"id":40879966},{"atb":[[13,6]],"id":39307895},{"atb":[[2.12,64.29]],"id":41738000},{"atb":[[2.42,50.7]],"id":42146659},{"atb":[[2.46,49.32]],"id":39594698}],"con":true,"img":false}]}
{"op":"mcm","clk":"5353605305","pt":1646216700519,"mc":[{"id":"1.195453782","rc":[{"atb":[[2.22,67.21]],"id":43167137},{"atl":[[38,8.2]],"id":43167137},{"atb":[[2.8,45.56]],"id":41419892},{"atb":[[3.55,32.16]],"id":40879966},{"atb":[[8.6,10.79]],"id":39307895},{"atb":[[1.67,122.39]],"id":41738000},{"atl":[[9,8.2]],"id":41738000},{"atb":[[1.85,96.47]],"id":42146659},{"atl":[[18,8.2]],"id":42146659},{"atb":[[1.88,93.18]],"id":39594698},{"atl":[[19.5,8.2]],"id":39594698}],"con":true,"img":false}]}
{"op":"mcm","clk":"5353605319","pt":1646216700624,"mc":[{"id":"1.195453782","rc":[{"atl":[[50,14.2]],"id":43167137},{"atb":[[2.62,46.3]],"id":41419892},{"atl":[[48,8.2],[60,14.2]],"id":41419892},{"atl":[[190,14.2]],"id":40879966},{"atb":[[2.62,46.3]],"id":39307895},{"atl":[[11.5,14.2]],"id":41738000},{"atl":[[23,14.2]],"id":42146659},{"atl":[[25,14.2]],"id":39594698}],"con":true,"img":false}]}
{"op":"mcm","clk":"5353605333","pt":1646216700725,"mc":[{"id":"1.195453782","rc":[{"atb":[[2.62,46.3]],"id":40879966},{"atb":[[4.2,26.56]],"id":39307895},{"atl":[[17,8.5],[34,13.5]],"id":41738000},{"atl":[[34,13.5]],"id":42146659},{"atl":[[34,13.5]],"id":39594698}],"con":true,"img":false}]}
{"op":"mcm","clk":"5353785758","pt":1646218464188,"mc":[{"id":"1.195453782","rc":[{"atb":[[5.1,18.55],[4.6,35.42]],"id":43167137},{"atl":[[10,6.49],[14,8.71]],"id":43167137},{"spn":7.55,"spf":"NaN","id":43167137},{"atb":[[7.2,9.42],[6.2,23.32]],"id":41419892},{"atl":[[19,6.73],[15.5,4.03]],"id":41419892},{"spn":11.35,"spf":"NaN","id":41419892},{"atb":[[8.8,7.49],[7.8,18.52]],"id":40879966},{"atl":[[21,2.92],[29,4.35]],"id":40879966},{"spn":15.3,"spf":"NaN","id":40879966},{"atb":[[19,6.05],[28,2.72]],"id":39307895},{"atl":[[150,2.72],[110,2.72]],"id":39307895},{"spn":72.0,"spf":"NaN","id":39307895},{"atb":[[3,55.31],[3.25,33.79]],"id":41738000},{"atl":[[8,15.8],[5.8,12.17]],"id":41738000},{"atb":[[3.6,22.48],[3.35,54.49]],"id":42146659},{"atl":[[9.2,14.71],[6.8,10.07]],"id":42146659},{"spn":5.32,"spf":"NaN","id":42146659},{"atb":[[3.45,46.04],[3.95,25.78]],"id":39594698},{"atl":[[7.2,9.42],[10,12.53]],"id":39594698},{"spn":5.57,"spf":"NaN","id":39594698}],"con":true,"img":false}]}
{"op":"mcm","clk":"5353786577","pt":1646218472973,"mc":[{"id":"1.195453782","rc":[{"atb":[[5.1,16.71]],"id":43167137},{"atb":[[3.25,30.45]],"id":41738000},{"atb":[[3.95,23.23]],"id":39594698}],"con":true,"img":false}]}
{"op":"mcm","clk":"5353787379","pt":1646218482027,"mc":[{"id":"1.195453782","rc":[{"atb":[[1.01,2.25]],"id":43167137},{"atb":[[3.3,3.27]],"id":41738000},{"atb":[[4,2.5]],"id":39594698}],"con":true,"img":false}]}
{"op":"mcm","clk":"5353787401","pt":1646218482181,"mc":[{"id":"1.195453782","rc":[{"atb":[[1.01,1.78]],"id":43167137}],"con":true,"img":false}]}
{"op":"mcm","clk":"5353787418","pt":1646218482384,"mc":[{"id":"1.195453782","rc":[{"atb":[[1.01,0]],"id":43167137}],"con":true,"img":false}]}
{"op":"mcm","clk":"5353787425","pt":1646218482491,"mc":[{"id":"1.195453782","rc":[{"atb":[[5.2,1.78]],"id":43167137}],"con":true,"img":false}]}
{"op":"mcm","clk":"5353789079","pt":1646218492819,"mc":[{"id":"1.195453782","rc":[{"atb":[[9.6,0],[8.6,1.33],[7.6,0],[6.6,0]],"id":40879966},{"atl":[[65,0],[130,0],[90,0],[46,0]],"id":40879966},{"atb":[[3.2,0],[2.88,0],[2.98,0],[2.78,0]],"id":41738000},{"atl":[[9.2,0],[10.5,0],[8.2,0],[13,0]],"id":41738000}],"con":true,"img":false}]}
{"op":"mcm","clk":"5353789243","pt":1646218494329,"mc":[{"id":"1.195453782","rc":[{"atb":[[3.25,25.97]],"id":41738000}],"con":true,"img":false}]}
{"op":"mcm","clk":"5353790074","pt":1646218503129,"mc":[{"id":"1.195453782","rc":[{"atb":[[3.4,41.67]],"id":43167137},{"atl":[[16.5,6.45]],"id":43167137},{"atb":[[4.2,31.25]],"id":41419892},{"atl":[[34,3.03]],"id":41419892},{"atb":[[2.7,46.3]],"id":40879966},{"atl":[[50,2.04]],"id":40879966},{"atb":[[9,12.5]],"id":39307895},{"atl":[[210,2]],"id":39307895},{"atb":[[2.24,80.65]],"id":41738000},{"atl":[[13,8.33]],"id":41738000},{"atb":[[2.42,121.12]],"id":42146659},{"atl":[[10.5,10.53]],"id":42146659},{"atb":[[2.6,62.5]],"id":39594698},{"atl":[[14.5,7.41]],"id":39594698}],"con":true,"img":false}]}
{"op":"mcm","clk":"5353790585","pt":1646218508238,"mc":[{"id":"1.195453782","rc":[{"atb":[[9.6,11.96],[8.6,14.86],[7.6,15.58],[6.6,18.37]],"id":40879966},{"atl":[[65,2.08],[130,1.54],[90,2.24],[46,2.95]],"id":40879966},{"atb":[[3.2,46.76],[2.88,54.71],[2.98,51.95],[2.78,57.79]],"id":41738000},{"atl":[[9.2,16.24],[10.5,21.03],[8.2,18.49],[13,24.97]],"id":41738000}],"con":true,"img":false}]}
{"op":"mcm","clk":"5353791419","pt":1646218514359,"mc":[{"id":"1.195453782","rc":[{"atb":[[3.3,6.89]],"id":41738000}],"con":true,"img":false}]}
{"op":"mcm","clk":"5353794858","pt":1646218540275,"mc":[{"id":"1.195453782","rc":[{"spn":7.6,"spf":"NaN","id":43167137},{"atl":[[190,2],[210,0]],"id":39307895},{"spn":4.25,"spf":"NaN","id":41738000},{"spn":5.6,"spf":"NaN","id":39594698}],"con":true,"img":false}]}
{"op":"mcm","clk":"5353803443","pt":1646218623165,"mc":[{"id":"1.195453782","rc":[{"atb":[[9,0],[7.8,14.71]],"id":39307895}],"con":true,"img":false}]}
{"op":"mcm","clk":"5353811218","pt":1646218708749,"mc":[{"id":"1.195453782","rc":[{"atb":[[1.02,2.25]],"id":40879966},{"atl":[[1000,2.25]],"id":39307895}],"con":true,"img":false}]}
{"op":"mcm","clk":"5353811228","pt":1646218708848,"mc":[{"id":"1.195453782","rc":[{"atb":[[1.02,0.38]],"id":40879966},{"atl":[[1000,0.03]],"id":39307895}],"con":true,"img":false}]}
{"op":"mcm","clk":"5353811250","pt":1646218709010,"mc":[{"id":"1.195453782","rc":[{"atb":[[1.02,0]],"id":40879966}],"con":true,"img":false}]}
{"op":"mcm","clk":"5353811257","pt":1646218709158,"mc":[{"id":"1.195453782","rc":[{"atb":[[9.8,0.38]],"id":40879966}],"con":true,"img":false}]}
{"op":"mcm","clk":"5353811279","pt":1646218709326,"mc":[{"id":"1.195453782","rc":[{"atl":[[1000,0]],"id":39307895}],"con":true,"img":false}]}
{"op":"mcm","clk":"5353811290","pt":1646218709426,"mc":[{"id":"1.195453782","rc":[{"atl":[[100,0.03]],"id":39307895}],"con":true,"img":false}]}
{"op":"mcm","clk":"5353814155","pt":1646218738768,"mc":[{"id":"1.195453782","rc":[{"atb":[[1.06,2.25]],"id":39307895}],"con":true,"img":false}]}
{"op":"mcm","clk":"5353814180","pt":1646218738973,"mc":[{"id":"1.195453782","rc":[{"atb":[[1.06,0.1]],"id":39307895}],"con":true,"img":false}]}
{"op":"mcm","clk":"5353814187","pt":1646218739070,"mc":[{"id":"1.195453782","rc":[{"atb":[[1.06,0]],"id":39307895}],"con":true,"img":false}]}
{"op":"mcm","clk":"5353814198","pt":1646218739180,"mc":[{"id":"1.195453782","rc":[{"atb":[[36,0.1]],"id":39307895}],"con":true,"img":false}]}
{"op":"mcm","clk":"5353847191","pt":1646219072398,"mc":[{"id":"1.195453782","rc":[{"atb":[[4,34.29],[5.1,16.71],[4.5,29.39],[5,25.71],[4.6,35.42],[5.2,1.78],[3.75,37.41]],"id":43167137},{"atl":[[16,8.87],[34,13.5],[18.5,7.61],[10,6.49],[22,9.51],[27,7.68],[14,8.72]],"id":43167137},{"atb":[[7.2,9.42],[5,25.71],[6.2,23.32],[5.5,22.85],[6,20.57],[7,17.14]],"id":41419892},{"atl":[[19,6.73],[19.5,7.19],[38,5.4],[24,5.79],[29,7.13],[15.5,4.03]],"id":41419892},{"atb":[[9.6,11.96],[8.6,14.86],[7.6,15.58],[9.8,0.38],[8.8,7.49],[7.8,18.53],[6.6,18.37]],"id":40879966},{"atl":[[65,2.08],[21,2.92],[90,2.24],[46,2.95],[29,4.36]],"id":40879966},{"spn":15.4,"spf":"NaN","id":40879966},{"atb":[[34,3.11],[36,0.1],[18.5,5.88],[19,6.05],[22,4.89],[27,4.34],[28,2.72]],"id":39307895},{"atl":[[150,2.72],[110,2.72]],"id":39307895},{"spn":68.0,"spf":"NaN","id":39307895},{"atb":[[3.2,46.76],[2.88,54.71],[3,55.31],[3.25,25.98],[2.98,51.95],[3.3,6.88],[2.78,57.79]],"id":41738000},{"atl":[[8,15.8],[5.8,12.17],[9.2,16.24],[10.5,21.03],[8.2,18.49],[5.2,8.17],[13,24.98]],"id":41738000},{"atb":[[3.6,22.48],[3.85,6.17],[3.35,54.5],[3.8,36.73],[3.55,40.34],[3.3,44.72],[3.05,50.17]],"id":42146659},{"atl":[[17,12.48],[9.2,14.71],[6.8,10.07],[12,12.11],[9.8,15.13],[14.5,14.8]],"id":42146659},{"atb":[[4,2.5],[3.45,46.04],[3.95,23.23],[3.4,42.86],[3.15,47.84],[3.9,37.47],[3.65,38.82]],"id":39594698},{"atl":[[7.2,9.42],[18,11.75],[10,12.53],[10.5,14.02],[13,11.1],[15.5,13.77]],"id":39594698}],"con":true,"img":false}]}
{"op":"mcm","clk":"5353847203","pt":1646219072603,"mc":[{"id":"1.195453782","rc":[{"atb":[[36,0],[1.06,2.25]],"id":39307895}],"con":true,"img":false}]}
{"op":"mcm","clk":"5353847210","pt":1646219072704,"mc":[{"id":"1.195453782","rc":[{"atb":[[1.06,0.1]],"id":39307895}],"con":true,"img":false}]}
{"op":"mcm","clk":"5353847220","pt":1646219072909,"mc":[{"id":"1.195453782","rc":[{"atb":[[1.06,0]],"id":39307895}],"con":true,"img":false}]}
{"op":"mcm","clk":"5353847226","pt":1646219073013,"mc":[{"id":"1.195453782","rc":[{"atb":[[29,0.1]],"id":39307895}],"con":true,"img":false}]}
{"op":"mcm","clk":"5353856484","pt":1646219159486,"mc":[{"id":"1.195453782","rc":[{"atb":[[1.06,2.25],[29,0]],"id":39307895},{"spn":67.0,"spf":"NaN","id":39307895}],"con":true,"img":false}]}
{"op":"mcm","clk":"5353856504","pt":1646219159685,"mc":[{"id":"1.195453782","rc":[{"atb":[[1.06,0.1]],"id":39307895}],"con":true,"img":false}]}
{"op":"mcm","clk":"5353856520","pt":1646219159895,"mc":[{"id":"1.195453782","rc":[{"atb":[[1.06,0]],"id":39307895}],"con":true,"img":false}]}
{"op":"mcm","clk":"5353856528","pt":1646219160000,"mc":[{"id":"1.195453782","rc":[{"atb":[[36,0.1]],"id":39307895}],"con":true,"img":false}]}
{"op":"mcm","clk":"5353862380","pt":1646219222313,"mc":[{"id":"1.195453782","rc":[{"spn":68.0,"spf":"NaN","id":39307895},{"atb":[[1.04,1.66]],"id":41738000},{"atb":[[1.04,1.66]],"id":42146659}],"con":true,"img":false}]}
{"op":"mcm","clk":"5353862393","pt":1646219222476,"mc":[{"id":"1.195453782","rc":[{"atb":[[1.04,1.65]],"id":41738000},{"atb":[[1.04,1.65]],"id":42146659}],"con":true,"img":false}]}
{"op":"mcm","clk":"5353862416","pt":1646219222686,"mc":[{"id":"1.195453782","rc":[{"atb":[[1.04,0]],"id":41738000},{"atb":[[1.04,0]],"id":42146659}],"con":true,"img":false}]}
{"op":"mcm","clk":"5353862423","pt":1646219222790,"mc":[{"id":"1.195453782","rc":[{"atb":[[3.4,1.65]],"id":41738000},{"atb":[[3.95,1.65]],"id":42146659}],"con":true,"img":false}]}
{"op":"mcm","clk":"5353876030","pt":1646219372841,"mc":[{"id":"1.195453782","rc":[{"atl":[[50,10.23]],"id":40879966},{"spn":4.3,"spf":"NaN","id":41738000},{"spn":5.37,"spf":"NaN","id":42146659}],"con":true,"img":false}]}
{"op":"mcm","clk":"5353897236","pt":1646219585835,"mc":[{"id":"1.195453782","rc":[{"atb":[[3.6,38.46],[2.7,0]],"id":40879966},{"atb":[[7.8,0],[8.8,12.82]],"id":39307895},{"atl":[[17.5,6.06],[13,16.65]],"id":41738000},{"atl":[[10.5,0],[7.4,15.62]],"id":42146659},{"atb":[[3.2,45.45],[2.6,0]],"id":39594698}],"con":true,"img":false}]}
{"op":"mcm","clk":"5353902906","pt":1646219644077,"mc":[{"id":"1.195453782","rc":[{"atl":[[9.2,0]],"id":42146659}],"con":true,"img":false}]}
{"op":"mcm","clk":"5353906581","pt":1646219680191,"mc":[{"id":"1.195453782","rc":[{"atl":[[7.2,20.71]],"id":42146659}],"con":true,"img":false}]}
{"op":"mcm","clk":"5353909885","pt":1646219712345,"mc":[{"id":"1.195453782","rc":[{"atb":[[5.5,22.22],[8.8,0]],"id":39307895},{"atl":[[7.4,0],[6.8,25.69]],"id":42146659},{"atb":[[3.45,86.86],[3.2,0]],"id":39594698}],"con":true,"img":false}]}
{"op":"mcm","clk":"5353910040","pt":1646219713646,"mc":[{"id":"1.195453782","rc":[{"atl":[[7.2,0]],"id":42146659}],"con":true,"img":false}]}
{"op":"mcm","clk":"5353912072","pt":1646219732991,"mc":[{"id":"1.195453782","rc":[{"atl":[[170,2],[190,0]],"id":39307895}],"con":true,"img":false}]}
{"op":"mcm","clk":"5353912517","pt":1646219737394,"mc":[{"id":"1.195453782","rc":[{"atb":[[5.5,0],[9.8,11.36]],"id":39307895}],"con":true,"img":false}]}
{"op":"mcm","clk":"5353913875","pt":1646219749629,"mc":[{"id":"1.195453782","rc":[{"atl":[[9.2,14.71]],"id":42146659}],"con":true,"img":false}]}
{"op":"mcm","clk":"5353917952","pt":1646219786180,"mc":[{"id":"1.195453782","rc":[{"spl":[[1.01,2.72]],"id":39307895}],"con":true,"img":false}]}
{"op":"mcm","clk":"5353918984","pt":1646219794035,"mc":[{"id":"1.195453782","rc":[{"spl":[[1.01,2.72]],"id":40879966}],"con":true,"img":false}]}
{"op":"mcm","clk":"5353919974","pt":1646219799223,"mc":[{"id":"1.195453782","rc":[{"spl":[[1.01,2.72]],"id":41419892}],"con":true,"img":false}]}
{"op":"mcm","clk":"5353926268","pt":1646219853018,"mc":[{"id":"1.195453782","rc":[{"spn":7.2,"spf":1.0,"id":41419892},{"spn":9.62,"spf":1.0,"id":40879966},{"spn":34.07,"spf":1.0,"id":39307895},{"atl":[[7.4,15.62],[6.8,10.07]],"id":42146659}],"con":true,"img":false}]}
{"op":"mcm","clk":"5353932453","pt":1646219916894,"mc":[{"id":"1.195453782","rc":[{"atl":[[7.2,20.71],[9.2,0]],"id":42146659}],"con":true,"img":false}]}
{"op":"mcm","clk":"5353941921","pt":1646220021578,"mc":[{"id":"1.195453782","rc":[{"atb":[[1.04,2.85]],"id":39307895},{"atb":[[1.02,3.42]],"id":42146659}],"con":true,"img":false}]}
{"op":"mcm","clk":"5353941938","pt":1646220021784,"mc":[{"id":"1.195453782","rc":[{"atb":[[1.02,3.24]],"id":43167137},{"atb":[[1.02,3.39]],"id":39594698}],"con":true,"img":false}]}
{"op":"mcm","clk":"5353941961","pt":1646220022097,"mc":[{"id":"1.195453782","rc":[{"atb":[[1.04,0.13]],"id":39307895},{"atb":[[1.02,0.69]],"id":42146659}],"con":true,"img":false}]}
{"op":"mcm","clk":"5353941969","pt":1646220022201,"mc":[{"id":"1.195453782","rc":[{"atb":[[1.02,0.52]],"id":43167137},{"atb":[[1.02,0.66]],"id":39594698}],"con":true,"img":false}]}
{"op":"mcm","clk":"5353942002","pt":1646220022462,"mc":[{"id":"1.195453782","rc":[{"atb":[[1.04,0]],"id":39307895}],"con":true,"img":false}]}
{"op":"mcm","clk":"5353942014","pt":1646220022568,"mc":[{"id":"1.195453782","rc":[{"atb":[[22,5.03]],"id":39307895},{"atb":[[1.02,0]],"id":42146659},{"atb":[[1.02,0]],"id":39594698}],"con":true,"img":false}]}
{"op":"mcm","clk":"5353942025","pt":1646220022675,"mc":[{"id":"1.195453782","rc":[{"atb":[[1.02,0]],"id":43167137},{"atb":[[4.2,0.69]],"id":42146659},{"atb":[[4.4,0.66]],"id":39594698}],"con":true,"img":false}]}
{"op":"mcm","clk":"5353942031","pt":1646220022775,"mc":[{"id":"1.195453782","rc":[{"atb":[[5.6,0.52]],"id":43167137},{"atb":[[1.02,3.02]],"id":40879966}],"con":true,"img":false}]}
{"op":"mcm","clk":"5353942048","pt":1646220022985,"mc":[{"id":"1.195453782","rc":[{"atb":[[1.03,3.1]],"id":41419892}],"con":true,"img":false}]}
{"op":"mcm","clk":"5353942063","pt":1646220023293,"mc":[{"id":"1.195453782","rc":[{"atb":[[1.02,0.29]],"id":40879966}],"con":true,"img":false}]}
{"op":"mcm","clk":"5353942069","pt":1646220023397,"mc":[{"id":"1.195453782","rc":[{"atb":[[1.02,3.54]],"id":41738000}],"con":true,"img":false}]}
{"op":"mcm","clk":"5353942075","pt":1646220023502,"mc":[{"id":"1.195453782","rc":[{"atb":[[1.03,0.37]],"id":41419892}],"con":true,"img":false}]}
{"op":"mcm","clk":"5353942091","pt":1646220023709,"mc":[{"id":"1.195453782","rc":[{"atb":[[1.02,0]],"id":40879966}],"con":true,"img":false}]}
{"op":"mcm","clk":"5353942096","pt":1646220023761,"mc":[{"id":"1.195453782","rc":[{"atb":[[9.8,0.68]],"id":40879966}],"con":true,"img":false}]}
{"op":"mcm","clk":"5353942101","pt":1646220023864,"mc":[{"id":"1.195453782","rc":[{"atb":[[1.02,0.82]],"id":41738000}],"con":true,"img":false}]}
{"op":"mcm","clk":"5353942107","pt":1646220023971,"mc":[{"id":"1.195453782","rc":[{"atb":[[1.03,0]],"id":41419892}],"con":true,"img":false}]}
{"op":"mcm","clk":"5353942135","pt":1646220024286,"mc":[{"id":"1.195453782","rc":[{"atb":[[7.8,0.37]],"id":41419892},{"atb":[[1.02,0]],"id":41738000}],"con":true,"img":false}]}
{"op":"mcm","clk":"5353942142","pt":1646220024386,"mc":[{"id":"1.195453782","rc":[{"atb":[[3.55,0.82]],"id":41738000}],"con":true,"img":false}]}
{"op":"mcm","clk":"5353942213","pt":1646220025278,"mc":[{"id":"1.195453782","rc":[{"atl":[[7.4,0],[6.8,25.69]],"id":42146659}],"con":true,"img":false}]}
{"op":"mcm","clk":"5353942476","pt":1646220028412,"mc":[{"id":"1.195453782","rc":[{"atl":[[7.2,0],[9.2,14.71]],"id":42146659}],"con":true,"img":false}]}
{"op":"mcm","clk":"5353949345","pt":1646220103755,"mc":[{"id":"1.195453782","rc":[{"spl":[[1.01,4]],"id":43167137},{"spn":5.21,"spf":1.0,"id":43167137},{"spl":[[1.01,6.72]],"id":41419892},{"spn":7.23,"spf":1.0,"id":41419892},{"spl":[[1.01,6.72]],"id":40879966},{"spn":9.62,"spf":1.0,"id":40879966},{"spl":[[1.01,6.72]],"id":39307895},{"spn":30.79,"spf":1.0,"id":39307895},{"spn":4.37,"spf":"NaN","id":41738000},{"spn":5.5,"spf":"NaN","id":42146659},{"spn":5.8,"spf":"NaN","id":39594698}],"con":true,"img":false}]}
{"op":"mcm","clk":"5353950641","pt":1646220117550,"mc":[{"id":"1.195453782","rc":[{"spl":[[1.01,8]],"id":43167137},{"spl":[[1.01,10.72]],"id":41419892},{"spl":[[1.01,10.72]],"id":40879966},{"spl":[[1.01,10.72]],"id":39307895}],"con":true,"img":false}]}
{"op":"mcm","clk":"5353965825","pt":1646220283019,"mc":[{"id":"1.195453782","rc":[{"spn":5.15,"spf":1.0,"id":43167137},{"spn":7.2,"spf":1.0,"id":41419892},{"spn":9.61,"spf":1.0,"id":40879966},{"spn":29.17,"spf":1.0,"id":39307895},{"atl":[[15,7.14],[17.5,0]],"id":41738000}],"con":true,"img":false}]}
{"op":"mcm","clk":"5353968191","pt":1646220306150,"mc":[{"id":"1.195453782","rc":[{"atb":[[4.3,15.15],[4.5,35.1],[3.95,42.37],[4.1,24.19]],"id":43167137},{"atl":[[13.5,1.6],[14.5,3.7],[15.5,5.17],[16.5,14.51]],"id":43167137},{"atb":[[5.8,10.42],[5.4,28.41],[5.6,16.3],[6,24.57]],"id":41419892},{"atl":[[16.5,8.06],[13.5,1.6],[14.5,3.7],[15.5,9.2]],"id":41419892},{"atb":[[3.35,53.19],[3.55,51.77],[3.45,30.61],[3.65,7.55]],"id":40879966},{"atl":[[19,1.11],[20,2.63],[22,3.57],[24,5.43]],"id":40879966},{"atb":[[17.5,7.58],[18.5,10.17],[19.5,2.7],[21,1]],"id":39307895},{"atl":[[390,1.49],[410,1],[430,1],[450,1]],"id":39307895},{"atb":[[2.98,62.05],[2.94,25.77],[2.9,39.47],[2.86,67.2]],"id":41738000},{"atl":[[15,8.57],[16,3.33],[17,13.19],[18,7.35]],"id":41738000},{"atb":[[2.6,12.5],[2.48,84.46],[2.56,32.05],[2.52,49.34]],"id":42146659},{"atl":[[5.9,15.31],[6.2,24.04],[5.5,4.44],[5.7,10.64]],"id":42146659},{"atb":[[3.45,117.47],[3.35,53.19],[3.55,19.61],[3.65,46.37]],"id":39594698},{"atl":[[8,7.14],[8.4,10.14],[7.6,3.03],[8.8,16.03]],"id":39594698}],"con":true,"img":false}]}
{"op":"mcm","clk":"5353968230","pt":1646220306565,"mc":[{"id":"1.195453782","rc":[{"atb":[[3.85,3.53]],"id":42146659}],"con":true,"img":false}]}
{"op":"mcm","clk":"5353968814","pt":1646220311956,"mc":[{"id":"1.195453782","rc":[{"atb":[[3.85,0]],"id":42146659}],"con":true,"img":false}]}
{"op":"mcm","clk":"5353971124","pt":1646220334499,"mc":[{"id":"1.195453782","rc":[{"atl":[[6.8,15.62]],"id":42146659}],"con":true,"img":false}]}
{"op":"mcm","clk":"5353971136","pt":1646220334603,"mc":[{"id":"1.195453782","rc":[{"atl":[[6.6,10.07]],"id":42146659}],"con":true,"img":false}]}
{"op":"mcm","clk":"5353973304","pt":1646220354541,"mc":[{"id":"1.195453782","rc":[{"atl":[[19,0]],"id":41419892},{"atl":[[21,9.46],[29,0]],"id":40879966},{"atb":[[19,0]],"id":39307895},{"spn":4.85,"spf":"NaN","id":42146659},{"atb":[[3.45,71.43]],"id":39594698},{"atl":[[10,0],[7.8,16.59]],"id":39594698}],"con":true,"img":false}]}
{"op":"mcm","clk":"5353973316","pt":1646220354657,"mc":[{"id":"1.195453782","rc":[{"atl":[[16,6.73]],"id":41419892},{"atb":[[20,6.05]],"id":39307895},{"atb":[[3.6,46.04]],"id":39594698}],"con":true,"img":false}]}
{"op":"mcm","clk":"5353976924","pt":1646220384587,"mc":[{"id":"1.195453782","rc":[{"atl":[[21,6.54]],"id":40879966}],"con":true,"img":false}]}
{"op":"mcm","clk":"5353976936","pt":1646220384690,"mc":[{"id":"1.195453782","rc":[{"atl":[[19.5,2.92]],"id":40879966}],"con":true,"img":false}]}
{"op":"mcm","clk":"5353978038","pt":1646220394618,"mc":[{"id":"1.195453782","rc":[{"atl":[[15.5,5.17]],"id":41419892}],"con":true,"img":false}]}
{"op":"mcm","clk":"5353978047","pt":1646220394672,"mc":[{"id":"1.195453782","rc":[{"atl":[[14,4.03]],"id":41419892}],"con":true,"img":false}]}
{"op":"mcm","clk":"5353979120","pt":1646220404113,"mc":[{"id":"1.195453782","rc":[{"atb":[[4,5.38]],"id":39594698}],"con":true,"img":false}]}
{"op":"mcm","clk":"5354024475","pt":1646220719578,"mc":[{"id":"1.195453782","rc":[{"atb":[[4.9,0]],"id":43167137},{"atb":[[6.6,0]],"id":41419892},{"atb":[[8.6,13.53]],"id":40879966},{"atb":[[27,3.95]],"id":39307895},{"spn":28.99,"spf":1.0,"id":39307895},{"atb":[[3.05,0]],"id":41738000},{"atb":[[3.65,0]],"id":42146659}],"con":true,"img":false}]}
{"op":"mcm","clk":"5354024503","pt":1646220719792,"mc":[{"id":"1.195453782","rc":[{"atb":[[5.1,18.71]],"id":43167137},{"atb":[[7.2,11.04]],"id":41419892},{"atb":[[9.2,1.23]],"id":40879966},{"atb":[[28,3.1]],"id":39307895},{"atb":[[3.15,2]],"id":41738000},{"atb":[[3.7,2]],"id":42146659}],"con":true,"img":false}]}
{"op":"mcm","clk":"5354024554","pt":1646220720209,"mc":[{"id":"1.195453782","rc":[{"atb":[[36,0],[1.06,2.25]],"id":39307895}],"con":true,"img":false}]}
{"op":"mcm","clk":"5354024566","pt":1646220720302,"mc":[{"id":"1.195453782","rc":[{"atb":[[1.06,0.1]],"id":39307895}],"con":true,"img":false}]}
{"op":"mcm","clk":"5354024577","pt":1646220720407,"mc":[{"id":"1.195453782","rc":[{"atb":[[1.02,2.25],[9.8,0.29]],"id":40879966}],"con":true,"img":false}]}
{"op":"mcm","clk":"5354024594","pt":1646220720468,"mc":[{"id":"1.195453782","rc":[{"atb":[[1.06,0]],"id":39307895}],"con":true,"img":false}]}
{"op":"mcm","clk":"5354024605","pt":1646220720575,"mc":[{"id":"1.195453782","rc":[{"atb":[[29,0.1]],"id":39307895}],"con":true,"img":false}]}
{"op":"mcm","clk":"5354024638","pt":1646220720786,"mc":[{"id":"1.195453782","rc":[{"atb":[[1.02,0.38]],"id":40879966}],"con":true,"img":false}]}
{"op":"mcm","clk":"5354024653","pt":1646220720885,"mc":[{"id":"1.195453782","rc":[{"atb":[[1.02,0]],"id":40879966}],"con":true,"img":false}]}
{"op":"mcm","clk":"5354024665","pt":1646220720990,"mc":[{"id":"1.195453782","rc":[{"atb":[[9.4,0.38]],"id":40879966}],"con":true,"img":false}]}
{"op":"mcm","clk":"5354027717","pt":1646220742402,"mc":[{"id":"1.195453782","rc":[{"atb":[[5.1,16.25]],"id":43167137}],"con":true,"img":false}]}
{"op":"mcm","clk":"5354039151","pt":1646220839877,"mc":[{"id":"1.195453782","rc":[{"spn":7.22,"spf":1.0,"id":41419892},{"spn":9.6,"spf":1.0,"id":40879966},{"atb":[[1.06,2.25],[29,0]],"id":39307895},{"spn":29.06,"spf":1.0,"id":39307895}],"con":true,"img":false}]}
{"op":"mcm","clk":"5354039161","pt":1646220839971,"mc":[{"id":"1.195453782","rc":[{"atb":[[1.06,0.1]],"id":39307895}],"con":true,"img":false}]}
{"op":"mcm","clk":"5354039172","pt":1646220840077,"mc":[{"id":"1.195453782","rc":[{"atb":[[1.06,0]],"id":39307895}],"con":true,"img":false}]}
{"op":"mcm","clk":"5354039188","pt":1646220840179,"mc":[{"id":"1.195453782","rc":[{"atb":[[36,0.1]],"id":39307895}],"con":true,"img":false}]}
{"op":"mcm","clk":"5354056237","pt":1646220995833,"mc":[{"id":"1.195453782","rc":[{"atb":[[7.4,2]],"id":41419892},{"spn":7.25,"spf":1.0,"id":41419892},{"atb":[[9.8,2.29]],"id":40879966},{"spn":9.64,"spf":1.0,"id":40879966},{"atb":[[36,2.1]],"id":39307895},{"atl":[[110,4.72]],"id":39307895},{"spn":31.09,"spf":1.0,"id":39307895}],"con":true,"img":false}]}
{"op":"mcm","clk":"5354057210","pt":1646221004582,"mc":[{"id":"1.195453782","rc":[{"atl":[[14,0]],"id":41419892},{"atl":[[19.5,0]],"id":40879966}],"con":true,"img":false}]}
{"op":"mcm","clk":"5354057229","pt":1646221004742,"mc":[{"id":"1.195453782","rc":[{"atl":[[15,4.03]],"id":41419892},{"atl":[[21,9.46]],"id":40879966}],"con":true,"img":false}]}
{"op":"mcm","clk":"5354057650","pt":1646221009493,"mc":[{"id":"1.195453782","rc":[{"atl":[[13.5,0],[14,1.54]],"id":41419892},{"atl":[[18,1.18],[19,0]],"id":40879966},{"atl":[[6.8,0],[6.2,43.27]],"id":42146659}],"con":true,"img":false}]}
{"op":"mcm","clk":"5354058743","pt":1646221019469,"mc":[{"id":"1.195453782","rc":[{"atl":[[15,7.6]],"id":41419892},{"atl":[[19,2.78]],"id":40879966}],"con":true,"img":false}]}
{"op":"mcm","clk":"5354059100","pt":1646221022978,"mc":[{"id":"1.195453782","rc":[{"atl":[[15,7.14],[16.5,8.06]],"id":43167137},{"atl":[[34,0],[13.5,1.6],[14,0],[15,4.03],[27,3.85]],"id":41419892},{"atl":[[18,0],[19,1.11],[24,0]],"id":40879966},{"atl":[[150,4.72],[170,0]],"id":39307895},{"atl":[[12,9.09],[14.5,0]],"id":39594698}],"con":true,"img":false}]}
{"op":"mcm","clk":"5354059115","pt":1646221023080,"mc":[{"id":"1.195453782","rc":[{"atl":[[1000,2.25]],"id":39307895}],"con":true,"img":false}]}
{"op":"mcm","clk":"5354059125","pt":1646221023186,"mc":[{"id":"1.195453782","rc":[{"atl":[[100,0]],"id":39307895}],"con":true,"img":false}]}
{"op":"mcm","clk":"5354059136","pt":1646221023286,"mc":[{"id":"1.195453782","rc":[{"atl":[[1000,0.03]],"id":39307895}],"con":true,"img":false}]}
{"op":"mcm","clk":"5354059148","pt":1646221023392,"mc":[{"id":"1.195453782","rc":[{"atl":[[1000,0]],"id":39307895}],"con":true,"img":false}]}
{"op":"mcm","clk":"5354059160","pt":1646221023497,"mc":[{"id":"1.195453782","rc":[{"atl":[[140,0.03]],"id":39307895}],"con":true,"img":false}]}
{"op":"mcm","clk":"5354059263","pt":1646221024593,"mc":[{"id":"1.195453782","rc":[{"atl":[[110,2]],"id":39307895}],"con":true,"img":false}]}
{"op":"mcm","clk":"5354059276","pt":1646221024697,"mc":[{"id":"1.195453782","rc":[{"atl":[[140,2.03],[100,2.72]],"id":39307895}],"con":true,"img":false}]}
{"op":"mcm","clk":"5354059288","pt":1646221024801,"mc":[{"id":"1.195453782","rc":[{"atl":[[110,0]],"id":39307895}],"con":true,"img":false}]}
{"op":"mcm","clk":"5354059298","pt":1646221024905,"mc":[{"id":"1.195453782","rc":[{"atl":[[140,0.03]],"id":39307895}],"con":true,"img":false}]}
{"op":"mcm","clk":"5354059308","pt":1646221024967,"mc":[{"id":"1.195453782","rc":[{"atl":[[100,4.72]],"id":39307895}],"con":true,"img":false}]}
{"op":"mcm","clk":"5354060240","pt":1646221032987,"mc":[{"id":"1.195453782","rc":[{"atl":[[24,5.43]],"id":40879966}],"con":true,"img":false}]}
{"op":"mcm","clk":"5354062427","pt":1646221054827,"mc":[{"id":"1.195453782","rc":[{"atl":[[100,2]],"id":39307895}],"con":true,"img":false}]}
{"op":"mcm","clk":"5354062439","pt":1646221054930,"mc":[{"id":"1.195453782","rc":[{"atl":[[140,2.03],[95,2.72]],"id":39307895}],"con":true,"img":false}]}
{"op":"mcm","clk":"5354062451","pt":1646221055037,"mc":[{"id":"1.195453782","rc":[{"atl":[[100,0]],"id":39307895}],"con":true,"img":false}]}
{"op":"mcm","clk":"5354062921","pt":1646221060119,"mc":[{"id":"1.195453782","rc":[{"atl":[[140,0.03],[95,4.72]],"id":39307895}],"con":true,"img":false}]}
{"op":"mcm","clk":"5354062929","pt":1646221060225,"mc":[{"id":"1.195453782","rc":[{"atl":[[95,2.72]],"id":39307895}],"con":true,"img":false}]}
{"op":"mcm","clk":"5354062948","pt":1646221060427,"mc":[{"id":"1.195453782","rc":[{"atb":[[2.38,68.58],[3.4,0]],"id":43167137},{"atl":[[15,0],[18.5,13.32]],"id":43167137},{"atb":[[5.4,51.14],[4.2,0]],"id":41419892},{"atl":[[13,1.67],[13.5,0],[20,5.26],[27,0]],"id":41419892},{"atb":[[9.8,0.29]],"id":40879966},{"atl":[[50,8.2],[17,1.25],[19,2],[28,3.7]],"id":40879966},{"atb":[[36,0.1],[12.5,8.7],[9.8,0]],"id":39307895},{"atl":[[140,2.03]],"id":39307895},{"atb":[[2.24,0],[1.55,101.48]],"id":41738000},{"atl":[[5.9,30.62],[6.2,24.04]],"id":42146659},{"atb":[[3.1,47.62],[3.45,30.61]],"id":39594698},{"atl":[[9.2,12.2],[12,0],[7.6,0],[6.6,3.57]],"id":39594698}],"con":true,"img":false}]}
{"op":"mcm","clk":"5354062964","pt":1646221060637,"mc":[{"id":"1.195453782","rc":[{"atl":[[150,2.72],[110,2]],"id":39307895}],"con":true,"img":false}]}
{"op":"mcm","clk":"5354063336","pt":1646221064548,"mc":[{"id":"1.195453782","rc":[{"atl":[[95,0]],"id":39307895}],"con":true,"img":false}]}
{"op":"mcm","clk":"5354063351","pt":1646221064651,"mc":[{"id":"1.195453782","rc":[{"atl":[[100,2.72]],"id":39307895}],"con":true,"img":false}]}
{"op":"mcm","clk":"5354063456","pt":1646221065649,"mc":[{"id":"1.195453782","rc":[{"atl":[[140,0.03],[100,4.72]],"id":39307895}],"con":true,"img":false}]}
{"op":"mcm","clk":"5354063475","pt":1646221065854,"mc":[{"id":"1.195453782","rc":[{"atl":[[100,2.72],[110,4]],"id":39307895},{"atl":[[6.4,3.7],[6.6,0]],"id":39594698}],"con":true,"img":false}]}
{"op":"mcm","clk":"5354063493","pt":1646221066018,"mc":[{"id":"1.195453782","rc":[{"atl":[[140,2.03],[110,2]],"id":39307895}],"con":true,"img":false}]}
{"op":"mcm","clk":"5354063868","pt":1646221070023,"mc":[{"id":"1.195453782","rc":[{"atb":[[4,2.88]],"id":39594698}],"con":true,"img":false}]}
{"op":"mcm","clk":"5354063915","pt":1646221070435,"mc":[{"id":"1.195453782","rc":[{"atl":[[18,2.94]],"id":40879966}],"con":true,"img":false}]}
{"op":"mcm","clk":"5354064087","pt":1646221072063,"mc":[{"id":"1.195453782","rc":[{"atb":[[2.38,0],[3.15,46.51]],"id":43167137},{"atl":[[15,7.14],[18.5,7.61]],"id":43167137},{"atl":[[24,9.78],[28,0]],"id":40879966},{"atb":[[1.84,111.94],[1.55,0]],"id":41738000},{"atb":[[3.6,84.5],[3.1,0]],"id":39594698}],"con":true,"img":false}]}
{"op":"mcm","clk":"5354064116","pt":1646221072332,"mc":[{"id":"1.195453782","rc":[{"atl":[[24,4.35]],"id":40879966}],"con":true,"img":false}]}
{"op":"mcm","clk":"5354064344","pt":1646221074540,"mc":[{"id":"1.195453782","rc":[{"atl":[[7.8,0]],"id":39594698}],"con":true,"img":false}]}
{"op":"mcm","clk":"5354064354","pt":1646221074643,"mc":[{"id":"1.195453782","rc":[{"atl":[[8.2,16.59]],"id":39594698}],"con":true,"img":false}]}
{"op":"mcm","clk":"5354064475","pt":1646221075956,"mc":[{"id":"1.195453782","rc":[{"atl":[[6.8,8.62]],"id":39594698}],"con":true,"img":false}]}
{"op":"mcm","clk":"5354064837","pt":1646221080437,"mc":[{"id":"1.195453782","rc":[{"atl":[[19,6.17]],"id":40879966}],"con":true,"img":false}]}
{"op":"mcm","clk":"5354065315","pt":1646221085956,"mc":[{"id":"1.195453782","rc":[{"atl":[[7.2,21.52],[8.8,0]],"id":39594698}],"con":true,"img":false}]}
{"op":"mcm","clk":"5354065726","pt":1646221090458,"mc":[{"id":"1.195453782","rc":[{"atl":[[20,6.58],[22,0]],"id":40879966}],"con":true,"img":false}]}
{"op":"mcm","clk":"5354066106","pt":1646221094542,"mc":[{"id":"1.195453782","rc":[{"atl":[[21,2.92]],"id":40879966}],"con":true,"img":false}]}
{"op":"mcm","clk":"5354066116","pt":1646221094641,"mc":[{"id":"1.195453782","rc":[{"atl":[[23,6.54]],"id":40879966}],"con":true,"img":false}]}
{"op":"mcm","clk":"5354066239","pt":1646221095850,"mc":[{"id":"1.195453782","rc":[{"atl":[[8.4,0],[7.6,18.94]],"id":39594698}],"con":true,"img":false}]}
{"op":"mcm","clk":"5354067055","pt":1646221104590,"mc":[{"id":"1.195453782","rc":[{"atl":[[21,0]],"id":40879966},{"atl":[[150,0]],"id":39307895}],"con":true,"img":false}]}
{"op":"mcm","clk":"5354067071","pt":1646221104698,"mc":[{"id":"1.195453782","rc":[{"atl":[[19.5,2.92]],"id":40879966},{"atl":[[130,2.72]],"id":39307895}],"con":true,"img":false}]}
{"op":"mcm","clk":"5354067085","pt":1646221104751,"mc":[{"id":"1.195453782","rc":[{"atl":[[140,0.03],[110,4]],"id":39307895}],"con":true,"img":false}]}
{"op":"mcm","clk":"5354067206","pt":1646221106059,"mc":[{"id":"1.195453782","rc":[{"atl":[[8,0]],"id":39594698}],"con":true,"img":false}]}
{"op":"mcm","clk":"5354068031","pt":1646221114591,"mc":[{"id":"1.195453782","rc":[{"atl":[[130,0]],"id":39307895}],"con":true,"img":false}]}
{"op":"mcm","clk":"5354068042","pt":1646221114696,"mc":[{"id":"1.195453782","rc":[{"atl":[[150,2.72]],"id":39307895}],"con":true,"img":false}]}
{"op":"mcm","clk":"5354069745","pt":1646221132715,"mc":[{"id":"1.195453782","rc":[{"atb":[[5.3,3.46]],"id":43167137},{"spn":5.24,"spf":1.0,"id":43167137},{"spn":9.6,"spf":1.0,"id":40879966},{"spn":29.2,"spf":1.0,"id":39307895},{"spn":5.4,"spf":"NaN","id":39594698}],"con":true,"img":false}]}
{"op":"mcm","clk":"5354070446","pt":1646221140207,"mc":[{"id":"1.195453782","rc":[{"atb":[[5.8,4.17],[6,20.57]],"id":41419892},{"atb":[[3.55,7.84],[3.65,38.82]],"id":39594698}],"con":true,"img":false}]}
{"op":"mcm","clk":"5354070886","pt":1646221144509,"mc":[{"id":"1.195453782","rc":[{"atl":[[8.2,0]],"id":39594698}],"con":true,"img":false}]}
{"op":"mcm","clk":"5354070899","pt":1646221144611,"mc":[{"id":"1.195453782","rc":[{"atl":[[7.4,16.59]],"id":39594698}],"con":true,"img":false}]}
{"op":"mcm","clk":"5354071449","pt":1646221150102,"mc":[{"id":"1.195453782","rc":[{"atb":[[5.6,0]],"id":41419892},{"atb":[[3.45,0]],"id":39594698}],"con":true,"img":false}]}
{"op":"mcm","clk":"5354071461","pt":1646221150205,"mc":[{"id":"1.195453782","rc":[{"atb":[[5.6,10.87]],"id":41419892},{"atb":[[3.45,20.41]],"id":39594698}],"con":true,"img":false}]}
{"op":"mcm","clk":"5354072364","pt":1646221160155,"mc":[{"id":"1.195453782","rc":[{"atb":[[5.4,39.78]],"id":41419892},{"atb":[[3.35,31.91]],"id":39594698}],"con":true,"img":false}]}
{"op":"mcm","clk":"5354073357","pt":1646221170132,"mc":[{"id":"1.195453782","rc":[{"atb":[[3.25,55.56]],"id":39594698}],"con":true,"img":false}]}
{"op":"mcm","clk":"5354073370","pt":1646221170242,"mc":[{"id":"1.195453782","rc":[{"atb":[[5.2,29.76]],"id":41419892}],"con":true,"img":false}]}
{"op":"mcm","clk":"5354074419","pt":1646221181550,"mc":[{"id":"1.195453782","rc":[{"atb":[[5.8,0],[6,24.57]],"id":41419892},{"atl":[[17.5,1.21]],"id":40879966},{"atb":[[2.92,10.42]],"id":41738000},{"atl":[[5.5,0],[5.7,4.26]],"id":42146659},{"atb":[[3.55,0],[3.65,46.37]],"id":39594698}],"con":true,"img":false}]}
{"op":"mcm","clk":"5354074427","pt":1646221181655,"mc":[{"id":"1.195453782","rc":[{"atl":[[17,0]],"id":40879966},{"atb":[[2.98,51.95],[2.94,0]],"id":41738000}],"con":true,"img":false}]}
{"op":"mcm","clk":"5354074583","pt":1646221183158,"mc":[{"id":"1.195453782","rc":[{"atl":[[5.7,7.13]],"id":42146659}],"con":true,"img":false}]}
{"op":"mcm","clk":"5354074594","pt":1646221183257,"mc":[{"id":"1.195453782","rc":[{"atl":[[5.7,28.41]],"id":42146659}],"con":true,"img":false}]}
{"op":"mcm","clk":"5354074602","pt":1646221183363,"mc":[{"id":"1.195453782","rc":[{"atl":[[5.9,15.31]],"id":42146659}],"con":true,"img":false}]}
{"op":"mcm","clk":"5354074643","pt":1646221183781,"mc":[{"id":"1.195453782","rc":[{"atl":[[12.5,1.74],[13,0]],"id":41419892}],"con":true,"img":false}]}
{"op":"mcm","clk":"5354074766","pt":1646221184876,"mc":[{"id":"1.195453782","rc":[{"atb":[[2.86,53.76],[3.15,0]],"id":43167137},{"atl":[[13.5,0],[14.5,0],[16,10.2]],"id":43167137},{"atb":[[3.3,8.7],[5.4,0],[5.6,0],[6,20.57],[5.2,0],[3.15,55.48]],"id":41419892},{"atb":[[3.6,0],[4.4,5.88],[4.2,31.25],[3.65,0]],"id":40879966},{"atl":[[17.5,0],[17,1.25]],"id":40879966},{"atb":[[21,0],[23,1]],"id":39307895},{"atb":[[2.98,62.05]],"id":41738000},{"atl":[[15,0],[16,0],[17,8.5],[18,7.06]],"id":41738000},{"atb":[[2.6,0],[2.84,54.35],[3.05,59.93],[2.42,50.7]],"id":42146659},{"atl":[[5.5,4.44]],"id":42146659},{"atb":[[3.55,7.84],[3.65,38.82]],"id":39594698}],"con":true,"img":false}]}
{"op":"mcm","clk":"5354074777","pt":1646221184980,"mc":[{"id":"1.195453782","rc":[{"atb":[[7.4,0]],"id":41419892},{"atl":[[18,5.88],[20,0]],"id":41419892},{"atb":[[1.84,0],[1.77,122.39]],"id":41738000},{"atb":[[2.92,10.42]],"id":42146659},{"atl":[[6.4,0],[6.6,3.57]],"id":39594698}],"con":true,"img":false}]}
{"op":"mcm","clk":"5354074932","pt":1646221186555,"mc":[{"id":"1.195453782","rc":[{"atl":[[5.7,25.54]],"id":42146659}],"con":true,"img":false}]}
{"op":"mcm","clk":"5354074949","pt":1646221186761,"mc":[{"id":"1.195453782","rc":[{"atl":[[15.5,0]],"id":43167137},{"atb":[[2.48,0],[2.56,0],[2.92,0],[2.52,0]],"id":42146659}],"con":true,"img":false}]}
{"op":"mcm","clk":"5354074958","pt":1646221186866,"mc":[{"id":"1.195453782","rc":[{"atb":[[3.05,50.17]],"id":42146659}],"con":true,"img":false}]}
{"op":"mcm","clk":"5354075099","pt":1646221188371,"mc":[{"id":"1.195453782","rc":[{"atl":[[5.9,35.72],[5.7,4.26]],"id":42146659}],"con":true,"img":false}]}
{"op":"mcm","clk":"5354075172","pt":1646221189163,"mc":[{"id":"1.195453782","rc":[{"atl":[[17,0]],"id":40879966},{"atb":[[2.98,51.95]],"id":41738000},{"atb":[[2.98,25.25],[2.94,38.66],[3.05,59.93],[2.9,65.79]],"id":42146659}],"con":true,"img":false}]}
{"op":"mcm","clk":"5354075183","pt":1646221189261,"mc":[{"id":"1.195453782","rc":[{"atl":[[17.5,1.21]],"id":40879966}],"con":true,"img":false}]}
{"op":"mcm","clk":"5354075268","pt":1646221190090,"mc":[{"id":"1.195453782","rc":[{"atb":[[2.72,58.14],[2.86,0]],"id":43167137}],"con":true,"img":false}]}
{"op":"mcm","clk":"5354075734","pt":1646221194900,"mc":[{"id":"1.195453782","rc":[{"atl":[[17,3.12]],"id":43167137},{"atl":[[13.5,4]],"id":41419892},{"spn":7.22,"spf":1.0,"id":41419892},{"atb":[[21,2.5]],"id":39307895},{"spn":29.24,"spf":1.0,"id":39307895},{"atb":[[2.88,81.31]],"id":41738000},{"atl":[[19,2.78]],"id":41738000},{"spn":5.5,"spf":"NaN","id":39594698}],"con":true,"img":false}]}
{"op":"mcm","clk":"5354075743","pt":1646221194955,"mc":[{"id":"1.195453782","rc":[{"atl":[[7,8.33]],"id":39594698}],"con":true,"img":false}]}
{"op":"mcm","clk":"5354075777","pt":1646221195273,"mc":[{"id":"1.195453782","rc":[{"atl":[[16.5,0]],"id":41419892},{"atb":[[17.5,0]],"id":39307895},{"atl":[[6.8,0],[7.2,9.42],[7.6,0]],"id":39594698}],"con":true,"img":false}]}
{"op":"mcm","clk":"5354076094","pt":1646221199172,"mc":[{"id":"1.195453782","rc":[{"atb":[[4.2,46.87]],"id":40879966},{"atl":[[18.5,2.86]],"id":40879966},{"atl":[[5.7,10.64]],"id":42146659}],"con":true,"img":false}]}
{"op":"mcm","clk":"5354076103","pt":1646221199275,"mc":[{"id":"1.195453782","rc":[{"atl":[[5.9,15.31],[5.7,31.92]],"id":42146659}],"con":true,"img":false}]}
{"op":"mcm","clk":"5354076225","pt":1646221200486,"mc":[{"id":"1.195453782","rc":[{"atb":[[3.35,0],[3.55,32.16],[3.45,0],[4.6,3]],"id":40879966},{"atl":[[17.5,0],[17,1.25],[18,0],[18.5,0],[19,2],[20,0]],"id":40879966},{"atb":[[2.98,62.05],[2.92,0]],"id":41738000},{"atl":[[18,9.06]],"id":41738000},{"atl":[[5,3]],"id":39594698}],"con":true,"img":false}]}
{"op":"mcm","clk":"5354076239","pt":1646221200693,"mc":[{"id":"1.195453782","rc":[{"atb":[[2.72,0],[2.86,53.76]],"id":43167137},{"atb":[[4.6,0]],"id":40879966},{"atb":[[36,2.1]],"id":39307895},{"atb":[[1.83,120.48],[1.77,0]],"id":41738000},{"atl":[[18,7.06]],"id":41738000},{"atb":[[2.98,0],[2.94,0],[3.05,50.17],[2.92,10.42]],"id":42146659},{"atl":[[4.8,4]],"id":42146659},{"atb":[[3.6,46.04],[3.7,37.04]],"id":39594698},{"atl":[[6.4,3.7],[4.9,3]],"id":39594698}],"con":true,"img":false}]}
{"op":"mcm","clk":"5354076368","pt":1646221202007,"mc":[{"id":"1.195453782","rc":[{"atb":[[4.6,4]],"id":40879966},{"atl":[[17,0],[17.5,1.21]],"id":40879966},{"atb":[[2.98,51.95],[2.92,10.42]],"id":41738000},{"atl":[[17,11.5]],"id":41738000},{"atl":[[4.7,3]],"id":42146659},{"atl":[[4.8,4]],"id":39594698}],"con":true,"img":false}]}
{"op":"mcm","clk":"5354076621","pt":1646221204589,"mc":[{"id":"1.195453782","rc":[{"atl":[[16,0]],"id":41419892},{"atl":[[19.5,0]],"id":40879966},{"atb":[[3.6,0]],"id":39594698},{"atl":[[7.4,0]],"id":39594698}],"con":true,"img":false}]}
{"op":"mcm","clk":"5354076633","pt":1646221204691,"mc":[{"id":"1.195453782","rc":[{"atl":[[17.5,6.73]],"id":41419892},{"atl":[[21,2.92]],"id":40879966},{"atb":[[3.5,46.04]],"id":39594698},{"atl":[[9,16.59]],"id":39594698}],"con":true,"img":false}]}
{"op":"mcm","clk":"5354076655","pt":1646221204884,"mc":[{"id":"1.195453782","rc":[{"atl":[[18,4.41]],"id":43167137},{"atl":[[14.5,5.56]],"id":41419892},{"atb":[[19.5,4.05]],"id":39307895}],"con":true,"img":false}]}
{"op":"mcm","clk":"5354077152","pt":1646221209780,"mc":[{"id":"1.195453782","rc":[{"atb":[[3.95,19.81]],"id":39594698}],"con":true,"img":false}]}
{"op":"mcm","clk":"5354077169","pt":1646221209985,"mc":[{"id":"1.195453782","rc":[{"atb":[[4.7,2]],"id":40879966},{"atl":[[16.5,2]],"id":41738000},{"atb":[[3.05,59.93]],"id":42146659},{"atl":[[4.8,0],[4.6,3],[4.7,0]],"id":42146659},{"atl":[[4.7,2]],"id":39594698}],"con":true,"img":false}]}
{"op":"mcm","clk":"5354077248","pt":1646221210711,"mc":[{"id":"1.195453782","rc":[{"atl":[[6.8,8.62]],"id":39594698}],"con":true,"img":false}]}
{"op":"mcm","clk":"5354077395","pt":1646221212023,"mc":[{"id":"1.195453782","rc":[{"atb":[[4,25]],"id":40879966},{"atl":[[18.5,2.86]],"id":40879966},{"atb":[[2.84,40.76]],"id":41738000},{"atl":[[20,3.95]],"id":41738000}],"con":true,"img":false}]}
{"op":"mcm","clk":"5354077700","pt":1646221214888,"mc":[{"id":"1.195453782","rc":[{"atl":[[19,6.94]],"id":43167137},{"atl":[[15.5,8.62]],"id":41419892},{"atb":[[18.5,13.02]],"id":39307895}],"con":true,"img":false}]}
{"op":"mcm","clk":"5354077719","pt":1646221215110,"mc":[{"id":"1.195453782","rc":[{"atl":[[16.5,0]],"id":43167137},{"atb":[[4.8,2]],"id":40879966},{"atb":[[2.9,0],[2.86,0]],"id":41738000},{"atl":[[16,4]],"id":41738000},{"atl":[[4.6,0]],"id":42146659}],"con":true,"img":false}]}
{"op":"mcm","clk":"5354077739","pt":1646221215309,"mc":[{"id":"1.195453782","rc":[{"atl":[[5.9,35.72],[5.7,10.64]],"id":42146659}],"con":true,"img":false}]}
{"op":"mcm","clk":"5354078230","pt":1646221220016,"mc":[{"id":"1.195453782","rc":[{"atb":[[2.98,25.25]],"id":42146659}],"con":true,"img":false}]}
{"op":"mcm","clk":"5354078250","pt":1646221220225,"mc":[{"id":"1.195453782","rc":[{"atb":[[4.9,4]],"id":40879966},{"atl":[[15.5,2]],"id":41738000},{"atb":[[2.98,0],[3.05,50.17]],"id":42146659}],"con":true,"img":false}]}
{"op":"mcm","clk":"5354078264","pt":1646221220330,"mc":[{"id":"1.195453782","rc":[{"atl":[[4.8,2]],"id":42146659}],"con":true,"img":false}]}
{"op":"mcm","clk":"5354078312","pt":1646221220710,"mc":[{"id":"1.195453782","rc":[{"atl":[[7.2,21.52]],"id":39594698}],"con":true,"img":false}]}
{"op":"mcm","clk":"5354078444","pt":1646221222001,"mc":[{"id":"1.195453782","rc":[{"atb":[[3.9,43.1]],"id":40879966},{"atl":[[19.5,4.05]],"id":40879966},{"atb":[[2.8,69.44]],"id":41738000},{"atl":[[22,5.95]],"id":41738000}],"con":true,"img":false}]}
{"op":"mcm","clk":"5354079262","pt":1646221230006,"mc":[{"id":"1.195453782","rc":[{"atb":[[2.88,26.6]],"id":42146659}],"con":true,"img":false}]}
{"op":"mcm","clk":"5354079290","pt":1646221230212,"mc":[{"id":"1.195453782","rc":[{"atb":[[3.05,59.93]],"id":42146659},{"atl":[[4.8,0],[5.9,15.31],[5.7,31.92],[4.7,2]],"id":42146659},{"atl":[[6.6,0],[7,0]],"id":39594698}],"con":true,"img":false}]}
{"op":"mcm","clk":"5354079344","pt":1646221230738,"mc":[{"id":"1.195453782","rc":[{"atl":[[7.6,18.94]],"id":39594698}],"con":true,"img":false}]}
{"op":"mcm","clk":"5354079494","pt":1646221232011,"mc":[{"id":"1.195453782","rc":[{"atl":[[21,9.17]],"id":40879966}],"con":true,"img":false}]}
{"op":"mcm","clk":"5354079766","pt":1646221234506,"mc":[{"id":"1.195453782","rc":[{"atl":[[15,0]],"id":41419892},{"atl":[[7.2,12.1]],"id":39594698}],"con":true,"img":false}]}
{"op":"mcm","clk":"5354079774","pt":1646221234611,"mc":[{"id":"1.195453782","rc":[{"atl":[[14,4.03]],"id":41419892},{"atl":[[6.6,9.42]],"id":39594698}],"con":true,"img":false}]}
{"op":"mcm","clk":"5354080473","pt":1646221240221,"mc":[{"id":"1.195453782","rc":[{"atb":[[2.98,25.25]],"id":42146659},{"atl":[[4.7,0]],"id":42146659}],"con":true,"img":false}]}
{"op":"mcm","clk":"5354080483","pt":1646221240325,"mc":[{"id":"1.195453782","rc":[{"atl":[[5.9,35.72]],"id":42146659}],"con":true,"img":false}]}
{"op":"mcm","clk":"5354080498","pt":1646221240427,"mc":[{"id":"1.195453782","rc":[{"atb":[[2.98,0],[3.05,50.17],[2.92,0],[2.88,0]],"id":42146659},{"atl":[[5.7,10.64]],"id":42146659}],"con":true,"img":false}]}
{"op":"mcm","clk":"5354080508","pt":1646221240529,"mc":[{"id":"1.195453782","rc":[{"atl":[[4.8,2]],"id":42146659}],"con":true,"img":false}]}
{"op":"mcm","clk":"5354080853","pt":1646221243940,"mc":[{"id":"1.195453782","rc":[{"atb":[[4.8,0],[4.9,0],[4.6,0],[4.7,0]],"id":40879966},{"atl":[[17.5,0],[17,1.25]],"id":40879966},{"atb":[[2.98,62.05]],"id":41738000},{"atl":[[15.5,0],[16,0],[16.5,0],[17,8.5]],"id":41738000},{"atb":[[2.92,10.42]],"id":42146659},{"atl":[[4.7,2]],"id":42146659}],"con":true,"img":false}]}
{"op":"mcm","clk":"5354080859","pt":1646221244043,"mc":[{"id":"1.195453782","rc":[{"atb":[[2.92,0]],"id":41738000}],"con":true,"img":false}]}
{"op":"mcm","clk":"5354081274","pt":1646221247731,"mc":[{"id":"1.195453782","rc":[{"atb":[[1.01,2]],"id":42146659}],"con":true,"img":false}]}
{"op":"mcm","clk":"5354081288","pt":1646221247831,"mc":[{"id":"1.195453782","rc":[{"atb":[[1.01,3.99]],"id":42146659}],"con":true,"img":false}]}
{"op":"mcm","clk":"5354081305","pt":1646221247950,"mc":[{"id":"1.195453782","rc":[{"atb":[[1.01,2],[3.05,59.93]],"id":42146659},{"atl":[[4.8,0],[4.6,3],[4.7,0]],"id":42146659}],"con":true,"img":false}]}
{"op":"mcm","clk":"5354081326","pt":1646221248042,"mc":[{"id":"1.195453782","rc":[{"atb":[[4,1.99]],"id":42146659}],"con":true,"img":false}]}
{"op":"mcm","clk":"5354081629","pt":1646221251229,"mc":[{"id":"1.195453782","rc":[{"atb":[[1.01,2]],"id":39594698}],"con":true,"img":false}]}
{"op":"mcm","clk":"5354081648","pt":1646221251443,"mc":[{"id":"1.195453782","rc":[{"atb":[[1.01,3.99]],"id":39594698}],"con":true,"img":false}]}
{"op":"mcm","clk":"5354081676","pt":1646221251757,"mc":[{"id":"1.195453782","rc":[{"atb":[[1.01,2]],"id":39594698}],"con":true,"img":false}]}
{"op":"mcm","clk":"5354081687","pt":1646221251861,"mc":[{"id":"1.195453782","rc":[{"atb":[[4.1,1.99]],"id":39594698}],"con":true,"img":false}]}
{"op":"mcm","clk":"5354081741","pt":1646221252438,"mc":[{"id":"1.195453782","rc":[{"atb":[[4,0]],"id":39594698}],"con":true,"img":false}]}
{"op":"mcm","clk":"5354081758","pt":1646221252642,"mc":[{"id":"1.195453782","rc":[{"atb":[[1.01,2]],"id":43167137}],"con":true,"img":false}]}
{"op":"mcm","clk":"5354081891","pt":1646221253951,"mc":[{"id":"1.195453782","rc":[{"atb":[[2.94,25.77]],"id":41738000}],"con":true,"img":false}]}
{"op":"mcm","clk":"5354081919","pt":1646221254162,"mc":[{"id":"1.195453782","rc":[{"atb":[[2.8,0],[2.84,0],[2.88,54.71]],"id":41738000},{"atl":[[4.6,0]],"id":42146659}],"con":true,"img":false}]}
{"op":"mcm","clk":"5354081943","pt":1646221254331,"mc":[{"id":"1.195453782","rc":[{"atl":[[5.9,15.31],[5.7,31.92]],"id":42146659}],"con":true,"img":false}]}
{"op":"mcm","clk":"5354081964","pt":1646221254543,"mc":[{"id":"1.195453782","rc":[{"atl":[[21,6.25]],"id":40879966},{"atl":[[5.9,35.72],[5.7,10.64]],"id":42146659},{"atl":[[6.6,0]],"id":39594698}],"con":true,"img":false}]}
{"op":"mcm","clk":"5354081975","pt":1646221254646,"mc":[{"id":"1.195453782","rc":[{"atl":[[19,4.92]],"id":40879966},{"atl":[[7,9.42]],"id":39594698}],"con":true,"img":false}]}
{"op":"mcm","clk":"5354082325","pt":1646221257941,"mc":[{"id":"1.195453782","rc":[{"atb":[[1.01,3.99]],"id":43167137},{"spn":31.09,"spf":1.0,"id":39307895},{"atb":[[2.98,25.25]],"id":42146659},{"spn":4.55,"spf":"NaN","id":39594698}],"con":true,"img":false}]}
{"op":"mcm","clk":"5354082356","pt":1646221258262,"mc":[{"id":"1.195453782","rc":[{"atb":[[1.01,2]],"id":43167137}],"con":true,"img":false}]}
{"op":"mcm","clk":"5354082367","pt":1646221258358,"mc":[{"id":"1.195453782","rc":[{"atb":[[5.4,1.99]],"id":43167137}],"con":true,"img":false}]}
{"op":"mcm","clk":"5354082438","pt":1646221259257,"mc":[{"id":"1.195453782","rc":[{"atb":[[1.01,2]],"id":40879966}],"con":true,"img":false}]}
{"op":"mcm","clk":"5354082455","pt":1646221259470,"mc":[{"id":"1.195453782","rc":[{"atb":[[3.75,0],[4,0],[4.5,5.71],[5,0]],"id":43167137},{"atl":[[16,1.33],[18.5,0],[22,0],[27,0]],"id":43167137},{"atb":[[5,0],[5.5,0],[6,0],[7,0]],"id":41419892},{"atl":[[38,0],[19.5,0],[24,0],[29,0]],"id":41419892},{"atb":[[1.01,3.99],[9.6,0],[8.6,0],[7.6,0],[6.6,0]],"id":40879966},{"atl":[[130,0],[46,0],[65,0],[90,0]],"id":40879966},{"atb":[[34,0],[18.5,7.14],[22,0.13],[27,0]],"id":39307895},{"atl":[[300,0],[350,0],[400,0],[250,0]],"id":39307895},{"atb":[[2.98,10.1],[3.2,0],[2.88,0],[2.78,0]],"id":41738000},{"atl":[[9.2,0],[10.5,0],[8.2,0],[13,0]],"id":41738000},{"atb":[[3.8,0],[3.55,0],[2.98,0],[3.3,0],[3.05,0]],"id":42146659},{"atl":[[4.8,2],[12,0],[14.5,0],[17,0],[9.8,0]],"id":42146659},{"atb":[[3.4,0],[3.15,0],[3.9,2],[3.65,0]],"id":39594698},{"atl":[[10.5,0],[13,0],[15.5,0],[18,0]],"id":39594698}],"con":true,"img":false}]}
{"op":"mcm","clk":"5354082472","pt":1646221259677,"mc":[{"id":"1.195453782","rc":[{"atb":[[36,0.1],[29,2]],"id":39307895}],"con":true,"img":false}]}
{"op":"mcm","clk":"5354082494","pt":1646221259845,"mc":[{"id":"1.195453782","rc":[{"atb":[[5.3,0]],"id":43167137}],"con":true,"img":false}]}
{"op":"mcm","clk":"5354082584","pt":1646221260842,"mc":[{"id":"1.195453782","rc":[{"atb":[[1.03,2.93]],"id":43167137},{"atb":[[1.02,3.01]],"id":42146659},{"atb":[[1.02,2.99]],"id":39594698}],"con":true,"img":false}]}
{"op":"mcm","clk":"5354082633","pt":1646221261256,"mc":[{"id":"1.195453782","rc":[{"atb":[[1.03,0.2]],"id":43167137},{"atb":[[1.02,0.26]],"id":39594698}],"con":true,"img":false}]}
{"op":"mcm","clk":"5354082648","pt":1646221261387,"mc":[{"id":"1.195453782","rc":[{"atb":[[1.02,3.04]],"id":41738000},{"atb":[[1.02,0.29]],"id":42146659}],"con":true,"img":false}]}
{"op":"mcm","clk":"5354082696","pt":1646221261772,"mc":[{"id":"1.195453782","rc":[{"atb":[[1.03,0]],"id":43167137},{"atb":[[1.02,0]],"id":39594698}],"con":true,"img":false}]}
{"op":"mcm","clk":"5354082707","pt":1646221261879,"mc":[{"id":"1.195453782","rc":[{"atb":[[5.2,1.99]],"id":43167137},{"atb":[[1.02,0.32]],"id":41738000},{"atb":[[1.02,0]],"id":42146659},{"atb":[[4,0.26]],"id":39594698}],"con":true,"img":false}]}
{"op":"mcm","clk":"5354082718","pt":1646221261944,"mc":[{"id":"1.195453782","rc":[{"atb":[[3.65,0.29]],"id":42146659}],"con":true,"img":false}]}
{"op":"mcm","clk":"5354082760","pt":1646221262352,"mc":[{"id":"1.195453782","rc":[{"atb":[[1.02,0]],"id":41738000}],"con":true,"img":false}]}
{"op":"mcm","clk":"5354082768","pt":1646221262459,"mc":[{"id":"1.195453782","rc":[{"atb":[[3.3,7.21]],"id":41738000}],"con":true,"img":false}]}
{"op":"mcm","clk":"5354082791","pt":1646221262674,"mc":[{"id":"1.195453782","rc":[{"atb":[[3.75,37.41],[4,34.29],[4.5,35.1],[5,25.71]],"id":43167137},{"atl":[[16,10.2],[18.5,7.61],[22,9.51],[27,7.68]],"id":43167137},{"atb":[[5,25.71],[5.5,22.85],[6,20.57],[7,17.14]],"id":41419892},{"atl":[[38,5.4],[19.5,7.19],[24,5.79],[29,7.13]],"id":41419892},{"atb":[[9.6,11.96],[8.6,13.53],[7.6,15.58],[6.6,18.37]],"id":40879966},{"atl":[[130,1.54],[46,2.95],[65,2.08],[90,2.24]],"id":40879966},{"atb":[[34,3.11],[18.5,13.02],[22,5.03],[27,3.95]],"id":39307895},{"atl":[[300,0.44],[350,0.57],[400,0.5],[250,0.53]],"id":39307895},{"atb":[[2.98,62.05],[3.2,46.76],[2.88,54.71],[2.78,57.79]],"id":41738000},{"atl":[[9.2,16.24],[10.5,21.03],[8.2,18.49],[13,16.65]],"id":41738000},{"atb":[[3.8,36.73],[3.55,40.34],[3.3,44.72],[3.05,50.17]],"id":42146659},{"atl":[[12,12.11],[14.5,14.8],[17,12.48],[9.8,15.13]],"id":42146659},{"atb":[[3.4,42.86],[3.15,47.84],[3.9,37.47],[3.65,38.82]],"id":39594698},{"atl":[[10.5,14.02],[13,11.1],[15.5,13.77],[18,11.75]],"id":39594698}],"con":true,"img":false}]}
{"op":"mcm","clk":"5354082815","pt":1646221262837,"mc":[{"id":"1.195453782","rc":[{"atb":[[36,2.1]],"id":39307895}],"con":true,"img":false}]}
{"op":"mcm","clk":"5354082821","pt":1646221262949,"mc":[{"id":"1.195453782","rc":[{"atb":[[29,0]],"id":39307895}],"con":true,"img":false}]}
{"op":"mcm","clk":"5354082864","pt":1646221263358,"mc":[{"id":"1.195453782","rc":[{"atb":[[5.2,7.65]],"id":43167137}],"con":true,"img":false}]}
{"op":"mcm","clk":"5354082918","pt":1646221263982,"mc":[{"id":"1.195453782","rc":[{"atb":[[2.9,39.47]],"id":41738000}],"con":true,"img":false}]}
{"op":"mcm","clk":"5354082999","pt":1646221264873,"mc":[{"id":"1.195453782","rc":[{"atb":[[1.01,2]],"id":40879966}],"con":true,"img":false}]}
{"op":"mcm","clk":"5354083011","pt":1646221264975,"mc":[{"id":"1.195453782","rc":[{"atb":[[1.02,1.99]],"id":40879966}],"con":true,"img":false}]}
{"op":"mcm","clk":"5354083038","pt":1646221265197,"mc":[{"id":"1.195453782","rc":[{"atb":[[3.05,59.93]],"id":42146659},{"atl":[[5.9,15.31],[5.7,31.92],[4.7,4]],"id":42146659}],"con":true,"img":false}]}
{"op":"mcm","clk":"5354083058","pt":1646221265397,"mc":[{"id":"1.195453782","rc":[{"atb":[[1.01,2]],"id":41419892},{"atl":[[4.8,0]],"id":42146659}],"con":true,"img":false}]}
{"op":"mcm","clk":"5354083077","pt":1646221265552,"mc":[{"id":"1.195453782","rc":[{"atb":[[1.01,3.99]],"id":41419892}],"con":true,"img":false}]}
{"op":"mcm","clk":"5354083096","pt":1646221265815,"mc":[{"id":"1.195453782","rc":[{"atb":[[1.01,2]],"id":41419892}],"con":true,"img":false}]}
{"op":"mcm","clk":"5354083105","pt":1646221265868,"mc":[{"id":"1.195453782","rc":[{"atb":[[1.02,1.99]],"id":41419892}],"con":true,"img":false}]}
{"op":"mcm","clk":"5354083195","pt":1646221266871,"mc":[{"id":"1.195453782","rc":[{"atb":[[1.01,2]],"id":41738000}],"con":true,"img":false}]}
{"op":"mcm","clk":"5354083212","pt":1646221267071,"mc":[{"id":"1.195453782","rc":[{"atb":[[1.01,3.99]],"id":41738000}],"con":true,"img":false}]}
{"op":"mcm","clk":"5354083234","pt":1646221267283,"mc":[{"id":"1.195453782","rc":[{"atb":[[1.01,2]],"id":41738000}],"con":true,"img":false}]}
{"op":"mcm","clk":"5354083240","pt":1646221267345,"mc":[{"id":"1.195453782","rc":[{"atb":[[1.02,1.99]],"id":41738000}],"con":true,"img":false}]}
{"op":"mcm","clk":"5354083399","pt":1646221268862,"mc":[{"id":"1.195453782","rc":[{"atb":[[1.02,0]],"id":41738000}],"con":true,"img":false}]}
{"op":"mcm","clk":"5354083412","pt":1646221268962,"mc":[{"id":"1.195453782","rc":[{"atl":[[1000,1.66]],"id":39307895},{"atb":[[3.45,1.99]],"id":41738000}],"con":true,"img":false}]}
{"op":"mcm","clk":"5354083435","pt":1646221269175,"mc":[{"id":"1.195453782","rc":[{"atl":[[1000,0.09]],"id":39307895}],"con":true,"img":false}]}
{"op":"mcm","clk":"5354083458","pt":1646221269386,"mc":[{"id":"1.195453782","rc":[{"atl":[[1000,0]],"id":39307895}],"con":true,"img":false}]}
{"op":"mcm","clk":"5354083473","pt":1646221269490,"mc":[{"id":"1.195453782","rc":[{"atl":[[95,0.09]],"id":39307895}],"con":true,"img":false}]}
{"op":"mcm","clk":"5354083974","pt":1646221273997,"mc":[{"id":"1.195453782","rc":[{"atb":[[2.86,67.2]],"id":41738000}],"con":true,"img":false}]}
{"op":"mcm","clk":"5354084015","pt":1646221274318,"mc":[{"id":"1.195453782","rc":[{"atl":[[4.7,0]],"id":42146659}],"con":true,"img":false}]}
{"op":"mcm","clk":"5354084035","pt":1646221274475,"mc":[{"id":"1.195453782","rc":[{"atl":[[5.9,35.72],[5.7,10.64]],"id":42146659}],"con":true,"img":false}]}
{"op":"mcm","clk":"5354084049","pt":1646221274675,"mc":[{"id":"1.195453782","rc":[{"atl":[[9,0]],"id":39594698}],"con":true,"img":false}]}
{"op":"mcm","clk":"5354084060","pt":1646221274779,"mc":[{"id":"1.195453782","rc":[{"atl":[[7.4,16.59]],"id":39594698}],"con":true,"img":false}]}
{"op":"mcm","clk":"5354084098","pt":1646221275196,"mc":[{"id":"1.195453782","rc":[{"atb":[[2.98,25.25]],"id":42146659}],"con":true,"img":false}]}
{"op":"mcm","clk":"5354085081","pt":1646221285114,"mc":[{"id":"1.195453782","rc":[{"atb":[[2.94,38.66]],"id":42146659}],"con":true,"img":false}]}
{"op":"mcm","clk":"5354085110","pt":1646221285286,"mc":[{"id":"1.195453782","rc":[{"atl":[[4.8,3]],"id":42146659}],"con":true,"img":false}]}
{"op":"mcm","clk":"5354085125","pt":1646221285384,"mc":[{"id":"1.195453782","rc":[{"atb":[[2.98,0],[2.94,0],[3.05,50.17],[2.92,0]],"id":42146659},{"atl":[[5.8,20.83],[5.9,15.31]],"id":42146659}],"con":true,"img":false}]}
{"op":"mcm","clk":"5354086217","pt":1646221295110,"mc":[{"id":"1.195453782","rc":[{"atb":[[2.92,10.42]],"id":42146659}],"con":true,"img":false}]}
{"op":"mcm","clk":"5354086253","pt":1646221295426,"mc":[{"id":"1.195453782","rc":[{"atb":[[3.05,59.93]],"id":42146659},{"atl":[[4.8,0],[4.7,2]],"id":42146659}],"con":true,"img":false}]}
{"op":"mcm","clk":"5354086266","pt":1646221295518,"mc":[{"id":"1.195453782","rc":[{"atl":[[5.7,25.95]],"id":42146659}],"con":true,"img":false}]}
{"op":"mcm","clk":"5354086280","pt":1646221295587,"mc":[{"id":"1.195453782","rc":[{"atl":[[5.8,0]],"id":42146659}],"con":true,"img":false}]}
{"op":"mcm","clk":"5354086690","pt":1646221298997,"mc":[{"id":"1.195453782","rc":[{"atb":[[1.01,3.66]],"id":43167137},{"atb":[[1.01,3.66]],"id":40879966},{"atb":[[1.04,1.66]],"id":39307895}],"con":true,"img":false}]}
{"op":"mcm","clk":"5354086710","pt":1646221299204,"mc":[{"id":"1.195453782","rc":[{"atb":[[1.01,3.45]],"id":43167137},{"atb":[[1.01,2.83]],"id":40879966}],"con":true,"img":false}]}
{"op":"mcm","clk":"5354086725","pt":1646221299412,"mc":[{"id":"1.195453782","rc":[{"atb":[[1.01,2]],"id":43167137},{"atb":[[1.04,0.21]],"id":39307895}],"con":true,"img":false}]}
{"op":"mcm","clk":"5354086735","pt":1646221299517,"mc":[{"id":"1.195453782","rc":[{"atb":[[5.7,1.45]],"id":43167137}],"con":true,"img":false}]}
{"op":"mcm","clk":"5354086748","pt":1646221299622,"mc":[{"id":"1.195453782","rc":[{"atb":[[1.01,2]],"id":40879966}],"con":true,"img":false}]}
{"op":"mcm","clk":"5354086756","pt":1646221299724,"mc":[{"id":"1.195453782","rc":[{"atb":[[10,0.83]],"id":40879966}],"con":true,"img":false}]}
{"op":"mcm","clk":"5354086769","pt":1646221299830,"mc":[{"id":"1.195453782","rc":[{"atb":[[1.04,0]],"id":39307895}],"con":true,"img":false}]}
{"op":"mcm","clk":"5354086780","pt":1646221299903,"mc":[{"id":"1.195453782","rc":[{"atb":[[38,0.21]],"id":39307895}],"con":true,"img":false}]}
{"op":"mcm","clk":"5354086838","pt":1646221300403,"mc":[{"id":"1.195453782","rc":[{"atb":[[1.01,3.66],[5.7,0]],"id":43167137},{"atb":[[10,0]],"id":40879966}],"con":true,"img":false}]}
{"op":"mcm","clk":"5354086853","pt":1646221300509,"mc":[{"id":"1.195453782","rc":[{"atb":[[1.01,3.66]],"id":40879966}],"con":true,"img":false}]}
{"op":"mcm","clk":"5354086863","pt":1646221300612,"mc":[{"id":"1.195453782","rc":[{"atl":[[4.7,0]],"id":42146659}],"con":true,"img":false}]}
{"op":"mcm","clk":"5354086876","pt":1646221300716,"mc":[{"id":"1.195453782","rc":[{"atb":[[1.01,3.45]],"id":43167137}],"con":true,"img":false}]}
{"op":"mcm","clk":"5354086888","pt":1646221300820,"mc":[{"id":"1.195453782","rc":[{"atb":[[1.01,2.83]],"id":40879966},{"atl":[[5.9,35.72],[5.7,10.64]],"id":42146659}],"con":true,"img":false}]}
{"op":"mcm","clk":"5354086898","pt":1646221300924,"mc":[{"id":"1.195453782","rc":[{"atb":[[1.01,2]],"id":43167137}],"con":true,"img":false}]}
{"op":"mcm","clk":"5354086909","pt":1646221301029,"mc":[{"id":"1.195453782","rc":[{"atb":[[5.5,1.45]],"id":43167137}],"con":true,"img":false}]}
{"op":"mcm","clk":"5354086931","pt":1646221301191,"mc":[{"id":"1.195453782","rc":[{"atb":[[1.01,2]],"id":40879966}],"con":true,"img":false}]}
{"op":"mcm","clk":"5354086942","pt":1646221301295,"mc":[{"id":"1.195453782","rc":[{"atb":[[9.8,1.13]],"id":40879966}],"con":true,"img":false}]}
{"op":"mcm","clk":"5354086984","pt":1646221301716,"mc":[{"id":"1.195453782","rc":[{"atb":[[1.01,3.66],[5.5,0]],"id":43167137}],"con":true,"img":false}]}
{"op":"mcm","clk":"5354087003","pt":1646221301918,"mc":[{"id":"1.195453782","rc":[{"atb":[[1.01,3.45]],"id":43167137}],"con":true,"img":false}]}
{"op":"mcm","clk":"5354087025","pt":1646221302126,"mc":[{"id":"1.195453782","rc":[{"atb":[[1.01,2]],"id":43167137}],"con":true,"img":false}]}
{"op":"mcm","clk":"5354087036","pt":1646221302231,"mc":[{"id":"1.195453782","rc":[{"atb":[[5.7,1.45]],"id":43167137}],"con":true,"img":false}]}
{"op":"mcm","clk":"5354087346","pt":1646221305415,"mc":[{"id":"1.195453782","rc":[{"atb":[[2.98,25.25]],"id":42146659}],"con":true,"img":false}]}
{"op":"mcm","clk":"5354087366","pt":1646221305620,"mc":[{"id":"1.195453782","rc":[{"atl":[[4.8,4]],"id":42146659}],"con":true,"img":false}]}
{"op":"mcm","clk":"5354087377","pt":1646221305724,"mc":[{"id":"1.195453782","rc":[{"atb":[[2.98,0],[3.05,50.17]],"id":42146659},{"atl":[[5.8,20.83],[5.9,15.31]],"id":42146659}],"con":true,"img":false}]}
{"op":"mcm","clk":"5354088361","pt":1646221315443,"mc":[{"id":"1.195453782","rc":[{"atb":[[2.88,26.6]],"id":42146659}],"con":true,"img":false}]}
{"op":"mcm","clk":"5354088382","pt":1646221315609,"mc":[{"id":"1.195453782","rc":[{"atb":[[3.05,59.93]],"id":42146659},{"atl":[[4.7,4]],"id":42146659}],"con":true,"img":false}]}
{"op":"mcm","clk":"5354088393","pt":1646221315718,"mc":[{"id":"1.195453782","rc":[{"atb":[[1.01,3.66]],"id":43167137},{"atl":[[4.8,0]],"id":42146659}],"con":true,"img":false}]}
{"op":"mcm","clk":"5354088404","pt":1646221315816,"mc":[{"id":"1.195453782","rc":[{"atb":[[5.7,0]],"id":43167137}],"con":true,"img":false}]}
{"op":"mcm","clk":"5354088414","pt":1646221315922,"mc":[{"id":"1.195453782","rc":[{"atb":[[1.01,3.45]],"id":43167137}],"con":true,"img":false}]}
{"op":"mcm","clk":"5354088432","pt":1646221316129,"mc":[{"id":"1.195453782","rc":[{"atb":[[1.01,2]],"id":43167137}],"con":true,"img":false}]}
{"op":"mcm","clk":"5354088443","pt":1646221316233,"mc":[{"id":"1.195453782","rc":[{"atb":[[5.5,1.45]],"id":43167137}],"con":true,"img":false}]}
{"op":"mcm","clk":"5354088480","pt":1646221316654,"mc":[{"id":"1.195453782","rc":[{"atb":[[1.01,3.66]],"id":43167137}],"con":true,"img":false}]}
{"op":"mcm","clk":"5354088494","pt":1646221316719,"mc":[{"id":"1.195453782","rc":[{"atb":[[1.01,3.45],[5.5,0]],"id":43167137}],"con":true,"img":false}]}
{"op":"mcm","clk":"5354088517","pt":1646221316923,"mc":[{"id":"1.195453782","rc":[{"atb":[[1.01,2]],"id":43167137}],"con":true,"img":false}]}
{"op":"mcm","clk":"5354088527","pt":1646221317021,"mc":[{"id":"1.195453782","rc":[{"atb":[[5.7,1.45]],"id":43167137}],"con":true,"img":false}]}
{"op":"mcm","clk":"5354089410","pt":1646221324947,"mc":[{"id":"1.195453782","rc":[{"spn":5.36,"spf":1.0,"id":43167137},{"spn":9.62,"spf":1.0,"id":40879966},{"spl":[[1.01,13.45]],"id":39307895},{"spn":30.15,"spf":1.0,"id":39307895},{"spn":4.45,"spf":"NaN","id":42146659}],"con":true,"img":false}]}
{"op":"mcm","clk":"5354089474","pt":1646221325629,"mc":[{"id":"1.195453782","rc":[{"atb":[[2.98,25.25]],"id":42146659},{"atl":[[4.7,0]],"id":42146659}],"con":true,"img":false}]}
{"op":"mcm","clk":"5354089485","pt":1646221325733,"mc":[{"id":"1.195453782","rc":[{"atb":[[1.01,3.66],[5.7,0]],"id":43167137}],"con":true,"img":false}]}
{"op":"mcm","clk":"5354089496","pt":1646221325835,"mc":[{"id":"1.195453782","rc":[{"atb":[[2.92,0],[2.88,0]],"id":42146659},{"atl":[[4.8,2]],"id":42146659}],"con":true,"img":false}]}
{"op":"mcm","clk":"5354089510","pt":1646221325944,"mc":[{"id":"1.195453782","rc":[{"atb":[[1.01,3.45]],"id":43167137},{"atb":[[2.98,0],[3.05,50.17]],"id":42146659}],"con":true,"img":false}]}
{"op":"mcm","clk":"5354089528","pt":1646221326150,"mc":[{"id":"1.195453782","rc":[{"atb":[[1.01,2]],"id":43167137}],"con":true,"img":false}]}
{"op":"mcm","clk":"5354089538","pt":1646221326254,"mc":[{"id":"1.195453782","rc":[{"atb":[[5.5,1.45]],"id":43167137}],"con":true,"img":false}]}
{"op":"mcm","clk":"5354089564","pt":1646221326416,"mc":[{"id":"1.195453782","rc":[{"atb":[[1.01,3.66]],"id":43167137}],"con":true,"img":false}]}
{"op":"mcm","clk":"5354089583","pt":1646221326627,"mc":[{"id":"1.195453782","rc":[{"atb":[[1.01,3.45],[5.5,0]],"id":43167137}],"con":true,"img":false}]}
{"op":"mcm","clk":"5354089598","pt":1646221326731,"mc":[{"id":"1.195453782","rc":[{"atb":[[1.01,2]],"id":43167137}],"con":true,"img":false}]}
{"op":"mcm","clk":"5354089608","pt":1646221326835,"mc":[{"id":"1.195453782","rc":[{"atb":[[5.7,1.45]],"id":43167137}],"con":true,"img":false}]}
{"op":"mcm","clk":"5354090396","pt":1646221334549,"mc":[{"id":"1.195453782","rc":[{"atl":[[7,0]],"id":39594698}],"con":true,"img":false}]}
{"op":"mcm","clk":"5354090408","pt":1646221334648,"mc":[{"id":"1.195453782","rc":[{"atl":[[6.6,9.42]],"id":39594698}],"con":true,"img":false}]}
{"op":"mcm","clk":"5354090431","pt":1646221334858,"mc":[{"id":"1.195453782","rc":[{"atb":[[3.05,59.93],[2.92,10.42]],"id":42146659},{"atl":[[4.8,0],[4.7,4]],"id":42146659}],"con":true,"img":false}]}
{"op":"mcm","clk":"5354090447","pt":1646221334963,"mc":[{"id":"1.195453782","rc":[{"atl":[[5.8,0],[5.7,25.95]],"id":42146659}],"con":true,"img":false}]}
{"op":"mcm","clk":"5354091417","pt":1646221344881,"mc":[{"id":"1.195453782","rc":[{"atb":[[2.98,25.25]],"id":42146659}],"con":true,"img":false}]}
{"op":"mcm","clk":"5354091426","pt":1646221344988,"mc":[{"id":"1.195453782","rc":[{"atl":[[4.7,0]],"id":42146659}],"con":true,"img":false}]}
{"op":"mcm","clk":"5354091452","pt":1646221345148,"mc":[{"id":"1.195453782","rc":[{"atl":[[5.9,35.72],[5.7,10.64]],"id":42146659}],"con":true,"img":false}]}
{"op":"mcm","clk":"5354092404","pt":1646221354567,"mc":[{"id":"1.195453782","rc":[{"atl":[[6.6,0]],"id":39594698}],"con":true,"img":false}]}
{"op":"mcm","clk":"5354092418","pt":1646221354672,"mc":[{"id":"1.195453782","rc":[{"atl":[[7,9.42]],"id":39594698}],"con":true,"img":false}]}
{"op":"mcm","clk":"5354092444","pt":1646221354878,"mc":[{"id":"1.195453782","rc":[{"atb":[[2.94,38.66]],"id":42146659}],"con":true,"img":false}]}
{"op":"mcm","clk":"5354092456","pt":1646221354980,"mc":[{"id":"1.195453782","rc":[{"atb":[[2.98,0],[3.05,50.17]],"id":42146659},{"atl":[[4.8,2]],"id":42146659}],"con":true,"img":false}]}
{"op":"mcm","clk":"5354092468","pt":1646221355086,"mc":[{"id":"1.195453782","rc":[{"atl":[[5.8,20.83],[5.9,15.31]],"id":42146659}],"con":true,"img":false}]}
{"op":"mcm","clk":"5354093010","pt":1646221360686,"mc":[{"id":"1.195453782","rc":[{"atb":[[2.94,0]],"id":42146659},{"atl":[[4.7,4]],"id":42146659}],"con":true,"img":false}]}
{"op":"mcm","clk":"5354093027","pt":1646221360893,"mc":[{"id":"1.195453782","rc":[{"atl":[[4.6,2]],"id":42146659}],"con":true,"img":false}]}
{"op":"mcm","clk":"5354093036","pt":1646221361000,"mc":[{"id":"1.195453782","rc":[{"atb":[[3.05,59.93]],"id":42146659},{"atl":[[4.8,0],[4.7,0]],"id":42146659}],"con":true,"img":false}]}
{"op":"mcm","clk":"5354093051","pt":1646221361062,"mc":[{"id":"1.195453782","rc":[{"atl":[[6.4,0],[6.2,3.85]],"id":39594698}],"con":true,"img":false}]}
{"op":"mcm","clk":"5354093063","pt":1646221361167,"mc":[{"id":"1.195453782","rc":[{"atl":[[4.6,0]],"id":42146659}],"con":true,"img":false}]}
{"op":"mcm","clk":"5354093070","pt":1646221361275,"mc":[{"id":"1.195453782","rc":[{"atb":[[4.6,3]],"id":40879966},{"atl":[[17,0],[17.5,1.21]],"id":40879966}],"con":true,"img":false}]}
{"op":"mcm","clk":"5354093454","pt":1646221364981,"mc":[{"id":"1.195453782","rc":[{"atb":[[3.35,4]],"id":41419892},{"atl":[[12.5,0]],"id":41419892},{"atb":[[4.7,2]],"id":40879966},{"atb":[[2.98,51.95],[2.94,0],[2.92,10.42]],"id":41738000},{"atl":[[17,11.5]],"id":41738000},{"atl":[[5.5,0],[5.7,4.26]],"id":42146659}],"con":true,"img":false}]}
{"op":"mcm","clk":"5354093465","pt":1646221365086,"mc":[{"id":"1.195453782","rc":[{"atl":[[13,1.67]],"id":41419892},{"atb":[[3.05,61.93]],"id":42146659}],"con":true,"img":false}]}
{"op":"mcm","clk":"5354093479","pt":1646221365190,"mc":[{"id":"1.195453782","rc":[{"atl":[[5.8,0],[5.9,35.72]],"id":42146659}],"con":true,"img":false}]}
{"op":"mcm","clk":"5354093501","pt":1646221365400,"mc":[{"id":"1.195453782","rc":[{"atl":[[6.2,43.27],[5.9,15.31]],"id":42146659}],"con":true,"img":false}]}
{"op":"mcm","clk":"5354093508","pt":1646221365503,"mc":[{"id":"1.195453782","rc":[{"atb":[[1.01,3]],"id":42146659}],"con":true,"img":false}]}
{"op":"mcm","clk":"5354094603","pt":1646221375010,"mc":[{"id":"1.195453782","rc":[{"atb":[[3.4,4]],"id":41419892},{"atb":[[2.88,81.31]],"id":41738000},{"atl":[[16.5,2]],"id":41738000},{"atb":[[3.1,2],[2.98,25.25]],"id":42146659},{"atl":[[5.9,10.2]],"id":42146659}],"con":true,"img":false}]}
{"op":"mcm","clk":"5354094610","pt":1646221375114,"mc":[{"id":"1.195453782","rc":[{"atl":[[14,7.88]],"id":41419892},{"atb":[[4.8,3]],"id":40879966}],"con":true,"img":false}]}
{"op":"mcm","clk":"5354094624","pt":1646221375172,"mc":[{"id":"1.195453782","rc":[{"atb":[[3.45,3]],"id":41419892},{"atl":[[16,3]],"id":41738000}],"con":true,"img":false}]}
{"op":"mcm","clk":"5354094638","pt":1646221375280,"mc":[{"id":"1.195453782","rc":[{"atb":[[3.15,4]],"id":42146659}],"con":true,"img":false}]}
{"op":"mcm","clk":"5354094902","pt":1646221377581,"mc":[{"id":"1.195453782","rc":[{"atb":[[36,2],[1.07,2.25]],"id":39307895}],"con":true,"img":false}]}
{"op":"mcm","clk":"5354094972","pt":1646221378316,"mc":[{"id":"1.195453782","rc":[{"atb":[[1.07,0.09]],"id":39307895}],"con":true,"img":false}]}
{"op":"mcm","clk":"5354094993","pt":1646221378477,"mc":[{"id":"1.195453782","rc":[{"atb":[[1.07,0]],"id":39307895}],"con":true,"img":false}]}
{"op":"mcm","clk":"5354095007","pt":1646221378585,"mc":[{"id":"1.195453782","rc":[{"atb":[[40,0.09]],"id":39307895}],"con":true,"img":false}]}
{"op":"mcm","clk":"5354095755","pt":1646221384981,"mc":[{"id":"1.195453782","rc":[{"atl":[[13.5,0],[14.5,0],[15,5.36],[15.5,0]],"id":41419892},{"atb":[[4.9,3]],"id":40879966},{"spn":30.16,"spf":1.0,"id":39307895},{"atb":[[2.84,40.76]],"id":41738000},{"atb":[[2.94,38.66]],"id":42146659},{"atl":[[6.2,33.65]],"id":42146659},{"spn":4.95,"spf":"NaN","id":42146659}],"con":true,"img":false}]}
{"op":"mcm","clk":"5354095780","pt":1646221385190,"mc":[{"id":"1.195453782","rc":[{"atb":[[3.5,3]],"id":41419892},{"atb":[[2.9,0],[2.86,0]],"id":41738000},{"atl":[[15.5,2]],"id":41738000},{"atb":[[2.92,0],[3.2,3]],"id":42146659}],"con":true,"img":false}]}
{"op":"mcm","clk":"5354096241","pt":1646221389090,"mc":[{"id":"1.195453782","rc":[{"atb":[[38,0],[1.04,1.66]],"id":39307895}],"con":true,"img":false}]}
{"op":"mcm","clk":"5354096255","pt":1646221389192,"mc":[{"id":"1.195453782","rc":[{"atb":[[1.04,0.19]],"id":39307895}],"con":true,"img":false}]}
{"op":"mcm","clk":"5354096268","pt":1646221389299,"mc":[{"id":"1.195453782","rc":[{"atb":[[1.04,0]],"id":39307895}],"con":true,"img":false}]}
{"op":"mcm","clk":"5354096281","pt":1646221389400,"mc":[{"id":"1.195453782","rc":[{"atb":[[42,0.19]],"id":39307895}],"con":true,"img":false}]}
{"op":"mcm","clk":"5354096784","pt":1646221394504,"mc":[{"id":"1.195453782","rc":[{"atl":[[14,3.85]],"id":41419892}],"con":true,"img":false}]}
{"op":"mcm","clk":"5354096799","pt":1646221394608,"mc":[{"id":"1.195453782","rc":[{"atl":[[14.5,4.03]],"id":41419892}],"con":true,"img":false}]}
{"op":"mcm","clk":"5354096852","pt":1646221395022,"mc":[{"id":"1.195453782","rc":[{"atl":[[16,8.33]],"id":41419892},{"atb":[[2.8,69.44]],"id":41738000},{"atl":[[6.6,32.39]],"id":42146659}],"con":true,"img":false}]}
{"op":"mcm","clk":"5354097106","pt":1646221397410,"mc":[{"id":"1.195453782","rc":[{"atb":[[1.01,3.66],[5.7,0]],"id":43167137}],"con":true,"img":false}]}
{"op":"mcm","clk":"5354102503","pt":1646221444583,"mc":[{"id":"1.195453782","rc":[{"atl":[[15.5,8.36],[17.5,0]],"id":41419892}],"con":true,"img":false}]}
{"op":"mcm","clk":"5354107412","pt":1646221485199,"mc":[{"id":"1.195453782","rc":[{"spn":5.27,"spf":1.0,"id":43167137},{"atb":[[3.35,0],[3.5,0],[3.45,0],[3.4,0]],"id":41419892},{"atl":[[12.5,1.74],[13,0]],"id":41419892},{"atl":[[17.5,0],[17,1.25]],"id":40879966},{"spn":30.2,"spf":1.0,"id":39307895},{"atb":[[2.98,62.05],[2.92,0]],"id":41738000},{"atl":[[15.5,0],[16,0],[16.5,0],[17,8.5]],"id":41738000},{"atb":[[3.1,0],[2.98,0],[2.94,0],[3.05,50.17],[2.92,10.42],[3.2,0],[3.15,0]],"id":42146659},{"atl":[[4.8,3],[5.5,4.44],[5.7,0]],"id":42146659},{"spn":4.5,"spf":"NaN","id":42146659}],"con":true,"img":false}]}
{"op":"mcm","clk":"5354107423","pt":1646221485302,"mc":[{"id":"1.195453782","rc":[{"atb":[[4.8,0],[4.9,0],[4.6,0],[4.7,0]],"id":40879966}],"con":true,"img":false}]}
{"op":"mcm","clk":"5354107439","pt":1646221485413,"mc":[{"id":"1.195453782","rc":[{"atb":[[3.05,59.93]],"id":42146659},{"atl":[[4.8,0],[5.8,20.83],[6.2,14.42],[4.7,3]],"id":42146659}],"con":true,"img":false}]}
{"op":"mcm","clk":"5354107462","pt":1646221485613,"mc":[{"id":"1.195453782","rc":[{"atb":[[1.01,3.45]],"id":43167137},{"atl":[[5.8,0],[5.7,21.28]],"id":42146659}],"con":true,"img":false}]}
{"op":"mcm","clk":"5354107476","pt":1646221485719,"mc":[{"id":"1.195453782","rc":[{"atb":[[1.01,2]],"id":43167137}],"con":true,"img":false}]}
{"op":"mcm","clk":"5354107491","pt":1646221485825,"mc":[{"id":"1.195453782","rc":[{"atb":[[5.7,1.45]],"id":43167137}],"con":true,"img":false}]}
{"op":"mcm","clk":"5354107517","pt":1646221486036,"mc":[{"id":"1.195453782","rc":[{"atb":[[1.01,3.66],[5.7,0]],"id":43167137}],"con":true,"img":false}]}
{"op":"mcm","clk":"5354107545","pt":1646221486199,"mc":[{"id":"1.195453782","rc":[{"atb":[[1.01,3.45]],"id":43167137}],"con":true,"img":false}]}
{"op":"mcm","clk":"5354107562","pt":1646221486407,"mc":[{"id":"1.195453782","rc":[{"atb":[[1.01,2]],"id":43167137}],"con":true,"img":false}]}
{"op":"mcm","clk":"5354107574","pt":1646221486510,"mc":[{"id":"1.195453782","rc":[{"atb":[[5.5,1.45]],"id":43167137}],"con":true,"img":false}]}
{"op":"mcm","clk":"5354107595","pt":1646221486718,"mc":[{"id":"1.195453782","rc":[{"atb":[[1.01,3.66],[5.5,0]],"id":43167137}],"con":true,"img":false}]}
{"op":"mcm","clk":"5354107620","pt":1646221486929,"mc":[{"id":"1.195453782","rc":[{"atb":[[1.01,3.45]],"id":43167137}],"con":true,"img":false}]}
{"op":"mcm","clk":"5354107632","pt":1646221487034,"mc":[{"id":"1.195453782","rc":[{"atb":[[1.01,2]],"id":43167137}],"con":true,"img":false}]}
{"op":"mcm","clk":"5354107647","pt":1646221487090,"mc":[{"id":"1.195453782","rc":[{"atb":[[5.7,1.45]],"id":43167137}],"con":true,"img":false}]}
{"op":"mcm","clk":"5354108564","pt":1646221495218,"mc":[{"id":"1.195453782","rc":[{"atb":[[2.94,25.77]],"id":41738000}],"con":true,"img":false}]}
{"op":"mcm","clk":"5354108586","pt":1646221495426,"mc":[{"id":"1.195453782","rc":[{"atb":[[2.8,0],[2.84,0],[2.88,54.71]],"id":41738000},{"atb":[[2.98,25.25]],"id":42146659},{"atl":[[5.7,31.92],[4.7,0]],"id":42146659}],"con":true,"img":false}]}
{"op":"mcm","clk":"5354108596","pt":1646221495530,"mc":[{"id":"1.195453782","rc":[{"atl":[[5.9,30.61],[5.7,10.64]],"id":42146659}],"con":true,"img":false}]}
{"op":"mcm","clk":"5354108806","pt":1646221497469,"mc":[{"id":"1.195453782","rc":[{"atb":[[3.75,0],[4,0],[4.5,5.71],[5,0]],"id":43167137},{"atl":[[16,1.33],[18.5,0],[22,0],[27,0]],"id":43167137},{"atb":[[5,0],[5.5,0],[6,0],[7,0]],"id":41419892},{"atl":[[38,0],[19.5,0],[24,0],[29,0]],"id":41419892},{"atb":[[9.6,0],[8.6,0],[7.6,0],[6.6,0]],"id":40879966},{"atl":[[130,0],[46,0],[65,0],[90,0]],"id":40879966},{"atb":[[34,0],[18.5,7.14],[22,0.13],[27,0]],"id":39307895},{"atl":[[250,0],[300,0],[350,0],[400,0]],"id":39307895},{"atb":[[2.98,10.1],[3.2,0],[2.88,0],[2.78,0]],"id":41738000},{"atl":[[9.2,0],[10.5,0],[8.2,0],[13,0]],"id":41738000},{"atb":[[3.8,0],[3.55,0],[3.3,0],[3.05,9.76]],"id":42146659},{"atl":[[12,0],[14.5,0],[17,0],[9.8,0]],"id":42146659},{"atb":[[3.4,0],[3.15,0],[3.9,2],[3.65,0]],"id":39594698},{"atl":[[10.5,0],[13,0],[15.5,0],[18,0]],"id":39594698}],"con":true,"img":false}]}
{"op":"mcm","clk":"5354108817","pt":1646221497625,"mc":[{"id":"1.195453782","rc":[{"atb":[[36,0],[29,2]],"id":39307895}],"con":true,"img":false}]}
{"op":"mcm","clk":"5354108877","pt":1646221498186,"mc":[{"id":"1.195453782","rc":[{"atb":[[1.01,3.66],[5.7,0]],"id":43167137},{"atb":[[42,0],[1.04,1.66]],"id":39307895}],"con":true,"img":false}]}
{"op":"mcm","clk":"5354108894","pt":1646221498340,"mc":[{"id":"1.195453782","rc":[{"atb":[[1.01,3.45]],"id":43167137},{"atb":[[1.01,3.66],[9.8,0.29]],"id":40879966},{"atb":[[1.04,0.19]],"id":39307895}],"con":true,"img":false}]}
{"op":"mcm","clk":"5354108918","pt":1646221498542,"mc":[{"id":"1.195453782","rc":[{"atb":[[1.04,0]],"id":39307895}],"con":true,"img":false}]}
{"op":"mcm","clk":"5354108931","pt":1646221498651,"mc":[{"id":"1.195453782","rc":[{"atb":[[29,2.19]],"id":39307895}],"con":true,"img":false}]}
{"op":"mcm","clk":"5354108940","pt":1646221498755,"mc":[{"id":"1.195453782","rc":[{"atb":[[1.01,2]],"id":43167137},{"atb":[[1.01,2.83]],"id":40879966}],"con":true,"img":false}]}
{"op":"mcm","clk":"5354108950","pt":1646221498861,"mc":[{"id":"1.195453782","rc":[{"atb":[[5.5,1.45]],"id":43167137}],"con":true,"img":false}]}
{"op":"mcm","clk":"5354108968","pt":1646221499016,"mc":[{"id":"1.195453782","rc":[{"atb":[[1.01,2]],"id":40879966}],"con":true,"img":false}]}
{"op":"mcm","clk":"5354108981","pt":1646221499120,"mc":[{"id":"1.195453782","rc":[{"atb":[[9.4,1.21]],"id":40879966}],"con":true,"img":false}]}
{"op":"mcm","clk":"5354108988","pt":1646221499229,"mc":[{"id":"1.195453782","rc":[{"atb":[[1.01,3.66]],"id":43167137}],"con":true,"img":false}]}
{"op":"mcm","clk":"5354108997","pt":1646221499335,"mc":[{"id":"1.195453782","rc":[{"atb":[[5.5,0]],"id":43167137}],"con":true,"img":false}]}
{"op":"mcm","clk":"5354109009","pt":1646221499431,"mc":[{"id":"1.195453782","rc":[{"atb":[[1.01,3.45]],"id":43167137}],"con":true,"img":false}]}
{"op":"mcm","clk":"5354109026","pt":1646221499640,"mc":[{"id":"1.195453782","rc":[{"atb":[[1.01,2]],"id":43167137}],"con":true,"img":false}]}
{"op":"mcm","clk":"5354109034","pt":1646221499750,"mc":[{"id":"1.195453782","rc":[{"atb":[[5.7,1.45]],"id":43167137}],"con":true,"img":false}]}
{"op":"mcm","clk":"5354109130","pt":1646221500321,"mc":[{"id":"1.195453782","rc":[{"atb":[[4.1,40.54]],"id":43167137},{"atb":[[5.6,16.35]],"id":41419892},{"atb":[[7.2,16.35]],"id":40879966},{"atb":[[24,16.35]],"id":39307895},{"atb":[[2.76,16.35]],"id":41738000},{"atb":[[3.25,16.35]],"id":42146659},{"atb":[[3.35,48.26]],"id":39594698}],"con":true,"img":false}]}
{"op":"mcm","clk":"5354109156","pt":1646221500528,"mc":[{"id":"1.195453782","rc":[{"atl":[[1000,4]],"id":43167137},{"atl":[[1000,4]],"id":41419892},{"atl":[[1000,4]],"id":40879966},{"atl":[[1000,4]],"id":39307895},{"atl":[[1000,4]],"id":41738000},{"atl":[[1000,4]],"id":42146659}],"con":true,"img":false}]}
{"op":"mcm","clk":"5354109173","pt":1646221500642,"mc":[{"id":"1.195453782","rc":[{"atb":[[3.75,37.41],[4,34.29],[4.5,35.1],[5,25.71]],"id":43167137},{"atl":[[16,10.2],[18.5,7.61],[22,9.51],[27,7.68]],"id":43167137},{"atb":[[5,25.71],[5.5,22.85],[6,20.57],[7,17.14]],"id":41419892},{"atl":[[38,5.4],[19.5,7.19],[24,5.79],[29,7.13]],"id":41419892},{"atb":[[9.6,11.96],[8.6,13.53],[7.6,15.58],[6.6,18.37]],"id":40879966},{"atl":[[130,1.54],[46,2.95],[65,2.08],[90,2.24]],"id":40879966},{"atb":[[34,3.11],[18.5,13.02],[22,5.03],[27,3.95]],"id":39307895},{"atl":[[250,0.53],[300,0.44],[350,0.57],[400,0.5]],"id":39307895},{"atb":[[2.98,62.05],[3.2,46.76],[2.88,54.71],[2.78,57.79]],"id":41738000},{"atl":[[9.2,16.24],[10.5,21.03],[8.2,18.49],[13,16.65]],"id":41738000},{"atb":[[3.8,36.73],[2.98,0],[3.55,40.34],[3.3,44.72],[3.05,50.17]],"id":42146659},{"atl":[[4.8,3],[12,12.11],[14.5,14.8],[17,12.48],[9.8,15.13],[6.6,10.07]],"id":42146659},{"atb":[[3.4,42.86],[3.15,47.84],[3.9,37.47],[3.65,38.82]],"id":39594698},{"atl":[[10.5,14.02],[13,11.1],[15.5,13.77],[18,11.75]],"id":39594698}],"con":true,"img":false}]}
{"op":"mcm","clk":"5354109197","pt":1646221500761,"mc":[{"id":"1.195453782","rc":[{"atl":[[1000,2]],"id":43167137},{"atl":[[1000,2]],"id":41419892},{"atl":[[1000,2]],"id":40879966},{"atl":[[1000,2]],"id":39307895},{"atl":[[1000,2]],"id":41738000},{"atl":[[1000,2]],"id":42146659}],"con":true,"img":false}]}
{"op":"mcm","clk":"5354109212","pt":1646221500852,"mc":[{"id":"1.195453782","rc":[{"atb":[[36,2],[29,0.19]],"id":39307895}],"con":true,"img":false}]}
{"op":"mcm","clk":"5354109234","pt":1646221500966,"mc":[{"id":"1.195453782","rc":[{"atl":[[1000,0]],"id":43167137},{"atl":[[1000,0]],"id":41419892},{"atb":[[1.01,3.66],[9.4,0.38]],"id":40879966},{"atl":[[1000,0]],"id":40879966},{"atl":[[1000,0]],"id":39307895},{"atl":[[1000,0]],"id":41738000},{"atl":[[1000,0]],"id":42146659}],"con":true,"img":false}]}
{"op":"mcm","clk":"5354109268","pt":1646221501172,"mc":[{"id":"1.195453782","rc":[{"atl":[[9.8,2]],"id":43167137},{"atl":[[12,2]],"id":41419892},{"atb":[[1.01,2.83]],"id":40879966},{"atl":[[18,2]],"id":40879966},{"atl":[[95,2.09]],"id":39307895},{"atl":[[5.1,2]],"id":41738000},{"atl":[[5.4,2]],"id":42146659}],"con":true,"img":false}]}
{"op":"mcm","clk":"5354109304","pt":1646221501337,"mc":[{"id":"1.195453782","rc":[{"atb":[[1.01,2]],"id":40879966},{"atl":[[95,4.09],[110,2]],"id":39307895}],"con":true,"img":false}]}
{"op":"mcm","clk":"5354109322","pt":1646221501439,"mc":[{"id":"1.195453782","rc":[{"atb":[[10,0.83]],"id":40879966}],"con":true,"img":false}]}
{"op":"mcm","clk":"5354109339","pt":1646221501542,"mc":[{"id":"1.195453782","rc":[{"atl":[[95,2.09],[100,4.72]],"id":39307895},{"atl":[[5.4,1]],"id":42146659}],"con":true,"img":false}]}
{"op":"mcm","clk":"5354109359","pt":1646221501645,"mc":[{"id":"1.195453782","rc":[{"atl":[[4.7,1]],"id":42146659}],"con":true,"img":false}]}
{"op":"mcm","clk":"5354109379","pt":1646221501751,"mc":[{"id":"1.195453782","rc":[{"atl":[[5.4,0]],"id":42146659}],"con":true,"img":false}]}
{"op":"mcm","clk":"5354109400","pt":1646221501859,"mc":[{"id":"1.195453782","rc":[{"atl":[[4.7,2]],"id":42146659}],"con":true,"img":false}]}
{"op":"mcm","clk":"5354109901","pt":1646221505262,"mc":[{"id":"1.195453782","rc":[{"atb":[[2.9,39.47]],"id":41738000}],"con":true,"img":false}]}
{"op":"mcm","clk":"5354109924","pt":1646221505421,"mc":[{"id":"1.195453782","rc":[{"atb":[[2.88,26.6]],"id":42146659},{"atl":[[5.9,35.72]],"id":42146659}],"con":true,"img":false}]}
{"op":"mcm","clk":"5354109964","pt":1646221505741,"mc":[{"id":"1.195453782","rc":[{"atb":[[3.05,59.93]],"id":42146659},{"atl":[[4.8,0],[5.9,15.31],[5.7,25.06],[4.7,6]],"id":42146659}],"con":true,"img":false}]}
{"op":"mcm","clk":"5354109989","pt":1646221505949,"mc":[{"id":"1.195453782","rc":[{"atb":[[3.6,3]],"id":41738000}],"con":true,"img":false}]}
{"op":"mcm","clk":"5354110036","pt":1646221506342,"mc":[{"id":"1.195453782","rc":[{"atb":[[3.45,0]],"id":41738000}],"con":true,"img":false}]}
{"op":"mcm","clk":"5354110048","pt":1646221506452,"mc":[{"id":"1.195453782","rc":[{"atb":[[3.65,1.99]],"id":41738000}],"con":true,"img":false}]}
{"op":"mcm","clk":"5354110339","pt":1646221508844,"mc":[{"id":"1.195453782","rc":[{"atb":[[3.85,3]],"id":41738000}],"con":true,"img":false}]}
{"op":"mcm","clk":"5354110389","pt":1646221509257,"mc":[{"id":"1.195453782","rc":[{"atb":[[3.65,0]],"id":41738000}],"con":true,"img":false}]}
{"op":"mcm","clk":"5354110404","pt":1646221509360,"mc":[{"id":"1.195453782","rc":[{"atb":[[5.7,0]],"id":43167137},{"atb":[[3.9,1.99]],"id":41738000}],"con":true,"img":false}]}
{"op":"mcm","clk":"5354110420","pt":1646221509464,"mc":[{"id":"1.195453782","rc":[{"atb":[[1.01,3.66]],"id":43167137},{"atb":[[10,0]],"id":40879966},{"atb":[[3.9,4.99]],"id":41738000}],"con":true,"img":false}]}
{"op":"mcm","clk":"5354110438","pt":1646221509566,"mc":[{"id":"1.195453782","rc":[{"atb":[[1.01,3.66]],"id":40879966}],"con":true,"img":false}]}
{"op":"mcm","clk":"5354110451","pt":1646221509624,"mc":[{"id":"1.195453782","rc":[{"atb":[[1.01,3.45]],"id":43167137}],"con":true,"img":false}]}
{"op":"mcm","clk":"5354110468","pt":1646221509725,"mc":[{"id":"1.195453782","rc":[{"atb":[[1.01,2]],"id":43167137}],"con":true,"img":false}]}
{"op":"mcm","clk":"5354110484","pt":1646221509837,"mc":[{"id":"1.195453782","rc":[{"atb":[[5.5,1.45]],"id":43167137},{"atb":[[1.01,2.83]],"id":40879966}],"con":true,"img":false}]}
{"op":"mcm","clk":"5354110509","pt":1646221510051,"mc":[{"id":"1.195453782","rc":[{"atb":[[1.01,2]],"id":40879966}],"con":true,"img":false}]}
{"op":"mcm","clk":"5354110524","pt":1646221510153,"mc":[{"id":"1.195453782","rc":[{"atb":[[9.8,1.13]],"id":40879966},{"atb":[[3.4,0],[1.04,1.66]],"id":41738000}],"con":true,"img":false}]}
{"op":"mcm","clk":"5354110543","pt":1646221510358,"mc":[{"id":"1.195453782","rc":[{"atb":[[4.1,3],[1.04,1.65]],"id":41738000}],"con":true,"img":false}]}
{"op":"mcm","clk":"5354110563","pt":1646221510559,"mc":[{"id":"1.195453782","rc":[{"atb":[[1.04,0]],"id":41738000}],"con":true,"img":false}]}
{"op":"mcm","clk":"5354110575","pt":1646221510669,"mc":[{"id":"1.195453782","rc":[{"atb":[[3.75,1.65]],"id":41738000}],"con":true,"img":false}]}
{"op":"mcm","clk":"5354110598","pt":1646221510873,"mc":[{"id":"1.195453782","rc":[{"atb":[[1.73,62.2],[1.83,0]],"id":41738000},{"atl":[[4.7,2]],"id":42146659}],"con":true,"img":false}]}
{"op":"mcm","clk":"5354110627","pt":1646221511043,"mc":[{"id":"1.195453782","rc":[{"atl":[[4.7,1]],"id":42146659}],"con":true,"img":false}]}
{"op":"mcm","clk":"5354110642","pt":1646221511138,"mc":[{"id":"1.195453782","rc":[{"atl":[[5.4,1]],"id":42146659}],"con":true,"img":false}]}
{"op":"mcm","clk":"5354110696","pt":1646221511561,"mc":[{"id":"1.195453782","rc":[{"atl":[[4.2,3]],"id":41738000}],"con":true,"img":false}]}
{"op":"mcm","clk":"5354110719","pt":1646221511765,"mc":[{"id":"1.195453782","rc":[{"atb":[[1.01,3.66],[5.5,0]],"id":43167137},{"atl":[[5.1,1],[4.2,0]],"id":41738000},{"trd":[[4.2,6]],"ltp":4.2,"tv":6.0,"id":41738000}],"con":true,"img":false}]}
{"op":"mcm","clk":"5354110755","pt":1646221511977,"mc":[{"id":"1.195453782","rc":[{"atb":[[1.01,3.43]],"id":43167137},{"atb":[[3.15,0]],"id":41738000},{"atl":[[1000,2]],"id":41738000},{"atl":[[4.7,0]],"id":42146659}],"con":true,"img":false}]}
{"op":"mcm","clk":"5354110763","pt":1646221512079,"mc":[{"id":"1.195453782","rc":[{"atb":[[3.3,3.94]],"id":41738000},{"atl":[[5.4,2]],"id":42146659}],"con":true,"img":false}]}
{"op":"mcm","clk":"5354110776","pt":1646221512185,"mc":[{"id":"1.195453782","rc":[{"atb":[[1.01,2]],"id":43167137},{"atl":[[1000,1],[5.1,1.36]],"id":41738000}],"con":true,"img":false}]}
{"op":"mcm","clk":"5354110781","pt":1646221512239,"mc":[{"id":"1.195453782","rc":[{"atb":[[5.8,1.43]],"id":43167137}],"con":true,"img":false}]}
{"op":"mcm","clk":"5354110797","pt":1646221512343,"mc":[{"id":"1.195453782","rc":[{"atl":[[1000,0]],"id":41738000}],"con":true,"img":false}]}
{"op":"mcm","clk":"5354110810","pt":1646221512448,"mc":[{"id":"1.195453782","rc":[{"atb":[[3.9,3]],"id":41738000},{"atl":[[5.1,2.36]],"id":41738000}],"con":true,"img":false}]}
{"op":"mcm","clk":"5354110820","pt":1646221512552,"mc":[{"id":"1.195453782","rc":[{"atb":[[4.2,1.99]],"id":41738000}],"con":true,"img":false}]}
{"op":"mcm","clk":"5354110922","pt":1646221513334,"mc":[{"id":"1.195453782","rc":[{"atb":[[4.2,4.99]],"id":41738000}],"con":true,"img":false}]}
{"op":"mcm","clk":"5354110959","pt":1646221513649,"mc":[{"id":"1.195453782","rc":[{"atb":[[4.3,3]],"id":41738000}],"con":true,"img":false}]}
{"op":"mcm","clk":"5354110982","pt":1646221513854,"mc":[{"id":"1.195453782","rc":[{"atb":[[4.3,3.41]],"id":41738000}],"con":true,"img":false}]}
{"op":"mcm","clk":"5354111007","pt":1646221514063,"mc":[{"id":"1.195453782","rc":[{"atb":[[4.2,3]],"id":41738000}],"con":true,"img":false}]}
{"op":"mcm","clk":"5354111027","pt":1646221514169,"mc":[{"id":"1.195453782","rc":[{"atb":[[1.02,1.99]],"id":41738000}],"con":true,"img":false}]}
{"op":"mcm","clk":"5354111070","pt":1646221514480,"mc":[{"id":"1.195453782","rc":[{"atl":[[4.4,3]],"id":41738000}],"con":true,"img":false}]}
{"op":"mcm","clk":"5354111095","pt":1646221514643,"mc":[{"id":"1.195453782","rc":[{"atl":[[5.1,0.36]],"id":41738000}],"con":true,"img":false}]}
{"op":"mcm","clk":"5354111190","pt":1646221515472,"mc":[{"id":"1.195453782","rc":[{"atb":[[6,36.92]],"id":41419892}],"con":true,"img":false}]}
{"op":"mcm","clk":"5354111204","pt":1646221515577,"mc":[{"id":"1.195453782","rc":[{"atb":[[4.4,16.35]],"id":43167137},{"atb":[[7.8,34.88]],"id":40879966},{"atb":[[2.8,16.35]],"id":41738000},{"atb":[[3.3,61.08]],"id":42146659},{"atb":[[3.5,62.39]],"id":39594698}],"con":true,"img":false}]}
{"op":"mcm","clk":"5354111239","pt":1646221515844,"mc":[{"id":"1.195453782","rc":[{"atl":[[4.4,0]],"id":41738000}],"con":true,"img":false}]}
{"op":"mcm","clk":"5354111259","pt":1646221516051,"mc":[{"id":"1.195453782","rc":[{"atl":[[1000,4]],"id":41738000}],"con":true,"img":false}]}
{"op":"mcm","clk":"5354111273","pt":1646221516157,"mc":[{"id":"1.195453782","rc":[{"atb":[[4.2,0],[2.86,67.2]],"id":41738000}],"con":true,"img":false}]}
{"op":"mcm","clk":"5354111282","pt":1646221516261,"mc":[{"id":"1.195453782","rc":[{"atl":[[1000,2]],"id":41738000}],"con":true,"img":false}]}
{"op":"mcm","clk":"5354111299","pt":1646221516363,"mc":[{"id":"1.195453782","rc":[{"atb":[[2.86,0],[2.52,60.01]],"id":43167137},{"atl":[[15,0],[18,10.29]],"id":43167137},{"atb":[[7.4,2],[3.3,0]],"id":41419892},{"atl":[[8.8,2]],"id":41419892},{"atb":[[4.4,0],[4.1,6.45],[9.8,3.13],[4.2,31.25]],"id":40879966},{"atl":[[12,3],[19,2.92]],"id":40879966},{"atl":[[110,0],[120,2]],"id":39307895},{"atb":[[1.73,0],[2.34,64.29],[4.1,3.4]],"id":41738000},{"atl":[[1000,1],[5.1,2.88]],"id":41738000},{"atb":[[3.05,50.17]],"id":42146659},{"atl":[[4.8,3],[6.4,18.52],[5.7,10.64]],"id":42146659},{"atb":[[3.85,35.09],[3.7,0]],"id":39594698},{"atl":[[6.2,0],[6.6,3.57]],"id":39594698}],"con":true,"img":false}]}
{"op":"mcm","clk":"5354111307","pt":1646221516469,"mc":[{"id":"1.195453782","rc":[{"atl":[[1000,0],[5.1,3.88]],"id":41738000}],"con":true,"img":false}]}
{"op":"mcm","clk":"5354111321","pt":1646221516577,"mc":[{"id":"1.195453782","rc":[{"atl":[[5.1,4.88]],"id":41738000}],"con":true,"img":false}]}
{"op":"mcm","clk":"5354111341","pt":1646221516683,"mc":[{"id":"1.195453782","rc":[{"atl":[[18,1]],"id":40879966},{"atb":[[2.84,95.11]],"id":42146659},{"atl":[[6.2,24.04]],"id":42146659}],"con":true,"img":false}]}
{"op":"mcm","clk":"5354111353","pt":1646221516787,"mc":[{"id":"1.195453782","rc":[{"atl":[[18,0]],"id":40879966}],"con":true,"img":false}]}
{"op":"mcm","clk":"5354111367","pt":1646221516887,"mc":[{"id":"1.195453782","rc":[{"atl":[[12,1]],"id":41419892},{"atl":[[5.4,1]],"id":42146659}],"con":true,"img":false}]}
{"op":"mcm","clk":"5354111383","pt":1646221516953,"mc":[{"id":"1.195453782","rc":[{"atl":[[12,0],[8.6,1]],"id":41419892},{"atb":[[3.3,0.32]],"id":41738000},{"atl":[[5.4,0],[4.7,1]],"id":42146659}],"con":true,"img":false}]}
{"op":"mcm","clk":"5354111394","pt":1646221517051,"mc":[{"id":"1.195453782","rc":[{"atl":[[8.6,2]],"id":41419892},{"atl":[[4.7,2]],"id":42146659}],"con":true,"img":false}]}
{"op":"mcm","clk":"5354111568","pt":1646221518459,"mc":[{"id":"1.195453782","rc":[{"atb":[[4.3,0.41]],"id":41738000}],"con":true,"img":false}]}
{"op":"mcm","clk":"5354111619","pt":1646221518876,"mc":[{"id":"1.195453782","rc":[{"atb":[[5.2,1.99]],"id":43167137}],"con":true,"img":false}]}
{"op":"mcm","clk":"5354111653","pt":1646221519182,"mc":[{"id":"1.195453782","rc":[{"atb":[[1.02,0]],"id":41738000}],"con":true,"img":false}]}
{"op":"mcm","clk":"5354111672","pt":1646221519238,"mc":[{"id":"1.195453782","rc":[{"atb":[[4.2,1.99]],"id":41738000}],"con":true,"img":false}]}
{"op":"mcm","clk":"5354111683","pt":1646221519346,"mc":[{"id":"1.195453782","rc":[{"atb":[[1.01,3.66]],"id":43167137}],"con":true,"img":false}]}
{"op":"mcm","clk":"5354111697","pt":1646221519444,"mc":[{"id":"1.195453782","rc":[{"atb":[[5.8,0]],"id":43167137}],"con":true,"img":false}]}
{"op":"mcm","clk":"5354111710","pt":1646221519551,"mc":[{"id":"1.195453782","rc":[{"atb":[[1.01,3.43]],"id":43167137}],"con":true,"img":false}]}
{"op":"mcm","clk":"5354111730","pt":1646221519758,"mc":[{"id":"1.195453782","rc":[{"atb":[[1.01,2]],"id":43167137}],"con":true,"img":false}]}
{"op":"mcm","clk":"5354111744","pt":1646221519860,"mc":[{"id":"1.195453782","rc":[{"atb":[[5.5,1.43]],"id":43167137}],"con":true,"img":false}]}
{"op":"mcm","clk":"5354111772","pt":1646221520066,"mc":[{"id":"1.195453782","rc":[{"atb":[[4.3,0],[4.2,0]],"id":41738000},{"atl":[[4.2,0.6]],"id":41738000},{"trd":[[4.2,9.98],[4.3,0.82]],"ltp":4.2,"tv":10.8,"id":41738000}],"con":true,"img":false}]}
{"op":"mcm","clk":"5354111782","pt":1646221520168,"mc":[{"id":"1.195453782","rc":[{"atl":[[4.2,0]],"id":41738000},{"trd":[[4.2,11.18]],"ltp":4.2,"tv":11.18,"id":41738000}],"con":true,"img":false}]}
{"op":"mcm","clk":"5354111811","pt":1646221520378,"mc":[{"id":"1.195453782","rc":[{"atb":[[1.01,3.66],[5.5,0]],"id":43167137},{"atb":[[4.1,3]],"id":41738000}],"con":true,"img":false}]}
{"op":"mcm","clk":"5354111850","pt":1646221520590,"mc":[{"id":"1.195453782","rc":[{"atb":[[1.01,3.43]],"id":43167137}],"con":true,"img":false}]}
{"op":"mcm","clk":"5354111875","pt":1646221520750,"mc":[{"id":"1.195453782","rc":[{"atb":[[1.01,2]],"id":43167137}],"con":true,"img":false}]}
{"op":"mcm","clk":"5354111888","pt":1646221520867,"mc":[{"id":"1.195453782","rc":[{"atb":[[5.8,1.43]],"id":43167137}],"con":true,"img":false}]}
{"op":"mcm","clk":"5354111984","pt":1646221521685,"mc":[{"id":"1.195453782","rc":[{"atb":[[4.2,3]],"id":41738000}],"con":true,"img":false}]}
{"op":"mcm","clk":"5354112025","pt":1646221521961,"mc":[{"id":"1.195453782","rc":[{"atb":[[2.4,60.01],[2.52,0],[5.7,5.11]],"id":43167137},{"atl":[[8.6,4]],"id":41419892},{"atb":[[9.8,1.13]],"id":40879966},{"atl":[[11.5,4]],"id":40879966},{"atl":[[4.7,4]],"id":42146659},{"atl":[[6.8,3.45],[6.6,0]],"id":39594698}],"con":true,"img":false}]}
{"op":"mcm","clk":"5354112042","pt":1646221522165,"mc":[{"id":"1.195453782","rc":[{"atl":[[8.6,3]],"id":41419892}],"con":true,"img":false}]}
{"op":"mcm","clk":"5354112064","pt":1646221522371,"mc":[{"id":"1.195453782","rc":[{"atl":[[8.6,2]],"id":41419892},{"atl":[[4.3,3]],"id":41738000}],"con":true,"img":false}]}
{"op":"mcm","clk":"5354112073","pt":1646221522474,"mc":[{"id":"1.195453782","rc":[{"atb":[[5.4,0]],"id":43167137}],"con":true,"img":false}]}
{"op":"mcm","clk":"5354112082","pt":1646221522579,"mc":[{"id":"1.195453782","rc":[{"atb":[[5.8,3.42]],"id":43167137},{"atl":[[4.3,0],[5.1,3.88]],"id":41738000},{"trd":[[4.3,6.82]],"ltp":4.3,"tv":6.82,"id":41738000}],"con":true,"img":false}]}
{"op":"mcm","clk":"5354112112","pt":1646221522886,"mc":[{"id":"1.195453782","rc":[{"atl":[[1000,2]],"id":41738000}],"con":true,"img":false}]}
{"op":"mcm","clk":"5354112142","pt":1646221523095,"mc":[{"id":"1.195453782","rc":[{"atl":[[1000,1]],"id":41738000}],"con":true,"img":false}]}
{"op":"mcm","clk":"5354112163","pt":1646221523255,"mc":[{"id":"1.195453782","rc":[{"atl":[[1000,0]],"id":41738000}],"con":true,"img":false}]}
{"op":"mcm","clk":"5354112181","pt":1646221523391,"mc":[{"id":"1.195453782","rc":[{"atl":[[5,1]],"id":41738000}],"con":true,"img":false}]}
{"op":"mcm","clk":"5354112204","pt":1646221523591,"mc":[{"id":"1.195453782","rc":[{"atl":[[5,1.35]],"id":41738000}],"con":true,"img":false}]}
{"op":"mcm","clk":"5354112248","pt":1646221523970,"mc":[{"id":"1.195453782","rc":[{"atl":[[5.1,1.36]],"id":41738000}],"con":true,"img":false}]}
{"op":"mcm","clk":"5354112271","pt":1646221524170,"mc":[{"id":"1.195453782","rc":[{"atb":[[4.3,3]],"id":41738000},{"atl":[[5,0.35]],"id":41738000}],"con":true,"img":false}]}
{"op":"mcm","clk":"5354112281","pt":1646221524280,"mc":[{"id":"1.195453782","rc":[{"atl":[[5.1,2.36]],"id":41738000}],"con":true,"img":false}]}
{"op":"mcm","clk":"5354112350","pt":1646221524857,"mc":[{"id":"1.195453782","rc":[{"atl":[[4.4,3]],"id":41738000}],"con":true,"img":false}]}
{"op":"mcm","clk":"5354112366","pt":1646221524972,"mc":[{"id":"1.195453782","rc":[{"atl":[[4.4,0]],"id":41738000},{"trd":[[4.4,6]],"ltp":4.4,"tv":6.0,"id":41738000}],"con":true,"img":false}]}
{"op":"mcm","clk":"5354112374","pt":1646221525067,"mc":[{"id":"1.195453782","rc":[{"atl":[[5.1,0.36]],"id":41738000}],"con":true,"img":false}]}
{"op":"mcm","clk":"5354112391","pt":1646221525272,"mc":[{"id":"1.195453782","rc":[{"atb":[[5.7,0]],"id":43167137},{"atl":[[1000,4]],"id":41738000}],"con":true,"img":false}]}
{"op":"mcm","clk":"5354112420","pt":1646221525480,"mc":[{"id":"1.195453782","rc":[{"atl":[[1000,2]],"id":41738000}],"con":true,"img":false}]}
{"op":"mcm","clk":"5354112444","pt":1646221525689,"mc":[{"id":"1.195453782","rc":[{"atl":[[1000,0]],"id":41738000}],"con":true,"img":false}]}
{"op":"mcm","clk":"5354112456","pt":1646221525785,"mc":[{"id":"1.195453782","rc":[{"atl":[[5.1,2.36]],"id":41738000}],"con":true,"img":false}]}
{"op":"mcm","clk":"5354112616","pt":1646221527095,"mc":[{"id":"1.195453782","rc":[{"atb":[[3.05,24.39]],"id":41419892},{"atb":[[3.95,16.95]],"id":40879966}],"con":true,"img":false}]}
{"op":"mcm","clk":"5354112628","pt":1646221527197,"mc":[{"id":"1.195453782","rc":[{"atl":[[4.4,3]],"id":41738000}],"con":true,"img":false}]}
{"op":"mcm","clk":"5354112640","pt":1646221527308,"mc":[{"id":"1.195453782","rc":[{"atl":[[8.4,2]],"id":41419892},{"atl":[[11,2]],"id":40879966}],"con":true,"img":false}]}
{"op":"mcm","clk":"5354112655","pt":1646221527375,"mc":[{"id":"1.195453782","rc":[{"atl":[[4.4,0],[5.1,1.36]],"id":41738000},{"trd":[[4.4,12]],"ltp":4.4,"tv":12.0,"id":41738000},{"atb":[[2.8,69.44]],"id":42146659},{"atl":[[4.6,3]],"id":42146659}],"con":true,"img":false}]}
{"op":"mcm","clk":"5354112693","pt":1646221527712,"mc":[{"id":"1.195453782","rc":[{"atl":[[4.7,3]],"id":42146659}],"con":true,"img":false}]}
{"op":"mcm","clk":"5354112716","pt":1646221527893,"mc":[{"id":"1.195453782","rc":[{"atl":[[1000,2]],"id":41738000}],"con":true,"img":false}]}
{"op":"mcm","clk":"5354112729","pt":1646221528003,"mc":[{"id":"1.195453782","rc":[{"atb":[[40,0],[1.07,2.25]],"id":39307895}],"con":true,"img":false}]}
{"op":"mcm","clk":"5354112742","pt":1646221528100,"mc":[{"id":"1.195453782","rc":[{"atl":[[1000,1]],"id":41738000},{"atl":[[4.7,2]],"id":42146659}],"con":true,"img":false}]}
{"op":"mcm","clk":"5354112751","pt":1646221528204,"mc":[{"id":"1.195453782","rc":[{"atb":[[1.07,0.09]],"id":39307895}],"con":true,"img":false}]}
{"op":"mcm","clk":"5354112768","pt":1646221528266,"mc":[{"id":"1.195453782","rc":[{"atb":[[1.07,0]],"id":39307895},{"atl":[[1000,0]],"id":41738000}],"con":true,"img":false}]}
{"op":"mcm","clk":"5354112781","pt":1646221528374,"mc":[{"id":"1.195453782","rc":[{"atb":[[38,0.09]],"id":39307895},{"atl":[[5.1,2.36]],"id":41738000}],"con":true,"img":false}]}
{"op":"mcm","clk":"5354112850","pt":1646221529098,"mc":[{"id":"1.195453782","rc":[{"atb":[[4.4,3]],"id":41738000}],"con":true,"img":false}]}
{"op":"mcm","clk":"5354112965","pt":1646221530000,"mc":[{"id":"1.195453782","rc":[{"atl":[[4.5,3]],"id":41738000}],"con":true,"img":false}]}
{"op":"mcm","clk":"5354112992","pt":1646221530202,"mc":[{"id":"1.195453782","rc":[{"atl":[[5.1,0.36]],"id":41738000}],"con":true,"img":false}]}
{"op":"mcm","clk":"5354113203","pt":1646221531783,"mc":[{"id":"1.195453782","rc":[{"atl":[[4.5,0]],"id":41738000}],"con":true,"img":false}]}
{"op":"mcm","clk":"5354113230","pt":1646221531990,"mc":[{"id":"1.195453782","rc":[{"atl":[[1000,2]],"id":41738000}],"con":true,"img":false}]}
{"op":"mcm","clk":"5354113255","pt":1646221532196,"mc":[{"id":"1.195453782","rc":[{"atl":[[1000,3]],"id":41738000}],"con":true,"img":false}]}
{"op":"mcm","clk":"5354113264","pt":1646221532296,"mc":[{"id":"1.195453782","rc":[{"atb":[[4.4,0]],"id":41738000}],"con":true,"img":false}]}
{"op":"mcm","clk":"5354113279","pt":1646221532400,"mc":[{"id":"1.195453782","rc":[{"atl":[[1000,1]],"id":41738000}],"con":true,"img":false}]}
{"op":"mcm","clk":"5354113290","pt":1646221532506,"mc":[{"id":"1.195453782","rc":[{"atl":[[8.2,3]],"id":41419892},{"atl":[[10.5,2]],"id":40879966},{"atl":[[5.1,1.36]],"id":41738000},{"atb":[[2.9,0]],"id":42146659},{"atl":[[4.5,2]],"id":42146659}],"con":true,"img":false}]}
{"op":"mcm","clk":"5354113304","pt":1646221532566,"mc":[{"id":"1.195453782","rc":[{"atb":[[4.3,0]],"id":41738000},{"atl":[[1000,0]],"id":41738000},{"atl":[[7.2,8.06]],"id":39594698}],"con":true,"img":false}]}
{"op":"mcm","clk":"5354113312","pt":1646221532675,"mc":[{"id":"1.195453782","rc":[{"atl":[[5.1,2.36]],"id":41738000}],"con":true,"img":false}]}
{"op":"mcm","clk":"5354113394","pt":1646221533399,"mc":[{"id":"1.195453782","rc":[{"atl":[[4.3,3]],"id":41738000}],"con":true,"img":false}]}
{"op":"mcm","clk":"5354113419","pt":1646221533605,"mc":[{"id":"1.195453782","rc":[{"atl":[[4.3,0],[5.1,0.36]],"id":41738000},{"trd":[[4.3,12.82]],"ltp":4.3,"tv":12.82,"id":41738000}],"con":true,"img":false}]}
{"op":"mcm","clk":"5354113448","pt":1646221533769,"mc":[{"id":"1.195453782","rc":[{"atl":[[1000,4]],"id":41738000}],"con":true,"img":false}]}
{"op":"mcm","clk":"5354113477","pt":1646221533981,"mc":[{"id":"1.195453782","rc":[{"atl":[[1000,2]],"id":41738000}],"con":true,"img":false}]}
{"op":"mcm","clk":"5354113503","pt":1646221534181,"mc":[{"id":"1.195453782","rc":[{"atl":[[1000,0]],"id":41738000}],"con":true,"img":false}]}
{"op":"mcm","clk":"5354113514","pt":1646221534292,"mc":[{"id":"1.195453782","rc":[{"atl":[[5.1,2.36]],"id":41738000}],"con":true,"img":false}]}
{"op":"mcm","clk":"5354113547","pt":1646221534600,"mc":[{"id":"1.195453782","rc":[{"atl":[[100,2]],"id":39307895},{"atl":[[6.6,0]],"id":42146659}],"con":true,"img":false}]}
{"op":"mcm","clk":"5354113558","pt":1646221534702,"mc":[{"id":"1.195453782","rc":[{"atl":[[90,2.72]],"id":39307895},{"atl":[[6.2,34.11]],"id":42146659}],"con":true,"img":false}]}
{"op":"mcm","clk":"5354113579","pt":1646221534864,"mc":[{"id":"1.195453782","rc":[{"atl":[[90,4.72],[95,0.09],[100,0]],"id":39307895},{"atb":[[4.3,3]],"id":41738000}],"con":true,"img":false}]}
{"op":"mcm","clk":"5354113595","pt":1646221534968,"mc":[{"id":"1.195453782","rc":[{"atl":[[85,2]],"id":39307895}],"con":true,"img":false}]}
{"op":"mcm","clk":"5354113688","pt":1646221535792,"mc":[{"id":"1.195453782","rc":[{"atl":[[4.4,3]],"id":41738000}],"con":true,"img":false}]}
{"op":"mcm","clk":"5354113703","pt":1646221535898,"mc":[{"id":"1.195453782","rc":[{"atl":[[4.4,0]],"id":41738000},{"trd":[[4.4,18]],"ltp":4.4,"tv":18.0,"id":41738000}],"con":true,"img":false}]}
{"op":"mcm","clk":"5354113726","pt":1646221536001,"mc":[{"id":"1.195453782","rc":[{"atl":[[5.1,1.36]],"id":41738000}],"con":true,"img":false}]}
{"op":"mcm","clk":"5354113768","pt":1646221536211,"mc":[{"id":"1.195453782","rc":[{"atl":[[1000,2]],"id":41738000}],"con":true,"img":false}]}
{"op":"mcm","clk":"5354113791","pt":1646221536368,"mc":[{"id":"1.195453782","rc":[{"atl":[[1000,1]],"id":41738000}],"con":true,"img":false}]}
{"op":"mcm","clk":"5354113814","pt":1646221536576,"mc":[{"id":"1.195453782","rc":[{"atl":[[1000,0]],"id":41738000}],"con":true,"img":false}]}
{"op":"mcm","clk":"5354113826","pt":1646221536686,"mc":[{"id":"1.195453782","rc":[{"atl":[[5.1,2.36]],"id":41738000}],"con":true,"img":false}]}
{"op":"mcm","clk":"5354113873","pt":1646221537204,"mc":[{"id":"1.195453782","rc":[{"atb":[[4.4,3]],"id":41738000}],"con":true,"img":false}]}
{"op":"mcm","clk":"5354113903","pt":1646221537511,"mc":[{"id":"1.195453782","rc":[{"atb":[[3.85,0],[3.9,71.95]],"id":39594698}],"con":true,"img":false}]}
{"op":"mcm","clk":"5354113922","pt":1646221537673,"mc":[{"id":"1.195453782","rc":[{"atb":[[2.98,37.88]],"id":41419892},{"atb":[[3.85,26.32]],"id":40879966}],"con":true,"img":false}]}
{"op":"mcm","clk":"5354114002","pt":1646221538086,"mc":[{"id":"1.195453782","rc":[{"atl":[[4.5,3]],"id":41738000}],"con":true,"img":false}]}
{"op":"mcm","clk":"5354114018","pt":1646221538191,"mc":[{"id":"1.195453782","rc":[{"atl":[[4.5,0]],"id":41738000},{"trd":[[4.5,6]],"ltp":4.5,"tv":6.0,"id":41738000}],"con":true,"img":false}]}
{"op":"mcm","clk":"5354114106","pt":1646221538814,"mc":[{"id":"1.195453782","rc":[{"atb":[[4,0],[3.9,0]],"id":40879966},{"atb":[[3.05,59.93],[2.92,0],[3.2,3]],"id":42146659},{"atl":[[4.8,0],[4.5,0],[4.6,0],[5.5,0],[5.7,4.26],[4.7,0]],"id":42146659}],"con":true,"img":false}]}
{"op":"mcm","clk":"5354114134","pt":1646221539022,"mc":[{"id":"1.195453782","rc":[{"atl":[[6.4,0],[6.2,52.63]],"id":42146659}],"con":true,"img":false}]}
{"op":"mcm","clk":"5354114140","pt":1646221539075,"mc":[{"id":"1.195453782","rc":[{"atl":[[1000,2]],"id":42146659}],"con":true,"img":false}]}
{"op":"mcm","clk":"5354114153","pt":1646221539193,"mc":[{"id":"1.195453782","rc":[{"atl":[[1000,4]],"id":42146659}],"con":true,"img":false}]}
{"op":"mcm","clk":"5354114162","pt":1646221539284,"mc":[{"id":"1.195453782","rc":[{"atl":[[1000,3]],"id":42146659}],"con":true,"img":false}]}
{"op":"mcm","clk":"5354114172","pt":1646221539388,"mc":[{"id":"1.195453782","rc":[{"atl":[[1000,2]],"id":42146659}],"con":true,"img":false}]}
{"op":"mcm","clk":"5354114185","pt":1646221539490,"mc":[{"id":"1.195453782","rc":[{"atl":[[1000,1]],"id":42146659}],"con":true,"img":false}]}
{"op":"mcm","clk":"5354114197","pt":1646221539595,"mc":[{"id":"1.195453782","rc":[{"atl":[[1000,0],[5.6,1]],"id":42146659}],"con":true,"img":false}]}
{"op":"mcm","clk":"5354114211","pt":1646221539701,"mc":[{"id":"1.195453782","rc":[{"atb":[[4.5,3]],"id":41738000},{"atl":[[5.6,2]],"id":42146659}],"con":true,"img":false}]}
{"op":"mcm","clk":"5354114273","pt":1646221540189,"mc":[{"id":"1.195453782","rc":[{"atb":[[3.5,3],[3.3,8.7]],"id":41419892},{"atl":[[8.2,0],[12.5,0],[13,1.67],[8.4,0],[8.6,0],[8.8,0]],"id":41419892},{"atb":[[4.4,8.88]],"id":40879966},{"atl":[[10.5,0],[11,0],[11.5,0],[12,0],[17,0],[17.5,1.21]],"id":40879966},{"atb":[[3.05,62.93]],"id":42146659}],"con":true,"img":false}]}
{"op":"mcm","clk":"5354114287","pt":1646221540287,"mc":[{"id":"1.195453782","rc":[{"atl":[[15.5,1.38]],"id":43167137},{"atb":[[4.8,5.26]],"id":40879966}],"con":true,"img":false}]}
{"op":"mcm","clk":"5354114298","pt":1646221540388,"mc":[{"id":"1.195453782","rc":[{"atl":[[16,8.87]],"id":43167137},{"atb":[[7.4,0],[2.6,48],[2.98,0],[3.5,0],[3.3,0],[3.05,0],[3.15,0],[2.78,11.24],[2.68,11.9]],"id":41419892},{"atl":[[12.5,1.74],[13,0],[1000,2],[8.8,2]],"id":41419892},{"atb":[[4.4,0],[4.5,5.71],[9.8,3.13]],"id":40879966},{"atl":[[12,4],[1000,2],[17.5,0],[17,1.25]],"id":40879966},{"atl":[[15.5,8.28],[18,0],[4.6,3]],"id":41738000},{"atb":[[2.72,50.7],[2.84,40.76],[3.3,69.78],[3.05,50.17],[3.2,0],[3.15,9.3]],"id":42146659},{"atl":[[4.8,3],[6.4,18.52],[6.2,34.11],[5.5,4.44]],"id":42146659},{"atl":[[6.8,0],[7,12.75]],"id":39594698}],"con":true,"img":false}]}
{"op":"mcm","clk":"5354114314","pt":1646221540489,"mc":[{"id":"1.195453782","rc":[{"atl":[[24,0],[27,3.85]],"id":40879966}],"con":true,"img":false}]}
{"op":"mcm","clk":"5354114327","pt":1646221540599,"mc":[{"id":"1.195453782","rc":[{"atb":[[6,53.27]],"id":41419892},{"atl":[[1000,1]],"id":41419892},{"atl":[[1000,1]],"id":40879966},{"atb":[[2.8,32.7]],"id":41738000},{"atl":[[5.1,1.36]],"id":41738000},{"atb":[[3.5,78.74]],"id":39594698}],"con":true,"img":false}]}
{"op":"mcm","clk":"5354114345","pt":1646221540699,"mc":[{"id":"1.195453782","rc":[{"atb":[[4.4,32.7]],"id":43167137},{"atb":[[7.8,51.23]],"id":40879966},{"atb":[[28,5.83]],"id":39307895},{"atb":[[3.3,86.13]],"id":42146659}],"con":true,"img":false}]}
{"op":"mcm","clk":"5354114358","pt":1646221540803,"mc":[{"id":"1.195453782","rc":[{"atb":[[5.4,9.41]],"id":43167137},{"atl":[[1000,0]],"id":41419892},{"atl":[[1000,0]],"id":40879966},{"atl":[[5.6,1]],"id":42146659}],"con":true,"img":false}]}
{"op":"mcm","clk":"5354114373","pt":1646221540909,"mc":[{"id":"1.195453782","rc":[{"atl":[[12.5,2.74]],"id":41419892},{"atl":[[18,1]],"id":40879966},{"atl":[[4.7,1]],"id":42146659}],"con":true,"img":false}]}
{"op":"mcm","clk":"5354114396","pt":1646221541150,"mc":[{"id":"1.195453782","rc":[{"atl":[[1000,2]],"id":41419892},{"atl":[[18,0]],"id":40879966},{"atl":[[5.1,0.36]],"id":41738000}],"con":true,"img":false}]}
{"op":"mcm","clk":"5354114416","pt":1646221541309,"mc":[{"id":"1.195453782","rc":[{"atl":[[12.5,1.74],[1000,1]],"id":41419892},{"atl":[[5.6,0]],"id":42146659}],"con":true,"img":false}]}
{"op":"mcm","clk":"5354114428","pt":1646221541414,"mc":[{"id":"1.195453782","rc":[{"atl":[[8.6,1]],"id":41419892},{"atl":[[4.7,2]],"id":42146659}],"con":true,"img":false}]}
{"op":"mcm","clk":"5354114439","pt":1646221541519,"mc":[{"id":"1.195453782","rc":[{"atl":[[1000,0]],"id":41419892}],"con":true,"img":false}]}
{"op":"mcm","clk":"5354114453","pt":1646221541584,"mc":[{"id":"1.195453782","rc":[{"atl":[[8.6,2]],"id":41419892}],"con":true,"img":false}]}
{"op":"mcm","clk":"5354114501","pt":1646221541991,"mc":[{"id":"1.195453782","rc":[{"atl":[[4.6,0]],"id":41738000}],"con":true,"img":false}]}
{"op":"mcm","clk":"5354114522","pt":1646221542199,"mc":[{"id":"1.195453782","rc":[{"atl":[[1000,4]],"id":41738000}],"con":true,"img":false}]}
{"op":"mcm","clk":"5354114533","pt":1646221542310,"mc":[{"id":"1.195453782","rc":[{"atb":[[4.5,0]],"id":41738000}],"con":true,"img":false}]}
{"op":"mcm","clk":"5354114545","pt":1646221542410,"mc":[{"id":"1.195453782","rc":[{"atb":[[4.6,12.78]],"id":43167137},{"atl":[[10,0],[11.5,4.15]],"id":43167137},{"atb":[[6.2,10.4]],"id":41419892},{"atl":[[15.5,0]],"id":41419892},{"atb":[[7.8,41.47]],"id":40879966},{"atl":[[19,0],[23,0]],"id":40879966},{"atb":[[28,3.1]],"id":39307895},{"atl":[[150,0],[90,2],[110,0.39]],"id":39307895},{"atb":[[3,19.8]],"id":41738000},{"atl":[[6.4,8.07],[5.8,0],[1000,2]],"id":41738000},{"atb":[[3.35,17.5]],"id":42146659},{"atl":[[6.2,24.04]],"id":42146659},{"atb":[[3.5,50.44]],"id":39594698},{"atl":[[7.4,0]],"id":39594698}],"con":true,"img":false}]}
{"op":"mcm","clk":"5354114559","pt":1646221542513,"mc":[{"id":"1.195453782","rc":[{"atl":[[17.5,8.36]],"id":41419892},{"atl":[[20,2.92],[26,6.54]],"id":40879966},{"atb":[[25,2.72]],"id":39307895},{"atl":[[240,2.72]],"id":39307895},{"atl":[[7,10.07]],"id":42146659},{"atl":[[9,16.59]],"id":39594698}],"con":true,"img":false}]}
{"op":"mcm","clk":"5354114569","pt":1646221542619,"mc":[{"id":"1.195453782","rc":[{"atl":[[8.8,0]],"id":41419892},{"atb":[[4.8,0]],"id":40879966},{"atl":[[11.5,4]],"id":40879966},{"atl":[[1000,0]],"id":41738000},{"atb":[[3.3,77.43]],"id":42146659},{"atl":[[4.7,4]],"id":42146659},{"atl":[[6.8,3.45]],"id":39594698}],"con":true,"img":false}]}
{"op":"mcm","clk":"5354114581","pt":1646221542681,"mc":[{"id":"1.195453782","rc":[{"atb":[[4.4,0]],"id":41738000},{"atl":[[5.1,2.36]],"id":41738000}],"con":true,"img":false}]}
{"op":"mcm","clk":"5354114678","pt":1646221543616,"mc":[{"id":"1.195453782","rc":[{"atl":[[4.4,3]],"id":41738000}],"con":true,"img":false}]}
{"op":"mcm","clk":"5354114699","pt":1646221543828,"mc":[{"id":"1.195453782","rc":[{"atl":[[4.4,0],[5.1,1.36]],"id":41738000},{"trd":[[4.4,24.01]],"ltp":4.4,"tv":24.01,"id":41738000}],"con":true,"img":false}]}
{"op":"mcm","clk":"5354114719","pt":1646221543988,"mc":[{"id":"1.195453782","rc":[{"atl":[[9.8,1]],"id":43167137},{"atl":[[8.6,1]],"id":41419892}],"con":true,"img":false}]}
{"op":"mcm","clk":"5354114733","pt":1646221544096,"mc":[{"id":"1.195453782","rc":[{"atl":[[11,1]],"id":43167137},{"atl":[[12,1]],"id":41419892}],"con":true,"img":false}]}
{"op":"mcm","clk":"5354114839","pt":1646221544989,"mc":[{"id":"1.195453782","rc":[{"atb":[[5.4,0]],"id":43167137}],"con":true,"img":false}]}
{"op":"mcm","clk":"5354114897","pt":1646221545406,"mc":[{"id":"1.195453782","rc":[{"atl":[[11,2.39]],"id":43167137},{"spn":5.45,"spf":1.0,"id":43167137},{"atl":[[13.5,1.26]],"id":41419892},{"spn":9.65,"spf":1.0,"id":40879966},{"spn":30.14,"spf":1.0,"id":39307895},{"spn":4.65,"spf":"NaN","id":41738000},{"spn":4.45,"spf":"NaN","id":42146659}],"con":true,"img":false}]}
{"op":"mcm","clk":"5354114911","pt":1646221545510,"mc":[{"id":"1.195453782","rc":[{"atl":[[4.4,3]],"id":41738000}],"con":true,"img":false}]}
{"op":"mcm","clk":"5354114937","pt":1646221545719,"mc":[{"id":"1.195453782","rc":[{"atl":[[5.1,0.36]],"id":41738000}],"con":true,"img":false}]}
{"op":"mcm","clk":"5354114961","pt":1646221545930,"mc":[{"id":"1.195453782","rc":[{"atl":[[9.8,0]],"id":43167137},{"atl":[[8.6,0]],"id":41419892}],"con":true,"img":false}]}
{"op":"mcm","clk":"5354114973","pt":1646221545995,"mc":[{"id":"1.195453782","rc":[{"atl":[[10.5,1]],"id":43167137},{"atl":[[12,2]],"id":41419892}],"con":true,"img":false}]}
{"op":"mcm","clk":"5354115053","pt":1646221546715,"mc":[{"id":"1.195453782","rc":[{"atl":[[4.4,0],[5.1,0],[5,0]],"id":41738000},{"trd":[[5.1,0.71],[5,0.69],[4.4,30.01]],"ltp":5.1,"tv":31.41,"id":41738000}],"con":true,"img":false}]}
{"op":"mcm","clk":"5354115079","pt":1646221546887,"mc":[{"id":"1.195453782","rc":[{"atb":[[4.3,3.36]],"id":41738000},{"atl":[[1000,4]],"id":41738000}],"con":true,"img":false}]}
{"op":"mcm","clk":"5354115103","pt":1646221547093,"mc":[{"id":"1.195453782","rc":[{"atl":[[1000,2]],"id":41738000}],"con":true,"img":false}]}
{"op":"mcm","clk":"5354115126","pt":1646221547299,"mc":[{"id":"1.195453782","rc":[{"atl":[[1000,0]],"id":41738000},{"atl":[[7,3.33]],"id":39594698}],"con":true,"img":false}]}
{"op":"mcm","clk":"5354115138","pt":1646221547402,"mc":[{"id":"1.195453782","rc":[{"atl":[[5.1,2]],"id":41738000},{"atl":[[7.2,17.48]],"id":39594698}],"con":true,"img":false}]}
{"op":"mcm","clk":"5354115164","pt":1646221547609,"mc":[{"id":"1.195453782","rc":[{"atl":[[11,3]],"id":40879966},{"atl":[[4.6,4]],"id":42146659}],"con":true,"img":false}]}
{"op":"mcm","clk":"5354115183","pt":1646221547820,"mc":[{"id":"1.195453782","rc":[{"atl":[[4.7,3]],"id":42146659}],"con":true,"img":false}]}
{"op":"mcm","clk":"5354115253","pt":1646221548403,"mc":[{"id":"1.195453782","rc":[{"atb":[[4.4,3]],"id":41738000}],"con":true,"img":false}]}
{"op":"mcm","clk":"5354115294","pt":1646221548715,"mc":[{"id":"1.195453782","rc":[{"atb":[[4.4,3.35]],"id":41738000}],"con":true,"img":false}]}
{"op":"mcm","clk":"5354115314","pt":1646221548925,"mc":[{"id":"1.195453782","rc":[{"atl":[[4.7,2]],"id":42146659}],"con":true,"img":false}]}
{"op":"mcm","clk":"5354115350","pt":1646221549194,"mc":[{"id":"1.195453782","rc":[{"atl":[[4.5,3]],"id":41738000}],"con":true,"img":false}]}
{"op":"mcm","clk":"5354115363","pt":1646221549293,"mc":[{"id":"1.195453782","rc":[{"atl":[[4.5,0.71]],"id":41738000},{"trd":[[4.5,10.58]],"ltp":4.5,"tv":10.58,"id":41738000}],"con":true,"img":false}]}
{"op":"mcm","clk":"5354115374","pt":1646221549395,"mc":[{"id":"1.195453782","rc":[{"atl":[[5.1,0]],"id":41738000}],"con":true,"img":false}]}
{"op":"mcm","clk":"5354115390","pt":1646221549503,"mc":[{"id":"1.195453782","rc":[{"atl":[[4.5,0]],"id":41738000},{"trd":[[4.5,12]],"ltp":4.5,"tv":12.0,"id":41738000}],"con":true,"img":false}]}
{"op":"mcm","clk":"5354115416","pt":1646221549710,"mc":[{"id":"1.195453782","rc":[{"atl":[[1000,4]],"id":41738000}],"con":true,"img":false}]}
{"op":"mcm","clk":"5354115438","pt":1646221549918,"mc":[{"id":"1.195453782","rc":[{"atl":[[1000,2]],"id":41738000}],"con":true,"img":false}]}
{"op":"mcm","clk":"5354115463","pt":1646221550128,"mc":[{"id":"1.195453782","rc":[{"atl":[[1000,0],[5.1,2.52]],"id":41738000}],"con":true,"img":false}]}
{"op":"mcm","clk":"5354115477","pt":1646221550195,"mc":[{"id":"1.195453782","rc":[{"atl":[[5.1,4.52]],"id":41738000}],"con":true,"img":false}]}
{"op":"mcm","clk":"5354115505","pt":1646221550394,"mc":[{"id":"1.195453782","rc":[{"atl":[[5.1,2]],"id":41738000}],"con":true,"img":false}]}
{"op":"mcm","clk":"5354115538","pt":1646221550703,"mc":[{"id":"1.195453782","rc":[{"atb":[[2.74,28.74]],"id":41419892},{"atl":[[16.5,3.23]],"id":41738000},{"atb":[[3.05,74.56]],"id":42146659},{"atl":[[5.7,10.64]],"id":42146659}],"con":true,"img":false}]}
{"op":"mcm","clk":"5354115550","pt":1646221550808,"mc":[{"id":"1.195453782","rc":[{"atb":[[4.3,15.15]],"id":40879966}],"con":true,"img":false}]}
{"op":"mcm","clk":"5354115624","pt":1646221551395,"mc":[{"id":"1.195453782","rc":[{"atb":[[7.8,32.7]],"id":40879966},{"atl":[[6.4,0]],"id":41738000}],"con":true,"img":false}]}
{"op":"mcm","clk":"5354115639","pt":1646221551496,"mc":[{"id":"1.195453782","rc":[{"atb":[[7.4,8.77]],"id":40879966},{"atl":[[6.8,8.07]],"id":41738000}],"con":true,"img":false}]}
{"op":"mcm","clk":"5354115801","pt":1646221552804,"mc":[{"id":"1.195453782","rc":[{"atb":[[4.5,3]],"id":41738000},{"atl":[[7.6,30.3]],"id":39594698}],"con":true,"img":false}]}
{"op":"mcm","clk":"5354115811","pt":1646221552911,"mc":[{"id":"1.195453782","rc":[{"atl":[[7.6,11.35]],"id":39594698}],"con":true,"img":false}]}
{"op":"mcm","clk":"5354115824","pt":1646221553018,"mc":[{"id":"1.195453782","rc":[{"atl":[[10.5,3]],"id":40879966},{"atb":[[4.5,3.34]],"id":41738000},{"atl":[[19,0],[20,0],[22,0]],"id":41738000},{"atb":[[2.8,0],[2.84,0],[2.88,0]],"id":42146659},{"atl":[[4.5,2]],"id":42146659}],"con":true,"img":false}]}
{"op":"mcm","clk":"5354115833","pt":1646221553122,"mc":[{"id":"1.195453782","rc":[{"atb":[[3.85,0]],"id":40879966}],"con":true,"img":false}]}
{"op":"mcm","clk":"5354115931","pt":1646221553936,"mc":[{"id":"1.195453782","rc":[{"atl":[[4.6,3]],"id":41738000}],"con":true,"img":false}]}
{"op":"mcm","clk":"5354115950","pt":1646221554116,"mc":[{"id":"1.195453782","rc":[{"atl":[[5.1,0]],"id":41738000}],"con":true,"img":false}]}
{"op":"mcm","clk":"5354116057","pt":1646221555003,"mc":[{"id":"1.195453782","rc":[{"atb":[[4.5,0.34]],"id":41738000}],"con":true,"img":false}]}
{"op":"mcm","clk":"5354116119","pt":1646221555522,"mc":[{"id":"1.195453782","rc":[{"atb":[[4.4,0.35]],"id":41738000}],"con":true,"img":false}]}
{"op":"mcm","clk":"5354116260","pt":1646221556823,"mc":[{"id":"1.195453782","rc":[{"atb":[[4.3,0.36]],"id":41738000}],"con":true,"img":false}]}
{"op":"mcm","clk":"5354116280","pt":1646221557031,"mc":[{"id":"1.195453782","rc":[{"atb":[[4.4,0]],"id":41738000}],"con":true,"img":false}]}
{"op":"mcm","clk":"5354116317","pt":1646221557298,"mc":[{"id":"1.195453782","rc":[{"atb":[[4.2,0]],"id":41738000}],"con":true,"img":false}]}
{"op":"mcm","clk":"5354116344","pt":1646221557501,"mc":[{"id":"1.195453782","rc":[{"atl":[[10.5,0]],"id":43167137},{"atl":[[12,1]],"id":41419892},{"atl":[[85,1]],"id":39307895},{"atb":[[4.1,0]],"id":41738000}],"con":true,"img":false}]}
{"op":"mcm","clk":"5354116358","pt":1646221557608,"mc":[{"id":"1.195453782","rc":[{"atl":[[90,0],[110,2.39]],"id":39307895}],"con":true,"img":false}]}
{"op":"mcm","clk":"5354116372","pt":1646221557711,"mc":[{"id":"1.195453782","rc":[{"atl":[[1000,2]],"id":41738000}],"con":true,"img":false}]}
{"op":"mcm","clk":"5354116405","pt":1646221557919,"mc":[{"id":"1.195453782","rc":[{"atl":[[1000,1]],"id":41738000}],"con":true,"img":false}]}
{"op":"mcm","clk":"5354116427","pt":1646221558130,"mc":[{"id":"1.195453782","rc":[{"atl":[[1000,0]],"id":41738000}],"con":true,"img":false}]}
{"op":"mcm","clk":"5354116438","pt":1646221558233,"mc":[{"id":"1.195453782","rc":[{"atb":[[4.5,0]],"id":41738000},{"atl":[[4.5,0.66]],"id":41738000},{"trd":[[4.5,12.68]],"ltp":4.5,"tv":12.68,"id":41738000}],"con":true,"img":false}]}
{"op":"mcm","clk":"5354116467","pt":1646221558405,"mc":[{"id":"1.195453782","rc":[{"atl":[[85,0]],"id":39307895},{"atl":[[4.5,0]],"id":41738000},{"trd":[[4.5,14]],"ltp":4.5,"tv":14.0,"id":41738000}],"con":true,"img":false}]}
{"op":"mcm","clk":"5354116478","pt":1646221558502,"mc":[{"id":"1.195453782","rc":[{"atl":[[100,1]],"id":39307895}],"con":true,"img":false}]}
{"op":"mcm","clk":"5354116489","pt":1646221558637,"mc":[{"id":"1.195453782","rc":[{"atb":[[4.3,0]],"id":41738000},{"atl":[[4.3,2.64]],"id":41738000},{"trd":[[4.3,13.54]],"ltp":4.3,"tv":13.54,"id":41738000}],"con":true,"img":false}]}
{"op":"mcm","clk":"5354116501","pt":1646221558736,"mc":[{"id":"1.195453782","rc":[{"atb":[[1.03,2]],"id":41738000}],"con":true,"img":false}]}
{"op":"mcm","clk":"5354116510","pt":1646221558840,"mc":[{"id":"1.195453782","rc":[{"atl":[[4.3,0]],"id":41738000},{"trd":[[4.3,18.83]],"ltp":4.3,"tv":18.83,"id":41738000}],"con":true,"img":false}]}
{"op":"mcm","clk":"5354116525","pt":1646221558946,"mc":[{"id":"1.195453782","rc":[{"atb":[[1.03,0.39]],"id":41738000}],"con":true,"img":false}]}
{"op":"mcm","clk":"5354116552","pt":1646221559107,"mc":[{"id":"1.195453782","rc":[{"atb":[[1.03,0]],"id":41738000}],"con":true,"img":false}]}
{"op":"mcm","clk":"5354116565","pt":1646221559212,"mc":[{"id":"1.195453782","rc":[{"atb":[[3.95,0.39]],"id":41738000}],"con":true,"img":false}]}
{"op":"mcm","clk":"5354116588","pt":1646221559415,"mc":[{"id":"1.195453782","rc":[{"atb":[[3.85,3.37]],"id":41738000}],"con":true,"img":false}]}
{"op":"mcm","clk":"5354116642","pt":1646221559932,"mc":[{"id":"1.195453782","rc":[{"atb":[[3.9,0]],"id":41738000}],"con":true,"img":false}]}
{"op":"mcm","clk":"5354116702","pt":1646221560406,"mc":[{"id":"1.195453782","rc":[{"atl":[[4.9,3]],"id":41738000}],"con":true,"img":false}]}
{"op":"mcm","clk":"5354116744","pt":1646221560819,"mc":[{"id":"1.195453782","rc":[{"atl":[[17.5,4.55]],"id":41738000}],"con":true,"img":false}]}
{"op":"mcm","clk":"5354116753","pt":1646221560927,"mc":[{"id":"1.195453782","rc":[{"atb":[[2.7,44.12]],"id":41419892},{"atb":[[4.1,24.19]],"id":40879966},{"atb":[[2.98,37.88]],"id":42146659}],"con":true,"img":false}]}
{"op":"mcm","clk":"5354116767","pt":1646221561029,"mc":[{"id":"1.195453782","rc":[{"atb":[[3.95,0]],"id":41738000}],"con":true,"img":false}]}
{"op":"mcm","clk":"5354116795","pt":1646221561206,"mc":[{"id":"1.195453782","rc":[{"atb":[[1.01,4]],"id":41738000}],"con":true,"img":false}]}
{"op":"mcm","clk":"5354116822","pt":1646221561404,"mc":[{"id":"1.195453782","rc":[{"atb":[[3.85,3],[1.01,3.15]],"id":41738000}],"con":true,"img":false}]}
{"op":"mcm","clk":"5354116845","pt":1646221561612,"mc":[{"id":"1.195453782","rc":[{"atb":[[1.01,2]],"id":41738000}],"con":true,"img":false}]}
{"op":"mcm","clk":"5354116869","pt":1646221561821,"mc":[{"id":"1.195453782","rc":[{"atb":[[3.9,1.15]],"id":41738000}],"con":true,"img":false}]}
{"op":"mcm","clk":"5354116964","pt":1646221562603,"mc":[{"id":"1.195453782","rc":[{"atb":[[3.85,0]],"id":41738000}],"con":true,"img":false}]}
{"op":"mcm","clk":"5354116984","pt":1646221562811,"mc":[{"id":"1.195453782","rc":[{"atb":[[3.9,0]],"id":41738000}],"con":true,"img":false}]}
{"op":"mcm","clk":"5354117008","pt":1646221563020,"mc":[{"id":"1.195453782","rc":[{"atb":[[1.01,4]],"id":41738000},{"atl":[[4.6,3.31]],"id":41738000},{"atl":[[8,17.86]],"id":39594698}],"con":true,"img":false}]}
{"op":"mcm","clk":"5354117027","pt":1646221563258,"mc":[{"id":"1.195453782","rc":[{"atb":[[2.4,0],[2.24,65.4]],"id":43167137},{"atb":[[3.6,5],[1.01,3.18]],"id":41738000},{"atl":[[15.5,6.9],[16.5,0],[17,9.75]],"id":41738000},{"atb":[[3.95,53.71],[3.9,37.47]],"id":39594698},{"atl":[[8,0],[6.8,0],[7.2,9.42],[7.6,0]],"id":39594698}],"con":true,"img":false}]}
{"op":"mcm","clk":"5354117050","pt":1646221563433,"mc":[{"id":"1.195453782","rc":[{"atb":[[1.01,2]],"id":41738000}],"con":true,"img":false}]}
{"op":"mcm","clk":"5354117068","pt":1646221563539,"mc":[{"id":"1.195453782","rc":[{"atb":[[3.8,1.18]],"id":41738000}],"con":true,"img":false}]}
{"op":"mcm","clk":"5354117114","pt":1646221563911,"mc":[{"id":"1.195453782","rc":[{"atl":[[11,1]],"id":43167137},{"atl":[[13.5,0]],"id":41419892}],"con":true,"img":false}]}
{"op":"mcm","clk":"5354117125","pt":1646221564011,"mc":[{"id":"1.195453782","rc":[{"atl":[[1000,1.39]],"id":43167137},{"atl":[[1000,1.26]],"id":41419892}],"con":true,"img":false}]}
{"op":"mcm","clk":"5354117172","pt":1646221564434,"mc":[{"id":"1.195453782","rc":[{"atb":[[3.6,2]],"id":41738000}],"con":true,"img":false}]}
{"op":"mcm","clk":"5354117243","pt":1646221565127,"mc":[{"id":"1.195453782","rc":[{"atl":[[4.8,3]],"id":41738000}],"con":true,"img":false}]}
{"op":"mcm","clk":"5354117336","pt":1646221566012,"mc":[{"id":"1.195453782","rc":[{"atb":[[4.1,24.19],[5.5,14.84]],"id":43167137},{"atb":[[5.6,0]],"id":41419892},{"atb":[[7.2,0]],"id":40879966},{"atb":[[24,0]],"id":39307895},{"atb":[[2.76,0]],"id":41738000},{"atb":[[3.25,0]],"id":42146659},{"atb":[[3.35,31.91]],"id":39594698}],"con":true,"img":false}]}
{"op":"mcm","clk":"5354117455","pt":1646221567015,"mc":[{"id":"1.195453782","rc":[{"atb":[[7.4,0],[6.8,13.18]],"id":40879966},{"atl":[[7.8,6.4],[7.2,0]],"id":39594698}],"con":true,"img":false}]}
{"op":"mcm","clk":"5354117469","pt":1646221567115,"mc":[{"id":"1.195453782","rc":[{"atb":[[3.75,0],[1.04,1.66]],"id":41738000}],"con":true,"img":false}]}
{"op":"mcm","clk":"5354117499","pt":1646221567325,"mc":[{"id":"1.195453782","rc":[{"atb":[[1.04,1.65]],"id":41738000}],"con":true,"img":false}]}
{"op":"mcm","clk":"5354117533","pt":1646221567529,"mc":[{"id":"1.195453782","rc":[{"atb":[[1.04,0]],"id":41738000}],"con":true,"img":false}]}
{"op":"mcm","clk":"5354117548","pt":1646221567632,"mc":[{"id":"1.195453782","rc":[{"atb":[[3.45,1.65]],"id":41738000}],"con":true,"img":false}]}
{"op":"mcm","clk":"5354117572","pt":1646221567840,"mc":[{"id":"1.195453782","rc":[{"atb":[[3.8,0]],"id":41738000}],"con":true,"img":false}]}
{"op":"mcm","clk":"5354117594","pt":1646221568049,"mc":[{"id":"1.195453782","rc":[{"atb":[[1.01,4]],"id":41738000}],"con":true,"img":false}]}
{"op":"mcm","clk":"5354117618","pt":1646221568217,"mc":[{"id":"1.195453782","rc":[{"atb":[[1.01,3.23],[3.55,1.18]],"id":41738000}],"con":true,"img":false}]}
{"op":"mcm","clk":"5354117628","pt":1646221568314,"mc":[{"id":"1.195453782","rc":[{"atb":[[3.65,4]],"id":41738000}],"con":true,"img":false}]}
{"op":"mcm","clk":"5354117643","pt":1646221568421,"mc":[{"id":"1.195453782","rc":[{"atb":[[1.01,2]],"id":41738000}],"con":true,"img":false}]}
{"op":"mcm","clk":"5354117659","pt":1646221568521,"mc":[{"id":"1.195453782","rc":[{"atb":[[3.6,2.36],[3.65,5.23]],"id":41738000}],"con":true,"img":false}]}
{"op":"mcm","clk":"5354117723","pt":1646221569040,"mc":[{"id":"1.195453782","rc":[{"atl":[[11.5,0]],"id":43167137}],"con":true,"img":false}]}
{"op":"mcm","clk":"5354117733","pt":1646221569144,"mc":[{"id":"1.195453782","rc":[{"atl":[[12,4.15]],"id":43167137}],"con":true,"img":false}]}
{"op":"mcm","clk":"5354117760","pt":1646221569350,"mc":[{"id":"1.195453782","rc":[{"atl":[[1000,0]],"id":43167137},{"atl":[[1000,0]],"id":41419892},{"atl":[[4.5,1.33]],"id":41738000}],"con":true,"img":false}]}
{"op":"mcm","clk":"5354117776","pt":1646221569406,"mc":[{"id":"1.195453782","rc":[{"atl":[[13.5,1.39]],"id":43167137},{"atl":[[13.5,1.26]],"id":41419892},{"atb":[[1.04,1.66]],"id":39307895}],"con":true,"img":false}]}
{"op":"mcm","clk":"5354117790","pt":1646221569509,"mc":[{"id":"1.195453782","rc":[{"atb":[[29,0]],"id":39307895},{"atl":[[4.5,1.63]],"id":41738000}],"con":true,"img":false}]}
{"op":"mcm","clk":"5354117800","pt":1646221569612,"mc":[{"id":"1.195453782","rc":[{"atl":[[11,0]],"id":43167137},{"atb":[[1.04,0.2]],"id":39307895}],"con":true,"img":false}]}
{"op":"mcm","clk":"5354117812","pt":1646221569716,"mc":[{"id":"1.195453782","rc":[{"atl":[[11.5,1]],"id":43167137},{"atb":[[1.04,0]],"id":39307895}],"con":true,"img":false}]}
{"op":"mcm","clk":"5354117824","pt":1646221569821,"mc":[{"id":"1.195453782","rc":[{"atb":[[40,0.2]],"id":39307895}],"con":true,"img":false}]}
{"op":"mcm","clk":"5354117875","pt":1646221570236,"mc":[{"id":"1.195453782","rc":[{"atl":[[13.5,0]],"id":43167137}],"con":true,"img":false}]}
{"op":"mcm","clk":"5354117890","pt":1646221570340,"mc":[{"id":"1.195453782","rc":[{"atl":[[11.5,2.39]],"id":43167137},{"atb":[[3.7,2.52]],"id":41738000}],"con":true,"img":false}]}
{"op":"mcm","clk":"5354117905","pt":1646221570445,"mc":[{"id":"1.195453782","rc":[{"atb":[[1.03,1.66]],"id":43167137},{"atb":[[1.03,1.66]],"id":41419892},{"atb":[[1.05,1.66]],"id":40879966},{"atb":[[1.17,1.66]],"id":39307895},{"atb":[[1.02,1.66]],"id":41738000},{"atb":[[1.02,1.66]],"id":42146659},{"atb":[[1.02,1.66]],"id":39594698}],"con":true,"img":false}]}
{"op":"mcm","clk":"5354117917","pt":1646221570507,"mc":[{"id":"1.195453782","rc":[{"atb":[[3.65,4]],"id":41738000}],"con":true,"img":false}]}
{"op":"mcm","clk":"5354117942","pt":1646221570715,"mc":[{"id":"1.195453782","rc":[{"atb":[[1.03,0.27]],"id":43167137},{"atb":[[1.03,0.22]],"id":41419892},{"atb":[[1.05,0.16]],"id":40879966},{"atb":[[1.17,0.04]],"id":39307895},{"atb":[[1.01,4],[1.02,0.44],[3.65,4.35]],"id":41738000},{"atb":[[1.02,0.41]],"id":42146659},{"atb":[[1.02,0.39]],"id":39594698}],"con":true,"img":false}]}
{"op":"mcm","clk":"5354117954","pt":1646221570817,"mc":[{"id":"1.195453782","rc":[{"atb":[[2.94,64.43]],"id":42146659},{"atb":[[3.5,66.79]],"id":39594698}],"con":true,"img":false}]}
{"op":"mcm","clk":"5354117964","pt":1646221570920,"mc":[{"id":"1.195453782","rc":[{"atb":[[1.03,0],[4.4,49.05],[5.5,0]],"id":43167137},{"atb":[[1.03,0],[6,69.62],[2.66,75.3]],"id":41419892},{"atb":[[7.8,49.05],[3.95,42.37],[1.05,0]],"id":40879966},{"atb":[[28,16.73],[1.17,0]],"id":39307895},{"atb":[[1.01,3.2],[1.02,0]],"id":41738000},{"atb":[[3.3,93.78],[1.02,0]],"id":42146659},{"atb":[[1.02,0]],"id":39594698}],"con":true,"img":false}]}
{"op":"mcm","clk":"5354117972","pt":1646221571025,"mc":[{"id":"1.195453782","rc":[{"atb":[[5.8,1.99],[5.9,0.27]],"id":43167137},{"atb":[[7.4,0.22]],"id":41419892},{"atb":[[9.8,3.29]],"id":40879966},{"atb":[[38,0.13]],"id":39307895},{"atb":[[2.8,49.05],[3.7,2.97]],"id":41738000},{"atl":[[6.8,0]],"id":41738000},{"atb":[[4,2.4]],"id":42146659},{"atb":[[4.1,2.38]],"id":39594698}],"con":true,"img":false}]}
{"op":"mcm","clk":"5354117983","pt":1646221571126,"mc":[{"id":"1.195453782","rc":[{"atb":[[1.01,3.66]],"id":43167137},{"atb":[[1.01,2]],"id":41738000},{"atl":[[6.4,8.07]],"id":41738000}],"con":true,"img":false}]}
{"op":"mcm","clk":"5354117993","pt":1646221571227,"mc":[{"id":"1.195453782","rc":[{"atb":[[1.01,3.43]],"id":43167137},{"atb":[[3.75,1.2]],"id":41738000}],"con":true,"img":false}]}
{"op":"mcm","clk":"5354118005","pt":1646221571330,"mc":[{"id":"1.195453782","rc":[{"atb":[[1.01,2]],"id":43167137},{"atb":[[3.7,3.31]],"id":41738000}],"con":true,"img":false}]}
{"op":"mcm","clk":"5354118015","pt":1646221571435,"mc":[{"id":"1.195453782","rc":[{"atb":[[5.3,1.43]],"id":43167137}],"con":true,"img":false}]}
{"op":"mcm","clk":"5354118072","pt":1646221572017,"mc":[{"id":"1.195453782","rc":[{"atl":[[4.5,0.3]],"id":41738000}],"con":true,"img":false}]}
{"op":"mcm","clk":"5354118085","pt":1646221572120,"mc":[{"id":"1.195453782","rc":[{"atl":[[1000,1.33]],"id":41738000}],"con":true,"img":false}]}
{"op":"mcm","clk":"5354118171","pt":1646221572941,"mc":[{"id":"1.195453782","rc":[{"atl":[[7.4,7.81]],"id":39594698}],"con":true,"img":false}]}
{"op":"mcm","clk":"5354118208","pt":1646221573251,"mc":[{"id":"1.195453782","rc":[{"atl":[[18,2.94]],"id":41738000}],"con":true,"img":false}]}
{"op":"mcm","clk":"5354118246","pt":1646221573517,"mc":[{"id":"1.195453782","rc":[{"atb":[[2.76,56.82],[2.24,0]],"id":43167137},{"atb":[[2.68,0]],"id":41419892},{"atb":[[3.7,7.31]],"id":41738000}],"con":true,"img":false}]}
{"op":"mcm","clk":"5354118329","pt":1646221574248,"mc":[{"id":"1.195453782","rc":[{"atl":[[4.5,3.3]],"id":41738000}],"con":true,"img":false}]}
{"op":"mcm","clk":"5354118520","pt":1646221575928,"mc":[{"id":"1.195453782","rc":[{"atl":[[4.7,3]],"id":41738000}],"con":true,"img":false}]}
{"op":"mcm","clk":"5354118566","pt":1646221576337,"mc":[{"id":"1.195453782","rc":[{"atl":[[4.5,0],[4.6,0],[4.7,0.72]],"id":41738000},{"trd":[[4.7,4.54],[4.5,20.61],[4.6,6.62]],"ltp":4.7,"tv":31.77,"id":41738000}],"con":true,"img":false}]}
{"op":"mcm","clk":"5354118576","pt":1646221576442,"mc":[{"id":"1.195453782","rc":[{"atb":[[3.75,1.54]],"id":41738000},{"atl":[[4.7,0]],"id":41738000},{"trd":[[4.7,6]],"ltp":4.7,"tv":6.0,"id":41738000}],"con":true,"img":false}]}
{"op":"mcm","clk":"5354118619","pt":1646221576857,"mc":[{"id":"1.195453782","rc":[{"atl":[[1000,2.25]],"id":41419892}],"con":true,"img":false}]}
{"op":"mcm","clk":"5354118738","pt":1646221577435,"mc":[{"id":"1.195453782","rc":[{"atl":[[1000,0]],"id":41738000}],"con":true,"img":false}]}
{"op":"mcm","clk":"5354118752","pt":1646221577535,"mc":[{"id":"1.195453782","rc":[{"atl":[[4.7,1.33]],"id":41738000}],"con":true,"img":false}]}
{"op":"mcm","clk":"5354118811","pt":1646221578057,"mc":[{"id":"1.195453782","rc":[{"atl":[[1000,0.15]],"id":41419892}],"con":true,"img":false}]}
{"op":"mcm","clk":"5354118834","pt":1646221578267,"mc":[{"id":"1.195453782","rc":[{"atb":[[5.9,0]],"id":43167137},{"atb":[[3.7,6.86]],"id":41738000},{"atl":[[4.7,16.34]],"id":41738000}],"con":true,"img":false}]}
{"op":"mcm","clk":"5354118845","pt":1646221578328,"mc":[{"id":"1.195453782","rc":[{"atb":[[5.9,0.27]],"id":43167137},{"atb":[[3.8,0.44]],"id":41738000}],"con":true,"img":false}]}
{"op":"mcm","clk":"5354118869","pt":1646221578533,"mc":[{"id":"1.195453782","rc":[{"atb":[[2.76,0],[2.24,49.91]],"id":43167137},{"atb":[[3.6,0.36],[3.8,0.78],[3.75,3.54],[3.7,2.86],[3.65,0.35]],"id":41738000},{"atl":[[15.5,8.28]],"id":41738000}],"con":true,"img":false}]}
{"op":"mcm","clk":"5354118881","pt":1646221578631,"mc":[{"id":"1.195453782","rc":[{"atl":[[1000,0]],"id":41419892}],"con":true,"img":false}]}
{"op":"mcm","clk":"5354118895","pt":1646221578736,"mc":[{"id":"1.195453782","rc":[{"atl":[[14,4]],"id":41419892},{"atb":[[3.7,0.34]],"id":41738000}],"con":true,"img":false}]}
{"op":"mcm","clk":"5354119151","pt":1646221580735,"mc":[{"id":"1.195453782","rc":[{"atl":[[4.6,2.99]],"id":41738000}],"con":true,"img":false}]}
{"op":"mcm","clk":"5354119389","pt":1646221582766,"mc":[{"id":"1.195453782","rc":[{"atl":[[7.8,17.43]],"id":39594698}],"con":true,"img":false}]}
{"op":"mcm","clk":"5354119431","pt":1646221583142,"mc":[{"id":"1.195453782","rc":[{"atb":[[5,0.49]],"id":39594698},{"atl":[[4.8,0],[4.9,0],[5,0],[4.7,0]],"id":39594698},{"trd":[[5,5.99],[4.8,7.99],[4.9,5.99],[4.7,3.99]],"ltp":5.0,"tv":23.96,"id":39594698}],"con":true,"img":false}]}
{"op":"mcm","clk":"5354119452","pt":1646221583344,"mc":[{"id":"1.195453782","rc":[{"atb":[[3.75,1.54]],"id":41738000},{"atb":[[4,14.84]],"id":39594698},{"atl":[[1000,2]],"id":39594698}],"con":true,"img":false}]}
{"op":"mcm","clk":"5354119470","pt":1646221583556,"mc":[{"id":"1.195453782","rc":[{"atb":[[3.6,4.36]],"id":41738000},{"atl":[[15.5,6.9]],"id":41738000},{"atb":[[4.3,13.56],[4,0.26]],"id":39594698},{"atl":[[1000,1],[7.2,2.74],[7,0.38]],"id":39594698}],"con":true,"img":false}]}
{"op":"mcm","clk":"5354119495","pt":1646221583764,"mc":[{"id":"1.195453782","rc":[{"atl":[[6.8,1.24],[1000,0]],"id":39594698}],"con":true,"img":false}]}
{"op":"mcm","clk":"5354119506","pt":1646221583826,"mc":[{"id":"1.195453782","rc":[{"atl":[[6.8,2.24]],"id":39594698}],"con":true,"img":false}]}
{"op":"mcm","clk":"5354119517","pt":1646221583974,"mc":[{"id":"1.195453782","rc":[{"atb":[[5,1.01]],"id":39594698},{"atl":[[6.8,2.64]],"id":39594698}],"con":true,"img":false}]}
{"op":"mcm","clk":"5354119551","pt":1646221584239,"mc":[{"id":"1.195453782","rc":[{"atb":[[3.75,0.34]],"id":41738000}],"con":true,"img":false}]}
{"op":"mcm","clk":"5354119574","pt":1646221584446,"mc":[{"id":"1.195453782","rc":[{"atb":[[1.01,4],[3.75,0]],"id":41738000}],"con":true,"img":false}]}
{"op":"mcm","clk":"5354119587","pt":1646221584552,"mc":[{"id":"1.195453782","rc":[{"atb":[[4.1,0.39]],"id":39594698}],"con":true,"img":false}]}
{"op":"mcm","clk":"5354119597","pt":1646221584653,"mc":[{"id":"1.195453782","rc":[{"atb":[[1.01,3.23]],"id":41738000},{"atb":[[4.4,2.65],[5,0.52]],"id":39594698},{"atl":[[6.8,1.4]],"id":39594698}],"con":true,"img":false}]}
{"op":"mcm","clk":"5354119610","pt":1646221584761,"mc":[{"id":"1.195453782","rc":[{"atl":[[7,1.62]],"id":39594698}],"con":true,"img":false}]}
{"op":"mcm","clk":"5354119623","pt":1646221584864,"mc":[{"id":"1.195453782","rc":[{"atb":[[1.01,2]],"id":41738000},{"atb":[[4.1,0.33]],"id":39594698}],"con":true,"img":false}]}
{"op":"mcm","clk":"5354119633","pt":1646221584924,"mc":[{"id":"1.195453782","rc":[{"atb":[[3.65,1.58]],"id":41738000}],"con":true,"img":false}]}
{"op":"mcm","clk":"5354119643","pt":1646221585024,"mc":[{"id":"1.195453782","rc":[{"atb":[[5.9,0]],"id":43167137},{"atb":[[4.5,2.52],[4.1,0]],"id":39594698}],"con":true,"img":false}]}
{"op":"mcm","clk":"5354119651","pt":1646221585128,"mc":[{"id":"1.195453782","rc":[{"atb":[[5.9,0.27]],"id":43167137},{"atb":[[5.1,0.33]],"id":39594698}],"con":true,"img":false}]}
{"op":"mcm","clk":"5354119667","pt":1646221585240,"mc":[{"id":"1.195453782","rc":[{"atb":[[5.1,0.83]],"id":39594698}],"con":true,"img":false}]}
{"op":"mcm","clk":"5354119676","pt":1646221585339,"mc":[{"id":"1.195453782","rc":[{"atb":[[4.4,0.66]],"id":39594698}],"con":true,"img":false}]}
{"op":"mcm","clk":"5354119687","pt":1646221585442,"mc":[{"id":"1.195453782","rc":[{"atb":[[1.02,1.99]],"id":39594698}],"con":true,"img":false}]}
{"op":"mcm","clk":"5354119698","pt":1646221585542,"mc":[{"id":"1.195453782","rc":[{"atl":[[4.7,15.01]],"id":41738000}],"con":true,"img":false}]}
{"op":"mcm","clk":"5354119706","pt":1646221585649,"mc":[{"id":"1.195453782","rc":[{"atb":[[5.8,0]],"id":43167137},{"atl":[[4.5,1.33]],"id":41738000}],"con":true,"img":false}]}
{"op":"mcm","clk":"5354119720","pt":1646221585752,"mc":[{"id":"1.195453782","rc":[{"atb":[[5.7,1.99]],"id":43167137}],"con":true,"img":false}]}
{"op":"mcm","clk":"5354119828","pt":1646221586648,"mc":[{"id":"1.195453782","rc":[{"atl":[[1000,2.25]],"id":41738000}],"con":true,"img":false}]}
{"op":"mcm","clk":"5354119865","pt":1646221586958,"mc":[{"id":"1.195453782","rc":[{"atb":[[3.3,77.43]],"id":42146659}],"con":true,"img":false}]}
{"op":"mcm","clk":"5354119882","pt":1646221587066,"mc":[{"id":"1.195453782","rc":[{"atb":[[4.4,32.7]],"id":43167137},{"atb":[[6,53.27]],"id":41419892},{"atb":[[7.8,32.7]],"id":40879966},{"atb":[[2.8,32.7]],"id":41738000},{"atb":[[3.5,50.44]],"id":39594698}],"con":true,"img":false}]}
{"op":"mcm","clk":"5354119893","pt":1646221587126,"mc":[{"id":"1.195453782","rc":[{"atl":[[1000,0.75]],"id":41738000}],"con":true,"img":false}]}
{"op":"mcm","clk":"5354119916","pt":1646221587336,"mc":[{"id":"1.195453782","rc":[{"atl":[[4.6,0]],"id":41738000}],"con":true,"img":false}]}
{"op":"mcm","clk":"5354119957","pt":1646221587645,"mc":[{"id":"1.195453782","rc":[{"atl":[[1000,0]],"id":41738000}],"con":true,"img":false}]}
{"op":"mcm","clk":"5354119967","pt":1646221587744,"mc":[{"id":"1.195453782","rc":[{"atb":[[3.8,0.04]],"id":41738000},{"trd":[[3.8,1.5]],"ltp":3.8,"tv":1.5,"id":41738000}],"con":true,"img":false}]}
{"op":"mcm","clk":"5354119999","pt":1646221588061,"mc":[{"id":"1.195453782","rc":[{"atb":[[3.8,0]],"id":41738000}],"con":true,"img":false}]}
{"op":"mcm","clk":"5354120008","pt":1646221588119,"mc":[{"id":"1.195453782","rc":[{"atl":[[19,4.17]],"id":41738000}],"con":true,"img":false}]}
{"op":"mcm","clk":"5354120019","pt":1646221588224,"mc":[{"id":"1.195453782","rc":[{"atl":[[4.5,0.3]],"id":41738000}],"con":true,"img":false}]}
{"op":"mcm","clk":"5354120028","pt":1646221588328,"mc":[{"id":"1.195453782","rc":[{"atl":[[4.6,1.33]],"id":41738000}],"con":true,"img":false}]}
{"op":"mcm","clk":"5354120113","pt":1646221589053,"mc":[{"id":"1.195453782","rc":[{"atb":[[4.6,35.42]],"id":43167137},{"atb":[[6.2,23.32]],"id":41419892},{"atb":[[3,55.31]],"id":41738000},{"atb":[[3.35,54.5]],"id":42146659},{"atb":[[3.5,77.82]],"id":39594698}],"con":true,"img":false}]}
{"op":"mcm","clk":"5354120140","pt":1646221589264,"mc":[{"id":"1.195453782","rc":[{"atb":[[7.4,2.22],[2.74,0],[2.78,0],[2.68,11.9],[2.7,0]],"id":41419892},{"atl":[[8.8,2]],"id":41419892},{"atl":[[120,0]],"id":39307895},{"atb":[[2.44,64.29],[2.34,0],[3.65,4.58]],"id":41738000},{"atb":[[4.3,0],[4.9,3.06]],"id":39594698}],"con":true,"img":false}]}
{"op":"mcm","clk":"5354120151","pt":1646221589332,"mc":[{"id":"1.195453782","rc":[{"atl":[[130,2]],"id":39307895}],"con":true,"img":false}]}
{"op":"mcm","clk":"5354120162","pt":1646221589435,"mc":[{"id":"1.195453782","rc":[{"atl":[[12,0]],"id":41419892}],"con":true,"img":false}]}
{"op":"mcm","clk":"5354120174","pt":1646221589531,"mc":[{"id":"1.195453782","rc":[{"atl":[[8.6,1]],"id":41419892},{"atl":[[4.5,2.82]],"id":41738000},{"atl":[[1000,2.25]],"id":39594698}],"con":true,"img":false}]}
{"op":"mcm","clk":"5354120247","pt":1646221590148,"mc":[{"id":"1.195453782","rc":[{"atl":[[4.6,0]],"id":41738000}],"con":true,"img":false}]}
{"op":"mcm","clk":"5354120260","pt":1646221590252,"mc":[{"id":"1.195453782","rc":[{"atl":[[4.4,1.33]],"id":41738000}],"con":true,"img":false}]}
{"op":"mcm","clk":"5354120329","pt":1646221590932,"mc":[{"id":"1.195453782","rc":[{"atl":[[1000,0.15]],"id":39594698}],"con":true,"img":false}]}
{"op":"mcm","clk":"5354120342","pt":1646221591034,"mc":[{"id":"1.195453782","rc":[{"atb":[[6,69.62]],"id":41419892},{"atl":[[20,0]],"id":40879966},{"atl":[[4.5,5.82]],"id":41738000},{"atb":[[3.3,93.78]],"id":42146659},{"atb":[[3.5,94.17]],"id":39594698}],"con":true,"img":false}]}
{"op":"mcm","clk":"5354120349","pt":1646221591143,"mc":[{"id":"1.195453782","rc":[{"atb":[[4.4,49.05]],"id":43167137},{"atb":[[7.8,49.05]],"id":40879966},{"atl":[[19,2.92]],"id":40879966},{"atb":[[2.8,49.05]],"id":41738000}],"con":true,"img":false}]}
{"op":"mcm","clk":"5354120361","pt":1646221591245,"mc":[{"id":"1.195453782","rc":[{"atl":[[4.4,1.63]],"id":41738000}],"con":true,"img":false}]}
{"op":"mcm","clk":"5354120372","pt":1646221591347,"mc":[{"id":"1.195453782","rc":[{"atl":[[4.4,4.63]],"id":41738000},{"atl":[[1000,0]],"id":39594698}],"con":true,"img":false}]}
{"op":"mcm","clk":"5354120386","pt":1646221591453,"mc":[{"id":"1.195453782","rc":[{"atl":[[7.2,2.89]],"id":39594698}],"con":true,"img":false}]}
{"op":"mcm","clk":"5354120436","pt":1646221591969,"mc":[{"id":"1.195453782","rc":[{"atl":[[4.4,3.3]],"id":41738000}],"con":true,"img":false}]}
{"op":"mcm","clk":"5354120447","pt":1646221592035,"mc":[{"id":"1.195453782","rc":[{"atl":[[1000,1.33]],"id":41738000}],"con":true,"img":false}]}
{"op":"mcm","clk":"5354120474","pt":1646221592288,"mc":[{"id":"1.195453782","rc":[{"atb":[[4.5,0]],"id":39594698}],"con":true,"img":false}]}
{"op":"mcm","clk":"5354120502","pt":1646221592555,"mc":[{"id":"1.195453782","rc":[{"atb":[[3.45,0],[1.04,1.66]],"id":41738000}],"con":true,"img":false}]}
{"op":"mcm","clk":"5354120517","pt":1646221592658,"mc":[{"id":"1.195453782","rc":[{"atb":[[1.04,1.65]],"id":41738000}],"con":true,"img":false}]}
{"op":"mcm","clk":"5354120533","pt":1646221592862,"mc":[{"id":"1.195453782","rc":[{"atb":[[1.04,0]],"id":41738000}],"con":true,"img":false}]}
{"op":"mcm","clk":"5354120543","pt":1646221592970,"mc":[{"id":"1.195453782","rc":[{"atb":[[3.7,1.99]],"id":41738000}],"con":true,"img":false}]}
{"op":"mcm","clk":"5354120557","pt":1646221593027,"mc":[{"id":"1.195453782","rc":[{"atl":[[10,7.27]],"id":43167137},{"atl":[[95,2.81]],"id":39307895},{"atl":[[5.7,13.91]],"id":41738000},{"atl":[[7,0]],"id":42146659},{"atl":[[7.2,13.44]],"id":39594698}],"con":true,"img":false}]}
{"op":"mcm","clk":"5354120570","pt":1646221593176,"mc":[{"id":"1.195453782","rc":[{"atl":[[12,0]],"id":43167137},{"atb":[[25,0]],"id":39307895},{"atl":[[95,4.81],[110,0]],"id":39307895},{"atb":[[3.65,3.35]],"id":41738000},{"atl":[[6.4,0]],"id":41738000},{"atl":[[6.2,34.11]],"id":42146659},{"atl":[[7.8,11.03]],"id":39594698}],"con":true,"img":false}]}
{"op":"mcm","clk":"5354120585","pt":1646221593237,"mc":[{"id":"1.195453782","rc":[{"atb":[[29,2.72]],"id":39307895},{"atl":[[7.6,6.43]],"id":39594698}],"con":true,"img":false}]}
{"op":"mcm","clk":"5354120597","pt":1646221593338,"mc":[{"id":"1.195453782","rc":[{"atl":[[95,2.81],[110,2]],"id":39307895},{"atb":[[1.01,4]],"id":41738000}],"con":true,"img":false}]}
{"op":"mcm","clk":"5354120607","pt":1646221593442,"mc":[{"id":"1.195453782","rc":[{"atl":[[110,0]],"id":39307895}],"con":true,"img":false}]}
{"op":"mcm","clk":"5354120618","pt":1646221593548,"mc":[{"id":"1.195453782","rc":[{"atl":[[95,4.81]],"id":39307895},{"atb":[[1.01,3.2]],"id":41738000}],"con":true,"img":false}]}
{"op":"mcm","clk":"5354120643","pt":1646221593757,"mc":[{"id":"1.195453782","rc":[{"atb":[[1.01,2]],"id":41738000}],"con":true,"img":false}]}
{"op":"mcm","clk":"5354120657","pt":1646221593856,"mc":[{"id":"1.195453782","rc":[{"atb":[[3.75,1.2]],"id":41738000}],"con":true,"img":false}]}
{"op":"mcm","clk":"5354120695","pt":1646221594165,"mc":[{"id":"1.195453782","rc":[{"atl":[[11.5,1.39]],"id":43167137},{"atl":[[100,0]],"id":39307895}],"con":true,"img":false}]}
{"op":"mcm","clk":"5354120706","pt":1646221594272,"mc":[{"id":"1.195453782","rc":[{"atl":[[9.8,1]],"id":43167137},{"atl":[[90,1]],"id":39307895}],"con":true,"img":false}]}
{"op":"mcm","clk":"5354120719","pt":1646221594341,"mc":[{"id":"1.195453782","rc":[{"atb":[[2.34,49.91],[2.24,0]],"id":43167137},{"atb":[[2.78,11.24]],"id":41419892},{"atl":[[8.8,0]],"id":41419892},{"atb":[[3.7,4.99]],"id":41738000},{"atb":[[3.95,19.81],[4.1,32.26]],"id":39594698},{"atl":[[7.4,10.46]],"id":39594698}],"con":true,"img":false}]}
{"op":"mcm","clk":"5354120729","pt":1646221594432,"mc":[{"id":"1.195453782","rc":[{"atb":[[7.4,0.22]],"id":41419892},{"atl":[[8.6,5]],"id":41419892},{"atl":[[7.4,2.65],[7.2,10.7]],"id":39594698}],"con":true,"img":false}]}
{"op":"mcm","clk":"5354120740","pt":1646221594536,"mc":[{"id":"1.195453782","rc":[{"atl":[[8.6,4]],"id":41419892},{"atb":[[3.75,1.54]],"id":41738000}],"con":true,"img":false}]}
{"op":"mcm","clk":"5354120752","pt":1646221594640,"mc":[{"id":"1.195453782","rc":[{"atl":[[12,1]],"id":41419892},{"atl":[[6.6,4.16]],"id":39594698}],"con":true,"img":false}]}
{"op":"mcm","clk":"5354120774","pt":1646221594857,"mc":[{"id":"1.195453782","rc":[{"atl":[[6.6,4.54]],"id":39594698}],"con":true,"img":false}]}
{"op":"mcm","clk":"5354120801","pt":1646221595055,"mc":[{"id":"1.195453782","rc":[{"atl":[[12,0]],"id":41419892},{"atl":[[6.8,0.4]],"id":39594698}],"con":true,"img":false}]}
{"op":"mcm","clk":"5354120810","pt":1646221595151,"mc":[{"id":"1.195453782","rc":[{"atl":[[8.4,1]],"id":41419892},{"atl":[[6.4,1]],"id":39594698}],"con":true,"img":false}]}
{"op":"mcm","clk":"5354120821","pt":1646221595259,"mc":[{"id":"1.195453782","rc":[{"atl":[[7.2,10.55]],"id":39594698}],"con":true,"img":false}]}
{"op":"mcm","clk":"5354120837","pt":1646221595359,"mc":[{"id":"1.195453782","rc":[{"atl":[[6.4,1.39],[990,0.15]],"id":39594698}],"con":true,"img":false}]}
{"op":"mcm","clk":"5354120850","pt":1646221595464,"mc":[{"id":"1.195453782","rc":[{"atl":[[7,0.38]],"id":39594698}],"con":true,"img":false}]}
{"op":"mcm","clk":"5354120867","pt":1646221595567,"mc":[{"id":"1.195453782","rc":[{"atl":[[6.4,2.63]],"id":39594698}],"con":true,"img":false}]}
{"op":"mcm","clk":"5354120990","pt":1646221596559,"mc":[{"id":"1.195453782","rc":[{"atb":[[5.8,3.4]],"id":43167137}],"con":true,"img":false}]}
{"op":"mcm","clk":"5354121048","pt":1646221597075,"mc":[{"id":"1.195453782","rc":[{"atl":[[8.6,0]],"id":41419892},{"atb":[[3.75,4.54]],"id":41738000}],"con":true,"img":false}]}
{"op":"mcm","clk":"5354121071","pt":1646221597289,"mc":[{"id":"1.195453782","rc":[{"atl":[[8.4,0]],"id":41419892},{"atl":[[4.3,2.7]],"id":41738000},{"atb":[[4,6.22]],"id":42146659}],"con":true,"img":false}]}
{"op":"mcm","clk":"5354121091","pt":1646221597447,"mc":[{"id":"1.195453782","rc":[{"atl":[[12,1]],"id":41419892},{"atl":[[4.3,3.02]],"id":41738000}],"con":true,"img":false}]}
{"op":"mcm","clk":"5354121117","pt":1646221597654,"mc":[{"id":"1.195453782","rc":[{"atl":[[4.5,3.3]],"id":41738000}],"con":true,"img":false}]}
{"op":"mcm","clk":"5354121130","pt":1646221597759,"mc":[{"id":"1.195453782","rc":[{"atl":[[20,6.58]],"id":41738000}],"con":true,"img":false}]}
{"op":"mcm","clk":"5354121190","pt":1646221598175,"mc":[{"id":"1.195453782","rc":[{"atb":[[5.7,0]],"id":43167137}],"con":true,"img":false}]}
{"op":"mcm","clk":"5354121202","pt":1646221598233,"mc":[{"id":"1.195453782","rc":[{"atb":[[5.9,2.26]],"id":43167137}],"con":true,"img":false}]}
{"op":"mcm","clk":"5354121503","pt":1646221600770,"mc":[{"id":"1.195453782","rc":[{"atb":[[5.8,0]],"id":43167137}],"con":true,"img":false}]}
{"op":"mcm","clk":"5354121600","pt":1646221601970,"mc":[{"id":"1.195453782","rc":[{"atl":[[1000,3.58]],"id":41738000}],"con":true,"img":false}]}
{"op":"mcm","clk":"5354121614","pt":1646221602178,"mc":[{"id":"1.195453782","rc":[{"atl":[[120,2]],"id":39307895},{"atl":[[17.5,0]],"id":41738000}],"con":true,"img":false}]}
{"op":"mcm","clk":"5354121623","pt":1646221602254,"mc":[{"id":"1.195453782","rc":[{"atl":[[130,0]],"id":39307895}],"con":true,"img":false}]}
{"op":"mcm","clk":"5354121644","pt":1646221602692,"mc":[{"id":"1.195453782","rc":[{"atl":[[1000,2.08]],"id":41738000}],"con":true,"img":false}]}
{"op":"mcm","clk":"5354121672","pt":1646221602739,"mc":[{"id":"1.195453782","rc":[{"atl":[[90,2.34]],"id":39307895}],"con":true,"img":false}]}
{"op":"mcm","clk":"5354121696","pt":1646221602947,"mc":[{"id":"1.195453782","rc":[{"atl":[[1000,1.33]],"id":41738000}],"con":true,"img":false}]}
{"op":"mcm","clk":"5354121704","pt":1646221603048,"mc":[{"id":"1.195453782","rc":[{"atb":[[1.1,2.72],[3.75,3.79]],"id":41738000},{"trd":[[3.75,1.5]],"ltp":3.75,"tv":1.5,"id":41738000},{"atb":[[1.1,2.72]],"id":39594698}],"con":true,"img":false}]}
{"op":"mcm","clk":"5354121772","pt":1646221603880,"mc":[{"id":"1.195453782","rc":[{"atb":[[2.74,28.74]],"id":41419892},{"atl":[[7.8,6.24]],"id":39594698}],"con":true,"img":false}]}
{"op":"mcm","clk":"5354121830","pt":1646221604460,"mc":[{"id":"1.195453782","rc":[{"atb":[[5.3,8.79]],"id":43167137}],"con":true,"img":false}]}
{"op":"mcm","clk":"5354121897","pt":1646221605178,"mc":[{"id":"1.195453782","rc":[{"atl":[[1000,3.58]],"id":41738000}],"con":true,"img":false}]}
{"op":"mcm","clk":"5354121968","pt":1646221605860,"mc":[{"id":"1.195453782","rc":[{"spn":5.48,"spf":1.0,"id":43167137},{"spn":7.22,"spf":1.0,"id":41419892},{"spn":9.66,"spf":1.0,"id":40879966},{"spn":31.06,"spf":1.0,"id":39307895},{"atl":[[1000,2.08]],"id":41738000},{"spn":4.02,"spf":"NaN","id":41738000},{"spn":4.35,"spf":"NaN","id":42146659},{"spn":5.75,"spf":"NaN","id":39594698}],"con":true,"img":false}]}
{"op":"mcm","clk":"5354122020","pt":1646221606372,"mc":[{"id":"1.195453782","rc":[{"atl":[[1000,1.33]],"id":41738000}],"con":true,"img":false}]}
{"op":"mcm","clk":"5354122029","pt":1646221606476,"mc":[{"id":"1.195453782","rc":[{"atl":[[4,0.75]],"id":41738000},{"atb":[[1.02,0]],"id":39594698}],"con":true,"img":false}]}
{"op":"mcm","clk":"5354122038","pt":1646221606538,"mc":[{"id":"1.195453782","rc":[{"atb":[[5,2.51]],"id":39594698}],"con":true,"img":false}]}
{"op":"mcm","clk":"5354122087","pt":1646221606953,"mc":[{"id":"1.195453782","rc":[{"atb":[[4.4,32.7]],"id":43167137},{"atb":[[6,53.27]],"id":41419892},{"atb":[[7.8,32.7]],"id":40879966},{"atb":[[28,14]],"id":39307895},{"atb":[[2.8,32.7]],"id":41738000},{"atb":[[3.3,77.43]],"id":42146659},{"atb":[[3.5,77.82]],"id":39594698},{"atl":[[1000,2.52]],"id":39594698}],"con":true,"img":false}]}
{"op":"mcm","clk":"5354122107","pt":1646221607158,"mc":[{"id":"1.195453782","rc":[{"atl":[[1000,2.1]],"id":39594698}],"con":true,"img":false}]}
{"op":"mcm","clk":"5354122119","pt":1646221607259,"mc":[{"id":"1.195453782","rc":[{"atl":[[1000,0]],"id":39594698}],"con":true,"img":false}]}
{"op":"mcm","clk":"5354122128","pt":1646221607364,"mc":[{"id":"1.195453782","rc":[{"atl":[[130,2],[120,0]],"id":39307895},{"atl":[[6.2,2.1]],"id":39594698}],"con":true,"img":false}]}
{"op":"mcm","clk":"5354122148","pt":1646221607569,"mc":[{"id":"1.195453782","rc":[{"atb":[[4.9,3.49],[5.1,0.33],[5,1.99]],"id":39594698},{"atl":[[6.2,2.47]],"id":39594698}],"con":true,"img":false}]}
{"op":"mcm","clk":"5354122157","pt":1646221607671,"mc":[{"id":"1.195453782","rc":[{"atl":[[6.4,1.63]],"id":39594698}],"con":true,"img":false}]}
{"op":"mcm","clk":"5354122167","pt":1646221607775,"mc":[{"id":"1.195453782","rc":[{"atl":[[6,1]],"id":39594698}],"con":true,"img":false}]}
{"op":"mcm","clk":"5354122177","pt":1646221607939,"mc":[{"id":"1.195453782","rc":[{"atl":[[6.2,2.1]],"id":39594698}],"con":true,"img":false}]}
{"op":"mcm","clk":"5354122185","pt":1646221608045,"mc":[{"id":"1.195453782","rc":[{"atl":[[90,1]],"id":39307895},{"atl":[[6.4,0.39]],"id":39594698}],"con":true,"img":false}]}
{"op":"mcm","clk":"5354122191","pt":1646221608143,"mc":[{"id":"1.195453782","rc":[{"atl":[[1000,1.34]],"id":39307895},{"atl":[[6,2.24]],"id":39594698}],"con":true,"img":false}]}
{"op":"mcm","clk":"5354122314","pt":1646221609656,"mc":[{"id":"1.195453782","rc":[{"atb":[[4.3,11.23]],"id":41738000},{"atl":[[4.3,0],[4,0]],"id":41738000},{"trd":[[4.3,24.87]],"ltp":4.3,"tv":24.87,"id":41738000}],"con":true,"img":false}]}
{"op":"mcm","clk":"5354122322","pt":1646221609763,"mc":[{"id":"1.195453782","rc":[{"atb":[[4.3,0]],"id":41738000},{"trd":[[4.3,47.35]],"ltp":4.3,"tv":47.35,"id":41738000}],"con":true,"img":false}]}
{"op":"mcm","clk":"5354122333","pt":1646221609867,"mc":[{"id":"1.195453782","rc":[{"atb":[[3.75,3.34]],"id":41738000},{"atl":[[4.4,3],[4.5,3]],"id":41738000}],"con":true,"img":false}]}
{"op":"mcm","clk":"5354122351","pt":1646221610073,"mc":[{"id":"1.195453782","rc":[{"atb":[[1.03,2]],"id":41738000}],"con":true,"img":false}]}
{"op":"mcm","clk":"5354122372","pt":1646221610279,"mc":[{"id":"1.195453782","rc":[{"atb":[[1.03,0.38]],"id":41738000}],"con":true,"img":false}]}
{"op":"mcm","clk":"5354122393","pt":1646221610448,"mc":[{"id":"1.195453782","rc":[{"atb":[[1.03,0]],"id":41738000}],"con":true,"img":false}]}
{"op":"mcm","clk":"5354122402","pt":1646221610555,"mc":[{"id":"1.195453782","rc":[{"atl":[[4.4,2.62]],"id":41738000},{"trd":[[4.4,30.78]],"ltp":4.4,"tv":30.78,"id":41738000}],"con":true,"img":false}]}
{"op":"mcm","clk":"5354122600","pt":1646221612574,"mc":[{"id":"1.195453782","rc":[{"atl":[[4.3,3]],"id":41738000}],"con":true,"img":false}]}
{"op":"mcm","clk":"5354122622","pt":1646221612781,"mc":[{"id":"1.195453782","rc":[{"atl":[[1000,3.33]],"id":41738000}],"con":true,"img":false}]}
{"op":"mcm","clk":"5354122635","pt":1646221612890,"mc":[{"id":"1.195453782","rc":[{"atb":[[9.8,1.29]],"id":40879966},{"atb":[[3.6,0.36],[3.75,0.34],[3.7,1.99],[3.65,0.35]],"id":41738000},{"atl":[[15.5,8.28],[17,8.5]],"id":41738000},{"atl":[[7.2,13.29]],"id":39594698}],"con":true,"img":false}]}
{"op":"mcm","clk":"5354122646","pt":1646221612961,"mc":[{"id":"1.195453782","rc":[{"atl":[[1000,2.33]],"id":41738000}],"con":true,"img":false}]}
{"op":"mcm","clk":"5354122657","pt":1646221613069,"mc":[{"id":"1.195453782","rc":[{"atb":[[2.7,44.12]],"id":41419892},{"atl":[[17.5,0]],"id":41419892}],"con":true,"img":false}]}
{"op":"mcm","clk":"5354122669","pt":1646221613162,"mc":[{"id":"1.195453782","rc":[{"atl":[[15.5,8.36]],"id":41419892},{"atl":[[1000,1.33]],"id":41738000}],"con":true,"img":false}]}
{"op":"mcm","clk":"5354122677","pt":1646221613266,"mc":[{"id":"1.195453782","rc":[{"atl":[[4.2,1]],"id":41738000}],"con":true,"img":false}]}
{"op":"mcm","clk":"5354122702","pt":1646221613477,"mc":[{"id":"1.195453782","rc":[{"atl":[[130,0],[120,2]],"id":39307895}],"con":true,"img":false}]}
{"op":"mcm","clk":"5354122803","pt":1646221614474,"mc":[{"id":"1.195453782","rc":[{"atl":[[1000,0]],"id":39307895}],"con":true,"img":false}]}
{"op":"mcm","clk":"5354122810","pt":1646221614572,"mc":[{"id":"1.195453782","rc":[{"atl":[[90,2.34]],"id":39307895}],"con":true,"img":false}]}
{"op":"mcm","clk":"5354122847","pt":1646221614887,"mc":[{"id":"1.195453782","rc":[{"atb":[[3.75,2.86]],"id":41738000}],"con":true,"img":false}]}
{"op":"mcm","clk":"5354122858","pt":1646221614990,"mc":[{"id":"1.195453782","rc":[{"atl":[[240,0]],"id":39307895},{"atl":[[6.2,0]],"id":39594698}],"con":true,"img":false}]}
{"op":"mcm","clk":"5354122874","pt":1646221615053,"mc":[{"id":"1.195453782","rc":[{"atb":[[8,17.98],[6.8,0]],"id":40879966},{"atl":[[110,2.72]],"id":39307895}],"con":true,"img":false}]}
{"op":"mcm","clk":"5354122885","pt":1646221615155,"mc":[{"id":"1.195453782","rc":[{"atl":[[6,1.24]],"id":39594698}],"con":true,"img":false}]}
{"op":"mcm","clk":"5354122895","pt":1646221615254,"mc":[{"id":"1.195453782","rc":[{"atl":[[6.4,1.39]],"id":39594698}],"con":true,"img":false}]}
{"op":"mcm","clk":"5354122904","pt":1646221615358,"mc":[{"id":"1.195453782","rc":[{"atl":[[1000,3.58]],"id":41738000},{"atl":[[6,0]],"id":39594698}],"con":true,"img":false}]}
{"op":"mcm","clk":"5354122913","pt":1646221615461,"mc":[{"id":"1.195453782","rc":[{"atb":[[5.1,0.71]],"id":39594698},{"atl":[[6.4,2.63]],"id":39594698}],"con":true,"img":false}]}
{"op":"mcm","clk":"5354122926","pt":1646221615568,"mc":[{"id":"1.195453782","rc":[{"atb":[[2.68,0]],"id":41419892}],"con":true,"img":false}]}
{"op":"mcm","clk":"5354122964","pt":1646221615977,"mc":[{"id":"1.195453782","rc":[{"atl":[[1000,2.08]],"id":41738000}],"con":true,"img":false}]}
{"op":"mcm","clk":"5354122996","pt":1646221616288,"mc":[{"id":"1.195453782","rc":[{"atb":[[6,69.62]],"id":41419892},{"atb":[[3.3,93.78]],"id":42146659},{"atb":[[3.5,94.17]],"id":39594698}],"con":true,"img":false}]}
{"op":"mcm","clk":"5354123003","pt":1646221616393,"mc":[{"id":"1.195453782","rc":[{"atb":[[4.4,49.05]],"id":43167137},{"atb":[[7.8,49.05]],"id":40879966},{"atb":[[28,19.45]],"id":39307895},{"atb":[[2.8,49.05]],"id":41738000}],"con":true,"img":false}]}
{"op":"mcm","clk":"5354123048","pt":1646221616762,"mc":[{"id":"1.195453782","rc":[{"atb":[[3.7,0.34]],"id":41738000},{"atl":[[1000,1.33]],"id":41738000}],"con":true,"img":false}]}
{"op":"mcm","clk":"5354123059","pt":1646221616870,"mc":[{"id":"1.195453782","rc":[{"atl":[[4,0.75]],"id":41738000}],"con":true,"img":false}]}
{"op":"mcm","clk":"5354123073","pt":1646221617068,"mc":[{"id":"1.195453782","rc":[{"atl":[[95,2.09]],"id":39307895},{"atl":[[9,0]],"id":39594698}],"con":true,"img":false}]}
{"op":"mcm","clk":"5354123086","pt":1646221617172,"mc":[{"id":"1.195453782","rc":[{"atl":[[90,5.06]],"id":39307895},{"atl":[[7.2,29.88]],"id":39594698}],"con":true,"img":false}]}
{"op":"mcm","clk":"5354123105","pt":1646221617379,"mc":[{"id":"1.195453782","rc":[{"atl":[[85,2],[95,0.09]],"id":39307895}],"con":true,"img":false}]}
{"op":"mcm","clk":"5354123123","pt":1646221617584,"mc":[{"id":"1.195453782","rc":[{"atl":[[90,4.06]],"id":39307895}],"con":true,"img":false}]}
{"op":"mcm","clk":"5354123138","pt":1646221617688,"mc":[{"id":"1.195453782","rc":[{"atl":[[80,1]],"id":39307895}],"con":true,"img":false}]}
{"op":"mcm","clk":"5354123159","pt":1646221617896,"mc":[{"id":"1.195453782","rc":[{"atb":[[3.6,3.36]],"id":41738000},{"atl":[[15.5,6.9],[17,9.75]],"id":41738000}],"con":true,"img":false}]}
{"op":"mcm","clk":"5354123164","pt":1646221618000,"mc":[{"id":"1.195453782","rc":[{"atl":[[90,2.72]],"id":39307895}],"con":true,"img":false}]}
{"op":"mcm","clk":"5354123181","pt":1646221618064,"mc":[{"id":"1.195453782","rc":[{"atl":[[85,3.34]],"id":39307895}],"con":true,"img":false}]}
{"op":"mcm","clk":"5354123190","pt":1646221618155,"mc":[{"id":"1.195453782","rc":[{"atl":[[90,4.72]],"id":39307895}],"con":true,"img":false}]}
{"op":"mcm","clk":"5354123200","pt":1646221618261,"mc":[{"id":"1.195453782","rc":[{"atl":[[85,1.34]],"id":39307895}],"con":true,"img":false}]}
{"op":"mcm","clk":"5354123231","pt":1646221618472,"mc":[{"id":"1.195453782","rc":[{"atl":[[80,0]],"id":39307895}],"con":true,"img":false}]}
{"op":"mcm","clk":"5354123244","pt":1646221618574,"mc":[{"id":"1.195453782","rc":[{"atl":[[85,2.34]],"id":39307895}],"con":true,"img":false}]}
{"op":"mcm","clk":"5354123282","pt":1646221618885,"mc":[{"id":"1.195453782","rc":[{"atl":[[1000,2.52]],"id":39594698}],"con":true,"img":false}]}
{"op":"mcm","clk":"5354123307","pt":1646221619089,"mc":[{"id":"1.195453782","rc":[{"atl":[[1000,2.1]],"id":39594698}],"con":true,"img":false}]}
{"op":"mcm","clk":"5354123329","pt":1646221619295,"mc":[{"id":"1.195453782","rc":[{"atl":[[1000,0]],"id":39594698}],"con":true,"img":false}]}
{"op":"mcm","clk":"5354123340","pt":1646221619400,"mc":[{"id":"1.195453782","rc":[{"atl":[[6.2,2.1]],"id":39594698}],"con":true,"img":false}]}
{"op":"mcm","clk":"5354123363","pt":1646221619558,"mc":[{"id":"1.195453782","rc":[{"atb":[[3.65,3.35]],"id":41738000},{"atb":[[5.1,0.33]],"id":39594698},{"atl":[[6.4,1.63],[6.2,2.44]],"id":39594698}],"con":true,"img":false}]}
{"op":"mcm","clk":"5354123376","pt":1646221619664,"mc":[{"id":"1.195453782","rc":[{"atl":[[6,1]],"id":39594698}],"con":true,"img":false}]}
{"op":"mcm","clk":"5354123383","pt":1646221619768,"mc":[{"id":"1.195453782","rc":[{"atl":[[6.2,2.1]],"id":39594698}],"con":true,"img":false}]}
{"op":"mcm","clk":"5354123392","pt":1646221619875,"mc":[{"id":"1.195453782","rc":[{"atl":[[6.4,0.39]],"id":39594698}],"con":true,"img":false}]}
{"op":"mcm","clk":"5354123414","pt":1646221619981,"mc":[{"id":"1.195453782","rc":[{"atl":[[6.2,3.35]],"id":39594698}],"con":true,"img":false}]}
{"op":"mcm","clk":"5354123457","pt":1646221620396,"mc":[{"id":"1.195453782","rc":[{"atb":[[2.22,0],[3.05,0]],"id":43167137},{"atl":[[34,0],[38,0],[50,0]],"id":43167137},{"atb":[[13,0],[2.62,0],[8.6,0],[4.2,0]],"id":39307895},{"atb":[[1.85,0],[2.42,0]],"id":42146659},{"atl":[[34,0],[18,0],[23,0]],"id":42146659},{"atb":[[1.88,0],[2.46,0]],"id":39594698},{"atl":[[34,0],[19.5,0],[25,0]],"id":39594698}],"con":true,"img":false}]}
{"op":"mcm","clk":"5354123467","pt":1646221620501,"mc":[{"id":"1.195453782","rc":[{"atb":[[2.8,0],[2.62,0],[4,0]],"id":41419892},{"atl":[[48,0],[60,0]],"id":41419892},{"atb":[[5.3,0],[3.55,0],[2.62,0]],"id":40879966},{"atl":[[190,0],[50,0]],"id":40879966},{"atb":[[4.3,10.26],[2.12,0],[1.67,0]],"id":41738000},{"atl":[[34,0],[4.3,0],[9,0],[11.5,0],[4,0],[17,1.25],[4.2,0]],"id":41738000},{"trd":[[4.2,13.18]],"ltp":4.2,"tv":13.18,"id":41738000}],"con":true,"img":false}]}
{"op":"mcm","clk":"5354123488","pt":1646221620665,"mc":[{"id":"1.195453782","rc":[{"atb":[[4.3,0],[1.01,4]],"id":41738000},{"trd":[[4.3,67.87]],"ltp":4.3,"tv":67.87,"id":41738000}],"con":true,"img":false}]}
{"op":"mcm","clk":"5354123513","pt":1646221620872,"mc":[{"id":"1.195453782","rc":[{"atb":[[1.01,2.96]],"id":41738000},{"atl":[[6.2,1.24]],"id":39594698}],"con":true,"img":false}]}
{"op":"mcm","clk":"5354123531","pt":1646221621079,"mc":[{"id":"1.195453782","rc":[{"atb":[[1.01,2]],"id":41738000}],"con":true,"img":false}]}
{"op":"mcm","clk":"5354123544","pt":1646221621193,"mc":[{"id":"1.195453782","rc":[{"atl":[[4.4,1.65]],"id":41738000},{"trd":[[4.4,32.7]],"ltp":4.4,"tv":32.7,"id":41738000}],"con":true,"img":false}]}
{"op":"mcm","clk":"5354123562","pt":1646221621391,"mc":[{"id":"1.195453782","rc":[{"atl":[[6,0]],"id":39594698}],"con":true,"img":false}]}
{"op":"mcm","clk":"5354123575","pt":1646221621497,"mc":[{"id":"1.195453782","rc":[{"atl":[[6.4,1.39]],"id":39594698}],"con":true,"img":false}]}
{"op":"mcm","clk":"5354123584","pt":1646221621601,"mc":[{"id":"1.195453782","rc":[{"atl":[[6.2,1.57]],"id":39594698}],"con":true,"img":false}]}
{"op":"mcm","clk":"5354123594","pt":1646221621663,"mc":[{"id":"1.195453782","rc":[{"atl":[[1000,3.33]],"id":41738000},{"atl":[[6.2,0.33]],"id":39594698}],"con":true,"img":false}]}
{"op":"mcm","clk":"5354123605","pt":1646221621770,"mc":[{"id":"1.195453782","rc":[{"atl":[[6.4,2.63]],"id":39594698}],"con":true,"img":false}]}
{"op":"mcm","clk":"5354123616","pt":1646221621866,"mc":[{"id":"1.195453782","rc":[{"atl":[[1000,2.33]],"id":41738000}],"con":true,"img":false}]}
{"op":"mcm","clk":"5354123625","pt":1646221621971,"mc":[{"id":"1.195453782","rc":[{"atl":[[8,9.09]],"id":39594698}],"con":true,"img":false}]}
{"op":"mcm","clk":"5354123634","pt":1646221622077,"mc":[{"id":"1.195453782","rc":[{"atl":[[1000,1.33]],"id":41738000}],"con":true,"img":false}]}
{"op":"mcm","clk":"5354123641","pt":1646221622178,"mc":[{"id":"1.195453782","rc":[{"atl":[[4.3,1]],"id":41738000}],"con":true,"img":false}]}
{"op":"mcm","clk":"5354123714","pt":1646221623065,"mc":[{"id":"1.195453782","rc":[{"atb":[[3.75,0.34]],"id":41738000}],"con":true,"img":false}]}
{"op":"mcm","clk":"5354123725","pt":1646221623166,"mc":[{"id":"1.195453782","rc":[{"atl":[[4.3,4]],"id":41738000}],"con":true,"img":false}]}
{"op":"mcm","clk":"5354123736","pt":1646221623271,"mc":[{"id":"1.195453782","rc":[{"atb":[[3.6,0.36],[3.7,3.34],[3.65,0.35]],"id":41738000},{"atl":[[15.5,8.28],[17,0]],"id":41738000},{"atl":[[7.4,0],[7.8,0]],"id":39594698}],"con":true,"img":false}]}
{"op":"mcm","clk":"5354123767","pt":1646221623581,"mc":[{"id":"1.195453782","rc":[{"atb":[[3.8,2.52]],"id":41738000}],"con":true,"img":false}]}
{"op":"mcm","clk":"5354123801","pt":1646221623893,"mc":[{"id":"1.195453782","rc":[{"atl":[[7.2,13.29]],"id":39594698}],"con":true,"img":false}]}
{"op":"mcm","clk":"5354123811","pt":1646221623993,"mc":[{"id":"1.195453782","rc":[{"atb":[[5.4,1.58]],"id":43167137},{"atb":[[7.4,1.89]],"id":41419892},{"atb":[[36,3.48]],"id":39307895},{"atl":[[7.4,16.59]],"id":39594698}],"con":true,"img":false}]}
{"op":"mcm","clk":"5354123867","pt":1646221624676,"mc":[{"id":"1.195453782","rc":[{"atb":[[4,4.23]],"id":42146659}],"con":true,"img":false}]}
{"op":"mcm","clk":"5354123878","pt":1646221624781,"mc":[{"id":"1.195453782","rc":[{"atb":[[1.02,1.99]],"id":42146659}],"con":true,"img":false}]}
{"op":"mcm","clk":"5354123889","pt":1646221624889,"mc":[{"id":"1.195453782","rc":[{"atl":[[90,2]],"id":39307895}],"con":true,"img":false}]}
{"op":"mcm","clk":"5354123903","pt":1646221624992,"mc":[{"id":"1.195453782","rc":[{"atl":[[110,5.45]],"id":39307895}],"con":true,"img":false}]}
{"op":"mcm","clk":"5354123913","pt":1646221625091,"mc":[{"id":"1.195453782","rc":[{"atb":[[5,0]],"id":39594698}],"con":true,"img":false}]}
{"op":"mcm","clk":"5354123920","pt":1646221625196,"mc":[{"id":"1.195453782","rc":[{"atb":[[1.02,1.99]],"id":39594698}],"con":true,"img":false}]}
{"op":"mcm","clk":"5354123928","pt":1646221625298,"mc":[{"id":"1.195453782","rc":[{"atl":[[85,1]],"id":39307895}],"con":true,"img":false}]}
{"op":"mcm","clk":"5354123935","pt":1646221625404,"mc":[{"id":"1.195453782","rc":[{"atl":[[1000,1.34]],"id":39307895}],"con":true,"img":false}]}
{"op":"mcm","clk":"5354123946","pt":1646221625466,"mc":[{"id":"1.195453782","rc":[{"atb":[[5.9,0.27]],"id":43167137},{"atl":[[90,0],[100,2]],"id":39307895}],"con":true,"img":false}]}
{"op":"mcm","clk":"5354123953","pt":1646221625563,"mc":[{"id":"1.195453782","rc":[{"atb":[[1.02,1.99]],"id":43167137}],"con":true,"img":false}]}
{"op":"mcm","clk":"5354123962","pt":1646221625668,"mc":[{"id":"1.195453782","rc":[{"atl":[[85,0]],"id":39307895}],"con":true,"img":false}]}
{"op":"mcm","clk":"5354123973","pt":1646221625769,"mc":[{"id":"1.195453782","rc":[{"atl":[[9.8,3]],"id":43167137},{"atl":[[12,3]],"id":41419892},{"atl":[[95,1.09]],"id":39307895}],"con":true,"img":false}]}
{"op":"mcm","clk":"5354124005","pt":1646221626136,"mc":[{"id":"1.195453782","rc":[{"atl":[[11.5,0]],"id":43167137},{"atl":[[13.5,0]],"id":41419892},{"atl":[[1000,0]],"id":39307895}],"con":true,"img":false}]}
{"op":"mcm","clk":"5354124022","pt":1646221626188,"mc":[{"id":"1.195453782","rc":[{"atl":[[9.6,1.39]],"id":43167137},{"atl":[[11.5,1.26]],"id":41419892},{"atl":[[100,3.34]],"id":39307895}],"con":true,"img":false}]}
{"op":"mcm","clk":"5354124053","pt":1646221626497,"mc":[{"id":"1.195453782","rc":[{"atb":[[5.1,26.27]],"id":43167137},{"atl":[[11.5,12.97]],"id":43167137},{"atl":[[12.5,15.95]],"id":41419892},{"atb":[[9.8,6.91]],"id":40879966},{"atb":[[36,4.61]],"id":39307895},{"atl":[[100,4.71]],"id":39307895},{"atb":[[1.02,0]],"id":42146659},{"atl":[[5.5,26.24]],"id":42146659},{"atb":[[4.3,14.12]],"id":39594698},{"atl":[[7.2,23.34]],"id":39594698}],"con":true,"img":false}]}
