{"op":"mcm","clk":"5345985314","pt":1646174444271,"mc":[{"id":"1.195453622","marketDefinition":{"bspMarket":true,"turnInPlayEnabled":false,"persistenceEnabled":false,"marketBaseRate":7.0,"eventId":"31272494","eventTypeId":"4339","numberOfWinners":2,"bettingType":"ODDS","marketType":"PLACE","marketTime":"2022-03-02T10:27:00.000Z","suspendTime":"2022-03-02T10:27:00.000Z","bspReconciled":false,"complete":true,"inPlay":false,"crossMatching":false,"runnersVoidable":false,"numberOfActiveRunners":7,"betDelay":0,"status":"OPEN","runners":[{"status":"ACTIVE","sortPriority":1,"id":40250501,"name":"1. Dwarshuis"},{"status":"ACTIVE","sortPriority":2,"id":6780934,"name":"2. Peacock"},{"status":"ACTIVE","sortPriority":3,"id":40846831,"name":"3. Rapid Voyage"},{"status":"ACTIVE","sortPriority":4,"id":23806261,"name":"4. Impending"},{"status":"ACTIVE","sortPriority":5,"id":40199925,"name":"6. Parzival"},{"status":"ACTIVE","sortPriority":6,"id":41308374,"name":"7. Gotham Baroness"},{"status":"ACTIVE","sortPriority":7,"id":36463352,"name":"8. Massimo"}],"regulators":["MR_INT"],"venue":"Traralgon","countryCode":"AU","discountAllowed":true,"timezone":"Australia/Sydney","openDate":"2022-03-02T08:31:00.000Z","version":4382425395,"name":"To Be Placed","eventName":"Traralgon (AUS) 2nd Mar"},"rc":[],"con":true,"img":false}]}
{"op":"mcm","clk":"5346059509","pt":1646175786400,"mc":[{"id":"1.195453622","rc":[{"atb":[[4.3,30.21],[3.9,34.38],[3.65,37.62]],"id":23806261},{"atl":[[32,2.34],[21,3.62],[15.5,2.49]],"id":23806261},{"spn":9.9,"spf":"NaN","id":23806261},{"atb":[[3.4,41.54],[3.15,46.37],[3.65,37.62]],"id":40250501},{"atl":[[10.5,3.81],[21,3.62],[15.5,5]],"id":40250501},{"spn":7.07,"spf":"NaN","id":40250501},{"atb":[[1.2,498.5],[1.25,398.8],[1.3,332.33]],"id":36463352},{"atl":[[2.54,23.54],[2.74,41.67],[2.94,37.37]],"id":36463352},{"spn":1.92,"spf":"NaN","id":36463352},{"atb":[[1.2,498.5],[1.25,398.8],[1.15,664.67]],"id":41308374},{"atl":[[2.44,25.17],[2.64,44.21],[2.84,39.4]],"id":41308374},{"spn":1.84,"spf":"NaN","id":41308374},{"atb":[[2.74,57.29],[2.84,54.18],[2.94,51.39]],"id":40846831},{"atl":[[8,5.17],[10,8.05],[15,5.17]],"id":40846831},{"spn":5.47,"spf":"NaN","id":40846831},{"atb":[[4,33.23],[4.5,28.48],[3.75,36.25]],"id":40199925},{"atl":[[16,2.41],[34,2.19],[22,3.45]],"id":40199925},{"spn":10.25,"spf":"NaN","id":40199925},{"atb":[[2.74,57.29],[2.84,54.18],[2.94,51.39]],"id":6780934},{"atl":[[8,5.17],[10,8.05],[15,5.17]],"id":6780934},{"spn":5.47,"spf":"NaN","id":6780934}],"con":true,"img":false}]}
{"op":"mcm","clk":"5346061998","pt":1646175839944,"mc":[{"id":"1.195453622","rc":[{"atb":[[4.3,0],[3.9,0],[3.65,0]],"id":23806261},{"atl":[[32,0],[21,0],[15.5,0]],"id":23806261},{"atb":[[3.4,0],[3.15,0],[3.65,0]],"id":40250501},{"atl":[[10.5,0],[21,0],[15.5,0]],"id":40250501},{"atb":[[1.2,0],[1.25,0],[1.3,0]],"id":36463352},{"atl":[[2.54,0],[2.74,0],[2.94,0]],"id":36463352},{"atb":[[1.2,0],[1.25,0],[1.15,0]],"id":41308374},{"atl":[[2.44,0],[2.64,0],[2.84,0]],"id":41308374},{"atb":[[2.74,0],[2.84,0],[2.94,0]],"id":40846831},{"atl":[[8,0],[10,0],[15,0]],"id":40846831},{"atb":[[4,0],[4.5,0],[3.75,0]],"id":40199925},{"atl":[[16,0],[34,0],[22,0]],"id":40199925},{"atb":[[2.74,0],[2.84,0],[2.94,0]],"id":6780934},{"atl":[[8,0],[10,0],[15,0]],"id":6780934}],"con":true,"img":false}]}
{"op":"mcm","clk":"5346062130","pt":1646175843036,"mc":[{"id":"1.195453622","rc":[{"atb":[[4.3,30.21],[3.9,34.38],[3.65,37.62]],"id":23806261},{"atl":[[32,2.34],[21,3.62],[15.5,2.49]],"id":23806261},{"atb":[[3.4,41.54],[3.15,46.37],[3.65,37.62]],"id":40250501},{"atl":[[10.5,3.81],[21,3.62],[15.5,5]],"id":40250501},{"atb":[[1.2,498.5],[1.25,398.8],[1.3,332.33]],"id":36463352},{"atl":[[2.54,23.54],[2.74,41.67],[2.94,37.37]],"id":36463352},{"atb":[[1.2,498.5],[1.25,398.8],[1.15,664.67]],"id":41308374},{"atl":[[2.44,25.17],[2.64,44.21],[2.84,39.4]],"id":41308374},{"atb":[[4,33.23],[4.5,28.48],[3.75,36.25]],"id":40199925},{"atl":[[16,2.41],[34,2.19],[22,3.45]],"id":40199925},{"atb":[[2.74,57.29],[2.84,54.18],[2.94,51.39]],"id":40846831},{"atl":[[8,5.17],[10,8.05],[15,5.17]],"id":40846831},{"atb":[[2.74,57.29],[2.84,54.18],[2.94,51.39]],"id":6780934},{"atl":[[8,5.17],[10,8.05],[15,5.17]],"id":6780934}],"con":true,"img":false}]}
{"op":"mcm","clk":"5346105176","pt":1646176602702,"mc":[{"id":"1.195453622","marketDefinition":{"bspMarket":true,"turnInPlayEnabled":false,"persistenceEnabled":false,"marketBaseRate":7.0,"eventId":"31272494","eventTypeId":"4339","numberOfWinners":2,"bettingType":"ODDS","marketType":"PLACE","marketTime":"2022-03-02T10:27:00.000Z","suspendTime":"2022-03-02T10:27:00.000Z","bspReconciled":false,"complete":true,"inPlay":false,"crossMatching":false,"runnersVoidable":false,"numberOfActiveRunners":7,"betDelay":0,"status":"OPEN","runners":[{"status":"ACTIVE","sortPriority":1,"id":40250501,"name":"1. Dwarshuis"},{"status":"ACTIVE","sortPriority":2,"id":6780934,"name":"2. Peacock"},{"status":"ACTIVE","sortPriority":3,"id":40846831,"name":"3. Rapid Voyage"},{"status":"ACTIVE","sortPriority":4,"id":23806261,"name":"4. Impending"},{"status":"ACTIVE","sortPriority":5,"id":40199925,"name":"6. Parzival"},{"status":"ACTIVE","sortPriority":6,"id":41308374,"name":"7. Gotham Baroness"},{"status":"ACTIVE","sortPriority":7,"id":36463352,"name":"8. Massimo"}],"regulators":["MR_INT"],"venue":"Traralgon","countryCode":"AU","discountAllowed":true,"timezone":"Australia/Sydney","openDate":"2022-03-02T08:31:00.000Z","version":4382425395,"name":"To Be Placed","eventName":"Traralgon (AUS) 2nd Mar"},"rc":[{"atb":[[4.3,30.21],[3.9,34.38],[3.65,37.62]],"id":23806261},{"atl":[[32,2.34],[21,3.62],[15.5,2.49]],"id":23806261},{"spn":9.9,"spf":"NaN","id":23806261},{"atb":[[3.4,41.54],[3.15,46.37],[3.65,37.62]],"id":40250501},{"atl":[[10.5,3.81],[21,3.62],[15.5,5]],"id":40250501},{"spn":7.07,"spf":"NaN","id":40250501},{"atb":[[1.2,498.5],[1.25,398.8],[1.3,332.33]],"id":36463352},{"atl":[[2.54,23.54],[2.74,41.67],[2.94,37.37]],"id":36463352},{"spn":1.92,"spf":"NaN","id":36463352},{"atb":[[1.2,498.5],[1.25,398.8],[1.15,664.67]],"id":41308374},{"atl":[[2.44,25.17],[2.64,44.21],[2.84,39.4]],"id":41308374},{"spn":1.84,"spf":"NaN","id":41308374},{"atb":[[2.74,57.29],[2.84,54.18],[2.94,51.39]],"id":40846831},{"atl":[[8,5.17],[10,8.05],[15,5.17]],"id":40846831},{"spn":5.47,"spf":"NaN","id":40846831},{"atb":[[4,33.23],[4.5,28.48],[3.75,36.25]],"id":40199925},{"atl":[[16,2.41],[34,2.19],[22,3.45]],"id":40199925},{"spn":10.25,"spf":"NaN","id":40199925},{"atb":[[2.74,57.29],[2.84,54.18],[2.94,51.39]],"id":6780934},{"atl":[[8,5.17],[10,8.05],[15,5.17]],"id":6780934},{"spn":5.47,"spf":"NaN","id":6780934}],"con":true,"img":true}]}
{"op":"mcm","clk":"5346279090","pt":1646180046050,"mc":[{"id":"1.195453622","rc":[{"atb":[[4.3,30.21],[3.9,34.38],[3.65,37.62]],"id":23806261},{"atl":[[32,2.34],[21,3.62],[15.5,2.49]],"id":23806261},{"atb":[[3.4,41.54],[3.15,46.37],[3.65,37.62]],"id":40250501},{"atl":[[10.5,3.81],[21,3.62],[15.5,5]],"id":40250501},{"atb":[[1.2,498.55],[1.25,398.84],[1.3,332.37]],"id":36463352},{"spl":[[1.01,2.72]],"id":36463352},{"atl":[[2.54,23.54],[2.74,41.67],[2.94,37.38]],"id":36463352},{"spn":1.3,"spf":1.0,"id":36463352},{"atb":[[1.2,498.55],[1.25,398.84],[1.15,664.74]],"id":41308374},{"atl":[[2.44,25.17],[2.64,44.21],[2.84,39.41]],"id":41308374},{"atb":[[2.74,57.3],[2.84,54.19],[2.94,51.39]],"id":40846831},{"atl":[[8,5.17],[10,8.05],[15,5.17]],"id":40846831},{"atb":[[4,33.23],[4.5,28.48],[3.75,36.25]],"id":40199925},{"atl":[[16,2.41],[34,2.19],[22,3.45]],"id":40199925},{"atb":[[2.74,57.3],[2.84,54.19],[2.94,51.39]],"id":6780934},{"atl":[[8,5.17],[10,8.05],[15,5.17]],"id":6780934}],"con":true,"img":false}]}
{"op":"mcm","clk":"5346767988","pt":1646187402734,"mc":[{"id":"1.195453622","marketDefinition":{"bspMarket":true,"turnInPlayEnabled":false,"persistenceEnabled":false,"marketBaseRate":7.0,"eventId":"31272494","eventTypeId":"4339","numberOfWinners":2,"bettingType":"ODDS","marketType":"PLACE","marketTime":"2022-03-02T10:27:00.000Z","suspendTime":"2022-03-02T10:27:00.000Z","bspReconciled":false,"complete":true,"inPlay":false,"crossMatching":false,"runnersVoidable":false,"numberOfActiveRunners":7,"betDelay":0,"status":"OPEN","runners":[{"status":"ACTIVE","sortPriority":1,"id":40250501,"name":"1. Dwarshuis"},{"status":"ACTIVE","sortPriority":2,"id":6780934,"name":"2. Peacock"},{"status":"ACTIVE","sortPriority":3,"id":40846831,"name":"3. Rapid Voyage"},{"status":"ACTIVE","sortPriority":4,"id":23806261,"name":"4. Impending"},{"status":"ACTIVE","sortPriority":5,"id":40199925,"name":"6. Parzival"},{"status":"ACTIVE","sortPriority":6,"id":41308374,"name":"7. Gotham Baroness"},{"status":"ACTIVE","sortPriority":7,"id":36463352,"name":"8. Massimo"}],"regulators":["MR_INT"],"venue":"Traralgon","countryCode":"AU","discountAllowed":true,"timezone":"Australia/Sydney","openDate":"2022-03-02T08:31:00.000Z","version":4382425395,"name":"To Be Placed","eventName":"Traralgon (AUS) 2nd Mar"},"rc":[{"atb":[[4.3,30.26],[3.9,34.44],[3.65,37.68]],"id":23806261},{"atl":[[32,2.34],[21,3.63],[15.5,2.5]],"id":23806261},{"spn":9.9,"spf":"NaN","id":23806261},{"atb":[[3.4,41.61],[3.15,46.45],[3.65,37.68]],"id":40250501},{"atl":[[10.5,3.82],[21,3.63],[15.5,5.01]],"id":40250501},{"spn":7.07,"spf":"NaN","id":40250501},{"atb":[[1.2,499.34],[1.25,399.47],[1.3,332.89]],"id":36463352},{"spl":[[1.01,2.72]],"id":36463352},{"atl":[[2.54,23.58],[2.74,41.74],[2.94,37.43]],"id":36463352},{"spn":1.3,"spf":1.0,"id":36463352},{"atb":[[1.2,499.34],[1.25,399.47],[1.15,665.79]],"id":41308374},{"atl":[[2.44,25.21],[2.64,44.28],[2.84,39.47]],"id":41308374},{"spn":1.84,"spf":"NaN","id":41308374},{"atb":[[2.74,57.39],[2.84,54.27],[2.94,51.48]],"id":40846831},{"atl":[[8,5.18],[10,8.07],[15,5.18]],"id":40846831},{"spn":5.47,"spf":"NaN","id":40846831},{"atb":[[4,33.28],[4.5,28.53],[3.75,36.31]],"id":40199925},{"atl":[[16,2.42],[34,2.2],[22,3.45]],"id":40199925},{"spn":10.25,"spf":"NaN","id":40199925},{"atb":[[2.74,57.39],[2.84,54.27],[2.94,51.48]],"id":6780934},{"atl":[[8,5.18],[10,8.07],[15,5.18]],"id":6780934},{"spn":5.47,"spf":"NaN","id":6780934}],"con":true,"img":true}]}
{"op":"mcm","clk":"5347092539","pt":1646192802714,"mc":[{"id":"1.195453622","marketDefinition":{"bspMarket":true,"turnInPlayEnabled":false,"persistenceEnabled":false,"marketBaseRate":7.0,"eventId":"31272494","eventTypeId":"4339","numberOfWinners":2,"bettingType":"ODDS","marketType":"PLACE","marketTime":"2022-03-02T10:27:00.000Z","suspendTime":"2022-03-02T10:27:00.000Z","bspReconciled":false,"complete":true,"inPlay":false,"crossMatching":false,"runnersVoidable":false,"numberOfActiveRunners":7,"betDelay":0,"status":"OPEN","runners":[{"status":"ACTIVE","sortPriority":1,"id":40250501,"name":"1. Dwarshuis"},{"status":"ACTIVE","sortPriority":2,"id":6780934,"name":"2. Peacock"},{"status":"ACTIVE","sortPriority":3,"id":40846831,"name":"3. Rapid Voyage"},{"status":"ACTIVE","sortPriority":4,"id":23806261,"name":"4. Impending"},{"status":"ACTIVE","sortPriority":5,"id":40199925,"name":"6. Parzival"},{"status":"ACTIVE","sortPriority":6,"id":41308374,"name":"7. Gotham Baroness"},{"status":"ACTIVE","sortPriority":7,"id":36463352,"name":"8. Massimo"}],"regulators":["MR_INT"],"venue":"Traralgon","countryCode":"AU","discountAllowed":true,"timezone":"Australia/Sydney","openDate":"2022-03-02T08:31:00.000Z","version":4382425395,"name":"To Be Placed","eventName":"Traralgon (AUS) 2nd Mar"},"rc":[{"atb":[[4.3,30.31],[3.9,34.49],[3.65,37.74]],"id":23806261},{"atl":[[32,2.34],[21,3.63],[15.5,2.5]],"id":23806261},{"spn":9.9,"spf":"NaN","id":23806261},{"atb":[[3.4,41.68],[3.15,46.53],[3.65,37.74]],"id":40250501},{"atl":[[10.5,3.82],[21,3.63],[15.5,5.01]],"id":40250501},{"spn":7.07,"spf":"NaN","id":40250501},{"atb":[[1.2,500.19],[1.25,400.15],[1.3,333.46]],"id":36463352},{"spl":[[1.01,2.73]],"id":36463352},{"atl":[[2.54,23.62],[2.74,41.81],[2.94,37.5]],"id":36463352},{"spn":1.3,"spf":1.0,"id":36463352},{"atb":[[1.2,500.19],[1.25,400.15],[1.15,666.92]],"id":41308374},{"atl":[[2.44,25.26],[2.64,44.36],[2.84,39.54]],"id":41308374},{"spn":1.84,"spf":"NaN","id":41308374},{"atb":[[2.74,57.49],[2.84,54.36],[2.94,51.56]],"id":40846831},{"atl":[[8,5.19],[10,8.08],[15,5.19]],"id":40846831},{"spn":5.47,"spf":"NaN","id":40846831},{"atb":[[4,33.34],[4.5,28.58],[3.75,36.37]],"id":40199925},{"atl":[[16,2.42],[34,2.2],[22,3.46]],"id":40199925},{"spn":10.25,"spf":"NaN","id":40199925},{"atb":[[2.74,57.49],[2.84,54.36],[2.94,51.56]],"id":6780934},{"atl":[[8,5.19],[10,8.08],[15,5.19]],"id":6780934},{"spn":5.47,"spf":"NaN","id":6780934}],"con":true,"img":true}]}
{"op":"mcm","clk":"5347381395","pt":1646198202731,"mc":[{"id":"1.195453622","marketDefinition":{"bspMarket":true,"turnInPlayEnabled":false,"persistenceEnabled":false,"marketBaseRate":7.0,"eventId":"31272494","eventTypeId":"4339","numberOfWinners":2,"bettingType":"ODDS","marketType":"PLACE","marketTime":"2022-03-02T10:27:00.000Z","suspendTime":"2022-03-02T10:27:00.000Z","bspReconciled":false,"complete":true,"inPlay":false,"crossMatching":false,"runnersVoidable":false,"numberOfActiveRunners":7,"betDelay":0,"status":"OPEN","runners":[{"status":"ACTIVE","sortPriority":1,"id":40250501,"name":"1. Dwarshuis"},{"status":"ACTIVE","sortPriority":2,"id":6780934,"name":"2. Peacock"},{"status":"ACTIVE","sortPriority":3,"id":40846831,"name":"3. Rapid Voyage"},{"status":"ACTIVE","sortPriority":4,"id":23806261,"name":"4. Impending"},{"status":"ACTIVE","sortPriority":5,"id":40199925,"name":"6. Parzival"},{"status":"ACTIVE","sortPriority":6,"id":41308374,"name":"7. Gotham Baroness"},{"status":"ACTIVE","sortPriority":7,"id":36463352,"name":"8. Massimo"}],"regulators":["MR_INT"],"venue":"Traralgon","countryCode":"AU","discountAllowed":true,"timezone":"Australia/Sydney","openDate":"2022-03-02T08:31:00.000Z","version":4382425395,"name":"To Be Placed","eventName":"Traralgon (AUS) 2nd Mar"},"rc":[{"atb":[[4.3,30.3],[3.9,34.48],[3.65,37.73]],"id":23806261},{"atl":[[32,2.34],[21,3.63],[15.5,2.5]],"id":23806261},{"spn":9.9,"spf":"NaN","id":23806261},{"atb":[[3.4,41.66],[3.15,46.51],[3.65,37.73]],"id":40250501},{"atl":[[10.5,3.82],[21,3.63],[15.5,5.01]],"id":40250501},{"spn":7.07,"spf":"NaN","id":40250501},{"atb":[[1.2,500],[1.25,400],[1.3,333.33]],"id":36463352},{"spl":[[1.01,2.73]],"id":36463352},{"atl":[[2.54,23.61],[2.74,41.79],[2.94,37.48]],"id":36463352},{"spn":1.3,"spf":1.0,"id":36463352},{"atb":[[1.2,500],[1.25,400],[1.15,666.66]],"id":41308374},{"atl":[[2.44,25.25],[2.64,44.34],[2.84,39.52]],"id":41308374},{"spn":1.84,"spf":"NaN","id":41308374},{"atb":[[2.74,57.47],[2.84,54.34],[2.94,51.54]],"id":40846831},{"atl":[[8,5.19],[10,8.08],[15,5.19]],"id":40846831},{"spn":5.47,"spf":"NaN","id":40846831},{"atb":[[4,33.33],[4.5,28.57],[3.75,36.36]],"id":40199925},{"atl":[[16,2.42],[34,2.2],[22,3.46]],"id":40199925},{"spn":10.25,"spf":"NaN","id":40199925},{"atb":[[2.74,57.47],[2.84,54.34],[2.94,51.54]],"id":6780934},{"atl":[[8,5.19],[10,8.08],[15,5.19]],"id":6780934},{"spn":5.47,"spf":"NaN","id":6780934}],"con":true,"img":true}]}
{"op":"mcm","clk":"5347849092","pt":1646209002735,"mc":[{"id":"1.195453622","marketDefinition":{"bspMarket":true,"turnInPlayEnabled":false,"persistenceEnabled":false,"marketBaseRate":7.0,"eventId":"31272494","eventTypeId":"4339","numberOfWinners":2,"bettingType":"ODDS","marketType":"PLACE","marketTime":"2022-03-02T10:27:00.000Z","suspendTime":"2022-03-02T10:27:00.000Z","bspReconciled":false,"complete":true,"inPlay":false,"crossMatching":false,"runnersVoidable":false,"numberOfActiveRunners":7,"betDelay":0,"status":"OPEN","runners":[{"status":"ACTIVE","sortPriority":1,"id":40250501,"name":"1. Dwarshuis"},{"status":"ACTIVE","sortPriority":2,"id":6780934,"name":"2. Peacock"},{"status":"ACTIVE","sortPriority":3,"id":40846831,"name":"3. Rapid Voyage"},{"status":"ACTIVE","sortPriority":4,"id":23806261,"name":"4. Impending"},{"status":"ACTIVE","sortPriority":5,"id":40199925,"name":"6. Parzival"},{"status":"ACTIVE","sortPriority":6,"id":41308374,"name":"7. Gotham Baroness"},{"status":"ACTIVE","sortPriority":7,"id":36463352,"name":"8. Massimo"}],"regulators":["MR_INT"],"venue":"Traralgon","countryCode":"AU","discountAllowed":true,"timezone":"Australia/Sydney","openDate":"2022-03-02T08:31:00.000Z","version":4382425395,"name":"To Be Placed","eventName":"Traralgon (AUS) 2nd Mar"},"rc":[{"atb":[[4.3,30.29],[3.9,34.47],[3.65,37.72]],"id":23806261},{"atl":[[32,2.34],[21,3.63],[15.5,2.5]],"id":23806261},{"spn":9.9,"spf":"NaN","id":23806261},{"atb":[[3.4,41.65],[3.15,46.5],[3.65,37.72]],"id":40250501},{"atl":[[10.5,3.82],[21,3.63],[15.5,5.01]],"id":40250501},{"spn":7.07,"spf":"NaN","id":40250501},{"atb":[[1.2,499.86],[1.25,399.89],[1.3,333.24]],"id":36463352},{"spl":[[1.01,2.72]],"id":36463352},{"atl":[[2.54,23.6],[2.74,41.78],[2.94,37.47]],"id":36463352},{"spn":1.3,"spf":1.0,"id":36463352},{"atb":[[1.2,499.86],[1.25,399.89],[1.15,666.48]],"id":41308374},{"atl":[[2.44,25.24],[2.64,44.33],[2.84,39.51]],"id":41308374},{"spn":1.84,"spf":"NaN","id":41308374},{"atb":[[2.74,57.45],[2.84,54.33],[2.94,51.53]],"id":40846831},{"atl":[[8,5.19],[10,8.07],[15,5.19]],"id":40846831},{"spn":5.47,"spf":"NaN","id":40846831},{"atb":[[4,33.32],[4.5,28.56],[3.75,36.35]],"id":40199925},{"atl":[[16,2.42],[34,2.2],[22,3.46]],"id":40199925},{"spn":10.25,"spf":"NaN","id":40199925},{"atb":[[2.74,57.45],[2.84,54.33],[2.94,51.53]],"id":6780934},{"atl":[[8,5.19],[10,8.07],[15,5.19]],"id":6780934},{"spn":5.47,"spf":"NaN","id":6780934}],"con":true,"img":true}]}
{"op":"mcm","clk":"5347967701","pt":1646211492287,"mc":[{"id":"1.195453622","rc":[{"atb":[[4.3,30.29],[5.2,13.67],[3.9,34.47],[5.9,8.91],[3.65,37.72]],"id":23806261},{"atl":[[32,2.34],[36,2.72],[38,2.72],[21,3.63],[15.5,2.5]],"id":23806261},{"spn":10.7,"spf":"NaN","id":23806261},{"atb":[[3.45,22.56],[3.85,16.17],[3.4,41.65],[3.15,46.5],[3.65,37.72]],"id":40250501},{"atl":[[10.5,3.82],[21,6.36],[22,2.72],[15.5,5.01]],"id":40250501},{"spn":7.17,"spf":"NaN","id":40250501},{"atb":[[1.2,499.86],[1.25,399.89],[1.26,238.81],[1.3,333.24],[1.31,86.21]],"id":36463352},{"spl":[[1.01,2.72]],"id":36463352},{"atl":[[2.72,25.38],[2.92,32.33],[2.54,23.6],[2.74,41.78],[2.94,37.47]],"id":36463352},{"spn":1.31,"spf":1.0,"id":36463352},{"atb":[[1.2,499.86],[1.25,399.89],[1.15,666.48],[1.21,276.17],[1.26,134.77]],"id":41308374},{"atl":[[2.44,25.24],[2.64,44.33],[2.84,39.51],[2.58,26.95],[2.62,35.8]],"id":41308374},{"spn":1.85,"spf":"NaN","id":41308374},{"atb":[[2.74,57.45],[2.84,54.33],[2.96,22.28],[2.94,51.53],[2.48,37.15]],"id":40846831},{"atl":[[8,5.19],[10,8.07],[12.5,3.79],[13.5,4.07],[15,5.19]],"id":40846831},{"spn":5.48,"spf":"NaN","id":40846831},{"atb":[[4,33.32],[4.5,28.56],[5.2,10.39],[3.75,36.35],[4.7,15.15]],"id":40199925},{"atl":[[16,2.42],[32,2.72],[34,4.93],[22,3.46]],"id":40199925},{"spn":10.6,"spf":"NaN","id":40199925},{"atb":[[2.74,57.45],[2.44,40.65],[2.84,54.33],[2.96,22.28],[2.94,51.53]],"id":6780934},{"atl":[[8,5.19],[10,8.07],[12.5,3.79],[13,4.33],[15,5.19]],"id":6780934},{"spn":5.48,"spf":"NaN","id":6780934}],"con":true,"img":false}]}
{"op":"mcm","clk":"5347971035","pt":1646211575716,"mc":[{"id":"1.195453622","rc":[{"atb":[[3.45,0]],"id":40250501},{"atl":[[22,0]],"id":40250501},{"atl":[[2.72,0]],"id":36463352},{"atl":[[2.58,0]],"id":41308374},{"atl":[[34,2.2]],"id":40199925}],"con":true,"img":false}]}
{"op":"mcm","clk":"5347971040","pt":1646211575820,"mc":[{"id":"1.195453622","rc":[{"atb":[[3.7,22.56]],"id":40250501},{"atl":[[20,2.72]],"id":40250501},{"atl":[[2.52,25.38]],"id":36463352},{"atl":[[2.42,26.95]],"id":41308374},{"atl":[[32,5.45]],"id":40199925}],"con":true,"img":false}]}
{"op":"mcm","clk":"5348057342","pt":1646213236037,"mc":[{"id":"1.195453622","rc":[{"atb":[[4.3,30.24],[5.2,13.65],[3.9,68.9],[5.9,8.89],[3.65,37.66]],"id":23806261},{"atl":[[32,2.34],[36,2.72],[38,2.72],[21,3.62],[46,2.22],[15.5,2.5]],"id":23806261},{"atb":[[3.85,16.14],[3.7,22.52],[3.4,41.58],[3.15,46.42],[3.9,22.56],[3.65,37.66]],"id":40250501},{"atl":[[65,2],[20,2.72],[10.5,3.82],[21,6.35],[15.5,5]],"id":40250501},{"spn":7.2,"spf":"NaN","id":40250501},{"atb":[[1.2,499.07],[1.25,399.25],[1.26,238.43],[1.3,332.71],[1.31,86.07]],"id":36463352},{"spl":[[1.01,2.72]],"id":36463352},{"atl":[[2.92,32.28],[2.54,23.57],[2.74,41.71],[2.5,25.39],[2.52,25.34],[2.94,37.41]],"id":36463352},{"atb":[[1.2,499.07],[1.25,399.25],[1.15,665.43],[1.21,275.73],[1.26,134.56],[1.13,769.23]],"id":41308374},{"atl":[[2.4,26.95],[2.42,26.91],[2.44,25.2],[2.64,44.26],[2.84,39.45],[2.62,35.74]],"id":41308374},{"spn":1.83,"spf":"NaN","id":41308374},{"atb":[[4,33.27],[4.5,28.51],[3.8,35.71],[5.2,10.38],[3.75,36.29],[4.7,15.13]],"id":40199925},{"atl":[[16,2.41],[32,5.44],[34,2.2],[22,3.45],[30,3.45]],"id":40199925},{"atb":[[2.74,57.36],[2.42,70.42],[2.84,54.24],[2.96,22.24],[2.94,51.45],[2.48,37.09]],"id":40846831},{"atl":[[8,5.18],[10,8.06],[11.5,9.52],[12.5,3.79],[13.5,4.06],[15,5.18]],"id":40846831},{"atb":[[2.74,57.36],[2.44,40.59],[2.84,54.24],[2.98,50.51],[2.96,22.24],[2.94,51.45]],"id":6780934},{"atl":[[8,5.18],[10,8.06],[12.5,3.79],[13,4.32],[15,5.18],[60,2]],"id":6780934},{"spn":5.49,"spf":"NaN","id":6780934}],"con":true,"img":false}]}
{"op":"mcm","clk":"5348058335","pt":1646213256164,"mc":[{"id":"1.195453622","rc":[{"atl":[[38,0]],"id":23806261},{"atb":[[5.2,0],[4.7,0]],"id":40199925},{"atb":[[2.2,45.75]],"id":40846831},{"atl":[[12.5,0],[13,0]],"id":6780934}],"con":true,"img":false}]}
{"op":"mcm","clk":"5348058344","pt":1646213256268,"mc":[{"id":"1.195453622","rc":[{"atl":[[55,2.72]],"id":23806261},{"atb":[[2.48,0]],"id":40846831},{"atb":[[4.6,10.38],[4.1,15.13]],"id":40199925},{"atl":[[14.5,4.32],[15,8.97]],"id":6780934}],"con":true,"img":false}]}
{"op":"mcm","clk":"5348058574","pt":1646213261552,"mc":[{"id":"1.195453622","rc":[{"atb":[[5.2,0],[4.4,16.87]],"id":23806261}],"con":true,"img":false}]}
{"op":"mcm","clk":"5348058579","pt":1646213261654,"mc":[{"id":"1.195453622","rc":[{"atb":[[5.9,0],[4.7,12.82]],"id":23806261},{"atl":[[20,0]],"id":40250501},{"atl":[[2.62,0]],"id":41308374}],"con":true,"img":false}]}
{"op":"mcm","clk":"5348058587","pt":1646213261761,"mc":[{"id":"1.195453622","rc":[{"atl":[[24,2.72]],"id":40250501},{"atl":[[2.82,35.74]],"id":41308374}],"con":true,"img":false}]}
{"op":"mcm","clk":"5348058932","pt":1646213268485,"mc":[{"id":"1.195453622","rc":[{"atb":[[3.85,0],[3.7,0]],"id":40250501},{"atl":[[2.52,0]],"id":36463352},{"atl":[[2.42,0]],"id":41308374},{"atl":[[32,0]],"id":40199925},{"atl":[[12.5,0]],"id":40846831}],"con":true,"img":false}]}
{"op":"mcm","clk":"5348058937","pt":1646213268537,"mc":[{"id":"1.195453622","rc":[{"atb":[[3.45,22.52],[3.7,16.14]],"id":40250501},{"atl":[[2.72,25.34]],"id":36463352},{"atl":[[2.38,26.91]],"id":41308374},{"atl":[[9.8,3.79]],"id":40846831},{"atl":[[25,2.72],[27,2.72]],"id":40199925}],"con":true,"img":false}]}
{"op":"mcm","clk":"5348058944","pt":1646213268640,"mc":[{"id":"1.195453622","rc":[{"atb":[[3.7,53.18],[3.9,0]],"id":40250501},{"atl":[[2.5,0],[2.52,50.78]],"id":36463352},{"atl":[[2.4,0],[2.42,53.9]],"id":41308374}],"con":true,"img":false}]}
{"op":"mcm","clk":"5348059242","pt":1646213274553,"mc":[{"id":"1.195453622","rc":[{"atl":[[36,0]],"id":23806261}],"con":true,"img":false}]}
{"op":"mcm","clk":"5348059248","pt":1646213274659,"mc":[{"id":"1.195453622","rc":[{"atl":[[46,4.94]],"id":23806261}],"con":true,"img":false}]}
{"op":"mcm","clk":"5348059777","pt":1646213285586,"mc":[{"id":"1.195453622","rc":[{"atl":[[2.38,0]],"id":41308374}],"con":true,"img":false}]}
{"op":"mcm","clk":"5348059780","pt":1646213285689,"mc":[{"id":"1.195453622","rc":[{"atl":[[2.4,26.91]],"id":41308374}],"con":true,"img":false}]}
{"op":"mcm","clk":"5348060207","pt":1646213294983,"mc":[{"id":"1.195453622","rc":[{"atl":[[9.8,10.03],[13.5,0]],"id":40846831}],"con":true,"img":false}]}
{"op":"mcm","clk":"5348060726","pt":1646213304791,"mc":[{"id":"1.195453622","rc":[{"atb":[[6.2,8.38],[4.7,0]],"id":23806261},{"atl":[[46,2.22]],"id":23806261},{"spn":10.85,"spf":"NaN","id":23806261},{"atb":[[3.7,37.04]],"id":40250501},{"spn":7.1,"spf":"NaN","id":40250501},{"atl":[[2.72,0]],"id":36463352},{"spn":10.3,"spf":"NaN","id":40199925}],"con":true,"img":false}]}
{"op":"mcm","clk":"5348060732","pt":1646213304892,"mc":[{"id":"1.195453622","rc":[{"atl":[[38,2.72]],"id":23806261},{"atb":[[3.95,16.14]],"id":40250501},{"atl":[[2.5,25.34]],"id":36463352}],"con":true,"img":false}]}
{"op":"mcm","clk":"5348060750","pt":1646213305334,"mc":[{"id":"1.195453622","rc":[{"atb":[[4,33.33],[3.7,0]],"id":40250501},{"atl":[[2.52,0],[2.48,25.35]],"id":36463352},{"atl":[[2.42,0],[2.38,26.91]],"id":41308374}],"con":true,"img":false}]}
{"op":"mcm","clk":"5348060799","pt":1646213306236,"mc":[{"id":"1.195453622","rc":[{"atb":[[6.2,0],[4.7,11.78]],"id":23806261},{"atl":[[9.8,3.79]],"id":40846831},{"atl":[[14.5,0]],"id":6780934}],"con":true,"img":false}]}
{"op":"mcm","clk":"5348060802","pt":1646213306284,"mc":[{"id":"1.195453622","rc":[{"atl":[[11,6.24]],"id":40846831},{"atl":[[15.5,4.32]],"id":6780934}],"con":true,"img":false}]}
{"op":"mcm","clk":"5348061442","pt":1646213318940,"mc":[{"id":"1.195453622","rc":[{"atl":[[55,0]],"id":23806261}],"con":true,"img":false}]}
{"op":"mcm","clk":"5348061445","pt":1646213319047,"mc":[{"id":"1.195453622","rc":[{"atl":[[38,5.44]],"id":23806261}],"con":true,"img":false}]}
{"op":"mcm","clk":"5348062512","pt":1646213338070,"mc":[{"id":"1.195453622","rc":[{"atb":[[4.7,0]],"id":23806261},{"atb":[[3.45,0],[3.95,0]],"id":40250501},{"atl":[[2.5,0]],"id":36463352},{"atl":[[2.4,0],[2.82,0]],"id":41308374},{"atb":[[2.96,0]],"id":6780934}],"con":true,"img":false}]}
{"op":"mcm","clk":"5348062517","pt":1646213338176,"mc":[{"id":"1.195453622","rc":[{"atb":[[5.1,11.78]],"id":23806261},{"atb":[[4.1,16.14],[3.7,22.52]],"id":40250501},{"atl":[[2.46,25.34]],"id":36463352},{"atl":[[2.36,26.91],[2.62,35.74]],"id":41308374},{"atb":[[3,22.24]],"id":6780934}],"con":true,"img":false}]}
{"op":"mcm","clk":"5348062522","pt":1646213338275,"mc":[{"id":"1.195453622","rc":[{"atb":[[4,0],[3.7,59.56]],"id":40250501},{"atl":[[2.52,50.7],[2.48,0]],"id":36463352},{"atl":[[2.42,53.82],[2.38,0]],"id":41308374},{"atb":[[2.98,0],[2.96,51.02]],"id":6780934}],"con":true,"img":false}]}
{"op":"mcm","clk":"5348063558","pt":1646213357389,"mc":[{"id":"1.195453622","rc":[{"atl":[[2.46,0]],"id":36463352},{"atl":[[2.36,0]],"id":41308374},{"atb":[[2.2,0]],"id":40846831}],"con":true,"img":false}]}
{"op":"mcm","clk":"5348063562","pt":1646213357490,"mc":[{"id":"1.195453622","rc":[{"atl":[[2.5,25.34]],"id":36463352},{"atl":[[2.4,26.91]],"id":41308374},{"atb":[[2.44,45.75]],"id":40846831}],"con":true,"img":false}]}
{"op":"mcm","clk":"5348063765","pt":1646213361113,"mc":[{"id":"1.195453622","rc":[{"atl":[[24,0]],"id":40250501},{"atb":[[1.21,0],[1.26,357.27]],"id":41308374},{"atl":[[11,0]],"id":40846831},{"atl":[[15.5,0]],"id":6780934}],"con":true,"img":false}]}
{"op":"mcm","clk":"5348063769","pt":1646213361204,"mc":[{"id":"1.195453622","rc":[{"atl":[[20,2.72]],"id":40250501},{"atl":[[9.8,10.03]],"id":40846831},{"atl":[[14.5,4.32]],"id":6780934}],"con":true,"img":false}]}
{"op":"mcm","clk":"5348064160","pt":1646213368504,"mc":[{"id":"1.195453622","rc":[{"spn":10.3,"spf":"NaN","id":23806261},{"spn":7.3,"spf":"NaN","id":40250501},{"atb":[[2.44,0],[2.98,29.52]],"id":6780934},{"spn":5.5,"spf":"NaN","id":6780934}],"con":true,"img":false}]}
{"op":"mcm","clk":"5348064494","pt":1646213374197,"mc":[{"id":"1.195453622","rc":[{"atb":[[4,33.33],[3.7,22.52]],"id":40250501},{"atl":[[2.52,0],[2.48,25.35]],"id":36463352},{"atl":[[2.42,0],[2.38,26.91]],"id":41308374},{"atb":[[2.96,0],[3.05,29.52]],"id":6780934}],"con":true,"img":false}]}
{"op":"mcm","clk":"5348065153","pt":1646213387017,"mc":[{"id":"1.195453622","rc":[{"atb":[[2.98,0]],"id":6780934}],"con":true,"img":false}]}
{"op":"mcm","clk":"5348065161","pt":1646213387118,"mc":[{"id":"1.195453622","rc":[{"atb":[[2.96,29.52]],"id":6780934}],"con":true,"img":false}]}
{"op":"mcm","clk":"5348065220","pt":1646213388455,"mc":[{"id":"1.195453622","rc":[{"atb":[[4,0],[3.9,34.48]],"id":40250501}],"con":true,"img":false}]}
{"op":"mcm","clk":"5348067518","pt":1646213426374,"mc":[{"id":"1.195453622","rc":[{"atl":[[38,2.72]],"id":23806261},{"atl":[[2.5,0]],"id":36463352},{"atl":[[2.4,0]],"id":41308374},{"atl":[[25,0],[27,0]],"id":40199925},{"atb":[[3,0]],"id":6780934}],"con":true,"img":false}]}
{"op":"mcm","clk":"5348067524","pt":1646213426478,"mc":[{"id":"1.195453622","rc":[{"atl":[[36,2.72]],"id":23806261},{"atl":[[2.52,50.7],[2.46,25.34]],"id":36463352},{"atl":[[2.36,26.91],[2.42,53.82],[2.38,0]],"id":41308374},{"atl":[[21,2.72],[23,2.72]],"id":40199925},{"atb":[[3.1,22.24],[2.98,50.51],[3.05,0]],"id":6780934}],"con":true,"img":false}]}
{"op":"mcm","clk":"5348067528","pt":1646213426581,"mc":[{"id":"1.195453622","rc":[{"atl":[[2.48,0]],"id":36463352}],"con":true,"img":false}]}
{"op":"mcm","clk":"5348067718","pt":1646213430790,"mc":[{"id":"1.195453622","rc":[{"atb":[[1.26,134.56]],"id":41308374},{"spn":1.81,"spf":"NaN","id":41308374},{"spn":5.55,"spf":"NaN","id":6780934}],"con":true,"img":false}]}
{"op":"mcm","clk":"5348067723","pt":1646213430892,"mc":[{"id":"1.195453622","rc":[{"atb":[[1.22,222.7]],"id":41308374}],"con":true,"img":false}]}
{"op":"mcm","clk":"5348068161","pt":1646213438722,"mc":[{"id":"1.195453622","rc":[{"atb":[[5.1,0]],"id":23806261},{"atl":[[2.46,0]],"id":36463352},{"atl":[[2.36,0]],"id":41308374}],"con":true,"img":false}]}
{"op":"mcm","clk":"5348068164","pt":1646213438825,"mc":[{"id":"1.195453622","rc":[{"atb":[[5.2,11.78]],"id":23806261},{"atl":[[2.5,25.34]],"id":36463352},{"atl":[[2.4,26.91]],"id":41308374}],"con":true,"img":false}]}
{"op":"mcm","clk":"5348068168","pt":1646213438928,"mc":[{"id":"1.195453622","rc":[{"atb":[[3.9,34.42],[3.65,75.4]],"id":23806261}],"con":true,"img":false}]}
{"op":"mcm","clk":"5348069448","pt":1646213461546,"mc":[{"id":"1.195453622","rc":[{"atl":[[2.48,25.35]],"id":36463352},{"atl":[[2.42,0],[2.38,26.91]],"id":41308374},{"atb":[[2.98,0],[3.15,29.52]],"id":6780934}],"con":true,"img":false}]}
{"op":"mcm","clk":"5348069459","pt":1646213461651,"mc":[{"id":"1.195453622","rc":[{"atl":[[2.52,0]],"id":36463352}],"con":true,"img":false}]}
{"op":"mcm","clk":"5348069699","pt":1646213465682,"mc":[{"id":"1.195453622","rc":[{"atb":[[5.2,0],[4.4,0]],"id":23806261},{"atl":[[36,0],[38,0]],"id":23806261},{"atb":[[4.1,0],[3.7,0]],"id":40250501},{"atl":[[20,0],[21,3.62]],"id":40250501},{"atb":[[1.26,0],[1.31,0]],"id":36463352},{"atl":[[2.92,0],[2.5,0]],"id":36463352},{"atb":[[1.26,0],[1.22,0]],"id":41308374},{"atl":[[2.4,0],[2.62,0]],"id":41308374},{"atb":[[4.6,0],[4.1,0]],"id":40199925},{"atl":[[21,0],[23,0]],"id":40199925},{"atb":[[2.44,0],[2.96,0]],"id":40846831},{"atl":[[9.8,0]],"id":40846831},{"atb":[[3.1,0],[2.96,0]],"id":6780934},{"atl":[[14.5,0],[15,5.18]],"id":6780934}],"con":true,"img":false}]}
{"op":"mcm","clk":"5348069714","pt":1646213465838,"mc":[{"id":"1.195453622","rc":[{"atb":[[3.7,37.04],[3.9,0]],"id":40250501}],"con":true,"img":false}]}
{"op":"mcm","clk":"5348069760","pt":1646213466666,"mc":[{"id":"1.195453622","rc":[{"atl":[[2.48,0]],"id":36463352},{"atl":[[2.38,0]],"id":41308374},{"atb":[[2.96,51.02]],"id":6780934}],"con":true,"img":false}]}
{"op":"mcm","clk":"5348069769","pt":1646213466770,"mc":[{"id":"1.195453622","rc":[{"atl":[[2.52,50.7]],"id":36463352},{"atl":[[2.42,53.82]],"id":41308374},{"atb":[[3.15,0]],"id":6780934}],"con":true,"img":false}]}
{"op":"mcm","clk":"5348071624","pt":1646213503047,"mc":[{"id":"1.195453622","rc":[{"atb":[[5.2,10.38],[4.7,15.5]],"id":23806261},{"atl":[[38,2.72],[40,2.72]],"id":23806261},{"spn":10.35,"spf":"NaN","id":23806261},{"atb":[[3.95,14.78],[3.7,57.47]],"id":40250501},{"atl":[[20,2.72],[22,2.72]],"id":40250501},{"spn":7.22,"spf":"NaN","id":40250501},{"atb":[[1.26,238.43],[1.31,86.07]],"id":36463352},{"atl":[[2.92,32.28],[2.5,29.06]],"id":36463352},{"atb":[[1.26,137.88],[1.22,263.2]],"id":41308374},{"atl":[[2.4,31.14],[2.62,35.74]],"id":41308374},{"spn":1.83,"spf":"NaN","id":41308374},{"atb":[[2.26,43.57],[2.96,22.24]],"id":40846831},{"atl":[[10.5,4.35],[11,5.48]],"id":40846831},{"atb":[[4.3,13.21],[3.85,19.64]],"id":40199925},{"atl":[[23,2.72],[25,2.72]],"id":40199925},{"spn":10.25,"spf":"NaN","id":40199925},{"atb":[[2.96,80.84],[3.05,22.01]],"id":6780934},{"atl":[[14.5,3.23],[15.5,4.03]],"id":6780934},{"spn":5.52,"spf":"NaN","id":6780934}],"con":true,"img":false}]}
{"op":"mcm","clk":"5348071631","pt":1646213503195,"mc":[{"id":"1.195453622","rc":[{"atb":[[3.7,20.43],[3.9,34.48]],"id":40250501},{"atl":[[2.52,0],[2.48,29.06]],"id":36463352},{"atl":[[2.42,0],[2.38,31.14]],"id":41308374},{"atb":[[3.1,47.62],[2.96,29.82]],"id":6780934}],"con":true,"img":false}]}
{"op":"mcm","clk":"5348073535","pt":1646213539057,"mc":[{"id":"1.195453622","rc":[{"atl":[[2.5,0]],"id":36463352},{"atl":[[2.4,0]],"id":41308374},{"atl":[[10.5,0]],"id":40846831},{"atb":[[4.3,0]],"id":40199925},{"atb":[[3.05,0]],"id":6780934}],"con":true,"img":false}]}
{"op":"mcm","clk":"5348073539","pt":1646213539160,"mc":[{"id":"1.195453622","rc":[{"atl":[[2.46,29.06]],"id":36463352},{"atl":[[2.36,31.14]],"id":41308374},{"atb":[[4.6,13.21]],"id":40199925},{"atl":[[9.8,4.35]],"id":40846831},{"atb":[[3.15,22.01]],"id":6780934}],"con":true,"img":false}]}
{"op":"mcm","clk":"5348073544","pt":1646213539264,"mc":[{"id":"1.195453622","rc":[{"atl":[[2.52,58.12],[2.48,0]],"id":36463352},{"atl":[[2.42,62.28],[2.38,0]],"id":41308374},{"atb":[[3.1,0],[2.98,50.51]],"id":6780934}],"con":true,"img":false}]}
{"op":"mcm","clk":"5348073549","pt":1646213539367,"mc":[{"id":"1.195453622","rc":[{"atl":[[2.52,0],[2.44,29.06]],"id":36463352},{"atl":[[2.42,0],[2.34,31.14]],"id":41308374},{"atb":[[3.2,29.82],[2.98,0]],"id":6780934}],"con":true,"img":false}]}
{"op":"mcm","clk":"5348074981","pt":1646213564138,"mc":[{"id":"1.195453622","rc":[{"atl":[[22,0]],"id":40250501},{"spn":1.8,"spf":"NaN","id":41308374},{"atb":[[3.85,0]],"id":40199925},{"atl":[[25,0]],"id":40199925},{"spn":10.3,"spf":"NaN","id":40199925},{"atl":[[11,0]],"id":40846831},{"atl":[[15.5,0]],"id":6780934},{"spn":5.6,"spf":"NaN","id":6780934}],"con":true,"img":false}]}
{"op":"mcm","clk":"5348074986","pt":1646213564201,"mc":[{"id":"1.195453622","rc":[{"atl":[[20,5.44]],"id":40250501},{"atl":[[9.8,9.84]],"id":40846831},{"atb":[[4.1,19.64]],"id":40199925},{"atl":[[21,2.72]],"id":40199925},{"atl":[[14.5,7.26]],"id":6780934}],"con":true,"img":false}]}
{"op":"mcm","clk":"5348075399","pt":1646213570311,"mc":[{"id":"1.195453622","rc":[{"atb":[[4,20.44],[3.9,0]],"id":40250501}],"con":true,"img":false}]}
{"op":"mcm","clk":"5348076243","pt":1646213584072,"mc":[{"id":"1.195453622","rc":[{"atl":[[2.46,0]],"id":36463352},{"atl":[[2.36,0]],"id":41308374},{"atb":[[3.15,0]],"id":6780934}],"con":true,"img":false}]}
{"op":"mcm","clk":"5348076249","pt":1646213584130,"mc":[{"id":"1.195453622","rc":[{"atl":[[2.42,29.06]],"id":36463352},{"atl":[[2.32,31.14]],"id":41308374},{"atb":[[3.25,22.01]],"id":6780934}],"con":true,"img":false}]}
{"op":"mcm","clk":"5348076252","pt":1646213584235,"mc":[{"id":"1.195453622","rc":[{"atl":[[2.52,58.12],[2.44,0]],"id":36463352},{"atl":[[2.42,62.28],[2.34,0]],"id":41308374},{"atb":[[3.2,0],[2.98,50.51]],"id":6780934}],"con":true,"img":false}]}
{"op":"mcm","clk":"5348077493","pt":1646213600504,"mc":[{"id":"1.195453622","rc":[{"atl":[[40,0]],"id":23806261},{"atl":[[2.42,0]],"id":36463352},{"atl":[[2.32,0]],"id":41308374},{"atb":[[3.25,0]],"id":6780934}],"con":true,"img":false}]}
{"op":"mcm","clk":"5348077499","pt":1646213600610,"mc":[{"id":"1.195453622","rc":[{"atl":[[42,2.72]],"id":23806261},{"atl":[[2.5,29.06]],"id":36463352},{"atl":[[2.4,31.14]],"id":41308374},{"atb":[[3.05,22.01]],"id":6780934}],"con":true,"img":false}]}
{"op":"mcm","clk":"5348077967","pt":1646213608087,"mc":[{"id":"1.195453622","rc":[{"atb":[[3.95,0]],"id":40250501}],"con":true,"img":false}]}
{"op":"mcm","clk":"5348077974","pt":1646213608190,"mc":[{"id":"1.195453622","rc":[{"atb":[[4,0],[4.1,14.78]],"id":40250501}],"con":true,"img":false}]}
{"op":"mcm","clk":"5348077981","pt":1646213608295,"mc":[{"id":"1.195453622","rc":[{"atb":[[3.75,36.36]],"id":40250501}],"con":true,"img":false}]}
{"op":"mcm","clk":"5348078634","pt":1646213617817,"mc":[{"id":"1.195453622","rc":[{"atl":[[2.52,0],[2.48,29.06]],"id":36463352},{"atl":[[2.42,0],[2.38,31.14]],"id":41308374},{"atb":[[3.1,29.82],[2.98,0]],"id":6780934}],"con":true,"img":false}]}
{"op":"mcm","clk":"5348080166","pt":1646213641567,"mc":[{"id":"1.195453622","rc":[{"atb":[[3.9,34.48],[3.75,0]],"id":40250501},{"spn":7.3,"spf":"NaN","id":40250501},{"spn":1.82,"spf":"NaN","id":41308374},{"spn":5.55,"spf":"NaN","id":6780934}],"con":true,"img":false}]}
{"op":"mcm","clk":"5348080612","pt":1646213647989,"mc":[{"id":"1.195453622","rc":[{"atb":[[2.26,0]],"id":40846831}],"con":true,"img":false}]}
{"op":"mcm","clk":"5348080623","pt":1646213648093,"mc":[{"id":"1.195453622","rc":[{"atb":[[2.44,43.57]],"id":40846831}],"con":true,"img":false}]}
{"op":"mcm","clk":"5348080963","pt":1646213654071,"mc":[{"id":"1.195453622","rc":[{"atl":[[2.5,0]],"id":36463352},{"atl":[[2.4,0]],"id":41308374},{"atb":[[3.05,0]],"id":6780934}],"con":true,"img":false}]}
{"op":"mcm","clk":"5348080975","pt":1646213654171,"mc":[{"id":"1.195453622","rc":[{"atl":[[2.46,29.06]],"id":36463352},{"atl":[[2.36,31.14]],"id":41308374},{"atb":[[3.15,22.01]],"id":6780934}],"con":true,"img":false}]}
{"op":"mcm","clk":"5348080979","pt":1646213654269,"mc":[{"id":"1.195453622","rc":[{"atl":[[2.52,58.12]],"id":36463352},{"atl":[[2.42,62.28],[2.38,0]],"id":41308374},{"atb":[[3.1,0],[2.98,50.51]],"id":6780934}],"con":true,"img":false}]}
{"op":"mcm","clk":"5348080988","pt":1646213654380,"mc":[{"id":"1.195453622","rc":[{"atl":[[2.48,0]],"id":36463352}],"con":true,"img":false}]}
{"op":"mcm","clk":"5348081700","pt":1646213665115,"mc":[{"id":"1.195453622","rc":[{"atl":[[2.46,0]],"id":36463352},{"atl":[[2.36,0]],"id":41308374},{"atb":[[2.44,0]],"id":40846831}],"con":true,"img":false}]}
{"op":"mcm","clk":"5348081708","pt":1646213665171,"mc":[{"id":"1.195453622","rc":[{"atl":[[2.5,29.06]],"id":36463352},{"atl":[[2.4,31.14]],"id":41308374},{"atb":[[2.24,43.57]],"id":40846831}],"con":true,"img":false}]}
{"op":"mcm","clk":"5348082954","pt":1646213687030,"mc":[{"id":"1.195453622","rc":[{"atl":[[2.48,29.06]],"id":36463352},{"atl":[[2.42,0]],"id":41308374},{"atb":[[3.2,29.82]],"id":6780934}],"con":true,"img":false}]}
{"op":"mcm","clk":"5348082959","pt":1646213687134,"mc":[{"id":"1.195453622","rc":[{"atl":[[2.52,0]],"id":36463352},{"atl":[[2.38,31.14]],"id":41308374},{"atb":[[2.98,0]],"id":6780934}],"con":true,"img":false}]}
{"op":"mcm","clk":"5348084751","pt":1646213718180,"mc":[{"id":"1.195453622","rc":[{"atl":[[2.5,0]],"id":36463352},{"atl":[[2.4,0]],"id":41308374},{"atb":[[3.15,0]],"id":6780934},{"spn":5.6,"spf":"NaN","id":6780934}],"con":true,"img":false}]}
{"op":"mcm","clk":"5348084757","pt":1646213718282,"mc":[{"id":"1.195453622","rc":[{"atl":[[2.46,29.06]],"id":36463352},{"atl":[[2.36,31.14]],"id":41308374},{"atb":[[3.2,0],[3.25,22.01],[2.98,50.51]],"id":6780934}],"con":true,"img":false}]}
{"op":"mcm","clk":"5348084762","pt":1646213718387,"mc":[{"id":"1.195453622","rc":[{"atl":[[2.52,58.12],[2.48,0]],"id":36463352},{"atl":[[2.42,62.28],[2.38,0]],"id":41308374}],"con":true,"img":false}]}
{"op":"mcm","clk":"5348084815","pt":1646213719475,"mc":[{"id":"1.195453622","rc":[{"atb":[[2.98,0],[3.3,29.82]],"id":6780934}],"con":true,"img":false}]}
{"op":"mcm","clk":"5348084820","pt":1646213719577,"mc":[{"id":"1.195453622","rc":[{"atl":[[2.42,0],[2.34,31.14]],"id":41308374}],"con":true,"img":false}]}
{"op":"mcm","clk":"5348085522","pt":1646213730811,"mc":[{"id":"1.195453622","rc":[{"atl":[[2.46,0]],"id":36463352}],"con":true,"img":false}]}
{"op":"mcm","clk":"5348085530","pt":1646213730910,"mc":[{"id":"1.195453622","rc":[{"atl":[[2.5,29.06]],"id":36463352}],"con":true,"img":false}]}
{"op":"mcm","clk":"5348086717","pt":1646213750562,"mc":[{"id":"1.195453622","rc":[{"atl":[[2.36,0]],"id":41308374},{"atb":[[3.25,0]],"id":6780934}],"con":true,"img":false}]}
{"op":"mcm","clk":"5348086724","pt":1646213750620,"mc":[{"id":"1.195453622","rc":[{"atl":[[2.52,0],[2.48,29.06]],"id":36463352},{"atl":[[2.32,31.14]],"id":41308374},{"atb":[[3.35,22.01]],"id":6780934}],"con":true,"img":false}]}
{"op":"mcm","clk":"5348086732","pt":1646213750725,"mc":[{"id":"1.195453622","rc":[{"atl":[[2.42,62.28],[2.34,0]],"id":41308374},{"atb":[[2.98,50.51],[3.3,0]],"id":6780934}],"con":true,"img":false}]}
{"op":"mcm","clk":"5348086905","pt":1646213753627,"mc":[{"id":"1.195453622","rc":[{"atb":[[4,33.33],[3.9,0]],"id":40250501}],"con":true,"img":false}]}
{"op":"mcm","clk":"5348086954","pt":1646213754459,"mc":[{"id":"1.195453622","rc":[{"atl":[[42,0]],"id":23806261},{"atb":[[3.35,0]],"id":6780934}],"con":true,"img":false}]}
{"op":"mcm","clk":"5348086959","pt":1646213754566,"mc":[{"id":"1.195453622","rc":[{"atl":[[44,2.72]],"id":23806261},{"atb":[[3.15,22.01]],"id":6780934}],"con":true,"img":false}]}
{"op":"mcm","clk":"5348087397","pt":1646213761986,"mc":[{"id":"1.195453622","rc":[{"atl":[[2.32,0]],"id":41308374}],"con":true,"img":false}]}
{"op":"mcm","clk":"5348087406","pt":1646213762096,"mc":[{"id":"1.195453622","rc":[{"atl":[[2.4,31.14]],"id":41308374}],"con":true,"img":false}]}
{"op":"mcm","clk":"5348088056","pt":1646213772851,"mc":[{"id":"1.195453622","rc":[{"atl":[[2.92,0]],"id":36463352}],"con":true,"img":false}]}
{"op":"mcm","clk":"5348088059","pt":1646213772954,"mc":[{"id":"1.195453622","rc":[{"atl":[[2.72,32.28]],"id":36463352}],"con":true,"img":false}]}
{"op":"mcm","clk":"5348088724","pt":1646213783793,"mc":[{"id":"1.195453622","rc":[{"atl":[[2.5,0]],"id":36463352},{"spn":1.83,"spf":"NaN","id":41308374},{"spn":5.57,"spf":"NaN","id":6780934}],"con":true,"img":false}]}
{"op":"mcm","clk":"5348088731","pt":1646213783897,"mc":[{"id":"1.195453622","rc":[{"atl":[[2.46,29.06]],"id":36463352}],"con":true,"img":false}]}
{"op":"mcm","clk":"5348089668","pt":1646213798796,"mc":[{"id":"1.195453622","rc":[{"atb":[[4,0],[3.9,34.48]],"id":40250501}],"con":true,"img":false}]}
{"op":"mcm","clk":"5348089702","pt":1646213799419,"mc":[{"id":"1.195453622","rc":[{"atl":[[2.44,29.06],[2.48,0]],"id":36463352}],"con":true,"img":false}]}
{"op":"mcm","clk":"5348090182","pt":1646213809000,"mc":[{"id":"1.195453622","rc":[{"atl":[[2.42,0]],"id":41308374},{"atb":[[2.98,0]],"id":6780934}],"con":true,"img":false}]}
{"op":"mcm","clk":"5348090193","pt":1646213809206,"mc":[{"id":"1.195453622","rc":[{"atl":[[2.38,31.14]],"id":41308374},{"atb":[[3.2,29.82]],"id":6780934}],"con":true,"img":false}]}
{"op":"mcm","clk":"5348091482","pt":1646213830275,"mc":[{"id":"1.195453622","rc":[{"atb":[[4,33.33],[3.9,0]],"id":40250501}],"con":true,"img":false}]}
{"op":"mcm","clk":"5348091689","pt":1646213834052,"mc":[{"id":"1.195453622","rc":[{"atl":[[2.46,0]],"id":36463352}],"con":true,"img":false}]}
{"op":"mcm","clk":"5348091693","pt":1646213834153,"mc":[{"id":"1.195453622","rc":[{"atl":[[2.42,29.06],[2.52,58.12],[2.44,0]],"id":36463352}],"con":true,"img":false}]}
{"op":"mcm","clk":"5348091707","pt":1646213834359,"mc":[{"id":"1.195453622","rc":[{"atl":[[2.4,29.06],[2.52,0]],"id":36463352}],"con":true,"img":false}]}
{"op":"mcm","clk":"5348092037","pt":1646213840174,"mc":[{"id":"1.195453622","rc":[{"atl":[[2.4,0]],"id":41308374},{"atb":[[3.15,0]],"id":6780934}],"con":true,"img":false}]}
{"op":"mcm","clk":"5348092039","pt":1646213840274,"mc":[{"id":"1.195453622","rc":[{"atl":[[2.36,31.14]],"id":41308374},{"atb":[[3.25,22.01]],"id":6780934}],"con":true,"img":false}]}
{"op":"mcm","clk":"5348092043","pt":1646213840381,"mc":[{"id":"1.195453622","rc":[{"atl":[[2.42,62.28],[2.38,0]],"id":41308374},{"atb":[[3.2,0],[2.98,50.51]],"id":6780934}],"con":true,"img":false}]}
{"op":"mcm","clk":"5348092668","pt":1646213851414,"mc":[{"id":"1.195453622","rc":[{"atl":[[2.36,0]],"id":41308374},{"spn":1.84,"spf":"NaN","id":41308374},{"spn":5.62,"spf":"NaN","id":6780934}],"con":true,"img":false}]}
{"op":"mcm","clk":"5348092673","pt":1646213851520,"mc":[{"id":"1.195453622","rc":[{"atl":[[2.4,31.14]],"id":41308374}],"con":true,"img":false}]}
{"op":"mcm","clk":"5348093590","pt":1646213868220,"mc":[{"id":"1.195453622","rc":[{"atl":[[2.42,0]],"id":36463352}],"con":true,"img":false}]}
{"op":"mcm","clk":"5348093599","pt":1646213868322,"mc":[{"id":"1.195453622","rc":[{"atl":[[2.4,0],[2.38,29.06],[2.52,58.12]],"id":36463352}],"con":true,"img":false}]}
{"op":"mcm","clk":"5348093741","pt":1646213871296,"mc":[{"id":"1.195453622","rc":[{"atl":[[2.38,31.14]],"id":41308374},{"atb":[[2.98,0],[3.3,29.82]],"id":6780934}],"con":true,"img":false}]}
{"op":"mcm","clk":"5348093749","pt":1646213871400,"mc":[{"id":"1.195453622","rc":[{"atl":[[2.42,0]],"id":41308374}],"con":true,"img":false}]}
{"op":"mcm","clk":"5348094439","pt":1646213883621,"mc":[{"id":"1.195453622","rc":[{"atl":[[2.38,0]],"id":36463352}],"con":true,"img":false}]}
{"op":"mcm","clk":"5348094445","pt":1646213883724,"mc":[{"id":"1.195453622","rc":[{"atl":[[2.5,29.06]],"id":36463352}],"con":true,"img":false}]}
{"op":"mcm","clk":"5348095281","pt":1646213898987,"mc":[{"id":"1.195453622","rc":[{"atl":[[2.52,0],[2.48,29.06]],"id":36463352}],"con":true,"img":false}]}
{"op":"mcm","clk":"5348095298","pt":1646213899246,"mc":[{"id":"1.195453622","rc":[{"atl":[[38,0]],"id":23806261}],"con":true,"img":false}]}
{"op":"mcm","clk":"5348095303","pt":1646213899349,"mc":[{"id":"1.195453622","rc":[{"atl":[[44,5.44]],"id":23806261}],"con":true,"img":false}]}
{"op":"mcm","clk":"5348095611","pt":1646213904576,"mc":[{"id":"1.195453622","rc":[{"atl":[[2.4,0]],"id":41308374},{"atb":[[3.25,0]],"id":6780934}],"con":true,"img":false}]}
{"op":"mcm","clk":"5348095619","pt":1646213904679,"mc":[{"id":"1.195453622","rc":[{"atl":[[2.36,31.14]],"id":41308374},{"atb":[[3.35,22.01]],"id":6780934}],"con":true,"img":false}]}
{"op":"mcm","clk":"5348095627","pt":1646213904783,"mc":[{"id":"1.195453622","rc":[{"atl":[[2.42,62.28],[2.38,0]],"id":41308374},{"atb":[[2.98,50.51],[3.3,0]],"id":6780934}],"con":true,"img":false}]}
{"op":"mcm","clk":"5348095633","pt":1646213904888,"mc":[{"id":"1.195453622","rc":[{"atl":[[2.42,0],[2.34,31.14]],"id":41308374},{"atb":[[3.4,29.82]],"id":6780934}],"con":true,"img":false}]}
{"op":"mcm","clk":"5348095640","pt":1646213904992,"mc":[{"id":"1.195453622","rc":[{"atb":[[2.98,0]],"id":6780934}],"con":true,"img":false}]}
{"op":"mcm","clk":"5348096205","pt":1646213914206,"mc":[{"id":"1.195453622","rc":[{"spn":1.8,"spf":"NaN","id":41308374},{"atl":[[14.5,3.23]],"id":6780934},{"spn":5.7,"spf":"NaN","id":6780934}],"con":true,"img":false}]}
{"op":"mcm","clk":"5348096210","pt":1646213914309,"mc":[{"id":"1.195453622","rc":[{"atl":[[17,4.03]],"id":6780934}],"con":true,"img":false}]}
{"op":"mcm","clk":"5348096988","pt":1646213928270,"mc":[{"id":"1.195453622","rc":[{"atl":[[2.5,0]],"id":36463352}],"con":true,"img":false}]}
{"op":"mcm","clk":"5348097000","pt":1646213928424,"mc":[{"id":"1.195453622","rc":[{"atl":[[2.52,58.12],[2.46,29.06],[2.48,0]],"id":36463352}],"con":true,"img":false}]}
{"op":"mcm","clk":"5348097012","pt":1646213928630,"mc":[{"id":"1.195453622","rc":[{"atl":[[2.52,0],[2.44,29.06]],"id":36463352}],"con":true,"img":false}]}
{"op":"mcm","clk":"5348097272","pt":1646213933041,"mc":[{"id":"1.195453622","rc":[{"atl":[[44,2.72]],"id":23806261}],"con":true,"img":false}]}
{"op":"mcm","clk":"5348097278","pt":1646213933142,"mc":[{"id":"1.195453622","rc":[{"atl":[[42,2.72]],"id":23806261}],"con":true,"img":false}]}
{"op":"mcm","clk":"5348097530","pt":1646213937333,"mc":[{"id":"1.195453622","rc":[{"atl":[[2.36,0]],"id":41308374},{"atb":[[3.35,0]],"id":6780934}],"con":true,"img":false}]}
{"op":"mcm","clk":"5348097536","pt":1646213937437,"mc":[{"id":"1.195453622","rc":[{"atl":[[2.32,31.14],[2.42,62.28],[2.34,0]],"id":41308374},{"atb":[[3.45,22.01],[3.4,0],[2.98,50.51]],"id":6780934}],"con":true,"img":false}]}
{"op":"mcm","clk":"5348097548","pt":1646213937645,"mc":[{"id":"1.195453622","rc":[{"atl":[[2.3,31.14],[2.42,0]],"id":41308374}],"con":true,"img":false}]}
{"op":"mcm","clk":"5348098033","pt":1646213944353,"mc":[{"id":"1.195453622","rc":[{"atb":[[3.45,0]],"id":6780934}],"con":true,"img":false}]}
{"op":"mcm","clk":"5348098040","pt":1646213944456,"mc":[{"id":"1.195453622","rc":[{"atb":[[3.15,22.01]],"id":6780934}],"con":true,"img":false}]}
{"op":"mcm","clk":"5348098634","pt":1646213955256,"mc":[{"id":"1.195453622","rc":[{"atb":[[4.1,32.26],[3.65,37.66]],"id":23806261},{"atb":[[4,0],[3.55,39.22]],"id":40250501},{"atb":[[4.1,51.9],[3.8,0]],"id":40199925}],"con":true,"img":false}]}
{"op":"mcm","clk":"5348098647","pt":1646213955462,"mc":[{"id":"1.195453622","rc":[{"atb":[[3.55,0],[4.2,20.44]],"id":40250501}],"con":true,"img":false}]}
{"op":"mcm","clk":"5348099037","pt":1646213961958,"mc":[{"id":"1.195453622","rc":[{"atl":[[2.46,0]],"id":36463352}],"con":true,"img":false}]}
{"op":"mcm","clk":"5348099045","pt":1646213962061,"mc":[{"id":"1.195453622","rc":[{"atl":[[2.42,29.06],[2.52,58.12],[2.44,0]],"id":36463352}],"con":true,"img":false}]}
{"op":"mcm","clk":"5348099304","pt":1646213966906,"mc":[{"id":"1.195453622","rc":[{"atl":[[42,0]],"id":23806261}],"con":true,"img":false}]}
{"op":"mcm","clk":"5348099312","pt":1646213967008,"mc":[{"id":"1.195453622","rc":[{"atl":[[40,2.72]],"id":23806261}],"con":true,"img":false}]}
{"op":"mcm","clk":"5348099339","pt":1646213967371,"mc":[{"id":"1.195453622","rc":[{"atb":[[3.2,29.82],[2.98,0]],"id":6780934}],"con":true,"img":false}]}
{"op":"mcm","clk":"5348099552","pt":1646213970984,"mc":[{"id":"1.195453622","rc":[{"atl":[[2.32,0]],"id":41308374}],"con":true,"img":false}]}
{"op":"mcm","clk":"5348099559","pt":1646213971089,"mc":[{"id":"1.195453622","rc":[{"atl":[[2.4,62.28],[2.3,0],[2.28,31.14]],"id":41308374}],"con":true,"img":false}]}
{"op":"mcm","clk":"5348099564","pt":1646213971191,"mc":[{"id":"1.195453622","rc":[{"atl":[[2.4,0],[2.26,31.14]],"id":41308374}],"con":true,"img":false}]}
{"op":"mcm","clk":"5348100087","pt":1646213981115,"mc":[{"id":"1.195453622","rc":[{"spn":7.35,"spf":"NaN","id":40250501},{"atl":[[2.42,0]],"id":36463352},{"spn":1.76,"spf":"NaN","id":41308374},{"spn":5.6,"spf":"NaN","id":6780934}],"con":true,"img":false}]}
{"op":"mcm","clk":"5348100094","pt":1646213981223,"mc":[{"id":"1.195453622","rc":[{"atl":[[2.5,29.06]],"id":36463352}],"con":true,"img":false}]}
{"op":"mcm","clk":"5348100637","pt":1646213989860,"mc":[{"id":"1.195453622","rc":[{"atb":[[4.1,0]],"id":40250501}],"con":true,"img":false}]}
{"op":"mcm","clk":"5348100644","pt":1646213989965,"mc":[{"id":"1.195453622","rc":[{"atb":[[4.3,14.78]],"id":40250501}],"con":true,"img":false}]}
{"op":"mcm","clk":"5348100648","pt":1646213990022,"mc":[{"id":"1.195453622","rc":[{"atb":[[4.2,0],[3.75,36.36]],"id":40250501}],"con":true,"img":false}]}
{"op":"mcm","clk":"5348100757","pt":1646213991734,"mc":[{"id":"1.195453622","rc":[{"atl":[[2.48,29.06]],"id":36463352}],"con":true,"img":false}]}
{"op":"mcm","clk":"5348100764","pt":1646213991835,"mc":[{"id":"1.195453622","rc":[{"atl":[[2.52,0]],"id":36463352}],"con":true,"img":false}]}
{"op":"mcm","clk":"5348100845","pt":1646213993437,"mc":[{"id":"1.195453622","rc":[{"atl":[[17,0]],"id":6780934}],"con":true,"img":false}]}
{"op":"mcm","clk":"5348100851","pt":1646213993546,"mc":[{"id":"1.195453622","rc":[{"atl":[[14.5,7.26]],"id":6780934}],"con":true,"img":false}]}
{"op":"mcm","clk":"5348101338","pt":1646214001592,"mc":[{"id":"1.195453622","rc":[{"atb":[[4.3,0]],"id":40250501},{"atb":[[3.15,0]],"id":6780934}],"con":true,"img":false}]}
{"op":"mcm","clk":"5348101347","pt":1646214001655,"mc":[{"id":"1.195453622","rc":[{"atb":[[3.95,14.78]],"id":40250501},{"atb":[[3.25,22.01]],"id":6780934}],"con":true,"img":false}]}
{"op":"mcm","clk":"5348101353","pt":1646214001755,"mc":[{"id":"1.195453622","rc":[{"atb":[[3.2,0],[2.98,50.51]],"id":6780934}],"con":true,"img":false}]}
{"op":"mcm","clk":"5348101363","pt":1646214001855,"mc":[{"id":"1.195453622","rc":[{"atb":[[2.98,0],[3.3,29.82]],"id":6780934}],"con":true,"img":false}]}
{"op":"mcm","clk":"5348101885","pt":1646214009570,"mc":[{"id":"1.195453622","rc":[{"atl":[[2.28,0]],"id":41308374}],"con":true,"img":false}]}
{"op":"mcm","clk":"5348101896","pt":1646214009676,"mc":[{"id":"1.195453622","rc":[{"atl":[[2.24,31.14]],"id":41308374}],"con":true,"img":false}]}
{"op":"mcm","clk":"5348101906","pt":1646214009779,"mc":[{"id":"1.195453622","rc":[{"atl":[[2.4,62.28],[2.26,0]],"id":41308374}],"con":true,"img":false}]}
{"op":"mcm","clk":"5348102514","pt":1646214019481,"mc":[{"id":"1.195453622","rc":[{"atb":[[4,20.44],[3.75,0]],"id":40250501}],"con":true,"img":false}]}
{"op":"mcm","clk":"5348102662","pt":1646214022016,"mc":[{"id":"1.195453622","rc":[{"atl":[[2.5,0]],"id":36463352},{"atl":[[2.24,0]],"id":41308374}],"con":true,"img":false}]}
{"op":"mcm","clk":"5348102666","pt":1646214022112,"mc":[{"id":"1.195453622","rc":[{"atl":[[2.46,29.06]],"id":36463352},{"atl":[[2.38,31.14]],"id":41308374}],"con":true,"img":false}]}
{"op":"mcm","clk":"5348102675","pt":1646214022165,"mc":[{"id":"1.195453622","rc":[{"atl":[[2.52,58.12],[2.48,0]],"id":36463352}],"con":true,"img":false}]}
{"op":"mcm","clk":"5348103269","pt":1646214033116,"mc":[{"id":"1.195453622","rc":[{"atl":[[2.46,0]],"id":36463352}],"con":true,"img":false}]}
{"op":"mcm","clk":"5348103275","pt":1646214033217,"mc":[{"id":"1.195453622","rc":[{"atl":[[2.5,29.06]],"id":36463352}],"con":true,"img":false}]}
{"op":"mcm","clk":"5348103578","pt":1646214038641,"mc":[{"id":"1.195453622","rc":[{"atb":[[3.25,0]],"id":6780934}],"con":true,"img":false}]}
{"op":"mcm","clk":"5348103583","pt":1646214038691,"mc":[{"id":"1.195453622","rc":[{"atb":[[3.35,22.01]],"id":6780934}],"con":true,"img":false}]}
{"op":"mcm","clk":"5348103588","pt":1646214038799,"mc":[{"id":"1.195453622","rc":[{"atb":[[2.98,50.51],[3.3,0]],"id":6780934}],"con":true,"img":false}]}
{"op":"mcm","clk":"5348103593","pt":1646214038903,"mc":[{"id":"1.195453622","rc":[{"atb":[[3.4,29.82],[2.98,0]],"id":6780934}],"con":true,"img":false}]}
{"op":"mcm","clk":"5348103597","pt":1646214039007,"mc":[{"id":"1.195453622","rc":[{"atl":[[2.4,0],[2.36,31.14]],"id":41308374}],"con":true,"img":false}]}
{"op":"mcm","clk":"5348104152","pt":1646214048052,"mc":[{"id":"1.195453622","rc":[{"spn":7.25,"spf":"NaN","id":40250501},{"spn":1.81,"spf":"NaN","id":41308374},{"atl":[[14.5,3.23]],"id":6780934},{"spn":5.7,"spf":"NaN","id":6780934}],"con":true,"img":false}]}
{"op":"mcm","clk":"5348104158","pt":1646214048108,"mc":[{"id":"1.195453622","rc":[{"atl":[[17,4.03]],"id":6780934}],"con":true,"img":false}]}
{"op":"mcm","clk":"5348104339","pt":1646214051355,"mc":[{"id":"1.195453622","rc":[{"atl":[[2.52,0],[2.48,29.06]],"id":36463352}],"con":true,"img":false}]}
{"op":"mcm","clk":"5348104387","pt":1646214052131,"mc":[{"id":"1.195453622","rc":[{"atb":[[3.95,0]],"id":40250501}],"con":true,"img":false}]}
{"op":"mcm","clk":"5348104393","pt":1646214052229,"mc":[{"id":"1.195453622","rc":[{"atb":[[4,0],[4.1,14.78],[3.75,36.36]],"id":40250501}],"con":true,"img":false}]}
{"op":"mcm","clk":"5348105596","pt":1646214073177,"mc":[{"id":"1.195453622","rc":[{"atl":[[2.38,0]],"id":41308374},{"atb":[[3.35,0]],"id":6780934}],"con":true,"img":false}]}
{"op":"mcm","clk":"5348105602","pt":1646214073280,"mc":[{"id":"1.195453622","rc":[{"atl":[[2.34,31.14]],"id":41308374},{"atb":[[3.45,22.01]],"id":6780934}],"con":true,"img":false}]}
{"op":"mcm","clk":"5348105604","pt":1646214073382,"mc":[{"id":"1.195453622","rc":[{"atl":[[2.36,0],[2.4,62.28]],"id":41308374},{"atb":[[3.4,0],[2.98,50.51]],"id":6780934}],"con":true,"img":false}]}
{"op":"mcm","clk":"5348105706","pt":1646214075193,"mc":[{"id":"1.195453622","rc":[{"atb":[[4.1,19.64],[4.2,31.25]],"id":40199925}],"con":true,"img":false}]}
{"op":"mcm","clk":"5348105802","pt":1646214076692,"mc":[{"id":"1.195453622","rc":[{"atb":[[3.45,0]],"id":6780934}],"con":true,"img":false}]}
{"op":"mcm","clk":"5348105811","pt":1646214076797,"mc":[{"id":"1.195453622","rc":[{"atb":[[3.2,22.01]],"id":6780934}],"con":true,"img":false}]}
{"op":"mcm","clk":"5348106223","pt":1646214080312,"mc":[{"id":"1.195453622","rc":[{"atl":[[2.5,0]],"id":36463352}],"con":true,"img":false}]}
{"op":"mcm","clk":"5348106227","pt":1646214080370,"mc":[{"id":"1.195453622","rc":[{"atl":[[2.46,29.06]],"id":36463352}],"con":true,"img":false}]}
{"op":"mcm","clk":"5348106231","pt":1646214080471,"mc":[{"id":"1.195453622","rc":[{"atl":[[2.52,58.12],[2.48,0]],"id":36463352}],"con":true,"img":false}]}
{"op":"mcm","clk":"5348106237","pt":1646214080578,"mc":[{"id":"1.195453622","rc":[{"atl":[[2.44,29.06]],"id":36463352}],"con":true,"img":false}]}
{"op":"mcm","clk":"5348106243","pt":1646214080680,"mc":[{"id":"1.195453622","rc":[{"atl":[[2.52,0]],"id":36463352}],"con":true,"img":false}]}
{"op":"mcm","clk":"5348106292","pt":1646214081098,"mc":[{"id":"1.195453622","rc":[{"atb":[[4.2,20.44],[3.75,0]],"id":40250501}],"con":true,"img":false}]}
{"op":"mcm","clk":"5348106460","pt":1646214083792,"mc":[{"id":"1.195453622","rc":[{"atl":[[2.34,0]],"id":41308374}],"con":true,"img":false}]}
{"op":"mcm","clk":"5348106466","pt":1646214083891,"mc":[{"id":"1.195453622","rc":[{"atl":[[2.38,31.14]],"id":41308374}],"con":true,"img":false}]}
{"op":"mcm","clk":"5348106976","pt":1646214093235,"mc":[{"id":"1.195453622","rc":[{"atb":[[2.92,52.08],[4.1,0]],"id":23806261},{"atb":[[3.15,46.51],[4.2,0]],"id":40199925}],"con":true,"img":false}]}
{"op":"mcm","clk":"5348106989","pt":1646214093437,"mc":[{"id":"1.195453622","rc":[{"atb":[[4,33.33],[2.92,0]],"id":23806261}],"con":true,"img":false}]}
{"op":"mcm","clk":"5348107472","pt":1646214102047,"mc":[{"id":"1.195453622","rc":[{"atl":[[2.4,0],[2.36,31.14]],"id":41308374},{"atb":[[2.98,0],[3.25,29.82]],"id":6780934}],"con":true,"img":false}]}
{"op":"mcm","clk":"5348107567","pt":1646214103711,"mc":[{"id":"1.195453622","rc":[{"atb":[[4,66.6],[3.15,0]],"id":40199925}],"con":true,"img":false}]}
{"op":"mcm","clk":"5348107999","pt":1646214112852,"mc":[{"id":"1.195453622","rc":[{"spn":7.35,"spf":"NaN","id":40250501},{"atl":[[2.46,0]],"id":36463352},{"atl":[[17,0]],"id":6780934},{"spn":5.62,"spf":"NaN","id":6780934}],"con":true,"img":false}]}
{"op":"mcm","clk":"5348108003","pt":1646214112954,"mc":[{"id":"1.195453622","rc":[{"atl":[[2.42,29.06]],"id":36463352},{"atl":[[14.5,7.26]],"id":6780934}],"con":true,"img":false}]}
{"op":"mcm","clk":"5348108010","pt":1646214113056,"mc":[{"id":"1.195453622","rc":[{"atl":[[2.52,58.12],[2.44,0]],"id":36463352}],"con":true,"img":false}]}
{"op":"mcm","clk":"5348108016","pt":1646214113161,"mc":[{"id":"1.195453622","rc":[{"atl":[[2.4,29.06],[2.52,0]],"id":36463352}],"con":true,"img":false}]}
{"op":"mcm","clk":"5348108195","pt":1646214117359,"mc":[{"id":"1.195453622","rc":[{"atb":[[4.1,0]],"id":40250501}],"con":true,"img":false}]}
{"op":"mcm","clk":"5348108201","pt":1646214117464,"mc":[{"id":"1.195453622","rc":[{"atb":[[4.3,14.78]],"id":40250501}],"con":true,"img":false}]}
{"op":"mcm","clk":"5348108210","pt":1646214117570,"mc":[{"id":"1.195453622","rc":[{"atb":[[4.2,0],[3.75,36.36]],"id":40250501}],"con":true,"img":false}]}
{"op":"mcm","clk":"5348108894","pt":1646214129064,"mc":[{"id":"1.195453622","rc":[{"atb":[[4.3,0]],"id":40250501}],"con":true,"img":false}]}
{"op":"mcm","clk":"5348108899","pt":1646214129163,"mc":[{"id":"1.195453622","rc":[{"atb":[[3.9,14.78]],"id":40250501}],"con":true,"img":false}]}
{"op":"mcm","clk":"5348109196","pt":1646214133413,"mc":[{"id":"1.195453622","rc":[{"atl":[[2.38,0]],"id":41308374}],"con":true,"img":false}]}
{"op":"mcm","clk":"5348109202","pt":1646214133470,"mc":[{"id":"1.195453622","rc":[{"atl":[[2.34,31.14]],"id":41308374}],"con":true,"img":false}]}
{"op":"mcm","clk":"5348109207","pt":1646214133571,"mc":[{"id":"1.195453622","rc":[{"atl":[[2.36,0],[2.4,62.28]],"id":41308374}],"con":true,"img":false}]}
{"op":"mcm","clk":"5348109212","pt":1646214133675,"mc":[{"id":"1.195453622","rc":[{"atl":[[2.4,0],[2.32,31.14]],"id":41308374}],"con":true,"img":false}]}
{"op":"mcm","clk":"5348109247","pt":1646214134293,"mc":[{"id":"1.195453622","rc":[{"atb":[[5.3,1.66]],"id":23806261},{"atb":[[3.95,1.66]],"id":40250501},{"atb":[[4.7,1.66]],"id":40199925},{"atb":[[2.98,1.66]],"id":40846831},{"atb":[[3.3,1.66]],"id":6780934}],"con":true,"img":false}]}
{"op":"mcm","clk":"5348109515","pt":1646214138689,"mc":[{"id":"1.195453622","rc":[{"atl":[[40,0]],"id":23806261},{"atb":[[3.2,0]],"id":6780934}],"con":true,"img":false}]}
{"op":"mcm","clk":"5348109519","pt":1646214138794,"mc":[{"id":"1.195453622","rc":[{"atl":[[38,2.72]],"id":23806261},{"atb":[[3.3,23.68]],"id":6780934}],"con":true,"img":false}]}
{"op":"mcm","clk":"5348109528","pt":1646214139001,"mc":[{"id":"1.195453622","rc":[{"atb":[[3.35,29.82],[3.25,0]],"id":6780934}],"con":true,"img":false}]}
{"op":"mcm","clk":"5348109687","pt":1646214142312,"mc":[{"id":"1.195453622","rc":[{"atb":[[3.3,22.01]],"id":6780934}],"con":true,"img":false}]}
{"op":"mcm","clk":"5348109694","pt":1646214142519,"mc":[{"id":"1.195453622","rc":[{"atb":[[3.4,1.66]],"id":6780934}],"con":true,"img":false}]}
{"op":"mcm","clk":"5348109870","pt":1646214145682,"mc":[{"id":"1.195453622","rc":[{"atb":[[3.75,0]],"id":40250501}],"con":true,"img":false}]}
{"op":"mcm","clk":"5348109875","pt":1646214145784,"mc":[{"id":"1.195453622","rc":[{"atb":[[3.95,16.44]],"id":40250501}],"con":true,"img":false}]}
{"op":"mcm","clk":"5348109892","pt":1646214146192,"mc":[{"id":"1.195453622","rc":[{"atl":[[2.42,0]],"id":36463352}],"con":true,"img":false}]}
{"op":"mcm","clk":"5348109896","pt":1646214146296,"mc":[{"id":"1.195453622","rc":[{"atl":[[2.4,0],[2.38,29.06],[2.52,58.12]],"id":36463352}],"con":true,"img":false}]}
{"op":"mcm","clk":"5348110224","pt":1646214152065,"mc":[{"id":"1.195453622","marketDefinition":{"bspMarket":true,"turnInPlayEnabled":false,"persistenceEnabled":false,"marketBaseRate":7.0,"eventId":"31272494","eventTypeId":"4339","numberOfWinners":2,"bettingType":"ODDS","marketType":"PLACE","marketTime":"2022-03-02T10:27:00.000Z","suspendTime":"2022-03-02T10:27:00.000Z","bspReconciled":false,"complete":true,"inPlay":false,"crossMatching":true,"runnersVoidable":false,"numberOfActiveRunners":7,"betDelay":0,"status":"OPEN","runners":[{"status":"ACTIVE","sortPriority":1,"id":40250501,"name":"1. Dwarshuis"},{"status":"ACTIVE","sortPriority":2,"id":6780934,"name":"2. Peacock"},{"status":"ACTIVE","sortPriority":3,"id":40846831,"name":"3. Rapid Voyage"},{"status":"ACTIVE","sortPriority":4,"id":23806261,"name":"4. Impending"},{"status":"ACTIVE","sortPriority":5,"id":40199925,"name":"6. Parzival"},{"status":"ACTIVE","sortPriority":6,"id":41308374,"name":"7. Gotham Baroness"},{"status":"ACTIVE","sortPriority":7,"id":36463352,"name":"8. Massimo"}],"regulators":["MR_INT"],"venue":"Traralgon","countryCode":"AU","discountAllowed":true,"timezone":"Australia/Sydney","openDate":"2022-03-02T08:31:00.000Z","version":4382425395,"name":"To Be Placed","eventName":"Traralgon (AUS) 2nd Mar"},"rc":[],"con":true,"img":false}]}
{"op":"mcm","clk":"5348110578","pt":1646214159024,"mc":[{"id":"1.195453622","rc":[{"atl":[[2.38,0]],"id":36463352}],"con":true,"img":false}]}
{"op":"mcm","clk":"5348110581","pt":1646214159126,"mc":[{"id":"1.195453622","rc":[{"atl":[[2.5,29.06]],"id":36463352}],"con":true,"img":false}]}
{"op":"mcm","clk":"5348110888","pt":1646214164517,"mc":[{"id":"1.195453622","rc":[{"atb":[[3.8,2.68]],"id":40250501},{"atb":[[1.34,22.11]],"id":36463352},{"atb":[[1.29,25.92]],"id":41308374},{"atb":[[3,3.75]],"id":40846831},{"atb":[[3.45,3.06]],"id":6780934}],"con":true,"img":false}]}
{"op":"mcm","clk":"5348110896","pt":1646214164621,"mc":[{"id":"1.195453622","rc":[{"atb":[[3.5,3.07]],"id":6780934}],"con":true,"img":false}]}
{"op":"mcm","clk":"5348110905","pt":1646214164726,"mc":[{"id":"1.195453622","rc":[{"atb":[[3.35,0]],"id":6780934}],"con":true,"img":false}]}
{"op":"mcm","clk":"5348110995","pt":1646214166227,"mc":[{"id":"1.195453622","rc":[{"atl":[[2.34,0]],"id":41308374}],"con":true,"img":false}]}
{"op":"mcm","clk":"5348111002","pt":1646214166331,"mc":[{"id":"1.195453622","rc":[{"atl":[[2.4,62.28],[2.32,0],[2.3,31.14]],"id":41308374}],"con":true,"img":false}]}
{"op":"mcm","clk":"5348111007","pt":1646214166434,"mc":[{"id":"1.195453622","rc":[{"atl":[[2.4,0],[2.28,31.14]],"id":41308374}],"con":true,"img":false}]}
{"op":"mcm","clk":"5348111013","pt":1646214166537,"mc":[{"id":"1.195453622","rc":[{"atb":[[2.98,0]],"id":40846831},{"atb":[[3.4,0]],"id":6780934}],"con":true,"img":false}]}
{"op":"mcm","clk":"5348111020","pt":1646214166744,"mc":[{"id":"1.195453622","rc":[{"atb":[[3.05,1.66]],"id":40846831},{"atb":[[3.45,0],[3.55,1.66]],"id":6780934}],"con":true,"img":false}]}
{"op":"mcm","clk":"5348111334","pt":1646214172437,"mc":[{"id":"1.195453622","rc":[{"atb":[[3.4,3.13]],"id":6780934}],"con":true,"img":false}]}
{"op":"mcm","clk":"5348111435","pt":1646214174159,"mc":[{"id":"1.195453622","rc":[{"spn":10.4,"spf":"NaN","id":23806261},{"spn":7.22,"spf":"NaN","id":40250501},{"atl":[[2.52,0],[2.48,29.06]],"id":36463352},{"spn":1.34,"spf":1.0,"id":36463352},{"spn":1.78,"spf":"NaN","id":41308374},{"spn":5.52,"spf":"NaN","id":40846831},{"spn":10.35,"spf":"NaN","id":40199925},{"spn":5.77,"spf":"NaN","id":6780934}],"con":true,"img":false}]}
{"op":"mcm","clk":"5348112737","pt":1646214195793,"mc":[{"id":"1.195453622","rc":[{"atb":[[3.9,0]],"id":40250501}],"con":true,"img":false}]}
{"op":"mcm","clk":"5348112745","pt":1646214195881,"mc":[{"id":"1.195453622","rc":[{"atb":[[4,14.78]],"id":40250501}],"con":true,"img":false}]}
{"op":"mcm","clk":"5348112754","pt":1646214195986,"mc":[{"id":"1.195453622","rc":[{"atb":[[4.1,14.78]],"id":40250501}],"con":true,"img":false}]}
{"op":"mcm","clk":"5348112759","pt":1646214196087,"mc":[{"id":"1.195453622","rc":[{"atb":[[3.95,1.66]],"id":40250501}],"con":true,"img":false}]}
{"op":"mcm","clk":"5348112909","pt":1646214198590,"mc":[{"id":"1.195453622","rc":[{"atb":[[3.95,0]],"id":40250501}],"con":true,"img":false}]}
{"op":"mcm","clk":"5348112924","pt":1646214198798,"mc":[{"id":"1.195453622","rc":[{"atb":[[4.2,1.66]],"id":40250501}],"con":true,"img":false}]}
{"op":"mcm","clk":"5348113084","pt":1646214201391,"mc":[{"id":"1.195453622","rc":[{"atl":[[2.3,0]],"id":41308374}],"con":true,"img":false}]}
{"op":"mcm","clk":"5348113093","pt":1646214201493,"mc":[{"id":"1.195453622","rc":[{"atl":[[2.4,62.28],[2.26,31.14]],"id":41308374}],"con":true,"img":false}]}
{"op":"mcm","clk":"5348113099","pt":1646214201598,"mc":[{"id":"1.195453622","rc":[{"atl":[[2.24,31.14],[2.28,0]],"id":41308374}],"con":true,"img":false}]}
{"op":"mcm","clk":"5348113106","pt":1646214201702,"mc":[{"id":"1.195453622","rc":[{"atl":[[2.4,0]],"id":41308374}],"con":true,"img":false}]}
{"op":"mcm","clk":"5348113557","pt":1646214208820,"mc":[{"id":"1.195453622","rc":[{"atl":[[2.5,0]],"id":36463352}],"con":true,"img":false}]}
{"op":"mcm","clk":"5348113565","pt":1646214208921,"mc":[{"id":"1.195453622","rc":[{"atl":[[2.46,29.06]],"id":36463352}],"con":true,"img":false}]}
{"op":"mcm","clk":"5348113570","pt":1646214209024,"mc":[{"id":"1.195453622","rc":[{"atl":[[2.52,58.12],[2.48,0]],"id":36463352}],"con":true,"img":false}]}
{"op":"mcm","clk":"5348113575","pt":1646214209128,"mc":[{"id":"1.195453622","rc":[{"atl":[[2.52,0],[2.44,29.06]],"id":36463352}],"con":true,"img":false}]}
{"op":"mcm","clk":"5348113867","pt":1646214213316,"mc":[{"id":"1.195453622","rc":[{"atb":[[4,31.23],[4.1,0]],"id":40250501}],"con":true,"img":false}]}
{"op":"mcm","clk":"5348113912","pt":1646214214139,"mc":[{"id":"1.195453622","rc":[{"atl":[[38,0]],"id":23806261}],"con":true,"img":false}]}
{"op":"mcm","clk":"5348113939","pt":1646214214240,"mc":[{"id":"1.195453622","rc":[{"atl":[[36,2.72]],"id":23806261}],"con":true,"img":false}]}
{"op":"mcm","clk":"5348113965","pt":1646214214605,"mc":[{"id":"1.195453622","rc":[{"atb":[[4.2,0]],"id":40250501}],"con":true,"img":false}]}
{"op":"mcm","clk":"5348113974","pt":1646214214707,"mc":[{"id":"1.195453622","rc":[{"atb":[[3.8,0]],"id":40250501}],"con":true,"img":false}]}
{"op":"mcm","clk":"5348113982","pt":1646214214810,"mc":[{"id":"1.195453622","rc":[{"atb":[[4.1,1.66]],"id":40250501}],"con":true,"img":false}]}
{"op":"mcm","clk":"5348114995","pt":1646214231460,"mc":[{"id":"1.195453622","rc":[{"atl":[[36,0]],"id":23806261}],"con":true,"img":false}]}
{"op":"mcm","clk":"5348115000","pt":1646214231563,"mc":[{"id":"1.195453622","rc":[{"atl":[[42,2.72]],"id":23806261}],"con":true,"img":false}]}
{"op":"mcm","clk":"5348115188","pt":1646214234977,"mc":[{"id":"1.195453622","rc":[{"spn":7.3,"spf":"NaN","id":40250501},{"atl":[[2.26,0]],"id":41308374},{"spn":1.76,"spf":"NaN","id":41308374}],"con":true,"img":false}]}
{"op":"mcm","clk":"5348115194","pt":1646214235080,"mc":[{"id":"1.195453622","rc":[{"atl":[[2.22,31.14]],"id":41308374}],"con":true,"img":false}]}
{"op":"mcm","clk":"5348115201","pt":1646214235183,"mc":[{"id":"1.195453622","rc":[{"atl":[[2.24,0],[2.42,62.28]],"id":41308374}],"con":true,"img":false}]}
{"op":"mcm","clk":"5348115683","pt":1646214242789,"mc":[{"id":"1.195453622","rc":[{"atl":[[2.46,0]],"id":36463352}],"con":true,"img":false}]}
{"op":"mcm","clk":"5348115686","pt":1646214242892,"mc":[{"id":"1.195453622","rc":[{"atl":[[2.42,29.06]],"id":36463352}],"con":true,"img":false}]}
{"op":"mcm","clk":"5348115695","pt":1646214242995,"mc":[{"id":"1.195453622","rc":[{"atl":[[2.52,58.12],[2.44,0]],"id":36463352}],"con":true,"img":false}]}
{"op":"mcm","clk":"5348116170","pt":1646214250603,"mc":[{"id":"1.195453622","rc":[{"atl":[[2.22,0]],"id":41308374}],"con":true,"img":false}]}
{"op":"mcm","clk":"5348116176","pt":1646214250708,"mc":[{"id":"1.195453622","rc":[{"atl":[[2.4,31.14]],"id":41308374}],"con":true,"img":false}]}
{"op":"mcm","clk":"5348116361","pt":1646214253907,"mc":[{"id":"1.195453622","rc":[{"atl":[[2.42,0]],"id":36463352}],"con":true,"img":false}]}
{"op":"mcm","clk":"5348116363","pt":1646214254011,"mc":[{"id":"1.195453622","rc":[{"atl":[[2.5,29.06]],"id":36463352}],"con":true,"img":false}]}
{"op":"mcm","clk":"5348116449","pt":1646214255416,"mc":[{"id":"1.195453622","rc":[{"atb":[[3.8,35.71]],"id":40199925}],"con":true,"img":false}]}
{"op":"mcm","clk":"5348116452","pt":1646214255509,"mc":[{"id":"1.195453622","rc":[{"atb":[[4,33.27]],"id":40199925}],"con":true,"img":false}]}
{"op":"mcm","clk":"5348116855","pt":1646214262133,"mc":[{"id":"1.195453622","rc":[{"atl":[[2.42,0],[2.38,31.14]],"id":41308374}],"con":true,"img":false}]}
{"op":"mcm","clk":"5348117380","pt":1646214269922,"mc":[{"id":"1.195453622","rc":[{"atl":[[2.52,0],[2.48,29.06]],"id":36463352}],"con":true,"img":false}]}
{"op":"mcm","clk":"5348117667","pt":1646214274356,"mc":[{"id":"1.195453622","rc":[{"atb":[[3.3,0]],"id":6780934}],"con":true,"img":false}]}
{"op":"mcm","clk":"5348117672","pt":1646214274457,"mc":[{"id":"1.195453622","rc":[{"atb":[[3.15,22.01]],"id":6780934}],"con":true,"img":false}]}
{"op":"mcm","clk":"5348117757","pt":1646214275649,"mc":[{"id":"1.195453622","rc":[{"atb":[[3.4,0]],"id":6780934}],"con":true,"img":false}]}
{"op":"mcm","clk":"5348118244","pt":1646214282266,"mc":[{"id":"1.195453622","rc":[{"atb":[[3.8,0],[3.9,34.48]],"id":40199925}],"con":true,"img":false}]}
{"op":"mcm","clk":"5348118350","pt":1646214283798,"mc":[{"id":"1.195453622","rc":[{"atb":[[3.05,3.66]],"id":6780934}],"con":true,"img":false}]}
{"op":"mcm","clk":"5348118940","pt":1646214292504,"mc":[{"id":"1.195453622","rc":[{"atl":[[2.4,0]],"id":41308374}],"con":true,"img":false}]}
{"op":"mcm","clk":"5348118946","pt":1646214292567,"mc":[{"id":"1.195453622","rc":[{"atl":[[2.36,31.14]],"id":41308374}],"con":true,"img":false}]}
{"op":"mcm","clk":"5348118952","pt":1646214292668,"mc":[{"id":"1.195453622","rc":[{"atl":[[2.4,62.28],[2.38,0]],"id":41308374}],"con":true,"img":false}]}
{"op":"mcm","clk":"5348119596","pt":1646214303115,"mc":[{"id":"1.195453622","rc":[{"atl":[[2.5,0]],"id":36463352},{"atl":[[2.36,0]],"id":41308374},{"spn":1.84,"spf":"NaN","id":41308374}],"con":true,"img":false}]}
{"op":"mcm","clk":"5348119602","pt":1646214303215,"mc":[{"id":"1.195453622","rc":[{"atl":[[2.46,29.06]],"id":36463352},{"atl":[[2.38,31.14]],"id":41308374}],"con":true,"img":false}]}
{"op":"mcm","clk":"5348119611","pt":1646214303330,"mc":[{"id":"1.195453622","rc":[{"atl":[[2.52,58.12],[2.48,0]],"id":36463352}],"con":true,"img":false}]}
{"op":"mcm","clk":"5348119627","pt":1646214303517,"mc":[{"id":"1.195453622","rc":[{"atl":[[2.44,29.06]],"id":36463352}],"con":true,"img":false}]}
{"op":"mcm","clk":"5348119636","pt":1646214303623,"mc":[{"id":"1.195453622","rc":[{"atl":[[2.52,0]],"id":36463352}],"con":true,"img":false}]}
{"op":"mcm","clk":"5348119708","pt":1646214304512,"mc":[{"id":"1.195453622","rc":[{"atb":[[4,66.6],[3.9,0]],"id":40199925}],"con":true,"img":false}]}
{"op":"mcm","clk":"5348120784","pt":1646214319145,"mc":[{"id":"1.195453622","rc":[{"atl":[[2.4,0],[2.36,31.14]],"id":41308374}],"con":true,"img":false}]}
{"op":"mcm","clk":"5348123556","pt":1646214358786,"mc":[{"id":"1.195453622","rc":[{"atl":[[42,0]],"id":23806261},{"atl":[[2.46,0]],"id":36463352},{"atl":[[2.38,0]],"id":41308374}],"con":true,"img":false}]}
{"op":"mcm","clk":"5348123562","pt":1646214358888,"mc":[{"id":"1.195453622","rc":[{"atl":[[40,2.72]],"id":23806261},{"atl":[[2.42,29.06]],"id":36463352},{"atl":[[2.34,31.14]],"id":41308374}],"con":true,"img":false}]}
{"op":"mcm","clk":"5348123568","pt":1646214358991,"mc":[{"id":"1.195453622","rc":[{"atl":[[2.52,58.12],[2.44,0]],"id":36463352},{"atl":[[2.36,0],[2.4,62.28]],"id":41308374}],"con":true,"img":false}]}
{"op":"mcm","clk":"5348125074","pt":1646214380854,"mc":[{"id":"1.195453622","rc":[{"atl":[[2.42,0]],"id":36463352},{"atl":[[2.34,0]],"id":41308374}],"con":true,"img":false}]}
{"op":"mcm","clk":"5348125078","pt":1646214380954,"mc":[{"id":"1.195453622","rc":[{"atl":[[2.5,29.06]],"id":36463352},{"atl":[[2.38,31.14]],"id":41308374}],"con":true,"img":false}]}
{"op":"mcm","clk":"5348125084","pt":1646214381057,"mc":[{"id":"1.195453622","rc":[{"atl":[[2.4,0],[2.42,70.42]],"id":41308374}],"con":true,"img":false}]}
{"op":"mcm","clk":"5348125347","pt":1646214384729,"mc":[{"id":"1.195453622","rc":[{"atl":[[2.52,0],[2.48,29.06]],"id":36463352},{"atl":[[2.36,31.14],[2.42,0]],"id":41308374}],"con":true,"img":false}]}
{"op":"mcm","clk":"5348125531","pt":1646214387667,"mc":[{"id":"1.195453622","rc":[{"atb":[[4,0],[3.7,37.04]],"id":23806261},{"atb":[[4,14.78],[3.85,35.09]],"id":40250501},{"atb":[[4,33.27],[3.65,37.74]],"id":40199925}],"con":true,"img":false}]}
{"op":"mcm","clk":"5348126127","pt":1646214397485,"mc":[{"id":"1.195453622","rc":[{"atl":[[2.38,0]],"id":41308374}],"con":true,"img":false}]}
{"op":"mcm","clk":"5348126133","pt":1646214397584,"mc":[{"id":"1.195453622","rc":[{"atl":[[2.4,31.14]],"id":41308374}],"con":true,"img":false}]}
{"op":"mcm","clk":"5348126140","pt":1646214397685,"mc":[{"id":"1.195453622","rc":[{"atl":[[2.36,0],[2.42,62.28]],"id":41308374}],"con":true,"img":false}]}
{"op":"mcm","clk":"5348136324","pt":1646214420130,"mc":[{"id":"1.195453622","rc":[{"atb":[[3.05,7.73]],"id":6780934}],"con":true,"img":false}]}
{"op":"mcm","clk":"5348136332","pt":1646214420224,"mc":[{"id":"1.195453622","rc":[{"atb":[[3,7.92]],"id":40846831}],"con":true,"img":false}]}
{"op":"mcm","clk":"5348136349","pt":1646214420430,"mc":[{"id":"1.195453622","rc":[{"atb":[[1.29,54.66]],"id":41308374}],"con":true,"img":false}]}
{"op":"mcm","clk":"5348136358","pt":1646214420532,"mc":[{"id":"1.195453622","rc":[{"atb":[[1.34,46.62]],"id":36463352}],"con":true,"img":false}]}
{"op":"mcm","clk":"5348136535","pt":1646214423024,"mc":[{"id":"1.195453622","rc":[{"atl":[[2.38,31.14]],"id":41308374}],"con":true,"img":false}]}
{"op":"mcm","clk":"5348136541","pt":1646214423128,"mc":[{"id":"1.195453622","rc":[{"atl":[[2.42,0]],"id":41308374}],"con":true,"img":false}]}
{"op":"mcm","clk":"5348136919","pt":1646214429018,"mc":[{"id":"1.195453622","rc":[{"atl":[[2.5,0]],"id":36463352}],"con":true,"img":false}]}
{"op":"mcm","clk":"5348136924","pt":1646214429121,"mc":[{"id":"1.195453622","rc":[{"atl":[[2.46,29.06]],"id":36463352}],"con":true,"img":false}]}
{"op":"mcm","clk":"5348136930","pt":1646214429232,"mc":[{"id":"1.195453622","rc":[{"atl":[[2.52,58.12],[2.48,0]],"id":36463352}],"con":true,"img":false}]}
{"op":"mcm","clk":"5348137382","pt":1646214435531,"mc":[{"id":"1.195453622","rc":[{"atb":[[3.95,33.9],[3.7,0]],"id":23806261},{"atb":[[3.85,0],[4.1,16.44]],"id":40250501},{"atb":[[3.8,35.71],[3.65,0]],"id":40199925}],"con":true,"img":false}]}
{"op":"mcm","clk":"5348137910","pt":1646214443477,"mc":[{"id":"1.195453622","rc":[{"atb":[[3.8,2.68]],"id":40250501},{"spn":1.83,"spf":"NaN","id":41308374}],"con":true,"img":false}]}
{"op":"mcm","clk":"5348138019","pt":1646214445028,"mc":[{"id":"1.195453622","rc":[{"atl":[[2.46,0]],"id":36463352}],"con":true,"img":false}]}
{"op":"mcm","clk":"5348138028","pt":1646214445135,"mc":[{"id":"1.195453622","rc":[{"atl":[[2.5,29.06]],"id":36463352}],"con":true,"img":false}]}
{"op":"mcm","clk":"5348138422","pt":1646214451050,"mc":[{"id":"1.195453622","rc":[{"atb":[[1.3,86.73]],"id":41308374}],"con":true,"img":false}]}
{"op":"mcm","clk":"5348138427","pt":1646214451152,"mc":[{"id":"1.195453622","rc":[{"atb":[[1.31,0]],"id":36463352},{"atb":[[1.26,0]],"id":41308374}],"con":true,"img":false}]}
{"op":"mcm","clk":"5348138435","pt":1646214451256,"mc":[{"id":"1.195453622","rc":[{"atb":[[1.35,86.07]],"id":36463352}],"con":true,"img":false}]}
{"op":"mcm","clk":"5348138539","pt":1646214452658,"mc":[{"id":"1.195453622","rc":[{"atb":[[1.34,24.51]],"id":36463352},{"atb":[[1.29,28.74]],"id":41308374}],"con":true,"img":false}]}
{"op":"mcm","clk":"5348138636","pt":1646214454267,"mc":[{"id":"1.195453622","rc":[{"atl":[[2.48,29.06]],"id":36463352}],"con":true,"img":false}]}
{"op":"mcm","clk":"5348138645","pt":1646214454370,"mc":[{"id":"1.195453622","rc":[{"atl":[[2.52,0]],"id":36463352}],"con":true,"img":false}]}
{"op":"mcm","clk":"5348138958","pt":1646214458581,"mc":[{"id":"1.195453622","rc":[{"atb":[[1.38,19.78]],"id":36463352},{"atb":[[1.33,22.78]],"id":41308374}],"con":true,"img":false}]}
{"op":"mcm","clk":"5348138983","pt":1646214458890,"mc":[{"id":"1.195453622","rc":[{"atl":[[2.4,0]],"id":41308374}],"con":true,"img":false}]}
{"op":"mcm","clk":"5348138989","pt":1646214458987,"mc":[{"id":"1.195453622","rc":[{"atl":[[2.36,31.14]],"id":41308374}],"con":true,"img":false}]}
{"op":"mcm","clk":"5348138999","pt":1646214459091,"mc":[{"id":"1.195453622","rc":[{"atl":[[2.4,62.28],[2.38,0]],"id":41308374}],"con":true,"img":false}]}
{"op":"mcm","clk":"5348139009","pt":1646214459199,"mc":[{"id":"1.195453622","rc":[{"atl":[[2.4,0],[2.34,31.14]],"id":41308374}],"con":true,"img":false}]}
{"op":"mcm","clk":"5348139089","pt":1646214460496,"mc":[{"id":"1.195453622","rc":[{"atb":[[3.95,33.9],[3.8,0]],"id":40199925}],"con":true,"img":false}]}
{"op":"mcm","clk":"5348139389","pt":1646214464440,"mc":[{"id":"1.195453622","rc":[{"atb":[[3.75,3.03]],"id":40250501}],"con":true,"img":false}]}
{"op":"mcm","clk":"5348139446","pt":1646214465166,"mc":[{"id":"1.195453622","rc":[{"atb":[[4,0]],"id":40250501},{"atb":[[1.35,0]],"id":36463352}],"con":true,"img":false}]}
{"op":"mcm","clk":"5348139453","pt":1646214465219,"mc":[{"id":"1.195453622","rc":[{"atb":[[4.2,14.78]],"id":40250501},{"atb":[[1.31,86.07]],"id":36463352}],"con":true,"img":false}]}
{"op":"mcm","clk":"5348139633","pt":1646214467666,"mc":[{"id":"1.195453622","rc":[{"atb":[[1.38,0]],"id":36463352}],"con":true,"img":false}]}
{"op":"mcm","clk":"5348139715","pt":1646214468753,"mc":[{"id":"1.195453622","rc":[{"atb":[[4.3,14.78],[4.1,1.66]],"id":40250501},{"atb":[[3.95,0],[4.1,51.9]],"id":40199925}],"con":true,"img":false}]}
{"op":"mcm","clk":"5348139924","pt":1646214471543,"mc":[{"id":"1.195453622","rc":[{"atb":[[4.1,0]],"id":40250501}],"con":true,"img":false}]}
{"op":"mcm","clk":"5348139941","pt":1646214471756,"mc":[{"id":"1.195453622","rc":[{"atb":[[4.4,1.66]],"id":40250501}],"con":true,"img":false}]}
{"op":"mcm","clk":"5348140049","pt":1646214473561,"mc":[{"id":"1.195453622","rc":[{"atb":[[1.34,46.62]],"id":36463352}],"con":true,"img":false}]}
{"op":"mcm","clk":"5348140249","pt":1646214476799,"mc":[{"id":"1.195453622","rc":[{"atb":[[1.29,0]],"id":41308374}],"con":true,"img":false}]}
{"op":"mcm","clk":"5348140257","pt":1646214476844,"mc":[{"id":"1.195453622","rc":[{"atb":[[1.3,0]],"id":41308374}],"con":true,"img":false}]}
{"op":"mcm","clk":"5348140264","pt":1646214476946,"mc":[{"id":"1.195453622","rc":[{"atb":[[1.26,86.73]],"id":41308374}],"con":true,"img":false}]}
{"op":"mcm","clk":"5348140440","pt":1646214479607,"mc":[{"id":"1.195453622","rc":[{"atb":[[1.33,0]],"id":41308374}],"con":true,"img":false}]}
{"op":"mcm","clk":"5348140989","pt":1646214486706,"mc":[{"id":"1.195453622","rc":[{"atb":[[1.29,25.92]],"id":41308374}],"con":true,"img":false}]}
{"op":"mcm","clk":"5348141094","pt":1646214488086,"mc":[{"id":"1.195453622","rc":[{"atl":[[2.5,0]],"id":36463352}],"con":true,"img":false}]}
{"op":"mcm","clk":"5348141101","pt":1646214488183,"mc":[{"id":"1.195453622","rc":[{"atl":[[2.46,29.06]],"id":36463352}],"con":true,"img":false}]}
{"op":"mcm","clk":"5348141108","pt":1646214488292,"mc":[{"id":"1.195453622","rc":[{"atl":[[2.52,58.12],[2.48,0]],"id":36463352}],"con":true,"img":false}]}
{"op":"mcm","clk":"5348141123","pt":1646214488492,"mc":[{"id":"1.195453622","rc":[{"atl":[[2.52,0],[2.44,29.06]],"id":36463352}],"con":true,"img":false}]}
{"op":"mcm","clk":"5348141492","pt":1646214493702,"mc":[{"id":"1.195453622","rc":[{"atl":[[40,0]],"id":23806261},{"atl":[[2.36,0]],"id":41308374}],"con":true,"img":false}]}
{"op":"mcm","clk":"5348141511","pt":1646214493810,"mc":[{"id":"1.195453622","rc":[{"atl":[[38,2.72]],"id":23806261},{"atl":[[2.32,31.14]],"id":41308374}],"con":true,"img":false}]}
{"op":"mcm","clk":"5348141527","pt":1646214493911,"mc":[{"id":"1.195453622","rc":[{"atl":[[2.36,62.28],[2.34,0]],"id":41308374}],"con":true,"img":false}]}
{"op":"mcm","clk":"5348141960","pt":1646214498766,"mc":[{"id":"1.195453622","rc":[{"atl":[[38,0]],"id":23806261}],"con":true,"img":false}]}
{"op":"mcm","clk":"5348141984","pt":1646214498875,"mc":[{"id":"1.195453622","rc":[{"atl":[[44,5.44]],"id":23806261}],"con":true,"img":false}]}
{"op":"mcm","clk":"5348142321","pt":1646214503677,"mc":[{"id":"1.195453622","rc":[{"atb":[[4.2,0]],"id":40250501},{"spn":7.45,"spf":"NaN","id":40250501},{"spn":1.8,"spf":"NaN","id":41308374}],"con":true,"img":false}]}
{"op":"mcm","clk":"5348142329","pt":1646214503783,"mc":[{"id":"1.195453622","rc":[{"atb":[[4.4,16.44]],"id":40250501}],"con":true,"img":false}]}
{"op":"mcm","clk":"5348142553","pt":1646214506663,"mc":[{"id":"1.195453622","rc":[{"atb":[[3.8,0]],"id":40250501}],"con":true,"img":false}]}
{"op":"mcm","clk":"5348142696","pt":1646214508574,"mc":[{"id":"1.195453622","rc":[{"atb":[[1.31,0]],"id":36463352},{"atl":[[2.32,0]],"id":41308374}],"con":true,"img":false}]}
{"op":"mcm","clk":"5348142699","pt":1646214508678,"mc":[{"id":"1.195453622","rc":[{"atb":[[1.35,86.07]],"id":36463352},{"atl":[[2.34,31.14]],"id":41308374}],"con":true,"img":false}]}
{"op":"mcm","clk":"5348142706","pt":1646214508781,"mc":[{"id":"1.195453622","rc":[{"atb":[[1.29,54.66]],"id":41308374}],"con":true,"img":false}]}
{"op":"mcm","clk":"5348142763","pt":1646214509705,"mc":[{"id":"1.195453622","rc":[{"atb":[[1.34,24.51]],"id":36463352}],"con":true,"img":false}]}
{"op":"mcm","clk":"5348143202","pt":1646214515596,"mc":[{"id":"1.195453622","rc":[{"atb":[[1.38,19.78]],"id":36463352}],"con":true,"img":false}]}
{"op":"mcm","clk":"5348143398","pt":1646214518331,"mc":[{"id":"1.195453622","rc":[{"atl":[[2.32,31.14]],"id":41308374}],"con":true,"img":false}]}
{"op":"mcm","clk":"5348143407","pt":1646214518434,"mc":[{"id":"1.195453622","rc":[{"atl":[[2.36,0]],"id":41308374}],"con":true,"img":false}]}
{"op":"mcm","clk":"5348143667","pt":1646214521947,"mc":[{"id":"1.195453622","rc":[{"atb":[[1.35,0]],"id":36463352},{"atl":[[2.72,0],[2.46,0]],"id":36463352}],"con":true,"img":false}]}
{"op":"mcm","clk":"5348143672","pt":1646214522048,"mc":[{"id":"1.195453622","rc":[{"atb":[[1.31,86.07]],"id":36463352},{"atl":[[2.92,32.28],[2.42,29.06]],"id":36463352}],"con":true,"img":false}]}
{"op":"mcm","clk":"5348143678","pt":1646214522147,"mc":[{"id":"1.195453622","rc":[{"atl":[[2.52,58.12],[2.44,0]],"id":36463352}],"con":true,"img":false}]}
{"op":"mcm","clk":"5348143714","pt":1646214522617,"mc":[{"id":"1.195453622","rc":[{"atb":[[1.38,0]],"id":36463352}],"con":true,"img":false}]}
{"op":"mcm","clk":"5348144095","pt":1646214527744,"mc":[{"id":"1.195453622","rc":[{"atb":[[1.34,46.62]],"id":36463352}],"con":true,"img":false}]}
{"op":"mcm","clk":"5348144642","pt":1646214534942,"mc":[{"id":"1.195453622","rc":[{"atl":[[2.42,0]],"id":36463352}],"con":true,"img":false}]}
{"op":"mcm","clk":"5348144650","pt":1646214535049,"mc":[{"id":"1.195453622","rc":[{"atl":[[2.5,29.06]],"id":36463352}],"con":true,"img":false}]}
{"op":"mcm","clk":"5348145220","pt":1646214543078,"mc":[{"id":"1.195453622","rc":[{"atb":[[1.26,0]],"id":41308374}],"con":true,"img":false}]}
{"op":"mcm","clk":"5348145226","pt":1646214543130,"mc":[{"id":"1.195453622","rc":[{"atb":[[1.3,86.73]],"id":41308374}],"con":true,"img":false}]}
{"op":"mcm","clk":"5348145460","pt":1646214546244,"mc":[{"id":"1.195453622","rc":[{"atl":[[2.52,0],[2.48,29.06]],"id":36463352}],"con":true,"img":false}]}
{"op":"mcm","clk":"5348145500","pt":1646214546868,"mc":[{"id":"1.195453622","rc":[{"atb":[[1.29,28.74]],"id":41308374}],"con":true,"img":false}]}
{"op":"mcm","clk":"5348145806","pt":1646214550645,"mc":[{"id":"1.195453622","rc":[{"atl":[[2.34,0]],"id":41308374}],"con":true,"img":false}]}
{"op":"mcm","clk":"5348145817","pt":1646214550749,"mc":[{"id":"1.195453622","rc":[{"atl":[[2.3,31.14]],"id":41308374}],"con":true,"img":false}]}
{"op":"mcm","clk":"5348145824","pt":1646214550852,"mc":[{"id":"1.195453622","rc":[{"atl":[[2.36,62.28],[2.32,0]],"id":41308374}],"con":true,"img":false}]}
{"op":"mcm","clk":"5348145844","pt":1646214551065,"mc":[{"id":"1.195453622","rc":[{"atl":[[2.36,0],[2.28,31.14]],"id":41308374}],"con":true,"img":false}]}
{"op":"mcm","clk":"5348145992","pt":1646214552773,"mc":[{"id":"1.195453622","rc":[{"atb":[[1.33,22.78]],"id":41308374}],"con":true,"img":false}]}
{"op":"mcm","clk":"5348146407","pt":1646214558247,"mc":[{"id":"1.195453622","rc":[{"atb":[[1.31,0]],"id":36463352},{"atb":[[1.3,0]],"id":41308374}],"con":true,"img":false}]}
{"op":"mcm","clk":"5348146413","pt":1646214558351,"mc":[{"id":"1.195453622","rc":[{"atb":[[1.35,86.07]],"id":36463352},{"atb":[[1.26,86.73]],"id":41308374}],"con":true,"img":false}]}
{"op":"mcm","clk":"5348146573","pt":1646214560872,"mc":[{"id":"1.195453622","rc":[{"atb":[[1.34,24.51]],"id":36463352},{"atb":[[1.33,0]],"id":41308374}],"con":true,"img":false}]}
{"op":"mcm","clk":"5348146686","pt":1646214562377,"mc":[{"id":"1.195453622","rc":[{"atb":[[4.3,0],[4.2,31.23]],"id":40250501},{"atb":[[2.42,0],[2.52,65.79]],"id":40846831}],"con":true,"img":false}]}
{"op":"mcm","clk":"5348146803","pt":1646214563887,"mc":[{"id":"1.195453622","rc":[{"atb":[[1.34,0]],"id":36463352},{"spn":1.35,"spf":1.0,"id":36463352},{"spn":1.78,"spf":"NaN","id":41308374}],"con":true,"img":false}]}
{"op":"mcm","clk":"5348146974","pt":1646214566209,"mc":[{"id":"1.195453622","rc":[{"atb":[[1.38,19.78]],"id":36463352},{"atb":[[1.29,54.66]],"id":41308374}],"con":true,"img":false}]}
{"op":"mcm","clk":"5348147173","pt":1646214569111,"mc":[{"id":"1.195453622","rc":[{"atb":[[1.35,0]],"id":36463352}],"con":true,"img":false}]}
{"op":"mcm","clk":"5348147179","pt":1646214569204,"mc":[{"id":"1.195453622","rc":[{"atb":[[1.31,86.07]],"id":36463352}],"con":true,"img":false}]}
{"op":"mcm","clk":"5348147262","pt":1646214570306,"mc":[{"id":"1.195453622","rc":[{"atb":[[1.38,0]],"id":36463352}],"con":true,"img":false}]}
{"op":"mcm","clk":"5348147458","pt":1646214572472,"mc":[{"id":"1.195453622","rc":[{"atb":[[4.4,1.66]],"id":40250501}],"con":true,"img":false}]}
{"op":"mcm","clk":"5348147465","pt":1646214572578,"mc":[{"id":"1.195453622","rc":[{"atb":[[4.3,14.78]],"id":40250501}],"con":true,"img":false}]}
{"op":"mcm","clk":"5348147690","pt":1646214575887,"mc":[{"id":"1.195453622","rc":[{"atl":[[2.5,0]],"id":36463352}],"con":true,"img":false}]}
{"op":"mcm","clk":"5348147696","pt":1646214575991,"mc":[{"id":"1.195453622","rc":[{"atl":[[2.46,29.06]],"id":36463352}],"con":true,"img":false}]}
{"op":"mcm","clk":"5348147702","pt":1646214576093,"mc":[{"id":"1.195453622","rc":[{"atl":[[2.52,58.12],[2.48,0]],"id":36463352}],"con":true,"img":false}]}
{"op":"mcm","clk":"5348147772","pt":1646214577291,"mc":[{"id":"1.195453622","rc":[{"atb":[[3.75,0]],"id":40250501}],"con":true,"img":false}]}
{"op":"mcm","clk":"5348147965","pt":1646214580299,"mc":[{"id":"1.195453622","rc":[{"atb":[[1.34,22.11]],"id":36463352}],"con":true,"img":false}]}
{"op":"mcm","clk":"5348148132","pt":1646214582734,"mc":[{"id":"1.195453622","rc":[{"atl":[[2.3,0]],"id":41308374}],"con":true,"img":false}]}
{"op":"mcm","clk":"5348148135","pt":1646214582784,"mc":[{"id":"1.195453622","rc":[{"atl":[[2.26,31.14]],"id":41308374}],"con":true,"img":false}]}
{"op":"mcm","clk":"5348148143","pt":1646214582887,"mc":[{"id":"1.195453622","rc":[{"atl":[[2.36,62.28],[2.28,0]],"id":41308374}],"con":true,"img":false}]}
{"op":"mcm","clk":"5348148374","pt":1646214586102,"mc":[{"id":"1.195453622","rc":[{"atb":[[4.3,35.22],[4.2,0]],"id":40250501}],"con":true,"img":false}]}
{"op":"mcm","clk":"5348148607","pt":1646214589220,"mc":[{"id":"1.195453622","rc":[{"atl":[[2.46,0]],"id":36463352}],"con":true,"img":false}]}
{"op":"mcm","clk":"5348148613","pt":1646214589322,"mc":[{"id":"1.195453622","rc":[{"atl":[[2.5,29.06]],"id":36463352}],"con":true,"img":false}]}
{"op":"mcm","clk":"5348148801","pt":1646214592016,"mc":[{"id":"1.195453622","rc":[{"atb":[[1.34,46.62]],"id":36463352}],"con":true,"img":false}]}
{"op":"mcm","clk":"5348149036","pt":1646214595645,"mc":[{"id":"1.195453622","rc":[{"atl":[[2.26,0]],"id":41308374}],"con":true,"img":false}]}
{"op":"mcm","clk":"5348149044","pt":1646214595751,"mc":[{"id":"1.195453622","rc":[{"atl":[[2.34,31.14]],"id":41308374}],"con":true,"img":false}]}
{"op":"mcm","clk":"5348149258","pt":1646214598711,"mc":[{"id":"1.195453622","rc":[{"atb":[[1.26,0]],"id":41308374}],"con":true,"img":false}]}
{"op":"mcm","clk":"5348149266","pt":1646214598813,"mc":[{"id":"1.195453622","rc":[{"atb":[[1.3,86.73]],"id":41308374}],"con":true,"img":false}]}
{"op":"mcm","clk":"5348149302","pt":1646214599443,"mc":[{"id":"1.195453622","rc":[{"atb":[[1.29,28.74]],"id":41308374}],"con":true,"img":false}]}
{"op":"mcm","clk":"5348149313","pt":1646214599641,"mc":[{"id":"1.195453622","rc":[{"atl":[[2.52,0]],"id":36463352}],"con":true,"img":false}]}
{"op":"mcm","clk":"5348149319","pt":1646214599749,"mc":[{"id":"1.195453622","rc":[{"atl":[[2.48,29.06]],"id":36463352}],"con":true,"img":false}]}
{"op":"mcm","clk":"5348149709","pt":1646214605264,"mc":[{"id":"1.195453622","rc":[{"atb":[[1.33,22.78]],"id":41308374}],"con":true,"img":false}]}
{"op":"mcm","clk":"5348149796","pt":1646214606457,"mc":[{"id":"1.195453622","rc":[{"atl":[[2.36,0],[2.32,31.14]],"id":41308374}],"con":true,"img":false}]}
{"op":"mcm","clk":"5348149948","pt":1646214608432,"mc":[{"id":"1.195453622","rc":[{"atb":[[1.29,0]],"id":41308374}],"con":true,"img":false}]}
{"op":"mcm","clk":"5348150142","pt":1646214610874,"mc":[{"id":"1.195453622","rc":[{"atb":[[1.3,0]],"id":41308374}],"con":true,"img":false}]}
{"op":"mcm","clk":"5348150152","pt":1646214610969,"mc":[{"id":"1.195453622","rc":[{"atb":[[1.26,86.73]],"id":41308374}],"con":true,"img":false}]}
{"op":"mcm","clk":"5348150165","pt":1646214611129,"mc":[{"id":"1.195453622","rc":[{"atb":[[1.33,0]],"id":41308374}],"con":true,"img":false}]}
{"op":"mcm","clk":"5348150365","pt":1646214613844,"mc":[{"id":"1.195453622","rc":[{"atl":[[2.92,0]],"id":36463352}],"con":true,"img":false}]}
{"op":"mcm","clk":"5348150371","pt":1646214613945,"mc":[{"id":"1.195453622","rc":[{"atl":[[2.72,32.28]],"id":36463352}],"con":true,"img":false}]}
{"op":"mcm","clk":"5348150751","pt":1646214619688,"mc":[{"id":"1.195453622","rc":[{"atb":[[1.31,0]],"id":36463352}],"con":true,"img":false}]}
{"op":"mcm","clk":"5348150755","pt":1646214619793,"mc":[{"id":"1.195453622","rc":[{"atb":[[1.35,86.07]],"id":36463352}],"con":true,"img":false}]}
{"op":"mcm","clk":"5348150792","pt":1646214620369,"mc":[{"id":"1.195453622","rc":[{"atb":[[1.34,24.51]],"id":36463352},{"atb":[[1.29,25.92]],"id":41308374}],"con":true,"img":false}]}
{"op":"mcm","clk":"5348151215","pt":1646214626474,"mc":[{"id":"1.195453622","rc":[{"atb":[[1.38,19.78]],"id":36463352},{"spn":1.38,"spf":1.0,"id":36463352},{"spn":1.8,"spf":"NaN","id":41308374}],"con":true,"img":false}]}
{"op":"mcm","clk":"5348151378","pt":1646214628709,"mc":[{"id":"1.195453622","rc":[{"atl":[[2.5,0]],"id":36463352}],"con":true,"img":false}]}
{"op":"mcm","clk":"5348151384","pt":1646214628803,"mc":[{"id":"1.195453622","rc":[{"atl":[[2.46,29.06]],"id":36463352}],"con":true,"img":false}]}
{"op":"mcm","clk":"5348151395","pt":1646214628915,"mc":[{"id":"1.195453622","rc":[{"atl":[[2.52,58.12],[2.48,0]],"id":36463352}],"con":true,"img":false}]}
{"op":"mcm","clk":"5348151616","pt":1646214631508,"mc":[{"id":"1.195453622","rc":[{"atb":[[1.35,0]],"id":36463352}],"con":true,"img":false}]}
{"op":"mcm","clk":"5348151623","pt":1646214631612,"mc":[{"id":"1.195453622","rc":[{"atb":[[1.31,86.07]],"id":36463352}],"con":true,"img":false}]}
{"op":"mcm","clk":"5348151682","pt":1646214632395,"mc":[{"id":"1.195453622","rc":[{"atb":[[1.38,0]],"id":36463352}],"con":true,"img":false}]}
{"op":"mcm","clk":"5348151765","pt":1646214633375,"mc":[{"id":"1.195453622","rc":[{"atb":[[1.29,54.66]],"id":41308374}],"con":true,"img":false}]}
{"op":"mcm","clk":"5348151998","pt":1646214636508,"mc":[{"id":"1.195453622","rc":[{"atl":[[2.34,0]],"id":41308374}],"con":true,"img":false}]}
{"op":"mcm","clk":"5348152005","pt":1646214636648,"mc":[{"id":"1.195453622","rc":[{"atl":[[2.3,31.14]],"id":41308374}],"con":true,"img":false}]}
{"op":"mcm","clk":"5348152009","pt":1646214636790,"mc":[{"id":"1.195453622","rc":[{"atl":[[2.36,62.28],[2.32,0]],"id":41308374}],"con":true,"img":false}]}
{"op":"mcm","clk":"5348152125","pt":1646214638317,"mc":[{"id":"1.195453622","rc":[{"atb":[[1.34,46.62]],"id":36463352}],"con":true,"img":false}]}
{"op":"mcm","clk":"5348152383","pt":1646214641941,"mc":[{"id":"1.195453622","rc":[{"atb":[[4.3,14.78]],"id":40250501},{"atl":[[65,0]],"id":40250501},{"atl":[[2.46,0]],"id":36463352},{"atb":[[1.13,0],[1.04,798.52]],"id":41308374},{"atb":[[2.22,81.97],[2.52,0]],"id":40846831},{"atb":[[4.1,19.64],[3.65,37.74]],"id":40199925},{"atl":[[60,0]],"id":6780934}],"con":true,"img":false}]}
{"op":"mcm","clk":"5348152389","pt":1646214642046,"mc":[{"id":"1.195453622","rc":[{"atb":[[3.95,0],[3.55,39.22]],"id":23806261},{"atl":[[34,3.03],[46,0]],"id":23806261},{"atb":[[3.4,83.25]],"id":40250501},{"atl":[[34,3.03]],"id":40250501},{"atl":[[2.52,0],[3.15,46.51]],"id":36463352},{"atl":[[22,8.21],[30,0]],"id":40199925},{"atl":[[29,3.57]],"id":6780934}],"con":true,"img":false}]}
{"op":"mcm","clk":"5348152395","pt":1646214642102,"mc":[{"id":"1.195453622","rc":[{"atl":[[2.5,29.06]],"id":36463352},{"atb":[[2.56,64.1],[2.22,0]],"id":40846831}],"con":true,"img":false}]}
{"op":"mcm","clk":"5348152403","pt":1646214642206,"mc":[{"id":"1.195453622","rc":[{"atb":[[3.55,0],[4.4,29.41]],"id":23806261},{"atb":[[4.3,35.22],[3.4,41.58]],"id":40250501}],"con":true,"img":false}]}
{"op":"mcm","clk":"5348152744","pt":1646214647316,"mc":[{"id":"1.195453622","rc":[{"atl":[[2.3,0]],"id":41308374}],"con":true,"img":false}]}
{"op":"mcm","clk":"5348152758","pt":1646214647419,"mc":[{"id":"1.195453622","rc":[{"atl":[[2.34,31.14]],"id":41308374}],"con":true,"img":false}]}
{"op":"mcm","clk":"5348152776","pt":1646214647574,"mc":[{"id":"1.195453622","rc":[{"atl":[[2.36,0],[2.42,70.42]],"id":41308374}],"con":true,"img":false}]}
{"op":"mcm","clk":"5348153037","pt":1646214652001,"mc":[{"id":"1.195453622","rc":[{"atl":[[2.72,84.91],[3.15,0]],"id":36463352}],"con":true,"img":false}]}
{"op":"mcm","clk":"5348153068","pt":1646214652517,"mc":[{"id":"1.195453622","rc":[{"atb":[[4.7,0]],"id":23806261},{"atl":[[20,2.72]],"id":40250501},{"atl":[[2.72,52.63],[2.5,0]],"id":36463352},{"atl":[[9.8,4.35]],"id":40846831},{"atb":[[4.1,0]],"id":40199925}],"con":true,"img":false}]}
{"op":"mcm","clk":"5348153078","pt":1646214652620,"mc":[{"id":"1.195453622","rc":[{"atb":[[4.5,15.5]],"id":23806261},{"atl":[[24,2.72]],"id":40250501},{"atl":[[2.92,32.28],[2.7,29.06]],"id":36463352},{"atb":[[3.8,19.64]],"id":40199925},{"atl":[[11,5.48]],"id":40846831}],"con":true,"img":false}]}
{"op":"mcm","clk":"5348153527","pt":1646214659727,"mc":[{"id":"1.195453622","rc":[{"atl":[[2.32,31.14],[2.42,0]],"id":41308374}],"con":true,"img":false}]}
{"op":"mcm","clk":"5348153721","pt":1646214662616,"mc":[{"id":"1.195453622","rc":[{"atb":[[5.2,0]],"id":23806261},{"atl":[[2.34,0]],"id":41308374}],"con":true,"img":false}]}
{"op":"mcm","clk":"5348153730","pt":1646214662719,"mc":[{"id":"1.195453622","rc":[{"atb":[[4.5,25.88]],"id":23806261},{"atl":[[2.4,31.14],[2.32,0],[2.42,62.28]],"id":41308374}],"con":true,"img":false}]}
{"op":"mcm","clk":"5348153875","pt":1646214664936,"mc":[{"id":"1.195453622","rc":[{"atb":[[1.11,798.52],[1.04,0]],"id":41308374},{"atb":[[3.65,0],[4.7,14.87]],"id":40199925}],"con":true,"img":false}]}
{"op":"mcm","clk":"5348153887","pt":1646214665041,"mc":[{"id":"1.195453622","rc":[{"atb":[[4.3,14.78],[4.1,32.26]],"id":40250501}],"con":true,"img":false}]}
{"op":"mcm","clk":"5348153893","pt":1646214665144,"mc":[{"id":"1.195453622","rc":[{"atb":[[4.5,57.03],[4.7,1.66]],"id":40199925}],"con":true,"img":false}]}
{"op":"mcm","clk":"5348154051","pt":1646214667520,"mc":[{"id":"1.195453622","rc":[{"atb":[[1.26,0]],"id":41308374}],"con":true,"img":false}]}
{"op":"mcm","clk":"5348154059","pt":1646214667621,"mc":[{"id":"1.195453622","rc":[{"atb":[[5.3,0]],"id":23806261},{"atb":[[1.3,86.73]],"id":41308374}],"con":true,"img":false}]}
{"op":"mcm","clk":"5348154066","pt":1646214667724,"mc":[{"id":"1.195453622","rc":[{"atb":[[4.3,60.54],[4.4,0]],"id":23806261}],"con":true,"img":false}]}
{"op":"mcm","clk":"5348154072","pt":1646214667826,"mc":[{"id":"1.195453622","rc":[{"atb":[[4.6,1.66]],"id":23806261}],"con":true,"img":false}]}
{"op":"mcm","clk":"5348154109","pt":1646214668347,"mc":[{"id":"1.195453622","rc":[{"atb":[[1.29,28.74]],"id":41308374}],"con":true,"img":false}]}
{"op":"mcm","clk":"5348154399","pt":1646214672344,"mc":[{"id":"1.195453622","rc":[{"atb":[[4.5,10.38]],"id":23806261},{"atb":[[1.3,0]],"id":41308374}],"con":true,"img":false}]}
{"op":"mcm","clk":"5348154406","pt":1646214672452,"mc":[{"id":"1.195453622","rc":[{"atb":[[4.4,15.5]],"id":23806261},{"atb":[[1.27,86.73]],"id":41308374}],"con":true,"img":false}]}
{"op":"mcm","clk":"5348154766","pt":1646214677253,"mc":[{"id":"1.195453622","rc":[{"atl":[[44,2.72]],"id":23806261},{"atl":[[23,0]],"id":40199925},{"atb":[[3.15,0]],"id":6780934}],"con":true,"img":false}]}
{"op":"mcm","clk":"5348154773","pt":1646214677355,"mc":[{"id":"1.195453622","rc":[{"atl":[[24,2.72]],"id":23806261},{"atl":[[21,5.44]],"id":40199925},{"atb":[[3.25,22.01]],"id":6780934}],"con":true,"img":false}]}
{"op":"mcm","clk":"5348154951","pt":1646214680441,"mc":[{"id":"1.195453622","rc":[{"atb":[[1.3,25.06]],"id":41308374},{"atb":[[3.05,4.06]],"id":6780934}],"con":true,"img":false}]}
{"op":"mcm","clk":"5348155286","pt":1646214685493,"mc":[{"id":"1.195453622","rc":[{"atl":[[2.42,0],[2.38,31.14]],"id":41308374}],"con":true,"img":false}]}
{"op":"mcm","clk":"5348155331","pt":1646214686261,"mc":[{"id":"1.195453622","rc":[{"atb":[[3.3,3.27]],"id":6780934}],"con":true,"img":false}]}
{"op":"mcm","clk":"5348155813","pt":1646214693785,"mc":[{"id":"1.195453622","rc":[{"spn":10.05,"spf":"NaN","id":23806261},{"spn":1.34,"spf":1.0,"id":36463352},{"spn":1.84,"spf":"NaN","id":41308374},{"atl":[[14.5,3.23]],"id":6780934}],"con":true,"img":false}]}
{"op":"mcm","clk":"5348155819","pt":1646214693911,"mc":[{"id":"1.195453622","rc":[{"atl":[[17,4.03]],"id":6780934}],"con":true,"img":false}]}
{"op":"mcm","clk":"5348156292","pt":1646214701775,"mc":[{"id":"1.195453622","rc":[{"atb":[[1.29,0]],"id":41308374}],"con":true,"img":false}]}
{"op":"mcm","clk":"5348156446","pt":1646214704812,"mc":[{"id":"1.195453622","rc":[{"atl":[[44,0]],"id":23806261},{"atb":[[1.22,0]],"id":41308374}],"con":true,"img":false}]}
{"op":"mcm","clk":"5348156450","pt":1646214704909,"mc":[{"id":"1.195453622","rc":[{"atl":[[25,2.72]],"id":23806261},{"atb":[[1.26,263.2]],"id":41308374}],"con":true,"img":false}]}
{"op":"mcm","clk":"5348157126","pt":1646214715910,"mc":[{"id":"1.195453622","rc":[{"atl":[[2.4,0]],"id":41308374}],"con":true,"img":false}]}
{"op":"mcm","clk":"5348157132","pt":1646214716010,"mc":[{"id":"1.195453622","rc":[{"atl":[[2.36,31.14],[2.42,62.28]],"id":41308374}],"con":true,"img":false}]}
{"op":"mcm","clk":"5348157139","pt":1646214716115,"mc":[{"id":"1.195453622","rc":[{"atl":[[2.38,0],[2.34,31.14]],"id":41308374}],"con":true,"img":false}]}
{"op":"mcm","clk":"5348157147","pt":1646214716220,"mc":[{"id":"1.195453622","rc":[{"atl":[[2.42,0]],"id":41308374}],"con":true,"img":false}]}
{"op":"mcm","clk":"5348157218","pt":1646214717352,"mc":[{"id":"1.195453622","rc":[{"atb":[[1.3,52.84]],"id":41308374}],"con":true,"img":false}]}
{"op":"mcm","clk":"5348158414","pt":1646214734542,"mc":[{"id":"1.195453622","rc":[{"atb":[[3.95,19.44],[4.4,0]],"id":23806261}],"con":true,"img":false}]}
{"op":"mcm","clk":"5348158425","pt":1646214734639,"mc":[{"id":"1.195453622","rc":[{"atl":[[20,0]],"id":40250501}],"con":true,"img":false}]}
{"op":"mcm","clk":"5348158430","pt":1646214734742,"mc":[{"id":"1.195453622","rc":[{"atl":[[23,2.72]],"id":40250501}],"con":true,"img":false}]}
{"op":"mcm","clk":"5348158992","pt":1646214742845,"mc":[{"id":"1.195453622","rc":[{"atb":[[3.7,0]],"id":40250501}],"con":true,"img":false}]}
{"op":"mcm","clk":"5348158999","pt":1646214742949,"mc":[{"id":"1.195453622","rc":[{"atb":[[4.2,20.43]],"id":40250501}],"con":true,"img":false}]}
{"op":"mcm","clk":"5348159278","pt":1646214746971,"mc":[{"id":"1.195453622","rc":[{"atl":[[2.36,0]],"id":41308374}],"con":true,"img":false}]}
{"op":"mcm","clk":"5348159284","pt":1646214747075,"mc":[{"id":"1.195453622","rc":[{"atl":[[2.32,31.14]],"id":41308374}],"con":true,"img":false}]}
{"op":"mcm","clk":"5348159292","pt":1646214747178,"mc":[{"id":"1.195453622","rc":[{"atl":[[2.42,62.28],[2.34,0]],"id":41308374}],"con":true,"img":false}]}
{"op":"mcm","clk":"5348159755","pt":1646214754403,"mc":[{"id":"1.195453622","rc":[{"spn":1.81,"spf":"NaN","id":41308374},{"atb":[[3.25,0]],"id":6780934}],"con":true,"img":false}]}
{"op":"mcm","clk":"5348159760","pt":1646214754459,"mc":[{"id":"1.195453622","rc":[{"atb":[[3.3,25.28]],"id":6780934}],"con":true,"img":false}]}
{"op":"mcm","clk":"5348159869","pt":1646214756005,"mc":[{"id":"1.195453622","rc":[{"atb":[[3.3,22.01]],"id":6780934}],"con":true,"img":false}]}
{"op":"mcm","clk":"5348160019","pt":1646214758181,"mc":[{"id":"1.195453622","rc":[{"atl":[[2.32,0]],"id":41308374}],"con":true,"img":false}]}
{"op":"mcm","clk":"5348160026","pt":1646214758281,"mc":[{"id":"1.195453622","rc":[{"atl":[[2.4,31.14]],"id":41308374}],"con":true,"img":false}]}
{"op":"mcm","clk":"5348160215","pt":1646214761425,"mc":[{"id":"1.195453622","rc":[{"atb":[[3.4,3.13]],"id":6780934}],"con":true,"img":false}]}
{"op":"mcm","clk":"5348160510","pt":1646214765595,"mc":[{"id":"1.195453622","rc":[{"atl":[[14.5,0]],"id":6780934}],"con":true,"img":false}]}
{"op":"mcm","clk":"5348160518","pt":1646214765700,"mc":[{"id":"1.195453622","rc":[{"atl":[[16.5,3.23]],"id":6780934}],"con":true,"img":false}]}
{"op":"mcm","clk":"5348160755","pt":1646214769011,"mc":[{"id":"1.195453622","rc":[{"atl":[[2.38,31.14]],"id":41308374}],"con":true,"img":false}]}
{"op":"mcm","clk":"5348160764","pt":1646214769112,"mc":[{"id":"1.195453622","rc":[{"atl":[[2.42,0]],"id":41308374}],"con":true,"img":false}]}
{"op":"mcm","clk":"5348161329","pt":1646214778516,"mc":[{"id":"1.195453622","rc":[{"atl":[[11,0]],"id":40846831}],"con":true,"img":false}]}
{"op":"mcm","clk":"5348161334","pt":1646214778618,"mc":[{"id":"1.195453622","rc":[{"atl":[[9.8,9.84]],"id":40846831}],"con":true,"img":false}]}
{"op":"mcm","clk":"5348161969","pt":1646214788429,"mc":[{"id":"1.195453622","rc":[{"atb":[[4.3,30.24],[3.95,53.34]],"id":23806261},{"atb":[[4.1,0],[3.8,35.71]],"id":40250501},{"atl":[[2.72,0],[2.86,53.76]],"id":36463352},{"atb":[[2.56,0],[2.38,72.46]],"id":40846831},{"atb":[[4.5,28.51],[4.1,32.26]],"id":40199925}],"con":true,"img":false}]}
{"op":"mcm","clk":"5348162100","pt":1646214790029,"mc":[{"id":"1.195453622","rc":[{"atb":[[1.31,0]],"id":36463352}],"con":true,"img":false}]}
{"op":"mcm","clk":"5348162107","pt":1646214790132,"mc":[{"id":"1.195453622","rc":[{"atb":[[1.35,86.07]],"id":36463352}],"con":true,"img":false}]}
{"op":"mcm","clk":"5348162221","pt":1646214791724,"mc":[{"id":"1.195453622","rc":[{"atb":[[1.34,24.51]],"id":36463352}],"con":true,"img":false}]}
{"op":"mcm","clk":"5348162363","pt":1646214793526,"mc":[{"id":"1.195453622","rc":[{"atl":[[24,0]],"id":40250501}],"con":true,"img":false}]}
{"op":"mcm","clk":"5348162373","pt":1646214793630,"mc":[{"id":"1.195453622","rc":[{"atl":[[26,2.72]],"id":40250501}],"con":true,"img":false}]}
{"op":"mcm","clk":"5348162651","pt":1646214797138,"mc":[{"id":"1.195453622","rc":[{"atb":[[4.2,0]],"id":40250501},{"atl":[[2.4,0]],"id":41308374}],"con":true,"img":false}]}
{"op":"mcm","clk":"5348162658","pt":1646214797241,"mc":[{"id":"1.195453622","rc":[{"atb":[[3.9,20.43]],"id":40250501},{"atl":[[2.36,31.14]],"id":41308374}],"con":true,"img":false}]}
{"op":"mcm","clk":"5348162668","pt":1646214797343,"mc":[{"id":"1.195453622","rc":[{"atl":[[2.42,62.28],[2.38,0]],"id":41308374}],"con":true,"img":false}]}
{"op":"mcm","clk":"5348162675","pt":1646214797447,"mc":[{"id":"1.195453622","rc":[{"atl":[[2.42,0],[2.34,31.14]],"id":41308374}],"con":true,"img":false}]}
{"op":"mcm","clk":"5348162750","pt":1646214798630,"mc":[{"id":"1.195453622","rc":[{"atb":[[1.38,19.78]],"id":36463352}],"con":true,"img":false}]}
{"op":"mcm","clk":"5348162841","pt":1646214800282,"mc":[{"id":"1.195453622","rc":[{"atb":[[1.34,0]],"id":36463352}],"con":true,"img":false}]}
{"op":"mcm","clk":"5348163037","pt":1646214803369,"mc":[{"id":"1.195453622","rc":[{"atb":[[1.35,0]],"id":36463352}],"con":true,"img":false}]}
{"op":"mcm","clk":"5348163042","pt":1646214803470,"mc":[{"id":"1.195453622","rc":[{"atb":[[1.31,86.07]],"id":36463352}],"con":true,"img":false}]}
{"op":"mcm","clk":"5348163240","pt":1646214806576,"mc":[{"id":"1.195453622","rc":[{"atb":[[1.38,0]],"id":36463352}],"con":true,"img":false}]}
{"op":"mcm","clk":"5348163671","pt":1646214812757,"mc":[{"id":"1.195453622","rc":[{"atb":[[1.34,22.11]],"id":36463352}],"con":true,"img":false}]}
{"op":"mcm","clk":"5348164570","pt":1646214826022,"mc":[{"id":"1.195453622","rc":[{"atb":[[4.3,0]],"id":40250501},{"spn":1.82,"spf":"NaN","id":41308374}],"con":true,"img":false}]}
{"op":"mcm","clk":"5348164578","pt":1646214826122,"mc":[{"id":"1.195453622","rc":[{"atb":[[4.4,16.44]],"id":40250501}],"con":true,"img":false}]}
{"op":"mcm","clk":"5348164739","pt":1646214828334,"mc":[{"id":"1.195453622","rc":[{"atb":[[1.34,46.62]],"id":36463352}],"con":true,"img":false}]}
{"op":"mcm","clk":"5348164759","pt":1646214828603,"mc":[{"id":"1.195453622","rc":[{"atl":[[2.36,0]],"id":41308374}],"con":true,"img":false}]}
{"op":"mcm","clk":"5348164772","pt":1646214828707,"mc":[{"id":"1.195453622","rc":[{"atl":[[2.32,31.14]],"id":41308374}],"con":true,"img":false}]}
{"op":"mcm","clk":"5348164782","pt":1646214828810,"mc":[{"id":"1.195453622","rc":[{"atl":[[2.42,62.28],[2.34,0]],"id":41308374}],"con":true,"img":false}]}
{"op":"mcm","clk":"5348165818","pt":1646214843447,"mc":[{"id":"1.195453622","rc":[{"atl":[[2.92,0]],"id":36463352},{"atl":[[2.32,0]],"id":41308374},{"atb":[[2.24,0]],"id":40846831}],"con":true,"img":false}]}
{"op":"mcm","clk":"5348165823","pt":1646214843558,"mc":[{"id":"1.195453622","rc":[{"atl":[[2.84,32.28]],"id":36463352},{"atl":[[2.4,31.14]],"id":41308374},{"atb":[[2.4,43.57]],"id":40846831}],"con":true,"img":false}]}
{"op":"mcm","clk":"5348166049","pt":1646214846756,"mc":[{"id":"1.195453622","rc":[{"atl":[[17,0]],"id":6780934}],"con":true,"img":false}]}
{"op":"mcm","clk":"5348166056","pt":1646214846855,"mc":[{"id":"1.195453622","rc":[{"atl":[[18,4.03]],"id":6780934}],"con":true,"img":false}]}
{"op":"mcm","clk":"5348166244","pt":1646214849839,"mc":[{"id":"1.195453622","rc":[{"atl":[[2.42,0],[2.38,31.14]],"id":41308374}],"con":true,"img":false}]}
{"op":"mcm","clk":"5348166761","pt":1646214857944,"mc":[{"id":"1.195453622","rc":[{"atb":[[1.31,0]],"id":36463352}],"con":true,"img":false}]}
{"op":"mcm","clk":"5348166765","pt":1646214858042,"mc":[{"id":"1.195453622","rc":[{"atb":[[1.35,86.07]],"id":36463352}],"con":true,"img":false}]}
{"op":"mcm","clk":"5348166939","pt":1646214860772,"mc":[{"id":"1.195453622","rc":[{"atb":[[1.34,24.51]],"id":36463352}],"con":true,"img":false}]}
{"op":"mcm","clk":"5348167403","pt":1646214866761,"mc":[{"id":"1.195453622","rc":[{"atb":[[1.38,19.78]],"id":36463352}],"con":true,"img":false}]}
{"op":"mcm","clk":"5348167808","pt":1646214872374,"mc":[{"id":"1.195453622","rc":[{"atb":[[1.35,0]],"id":36463352}],"con":true,"img":false}]}
{"op":"mcm","clk":"5348167814","pt":1646214872473,"mc":[{"id":"1.195453622","rc":[{"atb":[[1.31,86.07]],"id":36463352}],"con":true,"img":false}]}
{"op":"mcm","clk":"5348167834","pt":1646214872777,"mc":[{"id":"1.195453622","rc":[{"atb":[[1.38,0]],"id":36463352}],"con":true,"img":false}]}
{"op":"mcm","clk":"5348168204","pt":1646214878979,"mc":[{"id":"1.195453622","rc":[{"atb":[[1.34,46.62]],"id":36463352},{"atl":[[2.4,0]],"id":41308374}],"con":true,"img":false}]}
{"op":"mcm","clk":"5348168210","pt":1646214879079,"mc":[{"id":"1.195453622","rc":[{"atl":[[2.36,31.14]],"id":41308374}],"con":true,"img":false}]}
{"op":"mcm","clk":"5348168217","pt":1646214879185,"mc":[{"id":"1.195453622","rc":[{"atl":[[2.42,62.28],[2.38,0]],"id":41308374}],"con":true,"img":false}]}
{"op":"mcm","clk":"5348168967","pt":1646214890298,"mc":[{"id":"1.195453622","rc":[{"atl":[[2.36,0]],"id":41308374},{"spn":1.86,"spf":"NaN","id":41308374}],"con":true,"img":false}]}
{"op":"mcm","clk":"5348168974","pt":1646214890398,"mc":[{"id":"1.195453622","rc":[{"atl":[[2.4,31.14]],"id":41308374}],"con":true,"img":false}]}
{"op":"mcm","clk":"5348169545","pt":1646214899726,"mc":[{"id":"1.195453622","rc":[{"atl":[[2.42,0],[2.38,31.14]],"id":41308374}],"con":true,"img":false}]}
{"op":"mcm","clk":"5348170377","pt":1646214911719,"mc":[{"id":"1.195453622","rc":[{"atb":[[1.31,0]],"id":36463352}],"con":true,"img":false}]}
{"op":"mcm","clk":"5348170385","pt":1646214911820,"mc":[{"id":"1.195453622","rc":[{"atb":[[1.35,86.07]],"id":36463352}],"con":true,"img":false}]}
{"op":"mcm","clk":"5348170546","pt":1646214914346,"mc":[{"id":"1.195453622","rc":[{"atb":[[1.34,22.11]],"id":36463352}],"con":true,"img":false}]}
{"op":"mcm","clk":"5348170588","pt":1646214915014,"mc":[{"id":"1.195453622","rc":[{"atb":[[1.34,0]],"id":36463352}],"con":true,"img":false}]}
{"op":"mcm","clk":"5348170961","pt":1646214920951,"mc":[{"id":"1.195453622","rc":[{"atb":[[1.38,19.78]],"id":36463352}],"con":true,"img":false}]}
{"op":"mcm","clk":"5348171094","pt":1646214922920,"mc":[{"id":"1.195453622","rc":[{"atb":[[1.35,0]],"id":36463352}],"con":true,"img":false}]}
{"op":"mcm","clk":"5348171102","pt":1646214923022,"mc":[{"id":"1.195453622","rc":[{"atb":[[1.31,86.07]],"id":36463352}],"con":true,"img":false}]}
{"op":"mcm","clk":"5348171157","pt":1646214923949,"mc":[{"id":"1.195453622","rc":[{"atb":[[1.38,0]],"id":36463352}],"con":true,"img":false}]}
{"op":"mcm","clk":"5348171416","pt":1646214928435,"mc":[{"id":"1.195453622","rc":[{"atl":[[2.4,0]],"id":41308374}],"con":true,"img":false}]}
{"op":"mcm","clk":"5348171422","pt":1646214928538,"mc":[{"id":"1.195453622","rc":[{"atl":[[2.36,31.14],[2.42,62.28],[2.38,0]],"id":41308374}],"con":true,"img":false}]}
{"op":"mcm","clk":"5348171511","pt":1646214930032,"mc":[{"id":"1.195453622","rc":[{"atb":[[1.34,22.11]],"id":36463352}],"con":true,"img":false}]}
{"op":"mcm","clk":"5348172278","pt":1646214939178,"mc":[{"id":"1.195453622","rc":[{"atl":[[2.36,0]],"id":41308374}],"con":true,"img":false}]}
{"op":"mcm","clk":"5348172284","pt":1646214939287,"mc":[{"id":"1.195453622","rc":[{"atl":[[2.4,31.14]],"id":41308374}],"con":true,"img":false}]}
{"op":"mcm","clk":"5348172299","pt":1646214939537,"mc":[{"id":"1.195453622","rc":[{"atb":[[1.34,46.62]],"id":36463352}],"con":true,"img":false}]}
{"op":"mcm","clk":"5348172608","pt":1646214944558,"mc":[{"id":"1.195453622","rc":[{"atb":[[1.26,0]],"id":41308374}],"con":true,"img":false}]}
{"op":"mcm","clk":"5348172614","pt":1646214944663,"mc":[{"id":"1.195453622","rc":[{"atb":[[1.22,263.2]],"id":41308374}],"con":true,"img":false}]}
{"op":"mcm","clk":"5348172864","pt":1646214948696,"mc":[{"id":"1.195453622","rc":[{"atl":[[2.42,0],[2.38,31.14]],"id":41308374}],"con":true,"img":false}]}
{"op":"mcm","clk":"5348173868","pt":1646214966004,"mc":[{"id":"1.195453622","rc":[{"atb":[[4.3,60.54],[3.95,19.44]],"id":23806261},{"atb":[[4.1,32.26],[3.8,0]],"id":40250501},{"atl":[[2.72,52.63],[2.86,0]],"id":36463352},{"spn":1.84,"spf":"NaN","id":41308374},{"atb":[[2.5,66.67],[2.38,0]],"id":40846831},{"atb":[[4.5,57.08],[4.1,0]],"id":40199925}],"con":true,"img":false}]}
{"op":"mcm","clk":"5348174039","pt":1646214968897,"mc":[{"id":"1.195453622","rc":[{"atl":[[2.84,0]],"id":36463352},{"atb":[[2.4,0]],"id":40846831}],"con":true,"img":false}]}
{"op":"mcm","clk":"5348174045","pt":1646214968999,"mc":[{"id":"1.195453622","rc":[{"atl":[[2.92,32.28]],"id":36463352},{"atb":[[2.26,43.57]],"id":40846831}],"con":true,"img":false}]}
{"op":"mcm","clk":"5348174645","pt":1646214978136,"mc":[{"id":"1.195453622","rc":[{"atl":[[23,0],[26,0]],"id":40250501}],"con":true,"img":false}]}
{"op":"mcm","clk":"5348174654","pt":1646214978238,"mc":[{"id":"1.195453622","rc":[{"atl":[[27,2.72],[29,2.72]],"id":40250501}],"con":true,"img":false}]}
{"op":"mcm","clk":"5348175500","pt":1646214992564,"mc":[{"id":"1.195453622","rc":[{"atl":[[2.4,0]],"id":41308374}],"con":true,"img":false}]}
{"op":"mcm","clk":"5348175507","pt":1646214992664,"mc":[{"id":"1.195453622","rc":[{"atl":[[2.36,31.14]],"id":41308374}],"con":true,"img":false}]}
{"op":"mcm","clk":"5348175518","pt":1646214992768,"mc":[{"id":"1.195453622","rc":[{"atl":[[2.42,62.28],[2.38,0]],"id":41308374}],"con":true,"img":false}]}
{"op":"mcm","clk":"5348175525","pt":1646214992871,"mc":[{"id":"1.195453622","rc":[{"atl":[[2.42,0],[2.34,31.14]],"id":41308374}],"con":true,"img":false}]}
{"op":"mcm","clk":"5348176008","pt":1646215000578,"mc":[{"id":"1.195453622","rc":[{"atb":[[4.2,31.25]],"id":23806261},{"atb":[[4,33.33],[4.1,0]],"id":40250501}],"con":true,"img":false}]}
{"op":"mcm","clk":"5348176022","pt":1646215000681,"mc":[{"id":"1.195453622","rc":[{"atb":[[4.3,30.24]],"id":23806261}],"con":true,"img":false}]}
{"op":"mcm","clk":"5348177382","pt":1646215019769,"mc":[{"id":"1.195453622","rc":[{"atl":[[18,0],[19.5,3.16]],"id":6780934}],"con":true,"img":false}]}
{"op":"mcm","clk":"5348177478","pt":1646215021229,"mc":[{"id":"1.195453622","rc":[{"atb":[[5.1,12.2],[5.3,4.65],[4.9,19.23],[4.7,33.78]],"id":23806261},{"atl":[[32,3.34],[36,1.43],[40,1.92],[44,2.91]],"id":23806261},{"atb":[[3.85,7.02],[3.55,49.02],[3.65,65.96],[3.75,18.18]],"id":40250501},{"atl":[[32,1],[36,1.43],[40,1.92],[44,2.91]],"id":40250501},{"atb":[[1.37,135.14],[1.33,250],[1.39,51.28],[1.35,214.29]],"id":36463352},{"atl":[[2.02,19.61],[2.06,47.17],[2.1,68.18],[2.14,109.65]],"id":36463352},{"atb":[[2.9,65.79],[2.98,25.25],[2.94,90.11],[3.05,11.42]],"id":40846831},{"atl":[[11.5,11.42],[12.5,4.35],[13.5,6],[14.5,9.26]],"id":40846831},{"atb":[[5.1,12.2],[5.3,4.65],[4.9,19.23],[4.7,35.44]],"id":40199925},{"atl":[[12.5,1.74],[13.5,4],[14.5,5.56],[15.5,8.62]],"id":40199925},{"atb":[[2.9,65.79],[2.98,25.25],[2.94,90.11],[3.05,13.82]],"id":6780934},{"atl":[[10.5,5.26],[11.5,7.14],[9.8,2.27],[12.5,10.87]],"id":6780934}],"con":true,"img":false}]}
{"op":"mcm","clk":"5348177486","pt":1646215021328,"mc":[{"id":"1.195453622","rc":[{"atb":[[1.28,178.57],[1.26,250],[1.3,119.51],[1.24,250]],"id":41308374},{"atl":[[1.8,93.75],[1.82,152.44],[1.78,64.1],[1.76,26.32]],"id":41308374}],"con":true,"img":false}]}
{"op":"mcm","clk":"5348177495","pt":1646215021431,"mc":[{"id":"1.195453622","rc":[{"atb":[[3.9,0]],"id":40250501},{"atl":[[9.8,4.35]],"id":40846831},{"atb":[[2.52,38.45],[2.96,0]],"id":6780934}],"con":true,"img":false}]}
{"op":"mcm","clk":"5348177503","pt":1646215021486,"mc":[{"id":"1.195453622","rc":[{"atb":[[4.1,20.43]],"id":40250501},{"atl":[[1.91,31.14],[2.34,0]],"id":41308374},{"atl":[[11,5.48]],"id":40846831}],"con":true,"img":false}]}
{"op":"mcm","clk":"5348177576","pt":1646215022312,"mc":[{"id":"1.195453622","rc":[{"atb":[[4.4,29.41],[4.2,0]],"id":23806261},{"atb":[[4,0],[4.2,31.25]],"id":40250501},{"atb":[[4.5,28.51],[4.7,62.47]],"id":40199925}],"con":true,"img":false}]}
{"op":"mcm","clk":"5348177653","pt":1646215023196,"mc":[{"id":"1.195453622","rc":[{"atb":[[4.6,0]],"id":23806261},{"atb":[[4.7,60.81]],"id":40199925}],"con":true,"img":false}]}
{"op":"mcm","clk":"5348177676","pt":1646215023404,"mc":[{"id":"1.195453622","rc":[{"atb":[[5.4,1.66]],"id":23806261},{"atl":[[25,0]],"id":23806261},{"atb":[[4.1,0]],"id":40250501},{"atb":[[5.4,1.66]],"id":40199925}],"con":true,"img":false}]}
{"op":"mcm","clk":"5348177683","pt":1646215023505,"mc":[{"id":"1.195453622","rc":[{"atl":[[27,2.72]],"id":23806261},{"atb":[[3.75,38.61]],"id":40250501}],"con":true,"img":false}]}
{"op":"mcm","clk":"5348177728","pt":1646215024123,"mc":[{"id":"1.195453622","rc":[{"atb":[[1.34,24.51]],"id":36463352},{"atb":[[1.3,94.45]],"id":41308374},{"atb":[[3,4.16]],"id":40846831}],"con":true,"img":false}]}
{"op":"mcm","clk":"5348177737","pt":1646215024331,"mc":[{"id":"1.195453622","rc":[{"atl":[[32,2.34],[36,0],[150,1]],"id":23806261},{"atl":[[32,0],[9.6,2.33],[34,0],[24,4.35]],"id":40250501},{"atl":[[2.72,0],[2.46,68.49]],"id":36463352},{"atl":[[1.8,0],[1.82,0],[1.78,0],[1.91,0],[2.1,109.09],[1.76,0]],"id":41308374},{"atl":[[11.5,9.52],[12.5,0],[14,1.54]],"id":40846831},{"atl":[[12.5,0],[14,1.54]],"id":40199925},{"atl":[[22,4.76]],"id":6780934}],"con":true,"img":false}]}
{"op":"mcm","clk":"5348177747","pt":1646215024385,"mc":[{"id":"1.195453622","rc":[{"atl":[[29,0]],"id":6780934}],"con":true,"img":false}]}
{"op":"mcm","clk":"5348177789","pt":1646215024899,"mc":[{"id":"1.195453622","rc":[{"atl":[[40,0]],"id":23806261},{"atl":[[13.5,0]],"id":40199925},{"atl":[[13.5,0]],"id":40846831}],"con":true,"img":false}]}
{"op":"mcm","clk":"5348177856","pt":1646215026033,"mc":[{"id":"1.195453622","rc":[{"atl":[[44,0]],"id":23806261},{"spn":10.45,"spf":"NaN","id":23806261},{"spn":7.0,"spf":"NaN","id":40250501},{"spn":1.39,"spf":1.0,"id":36463352},{"spn":1.7,"spf":"NaN","id":41308374},{"spn":9.7,"spf":"NaN","id":40199925}],"con":true,"img":false}]}
{"op":"mcm","clk":"5348177936","pt":1646215027527,"mc":[{"id":"1.195453622","rc":[{"atb":[[3.85,42.11],[4.2,0]],"id":40250501},{"atb":[[4.3,30.3],[4.7,33.78]],"id":40199925}],"con":true,"img":false}]}
{"op":"mcm","clk":"5348178062","pt":1646215029437,"mc":[{"id":"1.195453622","rc":[{"atl":[[2.1,18.18],[2.34,74.63]],"id":41308374},{"atb":[[3.3,0]],"id":6780934}],"con":true,"img":false}]}
{"op":"mcm","clk":"5348178068","pt":1646215029490,"mc":[{"id":"1.195453622","rc":[{"atb":[[2.96,22.01]],"id":6780934}],"con":true,"img":false}]}
{"op":"mcm","clk":"5348178104","pt":1646215030115,"mc":[{"id":"1.195453622","rc":[{"atb":[[1.4,18.79]],"id":36463352},{"atb":[[1.33,22.78]],"id":41308374},{"atb":[[3.05,15.09]],"id":40846831},{"atb":[[3.4,0]],"id":6780934}],"con":true,"img":false}]}
{"op":"mcm","clk":"5348178190","pt":1646215031399,"mc":[{"id":"1.195453622","rc":[{"atb":[[3.75,18.18]],"id":40250501}],"con":true,"img":false}]}
{"op":"mcm","clk":"5348178197","pt":1646215031502,"mc":[{"id":"1.195453622","rc":[{"atb":[[3.7,20.43]],"id":40250501}],"con":true,"img":false}]}
{"op":"mcm","clk":"5348178332","pt":1646215033412,"mc":[{"id":"1.195453622","rc":[{"atb":[[4.4,1.66]],"id":40250501}],"con":true,"img":false}]}
{"op":"mcm","clk":"5348178338","pt":1646215033514,"mc":[{"id":"1.195453622","rc":[{"atb":[[3.9,14.78]],"id":40250501},{"atb":[[1.3,66.67]],"id":41308374},{"atb":[[3.05,9.76]],"id":6780934}],"con":true,"img":false}]}
{"op":"mcm","clk":"5348178387","pt":1646215034341,"mc":[{"id":"1.195453622","rc":[{"atl":[[170,1]],"id":23806261},{"atl":[[10,5.56]],"id":40250501},{"atl":[[2.14,43.86]],"id":41308374},{"atl":[[15,8.75]],"id":40846831},{"atl":[[15,3.57]],"id":40199925}],"con":true,"img":false}]}
{"op":"mcm","clk":"5348178454","pt":1646215035129,"mc":[{"id":"1.195453622","rc":[{"atl":[[36,0],[40,0],[44,0]],"id":40250501}],"con":true,"img":false}]}
{"op":"mcm","clk":"5348178521","pt":1646215036215,"mc":[{"id":"1.195453622","rc":[{"atb":[[4.4,0]],"id":40250501}],"con":true,"img":false}]}
{"op":"mcm","clk":"5348178528","pt":1646215036318,"mc":[{"id":"1.195453622","rc":[{"atb":[[3.95,1.66]],"id":40250501}],"con":true,"img":false}]}
{"op":"mcm","clk":"5348178584","pt":1646215037454,"mc":[{"id":"1.195453622","rc":[{"atb":[[3.2,25.08],[3.7,0]],"id":40250501}],"con":true,"img":false}]}
{"op":"mcm","clk":"5348178618","pt":1646215038135,"mc":[{"id":"1.195453622","rc":[{"atb":[[3.05,13.42]],"id":6780934}],"con":true,"img":false}]}
{"op":"mcm","clk":"5348178801","pt":1646215041445,"mc":[{"id":"1.195453622","rc":[{"atl":[[16.5,0],[10.5,9.84]],"id":6780934}],"con":true,"img":false}]}
{"op":"mcm","clk":"5348178927","pt":1646215043461,"mc":[{"id":"1.195453622","rc":[{"atb":[[4.5,0]],"id":23806261},{"atl":[[27,0]],"id":40250501},{"atb":[[1.31,0]],"id":36463352},{"atb":[[1.27,0]],"id":41308374},{"atl":[[21,2.72]],"id":40199925}],"con":true,"img":false}]}
{"op":"mcm","clk":"5348178932","pt":1646215043513,"mc":[{"id":"1.195453622","rc":[{"atb":[[5.1,22.58]],"id":23806261},{"atl":[[13,2.72]],"id":40250501},{"atb":[[1.38,86.07]],"id":36463352},{"atb":[[1.29,86.73]],"id":41308374},{"atl":[[15,6.29]],"id":40199925}],"con":true,"img":false}]}
{"op":"mcm","clk":"5348178965","pt":1646215044130,"mc":[{"id":"1.195453622","rc":[{"atb":[[1.4,0]],"id":36463352}],"con":true,"img":false}]}
{"op":"mcm","clk":"5348178980","pt":1646215044339,"mc":[{"id":"1.195453622","rc":[{"atl":[[190,1]],"id":23806261},{"atl":[[11,7.5]],"id":40250501},{"atl":[[2.18,63.56]],"id":41308374},{"atl":[[16,7.41]],"id":40199925},{"atl":[[16,5]],"id":40846831}],"con":true,"img":false}]}
{"op":"mcm","clk":"5348179048","pt":1646215045421,"mc":[{"id":"1.195453622","rc":[{"atl":[[2.04,41.92],[2.7,0]],"id":36463352},{"atb":[[4.6,0]],"id":40199925}],"con":true,"img":false}]}
{"op":"mcm","clk":"5348179054","pt":1646215045524,"mc":[{"id":"1.195453622","rc":[{"atb":[[5,13.21]],"id":40199925}],"con":true,"img":false}]}
{"op":"mcm","clk":"5348179072","pt":1646215045832,"mc":[{"id":"1.195453622","rc":[{"atl":[[2.46,0],[2.7,58.82]],"id":36463352},{"atl":[[14.5,0],[15.5,0]],"id":40199925}],"con":true,"img":false}]}
{"op":"mcm","clk":"5348179170","pt":1646215047334,"mc":[{"id":"1.195453622","rc":[{"atl":[[2.36,0]],"id":41308374}],"con":true,"img":false}]}
{"op":"mcm","clk":"5348179178","pt":1646215047434,"mc":[{"id":"1.195453622","rc":[{"atl":[[2.12,31.14]],"id":41308374}],"con":true,"img":false}]}
{"op":"mcm","clk":"5348179242","pt":1646215048421,"mc":[{"id":"1.195453622","rc":[{"atl":[[2.1,49.32],[2.34,0]],"id":41308374}],"con":true,"img":false}]}
{"op":"mcm","clk":"5348179268","pt":1646215048833,"mc":[{"id":"1.195453622","rc":[{"atb":[[1.34,0]],"id":36463352}],"con":true,"img":false}]}
{"op":"mcm","clk":"5348179279","pt":1646215048936,"mc":[{"id":"1.195453622","rc":[{"atb":[[3,4.16]],"id":6780934}],"con":true,"img":false}]}
{"op":"mcm","clk":"5348179290","pt":1646215049139,"mc":[{"id":"1.195453622","rc":[{"atb":[[1.33,48.04]],"id":41308374}],"con":true,"img":false}]}
{"op":"mcm","clk":"5348179352","pt":1646215050069,"mc":[{"id":"1.195453622","rc":[{"atb":[[1.41,18.33]],"id":36463352}],"con":true,"img":false}]}
{"op":"mcm","clk":"5348179445","pt":1646215051465,"mc":[{"id":"1.195453622","rc":[{"atb":[[2.96,0]],"id":6780934}],"con":true,"img":false}]}
{"op":"mcm","clk":"5348179455","pt":1646215051567,"mc":[{"id":"1.195453622","rc":[{"atb":[[3,26.18]],"id":6780934}],"con":true,"img":false}]}
{"op":"mcm","clk":"5348179565","pt":1646215053173,"mc":[{"id":"1.195453622","rc":[{"atl":[[2.44,69.44],[2.7,0]],"id":36463352}],"con":true,"img":false}]}
{"op":"mcm","clk":"5348179572","pt":1646215053381,"mc":[{"id":"1.195453622","rc":[{"atl":[[15,3.57]],"id":40199925}],"con":true,"img":false}]}
{"op":"mcm","clk":"5348179578","pt":1646215053434,"mc":[{"id":"1.195453622","rc":[{"atl":[[15.5,2.72]],"id":40199925}],"con":true,"img":false}]}
{"op":"mcm","clk":"5348179634","pt":1646215054366,"mc":[{"id":"1.195453622","rc":[{"atl":[[210,1]],"id":23806261},{"atl":[[12,11.36]],"id":40250501},{"atl":[[2.22,102.46]],"id":41308374},{"atl":[[17,7.81]],"id":40199925},{"atl":[[17,7.81]],"id":40846831}],"con":true,"img":false}]}
{"op":"mcm","clk":"5348179753","pt":1646215055966,"mc":[{"id":"1.195453622","rc":[{"atl":[[14.5,0]],"id":40846831}],"con":true,"img":false}]}
{"op":"mcm","clk":"5348180055","pt":1646215061451,"mc":[{"id":"1.195453622","rc":[{"atb":[[1.27,214.46],[1.22,0]],"id":41308374}],"con":true,"img":false}]}
{"op":"mcm","clk":"5348180069","pt":1646215061658,"mc":[{"id":"1.195453622","rc":[{"atl":[[2.92,0]],"id":36463352}],"con":true,"img":false}]}
{"op":"mcm","clk":"5348180073","pt":1646215061762,"mc":[{"id":"1.195453622","rc":[{"atl":[[2.72,32.28]],"id":36463352}],"con":true,"img":false}]}
{"op":"mcm","clk":"5348180167","pt":1646215063357,"mc":[{"id":"1.195453622","rc":[{"atb":[[2.52,36.12],[2.26,0]],"id":40846831},{"atl":[[19.5,0],[9.8,8.91]],"id":6780934}],"con":true,"img":false}]}
{"op":"mcm","clk":"5348180177","pt":1646215063564,"mc":[{"id":"1.195453622","rc":[{"atl":[[9.8,2.27]],"id":6780934}],"con":true,"img":false}]}
{"op":"mcm","clk":"5348180183","pt":1646215063668,"mc":[{"id":"1.195453622","rc":[{"atl":[[10,14.7]],"id":6780934}],"con":true,"img":false}]}
{"op":"mcm","clk":"5348180242","pt":1646215064643,"mc":[{"id":"1.195453622","rc":[{"atb":[[1.41,38.67]],"id":36463352}],"con":true,"img":false}]}
{"op":"mcm","clk":"5348180268","pt":1646215065362,"mc":[{"id":"1.195453622","rc":[{"atl":[[14,4.24]],"id":40250501}],"con":true,"img":false}]}
{"op":"mcm","clk":"5348180272","pt":1646215065463,"mc":[{"id":"1.195453622","rc":[{"atl":[[29,0]],"id":40250501},{"atl":[[10,8.06]],"id":6780934}],"con":true,"img":false}]}
{"op":"mcm","clk":"5348180279","pt":1646215065569,"mc":[{"id":"1.195453622","rc":[{"atl":[[11,6.64]],"id":6780934}],"con":true,"img":false}]}
{"op":"mcm","clk":"5348180376","pt":1646215067373,"mc":[{"id":"1.195453622","rc":[{"atb":[[5,14.33]],"id":23806261},{"atb":[[3.8,0]],"id":40199925}],"con":true,"img":false}]}
{"op":"mcm","clk":"5348180383","pt":1646215067467,"mc":[{"id":"1.195453622","rc":[{"atb":[[3.95,0]],"id":23806261},{"atb":[[4.4,19.64]],"id":40199925}],"con":true,"img":false}]}
{"op":"mcm","clk":"5348180482","pt":1646215069376,"mc":[{"id":"1.195453622","rc":[{"atl":[[2.12,0]],"id":41308374}],"con":true,"img":false}]}
{"op":"mcm","clk":"5348180490","pt":1646215069489,"mc":[{"id":"1.195453622","rc":[{"atl":[[2.18,148.31],[2.08,31.14]],"id":41308374}],"con":true,"img":false}]}
{"op":"mcm","clk":"5348180494","pt":1646215069584,"mc":[{"id":"1.195453622","rc":[{"atl":[[2.1,18.18]],"id":41308374}],"con":true,"img":false}]}
{"op":"mcm","clk":"5348180687","pt":1646215073457,"mc":[{"id":"1.195453622","rc":[{"atb":[[1.26,0]],"id":36463352}],"con":true,"img":false}]}
{"op":"mcm","clk":"5348180692","pt":1646215073560,"mc":[{"id":"1.195453622","rc":[{"atb":[[1.31,238.43]],"id":36463352}],"con":true,"img":false}]}
{"op":"mcm","clk":"5348180768","pt":1646215075410,"mc":[{"id":"1.195453622","rc":[{"atl":[[11.5,4.15],[13,0]],"id":40250501}],"con":true,"img":false}]}
{"op":"mcm","clk":"5348180888","pt":1646215077371,"mc":[{"id":"1.195453622","rc":[{"atl":[[2.08,0]],"id":41308374}],"con":true,"img":false}]}
{"op":"mcm","clk":"5348180893","pt":1646215077475,"mc":[{"id":"1.195453622","rc":[{"atl":[[2.12,31.14]],"id":41308374}],"con":true,"img":false}]}
{"op":"mcm","clk":"5348180982","pt":1646215079380,"mc":[{"id":"1.195453622","rc":[{"atb":[[2.52,0]],"id":6780934}],"con":true,"img":false}]}
{"op":"mcm","clk":"5348180988","pt":1646215079484,"mc":[{"id":"1.195453622","rc":[{"atb":[[2.76,38.45]],"id":6780934}],"con":true,"img":false}]}
{"op":"mcm","clk":"5348181496","pt":1646215088105,"mc":[{"id":"1.195453622","rc":[{"spn":6.77,"spf":"NaN","id":40250501},{"spn":1.41,"spf":1.0,"id":36463352},{"atl":[[2.1,49.32]],"id":41308374},{"spn":1.71,"spf":"NaN","id":41308374}],"con":true,"img":false}]}
{"op":"mcm","clk":"5348181501","pt":1646215088210,"mc":[{"id":"1.195453622","rc":[{"atl":[[2.18,63.56]],"id":41308374}],"con":true,"img":false}]}
{"op":"mcm","clk":"5348182635","pt":1646215107450,"mc":[{"id":"1.195453622","rc":[{"atl":[[11,0]],"id":6780934}],"con":true,"img":false}]}
{"op":"mcm","clk":"5348182642","pt":1646215107553,"mc":[{"id":"1.195453622","rc":[{"atl":[[9.8,8.91]],"id":6780934}],"con":true,"img":false}]}
{"op":"mcm","clk":"5348182778","pt":1646215109462,"mc":[{"id":"1.195453622","rc":[{"atl":[[2.12,0]],"id":41308374},{"atl":[[9.8,2.27]],"id":6780934}],"con":true,"img":false}]}
{"op":"mcm","clk":"5348182786","pt":1646215109566,"mc":[{"id":"1.195453622","rc":[{"atl":[[2.08,31.14]],"id":41308374},{"atl":[[10,14.7]],"id":6780934}],"con":true,"img":false}]}
{"op":"mcm","clk":"5348182794","pt":1646215109624,"mc":[{"id":"1.195453622","rc":[{"atl":[[2.18,148.31],[2.1,18.18]],"id":41308374}],"con":true,"img":false}]}
{"op":"mcm","clk":"5348182802","pt":1646215109775,"mc":[{"id":"1.195453622","rc":[{"atl":[[2.1,80.46]],"id":41308374}],"con":true,"img":false}]}
{"op":"mcm","clk":"5348182805","pt":1646215109831,"mc":[{"id":"1.195453622","rc":[{"atl":[[2.18,63.56]],"id":41308374}],"con":true,"img":false}]}
{"op":"mcm","clk":"5348183539","pt":1646215121977,"mc":[{"id":"1.195453622","rc":[{"atb":[[1.31,0]],"id":36463352}],"con":true,"img":false}]}
{"op":"mcm","clk":"5348183544","pt":1646215122036,"mc":[{"id":"1.195453622","rc":[{"atb":[[1.26,238.43]],"id":36463352}],"con":true,"img":false}]}
{"op":"mcm","clk":"5348184023","pt":1646215129485,"mc":[{"id":"1.195453622","rc":[{"atb":[[1.38,0]],"id":36463352}],"con":true,"img":false}]}
{"op":"mcm","clk":"5348184030","pt":1646215129589,"mc":[{"id":"1.195453622","rc":[{"atb":[[1.31,86.07]],"id":36463352}],"con":true,"img":false}]}
{"op":"mcm","clk":"5348184210","pt":1646215131457,"mc":[{"id":"1.195453622","rc":[{"atb":[[1.41,20.33]],"id":36463352}],"con":true,"img":false}]}
{"op":"mcm","clk":"5348184541","pt":1646215137485,"mc":[{"id":"1.195453622","rc":[{"atb":[[1.4,18.79]],"id":36463352}],"con":true,"img":false}]}
{"op":"mcm","clk":"5348184790","pt":1646215141378,"mc":[{"id":"1.195453622","rc":[{"atb":[[1.29,0]],"id":41308374},{"atb":[[2.96,0]],"id":40846831}],"con":true,"img":false}]}
{"op":"mcm","clk":"5348184801","pt":1646215141483,"mc":[{"id":"1.195453622","rc":[{"atb":[[1.31,86.73]],"id":41308374},{"atb":[[3,26.41]],"id":40846831}],"con":true,"img":false}]}
{"op":"mcm","clk":"5348184944","pt":1646215143606,"mc":[{"id":"1.195453622","rc":[{"atb":[[1.33,25.25]],"id":41308374}],"con":true,"img":false}]}
{"op":"mcm","clk":"5348184955","pt":1646215143872,"mc":[{"id":"1.195453622","rc":[{"atb":[[1.41,0]],"id":36463352}],"con":true,"img":false}]}
{"op":"mcm","clk":"5348185336","pt":1646215149404,"mc":[{"id":"1.195453622","rc":[{"spn":1.4,"spf":1.0,"id":36463352},{"spn":1.7,"spf":"NaN","id":41308374},{"atl":[[10,8.06]],"id":6780934}],"con":true,"img":false}]}
{"op":"mcm","clk":"5348185344","pt":1646215149506,"mc":[{"id":"1.195453622","rc":[{"atb":[[1.34,22.11]],"id":41308374},{"atl":[[9.8,8.91]],"id":6780934}],"con":true,"img":false}]}
{"op":"mcm","clk":"5348185447","pt":1646215151781,"mc":[{"id":"1.195453622","rc":[{"atl":[[8,0]],"id":6780934},{"trd":[[8,10.36]],"ltp":8.0,"tv":10.36,"id":6780934}],"con":true,"img":false}]}
{"op":"mcm","clk":"5348185812","pt":1646215157906,"mc":[{"id":"1.195453622","rc":[{"atb":[[1.4,39.63]],"id":36463352}],"con":true,"img":false}]}
{"op":"mcm","clk":"5348185823","pt":1646215158146,"mc":[{"id":"1.195453622","rc":[{"atb":[[1.33,0]],"id":41308374}],"con":true,"img":false}]}
{"op":"mcm","clk":"5348186419","pt":1646215165439,"mc":[{"id":"1.195453622","rc":[{"atb":[[2.52,0]],"id":40846831}],"con":true,"img":false}]}
{"op":"mcm","clk":"5348186436","pt":1646215165640,"mc":[{"id":"1.195453622","rc":[{"atb":[[2.76,36.12]],"id":40846831}],"con":true,"img":false}]}
{"op":"mcm","clk":"5348186858","pt":1646215171135,"mc":[{"id":"1.195453622","rc":[{"atb":[[1.34,46.62]],"id":41308374}],"con":true,"img":false}]}
{"op":"mcm","clk":"5348187140","pt":1646215175449,"mc":[{"id":"1.195453622","rc":[{"atl":[[10.5,5.26]],"id":6780934}],"con":true,"img":false}]}
{"op":"mcm","clk":"5348187147","pt":1646215175550,"mc":[{"id":"1.195453622","rc":[{"atl":[[9.8,13.5]],"id":6780934}],"con":true,"img":false}]}
{"op":"mcm","clk":"5348187717","pt":1646215185371,"mc":[{"id":"1.195453622","rc":[{"atb":[[5.1,12.2]],"id":23806261}],"con":true,"img":false}]}
{"op":"mcm","clk":"5348187721","pt":1646215185457,"mc":[{"id":"1.195453622","rc":[{"atb":[[5.2,10.38]],"id":23806261}],"con":true,"img":false}]}
{"op":"mcm","clk":"5348205119","pt":1646215422079,"mc":[{"id":"1.195453622","rc":[{"spn":1.71,"spf":"NaN","id":41308374},{"atb":[[2.76,0]],"id":40846831},{"spn":6.67,"spf":"NaN","id":6780934}],"con":true,"img":false}]}
{"op":"mcm","clk":"5348205125","pt":1646215422178,"mc":[{"id":"1.195453622","rc":[{"atb":[[2.52,36.12]],"id":40846831}],"con":true,"img":false}]}
{"op":"mcm","clk":"5348205681","pt":1646215429467,"mc":[{"id":"1.195453622","rc":[{"atb":[[1.31,0]],"id":41308374},{"atb":[[3,4.16]],"id":40846831}],"con":true,"img":false}]}
{"op":"mcm","clk":"5348205686","pt":1646215429570,"mc":[{"id":"1.195453622","rc":[{"atb":[[1.29,86.73]],"id":41308374},{"atb":[[2.96,22.24]],"id":40846831}],"con":true,"img":false}]}
{"op":"mcm","clk":"5348205906","pt":1646215432505,"mc":[{"id":"1.195453622","rc":[{"atb":[[1.34,24.51]],"id":41308374}],"con":true,"img":false}]}
{"op":"mcm","clk":"5348206443","pt":1646215438824,"mc":[{"id":"1.195453622","rc":[{"atb":[[1.33,22.78]],"id":41308374}],"con":true,"img":false}]}
{"op":"mcm","clk":"5348206825","pt":1646215443422,"mc":[{"id":"1.195453622","rc":[{"atb":[[1.31,0]],"id":36463352}],"con":true,"img":false}]}
{"op":"mcm","clk":"5348206834","pt":1646215443525,"mc":[{"id":"1.195453622","rc":[{"atb":[[1.38,86.07]],"id":36463352}],"con":true,"img":false}]}
{"op":"mcm","clk":"5348206883","pt":1646215444202,"mc":[{"id":"1.195453622","rc":[{"atb":[[1.4,20.84]],"id":36463352}],"con":true,"img":false}]}
{"op":"mcm","clk":"5348207404","pt":1646215450417,"mc":[{"id":"1.195453622","rc":[{"atb":[[1.41,18.33]],"id":36463352}],"con":true,"img":false}]}
{"op":"mcm","clk":"5348207467","pt":1646215451234,"mc":[{"id":"1.195453622","rc":[{"atb":[[1.34,0]],"id":41308374}],"con":true,"img":false}]}
{"op":"mcm","clk":"5348207816","pt":1646215455150,"mc":[{"id":"1.195453622","rc":[{"atb":[[4.6,27.78],[4.4,0]],"id":23806261},{"atl":[[9.6,0],[9.4,2.38]],"id":40250501},{"atl":[[2,20],[2.02,0]],"id":36463352},{"atb":[[4.3,0],[4.9,44.87]],"id":40199925},{"atl":[[19.5,5.41],[22,3.45]],"id":40199925}],"con":true,"img":false}]}
{"op":"mcm","clk":"5348207842","pt":1646215455415,"mc":[{"id":"1.195453622","rc":[{"atb":[[4.4,0]],"id":40199925}],"con":true,"img":false}]}
{"op":"mcm","clk":"5348207850","pt":1646215455518,"mc":[{"id":"1.195453622","rc":[{"atb":[[4.1,19.64]],"id":40199925}],"con":true,"img":false}]}
{"op":"mcm","clk":"5348208507","pt":1646215463348,"mc":[{"id":"1.195453622","rc":[{"atb":[[1.4,0]],"id":36463352}],"con":true,"img":false}]}
{"op":"mcm","clk":"5348208517","pt":1646215463454,"mc":[{"id":"1.195453622","rc":[{"atb":[[1.26,0]],"id":36463352}],"con":true,"img":false}]}
{"op":"mcm","clk":"5348208525","pt":1646215463506,"mc":[{"id":"1.195453622","rc":[{"atb":[[1.31,238.43]],"id":36463352}],"con":true,"img":false}]}
{"op":"mcm","clk":"5348208577","pt":1646215464030,"mc":[{"id":"1.195453622","rc":[{"atb":[[1.33,48.04]],"id":41308374}],"con":true,"img":false}]}
{"op":"mcm","clk":"5348209846","pt":1646215479145,"mc":[{"id":"1.195453622","rc":[{"atb":[[1.41,38.67]],"id":36463352}],"con":true,"img":false}]}
{"op":"mcm","clk":"5348210077","pt":1646215481960,"mc":[{"id":"1.195453622","rc":[{"atb":[[1.31,0]],"id":36463352}],"con":true,"img":false}]}
{"op":"mcm","clk":"5348210083","pt":1646215482063,"mc":[{"id":"1.195453622","rc":[{"atb":[[1.26,238.43]],"id":36463352}],"con":true,"img":false}]}
{"op":"mcm","clk":"5348210660","pt":1646215489450,"mc":[{"id":"1.195453622","rc":[{"spn":6.67,"spf":"NaN","id":40250501},{"atb":[[1.38,0]],"id":36463352},{"spn":1.41,"spf":1.0,"id":36463352},{"spn":1.7,"spf":"NaN","id":41308374}],"con":true,"img":false}]}
{"op":"mcm","clk":"5348210667","pt":1646215489554,"mc":[{"id":"1.195453622","rc":[{"atb":[[1.34,86.07]],"id":36463352}],"con":true,"img":false}]}
{"op":"mcm","clk":"5348210920","pt":1646215492567,"mc":[{"id":"1.195453622","rc":[{"atb":[[1.41,20.33]],"id":36463352}],"con":true,"img":false}]}
{"op":"mcm","clk":"5348210997","pt":1646215493449,"mc":[{"id":"1.195453622","rc":[{"atl":[[21,0]],"id":40199925}],"con":true,"img":false}]}
{"op":"mcm","clk":"5348211005","pt":1646215493607,"mc":[{"id":"1.195453622","rc":[{"atl":[[19,2.72]],"id":40199925}],"con":true,"img":false}]}
{"op":"mcm","clk":"5348211411","pt":1646215498550,"mc":[{"id":"1.195453622","rc":[{"atb":[[1.4,18.79]],"id":36463352}],"con":true,"img":false}]}
{"op":"mcm","clk":"5348212245","pt":1646215508870,"mc":[{"id":"1.195453622","rc":[{"atb":[[1.41,0]],"id":36463352}],"con":true,"img":false}]}
{"op":"mcm","clk":"5348213074","pt":1646215519503,"mc":[{"id":"1.195453622","rc":[{"atb":[[1.34,0]],"id":36463352}],"con":true,"img":false}]}
{"op":"mcm","clk":"5348213082","pt":1646215519603,"mc":[{"id":"1.195453622","rc":[{"atb":[[1.31,86.07]],"id":36463352}],"con":true,"img":false}]}
{"op":"mcm","clk":"5348213366","pt":1646215523195,"mc":[{"id":"1.195453622","rc":[{"atb":[[1.4,39.63]],"id":36463352}],"con":true,"img":false}]}
{"op":"mcm","clk":"5348214013","pt":1646215531412,"mc":[{"id":"1.195453622","rc":[{"atb":[[1.29,0]],"id":41308374},{"atb":[[2.96,0]],"id":40846831}],"con":true,"img":false}]}
{"op":"mcm","clk":"5348214017","pt":1646215531515,"mc":[{"id":"1.195453622","rc":[{"atb":[[1.31,86.73]],"id":41308374},{"atb":[[3,26.41]],"id":40846831}],"con":true,"img":false}]}
{"op":"mcm","clk":"5348214125","pt":1646215532822,"mc":[{"id":"1.195453622","rc":[{"atb":[[1.33,25.25]],"id":41308374}],"con":true,"img":false}]}
{"op":"mcm","clk":"5348214158","pt":1646215533235,"mc":[{"id":"1.195453622","rc":[{"atl":[[9.6,2.33],[9.4,0]],"id":40250501},{"atl":[[2,0],[2.02,19.61]],"id":36463352},{"atb":[[4.3,30.3],[4.9,19.23]],"id":40199925}],"con":true,"img":false}]}
{"op":"mcm","clk":"5348214761","pt":1646215540652,"mc":[{"id":"1.195453622","rc":[{"atb":[[1.34,22.11]],"id":41308374}],"con":true,"img":false}]}
{"op":"mcm","clk":"5348216027","pt":1646215554566,"mc":[{"id":"1.195453622","rc":[{"spn":6.77,"spf":"NaN","id":40250501},{"spn":1.4,"spf":1.0,"id":36463352},{"atb":[[1.33,0]],"id":41308374},{"spn":1.71,"spf":"NaN","id":41308374}],"con":true,"img":false}]}
{"op":"mcm","clk":"5348216121","pt":1646215555451,"mc":[{"id":"1.195453622","rc":[{"atb":[[2.52,0]],"id":40846831}],"con":true,"img":false}]}
{"op":"mcm","clk":"5348216130","pt":1646215555556,"mc":[{"id":"1.195453622","rc":[{"atb":[[2.76,36.12]],"id":40846831}],"con":true,"img":false}]}
{"op":"mcm","clk":"5348217416","pt":1646215569067,"mc":[{"id":"1.195453622","rc":[{"atb":[[1.34,46.62]],"id":41308374}],"con":true,"img":false}]}
{"op":"mcm","clk":"5348217779","pt":1646215573371,"mc":[{"id":"1.195453622","rc":[{"atb":[[4.1,0]],"id":40199925}],"con":true,"img":false}]}
{"op":"mcm","clk":"5348217788","pt":1646215573473,"mc":[{"id":"1.195453622","rc":[{"atb":[[4.4,19.64]],"id":40199925}],"con":true,"img":false}]}
{"op":"mcm","clk":"5348220430","pt":1646215602572,"mc":[{"id":"1.195453622","rc":[{"atl":[[9.6,0],[9.8,2.27]],"id":40250501}],"con":true,"img":false}]}
{"op":"mcm","clk":"5348220574","pt":1646215604503,"mc":[{"id":"1.195453622","rc":[{"atl":[[10,2.22],[9.8,0]],"id":40250501},{"atl":[[2.02,0],[2.04,61.15]],"id":36463352}],"con":true,"img":false}]}
{"op":"mcm","clk":"5348221281","pt":1646215612616,"mc":[{"id":"1.195453622","rc":[{"atb":[[5.1,0],[3.85,7.02],[4.6,0],[5.3,0],[4.9,0],[3.65,75.32],[4.7,0]],"id":23806261},{"atl":[[34,0],[150,0],[22,4.76],[12.5,1.74]],"id":23806261},{"atb":[[3.85,7.01],[3.95,16.44]],"id":40250501},{"atb":[[1.37,0],[1.03,250],[1.33,0],[1.39,0],[1.35,0]],"id":36463352},{"atl":[[2.32,90.91],[2.1,0],[2.14,0]],"id":41308374},{"atb":[[4.3,0],[4.7,60.81]],"id":40199925},{"atl":[[18.5,5.71],[19.5,0],[12.5,1.74],[14,0]],"id":40199925},{"atl":[[11.5,0],[14,0],[15.5,8.28]],"id":40846831}],"con":true,"img":false}]}
{"op":"mcm","clk":"5348221354","pt":1646215613296,"mc":[{"id":"1.195453622","rc":[{"atl":[[15,5.18]],"id":40846831}],"con":true,"img":false}]}
{"op":"mcm","clk":"5348221360","pt":1646215613398,"mc":[{"id":"1.195453622","rc":[{"atl":[[2.18,0]],"id":41308374},{"atl":[[11,0]],"id":40846831},{"atb":[[4.4,0]],"id":40199925},{"atl":[[19,0]],"id":40199925}],"con":true,"img":false}]}
{"op":"mcm","clk":"5348221368","pt":1646215613505,"mc":[{"id":"1.195453622","rc":[{"atb":[[4.1,19.64]],"id":40199925},{"atl":[[21,2.72]],"id":40199925},{"atl":[[11.5,5.48]],"id":40846831}],"con":true,"img":false}]}
{"op":"mcm","clk":"5348221444","pt":1646215614498,"mc":[{"id":"1.195453622","rc":[{"atl":[[11,5]],"id":40250501}],"con":true,"img":false}]}
{"op":"mcm","clk":"5348221533","pt":1646215615494,"mc":[{"id":"1.195453622","rc":[{"atb":[[5,0]],"id":23806261},{"spn":8.95,"spf":"NaN","id":23806261},{"spn":6.97,"spf":"NaN","id":40250501},{"spn":8.95,"spf":"NaN","id":40199925}],"con":true,"img":false}]}
{"op":"mcm","clk":"5348221538","pt":1646215615607,"mc":[{"id":"1.195453622","rc":[{"atb":[[4.5,14.33]],"id":23806261},{"atb":[[1.4,20.84]],"id":36463352}],"con":true,"img":false}]}
{"op":"mcm","clk":"5348221755","pt":1646215618411,"mc":[{"id":"1.195453622","rc":[{"atb":[[5.4,0]],"id":23806261}],"con":true,"img":false}]}
{"op":"mcm","clk":"5348221774","pt":1646215618627,"mc":[{"id":"1.195453622","rc":[{"atb":[[5.3,1.66]],"id":23806261}],"con":true,"img":false}]}
{"op":"mcm","clk":"5348221858","pt":1646215619404,"mc":[{"id":"1.195453622","rc":[{"atl":[[2.08,0]],"id":41308374}],"con":true,"img":false}]}
{"op":"mcm","clk":"5348221863","pt":1646215619509,"mc":[{"id":"1.195453622","rc":[{"atl":[[2.2,31.14]],"id":41308374}],"con":true,"img":false}]}
{"op":"mcm","clk":"5348221874","pt":1646215619613,"mc":[{"id":"1.195453622","rc":[{"atl":[[2.32,15.14],[2.42,70.42]],"id":41308374}],"con":true,"img":false}]}
{"op":"mcm","clk":"5348222023","pt":1646215621700,"mc":[{"id":"1.195453622","rc":[{"atb":[[3.75,20.91]],"id":40250501},{"atb":[[1.34,22.11]],"id":36463352}],"con":true,"img":false}]}
{"op":"mcm","clk":"5348222091","pt":1646215622630,"mc":[{"id":"1.195453622","rc":[{"atb":[[3.75,18.18]],"id":23806261},{"atl":[[13.5,4]],"id":23806261},{"atl":[[2.08,46.3]],"id":36463352},{"atl":[[2.36,36.76],[2.22,0]],"id":41308374},{"atl":[[13.5,4]],"id":40199925},{"atl":[[16.5,3.23]],"id":40846831}],"con":true,"img":false}]}
{"op":"mcm","clk":"5348222165","pt":1646215623424,"mc":[{"id":"1.195453622","rc":[{"atl":[[210,0]],"id":23806261},{"atl":[[16,2.41],[17,0],[15,0]],"id":40199925}],"con":true,"img":false}]}
{"op":"mcm","clk":"5348222174","pt":1646215623525,"mc":[{"id":"1.195453622","rc":[{"atl":[[2.06,0],[2.1,0],[2.14,0]],"id":36463352}],"con":true,"img":false}]}
{"op":"mcm","clk":"5348222260","pt":1646215624526,"mc":[{"id":"1.195453622","rc":[{"atl":[[12,6.82]],"id":40250501}],"con":true,"img":false}]}
{"op":"mcm","clk":"5348222601","pt":1646215629017,"mc":[{"id":"1.195453622","rc":[{"atb":[[1.4,0]],"id":36463352}],"con":true,"img":false}]}
{"op":"mcm","clk":"5348222611","pt":1646215629126,"mc":[{"id":"1.195453622","rc":[{"atl":[[2.2,0]],"id":41308374}],"con":true,"img":false}]}
{"op":"mcm","clk":"5348222617","pt":1646215629224,"mc":[{"id":"1.195453622","rc":[{"atb":[[3.75,23.95]],"id":40250501},{"atl":[[2.34,31.14]],"id":41308374}],"con":true,"img":false}]}
{"op":"mcm","clk":"5348222755","pt":1646215630837,"mc":[{"id":"1.195453622","rc":[{"atb":[[3.75,21.21]],"id":40250501},{"atl":[[2.44,0],[2.76,56.82]],"id":36463352}],"con":true,"img":false}]}
{"op":"mcm","clk":"5348222805","pt":1646215631418,"mc":[{"id":"1.195453622","rc":[{"atl":[[2.04,19.23]],"id":36463352},{"atl":[[15.5,0]],"id":40199925}],"con":true,"img":false}]}
{"op":"mcm","clk":"5348222813","pt":1646215631515,"mc":[{"id":"1.195453622","rc":[{"atl":[[2.06,41.92]],"id":36463352},{"atl":[[18,2.72]],"id":40199925}],"con":true,"img":false}]}
{"op":"mcm","clk":"5348222900","pt":1646215632617,"mc":[{"id":"1.195453622","rc":[{"atb":[[3.65,103.62]],"id":23806261},{"atl":[[14.5,5.56]],"id":23806261},{"atl":[[2.12,66.96]],"id":36463352},{"atl":[[2.4,53.57]],"id":41308374},{"atl":[[14.5,5.56]],"id":40199925},{"atl":[[17.5,4.55]],"id":40846831}],"con":true,"img":false}]}
{"op":"mcm","clk":"5348222905","pt":1646215632721,"mc":[{"id":"1.195453622","rc":[{"atl":[[2.32,46.28],[2.42,0]],"id":41308374}],"con":true,"img":false}]}
{"op":"mcm","clk":"5348222954","pt":1646215633442,"mc":[{"id":"1.195453622","rc":[{"atb":[[3.9,0]],"id":40250501}],"con":true,"img":false}]}
{"op":"mcm","clk":"5348222962","pt":1646215633545,"mc":[{"id":"1.195453622","rc":[{"atb":[[3.8,14.78]],"id":40250501}],"con":true,"img":false}]}
{"op":"mcm","clk":"5348223004","pt":1646215634025,"mc":[{"id":"1.195453622","rc":[{"atl":[[190,0]],"id":23806261}],"con":true,"img":false}]}
{"op":"mcm","clk":"5348223012","pt":1646215634123,"mc":[{"id":"1.195453622","rc":[{"atl":[[16,0],[17,0]],"id":40846831}],"con":true,"img":false}]}
{"op":"mcm","clk":"5348223042","pt":1646215634539,"mc":[{"id":"1.195453622","rc":[{"atl":[[13,10.42]],"id":40250501}],"con":true,"img":false}]}
{"op":"mcm","clk":"5348223119","pt":1646215635431,"mc":[{"id":"1.195453622","rc":[{"atb":[[4.5,0]],"id":23806261},{"atl":[[24,0]],"id":23806261}],"con":true,"img":false}]}
{"op":"mcm","clk":"5348223127","pt":1646215635536,"mc":[{"id":"1.195453622","rc":[{"atb":[[4.4,14.33]],"id":23806261},{"atl":[[18,2.72]],"id":23806261}],"con":true,"img":false}]}
{"op":"mcm","clk":"5348223616","pt":1646215641440,"mc":[{"id":"1.195453622","rc":[{"atb":[[5.2,0]],"id":23806261}],"con":true,"img":false}]}
{"op":"mcm","clk":"5348223624","pt":1646215641538,"mc":[{"id":"1.195453622","rc":[{"atb":[[4.5,10.38]],"id":23806261}],"con":true,"img":false}]}
{"op":"mcm","clk":"5348223725","pt":1646215642670,"mc":[{"id":"1.195453622","rc":[{"atb":[[3.55,49.02]],"id":23806261},{"atl":[[15.5,11.12]],"id":23806261},{"atl":[[2.16,107.76]],"id":36463352},{"atl":[[2.44,112.01]],"id":41308374},{"atl":[[18.5,7.14]],"id":40846831},{"atl":[[15.5,8.62]],"id":40199925}],"con":true,"img":false}]}
{"op":"mcm","clk":"5348223892","pt":1646215644967,"mc":[{"id":"1.195453622","rc":[{"atl":[[170,0]],"id":23806261}],"con":true,"img":false}]}
{"op":"mcm","clk":"5348223924","pt":1646215645338,"mc":[{"id":"1.195453622","rc":[{"atb":[[5.3,0]],"id":23806261}],"con":true,"img":false}]}
{"op":"mcm","clk":"5348223945","pt":1646215645550,"mc":[{"id":"1.195453622","rc":[{"atb":[[4.6,1.66]],"id":23806261}],"con":true,"img":false}]}
{"op":"mcm","clk":"5348224102","pt":1646215647436,"mc":[{"id":"1.195453622","rc":[{"atb":[[1.31,0]],"id":36463352}],"con":true,"img":false}]}
{"op":"mcm","clk":"5348224110","pt":1646215647541,"mc":[{"id":"1.195453622","rc":[{"atb":[[1.32,86.07]],"id":36463352}],"con":true,"img":false}]}
{"op":"mcm","clk":"5348224210","pt":1646215648755,"mc":[{"id":"1.195453622","rc":[{"atb":[[1.34,0]],"id":36463352}],"con":true,"img":false}]}
{"op":"mcm","clk":"5348224605","pt":1646215653466,"mc":[{"id":"1.195453622","rc":[{"atl":[[2.34,0]],"id":41308374}],"con":true,"img":false}]}
{"op":"mcm","clk":"5348224611","pt":1646215653568,"mc":[{"id":"1.195453622","rc":[{"atl":[[2.3,31.14]],"id":41308374}],"con":true,"img":false}]}
{"op":"mcm","clk":"5348224620","pt":1646215653677,"mc":[{"id":"1.195453622","rc":[{"atl":[[2.4,125],[2.32,15.14]],"id":41308374}],"con":true,"img":false}]}
{"op":"mcm","clk":"5348224738","pt":1646215654776,"mc":[{"id":"1.195453622","rc":[{"atb":[[1.35,21.48]],"id":36463352}],"con":true,"img":false}]}
{"op":"mcm","clk":"5348224809","pt":1646215655464,"mc":[{"id":"1.195453622","rc":[{"atl":[[27,0]],"id":23806261}],"con":true,"img":false}]}
{"op":"mcm","clk":"5348224822","pt":1646215655582,"mc":[{"id":"1.195453622","rc":[{"atl":[[20,2.72]],"id":23806261}],"con":true,"img":false}]}
{"op":"mcm","clk":"5348225004","pt":1646215657472,"mc":[{"id":"1.195453622","rc":[{"atl":[[18,0]],"id":40199925}],"con":true,"img":false}]}
{"op":"mcm","clk":"5348225012","pt":1646215657569,"mc":[{"id":"1.195453622","rc":[{"atl":[[15,2.72]],"id":40199925}],"con":true,"img":false}]}
{"op":"mcm","clk":"5348225141","pt":1646215659470,"mc":[{"id":"1.195453622","rc":[{"atl":[[18,0]],"id":23806261}],"con":true,"img":false}]}
{"op":"mcm","clk":"5348225146","pt":1646215659568,"mc":[{"id":"1.195453622","rc":[{"atl":[[15,2.72]],"id":23806261}],"con":true,"img":false}]}
{"op":"mcm","clk":"5348225329","pt":1646215661464,"mc":[{"id":"1.195453622","rc":[{"atl":[[11.5,0]],"id":40250501},{"atl":[[2.62,0]],"id":41308374}],"con":true,"img":false}]}
{"op":"mcm","clk":"5348225337","pt":1646215661564,"mc":[{"id":"1.195453622","rc":[{"atl":[[12.5,4.15]],"id":40250501},{"atl":[[2.42,35.74]],"id":41308374}],"con":true,"img":false}]}
{"op":"mcm","clk":"5348225411","pt":1646215662349,"mc":[{"id":"1.195453622","rc":[{"atb":[[1.35,45.29]],"id":36463352}],"con":true,"img":false}]}
{"op":"mcm","clk":"5348225798","pt":1646215666471,"mc":[{"id":"1.195453622","rc":[{"atl":[[2.4,53.56],[2.32,77.42]],"id":41308374}],"con":true,"img":false}]}
{"op":"mcm","clk":"5348225881","pt":1646215667366,"mc":[{"id":"1.195453622","rc":[{"atl":[[18,3.29]],"id":40199925}],"con":true,"img":false}]}
{"op":"mcm","clk":"5348225890","pt":1646215667467,"mc":[{"id":"1.195453622","rc":[{"atl":[[21,0]],"id":40199925}],"con":true,"img":false}]}
{"op":"mcm","clk":"5348226075","pt":1646215669456,"mc":[{"id":"1.195453622","rc":[{"atb":[[1.32,0]],"id":36463352}],"con":true,"img":false}]}
{"op":"mcm","clk":"5348226086","pt":1646215669562,"mc":[{"id":"1.195453622","rc":[{"atb":[[1.31,86.07]],"id":36463352}],"con":true,"img":false}]}
{"op":"mcm","clk":"5348226371","pt":1646215672886,"mc":[{"id":"1.195453622","rc":[{"atb":[[1.35,23.81]],"id":36463352}],"con":true,"img":false}]}
{"op":"mcm","clk":"5348226419","pt":1646215673471,"mc":[{"id":"1.195453622","rc":[{"atl":[[2.42,0]],"id":41308374}],"con":true,"img":false}]}
{"op":"mcm","clk":"5348226424","pt":1646215673575,"mc":[{"id":"1.195453622","rc":[{"atl":[[2.62,35.74]],"id":41308374}],"con":true,"img":false}]}
{"op":"mcm","clk":"5348226565","pt":1646215675463,"mc":[{"id":"1.195453622","rc":[{"atl":[[14,0]],"id":40250501}],"con":true,"img":false}]}
{"op":"mcm","clk":"5348226573","pt":1646215675593,"mc":[{"id":"1.195453622","rc":[{"spn":8.55,"spf":"NaN","id":23806261},{"atl":[[12.5,8.39]],"id":40250501},{"spn":1.35,"spf":1.0,"id":36463352},{"spn":1.82,"spf":"NaN","id":41308374}],"con":true,"img":false}]}
{"op":"mcm","clk":"5348226873","pt":1646215678799,"mc":[{"id":"1.195453622","rc":[{"atb":[[1.34,22.11]],"id":36463352}],"con":true,"img":false}]}
{"op":"mcm","clk":"5348227129","pt":1646215681407,"mc":[{"id":"1.195453622","rc":[{"atl":[[9.8,0]],"id":40846831}],"con":true,"img":false}]}
{"op":"mcm","clk":"5348227140","pt":1646215681512,"mc":[{"id":"1.195453622","rc":[{"atl":[[11,4.35]],"id":40846831}],"con":true,"img":false}]}
{"op":"mcm","clk":"5348227446","pt":1646215684785,"mc":[{"id":"1.195453622","rc":[{"atb":[[1.35,0]],"id":36463352}],"con":true,"img":false}]}
{"op":"mcm","clk":"5348227503","pt":1646215685416,"mc":[{"id":"1.195453622","rc":[{"atl":[[12.5,4.24]],"id":40250501}],"con":true,"img":false}]}
{"op":"mcm","clk":"5348227517","pt":1646215685486,"mc":[{"id":"1.195453622","rc":[{"atl":[[11.5,4.15]],"id":40250501}],"con":true,"img":false}]}
{"op":"mcm","clk":"5348227867","pt":1646215689403,"mc":[{"id":"1.195453622","rc":[{"atl":[[15,0]],"id":23806261},{"atl":[[15,0]],"id":40199925}],"con":true,"img":false}]}
{"op":"mcm","clk":"5348227875","pt":1646215689508,"mc":[{"id":"1.195453622","rc":[{"atl":[[14,2.72]],"id":23806261},{"atl":[[14,2.72]],"id":40199925}],"con":true,"img":false}]}
{"op":"mcm","clk":"5348228785","pt":1646215699401,"mc":[{"id":"1.195453622","rc":[{"atl":[[11.5,0]],"id":40846831}],"con":true,"img":false}]}
{"op":"mcm","clk":"5348228792","pt":1646215699510,"mc":[{"id":"1.195453622","rc":[{"atl":[[12,5.48]],"id":40846831}],"con":true,"img":false}]}
{"op":"mcm","clk":"5348228891","pt":1646215700713,"mc":[{"id":"1.195453622","rc":[{"atb":[[1.34,46.62]],"id":36463352}],"con":true,"img":false}]}
{"op":"mcm","clk":"5348230633","pt":1646215720325,"mc":[{"id":"1.195453622","rc":[{"atl":[[10,0],[10.5,5.93]],"id":40250501},{"atl":[[10.5,2.11],[9.8,11.23]],"id":6780934}],"con":true,"img":false}]}
{"op":"mcm","clk":"5348230745","pt":1646215721417,"mc":[{"id":"1.195453622","rc":[{"atl":[[9.8,4.58]],"id":6780934}],"con":true,"img":false}]}
{"op":"mcm","clk":"5348230757","pt":1646215721521,"mc":[{"id":"1.195453622","rc":[{"atl":[[11,6.64]],"id":6780934}],"con":true,"img":false}]}
{"op":"mcm","clk":"5348231554","pt":1646215730256,"mc":[{"id":"1.195453622","rc":[{"atl":[[11.5,11.9]],"id":6780934}],"con":true,"img":false}]}
{"op":"mcm","clk":"5348231561","pt":1646215730357,"mc":[{"id":"1.195453622","rc":[{"atl":[[11.5,8.91]],"id":40250501},{"atl":[[11.5,4.76]],"id":6780934}],"con":true,"img":false}]}
{"op":"mcm","clk":"5348231838","pt":1646215733430,"mc":[{"id":"1.195453622","rc":[{"atb":[[3.95,19.44],[4.4,0]],"id":23806261}],"con":true,"img":false}]}
{"op":"mcm","clk":"5348231887","pt":1646215734159,"mc":[{"id":"1.195453622","rc":[{"atl":[[11,0],[12,0],[13,0]],"id":40250501}],"con":true,"img":false}]}
{"op":"mcm","clk":"5348231990","pt":1646215735458,"mc":[{"id":"1.195453622","rc":[{"atl":[[11.5,4.76],[12.5,0]],"id":40250501}],"con":true,"img":false}]}
{"op":"mcm","clk":"5348231997","pt":1646215735563,"mc":[{"id":"1.195453622","rc":[{"atl":[[13,4.15],[14.5,4.24]],"id":40250501}],"con":true,"img":false}]}
{"op":"mcm","clk":"5348232459","pt":1646215740335,"mc":[{"id":"1.195453622","rc":[{"atl":[[12.5,6.52]],"id":40250501},{"spn":7.22,"spf":"NaN","id":40250501},{"spn":1.34,"spf":1.0,"id":36463352},{"atl":[[12.5,6.52]],"id":6780934}],"con":true,"img":false}]}
{"op":"mcm","clk":"5348232600","pt":1646215741854,"mc":[{"id":"1.195453622","rc":[{"atb":[[1.37,2.16]],"id":36463352},{"atb":[[1.37,2.16]],"id":41308374}],"con":true,"img":false}]}
{"op":"mcm","clk":"5348233343","pt":1646215750372,"mc":[{"id":"1.195453622","rc":[{"atl":[[13.5,10]],"id":40250501},{"atl":[[13.5,10]],"id":6780934}],"con":true,"img":false}]}
{"op":"mcm","clk":"5348234562","pt":1646215763476,"mc":[{"id":"1.195453622","rc":[{"atl":[[13,0]],"id":40250501}],"con":true,"img":false}]}
{"op":"mcm","clk":"5348234573","pt":1646215763579,"mc":[{"id":"1.195453622","rc":[{"atl":[[12,4.15]],"id":40250501}],"con":true,"img":false}]}
{"op":"mcm","clk":"5348234912","pt":1646215767479,"mc":[{"id":"1.195453622","rc":[{"atb":[[3.8,0]],"id":40250501}],"con":true,"img":false}]}
{"op":"mcm","clk":"5348234920","pt":1646215767581,"mc":[{"id":"1.195453622","rc":[{"atb":[[4,14.78]],"id":40250501}],"con":true,"img":false}]}
{"op":"mcm","clk":"5348234939","pt":1646215767741,"mc":[{"id":"1.195453622","rc":[{"atb":[[3.95,1.66],[4.1,14.78]],"id":40250501}],"con":true,"img":false}]}
{"op":"mcm","clk":"5348235189","pt":1646215770351,"mc":[{"id":"1.195453622","rc":[{"atb":[[3.95,0]],"id":40250501}],"con":true,"img":false}]}
{"op":"mcm","clk":"5348235211","pt":1646215770562,"mc":[{"id":"1.195453622","rc":[{"atb":[[4.2,1.66]],"id":40250501}],"con":true,"img":false}]}
{"op":"mcm","clk":"5348236962","pt":1646215789374,"mc":[{"id":"1.195453622","rc":[{"atb":[[4,0]],"id":40250501}],"con":true,"img":false}]}
{"op":"mcm","clk":"5348236971","pt":1646215789477,"mc":[{"id":"1.195453622","rc":[{"atb":[[4.2,16.44]],"id":40250501}],"con":true,"img":false}]}
{"op":"mcm","clk":"5348236987","pt":1646215789685,"mc":[{"id":"1.195453622","rc":[{"atb":[[4.3,14.78],[4.1,0]],"id":40250501}],"con":true,"img":false}]}
{"op":"mcm","clk":"5348237057","pt":1646215790471,"mc":[{"id":"1.195453622","rc":[{"atb":[[4.2,14.78]],"id":40250501}],"con":true,"img":false}]}
{"op":"mcm","clk":"5348237077","pt":1646215790680,"mc":[{"id":"1.195453622","rc":[{"atb":[[4.4,1.66]],"id":40250501}],"con":true,"img":false}]}
{"op":"mcm","clk":"5348237155","pt":1646215791409,"mc":[{"id":"1.195453622","rc":[{"atl":[[14.5,0]],"id":40250501}],"con":true,"img":false}]}
{"op":"mcm","clk":"5348237168","pt":1646215791474,"mc":[{"id":"1.195453622","rc":[{"atl":[[13,4.24]],"id":40250501}],"con":true,"img":false}]}
{"op":"mcm","clk":"5348237208","pt":1646215791883,"mc":[{"id":"1.195453622","rc":[{"atl":[[2.48,67.57],[2.76,0]],"id":36463352}],"con":true,"img":false}]}
{"op":"mcm","clk":"5348237359","pt":1646215793507,"mc":[{"id":"1.195453622","rc":[{"atb":[[5,0]],"id":40199925}],"con":true,"img":false}]}
{"op":"mcm","clk":"5348237373","pt":1646215793583,"mc":[{"id":"1.195453622","rc":[{"atb":[[5.2,13.21]],"id":40199925}],"con":true,"img":false}]}
{"op":"mcm","clk":"5348239302","pt":1646215815472,"mc":[{"id":"1.195453622","rc":[{"atb":[[4.2,0]],"id":40250501},{"spn":7.45,"spf":"NaN","id":40250501},{"atb":[[1.31,0]],"id":36463352},{"spn":1.36,"spf":1.0,"id":36463352},{"spn":1.83,"spf":"NaN","id":41308374}],"con":true,"img":false}]}
{"op":"mcm","clk":"5348239312","pt":1646215815521,"mc":[{"id":"1.195453622","rc":[{"atb":[[4.4,16.44]],"id":40250501},{"atb":[[1.35,86.07]],"id":36463352}],"con":true,"img":false}]}
{"op":"mcm","clk":"5348239390","pt":1646215816421,"mc":[{"id":"1.195453622","rc":[{"atb":[[1.34,24.51]],"id":36463352}],"con":true,"img":false}]}
{"op":"mcm","clk":"5348239915","pt":1646215822604,"mc":[{"id":"1.195453622","rc":[{"atb":[[1.38,19.78]],"id":36463352}],"con":true,"img":false}]}
{"op":"mcm","clk":"5348239986","pt":1646215823430,"mc":[{"id":"1.195453622","rc":[{"atb":[[1.35,0]],"id":36463352}],"con":true,"img":false}]}
{"op":"mcm","clk":"5348239994","pt":1646215823541,"mc":[{"id":"1.195453622","rc":[{"atb":[[1.31,86.07]],"id":36463352}],"con":true,"img":false}]}
{"op":"mcm","clk":"5348240013","pt":1646215823742,"mc":[{"id":"1.195453622","rc":[{"atb":[[1.41,2.16],[1.37,0]],"id":36463352}],"con":true,"img":false}]}
{"op":"mcm","clk":"5348240172","pt":1646215825437,"mc":[{"id":"1.195453622","rc":[{"atb":[[1.38,0]],"id":36463352}],"con":true,"img":false}]}
{"op":"mcm","clk":"5348240739","pt":1646215831440,"mc":[{"id":"1.195453622","rc":[{"atb":[[1.34,46.62]],"id":36463352}],"con":true,"img":false}]}
{"op":"mcm","clk":"5348240930","pt":1646215833439,"mc":[{"id":"1.195453622","rc":[{"atl":[[12,0]],"id":40846831}],"con":true,"img":false}]}
{"op":"mcm","clk":"5348240941","pt":1646215833539,"mc":[{"id":"1.195453622","rc":[{"atl":[[13,5.48]],"id":40846831}],"con":true,"img":false}]}
{"op":"mcm","clk":"5348241938","pt":1646215843446,"mc":[{"id":"1.195453622","rc":[{"atb":[[3,4.16]],"id":6780934}],"con":true,"img":false}]}
{"op":"mcm","clk":"5348241947","pt":1646215843552,"mc":[{"id":"1.195453622","rc":[{"atb":[[3.05,35.44]],"id":6780934}],"con":true,"img":false}]}
{"op":"mcm","clk":"5348242228","pt":1646215846450,"mc":[{"id":"1.195453622","rc":[{"atb":[[3.05,31.77]],"id":6780934}],"con":true,"img":false}]}
{"op":"mcm","clk":"5348242869","pt":1646215852558,"mc":[{"id":"1.195453622","rc":[{"atb":[[3.1,3.57]],"id":6780934}],"con":true,"img":false}]}
{"op":"mcm","clk":"5348242984","pt":1646215853485,"mc":[{"id":"1.195453622","rc":[{"atb":[[3.05,9.76]],"id":6780934}],"con":true,"img":false}]}
{"op":"mcm","clk":"5348242996","pt":1646215853567,"mc":[{"id":"1.195453622","rc":[{"atb":[[3,26.18]],"id":6780934}],"con":true,"img":false}]}
{"op":"mcm","clk":"5348243188","pt":1646215855562,"mc":[{"id":"1.195453622","rc":[{"atb":[[3.1,0]],"id":6780934}],"con":true,"img":false}]}
{"op":"mcm","clk":"5348243613","pt":1646215860145,"mc":[{"id":"1.195453622","rc":[{"atb":[[3,36.41],[3.05,5.33]],"id":40846831}],"con":true,"img":false}]}
{"op":"mcm","clk":"5348243732","pt":1646215861463,"mc":[{"id":"1.195453622","rc":[{"atb":[[3.05,13.42]],"id":6780934}],"con":true,"img":false}]}
{"op":"mcm","clk":"5348244638","pt":1646215870182,"mc":[{"id":"1.195453622","rc":[{"atb":[[2.96,25.51]],"id":40846831}],"con":true,"img":false}]}
{"op":"mcm","clk":"5348245610","pt":1646215880201,"mc":[{"id":"1.195453622","rc":[{"spn":1.39,"spf":1.0,"id":36463352},{"atb":[[2.92,39.06],[2.9,0],[2.98,0],[2.94,51.45]],"id":40846831}],"con":true,"img":false}]}
{"op":"mcm","clk":"5348245928","pt":1646215883404,"mc":[{"id":"1.195453622","rc":[{"atb":[[3,4.16]],"id":6780934}],"con":true,"img":false}]}
{"op":"mcm","clk":"5348245933","pt":1646215883456,"mc":[{"id":"1.195453622","rc":[{"atb":[[3.05,35.44]],"id":6780934}],"con":true,"img":false}]}
{"op":"mcm","clk":"5348246098","pt":1646215885600,"mc":[{"id":"1.195453622","rc":[{"atb":[[3.05,31.77]],"id":6780934}],"con":true,"img":false}]}
{"op":"mcm","clk":"5348246117","pt":1646215885760,"mc":[{"id":"1.195453622","rc":[{"atb":[[3,32.24]],"id":40846831},{"atb":[[3,0]],"id":6780934}],"con":true,"img":false}]}
{"op":"mcm","clk":"5348246275","pt":1646215887373,"mc":[{"id":"1.195453622","rc":[{"atb":[[3,10]],"id":40846831}],"con":true,"img":false}]}
{"op":"mcm","clk":"5348246283","pt":1646215887487,"mc":[{"id":"1.195453622","rc":[{"atb":[[2.98,22.24]],"id":40846831}],"con":true,"img":false}]}
{"op":"mcm","clk":"5348246503","pt":1646215890160,"mc":[{"id":"1.195453622","rc":[{"atb":[[2.88,66.49]],"id":40846831}],"con":true,"img":false}]}
{"op":"mcm","clk":"5348246617","pt":1646215891593,"mc":[{"id":"1.195453622","rc":[{"atb":[[3.1,3.57]],"id":6780934}],"con":true,"img":false}]}
{"op":"mcm","clk":"5348246771","pt":1646215893389,"mc":[{"id":"1.195453622","rc":[{"atb":[[3.05,9.76]],"id":6780934}],"con":true,"img":false}]}
{"op":"mcm","clk":"5348246780","pt":1646215893496,"mc":[{"id":"1.195453622","rc":[{"atb":[[3,22.01]],"id":6780934}],"con":true,"img":false}]}
{"op":"mcm","clk":"5348246990","pt":1646215895585,"mc":[{"id":"1.195453622","rc":[{"atb":[[3.1,0]],"id":6780934}],"con":true,"img":false}]}
{"op":"mcm","clk":"5348247776","pt":1646215903494,"mc":[{"id":"1.195453622","rc":[{"atb":[[3.05,13.42]],"id":6780934}],"con":true,"img":false}]}
{"op":"mcm","clk":"5348248449","pt":1646215910577,"mc":[{"id":"1.195453622","rc":[{"atb":[[3,0],[3.05,15.09]],"id":40846831}],"con":true,"img":false}]}
{"op":"mcm","clk":"5348248979","pt":1646215916395,"mc":[{"id":"1.195453622","rc":[{"atb":[[3,26.18]],"id":6780934}],"con":true,"img":false}]}
{"op":"mcm","clk":"5348249004","pt":1646215916707,"mc":[{"id":"1.195453622","rc":[{"atb":[[3,4.16]],"id":40846831}],"con":true,"img":false}]}
{"op":"mcm","clk":"5348249534","pt":1646215923423,"mc":[{"id":"1.195453622","rc":[{"atl":[[2.02,19.61],[2.04,0]],"id":36463352},{"atl":[[10,10.28],[10.5,0]],"id":6780934}],"con":true,"img":false}]}
{"op":"mcm","clk":"5348249651","pt":1646215924819,"mc":[{"id":"1.195453622","rc":[{"atb":[[1.3,0],[1.29,68.97]],"id":41308374},{"atl":[[2.06,4]],"id":41308374},{"atb":[[3,14.16],[3.05,5.33]],"id":40846831},{"atl":[[15.5,10.28]],"id":40846831}],"con":true,"img":false}]}
{"op":"mcm","clk":"5348249666","pt":1646215925030,"mc":[{"id":"1.195453622","rc":[{"atb":[[1.06,3]],"id":36463352},{"atl":[[15,8.18]],"id":40846831}],"con":true,"img":false}]}
{"op":"mcm","clk":"5348249673","pt":1646215925081,"mc":[{"id":"1.195453622","rc":[{"atl":[[2.04,2]],"id":41308374}],"con":true,"img":false}]}
{"op":"mcm","clk":"5348249949","pt":1646215928303,"mc":[{"id":"1.195453622","rc":[{"atb":[[1.03,0],[1.02,250],[1.06,0],[1.07,4]],"id":36463352},{"atb":[[1.3,66.67],[1.29,0]],"id":41308374},{"atl":[[2.02,3],[2.06,0],[2.04,0]],"id":41308374},{"atb":[[3,4.16],[3.05,15.09]],"id":40846831},{"atl":[[16.5,0],[17,1.25],[14.5,2],[15,5.18],[15.5,6.9]],"id":40846831}],"con":true,"img":false}]}
{"op":"mcm","clk":"5348250029","pt":1646215929299,"mc":[{"id":"1.195453622","rc":[{"atb":[[3.85,0],[3.95,26.22]],"id":23806261},{"atb":[[4.3,0],[4.4,31.22]],"id":40250501},{"atl":[[1.61,3]],"id":36463352},{"atl":[[2.02,0]],"id":41308374},{"atl":[[10.5,10.53],[11.5,1.9],[14.5,0],[15.5,0]],"id":40846831}],"con":true,"img":false}]}
{"op":"mcm","clk":"5348250040","pt":1646215929403,"mc":[{"id":"1.195453622","rc":[{"atb":[[1.07,0]],"id":36463352},{"atb":[[4.4,2]],"id":40846831}],"con":true,"img":false}]}
{"op":"mcm","clk":"5348250203","pt":1646215931538,"mc":[{"id":"1.195453622","rc":[{"atl":[[1.61,0],[1.52,3]],"id":36463352},{"atb":[[4.4,0],[4.5,4]],"id":40846831}],"con":true,"img":false}]}
{"op":"mcm","clk":"5348250211","pt":1646215931593,"mc":[{"id":"1.195453622","rc":[{"atb":[[2.5,0],[2.6,62.5]],"id":40846831},{"atl":[[10.5,12.64],[11.5,0]],"id":40846831}],"con":true,"img":false}]}
{"op":"mcm","clk":"5348250231","pt":1646215931800,"mc":[{"id":"1.195453622","rc":[{"atl":[[1.51,4]],"id":36463352},{"atb":[[4.5,0]],"id":40846831}],"con":true,"img":false}]}
{"op":"mcm","clk":"5348250382","pt":1646215933627,"mc":[{"id":"1.195453622","rc":[{"atb":[[1.34,24.51]],"id":36463352}],"con":true,"img":false}]}
{"op":"mcm","clk":"5348250403","pt":1646215933841,"mc":[{"id":"1.195453622","rc":[{"atl":[[1.5,4]],"id":36463352}],"con":true,"img":false}]}
{"op":"mcm","clk":"5348250702","pt":1646215936618,"mc":[{"id":"1.195453622","rc":[{"atl":[[1.49,4]],"id":36463352}],"con":true,"img":false}]}
{"op":"mcm","clk":"5348250955","pt":1646215939316,"mc":[{"id":"1.195453622","rc":[{"atb":[[3.85,17.54]],"id":23806261}],"con":true,"img":false}]}
{"op":"mcm","clk":"5348250998","pt":1646215939734,"mc":[{"id":"1.195453622","rc":[{"atb":[[3.55,0]],"id":23806261}],"con":true,"img":false}]}
{"op":"mcm","clk":"5348251154","pt":1646215941610,"mc":[{"id":"1.195453622","rc":[{"atl":[[11.5,4.76]],"id":40846831}],"con":true,"img":false}]}
{"op":"mcm","clk":"5348251170","pt":1646215941820,"mc":[{"id":"1.195453622","rc":[{"atb":[[4.5,3]],"id":40846831},{"atl":[[17,0],[10.5,10.53],[11.5,1.9]],"id":40846831}],"con":true,"img":false}]}
{"op":"mcm","clk":"5348251188","pt":1646215942025,"mc":[{"id":"1.195453622","rc":[{"atb":[[4.6,4]],"id":40846831}],"con":true,"img":false}]}
{"op":"mcm","clk":"5348251256","pt":1646215942621,"mc":[{"id":"1.195453622","rc":[{"atb":[[4.7,2]],"id":40846831}],"con":true,"img":false}]}
{"op":"mcm","clk":"5348251303","pt":1646215942963,"mc":[{"id":"1.195453622","rc":[{"atb":[[4.8,3]],"id":40846831}],"con":true,"img":false}]}
{"op":"mcm","clk":"5348251589","pt":1646215945629,"mc":[{"id":"1.195453622","rc":[{"atb":[[3.75,18.18]],"id":40250501},{"atb":[[1.34,0]],"id":36463352},{"atb":[[3.05,11.42]],"id":40846831}],"con":true,"img":false}]}
{"op":"mcm","clk":"5348251669","pt":1646215946517,"mc":[{"id":"1.195453622","rc":[{"atb":[[3.05,9.76]],"id":40846831}],"con":true,"img":false}]}
{"op":"mcm","clk":"5348251695","pt":1646215946828,"mc":[{"id":"1.195453622","rc":[{"atb":[[4.8,0],[4.5,0],[4.6,0],[4.7,0]],"id":40846831}],"con":true,"img":false}]}
{"op":"mcm","clk":"5348251705","pt":1646215946931,"mc":[{"id":"1.195453622","rc":[{"atl":[[10.5,12.64]],"id":40846831}],"con":true,"img":false}]}
{"op":"mcm","clk":"5348251942","pt":1646215949318,"mc":[{"id":"1.195453622","rc":[{"atb":[[3.75,27.27]],"id":23806261}],"con":true,"img":false}]}
{"op":"mcm","clk":"5348252469","pt":1646215954742,"mc":[{"id":"1.195453622","rc":[{"atb":[[3.05,13.42]],"id":40846831}],"con":true,"img":false}]}
{"op":"mcm","clk":"5348252532","pt":1646215955451,"mc":[{"id":"1.195453622","rc":[{"atl":[[11,0]],"id":40846831}],"con":true,"img":false}]}
{"op":"mcm","clk":"5348252542","pt":1646215955554,"mc":[{"id":"1.195453622","rc":[{"atl":[[9.8,4.35]],"id":40846831}],"con":true,"img":false}]}
{"op":"mcm","clk":"5348252626","pt":1646215956441,"mc":[{"id":"1.195453622","rc":[{"atb":[[3.1,1.66]],"id":40846831}],"con":true,"img":false}]}
{"op":"mcm","clk":"5348252662","pt":1646215956858,"mc":[{"id":"1.195453622","rc":[{"atl":[[11.5,4.76]],"id":40846831}],"con":true,"img":false}]}
{"op":"mcm","clk":"5348252909","pt":1646215959353,"mc":[{"id":"1.195453622","rc":[{"atb":[[3.65,122.49]],"id":23806261}],"con":true,"img":false}]}
{"op":"mcm","clk":"5348253125","pt":1646215961453,"mc":[{"id":"1.195453622","rc":[{"atl":[[12,0]],"id":40250501}],"con":true,"img":false}]}
{"op":"mcm","clk":"5348253134","pt":1646215961559,"mc":[{"id":"1.195453622","rc":[{"atl":[[10,4.15]],"id":40250501}],"con":true,"img":false}]}
{"op":"mcm","clk":"5348253614","pt":1646215966866,"mc":[{"id":"1.195453622","rc":[{"atl":[[12.5,6.52]],"id":40846831}],"con":true,"img":false}]}
{"op":"mcm","clk":"5348253944","pt":1646215969958,"mc":[{"id":"1.195453622","rc":[{"atl":[[18.5,0]],"id":40846831}],"con":true,"img":false}]}
{"op":"mcm","clk":"5348254290","pt":1646215973369,"mc":[{"id":"1.195453622","rc":[{"atl":[[2.72,0],[2.52,40.78]],"id":36463352},{"atl":[[13,0]],"id":40846831}],"con":true,"img":false}]}
{"op":"mcm","clk":"5348254301","pt":1646215973478,"mc":[{"id":"1.195453622","rc":[{"atl":[[10,13.55]],"id":40846831}],"con":true,"img":false}]}
{"op":"mcm","clk":"5348254492","pt":1646215975470,"mc":[{"id":"1.195453622","rc":[{"atb":[[3.95,6.78]],"id":23806261}],"con":true,"img":false}]}
{"op":"mcm","clk":"5348254501","pt":1646215975573,"mc":[{"id":"1.195453622","rc":[{"atb":[[4.4,19.44]],"id":23806261}],"con":true,"img":false}]}
{"op":"mcm","clk":"5348254537","pt":1646215975988,"mc":[{"id":"1.195453622","rc":[{"atb":[[1.21,295.2],[1.26,0]],"id":36463352}],"con":true,"img":false}]}
{"op":"mcm","clk":"5348254617","pt":1646215976889,"mc":[{"id":"1.195453622","rc":[{"atl":[[13.5,10]],"id":40846831}],"con":true,"img":false}]}
{"op":"mcm","clk":"5348254767","pt":1646215977636,"mc":[{"id":"1.195453622","rc":[{"atb":[[4.3,0],[3.9,0],[3.65,84.83]],"id":23806261},{"atl":[[32,0],[21,0],[15.5,8.62]],"id":23806261},{"atb":[[3.4,0],[3.15,0],[3.65,28.3]],"id":40250501},{"atl":[[10.5,2.11],[21,0],[15.5,0]],"id":40250501},{"atb":[[1.2,0],[1.25,0],[1.3,0]],"id":36463352},{"atl":[[2.54,0],[2.94,0],[2.74,0]],"id":36463352},{"atb":[[1.2,0],[1.25,0],[1.15,0]],"id":41308374},{"atl":[[2.44,86.81],[2.64,0],[2.84,0]],"id":41308374},{"atb":[[2.74,0],[2.84,0],[2.94,0]],"id":40846831},{"atl":[[8,0],[10,5.48],[15,0]],"id":40846831},{"atb":[[4,0],[4.5,0],[3.75,0]],"id":40199925},{"atl":[[16,0],[34,0],[22,0]],"id":40199925},{"atb":[[2.74,0],[2.84,0],[2.94,38.66]],"id":6780934},{"atl":[[10,2.22],[15,0]],"id":6780934}],"con":true,"img":false}]}
{"op":"mcm","clk":"5348254795","pt":1646215977800,"mc":[{"id":"1.195453622","rc":[{"atl":[[17.5,0]],"id":40846831}],"con":true,"img":false}]}
{"op":"mcm","clk":"5348255001","pt":1646215978876,"mc":[{"id":"1.195453622","rc":[{"atl":[[2,20],[2.02,0]],"id":36463352}],"con":true,"img":false}]}
{"op":"mcm","clk":"5348255053","pt":1646215979394,"mc":[{"id":"1.195453622","rc":[{"atb":[[4.4,0]],"id":23806261},{"atb":[[1.31,0]],"id":36463352},{"atl":[[2.52,0]],"id":36463352},{"atl":[[2.62,0]],"id":41308374},{"atb":[[2.76,0]],"id":40846831},{"atl":[[10,0]],"id":40846831},{"atb":[[2.76,0]],"id":6780934}],"con":true,"img":false}]}
{"op":"mcm","clk":"5348255063","pt":1646215979499,"mc":[{"id":"1.195453622","rc":[{"atb":[[4,19.44]],"id":23806261},{"atb":[[1.24,86.07]],"id":36463352},{"atl":[[2.74,40.78]],"id":36463352},{"atl":[[2.82,35.74]],"id":41308374},{"atb":[[2.62,36.12]],"id":40846831},{"atl":[[11,5.48]],"id":40846831},{"atb":[[2.6,38.45]],"id":6780934}],"con":true,"img":false}]}
{"op":"mcm","clk":"5348255266","pt":1646215981301,"mc":[{"id":"1.195453622","rc":[{"atb":[[4.3,30.24],[3.9,34.42],[3.65,122.49]],"id":23806261},{"atl":[[32,2.34],[21,3.62],[15.5,11.12]],"id":23806261},{"atb":[[3.4,41.58],[3.15,46.42],[3.65,65.96]],"id":40250501},{"atl":[[10.5,5.93],[21,3.62],[15.5,5]],"id":40250501},{"atb":[[1.2,499.07],[1.25,399.25],[1.3,332.71]],"id":36463352},{"atl":[[2.54,23.57],[2.94,37.41],[2.74,82.5]],"id":36463352},{"atb":[[1.2,499.07],[1.25,399.25],[1.15,665.43]],"id":41308374},{"atl":[[2.44,112.01],[2.64,44.26],[2.84,39.45]],"id":41308374},{"atb":[[2.74,57.36],[2.84,54.24],[2.94,51.45]],"id":40846831},{"atl":[[8,5.18],[10,8.06],[15,5.18]],"id":40846831},{"atb":[[4,33.27],[4.5,28.51],[3.75,36.29]],"id":40199925},{"atl":[[16,2.41],[34,2.2],[22,3.45]],"id":40199925},{"atb":[[2.74,64.24],[2.84,60.75],[2.94,96.28]],"id":6780934},{"atl":[[8,4.14],[10,8.67],[15,4.14]],"id":6780934}],"con":true,"img":false}]}
{"op":"mcm","clk":"5348255513","pt":1646215983302,"mc":[{"id":"1.195453622","rc":[{"atl":[[1.51,0],[1.5,0],[1.49,0],[1.52,0]],"id":36463352}],"con":true,"img":false}]}
{"op":"mcm","clk":"5348255531","pt":1646215983512,"mc":[{"id":"1.195453622","rc":[{"atl":[[11,0]],"id":40846831}],"con":true,"img":false}]}
{"op":"mcm","clk":"5348255540","pt":1646215983568,"mc":[{"id":"1.195453622","rc":[{"atl":[[11.5,10.24]],"id":40846831}],"con":true,"img":false}]}
{"op":"mcm","clk":"5348255567","pt":1646215983887,"mc":[{"id":"1.195453622","rc":[{"atl":[[2,0],[2.02,19.61]],"id":36463352}],"con":true,"img":false}]}
{"op":"mcm","clk":"5348255714","pt":1646215985403,"mc":[{"id":"1.195453622","rc":[{"atl":[[10,0]],"id":40250501}],"con":true,"img":false}]}
{"op":"mcm","clk":"5348255730","pt":1646215985508,"mc":[{"id":"1.195453622","rc":[{"atl":[[13,8.39]],"id":40250501}],"con":true,"img":false}]}
{"op":"mcm","clk":"5348256077","pt":1646215989118,"mc":[{"id":"1.195453622","rc":[{"atb":[[4.3,2]],"id":40846831},{"atl":[[11.5,12.14]],"id":40846831}],"con":true,"img":false}]}
{"op":"mcm","clk":"5348256091","pt":1646215989222,"mc":[{"id":"1.195453622","rc":[{"atl":[[10.5,10.53],[11.5,7.38]],"id":40846831}],"con":true,"img":false}]}
{"op":"mcm","clk":"5348256096","pt":1646215989277,"mc":[{"id":"1.195453622","rc":[{"atb":[[4.3,0],[4.5,2]],"id":40846831}],"con":true,"img":false}]}
{"op":"mcm","clk":"5348256125","pt":1646215989592,"mc":[{"id":"1.195453622","rc":[{"atb":[[4.6,2]],"id":40846831}],"con":true,"img":false}]}
{"op":"mcm","clk":"5348256163","pt":1646215990007,"mc":[{"id":"1.195453622","rc":[{"atb":[[4.7,3]],"id":40846831}],"con":true,"img":false}]}
{"op":"mcm","clk":"5348256188","pt":1646215990321,"mc":[{"id":"1.195453622","rc":[{"atb":[[4.8,2]],"id":40846831}],"con":true,"img":false}]}
{"op":"mcm","clk":"5348256257","pt":1646215991105,"mc":[{"id":"1.195453622","rc":[{"atb":[[1.33,22.78]],"id":36463352},{"atb":[[3.05,9.76]],"id":40846831}],"con":true,"img":false}]}
{"op":"mcm","clk":"5348256296","pt":1646215991522,"mc":[{"id":"1.195453622","rc":[{"atl":[[14,0]],"id":23806261},{"atl":[[14,0]],"id":40199925}],"con":true,"img":false}]}
{"op":"mcm","clk":"5348256306","pt":1646215991627,"mc":[{"id":"1.195453622","rc":[{"atl":[[15,2.72]],"id":23806261},{"atl":[[15,2.72]],"id":40199925}],"con":true,"img":false}]}
{"op":"mcm","clk":"5348256741","pt":1646215996623,"mc":[{"id":"1.195453622","rc":[{"atb":[[3.1,0]],"id":40846831}],"con":true,"img":false}]}
{"op":"mcm","clk":"5348256804","pt":1646215997415,"mc":[{"id":"1.195453622","rc":[{"atl":[[11,0],[11.5,10.07]],"id":6780934}],"con":true,"img":false}]}
{"op":"mcm","clk":"5348256906","pt":1646215998627,"mc":[{"id":"1.195453622","rc":[{"atb":[[4.8,0],[4.5,0],[4.6,0],[4.7,0]],"id":40846831},{"atl":[[10.5,12.64]],"id":40846831}],"con":true,"img":false}]}
{"op":"mcm","clk":"5348256920","pt":1646215998834,"mc":[{"id":"1.195453622","rc":[{"atb":[[3,0]],"id":40846831}],"con":true,"img":false}]}
{"op":"mcm","clk":"5348257634","pt":1646216006108,"mc":[{"id":"1.195453622","rc":[{"spn":1.39,"spf":1.0,"id":36463352},{"atb":[[3.05,13.42]],"id":40846831},{"spn":5.77,"spf":"NaN","id":6780934}],"con":true,"img":false}]}
{"op":"mcm","clk":"5348257677","pt":1646216006522,"mc":[{"id":"1.195453622","rc":[{"atb":[[3.1,1.66]],"id":40846831}],"con":true,"img":false}]}
{"op":"mcm","clk":"5348257755","pt":1646216007413,"mc":[{"id":"1.195453622","rc":[{"atb":[[1.24,0]],"id":36463352}],"con":true,"img":false}]}
{"op":"mcm","clk":"5348257767","pt":1646216007517,"mc":[{"id":"1.195453622","rc":[{"atb":[[1.26,86.07]],"id":36463352}],"con":true,"img":false}]}
{"op":"mcm","clk":"5348257871","pt":1646216008513,"mc":[{"id":"1.195453622","rc":[{"atl":[[8,0]],"id":6780934},{"trd":[[8,18.66]],"ltp":8.0,"tv":18.66,"id":6780934}],"con":true,"img":false}]}
{"op":"mcm","clk":"5348257884","pt":1646216008617,"mc":[{"id":"1.195453622","rc":[{"atl":[[11.5,10.24]],"id":40846831}],"con":true,"img":false}]}
{"op":"mcm","clk":"5348257991","pt":1646216009501,"mc":[{"id":"1.195453622","rc":[{"atb":[[4.3,2]],"id":40846831},{"atl":[[10.5,10.53],[11.5,7.38]],"id":40846831}],"con":true,"img":false}]}
{"op":"mcm","clk":"5348258010","pt":1646216009711,"mc":[{"id":"1.195453622","rc":[{"atb":[[4.3,0],[4.5,4]],"id":40846831}],"con":true,"img":false}]}
{"op":"mcm","clk":"5348258298","pt":1646216011914,"mc":[{"id":"1.195453622","rc":[{"atb":[[4.6,2]],"id":40846831}],"con":true,"img":false}]}
{"op":"mcm","clk":"5348258593","pt":1646216014333,"mc":[{"id":"1.195453622","rc":[{"atb":[[4.7,3]],"id":40846831}],"con":true,"img":false}]}
{"op":"mcm","clk":"5348258611","pt":1646216014539,"mc":[{"id":"1.195453622","rc":[{"atb":[[4.8,2],[4.5,0],[4.6,0],[4.7,0]],"id":40846831},{"atl":[[10.5,12.64]],"id":40846831}],"con":true,"img":false}]}
{"op":"mcm","clk":"5348258629","pt":1646216014773,"mc":[{"id":"1.195453622","rc":[{"atb":[[4.8,0]],"id":40846831}],"con":true,"img":false}]}
{"op":"mcm","clk":"5348258636","pt":1646216014846,"mc":[{"id":"1.195453622","rc":[{"atb":[[1.33,48.04]],"id":36463352}],"con":true,"img":false}]}
{"op":"mcm","clk":"5348258649","pt":1646216014948,"mc":[{"id":"1.195453622","rc":[{"atb":[[3.05,9.76]],"id":40846831}],"con":true,"img":false}]}
{"op":"mcm","clk":"5348259375","pt":1646216021443,"mc":[{"id":"1.195453622","rc":[{"atl":[[2.82,0]],"id":41308374}],"con":true,"img":false}]}
{"op":"mcm","clk":"5348259383","pt":1646216021549,"mc":[{"id":"1.195453622","rc":[{"atl":[[2.62,35.74]],"id":41308374}],"con":true,"img":false}]}
{"op":"mcm","clk":"5348259608","pt":1646216023422,"mc":[{"id":"1.195453622","rc":[{"atb":[[2.62,0]],"id":40846831},{"atb":[[2.6,0]],"id":6780934}],"con":true,"img":false}]}
{"op":"mcm","clk":"5348259622","pt":1646216023527,"mc":[{"id":"1.195453622","rc":[{"atb":[[2.76,36.12]],"id":40846831},{"atb":[[2.76,38.45]],"id":6780934}],"con":true,"img":false}]}
{"op":"mcm","clk":"5348259679","pt":1646216024045,"mc":[{"id":"1.195453622","rc":[{"atb":[[3.05,13.42]],"id":40846831}],"con":true,"img":false}]}
{"op":"mcm","clk":"5348259724","pt":1646216024563,"mc":[{"id":"1.195453622","rc":[{"atl":[[11.5,12.14]],"id":40846831}],"con":true,"img":false}]}
{"op":"mcm","clk":"5348259738","pt":1646216024665,"mc":[{"id":"1.195453622","rc":[{"atl":[[11.5,10.24]],"id":40846831}],"con":true,"img":false}]}
{"op":"mcm","clk":"5348259779","pt":1646216025034,"mc":[{"id":"1.195453622","rc":[{"atb":[[4.3,2]],"id":40846831},{"atl":[[10.5,10.53],[11.5,5.48]],"id":40846831}],"con":true,"img":false}]}
{"op":"mcm","clk":"5348259789","pt":1646216025144,"mc":[{"id":"1.195453622","rc":[{"atl":[[11.5,7.38]],"id":40846831}],"con":true,"img":false}]}
{"op":"mcm","clk":"5348259797","pt":1646216025245,"mc":[{"id":"1.195453622","rc":[{"atb":[[4.3,0],[4.5,3]],"id":40846831}],"con":true,"img":false}]}
{"op":"mcm","clk":"5348259824","pt":1646216025555,"mc":[{"id":"1.195453622","rc":[{"atb":[[1.27,0]],"id":41308374},{"atb":[[2.76,0]],"id":40846831}],"con":true,"img":false}]}
{"op":"mcm","clk":"5348259838","pt":1646216025655,"mc":[{"id":"1.195453622","rc":[{"atb":[[1.26,464.46]],"id":41308374},{"atb":[[2.62,36.12]],"id":40846831}],"con":true,"img":false}]}
{"op":"mcm","clk":"5348259929","pt":1646216026540,"mc":[{"id":"1.195453622","rc":[{"atb":[[3.1,0]],"id":40846831}],"con":true,"img":false}]}
{"op":"mcm","clk":"5348259979","pt":1646216027056,"mc":[{"id":"1.195453622","rc":[{"atb":[[4.6,2]],"id":40846831}],"con":true,"img":false}]}
{"op":"mcm","clk":"5348260229","pt":1646216029364,"mc":[{"id":"1.195453622","rc":[{"atb":[[3,4.16]],"id":40846831}],"con":true,"img":false}]}
{"op":"mcm","clk":"5348260322","pt":1646216030249,"mc":[{"id":"1.195453622","rc":[{"atb":[[4.5,0],[4.6,0],[4.7,3]],"id":40846831},{"atl":[[10.5,12.64]],"id":40846831}],"con":true,"img":false}]}
{"op":"mcm","clk":"5348260513","pt":1646216032138,"mc":[{"id":"1.195453622","rc":[{"atb":[[4.7,0]],"id":40846831}],"con":true,"img":false}]}
{"op":"mcm","clk":"5348260648","pt":1646216033483,"mc":[{"id":"1.195453622","rc":[{"atb":[[1.31,0]],"id":41308374},{"atb":[[2.98,0]],"id":40846831}],"con":true,"img":false}]}
{"op":"mcm","clk":"5348260656","pt":1646216033554,"mc":[{"id":"1.195453622","rc":[{"atb":[[1.29,86.73]],"id":41308374},{"atb":[[2.9,22.24]],"id":40846831}],"con":true,"img":false}]}
{"op":"mcm","clk":"5348260896","pt":1646216036068,"mc":[{"id":"1.195453622","rc":[{"atb":[[1.34,24.51]],"id":41308374}],"con":true,"img":false}]}
{"op":"mcm","clk":"5348260944","pt":1646216036451,"mc":[{"id":"1.195453622","rc":[{"atb":[[3.1,1.66]],"id":40846831}],"con":true,"img":false}]}
{"op":"mcm","clk":"5348261240","pt":1646216039467,"mc":[{"id":"1.195453622","rc":[{"atb":[[5.2,0]],"id":40199925}],"con":true,"img":false}]}
{"op":"mcm","clk":"5348261253","pt":1646216039574,"mc":[{"id":"1.195453622","rc":[{"atb":[[5,13.21]],"id":40199925}],"con":true,"img":false}]}
{"op":"mcm","clk":"5348261314","pt":1646216040267,"mc":[{"id":"1.195453622","rc":[{"atl":[[11.5,10.24]],"id":40846831}],"con":true,"img":false}]}
{"op":"mcm","clk":"5348261489","pt":1646216041996,"mc":[{"id":"1.195453622","rc":[{"atb":[[1.33,22.78]],"id":41308374}],"con":true,"img":false}]}
{"op":"mcm","clk":"5348261667","pt":1646216043569,"mc":[{"id":"1.195453622","rc":[{"atb":[[4.3,2]],"id":40846831},{"atl":[[11.5,12.14]],"id":40846831}],"con":true,"img":false}]}
{"op":"mcm","clk":"5348261690","pt":1646216043778,"mc":[{"id":"1.195453622","rc":[{"atb":[[4.3,0],[4.5,2]],"id":40846831},{"atl":[[10.5,10.53],[11.5,7.38]],"id":40846831}],"con":true,"img":false}]}
{"op":"mcm","clk":"5348261906","pt":1646216045565,"mc":[{"id":"1.195453622","rc":[{"atb":[[4.6,3]],"id":40846831}],"con":true,"img":false}]}
{"op":"mcm","clk":"5348262016","pt":1646216046662,"mc":[{"id":"1.195453622","rc":[{"atb":[[3.1,0]],"id":40846831}],"con":true,"img":false}]}
{"op":"mcm","clk":"5348262090","pt":1646216047485,"mc":[{"id":"1.195453622","rc":[{"atl":[[13,4.24]],"id":40250501},{"atb":[[1.26,0]],"id":36463352}],"con":true,"img":false}]}
{"op":"mcm","clk":"5348262103","pt":1646216047593,"mc":[{"id":"1.195453622","rc":[{"atl":[[12,4.15]],"id":40250501},{"atb":[[1.34,86.07]],"id":36463352}],"con":true,"img":false}]}
{"op":"mcm","clk":"5348262137","pt":1646216047856,"mc":[{"id":"1.195453622","rc":[{"atb":[[4.7,2]],"id":40846831}],"con":true,"img":false}]}
{"op":"mcm","clk":"5348262147","pt":1646216047959,"mc":[{"id":"1.195453622","rc":[{"atb":[[1.33,25.25]],"id":36463352}],"con":true,"img":false}]}
{"op":"mcm","clk":"5348262231","pt":1646216048892,"mc":[{"id":"1.195453622","rc":[{"atb":[[4.8,4],[4.5,0],[4.6,0],[4.7,0]],"id":40846831},{"atl":[[10.5,12.64]],"id":40846831}],"con":true,"img":false}]}
{"op":"mcm","clk":"5348262247","pt":1646216049055,"mc":[{"id":"1.195453622","rc":[{"atb":[[4.8,0]],"id":40846831}],"con":true,"img":false}]}
{"op":"mcm","clk":"5348262538","pt":1646216052089,"mc":[{"id":"1.195453622","rc":[{"atl":[[11.5,1.9]],"id":40846831}],"con":true,"img":false}]}
{"op":"mcm","clk":"5348262551","pt":1646216052188,"mc":[{"id":"1.195453622","rc":[{"atl":[[10,13.55]],"id":40846831}],"con":true,"img":false}]}
{"op":"mcm","clk":"5348262775","pt":1646216054063,"mc":[{"id":"1.195453622","rc":[{"atb":[[1.37,20.32]],"id":36463352}],"con":true,"img":false}]}
{"op":"mcm","clk":"5348262931","pt":1646216055474,"mc":[{"id":"1.195453622","rc":[{"atb":[[1.34,0]],"id":36463352}],"con":true,"img":false}]}
{"op":"mcm","clk":"5348262943","pt":1646216055586,"mc":[{"id":"1.195453622","rc":[{"atb":[[1.31,86.07]],"id":36463352}],"con":true,"img":false}]}
{"op":"mcm","clk":"5348263179","pt":1646216058883,"mc":[{"id":"1.195453622","rc":[{"atl":[[11.5,4.76]],"id":40846831}],"con":true,"img":false}]}
{"op":"mcm","clk":"5348263366","pt":1646216062008,"mc":[{"id":"1.195453622","rc":[{"atb":[[4.4,3]],"id":40846831},{"atl":[[11.5,6.66]],"id":40846831}],"con":true,"img":false}]}
{"op":"mcm","clk":"5348264334","pt":1646216067448,"mc":[{"id":"1.195453622","rc":[{"atb":[[1.21,0],[1.26,238.43]],"id":36463352},{"spn":1.4,"spf":1.0,"id":36463352},{"spn":6.2,"spf":"NaN","id":40846831},{"spn":6.67,"spf":"NaN","id":6780934}],"con":true,"img":false}]}
{"op":"mcm","clk":"5348264420","pt":1646216067965,"mc":[{"id":"1.195453622","rc":[{"atb":[[5,0]],"id":40199925},{"atb":[[2.86,31.42],[2.76,0]],"id":6780934}],"con":true,"img":false}]}
{"op":"mcm","clk":"5348264448","pt":1646216068130,"mc":[{"id":"1.195453622","rc":[{"atb":[[5.2,13.21]],"id":40199925}],"con":true,"img":false}]}
{"op":"mcm","clk":"5348264633","pt":1646216069244,"mc":[{"id":"1.195453622","rc":[{"atl":[[10.5,10.53],[11.5,1.9]],"id":40846831}],"con":true,"img":false}]}
{"op":"mcm","clk":"5348264996","pt":1646216071437,"mc":[{"id":"1.195453622","rc":[{"atb":[[1.37,0]],"id":36463352}],"con":true,"img":false}]}
{"op":"mcm","clk":"5348265047","pt":1646216071595,"mc":[{"id":"1.195453622","rc":[{"atl":[[15,0]],"id":23806261},{"atl":[[15,0]],"id":40199925}],"con":true,"img":false}]}
{"op":"mcm","clk":"5348265126","pt":1646216071884,"mc":[{"id":"1.195453622","rc":[{"atl":[[14,2.72]],"id":23806261},{"atl":[[14,2.72]],"id":40199925}],"con":true,"img":false}]}
{"op":"mcm","clk":"5348265373","pt":1646216073434,"mc":[{"id":"1.195453622","rc":[{"atb":[[2.9,0]],"id":40846831}],"con":true,"img":false}]}
{"op":"mcm","clk":"5348265385","pt":1646216073535,"mc":[{"id":"1.195453622","rc":[{"atb":[[2.98,22.24]],"id":40846831}],"con":true,"img":false}]}
{"op":"mcm","clk":"5348265581","pt":1646216075280,"mc":[{"id":"1.195453622","rc":[{"atb":[[4.4,0]],"id":40846831},{"atl":[[10.5,12.64]],"id":40846831}],"con":true,"img":false}]}
{"op":"mcm","clk":"5348265594","pt":1646216075342,"mc":[{"id":"1.195453622","rc":[{"atb":[[1.34,0]],"id":41308374}],"con":true,"img":false}]}
{"op":"mcm","clk":"5348266034","pt":1646216078062,"mc":[{"id":"1.195453622","rc":[{"atb":[[1.34,22.11]],"id":36463352}],"con":true,"img":false}]}
{"op":"mcm","clk":"5348266407","pt":1646216079541,"mc":[{"id":"1.195453622","rc":[{"atl":[[10,6.45]],"id":6780934}],"con":true,"img":false}]}
{"op":"mcm","clk":"5348266417","pt":1646216079701,"mc":[{"id":"1.195453622","rc":[{"atl":[[10.5,2.11]],"id":6780934}],"con":true,"img":false}]}
{"op":"mcm","clk":"5348266545","pt":1646216080438,"mc":[{"id":"1.195453622","rc":[{"atb":[[4.4,2]],"id":40846831},{"atl":[[10.5,10.53]],"id":40846831}],"con":true,"img":false}]}
{"op":"mcm","clk":"5348266832","pt":1646216081948,"mc":[{"id":"1.195453622","rc":[{"atl":[[10.5,3.82]],"id":40250501},{"atl":[[2.02,0],[2.04,19.23]],"id":36463352},{"atb":[[4.5,4]],"id":40846831},{"atl":[[17.5,6.06]],"id":40199925}],"con":true,"img":false}]}
{"op":"mcm","clk":"5348266860","pt":1646216082008,"mc":[{"id":"1.195453622","rc":[{"atl":[[11,2]],"id":40250501},{"atl":[[18.5,0]],"id":40199925}],"con":true,"img":false}]}
{"op":"mcm","clk":"5348267227","pt":1646216083086,"mc":[{"id":"1.195453622","rc":[{"atb":[[1.03,250]],"id":36463352},{"atb":[[4.4,0],[4.5,0]],"id":40846831},{"atl":[[10.5,12.64]],"id":40846831}],"con":true,"img":false}]}
{"op":"mcm","clk":"5348267241","pt":1646216083199,"mc":[{"id":"1.195453622","rc":[{"atb":[[4,40.2],[3.95,0],[4.2,6.25],[3.65,84.83]],"id":23806261},{"atl":[[18.5,5.71],[22,0]],"id":23806261},{"atl":[[2.32,0],[2.28,36.76],[2.1,18.18]],"id":41308374},{"atl":[[10.5,2.11],[7.8,5.18],[5.9,4.08]],"id":40846831},{"atb":[[4.1,51.9],[4.7,33.78]],"id":40199925}],"con":true,"img":false}]}
{"op":"mcm","clk":"5348267409","pt":1646216083629,"mc":[{"id":"1.195453622","rc":[{"atl":[[18,0]],"id":40199925},{"atl":[[10,8.06]],"id":40846831}],"con":true,"img":false}]}
{"op":"mcm","clk":"5348267486","pt":1646216083824,"mc":[{"id":"1.195453622","rc":[{"atl":[[21,3.29]],"id":40199925},{"atl":[[11.5,7.38]],"id":40846831}],"con":true,"img":false}]}
{"op":"mcm","clk":"5348267530","pt":1646216083898,"mc":[{"id":"1.195453622","rc":[{"atb":[[3.1,1.66]],"id":40846831}],"con":true,"img":false}]}
{"op":"mcm","clk":"5348268003","pt":1646216085222,"mc":[{"id":"1.195453622","rc":[{"atb":[[3,14.16],[3.05,3.66]],"id":40846831},{"atl":[[13.5,0],[5.4,2]],"id":40846831}],"con":true,"img":false}]}
{"op":"mcm","clk":"5348268157","pt":1646216085466,"mc":[{"id":"1.195453622","rc":[{"atl":[[5.3,2]],"id":40846831}],"con":true,"img":false}]}
{"op":"mcm","clk":"5348268289","pt":1646216085790,"mc":[{"id":"1.195453622","rc":[{"atl":[[5.2,3]],"id":40846831}],"con":true,"img":false}]}
{"op":"mcm","clk":"5348268507","pt":1646216086448,"mc":[{"id":"1.195453622","rc":[{"atl":[[5.1,2]],"id":40846831}],"con":true,"img":false}]}
{"op":"mcm","clk":"5348269929","pt":1646216091685,"mc":[{"id":"1.195453622","rc":[{"atl":[[7.8,0],[6.6,5.18]],"id":40846831}],"con":true,"img":false}]}
{"op":"mcm","clk":"5348269985","pt":1646216091886,"mc":[{"id":"1.195453622","rc":[{"atl":[[12,8.7]],"id":40250501}],"con":true,"img":false}]}
{"op":"mcm","clk":"5348270054","pt":1646216092067,"mc":[{"id":"1.195453622","rc":[{"atl":[[11.5,0],[12.5,0],[13.5,0]],"id":40250501},{"atb":[[3,4.16],[3.05,13.42]],"id":40846831},{"atl":[[5.3,0],[5.4,0],[5.1,0],[5.2,0]],"id":40846831}],"con":true,"img":false}]}
{"op":"mcm","clk":"5348270361","pt":1646216093171,"mc":[{"id":"1.195453622","rc":[{"atb":[[4,56.87]],"id":23806261},{"atl":[[2.14,43.86]],"id":41308374}],"con":true,"img":false}]}
{"op":"mcm","clk":"5348270442","pt":1646216093543,"mc":[{"id":"1.195453622","rc":[{"atl":[[12,4.55],[13,0]],"id":40250501}],"con":true,"img":false}]}
{"op":"mcm","clk":"5348270517","pt":1646216093676,"mc":[{"id":"1.195453622","rc":[{"atl":[[13.5,4.15],[15,4.24]],"id":40250501}],"con":true,"img":false}]}
{"op":"mcm","clk":"5348271135","pt":1646216095866,"mc":[{"id":"1.195453622","rc":[{"atb":[[3.85,0],[3.75,0],[3.65,37.66]],"id":23806261},{"atl":[[2.36,0],[2.4,0],[2.44,25.2]],"id":41308374}],"con":true,"img":false}]}
{"op":"mcm","clk":"5348271368","pt":1646216096779,"mc":[{"id":"1.195453622","rc":[{"atb":[[1.33,0]],"id":36463352}],"con":true,"img":false}]}
{"op":"mcm","clk":"5348271477","pt":1646216097291,"mc":[{"id":"1.195453622","rc":[{"atb":[[1.33,48.04]],"id":41308374}],"con":true,"img":false}]}
{"op":"mcm","clk":"5348272374","pt":1646216101899,"mc":[{"id":"1.195453622","rc":[{"atb":[[4.5,8.68],[3.75,35.54]],"id":40250501},{"atl":[[10.5,10.81],[13,6.25]],"id":40250501}],"con":true,"img":false}]}
{"op":"mcm","clk":"5348272405","pt":1646216102106,"mc":[{"id":"1.195453622","rc":[{"atb":[[4.5,20.42],[4.9,2.5],[4.2,21.63]],"id":23806261},{"atl":[[12,5.04],[13.5,6.5]],"id":23806261},{"atb":[[3.7,10],[3.9,5],[4.2,2.5]],"id":40250501},{"atb":[[1.3,342.71],[1.34,27.11],[1.38,2.5]],"id":36463352},{"atl":[[2.04,67.25],[2.08,142.34]],"id":36463352},{"atl":[[2.28,136.05],[2.1,78.64]],"id":41308374},{"atb":[[2.98,37.78],[3.05,15.42]],"id":40846831},{"atl":[[8,20.72],[6.4,1.86],[6.2,9.62]],"id":40846831},{"atb":[[5.1,27.68],[5.3,9.69]],"id":40199925},{"atl":[[12.5,6.78],[13.5,6.5],[14,18.2]],"id":40199925},{"atb":[[3.8,10],[3.55,7.4],[4.4,2.5],[4,5]],"id":6780934},{"atl":[[9.8,10.32]],"id":6780934}],"con":true,"img":false}]}
{"op":"mcm","clk":"5348272422","pt":1646216102164,"mc":[{"id":"1.195453622","rc":[{"atb":[[1.31,2.5]],"id":41308374},{"atl":[[7.8,5],[8.6,10],[7,2.5]],"id":40846831},{"atb":[[3.1,25.25],[3,42.97],[3.5,0]],"id":6780934}],"con":true,"img":false}]}
{"op":"mcm","clk":"5348272600","pt":1646216103188,"mc":[{"id":"1.195453622","rc":[{"atb":[[3.9,60.28]],"id":23806261},{"atl":[[2.18,63.56]],"id":41308374}],"con":true,"img":false}]}
{"op":"mcm","clk":"5348272643","pt":1646216103405,"mc":[{"id":"1.195453622","rc":[{"atl":[[2.28,99.29],[2.18,148.31]],"id":41308374}],"con":true,"img":false}]}
{"op":"mcm","clk":"5348272830","pt":1646216104306,"mc":[{"id":"1.195453622","rc":[{"atl":[[12.5,0]],"id":40846831}],"con":true,"img":false}]}
{"op":"mcm","clk":"5348272972","pt":1646216104977,"mc":[{"id":"1.195453622","rc":[{"atb":[[3.05,9.76]],"id":6780934}],"con":true,"img":false}]}
{"op":"mcm","clk":"5348273138","pt":1646216105525,"mc":[{"id":"1.195453622","rc":[{"atl":[[2.3,0]],"id":41308374}],"con":true,"img":false}]}
{"op":"mcm","clk":"5348273166","pt":1646216105619,"mc":[{"id":"1.195453622","rc":[{"atl":[[2.08,31.14]],"id":41308374}],"con":true,"img":false}]}
{"op":"mcm","clk":"5348273302","pt":1646216105926,"mc":[{"id":"1.195453622","rc":[{"atb":[[4.6,0]],"id":23806261},{"atb":[[4.4,29.56]],"id":40250501},{"atb":[[3.55,5.74]],"id":6780934}],"con":true,"img":false}]}
{"op":"mcm","clk":"5348273359","pt":1646216106082,"mc":[{"id":"1.195453622","rc":[{"atb":[[5,1.66]],"id":23806261},{"atb":[[4.6,1.66]],"id":40250501},{"atb":[[4.5,1.66]],"id":6780934},{"atl":[[1000,2.52]],"id":6780934}],"con":true,"img":false}]}
{"op":"mcm","clk":"5348273410","pt":1646216106290,"mc":[{"id":"1.195453622","rc":[{"atb":[[4.4,14.78],[4.5,17.36]],"id":40250501}],"con":true,"img":false}]}
{"op":"mcm","clk":"5348273448","pt":1646216106409,"mc":[{"id":"1.195453622","rc":[{"atl":[[1000,1.68]],"id":6780934}],"con":true,"img":false}]}
{"op":"mcm","clk":"5348273542","pt":1646216106593,"mc":[{"id":"1.195453622","rc":[{"atl":[[1000,0]],"id":6780934}],"con":true,"img":false}]}
{"op":"mcm","clk":"5348273580","pt":1646216106705,"mc":[{"id":"1.195453622","rc":[{"atl":[[9.6,1.68]],"id":6780934}],"con":true,"img":false}]}
{"op":"mcm","clk":"5348274618","pt":1646216109491,"mc":[{"id":"1.195453622","rc":[{"atl":[[14,0]],"id":23806261}],"con":true,"img":false}]}
{"op":"mcm","clk":"5348274661","pt":1646216109592,"mc":[{"id":"1.195453622","rc":[{"atl":[[15,2.72]],"id":23806261}],"con":true,"img":false}]}
{"op":"mcm","clk":"5348274878","pt":1646216110497,"mc":[{"id":"1.195453622","rc":[{"atb":[[4.3,5.74],[3.1,0]],"id":6780934}],"con":true,"img":false}]}
{"op":"mcm","clk":"5348275124","pt":1646216111673,"mc":[{"id":"1.195453622","rc":[{"atl":[[2.18,63.56],[2.1,157.28]],"id":41308374}],"con":true,"img":false}]}
{"op":"mcm","clk":"5348275164","pt":1646216111890,"mc":[{"id":"1.195453622","rc":[{"atl":[[14,9.62]],"id":40250501}],"con":true,"img":false}]}
{"op":"mcm","clk":"5348275209","pt":1646216112102,"mc":[{"id":"1.195453622","rc":[{"atl":[[6.6,18.57]],"id":40846831}],"con":true,"img":false}]}
{"op":"mcm","clk":"5348275414","pt":1646216113255,"mc":[{"id":"1.195453622","rc":[{"atb":[[3.8,44.64]],"id":23806261},{"atl":[[2.22,102.46]],"id":41308374}],"con":true,"img":false}]}
{"op":"mcm","clk":"5348275493","pt":1646216113486,"mc":[{"id":"1.195453622","rc":[{"atl":[[11.5,4.76]],"id":6780934}],"con":true,"img":false}]}
{"op":"mcm","clk":"5348275519","pt":1646216113585,"mc":[{"id":"1.195453622","rc":[{"atl":[[12,5.31]],"id":6780934}],"con":true,"img":false}]}
{"op":"mcm","clk":"5348275909","pt":1646216115501,"mc":[{"id":"1.195453622","rc":[{"atl":[[11.5,5.48]],"id":40846831}],"con":true,"img":false}]}
{"op":"mcm","clk":"5348276113","pt":1646216116598,"mc":[{"id":"1.195453622","rc":[{"atb":[[1.34,51.62]],"id":36463352}],"con":true,"img":false}]}
{"op":"mcm","clk":"5348276235","pt":1646216117077,"mc":[{"id":"1.195453622","rc":[{"atb":[[3.05,13.42]],"id":6780934}],"con":true,"img":false}]}
{"op":"mcm","clk":"5348276678","pt":1646216119411,"mc":[{"id":"1.195453622","rc":[{"atb":[[3.75,18.18],[4.6,13.18],[4.2,25.54]],"id":40250501}],"con":true,"img":false}]}
{"op":"mcm","clk":"5348276716","pt":1646216119576,"mc":[{"id":"1.195453622","rc":[{"atb":[[4.3,47.55],[4.9,8.16],[4.2,6.25]],"id":23806261},{"atb":[[4.5,8.68]],"id":40250501},{"atl":[[2.28,0],[2.14,155.48],[2.08,87.39]],"id":41308374},{"atl":[[8,5.18],[6.4,22.54],[5.8,6.19]],"id":40846831},{"atb":[[4.4,8.68]],"id":6780934},{"atl":[[9.6,7.86]],"id":6780934}],"con":true,"img":false}]}
{"op":"mcm","clk":"5348276741","pt":1646216119679,"mc":[{"id":"1.195453622","rc":[{"atl":[[2.1,96.82],[2.14,243.2]],"id":41308374},{"atl":[[6.4,20.68]],"id":40846831},{"atb":[[3,26.18],[4,21.11]],"id":6780934},{"atl":[[9.8,4.58]],"id":6780934}],"con":true,"img":false}]}
{"op":"mcm","clk":"5348276766","pt":1646216119790,"mc":[{"id":"1.195453622","rc":[{"atb":[[4.5,15.38]],"id":23806261},{"atl":[[2.1,18.18]],"id":41308374},{"atb":[[3.55,0]],"id":6780934}],"con":true,"img":false}]}
{"op":"mcm","clk":"5348276810","pt":1646216119993,"mc":[{"id":"1.195453622","rc":[{"atl":[[2.1,109.09],[2.14,155.48]],"id":41308374}],"con":true,"img":false}]}
{"op":"mcm","clk":"5348276818","pt":1646216120091,"mc":[{"id":"1.195453622","rc":[{"atb":[[3.05,9.76]],"id":6780934}],"con":true,"img":false}]}
{"op":"mcm","clk":"5348277216","pt":1646216122085,"mc":[{"id":"1.195453622","rc":[{"atl":[[7,23.33]],"id":40846831}],"con":true,"img":false}]}
{"op":"mcm","clk":"5348277519","pt":1646216123425,"mc":[{"id":"1.195453622","rc":[{"atl":[[2.06,0],[2.74,41.71]],"id":36463352}],"con":true,"img":false}]}
{"op":"mcm","clk":"5348277559","pt":1646216123532,"mc":[{"id":"1.195453622","rc":[{"atl":[[2.02,41.92],[2.46,40.78]],"id":36463352}],"con":true,"img":false}]}
{"op":"mcm","clk":"5348277627","pt":1646216123808,"mc":[{"id":"1.195453622","rc":[{"atl":[[2.02,111.05]],"id":36463352}],"con":true,"img":false}]}
{"op":"mcm","clk":"5348277678","pt":1646216124022,"mc":[{"id":"1.195453622","rc":[{"atl":[[2.04,19.23]],"id":36463352}],"con":true,"img":false}]}
{"op":"mcm","clk":"5348278034","pt":1646216125400,"mc":[{"id":"1.195453622","rc":[{"atl":[[6.2,18],[9.8,0]],"id":40846831}],"con":true,"img":false}]}
{"op":"mcm","clk":"5348278063","pt":1646216125498,"mc":[{"id":"1.195453622","rc":[{"atb":[[4.5,5]],"id":23806261}],"con":true,"img":false}]}
{"op":"mcm","clk":"5348278100","pt":1646216125609,"mc":[{"id":"1.195453622","rc":[{"atb":[[4.8,10.38]],"id":23806261}],"con":true,"img":false}]}
{"op":"mcm","clk":"5348278563","pt":1646216127421,"mc":[{"id":"1.195453622","rc":[{"atl":[[13.5,0]],"id":40250501},{"atb":[[1.31,0]],"id":36463352},{"atb":[[5.2,0]],"id":40199925}],"con":true,"img":false}]}
{"op":"mcm","clk":"5348278576","pt":1646216127529,"mc":[{"id":"1.195453622","rc":[{"spn":8.5,"spf":"NaN","id":23806261},{"atl":[[13,10.4]],"id":40250501},{"spn":7.55,"spf":"NaN","id":40250501},{"atb":[[1.26,324.5]],"id":36463352},{"spn":1.4,"spf":1.0,"id":36463352},{"spn":1.72,"spf":"NaN","id":41308374},{"atb":[[5.4,14.87]],"id":40199925},{"spn":4.45,"spf":"NaN","id":40846831},{"spn":7.05,"spf":"NaN","id":6780934}],"con":true,"img":false}]}
{"op":"mcm","clk":"5348278597","pt":1646216127583,"mc":[{"id":"1.195453622","rc":[{"atb":[[5.1,12.2],[4.9,66.07]],"id":40199925}],"con":true,"img":false}]}
{"op":"mcm","clk":"5348278617","pt":1646216127697,"mc":[{"id":"1.195453622","rc":[{"atb":[[5.4,33.05]],"id":40199925}],"con":true,"img":false}]}
{"op":"mcm","clk":"5348278667","pt":1646216127919,"mc":[{"id":"1.195453622","rc":[{"atb":[[5.3,4.65]],"id":40199925}],"con":true,"img":false}]}
{"op":"mcm","clk":"5348279030","pt":1646216129216,"mc":[{"id":"1.195453622","rc":[{"atb":[[1.34,29.51]],"id":36463352}],"con":true,"img":false}]}
{"op":"mcm","clk":"5348279463","pt":1646216131418,"mc":[{"id":"1.195453622","rc":[{"atb":[[4.4,0]],"id":40250501},{"atb":[[3,4.16]],"id":6780934}],"con":true,"img":false}]}
