{"op":"mcm","clk":"5345985302","pt":1646174444265,"mc":[{"id":"1.195453631","marketDefinition":{"bspMarket":true,"turnInPlayEnabled":false,"persistenceEnabled":false,"marketBaseRate":7.0,"eventId":"31272494","eventTypeId":"4339","numberOfWinners":1,"bettingType":"ODDS","marketType":"WIN","marketTime":"2022-03-02T12:04:00.000Z","suspendTime":"2022-03-02T12:04:00.000Z","bspReconciled":false,"complete":true,"inPlay":false,"crossMatching":false,"runnersVoidable":false,"numberOfActiveRunners":8,"betDelay":0,"status":"OPEN","runners":[{"status":"ACTIVE","sortPriority":1,"id":36120434,"name":"1. Missys Hand"},{"status":"ACTIVE","sortPriority":2,"id":40637101,"name":"2. Odessa Rock"},{"status":"ACTIVE","sortPriority":3,"id":39183170,"name":"3. Sweet Suzie"},{"status":"ACTIVE","sortPriority":4,"id":35381686,"name":"4. Castle Sween"},{"status":"ACTIVE","sortPriority":5,"id":40917619,"name":"5. Kens Crew"},{"status":"ACTIVE","sortPriority":6,"id":38554545,"name":"6. Call Me Harvey"},{"status":"ACTIVE","sortPriority":7,"id":26349442,"name":"7. Inuka"},{"status":"ACTIVE","sortPriority":8,"id":41398505,"name":"8. Afternoon"}],"regulators":["MR_INT"],"venue":"Traralgon","countryCode":"AU","discountAllowed":true,"timezone":"Australia/Sydney","openDate":"2022-03-02T08:31:00.000Z","version":4382425375,"name":"R12 350m Gr5","eventName":"Traralgon (AUS) 2nd Mar"},"rc":[],"con":true,"img":false}]}
{"op":"mcm","clk":"5346059623","pt":1646175788371,"mc":[{"id":"1.195453631","rc":[{"atb":[[3.45,16.66],[2.88,43.43],[2.98,20.62],[2.78,45.87],[2.68,97.2]],"id":26349442},{"atl":[[16,13.3],[11,13.3],[13.5,15.96],[9.4,15.84]],"id":26349442},{"spn":6.42,"spf":"NaN","id":26349442},{"atb":[[8.6,5.37],[5.8,34.02],[11.5,3.88],[7.6,12.37],[6.6,14.58]],"id":40637101},{"atl":[[130,1.02],[90,1.49],[180,1.11],[230,0.87]],"id":40637101},{"spn":50.75,"spf":"NaN","id":40637101},{"atb":[[9.6,9.49],[8.6,21.48],[19,2.27],[11.5,7.77],[14,3.14]],"id":36120434},{"atl":[[260,0.77],[310,0.64],[160,0.83],[210,0.63]],"id":36120434},{"spn":89.5,"spf":"NaN","id":36120434},{"atb":[[4.8,21.48],[4.3,49.48],[5.8,8.5],[5.3,18.98],[7.6,6.18]],"id":40917619},{"atl":[[65,3.11],[36,3.79],[90,2.24],[46,2.95]],"id":40917619},{"spn":21.8,"spf":"NaN","id":40917619},{"atb":[[2.4,29.16],[2,81.65],[2.2,34.02],[1.95,171.9],[2.1,74.22]],"id":41398505},{"atl":[[8.6,26.26],[5.8,27.71],[7.6,30.23],[6.6,23.75]],"id":41398505},{"spn":4.1,"spf":"NaN","id":41398505},{"atb":[[2.8,45.36],[2.9,21.48],[2.6,102.06],[3.25,18.14],[2.7,48.03]],"id":39183170},{"atl":[[11,19.95],[13.5,15.96],[8.4,17.98],[9.4,15.84]],"id":39183170},{"spn":5.82,"spf":"NaN","id":39183170},{"atb":[[9.6,9.49],[8.6,21.48],[19,2.27],[11.5,7.77],[14,3.14]],"id":35381686},{"atl":[[260,0.77],[310,0.64],[160,0.83],[210,0.63]],"id":35381686},{"spn":89.5,"spf":"NaN","id":35381686},{"atb":[[4.8,42.97],[8.6,5.37],[5.8,17.01],[5.3,18.98],[6.6,7.28]],"id":38554545},{"atl":[[65,2.07],[130,1.54],[90,2.24],[46,2.95]],"id":38554545},{"spn":27.3,"spf":"NaN","id":38554545}],"con":true,"img":false}]}
{"op":"mcm","clk":"5346061998","pt":1646175839944,"mc":[{"id":"1.195453631","rc":[{"atb":[[3.45,0],[2.88,0],[2.98,0],[2.78,0],[2.68,0]],"id":26349442},{"atl":[[16,0],[11,0],[13.5,0],[9.4,0]],"id":26349442},{"atb":[[8.6,0],[5.8,0],[11.5,0],[7.6,0],[6.6,0]],"id":40637101},{"atl":[[130,0],[90,0],[180,0],[230,0]],"id":40637101},{"atb":[[9.6,0],[8.6,0],[19,0],[11.5,0],[14,0]],"id":36120434},{"atl":[[260,0],[310,0],[160,0],[210,0]],"id":36120434},{"atb":[[4.8,0],[4.3,0],[5.8,0],[5.3,0],[7.6,0]],"id":40917619},{"atl":[[65,0],[36,0],[90,0],[46,0]],"id":40917619},{"atb":[[2.4,0],[2,0],[2.2,0],[1.95,0],[2.1,0]],"id":41398505},{"atl":[[8.6,0],[5.8,0],[7.6,0],[6.6,0]],"id":41398505},{"atb":[[2.8,0],[2.9,0],[2.6,0],[3.25,0],[2.7,0]],"id":39183170},{"atl":[[11,0],[13.5,0],[8.4,0],[9.4,0]],"id":39183170},{"atb":[[9.6,0],[8.6,0],[19,0],[11.5,0],[14,0]],"id":35381686},{"atl":[[260,0],[310,0],[160,0],[210,0]],"id":35381686},{"atb":[[4.8,0],[8.6,0],[5.8,0],[5.3,0],[6.6,0]],"id":38554545},{"atl":[[65,0],[130,0],[90,0],[46,0]],"id":38554545}],"con":true,"img":false}]}
{"op":"mcm","clk":"5346062230","pt":1646175844837,"mc":[{"id":"1.195453631","rc":[{"atb":[[3.45,16.66],[2.88,43.43],[2.98,20.62],[2.78,45.87],[2.68,97.2]],"id":26349442},{"atl":[[16,13.3],[11,13.3],[13.5,15.96],[9.4,15.84]],"id":26349442},{"atb":[[9.6,9.49],[8.6,21.48],[19,2.27],[11.5,7.77],[14,3.14]],"id":36120434},{"atl":[[260,0.77],[310,0.64],[160,0.83],[210,0.63]],"id":36120434},{"atb":[[8.6,5.37],[5.8,34.02],[11.5,3.88],[7.6,12.37],[6.6,14.58]],"id":40637101},{"atl":[[130,1.02],[90,1.49],[180,1.11],[230,0.87]],"id":40637101},{"atb":[[4.8,21.48],[4.3,49.48],[5.8,8.5],[5.3,18.98],[7.6,6.18]],"id":40917619},{"atl":[[65,3.11],[36,3.79],[90,2.24],[46,2.95]],"id":40917619},{"atb":[[2.4,29.16],[2,81.65],[2.2,34.02],[1.95,171.9],[2.1,74.22]],"id":41398505},{"atl":[[8.6,26.26],[5.8,27.71],[7.6,30.23],[6.6,23.75]],"id":41398505},{"atb":[[2.8,45.36],[2.9,21.48],[2.6,102.06],[3.25,18.14],[2.7,48.03]],"id":39183170},{"atl":[[11,19.95],[13.5,15.96],[8.4,17.98],[9.4,15.84]],"id":39183170},{"atb":[[9.6,9.49],[8.6,21.48],[19,2.27],[11.5,7.77],[14,3.14]],"id":35381686},{"atl":[[260,0.77],[310,0.64],[160,0.83],[210,0.63]],"id":35381686},{"atb":[[4.8,42.97],[8.6,5.37],[5.8,17.01],[5.3,18.98],[6.6,7.28]],"id":38554545},{"atl":[[65,2.07],[130,1.54],[90,2.24],[46,2.95]],"id":38554545}],"con":true,"img":false}]}
{"op":"mcm","clk":"5346105187","pt":1646176602709,"mc":[{"id":"1.195453631","marketDefinition":{"bspMarket":true,"turnInPlayEnabled":false,"persistenceEnabled":false,"marketBaseRate":7.0,"eventId":"31272494","eventTypeId":"4339","numberOfWinners":1,"bettingType":"ODDS","marketType":"WIN","marketTime":"2022-03-02T12:04:00.000Z","suspendTime":"2022-03-02T12:04:00.000Z","bspReconciled":false,"complete":true,"inPlay":false,"crossMatching":false,"runnersVoidable":false,"numberOfActiveRunners":8,"betDelay":0,"status":"OPEN","runners":[{"status":"ACTIVE","sortPriority":1,"id":36120434,"name":"1. Missys Hand"},{"status":"ACTIVE","sortPriority":2,"id":40637101,"name":"2. Odessa Rock"},{"status":"ACTIVE","sortPriority":3,"id":39183170,"name":"3. Sweet Suzie"},{"status":"ACTIVE","sortPriority":4,"id":35381686,"name":"4. Castle Sween"},{"status":"ACTIVE","sortPriority":5,"id":40917619,"name":"5. Kens Crew"},{"status":"ACTIVE","sortPriority":6,"id":38554545,"name":"6. Call Me Harvey"},{"status":"ACTIVE","sortPriority":7,"id":26349442,"name":"7. Inuka"},{"status":"ACTIVE","sortPriority":8,"id":41398505,"name":"8. Afternoon"}],"regulators":["MR_INT"],"venue":"Traralgon","countryCode":"AU","discountAllowed":true,"timezone":"Australia/Sydney","openDate":"2022-03-02T08:31:00.000Z","version":4382425375,"name":"R12 350m Gr5","eventName":"Traralgon (AUS) 2nd Mar"},"rc":[{"atb":[[3.45,16.66],[2.88,43.43],[2.98,20.62],[2.78,45.87],[2.68,97.2]],"id":26349442},{"atl":[[16,13.3],[11,13.3],[13.5,15.96],[9.4,15.84]],"id":26349442},{"spn":6.42,"spf":"NaN","id":26349442},{"atb":[[9.6,9.49],[8.6,21.48],[19,2.27],[11.5,7.77],[14,3.14]],"id":36120434},{"atl":[[260,0.77],[310,0.64],[160,0.83],[210,0.63]],"id":36120434},{"spn":89.5,"spf":"NaN","id":36120434},{"atb":[[8.6,5.37],[5.8,34.02],[11.5,3.88],[7.6,12.37],[6.6,14.58]],"id":40637101},{"atl":[[130,1.02],[90,1.49],[180,1.11],[230,0.87]],"id":40637101},{"spn":50.75,"spf":"NaN","id":40637101},{"atb":[[4.8,21.48],[4.3,49.48],[5.8,8.5],[5.3,18.98],[7.6,6.18]],"id":40917619},{"atl":[[65,3.11],[36,3.79],[90,2.24],[46,2.95]],"id":40917619},{"spn":21.8,"spf":"NaN","id":40917619},{"atb":[[2.4,29.16],[2,81.65],[2.2,34.02],[1.95,171.9],[2.1,74.22]],"id":41398505},{"atl":[[8.6,26.26],[5.8,27.71],[7.6,30.23],[6.6,23.75]],"id":41398505},{"spn":4.1,"spf":"NaN","id":41398505},{"atb":[[2.8,45.36],[2.9,21.48],[2.6,102.06],[3.25,18.14],[2.7,48.03]],"id":39183170},{"atl":[[11,19.95],[13.5,15.96],[8.4,17.98],[9.4,15.84]],"id":39183170},{"spn":5.82,"spf":"NaN","id":39183170},{"atb":[[9.6,9.49],[8.6,21.48],[19,2.27],[11.5,7.77],[14,3.14]],"id":35381686},{"atl":[[260,0.77],[310,0.64],[160,0.83],[210,0.63]],"id":35381686},{"spn":89.5,"spf":"NaN","id":35381686},{"atb":[[4.8,42.97],[8.6,5.37],[5.8,17.01],[5.3,18.98],[6.6,7.28]],"id":38554545},{"atl":[[65,2.07],[130,1.54],[90,2.24],[46,2.95]],"id":38554545},{"spn":27.3,"spf":"NaN","id":38554545}],"con":true,"img":true}]}
{"op":"mcm","clk":"5346220441","pt":1646178833710,"mc":[{"id":"1.195453631","rc":[{"atb":[[9.6,0],[8.6,0],[19,0],[11.5,0],[14,0]],"id":36120434},{"atl":[[260,0],[310,0],[160,0],[210,0]],"id":36120434},{"spn":"NaN","spf":"NaN","id":36120434},{"atb":[[8.6,0],[5.8,0],[11.5,0],[7.6,0],[6.6,0]],"id":40637101},{"atl":[[130,0],[90,0],[180,0],[230,0]],"id":40637101},{"spn":"NaN","spf":"NaN","id":40637101},{"atb":[[4.8,0],[4.3,0],[5.8,0],[5.3,0],[7.6,0]],"id":40917619},{"atl":[[65,0],[36,0],[90,0],[46,0]],"id":40917619},{"spn":"NaN","spf":"NaN","id":40917619},{"atb":[[2.4,0],[2,0],[2.2,0],[1.95,0],[2.1,0]],"id":41398505},{"atl":[[8.6,0],[5.8,0],[7.6,0],[6.6,0]],"id":41398505},{"spn":"NaN","spf":"NaN","id":41398505},{"atb":[[2.8,0],[2.9,0],[2.6,0],[3.25,0],[2.7,0]],"id":39183170},{"atl":[[11,0],[13.5,0],[8.4,0],[9.4,0]],"id":39183170},{"spn":"NaN","spf":"NaN","id":39183170},{"atb":[[9.6,0],[8.6,0],[19,0],[11.5,0],[14,0]],"id":35381686},{"atl":[[260,0],[310,0],[160,0],[210,0]],"id":35381686},{"spn":"NaN","spf":"NaN","id":35381686},{"atb":[[4.8,0],[8.6,0],[5.8,0],[5.3,0],[6.6,0]],"id":38554545},{"atl":[[65,0],[130,0],[90,0],[46,0]],"id":38554545},{"spn":"NaN","spf":"NaN","id":38554545}],"con":true,"img":false}]}
{"op":"mcm","clk":"5346221440","pt":1646178853461,"mc":[{"id":"1.195453631","rc":[{"atb":[[6.4,30.24],[7.4,12.75],[13.5,3.26],[8.4,11.03],[9.4,4.86]],"id":40637101},{"atl":[[260,0.77],[160,0.83],[210,0.95],[110,1.21]],"id":40637101},{"atb":[[9.2,19.91],[21,2.04],[10.5,8.59],[13,6.8],[15.5,2.81]],"id":36120434},{"atl":[[300,0.66],[350,0.57],[200,0.66],[250,0.53]],"id":36120434},{"atb":[[4.8,21.48],[4.3,49.48],[5.8,8.5],[5.3,18.98],[7.6,6.18]],"id":40917619},{"atl":[[65,3.11],[36,3.79],[90,2.24],[46,2.95]],"id":40917619},{"atb":[[2.36,30.02],[2.06,77.03],[1.98,83.32],[1.93,175.6],[2.16,35.19]],"id":41398505},{"atl":[[6.4,24.63],[7.4,31.18],[5.7,28.3],[8.4,26.96]],"id":41398505},{"atb":[[2.56,104.68],[2.86,21.94],[2.66,49.18],[3.15,18.98],[2.76,46.39]],"id":39183170},{"atl":[[11,19.95],[13.5,15.96],[8.4,17.98],[9.4,15.84]],"id":39183170},{"atb":[[9.2,19.91],[21,2.04],[10.5,8.59],[13,6.8],[15.5,2.81]],"id":35381686},{"atl":[[300,0.66],[350,0.57],[200,0.66],[250,0.53]],"id":35381686},{"atb":[[4.8,42.97],[8.6,5.37],[5.8,17.01],[5.3,18.98],[6.6,7.28]],"id":38554545},{"atl":[[65,2.07],[130,1.54],[90,2.24],[46,2.95]],"id":38554545}],"con":true,"img":false}]}
{"op":"mcm","clk":"5346401643","pt":1646182002790,"mc":[{"id":"1.195453631","marketDefinition":{"bspMarket":true,"turnInPlayEnabled":false,"persistenceEnabled":false,"marketBaseRate":7.0,"eventId":"31272494","eventTypeId":"4339","numberOfWinners":1,"bettingType":"ODDS","marketType":"WIN","marketTime":"2022-03-02T12:04:00.000Z","suspendTime":"2022-03-02T12:04:00.000Z","bspReconciled":false,"complete":true,"inPlay":false,"crossMatching":false,"runnersVoidable":false,"numberOfActiveRunners":8,"betDelay":0,"status":"OPEN","runners":[{"status":"ACTIVE","sortPriority":1,"id":36120434,"name":"1. Missys Hand"},{"status":"ACTIVE","sortPriority":2,"id":40637101,"name":"2. Odessa Rock"},{"status":"ACTIVE","sortPriority":3,"id":39183170,"name":"3. Sweet Suzie"},{"status":"ACTIVE","sortPriority":4,"id":35381686,"name":"4. Castle Sween"},{"status":"ACTIVE","sortPriority":5,"id":40917619,"name":"5. Kens Crew"},{"status":"ACTIVE","sortPriority":6,"id":38554545,"name":"6. Call Me Harvey"},{"status":"ACTIVE","sortPriority":7,"id":26349442,"name":"7. Inuka"},{"status":"ACTIVE","sortPriority":8,"id":41398505,"name":"8. Afternoon"}],"regulators":["MR_INT"],"venue":"Traralgon","countryCode":"AU","discountAllowed":true,"timezone":"Australia/Sydney","openDate":"2022-03-02T08:31:00.000Z","version":4382425375,"name":"R12 350m Gr5","eventName":"Traralgon (AUS) 2nd Mar"},"rc":[{"atb":[[3.45,16.66],[2.88,43.43],[2.98,20.62],[2.78,45.87],[2.68,97.21]],"id":26349442},{"atl":[[16,13.3],[11,13.3],[13.5,15.96],[9.4,15.84]],"id":26349442},{"spn":6.42,"spf":"NaN","id":26349442},{"atb":[[6.4,30.24],[7.4,12.76],[13.5,3.26],[8.4,11.03],[9.4,4.86]],"id":40637101},{"atl":[[260,0.77],[160,0.83],[210,0.95],[110,1.21]],"id":40637101},{"spn":61.75,"spf":"NaN","id":40637101},{"atb":[[9.2,19.92],[21,2.04],[10.5,8.59],[13,6.8],[15.5,2.81]],"id":36120434},{"atl":[[300,0.66],[350,0.57],[200,0.66],[250,0.53]],"id":36120434},{"spn":110.5,"spf":"NaN","id":36120434},{"atb":[[4.8,21.48],[4.3,49.49],[5.8,8.5],[5.3,18.98],[7.6,6.18]],"id":40917619},{"atl":[[65,3.11],[36,3.8],[90,2.24],[46,2.95]],"id":40917619},{"spn":21.8,"spf":"NaN","id":40917619},{"atb":[[2.36,30.02],[2.06,77.04],[1.98,83.32],[1.93,175.62],[2.16,35.2]],"id":41398505},{"atl":[[6.4,24.64],[7.4,31.18],[5.7,28.31],[8.4,26.97]],"id":41398505},{"spn":4.03,"spf":"NaN","id":41398505},{"atb":[[2.56,104.69],[2.86,21.95],[2.66,49.19],[3.15,18.98],[2.76,46.4]],"id":39183170},{"atl":[[11,19.95],[13.5,15.96],[8.4,17.98],[9.4,15.84]],"id":39183170},{"spn":5.77,"spf":"NaN","id":39183170},{"atb":[[9.2,19.92],[21,2.04],[10.5,8.59],[13,6.8],[15.5,2.81]],"id":35381686},{"atl":[[300,0.66],[350,0.57],[200,0.66],[250,0.53]],"id":35381686},{"spn":110.5,"spf":"NaN","id":35381686},{"atb":[[4.8,42.98],[8.6,5.37],[5.8,17.01],[5.3,18.98],[6.6,7.28]],"id":38554545},{"atl":[[65,2.07],[130,1.54],[90,2.24],[46,2.95]],"id":38554545},{"spn":27.3,"spf":"NaN","id":38554545}],"con":true,"img":true}]}
{"op":"mcm","clk":"5346767997","pt":1646187402735,"mc":[{"id":"1.195453631","marketDefinition":{"bspMarket":true,"turnInPlayEnabled":false,"persistenceEnabled":false,"marketBaseRate":7.0,"eventId":"31272494","eventTypeId":"4339","numberOfWinners":1,"bettingType":"ODDS","marketType":"WIN","marketTime":"2022-03-02T12:04:00.000Z","suspendTime":"2022-03-02T12:04:00.000Z","bspReconciled":false,"complete":true,"inPlay":false,"crossMatching":false,"runnersVoidable":false,"numberOfActiveRunners":8,"betDelay":0,"status":"OPEN","runners":[{"status":"ACTIVE","sortPriority":1,"id":36120434,"name":"1. Missys Hand"},{"status":"ACTIVE","sortPriority":2,"id":40637101,"name":"2. Odessa Rock"},{"status":"ACTIVE","sortPriority":3,"id":39183170,"name":"3. Sweet Suzie"},{"status":"ACTIVE","sortPriority":4,"id":35381686,"name":"4. Castle Sween"},{"status":"ACTIVE","sortPriority":5,"id":40917619,"name":"5. Kens Crew"},{"status":"ACTIVE","sortPriority":6,"id":38554545,"name":"6. Call Me Harvey"},{"status":"ACTIVE","sortPriority":7,"id":26349442,"name":"7. Inuka"},{"status":"ACTIVE","sortPriority":8,"id":41398505,"name":"8. Afternoon"}],"regulators":["MR_INT"],"venue":"Traralgon","countryCode":"AU","discountAllowed":true,"timezone":"Australia/Sydney","openDate":"2022-03-02T08:31:00.000Z","version":4382425375,"name":"R12 350m Gr5","eventName":"Traralgon (AUS) 2nd Mar"},"rc":[{"atb":[[3.45,16.69],[2.88,43.5],[2.98,20.65],[2.78,45.95],[2.68,97.37]],"id":26349442},{"atl":[[16,13.32],[11,13.32],[13.5,15.99],[9.4,15.86]],"id":26349442},{"spn":6.42,"spf":"NaN","id":26349442},{"atb":[[6.4,30.29],[7.4,12.78],[13.5,3.27],[8.4,11.05],[9.4,4.86]],"id":40637101},{"atl":[[260,0.77],[160,0.83],[210,0.95],[110,1.22]],"id":40637101},{"spn":61.75,"spf":"NaN","id":40637101},{"atb":[[9.2,19.95],[21,2.04],[10.5,8.61],[13,6.81],[15.5,2.81]],"id":36120434},{"atl":[[300,0.67],[350,0.57],[200,0.67],[250,0.53]],"id":36120434},{"spn":110.5,"spf":"NaN","id":36120434},{"atb":[[4.8,21.52],[4.3,49.57],[5.8,8.52],[5.3,19.01],[7.6,6.19]],"id":40917619},{"atl":[[65,3.12],[36,3.8],[90,2.24],[46,2.96]],"id":40917619},{"spn":21.8,"spf":"NaN","id":40917619},{"atb":[[2.36,30.07],[2.06,77.16],[1.98,83.46],[1.93,175.89],[2.16,35.25]],"id":41398505},{"atl":[[6.4,24.67],[7.4,31.23],[5.7,28.35],[8.4,27.01]],"id":41398505},{"spn":4.03,"spf":"NaN","id":41398505},{"atb":[[2.56,104.86],[2.86,21.98],[2.66,49.27],[3.15,19.01],[2.76,46.47]],"id":39183170},{"atl":[[11,19.99],[13.5,15.99],[8.4,18.01],[9.4,15.86]],"id":39183170},{"spn":5.77,"spf":"NaN","id":39183170},{"atb":[[9.2,19.95],[21,2.04],[10.5,8.61],[13,6.81],[15.5,2.81]],"id":35381686},{"atl":[[300,0.67],[350,0.57],[200,0.67],[250,0.53]],"id":35381686},{"spn":110.5,"spf":"NaN","id":35381686},{"atb":[[4.8,43.05],[8.6,5.38],[5.8,17.04],[5.3,19.01],[6.6,7.3]],"id":38554545},{"atl":[[65,2.08],[130,1.54],[90,2.24],[46,2.96]],"id":38554545},{"spn":27.3,"spf":"NaN","id":38554545}],"con":true,"img":true}]}
{"op":"mcm","clk":"5347092548","pt":1646192802714,"mc":[{"id":"1.195453631","marketDefinition":{"bspMarket":true,"turnInPlayEnabled":false,"persistenceEnabled":false,"marketBaseRate":7.0,"eventId":"31272494","eventTypeId":"4339","numberOfWinners":1,"bettingType":"ODDS","marketType":"WIN","marketTime":"2022-03-02T12:04:00.000Z","suspendTime":"2022-03-02T12:04:00.000Z","bspReconciled":false,"complete":true,"inPlay":false,"crossMatching":false,"runnersVoidable":false,"numberOfActiveRunners":8,"betDelay":0,"status":"OPEN","runners":[{"status":"ACTIVE","sortPriority":1,"id":36120434,"name":"1. Missys Hand"},{"status":"ACTIVE","sortPriority":2,"id":40637101,"name":"2. Odessa Rock"},{"status":"ACTIVE","sortPriority":3,"id":39183170,"name":"3. Sweet Suzie"},{"status":"ACTIVE","sortPriority":4,"id":35381686,"name":"4. Castle Sween"},{"status":"ACTIVE","sortPriority":5,"id":40917619,"name":"5. Kens Crew"},{"status":"ACTIVE","sortPriority":6,"id":38554545,"name":"6. Call Me Harvey"},{"status":"ACTIVE","sortPriority":7,"id":26349442,"name":"7. Inuka"},{"status":"ACTIVE","sortPriority":8,"id":41398505,"name":"8. Afternoon"}],"regulators":["MR_INT"],"venue":"Traralgon","countryCode":"AU","discountAllowed":true,"timezone":"Australia/Sydney","openDate":"2022-03-02T08:31:00.000Z","version":4382425375,"name":"R12 350m Gr5","eventName":"Traralgon (AUS) 2nd Mar"},"rc":[{"atb":[[3.45,16.71],[2.88,43.58],[2.98,20.69],[2.78,46.02],[2.68,97.53]],"id":26349442},{"atl":[[16,13.34],[11,13.34],[13.5,16.02],[9.4,15.89]],"id":26349442},{"spn":6.42,"spf":"NaN","id":26349442},{"atb":[[6.4,30.34],[7.4,12.8],[13.5,3.27],[8.4,11.07],[9.4,4.87]],"id":40637101},{"atl":[[260,0.77],[160,0.84],[210,0.95],[110,1.22]],"id":40637101},{"spn":61.75,"spf":"NaN","id":40637101},{"atb":[[9.2,19.98],[21,2.04],[10.5,8.62],[13,6.82],[15.5,2.82]],"id":36120434},{"atl":[[300,0.67],[350,0.57],[200,0.67],[250,0.53]],"id":36120434},{"spn":110.5,"spf":"NaN","id":36120434},{"atb":[[4.8,21.55],[4.3,49.65],[5.8,8.53],[5.3,19.05],[7.6,6.2]],"id":40917619},{"atl":[[65,3.12],[36,3.81],[90,2.25],[46,2.96]],"id":40917619},{"spn":21.8,"spf":"NaN","id":40917619},{"atb":[[2.36,30.12],[2.06,77.29],[1.98,83.6],[1.93,176.19],[2.16,35.31]],"id":41398505},{"atl":[[6.4,24.72],[7.4,31.28],[5.7,28.4],[8.4,27.05]],"id":41398505},{"spn":4.03,"spf":"NaN","id":41398505},{"atb":[[2.56,105.04],[2.86,22.02],[2.66,49.35],[3.15,19.05],[2.76,46.55]],"id":39183170},{"atl":[[11,20.02],[13.5,16.02],[8.4,18.04],[9.4,15.89]],"id":39183170},{"spn":5.77,"spf":"NaN","id":39183170},{"atb":[[9.2,19.98],[21,2.04],[10.5,8.62],[13,6.82],[15.5,2.82]],"id":35381686},{"atl":[[300,0.67],[350,0.57],[200,0.67],[250,0.53]],"id":35381686},{"spn":110.5,"spf":"NaN","id":35381686},{"atb":[[4.8,43.12],[8.6,5.39],[5.8,17.06],[5.3,19.05],[6.6,7.31]],"id":38554545},{"atl":[[65,2.08],[130,1.55],[90,2.25],[46,2.96]],"id":38554545},{"spn":27.3,"spf":"NaN","id":38554545}],"con":true,"img":true}]}
{"op":"mcm","clk":"5347355991","pt":1646197786969,"mc":[{"id":"1.195453631","rc":[{"atb":[[3.45,16.71],[2.88,43.56],[2.98,20.68],[2.78,46.01],[2.68,97.49]],"id":26349442},{"atl":[[16,13.34],[11,13.34],[13.5,16.01],[9.4,15.88]],"id":26349442},{"atb":[[6.4,30.33],[7.4,12.79],[13.5,3.27],[8.4,11.06],[9.4,4.87]],"id":40637101},{"atl":[[260,0.77],[160,0.84],[210,0.95],[110,1.22]],"id":40637101},{"spn":61.75,"spf":"NaN","id":40637101},{"atb":[[9.2,19.97],[21,2.04],[10.5,8.62],[13,6.82],[15.5,2.82]],"id":36120434},{"atl":[[300,0.67],[350,0.57],[200,0.67],[250,0.53]],"id":36120434},{"spn":110.5,"spf":"NaN","id":36120434},{"atb":[[4.8,21.55],[4.3,49.63],[5.8,8.53],[5.3,19.04],[7.6,6.2]],"id":40917619},{"atl":[[65,3.12],[36,3.81],[90,2.24],[46,2.96]],"id":40917619},{"spn":21.8,"spf":"NaN","id":40917619},{"atb":[[2.36,30.11],[2.06,77.26],[1.98,83.57],[1.93,176.12],[2.16,35.3]],"id":41398505},{"atl":[[4,8.19],[6.4,24.71],[7.4,31.27],[5.7,28.39],[8.4,27.04]],"id":41398505},{"spn":3.18,"spf":"NaN","id":41398505},{"atb":[[2.56,105],[2.86,22.01],[2.66,49.33],[3.15,19.04],[2.76,46.53]],"id":39183170},{"atl":[[11,20.01],[13.5,16.01],[8.4,18.03],[9.4,15.88]],"id":39183170},{"spn":5.77,"spf":"NaN","id":39183170},{"atb":[[9.2,19.97],[21,2.04],[10.5,8.62],[13,6.82],[15.5,2.82]],"id":35381686},{"atl":[[300,0.67],[350,0.57],[200,0.67],[250,0.53]],"id":35381686},{"spn":110.5,"spf":"NaN","id":35381686},{"atb":[[4.8,43.1],[8.6,5.38],[5.8,17.06],[5.3,19.04],[6.6,7.31]],"id":38554545},{"atl":[[65,2.08],[130,1.55],[90,2.24],[46,2.96]],"id":38554545},{"spn":27.3,"spf":"NaN","id":38554545}],"con":true,"img":false}]}
{"op":"mcm","clk":"5347483019","pt":1646200397675,"mc":[{"id":"1.195453631","rc":[{"atl":[[3.6,4.92]],"id":41398505},{"spn":2.98,"spf":"NaN","id":41398505}],"con":true,"img":false}]}
{"op":"mcm","clk":"5347849099","pt":1646209002736,"mc":[{"id":"1.195453631","marketDefinition":{"bspMarket":true,"turnInPlayEnabled":false,"persistenceEnabled":false,"marketBaseRate":7.0,"eventId":"31272494","eventTypeId":"4339","numberOfWinners":1,"bettingType":"ODDS","marketType":"WIN","marketTime":"2022-03-02T12:04:00.000Z","suspendTime":"2022-03-02T12:04:00.000Z","bspReconciled":false,"complete":true,"inPlay":false,"crossMatching":false,"runnersVoidable":false,"numberOfActiveRunners":8,"betDelay":0,"status":"OPEN","runners":[{"status":"ACTIVE","sortPriority":1,"id":36120434,"name":"1. Missys Hand"},{"status":"ACTIVE","sortPriority":2,"id":40637101,"name":"2. Odessa Rock"},{"status":"ACTIVE","sortPriority":3,"id":39183170,"name":"3. Sweet Suzie"},{"status":"ACTIVE","sortPriority":4,"id":35381686,"name":"4. Castle Sween"},{"status":"ACTIVE","sortPriority":5,"id":40917619,"name":"5. Kens Crew"},{"status":"ACTIVE","sortPriority":6,"id":38554545,"name":"6. Call Me Harvey"},{"status":"ACTIVE","sortPriority":7,"id":26349442,"name":"7. Inuka"},{"status":"ACTIVE","sortPriority":8,"id":41398505,"name":"8. Afternoon"}],"regulators":["MR_INT"],"venue":"Traralgon","countryCode":"AU","discountAllowed":true,"timezone":"Australia/Sydney","openDate":"2022-03-02T08:31:00.000Z","version":4382425375,"name":"R12 350m Gr5","eventName":"Traralgon (AUS) 2nd Mar"},"rc":[{"atb":[[3.45,16.7],[2.88,43.55],[2.98,20.67],[2.78,45.99],[2.68,97.47]],"id":26349442},{"atl":[[16,13.34],[11,13.34],[13.5,16],[9.4,15.88]],"id":26349442},{"spn":6.42,"spf":"NaN","id":26349442},{"atb":[[6.4,30.32],[7.4,12.79],[13.5,3.27],[8.4,11.06],[9.4,4.87]],"id":40637101},{"atl":[[260,0.77],[160,0.84],[210,0.95],[110,1.22]],"id":40637101},{"spn":61.75,"spf":"NaN","id":40637101},{"atb":[[9.2,19.97],[21,2.04],[10.5,8.61],[13,6.82],[15.5,2.82]],"id":36120434},{"atl":[[300,0.67],[350,0.57],[200,0.67],[250,0.53]],"id":36120434},{"spn":110.5,"spf":"NaN","id":36120434},{"atb":[[4.8,21.54],[4.3,49.62],[5.8,8.53],[5.3,19.03],[7.6,6.2]],"id":40917619},{"atl":[[65,3.12],[36,3.81],[90,2.24],[46,2.96]],"id":40917619},{"spn":21.8,"spf":"NaN","id":40917619},{"atb":[[2.36,30.1],[2.06,77.24],[1.98,83.54],[1.93,176.08],[2.16,35.29]],"id":41398505},{"atl":[[4,8.18],[3.6,4.93],[6.4,24.7],[7.4,31.26],[5.7,28.38],[8.4,27.04]],"id":41398505},{"spn":2.98,"spf":"NaN","id":41398505},{"atb":[[2.56,104.97],[2.86,22],[2.66,49.32],[3.15,19.03],[2.76,46.52]],"id":39183170},{"atl":[[11,20.01],[13.5,16],[8.4,18.02],[9.4,15.88]],"id":39183170},{"spn":5.77,"spf":"NaN","id":39183170},{"atb":[[9.2,19.97],[21,2.04],[10.5,8.61],[13,6.82],[15.5,2.82]],"id":35381686},{"atl":[[300,0.67],[350,0.57],[200,0.67],[250,0.53]],"id":35381686},{"spn":110.5,"spf":"NaN","id":35381686},{"atb":[[4.8,43.09],[8.6,5.38],[5.8,17.05],[5.3,19.03],[6.6,7.3]],"id":38554545},{"atl":[[65,2.08],[130,1.55],[90,2.24],[46,2.96]],"id":38554545},{"spn":27.3,"spf":"NaN","id":38554545}],"con":true,"img":true}]}
{"op":"mcm","clk":"5348089509","pt":1646213796526,"mc":[{"id":"1.195453631","rc":[{"atb":[[3.45,16.68],[2.92,3.91],[2.88,43.48],[2.98,20.64],[2.78,45.92],[2.68,97.31]],"id":26349442},{"atl":[[16,13.31],[11,13.31],[13.5,15.98],[9.4,15.85]],"id":26349442},{"atb":[[6.4,30.27],[7.4,12.77],[13.5,3.26],[8.4,11.04],[9.4,4.86]],"id":40637101},{"atl":[[260,0.77],[160,0.83],[210,0.95],[110,1.22]],"id":40637101},{"atb":[[9.2,19.94],[21,2.04],[10.5,8.6],[13,6.81],[15.5,2.81]],"id":36120434},{"atl":[[300,0.67],[350,0.57],[200,0.67],[250,0.53]],"id":36120434},{"atb":[[4.8,21.51],[4.3,49.54],[5.8,8.51],[5.3,19],[7.6,6.19]],"id":40917619},{"atl":[[65,3.12],[36,3.8],[90,2.24],[46,2.95]],"id":40917619},{"atb":[[2.36,30.05],[2.06,77.12],[1.98,83.41],[1.93,175.8],[2.16,35.23]],"id":41398505},{"atl":[[4,8.17],[3.6,4.93],[6.4,24.66],[7.4,31.21],[5.7,28.33],[8.4,26.99]],"id":41398505},{"atb":[[2.56,104.8],[2.86,21.97],[2.66,49.24],[3.15,19],[2.76,46.44]],"id":39183170},{"atl":[[11,19.97],[13.5,15.98],[8.4,18],[9.4,15.85]],"id":39183170},{"atb":[[9.2,19.94],[21,2.04],[10.5,8.6],[13,6.81],[15.5,2.81]],"id":35381686},{"atl":[[300,0.67],[350,0.57],[200,0.67],[250,0.53]],"id":35381686},{"atb":[[4.8,43.02],[8.6,5.37],[5.8,17.03],[5.3,19],[6.6,7.29]],"id":38554545},{"atl":[[65,2.08],[130,1.54],[90,2.24],[46,2.95]],"id":38554545}],"con":true,"img":false}]}
{"op":"mcm","clk":"5348089514","pt":1646213796580,"mc":[{"id":"1.195453631","rc":[{"atb":[[1.01,2.25]],"id":40917619},{"atb":[[2.2,6.26]],"id":41398505},{"atb":[[2.8,4.18]],"id":39183170},{"atb":[[1.01,2.25]],"id":38554545}],"con":true,"img":false}]}
{"op":"mcm","clk":"5348089527","pt":1646213796784,"mc":[{"id":"1.195453631","rc":[{"atb":[[1.01,1.7]],"id":40917619},{"atb":[[1.01,1.53]],"id":38554545}],"con":true,"img":false}]}
{"op":"mcm","clk":"5348089535","pt":1646213796990,"mc":[{"id":"1.195453631","rc":[{"atb":[[1.01,0]],"id":40917619}],"con":true,"img":false}]}
{"op":"mcm","clk":"5348089543","pt":1646213797095,"mc":[{"id":"1.195453631","rc":[{"atb":[[5.4,1.7]],"id":40917619}],"con":true,"img":false}]}
{"op":"mcm","clk":"5348089563","pt":1646213797398,"mc":[{"id":"1.195453631","rc":[{"atb":[[1.01,0]],"id":38554545}],"con":true,"img":false}]}
{"op":"mcm","clk":"5348089573","pt":1646213797504,"mc":[{"id":"1.195453631","rc":[{"atb":[[5.9,1.53]],"id":38554545}],"con":true,"img":false}]}
{"op":"mcm","clk":"5348090868","pt":1646213820426,"mc":[{"id":"1.195453631","marketDefinition":{"bspMarket":true,"turnInPlayEnabled":false,"persistenceEnabled":false,"marketBaseRate":7.0,"eventId":"31272494","eventTypeId":"4339","numberOfWinners":1,"bettingType":"ODDS","marketType":"WIN","marketTime":"2022-03-02T12:04:00.000Z","suspendTime":"2022-03-02T12:04:00.000Z","bspReconciled":false,"complete":true,"inPlay":false,"crossMatching":true,"runnersVoidable":false,"numberOfActiveRunners":8,"betDelay":0,"status":"OPEN","runners":[{"status":"ACTIVE","sortPriority":1,"id":36120434,"name":"1. Missys Hand"},{"status":"ACTIVE","sortPriority":2,"id":40637101,"name":"2. Odessa Rock"},{"status":"ACTIVE","sortPriority":3,"id":39183170,"name":"3. Sweet Suzie"},{"status":"ACTIVE","sortPriority":4,"id":35381686,"name":"4. Castle Sween"},{"status":"ACTIVE","sortPriority":5,"id":40917619,"name":"5. Kens Crew"},{"status":"ACTIVE","sortPriority":6,"id":38554545,"name":"6. Call Me Harvey"},{"status":"ACTIVE","sortPriority":7,"id":26349442,"name":"7. Inuka"},{"status":"ACTIVE","sortPriority":8,"id":41398505,"name":"8. Afternoon"}],"regulators":["MR_INT"],"venue":"Traralgon","countryCode":"AU","discountAllowed":true,"timezone":"Australia/Sydney","openDate":"2022-03-02T08:31:00.000Z","version":4382425375,"name":"R12 350m Gr5","eventName":"Traralgon (AUS) 2nd Mar"},"rc":[],"con":true,"img":false}]}
{"op":"mcm","clk":"5348097074","pt":1646213929508,"mc":[{"id":"1.195453631","rc":[{"atb":[[2.8,8.81]],"id":39183170}],"con":true,"img":false}]}
{"op":"mcm","clk":"5348097082","pt":1646213929612,"mc":[{"id":"1.195453631","rc":[{"atb":[[5.4,3.59]],"id":40917619}],"con":true,"img":false}]}
{"op":"mcm","clk":"5348097094","pt":1646213929815,"mc":[{"id":"1.195453631","rc":[{"atb":[[2.1,7.57]],"id":41398505}],"con":true,"img":false}]}
{"op":"mcm","clk":"5348097101","pt":1646213929919,"mc":[{"id":"1.195453631","rc":[{"atb":[[2.92,8.26]],"id":26349442}],"con":true,"img":false}]}
{"op":"mcm","clk":"5348097124","pt":1646213930329,"mc":[{"id":"1.195453631","rc":[{"atb":[[5.9,3.23]],"id":38554545}],"con":true,"img":false}]}
{"op":"mcm","clk":"5348206552","pt":1646215440133,"mc":[{"id":"1.195453631","rc":[{"atb":[[14.5,0.75]],"id":40637101},{"spn":62.25,"spf":"NaN","id":40637101},{"atb":[[21,2.55]],"id":36120434}],"con":true,"img":false}]}
{"op":"mcm","clk":"5348206562","pt":1646215440182,"mc":[{"id":"1.195453631","rc":[{"atb":[[3.55,2]],"id":26349442},{"atb":[[8.2,1.4]],"id":40917619},{"atb":[[2.36,32.05]],"id":41398505},{"atb":[[3.35,2]],"id":39183170},{"atb":[[22,0.49]],"id":35381686},{"atb":[[8.6,6.7]],"id":38554545}],"con":true,"img":false}]}
{"op":"mcm","clk":"5348207167","pt":1646215447524,"mc":[{"id":"1.195453631","rc":[{"atb":[[2.2,0]],"id":41398505}],"con":true,"img":false}]}
{"op":"mcm","clk":"5348208185","pt":1646215459440,"mc":[{"id":"1.195453631","rc":[{"atb":[[2.4,5.36]],"id":41398505}],"con":true,"img":false}]}
{"op":"mcm","clk":"5348284369","pt":1646216165247,"mc":[{"id":"1.195453631","rc":[{"spn":6.47,"spf":"NaN","id":26349442},{"atb":[[14.5,0]],"id":40637101},{"spn":61.75,"spf":"NaN","id":40637101},{"spn":22.1,"spf":"NaN","id":40917619},{"spn":3.0,"spf":"NaN","id":41398505},{"spn":5.87,"spf":"NaN","id":39183170},{"spn":111.0,"spf":"NaN","id":35381686}],"con":true,"img":false}]}
{"op":"mcm","clk":"5348284383","pt":1646216165350,"mc":[{"id":"1.195453631","rc":[{"atb":[[2.36,30.05]],"id":41398505}],"con":true,"img":false}]}
{"op":"mcm","clk":"5348284394","pt":1646216165454,"mc":[{"id":"1.195453631","rc":[{"atb":[[15,0.72]],"id":40637101}],"con":true,"img":false}]}
{"op":"mcm","clk":"5348284410","pt":1646216165560,"mc":[{"id":"1.195453631","rc":[{"atb":[[2.42,2]],"id":41398505}],"con":true,"img":false}]}
{"op":"mcm","clk":"5348285641","pt":1646216174427,"mc":[{"id":"1.195453631","rc":[{"atb":[[2.4,0]],"id":41398505}],"con":true,"img":false}]}
{"op":"mcm","clk":"5348286892","pt":1646216183249,"mc":[{"id":"1.195453631","rc":[{"atb":[[2.2,6.26]],"id":41398505}],"con":true,"img":false}]}
{"op":"mcm","clk":"5348395309","pt":1646217245644,"mc":[{"id":"1.195453631","rc":[{"atb":[[2.26,57.14]],"id":26349442},{"atb":[[7.2,11.61],[4.7,22.16]],"id":40637101},{"spn":62.5,"spf":"NaN","id":40637101},{"atb":[[11,7.2],[7,13.67]],"id":36120434},{"atb":[[4.3,71.36],[2.96,41.84]],"id":40917619},{"spn":3.01,"spf":"NaN","id":41398505},{"atb":[[11,7.2],[7,13.67]],"id":35381686},{"atb":[[4.8,61.97]],"id":38554545}],"con":true,"img":false}]}
{"op":"mcm","clk":"5348395321","pt":1646217245748,"mc":[{"id":"1.195453631","rc":[{"atb":[[1.76,107.89]],"id":26349442},{"atb":[[3.25,36.44]],"id":38554545}],"con":true,"img":false}]}
{"op":"mcm","clk":"5348395332","pt":1646217245855,"mc":[{"id":"1.195453631","rc":[{"atl":[[17,8.2]],"id":26349442},{"atl":[[130,8.2]],"id":40917619},{"atl":[[15.5,8.2]],"id":39183170}],"con":true,"img":false}]}
{"op":"mcm","clk":"5348395341","pt":1646217245955,"mc":[{"id":"1.195453631","rc":[{"atl":[[22,14.2]],"id":26349442},{"atl":[[150,14.2]],"id":40917619},{"atl":[[6,8.2]],"id":41398505},{"atl":[[19.5,14.2]],"id":39183170},{"atl":[[190,14.2]],"id":38554545}],"con":true,"img":false}]}
{"op":"mcm","clk":"5348395349","pt":1646217246064,"mc":[{"id":"1.195453631","rc":[{"atb":[[2.62,46.3]],"id":40637101},{"atb":[[2.62,46.3]],"id":36120434},{"atl":[[7.6,14.2]],"id":41398505},{"atb":[[2.62,46.3]],"id":35381686}],"con":true,"img":false}]}
{"op":"mcm","clk":"5348395361","pt":1646217246164,"mc":[{"id":"1.195453631","rc":[{"atb":[[4.2,26.56]],"id":36120434},{"atb":[[2.62,46.3]],"id":40917619},{"atb":[[2.62,46.3]],"id":38554545}],"con":true,"img":false}]}
{"op":"mcm","clk":"5348395372","pt":1646217246268,"mc":[{"id":"1.195453631","rc":[{"atl":[[34,13.5]],"id":26349442},{"atb":[[4.2,26.56]],"id":40637101},{"atl":[[17,8.5],[34,13.5]],"id":41398505},{"atl":[[34,13.5]],"id":39183170},{"atb":[[4.2,26.56]],"id":35381686}],"con":true,"img":false}]}
{"op":"mcm","clk":"5348402505","pt":1646217323003,"mc":[{"id":"1.195453631","rc":[{"atb":[[3,54.36],[3.5,23.38]],"id":26349442},{"atl":[[9.2,13.25],[7,9.74]],"id":26349442},{"spn":5.27,"spf":"NaN","id":26349442},{"atb":[[10.5,13.62],[13,4.87]],"id":40637101},{"atl":[[42,2.72],[55,2.72]],"id":40637101},{"spn":28.5,"spf":"NaN","id":40637101},{"atb":[[17.5,3.54],[14,9.15]],"id":36120434},{"atl":[[70,2.72],[95,2.72]],"id":36120434},{"spn":45.5,"spf":"NaN","id":36120434},{"atb":[[6.4,25.41],[7.8,8.59]],"id":40917619},{"atl":[[20,3.07],[28,4.61]],"id":40917619},{"spn":14.1,"spf":"NaN","id":40917619},{"atb":[[2.38,42.35],[2.18,107.9]],"id":41398505},{"atl":[[5.6,27.79],[4.2,18.26]],"id":41398505},{"atb":[[3.2,59.4],[3.3,25.41]],"id":39183170},{"atl":[[8.2,17.98],[6.6,10.43]],"id":39183170},{"spn":4.97,"spf":"NaN","id":39183170},{"atb":[[17,8.71],[22,3.27]],"id":35381686},{"atl":[[150,2.72],[110,2.72]],"id":35381686},{"spn":66.0,"spf":"NaN","id":35381686},{"atb":[[6.8,20.06],[8.8,7.49]],"id":38554545},{"atl":[[21,2.92],[30,4.01]],"id":38554545},{"spn":14.9,"spf":"NaN","id":38554545}],"con":true,"img":false}]}
{"op":"mcm","clk":"5348402798","pt":1646217325785,"mc":[{"id":"1.195453631","rc":[{"atb":[[1.65,110.77]],"id":41398505},{"atb":[[2.16,62.07]],"id":39183170}],"con":true,"img":false}]}
{"op":"mcm","clk":"5348402808","pt":1646217325897,"mc":[{"id":"1.195453631","rc":[{"atb":[[1.38,215.79]],"id":41398505},{"atb":[[1.7,117.14]],"id":39183170}],"con":true,"img":false}]}
{"op":"mcm","clk":"5348403323","pt":1646217330881,"mc":[{"id":"1.195453631","rc":[{"atb":[[2.92,4.34]],"id":26349442},{"atb":[[5.4,1.89]],"id":40917619},{"atb":[[2.2,0]],"id":41398505},{"atb":[[2.8,4.63]],"id":39183170},{"atb":[[5.9,1.7]],"id":38554545}],"con":true,"img":false}]}
{"op":"mcm","clk":"5348404173","pt":1646217339913,"mc":[{"id":"1.195453631","rc":[{"atb":[[3.55,4.94]],"id":26349442},{"atb":[[2.42,7.29]],"id":41398505},{"atb":[[3.35,5.2]],"id":39183170}],"con":true,"img":false}]}
{"op":"mcm","clk":"5348404185","pt":1646217340017,"mc":[{"id":"1.195453631","rc":[{"atb":[[1.01,2.25]],"id":40917619}],"con":true,"img":false}]}
{"op":"mcm","clk":"5348404205","pt":1646217340182,"mc":[{"id":"1.195453631","rc":[{"atb":[[1.01,1.34]],"id":40917619}],"con":true,"img":false}]}
{"op":"mcm","clk":"5348404221","pt":1646217340392,"mc":[{"id":"1.195453631","rc":[{"atb":[[1.01,0]],"id":40917619}],"con":true,"img":false}]}
{"op":"mcm","clk":"5348404231","pt":1646217340495,"mc":[{"id":"1.195453631","rc":[{"atb":[[6.6,1.34]],"id":40917619}],"con":true,"img":false}]}
{"op":"mcm","clk":"5348405328","pt":1646217352627,"mc":[{"id":"1.195453631","rc":[{"atb":[[2.92,0]],"id":26349442},{"atb":[[5.4,0]],"id":40917619},{"atb":[[2.1,0]],"id":41398505},{"atb":[[2.8,0]],"id":39183170},{"atb":[[5.9,0]],"id":38554545}],"con":true,"img":false}]}
{"op":"mcm","clk":"5348406743","pt":1646217367439,"mc":[{"id":"1.195453631","rc":[{"atb":[[3.35,8.75]],"id":39183170}],"con":true,"img":false}]}
{"op":"mcm","clk":"5348406755","pt":1646217367543,"mc":[{"id":"1.195453631","rc":[{"atb":[[3.55,8.21]],"id":26349442}],"con":true,"img":false}]}
{"op":"mcm","clk":"5348406771","pt":1646217367749,"mc":[{"id":"1.195453631","rc":[{"atb":[[2.42,13.16]],"id":41398505}],"con":true,"img":false}]}
{"op":"mcm","clk":"5348406798","pt":1646217368058,"mc":[{"id":"1.195453631","rc":[{"atb":[[1.01,1.66]],"id":40917619}],"con":true,"img":false}]}
{"op":"mcm","clk":"5348406824","pt":1646217368324,"mc":[{"id":"1.195453631","rc":[{"atb":[[1.01,1.49]],"id":40917619}],"con":true,"img":false}]}
{"op":"mcm","clk":"5348406897","pt":1646217369318,"mc":[{"id":"1.195453631","rc":[{"atb":[[1.01,0]],"id":40917619}],"con":true,"img":false}]}
{"op":"mcm","clk":"5348406904","pt":1646217369421,"mc":[{"id":"1.195453631","rc":[{"atb":[[6.6,2.83]],"id":40917619}],"con":true,"img":false}]}
{"op":"mcm","clk":"5348410180","pt":1646217406463,"mc":[{"id":"1.195453631","rc":[{"atb":[[17.5,0],[14,0]],"id":36120434},{"atb":[[6.4,0],[7.8,26.9]],"id":40917619}],"con":true,"img":false}]}
{"op":"mcm","clk":"5348410189","pt":1646217406565,"mc":[{"id":"1.195453631","rc":[{"atb":[[16,9.15],[18,3.54]],"id":36120434}],"con":true,"img":false}]}
{"op":"mcm","clk":"5348410948","pt":1646217415097,"mc":[{"id":"1.195453631","rc":[{"atb":[[6.6,1.49]],"id":40917619}],"con":true,"img":false}]}
{"op":"mcm","clk":"5348412186","pt":1646217427738,"mc":[{"id":"1.195453631","rc":[{"atb":[[6.6,0]],"id":40917619}],"con":true,"img":false}]}
{"op":"mcm","clk":"5348503121","pt":1646218255466,"mc":[{"id":"1.195453631","rc":[{"atl":[[50,8.2]],"id":38554545}],"con":true,"img":false}]}
{"op":"mcm","clk":"5348503131","pt":1646218255563,"mc":[{"id":"1.195453631","rc":[{"atl":[[180,14.2]],"id":40637101}],"con":true,"img":false}]}
{"op":"mcm","clk":"5348581374","pt":1646219046737,"mc":[{"id":"1.195453631","rc":[{"atb":[[3.45,16.68],[2.88,43.48],[3,54.36],[3.55,8.2],[2.98,20.64],[3.5,23.38],[2.78,102.1],[2.68,97.32]],"id":26349442},{"atl":[[16,13.32],[9.2,13.26],[11,13.32],[11.5,9.52],[13.5,15.98],[7,9.74],[9.4,15.86]],"id":26349442},{"atb":[[6.4,30.28],[10.5,13.62],[7.4,12.77],[13,4.87],[13.5,3.27],[8.4,11.04],[9.4,4.86],[5.4,22.73]],"id":40637101},{"atl":[[42,2.72],[55,2.72],[120,2]],"id":40637101},{"atb":[[16,9.15],[18,3.54],[9.2,19.94],[5.8,20.83],[21,2.55],[10.5,8.6],[13,6.81],[15.5,2.81]],"id":36120434},{"atl":[[70,2.72],[150,2],[95,2.72]],"id":36120434},{"atb":[[4.8,21.51],[4.3,71.36],[5.8,8.51],[5.3,19.01],[7.6,6.19],[3.15,44.07],[7.8,26.9]],"id":40917619},{"atl":[[65,3.12],[36,3.8],[20,6.87],[90,2.24],[46,2.95],[28,4.61]],"id":40917619},{"atb":[[2.36,30.05],[2.06,77.12],[1.98,83.42],[2.42,13.14],[2.38,42.35],[2.18,107.91],[1.93,175.81],[2.16,35.24]],"id":41398505},{"atl":[[4,8.17],[5.6,27.79],[3.6,4.92],[6.4,24.66],[7.4,31.21],[5.7,28.34],[4.2,18.26],[8.4,27]],"id":41398505},{"atb":[[2.56,104.81],[3.2,59.4],[2.86,21.97],[3.35,8.74],[2.66,49.24],[3.15,19.01],[2.84,49.25],[3.3,25.41],[2.76,46.45]],"id":39183170},{"atl":[[8.2,17.98],[11,19.98],[13.5,15.98],[27,3.85],[6.6,10.43],[8.4,18],[9.4,15.86]],"id":39183170},{"atb":[[17,8.72],[9.2,19.94],[21,2.04],[10.5,8.6],[22,3.27],[7.6,15.15],[13,6.81],[15.5,2.81]],"id":35381686},{"atl":[[150,2.72],[600,2],[110,2.72]],"id":35381686},{"atb":[[4.8,61.97],[8.6,6.7],[5.8,17.03],[5.3,19.01],[6.8,20.06],[8.8,7.49],[6.6,7.29]],"id":38554545},{"atl":[[65,2.08],[21,2.92],[90,2.24],[46,2.95],[30,4.01]],"id":38554545}],"con":true,"img":false}]}
{"op":"mcm","clk":"5348581396","pt":1646219046940,"mc":[{"id":"1.195453631","rc":[{"atb":[[2.26,77.12]],"id":41398505},{"atl":[[6.6,17.86]],"id":41398505}],"con":true,"img":false}]}
{"op":"mcm","clk":"5348581913","pt":1646219052625,"mc":[{"id":"1.195453631","rc":[{"atb":[[3.45,40.82]],"id":38554545},{"atl":[[26,4]],"id":38554545}],"con":true,"img":false}]}
{"op":"mcm","clk":"5348582231","pt":1646219055809,"mc":[{"id":"1.195453631","rc":[{"atl":[[110,1.14]],"id":35381686},{"trd":[[110,3.15]],"ltp":110.0,"tv":3.15,"id":35381686}],"con":true,"img":false}]}
{"op":"mcm","clk":"5348583746","pt":1646219071142,"mc":[{"id":"1.195453631","rc":[{"atb":[[16,0],[18,0]],"id":36120434},{"atb":[[13,0]],"id":40637101},{"atb":[[3.2,0],[3.3,0]],"id":39183170},{"atl":[[150,0]],"id":35381686},{"atb":[[8.8,0]],"id":38554545}],"con":true,"img":false}]}
{"op":"mcm","clk":"5348583759","pt":1646219071247,"mc":[{"id":"1.195453631","rc":[{"atb":[[13.5,9.15],[15.5,6.36]],"id":36120434},{"atb":[[11.5,4.87]],"id":40637101},{"atb":[[6,25.41]],"id":40917619},{"atb":[[3.2,25.41],[2.88,59.4]],"id":39183170},{"atl":[[190,2.72]],"id":35381686},{"atb":[[7.8,7.49]],"id":38554545}],"con":true,"img":false}]}
{"op":"mcm","clk":"5348583785","pt":1646219071456,"mc":[{"id":"1.195453631","rc":[{"atb":[[7.8,18.31]],"id":40917619}],"con":true,"img":false}]}
{"op":"mcm","clk":"5348583796","pt":1646219071562,"mc":[{"id":"1.195453631","rc":[{"atb":[[7.2,8.59],[6,0],[7.8,0]],"id":40917619},{"atl":[[110,0]],"id":35381686}],"con":true,"img":false}]}
{"op":"mcm","clk":"5348585175","pt":1646219080163,"mc":[{"id":"1.195453631","rc":[{"atb":[[3.35,5.54]],"id":39183170}],"con":true,"img":false}]}
{"op":"mcm","clk":"5348586188","pt":1646219089161,"mc":[{"id":"1.195453631","rc":[{"atb":[[1.01,2.25]],"id":40917619},{"atb":[[3.25,3.33]],"id":39183170}],"con":true,"img":false}]}
{"op":"mcm","clk":"5348586206","pt":1646219089370,"mc":[{"id":"1.195453631","rc":[{"atb":[[1.01,1.7]],"id":40917619}],"con":true,"img":false}]}
{"op":"mcm","clk":"5348586234","pt":1646219089676,"mc":[{"id":"1.195453631","rc":[{"atb":[[1.01,0]],"id":40917619}],"con":true,"img":false}]}
{"op":"mcm","clk":"5348586239","pt":1646219089778,"mc":[{"id":"1.195453631","rc":[{"atb":[[5.4,1.7]],"id":40917619}],"con":true,"img":false}]}
{"op":"mcm","clk":"5348586630","pt":1646219093880,"mc":[{"id":"1.195453631","rc":[{"atl":[[7,0]],"id":26349442},{"atl":[[42,0]],"id":40637101},{"atl":[[20,3.8]],"id":40917619},{"atl":[[4.2,0]],"id":41398505},{"atl":[[6.6,0]],"id":39183170},{"atb":[[22,0.49],[25,1.3]],"id":35381686},{"atl":[[130,0.04]],"id":35381686},{"atl":[[21,0]],"id":38554545}],"con":true,"img":false}]}
{"op":"mcm","clk":"5348586641","pt":1646219093979,"mc":[{"id":"1.195453631","rc":[{"atl":[[6,9.74]],"id":26349442},{"atl":[[38,2.72]],"id":40637101},{"atl":[[17,3.07]],"id":40917619},{"atl":[[3.8,18.26]],"id":41398505},{"atl":[[5.7,10.43]],"id":39183170},{"atl":[[18.5,2.92]],"id":38554545}],"con":true,"img":false}]}
{"op":"mcm","clk":"5348586650","pt":1646219094083,"mc":[{"id":"1.195453631","rc":[{"atl":[[20,0],[27,3.85]],"id":40917619},{"atl":[[26,0],[29,3.57]],"id":38554545}],"con":true,"img":false}]}
{"op":"mcm","clk":"5348586663","pt":1646219094189,"mc":[{"id":"1.195453631","rc":[{"atl":[[20,5.26],[27,0]],"id":40917619},{"atl":[[26,4],[29,0]],"id":38554545}],"con":true,"img":false}]}
{"op":"mcm","clk":"5348587432","pt":1646219101884,"mc":[{"id":"1.195453631","rc":[{"atb":[[3.35,2]],"id":39183170}],"con":true,"img":false}]}
{"op":"mcm","clk":"5348587455","pt":1646219102089,"mc":[{"id":"1.195453631","rc":[{"atb":[[5.4,3.59]],"id":40917619}],"con":true,"img":false}]}
{"op":"mcm","clk":"5348588784","pt":1646219112195,"mc":[{"id":"1.195453631","rc":[{"spn":4.77,"spf":"NaN","id":26349442},{"spn":26.5,"spf":"NaN","id":40637101},{"atb":[[7.2,0],[6,25.41]],"id":40917619},{"atl":[[19.5,6.73],[28,0]],"id":40917619},{"spn":12.6,"spf":"NaN","id":40917619},{"spn":4.52,"spf":"NaN","id":39183170},{"atb":[[17,0],[22,7.03]],"id":35381686},{"spn":77.5,"spf":"NaN","id":35381686},{"atl":[[25,4.85],[30,0]],"id":38554545},{"spn":13.55,"spf":"NaN","id":38554545}],"con":true,"img":false}]}
{"op":"mcm","clk":"5348588816","pt":1646219112393,"mc":[{"id":"1.195453631","rc":[{"atb":[[7.8,8.59]],"id":40917619}],"con":true,"img":false}]}
{"op":"mcm","clk":"5348588854","pt":1646219112604,"mc":[{"id":"1.195453631","rc":[{"atb":[[10.5,0],[11.5,0]],"id":40637101}],"con":true,"img":false}]}
{"op":"mcm","clk":"5348588870","pt":1646219112710,"mc":[{"id":"1.195453631","rc":[{"atb":[[10,4.87],[9.6,13.62]],"id":40637101}],"con":true,"img":false}]}
{"op":"mcm","clk":"5348590211","pt":1646219122245,"mc":[{"id":"1.195453631","rc":[{"atb":[[5.4,1.89]],"id":40917619}],"con":true,"img":false}]}
{"op":"mcm","clk":"5348591451","pt":1646219131240,"mc":[{"id":"1.195453631","rc":[{"atb":[[1.01,2.25]],"id":40917619}],"con":true,"img":false}]}
{"op":"mcm","clk":"5348591470","pt":1646219131447,"mc":[{"id":"1.195453631","rc":[{"atb":[[1.01,1.44]],"id":40917619}],"con":true,"img":false}]}
{"op":"mcm","clk":"5348591503","pt":1646219131648,"mc":[{"id":"1.195453631","rc":[{"atb":[[1.01,0]],"id":40917619}],"con":true,"img":false}]}
{"op":"mcm","clk":"5348591517","pt":1646219131752,"mc":[{"id":"1.195453631","rc":[{"atb":[[6.2,1.44]],"id":40917619}],"con":true,"img":false}]}
{"op":"mcm","clk":"5348593928","pt":1646219150170,"mc":[{"id":"1.195453631","rc":[{"atl":[[17,0]],"id":40917619}],"con":true,"img":false}]}
{"op":"mcm","clk":"5348593941","pt":1646219150268,"mc":[{"id":"1.195453631","rc":[{"atl":[[16.5,3.07]],"id":40917619}],"con":true,"img":false}]}
{"op":"mcm","clk":"5348596342","pt":1646219170088,"mc":[{"id":"1.195453631","rc":[{"atb":[[2.18,0]],"id":41398505},{"atl":[[5.6,0],[3.95,43.05]],"id":41398505}],"con":true,"img":false}]}
{"op":"mcm","clk":"5348596352","pt":1646219170192,"mc":[{"id":"1.195453631","rc":[{"atb":[[2.28,107.91]],"id":41398505}],"con":true,"img":false}]}
{"op":"mcm","clk":"5348598696","pt":1646219190232,"mc":[{"id":"1.195453631","rc":[{"atb":[[10,0]],"id":40637101},{"spn":12.35,"spf":"NaN","id":40917619}],"con":true,"img":false}]}
{"op":"mcm","clk":"5348598709","pt":1646219190336,"mc":[{"id":"1.195453631","rc":[{"atb":[[11,4.87]],"id":40637101}],"con":true,"img":false}]}
{"op":"mcm","clk":"5348600165","pt":1646219202622,"mc":[{"id":"1.195453631","rc":[{"atb":[[7.8,0]],"id":38554545}],"con":true,"img":false}]}
{"op":"mcm","clk":"5348600176","pt":1646219202723,"mc":[{"id":"1.195453631","rc":[{"atb":[[7.4,7.49]],"id":38554545}],"con":true,"img":false}]}
{"op":"mcm","clk":"5348602210","pt":1646219219653,"mc":[{"id":"1.195453631","rc":[{"atl":[[1000,2.25]],"id":36120434},{"atb":[[1.02,2.25]],"id":40917619},{"atb":[[1.05,2.25]],"id":35381686},{"atb":[[1.02,2.25]],"id":38554545}],"con":true,"img":false}]}
{"op":"mcm","clk":"5348602231","pt":1646219219861,"mc":[{"id":"1.195453631","rc":[{"atl":[[1000,0.06]],"id":36120434},{"atb":[[1.02,0.45]],"id":40917619},{"atb":[[1.05,0.14]],"id":35381686},{"atb":[[1.02,0.42]],"id":38554545}],"con":true,"img":false}]}
{"op":"mcm","clk":"5348602247","pt":1646219219972,"mc":[{"id":"1.195453631","rc":[{"atb":[[1.02,0]],"id":40917619}],"con":true,"img":false}]}
{"op":"mcm","clk":"5348602260","pt":1646219220071,"mc":[{"id":"1.195453631","rc":[{"atb":[[8.4,0.45]],"id":40917619}],"con":true,"img":false}]}
{"op":"mcm","clk":"5348602273","pt":1646219220179,"mc":[{"id":"1.195453631","rc":[{"atl":[[1000,0]],"id":36120434}],"con":true,"img":false}]}
{"op":"mcm","clk":"5348602283","pt":1646219220283,"mc":[{"id":"1.195453631","rc":[{"atl":[[65,0.06]],"id":36120434}],"con":true,"img":false}]}
{"op":"mcm","clk":"5348602310","pt":1646219220487,"mc":[{"id":"1.195453631","rc":[{"atb":[[1.05,0]],"id":35381686}],"con":true,"img":false}]}
{"op":"mcm","clk":"5348602319","pt":1646219220593,"mc":[{"id":"1.195453631","rc":[{"atb":[[26,0.14]],"id":35381686}],"con":true,"img":false}]}
{"op":"mcm","clk":"5348602354","pt":1646219220857,"mc":[{"id":"1.195453631","rc":[{"atb":[[1.02,0]],"id":38554545}],"con":true,"img":false}]}
{"op":"mcm","clk":"5348602364","pt":1646219220962,"mc":[{"id":"1.195453631","rc":[{"atb":[[8.8,0.42]],"id":38554545}],"con":true,"img":false}]}
{"op":"mcm","clk":"5348609012","pt":1646219276585,"mc":[{"id":"1.195453631","rc":[{"spn":43.0,"spf":"NaN","id":36120434},{"atb":[[1.03,2.25]],"id":40637101},{"spn":12.45,"spf":"NaN","id":40917619},{"spn":78.0,"spf":"NaN","id":35381686},{"spn":13.65,"spf":"NaN","id":38554545}],"con":true,"img":false}]}
{"op":"mcm","clk":"5348609034","pt":1646219276742,"mc":[{"id":"1.195453631","rc":[{"atb":[[1.03,0.24]],"id":40637101},{"atl":[[4,0]],"id":41398505}],"con":true,"img":false}]}
{"op":"mcm","clk":"5348609056","pt":1646219276954,"mc":[{"id":"1.195453631","rc":[{"atb":[[1.03,0]],"id":40637101}],"con":true,"img":false}]}
{"op":"mcm","clk":"5348609069","pt":1646219277059,"mc":[{"id":"1.195453631","rc":[{"atb":[[15.5,0.24]],"id":40637101}],"con":true,"img":false}]}
{"op":"mcm","clk":"5348611554","pt":1646219296494,"mc":[{"id":"1.195453631","rc":[{"atl":[[5.1,27.79],[3.95,0]],"id":41398505}],"con":true,"img":false}]}
{"op":"mcm","clk":"5348611569","pt":1646219296604,"mc":[{"id":"1.195453631","rc":[{"atl":[[3.95,8.17]],"id":41398505}],"con":true,"img":false}]}
{"op":"mcm","clk":"5348612066","pt":1646219301005,"mc":[{"id":"1.195453631","rc":[{"atb":[[3.25,7.03]],"id":39183170}],"con":true,"img":false}]}
{"op":"mcm","clk":"5348615111","pt":1646219325549,"mc":[{"id":"1.195453631","rc":[{"atb":[[5.4,0]],"id":40917619}],"con":true,"img":false}]}
{"op":"mcm","clk":"5348617554","pt":1646219345458,"mc":[{"id":"1.195453631","rc":[{"spn":26.75,"spf":"NaN","id":40637101},{"atb":[[1.01,1.66]],"id":40917619}],"con":true,"img":false}]}
{"op":"mcm","clk":"5348617582","pt":1646219345767,"mc":[{"id":"1.195453631","rc":[{"atb":[[1.01,1.59]],"id":40917619}],"con":true,"img":false}]}
{"op":"mcm","clk":"5348617639","pt":1646219346284,"mc":[{"id":"1.195453631","rc":[{"atb":[[1.01,0]],"id":40917619}],"con":true,"img":false}]}
{"op":"mcm","clk":"5348617653","pt":1646219346388,"mc":[{"id":"1.195453631","rc":[{"atb":[[6.2,3.04]],"id":40917619}],"con":true,"img":false}]}
{"op":"mcm","clk":"5348620836","pt":1646219373109,"mc":[{"id":"1.195453631","rc":[{"atl":[[5.1,0],[3.9,44.14]],"id":41398505}],"con":true,"img":false}]}
{"op":"mcm","clk":"5348653806","pt":1646219654959,"mc":[{"id":"1.195453631","rc":[{"atb":[[5.4,0],[3.9,34.48]],"id":40637101},{"atb":[[3.45,40.82],[3.15,0]],"id":40917619},{"atb":[[2.3,76.92],[2.26,0]],"id":41398505},{"atb":[[2.84,0],[2.96,49.25]],"id":39183170},{"atl":[[550,2],[600,0]],"id":35381686},{"atb":[[3.45,0],[3.1,46.3]],"id":38554545}],"con":true,"img":false}]}
{"op":"mcm","clk":"5348653828","pt":1646219655160,"mc":[{"id":"1.195453631","rc":[{"atl":[[3.95,0]],"id":41398505}],"con":true,"img":false}]}
{"op":"mcm","clk":"5348655801","pt":1646219673202,"mc":[{"id":"1.195453631","rc":[{"atb":[[2.78,45.92],[2.94,51.55]],"id":26349442},{"atl":[[19,5.56],[20,0]],"id":40917619},{"atb":[[2.3,0],[2.2,83.33]],"id":41398505}],"con":true,"img":false}]}
{"op":"mcm","clk":"5348656027","pt":1646219675290,"mc":[{"id":"1.195453631","rc":[{"atl":[[5.1,27.79]],"id":41398505}],"con":true,"img":false}]}
{"op":"mcm","clk":"5348656040","pt":1646219675393,"mc":[{"id":"1.195453631","rc":[{"atb":[[2.28,0]],"id":41398505},{"atl":[[3.9,0]],"id":41398505}],"con":true,"img":false}]}
{"op":"mcm","clk":"5348656048","pt":1646219675501,"mc":[{"id":"1.195453631","rc":[{"atb":[[2.22,107.91]],"id":41398505}],"con":true,"img":false}]}
{"op":"mcm","clk":"5348656125","pt":1646219676210,"mc":[{"id":"1.195453631","rc":[{"atl":[[3.95,8.17]],"id":41398505}],"con":true,"img":false}]}
{"op":"mcm","clk":"5348657211","pt":1646219686038,"mc":[{"id":"1.195453631","rc":[{"atb":[[5.9,20.41],[3.9,0]],"id":40637101},{"atb":[[3,49.25]],"id":39183170},{"atb":[[3.1,0],[3.65,37.74]],"id":38554545}],"con":true,"img":false}]}
{"op":"mcm","clk":"5348657227","pt":1646219686249,"mc":[{"id":"1.195453631","rc":[{"atb":[[2.96,0]],"id":39183170}],"con":true,"img":false}]}
{"op":"mcm","clk":"5348659123","pt":1646219704053,"mc":[{"id":"1.195453631","rc":[{"atl":[[18.5,5.71],[19,0]],"id":40917619}],"con":true,"img":false}]}
{"op":"mcm","clk":"5348659132","pt":1646219704160,"mc":[{"id":"1.195453631","rc":[{"atb":[[2.36,103.58],[2.2,0]],"id":41398505}],"con":true,"img":false}]}
{"op":"mcm","clk":"5348659961","pt":1646219711354,"mc":[{"id":"1.195453631","rc":[{"atl":[[19.5,0]],"id":40917619},{"atb":[[2.22,0]],"id":41398505},{"atb":[[2.88,0]],"id":39183170}],"con":true,"img":false}]}
{"op":"mcm","clk":"5348659974","pt":1646219711453,"mc":[{"id":"1.195453631","rc":[{"atl":[[18,6.73]],"id":40917619},{"atb":[[2.18,107.91]],"id":41398505},{"atb":[[3.05,59.4]],"id":39183170}],"con":true,"img":false}]}
{"op":"mcm","clk":"5348661716","pt":1646219725400,"mc":[{"id":"1.195453631","rc":[{"atl":[[17,16.7]],"id":26349442},{"atl":[[17,8.5]],"id":39183170}],"con":true,"img":false}]}
{"op":"mcm","clk":"5348663858","pt":1646219743401,"mc":[{"id":"1.195453631","rc":[{"atl":[[5.1,0],[3.9,44.14]],"id":41398505}],"con":true,"img":false}]}
{"op":"mcm","clk":"5348666016","pt":1646219762242,"mc":[{"id":"1.195453631","rc":[{"atb":[[1.04,1.66]],"id":26349442},{"atb":[[1.04,1.66]],"id":41398505},{"atb":[[1.04,1.66]],"id":39183170}],"con":true,"img":false}]}
{"op":"mcm","clk":"5348666041","pt":1646219762442,"mc":[{"id":"1.195453631","rc":[{"atb":[[1.04,1.65]],"id":26349442},{"atb":[[1.04,1.65]],"id":41398505},{"atb":[[1.04,1.65]],"id":39183170}],"con":true,"img":false}]}
{"op":"mcm","clk":"5348666058","pt":1646219762649,"mc":[{"id":"1.195453631","rc":[{"atb":[[1.04,0]],"id":26349442},{"atb":[[1.04,0]],"id":41398505},{"atb":[[1.04,0]],"id":39183170}],"con":true,"img":false}]}
{"op":"mcm","clk":"5348666070","pt":1646219762753,"mc":[{"id":"1.195453631","rc":[{"atb":[[3.65,1.65]],"id":26349442},{"atb":[[2.48,1.65]],"id":41398505},{"atb":[[3.35,3.65]],"id":39183170}],"con":true,"img":false}]}
{"op":"mcm","clk":"5348669583","pt":1646219793204,"mc":[{"id":"1.195453631","rc":[{"atb":[[2.78,102.1],[2.94,0]],"id":26349442},{"spn":4.82,"spf":"NaN","id":26349442},{"atb":[[3.45,0],[3.15,44.07]],"id":40917619},{"atl":[[18.5,0],[20,5.26]],"id":40917619},{"atb":[[2.36,30.05],[2.26,77.13]],"id":41398505},{"spn":3.04,"spf":"NaN","id":41398505},{"atb":[[3,0],[2.84,49.25]],"id":39183170}],"con":true,"img":false}]}
{"op":"mcm","clk":"5348680141","pt":1646219804739,"mc":[{"id":"1.195453631","rc":[{"atl":[[18,0]],"id":40917619},{"atb":[[3.05,0]],"id":39183170}],"con":true,"img":false}]}
{"op":"mcm","clk":"5348680153","pt":1646219804796,"mc":[{"id":"1.195453631","rc":[{"atl":[[19.5,6.73]],"id":40917619},{"atb":[[2.88,59.4]],"id":39183170}],"con":true,"img":false}]}
{"op":"mcm","clk":"5348680447","pt":1646219807628,"mc":[{"id":"1.195453631","rc":[{"atl":[[3.95,0]],"id":41398505}],"con":true,"img":false}]}
{"op":"mcm","clk":"5348680804","pt":1646219809709,"mc":[{"id":"1.195453631","rc":[{"spl":[[1.01,2.72]],"id":36120434}],"con":true,"img":false}]}
{"op":"mcm","clk":"5348681609","pt":1646219815135,"mc":[{"id":"1.195453631","rc":[{"spl":[[1.01,2.72]],"id":40637101}],"con":true,"img":false}]}
{"op":"mcm","clk":"5348682328","pt":1646219820754,"mc":[{"id":"1.195453631","rc":[{"spl":[[1.01,2.72]],"id":35381686}],"con":true,"img":false}]}
{"op":"mcm","clk":"5348682942","pt":1646219825641,"mc":[{"id":"1.195453631","rc":[{"atl":[[5.1,27.79]],"id":41398505}],"con":true,"img":false}]}
{"op":"mcm","clk":"5348682955","pt":1646219825743,"mc":[{"id":"1.195453631","rc":[{"atl":[[3.9,0]],"id":41398505}],"con":true,"img":false}]}
{"op":"mcm","clk":"5348682965","pt":1646219825848,"mc":[{"id":"1.195453631","rc":[{"atl":[[3.95,8.17]],"id":41398505}],"con":true,"img":false}]}
{"op":"mcm","clk":"5348683674","pt":1646219831678,"mc":[{"id":"1.195453631","rc":[{"spl":[[1.01,2.72]],"id":40917619}],"con":true,"img":false}]}
{"op":"mcm","clk":"5348684431","pt":1646219837967,"mc":[{"id":"1.195453631","rc":[{"spl":[[1.01,2.72]],"id":38554545}],"con":true,"img":false}]}
{"op":"mcm","clk":"5348686959","pt":1646219858818,"mc":[{"id":"1.195453631","rc":[{"spn":14.07,"spf":1.0,"id":40637101},{"spn":20.65,"spf":1.0,"id":36120434},{"spn":8.1,"spf":1.0,"id":40917619},{"atb":[[2.18,0]],"id":41398505},{"spn":23.64,"spf":1.0,"id":35381686},{"spn":8.63,"spf":1.0,"id":38554545}],"con":true,"img":false}]}
{"op":"mcm","clk":"5348686974","pt":1646219858918,"mc":[{"id":"1.195453631","rc":[{"atb":[[2.28,107.91]],"id":41398505}],"con":true,"img":false}]}
{"op":"mcm","clk":"5348691960","pt":1646219896673,"mc":[{"id":"1.195453631","rc":[{"atl":[[5.1,0],[3.9,44.14]],"id":41398505}],"con":true,"img":false}]}
{"op":"mcm","clk":"5348708490","pt":1646220025587,"mc":[{"id":"1.195453631","rc":[{"atl":[[140,8.2]],"id":40637101}],"con":true,"img":false}]}
{"op":"mcm","clk":"5348708515","pt":1646220025794,"mc":[{"id":"1.195453631","rc":[{"atl":[[3.95,0]],"id":41398505}],"con":true,"img":false}]}
{"op":"mcm","clk":"5348709183","pt":1646220031120,"mc":[{"id":"1.195453631","rc":[{"atl":[[5.1,27.79],[3.9,0]],"id":41398505}],"con":true,"img":false}]}
{"op":"mcm","clk":"5348709204","pt":1646220031332,"mc":[{"id":"1.195453631","rc":[{"atl":[[3.95,8.17]],"id":41398505}],"con":true,"img":false}]}
{"op":"mcm","clk":"5348716211","pt":1646220088804,"mc":[{"id":"1.195453631","rc":[{"atl":[[5.1,0],[3.9,44.14]],"id":41398505}],"con":true,"img":false}]}
{"op":"mcm","clk":"5348721674","pt":1646220130601,"mc":[{"id":"1.195453631","rc":[{"spl":[[1.01,6.72]],"id":40637101},{"spl":[[1.01,6.72]],"id":36120434},{"spl":[[1.01,6.72]],"id":40917619},{"spl":[[1.01,6.72]],"id":35381686},{"spl":[[1.01,6.72]],"id":38554545}],"con":true,"img":false}]}
{"op":"mcm","clk":"5348722564","pt":1646220137897,"mc":[{"id":"1.195453631","rc":[{"atl":[[20,5.26],[27,0]],"id":39183170}],"con":true,"img":false}]}
{"op":"mcm","clk":"5348733745","pt":1646220228854,"mc":[{"id":"1.195453631","rc":[{"spn":17.58,"spf":1.0,"id":36120434},{"spn":12.8,"spf":1.0,"id":40637101},{"spn":7.92,"spf":1.0,"id":40917619},{"atb":[[8.6,13.16],[7.6,0]],"id":35381686},{"spn":22.66,"spf":1.0,"id":35381686},{"spn":8.61,"spf":1.0,"id":38554545}],"con":true,"img":false}]}
{"op":"mcm","clk":"5348733770","pt":1646220229031,"mc":[{"id":"1.195453631","rc":[{"atl":[[3.95,0]],"id":41398505}],"con":true,"img":false}]}
{"op":"mcm","clk":"5348734752","pt":1646220237928,"mc":[{"id":"1.195453631","rc":[{"atl":[[5,27.79],[3.9,0]],"id":41398505},{"atb":[[7.4,0]],"id":38554545}],"con":true,"img":false}]}
{"op":"mcm","clk":"5348734765","pt":1646220238038,"mc":[{"id":"1.195453631","rc":[{"atl":[[3.95,8.17]],"id":41398505},{"atb":[[7.6,7.49]],"id":38554545}],"con":true,"img":false}]}
{"op":"mcm","clk":"5348742322","pt":1646220305469,"mc":[{"id":"1.195453631","rc":[{"atl":[[5,0],[3.9,44.14]],"id":41398505}],"con":true,"img":false}]}
{"op":"mcm","clk":"5348804290","pt":1646220835137,"mc":[{"id":"1.195453631","rc":[{"atb":[[2.64,60.98],[2.78,45.92]],"id":26349442},{"atb":[[10,11.11]],"id":35381686}],"con":true,"img":false}]}
{"op":"mcm","clk":"5348804294","pt":1646220835240,"mc":[{"id":"1.195453631","rc":[{"atb":[[8.6,0]],"id":35381686}],"con":true,"img":false}]}
{"op":"mcm","clk":"5348804312","pt":1646220835345,"mc":[{"id":"1.195453631","rc":[{"atl":[[3.95,0]],"id":41398505}],"con":true,"img":false}]}
{"op":"mcm","clk":"5348805443","pt":1646220844924,"mc":[{"id":"1.195453631","rc":[{"atb":[[3.7,2.49]],"id":26349442},{"atb":[[15.5,2.32]],"id":40637101},{"atb":[[8.4,2.94]],"id":40917619},{"atb":[[2.5,2.49]],"id":41398505},{"atb":[[3.4,2.49]],"id":39183170},{"atb":[[26,1.8]],"id":35381686}],"con":true,"img":false}]}
{"op":"mcm","clk":"5348805593","pt":1646220846148,"mc":[{"id":"1.195453631","rc":[{"atb":[[2.82,27.47],[2.86,10.75],[2.74,71.84],[2.78,88.05]],"id":26349442},{"atl":[[6.4,13.89],[5.8,4.17],[6.8,21.55],[6,19.74]],"id":26349442},{"atb":[[10.5,7.89],[11.5,4.76],[12.5,1.74],[9.8,14.2]],"id":40637101},{"atl":[[180,15.2],[200,1],[220,1],[240,1]],"id":40637101},{"atb":[[6.4,9.26],[5.8,46.87],[6.8,3.45],[6,15]],"id":36120434},{"atl":[[300,1.67],[320,1],[340,1],[360,1]],"id":36120434},{"atb":[[3.55,29.41],[3.75,7.27],[3.45,51.02],[3.65,18.87]],"id":40917619},{"atl":[[18,1.18],[19,2.78],[20,9.21],[22,5.95]],"id":40917619},{"atb":[[2.22,40.98],[2.26,93],[2.14,109.65],[2.18,63.56]],"id":41398505},{"atl":[[4.8,19.74],[4.4,5.88],[4.6,13.89],[5,31.25]],"id":41398505},{"atb":[[3.25,15.92],[2.98,63.13],[3.05,36.59],[3.15,42.27]],"id":39183170},{"atl":[[24,1],[26,2],[28,2.78],[30,4.31]],"id":39183170},{"atb":[[9.2,26.04],[8.4,16.89],[9.6,2.33],[8.8,9.62]],"id":35381686},{"atl":[[530,1],[550,3],[490,1],[510,1]],"id":35381686},{"atb":[[6.4,13.89],[6.8,28.68],[7.2,3.23],[6,25]],"id":38554545},{"atl":[[19.5,1.08],[21,2.5],[23,3.41],[25,10.06]],"id":38554545}],"con":true,"img":false}]}
{"op":"mcm","clk":"5348805634","pt":1646220846451,"mc":[{"id":"1.195453631","rc":[{"atl":[[4.5,36.51],[3.9,0]],"id":41398505}],"con":true,"img":false}]}
{"op":"mcm","clk":"5348805659","pt":1646220846664,"mc":[{"id":"1.195453631","rc":[{"atl":[[3.95,8.17]],"id":41398505}],"con":true,"img":false}]}
{"op":"mcm","clk":"5348806213","pt":1646220850961,"mc":[{"id":"1.195453631","rc":[{"atl":[[130,2],[150,0]],"id":36120434},{"atl":[[17.5,6.06],[20,3.95]],"id":40917619},{"atl":[[550,1],[500,2]],"id":35381686},{"atl":[[23,7.96],[26,0]],"id":38554545}],"con":true,"img":false}]}
{"op":"mcm","clk":"5348806894","pt":1646220856435,"mc":[{"id":"1.195453631","rc":[{"atb":[[15.5,2.81]],"id":36120434},{"atl":[[38,0]],"id":40637101}],"con":true,"img":false}]}
{"op":"mcm","clk":"5348806911","pt":1646220856575,"mc":[{"id":"1.195453631","rc":[{"atb":[[16,3.54]],"id":36120434},{"atl":[[40,2.72]],"id":40637101}],"con":true,"img":false}]}
{"op":"mcm","clk":"5348806926","pt":1646220856648,"mc":[{"id":"1.195453631","rc":[{"atl":[[100,2],[120,0]],"id":40637101}],"con":true,"img":false}]}
{"op":"mcm","clk":"5348808035","pt":1646220866392,"mc":[{"id":"1.195453631","rc":[{"atb":[[27,1.2]],"id":35381686}],"con":true,"img":false}]}
{"op":"mcm","clk":"5348808046","pt":1646220866443,"mc":[{"id":"1.195453631","rc":[{"atl":[[3.8,0]],"id":41398505},{"atb":[[25,0]],"id":35381686},{"atl":[[18.5,0]],"id":38554545}],"con":true,"img":false}]}
{"op":"mcm","clk":"5348808061","pt":1646220866553,"mc":[{"id":"1.195453631","rc":[{"atl":[[3.75,18.26]],"id":41398505},{"atb":[[3.2,0]],"id":39183170},{"atl":[[18,2.92]],"id":38554545}],"con":true,"img":false}]}
{"op":"mcm","clk":"5348808074","pt":1646220866658,"mc":[{"id":"1.195453631","rc":[{"atb":[[3.3,25.41]],"id":39183170}],"con":true,"img":false}]}
{"op":"mcm","clk":"5348808255","pt":1646220868181,"mc":[{"id":"1.195453631","rc":[{"atb":[[26,0.14]],"id":35381686}],"con":true,"img":false}]}
{"op":"mcm","clk":"5348809053","pt":1646220874787,"mc":[{"id":"1.195453631","rc":[{"atb":[[3.25,12.58]],"id":39183170}],"con":true,"img":false}]}
{"op":"mcm","clk":"5348809274","pt":1646220876365,"mc":[{"id":"1.195453631","rc":[{"atb":[[11,0]],"id":40637101},{"atl":[[19.5,0]],"id":40917619},{"atb":[[3.3,0]],"id":39183170}],"con":true,"img":false}]}
{"op":"mcm","clk":"5348809286","pt":1646220876467,"mc":[{"id":"1.195453631","rc":[{"atb":[[12,4.87]],"id":40637101},{"atl":[[17,6.73]],"id":40917619},{"atb":[[3.2,25.41]],"id":39183170}],"con":true,"img":false}]}
{"op":"mcm","clk":"5348810471","pt":1646220886403,"mc":[{"id":"1.195453631","rc":[{"atl":[[9.2,0],[6.2,20.91]],"id":26349442},{"atb":[[9.6,0]],"id":40637101},{"atl":[[4.5,0]],"id":41398505},{"atb":[[2.88,0]],"id":39183170},{"atl":[[20,6.12],[25,5.21]],"id":38554545}],"con":true,"img":false}]}
{"op":"mcm","clk":"5348810482","pt":1646220886501,"mc":[{"id":"1.195453631","rc":[{"atb":[[11,13.62]],"id":40637101},{"atl":[[4.3,36.51]],"id":41398505},{"atb":[[3.1,59.4]],"id":39183170}],"con":true,"img":false}]}
{"op":"mcm","clk":"5348811622","pt":1646220895705,"mc":[{"id":"1.195453631","rc":[{"spn":4.75,"spf":"NaN","id":26349442},{"spn":14.28,"spf":1.0,"id":40637101},{"spn":17.85,"spf":1.0,"id":36120434},{"spn":8.14,"spf":1.0,"id":40917619},{"spn":3.05,"spf":"NaN","id":41398505},{"atb":[[3.25,15.92]],"id":39183170},{"spn":4.55,"spf":"NaN","id":39183170},{"spn":22.98,"spf":1.0,"id":35381686}],"con":true,"img":false}]}
{"op":"mcm","clk":"5348811693","pt":1646220896384,"mc":[{"id":"1.195453631","rc":[{"atb":[[16,0]],"id":36120434}],"con":true,"img":false}]}
{"op":"mcm","clk":"5348811711","pt":1646220896502,"mc":[{"id":"1.195453631","rc":[{"atb":[[16.5,3.54]],"id":36120434}],"con":true,"img":false}]}
{"op":"mcm","clk":"5348815112","pt":1646220926448,"mc":[{"id":"1.195453631","rc":[{"atb":[[3.2,0]],"id":39183170}],"con":true,"img":false}]}
{"op":"mcm","clk":"5348815129","pt":1646220926553,"mc":[{"id":"1.195453631","rc":[{"atb":[[3.3,25.41]],"id":39183170}],"con":true,"img":false}]}
{"op":"mcm","clk":"5348815338","pt":1646220928323,"mc":[{"id":"1.195453631","rc":[{"atb":[[16.5,0]],"id":36120434}],"con":true,"img":false}]}
{"op":"mcm","clk":"5348815348","pt":1646220928430,"mc":[{"id":"1.195453631","rc":[{"atb":[[17,3.54]],"id":36120434}],"con":true,"img":false}]}
{"op":"mcm","clk":"5348815546","pt":1646220929948,"mc":[{"id":"1.195453631","rc":[{"atb":[[26,0],[1.05,2.25]],"id":35381686}],"con":true,"img":false}]}
{"op":"mcm","clk":"5348815584","pt":1646220930250,"mc":[{"id":"1.195453631","rc":[{"atb":[[1.05,0.13]],"id":35381686}],"con":true,"img":false}]}
{"op":"mcm","clk":"5348815603","pt":1646220930455,"mc":[{"id":"1.195453631","rc":[{"atb":[[1.05,0]],"id":35381686}],"con":true,"img":false}]}
{"op":"mcm","clk":"5348815615","pt":1646220930523,"mc":[{"id":"1.195453631","rc":[{"atb":[[28,0.13]],"id":35381686}],"con":true,"img":false}]}
{"op":"mcm","clk":"5348816339","pt":1646220936440,"mc":[{"id":"1.195453631","rc":[{"atb":[[17,0]],"id":36120434}],"con":true,"img":false}]}
{"op":"mcm","clk":"5348816352","pt":1646220936547,"mc":[{"id":"1.195453631","rc":[{"atb":[[16,3.54]],"id":36120434}],"con":true,"img":false}]}
{"op":"mcm","clk":"5348816526","pt":1646220937757,"mc":[{"id":"1.195453631","rc":[{"atb":[[3.25,12.58]],"id":39183170}],"con":true,"img":false}]}
{"op":"mcm","clk":"5348817283","pt":1646220943378,"mc":[{"id":"1.195453631","rc":[{"atb":[[3.25,8.89]],"id":39183170}],"con":true,"img":false}]}
{"op":"mcm","clk":"5348817688","pt":1646220946388,"mc":[{"id":"1.195453631","rc":[{"atb":[[3.1,0],[3.3,0]],"id":39183170}],"con":true,"img":false}]}
{"op":"mcm","clk":"5348817706","pt":1646220946494,"mc":[{"id":"1.195453631","rc":[{"atb":[[3.2,84.82]],"id":39183170}],"con":true,"img":false}]}
{"op":"mcm","clk":"5348819822","pt":1646220964897,"mc":[{"id":"1.195453631","rc":[{"atb":[[3.25,12.55]],"id":39183170},{"spn":23.02,"spf":1.0,"id":35381686}],"con":true,"img":false}]}
{"op":"mcm","clk":"5348819981","pt":1646220966414,"mc":[{"id":"1.195453631","rc":[{"atb":[[3.25,16.25]],"id":39183170}],"con":true,"img":false}]}
{"op":"mcm","clk":"5348821228","pt":1646220976393,"mc":[{"id":"1.195453631","rc":[{"atb":[[16,0]],"id":36120434}],"con":true,"img":false}]}
{"op":"mcm","clk":"5348821239","pt":1646220976494,"mc":[{"id":"1.195453631","rc":[{"atb":[[16.5,3.54]],"id":36120434}],"con":true,"img":false}]}
{"op":"mcm","clk":"5348823492","pt":1646220996424,"mc":[{"id":"1.195453631","rc":[{"atb":[[3.2,59.4]],"id":39183170}],"con":true,"img":false}]}
{"op":"mcm","clk":"5348823506","pt":1646220996549,"mc":[{"id":"1.195453631","rc":[{"atb":[[3.3,25.41]],"id":39183170}],"con":true,"img":false}]}
{"op":"mcm","clk":"5348824467","pt":1646221003953,"mc":[{"id":"1.195453631","rc":[{"atb":[[3.25,12.58]],"id":39183170}],"con":true,"img":false}]}
{"op":"mcm","clk":"5348824762","pt":1646221006429,"mc":[{"id":"1.195453631","rc":[{"atb":[[3.3,0]],"id":39183170}],"con":true,"img":false}]}
{"op":"mcm","clk":"5348824778","pt":1646221006530,"mc":[{"id":"1.195453631","rc":[{"atb":[[3.2,84.82]],"id":39183170}],"con":true,"img":false}]}
{"op":"mcm","clk":"5348825992","pt":1646221016447,"mc":[{"id":"1.195453631","rc":[{"atb":[[16.5,0]],"id":36120434}],"con":true,"img":false}]}
{"op":"mcm","clk":"5348826004","pt":1646221016553,"mc":[{"id":"1.195453631","rc":[{"atb":[[17,3.54]],"id":36120434}],"con":true,"img":false}]}
{"op":"mcm","clk":"5348826667","pt":1646221022046,"mc":[{"id":"1.195453631","rc":[{"atb":[[3.25,16.61]],"id":39183170}],"con":true,"img":false}]}
{"op":"mcm","clk":"5348827149","pt":1646221026475,"mc":[{"id":"1.195453631","rc":[{"atb":[[17,0]],"id":36120434},{"spn":17.18,"spf":1.0,"id":36120434}],"con":true,"img":false}]}
{"op":"mcm","clk":"5348827158","pt":1646221026578,"mc":[{"id":"1.195453631","rc":[{"atb":[[16,3.54]],"id":36120434}],"con":true,"img":false}]}
{"op":"mcm","clk":"5348829612","pt":1646221046400,"mc":[{"id":"1.195453631","rc":[{"atb":[[3.2,59.4]],"id":39183170}],"con":true,"img":false}]}
{"op":"mcm","clk":"5348829624","pt":1646221046504,"mc":[{"id":"1.195453631","rc":[{"atb":[[3.3,25.41]],"id":39183170}],"con":true,"img":false}]}
{"op":"mcm","clk":"5348830628","pt":1646221055003,"mc":[{"id":"1.195453631","rc":[{"atb":[[3.25,12.58]],"id":39183170}],"con":true,"img":false}]}
{"op":"mcm","clk":"5348830792","pt":1646221056406,"mc":[{"id":"1.195453631","rc":[{"atb":[[3.3,0]],"id":39183170}],"con":true,"img":false}]}
{"op":"mcm","clk":"5348830801","pt":1646221056499,"mc":[{"id":"1.195453631","rc":[{"atb":[[3.2,84.82]],"id":39183170}],"con":true,"img":false}]}
{"op":"mcm","clk":"5348831956","pt":1646221066400,"mc":[{"id":"1.195453631","rc":[{"atb":[[16,0]],"id":36120434}],"con":true,"img":false}]}
{"op":"mcm","clk":"5348831966","pt":1646221066502,"mc":[{"id":"1.195453631","rc":[{"atb":[[16.5,3.54]],"id":36120434}],"con":true,"img":false}]}
{"op":"mcm","clk":"5348832688","pt":1646221073024,"mc":[{"id":"1.195453631","rc":[{"atb":[[3.25,16.61]],"id":39183170}],"con":true,"img":false}]}
{"op":"mcm","clk":"5348835545","pt":1646221096433,"mc":[{"id":"1.195453631","rc":[{"spn":18.11,"spf":1.0,"id":36120434},{"atb":[[3.2,59.4]],"id":39183170}],"con":true,"img":false}]}
{"op":"mcm","clk":"5348835554","pt":1646221096534,"mc":[{"id":"1.195453631","rc":[{"atb":[[3.3,25.41]],"id":39183170}],"con":true,"img":false}]}
{"op":"mcm","clk":"5348836392","pt":1646221103067,"mc":[{"id":"1.195453631","rc":[{"atb":[[3.25,12.58]],"id":39183170}],"con":true,"img":false}]}
{"op":"mcm","clk":"5348836800","pt":1646221106439,"mc":[{"id":"1.195453631","rc":[{"atb":[[16.5,0]],"id":36120434},{"atb":[[3.3,0]],"id":39183170}],"con":true,"img":false}]}
{"op":"mcm","clk":"5348836823","pt":1646221106642,"mc":[{"id":"1.195453631","rc":[{"atb":[[17,3.54]],"id":36120434},{"atb":[[3.2,84.82]],"id":39183170}],"con":true,"img":false}]}
{"op":"mcm","clk":"5348836870","pt":1646221107058,"mc":[{"id":"1.195453631","rc":[{"atb":[[3.25,8.89]],"id":39183170}],"con":true,"img":false}]}
{"op":"mcm","clk":"5348838035","pt":1646221116443,"mc":[{"id":"1.195453631","rc":[{"atb":[[17,0]],"id":36120434}],"con":true,"img":false}]}
{"op":"mcm","clk":"5348838051","pt":1646221116551,"mc":[{"id":"1.195453631","rc":[{"atb":[[16,3.54]],"id":36120434}],"con":true,"img":false}]}
{"op":"mcm","clk":"5348839309","pt":1646221127090,"mc":[{"id":"1.195453631","rc":[{"atb":[[3.25,12.92]],"id":39183170}],"con":true,"img":false}]}
{"op":"mcm","clk":"5348840111","pt":1646221133663,"mc":[{"id":"1.195453631","rc":[{"atb":[[3.25,16.61]],"id":39183170}],"con":true,"img":false}]}
{"op":"mcm","clk":"5348842451","pt":1646221154925,"mc":[{"id":"1.195453631","rc":[{"atl":[[5.8,0],[11.5,0],[5.6,4.35],[8.8,12.82]],"id":26349442},{"atb":[[5.8,26.04],[6.6,15]],"id":36120434},{"atb":[[5.9,0],[3.9,34.48]],"id":40637101},{"atb":[[3.45,91.84],[3.15,0]],"id":40917619},{"atb":[[2.3,76.92],[2.26,15.87]],"id":41398505},{"atl":[[5.4,22.73],[6.6,0]],"id":41398505},{"atb":[[2.84,0],[2.96,51.02]],"id":39183170},{"atl":[[490,0],[500,3]],"id":35381686},{"atb":[[3.1,46.3],[7.8,2.94],[3.65,0]],"id":38554545}],"con":true,"img":false}]}
{"op":"mcm","clk":"5348842471","pt":1646221155093,"mc":[{"id":"1.195453631","rc":[{"atb":[[3.1,0],[3.8,35.71]],"id":38554545}],"con":true,"img":false}]}
{"op":"mcm","clk":"5348842489","pt":1646221155304,"mc":[{"id":"1.195453631","rc":[{"atb":[[7.2,0]],"id":38554545}],"con":true,"img":false}]}
{"op":"mcm","clk":"5348842624","pt":1646221156402,"mc":[{"id":"1.195453631","rc":[{"atb":[[16,0]],"id":36120434},{"atb":[[2.28,0]],"id":41398505},{"atb":[[3.2,59.4]],"id":39183170}],"con":true,"img":false}]}
{"op":"mcm","clk":"5348842640","pt":1646221156505,"mc":[{"id":"1.195453631","rc":[{"spn":4.65,"spf":"NaN","id":26349442},{"atb":[[16.5,3.54]],"id":36120434},{"atb":[[2.24,107.91]],"id":41398505},{"atb":[[3.3,25.41]],"id":39183170}],"con":true,"img":false}]}
{"op":"mcm","clk":"5348843551","pt":1646221164914,"mc":[{"id":"1.195453631","rc":[{"atl":[[5.8,10.42]],"id":26349442},{"atl":[[520,1]],"id":35381686},{"atb":[[7.4,7.81]],"id":38554545}],"con":true,"img":false}]}
{"op":"mcm","clk":"5348843698","pt":1646221166320,"mc":[{"id":"1.195453631","rc":[{"atb":[[3.25,12.58]],"id":39183170}],"con":true,"img":false}]}
{"op":"mcm","clk":"5348844160","pt":1646221170918,"mc":[{"id":"1.195453631","rc":[{"atb":[[6.4,48.8],[3.9,0]],"id":40637101},{"atb":[[3,50],[2.96,0]],"id":39183170}],"con":true,"img":false}]}
{"op":"mcm","clk":"5348844345","pt":1646221172638,"mc":[{"id":"1.195453631","rc":[{"atb":[[3.25,8.89]],"id":39183170}],"con":true,"img":false}]}
{"op":"mcm","clk":"5348844392","pt":1646221173124,"mc":[{"id":"1.195453631","rc":[{"atl":[[5.8,4.17],[6.8,0],[5.6,0]],"id":26349442},{"atb":[[2.3,0],[2.36,60.11]],"id":41398505},{"atl":[[520,0],[490,1],[500,2]],"id":35381686},{"atb":[[7.8,0],[7.2,3.23]],"id":38554545},{"atl":[[22,4.76],[23,3.41]],"id":38554545}],"con":true,"img":false}]}
{"op":"mcm","clk":"5348844415","pt":1646221173329,"mc":[{"id":"1.195453631","rc":[{"atb":[[1.02,2.25],[8.8,0]],"id":38554545},{"atl":[[21,7.5],[22,0]],"id":38554545}],"con":true,"img":false}]}
{"op":"mcm","clk":"5348844426","pt":1646221173428,"mc":[{"id":"1.195453631","rc":[{"atb":[[1.02,0.42]],"id":38554545}],"con":true,"img":false}]}
{"op":"mcm","clk":"5348844434","pt":1646221173530,"mc":[{"id":"1.195453631","rc":[{"atb":[[1.02,0]],"id":38554545}],"con":true,"img":false}]}
{"op":"mcm","clk":"5348844442","pt":1646221173633,"mc":[{"id":"1.195453631","rc":[{"atb":[[7.8,0.42]],"id":38554545}],"con":true,"img":false}]}
{"op":"mcm","clk":"5348844704","pt":1646221176410,"mc":[{"id":"1.195453631","rc":[{"atb":[[3.3,0]],"id":39183170}],"con":true,"img":false}]}
{"op":"mcm","clk":"5348844713","pt":1646221176514,"mc":[{"id":"1.195453631","rc":[{"atb":[[3.2,84.82]],"id":39183170}],"con":true,"img":false}]}
{"op":"mcm","clk":"5348845344","pt":1646221183155,"mc":[{"id":"1.195453631","rc":[{"atl":[[6.8,21.55]],"id":26349442},{"atb":[[7.4,0]],"id":38554545}],"con":true,"img":false}]}
{"op":"mcm","clk":"5348845664","pt":1646221186447,"mc":[{"id":"1.195453631","rc":[{"atl":[[5.7,0]],"id":39183170}],"con":true,"img":false}]}
{"op":"mcm","clk":"5348845673","pt":1646221186542,"mc":[{"id":"1.195453631","rc":[{"atl":[[5.9,10.43]],"id":39183170}],"con":true,"img":false}]}
{"op":"mcm","clk":"5348846351","pt":1646221193332,"mc":[{"id":"1.195453631","rc":[{"atb":[[3.25,12.92]],"id":39183170}],"con":true,"img":false}]}
{"op":"mcm","clk":"5348846671","pt":1646221196357,"mc":[{"id":"1.195453631","rc":[{"atb":[[3.25,16.61]],"id":39183170}],"con":true,"img":false}]}
{"op":"mcm","clk":"5348846678","pt":1646221196460,"mc":[{"id":"1.195453631","rc":[{"atb":[[16.5,0]],"id":36120434}],"con":true,"img":false}]}
{"op":"mcm","clk":"5348846689","pt":1646221196563,"mc":[{"id":"1.195453631","rc":[{"atb":[[17,3.54]],"id":36120434}],"con":true,"img":false}]}
{"op":"mcm","clk":"5348847501","pt":1646221204746,"mc":[{"id":"1.195453631","rc":[{"atb":[[14,7.25]],"id":36120434},{"atb":[[14,4.55]],"id":40637101},{"atb":[[2.44,6.23]],"id":41398505},{"atb":[[3.4,7.11]],"id":39183170},{"atb":[[16,6.29]],"id":35381686}],"con":true,"img":false}]}
{"op":"mcm","clk":"5348848699","pt":1646221216355,"mc":[{"id":"1.195453631","rc":[{"atb":[[3.2,59.4]],"id":39183170}],"con":true,"img":false}]}
{"op":"mcm","clk":"5348848707","pt":1646221216459,"mc":[{"id":"1.195453631","rc":[{"atb":[[3.3,25.41]],"id":39183170}],"con":true,"img":false}]}
{"op":"mcm","clk":"5348849451","pt":1646221223580,"mc":[{"id":"1.195453631","rc":[{"spn":4.75,"spf":"NaN","id":26349442},{"spn":18.37,"spf":1.0,"id":36120434},{"spn":14.62,"spf":1.0,"id":40637101},{"atb":[[3.25,12.58]],"id":39183170},{"spn":4.65,"spf":"NaN","id":39183170},{"spn":8.59,"spf":1.0,"id":38554545}],"con":true,"img":false}]}
{"op":"mcm","clk":"5348849765","pt":1646221226474,"mc":[{"id":"1.195453631","rc":[{"atb":[[3.3,0]],"id":39183170}],"con":true,"img":false}]}
{"op":"mcm","clk":"5348849777","pt":1646221226568,"mc":[{"id":"1.195453631","rc":[{"atb":[[3.2,84.82]],"id":39183170}],"con":true,"img":false}]}
{"op":"mcm","clk":"5348850769","pt":1646221236396,"mc":[{"id":"1.195453631","rc":[{"atb":[[17,0]],"id":36120434},{"atb":[[12,0]],"id":40637101}],"con":true,"img":false}]}
{"op":"mcm","clk":"5348850794","pt":1646221236501,"mc":[{"id":"1.195453631","rc":[{"atb":[[17.5,3.54]],"id":36120434},{"atb":[[13,4.87]],"id":40637101}],"con":true,"img":false}]}
{"op":"mcm","clk":"5348851675","pt":1646221244600,"mc":[{"id":"1.195453631","rc":[{"atb":[[3.25,16.61]],"id":39183170}],"con":true,"img":false}]}
{"op":"mcm","clk":"5348851871","pt":1646221246416,"mc":[{"id":"1.195453631","rc":[{"atb":[[13.5,0]],"id":36120434}],"con":true,"img":false}]}
{"op":"mcm","clk":"5348851881","pt":1646221246534,"mc":[{"id":"1.195453631","rc":[{"atb":[[14.5,9.15]],"id":36120434}],"con":true,"img":false}]}
{"op":"mcm","clk":"5348852270","pt":1646221250097,"mc":[{"id":"1.195453631","rc":[{"atb":[[14,0]],"id":36120434}],"con":true,"img":false}]}
{"op":"mcm","clk":"5348852725","pt":1646221254221,"mc":[{"id":"1.195453631","rc":[{"atb":[[15,6.74]],"id":36120434}],"con":true,"img":false}]}
{"op":"mcm","clk":"5348852947","pt":1646221256430,"mc":[{"id":"1.195453631","rc":[{"atb":[[14.5,0],[17.5,0]],"id":36120434}],"con":true,"img":false}]}
{"op":"mcm","clk":"5348852961","pt":1646221256535,"mc":[{"id":"1.195453631","rc":[{"atb":[[13.5,9.15],[16,3.54]],"id":36120434}],"con":true,"img":false}]}
{"op":"mcm","clk":"5348853008","pt":1646221256936,"mc":[{"id":"1.195453631","rc":[{"atb":[[7.8,0],[1.02,2.25]],"id":38554545}],"con":true,"img":false}]}
{"op":"mcm","clk":"5348853032","pt":1646221257143,"mc":[{"id":"1.195453631","rc":[{"atb":[[1.02,0.42]],"id":38554545}],"con":true,"img":false}]}
{"op":"mcm","clk":"5348853054","pt":1646221257323,"mc":[{"id":"1.195453631","rc":[{"atb":[[1.02,0]],"id":38554545}],"con":true,"img":false}]}
{"op":"mcm","clk":"5348853069","pt":1646221257426,"mc":[{"id":"1.195453631","rc":[{"atb":[[8.8,0.42]],"id":38554545}],"con":true,"img":false}]}
{"op":"mcm","clk":"5348853444","pt":1646221260527,"mc":[{"id":"1.195453631","rc":[{"atb":[[15,0]],"id":36120434}],"con":true,"img":false}]}
{"op":"mcm","clk":"5348853914","pt":1646221265250,"mc":[{"id":"1.195453631","rc":[{"atb":[[14,7.25]],"id":36120434}],"con":true,"img":false}]}
{"op":"mcm","clk":"5348854037","pt":1646221266449,"mc":[{"id":"1.195453631","rc":[{"atb":[[3.2,59.4]],"id":39183170}],"con":true,"img":false}]}
{"op":"mcm","clk":"5348854050","pt":1646221266552,"mc":[{"id":"1.195453631","rc":[{"atb":[[3.3,25.41]],"id":39183170}],"con":true,"img":false}]}
{"op":"mcm","clk":"5348854890","pt":1646221274533,"mc":[{"id":"1.195453631","rc":[{"atb":[[3.25,12.58]],"id":39183170}],"con":true,"img":false}]}
{"op":"mcm","clk":"5348855099","pt":1646221276467,"mc":[{"id":"1.195453631","rc":[{"atb":[[3.3,0]],"id":39183170}],"con":true,"img":false}]}
{"op":"mcm","clk":"5348855107","pt":1646221276567,"mc":[{"id":"1.195453631","rc":[{"atb":[[3.2,84.82]],"id":39183170}],"con":true,"img":false}]}
{"op":"mcm","clk":"5348856134","pt":1646221286475,"mc":[{"id":"1.195453631","rc":[{"atb":[[16,0]],"id":36120434},{"spn":17.28,"spf":1.0,"id":36120434},{"spn":8.61,"spf":1.0,"id":38554545}],"con":true,"img":false}]}
{"op":"mcm","clk":"5348856151","pt":1646221286649,"mc":[{"id":"1.195453631","rc":[{"atb":[[16.5,3.54]],"id":36120434}],"con":true,"img":false}]}
{"op":"mcm","clk":"5348856726","pt":1646221292068,"mc":[{"id":"1.195453631","rc":[{"atb":[[8.2,0]],"id":40917619},{"atb":[[3.35,1.65]],"id":39183170},{"atb":[[22,6.54]],"id":35381686}],"con":true,"img":false}]}
{"op":"mcm","clk":"5348856732","pt":1646221292170,"mc":[{"id":"1.195453631","rc":[{"atb":[[8.4,4.3]],"id":40917619},{"atb":[[3.45,2]],"id":39183170},{"atb":[[26,0.41]],"id":35381686}],"con":true,"img":false}]}
{"op":"mcm","clk":"5348856743","pt":1646221292274,"mc":[{"id":"1.195453631","rc":[{"atb":[[28,0],[1.05,2.25]],"id":35381686}],"con":true,"img":false}]}
{"op":"mcm","clk":"5348856755","pt":1646221292383,"mc":[{"id":"1.195453631","rc":[{"atb":[[1.05,0.13]],"id":35381686}],"con":true,"img":false}]}
{"op":"mcm","clk":"5348856767","pt":1646221292480,"mc":[{"id":"1.195453631","rc":[{"atb":[[1.05,0]],"id":35381686}],"con":true,"img":false}]}
{"op":"mcm","clk":"5348856778","pt":1646221292586,"mc":[{"id":"1.195453631","rc":[{"atb":[[23,0.13]],"id":35381686}],"con":true,"img":false}]}
{"op":"mcm","clk":"5348856796","pt":1646221292652,"mc":[{"id":"1.195453631","rc":[{"atb":[[3.25,16.61]],"id":39183170}],"con":true,"img":false}]}
{"op":"mcm","clk":"5348856825","pt":1646221292859,"mc":[{"id":"1.195453631","rc":[{"atb":[[3.4,4.61]],"id":39183170}],"con":true,"img":false}]}
{"op":"mcm","clk":"5348856865","pt":1646221293171,"mc":[{"id":"1.195453631","rc":[{"atl":[[10.5,10.53],[8.8,0]],"id":26349442},{"atb":[[6.4,30.28],[5.4,22.73]],"id":40637101},{"atb":[[3.45,51.02],[3.15,44.07]],"id":40917619},{"atl":[[5.4,0],[6,28.2]],"id":41398505},{"atb":[[3,0],[2.84,54.35]],"id":39183170},{"atb":[[3.8,0],[3.45,40.82]],"id":38554545}],"con":true,"img":false}]}
{"op":"mcm","clk":"5348857130","pt":1646221295380,"mc":[{"id":"1.195453631","rc":[{"atb":[[3.5,2.49]],"id":39183170}],"con":true,"img":false}]}
{"op":"mcm","clk":"5348857183","pt":1646221295857,"mc":[{"id":"1.195453631","rc":[{"atb":[[3.4,0]],"id":39183170}],"con":true,"img":false}]}
{"op":"mcm","clk":"5348857654","pt":1646221300160,"mc":[{"id":"1.195453631","rc":[{"atb":[[3.3,7.86]],"id":39183170}],"con":true,"img":false}]}
{"op":"mcm","clk":"5348858339","pt":1646221306401,"mc":[{"id":"1.195453631","rc":[{"atb":[[13.5,0]],"id":36120434}],"con":true,"img":false}]}
{"op":"mcm","clk":"5348858350","pt":1646221306511,"mc":[{"id":"1.195453631","rc":[{"atb":[[14.5,9.15]],"id":36120434}],"con":true,"img":false}]}
{"op":"mcm","clk":"5348858725","pt":1646221310102,"mc":[{"id":"1.195453631","rc":[{"atb":[[14,0]],"id":36120434}],"con":true,"img":false}]}
{"op":"mcm","clk":"5348859130","pt":1646221314098,"mc":[{"id":"1.195453631","rc":[{"atb":[[15,6.74]],"id":36120434}],"con":true,"img":false}]}
{"op":"mcm","clk":"5348859416","pt":1646221316394,"mc":[{"id":"1.195453631","rc":[{"atb":[[14.5,0]],"id":36120434},{"atb":[[3.2,59.4]],"id":39183170}],"con":true,"img":false}]}
{"op":"mcm","clk":"5348859428","pt":1646221316507,"mc":[{"id":"1.195453631","rc":[{"atb":[[13.5,9.15]],"id":36120434},{"atb":[[3.3,33.28]],"id":39183170}],"con":true,"img":false}]}
{"op":"mcm","clk":"5348859749","pt":1646221319906,"mc":[{"id":"1.195453631","rc":[{"atb":[[3.25,12.92]],"id":39183170}],"con":true,"img":false}]}
{"op":"mcm","clk":"5348859856","pt":1646221320901,"mc":[{"id":"1.195453631","rc":[{"atb":[[15,0]],"id":36120434}],"con":true,"img":false}]}
{"op":"mcm","clk":"5348860279","pt":1646221325004,"mc":[{"id":"1.195453631","rc":[{"atb":[[14,7.25]],"id":36120434}],"con":true,"img":false}]}
{"op":"mcm","clk":"5348860366","pt":1646221325731,"mc":[{"id":"1.195453631","rc":[{"atb":[[3.25,8.89]],"id":39183170}],"con":true,"img":false}]}
{"op":"mcm","clk":"5348860439","pt":1646221326414,"mc":[{"id":"1.195453631","rc":[{"atb":[[2.24,0]],"id":41398505},{"atb":[[3.3,7.86]],"id":39183170}],"con":true,"img":false}]}
{"op":"mcm","clk":"5348860450","pt":1646221326518,"mc":[{"id":"1.195453631","rc":[{"atb":[[2.28,107.91]],"id":41398505},{"atb":[[3.2,84.82]],"id":39183170}],"con":true,"img":false}]}
{"op":"mcm","clk":"5348862389","pt":1646221343734,"mc":[{"id":"1.195453631","rc":[{"atb":[[3.25,12.92]],"id":39183170}],"con":true,"img":false}]}
{"op":"mcm","clk":"5348862868","pt":1646221347760,"mc":[{"id":"1.195453631","rc":[{"spn":18.11,"spf":1.0,"id":36120434},{"spn":8.18,"spf":1.0,"id":40917619},{"atb":[[3.25,16.61]],"id":39183170},{"spn":4.7,"spf":"NaN","id":39183170},{"spn":23.16,"spf":1.0,"id":35381686}],"con":true,"img":false}]}
{"op":"mcm","clk":"5348864854","pt":1646221366344,"mc":[{"id":"1.195453631","rc":[{"atb":[[13.5,0]],"id":36120434}],"con":true,"img":false}]}
{"op":"mcm","clk":"5348864862","pt":1646221366448,"mc":[{"id":"1.195453631","rc":[{"atb":[[14.5,9.15]],"id":36120434}],"con":true,"img":false}]}
{"op":"mcm","clk":"5348865227","pt":1646221370379,"mc":[{"id":"1.195453631","rc":[{"atb":[[14,0]],"id":36120434}],"con":true,"img":false}]}
{"op":"mcm","clk":"5348865651","pt":1646221374546,"mc":[{"id":"1.195453631","rc":[{"atb":[[15,6.74]],"id":36120434}],"con":true,"img":false}]}
{"op":"mcm","clk":"5348865808","pt":1646221376379,"mc":[{"id":"1.195453631","rc":[{"atb":[[14.5,0]],"id":36120434},{"atb":[[3.2,59.4]],"id":39183170}],"con":true,"img":false}]}
{"op":"mcm","clk":"5348865821","pt":1646221376485,"mc":[{"id":"1.195453631","rc":[{"atb":[[13.5,9.15]],"id":36120434},{"atb":[[3.3,33.28]],"id":39183170}],"con":true,"img":false}]}
{"op":"mcm","clk":"5348865953","pt":1646221377577,"mc":[{"id":"1.195453631","rc":[{"atb":[[23,0],[1.05,2.25]],"id":35381686}],"con":true,"img":false}]}
{"op":"mcm","clk":"5348866037","pt":1646221378266,"mc":[{"id":"1.195453631","rc":[{"atb":[[1.05,0.13]],"id":35381686}],"con":true,"img":false}]}
{"op":"mcm","clk":"5348866081","pt":1646221378792,"mc":[{"id":"1.195453631","rc":[{"atb":[[1.05,0]],"id":35381686}],"con":true,"img":false}]}
{"op":"mcm","clk":"5348866091","pt":1646221378854,"mc":[{"id":"1.195453631","rc":[{"atb":[[28,0.13]],"id":35381686}],"con":true,"img":false}]}
{"op":"mcm","clk":"5348866759","pt":1646221385760,"mc":[{"id":"1.195453631","rc":[{"atb":[[3.25,12.58]],"id":39183170}],"con":true,"img":false}]}
{"op":"mcm","clk":"5348866816","pt":1646221386495,"mc":[{"id":"1.195453631","rc":[{"atb":[[2.28,0]],"id":41398505},{"atb":[[3.3,7.86]],"id":39183170}],"con":true,"img":false}]}
{"op":"mcm","clk":"5348866828","pt":1646221386603,"mc":[{"id":"1.195453631","rc":[{"atb":[[2.24,107.91]],"id":41398505},{"atb":[[3.2,84.82]],"id":39183170}],"con":true,"img":false}]}
{"op":"mcm","clk":"5348868438","pt":1646221404804,"mc":[{"id":"1.195453631","rc":[{"atb":[[3.25,16.61]],"id":39183170}],"con":true,"img":false}]}
{"op":"mcm","clk":"5348870193","pt":1646221426402,"mc":[{"id":"1.195453631","rc":[{"atb":[[3.2,59.4]],"id":39183170},{"spn":23.26,"spf":1.0,"id":35381686}],"con":true,"img":false}]}
{"op":"mcm","clk":"5348870202","pt":1646221426506,"mc":[{"id":"1.195453631","rc":[{"atb":[[3.3,33.28]],"id":39183170}],"con":true,"img":false}]}
{"op":"mcm","clk":"5348870687","pt":1646221431564,"mc":[{"id":"1.195453631","rc":[{"atb":[[2.64,0],[3.05,9.76],[2.86,0],[2.78,144.23]],"id":26349442},{"atb":[[7.4,3.12],[6.8,0]],"id":36120434},{"atl":[[180,14.2]],"id":40637101},{"atl":[[4.8,5.26],[4.4,0]],"id":41398505},{"atl":[[18,1.18],[24,0]],"id":39183170},{"atb":[[10.5,10.71],[9.6,0]],"id":35381686}],"con":true,"img":false}]}
{"op":"mcm","clk":"5348870912","pt":1646221433956,"mc":[{"id":"1.195453631","rc":[{"atb":[[3.25,12.58]],"id":39183170}],"con":true,"img":false}]}
{"op":"mcm","clk":"5348871149","pt":1646221436448,"mc":[{"id":"1.195453631","rc":[{"atl":[[4.3,0]],"id":41398505},{"atb":[[3.3,7.86]],"id":39183170}],"con":true,"img":false}]}
{"op":"mcm","clk":"5348871159","pt":1646221436556,"mc":[{"id":"1.195453631","rc":[{"atl":[[4.5,36.51]],"id":41398505},{"atb":[[3.2,84.82]],"id":39183170}],"con":true,"img":false}]}
{"op":"mcm","clk":"5348871570","pt":1646221441556,"mc":[{"id":"1.195453631","rc":[{"atb":[[2.98,45.89]],"id":26349442},{"atb":[[7,22]],"id":36120434},{"atb":[[15.5,4.32]],"id":40637101},{"atl":[[260,1.77],[40,4.72]],"id":40637101},{"atl":[[4.6,0],[5,12.5]],"id":41398505},{"atl":[[19,2.78]],"id":39183170},{"atb":[[9.8,5.68],[27,3.2]],"id":35381686},{"atl":[[190,4.72]],"id":35381686}],"con":true,"img":false}]}
{"op":"mcm","clk":"5348871574","pt":1646221441658,"mc":[{"id":"1.195453631","rc":[{"atb":[[22,2]],"id":36120434},{"atl":[[70,4.72]],"id":36120434}],"con":true,"img":false}]}
{"op":"mcm","clk":"5348871579","pt":1646221441764,"mc":[{"id":"1.195453631","rc":[{"atl":[[16,2]],"id":40917619},{"atl":[[18,4.92]],"id":38554545}],"con":true,"img":false}]}
{"op":"mcm","clk":"5348871682","pt":1646221442956,"mc":[{"id":"1.195453631","rc":[{"atb":[[23,1.66]],"id":36120434}],"con":true,"img":false}]}
{"op":"mcm","clk":"5348871919","pt":1646221445565,"mc":[{"id":"1.195453631","rc":[{"atb":[[15,0]],"id":36120434},{"atb":[[16,0]],"id":35381686}],"con":true,"img":false}]}
{"op":"mcm","clk":"5348872299","pt":1646221449847,"mc":[{"id":"1.195453631","rc":[{"atb":[[17,5.9]],"id":36120434}],"con":true,"img":false}]}
{"op":"mcm","clk":"5348872456","pt":1646221451559,"mc":[{"id":"1.195453631","rc":[{"atb":[[2.94,38.66],[2.74,0]],"id":26349442},{"atb":[[6.4,0],[5.8,0],[6,0],[6.6,28.39]],"id":36120434},{"atl":[[5.2,17.86]],"id":41398505},{"atl":[[20,9.21],[30,0]],"id":39183170},{"atb":[[9.2,19.94],[8.4,0],[9.4,8.93],[8.8,0]],"id":35381686}],"con":true,"img":false}]}
{"op":"mcm","clk":"5348872476","pt":1646221451875,"mc":[{"id":"1.195453631","rc":[{"atb":[[3.25,15.92]],"id":39183170}],"con":true,"img":false}]}
{"op":"mcm","clk":"5348872828","pt":1646221455781,"mc":[{"id":"1.195453631","rc":[{"atb":[[8.4,2.94]],"id":40917619}],"con":true,"img":false}]}
{"op":"mcm","clk":"5348872839","pt":1646221455831,"mc":[{"id":"1.195453631","rc":[{"atb":[[8.2,1.4]],"id":40917619}],"con":true,"img":false}]}
{"op":"mcm","clk":"5348873384","pt":1646221461575,"mc":[{"id":"1.195453631","rc":[{"atb":[[2.78,102.1]],"id":26349442},{"atb":[[6.2,24.04]],"id":36120434},{"atl":[[5.4,28.41]],"id":41398505},{"atl":[[22,5.95]],"id":39183170}],"con":true,"img":false}]}
{"op":"mcm","clk":"5348873395","pt":1646221461680,"mc":[{"id":"1.195453631","rc":[{"atb":[[2.9,65.79]],"id":26349442},{"atl":[[28,0]],"id":39183170},{"atb":[[9,15.62]],"id":35381686}],"con":true,"img":false}]}
{"op":"mcm","clk":"5348873842","pt":1646221466470,"mc":[{"id":"1.195453631","rc":[{"atl":[[70,2]],"id":36120434}],"con":true,"img":false}]}
{"op":"mcm","clk":"5348873852","pt":1646221466576,"mc":[{"id":"1.195453631","rc":[{"atl":[[65,2.78],[95,4.72]],"id":36120434}],"con":true,"img":false}]}
{"op":"mcm","clk":"5348873864","pt":1646221466679,"mc":[{"id":"1.195453631","rc":[{"atl":[[70,0]],"id":36120434}],"con":true,"img":false}]}
{"op":"mcm","clk":"5348873875","pt":1646221466786,"mc":[{"id":"1.195453631","rc":[{"atl":[[95,2.72]],"id":36120434}],"con":true,"img":false}]}
{"op":"mcm","clk":"5348873899","pt":1646221466994,"mc":[{"id":"1.195453631","rc":[{"atl":[[65,4.78]],"id":36120434}],"con":true,"img":false}]}
{"op":"mcm","clk":"5348874322","pt":1646221471582,"mc":[{"id":"1.195453631","rc":[{"atl":[[26,0]],"id":39183170}],"con":true,"img":false}]}
{"op":"mcm","clk":"5348874331","pt":1646221471686,"mc":[{"id":"1.195453631","rc":[{"atb":[[2.82,0]],"id":26349442}],"con":true,"img":false}]}
{"op":"mcm","clk":"5348874717","pt":1646221476482,"mc":[{"id":"1.195453631","rc":[{"atb":[[16.5,0]],"id":36120434},{"atb":[[3.2,59.4]],"id":39183170},{"atl":[[20,0]],"id":38554545}],"con":true,"img":false}]}
{"op":"mcm","clk":"5348874726","pt":1646221476586,"mc":[{"id":"1.195453631","rc":[{"atb":[[17.5,3.54]],"id":36120434},{"atb":[[3.3,33.28]],"id":39183170},{"atl":[[19,6.12]],"id":38554545}],"con":true,"img":false}]}
{"op":"mcm","clk":"5348875072","pt":1646221480386,"mc":[{"id":"1.195453631","rc":[{"atb":[[17,0]],"id":36120434}],"con":true,"img":false}]}
{"op":"mcm","clk":"5348875271","pt":1646221482475,"mc":[{"id":"1.195453631","rc":[{"atb":[[3.55,6.2]],"id":26349442}],"con":true,"img":false}]}
{"op":"mcm","clk":"5348875290","pt":1646221482687,"mc":[{"id":"1.195453631","rc":[{"atb":[[3.65,3.65]],"id":26349442}],"con":true,"img":false}]}
{"op":"mcm","clk":"5348875317","pt":1646221482998,"mc":[{"id":"1.195453631","rc":[{"atl":[[19,0]],"id":38554545}],"con":true,"img":false}]}
{"op":"mcm","clk":"5348875325","pt":1646221483102,"mc":[{"id":"1.195453631","rc":[{"atl":[[19.5,7.2]],"id":38554545}],"con":true,"img":false}]}
{"op":"mcm","clk":"5348875476","pt":1646221484779,"mc":[{"id":"1.195453631","rc":[{"atb":[[18,5.55]],"id":36120434}],"con":true,"img":false}]}
{"op":"mcm","clk":"5348875616","pt":1646221486297,"mc":[{"id":"1.195453631","rc":[{"atb":[[3.25,12.22]],"id":39183170}],"con":true,"img":false}]}
{"op":"mcm","clk":"5348875628","pt":1646221486403,"mc":[{"id":"1.195453631","rc":[{"spn":21.56,"spf":1.0,"id":36120434},{"spn":15.07,"spf":1.0,"id":40637101},{"spn":8.14,"spf":1.0,"id":40917619},{"spn":24.75,"spf":1.0,"id":35381686},{"atl":[[19.5,1.08]],"id":38554545}],"con":true,"img":false}]}
{"op":"mcm","clk":"5348875639","pt":1646221486506,"mc":[{"id":"1.195453631","rc":[{"atl":[[20,6.12]],"id":38554545}],"con":true,"img":false}]}
{"op":"mcm","clk":"5348875804","pt":1646221487983,"mc":[{"id":"1.195453631","rc":[{"atb":[[3.25,8.89]],"id":39183170}],"con":true,"img":false}]}
{"op":"mcm","clk":"5348875982","pt":1646221489893,"mc":[{"id":"1.195453631","rc":[{"atb":[[22,0]],"id":36120434},{"atl":[[65,2.78]],"id":36120434},{"atb":[[15.5,2.32]],"id":40637101},{"atl":[[40,2.72]],"id":40637101},{"atl":[[16,0]],"id":40917619},{"atb":[[27,1.2]],"id":35381686},{"atl":[[190,2.72]],"id":35381686},{"atl":[[18,2.92]],"id":38554545}],"con":true,"img":false}]}
{"op":"mcm","clk":"5348876212","pt":1646221492404,"mc":[{"id":"1.195453631","rc":[{"atb":[[16,6.29]],"id":35381686}],"con":true,"img":false}]}
{"op":"mcm","clk":"5348876367","pt":1646221494024,"mc":[{"id":"1.195453631","rc":[{"atb":[[3.35,4.85]],"id":39183170}],"con":true,"img":false}]}
{"op":"mcm","clk":"5348876561","pt":1646221496210,"mc":[{"id":"1.195453631","rc":[{"atb":[[3.3,25.41]],"id":39183170}],"con":true,"img":false}]}
{"op":"mcm","clk":"5348876586","pt":1646221496421,"mc":[{"id":"1.195453631","rc":[{"atl":[[65,0.06]],"id":36120434},{"atb":[[3.3,0]],"id":39183170}],"con":true,"img":false}]}
{"op":"mcm","clk":"5348876599","pt":1646221496525,"mc":[{"id":"1.195453631","rc":[{"atl":[[70,2.72]],"id":36120434},{"atb":[[3.2,84.82]],"id":39183170}],"con":true,"img":false}]}
{"op":"mcm","clk":"5348877003","pt":1646221500316,"mc":[{"id":"1.195453631","rc":[{"atb":[[3.5,5.86]],"id":39183170}],"con":true,"img":false}]}
{"op":"mcm","clk":"5348877289","pt":1646221503115,"mc":[{"id":"1.195453631","rc":[{"atb":[[3.35,1.65]],"id":39183170}],"con":true,"img":false}]}
{"op":"mcm","clk":"5348877644","pt":1646221506387,"mc":[{"id":"1.195453631","rc":[{"atb":[[17.5,0]],"id":36120434}],"con":true,"img":false}]}
{"op":"mcm","clk":"5348877654","pt":1646221506496,"mc":[{"id":"1.195453631","rc":[{"atb":[[18.5,3.54]],"id":36120434}],"con":true,"img":false}]}
{"op":"mcm","clk":"5348878020","pt":1646221510304,"mc":[{"id":"1.195453631","rc":[{"atb":[[18,0]],"id":36120434}],"con":true,"img":false}]}
{"op":"mcm","clk":"5348878175","pt":1646221511712,"mc":[{"id":"1.195453631","rc":[{"atl":[[190,0]],"id":35381686}],"con":true,"img":false}]}
{"op":"mcm","clk":"5348878184","pt":1646221511816,"mc":[{"id":"1.195453631","rc":[{"atl":[[240,2.72]],"id":35381686}],"con":true,"img":false}]}
{"op":"mcm","clk":"5348878210","pt":1646221512024,"mc":[{"id":"1.195453631","rc":[{"atb":[[3.25,12.22]],"id":39183170}],"con":true,"img":false}]}
{"op":"mcm","clk":"5348878538","pt":1646221515380,"mc":[{"id":"1.195453631","rc":[{"atb":[[19,5.24]],"id":36120434},{"atb":[[16,0]],"id":35381686}],"con":true,"img":false}]}
{"op":"mcm","clk":"5348878683","pt":1646221516831,"mc":[{"id":"1.195453631","rc":[{"atb":[[3.25,15.92]],"id":39183170}],"con":true,"img":false}]}
{"op":"mcm","clk":"5348878971","pt":1646221519806,"mc":[{"id":"1.195453631","rc":[{"atb":[[16,6.29]],"id":35381686}],"con":true,"img":false}]}
{"op":"mcm","clk":"5348879844","pt":1646221527946,"mc":[{"id":"1.195453631","rc":[{"atb":[[1.04,2.25]],"id":36120434}],"con":true,"img":false}]}
{"op":"mcm","clk":"5348879867","pt":1646221528150,"mc":[{"id":"1.195453631","rc":[{"atb":[[1.04,0.15]],"id":36120434}],"con":true,"img":false}]}
{"op":"mcm","clk":"5348879909","pt":1646221528585,"mc":[{"id":"1.195453631","rc":[{"atb":[[1.04,0]],"id":36120434}],"con":true,"img":false}]}
{"op":"mcm","clk":"5348879916","pt":1646221528643,"mc":[{"id":"1.195453631","rc":[{"atb":[[24,0.15]],"id":36120434}],"con":true,"img":false}]}
{"op":"mcm","clk":"5348880525","pt":1646221534856,"mc":[{"id":"1.195453631","rc":[{"atb":[[18.5,0]],"id":36120434}],"con":true,"img":false}]}
{"op":"mcm","clk":"5348880534","pt":1646221534959,"mc":[{"id":"1.195453631","rc":[{"atb":[[19.5,3.54]],"id":36120434}],"con":true,"img":false}]}
{"op":"mcm","clk":"5348880704","pt":1646221536674,"mc":[{"id":"1.195453631","rc":[{"atb":[[8.6,5.37]],"id":38554545}],"con":true,"img":false}]}
{"op":"mcm","clk":"5348880713","pt":1646221536780,"mc":[{"id":"1.195453631","rc":[{"atb":[[8.4,1.36]],"id":38554545}],"con":true,"img":false}]}
{"op":"mcm","clk":"5348880879","pt":1646221538235,"mc":[{"id":"1.195453631","rc":[{"atb":[[19,0]],"id":36120434}],"con":true,"img":false}]}
{"op":"mcm","clk":"5348880916","pt":1646221538762,"mc":[{"id":"1.195453631","rc":[{"atb":[[8.8,2.92]],"id":38554545}],"con":true,"img":false}]}
{"op":"mcm","clk":"5348880982","pt":1646221539652,"mc":[{"id":"1.195453631","rc":[{"atb":[[22,2]],"id":36120434},{"atl":[[70,4.72]],"id":36120434},{"atb":[[15.5,4.32]],"id":40637101},{"atl":[[40,4.72]],"id":40637101},{"atl":[[16,2]],"id":40917619},{"atb":[[27,3.2]],"id":35381686},{"atl":[[230,2]],"id":35381686},{"atl":[[18,4.92]],"id":38554545}],"con":true,"img":false}]}
{"op":"mcm","clk":"5348881252","pt":1646221542369,"mc":[{"id":"1.195453631","rc":[{"atb":[[16,0]],"id":35381686}],"con":true,"img":false}]}
{"op":"mcm","clk":"5348882492","pt":1646221556364,"mc":[{"id":"1.195453631","rc":[{"atb":[[19.5,0]],"id":36120434},{"spn":21.57,"spf":1.0,"id":36120434},{"atb":[[3.2,59.4]],"id":39183170},{"spn":8.68,"spf":1.0,"id":38554545}],"con":true,"img":false}]}
{"op":"mcm","clk":"5348882500","pt":1646221556473,"mc":[{"id":"1.195453631","rc":[{"atb":[[16,3.54]],"id":36120434},{"atb":[[3.3,25.41]],"id":39183170}],"con":true,"img":false}]}
{"op":"mcm","clk":"5348882869","pt":1646221560612,"mc":[{"id":"1.195453631","rc":[{"atb":[[16.5,6.08]],"id":36120434},{"atb":[[3.5,2.49]],"id":39183170}],"con":true,"img":false}]}
{"op":"mcm","clk":"5348883118","pt":1646221563225,"mc":[{"id":"1.195453631","rc":[{"atb":[[3.25,12.58]],"id":39183170}],"con":true,"img":false}]}
{"op":"mcm","clk":"5348883268","pt":1646221564805,"mc":[{"id":"1.195453631","rc":[{"atb":[[3.35,8.39]],"id":39183170}],"con":true,"img":false}]}
{"op":"mcm","clk":"5348883423","pt":1646221566382,"mc":[{"id":"1.195453631","rc":[{"atb":[[3.3,0]],"id":39183170}],"con":true,"img":false}]}
{"op":"mcm","clk":"5348883435","pt":1646221566485,"mc":[{"id":"1.195453631","rc":[{"atb":[[3.2,84.82]],"id":39183170}],"con":true,"img":false}]}
{"op":"mcm","clk":"5348885231","pt":1646221584189,"mc":[{"id":"1.195453631","rc":[{"atb":[[3.25,15.92]],"id":39183170}],"con":true,"img":false}]}
{"op":"mcm","clk":"5348885464","pt":1646221586438,"mc":[{"id":"1.195453631","rc":[{"atb":[[16,0]],"id":36120434},{"atl":[[240,0]],"id":35381686}],"con":true,"img":false}]}
{"op":"mcm","clk":"5348885476","pt":1646221586540,"mc":[{"id":"1.195453631","rc":[{"atb":[[17,3.54]],"id":36120434},{"atl":[[220,2.72]],"id":35381686}],"con":true,"img":false}]}
{"op":"mcm","clk":"5348885486","pt":1646221586645,"mc":[{"id":"1.195453631","rc":[{"atl":[[230,0],[250,2.53]],"id":35381686}],"con":true,"img":false}]}
{"op":"mcm","clk":"5348885493","pt":1646221586706,"mc":[{"id":"1.195453631","rc":[{"atl":[[210,2],[250,0.53]],"id":35381686}],"con":true,"img":false}]}
{"op":"mcm","clk":"5348885789","pt":1646221589942,"mc":[{"id":"1.195453631","rc":[{"atb":[[16.5,0]],"id":36120434}],"con":true,"img":false}]}
{"op":"mcm","clk":"5348886243","pt":1646221594223,"mc":[{"id":"1.195453631","rc":[{"atb":[[17.5,5.72]],"id":36120434}],"con":true,"img":false}]}
{"op":"mcm","clk":"5348886883","pt":1646221600830,"mc":[{"id":"1.195453631","rc":[{"atb":[[22,0]],"id":36120434},{"atl":[[70,2.72]],"id":36120434},{"atb":[[15.5,2.32]],"id":40637101},{"atl":[[40,2.72]],"id":40637101},{"atl":[[16,0]],"id":40917619},{"atb":[[27,1.2]],"id":35381686},{"atl":[[210,0]],"id":35381686},{"atl":[[18,2.92]],"id":38554545}],"con":true,"img":false}]}
{"op":"mcm","clk":"5348886892","pt":1646221601057,"mc":[{"id":"1.195453631","rc":[{"atb":[[24,0],[1.04,2.25]],"id":36120434}],"con":true,"img":false}]}
{"op":"mcm","clk":"5348886898","pt":1646221601136,"mc":[{"id":"1.195453631","rc":[{"atb":[[1.04,0.15]],"id":36120434}],"con":true,"img":false}]}
{"op":"mcm","clk":"5348886916","pt":1646221601348,"mc":[{"id":"1.195453631","rc":[{"atb":[[1.04,0]],"id":36120434}],"con":true,"img":false}]}
{"op":"mcm","clk":"5348886929","pt":1646221601450,"mc":[{"id":"1.195453631","rc":[{"atb":[[22,0.15]],"id":36120434}],"con":true,"img":false}]}
{"op":"mcm","clk":"5348887269","pt":1646221604659,"mc":[{"id":"1.195453631","rc":[{"atb":[[16,6.29]],"id":35381686}],"con":true,"img":false}]}
{"op":"mcm","clk":"5348887444","pt":1646221606435,"mc":[{"id":"1.195453631","rc":[{"atb":[[3.2,59.4]],"id":39183170},{"atl":[[220,0]],"id":35381686}],"con":true,"img":false}]}
{"op":"mcm","clk":"5348887453","pt":1646221606537,"mc":[{"id":"1.195453631","rc":[{"atb":[[3.3,25.41]],"id":39183170},{"atl":[[240,2.72]],"id":35381686}],"con":true,"img":false}]}
{"op":"mcm","clk":"5348888186","pt":1646221614262,"mc":[{"id":"1.195453631","rc":[{"atb":[[3.25,12.58]],"id":39183170}],"con":true,"img":false}]}
{"op":"mcm","clk":"5348888328","pt":1646221615669,"mc":[{"id":"1.195453631","rc":[{"atb":[[3.25,8.89]],"id":39183170}],"con":true,"img":false}]}
{"op":"mcm","clk":"5348888394","pt":1646221616353,"mc":[{"id":"1.195453631","rc":[{"atb":[[17,0]],"id":36120434}],"con":true,"img":false}]}
{"op":"mcm","clk":"5348888406","pt":1646221616454,"mc":[{"id":"1.195453631","rc":[{"atb":[[18,3.54]],"id":36120434},{"spn":20.47,"spf":1.0,"id":36120434},{"spn":14.62,"spf":1.0,"id":40637101},{"spn":23.26,"spf":1.0,"id":35381686}],"con":true,"img":false}]}
{"op":"mcm","clk":"5348888727","pt":1646221619977,"mc":[{"id":"1.195453631","rc":[{"atb":[[17.5,0]],"id":36120434}],"con":true,"img":false}]}
{"op":"mcm","clk":"5348889025","pt":1646221623269,"mc":[{"id":"1.195453631","rc":[{"atb":[[3.35,11.59]],"id":39183170}],"con":true,"img":false}]}
{"op":"mcm","clk":"5348889098","pt":1646221624051,"mc":[{"id":"1.195453631","rc":[{"atb":[[18.5,5.39]],"id":36120434}],"con":true,"img":false}]}
{"op":"mcm","clk":"5348889290","pt":1646221626186,"mc":[{"id":"1.195453631","rc":[{"atb":[[3.35,15.14]],"id":39183170}],"con":true,"img":false}]}
{"op":"mcm","clk":"5348891346","pt":1646221646404,"mc":[{"id":"1.195453631","rc":[{"atb":[[18,0]],"id":36120434},{"atb":[[3.3,0]],"id":39183170}],"con":true,"img":false}]}
{"op":"mcm","clk":"5348891363","pt":1646221646608,"mc":[{"id":"1.195453631","rc":[{"atb":[[19,3.54]],"id":36120434},{"atb":[[3.4,25.41]],"id":39183170}],"con":true,"img":false}]}
{"op":"mcm","clk":"5348891401","pt":1646221646988,"mc":[{"id":"1.195453631","rc":[{"atb":[[3.35,13.48]],"id":39183170}],"con":true,"img":false}]}
{"op":"mcm","clk":"5348891740","pt":1646221650519,"mc":[{"id":"1.195453631","rc":[{"atb":[[18.5,0]],"id":36120434},{"atb":[[3.35,6.74]],"id":39183170}],"con":true,"img":false}]}
{"op":"mcm","clk":"5348892018","pt":1646221653404,"mc":[{"id":"1.195453631","rc":[{"atb":[[3.35,3.54]],"id":39183170}],"con":true,"img":false}]}
{"op":"mcm","clk":"5348892210","pt":1646221655498,"mc":[{"id":"1.195453631","rc":[{"atb":[[19.5,5.1]],"id":36120434},{"atb":[[3.5,5.86]],"id":39183170}],"con":true,"img":false}]}
{"op":"mcm","clk":"5348892314","pt":1646221656388,"mc":[{"id":"1.195453631","rc":[{"atb":[[3.4,0]],"id":39183170}],"con":true,"img":false}]}
{"op":"mcm","clk":"5348892323","pt":1646221656494,"mc":[{"id":"1.195453631","rc":[{"atb":[[3.25,34.3]],"id":39183170}],"con":true,"img":false}]}
{"op":"mcm","clk":"5348892876","pt":1646221662720,"mc":[{"id":"1.195453631","rc":[{"atb":[[3.35,0]],"id":39183170}],"con":true,"img":false}]}
{"op":"mcm","clk":"5348893215","pt":1646221666439,"mc":[{"id":"1.195453631","rc":[{"atb":[[3.5,2.49]],"id":39183170}],"con":true,"img":false}]}
{"op":"mcm","clk":"5348893630","pt":1646221671024,"mc":[{"id":"1.195453631","rc":[{"atb":[[3.3,7.86]],"id":39183170}],"con":true,"img":false}]}
{"op":"mcm","clk":"5348893925","pt":1646221674400,"mc":[{"id":"1.195453631","rc":[{"atb":[[3.3,11.13]],"id":39183170}],"con":true,"img":false}]}
{"op":"mcm","clk":"5348894125","pt":1646221676437,"mc":[{"id":"1.195453631","rc":[{"atb":[[19,0]],"id":36120434}],"con":true,"img":false}]}
{"op":"mcm","clk":"5348894133","pt":1646221676542,"mc":[{"id":"1.195453631","rc":[{"atb":[[20,3.54]],"id":36120434},{"spn":21.16,"spf":1.0,"id":36120434}],"con":true,"img":false}]}
{"op":"mcm","clk":"5348894278","pt":1646221677948,"mc":[{"id":"1.195453631","rc":[{"atb":[[22,0],[1.04,2.25]],"id":36120434}],"con":true,"img":false}]}
{"op":"mcm","clk":"5348894293","pt":1646221678158,"mc":[{"id":"1.195453631","rc":[{"atb":[[1.04,0.15]],"id":36120434}],"con":true,"img":false}]}
{"op":"mcm","clk":"5348894310","pt":1646221678318,"mc":[{"id":"1.195453631","rc":[{"atb":[[1.04,0]],"id":36120434}],"con":true,"img":false}]}
{"op":"mcm","clk":"5348894320","pt":1646221678420,"mc":[{"id":"1.195453631","rc":[{"atb":[[24,0.15]],"id":36120434}],"con":true,"img":false}]}
{"op":"mcm","clk":"5348894428","pt":1646221679523,"mc":[{"id":"1.195453631","rc":[{"atb":[[19.5,0]],"id":36120434}],"con":true,"img":false}]}
{"op":"mcm","clk":"5348895103","pt":1646221686326,"mc":[{"id":"1.195453631","rc":[{"atb":[[20,0]],"id":36120434}],"con":true,"img":false}]}
{"op":"mcm","clk":"5348895111","pt":1646221686429,"mc":[{"id":"1.195453631","rc":[{"atb":[[16,3.54]],"id":36120434}],"con":true,"img":false}]}
{"op":"mcm","clk":"5348895520","pt":1646221690547,"mc":[{"id":"1.195453631","rc":[{"atb":[[16.5,6.08]],"id":36120434}],"con":true,"img":false}]}
{"op":"mcm","clk":"5348898002","pt":1646221716382,"mc":[{"id":"1.195453631","rc":[{"atb":[[16,0]],"id":36120434}],"con":true,"img":false}]}
{"op":"mcm","clk":"5348898012","pt":1646221716478,"mc":[{"id":"1.195453631","rc":[{"atb":[[17,3.54]],"id":36120434}],"con":true,"img":false}]}
{"op":"mcm","clk":"5348898279","pt":1646221719597,"mc":[{"id":"1.195453631","rc":[{"atb":[[16.5,0]],"id":36120434}],"con":true,"img":false}]}
{"op":"mcm","clk":"5348898494","pt":1646221721785,"mc":[{"id":"1.195453631","rc":[{"atb":[[22,2]],"id":36120434},{"atl":[[70,4.72]],"id":36120434},{"atb":[[15.5,4.32]],"id":40637101},{"atl":[[40,4.72]],"id":40637101},{"atl":[[16,2]],"id":40917619},{"atb":[[27,3.2]],"id":35381686},{"atl":[[230,2]],"id":35381686},{"atl":[[18,4.92]],"id":38554545}],"con":true,"img":false}]}
{"op":"mcm","clk":"5348898501","pt":1646221721889,"mc":[{"id":"1.195453631","rc":[{"atb":[[15,2.72]],"id":40637101},{"atl":[[55,4.72]],"id":40637101},{"atl":[[70,2.72],[90,2]],"id":36120434},{"atb":[[27,1.2]],"id":35381686}],"con":true,"img":false}]}
{"op":"mcm","clk":"5348898513","pt":1646221721997,"mc":[{"id":"1.195453631","rc":[{"atb":[[15.5,2.32]],"id":40637101},{"atl":[[40,2.72]],"id":40637101},{"atb":[[23,2]],"id":35381686},{"atl":[[18,2.92],[19.5,3.08]],"id":38554545}],"con":true,"img":false}]}
{"op":"mcm","clk":"5348898519","pt":1646221722101,"mc":[{"id":"1.195453631","rc":[{"atb":[[15,0.72]],"id":40637101},{"atl":[[55,2.72]],"id":40637101},{"atl":[[70,4.72],[90,0]],"id":36120434}],"con":true,"img":false}]}
{"op":"mcm","clk":"5348898527","pt":1646221722202,"mc":[{"id":"1.195453631","rc":[{"atb":[[15,2.72]],"id":40637101},{"atl":[[40,4.72]],"id":40637101},{"atl":[[70,2.72],[90,2]],"id":36120434},{"atb":[[23,0],[27,3.2]],"id":35381686},{"atl":[[18,4.92],[19.5,1.08]],"id":38554545}],"con":true,"img":false}]}
{"op":"mcm","clk":"5348898546","pt":1646221722412,"mc":[{"id":"1.195453631","rc":[{"atb":[[27,1.2]],"id":35381686},{"atl":[[18,2.92]],"id":38554545}],"con":true,"img":false}]}
{"op":"mcm","clk":"5348898555","pt":1646221722517,"mc":[{"id":"1.195453631","rc":[{"atb":[[27,3.2]],"id":35381686},{"atl":[[18,4.92]],"id":38554545}],"con":true,"img":false}]}
{"op":"mcm","clk":"5348898632","pt":1646221723397,"mc":[{"id":"1.195453631","rc":[{"atb":[[17.5,5.72]],"id":36120434}],"con":true,"img":false}]}
{"op":"mcm","clk":"5348898671","pt":1646221723815,"mc":[{"id":"1.195453631","rc":[{"atl":[[18,0],[19,1.11]],"id":40917619},{"atb":[[2.22,16.39],[2.26,0]],"id":41398505},{"atl":[[19.5,0],[20,7.17]],"id":38554545}],"con":true,"img":false}]}
{"op":"mcm","clk":"5348898821","pt":1646221725172,"mc":[{"id":"1.195453631","rc":[{"atb":[[16,0]],"id":35381686}],"con":true,"img":false}]}
{"op":"mcm","clk":"5348898880","pt":1646221725592,"mc":[{"id":"1.195453631","rc":[{"atb":[[3.35,8.51],[3.3,8.7],[3.05,0]],"id":26349442},{"atb":[[8,2.86],[7.4,0]],"id":36120434},{"atb":[[5.9,20.41],[5.4,0]],"id":40637101},{"atl":[[170,1],[200,0]],"id":40637101},{"atb":[[4.8,26.77],[3.75,0]],"id":40917619},{"atl":[[18,1.18]],"id":40917619},{"atl":[[4.8,0],[4.1,6.45]],"id":41398505},{"atl":[[13,10],[18,0],[20,3.95]],"id":39183170},{"atb":[[10,0],[10.5,8.6],[12.5,1.74],[13.5,7.2]],"id":35381686}],"con":true,"img":false}]}
{"op":"mcm","clk":"5348899039","pt":1646221727300,"mc":[{"id":"1.195453631","rc":[{"atl":[[70,4.72],[90,0]],"id":36120434}],"con":true,"img":false}]}
{"op":"mcm","clk":"5348899049","pt":1646221727405,"mc":[{"id":"1.195453631","rc":[{"atb":[[3.3,0]],"id":26349442},{"atl":[[70,2.72],[90,2]],"id":36120434},{"atb":[[2.26,15.87]],"id":41398505},{"atl":[[19.5,1.08],[20,6.12]],"id":38554545}],"con":true,"img":false}]}
{"op":"mcm","clk":"5348899067","pt":1646221727509,"mc":[{"id":"1.195453631","rc":[{"atl":[[70,4.72]],"id":36120434}],"con":true,"img":false}]}
{"op":"mcm","clk":"5348899079","pt":1646221727612,"mc":[{"id":"1.195453631","rc":[{"atl":[[90,0]],"id":36120434}],"con":true,"img":false}]}
{"op":"mcm","clk":"5348899850","pt":1646221735597,"mc":[{"id":"1.195453631","rc":[{"atb":[[3.25,22.22]],"id":26349442},{"atb":[[7.6,7.58]],"id":36120434},{"atl":[[190,1]],"id":40637101},{"atb":[[4.6,13.89]],"id":40917619},{"atl":[[19,2.78]],"id":40917619},{"atl":[[14,3.85]],"id":39183170},{"atb":[[11.5,4.76]],"id":35381686}],"con":true,"img":false}]}
{"op":"mcm","clk":"5348899988","pt":1646221737327,"mc":[{"id":"1.195453631","rc":[{"spn":14.92,"spf":1.0,"id":40637101},{"spn":21.68,"spf":1.0,"id":36120434},{"atb":[[2.22,40.98]],"id":41398505},{"atl":[[4.3,15.15]],"id":41398505},{"spn":24.75,"spf":1.0,"id":35381686}],"con":true,"img":false}]}
{"op":"mcm","clk":"5348900616","pt":1646221744391,"mc":[{"id":"1.195453631","rc":[{"atb":[[2.9,0]],"id":26349442},{"atl":[[220,0],[240,0],[260,0.77]],"id":40637101},{"atb":[[6.2,0],[7,13.67],[6.6,15]],"id":36120434},{"atb":[[3.55,0],[3.45,0],[3.65,0]],"id":40917619},{"atl":[[18,0],[19,1.11]],"id":40917619},{"atb":[[2.22,16.39],[2.26,0]],"id":41398505},{"atl":[[5.4,0],[5,0],[5.2,0]],"id":41398505},{"atl":[[22,0]],"id":39183170},{"atb":[[9,0]],"id":35381686},{"atl":[[19.5,0],[20,7.17]],"id":38554545}],"con":true,"img":false}]}
{"op":"mcm","clk":"5348900644","pt":1646221744645,"mc":[{"id":"1.195453631","rc":[{"atb":[[2.22,0],[2.18,16.95]],"id":41398505},{"atl":[[20,6.12],[21,6]],"id":38554545}],"con":true,"img":false}]}
{"op":"mcm","clk":"5348900743","pt":1646221745637,"mc":[{"id":"1.195453631","rc":[{"atb":[[3.15,34.88]],"id":26349442},{"atl":[[210,1.95]],"id":40637101},{"atb":[[7.2,12.1]],"id":36120434},{"atl":[[15,5.36]],"id":39183170},{"atb":[[10.5,16.49]],"id":35381686}],"con":true,"img":false}]}
{"op":"mcm","clk":"5348900811","pt":1646221746319,"mc":[{"id":"1.195453631","rc":[{"atb":[[3.35,0],[3.25,0],[3.3,8.7],[2.94,0]],"id":26349442},{"atl":[[18.5,1.14]],"id":40917619},{"atl":[[20,0]],"id":39183170},{"atb":[[9.4,0]],"id":35381686}],"con":true,"img":false}]}
{"op":"mcm","clk":"5348900820","pt":1646221746424,"mc":[{"id":"1.195453631","rc":[{"atb":[[17,0]],"id":36120434},{"atb":[[2.24,0]],"id":41398505}],"con":true,"img":false}]}
{"op":"mcm","clk":"5348900834","pt":1646221746528,"mc":[{"id":"1.195453631","rc":[{"atb":[[18,3.54]],"id":36120434},{"atb":[[2.2,107.91]],"id":41398505}],"con":true,"img":false}]}
{"op":"mcm","clk":"5348901123","pt":1646221749544,"mc":[{"id":"1.195453631","rc":[{"atb":[[17.5,0]],"id":36120434}],"con":true,"img":false}]}
{"op":"mcm","clk":"5348901509","pt":1646221753850,"mc":[{"id":"1.195453631","rc":[{"atb":[[18.5,5.39]],"id":36120434}],"con":true,"img":false}]}
{"op":"mcm","clk":"5348901576","pt":1646221754628,"mc":[{"id":"1.195453631","rc":[{"atb":[[2.14,43.86]],"id":41398505},{"atl":[[4.5,57.94]],"id":41398505},{"atl":[[23,2.27]],"id":38554545}],"con":true,"img":false}]}
{"op":"mcm","clk":"5348901667","pt":1646221755621,"mc":[{"id":"1.195453631","rc":[{"atb":[[6.8,21.55]],"id":36120434},{"atl":[[230,1]],"id":40637101},{"atl":[[16,8.33]],"id":39183170},{"atb":[[9.8,14.2]],"id":35381686}],"con":true,"img":false}]}
{"op":"mcm","clk":"5348901737","pt":1646221756356,"mc":[{"id":"1.195453631","rc":[{"atb":[[4.4,22.06]],"id":40917619},{"atl":[[19.5,2.7]],"id":40917619}],"con":true,"img":false}]}
{"op":"mcm","clk":"5348901744","pt":1646221756460,"mc":[{"id":"1.195453631","rc":[{"atl":[[240,0]],"id":35381686}],"con":true,"img":false}]}
{"op":"mcm","clk":"5348901753","pt":1646221756519,"mc":[{"id":"1.195453631","rc":[{"atl":[[220,2.72]],"id":35381686}],"con":true,"img":false}]}
{"op":"mcm","clk":"5348901768","pt":1646221756627,"mc":[{"id":"1.195453631","rc":[{"atl":[[230,0],[250,2.53]],"id":35381686}],"con":true,"img":false}]}
{"op":"mcm","clk":"5348902103","pt":1646221760064,"mc":[{"id":"1.195453631","rc":[{"atb":[[3,0]],"id":26349442},{"atl":[[4.5,21.43]],"id":41398505}],"con":true,"img":false}]}
{"op":"mcm","clk":"5348902112","pt":1646221760117,"mc":[{"id":"1.195453631","rc":[{"atb":[[3.2,54.36]],"id":26349442},{"atl":[[4,36.51]],"id":41398505}],"con":true,"img":false}]}
{"op":"mcm","clk":"5348902264","pt":1646221761732,"mc":[{"id":"1.195453631","rc":[{"atl":[[210,2],[250,0.53]],"id":35381686}],"con":true,"img":false}]}
{"op":"mcm","clk":"5348902283","pt":1646221761940,"mc":[{"id":"1.195453631","rc":[{"atl":[[210,0]],"id":35381686}],"con":true,"img":false}]}
{"op":"mcm","clk":"5348902302","pt":1646221762150,"mc":[{"id":"1.195453631","rc":[{"atl":[[210,2]],"id":35381686}],"con":true,"img":false}]}
{"op":"mcm","clk":"5348902578","pt":1646221764652,"mc":[{"id":"1.195453631","rc":[{"atb":[[2.1,68.18]],"id":41398505},{"atl":[[4.7,33.78]],"id":41398505},{"atl":[[25,3.12]],"id":38554545}],"con":true,"img":false}]}
{"op":"mcm","clk":"5348902684","pt":1646221765745,"mc":[{"id":"1.195453631","rc":[{"atl":[[19,0]],"id":39183170}],"con":true,"img":false}]}
{"op":"mcm","clk":"5348902744","pt":1646221766367,"mc":[{"id":"1.195453631","rc":[{"atb":[[4.2,39.06]],"id":40917619},{"atl":[[19,0],[20,0],[21,3.75],[22,0]],"id":40917619}],"con":true,"img":false}]}
{"op":"mcm","clk":"5348902757","pt":1646221766426,"mc":[{"id":"1.195453631","rc":[{"atl":[[3.75,0]],"id":41398505}],"con":true,"img":false}]}
{"op":"mcm","clk":"5348902768","pt":1646221766577,"mc":[{"id":"1.195453631","rc":[{"atl":[[3.65,18.26]],"id":41398505}],"con":true,"img":false}]}
{"op":"mcm","clk":"5348902963","pt":1646221768663,"mc":[{"id":"1.195453631","rc":[{"atb":[[3.3,14.75]],"id":39183170}],"con":true,"img":false}]}
{"op":"mcm","clk":"5348903562","pt":1646221774652,"mc":[{"id":"1.195453631","rc":[{"atb":[[2.06,195.04]],"id":41398505},{"atl":[[27,4.81]],"id":38554545}],"con":true,"img":false}]}
{"op":"mcm","clk":"5348903723","pt":1646221776374,"mc":[{"id":"1.195453631","rc":[{"atl":[[23,5.68]],"id":40917619}],"con":true,"img":false}]}
{"op":"mcm","clk":"5348903736","pt":1646221776478,"mc":[{"id":"1.195453631","rc":[{"atb":[[18,0]],"id":36120434}],"con":true,"img":false}]}
{"op":"mcm","clk":"5348903743","pt":1646221776581,"mc":[{"id":"1.195453631","rc":[{"atb":[[19,3.54]],"id":36120434}],"con":true,"img":false}]}
{"op":"mcm","clk":"5348903976","pt":1646221778890,"mc":[{"id":"1.195453631","rc":[{"atb":[[18.5,0]],"id":36120434}],"con":true,"img":false}]}
{"op":"mcm","clk":"5348904429","pt":1646221783174,"mc":[{"id":"1.195453631","rc":[{"atb":[[19.5,5.1]],"id":36120434}],"con":true,"img":false}]}
{"op":"mcm","clk":"5348904941","pt":1646221788182,"mc":[{"id":"1.195453631","rc":[{"atb":[[22,0]],"id":36120434},{"atl":[[70,2.72]],"id":36120434},{"atb":[[15,0.72]],"id":40637101},{"atl":[[40,2.72]],"id":40637101},{"atl":[[16,0]],"id":40917619},{"atb":[[27,1.2]],"id":35381686},{"atl":[[210,0]],"id":35381686},{"atl":[[18,2.92]],"id":38554545}],"con":true,"img":false}]}
{"op":"mcm","clk":"5348904953","pt":1646221788288,"mc":[{"id":"1.195453631","rc":[{"spl":[[1.01,10.72]],"id":40637101},{"spl":[[1.01,10.72]],"id":36120434},{"spl":[[1.01,10.72]],"id":40917619},{"spl":[[1.01,10.72]],"id":35381686},{"spl":[[1.01,10.72]],"id":38554545}],"con":true,"img":false}]}
{"op":"mcm","clk":"5348904962","pt":1646221788390,"mc":[{"id":"1.195453631","rc":[{"atb":[[24,0],[1.04,2.25]],"id":36120434}],"con":true,"img":false}]}
{"op":"mcm","clk":"5348904989","pt":1646221788598,"mc":[{"id":"1.195453631","rc":[{"atb":[[1.04,0.15]],"id":36120434}],"con":true,"img":false}]}
{"op":"mcm","clk":"5348905011","pt":1646221788754,"mc":[{"id":"1.195453631","rc":[{"atb":[[1.04,0]],"id":36120434}],"con":true,"img":false}]}
{"op":"mcm","clk":"5348905021","pt":1646221788861,"mc":[{"id":"1.195453631","rc":[{"atb":[[22,0.15]],"id":36120434}],"con":true,"img":false}]}
{"op":"mcm","clk":"5348905318","pt":1646221791918,"mc":[{"id":"1.195453631","rc":[{"atb":[[16,6.29]],"id":35381686},{"atb":[[7.8,13.88]],"id":38554545}],"con":true,"img":false}]}
{"op":"mcm","clk":"5348905775","pt":1646221796360,"mc":[{"id":"1.195453631","rc":[{"atb":[[3.25,8.89]],"id":39183170},{"atl":[[220,0]],"id":35381686}],"con":true,"img":false}]}
{"op":"mcm","clk":"5348905782","pt":1646221796463,"mc":[{"id":"1.195453631","rc":[{"atb":[[3.35,25.41]],"id":39183170},{"atl":[[240,2.72]],"id":35381686}],"con":true,"img":false}]}
{"op":"mcm","clk":"5348905965","pt":1646221798763,"mc":[{"id":"1.195453631","rc":[{"spn":20.37,"spf":1.0,"id":36120434},{"spn":14.24,"spf":1.0,"id":40637101},{"spn":8.01,"spf":1.0,"id":40917619},{"atb":[[16,0]],"id":35381686},{"spn":22.36,"spf":1.0,"id":35381686},{"spn":8.55,"spf":1.0,"id":38554545}],"con":true,"img":false}]}
{"op":"mcm","clk":"5348906117","pt":1646221800690,"mc":[{"id":"1.195453631","rc":[{"atb":[[3.3,6.88]],"id":39183170}],"con":true,"img":false}]}
{"op":"mcm","clk":"5348906211","pt":1646221801540,"mc":[{"id":"1.195453631","rc":[{"atb":[[2.98,25.25],[3.45,0],[2.88,0],[2.78,56.18],[2.68,0]],"id":26349442},{"atl":[[11,0],[13.5,0],[9.4,0],[16,0]],"id":26349442},{"atb":[[9.2,0],[10.5,0],[13,0],[15.5,0],[21,0.51]],"id":36120434},{"atl":[[300,1],[350,0],[200,0],[250,0]],"id":36120434},{"atb":[[6.4,0],[7.4,0],[13.5,0],[8.4,0],[9.4,0]],"id":40637101},{"atl":[[260,0],[160,0],[210,1],[110,0]],"id":40637101},{"atb":[[4.8,5.26],[4.3,21.82],[5.8,0],[5.3,0],[7.6,0]],"id":40917619},{"atl":[[36,0],[46,0],[65,0],[90,0]],"id":40917619},{"atb":[[1.98,0],[1.93,0],[2.36,30.06],[2.06,117.92],[2.16,0]],"id":41398505},{"atl":[[6.4,0],[7.4,0],[8.4,0],[5.7,0]],"id":41398505},{"atb":[[2.76,0],[2.56,0],[2.86,0],[2.66,0],[3.15,23.26]],"id":39183170},{"atl":[[11,0],[13.5,0],[8.4,0],[9.4,0]],"id":39183170},{"atb":[[9.2,0],[10.5,7.89],[13,0],[15.5,0],[21,0]],"id":35381686},{"atl":[[300,0],[350,0],[200,0],[250,0]],"id":35381686},{"atb":[[4.8,18.95],[5.8,0],[5.3,0],[8.6,0],[6.6,0]],"id":38554545},{"atl":[[65,0],[130,0],[90,0],[46,0]],"id":38554545}],"con":true,"img":false}]}
{"op":"mcm","clk":"5348906246","pt":1646221802003,"mc":[{"id":"1.195453631","rc":[{"atb":[[1.01,2]],"id":39183170}],"con":true,"img":false}]}
{"op":"mcm","clk":"5348906274","pt":1646221802285,"mc":[{"id":"1.195453631","rc":[{"atb":[[1.01,3.99]],"id":39183170}],"con":true,"img":false}]}
{"op":"mcm","clk":"5348906285","pt":1646221802488,"mc":[{"id":"1.195453631","rc":[{"atb":[[1.02,2.99]],"id":26349442},{"atb":[[1.03,2.88]],"id":40917619},{"atb":[[1.03,3.11]],"id":41398505},{"atb":[[1.02,3]],"id":39183170}],"con":true,"img":false}]}
{"op":"mcm","clk":"5348906297","pt":1646221802588,"mc":[{"id":"1.195453631","rc":[{"atb":[[1.01,2]],"id":39183170}],"con":true,"img":false}]}
{"op":"mcm","clk":"5348906307","pt":1646221802696,"mc":[{"id":"1.195453631","rc":[{"atb":[[3.55,1.99]],"id":39183170}],"con":true,"img":false}]}
{"op":"mcm","clk":"5348906336","pt":1646221802997,"mc":[{"id":"1.195453631","rc":[{"atb":[[1.02,0.26]],"id":26349442},{"atb":[[1.03,0.15]],"id":40917619},{"atb":[[1.03,0.38]],"id":41398505},{"atb":[[1.02,0.27]],"id":39183170},{"atb":[[16,6.29]],"id":35381686}],"con":true,"img":false}]}
{"op":"mcm","clk":"5348906369","pt":1646221803377,"mc":[{"id":"1.195453631","rc":[{"atb":[[1.03,0]],"id":40917619}],"con":true,"img":false}]}
{"op":"mcm","clk":"5348906378","pt":1646221803481,"mc":[{"id":"1.195453631","rc":[{"atb":[[1.02,0]],"id":26349442},{"atb":[[6.8,0.15]],"id":40917619},{"atb":[[1.03,0]],"id":41398505},{"atb":[[1.02,0]],"id":39183170}],"con":true,"img":false}]}
{"op":"mcm","clk":"5348906391","pt":1646221803583,"mc":[{"id":"1.195453631","rc":[{"atb":[[4,0.26]],"id":26349442},{"atb":[[2.76,0.38]],"id":41398505},{"atb":[[3.8,0.27]],"id":39183170}],"con":true,"img":false}]}
{"op":"mcm","clk":"5348906405","pt":1646221803786,"mc":[{"id":"1.195453631","rc":[{"atb":[[3.3,3.62]],"id":39183170}],"con":true,"img":false}]}
{"op":"mcm","clk":"5348906503","pt":1646221804983,"mc":[{"id":"1.195453631","rc":[{"atb":[[1.01,2]],"id":40917619}],"con":true,"img":false}]}
{"op":"mcm","clk":"5348906522","pt":1646221805187,"mc":[{"id":"1.195453631","rc":[{"atb":[[1.01,3.99]],"id":40917619}],"con":true,"img":false}]}
{"op":"mcm","clk":"5348906536","pt":1646221805396,"mc":[{"id":"1.195453631","rc":[{"atb":[[1.01,2]],"id":40917619}],"con":true,"img":false}]}
{"op":"mcm","clk":"5348906541","pt":1646221805498,"mc":[{"id":"1.195453631","rc":[{"atb":[[14,0]],"id":40637101},{"atb":[[8.6,1.99]],"id":40917619},{"atb":[[3.4,6.73]],"id":39183170}],"con":true,"img":false}]}
{"op":"mcm","clk":"5348906564","pt":1646221805711,"mc":[{"id":"1.195453631","rc":[{"atb":[[2.98,45.89],[3.45,16.68],[2.88,43.48],[2.78,102.1],[2.68,97.32]],"id":26349442},{"atl":[[11,13.32],[13.5,15.98],[9.4,15.86],[16,13.32]],"id":26349442},{"atb":[[6.4,30.28],[7.4,12.77],[13.5,3.27],[8.4,11.04],[9.4,4.86]],"id":40637101},{"atl":[[260,0.77],[160,0.83],[210,1.95],[110,1.22]],"id":40637101},{"atb":[[9.2,19.94],[10.5,8.6],[13,6.81],[15.5,2.81],[21,2.55]],"id":36120434},{"atl":[[300,1.67],[350,0.57],[200,0.67],[250,0.53]],"id":36120434},{"atb":[[4.8,26.77],[4.3,71.36],[5.8,8.51],[5.3,19.01],[7.6,6.19]],"id":40917619},{"atl":[[36,3.8],[46,2.95],[65,3.12],[90,2.24]],"id":40917619},{"atb":[[1.98,83.42],[1.93,175.81],[2.36,60.11],[2.06,195.04],[2.16,35.24]],"id":41398505},{"atl":[[6.4,24.66],[7.4,31.21],[8.4,27],[5.7,28.34]],"id":41398505},{"atb":[[2.76,46.45],[2.56,104.81],[2.86,21.97],[2.66,49.24],[3.15,42.27]],"id":39183170},{"atl":[[11,19.98],[13.5,15.98],[8.4,18],[9.4,15.86]],"id":39183170},{"atb":[[9.2,19.94],[10.5,16.49],[13,6.81],[15.5,2.81],[21,2.04]],"id":35381686},{"atl":[[300,0.67],[350,0.57],[200,0.67],[250,0.53]],"id":35381686},{"atb":[[4.8,61.97],[5.8,17.03],[5.3,19.01],[8.6,5.37],[6.6,7.29]],"id":38554545},{"atl":[[65,2.08],[130,1.54],[90,2.24],[46,2.95]],"id":38554545}],"con":true,"img":false}]}
{"op":"mcm","clk":"5348906611","pt":1646221806386,"mc":[{"id":"1.195453631","rc":[{"atb":[[13,0]],"id":40637101},{"atb":[[19,0]],"id":36120434},{"atb":[[3.35,0]],"id":39183170},{"atb":[[1.01,2]],"id":38554545}],"con":true,"img":false}]}
{"op":"mcm","clk":"5348906624","pt":1646221806491,"mc":[{"id":"1.195453631","rc":[{"atb":[[20,3.54]],"id":36120434},{"atb":[[12,4.87]],"id":40637101},{"atb":[[3.25,34.3]],"id":39183170}],"con":true,"img":false}]}
{"op":"mcm","clk":"5348906633","pt":1646221806596,"mc":[{"id":"1.195453631","rc":[{"atb":[[1.01,3.99]],"id":38554545}],"con":true,"img":false}]}
{"op":"mcm","clk":"5348906651","pt":1646221806804,"mc":[{"id":"1.195453631","rc":[{"atb":[[1.01,2]],"id":38554545}],"con":true,"img":false}]}
{"op":"mcm","clk":"5348906664","pt":1646221806923,"mc":[{"id":"1.195453631","rc":[{"atb":[[2.88,96.67],[2.78,45.92]],"id":26349442},{"atl":[[5.8,0],[10.5,0],[5.6,4.35],[8.6,13.16]],"id":26349442},{"atb":[[5.9,0],[15,2.72],[5,25]],"id":40637101},{"atl":[[40,4.72],[65,2]],"id":40637101},{"atb":[[5.4,22.73],[6.6,0]],"id":36120434},{"atl":[[130,0],[70,4.72],[85,2]],"id":36120434},{"atb":[[3.4,41.67],[3.15,0]],"id":40917619},{"atl":[[16,2]],"id":40917619},{"atb":[[2.22,35.24],[2.36,30.05]],"id":41398505},{"atl":[[5.1,24.39],[4.1,0],[3.7,7.41],[6,8.2]],"id":41398505},{"atb":[[2.54,64.94],[2.84,0]],"id":39183170},{"atb":[[27,3.2]],"id":35381686},{"atl":[[230,2],[420,2],[460,1],[490,0],[500,0]],"id":35381686},{"atb":[[7.8,16.82],[2.14,30.92],[7.2,0],[3.45,0]],"id":38554545},{"atl":[[18,4.92],[21,1],[22,4.76]],"id":38554545}],"con":true,"img":false}]}
{"op":"mcm","clk":"5348906673","pt":1646221807019,"mc":[{"id":"1.195453631","rc":[{"atl":[[100,0]],"id":40637101},{"atb":[[9,1.99],[11,4]],"id":38554545}],"con":true,"img":false}]}
{"op":"mcm","clk":"5348906683","pt":1646221807123,"mc":[{"id":"1.195453631","rc":[{"atl":[[4.5,2]],"id":26349442},{"atl":[[2.96,4]],"id":41398505}],"con":true,"img":false}]}
{"op":"mcm","clk":"5348906700","pt":1646221807283,"mc":[{"id":"1.195453631","rc":[{"atl":[[4.4,3]],"id":26349442},{"atl":[[2.94,2]],"id":41398505},{"atb":[[11.5,4]],"id":38554545}],"con":true,"img":false}]}
{"op":"mcm","clk":"5348906777","pt":1646221808216,"mc":[{"id":"1.195453631","rc":[{"atb":[[1.01,2]],"id":26349442}],"con":true,"img":false}]}
{"op":"mcm","clk":"5348906794","pt":1646221808373,"mc":[{"id":"1.195453631","rc":[{"atb":[[1.01,3.99]],"id":26349442}],"con":true,"img":false}]}
{"op":"mcm","clk":"5348906819","pt":1646221808686,"mc":[{"id":"1.195453631","rc":[{"atb":[[1.01,2]],"id":26349442}],"con":true,"img":false}]}
{"op":"mcm","clk":"5348906830","pt":1646221808785,"mc":[{"id":"1.195453631","rc":[{"atb":[[3.75,1.99]],"id":26349442}],"con":true,"img":false}]}
{"op":"mcm","clk":"5348906909","pt":1646221809776,"mc":[{"id":"1.195453631","rc":[{"atb":[[3.55,3.26]],"id":26349442}],"con":true,"img":false}]}
{"op":"mcm","clk":"5348906918","pt":1646221809881,"mc":[{"id":"1.195453631","rc":[{"atb":[[1.01,2]],"id":41398505}],"con":true,"img":false}]}
{"op":"mcm","clk":"5348906928","pt":1646221809985,"mc":[{"id":"1.195453631","rc":[{"atl":[[1000,1.66]],"id":40637101}],"con":true,"img":false}]}
{"op":"mcm","clk":"5348906946","pt":1646221810190,"mc":[{"id":"1.195453631","rc":[{"atb":[[14,7.25]],"id":40637101},{"atl":[[1000,0.21]],"id":40637101},{"atb":[[19.5,0]],"id":36120434},{"atb":[[1.01,3.99]],"id":41398505},{"atb":[[3.4,0]],"id":39183170},{"atb":[[16,0]],"id":35381686},{"atb":[[7.8,2.94]],"id":38554545}],"con":true,"img":false}]}
{"op":"mcm","clk":"5348906955","pt":1646221810294,"mc":[{"id":"1.195453631","rc":[{"atl":[[1000,0]],"id":40637101}],"con":true,"img":false}]}
{"op":"mcm","clk":"5348906964","pt":1646221810400,"mc":[{"id":"1.195453631","rc":[{"atl":[[38,0.21]],"id":40637101}],"con":true,"img":false}]}
{"op":"mcm","clk":"5348906967","pt":1646221810504,"mc":[{"id":"1.195453631","rc":[{"atb":[[1.01,2]],"id":41398505}],"con":true,"img":false}]}
{"op":"mcm","clk":"5348906973","pt":1646221810607,"mc":[{"id":"1.195453631","rc":[{"atb":[[1.02,1.99]],"id":41398505}],"con":true,"img":false}]}
{"op":"mcm","clk":"5348907090","pt":1646221812128,"mc":[{"id":"1.195453631","rc":[{"atb":[[9,0]],"id":38554545}],"con":true,"img":false}]}
{"op":"mcm","clk":"5348907105","pt":1646221812224,"mc":[{"id":"1.195453631","rc":[{"atb":[[1.02,1.99]],"id":38554545}],"con":true,"img":false}]}
{"op":"mcm","clk":"5348907136","pt":1646221812488,"mc":[{"id":"1.195453631","rc":[{"atl":[[4.3,2],[5.6,0],[5.5,4.44]],"id":26349442},{"atl":[[2.92,2],[3.7,0],[3.65,25.81]],"id":41398505},{"atb":[[12,3]],"id":38554545}],"con":true,"img":false}]}
{"op":"mcm","clk":"5348907350","pt":1646221814784,"mc":[{"id":"1.195453631","rc":[{"atb":[[3.7,2.89]],"id":39183170}],"con":true,"img":false}]}
{"op":"mcm","clk":"5348907491","pt":1646221816404,"mc":[{"id":"1.195453631","rc":[{"atb":[[3.3,43.58],[2.88,43.48]],"id":26349442},{"atl":[[7.2,16.13],[8.6,0]],"id":26349442},{"atb":[[7.8,12.78],[5,0]],"id":40637101},{"atb":[[20,0]],"id":36120434},{"atb":[[2.54,0],[3.05,73.18]],"id":39183170},{"atl":[[330,2],[420,0]],"id":35381686},{"atl":[[20,0]],"id":38554545}],"con":true,"img":false}]}
{"op":"mcm","clk":"5348907500","pt":1646221816509,"mc":[{"id":"1.195453631","rc":[{"atb":[[3.55,0]],"id":26349442},{"atb":[[5.4,0],[16,3.54],[7.2,25.77]],"id":36120434},{"atl":[[75,2],[85,0]],"id":36120434},{"atb":[[4.3,101.66],[3.4,0]],"id":40917619},{"atb":[[2.22,0],[2.34,35.24]],"id":41398505},{"atl":[[4.5,45.82],[5.1,0]],"id":41398505},{"atb":[[3,30.92],[2.14,0]],"id":38554545},{"atl":[[21,7.12]],"id":38554545}],"con":true,"img":false}]}
{"op":"mcm","clk":"5348907510","pt":1646221816606,"mc":[{"id":"1.195453631","rc":[{"atb":[[3.55,0]],"id":39183170}],"con":true,"img":false}]}
{"op":"mcm","clk":"5348907527","pt":1646221816712,"mc":[{"id":"1.195453631","rc":[{"atb":[[3.75,1.99]],"id":39183170}],"con":true,"img":false}]}
{"op":"mcm","clk":"5348907542","pt":1646221816816,"mc":[{"id":"1.195453631","rc":[{"atb":[[2.44,0]],"id":41398505},{"atl":[[480,1]],"id":35381686},{"atb":[[7.4,7.81]],"id":38554545}],"con":true,"img":false}]}
{"op":"mcm","clk":"5348907572","pt":1646221817080,"mc":[{"id":"1.195453631","rc":[{"atb":[[3.7,0]],"id":26349442},{"atl":[[4.3,0]],"id":26349442},{"trd":[[4.3,4]],"ltp":4.3,"tv":4.0,"id":26349442},{"atb":[[8.4,0.45]],"id":40917619},{"atb":[[2.5,0]],"id":41398505},{"atb":[[3.5,0]],"id":39183170},{"atb":[[8.8,0.42]],"id":38554545}],"con":true,"img":false}]}
{"op":"mcm","clk":"5348907599","pt":1646221817288,"mc":[{"id":"1.195453631","rc":[{"atl":[[4.4,0],[4.5,0]],"id":26349442}],"con":true,"img":false}]}
{"op":"mcm","clk":"5348907729","pt":1646221818693,"mc":[{"id":"1.195453631","rc":[{"atl":[[5.4,2.52]],"id":26349442}],"con":true,"img":false}]}
{"op":"mcm","clk":"5348907747","pt":1646221818913,"mc":[{"id":"1.195453631","rc":[{"atb":[[16.5,6.08]],"id":36120434},{"atl":[[2.9,2]],"id":41398505},{"atl":[[530,0],[550,0],[510,0]],"id":35381686},{"atb":[[6.4,0],[6.8,20.06],[12.5,3],[6,0]],"id":38554545}],"con":true,"img":false}]}
{"op":"mcm","clk":"5348907797","pt":1646221819481,"mc":[{"id":"1.195453631","rc":[{"atb":[[3.8,2.49]],"id":26349442},{"atb":[[8.8,2.49]],"id":40917619},{"atb":[[3.8,2.77]],"id":39183170},{"atb":[[12.5,5.08]],"id":38554545}],"con":true,"img":false}]}
{"op":"mcm","clk":"5348907855","pt":1646221820018,"mc":[{"id":"1.195453631","rc":[{"atb":[[3.75,0]],"id":39183170}],"con":true,"img":false}]}
{"op":"mcm","clk":"5348907863","pt":1646221820122,"mc":[{"id":"1.195453631","rc":[{"atb":[[3.85,1.99]],"id":39183170}],"con":true,"img":false}]}
{"op":"mcm","clk":"5348907883","pt":1646221820338,"mc":[{"id":"1.195453631","rc":[{"atb":[[8.6,0]],"id":40917619}],"con":true,"img":false}]}
{"op":"mcm","clk":"5348907891","pt":1646221820384,"mc":[{"id":"1.195453631","rc":[{"atb":[[9,1.99]],"id":40917619}],"con":true,"img":false}]}
{"op":"mcm","clk":"5348907908","pt":1646221820592,"mc":[{"id":"1.195453631","rc":[{"atb":[[3.75,0]],"id":26349442}],"con":true,"img":false}]}
{"op":"mcm","clk":"5348907917","pt":1646221820695,"mc":[{"id":"1.195453631","rc":[{"atb":[[3.85,1.99]],"id":26349442}],"con":true,"img":false}]}
{"op":"mcm","clk":"5348907926","pt":1646221820801,"mc":[{"id":"1.195453631","rc":[{"atb":[[3.7,0]],"id":39183170}],"con":true,"img":false}]}
{"op":"mcm","clk":"5348908087","pt":1646221822520,"mc":[{"id":"1.195453631","rc":[{"atl":[[5.7,10.4]],"id":26349442},{"atl":[[3.75,18.18]],"id":41398505}],"con":true,"img":false}]}
{"op":"mcm","clk":"5348908106","pt":1646221822727,"mc":[{"id":"1.195453631","rc":[{"atb":[[3.8,0]],"id":26349442},{"atb":[[8.8,0]],"id":40917619},{"atb":[[3.8,0.27]],"id":39183170}],"con":true,"img":false}]}
{"op":"mcm","clk":"5348908217","pt":1646221823931,"mc":[{"id":"1.195453631","rc":[{"atb":[[9,0]],"id":40917619}],"con":true,"img":false}]}
{"op":"mcm","clk":"5348908231","pt":1646221824025,"mc":[{"id":"1.195453631","rc":[{"atb":[[8.6,1.99]],"id":40917619}],"con":true,"img":false}]}
{"op":"mcm","clk":"5348908260","pt":1646221824286,"mc":[{"id":"1.195453631","rc":[{"atl":[[6.4,0],[6.8,0],[6,9.74]],"id":26349442},{"atl":[[3.6,12.61]],"id":41398505}],"con":true,"img":false}]}
{"op":"mcm","clk":"5348908270","pt":1646221824392,"mc":[{"id":"1.195453631","rc":[{"atl":[[4.3,0],[3.75,0],[4.5,24.39],[3.65,18.26],[4.7,0]],"id":41398505}],"con":true,"img":false}]}
{"op":"mcm","clk":"5348908310","pt":1646221824807,"mc":[{"id":"1.195453631","rc":[{"atb":[[8.8,2.49]],"id":40917619},{"atb":[[3.35,15.49]],"id":39183170}],"con":true,"img":false}]}
{"op":"mcm","clk":"5348908400","pt":1646221825530,"mc":[{"id":"1.195453631","rc":[{"atb":[[8.6,0]],"id":40917619}],"con":true,"img":false}]}
{"op":"mcm","clk":"5348908413","pt":1646221825633,"mc":[{"id":"1.195453631","rc":[{"atb":[[9,1.99]],"id":40917619}],"con":true,"img":false}]}
{"op":"mcm","clk":"5348908489","pt":1646221826411,"mc":[{"id":"1.195453631","rc":[{"atl":[[6.2,0]],"id":26349442},{"atl":[[4,0]],"id":41398505},{"atl":[[18,2]],"id":38554545}],"con":true,"img":false}]}
{"op":"mcm","clk":"5348908497","pt":1646221826514,"mc":[{"id":"1.195453631","rc":[{"atl":[[7,20.91]],"id":26349442},{"atl":[[4.4,36.51]],"id":41398505},{"atl":[[19,2.92]],"id":38554545}],"con":true,"img":false}]}
{"op":"mcm","clk":"5348908507","pt":1646221826619,"mc":[{"id":"1.195453631","rc":[{"atl":[[18,0],[20,2]],"id":38554545}],"con":true,"img":false}]}
{"op":"mcm","clk":"5348908530","pt":1646221826826,"mc":[{"id":"1.195453631","rc":[{"atl":[[500,1]],"id":35381686},{"atb":[[7,12.5]],"id":38554545},{"atl":[[22,0],[23,6.82]],"id":38554545}],"con":true,"img":false}]}
{"op":"mcm","clk":"5348908596","pt":1646221827511,"mc":[{"id":"1.195453631","rc":[{"atb":[[8.8,0]],"id":40917619}],"con":true,"img":false}]}
{"op":"mcm","clk":"5348908711","pt":1646221828599,"mc":[{"id":"1.195453631","rc":[{"atb":[[9,0]],"id":40917619}],"con":true,"img":false}]}
{"op":"mcm","clk":"5348908720","pt":1646221828707,"mc":[{"id":"1.195453631","rc":[{"atb":[[8.6,1.99]],"id":40917619}],"con":true,"img":false}]}
{"op":"mcm","clk":"5348908843","pt":1646221830006,"mc":[{"id":"1.195453631","rc":[{"atb":[[8.8,2.49]],"id":40917619}],"con":true,"img":false}]}
{"op":"mcm","clk":"5348908864","pt":1646221830213,"mc":[{"id":"1.195453631","rc":[{"atb":[[3,0],[2.84,14.79]],"id":38554545}],"con":true,"img":false}]}
{"op":"mcm","clk":"5348908962","pt":1646221831415,"mc":[{"id":"1.195453631","rc":[{"atb":[[8.6,0]],"id":40917619}],"con":true,"img":false}]}
{"op":"mcm","clk":"5348908971","pt":1646221831520,"mc":[{"id":"1.195453631","rc":[{"atb":[[9,1.99]],"id":40917619}],"con":true,"img":false}]}
{"op":"mcm","clk":"5348908994","pt":1646221831830,"mc":[{"id":"1.195453631","rc":[{"atl":[[19,4.92]],"id":38554545}],"con":true,"img":false}]}
{"op":"mcm","clk":"5348909001","pt":1646221831933,"mc":[{"id":"1.195453631","rc":[{"atl":[[20,0]],"id":38554545}],"con":true,"img":false}]}
{"op":"mcm","clk":"5348909011","pt":1646221832039,"mc":[{"id":"1.195453631","rc":[{"atl":[[19,2.92]],"id":38554545}],"con":true,"img":false}]}
{"op":"mcm","clk":"5348909021","pt":1646221832140,"mc":[{"id":"1.195453631","rc":[{"atl":[[19,4.92]],"id":38554545}],"con":true,"img":false}]}
{"op":"mcm","clk":"5348909033","pt":1646221832248,"mc":[{"id":"1.195453631","rc":[{"atb":[[8.8,0]],"id":40917619}],"con":true,"img":false}]}
{"op":"mcm","clk":"5348909067","pt":1646221832508,"mc":[{"id":"1.195453631","rc":[{"atl":[[5.9,14.96]],"id":26349442}],"con":true,"img":false}]}
{"op":"mcm","clk":"5348909096","pt":1646221832820,"mc":[{"id":"1.195453631","rc":[{"atb":[[9,0]],"id":40917619},{"atb":[[8.4,0]],"id":38554545}],"con":true,"img":false}]}
{"op":"mcm","clk":"5348909108","pt":1646221832929,"mc":[{"id":"1.195453631","rc":[{"atb":[[8.6,1.99]],"id":40917619},{"atb":[[8.8,1.71]],"id":38554545}],"con":true,"img":false}]}
{"op":"mcm","clk":"5348909238","pt":1646221834334,"mc":[{"id":"1.195453631","rc":[{"atl":[[3.7,18.52]],"id":41398505}],"con":true,"img":false}]}
{"op":"mcm","clk":"5348909285","pt":1646221834703,"mc":[{"id":"1.195453631","rc":[{"atb":[[8.8,2.49]],"id":40917619}],"con":true,"img":false}]}
{"op":"mcm","clk":"5348909364","pt":1646221835847,"mc":[{"id":"1.195453631","rc":[{"atb":[[8.6,0]],"id":40917619}],"con":true,"img":false}]}
{"op":"mcm","clk":"5348909376","pt":1646221835952,"mc":[{"id":"1.195453631","rc":[{"atb":[[9,1.99]],"id":40917619}],"con":true,"img":false}]}
{"op":"mcm","clk":"5348909429","pt":1646221836421,"mc":[{"id":"1.195453631","rc":[{"atl":[[40,2]],"id":40637101},{"atl":[[19,2],[21,1]],"id":38554545}],"con":true,"img":false}]}
{"op":"mcm","clk":"5348909439","pt":1646221836522,"mc":[{"id":"1.195453631","rc":[{"atl":[[38,2.94],[40,0],[55,4.72]],"id":40637101},{"atl":[[20,2.92],[22,6.12]],"id":38554545}],"con":true,"img":false}]}
{"op":"mcm","clk":"5348909450","pt":1646221836624,"mc":[{"id":"1.195453631","rc":[{"atl":[[38,4.94]],"id":40637101}],"con":true,"img":false}]}
{"op":"mcm","clk":"5348909463","pt":1646221836729,"mc":[{"id":"1.195453631","rc":[{"atl":[[55,2.72]],"id":40637101}],"con":true,"img":false}]}
{"op":"mcm","clk":"5348909471","pt":1646221836833,"mc":[{"id":"1.195453631","rc":[{"atl":[[520,1]],"id":35381686},{"atb":[[6.6,29.61]],"id":38554545}],"con":true,"img":false}]}
{"op":"mcm","clk":"5348909482","pt":1646221836940,"mc":[{"id":"1.195453631","rc":[{"atl":[[19,0],[20,4.92]],"id":38554545}],"con":true,"img":false}]}
{"op":"mcm","clk":"5348909524","pt":1646221837306,"mc":[{"id":"1.195453631","rc":[{"atb":[[8.8,0]],"id":40917619}],"con":true,"img":false}]}
{"op":"mcm","clk":"5348909562","pt":1646221837720,"mc":[{"id":"1.195453631","rc":[{"atb":[[9,0]],"id":40917619}],"con":true,"img":false}]}
{"op":"mcm","clk":"5348909572","pt":1646221837824,"mc":[{"id":"1.195453631","rc":[{"atb":[[8.6,1.99]],"id":40917619}],"con":true,"img":false}]}
{"op":"mcm","clk":"5348909792","pt":1646221839951,"mc":[{"id":"1.195453631","rc":[{"atb":[[8.8,2.49]],"id":40917619}],"con":true,"img":false}]}
{"op":"mcm","clk":"5348909801","pt":1646221840057,"mc":[{"id":"1.195453631","rc":[{"atb":[[1.02,1.66]],"id":36120434}],"con":true,"img":false}]}
{"op":"mcm","clk":"5348909817","pt":1646221840166,"mc":[{"id":"1.195453631","rc":[{"atl":[[1000,1.66]],"id":36120434},{"atb":[[1.02,1.66]],"id":40637101}],"con":true,"img":false}]}
{"op":"mcm","clk":"5348909827","pt":1646221840218,"mc":[{"id":"1.195453631","rc":[{"atb":[[1.01,3.66]],"id":40917619},{"atb":[[1.03,1.66]],"id":35381686}],"con":true,"img":false}]}
{"op":"mcm","clk":"5348909846","pt":1646221840427,"mc":[{"id":"1.195453631","rc":[{"atb":[[1.02,0.34]],"id":36120434},{"atl":[[1000,0.14]],"id":36120434}],"con":true,"img":false}]}
{"op":"mcm","clk":"5348909858","pt":1646221840531,"mc":[{"id":"1.195453631","rc":[{"atl":[[1000,1.66]],"id":36120434},{"atb":[[1.02,0.51]],"id":40637101}],"con":true,"img":false}]}
{"op":"mcm","clk":"5348909865","pt":1646221840633,"mc":[{"id":"1.195453631","rc":[{"atl":[[60,0.14]],"id":36120434},{"atb":[[1.03,0.28]],"id":35381686}],"con":true,"img":false}]}
{"op":"mcm","clk":"5348909876","pt":1646221840736,"mc":[{"id":"1.195453631","rc":[{"atb":[[1.01,2.94]],"id":40917619}],"con":true,"img":false}]}
{"op":"mcm","clk":"5348909888","pt":1646221840849,"mc":[{"id":"1.195453631","rc":[{"atb":[[1.02,0]],"id":36120434}],"con":true,"img":false}]}
{"op":"mcm","clk":"5348909898","pt":1646221840951,"mc":[{"id":"1.195453631","rc":[{"atb":[[24,0.34]],"id":36120434}],"con":true,"img":false}]}
{"op":"mcm","clk":"5348909917","pt":1646221841161,"mc":[{"id":"1.195453631","rc":[{"atb":[[1.02,0]],"id":40637101},{"atl":[[23,2.27],[24,4.35]],"id":38554545}],"con":true,"img":false}]}
{"op":"mcm","clk":"5348909925","pt":1646221841216,"mc":[{"id":"1.195453631","rc":[{"atb":[[16,0.51]],"id":40637101},{"atb":[[8.6,0]],"id":40917619}],"con":true,"img":false}]}
{"op":"mcm","clk":"5348909935","pt":1646221841323,"mc":[{"id":"1.195453631","rc":[{"atl":[[1000,0.14]],"id":36120434},{"atb":[[9,1.99]],"id":40917619},{"atb":[[1.03,0]],"id":35381686}],"con":true,"img":false}]}
{"op":"mcm","clk":"5348909948","pt":1646221841426,"mc":[{"id":"1.195453631","rc":[{"atb":[[29,0.28]],"id":35381686}],"con":true,"img":false}]}
{"op":"mcm","clk":"5348909967","pt":1646221841632,"mc":[{"id":"1.195453631","rc":[{"atb":[[1.01,2]],"id":40917619}],"con":true,"img":false}]}
{"op":"mcm","clk":"5348909979","pt":1646221841737,"mc":[{"id":"1.195453631","rc":[{"atb":[[8.8,3.44]],"id":40917619}],"con":true,"img":false}]}
{"op":"mcm","clk":"5348909999","pt":1646221841945,"mc":[{"id":"1.195453631","rc":[{"atl":[[1000,0]],"id":36120434}],"con":true,"img":false}]}
{"op":"mcm","clk":"5348910011","pt":1646221842050,"mc":[{"id":"1.195453631","rc":[{"atl":[[60,0.28]],"id":36120434}],"con":true,"img":false}]}
{"op":"mcm","clk":"5348910021","pt":1646221842153,"mc":[{"id":"1.195453631","rc":[{"atb":[[1.01,3.66]],"id":40917619}],"con":true,"img":false}]}
{"op":"mcm","clk":"5348910027","pt":1646221842257,"mc":[{"id":"1.195453631","rc":[{"atb":[[8.8,2.49]],"id":40917619}],"con":true,"img":false}]}
{"op":"mcm","clk":"5348910038","pt":1646221842362,"mc":[{"id":"1.195453631","rc":[{"atb":[[1.01,2.9]],"id":40917619}],"con":true,"img":false}]}
{"op":"mcm","clk":"5348910060","pt":1646221842523,"mc":[{"id":"1.195453631","rc":[{"atl":[[6.2,23.5]],"id":26349442},{"atb":[[1.01,2]],"id":40917619}],"con":true,"img":false}]}
{"op":"mcm","clk":"5348910067","pt":1646221842622,"mc":[{"id":"1.195453631","rc":[{"atb":[[9.2,0.9],[8.8,0]],"id":40917619}],"con":true,"img":false}]}
{"op":"mcm","clk":"5348910115","pt":1646221843246,"mc":[{"id":"1.195453631","rc":[{"atl":[[22,10.88]],"id":38554545}],"con":true,"img":false}]}
{"op":"mcm","clk":"5348910123","pt":1646221843353,"mc":[{"id":"1.195453631","rc":[{"atl":[[24,0]],"id":38554545}],"con":true,"img":false}]}
{"op":"mcm","clk":"5348910196","pt":1646221844345,"mc":[{"id":"1.195453631","rc":[{"atl":[[3.8,26.79]],"id":41398505}],"con":true,"img":false}]}
{"op":"mcm","clk":"5348910258","pt":1646221845128,"mc":[{"id":"1.195453631","rc":[{"atb":[[9.4,2.49]],"id":40917619}],"con":true,"img":false}]}
{"op":"mcm","clk":"5348910322","pt":1646221845853,"mc":[{"id":"1.195453631","rc":[{"atb":[[9,0]],"id":40917619}],"con":true,"img":false}]}
{"op":"mcm","clk":"5348910328","pt":1646221845957,"mc":[{"id":"1.195453631","rc":[{"atb":[[9.6,1.99]],"id":40917619}],"con":true,"img":false}]}
{"op":"mcm","clk":"5348910365","pt":1646221846426,"mc":[{"id":"1.195453631","rc":[{"atb":[[3.2,0]],"id":26349442},{"atb":[[16,0]],"id":36120434},{"atb":[[12,0]],"id":40637101},{"atl":[[240,0]],"id":35381686}],"con":true,"img":false}]}
{"op":"mcm","clk":"5348910373","pt":1646221846533,"mc":[{"id":"1.195453631","rc":[{"atb":[[3.35,54.36]],"id":26349442},{"atb":[[17,3.54]],"id":36120434},{"atb":[[13,4.87]],"id":40637101},{"atl":[[220,2.72],[250,2.53]],"id":35381686}],"con":true,"img":false}]}
{"op":"mcm","clk":"5348910380","pt":1646221846637,"mc":[{"id":"1.195453631","rc":[{"atl":[[230,0]],"id":35381686}],"con":true,"img":false}]}
{"op":"mcm","clk":"5348910388","pt":1646221846743,"mc":[{"id":"1.195453631","rc":[{"atb":[[9.4,0]],"id":40917619}],"con":true,"img":false}]}
{"op":"mcm","clk":"5348910589","pt":1646221848943,"mc":[{"id":"1.195453631","rc":[{"atb":[[16.5,0]],"id":36120434}],"con":true,"img":false}]}
{"op":"mcm","clk":"5348910600","pt":1646221849049,"mc":[{"id":"1.195453631","rc":[{"atb":[[9.6,0],[9.8,2.49]],"id":40917619}],"con":true,"img":false}]}
{"op":"mcm","clk":"5348910614","pt":1646221849153,"mc":[{"id":"1.195453631","rc":[{"atb":[[9.4,1.99]],"id":40917619}],"con":true,"img":false}]}
{"op":"mcm","clk":"5348910662","pt":1646221849752,"mc":[{"id":"1.195453631","rc":[{"atb":[[7,0]],"id":35381686}],"con":true,"img":false}]}
{"op":"mcm","clk":"5348910695","pt":1646221850166,"mc":[{"id":"1.195453631","rc":[{"atb":[[9.4,0]],"id":40917619}],"con":true,"img":false}]}
{"op":"mcm","clk":"5348910704","pt":1646221850217,"mc":[{"id":"1.195453631","rc":[{"atb":[[10,1.99]],"id":40917619}],"con":true,"img":false}]}
{"op":"mcm","clk":"5348910816","pt":1646221851672,"mc":[{"id":"1.195453631","rc":[{"atb":[[9.8,0]],"id":40917619},{"atl":[[210,2],[250,0.53]],"id":35381686}],"con":true,"img":false}]}
{"op":"mcm","clk":"5348910833","pt":1646221851829,"mc":[{"id":"1.195453631","rc":[{"atl":[[210,0]],"id":35381686}],"con":true,"img":false}]}
{"op":"mcm","clk":"5348910839","pt":1646221851932,"mc":[{"id":"1.195453631","rc":[{"atl":[[210,2]],"id":35381686}],"con":true,"img":false}]}
{"op":"mcm","clk":"5348910875","pt":1646221852449,"mc":[{"id":"1.195453631","rc":[{"atb":[[10,0]],"id":40917619}],"con":true,"img":false}]}
{"op":"mcm","clk":"5348910884","pt":1646221852553,"mc":[{"id":"1.195453631","rc":[{"atb":[[9.4,1.99]],"id":40917619}],"con":true,"img":false}]}
{"op":"mcm","clk":"5348910927","pt":1646221853026,"mc":[{"id":"1.195453631","rc":[{"atb":[[17.5,5.72]],"id":36120434}],"con":true,"img":false}]}
{"op":"mcm","clk":"5348911024","pt":1646221854383,"mc":[{"id":"1.195453631","rc":[{"atb":[[9.6,2.49]],"id":40917619},{"atl":[[3.9,43.1]],"id":41398505}],"con":true,"img":false}]}
{"op":"mcm","clk":"5348911067","pt":1646221854846,"mc":[{"id":"1.195453631","rc":[{"atb":[[9.4,0]],"id":40917619}],"con":true,"img":false}]}
{"op":"mcm","clk":"5348911076","pt":1646221854952,"mc":[{"id":"1.195453631","rc":[{"atb":[[9.8,1.99]],"id":40917619}],"con":true,"img":false}]}
{"op":"mcm","clk":"5348911129","pt":1646221855570,"mc":[{"id":"1.195453631","rc":[{"atb":[[3.35,0]],"id":26349442},{"atl":[[6,0]],"id":26349442},{"atb":[[3.25,8.89]],"id":39183170}],"con":true,"img":false}]}
{"op":"mcm","clk":"5348911138","pt":1646221855673,"mc":[{"id":"1.195453631","rc":[{"atb":[[3.25,54.36]],"id":26349442},{"atl":[[5.6,9.74]],"id":26349442},{"atb":[[3.4,25.41]],"id":39183170}],"con":true,"img":false}]}
{"op":"mcm","clk":"5348911220","pt":1646221856453,"mc":[{"id":"1.195453631","rc":[{"atb":[[3.25,0]],"id":26349442}],"con":true,"img":false}]}
{"op":"mcm","clk":"5348911230","pt":1646221856555,"mc":[{"id":"1.195453631","rc":[{"atb":[[3.2,54.36]],"id":26349442}],"con":true,"img":false}]}
{"op":"mcm","clk":"5348911243","pt":1646221856762,"mc":[{"id":"1.195453631","rc":[{"atb":[[9.6,0]],"id":40917619}],"con":true,"img":false}]}
{"op":"mcm","clk":"5348911344","pt":1646221858068,"mc":[{"id":"1.195453631","rc":[{"atb":[[10,2.49],[9.8,0]],"id":40917619}],"con":true,"img":false}]}
{"op":"mcm","clk":"5348911350","pt":1646221858171,"mc":[{"id":"1.195453631","rc":[{"atb":[[9.4,1.99]],"id":40917619}],"con":true,"img":false}]}
{"op":"mcm","clk":"5348911401","pt":1646221858747,"mc":[{"id":"1.195453631","rc":[{"atb":[[8.2,0]],"id":40917619}],"con":true,"img":false}]}
{"op":"mcm","clk":"5348911420","pt":1646221858955,"mc":[{"id":"1.195453631","rc":[{"spn":4.7,"spf":"NaN","id":26349442},{"spn":19.45,"spf":1.0,"id":36120434},{"spn":14.67,"spf":1.0,"id":40637101},{"atb":[[8.4,1.81]],"id":40917619},{"spn":8.82,"spf":1.0,"id":40917619},{"spn":2.83,"spf":"NaN","id":41398505},{"spn":4.87,"spf":"NaN","id":39183170},{"spn":23.89,"spf":1.0,"id":35381686},{"spn":12.11,"spf":1.0,"id":38554545}],"con":true,"img":false}]}
{"op":"mcm","clk":"5348911499","pt":1646221859655,"mc":[{"id":"1.195453631","rc":[{"atb":[[3.35,0]],"id":39183170}],"con":true,"img":false}]}
{"op":"mcm","clk":"5348911557","pt":1646221860194,"mc":[{"id":"1.195453631","rc":[{"atb":[[9.4,0]],"id":40917619}],"con":true,"img":false}]}
{"op":"mcm","clk":"5348911570","pt":1646221860282,"mc":[{"id":"1.195453631","rc":[{"atb":[[1.02,1.99]],"id":40917619}],"con":true,"img":false}]}
{"op":"mcm","clk":"5348911859","pt":1646221863261,"mc":[{"id":"1.195453631","rc":[{"atb":[[3.5,3.19]],"id":39183170}],"con":true,"img":false}]}
{"op":"mcm","clk":"5348912141","pt":1646221866343,"mc":[{"id":"1.195453631","rc":[{"atl":[[38,2.21]],"id":40637101},{"atb":[[3.4,0]],"id":39183170},{"atb":[[27,2],[30,1.09]],"id":35381686}],"con":true,"img":false}]}
{"op":"mcm","clk":"5348912152","pt":1646221866448,"mc":[{"id":"1.195453631","rc":[{"atl":[[36,2.72],[38,0.21],[55,4.72]],"id":40637101},{"atb":[[3.25,34.3]],"id":39183170},{"atb":[[1.03,1.66],[27,0],[29,0],[30,3.09]],"id":35381686}],"con":true,"img":false}]}
{"op":"mcm","clk":"5348912160","pt":1646221866563,"mc":[{"id":"1.195453631","rc":[{"atb":[[1.03,0.25]],"id":35381686},{"atb":[[7.6,0]],"id":38554545}],"con":true,"img":false}]}
{"op":"mcm","clk":"5348912171","pt":1646221866655,"mc":[{"id":"1.195453631","rc":[{"atb":[[7.8,10.43]],"id":38554545}],"con":true,"img":false}]}
{"op":"mcm","clk":"5348912180","pt":1646221866760,"mc":[{"id":"1.195453631","rc":[{"atb":[[1.03,0]],"id":35381686}],"con":true,"img":false}]}
{"op":"mcm","clk":"5348912191","pt":1646221866863,"mc":[{"id":"1.195453631","rc":[{"atb":[[32,0.25]],"id":35381686}],"con":true,"img":false}]}
{"op":"mcm","clk":"5348912339","pt":1646221868679,"mc":[{"id":"1.195453631","rc":[{"atb":[[3.5,0]],"id":39183170}],"con":true,"img":false}]}
{"op":"mcm","clk":"5348912358","pt":1646221868940,"mc":[{"id":"1.195453631","rc":[{"atl":[[3.95,0]],"id":41398505}],"con":true,"img":false}]}
{"op":"mcm","clk":"5348912714","pt":1646221872580,"mc":[{"id":"1.195453631","rc":[{"atb":[[3.35,6.39]],"id":39183170}],"con":true,"img":false}]}
{"op":"mcm","clk":"5348912735","pt":1646221872785,"mc":[{"id":"1.195453631","rc":[{"atl":[[470,1]],"id":35381686}],"con":true,"img":false}]}
{"op":"mcm","clk":"5348912741","pt":1646221872888,"mc":[{"id":"1.195453631","rc":[{"atl":[[460,0]],"id":35381686}],"con":true,"img":false}]}
{"op":"mcm","clk":"5348913022","pt":1646221876364,"mc":[{"id":"1.195453631","rc":[{"atl":[[36,0]],"id":40637101},{"atb":[[17,0]],"id":36120434},{"atl":[[3.65,66.23]],"id":41398505},{"atb":[[6.8,0]],"id":38554545}],"con":true,"img":false}]}
{"op":"mcm","clk":"5348913029","pt":1646221876466,"mc":[{"id":"1.195453631","rc":[{"atl":[[40,2.72]],"id":40637101},{"atb":[[18,3.54]],"id":36120434},{"atl":[[4.4,0]],"id":41398505},{"atb":[[7.6,20.06]],"id":38554545}],"con":true,"img":false}]}
{"op":"mcm","clk":"5348913037","pt":1646221876572,"mc":[{"id":"1.195453631","rc":[{"atl":[[40,4.72],[55,2.72]],"id":40637101}],"con":true,"img":false}]}
{"op":"mcm","clk":"5348913211","pt":1646221878883,"mc":[{"id":"1.195453631","rc":[{"atb":[[17.5,0]],"id":36120434}],"con":true,"img":false}]}
{"op":"mcm","clk":"5348913498","pt":1646221882482,"mc":[{"id":"1.195453631","rc":[{"atb":[[18.5,5.39]],"id":36120434}],"con":true,"img":false}]}
{"op":"mcm","clk":"5348913525","pt":1646221882797,"mc":[{"id":"1.195453631","rc":[{"atl":[[490,1]],"id":35381686}],"con":true,"img":false}]}
{"op":"mcm","clk":"5348913851","pt":1646221886498,"mc":[{"id":"1.195453631","rc":[{"atl":[[22,4.76]],"id":38554545}],"con":true,"img":false}]}
{"op":"mcm","clk":"5348913860","pt":1646221886609,"mc":[{"id":"1.195453631","rc":[{"atl":[[20,11.04]],"id":38554545}],"con":true,"img":false}]}
{"op":"mcm","clk":"5348914090","pt":1646221889402,"mc":[{"id":"1.195453631","rc":[{"atl":[[95,0]],"id":36120434},{"atl":[[20,4.92]],"id":38554545}],"con":true,"img":false}]}
{"op":"mcm","clk":"5348914102","pt":1646221889505,"mc":[{"id":"1.195453631","rc":[{"atl":[[70,7.45]],"id":36120434},{"atl":[[21,7.12]],"id":38554545}],"con":true,"img":false}]}
{"op":"mcm","clk":"5348914417","pt":1646221892793,"mc":[{"id":"1.195453631","rc":[{"atl":[[510,1]],"id":35381686}],"con":true,"img":false}]}
{"op":"mcm","clk":"5348914426","pt":1646221892887,"mc":[{"id":"1.195453631","rc":[{"atl":[[520,0],[480,0],[500,0]],"id":35381686}],"con":true,"img":false}]}
{"op":"mcm","clk":"5348914723","pt":1646221896415,"mc":[{"id":"1.195453631","rc":[{"atb":[[34,0.95],[30,2]],"id":35381686}],"con":true,"img":false}]}
{"op":"mcm","clk":"5348914730","pt":1646221896518,"mc":[{"id":"1.195453631","rc":[{"atl":[[220,0]],"id":35381686}],"con":true,"img":false}]}
{"op":"mcm","clk":"5348914740","pt":1646221896579,"mc":[{"id":"1.195453631","rc":[{"atl":[[40,2]],"id":40637101},{"atb":[[28,2.13],[30,0]],"id":35381686},{"atl":[[200,3.39]],"id":35381686}],"con":true,"img":false}]}
{"op":"mcm","clk":"5348914747","pt":1646221896680,"mc":[{"id":"1.195453631","rc":[{"atl":[[38,2.94],[55,4.72]],"id":40637101},{"atl":[[210,0],[470,0],[480,1],[250,2.53]],"id":35381686}],"con":true,"img":false}]}
{"op":"mcm","clk":"5348914762","pt":1646221896885,"mc":[{"id":"1.195453631","rc":[{"atl":[[40,0],[55,2.72]],"id":40637101}],"con":true,"img":false}]}
{"op":"mcm","clk":"5348914777","pt":1646221896990,"mc":[{"id":"1.195453631","rc":[{"atl":[[38,4.94]],"id":40637101}],"con":true,"img":false}]}
{"op":"mcm","clk":"5348915002","pt":1646221899893,"mc":[{"id":"1.195453631","rc":[{"atb":[[3.35,8.51]],"id":26349442},{"atl":[[5.5,0],[5.7,4.16]],"id":26349442},{"atb":[[8.8,4]],"id":40917619},{"atl":[[18.5,0],[19,1.11]],"id":40917619}],"con":true,"img":false}]}
{"op":"mcm","clk":"5348915037","pt":1646221900309,"mc":[{"id":"1.195453631","rc":[{"atb":[[32,0],[1.03,1.66]],"id":35381686}],"con":true,"img":false}]}
{"op":"mcm","clk":"5348915053","pt":1646221900513,"mc":[{"id":"1.195453631","rc":[{"atb":[[1.03,0.23],[26,2.41]],"id":35381686}],"con":true,"img":false}]}
{"op":"mcm","clk":"5348915060","pt":1646221900618,"mc":[{"id":"1.195453631","rc":[{"atb":[[28,0.13]],"id":35381686}],"con":true,"img":false}]}
{"op":"mcm","clk":"5348915068","pt":1646221900721,"mc":[{"id":"1.195453631","rc":[{"atb":[[1.03,0]],"id":35381686}],"con":true,"img":false}]}
{"op":"mcm","clk":"5348915077","pt":1646221900827,"mc":[{"id":"1.195453631","rc":[{"atb":[[36,0.23]],"id":35381686}],"con":true,"img":false}]}
{"op":"mcm","clk":"5348915143","pt":1646221901606,"mc":[{"id":"1.195453631","rc":[{"atb":[[9,2]],"id":40917619},{"atl":[[3.6,4.92],[3.55,7.84]],"id":41398505},{"atl":[[480,0]],"id":35381686},{"atb":[[2.6,25],[2.84,0]],"id":38554545},{"atl":[[22,0],[23,6.82]],"id":38554545}],"con":true,"img":false}]}
{"op":"mcm","clk":"5348915158","pt":1646221901812,"mc":[{"id":"1.195453631","rc":[{"atb":[[3.35,0]],"id":26349442},{"atl":[[5.5,4.35]],"id":26349442},{"atb":[[8,0],[7.2,16.9],[7.6,0]],"id":36120434},{"atb":[[4.8,21.51],[9,0],[9.2,3.9],[5,5],[8.8,0]],"id":40917619},{"atl":[[18.5,1.14],[19,0]],"id":40917619},{"atb":[[12.5,0],[13.5,8.8]],"id":35381686},{"atb":[[11,0],[11.5,0],[13,2]],"id":38554545}],"con":true,"img":false}]}
{"op":"mcm","clk":"5348915166","pt":1646221901918,"mc":[{"id":"1.195453631","rc":[{"atl":[[190,2],[250,0.53]],"id":35381686}],"con":true,"img":false}]}
{"op":"mcm","clk":"5348915239","pt":1646221902798,"mc":[{"id":"1.195453631","rc":[{"atl":[[5.4,0]],"id":26349442}],"con":true,"img":false}]}
{"op":"mcm","clk":"5348915258","pt":1646221903009,"mc":[{"id":"1.195453631","rc":[{"atb":[[12.5,3]],"id":38554545}],"con":true,"img":false}]}
{"op":"mcm","clk":"5348915309","pt":1646221903630,"mc":[{"id":"1.195453631","rc":[{"atb":[[3.35,8.51]],"id":26349442},{"atl":[[5.5,0]],"id":26349442},{"atb":[[9.2,0.9]],"id":40917619},{"atb":[[2.22,16.39],[2.18,0]],"id":41398505},{"atl":[[2.94,0],[2.92,0],[2.9,0],[2.96,0]],"id":41398505},{"atb":[[12,0],[12.5,0],[13,0]],"id":38554545},{"atl":[[19.5,1.08],[21,6.12]],"id":38554545}],"con":true,"img":false}]}
{"op":"mcm","clk":"5348915331","pt":1646221903790,"mc":[{"id":"1.195453631","rc":[{"atb":[[7.4,3.12],[7.8,7.49]],"id":38554545},{"atl":[[14,3]],"id":38554545}],"con":true,"img":false}]}
{"op":"mcm","clk":"5348915421","pt":1646221904623,"mc":[{"id":"1.195453631","rc":[{"atb":[[1.02,0]],"id":38554545}],"con":true,"img":false}]}
{"op":"mcm","clk":"5348915428","pt":1646221904727,"mc":[{"id":"1.195453631","rc":[{"atb":[[8.8,3.7]],"id":38554545}],"con":true,"img":false}]}
{"op":"mcm","clk":"5348915502","pt":1646221905419,"mc":[{"id":"1.195453631","rc":[{"atb":[[2.5,2.49]],"id":41398505},{"atb":[[9,2.49]],"id":38554545}],"con":true,"img":false}]}
{"op":"mcm","clk":"5348915524","pt":1646221905625,"mc":[{"id":"1.195453631","rc":[{"atb":[[8.8,1.71]],"id":38554545}],"con":true,"img":false}]}
{"op":"mcm","clk":"5348915535","pt":1646221905730,"mc":[{"id":"1.195453631","rc":[{"atb":[[26,0.41],[28,2.13]],"id":35381686},{"atb":[[9.2,1.99]],"id":38554545}],"con":true,"img":false}]}
{"op":"mcm","clk":"5348915599","pt":1646221906412,"mc":[{"id":"1.195453631","rc":[{"atl":[[5.6,0]],"id":26349442},{"atb":[[18,0]],"id":36120434},{"atb":[[2.2,0]],"id":41398505},{"atl":[[200,0.67]],"id":35381686},{"atb":[[7.6,0]],"id":38554545}],"con":true,"img":false}]}
{"op":"mcm","clk":"5348915610","pt":1646221906513,"mc":[{"id":"1.195453631","rc":[{"atl":[[5.8,9.74]],"id":26349442},{"atb":[[19,3.54]],"id":36120434},{"atb":[[2.18,107.91]],"id":41398505},{"atl":[[240,2.72]],"id":35381686},{"atb":[[7.2,20.06]],"id":38554545}],"con":true,"img":false}]}
{"op":"mcm","clk":"5348915664","pt":1646221907064,"mc":[{"id":"1.195453631","rc":[{"atl":[[190,0],[230,2]],"id":35381686}],"con":true,"img":false}]}
{"op":"mcm","clk":"5348915687","pt":1646221907293,"mc":[{"id":"1.195453631","rc":[{"atl":[[5.5,4.35]],"id":26349442},{"atb":[[2.44,11.39]],"id":41398505},{"atl":[[3.55,0],[3.7,7.41]],"id":41398505},{"atb":[[2.6,0],[3.55,36.44]],"id":38554545},{"atl":[[13.5,4]],"id":38554545}],"con":true,"img":false}]}
{"op":"mcm","clk":"5348915766","pt":1646221908130,"mc":[{"id":"1.195453631","rc":[{"atl":[[3.6,8.25]],"id":41398505}],"con":true,"img":false}]}
{"op":"mcm","clk":"5348915776","pt":1646221908234,"mc":[{"id":"1.195453631","rc":[{"atb":[[9,0]],"id":38554545}],"con":true,"img":false}]}
{"op":"mcm","clk":"5348915810","pt":1646221908598,"mc":[{"id":"1.195453631","rc":[{"atb":[[9.2,0]],"id":38554545}],"con":true,"img":false}]}
{"op":"mcm","clk":"5348915821","pt":1646221908702,"mc":[{"id":"1.195453631","rc":[{"atb":[[9,1.99]],"id":38554545}],"con":true,"img":false}]}
{"op":"mcm","clk":"5348915876","pt":1646221909324,"mc":[{"id":"1.195453631","rc":[{"atb":[[9,4.48]],"id":38554545}],"con":true,"img":false}]}
{"op":"mcm","clk":"5348915912","pt":1646221909693,"mc":[{"id":"1.195453631","rc":[{"atb":[[18.5,0]],"id":36120434}],"con":true,"img":false}]}
{"op":"mcm","clk":"5348916071","pt":1646221911615,"mc":[{"id":"1.195453631","rc":[{"atb":[[2.44,0]],"id":41398505}],"con":true,"img":false}]}
{"op":"mcm","clk":"5348916078","pt":1646221911718,"mc":[{"id":"1.195453631","rc":[{"atb":[[4.8,34.67]],"id":40917619},{"atb":[[12.5,4.35]],"id":35381686},{"atl":[[530,1]],"id":35381686}],"con":true,"img":false}]}
{"op":"mcm","clk":"5348916085","pt":1646221911823,"mc":[{"id":"1.195453631","rc":[{"atb":[[6.8,8.62]],"id":36120434}],"con":true,"img":false}]}
{"op":"mcm","clk":"5348916246","pt":1646221913632,"mc":[{"id":"1.195453631","rc":[{"atb":[[19.5,5.1]],"id":36120434}],"con":true,"img":false}]}
{"op":"mcm","clk":"5348916261","pt":1646221913839,"mc":[{"id":"1.195453631","rc":[{"atb":[[7,8.33]],"id":38554545},{"atl":[[21,8.62]],"id":38554545}],"con":true,"img":false}]}
{"op":"mcm","clk":"5348916272","pt":1646221913893,"mc":[{"id":"1.195453631","rc":[{"atl":[[5.5,0]],"id":26349442},{"atb":[[4.2,0]],"id":40917619},{"atb":[[9.8,0]],"id":35381686},{"atl":[[490,0],[500,1]],"id":35381686},{"atl":[[13,4]],"id":38554545}],"con":true,"img":false}]}
{"op":"mcm","clk":"5348916437","pt":1646221915814,"mc":[{"id":"1.195453631","rc":[{"atb":[[2.44,6.8]],"id":41398505}],"con":true,"img":false}]}
{"op":"mcm","clk":"5348916484","pt":1646221916433,"mc":[{"id":"1.195453631","rc":[{"atl":[[3.65,18.26]],"id":41398505},{"atl":[[20,2]],"id":38554545}],"con":true,"img":false}]}
{"op":"mcm","clk":"5348916495","pt":1646221916543,"mc":[{"id":"1.195453631","rc":[{"atl":[[3.75,47.96]],"id":41398505},{"atl":[[19,2.92]],"id":38554545}],"con":true,"img":false}]}
{"op":"mcm","clk":"5348916558","pt":1646221917322,"mc":[{"id":"1.195453631","rc":[{"atb":[[3.25,22.22]],"id":26349442},{"atl":[[5.9,24.94]],"id":26349442},{"atb":[[2.18,150.28]],"id":41398505},{"atl":[[3.8,17.86]],"id":41398505}],"con":true,"img":false}]}
{"op":"mcm","clk":"5348916566","pt":1646221917428,"mc":[{"id":"1.195453631","rc":[{"atl":[[5.9,9.98]],"id":26349442}],"con":true,"img":false}]}
{"op":"mcm","clk":"5348916685","pt":1646221918827,"mc":[{"id":"1.195453631","rc":[{"atb":[[8.8,0.42]],"id":38554545}],"con":true,"img":false}]}
{"op":"mcm","clk":"5348916694","pt":1646221918932,"mc":[{"id":"1.195453631","rc":[{"atb":[[9,5.74]],"id":38554545}],"con":true,"img":false}]}
{"op":"mcm","clk":"5348916701","pt":1646221919037,"mc":[{"id":"1.195453631","rc":[{"atb":[[3.3,34.88]],"id":26349442},{"atl":[[5.5,4.35]],"id":26349442},{"spn":4.75,"spf":"NaN","id":26349442},{"spn":20.54,"spf":1.0,"id":36120434},{"spn":8.53,"spf":1.0,"id":40917619},{"atb":[[2.06,77.12]],"id":41398505},{"spn":3.18,"spf":"NaN","id":41398505},{"spn":24.68,"spf":1.0,"id":35381686},{"atl":[[12.5,3]],"id":38554545},{"spn":8.82,"spf":1.0,"id":38554545}],"con":true,"img":false}]}
{"op":"mcm","clk":"5348916715","pt":1646221919246,"mc":[{"id":"1.195453631","rc":[{"atl":[[27,0]],"id":38554545}],"con":true,"img":false}]}
{"op":"mcm","clk":"5348916820","pt":1646221920448,"mc":[{"id":"1.195453631","rc":[{"atb":[[9,3.25]],"id":38554545}],"con":true,"img":false}]}
{"op":"mcm","clk":"5348916947","pt":1646221921805,"mc":[{"id":"1.195453631","rc":[{"atb":[[6.4,13.89]],"id":36120434},{"atb":[[4.6,20.83]],"id":40917619}],"con":true,"img":false}]}
{"op":"mcm","clk":"5348917132","pt":1646221923822,"mc":[{"id":"1.195453631","rc":[{"atb":[[6.6,20.68]],"id":38554545},{"atl":[[23,7.96]],"id":38554545}],"con":true,"img":false}]}
{"op":"mcm","clk":"5348917144","pt":1646221923927,"mc":[{"id":"1.195453631","rc":[{"atb":[[11.5,7.14]],"id":35381686},{"atl":[[520,1]],"id":35381686}],"con":true,"img":false}]}
{"op":"mcm","clk":"5348917178","pt":1646221924245,"mc":[{"id":"1.195453631","rc":[{"atl":[[5.5,0]],"id":26349442}],"con":true,"img":false}]}
{"op":"mcm","clk":"5348917395","pt":1646221926425,"mc":[{"id":"1.195453631","rc":[{"atl":[[38,2.21]],"id":40637101},{"atl":[[5.9,0]],"id":39183170},{"atb":[[34,0],[38,0.86]],"id":35381686}],"con":true,"img":false}]}
{"op":"mcm","clk":"5348917407","pt":1646221926531,"mc":[{"id":"1.195453631","rc":[{"atl":[[40,2.72]],"id":40637101},{"atl":[[6.2,10.43]],"id":39183170}],"con":true,"img":false}]}
{"op":"mcm","clk":"5348917416","pt":1646221926631,"mc":[{"id":"1.195453631","rc":[{"atl":[[38,0.21],[55,4.72]],"id":40637101}],"con":true,"img":false}]}
{"op":"mcm","clk":"5348917475","pt":1646221927314,"mc":[{"id":"1.195453631","rc":[{"atb":[[2.14,65.79]],"id":41398505},{"atl":[[3.9,25.86]],"id":41398505}],"con":true,"img":false}]}
{"op":"mcm","clk":"5348917653","pt":1646221929025,"mc":[{"id":"1.195453631","rc":[{"atb":[[3.05,60.98]],"id":26349442},{"atl":[[6.2,14.1]],"id":26349442}],"con":true,"img":false}]}
{"op":"mcm","clk":"5348917671","pt":1646221929235,"mc":[{"id":"1.195453631","rc":[{"atb":[[2.98,20.64]],"id":26349442},{"atl":[[5.5,4.35]],"id":26349442}],"con":true,"img":false}]}
{"op":"mcm","clk":"5348917907","pt":1646221931749,"mc":[{"id":"1.195453631","rc":[{"atl":[[40,4.72]],"id":40637101}],"con":true,"img":false}]}
{"op":"mcm","clk":"5348917919","pt":1646221931851,"mc":[{"id":"1.195453631","rc":[{"atl":[[55,2.72]],"id":40637101},{"atb":[[6,25]],"id":36120434},{"atb":[[4.4,36.76]],"id":40917619}],"con":true,"img":false}]}
{"op":"mcm","clk":"5348918060","pt":1646221933825,"mc":[{"id":"1.195453631","rc":[{"atb":[[6.2,24.04]],"id":38554545},{"atl":[[25,5.21]],"id":38554545}],"con":true,"img":false}]}
{"op":"mcm","clk":"5348918067","pt":1646221933942,"mc":[{"id":"1.195453631","rc":[{"atb":[[10.5,21.76]],"id":35381686},{"atl":[[540,1]],"id":35381686}],"con":true,"img":false}]}
{"op":"mcm","clk":"5348918292","pt":1646221936431,"mc":[{"id":"1.195453631","rc":[{"atb":[[19,0]],"id":36120434},{"atl":[[21,2.5]],"id":38554545}],"con":true,"img":false}]}
{"op":"mcm","clk":"5348918302","pt":1646221936535,"mc":[{"id":"1.195453631","rc":[{"atb":[[20,3.54]],"id":36120434},{"atl":[[19.5,7.2]],"id":38554545}],"con":true,"img":false}]}
{"op":"mcm","clk":"5348918311","pt":1646221936636,"mc":[{"id":"1.195453631","rc":[{"atl":[[5.5,0]],"id":26349442},{"atl":[[530,0],[510,0]],"id":35381686}],"con":true,"img":false}]}
{"op":"mcm","clk":"5348918376","pt":1646221937361,"mc":[{"id":"1.195453631","rc":[{"atb":[[2.1,113.64]],"id":41398505},{"atl":[[4,41.67]],"id":41398505}],"con":true,"img":false}]}
{"op":"mcm","clk":"5348918567","pt":1646221939236,"mc":[{"id":"1.195453631","rc":[{"atl":[[6.6,21.82]],"id":26349442}],"con":true,"img":false}]}
{"op":"mcm","clk":"5348918631","pt":1646221939967,"mc":[{"id":"1.195453631","rc":[{"atb":[[19.5,0]],"id":36120434}],"con":true,"img":false}]}
{"op":"mcm","clk":"5348918675","pt":1646221940436,"mc":[{"id":"1.195453631","rc":[{"atb":[[9,1.99]],"id":38554545}],"con":true,"img":false}]}
{"op":"mcm","clk":"5348918694","pt":1646221940642,"mc":[{"id":"1.195453631","rc":[{"atb":[[8,1.44]],"id":38554545}],"con":true,"img":false}]}
{"op":"mcm","clk":"5348918988","pt":1646221943926,"mc":[{"id":"1.195453631","rc":[{"atl":[[560,1]],"id":35381686}],"con":true,"img":false}]}
{"op":"mcm","clk":"5348919007","pt":1646221944133,"mc":[{"id":"1.195453631","rc":[{"atl":[[5.5,4.35],[5.7,0]],"id":26349442}],"con":true,"img":false}]}
{"op":"mcm","clk":"5348919225","pt":1646221946466,"mc":[{"id":"1.195453631","rc":[{"atb":[[20,0]],"id":36120434},{"atl":[[240,0]],"id":35381686}],"con":true,"img":false}]}
{"op":"mcm","clk":"5348919232","pt":1646221946571,"mc":[{"id":"1.195453631","rc":[{"atb":[[16,3.54]],"id":36120434},{"atl":[[220,2.72]],"id":35381686}],"con":true,"img":false}]}
{"op":"mcm","clk":"5348919240","pt":1646221946673,"mc":[{"id":"1.195453631","rc":[{"atl":[[230,0],[250,2.53]],"id":35381686}],"con":true,"img":false}]}
{"op":"mcm","clk":"5348919247","pt":1646221946777,"mc":[{"id":"1.195453631","rc":[{"atl":[[210,2]],"id":35381686}],"con":true,"img":false}]}
{"op":"mcm","clk":"5348919257","pt":1646221946834,"mc":[{"id":"1.195453631","rc":[{"atl":[[250,0.53]],"id":35381686}],"con":true,"img":false}]}
{"op":"mcm","clk":"5348919469","pt":1646221949635,"mc":[{"id":"1.195453631","rc":[{"atb":[[16.5,6.09]],"id":36120434}],"con":true,"img":false}]}
{"op":"mcm","clk":"5348919491","pt":1646221949957,"mc":[{"id":"1.195453631","rc":[{"atl":[[5.5,0],[5.7,4.16]],"id":26349442}],"con":true,"img":false}]}
{"op":"mcm","clk":"5348920028","pt":1646221956472,"mc":[{"id":"1.195453631","rc":[{"atb":[[3.2,0]],"id":26349442},{"atl":[[40,2]],"id":40637101}],"con":true,"img":false}]}
{"op":"mcm","clk":"5348920039","pt":1646221956574,"mc":[{"id":"1.195453631","rc":[{"atb":[[3.3,89.24]],"id":26349442},{"atl":[[38,2.94],[55,4.72]],"id":40637101}],"con":true,"img":false}]}
{"op":"mcm","clk":"5348920047","pt":1646221956674,"mc":[{"id":"1.195453631","rc":[{"atl":[[5.5,4.35],[5.7,0]],"id":26349442},{"atl":[[40,0]],"id":40637101}],"con":true,"img":false}]}
{"op":"mcm","clk":"5348920056","pt":1646221956780,"mc":[{"id":"1.195453631","rc":[{"atl":[[38,4.94],[55,2.72]],"id":40637101}],"con":true,"img":false}]}
{"op":"mcm","clk":"5348920116","pt":1646221957459,"mc":[{"id":"1.195453631","rc":[{"atl":[[70,4.72]],"id":36120434},{"atb":[[7.2,0]],"id":38554545}],"con":true,"img":false}]}
{"op":"mcm","clk":"5348920123","pt":1646221957563,"mc":[{"id":"1.195453631","rc":[{"atl":[[100,2.72]],"id":36120434},{"atb":[[5.9,20.06]],"id":38554545}],"con":true,"img":false}]}
{"op":"mcm","clk":"5348920368","pt":1646221960376,"mc":[{"id":"1.195453631","rc":[{"atb":[[36,0],[1.04,1.66]],"id":35381686}],"con":true,"img":false}]}
{"op":"mcm","clk":"5348920387","pt":1646221960581,"mc":[{"id":"1.195453631","rc":[{"atb":[[26,2.41],[28,0.13],[1.04,0.2]],"id":35381686}],"con":true,"img":false}]}
{"op":"mcm","clk":"5348920408","pt":1646221960790,"mc":[{"id":"1.195453631","rc":[{"atb":[[23,2],[26,0.41],[1.04,0]],"id":35381686}],"con":true,"img":false}]}
{"op":"mcm","clk":"5348920420","pt":1646221960900,"mc":[{"id":"1.195453631","rc":[{"atb":[[40,0.2]],"id":35381686}],"con":true,"img":false}]}
{"op":"mcm","clk":"5348920431","pt":1646221960997,"mc":[{"id":"1.195453631","rc":[{"atb":[[23,0]],"id":35381686}],"con":true,"img":false}]}
{"op":"mcm","clk":"5348920440","pt":1646221961054,"mc":[{"id":"1.195453631","rc":[{"atb":[[28,2.13]],"id":35381686}],"con":true,"img":false}]}
{"op":"mcm","clk":"5348920828","pt":1646221965466,"mc":[{"id":"1.195453631","rc":[{"atb":[[1.01,3]],"id":38554545}],"con":true,"img":false}]}
{"op":"mcm","clk":"5348920839","pt":1646221965672,"mc":[{"id":"1.195453631","rc":[{"atl":[[5.5,0],[5.7,4.16]],"id":26349442},{"atl":[[500,0],[510,1]],"id":35381686}],"con":true,"img":false}]}
{"op":"mcm","clk":"5348920904","pt":1646221966399,"mc":[{"id":"1.195453631","rc":[{"atb":[[6.4,10.82]],"id":38554545}],"con":true,"img":false}]}
{"op":"mcm","clk":"5348920913","pt":1646221966501,"mc":[{"id":"1.195453631","rc":[{"atl":[[38,2.21]],"id":40637101},{"atb":[[8.4,0.45]],"id":40917619},{"atl":[[16.5,0]],"id":40917619},{"atb":[[7.8,0]],"id":38554545}],"con":true,"img":false}]}
{"op":"mcm","clk":"5348920923","pt":1646221966605,"mc":[{"id":"1.195453631","rc":[{"atl":[[40,2.72]],"id":40637101},{"atb":[[8.2,1.4]],"id":40917619},{"atl":[[17,9.8]],"id":40917619}],"con":true,"img":false}]}
{"op":"mcm","clk":"5348920933","pt":1646221966710,"mc":[{"id":"1.195453631","rc":[{"atl":[[38,0.21],[55,4.72]],"id":40637101},{"atl":[[16,0],[16.5,2]],"id":40917619}],"con":true,"img":false}]}
{"op":"mcm","clk":"5348920941","pt":1646221966765,"mc":[{"id":"1.195453631","rc":[{"atl":[[55,2.72]],"id":40637101},{"atl":[[16.5,0]],"id":40917619}],"con":true,"img":false}]}
{"op":"mcm","clk":"5348920954","pt":1646221966869,"mc":[{"id":"1.195453631","rc":[{"atl":[[16.5,2]],"id":40917619}],"con":true,"img":false}]}
{"op":"mcm","clk":"5348920964","pt":1646221966975,"mc":[{"id":"1.195453631","rc":[{"atl":[[40,4.72]],"id":40637101}],"con":true,"img":false}]}
{"op":"mcm","clk":"5348921711","pt":1646221975709,"mc":[{"id":"1.195453631","rc":[{"atl":[[530,1]],"id":35381686}],"con":true,"img":false}]}
{"op":"mcm","clk":"5348921735","pt":1646221976010,"mc":[{"id":"1.195453631","rc":[{"atl":[[520,0],[540,0],[560,0]],"id":35381686}],"con":true,"img":false}]}
{"op":"mcm","clk":"5348921775","pt":1646221976376,"mc":[{"id":"1.195453631","rc":[{"atb":[[16,0]],"id":36120434},{"atl":[[19,0]],"id":38554545}],"con":true,"img":false}]}
{"op":"mcm","clk":"5348921796","pt":1646221976593,"mc":[{"id":"1.195453631","rc":[{"atb":[[17,3.54]],"id":36120434},{"atl":[[18,2.92]],"id":38554545}],"con":true,"img":false}]}
{"op":"mcm","clk":"5348921943","pt":1646221978303,"mc":[{"id":"1.195453631","rc":[{"atb":[[22,0],[1.04,2.25]],"id":36120434},{"atb":[[1.03,2.25]],"id":40637101}],"con":true,"img":false}]}
{"op":"mcm","clk":"5348921951","pt":1646221978418,"mc":[{"id":"1.195453631","rc":[{"atb":[[15.5,2.08]],"id":40637101}],"con":true,"img":false}]}
{"op":"mcm","clk":"5348921953","pt":1646221978503,"mc":[{"id":"1.195453631","rc":[{"atb":[[1.03,0.22]],"id":40637101},{"atb":[[1.04,0.15]],"id":36120434}],"con":true,"img":false}]}
{"op":"mcm","clk":"5348922015","pt":1646221979187,"mc":[{"id":"1.195453631","rc":[{"spn":4.85,"spf":"NaN","id":26349442},{"atb":[[1.03,0]],"id":40637101},{"spn":14.64,"spf":1.0,"id":40637101},{"spn":18.99,"spf":1.0,"id":36120434},{"spn":8.5,"spf":1.0,"id":40917619},{"spn":5.02,"spf":"NaN","id":39183170},{"spn":24.92,"spf":1.0,"id":35381686},{"spn":8.43,"spf":1.0,"id":38554545}],"con":true,"img":false}]}
{"op":"mcm","clk":"5348922021","pt":1646221979287,"mc":[{"id":"1.195453631","rc":[{"atb":[[16.5,0.22]],"id":40637101},{"atb":[[16.5,0]],"id":36120434}],"con":true,"img":false}]}
{"op":"mcm","clk":"5348922043","pt":1646221979494,"mc":[{"id":"1.195453631","rc":[{"atb":[[1.04,0]],"id":36120434},{"atb":[[15,0.72],[16,2.51]],"id":40637101}],"con":true,"img":false}]}
{"op":"mcm","clk":"5348922052","pt":1646221979614,"mc":[{"id":"1.195453631","rc":[{"atb":[[25,0.15]],"id":36120434},{"atb":[[15.5,4.08]],"id":40637101}],"con":true,"img":false}]}
{"op":"mcm","clk":"5348922059","pt":1646221979707,"mc":[{"id":"1.195453631","rc":[{"atb":[[16,0.51]],"id":40637101}],"con":true,"img":false}]}
{"op":"mcm","clk":"5348922386","pt":1646221983408,"mc":[{"id":"1.195453631","rc":[{"atb":[[17.5,5.72]],"id":36120434}],"con":true,"img":false}]}
{"op":"mcm","clk":"5348922603","pt":1646221985705,"mc":[{"id":"1.195453631","rc":[{"atl":[[550,1]],"id":35381686}],"con":true,"img":false}]}
{"op":"mcm","clk":"5348922659","pt":1646221986419,"mc":[{"id":"1.195453631","rc":[{"atl":[[7,0]],"id":26349442},{"atb":[[38,0],[42,0.77]],"id":35381686},{"atl":[[220,0]],"id":35381686}],"con":true,"img":false}]}
{"op":"mcm","clk":"5348922673","pt":1646221986523,"mc":[{"id":"1.195453631","rc":[{"atl":[[6.4,20.91]],"id":26349442},{"atl":[[200,3.39]],"id":35381686}],"con":true,"img":false}]}
{"op":"mcm","clk":"5348922680","pt":1646221986626,"mc":[{"id":"1.195453631","rc":[{"atb":[[4.2,4]],"id":26349442},{"atl":[[210,0],[250,2.53]],"id":35381686}],"con":true,"img":false}]}
{"op":"mcm","clk":"5348922702","pt":1646221986794,"mc":[{"id":"1.195453631","rc":[{"atl":[[250,0.53]],"id":35381686}],"con":true,"img":false}]}
{"op":"mcm","clk":"5348922707","pt":1646221986894,"mc":[{"id":"1.195453631","rc":[{"atb":[[3.85,0]],"id":26349442},{"atl":[[190,2]],"id":35381686}],"con":true,"img":false}]}
{"op":"mcm","clk":"5348922719","pt":1646221986995,"mc":[{"id":"1.195453631","rc":[{"atb":[[4.3,1.99]],"id":26349442}],"con":true,"img":false}]}
{"op":"mcm","clk":"5348922837","pt":1646221988396,"mc":[{"id":"1.195453631","rc":[{"atl":[[5.6,2.52]],"id":26349442}],"con":true,"img":false}]}
{"op":"mcm","clk":"5348922912","pt":1646221989223,"mc":[{"id":"1.195453631","rc":[{"atl":[[19,5.56],[23,3.41]],"id":38554545}],"con":true,"img":false}]}
{"op":"mcm","clk":"5348922930","pt":1646221989441,"mc":[{"id":"1.195453631","rc":[{"atb":[[4.3,4.99],[4.2,0]],"id":26349442},{"atl":[[5.5,4.35],[5.7,0]],"id":26349442}],"con":true,"img":false}]}
{"op":"mcm","clk":"5348923027","pt":1646221990417,"mc":[{"id":"1.195453631","rc":[{"atb":[[1.03,1.66],[24,0]],"id":36120434}],"con":true,"img":false}]}
{"op":"mcm","clk":"5348923039","pt":1646221990529,"mc":[{"id":"1.195453631","rc":[{"atb":[[16,0],[1.02,1.66]],"id":40637101}],"con":true,"img":false}]}
{"op":"mcm","clk":"5348923058","pt":1646221990731,"mc":[{"id":"1.195453631","rc":[{"atb":[[1.03,0.31]],"id":36120434}],"con":true,"img":false}]}
{"op":"mcm","clk":"5348923079","pt":1646221990933,"mc":[{"id":"1.195453631","rc":[{"atb":[[1.02,0.49]],"id":40637101}],"con":true,"img":false}]}
{"op":"mcm","clk":"5348923130","pt":1646221991512,"mc":[{"id":"1.195453631","rc":[{"atb":[[1.03,0]],"id":36120434}],"con":true,"img":false}]}
{"op":"mcm","clk":"5348923139","pt":1646221991614,"mc":[{"id":"1.195453631","rc":[{"atb":[[26,0.31]],"id":36120434}],"con":true,"img":false}]}
{"op":"mcm","clk":"5348923175","pt":1646221992026,"mc":[{"id":"1.195453631","rc":[{"atb":[[1.02,0]],"id":40637101}],"con":true,"img":false}]}
{"op":"mcm","clk":"5348923179","pt":1646221992139,"mc":[{"id":"1.195453631","rc":[{"atb":[[17,0.49]],"id":40637101}],"con":true,"img":false}]}
{"op":"mcm","clk":"5348923305","pt":1646221993535,"mc":[{"id":"1.195453631","rc":[{"atl":[[200,0.67]],"id":35381686}],"con":true,"img":false}]}
{"op":"mcm","clk":"5348923317","pt":1646221993640,"mc":[{"id":"1.195453631","rc":[{"atl":[[210,2.72]],"id":35381686}],"con":true,"img":false}]}
{"op":"mcm","clk":"5348923327","pt":1646221993745,"mc":[{"id":"1.195453631","rc":[{"atl":[[190,0],[250,2.53]],"id":35381686}],"con":true,"img":false}]}
{"op":"mcm","clk":"5348923491","pt":1646221995617,"mc":[{"id":"1.195453631","rc":[{"atl":[[5.6,0]],"id":26349442}],"con":true,"img":false}]}
{"op":"mcm","clk":"5348923501","pt":1646221995713,"mc":[{"id":"1.195453631","rc":[{"atl":[[570,1]],"id":35381686}],"con":true,"img":false}]}
{"op":"mcm","clk":"5348923526","pt":1646221996029,"mc":[{"id":"1.195453631","rc":[{"atb":[[4.3,1.99]],"id":26349442}],"con":true,"img":false}]}
{"op":"mcm","clk":"5348923560","pt":1646221996440,"mc":[{"id":"1.195453631","rc":[{"atb":[[2.18,42.37]],"id":41398505},{"atl":[[210,0]],"id":35381686}],"con":true,"img":false}]}
{"op":"mcm","clk":"5348923572","pt":1646221996543,"mc":[{"id":"1.195453631","rc":[{"atb":[[2.24,107.91]],"id":41398505},{"atl":[[240,2.72]],"id":35381686}],"con":true,"img":false}]}
{"op":"mcm","clk":"5348923598","pt":1646221996810,"mc":[{"id":"1.195453631","rc":[{"atb":[[4.3,0]],"id":26349442}],"con":true,"img":false}]}
{"op":"mcm","clk":"5348923608","pt":1646221996918,"mc":[{"id":"1.195453631","rc":[{"atb":[[4.1,1.99]],"id":26349442}],"con":true,"img":false}]}
{"op":"mcm","clk":"5348923662","pt":1646221997535,"mc":[{"id":"1.195453631","rc":[{"atb":[[3.7,2.49]],"id":26349442}],"con":true,"img":false}]}
{"op":"mcm","clk":"5348923707","pt":1646221998048,"mc":[{"id":"1.195453631","rc":[{"atl":[[5.4,2.52]],"id":26349442}],"con":true,"img":false}]}
{"op":"mcm","clk":"5348923766","pt":1646221998933,"mc":[{"id":"1.195453631","rc":[{"atb":[[3.7,0]],"id":26349442},{"atl":[[230,2]],"id":35381686}],"con":true,"img":false}]}
{"op":"mcm","clk":"5348923774","pt":1646221999037,"mc":[{"id":"1.195453631","rc":[{"atl":[[250,0.53]],"id":35381686}],"con":true,"img":false}]}
{"op":"mcm","clk":"5348923782","pt":1646221999138,"mc":[{"id":"1.195453631","rc":[{"atl":[[230,0]],"id":35381686}],"con":true,"img":false}]}
{"op":"mcm","clk":"5348923789","pt":1646221999240,"mc":[{"id":"1.195453631","rc":[{"atl":[[230,2]],"id":35381686}],"con":true,"img":false}]}
{"op":"mcm","clk":"5348923801","pt":1646221999451,"mc":[{"id":"1.195453631","rc":[{"atl":[[5.7,10.4]],"id":26349442}],"con":true,"img":false}]}
{"op":"mcm","clk":"5348923883","pt":1646222000436,"mc":[{"id":"1.195453631","rc":[{"atb":[[3.3,97.94]],"id":26349442},{"atl":[[180,15.2]],"id":40637101},{"atl":[[300,0.67],[310,1]],"id":36120434},{"atl":[[19.5,6.12],[20,3.05]],"id":38554545}],"con":true,"img":false}]}
{"op":"mcm","clk":"5348923892","pt":1646222000542,"mc":[{"id":"1.195453631","rc":[{"atb":[[3.35,0]],"id":26349442},{"atl":[[6.6,0]],"id":26349442},{"atl":[[170,0]],"id":40637101}],"con":true,"img":false}]}
{"op":"mcm","clk":"5348924000","pt":1646222001845,"mc":[{"id":"1.195453631","rc":[{"atl":[[6.8,17.24],[5.4,6.96],[7.2,0],[5.5,0]],"id":26349442},{"atb":[[10,11.05],[7.8,0]],"id":40637101},{"atl":[[3.7,0],[3.65,25.81]],"id":41398505},{"atl":[[510,0]],"id":35381686},{"atb":[[4.3,30.3],[3.55,0]],"id":38554545}],"con":true,"img":false}]}
{"op":"mcm","clk":"5348924029","pt":1646222002148,"mc":[{"id":"1.195453631","rc":[{"atb":[[4.2,2]],"id":26349442},{"atl":[[5.4,2.52],[5.6,4.25]],"id":26349442}],"con":true,"img":false}]}
{"op":"mcm","clk":"5348924095","pt":1646222002926,"mc":[{"id":"1.195453631","rc":[{"atb":[[4.1,0]],"id":26349442}],"con":true,"img":false}]}
{"op":"mcm","clk":"5348924108","pt":1646222003036,"mc":[{"id":"1.195453631","rc":[{"atb":[[4.3,1.99]],"id":26349442}],"con":true,"img":false}]}
{"op":"mcm","clk":"5348924356","pt":1646222005744,"mc":[{"id":"1.195453631","rc":[{"atl":[[590,1]],"id":35381686}],"con":true,"img":false}]}
{"op":"mcm","clk":"5348924418","pt":1646222006409,"mc":[{"id":"1.195453631","rc":[{"atb":[[3.3,43.58]],"id":26349442},{"atl":[[6.4,0]],"id":26349442},{"atb":[[17,0]],"id":36120434},{"atb":[[6.4,0]],"id":38554545}],"con":true,"img":false}]}
{"op":"mcm","clk":"5348924428","pt":1646222006521,"mc":[{"id":"1.195453631","rc":[{"atb":[[3.35,54.36]],"id":26349442},{"atl":[[6.6,20.91]],"id":26349442},{"atb":[[18,3.54]],"id":36120434},{"atb":[[7.2,10.82]],"id":38554545}],"con":true,"img":false}]}
{"op":"mcm","clk":"5348924521","pt":1646222007712,"mc":[{"id":"1.195453631","rc":[{"atl":[[5.4,0]],"id":26349442}],"con":true,"img":false}]}
{"op":"mcm","clk":"5348924662","pt":1646222009363,"mc":[{"id":"1.195453631","rc":[{"atb":[[17.5,0]],"id":36120434}],"con":true,"img":false}]}
{"op":"mcm","clk":"5348924730","pt":1646222010256,"mc":[{"id":"1.195453631","rc":[{"atl":[[5.5,2.52]],"id":26349442}],"con":true,"img":false}]}
{"op":"mcm","clk":"5348924750","pt":1646222010463,"mc":[{"id":"1.195453631","rc":[{"atl":[[330,1]],"id":36120434},{"atl":[[200,1]],"id":40637101},{"atl":[[22,2.38]],"id":38554545}],"con":true,"img":false}]}
{"op":"mcm","clk":"5348924760","pt":1646222010563,"mc":[{"id":"1.195453631","rc":[{"atb":[[4.3,5.99],[4.2,0]],"id":26349442},{"atl":[[5.4,4.44],[5.6,0]],"id":26349442}],"con":true,"img":false}]}
{"op":"mcm","clk":"5348925061","pt":1646222014352,"mc":[{"id":"1.195453631","rc":[{"atb":[[18.5,5.39]],"id":36120434}],"con":true,"img":false}]}
{"op":"mcm","clk":"5348925230","pt":1646222016438,"mc":[{"id":"1.195453631","rc":[{"atl":[[40,2]],"id":40637101}],"con":true,"img":false}]}
{"op":"mcm","clk":"5348925238","pt":1646222016538,"mc":[{"id":"1.195453631","rc":[{"atl":[[38,2.94]],"id":40637101}],"con":true,"img":false}]}
{"op":"mcm","clk":"5348925246","pt":1646222016641,"mc":[{"id":"1.195453631","rc":[{"atb":[[4.3,1.99],[4.2,2]],"id":26349442},{"atl":[[5.4,0],[5.6,4.25]],"id":26349442},{"atl":[[40,0],[190,0],[210,0.95],[55,4.72],[230,0]],"id":40637101},{"atl":[[320,0],[340,0],[360,0]],"id":36120434},{"atl":[[21,0],[23,0],[25,0]],"id":38554545}],"con":true,"img":false}]}
{"op":"mcm","clk":"5348925568","pt":1646222020444,"mc":[{"id":"1.195453631","rc":[{"atl":[[220,1]],"id":40637101},{"atl":[[350,1.57]],"id":36120434},{"atl":[[24,3.26]],"id":38554545}],"con":true,"img":false}]}
{"op":"mcm","clk":"5348925602","pt":1646222020746,"mc":[{"id":"1.195453631","rc":[{"atb":[[40,0],[1.04,1.66]],"id":35381686}],"con":true,"img":false}]}
{"op":"mcm","clk":"5348925627","pt":1646222020955,"mc":[{"id":"1.195453631","rc":[{"atb":[[26,2.41],[28,0.13]],"id":35381686}],"con":true,"img":false}]}
{"op":"mcm","clk":"5348925649","pt":1646222021161,"mc":[{"id":"1.195453631","rc":[{"atb":[[1.04,0.19]],"id":35381686}],"con":true,"img":false}]}
{"op":"mcm","clk":"5348925700","pt":1646222021872,"mc":[{"id":"1.195453631","rc":[{"atl":[[38,4.94],[55,2.72]],"id":40637101}],"con":true,"img":false}]}
{"op":"mcm","clk":"5348925721","pt":1646222022053,"mc":[{"id":"1.195453631","rc":[{"atb":[[1.04,0]],"id":35381686}],"con":true,"img":false}]}
{"op":"mcm","clk":"5348925730","pt":1646222022149,"mc":[{"id":"1.195453631","rc":[{"atb":[[4.3,3.99],[4.2,0]],"id":26349442},{"atl":[[5.4,4.44],[5.6,0]],"id":26349442},{"atb":[[44,0.19]],"id":35381686}],"con":true,"img":false}]}
{"op":"mcm","clk":"5348925842","pt":1646222023453,"mc":[{"id":"1.195453631","rc":[{"atb":[[4.3,1.99],[3.25,8.89],[3.3,34.88]],"id":26349442},{"atl":[[170,1]],"id":40637101},{"atl":[[300,1.67]],"id":36120434},{"atl":[[18.5,0],[18,1.18]],"id":40917619},{"atb":[[2.22,0],[2.26,15.87]],"id":41398505},{"atl":[[19.5,7.2]],"id":38554545}],"con":true,"img":false}]}
{"op":"mcm","clk":"5348925862","pt":1646222023660,"mc":[{"id":"1.195453631","rc":[{"atl":[[170,0]],"id":40637101},{"atl":[[65,2.06],[260,1],[75,0],[300,0.67]],"id":36120434},{"atl":[[17.5,0],[18,5.88],[18.5,1.14]],"id":40917619},{"atl":[[19.5,6.12]],"id":38554545}],"con":true,"img":false}]}
{"op":"mcm","clk":"5348925883","pt":1646222023969,"mc":[{"id":"1.195453631","rc":[{"atb":[[4.3,0]],"id":26349442}],"con":true,"img":false}]}
{"op":"mcm","clk":"5348925891","pt":1646222024074,"mc":[{"id":"1.195453631","rc":[{"atb":[[4.1,1.99]],"id":26349442}],"con":true,"img":false}]}
{"op":"mcm","clk":"5348925929","pt":1646222024440,"mc":[{"id":"1.195453631","rc":[{"atl":[[5.5,0]],"id":26349442}],"con":true,"img":false}]}
{"op":"mcm","clk":"5348925961","pt":1646222025066,"mc":[{"id":"1.195453631","rc":[{"atl":[[17,3.07]],"id":40917619},{"atb":[[5.9,0]],"id":38554545}],"con":true,"img":false}]}
{"op":"mcm","clk":"5348925971","pt":1646222025168,"mc":[{"id":"1.195453631","rc":[{"atl":[[19,6.73]],"id":40917619},{"atb":[[6.8,20.06]],"id":38554545}],"con":true,"img":false}]}
{"op":"mcm","clk":"5348926041","pt":1646222026050,"mc":[{"id":"1.195453631","rc":[{"atb":[[26,0.41]],"id":35381686}],"con":true,"img":false}]}
{"op":"mcm","clk":"5348926048","pt":1646222026158,"mc":[{"id":"1.195453631","rc":[{"atb":[[28,2.13]],"id":35381686}],"con":true,"img":false}]}
{"op":"mcm","clk":"5348926070","pt":1646222026369,"mc":[{"id":"1.195453631","rc":[{"atl":[[5.8,0]],"id":26349442},{"atl":[[38,2.21]],"id":40637101},{"atb":[[2.24,0]],"id":41398505}],"con":true,"img":false}]}
{"op":"mcm","clk":"5348926079","pt":1646222026468,"mc":[{"id":"1.195453631","rc":[{"atl":[[5.6,9.74]],"id":26349442},{"atl":[[40,2.72]],"id":40637101},{"atb":[[2.2,107.91]],"id":41398505}],"con":true,"img":false}]}
{"op":"mcm","clk":"5348926123","pt":1646222026985,"mc":[{"id":"1.195453631","rc":[{"atl":[[38,0.21],[40,4.72]],"id":40637101}],"con":true,"img":false}]}
{"op":"mcm","clk":"5348926151","pt":1646222027253,"mc":[{"id":"1.195453631","rc":[{"atl":[[530,0],[540,1]],"id":35381686}],"con":true,"img":false}]}
{"op":"mcm","clk":"5348926228","pt":1646222028084,"mc":[{"id":"1.195453631","rc":[{"atl":[[18,0],[19,11.8],[20,1.05]],"id":40917619}],"con":true,"img":false}]}
{"op":"mcm","clk":"5348926238","pt":1646222028183,"mc":[{"id":"1.195453631","rc":[{"atl":[[16.5,0],[18.5,0]],"id":40917619}],"con":true,"img":false}]}
{"op":"mcm","clk":"5348926360","pt":1646222029554,"mc":[{"id":"1.195453631","rc":[{"atb":[[18,0]],"id":36120434},{"atl":[[130,0]],"id":35381686}],"con":true,"img":false}]}
{"op":"mcm","clk":"5348926369","pt":1646222029671,"mc":[{"id":"1.195453631","rc":[{"atb":[[19,3.54]],"id":36120434},{"atl":[[170,0.04]],"id":35381686}],"con":true,"img":false}]}
{"op":"mcm","clk":"5348926379","pt":1646222029768,"mc":[{"id":"1.195453631","rc":[{"atl":[[230,0],[240,4.72]],"id":35381686}],"con":true,"img":false}]}
{"op":"mcm","clk":"5348926613","pt":1646222032462,"mc":[{"id":"1.195453631","rc":[{"atb":[[18.5,0]],"id":36120434}],"con":true,"img":false}]}
{"op":"mcm","clk":"5348926633","pt":1646222032698,"mc":[{"id":"1.195453631","rc":[{"atb":[[2.98,0],[3.45,0],[2.88,0],[2.78,0],[2.68,0]],"id":26349442},{"atl":[[11,0],[13.5,0],[9.4,0],[16,0]],"id":26349442},{"atb":[[9.2,0],[10.5,0],[13,0],[15.5,0],[21,0.51]],"id":36120434},{"atl":[[300,0],[350,1],[200,0],[250,0]],"id":36120434},{"atb":[[6.4,0],[7.4,0],[13.5,0],[8.4,0],[9.4,0]],"id":40637101},{"atl":[[260,0],[160,0],[210,0],[110,0]],"id":40637101},{"atb":[[4.8,13.16],[4.3,52.12],[5.8,0],[5.3,0],[7.6,0]],"id":40917619},{"atl":[[65,0],[36,0],[90,0],[46,0]],"id":40917619},{"atb":[[1.98,0],[1.93,0],[2.36,0],[2.06,0],[2.16,0]],"id":41398505},{"atl":[[6.4,0],[7.4,0],[8.4,0],[5.7,0]],"id":41398505},{"atb":[[9.2,0],[10.5,13.16],[13,0],[15.5,0],[21,0]],"id":35381686},{"atl":[[300,0],[350,0],[200,0],[250,0]],"id":35381686},{"atb":[[4.8,18.95],[5.8,0],[5.3,0],[8.6,0],[6.6,13.39]],"id":38554545},{"atl":[[130,0],[46,0],[65,0],[90,0]],"id":38554545}],"con":true,"img":false}]}
{"op":"mcm","clk":"5348926659","pt":1646222032888,"mc":[{"id":"1.195453631","rc":[{"atb":[[1.03,1.66],[26,0]],"id":36120434}],"con":true,"img":false}]}
{"op":"mcm","clk":"5348926671","pt":1646222032995,"mc":[{"id":"1.195453631","rc":[{"atl":[[19.5,0]],"id":40917619},{"atl":[[540,0]],"id":35381686}],"con":true,"img":false}]}
{"op":"mcm","clk":"5348926682","pt":1646222033086,"mc":[{"id":"1.195453631","rc":[{"atb":[[1.03,0.31]],"id":36120434}],"con":true,"img":false}]}
{"op":"mcm","clk":"5348926694","pt":1646222033192,"mc":[{"id":"1.195453631","rc":[{"atb":[[1.03,0]],"id":36120434}],"con":true,"img":false}]}
{"op":"mcm","clk":"5348926700","pt":1646222033253,"mc":[{"id":"1.195453631","rc":[{"atb":[[19.5,0.31]],"id":36120434}],"con":true,"img":false}]}
{"op":"mcm","clk":"5348926713","pt":1646222033361,"mc":[{"id":"1.195453631","rc":[{"atl":[[26,5]],"id":38554545}],"con":true,"img":false}]}
{"op":"mcm","clk":"5348926724","pt":1646222033463,"mc":[{"id":"1.195453631","rc":[{"atb":[[3.15,23.26]],"id":26349442},{"atl":[[240,1]],"id":40637101},{"atb":[[2.22,40.98]],"id":41398505}],"con":true,"img":false}]}
{"op":"mcm","clk":"5348926737","pt":1646222033671,"mc":[{"id":"1.195453631","rc":[{"atl":[[280,1]],"id":36120434}],"con":true,"img":false}]}
{"op":"mcm","clk":"5348926882","pt":1646222035588,"mc":[{"id":"1.195453631","rc":[{"atl":[[19.5,0]],"id":38554545}],"con":true,"img":false}]}
{"op":"mcm","clk":"5348926889","pt":1646222035684,"mc":[{"id":"1.195453631","rc":[{"atl":[[18.5,6.12]],"id":38554545}],"con":true,"img":false}]}
{"op":"mcm","clk":"5348926947","pt":1646222036372,"mc":[{"id":"1.195453631","rc":[{"atb":[[19,0]],"id":36120434},{"atb":[[7.8,0]],"id":40917619},{"atl":[[17,0]],"id":40917619}],"con":true,"img":false}]}
{"op":"mcm","clk":"5348926957","pt":1646222036477,"mc":[{"id":"1.195453631","rc":[{"atb":[[15,3.54]],"id":36120434},{"atb":[[7.2,8.59]],"id":40917619},{"atl":[[18,3.07]],"id":40917619}],"con":true,"img":false}]}
{"op":"mcm","clk":"5348926972","pt":1646222036587,"mc":[{"id":"1.195453631","rc":[{"atb":[[14,7.26]],"id":36120434},{"atb":[[14,0]],"id":40637101},{"atl":[[18.5,2]],"id":40917619}],"con":true,"img":false}]}
{"op":"mcm","clk":"5348926992","pt":1646222036785,"mc":[{"id":"1.195453631","rc":[{"atb":[[17,0],[1.02,1.66]],"id":40637101}],"con":true,"img":false}]}
{"op":"mcm","clk":"5348927000","pt":1646222036893,"mc":[{"id":"1.195453631","rc":[{"atb":[[1.02,0.49]],"id":40637101}],"con":true,"img":false}]}
{"op":"mcm","clk":"5348927015","pt":1646222036995,"mc":[{"id":"1.195453631","rc":[{"atb":[[1.02,0]],"id":40637101}],"con":true,"img":false}]}
{"op":"mcm","clk":"5348927025","pt":1646222037066,"mc":[{"id":"1.195453631","rc":[{"atb":[[13.5,0.49]],"id":40637101}],"con":true,"img":false}]}
{"op":"mcm","clk":"5348927040","pt":1646222037261,"mc":[{"id":"1.195453631","rc":[{"atb":[[1.02,1.66]],"id":40637101},{"atl":[[610,1]],"id":35381686}],"con":true,"img":false}]}
{"op":"mcm","clk":"5348927051","pt":1646222037360,"mc":[{"id":"1.195453631","rc":[{"atb":[[13.5,0]],"id":40637101}],"con":true,"img":false}]}
{"op":"mcm","clk":"5348927062","pt":1646222037481,"mc":[{"id":"1.195453631","rc":[{"atb":[[1.02,0.47]],"id":40637101}],"con":true,"img":false}]}
{"op":"mcm","clk":"5348927069","pt":1646222037571,"mc":[{"id":"1.195453631","rc":[{"atb":[[1.02,0]],"id":40637101}],"con":true,"img":false}]}
{"op":"mcm","clk":"5348927078","pt":1646222037676,"mc":[{"id":"1.195453631","rc":[{"atb":[[17.5,0.47]],"id":40637101}],"con":true,"img":false}]}
{"op":"mcm","clk":"5348927117","pt":1646222038089,"mc":[{"id":"1.195453631","rc":[{"atl":[[22,2.38]],"id":40917619}],"con":true,"img":false}]}
{"op":"mcm","clk":"5348927139","pt":1646222038358,"mc":[{"id":"1.195453631","rc":[{"atl":[[5.3,4.55],[5.4,0]],"id":26349442},{"atl":[[310,0],[330,0],[350,0]],"id":36120434},{"atb":[[2.1,0]],"id":41398505}],"con":true,"img":false}]}
{"op":"mcm","clk":"5348927150","pt":1646222038467,"mc":[{"id":"1.195453631","rc":[{"atl":[[70,2]],"id":36120434}],"con":true,"img":false}]}
{"op":"mcm","clk":"5348927158","pt":1646222038559,"mc":[{"id":"1.195453631","rc":[{"atb":[[25,0],[1.04,2.25]],"id":36120434},{"atl":[[60,3]],"id":36120434}],"con":true,"img":false}]}
{"op":"mcm","clk":"5348927167","pt":1646222038668,"mc":[{"id":"1.195453631","rc":[{"atb":[[1.04,0.15]],"id":36120434},{"atl":[[65,0.06],[70,4]],"id":36120434}],"con":true,"img":false}]}
{"op":"mcm","clk":"5348927176","pt":1646222038765,"mc":[{"id":"1.195453631","rc":[{"atb":[[1.04,0]],"id":36120434}],"con":true,"img":false}]}
{"op":"mcm","clk":"5348927185","pt":1646222038874,"mc":[{"id":"1.195453631","rc":[{"atb":[[24,0.15]],"id":36120434}],"con":true,"img":false}]}
{"op":"mcm","clk":"5348927200","pt":1646222039079,"mc":[{"id":"1.195453631","rc":[{"atb":[[8.2,0]],"id":40917619}],"con":true,"img":false}]}
{"op":"mcm","clk":"5348927215","pt":1646222039197,"mc":[{"id":"1.195453631","rc":[{"spn":4.7,"spf":"NaN","id":26349442},{"spn":16.36,"spf":1.0,"id":36120434},{"spn":14.34,"spf":1.0,"id":40637101},{"atb":[[8.4,1.81]],"id":40917619},{"spn":8.22,"spf":1.0,"id":40917619},{"spn":24.66,"spf":1.0,"id":35381686},{"spn":7.76,"spf":1.0,"id":38554545}],"con":true,"img":false}]}
{"op":"mcm","clk":"5348927297","pt":1646222040175,"mc":[{"id":"1.195453631","rc":[{"atb":[[44,0.22]],"id":35381686},{"atl":[[170,0.05]],"id":35381686}],"con":true,"img":false}]}
{"op":"mcm","clk":"5348927313","pt":1646222040381,"mc":[{"id":"1.195453631","rc":[{"atb":[[2.94,16.35]],"id":26349442},{"atl":[[1000,3.66]],"id":26349442},{"atb":[[16,16.35]],"id":36120434},{"atl":[[1000,3.66]],"id":36120434},{"atb":[[15,17.07]],"id":40637101},{"atl":[[1000,3.66]],"id":40637101},{"atb":[[8.2,16.35]],"id":40917619},{"atl":[[1000,3.66]],"id":40917619},{"atb":[[2.24,16.35]],"id":41398505},{"atl":[[1000,3.66]],"id":41398505},{"atb":[[3,16.35]],"id":39183170},{"atl":[[1000,3.66]],"id":39183170},{"atb":[[23,16.35]],"id":35381686},{"atl":[[1000,3.66]],"id":35381686},{"atb":[[8.2,16.35]],"id":38554545},{"atl":[[1000,3.66]],"id":38554545}],"con":true,"img":false}]}
{"op":"mcm","clk":"5348927335","pt":1646222040596,"mc":[{"id":"1.195453631","rc":[{"atl":[[1000,1.83]],"id":26349442},{"atl":[[1000,1.83]],"id":36120434},{"atl":[[1000,1.83]],"id":40637101},{"atl":[[1000,1.83]],"id":40917619},{"atl":[[1000,1.83]],"id":41398505},{"atl":[[1000,1.83]],"id":39183170},{"atl":[[1000,1.83]],"id":35381686},{"atl":[[1000,1.83]],"id":38554545}],"con":true,"img":false}]}
{"op":"mcm","clk":"5348927345","pt":1646222040699,"mc":[{"id":"1.195453631","rc":[{"atb":[[13.5,7.56]],"id":40637101}],"con":true,"img":false}]}
{"op":"mcm","clk":"5348927351","pt":1646222040795,"mc":[{"id":"1.195453631","rc":[{"atl":[[1000,0]],"id":26349442},{"atl":[[1000,0]],"id":40637101},{"atl":[[1000,0]],"id":36120434},{"atl":[[1000,0]],"id":40917619},{"atl":[[1000,0]],"id":41398505},{"atl":[[1000,0]],"id":39183170},{"atl":[[1000,0]],"id":35381686},{"atl":[[1000,0]],"id":38554545}],"con":true,"img":false}]}
{"op":"mcm","clk":"5348927362","pt":1646222040901,"mc":[{"id":"1.195453631","rc":[{"atl":[[5.2,1.83]],"id":26349442},{"atl":[[55,3.07]],"id":36120434},{"atl":[[38,2.04]],"id":40637101},{"atl":[[17.5,1.83]],"id":40917619},{"atl":[[3.55,1.83]],"id":41398505},{"atl":[[6,1.83]],"id":39183170},{"atl":[[230,1.83]],"id":35381686},{"atl":[[12,1.83]],"id":38554545}],"con":true,"img":false}]}
{"op":"mcm","clk":"5348927367","pt":1646222040964,"mc":[{"id":"1.195453631","rc":[{"atl":[[38,3.29]],"id":40637101},{"atl":[[1000,1.24]],"id":39183170}],"con":true,"img":false}]}
{"op":"mcm","clk":"5348927378","pt":1646222041108,"mc":[{"id":"1.195453631","rc":[{"atl":[[230,3.07]],"id":35381686}],"con":true,"img":false}]}
{"op":"mcm","clk":"5348927386","pt":1646222041182,"mc":[{"id":"1.195453631","rc":[{"atl":[[17.5,3.07]],"id":40917619},{"atl":[[1000,0]],"id":39183170},{"atl":[[1000,1.24]],"id":38554545}],"con":true,"img":false}]}
{"op":"mcm","clk":"5348927394","pt":1646222041272,"mc":[{"id":"1.195453631","rc":[{"atb":[[4.2,1]],"id":26349442},{"atb":[[2.52,1]],"id":41398505},{"atl":[[1000,1.24]],"id":41398505},{"atb":[[3.9,1]],"id":39183170},{"atl":[[6,3.07]],"id":39183170},{"atl":[[220,2],[240,2.72]],"id":35381686}],"con":true,"img":false}]}
{"op":"mcm","clk":"5348927401","pt":1646222041376,"mc":[{"id":"1.195453631","rc":[{"atl":[[1000,0]],"id":38554545}],"con":true,"img":false}]}
{"op":"mcm","clk":"5348927409","pt":1646222041488,"mc":[{"id":"1.195453631","rc":[{"atb":[[4,1.38]],"id":26349442},{"atl":[[1000,0]],"id":41398505},{"atl":[[230,1.24]],"id":35381686},{"atl":[[12,3.07]],"id":38554545}],"con":true,"img":false}]}
{"op":"mcm","clk":"5348927419","pt":1646222041589,"mc":[{"id":"1.195453631","rc":[{"atl":[[3.55,3.07]],"id":41398505},{"atl":[[210,1.83]],"id":35381686}],"con":true,"img":false}]}
{"op":"mcm","clk":"5348927431","pt":1646222041792,"mc":[{"id":"1.195453631","rc":[{"atl":[[17,2],[18.5,0]],"id":40917619}],"con":true,"img":false}]}
{"op":"mcm","clk":"5348927447","pt":1646222041999,"mc":[{"id":"1.195453631","rc":[{"atl":[[17.5,2.24]],"id":40917619}],"con":true,"img":false}]}
{"op":"mcm","clk":"5348927455","pt":1646222042063,"mc":[{"id":"1.195453631","rc":[{"atl":[[16.5,0.83]],"id":40917619}],"con":true,"img":false}]}
{"op":"mcm","clk":"5348927489","pt":1646222042477,"mc":[{"id":"1.195453631","rc":[{"atb":[[2.5,0]],"id":41398505},{"atb":[[3.95,2.49]],"id":39183170}],"con":true,"img":false}]}
{"op":"mcm","clk":"5348927497","pt":1646222042575,"mc":[{"id":"1.195453631","rc":[{"atl":[[5.1,2.52]],"id":26349442},{"atb":[[14,0]],"id":36120434}],"con":true,"img":false}]}
{"op":"mcm","clk":"5348927512","pt":1646222042781,"mc":[{"id":"1.195453631","rc":[{"atl":[[5.3,5.5],[5.2,1]],"id":26349442},{"atb":[[3.85,0]],"id":39183170}],"con":true,"img":false}]}
{"op":"mcm","clk":"5348927523","pt":1646222042895,"mc":[{"id":"1.195453631","rc":[{"atl":[[5,0.83]],"id":26349442},{"atb":[[4,1.99]],"id":39183170}],"con":true,"img":false}]}
{"op":"mcm","clk":"5348927539","pt":1646222043097,"mc":[{"id":"1.195453631","rc":[{"atl":[[5.1,3.48]],"id":26349442}],"con":true,"img":false}]}
{"op":"mcm","clk":"5348927567","pt":1646222043408,"mc":[{"id":"1.195453631","rc":[{"atl":[[5.2,0]],"id":26349442},{"atl":[[17.5,1.24]],"id":40917619},{"atb":[[2.52,0],[2.18,63.56]],"id":41398505},{"atb":[[3.9,0]],"id":39183170}],"con":true,"img":false}]}
{"op":"mcm","clk":"5348927571","pt":1646222043462,"mc":[{"id":"1.195453631","rc":[{"atl":[[5,1.83]],"id":26349442},{"atl":[[16.5,1.83]],"id":40917619},{"atb":[[2.5,1]],"id":41398505},{"atb":[[4.1,1]],"id":39183170}],"con":true,"img":false}]}
{"op":"mcm","clk":"5348927584","pt":1646222043574,"mc":[{"id":"1.195453631","rc":[{"atl":[[5.1,2.52]],"id":26349442}],"con":true,"img":false}]}
{"op":"mcm","clk":"5348927593","pt":1646222043676,"mc":[{"id":"1.195453631","rc":[{"atl":[[300,1]],"id":36120434}],"con":true,"img":false}]}
{"op":"mcm","clk":"5348927598","pt":1646222043771,"mc":[{"id":"1.195453631","rc":[{"atb":[[3.95,0]],"id":39183170}],"con":true,"img":false}]}
{"op":"mcm","clk":"5348927626","pt":1646222044189,"mc":[{"id":"1.195453631","rc":[{"atl":[[3.6,4.92]],"id":41398505}],"con":true,"img":false}]}
{"op":"mcm","clk":"5348927663","pt":1646222044566,"mc":[{"id":"1.195453631","rc":[{"atb":[[13.5,0]],"id":40637101}],"con":true,"img":false}]}
{"op":"mcm","clk":"5348927716","pt":1646222045178,"mc":[{"id":"1.195453631","rc":[{"atb":[[2.52,2.49]],"id":41398505},{"atb":[[4.2,2.49]],"id":39183170}],"con":true,"img":false}]}
{"op":"mcm","clk":"5348927777","pt":1646222045707,"mc":[{"id":"1.195453631","rc":[{"atb":[[4,0]],"id":39183170}],"con":true,"img":false}]}
{"op":"mcm","clk":"5348927785","pt":1646222045755,"mc":[{"id":"1.195453631","rc":[{"atb":[[4.3,1.99]],"id":39183170}],"con":true,"img":false}]}
{"op":"mcm","clk":"5348927794","pt":1646222045860,"mc":[{"id":"1.195453631","rc":[{"atl":[[65,2.06],[70,2]],"id":36120434}],"con":true,"img":false}]}
{"op":"mcm","clk":"5348927823","pt":1646222046179,"mc":[{"id":"1.195453631","rc":[{"atb":[[4.3,0]],"id":39183170}],"con":true,"img":false}]}
{"op":"mcm","clk":"5348927837","pt":1646222046287,"mc":[{"id":"1.195453631","rc":[{"atb":[[2.5,0]],"id":41398505},{"atb":[[4.1,0],[1.02,1.99]],"id":39183170}],"con":true,"img":false}]}
{"op":"mcm","clk":"5348927848","pt":1646222046390,"mc":[{"id":"1.195453631","rc":[{"atb":[[3.5,0]],"id":26349442},{"atb":[[21,0]],"id":36120434},{"atb":[[13,0]],"id":40637101},{"atb":[[8.4,0.45]],"id":40917619},{"atb":[[2.54,1],[2.38,0]],"id":41398505},{"atb":[[4.4,1]],"id":39183170},{"atb":[[42,0],[30,1.12]],"id":35381686},{"atl":[[240,0]],"id":35381686}],"con":true,"img":false}]}
{"op":"mcm","clk":"5348927853","pt":1646222046488,"mc":[{"id":"1.195453631","rc":[{"atb":[[3.35,77.74]],"id":26349442},{"atb":[[12,4.87]],"id":40637101},{"atb":[[8.6,1.33]],"id":40917619},{"atb":[[2.36,42.35]],"id":41398505},{"atl":[[320,2.72]],"id":35381686}],"con":true,"img":false}]}
{"op":"mcm","clk":"5348927865","pt":1646222046594,"mc":[{"id":"1.195453631","rc":[{"atb":[[19.5,0.86]],"id":36120434},{"atb":[[28,0.13],[30,3.12]],"id":35381686}],"con":true,"img":false}]}
{"op":"mcm","clk":"5348927927","pt":1646222047176,"mc":[{"id":"1.195453631","rc":[{"atb":[[6.2,1.59]],"id":40917619}],"con":true,"img":false}]}
{"op":"mcm","clk":"5348927935","pt":1646222047282,"mc":[{"id":"1.195453631","rc":[{"atb":[[4.4,0]],"id":39183170}],"con":true,"img":false}]}
{"op":"mcm","clk":"5348927950","pt":1646222047390,"mc":[{"id":"1.195453631","rc":[{"atb":[[4.3,1]],"id":39183170}],"con":true,"img":false}]}
{"op":"mcm","clk":"5348927959","pt":1646222047501,"mc":[{"id":"1.195453631","rc":[{"atb":[[2.52,0]],"id":41398505},{"atb":[[4.2,0]],"id":39183170}],"con":true,"img":false}]}
