{"op":"mcm","clk":"5352134791","pt":1646183310068,"mc":[{"id":"1.195503856","marketDefinition":{"bspMarket":false,"turnInPlayEnabled":false,"persistenceEnabled":false,"marketBaseRate":7.0,"eventId":"31272499","eventTypeId":"4339","numberOfWinners":1,"bettingType":"ODDS","marketType":"MATCH_BET","marketTime":"2022-03-02T11:19:00.000Z","suspendTime":"2022-03-02T11:19:00.000Z","bspReconciled":false,"complete":true,"inPlay":false,"crossMatching":true,"runnersVoidable":false,"numberOfActiveRunners":2,"betDelay":0,"status":"OPEN","runners":[{"status":"ACTIVE","sortPriority":1,"id":38247337,"name":"5. On The Bayou"},{"status":"ACTIVE","sortPriority":2,"id":39832467,"name":"7. Shian Ned"}],"regulators":["MR_INT"],"venue":"Rockhampton","countryCode":"AU","discountAllowed":true,"timezone":"Australia/Queensland","openDate":"2022-03-02T08:34:00.000Z","version":4382585406,"name":"On The Bayou v Shian Ned","eventName":"Rockhampton (AUS) 2nd Mar"},"rc":[],"con":true,"img":false}]}
{"op":"mcm","clk":"5352139712","pt":1646183422125,"mc":[{"id":"1.195503856","rc":[{"atb":[[1.46,11.73],[1.26,20.76],[1.66,8.17]],"id":38247337},{"atb":[[1.89,6.06],[1.49,11.01],[1.69,7.82]],"id":39832467}],"con":true,"img":false}]}
{"op":"mcm","clk":"5352146175","pt":1646183572636,"mc":[{"id":"1.195503856","marketDefinition":{"bspMarket":false,"turnInPlayEnabled":false,"persistenceEnabled":false,"marketBaseRate":7.0,"eventId":"31272499","eventTypeId":"4339","numberOfWinners":1,"bettingType":"ODDS","marketType":"MATCH_BET","marketTime":"2022-03-02T11:19:00.000Z","suspendTime":"2022-03-02T11:19:00.000Z","bspReconciled":false,"complete":true,"inPlay":false,"crossMatching":true,"runnersVoidable":false,"numberOfActiveRunners":2,"betDelay":0,"status":"OPEN","runners":[{"status":"ACTIVE","sortPriority":1,"id":38247337,"name":"5. On The Bayou"},{"status":"ACTIVE","sortPriority":2,"id":39832467,"name":"7. Shian Ned"}],"regulators":["MR_INT"],"venue":"Rockhampton","countryCode":"AU","discountAllowed":true,"timezone":"Australia/Queensland","openDate":"2022-03-02T08:28:00.000Z","version":4382597880,"name":"On The Bayou v Shian Ned","eventName":"Rockhampton (AUS) 2nd Mar"},"rc":[],"con":true,"img":false}]}
{"op":"mcm","clk":"5352163431","pt":1646184031617,"mc":[{"id":"1.195503856","marketDefinition":{"bspMarket":false,"turnInPlayEnabled":false,"persistenceEnabled":false,"marketBaseRate":7.0,"eventId":"31272499","eventTypeId":"4339","numberOfWinners":1,"bettingType":"ODDS","marketType":"MATCH_BET","marketTime":"2022-03-02T11:09:00.000Z","suspendTime":"2022-03-02T11:09:00.000Z","bspReconciled":false,"complete":true,"inPlay":false,"crossMatching":true,"runnersVoidable":false,"numberOfActiveRunners":2,"betDelay":0,"status":"OPEN","runners":[{"status":"ACTIVE","sortPriority":1,"id":38247337,"name":"5. On The Bayou"},{"status":"ACTIVE","sortPriority":2,"id":39832467,"name":"7. Shian Ned"}],"regulators":["MR_INT"],"venue":"Rockhampton","countryCode":"AU","discountAllowed":true,"timezone":"Australia/Queensland","openDate":"2022-03-02T08:28:00.000Z","version":4382605982,"name":"On The Bayou v Shian Ned","eventName":"Rockhampton (AUS) 2nd Mar"},"rc":[],"con":true,"img":false}]}
{"op":"mcm","clk":"5352466710","pt":1646191002691,"mc":[{"id":"1.195503856","marketDefinition":{"bspMarket":false,"turnInPlayEnabled":false,"persistenceEnabled":false,"marketBaseRate":7.0,"eventId":"31272499","eventTypeId":"4339","numberOfWinners":1,"bettingType":"ODDS","marketType":"MATCH_BET","marketTime":"2022-03-02T11:09:00.000Z","suspendTime":"2022-03-02T11:09:00.000Z","bspReconciled":false,"complete":true,"inPlay":false,"crossMatching":true,"runnersVoidable":false,"numberOfActiveRunners":2,"betDelay":0,"status":"OPEN","runners":[{"status":"ACTIVE","sortPriority":1,"id":38247337,"name":"5. On The Bayou"},{"status":"ACTIVE","sortPriority":2,"id":39832467,"name":"7. Shian Ned"}],"regulators":["MR_INT"],"venue":"Rockhampton","countryCode":"AU","discountAllowed":true,"timezone":"Australia/Queensland","openDate":"2022-03-02T08:28:00.000Z","version":4382605982,"name":"On The Bayou v Shian Ned","eventName":"Rockhampton (AUS) 2nd Mar"},"rc":[{"atb":[[1.46,11.75],[1.26,20.79],[1.66,8.19]],"id":38247337},{"atb":[[1.89,6.07],[1.49,11.03],[1.69,7.83]],"id":39832467}],"con":true,"img":true}]}
{"op":"mcm","clk":"5352823516","pt":1646201802742,"mc":[{"id":"1.195503856","marketDefinition":{"bspMarket":false,"turnInPlayEnabled":false,"persistenceEnabled":false,"marketBaseRate":7.0,"eventId":"31272499","eventTypeId":"4339","numberOfWinners":1,"bettingType":"ODDS","marketType":"MATCH_BET","marketTime":"2022-03-02T11:09:00.000Z","suspendTime":"2022-03-02T11:09:00.000Z","bspReconciled":false,"complete":true,"inPlay":false,"crossMatching":true,"runnersVoidable":false,"numberOfActiveRunners":2,"betDelay":0,"status":"OPEN","runners":[{"status":"ACTIVE","sortPriority":1,"id":38247337,"name":"5. On The Bayou"},{"status":"ACTIVE","sortPriority":2,"id":39832467,"name":"7. Shian Ned"}],"regulators":["MR_INT"],"venue":"Rockhampton","countryCode":"AU","discountAllowed":true,"timezone":"Australia/Queensland","openDate":"2022-03-02T08:28:00.000Z","version":4382605982,"name":"On The Bayou v Shian Ned","eventName":"Rockhampton (AUS) 2nd Mar"},"rc":[{"atb":[[1.46,11.74],[1.26,20.79],[1.66,8.19]],"id":38247337},{"atb":[[1.89,6.07],[1.49,11.02],[1.69,7.83]],"id":39832467}],"con":true,"img":true}]}
{"op":"mcm","clk":"5352957923","pt":1646205655386,"mc":[{"id":"1.195503856","rc":[{"atb":[[1.46,0],[1.26,0],[1.66,0]],"id":38247337},{"atb":[[1.89,0],[1.49,0],[1.69,0]],"id":39832467}],"con":true,"img":false}]}
{"op":"mcm","clk":"5352958469","pt":1646205672803,"mc":[{"id":"1.195503856","rc":[{"atb":[[1.46,11.74],[1.26,20.78],[1.66,8.18]],"id":38247337},{"atb":[[1.89,6.06],[1.49,11.02],[1.69,7.83]],"id":39832467}],"con":true,"img":false}]}
{"op":"mcm","clk":"5353300273","pt":1646212602762,"mc":[{"id":"1.195503856","marketDefinition":{"bspMarket":false,"turnInPlayEnabled":false,"persistenceEnabled":false,"marketBaseRate":7.0,"eventId":"31272499","eventTypeId":"4339","numberOfWinners":1,"bettingType":"ODDS","marketType":"MATCH_BET","marketTime":"2022-03-02T11:09:00.000Z","suspendTime":"2022-03-02T11:09:00.000Z","bspReconciled":false,"complete":true,"inPlay":false,"crossMatching":true,"runnersVoidable":false,"numberOfActiveRunners":2,"betDelay":0,"status":"OPEN","runners":[{"status":"ACTIVE","sortPriority":1,"id":38247337,"name":"5. On The Bayou"},{"status":"ACTIVE","sortPriority":2,"id":39832467,"name":"7. Shian Ned"}],"regulators":["MR_INT"],"venue":"Rockhampton","countryCode":"AU","discountAllowed":true,"timezone":"Australia/Queensland","openDate":"2022-03-02T08:28:00.000Z","version":4382605982,"name":"On The Bayou v Shian Ned","eventName":"Rockhampton (AUS) 2nd Mar"},"rc":[{"atb":[[1.46,11.72],[1.26,20.75],[1.66,8.17]],"id":38247337},{"atb":[[1.89,6.06],[1.49,11],[1.69,7.82]],"id":39832467}],"con":true,"img":true}]}
{"op":"mcm","clk":"5353305249","pt":1646212673199,"mc":[{"id":"1.195503856","rc":[{"atb":[[1.46,0],[1.26,0],[1.66,0]],"id":38247337},{"atb":[[1.89,0],[1.49,0],[1.69,0]],"id":39832467}],"con":true,"img":false}]}
{"op":"mcm","clk":"5353305895","pt":1646212685147,"mc":[{"id":"1.195503856","rc":[{"atb":[[1.56,9.63],[1.96,5.61],[1.76,7.1]],"id":38247337},{"atb":[[1.37,14.58],[1.57,9.46],[1.17,31.74]],"id":39832467}],"con":true,"img":false}]}
{"op":"mcm","clk":"5353758238","pt":1646218143002,"mc":[{"id":"1.195503856","rc":[{"atb":[[1.88,2]],"id":38247337},{"atl":[[2.56,2]],"id":38247337},{"atb":[[1.59,2]],"id":39832467},{"atl":[[2.18,2]],"id":39832467}],"con":true,"img":false}]}
{"op":"mcm","clk":"5353759572","pt":1646218158897,"mc":[{"id":"1.195503856","rc":[{"atb":[[1.59,0],[1.58,2]],"id":39832467}],"con":true,"img":false}]}
{"op":"mcm","clk":"5353761541","pt":1646218182950,"mc":[{"id":"1.195503856","rc":[{"atb":[[1.59,2],[1.58,0]],"id":39832467}],"con":true,"img":false}]}
{"op":"mcm","clk":"5353763046","pt":1646218202985,"mc":[{"id":"1.195503856","rc":[{"atb":[[1.88,0]],"id":38247337},{"atl":[[2.56,0]],"id":38247337},{"atb":[[1.59,0]],"id":39832467},{"atl":[[2.18,0]],"id":39832467}],"con":true,"img":false}]}
{"op":"mcm","clk":"5353790116","pt":1646218503660,"mc":[{"id":"1.195503856","rc":[{"atb":[[1.56,0],[1.96,0],[1.76,0]],"id":38247337},{"atb":[[1.37,0],[1.57,0],[1.17,0]],"id":39832467}],"con":true,"img":false}]}
{"op":"mcm","clk":"5353790585","pt":1646218508238,"mc":[{"id":"1.195503856","rc":[{"atb":[[1.56,9.63],[1.96,5.61],[1.76,7.1]],"id":38247337},{"atb":[[1.37,14.58],[1.57,9.46],[1.17,31.74]],"id":39832467}],"con":true,"img":false}]}
{"op":"mcm","clk":"5353790627","pt":1646218508550,"mc":[{"id":"1.195503856","rc":[{"atb":[[1.79,2]],"id":38247337},{"atl":[[2.5,2]],"id":38247337},{"atb":[[1.63,2]],"id":39832467},{"atl":[[2.24,2]],"id":39832467}],"con":true,"img":false}]}
{"op":"mcm","clk":"5353791345","pt":1646218513735,"mc":[{"id":"1.195503856","rc":[{"atl":[[2.5,0],[2.42,2]],"id":38247337},{"atb":[[1.63,0],[1.67,2]],"id":39832467}],"con":true,"img":false}]}
{"op":"mcm","clk":"5353792516","pt":1646218522882,"mc":[{"id":"1.195503856","rc":[{"atl":[[2.5,2],[2.42,0]],"id":38247337},{"atb":[[1.67,0],[1.62,2]],"id":39832467}],"con":true,"img":false}]}
{"op":"mcm","clk":"5353793347","pt":1646218528877,"mc":[{"id":"1.195503856","rc":[{"atb":[[1.63,2],[1.62,0]],"id":39832467}],"con":true,"img":false}]}
{"op":"mcm","clk":"5353795723","pt":1646218547600,"mc":[{"id":"1.195503856","rc":[{"atb":[[1.63,0],[1.61,2]],"id":39832467}],"con":true,"img":false}]}
{"op":"mcm","clk":"5353796292","pt":1646218552732,"mc":[{"id":"1.195503856","rc":[{"atb":[[1.62,2]],"id":39832467}],"con":true,"img":false}]}
{"op":"mcm","clk":"5353796303","pt":1646218552798,"mc":[{"id":"1.195503856","rc":[{"atb":[[1.61,0]],"id":39832467}],"con":true,"img":false}]}
{"op":"mcm","clk":"5353797841","pt":1646218566435,"mc":[{"id":"1.195503856","rc":[{"atb":[[1.62,0],[1.61,2]],"id":39832467}],"con":true,"img":false}]}
{"op":"mcm","clk":"5353798322","pt":1646218571440,"mc":[{"id":"1.195503856","rc":[{"atl":[[2.5,0],[2.48,2]],"id":38247337}],"con":true,"img":false}]}
{"op":"mcm","clk":"5353798330","pt":1646218571535,"mc":[{"id":"1.195503856","rc":[{"atb":[[1.63,2],[1.61,0]],"id":39832467}],"con":true,"img":false}]}
{"op":"mcm","clk":"5353800050","pt":1646218588980,"mc":[{"id":"1.195503856","rc":[{"atb":[[1.63,0],[1.62,2]],"id":39832467}],"con":true,"img":false}]}
{"op":"mcm","clk":"5353800103","pt":1646218589473,"mc":[{"id":"1.195503856","rc":[{"atb":[[1.63,2],[1.62,0]],"id":39832467}],"con":true,"img":false}]}
{"op":"mcm","clk":"5353801350","pt":1646218602602,"mc":[{"id":"1.195503856","rc":[{"atb":[[1.63,0],[1.6,2]],"id":39832467}],"con":true,"img":false}]}
{"op":"mcm","clk":"5353801589","pt":1646218604808,"mc":[{"id":"1.195503856","rc":[{"atb":[[1.6,0],[1.63,2]],"id":39832467}],"con":true,"img":false}]}
{"op":"mcm","clk":"5353802130","pt":1646218609896,"mc":[{"id":"1.195503856","rc":[{"atb":[[1.63,0],[1.61,2]],"id":39832467}],"con":true,"img":false}]}
{"op":"mcm","clk":"5353802632","pt":1646218615008,"mc":[{"id":"1.195503856","rc":[{"atb":[[1.6,2]],"id":39832467}],"con":true,"img":false}]}
{"op":"mcm","clk":"5353802639","pt":1646218615109,"mc":[{"id":"1.195503856","rc":[{"atb":[[1.61,0]],"id":39832467}],"con":true,"img":false}]}
{"op":"mcm","clk":"5353806954","pt":1646218661687,"mc":[{"id":"1.195503856","rc":[{"atb":[[1.6,0],[1.63,2]],"id":39832467}],"con":true,"img":false}]}
{"op":"mcm","clk":"5353807826","pt":1646218671999,"mc":[{"id":"1.195503856","rc":[{"atb":[[1.63,0],[1.62,2]],"id":39832467}],"con":true,"img":false}]}
{"op":"mcm","clk":"5353808535","pt":1646218679589,"mc":[{"id":"1.195503856","rc":[{"atb":[[1.64,2],[1.62,0]],"id":39832467}],"con":true,"img":false}]}
{"op":"mcm","clk":"5353809189","pt":1646218686612,"mc":[{"id":"1.195503856","rc":[{"atl":[[2.46,2],[2.48,0]],"id":38247337}],"con":true,"img":false}]}
{"op":"mcm","clk":"5353809653","pt":1646218691909,"mc":[{"id":"1.195503856","rc":[{"atb":[[1.64,0],[1.65,2]],"id":39832467}],"con":true,"img":false}]}
{"op":"mcm","clk":"5353812064","pt":1646218716838,"mc":[{"id":"1.195503856","rc":[{"atb":[[1.64,2],[1.65,0]],"id":39832467}],"con":true,"img":false}]}
{"op":"mcm","clk":"5353812642","pt":1646218722876,"mc":[{"id":"1.195503856","rc":[{"atb":[[1.64,0],[1.65,2]],"id":39832467}],"con":true,"img":false}]}
{"op":"mcm","clk":"5353812652","pt":1646218722981,"mc":[{"id":"1.195503856","rc":[{"atl":[[2.42,2],[2.46,0]],"id":38247337}],"con":true,"img":false}]}
{"op":"mcm","clk":"5353813111","pt":1646218727944,"mc":[{"id":"1.195503856","rc":[{"atb":[[1.64,2],[1.65,0]],"id":39832467}],"con":true,"img":false}]}
{"op":"mcm","clk":"5353813588","pt":1646218733083,"mc":[{"id":"1.195503856","rc":[{"atb":[[1.65,2]],"id":39832467}],"con":true,"img":false}]}
{"op":"mcm","clk":"5353813600","pt":1646218733182,"mc":[{"id":"1.195503856","rc":[{"atb":[[1.64,0]],"id":39832467}],"con":true,"img":false}]}
{"op":"mcm","clk":"5353813827","pt":1646218735535,"mc":[{"id":"1.195503856","rc":[{"atb":[[1.56,0],[1.96,0],[1.76,0]],"id":38247337},{"atb":[[1.37,0],[1.57,0],[1.17,0]],"id":39832467}],"con":true,"img":false}]}
{"op":"mcm","clk":"5353814233","pt":1646218739487,"mc":[{"id":"1.195503856","rc":[{"atb":[[1.56,9.63],[1.96,5.61],[1.76,7.1]],"id":38247337},{"atb":[[1.37,14.58],[1.57,9.46],[1.17,31.74]],"id":39832467}],"con":true,"img":false}]}
{"op":"mcm","clk":"5353814258","pt":1646218739703,"mc":[{"id":"1.195503856","rc":[{"atb":[[1.64,2],[1.65,0]],"id":39832467}],"con":true,"img":false}]}
{"op":"mcm","clk":"5353814392","pt":1646218741005,"mc":[{"id":"1.195503856","rc":[{"atb":[[1.64,0],[1.65,2]],"id":39832467}],"con":true,"img":false}]}
{"op":"mcm","clk":"5353814540","pt":1646218742381,"mc":[{"id":"1.195503856","rc":[{"atb":[[1.65,0],[1.66,2]],"id":39832467}],"con":true,"img":false}]}
{"op":"mcm","clk":"5353814665","pt":1646218743579,"mc":[{"id":"1.195503856","rc":[{"atb":[[1.66,0],[1.65,2]],"id":39832467}],"con":true,"img":false}]}
{"op":"mcm","clk":"5353815185","pt":1646218748707,"mc":[{"id":"1.195503856","rc":[{"atb":[[1.65,0]],"id":39832467}],"con":true,"img":false}]}
{"op":"mcm","clk":"5353815199","pt":1646218748798,"mc":[{"id":"1.195503856","rc":[{"atb":[[1.67,2]],"id":39832467}],"con":true,"img":false}]}
{"op":"mcm","clk":"5353815227","pt":1646218749111,"mc":[{"id":"1.195503856","rc":[{"atb":[[1.67,0],[1.66,2]],"id":39832467}],"con":true,"img":false}]}
{"op":"mcm","clk":"5353815749","pt":1646218754288,"mc":[{"id":"1.195503856","rc":[{"atb":[[1.67,2],[1.66,0]],"id":39832467}],"con":true,"img":false}]}
{"op":"mcm","clk":"5353817306","pt":1646218769423,"mc":[{"id":"1.195503856","rc":[{"atb":[[1.67,0],[1.66,2]],"id":39832467}],"con":true,"img":false}]}
{"op":"mcm","clk":"5353817801","pt":1646218774639,"mc":[{"id":"1.195503856","rc":[{"atb":[[1.67,2],[1.66,0]],"id":39832467}],"con":true,"img":false}]}
{"op":"mcm","clk":"5353818037","pt":1646218777142,"mc":[{"id":"1.195503856","rc":[{"atb":[[1.79,0]],"id":38247337},{"atl":[[2.24,0],[2.3,2]],"id":39832467}],"con":true,"img":false}]}
{"op":"mcm","clk":"5353818052","pt":1646218777349,"mc":[{"id":"1.195503856","rc":[{"atb":[[1.75,2]],"id":38247337}],"con":true,"img":false}]}
{"op":"mcm","clk":"5353818281","pt":1646218779746,"mc":[{"id":"1.195503856","rc":[{"atb":[[1.66,2]],"id":39832467}],"con":true,"img":false}]}
{"op":"mcm","clk":"5353818291","pt":1646218779848,"mc":[{"id":"1.195503856","rc":[{"atb":[[1.67,0]],"id":39832467}],"con":true,"img":false}]}
{"op":"mcm","clk":"5353818574","pt":1646218782348,"mc":[{"id":"1.195503856","rc":[{"atl":[[2.3,0],[2.28,2]],"id":39832467}],"con":true,"img":false}]}
{"op":"mcm","clk":"5353823694","pt":1646218832079,"mc":[{"id":"1.195503856","rc":[{"atb":[[1.56,9.63],[1.96,5.61],[1.76,7.1]],"id":38247337},{"atl":[[2.4,2],[2.42,0]],"id":38247337},{"atb":[[1.37,14.58],[1.57,9.46],[1.67,2],[1.66,0],[1.17,31.74]],"id":39832467}],"con":true,"img":false}]}
{"op":"mcm","clk":"5353824096","pt":1646218835725,"mc":[{"id":"1.195503856","rc":[{"atb":[[1.75,0]],"id":38247337},{"atl":[[2.28,0],[2.34,2]],"id":39832467}],"con":true,"img":false}]}
{"op":"mcm","clk":"5353824118","pt":1646218835886,"mc":[{"id":"1.195503856","rc":[{"atb":[[1.72,2]],"id":38247337}],"con":true,"img":false}]}
{"op":"mcm","clk":"5353824202","pt":1646218836717,"mc":[{"id":"1.195503856","rc":[{"atl":[[2.26,2],[2.34,0]],"id":39832467}],"con":true,"img":false}]}
{"op":"mcm","clk":"5353824665","pt":1646218841004,"mc":[{"id":"1.195503856","rc":[{"atb":[[1.72,0],[1.77,2]],"id":38247337}],"con":true,"img":false}]}
{"op":"mcm","clk":"5353826893","pt":1646218865339,"mc":[{"id":"1.195503856","rc":[{"atb":[[1.68,2]],"id":39832467}],"con":true,"img":false}]}
{"op":"mcm","clk":"5353826904","pt":1646218865399,"mc":[{"id":"1.195503856","rc":[{"atb":[[1.67,0]],"id":39832467}],"con":true,"img":false}]}
{"op":"mcm","clk":"5353827239","pt":1646218869029,"mc":[{"id":"1.195503856","rc":[{"atl":[[2.32,15]],"id":38247337}],"con":true,"img":false}]}
{"op":"mcm","clk":"5353827297","pt":1646218869605,"mc":[{"id":"1.195503856","rc":[{"atb":[[1.56,20],[1.59,15],[1.57,27.46],[1.58,16],[1.55,22],[1.54,24],[1.53,26]],"id":39832467}],"con":true,"img":false}]}
{"op":"mcm","clk":"5353827348","pt":1646218870123,"mc":[{"id":"1.195503856","rc":[{"atl":[[2.8,7],[2.82,8],[2.88,11],[2.86,10],[2.84,9],[2.78,6],[2.76,5]],"id":39832467}],"con":true,"img":false}]}
{"op":"mcm","clk":"5353827369","pt":1646218870333,"mc":[{"id":"1.195503856","rc":[{"atl":[[2.36,2],[2.26,0]],"id":39832467}],"con":true,"img":false}]}
{"op":"mcm","clk":"5353828057","pt":1646218876324,"mc":[{"id":"1.195503856","rc":[{"atl":[[2.36,0],[2.38,2]],"id":39832467}],"con":true,"img":false}]}
{"op":"mcm","clk":"5353828530","pt":1646218881534,"mc":[{"id":"1.195503856","rc":[{"atl":[[2.36,2],[2.38,0]],"id":39832467}],"con":true,"img":false}]}
{"op":"mcm","clk":"5353829062","pt":1646218886941,"mc":[{"id":"1.195503856","rc":[{"atl":[[2.36,0],[2.38,2]],"id":39832467}],"con":true,"img":false}]}
{"op":"mcm","clk":"5353829402","pt":1646218890528,"mc":[{"id":"1.195503856","rc":[{"atb":[[1.96,0]],"id":38247337},{"atl":[[1.96,3.11]],"id":38247337},{"trd":[[1.96,11.23]],"ltp":1.96,"tv":11.23,"id":38247337}],"con":true,"img":false}]}
{"op":"mcm","clk":"5353829409","pt":1646218890635,"mc":[{"id":"1.195503856","rc":[{"atl":[[2.22,2],[1.96,0]],"id":38247337},{"trd":[[1.96,17.45]],"ltp":1.96,"tv":17.45,"id":38247337}],"con":true,"img":false}]}
{"op":"mcm","clk":"5353829420","pt":1646218890738,"mc":[{"id":"1.195503856","rc":[{"atl":[[2.4,0]],"id":38247337}],"con":true,"img":false}]}
{"op":"mcm","clk":"5353829427","pt":1646218890842,"mc":[{"id":"1.195503856","rc":[{"atl":[[2.4,2],[2.22,0]],"id":38247337},{"atl":[[2.42,2],[2.38,0]],"id":39832467}],"con":true,"img":false}]}
{"op":"mcm","clk":"5353829432","pt":1646218890946,"mc":[{"id":"1.195503856","rc":[{"atl":[[2.4,0],[2.32,17]],"id":38247337}],"con":true,"img":false}]}
{"op":"mcm","clk":"5353829438","pt":1646218891054,"mc":[{"id":"1.195503856","rc":[{"atl":[[2.4,2],[2.32,15]],"id":38247337}],"con":true,"img":false}]}
{"op":"mcm","clk":"5353829551","pt":1646218892258,"mc":[{"id":"1.195503856","rc":[{"atl":[[2.4,2],[2.42,0]],"id":39832467}],"con":true,"img":false}]}
{"op":"mcm","clk":"5353830008","pt":1646218897346,"mc":[{"id":"1.195503856","rc":[{"atl":[[2.4,0],[2.44,2]],"id":39832467}],"con":true,"img":false}]}
{"op":"mcm","clk":"5353830183","pt":1646218899190,"mc":[{"id":"1.195503856","rc":[{"atb":[[1.64,2],[1.68,0]],"id":39832467}],"con":true,"img":false}]}
{"op":"mcm","clk":"5353830869","pt":1646218902570,"mc":[{"id":"1.195503856","rc":[{"atl":[[2.4,2],[2.44,0]],"id":39832467}],"con":true,"img":false}]}
{"op":"mcm","clk":"5353831208","pt":1646218904366,"mc":[{"id":"1.195503856","rc":[{"atb":[[1.64,0],[1.66,2]],"id":39832467}],"con":true,"img":false}]}
{"op":"mcm","clk":"5353831719","pt":1646218907682,"mc":[{"id":"1.195503856","rc":[{"atl":[[2.36,2]],"id":39832467}],"con":true,"img":false}]}
{"op":"mcm","clk":"5353831732","pt":1646218907805,"mc":[{"id":"1.195503856","rc":[{"atl":[[2.4,0]],"id":39832467}],"con":true,"img":false}]}
{"op":"mcm","clk":"5353832043","pt":1646218909598,"mc":[{"id":"1.195503856","rc":[{"atb":[[1.67,2],[1.66,0]],"id":39832467}],"con":true,"img":false}]}
{"op":"mcm","clk":"5353832925","pt":1646218914508,"mc":[{"id":"1.195503856","rc":[{"atl":[[2.36,0],[2.38,2]],"id":39832467}],"con":true,"img":false}]}
{"op":"mcm","clk":"5353834197","pt":1646218921076,"mc":[{"id":"1.195503856","rc":[{"atl":[[2.4,2],[2.38,0]],"id":39832467}],"con":true,"img":false}]}
{"op":"mcm","clk":"5353834215","pt":1646218921186,"mc":[{"id":"1.195503856","rc":[{"atl":[[15,1.42]],"id":38247337},{"atb":[[1.91,1.42]],"id":39832467},{"atl":[[14.5,1.42]],"id":39832467}],"con":true,"img":false}]}
{"op":"mcm","clk":"5353834248","pt":1646218921398,"mc":[{"id":"1.195503856","rc":[{"atl":[[2.4,0],[2.42,2]],"id":38247337},{"atb":[[1.79,2],[1.67,0]],"id":39832467},{"atl":[[2.4,0],[2.38,2]],"id":39832467}],"con":true,"img":false}]}
{"op":"mcm","clk":"5353834503","pt":1646218922882,"mc":[{"id":"1.195503856","rc":[{"atl":[[15.5,1.42]],"id":38247337},{"atb":[[1.86,1.42]],"id":39832467},{"atl":[[15,1.42]],"id":39832467}],"con":true,"img":false}]}
{"op":"mcm","clk":"5353834608","pt":1646218923409,"mc":[{"id":"1.195503856","rc":[{"atb":[[1.91,0]],"id":39832467}],"con":true,"img":false}]}
{"op":"mcm","clk":"5353834807","pt":1646218924686,"mc":[{"id":"1.195503856","rc":[{"atl":[[17,1.42]],"id":38247337},{"atb":[[1.84,1.42]],"id":39832467},{"atl":[[17,1.42]],"id":39832467}],"con":true,"img":false}]}
{"op":"mcm","clk":"5353834835","pt":1646218924896,"mc":[{"id":"1.195503856","rc":[{"atb":[[1.86,0]],"id":39832467},{"atl":[[14.5,0]],"id":39832467}],"con":true,"img":false}]}
{"op":"mcm","clk":"5353834999","pt":1646218925998,"mc":[{"id":"1.195503856","rc":[{"atl":[[17.5,1.42]],"id":38247337},{"atb":[[1.83,1.42]],"id":39832467},{"atl":[[17.5,1.42]],"id":39832467}],"con":true,"img":false}]}
{"op":"mcm","clk":"5353835027","pt":1646218926205,"mc":[{"id":"1.195503856","rc":[{"atb":[[1.84,0]],"id":39832467}],"con":true,"img":false}]}
{"op":"mcm","clk":"5353835085","pt":1646218926617,"mc":[{"id":"1.195503856","rc":[{"atl":[[2.42,2],[2.38,0]],"id":39832467}],"con":true,"img":false}]}
{"op":"mcm","clk":"5353835106","pt":1646218926779,"mc":[{"id":"1.195503856","rc":[{"atl":[[2.42,0],[2.44,2]],"id":38247337}],"con":true,"img":false}]}
{"op":"mcm","clk":"5353835166","pt":1646218927198,"mc":[{"id":"1.195503856","rc":[{"atl":[[18,1.42]],"id":38247337},{"atb":[[1.85,1.42]],"id":39832467},{"atl":[[18,1.42]],"id":39832467}],"con":true,"img":false}]}
{"op":"mcm","clk":"5353835182","pt":1646218927299,"mc":[{"id":"1.195503856","rc":[{"atl":[[15,0]],"id":39832467}],"con":true,"img":false}]}
{"op":"mcm","clk":"5353835337","pt":1646218928616,"mc":[{"id":"1.195503856","rc":[{"atl":[[18.5,1.42]],"id":38247337},{"atb":[[1.84,1.42]],"id":39832467},{"atl":[[18.5,1.42]],"id":39832467}],"con":true,"img":false}]}
{"op":"mcm","clk":"5353835391","pt":1646218928975,"mc":[{"id":"1.195503856","rc":[{"atl":[[15,0]],"id":38247337}],"con":true,"img":false}]}
{"op":"mcm","clk":"5353835508","pt":1646218930112,"mc":[{"id":"1.195503856","rc":[{"atl":[[19,1.42]],"id":38247337},{"atb":[[1.82,1.42]],"id":39832467},{"atl":[[19,1.42]],"id":39832467}],"con":true,"img":false}]}
{"op":"mcm","clk":"5353835532","pt":1646218930328,"mc":[{"id":"1.195503856","rc":[{"atl":[[2.4,2],[2.42,0]],"id":39832467}],"con":true,"img":false}]}
{"op":"mcm","clk":"5353835595","pt":1646218930898,"mc":[{"id":"1.195503856","rc":[{"atb":[[1.85,0]],"id":39832467}],"con":true,"img":false}]}
{"op":"mcm","clk":"5353835720","pt":1646218931998,"mc":[{"id":"1.195503856","rc":[{"atl":[[2.38,2],[2.44,0]],"id":38247337}],"con":true,"img":false}]}
{"op":"mcm","clk":"5353835774","pt":1646218932621,"mc":[{"id":"1.195503856","rc":[{"atl":[[19.5,1.42]],"id":38247337},{"atb":[[1.87,1.42]],"id":39832467},{"atl":[[19.5,1.42]],"id":39832467}],"con":true,"img":false}]}
{"op":"mcm","clk":"5353835819","pt":1646218933094,"mc":[{"id":"1.195503856","rc":[{"atb":[[1.84,0]],"id":39832467}],"con":true,"img":false}]}
{"op":"mcm","clk":"5353835968","pt":1646218934819,"mc":[{"id":"1.195503856","rc":[{"atb":[[1.87,0]],"id":39832467}],"con":true,"img":false}]}
{"op":"mcm","clk":"5353836011","pt":1646218935387,"mc":[{"id":"1.195503856","rc":[{"atl":[[20,1.42]],"id":38247337},{"atb":[[1.86,1.42]],"id":39832467},{"atl":[[20,1.42]],"id":39832467}],"con":true,"img":false}]}
{"op":"mcm","clk":"5353836021","pt":1646218935492,"mc":[{"id":"1.195503856","rc":[{"atl":[[2.4,0],[2.42,2]],"id":39832467}],"con":true,"img":false}]}
{"op":"mcm","clk":"5353836100","pt":1646218936426,"mc":[{"id":"1.195503856","rc":[{"atl":[[15.5,0]],"id":38247337},{"atb":[[1.83,0]],"id":39832467}],"con":true,"img":false}]}
{"op":"mcm","clk":"5353836109","pt":1646218936531,"mc":[{"id":"1.195503856","rc":[{"atl":[[2.44,2],[2.42,0]],"id":39832467}],"con":true,"img":false}]}
{"op":"mcm","clk":"5353836189","pt":1646218937524,"mc":[{"id":"1.195503856","rc":[{"atl":[[20,2.84]],"id":38247337},{"atb":[[1.81,1.42]],"id":39832467},{"atl":[[20,2.84]],"id":39832467}],"con":true,"img":false}]}
{"op":"mcm","clk":"5353836227","pt":1646218937995,"mc":[{"id":"1.195503856","rc":[{"atb":[[1.86,0]],"id":39832467}],"con":true,"img":false}]}
{"op":"mcm","clk":"5353836292","pt":1646218938938,"mc":[{"id":"1.195503856","rc":[{"atl":[[2.36,2],[2.38,0]],"id":38247337}],"con":true,"img":false}]}
{"op":"mcm","clk":"5353836379","pt":1646218940041,"mc":[{"id":"1.195503856","rc":[{"atl":[[21,1.42]],"id":38247337},{"atb":[[1.83,1.42]],"id":39832467},{"atl":[[21,1.42]],"id":39832467}],"con":true,"img":false}]}
{"op":"mcm","clk":"5353836396","pt":1646218940196,"mc":[{"id":"1.195503856","rc":[{"atb":[[1.82,0]],"id":39832467}],"con":true,"img":false}]}
{"op":"mcm","clk":"5353836497","pt":1646218941589,"mc":[{"id":"1.195503856","rc":[{"atb":[[1.82,1.42]],"id":39832467}],"con":true,"img":false}]}
{"op":"mcm","clk":"5353836506","pt":1646218941694,"mc":[{"id":"1.195503856","rc":[{"atl":[[2.44,0],[2.42,2]],"id":39832467}],"con":true,"img":false}]}
{"op":"mcm","clk":"5353836584","pt":1646218942739,"mc":[{"id":"1.195503856","rc":[{"atb":[[1.82,2.84]],"id":39832467}],"con":true,"img":false}]}
{"op":"mcm","clk":"5353836671","pt":1646218943731,"mc":[{"id":"1.195503856","rc":[{"atb":[[1.83,0]],"id":39832467}],"con":true,"img":false}]}
{"op":"mcm","clk":"5353836851","pt":1646218945504,"mc":[{"id":"1.195503856","rc":[{"atl":[[2.36,0],[2.38,2]],"id":38247337},{"atb":[[1.86,1.42]],"id":39832467}],"con":true,"img":false}]}
{"op":"mcm","clk":"5353836887","pt":1646218945922,"mc":[{"id":"1.195503856","rc":[{"atb":[[1.82,0]],"id":39832467}],"con":true,"img":false}]}
{"op":"mcm","clk":"5353837037","pt":1646218947536,"mc":[{"id":"1.195503856","rc":[{"atb":[[1.84,1.42]],"id":39832467}],"con":true,"img":false}]}
{"op":"mcm","clk":"5353837047","pt":1646218947745,"mc":[{"id":"1.195503856","rc":[{"atb":[[1.86,0]],"id":39832467}],"con":true,"img":false}]}
{"op":"mcm","clk":"5353837163","pt":1646218949199,"mc":[{"id":"1.195503856","rc":[{"atb":[[1.83,1.42]],"id":39832467}],"con":true,"img":false}]}
{"op":"mcm","clk":"5353837202","pt":1646218949712,"mc":[{"id":"1.195503856","rc":[{"atb":[[1.84,0]],"id":39832467}],"con":true,"img":false}]}
{"op":"mcm","clk":"5353837343","pt":1646218951430,"mc":[{"id":"1.195503856","rc":[{"atb":[[1.84,1.42]],"id":39832467}],"con":true,"img":false}]}
{"op":"mcm","clk":"5353837385","pt":1646218952052,"mc":[{"id":"1.195503856","rc":[{"atl":[[2.4,2],[2.42,0]],"id":39832467}],"con":true,"img":false}]}
{"op":"mcm","clk":"5353837456","pt":1646218952972,"mc":[{"id":"1.195503856","rc":[{"atb":[[1.86,1.42]],"id":39832467}],"con":true,"img":false}]}
{"op":"mcm","clk":"5353837493","pt":1646218953345,"mc":[{"id":"1.195503856","rc":[{"atb":[[1.84,0]],"id":39832467}],"con":true,"img":false}]}
{"op":"mcm","clk":"5353837617","pt":1646218954748,"mc":[{"id":"1.195503856","rc":[{"atb":[[1.85,1.42]],"id":39832467}],"con":true,"img":false}]}
{"op":"mcm","clk":"5353837665","pt":1646218955314,"mc":[{"id":"1.195503856","rc":[{"atb":[[1.86,0]],"id":39832467}],"con":true,"img":false}]}
{"op":"mcm","clk":"5353837675","pt":1646218955515,"mc":[{"id":"1.195503856","rc":[{"atl":[[2.36,2],[2.38,0]],"id":38247337}],"con":true,"img":false}]}
{"op":"mcm","clk":"5353837798","pt":1646218956923,"mc":[{"id":"1.195503856","rc":[{"atb":[[1.87,1.42]],"id":39832467}],"con":true,"img":false}]}
{"op":"mcm","clk":"5353837819","pt":1646218957141,"mc":[{"id":"1.195503856","rc":[{"atl":[[2.36,0],[2.38,2]],"id":38247337}],"con":true,"img":false}]}
{"op":"mcm","clk":"5353837829","pt":1646218957241,"mc":[{"id":"1.195503856","rc":[{"atl":[[2.4,0],[2.42,2]],"id":39832467}],"con":true,"img":false}]}
{"op":"mcm","clk":"5353838174","pt":1646218961138,"mc":[{"id":"1.195503856","rc":[{"atb":[[1.86,1.42]],"id":39832467}],"con":true,"img":false}]}
{"op":"mcm","clk":"5353838275","pt":1646218962240,"mc":[{"id":"1.195503856","rc":[{"atl":[[2.22,2],[2.38,0]],"id":38247337}],"con":true,"img":false}]}
{"op":"mcm","clk":"5353838285","pt":1646218962343,"mc":[{"id":"1.195503856","rc":[{"atb":[[1.86,2.84]],"id":39832467},{"atl":[[2.44,2],[2.42,0]],"id":39832467}],"con":true,"img":false}]}
{"op":"mcm","clk":"5353838333","pt":1646218962869,"mc":[{"id":"1.195503856","rc":[{"atl":[[2.44,0],[2.46,2]],"id":39832467}],"con":true,"img":false}]}
{"op":"mcm","clk":"5353838361","pt":1646218963237,"mc":[{"id":"1.195503856","rc":[{"atb":[[1.87,0]],"id":39832467}],"con":true,"img":false}]}
{"op":"mcm","clk":"5353838497","pt":1646218964931,"mc":[{"id":"1.195503856","rc":[{"atb":[[1.88,1.42]],"id":39832467},{"atl":[[22,1.42]],"id":39832467}],"con":true,"img":false}]}
{"op":"mcm","clk":"5353838562","pt":1646218965656,"mc":[{"id":"1.195503856","rc":[{"atb":[[1.86,0]],"id":39832467}],"con":true,"img":false}]}
{"op":"mcm","clk":"5353838739","pt":1646218967547,"mc":[{"id":"1.195503856","rc":[{"atb":[[1.87,1.42]],"id":39832467}],"con":true,"img":false}]}
{"op":"mcm","clk":"5353838773","pt":1646218967967,"mc":[{"id":"1.195503856","rc":[{"atb":[[1.88,0]],"id":39832467},{"atl":[[2.54,2],[2.46,0]],"id":39832467}],"con":true,"img":false}]}
{"op":"mcm","clk":"5353838917","pt":1646218969587,"mc":[{"id":"1.195503856","rc":[{"atb":[[1.87,2.84]],"id":39832467}],"con":true,"img":false}]}
{"op":"mcm","clk":"5353839079","pt":1646218971300,"mc":[{"id":"1.195503856","rc":[{"atl":[[22,1.42]],"id":38247337},{"atb":[[1.86,1.42]],"id":39832467}],"con":true,"img":false}]}
{"op":"mcm","clk":"5353839235","pt":1646218973089,"mc":[{"id":"1.195503856","rc":[{"atb":[[1.56,0],[1.76,0]],"id":38247337},{"atb":[[1.37,0],[1.57,18],[1.17,0]],"id":39832467}],"con":true,"img":false}]}
{"op":"mcm","clk":"5353839250","pt":1646218973283,"mc":[{"id":"1.195503856","rc":[{"atb":[[1.88,1.42]],"id":39832467}],"con":true,"img":false}]}
{"op":"mcm","clk":"5353839306","pt":1646218973901,"mc":[{"id":"1.195503856","rc":[{"atb":[[1.87,0]],"id":39832467}],"con":true,"img":false}]}
{"op":"mcm","clk":"5353839643","pt":1646218977400,"mc":[{"id":"1.195503856","rc":[{"atl":[[23,1.42]],"id":38247337},{"atb":[[1.87,1.42]],"id":39832467},{"atl":[[23,1.42]],"id":39832467}],"con":true,"img":false}]}
{"op":"mcm","clk":"5353839694","pt":1646218977813,"mc":[{"id":"1.195503856","rc":[{"atl":[[2.54,0],[2.56,10]],"id":39832467}],"con":true,"img":false}]}
{"op":"mcm","clk":"5353839873","pt":1646218979586,"mc":[{"id":"1.195503856","rc":[{"atb":[[1.84,1.42]],"id":39832467}],"con":true,"img":false}]}
{"op":"mcm","clk":"5353839923","pt":1646218980208,"mc":[{"id":"1.195503856","rc":[{"atb":[[1.88,0]],"id":39832467}],"con":true,"img":false}]}
{"op":"mcm","clk":"5353840015","pt":1646218981204,"mc":[{"id":"1.195503856","rc":[{"atb":[[1.56,9.63],[1.96,5.61],[1.76,7.1]],"id":38247337},{"atb":[[1.37,14.58],[1.57,27.46],[1.17,31.74]],"id":39832467}],"con":true,"img":false}]}
{"op":"mcm","clk":"5353840029","pt":1646218981414,"mc":[{"id":"1.195503856","rc":[{"atb":[[1.84,12.72],[1.77,0]],"id":38247337}],"con":true,"img":false}]}
{"op":"mcm","clk":"5353840060","pt":1646218981791,"mc":[{"id":"1.195503856","rc":[{"atb":[[1.88,1.42]],"id":39832467}],"con":true,"img":false}]}
{"op":"mcm","clk":"5353840093","pt":1646218982309,"mc":[{"id":"1.195503856","rc":[{"atb":[[1.87,0]],"id":39832467}],"con":true,"img":false}]}
{"op":"mcm","clk":"5353840145","pt":1646218982904,"mc":[{"id":"1.195503856","rc":[{"atl":[[2.58,10]],"id":39832467}],"con":true,"img":false}]}
{"op":"mcm","clk":"5353840152","pt":1646218982998,"mc":[{"id":"1.195503856","rc":[{"atl":[[2.56,0]],"id":39832467}],"con":true,"img":false}]}
{"op":"mcm","clk":"5353840247","pt":1646218984094,"mc":[{"id":"1.195503856","rc":[{"atb":[[1.87,1.42]],"id":39832467}],"con":true,"img":false}]}
{"op":"mcm","clk":"5353840324","pt":1646218984918,"mc":[{"id":"1.195503856","rc":[{"atl":[[17,0],[17.5,0],[18,0],[18.5,0],[19,0],[19.5,0],[20,0],[21,0],[22,0],[23,0]],"id":38247337},{"atl":[[17,0],[17.5,0]],"id":39832467}],"con":true,"img":false}]}
{"op":"mcm","clk":"5353840503","pt":1646218987052,"mc":[{"id":"1.195503856","rc":[{"atl":[[23,1.42]],"id":38247337},{"atb":[[1.82,1.42]],"id":39832467},{"atl":[[24,1.42]],"id":39832467}],"con":true,"img":false}]}
{"op":"mcm","clk":"5353840521","pt":1646218987209,"mc":[{"id":"1.195503856","rc":[{"atb":[[1.88,0]],"id":39832467},{"atl":[[18,0],[18.5,0]],"id":39832467}],"con":true,"img":false}]}
{"op":"mcm","clk":"5353840630","pt":1646218988310,"mc":[{"id":"1.195503856","rc":[{"atl":[[23,2.84]],"id":38247337},{"atb":[[1.82,2.84]],"id":39832467},{"atl":[[24,2.84]],"id":39832467}],"con":true,"img":false}]}
{"op":"mcm","clk":"5353840763","pt":1646218989612,"mc":[{"id":"1.195503856","rc":[{"atb":[[1.87,0]],"id":39832467},{"atl":[[19,0]],"id":39832467}],"con":true,"img":false}]}
{"op":"mcm","clk":"5353840895","pt":1646218991010,"mc":[{"id":"1.195503856","rc":[{"atl":[[24,1.42]],"id":38247337},{"atl":[[25,1.42]],"id":39832467}],"con":true,"img":false}]}
{"op":"mcm","clk":"5353840980","pt":1646218991904,"mc":[{"id":"1.195503856","rc":[{"atb":[[1.86,0]],"id":39832467},{"atl":[[19.5,0],[20,0]],"id":39832467}],"con":true,"img":false}]}
{"op":"mcm","clk":"5353841158","pt":1646218994085,"mc":[{"id":"1.195503856","rc":[{"atl":[[25,1.42]],"id":38247337},{"atl":[[26,1.42]],"id":39832467}],"con":true,"img":false}]}
{"op":"mcm","clk":"5353841197","pt":1646218994602,"mc":[{"id":"1.195503856","rc":[{"atb":[[1.85,0]],"id":39832467},{"atl":[[21,0]],"id":39832467}],"con":true,"img":false}]}
{"op":"mcm","clk":"5353841316","pt":1646218996320,"mc":[{"id":"1.195503856","rc":[{"atl":[[29,1.42]],"id":38247337},{"atb":[[1.77,1.42]],"id":39832467},{"atl":[[28,1.42]],"id":39832467}],"con":true,"img":false}]}
{"op":"mcm","clk":"5353841347","pt":1646218996697,"mc":[{"id":"1.195503856","rc":[{"atb":[[1.84,0]],"id":39832467},{"atl":[[22,0]],"id":39832467}],"con":true,"img":false}]}
{"op":"mcm","clk":"5353841503","pt":1646218998314,"mc":[{"id":"1.195503856","rc":[{"atl":[[29,2.84]],"id":38247337},{"atb":[[1.77,2.84]],"id":39832467},{"atl":[[28,2.84]],"id":39832467}],"con":true,"img":false}]}
{"op":"mcm","clk":"5353841600","pt":1646218999420,"mc":[{"id":"1.195503856","rc":[{"atl":[[23,0]],"id":38247337},{"atb":[[1.83,0]],"id":39832467},{"atl":[[23,0]],"id":39832467}],"con":true,"img":false}]}
{"op":"mcm","clk":"5353841793","pt":1646219001727,"mc":[{"id":"1.195503856","rc":[{"atl":[[32,1.42]],"id":38247337},{"atb":[[1.76,1.42]],"id":39832467},{"atl":[[32,1.42]],"id":39832467}],"con":true,"img":false}]}
{"op":"mcm","clk":"5353841818","pt":1646219002038,"mc":[{"id":"1.195503856","rc":[{"atl":[[24,0]],"id":38247337},{"atb":[[1.82,0]],"id":39832467},{"atl":[[24,0]],"id":39832467}],"con":true,"img":false}]}
{"op":"mcm","clk":"5353841830","pt":1646219002136,"mc":[{"id":"1.195503856","rc":[{"atl":[[2.58,0],[2.56,10]],"id":39832467}],"con":true,"img":false}]}
{"op":"mcm","clk":"5353841903","pt":1646219002919,"mc":[{"id":"1.195503856","rc":[{"atl":[[2.56,0],[2.52,2]],"id":39832467}],"con":true,"img":false}]}
{"op":"mcm","clk":"5353841920","pt":1646219003124,"mc":[{"id":"1.195503856","rc":[{"atl":[[2.56,10]],"id":39832467}],"con":true,"img":false}]}
{"op":"mcm","clk":"5353841928","pt":1646219003232,"mc":[{"id":"1.195503856","rc":[{"atl":[[2.52,0]],"id":39832467}],"con":true,"img":false}]}
{"op":"mcm","clk":"5353841984","pt":1646219003708,"mc":[{"id":"1.195503856","rc":[{"atl":[[32,2.84]],"id":38247337},{"atb":[[1.76,2.84]],"id":39832467},{"atl":[[32,2.84]],"id":39832467}],"con":true,"img":false}]}
{"op":"mcm","clk":"5353842080","pt":1646219004702,"mc":[{"id":"1.195503856","rc":[{"atl":[[25,0]],"id":38247337},{"atl":[[25,0]],"id":39832467}],"con":true,"img":false}]}
{"op":"mcm","clk":"5353842253","pt":1646219006519,"mc":[{"id":"1.195503856","rc":[{"atl":[[34,1.42]],"id":38247337},{"atl":[[34,1.42]],"id":39832467}],"con":true,"img":false}]}
{"op":"mcm","clk":"5353842298","pt":1646219007039,"mc":[{"id":"1.195503856","rc":[{"atl":[[26,0]],"id":39832467}],"con":true,"img":false}]}
{"op":"mcm","clk":"5353842407","pt":1646219008139,"mc":[{"id":"1.195503856","rc":[{"atl":[[36,1.42]],"id":38247337},{"atl":[[36,1.42]],"id":39832467}],"con":true,"img":false}]}
{"op":"mcm","clk":"5353842416","pt":1646219008243,"mc":[{"id":"1.195503856","rc":[{"atl":[[2.54,10],[2.56,0]],"id":39832467}],"con":true,"img":false}]}
{"op":"mcm","clk":"5353842603","pt":1646219010328,"mc":[{"id":"1.195503856","rc":[{"atl":[[38,1.42]],"id":38247337},{"atl":[[38,1.42]],"id":39832467}],"con":true,"img":false}]}
{"op":"mcm","clk":"5353842717","pt":1646219011531,"mc":[{"id":"1.195503856","rc":[{"atl":[[38,2.84]],"id":38247337},{"atl":[[38,2.84]],"id":39832467}],"con":true,"img":false}]}
{"op":"mcm","clk":"5353842952","pt":1646219014555,"mc":[{"id":"1.195503856","rc":[{"atl":[[40,1.42]],"id":38247337},{"atb":[[1.78,1.42]],"id":39832467}],"con":true,"img":false}]}
{"op":"mcm","clk":"5353843139","pt":1646219017087,"mc":[{"id":"1.195503856","rc":[{"atl":[[32,0],[34,0],[36,0],[38,0],[40,0],[29,0]],"id":38247337}],"con":true,"img":false}]}
{"op":"mcm","clk":"5353843151","pt":1646219017314,"mc":[{"id":"1.195503856","rc":[{"atl":[[2.54,0],[2.52,10]],"id":39832467}],"con":true,"img":false}]}
{"op":"mcm","clk":"5353843187","pt":1646219017842,"mc":[{"id":"1.195503856","rc":[{"atl":[[2.54,10],[2.52,0]],"id":39832467}],"con":true,"img":false}]}
{"op":"mcm","clk":"5353843219","pt":1646219018253,"mc":[{"id":"1.195503856","rc":[{"atl":[[30,1.42]],"id":39832467}],"con":true,"img":false}]}
{"op":"mcm","clk":"5353843391","pt":1646219020651,"mc":[{"id":"1.195503856","rc":[{"atl":[[34,1.42]],"id":38247337}],"con":true,"img":false}]}
{"op":"mcm","clk":"5353843557","pt":1646219022944,"mc":[{"id":"1.195503856","rc":[{"atl":[[2.54,0],[2.52,10]],"id":39832467}],"con":true,"img":false}]}
{"op":"mcm","clk":"5353843563","pt":1646219023051,"mc":[{"id":"1.195503856","rc":[{"atl":[[36,1.42]],"id":38247337}],"con":true,"img":false}]}
{"op":"mcm","clk":"5353843950","pt":1646219028140,"mc":[{"id":"1.195503856","rc":[{"atl":[[2.56,10],[2.52,0]],"id":39832467}],"con":true,"img":false}]}
{"op":"mcm","clk":"5353844042","pt":1646219029650,"mc":[{"id":"1.195503856","rc":[{"atl":[[38,1.42]],"id":38247337},{"atl":[[29,1.42]],"id":39832467}],"con":true,"img":false}]}
{"op":"mcm","clk":"5353844143","pt":1646219031263,"mc":[{"id":"1.195503856","rc":[{"atl":[[40,1.42]],"id":38247337}],"con":true,"img":false}]}
{"op":"mcm","clk":"5353844247","pt":1646219032744,"mc":[{"id":"1.195503856","rc":[{"atl":[[40,2.84]],"id":38247337}],"con":true,"img":false}]}
{"op":"mcm","clk":"5353844691","pt":1646219038865,"mc":[{"id":"1.195503856","rc":[{"atl":[[2.62,10]],"id":39832467}],"con":true,"img":false}]}
{"op":"mcm","clk":"5353844697","pt":1646219038965,"mc":[{"id":"1.195503856","rc":[{"atl":[[2.56,0]],"id":39832467}],"con":true,"img":false}]}
{"op":"mcm","clk":"5353844711","pt":1646219039180,"mc":[{"id":"1.195503856","rc":[{"atl":[[2.6,10],[2.62,0]],"id":39832467}],"con":true,"img":false}]}
{"op":"mcm","clk":"5353844720","pt":1646219039381,"mc":[{"id":"1.195503856","rc":[{"atl":[[2.6,0],[2.58,10]],"id":39832467}],"con":true,"img":false}]}
{"op":"mcm","clk":"5353845057","pt":1646219044456,"mc":[{"id":"1.195503856","rc":[{"atl":[[2.58,0],[2.62,10]],"id":39832467}],"con":true,"img":false}]}
{"op":"mcm","clk":"5353845402","pt":1646219049658,"mc":[{"id":"1.195503856","rc":[{"atl":[[2.62,0],[2.66,10]],"id":39832467}],"con":true,"img":false}]}
{"op":"mcm","clk":"5353845423","pt":1646219049967,"mc":[{"id":"1.195503856","rc":[{"atl":[[2.62,10],[2.66,0]],"id":39832467}],"con":true,"img":false}]}
{"op":"mcm","clk":"5353845804","pt":1646219055082,"mc":[{"id":"1.195503856","rc":[{"atl":[[2.66,10]],"id":39832467}],"con":true,"img":false}]}
{"op":"mcm","clk":"5353845806","pt":1646219055185,"mc":[{"id":"1.195503856","rc":[{"atl":[[2.62,0]],"id":39832467}],"con":true,"img":false}]}
{"op":"mcm","clk":"5353846194","pt":1646219060301,"mc":[{"id":"1.195503856","rc":[{"atl":[[2.76,15],[2.66,0]],"id":39832467}],"con":true,"img":false}]}
{"op":"mcm","clk":"5353846592","pt":1646219064892,"mc":[{"id":"1.195503856","rc":[{"atb":[[1.84,0]],"id":38247337}],"con":true,"img":false}]}
{"op":"mcm","clk":"5353846596","pt":1646219064996,"mc":[{"id":"1.195503856","rc":[{"atb":[[1.81,12.72]],"id":38247337}],"con":true,"img":false}]}
{"op":"mcm","clk":"5353846635","pt":1646219065510,"mc":[{"id":"1.195503856","rc":[{"atl":[[2.76,5],[2.74,10]],"id":39832467}],"con":true,"img":false}]}
{"op":"mcm","clk":"5353846699","pt":1646219066095,"mc":[{"id":"1.195503856","rc":[{"atl":[[2.74,0],[2.78,16]],"id":39832467}],"con":true,"img":false}]}
{"op":"mcm","clk":"5353847119","pt":1646219071301,"mc":[{"id":"1.195503856","rc":[{"atl":[[2.72,10],[2.78,6]],"id":39832467}],"con":true,"img":false}]}
{"op":"mcm","clk":"5353847522","pt":1646219076511,"mc":[{"id":"1.195503856","rc":[{"atl":[[2.72,0],[2.74,10]],"id":39832467}],"con":true,"img":false}]}
{"op":"mcm","clk":"5353848548","pt":1646219081705,"mc":[{"id":"1.195503856","rc":[{"atl":[[2.76,15],[2.74,0]],"id":39832467}],"con":true,"img":false}]}
{"op":"mcm","clk":"5353849258","pt":1646219090096,"mc":[{"id":"1.195503856","rc":[{"atl":[[2.22,0]],"id":38247337}],"con":true,"img":false}]}
{"op":"mcm","clk":"5353849271","pt":1646219090198,"mc":[{"id":"1.195503856","rc":[{"atl":[[2.2,2]],"id":38247337}],"con":true,"img":false}]}
{"op":"mcm","clk":"5353849282","pt":1646219090404,"mc":[{"id":"1.195503856","rc":[{"atl":[[2.76,5],[2.78,8]],"id":39832467}],"con":true,"img":false}]}
{"op":"mcm","clk":"5353850131","pt":1646219101301,"mc":[{"id":"1.195503856","rc":[{"atl":[[2.8,9],[2.78,6]],"id":39832467}],"con":true,"img":false}]}
{"op":"mcm","clk":"5353850628","pt":1646219105526,"mc":[{"id":"1.195503856","rc":[{"atl":[[42,1.42]],"id":38247337}],"con":true,"img":false}]}
{"op":"mcm","clk":"5353850772","pt":1646219106837,"mc":[{"id":"1.195503856","rc":[{"atl":[[42,2.84]],"id":38247337},{"atl":[[2.8,7],[2.78,8]],"id":39832467}],"con":true,"img":false}]}
{"op":"mcm","clk":"5353851350","pt":1646219112033,"mc":[{"id":"1.195503856","rc":[{"atl":[[2.8,9],[2.78,6]],"id":39832467}],"con":true,"img":false}]}
{"op":"mcm","clk":"5353852496","pt":1646219121971,"mc":[{"id":"1.195503856","rc":[{"atb":[[1.56,0],[1.96,0],[1.76,0]],"id":38247337},{"atb":[[1.37,0],[1.57,18],[1.17,0]],"id":39832467}],"con":true,"img":false}]}
{"op":"mcm","clk":"5353852516","pt":1646219122187,"mc":[{"id":"1.195503856","rc":[{"atb":[[1.79,2],[1.81,0]],"id":38247337}],"con":true,"img":false}]}
{"op":"mcm","clk":"5353853018","pt":1646219126572,"mc":[{"id":"1.195503856","rc":[{"atl":[[32,1.42]],"id":38247337}],"con":true,"img":false}]}
{"op":"mcm","clk":"5353853266","pt":1646219128876,"mc":[{"id":"1.195503856","rc":[{"atb":[[1.45,11.99],[1.85,6.34],[1.65,8.3]],"id":38247337},{"atb":[[1.72,7.49],[1.32,16.86],[1.52,10.37]],"id":39832467}],"con":true,"img":false}]}
{"op":"mcm","clk":"5353853303","pt":1646219129245,"mc":[{"id":"1.195503856","rc":[{"atl":[[28,1.42]],"id":38247337},{"atb":[[1.8,1.42]],"id":39832467},{"atl":[[26,1.42]],"id":39832467}],"con":true,"img":false}]}
{"op":"mcm","clk":"5353853614","pt":1646219131755,"mc":[{"id":"1.195503856","rc":[{"atl":[[27,1.42]],"id":38247337},{"atl":[[27,1.42]],"id":39832467}],"con":true,"img":false}]}
{"op":"mcm","clk":"5353853740","pt":1646219132861,"mc":[{"id":"1.195503856","rc":[{"atl":[[27,2.84]],"id":38247337},{"atl":[[27,2.84]],"id":39832467}],"con":true,"img":false}]}
{"op":"mcm","clk":"5353853978","pt":1646219134951,"mc":[{"id":"1.195503856","rc":[{"atl":[[26,1.42]],"id":38247337},{"atb":[[1.82,1.42]],"id":39832467},{"atl":[[25,1.42]],"id":39832467}],"con":true,"img":false}]}
{"op":"mcm","clk":"5353854102","pt":1646219136144,"mc":[{"id":"1.195503856","rc":[{"atl":[[32,0],[34,0],[36,0],[38,0],[40,0],[42,0],[27,0],[28,0]],"id":38247337}],"con":true,"img":false}]}
{"op":"mcm","clk":"5353854188","pt":1646219137177,"mc":[{"id":"1.195503856","rc":[{"atl":[[2.2,0],[2.16,2]],"id":38247337},{"atb":[[1.82,3.42],[1.79,0]],"id":39832467}],"con":true,"img":false}]}
{"op":"mcm","clk":"5353854504","pt":1646219140369,"mc":[{"id":"1.195503856","rc":[{"atb":[[1.79,0]],"id":38247337}],"con":true,"img":false}]}
{"op":"mcm","clk":"5353854514","pt":1646219140471,"mc":[{"id":"1.195503856","rc":[{"atb":[[1.76,2]],"id":38247337}],"con":true,"img":false}]}
{"op":"mcm","clk":"5353854639","pt":1646219141780,"mc":[{"id":"1.195503856","rc":[{"atb":[[1.76,0]],"id":38247337}],"con":true,"img":false}]}
{"op":"mcm","clk":"5353854659","pt":1646219141984,"mc":[{"id":"1.195503856","rc":[{"atb":[[1.73,2]],"id":38247337}],"con":true,"img":false}]}
{"op":"mcm","clk":"5353854760","pt":1646219142878,"mc":[{"id":"1.195503856","rc":[{"atl":[[24,1.42]],"id":38247337},{"atb":[[1.84,1.42]],"id":39832467},{"atl":[[23,1.42]],"id":39832467}],"con":true,"img":false}]}
{"op":"mcm","clk":"5353854981","pt":1646219145281,"mc":[{"id":"1.195503856","rc":[{"atl":[[23,1.42]],"id":38247337},{"atb":[[1.85,1.42]],"id":39832467},{"atl":[[22,1.42]],"id":39832467}],"con":true,"img":false}]}
{"op":"mcm","clk":"5353855291","pt":1646219148279,"mc":[{"id":"1.195503856","rc":[{"atl":[[25,1.42]],"id":38247337},{"atb":[[1.83,1.42]],"id":39832467},{"atl":[[24,1.42]],"id":39832467}],"con":true,"img":false}]}
{"op":"mcm","clk":"5353855688","pt":1646219151995,"mc":[{"id":"1.195503856","rc":[{"atl":[[27,1.42]],"id":38247337}],"con":true,"img":false}]}
{"op":"mcm","clk":"5353855876","pt":1646219153408,"mc":[{"id":"1.195503856","rc":[{"atl":[[2.8,7],[2.78,8]],"id":39832467}],"con":true,"img":false}]}
{"op":"mcm","clk":"5353855981","pt":1646219154196,"mc":[{"id":"1.195503856","rc":[{"atb":[[1.45,0],[1.85,0],[1.65,0]],"id":38247337},{"atb":[[1.72,0],[1.32,0],[1.52,0]],"id":39832467}],"con":true,"img":false}]}
{"op":"mcm","clk":"5353856004","pt":1646219154402,"mc":[{"id":"1.195503856","rc":[{"atl":[[27,2.84]],"id":38247337}],"con":true,"img":false}]}
{"op":"mcm","clk":"5353856270","pt":1646219157392,"mc":[{"id":"1.195503856","rc":[{"atl":[[28,1.42]],"id":38247337}],"con":true,"img":false}]}
{"op":"mcm","clk":"5353856379","pt":1646219158484,"mc":[{"id":"1.195503856","rc":[{"atl":[[2.76,7],[2.78,6]],"id":39832467}],"con":true,"img":false}]}
{"op":"mcm","clk":"5353856425","pt":1646219159008,"mc":[{"id":"1.195503856","rc":[{"atl":[[28,2.84]],"id":38247337}],"con":true,"img":false}]}
{"op":"mcm","clk":"5353857173","pt":1646219165957,"mc":[{"id":"1.195503856","rc":[{"atb":[[1.57,1.42]],"id":38247337},{"atl":[[22,1.42]],"id":38247337},{"atb":[[1.87,1.42]],"id":39832467},{"atl":[[21,1.42]],"id":39832467}],"con":true,"img":false}]}
{"op":"mcm","clk":"5353857196","pt":1646219166119,"mc":[{"id":"1.195503856","rc":[{"atb":[[1.73,0],[1.57,3.42]],"id":38247337}],"con":true,"img":false}]}
{"op":"mcm","clk":"5353857311","pt":1646219167118,"mc":[{"id":"1.195503856","rc":[{"atb":[[1.45,11.99],[1.85,6.34],[1.65,8.3]],"id":38247337},{"atb":[[1.72,7.49],[1.32,16.86],[1.52,10.37]],"id":39832467}],"con":true,"img":false}]}
{"op":"mcm","clk":"5353857519","pt":1646219168939,"mc":[{"id":"1.195503856","rc":[{"atb":[[1.89,1.42]],"id":39832467}],"con":true,"img":false}]}
{"op":"mcm","clk":"5353857552","pt":1646219169209,"mc":[{"id":"1.195503856","rc":[{"atb":[[1.57,2]],"id":38247337},{"atl":[[22,0],[23,0],[24,0],[25,0],[26,0],[27,0],[28,0]],"id":38247337}],"con":true,"img":false}]}
{"op":"mcm","clk":"5353857738","pt":1646219171237,"mc":[{"id":"1.195503856","rc":[{"atb":[[1.88,1.42]],"id":39832467}],"con":true,"img":false}]}
{"op":"mcm","clk":"5353857749","pt":1646219171341,"mc":[{"id":"1.195503856","rc":[{"atb":[[1.57,0],[1.74,2]],"id":38247337}],"con":true,"img":false}]}
{"op":"mcm","clk":"5353858038","pt":1646219174034,"mc":[{"id":"1.195503856","rc":[{"atb":[[1.89,0]],"id":39832467}],"con":true,"img":false}]}
{"op":"mcm","clk":"5353858246","pt":1646219176051,"mc":[{"id":"1.195503856","rc":[{"atl":[[21,1.42]],"id":38247337},{"atb":[[1.89,1.42],[1.88,0]],"id":39832467}],"con":true,"img":false}]}
{"op":"mcm","clk":"5353858382","pt":1646219177517,"mc":[{"id":"1.195503856","rc":[{"atl":[[21,2.84]],"id":38247337},{"atb":[[1.89,2.84]],"id":39832467}],"con":true,"img":false}]}
{"op":"mcm","clk":"5353858809","pt":1646219182751,"mc":[{"id":"1.195503856","rc":[{"atl":[[22,1.42]],"id":38247337},{"atb":[[1.88,1.42]],"id":39832467}],"con":true,"img":false}]}
{"op":"mcm","clk":"5353858960","pt":1646219184324,"mc":[{"id":"1.195503856","rc":[{"atl":[[23,1.42]],"id":38247337}],"con":true,"img":false}]}
{"op":"mcm","clk":"5353859066","pt":1646219185367,"mc":[{"id":"1.195503856","rc":[{"atb":[[1.89,0],[1.78,0],[1.82,2]],"id":39832467}],"con":true,"img":false}]}
{"op":"mcm","clk":"5353859236","pt":1646219187354,"mc":[{"id":"1.195503856","rc":[{"atl":[[24,1.42]],"id":38247337}],"con":true,"img":false}]}
{"op":"mcm","clk":"5353859253","pt":1646219187561,"mc":[{"id":"1.195503856","rc":[{"atb":[[1.88,0]],"id":39832467}],"con":true,"img":false}]}
{"op":"mcm","clk":"5353859359","pt":1646219188869,"mc":[{"id":"1.195503856","rc":[{"atl":[[26,1.42]],"id":38247337}],"con":true,"img":false}]}
{"op":"mcm","clk":"5353859445","pt":1646219189865,"mc":[{"id":"1.195503856","rc":[{"atl":[[21,0]],"id":38247337},{"atl":[[21,0]],"id":39832467}],"con":true,"img":false}]}
{"op":"mcm","clk":"5353859575","pt":1646219191590,"mc":[{"id":"1.195503856","rc":[{"atl":[[2.16,6]],"id":38247337},{"atb":[[1.87,4.26]],"id":39832467},{"atl":[[2.76,21]],"id":39832467}],"con":true,"img":false}]}
{"op":"mcm","clk":"5353859591","pt":1646219191753,"mc":[{"id":"1.195503856","rc":[{"atb":[[1.85,0]],"id":38247337},{"atl":[[1.85,16.22]],"id":38247337},{"trd":[[1.85,12.69]],"ltp":1.85,"tv":12.69,"id":38247337}],"con":true,"img":false}]}
{"op":"mcm","clk":"5353859600","pt":1646219191867,"mc":[{"id":"1.195503856","rc":[{"atl":[[1.85,7.57],[2.16,2]],"id":38247337},{"trd":[[1.85,29.99]],"ltp":1.85,"tv":29.99,"id":38247337},{"atb":[[1.87,1.42]],"id":39832467},{"atl":[[2.76,7]],"id":39832467}],"con":true,"img":false}]}
{"op":"mcm","clk":"5353859618","pt":1646219192075,"mc":[{"id":"1.195503856","rc":[{"atl":[[1.85,0]],"id":38247337},{"trd":[[1.85,45.15]],"ltp":1.85,"tv":45.15,"id":38247337}],"con":true,"img":false}]}
{"op":"mcm","clk":"5353859626","pt":1646219192165,"mc":[{"id":"1.195503856","rc":[{"atl":[[27,1.42]],"id":38247337},{"atb":[[1.87,4.26]],"id":39832467},{"atl":[[2.76,21]],"id":39832467}],"con":true,"img":false}]}
{"op":"mcm","clk":"5353859634","pt":1646219192286,"mc":[{"id":"1.195503856","rc":[{"atb":[[1.74,0],[1.66,2]],"id":38247337}],"con":true,"img":false}]}
{"op":"mcm","clk":"5353859643","pt":1646219192376,"mc":[{"id":"1.195503856","rc":[{"atl":[[2.16,6]],"id":38247337}],"con":true,"img":false}]}
{"op":"mcm","clk":"5353859672","pt":1646219192694,"mc":[{"id":"1.195503856","rc":[{"atb":[[1.66,6]],"id":38247337}],"con":true,"img":false}]}
{"op":"mcm","clk":"5353859702","pt":1646219192966,"mc":[{"id":"1.195503856","rc":[{"atb":[[1.66,2]],"id":38247337}],"con":true,"img":false}]}
{"op":"mcm","clk":"5353859750","pt":1646219193438,"mc":[{"id":"1.195503856","rc":[{"atb":[[1.66,6]],"id":38247337}],"con":true,"img":false}]}
{"op":"mcm","clk":"5353859850","pt":1646219194664,"mc":[{"id":"1.195503856","rc":[{"atb":[[1.7,1.42]],"id":38247337},{"atl":[[25,1.42]],"id":38247337}],"con":true,"img":false}]}
{"op":"mcm","clk":"5353859887","pt":1646219195169,"mc":[{"id":"1.195503856","rc":[{"atb":[[1.83,0],[1.84,0],[1.8,0],[1.81,0],[1.77,0]],"id":39832467}],"con":true,"img":false}]}
{"op":"mcm","clk":"5353860068","pt":1646219197373,"mc":[{"id":"1.195503856","rc":[{"atb":[[1.69,1.42]],"id":38247337},{"atl":[[28,1.42]],"id":38247337}],"con":true,"img":false}]}
{"op":"mcm","clk":"5353860075","pt":1646219197479,"mc":[{"id":"1.195503856","rc":[{"atb":[[1.7,3.42]],"id":38247337}],"con":true,"img":false}]}
{"op":"mcm","clk":"5353860089","pt":1646219197691,"mc":[{"id":"1.195503856","rc":[{"atb":[[1.7,1.42],[1.66,4],[1.69,3.42]],"id":38247337}],"con":true,"img":false}]}
{"op":"mcm","clk":"5353860123","pt":1646219198064,"mc":[{"id":"1.195503856","rc":[{"atb":[[1.7,0]],"id":38247337}],"con":true,"img":false}]}
{"op":"mcm","clk":"5353860151","pt":1646219198370,"mc":[{"id":"1.195503856","rc":[{"atb":[[1.66,0]],"id":38247337}],"con":true,"img":false}]}
{"op":"mcm","clk":"5353860187","pt":1646219198786,"mc":[{"id":"1.195503856","rc":[{"atb":[[1.69,10.26]],"id":38247337}],"con":true,"img":false}]}
{"op":"mcm","clk":"5353860344","pt":1646219200361,"mc":[{"id":"1.195503856","rc":[{"atb":[[1.75,1.42]],"id":38247337},{"atb":[[1.89,1.42]],"id":39832467}],"con":true,"img":false}]}
{"op":"mcm","clk":"5353860362","pt":1646219200574,"mc":[{"id":"1.195503856","rc":[{"atb":[[1.69,3.42]],"id":38247337}],"con":true,"img":false}]}
{"op":"mcm","clk":"5353860373","pt":1646219200674,"mc":[{"id":"1.195503856","rc":[{"atb":[[1.87,1.42]],"id":39832467}],"con":true,"img":false}]}
{"op":"mcm","clk":"5353860383","pt":1646219200777,"mc":[{"id":"1.195503856","rc":[{"atb":[[1.89,4.26]],"id":39832467}],"con":true,"img":false}]}
{"op":"mcm","clk":"5353860455","pt":1646219201674,"mc":[{"id":"1.195503856","rc":[{"atb":[[1.75,2.84]],"id":38247337},{"atb":[[1.89,5.68]],"id":39832467}],"con":true,"img":false}]}
{"op":"mcm","clk":"5353860563","pt":1646219202675,"mc":[{"id":"1.195503856","rc":[{"atb":[[1.75,1.42]],"id":38247337},{"atb":[[1.85,0]],"id":39832467}],"con":true,"img":false}]}
{"op":"mcm","clk":"5353860581","pt":1646219202892,"mc":[{"id":"1.195503856","rc":[{"atb":[[1.74,2],[1.69,1.42]],"id":38247337}],"con":true,"img":false}]}
{"op":"mcm","clk":"5353860780","pt":1646219205090,"mc":[{"id":"1.195503856","rc":[{"atb":[[1.71,1.42]],"id":38247337},{"atl":[[21,1.42]],"id":38247337},{"atb":[[1.91,1.42]],"id":39832467},{"atl":[[21,1.42]],"id":39832467}],"con":true,"img":false}]}
{"op":"mcm","clk":"5353860810","pt":1646219205398,"mc":[{"id":"1.195503856","rc":[{"atb":[[1.89,2.84]],"id":39832467}],"con":true,"img":false}]}
{"op":"mcm","clk":"5353860823","pt":1646219205456,"mc":[{"id":"1.195503856","rc":[{"atb":[[1.91,4.26]],"id":39832467}],"con":true,"img":false}]}
{"op":"mcm","clk":"5353861107","pt":1646219208575,"mc":[{"id":"1.195503856","rc":[{"atb":[[1.73,1.42]],"id":38247337},{"atl":[[20,1.42]],"id":38247337},{"atb":[[1.94,1.42]],"id":39832467},{"atl":[[19.5,1.42]],"id":39832467}],"con":true,"img":false}]}
{"op":"mcm","clk":"5353861154","pt":1646219208990,"mc":[{"id":"1.195503856","rc":[{"atb":[[1.91,1.42]],"id":39832467}],"con":true,"img":false}]}
{"op":"mcm","clk":"5353861173","pt":1646219209092,"mc":[{"id":"1.195503856","rc":[{"atb":[[1.94,4.26]],"id":39832467}],"con":true,"img":false}]}
{"op":"mcm","clk":"5353861383","pt":1646219211284,"mc":[{"id":"1.195503856","rc":[{"atb":[[1.72,1.42]],"id":38247337},{"atl":[[19.5,1.42]],"id":38247337},{"atb":[[1.95,1.42]],"id":39832467},{"atl":[[19,1.42]],"id":39832467}],"con":true,"img":false}]}
{"op":"mcm","clk":"5353861409","pt":1646219211599,"mc":[{"id":"1.195503856","rc":[{"atb":[[1.94,1.42]],"id":39832467}],"con":true,"img":false}]}
{"op":"mcm","clk":"5353861419","pt":1646219211701,"mc":[{"id":"1.195503856","rc":[{"atb":[[1.95,4.26]],"id":39832467}],"con":true,"img":false}]}
{"op":"mcm","clk":"5353861521","pt":1646219212709,"mc":[{"id":"1.195503856","rc":[{"atb":[[1.7,1.42]],"id":38247337},{"atb":[[1.93,1.42]],"id":39832467},{"atl":[[20,1.42]],"id":39832467}],"con":true,"img":false}]}
{"op":"mcm","clk":"5353861577","pt":1646219213283,"mc":[{"id":"1.195503856","rc":[{"atb":[[1.95,2.84]],"id":39832467}],"con":true,"img":false}]}
{"op":"mcm","clk":"5353861622","pt":1646219213703,"mc":[{"id":"1.195503856","rc":[{"atb":[[1.95,0]],"id":39832467}],"con":true,"img":false}]}
{"op":"mcm","clk":"5353861652","pt":1646219213969,"mc":[{"id":"1.195503856","rc":[{"atb":[[1.94,4.26]],"id":39832467}],"con":true,"img":false}]}
{"op":"mcm","clk":"5353861663","pt":1646219214070,"mc":[{"id":"1.195503856","rc":[{"atb":[[1.7,2.84]],"id":38247337},{"atb":[[1.96,1.42]],"id":39832467},{"atl":[[18.5,1.42]],"id":39832467}],"con":true,"img":false}]}
{"op":"mcm","clk":"5353861693","pt":1646219214493,"mc":[{"id":"1.195503856","rc":[{"atb":[[1.94,1.42]],"id":39832467}],"con":true,"img":false}]}
{"op":"mcm","clk":"5353861703","pt":1646219214586,"mc":[{"id":"1.195503856","rc":[{"atb":[[1.96,4.26]],"id":39832467}],"con":true,"img":false}]}
{"op":"mcm","clk":"5353861771","pt":1646219215379,"mc":[{"id":"1.195503856","rc":[{"atb":[[1.94,0]],"id":39832467}],"con":true,"img":false}]}
{"op":"mcm","clk":"5353861851","pt":1646219216413,"mc":[{"id":"1.195503856","rc":[{"atl":[[19,1.42]],"id":38247337},{"atb":[[1.95,1.42]],"id":39832467},{"atl":[[18.5,2.84]],"id":39832467}],"con":true,"img":false}]}
{"op":"mcm","clk":"5353862056","pt":1646219218566,"mc":[{"id":"1.195503856","rc":[{"atb":[[1.76,1.42]],"id":38247337},{"atb":[[1.94,1.42]],"id":39832467}],"con":true,"img":false}]}
{"op":"mcm","clk":"5353862138","pt":1646219219601,"mc":[{"id":"1.195503856","rc":[{"atl":[[19,0],[19.5,0],[20,0],[21,0],[22,0],[23,0],[24,0],[25,0],[26,0],[27,0],[28,0]],"id":38247337}],"con":true,"img":false}]}
{"op":"mcm","clk":"5353862386","pt":1646219222373,"mc":[{"id":"1.195503856","rc":[{"atb":[[1.76,0]],"id":38247337},{"atb":[[1.87,0]],"id":39832467}],"con":true,"img":false}]}
{"op":"mcm","clk":"5353862588","pt":1646219224510,"mc":[{"id":"1.195503856","rc":[{"atl":[[21,1.42]],"id":38247337}],"con":true,"img":false}]}
{"op":"mcm","clk":"5353862612","pt":1646219224775,"mc":[{"id":"1.195503856","rc":[{"atb":[[1.91,0]],"id":39832467}],"con":true,"img":false}]}
{"op":"mcm","clk":"5353862704","pt":1646219226024,"mc":[{"id":"1.195503856","rc":[{"atl":[[22,1.42]],"id":38247337}],"con":true,"img":false}]}
{"op":"mcm","clk":"5353862790","pt":1646219226817,"mc":[{"id":"1.195503856","rc":[{"atb":[[1.94,0]],"id":39832467}],"con":true,"img":false}]}
{"op":"mcm","clk":"5353862975","pt":1646219228805,"mc":[{"id":"1.195503856","rc":[{"atl":[[23,1.42]],"id":38247337}],"con":true,"img":false}]}
{"op":"mcm","clk":"5353863037","pt":1646219229534,"mc":[{"id":"1.195503856","rc":[{"atb":[[1.95,0],[1.93,0]],"id":39832467}],"con":true,"img":false}]}
{"op":"mcm","clk":"5353863079","pt":1646219230010,"mc":[{"id":"1.195503856","rc":[{"atl":[[2.16,2]],"id":38247337},{"atb":[[1.96,1.42]],"id":39832467},{"atl":[[2.76,7]],"id":39832467}],"con":true,"img":false}]}
{"op":"mcm","clk":"5353863102","pt":1646219230211,"mc":[{"id":"1.195503856","rc":[{"atl":[[2.8,9],[2.76,5]],"id":39832467}],"con":true,"img":false}]}
{"op":"mcm","clk":"5353863140","pt":1646219230734,"mc":[{"id":"1.195503856","rc":[{"atl":[[2.16,6]],"id":38247337},{"atb":[[1.96,4.26]],"id":39832467},{"atl":[[2.76,15]],"id":39832467}],"con":true,"img":false}]}
{"op":"mcm","clk":"5353863214","pt":1646219231518,"mc":[{"id":"1.195503856","rc":[{"atl":[[24,1.42]],"id":38247337}],"con":true,"img":false}]}
{"op":"mcm","clk":"5353863310","pt":1646219232509,"mc":[{"id":"1.195503856","rc":[{"atb":[[1.73,0],[1.72,0],[1.7,0],[1.71,0],[1.69,0]],"id":38247337},{"atb":[[1.96,2.84]],"id":39832467},{"atl":[[18.5,0]],"id":39832467}],"con":true,"img":false}]}
{"op":"mcm","clk":"5353863362","pt":1646219232930,"mc":[{"id":"1.195503856","rc":[{"atb":[[1.96,0]],"id":39832467}],"con":true,"img":false}]}
{"op":"mcm","clk":"5353863400","pt":1646219233201,"mc":[{"id":"1.195503856","rc":[{"atb":[[1.89,8.52]],"id":39832467}],"con":true,"img":false}]}
{"op":"mcm","clk":"5353863491","pt":1646219234501,"mc":[{"id":"1.195503856","rc":[{"atl":[[25,1.42]],"id":38247337}],"con":true,"img":false}]}
{"op":"mcm","clk":"5353863547","pt":1646219235330,"mc":[{"id":"1.195503856","rc":[{"atl":[[2.74,2],[2.8,7]],"id":39832467}],"con":true,"img":false}]}
{"op":"mcm","clk":"5353863578","pt":1646219235696,"mc":[{"id":"1.195503856","rc":[{"atl":[[2.76,5]],"id":39832467}],"con":true,"img":false}]}
{"op":"mcm","clk":"5353863583","pt":1646219235800,"mc":[{"id":"1.195503856","rc":[{"atl":[[2.74,12]],"id":39832467}],"con":true,"img":false}]}
{"op":"mcm","clk":"5353863601","pt":1646219236114,"mc":[{"id":"1.195503856","rc":[{"atl":[[2.74,6]],"id":39832467}],"con":true,"img":false}]}
{"op":"mcm","clk":"5353863615","pt":1646219236322,"mc":[{"id":"1.195503856","rc":[{"atb":[[1.68,1.42]],"id":38247337},{"atl":[[25,2.84]],"id":38247337},{"atb":[[1.94,1.42]],"id":39832467}],"con":true,"img":false}]}
{"op":"mcm","clk":"5353863799","pt":1646219238410,"mc":[{"id":"1.195503856","rc":[{"atl":[[2.2,2],[2.16,4]],"id":38247337}],"con":true,"img":false}]}
{"op":"mcm","clk":"5353863807","pt":1646219238516,"mc":[{"id":"1.195503856","rc":[{"atl":[[26,1.42]],"id":38247337},{"atb":[[1.94,2.84]],"id":39832467}],"con":true,"img":false}]}
{"op":"mcm","clk":"5353863825","pt":1646219238725,"mc":[{"id":"1.195503856","rc":[{"atl":[[2.16,0]],"id":38247337}],"con":true,"img":false}]}
{"op":"mcm","clk":"5353863853","pt":1646219239035,"mc":[{"id":"1.195503856","rc":[{"atl":[[2.2,6]],"id":38247337}],"con":true,"img":false}]}
{"op":"mcm","clk":"5353863898","pt":1646219239621,"mc":[{"id":"1.195503856","rc":[{"atb":[[1.68,0]],"id":38247337},{"atb":[[1.94,1.42]],"id":39832467}],"con":true,"img":false}]}
{"op":"mcm","clk":"5353863988","pt":1646219240837,"mc":[{"id":"1.195503856","rc":[{"atb":[[1.45,0],[1.65,0]],"id":38247337},{"atb":[[1.72,0],[1.32,0],[1.52,0]],"id":39832467}],"con":true,"img":false}]}
{"op":"mcm","clk":"5353864054","pt":1646219241628,"mc":[{"id":"1.195503856","rc":[{"atl":[[26,2.84]],"id":38247337},{"atb":[[1.91,1.42]],"id":39832467}],"con":true,"img":false}]}
{"op":"mcm","clk":"5353864150","pt":1646219242533,"mc":[{"id":"1.195503856","rc":[{"atb":[[1.94,0]],"id":39832467}],"con":true,"img":false}]}
{"op":"mcm","clk":"5353864197","pt":1646219242947,"mc":[{"id":"1.195503856","rc":[{"atb":[[1.89,2.84]],"id":39832467}],"con":true,"img":false}]}
{"op":"mcm","clk":"5353864210","pt":1646219243013,"mc":[{"id":"1.195503856","rc":[{"atb":[[1.91,7.1]],"id":39832467}],"con":true,"img":false}]}
{"op":"mcm","clk":"5353864348","pt":1646219244432,"mc":[{"id":"1.195503856","rc":[{"atb":[[1.2,2],[1.01,118],[1.45,2],[1.09,2],[1.39,2],[1.34,60],[1.63,2],[1.27,2],[1.57,2],[1.67,22],[1.54,2],[1.5,43],[1.13,84],[1.65,2],[1.61,31],[1.05,2]],"id":38247337}],"con":true,"img":false}]}
{"op":"mcm","clk":"5353864424","pt":1646219245119,"mc":[{"id":"1.195503856","rc":[{"atb":[[1.9,1.42]],"id":39832467}],"con":true,"img":false}]}
{"op":"mcm","clk":"5353864601","pt":1646219247164,"mc":[{"id":"1.195503856","rc":[{"atb":[[1.6,8.99],[1.4,13.48],[1.8,6.74]],"id":38247337},{"atb":[[1.6,8.99],[1.4,13.48],[1.8,6.74]],"id":39832467}],"con":true,"img":false}]}
{"op":"mcm","clk":"5353864618","pt":1646219247322,"mc":[{"id":"1.195503856","rc":[{"atb":[[1.76,2],[1.74,0]],"id":38247337}],"con":true,"img":false}]}
{"op":"mcm","clk":"5353864630","pt":1646219247425,"mc":[{"id":"1.195503856","rc":[{"atb":[[1.92,1.42]],"id":39832467}],"con":true,"img":false}]}
{"op":"mcm","clk":"5353864675","pt":1646219247839,"mc":[{"id":"1.195503856","rc":[{"atb":[[1.91,1.42]],"id":39832467}],"con":true,"img":false}]}
{"op":"mcm","clk":"5353864685","pt":1646219247944,"mc":[{"id":"1.195503856","rc":[{"atb":[[1.92,7.1]],"id":39832467}],"con":true,"img":false}]}
{"op":"mcm","clk":"5353864738","pt":1646219248527,"mc":[{"id":"1.195503856","rc":[{"atb":[[1.89,0]],"id":39832467},{"atl":[[32,0],[34,0],[36,0],[38,0],[19,0],[19.5,0],[20,0],[21,0],[22,0],[23,0],[24,0],[25,0],[26,0],[27,0],[28,0],[29,0],[30,0]],"id":39832467}],"con":true,"img":false}]}
{"op":"mcm","clk":"5353864776","pt":1646219249149,"mc":[{"id":"1.195503856","rc":[{"atl":[[2.2,2]],"id":38247337},{"atb":[[1.92,1.42]],"id":39832467},{"atl":[[2.74,2]],"id":39832467}],"con":true,"img":false}]}
{"op":"mcm","clk":"5353864790","pt":1646219249358,"mc":[{"id":"1.195503856","rc":[{"atl":[[2.74,0],[2.78,8]],"id":39832467}],"con":true,"img":false}]}
{"op":"mcm","clk":"5353864860","pt":1646219250042,"mc":[{"id":"1.195503856","rc":[{"atl":[[2.2,6]],"id":38247337},{"atb":[[1.92,4.26]],"id":39832467},{"atl":[[2.76,15]],"id":39832467}],"con":true,"img":false}]}
{"op":"mcm","clk":"5353864878","pt":1646219250248,"mc":[{"id":"1.195503856","rc":[{"atb":[[1.78,1.42]],"id":38247337},{"atl":[[2.4,1.42]],"id":39832467}],"con":true,"img":false}]}
{"op":"mcm","clk":"5353864978","pt":1646219251254,"mc":[{"id":"1.195503856","rc":[{"atb":[[1.92,2.84]],"id":39832467}],"con":true,"img":false}]}
{"op":"mcm","clk":"5353865010","pt":1646219251629,"mc":[{"id":"1.195503856","rc":[{"atb":[[1.92,0]],"id":39832467}],"con":true,"img":false}]}
{"op":"mcm","clk":"5353865043","pt":1646219252046,"mc":[{"id":"1.195503856","rc":[{"atb":[[1.91,4.26]],"id":39832467}],"con":true,"img":false}]}
{"op":"mcm","clk":"5353865110","pt":1646219252840,"mc":[{"id":"1.195503856","rc":[{"atb":[[1.4,61.48],[1.92,2],[1.81,2],[1.88,17],[1.9,3.42],[1.77,24],[1.66,2],[1.31,2],[1.61,34],[1.84,2],[1.23,2],[1.14,67],[1.94,12],[1.72,2],[1.54,26],[1.47,2]],"id":39832467}],"con":true,"img":false}]}
{"op":"mcm","clk":"5353865137","pt":1646219253149,"mc":[{"id":"1.195503856","rc":[{"atb":[[1.91,1.42]],"id":39832467}],"con":true,"img":false}]}
{"op":"mcm","clk":"5353865153","pt":1646219253357,"mc":[{"id":"1.195503856","rc":[{"atb":[[1.85,1.42]],"id":38247337},{"atb":[[1.89,1.42]],"id":39832467},{"atl":[[2.24,1.42]],"id":39832467}],"con":true,"img":false}]}
{"op":"mcm","clk":"5353865158","pt":1646219253460,"mc":[{"id":"1.195503856","rc":[{"atb":[[1.91,0]],"id":39832467}],"con":true,"img":false}]}
{"op":"mcm","clk":"5353865165","pt":1646219253522,"mc":[{"id":"1.195503856","rc":[{"atb":[[1.94,31.03]],"id":39832467}],"con":true,"img":false}]}
{"op":"mcm","clk":"5353865182","pt":1646219253729,"mc":[{"id":"1.195503856","rc":[{"atb":[[1.89,34.18]],"id":39832467}],"con":true,"img":false}]}
{"op":"mcm","clk":"5353865211","pt":1646219254245,"mc":[{"id":"1.195503856","rc":[{"atb":[[1.89,1.42]],"id":39832467}],"con":true,"img":false}]}
{"op":"mcm","clk":"5353865228","pt":1646219254554,"mc":[{"id":"1.195503856","rc":[{"atl":[[2.28,2],[2.78,6]],"id":39832467}],"con":true,"img":false}]}
{"op":"mcm","clk":"5353865284","pt":1646219255239,"mc":[{"id":"1.195503856","rc":[{"atb":[[1.93,31.34]],"id":39832467}],"con":true,"img":false}]}
{"op":"mcm","clk":"5353865322","pt":1646219255860,"mc":[{"id":"1.195503856","rc":[{"atb":[[1.82,1.42]],"id":38247337},{"atl":[[2,1.42]],"id":38247337},{"atb":[[2,1.42]],"id":39832467},{"atl":[[2.22,1.42]],"id":39832467}],"con":true,"img":false}]}
{"op":"mcm","clk":"5353865338","pt":1646219256034,"mc":[{"id":"1.195503856","rc":[{"atb":[[1.85,0]],"id":38247337},{"atl":[[21,0],[22,0],[23,0],[24,0],[25,0],[26,0]],"id":38247337},{"atb":[[1.9,2]],"id":39832467}],"con":true,"img":false}]}
{"op":"mcm","clk":"5353865353","pt":1646219256232,"mc":[{"id":"1.195503856","rc":[{"atb":[[1.68,42.87]],"id":38247337},{"atb":[[1.95,30.68]],"id":39832467}],"con":true,"img":false}]}
{"op":"mcm","clk":"5353865407","pt":1646219256959,"mc":[{"id":"1.195503856","rc":[{"atb":[[1.82,2.84]],"id":38247337},{"atl":[[2,2.84]],"id":38247337},{"atb":[[2,2.84]],"id":39832467},{"atl":[[2.22,2.84]],"id":39832467}],"con":true,"img":false}]}
{"op":"mcm","clk":"5353865511","pt":1646219258272,"mc":[{"id":"1.195503856","rc":[{"atb":[[1.77,2],[1.76,0]],"id":38247337}],"con":true,"img":false}]}
{"op":"mcm","clk":"5353865524","pt":1646219258422,"mc":[{"id":"1.195503856","rc":[{"atl":[[2,1.42]],"id":38247337},{"atb":[[2,1.42]],"id":39832467},{"atl":[[2.22,1.42]],"id":39832467}],"con":true,"img":false}]}
{"op":"mcm","clk":"5353865628","pt":1646219259747,"mc":[{"id":"1.195503856","rc":[{"atl":[[2.28,0],[2.26,2]],"id":39832467}],"con":true,"img":false}]}
{"op":"mcm","clk":"5353865704","pt":1646219260571,"mc":[{"id":"1.195503856","rc":[{"atb":[[1.83,1.42]],"id":38247337},{"atl":[[1.95,1.42]],"id":38247337},{"atb":[[1.99,1.42]],"id":39832467},{"atl":[[2.16,1.42]],"id":39832467}],"con":true,"img":false}]}
{"op":"mcm","clk":"5353865746","pt":1646219261054,"mc":[{"id":"1.195503856","rc":[{"atl":[[2,0]],"id":38247337},{"atb":[[2,0]],"id":39832467},{"atl":[[2.22,0]],"id":39832467}],"con":true,"img":false}]}
{"op":"mcm","clk":"5353865756","pt":1646219261162,"mc":[{"id":"1.195503856","rc":[{"atb":[[1.68,0]],"id":38247337},{"atb":[[1.95,0],[1.93,0]],"id":39832467}],"con":true,"img":false}]}
{"op":"mcm","clk":"5353865918","pt":1646219263096,"mc":[{"id":"1.195503856","rc":[{"atb":[[1.81,1.42]],"id":38247337},{"atl":[[1.98,1.42]],"id":38247337},{"atb":[[1.98,1.42]],"id":39832467},{"atl":[[2.28,1.42]],"id":39832467}],"con":true,"img":false}]}
{"op":"mcm","clk":"5353865945","pt":1646219263351,"mc":[{"id":"1.195503856","rc":[{"atb":[[1.78,3.42],[1.77,0]],"id":38247337}],"con":true,"img":false}]}
{"op":"mcm","clk":"5353865962","pt":1646219263572,"mc":[{"id":"1.195503856","rc":[{"atb":[[1.78,2],[1.75,0]],"id":38247337},{"atl":[[1.95,0]],"id":38247337},{"atb":[[1.89,0],[1.76,0]],"id":39832467},{"atl":[[2.4,0],[2.16,0]],"id":39832467}],"con":true,"img":false}]}
{"op":"mcm","clk":"5353865979","pt":1646219263781,"mc":[{"id":"1.195503856","rc":[{"atb":[[1.68,42.87]],"id":38247337},{"atb":[[1.95,30.68]],"id":39832467}],"con":true,"img":false}]}
{"op":"mcm","clk":"5353866072","pt":1646219264888,"mc":[{"id":"1.195503856","rc":[{"atl":[[2.2,2]],"id":38247337},{"atb":[[1.94,12]],"id":39832467}],"con":true,"img":false}]}
{"op":"mcm","clk":"5353866079","pt":1646219264974,"mc":[{"id":"1.195503856","rc":[{"atb":[[1.81,2.84]],"id":38247337},{"atl":[[1.98,5.42]],"id":38247337},{"atb":[[1.99,20.45],[1.97,1.42]],"id":39832467}],"con":true,"img":false}]}
{"op":"mcm","clk":"5353866114","pt":1646219265388,"mc":[{"id":"1.195503856","rc":[{"atb":[[1.99,4.26]],"id":39832467}],"con":true,"img":false}]}
{"op":"mcm","clk":"5353866151","pt":1646219265775,"mc":[{"id":"1.195503856","rc":[{"atb":[[1.68,0]],"id":38247337},{"atb":[[1.95,0]],"id":39832467}],"con":true,"img":false}]}
{"op":"mcm","clk":"5353866196","pt":1646219266282,"mc":[{"id":"1.195503856","rc":[{"atb":[[1.89,32.75]],"id":39832467}],"con":true,"img":false}]}
{"op":"mcm","clk":"5353866224","pt":1646219266596,"mc":[{"id":"1.195503856","rc":[{"atb":[[1.83,0]],"id":38247337},{"atl":[[1.98,4]],"id":38247337},{"atl":[[2.28,0]],"id":39832467}],"con":true,"img":false}]}
{"op":"mcm","clk":"5353866265","pt":1646219266982,"mc":[{"id":"1.195503856","rc":[{"atl":[[1.98,0]],"id":38247337}],"con":true,"img":false}]}
{"op":"mcm","clk":"5353866308","pt":1646219267387,"mc":[{"id":"1.195503856","rc":[{"atl":[[2.2,6]],"id":38247337}],"con":true,"img":false}]}
{"op":"mcm","clk":"5353866339","pt":1646219267698,"mc":[{"id":"1.195503856","rc":[{"atl":[[2.2,2]],"id":38247337}],"con":true,"img":false}]}
{"op":"mcm","clk":"5353866367","pt":1646219267969,"mc":[{"id":"1.195503856","rc":[{"atl":[[2.2,6]],"id":38247337}],"con":true,"img":false}]}
{"op":"mcm","clk":"5353866440","pt":1646219268753,"mc":[{"id":"1.195503856","rc":[{"atl":[[1.97,1.42]],"id":38247337},{"atb":[[1.96,1.42]],"id":39832467},{"atl":[[2.2,1.42]],"id":39832467}],"con":true,"img":false}]}
{"op":"mcm","clk":"5353866510","pt":1646219269588,"mc":[{"id":"1.195503856","rc":[{"atb":[[1.82,0]],"id":38247337}],"con":true,"img":false}]}
{"op":"mcm","clk":"5353866598","pt":1646219270686,"mc":[{"id":"1.195503856","rc":[{"atb":[[1.78,0],[1.77,2]],"id":38247337}],"con":true,"img":false}]}
{"op":"mcm","clk":"5353866681","pt":1646219271785,"mc":[{"id":"1.195503856","rc":[{"atb":[[1.95,1.42]],"id":39832467}],"con":true,"img":false}]}
{"op":"mcm","clk":"5353866712","pt":1646219272104,"mc":[{"id":"1.195503856","rc":[{"atl":[[1.97,0]],"id":38247337},{"atl":[[2.24,0]],"id":39832467}],"con":true,"img":false}]}
{"op":"mcm","clk":"5353866724","pt":1646219272211,"mc":[{"id":"1.195503856","rc":[{"atb":[[1.89,0]],"id":39832467}],"con":true,"img":false}]}
{"op":"mcm","clk":"5353866836","pt":1646219273390,"mc":[{"id":"1.195503856","rc":[{"atb":[[1.6,0],[1.4,0],[1.8,0]],"id":38247337},{"atb":[[1.4,48],[1.6,0],[1.8,0]],"id":39832467}],"con":true,"img":false}]}
{"op":"mcm","clk":"5353866858","pt":1646219273706,"mc":[{"id":"1.195503856","rc":[{"atb":[[1.89,32.75]],"id":39832467}],"con":true,"img":false}]}
{"op":"mcm","clk":"5353867041","pt":1646219275694,"mc":[{"id":"1.195503856","rc":[{"atl":[[2.28,2],[2.26,0]],"id":39832467}],"con":true,"img":false}]}
{"op":"mcm","clk":"5353867048","pt":1646219275799,"mc":[{"id":"1.195503856","rc":[{"atb":[[1.76,2]],"id":38247337}],"con":true,"img":false}]}
{"op":"mcm","clk":"5353867059","pt":1646219275903,"mc":[{"id":"1.195503856","rc":[{"atb":[[1.77,0]],"id":38247337}],"con":true,"img":false}]}
{"op":"mcm","clk":"5353867111","pt":1646219276687,"mc":[{"id":"1.195503856","rc":[{"atb":[[1.81,0]],"id":38247337}],"con":true,"img":false}]}
{"op":"mcm","clk":"5353867220","pt":1646219277989,"mc":[{"id":"1.195503856","rc":[{"atb":[[1.7,1.42]],"id":38247337},{"atl":[[2.48,1.42]],"id":39832467}],"con":true,"img":false}]}
{"op":"mcm","clk":"5353867310","pt":1646219278997,"mc":[{"id":"1.195503856","rc":[{"atl":[[2.2,0]],"id":39832467}],"con":true,"img":false}]}
{"op":"mcm","clk":"5353867474","pt":1646219280777,"mc":[{"id":"1.195503856","rc":[{"atl":[[2.28,0],[2.48,3.42]],"id":39832467}],"con":true,"img":false}]}
{"op":"mcm","clk":"5353867484","pt":1646219280881,"mc":[{"id":"1.195503856","rc":[{"atb":[[1.7,3.42],[1.76,0]],"id":38247337}],"con":true,"img":false}]}
{"op":"mcm","clk":"5353867496","pt":1646219281092,"mc":[{"id":"1.195503856","rc":[{"atl":[[2.76,5]],"id":39832467}],"con":true,"img":false}]}
{"op":"mcm","clk":"5353867502","pt":1646219281197,"mc":[{"id":"1.195503856","rc":[{"atl":[[2.48,13.42]],"id":39832467}],"con":true,"img":false}]}
{"op":"mcm","clk":"5353867512","pt":1646219281298,"mc":[{"id":"1.195503856","rc":[{"atb":[[1.7,10.26]],"id":38247337}],"con":true,"img":false}]}
{"op":"mcm","clk":"5353867519","pt":1646219281398,"mc":[{"id":"1.195503856","rc":[{"atb":[[1.69,1.42]],"id":38247337}],"con":true,"img":false}]}
{"op":"mcm","clk":"5353867685","pt":1646219283299,"mc":[{"id":"1.195503856","rc":[{"atb":[[1.7,10.13]],"id":38247337},{"trd":[[1.7,0.26]],"ltp":1.7,"tv":0.26,"id":38247337}],"con":true,"img":false}]}
{"op":"mcm","clk":"5353867810","pt":1646219284911,"mc":[{"id":"1.195503856","rc":[{"atb":[[1.74,1.42]],"id":38247337},{"atb":[[1.93,1.42]],"id":39832467},{"atl":[[2.38,1.42]],"id":39832467}],"con":true,"img":false}]}
{"op":"mcm","clk":"5353867843","pt":1646219285118,"mc":[{"id":"1.195503856","rc":[{"atb":[[1.7,8.13],[1.74,3.42]],"id":38247337},{"atl":[[2.38,3.42],[2.48,11.42]],"id":39832467}],"con":true,"img":false}]}
{"op":"mcm","clk":"5353867853","pt":1646219285225,"mc":[{"id":"1.195503856","rc":[{"atb":[[1.89,0]],"id":39832467}],"con":true,"img":false}]}
{"op":"mcm","clk":"5353867882","pt":1646219285493,"mc":[{"id":"1.195503856","rc":[{"atb":[[1.6,8.99],[1.4,13.48],[1.8,6.74]],"id":38247337},{"atb":[[1.4,61.48],[1.6,8.99],[1.8,6.74]],"id":39832467}],"con":true,"img":false}]}
{"op":"mcm","clk":"5353867963","pt":1646219286230,"mc":[{"id":"1.195503856","rc":[{"atb":[[1.89,32.75]],"id":39832467}],"con":true,"img":false}]}
{"op":"mcm","clk":"5353868002","pt":1646219286702,"mc":[{"id":"1.195503856","rc":[{"atb":[[1.89,0]],"id":39832467}],"con":true,"img":false}]}
{"op":"mcm","clk":"5353868037","pt":1646219287220,"mc":[{"id":"1.195503856","rc":[{"atb":[[1.89,32.75]],"id":39832467}],"con":true,"img":false}]}
{"op":"mcm","clk":"5353868080","pt":1646219287707,"mc":[{"id":"1.195503856","rc":[{"atb":[[1.89,0]],"id":39832467}],"con":true,"img":false}]}
{"op":"mcm","clk":"5353868133","pt":1646219288215,"mc":[{"id":"1.195503856","rc":[{"atb":[[1.89,32.75]],"id":39832467}],"con":true,"img":false}]}
{"op":"mcm","clk":"5353868172","pt":1646219288693,"mc":[{"id":"1.195503856","rc":[{"atb":[[1.89,0]],"id":39832467}],"con":true,"img":false}]}
{"op":"mcm","clk":"5353868180","pt":1646219288799,"mc":[{"id":"1.195503856","rc":[{"atb":[[1.81,1.42]],"id":38247337},{"atl":[[2.34,1.42]],"id":39832467}],"con":true,"img":false}]}
{"op":"mcm","clk":"5353868198","pt":1646219289010,"mc":[{"id":"1.195503856","rc":[{"atb":[[1.93,0]],"id":39832467}],"con":true,"img":false}]}
{"op":"mcm","clk":"5353868214","pt":1646219289228,"mc":[{"id":"1.195503856","rc":[{"atb":[[1.89,32.75]],"id":39832467}],"con":true,"img":false}]}
{"op":"mcm","clk":"5353868277","pt":1646219289906,"mc":[{"id":"1.195503856","rc":[{"atb":[[1.81,2.84]],"id":38247337},{"atl":[[2.34,2.84]],"id":39832467}],"con":true,"img":false}]}
{"op":"mcm","clk":"5353868296","pt":1646219290222,"mc":[{"id":"1.195503856","rc":[{"atb":[[1.76,2],[1.74,1.42]],"id":38247337},{"atl":[[2.34,4.84]],"id":39832467}],"con":true,"img":false}]}
{"op":"mcm","clk":"5353868303","pt":1646219290322,"mc":[{"id":"1.195503856","rc":[{"atl":[[2.38,1.42]],"id":39832467}],"con":true,"img":false}]}
{"op":"mcm","clk":"5353868362","pt":1646219291005,"mc":[{"id":"1.195503856","rc":[{"atb":[[1.77,2],[1.76,0]],"id":38247337}],"con":true,"img":false}]}
{"op":"mcm","clk":"5353868497","pt":1646219292421,"mc":[{"id":"1.195503856","rc":[{"atb":[[1.82,1.42]],"id":38247337},{"atl":[[2,1.42]],"id":38247337},{"atb":[[1.93,1.42]],"id":39832467},{"atl":[[2.42,1.42]],"id":39832467}],"con":true,"img":false}]}
{"op":"mcm","clk":"5353868521","pt":1646219292723,"mc":[{"id":"1.195503856","rc":[{"atb":[[1.89,0]],"id":39832467}],"con":true,"img":false}]}
{"op":"mcm","clk":"5353868720","pt":1646219294821,"mc":[{"id":"1.195503856","rc":[{"atb":[[1.76,1.42]],"id":38247337},{"atl":[[2,2.84]],"id":38247337},{"atb":[[1.93,2.84]],"id":39832467},{"atl":[[2.42,2.84]],"id":39832467}],"con":true,"img":false}]}
{"op":"mcm","clk":"5353868760","pt":1646219295237,"mc":[{"id":"1.195503856","rc":[{"atb":[[1.91,32.03]],"id":39832467}],"con":true,"img":false}]}
{"op":"mcm","clk":"5353868806","pt":1646219295714,"mc":[{"id":"1.195503856","rc":[{"atb":[[1.91,0]],"id":39832467}],"con":true,"img":false}]}
{"op":"mcm","clk":"5353868823","pt":1646219295922,"mc":[{"id":"1.195503856","rc":[{"atb":[[1.82,0]],"id":38247337},{"atb":[[1.93,1.42]],"id":39832467}],"con":true,"img":false}]}
{"op":"mcm","clk":"5353868854","pt":1646219296229,"mc":[{"id":"1.195503856","rc":[{"atb":[[1.77,0],[1.79,2]],"id":38247337}],"con":true,"img":false}]}
{"op":"mcm","clk":"5353868902","pt":1646219296812,"mc":[{"id":"1.195503856","rc":[{"atl":[[2.48,1.42]],"id":39832467}],"con":true,"img":false}]}
{"op":"mcm","clk":"5353868911","pt":1646219296919,"mc":[{"id":"1.195503856","rc":[{"atl":[[2.34,14.84]],"id":39832467}],"con":true,"img":false}]}
{"op":"mcm","clk":"5353868973","pt":1646219297430,"mc":[{"id":"1.195503856","rc":[{"atb":[[1.75,1.42]],"id":38247337}],"con":true,"img":false}]}
{"op":"mcm","clk":"5353869050","pt":1646219298221,"mc":[{"id":"1.195503856","rc":[{"atl":[[2.2,2]],"id":38247337}],"con":true,"img":false}]}
{"op":"mcm","clk":"5353869089","pt":1646219298632,"mc":[{"id":"1.195503856","rc":[{"atl":[[2,8.52]],"id":38247337}],"con":true,"img":false}]}
{"op":"mcm","clk":"5353869108","pt":1646219298842,"mc":[{"id":"1.195503856","rc":[{"atb":[[1.93,0]],"id":39832467},{"atl":[[2.42,0]],"id":39832467}],"con":true,"img":false}]}
{"op":"mcm","clk":"5353869160","pt":1646219299211,"mc":[{"id":"1.195503856","rc":[{"atb":[[1.71,41.06]],"id":38247337},{"atb":[[1.95,32.1]],"id":39832467}],"con":true,"img":false}]}
{"op":"mcm","clk":"5353869287","pt":1646219300834,"mc":[{"id":"1.195503856","rc":[{"atb":[[1.78,2],[1.79,0]],"id":38247337}],"con":true,"img":false}]}
{"op":"mcm","clk":"5353869295","pt":1646219300940,"mc":[{"id":"1.195503856","rc":[{"atb":[[1.78,3.42]],"id":38247337},{"atl":[[2.22,1.42]],"id":39832467}],"con":true,"img":false}]}
{"op":"mcm","clk":"5353869315","pt":1646219301108,"mc":[{"id":"1.195503856","rc":[{"atl":[[2.26,2],[2.34,12.84]],"id":39832467}],"con":true,"img":false}]}
{"op":"mcm","clk":"5353869364","pt":1646219301730,"mc":[{"id":"1.195503856","rc":[{"atb":[[1.71,0]],"id":38247337}],"con":true,"img":false}]}
{"op":"mcm","clk":"5353869381","pt":1646219301939,"mc":[{"id":"1.195503856","rc":[{"atl":[[2.48,0]],"id":39832467}],"con":true,"img":false}]}
{"op":"mcm","clk":"5353869406","pt":1646219302208,"mc":[{"id":"1.195503856","rc":[{"atb":[[1.75,40.29]],"id":38247337}],"con":true,"img":false}]}
{"op":"mcm","clk":"5353869421","pt":1646219302316,"mc":[{"id":"1.195503856","rc":[{"atl":[[1.82,1.24]],"id":38247337}],"con":true,"img":false}]}
{"op":"mcm","clk":"5353869430","pt":1646219302424,"mc":[{"id":"1.195503856","rc":[{"atl":[[1.82,0]],"id":38247337},{"trd":[[1.82,2.49]],"ltp":1.82,"tv":2.49,"id":38247337}],"con":true,"img":false}]}
{"op":"mcm","clk":"5353869459","pt":1646219302836,"mc":[{"id":"1.195503856","rc":[{"atb":[[1.7,1.29]],"id":38247337},{"atl":[[2,2.84]],"id":38247337},{"atb":[[1.99,1.42]],"id":39832467},{"atl":[[2.34,2.84]],"id":39832467}],"con":true,"img":false}]}
{"op":"mcm","clk":"5353869485","pt":1646219303152,"mc":[{"id":"1.195503856","rc":[{"atb":[[1.78,4.84]],"id":38247337},{"atl":[[1.97,1.42]],"id":38247337},{"atl":[[2.2,1.42]],"id":39832467}],"con":true,"img":false}]}
{"op":"mcm","clk":"5353869510","pt":1646219303362,"mc":[{"id":"1.195503856","rc":[{"atl":[[2,8.52]],"id":38247337},{"atb":[[1.99,4.26]],"id":39832467}],"con":true,"img":false}]}
{"op":"mcm","clk":"5353869544","pt":1646219303734,"mc":[{"id":"1.195503856","rc":[{"atb":[[1.75,1.42]],"id":38247337},{"atl":[[2,2.84]],"id":38247337},{"atb":[[1.95,1.42]],"id":39832467}],"con":true,"img":false}]}
{"op":"mcm","clk":"5353869559","pt":1646219303836,"mc":[{"id":"1.195503856","rc":[{"atl":[[1.97,7.1]],"id":38247337}],"con":true,"img":false}]}
{"op":"mcm","clk":"5353869616","pt":1646219304463,"mc":[{"id":"1.195503856","rc":[{"atl":[[2.38,0]],"id":39832467}],"con":true,"img":false}]}
{"op":"mcm","clk":"5353869927","pt":1646219307958,"mc":[{"id":"1.195503856","rc":[{"atb":[[1.78,2],[1.74,0],[1.76,0],[1.75,0]],"id":38247337},{"atb":[[1.95,0],[1.98,0],[1.97,0]],"id":39832467},{"atl":[[2.22,0],[2.2,0],[2.34,0]],"id":39832467}],"con":true,"img":false}]}
{"op":"mcm","clk":"5353869942","pt":1646219308168,"mc":[{"id":"1.195503856","rc":[{"atl":[[2.6,2],[2.26,0]],"id":39832467}],"con":true,"img":false}]}
{"op":"mcm","clk":"5353869949","pt":1646219308275,"mc":[{"id":"1.195503856","rc":[{"atb":[[1.91,32.03]],"id":39832467}],"con":true,"img":false}]}
{"op":"mcm","clk":"5353869976","pt":1646219308640,"mc":[{"id":"1.195503856","rc":[{"atl":[[2.6,6]],"id":39832467}],"con":true,"img":false}]}
{"op":"mcm","clk":"5353870017","pt":1646219309058,"mc":[{"id":"1.195503856","rc":[{"atl":[[2.6,2]],"id":39832467}],"con":true,"img":false}]}
{"op":"mcm","clk":"5353870057","pt":1646219309577,"mc":[{"id":"1.195503856","rc":[{"atl":[[2.6,6]],"id":39832467}],"con":true,"img":false}]}
{"op":"mcm","clk":"5353870084","pt":1646219309845,"mc":[{"id":"1.195503856","rc":[{"atb":[[2.04,1.42]],"id":39832467}],"con":true,"img":false}]}
{"op":"mcm","clk":"5353870116","pt":1646219310154,"mc":[{"id":"1.195503856","rc":[{"atb":[[1.99,1.42]],"id":39832467}],"con":true,"img":false}]}
{"op":"mcm","clk":"5353870124","pt":1646219310256,"mc":[{"id":"1.195503856","rc":[{"atb":[[1.93,31.34],[2.04,4.26]],"id":39832467}],"con":true,"img":false}]}
{"op":"mcm","clk":"5353870354","pt":1646219312946,"mc":[{"id":"1.195503856","rc":[{"atl":[[2.04,1.42]],"id":38247337},{"atb":[[2.06,1.42]],"id":39832467},{"atl":[[2.48,1.42]],"id":39832467}],"con":true,"img":false}]}
{"op":"mcm","clk":"5353870378","pt":1646219313261,"mc":[{"id":"1.195503856","rc":[{"atb":[[1.95,30.68],[2.04,1.42]],"id":39832467},{"atl":[[2.6,4],[2.48,3.42]],"id":39832467}],"con":true,"img":false}]}
{"op":"mcm","clk":"5353870386","pt":1646219313368,"mc":[{"id":"1.195503856","rc":[{"atb":[[2.06,4.26]],"id":39832467}],"con":true,"img":false}]}
{"op":"mcm","clk":"5353870462","pt":1646219314263,"mc":[{"id":"1.195503856","rc":[{"atl":[[2.04,2.84]],"id":38247337},{"atb":[[2.06,5.68]],"id":39832467},{"atl":[[2.48,4.84]],"id":39832467}],"con":true,"img":false}]}
{"op":"mcm","clk":"5353870512","pt":1646219314749,"mc":[{"id":"1.195503856","rc":[{"atb":[[1.68,42.87]],"id":38247337}],"con":true,"img":false}]}
{"op":"mcm","clk":"5353870523","pt":1646219314878,"mc":[{"id":"1.195503856","rc":[{"atb":[[1.78,0],[1.76,2]],"id":38247337}],"con":true,"img":false}]}
{"op":"mcm","clk":"5353870722","pt":1646219317263,"mc":[{"id":"1.195503856","rc":[{"atl":[[1.93,1.42]],"id":38247337},{"atb":[[1.98,1.42]],"id":39832467},{"atl":[[2.46,1.42]],"id":39832467}],"con":true,"img":false}]}
{"op":"mcm","clk":"5353870744","pt":1646219317576,"mc":[{"id":"1.195503856","rc":[{"atl":[[1.97,1.42]],"id":38247337}],"con":true,"img":false}]}
{"op":"mcm","clk":"5353870753","pt":1646219317679,"mc":[{"id":"1.195503856","rc":[{"atl":[[1.93,7.1]],"id":38247337}],"con":true,"img":false}]}
{"op":"mcm","clk":"5353870779","pt":1646219317946,"mc":[{"id":"1.195503856","rc":[{"atl":[[1.93,1.42]],"id":38247337}],"con":true,"img":false}]}
{"op":"mcm","clk":"5353870855","pt":1646219318887,"mc":[{"id":"1.195503856","rc":[{"atb":[[1.72,1.42]],"id":38247337},{"atl":[[1.93,2.84]],"id":38247337},{"atb":[[1.98,2.84]],"id":39832467},{"atl":[[2.42,1.42]],"id":39832467}],"con":true,"img":false}]}
{"op":"mcm","clk":"5353870873","pt":1646219319054,"mc":[{"id":"1.195503856","rc":[{"atl":[[2.42,3.42],[2.48,2.84]],"id":39832467}],"con":true,"img":false}]}
{"op":"mcm","clk":"5353870926","pt":1646219319674,"mc":[{"id":"1.195503856","rc":[{"atl":[[1.93,8.52]],"id":38247337}],"con":true,"img":false}]}
{"op":"mcm","clk":"5353870991","pt":1646219320269,"mc":[{"id":"1.195503856","rc":[{"atb":[[1.77,2],[1.76,0]],"id":38247337}],"con":true,"img":false}]}
{"op":"mcm","clk":"5353871101","pt":1646219321363,"mc":[{"id":"1.195503856","rc":[{"atb":[[1.71,1.42]],"id":38247337},{"atb":[[1.97,1.42]],"id":39832467},{"atl":[[2.42,4.84]],"id":39832467}],"con":true,"img":false}]}
{"op":"mcm","clk":"5353871138","pt":1646219321781,"mc":[{"id":"1.195503856","rc":[{"atb":[[1.91,0]],"id":39832467}],"con":true,"img":false}]}
{"op":"mcm","clk":"5353871225","pt":1646219322463,"mc":[{"id":"1.195503856","rc":[{"atl":[[2.6,0]],"id":39832467}],"con":true,"img":false}]}
{"op":"mcm","clk":"5353871272","pt":1646219322979,"mc":[{"id":"1.195503856","rc":[{"atl":[[2.42,13.37]],"id":39832467}],"con":true,"img":false}]}
{"op":"mcm","clk":"5353871297","pt":1646219323293,"mc":[{"id":"1.195503856","rc":[{"atb":[[1.68,0]],"id":38247337},{"atb":[[1.97,31.47]],"id":39832467}],"con":true,"img":false}]}
{"op":"mcm","clk":"5353871432","pt":1646219324755,"mc":[{"id":"1.195503856","rc":[{"atl":[[2.44,1.42]],"id":39832467}],"con":true,"img":false}]}
{"op":"mcm","clk":"5353871461","pt":1646219325063,"mc":[{"id":"1.195503856","rc":[{"atb":[[1.69,0]],"id":38247337},{"atl":[[2.48,0]],"id":39832467}],"con":true,"img":false}]}
{"op":"mcm","clk":"5353871479","pt":1646219325273,"mc":[{"id":"1.195503856","rc":[{"atb":[[1.69,42.24]],"id":38247337}],"con":true,"img":false}]}
{"op":"mcm","clk":"5353871513","pt":1646219325802,"mc":[{"id":"1.195503856","rc":[{"atb":[[1.69,0]],"id":38247337}],"con":true,"img":false}]}
{"op":"mcm","clk":"5353871586","pt":1646219326273,"mc":[{"id":"1.195503856","rc":[{"atb":[[1.68,42.87]],"id":38247337}],"con":true,"img":false}]}
{"op":"mcm","clk":"5353871639","pt":1646219326796,"mc":[{"id":"1.195503856","rc":[{"atb":[[1.68,0]],"id":38247337},{"atb":[[1.95,0],[1.93,0],[1.97,1.42]],"id":39832467}],"con":true,"img":false}]}
{"op":"mcm","clk":"5353871682","pt":1646219327165,"mc":[{"id":"1.195503856","rc":[{"atl":[[1.98,1.42]],"id":38247337}],"con":true,"img":false}]}
{"op":"mcm","clk":"5353871690","pt":1646219327277,"mc":[{"id":"1.195503856","rc":[{"atb":[[1.97,31.47]],"id":39832467}],"con":true,"img":false}]}
{"op":"mcm","clk":"5353871704","pt":1646219327377,"mc":[{"id":"1.195503856","rc":[{"atl":[[2.44,0]],"id":39832467}],"con":true,"img":false}]}
{"op":"mcm","clk":"5353871821","pt":1646219328597,"mc":[{"id":"1.195503856","rc":[{"atl":[[1.99,1.42]],"id":38247337}],"con":true,"img":false}]}
{"op":"mcm","clk":"5353871883","pt":1646219329277,"mc":[{"id":"1.195503856","rc":[{"atb":[[1.68,42.87]],"id":38247337}],"con":true,"img":false}]}
{"op":"mcm","clk":"5353871890","pt":1646219329391,"mc":[{"id":"1.195503856","rc":[{"atl":[[2,0],[1.98,0],[1.97,0],[2.04,0]],"id":38247337},{"atb":[[1.96,0]],"id":39832467},{"atl":[[2.46,0]],"id":39832467}],"con":true,"img":false}]}
{"op":"mcm","clk":"5353871934","pt":1646219329804,"mc":[{"id":"1.195503856","rc":[{"atb":[[1.68,0]],"id":38247337},{"atb":[[1.97,1.42]],"id":39832467}],"con":true,"img":false}]}
{"op":"mcm","clk":"5353871957","pt":1646219329971,"mc":[{"id":"1.195503856","rc":[{"atl":[[1000,1.69]],"id":39832467}],"con":true,"img":false}]}
{"op":"mcm","clk":"5353871970","pt":1646219330070,"mc":[{"id":"1.195503856","rc":[{"atl":[[1000,1.75]],"id":38247337},{"atl":[[1000,0.02]],"id":39832467}],"con":true,"img":false}]}
{"op":"mcm","clk":"5353871991","pt":1646219330276,"mc":[{"id":"1.195503856","rc":[{"atl":[[1000,0.09]],"id":38247337},{"atb":[[1.95,30.68]],"id":39832467},{"atl":[[1000,0]],"id":39832467}],"con":true,"img":false}]}
{"op":"mcm","clk":"5353872001","pt":1646219330381,"mc":[{"id":"1.195503856","rc":[{"atl":[[2.16,0.02]],"id":39832467}],"con":true,"img":false}]}
{"op":"mcm","clk":"5353872012","pt":1646219330487,"mc":[{"id":"1.195503856","rc":[{"atl":[[1000,0]],"id":38247337},{"atl":[[2.16,0]],"id":39832467},{"trd":[[2.16,0.04]],"ltp":2.16,"tv":0.04,"id":39832467}],"con":true,"img":false}]}
{"op":"mcm","clk":"5353872018","pt":1646219330591,"mc":[{"id":"1.195503856","rc":[{"atl":[[1.86,0.09]],"id":38247337}],"con":true,"img":false}]}
{"op":"mcm","clk":"5353872035","pt":1646219330800,"mc":[{"id":"1.195503856","rc":[{"atl":[[1.86,0]],"id":38247337},{"trd":[[1.86,0.18]],"ltp":1.86,"tv":0.18,"id":38247337}],"con":true,"img":false}]}
{"op":"mcm","clk":"5353872127","pt":1646219331793,"mc":[{"id":"1.195503856","rc":[{"atl":[[1.99,0]],"id":38247337},{"atb":[[1.99,0],[1.98,0],[2.04,0],[1.97,0]],"id":39832467}],"con":true,"img":false}]}
{"op":"mcm","clk":"5353872158","pt":1646219332112,"mc":[{"id":"1.195503856","rc":[{"atl":[[1.93,2.84]],"id":38247337},{"atb":[[2.06,2.84]],"id":39832467},{"atl":[[2.42,4.84]],"id":39832467}],"con":true,"img":false}]}
{"op":"mcm","clk":"5353872177","pt":1646219332284,"mc":[{"id":"1.195503856","rc":[{"atb":[[1.95,0],[1.91,32.03]],"id":39832467}],"con":true,"img":false}]}
{"op":"mcm","clk":"5353872184","pt":1646219332383,"mc":[{"id":"1.195503856","rc":[{"atb":[[1.6,0],[1.4,0],[1.8,0]],"id":38247337},{"atb":[[1.4,48],[1.6,0],[1.8,0]],"id":39832467}],"con":true,"img":false}]}
{"op":"mcm","clk":"5353872203","pt":1646219332595,"mc":[{"id":"1.195503856","rc":[{"atl":[[1.93,8.52]],"id":38247337},{"atb":[[2.06,8.52]],"id":39832467},{"atl":[[2.42,13.07]],"id":39832467}],"con":true,"img":false}]}
{"op":"mcm","clk":"5353872224","pt":1646219332809,"mc":[{"id":"1.195503856","rc":[{"atb":[[1.91,0]],"id":39832467}],"con":true,"img":false}]}
{"op":"mcm","clk":"5353872292","pt":1646219333281,"mc":[{"id":"1.195503856","rc":[{"atb":[[1.93,31.34]],"id":39832467}],"con":true,"img":false}]}
{"op":"mcm","clk":"5353872374","pt":1646219334015,"mc":[{"id":"1.195503856","rc":[{"atb":[[1.95,1.42]],"id":39832467}],"con":true,"img":false}]}
{"op":"mcm","clk":"5353872392","pt":1646219334177,"mc":[{"id":"1.195503856","rc":[{"atb":[[1.81,0]],"id":38247337}],"con":true,"img":false}]}
{"op":"mcm","clk":"5353872398","pt":1646219334276,"mc":[{"id":"1.195503856","rc":[{"atb":[[1.68,42.87],[1.72,3.42],[1.77,0]],"id":38247337},{"atb":[[1.95,32.1]],"id":39832467}],"con":true,"img":false}]}
{"op":"mcm","clk":"5353872438","pt":1646219334696,"mc":[{"id":"1.195503856","rc":[{"atb":[[1.72,10.26]],"id":38247337}],"con":true,"img":false}]}
{"op":"mcm","clk":"5353872489","pt":1646219335325,"mc":[{"id":"1.195503856","rc":[{"atb":[[1.68,0]],"id":38247337}],"con":true,"img":false}]}
{"op":"mcm","clk":"5353872517","pt":1646219335591,"mc":[{"id":"1.195503856","rc":[{"atl":[[1.93,2.84]],"id":38247337}],"con":true,"img":false}]}
{"op":"mcm","clk":"5353872581","pt":1646219336222,"mc":[{"id":"1.195503856","rc":[{"atb":[[1.72,8.84]],"id":38247337}],"con":true,"img":false}]}
{"op":"mcm","clk":"5353872591","pt":1646219336274,"mc":[{"id":"1.195503856","rc":[{"atb":[[1.95,1.42],[1.93,0],[1.89,32.75]],"id":39832467}],"con":true,"img":false}]}
{"op":"mcm","clk":"5353872690","pt":1646219337385,"mc":[{"id":"1.195503856","rc":[{"atl":[[1.93,8.52]],"id":38247337}],"con":true,"img":false}]}
{"op":"mcm","clk":"5353872725","pt":1646219337793,"mc":[{"id":"1.195503856","rc":[{"atb":[[1.68,42.87]],"id":38247337},{"atb":[[1.95,32.1]],"id":39832467}],"con":true,"img":false}]}
{"op":"mcm","clk":"5353872841","pt":1646219339220,"mc":[{"id":"1.195503856","rc":[{"atl":[[1.93,2.84]],"id":38247337}],"con":true,"img":false}]}
{"op":"mcm","clk":"5353872897","pt":1646219339802,"mc":[{"id":"1.195503856","rc":[{"atb":[[1.68,0]],"id":38247337},{"atb":[[1.95,1.42]],"id":39832467}],"con":true,"img":false}]}
{"op":"mcm","clk":"5353872950","pt":1646219340338,"mc":[{"id":"1.195503856","rc":[{"atb":[[1.73,1.42]],"id":38247337},{"atl":[[2.38,1.42]],"id":39832467}],"con":true,"img":false}]}
{"op":"mcm","clk":"5353872971","pt":1646219340550,"mc":[{"id":"1.195503856","rc":[{"atl":[[2.42,11.07],[2.38,3.42]],"id":39832467}],"con":true,"img":false}]}
{"op":"mcm","clk":"5353872982","pt":1646219340606,"mc":[{"id":"1.195503856","rc":[{"atb":[[1.72,2]],"id":38247337},{"atl":[[2.42,2.84]],"id":39832467}],"con":true,"img":false}]}
{"op":"mcm","clk":"5353872991","pt":1646219340709,"mc":[{"id":"1.195503856","rc":[{"atb":[[1.73,8.26]],"id":38247337},{"atl":[[2.38,11.65]],"id":39832467}],"con":true,"img":false}]}
{"op":"mcm","clk":"5353873014","pt":1646219340921,"mc":[{"id":"1.195503856","rc":[{"atb":[[1.72,0],[1.74,2]],"id":38247337}],"con":true,"img":false}]}
{"op":"mcm","clk":"5353873037","pt":1646219341128,"mc":[{"id":"1.195503856","rc":[{"atb":[[1.73,4.26]],"id":38247337}],"con":true,"img":false}]}
{"op":"mcm","clk":"5353873086","pt":1646219341602,"mc":[{"id":"1.195503856","rc":[{"atb":[[1.73,1.42]],"id":38247337}],"con":true,"img":false}]}
{"op":"mcm","clk":"5353873128","pt":1646219342020,"mc":[{"id":"1.195503856","rc":[{"atb":[[1.74,6]],"id":38247337}],"con":true,"img":false}]}
{"op":"mcm","clk":"5353873209","pt":1646219342805,"mc":[{"id":"1.195503856","rc":[{"atl":[[1.93,8.52]],"id":38247337}],"con":true,"img":false}]}
{"op":"mcm","clk":"5353873228","pt":1646219343018,"mc":[{"id":"1.195503856","rc":[{"atb":[[1.73,0]],"id":38247337},{"atb":[[2.06,5.68]],"id":39832467},{"atl":[[2.38,10.23]],"id":39832467}],"con":true,"img":false}]}
{"op":"mcm","clk":"5353873252","pt":1646219343332,"mc":[{"id":"1.195503856","rc":[{"atb":[[1.91,32.03],[2.06,0]],"id":39832467},{"atl":[[2.38,6]],"id":39832467}],"con":true,"img":false}]}
{"op":"mcm","clk":"5353873260","pt":1646219343393,"mc":[{"id":"1.195503856","rc":[{"atb":[[1.95,7.1]],"id":39832467}],"con":true,"img":false}]}
{"op":"mcm","clk":"5353873368","pt":1646219344603,"mc":[{"id":"1.195503856","rc":[{"atb":[[1.03,2.87]],"id":38247337}],"con":true,"img":false}]}
{"op":"mcm","clk":"5353873384","pt":1646219344812,"mc":[{"id":"1.195503856","rc":[{"atb":[[1.03,0.14]],"id":38247337}],"con":true,"img":false}]}
{"op":"mcm","clk":"5353873399","pt":1646219345023,"mc":[{"id":"1.195503856","rc":[{"atb":[[1.03,0]],"id":38247337}],"con":true,"img":false}]}
{"op":"mcm","clk":"5353873410","pt":1646219345128,"mc":[{"id":"1.195503856","rc":[{"atl":[[1.93,8.37]],"id":38247337},{"trd":[[1.93,0.29]],"ltp":1.93,"tv":0.29,"id":38247337}],"con":true,"img":false}]}
{"op":"mcm","clk":"5353873440","pt":1646219345341,"mc":[{"id":"1.195503856","rc":[{"atb":[[1.7,0],[1.71,0]],"id":38247337},{"atl":[[1.93,5.68]],"id":38247337},{"atb":[[1.95,5.68]],"id":39832467},{"atl":[[2.42,0]],"id":39832467}],"con":true,"img":false}]}
{"op":"mcm","clk":"5353873484","pt":1646219345708,"mc":[{"id":"1.195503856","rc":[{"atl":[[1.93,0]],"id":38247337},{"atb":[[1.95,0],[1.91,0]],"id":39832467}],"con":true,"img":false}]}
{"op":"mcm","clk":"5353873519","pt":1646219346127,"mc":[{"id":"1.195503856","rc":[{"atl":[[2.2,6]],"id":38247337},{"atb":[[1.94,28.33]],"id":39832467}],"con":true,"img":false}]}
{"op":"mcm","clk":"5353873573","pt":1646219346822,"mc":[{"id":"1.195503856","rc":[{"atb":[[1.6,8.99],[1.4,13.48],[1.8,6.74]],"id":38247337},{"atb":[[1.4,61.48],[1.91,32.03],[1.6,8.99],[1.89,0],[1.8,6.74]],"id":39832467}],"con":true,"img":false}]}
{"op":"mcm","clk":"5353873589","pt":1646219347027,"mc":[{"id":"1.195503856","rc":[{"atb":[[1.79,2],[1.74,4]],"id":38247337}],"con":true,"img":false}]}
{"op":"mcm","clk":"5353873609","pt":1646219347236,"mc":[{"id":"1.195503856","rc":[{"atb":[[1.8,8.74],[1.79,0]],"id":38247337}],"con":true,"img":false}]}
{"op":"mcm","clk":"5353873883","pt":1646219350336,"mc":[{"id":"1.195503856","rc":[{"atb":[[1.74,0]],"id":38247337},{"atl":[[2.2,2]],"id":38247337},{"atb":[[1.94,12]],"id":39832467},{"atl":[[2.38,2]],"id":39832467}],"con":true,"img":false}]}
{"op":"mcm","clk":"5353873905","pt":1646219350548,"mc":[{"id":"1.195503856","rc":[{"atl":[[2.38,0],[2.78,19]],"id":39832467}],"con":true,"img":false}]}
{"op":"mcm","clk":"5353873922","pt":1646219350713,"mc":[{"id":"1.195503856","rc":[{"atb":[[1.91,0]],"id":39832467}],"con":true,"img":false}]}
{"op":"mcm","clk":"5353873931","pt":1646219350819,"mc":[{"id":"1.195503856","rc":[{"atb":[[1.89,32.75]],"id":39832467}],"con":true,"img":false}]}
{"op":"mcm","clk":"5353873980","pt":1646219351342,"mc":[{"id":"1.195503856","rc":[{"atl":[[2.2,6]],"id":38247337},{"atb":[[1.94,27.78]],"id":39832467},{"atl":[[2.76,15]],"id":39832467}],"con":true,"img":false}]}
{"op":"mcm","clk":"5353874023","pt":1646219351712,"mc":[{"id":"1.195503856","rc":[{"atb":[[1.91,32.03],[1.89,0]],"id":39832467}],"con":true,"img":false}]}
{"op":"mcm","clk":"5353874092","pt":1646219352342,"mc":[{"id":"1.195503856","rc":[{"atb":[[1.8,6.74],[1.79,2]],"id":38247337}],"con":true,"img":false}]}
{"op":"mcm","clk":"5353874328","pt":1646219354837,"mc":[{"id":"1.195503856","rc":[{"atb":[[1.03,2.87]],"id":39832467}],"con":true,"img":false}]}
{"op":"mcm","clk":"5353874349","pt":1646219355042,"mc":[{"id":"1.195503856","rc":[{"atb":[[1.03,0.14]],"id":39832467}],"con":true,"img":false}]}
{"op":"mcm","clk":"5353874367","pt":1646219355252,"mc":[{"id":"1.195503856","rc":[{"atb":[[1.03,0]],"id":39832467}],"con":true,"img":false}]}
{"op":"mcm","clk":"5353874373","pt":1646219355356,"mc":[{"id":"1.195503856","rc":[{"atb":[[1.8,6.56]],"id":38247337},{"trd":[[1.8,0.18]],"ltp":1.8,"tv":0.18,"id":38247337},{"trd":[[2.26,0.14]],"ltp":2.26,"tv":0.14,"id":39832467}],"con":true,"img":false}]}
{"op":"mcm","clk":"5353874410","pt":1646219355727,"mc":[{"id":"1.195503856","rc":[{"atl":[[2.74,2],[2.78,6]],"id":39832467}],"con":true,"img":false}]}
{"op":"mcm","clk":"5353874443","pt":1646219356041,"mc":[{"id":"1.195503856","rc":[{"atl":[[2.76,5]],"id":39832467}],"con":true,"img":false}]}
{"op":"mcm","clk":"5353874459","pt":1646219356146,"mc":[{"id":"1.195503856","rc":[{"atl":[[2.74,12]],"id":39832467}],"con":true,"img":false}]}
{"op":"mcm","clk":"5353874491","pt":1646219356416,"mc":[{"id":"1.195503856","rc":[{"atl":[[2.74,6]],"id":39832467}],"con":true,"img":false}]}
{"op":"mcm","clk":"5353874845","pt":1646219360243,"mc":[{"id":"1.195503856","rc":[{"atb":[[1.79,37]],"id":38247337}],"con":true,"img":false}]}
{"op":"mcm","clk":"5353874892","pt":1646219360767,"mc":[{"id":"1.195503856","rc":[{"atb":[[1.72,2],[1.79,0]],"id":38247337},{"atb":[[1.82,0]],"id":39832467}],"con":true,"img":false}]}
{"op":"mcm","clk":"5353874900","pt":1646219360831,"mc":[{"id":"1.195503856","rc":[{"atb":[[1.8,43]],"id":38247337},{"atl":[[2.2,4],[2.1,2]],"id":38247337},{"atb":[[1.93,2]],"id":39832467}],"con":true,"img":false}]}
{"op":"mcm","clk":"5353874949","pt":1646219361247,"mc":[{"id":"1.195503856","rc":[{"atb":[[1.8,6.56]],"id":38247337}],"con":true,"img":false}]}
{"op":"mcm","clk":"5353874997","pt":1646219361725,"mc":[{"id":"1.195503856","rc":[{"atl":[[2.3,2],[2.22,38],[2.26,2],[2.34,2],[2.24,2],[2.36,86],[2.4,2],[2.42,2],[2.28,57],[2.46,129],[2.18,25]],"id":38247337},{"atb":[[1.93,33.34]],"id":39832467}],"con":true,"img":false}]}
{"op":"mcm","clk":"5353875051","pt":1646219362255,"mc":[{"id":"1.195503856","rc":[{"atb":[[1.93,2],[1.91,0]],"id":39832467}],"con":true,"img":false}]}
{"op":"mcm","clk":"5353875106","pt":1646219362728,"mc":[{"id":"1.195503856","rc":[{"atb":[[1.93,33.34]],"id":39832467}],"con":true,"img":false}]}
{"op":"mcm","clk":"5353875652","pt":1646219368569,"mc":[{"id":"1.195503856","rc":[{"atb":[[1.95,2.96]],"id":39832467}],"con":true,"img":false}]}
{"op":"mcm","clk":"5353875675","pt":1646219368832,"mc":[{"id":"1.195503856","rc":[{"atb":[[1.94,12]],"id":39832467}],"con":true,"img":false}]}
{"op":"mcm","clk":"5353875681","pt":1646219368938,"mc":[{"id":"1.195503856","rc":[{"atb":[[1.95,18.74]],"id":39832467}],"con":true,"img":false}]}
{"op":"mcm","clk":"5353875718","pt":1646219369253,"mc":[{"id":"1.195503856","rc":[{"atb":[[1.95,8.9]],"id":39832467}],"con":true,"img":false}]}
{"op":"mcm","clk":"5353875764","pt":1646219369767,"mc":[{"id":"1.195503856","rc":[{"atb":[[1.89,32.75]],"id":39832467}],"con":true,"img":false}]}
{"op":"mcm","clk":"5353875769","pt":1646219369873,"mc":[{"id":"1.195503856","rc":[{"atb":[[1.93,2]],"id":39832467}],"con":true,"img":false}]}
{"op":"mcm","clk":"5353875972","pt":1646219372157,"mc":[{"id":"1.195503856","rc":[{"atl":[[2.2,0]],"id":38247337}],"con":true,"img":false}]}
{"op":"mcm","clk":"5353875980","pt":1646219372263,"mc":[{"id":"1.195503856","rc":[{"atl":[[2.1,6]],"id":38247337}],"con":true,"img":false}]}
{"op":"mcm","clk":"5353876006","pt":1646219372578,"mc":[{"id":"1.195503856","rc":[{"atb":[[1.95,5.94]],"id":39832467}],"con":true,"img":false}]}
{"op":"mcm","clk":"5353876020","pt":1646219372785,"mc":[{"id":"1.195503856","rc":[{"atb":[[1.91,32.03],[1.89,0]],"id":39832467}],"con":true,"img":false}]}
{"op":"mcm","clk":"5353876037","pt":1646219372998,"mc":[{"id":"1.195503856","rc":[{"atb":[[1.95,0]],"id":39832467}],"con":true,"img":false}]}
{"op":"mcm","clk":"5353876051","pt":1646219373157,"mc":[{"id":"1.195503856","rc":[{"atb":[[1.93,0],[1.92,4]],"id":39832467}],"con":true,"img":false}]}
{"op":"mcm","clk":"5353876059","pt":1646219373258,"mc":[{"id":"1.195503856","rc":[{"atb":[[1.91,0]],"id":39832467}],"con":true,"img":false}]}
{"op":"mcm","clk":"5353876083","pt":1646219373676,"mc":[{"id":"1.195503856","rc":[{"atb":[[1.94,28.35]],"id":39832467}],"con":true,"img":false}]}
{"op":"mcm","clk":"5353876092","pt":1646219373782,"mc":[{"id":"1.195503856","rc":[{"atb":[[1.89,32.75]],"id":39832467}],"con":true,"img":false}]}
{"op":"mcm","clk":"5353876133","pt":1646219374260,"mc":[{"id":"1.195503856","rc":[{"atb":[[1.89,0]],"id":39832467}],"con":true,"img":false}]}
{"op":"mcm","clk":"5353876283","pt":1646219376133,"mc":[{"id":"1.195503856","rc":[{"atl":[[2.1,4],[2.08,2]],"id":38247337}],"con":true,"img":false}]}
{"op":"mcm","clk":"5353876297","pt":1646219376341,"mc":[{"id":"1.195503856","rc":[{"atl":[[2.1,6],[2.08,0]],"id":38247337}],"con":true,"img":false}]}
{"op":"mcm","clk":"5353876309","pt":1646219376550,"mc":[{"id":"1.195503856","rc":[{"atl":[[2.1,2]],"id":38247337}],"con":true,"img":false}]}
{"op":"mcm","clk":"5353876318","pt":1646219376654,"mc":[{"id":"1.195503856","rc":[{"atl":[[2.08,4]],"id":38247337}],"con":true,"img":false}]}
{"op":"mcm","clk":"5353876329","pt":1646219376758,"mc":[{"id":"1.195503856","rc":[{"atl":[[2.1,0],[2.06,2]],"id":38247337},{"atb":[[1.93,31.34]],"id":39832467}],"con":true,"img":false}]}
{"op":"mcm","clk":"5353876356","pt":1646219377073,"mc":[{"id":"1.195503856","rc":[{"atl":[[2.08,0]],"id":38247337}],"con":true,"img":false}]}
{"op":"mcm","clk":"5353876364","pt":1646219377177,"mc":[{"id":"1.195503856","rc":[{"atl":[[2.06,6]],"id":38247337}],"con":true,"img":false}]}
{"op":"mcm","clk":"5353876419","pt":1646219377752,"mc":[{"id":"1.195503856","rc":[{"atb":[[1.95,30.68]],"id":39832467}],"con":true,"img":false}]}
{"op":"mcm","clk":"5353876469","pt":1646219378281,"mc":[{"id":"1.195503856","rc":[{"atb":[[1.93,33.34],[1.92,2]],"id":39832467}],"con":true,"img":false}]}
{"op":"mcm","clk":"5353876478","pt":1646219378382,"mc":[{"id":"1.195503856","rc":[{"atb":[[1.94,11.99]],"id":39832467}],"con":true,"img":false}]}
{"op":"mcm","clk":"5353876486","pt":1646219378443,"mc":[{"id":"1.195503856","rc":[{"atb":[[1.95,47.03]],"id":39832467}],"con":true,"img":false}]}
{"op":"mcm","clk":"5353876541","pt":1646219379176,"mc":[{"id":"1.195503856","marketDefinition":{"bspMarket":false,"turnInPlayEnabled":false,"persistenceEnabled":false,"marketBaseRate":7.0,"eventId":"31272499","eventTypeId":"4339","numberOfWinners":1,"bettingType":"ODDS","marketType":"MATCH_BET","marketTime":"2022-03-02T11:09:00.000Z","suspendTime":"2022-03-02T11:09:00.000Z","bspReconciled":false,"complete":true,"inPlay":false,"crossMatching":true,"runnersVoidable":false,"numberOfActiveRunners":2,"betDelay":0,"status":"SUSPENDED","runners":[{"status":"ACTIVE","sortPriority":1,"id":38247337,"name":"5. On The Bayou"},{"status":"ACTIVE","sortPriority":2,"id":39832467,"name":"7. Shian Ned"}],"regulators":["MR_INT"],"venue":"Rockhampton","countryCode":"AU","discountAllowed":true,"timezone":"Australia/Queensland","openDate":"2022-03-02T08:28:00.000Z","version":4382983712,"name":"On The Bayou v Shian Ned","eventName":"Rockhampton (AUS) 2nd Mar"},"rc":[],"con":true,"img":false}]}
{"op":"mcm","clk":"5353876541","pt":1646219379176,"mc":[{"id":"1.195503856","rc":[{"atb":[[1.2,0],[1.6,0],[1.01,0],[1.45,0],[1.09,0],[1.39,0],[1.34,0],[1.4,0],[1.8,0],[1.72,0],[1.63,0],[1.27,0],[1.57,0],[1.67,0],[1.54,0],[1.5,0],[1.13,0],[1.65,0],[1.61,0],[1.05,0]],"id":38247337},{"atl":[[2.3,0],[2.32,0],[2.22,0],[2.26,0],[2.34,0],[2.24,0],[2.36,0],[2.4,0],[2.06,0],[2.42,0],[2.28,0],[2.46,0],[2.18,0]],"id":38247337},{"atb":[[1.95,0],[1.93,0],[1.53,0],[1.56,0],[1.4,0],[1.92,0],[1.81,0],[1.88,0],[1.9,0],[1.77,0],[1.66,0],[1.31,0],[1.61,0],[1.59,0],[1.6,0],[1.84,0],[1.58,0],[1.23,0],[1.14,0],[1.94,0],[1.8,0],[1.72,0],[1.57,0],[1.55,0],[1.54,0],[1.47,0]],"id":39832467},{"atl":[[2.8,0],[2.82,0],[2.88,0],[2.74,0],[2.86,0],[2.84,0],[2.78,0],[2.76,0]],"id":39832467}],"con":true,"img":false}]}
{"op":"mcm","clk":"5353882027","pt":1646219435448,"mc":[{"id":"1.195503856","rc":[{"trd":[[1.8,0],[1.82,0],[1.85,0],[1.7,0],[1.86,0],[1.96,0],[1.93,0]],"ltp":1.8,"tv":0.0,"id":38247337},{"trd":[[2.26,0],[2.16,0]],"ltp":2.26,"tv":0.0,"id":39832467}],"con":true,"img":false}]}
{"op":"mcm","clk":"5353882124","pt":1646219436435,"mc":[{"id":"1.195503856","marketDefinition":{"bspMarket":false,"turnInPlayEnabled":false,"persistenceEnabled":false,"marketBaseRate":7.0,"eventId":"31272499","eventTypeId":"4339","numberOfWinners":1,"bettingType":"ODDS","marketType":"MATCH_BET","marketTime":"2022-03-02T11:09:00.000Z","suspendTime":"2022-03-02T11:09:00.000Z","bspReconciled":false,"complete":true,"inPlay":false,"crossMatching":false,"runnersVoidable":false,"numberOfActiveRunners":0,"betDelay":0,"status":"CLOSED","settledTime":"2022-03-02T11:10:34.000Z","runners":[{"status":"LOSER","sortPriority":1,"id":38247337,"name":"5. On The Bayou"},{"status":"WINNER","sortPriority":2,"id":39832467,"name":"7. Shian Ned"}],"regulators":["MR_INT"],"venue":"Rockhampton","countryCode":"AU","discountAllowed":true,"timezone":"Australia/Queensland","openDate":"2022-03-02T08:28:00.000Z","version":4382986822,"name":"On The Bayou v Shian Ned","eventName":"Rockhampton (AUS) 2nd Mar"},"rc":[],"con":true,"img":false}]}
