{"op":"mcm","clk":"5317728516","pt":1646251399897,"mc":[{"id":"1.195532869","marketDefinition":{"bspMarket":true,"turnInPlayEnabled":false,"persistenceEnabled":false,"marketBaseRate":5.0,"eventId":"31275720","eventTypeId":"4339","numberOfWinners":2,"bettingType":"ODDS","marketType":"PLACE","marketTime":"2022-03-03T16:28:00.000Z","suspendTime":"2022-03-03T16:28:00.000Z","bspReconciled":false,"complete":true,"inPlay":false,"crossMatching":false,"runnersVoidable":false,"numberOfActiveRunners":6,"betDelay":0,"status":"OPEN","runners":[{"status":"ACTIVE","sortPriority":1,"id":42142047,"name":"1. Underground Girl"},{"status":"ACTIVE","sortPriority":2,"id":36909993,"name":"2. Brosna Misty"},{"status":"ACTIVE","sortPriority":3,"id":42609835,"name":"3. Slaneyside Nally"},{"status":"ACTIVE","sortPriority":4,"id":2441997,"name":"4. Fine Line"},{"status":"ACTIVE","sortPriority":5,"id":40302111,"name":"5. Urry Up Alex"},{"status":"ACTIVE","sortPriority":6,"id":40133336,"name":"6. Mayses Stan"}],"regulators":["MR_INT"],"venue":"Romford","countryCode":"GB","discountAllowed":false,"timezone":"Europe/London","openDate":"2022-03-03T13:57:00.000Z","version":4384107310,"name":"To Be Placed","eventName":"Romford 3rd Mar"},"rc":[],"con":true,"img":false}]}
{"op":"mcm","clk":"5317728860","pt":1646251401766,"mc":[{"id":"1.195532869","marketDefinition":{"bspMarket":true,"turnInPlayEnabled":false,"persistenceEnabled":false,"marketBaseRate":5.0,"eventId":"31275720","eventTypeId":"4339","numberOfWinners":2,"bettingType":"ODDS","marketType":"PLACE","marketTime":"2022-03-03T16:28:00.000Z","suspendTime":"2022-03-03T16:28:00.000Z","bspReconciled":false,"complete":true,"inPlay":false,"crossMatching":false,"runnersVoidable":false,"numberOfActiveRunners":6,"betDelay":0,"status":"OPEN","runners":[{"status":"ACTIVE","sortPriority":1,"id":42142047,"name":"1. Underground Girl"},{"status":"ACTIVE","sortPriority":2,"id":36909993,"name":"2. Brosna Misty"},{"status":"ACTIVE","sortPriority":3,"id":42609835,"name":"3. Slaneyside Nally"},{"status":"ACTIVE","sortPriority":4,"id":2441997,"name":"4. Fine Line"},{"status":"ACTIVE","sortPriority":5,"id":40302111,"name":"5. Urry Up Alex"},{"status":"ACTIVE","sortPriority":6,"id":40133336,"name":"6. Mayses Stan"}],"regulators":["MR_INT"],"venue":"Romford","countryCode":"GB","discountAllowed":true,"timezone":"Europe/London","openDate":"2022-03-03T13:57:00.000Z","version":4384107310,"name":"To Be Placed","eventName":"Romford 3rd Mar"},"rc":[],"con":true,"img":false}]}
{"op":"mcm","clk":"5321521265","pt":1646310610037,"mc":[{"id":"1.195532869","rc":[{"atb":[[1.01,102.04]],"id":2441997},{"spn":"Infinity","spf":"NaN","id":2441997},{"atb":[[1.01,102.04]],"id":36909993},{"spn":"Infinity","spf":"NaN","id":36909993},{"atb":[[1.01,102.04]],"id":42609835},{"spn":"Infinity","spf":"NaN","id":42609835}],"con":true,"img":false}]}
{"op":"mcm","clk":"5321521275","pt":1646310610186,"mc":[{"id":"1.195532869","rc":[{"atb":[[1.01,102.04]],"id":40302111},{"atb":[[1.01,102.04]],"id":42142047},{"atb":[[1.01,102.04]],"id":40133336}],"con":true,"img":false}]}
{"op":"mcm","clk":"5321555825","pt":1646310928572,"mc":[{"id":"1.195532869","rc":[{"atl":[[1000,5]],"id":40302111},{"spn":500.5,"spf":"NaN","id":40302111},{"atl":[[1000,5]],"id":2441997},{"spn":500.5,"spf":"NaN","id":2441997},{"atl":[[1000,5]],"id":36909993},{"spn":500.5,"spf":"NaN","id":36909993},{"atl":[[1000,5]],"id":42142047},{"spn":500.5,"spf":"NaN","id":42142047},{"atl":[[1000,5]],"id":42609835},{"spn":500.5,"spf":"NaN","id":42609835},{"atl":[[1000,5]],"id":40133336},{"spn":500.5,"spf":"NaN","id":40133336}],"con":true,"img":false}]}
{"op":"mcm","clk":"5321555871","pt":1646310928983,"mc":[{"id":"1.195532869","rc":[{"atb":[[1.01,4802.04]],"id":40302111},{"atb":[[1.01,4802.04]],"id":2441997},{"atb":[[1.01,4802.04]],"id":36909993},{"atb":[[1.01,4802.04]],"id":42142047},{"atb":[[1.01,4802.04]],"id":42609835},{"atb":[[1.01,4802.04]],"id":40133336}],"con":true,"img":false}]}
{"op":"mcm","clk":"5322609169","pt":1646322331824,"mc":[{"id":"1.195532869","rc":[{"spl":[[1.01,1]],"id":2441997},{"spn":1.01,"spf":1.0,"id":2441997},{"spl":[[1.01,1]],"id":42609835},{"spn":1.01,"spf":1.0,"id":42609835}],"con":true,"img":false}]}
{"op":"mcm","clk":"5322679775","pt":1646323028277,"mc":[{"id":"1.195532869","rc":[{"atl":[[46,2.73]],"id":40302111},{"spn":23.5,"spf":"NaN","id":40302111},{"atl":[[46,2.73]],"id":2441997},{"atl":[[46,2.73]],"id":36909993},{"spn":23.5,"spf":"NaN","id":36909993},{"atl":[[46,2.73]],"id":42142047},{"spn":23.5,"spf":"NaN","id":42142047},{"atl":[[46,2.73]],"id":42609835},{"atl":[[46,2.73]],"id":40133336},{"spn":23.5,"spf":"NaN","id":40133336}],"con":true,"img":false}]}
{"op":"mcm","clk":"5322684157","pt":1646323085457,"mc":[{"id":"1.195532869","rc":[{"atb":[[1.01,5052.04]],"id":40302111},{"atl":[[70,2.17],[80,3.16],[50,1],[60,1.69]],"id":40302111},{"atb":[[1.01,5052.04]],"id":2441997},{"atl":[[70,2.17],[80,3.16],[50,1],[60,1.69]],"id":2441997},{"atb":[[1.01,5052.04]],"id":36909993},{"atl":[[70,2.17],[80,3.16],[50,1],[60,1.69]],"id":36909993},{"atb":[[1.01,5052.04]],"id":42142047},{"atl":[[70,2.17],[80,3.16],[50,1],[60,1.69]],"id":42142047},{"atb":[[1.01,5052.04]],"id":42609835},{"atl":[[70,2.17],[80,3.16],[50,1],[60,1.69]],"id":42609835},{"atb":[[1.01,5052.04]],"id":40133336},{"atl":[[70,2.17],[80,3.16],[50,1],[60,1.69]],"id":40133336}],"con":true,"img":false}]}
{"op":"mcm","clk":"5322686185","pt":1646323111016,"mc":[{"id":"1.195532869","marketDefinition":{"bspMarket":true,"turnInPlayEnabled":false,"persistenceEnabled":false,"marketBaseRate":5.0,"eventId":"31275720","eventTypeId":"4339","numberOfWinners":2,"bettingType":"ODDS","marketType":"PLACE","marketTime":"2022-03-03T16:28:00.000Z","suspendTime":"2022-03-03T16:28:00.000Z","bspReconciled":false,"complete":true,"inPlay":false,"crossMatching":true,"runnersVoidable":false,"numberOfActiveRunners":6,"betDelay":0,"status":"OPEN","runners":[{"status":"ACTIVE","sortPriority":1,"id":42142047,"name":"1. Underground Girl"},{"status":"ACTIVE","sortPriority":2,"id":36909993,"name":"2. Brosna Misty"},{"status":"ACTIVE","sortPriority":3,"id":42609835,"name":"3. Slaneyside Nally"},{"status":"ACTIVE","sortPriority":4,"id":2441997,"name":"4. Fine Line"},{"status":"ACTIVE","sortPriority":5,"id":40302111,"name":"5. Urry Up Alex"},{"status":"ACTIVE","sortPriority":6,"id":40133336,"name":"6. Mayses Stan"}],"regulators":["MR_INT"],"venue":"Romford","countryCode":"GB","discountAllowed":true,"timezone":"Europe/London","openDate":"2022-03-03T13:57:00.000Z","version":4384107310,"name":"To Be Placed","eventName":"Romford 3rd Mar"},"rc":[],"con":true,"img":false}]}
{"op":"mcm","clk":"5322744135","pt":1646323745632,"mc":[{"id":"1.195532869","rc":[{"atl":[[46,2.74]],"id":40302111},{"atl":[[46,2.74]],"id":2441997},{"atl":[[46,2.74]],"id":36909993},{"atl":[[46,2.74]],"id":42142047},{"spl":[[1.01,11]],"id":42609835},{"atl":[[46,2.74]],"id":42609835},{"atl":[[46,2.74]],"id":40133336}],"con":true,"img":false}]}
{"op":"mcm","clk":"5322776775","pt":1646324021319,"mc":[{"id":"1.195532869","rc":[{"atb":[[1.02,5000]],"id":36909993},{"atl":[[4,2]],"id":36909993},{"spn":2.51,"spf":"NaN","id":36909993}],"con":true,"img":false}]}
{"op":"mcm","clk":"5322776787","pt":1646324021420,"mc":[{"id":"1.195532869","rc":[{"atb":[[1.19,526.32]],"id":40302111},{"atl":[[46,4.74]],"id":40302111},{"atb":[[1.21,476.19]],"id":2441997},{"atl":[[6.4,2]],"id":2441997},{"atb":[[1.92,108.7]],"id":42142047},{"atl":[[25,2]],"id":42142047},{"atb":[[1.65,153.85]],"id":42609835},{"atl":[[11.5,2]],"id":42609835},{"atb":[[1.62,161.29]],"id":40133336},{"atl":[[9.4,2]],"id":40133336}],"con":true,"img":false}]}
{"op":"mcm","clk":"5322776797","pt":1646324021525,"mc":[{"id":"1.195532869","rc":[{"atb":[[1.77,129.87]],"id":40302111}],"con":true,"img":false}]}
{"op":"mcm","clk":"5322776806","pt":1646324021630,"mc":[{"id":"1.195532869","rc":[{"atb":[[1.19,0]],"id":40302111},{"atb":[[1.65,0],[1.71,140.85]],"id":42609835},{"atl":[[10.5,2],[11.5,0]],"id":42609835}],"con":true,"img":false}]}
{"op":"mcm","clk":"5322777042","pt":1646324023734,"mc":[{"id":"1.195532869","rc":[{"atb":[[1.75,53.33]],"id":40302111},{"atb":[[1.19,210.53]],"id":2441997},{"atl":[[6.8,6.9],[50,0]],"id":2441997},{"atl":[[50,0],[4.2,12.5]],"id":36909993},{"atb":[[1.9,44.44]],"id":42142047},{"atl":[[50,0],[27,1.54]],"id":42142047},{"atb":[[1.69,57.97]],"id":42609835},{"atl":[[11.5,3.81],[50,0]],"id":42609835},{"atb":[[1.6,66.67]],"id":40133336},{"atl":[[50,0],[9.8,4.55]],"id":40133336}],"con":true,"img":false}]}
{"op":"mcm","clk":"5322777354","pt":1646324026533,"mc":[{"id":"1.195532869","rc":[{"atb":[[2.22,81.97],[1.77,0]],"id":40302111},{"atb":[[1.02,1285.72]],"id":2441997},{"atl":[[6.6,4]],"id":2441997},{"atb":[[1.02,1096.78]],"id":40133336}],"con":true,"img":false}]}
{"op":"mcm","clk":"5322777368","pt":1646324026637,"mc":[{"id":"1.195532869","rc":[{"atl":[[6.4,0]],"id":2441997}],"con":true,"img":false}]}
{"op":"mcm","clk":"5322777388","pt":1646324026842,"mc":[{"id":"1.195532869","rc":[{"atb":[[2.18,33.9]],"id":40302111},{"atl":[[6.8,0],[7,6.67]],"id":2441997}],"con":true,"img":false}]}
{"op":"mcm","clk":"5322777776","pt":1646324030772,"mc":[{"id":"1.195532869","rc":[{"atb":[[2.24,1.65]],"id":40302111}],"con":true,"img":false}]}
{"op":"mcm","clk":"5322777815","pt":1646324031090,"mc":[{"id":"1.195532869","rc":[{"atb":[[1.15,666.67],[1.02,0]],"id":36909993},{"atl":[[4,0],[3.5,2.74]],"id":36909993}],"con":true,"img":false}]}
{"op":"mcm","clk":"5322777828","pt":1646324031192,"mc":[{"id":"1.195532869","rc":[{"atb":[[1.21,0],[1.48,208.33]],"id":2441997},{"atb":[[2.24,80.65],[1.92,0]],"id":42142047},{"atl":[[21,2],[25,0]],"id":42142047},{"atb":[[1.67,149.25],[1.62,0]],"id":40133336},{"atl":[[8,2.74],[9.4,0]],"id":40133336}],"con":true,"img":false}]}
{"op":"mcm","clk":"5322777847","pt":1646324031404,"mc":[{"id":"1.195532869","rc":[{"atb":[[1.83,120.48],[1.71,0]],"id":42609835}],"con":true,"img":false}]}
{"op":"mcm","clk":"5322777884","pt":1646324031719,"mc":[{"id":"1.195532869","rc":[{"atb":[[2.2,33.33]],"id":40302111},{"atb":[[1.46,86.96]],"id":2441997},{"atb":[[1.13,250]],"id":36909993},{"atl":[[3.6,15.38],[4.2,0]],"id":36909993},{"atb":[[2.2,33.33]],"id":42142047},{"atl":[[23,1.82],[27,0]],"id":42142047},{"atb":[[1.81,49.38]],"id":42609835},{"atb":[[1.65,61.54]],"id":40133336},{"atl":[[9.8,0],[8.4,5.41]],"id":40133336}],"con":true,"img":false}]}
{"op":"mcm","clk":"5322778023","pt":1646324032982,"mc":[{"id":"1.195532869","rc":[{"atb":[[2.28,2.15]],"id":40302111},{"atb":[[1.7,2.15]],"id":40133336}],"con":true,"img":false}]}
{"op":"mcm","clk":"5322778047","pt":1646324033197,"mc":[{"id":"1.195532869","rc":[{"atb":[[2.22,0],[2.28,4.31]],"id":40302111}],"con":true,"img":false}]}
{"op":"mcm","clk":"5322778188","pt":1646324034619,"mc":[{"id":"1.195532869","rc":[{"atb":[[2.24,33.91],[2.2,0]],"id":40302111},{"atb":[[1.68,58.82]],"id":40133336}],"con":true,"img":false}]}
{"op":"mcm","clk":"5322778232","pt":1646324034985,"mc":[{"id":"1.195532869","rc":[{"atb":[[1.02,0]],"id":2441997},{"atb":[[1.02,1400]],"id":36909993},{"atb":[[1.02,0]],"id":40133336}],"con":true,"img":false}]}
{"op":"mcm","clk":"5322778252","pt":1646324035194,"mc":[{"id":"1.195532869","rc":[{"atb":[[1.01,5054.04]],"id":42142047}],"con":true,"img":false}]}
{"op":"mcm","clk":"5322778275","pt":1646324035404,"mc":[{"id":"1.195532869","rc":[{"atb":[[1.01,5056.03]],"id":42142047}],"con":true,"img":false}]}
{"op":"mcm","clk":"5322778294","pt":1646324035606,"mc":[{"id":"1.195532869","rc":[{"atb":[[1.01,5054.04]],"id":42142047}],"con":true,"img":false}]}
{"op":"mcm","clk":"5322778309","pt":1646324035721,"mc":[{"id":"1.195532869","rc":[{"atb":[[1.93,1.99]],"id":42142047}],"con":true,"img":false}]}
{"op":"mcm","clk":"5322778340","pt":1646324035976,"mc":[{"id":"1.195532869","rc":[{"atb":[[1.01,5054.04]],"id":36909993}],"con":true,"img":false}]}
{"op":"mcm","clk":"5322778361","pt":1646324036187,"mc":[{"id":"1.195532869","rc":[{"atb":[[1.01,5056.03]],"id":36909993}],"con":true,"img":false}]}
{"op":"mcm","clk":"5322778387","pt":1646324036402,"mc":[{"id":"1.195532869","rc":[{"atb":[[1.01,5054.04]],"id":36909993}],"con":true,"img":false}]}
{"op":"mcm","clk":"5322778397","pt":1646324036517,"mc":[{"id":"1.195532869","rc":[{"atb":[[1.03,1.99]],"id":36909993}],"con":true,"img":false}]}
{"op":"mcm","clk":"5322778419","pt":1646324036747,"mc":[{"id":"1.195532869","rc":[{"atb":[[1.01,5054.04]],"id":42609835}],"con":true,"img":false}]}
{"op":"mcm","clk":"5322778445","pt":1646324036886,"mc":[{"id":"1.195532869","rc":[{"atb":[[1.01,5056.03]],"id":42609835}],"con":true,"img":false}]}
{"op":"mcm","clk":"5322778477","pt":1646324037193,"mc":[{"id":"1.195532869","rc":[{"atb":[[1.01,5054.04]],"id":42609835}],"con":true,"img":false}]}
{"op":"mcm","clk":"5322778485","pt":1646324037302,"mc":[{"id":"1.195532869","rc":[{"atb":[[1.46,304.35],[1.48,0]],"id":2441997},{"atl":[[6.8,8],[6.6,0]],"id":2441997},{"atl":[[3.55,5.48],[3.5,0]],"id":36909993},{"atb":[[1.83,0],[1.72,1.99],[1.84,57.97]],"id":42609835}],"con":true,"img":false}]}
{"op":"mcm","clk":"5322778509","pt":1646324037511,"mc":[{"id":"1.195532869","rc":[{"atb":[[1.46,217.39],[1.01,5054.04],[1.44,90.91]],"id":2441997},{"atl":[[7.2,6.45],[7,0]],"id":2441997},{"atl":[[3.6,0],[3.65,15.09]],"id":36909993},{"atb":[[1.82,48.78]],"id":42609835}],"con":true,"img":false}]}
{"op":"mcm","clk":"5322778532","pt":1646324037721,"mc":[{"id":"1.195532869","rc":[{"atb":[[1.01,5056.03]],"id":2441997}],"con":true,"img":false}]}
{"op":"mcm","clk":"5322778557","pt":1646324037978,"mc":[{"id":"1.195532869","rc":[{"atb":[[1.01,5054.04]],"id":2441997}],"con":true,"img":false}]}
{"op":"mcm","clk":"5322778565","pt":1646324038079,"mc":[{"id":"1.195532869","rc":[{"atb":[[1.22,1.99]],"id":2441997}],"con":true,"img":false}]}
{"op":"mcm","clk":"5322778588","pt":1646324038301,"mc":[{"id":"1.195532869","rc":[{"atb":[[1.01,5054.04]],"id":40302111},{"atb":[[1.87,2.15]],"id":42609835}],"con":true,"img":false}]}
{"op":"mcm","clk":"5322778609","pt":1646324038499,"mc":[{"id":"1.195532869","rc":[{"atb":[[1.84,0],[1.87,50.93]],"id":42609835}],"con":true,"img":false}]}
{"op":"mcm","clk":"5322778623","pt":1646324038615,"mc":[{"id":"1.195532869","rc":[{"atb":[[1.84,49.38]],"id":42609835}],"con":true,"img":false}]}
{"op":"mcm","clk":"5322778632","pt":1646324038721,"mc":[{"id":"1.195532869","rc":[{"atb":[[1.87,2.15]],"id":42609835}],"con":true,"img":false}]}
{"op":"mcm","clk":"5322778652","pt":1646324038925,"mc":[{"id":"1.195532869","rc":[{"atb":[[1.84,0],[1.87,51.53]],"id":42609835}],"con":true,"img":false}]}
{"op":"mcm","clk":"5322778684","pt":1646324039188,"mc":[{"id":"1.195532869","rc":[{"atb":[[1.82,0],[1.85,47.06]],"id":42609835}],"con":true,"img":false}]}
{"op":"mcm","clk":"5322778717","pt":1646324039596,"mc":[{"id":"1.195532869","rc":[{"atb":[[1.2,182.8]],"id":2441997},{"atb":[[1.69,42.68]],"id":40133336}],"con":true,"img":false}]}
{"op":"mcm","clk":"5322778739","pt":1646324039815,"mc":[{"id":"1.195532869","rc":[{"atb":[[2.24,32.26]],"id":40302111}],"con":true,"img":false}]}
{"op":"mcm","clk":"5322778763","pt":1646324040022,"mc":[{"id":"1.195532869","rc":[{"atb":[[2.3,1.65]],"id":40302111},{"atb":[[2.26,1.65]],"id":42142047}],"con":true,"img":false}]}
{"op":"mcm","clk":"5322778802","pt":1646324040396,"mc":[{"id":"1.195532869","rc":[{"atb":[[2.24,0],[2.26,31.75]],"id":40302111},{"atb":[[2.22,32.79]],"id":42142047}],"con":true,"img":false}]}
{"op":"mcm","clk":"5322778844","pt":1646324040715,"mc":[{"id":"1.195532869","rc":[{"atb":[[1.15,0],[1.17,250]],"id":36909993}],"con":true,"img":false}]}
{"op":"mcm","clk":"5322778857","pt":1646324040811,"mc":[{"id":"1.195532869","rc":[{"atb":[[1.67,0],[1.7,44.83]],"id":40133336},{"atl":[[8,0],[7.8,2.74]],"id":40133336}],"con":true,"img":false}]}
{"op":"mcm","clk":"5322778879","pt":1646324041023,"mc":[{"id":"1.195532869","rc":[{"atb":[[1.15,250]],"id":36909993},{"atl":[[8.2,5.56],[8.4,0]],"id":40133336}],"con":true,"img":false}]}
{"op":"mcm","clk":"5322778937","pt":1646324041492,"mc":[{"id":"1.195532869","rc":[{"atb":[[1.02,0]],"id":36909993},{"atb":[[2.3,2.15]],"id":42142047}],"con":true,"img":false}]}
{"op":"mcm","clk":"5322778962","pt":1646324041702,"mc":[{"id":"1.195532869","rc":[{"atb":[[2.24,0],[2.3,4.31]],"id":42142047}],"con":true,"img":false}]}
{"op":"mcm","clk":"5322778975","pt":1646324041807,"mc":[{"id":"1.195532869","rc":[{"atb":[[2.26,34.44]],"id":42142047}],"con":true,"img":false}]}
{"op":"mcm","clk":"5322778986","pt":1646324041904,"mc":[{"id":"1.195532869","rc":[{"atb":[[2.3,2.15]],"id":42142047}],"con":true,"img":false}]}
{"op":"mcm","clk":"5322779015","pt":1646324042118,"mc":[{"id":"1.195532869","rc":[{"atb":[[2.22,0],[2.26,66.19]],"id":42142047}],"con":true,"img":false}]}
{"op":"mcm","clk":"5322779035","pt":1646324042321,"mc":[{"id":"1.195532869","rc":[{"atb":[[2.24,36.61],[2.26,33.4]],"id":42142047}],"con":true,"img":false}]}
{"op":"mcm","clk":"5322779054","pt":1646324042484,"mc":[{"id":"1.195532869","rc":[{"atb":[[2.24,0],[2.3,35.56]],"id":42142047}],"con":true,"img":false}]}
{"op":"mcm","clk":"5322779141","pt":1646324043223,"mc":[{"id":"1.195532869","rc":[{"atl":[[6.8,0],[7,16]],"id":2441997}],"con":true,"img":false}]}
{"op":"mcm","clk":"5322779164","pt":1646324043429,"mc":[{"id":"1.195532869","rc":[{"atb":[[1.01,5056.03]],"id":40302111}],"con":true,"img":false}]}
{"op":"mcm","clk":"5322779188","pt":1646324043592,"mc":[{"id":"1.195532869","rc":[{"atb":[[1.01,5054.04]],"id":40302111}],"con":true,"img":false}]}
{"op":"mcm","clk":"5322779197","pt":1646324043694,"mc":[{"id":"1.195532869","rc":[{"atb":[[1.78,1.99]],"id":40302111}],"con":true,"img":false}]}
{"op":"mcm","clk":"5322779204","pt":1646324043789,"mc":[{"id":"1.195532869","rc":[{"atb":[[1.01,5054.04],[1.69,0]],"id":40133336}],"con":true,"img":false}]}
{"op":"mcm","clk":"5322779216","pt":1646324043897,"mc":[{"id":"1.195532869","rc":[{"atb":[[1.01,5056.03]],"id":40133336}],"con":true,"img":false}]}
{"op":"mcm","clk":"5322779369","pt":1646324045419,"mc":[{"id":"1.195532869","rc":[{"atl":[[7.2,0],[7.4,6.25]],"id":2441997}],"con":true,"img":false}]}
{"op":"mcm","clk":"5322779470","pt":1646324046349,"mc":[{"id":"1.195532869","rc":[{"atb":[[1.2,0]],"id":2441997},{"atb":[[1.18,175]],"id":36909993}],"con":true,"img":false}]}
{"op":"mcm","clk":"5322779490","pt":1646324046511,"mc":[{"id":"1.195532869","rc":[{"atb":[[1.19,250],[1.17,0]],"id":36909993}],"con":true,"img":false}]}
{"op":"mcm","clk":"5322779613","pt":1646324047820,"mc":[{"id":"1.195532869","rc":[{"atb":[[1.17,235.29]],"id":36909993}],"con":true,"img":false}]}
{"op":"mcm","clk":"5322779677","pt":1646324048434,"mc":[{"id":"1.195532869","rc":[{"atb":[[1.66,53.8]],"id":40133336}],"con":true,"img":false}]}
{"op":"mcm","clk":"5322779719","pt":1646324048811,"mc":[{"id":"1.195532869","rc":[{"atb":[[2.26,31.75]],"id":42142047}],"con":true,"img":false}]}
{"op":"mcm","clk":"5322779734","pt":1646324048915,"mc":[{"id":"1.195532869","rc":[{"atb":[[2.32,1.65]],"id":42142047}],"con":true,"img":false}]}
{"op":"mcm","clk":"5322779752","pt":1646324049118,"mc":[{"id":"1.195532869","rc":[{"atb":[[1.01,5054.04]],"id":40133336}],"con":true,"img":false}]}
{"op":"mcm","clk":"5322779766","pt":1646324049227,"mc":[{"id":"1.195532869","rc":[{"atb":[[1.83,120.48]],"id":42609835},{"atl":[[12.5,8.7]],"id":42609835},{"atb":[[1.63,1.99]],"id":40133336}],"con":true,"img":false}]}
{"op":"mcm","clk":"5322779826","pt":1646324049809,"mc":[{"id":"1.195532869","rc":[{"atb":[[2.28,31.25],[2.26,0]],"id":42142047},{"atb":[[1.01,4804.04]],"id":42609835},{"atl":[[70,0],[80,0],[60,0]],"id":42609835}],"con":true,"img":false}]}
{"op":"mcm","clk":"5322779884","pt":1646324050431,"mc":[{"id":"1.195532869","rc":[{"atb":[[2.22,81.97]],"id":40302111}],"con":true,"img":false}]}
{"op":"mcm","clk":"5322779944","pt":1646324051005,"mc":[{"id":"1.195532869","rc":[{"atb":[[1.01,4804.04]],"id":40302111},{"atb":[[1.2,182.8]],"id":2441997},{"atb":[[1.18,0]],"id":36909993},{"atb":[[1.93,0]],"id":42142047},{"atl":[[8.6,13.16]],"id":40133336}],"con":true,"img":false}]}
{"op":"mcm","clk":"5322779958","pt":1646324051107,"mc":[{"id":"1.195532869","rc":[{"atb":[[1.17,735.29]],"id":36909993},{"atb":[[2.32,3.64]],"id":42142047}],"con":true,"img":false}]}
{"op":"mcm","clk":"5322779967","pt":1646324051213,"mc":[{"id":"1.195532869","rc":[{"atb":[[1.19,0]],"id":36909993},{"atl":[[70,0],[80,0],[60,0]],"id":40133336}],"con":true,"img":false}]}
{"op":"mcm","clk":"5322779980","pt":1646324051318,"mc":[{"id":"1.195532869","rc":[{"atb":[[1.03,0]],"id":36909993}],"con":true,"img":false}]}
{"op":"mcm","clk":"5322779993","pt":1646324051420,"mc":[{"id":"1.195532869","rc":[{"atb":[[1.2,1.99]],"id":36909993}],"con":true,"img":false}]}
{"op":"mcm","clk":"5322780016","pt":1646324051631,"mc":[{"id":"1.195532869","rc":[{"atb":[[1.72,0]],"id":42609835}],"con":true,"img":false}]}
{"op":"mcm","clk":"5322780029","pt":1646324051736,"mc":[{"id":"1.195532869","rc":[{"atb":[[1.88,1.99]],"id":42609835}],"con":true,"img":false}]}
{"op":"mcm","clk":"5322780037","pt":1646324051840,"mc":[{"id":"1.195532869","rc":[{"atb":[[1.18,222.22],[1.17,500]],"id":36909993}],"con":true,"img":false}]}
{"op":"mcm","clk":"5322780045","pt":1646324051933,"mc":[{"id":"1.195532869","rc":[{"atb":[[1.22,0]],"id":2441997}],"con":true,"img":false}]}
{"op":"mcm","clk":"5322780053","pt":1646324052001,"mc":[{"id":"1.195532869","rc":[{"atb":[[1.47,1.99]],"id":2441997}],"con":true,"img":false}]}
{"op":"mcm","clk":"5322780064","pt":1646324052107,"mc":[{"id":"1.195532869","rc":[{"atb":[[2.3,2.15],[2.34,31.25]],"id":42142047}],"con":true,"img":false}]}
{"op":"mcm","clk":"5322780076","pt":1646324052204,"mc":[{"id":"1.195532869","rc":[{"atb":[[1.78,0]],"id":40302111}],"con":true,"img":false}]}
{"op":"mcm","clk":"5322780089","pt":1646324052310,"mc":[{"id":"1.195532869","rc":[{"atb":[[2.3,3.64]],"id":40302111}],"con":true,"img":false}]}
{"op":"mcm","clk":"5322780107","pt":1646324052507,"mc":[{"id":"1.195532869","rc":[{"atb":[[2.32,4.32],[2.28,2.15]],"id":40302111}],"con":true,"img":false}]}
{"op":"mcm","clk":"5322780116","pt":1646324052613,"mc":[{"id":"1.195532869","rc":[{"atb":[[1.63,0]],"id":40133336}],"con":true,"img":false}]}
{"op":"mcm","clk":"5322780128","pt":1646324052731,"mc":[{"id":"1.195532869","rc":[{"atb":[[1.71,1.99]],"id":40133336}],"con":true,"img":false}]}
{"op":"mcm","clk":"5322780148","pt":1646324052941,"mc":[{"id":"1.195532869","rc":[{"atb":[[2.28,33.4]],"id":40302111},{"atb":[[1.45,88.89]],"id":2441997},{"atb":[[2.3,32.92]],"id":42142047},{"atb":[[1.85,0],[1.86,46.51]],"id":42609835},{"atb":[[1.68,0],[1.69,57.97]],"id":40133336}],"con":true,"img":false}]}
{"op":"mcm","clk":"5322780156","pt":1646324053028,"mc":[{"id":"1.195532869","rc":[{"atb":[[2.26,0]],"id":40302111},{"atb":[[2.28,0]],"id":42142047}],"con":true,"img":false}]}
{"op":"mcm","clk":"5322780198","pt":1646324053419,"mc":[{"id":"1.195532869","rc":[{"atb":[[1.49,2.15]],"id":2441997},{"atb":[[2.4,2.15],[2.3,30.77]],"id":42142047}],"con":true,"img":false}]}
{"op":"mcm","clk":"5322780218","pt":1646324053620,"mc":[{"id":"1.195532869","rc":[{"atb":[[1.46,0],[1.49,4.31]],"id":2441997}],"con":true,"img":false}]}
{"op":"mcm","clk":"5322780342","pt":1646324055333,"mc":[{"id":"1.195532869","rc":[{"atb":[[1.19,156.94]],"id":36909993}],"con":true,"img":false}]}
{"op":"mcm","clk":"5322780381","pt":1646324055845,"mc":[{"id":"1.195532869","rc":[{"atb":[[1.45,0],[1.47,87.1]],"id":2441997},{"atb":[[2.36,29.41]],"id":42142047}],"con":true,"img":false}]}
{"op":"mcm","clk":"5322780393","pt":1646324055914,"mc":[{"id":"1.195532869","rc":[{"atb":[[2.3,0]],"id":42142047}],"con":true,"img":false}]}
{"op":"mcm","clk":"5322780403","pt":1646324056013,"mc":[{"id":"1.195532869","rc":[{"atl":[[6.8,6.25],[7,0]],"id":2441997},{"atb":[[1.01,4804.04]],"id":42142047}],"con":true,"img":false}]}
{"op":"mcm","clk":"5322780521","pt":1646324057228,"mc":[{"id":"1.195532869","rc":[{"atb":[[1.2,0]],"id":2441997},{"atb":[[1.66,0]],"id":40133336}],"con":true,"img":false}]}
{"op":"mcm","clk":"5322780530","pt":1646324057327,"mc":[{"id":"1.195532869","rc":[{"atl":[[7.2,6.45],[7.4,0]],"id":2441997}],"con":true,"img":false}]}
{"op":"mcm","clk":"5322780581","pt":1646324057846,"mc":[{"id":"1.195532869","rc":[{"atb":[[2.3,1.99]],"id":40302111},{"atb":[[2.32,1.99]],"id":42142047}],"con":true,"img":false}]}
{"op":"mcm","clk":"5322780601","pt":1646324058050,"mc":[{"id":"1.195532869","rc":[{"atb":[[2.32,0],[2.3,35.4],[2.34,1.65]],"id":40302111},{"atb":[[2.42,1.65]],"id":42142047}],"con":true,"img":false}]}
{"op":"mcm","clk":"5322780623","pt":1646324058219,"mc":[{"id":"1.195532869","rc":[{"atb":[[2.3,66.17],[2.28,2.15]],"id":40302111},{"atb":[[2.38,28.99]],"id":42142047},{"atl":[[7.8,0]],"id":40133336}],"con":true,"img":false}]}
{"op":"mcm","clk":"5322780636","pt":1646324058320,"mc":[{"id":"1.195532869","rc":[{"atl":[[8,5.56]],"id":40133336}],"con":true,"img":false}]}
{"op":"mcm","clk":"5322780656","pt":1646324058528,"mc":[{"id":"1.195532869","rc":[{"atb":[[2.32,0]],"id":42142047},{"atl":[[8.2,0],[8.4,5.41]],"id":40133336}],"con":true,"img":false}]}
{"op":"mcm","clk":"5322780665","pt":1646324058627,"mc":[{"id":"1.195532869","rc":[{"atb":[[2.36,31.4]],"id":42142047}],"con":true,"img":false}]}
{"op":"mcm","clk":"5322780685","pt":1646324058834,"mc":[{"id":"1.195532869","rc":[{"atb":[[1.2,0]],"id":36909993}],"con":true,"img":false}]}
{"op":"mcm","clk":"5322780697","pt":1646324058934,"mc":[{"id":"1.195532869","rc":[{"atb":[[1.19,158.93]],"id":36909993}],"con":true,"img":false}]}
{"op":"mcm","clk":"5322780713","pt":1646324059148,"mc":[{"id":"1.195532869","rc":[{"atb":[[2.3,64.18]],"id":40302111}],"con":true,"img":false}]}
{"op":"mcm","clk":"5322780722","pt":1646324059243,"mc":[{"id":"1.195532869","rc":[{"atb":[[2.34,3.64]],"id":40302111}],"con":true,"img":false}]}
{"op":"mcm","clk":"5322780730","pt":1646324059310,"mc":[{"id":"1.195532869","rc":[{"atb":[[1.17,735.29]],"id":36909993}],"con":true,"img":false}]}
{"op":"mcm","clk":"5322780740","pt":1646324059414,"mc":[{"id":"1.195532869","rc":[{"atb":[[1.18,0]],"id":36909993}],"con":true,"img":false}]}
{"op":"mcm","clk":"5322780835","pt":1646324060545,"mc":[{"id":"1.195532869","rc":[{"atb":[[1.2,250],[1.17,235.29]],"id":36909993},{"atb":[[2.36,29.41]],"id":42142047}],"con":true,"img":false}]}
{"op":"mcm","clk":"5322780844","pt":1646324060612,"mc":[{"id":"1.195532869","rc":[{"atb":[[2.42,3.64]],"id":42142047}],"con":true,"img":false}]}
{"op":"mcm","clk":"5322780863","pt":1646324060822,"mc":[{"id":"1.195532869","rc":[{"atb":[[1.47,85.11]],"id":2441997}],"con":true,"img":false}]}
{"op":"mcm","clk":"5322780871","pt":1646324060916,"mc":[{"id":"1.195532869","rc":[{"atb":[[1.5,1.99]],"id":2441997}],"con":true,"img":false}]}
{"op":"mcm","clk":"5322780883","pt":1646324061032,"mc":[{"id":"1.195532869","rc":[{"atb":[[1.18,222.22],[1.17,0]],"id":36909993}],"con":true,"img":false}]}
{"op":"mcm","clk":"5322780892","pt":1646324061128,"mc":[{"id":"1.195532869","rc":[{"atl":[[6.8,0],[7,12.5]],"id":2441997}],"con":true,"img":false}]}
{"op":"mcm","clk":"5322780929","pt":1646324061541,"mc":[{"id":"1.195532869","rc":[{"atb":[[1.48,83.33],[1.47,0]],"id":2441997},{"atl":[[7.2,0],[7.4,6.25]],"id":2441997},{"atb":[[2.44,3.65],[2.34,0]],"id":42142047}],"con":true,"img":false}]}
{"op":"mcm","clk":"5322780967","pt":1646324061915,"mc":[{"id":"1.195532869","rc":[{"atb":[[1.45,5.17]],"id":2441997},{"atb":[[1.66,55.39]],"id":40133336}],"con":true,"img":false}]}
{"op":"mcm","clk":"5322781007","pt":1646324062332,"mc":[{"id":"1.195532869","rc":[{"atb":[[2.4,30.72],[2.38,0]],"id":42142047}],"con":true,"img":false}]}
{"op":"mcm","clk":"5322781062","pt":1646324062916,"mc":[{"id":"1.195532869","rc":[{"atl":[[13.5,12]],"id":42609835}],"con":true,"img":false}]}
{"op":"mcm","clk":"5322781139","pt":1646324063846,"mc":[{"id":"1.195532869","rc":[{"atb":[[2.36,2.15],[2.28,0]],"id":40302111}],"con":true,"img":false}]}
{"op":"mcm","clk":"5322781185","pt":1646324064432,"mc":[{"id":"1.195532869","rc":[{"atb":[[1.19,1.99]],"id":36909993}],"con":true,"img":false}]}
{"op":"mcm","clk":"5322781294","pt":1646324065644,"mc":[{"id":"1.195532869","rc":[{"atb":[[1.2,0],[1.19,501.99]],"id":36909993}],"con":true,"img":false}]}
{"op":"mcm","clk":"5322781343","pt":1646324066163,"mc":[{"id":"1.195532869","rc":[{"atb":[[2.34,1.65]],"id":40302111}],"con":true,"img":false}]}
{"op":"mcm","clk":"5322781354","pt":1646324066226,"mc":[{"id":"1.195532869","rc":[{"atb":[[2.3,33.41],[2.32,32.29]],"id":40302111},{"atb":[[1.18,0]],"id":36909993}],"con":true,"img":false}]}
{"op":"mcm","clk":"5322781370","pt":1646324066340,"mc":[{"id":"1.195532869","rc":[{"atb":[[1.17,235.29]],"id":36909993}],"con":true,"img":false}]}
{"op":"mcm","clk":"5322781426","pt":1646324066953,"mc":[{"id":"1.195532869","rc":[{"atb":[[2.34,0]],"id":40302111},{"atb":[[2.42,1.99]],"id":42142047}],"con":true,"img":false}]}
{"op":"mcm","clk":"5322781442","pt":1646324067119,"mc":[{"id":"1.195532869","rc":[{"atb":[[2.38,1.65]],"id":40302111},{"atb":[[2.42,29.41],[2.46,1.65],[2.44,0]],"id":42142047}],"con":true,"img":false}]}
{"op":"mcm","clk":"5322781453","pt":1646324067221,"mc":[{"id":"1.195532869","rc":[{"atb":[[2.46,3.64]],"id":42142047}],"con":true,"img":false}]}
{"op":"mcm","clk":"5322781464","pt":1646324067325,"mc":[{"id":"1.195532869","rc":[{"atb":[[2.3,0],[2.38,3.81]],"id":40302111}],"con":true,"img":false}]}
{"op":"mcm","clk":"5322781474","pt":1646324067432,"mc":[{"id":"1.195532869","rc":[{"atb":[[2.32,30.3]],"id":40302111}],"con":true,"img":false}]}
{"op":"mcm","clk":"5322781487","pt":1646324067543,"mc":[{"id":"1.195532869","rc":[{"atb":[[2.38,5.8]],"id":40302111}],"con":true,"img":false}]}
{"op":"mcm","clk":"5322781597","pt":1646324068532,"mc":[{"id":"1.195532869","rc":[{"atb":[[1.67,149.25]],"id":40133336},{"atl":[[8.8,12.82]],"id":40133336}],"con":true,"img":false}]}
{"op":"mcm","clk":"5322781649","pt":1646324069050,"mc":[{"id":"1.195532869","rc":[{"atb":[[2.46,1.65]],"id":42142047}],"con":true,"img":false}]}
{"op":"mcm","clk":"5322781658","pt":1646324069152,"mc":[{"id":"1.195532869","rc":[{"atb":[[2.44,1.99]],"id":42142047}],"con":true,"img":false}]}
{"op":"mcm","clk":"5322781889","pt":1646324071548,"mc":[{"id":"1.195532869","rc":[{"atb":[[1.46,217.39]],"id":2441997},{"atl":[[7.8,14.71]],"id":2441997}],"con":true,"img":false}]}
{"op":"mcm","clk":"5322781945","pt":1646324072239,"mc":[{"id":"1.195532869","rc":[{"atb":[[1.2,182.8]],"id":36909993},{"atb":[[1.66,0]],"id":40133336}],"con":true,"img":false}]}
{"op":"mcm","clk":"5322781953","pt":1646324072337,"mc":[{"id":"1.195532869","rc":[{"atb":[[2.36,73.53]],"id":42142047},{"atl":[[25,4.17]],"id":42142047}],"con":true,"img":false}]}
{"op":"mcm","clk":"5322782007","pt":1646324072911,"mc":[{"id":"1.195532869","rc":[{"atl":[[14.5,18.52]],"id":42609835}],"con":true,"img":false}]}
{"op":"mcm","clk":"5322782017","pt":1646324073015,"mc":[{"id":"1.195532869","rc":[{"atb":[[1.19,500]],"id":36909993}],"con":true,"img":false}]}
{"op":"mcm","clk":"5322782030","pt":1646324073126,"mc":[{"id":"1.195532869","rc":[{"atb":[[1.21,1.99]],"id":36909993}],"con":true,"img":false}]}
{"op":"mcm","clk":"5322782253","pt":1646324074346,"mc":[{"id":"1.195532869","rc":[{"atb":[[1.45,0]],"id":2441997}],"con":true,"img":false}]}
{"op":"mcm","clk":"5322782264","pt":1646324074440,"mc":[{"id":"1.195532869","rc":[{"atb":[[2.4,28.57],[2.48,2.15]],"id":42142047}],"con":true,"img":false}]}
{"op":"mcm","clk":"5322782316","pt":1646324074954,"mc":[{"id":"1.195532869","rc":[{"atb":[[1.21,184.79],[1.19,0]],"id":36909993}],"con":true,"img":false}]}
{"op":"mcm","clk":"5322782338","pt":1646324075122,"mc":[{"id":"1.195532869","rc":[{"atb":[[2.32,3.73],[2.34,29.85]],"id":40302111},{"atb":[[1.01,4804.04],[1.19,0]],"id":2441997},{"atl":[[70,0],[80,0],[60,0]],"id":2441997},{"atb":[[1.19,210.53],[1.17,0]],"id":36909993},{"atb":[[2.2,37.43]],"id":42142047},{"atl":[[70,0],[80,0],[60,0]],"id":42142047},{"atb":[[1.6,0]],"id":40133336}],"con":true,"img":false}]}
{"op":"mcm","clk":"5322782358","pt":1646324075340,"mc":[{"id":"1.195532869","rc":[{"atb":[[2.32,0]],"id":40302111},{"atl":[[8,7.36]],"id":2441997},{"atb":[[2.2,33.33]],"id":42142047}],"con":true,"img":false}]}
{"op":"mcm","clk":"5322782364","pt":1646324075432,"mc":[{"id":"1.195532869","rc":[{"atb":[[2.44,0]],"id":42142047}],"con":true,"img":false}]}
{"op":"mcm","clk":"5322782377","pt":1646324075542,"mc":[{"id":"1.195532869","rc":[{"atl":[[46,2.74],[27,2]],"id":40302111},{"atb":[[1.49,2.15],[1.51,4.32]],"id":2441997},{"atl":[[8,0],[5.3,12.5],[7,0]],"id":2441997},{"atl":[[3.6,18.44],[3.55,0]],"id":36909993},{"atb":[[2.5,1.99]],"id":42142047},{"atl":[[21,0],[22,4]],"id":42142047},{"atb":[[1.9,46.51],[1.87,2.15],[2.08,12.34]],"id":42609835},{"atl":[[10.5,0],[11,8.7]],"id":42609835},{"atb":[[1.7,2.15],[1.77,44.84]],"id":40133336},{"atl":[[8,0],[8.6,25.98]],"id":40133336}],"con":true,"img":false}]}
{"op":"mcm","clk":"5322782387","pt":1646324075674,"mc":[{"id":"1.195532869","rc":[{"atb":[[2.72,3.76]],"id":40302111},{"atb":[[1.46,228.75]],"id":2441997},{"atb":[[1.92,23.4],[1.63,23.4]],"id":40133336},{"atl":[[8.2,3.57]],"id":40133336}],"con":true,"img":false}]}
{"op":"mcm","clk":"5322782396","pt":1646324075729,"mc":[{"id":"1.195532869","rc":[{"atl":[[50,0],[29,1.43]],"id":40302111},{"atb":[[1.49,83.78]],"id":2441997},{"atl":[[5.5,8.89]],"id":2441997},{"atl":[[3.7,14.81],[3.65,0]],"id":36909993},{"atl":[[23,0],[24,1.74]],"id":42142047},{"atb":[[2.04,38.46],[1.86,0],[2.08,0]],"id":42609835},{"atl":[[11,0],[11.5,9.52],[12,3.64]],"id":42609835},{"atb":[[1.75,53.33],[1.69,0]],"id":40133336},{"atl":[[8.8,5.13],[8.4,0]],"id":40133336}],"con":true,"img":false}]}
{"op":"mcm","clk":"5322782401","pt":1646324075833,"mc":[{"id":"1.195532869","rc":[{"atb":[[1.46,217.39]],"id":2441997},{"atl":[[3.6,10.96]],"id":36909993},{"atb":[[2.46,0]],"id":42142047},{"atb":[[1.63,0]],"id":40133336}],"con":true,"img":false}]}
{"op":"mcm","clk":"5322782413","pt":1646324075933,"mc":[{"id":"1.195532869","rc":[{"atl":[[11.5,0],[12,12.73]],"id":42609835}],"con":true,"img":false}]}
{"op":"mcm","clk":"5322782425","pt":1646324076036,"mc":[{"id":"1.195532869","rc":[{"atb":[[2.5,3.64]],"id":42142047}],"con":true,"img":false}]}
{"op":"mcm","clk":"5322782444","pt":1646324076139,"mc":[{"id":"1.195532869","rc":[{"atb":[[1.88,0]],"id":42609835}],"con":true,"img":false}]}
{"op":"mcm","clk":"5322782454","pt":1646324076241,"mc":[{"id":"1.195532869","rc":[{"atb":[[2.06,1.99]],"id":42609835}],"con":true,"img":false}]}
{"op":"mcm","clk":"5322782465","pt":1646324076345,"mc":[{"id":"1.195532869","rc":[{"atb":[[2.68,23.81],[2.34,0]],"id":40302111},{"atb":[[2,40],[2.04,0]],"id":42609835},{"atl":[[12,9.09],[13,3.33]],"id":42609835},{"atb":[[1.9,44.44],[1.75,0]],"id":40133336},{"atl":[[8.6,18.08]],"id":40133336}],"con":true,"img":false}]}
{"op":"mcm","clk":"5322782476","pt":1646324076446,"mc":[{"id":"1.195532869","rc":[{"atb":[[2.42,0],[2.52,3.65]],"id":42142047},{"atb":[[2.06,40.45],[1.9,0]],"id":42609835}],"con":true,"img":false}]}
{"op":"mcm","clk":"5322782485","pt":1646324076551,"mc":[{"id":"1.195532869","rc":[{"atb":[[2.4,0],[2.42,3.08],[2.46,27.4]],"id":42142047},{"atb":[[2,0],[2.02,39.22]],"id":42609835},{"atl":[[12.5,0]],"id":42609835}],"con":true,"img":false}]}
{"op":"mcm","clk":"5322782494","pt":1646324076654,"mc":[{"id":"1.195532869","rc":[{"atb":[[2.3,21.44]],"id":42609835}],"con":true,"img":false}]}
{"op":"mcm","clk":"5322782502","pt":1646324076759,"mc":[{"id":"1.195532869","rc":[{"atb":[[2.46,0],[2.48,29.18]],"id":42142047}],"con":true,"img":false}]}
{"op":"mcm","clk":"5322782511","pt":1646324076863,"mc":[{"id":"1.195532869","rc":[{"atb":[[2.02,0],[2.26,31.75]],"id":42609835},{"atb":[[1.71,34.76]],"id":40133336}],"con":true,"img":false}]}
{"op":"mcm","clk":"5322782584","pt":1646324077556,"mc":[{"id":"1.195532869","rc":[{"atb":[[2.72,0]],"id":40302111},{"atb":[[2.42,0]],"id":42142047},{"atb":[[2.3,0]],"id":42609835},{"atb":[[1.92,0]],"id":40133336},{"atl":[[8.2,0]],"id":40133336}],"con":true,"img":false}]}
{"op":"mcm","clk":"5322782663","pt":1646324078449,"mc":[{"id":"1.195532869","rc":[{"atb":[[2.64,24.39],[2.68,0]],"id":40302111},{"atb":[[2.22,32.79],[2.26,0]],"id":42609835},{"atb":[[1.88,45.45],[1.9,0]],"id":40133336},{"atl":[[8.6,12.82],[9,5]],"id":40133336}],"con":true,"img":false}]}
{"op":"mcm","clk":"5322782728","pt":1646324079135,"mc":[{"id":"1.195532869","rc":[{"atb":[[1.2,0]],"id":36909993}],"con":true,"img":false}]}
{"op":"mcm","clk":"5322782736","pt":1646324079236,"mc":[{"id":"1.195532869","rc":[{"atb":[[1.52,3.02]],"id":2441997}],"con":true,"img":false}]}
{"op":"mcm","clk":"5322782885","pt":1646324080760,"mc":[{"id":"1.195532869","rc":[{"atl":[[44,2.33],[27,0]],"id":40302111},{"atl":[[5.3,0],[7,16.67]],"id":2441997}],"con":true,"img":false}]}
{"op":"mcm","clk":"5322782956","pt":1646324081455,"mc":[{"id":"1.195532869","rc":[{"spn":15.82,"spf":"NaN","id":40302111},{"atb":[[1.5,0]],"id":2441997},{"spn":1.52,"spf":1.0,"id":2441997},{"spn":2.4,"spf":"NaN","id":36909993},{"spn":12.26,"spf":"NaN","id":42142047},{"spn":2.22,"spf":1.0,"id":42609835},{"spn":5.24,"spf":"NaN","id":40133336}],"con":true,"img":false}]}
{"op":"mcm","clk":"5322782965","pt":1646324081557,"mc":[{"id":"1.195532869","rc":[{"atb":[[1.52,5.01]],"id":2441997}],"con":true,"img":false}]}
{"op":"mcm","clk":"5322782974","pt":1646324081651,"mc":[{"id":"1.195532869","rc":[{"atb":[[2.38,3.81]],"id":40302111}],"con":true,"img":false}]}
{"op":"mcm","clk":"5322782984","pt":1646324081760,"mc":[{"id":"1.195532869","rc":[{"atb":[[2.74,1.99]],"id":40302111}],"con":true,"img":false}]}
{"op":"mcm","clk":"5322782995","pt":1646324081864,"mc":[{"id":"1.195532869","rc":[{"atb":[[1.71,32.77]],"id":40133336}],"con":true,"img":false}]}
{"op":"mcm","clk":"5322783006","pt":1646324081969,"mc":[{"id":"1.195532869","rc":[{"atb":[[2.74,5.81],[2.38,1.65]],"id":40302111},{"atb":[[1.93,1.99]],"id":40133336}],"con":true,"img":false}]}
{"op":"mcm","clk":"5322783013","pt":1646324082066,"mc":[{"id":"1.195532869","rc":[{"atb":[[1.16,228.51]],"id":36909993},{"atb":[[1.71,0]],"id":40133336}],"con":true,"img":false}]}
{"op":"mcm","clk":"5322783140","pt":1646324083163,"mc":[{"id":"1.195532869","rc":[{"atb":[[2.64,0],[2.7,23.53]],"id":40302111},{"atl":[[32,1.29],[29,0]],"id":40302111},{"atb":[[1.5,80],[1.49,2.15]],"id":2441997},{"atl":[[5.5,0],[5.7,8.51]],"id":2441997},{"atb":[[2.18,33.9]],"id":42609835},{"atb":[[1.9,44.44]],"id":40133336}],"con":true,"img":false}]}
{"op":"mcm","clk":"5322783150","pt":1646324083262,"mc":[{"id":"1.195532869","rc":[{"atb":[[2.22,0]],"id":42609835},{"atb":[[1.88,0]],"id":40133336},{"atl":[[8.8,0]],"id":40133336}],"con":true,"img":false}]}
{"op":"mcm","clk":"5322783320","pt":1646324084772,"mc":[{"id":"1.195532869","rc":[{"atb":[[1.51,0],[1.53,5.01]],"id":2441997},{"atl":[[21,4],[22,0]],"id":42142047},{"atb":[[1.93,46.43]],"id":40133336},{"atl":[[8.6,0],[7.6,5]],"id":40133336}],"con":true,"img":false}]}
{"op":"mcm","clk":"5322783330","pt":1646324084827,"mc":[{"id":"1.195532869","rc":[{"atb":[[2.38,0]],"id":40302111},{"atb":[[2.5,1.99]],"id":42142047},{"atb":[[1.77,0]],"id":40133336}],"con":true,"img":false}]}
{"op":"mcm","clk":"5322783339","pt":1646324084934,"mc":[{"id":"1.195532869","rc":[{"atb":[[2.5,31.18]],"id":42142047}],"con":true,"img":false}]}
{"op":"mcm","clk":"5322783354","pt":1646324085043,"mc":[{"id":"1.195532869","rc":[{"atb":[[2.76,1.65]],"id":40302111},{"atb":[[1.55,2.15],[1.49,0]],"id":2441997},{"atb":[[2.54,1.65],[2.52,0]],"id":42142047},{"atb":[[2.2,1.65]],"id":42609835}],"con":true,"img":false}]}
{"op":"mcm","clk":"5322783365","pt":1646324085149,"mc":[{"id":"1.195532869","rc":[{"atl":[[10.5,9.09],[12,0]],"id":42609835}],"con":true,"img":false}]}
{"op":"mcm","clk":"5322783374","pt":1646324085245,"mc":[{"id":"1.195532869","rc":[{"atb":[[1.55,7.16],[1.53,0]],"id":2441997}],"con":true,"img":false}]}
{"op":"mcm","clk":"5322783426","pt":1646324085657,"mc":[{"id":"1.195532869","rc":[{"atb":[[2.06,1.99],[2.2,35.55]],"id":42609835}],"con":true,"img":false}]}
{"op":"mcm","clk":"5322783436","pt":1646324085762,"mc":[{"id":"1.195532869","rc":[{"atb":[[1.17,250]],"id":36909993},{"atl":[[3.8,35.71]],"id":36909993}],"con":true,"img":false}]}
{"op":"mcm","clk":"5322783540","pt":1646324086774,"mc":[{"id":"1.195532869","rc":[{"atb":[[2.5,57.85],[2.48,2.15]],"id":42142047},{"atl":[[23,1.82]],"id":42142047}],"con":true,"img":false}]}
{"op":"mcm","clk":"5322783560","pt":1646324086975,"mc":[{"id":"1.195532869","rc":[{"atb":[[1.68,53.76]],"id":40133336}],"con":true,"img":false}]}
{"op":"mcm","clk":"5322783655","pt":1646324087772,"mc":[{"id":"1.195532869","rc":[{"atb":[[2.06,0]],"id":42609835}],"con":true,"img":false}]}
{"op":"mcm","clk":"5322783671","pt":1646324087878,"mc":[{"id":"1.195532869","rc":[{"atb":[[2.22,1.99]],"id":42609835}],"con":true,"img":false}]}
{"op":"mcm","clk":"5322783698","pt":1646324088084,"mc":[{"id":"1.195532869","rc":[{"atb":[[2.72,23.26],[2.7,0]],"id":40302111},{"atl":[[32,0],[36,1.14]],"id":40302111},{"atb":[[1.5,0],[1.53,75.47]],"id":2441997},{"atl":[[5.7,0],[5.9,8.16]],"id":2441997},{"atb":[[1.01,4804.04]],"id":36909993},{"atl":[[80,0]],"id":36909993},{"atl":[[11.5,3.81]],"id":42609835},{"atl":[[8,5.71]],"id":40133336}],"con":true,"img":false}]}
{"op":"mcm","clk":"5322783809","pt":1646324089179,"mc":[{"id":"1.195532869","rc":[{"atb":[[1.52,1.99]],"id":2441997},{"atb":[[1.16,0]],"id":36909993}],"con":true,"img":false}]}
{"op":"mcm","clk":"5322783821","pt":1646324089283,"mc":[{"id":"1.195532869","rc":[{"atl":[[6.2,7.69],[5.9,0]],"id":2441997}],"con":true,"img":false}]}
{"op":"mcm","clk":"5322783845","pt":1646324089492,"mc":[{"id":"1.195532869","rc":[{"atb":[[1.14,14.28]],"id":36909993}],"con":true,"img":false}]}
{"op":"mcm","clk":"5322783895","pt":1646324089859,"mc":[{"id":"1.195532869","rc":[{"atb":[[1.14,0]],"id":36909993}],"con":true,"img":false}]}
{"op":"mcm","clk":"5322784262","pt":1646324093382,"mc":[{"id":"1.195532869","rc":[{"atb":[[1.52,0]],"id":2441997}],"con":true,"img":false}]}
{"op":"mcm","clk":"5322784279","pt":1646324093495,"mc":[{"id":"1.195532869","rc":[{"atb":[[1.56,1.99]],"id":2441997}],"con":true,"img":false}]}
{"op":"mcm","clk":"5322784294","pt":1646324093630,"mc":[{"id":"1.195532869","rc":[{"atl":[[6.2,0],[6.6,7.14]],"id":2441997}],"con":true,"img":false}]}
{"op":"mcm","clk":"5322784333","pt":1646324093863,"mc":[{"id":"1.195532869","rc":[{"atb":[[2.54,0]],"id":42142047},{"atb":[[2.2,33.9]],"id":42609835}],"con":true,"img":false}]}
{"op":"mcm","clk":"5322784344","pt":1646324093967,"mc":[{"id":"1.195532869","rc":[{"atb":[[2.54,2.16]],"id":42142047}],"con":true,"img":false}]}
{"op":"mcm","clk":"5322784358","pt":1646324094103,"mc":[{"id":"1.195532869","rc":[{"atb":[[2.5,28.66],[2.52,1.65]],"id":42142047},{"atb":[[2.24,1.65]],"id":42609835}],"con":true,"img":false}]}
{"op":"mcm","clk":"5322784367","pt":1646324094169,"mc":[{"id":"1.195532869","rc":[{"atb":[[1.49,10.02]],"id":2441997},{"atb":[[1.22,129.35]],"id":36909993}],"con":true,"img":false}]}
{"op":"mcm","clk":"5322784391","pt":1646324094805,"mc":[{"id":"1.195532869","rc":[{"atb":[[1.54,74.07],[1.53,0]],"id":2441997},{"atl":[[6.6,0],[7,23.34]],"id":2441997},{"atb":[[1.2,200],[1.21,1.99],[1.19,0],[1.23,184.79]],"id":36909993},{"atb":[[2.18,0],[2.2,67.23]],"id":42609835}],"con":true,"img":false}]}
{"op":"mcm","clk":"5322784436","pt":1646324094868,"mc":[{"id":"1.195532869","rc":[{"atb":[[2.24,3.65],[2.2,33.33]],"id":42609835}],"con":true,"img":false}]}
{"op":"mcm","clk":"5322784477","pt":1646324095062,"mc":[{"id":"1.195532869","rc":[{"atl":[[7,16.67]],"id":2441997},{"atb":[[1.2,0],[1.21,192.47]],"id":36909993}],"con":true,"img":false}]}
{"op":"mcm","clk":"5322784564","pt":1646324095884,"mc":[{"id":"1.195532869","rc":[{"atb":[[2.5,26.67]],"id":42142047}],"con":true,"img":false}]}
{"op":"mcm","clk":"5322784577","pt":1646324095998,"mc":[{"id":"1.195532869","rc":[{"atb":[[2.56,1.99]],"id":42142047}],"con":true,"img":false}]}
{"op":"mcm","clk":"5322784594","pt":1646324096152,"mc":[{"id":"1.195532869","rc":[{"atb":[[1.21,190.48]],"id":36909993}],"con":true,"img":false}]}
{"op":"mcm","clk":"5322784605","pt":1646324096261,"mc":[{"id":"1.195532869","rc":[{"atb":[[1.24,1.99]],"id":36909993}],"con":true,"img":false}]}
{"op":"mcm","clk":"5322784655","pt":1646324096783,"mc":[{"id":"1.195532869","rc":[{"atb":[[2.46,68.49]],"id":42142047},{"atl":[[27,5.77]],"id":42142047}],"con":true,"img":false}]}
{"op":"mcm","clk":"5322784666","pt":1646324096882,"mc":[{"id":"1.195532869","rc":[{"atb":[[1.85,23.26]],"id":2441997},{"atb":[[1.21,0],[1.67,29.41],[1.22,311.17]],"id":36909993}],"con":true,"img":false}]}
{"op":"mcm","clk":"5322784722","pt":1646324097562,"mc":[{"id":"1.195532869","rc":[{"atb":[[1.67,0]],"id":36909993}],"con":true,"img":false}]}
{"op":"mcm","clk":"5322784743","pt":1646324097867,"mc":[{"id":"1.195532869","rc":[{"atb":[[1.7,2.15]],"id":36909993},{"atb":[[2.56,4.14],[2.48,0]],"id":42142047}],"con":true,"img":false}]}
{"op":"mcm","clk":"5322784756","pt":1646324097980,"mc":[{"id":"1.195532869","rc":[{"atb":[[1.85,0]],"id":2441997}],"con":true,"img":false}]}
{"op":"mcm","clk":"5322784770","pt":1646324098086,"mc":[{"id":"1.195532869","rc":[{"atb":[[2.68,59.52]],"id":40302111},{"atl":[[40,2.56]],"id":40302111},{"atb":[[1.57,175.44],[1.23,0]],"id":36909993},{"atb":[[1.88,113.64]],"id":40133336},{"atl":[[7.4,5],[8.4,13.51]],"id":40133336}],"con":true,"img":false}]}
{"op":"mcm","clk":"5322784786","pt":1646324098181,"mc":[{"id":"1.195532869","rc":[{"atl":[[7.6,0]],"id":40133336}],"con":true,"img":false}]}
{"op":"mcm","clk":"5322784858","pt":1646324098756,"mc":[{"id":"1.195532869","rc":[{"atb":[[1.22,181.82]],"id":36909993}],"con":true,"img":false}]}
{"op":"mcm","clk":"5322785080","pt":1646324100882,"mc":[{"id":"1.195532869","rc":[{"atb":[[1.68,0]],"id":40133336}],"con":true,"img":false}]}
{"op":"mcm","clk":"5322785240","pt":1646324102195,"mc":[{"id":"1.195532869","rc":[{"atb":[[2.22,0],[2.18,0],[1.75,0]],"id":40302111},{"atl":[[70,0],[36,0],[40,1.03],[80,0],[60,0]],"id":40302111},{"atb":[[1.68,58.82],[1.22,0]],"id":36909993},{"atb":[[2.36,0],[1.9,0],[2.2,0]],"id":42142047},{"atb":[[1.01,4804.04],[1.67,0],[1.65,0]],"id":40133336},{"atl":[[7.8,5.88]],"id":40133336}],"con":true,"img":false}]}
{"op":"mcm","clk":"5322785262","pt":1646324102396,"mc":[{"id":"1.195532869","rc":[{"atl":[[40,3.36],[44,0]],"id":40302111}],"con":true,"img":false}]}
{"op":"mcm","clk":"5322785331","pt":1646324102871,"mc":[{"id":"1.195532869","rc":[{"atb":[[2.52,0]],"id":42142047}],"con":true,"img":false}]}
{"op":"mcm","clk":"5322785349","pt":1646324102976,"mc":[{"id":"1.195532869","rc":[{"atb":[[2.58,2.16]],"id":42142047}],"con":true,"img":false}]}
{"op":"mcm","clk":"5322785364","pt":1646324103091,"mc":[{"id":"1.195532869","rc":[{"atb":[[2.54,0],[2.58,3.81]],"id":42142047}],"con":true,"img":false}]}
{"op":"mcm","clk":"5322785394","pt":1646324103288,"mc":[{"id":"1.195532869","rc":[{"atb":[[1.18,203.11]],"id":36909993}],"con":true,"img":false}]}
{"op":"mcm","clk":"5322785427","pt":1646324103556,"mc":[{"id":"1.195532869","rc":[{"atl":[[40,2.33],[44,1]],"id":40302111}],"con":true,"img":false}]}
{"op":"mcm","clk":"5322785537","pt":1646324104400,"mc":[{"id":"1.195532869","rc":[{"atb":[[1.52,192.31]],"id":2441997},{"atl":[[8.2,20.83]],"id":2441997},{"atb":[[2.16,86.21]],"id":42609835}],"con":true,"img":false}]}
{"op":"mcm","clk":"5322785573","pt":1646324104708,"mc":[{"id":"1.195532869","rc":[{"atb":[[1.44,0]],"id":2441997},{"atb":[[1.83,0],[1.81,0],[1.69,0]],"id":42609835}],"con":true,"img":false}]}
{"op":"mcm","clk":"5322785727","pt":1646324105820,"mc":[{"id":"1.195532869","rc":[{"atb":[[1.91,40.17]],"id":40133336}],"con":true,"img":false}]}
{"op":"mcm","clk":"5322785811","pt":1646324106597,"mc":[{"id":"1.195532869","rc":[{"atb":[[2.22,0]],"id":42609835}],"con":true,"img":false}]}
{"op":"mcm","clk":"5322785822","pt":1646324106701,"mc":[{"id":"1.195532869","rc":[{"atb":[[2.26,1.99]],"id":42609835}],"con":true,"img":false}]}
{"op":"mcm","clk":"5322785838","pt":1646324106807,"mc":[{"id":"1.195532869","rc":[{"atb":[[2.42,105.63]],"id":42142047},{"atl":[[29,8.93]],"id":42142047}],"con":true,"img":false}]}
{"op":"mcm","clk":"5322785917","pt":1646324107498,"mc":[{"id":"1.195532869","rc":[{"atl":[[40,0],[44,3.33]],"id":40302111}],"con":true,"img":false}]}
{"op":"mcm","clk":"5322785953","pt":1646324107810,"mc":[{"id":"1.195532869","rc":[{"atl":[[44,2.33],[48,1]],"id":40302111},{"atl":[[24,0]],"id":42142047},{"atb":[[2.22,32.79]],"id":42609835}],"con":true,"img":false}]}
{"op":"mcm","clk":"5322785985","pt":1646324108074,"mc":[{"id":"1.195532869","rc":[{"atb":[[1.49,0]],"id":2441997}],"con":true,"img":false}]}
{"op":"mcm","clk":"5322786019","pt":1646324108387,"mc":[{"id":"1.195532869","rc":[{"atb":[[2.56,2.15]],"id":42142047}],"con":true,"img":false}]}
{"op":"mcm","clk":"5322786031","pt":1646324108493,"mc":[{"id":"1.195532869","rc":[{"atb":[[2.6,1.99]],"id":42142047}],"con":true,"img":false}]}
{"op":"mcm","clk":"5322786041","pt":1646324108595,"mc":[{"id":"1.195532869","rc":[{"atb":[[2.28,2.15],[1.87,0]],"id":42609835},{"atb":[[1.7,0],[1.96,2.15]],"id":40133336}],"con":true,"img":false}]}
{"op":"mcm","clk":"5322786061","pt":1646324108807,"mc":[{"id":"1.195532869","rc":[{"atb":[[1.24,0]],"id":36909993},{"atb":[[2.24,1.65],[2.28,4.31]],"id":42609835},{"atb":[[1.96,42.33],[1.93,1.99]],"id":40133336}],"con":true,"img":false}]}
{"op":"mcm","clk":"5322786075","pt":1646324108865,"mc":[{"id":"1.195532869","rc":[{"atb":[[1.02,1.99]],"id":36909993}],"con":true,"img":false}]}
{"op":"mcm","clk":"5322786216","pt":1646324109984,"mc":[{"id":"1.195532869","rc":[{"atb":[[2.26,0]],"id":42609835}],"con":true,"img":false}]}
{"op":"mcm","clk":"5322786232","pt":1646324110080,"mc":[{"id":"1.195532869","rc":[{"atb":[[2.3,1.99]],"id":42609835}],"con":true,"img":false}]}
{"op":"mcm","clk":"5322786256","pt":1646324110295,"mc":[{"id":"1.195532869","rc":[{"atb":[[1.93,0]],"id":40133336}],"con":true,"img":false}]}
{"op":"mcm","clk":"5322786267","pt":1646324110402,"mc":[{"id":"1.195532869","rc":[{"atb":[[1.97,1.99]],"id":40133336}],"con":true,"img":false}]}
{"op":"mcm","clk":"5322786280","pt":1646324110511,"mc":[{"id":"1.195532869","rc":[{"atb":[[2.26,31.75]],"id":42609835}],"con":true,"img":false}]}
{"op":"mcm","clk":"5322786437","pt":1646324111773,"mc":[{"id":"1.195532869","rc":[{"atb":[[2.58,2.16]],"id":42142047},{"atb":[[2.24,0]],"id":42609835}],"con":true,"img":false}]}
{"op":"mcm","clk":"5322786459","pt":1646324111979,"mc":[{"id":"1.195532869","rc":[{"atb":[[2.62,1.65]],"id":42142047},{"atb":[[2.32,1.65]],"id":42609835}],"con":true,"img":false}]}
{"op":"mcm","clk":"5322786477","pt":1646324112083,"mc":[{"id":"1.195532869","rc":[{"atb":[[2.58,0],[2.62,3.65]],"id":42142047}],"con":true,"img":false}]}
{"op":"mcm","clk":"5322786493","pt":1646324112190,"mc":[{"id":"1.195532869","rc":[{"atb":[[1.66,151.52]],"id":36909993},{"atl":[[3.9,51.72]],"id":36909993},{"atb":[[2.28,35.56],[2.26,0]],"id":42609835},{"atb":[[1.86,174.42]],"id":40133336},{"atl":[[8.2,13.89]],"id":40133336}],"con":true,"img":false}]}
{"op":"mcm","clk":"5322786560","pt":1646324112712,"mc":[{"id":"1.195532869","rc":[{"atl":[[44,0],[46,4.96]],"id":40302111},{"atb":[[1.56,8.39]],"id":2441997}],"con":true,"img":false}]}
{"op":"mcm","clk":"5322786590","pt":1646324112872,"mc":[{"id":"1.195532869","rc":[{"atb":[[1.55,2.15],[1.57,8.4]],"id":2441997}],"con":true,"img":false}]}
{"op":"mcm","clk":"5322786620","pt":1646324113082,"mc":[{"id":"1.195532869","rc":[{"atb":[[2.6,0]],"id":42142047}],"con":true,"img":false}]}
{"op":"mcm","clk":"5322786631","pt":1646324113189,"mc":[{"id":"1.195532869","rc":[{"atb":[[2.64,1.99]],"id":42142047}],"con":true,"img":false}]}
{"op":"mcm","clk":"5322786675","pt":1646324113505,"mc":[{"id":"1.195532869","rc":[{"atb":[[2.74,1.99]],"id":40302111},{"atl":[[48,0],[50,1]],"id":40302111},{"atb":[[1.55,74.88],[1.54,0]],"id":2441997},{"atl":[[7,0],[6.6,14.71]],"id":2441997},{"atb":[[1.15,0],[1.13,0],[1.17,0]],"id":36909993},{"atl":[[3.6,0],[70,0],[3.55,14.81]],"id":36909993},{"atl":[[8,0],[7.4,0],[7.6,10],[8.4,0]],"id":40133336}],"con":true,"img":false}]}
{"op":"mcm","clk":"5322786705","pt":1646324113715,"mc":[{"id":"1.195532869","rc":[{"atb":[[1.56,6.4]],"id":2441997},{"atl":[[7,6.67]],"id":2441997},{"atl":[[3.7,0],[3.65,15.09]],"id":36909993},{"atl":[[8,5.71],[7.8,0]],"id":40133336}],"con":true,"img":false}]}
{"op":"mcm","clk":"5322786719","pt":1646324113768,"mc":[{"id":"1.195532869","rc":[{"atb":[[1.58,1.99]],"id":2441997}],"con":true,"img":false}]}
{"op":"mcm","clk":"5322786854","pt":1646324114877,"mc":[{"id":"1.195532869","rc":[{"atb":[[1.18,0]],"id":36909993}],"con":true,"img":false}]}
{"op":"mcm","clk":"5322786988","pt":1646324115783,"mc":[{"id":"1.195532869","rc":[{"atb":[[1.56,77.83],[1.55,2.15],[1.54,9.09]],"id":2441997}],"con":true,"img":false}]}
{"op":"mcm","clk":"5322787043","pt":1646324116311,"mc":[{"id":"1.195532869","rc":[{"atb":[[1.54,0]],"id":2441997}],"con":true,"img":false}]}
{"op":"mcm","clk":"5322787081","pt":1646324116570,"mc":[{"id":"1.195532869","rc":[{"atb":[[2.18,8.93]],"id":42609835}],"con":true,"img":false}]}
{"op":"mcm","clk":"5322787106","pt":1646324116785,"mc":[{"id":"1.195532869","rc":[{"atb":[[2.38,181.16]],"id":42142047},{"atb":[[2.18,0]],"id":42609835}],"con":true,"img":false}]}
{"op":"mcm","clk":"5322787135","pt":1646324116990,"mc":[{"id":"1.195532869","rc":[{"atb":[[1.56,71.43]],"id":2441997}],"con":true,"img":false}]}
{"op":"mcm","clk":"5322787219","pt":1646324117718,"mc":[{"id":"1.195532869","rc":[{"atb":[[2.32,3.65],[2.28,33.4]],"id":42609835}],"con":true,"img":false}]}
{"op":"mcm","clk":"5322787415","pt":1646324119087,"mc":[{"id":"1.195532869","rc":[{"atb":[[2.3,0]],"id":42609835}],"con":true,"img":false}]}
{"op":"mcm","clk":"5322787428","pt":1646324119193,"mc":[{"id":"1.195532869","rc":[{"atb":[[1.6,2.15],[1.55,0]],"id":2441997},{"atb":[[2.34,1.99]],"id":42609835}],"con":true,"img":false}]}
{"op":"mcm","clk":"5322787479","pt":1646324119616,"mc":[{"id":"1.195532869","rc":[{"atb":[[1.56,0],[1.58,70.96],[1.55,8.93]],"id":2441997},{"atb":[[2.3,30.77],[2.28,2.15]],"id":42609835}],"con":true,"img":false}]}
{"op":"mcm","clk":"5322787491","pt":1646324119717,"mc":[{"id":"1.195532869","rc":[{"atb":[[1.53,12.46]],"id":2441997},{"atb":[[1.58,63.03]],"id":36909993}],"con":true,"img":false}]}
{"op":"mcm","clk":"5322787498","pt":1646324119818,"mc":[{"id":"1.195532869","rc":[{"atb":[[1.55,0]],"id":2441997}],"con":true,"img":false}]}
{"op":"mcm","clk":"5322787539","pt":1646324120083,"mc":[{"id":"1.195532869","rc":[{"atb":[[1.58,68.97]],"id":2441997}],"con":true,"img":false}]}
{"op":"mcm","clk":"5322787551","pt":1646324120186,"mc":[{"id":"1.195532869","rc":[{"atb":[[1.61,1.99]],"id":2441997}],"con":true,"img":false}]}
{"op":"mcm","clk":"5322787632","pt":1646324120847,"mc":[{"id":"1.195532869","rc":[{"atb":[[2.62,2]],"id":42142047},{"atb":[[2.32,2]],"id":42609835}],"con":true,"img":false}]}
{"op":"mcm","clk":"5322787655","pt":1646324120986,"mc":[{"id":"1.195532869","rc":[{"atb":[[2.66,1.65]],"id":42142047},{"atb":[[2.36,1.65]],"id":42609835}],"con":true,"img":false}]}
{"op":"mcm","clk":"5322787665","pt":1646324121094,"mc":[{"id":"1.195532869","rc":[{"atb":[[1.59,67.8],[1.58,0]],"id":2441997},{"atb":[[2.66,3.65],[2.62,0]],"id":42142047}],"con":true,"img":false}]}
{"op":"mcm","clk":"5322787723","pt":1646324121618,"mc":[{"id":"1.195532869","rc":[{"atb":[[2.64,0]],"id":42142047}],"con":true,"img":false}]}
{"op":"mcm","clk":"5322787736","pt":1646324121727,"mc":[{"id":"1.195532869","rc":[{"atb":[[1.57,0],[1.61,4.15]],"id":2441997},{"atb":[[2.68,1.99]],"id":42142047}],"con":true,"img":false}]}
{"op":"mcm","clk":"5322787767","pt":1646324121988,"mc":[{"id":"1.195532869","rc":[{"atb":[[2.32,32.3],[2.3,0]],"id":42609835}],"con":true,"img":false}]}
{"op":"mcm","clk":"5322787928","pt":1646324123405,"mc":[{"id":"1.195532869","rc":[{"atb":[[2.64,91.46]],"id":40302111},{"atl":[[60,1.69]],"id":40302111}],"con":true,"img":false}]}
{"op":"mcm","clk":"5322787962","pt":1646324123673,"mc":[{"id":"1.195532869","rc":[{"atb":[[1.64,234.38]],"id":36909993},{"atb":[[1.84,250]],"id":40133336},{"atl":[[8.4,13.51]],"id":40133336}],"con":true,"img":false}]}
{"op":"mcm","clk":"5322787991","pt":1646324124038,"mc":[{"id":"1.195532869","rc":[{"atb":[[1.53,0]],"id":2441997}],"con":true,"img":false}]}
{"op":"mcm","clk":"5322788230","pt":1646324126081,"mc":[{"id":"1.195532869","rc":[{"atl":[[6.4,6.67],[6.6,0]],"id":2441997}],"con":true,"img":false}]}
{"op":"mcm","clk":"5322788239","pt":1646324126186,"mc":[{"id":"1.195532869","rc":[{"atl":[[6.8,4.46]],"id":2441997},{"atb":[[1.58,0]],"id":36909993}],"con":true,"img":false}]}
{"op":"mcm","clk":"5322788251","pt":1646324126291,"mc":[{"id":"1.195532869","rc":[{"atl":[[6.8,11.36],[7,0]],"id":2441997}],"con":true,"img":false}]}
{"op":"mcm","clk":"5322788276","pt":1646324126499,"mc":[{"id":"1.195532869","rc":[{"atb":[[2.36,3.65],[2.32,30.3]],"id":42609835}],"con":true,"img":false}]}
{"op":"mcm","clk":"5322788290","pt":1646324126605,"mc":[{"id":"1.195532869","rc":[{"atb":[[2.36,1.65],[2.34,5.31]],"id":42609835}],"con":true,"img":false}]}
{"op":"mcm","clk":"5322788457","pt":1646324128288,"mc":[{"id":"1.195532869","rc":[{"atl":[[6.8,6.9]],"id":2441997}],"con":true,"img":false}]}
{"op":"mcm","clk":"5322788475","pt":1646324128498,"mc":[{"id":"1.195532869","rc":[{"atb":[[1.53,6.64]],"id":2441997}],"con":true,"img":false}]}
{"op":"mcm","clk":"5322788627","pt":1646324129799,"mc":[{"id":"1.195532869","rc":[{"atb":[[2.66,2]],"id":42142047},{"atb":[[2.38,2.15],[2.28,0]],"id":42609835}],"con":true,"img":false}]}
{"op":"mcm","clk":"5322788639","pt":1646324129904,"mc":[{"id":"1.195532869","rc":[{"atb":[[2.38,4.31]],"id":42609835}],"con":true,"img":false}]}
{"op":"mcm","clk":"5322788650","pt":1646324130009,"mc":[{"id":"1.195532869","rc":[{"atb":[[2.7,1.65]],"id":42142047},{"atb":[[2.38,2.15],[2.34,1.99]],"id":42609835}],"con":true,"img":false}]}
{"op":"mcm","clk":"5322788663","pt":1646324130114,"mc":[{"id":"1.195532869","rc":[{"atb":[[2.66,0],[2.7,3.65]],"id":42142047},{"atb":[[2.36,6.96]],"id":42609835}],"con":true,"img":false}]}
{"op":"mcm","clk":"5322788672","pt":1646324130219,"mc":[{"id":"1.195532869","rc":[{"atb":[[2.68,5.31],[2.7,1.65]],"id":42142047}],"con":true,"img":false}]}
{"op":"mcm","clk":"5322788771","pt":1646324131010,"mc":[{"id":"1.195532869","rc":[{"atb":[[1.69,42.68]],"id":36909993}],"con":true,"img":false}]}
{"op":"mcm","clk":"5322788821","pt":1646324131510,"mc":[{"id":"1.195532869","rc":[{"atb":[[2.32,0],[2.34,31.84],[2.48,8.93]],"id":42609835},{"atb":[[1.96,2.15],[1.95,44.44]],"id":40133336}],"con":true,"img":false}]}
{"op":"mcm","clk":"5322788846","pt":1646324131704,"mc":[{"id":"1.195532869","rc":[{"atb":[[1.9,64.08]],"id":40133336}],"con":true,"img":false}]}
{"op":"mcm","clk":"5322788894","pt":1646324132126,"mc":[{"id":"1.195532869","rc":[{"atb":[[2.34,29.85]],"id":42609835}],"con":true,"img":false}]}
{"op":"mcm","clk":"5322788909","pt":1646324132232,"mc":[{"id":"1.195532869","rc":[{"atb":[[2.5,1.99]],"id":42609835}],"con":true,"img":false}]}
{"op":"mcm","clk":"5322788922","pt":1646324132286,"mc":[{"id":"1.195532869","rc":[{"atb":[[2.48,0]],"id":42609835},{"atb":[[1.89,5],[1.9,44.44]],"id":40133336}],"con":true,"img":false}]}
{"op":"mcm","clk":"5322788938","pt":1646324132392,"mc":[{"id":"1.195532869","rc":[{"atb":[[2.36,1.65],[2.42,10.92]],"id":42609835}],"con":true,"img":false}]}
{"op":"mcm","clk":"5322788947","pt":1646324132495,"mc":[{"id":"1.195532869","rc":[{"atb":[[1.89,0]],"id":40133336}],"con":true,"img":false}]}
{"op":"mcm","clk":"5322789060","pt":1646324133440,"mc":[{"id":"1.195532869","rc":[{"atb":[[2.6,156.25]],"id":40302111},{"atl":[[70,2.17]],"id":40302111}],"con":true,"img":false}]}
{"op":"mcm","clk":"5322789104","pt":1646324133710,"mc":[{"id":"1.195532869","rc":[{"atb":[[1.62,250]],"id":36909993},{"atb":[[2.5,0]],"id":42609835},{"atl":[[8.8,19.23]],"id":40133336}],"con":true,"img":false}]}
{"op":"mcm","clk":"5322789124","pt":1646324133821,"mc":[{"id":"1.195532869","rc":[{"atb":[[2.44,1.99]],"id":42609835}],"con":true,"img":false}]}
{"op":"mcm","clk":"5322789133","pt":1646324133919,"mc":[{"id":"1.195532869","rc":[{"atb":[[2.42,0],[2.38,23.99]],"id":42609835}],"con":true,"img":false}]}
{"op":"mcm","clk":"5322789146","pt":1646324134026,"mc":[{"id":"1.195532869","rc":[{"atb":[[2.42,3.98],[2.38,2.15]],"id":42609835}],"con":true,"img":false}]}
{"op":"mcm","clk":"5322789289","pt":1646324135341,"mc":[{"id":"1.195532869","rc":[{"atb":[[1.91,0]],"id":40133336}],"con":true,"img":false}]}
{"op":"mcm","clk":"5322789396","pt":1646324136240,"mc":[{"id":"1.195532869","rc":[{"atb":[[1.57,175.44]],"id":2441997}],"con":true,"img":false}]}
{"op":"mcm","clk":"5322789476","pt":1646324136821,"mc":[{"id":"1.195532869","rc":[{"atb":[[1.46,0],[1.48,0],[1.52,0]],"id":2441997},{"atb":[[2.4,28.57],[2.34,0]],"id":42609835},{"atl":[[9,0],[8.2,0],[8.4,18.72]],"id":40133336}],"con":true,"img":false}]}
{"op":"mcm","clk":"5322789496","pt":1646324137033,"mc":[{"id":"1.195532869","rc":[{"atl":[[6.4,0],[6.6,13.34]],"id":2441997}],"con":true,"img":false}]}
{"op":"mcm","clk":"5322789692","pt":1646324138819,"mc":[{"id":"1.195532869","rc":[{"atb":[[2.36,0]],"id":42609835}],"con":true,"img":false}]}
{"op":"mcm","clk":"5322789717","pt":1646324139034,"mc":[{"id":"1.195532869","rc":[{"atb":[[2.46,1.65]],"id":42609835}],"con":true,"img":false}]}
{"op":"mcm","clk":"5322789731","pt":1646324139138,"mc":[{"id":"1.195532869","rc":[{"atl":[[6.8,0],[7,6.67]],"id":2441997}],"con":true,"img":false}]}
{"op":"mcm","clk":"5322789745","pt":1646324139246,"mc":[{"id":"1.195532869","rc":[{"atb":[[2.4,0],[2.42,32.15]],"id":42609835}],"con":true,"img":false}]}
{"op":"mcm","clk":"5322789825","pt":1646324139826,"mc":[{"id":"1.195532869","rc":[{"atb":[[1.53,0]],"id":2441997}],"con":true,"img":false}]}
{"op":"mcm","clk":"5322789835","pt":1646324139932,"mc":[{"id":"1.195532869","rc":[{"atb":[[1.91,5.38]],"id":40133336}],"con":true,"img":false}]}
{"op":"mcm","clk":"5322789900","pt":1646324140456,"mc":[{"id":"1.195532869","rc":[{"atl":[[8.4,13.51]],"id":40133336}],"con":true,"img":false}]}
{"op":"mcm","clk":"5322790177","pt":1646324142413,"mc":[{"id":"1.195532869","rc":[{"spn":24.38,"spf":"NaN","id":40302111},{"atb":[[1.62,2.9]],"id":2441997},{"spn":1.62,"spf":1.0,"id":2441997},{"spn":2.62,"spf":"NaN","id":36909993},{"spn":11.85,"spf":"NaN","id":42142047},{"spn":2.42,"spf":1.0,"id":42609835},{"spn":4.78,"spf":"NaN","id":40133336}],"con":true,"img":false}]}
{"op":"mcm","clk":"5322790246","pt":1646324143145,"mc":[{"id":"1.195532869","rc":[{"atb":[[1.61,2.16]],"id":2441997}],"con":true,"img":false}]}
{"op":"mcm","clk":"5322790258","pt":1646324143250,"mc":[{"id":"1.195532869","rc":[{"atb":[[1.63,1.99]],"id":2441997}],"con":true,"img":false}]}
{"op":"mcm","clk":"5322790282","pt":1646324143430,"mc":[{"id":"1.195532869","rc":[{"atl":[[80,3.16]],"id":40302111},{"atb":[[1.63,4.15],[1.61,0]],"id":2441997}],"con":true,"img":false}]}
{"op":"mcm","clk":"5322790313","pt":1646324143732,"mc":[{"id":"1.195532869","rc":[{"atl":[[9.2,30.49]],"id":40133336}],"con":true,"img":false}]}
{"op":"mcm","clk":"5322790323","pt":1646324143837,"mc":[{"id":"1.195532869","rc":[{"atb":[[1.61,65.57]],"id":2441997}],"con":true,"img":false}]}
{"op":"mcm","clk":"5322790386","pt":1646324144517,"mc":[{"id":"1.195532869","rc":[{"atb":[[1.64,2.15],[1.6,0]],"id":2441997}],"con":true,"img":false}]}
{"op":"mcm","clk":"5322790418","pt":1646324144827,"mc":[{"id":"1.195532869","rc":[{"atb":[[1.63,2.16]],"id":2441997}],"con":true,"img":false}]}
{"op":"mcm","clk":"5322790428","pt":1646324144934,"mc":[{"id":"1.195532869","rc":[{"atb":[[1.65,1.99]],"id":2441997}],"con":true,"img":false}]}
{"op":"mcm","clk":"5322790622","pt":1646324146934,"mc":[{"id":"1.195532869","rc":[{"atb":[[1.62,0]],"id":2441997}],"con":true,"img":false}]}
{"op":"mcm","clk":"5322790859","pt":1646324149237,"mc":[{"id":"1.195532869","rc":[{"atb":[[2.38,74.61]],"id":42609835}],"con":true,"img":false}]}
{"op":"mcm","clk":"5322791088","pt":1646324151142,"mc":[{"id":"1.195532869","rc":[{"atb":[[1.62,4.14]],"id":2441997}],"con":true,"img":false}]}
{"op":"mcm","clk":"5322791176","pt":1646324151941,"mc":[{"id":"1.195532869","rc":[{"atb":[[1.63,0],[1.65,4.15]],"id":2441997}],"con":true,"img":false}]}
{"op":"mcm","clk":"5322791374","pt":1646324153849,"mc":[{"id":"1.195532869","rc":[{"atb":[[1.63,63.49]],"id":2441997},{"atl":[[7.4,15.62]],"id":2441997}],"con":true,"img":false}]}
{"op":"mcm","clk":"5322791396","pt":1646324154047,"mc":[{"id":"1.195532869","rc":[{"atb":[[1.56,22.98]],"id":2441997}],"con":true,"img":false}]}
{"op":"mcm","clk":"5322791424","pt":1646324154358,"mc":[{"id":"1.195532869","rc":[{"atb":[[1.56,0]],"id":2441997}],"con":true,"img":false}]}
{"op":"mcm","clk":"5322791749","pt":1646324157593,"mc":[{"id":"1.195532869","rc":[{"atb":[[1.62,0]],"id":2441997}],"con":true,"img":false}]}
{"op":"mcm","clk":"5322791954","pt":1646324159240,"mc":[{"id":"1.195532869","rc":[{"atb":[[2.22,41.72],[2.2,0],[2.16,0],[2.34,111.94]],"id":42609835}],"con":true,"img":false}]}
{"op":"mcm","clk":"5322791986","pt":1646324159557,"mc":[{"id":"1.195532869","rc":[{"atb":[[2.22,32.79]],"id":42609835}],"con":true,"img":false}]}
{"op":"mcm","clk":"5322792064","pt":1646324160241,"mc":[{"id":"1.195532869","rc":[{"atb":[[2.48,2.15]],"id":42609835}],"con":true,"img":false}]}
{"op":"mcm","clk":"5322792077","pt":1646324160351,"mc":[{"id":"1.195532869","rc":[{"atb":[[5.1,5],[5.5,2.5],[4.7,10]],"id":40302111},{"atl":[[20,2.5],[44,1.86],[24,5]],"id":40302111},{"atb":[[2,5],[1.96,10],[1.95,15.01],[2.08,2.5]],"id":2441997},{"atl":[[4.5,2.5],[6.4,14.81],[5.3,10],[4.9,5]],"id":2441997},{"atl":[[2.84,38.1],[3.75,2.5]],"id":36909993},{"atb":[[2.54,10],[2.62,5],[2.7,4.15]],"id":42142047},{"atl":[[9.2,10],[7.6,2.5],[8.4,5]],"id":42142047},{"atb":[[2.42,41.47],[2.38,72.46]],"id":42609835},{"atl":[[6.4,10],[5.8,5],[13,18.25],[5.4,2.5]],"id":42609835},{"atb":[[2,11.78]],"id":40133336},{"atl":[[7,11.78]],"id":40133336}],"con":true,"img":false}]}
{"op":"mcm","clk":"5322792089","pt":1646324160459,"mc":[{"id":"1.195532869","rc":[{"atl":[[60,5.43]],"id":40302111},{"atb":[[1.63,88.5],[1.91,15]],"id":2441997},{"atl":[[4.5,7.5],[6.4,18.71],[7.4,46.04]],"id":2441997},{"atl":[[3.8,94.96]],"id":36909993},{"atb":[[2.5,36.88],[2.7,8.77]],"id":42142047},{"atl":[[21,0],[11,4.62],[25,13.17]],"id":42142047},{"atb":[[2.48,6.27]],"id":42609835},{"atl":[[10.5,0],[8.4,4.12]],"id":42609835},{"atb":[[1.91,25.02]],"id":40133336},{"atl":[[4.5,5],[4.1,2.5],[4.9,10],[8.4,40.31]],"id":40133336}],"con":true,"img":false}]}
{"op":"mcm","clk":"5322792104","pt":1646324160565,"mc":[{"id":"1.195532869","rc":[{"atb":[[1.85,10.69],[1.65,1.99]],"id":2441997},{"atl":[[6.6,0]],"id":2441997},{"atl":[[2.82,15.09],[2.84,0],[3.55,0]],"id":36909993},{"atl":[[9.2,14]],"id":42142047},{"atl":[[6.4,13.81],[11,5.82]],"id":42609835},{"atl":[[7.6,0],[6.8,10],[7,0]],"id":40133336}],"con":true,"img":false}]}
{"op":"mcm","clk":"5322792119","pt":1646324160674,"mc":[{"id":"1.195532869","rc":[{"atb":[[2.72,5.31],[2.68,1.99]],"id":42142047},{"atl":[[4,5.62]],"id":40133336}],"con":true,"img":false}]}
{"op":"mcm","clk":"5322792134","pt":1646324160782,"mc":[{"id":"1.195532869","rc":[{"atb":[[1.85,0]],"id":2441997},{"atl":[[2.82,0],[2.8,12.94],[2.86,10.26],[3.55,30.18]],"id":36909993},{"atl":[[11,0]],"id":42609835},{"atl":[[6.8,0],[4.9,20]],"id":40133336}],"con":true,"img":false}]}
{"op":"mcm","clk":"5322792150","pt":1646324160840,"mc":[{"id":"1.195532869","rc":[{"atl":[[6.4,14.81]],"id":2441997},{"atb":[[2.72,0],[2.68,0],[2.7,14.08]],"id":42142047}],"con":true,"img":false}]}
{"op":"mcm","clk":"5322792160","pt":1646324160945,"mc":[{"id":"1.195532869","rc":[{"atl":[[2.86,0]],"id":36909993},{"atb":[[2.74,1.99]],"id":42142047}],"con":true,"img":false}]}
{"op":"mcm","clk":"5322792173","pt":1646324161054,"mc":[{"id":"1.195532869","rc":[{"atl":[[2.8,0]],"id":36909993}],"con":true,"img":false}]}
{"op":"mcm","clk":"5322792188","pt":1646324161160,"mc":[{"id":"1.195532869","rc":[{"atl":[[2.82,33.95]],"id":36909993},{"atb":[[2.44,0]],"id":42609835}],"con":true,"img":false}]}
{"op":"mcm","clk":"5322792196","pt":1646324161266,"mc":[{"id":"1.195532869","rc":[{"atb":[[2.5,1.99]],"id":42609835}],"con":true,"img":false}]}
{"op":"mcm","clk":"5322792217","pt":1646324161479,"mc":[{"id":"1.195532869","rc":[{"atb":[[1.65,0]],"id":2441997}],"con":true,"img":false}]}
{"op":"mcm","clk":"5322792228","pt":1646324161544,"mc":[{"id":"1.195532869","rc":[{"atb":[[2.1,1.99]],"id":2441997}],"con":true,"img":false}]}
{"op":"mcm","clk":"5322792242","pt":1646324161644,"mc":[{"id":"1.195532869","rc":[{"atb":[[2.74,0]],"id":40302111}],"con":true,"img":false}]}
{"op":"mcm","clk":"5322792252","pt":1646324161748,"mc":[{"id":"1.195532869","rc":[{"atb":[[5.6,1.99]],"id":40302111}],"con":true,"img":false}]}
{"op":"mcm","clk":"5322792271","pt":1646324161962,"mc":[{"id":"1.195532869","rc":[{"atb":[[4.6,5]],"id":40302111},{"atb":[[1.66,2.9]],"id":2441997},{"atb":[[1.97,0]],"id":40133336}],"con":true,"img":false}]}
{"op":"mcm","clk":"5322792279","pt":1646324162069,"mc":[{"id":"1.195532869","rc":[{"atb":[[2.02,1.99]],"id":40133336}],"con":true,"img":false}]}
{"op":"mcm","clk":"5322792367","pt":1646324162762,"mc":[{"id":"1.195532869","rc":[{"atb":[[4.6,0]],"id":40302111}],"con":true,"img":false}]}
{"op":"mcm","clk":"5322792381","pt":1646324162869,"mc":[{"id":"1.195532869","rc":[{"atb":[[2.74,0]],"id":42142047}],"con":true,"img":false}]}
{"op":"mcm","clk":"5322792391","pt":1646324162973,"mc":[{"id":"1.195532869","rc":[{"atb":[[2.72,1.99]],"id":42142047}],"con":true,"img":false}]}
{"op":"mcm","clk":"5322792402","pt":1646324163078,"mc":[{"id":"1.195532869","rc":[{"atb":[[2.66,7.04],[2.62,13.44]],"id":42142047}],"con":true,"img":false}]}
{"op":"mcm","clk":"5322792439","pt":1646324163447,"mc":[{"id":"1.195532869","rc":[{"atb":[[2.62,5]],"id":42142047}],"con":true,"img":false}]}
{"op":"mcm","clk":"5322792466","pt":1646324163657,"mc":[{"id":"1.195532869","rc":[{"atb":[[1.65,7.35]],"id":36909993}],"con":true,"img":false}]}
{"op":"mcm","clk":"5322792491","pt":1646324163866,"mc":[{"id":"1.195532869","rc":[{"atb":[[1.63,25.01],[1.86,46.51]],"id":2441997},{"atl":[[7,0],[4.7,10.81]],"id":2441997}],"con":true,"img":false}]}
{"op":"mcm","clk":"5322792503","pt":1646324163971,"mc":[{"id":"1.195532869","rc":[{"atb":[[1.65,0]],"id":36909993}],"con":true,"img":false}]}
{"op":"mcm","clk":"5322792511","pt":1646324164076,"mc":[{"id":"1.195532869","rc":[{"atl":[[5.4,5]],"id":2441997},{"atb":[[1.91,19.64]],"id":40133336}],"con":true,"img":false}]}
{"op":"mcm","clk":"5322792575","pt":1646324164553,"mc":[{"id":"1.195532869","rc":[{"atb":[[2.72,0],[3.3,17.39]],"id":40302111},{"atl":[[22,1.9],[50,0]],"id":40302111},{"atl":[[3.65,0]],"id":36909993},{"atl":[[8,5.71],[23,0]],"id":42142047},{"atb":[[2.42,13.3],[2.46,29.05]],"id":42609835},{"atl":[[5.6,8.7],[11.5,0]],"id":42609835},{"atl":[[8,0],[4.2,12.5]],"id":40133336}],"con":true,"img":false}]}
{"op":"mcm","clk":"5322792589","pt":1646324164657,"mc":[{"id":"1.195532869","rc":[{"atl":[[22,6.66],[46,2.74]],"id":40302111},{"atl":[[2.86,21.51]],"id":36909993},{"atl":[[9.2,10],[7.8,5.71]],"id":42142047},{"atl":[[6.4,10]],"id":42609835}],"con":true,"img":false}]}
{"op":"mcm","clk":"5322792601","pt":1646324164764,"mc":[{"id":"1.195532869","rc":[{"atl":[[5.4,0]],"id":2441997},{"atb":[[2.66,0]],"id":42142047},{"atl":[[5.5,8.7]],"id":42609835}],"con":true,"img":false}]}
{"op":"mcm","clk":"5322792612","pt":1646324164871,"mc":[{"id":"1.195532869","rc":[{"atl":[[8,13.92],[7.8,0]],"id":42142047}],"con":true,"img":false}]}
{"op":"mcm","clk":"5322792728","pt":1646324165656,"mc":[{"id":"1.195532869","rc":[{"atl":[[4.5,2.5],[4.9,23.31]],"id":2441997}],"con":true,"img":false}]}
{"op":"mcm","clk":"5322792743","pt":1646324165761,"mc":[{"id":"1.195532869","rc":[{"atb":[[2.76,0]],"id":40302111},{"atb":[[2.7,12.43]],"id":42142047},{"atb":[[2.46,27.4]],"id":42609835}],"con":true,"img":false}]}
{"op":"mcm","clk":"5322792765","pt":1646324165972,"mc":[{"id":"1.195532869","rc":[{"atb":[[5.7,1.65]],"id":40302111},{"atb":[[2.12,1.65]],"id":2441997},{"atb":[[2.74,1.65]],"id":42142047},{"atb":[[2.52,1.65]],"id":42609835},{"atb":[[2.04,1.65]],"id":40133336}],"con":true,"img":false}]}
{"op":"mcm","clk":"5322792806","pt":1646324166241,"mc":[{"id":"1.195532869","rc":[{"atb":[[1.66,0]],"id":2441997}],"con":true,"img":false}]}
{"op":"mcm","clk":"5322792820","pt":1646324166346,"mc":[{"id":"1.195532869","rc":[{"atb":[[2.46,0]],"id":42609835}],"con":true,"img":false}]}
{"op":"mcm","clk":"5322792834","pt":1646324166451,"mc":[{"id":"1.195532869","rc":[{"atb":[[2.48,33.3]],"id":42609835}],"con":true,"img":false}]}
{"op":"mcm","clk":"5322793111","pt":1646324168875,"mc":[{"id":"1.195532869","rc":[{"atb":[[1.96,6.9]],"id":40133336}],"con":true,"img":false}]}
{"op":"mcm","clk":"5322793153","pt":1646324169190,"mc":[{"id":"1.195532869","rc":[{"atb":[[2.74,3.65],[2.7,7.12]],"id":42142047},{"atl":[[4.9,10],[4.2,25]],"id":40133336}],"con":true,"img":false}]}
{"op":"mcm","clk":"5322793231","pt":1646324169885,"mc":[{"id":"1.195532869","rc":[{"atl":[[22,1.9],[24,9.35]],"id":40302111},{"atl":[[5.6,19.9],[5.5,0]],"id":42609835}],"con":true,"img":false}]}
{"op":"mcm","clk":"5322793247","pt":1646324169988,"mc":[{"id":"1.195532869","rc":[{"atb":[[2.72,0]],"id":42142047},{"atl":[[8,5.7],[8.4,18.51]],"id":42142047}],"con":true,"img":false}]}
{"op":"mcm","clk":"5322793259","pt":1646324170097,"mc":[{"id":"1.195532869","rc":[{"atb":[[2.76,1.99]],"id":42142047}],"con":true,"img":false}]}
{"op":"mcm","clk":"5322793282","pt":1646324170263,"mc":[{"id":"1.195532869","rc":[{"atb":[[1.9,0],[1.86,46.51]],"id":40133336}],"con":true,"img":false}]}
{"op":"mcm","clk":"5322793294","pt":1646324170366,"mc":[{"id":"1.195532869","rc":[{"atb":[[1.89,5.56]],"id":40133336}],"con":true,"img":false}]}
{"op":"mcm","clk":"5322793306","pt":1646324170470,"mc":[{"id":"1.195532869","rc":[{"atb":[[1.89,0]],"id":40133336}],"con":true,"img":false}]}
{"op":"mcm","clk":"5322793317","pt":1646324170577,"mc":[{"id":"1.195532869","rc":[{"atb":[[1.88,0]],"id":40133336}],"con":true,"img":false}]}
{"op":"mcm","clk":"5322793354","pt":1646324170948,"mc":[{"id":"1.195532869","rc":[{"atb":[[2.06,2.15]],"id":2441997},{"atb":[[2.06,2.15]],"id":40133336}],"con":true,"img":false}]}
{"op":"mcm","clk":"5322793365","pt":1646324171052,"mc":[{"id":"1.195532869","rc":[{"atb":[[1.64,0],[1.63,0]],"id":2441997},{"atb":[[1.96,4.74]],"id":40133336}],"con":true,"img":false}]}
{"op":"mcm","clk":"5322793410","pt":1646324171486,"mc":[{"id":"1.195532869","rc":[{"atb":[[2.02,4.37]],"id":2441997}],"con":true,"img":false}]}
{"op":"mcm","clk":"5322793560","pt":1646324172551,"mc":[{"id":"1.195532869","rc":[{"atb":[[2.02,0]],"id":40133336}],"con":true,"img":false}]}
{"op":"mcm","clk":"5322793571","pt":1646324172658,"mc":[{"id":"1.195532869","rc":[{"atb":[[2.08,1.99]],"id":40133336}],"con":true,"img":false}]}
{"op":"mcm","clk":"5322793707","pt":1646324173867,"mc":[{"id":"1.195532869","rc":[{"atb":[[1.84,119.05]],"id":2441997},{"atl":[[4.9,48.95]],"id":2441997}],"con":true,"img":false}]}
{"op":"mcm","clk":"5322793787","pt":1646324174502,"mc":[{"id":"1.195532869","rc":[{"atb":[[1.59,0],[1.82,67.8],[1.57,0],[1.91,0],[1.61,0]],"id":2441997},{"atl":[[8.2,0]],"id":2441997},{"atb":[[2,0],[1.89,112.36],[1.95,0]],"id":40133336}],"con":true,"img":false}]}
{"op":"mcm","clk":"5322793798","pt":1646324174558,"mc":[{"id":"1.195532869","rc":[{"atb":[[3.2,45.45]],"id":40302111},{"atl":[[24,13.7]],"id":40302111},{"atb":[[2,5.82]],"id":40133336}],"con":true,"img":false}]}
{"op":"mcm","clk":"5322793809","pt":1646324174652,"mc":[{"id":"1.195532869","rc":[{"atl":[[2.9,52.63]],"id":36909993},{"atl":[[8.4,32.02]],"id":42142047}],"con":true,"img":false}]}
{"op":"mcm","clk":"5322793823","pt":1646324174771,"mc":[{"id":"1.195532869","rc":[{"atl":[[2.9,105.26],[3.55,0]],"id":36909993},{"atb":[[2.74,2]],"id":42142047},{"atb":[[2.04,0]],"id":40133336}],"con":true,"img":false}]}
{"op":"mcm","clk":"5322793837","pt":1646324174866,"mc":[{"id":"1.195532869","rc":[{"atb":[[2.78,1.65]],"id":42142047},{"atb":[[2.1,1.65]],"id":40133336}],"con":true,"img":false}]}
{"op":"mcm","clk":"5322793851","pt":1646324174986,"mc":[{"id":"1.195532869","rc":[{"atb":[[2,0]],"id":40133336}],"con":true,"img":false}]}
{"op":"mcm","clk":"5322793862","pt":1646324175094,"mc":[{"id":"1.195532869","rc":[{"atl":[[5.6,8.7],[5.8,25.83]],"id":42609835},{"atb":[[1.91,0]],"id":40133336}],"con":true,"img":false}]}
{"op":"mcm","clk":"5322793949","pt":1646324175785,"mc":[{"id":"1.195532869","rc":[{"atb":[[1.96,0]],"id":40133336}],"con":true,"img":false}]}
{"op":"mcm","clk":"5322794024","pt":1646324176365,"mc":[{"id":"1.195532869","rc":[{"atb":[[2.44,69.44]],"id":42609835},{"atl":[[5.8,46.66]],"id":42609835}],"con":true,"img":false}]}
{"op":"mcm","clk":"5322794157","pt":1646324177480,"mc":[{"id":"1.195532869","rc":[{"atb":[[2.74,0],[2.78,3.65]],"id":42142047}],"con":true,"img":false}]}
{"op":"mcm","clk":"5322794172","pt":1646324177581,"mc":[{"id":"1.195532869","rc":[{"atb":[[2.6,0]],"id":40302111},{"atl":[[80,0]],"id":40302111},{"atl":[[3.8,59.25],[3.9,0],[60,0]],"id":36909993},{"atl":[[25,9],[27,0],[29,0]],"id":42142047},{"atb":[[2.22,0],[2.38,0],[2.34,0]],"id":42609835},{"atl":[[13.5,0],[14.5,0]],"id":42609835}],"con":true,"img":false}]}
{"op":"mcm","clk":"5322794209","pt":1646324177887,"mc":[{"id":"1.195532869","rc":[{"atl":[[4.4,3.75]],"id":2441997},{"atl":[[2.82,39.32],[2.8,44.44]],"id":36909993},{"atb":[[2.42,3.98],[2.44,121.95]],"id":42609835},{"atl":[[5.8,87.63],[13,3.33]],"id":42609835}],"con":true,"img":false}]}
{"op":"mcm","clk":"5322794219","pt":1646324177991,"mc":[{"id":"1.195532869","rc":[{"atl":[[19.5,3.37],[24,23.6],[60,1.69]],"id":40302111},{"atl":[[7.4,15.62],[4.9,61.25]],"id":2441997},{"atl":[[2.9,187.24]],"id":36909993},{"atb":[[2.5,26.67],[2.78,10.68],[2.62,18.39]],"id":42142047},{"atl":[[7.4,7.03],[25,0],[8.4,53.44]],"id":42142047},{"atb":[[2.5,10.39]],"id":42609835},{"atl":[[5.3,8.4]],"id":42609835},{"atb":[[1.89,123.95]],"id":40133336},{"atl":[[4.2,43.54],[8.4,13.51]],"id":40133336}],"con":true,"img":false}]}
{"op":"mcm","clk":"5322794233","pt":1646324178094,"mc":[{"id":"1.195532869","rc":[{"atl":[[6.4,0],[4.9,42.94],[4.7,21.62]],"id":2441997},{"atl":[[2.82,0],[2.86,75.27],[2.9,134.61],[3.8,0]],"id":36909993},{"atb":[[2.76,0]],"id":42142047}],"con":true,"img":false}]}
{"op":"mcm","clk":"5322794246","pt":1646324178162,"mc":[{"id":"1.195532869","rc":[{"atl":[[19,2.5],[44,0],[24,19.25]],"id":40302111},{"atb":[[2.8,1.99],[2.7,2.5]],"id":42142047},{"atl":[[7.2,5.71],[11,0],[8.4,39.93]],"id":42142047},{"atb":[[2.48,29.18]],"id":42609835},{"atl":[[8.4,0]],"id":42609835}],"con":true,"img":false}]}
{"op":"mcm","clk":"5322794283","pt":1646324178473,"mc":[{"id":"1.195532869","rc":[{"atl":[[20,4.61],[22,0]],"id":40302111},{"atl":[[4.6,11.11],[4.7,10.81]],"id":2441997},{"atl":[[2.84,21.74]],"id":36909993},{"atl":[[7.6,8.56]],"id":42142047},{"atl":[[5.5,8.89]],"id":42609835}],"con":true,"img":false}]}
{"op":"mcm","clk":"5322794552","pt":1646324180289,"mc":[{"id":"1.195532869","rc":[{"atb":[[1.84,119.05],[1.87,9.12]],"id":40133336},{"atl":[[4.4,29.41]],"id":40133336}],"con":true,"img":false}]}
{"op":"mcm","clk":"5322794714","pt":1646324181667,"mc":[{"id":"1.195532869","rc":[{"atb":[[2.56,2.15],[2.48,27.03]],"id":42609835},{"atb":[[1.92,2.15],[2.06,0]],"id":40133336}],"con":true,"img":false}]}
{"op":"mcm","clk":"5322794801","pt":1646324182392,"mc":[{"id":"1.195532869","rc":[{"atb":[[2.02,0]],"id":2441997}],"con":true,"img":false}]}
{"op":"mcm","clk":"5322794820","pt":1646324182602,"mc":[{"id":"1.195532869","rc":[{"atb":[[1.82,0],[1.87,67.8]],"id":2441997},{"atb":[[2.5,37.06],[2.46,13.62]],"id":42609835},{"atl":[[9.2,0]],"id":40133336}],"con":true,"img":false}]}
{"op":"mcm","clk":"5322794859","pt":1646324182877,"mc":[{"id":"1.195532869","rc":[{"atb":[[2.5,35.07]],"id":42609835}],"con":true,"img":false}]}
{"op":"mcm","clk":"5322794871","pt":1646324182983,"mc":[{"id":"1.195532869","rc":[{"atb":[[2.46,0],[2.58,1.99]],"id":42609835}],"con":true,"img":false}]}
{"op":"mcm","clk":"5322794898","pt":1646324183190,"mc":[{"id":"1.195532869","rc":[{"atb":[[2.08,0]],"id":40133336}],"con":true,"img":false}]}
{"op":"mcm","clk":"5322794913","pt":1646324183295,"mc":[{"id":"1.195532869","rc":[{"atl":[[19,0],[20,9.87]],"id":40302111},{"atl":[[7.2,0],[7.6,21.3]],"id":42142047},{"atl":[[5.8,66.8],[5.5,19.79]],"id":42609835},{"atb":[[1.93,1.99]],"id":40133336}],"con":true,"img":false}]}
{"op":"mcm","clk":"5322794924","pt":1646324183392,"mc":[{"id":"1.195532869","rc":[{"atb":[[1.92,8.24]],"id":40133336}],"con":true,"img":false}]}
{"op":"mcm","clk":"5322794979","pt":1646324183771,"mc":[{"id":"1.195532869","rc":[{"atb":[[2.78,9.03]],"id":42142047},{"atb":[[2.52,0]],"id":42609835},{"atb":[[2.1,0]],"id":40133336}],"con":true,"img":false}]}
{"op":"mcm","clk":"5322795001","pt":1646324183979,"mc":[{"id":"1.195532869","rc":[{"atb":[[2.82,1.65]],"id":42142047},{"atb":[[2.6,1.65]],"id":42609835},{"atb":[[1.89,11.59],[1.91,46.51]],"id":40133336}],"con":true,"img":false}]}
{"op":"mcm","clk":"5322795134","pt":1646324185123,"mc":[{"id":"1.195532869","rc":[{"atl":[[20,7.76],[21,2]],"id":40302111},{"atl":[[7.6,15.24],[7.8,5.88]],"id":42142047}],"con":true,"img":false}]}
{"op":"mcm","clk":"5322795214","pt":1646324185667,"mc":[{"id":"1.195532869","rc":[{"atb":[[2.82,3.65],[2.78,7.03]],"id":42142047}],"con":true,"img":false}]}
{"op":"mcm","clk":"5322795261","pt":1646324186098,"mc":[{"id":"1.195532869","rc":[{"atb":[[2.8,0]],"id":42142047}],"con":true,"img":false}]}
{"op":"mcm","clk":"5322795272","pt":1646324186201,"mc":[{"id":"1.195532869","rc":[{"atb":[[2.84,1.99]],"id":42142047}],"con":true,"img":false}]}
{"op":"mcm","clk":"5322795353","pt":1646324186985,"mc":[{"id":"1.195532869","rc":[{"atb":[[2.02,4.37]],"id":2441997},{"atb":[[1.87,0]],"id":40133336}],"con":true,"img":false}]}
{"op":"mcm","clk":"5322795500","pt":1646324188409,"mc":[{"id":"1.195532869","rc":[{"atl":[[20,2.5],[21,7]],"id":40302111},{"atl":[[7.8,20.59]],"id":42142047}],"con":true,"img":false}]}
{"op":"mcm","clk":"5322795514","pt":1646324188502,"mc":[{"id":"1.195532869","rc":[{"atb":[[1.82,182.93]],"id":2441997},{"atl":[[2.88,53.19]],"id":36909993},{"atl":[[7.6,2.5]],"id":42142047}],"con":true,"img":false}]}
{"op":"mcm","clk":"5322795586","pt":1646324189188,"mc":[{"id":"1.195532869","rc":[{"atb":[[1.91,0],[1.9,46.51]],"id":40133336}],"con":true,"img":false}]}
{"op":"mcm","clk":"5322795685","pt":1646324190291,"mc":[{"id":"1.195532869","rc":[{"atb":[[1.82,182.93]],"id":40133336},{"atl":[[4.6,41.67]],"id":40133336}],"con":true,"img":false}]}
{"op":"mcm","clk":"5322795825","pt":1646324191605,"mc":[{"id":"1.195532869","rc":[{"atb":[[1.93,9.15]],"id":40133336}],"con":true,"img":false}]}
{"op":"mcm","clk":"5322795928","pt":1646324192603,"mc":[{"id":"1.195532869","rc":[{"atb":[[2.46,68.49]],"id":42609835},{"atl":[[5.7,21.28]],"id":42609835}],"con":true,"img":false}]}
{"op":"mcm","clk":"5322795954","pt":1646324192777,"mc":[{"id":"1.195532869","rc":[{"atb":[[2.82,2]],"id":42142047}],"con":true,"img":false}]}
{"op":"mcm","clk":"5322795964","pt":1646324192873,"mc":[{"id":"1.195532869","rc":[{"atb":[[2.86,1.65]],"id":42142047}],"con":true,"img":false}]}
{"op":"mcm","clk":"5322796038","pt":1646324193408,"mc":[{"id":"1.195532869","rc":[{"atl":[[5.6,0],[5.8,45.97],[13,0]],"id":42609835},{"atl":[[8.8,0]],"id":40133336}],"con":true,"img":false}]}
{"op":"mcm","clk":"5322796150","pt":1646324193783,"mc":[{"id":"1.195532869","rc":[{"atb":[[2.82,0],[2.86,3.65]],"id":42142047}],"con":true,"img":false}]}
{"op":"mcm","clk":"5322796214","pt":1646324194314,"mc":[{"id":"1.195532869","rc":[{"atb":[[2.84,0]],"id":42142047}],"con":true,"img":false}]}
{"op":"mcm","clk":"5322796228","pt":1646324194407,"mc":[{"id":"1.195532869","rc":[{"atb":[[2.88,1.99]],"id":42142047}],"con":true,"img":false}]}
{"op":"mcm","clk":"5322796299","pt":1646324195111,"mc":[{"id":"1.195532869","rc":[{"atb":[[3.1,71.43]],"id":40302111},{"atl":[[8.2,13.89]],"id":42142047},{"atb":[[2.5,50.13],[2.44,69.44]],"id":42609835},{"atl":[[5.8,5],[5.5,43.89]],"id":42609835},{"atl":[[4.3,4.46]],"id":40133336}],"con":true,"img":false}]}
{"op":"mcm","clk":"5322796310","pt":1646324195212,"mc":[{"id":"1.195532869","rc":[{"atl":[[21,18.9],[24,9.35]],"id":40302111},{"atl":[[4.6,23.41],[4.9,30.64]],"id":2441997},{"atl":[[2.86,162.69],[2.9,52.63]],"id":36909993},{"atb":[[2.86,11.67],[2.62,5],[2.7,18.35]],"id":42142047},{"atl":[[7.8,45.95],[8.4,18.51]],"id":42142047},{"atl":[[5.2,3.5]],"id":42609835},{"atb":[[1.89,0],[1.9,68.27]],"id":40133336}],"con":true,"img":false}]}
{"op":"mcm","clk":"5322796320","pt":1646324195307,"mc":[{"id":"1.195532869","rc":[{"atb":[[2.78,0]],"id":42142047},{"atb":[[2.42,7.52]],"id":42609835},{"atl":[[4.3,0]],"id":40133336}],"con":true,"img":false}]}
{"op":"mcm","clk":"5322796334","pt":1646324195410,"mc":[{"id":"1.195532869","rc":[{"atb":[[2.42,3.98]],"id":42609835},{"atl":[[5.3,0]],"id":42609835}],"con":true,"img":false}]}
{"op":"mcm","clk":"5322796475","pt":1646324196589,"mc":[{"id":"1.195532869","rc":[{"atl":[[5.4,6.7]],"id":42609835}],"con":true,"img":false}]}
{"op":"mcm","clk":"5322796530","pt":1646324197221,"mc":[{"id":"1.195532869","rc":[{"atl":[[5.4,2.5]],"id":42609835}],"con":true,"img":false}]}
{"op":"mcm","clk":"5322796647","pt":1646324198517,"mc":[{"id":"1.195532869","rc":[{"atb":[[1.8,250]],"id":2441997},{"atl":[[2.92,78.12]],"id":36909993}],"con":true,"img":false}]}
{"op":"mcm","clk":"5322796803","pt":1646324199798,"mc":[{"id":"1.195532869","rc":[{"atb":[[2.64,0]],"id":40302111},{"atl":[[2.86,141.18],[2.9,0]],"id":36909993},{"atl":[[5.4,11.59]],"id":42609835}],"con":true,"img":false}]}
{"op":"mcm","clk":"5322796818","pt":1646324199901,"mc":[{"id":"1.195532869","rc":[{"atl":[[2.88,63.94]],"id":36909993},{"atl":[[7.8,48.98]],"id":42142047},{"atb":[[1.89,112.36],[1.9,21.76]],"id":40133336}],"con":true,"img":false}]}
{"op":"mcm","clk":"5322796859","pt":1646324200312,"mc":[{"id":"1.195532869","rc":[{"atb":[[1.8,250]],"id":40133336},{"atl":[[4.8,65.79]],"id":40133336}],"con":true,"img":false}]}
{"op":"mcm","clk":"5322796878","pt":1646324200499,"mc":[{"id":"1.195532869","rc":[{"atb":[[1.93,22.21]],"id":40133336}],"con":true,"img":false}]}
{"op":"mcm","clk":"5322796889","pt":1646324200607,"mc":[{"id":"1.195532869","rc":[{"atb":[[1.92,2.15]],"id":40133336}],"con":true,"img":false}]}
{"op":"mcm","clk":"5322796915","pt":1646324200813,"mc":[{"id":"1.195532869","rc":[{"atl":[[8.4,0]],"id":40133336}],"con":true,"img":false}]}
{"op":"mcm","clk":"5322796964","pt":1646324201222,"mc":[{"id":"1.195532869","rc":[{"atl":[[7.8,45.95]],"id":42142047}],"con":true,"img":false}]}
{"op":"mcm","clk":"5322796981","pt":1646324201339,"mc":[{"id":"1.195532869","rc":[{"atl":[[2.88,53.19]],"id":36909993}],"con":true,"img":false}]}
{"op":"mcm","clk":"5322797055","pt":1646324201817,"mc":[{"id":"1.195532869","rc":[{"atb":[[2.86,10.02]],"id":42142047}],"con":true,"img":false}]}
{"op":"mcm","clk":"5322797069","pt":1646324201921,"mc":[{"id":"1.195532869","rc":[{"atb":[[1.92,0],[1.96,2.15]],"id":40133336}],"con":true,"img":false}]}
{"op":"mcm","clk":"5322797084","pt":1646324202025,"mc":[{"id":"1.195532869","rc":[{"atb":[[2.9,1.65]],"id":42142047}],"con":true,"img":false}]}
{"op":"mcm","clk":"5322797107","pt":1646324202227,"mc":[{"id":"1.195532869","rc":[{"atb":[[2.9,3.65],[2.86,8.02]],"id":42142047}],"con":true,"img":false}]}
{"op":"mcm","clk":"5322797122","pt":1646324202297,"mc":[{"id":"1.195532869","rc":[{"atb":[[1.93,20.22]],"id":40133336}],"con":true,"img":false}]}
{"op":"mcm","clk":"5322799421","pt":1646324202565,"mc":[{"id":"1.195532869","marketDefinition":{"bspMarket":true,"turnInPlayEnabled":false,"persistenceEnabled":false,"marketBaseRate":5.0,"eventId":"31275720","eventTypeId":"4339","numberOfWinners":2,"bettingType":"ODDS","marketType":"PLACE","marketTime":"2022-03-03T16:28:00.000Z","suspendTime":"2022-03-03T16:28:00.000Z","bspReconciled":false,"complete":true,"inPlay":false,"crossMatching":true,"runnersVoidable":false,"numberOfActiveRunners":6,"betDelay":0,"status":"OPEN","runners":[{"status":"ACTIVE","sortPriority":1,"id":42142047,"name":"1. Underground Girl"},{"status":"ACTIVE","sortPriority":2,"id":36909993,"name":"2. Brosna Misty"},{"status":"ACTIVE","sortPriority":3,"id":42609835,"name":"3. Slaneyside Nally"},{"status":"ACTIVE","sortPriority":4,"id":2441997,"name":"4. Fine Line"},{"status":"ACTIVE","sortPriority":5,"id":40302111,"name":"5. Urry Up Alex"},{"status":"ACTIVE","sortPriority":6,"id":40133336,"name":"6. Mayses Stan"}],"regulators":["MR_INT"],"venue":"Romford","countryCode":"GB","discountAllowed":true,"timezone":"Europe/London","openDate":"2022-03-03T13:57:00.000Z","version":4384107310,"name":"To Be Placed","eventName":"Romford 3rd Mar"},"rc":[{"atb":[[5.6,1.99],[2.36,2.15],[5.1,5],[3.2,45.45],[1.01,4804.04],[3.1,71.43],[5.5,2.5],[5.7,1.65],[3.3,17.39],[2.68,59.52],[4.7,10]],"id":40302111},{"atl":[[70,2.17],[19.5,3.37],[20,2.5],[21,18.9],[46,2.74],[24,9.35],[60,1.69],[1000,5]],"id":40302111},{"spn":12.6,"spf":"NaN","id":40302111},{"atb":[[2,5],[1.01,4804.04],[1.84,119.05],[2.12,1.65],[1.96,10],[1.95,15.01],[1.87,67.8],[2.1,1.99],[2.08,2.5],[1.82,182.93],[1.8,250],[2.02,4.37],[2.06,2.15],[1.86,46.51]],"id":2441997},{"spl":[[1.01,1]],"id":2441997},{"atl":[[4.5,2.5],[4.6,23.41],[5.3,10],[7.4,15.62],[46,2.74],[4.9,30.64],[4.4,3.75],[7.8,14.71],[4.7,10.81],[1000,5]],"id":2441997},{"spn":2.12,"spf":1.0,"id":2441997},{"atb":[[1.64,234.38],[1.01,4804.04],[1.57,175.44],[1.02,1.99],[1.7,2.15],[1.68,58.82],[1.62,250],[1.66,151.52],[1.69,42.68]],"id":36909993},{"atl":[[2.8,44.44],[2.92,78.12],[2.88,53.19],[2.86,141.18],[46,2.74],[2.84,21.74],[3.75,2.5],[1000,5]],"id":36909993},{"spn":2.25,"spf":"NaN","id":36909993},{"atb":[[2.56,2.15],[2.88,1.99],[2.54,10],[1.01,4804.04],[2.9,3.65],[2.86,8.02],[2.5,26.67],[2.42,105.63],[2.38,181.16],[2.46,68.49],[2.62,5],[2.7,18.35]],"id":42142047},{"atl":[[8,5.7],[9.2,10],[8.2,13.89],[7.4,7.03],[46,2.74],[7.6,2.5],[7.8,45.95],[8.4,18.51],[1000,5]],"id":42142047},{"spn":5.15,"spf":"NaN","id":42142047},{"atb":[[2.56,2.15],[1.01,4804.04],[2.5,50.13],[2.42,3.98],[2.46,68.49],[2.6,1.65],[2.44,69.44],[2.58,1.99],[2.48,27.03]],"id":42609835},{"spl":[[1.01,11]],"id":42609835},{"atl":[[6.4,10],[5.8,5],[5.5,43.89],[46,2.74],[5.2,3.5],[5.7,21.28],[5.4,11.59],[1000,5]],"id":42609835},{"spn":2.54,"spf":1.0,"id":42609835},{"atb":[[1.82,182.93],[1.8,250],[1.01,4804.04],[1.89,112.36],[1.84,119.05],[1.9,21.76],[1.96,2.15],[1.86,46.51],[1.93,20.22]],"id":40133336},{"atl":[[4,5.62],[4.8,65.79],[4.5,5],[4.6,41.67],[4.1,2.5],[46,2.74],[4.9,10],[4.4,29.41],[4.2,43.54],[1000,5]],"id":40133336},{"spn":2.98,"spf":"NaN","id":40133336}],"con":true,"img":true}]}
{"op":"mcm","clk":"5322807343","pt":1646324202929,"mc":[{"id":"1.195532869","rc":[{"spn":12.6,"spf":"NaN","id":40302111},{"spn":2.12,"spf":1.0,"id":2441997},{"spn":2.25,"spf":"NaN","id":36909993},{"spn":5.15,"spf":"NaN","id":42142047},{"spn":2.54,"spf":1.0,"id":42609835},{"atb":[[1.97,1.99]],"id":40133336},{"spn":2.98,"spf":"NaN","id":40133336}],"con":true,"img":false}]}
{"op":"mcm","clk":"5322807493","pt":1646324203791,"mc":[{"id":"1.195532869","rc":[{"atb":[[2.88,0]],"id":42142047}],"con":true,"img":false}]}
{"op":"mcm","clk":"5322807505","pt":1646324203899,"mc":[{"id":"1.195532869","rc":[{"atb":[[2.92,1.99]],"id":42142047}],"con":true,"img":false}]}
{"op":"mcm","clk":"5322807547","pt":1646324204311,"mc":[{"id":"1.195532869","rc":[{"atb":[[1.93,13.06]],"id":40133336}],"con":true,"img":false}]}
{"op":"mcm","clk":"5322807633","pt":1646324205101,"mc":[{"id":"1.195532869","rc":[{"atb":[[3,125]],"id":40302111},{"atl":[[8.6,19.74]],"id":42142047}],"con":true,"img":false}]}
{"op":"mcm","clk":"5322807880","pt":1646324207241,"mc":[{"id":"1.195532869","rc":[{"atb":[[2.68,0]],"id":40302111},{"atl":[[8,0],[8.4,5]],"id":42142047}],"con":true,"img":false}]}
{"op":"mcm","clk":"5322808042","pt":1646324208528,"mc":[{"id":"1.195532869","rc":[{"atl":[[2.96,127.55]],"id":36909993},{"atb":[[1.85,10.15]],"id":40133336}],"con":true,"img":false}]}
{"op":"mcm","clk":"5322808100","pt":1646324209051,"mc":[{"id":"1.195532869","rc":[{"atb":[[1.85,0]],"id":40133336}],"con":true,"img":false}]}
{"op":"mcm","clk":"5322808115","pt":1646324209206,"mc":[{"id":"1.195532869","rc":[{"atb":[[1.94,15.66]],"id":40133336}],"con":true,"img":false}]}
{"op":"mcm","clk":"5322808175","pt":1646324209840,"mc":[{"id":"1.195532869","rc":[{"atb":[[2.42,109.61]],"id":42609835},{"atl":[[5.6,21.74]],"id":42609835},{"atb":[[1.91,3.65]],"id":40133336}],"con":true,"img":false}]}
{"op":"mcm","clk":"5322808290","pt":1646324210902,"mc":[{"id":"1.195532869","rc":[{"atb":[[2.9,2]],"id":42142047}],"con":true,"img":false}]}
{"op":"mcm","clk":"5322808296","pt":1646324210942,"mc":[{"id":"1.195532869","rc":[{"atb":[[2.44,0],[2.48,0]],"id":42609835}],"con":true,"img":false}]}
{"op":"mcm","clk":"5322808308","pt":1646324211049,"mc":[{"id":"1.195532869","rc":[{"atb":[[2.94,1.65]],"id":42142047}],"con":true,"img":false}]}
{"op":"mcm","clk":"5322808332","pt":1646324211235,"mc":[{"id":"1.195532869","rc":[{"atb":[[2.94,3.65],[2.9,0]],"id":42142047}],"con":true,"img":false}]}
{"op":"mcm","clk":"5322808338","pt":1646324211317,"mc":[{"id":"1.195532869","rc":[{"atb":[[1.91,0]],"id":40133336}],"con":true,"img":false}]}
{"op":"mcm","clk":"5322808360","pt":1646324211534,"mc":[{"id":"1.195532869","rc":[{"atb":[[2.92,0]],"id":42142047}],"con":true,"img":false}]}
{"op":"mcm","clk":"5322808372","pt":1646324211648,"mc":[{"id":"1.195532869","rc":[{"atb":[[2.96,1.99]],"id":42142047}],"con":true,"img":false}]}
{"op":"mcm","clk":"5322808433","pt":1646324212052,"mc":[{"id":"1.195532869","rc":[{"atb":[[2.94,11.67]],"id":42142047},{"atb":[[1.93,36.41]],"id":40133336}],"con":true,"img":false}]}
{"op":"mcm","clk":"5322808444","pt":1646324212156,"mc":[{"id":"1.195532869","rc":[{"atb":[[2.86,0]],"id":42142047},{"atb":[[1.9,0]],"id":40133336}],"con":true,"img":false}]}
{"op":"mcm","clk":"5322808475","pt":1646324212318,"mc":[{"id":"1.195532869","rc":[{"atb":[[2.62,30.88],[2.7,2.5]],"id":42142047}],"con":true,"img":false}]}
{"op":"mcm","clk":"5322808658","pt":1646324213646,"mc":[{"id":"1.195532869","rc":[{"atb":[[1.94,0]],"id":40133336}],"con":true,"img":false}]}
{"op":"mcm","clk":"5322808884","pt":1646324215112,"mc":[{"id":"1.195532869","rc":[{"atl":[[9,31.25]],"id":42142047}],"con":true,"img":false}]}
{"op":"mcm","clk":"5322809111","pt":1646324217259,"mc":[{"id":"1.195532869","rc":[{"atb":[[1.96,8.24]],"id":40133336}],"con":true,"img":false}]}
{"op":"mcm","clk":"5322809131","pt":1646324217430,"mc":[{"id":"1.195532869","rc":[{"atb":[[1.93,23.35]],"id":40133336}],"con":true,"img":false}]}
{"op":"mcm","clk":"5322809208","pt":1646324218030,"mc":[{"id":"1.195532869","rc":[{"atb":[[5.7,7.13]],"id":40302111},{"atb":[[2.04,9.12]],"id":2441997},{"atb":[[1.7,69.41]],"id":36909993},{"atb":[[2.64,28.82]],"id":42142047},{"atb":[[2.52,9.12]],"id":42609835},{"atb":[[1.9,13.46]],"id":40133336}],"con":true,"img":false}]}
{"op":"mcm","clk":"5322809217","pt":1646324218132,"mc":[{"id":"1.195532869","rc":[{"atb":[[1.9,19.27]],"id":40133336}],"con":true,"img":false}]}
{"op":"mcm","clk":"5322809229","pt":1646324218224,"mc":[{"id":"1.195532869","rc":[{"atb":[[2.5,35.07],[2.52,25.1]],"id":42609835}],"con":true,"img":false}]}
{"op":"mcm","clk":"5322809240","pt":1646324218342,"mc":[{"id":"1.195532869","rc":[{"atb":[[5.6,0]],"id":40302111}],"con":true,"img":false}]}
{"op":"mcm","clk":"5322809252","pt":1646324218444,"mc":[{"id":"1.195532869","rc":[{"atb":[[5.8,1.99]],"id":40302111}],"con":true,"img":false}]}
{"op":"mcm","clk":"5322809402","pt":1646324219834,"mc":[{"id":"1.195532869","rc":[{"atb":[[5.7,5.47]],"id":40302111},{"atb":[[2.94,10.02]],"id":42142047},{"atb":[[2.38,181.16]],"id":42609835},{"atl":[[5.8,36.25]],"id":42609835},{"atb":[[1.9,56.16],[1.93,0]],"id":40133336}],"con":true,"img":false}]}
{"op":"mcm","clk":"5322809421","pt":1646324220027,"mc":[{"id":"1.195532869","rc":[{"atb":[[5.9,1.65]],"id":40302111},{"atb":[[2.98,1.65]],"id":42142047}],"con":true,"img":false}]}
{"op":"mcm","clk":"5322809431","pt":1646324220131,"mc":[{"id":"1.195532869","rc":[{"atb":[[2.02,0]],"id":2441997},{"atb":[[1.69,0]],"id":36909993},{"atb":[[2.98,3.65]],"id":42142047}],"con":true,"img":false}]}
{"op":"mcm","clk":"5322809446","pt":1646324220246,"mc":[{"id":"1.195532869","rc":[{"atb":[[2.94,8.02]],"id":42142047}],"con":true,"img":false}]}
{"op":"mcm","clk":"5322809457","pt":1646324220352,"mc":[{"id":"1.195532869","rc":[{"atb":[[1.67,3.84]],"id":36909993}],"con":true,"img":false}]}
{"op":"mcm","clk":"5322809517","pt":1646324220823,"mc":[{"id":"1.195532869","rc":[{"atb":[[1.67,0]],"id":36909993},{"atb":[[2.96,0]],"id":42142047}],"con":true,"img":false}]}
{"op":"mcm","clk":"5322809526","pt":1646324220933,"mc":[{"id":"1.195532869","rc":[{"atb":[[3,1.99]],"id":42142047}],"con":true,"img":false}]}
{"op":"mcm","clk":"5322809818","pt":1646324223246,"mc":[{"id":"1.195532869","rc":[{"atb":[[2.12,4.21]],"id":2441997},{"atb":[[1.71,48.59]],"id":36909993}],"con":true,"img":false}]}
{"op":"mcm","clk":"5322809865","pt":1646324223631,"mc":[{"id":"1.195532869","rc":[{"atl":[[5.5,35],[5.7,0]],"id":42609835}],"con":true,"img":false}]}
{"op":"mcm","clk":"5322809892","pt":1646324223937,"mc":[{"id":"1.195532869","rc":[{"atb":[[1.74,2.15],[1.7,67.25]],"id":36909993}],"con":true,"img":false}]}
{"op":"mcm","clk":"5322809934","pt":1646324224355,"mc":[{"id":"1.195532869","rc":[{"atb":[[2.1,0]],"id":2441997}],"con":true,"img":false}]}
{"op":"mcm","clk":"5322809945","pt":1646324224423,"mc":[{"id":"1.195532869","rc":[{"atb":[[2.14,1.99]],"id":2441997}],"con":true,"img":false}]}
{"op":"mcm","clk":"5322810000","pt":1646324224926,"mc":[{"id":"1.195532869","rc":[{"atb":[[5.7,0]],"id":40302111},{"atb":[[1.7,0]],"id":36909993},{"atb":[[2.64,0]],"id":42142047}],"con":true,"img":false}]}
{"op":"mcm","clk":"5322810020","pt":1646324225138,"mc":[{"id":"1.195532869","rc":[{"atb":[[1.68,63.16]],"id":36909993}],"con":true,"img":false}]}
{"op":"mcm","clk":"5322810031","pt":1646324225240,"mc":[{"id":"1.195532869","rc":[{"atb":[[5.8,0]],"id":40302111}],"con":true,"img":false}]}
{"op":"mcm","clk":"5322810043","pt":1646324225346,"mc":[{"id":"1.195532869","rc":[{"atb":[[5.6,1.99]],"id":40302111}],"con":true,"img":false}]}
{"op":"mcm","clk":"5322810056","pt":1646324225451,"mc":[{"id":"1.195532869","rc":[{"atb":[[1.68,58.82]],"id":36909993}],"con":true,"img":false}]}
{"op":"mcm","clk":"5322810149","pt":1646324226353,"mc":[{"id":"1.195532869","rc":[{"atb":[[2.12,9.21],[2.2,2.5]],"id":2441997}],"con":true,"img":false}]}
{"op":"mcm","clk":"5322810158","pt":1646324226453,"mc":[{"id":"1.195532869","rc":[{"atb":[[2,0],[1.96,0],[2.08,0]],"id":2441997},{"atl":[[9.2,0],[8.2,18.89],[7.4,9.53],[7.6,0],[8.4,0]],"id":42142047},{"atl":[[6.4,0],[5.8,31.25],[5.3,2.5],[5.4,9.09]],"id":42609835},{"atl":[[4.5,0],[4.3,5],[3.95,2.5],[4.1,0],[4.9,0]],"id":40133336}],"con":true,"img":false}]}
{"op":"mcm","clk":"5322810184","pt":1646324226665,"mc":[{"id":"1.195532869","rc":[{"atb":[[2.14,0]],"id":2441997},{"atl":[[8.2,52.11],[7.4,25.15],[7.8,5.88]],"id":42142047},{"atl":[[5.3,11.59],[5.5,0],[5.4,23.39]],"id":42609835},{"atl":[[3.95,8.59]],"id":40133336}],"con":true,"img":false}]}
{"op":"mcm","clk":"5322810195","pt":1646324226725,"mc":[{"id":"1.195532869","rc":[{"atb":[[2.22,1.99]],"id":2441997}],"con":true,"img":false}]}
{"op":"mcm","clk":"5322810207","pt":1646324226878,"mc":[{"id":"1.195532869","rc":[{"atl":[[4,0],[4.1,12.9],[4.2,31.04]],"id":40133336}],"con":true,"img":false}]}
{"op":"mcm","clk":"5322810232","pt":1646324227055,"mc":[{"id":"1.195532869","rc":[{"atl":[[4.3,8.06]],"id":40133336}],"con":true,"img":false}]}
{"op":"mcm","clk":"5322810241","pt":1646324227144,"mc":[{"id":"1.195532869","rc":[{"atb":[[2.04,0]],"id":2441997}],"con":true,"img":false}]}
{"op":"mcm","clk":"5322810260","pt":1646324227355,"mc":[{"id":"1.195532869","rc":[{"atl":[[4.3,5]],"id":40133336}],"con":true,"img":false}]}
{"op":"mcm","clk":"5322810299","pt":1646324227626,"mc":[{"id":"1.195532869","rc":[{"atb":[[1.89,167.28],[1.9,19.27]],"id":40133336}],"con":true,"img":false}]}
{"op":"mcm","clk":"5322810324","pt":1646324227836,"mc":[{"id":"1.195532869","rc":[{"atb":[[5.9,0]],"id":40302111},{"atb":[[2.12,7.55]],"id":2441997},{"atb":[[2.98,2]],"id":42142047}],"con":true,"img":false}]}
{"op":"mcm","clk":"5322810339","pt":1646324228026,"mc":[{"id":"1.195532869","rc":[{"atb":[[5.7,1.65]],"id":40302111},{"atb":[[3.05,1.65]],"id":42142047}],"con":true,"img":false}]}
{"op":"mcm","clk":"5322810358","pt":1646324228239,"mc":[{"id":"1.195532869","rc":[{"atb":[[2.98,0],[3.05,3.65]],"id":42142047}],"con":true,"img":false}]}
{"op":"mcm","clk":"5322810369","pt":1646324228347,"mc":[{"id":"1.195532869","rc":[{"atb":[[2.9,3.48]],"id":42142047}],"con":true,"img":false}]}
{"op":"mcm","clk":"5322810387","pt":1646324228547,"mc":[{"id":"1.195532869","rc":[{"atb":[[3.05,14.07]],"id":42142047}],"con":true,"img":false}]}
{"op":"mcm","clk":"5322810397","pt":1646324228660,"mc":[{"id":"1.195532869","rc":[{"atb":[[2.9,0]],"id":42142047}],"con":true,"img":false}]}
{"op":"mcm","clk":"5322810410","pt":1646324228756,"mc":[{"id":"1.195532869","rc":[{"atb":[[3,0],[2.94,0]],"id":42142047}],"con":true,"img":false}]}
{"op":"mcm","clk":"5322810426","pt":1646324228876,"mc":[{"id":"1.195532869","rc":[{"atb":[[3.1,1.99],[2.62,5],[2.7,32.61]],"id":42142047}],"con":true,"img":false}]}
{"op":"mcm","clk":"5322810477","pt":1646324229348,"mc":[{"id":"1.195532869","rc":[{"atl":[[4.3,12.81]],"id":40133336}],"con":true,"img":false}]}
{"op":"mcm","clk":"5322810493","pt":1646324229452,"mc":[{"id":"1.195532869","rc":[{"atb":[[2.12,5]],"id":2441997}],"con":true,"img":false}]}
{"op":"mcm","clk":"5322810522","pt":1646324229667,"mc":[{"id":"1.195532869","rc":[{"atl":[[4.3,5]],"id":40133336}],"con":true,"img":false}]}
{"op":"mcm","clk":"5322810546","pt":1646324229865,"mc":[{"id":"1.195532869","rc":[{"atl":[[6,50]],"id":42609835}],"con":true,"img":false}]}
{"op":"mcm","clk":"5322810637","pt":1646324230733,"mc":[{"id":"1.195532869","rc":[{"atb":[[5.7,7.13]],"id":40302111},{"atb":[[1.69,68.5]],"id":36909993},{"atb":[[2.72,27.47]],"id":42142047},{"atl":[[5.6,26.08]],"id":42609835}],"con":true,"img":false}]}
{"op":"mcm","clk":"5322810681","pt":1646324231151,"mc":[{"id":"1.195532869","rc":[{"atb":[[5.6,0]],"id":40302111}],"con":true,"img":false}]}
{"op":"mcm","clk":"5322810695","pt":1646324231255,"mc":[{"id":"1.195532869","rc":[{"atb":[[5.8,1.99]],"id":40302111},{"atl":[[5.6,21.74]],"id":42609835}],"con":true,"img":false}]}
{"op":"mcm","clk":"5322810753","pt":1646324231838,"mc":[{"id":"1.195532869","rc":[{"atl":[[8.2,66],[7.4,9.53]],"id":42142047},{"atl":[[5.3,2.5],[5.4,46.12]],"id":42609835}],"con":true,"img":false}]}
{"op":"mcm","clk":"5322810890","pt":1646324233152,"mc":[{"id":"1.195532869","rc":[{"atb":[[1.96,23.57]],"id":2441997}],"con":true,"img":false}]}
{"op":"mcm","clk":"5322810975","pt":1646324234041,"mc":[{"id":"1.195532869","rc":[{"atb":[[1.96,33.45]],"id":2441997}],"con":true,"img":false}]}
{"op":"mcm","clk":"5322811166","pt":1646324235844,"mc":[{"id":"1.195532869","rc":[{"atb":[[5.7,5.47]],"id":40302111},{"atb":[[3.05,12.42]],"id":42142047}],"con":true,"img":false}]}
{"op":"mcm","clk":"5322811174","pt":1646324235949,"mc":[{"id":"1.195532869","rc":[{"atb":[[2.64,3.48]],"id":42142047}],"con":true,"img":false}]}
{"op":"mcm","clk":"5322811187","pt":1646324236055,"mc":[{"id":"1.195532869","rc":[{"atb":[[5.9,1.65]],"id":40302111}],"con":true,"img":false}]}
{"op":"mcm","clk":"5322811241","pt":1646324236530,"mc":[{"id":"1.195532869","rc":[{"atb":[[2.64,0]],"id":42142047}],"con":true,"img":false}]}
{"op":"mcm","clk":"5322811482","pt":1646324238935,"mc":[{"id":"1.195532869","rc":[{"atl":[[7.8,8.91]],"id":42142047}],"con":true,"img":false}]}
{"op":"mcm","clk":"5322811501","pt":1646324239142,"mc":[{"id":"1.195532869","rc":[{"atl":[[7.8,5.88]],"id":42142047}],"con":true,"img":false}]}
{"op":"mcm","clk":"5322811653","pt":1646324240567,"mc":[{"id":"1.195532869","rc":[{"atb":[[5.7,0]],"id":40302111}],"con":true,"img":false}]}
{"op":"mcm","clk":"5322811811","pt":1646324242196,"mc":[{"id":"1.195532869","rc":[{"atb":[[5.8,0]],"id":40302111}],"con":true,"img":false}]}
{"op":"mcm","clk":"5322811822","pt":1646324242243,"mc":[{"id":"1.195532869","rc":[{"atb":[[5.6,1.99]],"id":40302111}],"con":true,"img":false}]}
{"op":"mcm","clk":"5322812039","pt":1646324243830,"mc":[{"id":"1.195532869","rc":[{"atb":[[5.9,0]],"id":40302111}],"con":true,"img":false}]}
{"op":"mcm","clk":"5322812057","pt":1646324244036,"mc":[{"id":"1.195532869","rc":[{"atb":[[5.7,1.65]],"id":40302111}],"con":true,"img":false}]}
{"op":"mcm","clk":"5322812197","pt":1646324245587,"mc":[{"id":"1.195532869","rc":[{"atb":[[5.7,7.13]],"id":40302111}],"con":true,"img":false}]}
{"op":"mcm","clk":"5322812265","pt":1646324246247,"mc":[{"id":"1.195532869","rc":[{"atb":[[5.6,0]],"id":40302111}],"con":true,"img":false}]}
{"op":"mcm","clk":"5322812272","pt":1646324246341,"mc":[{"id":"1.195532869","rc":[{"atb":[[5.8,1.99]],"id":40302111}],"con":true,"img":false}]}
{"op":"mcm","clk":"5322812447","pt":1646324248162,"mc":[{"id":"1.195532869","rc":[{"atb":[[1.85,5.81]],"id":40133336}],"con":true,"img":false}]}
{"op":"mcm","clk":"5322812490","pt":1646324248631,"mc":[{"id":"1.195532869","rc":[{"atb":[[2.46,74.16],[2.58,5.49]],"id":42609835},{"atb":[[1.85,0]],"id":40133336}],"con":true,"img":false}]}
{"op":"mcm","clk":"5322812506","pt":1646324248748,"mc":[{"id":"1.195532869","rc":[{"atb":[[2.5,26.67]],"id":42609835}],"con":true,"img":false}]}
{"op":"mcm","clk":"5322812538","pt":1646324249166,"mc":[{"id":"1.195532869","rc":[{"atb":[[2.46,68.49]],"id":42609835}],"con":true,"img":false}]}
{"op":"mcm","clk":"5322812766","pt":1646324251785,"mc":[{"id":"1.195532869","rc":[{"atb":[[5.7,5.47]],"id":40302111}],"con":true,"img":false}]}
{"op":"mcm","clk":"5322812796","pt":1646324252005,"mc":[{"id":"1.195532869","rc":[{"atb":[[5.9,1.65]],"id":40302111}],"con":true,"img":false}]}
{"op":"mcm","clk":"5322812982","pt":1646324254000,"mc":[{"id":"1.195532869","rc":[{"atb":[[1.65,7.35]],"id":36909993}],"con":true,"img":false}]}
{"op":"mcm","clk":"5322813000","pt":1646324254198,"mc":[{"id":"1.195532869","rc":[{"atb":[[1.65,0]],"id":36909993}],"con":true,"img":false}]}
{"op":"mcm","clk":"5322813080","pt":1646324255201,"mc":[{"id":"1.195532869","rc":[{"atb":[[5.7,0]],"id":40302111}],"con":true,"img":false}]}
{"op":"mcm","clk":"5322813236","pt":1646324256780,"mc":[{"id":"1.195532869","rc":[{"atb":[[5.8,0]],"id":40302111},{"atl":[[5.6,29.24]],"id":42609835}],"con":true,"img":false}]}
{"op":"mcm","clk":"5322813245","pt":1646324256888,"mc":[{"id":"1.195532869","rc":[{"atb":[[5.6,1.99]],"id":40302111}],"con":true,"img":false}]}
{"op":"mcm","clk":"5322813266","pt":1646324257197,"mc":[{"id":"1.195532869","rc":[{"atl":[[5.6,21.74]],"id":42609835}],"con":true,"img":false}]}
{"op":"mcm","clk":"5322813530","pt":1646324259779,"mc":[{"id":"1.195532869","rc":[{"atb":[[5.9,0]],"id":40302111}],"con":true,"img":false}]}
{"op":"mcm","clk":"5322813539","pt":1646324259887,"mc":[{"id":"1.195532869","rc":[{"atb":[[5.7,1.65]],"id":40302111}],"con":true,"img":false}]}
{"op":"mcm","clk":"5322813568","pt":1646324260209,"mc":[{"id":"1.195532869","rc":[{"atb":[[5.7,7.13]],"id":40302111}],"con":true,"img":false}]}
{"op":"mcm","clk":"5322813666","pt":1646324261207,"mc":[{"id":"1.195532869","rc":[{"atb":[[5.6,0]],"id":40302111}],"con":true,"img":false}]}
{"op":"mcm","clk":"5322813674","pt":1646324261304,"mc":[{"id":"1.195532869","rc":[{"atb":[[5.8,1.99]],"id":40302111}],"con":true,"img":false}]}
{"op":"mcm","clk":"5322814235","pt":1646324267820,"mc":[{"id":"1.195532869","rc":[{"atb":[[5.7,5.47]],"id":40302111},{"spn":12.65,"spf":"NaN","id":40302111},{"spn":2.22,"spf":1.0,"id":2441997},{"spn":2.27,"spf":"NaN","id":36909993},{"spn":5.25,"spf":"NaN","id":42142047},{"spn":2.56,"spf":1.0,"id":42609835},{"spn":2.96,"spf":"NaN","id":40133336}],"con":true,"img":false}]}
{"op":"mcm","clk":"5322814272","pt":1646324268103,"mc":[{"id":"1.195532869","rc":[{"atb":[[5.9,1.65]],"id":40302111}],"con":true,"img":false}]}
{"op":"mcm","clk":"5322814623","pt":1646324271737,"mc":[{"id":"1.195532869","rc":[{"atb":[[5.7,0]],"id":40302111}],"con":true,"img":false}]}
{"op":"mcm","clk":"5322814675","pt":1646324272303,"mc":[{"id":"1.195532869","rc":[{"atb":[[5.8,0]],"id":40302111}],"con":true,"img":false}]}
{"op":"mcm","clk":"5322814688","pt":1646324272417,"mc":[{"id":"1.195532869","rc":[{"atb":[[5.6,1.99]],"id":40302111}],"con":true,"img":false}]}
{"op":"mcm","clk":"5322814810","pt":1646324273531,"mc":[{"id":"1.195532869","rc":[{"atb":[[3,27.48],[3.05,10.42]],"id":42142047},{"atb":[[2.58,1.99]],"id":42609835},{"atb":[[1.89,54.92],[1.81,123.46],[1.96,2.15]],"id":40133336}],"con":true,"img":false}]}
{"op":"mcm","clk":"5322814817","pt":1646324273628,"mc":[{"id":"1.195532869","rc":[{"atb":[[1.96,5.51]],"id":40133336}],"con":true,"img":false}]}
{"op":"mcm","clk":"5322814830","pt":1646324273735,"mc":[{"id":"1.195532869","rc":[{"atb":[[2.72,77.33],[2.7,2.5]],"id":42142047},{"atl":[[7.2,12.9]],"id":42142047},{"atb":[[1.96,2.15]],"id":40133336}],"con":true,"img":false}]}
{"op":"mcm","clk":"5322814842","pt":1646324273830,"mc":[{"id":"1.195532869","rc":[{"atl":[[8,3.68],[7.8,20.59]],"id":42142047}],"con":true,"img":false}]}
{"op":"mcm","clk":"5322814850","pt":1646324273889,"mc":[{"id":"1.195532869","rc":[{"atl":[[8.2,18.89],[7.4,2.5],[7.8,59.84]],"id":42142047}],"con":true,"img":false}]}
{"op":"mcm","clk":"5322814873","pt":1646324274109,"mc":[{"id":"1.195532869","rc":[{"atl":[[8,6.98]],"id":42142047}],"con":true,"img":false}]}
{"op":"mcm","clk":"5322814890","pt":1646324274307,"mc":[{"id":"1.195532869","rc":[{"atl":[[8,3.68]],"id":42142047}],"con":true,"img":false}]}
{"op":"mcm","clk":"5322814908","pt":1646324274411,"mc":[{"id":"1.195532869","rc":[{"atl":[[8,0]],"id":42142047}],"con":true,"img":false}]}
{"op":"mcm","clk":"5322814957","pt":1646324274846,"mc":[{"id":"1.195532869","rc":[{"atl":[[7.6,6.06],[7.8,53.96]],"id":42142047}],"con":true,"img":false}]}
{"op":"mcm","clk":"5322815072","pt":1646324275846,"mc":[{"id":"1.195532869","rc":[{"atb":[[5.9,0]],"id":40302111}],"con":true,"img":false}]}
{"op":"mcm","clk":"5322815096","pt":1646324276048,"mc":[{"id":"1.195532869","rc":[{"atb":[[5.7,1.65]],"id":40302111}],"con":true,"img":false}]}
{"op":"mcm","clk":"5322815181","pt":1646324276940,"mc":[{"id":"1.195532869","rc":[{"atb":[[5.7,7.13]],"id":40302111},{"atb":[[2.72,49.86]],"id":42142047}],"con":true,"img":false}]}
{"op":"mcm","clk":"5322815244","pt":1646324277539,"mc":[{"id":"1.195532869","rc":[{"atb":[[5.6,0]],"id":40302111}],"con":true,"img":false}]}
{"op":"mcm","clk":"5322815255","pt":1646324277640,"mc":[{"id":"1.195532869","rc":[{"atb":[[5.8,1.99]],"id":40302111}],"con":true,"img":false}]}
{"op":"mcm","clk":"5322815279","pt":1646324277843,"mc":[{"id":"1.195532869","rc":[{"atb":[[2.64,4.69]],"id":42142047}],"con":true,"img":false}]}
{"op":"mcm","clk":"5322815299","pt":1646324277989,"mc":[{"id":"1.195532869","rc":[{"atb":[[2.64,0]],"id":42142047}],"con":true,"img":false}]}
{"op":"mcm","clk":"5322815486","pt":1646324280045,"mc":[{"id":"1.195532869","rc":[{"atl":[[2.8,48.22]],"id":36909993},{"atb":[[3,0],[2.96,20.84]],"id":42142047}],"con":true,"img":false}]}
{"op":"mcm","clk":"5322815502","pt":1646324280248,"mc":[{"id":"1.195532869","rc":[{"atb":[[2.98,11.82]],"id":42142047}],"con":true,"img":false}]}
{"op":"mcm","clk":"5322815525","pt":1646324280527,"mc":[{"id":"1.195532869","rc":[{"atl":[[2.8,44.44]],"id":36909993}],"con":true,"img":false}]}
{"op":"mcm","clk":"5322815535","pt":1646324280622,"mc":[{"id":"1.195532869","rc":[{"atl":[[4.6,25.02]],"id":2441997},{"atl":[[6.8,2.54]],"id":42142047}],"con":true,"img":false}]}
{"op":"mcm","clk":"5322815540","pt":1646324280718,"mc":[{"id":"1.195532869","rc":[{"atl":[[2.8,0]],"id":36909993},{"atb":[[2.98,0]],"id":42142047}],"con":true,"img":false}]}
{"op":"mcm","clk":"5322815552","pt":1646324280836,"mc":[{"id":"1.195532869","rc":[{"atl":[[4.5,13.31],[4.7,0]],"id":2441997},{"atl":[[2.88,161.25]],"id":36909993}],"con":true,"img":false}]}
{"op":"mcm","clk":"5322815561","pt":1646324280934,"mc":[{"id":"1.195532869","rc":[{"atl":[[2.82,43.96],[2.86,77.67]],"id":36909993}],"con":true,"img":false}]}
{"op":"mcm","clk":"5322815571","pt":1646324281048,"mc":[{"id":"1.195532869","rc":[{"atl":[[2.88,214.44],[2.86,23.91]],"id":36909993},{"atl":[[6.8,5.08],[7.8,39.25]],"id":42142047}],"con":true,"img":false}]}
{"op":"mcm","clk":"5322815579","pt":1646324281137,"mc":[{"id":"1.195532869","rc":[{"atl":[[4.8,8.92]],"id":2441997}],"con":true,"img":false}]}
{"op":"mcm","clk":"5322815585","pt":1646324281248,"mc":[{"id":"1.195532869","rc":[{"atl":[[2.86,0]],"id":36909993}],"con":true,"img":false}]}
{"op":"mcm","clk":"5322815612","pt":1646324281520,"mc":[{"id":"1.195532869","rc":[{"atl":[[2.86,21.51],[2.84,0]],"id":36909993},{"atl":[[7.2,19.35],[7.6,0]],"id":42142047}],"con":true,"img":false}]}
{"op":"mcm","clk":"5322815634","pt":1646324281746,"mc":[{"id":"1.195532869","rc":[{"atl":[[4.8,0]],"id":2441997}],"con":true,"img":false}]}
{"op":"mcm","clk":"5322815644","pt":1646324281847,"mc":[{"id":"1.195532869","rc":[{"atl":[[6.8,2.54]],"id":42142047}],"con":true,"img":false}]}
{"op":"mcm","clk":"5322815661","pt":1646324282041,"mc":[{"id":"1.195532869","rc":[{"atl":[[4.6,23.41]],"id":2441997},{"atb":[[3.1,20.6]],"id":42142047}],"con":true,"img":false}]}
{"op":"mcm","clk":"5322815677","pt":1646324282212,"mc":[{"id":"1.195532869","rc":[{"atb":[[3.15,21.08]],"id":42142047}],"con":true,"img":false}]}
{"op":"mcm","clk":"5322815700","pt":1646324282456,"mc":[{"id":"1.195532869","rc":[{"atb":[[3.05,0]],"id":42142047}],"con":true,"img":false}]}
{"op":"mcm","clk":"5322815733","pt":1646324282845,"mc":[{"id":"1.195532869","rc":[{"atb":[[3.1,18.61]],"id":42142047}],"con":true,"img":false}]}
{"op":"mcm","clk":"5322815741","pt":1646324282937,"mc":[{"id":"1.195532869","rc":[{"atb":[[3.2,1.99]],"id":42142047}],"con":true,"img":false}]}
{"op":"mcm","clk":"5322815867","pt":1646324283855,"mc":[{"id":"1.195532869","rc":[{"atb":[[5.7,5.47]],"id":40302111}],"con":true,"img":false}]}
{"op":"mcm","clk":"5322815891","pt":1646324284052,"mc":[{"id":"1.195532869","rc":[{"atb":[[5.9,1.65]],"id":40302111}],"con":true,"img":false}]}
{"op":"mcm","clk":"5322815978","pt":1646324284849,"mc":[{"id":"1.195532869","rc":[{"atl":[[6.4,3.4]],"id":42142047}],"con":true,"img":false}]}
{"op":"mcm","clk":"5322815999","pt":1646324285051,"mc":[{"id":"1.195532869","rc":[{"atl":[[6.8,9.44]],"id":42142047}],"con":true,"img":false}]}
{"op":"mcm","clk":"5322816008","pt":1646324285109,"mc":[{"id":"1.195532869","rc":[{"atl":[[7.2,12.9]],"id":42142047}],"con":true,"img":false}]}
{"op":"mcm","clk":"5322816040","pt":1646324285426,"mc":[{"id":"1.195532869","rc":[{"atl":[[4.6,25.26]],"id":2441997}],"con":true,"img":false}]}
{"op":"mcm","clk":"5322816206","pt":1646324286928,"mc":[{"id":"1.195532869","rc":[{"atb":[[5.7,0]],"id":40302111},{"atb":[[3.1,0]],"id":42142047}],"con":true,"img":false}]}
{"op":"mcm","clk":"5322816254","pt":1646324287405,"mc":[{"id":"1.195532869","rc":[{"atb":[[5.8,0]],"id":40302111}],"con":true,"img":false}]}
{"op":"mcm","clk":"5322816264","pt":1646324287510,"mc":[{"id":"1.195532869","rc":[{"atb":[[5.6,1.99]],"id":40302111}],"con":true,"img":false}]}
{"op":"mcm","clk":"5322816322","pt":1646324288035,"mc":[{"id":"1.195532869","rc":[{"atb":[[1.69,184.19]],"id":36909993}],"con":true,"img":false}]}
{"op":"mcm","clk":"5322816338","pt":1646324288244,"mc":[{"id":"1.195532869","rc":[{"atb":[[1.67,4.28]],"id":36909993},{"atl":[[6.2,9.44],[6.8,6.9]],"id":42142047}],"con":true,"img":false}]}
{"op":"mcm","clk":"5322816353","pt":1646324288404,"mc":[{"id":"1.195532869","rc":[{"atb":[[1.67,0]],"id":36909993}],"con":true,"img":false}]}
{"op":"mcm","clk":"5322816411","pt":1646324289040,"mc":[{"id":"1.195532869","rc":[{"atl":[[6,12.26],[7,2.5]],"id":42142047},{"atl":[[5.6,26.74],[5.3,0],[5.2,6]],"id":42609835},{"atl":[[3.9,2.5],[4.2,36.04]],"id":40133336}],"con":true,"img":false}]}
{"op":"mcm","clk":"5322816426","pt":1646324289157,"mc":[{"id":"1.195532869","rc":[{"atl":[[8.2,13.89],[7.4,0]],"id":42142047},{"atl":[[5.6,30.74]],"id":42609835},{"atl":[[4.3,0],[3.95,6.09]],"id":40133336}],"con":true,"img":false}]}
{"op":"mcm","clk":"5322816431","pt":1646324289243,"mc":[{"id":"1.195532869","rc":[{"atl":[[7.2,0],[6.4,52.96],[7.8,0]],"id":42142047},{"atl":[[5.6,87.37],[5.2,29.81],[5.4,9.09]],"id":42609835},{"atl":[[4.3,13.86],[3.85,8.32],[4.1,55.88],[3.9,11.09],[4.2,5]],"id":40133336}],"con":true,"img":false}]}
{"op":"mcm","clk":"5322816442","pt":1646324289371,"mc":[{"id":"1.195532869","rc":[{"atb":[[1.08,50]],"id":40302111},{"atb":[[1.08,50]],"id":2441997},{"atb":[[1.08,50]],"id":36909993},{"atb":[[1.08,50]],"id":42142047},{"atb":[[1.08,50]],"id":42609835},{"atl":[[5.6,86.48],[5.4,13.09]],"id":42609835},{"atb":[[1.08,50]],"id":40133336},{"atl":[[3.95,0]],"id":40133336}],"con":true,"img":false}]}
{"op":"mcm","clk":"5322816461","pt":1646324289556,"mc":[{"id":"1.195532869","rc":[{"atl":[[5.6,83.37],[5.1,11.44]],"id":42609835}],"con":true,"img":false}]}
{"op":"mcm","clk":"5322816467","pt":1646324289619,"mc":[{"id":"1.195532869","rc":[{"atl":[[4.3,20.67]],"id":40133336}],"con":true,"img":false}]}
{"op":"mcm","clk":"5322816478","pt":1646324289733,"mc":[{"id":"1.195532869","rc":[{"atl":[[5.2,26.31],[5.4,9.09]],"id":42609835},{"atl":[[4.3,6.81]],"id":40133336}],"con":true,"img":false}]}
{"op":"mcm","clk":"5322816505","pt":1646324290035,"mc":[{"id":"1.195532869","rc":[{"atl":[[5.3,9.3]],"id":42609835},{"atl":[[3.95,13.56],[4.1,42.98]],"id":40133336}],"con":true,"img":false}]}
{"op":"mcm","clk":"5322816514","pt":1646324290148,"mc":[{"id":"1.195532869","rc":[{"atl":[[5.4,0]],"id":42609835},{"atl":[[4.3,0]],"id":40133336}],"con":true,"img":false}]}
{"op":"mcm","clk":"5322816547","pt":1646324290513,"mc":[{"id":"1.195532869","rc":[{"atl":[[19.5,5.87],[20,0],[23,5],[24,4.35]],"id":40302111},{"atl":[[6.4,60.37],[6.8,0]],"id":42142047},{"atb":[[1.96,16.71]],"id":40133336}],"con":true,"img":false}]}
{"op":"mcm","clk":"5322816555","pt":1646324290613,"mc":[{"id":"1.195532869","rc":[{"atl":[[19.5,11.28]],"id":40302111}],"con":true,"img":false}]}
{"op":"mcm","clk":"5322816562","pt":1646324290717,"mc":[{"id":"1.195532869","rc":[{"atl":[[21,5.13],[23,23.38]],"id":40302111}],"con":true,"img":false}]}
{"op":"mcm","clk":"5322816571","pt":1646324290824,"mc":[{"id":"1.195532869","rc":[{"atl":[[19.5,5.87]],"id":40302111}],"con":true,"img":false}]}
{"op":"mcm","clk":"5322816597","pt":1646324291139,"mc":[{"id":"1.195532869","rc":[{"atl":[[19,4.44]],"id":40302111},{"atb":[[1.87,4.91]],"id":40133336}],"con":true,"img":false}]}
{"op":"mcm","clk":"5322816609","pt":1646324291242,"mc":[{"id":"1.195532869","rc":[{"atl":[[19.5,2.5],[21,10.13]],"id":40302111}],"con":true,"img":false}]}
{"op":"mcm","clk":"5322816618","pt":1646324291349,"mc":[{"id":"1.195532869","rc":[{"atl":[[21,7],[23,18.83]],"id":40302111}],"con":true,"img":false}]}
{"op":"mcm","clk":"5322816651","pt":1646324291614,"mc":[{"id":"1.195532869","rc":[{"atb":[[1.87,0]],"id":40133336}],"con":true,"img":false}]}
{"op":"mcm","clk":"5322816695","pt":1646324292034,"mc":[{"id":"1.195532869","rc":[{"atl":[[20,2.11],[21,5]],"id":40302111}],"con":true,"img":false}]}
{"op":"mcm","clk":"5322816719","pt":1646324292352,"mc":[{"id":"1.195532869","rc":[{"atb":[[5.7,5.47]],"id":40302111},{"atb":[[2.74,27.16]],"id":42142047}],"con":true,"img":false}]}
{"op":"mcm","clk":"5322816736","pt":1646324292513,"mc":[{"id":"1.195532869","rc":[{"atl":[[2.9,52.63]],"id":36909993},{"atb":[[2.72,0],[2.74,82.05]],"id":42142047}],"con":true,"img":false}]}
{"op":"mcm","clk":"5322816780","pt":1646324292932,"mc":[{"id":"1.195532869","rc":[{"atb":[[5.9,0]],"id":40302111}],"con":true,"img":false}]}
{"op":"mcm","clk":"5322816789","pt":1646324293035,"mc":[{"id":"1.195532869","rc":[{"atb":[[5.8,1.65]],"id":40302111}],"con":true,"img":false}]}
{"op":"mcm","clk":"5322816830","pt":1646324293408,"mc":[{"id":"1.195532869","rc":[{"atb":[[5.6,0]],"id":40302111}],"con":true,"img":false}]}
{"op":"mcm","clk":"5322816843","pt":1646324293509,"mc":[{"id":"1.195532869","rc":[{"atb":[[5.8,3.64]],"id":40302111}],"con":true,"img":false}]}
{"op":"mcm","clk":"5322816862","pt":1646324293717,"mc":[{"id":"1.195532869","rc":[{"atl":[[2.92,0],[2.88,161.25],[2.96,0]],"id":36909993}],"con":true,"img":false}]}
{"op":"mcm","clk":"5322816921","pt":1646324294406,"mc":[{"id":"1.195532869","rc":[{"atl":[[5.3,32.56]],"id":42609835},{"atl":[[3.95,32.97],[3.9,2.5]],"id":40133336}],"con":true,"img":false}]}
{"op":"mcm","clk":"5322816928","pt":1646324294445,"mc":[{"id":"1.195532869","rc":[{"atl":[[5.2,2.5]],"id":42609835}],"con":true,"img":false}]}
{"op":"mcm","clk":"5322817063","pt":1646324296015,"mc":[{"id":"1.195532869","rc":[{"atl":[[2.8,44.44]],"id":36909993}],"con":true,"img":false}]}
{"op":"mcm","clk":"5322817072","pt":1646324296122,"mc":[{"id":"1.195532869","rc":[{"atl":[[2.82,0]],"id":36909993}],"con":true,"img":false}]}
{"op":"mcm","clk":"5322817078","pt":1646324296225,"mc":[{"id":"1.195532869","rc":[{"atl":[[2.88,53.19],[2.86,134.16]],"id":36909993}],"con":true,"img":false}]}
{"op":"mcm","clk":"5322817151","pt":1646324297220,"mc":[{"id":"1.195532869","rc":[{"atb":[[5.7,0]],"id":40302111}],"con":true,"img":false}]}
{"op":"mcm","clk":"5322817169","pt":1646324297533,"mc":[{"id":"1.195532869","rc":[{"atb":[[5.8,1.65]],"id":40302111}],"con":true,"img":false}]}
{"op":"mcm","clk":"5322817179","pt":1646324297640,"mc":[{"id":"1.195532869","rc":[{"atb":[[5.6,1.99]],"id":40302111}],"con":true,"img":false}]}
{"op":"mcm","clk":"5322817250","pt":1646324298319,"mc":[{"id":"1.195532869","rc":[{"atb":[[5,3.5]],"id":40302111}],"con":true,"img":false}]}
{"op":"mcm","clk":"5322817260","pt":1646324298425,"mc":[{"id":"1.195532869","rc":[{"atb":[[5,0]],"id":40302111}],"con":true,"img":false}]}
{"op":"mcm","clk":"5322817386","pt":1646324299632,"mc":[{"id":"1.195532869","rc":[{"atl":[[2.84,21.74]],"id":36909993}],"con":true,"img":false}]}
{"op":"mcm","clk":"5322817395","pt":1646324299738,"mc":[{"id":"1.195532869","rc":[{"atl":[[2.8,0]],"id":36909993}],"con":true,"img":false}]}
{"op":"mcm","clk":"5322817403","pt":1646324299854,"mc":[{"id":"1.195532869","rc":[{"atl":[[2.82,54.95],[2.88,0]],"id":36909993}],"con":true,"img":false}]}
{"op":"mcm","clk":"5322817413","pt":1646324299946,"mc":[{"id":"1.195532869","rc":[{"atl":[[2.82,98.91],[2.88,53.19]],"id":36909993}],"con":true,"img":false}]}
{"op":"mcm","clk":"5322817424","pt":1646324300082,"mc":[{"id":"1.195532869","rc":[{"atl":[[2.82,43.96]],"id":36909993}],"con":true,"img":false}]}
{"op":"mcm","clk":"5322817479","pt":1646324300544,"mc":[{"id":"1.195532869","rc":[{"atl":[[2.84,0]],"id":36909993}],"con":true,"img":false}]}
{"op":"mcm","clk":"5322817517","pt":1646324300912,"mc":[{"id":"1.195532869","rc":[{"atl":[[4.1,75.24]],"id":40133336}],"con":true,"img":false}]}
{"op":"mcm","clk":"5322817558","pt":1646324301331,"mc":[{"id":"1.195532869","rc":[{"atl":[[6.8,17.24]],"id":42142047}],"con":true,"img":false}]}
{"op":"mcm","clk":"5322817586","pt":1646324301647,"mc":[{"id":"1.195532869","rc":[{"atl":[[8.6,0],[9,0],[8.2,0]],"id":42142047}],"con":true,"img":false}]}
{"op":"mcm","clk":"5322817615","pt":1646324301911,"mc":[{"id":"1.195532869","rc":[{"atb":[[5.8,0]],"id":40302111}],"con":true,"img":false}]}
{"op":"mcm","clk":"5322817649","pt":1646324302119,"mc":[{"id":"1.195532869","rc":[{"atb":[[5.7,1.65]],"id":40302111}],"con":true,"img":false}]}
{"op":"mcm","clk":"5322817670","pt":1646324302329,"mc":[{"id":"1.195532869","rc":[{"atb":[[5.7,7.13]],"id":40302111}],"con":true,"img":false}]}
{"op":"mcm","clk":"5322817700","pt":1646324302644,"mc":[{"id":"1.195532869","rc":[{"atb":[[5.6,0]],"id":40302111}],"con":true,"img":false}]}
{"op":"mcm","clk":"5322817713","pt":1646324302743,"mc":[{"id":"1.195532869","rc":[{"atb":[[5.8,1.99]],"id":40302111}],"con":true,"img":false}]}
{"op":"mcm","clk":"5322817725","pt":1646324302854,"mc":[{"id":"1.195532869","rc":[{"atl":[[22,4.76]],"id":40302111}],"con":true,"img":false}]}
{"op":"mcm","clk":"5322817771","pt":1646324303216,"mc":[{"id":"1.195532869","rc":[{"atl":[[2.88,166.79],[2.86,21.51]],"id":36909993}],"con":true,"img":false}]}
{"op":"mcm","clk":"5322817786","pt":1646324303318,"mc":[{"id":"1.195532869","rc":[{"atl":[[6.4,56.97]],"id":42142047}],"con":true,"img":false}]}
{"op":"mcm","clk":"5322817794","pt":1646324303427,"mc":[{"id":"1.195532869","rc":[{"atl":[[6.4,75.49],[6.2,0]],"id":42142047}],"con":true,"img":false}]}
{"op":"mcm","clk":"5322817806","pt":1646324303531,"mc":[{"id":"1.195532869","rc":[{"atl":[[6.4,7.41],[6,0],[6.8,82.63]],"id":42142047}],"con":true,"img":false}]}
{"op":"mcm","clk":"5322817838","pt":1646324303743,"mc":[{"id":"1.195532869","rc":[{"atl":[[6.2,15.38],[6.8,65.39],[7,19.17]],"id":42142047}],"con":true,"img":false}]}
{"op":"mcm","clk":"5322817888","pt":1646324304174,"mc":[{"id":"1.195532869","rc":[{"atl":[[5.6,26.74],[5.3,62.74]],"id":42609835},{"atl":[[3.95,108.93],[4.1,32.26]],"id":40133336}],"con":true,"img":false}]}
{"op":"mcm","clk":"5322818005","pt":1646324305419,"mc":[{"id":"1.195532869","rc":[{"atl":[[70,0]],"id":40302111},{"atl":[[6.4,0],[6.6,7.14]],"id":42142047},{"atb":[[1.96,2.15]],"id":40133336},{"atl":[[4.8,0],[4.6,0],[4.4,0]],"id":40133336}],"con":true,"img":false}]}
{"op":"mcm","clk":"5322818014","pt":1646324305523,"mc":[{"id":"1.195532869","rc":[{"atl":[[6.4,18.52],[7,2.5]],"id":42142047}],"con":true,"img":false}]}
{"op":"mcm","clk":"5322818023","pt":1646324305630,"mc":[{"id":"1.195532869","rc":[{"atl":[[20,15.99],[23,5]],"id":40302111},{"atl":[[6.8,17.24],[6.6,35.29]],"id":42142047},{"atb":[[1.91,8.12]],"id":40133336}],"con":true,"img":false}]}
{"op":"mcm","clk":"5322818030","pt":1646324305730,"mc":[{"id":"1.195532869","rc":[{"atl":[[19.5,7.91]],"id":40302111},{"atl":[[6.6,56.97]],"id":42142047},{"atb":[[1.9,39.82]],"id":40133336}],"con":true,"img":false}]}
{"op":"mcm","clk":"5322818040","pt":1646324305836,"mc":[{"id":"1.195532869","rc":[{"atl":[[19.5,2.5],[20,21.25],[21,0]],"id":40302111},{"atb":[[1.89,0]],"id":40133336}],"con":true,"img":false}]}
{"op":"mcm","clk":"5322818049","pt":1646324305941,"mc":[{"id":"1.195532869","rc":[{"atl":[[6,3]],"id":42142047}],"con":true,"img":false}]}
{"op":"mcm","clk":"5322818059","pt":1646324306049,"mc":[{"id":"1.195532869","rc":[{"atl":[[18.5,4.57]],"id":40302111}],"con":true,"img":false}]}
{"op":"mcm","clk":"5322818073","pt":1646324306152,"mc":[{"id":"1.195532869","rc":[{"atl":[[5.9,16.33]],"id":42142047}],"con":true,"img":false}]}
{"op":"mcm","clk":"5322818080","pt":1646324306259,"mc":[{"id":"1.195532869","rc":[{"atl":[[19,0]],"id":40302111}],"con":true,"img":false}]}
{"op":"mcm","clk":"5322818090","pt":1646324306315,"mc":[{"id":"1.195532869","rc":[{"atl":[[6.2,0]],"id":42142047}],"con":true,"img":false}]}
{"op":"mcm","clk":"5322818158","pt":1646324307050,"mc":[{"id":"1.195532869","rc":[{"atb":[[2.74,54.89]],"id":42142047}],"con":true,"img":false}]}
{"op":"mcm","clk":"5322818264","pt":1646324308253,"mc":[{"id":"1.195532869","rc":[{"atl":[[19.5,4.66]],"id":40302111},{"atl":[[6.2,7.69]],"id":42142047}],"con":true,"img":false}]}
{"op":"mcm","clk":"5322818273","pt":1646324308362,"mc":[{"id":"1.195532869","rc":[{"atl":[[20,19.14]],"id":40302111}],"con":true,"img":false}]}
{"op":"mcm","clk":"5322818297","pt":1646324308568,"mc":[{"id":"1.195532869","rc":[{"atl":[[22,0],[24,0],[60,0]],"id":40302111}],"con":true,"img":false}]}
{"op":"mcm","clk":"5322818387","pt":1646324309460,"mc":[{"id":"1.195532869","rc":[{"atb":[[1.9,34.01]],"id":40133336}],"con":true,"img":false}]}
{"op":"mcm","clk":"5322818429","pt":1646324309833,"mc":[{"id":"1.195532869","rc":[{"atb":[[5.7,1.65]],"id":40302111},{"atb":[[1.9,20.55]],"id":40133336}],"con":true,"img":false}]}
{"op":"mcm","clk":"5322818491","pt":1646324310356,"mc":[{"id":"1.195532869","rc":[{"atl":[[2.94,77.32]],"id":36909993}],"con":true,"img":false}]}
{"op":"mcm","clk":"5322818530","pt":1646324310727,"mc":[{"id":"1.195532869","rc":[{"atl":[[2.82,57.85]],"id":36909993},{"atl":[[6.6,61.7]],"id":42142047}],"con":true,"img":false}]}
{"op":"mcm","clk":"5322818541","pt":1646324310834,"mc":[{"id":"1.195532869","rc":[{"atl":[[2.8,55.56],[2.88,113.6]],"id":36909993}],"con":true,"img":false}]}
{"op":"mcm","clk":"5322818554","pt":1646324310938,"mc":[{"id":"1.195532869","rc":[{"atb":[[5.7,0]],"id":40302111},{"atl":[[2.82,43.96],[2.88,121.6],[2.78,44.94]],"id":36909993},{"atl":[[6.6,56.97]],"id":42142047}],"con":true,"img":false}]}
{"op":"mcm","clk":"5322818563","pt":1646324311039,"mc":[{"id":"1.195532869","rc":[{"atl":[[2.88,8],[2.86,137.86],[2.84,21.74]],"id":36909993},{"atb":[[3.05,10.44]],"id":42142047}],"con":true,"img":false}]}
{"op":"mcm","clk":"5322818572","pt":1646324311144,"mc":[{"id":"1.195532869","rc":[{"atb":[[5.9,1.65]],"id":40302111},{"atl":[[2.82,0],[2.88,0]],"id":36909993},{"atb":[[2.96,54.3]],"id":42142047}],"con":true,"img":false}]}
{"op":"mcm","clk":"5322818579","pt":1646324311248,"mc":[{"id":"1.195532869","rc":[{"atb":[[2.74,0]],"id":42142047}],"con":true,"img":false}]}
{"op":"mcm","clk":"5322818588","pt":1646324311352,"mc":[{"id":"1.195532869","rc":[{"atb":[[5.8,0]],"id":40302111}],"con":true,"img":false}]}
{"op":"mcm","clk":"5322818599","pt":1646324311456,"mc":[{"id":"1.195532869","rc":[{"atb":[[5.6,1.99]],"id":40302111},{"atb":[[3.05,0]],"id":42142047}],"con":true,"img":false}]}
{"op":"mcm","clk":"5322818615","pt":1646324311560,"mc":[{"id":"1.195532869","rc":[{"atl":[[4.3,45.45]],"id":40133336}],"con":true,"img":false}]}
{"op":"mcm","clk":"5322818692","pt":1646324312465,"mc":[{"id":"1.195532869","rc":[{"atb":[[2.76,26.85]],"id":42142047},{"atl":[[6.4,0],[6,23]],"id":42142047}],"con":true,"img":false}]}
{"op":"mcm","clk":"5322818711","pt":1646324312682,"mc":[{"id":"1.195532869","rc":[{"atl":[[6.2,26.92],[6,3]],"id":42142047}],"con":true,"img":false}]}
{"op":"mcm","clk":"5322818817","pt":1646324313665,"mc":[{"id":"1.195532869","rc":[{"atb":[[1.92,4.97]],"id":40133336}],"con":true,"img":false}]}
{"op":"mcm","clk":"5322818836","pt":1646324313874,"mc":[{"id":"1.195532869","rc":[{"atb":[[1.9,24.61]],"id":40133336}],"con":true,"img":false}]}
{"op":"mcm","clk":"5322818874","pt":1646324314244,"mc":[{"id":"1.195532869","rc":[{"atb":[[1.9,20.55]],"id":40133336}],"con":true,"img":false}]}
{"op":"mcm","clk":"5322819006","pt":1646324315677,"mc":[{"id":"1.195532869","rc":[{"atb":[[5.7,5.47]],"id":40302111},{"atb":[[1.92,16.37]],"id":40133336}],"con":true,"img":false}]}
{"op":"mcm","clk":"5322819036","pt":1646324315939,"mc":[{"id":"1.195532869","rc":[{"atl":[[2.84,76.09]],"id":36909993}],"con":true,"img":false}]}
{"op":"mcm","clk":"5322819046","pt":1646324316046,"mc":[{"id":"1.195532869","rc":[{"atl":[[2.8,0],[2.82,21.98],[2.84,54.35]],"id":36909993}],"con":true,"img":false}]}
{"op":"mcm","clk":"5322819061","pt":1646324316256,"mc":[{"id":"1.195532869","rc":[{"atb":[[5.6,0]],"id":40302111}],"con":true,"img":false}]}
{"op":"mcm","clk":"5322819071","pt":1646324316361,"mc":[{"id":"1.195532869","rc":[{"atb":[[5.8,1.99]],"id":40302111},{"atb":[[2.6,5.07]],"id":42142047}],"con":true,"img":false}]}
{"op":"mcm","clk":"5322819082","pt":1646324316466,"mc":[{"id":"1.195532869","rc":[{"atb":[[2.6,0]],"id":42142047}],"con":true,"img":false}]}
{"op":"mcm","clk":"5322819240","pt":1646324317941,"mc":[{"id":"1.195532869","rc":[{"atl":[[2.86,21.51],[2.84,173.25]],"id":36909993},{"atb":[[2.76,89.26]],"id":42142047}],"con":true,"img":false}]}
{"op":"mcm","clk":"5322819246","pt":1646324318044,"mc":[{"id":"1.195532869","rc":[{"atb":[[2.96,20.84]],"id":42142047}],"con":true,"img":false}]}
{"op":"mcm","clk":"5322819256","pt":1646324318151,"mc":[{"id":"1.195532869","rc":[{"atl":[[2.78,0]],"id":36909993}],"con":true,"img":false}]}
{"op":"mcm","clk":"5322819270","pt":1646324318253,"mc":[{"id":"1.195532869","rc":[{"atl":[[2.8,44.44]],"id":36909993},{"atl":[[6.2,81.42],[6.6,7.14]],"id":42142047}],"con":true,"img":false}]}
{"op":"mcm","clk":"5322819325","pt":1646324318776,"mc":[{"id":"1.195532869","rc":[{"atl":[[21,5]],"id":40302111},{"atl":[[6.6,17.86]],"id":42142047}],"con":true,"img":false}]}
{"op":"mcm","clk":"5322819369","pt":1646324319154,"mc":[{"id":"1.195532869","rc":[{"atl":[[4.1,37.14]],"id":40133336}],"con":true,"img":false}]}
{"op":"mcm","clk":"5322819383","pt":1646324319261,"mc":[{"id":"1.195532869","rc":[{"atl":[[4,13.52]],"id":40133336}],"con":true,"img":false}]}
{"op":"mcm","clk":"5322819393","pt":1646324319367,"mc":[{"id":"1.195532869","rc":[{"atl":[[4.1,32.26]],"id":40133336}],"con":true,"img":false}]}
{"op":"mcm","clk":"5322819409","pt":1646324319471,"mc":[{"id":"1.195532869","rc":[{"atl":[[2.82,0],[2.84,194.99]],"id":36909993}],"con":true,"img":false}]}
{"op":"mcm","clk":"5322819424","pt":1646324319574,"mc":[{"id":"1.195532869","rc":[{"atl":[[4.6,23.41]],"id":2441997}],"con":true,"img":false}]}
{"op":"mcm","clk":"5322819449","pt":1646324319735,"mc":[{"id":"1.195532869","rc":[{"atl":[[4.6,46.82]],"id":2441997},{"atl":[[4,0]],"id":40133336}],"con":true,"img":false}]}
{"op":"mcm","clk":"5322819456","pt":1646324319890,"mc":[{"id":"1.195532869","rc":[{"atl":[[4.5,6.37]],"id":2441997}],"con":true,"img":false}]}
{"op":"mcm","clk":"5322819466","pt":1646324319946,"mc":[{"id":"1.195532869","rc":[{"atb":[[2.24,1.65]],"id":2441997}],"con":true,"img":false}]}
{"op":"mcm","clk":"5322819481","pt":1646324320051,"mc":[{"id":"1.195532869","rc":[{"atl":[[4.7,5.72]],"id":2441997}],"con":true,"img":false}]}
{"op":"mcm","clk":"5322819497","pt":1646324320260,"mc":[{"id":"1.195532869","rc":[{"atl":[[4.7,0]],"id":2441997},{"atb":[[1.96,10.27]],"id":40133336}],"con":true,"img":false}]}
{"op":"mcm","clk":"5322819518","pt":1646324320475,"mc":[{"id":"1.195532869","rc":[{"atb":[[1.91,20.55],[1.9,0]],"id":40133336}],"con":true,"img":false}]}
{"op":"mcm","clk":"5322819526","pt":1646324320581,"mc":[{"id":"1.195532869","rc":[{"atb":[[5.7,0]],"id":40302111}],"con":true,"img":false}]}
{"op":"mcm","clk":"5322819602","pt":1646324321063,"mc":[{"id":"1.195532869","rc":[{"atb":[[5.8,0]],"id":40302111}],"con":true,"img":false}]}
{"op":"mcm","clk":"5322819613","pt":1646324321170,"mc":[{"id":"1.195532869","rc":[{"atb":[[5.6,1.99],[1.72,138.89]],"id":40302111},{"atb":[[2.22,4.49],[2.12,0],[2.14,5],[2.2,0]],"id":2441997},{"atb":[[2.98,23.07],[2.96,0]],"id":42142047},{"atb":[[2.58,5.49]],"id":42609835}],"con":true,"img":false}]}
{"op":"mcm","clk":"5322819716","pt":1646324322087,"mc":[{"id":"1.195532869","rc":[{"atl":[[4.5,71.43]],"id":40133336}],"con":true,"img":false}]}
{"op":"mcm","clk":"5322819807","pt":1646324322875,"mc":[{"id":"1.195532869","rc":[{"atb":[[1.96,9.87]],"id":2441997}],"con":true,"img":false}]}
{"op":"mcm","clk":"5322819938","pt":1646324324090,"mc":[{"id":"1.195532869","rc":[{"atb":[[1.96,0]],"id":2441997}],"con":true,"img":false}]}
{"op":"mcm","clk":"5322820004","pt":1646324324772,"mc":[{"id":"1.195532869","rc":[{"atl":[[2.86,141.28],[2.84,76.09]],"id":36909993}],"con":true,"img":false}]}
{"op":"mcm","clk":"5322820012","pt":1646324324881,"mc":[{"id":"1.195532869","rc":[{"atl":[[2.86,195.04],[2.84,21.74]],"id":36909993}],"con":true,"img":false}]}
{"op":"mcm","clk":"5322820079","pt":1646324325668,"mc":[{"id":"1.195532869","rc":[{"atb":[[5.7,5.47]],"id":40302111},{"atb":[[2.76,62.41]],"id":42142047}],"con":true,"img":false}]}
{"op":"mcm","clk":"5322820141","pt":1646324326361,"mc":[{"id":"1.195532869","rc":[{"atb":[[5.6,0]],"id":40302111}],"con":true,"img":false}]}
{"op":"mcm","clk":"5322820148","pt":1646324326464,"mc":[{"id":"1.195532869","rc":[{"atb":[[5.8,1.99]],"id":40302111},{"atl":[[4.6,23.41],[4.4,10.12]],"id":2441997}],"con":true,"img":false}]}
{"op":"mcm","clk":"5322820333","pt":1646324328253,"mc":[{"id":"1.195532869","rc":[{"spn":12.2,"spf":"NaN","id":40302111},{"atb":[[1.96,33.8]],"id":2441997},{"spn":2.24,"spf":1.0,"id":2441997},{"spn":4.55,"spf":"NaN","id":42142047},{"spn":2.91,"spf":"NaN","id":40133336}],"con":true,"img":false}]}
{"op":"mcm","clk":"5322820403","pt":1646324328988,"mc":[{"id":"1.195532869","rc":[{"atb":[[1.96,47.94]],"id":2441997}],"con":true,"img":false}]}
{"op":"mcm","clk":"5322820420","pt":1646324329199,"mc":[{"id":"1.195532869","rc":[{"atl":[[23,11.82]],"id":40302111},{"atl":[[7,27.5]],"id":42142047}],"con":true,"img":false}]}
{"op":"mcm","clk":"5322820491","pt":1646324329784,"mc":[{"id":"1.195532869","rc":[{"atl":[[2.88,53.19]],"id":36909993}],"con":true,"img":false}]}
{"op":"mcm","clk":"5322820641","pt":1646324331158,"mc":[{"id":"1.195532869","rc":[{"atb":[[5.7,0]],"id":40302111},{"atb":[[3,23.63]],"id":42142047}],"con":true,"img":false}]}
{"op":"mcm","clk":"5322820654","pt":1646324331260,"mc":[{"id":"1.195532869","rc":[{"atb":[[2.98,80.75]],"id":42142047}],"con":true,"img":false}]}
{"op":"mcm","clk":"5322820663","pt":1646324331368,"mc":[{"id":"1.195532869","rc":[{"atb":[[2.76,0]],"id":42142047}],"con":true,"img":false}]}
{"op":"mcm","clk":"5322820670","pt":1646324331472,"mc":[{"id":"1.195532869","rc":[{"atb":[[5.6,4.43]],"id":40302111}],"con":true,"img":false}]}
{"op":"mcm","clk":"5322820691","pt":1646324331685,"mc":[{"id":"1.195532869","rc":[{"atb":[[5.8,0]],"id":40302111},{"atb":[[3,47.26]],"id":42142047}],"con":true,"img":false}]}
{"op":"mcm","clk":"5322820697","pt":1646324331796,"mc":[{"id":"1.195532869","rc":[{"atb":[[5.6,1.99]],"id":40302111},{"atl":[[2.86,173.53],[2.9,0],[2.94,0]],"id":36909993},{"atb":[[2.98,57.68]],"id":42142047}],"con":true,"img":false}]}
{"op":"mcm","clk":"5322820884","pt":1646324333695,"mc":[{"id":"1.195532869","rc":[{"atb":[[2.48,3.8]],"id":42609835}],"con":true,"img":false}]}
{"op":"mcm","clk":"5322820940","pt":1646324334176,"mc":[{"id":"1.195532869","rc":[{"atb":[[2.48,0]],"id":42609835}],"con":true,"img":false}]}
{"op":"mcm","clk":"5322821096","pt":1646324335596,"mc":[{"id":"1.195532869","rc":[{"atb":[[2.6,7.64]],"id":42609835}],"con":true,"img":false}]}
{"op":"mcm","clk":"5322821115","pt":1646324335756,"mc":[{"id":"1.195532869","rc":[{"atb":[[2.56,18.57],[2.52,9.12],[2.58,1.99]],"id":42609835}],"con":true,"img":false}]}
{"op":"mcm","clk":"5322821156","pt":1646324336282,"mc":[{"id":"1.195532869","rc":[{"atb":[[5.7,5.47]],"id":40302111}],"con":true,"img":false}]}
{"op":"mcm","clk":"5322821194","pt":1646324336699,"mc":[{"id":"1.195532869","rc":[{"atb":[[1.95,105.26],[1.72,0]],"id":40302111},{"atb":[[2.56,28.1]],"id":42609835},{"atb":[[1.81,0]],"id":40133336}],"con":true,"img":false}]}
{"op":"mcm","clk":"5322821205","pt":1646324336752,"mc":[{"id":"1.195532869","rc":[{"atb":[[2.6,1.65]],"id":42609835},{"atb":[[1.94,20.55]],"id":40133336}],"con":true,"img":false}]}
{"op":"mcm","clk":"5322821212","pt":1646324336857,"mc":[{"id":"1.195532869","rc":[{"atb":[[3,23.63],[2.96,51.02]],"id":42142047},{"atb":[[1.92,52.18],[1.91,0]],"id":40133336}],"con":true,"img":false}]}
{"op":"mcm","clk":"5322821224","pt":1646324336962,"mc":[{"id":"1.195532869","rc":[{"atb":[[5.6,0]],"id":40302111}],"con":true,"img":false}]}
{"op":"mcm","clk":"5322821233","pt":1646324337070,"mc":[{"id":"1.195532869","rc":[{"atb":[[5.8,1.99]],"id":40302111}],"con":true,"img":false}]}
{"op":"mcm","clk":"5322821250","pt":1646324337280,"mc":[{"id":"1.195532869","rc":[{"atb":[[2.56,18.57]],"id":42609835}],"con":true,"img":false}]}
{"op":"mcm","clk":"5322821369","pt":1646324338293,"mc":[{"id":"1.195532869","rc":[{"atl":[[6,0]],"id":42142047}],"con":true,"img":false}]}
{"op":"mcm","clk":"5322821387","pt":1646324338490,"mc":[{"id":"1.195532869","rc":[{"atl":[[6.2,7.69],[6.6,89.1],[5.9,0]],"id":42142047}],"con":true,"img":false}]}
{"op":"mcm","clk":"5322821399","pt":1646324338598,"mc":[{"id":"1.195532869","rc":[{"atl":[[6.2,11.69],[6,16]],"id":42142047},{"atb":[[2.52,0]],"id":42609835}],"con":true,"img":false}]}
{"op":"mcm","clk":"5322821409","pt":1646324338653,"mc":[{"id":"1.195532869","rc":[{"atl":[[6.2,7.69],[6.8,34.48],[6.6,71.24]],"id":42142047}],"con":true,"img":false}]}
{"op":"mcm","clk":"5322821479","pt":1646324339310,"mc":[{"id":"1.195532869","rc":[{"atl":[[25,10.42]],"id":40302111},{"atl":[[6.4,7.41],[6.2,0]],"id":42142047}],"con":true,"img":false}]}
{"op":"mcm","clk":"5322821493","pt":1646324339489,"mc":[{"id":"1.195532869","rc":[{"atl":[[6.4,25.93],[6.8,17.24]],"id":42142047}],"con":true,"img":false}]}
{"op":"mcm","clk":"5322821500","pt":1646324339593,"mc":[{"id":"1.195532869","rc":[{"atl":[[5.9,3]],"id":42142047}],"con":true,"img":false}]}
{"op":"mcm","clk":"5322821529","pt":1646324339870,"mc":[{"id":"1.195532869","rc":[{"atl":[[6.4,18.52],[6.2,7.69]],"id":42142047}],"con":true,"img":false}]}
{"op":"mcm","clk":"5322821543","pt":1646324339966,"mc":[{"id":"1.195532869","rc":[{"atl":[[2.92,78.12]],"id":36909993}],"con":true,"img":false}]}
{"op":"mcm","clk":"5322821572","pt":1646324340384,"mc":[{"id":"1.195532869","rc":[{"atb":[[3.15,25.92]],"id":42142047},{"atb":[[1.92,47.21]],"id":40133336}],"con":true,"img":false}]}
{"op":"mcm","clk":"5322821614","pt":1646324340757,"mc":[{"id":"1.195532869","rc":[{"atb":[[3.15,4.84]],"id":42142047}],"con":true,"img":false}]}
{"op":"mcm","clk":"5322821623","pt":1646324340863,"mc":[{"id":"1.195532869","rc":[{"atl":[[2.86,181.65]],"id":36909993},{"atb":[[3.05,9.4],[3.15,0]],"id":42142047}],"con":true,"img":false}]}
{"op":"mcm","clk":"5322821636","pt":1646324340971,"mc":[{"id":"1.195532869","rc":[{"atb":[[5.7,0]],"id":40302111},{"atb":[[1.92,35.81]],"id":40133336}],"con":true,"img":false}]}
{"op":"mcm","clk":"5322821644","pt":1646324341073,"mc":[{"id":"1.195532869","rc":[{"atl":[[2.86,173.53]],"id":36909993}],"con":true,"img":false}]}
{"op":"mcm","clk":"5322821655","pt":1646324341182,"mc":[{"id":"1.195532869","rc":[{"atb":[[3.2,0]],"id":42142047}],"con":true,"img":false}]}
{"op":"mcm","clk":"5322821667","pt":1646324341282,"mc":[{"id":"1.195532869","rc":[{"atb":[[3.1,1.99]],"id":42142047}],"con":true,"img":false}]}
{"op":"mcm","clk":"5322821738","pt":1646324341968,"mc":[{"id":"1.195532869","rc":[{"atb":[[2.94,47.26],[2.96,0]],"id":42142047}],"con":true,"img":false}]}
{"op":"mcm","clk":"5322821762","pt":1646324342192,"mc":[{"id":"1.195532869","rc":[{"atb":[[5.8,0]],"id":40302111}],"con":true,"img":false}]}
{"op":"mcm","clk":"5322821774","pt":1646324342288,"mc":[{"id":"1.195532869","rc":[{"atb":[[5.6,1.99]],"id":40302111}],"con":true,"img":false}]}
{"op":"mcm","clk":"5322821785","pt":1646324342394,"mc":[{"id":"1.195532869","rc":[{"atb":[[2.56,2.15],[2.5,64.19]],"id":42609835}],"con":true,"img":false}]}
{"op":"mcm","clk":"5322821859","pt":1646324343181,"mc":[{"id":"1.195532869","rc":[{"atb":[[1.87,8.22]],"id":40133336}],"con":true,"img":false}]}
{"op":"mcm","clk":"5322821868","pt":1646324343285,"mc":[{"id":"1.195532869","rc":[{"atb":[[1.87,0]],"id":40133336}],"con":true,"img":false}]}
{"op":"mcm","clk":"5322821880","pt":1646324343390,"mc":[{"id":"1.195532869","rc":[{"atb":[[1.96,30.82],[1.94,0]],"id":40133336}],"con":true,"img":false}]}
{"op":"mcm","clk":"5322821894","pt":1646324343605,"mc":[{"id":"1.195532869","rc":[{"atb":[[1.92,0],[1.86,132.3],[1.93,3.93],[1.87,2.5]],"id":40133336}],"con":true,"img":false}]}
{"op":"mcm","clk":"5322821907","pt":1646324343658,"mc":[{"id":"1.195532869","rc":[{"atb":[[2.52,9.12]],"id":42609835}],"con":true,"img":false}]}
{"op":"mcm","clk":"5322821934","pt":1646324344077,"mc":[{"id":"1.195532869","rc":[{"atb":[[1.93,0]],"id":40133336}],"con":true,"img":false}]}
{"op":"mcm","clk":"5322821992","pt":1646324344658,"mc":[{"id":"1.195532869","rc":[{"atb":[[2.6,3.01]],"id":42142047}],"con":true,"img":false}]}
{"op":"mcm","clk":"5322822005","pt":1646324344763,"mc":[{"id":"1.195532869","rc":[{"atb":[[1.97,10.57]],"id":40133336}],"con":true,"img":false}]}
{"op":"mcm","clk":"5322822019","pt":1646324344870,"mc":[{"id":"1.195532869","rc":[{"atb":[[2.6,0]],"id":42142047},{"atb":[[1.98,14.17]],"id":40133336}],"con":true,"img":false}]}
{"op":"mcm","clk":"5322822038","pt":1646324345077,"mc":[{"id":"1.195532869","rc":[{"atb":[[1.96,22.7]],"id":40133336}],"con":true,"img":false}]}
{"op":"mcm","clk":"5322822051","pt":1646324345181,"mc":[{"id":"1.195532869","rc":[{"atb":[[2.02,2.15],[1.96,20.55]],"id":40133336}],"con":true,"img":false}]}
{"op":"mcm","clk":"5322822061","pt":1646324345286,"mc":[{"id":"1.195532869","rc":[{"atb":[[1.97,8.58]],"id":40133336}],"con":true,"img":false}]}
{"op":"mcm","clk":"5322822070","pt":1646324345388,"mc":[{"id":"1.195532869","rc":[{"atb":[[1.99,1.99]],"id":40133336}],"con":true,"img":false}]}
{"op":"mcm","clk":"5322822106","pt":1646324345759,"mc":[{"id":"1.195532869","rc":[{"atb":[[1.99,0]],"id":40133336}],"con":true,"img":false}]}
{"op":"mcm","clk":"5322822114","pt":1646324345863,"mc":[{"id":"1.195532869","rc":[{"atb":[[2.04,1.99]],"id":40133336}],"con":true,"img":false}]}
{"op":"mcm","clk":"5322822122","pt":1646324345967,"mc":[{"id":"1.195532869","rc":[{"atl":[[6.4,0],[5.8,7.69]],"id":42142047}],"con":true,"img":false}]}
{"op":"mcm","clk":"5322822141","pt":1646324346177,"mc":[{"id":"1.195532869","rc":[{"atl":[[5.9,18.38]],"id":42142047}],"con":true,"img":false}]}
{"op":"mcm","clk":"5322822153","pt":1646324346283,"mc":[{"id":"1.195532869","rc":[{"atl":[[5.8,0]],"id":42142047}],"con":true,"img":false}]}
{"op":"mcm","clk":"5322822214","pt":1646324346824,"mc":[{"id":"1.195532869","rc":[{"atb":[[5.7,5.47]],"id":40302111},{"atb":[[1.88,53.71]],"id":40133336}],"con":true,"img":false}]}
{"op":"mcm","clk":"5322822232","pt":1646324346967,"mc":[{"id":"1.195532869","rc":[{"atb":[[5.9,0]],"id":40302111}],"con":true,"img":false}]}
{"op":"mcm","clk":"5322822246","pt":1646324347174,"mc":[{"id":"1.195532869","rc":[{"atb":[[5.7,7.13]],"id":40302111},{"atb":[[2.06,1.65]],"id":40133336}],"con":true,"img":false}]}
{"op":"mcm","clk":"5322822358","pt":1646324348488,"mc":[{"id":"1.195532869","rc":[{"atb":[[5.6,0]],"id":40302111}],"con":true,"img":false}]}
{"op":"mcm","clk":"5322822368","pt":1646324348591,"mc":[{"id":"1.195532869","rc":[{"atb":[[5.8,1.99]],"id":40302111}],"con":true,"img":false}]}
{"op":"mcm","clk":"5322822448","pt":1646324349181,"mc":[{"id":"1.195532869","rc":[{"atb":[[1.97,0]],"id":40133336}],"con":true,"img":false}]}
{"op":"mcm","clk":"5322822528","pt":1646324349801,"mc":[{"id":"1.195532869","rc":[{"atb":[[2.5,26.66],[2.52,25.1]],"id":42609835}],"con":true,"img":false}]}
{"op":"mcm","clk":"5322822547","pt":1646324349905,"mc":[{"id":"1.195532869","rc":[{"atl":[[7.4,39.06]],"id":42142047}],"con":true,"img":false}]}
{"op":"mcm","clk":"5322822556","pt":1646324350011,"mc":[{"id":"1.195532869","rc":[{"atl":[[16.5,5],[18.5,10],[14.5,2.5]],"id":40302111},{"atl":[[2.96,127.55]],"id":36909993}],"con":true,"img":false}]}
{"op":"mcm","clk":"5322822568","pt":1646324350068,"mc":[{"id":"1.195532869","rc":[{"atl":[[19.5,2.16],[23,6.82]],"id":40302111}],"con":true,"img":false}]}
{"op":"mcm","clk":"5322822579","pt":1646324350174,"mc":[{"id":"1.195532869","rc":[{"atl":[[18.5,34.15],[19,3.37],[20,0],[21,9.06]],"id":40302111}],"con":true,"img":false}]}
{"op":"mcm","clk":"5322822594","pt":1646324350386,"mc":[{"id":"1.195532869","rc":[{"atl":[[21,5]],"id":40302111}],"con":true,"img":false}]}
{"op":"mcm","clk":"5322822639","pt":1646324351021,"mc":[{"id":"1.195532869","rc":[{"atb":[[1.98,29.13]],"id":40133336}],"con":true,"img":false}]}
{"op":"mcm","clk":"5322822648","pt":1646324351039,"mc":[{"id":"1.195532869","rc":[{"atb":[[1.86,46.51]],"id":40133336}],"con":true,"img":false}]}
{"op":"mcm","clk":"5322822775","pt":1646324352381,"mc":[{"id":"1.195532869","rc":[{"atl":[[6.2,66.13],[6.6,17.86]],"id":42142047}],"con":true,"img":false}]}
{"op":"mcm","clk":"5322822797","pt":1646324352587,"mc":[{"id":"1.195532869","rc":[{"atl":[[5.8,16.67]],"id":42142047}],"con":true,"img":false}]}
{"op":"mcm","clk":"5322822810","pt":1646324352689,"mc":[{"id":"1.195532869","rc":[{"atl":[[5.7,16.67],[5.9,3]],"id":42142047}],"con":true,"img":false}]}
{"op":"mcm","clk":"5322822825","pt":1646324352794,"mc":[{"id":"1.195532869","rc":[{"atb":[[5.9,1.76]],"id":40302111},{"atl":[[19.5,0],[15.5,2.76]],"id":40302111},{"atb":[[2.26,3.55]],"id":2441997},{"atb":[[1.75,3.84]],"id":36909993},{"atb":[[2.94,0],[2.92,47.26]],"id":42142047},{"atl":[[6.2,58.44],[7.4,0],[6,8],[6.6,0],[7,0]],"id":42142047},{"atb":[[1.96,0],[2.08,4.5],[1.97,20.55]],"id":40133336}],"con":true,"img":false}]}
{"op":"mcm","clk":"5322822837","pt":1646324352896,"mc":[{"id":"1.195532869","rc":[{"atl":[[6.4,6.94],[6.8,0],[5.9,11.16]],"id":42142047}],"con":true,"img":false}]}
{"op":"mcm","clk":"5322822845","pt":1646324352999,"mc":[{"id":"1.195532869","rc":[{"atl":[[18.5,29.49],[15.5,7.76]],"id":40302111},{"atb":[[1.68,93.07],[1.71,131.31],[1.69,68.5]],"id":36909993}],"con":true,"img":false}]}
{"op":"mcm","clk":"5322822876","pt":1646324353380,"mc":[{"id":"1.195532869","rc":[{"atl":[[6.4,0]],"id":42142047},{"atb":[[1.88,0]],"id":40133336}],"con":true,"img":false}]}
{"op":"mcm","clk":"5322822887","pt":1646324353476,"mc":[{"id":"1.195532869","rc":[{"atb":[[2.22,2.5],[2.12,4]],"id":2441997},{"atb":[[1.99,4.01]],"id":40133336}],"con":true,"img":false}]}
{"op":"mcm","clk":"5322822894","pt":1646324353578,"mc":[{"id":"1.195532869","rc":[{"atb":[[2.28,1.99]],"id":2441997}],"con":true,"img":false}]}
{"op":"mcm","clk":"5322822903","pt":1646324353684,"mc":[{"id":"1.195532869","rc":[{"atb":[[2.3,3.38]],"id":2441997}],"con":true,"img":false}]}
{"op":"mcm","clk":"5322822914","pt":1646324353786,"mc":[{"id":"1.195532869","rc":[{"atb":[[2.04,0]],"id":40133336}],"con":true,"img":false}]}
{"op":"mcm","clk":"5322822922","pt":1646324353890,"mc":[{"id":"1.195532869","rc":[{"atb":[[2.12,0]],"id":2441997},{"atb":[[1.68,58.82],[1.67,8.56]],"id":36909993},{"atb":[[2.1,1.99]],"id":40133336}],"con":true,"img":false}]}
{"op":"mcm","clk":"5322822928","pt":1646324354009,"mc":[{"id":"1.195532869","rc":[{"atb":[[2.12,4.26]],"id":40133336}],"con":true,"img":false}]}
{"op":"mcm","clk":"5322822962","pt":1646324354408,"mc":[{"id":"1.195532869","rc":[{"atb":[[1.67,0]],"id":36909993}],"con":true,"img":false}]}
{"op":"mcm","clk":"5322822989","pt":1646324354671,"mc":[{"id":"1.195532869","rc":[{"atb":[[2.28,0]],"id":2441997}],"con":true,"img":false}]}
{"op":"mcm","clk":"5322823001","pt":1646324354779,"mc":[{"id":"1.195532869","rc":[{"atb":[[2.32,1.99]],"id":2441997}],"con":true,"img":false}]}
{"op":"mcm","clk":"5322823007","pt":1646324354886,"mc":[{"id":"1.195532869","rc":[{"atb":[[2.3,0],[2.26,0]],"id":2441997}],"con":true,"img":false}]}
{"op":"mcm","clk":"5322823016","pt":1646324354988,"mc":[{"id":"1.195532869","rc":[{"atb":[[2.1,0]],"id":40133336}],"con":true,"img":false}]}
{"op":"mcm","clk":"5322823026","pt":1646324355092,"mc":[{"id":"1.195532869","rc":[{"atb":[[2.34,3.22]],"id":2441997},{"atb":[[2.12,0],[2.14,1.99],[2.08,0]],"id":40133336}],"con":true,"img":false}]}
{"op":"mcm","clk":"5322823064","pt":1646324355611,"mc":[{"id":"1.195532869","rc":[{"atb":[[1.96,33.8]],"id":2441997},{"atb":[[1.71,82.72]],"id":36909993}],"con":true,"img":false}]}
{"op":"mcm","clk":"5322823084","pt":1646324355767,"mc":[{"id":"1.195532869","rc":[{"atb":[[2.16,4.03]],"id":40133336}],"con":true,"img":false}]}
{"op":"mcm","clk":"5322823101","pt":1646324355979,"mc":[{"id":"1.195532869","rc":[{"atb":[[5.7,0]],"id":40302111},{"atb":[[1.96,0],[2.24,0]],"id":2441997},{"atb":[[1.69,0]],"id":36909993},{"atb":[[2.06,0]],"id":40133336}],"con":true,"img":false}]}
{"op":"mcm","clk":"5322823122","pt":1646324356182,"mc":[{"id":"1.195532869","rc":[{"atb":[[6,1.65]],"id":40302111},{"atb":[[2.16,5.68]],"id":40133336}],"con":true,"img":false}]}
{"op":"mcm","clk":"5322823133","pt":1646324356287,"mc":[{"id":"1.195532869","rc":[{"atb":[[6.2,3.21]],"id":40302111}],"con":true,"img":false}]}
{"op":"mcm","clk":"5322823143","pt":1646324356391,"mc":[{"id":"1.195532869","rc":[{"atb":[[2.32,0]],"id":2441997}],"con":true,"img":false}]}
{"op":"mcm","clk":"5322823150","pt":1646324356495,"mc":[{"id":"1.195532869","rc":[{"atb":[[2.36,1.99]],"id":2441997}],"con":true,"img":false}]}
{"op":"mcm","clk":"5322823159","pt":1646324356598,"mc":[{"id":"1.195532869","rc":[{"atb":[[2.34,0],[2.38,3.08]],"id":2441997}],"con":true,"img":false}]}
{"op":"mcm","clk":"5322823167","pt":1646324356702,"mc":[{"id":"1.195532869","rc":[{"atb":[[5.8,0]],"id":40302111}],"con":true,"img":false}]}
{"op":"mcm","clk":"5322823175","pt":1646324356807,"mc":[{"id":"1.195532869","rc":[{"atb":[[6,3.64]],"id":40302111}],"con":true,"img":false}]}
{"op":"mcm","clk":"5322823194","pt":1646324357025,"mc":[{"id":"1.195532869","rc":[{"atb":[[2.14,0]],"id":40133336}],"con":true,"img":false}]}
{"op":"mcm","clk":"5322823202","pt":1646324357084,"mc":[{"id":"1.195532869","rc":[{"atb":[[2.18,1.99]],"id":40133336}],"con":true,"img":false}]}
{"op":"mcm","clk":"5322823216","pt":1646324357177,"mc":[{"id":"1.195532869","rc":[{"atb":[[2.18,5.92]],"id":40133336}],"con":true,"img":false}]}
{"op":"mcm","clk":"5322823250","pt":1646324357499,"mc":[{"id":"1.195532869","rc":[{"atb":[[1.98,14.17],[2.02,16.66]],"id":40133336}],"con":true,"img":false}]}
{"op":"mcm","clk":"5322823276","pt":1646324357806,"mc":[{"id":"1.195532869","rc":[{"atb":[[2.22,2.15],[2.02,14.51]],"id":40133336}],"con":true,"img":false}]}
{"op":"mcm","clk":"5322823287","pt":1646324357912,"mc":[{"id":"1.195532869","rc":[{"atl":[[5.8,37.5],[5.7,0]],"id":42142047}],"con":true,"img":false}]}
{"op":"mcm","clk":"5322823299","pt":1646324357967,"mc":[{"id":"1.195532869","rc":[{"atb":[[2.02,0]],"id":40133336}],"con":true,"img":false}]}
{"op":"mcm","clk":"5322823308","pt":1646324358120,"mc":[{"id":"1.195532869","rc":[{"atl":[[16.5,11.45],[15.5,2.76]],"id":40302111},{"atb":[[2.36,0]],"id":2441997},{"atl":[[5.8,16.67],[5.9,23.41]],"id":42142047}],"con":true,"img":false}]}
{"op":"mcm","clk":"5322823324","pt":1646324358181,"mc":[{"id":"1.195532869","rc":[{"atb":[[2.4,1.99]],"id":2441997}],"con":true,"img":false}]}
{"op":"mcm","clk":"5322823337","pt":1646324358284,"mc":[{"id":"1.195532869","rc":[{"atb":[[2.42,2.94],[2.38,0]],"id":2441997}],"con":true,"img":false}]}
{"op":"mcm","clk":"5322823359","pt":1646324358506,"mc":[{"id":"1.195532869","rc":[{"atb":[[6,1.65]],"id":40302111},{"atl":[[4,6.78]],"id":40133336}],"con":true,"img":false}]}
{"op":"mcm","clk":"5322823372","pt":1646324358596,"mc":[{"id":"1.195532869","rc":[{"atb":[[1.02,1.99]],"id":40302111},{"atb":[[2,9.12]],"id":40133336}],"con":true,"img":false}]}
{"op":"mcm","clk":"5322823381","pt":1646324358702,"mc":[{"id":"1.195532869","rc":[{"atl":[[4,0]],"id":40133336}],"con":true,"img":false}]}
{"op":"mcm","clk":"5322823441","pt":1646324359284,"mc":[{"id":"1.195532869","rc":[{"atb":[[2.4,0]],"id":2441997}],"con":true,"img":false}]}
{"op":"mcm","clk":"5322823451","pt":1646324359393,"mc":[{"id":"1.195532869","rc":[{"atb":[[2.42,0],[1.02,1.99]],"id":2441997}],"con":true,"img":false}]}
{"op":"mcm","clk":"5322823458","pt":1646324359495,"mc":[{"id":"1.195532869","rc":[{"atb":[[2.24,3.64]],"id":2441997}],"con":true,"img":false}]}
{"op":"mcm","clk":"5322823476","pt":1646324359704,"mc":[{"id":"1.195532869","rc":[{"atb":[[2.18,3.93]],"id":40133336}],"con":true,"img":false}]}
{"op":"mcm","clk":"5322823490","pt":1646324359813,"mc":[{"id":"1.195532869","rc":[{"atb":[[2.24,1.99]],"id":40133336}],"con":true,"img":false}]}
{"op":"mcm","clk":"5322823519","pt":1646324359971,"mc":[{"id":"1.195532869","rc":[{"atl":[[3.85,4],[5.1,21],[4.6,37.41],[3.95,6],[4.2,9]],"id":2441997}],"con":true,"img":false}]}
{"op":"mcm","clk":"5322823540","pt":1646324360074,"mc":[{"id":"1.195532869","rc":[{"atl":[[3.8,6],[4.4,3.75],[4.6,14],[3.95,19.56],[4.2,27],[3.65,8.53]],"id":2441997}],"con":true,"img":false}]}
{"op":"mcm","clk":"5322823549","pt":1646324360185,"mc":[{"id":"1.195532869","rc":[{"atl":[[4.8,3.2],[4.2,30.5]],"id":2441997}],"con":true,"img":false}]}
{"op":"mcm","clk":"5322823565","pt":1646324360284,"mc":[{"id":"1.195532869","rc":[{"atb":[[2.16,5.85]],"id":2441997},{"atl":[[4.4,0],[3.65,0]],"id":2441997},{"atb":[[1.69,5.37]],"id":36909993},{"atb":[[1.99,0]],"id":40133336}],"con":true,"img":false}]}
{"op":"mcm","clk":"5322823576","pt":1646324360394,"mc":[{"id":"1.195532869","rc":[{"atb":[[1.02,0]],"id":2441997},{"atl":[[4.8,0],[3.7,5.73]],"id":2441997}],"con":true,"img":false}]}
{"op":"mcm","clk":"5322823588","pt":1646324360501,"mc":[{"id":"1.195532869","rc":[{"atb":[[2.26,1.99]],"id":2441997}],"con":true,"img":false}]}
{"op":"mcm","clk":"5322823602","pt":1646324360628,"mc":[{"id":"1.195532869","rc":[{"atb":[[2.28,3.46]],"id":2441997}],"con":true,"img":false}]}
{"op":"mcm","clk":"5322823618","pt":1646324360807,"mc":[{"id":"1.195532869","rc":[{"atl":[[4.2,27]],"id":2441997}],"con":true,"img":false}]}
{"op":"mcm","clk":"5322823662","pt":1646324361172,"mc":[{"id":"1.195532869","rc":[{"atb":[[2.26,0]],"id":2441997}],"con":true,"img":false}]}
{"op":"mcm","clk":"5322823671","pt":1646324361281,"mc":[{"id":"1.195532869","rc":[{"atb":[[2.3,1.99],[2.24,0],[2.28,0]],"id":2441997}],"con":true,"img":false}]}
{"op":"mcm","clk":"5322823696","pt":1646324361599,"mc":[{"id":"1.195532869","rc":[{"atb":[[2.3,0]],"id":2441997}],"con":true,"img":false}]}
{"op":"mcm","clk":"5322823707","pt":1646324361702,"mc":[{"id":"1.195532869","rc":[{"atb":[[2.24,5.63]],"id":2441997}],"con":true,"img":false}]}
{"op":"mcm","clk":"5322823716","pt":1646324361804,"mc":[{"id":"1.195532869","rc":[{"atb":[[2.16,20.54]],"id":2441997},{"atb":[[1.69,17.84]],"id":36909993}],"con":true,"img":false}]}
{"op":"mcm","clk":"5322823722","pt":1646324361911,"mc":[{"id":"1.195532869","rc":[{"atb":[[2.82,9],[2.64,21],[2.92,51.26],[2.88,6],[2.74,14]],"id":42142047}],"con":true,"img":false}]}
{"op":"mcm","clk":"5322823744","pt":1646324362116,"mc":[{"id":"1.195532869","rc":[{"atl":[[3.8,20.29],[3.95,6]],"id":2441997}],"con":true,"img":false}]}
{"op":"mcm","clk":"5322823791","pt":1646324362594,"mc":[{"id":"1.195532869","rc":[{"atl":[[16.5,17.9]],"id":40302111}],"con":true,"img":false}]}
{"op":"mcm","clk":"5322823801","pt":1646324362696,"mc":[{"id":"1.195532869","rc":[{"atl":[[6.4,18.52]],"id":42142047}],"con":true,"img":false}]}
{"op":"mcm","clk":"5322823820","pt":1646324362902,"mc":[{"id":"1.195532869","rc":[{"atl":[[25,0]],"id":40302111}],"con":true,"img":false}]}
{"op":"mcm","clk":"5322823846","pt":1646324363215,"mc":[{"id":"1.195532869","rc":[{"atb":[[1.95,0],[2.28,50]],"id":40302111},{"atb":[[1.87,0],[1.92,67.8]],"id":2441997},{"atb":[[3.05,33.03],[2.92,4]],"id":42142047},{"atb":[[2.02,14.17],[1.97,0]],"id":40133336}],"con":true,"img":false}]}
{"op":"mcm","clk":"5322823855","pt":1646324363319,"mc":[{"id":"1.195532869","rc":[{"atl":[[7.2,21],[6.2,72.44],[5.2,4],[5.7,9],[5.4,6]],"id":42142047}],"con":true,"img":false}]}
{"op":"mcm","clk":"5322823884","pt":1646324363684,"mc":[{"id":"1.195532869","rc":[{"atl":[[5.9,20.41]],"id":42142047}],"con":true,"img":false}]}
{"op":"mcm","clk":"5322823905","pt":1646324363892,"mc":[{"id":"1.195532869","rc":[{"atl":[[16.5,29.84],[18.5,10],[14,3.94]],"id":40302111}],"con":true,"img":false}]}
{"op":"mcm","clk":"5322823915","pt":1646324364000,"mc":[{"id":"1.195532869","rc":[{"atl":[[19,0],[13.5,2.76]],"id":40302111},{"atb":[[2,0]],"id":40133336}],"con":true,"img":false}]}
{"op":"mcm","clk":"5322823928","pt":1646324364106,"mc":[{"id":"1.195532869","rc":[{"atl":[[16.5,23.39],[13.5,0],[15.5,9.66]],"id":40302111}],"con":true,"img":false}]}
{"op":"mcm","clk":"5322823945","pt":1646324364311,"mc":[{"id":"1.195532869","rc":[{"atl":[[5.3,3]],"id":42142047}],"con":true,"img":false}]}
{"op":"mcm","clk":"5322823953","pt":1646324364520,"mc":[{"id":"1.195532869","rc":[{"atl":[[5.9,0],[5.5,16.67]],"id":42142047}],"con":true,"img":false}]}
{"op":"mcm","clk":"5322823990","pt":1646324364888,"mc":[{"id":"1.195532869","rc":[{"atb":[[2.24,4.89]],"id":40133336}],"con":true,"img":false}]}
{"op":"mcm","clk":"5322823999","pt":1646324364999,"mc":[{"id":"1.195532869","rc":[{"atb":[[6,0]],"id":40302111},{"atb":[[2.16,4.03]],"id":40133336}],"con":true,"img":false}]}
{"op":"mcm","clk":"5322824020","pt":1646324365203,"mc":[{"id":"1.195532869","rc":[{"atb":[[6.4,1.65],[5.9,0],[6.2,0]],"id":40302111},{"atb":[[2.26,1.65]],"id":2441997},{"atl":[[3.85,30.02]],"id":2441997}],"con":true,"img":false}]}
{"op":"mcm","clk":"5322824031","pt":1646324365307,"mc":[{"id":"1.195532869","rc":[{"atb":[[2.28,3.46]],"id":2441997},{"atl":[[3.8,14.29]],"id":2441997}],"con":true,"img":false}]}
{"op":"mcm","clk":"5322824042","pt":1646324365409,"mc":[{"id":"1.195532869","rc":[{"atb":[[1.02,0],[6.6,2.8]],"id":40302111}],"con":true,"img":false}]}
{"op":"mcm","clk":"5322824049","pt":1646324365516,"mc":[{"id":"1.195532869","rc":[{"atb":[[5.6,1.99]],"id":40302111}],"con":true,"img":false}]}
{"op":"mcm","clk":"5322824076","pt":1646324365779,"mc":[{"id":"1.195532869","rc":[{"atb":[[2.24,3.64]],"id":2441997}],"con":true,"img":false}]}
{"op":"mcm","clk":"5322824084","pt":1646324365884,"mc":[{"id":"1.195532869","rc":[{"atb":[[2.3,1.99]],"id":2441997}],"con":true,"img":false}]}
{"op":"mcm","clk":"5322824097","pt":1646324365985,"mc":[{"id":"1.195532869","rc":[{"atb":[[2.32,3.3]],"id":2441997}],"con":true,"img":false}]}
{"op":"mcm","clk":"5322824113","pt":1646324366098,"mc":[{"id":"1.195532869","rc":[{"atb":[[5.6,0]],"id":40302111},{"atl":[[6.2,14],[5.4,65.26]],"id":42142047}],"con":true,"img":false}]}
{"op":"mcm","clk":"5322824125","pt":1646324366192,"mc":[{"id":"1.195532869","rc":[{"atb":[[1.02,1.99]],"id":40302111}],"con":true,"img":false}]}
{"op":"mcm","clk":"5322824133","pt":1646324366300,"mc":[{"id":"1.195532869","rc":[{"atl":[[5.2,23.05]],"id":42142047}],"con":true,"img":false}]}
{"op":"mcm","clk":"5322824157","pt":1646324366511,"mc":[{"id":"1.195532869","rc":[{"atl":[[5.8,0]],"id":42142047}],"con":true,"img":false}]}
{"op":"mcm","clk":"5322824180","pt":1646324366717,"mc":[{"id":"1.195532869","rc":[{"atb":[[2.3,0]],"id":2441997}],"con":true,"img":false}]}
{"op":"mcm","clk":"5322824189","pt":1646324366820,"mc":[{"id":"1.195532869","rc":[{"atb":[[2.34,1.99]],"id":2441997}],"con":true,"img":false}]}
{"op":"mcm","clk":"5322824198","pt":1646324366924,"mc":[{"id":"1.195532869","rc":[{"atb":[[2.32,0],[2.24,0],[2.28,0]],"id":2441997}],"con":true,"img":false}]}
{"op":"mcm","clk":"5322824236","pt":1646324367296,"mc":[{"id":"1.195532869","rc":[{"atb":[[2.34,0]],"id":2441997}],"con":true,"img":false}]}
{"op":"mcm","clk":"5322824247","pt":1646324367397,"mc":[{"id":"1.195532869","rc":[{"atb":[[2.28,5.45]],"id":2441997}],"con":true,"img":false}]}
{"op":"mcm","clk":"5322824401","pt":1646324369120,"mc":[{"id":"1.195532869","rc":[{"atb":[[2.16,14.69]],"id":2441997}],"con":true,"img":false}]}
{"op":"mcm","clk":"5322824414","pt":1646324369226,"mc":[{"id":"1.195532869","rc":[{"atl":[[15,2.86],[15.5,6.9]],"id":40302111},{"atb":[[3,58.65],[3.05,9.4]],"id":42142047},{"atl":[[5.4,74.35]],"id":42142047}],"con":true,"img":false}]}
{"op":"mcm","clk":"5322824425","pt":1646324369285,"mc":[{"id":"1.195532869","rc":[{"atb":[[3,68.35]],"id":42142047}],"con":true,"img":false}]}
{"op":"mcm","clk":"5322824454","pt":1646324369592,"mc":[{"id":"1.195532869","rc":[{"atb":[[5.6,9.81]],"id":40302111},{"atb":[[2.16,0]],"id":2441997},{"atb":[[2.26,7.33]],"id":40133336}],"con":true,"img":false}]}
{"op":"mcm","clk":"5322824469","pt":1646324369809,"mc":[{"id":"1.195532869","rc":[{"atb":[[3,58.65]],"id":42142047}],"con":true,"img":false}]}
{"op":"mcm","clk":"5322824488","pt":1646324370018,"mc":[{"id":"1.195532869","rc":[{"atb":[[2.46,74.3]],"id":42609835},{"atb":[[2.24,2.9]],"id":40133336}],"con":true,"img":false}]}
{"op":"mcm","clk":"5322824496","pt":1646324370117,"mc":[{"id":"1.195532869","rc":[{"atb":[[2.58,5.49]],"id":42609835},{"atb":[[2.28,1.99]],"id":40133336}],"con":true,"img":false}]}
{"op":"mcm","clk":"5322824525","pt":1646324370496,"mc":[{"id":"1.195532869","rc":[{"atb":[[2.3,2.15],[2.22,0]],"id":40133336}],"con":true,"img":false}]}
{"op":"mcm","clk":"5322824537","pt":1646324370591,"mc":[{"id":"1.195532869","rc":[{"atb":[[2.46,68.49]],"id":42609835}],"con":true,"img":false}]}
{"op":"mcm","clk":"5322824554","pt":1646324370798,"mc":[{"id":"1.195532869","rc":[{"atl":[[5.4,97.08]],"id":42142047}],"con":true,"img":false}]}
{"op":"mcm","clk":"5322824560","pt":1646324370908,"mc":[{"id":"1.195532869","rc":[{"atl":[[5.5,0]],"id":42142047}],"con":true,"img":false}]}
{"op":"mcm","clk":"5322824626","pt":1646324371692,"mc":[{"id":"1.195532869","rc":[{"atl":[[3.9,34.48]],"id":2441997}],"con":true,"img":false}]}
{"op":"mcm","clk":"5322824634","pt":1646324371792,"mc":[{"id":"1.195532869","rc":[{"atb":[[2.28,0]],"id":40133336}],"con":true,"img":false}]}
{"op":"mcm","clk":"5322824644","pt":1646324371896,"mc":[{"id":"1.195532869","rc":[{"atb":[[2.32,1.99]],"id":40133336}],"con":true,"img":false}]}
{"op":"mcm","clk":"5322824788","pt":1646324373621,"mc":[{"id":"1.195532869","rc":[{"atl":[[3.85,52.38]],"id":2441997}],"con":true,"img":false}]}
{"op":"mcm","clk":"5322824799","pt":1646324373718,"mc":[{"id":"1.195532869","rc":[{"atl":[[4.2,9]],"id":2441997}],"con":true,"img":false}]}
{"op":"mcm","clk":"5322824826","pt":1646324374030,"mc":[{"id":"1.195532869","rc":[{"atb":[[6.4,0]],"id":40302111},{"atb":[[2.26,0],[2.16,7.63]],"id":2441997},{"atb":[[2.24,0]],"id":40133336}],"con":true,"img":false}]}
{"op":"mcm","clk":"5322824846","pt":1646324374197,"mc":[{"id":"1.195532869","rc":[{"atb":[[6.6,0]],"id":40302111},{"atb":[[2.3,1.65]],"id":2441997}],"con":true,"img":false}]}
{"op":"mcm","clk":"5322824853","pt":1646324374301,"mc":[{"id":"1.195532869","rc":[{"atb":[[5.7,1.9]],"id":40302111},{"atb":[[2.32,3.3]],"id":2441997}],"con":true,"img":false}]}
{"op":"mcm","clk":"5322824895","pt":1646324374737,"mc":[{"id":"1.195532869","rc":[{"atb":[[2.16,25.34]],"id":2441997},{"atb":[[2.26,0]],"id":40133336}],"con":true,"img":false}]}
{"op":"mcm","clk":"5322824908","pt":1646324374931,"mc":[{"id":"1.195532869","rc":[{"atb":[[2.24,3.66],[2.16,14.25]],"id":40133336}],"con":true,"img":false}]}
{"op":"mcm","clk":"5322824923","pt":1646324375087,"mc":[{"id":"1.195532869","rc":[{"atb":[[1.85,5.82]],"id":40133336}],"con":true,"img":false}]}
{"op":"mcm","clk":"5322824934","pt":1646324375203,"mc":[{"id":"1.195532869","rc":[{"atb":[[2.28,3.46]],"id":2441997},{"atb":[[2.24,0],[2.16,4.02]],"id":40133336}],"con":true,"img":false}]}
{"op":"mcm","clk":"5322824942","pt":1646324375297,"mc":[{"id":"1.195532869","rc":[{"atb":[[2.34,1.99]],"id":2441997}],"con":true,"img":false}]}
{"op":"mcm","clk":"5322824953","pt":1646324375399,"mc":[{"id":"1.195532869","rc":[{"atb":[[2.36,3.15]],"id":2441997}],"con":true,"img":false}]}
{"op":"mcm","clk":"5322824962","pt":1646324375507,"mc":[{"id":"1.195532869","rc":[{"atb":[[1.02,0]],"id":40302111}],"con":true,"img":false}]}
{"op":"mcm","clk":"5322824970","pt":1646324375616,"mc":[{"id":"1.195532869","rc":[{"atb":[[5.7,3.89]],"id":40302111},{"atb":[[1.85,0]],"id":40133336}],"con":true,"img":false}]}
{"op":"mcm","clk":"5322825029","pt":1646324376302,"mc":[{"id":"1.195532869","rc":[{"atb":[[2.34,0]],"id":2441997}],"con":true,"img":false}]}
{"op":"mcm","clk":"5322825040","pt":1646324376406,"mc":[{"id":"1.195532869","rc":[{"atb":[[2.38,1.99]],"id":2441997}],"con":true,"img":false}]}
{"op":"mcm","clk":"5322825049","pt":1646324376512,"mc":[{"id":"1.195532869","rc":[{"atb":[[2.32,0],[2.36,0],[2.28,0]],"id":2441997}],"con":true,"img":false}]}
{"op":"mcm","clk":"5322825079","pt":1646324376822,"mc":[{"id":"1.195532869","rc":[{"atb":[[2.38,0]],"id":2441997}],"con":true,"img":false}]}
{"op":"mcm","clk":"5322825089","pt":1646324376934,"mc":[{"id":"1.195532869","rc":[{"atb":[[2.32,1.99]],"id":2441997}],"con":true,"img":false}]}
{"op":"mcm","clk":"5322825099","pt":1646324377027,"mc":[{"id":"1.195532869","rc":[{"atb":[[2.32,5.29]],"id":2441997}],"con":true,"img":false}]}
{"op":"mcm","clk":"5322825136","pt":1646324377406,"mc":[{"id":"1.195532869","rc":[{"atl":[[16.5,11.45],[15,16.36]],"id":40302111}],"con":true,"img":false}]}
{"op":"mcm","clk":"5322825147","pt":1646324377502,"mc":[{"id":"1.195532869","rc":[{"atl":[[14.5,9.91],[15.5,0]],"id":40302111}],"con":true,"img":false}]}
{"op":"mcm","clk":"5322825245","pt":1646324378706,"mc":[{"id":"1.195532869","rc":[{"atb":[[2.16,17.71]],"id":2441997},{"atl":[[5.6,21.74]],"id":42142047},{"atb":[[2.2,5.38]],"id":40133336}],"con":true,"img":false}]}
{"op":"mcm","clk":"5322825323","pt":1646324379609,"mc":[{"id":"1.195532869","rc":[{"atb":[[2.2,17.82]],"id":40133336}],"con":true,"img":false}]}
{"op":"mcm","clk":"5322825470","pt":1646324381233,"mc":[{"id":"1.195532869","rc":[{"atl":[[4,50]],"id":2441997}],"con":true,"img":false}]}
{"op":"mcm","clk":"5322825479","pt":1646324381337,"mc":[{"id":"1.195532869","rc":[{"atl":[[7.4,0],[4.9,5],[7.8,0]],"id":2441997}],"con":true,"img":false}]}
{"op":"mcm","clk":"5322825538","pt":1646324381919,"mc":[{"id":"1.195532869","rc":[{"atb":[[2.16,0]],"id":2441997}],"con":true,"img":false}]}
{"op":"mcm","clk":"5322825592","pt":1646324382703,"mc":[{"id":"1.195532869","rc":[{"atl":[[15,23.5]],"id":40302111}],"con":true,"img":false}]}
{"op":"mcm","clk":"5322825602","pt":1646324382844,"mc":[{"id":"1.195532869","rc":[{"atl":[[14.5,2.5]],"id":40302111}],"con":true,"img":false}]}
{"op":"mcm","clk":"5322825614","pt":1646324383018,"mc":[{"id":"1.195532869","rc":[{"atb":[[2.3,0]],"id":2441997}],"con":true,"img":false}]}
{"op":"mcm","clk":"5322825628","pt":1646324383226,"mc":[{"id":"1.195532869","rc":[{"atb":[[5.8,1.65]],"id":40302111},{"atb":[[2.34,1.65]],"id":2441997}],"con":true,"img":false}]}
{"op":"mcm","clk":"5322825636","pt":1646324383332,"mc":[{"id":"1.195532869","rc":[{"atb":[[5.9,1.76]],"id":40302111},{"atb":[[2.36,3.15]],"id":2441997}],"con":true,"img":false}]}
{"op":"mcm","clk":"5322825657","pt":1646324383544,"mc":[{"id":"1.195532869","rc":[{"atb":[[5.5,6.52]],"id":40302111}],"con":true,"img":false}]}
{"op":"mcm","clk":"5322825688","pt":1646324383810,"mc":[{"id":"1.195532869","rc":[{"atb":[[2.32,3.3]],"id":2441997}],"con":true,"img":false}]}
{"op":"mcm","clk":"5322825700","pt":1646324383913,"mc":[{"id":"1.195532869","rc":[{"atb":[[2.38,1.99],[2.18,7.93]],"id":2441997}],"con":true,"img":false}]}
{"op":"mcm","clk":"5322825709","pt":1646324384019,"mc":[{"id":"1.195532869","rc":[{"atb":[[2.4,3.01]],"id":2441997}],"con":true,"img":false}]}
{"op":"mcm","clk":"5322825724","pt":1646324384226,"mc":[{"id":"1.195532869","rc":[{"atb":[[5.5,2.5]],"id":40302111}],"con":true,"img":false}]}
{"op":"mcm","clk":"5322825733","pt":1646324384330,"mc":[{"id":"1.195532869","rc":[{"atb":[[5.7,1.9]],"id":40302111}],"con":true,"img":false}]}
{"op":"mcm","clk":"5322825747","pt":1646324384440,"mc":[{"id":"1.195532869","rc":[{"atb":[[5.9,3.75]],"id":40302111}],"con":true,"img":false}]}
{"op":"mcm","clk":"5322825801","pt":1646324384914,"mc":[{"id":"1.195532869","rc":[{"atb":[[2.38,0]],"id":2441997}],"con":true,"img":false}]}
{"op":"mcm","clk":"5322825815","pt":1646324385019,"mc":[{"id":"1.195532869","rc":[{"atb":[[1.02,1.99]],"id":2441997}],"con":true,"img":false}]}
{"op":"mcm","clk":"5322825825","pt":1646324385125,"mc":[{"id":"1.195532869","rc":[{"atb":[[2.32,0],[2.4,0],[2.36,0]],"id":2441997}],"con":true,"img":false}]}
{"op":"mcm","clk":"5322825836","pt":1646324385236,"mc":[{"id":"1.195532869","rc":[{"atb":[[5.9,1.76]],"id":40302111}],"con":true,"img":false}]}
{"op":"mcm","clk":"5322825840","pt":1646324385336,"mc":[{"id":"1.195532869","rc":[{"atb":[[5.8,3.64]],"id":40302111}],"con":true,"img":false}]}
{"op":"mcm","clk":"5322825854","pt":1646324385540,"mc":[{"id":"1.195532869","rc":[{"atb":[[2.36,3.15]],"id":2441997}],"con":true,"img":false}]}
{"op":"mcm","clk":"5322825891","pt":1646324386015,"mc":[{"id":"1.195532869","rc":[{"atb":[[1.02,0]],"id":2441997}],"con":true,"img":false}]}
{"op":"mcm","clk":"5322825900","pt":1646324386119,"mc":[{"id":"1.195532869","rc":[{"atb":[[2.38,1.99]],"id":2441997}],"con":true,"img":false}]}
{"op":"mcm","clk":"5322825920","pt":1646324386330,"mc":[{"id":"1.195532869","rc":[{"atb":[[2.4,3.01]],"id":2441997}],"con":true,"img":false}]}
{"op":"mcm","clk":"5322825948","pt":1646324386649,"mc":[{"id":"1.195532869","rc":[{"atb":[[2.38,0]],"id":2441997}],"con":true,"img":false}]}
{"op":"mcm","clk":"5322825960","pt":1646324386700,"mc":[{"id":"1.195532869","rc":[{"atb":[[1.02,1.99]],"id":2441997}],"con":true,"img":false}]}
{"op":"mcm","clk":"5322825969","pt":1646324386805,"mc":[{"id":"1.195532869","rc":[{"atb":[[2.4,0],[2.36,0]],"id":2441997}],"con":true,"img":false}]}
{"op":"mcm","clk":"5322825990","pt":1646324387019,"mc":[{"id":"1.195532869","rc":[{"atb":[[5.6,0]],"id":40302111},{"atb":[[2.42,4.51]],"id":2441997}],"con":true,"img":false}]}
{"op":"mcm","clk":"5322826003","pt":1646324387119,"mc":[{"id":"1.195532869","rc":[{"atb":[[2.44,2.87]],"id":2441997}],"con":true,"img":false}]}
{"op":"mcm","clk":"5322826078","pt":1646324388110,"mc":[{"id":"1.195532869","rc":[{"atl":[[5.8,31.25]],"id":42142047}],"con":true,"img":false}]}
{"op":"mcm","clk":"5322826278","pt":1646324390311,"mc":[{"id":"1.195532869","rc":[{"spn":9.95,"spf":"NaN","id":40302111},{"atb":[[2.18,0]],"id":2441997},{"spn":2.44,"spf":1.0,"id":2441997},{"spn":2.27,"spf":"NaN","id":36909993},{"spn":4.15,"spf":"NaN","id":42142047},{"spn":3.08,"spf":"NaN","id":40133336}],"con":true,"img":false}]}
{"op":"mcm","clk":"5322826302","pt":1646324390524,"mc":[{"id":"1.195532869","rc":[{"atl":[[4.2,87.12]],"id":2441997}],"con":true,"img":false}]}
{"op":"mcm","clk":"5322826429","pt":1646324391912,"mc":[{"id":"1.195532869","rc":[{"atb":[[5.8,1.99]],"id":40302111},{"atb":[[2.34,0]],"id":2441997}],"con":true,"img":false}]}
{"op":"mcm","clk":"5322826437","pt":1646324392026,"mc":[{"id":"1.195532869","rc":[{"atb":[[5.6,10.27]],"id":40302111},{"atb":[[2.42,0]],"id":2441997}],"con":true,"img":false}]}
{"op":"mcm","clk":"5322826444","pt":1646324392119,"mc":[{"id":"1.195532869","rc":[{"atb":[[6,1.65]],"id":40302111},{"atb":[[2.46,1.65]],"id":2441997}],"con":true,"img":false}]}
{"op":"mcm","clk":"5322826455","pt":1646324392221,"mc":[{"id":"1.195532869","rc":[{"atb":[[2.44,0]],"id":2441997}],"con":true,"img":false}]}
{"op":"mcm","clk":"5322826465","pt":1646324392325,"mc":[{"id":"1.195532869","rc":[{"atb":[[6.2,3.21]],"id":40302111},{"atb":[[2.48,2.75],[2.06,15.56]],"id":2441997}],"con":true,"img":false}]}
{"op":"mcm","clk":"5322826486","pt":1646324392590,"mc":[{"id":"1.195532869","rc":[{"atb":[[2.06,2.15]],"id":2441997}],"con":true,"img":false}]}
{"op":"mcm","clk":"5322826519","pt":1646324393265,"mc":[{"id":"1.195532869","rc":[{"atb":[[5.8,0]],"id":40302111}],"con":true,"img":false}]}
{"op":"mcm","clk":"5322826526","pt":1646324393276,"mc":[{"id":"1.195532869","rc":[{"atb":[[1.02,1.99]],"id":40302111}],"con":true,"img":false}]}
{"op":"mcm","clk":"5322826661","pt":1646324394785,"mc":[{"id":"1.195532869","rc":[{"atb":[[2.16,6.6]],"id":2441997}],"con":true,"img":false}]}
{"op":"mcm","clk":"5322826861","pt":1646324397338,"mc":[{"id":"1.195532869","rc":[{"atl":[[6.4,0],[6,50]],"id":42142047}],"con":true,"img":false}]}
{"op":"mcm","clk":"5322826981","pt":1646324399024,"mc":[{"id":"1.195532869","rc":[{"atb":[[5.6,0]],"id":40302111},{"atb":[[2.18,15.12]],"id":2441997},{"atl":[[3.9,38.41]],"id":2441997}],"con":true,"img":false}]}
{"op":"mcm","clk":"5322827015","pt":1646324399501,"mc":[{"id":"1.195532869","rc":[{"atl":[[3.9,34.48]],"id":2441997}],"con":true,"img":false}]}
{"op":"mcm","clk":"5322827088","pt":1646324400396,"mc":[{"id":"1.195532869","rc":[{"atb":[[1.87,0]],"id":40133336}],"con":true,"img":false}]}
{"op":"mcm","clk":"5322827129","pt":1646324400931,"mc":[{"id":"1.195532869","rc":[{"atb":[[6,0]],"id":40302111},{"atb":[[2.46,0]],"id":2441997}],"con":true,"img":false}]}
{"op":"mcm","clk":"5322827151","pt":1646324401145,"mc":[{"id":"1.195532869","rc":[{"atb":[[6.4,1.65],[5.9,0],[6.2,0],[5.7,0]],"id":40302111},{"atb":[[2.5,1.65],[2.48,0]],"id":2441997}],"con":true,"img":false}]}
{"op":"mcm","clk":"5322827172","pt":1646324401306,"mc":[{"id":"1.195532869","rc":[{"atb":[[2.52,2.64]],"id":2441997}],"con":true,"img":false}]}
{"op":"mcm","clk":"5322827183","pt":1646324401414,"mc":[{"id":"1.195532869","rc":[{"atb":[[6.6,2.8]],"id":40302111},{"atb":[[2.16,0]],"id":2441997}],"con":true,"img":false}]}
{"op":"mcm","clk":"5322827195","pt":1646324401517,"mc":[{"id":"1.195532869","rc":[{"atb":[[2.16,3.34]],"id":2441997}],"con":true,"img":false}]}
{"op":"mcm","clk":"5322827252","pt":1646324402094,"mc":[{"id":"1.195532869","rc":[{"atb":[[2.16,0]],"id":2441997}],"con":true,"img":false}]}
{"op":"mcm","clk":"5322827417","pt":1646324403999,"mc":[{"id":"1.195532869","rc":[{"atb":[[5.8,8.02]],"id":40302111}],"con":true,"img":false}]}
{"op":"mcm","clk":"5322827616","pt":1646324406005,"mc":[{"id":"1.195532869","rc":[{"atb":[[2.24,5.8]],"id":2441997}],"con":true,"img":false}]}
{"op":"mcm","clk":"5322827630","pt":1646324406219,"mc":[{"id":"1.195532869","rc":[{"atb":[[2.18,0]],"id":2441997}],"con":true,"img":false}]}
{"op":"mcm","clk":"5322828001","pt":1646324409957,"mc":[{"id":"1.195532869","rc":[{"atb":[[6.4,0]],"id":40302111},{"atb":[[2.5,0]],"id":2441997}],"con":true,"img":false}]}
{"op":"mcm","clk":"5322828023","pt":1646324410164,"mc":[{"id":"1.195532869","rc":[{"atb":[[6.6,0]],"id":40302111},{"atb":[[2.54,1.65],[2.52,0]],"id":2441997}],"con":true,"img":false}]}
{"op":"mcm","clk":"5322828040","pt":1646324410326,"mc":[{"id":"1.195532869","rc":[{"atb":[[6.8,2.62]],"id":40302111},{"atb":[[2.54,4.23]],"id":2441997}],"con":true,"img":false}]}
{"op":"mcm","clk":"5322828049","pt":1646324410432,"mc":[{"id":"1.195532869","rc":[{"atb":[[5.9,1.76]],"id":40302111}],"con":true,"img":false}]}
{"op":"mcm","clk":"5322828059","pt":1646324410535,"mc":[{"id":"1.195532869","rc":[{"atb":[[6.8,0]],"id":40302111}],"con":true,"img":false}]}
{"op":"mcm","clk":"5322828075","pt":1646324410638,"mc":[{"id":"1.195532869","rc":[{"atb":[[5.9,0]],"id":40302111}],"con":true,"img":false}]}
{"op":"mcm","clk":"5322828109","pt":1646324411115,"mc":[{"id":"1.195532869","rc":[{"atb":[[1.02,0]],"id":40302111}],"con":true,"img":false}]}
{"op":"mcm","clk":"5322828115","pt":1646324411233,"mc":[{"id":"1.195532869","rc":[{"atb":[[5.9,3.75]],"id":40302111},{"atb":[[2.26,13.19]],"id":2441997}],"con":true,"img":false}]}
{"op":"mcm","clk":"5322828241","pt":1646324412655,"mc":[{"id":"1.195532869","rc":[{"atb":[[2.24,0]],"id":2441997}],"con":true,"img":false}]}
{"op":"mcm","clk":"5322828320","pt":1646324413442,"mc":[{"id":"1.195532869","rc":[{"atb":[[5.8,0]],"id":40302111}],"con":true,"img":false}]}
{"op":"mcm","clk":"5322828340","pt":1646324413648,"mc":[{"id":"1.195532869","rc":[{"atb":[[5.7,3.36]],"id":40302111}],"con":true,"img":false}]}
{"op":"mcm","clk":"5322828374","pt":1646324413911,"mc":[{"id":"1.195532869","rc":[{"atb":[[5.7,0]],"id":40302111}],"con":true,"img":false}]}
{"op":"mcm","clk":"5322828399","pt":1646324414223,"mc":[{"id":"1.195532869","rc":[{"atb":[[5.9,1.76]],"id":40302111}],"con":true,"img":false}]}
{"op":"mcm","clk":"5322828407","pt":1646324414331,"mc":[{"id":"1.195532869","rc":[{"atb":[[5.6,1.99]],"id":40302111}],"con":true,"img":false}]}
{"op":"mcm","clk":"5322828578","pt":1646324416124,"mc":[{"id":"1.195532869","rc":[{"atb":[[2.18,19.52]],"id":40133336}],"con":true,"img":false}]}
{"op":"mcm","clk":"5322828697","pt":1646324417183,"mc":[{"id":"1.195532869","rc":[{"atb":[[2.6,4.09]],"id":42609835}],"con":true,"img":false}]}
{"op":"mcm","clk":"5322828714","pt":1646324417325,"mc":[{"id":"1.195532869","rc":[{"atb":[[2.56,14.14]],"id":42609835}],"con":true,"img":false}]}
{"op":"mcm","clk":"5322828724","pt":1646324417481,"mc":[{"id":"1.195532869","rc":[{"atb":[[2.28,8.88]],"id":2441997},{"atb":[[2.52,9.12]],"id":42609835}],"con":true,"img":false}]}
{"op":"mcm","clk":"5322828797","pt":1646324418265,"mc":[{"id":"1.195532869","rc":[{"atb":[[2.58,3.5]],"id":42609835}],"con":true,"img":false}]}
{"op":"mcm","clk":"5322828813","pt":1646324418323,"mc":[{"id":"1.195532869","rc":[{"atb":[[2.62,1.99]],"id":42609835}],"con":true,"img":false}]}
{"op":"mcm","clk":"5322828827","pt":1646324418428,"mc":[{"id":"1.195532869","rc":[{"atb":[[5.7,5.62]],"id":40302111}],"con":true,"img":false}]}
{"op":"mcm","clk":"5322828866","pt":1646324418747,"mc":[{"id":"1.195532869","rc":[{"atb":[[2.64,2.33]],"id":42609835}],"con":true,"img":false}]}
{"op":"mcm","clk":"5322828898","pt":1646324419055,"mc":[{"id":"1.195532869","rc":[{"atb":[[2.6,2.44]],"id":42609835}],"con":true,"img":false}]}
{"op":"mcm","clk":"5322828911","pt":1646324419201,"mc":[{"id":"1.195532869","rc":[{"atb":[[6,1.65]],"id":40302111},{"atb":[[2.64,3.98],[2.62,0]],"id":42609835}],"con":true,"img":false}]}
{"op":"mcm","clk":"5322828923","pt":1646324419264,"mc":[{"id":"1.195532869","rc":[{"atb":[[2.66,1.99]],"id":42609835}],"con":true,"img":false}]}
{"op":"mcm","clk":"5322828928","pt":1646324419398,"mc":[{"id":"1.195532869","rc":[{"atb":[[6.2,3.21]],"id":40302111}],"con":true,"img":false}]}
{"op":"mcm","clk":"5322828943","pt":1646324419450,"mc":[{"id":"1.195532869","rc":[{"atb":[[5.6,0]],"id":40302111}],"con":true,"img":false}]}
{"op":"mcm","clk":"5322828954","pt":1646324419556,"mc":[{"id":"1.195532869","rc":[{"atb":[[5.8,1.99]],"id":40302111}],"con":true,"img":false}]}
{"op":"mcm","clk":"5322828988","pt":1646324419763,"mc":[{"id":"1.195532869","rc":[{"atb":[[2.56,11.99],[2.64,6.14]],"id":42609835}],"con":true,"img":false}]}
{"op":"mcm","clk":"5322829025","pt":1646324420131,"mc":[{"id":"1.195532869","rc":[{"atb":[[5.8,0]],"id":40302111}],"con":true,"img":false}]}
{"op":"mcm","clk":"5322829036","pt":1646324420255,"mc":[{"id":"1.195532869","rc":[{"atb":[[1.02,1.99]],"id":40302111}],"con":true,"img":false}]}
{"op":"mcm","clk":"5322829072","pt":1646324420552,"mc":[{"id":"1.195532869","rc":[{"atb":[[2.66,4.28]],"id":42609835}],"con":true,"img":false}]}
{"op":"mcm","clk":"5322829088","pt":1646324420763,"mc":[{"id":"1.195532869","rc":[{"atb":[[2.56,0]],"id":42609835}],"con":true,"img":false}]}
{"op":"mcm","clk":"5322829101","pt":1646324420878,"mc":[{"id":"1.195532869","rc":[{"atb":[[2.26,0]],"id":2441997},{"atb":[[2.52,0]],"id":42609835}],"con":true,"img":false}]}
{"op":"mcm","clk":"5322829162","pt":1646324421340,"mc":[{"id":"1.195532869","rc":[{"atl":[[2.82,9.96]],"id":36909993}],"con":true,"img":false}]}
{"op":"mcm","clk":"5322829173","pt":1646324421453,"mc":[{"id":"1.195532869","rc":[{"atl":[[2.84,85.14]],"id":36909993}],"con":true,"img":false}]}
{"op":"mcm","clk":"5322829186","pt":1646324421552,"mc":[{"id":"1.195532869","rc":[{"atl":[[2.82,0],[2.86,53.76]],"id":36909993}],"con":true,"img":false}]}
{"op":"mcm","clk":"5322829208","pt":1646324421759,"mc":[{"id":"1.195532869","rc":[{"atb":[[2.66,1.99],[2.64,3.81]],"id":42609835}],"con":true,"img":false}]}
{"op":"mcm","clk":"5322829380","pt":1646324423641,"mc":[{"id":"1.195532869","rc":[{"atl":[[5.3,0]],"id":42142047}],"con":true,"img":false}]}
{"op":"mcm","clk":"5322829400","pt":1646324423855,"mc":[{"id":"1.195532869","rc":[{"atl":[[5.6,117.28],[5.4,19.89]],"id":42142047}],"con":true,"img":false}]}
{"op":"mcm","clk":"5322829412","pt":1646324423958,"mc":[{"id":"1.195532869","rc":[{"atb":[[2.28,0]],"id":2441997}],"con":true,"img":false}]}
{"op":"mcm","clk":"5322829425","pt":1646324424061,"mc":[{"id":"1.195532869","rc":[{"atl":[[5.4,15.09]],"id":42142047}],"con":true,"img":false}]}
{"op":"mcm","clk":"5322829465","pt":1646324424431,"mc":[{"id":"1.195532869","rc":[{"atl":[[5.1,3]],"id":42142047}],"con":true,"img":false}]}
{"op":"mcm","clk":"5322829473","pt":1646324424534,"mc":[{"id":"1.195532869","rc":[{"atl":[[5.6,95.54],[5,18.37],[5.4,37.82]],"id":42142047}],"con":true,"img":false}]}
{"op":"mcm","clk":"5322829496","pt":1646324424744,"mc":[{"id":"1.195532869","rc":[{"atl":[[5.2,4]],"id":42142047}],"con":true,"img":false}]}
{"op":"mcm","clk":"5322829507","pt":1646324424847,"mc":[{"id":"1.195532869","rc":[{"atb":[[3.15,20.83]],"id":42142047},{"atl":[[5.2,13.52],[5.4,28.73]],"id":42142047}],"con":true,"img":false}]}
{"op":"mcm","clk":"5322829519","pt":1646324424951,"mc":[{"id":"1.195532869","rc":[{"atb":[[3,98.51],[3.05,3.34]],"id":42142047}],"con":true,"img":false}]}
{"op":"mcm","clk":"5322829530","pt":1646324425055,"mc":[{"id":"1.195532869","rc":[{"atb":[[3.1,0],[2.98,0]],"id":42142047}],"con":true,"img":false}]}
{"op":"mcm","clk":"5322829542","pt":1646324425161,"mc":[{"id":"1.195532869","rc":[{"atb":[[5.7,0]],"id":40302111},{"atb":[[3.05,0],[3.2,1.99]],"id":42142047}],"con":true,"img":false}]}
{"op":"mcm","clk":"5322829686","pt":1646324427167,"mc":[{"id":"1.195532869","rc":[{"atl":[[2.86,199.12],[2.84,21.74]],"id":36909993}],"con":true,"img":false}]}
{"op":"mcm","clk":"5322829764","pt":1646324428063,"mc":[{"id":"1.195532869","rc":[{"atb":[[6,0]],"id":40302111},{"atb":[[2.64,2.15]],"id":42609835}],"con":true,"img":false}]}
{"op":"mcm","clk":"5322829772","pt":1646324428166,"mc":[{"id":"1.195532869","rc":[{"atb":[[2.68,1.65]],"id":42609835}],"con":true,"img":false}]}
{"op":"mcm","clk":"5322829776","pt":1646324428272,"mc":[{"id":"1.195532869","rc":[{"atb":[[5.9,0],[6.2,0]],"id":40302111},{"atb":[[3,74.88]],"id":42142047},{"atl":[[5.4,6],[5.5,22.22]],"id":42142047}],"con":true,"img":false}]}
{"op":"mcm","clk":"5322829785","pt":1646324428327,"mc":[{"id":"1.195532869","rc":[{"atb":[[2.16,27.52]],"id":2441997},{"atb":[[2.66,10.69]],"id":42609835}],"con":true,"img":false}]}
{"op":"mcm","clk":"5322829794","pt":1646324428429,"mc":[{"id":"1.195532869","rc":[{"atb":[[2.16,38.96]],"id":2441997}],"con":true,"img":false}]}
{"op":"mcm","clk":"5322829801","pt":1646324428596,"mc":[{"id":"1.195532869","rc":[{"atb":[[1.02,0]],"id":40302111}],"con":true,"img":false}]}
{"op":"mcm","clk":"5322829805","pt":1646324428638,"mc":[{"id":"1.195532869","rc":[{"atb":[[5.6,1.99]],"id":40302111}],"con":true,"img":false}]}
{"op":"mcm","clk":"5322829815","pt":1646324428744,"mc":[{"id":"1.195532869","rc":[{"atb":[[5.6,3.97]],"id":40302111}],"con":true,"img":false}]}
{"op":"mcm","clk":"5322829976","pt":1646324430634,"mc":[{"id":"1.195532869","rc":[{"atb":[[3,35.02],[2.92,43.86]],"id":42142047}],"con":true,"img":false}]}
{"op":"mcm","clk":"5322830184","pt":1646324433433,"mc":[{"id":"1.195532869","rc":[{"atl":[[5.4,28.73]],"id":42142047}],"con":true,"img":false}]}
{"op":"mcm","clk":"5322830220","pt":1646324433852,"mc":[{"id":"1.195532869","rc":[{"atb":[[5.7,5.95]],"id":40302111},{"atb":[[3.05,23.05]],"id":42142047}],"con":true,"img":false}]}
{"op":"mcm","clk":"5322830240","pt":1646324434063,"mc":[{"id":"1.195532869","rc":[{"atb":[[5.8,1.83]],"id":40302111}],"con":true,"img":false}]}
{"op":"mcm","clk":"5322830284","pt":1646324434640,"mc":[{"id":"1.195532869","rc":[{"atb":[[5.6,1.98]],"id":40302111}],"con":true,"img":false}]}
{"op":"mcm","clk":"5322830291","pt":1646324434744,"mc":[{"id":"1.195532869","rc":[{"atb":[[5.8,3.82]],"id":40302111}],"con":true,"img":false}]}
{"op":"mcm","clk":"5322830413","pt":1646324436150,"mc":[{"id":"1.195532869","rc":[{"atl":[[5.6,21.74],[5.2,94.69]],"id":42142047}],"con":true,"img":false}]}
{"op":"mcm","clk":"5322830466","pt":1646324436779,"mc":[{"id":"1.195532869","rc":[{"atl":[[6,0]],"id":42142047}],"con":true,"img":false}]}
{"op":"mcm","clk":"5322830483","pt":1646324436939,"mc":[{"id":"1.195532869","rc":[{"atb":[[5.9,1.65]],"id":40302111}],"con":true,"img":false}]}
{"op":"mcm","clk":"5322830488","pt":1646324437041,"mc":[{"id":"1.195532869","rc":[{"atb":[[6,1.7]],"id":40302111}],"con":true,"img":false}]}
{"op":"mcm","clk":"5322830506","pt":1646324437250,"mc":[{"id":"1.195532869","rc":[{"atb":[[3,92.37],[2.92,4]],"id":42142047}],"con":true,"img":false}]}
{"op":"mcm","clk":"5322830513","pt":1646324437356,"mc":[{"id":"1.195532869","rc":[{"atb":[[5.8,1.83]],"id":40302111}],"con":true,"img":false}]}
{"op":"mcm","clk":"5322830528","pt":1646324437463,"mc":[{"id":"1.195532869","rc":[{"atb":[[6,3.69]],"id":40302111}],"con":true,"img":false}]}
{"op":"mcm","clk":"5322830621","pt":1646324438363,"mc":[{"id":"1.195532869","rc":[{"atb":[[5.7,0]],"id":40302111}],"con":true,"img":false}]}
{"op":"mcm","clk":"5322830633","pt":1646324438470,"mc":[{"id":"1.195532869","rc":[{"atl":[[5.5,0],[5.4,51.46]],"id":42142047}],"con":true,"img":false}]}
{"op":"mcm","clk":"5322830693","pt":1646324439155,"mc":[{"id":"1.195532869","rc":[{"atb":[[6,1.7]],"id":40302111}],"con":true,"img":false}]}
{"op":"mcm","clk":"5322830701","pt":1646324439264,"mc":[{"id":"1.195532869","rc":[{"atb":[[5.9,3.64]],"id":40302111}],"con":true,"img":false}]}
{"op":"mcm","clk":"5322830860","pt":1646324441263,"mc":[{"id":"1.195532869","rc":[{"atb":[[2.44,3.34]],"id":42609835}],"con":true,"img":false}]}
{"op":"mcm","clk":"5322830906","pt":1646324441790,"mc":[{"id":"1.195532869","rc":[{"atb":[[2.44,0]],"id":42609835}],"con":true,"img":false}]}
{"op":"mcm","clk":"5322830919","pt":1646324441894,"mc":[{"id":"1.195532869","rc":[{"atl":[[5.6,32.61]],"id":42142047}],"con":true,"img":false}]}
{"op":"mcm","clk":"5322831019","pt":1646324443060,"mc":[{"id":"1.195532869","rc":[{"atb":[[5.7,10.05]],"id":40302111}],"con":true,"img":false}]}
{"op":"mcm","clk":"5322831256","pt":1646324445983,"mc":[{"id":"1.195532869","rc":[{"atb":[[5.9,1.99]],"id":40302111}],"con":true,"img":false}]}
{"op":"mcm","clk":"5322831333","pt":1646324446391,"mc":[{"id":"1.195532869","rc":[{"atb":[[5.9,0]],"id":40302111}],"con":true,"img":false}]}
{"op":"mcm","clk":"5322831340","pt":1646324446495,"mc":[{"id":"1.195532869","rc":[{"atb":[[5.8,3.82]],"id":40302111}],"con":true,"img":false}]}
{"op":"mcm","clk":"5322831352","pt":1646324446660,"mc":[{"id":"1.195532869","rc":[{"atb":[[5.8,1.99],[5.6,0],[6,0]],"id":40302111}],"con":true,"img":false}]}
{"op":"mcm","clk":"5322831412","pt":1646324447495,"mc":[{"id":"1.195532869","rc":[{"atb":[[5.9,1.76]],"id":40302111}],"con":true,"img":false}]}
{"op":"mcm","clk":"5322831438","pt":1646324447866,"mc":[{"id":"1.195532869","rc":[{"atb":[[2.6,19.86],[2.68,3.9]],"id":42609835}],"con":true,"img":false}]}
{"op":"mcm","clk":"5322831443","pt":1646324447971,"mc":[{"id":"1.195532869","rc":[{"atb":[[1.7,6.01]],"id":36909993},{"atb":[[3.05,39.93]],"id":42142047}],"con":true,"img":false}]}
{"op":"mcm","clk":"5322831453","pt":1646324448077,"mc":[{"id":"1.195532869","rc":[{"atb":[[2.6,2.44]],"id":42609835}],"con":true,"img":false}]}
{"op":"mcm","clk":"5322831461","pt":1646324448180,"mc":[{"id":"1.195532869","rc":[{"atl":[[5.1,0]],"id":42142047}],"con":true,"img":false}]}
{"op":"mcm","clk":"5322831467","pt":1646324448291,"mc":[{"id":"1.195532869","rc":[{"atb":[[1.7,0]],"id":36909993},{"atl":[[5,0],[5.2,13.52],[5.4,131.24]],"id":42142047}],"con":true,"img":false}]}
{"op":"mcm","clk":"5322831478","pt":1646324448397,"mc":[{"id":"1.195532869","rc":[{"atl":[[5.1,19.51]],"id":42142047}],"con":true,"img":false}]}
{"op":"mcm","clk":"5322831487","pt":1646324448501,"mc":[{"id":"1.195532869","rc":[{"atl":[[5.6,58.79],[5.1,9.18],[5,4],[5.4,108.51]],"id":42142047}],"con":true,"img":false}]}
{"op":"mcm","clk":"5322831495","pt":1646324448555,"mc":[{"id":"1.195532869","rc":[{"atl":[[5.6,37.05],[5.1,28.69],[5.4,131.24]],"id":42142047}],"con":true,"img":false}]}
{"op":"mcm","clk":"5322831516","pt":1646324448871,"mc":[{"id":"1.195532869","rc":[{"atb":[[3,96.59],[3.05,23.05]],"id":42142047},{"atl":[[5.6,32.61],[5.1,19.51],[5,0]],"id":42142047}],"con":true,"img":false}]}
{"op":"mcm","clk":"5322831542","pt":1646324449209,"mc":[{"id":"1.195532869","rc":[{"atl":[[4.8,3],[5.3,9.3],[5.2,4]],"id":42142047}],"con":true,"img":false}]}
{"op":"mcm","clk":"5322831549","pt":1646324449289,"mc":[{"id":"1.195532869","rc":[{"atb":[[2.66,8.7]],"id":42609835}],"con":true,"img":false}]}
{"op":"mcm","clk":"5322831561","pt":1646324449404,"mc":[{"id":"1.195532869","rc":[{"atb":[[3,92.37]],"id":42142047},{"atb":[[2.7,1.99]],"id":42609835}],"con":true,"img":false}]}
{"op":"mcm","clk":"5322831572","pt":1646324449603,"mc":[{"id":"1.195532869","rc":[{"atl":[[4.5,2.5]],"id":2441997},{"atb":[[2.7,4.2]],"id":42609835}],"con":true,"img":false}]}
{"op":"mcm","clk":"5322831591","pt":1646324449871,"mc":[{"id":"1.195532869","rc":[{"atb":[[3.15,0]],"id":42142047},{"atl":[[5,10]],"id":42142047}],"con":true,"img":false}]}
{"op":"mcm","clk":"5322831598","pt":1646324449972,"mc":[{"id":"1.195532869","rc":[{"atb":[[5.7,0]],"id":40302111},{"atb":[[3.05,32.8],[2.92,40.89]],"id":42142047},{"atl":[[5.3,0]],"id":42142047}],"con":true,"img":false}]}
{"op":"mcm","clk":"5322831606","pt":1646324450078,"mc":[{"id":"1.195532869","rc":[{"atb":[[3,35.02]],"id":42142047},{"atl":[[5.4,51.46]],"id":42142047}],"con":true,"img":false}]}
{"op":"mcm","clk":"5322831625","pt":1646324450294,"mc":[{"id":"1.195532869","rc":[{"atb":[[3.2,0]],"id":42142047}],"con":true,"img":false}]}
{"op":"mcm","clk":"5322831640","pt":1646324450400,"mc":[{"id":"1.195532869","rc":[{"atb":[[5.6,3.68]],"id":40302111},{"spn":2.54,"spf":1.0,"id":2441997},{"atb":[[3.1,1.99]],"id":42142047},{"spn":3.95,"spf":"NaN","id":42142047},{"spn":2.68,"spf":1.0,"id":42609835}],"con":true,"img":false}]}
{"op":"mcm","clk":"5322831662","pt":1646324450562,"mc":[{"id":"1.195532869","rc":[{"atb":[[5.8,0]],"id":40302111}],"con":true,"img":false}]}
{"op":"mcm","clk":"5322831671","pt":1646324450666,"mc":[{"id":"1.195532869","rc":[{"atb":[[5.6,5.67]],"id":40302111}],"con":true,"img":false}]}
{"op":"mcm","clk":"5322831688","pt":1646324450887,"mc":[{"id":"1.195532869","rc":[{"atb":[[5.6,1.99]],"id":40302111}],"con":true,"img":false}]}
{"op":"mcm","clk":"5322831739","pt":1646324451467,"mc":[{"id":"1.195532869","rc":[{"atl":[[2.82,13.89]],"id":36909993}],"con":true,"img":false}]}
{"op":"mcm","clk":"5322831746","pt":1646324451568,"mc":[{"id":"1.195532869","rc":[{"atl":[[2.8,66.18],[2.86,0],[2.84,93]],"id":36909993}],"con":true,"img":false}]}
{"op":"mcm","clk":"5322831758","pt":1646324451775,"mc":[{"id":"1.195532869","rc":[{"atl":[[2.8,44.44],[2.84,147.35]],"id":36909993}],"con":true,"img":false}]}
{"op":"mcm","clk":"5322831766","pt":1646324451882,"mc":[{"id":"1.195532869","rc":[{"atl":[[2.82,0]],"id":36909993}],"con":true,"img":false}]}
{"op":"mcm","clk":"5322831774","pt":1646324451989,"mc":[{"id":"1.195532869","rc":[{"atl":[[2.86,9.84]],"id":36909993}],"con":true,"img":false}]}
{"op":"mcm","clk":"5322831798","pt":1646324452301,"mc":[{"id":"1.195532869","rc":[{"atb":[[2.66,0]],"id":42609835}],"con":true,"img":false}]}
{"op":"mcm","clk":"5322831809","pt":1646324452408,"mc":[{"id":"1.195532869","rc":[{"atl":[[2.86,7.95]],"id":36909993}],"con":true,"img":false}]}
{"op":"mcm","clk":"5322831860","pt":1646324452984,"mc":[{"id":"1.195532869","rc":[{"atl":[[2.86,5.57]],"id":36909993}],"con":true,"img":false}]}
{"op":"mcm","clk":"5322831895","pt":1646324453509,"mc":[{"id":"1.195532869","rc":[{"atl":[[2.86,0]],"id":36909993}],"con":true,"img":false}]}
{"op":"mcm","clk":"5322832017","pt":1646324454979,"mc":[{"id":"1.195532869","rc":[{"atb":[[2.68,2.25]],"id":42609835}],"con":true,"img":false}]}
{"op":"mcm","clk":"5322832024","pt":1646324455082,"mc":[{"id":"1.195532869","rc":[{"atb":[[5.7,5.62]],"id":40302111}],"con":true,"img":false}]}
{"op":"mcm","clk":"5322832030","pt":1646324455189,"mc":[{"id":"1.195532869","rc":[{"atb":[[6,1.65]],"id":40302111}],"con":true,"img":false}]}
{"op":"mcm","clk":"5322832037","pt":1646324455293,"mc":[{"id":"1.195532869","rc":[{"atb":[[6.2,3.21]],"id":40302111}],"con":true,"img":false}]}
{"op":"mcm","clk":"5322832054","pt":1646324455505,"mc":[{"id":"1.195532869","rc":[{"atb":[[5.6,0]],"id":40302111}],"con":true,"img":false}]}
{"op":"mcm","clk":"5322832062","pt":1646324455609,"mc":[{"id":"1.195532869","rc":[{"atb":[[6,3.64]],"id":40302111}],"con":true,"img":false}]}
{"op":"mcm","clk":"5322832071","pt":1646324455714,"mc":[{"id":"1.195532869","rc":[{"atl":[[4.8,0]],"id":42142047}],"con":true,"img":false}]}
{"op":"mcm","clk":"5322832102","pt":1646324456085,"mc":[{"id":"1.195532869","rc":[{"atb":[[6,1.65]],"id":40302111}],"con":true,"img":false}]}
{"op":"mcm","clk":"5322832107","pt":1646324456204,"mc":[{"id":"1.195532869","rc":[{"atb":[[1.02,1.99]],"id":40302111}],"con":true,"img":false}]}
{"op":"mcm","clk":"5322832138","pt":1646324456610,"mc":[{"id":"1.195532869","rc":[{"atl":[[5.2,13.52]],"id":42142047}],"con":true,"img":false}]}
{"op":"mcm","clk":"5322832145","pt":1646324456715,"mc":[{"id":"1.195532869","rc":[{"atl":[[5,0]],"id":42142047}],"con":true,"img":false}]}
{"op":"mcm","clk":"5322832164","pt":1646324456881,"mc":[{"id":"1.195532869","rc":[{"atl":[[2.88,106.38]],"id":36909993}],"con":true,"img":false}]}
{"op":"mcm","clk":"5322832173","pt":1646324456977,"mc":[{"id":"1.195532869","rc":[{"atl":[[2.88,258.13],[2.84,21.74]],"id":36909993}],"con":true,"img":false}]}
{"op":"mcm","clk":"5322832234","pt":1646324457789,"mc":[{"id":"1.195532869","rc":[{"atb":[[2.62,11.54]],"id":42609835}],"con":true,"img":false}]}
{"op":"mcm","clk":"5322832403","pt":1646324459986,"mc":[{"id":"1.195532869","rc":[{"atl":[[5.3,9.3],[5.2,4]],"id":42142047}],"con":true,"img":false}]}
{"op":"mcm","clk":"5322832414","pt":1646324460089,"mc":[{"id":"1.195532869","rc":[{"atl":[[5.4,132.79]],"id":42142047}],"con":true,"img":false}]}
{"op":"mcm","clk":"5322832422","pt":1646324460194,"mc":[{"id":"1.195532869","rc":[{"atb":[[5.7,0]],"id":40302111}],"con":true,"img":false}]}
{"op":"mcm","clk":"5322832570","pt":1646324461792,"mc":[{"id":"1.195532869","rc":[{"atb":[[3.1,23.6]],"id":42142047}],"con":true,"img":false}]}
{"op":"mcm","clk":"5322832589","pt":1646324461997,"mc":[{"id":"1.195532869","rc":[{"atb":[[3,88.91],[3.05,23.05],[2.92,4]],"id":42142047}],"con":true,"img":false}]}
{"op":"mcm","clk":"5322832729","pt":1646324463431,"mc":[{"id":"1.195532869","rc":[{"atb":[[3,53.89],[2.98,47.2]],"id":42142047}],"con":true,"img":false}]}
{"op":"mcm","clk":"5322832797","pt":1646324464013,"mc":[{"id":"1.195532869","rc":[{"atb":[[6,0]],"id":40302111}],"con":true,"img":false}]}
{"op":"mcm","clk":"5322832820","pt":1646324464223,"mc":[{"id":"1.195532869","rc":[{"atb":[[5.9,0],[6.2,0]],"id":40302111}],"con":true,"img":false}]}
{"op":"mcm","clk":"5322832879","pt":1646324464800,"mc":[{"id":"1.195532869","rc":[{"atb":[[5.6,1.98]],"id":40302111}],"con":true,"img":false}]}
{"op":"mcm","clk":"5322833013","pt":1646324466096,"mc":[{"id":"1.195532869","rc":[{"atb":[[1.02,0]],"id":40302111}],"con":true,"img":false}]}
{"op":"mcm","clk":"5322833021","pt":1646324466200,"mc":[{"id":"1.195532869","rc":[{"atb":[[5.6,3.97]],"id":40302111}],"con":true,"img":false}]}
{"op":"mcm","clk":"5322833115","pt":1646324467204,"mc":[{"id":"1.195532869","rc":[{"atb":[[5.2,6.25]],"id":40302111}],"con":true,"img":false}]}
{"op":"mcm","clk":"5322833177","pt":1646324468002,"mc":[{"id":"1.195532869","rc":[{"atl":[[5.5,22.22]],"id":42142047}],"con":true,"img":false}]}
{"op":"mcm","clk":"5322833231","pt":1646324468664,"mc":[{"id":"1.195532869","rc":[{"atb":[[2.12,89.29],[2.28,0]],"id":40302111},{"atb":[[1.92,0],[1.97,46.51]],"id":2441997},{"atl":[[5.6,0],[5.8,0],[5.4,110.06]],"id":42142047},{"atb":[[2.64,10.53]],"id":42609835},{"atb":[[2.1,14.17],[2.02,13.52]],"id":40133336}],"con":true,"img":false}]}
{"op":"mcm","clk":"5322833243","pt":1646324468741,"mc":[{"id":"1.195532869","rc":[{"atb":[[3,101.09],[2.98,0]],"id":42142047}],"con":true,"img":false}]}
{"op":"mcm","clk":"5322833269","pt":1646324469010,"mc":[{"id":"1.195532869","rc":[{"atl":[[4.8,14.83]],"id":42142047},{"atb":[[2.02,0]],"id":40133336}],"con":true,"img":false}]}
{"op":"mcm","clk":"5322833277","pt":1646324469118,"mc":[{"id":"1.195532869","rc":[{"atl":[[4.7,20.74]],"id":42142047}],"con":true,"img":false}]}
{"op":"mcm","clk":"5322833287","pt":1646324469220,"mc":[{"id":"1.195532869","rc":[{"atl":[[5,10]],"id":42142047}],"con":true,"img":false}]}
{"op":"mcm","clk":"5322833295","pt":1646324469330,"mc":[{"id":"1.195532869","rc":[{"atl":[[5.4,28.73],[5.1,0]],"id":42142047}],"con":true,"img":false}]}
{"op":"mcm","clk":"5322833325","pt":1646324469642,"mc":[{"id":"1.195532869","rc":[{"atl":[[4.9,10.26]],"id":42142047}],"con":true,"img":false}]}
{"op":"mcm","clk":"5322833358","pt":1646324469914,"mc":[{"id":"1.195532869","rc":[{"atl":[[4.8,0]],"id":42142047}],"con":true,"img":false}]}
{"op":"mcm","clk":"5322833381","pt":1646324470127,"mc":[{"id":"1.195532869","rc":[{"atl":[[5.3,14.65],[4.7,0]],"id":42142047}],"con":true,"img":false}]}
{"op":"mcm","clk":"5322833393","pt":1646324470231,"mc":[{"id":"1.195532869","rc":[{"atl":[[4.9,30.77],[4.7,3.75]],"id":42142047}],"con":true,"img":false}]}
