{"op":"mcm","clk":"5305619427","pt":1646080581431,"mc":[{"id":"1.195395430","marketDefinition":{"bspMarket":true,"turnInPlayEnabled":false,"persistenceEnabled":false,"marketBaseRate":7.0,"eventId":"31270458","eventTypeId":"4339","numberOfWinners":3,"bettingType":"ODDS","marketType":"PLACE","marketTime":"2022-03-01T03:42:00.000Z","suspendTime":"2022-03-01T03:42:00.000Z","bspReconciled":false,"complete":true,"inPlay":false,"crossMatching":false,"runnersVoidable":false,"numberOfActiveRunners":8,"betDelay":0,"status":"OPEN","runners":[{"status":"ACTIVE","sortPriority":1,"id":40494181,"name":"1. Loch And Loaded"},{"status":"ACTIVE","sortPriority":2,"id":38206580,"name":"2. Buckle Up Wilder"},{"status":"ACTIVE","sortPriority":3,"id":38206560,"name":"3. Hiccup Amisha"},{"status":"ACTIVE","sortPriority":4,"id":36104895,"name":"4. Langley Roo"},{"status":"ACTIVE","sortPriority":5,"id":39520250,"name":"5. Rip On Bye"},{"status":"ACTIVE","sortPriority":6,"id":41762283,"name":"6. Gracies Joy"},{"status":"ACTIVE","sortPriority":7,"id":37265273,"name":"7. Just Mercy"},{"status":"ACTIVE","sortPriority":8,"id":27701417,"name":"8. Jalla General"}],"regulators":["MR_INT"],"venue":"Devonport","countryCode":"AU","discountAllowed":true,"timezone":"Australia/Sydney","openDate":"2022-03-01T02:00:00.000Z","version":4380714804,"name":"To Be Placed","eventName":"Devonport (AUS) 1st Mar"},"rc":[],"con":true,"img":false}]}
{"op":"mcm","clk":"5305743101","pt":1646082026907,"mc":[{"id":"1.195395430","rc":[{"atb":[[3.45,24.65],[3.2,54.91],[2.98,61.02]],"id":39520250},{"atl":[[18.5,1.37],[44,1.12],[13.5,0.96],[27,0.92],[9.4,1.42]],"id":39520250},{"spn":6.42,"spf":"NaN","id":39520250},{"atb":[[1.6,201.36],[1.7,86.29],[1.65,185.87]],"id":37265273},{"atl":[[3.2,5.46],[3.7,4.44],[6.8,8.28],[4.4,7.06],[5.4,5.46]],"id":37265273},{"spn":2.45,"spf":"NaN","id":37265273},{"atb":[[2.4,86.29],[2.5,80.54],[2.6,37.75]],"id":36104895},{"atl":[[6.2,2.31],[10.5,2.52],[21,2.4],[8.2,1.66],[15.5,1.65]],"id":36104895},{"spn":4.4,"spf":"NaN","id":36104895},{"atb":[[1.45,268.48],[1.55,109.83],[1.5,241.63]],"id":38206580},{"atl":[[2.82,6.6],[5.1,11.72],[4.1,7.75],[3.55,9.42],[3.05,5.86]],"id":38206580},{"spn":2.18,"spf":"NaN","id":38206580},{"atb":[[3.6,46.47],[3.85,21.19],[3.35,51.41]],"id":27701417},{"atl":[[17.5,0.73],[75,0.64],[40,0.61],[12.5,1.04],[25,1]],"id":27701417},{"spn":8.17,"spf":"NaN","id":27701417},{"atb":[[2,120.81],[2.2,50.34],[2.1,109.83]],"id":38206560},{"atl":[[17.5,2.91],[9,3],[5.5,2.66],[12.5,2.08],[7,2]],"id":38206560},{"spn":3.85,"spf":"NaN","id":38206560},{"atb":[[1.6,100.68],[1.55,219.67],[1.5,241.63]],"id":41762283},{"atl":[[2.88,6.39],[3.2,5.46],[3.7,8.89],[4.4,7.06],[5.4,10.92]],"id":41762283},{"spn":2.24,"spf":"NaN","id":41762283},{"atb":[[1.01,30204.61]],"id":40494181},{"atl":[[2.36,17.67],[2.56,15.4],[1.98,12.26],[2.16,10.36],[2.76,27.3]],"id":40494181},{"spn":1.49,"spf":"NaN","id":40494181}],"con":true,"img":false}]}
{"op":"mcm","clk":"5305747397","pt":1646082083779,"mc":[{"id":"1.195395430","rc":[{"atb":[[3.45,0],[3.2,0],[2.98,0]],"id":39520250},{"atl":[[18.5,0],[44,0],[13.5,0],[27,0],[9.4,0]],"id":39520250},{"atb":[[1.6,0],[1.7,0],[1.65,0]],"id":37265273},{"atl":[[3.2,0],[3.7,0],[6.8,0],[4.4,0],[5.4,0]],"id":37265273},{"atb":[[2.4,0],[2.5,0],[2.6,0]],"id":36104895},{"atl":[[6.2,0],[10.5,0],[21,0],[8.2,0],[15.5,0]],"id":36104895},{"atb":[[1.45,0],[1.55,0],[1.5,0]],"id":38206580},{"atl":[[2.82,0],[5.1,0],[4.1,0],[3.55,0],[3.05,0]],"id":38206580},{"atb":[[3.6,0],[3.85,0],[3.35,0]],"id":27701417},{"atl":[[17.5,0],[75,0],[40,0],[12.5,0],[25,0]],"id":27701417},{"atb":[[2,0],[2.2,0],[2.1,0]],"id":38206560},{"atl":[[17.5,0],[9,0],[5.5,0],[12.5,0],[7,0]],"id":38206560},{"atb":[[1.6,0],[1.55,0],[1.5,0]],"id":41762283},{"atl":[[2.88,0],[3.2,0],[3.7,0],[4.4,0],[5.4,0]],"id":41762283},{"atb":[[1.01,0]],"id":40494181},{"atl":[[2.36,0],[2.56,0],[1.98,0],[2.16,0],[2.76,0]],"id":40494181}],"con":true,"img":false}]}
{"op":"mcm","clk":"5305747684","pt":1646082087094,"mc":[{"id":"1.195395430","rc":[{"atb":[[3.45,24.65],[3.2,54.91],[2.98,61.02]],"id":39520250},{"atl":[[18.5,1.37],[44,1.12],[13.5,0.96],[27,0.92],[9.4,1.42]],"id":39520250},{"atb":[[1.6,201.36],[1.7,86.29],[1.65,185.87]],"id":37265273},{"atl":[[3.2,5.46],[3.7,4.44],[6.8,8.28],[4.4,7.06],[5.4,5.46]],"id":37265273},{"atb":[[2.4,86.29],[2.5,80.54],[2.6,37.75]],"id":36104895},{"atl":[[6.2,2.31],[10.5,2.52],[21,2.4],[8.2,1.66],[15.5,1.65]],"id":36104895},{"atb":[[1.45,268.48],[1.55,109.83],[1.5,241.63]],"id":38206580},{"atl":[[2.82,6.6],[5.1,11.72],[4.1,7.75],[3.55,9.42],[3.05,5.86]],"id":38206580},{"atb":[[3.6,46.47],[3.85,21.19],[3.35,51.41]],"id":27701417},{"atl":[[17.5,0.73],[75,0.64],[40,0.61],[12.5,1.04],[25,1]],"id":27701417},{"atb":[[2,120.81],[2.2,50.34],[2.1,109.83]],"id":38206560},{"atl":[[17.5,2.91],[9,3],[5.5,2.66],[12.5,2.08],[7,2]],"id":38206560},{"atb":[[1.6,100.68],[1.55,219.67],[1.5,241.63]],"id":41762283},{"atl":[[2.88,6.39],[3.2,5.46],[3.7,8.89],[4.4,7.06],[5.4,10.92]],"id":41762283},{"atb":[[1.01,30204.61]],"id":40494181},{"atl":[[2.36,17.67],[2.56,15.4],[1.98,12.26],[2.16,10.36],[2.76,27.3]],"id":40494181}],"con":true,"img":false}]}
{"op":"mcm","clk":"5305990512","pt":1646086602699,"mc":[{"id":"1.195395430","marketDefinition":{"bspMarket":true,"turnInPlayEnabled":false,"persistenceEnabled":false,"marketBaseRate":7.0,"eventId":"31270458","eventTypeId":"4339","numberOfWinners":3,"bettingType":"ODDS","marketType":"PLACE","marketTime":"2022-03-01T03:42:00.000Z","suspendTime":"2022-03-01T03:42:00.000Z","bspReconciled":false,"complete":true,"inPlay":false,"crossMatching":false,"runnersVoidable":false,"numberOfActiveRunners":8,"betDelay":0,"status":"OPEN","runners":[{"status":"ACTIVE","sortPriority":1,"id":40494181,"name":"1. Loch And Loaded"},{"status":"ACTIVE","sortPriority":2,"id":38206580,"name":"2. Buckle Up Wilder"},{"status":"ACTIVE","sortPriority":3,"id":38206560,"name":"3. Hiccup Amisha"},{"status":"ACTIVE","sortPriority":4,"id":36104895,"name":"4. Langley Roo"},{"status":"ACTIVE","sortPriority":5,"id":39520250,"name":"5. Rip On Bye"},{"status":"ACTIVE","sortPriority":6,"id":41762283,"name":"6. Gracies Joy"},{"status":"ACTIVE","sortPriority":7,"id":37265273,"name":"7. Just Mercy"},{"status":"ACTIVE","sortPriority":8,"id":27701417,"name":"8. Jalla General"}],"regulators":["MR_INT"],"venue":"Devonport","countryCode":"AU","discountAllowed":true,"timezone":"Australia/Sydney","openDate":"2022-03-01T02:00:00.000Z","version":4380714804,"name":"To Be Placed","eventName":"Devonport (AUS) 1st Mar"},"rc":[{"atb":[[3.45,24.65],[3.2,54.9],[2.98,61.01]],"id":39520250},{"atl":[[18.5,1.37],[44,1.12],[13.5,0.96],[27,0.92],[9.4,1.42]],"id":39520250},{"spn":6.42,"spf":"NaN","id":39520250},{"atb":[[1.6,201.33],[1.7,86.28],[1.65,185.84]],"id":37265273},{"atl":[[3.2,5.46],[3.7,4.44],[6.8,8.28],[4.4,7.06],[5.4,5.46]],"id":37265273},{"spn":2.45,"spf":"NaN","id":37265273},{"atb":[[2.4,86.28],[2.5,80.53],[2.6,37.74]],"id":36104895},{"atl":[[6.2,2.31],[10.5,2.52],[21,2.4],[8.2,1.66],[15.5,1.65]],"id":36104895},{"spn":4.4,"spf":"NaN","id":36104895},{"atb":[[1.45,268.44],[1.55,109.81],[1.5,241.59]],"id":38206580},{"atl":[[2.82,6.6],[5.1,11.72],[4.1,7.75],[3.55,9.42],[3.05,5.86]],"id":38206580},{"spn":2.18,"spf":"NaN","id":38206580},{"atb":[[3.6,46.46],[3.85,21.19],[3.35,51.4]],"id":27701417},{"atl":[[17.5,0.73],[75,0.64],[40,0.61],[12.5,1.04],[25,1]],"id":27701417},{"spn":8.17,"spf":"NaN","id":27701417},{"atb":[[2,120.79],[2.2,50.33],[2.1,109.81]],"id":38206560},{"atl":[[17.5,2.91],[9,3],[5.5,2.66],[12.5,2.08],[7,2]],"id":38206560},{"spn":3.85,"spf":"NaN","id":38206560},{"atb":[[1.6,100.66],[1.55,219.63],[1.5,241.59]],"id":41762283},{"atl":[[2.88,6.39],[3.2,5.46],[3.7,8.89],[4.4,7.06],[5.4,10.92]],"id":41762283},{"spn":2.24,"spf":"NaN","id":41762283},{"atb":[[1.01,30199.7]],"id":40494181},{"atl":[[2.36,17.67],[2.56,15.4],[1.98,12.25],[2.16,10.35],[2.76,27.3]],"id":40494181},{"spn":1.49,"spf":"NaN","id":40494181}],"con":true,"img":true}]}
{"op":"mcm","clk":"5306064320","pt":1646088413607,"mc":[{"id":"1.195395430","rc":[{"atb":[[3.45,0],[3.2,0],[2.98,0]],"id":39520250},{"atl":[[18.5,0],[44,0],[13.5,0],[27,0],[9.4,0]],"id":39520250},{"spn":"NaN","spf":"NaN","id":39520250},{"atb":[[1.6,201.33],[1.7,86.28],[1.65,185.84]],"id":37265273},{"atl":[[3.2,5.46],[3.7,4.44],[6.8,8.28],[4.4,7.06],[5.4,5.46]],"id":37265273},{"atb":[[2.4,86.28],[2.5,80.53],[2.6,37.74]],"id":36104895},{"atl":[[6.2,2.31],[10.5,2.52],[21,2.4],[8.2,1.66],[15.5,1.65]],"id":36104895},{"atb":[[1.45,0],[1.55,0],[1.5,0]],"id":38206580},{"atl":[[2.82,0],[5.1,0],[4.1,0],[3.55,0],[3.05,0]],"id":38206580},{"spn":"NaN","spf":"NaN","id":38206580},{"atb":[[3.6,0],[3.85,0],[3.35,0]],"id":27701417},{"atl":[[17.5,0],[75,0],[40,0],[12.5,0],[25,0]],"id":27701417},{"spn":"NaN","spf":"NaN","id":27701417},{"atb":[[2,120.79],[2.2,50.33],[2.1,109.81]],"id":38206560},{"atl":[[17.5,2.91],[9,3],[5.5,2.66],[12.5,2.08],[7,2]],"id":38206560},{"atb":[[1.6,0],[1.55,0],[1.5,0]],"id":41762283},{"atl":[[2.88,0],[3.2,0],[3.7,0],[4.4,0],[5.4,0]],"id":41762283},{"spn":"NaN","spf":"NaN","id":41762283},{"atb":[[1.01,0]],"id":40494181},{"atl":[[2.36,0],[2.56,0],[1.98,0],[2.16,0],[2.76,0]],"id":40494181},{"spn":"NaN","spf":"NaN","id":40494181}],"con":true,"img":false}]}
{"op":"mcm","clk":"5306064604","pt":1646088420529,"mc":[{"id":"1.195395430","rc":[{"atb":[[3.1,57.52],[3.35,25.7],[2.94,62.26]],"id":39520250},{"atl":[[17,1.5],[38,1.29],[12,1.09],[24,1.04],[8.8,1.54]],"id":39520250},{"atb":[[1.6,402.66],[1.7,172.57],[1.65,371.68]],"id":37265273},{"atl":[[3.2,10.92],[3.7,8.89],[6.8,16.57],[4.4,14.13],[5.4,10.92]],"id":37265273},{"atb":[[1.4,301.99],[1.45,268.44],[1.5,120.79]],"id":38206580},{"atl":[[3.45,9.8],[3.95,8.14],[4.9,12.32],[2.98,6.06],[2.78,6.74]],"id":38206580},{"atb":[[4.3,18.3],[3.9,41.65],[3.65,45.58]],"id":27701417},{"atl":[[32,0.77],[21,0.6],[55,0.44],[110,0.43],[15.5,0.82]],"id":27701417},{"atb":[[1.8,75.49],[1.7,172.57],[1.75,161.06]],"id":41762283},{"atl":[[3.6,4.62],[6.4,4.44],[5.2,5.72],[4.2,3.75],[8.4,6.49]],"id":41762283},{"atb":[[1.01,30199.7]],"id":40494181},{"atl":[[2.54,15.6],[2.74,27.61],[1.97,12.38],[2.14,10.53],[2.34,17.93]],"id":40494181}],"con":true,"img":false}]}
{"op":"mcm","clk":"5306086901","pt":1646088981482,"mc":[{"id":"1.195395430","rc":[{"spn":6.07,"spf":"NaN","id":39520250},{"spn":2.14,"spf":"NaN","id":38206580},{"spn":9.9,"spf":"NaN","id":27701417},{"atb":[[2,0],[2.2,0],[2.1,0]],"id":38206560},{"atl":[[17.5,0],[9,0],[5.5,0],[12.5,0],[7,0]],"id":38206560},{"spn":"NaN","spf":"NaN","id":38206560},{"spn":2.7,"spf":"NaN","id":41762283},{"atb":[[1.01,0]],"id":40494181},{"atl":[[2.54,0],[2.74,0],[1.97,0],[2.14,0],[2.34,0]],"id":40494181}],"con":true,"img":false}]}
{"op":"mcm","clk":"5306087014","pt":1646088984565,"mc":[{"id":"1.195395430","rc":[{"atb":[[2.4,43.14],[2.3,92.92],[2.2,100.66]],"id":38206560},{"atl":[[9.6,2.79],[19,2.66],[5.8,2.5],[7.6,1.81],[14,1.85]],"id":38206560},{"atb":[[1.01,30199.7]],"id":40494181},{"atl":[[2.54,15.6],[2.74,27.61],[1.97,12.38],[2.14,10.53],[2.34,17.93]],"id":40494181}],"con":true,"img":false}]}
{"op":"mcm","clk":"5306089056","pt":1646089041275,"mc":[{"id":"1.195395430","rc":[{"atb":[[2.4,0],[2.3,0],[2.2,0]],"id":38206560},{"atl":[[9.6,0],[19,0],[5.8,0],[7.6,0],[14,0]],"id":38206560}],"con":true,"img":false}]}
{"op":"mcm","clk":"5306089193","pt":1646089044467,"mc":[{"id":"1.195395430","rc":[{"atb":[[2.4,86.28],[2.5,40.26],[2.3,92.92]],"id":38206560},{"atl":[[8,1.71],[10,2.66],[20,2.52],[6,2.4],[15,1.71]],"id":38206560},{"spn":4.25,"spf":"NaN","id":38206560},{"spn":1.49,"spf":"NaN","id":40494181}],"con":true,"img":false}]}
{"op":"mcm","clk":"5306090270","pt":1646089072441,"mc":[{"id":"1.195395430","rc":[{"atb":[[2.4,0],[2.5,0],[2.6,0]],"id":36104895},{"atl":[[6.2,0],[10.5,0],[21,0],[8.2,0],[15.5,0]],"id":36104895},{"atb":[[1.4,0],[1.45,0],[1.5,0]],"id":38206580},{"atl":[[3.45,0],[3.95,0],[4.9,0],[2.98,0],[2.78,0]],"id":38206580},{"atb":[[2.4,0],[2.5,0],[2.3,0]],"id":38206560},{"atl":[[8,0],[10,0],[20,0],[6,0],[15,0]],"id":38206560}],"con":true,"img":false}]}
{"op":"mcm","clk":"5306090450","pt":1646089076413,"mc":[{"id":"1.195395430","rc":[{"atb":[[1.6,603.99],[1.55,219.63],[1.65,464.6]],"id":37265273},{"atl":[[3.45,4.9],[3.95,8.14],[4.9,6.15],[2.98,6.06],[5.9,9.8]],"id":37265273},{"atb":[[2.86,64.94],[3.15,28.09],[2.96,61.63]],"id":36104895},{"atl":[[16,1.6],[34,1.45],[11,1.2],[22,1.14],[8.4,1.62]],"id":36104895},{"atb":[[1.4,150.99],[1.3,402.66],[1.35,345.13]],"id":38206580},{"atl":[[4.3,14.56],[2.86,6.46],[2.66,7.23],[3.15,11.17],[3.65,9.06]],"id":38206580},{"atb":[[2.4,43.14],[2.3,92.92],[2.2,100.66]],"id":38206560},{"atl":[[9.6,2.79],[19,2.66],[5.8,2.5],[7.6,1.81],[14,1.85]],"id":38206560}],"con":true,"img":false}]}
{"op":"mcm","clk":"5306196768","pt":1646092002673,"mc":[{"id":"1.195395430","marketDefinition":{"bspMarket":true,"turnInPlayEnabled":false,"persistenceEnabled":false,"marketBaseRate":7.0,"eventId":"31270458","eventTypeId":"4339","numberOfWinners":3,"bettingType":"ODDS","marketType":"PLACE","marketTime":"2022-03-01T03:42:00.000Z","suspendTime":"2022-03-01T03:42:00.000Z","bspReconciled":false,"complete":true,"inPlay":false,"crossMatching":false,"runnersVoidable":false,"numberOfActiveRunners":8,"betDelay":0,"status":"OPEN","runners":[{"status":"ACTIVE","sortPriority":1,"id":40494181,"name":"1. Loch And Loaded"},{"status":"ACTIVE","sortPriority":2,"id":38206580,"name":"2. Buckle Up Wilder"},{"status":"ACTIVE","sortPriority":3,"id":38206560,"name":"3. Hiccup Amisha"},{"status":"ACTIVE","sortPriority":4,"id":36104895,"name":"4. Langley Roo"},{"status":"ACTIVE","sortPriority":5,"id":39520250,"name":"5. Rip On Bye"},{"status":"ACTIVE","sortPriority":6,"id":41762283,"name":"6. Gracies Joy"},{"status":"ACTIVE","sortPriority":7,"id":37265273,"name":"7. Just Mercy"},{"status":"ACTIVE","sortPriority":8,"id":27701417,"name":"8. Jalla General"}],"regulators":["MR_INT"],"venue":"Devonport","countryCode":"AU","discountAllowed":true,"timezone":"Australia/Sydney","openDate":"2022-03-01T02:00:00.000Z","version":4380714804,"name":"To Be Placed","eventName":"Devonport (AUS) 1st Mar"},"rc":[{"atb":[[3.1,57.52],[3.35,25.7],[2.94,62.26]],"id":39520250},{"atl":[[17,1.5],[38,1.29],[12,1.09],[24,1.04],[8.8,1.54]],"id":39520250},{"spn":6.07,"spf":"NaN","id":39520250},{"atb":[[1.6,603.99],[1.55,219.63],[1.7,172.57],[1.65,464.6]],"id":37265273},{"atl":[[3.45,4.9],[3.2,10.92],[3.95,8.14],[3.7,8.89],[6.8,16.57],[4.9,6.15],[2.98,6.06],[4.4,14.13],[5.9,9.8],[5.4,10.92]],"id":37265273},{"spn":2.34,"spf":"NaN","id":37265273},{"atb":[[2.86,64.94],[3.15,28.09],[2.96,61.63]],"id":36104895},{"atl":[[16,1.6],[34,1.45],[11,1.2],[22,1.14],[8.4,1.62]],"id":36104895},{"spn":5.77,"spf":"NaN","id":36104895},{"atb":[[1.4,150.99],[1.3,402.66],[1.35,345.13]],"id":38206580},{"atl":[[4.3,14.56],[2.86,6.46],[2.66,7.23],[3.15,11.17],[3.65,9.06]],"id":38206580},{"spn":2.03,"spf":"NaN","id":38206580},{"atb":[[4.3,18.3],[3.9,41.65],[3.65,45.58]],"id":27701417},{"atl":[[32,0.77],[21,0.6],[55,0.44],[110,0.43],[15.5,0.82]],"id":27701417},{"spn":9.9,"spf":"NaN","id":27701417},{"atb":[[2.4,43.14],[2.3,92.92],[2.2,100.66]],"id":38206560},{"atl":[[9.6,2.79],[19,2.66],[5.8,2.5],[7.6,1.81],[14,1.85]],"id":38206560},{"spn":4.1,"spf":"NaN","id":38206560},{"atb":[[1.8,75.49],[1.7,172.57],[1.75,161.06]],"id":41762283},{"atl":[[3.6,4.62],[6.4,4.44],[5.2,5.72],[4.2,3.75],[8.4,6.49]],"id":41762283},{"spn":2.7,"spf":"NaN","id":41762283},{"atb":[[1.01,30199.7]],"id":40494181},{"atl":[[2.54,15.6],[2.74,27.61],[1.97,12.38],[2.14,10.53],[2.34,17.93]],"id":40494181},{"spn":1.49,"spf":"NaN","id":40494181}],"con":true,"img":true}]}
{"op":"mcm","clk":"5306352568","pt":1646096212700,"mc":[{"id":"1.195395430","rc":[{"atb":[[3.1,0],[3.35,0],[2.94,0]],"id":39520250},{"atl":[[17,0],[38,0],[12,0],[24,0],[8.8,0]],"id":39520250},{"spn":"NaN","spf":"NaN","id":39520250},{"atb":[[1.6,603.6],[1.55,219.49],[1.7,172.45],[1.65,464.3]],"id":37265273},{"atl":[[3.45,4.9],[3.2,10.91],[3.95,8.13],[3.7,8.89],[6.8,16.56],[4.9,6.15],[2.98,6.06],[4.4,14.12],[5.9,9.8],[5.4,10.91]],"id":37265273},{"spn":2.34,"spf":"NaN","id":37265273},{"atb":[[2.86,0],[3.15,0],[2.96,0]],"id":36104895},{"atl":[[16,0],[34,0],[11,0],[22,0],[8.4,0]],"id":36104895},{"spn":"NaN","spf":"NaN","id":36104895},{"atb":[[1.4,150.9],[1.3,402.4],[1.35,344.91]],"id":38206580},{"atl":[[4.3,14.55],[2.86,6.45],[2.66,7.23],[3.15,11.16],[3.65,9.05]],"id":38206580},{"spn":2.03,"spf":"NaN","id":38206580},{"atb":[[4.3,0],[3.9,0],[3.65,0]],"id":27701417},{"atl":[[32,0],[21,0],[55,0],[110,0],[15.5,0]],"id":27701417},{"spn":"NaN","spf":"NaN","id":27701417},{"atb":[[2.4,0],[2.3,0],[2.2,0]],"id":38206560},{"atl":[[9.6,0],[19,0],[5.8,0],[7.6,0],[14,0]],"id":38206560},{"spn":"NaN","spf":"NaN","id":38206560},{"atb":[[1.8,0],[1.7,0],[1.75,0]],"id":41762283},{"atl":[[3.6,0],[6.4,0],[5.2,0],[4.2,0],[8.4,0]],"id":41762283},{"spn":"NaN","spf":"NaN","id":41762283},{"atb":[[1.01,30180.1]],"id":40494181},{"atl":[[2.54,15.59],[2.74,27.6],[1.97,12.38],[2.14,10.53],[2.34,17.91]],"id":40494181}],"con":true,"img":false}]}
{"op":"mcm","clk":"5306353035","pt":1646096223976,"mc":[{"id":"1.195395430","rc":[{"atb":[[3.1,57.48],[3.35,25.68],[2.94,62.22]],"id":39520250},{"atl":[[17,1.5],[38,1.29],[12,1.09],[24,1.04],[8.8,1.54]],"id":39520250},{"atb":[[1.7,344.91],[1.65,650.02],[1.75,80.48]],"id":37265273},{"atl":[[8,6.86],[3.5,4.8],[4,4],[5,6],[6,4.8]],"id":37265273},{"atb":[[2.8,33.53],[2.6,75.45],[2.7,71]],"id":36104895},{"atl":[[7.2,1.93],[18,1.41],[9.2,1.46],[13,2],[26,1.92]],"id":36104895},{"atb":[[3.45,49.27],[3.95,20.46],[3.7,44.71]],"id":27701417},{"atl":[[18.5,0.68],[85,0.57],[44,0.55],[13.5,0.96],[27,0.92]],"id":27701417},{"atb":[[2.4,43.11],[2.3,92.86],[2.2,100.6]],"id":38206560},{"atl":[[9.6,2.79],[19,2.66],[5.8,2.5],[7.6,1.81],[14,1.84]],"id":38206560},{"atb":[[1.7,172.45],[1.75,80.48],[1.65,185.72]],"id":41762283},{"atl":[[4,4],[8,6.86],[5,6],[6,4.8],[3.5,4.8]],"id":41762283}],"con":true,"img":false}]}
{"op":"mcm","clk":"5306354785","pt":1646096272772,"mc":[{"id":"1.195395430","rc":[{"atb":[[3.1,0],[3.35,0],[2.94,0]],"id":39520250},{"atl":[[17,0],[38,0],[12,0],[24,0],[8.8,0]],"id":39520250},{"spn":2.36,"spf":"NaN","id":37265273},{"atb":[[2.8,0],[2.6,0],[2.7,0]],"id":36104895},{"atl":[[7.2,0],[18,0],[9.2,0],[13,0],[26,0]],"id":36104895},{"atb":[[1.4,0],[1.3,0],[1.35,0]],"id":38206580},{"atl":[[4.3,0],[2.86,0],[2.66,0],[3.15,0],[3.65,0]],"id":38206580},{"spn":"NaN","spf":"NaN","id":38206580},{"atb":[[3.45,0],[3.95,0],[3.7,0]],"id":27701417},{"atl":[[18.5,0],[85,0],[44,0],[13.5,0],[27,0]],"id":27701417},{"atb":[[2.4,0],[2.3,0],[2.2,0]],"id":38206560},{"atl":[[9.6,0],[19,0],[5.8,0],[7.6,0],[14,0]],"id":38206560},{"atb":[[1.7,0],[1.75,0],[1.65,0]],"id":41762283},{"atl":[[4,0],[8,0],[5,0],[6,0],[3.5,0]],"id":41762283},{"atb":[[1.01,0]],"id":40494181},{"atl":[[2.54,0],[2.74,0],[1.97,0],[2.14,0],[2.34,0]],"id":40494181},{"spn":"NaN","spf":"NaN","id":40494181}],"con":true,"img":false}]}
{"op":"mcm","clk":"5306355053","pt":1646096280487,"mc":[{"id":"1.195395430","rc":[{"atb":[[2.4,86.22],[2.5,40.24],[2.3,92.86]],"id":39520250},{"atl":[[8,1.71],[10,2.66],[20,2.52],[6,2.4],[15,1.71]],"id":39520250},{"atb":[[1.8,75.45],[1.7,517.37],[1.75,241.44]],"id":37265273},{"atl":[[3.6,4.61],[6.4,4.44],[8.4,6.49],[5.2,5.71],[4.2,3.75]],"id":37265273},{"atb":[[2.88,64.21],[2.98,30.48],[2.78,67.81]],"id":36104895},{"atl":[[32,1.54],[10.5,1.26],[21,1.2],[8.2,1.66],[15.5,1.65]],"id":36104895},{"atb":[[1.45,268.26],[1.55,109.74],[1.5,241.44]],"id":38206580},{"atl":[[2.82,6.59],[5.1,11.71],[4.1,7.74],[3.55,9.41],[3.05,5.85]],"id":38206580},{"atb":[[4.1,19.47],[3.8,43.11],[3.55,47.34]],"id":27701417},{"atl":[[19.5,0.64],[95,0.5],[48,0.5],[14.5,0.88],[29,0.85]],"id":27701417},{"atb":[[2.4,86.22],[2.5,40.24],[2.3,92.86]],"id":38206560},{"atl":[[8,1.71],[10,2.66],[20,2.52],[6,2.4],[15,1.71]],"id":38206560},{"atb":[[1.8,75.45],[1.7,172.45],[1.75,160.96]],"id":41762283},{"atl":[[3.6,4.61],[6.4,4.44],[5.2,5.71],[4.2,3.75],[8.4,6.49]],"id":41762283},{"atb":[[1.01,30180.1]],"id":40494181},{"atl":[[2.54,15.59],[2.74,27.6],[1.97,12.38],[2.14,10.53],[2.34,17.91]],"id":40494181}],"con":true,"img":false}]}
{"op":"mcm","clk":"5306358257","pt":1646096361770,"mc":[{"id":"1.195395430","rc":[{"atb":[[2.4,0],[2.5,0],[2.3,0]],"id":39520250},{"atl":[[8,0],[10,0],[20,0],[6,0],[15,0]],"id":39520250},{"spn":2.39,"spf":"NaN","id":37265273},{"atb":[[2.88,0],[2.98,0],[2.78,0]],"id":36104895},{"atl":[[32,0],[10.5,0],[21,0],[8.2,0],[15.5,0]],"id":36104895},{"spn":2.18,"spf":"NaN","id":38206580},{"spn":9.3,"spf":"NaN","id":27701417},{"spn":4.25,"spf":"NaN","id":38206560},{"spn":2.7,"spf":"NaN","id":41762283},{"spn":1.49,"spf":"NaN","id":40494181}],"con":true,"img":false}]}
{"op":"mcm","clk":"5306358450","pt":1646096366444,"mc":[{"id":"1.195395430","rc":[{"atb":[[2,120.72],[2.2,50.3],[2.1,109.74]],"id":39520250},{"atl":[[17.5,2.9],[9,3],[5.5,2.66],[12.5,2.08],[7,2]],"id":39520250},{"atb":[[1.6,804.8],[1.7,603.6],[1.65,835.74]],"id":37265273},{"atl":[[6.8,24.84],[4.4,21.19],[5.4,16.37],[3.2,16.37],[3.7,13.33]],"id":37265273},{"atb":[[2.86,64.9],[3.15,28.07],[2.96,61.59]],"id":36104895},{"atl":[[16,1.6],[34,1.45],[11,1.2],[22,1.14],[8.4,1.62]],"id":36104895}],"con":true,"img":false}]}
{"op":"mcm","clk":"5306387136","pt":1646097082158,"mc":[{"id":"1.195395430","rc":[{"atb":[[2,0],[2.2,0],[2.1,0]],"id":39520250},{"atl":[[17.5,0],[9,0],[5.5,0],[12.5,0],[7,0]],"id":39520250},{"spn":5.77,"spf":"NaN","id":36104895}],"con":true,"img":false}]}
{"op":"mcm","clk":"5306387345","pt":1646097088437,"mc":[{"id":"1.195395430","rc":[{"atb":[[2.3,46.43],[2.2,100.6],[2.1,109.74]],"id":39520250},{"atl":[[5.6,2.61],[7.2,1.93],[18,2.82],[9.2,2.92],[13,2]],"id":39520250}],"con":true,"img":false}]}
{"op":"mcm","clk":"5306404681","pt":1646097402649,"mc":[{"id":"1.195395430","marketDefinition":{"bspMarket":true,"turnInPlayEnabled":false,"persistenceEnabled":false,"marketBaseRate":7.0,"eventId":"31270458","eventTypeId":"4339","numberOfWinners":3,"bettingType":"ODDS","marketType":"PLACE","marketTime":"2022-03-01T03:42:00.000Z","suspendTime":"2022-03-01T03:42:00.000Z","bspReconciled":false,"complete":true,"inPlay":false,"crossMatching":false,"runnersVoidable":false,"numberOfActiveRunners":8,"betDelay":0,"status":"OPEN","runners":[{"status":"ACTIVE","sortPriority":1,"id":40494181,"name":"1. Loch And Loaded"},{"status":"ACTIVE","sortPriority":2,"id":38206580,"name":"2. Buckle Up Wilder"},{"status":"ACTIVE","sortPriority":3,"id":38206560,"name":"3. Hiccup Amisha"},{"status":"ACTIVE","sortPriority":4,"id":36104895,"name":"4. Langley Roo"},{"status":"ACTIVE","sortPriority":5,"id":39520250,"name":"5. Rip On Bye"},{"status":"ACTIVE","sortPriority":6,"id":41762283,"name":"6. Gracies Joy"},{"status":"ACTIVE","sortPriority":7,"id":37265273,"name":"7. Just Mercy"},{"status":"ACTIVE","sortPriority":8,"id":27701417,"name":"8. Jalla General"}],"regulators":["MR_INT"],"venue":"Devonport","countryCode":"AU","discountAllowed":true,"timezone":"Australia/Sydney","openDate":"2022-03-01T02:00:00.000Z","version":4380714804,"name":"To Be Placed","eventName":"Devonport (AUS) 1st Mar"},"rc":[{"atb":[[2.3,46.43],[2.2,100.6],[2.1,109.74]],"id":39520250},{"atl":[[5.6,2.61],[7.2,1.93],[18,2.82],[9.2,2.92],[13,2]],"id":39520250},{"spn":3.95,"spf":"NaN","id":39520250},{"atb":[[1.8,75.45],[1.6,804.8],[1.55,219.49],[1.7,603.6],[1.75,241.44],[1.65,835.74]],"id":37265273},{"atl":[[8,6.86],[3.6,4.61],[6.4,4.44],[6.8,24.84],[4.9,6.15],[2.98,6.06],[4.4,21.19],[3.5,4.8],[5.9,9.8],[8.4,6.49],[5.4,16.37],[4,4],[3.45,4.9],[3.2,16.37],[5,6],[3.95,8.13],[3.7,13.33],[6,4.8],[5.2,5.71],[4.2,3.75]],"id":37265273},{"spn":2.39,"spf":"NaN","id":37265273},{"atb":[[2.86,64.9],[3.15,28.07],[2.96,61.59]],"id":36104895},{"atl":[[16,1.6],[34,1.45],[11,1.2],[22,1.14],[8.4,1.62]],"id":36104895},{"spn":5.77,"spf":"NaN","id":36104895},{"atb":[[1.45,268.26],[1.55,109.74],[1.5,241.44]],"id":38206580},{"atl":[[2.82,6.59],[5.1,11.71],[4.1,7.74],[3.55,9.41],[3.05,5.85]],"id":38206580},{"spn":2.18,"spf":"NaN","id":38206580},{"atb":[[4.1,19.47],[3.8,43.11],[3.55,47.34]],"id":27701417},{"atl":[[19.5,0.64],[95,0.5],[48,0.5],[14.5,0.88],[29,0.85]],"id":27701417},{"spn":9.3,"spf":"NaN","id":27701417},{"atb":[[2.4,86.22],[2.5,40.24],[2.3,92.86]],"id":38206560},{"atl":[[8,1.71],[10,2.66],[20,2.52],[6,2.4],[15,1.71]],"id":38206560},{"spn":4.25,"spf":"NaN","id":38206560},{"atb":[[1.8,75.45],[1.7,172.45],[1.75,160.96]],"id":41762283},{"atl":[[3.6,4.61],[6.4,4.44],[5.2,5.71],[4.2,3.75],[8.4,6.49]],"id":41762283},{"spn":2.7,"spf":"NaN","id":41762283},{"atb":[[1.01,30180.1]],"id":40494181},{"atl":[[2.54,15.59],[2.74,27.6],[1.97,12.38],[2.14,10.53],[2.34,17.91]],"id":40494181},{"spn":1.49,"spf":"NaN","id":40494181}],"con":true,"img":true}]}
{"op":"mcm","clk":"5306554683","pt":1646100805267,"mc":[{"id":"1.195395430","rc":[{"atb":[[2.3,46.45],[2.06,40.83],[1.88,47.61],[2.2,100.64],[2.1,109.79]],"id":39520250},{"atl":[[5.6,2.61],[7.2,1.93],[18,2.82],[9.2,2.92],[8.2,5.41],[7.4,6.76],[13,2]],"id":39520250},{"spn":3.95,"spf":"NaN","id":39520250},{"atb":[[1.8,75.48],[1.6,805.15],[1.55,219.58],[1.7,603.86],[1.49,83.74],[1.75,241.54],[1.65,836.1],[1.71,60.97]],"id":37265273},{"atl":[[8,6.86],[3.6,4.62],[6.4,4.44],[6.8,24.85],[4.9,16.67],[2.98,6.06],[4.4,21.2],[3.5,4.8],[5.9,9.8],[8.4,6.49],[5.4,16.37],[4,4],[3.45,4.9],[3.2,16.37],[5,6],[3.95,8.14],[3.7,13.34],[6,4.8],[5.2,5.71],[3.15,20.13],[4.2,3.75]],"id":37265273},{"atb":[[2.72,24.89],[2.86,64.93],[3.1,20.61],[3.15,28.08],[2.96,61.62]],"id":36104895},{"atl":[[16,1.6],[34,1.45],[17,2.7],[11,1.2],[22,1.14],[8.4,1.62],[15.5,2.98]],"id":36104895},{"atb":[[1.6,72.14],[1.45,268.38],[1.55,109.79],[1.5,241.54],[1.49,87.11]],"id":38206580},{"atl":[[2.82,6.6],[5.1,11.72],[5,10.82],[4.1,7.74],[3.55,9.42],[3.05,5.86],[4.7,10.82]],"id":38206580},{"spn":2.21,"spf":"NaN","id":38206580},{"atb":[[4,14.43],[3.45,14.39],[4.1,19.47],[3.8,43.13],[3.55,47.36]],"id":27701417},{"atl":[[19.5,0.64],[95,0.5],[48,0.5],[24,2.7],[26,2.7],[14.5,0.88],[29,0.86]],"id":27701417},{"atb":[[2.4,86.26],[2.5,40.25],[2.3,92.9],[2.46,29.64],[2.2,34.63]],"id":38206560},{"atl":[[8,1.71],[10,2.66],[20,2.52],[10.5,4.55],[11,4.32],[6,2.4],[15,1.71]],"id":38206560},{"atb":[[1.8,75.48],[1.58,64.99],[1.7,172.53],[1.75,161.03],[1.71,60.97]],"id":41762283},{"atl":[[3.6,4.62],[6.4,4.44],[5.3,10.06],[5.2,5.71],[4.2,3.75],[8.4,6.49],[5.9,7.25]],"id":41762283},{"atb":[[1.01,30193.17],[1.07,455.12],[1.05,786.39]],"id":40494181},{"atl":[[2.54,15.59],[2.74,27.61],[1.97,12.38],[1.62,63.41],[1.51,43.28],[2.14,10.53],[2.34,17.92]],"id":40494181},{"spn":1.29,"spf":"NaN","id":40494181}],"con":true,"img":false}]}
{"op":"mcm","clk":"5306556020","pt":1646100832297,"mc":[{"id":"1.195395430","rc":[{"atb":[[1.07,104.62]],"id":40494181}],"con":true,"img":false}]}
{"op":"mcm","clk":"5306558594","pt":1646100885063,"mc":[{"id":"1.195395430","rc":[{"atb":[[2.06,0]],"id":39520250},{"atb":[[1.49,0]],"id":37265273},{"atb":[[2.72,0]],"id":36104895},{"atb":[[1.49,0]],"id":38206580},{"atl":[[3.5,17.31],[4.7,0]],"id":38206580},{"atb":[[3.45,0]],"id":27701417},{"atb":[[2.2,0]],"id":38206560},{"atb":[[1.71,0]],"id":41762283}],"con":true,"img":false}]}
{"op":"mcm","clk":"5306558601","pt":1646100885165,"mc":[{"id":"1.195395430","rc":[{"atb":[[2.22,40.83]],"id":39520250},{"atb":[[1.56,83.74]],"id":37265273},{"atb":[[2.88,24.89]],"id":36104895},{"atb":[[1.51,87.11]],"id":38206580},{"atb":[[3.6,14.39]],"id":27701417},{"atb":[[2.42,34.63]],"id":38206560},{"atb":[[1.76,60.97]],"id":41762283}],"con":true,"img":false}]}
{"op":"mcm","clk":"5306561647","pt":1646100947351,"mc":[{"id":"1.195395430","rc":[{"atb":[[2.88,0]],"id":36104895}],"con":true,"img":false}]}
{"op":"mcm","clk":"5306561652","pt":1646100947453,"mc":[{"id":"1.195395430","rc":[{"atb":[[2.98,24.89]],"id":36104895}],"con":true,"img":false}]}
{"op":"mcm","clk":"5306563381","pt":1646100983195,"mc":[{"id":"1.195395430","rc":[{"atb":[[1.76,0]],"id":41762283}],"con":true,"img":false}]}
{"op":"mcm","clk":"5306563390","pt":1646100983298,"mc":[{"id":"1.195395430","rc":[{"atb":[[1.81,60.97]],"id":41762283}],"con":true,"img":false}]}
{"op":"mcm","clk":"5306569486","pt":1646101120304,"mc":[{"id":"1.195395430","marketDefinition":{"bspMarket":true,"turnInPlayEnabled":false,"persistenceEnabled":false,"marketBaseRate":7.0,"eventId":"31270458","eventTypeId":"4339","numberOfWinners":3,"bettingType":"ODDS","marketType":"PLACE","marketTime":"2022-03-01T03:57:00.000Z","suspendTime":"2022-03-01T03:57:00.000Z","bspReconciled":false,"complete":true,"inPlay":false,"crossMatching":false,"runnersVoidable":false,"numberOfActiveRunners":8,"betDelay":0,"status":"OPEN","runners":[{"status":"ACTIVE","sortPriority":1,"id":40494181,"name":"1. Loch And Loaded"},{"status":"ACTIVE","sortPriority":2,"id":38206580,"name":"2. Buckle Up Wilder"},{"status":"ACTIVE","sortPriority":3,"id":38206560,"name":"3. Hiccup Amisha"},{"status":"ACTIVE","sortPriority":4,"id":36104895,"name":"4. Langley Roo"},{"status":"ACTIVE","sortPriority":5,"id":39520250,"name":"5. Rip On Bye"},{"status":"ACTIVE","sortPriority":6,"id":41762283,"name":"6. Gracies Joy"},{"status":"ACTIVE","sortPriority":7,"id":37265273,"name":"7. Just Mercy"},{"status":"ACTIVE","sortPriority":8,"id":27701417,"name":"8. Jalla General"}],"regulators":["MR_INT"],"venue":"Devonport","countryCode":"AU","discountAllowed":true,"timezone":"Australia/Sydney","openDate":"2022-03-01T02:00:00.000Z","version":4381058394,"name":"To Be Placed","eventName":"Devonport (AUS) 1st Mar"},"rc":[],"con":true,"img":false}]}
{"op":"mcm","clk":"5306596095","pt":1646101721751,"mc":[{"id":"1.195395430","rc":[{"spn":2.7,"spf":"NaN","id":41762283},{"atl":[[1.21,91.98]],"id":40494181},{"spn":1.14,"spf":"NaN","id":40494181}],"con":true,"img":false}]}
{"op":"mcm","clk":"5306596577","pt":1646101735585,"mc":[{"id":"1.195395430","rc":[{"atl":[[3.5,0]],"id":38206580}],"con":true,"img":false}]}
{"op":"mcm","clk":"5306599089","pt":1646101796095,"mc":[{"id":"1.195395430","rc":[{"atl":[[4.6,12.02]],"id":38206580}],"con":true,"img":false}]}
{"op":"mcm","clk":"5306599093","pt":1646101796152,"mc":[{"id":"1.195395430","rc":[{"atl":[[1.51,0]],"id":40494181}],"con":true,"img":false}]}
{"op":"mcm","clk":"5306599098","pt":1646101796258,"mc":[{"id":"1.195395430","rc":[{"atl":[[1.45,43.28]],"id":40494181}],"con":true,"img":false}]}
{"op":"mcm","clk":"5306600870","pt":1646101832105,"mc":[{"id":"1.195395430","rc":[{"atb":[[1.58,0],[1.71,53.09]],"id":41762283}],"con":true,"img":false}]}
{"op":"mcm","clk":"5306600874","pt":1646101832206,"mc":[{"id":"1.195395430","rc":[{"atl":[[4.9,6.15]],"id":37265273}],"con":true,"img":false}]}
{"op":"mcm","clk":"5306600879","pt":1646101832310,"mc":[{"id":"1.195395430","rc":[{"atl":[[4.3,10.51]],"id":37265273}],"con":true,"img":false}]}
{"op":"mcm","clk":"5306676931","pt":1646103347332,"mc":[{"id":"1.195395430","marketDefinition":{"bspMarket":true,"turnInPlayEnabled":false,"persistenceEnabled":false,"marketBaseRate":7.0,"eventId":"31270458","eventTypeId":"4339","numberOfWinners":3,"bettingType":"ODDS","marketType":"PLACE","marketTime":"2022-03-01T04:42:00.000Z","suspendTime":"2022-03-01T04:42:00.000Z","bspReconciled":false,"complete":true,"inPlay":false,"crossMatching":false,"runnersVoidable":false,"numberOfActiveRunners":8,"betDelay":0,"status":"OPEN","runners":[{"status":"ACTIVE","sortPriority":1,"id":40494181,"name":"1. Loch And Loaded"},{"status":"ACTIVE","sortPriority":2,"id":38206580,"name":"2. Buckle Up Wilder"},{"status":"ACTIVE","sortPriority":3,"id":38206560,"name":"3. Hiccup Amisha"},{"status":"ACTIVE","sortPriority":4,"id":36104895,"name":"4. Langley Roo"},{"status":"ACTIVE","sortPriority":5,"id":39520250,"name":"5. Rip On Bye"},{"status":"ACTIVE","sortPriority":6,"id":41762283,"name":"6. Gracies Joy"},{"status":"ACTIVE","sortPriority":7,"id":37265273,"name":"7. Just Mercy"},{"status":"ACTIVE","sortPriority":8,"id":27701417,"name":"8. Jalla General"}],"regulators":["MR_INT"],"venue":"Devonport","countryCode":"AU","discountAllowed":true,"timezone":"Australia/Sydney","openDate":"2022-03-01T02:00:00.000Z","version":4381083967,"name":"To Be Placed","eventName":"Devonport (AUS) 1st Mar"},"rc":[],"con":true,"img":false}]}
{"op":"mcm","clk":"5306745998","pt":1646105018352,"mc":[{"id":"1.195395430","rc":[{"atb":[[2.24,24.93]],"id":39520250},{"atb":[[1.72,42.93]],"id":37265273},{"atb":[[1.52,59.44]],"id":38206580},{"atb":[[2.52,20.33]],"id":38206560},{"spn":4.26,"spf":"NaN","id":38206560},{"atb":[[1.76,40.67]],"id":41762283},{"atb":[[1.02,366.19]],"id":40494181}],"con":true,"img":false}]}
{"op":"mcm","clk":"5306746691","pt":1646105037255,"mc":[{"id":"1.195395430","marketDefinition":{"bspMarket":true,"turnInPlayEnabled":false,"persistenceEnabled":false,"marketBaseRate":7.0,"eventId":"31270458","eventTypeId":"4339","numberOfWinners":3,"bettingType":"ODDS","marketType":"PLACE","marketTime":"2022-03-01T04:42:00.000Z","suspendTime":"2022-03-01T04:42:00.000Z","bspReconciled":false,"complete":true,"inPlay":false,"crossMatching":true,"runnersVoidable":false,"numberOfActiveRunners":8,"betDelay":0,"status":"OPEN","runners":[{"status":"ACTIVE","sortPriority":1,"id":40494181,"name":"1. Loch And Loaded"},{"status":"ACTIVE","sortPriority":2,"id":38206580,"name":"2. Buckle Up Wilder"},{"status":"ACTIVE","sortPriority":3,"id":38206560,"name":"3. Hiccup Amisha"},{"status":"ACTIVE","sortPriority":4,"id":36104895,"name":"4. Langley Roo"},{"status":"ACTIVE","sortPriority":5,"id":39520250,"name":"5. Rip On Bye"},{"status":"ACTIVE","sortPriority":6,"id":41762283,"name":"6. Gracies Joy"},{"status":"ACTIVE","sortPriority":7,"id":37265273,"name":"7. Just Mercy"},{"status":"ACTIVE","sortPriority":8,"id":27701417,"name":"8. Jalla General"}],"regulators":["MR_INT"],"venue":"Devonport","countryCode":"AU","discountAllowed":true,"timezone":"Australia/Sydney","openDate":"2022-03-01T02:00:00.000Z","version":4381083967,"name":"To Be Placed","eventName":"Devonport (AUS) 1st Mar"},"rc":[],"con":true,"img":false}]}
{"op":"mcm","clk":"5306748234","pt":1646105074338,"mc":[{"id":"1.195395430","rc":[{"atb":[[1.51,0]],"id":38206580},{"atb":[[3.6,0]],"id":27701417}],"con":true,"img":false}]}
{"op":"mcm","clk":"5306748238","pt":1646105074389,"mc":[{"id":"1.195395430","rc":[{"atb":[[1.56,87.11]],"id":38206580},{"atb":[[3.85,14.39]],"id":27701417}],"con":true,"img":false}]}
{"op":"mcm","clk":"5306748395","pt":1646105078233,"mc":[{"id":"1.195395430","rc":[{"atb":[[1.52,0]],"id":38206580}],"con":true,"img":false}]}
{"op":"mcm","clk":"5306748636","pt":1646105082518,"mc":[{"id":"1.195395430","rc":[{"atb":[[1.57,54.22]],"id":38206580}],"con":true,"img":false}]}
{"op":"mcm","clk":"5306762047","pt":1646105451987,"mc":[{"id":"1.195395430","rc":[{"atb":[[2.24,0]],"id":39520250},{"atb":[[1.72,0]],"id":37265273},{"atb":[[1.57,0]],"id":38206580},{"atb":[[2.52,0]],"id":38206560},{"spn":4.25,"spf":"NaN","id":38206560},{"atb":[[1.76,0]],"id":41762283},{"atb":[[1.02,0]],"id":40494181}],"con":true,"img":false}]}
{"op":"mcm","clk":"5306762107","pt":1646105454135,"mc":[{"id":"1.195395430","rc":[{"atb":[[1.56,0]],"id":38206580},{"atb":[[3.85,0]],"id":27701417}],"con":true,"img":false}]}
{"op":"mcm","clk":"5306762111","pt":1646105454187,"mc":[{"id":"1.195395430","rc":[{"atb":[[1.51,87.11]],"id":38206580},{"atb":[[3.6,14.39]],"id":27701417}],"con":true,"img":false}]}
{"op":"mcm","clk":"5306764184","pt":1646105529525,"mc":[{"id":"1.195395430","rc":[{"atb":[[2.3,0],[2.2,0],[2.1,0]],"id":39520250},{"atl":[[5.6,0],[7.2,0],[18,0],[9.2,0],[13,0]],"id":39520250},{"spn":4.81,"spf":"NaN","id":39520250},{"atb":[[1.8,0],[1.6,0],[1.55,0],[1.7,0],[1.75,0],[1.65,0]],"id":37265273},{"atl":[[8,0],[3.6,0],[6.4,0],[6.8,0],[4.9,0],[2.98,0],[4.4,0],[3.5,0],[5.9,0],[8.4,0],[5.4,0],[4,0],[3.45,0],[3.2,0],[5,0],[3.95,0],[3.7,0],[6,0],[5.2,0],[4.2,0]],"id":37265273},{"spn":2.43,"spf":"NaN","id":37265273},{"atb":[[2.86,0],[3.15,0],[2.96,0]],"id":36104895},{"atl":[[16,0],[34,0],[11,0],[22,0],[8.4,0]],"id":36104895},{"spn":9.3,"spf":"NaN","id":36104895},{"atb":[[1.45,0],[1.55,0],[1.5,0]],"id":38206580},{"atl":[[2.82,0],[5.1,0],[4.1,0],[3.55,0],[3.05,0]],"id":38206580},{"spn":3.1,"spf":"NaN","id":38206580},{"atb":[[4.1,0],[3.8,0],[3.55,0]],"id":27701417},{"atl":[[19.5,0],[95,0],[48,0],[14.5,0],[29,0]],"id":27701417},{"spn":14.0,"spf":"NaN","id":27701417},{"atb":[[2.4,0],[2.5,0],[2.3,0]],"id":38206560},{"atl":[[8,0],[10,0],[20,0],[6,0],[15,0]],"id":38206560},{"spn":6.48,"spf":"NaN","id":38206560},{"atb":[[1.8,0],[1.7,0],[1.75,0]],"id":41762283},{"atl":[[3.6,0],[6.4,0],[5.2,0],[4.2,0],[8.4,0]],"id":41762283},{"spn":3.55,"spf":"NaN","id":41762283},{"atb":[[1.01,0]],"id":40494181},{"atl":[[2.54,0],[2.74,0],[1.97,0],[2.14,0],[2.34,0]],"id":40494181}],"con":true,"img":false}]}
{"op":"mcm","clk":"5306764243","pt":1646105532643,"mc":[{"id":"1.195395430","rc":[{"atb":[[2.3,46.19],[2.2,100.1],[2.1,109.2]],"id":39520250},{"atl":[[5.6,0.11],[7.2,0.08],[9.2,0.53]],"id":39520250},{"atb":[[1.6,200.2],[1.7,85.8],[1.65,184.8]],"id":37265273},{"atl":[[3.2,0.24],[3.7,0.2],[4.4,1.27]],"id":37265273},{"atb":[[2.86,64.57],[3.15,27.93],[2.96,61.28]],"id":36104895},{"atl":[[16,0.28],[11,0.05],[8.4,0.07]],"id":36104895},{"atb":[[1.45,266.93],[1.55,109.2],[1.5,240.24]],"id":38206580},{"atl":[[2.82,0.29],[3.55,1.69],[3.05,0.26]],"id":38206580},{"atb":[[4.1,19.37],[3.8,42.9],[3.55,47.1]],"id":27701417},{"atl":[[19.5,0.02],[14.5,0.03],[29,0.15]],"id":27701417},{"atb":[[2.4,85.8],[2.5,40.04],[2.3,92.4]],"id":38206560},{"atl":[[8,0.07],[10,0.48],[6,0.1]],"id":38206560},{"atb":[[1.8,75.07],[1.7,171.6],[1.75,160.16]],"id":41762283},{"atl":[[3.6,0.2],[5.2,1.02],[4.2,0.16]],"id":41762283},{"atb":[[1.01,30030.84]],"id":40494181},{"atl":[[1.97,0.55],[2.14,0.47],[2.34,3.23]],"id":40494181}],"con":true,"img":false}]}
{"op":"mcm","clk":"5306764509","pt":1646105542008,"mc":[{"id":"1.195395430","rc":[{"atl":[[4.5,12.36],[3.15,0]],"id":37265273}],"con":true,"img":false}]}
{"op":"mcm","clk":"5306764512","pt":1646105542109,"mc":[{"id":"1.195395430","rc":[{"atb":[[1.56,0]],"id":37265273},{"atl":[[4.3,0]],"id":37265273}],"con":true,"img":false}]}
{"op":"mcm","clk":"5306764513","pt":1646105542210,"mc":[{"id":"1.195395430","rc":[{"atb":[[1.49,83.74]],"id":37265273},{"atl":[[5,10.51]],"id":37265273}],"con":true,"img":false}]}
{"op":"mcm","clk":"5306765472","pt":1646105584292,"mc":[{"id":"1.195395430","rc":[{"atb":[[3.1,0]],"id":36104895},{"atb":[[1.51,0]],"id":38206580},{"atb":[[3.6,0]],"id":27701417},{"atb":[[2.46,0]],"id":38206560}],"con":true,"img":false}]}
{"op":"mcm","clk":"5306765475","pt":1646105584394,"mc":[{"id":"1.195395430","rc":[{"atb":[[3.2,20.61]],"id":36104895},{"atb":[[1.56,87.11]],"id":38206580},{"atb":[[3.85,14.39]],"id":27701417},{"atb":[[2.52,29.64]],"id":38206560}],"con":true,"img":false}]}
{"op":"mcm","clk":"5306780904","pt":1646106089438,"mc":[{"id":"1.195395430","rc":[{"atb":[[2.3,0],[2.2,0],[2.1,0]],"id":39520250},{"atl":[[5.6,0],[7.2,0],[9.2,0]],"id":39520250},{"atb":[[1.6,0],[1.7,0],[1.65,0]],"id":37265273},{"atl":[[3.2,0],[3.7,0],[4.4,0]],"id":37265273},{"spn":3.1,"spf":"NaN","id":37265273},{"atb":[[2.86,0],[3.15,0],[2.96,0]],"id":36104895},{"atl":[[16,0],[11,0],[8.4,0]],"id":36104895},{"spn":9.35,"spf":"NaN","id":36104895},{"atb":[[1.45,0],[1.55,0],[1.5,0]],"id":38206580},{"atl":[[2.82,0],[3.55,0],[3.05,0]],"id":38206580},{"atb":[[4.1,0],[3.8,0],[3.55,0]],"id":27701417},{"atl":[[19.5,0],[14.5,0],[29,0]],"id":27701417},{"atb":[[2.4,0],[2.5,0],[2.3,0]],"id":38206560},{"atl":[[8,0],[10,0],[6,0]],"id":38206560},{"spn":6.51,"spf":"NaN","id":38206560},{"atb":[[1.8,0],[1.7,0],[1.75,0]],"id":41762283},{"atl":[[3.6,0],[5.2,0],[4.2,0]],"id":41762283},{"atb":[[1.01,0]],"id":40494181},{"atl":[[1.97,0],[2.14,0],[2.34,0]],"id":40494181}],"con":true,"img":false}]}
{"op":"mcm","clk":"5306780976","pt":1646106092152,"mc":[{"id":"1.195395430","rc":[{"atb":[[2.3,46.19],[2.2,100.1],[2.1,109.2]],"id":39520250},{"atl":[[5.6,0.11],[7.2,0.08],[9.2,0.53]],"id":39520250},{"atb":[[1.6,200.2],[1.7,85.8],[1.65,184.8]],"id":37265273},{"atl":[[3.2,0.24],[3.7,0.2],[4.4,1.27]],"id":37265273},{"atb":[[2.86,64.57],[3.15,27.93],[2.96,61.28]],"id":36104895},{"atl":[[16,0.28],[11,0.05],[8.4,0.07]],"id":36104895},{"atb":[[1.45,266.93],[1.55,109.2],[1.5,240.24]],"id":38206580},{"atl":[[2.82,0.29],[3.55,1.69],[3.05,0.26]],"id":38206580},{"atb":[[4.1,19.37],[3.8,42.9],[3.55,47.1]],"id":27701417},{"atl":[[19.5,0.02],[14.5,0.03],[29,0.15]],"id":27701417},{"atb":[[2.4,85.8],[2.5,40.04],[2.3,92.4]],"id":38206560},{"atl":[[8,0.07],[10,0.48],[6,0.1]],"id":38206560},{"atb":[[1.8,75.07],[1.7,171.6],[1.75,160.16]],"id":41762283},{"atl":[[3.6,0.2],[5.2,1.02],[4.2,0.16]],"id":41762283},{"atb":[[1.01,30030.84]],"id":40494181},{"atl":[[1.97,0.55],[2.14,0.47],[2.34,3.23]],"id":40494181}],"con":true,"img":false}]}
{"op":"mcm","clk":"5306781067","pt":1646106094919,"mc":[{"id":"1.195395430","rc":[{"atb":[[1.9,108.21]],"id":39520250},{"atb":[[1.87,108.21]],"id":38206580},{"atb":[[1.9,108.21]],"id":41762283},{"atb":[[1.04,108.21]],"id":40494181}],"con":true,"img":false}]}
{"op":"mcm","clk":"5306781351","pt":1646106105152,"mc":[{"id":"1.195395430","rc":[{"atb":[[3.2,0]],"id":36104895}],"con":true,"img":false}]}
{"op":"mcm","clk":"5306781353","pt":1646106105254,"mc":[{"id":"1.195395430","rc":[{"atb":[[3.1,20.61]],"id":36104895}],"con":true,"img":false}]}
{"op":"mcm","clk":"5306782694","pt":1646106142208,"mc":[{"id":"1.195395430","rc":[{"atb":[[1.88,0]],"id":39520250},{"atb":[[1.6,0]],"id":38206580}],"con":true,"img":false}]}
{"op":"mcm","clk":"5306782697","pt":1646106142310,"mc":[{"id":"1.195395430","rc":[{"atb":[[1.91,47.61]],"id":39520250},{"atb":[[1.65,72.14]],"id":38206580}],"con":true,"img":false}]}
{"op":"mcm","clk":"5306782787","pt":1646106144508,"mc":[{"id":"1.195395430","rc":[{"atb":[[1.87,0]],"id":38206580}],"con":true,"img":false}]}
{"op":"mcm","clk":"5306782792","pt":1646106144608,"mc":[{"id":"1.195395430","rc":[{"atb":[[1.77,108.21]],"id":38206580}],"con":true,"img":false}]}
{"op":"mcm","clk":"5306782908","pt":1646106148036,"mc":[{"id":"1.195395430","rc":[{"atb":[[1.77,0]],"id":38206580},{"atb":[[1.9,0]],"id":41762283}],"con":true,"img":false}]}
{"op":"mcm","clk":"5306782916","pt":1646106148189,"mc":[{"id":"1.195395430","rc":[{"atb":[[1.9,108.21]],"id":38206580},{"atb":[[1.8,183.29]],"id":41762283}],"con":true,"img":false}]}
{"op":"mcm","clk":"5306783170","pt":1646106155706,"mc":[{"id":"1.195395430","rc":[{"spn":3.95,"spf":"NaN","id":39520250},{"spn":2.45,"spf":"NaN","id":37265273},{"spn":5.77,"spf":"NaN","id":36104895},{"spn":2.36,"spf":"NaN","id":38206580},{"spn":9.3,"spf":"NaN","id":27701417},{"spn":4.26,"spf":"NaN","id":38206560},{"atb":[[1.8,75.07]],"id":41762283},{"spn":2.7,"spf":"NaN","id":41762283}],"con":true,"img":false}]}
{"op":"mcm","clk":"5306783174","pt":1646106155808,"mc":[{"id":"1.195395430","rc":[{"atb":[[1.72,108.21]],"id":41762283}],"con":true,"img":false}]}
{"op":"mcm","clk":"5306783601","pt":1646106166723,"mc":[{"id":"1.195395430","rc":[{"atb":[[1.9,0]],"id":38206580}],"con":true,"img":false}]}
{"op":"mcm","clk":"5306783609","pt":1646106166824,"mc":[{"id":"1.195395430","rc":[{"atb":[[1.82,108.21]],"id":38206580}],"con":true,"img":false}]}
{"op":"mcm","clk":"5306783617","pt":1646106167029,"mc":[{"id":"1.195395430","rc":[{"atb":[[1.58,64.99]],"id":41762283}],"con":true,"img":false}]}
{"op":"mcm","clk":"5306783628","pt":1646106167232,"mc":[{"id":"1.195395430","rc":[{"atb":[[1.71,0]],"id":41762283}],"con":true,"img":false}]}
{"op":"mcm","clk":"5306784139","pt":1646106181270,"mc":[{"id":"1.195395430","rc":[{"atb":[[2.22,0]],"id":39520250},{"atb":[[1.07,0]],"id":40494181}],"con":true,"img":false}]}
{"op":"mcm","clk":"5306784141","pt":1646106181324,"mc":[{"id":"1.195395430","rc":[{"atb":[[2.32,40.83]],"id":39520250},{"atb":[[1.08,104.62]],"id":40494181}],"con":true,"img":false}]}
{"op":"mcm","clk":"5306784162","pt":1646106182241,"mc":[{"id":"1.195395430","rc":[{"atb":[[3.1,0]],"id":36104895},{"atb":[[1.65,0]],"id":38206580},{"atb":[[4,0]],"id":27701417}],"con":true,"img":false}]}
{"op":"mcm","clk":"5306784166","pt":1646106182343,"mc":[{"id":"1.195395430","rc":[{"atb":[[3.4,20.61]],"id":36104895},{"atb":[[1.83,72.14]],"id":38206580},{"atb":[[4.7,14.43]],"id":27701417}],"con":true,"img":false}]}
{"op":"mcm","clk":"5306784965","pt":1646106207672,"mc":[{"id":"1.195395430","rc":[{"atb":[[1.07,561.71]],"id":40494181}],"con":true,"img":false}]}
{"op":"mcm","clk":"5306784968","pt":1646106207775,"mc":[{"id":"1.195395430","rc":[{"atb":[[1.05,0]],"id":40494181}],"con":true,"img":false}]}
{"op":"mcm","clk":"5306785553","pt":1646106226914,"mc":[{"id":"1.195395430","rc":[{"spn":3.96,"spf":"NaN","id":39520250},{"spn":5.9,"spf":"NaN","id":36104895},{"spn":2.32,"spf":"NaN","id":38206580},{"spn":9.6,"spf":"NaN","id":27701417},{"atb":[[1.58,0],[1.71,53.09]],"id":41762283},{"spn":1.14,"spf":"NaN","id":40494181}],"con":true,"img":false}]}
{"op":"mcm","clk":"5306786013","pt":1646106241345,"mc":[{"id":"1.195395430","rc":[{"atb":[[1.56,67.31],[1.71,0]],"id":41762283}],"con":true,"img":false}]}
{"op":"mcm","clk":"5306786352","pt":1646106251738,"mc":[{"id":"1.195395430","rc":[{"atb":[[2.32,0]],"id":39520250},{"atl":[[1.45,0]],"id":40494181}],"con":true,"img":false}]}
{"op":"mcm","clk":"5306786358","pt":1646106251840,"mc":[{"id":"1.195395430","rc":[{"atb":[[2.22,40.83]],"id":39520250},{"atl":[[1.48,43.28]],"id":40494181}],"con":true,"img":false}]}
{"op":"mcm","clk":"5306786874","pt":1646106267957,"mc":[{"id":"1.195395430","rc":[{"atb":[[1.08,0]],"id":40494181}],"con":true,"img":false}]}
{"op":"mcm","clk":"5306786876","pt":1646106268059,"mc":[{"id":"1.195395430","rc":[{"atb":[[1.09,104.62]],"id":40494181}],"con":true,"img":false}]}
{"op":"mcm","clk":"5306786899","pt":1646106269079,"mc":[{"id":"1.195395430","rc":[{"atl":[[10.5,0]],"id":38206560},{"atl":[[5.3,0]],"id":41762283}],"con":true,"img":false}]}
{"op":"mcm","clk":"5306786903","pt":1646106269138,"mc":[{"id":"1.195395430","rc":[{"atl":[[9.4,4.55]],"id":38206560},{"atl":[[4.9,10.06]],"id":41762283}],"con":true,"img":false}]}
{"op":"mcm","clk":"5306787195","pt":1646106279065,"mc":[{"id":"1.195395430","rc":[{"atb":[[1.81,0]],"id":41762283}],"con":true,"img":false}]}
{"op":"mcm","clk":"5306787199","pt":1646106279170,"mc":[{"id":"1.195395430","rc":[{"atb":[[1.76,60.97]],"id":41762283}],"con":true,"img":false}]}
{"op":"mcm","clk":"5306787812","pt":1646106297799,"mc":[{"id":"1.195395430","rc":[{"spn":3.95,"spf":"NaN","id":39520250},{"atb":[[1.49,0],[1.61,67.26]],"id":37265273},{"spn":2.7,"spf":"NaN","id":41762283},{"spn":1.15,"spf":"NaN","id":40494181}],"con":true,"img":false}]}
{"op":"mcm","clk":"5306788588","pt":1646106324024,"mc":[{"id":"1.195395430","rc":[{"atb":[[2.22,0]],"id":39520250}],"con":true,"img":false}]}
{"op":"mcm","clk":"5306788590","pt":1646106324127,"mc":[{"id":"1.195395430","rc":[{"atb":[[2.32,40.83]],"id":39520250}],"con":true,"img":false}]}
{"op":"mcm","clk":"5306788645","pt":1646106326361,"mc":[{"id":"1.195395430","rc":[{"atb":[[1.76,0]],"id":41762283}],"con":true,"img":false}]}
{"op":"mcm","clk":"5306788651","pt":1646106326454,"mc":[{"id":"1.195395430","rc":[{"atb":[[1.81,60.97]],"id":41762283}],"con":true,"img":false}]}
{"op":"mcm","clk":"5306805304","pt":1646106843949,"mc":[{"id":"1.195395430","rc":[{"spn":3.96,"spf":"NaN","id":39520250},{"atl":[[15.5,0]],"id":36104895},{"spn":2.7,"spf":"NaN","id":41762283}],"con":true,"img":false}]}
{"op":"mcm","clk":"5306805307","pt":1646106844048,"mc":[{"id":"1.195395430","rc":[{"atl":[[14,2.98]],"id":36104895}],"con":true,"img":false}]}
{"op":"mcm","clk":"5306806528","pt":1646106878768,"mc":[{"id":"1.195395430","rc":[{"atl":[[17,0]],"id":36104895}],"con":true,"img":false}]}
{"op":"mcm","clk":"5306806531","pt":1646106878869,"mc":[{"id":"1.195395430","rc":[{"atl":[[15,2.7]],"id":36104895}],"con":true,"img":false}]}
{"op":"mcm","clk":"5306812041","pt":1646107026812,"mc":[{"id":"1.195395430","rc":[{"atb":[[2.34,1.66]],"id":39520250},{"spn":3.97,"spf":"NaN","id":39520250},{"atb":[[3.45,1.66]],"id":36104895},{"spn":5.92,"spf":"NaN","id":36104895},{"atb":[[4.8,1.66]],"id":27701417},{"spn":9.65,"spf":"NaN","id":27701417},{"atb":[[2.54,1.66]],"id":38206560},{"spn":4.27,"spf":"NaN","id":38206560}],"con":true,"img":false}]}
{"op":"mcm","clk":"5306818176","pt":1646107187861,"mc":[{"id":"1.195395430","rc":[{"atb":[[1.87,9.59]],"id":38206580},{"spn":2.34,"spf":"NaN","id":38206580}],"con":true,"img":false}]}
{"op":"mcm","clk":"5306818179","pt":1646107187962,"mc":[{"id":"1.195395430","rc":[{"atb":[[1.85,9.81]],"id":41762283}],"con":true,"img":false}]}
{"op":"mcm","clk":"5306818187","pt":1646107188068,"mc":[{"id":"1.195395430","rc":[{"atb":[[2.38,6.05]],"id":39520250}],"con":true,"img":false}]}
{"op":"mcm","clk":"5306818193","pt":1646107188168,"mc":[{"id":"1.195395430","rc":[{"atb":[[3.2,3.79]],"id":36104895}],"con":true,"img":false}]}
{"op":"mcm","clk":"5306818197","pt":1646107188272,"mc":[{"id":"1.195395430","rc":[{"atb":[[1.75,11.12]],"id":37265273}],"con":true,"img":false}]}
{"op":"mcm","clk":"5306818210","pt":1646107188428,"mc":[{"id":"1.195395430","rc":[{"atb":[[2.56,5.35]],"id":38206560}],"con":true,"img":false}]}
{"op":"mcm","clk":"5306818347","pt":1646107190959,"mc":[{"id":"1.195395430","rc":[{"atb":[[2.34,0]],"id":39520250},{"atb":[[2.54,0]],"id":38206560}],"con":true,"img":false}]}
{"op":"mcm","clk":"5306818359","pt":1646107191165,"mc":[{"id":"1.195395430","rc":[{"atb":[[2.4,1.66]],"id":39520250},{"atb":[[2.58,1.66]],"id":38206560}],"con":true,"img":false}]}
{"op":"mcm","clk":"5306818677","pt":1646107197640,"mc":[{"id":"1.195395430","rc":[{"atb":[[2.38,11.45]],"id":39520250},{"atb":[[1.75,21.06]],"id":37265273},{"atb":[[3.2,7.19]],"id":36104895},{"atb":[[1.87,18.15]],"id":38206580},{"atb":[[2.58,6.38]],"id":38206560},{"atb":[[1.85,18.58]],"id":41762283}],"con":true,"img":false}]}
{"op":"mcm","clk":"5306821308","pt":1646107266984,"mc":[{"id":"1.195395430","marketDefinition":{"bspMarket":true,"turnInPlayEnabled":false,"persistenceEnabled":false,"marketBaseRate":7.0,"eventId":"31270458","eventTypeId":"4339","numberOfWinners":3,"bettingType":"ODDS","marketType":"PLACE","marketTime":"2022-03-01T05:32:00.000Z","suspendTime":"2022-03-01T05:32:00.000Z","bspReconciled":false,"complete":true,"inPlay":false,"crossMatching":true,"runnersVoidable":false,"numberOfActiveRunners":8,"betDelay":0,"status":"OPEN","runners":[{"status":"ACTIVE","sortPriority":1,"id":40494181,"name":"1. Loch And Loaded"},{"status":"ACTIVE","sortPriority":2,"id":38206580,"name":"2. Buckle Up Wilder"},{"status":"ACTIVE","sortPriority":3,"id":38206560,"name":"3. Hiccup Amisha"},{"status":"ACTIVE","sortPriority":4,"id":36104895,"name":"4. Langley Roo"},{"status":"ACTIVE","sortPriority":5,"id":39520250,"name":"5. Rip On Bye"},{"status":"ACTIVE","sortPriority":6,"id":41762283,"name":"6. Gracies Joy"},{"status":"ACTIVE","sortPriority":7,"id":37265273,"name":"7. Just Mercy"},{"status":"ACTIVE","sortPriority":8,"id":27701417,"name":"8. Jalla General"}],"regulators":["MR_INT"],"venue":"Devonport","countryCode":"AU","discountAllowed":true,"timezone":"Australia/Sydney","openDate":"2022-03-01T02:00:00.000Z","version":4381118397,"name":"To Be Placed","eventName":"Devonport (AUS) 1st Mar"},"rc":[],"con":true,"img":false}]}
{"op":"mcm","clk":"5306822391","pt":1646107300416,"mc":[{"id":"1.195395430","rc":[{"atb":[[2.4,1.66],[2.32,40.81],[2.3,46.17],[2.38,11.46],[1.91,47.58],[1.9,108.15],[2.2,100.04],[2.1,109.13]],"id":39520250},{"atl":[[9.2,0.52],[8.2,5.4],[7.4,6.75]],"id":39520250},{"spn":4.0,"spf":"NaN","id":39520250},{"atb":[[1.6,200.08],[1.7,85.75],[1.75,21.07],[1.65,184.69],[1.71,60.93],[1.61,0]],"id":37265273},{"atl":[[4.5,12.36],[3.2,0.24],[5,10.51],[3.7,0.2],[4.4,1.27]],"id":37265273},{"spn":2.47,"spf":"NaN","id":37265273},{"atb":[[3.45,1.66],[3.2,7.19],[2.86,64.54],[3.4,20.6],[3.15,27.92],[2.98,24.87],[2.96,61.25]],"id":36104895},{"atl":[[16,0.28],[14,2.98],[15,2.7]],"id":36104895},{"atb":[[1.56,87.06],[1.83,72.1],[1.82,108.15],[1.45,266.78],[1.55,109.13],[1.5,240.1],[1.87,18.16]],"id":38206580},{"atl":[[2.82,0.29],[4.6,12.01],[5,10.81],[3.55,1.69],[3.05,0.26]],"id":38206580},{"atb":[[4.8,1.66],[3.85,14.38],[4.1,19.36],[3.8,42.87],[3.55,47.07],[4.7,14.42]],"id":27701417},{"atl":[[24,2.7],[26,2.7]],"id":27701417},{"atb":[[2.56,5.35],[2.4,85.75],[2.5,40.01],[2.3,92.34],[2.42,0],[2.52,57.2],[2.58,6.39]],"id":38206560},{"atl":[[10,0.48],[11,4.32],[9.4,4.55]],"id":38206560},{"spn":4.29,"spf":"NaN","id":38206560},{"atb":[[1.56,67.27],[1.8,75.03],[1.72,108.15],[1.81,60.93],[1.85,18.59],[1.7,171.5],[1.75,160.06]],"id":41762283},{"atl":[[3.6,0.2],[4.9,10.05],[5.2,1.02],[5.9,7.24]],"id":41762283},{"spn":2.72,"spf":"NaN","id":41762283},{"atb":[[1.01,30012.97],[1.09,104.56],[1.07,561.37],[1.04,108.15]],"id":40494181},{"atl":[[1.21,91.92],[1.97,0.55],[1.62,63.37],[1.48,43.26],[2.14,0.47],[2.34,3.22]],"id":40494181}],"con":true,"img":false}]}
{"op":"mcm","clk":"5306822396","pt":1646107300519,"mc":[{"id":"1.195395430","rc":[{"atb":[[1.66,67.22]],"id":37265273}],"con":true,"img":false}]}
{"op":"mcm","clk":"5306822419","pt":1646107301285,"mc":[{"id":"1.195395430","rc":[{"atb":[[3.2,26.66],[2.98,0]],"id":36104895}],"con":true,"img":false}]}
{"op":"mcm","clk":"5306822471","pt":1646107302823,"mc":[{"id":"1.195395430","rc":[{"atb":[[3.2,23.26]],"id":36104895}],"con":true,"img":false}]}
{"op":"mcm","clk":"5306822648","pt":1646107308798,"mc":[{"id":"1.195395430","rc":[{"atb":[[3.25,3.31]],"id":36104895}],"con":true,"img":false}]}
{"op":"mcm","clk":"5306822958","pt":1646107318750,"mc":[{"id":"1.195395430","rc":[{"atb":[[2.56,0]],"id":38206560}],"con":true,"img":false}]}
{"op":"mcm","clk":"5306823170","pt":1646107324842,"mc":[{"id":"1.195395430","rc":[{"atb":[[2.58,11.67]],"id":38206560}],"con":true,"img":false}]}
{"op":"mcm","clk":"5306836013","pt":1646107701411,"mc":[{"id":"1.195395430","rc":[{"atb":[[1.82,0]],"id":38206580}],"con":true,"img":false}]}
{"op":"mcm","clk":"5306836015","pt":1646107701513,"mc":[{"id":"1.195395430","rc":[{"atb":[[1.9,108.15]],"id":38206580}],"con":true,"img":false}]}
{"op":"mcm","clk":"5306836108","pt":1646107704836,"mc":[{"id":"1.195395430","rc":[{"atb":[[1.87,9.59]],"id":38206580}],"con":true,"img":false}]}
{"op":"mcm","clk":"5306836312","pt":1646107710770,"mc":[{"id":"1.195395430","rc":[{"atb":[[1.94,7.93]],"id":38206580}],"con":true,"img":false}]}
{"op":"mcm","clk":"5306836568","pt":1646107719053,"mc":[{"id":"1.195395430","rc":[{"atb":[[1.87,0]],"id":38206580}],"con":true,"img":false}]}
{"op":"mcm","clk":"5306836756","pt":1646107725147,"mc":[{"id":"1.195395430","rc":[{"atb":[[1.94,16.81]],"id":38206580}],"con":true,"img":false}]}
{"op":"mcm","clk":"5306836946","pt":1646107731743,"mc":[{"id":"1.195395430","rc":[{"atb":[[1.83,0],[1.91,47.53]],"id":38206580}],"con":true,"img":false}]}
{"op":"mcm","clk":"5306837069","pt":1646107734966,"mc":[{"id":"1.195395430","rc":[{"atb":[[1.94,8.88]],"id":38206580}],"con":true,"img":false}]}
{"op":"mcm","clk":"5306837252","pt":1646107740846,"mc":[{"id":"1.195395430","rc":[{"atb":[[1.95,7.85]],"id":38206580}],"con":true,"img":false}]}
{"op":"mcm","clk":"5306837549","pt":1646107749749,"mc":[{"id":"1.195395430","rc":[{"atb":[[1.94,0]],"id":38206580}],"con":true,"img":false}]}
{"op":"mcm","clk":"5306837773","pt":1646107755838,"mc":[{"id":"1.195395430","rc":[{"atb":[[1.95,16.64]],"id":38206580}],"con":true,"img":false}]}
{"op":"mcm","clk":"5306839859","pt":1646107815962,"mc":[{"id":"1.195395430","rc":[{"atb":[[1.9,0]],"id":39520250},{"spn":2.38,"spf":"NaN","id":38206580}],"con":true,"img":false}]}
{"op":"mcm","clk":"5306839861","pt":1646107816063,"mc":[{"id":"1.195395430","rc":[{"atb":[[1.9,108.15]],"id":38206560}],"con":true,"img":false}]}
{"op":"mcm","clk":"5306843992","pt":1646107959741,"mc":[{"id":"1.195395430","rc":[{"atb":[[1.72,23.18]],"id":37265273},{"atb":[[1.82,20.44]],"id":41762283}],"con":true,"img":false}]}
{"op":"mcm","clk":"5306843994","pt":1646107959844,"mc":[{"id":"1.195395430","rc":[{"atb":[[1.72,46.36]],"id":37265273},{"atb":[[1.82,40.89]],"id":41762283}],"con":true,"img":false}]}
{"op":"mcm","clk":"5306844002","pt":1646107960354,"mc":[{"id":"1.195395430","rc":[{"atb":[[1.75,11.12]],"id":37265273},{"atb":[[1.85,9.81]],"id":41762283}],"con":true,"img":false}]}
{"op":"mcm","clk":"5306844117","pt":1646107966240,"mc":[{"id":"1.195395430","rc":[{"atb":[[1.76,9.81]],"id":37265273},{"atb":[[1.86,8.67]],"id":41762283}],"con":true,"img":false}]}
{"op":"mcm","clk":"5306844189","pt":1646107969771,"mc":[{"id":"1.195395430","rc":[{"atb":[[1.72,23.18]],"id":37265273},{"atb":[[1.82,20.44]],"id":41762283}],"con":true,"img":false}]}
{"op":"mcm","clk":"5306844243","pt":1646107973000,"mc":[{"id":"1.195395430","rc":[{"atb":[[1.76,0]],"id":37265273},{"atb":[[1.86,0]],"id":41762283}],"con":true,"img":false}]}
{"op":"mcm","clk":"5306844249","pt":1646107973152,"mc":[{"id":"1.195395430","rc":[{"atb":[[1.72,0]],"id":37265273},{"atb":[[1.82,0]],"id":41762283}],"con":true,"img":false}]}
{"op":"mcm","clk":"5306844322","pt":1646107976783,"mc":[{"id":"1.195395430","rc":[{"atb":[[1.76,7.78]],"id":37265273},{"atb":[[1.86,6.87]],"id":41762283}],"con":true,"img":false}]}
{"op":"mcm","clk":"5306844336","pt":1646107977500,"mc":[{"id":"1.195395430","rc":[{"atb":[[2.3,0],[2.2,0],[2.1,0]],"id":39520250},{"atl":[[5.6,0],[7.2,0],[9.2,0]],"id":39520250},{"atb":[[1.6,0],[1.7,0],[1.65,0]],"id":37265273},{"atl":[[3.2,0],[3.7,0],[4.4,0]],"id":37265273},{"atb":[[2.86,0],[3.15,0],[2.96,0]],"id":36104895},{"atl":[[16,0],[11,0],[8.4,0]],"id":36104895},{"atb":[[1.45,0],[1.55,0],[1.5,0]],"id":38206580},{"atl":[[2.82,0],[3.55,0],[3.05,0]],"id":38206580},{"atb":[[4.1,0],[3.8,0],[3.55,0]],"id":27701417},{"atl":[[19.5,0],[14.5,0],[29,0]],"id":27701417},{"atb":[[2.4,0],[2.5,0],[2.3,0]],"id":38206560},{"atl":[[8,0],[10,0],[6,0]],"id":38206560},{"atb":[[1.8,0],[1.7,0],[1.75,0]],"id":41762283},{"atl":[[3.6,0],[5.2,0],[4.2,0]],"id":41762283},{"atb":[[1.01,0]],"id":40494181},{"atl":[[1.97,0],[2.14,0],[2.34,0]],"id":40494181}],"con":true,"img":false}]}
{"op":"mcm","clk":"5306844343","pt":1646107977964,"mc":[{"id":"1.195395430","rc":[{"atb":[[2.82,23.79],[3.2,3.79]],"id":36104895},{"atb":[[2.24,33.52],[2.52,29.62]],"id":38206560}],"con":true,"img":false}]}
{"op":"mcm","clk":"5306844345","pt":1646107978066,"mc":[{"id":"1.195395430","rc":[{"atb":[[2.32,0]],"id":39520250},{"atb":[[1.66,0]],"id":37265273}],"con":true,"img":false}]}
{"op":"mcm","clk":"5306844346","pt":1646107978168,"mc":[{"id":"1.195395430","rc":[{"atb":[[2.08,40.81]],"id":39520250},{"atb":[[1.54,67.22]],"id":37265273}],"con":true,"img":false}]}
{"op":"mcm","clk":"5306844349","pt":1646107978373,"mc":[{"id":"1.195395430","rc":[{"atb":[[2.38,6.05]],"id":39520250},{"atb":[[1.75,21.07]],"id":37265273},{"atb":[[3.25,0]],"id":36104895},{"atb":[[1.85,18.59]],"id":41762283}],"con":true,"img":false}]}
{"op":"mcm","clk":"5306844374","pt":1646107980113,"mc":[{"id":"1.195395430","rc":[{"atb":[[1.72,12.24]],"id":37265273},{"atb":[[1.82,10.8]],"id":41762283}],"con":true,"img":false}]}
{"op":"mcm","clk":"5306844376","pt":1646107980165,"mc":[{"id":"1.195395430","rc":[{"atb":[[2.3,46.42],[2.2,100.58],[2.1,109.72]],"id":39520250},{"atl":[[5.6,2.61],[7.2,1.93],[18,2.82],[9.2,2.92],[13,2]],"id":39520250},{"atb":[[1.6,201.16],[1.7,86.21],[1.65,185.69]],"id":37265273},{"atl":[[3.2,5.45],[3.7,4.44],[6.8,8.27],[4.4,7.06],[5.4,5.45]],"id":37265273},{"atb":[[2.86,64.89],[3.15,28.07],[2.96,61.58]],"id":36104895},{"atl":[[16,1.6],[34,1.45],[11,1.2],[22,1.14],[8.4,1.62]],"id":36104895},{"atb":[[1.45,268.22],[1.55,109.72],[1.5,241.4]],"id":38206580},{"atl":[[2.82,6.59],[5.1,11.71],[4.1,7.74],[3.55,9.41],[3.05,5.85]],"id":38206580},{"atb":[[4.1,19.46],[3.8,43.1],[3.55,47.33]],"id":27701417},{"atl":[[19.5,0.64],[95,0.5],[48,0.5],[14.5,0.88],[29,0.85]],"id":27701417},{"atb":[[2.4,86.21],[2.5,40.23],[2.3,92.84]],"id":38206560},{"atl":[[8,1.71],[10,2.66],[20,2.52],[6,2.4],[15,1.71]],"id":38206560},{"atb":[[1.8,75.43],[1.7,172.43],[1.75,160.93]],"id":41762283},{"atl":[[3.6,4.61],[6.4,4.44],[5.2,5.71],[4.2,3.75],[8.4,6.48]],"id":41762283},{"atb":[[1.01,30175.21]],"id":40494181},{"atl":[[2.54,15.59],[2.74,27.59],[1.97,12.37],[2.14,10.52],[2.34,17.91]],"id":40494181}],"con":true,"img":false}]}
{"op":"mcm","clk":"5306844478","pt":1646107986195,"mc":[{"id":"1.195395430","rc":[{"atb":[[1.72,0]],"id":37265273},{"atb":[[1.82,0]],"id":41762283}],"con":true,"img":false}]}
{"op":"mcm","clk":"5306844481","pt":1646107986400,"mc":[{"id":"1.195395430","rc":[{"atb":[[1.76,0]],"id":37265273},{"atb":[[1.86,0]],"id":41762283}],"con":true,"img":false}]}
{"op":"mcm","clk":"5306844494","pt":1646107987320,"mc":[{"id":"1.195395430","rc":[{"atb":[[2.36,5.48]],"id":39520250},{"atb":[[3.2,7.19]],"id":36104895}],"con":true,"img":false}]}
{"op":"mcm","clk":"5306844591","pt":1646107992890,"mc":[{"id":"1.195395430","rc":[{"atb":[[1.72,23.18]],"id":37265273},{"atb":[[1.82,20.44]],"id":41762283}],"con":true,"img":false}]}
{"op":"mcm","clk":"5306844608","pt":1646107993912,"mc":[{"id":"1.195395430","rc":[{"atb":[[1.72,46.36]],"id":37265273},{"atb":[[1.82,40.89]],"id":41762283}],"con":true,"img":false}]}
{"op":"mcm","clk":"5306844633","pt":1646107995088,"mc":[{"id":"1.195395430","rc":[{"atb":[[2.38,0]],"id":39520250},{"atb":[[1.75,9.94]],"id":37265273},{"atb":[[2.58,6.39]],"id":38206560}],"con":true,"img":false}]}
{"op":"mcm","clk":"5306844652","pt":1646107996313,"mc":[{"id":"1.195395430","rc":[{"atb":[[1.75,0]],"id":37265273},{"atb":[[1.85,9.81]],"id":41762283}],"con":true,"img":false}]}
{"op":"mcm","clk":"5306844693","pt":1646107998213,"mc":[{"id":"1.195395430","rc":[{"atb":[[2.4,0]],"id":39520250}],"con":true,"img":false}]}
{"op":"mcm","clk":"5306844697","pt":1646107998318,"mc":[{"id":"1.195395430","rc":[{"atb":[[2.38,1.66]],"id":39520250}],"con":true,"img":false}]}
{"op":"mcm","clk":"5306844747","pt":1646108000727,"mc":[{"id":"1.195395430","rc":[{"atb":[[2.56,5.35]],"id":38206560}],"con":true,"img":false}]}
{"op":"mcm","clk":"5306844750","pt":1646108000933,"mc":[{"id":"1.195395430","rc":[{"atb":[[2.36,11.61]],"id":39520250}],"con":true,"img":false}]}
{"op":"mcm","clk":"5306844793","pt":1646108002219,"mc":[{"id":"1.195395430","rc":[{"atb":[[1.76,9.81]],"id":37265273},{"atb":[[1.86,8.67]],"id":41762283}],"con":true,"img":false}]}
{"op":"mcm","clk":"5306844876","pt":1646108005649,"mc":[{"id":"1.195395430","rc":[{"atb":[[1.76,20.8]],"id":37265273}],"con":true,"img":false}]}
{"op":"mcm","clk":"5306844893","pt":1646108006416,"mc":[{"id":"1.195395430","rc":[{"atb":[[1.82,20.44]],"id":41762283}],"con":true,"img":false}]}
{"op":"mcm","clk":"5306844924","pt":1646108008463,"mc":[{"id":"1.195395430","rc":[{"atb":[[1.82,0],[1.86,0]],"id":41762283}],"con":true,"img":false}]}
{"op":"mcm","clk":"5306845001","pt":1646108012556,"mc":[{"id":"1.195395430","rc":[{"atb":[[2.08,0]],"id":39520250}],"con":true,"img":false}]}
{"op":"mcm","clk":"5306845007","pt":1646108012658,"mc":[{"id":"1.195395430","rc":[{"atb":[[2.32,40.81]],"id":39520250}],"con":true,"img":false}]}
{"op":"mcm","clk":"5306845044","pt":1646108013833,"mc":[{"id":"1.195395430","rc":[{"atb":[[1.82,10.8]],"id":41762283}],"con":true,"img":false}]}
{"op":"mcm","clk":"5306845049","pt":1646108014344,"mc":[{"id":"1.195395430","rc":[{"atb":[[2.36,6.13]],"id":39520250},{"atb":[[1.85,18.59]],"id":41762283}],"con":true,"img":false}]}
{"op":"mcm","clk":"5306845067","pt":1646108015569,"mc":[{"id":"1.195395430","rc":[{"atb":[[1.71,0]],"id":37265273},{"atb":[[1.82,21.6]],"id":41762283}],"con":true,"img":false}]}
{"op":"mcm","clk":"5306845070","pt":1646108015672,"mc":[{"id":"1.195395430","rc":[{"atb":[[1.73,60.93]],"id":37265273}],"con":true,"img":false}]}
{"op":"mcm","clk":"5306845100","pt":1646108017356,"mc":[{"id":"1.195395430","rc":[{"atb":[[1.76,10.98]],"id":37265273}],"con":true,"img":false}]}
{"op":"mcm","clk":"5306845142","pt":1646108020264,"mc":[{"id":"1.195395430","rc":[{"spn":3.99,"spf":"NaN","id":39520250},{"atb":[[1.72,23.18]],"id":37265273},{"spn":2.48,"spf":"NaN","id":37265273}],"con":true,"img":false}]}
{"op":"mcm","clk":"5306845143","pt":1646108020366,"mc":[{"id":"1.195395430","rc":[{"atb":[[2.38,7.07]],"id":39520250}],"con":true,"img":false}]}
{"op":"mcm","clk":"5306845153","pt":1646108021436,"mc":[{"id":"1.195395430","rc":[{"atb":[[1.54,0]],"id":37265273}],"con":true,"img":false}]}
{"op":"mcm","clk":"5306845156","pt":1646108021538,"mc":[{"id":"1.195395430","rc":[{"atb":[[1.66,67.22]],"id":37265273}],"con":true,"img":false}]}
{"op":"mcm","clk":"5306845169","pt":1646108022254,"mc":[{"id":"1.195395430","rc":[{"atb":[[1.72,0]],"id":37265273}],"con":true,"img":false}]}
{"op":"mcm","clk":"5306845172","pt":1646108022458,"mc":[{"id":"1.195395430","rc":[{"atb":[[2.82,0],[3.2,26.66]],"id":36104895},{"atb":[[2.24,0],[2.52,57.2]],"id":38206560}],"con":true,"img":false}]}
{"op":"mcm","clk":"5306845204","pt":1646108023453,"mc":[{"id":"1.195395430","rc":[{"atb":[[1.77,9.68]],"id":37265273}],"con":true,"img":false}]}
{"op":"mcm","clk":"5306845230","pt":1646108023555,"mc":[{"id":"1.195395430","rc":[{"atb":[[3.2,23.26]],"id":36104895}],"con":true,"img":false}]}
{"op":"mcm","clk":"5306845320","pt":1646108026571,"mc":[{"id":"1.195395430","rc":[{"atb":[[1.71,14.28]],"id":37265273}],"con":true,"img":false}]}
{"op":"mcm","clk":"5306845368","pt":1646108028664,"mc":[{"id":"1.195395430","rc":[{"atb":[[1.74,10.65]],"id":37265273}],"con":true,"img":false}]}
{"op":"mcm","clk":"5306845385","pt":1646108029379,"mc":[{"id":"1.195395430","rc":[{"atb":[[3.25,3.31]],"id":36104895}],"con":true,"img":false}]}
{"op":"mcm","clk":"5306845392","pt":1646108030042,"mc":[{"id":"1.195395430","rc":[{"atb":[[2.36,0]],"id":39520250},{"atb":[[1.76,0]],"id":37265273}],"con":true,"img":false}]}
{"op":"mcm","clk":"5306845435","pt":1646108032648,"mc":[{"id":"1.195395430","rc":[{"atb":[[1.71,0]],"id":37265273}],"con":true,"img":false}]}
{"op":"mcm","clk":"5306845475","pt":1646108036077,"mc":[{"id":"1.195395430","rc":[{"atb":[[2.38,13.13]],"id":39520250}],"con":true,"img":false}]}
{"op":"mcm","clk":"5306845481","pt":1646108036281,"mc":[{"id":"1.195395430","rc":[{"atb":[[2.56,0]],"id":38206560}],"con":true,"img":false}]}
{"op":"mcm","clk":"5306845483","pt":1646108036485,"mc":[{"id":"1.195395430","rc":[{"atb":[[1.77,20.53]],"id":37265273}],"con":true,"img":false}]}
{"op":"mcm","clk":"5306845549","pt":1646108039397,"mc":[{"id":"1.195395430","rc":[{"atb":[[1.78,6.78]],"id":37265273}],"con":true,"img":false}]}
{"op":"mcm","clk":"5306845635","pt":1646108042881,"mc":[{"id":"1.195395430","rc":[{"atb":[[2.58,11.67]],"id":38206560}],"con":true,"img":false}]}
{"op":"mcm","clk":"5306845675","pt":1646108044316,"mc":[{"id":"1.195395430","rc":[{"atb":[[1.74,0]],"id":37265273}],"con":true,"img":false}]}
{"op":"mcm","clk":"5306845761","pt":1646108048815,"mc":[{"id":"1.195395430","rc":[{"atb":[[1.78,0]],"id":37265273}],"con":true,"img":false}]}
{"op":"mcm","clk":"5306845821","pt":1646108051016,"mc":[{"id":"1.195395430","rc":[{"atb":[[1.74,8.13]],"id":37265273}],"con":true,"img":false}]}
{"op":"mcm","clk":"5306845921","pt":1646108056431,"mc":[{"id":"1.195395430","rc":[{"atb":[[1.78,14.37]],"id":37265273}],"con":true,"img":false}]}
{"op":"mcm","clk":"5306846020","pt":1646108060126,"mc":[{"id":"1.195395430","rc":[{"atb":[[1.74,0]],"id":37265273}],"con":true,"img":false}]}
{"op":"mcm","clk":"5306846138","pt":1646108065899,"mc":[{"id":"1.195395430","rc":[{"atb":[[1.78,0]],"id":37265273}],"con":true,"img":false}]}
{"op":"mcm","clk":"5306846151","pt":1646108066617,"mc":[{"id":"1.195395430","rc":[{"atb":[[1.74,17.24]],"id":37265273}],"con":true,"img":false}]}
{"op":"mcm","clk":"5306846259","pt":1646108072546,"mc":[{"id":"1.195395430","rc":[{"atb":[[1.78,14.37]],"id":37265273}],"con":true,"img":false}]}
{"op":"mcm","clk":"5306846322","pt":1646108075608,"mc":[{"id":"1.195395430","rc":[{"atb":[[1.74,0]],"id":37265273}],"con":true,"img":false}]}
{"op":"mcm","clk":"5306846451","pt":1646108081949,"mc":[{"id":"1.195395430","rc":[{"atb":[[1.74,17.24]],"id":37265273},{"spn":2.49,"spf":"NaN","id":37265273}],"con":true,"img":false}]}
{"op":"mcm","clk":"5306846453","pt":1646108082051,"mc":[{"id":"1.195395430","rc":[{"atb":[[1.78,0]],"id":37265273}],"con":true,"img":false}]}
{"op":"mcm","clk":"5306846583","pt":1646108088143,"mc":[{"id":"1.195395430","rc":[{"atb":[[1.78,14.37]],"id":37265273}],"con":true,"img":false}]}
{"op":"mcm","clk":"5306846687","pt":1646108094582,"mc":[{"id":"1.195395430","rc":[{"atb":[[1.74,0]],"id":37265273}],"con":true,"img":false}]}
{"op":"mcm","clk":"5306846837","pt":1646108100161,"mc":[{"id":"1.195395430","rc":[{"atb":[[1.78,0]],"id":37265273}],"con":true,"img":false}]}
{"op":"mcm","clk":"5306846854","pt":1646108100779,"mc":[{"id":"1.195395430","rc":[{"atb":[[1.74,17.24]],"id":37265273}],"con":true,"img":false}]}
{"op":"mcm","clk":"5306847076","pt":1646108106666,"mc":[{"id":"1.195395430","rc":[{"atb":[[1.78,14.37]],"id":37265273}],"con":true,"img":false}]}
{"op":"mcm","clk":"5306847138","pt":1646108110103,"mc":[{"id":"1.195395430","rc":[{"atb":[[1.74,0]],"id":37265273}],"con":true,"img":false}]}
{"op":"mcm","clk":"5306847300","pt":1646108116411,"mc":[{"id":"1.195395430","rc":[{"atb":[[1.74,17.24]],"id":37265273}],"con":true,"img":false}]}
{"op":"mcm","clk":"5306847380","pt":1646108120099,"mc":[{"id":"1.195395430","rc":[{"atb":[[1.78,0]],"id":37265273}],"con":true,"img":false}]}
{"op":"mcm","clk":"5306847577","pt":1646108126816,"mc":[{"id":"1.195395430","rc":[{"atb":[[1.78,14.37]],"id":37265273}],"con":true,"img":false}]}
{"op":"mcm","clk":"5306865029","pt":1646108451947,"mc":[{"id":"1.195395430","rc":[{"atb":[[1.66,0]],"id":37265273},{"atb":[[2.52,29.62]],"id":38206560}],"con":true,"img":false}]}
{"op":"mcm","clk":"5306865033","pt":1646108452049,"mc":[{"id":"1.195395430","rc":[{"atb":[[1.61,67.22]],"id":37265273},{"atb":[[2.42,27.57]],"id":38206560}],"con":true,"img":false}]}
{"op":"mcm","clk":"5306865596","pt":1646108470789,"mc":[{"id":"1.195395430","rc":[{"atb":[[2.58,6.39]],"id":38206560}],"con":true,"img":false}]}
{"op":"mcm","clk":"5306865784","pt":1646108477518,"mc":[{"id":"1.195395430","rc":[{"atb":[[2.56,5.35]],"id":38206560}],"con":true,"img":false}]}
{"op":"mcm","clk":"5306866156","pt":1646108491813,"mc":[{"id":"1.195395430","rc":[{"atl":[[1.48,0]],"id":40494181}],"con":true,"img":false}]}
{"op":"mcm","clk":"5306866159","pt":1646108491915,"mc":[{"id":"1.195395430","rc":[{"atl":[[1.44,43.26]],"id":40494181}],"con":true,"img":false}]}
{"op":"mcm","clk":"5306867128","pt":1646108524169,"mc":[{"id":"1.195395430","rc":[{"atb":[[1.56,0]],"id":41762283}],"con":true,"img":false}]}
{"op":"mcm","clk":"5306867130","pt":1646108524271,"mc":[{"id":"1.195395430","rc":[{"atb":[[1.71,53.06]],"id":41762283}],"con":true,"img":false}]}
{"op":"mcm","clk":"5306868933","pt":1646108587574,"mc":[{"id":"1.195395430","rc":[{"atb":[[3.85,0],[4.2,11.01]],"id":27701417}],"con":true,"img":false}]}
{"op":"mcm","clk":"5306884614","pt":1646109180413,"mc":[{"id":"1.195395430","marketDefinition":{"bspMarket":true,"turnInPlayEnabled":false,"persistenceEnabled":false,"marketBaseRate":7.0,"eventId":"31270458","eventTypeId":"4339","numberOfWinners":3,"bettingType":"ODDS","marketType":"PLACE","marketTime":"2022-03-01T05:50:00.000Z","suspendTime":"2022-03-01T05:50:00.000Z","bspReconciled":false,"complete":true,"inPlay":false,"crossMatching":true,"runnersVoidable":false,"numberOfActiveRunners":8,"betDelay":0,"status":"OPEN","runners":[{"status":"ACTIVE","sortPriority":1,"id":40494181,"name":"1. Loch And Loaded"},{"status":"ACTIVE","sortPriority":2,"id":38206580,"name":"2. Buckle Up Wilder"},{"status":"ACTIVE","sortPriority":3,"id":38206560,"name":"3. Hiccup Amisha"},{"status":"ACTIVE","sortPriority":4,"id":36104895,"name":"4. Langley Roo"},{"status":"ACTIVE","sortPriority":5,"id":39520250,"name":"5. Rip On Bye"},{"status":"ACTIVE","sortPriority":6,"id":41762283,"name":"6. Gracies Joy"},{"status":"ACTIVE","sortPriority":7,"id":37265273,"name":"7. Just Mercy"},{"status":"ACTIVE","sortPriority":8,"id":27701417,"name":"8. Jalla General"}],"regulators":["MR_INT"],"venue":"Devonport","countryCode":"AU","discountAllowed":true,"timezone":"Australia/Sydney","openDate":"2022-03-01T02:00:00.000Z","version":4381128824,"name":"To Be Placed","eventName":"Devonport (AUS) 1st Mar"},"rc":[],"con":true,"img":false}]}
{"op":"mcm","clk":"5306884986","pt":1646109195711,"mc":[{"id":"1.195395430","rc":[{"atb":[[1.9,0]],"id":38206560}],"con":true,"img":false}]}
{"op":"mcm","clk":"5306884989","pt":1646109195814,"mc":[{"id":"1.195395430","rc":[{"atb":[[1.9,108.15]],"id":39520250}],"con":true,"img":false}]}
{"op":"mcm","clk":"5306885229","pt":1646109203394,"mc":[{"id":"1.195395430","rc":[{"atb":[[1.9,0]],"id":39520250}],"con":true,"img":false}]}
{"op":"mcm","clk":"5306885231","pt":1646109203495,"mc":[{"id":"1.195395430","rc":[{"atb":[[1.9,108.15]],"id":38206560}],"con":true,"img":false}]}
{"op":"mcm","clk":"5306885284","pt":1646109204696,"mc":[{"id":"1.195395430","rc":[{"atb":[[1.9,0]],"id":38206560}],"con":true,"img":false}]}
{"op":"mcm","clk":"5306885288","pt":1646109204799,"mc":[{"id":"1.195395430","rc":[{"atb":[[1.9,108.15]],"id":39520250}],"con":true,"img":false}]}
{"op":"mcm","clk":"5306885553","pt":1646109213846,"mc":[{"id":"1.195395430","rc":[{"atb":[[1.58,64.95],[1.71,0]],"id":41762283}],"con":true,"img":false}]}
{"op":"mcm","clk":"5306885816","pt":1646109222958,"mc":[{"id":"1.195395430","rc":[{"atb":[[1.9,0]],"id":39520250},{"atb":[[1.72,0]],"id":41762283}],"con":true,"img":false}]}
{"op":"mcm","clk":"5306885819","pt":1646109223060,"mc":[{"id":"1.195395430","rc":[{"atb":[[1.9,108.15]],"id":38206560},{"atb":[[1.65,108.15]],"id":41762283}],"con":true,"img":false}]}
{"op":"mcm","clk":"5306886249","pt":1646109236567,"mc":[{"id":"1.195395430","rc":[{"atb":[[1.05,785.92]],"id":40494181}],"con":true,"img":false}]}
{"op":"mcm","clk":"5306886253","pt":1646109236668,"mc":[{"id":"1.195395430","rc":[{"atb":[[3.2,3.79]],"id":36104895},{"atb":[[4.2,0]],"id":27701417},{"atb":[[2.42,0]],"id":38206560},{"atb":[[1.09,0],[1.07,0]],"id":40494181}],"con":true,"img":false}]}
{"op":"mcm","clk":"5306886257","pt":1646109236771,"mc":[{"id":"1.195395430","rc":[{"atb":[[2.88,19.46]],"id":36104895},{"atb":[[3.85,11.01]],"id":27701417},{"atb":[[2.32,27.57]],"id":38206560},{"atb":[[1.07,104.56]],"id":40494181}],"con":true,"img":false}]}
{"op":"mcm","clk":"5306886298","pt":1646109237542,"mc":[{"id":"1.195395430","rc":[{"atb":[[3.25,0]],"id":36104895}],"con":true,"img":false}]}
{"op":"mcm","clk":"5306886401","pt":1646109240557,"mc":[{"id":"1.195395430","rc":[{"atb":[[1.08,73.19]],"id":40494181}],"con":true,"img":false}]}
{"op":"mcm","clk":"5306886404","pt":1646109240659,"mc":[{"id":"1.195395430","rc":[{"atb":[[1.08,146.39]],"id":40494181}],"con":true,"img":false}]}
{"op":"mcm","clk":"5306886481","pt":1646109243268,"mc":[{"id":"1.195395430","rc":[{"atb":[[3.2,7.19]],"id":36104895}],"con":true,"img":false}]}
{"op":"mcm","clk":"5306886565","pt":1646109245977,"mc":[{"id":"1.195395430","rc":[{"atb":[[1.65,66.55]],"id":38206580}],"con":true,"img":false}]}
{"op":"mcm","clk":"5306886567","pt":1646109246080,"mc":[{"id":"1.195395430","rc":[{"atb":[[1.91,0]],"id":38206580}],"con":true,"img":false}]}
{"op":"mcm","clk":"5306886569","pt":1646109246181,"mc":[{"id":"1.195395430","rc":[{"atb":[[2.32,0]],"id":39520250},{"atb":[[1.73,0]],"id":37265273},{"atb":[[3.4,0]],"id":36104895},{"atb":[[4.7,0]],"id":27701417},{"atb":[[1.81,0]],"id":41762283}],"con":true,"img":false}]}
{"op":"mcm","clk":"5306886571","pt":1646109246285,"mc":[{"id":"1.195395430","rc":[{"atb":[[2.12,40.81]],"id":39520250},{"atb":[[1.71,60.93]],"id":37265273},{"atb":[[3.2,27.79]],"id":36104895},{"atb":[[4.2,14.42]],"id":27701417},{"atb":[[1.76,60.93]],"id":41762283}],"con":true,"img":false}]}
{"op":"mcm","clk":"5306886644","pt":1646109249349,"mc":[{"id":"1.195395430","rc":[{"atb":[[2.38,7.72]],"id":39520250},{"atb":[[1.77,10.84]],"id":37265273},{"atb":[[3.2,24.4]],"id":36104895},{"atb":[[1.95,8.79]],"id":38206580},{"atb":[[1.82,10.8],[1.85,9.81]],"id":41762283}],"con":true,"img":false}]}
{"op":"mcm","clk":"5306886649","pt":1646109249655,"mc":[{"id":"1.195395430","rc":[{"atb":[[1.9,0]],"id":38206560}],"con":true,"img":false}]}
{"op":"mcm","clk":"5306886652","pt":1646109249757,"mc":[{"id":"1.195395430","rc":[{"atb":[[1.9,108.15]],"id":39520250},{"atb":[[1.82,0]],"id":41762283}],"con":true,"img":false}]}
{"op":"mcm","clk":"5306886792","pt":1646109255274,"mc":[{"id":"1.195395430","rc":[{"atb":[[2.36,5.48]],"id":39520250},{"atb":[[1.75,9.94]],"id":37265273},{"atb":[[3.25,3.31]],"id":36104895},{"atb":[[1.94,7.93]],"id":38206580},{"atb":[[1.84,8.87]],"id":41762283}],"con":true,"img":false}]}
{"op":"mcm","clk":"5306886800","pt":1646109255583,"mc":[{"id":"1.195395430","rc":[{"atb":[[1.77,15.7]],"id":41762283}],"con":true,"img":false}]}
{"op":"mcm","clk":"5306886814","pt":1646109256097,"mc":[{"id":"1.195395430","rc":[{"atb":[[1.77,31.41]],"id":41762283},{"spn":1.14,"spf":"NaN","id":40494181}],"con":true,"img":false}]}
{"op":"mcm","clk":"5306886901","pt":1646109258859,"mc":[{"id":"1.195395430","rc":[{"atb":[[1.74,0]],"id":37265273}],"con":true,"img":false}]}
{"op":"mcm","clk":"5306886975","pt":1646109261168,"mc":[{"id":"1.195395430","rc":[{"atb":[[1.77,15.7]],"id":41762283}],"con":true,"img":false}]}
{"op":"mcm","clk":"5306886996","pt":1646109261781,"mc":[{"id":"1.195395430","rc":[{"atb":[[1.77,0]],"id":41762283}],"con":true,"img":false}]}
{"op":"mcm","clk":"5306887101","pt":1646109264904,"mc":[{"id":"1.195395430","rc":[{"atb":[[1.79,10.06]],"id":37265273}],"con":true,"img":false}]}
{"op":"mcm","clk":"5306887158","pt":1646109266998,"mc":[{"id":"1.195395430","rc":[{"atb":[[1.81,11.77]],"id":41762283}],"con":true,"img":false}]}
{"op":"mcm","clk":"5306887193","pt":1646109268073,"mc":[{"id":"1.195395430","rc":[{"atb":[[1.81,23.55]],"id":41762283}],"con":true,"img":false}]}
{"op":"mcm","clk":"5306887229","pt":1646109269601,"mc":[{"id":"1.195395430","rc":[{"atb":[[1.78,0]],"id":37265273}],"con":true,"img":false}]}
{"op":"mcm","clk":"5306887314","pt":1646109274196,"mc":[{"id":"1.195395430","rc":[{"atb":[[1.79,0]],"id":37265273}],"con":true,"img":false}]}
{"op":"mcm","clk":"5306887362","pt":1646109275887,"mc":[{"id":"1.195395430","rc":[{"atb":[[1.8,7.04]],"id":37265273}],"con":true,"img":false}]}
{"op":"mcm","clk":"5306887410","pt":1646109277370,"mc":[{"id":"1.195395430","rc":[{"atb":[[1.58,0]],"id":41762283}],"con":true,"img":false}]}
{"op":"mcm","clk":"5306887413","pt":1646109277472,"mc":[{"id":"1.195395430","rc":[{"atb":[[1.66,64.95]],"id":41762283}],"con":true,"img":false}]}
{"op":"mcm","clk":"5306887467","pt":1646109279773,"mc":[{"id":"1.195395430","rc":[{"atb":[[1.65,0]],"id":41762283}],"con":true,"img":false}]}
{"op":"mcm","clk":"5306887474","pt":1646109279978,"mc":[{"id":"1.195395430","rc":[{"atb":[[1.72,108.15]],"id":41762283}],"con":true,"img":false}]}
{"op":"mcm","clk":"5306887478","pt":1646109280182,"mc":[{"id":"1.195395430","rc":[{"atb":[[1.78,7.04]],"id":37265273}],"con":true,"img":false}]}
{"op":"mcm","clk":"5306887487","pt":1646109280593,"mc":[{"id":"1.195395430","rc":[{"atb":[[1.66,0]],"id":41762283}],"con":true,"img":false}]}
{"op":"mcm","clk":"5306887489","pt":1646109280697,"mc":[{"id":"1.195395430","rc":[{"atb":[[1.57,64.95]],"id":41762283}],"con":true,"img":false}]}
{"op":"mcm","clk":"5306887603","pt":1646109284697,"mc":[{"id":"1.195395430","rc":[{"atb":[[2.38,1.66]],"id":39520250},{"atb":[[1.77,0]],"id":37265273},{"atb":[[1.95,0]],"id":38206580},{"atb":[[1.85,0]],"id":41762283}],"con":true,"img":false}]}
{"op":"mcm","clk":"5306887674","pt":1646109287607,"mc":[{"id":"1.195395430","rc":[{"atb":[[1.72,0]],"id":41762283}],"con":true,"img":false}]}
{"op":"mcm","clk":"5306887676","pt":1646109287709,"mc":[{"id":"1.195395430","rc":[{"atb":[[1.64,108.15]],"id":41762283}],"con":true,"img":false}]}
{"op":"mcm","clk":"5306887687","pt":1646109288219,"mc":[{"id":"1.195395430","rc":[{"atb":[[1.78,0]],"id":37265273}],"con":true,"img":false}]}
{"op":"mcm","clk":"5306887728","pt":1646109289702,"mc":[{"id":"1.195395430","rc":[{"atb":[[1.8,0]],"id":37265273}],"con":true,"img":false}]}
{"op":"mcm","clk":"5306887876","pt":1646109294099,"mc":[{"id":"1.195395430","rc":[{"atb":[[1.72,10.93]],"id":37265273}],"con":true,"img":false}]}
{"op":"mcm","clk":"5306887906","pt":1646109295221,"mc":[{"id":"1.195395430","rc":[{"atb":[[2.36,11.61]],"id":39520250}],"con":true,"img":false}]}
{"op":"mcm","clk":"5306887916","pt":1646109295631,"mc":[{"id":"1.195395430","rc":[{"atb":[[1.75,21.07]],"id":37265273}],"con":true,"img":false}]}
{"op":"mcm","clk":"5306887919","pt":1646109295835,"mc":[{"id":"1.195395430","rc":[{"atb":[[1.94,16.81]],"id":38206580},{"atb":[[1.84,18.81]],"id":41762283}],"con":true,"img":false}]}
{"op":"mcm","clk":"5306887923","pt":1646109296037,"mc":[{"id":"1.195395430","rc":[{"atb":[[1.72,21.87]],"id":37265273}],"con":true,"img":false}]}
{"op":"mcm","clk":"5306889408","pt":1646109342673,"mc":[{"id":"1.195395430","rc":[{"spn":2.47,"spf":"NaN","id":37265273},{"spn":2.38,"spf":"NaN","id":38206580},{"atb":[[1.57,0]],"id":41762283},{"spn":2.72,"spf":"NaN","id":41762283}],"con":true,"img":false}]}
{"op":"mcm","clk":"5306889411","pt":1646109342773,"mc":[{"id":"1.195395430","rc":[{"atb":[[1.65,64.95]],"id":41762283}],"con":true,"img":false}]}
{"op":"mcm","clk":"5306891074","pt":1646109401443,"mc":[{"id":"1.195395430","rc":[{"atb":[[1.9,0]],"id":39520250}],"con":true,"img":false}]}
{"op":"mcm","clk":"5306891079","pt":1646109401545,"mc":[{"id":"1.195395430","rc":[{"atb":[[1.9,108.15]],"id":38206560}],"con":true,"img":false}]}
{"op":"mcm","clk":"5306891618","pt":1646109420258,"mc":[{"id":"1.195395430","rc":[{"atb":[[1.23,250]],"id":39520250},{"atb":[[1.23,250]],"id":36104895},{"atb":[[1.23,250]],"id":38206580},{"atb":[[1.23,250]],"id":27701417},{"atb":[[1.23,250]],"id":38206560},{"atb":[[1.23,250]],"id":41762283}],"con":true,"img":false}]}
{"op":"mcm","clk":"5306892037","pt":1646109436286,"mc":[{"id":"1.195395430","rc":[{"atb":[[1.64,0]],"id":41762283}],"con":true,"img":false}]}
{"op":"mcm","clk":"5306892040","pt":1646109436388,"mc":[{"id":"1.195395430","rc":[{"atb":[[1.58,108.15]],"id":41762283}],"con":true,"img":false}]}
{"op":"mcm","clk":"5306892055","pt":1646109436797,"mc":[{"id":"1.195395430","rc":[{"atb":[[1.65,0]],"id":41762283}],"con":true,"img":false}]}
{"op":"mcm","clk":"5306892059","pt":1646109436900,"mc":[{"id":"1.195395430","rc":[{"atb":[[1.59,64.95]],"id":41762283}],"con":true,"img":false}]}
{"op":"mcm","clk":"5306892401","pt":1646109449645,"mc":[{"id":"1.195395430","rc":[{"atb":[[1.58,0]],"id":41762283}],"con":true,"img":false}]}
{"op":"mcm","clk":"5306892407","pt":1646109449696,"mc":[{"id":"1.195395430","rc":[{"atb":[[1.5,108.15]],"id":41762283}],"con":true,"img":false}]}
{"op":"mcm","clk":"5306894219","pt":1646109509101,"mc":[{"id":"1.195395430","rc":[{"atb":[[1.5,0]],"id":41762283}],"con":true,"img":false}]}
{"op":"mcm","clk":"5306894222","pt":1646109509203,"mc":[{"id":"1.195395430","rc":[{"atb":[[1.44,108.15]],"id":41762283}],"con":true,"img":false}]}
{"op":"mcm","clk":"5306894243","pt":1646109509818,"mc":[{"id":"1.195395430","rc":[{"atl":[[5.6,16.24]],"id":39520250},{"atb":[[1.75,34.59],[1.76,3.74]],"id":37265273},{"atl":[[8.4,10.32]],"id":36104895},{"atb":[[1.94,30.33],[1.95,3.74]],"id":38206580},{"atl":[[14.5,8.47]],"id":27701417},{"atl":[[6,12.87]],"id":38206560},{"atl":[[3.6,22.18]],"id":41762283},{"atb":[[1.09,12.64],[1.07,118.08]],"id":40494181}],"con":true,"img":false}]}
{"op":"mcm","clk":"5306894390","pt":1646109514384,"mc":[{"id":"1.195395430","rc":[{"atb":[[1.72,10.93]],"id":37265273},{"atb":[[1.08,73.19]],"id":40494181}],"con":true,"img":false}]}
{"op":"mcm","clk":"5306894440","pt":1646109515623,"mc":[{"id":"1.195395430","rc":[{"atb":[[1.72,0]],"id":37265273},{"atb":[[1.08,0]],"id":40494181}],"con":true,"img":false}]}
{"op":"mcm","clk":"5306894602","pt":1646109520512,"mc":[{"id":"1.195395430","rc":[{"atb":[[1.72,4.49]],"id":37265273}],"con":true,"img":false}]}
{"op":"mcm","clk":"5306894662","pt":1646109522409,"mc":[{"id":"1.195395430","rc":[{"atb":[[1.72,8.98]],"id":37265273}],"con":true,"img":false}]}
{"op":"mcm","clk":"5306894860","pt":1646109528096,"mc":[{"id":"1.195395430","rc":[{"atl":[[3.2,18.84],[3.15,3.34]],"id":37265273},{"atl":[[1.43,13.51]],"id":40494181}],"con":true,"img":false}]}
{"op":"mcm","clk":"5306894976","pt":1646109531730,"mc":[{"id":"1.195395430","rc":[{"atb":[[1.76,0]],"id":41762283},{"atb":[[1.07,13.51]],"id":40494181}],"con":true,"img":false}]}
{"op":"mcm","clk":"5306894981","pt":1646109531831,"mc":[{"id":"1.195395430","rc":[{"atb":[[1.72,4.49]],"id":37265273},{"atb":[[1.81,84.49]],"id":41762283},{"atb":[[1.08,104.56]],"id":40494181}],"con":true,"img":false}]}
{"op":"mcm","clk":"5306895016","pt":1646109532809,"mc":[{"id":"1.195395430","rc":[{"atb":[[1.72,0]],"id":37265273}],"con":true,"img":false}]}
{"op":"mcm","clk":"5306895018","pt":1646109532913,"mc":[{"id":"1.195395430","rc":[{"atb":[[2.12,0]],"id":39520250},{"atb":[[4.2,0]],"id":27701417}],"con":true,"img":false}]}
{"op":"mcm","clk":"5306895020","pt":1646109533012,"mc":[{"id":"1.195395430","rc":[{"atb":[[2.32,40.81]],"id":39520250},{"atb":[[4.7,14.42]],"id":27701417}],"con":true,"img":false}]}
{"op":"mcm","clk":"5306895053","pt":1646109534050,"mc":[{"id":"1.195395430","rc":[{"atb":[[1.91,47.53],[1.65,0]],"id":38206580}],"con":true,"img":false}]}
{"op":"mcm","clk":"5306895089","pt":1646109534911,"mc":[{"id":"1.195395430","rc":[{"atb":[[2.36,6.13]],"id":39520250},{"atb":[[1.94,22.4]],"id":38206580},{"atb":[[1.84,9.93]],"id":41762283}],"con":true,"img":false}]}
{"op":"mcm","clk":"5306895224","pt":1646109539006,"mc":[{"id":"1.195395430","rc":[{"atb":[[1.72,4.49]],"id":37265273}],"con":true,"img":false}]}
{"op":"mcm","clk":"5306895257","pt":1646109540130,"mc":[{"id":"1.195395430","rc":[{"atb":[[1.72,8.98]],"id":37265273}],"con":true,"img":false}]}
{"op":"mcm","clk":"5306895273","pt":1646109540540,"mc":[{"id":"1.195395430","rc":[{"atb":[[1.71,0]],"id":37265273}],"con":true,"img":false}]}
{"op":"mcm","clk":"5306895275","pt":1646109540641,"mc":[{"id":"1.195395430","rc":[{"atb":[[1.76,64.67]],"id":37265273}],"con":true,"img":false}]}
{"op":"mcm","clk":"5306895289","pt":1646109540956,"mc":[{"id":"1.195395430","rc":[{"atb":[[2.38,7.07]],"id":39520250},{"atb":[[1.75,24.64]],"id":37265273},{"atb":[[1.95,11.59]],"id":38206580},{"atb":[[1.85,8.77]],"id":41762283}],"con":true,"img":false}]}
{"op":"mcm","clk":"5306895352","pt":1646109542705,"mc":[{"id":"1.195395430","rc":[{"atl":[[24,0]],"id":27701417}],"con":true,"img":false}]}
{"op":"mcm","clk":"5306895356","pt":1646109542810,"mc":[{"id":"1.195395430","rc":[{"atl":[[14,2.7]],"id":27701417}],"con":true,"img":false}]}
{"op":"mcm","clk":"5306895510","pt":1646109546913,"mc":[{"id":"1.195395430","rc":[{"atb":[[1.8,9.32]],"id":37265273}],"con":true,"img":false}]}
{"op":"mcm","clk":"5306895643","pt":1646109551218,"mc":[{"id":"1.195395430","rc":[{"atb":[[1.76,3.74]],"id":37265273}],"con":true,"img":false}]}
{"op":"mcm","clk":"5306895646","pt":1646109551321,"mc":[{"id":"1.195395430","rc":[{"atb":[[1.71,60.93]],"id":37265273}],"con":true,"img":false}]}
{"op":"mcm","clk":"5306895671","pt":1646109552139,"mc":[{"id":"1.195395430","rc":[{"atb":[[1.72,4.49]],"id":37265273}],"con":true,"img":false}]}
{"op":"mcm","clk":"5306895685","pt":1646109552653,"mc":[{"id":"1.195395430","rc":[{"atb":[[1.72,0]],"id":37265273}],"con":true,"img":false}]}
{"op":"mcm","clk":"5306895696","pt":1646109552962,"mc":[{"id":"1.195395430","rc":[{"atb":[[1.8,0]],"id":37265273}],"con":true,"img":false}]}
{"op":"mcm","clk":"5306895869","pt":1646109558454,"mc":[{"id":"1.195395430","rc":[{"atb":[[1.07,574.89]],"id":40494181}],"con":true,"img":false}]}
{"op":"mcm","clk":"5306895872","pt":1646109558556,"mc":[{"id":"1.195395430","rc":[{"atb":[[1.72,4.49]],"id":37265273},{"atb":[[1.05,0]],"id":40494181}],"con":true,"img":false}]}
{"op":"mcm","clk":"5306895884","pt":1646109559069,"mc":[{"id":"1.195395430","rc":[{"atb":[[1.75,34.59]],"id":37265273}],"con":true,"img":false}]}
{"op":"mcm","clk":"5306895893","pt":1646109559327,"mc":[{"id":"1.195395430","rc":[{"atb":[[1.72,8.98]],"id":37265273}],"con":true,"img":false}]}
{"op":"mcm","clk":"5306895896","pt":1646109559532,"mc":[{"id":"1.195395430","rc":[{"atb":[[2.32,0]],"id":38206560}],"con":true,"img":false}]}
{"op":"mcm","clk":"5306895900","pt":1646109559633,"mc":[{"id":"1.195395430","rc":[{"atb":[[2.42,27.57]],"id":38206560}],"con":true,"img":false}]}
{"op":"mcm","clk":"5306895925","pt":1646109560457,"mc":[{"id":"1.195395430","rc":[{"atb":[[2.88,0]],"id":36104895},{"atb":[[1.71,53.06]],"id":41762283}],"con":true,"img":false}]}
{"op":"mcm","clk":"5306895928","pt":1646109560559,"mc":[{"id":"1.195395430","rc":[{"atb":[[3.2,43.87]],"id":36104895},{"atb":[[1.59,0]],"id":41762283}],"con":true,"img":false}]}
{"op":"mcm","clk":"5306895941","pt":1646109560871,"mc":[{"id":"1.195395430","rc":[{"atb":[[2.36,0]],"id":39520250},{"atb":[[1.94,13.51]],"id":38206580},{"atb":[[1.84,0]],"id":41762283}],"con":true,"img":false}]}
{"op":"mcm","clk":"5306896228","pt":1646109569447,"mc":[{"id":"1.195395430","rc":[{"spn":2.45,"spf":"NaN","id":37265273},{"atb":[[1.95,20.38]],"id":38206580},{"spn":2.38,"spf":"NaN","id":38206580},{"spn":9.4,"spf":"NaN","id":27701417},{"spn":2.72,"spf":"NaN","id":41762283},{"spn":1.15,"spf":"NaN","id":40494181}],"con":true,"img":false}]}
{"op":"mcm","clk":"5306896235","pt":1646109569650,"mc":[{"id":"1.195395430","rc":[{"atb":[[2.38,13.13]],"id":39520250}],"con":true,"img":false}]}
{"op":"mcm","clk":"5306896238","pt":1646109569755,"mc":[{"id":"1.195395430","rc":[{"atb":[[3.85,0]],"id":27701417}],"con":true,"img":false}]}
{"op":"mcm","clk":"5306896244","pt":1646109569855,"mc":[{"id":"1.195395430","rc":[{"atb":[[4.2,11.01]],"id":27701417}],"con":true,"img":false}]}
{"op":"mcm","clk":"5306896251","pt":1646109570162,"mc":[{"id":"1.195395430","rc":[{"atb":[[1.85,18.59]],"id":41762283}],"con":true,"img":false}]}
{"op":"mcm","clk":"5306896296","pt":1646109571649,"mc":[{"id":"1.195395430","rc":[{"atb":[[1.96,3.66]],"id":38206580},{"atb":[[1.85,32.1],[1.86,4.57]],"id":41762283}],"con":true,"img":false}]}
{"op":"mcm","clk":"5306896401","pt":1646109575453,"mc":[{"id":"1.195395430","rc":[{"atb":[[1.81,72.71]],"id":41762283}],"con":true,"img":false}]}
{"op":"mcm","clk":"5306896458","pt":1646109577356,"mc":[{"id":"1.195395430","rc":[{"atb":[[1.81,60.93]],"id":41762283}],"con":true,"img":false}]}
{"op":"mcm","clk":"5306896585","pt":1646109581682,"mc":[{"id":"1.195395430","rc":[{"atb":[[1.82,5.49]],"id":41762283}],"con":true,"img":false}]}
{"op":"mcm","clk":"5306896663","pt":1646109583996,"mc":[{"id":"1.195395430","rc":[{"atb":[[1.82,10.98]],"id":41762283}],"con":true,"img":false}]}
{"op":"mcm","clk":"5306896706","pt":1646109585380,"mc":[{"id":"1.195395430","rc":[{"atb":[[3.2,40.07]],"id":36104895}],"con":true,"img":false}]}
{"op":"mcm","clk":"5306896842","pt":1646109589485,"mc":[{"id":"1.195395430","rc":[{"atb":[[1.71,0]],"id":37265273}],"con":true,"img":false}]}
{"op":"mcm","clk":"5306896845","pt":1646109589587,"mc":[{"id":"1.195395430","rc":[{"atb":[[1.76,64.67]],"id":37265273}],"con":true,"img":false}]}
{"op":"mcm","clk":"5306896888","pt":1646109590973,"mc":[{"id":"1.195395430","rc":[{"atb":[[1.75,23.46]],"id":37265273}],"con":true,"img":false}]}
{"op":"mcm","clk":"5306896911","pt":1646109591689,"mc":[{"id":"1.195395430","rc":[{"atb":[[3.25,7.01]],"id":36104895}],"con":true,"img":false}]}
{"op":"mcm","clk":"5306896926","pt":1646109592100,"mc":[{"id":"1.195395430","rc":[{"atb":[[1.75,13.51]],"id":37265273}],"con":true,"img":false}]}
{"op":"mcm","clk":"5306897096","pt":1646109596266,"mc":[{"id":"1.195395430","rc":[{"atb":[[1.9,0]],"id":38206560},{"atb":[[1.44,0]],"id":41762283}],"con":true,"img":false}]}
{"op":"mcm","clk":"5306897103","pt":1646109596368,"mc":[{"id":"1.195395430","rc":[{"atb":[[1.9,108.15]],"id":39520250},{"atb":[[1.49,108.15]],"id":41762283}],"con":true,"img":false}]}
{"op":"mcm","clk":"5306897175","pt":1646109598111,"mc":[{"id":"1.195395430","rc":[{"atb":[[1.8,9.32]],"id":37265273}],"con":true,"img":false}]}
{"op":"mcm","clk":"5306897318","pt":1646109601501,"mc":[{"id":"1.195395430","rc":[{"atb":[[1.72,4.49]],"id":37265273}],"con":true,"img":false}]}
{"op":"mcm","clk":"5306897340","pt":1646109602015,"mc":[{"id":"1.195395430","rc":[{"atb":[[1.76,3.74]],"id":37265273}],"con":true,"img":false}]}
{"op":"mcm","clk":"5306897344","pt":1646109602068,"mc":[{"id":"1.195395430","rc":[{"atb":[[1.71,60.93]],"id":37265273}],"con":true,"img":false}]}
{"op":"mcm","clk":"5306897366","pt":1646109602892,"mc":[{"id":"1.195395430","rc":[{"atb":[[1.72,0]],"id":37265273}],"con":true,"img":false}]}
{"op":"mcm","clk":"5306897419","pt":1646109603980,"mc":[{"id":"1.195395430","rc":[{"atb":[[1.9,0]],"id":39520250},{"atb":[[1.49,0]],"id":41762283}],"con":true,"img":false}]}
{"op":"mcm","clk":"5306897424","pt":1646109604082,"mc":[{"id":"1.195395430","rc":[{"atb":[[1.8,0]],"id":37265273}],"con":true,"img":false}]}
{"op":"mcm","clk":"5306897428","pt":1646109604187,"mc":[{"id":"1.195395430","rc":[{"atb":[[1.9,108.15]],"id":38206560},{"atb":[[1.43,108.15]],"id":41762283}],"con":true,"img":false}]}
{"op":"mcm","clk":"5306897608","pt":1646109610130,"mc":[{"id":"1.195395430","rc":[{"atb":[[1.75,23.46]],"id":37265273}],"con":true,"img":false}]}
{"op":"mcm","clk":"5306897900","pt":1646109617915,"mc":[{"id":"1.195395430","rc":[{"atb":[[1.75,34.59]],"id":37265273}],"con":true,"img":false}]}
{"op":"mcm","clk":"5306898189","pt":1646109625529,"mc":[{"id":"1.195395430","rc":[{"atb":[[2.4,0],[2.5,0],[2.3,0]],"id":38206560},{"atl":[[8,0],[10,0],[20,0],[6,10.47],[15,0]],"id":38206560},{"atb":[[1.8,0],[1.7,0],[1.75,0]],"id":41762283},{"atl":[[3.6,17.56],[6.4,0],[5.2,0],[4.2,0],[8.4,0]],"id":41762283}],"con":true,"img":false}]}
{"op":"mcm","clk":"5306898222","pt":1646109626432,"mc":[{"id":"1.195395430","rc":[{"atb":[[2.24,33.52],[2.42,0]],"id":38206560},{"atb":[[1.58,64.95],[1.71,0]],"id":41762283}],"con":true,"img":false}]}
{"op":"mcm","clk":"5306898271","pt":1646109627823,"mc":[{"id":"1.195395430","rc":[{"atb":[[1.07,13.51],[1.05,785.92]],"id":40494181}],"con":true,"img":false}]}
{"op":"mcm","clk":"5306898275","pt":1646109627927,"mc":[{"id":"1.195395430","rc":[{"atb":[[3.2,20.6]],"id":36104895},{"atb":[[4.2,0]],"id":27701417},{"atb":[[2.52,0]],"id":38206560},{"atb":[[1.08,0]],"id":40494181}],"con":true,"img":false}]}
{"op":"mcm","clk":"5306898279","pt":1646109628033,"mc":[{"id":"1.195395430","rc":[{"atb":[[2.88,19.46]],"id":36104895},{"atb":[[3.85,11.01]],"id":27701417},{"atb":[[2.38,29.62]],"id":38206560},{"atb":[[1.07,118.08]],"id":40494181}],"con":true,"img":false}]}
{"op":"mcm","clk":"5306898390","pt":1646109631426,"mc":[{"id":"1.195395430","rc":[{"atb":[[3.25,3.7]],"id":36104895},{"spn":2.39,"spf":"NaN","id":38206580},{"atb":[[2.58,1.66]],"id":38206560},{"spn":2.73,"spf":"NaN","id":41762283}],"con":true,"img":false}]}
{"op":"mcm","clk":"5306898417","pt":1646109632146,"mc":[{"id":"1.195395430","rc":[{"atb":[[1.44,85.62],[1.81,0],[1.58,0]],"id":41762283}],"con":true,"img":false}]}
{"op":"mcm","clk":"5306898419","pt":1646109632251,"mc":[{"id":"1.195395430","rc":[{"atb":[[1.49,60.93]],"id":41762283}],"con":true,"img":false}]}
{"op":"mcm","clk":"5306898494","pt":1646109634566,"mc":[{"id":"1.195395430","rc":[{"atb":[[1.85,23.33]],"id":41762283}],"con":true,"img":false}]}
{"op":"mcm","clk":"5306898576","pt":1646109637036,"mc":[{"id":"1.195395430","rc":[{"atl":[[15,0]],"id":36104895}],"con":true,"img":false}]}
{"op":"mcm","clk":"5306898580","pt":1646109637134,"mc":[{"id":"1.195395430","rc":[{"atl":[[16,4.3]],"id":36104895}],"con":true,"img":false}]}
{"op":"mcm","clk":"5306898590","pt":1646109637453,"mc":[{"id":"1.195395430","rc":[{"atb":[[3.2,23.99]],"id":36104895},{"atb":[[2.3,5.73]],"id":38206560}],"con":true,"img":false}]}
{"op":"mcm","clk":"5306898864","pt":1646109645036,"mc":[{"id":"1.195395430","rc":[{"atb":[[3.25,0]],"id":36104895},{"atb":[[2.56,0]],"id":38206560}],"con":true,"img":false}]}
{"op":"mcm","clk":"5306898938","pt":1646109647748,"mc":[{"id":"1.195395430","rc":[{"atb":[[1.71,0]],"id":37265273}],"con":true,"img":false}]}
{"op":"mcm","clk":"5306898944","pt":1646109647849,"mc":[{"id":"1.195395430","rc":[{"atb":[[1.76,64.67]],"id":37265273}],"con":true,"img":false}]}
{"op":"mcm","clk":"5306899000","pt":1646109649587,"mc":[{"id":"1.195395430","rc":[{"atb":[[1.75,24.64]],"id":37265273}],"con":true,"img":false}]}
{"op":"mcm","clk":"5306899062","pt":1646109651072,"mc":[{"id":"1.195395430","rc":[{"atb":[[1.85,13.51]],"id":41762283}],"con":true,"img":false}]}
{"op":"mcm","clk":"5306899072","pt":1646109651275,"mc":[{"id":"1.195395430","rc":[{"atb":[[3.2,27.79]],"id":36104895}],"con":true,"img":false}]}
{"op":"mcm","clk":"5306899106","pt":1646109652457,"mc":[{"id":"1.195395430","rc":[{"atb":[[3.2,24.4]],"id":36104895}],"con":true,"img":false}]}
{"op":"mcm","clk":"5306899235","pt":1646109655587,"mc":[{"id":"1.195395430","rc":[{"atb":[[1.8,9.32]],"id":37265273}],"con":true,"img":false}]}
{"op":"mcm","clk":"5306899241","pt":1646109655691,"mc":[{"id":"1.195395430","rc":[{"atl":[[5,0]],"id":37265273}],"con":true,"img":false}]}
{"op":"mcm","clk":"5306899244","pt":1646109655741,"mc":[{"id":"1.195395430","rc":[{"atl":[[5.4,15.96]],"id":37265273}],"con":true,"img":false}]}
{"op":"mcm","clk":"5306899283","pt":1646109656770,"mc":[{"id":"1.195395430","rc":[{"atb":[[1.43,0]],"id":41762283}],"con":true,"img":false}]}
{"op":"mcm","clk":"5306899287","pt":1646109656874,"mc":[{"id":"1.195395430","rc":[{"atb":[[1.38,108.15]],"id":41762283}],"con":true,"img":false}]}
{"op":"mcm","clk":"5306899348","pt":1646109658359,"mc":[{"id":"1.195395430","rc":[{"atb":[[3.25,3.31]],"id":36104895}],"con":true,"img":false}]}
{"op":"mcm","clk":"5306899361","pt":1646109658668,"mc":[{"id":"1.195395430","rc":[{"atb":[[1.07,13.51]],"id":40494181}],"con":true,"img":false}]}
{"op":"mcm","clk":"5306899366","pt":1646109658768,"mc":[{"id":"1.195395430","rc":[{"atb":[[1.09,117.2]],"id":40494181}],"con":true,"img":false}]}
{"op":"mcm","clk":"5306899455","pt":1646109660877,"mc":[{"id":"1.195395430","rc":[{"atb":[[2.38,0]],"id":38206560}],"con":true,"img":false}]}
{"op":"mcm","clk":"5306899459","pt":1646109660978,"mc":[{"id":"1.195395430","rc":[{"atb":[[2.7,29.62]],"id":38206560}],"con":true,"img":false}]}
{"op":"mcm","clk":"5306899525","pt":1646109662676,"mc":[{"id":"1.195395430","rc":[{"atb":[[1.6,402.33],[1.7,172.43],[1.65,371.38]],"id":37265273},{"atl":[[3.2,24.3],[3.7,8.89],[6.8,16.55],[4.4,14.12],[5.4,21.42]],"id":37265273},{"atb":[[2.8,33.52],[2.6,75.43],[2.7,100.62]],"id":38206560},{"atl":[[7.2,1.93],[18,1.41],[9.2,1.46],[13,2],[26,1.91]],"id":38206560},{"atb":[[1.6,201.16],[1.55,219.45],[1.65,92.84]],"id":41762283},{"atl":[[3.45,4.89],[3.95,8.13],[4.9,16.21],[2.98,6.06],[5.9,17.04]],"id":41762283}],"con":true,"img":false}]}
{"op":"mcm","clk":"5306899546","pt":1646109663198,"mc":[{"id":"1.195395430","rc":[{"atb":[[1.75,13.51]],"id":37265273}],"con":true,"img":false}]}
{"op":"mcm","clk":"5306899561","pt":1646109663455,"mc":[{"id":"1.195395430","rc":[{"atb":[[1.9,0]],"id":38206560},{"atb":[[1.38,0]],"id":41762283}],"con":true,"img":false}]}
{"op":"mcm","clk":"5306899573","pt":1646109663659,"mc":[{"id":"1.195395430","rc":[{"atb":[[1.9,108.15]],"id":39520250},{"atb":[[1.53,108.15]],"id":41762283}],"con":true,"img":false}]}
{"op":"mcm","clk":"5306899586","pt":1646109663969,"mc":[{"id":"1.195395430","rc":[{"atb":[[2.44,29.74]],"id":36104895},{"atl":[[6.2,8.11]],"id":38206580},{"atb":[[2.76,20.02]],"id":27701417},{"atl":[[2.1,35.72]],"id":40494181}],"con":true,"img":false}]}
{"op":"mcm","clk":"5306899588","pt":1646109664072,"mc":[{"id":"1.195395430","rc":[{"atl":[[8.2,0]],"id":39520250},{"atb":[[2.88,0]],"id":36104895},{"atl":[[4.6,0],[5,0]],"id":38206580},{"atb":[[3.85,0]],"id":27701417},{"atb":[[2.24,0],[2.7,70.99]],"id":38206560},{"atl":[[1.62,0]],"id":40494181}],"con":true,"img":false}]}
{"op":"mcm","clk":"5306899592","pt":1646109664174,"mc":[{"id":"1.195395430","rc":[{"atl":[[8.8,5.4]],"id":39520250},{"atl":[[5.6,12.01]],"id":38206580},{"atb":[[2.36,29.62],[2.1,33.52]],"id":38206560},{"atb":[[1.49,0]],"id":41762283}],"con":true,"img":false}]}
{"op":"mcm","clk":"5306899596","pt":1646109664275,"mc":[{"id":"1.195395430","rc":[{"atb":[[1.55,280.39]],"id":41762283}],"con":true,"img":false}]}
{"op":"mcm","clk":"5306899602","pt":1646109664481,"mc":[{"id":"1.195395430","rc":[{"atb":[[2.3,0]],"id":38206560}],"con":true,"img":false}]}
{"op":"mcm","clk":"5306899622","pt":1646109665102,"mc":[{"id":"1.195395430","rc":[{"atb":[[1.82,5.49]],"id":41762283},{"atl":[[4.9,6.15]],"id":41762283}],"con":true,"img":false}]}
{"op":"mcm","clk":"5306899626","pt":1646109665151,"mc":[{"id":"1.195395430","rc":[{"atl":[[4.1,10.05]],"id":41762283}],"con":true,"img":false}]}
{"op":"mcm","clk":"5306899771","pt":1646109669197,"mc":[{"id":"1.195395430","rc":[{"atb":[[1.8,19.75]],"id":37265273}],"con":true,"img":false}]}
{"op":"mcm","clk":"5306899833","pt":1646109670591,"mc":[{"id":"1.195395430","rc":[{"atb":[[2.86,4.01]],"id":38206560},{"atb":[[1.69,10.8]],"id":41762283}],"con":true,"img":false}]}
{"op":"mcm","clk":"5306899990","pt":1646109674486,"mc":[{"id":"1.195395430","rc":[{"atb":[[1.76,3.74]],"id":37265273},{"atb":[[4.7,0]],"id":27701417},{"atl":[[1.44,0]],"id":40494181}],"con":true,"img":false}]}
{"op":"mcm","clk":"5306899993","pt":1646109674592,"mc":[{"id":"1.195395430","rc":[{"atb":[[1.71,60.93]],"id":37265273},{"atb":[[4.2,14.42]],"id":27701417},{"atl":[[1.83,43.26]],"id":40494181}],"con":true,"img":false}]}
{"op":"mcm","clk":"5306900066","pt":1646109676387,"mc":[{"id":"1.195395430","rc":[{"atb":[[1.82,0]],"id":41762283}],"con":true,"img":false}]}
{"op":"mcm","clk":"5306900078","pt":1646109676694,"mc":[{"id":"1.195395430","rc":[{"atb":[[1.8,10.43]],"id":37265273}],"con":true,"img":false}]}
{"op":"mcm","clk":"5306900299","pt":1646109682484,"mc":[{"id":"1.195395430","rc":[{"atb":[[1.75,23.46]],"id":37265273}],"con":true,"img":false}]}
{"op":"mcm","clk":"5306900356","pt":1646109684178,"mc":[{"id":"1.195395430","rc":[{"atb":[[2.86,8.5]],"id":38206560}],"con":true,"img":false}]}
{"op":"mcm","clk":"5306900381","pt":1646109684688,"mc":[{"id":"1.195395430","rc":[{"atb":[[1.69,22.9]],"id":41762283}],"con":true,"img":false}]}
{"op":"mcm","clk":"5306900490","pt":1646109687713,"mc":[{"id":"1.195395430","rc":[{"atl":[[4.6,9.91],[5.9,9.79]],"id":41762283},{"atb":[[1.13,302.27],[1.05,0]],"id":40494181}],"con":true,"img":false}]}
{"op":"mcm","clk":"5306900597","pt":1646109690326,"mc":[{"id":"1.195395430","rc":[{"atb":[[1.99,2]],"id":39520250},{"atl":[[11.5,2]],"id":39520250},{"atb":[[1.59,2]],"id":37265273},{"atl":[[5,2]],"id":37265273},{"atb":[[2.76,2]],"id":36104895},{"atl":[[24,2]],"id":36104895},{"atb":[[1.78,2]],"id":38206580},{"atl":[[4.7,2]],"id":38206580},{"atb":[[3.25,2]],"id":27701417},{"atl":[[80,2]],"id":27701417},{"atb":[[2.38,2]],"id":38206560},{"atl":[[16,2]],"id":38206560},{"atb":[[1.53,110.15]],"id":41762283},{"atl":[[4.8,2]],"id":41762283},{"atb":[[1.01,30177.21]],"id":40494181},{"atl":[[1.99,2]],"id":40494181}],"con":true,"img":false}]}
{"op":"mcm","clk":"5306900618","pt":1646109690687,"mc":[{"id":"1.195395430","rc":[{"atl":[[11,5.52],[14,0]],"id":36104895},{"atb":[[1.09,12.64]],"id":40494181}],"con":true,"img":false}]}
{"op":"mcm","clk":"5306900621","pt":1646109690791,"mc":[{"id":"1.195395430","rc":[{"atb":[[1.16,104.56]],"id":40494181}],"con":true,"img":false}]}
{"op":"mcm","clk":"5306900698","pt":1646109693097,"mc":[{"id":"1.195395430","rc":[{"atb":[[1.8,0]],"id":37265273},{"spn":4.43,"spf":"NaN","id":38206560},{"spn":2.42,"spf":"NaN","id":41762283},{"spn":1.18,"spf":"NaN","id":40494181}],"con":true,"img":false}]}
{"op":"mcm","clk":"5306900745","pt":1646109694685,"mc":[{"id":"1.195395430","rc":[{"atb":[[1.55,219.45]],"id":41762283}],"con":true,"img":false}]}
{"op":"mcm","clk":"5306900747","pt":1646109694786,"mc":[{"id":"1.195395430","rc":[{"atb":[[1.66,60.93]],"id":41762283}],"con":true,"img":false}]}
{"op":"mcm","clk":"5306900817","pt":1646109697506,"mc":[{"id":"1.195395430","rc":[{"atb":[[1.69,12.09]],"id":41762283}],"con":true,"img":false}]}
{"op":"mcm","clk":"5306900822","pt":1646109697709,"mc":[{"id":"1.195395430","rc":[{"atl":[[4.5,0],[3.15,23.46]],"id":37265273}],"con":true,"img":false}]}
{"op":"mcm","clk":"5306900848","pt":1646109698992,"mc":[{"id":"1.195395430","rc":[{"atb":[[1.75,34.59]],"id":37265273}],"con":true,"img":false}]}
{"op":"mcm","clk":"5306900869","pt":1646109699611,"mc":[{"id":"1.195395430","rc":[{"atb":[[2.36,0]],"id":38206560}],"con":true,"img":false}]}
{"op":"mcm","clk":"5306900871","pt":1646109699712,"mc":[{"id":"1.195395430","rc":[{"atb":[[2.82,29.62]],"id":38206560}],"con":true,"img":false}]}
{"op":"mcm","clk":"5306900898","pt":1646109700635,"mc":[{"id":"1.195395430","rc":[{"atb":[[2.86,4.49]],"id":38206560}],"con":true,"img":false}]}
{"op":"mcm","clk":"5306900976","pt":1646109703608,"mc":[{"id":"1.195395430","rc":[{"atb":[[1.7,10.65]],"id":41762283}],"con":true,"img":false}]}
{"op":"mcm","clk":"5306901008","pt":1646109705294,"mc":[{"id":"1.195395430","rc":[{"atb":[[1.59,0],[1.55,2]],"id":37265273},{"atl":[[24,0],[28,2]],"id":36104895},{"atb":[[2.38,0],[2.48,2]],"id":38206560},{"atb":[[1.54,2],[1.53,108.15]],"id":41762283}],"con":true,"img":false}]}
{"op":"mcm","clk":"5306901044","pt":1646109706725,"mc":[{"id":"1.195395430","rc":[{"atb":[[2.88,3.96]],"id":38206560}],"con":true,"img":false}]}
{"op":"mcm","clk":"5306901178","pt":1646109710918,"mc":[{"id":"1.195395430","rc":[{"atb":[[1.69,0]],"id":41762283}],"con":true,"img":false}]}
{"op":"mcm","clk":"5306901323","pt":1646109715947,"mc":[{"id":"1.195395430","rc":[{"atl":[[4.1,0],[3.55,16.96]],"id":41762283}],"con":true,"img":false}]}
{"op":"mcm","clk":"5306901356","pt":1646109717026,"mc":[{"id":"1.195395430","rc":[{"atl":[[11,0]],"id":38206560}],"con":true,"img":false}]}
{"op":"mcm","clk":"5306901359","pt":1646109717126,"mc":[{"id":"1.195395430","rc":[{"atb":[[2.86,0]],"id":38206560},{"atl":[[9.8,4.32]],"id":38206560}],"con":true,"img":false}]}
{"op":"mcm","clk":"5306901362","pt":1646109717334,"mc":[{"id":"1.195395430","rc":[{"atb":[[1.7,22.58]],"id":41762283}],"con":true,"img":false}]}
{"op":"mcm","clk":"5306901377","pt":1646109717946,"mc":[{"id":"1.195395430","rc":[{"atl":[[16,1.6],[12,3.78]],"id":36104895},{"atb":[[1.56,67.27],[1.44,0]],"id":41762283}],"con":true,"img":false}]}
{"op":"mcm","clk":"5306901402","pt":1646109718920,"mc":[{"id":"1.195395430","rc":[{"atb":[[1.67,63.27]],"id":38206580},{"atl":[[26,0]],"id":27701417}],"con":true,"img":false}]}
{"op":"mcm","clk":"5306901408","pt":1646109719020,"mc":[{"id":"1.195395430","rc":[{"atb":[[1.56,0]],"id":38206580},{"atl":[[14,5.4]],"id":27701417}],"con":true,"img":false}]}
{"op":"mcm","clk":"5306901449","pt":1646109719946,"mc":[{"id":"1.195395430","rc":[{"atb":[[2.12,37.31]],"id":39520250}],"con":true,"img":false}]}
{"op":"mcm","clk":"5306901451","pt":1646109720051,"mc":[{"id":"1.195395430","rc":[{"atb":[[1.91,0]],"id":39520250}],"con":true,"img":false}]}
{"op":"mcm","clk":"5306901460","pt":1646109720462,"mc":[{"id":"1.195395430","rc":[{"atl":[[20,2],[28,0]],"id":36104895},{"atl":[[80,0],[95,2.5]],"id":27701417},{"atl":[[4.8,0],[4.7,2]],"id":41762283}],"con":true,"img":false}]}
{"op":"mcm","clk":"5306901478","pt":1646109721025,"mc":[{"id":"1.195395430","rc":[{"atl":[[3.1,3.35]],"id":37265273},{"atl":[[2.98,19.58],[2.96,4.05]],"id":41762283}],"con":true,"img":false}]}
{"op":"mcm","clk":"5306901495","pt":1646109721639,"mc":[{"id":"1.195395430","rc":[{"atb":[[1.56,0]],"id":41762283}],"con":true,"img":false}]}
{"op":"mcm","clk":"5306901499","pt":1646109721742,"mc":[{"id":"1.195395430","rc":[{"atb":[[1.54,69.27]],"id":41762283}],"con":true,"img":false}]}
{"op":"mcm","clk":"5306901555","pt":1646109723023,"mc":[{"id":"1.195395430","rc":[{"atb":[[2.88,8.4]],"id":38206560}],"con":true,"img":false}]}
{"op":"mcm","clk":"5306901702","pt":1646109728459,"mc":[{"id":"1.195395430","rc":[{"atb":[[1.71,0]],"id":37265273}],"con":true,"img":false}]}
{"op":"mcm","clk":"5306901704","pt":1646109728562,"mc":[{"id":"1.195395430","rc":[{"atb":[[1.76,64.67]],"id":37265273}],"con":true,"img":false}]}
{"op":"mcm","clk":"5306901752","pt":1646109730761,"mc":[{"id":"1.195395430","rc":[{"atb":[[1.75,24.64]],"id":37265273}],"con":true,"img":false}]}
{"op":"mcm","clk":"5306901880","pt":1646109735575,"mc":[{"id":"1.195395430","rc":[{"atb":[[1.55,0],[1.54,2]],"id":37265273},{"atl":[[4,2],[5,0]],"id":37265273},{"atl":[[4.5,2],[4.7,0]],"id":41762283}],"con":true,"img":false}]}
{"op":"mcm","clk":"5306901903","pt":1646109736744,"mc":[{"id":"1.195395430","rc":[{"atb":[[1.8,9.32]],"id":37265273}],"con":true,"img":false}]}
{"op":"mcm","clk":"5306902017","pt":1646109740682,"mc":[{"id":"1.195395430","rc":[{"atb":[[1.75,13.51]],"id":37265273}],"con":true,"img":false}]}
{"op":"mcm","clk":"5306902039","pt":1646109741243,"mc":[{"id":"1.195395430","rc":[{"atb":[[1.76,3.74]],"id":37265273}],"con":true,"img":false}]}
{"op":"mcm","clk":"5306902041","pt":1646109741347,"mc":[{"id":"1.195395430","rc":[{"atb":[[1.71,60.93]],"id":37265273}],"con":true,"img":false}]}
{"op":"mcm","clk":"5306902067","pt":1646109742777,"mc":[{"id":"1.195395430","rc":[{"atb":[[1.8,0]],"id":37265273}],"con":true,"img":false}]}
{"op":"mcm","clk":"5306902215","pt":1646109748662,"mc":[{"id":"1.195395430","rc":[{"atb":[[1.75,23.46]],"id":37265273}],"con":true,"img":false}]}
{"op":"mcm","clk":"5306902264","pt":1646109750557,"mc":[{"id":"1.195395430","rc":[{"atb":[[1.55,2],[1.54,0]],"id":37265273}],"con":true,"img":false}]}
{"op":"mcm","clk":"5306902434","pt":1646109759155,"mc":[{"id":"1.195395430","rc":[{"atb":[[1.75,34.59]],"id":37265273},{"spn":2.43,"spf":"NaN","id":37265273},{"spn":4.44,"spf":"NaN","id":38206560},{"spn":2.41,"spf":"NaN","id":41762283}],"con":true,"img":false}]}
{"op":"mcm","clk":"5306902769","pt":1646109773613,"mc":[{"id":"1.195395430","rc":[{"atb":[[2.8,0],[2.6,0],[2.7,0]],"id":38206560},{"atl":[[7.2,0],[18,0],[9.2,0],[13,0],[26,0]],"id":38206560},{"atb":[[1.6,0],[1.55,0],[1.65,0]],"id":41762283},{"atl":[[3.45,0],[3.95,0],[4.9,0],[2.98,13.51],[5.9,0]],"id":41762283},{"atb":[[1.01,2]],"id":40494181},{"atl":[[2.54,0],[2.74,0],[1.97,0],[2.14,0],[2.34,0]],"id":40494181}],"con":true,"img":false}]}
{"op":"mcm","clk":"5306902792","pt":1646109774232,"mc":[{"id":"1.195395430","rc":[{"atb":[[2.82,0]],"id":38206560}],"con":true,"img":false}]}
{"op":"mcm","clk":"5306902796","pt":1646109774286,"mc":[{"id":"1.195395430","rc":[{"atb":[[2.36,29.62]],"id":38206560}],"con":true,"img":false}]}
{"op":"mcm","clk":"5306902831","pt":1646109775773,"mc":[{"id":"1.195395430","rc":[{"atb":[[2.88,4.44]],"id":38206560}],"con":true,"img":false}]}
{"op":"mcm","clk":"5306903019","pt":1646109780806,"mc":[{"id":"1.195395430","rc":[{"atb":[[2.16,2],[2.48,0]],"id":38206560},{"atl":[[16,0],[17.5,2]],"id":38206560},{"atl":[[4.5,0],[4.7,2]],"id":41762283}],"con":true,"img":false}]}
{"op":"mcm","clk":"5306903158","pt":1646109784601,"mc":[{"id":"1.195395430","rc":[{"atb":[[1.66,0]],"id":41762283}],"con":true,"img":false}]}
{"op":"mcm","clk":"5306903161","pt":1646109784704,"mc":[{"id":"1.195395430","rc":[{"atb":[[1.57,60.93]],"id":41762283}],"con":true,"img":false}]}
{"op":"mcm","clk":"5306903234","pt":1646109787830,"mc":[{"id":"1.195395430","rc":[{"atb":[[1.7,11.93]],"id":41762283}],"con":true,"img":false}]}
{"op":"mcm","clk":"5306903274","pt":1646109788802,"mc":[{"id":"1.195395430","rc":[{"atb":[[1.71,0]],"id":37265273}],"con":true,"img":false}]}
{"op":"mcm","clk":"5306903276","pt":1646109788907,"mc":[{"id":"1.195395430","rc":[{"atb":[[1.76,64.67]],"id":37265273}],"con":true,"img":false}]}
{"op":"mcm","clk":"5306903311","pt":1646109790797,"mc":[{"id":"1.195395430","rc":[{"atb":[[1.75,24.64]],"id":37265273}],"con":true,"img":false}]}
{"op":"mcm","clk":"5306903334","pt":1646109792135,"mc":[{"id":"1.195395430","rc":[{"atb":[[2.4,86.21],[2.5,80.46],[2.6,37.71]],"id":38206560},{"atl":[[6.2,2.3],[10.5,2.52],[21,2.4],[8.2,1.66],[15.5,1.65]],"id":38206560},{"atb":[[1.6,201.16],[1.55,219.45],[1.65,92.84]],"id":41762283},{"atl":[[3.45,4.89],[3.95,8.13],[4.9,6.15],[2.98,19.58],[5.9,9.79]],"id":41762283},{"atb":[[1.01,30177.21]],"id":40494181},{"atl":[[2.54,15.59],[2.74,27.59],[1.97,12.37],[2.14,10.52],[2.34,17.91]],"id":40494181}],"con":true,"img":false}]}
{"op":"mcm","clk":"5306903353","pt":1646109792645,"mc":[{"id":"1.195395430","rc":[{"atb":[[2.88,0]],"id":38206560}],"con":true,"img":false}]}
{"op":"mcm","clk":"5306903421","pt":1646109795822,"mc":[{"id":"1.195395430","rc":[{"atb":[[1.55,0],[1.54,2]],"id":37265273},{"atb":[[2.18,2],[2.16,0]],"id":38206560},{"atl":[[17.5,0],[13.5,2]],"id":38206560},{"atl":[[4.5,2],[4.7,0]],"id":41762283}],"con":true,"img":false}]}
{"op":"mcm","clk":"5306903436","pt":1646109796948,"mc":[{"id":"1.195395430","rc":[{"atb":[[1.8,9.32]],"id":37265273}],"con":true,"img":false}]}
{"op":"mcm","clk":"5306903466","pt":1646109797821,"mc":[{"id":"1.195395430","rc":[{"atb":[[1.7,0]],"id":41762283}],"con":true,"img":false}]}
{"op":"mcm","clk":"5306903508","pt":1646109799918,"mc":[{"id":"1.195395430","rc":[{"atb":[[2.66,4.49]],"id":38206560},{"atb":[[1.69,10.8]],"id":41762283}],"con":true,"img":false}]}
{"op":"mcm","clk":"5306903549","pt":1646109801866,"mc":[{"id":"1.195395430","rc":[{"atb":[[1.76,3.74]],"id":37265273}],"con":true,"img":false}]}
{"op":"mcm","clk":"5306903551","pt":1646109801918,"mc":[{"id":"1.195395430","rc":[{"atb":[[1.71,60.93]],"id":37265273}],"con":true,"img":false}]}
{"op":"mcm","clk":"5306903576","pt":1646109803044,"mc":[{"id":"1.195395430","rc":[{"atb":[[1.8,0]],"id":37265273}],"con":true,"img":false}]}
{"op":"mcm","clk":"5306903728","pt":1646109809042,"mc":[{"id":"1.195395430","rc":[{"atb":[[1.75,34.59]],"id":37265273}],"con":true,"img":false}]}
{"op":"mcm","clk":"5306903755","pt":1646109810064,"mc":[{"id":"1.195395430","rc":[{"atb":[[2.66,9.51]],"id":38206560}],"con":true,"img":false}]}
{"op":"mcm","clk":"5306903761","pt":1646109810269,"mc":[{"id":"1.195395430","rc":[{"atb":[[1.69,22.9]],"id":41762283}],"con":true,"img":false}]}
{"op":"mcm","clk":"5306903783","pt":1646109810934,"mc":[{"id":"1.195395430","rc":[{"atb":[[1.55,2],[1.54,0]],"id":37265273},{"atb":[[2.18,0],[2.26,2]],"id":38206560},{"atb":[[1.54,67.27],[1.53,110.15]],"id":41762283}],"con":true,"img":false}]}
{"op":"mcm","clk":"5306904026","pt":1646109823683,"mc":[{"id":"1.195395430","rc":[{"spn":4.33,"spf":"NaN","id":38206560},{"atb":[[1.57,0]],"id":41762283}],"con":true,"img":false}]}
{"op":"mcm","clk":"5306904030","pt":1646109823735,"mc":[{"id":"1.195395430","rc":[{"atb":[[1.66,60.93]],"id":41762283}],"con":true,"img":false}]}
{"op":"mcm","clk":"5306904123","pt":1646109827082,"mc":[{"id":"1.195395430","rc":[{"atb":[[1.69,12.09]],"id":41762283}],"con":true,"img":false}]}
{"op":"mcm","clk":"5306904230","pt":1646109832300,"mc":[{"id":"1.195395430","rc":[{"atb":[[2.3,0],[2.2,0],[2.1,0]],"id":39520250},{"atl":[[5.6,13.63],[7.2,0],[18,0],[9.2,0],[13,0]],"id":39520250},{"atb":[[2.86,0],[3.15,0],[2.96,0]],"id":36104895},{"atl":[[16,0],[34,0],[11,4.32],[22,0],[8.4,8.7]],"id":36104895},{"atb":[[2.4,0],[2.36,0],[2.5,0],[2.6,0]],"id":38206560},{"atl":[[6.2,0],[10.5,0],[21,0],[8.2,0],[15.5,0]],"id":38206560}],"con":true,"img":false}]}
{"op":"mcm","clk":"5306904233","pt":1646109832352,"mc":[{"id":"1.195395430","rc":[{"atb":[[2.62,29.62]],"id":38206560}],"con":true,"img":false}]}
{"op":"mcm","clk":"5306904245","pt":1646109832870,"mc":[{"id":"1.195395430","rc":[{"atb":[[1.7,10.65]],"id":41762283}],"con":true,"img":false}]}
{"op":"mcm","clk":"5306904248","pt":1646109832973,"mc":[{"id":"1.195395430","rc":[{"atb":[[2.66,5.02]],"id":38206560}],"con":true,"img":false}]}
{"op":"mcm","clk":"5306904266","pt":1646109833487,"mc":[{"id":"1.195395430","rc":[{"atb":[[1.92,45.96],[2.32,0],[2.12,0]],"id":39520250},{"atb":[[3.2,3.79]],"id":36104895},{"atb":[[2.62,0]],"id":38206560}],"con":true,"img":false}]}
{"op":"mcm","clk":"5306904272","pt":1646109833586,"mc":[{"id":"1.195395430","rc":[{"atb":[[2.12,40.81]],"id":39520250},{"atb":[[2.74,20.6]],"id":36104895},{"atb":[[2.36,29.62]],"id":38206560}],"con":true,"img":false}]}
{"op":"mcm","clk":"5306904329","pt":1646109836069,"mc":[{"id":"1.195395430","rc":[{"atb":[[2.38,7.72]],"id":39520250},{"atb":[[3.25,0]],"id":36104895}],"con":true,"img":false}]}
{"op":"mcm","clk":"5306904381","pt":1646109838070,"mc":[{"id":"1.195395430","rc":[{"atb":[[1.71,0]],"id":37265273}],"con":true,"img":false}]}
{"op":"mcm","clk":"5306904384","pt":1646109838173,"mc":[{"id":"1.195395430","rc":[{"atb":[[1.76,64.67]],"id":37265273}],"con":true,"img":false}]}
{"op":"mcm","clk":"5306904416","pt":1646109839197,"mc":[{"id":"1.195395430","rc":[{"atb":[[1.75,24.64]],"id":37265273}],"con":true,"img":false}]}
{"op":"mcm","clk":"5306904447","pt":1646109840382,"mc":[{"id":"1.195395430","rc":[{"atb":[[1.75,13.51]],"id":37265273},{"atb":[[1.69,0]],"id":41762283}],"con":true,"img":false}]}
{"op":"mcm","clk":"5306904464","pt":1646109841104,"mc":[{"id":"1.195395430","rc":[{"atb":[[1.83,2],[1.99,0]],"id":39520250},{"atl":[[11.5,0],[15,2]],"id":39520250},{"atb":[[1.55,0],[1.54,2]],"id":37265273},{"atb":[[2.44,31.74],[2.76,0]],"id":36104895},{"atb":[[2.04,2],[2.26,0]],"id":38206560},{"atl":[[17.5,2],[13.5,0]],"id":38206560},{"atb":[[1.54,69.27],[1.53,108.15]],"id":41762283}],"con":true,"img":false}]}
{"op":"mcm","clk":"5306904493","pt":1646109841978,"mc":[{"id":"1.195395430","rc":[{"atb":[[2.16,6.42]],"id":39520250}],"con":true,"img":false}]}
{"op":"mcm","clk":"5306904528","pt":1646109843210,"mc":[{"id":"1.195395430","rc":[{"atb":[[2.06,113.87],[2.26,47.89],[2.16,110.48]],"id":39520250},{"atl":[[5.6,16.24],[7.2,1.93],[18,2.82],[9.2,2.92],[13,2]],"id":39520250},{"atb":[[3.1,57.47],[3.35,25.68],[2.94,62.21]],"id":36104895},{"atl":[[17,1.5],[38,1.29],[12,4.87],[24,1.04],[8.8,1.54]],"id":36104895},{"atb":[[2.8,33.52],[2.6,75.43],[2.7,70.99]],"id":38206560},{"atl":[[7.2,1.93],[18,1.41],[9.2,1.46],[13,2],[26,1.91]],"id":38206560}],"con":true,"img":false}]}
{"op":"mcm","clk":"5306904586","pt":1646109845107,"mc":[{"id":"1.195395430","rc":[{"atb":[[2.16,104.05]],"id":39520250},{"atb":[[1.8,9.32]],"id":37265273}],"con":true,"img":false}]}
{"op":"mcm","clk":"5306904619","pt":1646109847106,"mc":[{"id":"1.195395430","rc":[{"atb":[[2.38,1.66]],"id":39520250},{"atb":[[3.2,0]],"id":36104895},{"atb":[[2.66,0]],"id":38206560}],"con":true,"img":false}]}
{"op":"mcm","clk":"5306904626","pt":1646109847307,"mc":[{"id":"1.195395430","rc":[{"atb":[[1.7,22.58]],"id":41762283}],"con":true,"img":false}]}
{"op":"mcm","clk":"5306904689","pt":1646109850178,"mc":[{"id":"1.195395430","rc":[{"atb":[[1.76,3.74]],"id":37265273}],"con":true,"img":false}]}
{"op":"mcm","clk":"5306904690","pt":1646109850281,"mc":[{"id":"1.195395430","rc":[{"atb":[[1.71,60.93]],"id":37265273}],"con":true,"img":false}]}
{"op":"mcm","clk":"5306904708","pt":1646109851203,"mc":[{"id":"1.195395430","rc":[{"atb":[[1.8,0]],"id":37265273},{"atb":[[3.45,4.71]],"id":36104895},{"atb":[[2.86,4.01]],"id":38206560}],"con":true,"img":false}]}
{"op":"mcm","clk":"5306904709","pt":1646109851306,"mc":[{"id":"1.195395430","rc":[{"atb":[[2.32,5.65]],"id":39520250}],"con":true,"img":false}]}
{"op":"mcm","clk":"5306904802","pt":1646109856118,"mc":[{"id":"1.195395430","rc":[{"atb":[[1.83,0],[1.97,2]],"id":39520250},{"atl":[[11.5,2],[15,0]],"id":39520250},{"atb":[[1.55,2],[1.54,0]],"id":37265273},{"atb":[[2.72,2],[2.44,29.74]],"id":36104895},{"atl":[[19,2],[20,0]],"id":36104895},{"atb":[[2.04,0],[2.38,2]],"id":38206560},{"atl":[[16,2],[17.5,0]],"id":38206560}],"con":true,"img":false}]}
{"op":"mcm","clk":"5306904838","pt":1646109857095,"mc":[{"id":"1.195395430","rc":[{"atb":[[1.75,23.46]],"id":37265273}],"con":true,"img":false}]}
{"op":"mcm","clk":"5306904870","pt":1646109858680,"mc":[{"id":"1.195395430","rc":[{"atb":[[2.86,8.5]],"id":38206560}],"con":true,"img":false}]}
{"op":"mcm","clk":"5306904871","pt":1646109858783,"mc":[{"id":"1.195395430","rc":[{"atb":[[2.32,11.98]],"id":39520250}],"con":true,"img":false}]}
{"op":"mcm","clk":"5306904875","pt":1646109858988,"mc":[{"id":"1.195395430","rc":[{"atb":[[3.45,8.11]],"id":36104895}],"con":true,"img":false}]}
{"op":"mcm","clk":"5306904996","pt":1646109864822,"mc":[{"id":"1.195395430","rc":[{"atb":[[1.75,34.59]],"id":37265273}],"con":true,"img":false}]}
{"op":"mcm","clk":"5306905232","pt":1646109874514,"mc":[{"id":"1.195395430","rc":[{"atl":[[3.55,0]],"id":41762283}],"con":true,"img":false}]}
{"op":"mcm","clk":"5306905235","pt":1646109874614,"mc":[{"id":"1.195395430","rc":[{"atl":[[2.96,21.01]],"id":41762283}],"con":true,"img":false}]}
{"op":"mcm","clk":"5306905307","pt":1646109877836,"mc":[{"id":"1.195395430","rc":[{"atb":[[2.12,0]],"id":39520250}],"con":true,"img":false}]}
{"op":"mcm","clk":"5306905309","pt":1646109877890,"mc":[{"id":"1.195395430","rc":[{"atb":[[2.28,40.81]],"id":39520250}],"con":true,"img":false}]}
{"op":"mcm","clk":"5306905322","pt":1646109878708,"mc":[{"id":"1.195395430","rc":[{"atl":[[5.5,9.61]],"id":39520250}],"con":true,"img":false}]}
{"op":"mcm","clk":"5306905323","pt":1646109878813,"mc":[{"id":"1.195395430","rc":[{"atl":[[7.4,0]],"id":39520250}],"con":true,"img":false}]}
{"op":"mcm","clk":"5306905380","pt":1646109881224,"mc":[{"id":"1.195395430","rc":[{"atb":[[2.32,6.32]],"id":39520250}],"con":true,"img":false}]}
{"op":"mcm","clk":"5306905435","pt":1646109883024,"mc":[{"id":"1.195395430","rc":[{"atb":[[2.74,0]],"id":36104895},{"atb":[[2.36,0]],"id":38206560}],"con":true,"img":false}]}
{"op":"mcm","clk":"5306905436","pt":1646109883125,"mc":[{"id":"1.195395430","rc":[{"atb":[[3.4,20.6]],"id":36104895},{"atb":[[2.82,29.62]],"id":38206560}],"con":true,"img":false}]}
{"op":"mcm","clk":"5306905453","pt":1646109884201,"mc":[{"id":"1.195395430","rc":[{"spn":3.94,"spf":"NaN","id":39520250},{"atb":[[2.86,4.49]],"id":38206560},{"spn":4.43,"spf":"NaN","id":38206560}],"con":true,"img":false}]}
{"op":"mcm","clk":"5306905496","pt":1646109886206,"mc":[{"id":"1.195395430","rc":[{"atb":[[1.98,2],[1.97,0]],"id":39520250},{"atl":[[11,2],[11.5,0]],"id":39520250},{"atb":[[2.82,2],[2.72,0]],"id":36104895},{"atb":[[2.38,0],[2.48,2]],"id":38206560}],"con":true,"img":false}]}
{"op":"mcm","clk":"5306905512","pt":1646109887129,"mc":[{"id":"1.195395430","rc":[{"atb":[[2.34,5.56]],"id":39520250}],"con":true,"img":false}]}
{"op":"mcm","clk":"5306905582","pt":1646109890151,"mc":[{"id":"1.195395430","rc":[{"atb":[[2.88,3.96]],"id":38206560}],"con":true,"img":false}]}
{"op":"mcm","clk":"5306905667","pt":1646109893740,"mc":[{"id":"1.195395430","rc":[{"atb":[[2.32,0]],"id":39520250}],"con":true,"img":false}]}
{"op":"mcm","clk":"5306905806","pt":1646109899135,"mc":[{"id":"1.195395430","rc":[{"atb":[[1.92,0]],"id":39520250}],"con":true,"img":false}]}
{"op":"mcm","clk":"5306905808","pt":1646109899235,"mc":[{"id":"1.195395430","rc":[{"atb":[[2.08,45.96]],"id":39520250},{"atb":[[2.86,0]],"id":38206560}],"con":true,"img":false}]}
{"op":"mcm","clk":"5306905811","pt":1646109899338,"mc":[{"id":"1.195395430","rc":[{"atb":[[2.34,11.79]],"id":39520250}],"con":true,"img":false}]}
{"op":"mcm","clk":"5306905901","pt":1646109903052,"mc":[{"id":"1.195395430","rc":[{"atb":[[1.54,2]],"id":41762283}],"con":true,"img":false}]}
{"op":"mcm","clk":"5306905905","pt":1646109903158,"mc":[{"id":"1.195395430","rc":[{"atb":[[1.56,67.27]],"id":41762283}],"con":true,"img":false}]}
{"op":"mcm","clk":"5306905984","pt":1646109905778,"mc":[{"id":"1.195395430","rc":[{"atb":[[2.88,8.4]],"id":38206560}],"con":true,"img":false}]}
{"op":"mcm","clk":"5306906016","pt":1646109906962,"mc":[{"id":"1.195395430","rc":[{"atb":[[1.71,0]],"id":37265273}],"con":true,"img":false}]}
{"op":"mcm","clk":"5306906021","pt":1646109907065,"mc":[{"id":"1.195395430","rc":[{"atb":[[1.76,64.67]],"id":37265273}],"con":true,"img":false}]}
{"op":"mcm","clk":"5306906056","pt":1646109908448,"mc":[{"id":"1.195395430","rc":[{"atb":[[1.75,24.64]],"id":37265273}],"con":true,"img":false}]}
{"op":"mcm","clk":"5306906184","pt":1646109914077,"mc":[{"id":"1.195395430","rc":[{"atl":[[11,0]],"id":36104895}],"con":true,"img":false}]}
{"op":"mcm","clk":"5306906185","pt":1646109914179,"mc":[{"id":"1.195395430","rc":[{"atl":[[8.2,4.32]],"id":36104895}],"con":true,"img":false}]}
{"op":"mcm","clk":"5306906196","pt":1646109914742,"mc":[{"id":"1.195395430","rc":[{"atb":[[1.8,9.32]],"id":37265273}],"con":true,"img":false}]}
{"op":"mcm","clk":"5306906263","pt":1646109916449,"mc":[{"id":"1.195395430","rc":[{"atb":[[1.59,2],[1.55,0]],"id":37265273},{"atl":[[19,0],[15,2]],"id":36104895}],"con":true,"img":false}]}
{"op":"mcm","clk":"5306906338","pt":1646109918773,"mc":[{"id":"1.195395430","rc":[{"atb":[[1.76,3.74]],"id":37265273}],"con":true,"img":false}]}
{"op":"mcm","clk":"5306906341","pt":1646109918875,"mc":[{"id":"1.195395430","rc":[{"atb":[[1.71,60.93]],"id":37265273}],"con":true,"img":false}]}
{"op":"mcm","clk":"5306906386","pt":1646109920267,"mc":[{"id":"1.195395430","rc":[{"atb":[[1.8,0]],"id":37265273}],"con":true,"img":false}]}
{"op":"mcm","clk":"5306906606","pt":1646109927301,"mc":[{"id":"1.195395430","rc":[{"atb":[[1.75,34.59]],"id":37265273}],"con":true,"img":false}]}
{"op":"mcm","clk":"5306906697","pt":1646109931506,"mc":[{"id":"1.195395430","rc":[{"atb":[[1.55,2]],"id":37265273}],"con":true,"img":false}]}
{"op":"mcm","clk":"5306906699","pt":1646109931609,"mc":[{"id":"1.195395430","rc":[{"atb":[[1.59,0]],"id":37265273}],"con":true,"img":false}]}
{"op":"mcm","clk":"5306907233","pt":1646109956644,"mc":[{"id":"1.195395430","rc":[{"atb":[[1.71,0]],"id":37265273},{"spn":5.82,"spf":"NaN","id":36104895},{"spn":4.44,"spf":"NaN","id":38206560}],"con":true,"img":false}]}
{"op":"mcm","clk":"5306907235","pt":1646109956743,"mc":[{"id":"1.195395430","rc":[{"atb":[[1.76,64.67]],"id":37265273}],"con":true,"img":false}]}
{"op":"mcm","clk":"5306907281","pt":1646109959254,"mc":[{"id":"1.195395430","rc":[{"atb":[[1.75,23.46]],"id":37265273}],"con":true,"img":false}]}
{"op":"mcm","clk":"5306907312","pt":1646109960436,"mc":[{"id":"1.195395430","rc":[{"atb":[[1.75,13.51]],"id":37265273}],"con":true,"img":false}]}
{"op":"mcm","clk":"5306907331","pt":1646109961617,"mc":[{"id":"1.195395430","rc":[{"atb":[[1.55,0],[1.54,2]],"id":37265273}],"con":true,"img":false}]}
{"op":"mcm","clk":"5306907415","pt":1646109966142,"mc":[{"id":"1.195395430","rc":[{"atb":[[1.8,9.32]],"id":37265273}],"con":true,"img":false}]}
{"op":"mcm","clk":"5306907482","pt":1646109969169,"mc":[{"id":"1.195395430","rc":[{"atb":[[1.76,3.74]],"id":37265273}],"con":true,"img":false}]}
{"op":"mcm","clk":"5306907483","pt":1646109969270,"mc":[{"id":"1.195395430","rc":[{"atb":[[1.71,60.93]],"id":37265273}],"con":true,"img":false}]}
{"op":"mcm","clk":"5306907536","pt":1646109971532,"mc":[{"id":"1.195395430","rc":[{"atb":[[1.8,0]],"id":37265273}],"con":true,"img":false}]}
{"op":"mcm","clk":"5306907649","pt":1646109976664,"mc":[{"id":"1.195395430","rc":[{"atb":[[1.55,2],[1.54,0]],"id":37265273}],"con":true,"img":false}]}
{"op":"mcm","clk":"5306907672","pt":1646109977333,"mc":[{"id":"1.195395430","rc":[{"atb":[[1.75,23.46]],"id":37265273}],"con":true,"img":false}]}
{"op":"mcm","clk":"5306907769","pt":1646109983275,"mc":[{"id":"1.195395430","rc":[{"atb":[[1.75,34.59]],"id":37265273}],"con":true,"img":false}]}
{"op":"mcm","clk":"5306908208","pt":1646110008295,"mc":[{"id":"1.195395430","rc":[{"atl":[[85,5]],"id":37265273},{"atl":[[85,5]],"id":38206580},{"atl":[[85,5]],"id":41762283},{"atl":[[85,10]],"id":40494181}],"con":true,"img":false}]}
{"op":"mcm","clk":"5306908331","pt":1646110012904,"mc":[{"id":"1.195395430","rc":[{"atb":[[1.71,0]],"id":37265273}],"con":true,"img":false}]}
{"op":"mcm","clk":"5306908334","pt":1646110013005,"mc":[{"id":"1.195395430","rc":[{"atb":[[1.76,64.67]],"id":37265273}],"con":true,"img":false}]}
{"op":"mcm","clk":"5306908344","pt":1646110013517,"mc":[{"id":"1.195395430","rc":[{"atb":[[1.75,24.64]],"id":37265273}],"con":true,"img":false}]}
{"op":"mcm","clk":"5306908501","pt":1646110019510,"mc":[{"id":"1.195395430","rc":[{"atb":[[1.8,9.32]],"id":37265273},{"spn":2.45,"spf":"NaN","id":37265273}],"con":true,"img":false}]}
{"op":"mcm","clk":"5306908558","pt":1646110021912,"mc":[{"id":"1.195395430","rc":[{"atb":[[1.59,2],[1.55,0]],"id":37265273}],"con":true,"img":false}]}
{"op":"mcm","clk":"5306908623","pt":1646110024416,"mc":[{"id":"1.195395430","rc":[{"atb":[[1.76,3.74]],"id":37265273}],"con":true,"img":false}]}
{"op":"mcm","clk":"5306908628","pt":1646110024518,"mc":[{"id":"1.195395430","rc":[{"atb":[[1.71,60.93]],"id":37265273}],"con":true,"img":false}]}
{"op":"mcm","clk":"5306908674","pt":1646110025749,"mc":[{"id":"1.195395430","rc":[{"atb":[[1.8,0]],"id":37265273}],"con":true,"img":false}]}
{"op":"mcm","clk":"5306908764","pt":1646110028457,"mc":[{"id":"1.195395430","rc":[{"atb":[[2.38,0]],"id":39520250},{"atb":[[4.8,0]],"id":27701417},{"atb":[[2.58,0]],"id":38206560}],"con":true,"img":false}]}
{"op":"mcm","clk":"5306908766","pt":1646110028610,"mc":[{"id":"1.195395430","rc":[{"atb":[[2.36,1.66]],"id":39520250},{"atb":[[4.3,1.66]],"id":27701417},{"atb":[[2.9,1.66]],"id":38206560}],"con":true,"img":false}]}
{"op":"mcm","clk":"5306908829","pt":1646110031426,"mc":[{"id":"1.195395430","rc":[{"atb":[[1.75,34.59]],"id":37265273}],"con":true,"img":false}]}
{"op":"mcm","clk":"5306908972","pt":1646110036941,"mc":[{"id":"1.195395430","rc":[{"atb":[[1.59,0],[1.55,2]],"id":37265273},{"atb":[[2.5,2],[2.48,0]],"id":38206560}],"con":true,"img":false}]}
{"op":"mcm","clk":"5306909620","pt":1646110060564,"mc":[{"id":"1.195395430","rc":[{"atb":[[1.71,0]],"id":37265273}],"con":true,"img":false}]}
{"op":"mcm","clk":"5306909623","pt":1646110060665,"mc":[{"id":"1.195395430","rc":[{"atb":[[1.76,64.67]],"id":37265273}],"con":true,"img":false}]}
{"op":"mcm","clk":"5306909645","pt":1646110061687,"mc":[{"id":"1.195395430","rc":[{"atb":[[1.75,24.64]],"id":37265273}],"con":true,"img":false}]}
{"op":"mcm","clk":"5306909657","pt":1646110062095,"mc":[{"id":"1.195395430","rc":[{"atb":[[1.75,13.51]],"id":37265273}],"con":true,"img":false}]}
{"op":"mcm","clk":"5306909762","pt":1646110067064,"mc":[{"id":"1.195395430","rc":[{"atb":[[1.54,2]],"id":37265273}],"con":true,"img":false}]}
{"op":"mcm","clk":"5306909765","pt":1646110067167,"mc":[{"id":"1.195395430","rc":[{"atb":[[1.55,0]],"id":37265273}],"con":true,"img":false}]}
{"op":"mcm","clk":"5306909777","pt":1646110067473,"mc":[{"id":"1.195395430","rc":[{"atb":[[1.8,9.32]],"id":37265273}],"con":true,"img":false}]}
{"op":"mcm","clk":"5306909934","pt":1646110073304,"mc":[{"id":"1.195395430","rc":[{"atb":[[1.76,3.74]],"id":37265273}],"con":true,"img":false}]}
{"op":"mcm","clk":"5306909939","pt":1646110073405,"mc":[{"id":"1.195395430","rc":[{"atb":[[1.71,60.93]],"id":37265273}],"con":true,"img":false}]}
{"op":"mcm","clk":"5306910084","pt":1646110076999,"mc":[{"id":"1.195395430","rc":[{"atb":[[1.8,0]],"id":37265273}],"con":true,"img":false}]}
{"op":"mcm","clk":"5306910187","pt":1646110082109,"mc":[{"id":"1.195395430","rc":[{"spn":3.93,"spf":"NaN","id":39520250},{"atb":[[1.55,2],[1.54,0]],"id":37265273},{"spn":2.43,"spf":"NaN","id":37265273},{"spn":9.15,"spf":"NaN","id":27701417},{"spn":4.45,"spf":"NaN","id":38206560}],"con":true,"img":false}]}
{"op":"mcm","clk":"5306910197","pt":1646110082516,"mc":[{"id":"1.195395430","rc":[{"atb":[[1.75,23.46]],"id":37265273}],"con":true,"img":false}]}
{"op":"mcm","clk":"5306910406","pt":1646110091825,"mc":[{"id":"1.195395430","rc":[{"atb":[[1.75,34.59]],"id":37265273}],"con":true,"img":false}]}
{"op":"mcm","clk":"5306912071","pt":1646110121079,"mc":[{"id":"1.195395430","rc":[{"atb":[[1.71,0]],"id":37265273}],"con":true,"img":false}]}
{"op":"mcm","clk":"5306912076","pt":1646110121181,"mc":[{"id":"1.195395430","rc":[{"atb":[[1.76,64.67]],"id":37265273}],"con":true,"img":false}]}
{"op":"mcm","clk":"5306912090","pt":1646110121546,"mc":[{"id":"1.195395430","rc":[{"atb":[[1.75,24.64]],"id":37265273}],"con":true,"img":false}]}
{"op":"mcm","clk":"5306912302","pt":1646110126989,"mc":[{"id":"1.195395430","rc":[{"atb":[[1.8,9.32]],"id":37265273}],"con":true,"img":false}]}
{"op":"mcm","clk":"5306912322","pt":1646110127350,"mc":[{"id":"1.195395430","rc":[{"atb":[[1.59,2],[1.55,0]],"id":37265273}],"con":true,"img":false}]}
{"op":"mcm","clk":"5306912505","pt":1646110132064,"mc":[{"id":"1.195395430","rc":[{"atb":[[1.76,3.74]],"id":37265273}],"con":true,"img":false}]}
{"op":"mcm","clk":"5306912509","pt":1646110132167,"mc":[{"id":"1.195395430","rc":[{"atb":[[1.71,60.93]],"id":37265273}],"con":true,"img":false}]}
{"op":"mcm","clk":"5306912544","pt":1646110132988,"mc":[{"id":"1.195395430","rc":[{"atb":[[1.8,0]],"id":37265273}],"con":true,"img":false}]}
{"op":"mcm","clk":"5306912769","pt":1646110138989,"mc":[{"id":"1.195395430","rc":[{"atb":[[1.75,34.59]],"id":37265273}],"con":true,"img":false}]}
{"op":"mcm","clk":"5306912901","pt":1646110142487,"mc":[{"id":"1.195395430","rc":[{"atb":[[1.59,0],[1.55,2]],"id":37265273}],"con":true,"img":false}]}
{"op":"mcm","clk":"5306913713","pt":1646110167209,"mc":[{"id":"1.195395430","rc":[{"atb":[[1.71,0]],"id":37265273}],"con":true,"img":false}]}
{"op":"mcm","clk":"5306913719","pt":1646110167312,"mc":[{"id":"1.195395430","rc":[{"atb":[[1.76,64.67]],"id":37265273}],"con":true,"img":false}]}
{"op":"mcm","clk":"5306913793","pt":1646110169107,"mc":[{"id":"1.195395430","rc":[{"atb":[[1.75,24.64]],"id":37265273}],"con":true,"img":false}]}
{"op":"mcm","clk":"5306913895","pt":1646110172028,"mc":[{"id":"1.195395430","rc":[{"atb":[[1.75,13.51]],"id":37265273}],"con":true,"img":false}]}
{"op":"mcm","clk":"5306913911","pt":1646110172645,"mc":[{"id":"1.195395430","rc":[{"atb":[[1.55,0],[1.54,2]],"id":37265273}],"con":true,"img":false}]}
{"op":"mcm","clk":"5306913974","pt":1646110175053,"mc":[{"id":"1.195395430","rc":[{"atb":[[1.8,9.32]],"id":37265273}],"con":true,"img":false}]}
{"op":"mcm","clk":"5306914136","pt":1646110179458,"mc":[{"id":"1.195395430","rc":[{"atb":[[1.76,3.74]],"id":37265273}],"con":true,"img":false}]}
{"op":"mcm","clk":"5306914140","pt":1646110179559,"mc":[{"id":"1.195395430","rc":[{"atb":[[1.71,60.93]],"id":37265273}],"con":true,"img":false}]}
{"op":"mcm","clk":"5306914190","pt":1646110181056,"mc":[{"id":"1.195395430","rc":[{"atb":[[1.8,0]],"id":37265273}],"con":true,"img":false}]}
{"op":"mcm","clk":"5306914241","pt":1646110182452,"mc":[{"id":"1.195395430","rc":[{"atb":[[1.23,0]],"id":39520250},{"atb":[[1.23,0]],"id":36104895},{"atb":[[1.23,0]],"id":38206580},{"atb":[[1.23,0]],"id":27701417},{"atb":[[1.23,0]],"id":38206560},{"atb":[[1.23,0]],"id":41762283}],"con":true,"img":false}]}
{"op":"mcm","clk":"5306914251","pt":1646110182855,"mc":[{"id":"1.195395430","rc":[{"atb":[[1.23,250]],"id":39520250},{"atb":[[1.23,250]],"id":36104895},{"atb":[[1.23,250]],"id":38206580},{"atb":[[1.23,250]],"id":27701417},{"atb":[[1.23,250]],"id":38206560},{"atb":[[1.23,250]],"id":41762283}],"con":true,"img":false}]}
{"op":"mcm","clk":"5306914358","pt":1646110187070,"mc":[{"id":"1.195395430","rc":[{"atb":[[1.75,23.46]],"id":37265273}],"con":true,"img":false}]}
{"op":"mcm","clk":"5306914381","pt":1646110187736,"mc":[{"id":"1.195395430","rc":[{"atb":[[1.55,2],[1.54,0]],"id":37265273}],"con":true,"img":false}]}
{"op":"mcm","clk":"5306914732","pt":1646110198467,"mc":[{"id":"1.195395430","rc":[{"atb":[[1.75,34.59]],"id":37265273}],"con":true,"img":false}]}
{"op":"mcm","clk":"5306914885","pt":1646110203561,"mc":[{"id":"1.195395430","rc":[{"atb":[[1.77,34.59]],"id":37265273},{"atl":[[3.85,32.36]],"id":37265273},{"spn":2.43,"spf":"NaN","id":37265273},{"atb":[[1.26,250]],"id":36104895},{"atl":[[12,13.53]],"id":36104895},{"atb":[[1.86,63.27]],"id":38206580},{"atl":[[4.3,14.34]],"id":38206580},{"atb":[[2.14,87.72]],"id":38206560},{"atl":[[11,8.66]],"id":38206560},{"atb":[[1.35,250]],"id":41762283},{"atl":[[3.2,40.59]],"id":41762283},{"atl":[[1.67,105.45]],"id":40494181}],"con":true,"img":false}]}
{"op":"mcm","clk":"5306914888","pt":1646110203662,"mc":[{"id":"1.195395430","rc":[{"atb":[[2.36,13.45]],"id":39520250},{"atl":[[10,10.82]],"id":39520250},{"atb":[[2.36,73.53]],"id":27701417},{"atl":[[13.5,5.41]],"id":27701417}],"con":true,"img":false}]}
{"op":"mcm","clk":"5306914963","pt":1646110205663,"mc":[{"id":"1.195395430","rc":[{"atl":[[8.2,0]],"id":36104895}],"con":true,"img":false}]}
{"op":"mcm","clk":"5306914969","pt":1646110205767,"mc":[{"id":"1.195395430","rc":[{"atl":[[9,4.32]],"id":36104895}],"con":true,"img":false}]}
{"op":"mcm","clk":"5306915348","pt":1646110217916,"mc":[{"id":"1.195395430","rc":[{"atb":[[1.59,2],[1.55,0]],"id":37265273},{"atl":[[15,0],[15.5,2]],"id":36104895},{"atl":[[95,0.5],[25,2]],"id":27701417},{"atl":[[4,2],[4.5,0]],"id":41762283},{"atl":[[1.83,45.26],[1.99,0]],"id":40494181}],"con":true,"img":false}]}
{"op":"mcm","clk":"5306915677","pt":1646110228310,"mc":[{"id":"1.195395430","rc":[{"atb":[[1.71,0]],"id":37265273}],"con":true,"img":false}]}
{"op":"mcm","clk":"5306915681","pt":1646110228413,"mc":[{"id":"1.195395430","rc":[{"atb":[[1.78,60.93]],"id":37265273}],"con":true,"img":false}]}
{"op":"mcm","clk":"5306915683","pt":1646110228516,"mc":[{"id":"1.195395430","rc":[{"atb":[[1.79,34.59],[1.77,0]],"id":37265273}],"con":true,"img":false}]}
{"op":"mcm","clk":"5306915763","pt":1646110230717,"mc":[{"id":"1.195395430","rc":[{"atl":[[1.83,2]],"id":40494181}],"con":true,"img":false}]}
{"op":"mcm","clk":"5306915767","pt":1646110230823,"mc":[{"id":"1.195395430","rc":[{"atl":[[1.64,43.26]],"id":40494181}],"con":true,"img":false}]}
{"op":"mcm","clk":"5306915825","pt":1646110232842,"mc":[{"id":"1.195395430","rc":[{"atl":[[12,3.93],[14,2.7]],"id":27701417},{"atl":[[7.4,6.75],[9.4,0]],"id":38206560}],"con":true,"img":false}]}
{"op":"mcm","clk":"5306915828","pt":1646110232944,"mc":[{"id":"1.195395430","rc":[{"atb":[[1.59,0],[1.6,404.33]],"id":37265273},{"atl":[[1.83,0],[1.8,2]],"id":40494181}],"con":true,"img":false}]}
{"op":"mcm","clk":"5306915833","pt":1646110233045,"mc":[{"id":"1.195395430","rc":[{"atl":[[11.5,3.93],[13.5,0]],"id":27701417}],"con":true,"img":false}]}
{"op":"mcm","clk":"5306916211","pt":1646110244137,"mc":[{"id":"1.195395430","rc":[{"atb":[[1.75,24.64]],"id":37265273}],"con":true,"img":false}]}
{"op":"mcm","clk":"5306916222","pt":1646110244343,"mc":[{"id":"1.195395430","rc":[{"atb":[[1.75,13.51]],"id":37265273}],"con":true,"img":false}]}
{"op":"mcm","clk":"5306916329","pt":1646110247934,"mc":[{"id":"1.195395430","rc":[{"atl":[[24,2],[25,0]],"id":27701417},{"atl":[[16,0],[11.5,2]],"id":38206560}],"con":true,"img":false}]}
{"op":"mcm","clk":"5306916380","pt":1646110249832,"mc":[{"id":"1.195395430","rc":[{"atb":[[1.82,10.18]],"id":37265273}],"con":true,"img":false}]}
{"op":"mcm","clk":"5306916395","pt":1646110250244,"mc":[{"id":"1.195395430","rc":[{"atb":[[1.82,19.28]],"id":37265273}],"con":true,"img":false}]}
{"op":"mcm","clk":"5306916529","pt":1646110254760,"mc":[{"id":"1.195395430","rc":[{"atb":[[1.23,250]],"id":37265273}],"con":true,"img":false}]}
{"op":"mcm","clk":"5306916587","pt":1646110257540,"mc":[{"id":"1.195395430","rc":[{"atb":[[1.78,0]],"id":37265273},{"atb":[[2.1,0]],"id":38206560}],"con":true,"img":false}]}
{"op":"mcm","clk":"5306916594","pt":1646110257642,"mc":[{"id":"1.195395430","rc":[{"atb":[[1.8,60.93]],"id":37265273},{"atb":[[2.16,33.52]],"id":38206560}],"con":true,"img":false}]}
{"op":"mcm","clk":"5306916625","pt":1646110258770,"mc":[{"id":"1.195395430","rc":[{"atb":[[1.61,0]],"id":37265273}],"con":true,"img":false}]}
{"op":"mcm","clk":"5306916629","pt":1646110258871,"mc":[{"id":"1.195395430","rc":[{"atb":[[1.66,67.22]],"id":37265273}],"con":true,"img":false}]}
{"op":"mcm","clk":"5306916659","pt":1646110259845,"mc":[{"id":"1.195395430","rc":[{"atb":[[2.18,35.69]],"id":39520250},{"atl":[[7.2,8.96]],"id":39520250},{"atl":[[10,4.86]],"id":36104895},{"atl":[[5,10.81]],"id":38206580},{"atl":[[8.4,5.4]],"id":38206560},{"atl":[[1.85,46.23]],"id":40494181}],"con":true,"img":false}]}
{"op":"mcm","clk":"5306916660","pt":1646110259948,"mc":[{"id":"1.195395430","rc":[{"atb":[[2.08,0]],"id":39520250},{"atl":[[8.8,0]],"id":39520250},{"atl":[[12,9.75]],"id":36104895},{"atl":[[6.2,0]],"id":38206580},{"atl":[[9.8,0]],"id":38206560},{"atl":[[2.1,0]],"id":40494181}],"con":true,"img":false}]}
{"op":"mcm","clk":"5306916662","pt":1646110260051,"mc":[{"id":"1.195395430","rc":[{"atl":[[5.4,10.91]],"id":37265273}],"con":true,"img":false}]}
{"op":"mcm","clk":"5306916664","pt":1646110260154,"mc":[{"id":"1.195395430","rc":[{"atl":[[4.3,10.51]],"id":37265273}],"con":true,"img":false}]}
{"op":"mcm","clk":"5306916719","pt":1646110261750,"mc":[{"id":"1.195395430","rc":[{"atl":[[4.6,0],[3.55,14.77]],"id":41762283}],"con":true,"img":false}]}
{"op":"mcm","clk":"5306916769","pt":1646110263083,"mc":[{"id":"1.195395430","rc":[{"atb":[[1.6,402.33],[1.63,2]],"id":37265273}],"con":true,"img":false}]}
{"op":"mcm","clk":"5306916833","pt":1646110265291,"mc":[{"id":"1.195395430","rc":[{"atb":[[1.82,10.18]],"id":37265273},{"spn":2.46,"spf":"NaN","id":37265273},{"spn":5.92,"spf":"NaN","id":36104895},{"spn":7.9,"spf":"NaN","id":27701417}],"con":true,"img":false}]}
{"op":"mcm","clk":"5306916847","pt":1646110265958,"mc":[{"id":"1.195395430","rc":[{"atl":[[9,0]],"id":36104895}],"con":true,"img":false}]}
{"op":"mcm","clk":"5306916849","pt":1646110266062,"mc":[{"id":"1.195395430","rc":[{"atl":[[8.2,4.32]],"id":36104895}],"con":true,"img":false}]}
{"op":"mcm","clk":"5306916862","pt":1646110266573,"mc":[{"id":"1.195395430","rc":[{"atb":[[1.98,0]],"id":39520250},{"atl":[[11,0]],"id":39520250},{"atb":[[1.63,0]],"id":37265273},{"atl":[[4,0]],"id":37265273},{"atb":[[2.82,0]],"id":36104895},{"atl":[[15.5,0]],"id":36104895},{"atb":[[1.78,0]],"id":38206580},{"atl":[[4.7,0]],"id":38206580},{"atb":[[3.25,0]],"id":27701417},{"atl":[[24,0]],"id":27701417},{"atb":[[2.5,0]],"id":38206560},{"atl":[[11.5,0]],"id":38206560},{"atb":[[1.54,0]],"id":41762283},{"atl":[[4,0]],"id":41762283},{"atb":[[1.01,30175.21]],"id":40494181},{"atl":[[1.8,0]],"id":40494181}],"con":true,"img":false}]}
{"op":"mcm","clk":"5306916866","pt":1646110266777,"mc":[{"id":"1.195395430","rc":[{"atb":[[1.98,2]],"id":39520250},{"atl":[[11,2]],"id":39520250},{"atb":[[1.63,2]],"id":37265273},{"atl":[[4,2]],"id":37265273},{"atb":[[2.82,2]],"id":36104895},{"atl":[[15,2]],"id":36104895},{"atb":[[1.78,2]],"id":38206580},{"atl":[[4.7,2]],"id":38206580},{"atb":[[3.25,2]],"id":27701417},{"atl":[[24,2]],"id":27701417},{"atb":[[2.5,2]],"id":38206560},{"atl":[[11.5,2]],"id":38206560},{"atb":[[1.54,2]],"id":41762283},{"atl":[[4,2]],"id":41762283},{"atb":[[1.01,30177.21]],"id":40494181},{"atl":[[1.8,2]],"id":40494181}],"con":true,"img":false}]}
{"op":"mcm","clk":"5306916874","pt":1646110267185,"mc":[{"id":"1.195395430","rc":[{"atl":[[7.4,0]],"id":38206560}],"con":true,"img":false}]}
{"op":"mcm","clk":"5306916875","pt":1646110267287,"mc":[{"id":"1.195395430","rc":[{"atl":[[5.9,6.75]],"id":38206560}],"con":true,"img":false}]}
{"op":"mcm","clk":"5306916893","pt":1646110267899,"mc":[{"id":"1.195395430","rc":[{"atb":[[1.79,0],[1.81,34.59]],"id":37265273},{"atb":[[1.89,63.27],[1.86,0]],"id":38206580}],"con":true,"img":false}]}
{"op":"mcm","clk":"5306917005","pt":1646110271190,"mc":[{"id":"1.195395430","rc":[{"atb":[[1.84,8.87]],"id":37265273}],"con":true,"img":false}]}
{"op":"mcm","clk":"5306917063","pt":1646110273704,"mc":[{"id":"1.195395430","rc":[{"atb":[[1.82,0]],"id":37265273}],"con":true,"img":false}]}
{"op":"mcm","clk":"5306917192","pt":1646110278372,"mc":[{"id":"1.195395430","rc":[{"atl":[[3.2,0],[3.15,40.59]],"id":41762283}],"con":true,"img":false}]}
{"op":"mcm","clk":"5306917248","pt":1646110280282,"mc":[{"id":"1.195395430","rc":[{"atb":[[1.84,18.81]],"id":37265273}],"con":true,"img":false}]}
{"op":"mcm","clk":"5306917293","pt":1646110281920,"mc":[{"id":"1.195395430","rc":[{"atb":[[1.64,2],[1.63,0]],"id":37265273},{"atl":[[11,10.66],[11.5,0]],"id":38206560},{"atl":[[4,0],[3.95,10.13]],"id":41762283}],"con":true,"img":false}]}
{"op":"mcm","clk":"5306917518","pt":1646110290317,"mc":[{"id":"1.195395430","rc":[{"atl":[[5.6,0]],"id":38206580}],"con":true,"img":false}]}
{"op":"mcm","clk":"5306917520","pt":1646110290422,"mc":[{"id":"1.195395430","rc":[{"atl":[[4.2,12.01]],"id":38206580}],"con":true,"img":false}]}
{"op":"mcm","clk":"5306917713","pt":1646110298098,"mc":[{"id":"1.195395430","rc":[{"atb":[[1.8,0]],"id":37265273}],"con":true,"img":false}]}
{"op":"mcm","clk":"5306917715","pt":1646110298199,"mc":[{"id":"1.195395430","rc":[{"atb":[[1.82,60.93]],"id":37265273}],"con":true,"img":false}]}
{"op":"mcm","clk":"5306917739","pt":1646110299324,"mc":[{"id":"1.195395430","rc":[{"atb":[[1.84,9.93]],"id":37265273}],"con":true,"img":false}]}
{"op":"mcm","clk":"5306917999","pt":1646110308242,"mc":[{"id":"1.195395430","rc":[{"atb":[[1.86,8.67]],"id":37265273}],"con":true,"img":false}]}
{"op":"mcm","clk":"5306918106","pt":1646110311938,"mc":[{"id":"1.195395430","rc":[{"atb":[[1.64,0],[1.66,69.22]],"id":37265273}],"con":true,"img":false}]}
{"op":"mcm","clk":"5306918212","pt":1646110315166,"mc":[{"id":"1.195395430","rc":[{"atb":[[1.84,0]],"id":37265273}],"con":true,"img":false}]}
{"op":"mcm","clk":"5306918441","pt":1646110323460,"mc":[{"id":"1.195395430","rc":[{"atb":[[1.86,18.38]],"id":37265273}],"con":true,"img":false}]}
{"op":"mcm","clk":"5306918520","pt":1646110327046,"mc":[{"id":"1.195395430","rc":[{"atb":[[1.66,67.22],[1.65,373.38]],"id":37265273},{"spn":2.48,"spf":"NaN","id":37265273},{"spn":5.82,"spf":"NaN","id":36104895},{"spn":4.4,"spf":"NaN","id":38206560}],"con":true,"img":false}]}
{"op":"mcm","clk":"5306920019","pt":1646110372236,"mc":[{"id":"1.195395430","rc":[{"atb":[[1.98,0]],"id":39520250},{"atl":[[11,0]],"id":39520250},{"atb":[[1.65,371.38]],"id":37265273},{"atl":[[4,0]],"id":37265273},{"atb":[[2.82,0]],"id":36104895},{"atl":[[15,0]],"id":36104895},{"atb":[[1.78,0]],"id":38206580},{"atl":[[4.7,0]],"id":38206580},{"atb":[[3.25,0]],"id":27701417},{"atl":[[24,0]],"id":27701417},{"atb":[[2.5,0]],"id":38206560},{"atl":[[11,8.66]],"id":38206560},{"atb":[[1.54,0]],"id":41762283},{"atl":[[3.95,8.13]],"id":41762283},{"atb":[[1.01,30175.21]],"id":40494181},{"atl":[[1.8,0]],"id":40494181}],"con":true,"img":false}]}
{"op":"mcm","clk":"5306920486","pt":1646110387291,"mc":[{"id":"1.195395430","rc":[{"atb":[[1.98,2]],"id":39520250},{"atl":[[11,2]],"id":39520250},{"atb":[[1.65,373.38]],"id":37265273},{"atl":[[4,2]],"id":37265273},{"atb":[[2.82,2]],"id":36104895},{"atl":[[15,2]],"id":36104895},{"atb":[[1.78,2]],"id":38206580},{"atl":[[4.7,2]],"id":38206580},{"atb":[[3.25,2]],"id":27701417},{"atl":[[24,2]],"id":27701417},{"atb":[[2.5,2]],"id":38206560},{"atl":[[11,10.66]],"id":38206560},{"atb":[[1.54,2]],"id":41762283},{"atl":[[3.95,10.13]],"id":41762283},{"atb":[[1.01,30177.21]],"id":40494181},{"atl":[[1.8,2]],"id":40494181}],"con":true,"img":false}]}
{"op":"mcm","clk":"5306921749","pt":1646110432562,"mc":[{"id":"1.195395430","rc":[{"atb":[[1.98,0]],"id":39520250},{"atl":[[11,0]],"id":39520250},{"atb":[[1.65,371.38]],"id":37265273},{"atl":[[4,0]],"id":37265273},{"atb":[[2.82,0]],"id":36104895},{"atl":[[15,0]],"id":36104895},{"atb":[[1.78,0]],"id":38206580},{"atl":[[4.7,0]],"id":38206580},{"atb":[[3.25,0]],"id":27701417},{"atl":[[24,0]],"id":27701417},{"atb":[[2.5,0]],"id":38206560},{"atl":[[11,8.66]],"id":38206560},{"atb":[[1.54,0]],"id":41762283},{"atl":[[3.95,8.13]],"id":41762283},{"atb":[[1.01,30175.21]],"id":40494181},{"atl":[[1.8,0]],"id":40494181}],"con":true,"img":false}]}
{"op":"mcm","clk":"5306921818","pt":1646110434554,"mc":[{"id":"1.195395430","rc":[{"atb":[[2.36,25.68],[2.38,3.05]],"id":39520250},{"atb":[[1.86,31.9],[1.87,3.76]],"id":37265273},{"atb":[[3.45,18.03]],"id":36104895},{"atb":[[4.3,10.41]],"id":27701417},{"atb":[[2.9,4.62]],"id":38206560}],"con":true,"img":false}]}
{"op":"mcm","clk":"5306921823","pt":1646110434658,"mc":[{"id":"1.195395430","rc":[{"atb":[[2.36,13.89],[2.4,11.79]],"id":39520250},{"atb":[[2.9,16.46]],"id":38206560}],"con":true,"img":false}]}
{"op":"mcm","clk":"5306922016","pt":1646110441573,"mc":[{"id":"1.195395430","rc":[{"atb":[[2.36,12.22]],"id":39520250}],"con":true,"img":false}]}
{"op":"mcm","clk":"5306922025","pt":1646110441777,"mc":[{"id":"1.195395430","rc":[{"atb":[[2.42,1.66]],"id":39520250}],"con":true,"img":false}]}
{"op":"mcm","clk":"5306922172","pt":1646110447562,"mc":[{"id":"1.195395430","rc":[{"atb":[[2.06,115.87]],"id":39520250},{"atl":[[11,2]],"id":39520250},{"spn":3.96,"spf":"NaN","id":39520250},{"atb":[[1.66,69.22]],"id":37265273},{"atl":[[4,2]],"id":37265273},{"spn":2.48,"spf":"NaN","id":37265273},{"atb":[[2.82,2]],"id":36104895},{"atl":[[15,2]],"id":36104895},{"atb":[[1.78,2]],"id":38206580},{"atl":[[4.7,2]],"id":38206580},{"atb":[[3.25,2]],"id":27701417},{"atl":[[24,2]],"id":27701417},{"atb":[[2.5,2]],"id":38206560},{"atl":[[11,10.66]],"id":38206560},{"atb":[[1.54,2]],"id":41762283},{"atl":[[3.95,10.13]],"id":41762283},{"atb":[[1.01,30177.21]],"id":40494181},{"atl":[[1.8,2]],"id":40494181}],"con":true,"img":false}]}
{"op":"mcm","clk":"5306922616","pt":1646110464410,"mc":[{"id":"1.195395430","rc":[{"atb":[[1.82,0]],"id":37265273},{"atb":[[3.4,0]],"id":36104895}],"con":true,"img":false}]}
{"op":"mcm","clk":"5306922626","pt":1646110464464,"mc":[{"id":"1.195395430","rc":[{"atb":[[1.87,64.69]],"id":37265273},{"atb":[[3.5,20.6]],"id":36104895}],"con":true,"img":false}]}
{"op":"mcm","clk":"5306922677","pt":1646110465493,"mc":[{"id":"1.195395430","rc":[{"atb":[[3.45,16.36]],"id":36104895}],"con":true,"img":false}]}
{"op":"mcm","clk":"5306922681","pt":1646110465596,"mc":[{"id":"1.195395430","rc":[{"atb":[[3.55,1.66]],"id":36104895}],"con":true,"img":false}]}
{"op":"mcm","clk":"5306922706","pt":1646110466773,"mc":[{"id":"1.195395430","rc":[{"atb":[[1.86,23.22]],"id":37265273},{"atb":[[3.45,13.31]],"id":36104895}],"con":true,"img":false}]}
{"op":"mcm","clk":"5306922839","pt":1646110472600,"mc":[{"id":"1.195395430","rc":[{"atb":[[1.91,8.19]],"id":37265273},{"atb":[[3.6,2.87]],"id":36104895}],"con":true,"img":false}]}
{"op":"mcm","clk":"5306922857","pt":1646110473521,"mc":[{"id":"1.195395430","rc":[{"atb":[[3.55,0]],"id":36104895}],"con":true,"img":false}]}
{"op":"mcm","clk":"5306922860","pt":1646110473574,"mc":[{"id":"1.195395430","rc":[{"atb":[[3.65,1.66]],"id":36104895}],"con":true,"img":false}]}
{"op":"mcm","clk":"5306922936","pt":1646110477722,"mc":[{"id":"1.195395430","rc":[{"atb":[[1.7,174.43],[1.86,13.51],[1.66,67.22]],"id":37265273},{"atb":[[2.82,0],[2.88,2]],"id":36104895}],"con":true,"img":false}]}
{"op":"mcm","clk":"5306923116","pt":1646110484186,"mc":[{"id":"1.195395430","rc":[{"atb":[[1.91,17.37]],"id":37265273}],"con":true,"img":false}]}
{"op":"mcm","clk":"5306923216","pt":1646110488530,"mc":[{"id":"1.195395430","rc":[{"atb":[[1.87,3.76]],"id":37265273}],"con":true,"img":false}]}
{"op":"mcm","clk":"5306923217","pt":1646110488632,"mc":[{"id":"1.195395430","rc":[{"atb":[[1.82,60.93]],"id":37265273}],"con":true,"img":false}]}
{"op":"mcm","clk":"5306923264","pt":1646110490733,"mc":[{"id":"1.195395430","rc":[{"atb":[[1.91,9.17]],"id":37265273}],"con":true,"img":false}]}
{"op":"mcm","clk":"5306923364","pt":1646110495145,"mc":[{"id":"1.195395430","rc":[{"atb":[[2.82,0]],"id":38206560}],"con":true,"img":false}]}
{"op":"mcm","clk":"5306923367","pt":1646110495199,"mc":[{"id":"1.195395430","rc":[{"atb":[[2.92,29.62]],"id":38206560}],"con":true,"img":false}]}
{"op":"mcm","clk":"5306923402","pt":1646110496632,"mc":[{"id":"1.195395430","rc":[{"atb":[[1.86,22.19]],"id":37265273},{"atb":[[2.88,4.44]],"id":38206560}],"con":true,"img":false}]}
{"op":"mcm","clk":"5306923415","pt":1646110497450,"mc":[{"id":"1.195395430","rc":[{"atb":[[2.9,14.79]],"id":38206560}],"con":true,"img":false}]}
{"op":"mcm","clk":"5306923417","pt":1646110497552,"mc":[{"id":"1.195395430","rc":[{"atb":[[2.94,1.66]],"id":38206560}],"con":true,"img":false}]}
{"op":"mcm","clk":"5306923545","pt":1646110502640,"mc":[{"id":"1.195395430","rc":[{"atb":[[4.2,0]],"id":27701417}],"con":true,"img":false}]}
{"op":"mcm","clk":"5306923551","pt":1646110502745,"mc":[{"id":"1.195395430","rc":[{"atb":[[4.4,14.42]],"id":27701417}],"con":true,"img":false}]}
{"op":"mcm","clk":"5306923555","pt":1646110502849,"mc":[{"id":"1.195395430","rc":[{"atb":[[2.98,3.76]],"id":38206560}],"con":true,"img":false}]}
{"op":"mcm","clk":"5306923592","pt":1646110503771,"mc":[{"id":"1.195395430","rc":[{"atb":[[1.91,0]],"id":38206580}],"con":true,"img":false}]}
{"op":"mcm","clk":"5306923594","pt":1646110503828,"mc":[{"id":"1.195395430","rc":[{"atb":[[1.96,51.2]],"id":38206580}],"con":true,"img":false}]}
{"op":"mcm","clk":"5306923603","pt":1646110504136,"mc":[{"id":"1.195395430","rc":[{"atb":[[1.91,0]],"id":37265273}],"con":true,"img":false}]}
{"op":"mcm","clk":"5306923642","pt":1646110505524,"mc":[{"id":"1.195395430","rc":[{"atb":[[4.3,8.74]],"id":27701417},{"atb":[[2.94,0]],"id":38206560}],"con":true,"img":false}]}
{"op":"mcm","clk":"5306923648","pt":1646110505731,"mc":[{"id":"1.195395430","rc":[{"atb":[[1.95,12.53]],"id":38206580},{"atb":[[4.5,1.66]],"id":27701417},{"atb":[[3,1.66]],"id":38206560}],"con":true,"img":false}]}
{"op":"mcm","clk":"5306923695","pt":1646110507775,"mc":[{"id":"1.195395430","rc":[{"atb":[[1.7,172.43],[1.66,69.22]],"id":37265273},{"spn":5.92,"spf":"NaN","id":36104895},{"atb":[[3.35,2],[3.25,0]],"id":27701417},{"spn":8.0,"spf":"NaN","id":27701417},{"atb":[[2.5,0],[2.6,77.43]],"id":38206560},{"spn":4.45,"spf":"NaN","id":38206560}],"con":true,"img":false}]}
{"op":"mcm","clk":"5306923757","pt":1646110510135,"mc":[{"id":"1.195395430","rc":[{"atb":[[1.86,31.9]],"id":37265273}],"con":true,"img":false}]}
{"op":"mcm","clk":"5306923760","pt":1646110510235,"mc":[{"id":"1.195395430","rc":[{"atb":[[2.88,0]],"id":38206560}],"con":true,"img":false}]}
{"op":"mcm","clk":"5306923787","pt":1646110511771,"mc":[{"id":"1.195395430","rc":[{"atb":[[2,7.45]],"id":38206580}],"con":true,"img":false}]}
{"op":"mcm","clk":"5306923831","pt":1646110513461,"mc":[{"id":"1.195395430","rc":[{"atb":[[2.02,1.66]],"id":38206580}],"con":true,"img":false}]}
{"op":"mcm","clk":"5306923848","pt":1646110514335,"mc":[{"id":"1.195395430","rc":[{"atb":[[1.96,3.66]],"id":38206580}],"con":true,"img":false}]}
{"op":"mcm","clk":"5306923852","pt":1646110514438,"mc":[{"id":"1.195395430","rc":[{"atb":[[1.91,47.53]],"id":38206580}],"con":true,"img":false}]}
{"op":"mcm","clk":"5306923863","pt":1646110514744,"mc":[{"id":"1.195395430","rc":[{"atb":[[2,0]],"id":38206580}],"con":true,"img":false}]}
{"op":"mcm","clk":"5306923979","pt":1646110519249,"mc":[{"id":"1.195395430","rc":[{"atb":[[2.98,7.98]],"id":38206560}],"con":true,"img":false}]}
{"op":"mcm","clk":"5306924035","pt":1646110521554,"mc":[{"id":"1.195395430","rc":[{"atb":[[2.02,0]],"id":38206580}],"con":true,"img":false}]}
{"op":"mcm","clk":"5306924083","pt":1646110523700,"mc":[{"id":"1.195395430","rc":[{"atb":[[1.95,20.38]],"id":38206580}],"con":true,"img":false}]}
{"op":"mcm","clk":"5306924238","pt":1646110530198,"mc":[{"id":"1.195395430","rc":[{"atb":[[4.4,0]],"id":27701417}],"con":true,"img":false}]}
{"op":"mcm","clk":"5306924240","pt":1646110530300,"mc":[{"id":"1.195395430","rc":[{"atb":[[4.2,14.42]],"id":27701417}],"con":true,"img":false}]}
{"op":"mcm","clk":"5306924321","pt":1646110534192,"mc":[{"id":"1.195395430","rc":[{"atb":[[1.82,0]],"id":37265273},{"atb":[[1.66,0]],"id":41762283}],"con":true,"img":false}]}
{"op":"mcm","clk":"5306924323","pt":1646110534294,"mc":[{"id":"1.195395430","rc":[{"atb":[[1.87,64.69]],"id":37265273},{"atb":[[1.71,60.93]],"id":41762283}],"con":true,"img":false}]}
{"op":"mcm","clk":"5306924354","pt":1646110535883,"mc":[{"id":"1.195395430","rc":[{"atb":[[1.86,23.22]],"id":37265273},{"atb":[[1.7,11.93]],"id":41762283}],"con":true,"img":false}]}
{"op":"mcm","clk":"5306924397","pt":1646110537518,"mc":[{"id":"1.195395430","rc":[{"atb":[[4.5,0]],"id":27701417}],"con":true,"img":false}]}
{"op":"mcm","clk":"5306924403","pt":1646110537722,"mc":[{"id":"1.195395430","rc":[{"atb":[[4.4,1.66]],"id":27701417}],"con":true,"img":false}]}
{"op":"mcm","clk":"5306924409","pt":1646110537927,"mc":[{"id":"1.195395430","rc":[{"atb":[[1.66,67.22],[1.65,373.38]],"id":37265273},{"atb":[[3.35,0],[3.25,2]],"id":27701417},{"atb":[[1.55,221.45],[1.54,0]],"id":41762283}],"con":true,"img":false}]}
{"op":"mcm","clk":"5306924476","pt":1646110541821,"mc":[{"id":"1.195395430","rc":[{"atb":[[1.91,8.19]],"id":37265273},{"atb":[[1.75,9.94]],"id":41762283}],"con":true,"img":false}]}
{"op":"mcm","clk":"5306924546","pt":1646110544720,"mc":[{"id":"1.195395430","marketDefinition":{"bspMarket":true,"turnInPlayEnabled":false,"persistenceEnabled":false,"marketBaseRate":7.0,"eventId":"31270458","eventTypeId":"4339","numberOfWinners":3,"bettingType":"ODDS","marketType":"PLACE","marketTime":"2022-03-01T05:50:00.000Z","suspendTime":"2022-03-01T05:50:00.000Z","bspReconciled":false,"complete":true,"inPlay":false,"crossMatching":true,"runnersVoidable":false,"numberOfActiveRunners":8,"betDelay":0,"status":"SUSPENDED","runners":[{"status":"ACTIVE","sortPriority":1,"id":40494181,"name":"1. Loch And Loaded"},{"status":"ACTIVE","sortPriority":2,"id":38206580,"name":"2. Buckle Up Wilder"},{"status":"ACTIVE","sortPriority":3,"id":38206560,"name":"3. Hiccup Amisha"},{"status":"ACTIVE","sortPriority":4,"id":36104895,"name":"4. Langley Roo"},{"status":"ACTIVE","sortPriority":5,"id":39520250,"name":"5. Rip On Bye"},{"status":"ACTIVE","sortPriority":6,"id":41762283,"name":"6. Gracies Joy"},{"status":"ACTIVE","sortPriority":7,"id":37265273,"name":"7. Just Mercy"},{"status":"ACTIVE","sortPriority":8,"id":27701417,"name":"8. Jalla General"}],"regulators":["MR_INT"],"venue":"Devonport","countryCode":"AU","discountAllowed":true,"timezone":"Australia/Sydney","openDate":"2022-03-01T02:00:00.000Z","version":4381133043,"name":"To Be Placed","eventName":"Devonport (AUS) 1st Mar"},"rc":[],"con":true,"img":false}]}
{"op":"mcm","clk":"5306924550","pt":1646110544895,"mc":[{"id":"1.195395430","rc":[{"atb":[[1.9,0]],"id":39520250},{"atb":[[1.9,0]],"id":38206580},{"atb":[[1.53,0]],"id":41762283},{"atb":[[1.04,0]],"id":40494181}],"con":true,"img":false}]}
{"op":"mcm","clk":"5306924653","pt":1646110550427,"mc":[{"id":"1.195395430","rc":[{"atb":[[1.23,0]],"id":39520250},{"atb":[[1.23,0]],"id":37265273},{"atb":[[1.23,0]],"id":36104895},{"atb":[[1.23,0]],"id":38206580},{"atb":[[1.23,0]],"id":27701417},{"atb":[[1.23,0]],"id":38206560},{"atb":[[1.23,0]],"id":41762283}],"con":true,"img":false}]}
{"op":"mcm","clk":"5306927301","pt":1646110689551,"mc":[{"id":"1.195395430","marketDefinition":{"bspMarket":true,"turnInPlayEnabled":false,"persistenceEnabled":false,"marketBaseRate":7.0,"eventId":"31270458","eventTypeId":"4339","numberOfWinners":3,"bettingType":"ODDS","marketType":"PLACE","marketTime":"2022-03-01T05:50:00.000Z","suspendTime":"2022-03-01T05:50:00.000Z","bspReconciled":false,"complete":true,"inPlay":false,"crossMatching":false,"runnersVoidable":false,"numberOfActiveRunners":8,"betDelay":0,"status":"SUSPENDED","runners":[{"status":"ACTIVE","sortPriority":1,"id":40494181,"name":"1. Loch And Loaded"},{"status":"ACTIVE","sortPriority":2,"id":38206580,"name":"2. Buckle Up Wilder"},{"status":"ACTIVE","sortPriority":3,"id":38206560,"name":"3. Hiccup Amisha"},{"status":"ACTIVE","sortPriority":4,"id":36104895,"name":"4. Langley Roo"},{"status":"ACTIVE","sortPriority":5,"id":39520250,"name":"5. Rip On Bye"},{"status":"ACTIVE","sortPriority":6,"id":41762283,"name":"6. Gracies Joy"},{"status":"ACTIVE","sortPriority":7,"id":37265273,"name":"7. Just Mercy"},{"status":"ACTIVE","sortPriority":8,"id":27701417,"name":"8. Jalla General"}],"regulators":["MR_INT"],"venue":"Devonport","countryCode":"AU","discountAllowed":true,"timezone":"Australia/Sydney","openDate":"2022-03-01T02:00:00.000Z","version":4381133813,"name":"To Be Placed","eventName":"Devonport (AUS) 1st Mar"},"rc":[],"con":true,"img":false}]}
{"op":"mcm","clk":"5306927301","pt":1646110689551,"mc":[{"id":"1.195395430","rc":[{"atb":[[2.4,0],[2.36,0],[2.06,0],[2.42,0],[2.38,0],[2.28,0],[2.18,0],[2.26,0],[2.16,0],[2.34,0]],"id":39520250},{"atl":[[5.6,0],[7.2,0],[18,0],[9.2,0],[10,0],[5.5,0],[11,0],[13,0]],"id":39520250},{"atb":[[1.6,0],[1.81,0],[1.91,0],[1.7,0],[1.86,0],[1.87,0],[1.75,0],[1.66,0],[1.65,0],[1.76,0]],"id":37265273},{"atl":[[4,0],[4.3,0],[3.2,0],[3.85,0],[3.1,0],[85,0],[3.7,0],[6.8,0],[3.15,0],[4.4,0],[5.4,0]],"id":37265273},{"atb":[[3.6,0],[3.45,0],[2.88,0],[3.1,0],[3.35,0],[1.26,0],[2.44,0],[3.5,0],[2.94,0],[3.65,0]],"id":36104895},{"atl":[[17,0],[38,0],[10,0],[8.2,0],[12,0],[24,0],[8.8,0],[8.4,0],[15,0]],"id":36104895},{"atb":[[1.89,0],[1.45,0],[1.55,0],[1.67,0],[1.91,0],[1.78,0],[1.5,0],[1.96,0],[1.94,0],[1.95,0]],"id":38206580},{"atl":[[2.82,0],[4.3,0],[5.1,0],[5,0],[85,0],[4.1,0],[3.55,0],[4.2,0],[3.05,0],[4.7,0]],"id":38206580},{"atb":[[2.36,0],[4.3,0],[4.1,0],[3.8,0],[3.55,0],[3.25,0],[4.4,0],[4.2,0],[2.76,0]],"id":27701417},{"atl":[[19.5,0],[11.5,0],[95,0],[12,0],[24,0],[48,0],[14,0],[14.5,0],[29,0]],"id":27701417},{"atb":[[2.8,0],[2.92,0],[2.9,0],[3,0],[2.6,0],[2.98,0],[2.16,0],[2.14,0],[2.7,0]],"id":38206560},{"atl":[[7.2,0],[18,0],[9.2,0],[11,0],[6,0],[13,0],[26,0],[5.9,0],[8.4,0]],"id":38206560},{"atb":[[1.56,0],[1.6,0],[1.55,0],[1.85,0],[1.7,0],[1.86,0],[1.75,0],[1.65,0],[1.71,0],[1.35,0]],"id":41762283},{"atl":[[3.45,0],[3.6,0],[3.95,0],[85,0],[4.9,0],[2.98,0],[3.15,0],[3.55,0],[2.96,0],[5.9,0]],"id":41762283},{"atb":[[1.01,0],[1.16,0],[1.09,0],[1.13,0],[1.07,0]],"id":40494181},{"atl":[[1.64,0],[1.8,0],[2.54,0],[1.43,0],[2.74,0],[1.21,0],[1.97,0],[85,0],[1.67,0],[1.85,0],[2.14,0],[2.34,0]],"id":40494181}],"con":true,"img":false}]}
{"op":"mcm","clk":"5306927343","pt":1646110690943,"mc":[{"id":"1.195395430","marketDefinition":{"bspMarket":true,"turnInPlayEnabled":false,"persistenceEnabled":false,"marketBaseRate":7.0,"eventId":"31270458","eventTypeId":"4339","numberOfWinners":3,"bettingType":"ODDS","marketType":"PLACE","marketTime":"2022-03-01T05:50:00.000Z","suspendTime":"2022-03-01T05:50:00.000Z","bspReconciled":false,"complete":true,"inPlay":false,"crossMatching":false,"runnersVoidable":false,"numberOfActiveRunners":0,"betDelay":0,"status":"CLOSED","settledTime":"2022-03-01T04:58:09.000Z","runners":[{"status":"REMOVED","sortPriority":1,"removalDate":"2022-03-01T04:58:09.000Z","id":40494181,"name":"1. Loch And Loaded"},{"status":"REMOVED","sortPriority":2,"removalDate":"2022-03-01T04:58:09.000Z","id":38206580,"name":"2. Buckle Up Wilder"},{"status":"REMOVED","sortPriority":3,"removalDate":"2022-03-01T04:58:09.000Z","id":38206560,"name":"3. Hiccup Amisha"},{"status":"REMOVED","sortPriority":4,"removalDate":"2022-03-01T04:58:09.000Z","id":36104895,"name":"4. Langley Roo"},{"status":"REMOVED","sortPriority":5,"removalDate":"2022-03-01T04:58:09.000Z","id":39520250,"name":"5. Rip On Bye"},{"status":"REMOVED","sortPriority":6,"removalDate":"2022-03-01T04:58:09.000Z","id":41762283,"name":"6. Gracies Joy"},{"status":"REMOVED","sortPriority":7,"removalDate":"2022-03-01T04:58:09.000Z","id":37265273,"name":"7. Just Mercy"},{"status":"REMOVED","sortPriority":8,"removalDate":"2022-03-01T04:58:09.000Z","id":27701417,"name":"8. Jalla General"}],"regulators":["MR_INT"],"venue":"Devonport","countryCode":"AU","discountAllowed":true,"timezone":"Australia/Sydney","openDate":"2022-03-01T02:00:00.000Z","version":4381133833,"name":"To Be Placed","eventName":"Devonport (AUS) 1st Mar"},"rc":[],"con":true,"img":false}]}
