{"op":"mcm","clk":"5352134787","pt":1646183310062,"mc":[{"id":"1.195503848","marketDefinition":{"bspMarket":false,"turnInPlayEnabled":false,"persistenceEnabled":false,"marketBaseRate":7.0,"eventId":"31272499","eventTypeId":"4339","numberOfWinners":1,"bettingType":"ODDS","marketType":"MATCH_BET","marketTime":"2022-03-02T08:34:00.000Z","suspendTime":"2022-03-02T08:34:00.000Z","bspReconciled":false,"complete":true,"inPlay":false,"crossMatching":true,"runnersVoidable":false,"numberOfActiveRunners":2,"betDelay":0,"status":"OPEN","runners":[{"status":"ACTIVE","sortPriority":1,"id":43167125,"name":"3. Lovely Result"},{"status":"ACTIVE","sortPriority":2,"id":43167126,"name":"4. Zipping Fern"}],"regulators":["MR_INT"],"venue":"Rockhampton","countryCode":"AU","discountAllowed":true,"timezone":"Australia/Queensland","openDate":"2022-03-02T08:34:00.000Z","version":4382585390,"name":"Lovely Result v Zipping Fern","eventName":"Rockhampton (AUS) 2nd Mar"},"rc":[],"con":true,"img":false}]}
{"op":"mcm","clk":"5352139712","pt":1646183422125,"mc":[{"id":"1.195503848","rc":[{"atb":[[1.67,8.05],[1.87,6.2],[2.14,4.73]],"id":43167126},{"atb":[[1.46,11.73],[1.26,20.76],[1.06,89.97]],"id":43167125}],"con":true,"img":false}]}
{"op":"mcm","clk":"5352146191","pt":1646183572652,"mc":[{"id":"1.195503848","marketDefinition":{"bspMarket":false,"turnInPlayEnabled":false,"persistenceEnabled":false,"marketBaseRate":7.0,"eventId":"31272499","eventTypeId":"4339","numberOfWinners":1,"bettingType":"ODDS","marketType":"MATCH_BET","marketTime":"2022-03-02T08:34:00.000Z","suspendTime":"2022-03-02T08:34:00.000Z","bspReconciled":false,"complete":true,"inPlay":false,"crossMatching":true,"runnersVoidable":false,"numberOfActiveRunners":2,"betDelay":0,"status":"OPEN","runners":[{"status":"ACTIVE","sortPriority":1,"id":43167125,"name":"3. Lovely Result"},{"status":"ACTIVE","sortPriority":2,"id":43167126,"name":"4. Zipping Fern"}],"regulators":["MR_INT"],"venue":"Rockhampton","countryCode":"AU","discountAllowed":true,"timezone":"Australia/Queensland","openDate":"2022-03-02T08:28:00.000Z","version":4382597864,"name":"Lovely Result v Zipping Fern","eventName":"Rockhampton (AUS) 2nd Mar"},"rc":[],"con":true,"img":false}]}
{"op":"mcm","clk":"5352146585","pt":1646183580653,"mc":[{"id":"1.195503848","marketDefinition":{"bspMarket":false,"turnInPlayEnabled":false,"persistenceEnabled":false,"marketBaseRate":7.0,"eventId":"31272499","eventTypeId":"4339","numberOfWinners":1,"bettingType":"ODDS","marketType":"MATCH_BET","marketTime":"2022-03-02T08:28:00.000Z","suspendTime":"2022-03-02T08:28:00.000Z","bspReconciled":false,"complete":true,"inPlay":false,"crossMatching":true,"runnersVoidable":false,"numberOfActiveRunners":2,"betDelay":0,"status":"OPEN","runners":[{"status":"ACTIVE","sortPriority":1,"id":43167125,"name":"3. Lovely Result"},{"status":"ACTIVE","sortPriority":2,"id":43167126,"name":"4. Zipping Fern"}],"regulators":["MR_INT"],"venue":"Rockhampton","countryCode":"AU","discountAllowed":true,"timezone":"Australia/Queensland","openDate":"2022-03-02T08:28:00.000Z","version":4382597942,"name":"Lovely Result v Zipping Fern","eventName":"Rockhampton (AUS) 2nd Mar"},"rc":[],"con":true,"img":false}]}
{"op":"mcm","clk":"5352466695","pt":1646191002690,"mc":[{"id":"1.195503848","marketDefinition":{"bspMarket":false,"turnInPlayEnabled":false,"persistenceEnabled":false,"marketBaseRate":7.0,"eventId":"31272499","eventTypeId":"4339","numberOfWinners":1,"bettingType":"ODDS","marketType":"MATCH_BET","marketTime":"2022-03-02T08:28:00.000Z","suspendTime":"2022-03-02T08:28:00.000Z","bspReconciled":false,"complete":true,"inPlay":false,"crossMatching":true,"runnersVoidable":false,"numberOfActiveRunners":2,"betDelay":0,"status":"OPEN","runners":[{"status":"ACTIVE","sortPriority":1,"id":43167125,"name":"3. Lovely Result"},{"status":"ACTIVE","sortPriority":2,"id":43167126,"name":"4. Zipping Fern"}],"regulators":["MR_INT"],"venue":"Rockhampton","countryCode":"AU","discountAllowed":true,"timezone":"Australia/Queensland","openDate":"2022-03-02T08:28:00.000Z","version":4382597942,"name":"Lovely Result v Zipping Fern","eventName":"Rockhampton (AUS) 2nd Mar"},"rc":[{"atb":[[1.67,8.07],[1.87,6.21],[2.14,4.74]],"id":43167126},{"atb":[[1.46,11.75],[1.26,20.79],[1.06,90.12]],"id":43167125}],"con":true,"img":true}]}
{"op":"mcm","clk":"5352715136","pt":1646197991308,"mc":[{"id":"1.195503848","rc":[{"atb":[[1.67,8.06],[1.87,6.21],[2.14,0]],"id":43167126},{"atl":[[2.14,3.99]],"id":43167126},{"trd":[[2.14,9.47]],"ltp":2.14,"tv":9.47,"id":43167126},{"atb":[[1.46,11.74],[1.26,20.79],[1.06,90.09]],"id":43167125}],"con":true,"img":false}]}
{"op":"mcm","clk":"5352715494","pt":1646198003744,"mc":[{"id":"1.195503848","rc":[{"atl":[[2.14,0]],"id":43167126}],"con":true,"img":false}]}
{"op":"mcm","clk":"5352716097","pt":1646198023272,"mc":[{"id":"1.195503848","rc":[{"atb":[[1.87,0.99]],"id":43167126},{"trd":[[1.87,10.43]],"ltp":1.87,"tv":10.43,"id":43167126}],"con":true,"img":false}]}
{"op":"mcm","clk":"5352934037","pt":1646205054847,"mc":[{"id":"1.195503848","rc":[{"atb":[[1.67,0],[1.87,0]],"id":43167126},{"trd":[[1.87,10.44],[2.14,9.48]],"ltp":1.87,"tv":19.92,"id":43167126},{"atb":[[1.46,0],[1.26,0],[1.06,0]],"id":43167125}],"con":true,"img":false}]}
{"op":"mcm","clk":"5352934744","pt":1646205071559,"mc":[{"id":"1.195503848","rc":[{"atb":[[2.02,5.3],[1.81,6.67],[1.61,8.85]],"id":43167126},{"atb":[[1.11,49.12],[1.51,10.59],[1.31,17.43]],"id":43167125}],"con":true,"img":false}]}
{"op":"mcm","clk":"5353084257","pt":1646208480904,"mc":[{"id":"1.195503848","rc":[{"atb":[[1.88,2]],"id":43167126},{"atl":[[2.72,2]],"id":43167126},{"atb":[[1.52,2]],"id":43167125},{"atl":[[2.16,2]],"id":43167125}],"con":true,"img":false}]}
{"op":"mcm","clk":"5353089062","pt":1646208593355,"mc":[{"id":"1.195503848","rc":[{"atb":[[1.91,2]],"id":43167126}],"con":true,"img":false}]}
{"op":"mcm","clk":"5353089069","pt":1646208593458,"mc":[{"id":"1.195503848","rc":[{"atb":[[1.88,0]],"id":43167126}],"con":true,"img":false}]}
{"op":"mcm","clk":"5353093722","pt":1646208692984,"mc":[{"id":"1.195503848","rc":[{"atb":[[1.91,0]],"id":43167126},{"atl":[[2.72,0]],"id":43167126},{"atb":[[1.52,0]],"id":43167125},{"atl":[[2.16,0]],"id":43167125}],"con":true,"img":false}]}
{"op":"mcm","clk":"5353093949","pt":1646208697714,"mc":[{"id":"1.195503848","rc":[{"atb":[[1.89,2]],"id":43167126},{"atl":[[2.72,2]],"id":43167126},{"atb":[[1.52,2]],"id":43167125},{"atl":[[2.16,2]],"id":43167125}],"con":true,"img":false}]}
{"op":"mcm","clk":"5353098033","pt":1646208785719,"mc":[{"id":"1.195503848","rc":[{"atb":[[1.55,2],[1.52,0]],"id":43167125}],"con":true,"img":false}]}
{"op":"mcm","clk":"5353098038","pt":1646208785822,"mc":[{"id":"1.195503848","rc":[{"atl":[[2.72,0],[2.64,2]],"id":43167126},{"atl":[[2.16,0],[2.14,2]],"id":43167125}],"con":true,"img":false}]}
{"op":"mcm","clk":"5353098303","pt":1646208790928,"mc":[{"id":"1.195503848","rc":[{"atb":[[1.55,0],[1.54,2]],"id":43167125}],"con":true,"img":false}]}
{"op":"mcm","clk":"5353098556","pt":1646208796029,"mc":[{"id":"1.195503848","rc":[{"atl":[[2.64,0],[2.62,2]],"id":43167126},{"atb":[[1.57,2],[1.54,0]],"id":43167125}],"con":true,"img":false}]}
{"op":"mcm","clk":"5353098775","pt":1646208801122,"mc":[{"id":"1.195503848","rc":[{"atl":[[2.6,2]],"id":43167126}],"con":true,"img":false}]}
{"op":"mcm","clk":"5353098781","pt":1646208801249,"mc":[{"id":"1.195503848","rc":[{"atl":[[2.62,0]],"id":43167126},{"atb":[[1.57,0],[1.58,2]],"id":43167125}],"con":true,"img":false}]}
{"op":"mcm","clk":"5353098944","pt":1646208804321,"mc":[{"id":"1.195503848","rc":[{"atl":[[2.52,2],[2.6,0]],"id":43167126}],"con":true,"img":false}]}
{"op":"mcm","clk":"5353099044","pt":1646208806327,"mc":[{"id":"1.195503848","rc":[{"atb":[[1.61,2]],"id":43167125}],"con":true,"img":false}]}
{"op":"mcm","clk":"5353099049","pt":1646208806431,"mc":[{"id":"1.195503848","rc":[{"atb":[[1.58,0]],"id":43167125}],"con":true,"img":false}]}
{"op":"mcm","clk":"5353099107","pt":1646208807760,"mc":[{"id":"1.195503848","rc":[{"atb":[[1.63,2],[1.61,0]],"id":43167125}],"con":true,"img":false}]}
{"op":"mcm","clk":"5353099176","pt":1646208809456,"mc":[{"id":"1.195503848","rc":[{"atl":[[2.5,2],[2.52,0]],"id":43167126}],"con":true,"img":false}]}
{"op":"mcm","clk":"5353099258","pt":1646208811688,"mc":[{"id":"1.195503848","rc":[{"atb":[[2.02,0],[1.81,0],[1.61,0]],"id":43167126},{"atb":[[1.11,0],[1.51,0],[1.31,0]],"id":43167125}],"con":true,"img":false}]}
{"op":"mcm","clk":"5353099317","pt":1646208812873,"mc":[{"id":"1.195503848","rc":[{"atb":[[1.64,2],[1.63,0]],"id":43167125}],"con":true,"img":false}]}
{"op":"mcm","clk":"5353099395","pt":1646208814544,"mc":[{"id":"1.195503848","rc":[{"atl":[[2.5,0],[2.46,2]],"id":43167126}],"con":true,"img":false}]}
{"op":"mcm","clk":"5353099504","pt":1646208816678,"mc":[{"id":"1.195503848","rc":[{"atb":[[2.02,5.3],[1.81,6.67],[1.61,8.85]],"id":43167126},{"atb":[[1.11,49.12],[1.51,10.59],[1.31,17.43]],"id":43167125}],"con":true,"img":false}]}
{"op":"mcm","clk":"5353099559","pt":1646208817949,"mc":[{"id":"1.195503848","rc":[{"atb":[[1.63,2]],"id":43167125}],"con":true,"img":false}]}
{"op":"mcm","clk":"5353099563","pt":1646208818053,"mc":[{"id":"1.195503848","rc":[{"atb":[[1.64,0]],"id":43167125}],"con":true,"img":false}]}
{"op":"mcm","clk":"5353099570","pt":1646208818259,"mc":[{"id":"1.195503848","rc":[{"atb":[[1.64,2],[1.63,0]],"id":43167125}],"con":true,"img":false}]}
{"op":"mcm","clk":"5353099661","pt":1646208819856,"mc":[{"id":"1.195503848","rc":[{"atb":[[1.64,0],[1.65,2]],"id":43167125}],"con":true,"img":false}]}
{"op":"mcm","clk":"5353099883","pt":1646208824890,"mc":[{"id":"1.195503848","rc":[{"atl":[[2.12,34.86],[2.14,0]],"id":43167125}],"con":true,"img":false}]}
{"op":"mcm","clk":"5353099887","pt":1646208824992,"mc":[{"id":"1.195503848","rc":[{"atb":[[1.55,34.86],[1.65,0]],"id":43167125}],"con":true,"img":false}]}
{"op":"mcm","clk":"5353100134","pt":1646208829952,"mc":[{"id":"1.195503848","rc":[{"atl":[[2.14,2]],"id":43167125}],"con":true,"img":false}]}
{"op":"mcm","clk":"5353100140","pt":1646208830057,"mc":[{"id":"1.195503848","rc":[{"atl":[[2.12,0]],"id":43167125}],"con":true,"img":false}]}
{"op":"mcm","clk":"5353100148","pt":1646208830158,"mc":[{"id":"1.195503848","rc":[{"atb":[[1.55,0],[1.61,2]],"id":43167125}],"con":true,"img":false}]}
{"op":"mcm","clk":"5353100170","pt":1646208830568,"mc":[{"id":"1.195503848","rc":[{"atl":[[2.36,2],[2.46,0]],"id":43167126},{"atb":[[1.7,2],[1.61,0]],"id":43167125}],"con":true,"img":false}]}
{"op":"mcm","clk":"5353100192","pt":1646208831084,"mc":[{"id":"1.195503848","rc":[{"atb":[[1.7,0],[1.71,2]],"id":43167125}],"con":true,"img":false}]}
{"op":"mcm","clk":"5353102408","pt":1646208877145,"mc":[{"id":"1.195503848","rc":[{"atb":[[1.7,2],[1.71,0]],"id":43167125}],"con":true,"img":false}]}
{"op":"mcm","clk":"5353102794","pt":1646208885854,"mc":[{"id":"1.195503848","rc":[{"atb":[[1.7,0],[1.71,2]],"id":43167125}],"con":true,"img":false}]}
{"op":"mcm","clk":"5353103209","pt":1646208894967,"mc":[{"id":"1.195503848","rc":[{"atl":[[2.36,0],[2.34,2]],"id":43167126}],"con":true,"img":false}]}
{"op":"mcm","clk":"5353103650","pt":1646208903662,"mc":[{"id":"1.195503848","rc":[{"atb":[[1.72,2],[1.71,0]],"id":43167125}],"con":true,"img":false}]}
{"op":"mcm","clk":"5353105208","pt":1646208937805,"mc":[{"id":"1.195503848","rc":[{"atb":[[1.72,0],[1.6,2]],"id":43167125}],"con":true,"img":false}]}
{"op":"mcm","clk":"5353105260","pt":1646208938989,"mc":[{"id":"1.195503848","rc":[{"atb":[[1.61,2]],"id":43167125}],"con":true,"img":false}]}
{"op":"mcm","clk":"5353105264","pt":1646208939092,"mc":[{"id":"1.195503848","rc":[{"atb":[[1.6,0]],"id":43167125}],"con":true,"img":false}]}
{"op":"mcm","clk":"5353105495","pt":1646208944092,"mc":[{"id":"1.195503848","rc":[{"atb":[[1.54,34.86]],"id":43167125}],"con":true,"img":false}]}
{"op":"mcm","clk":"5353105501","pt":1646208944194,"mc":[{"id":"1.195503848","rc":[{"atb":[[1.61,0]],"id":43167125}],"con":true,"img":false}]}
{"op":"mcm","clk":"5353105564","pt":1646208945530,"mc":[{"id":"1.195503848","rc":[{"atb":[[1.6,34.86],[1.54,0]],"id":43167125}],"con":true,"img":false}]}
{"op":"mcm","clk":"5353105569","pt":1646208945633,"mc":[{"id":"1.195503848","rc":[{"atb":[[1.6,0],[1.61,2]],"id":43167125}],"con":true,"img":false}]}
{"op":"mcm","clk":"5353105664","pt":1646208947492,"mc":[{"id":"1.195503848","rc":[{"atb":[[1.62,2],[1.61,0]],"id":43167125}],"con":true,"img":false}]}
{"op":"mcm","clk":"5353106630","pt":1646208968830,"mc":[{"id":"1.195503848","rc":[{"atb":[[1.89,0],[1.91,2]],"id":43167126}],"con":true,"img":false}]}
{"op":"mcm","clk":"5353107857","pt":1646208998866,"mc":[{"id":"1.195503848","rc":[{"atb":[[1.62,0],[1.71,2]],"id":43167125}],"con":true,"img":false}]}
{"op":"mcm","clk":"5353107975","pt":1646209001393,"mc":[{"id":"1.195503848","rc":[{"atl":[[2.32,2],[2.34,0]],"id":43167126},{"atb":[[1.73,2],[1.71,0]],"id":43167125}],"con":true,"img":false}]}
{"op":"mcm","clk":"5353108195","pt":1646209006496,"mc":[{"id":"1.195503848","rc":[{"atl":[[2.3,2]],"id":43167126},{"atb":[[1.75,2]],"id":43167125}],"con":true,"img":false}]}
{"op":"mcm","clk":"5353108201","pt":1646209006600,"mc":[{"id":"1.195503848","rc":[{"atl":[[2.32,0]],"id":43167126},{"atb":[[1.73,0]],"id":43167125}],"con":true,"img":false}]}
{"op":"mcm","clk":"5353108691","pt":1646209018688,"mc":[{"id":"1.195503848","rc":[{"atb":[[1.74,2],[1.75,0]],"id":43167125}],"con":true,"img":false}]}
{"op":"mcm","clk":"5353108760","pt":1646209020130,"mc":[{"id":"1.195503848","rc":[{"atl":[[2.3,0],[2.26,2]],"id":43167126}],"con":true,"img":false}]}
{"op":"mcm","clk":"5353108920","pt":1646209023805,"mc":[{"id":"1.195503848","rc":[{"atb":[[1.74,0],[1.77,2]],"id":43167125}],"con":true,"img":false}]}
{"op":"mcm","clk":"5353110518","pt":1646209062679,"mc":[{"id":"1.195503848","rc":[{"atb":[[1.74,2],[1.77,0]],"id":43167125}],"con":true,"img":false}]}
{"op":"mcm","clk":"5353110728","pt":1646209067885,"mc":[{"id":"1.195503848","rc":[{"atb":[[1.72,2],[1.74,0]],"id":43167125}],"con":true,"img":false}]}
{"op":"mcm","clk":"5353110968","pt":1646209073068,"mc":[{"id":"1.195503848","rc":[{"atb":[[1.72,0],[1.7,2]],"id":43167125}],"con":true,"img":false}]}
{"op":"mcm","clk":"5353111160","pt":1646209078198,"mc":[{"id":"1.195503848","rc":[{"atb":[[1.7,0],[1.71,2]],"id":43167125}],"con":true,"img":false}]}
{"op":"mcm","clk":"5353111185","pt":1646209078980,"mc":[{"id":"1.195503848","rc":[{"atb":[[1.7,2],[1.71,0]],"id":43167125}],"con":true,"img":false}]}
{"op":"mcm","clk":"5353111399","pt":1646209084082,"mc":[{"id":"1.195503848","rc":[{"atb":[[1.7,0],[1.71,2]],"id":43167125}],"con":true,"img":false}]}
{"op":"mcm","clk":"5353111467","pt":1646209085545,"mc":[{"id":"1.195503848","rc":[{"atb":[[2.02,0],[1.81,0],[1.61,0]],"id":43167126},{"atb":[[1.11,0],[1.51,0],[1.31,0]],"id":43167125}],"con":true,"img":false}]}
{"op":"mcm","clk":"5353111476","pt":1646209085705,"mc":[{"id":"1.195503848","rc":[{"atb":[[1.91,0],[1.9,2]],"id":43167126}],"con":true,"img":false}]}
{"op":"mcm","clk":"5353111601","pt":1646209089178,"mc":[{"id":"1.195503848","rc":[{"atb":[[1.74,2],[1.71,0]],"id":43167125}],"con":true,"img":false}]}
{"op":"mcm","clk":"5353111607","pt":1646209089429,"mc":[{"id":"1.195503848","rc":[{"atb":[[2.02,5.3],[1.81,6.67],[1.61,8.85]],"id":43167126},{"atb":[[1.11,49.12],[1.51,10.59],[1.31,17.43]],"id":43167125}],"con":true,"img":false}]}
{"op":"mcm","clk":"5353112165","pt":1646209103816,"mc":[{"id":"1.195503848","rc":[{"atl":[[2.24,2],[2.26,0]],"id":43167126},{"atb":[[1.79,2],[1.74,0]],"id":43167125}],"con":true,"img":false}]}
{"op":"mcm","clk":"5353112364","pt":1646209108934,"mc":[{"id":"1.195503848","rc":[{"atl":[[2.18,13.34]],"id":43167126},{"atb":[[1.83,34.86],[1.79,0]],"id":43167125}],"con":true,"img":false}]}
{"op":"mcm","clk":"5353112370","pt":1646209109036,"mc":[{"id":"1.195503848","rc":[{"atl":[[2.24,0]],"id":43167126}],"con":true,"img":false}]}
{"op":"mcm","clk":"5353112567","pt":1646209114095,"mc":[{"id":"1.195503848","rc":[{"atb":[[1.83,0],[1.71,2]],"id":43167125}],"con":true,"img":false}]}
{"op":"mcm","clk":"5353112778","pt":1646209119613,"mc":[{"id":"1.195503848","rc":[{"atb":[[1.7,2],[1.71,0]],"id":43167125}],"con":true,"img":false}]}
{"op":"mcm","clk":"5353113047","pt":1646209124732,"mc":[{"id":"1.195503848","rc":[{"atb":[[1.61,2]],"id":43167125}],"con":true,"img":false}]}
{"op":"mcm","clk":"5353113051","pt":1646209124835,"mc":[{"id":"1.195503848","rc":[{"atb":[[1.7,0]],"id":43167125}],"con":true,"img":false}]}
{"op":"mcm","clk":"5353113101","pt":1646209125916,"mc":[{"id":"1.195503848","rc":[{"atl":[[2.2,2]],"id":43167126}],"con":true,"img":false}]}
{"op":"mcm","clk":"5353113103","pt":1646209126019,"mc":[{"id":"1.195503848","rc":[{"atl":[[2.18,0]],"id":43167126},{"atb":[[1.61,0],[1.71,2]],"id":43167125}],"con":true,"img":false}]}
{"op":"mcm","clk":"5353113309","pt":1646209131164,"mc":[{"id":"1.195503848","rc":[{"atb":[[1.68,2],[1.71,0]],"id":43167125}],"con":true,"img":false}]}
{"op":"mcm","clk":"5353113537","pt":1646209136345,"mc":[{"id":"1.195503848","rc":[{"atb":[[1.68,0],[1.65,2]],"id":43167125}],"con":true,"img":false}]}
{"op":"mcm","clk":"5353113746","pt":1646209141454,"mc":[{"id":"1.195503848","rc":[{"atb":[[1.6,2],[1.65,0]],"id":43167125}],"con":true,"img":false}]}
{"op":"mcm","clk":"5353113956","pt":1646209146573,"mc":[{"id":"1.195503848","rc":[{"atb":[[1.69,2]],"id":43167125}],"con":true,"img":false}]}
{"op":"mcm","clk":"5353113961","pt":1646209146676,"mc":[{"id":"1.195503848","rc":[{"atb":[[1.6,0]],"id":43167125}],"con":true,"img":false}]}
{"op":"mcm","clk":"5353113969","pt":1646209146881,"mc":[{"id":"1.195503848","rc":[{"atb":[[1.67,2]],"id":43167125}],"con":true,"img":false}]}
{"op":"mcm","clk":"5353113973","pt":1646209146984,"mc":[{"id":"1.195503848","rc":[{"atb":[[1.69,0]],"id":43167125}],"con":true,"img":false}]}
{"op":"mcm","clk":"5353114194","pt":1646209151997,"mc":[{"id":"1.195503848","rc":[{"atb":[[1.67,0],[1.71,2]],"id":43167125}],"con":true,"img":false}]}
{"op":"mcm","clk":"5353114296","pt":1646209154482,"mc":[{"id":"1.195503848","rc":[{"atb":[[1.92,2],[1.9,0]],"id":43167126},{"atl":[[2.2,0],[2.26,2]],"id":43167126}],"con":true,"img":false}]}
{"op":"mcm","clk":"5353114405","pt":1646209157069,"mc":[{"id":"1.195503848","rc":[{"atb":[[1.67,2],[1.71,0]],"id":43167125}],"con":true,"img":false}]}
{"op":"mcm","clk":"5353114815","pt":1646209168116,"mc":[{"id":"1.195503848","rc":[{"atb":[[1.64,2],[1.67,0]],"id":43167125}],"con":true,"img":false}]}
{"op":"mcm","clk":"5353114865","pt":1646209169305,"mc":[{"id":"1.195503848","rc":[{"atb":[[1.64,0],[1.65,2]],"id":43167125}],"con":true,"img":false}]}
{"op":"mcm","clk":"5353115106","pt":1646209175708,"mc":[{"id":"1.195503848","rc":[{"atb":[[1.92,0]],"id":43167126}],"con":true,"img":false}]}
{"op":"mcm","clk":"5353115113","pt":1646209175811,"mc":[{"id":"1.195503848","rc":[{"atb":[[1.88,2]],"id":43167126}],"con":true,"img":false}]}
{"op":"mcm","clk":"5353115600","pt":1646209186523,"mc":[{"id":"1.195503848","rc":[{"atb":[[1.65,0],[1.66,2]],"id":43167125}],"con":true,"img":false}]}
{"op":"mcm","clk":"5353116133","pt":1646209199364,"mc":[{"id":"1.195503848","rc":[{"atb":[[1.64,2],[1.66,0]],"id":43167125}],"con":true,"img":false}]}
{"op":"mcm","clk":"5353116409","pt":1646209204448,"mc":[{"id":"1.195503848","rc":[{"atb":[[1.64,0],[1.63,2]],"id":43167125}],"con":true,"img":false}]}
{"op":"mcm","clk":"5353116660","pt":1646209209563,"mc":[{"id":"1.195503848","rc":[{"atb":[[1.64,2],[1.63,0]],"id":43167125}],"con":true,"img":false}]}
{"op":"mcm","clk":"5353117587","pt":1646209230207,"mc":[{"id":"1.195503848","rc":[{"atb":[[1.64,0],[1.67,2]],"id":43167125}],"con":true,"img":false}]}
{"op":"mcm","clk":"5353117822","pt":1646209235414,"mc":[{"id":"1.195503848","rc":[{"atb":[[1.64,2],[1.67,0]],"id":43167125}],"con":true,"img":false}]}
{"op":"mcm","clk":"5353118121","pt":1646209241704,"mc":[{"id":"1.195503848","rc":[{"atb":[[1.64,0],[1.62,2]],"id":43167125}],"con":true,"img":false}]}
{"op":"mcm","clk":"5353118337","pt":1646209246799,"mc":[{"id":"1.195503848","rc":[{"atb":[[1.62,0],[1.52,2]],"id":43167125}],"con":true,"img":false}]}
{"op":"mcm","clk":"5353118931","pt":1646209261270,"mc":[{"id":"1.195503848","rc":[{"atl":[[38,1.42]],"id":43167126},{"atl":[[36,1.42]],"id":43167125}],"con":true,"img":false}]}
{"op":"mcm","clk":"5353118941","pt":1646209261430,"mc":[{"id":"1.195503848","rc":[{"atl":[[2.26,0],[2.78,2]],"id":43167126},{"atl":[[2.24,2],[2.14,0]],"id":43167125}],"con":true,"img":false}]}
{"op":"mcm","clk":"5353119001","pt":1646209262260,"mc":[{"id":"1.195503848","rc":[{"atl":[[40,1.42]],"id":43167126},{"atl":[[38,1.42]],"id":43167125}],"con":true,"img":false}]}
{"op":"mcm","clk":"5353119065","pt":1646209263454,"mc":[{"id":"1.195503848","rc":[{"atl":[[25,1.42]],"id":43167126},{"atl":[[23,1.42]],"id":43167125}],"con":true,"img":false}]}
{"op":"mcm","clk":"5353119112","pt":1646209264538,"mc":[{"id":"1.195503848","rc":[{"atb":[[1.53,2],[1.52,0]],"id":43167125}],"con":true,"img":false}]}
{"op":"mcm","clk":"5353119122","pt":1646209264741,"mc":[{"id":"1.195503848","rc":[{"atl":[[19.5,1.42]],"id":43167126},{"atl":[[18,1.42]],"id":43167125}],"con":true,"img":false}]}
{"op":"mcm","clk":"5353119169","pt":1646209265854,"mc":[{"id":"1.195503848","rc":[{"atl":[[18.5,1.42]],"id":43167126},{"atl":[[17,1.42]],"id":43167125}],"con":true,"img":false}]}
{"op":"mcm","clk":"5353119201","pt":1646209266569,"mc":[{"id":"1.195503848","rc":[{"atl":[[2.92,2],[2.78,0]],"id":43167126},{"atl":[[2.24,0],[2.26,2]],"id":43167125}],"con":true,"img":false}]}
{"op":"mcm","clk":"5353119205","pt":1646209266767,"mc":[{"id":"1.195503848","rc":[{"atl":[[2.92,0],[2.9,2]],"id":43167126}],"con":true,"img":false}]}
{"op":"mcm","clk":"5353119224","pt":1646209267138,"mc":[{"id":"1.195503848","rc":[{"atl":[[16.5,1.42]],"id":43167126},{"atl":[[2.24,2],[16.5,1.42],[2.26,0]],"id":43167125}],"con":true,"img":false}]}
{"op":"mcm","clk":"5353119282","pt":1646209268370,"mc":[{"id":"1.195503848","rc":[{"atl":[[16,1.42]],"id":43167126},{"atl":[[16,1.42]],"id":43167125}],"con":true,"img":false}]}
{"op":"mcm","clk":"5353119326","pt":1646209269461,"mc":[{"id":"1.195503848","rc":[{"atl":[[15.5,1.42]],"id":43167126},{"atl":[[15.5,1.42]],"id":43167125}],"con":true,"img":false}]}
{"op":"mcm","clk":"5353119334","pt":1646209269664,"mc":[{"id":"1.195503848","rc":[{"atb":[[1.53,0],[1.52,2]],"id":43167125}],"con":true,"img":false}]}
{"op":"mcm","clk":"5353119430","pt":1646209271876,"mc":[{"id":"1.195503848","rc":[{"atl":[[2.9,0],[2.78,2]],"id":43167126}],"con":true,"img":false}]}
{"op":"mcm","clk":"5353119460","pt":1646209272588,"mc":[{"id":"1.195503848","rc":[{"atl":[[14.5,1.42]],"id":43167126},{"atl":[[14.5,1.42]],"id":43167125}],"con":true,"img":false}]}
{"op":"mcm","clk":"5353119501","pt":1646209273368,"mc":[{"id":"1.195503848","rc":[{"atl":[[2.24,0],[2.26,2]],"id":43167125}],"con":true,"img":false}]}
{"op":"mcm","clk":"5353119516","pt":1646209273778,"mc":[{"id":"1.195503848","rc":[{"atl":[[13.5,1.42]],"id":43167126},{"atl":[[13.5,1.42]],"id":43167125}],"con":true,"img":false}]}
{"op":"mcm","clk":"5353119566","pt":1646209274751,"mc":[{"id":"1.195503848","rc":[{"atl":[[14,1.42]],"id":43167126},{"atl":[[14,1.42]],"id":43167125}],"con":true,"img":false}]}
{"op":"mcm","clk":"5353119633","pt":1646209276185,"mc":[{"id":"1.195503848","rc":[{"atl":[[15,1.42]],"id":43167126},{"atl":[[15,1.42]],"id":43167125}],"con":true,"img":false}]}
{"op":"mcm","clk":"5353119678","pt":1646209277479,"mc":[{"id":"1.195503848","rc":[{"atl":[[17,1.42]],"id":43167126},{"atl":[[17.5,1.42]],"id":43167125}],"con":true,"img":false}]}
{"op":"mcm","clk":"5353119713","pt":1646209278255,"mc":[{"id":"1.195503848","rc":[{"atl":[[13.5,0]],"id":43167126}],"con":true,"img":false}]}
{"op":"mcm","clk":"5353119728","pt":1646209278667,"mc":[{"id":"1.195503848","rc":[{"atl":[[2.26,0],[2.24,2]],"id":43167125}],"con":true,"img":false}]}
{"op":"mcm","clk":"5353119731","pt":1646209278771,"mc":[{"id":"1.195503848","rc":[{"atl":[[17.5,1.42]],"id":43167126}],"con":true,"img":false}]}
{"op":"mcm","clk":"5353119897","pt":1646209282676,"mc":[{"id":"1.195503848","rc":[{"atl":[[18,1.42]],"id":43167126}],"con":true,"img":false}]}
{"op":"mcm","clk":"5353119917","pt":1646209283084,"mc":[{"id":"1.195503848","rc":[{"atl":[[2.76,2],[2.78,0]],"id":43167126}],"con":true,"img":false}]}
{"op":"mcm","clk":"5353119936","pt":1646209283799,"mc":[{"id":"1.195503848","rc":[{"atl":[[2.26,2],[2.24,0]],"id":43167125}],"con":true,"img":false}]}
{"op":"mcm","clk":"5353119958","pt":1646209284373,"mc":[{"id":"1.195503848","rc":[{"atb":[[2.02,0],[1.81,0],[1.61,0]],"id":43167126},{"atb":[[1.11,0],[1.51,0],[1.31,0]],"id":43167125}],"con":true,"img":false}]}
{"op":"mcm","clk":"5353120043","pt":1646209286084,"mc":[{"id":"1.195503848","rc":[{"atl":[[13.5,1.42]],"id":43167126}],"con":true,"img":false}]}
{"op":"mcm","clk":"5353120086","pt":1646209287104,"mc":[{"id":"1.195503848","rc":[{"atl":[[13,1.42]],"id":43167125}],"con":true,"img":false}]}
{"op":"mcm","clk":"5353120126","pt":1646209288188,"mc":[{"id":"1.195503848","rc":[{"atl":[[2.78,2]],"id":43167126}],"con":true,"img":false}]}
{"op":"mcm","clk":"5353120129","pt":1646209288293,"mc":[{"id":"1.195503848","rc":[{"atl":[[2.76,0]],"id":43167126}],"con":true,"img":false}]}
{"op":"mcm","clk":"5353120175","pt":1646209289271,"mc":[{"id":"1.195503848","rc":[{"atl":[[13,1.42]],"id":43167126}],"con":true,"img":false}]}
{"op":"mcm","clk":"5353120220","pt":1646209290296,"mc":[{"id":"1.195503848","rc":[{"atl":[[12.5,1.42]],"id":43167126},{"atl":[[12.5,1.42]],"id":43167125}],"con":true,"img":false}]}
{"op":"mcm","clk":"5353120238","pt":1646209290708,"mc":[{"id":"1.195503848","rc":[{"atl":[[40,0]],"id":43167126}],"con":true,"img":false}]}
{"op":"mcm","clk":"5353120301","pt":1646209291888,"mc":[{"id":"1.195503848","rc":[{"atl":[[38,0]],"id":43167125}],"con":true,"img":false}]}
{"op":"mcm","clk":"5353120339","pt":1646209292709,"mc":[{"id":"1.195503848","rc":[{"atl":[[12,1.42]],"id":43167126},{"atl":[[12,1.42]],"id":43167125}],"con":true,"img":false}]}
{"op":"mcm","clk":"5353120348","pt":1646209292908,"mc":[{"id":"1.195503848","rc":[{"atl":[[38,0]],"id":43167126}],"con":true,"img":false}]}
{"op":"mcm","clk":"5353120366","pt":1646209293175,"mc":[{"id":"1.195503848","rc":[{"atl":[[2.26,0],[2.24,2]],"id":43167125}],"con":true,"img":false}]}
{"op":"mcm","clk":"5353120369","pt":1646209293270,"mc":[{"id":"1.195503848","rc":[{"atl":[[2.76,2],[2.78,0]],"id":43167126}],"con":true,"img":false}]}
{"op":"mcm","clk":"5353120398","pt":1646209293891,"mc":[{"id":"1.195503848","rc":[{"atb":[[1.2,48],[1.44,2],[1.45,6],[1.43,2],[1.33,21],[1.39,2],[1.35,2],[1.41,2],[1.36,2],[1.27,32],[1.25,2],[1.22,2],[1.42,9],[1.29,2],[1.31,2],[1.47,4],[1.38,14]],"id":43167125},{"atl":[[11.5,1.42]],"id":43167125}],"con":true,"img":false}]}
{"op":"mcm","clk":"5353120405","pt":1646209294089,"mc":[{"id":"1.195503848","rc":[{"atb":[[1.51,2],[1.52,0]],"id":43167125}],"con":true,"img":false}]}
{"op":"mcm","clk":"5353120422","pt":1646209294397,"mc":[{"id":"1.195503848","rc":[{"atl":[[36,0]],"id":43167125}],"con":true,"img":false}]}
{"op":"mcm","clk":"5353120448","pt":1646209294918,"mc":[{"id":"1.195503848","rc":[{"atl":[[11.5,2.84]],"id":43167125}],"con":true,"img":false}]}
{"op":"mcm","clk":"5353120497","pt":1646209296099,"mc":[{"id":"1.195503848","rc":[{"atl":[[11,1.42]],"id":43167126},{"atb":[[1.62,1.42]],"id":43167125}],"con":true,"img":false}]}
{"op":"mcm","clk":"5353120503","pt":1646209296303,"mc":[{"id":"1.195503848","rc":[{"atb":[[1.62,3.42],[1.51,0]],"id":43167125},{"atl":[[3.1,2],[2.6,2],[2.64,9],[2.58,6],[2.94,32],[3.2,48],[2.66,2],[2.78,2],[2.7,2],[2.82,21],[2.72,14],[2.54,4],[2.98,2],[2.62,2],[2.76,2],[2.86,2],[2.9,2]],"id":43167125}],"con":true,"img":false}]}
{"op":"mcm","clk":"5353120529","pt":1646209296923,"mc":[{"id":"1.195503848","rc":[{"atb":[[1.62,2]],"id":43167125},{"atl":[[11.5,0],[12,0],[12.5,0],[13,0],[13.5,0],[14,0],[14.5,0],[15,0],[15.5,0],[16,0],[16.5,0],[17,0],[17.5,0],[18,0],[23,0]],"id":43167125}],"con":true,"img":false}]}
{"op":"mcm","clk":"5353120533","pt":1646209297069,"mc":[{"id":"1.195503848","rc":[{"atb":[[1.94,1.42]],"id":43167126},{"atl":[[11.5,1.42]],"id":43167126},{"atb":[[1.61,1.42]],"id":43167125},{"atl":[[2.16,1.42]],"id":43167125}],"con":true,"img":false}]}
{"op":"mcm","clk":"5353120537","pt":1646209297172,"mc":[{"id":"1.195503848","rc":[{"atb":[[1.59,9.15],[1.99,5.45],[1.79,6.83],[1.89,2],[1.88,0]],"id":43167126},{"atb":[[1.33,37.37],[1.53,10.19],[1.13,41.56]],"id":43167125}],"con":true,"img":false}]}
{"op":"mcm","clk":"5353120572","pt":1646209297998,"mc":[{"id":"1.195503848","rc":[{"atb":[[1.94,0]],"id":43167126}],"con":true,"img":false}]}
{"op":"mcm","clk":"5353120577","pt":1646209298103,"mc":[{"id":"1.195503848","rc":[{"atb":[[1.93,1.42]],"id":43167126},{"atb":[[1.6,1.42]],"id":43167125},{"atl":[[2.22,1.42]],"id":43167125}],"con":true,"img":false}]}
{"op":"mcm","clk":"5353120586","pt":1646209298306,"mc":[{"id":"1.195503848","rc":[{"atl":[[2.16,3.42]],"id":43167125}],"con":true,"img":false}]}
{"op":"mcm","clk":"5353120588","pt":1646209298410,"mc":[{"id":"1.195503848","rc":[{"atl":[[2.76,0],[2.74,2]],"id":43167126},{"atl":[[2.22,3.42],[2.24,0],[2.16,1.42]],"id":43167125}],"con":true,"img":false}]}
{"op":"mcm","clk":"5353120593","pt":1646209298511,"mc":[{"id":"1.195503848","rc":[{"atl":[[2.22,1.42],[2.16,3.42]],"id":43167125}],"con":true,"img":false}]}
{"op":"mcm","clk":"5353120603","pt":1646209298767,"mc":[{"id":"1.195503848","rc":[{"atl":[[11,0]],"id":43167126}],"con":true,"img":false}]}
{"op":"mcm","clk":"5353120607","pt":1646209298871,"mc":[{"id":"1.195503848","rc":[{"atl":[[2.74,0],[2.7,2]],"id":43167126}],"con":true,"img":false}]}
{"op":"mcm","clk":"5353120624","pt":1646209299383,"mc":[{"id":"1.195503848","rc":[{"atb":[[2.1,1.42]],"id":43167126},{"atb":[[1.63,1.42]],"id":43167125},{"atl":[[2,1.42]],"id":43167125}],"con":true,"img":false}]}
{"op":"mcm","clk":"5353120661","pt":1646209300513,"mc":[{"id":"1.195503848","rc":[{"atb":[[2.02,1.42]],"id":43167126},{"atb":[[1.59,1.42]],"id":43167125}],"con":true,"img":false}]}
{"op":"mcm","clk":"5353120686","pt":1646209301181,"mc":[{"id":"1.195503848","rc":[{"atb":[[2.1,0]],"id":43167126},{"atl":[[11.5,0]],"id":43167126}],"con":true,"img":false}]}
{"op":"mcm","clk":"5353120786","pt":1646209302878,"mc":[{"id":"1.195503848","rc":[{"atl":[[12,0]],"id":43167126}],"con":true,"img":false}]}
{"op":"mcm","clk":"5353120819","pt":1646209303597,"mc":[{"id":"1.195503848","rc":[{"atl":[[2.12,2]],"id":43167125}],"con":true,"img":false}]}
{"op":"mcm","clk":"5353120823","pt":1646209303699,"mc":[{"id":"1.195503848","rc":[{"atl":[[12.5,0]],"id":43167126},{"atl":[[2.16,1.42]],"id":43167125}],"con":true,"img":false}]}
{"op":"mcm","clk":"5353120832","pt":1646209304008,"mc":[{"id":"1.195503848","rc":[{"atl":[[2.66,2],[2.7,0]],"id":43167126}],"con":true,"img":false}]}
{"op":"mcm","clk":"5353120849","pt":1646209304319,"mc":[{"id":"1.195503848","rc":[{"atb":[[2.08,1.42]],"id":43167126},{"atl":[[2.12,3.42]],"id":43167125}],"con":true,"img":false}]}
{"op":"mcm","clk":"5353120867","pt":1646209304789,"mc":[{"id":"1.195503848","rc":[{"atb":[[1.93,0]],"id":43167126},{"atl":[[13,0]],"id":43167126},{"atl":[[2,0]],"id":43167125}],"con":true,"img":false}]}
{"op":"mcm","clk":"5353120903","pt":1646209305587,"mc":[{"id":"1.195503848","rc":[{"atb":[[2,1.42]],"id":43167126},{"atl":[[19,1.42]],"id":43167126}],"con":true,"img":false}]}
{"op":"mcm","clk":"5353120923","pt":1646209306003,"mc":[{"id":"1.195503848","rc":[{"atb":[[1.94,15],[2.08,0]],"id":43167126},{"atl":[[13.5,0],[14,0]],"id":43167126},{"atb":[[1.59,0]],"id":43167125},{"atl":[[2.22,0]],"id":43167125}],"con":true,"img":false}]}
{"op":"mcm","clk":"5353121022","pt":1646209308107,"mc":[{"id":"1.195503848","rc":[{"atb":[[2.02,0]],"id":43167126},{"atl":[[14.5,0]],"id":43167126},{"atb":[[1.6,0],[1.61,0]],"id":43167125},{"atl":[[2.12,2],[2.16,0]],"id":43167125}],"con":true,"img":false}]}
{"op":"mcm","clk":"5353121027","pt":1646209308216,"mc":[{"id":"1.195503848","rc":[{"atl":[[2.12,0],[2.2,2]],"id":43167125}],"con":true,"img":false}]}
{"op":"mcm","clk":"5353121041","pt":1646209308632,"mc":[{"id":"1.195503848","rc":[{"atb":[[1.98,1.42]],"id":43167126}],"con":true,"img":false}]}
{"op":"mcm","clk":"5353121068","pt":1646209309092,"mc":[{"id":"1.195503848","rc":[{"atl":[[2.62,2],[2.66,0]],"id":43167126}],"con":true,"img":false}]}
{"op":"mcm","clk":"5353121096","pt":1646209309922,"mc":[{"id":"1.195503848","rc":[{"atb":[[1.97,1.42]],"id":43167126}],"con":true,"img":false}]}
{"op":"mcm","clk":"5353121103","pt":1646209310129,"mc":[{"id":"1.195503848","rc":[{"atl":[[15,0]],"id":43167126}],"con":true,"img":false}]}
{"op":"mcm","clk":"5353121153","pt":1646209311109,"mc":[{"id":"1.195503848","rc":[{"atb":[[1.96,1.42]],"id":43167126},{"atl":[[20,1.42]],"id":43167126}],"con":true,"img":false}]}
{"op":"mcm","clk":"5353121245","pt":1646209312094,"mc":[{"id":"1.195503848","rc":[{"atb":[[2.02,1.42]],"id":43167126}],"con":true,"img":false}]}
{"op":"mcm","clk":"5353121265","pt":1646209312310,"mc":[{"id":"1.195503848","rc":[{"atb":[[1.83,2],[1.89,0],[1.94,0]],"id":43167126}],"con":true,"img":false}]}
{"op":"mcm","clk":"5353121314","pt":1646209313335,"mc":[{"id":"1.195503848","rc":[{"atl":[[2.22,2],[2.2,0]],"id":43167125}],"con":true,"img":false}]}
{"op":"mcm","clk":"5353121321","pt":1646209313544,"mc":[{"id":"1.195503848","rc":[{"atb":[[2.02,0],[1.98,0],[1.97,0],[1.96,0]],"id":43167126},{"atb":[[1.54,1.42]],"id":43167125}],"con":true,"img":false}]}
{"op":"mcm","clk":"5353121338","pt":1646209313999,"mc":[{"id":"1.195503848","rc":[{"atl":[[2.22,0],[2.28,2]],"id":43167125}],"con":true,"img":false}]}
{"op":"mcm","clk":"5353121350","pt":1646209314203,"mc":[{"id":"1.195503848","rc":[{"atl":[[2.58,2],[2.62,0]],"id":43167126}],"con":true,"img":false}]}
{"op":"mcm","clk":"5353121519","pt":1646209318210,"mc":[{"id":"1.195503848","rc":[{"atl":[[2.26,1.42]],"id":43167125}],"con":true,"img":false}]}
{"op":"mcm","clk":"5353121566","pt":1646209319442,"mc":[{"id":"1.195503848","rc":[{"atl":[[2.58,0],[2.56,2]],"id":43167126}],"con":true,"img":false}]}
{"op":"mcm","clk":"5353121614","pt":1646209320420,"mc":[{"id":"1.195503848","rc":[{"atb":[[1.63,0]],"id":43167125}],"con":true,"img":false}]}
{"op":"mcm","clk":"5353121618","pt":1646209320523,"mc":[{"id":"1.195503848","rc":[{"atb":[[2,10.01]],"id":43167126},{"atl":[[2.56,10.56]],"id":43167126},{"atb":[[1.59,2],[1.62,10.08]],"id":43167125}],"con":true,"img":false}]}
{"op":"mcm","clk":"5353121656","pt":1646209321346,"mc":[{"id":"1.195503848","rc":[{"atb":[[2.06,1.42]],"id":43167126},{"atb":[[1.7,1.42]],"id":43167125}],"con":true,"img":false}]}
{"op":"mcm","clk":"5353121666","pt":1646209321553,"mc":[{"id":"1.195503848","rc":[{"atb":[[1.54,0]],"id":43167125}],"con":true,"img":false}]}
{"op":"mcm","clk":"5353121726","pt":1646209322840,"mc":[{"id":"1.195503848","rc":[{"atb":[[2.08,1.42]],"id":43167126},{"atb":[[1.67,1.42]],"id":43167125}],"con":true,"img":false}]}
{"op":"mcm","clk":"5353121742","pt":1646209323251,"mc":[{"id":"1.195503848","rc":[{"atb":[[2.06,0]],"id":43167126},{"atb":[[1.7,0]],"id":43167125},{"atl":[[2.26,0]],"id":43167125}],"con":true,"img":false}]}
{"op":"mcm","clk":"5353121749","pt":1646209323405,"mc":[{"id":"1.195503848","rc":[{"atl":[[2.3,2],[2.28,0]],"id":43167125}],"con":true,"img":false}]}
{"op":"mcm","clk":"5353121754","pt":1646209323507,"mc":[{"id":"1.195503848","rc":[{"atb":[[1.67,11.49]],"id":43167125}],"con":true,"img":false}]}
{"op":"mcm","clk":"5353121788","pt":1646209324334,"mc":[{"id":"1.195503848","rc":[{"atb":[[2.02,1.42]],"id":43167126},{"atb":[[1.7,1.42]],"id":43167125}],"con":true,"img":false}]}
{"op":"mcm","clk":"5353121810","pt":1646209324950,"mc":[{"id":"1.195503848","rc":[{"atb":[[2.08,0]],"id":43167126},{"atl":[[15.5,0]],"id":43167126},{"atb":[[1.67,10.06]],"id":43167125}],"con":true,"img":false}]}
{"op":"mcm","clk":"5353121827","pt":1646209325311,"mc":[{"id":"1.195503848","rc":[{"atl":[[2.3,0],[2.28,2]],"id":43167125}],"con":true,"img":false}]}
{"op":"mcm","clk":"5353121841","pt":1646209325619,"mc":[{"id":"1.195503848","rc":[{"atb":[[1.59,0],[1.7,3.42]],"id":43167125}],"con":true,"img":false}]}
{"op":"mcm","clk":"5353121871","pt":1646209326444,"mc":[{"id":"1.195503848","rc":[{"atb":[[2.02,0],[2.08,1.42]],"id":43167126},{"atl":[[21,1.42]],"id":43167126},{"atb":[[1.7,2],[1.72,1.42]],"id":43167125},{"atl":[[2.3,2],[2.28,0]],"id":43167125}],"con":true,"img":false}]}
{"op":"mcm","clk":"5353121920","pt":1646209327631,"mc":[{"id":"1.195503848","rc":[{"atl":[[22,1.42]],"id":43167126},{"atb":[[1.68,1.42],[1.72,11.47]],"id":43167125}],"con":true,"img":false}]}
{"op":"mcm","clk":"5353121941","pt":1646209328041,"mc":[{"id":"1.195503848","rc":[{"atb":[[2.08,0]],"id":43167126},{"atl":[[16,0]],"id":43167126}],"con":true,"img":false}]}
{"op":"mcm","clk":"5353121967","pt":1646209328715,"mc":[{"id":"1.195503848","rc":[{"atl":[[2.3,11.6]],"id":43167125}],"con":true,"img":false}]}
{"op":"mcm","clk":"5353121976","pt":1646209329024,"mc":[{"id":"1.195503848","rc":[{"atb":[[2.04,1.42]],"id":43167126},{"atb":[[1.69,1.42]],"id":43167125}],"con":true,"img":false}]}
{"op":"mcm","clk":"5353122002","pt":1646209329640,"mc":[{"id":"1.195503848","rc":[{"atl":[[16.5,0]],"id":43167126},{"atb":[[1.68,0]],"id":43167125}],"con":true,"img":false}]}
{"op":"mcm","clk":"5353122040","pt":1646209330623,"mc":[{"id":"1.195503848","rc":[{"atb":[[2.04,2.84]],"id":43167126},{"atl":[[23,1.42]],"id":43167126},{"atb":[[1.75,1.42]],"id":43167125}],"con":true,"img":false}]}
{"op":"mcm","clk":"5353122045","pt":1646209330724,"mc":[{"id":"1.195503848","rc":[{"atb":[[1.7,0],[1.75,3.42]],"id":43167125}],"con":true,"img":false}]}
{"op":"mcm","clk":"5353122077","pt":1646209331343,"mc":[{"id":"1.195503848","rc":[{"atl":[[17,0]],"id":43167126},{"atb":[[1.69,0]],"id":43167125}],"con":true,"img":false}]}
{"op":"mcm","clk":"5353122148","pt":1646209332535,"mc":[{"id":"1.195503848","rc":[{"atl":[[24,1.42]],"id":43167126}],"con":true,"img":false}]}
{"op":"mcm","clk":"5353122178","pt":1646209333048,"mc":[{"id":"1.195503848","rc":[{"atl":[[17.5,0],[18,0]],"id":43167126},{"atb":[[1.75,2]],"id":43167125}],"con":true,"img":false}]}
{"op":"mcm","clk":"5353122250","pt":1646209334445,"mc":[{"id":"1.195503848","rc":[{"atl":[[26,1.42]],"id":43167126}],"con":true,"img":false}]}
{"op":"mcm","clk":"5353122273","pt":1646209334855,"mc":[{"id":"1.195503848","rc":[{"atl":[[18.5,0],[19,0]],"id":43167126}],"con":true,"img":false}]}
{"op":"mcm","clk":"5353122328","pt":1646209335836,"mc":[{"id":"1.195503848","rc":[{"atl":[[26,2.84]],"id":43167126},{"atb":[[1.73,2],[1.75,0]],"id":43167125}],"con":true,"img":false}]}
{"op":"mcm","clk":"5353122357","pt":1646209336557,"mc":[{"id":"1.195503848","rc":[{"atl":[[19.5,0]],"id":43167126}],"con":true,"img":false}]}
{"op":"mcm","clk":"5353122398","pt":1646209337438,"mc":[{"id":"1.195503848","rc":[{"atl":[[27,1.42]],"id":43167126}],"con":true,"img":false}]}
{"op":"mcm","clk":"5353122403","pt":1646209337541,"mc":[{"id":"1.195503848","rc":[{"atl":[[20,0]],"id":43167126}],"con":true,"img":false}]}
{"op":"mcm","clk":"5353122467","pt":1646209339032,"mc":[{"id":"1.195503848","rc":[{"atl":[[27,2.84]],"id":43167126}],"con":true,"img":false}]}
{"op":"mcm","clk":"5353122476","pt":1646209339342,"mc":[{"id":"1.195503848","rc":[{"atl":[[21,0]],"id":43167126}],"con":true,"img":false}]}
{"op":"mcm","clk":"5353122522","pt":1646209340525,"mc":[{"id":"1.195503848","rc":[{"atl":[[28,1.42]],"id":43167126}],"con":true,"img":false}]}
{"op":"mcm","clk":"5353122575","pt":1646209341969,"mc":[{"id":"1.195503848","rc":[{"atl":[[28,2.84]],"id":43167126}],"con":true,"img":false}]}
{"op":"mcm","clk":"5353122595","pt":1646209342438,"mc":[{"id":"1.195503848","rc":[{"atl":[[22,0]],"id":43167126}],"con":true,"img":false}]}
{"op":"mcm","clk":"5353122638","pt":1646209343473,"mc":[{"id":"1.195503848","rc":[{"atl":[[29,1.42]],"id":43167126}],"con":true,"img":false}]}
{"op":"mcm","clk":"5353122645","pt":1646209343631,"mc":[{"id":"1.195503848","rc":[{"atb":[[1.59,0],[1.99,0],[1.79,0]],"id":43167126},{"atb":[[1.33,21],[1.53,0],[1.13,0]],"id":43167125}],"con":true,"img":false}]}
{"op":"mcm","clk":"5353122661","pt":1646209344050,"mc":[{"id":"1.195503848","rc":[{"atb":[[1.73,12.04]],"id":43167125}],"con":true,"img":false}]}
{"op":"mcm","clk":"5353122698","pt":1646209344873,"mc":[{"id":"1.195503848","rc":[{"atl":[[29,2.84]],"id":43167126}],"con":true,"img":false}]}
{"op":"mcm","clk":"5353122730","pt":1646209345551,"mc":[{"id":"1.195503848","rc":[{"atb":[[2,8.58]],"id":43167126},{"atb":[[1.72,10.05]],"id":43167125}],"con":true,"img":false}]}
{"op":"mcm","clk":"5353122792","pt":1646209346185,"mc":[{"id":"1.195503848","rc":[{"atb":[[2.06,8.59]],"id":43167126}],"con":true,"img":false}]}
{"op":"mcm","clk":"5353122802","pt":1646209346241,"mc":[{"id":"1.195503848","rc":[{"atl":[[30,1.42]],"id":43167126}],"con":true,"img":false}]}
{"op":"mcm","clk":"5353122927","pt":1646209347949,"mc":[{"id":"1.195503848","rc":[{"atl":[[30,2.84]],"id":43167126}],"con":true,"img":false}]}
{"op":"mcm","clk":"5353122967","pt":1646209348773,"mc":[{"id":"1.195503848","rc":[{"atb":[[2.04,0]],"id":43167126}],"con":true,"img":false}]}
{"op":"mcm","clk":"5353123031","pt":1646209350060,"mc":[{"id":"1.195503848","rc":[{"atl":[[32,1.42]],"id":43167126}],"con":true,"img":false}]}
{"op":"mcm","clk":"5353123069","pt":1646209351036,"mc":[{"id":"1.195503848","rc":[{"atl":[[32,2.84]],"id":43167126}],"con":true,"img":false}]}
{"op":"mcm","clk":"5353123181","pt":1646209353044,"mc":[{"id":"1.195503848","rc":[{"atl":[[34,1.42]],"id":43167126}],"con":true,"img":false}]}
{"op":"mcm","clk":"5353123250","pt":1646209354484,"mc":[{"id":"1.195503848","rc":[{"atl":[[34,2.84]],"id":43167126}],"con":true,"img":false}]}
{"op":"mcm","clk":"5353123278","pt":1646209355105,"mc":[{"id":"1.195503848","rc":[{"atb":[[1.56,9.65],[1.96,5.62],[1.76,7.11]],"id":43167126},{"atb":[[1.37,14.6],[1.57,9.48],[1.17,31.79]],"id":43167125}],"con":true,"img":false}]}
{"op":"mcm","clk":"5353123316","pt":1646209355879,"mc":[{"id":"1.195503848","rc":[{"atl":[[36,1.42]],"id":43167126}],"con":true,"img":false}]}
{"op":"mcm","clk":"5353123328","pt":1646209356081,"mc":[{"id":"1.195503848","rc":[{"atl":[[2.54,2],[2.56,8.56]],"id":43167126}],"con":true,"img":false}]}
{"op":"mcm","clk":"5353123331","pt":1646209356186,"mc":[{"id":"1.195503848","rc":[{"atl":[[23,0]],"id":43167126}],"con":true,"img":false}]}
{"op":"mcm","clk":"5353123382","pt":1646209357271,"mc":[{"id":"1.195503848","rc":[{"atb":[[1.74,1.42]],"id":43167125}],"con":true,"img":false}]}
{"op":"mcm","clk":"5353123392","pt":1646209357477,"mc":[{"id":"1.195503848","rc":[{"atl":[[32,0],[34,0],[36,0],[24,0],[25,0],[26,0],[27,0],[28,0],[29,0],[30,0]],"id":43167126}],"con":true,"img":false}]}
{"op":"mcm","clk":"5353123428","pt":1646209358352,"mc":[{"id":"1.195503848","rc":[{"atb":[[1.74,11.39]],"id":43167125}],"con":true,"img":false}]}
{"op":"mcm","clk":"5353123432","pt":1646209358455,"mc":[{"id":"1.195503848","rc":[{"atb":[[1.73,10.04],[1.75,2]],"id":43167125}],"con":true,"img":false}]}
{"op":"mcm","clk":"5353123438","pt":1646209358558,"mc":[{"id":"1.195503848","rc":[{"atb":[[1.62,0]],"id":43167125}],"con":true,"img":false}]}
{"op":"mcm","clk":"5353123499","pt":1646209359946,"mc":[{"id":"1.195503848","rc":[{"atl":[[30,1.42]],"id":43167126}],"con":true,"img":false}]}
{"op":"mcm","clk":"5353123525","pt":1646209360672,"mc":[{"id":"1.195503848","rc":[{"atl":[[2.54,10.62]],"id":43167126},{"atb":[[1.75,11.97]],"id":43167125}],"con":true,"img":false}]}
{"op":"mcm","clk":"5353123533","pt":1646209360878,"mc":[{"id":"1.195503848","rc":[{"atb":[[1.67,0]],"id":43167125}],"con":true,"img":false}]}
{"op":"mcm","clk":"5353123573","pt":1646209361763,"mc":[{"id":"1.195503848","rc":[{"atl":[[32,1.42]],"id":43167126},{"atb":[[1.77,1.42]],"id":43167125}],"con":true,"img":false}]}
{"op":"mcm","clk":"5353123599","pt":1646209362282,"mc":[{"id":"1.195503848","rc":[{"atb":[[1.74,9.97]],"id":43167125}],"con":true,"img":false}]}
{"op":"mcm","clk":"5353123664","pt":1646209363578,"mc":[{"id":"1.195503848","rc":[{"atb":[[1.77,3.42],[1.75,9.97]],"id":43167125}],"con":true,"img":false}]}
{"op":"mcm","clk":"5353123669","pt":1646209363680,"mc":[{"id":"1.195503848","rc":[{"atl":[[34,1.42]],"id":43167126},{"atb":[[1.76,1.42]],"id":43167125}],"con":true,"img":false}]}
{"op":"mcm","clk":"5353123738","pt":1646209364982,"mc":[{"id":"1.195503848","rc":[{"atl":[[36,1.42]],"id":43167126}],"con":true,"img":false}]}
{"op":"mcm","clk":"5353123746","pt":1646209365189,"mc":[{"id":"1.195503848","rc":[{"atb":[[1.77,2]],"id":43167125}],"con":true,"img":false}]}
{"op":"mcm","clk":"5353123797","pt":1646209366271,"mc":[{"id":"1.195503848","rc":[{"atl":[[38,1.42]],"id":43167126}],"con":true,"img":false}]}
{"op":"mcm","clk":"5353123850","pt":1646209367510,"mc":[{"id":"1.195503848","rc":[{"atl":[[40,1.42]],"id":43167126}],"con":true,"img":false}]}
{"op":"mcm","clk":"5353123856","pt":1646209367560,"mc":[{"id":"1.195503848","rc":[{"atb":[[1.77,12]],"id":43167125}],"con":true,"img":false}]}
{"op":"mcm","clk":"5353123861","pt":1646209367663,"mc":[{"id":"1.195503848","rc":[{"atb":[[1.72,0]],"id":43167125}],"con":true,"img":false}]}
{"op":"mcm","clk":"5353123919","pt":1646209368900,"mc":[{"id":"1.195503848","rc":[{"atl":[[40,2.84]],"id":43167126}],"con":true,"img":false}]}
{"op":"mcm","clk":"5353123928","pt":1646209369105,"mc":[{"id":"1.195503848","rc":[{"atb":[[1.76,0]],"id":43167125}],"con":true,"img":false}]}
{"op":"mcm","clk":"5353124004","pt":1646209370495,"mc":[{"id":"1.195503848","rc":[{"atl":[[42,1.42]],"id":43167126},{"atb":[[1.78,1.42]],"id":43167125}],"con":true,"img":false}]}
{"op":"mcm","clk":"5353124077","pt":1646209371989,"mc":[{"id":"1.195503848","rc":[{"atl":[[42,2.84]],"id":43167126}],"con":true,"img":false}]}
{"op":"mcm","clk":"5353124124","pt":1646209373276,"mc":[{"id":"1.195503848","rc":[{"atb":[[2.06,0]],"id":43167126},{"atb":[[1.78,11.39]],"id":43167125}],"con":true,"img":false}]}
{"op":"mcm","clk":"5353124126","pt":1646209373379,"mc":[{"id":"1.195503848","rc":[{"atl":[[44,1.42]],"id":43167126},{"atb":[[1.77,10],[1.73,0],[1.79,2]],"id":43167125}],"con":true,"img":false}]}
{"op":"mcm","clk":"5353124145","pt":1646209373898,"mc":[{"id":"1.195503848","rc":[{"atl":[[32,0],[34,0],[36,0],[38,0],[40,0],[42,0],[30,0]],"id":43167126}],"con":true,"img":false}]}
{"op":"mcm","clk":"5353124218","pt":1646209375293,"mc":[{"id":"1.195503848","rc":[{"atl":[[38,1.42]],"id":43167126}],"con":true,"img":false}]}
{"op":"mcm","clk":"5353124272","pt":1646209376478,"mc":[{"id":"1.195503848","rc":[{"atl":[[2.54,8.62],[2.5,2]],"id":43167126},{"atb":[[1.79,11.89]],"id":43167125}],"con":true,"img":false}]}
{"op":"mcm","clk":"5353124285","pt":1646209376688,"mc":[{"id":"1.195503848","rc":[{"atl":[[40,1.42]],"id":43167126},{"atb":[[1.74,0]],"id":43167125}],"con":true,"img":false}]}
{"op":"mcm","clk":"5353124335","pt":1646209378074,"mc":[{"id":"1.195503848","rc":[{"atl":[[36,1.42]],"id":43167126}],"con":true,"img":false}]}
{"op":"mcm","clk":"5353124339","pt":1646209378176,"mc":[{"id":"1.195503848","rc":[{"atb":[[1.78,9.96]],"id":43167125}],"con":true,"img":false}]}
{"op":"mcm","clk":"5353124413","pt":1646209379420,"mc":[{"id":"1.195503848","rc":[{"atl":[[36,2.84]],"id":43167126}],"con":true,"img":false}]}
{"op":"mcm","clk":"5353124461","pt":1646209380195,"mc":[{"id":"1.195503848","rc":[{"atl":[[2.3,9.6],[2.28,2]],"id":43167125}],"con":true,"img":false}]}
{"op":"mcm","clk":"5353124482","pt":1646209380709,"mc":[{"id":"1.195503848","rc":[{"atl":[[2.5,10.64]],"id":43167126},{"atl":[[2.28,11.61]],"id":43167125}],"con":true,"img":false}]}
{"op":"mcm","clk":"5353124489","pt":1646209380814,"mc":[{"id":"1.195503848","rc":[{"atl":[[42,1.42]],"id":43167126}],"con":true,"img":false}]}
{"op":"mcm","clk":"5353124523","pt":1646209381585,"mc":[{"id":"1.195503848","rc":[{"atl":[[2.5,8.64],[2.48,2]],"id":43167126}],"con":true,"img":false}]}
{"op":"mcm","clk":"5353124578","pt":1646209382613,"mc":[{"id":"1.195503848","rc":[{"atl":[[36,0],[38,0],[40,0],[42,0],[44,0]],"id":43167126}],"con":true,"img":false}]}
{"op":"mcm","clk":"5353124715","pt":1646209385734,"mc":[{"id":"1.195503848","rc":[{"atl":[[34,1.42]],"id":43167126},{"atb":[[1.8,1.42]],"id":43167125}],"con":true,"img":false}]}
{"op":"mcm","clk":"5353124778","pt":1646209387124,"mc":[{"id":"1.195503848","rc":[{"atl":[[36,1.42]],"id":43167126}],"con":true,"img":false}]}
{"op":"mcm","clk":"5353124830","pt":1646209388207,"mc":[{"id":"1.195503848","rc":[{"atl":[[32,1.42]],"id":43167126}],"con":true,"img":false}]}
{"op":"mcm","clk":"5353124897","pt":1646209389494,"mc":[{"id":"1.195503848","rc":[{"atl":[[38,1.42]],"id":43167126}],"con":true,"img":false}]}
{"op":"mcm","clk":"5353124935","pt":1646209390518,"mc":[{"id":"1.195503848","rc":[{"atl":[[40,1.42]],"id":43167126}],"con":true,"img":false}]}
{"op":"mcm","clk":"5353125012","pt":1646209391908,"mc":[{"id":"1.195503848","rc":[{"atl":[[32,0],[34,0],[36,0],[38,0],[40,0]],"id":43167126}],"con":true,"img":false}]}
{"op":"mcm","clk":"5353125133","pt":1646209394329,"mc":[{"id":"1.195503848","rc":[{"atl":[[34,1.42]],"id":43167126}],"con":true,"img":false}]}
{"op":"mcm","clk":"5353125201","pt":1646209395718,"mc":[{"id":"1.195503848","rc":[{"atl":[[36,1.42]],"id":43167126}],"con":true,"img":false}]}
{"op":"mcm","clk":"5353125256","pt":1646209396851,"mc":[{"id":"1.195503848","rc":[{"atl":[[2.48,10.63]],"id":43167126},{"atb":[[1.8,11.29]],"id":43167125}],"con":true,"img":false}]}
{"op":"mcm","clk":"5353125267","pt":1646209397057,"mc":[{"id":"1.195503848","rc":[{"atb":[[1.81,2],[1.79,9.89],[1.75,0]],"id":43167125}],"con":true,"img":false}]}
{"op":"mcm","clk":"5353125390","pt":1646209399640,"mc":[{"id":"1.195503848","rc":[{"atl":[[34,0],[36,0]],"id":43167126}],"con":true,"img":false}]}
{"op":"mcm","clk":"5353125612","pt":1646209403525,"mc":[{"id":"1.195503848","rc":[{"atb":[[1.56,0],[1.96,0],[1.76,0]],"id":43167126},{"atb":[[1.17,0],[1.37,0],[1.57,0]],"id":43167125}],"con":true,"img":false}]}
{"op":"mcm","clk":"5353125721","pt":1646209405225,"mc":[{"id":"1.195503848","rc":[{"atb":[[1.81,11.86]],"id":43167125}],"con":true,"img":false}]}
{"op":"mcm","clk":"5353125727","pt":1646209405328,"mc":[{"id":"1.195503848","rc":[{"atb":[[1.77,0]],"id":43167125}],"con":true,"img":false}]}
{"op":"mcm","clk":"5353125732","pt":1646209405433,"mc":[{"id":"1.195503848","rc":[{"atl":[[2.48,8.63]],"id":43167126}],"con":true,"img":false}]}
{"op":"mcm","clk":"5353125739","pt":1646209405538,"mc":[{"id":"1.195503848","rc":[{"atl":[[2.44,2]],"id":43167126}],"con":true,"img":false}]}
{"op":"mcm","clk":"5353125744","pt":1646209405641,"mc":[{"id":"1.195503848","rc":[{"atl":[[2.46,2]],"id":43167126}],"con":true,"img":false}]}
{"op":"mcm","clk":"5353125749","pt":1646209405744,"mc":[{"id":"1.195503848","rc":[{"atl":[[2.44,0]],"id":43167126}],"con":true,"img":false}]}
{"op":"mcm","clk":"5353125754","pt":1646209405847,"mc":[{"id":"1.195503848","rc":[{"atl":[[36,1.42]],"id":43167126}],"con":true,"img":false}]}
{"op":"mcm","clk":"5353125828","pt":1646209407341,"mc":[{"id":"1.195503848","rc":[{"atl":[[36,2.84]],"id":43167126}],"con":true,"img":false}]}
{"op":"mcm","clk":"5353125865","pt":1646209408062,"mc":[{"id":"1.195503848","rc":[{"atb":[[1.8,9.87]],"id":43167125}],"con":true,"img":false}]}
{"op":"mcm","clk":"5353125890","pt":1646209408628,"mc":[{"id":"1.195503848","rc":[{"atl":[[2.46,10.62]],"id":43167126}],"con":true,"img":false}]}
{"op":"mcm","clk":"5353125892","pt":1646209408734,"mc":[{"id":"1.195503848","rc":[{"atl":[[2.56,0]],"id":43167126}],"con":true,"img":false}]}
{"op":"mcm","clk":"5353125935","pt":1646209409558,"mc":[{"id":"1.195503848","rc":[{"atl":[[38,1.42]],"id":43167126}],"con":true,"img":false}]}
{"op":"mcm","clk":"5353125989","pt":1646209410642,"mc":[{"id":"1.195503848","rc":[{"atl":[[40,1.42]],"id":43167126}],"con":true,"img":false}]}
{"op":"mcm","clk":"5353126058","pt":1646209412137,"mc":[{"id":"1.195503848","rc":[{"atl":[[42,1.42]],"id":43167126}],"con":true,"img":false}]}
{"op":"mcm","clk":"5353126141","pt":1646209413532,"mc":[{"id":"1.195503848","rc":[{"atl":[[42,2.84]],"id":43167126}],"con":true,"img":false}]}
{"op":"mcm","clk":"5353126187","pt":1646209414560,"mc":[{"id":"1.195503848","rc":[{"atb":[[1.88,6.14],[1.68,7.94],[1.48,11.26]],"id":43167126},{"atb":[[1.28,19.3],[1.68,7.94],[1.48,11.26]],"id":43167125}],"con":true,"img":false}]}
{"op":"mcm","clk":"5353126205","pt":1646209415081,"mc":[{"id":"1.195503848","rc":[{"atl":[[44,1.42]],"id":43167126}],"con":true,"img":false}]}
{"op":"mcm","clk":"5353126270","pt":1646209416361,"mc":[{"id":"1.195503848","rc":[{"atl":[[44,2.84]],"id":43167126}],"con":true,"img":false}]}
{"op":"mcm","clk":"5353126310","pt":1646209417138,"mc":[{"id":"1.195503848","rc":[{"atl":[[36,0],[38,0],[40,0],[42,0],[44,1.42]],"id":43167126}],"con":true,"img":false}]}
{"op":"mcm","clk":"5353126371","pt":1646209418277,"mc":[{"id":"1.195503848","rc":[{"atb":[[1.83,0],[1.92,2]],"id":43167126}],"con":true,"img":false}]}
{"op":"mcm","clk":"5353126386","pt":1646209418561,"mc":[{"id":"1.195503848","rc":[{"atl":[[44,0]],"id":43167126},{"atb":[[1.82,1.42]],"id":43167125}],"con":true,"img":false}]}
{"op":"mcm","clk":"5353126409","pt":1646209419030,"mc":[{"id":"1.195503848","rc":[{"atb":[[1.82,11.26]],"id":43167125}],"con":true,"img":false}]}
{"op":"mcm","clk":"5353126413","pt":1646209419132,"mc":[{"id":"1.195503848","rc":[{"atb":[[1.78,0],[1.81,9.86],[1.82,13.26]],"id":43167125}],"con":true,"img":false}]}
{"op":"mcm","clk":"5353126478","pt":1646209420579,"mc":[{"id":"1.195503848","rc":[{"atb":[[1.83,1.42]],"id":43167125}],"con":true,"img":false}]}
{"op":"mcm","clk":"5353126488","pt":1646209420734,"mc":[{"id":"1.195503848","rc":[{"atl":[[2.22,2],[2.28,9.61]],"id":43167125}],"con":true,"img":false}]}
{"op":"mcm","clk":"5353126516","pt":1646209421352,"mc":[{"id":"1.195503848","rc":[{"atb":[[1.83,11.26]],"id":43167125},{"atl":[[2.22,11.65]],"id":43167125}],"con":true,"img":false}]}
{"op":"mcm","clk":"5353126523","pt":1646209421457,"mc":[{"id":"1.195503848","rc":[{"atl":[[2.22,9.65],[2.2,2]],"id":43167125}],"con":true,"img":false}]}
{"op":"mcm","clk":"5353126528","pt":1646209421559,"mc":[{"id":"1.195503848","rc":[{"atb":[[1.79,0]],"id":43167125}],"con":true,"img":false}]}
{"op":"mcm","clk":"5353126617","pt":1646209423463,"mc":[{"id":"1.195503848","rc":[{"atb":[[1.82,11.83]],"id":43167125}],"con":true,"img":false}]}
{"op":"mcm","clk":"5353126651","pt":1646209424247,"mc":[{"id":"1.195503848","rc":[{"atb":[[1.84,1.42]],"id":43167125}],"con":true,"img":false}]}
{"op":"mcm","clk":"5353126787","pt":1646209427071,"mc":[{"id":"1.195503848","rc":[{"atb":[[1.84,0]],"id":43167125}],"con":true,"img":false}]}
{"op":"mcm","clk":"5353127034","pt":1646209431670,"mc":[{"id":"1.195503848","rc":[{"atl":[[2.2,11.68]],"id":43167125}],"con":true,"img":false}]}
{"op":"mcm","clk":"5353127554","pt":1646209442486,"mc":[{"id":"1.195503848","rc":[{"atb":[[1.82,9.83],[1.81,11.86]],"id":43167125}],"con":true,"img":false}]}
{"op":"mcm","clk":"5353127827","pt":1646209447578,"mc":[{"id":"1.195503848","rc":[{"atb":[[1.82,11.83],[1.81,9.86]],"id":43167125}],"con":true,"img":false}]}
{"op":"mcm","clk":"5353128964","pt":1646209467736,"mc":[{"id":"1.195503848","rc":[{"atb":[[1.82,9.83],[1.81,11.86]],"id":43167125}],"con":true,"img":false}]}
{"op":"mcm","clk":"5353129698","pt":1646209480842,"mc":[{"id":"1.195503848","rc":[{"atb":[[1.8,11.87],[1.81,9.86]],"id":43167125}],"con":true,"img":false}]}
{"op":"mcm","clk":"5353131115","pt":1646209504945,"mc":[{"id":"1.195503848","rc":[{"atb":[[1.83,1.42]],"id":43167125}],"con":true,"img":false}]}
{"op":"mcm","clk":"5353131308","pt":1646209508267,"mc":[{"id":"1.195503848","rc":[{"atl":[[40,1.42]],"id":43167126}],"con":true,"img":false}]}
{"op":"mcm","clk":"5353131485","pt":1646209510753,"mc":[{"id":"1.195503848","rc":[{"atl":[[42,1.42]],"id":43167126}],"con":true,"img":false}]}
{"op":"mcm","clk":"5353131856","pt":1646209516290,"mc":[{"id":"1.195503848","rc":[{"atl":[[44,1.42]],"id":43167126}],"con":true,"img":false}]}
{"op":"mcm","clk":"5353131928","pt":1646209517280,"mc":[{"id":"1.195503848","rc":[{"atb":[[1.83,11.5]],"id":43167125}],"con":true,"img":false}]}
{"op":"mcm","clk":"5353131941","pt":1646209517490,"mc":[{"id":"1.195503848","rc":[{"atb":[[1.83,1.42]],"id":43167125}],"con":true,"img":false}]}
{"op":"mcm","clk":"5353132037","pt":1646209518998,"mc":[{"id":"1.195503848","rc":[{"atl":[[46,1.42]],"id":43167126}],"con":true,"img":false}]}
{"op":"mcm","clk":"5353132048","pt":1646209519205,"mc":[{"id":"1.195503848","rc":[{"atb":[[1.98,2]],"id":43167126},{"atb":[[1.76,2],[1.8,9.87]],"id":43167125}],"con":true,"img":false}]}
{"op":"mcm","clk":"5353132054","pt":1646209519307,"mc":[{"id":"1.195503848","rc":[{"atb":[[1.92,0]],"id":43167126}],"con":true,"img":false}]}
{"op":"mcm","clk":"5353132201","pt":1646209521794,"mc":[{"id":"1.195503848","rc":[{"atl":[[40,0],[42,0],[44,0],[46,0]],"id":43167126}],"con":true,"img":false}]}
{"op":"mcm","clk":"5353132473","pt":1646209526209,"mc":[{"id":"1.195503848","rc":[{"atl":[[40,1.42]],"id":43167126}],"con":true,"img":false}]}
{"op":"mcm","clk":"5353132488","pt":1646209526417,"mc":[{"id":"1.195503848","rc":[{"atl":[[2.18,2],[2.2,9.68]],"id":43167125}],"con":true,"img":false}]}
{"op":"mcm","clk":"5353132529","pt":1646209527086,"mc":[{"id":"1.195503848","rc":[{"atl":[[2.18,11.96]],"id":43167125}],"con":true,"img":false}]}
{"op":"mcm","clk":"5353132538","pt":1646209527288,"mc":[{"id":"1.195503848","rc":[{"atl":[[2.3,0]],"id":43167125}],"con":true,"img":false}]}
{"op":"mcm","clk":"5353132602","pt":1646209528484,"mc":[{"id":"1.195503848","rc":[{"atl":[[42,1.42]],"id":43167126}],"con":true,"img":false}]}
{"op":"mcm","clk":"5353132693","pt":1646209529825,"mc":[{"id":"1.195503848","rc":[{"atl":[[2.46,26.5]],"id":43167126},{"atb":[[1.83,4.26]],"id":43167125},{"atl":[[2.18,24.98]],"id":43167125}],"con":true,"img":false}]}
{"op":"mcm","clk":"5353132697","pt":1646209529877,"mc":[{"id":"1.195503848","rc":[{"atl":[[44,1.42]],"id":43167126}],"con":true,"img":false}]}
{"op":"mcm","clk":"5353132762","pt":1646209530928,"mc":[{"id":"1.195503848","rc":[{"atb":[[1.98,0],[1.95,2]],"id":43167126}],"con":true,"img":false}]}
{"op":"mcm","clk":"5353132791","pt":1646209531490,"mc":[{"id":"1.195503848","rc":[{"atl":[[2.16,2]],"id":43167125}],"con":true,"img":false}]}
{"op":"mcm","clk":"5353132796","pt":1646209531592,"mc":[{"id":"1.195503848","rc":[{"atl":[[2.18,22.98]],"id":43167125}],"con":true,"img":false}]}
{"op":"mcm","clk":"5353132804","pt":1646209531800,"mc":[{"id":"1.195503848","rc":[{"atl":[[2.18,9.96]],"id":43167125}],"con":true,"img":false}]}
{"op":"mcm","clk":"5353132808","pt":1646209531905,"mc":[{"id":"1.195503848","rc":[{"atb":[[2,19.16]],"id":43167126},{"atb":[[1.83,1.42]],"id":43167125},{"atl":[[2.16,15.02]],"id":43167125}],"con":true,"img":false}]}
{"op":"mcm","clk":"5353132812","pt":1646209532010,"mc":[{"id":"1.195503848","rc":[{"atl":[[2.54,0],[2.44,8.37]],"id":43167126}],"con":true,"img":false}]}
{"op":"mcm","clk":"5353132818","pt":1646209532111,"mc":[{"id":"1.195503848","rc":[{"atl":[[2.42,2],[2.46,24.5]],"id":43167126}],"con":true,"img":false}]}
{"op":"mcm","clk":"5353132822","pt":1646209532213,"mc":[{"id":"1.195503848","rc":[{"atl":[[2.16,6]],"id":43167125}],"con":true,"img":false}]}
{"op":"mcm","clk":"5353132826","pt":1646209532319,"mc":[{"id":"1.195503848","rc":[{"atl":[[2.46,8.62]],"id":43167126}],"con":true,"img":false}]}
{"op":"mcm","clk":"5353132835","pt":1646209532422,"mc":[{"id":"1.195503848","rc":[{"atl":[[2.44,24.25]],"id":43167126}],"con":true,"img":false}]}
{"op":"mcm","clk":"5353132848","pt":1646209532631,"mc":[{"id":"1.195503848","rc":[{"atl":[[40,0],[42,0],[44,0]],"id":43167126}],"con":true,"img":false}]}
{"op":"mcm","clk":"5353132851","pt":1646209532732,"mc":[{"id":"1.195503848","rc":[{"atl":[[2.44,8.37]],"id":43167126}],"con":true,"img":false}]}
{"op":"mcm","clk":"5353132857","pt":1646209532837,"mc":[{"id":"1.195503848","rc":[{"atl":[[2.42,17.88]],"id":43167126}],"con":true,"img":false}]}
{"op":"mcm","clk":"5353132885","pt":1646209533199,"mc":[{"id":"1.195503848","rc":[{"atl":[[2.42,6]],"id":43167126}],"con":true,"img":false}]}
{"op":"mcm","clk":"5353132939","pt":1646209534126,"mc":[{"id":"1.195503848","rc":[{"atb":[[2.02,8.47]],"id":43167126},{"atl":[[2.4,8.37]],"id":43167126},{"atl":[[2.14,9.95]],"id":43167125}],"con":true,"img":false}]}
{"op":"mcm","clk":"5353132953","pt":1646209534335,"mc":[{"id":"1.195503848","rc":[{"atl":[[2.5,0],[2.42,4],[2.38,2]],"id":43167126},{"atl":[[2.28,0]],"id":43167125}],"con":true,"img":false}]}
{"op":"mcm","clk":"5353132962","pt":1646209534389,"mc":[{"id":"1.195503848","rc":[{"atl":[[2.42,0]],"id":43167126},{"atl":[[2.16,2]],"id":43167125}],"con":true,"img":false}]}
{"op":"mcm","clk":"5353132965","pt":1646209534492,"mc":[{"id":"1.195503848","rc":[{"atb":[[2,8.58]],"id":43167126}],"con":true,"img":false}]}
{"op":"mcm","clk":"5353132970","pt":1646209534592,"mc":[{"id":"1.195503848","rc":[{"atb":[[2.02,19.05]],"id":43167126}],"con":true,"img":false}]}
{"op":"mcm","clk":"5353132975","pt":1646209534697,"mc":[{"id":"1.195503848","rc":[{"atl":[[2.38,6]],"id":43167126},{"atl":[[2.14,27.88]],"id":43167125}],"con":true,"img":false}]}
{"op":"mcm","clk":"5353132978","pt":1646209534799,"mc":[{"id":"1.195503848","rc":[{"atb":[[1.96,30.45]],"id":43167126},{"atb":[[1.72,40.59]],"id":43167125}],"con":true,"img":false}]}
{"op":"mcm","clk":"5353133086","pt":1646209536703,"mc":[{"id":"1.195503848","rc":[{"atl":[[2.12,2],[2.16,0]],"id":43167125}],"con":true,"img":false}]}
{"op":"mcm","clk":"5353133100","pt":1646209537012,"mc":[{"id":"1.195503848","rc":[{"atl":[[2.14,9.95]],"id":43167125}],"con":true,"img":false}]}
{"op":"mcm","clk":"5353133106","pt":1646209537115,"mc":[{"id":"1.195503848","rc":[{"atl":[[2.12,19.93]],"id":43167125}],"con":true,"img":false}]}
{"op":"mcm","clk":"5353133118","pt":1646209537328,"mc":[{"id":"1.195503848","rc":[{"atl":[[40,1.42]],"id":43167126}],"con":true,"img":false}]}
{"op":"mcm","clk":"5353133128","pt":1646209537535,"mc":[{"id":"1.195503848","rc":[{"atl":[[2.12,6]],"id":43167125}],"con":true,"img":false}]}
{"op":"mcm","clk":"5353133174","pt":1646209538313,"mc":[{"id":"1.195503848","rc":[{"atl":[[2.1,9.95]],"id":43167125}],"con":true,"img":false}]}
{"op":"mcm","clk":"5353133185","pt":1646209538518,"mc":[{"id":"1.195503848","rc":[{"atb":[[2.04,1.42]],"id":43167126},{"atb":[[1.84,1.42]],"id":43167125},{"atl":[[2.22,0]],"id":43167125}],"con":true,"img":false}]}
{"op":"mcm","clk":"5353133192","pt":1646209538621,"mc":[{"id":"1.195503848","rc":[{"atl":[[2.12,2]],"id":43167125}],"con":true,"img":false}]}
{"op":"mcm","clk":"5353133202","pt":1646209538830,"mc":[{"id":"1.195503848","rc":[{"atb":[[2.02,37.12]],"id":43167126}],"con":true,"img":false}]}
{"op":"mcm","clk":"5353133207","pt":1646209538934,"mc":[{"id":"1.195503848","rc":[{"atb":[[2.04,12]],"id":43167126},{"atl":[[2.1,24.33]],"id":43167125}],"con":true,"img":false}]}
{"op":"mcm","clk":"5353133223","pt":1646209539196,"mc":[{"id":"1.195503848","rc":[{"atb":[[2.04,4.26]],"id":43167126}],"con":true,"img":false}]}
{"op":"mcm","clk":"5353133254","pt":1646209539709,"mc":[{"id":"1.195503848","rc":[{"atl":[[40,0]],"id":43167126}],"con":true,"img":false}]}
{"op":"mcm","clk":"5353133259","pt":1646209539813,"mc":[{"id":"1.195503848","rc":[{"atb":[[2.02,8.47],[1.91,32.12],[1.96,0]],"id":43167126},{"atb":[[1.73,40.04],[1.72,0]],"id":43167125}],"con":true,"img":false}]}
{"op":"mcm","clk":"5353133284","pt":1646209540329,"mc":[{"id":"1.195503848","rc":[{"atb":[[1.73,0]],"id":43167125}],"con":true,"img":false}]}
{"op":"mcm","clk":"5353133341","pt":1646209541315,"mc":[{"id":"1.195503848","rc":[{"atb":[[2.06,8.47]],"id":43167126},{"atl":[[2.36,8.37]],"id":43167126},{"atl":[[2.08,9.95]],"id":43167125}],"con":true,"img":false}]}
{"op":"mcm","clk":"5353133346","pt":1646209541417,"mc":[{"id":"1.195503848","rc":[{"atl":[[2.38,4],[2.34,2]],"id":43167126}],"con":true,"img":false}]}
{"op":"mcm","clk":"5353133350","pt":1646209541531,"mc":[{"id":"1.195503848","rc":[{"atl":[[2.48,0]],"id":43167126},{"atl":[[2.2,0]],"id":43167125}],"con":true,"img":false}]}
{"op":"mcm","clk":"5353133355","pt":1646209541586,"mc":[{"id":"1.195503848","rc":[{"atb":[[2.04,1.42]],"id":43167126},{"atl":[[2.38,0]],"id":43167126},{"atl":[[2.1,9.95]],"id":43167125}],"con":true,"img":false}]}
{"op":"mcm","clk":"5353133367","pt":1646209541796,"mc":[{"id":"1.195503848","rc":[{"atb":[[2.06,17.04]],"id":43167126},{"atl":[[2.12,0],[2.08,26.64],[2.06,2]],"id":43167125}],"con":true,"img":false}]}
{"op":"mcm","clk":"5353133374","pt":1646209541893,"mc":[{"id":"1.195503848","rc":[{"atb":[[1.96,30.45]],"id":43167126},{"atb":[[1.75,38.97]],"id":43167125}],"con":true,"img":false}]}
{"op":"mcm","clk":"5353133379","pt":1646209541995,"mc":[{"id":"1.195503848","rc":[{"atb":[[1.84,0]],"id":43167125}],"con":true,"img":false}]}
{"op":"mcm","clk":"5353133383","pt":1646209542097,"mc":[{"id":"1.195503848","rc":[{"atb":[[1.77,2],[1.76,0]],"id":43167125}],"con":true,"img":false}]}
{"op":"mcm","clk":"5353133387","pt":1646209542201,"mc":[{"id":"1.195503848","rc":[{"atl":[[2.08,9.95]],"id":43167125}],"con":true,"img":false}]}
{"op":"mcm","clk":"5353133392","pt":1646209542304,"mc":[{"id":"1.195503848","rc":[{"atl":[[2.06,18.69]],"id":43167125}],"con":true,"img":false}]}
{"op":"mcm","clk":"5353133395","pt":1646209542407,"mc":[{"id":"1.195503848","rc":[{"atb":[[1.75,0]],"id":43167125}],"con":true,"img":false}]}
{"op":"mcm","clk":"5353133404","pt":1646209542614,"mc":[{"id":"1.195503848","rc":[{"atl":[[2.06,6]],"id":43167125}],"con":true,"img":false}]}
{"op":"mcm","clk":"5353133407","pt":1646209542718,"mc":[{"id":"1.195503848","rc":[{"atb":[[2.08,8.47]],"id":43167126},{"atl":[[2.46,0],[2.34,10.37]],"id":43167126},{"atl":[[2.04,9.95]],"id":43167125}],"con":true,"img":false}]}
{"op":"mcm","clk":"5353133411","pt":1646209542822,"mc":[{"id":"1.195503848","rc":[{"atb":[[2.02,37.12]],"id":43167126},{"atb":[[1.74,39.5]],"id":43167125},{"atl":[[2.18,0]],"id":43167125}],"con":true,"img":false}]}
{"op":"mcm","clk":"5353133420","pt":1646209543027,"mc":[{"id":"1.195503848","rc":[{"atb":[[2.06,8.47]],"id":43167126},{"atl":[[2.06,2]],"id":43167125}],"con":true,"img":false}]}
{"op":"mcm","clk":"5353133425","pt":1646209543130,"mc":[{"id":"1.195503848","rc":[{"atb":[[2.08,17.04]],"id":43167126}],"con":true,"img":false}]}
{"op":"mcm","clk":"5353133433","pt":1646209543335,"mc":[{"id":"1.195503848","rc":[{"atl":[[2.04,24.63]],"id":43167125}],"con":true,"img":false}]}
{"op":"mcm","clk":"5353133440","pt":1646209543439,"mc":[{"id":"1.195503848","rc":[{"atb":[[2.08,8.47]],"id":43167126}],"con":true,"img":false}]}
{"op":"mcm","clk":"5353133446","pt":1646209543496,"mc":[{"id":"1.195503848","rc":[{"atb":[[2.06,17.04]],"id":43167126}],"con":true,"img":false}]}
{"op":"mcm","clk":"5353133468","pt":1646209543904,"mc":[{"id":"1.195503848","rc":[{"atb":[[2.06,8.47]],"id":43167126}],"con":true,"img":false}]}
{"op":"mcm","clk":"5353133475","pt":1646209544010,"mc":[{"id":"1.195503848","rc":[{"atb":[[2.08,17.04]],"id":43167126}],"con":true,"img":false}]}
{"op":"mcm","clk":"5353133617","pt":1646209546338,"mc":[{"id":"1.195503848","rc":[{"atb":[[1.99,1.42]],"id":43167126},{"atl":[[44,1.42]],"id":43167126},{"atl":[[1.92,1.42]],"id":43167125}],"con":true,"img":false}]}
{"op":"mcm","clk":"5353133654","pt":1646209546904,"mc":[{"id":"1.195503848","rc":[{"atb":[[1.91,0]],"id":43167126}],"con":true,"img":false}]}
{"op":"mcm","clk":"5353133701","pt":1646209547828,"mc":[{"id":"1.195503848","rc":[{"atb":[[1.99,2.84]],"id":43167126},{"atl":[[1.92,12.8]],"id":43167125}],"con":true,"img":false}]}
{"op":"mcm","clk":"5353133713","pt":1646209548033,"mc":[{"id":"1.195503848","rc":[{"atl":[[2.14,0]],"id":43167125}],"con":true,"img":false}]}
{"op":"mcm","clk":"5353133728","pt":1646209548341,"mc":[{"id":"1.195503848","rc":[{"atb":[[2.1,26.57]],"id":43167126}],"con":true,"img":false}]}
{"op":"mcm","clk":"5353133742","pt":1646209548598,"mc":[{"id":"1.195503848","rc":[{"atb":[[2.08,8.47]],"id":43167126}],"con":true,"img":false}]}
{"op":"mcm","clk":"5353133749","pt":1646209548701,"mc":[{"id":"1.195503848","rc":[{"atb":[[2.1,35.14]],"id":43167126}],"con":true,"img":false}]}
{"op":"mcm","clk":"5353133758","pt":1646209548908,"mc":[{"id":"1.195503848","rc":[{"atl":[[44,0]],"id":43167126}],"con":true,"img":false}]}
{"op":"mcm","clk":"5353133897","pt":1646209551225,"mc":[{"id":"1.195503848","rc":[{"atb":[[1.98,1.42]],"id":43167126},{"atl":[[2.34,15.66]],"id":43167126},{"atl":[[1.94,1.42]],"id":43167125}],"con":true,"img":false}]}
{"op":"mcm","clk":"5353133979","pt":1646209552823,"mc":[{"id":"1.195503848","rc":[{"atb":[[1.97,1.42]],"id":43167126}],"con":true,"img":false}]}
{"op":"mcm","clk":"5353133991","pt":1646209553028,"mc":[{"id":"1.195503848","rc":[{"atl":[[2.34,10.37]],"id":43167126}],"con":true,"img":false}]}
{"op":"mcm","clk":"5353134000","pt":1646209553339,"mc":[{"id":"1.195503848","rc":[{"atl":[[2.04,9.95]],"id":43167125}],"con":true,"img":false}]}
{"op":"mcm","clk":"5353134005","pt":1646209553442,"mc":[{"id":"1.195503848","rc":[{"atl":[[1.92,27.48]],"id":43167125}],"con":true,"img":false}]}
{"op":"mcm","clk":"5353134079","pt":1646209554729,"mc":[{"id":"1.195503848","rc":[{"atb":[[2.1,26.57]],"id":43167126},{"atl":[[1.92,12.8]],"id":43167125}],"con":true,"img":false}]}
{"op":"mcm","clk":"5353134109","pt":1646209555345,"mc":[{"id":"1.195503848","rc":[{"atb":[[2.1,0],[2.08,35.54]],"id":43167126}],"con":true,"img":false}]}
{"op":"mcm","clk":"5353134114","pt":1646209555448,"mc":[{"id":"1.195503848","rc":[{"atl":[[1.98,1.42]],"id":43167125}],"con":true,"img":false}]}
{"op":"mcm","clk":"5353134120","pt":1646209555552,"mc":[{"id":"1.195503848","rc":[{"atb":[[2.1,8.46]],"id":43167126},{"atl":[[1.92,22.84]],"id":43167125}],"con":true,"img":false}]}
{"op":"mcm","clk":"5353134139","pt":1646209555810,"mc":[{"id":"1.195503848","rc":[{"atb":[[2.1,0]],"id":43167126}],"con":true,"img":false}]}
{"op":"mcm","clk":"5353134148","pt":1646209556122,"mc":[{"id":"1.195503848","rc":[{"atb":[[2.08,45.2]],"id":43167126}],"con":true,"img":false}]}
{"op":"mcm","clk":"5353134178","pt":1646209556739,"mc":[{"id":"1.195503848","rc":[{"atl":[[1.98,2.84]],"id":43167125}],"con":true,"img":false}]}
{"op":"mcm","clk":"5353134320","pt":1646209559741,"mc":[{"id":"1.195503848","rc":[{"atl":[[1.94,0]],"id":43167125}],"con":true,"img":false}]}
{"op":"mcm","clk":"5353134467","pt":1646209562333,"mc":[{"id":"1.195503848","rc":[{"atb":[[2.08,35.54]],"id":43167126},{"atl":[[1.92,12.8]],"id":43167125}],"con":true,"img":false}]}
{"op":"mcm","clk":"5353134486","pt":1646209562648,"mc":[{"id":"1.195503848","rc":[{"atb":[[2.08,43.28]],"id":43167126},{"atl":[[1.92,20.76]],"id":43167125}],"con":true,"img":false}]}
{"op":"mcm","clk":"5353134719","pt":1646209567045,"mc":[{"id":"1.195503848","rc":[{"atl":[[1.92,10.8]],"id":43167125}],"con":true,"img":false}]}
{"op":"mcm","clk":"5353134814","pt":1646209568546,"mc":[{"id":"1.195503848","rc":[{"atl":[[1.92,20.78]],"id":43167125}],"con":true,"img":false}]}
{"op":"mcm","clk":"5353134821","pt":1646209568654,"mc":[{"id":"1.195503848","rc":[{"atb":[[2.08,35.54]],"id":43167126},{"atl":[[2.34,17.56]],"id":43167126},{"atl":[[1.92,12.82]],"id":43167125}],"con":true,"img":false}]}
{"op":"mcm","clk":"5353135018","pt":1646209572053,"mc":[{"id":"1.195503848","rc":[{"atl":[[2.32,8.38]],"id":43167126}],"con":true,"img":false}]}
{"op":"mcm","clk":"5353135024","pt":1646209572154,"mc":[{"id":"1.195503848","rc":[{"atl":[[2.3,2],[2.44,0],[2.34,15.56]],"id":43167126}],"con":true,"img":false}]}
{"op":"mcm","clk":"5353135034","pt":1646209572360,"mc":[{"id":"1.195503848","rc":[{"atl":[[2.34,8.37]],"id":43167126},{"atb":[[1.76,38.46]],"id":43167125}],"con":true,"img":false}]}
{"op":"mcm","clk":"5353135040","pt":1646209572461,"mc":[{"id":"1.195503848","rc":[{"atl":[[2.32,15.57]],"id":43167126}],"con":true,"img":false}]}
{"op":"mcm","clk":"5353135057","pt":1646209572774,"mc":[{"id":"1.195503848","rc":[{"atl":[[2.32,8.38]],"id":43167126}],"con":true,"img":false}]}
{"op":"mcm","clk":"5353135064","pt":1646209572874,"mc":[{"id":"1.195503848","rc":[{"atl":[[2.3,9.19]],"id":43167126}],"con":true,"img":false}]}
{"op":"mcm","clk":"5353135093","pt":1646209573443,"mc":[{"id":"1.195503848","rc":[{"atl":[[2.28,8.39]],"id":43167126}],"con":true,"img":false}]}
{"op":"mcm","clk":"5353135105","pt":1646209573651,"mc":[{"id":"1.195503848","rc":[{"atl":[[2.4,0]],"id":43167126}],"con":true,"img":false}]}
{"op":"mcm","clk":"5353135178","pt":1646209574738,"mc":[{"id":"1.195503848","rc":[{"atl":[[2.2,1.42]],"id":43167126},{"atb":[[1.79,1.42]],"id":43167125}],"con":true,"img":false}]}
{"op":"mcm","clk":"5353135212","pt":1646209575352,"mc":[{"id":"1.195503848","rc":[{"atb":[[1.79,38.42]],"id":43167125}],"con":true,"img":false}]}
{"op":"mcm","clk":"5353135219","pt":1646209575559,"mc":[{"id":"1.195503848","rc":[{"atb":[[2.08,43.3]],"id":43167126},{"atl":[[1.92,20.81]],"id":43167125}],"con":true,"img":false}]}
{"op":"mcm","clk":"5353135244","pt":1646209576075,"mc":[{"id":"1.195503848","rc":[{"atl":[[2.2,2.84]],"id":43167126},{"atb":[[1.79,39.84]],"id":43167125}],"con":true,"img":false}]}
{"op":"mcm","clk":"5353135285","pt":1646209576743,"mc":[{"id":"1.195503848","rc":[{"atl":[[1.92,10.83]],"id":43167125}],"con":true,"img":false}]}
{"op":"mcm","clk":"5353135301","pt":1646209577052,"mc":[{"id":"1.195503848","rc":[{"atl":[[1.92,20.77]],"id":43167125}],"con":true,"img":false}]}
{"op":"mcm","clk":"5353135312","pt":1646209577261,"mc":[{"id":"1.195503848","rc":[{"atl":[[2.3,7.19],[2.26,2]],"id":43167126}],"con":true,"img":false}]}
{"op":"mcm","clk":"5353135566","pt":1646209582260,"mc":[{"id":"1.195503848","rc":[{"atb":[[1.82,0]],"id":43167125},{"atl":[[1.92,10.83]],"id":43167125}],"con":true,"img":false}]}
{"op":"mcm","clk":"5353135579","pt":1646209582567,"mc":[{"id":"1.195503848","rc":[{"atl":[[1.97,9.92]],"id":43167125}],"con":true,"img":false}]}
{"op":"mcm","clk":"5353135668","pt":1646209584372,"mc":[{"id":"1.195503848","rc":[{"atl":[[2.38,1.42]],"id":43167126},{"atb":[[1.82,1.42]],"id":43167125}],"con":true,"img":false}]}
{"op":"mcm","clk":"5353135907","pt":1646209589165,"mc":[{"id":"1.195503848","rc":[{"atl":[[2.26,10.32]],"id":43167126},{"atl":[[1.92,20.77]],"id":43167125}],"con":true,"img":false}]}
{"op":"mcm","clk":"5353135912","pt":1646209589273,"mc":[{"id":"1.195503848","rc":[{"atl":[[2.36,0]],"id":43167126},{"atl":[[2.1,0]],"id":43167125}],"con":true,"img":false}]}
{"op":"mcm","clk":"5353135941","pt":1646209589885,"mc":[{"id":"1.195503848","rc":[{"atb":[[1.78,2],[1.77,0],[1.82,11.55]],"id":43167125}],"con":true,"img":false}]}
{"op":"mcm","clk":"5353135964","pt":1646209590399,"mc":[{"id":"1.195503848","rc":[{"atb":[[1.74,0]],"id":43167125}],"con":true,"img":false}]}
{"op":"mcm","clk":"5353136053","pt":1646209592160,"mc":[{"id":"1.195503848","rc":[{"atl":[[2.36,1.42]],"id":43167126},{"atb":[[1.77,1.42]],"id":43167125}],"con":true,"img":false}]}
{"op":"mcm","clk":"5353136539","pt":1646209600666,"mc":[{"id":"1.195503848","rc":[{"atb":[[2.08,34.82]],"id":43167126},{"atl":[[2.2,11.29]],"id":43167126},{"atb":[[1.83,11.38]],"id":43167125},{"atl":[[1.92,10.83]],"id":43167125}],"con":true,"img":false}]}
{"op":"mcm","clk":"5353136548","pt":1646209600874,"mc":[{"id":"1.195503848","rc":[{"atb":[[2.04,29.52],[2.08,7.76]],"id":43167126},{"atl":[[2.34,0]],"id":43167126},{"atb":[[1.83,46.6]],"id":43167125}],"con":true,"img":false}]}
{"op":"mcm","clk":"5353136566","pt":1646209601182,"mc":[{"id":"1.195503848","rc":[{"atb":[[2.08,0]],"id":43167126}],"con":true,"img":false}]}
{"op":"mcm","clk":"5353136587","pt":1646209601497,"mc":[{"id":"1.195503848","rc":[{"atb":[[2.06,18.36]],"id":43167126}],"con":true,"img":false}]}
{"op":"mcm","clk":"5353136610","pt":1646209601905,"mc":[{"id":"1.195503848","rc":[{"atb":[[1.96,0]],"id":43167126}],"con":true,"img":false}]}
{"op":"mcm","clk":"5353136627","pt":1646209602169,"mc":[{"id":"1.195503848","rc":[{"atl":[[2.34,1.42]],"id":43167126}],"con":true,"img":false}]}
{"op":"mcm","clk":"5353136704","pt":1646209603810,"mc":[{"id":"1.195503848","rc":[{"atl":[[1.93,1.42]],"id":43167125}],"con":true,"img":false}]}
{"op":"mcm","clk":"5353136743","pt":1646209604379,"mc":[{"id":"1.195503848","rc":[{"atb":[[2.06,45.94]],"id":43167126},{"atl":[[1.98,0]],"id":43167125}],"con":true,"img":false}]}
{"op":"mcm","clk":"5353136796","pt":1646209605307,"mc":[{"id":"1.195503848","rc":[{"atl":[[1.94,1.42]],"id":43167125}],"con":true,"img":false}]}
{"op":"mcm","clk":"5353136845","pt":1646209606186,"mc":[{"id":"1.195503848","rc":[{"atl":[[1.93,11.29]],"id":43167125}],"con":true,"img":false}]}
{"op":"mcm","clk":"5353136932","pt":1646209607784,"mc":[{"id":"1.195503848","rc":[{"atb":[[2.08,8.45]],"id":43167126},{"atl":[[2.2,2.84]],"id":43167126},{"atb":[[1.83,36.64]],"id":43167125},{"atl":[[2.08,0],[1.91,10.04]],"id":43167125}],"con":true,"img":false}]}
{"op":"mcm","clk":"5353136956","pt":1646209608198,"mc":[{"id":"1.195503848","rc":[{"atb":[[2.06,36.05]],"id":43167126},{"atl":[[1.92,2.84]],"id":43167125}],"con":true,"img":false}]}
{"op":"mcm","clk":"5353136961","pt":1646209608302,"mc":[{"id":"1.195503848","rc":[{"atb":[[2.08,18.34]],"id":43167126},{"atl":[[1.96,1.42]],"id":43167125}],"con":true,"img":false}]}
{"op":"mcm","clk":"5353136964","pt":1646209608405,"mc":[{"id":"1.195503848","rc":[{"atb":[[1.81,45.95],[1.83,1.42]],"id":43167125}],"con":true,"img":false}]}
{"op":"mcm","clk":"5353136971","pt":1646209608508,"mc":[{"id":"1.195503848","rc":[{"atl":[[1.91,18.33]],"id":43167125}],"con":true,"img":false}]}
{"op":"mcm","clk":"5353136999","pt":1646209608876,"mc":[{"id":"1.195503848","rc":[{"atb":[[2.02,8.47]],"id":43167126}],"con":true,"img":false}]}
{"op":"mcm","clk":"5353137034","pt":1646209609491,"mc":[{"id":"1.195503848","rc":[{"atl":[[1.96,2.84]],"id":43167125}],"con":true,"img":false}]}
{"op":"mcm","clk":"5353137040","pt":1646209609595,"mc":[{"id":"1.195503848","rc":[{"atb":[[1.82,1.42]],"id":43167125}],"con":true,"img":false}]}
{"op":"mcm","clk":"5353137063","pt":1646209609904,"mc":[{"id":"1.195503848","rc":[{"atb":[[2.08,45.41]],"id":43167126},{"atb":[[1.81,9.86]],"id":43167125}],"con":true,"img":false}]}
{"op":"mcm","clk":"5353137106","pt":1646209610482,"mc":[{"id":"1.195503848","rc":[{"atb":[[2.1,8.44]],"id":43167126}],"con":true,"img":false}]}
{"op":"mcm","clk":"5353137109","pt":1646209610582,"mc":[{"id":"1.195503848","rc":[{"atb":[[2,0]],"id":43167126}],"con":true,"img":false}]}
{"op":"mcm","clk":"5353137120","pt":1646209610790,"mc":[{"id":"1.195503848","rc":[{"atb":[[2.08,35.52]],"id":43167126}],"con":true,"img":false}]}
{"op":"mcm","clk":"5353137127","pt":1646209610890,"mc":[{"id":"1.195503848","rc":[{"atb":[[2.1,18.33]],"id":43167126}],"con":true,"img":false}]}
{"op":"mcm","clk":"5353137163","pt":1646209611615,"mc":[{"id":"1.195503848","rc":[{"atb":[[1.78,0],[1.77,3.42]],"id":43167125}],"con":true,"img":false}]}
{"op":"mcm","clk":"5353137171","pt":1646209611715,"mc":[{"id":"1.195503848","rc":[{"atb":[[2,1.42]],"id":43167126},{"atl":[[1.98,1.42]],"id":43167125}],"con":true,"img":false}]}
{"op":"mcm","clk":"5353137184","pt":1646209611978,"mc":[{"id":"1.195503848","rc":[{"atl":[[2.34,0]],"id":43167126}],"con":true,"img":false}]}
{"op":"mcm","clk":"5353137298","pt":1646209614298,"mc":[{"id":"1.195503848","rc":[{"atl":[[2.36,0],[2.38,0]],"id":43167126}],"con":true,"img":false}]}
{"op":"mcm","clk":"5353137314","pt":1646209614605,"mc":[{"id":"1.195503848","rc":[{"atl":[[2.2,0]],"id":43167126},{"trd":[[2.2,2.84]],"ltp":2.2,"tv":2.84,"id":43167126},{"atb":[[1.81,6.14],[1.83,0],[1.82,0]],"id":43167125},{"trd":[[1.81,7.45],[1.82,2.84],[1.83,6.27]],"ltp":1.81,"tv":16.56,"id":43167125}],"con":true,"img":false}]}
{"op":"mcm","clk":"5353137320","pt":1646209614705,"mc":[{"id":"1.195503848","rc":[{"atb":[[2.12,8.43]],"id":43167126},{"atl":[[1.9,10.05]],"id":43167125}],"con":true,"img":false}]}
{"op":"mcm","clk":"5353137326","pt":1646209614811,"mc":[{"id":"1.195503848","rc":[{"atb":[[1.81,0]],"id":43167125}],"con":true,"img":false}]}
{"op":"mcm","clk":"5353137332","pt":1646209614913,"mc":[{"id":"1.195503848","rc":[{"atb":[[2.04,1.42]],"id":43167126}],"con":true,"img":false}]}
{"op":"mcm","clk":"5353137338","pt":1646209615016,"mc":[{"id":"1.195503848","rc":[{"atb":[[2.1,8.44]],"id":43167126},{"atl":[[1.91,10.04]],"id":43167125}],"con":true,"img":false}]}
{"op":"mcm","clk":"5353137347","pt":1646209615119,"mc":[{"id":"1.195503848","rc":[{"atb":[[2.12,18.32]],"id":43167126},{"atl":[[1.9,18.34]],"id":43167125}],"con":true,"img":false}]}
{"op":"mcm","clk":"5353137365","pt":1646209615429,"mc":[{"id":"1.195503848","rc":[{"atb":[[2.12,8.43]],"id":43167126},{"atb":[[1.79,2.84]],"id":43167125},{"atl":[[1.9,13.57]],"id":43167125}],"con":true,"img":false}]}
{"op":"mcm","clk":"5353137375","pt":1646209615486,"mc":[{"id":"1.195503848","rc":[{"atb":[[2.1,18.33]],"id":43167126}],"con":true,"img":false}]}
{"op":"mcm","clk":"5353137386","pt":1646209615694,"mc":[{"id":"1.195503848","rc":[{"atb":[[2.1,8.44]],"id":43167126},{"atb":[[1.76,40.46],[1.77,1.42]],"id":43167125}],"con":true,"img":false}]}
{"op":"mcm","clk":"5353137392","pt":1646209615794,"mc":[{"id":"1.195503848","rc":[{"atb":[[2.12,18.32]],"id":43167126},{"atl":[[2.28,10.39],[2.26,8.32]],"id":43167126}],"con":true,"img":false}]}
{"op":"mcm","clk":"5353137398","pt":1646209615900,"mc":[{"id":"1.195503848","rc":[{"atb":[[2.12,44.42]],"id":43167126},{"atb":[[1.78,37.47]],"id":43167125}],"con":true,"img":false}]}
{"op":"mcm","clk":"5353137458","pt":1646209616922,"mc":[{"id":"1.195503848","rc":[{"atb":[[2.14,8.41]],"id":43167126},{"atb":[[1.77,0],[1.79,0]],"id":43167125},{"atl":[[1.89,10.08]],"id":43167125}],"con":true,"img":false}]}
{"op":"mcm","clk":"5353137471","pt":1646209617230,"mc":[{"id":"1.195503848","rc":[{"atl":[[1.9,10.05]],"id":43167125}],"con":true,"img":false}]}
{"op":"mcm","clk":"5353137480","pt":1646209617390,"mc":[{"id":"1.195503848","rc":[{"atb":[[1.78,0]],"id":43167125}],"con":true,"img":false}]}
{"op":"mcm","clk":"5353137484","pt":1646209617498,"mc":[{"id":"1.195503848","rc":[{"atl":[[1.89,16.96]],"id":43167125}],"con":true,"img":false}]}
{"op":"mcm","clk":"5353137496","pt":1646209617801,"mc":[{"id":"1.195503848","rc":[{"atl":[[1.88,10.09],[1.89,18.39]],"id":43167125}],"con":true,"img":false}]}
{"op":"mcm","clk":"5353137969","pt":1646209626622,"mc":[{"id":"1.195503848","rc":[{"atb":[[1.8,7.87]],"id":43167125},{"trd":[[1.8,3.99]],"ltp":1.8,"tv":3.99,"id":43167125}],"con":true,"img":false}]}
{"op":"mcm","clk":"5353137972","pt":1646209626722,"mc":[{"id":"1.195503848","rc":[{"atb":[[1.8,0]],"id":43167125},{"trd":[[1.8,19.75]],"ltp":1.8,"tv":19.75,"id":43167125}],"con":true,"img":false}]}
{"op":"mcm","clk":"5353138006","pt":1646209627545,"mc":[{"id":"1.195503848","rc":[{"atb":[[1.77,10.23]],"id":43167125}],"con":true,"img":false}]}
{"op":"mcm","clk":"5353138012","pt":1646209627646,"mc":[{"id":"1.195503848","rc":[{"atl":[[2.3,9.19],[2.28,8.39]],"id":43167126},{"atb":[[1.76,38.46]],"id":43167125}],"con":true,"img":false}]}
{"op":"mcm","clk":"5353138018","pt":1646209627702,"mc":[{"id":"1.195503848","rc":[{"atb":[[1.74,2]],"id":43167125}],"con":true,"img":false}]}
{"op":"mcm","clk":"5353138151","pt":1646209629719,"mc":[{"id":"1.195503848","rc":[{"atb":[[1.75,2]],"id":43167125}],"con":true,"img":false}]}
{"op":"mcm","clk":"5353138155","pt":1646209629824,"mc":[{"id":"1.195503848","rc":[{"atb":[[1.74,0]],"id":43167125}],"con":true,"img":false}]}
{"op":"mcm","clk":"5353138321","pt":1646209632748,"mc":[{"id":"1.195503848","rc":[{"atl":[[1.87,1.42]],"id":43167125}],"con":true,"img":false}]}
{"op":"mcm","clk":"5353138822","pt":1646209641523,"mc":[{"id":"1.195503848","rc":[{"atl":[[1.87,11.48]],"id":43167125}],"con":true,"img":false}]}
{"op":"mcm","clk":"5353138981","pt":1646209643325,"mc":[{"id":"1.195503848","rc":[{"atl":[[1.87,1.42]],"id":43167125}],"con":true,"img":false}]}
{"op":"mcm","clk":"5353139011","pt":1646209643743,"mc":[{"id":"1.195503848","rc":[{"atl":[[2.3,7.19],[2.28,10.39]],"id":43167126}],"con":true,"img":false}]}
{"op":"mcm","clk":"5353139139","pt":1646209645452,"mc":[{"id":"1.195503848","rc":[{"atb":[[1.76,40.46],[1.75,0]],"id":43167125}],"con":true,"img":false}]}
{"op":"mcm","clk":"5353139240","pt":1646209647252,"mc":[{"id":"1.195503848","rc":[{"atl":[[1.87,11.73]],"id":43167125}],"con":true,"img":false}]}
{"op":"mcm","clk":"5353139244","pt":1646209647345,"mc":[{"id":"1.195503848","rc":[{"atl":[[1.87,22.04]],"id":43167125}],"con":true,"img":false}]}
{"op":"mcm","clk":"5353139247","pt":1646209647458,"mc":[{"id":"1.195503848","rc":[{"atl":[[2.04,0]],"id":43167125}],"con":true,"img":false}]}
{"op":"mcm","clk":"5353139272","pt":1646209647961,"mc":[{"id":"1.195503848","rc":[{"atb":[[2.06,8.47]],"id":43167126}],"con":true,"img":false}]}
{"op":"mcm","clk":"5353139303","pt":1646209648646,"mc":[{"id":"1.195503848","rc":[{"atl":[[1.87,11.73]],"id":43167125}],"con":true,"img":false}]}
{"op":"mcm","clk":"5353139312","pt":1646209648842,"mc":[{"id":"1.195503848","rc":[{"atl":[[2.3,9.19],[2.28,8.39]],"id":43167126}],"con":true,"img":false}]}
{"op":"mcm","clk":"5353139358","pt":1646209649869,"mc":[{"id":"1.195503848","rc":[{"atl":[[2.3,2]],"id":43167126},{"atb":[[1.77,20.85]],"id":43167125}],"con":true,"img":false}]}
{"op":"mcm","clk":"5353139360","pt":1646209649971,"mc":[{"id":"1.195503848","rc":[{"atl":[[2.26,15.51]],"id":43167126}],"con":true,"img":false}]}
{"op":"mcm","clk":"5353139373","pt":1646209650228,"mc":[{"id":"1.195503848","rc":[{"atl":[[2.24,8.26]],"id":43167126},{"atb":[[1.78,10.21]],"id":43167125}],"con":true,"img":false}]}
{"op":"mcm","clk":"5353139385","pt":1646209650437,"mc":[{"id":"1.195503848","rc":[{"atb":[[1.79,36.99]],"id":43167125}],"con":true,"img":false}]}
{"op":"mcm","clk":"5353139389","pt":1646209650545,"mc":[{"id":"1.195503848","rc":[{"atl":[[2.26,8.32]],"id":43167126},{"atb":[[1.77,10.23]],"id":43167125}],"con":true,"img":false}]}
{"op":"mcm","clk":"5353139396","pt":1646209650645,"mc":[{"id":"1.195503848","rc":[{"atl":[[2.24,15.45]],"id":43167126},{"atb":[[1.78,20.83],[1.76,38.46],[1.75,2]],"id":43167125}],"con":true,"img":false}]}
{"op":"mcm","clk":"5353139413","pt":1646209650958,"mc":[{"id":"1.195503848","rc":[{"atl":[[2.24,7.19]],"id":43167126},{"atb":[[1.78,10.21],[1.8,10.25]],"id":43167125}],"con":true,"img":false}]}
{"op":"mcm","clk":"5353139418","pt":1646209651059,"mc":[{"id":"1.195503848","rc":[{"atb":[[1.79,47.61]],"id":43167125}],"con":true,"img":false}]}
{"op":"mcm","clk":"5353139429","pt":1646209651261,"mc":[{"id":"1.195503848","rc":[{"atl":[[2.24,0]],"id":43167126}],"con":true,"img":false}]}
{"op":"mcm","clk":"5353139436","pt":1646209651364,"mc":[{"id":"1.195503848","rc":[{"atl":[[2.26,15.51]],"id":43167126},{"atb":[[1.79,36.99]],"id":43167125}],"con":true,"img":false}]}
{"op":"mcm","clk":"5353139441","pt":1646209651467,"mc":[{"id":"1.195503848","rc":[{"atb":[[1.8,20.87]],"id":43167125}],"con":true,"img":false}]}
{"op":"mcm","clk":"5353139500","pt":1646209652451,"mc":[{"id":"1.195503848","rc":[{"atb":[[1.04,1.45]],"id":43167126}],"con":true,"img":false}]}
{"op":"mcm","clk":"5353139510","pt":1646209652654,"mc":[{"id":"1.195503848","rc":[{"atb":[[1.04,0.06]],"id":43167126}],"con":true,"img":false}]}
{"op":"mcm","clk":"5353139515","pt":1646209652759,"mc":[{"id":"1.195503848","rc":[{"atb":[[1.04,0]],"id":43167126}],"con":true,"img":false}]}
{"op":"mcm","clk":"5353139518","pt":1646209652861,"mc":[{"id":"1.195503848","rc":[{"atl":[[2.26,15.44]],"id":43167126},{"trd":[[2.26,0.13]],"ltp":2.26,"tv":0.13,"id":43167126}],"con":true,"img":false}]}
{"op":"mcm","clk":"5353139563","pt":1646209653535,"mc":[{"id":"1.195503848","rc":[{"atl":[[2.36,1.42]],"id":43167126}],"con":true,"img":false}]}
{"op":"mcm","clk":"5353139567","pt":1646209653636,"mc":[{"id":"1.195503848","rc":[{"atl":[[2.24,8.38]],"id":43167126},{"atb":[[1.81,10.08]],"id":43167125}],"con":true,"img":false}]}
{"op":"mcm","clk":"5353139576","pt":1646209653844,"mc":[{"id":"1.195503848","rc":[{"atl":[[1.87,1.42]],"id":43167125}],"con":true,"img":false}]}
{"op":"mcm","clk":"5353139582","pt":1646209653950,"mc":[{"id":"1.195503848","rc":[{"atb":[[2.12,18.32]],"id":43167126}],"con":true,"img":false}]}
{"op":"mcm","clk":"5353139592","pt":1646209654180,"mc":[{"id":"1.195503848","rc":[{"atl":[[1.83,2]],"id":43167125}],"con":true,"img":false}]}
{"op":"mcm","clk":"5353139600","pt":1646209654339,"mc":[{"id":"1.195503848","rc":[{"atb":[[2.1,35.02]],"id":43167126},{"atb":[[1.79,0]],"id":43167125},{"atl":[[1.83,0.01]],"id":43167125},{"trd":[[1.83,10.26]],"ltp":1.83,"tv":10.26,"id":43167125}],"con":true,"img":false}]}
{"op":"mcm","clk":"5353139652","pt":1646209655160,"mc":[{"id":"1.195503848","rc":[{"atl":[[2.36,2.84]],"id":43167126}],"con":true,"img":false}]}
{"op":"mcm","clk":"5353139692","pt":1646209655774,"mc":[{"id":"1.195503848","rc":[{"atl":[[1.87,11.53]],"id":43167125}],"con":true,"img":false}]}
{"op":"mcm","clk":"5353139709","pt":1646209656036,"mc":[{"id":"1.195503848","rc":[{"atl":[[2.36,1.42]],"id":43167126}],"con":true,"img":false}]}
{"op":"mcm","clk":"5353139729","pt":1646209656345,"mc":[{"id":"1.195503848","rc":[{"atb":[[1.79,36.99]],"id":43167125}],"con":true,"img":false}]}
{"op":"mcm","clk":"5353139783","pt":1646209657272,"mc":[{"id":"1.195503848","rc":[{"atl":[[1.83,0]],"id":43167125}],"con":true,"img":false}]}
{"op":"mcm","clk":"5353139898","pt":1646209659441,"mc":[{"id":"1.195503848","rc":[{"atl":[[2.24,0]],"id":43167126},{"atb":[[1.81,0],[1.8,10.62]],"id":43167125}],"con":true,"img":false}]}
{"op":"mcm","clk":"5353139914","pt":1646209659751,"mc":[{"id":"1.195503848","rc":[{"atl":[[2.26,8.25]],"id":43167126},{"atb":[[1.8,0]],"id":43167125}],"con":true,"img":false}]}
{"op":"mcm","clk":"5353139929","pt":1646209659956,"mc":[{"id":"1.195503848","rc":[{"atb":[[2.12,44.42]],"id":43167126}],"con":true,"img":false}]}
{"op":"mcm","clk":"5353139942","pt":1646209660161,"mc":[{"id":"1.195503848","rc":[{"atl":[[2.38,1.42]],"id":43167126}],"con":true,"img":false}]}
{"op":"mcm","clk":"5353139954","pt":1646209660366,"mc":[{"id":"1.195503848","rc":[{"atb":[[1.79,0]],"id":43167125}],"con":true,"img":false}]}
{"op":"mcm","clk":"5353139992","pt":1646209660884,"mc":[{"id":"1.195503848","rc":[{"atb":[[1.78,47.69]],"id":43167125}],"con":true,"img":false}]}
{"op":"mcm","clk":"5353140023","pt":1646209661454,"mc":[{"id":"1.195503848","rc":[{"atl":[[2.38,2.84]],"id":43167126}],"con":true,"img":false}]}
{"op":"mcm","clk":"5353140029","pt":1646209661558,"mc":[{"id":"1.195503848","rc":[{"atb":[[1.79,10.35]],"id":43167125}],"con":true,"img":false}]}
{"op":"mcm","clk":"5353140054","pt":1646209661978,"mc":[{"id":"1.195503848","rc":[{"atl":[[2.26,0]],"id":43167126}],"con":true,"img":false}]}
{"op":"mcm","clk":"5353140074","pt":1646209662286,"mc":[{"id":"1.195503848","rc":[{"atl":[[2.36,0],[2.38,1.42]],"id":43167126}],"con":true,"img":false}]}
{"op":"mcm","clk":"5353140096","pt":1646209662746,"mc":[{"id":"1.195503848","rc":[{"atb":[[1.74,2],[1.75,0]],"id":43167125}],"con":true,"img":false}]}
{"op":"mcm","clk":"5353140153","pt":1646209663878,"mc":[{"id":"1.195503848","rc":[{"atb":[[1.79,0]],"id":43167125}],"con":true,"img":false}]}
{"op":"mcm","clk":"5353140180","pt":1646209664244,"mc":[{"id":"1.195503848","rc":[{"atl":[[2.38,0]],"id":43167126}],"con":true,"img":false}]}
{"op":"mcm","clk":"5353140190","pt":1646209664447,"mc":[{"id":"1.195503848","rc":[{"atb":[[1.78,10.21]],"id":43167125}],"con":true,"img":false}]}
{"op":"mcm","clk":"5353140231","pt":1646209665168,"mc":[{"id":"1.195503848","rc":[{"atl":[[2.28,13.73]],"id":43167126},{"atb":[[1.78,17.16]],"id":43167125}],"con":true,"img":false}]}
{"op":"mcm","clk":"5353140244","pt":1646209665380,"mc":[{"id":"1.195503848","rc":[{"atb":[[1.78,54.64]],"id":43167125}],"con":true,"img":false}]}
{"op":"mcm","clk":"5353140260","pt":1646209665782,"mc":[{"id":"1.195503848","rc":[{"atb":[[1.79,10.4]],"id":43167125}],"con":true,"img":false}]}
{"op":"mcm","clk":"5353140264","pt":1646209665836,"mc":[{"id":"1.195503848","rc":[{"atb":[[1.79,0]],"id":43167125}],"con":true,"img":false}]}
{"op":"mcm","clk":"5353140416","pt":1646209668465,"mc":[{"id":"1.195503848","rc":[{"atl":[[2.28,8.39]],"id":43167126},{"atb":[[1.78,47.69]],"id":43167125}],"con":true,"img":false}]}
{"op":"mcm","clk":"5353140434","pt":1646209668878,"mc":[{"id":"1.195503848","rc":[{"atb":[[1.78,10.21]],"id":43167125}],"con":true,"img":false}]}
{"op":"mcm","clk":"5353140441","pt":1646209668981,"mc":[{"id":"1.195503848","rc":[{"atb":[[2.16,1.42]],"id":43167126},{"atl":[[1.86,1.42]],"id":43167125}],"con":true,"img":false}]}
{"op":"mcm","clk":"5353140486","pt":1646209669858,"mc":[{"id":"1.195503848","rc":[{"atl":[[1000,1.99]],"id":43167126},{"atl":[[1000,1.69]],"id":43167125}],"con":true,"img":false}]}
{"op":"mcm","clk":"5353140493","pt":1646209669964,"mc":[{"id":"1.195503848","rc":[{"atb":[[2.16,9.61]],"id":43167126},{"atl":[[1000,0.32]],"id":43167126},{"atl":[[1000,0.02],[1.9,0],[1.86,11.75]],"id":43167125}],"con":true,"img":false}]}
{"op":"mcm","clk":"5353140498","pt":1646209670066,"mc":[{"id":"1.195503848","rc":[{"atl":[[1000,0]],"id":43167126},{"atl":[[1000,0]],"id":43167125}],"con":true,"img":false}]}
{"op":"mcm","clk":"5353140503","pt":1646209670171,"mc":[{"id":"1.195503848","rc":[{"atl":[[2.26,0.32]],"id":43167126},{"atl":[[1.83,0.02]],"id":43167125}],"con":true,"img":false}]}
{"op":"mcm","clk":"5353140521","pt":1646209670509,"mc":[{"id":"1.195503848","rc":[{"atb":[[2.08,8.45]],"id":43167126}],"con":true,"img":false}]}
{"op":"mcm","clk":"5353140682","pt":1646209673374,"mc":[{"id":"1.195503848","rc":[{"atb":[[2.12,34.53]],"id":43167126},{"atl":[[1.89,11.51]],"id":43167125}],"con":true,"img":false}]}
{"op":"mcm","clk":"5353140735","pt":1646209674356,"mc":[{"id":"1.195503848","rc":[{"atl":[[1.83,10.39]],"id":43167125}],"con":true,"img":false}]}
{"op":"mcm","clk":"5353140743","pt":1646209674459,"mc":[{"id":"1.195503848","rc":[{"atl":[[1.83,0.02],[1.89,1.42]],"id":43167125}],"con":true,"img":false}]}
{"op":"mcm","clk":"5353140804","pt":1646209675694,"mc":[{"id":"1.195503848","rc":[{"atl":[[2.26,8.57]],"id":43167126}],"con":true,"img":false}]}
{"op":"mcm","clk":"5353140816","pt":1646209675901,"mc":[{"id":"1.195503848","rc":[{"atb":[[2.14,34.05]],"id":43167126},{"atb":[[1.77,48.19]],"id":43167125}],"con":true,"img":false}]}
{"op":"mcm","clk":"5353140924","pt":1646209677989,"mc":[{"id":"1.195503848","rc":[{"atb":[[1.74,0],[1.75,2]],"id":43167125}],"con":true,"img":false}]}
{"op":"mcm","clk":"5353141044","pt":1646209680282,"mc":[{"id":"1.195503848","rc":[{"atl":[[2.26,0.32]],"id":43167126}],"con":true,"img":false}]}
{"op":"mcm","clk":"5353141093","pt":1646209681011,"mc":[{"id":"1.195503848","rc":[{"atb":[[1.77,10.23]],"id":43167125}],"con":true,"img":false}]}
{"op":"mcm","clk":"5353141128","pt":1646209681490,"mc":[{"id":"1.195503848","rc":[{"atl":[[1.83,10.4]],"id":43167125}],"con":true,"img":false}]}
{"op":"mcm","clk":"5353141136","pt":1646209681592,"mc":[{"id":"1.195503848","rc":[{"atl":[[2.28,0]],"id":43167126},{"atb":[[1.78,0],[1.77,0]],"id":43167125}],"con":true,"img":false}]}
{"op":"mcm","clk":"5353141154","pt":1646209681899,"mc":[{"id":"1.195503848","rc":[{"atb":[[2.1,8.44]],"id":43167126},{"atb":[[1.76,0]],"id":43167125}],"con":true,"img":false}]}
{"op":"mcm","clk":"5353141159","pt":1646209682005,"mc":[{"id":"1.195503848","rc":[{"atl":[[2.3,10.05]],"id":43167126},{"atb":[[1.77,10.57]],"id":43167125}],"con":true,"img":false}]}
{"op":"mcm","clk":"5353141168","pt":1646209682107,"mc":[{"id":"1.195503848","rc":[{"atb":[[1.69,2],[1.75,0]],"id":43167125}],"con":true,"img":false}]}
{"op":"mcm","clk":"5353141171","pt":1646209682211,"mc":[{"id":"1.195503848","rc":[{"atb":[[2.16,8.19]],"id":43167126}],"con":true,"img":false}]}
{"op":"mcm","clk":"5353141259","pt":1646209683875,"mc":[{"id":"1.195503848","rc":[{"atl":[[2.3,16.1]],"id":43167126},{"atb":[[1.77,18.36]],"id":43167125}],"con":true,"img":false}]}
{"op":"mcm","clk":"5353141288","pt":1646209684396,"mc":[{"id":"1.195503848","rc":[{"atb":[[2.16,33.39]],"id":43167126},{"atb":[[1.76,38.46]],"id":43167125}],"con":true,"img":false}]}
{"op":"mcm","clk":"5353141291","pt":1646209684500,"mc":[{"id":"1.195503848","rc":[{"atb":[[2,0],[1.98,0],[2.04,0],[1.99,0],[1.97,0]],"id":43167126},{"atl":[[1.96,0],[1.93,9.87],[1.92,0],[1.89,0],[1.98,0],[1.94,0]],"id":43167125}],"con":true,"img":false}]}
{"op":"mcm","clk":"5353141361","pt":1646209685583,"mc":[{"id":"1.195503848","rc":[{"atl":[[2.3,10.05]],"id":43167126},{"atb":[[1.77,10.57]],"id":43167125}],"con":true,"img":false}]}
{"op":"mcm","clk":"5353141376","pt":1646209685892,"mc":[{"id":"1.195503848","rc":[{"atb":[[1.76,0],[1.69,44.36]],"id":43167125}],"con":true,"img":false}]}
{"op":"mcm","clk":"5353141390","pt":1646209685996,"mc":[{"id":"1.195503848","rc":[{"atb":[[2.18,8.12]],"id":43167126}],"con":true,"img":false}]}
{"op":"mcm","clk":"5353141448","pt":1646209687089,"mc":[{"id":"1.195503848","rc":[{"atl":[[1.86,10.33],[1.87,10.1]],"id":43167125}],"con":true,"img":false}]}
{"op":"mcm","clk":"5353141462","pt":1646209687297,"mc":[{"id":"1.195503848","rc":[{"atb":[[1.69,42.36],[1.75,2]],"id":43167125}],"con":true,"img":false}]}
{"op":"mcm","clk":"5353141694","pt":1646209690515,"mc":[{"id":"1.195503848","rc":[{"atl":[[2.3,2]],"id":43167126},{"atb":[[1.77,0]],"id":43167125}],"con":true,"img":false}]}
{"op":"mcm","clk":"5353141700","pt":1646209690609,"mc":[{"id":"1.195503848","rc":[{"atb":[[1.03,3.08]],"id":43167126}],"con":true,"img":false}]}
{"op":"mcm","clk":"5353141717","pt":1646209690820,"mc":[{"id":"1.195503848","rc":[{"atb":[[1.03,0.35]],"id":43167126},{"atb":[[1.75,12.57]],"id":43167125}],"con":true,"img":false}]}
{"op":"mcm","clk":"5353141725","pt":1646209690918,"mc":[{"id":"1.195503848","rc":[{"atb":[[1.03,0],[2.14,8.41],[2.16,8.19]],"id":43167126},{"atb":[[1.69,0]],"id":43167125}],"con":true,"img":false}]}
{"op":"mcm","clk":"5353141728","pt":1646209690971,"mc":[{"id":"1.195503848","rc":[{"atl":[[2.3,1.97],[2.26,0]],"id":43167126},{"trd":[[2.3,0.05],[2.26,0.79]],"ltp":2.3,"tv":0.84,"id":43167126}],"con":true,"img":false}]}
{"op":"mcm","clk":"5353141766","pt":1646209691395,"mc":[{"id":"1.195503848","rc":[{"atl":[[2.3,10.17]],"id":43167126},{"atl":[[1.83,0.02]],"id":43167125}],"con":true,"img":false}]}
{"op":"mcm","clk":"5353141779","pt":1646209691594,"mc":[{"id":"1.195503848","rc":[{"atb":[[1.04,2.87]],"id":43167125}],"con":true,"img":false}]}
{"op":"mcm","clk":"5353141789","pt":1646209691801,"mc":[{"id":"1.195503848","rc":[{"atb":[[1.04,0.14]],"id":43167125}],"con":true,"img":false}]}
{"op":"mcm","clk":"5353141795","pt":1646209691903,"mc":[{"id":"1.195503848","rc":[{"atb":[[2.18,32.89]],"id":43167126},{"atb":[[1.69,42.36],[1.04,0]],"id":43167125}],"con":true,"img":false}]}
{"op":"mcm","clk":"5353141803","pt":1646209692013,"mc":[{"id":"1.195503848","rc":[{"atb":[[1.83,0.11]],"id":43167125},{"atl":[[1.83,0]],"id":43167125},{"trd":[[1.83,10.31]],"ltp":1.83,"tv":10.31,"id":43167125}],"con":true,"img":false}]}
{"op":"mcm","clk":"5353141815","pt":1646209692217,"mc":[{"id":"1.195503848","rc":[{"atb":[[1.83,0]],"id":43167125},{"trd":[[1.83,10.53]],"ltp":1.83,"tv":10.53,"id":43167125}],"con":true,"img":false}]}
{"op":"mcm","clk":"5353141829","pt":1646209692421,"mc":[{"id":"1.195503848","rc":[{"atb":[[2.12,26.1],[2.2,8.18]],"id":43167126}],"con":true,"img":false}]}
{"op":"mcm","clk":"5353141904","pt":1646209693610,"mc":[{"id":"1.195503848","rc":[{"atb":[[2.2,0]],"id":43167126}],"con":true,"img":false}]}
{"op":"mcm","clk":"5353141971","pt":1646209694392,"mc":[{"id":"1.195503848","rc":[{"atb":[[1.75,19.68]],"id":43167125}],"con":true,"img":false}]}
{"op":"mcm","clk":"5353141982","pt":1646209694707,"mc":[{"id":"1.195503848","rc":[{"atb":[[1.76,10.38]],"id":43167125},{"atl":[[1.83,6.26]],"id":43167125}],"con":true,"img":false}]}
{"op":"mcm","clk":"5353141994","pt":1646209694917,"mc":[{"id":"1.195503848","rc":[{"atb":[[2.18,8.12],[2.16,33.39]],"id":43167126},{"atb":[[1.76,48.84]],"id":43167125}],"con":true,"img":false}]}
{"op":"mcm","clk":"5353142022","pt":1646209695278,"mc":[{"id":"1.195503848","rc":[{"atb":[[1.77,10.35]],"id":43167125}],"con":true,"img":false}]}
{"op":"mcm","clk":"5353142226","pt":1646209698297,"mc":[{"id":"1.195503848","rc":[{"atb":[[1.76,50.84],[1.75,17.68]],"id":43167125}],"con":true,"img":false}]}
{"op":"mcm","clk":"5353142390","pt":1646209701294,"mc":[{"id":"1.195503848","rc":[{"atb":[[1.76,48.84],[1.75,19.68]],"id":43167125}],"con":true,"img":false}]}
{"op":"mcm","clk":"5353142468","pt":1646209702890,"mc":[{"id":"1.195503848","rc":[{"atl":[[2.3,15.88]],"id":43167126},{"atb":[[1.75,12.57]],"id":43167125}],"con":true,"img":false}]}
{"op":"mcm","clk":"5353142493","pt":1646209703411,"mc":[{"id":"1.195503848","rc":[{"atb":[[1.77,17.69]],"id":43167125}],"con":true,"img":false}]}
{"op":"mcm","clk":"5353142580","pt":1646209704913,"mc":[{"id":"1.195503848","rc":[{"atl":[[2.28,8.2]],"id":43167126},{"atb":[[1.78,10.33]],"id":43167125}],"con":true,"img":false}]}
{"op":"mcm","clk":"5353142600","pt":1646209705325,"mc":[{"id":"1.195503848","rc":[{"atl":[[2.3,10.17]],"id":43167126},{"atb":[[1.77,10.35]],"id":43167125}],"con":true,"img":false}]}
{"op":"mcm","clk":"5353142607","pt":1646209705430,"mc":[{"id":"1.195503848","rc":[{"atb":[[2.16,8.19],[2.14,34.05]],"id":43167126},{"atb":[[1.77,48.31]],"id":43167125}],"con":true,"img":false}]}
{"op":"mcm","clk":"5353142620","pt":1646209705582,"mc":[{"id":"1.195503848","rc":[{"atl":[[2.28,14.04]],"id":43167126},{"atb":[[1.78,17.93]],"id":43167125}],"con":true,"img":false}]}
{"op":"mcm","clk":"5353142651","pt":1646209706099,"mc":[{"id":"1.195503848","rc":[{"atl":[[2.3,8.2],[2.28,16.04]],"id":43167126}],"con":true,"img":false}]}
{"op":"mcm","clk":"5353142678","pt":1646209706514,"mc":[{"id":"1.195503848","rc":[{"atb":[[1.77,50.31],[1.75,10.57]],"id":43167125}],"con":true,"img":false}]}
{"op":"mcm","clk":"5353142680","pt":1646209706619,"mc":[{"id":"1.195503848","rc":[{"atb":[[2.18,0],[2.16,0],[2.14,25.64],[2.1,0]],"id":43167126},{"atl":[[2.26,8.52]],"id":43167126},{"atb":[[1.79,9.93]],"id":43167125},{"atl":[[1.88,0],[1.91,0],[1.86,0],[1.83,0],[1.87,0]],"id":43167125},{"trd":[[1.83,23.07]],"ltp":1.83,"tv":23.07,"id":43167125}],"con":true,"img":false}]}
{"op":"mcm","clk":"5353142684","pt":1646209706723,"mc":[{"id":"1.195503848","rc":[{"atb":[[1.75,0]],"id":43167125}],"con":true,"img":false}]}
{"op":"mcm","clk":"5353142689","pt":1646209706830,"mc":[{"id":"1.195503848","rc":[{"atb":[[2.1,8.52]],"id":43167126}],"con":true,"img":false}]}
{"op":"mcm","clk":"5353142694","pt":1646209706931,"mc":[{"id":"1.195503848","rc":[{"atb":[[2.12,0],[2.14,0]],"id":43167126},{"atb":[[1.69,0]],"id":43167125}],"con":true,"img":false}]}
{"op":"mcm","clk":"5353142719","pt":1646209707398,"mc":[{"id":"1.195503848","rc":[{"atb":[[2.08,35.52]],"id":43167126},{"atb":[[1.79,46.93]],"id":43167125}],"con":true,"img":false}]}
{"op":"mcm","clk":"5353142763","pt":1646209708230,"mc":[{"id":"1.195503848","rc":[{"atb":[[1.78,10.33]],"id":43167125}],"con":true,"img":false}]}
{"op":"mcm","clk":"5353142766","pt":1646209708334,"mc":[{"id":"1.195503848","rc":[{"atb":[[1.79,54.53]],"id":43167125}],"con":true,"img":false}]}
{"op":"mcm","clk":"5353142831","pt":1646209709427,"mc":[{"id":"1.195503848","rc":[{"atb":[[1.88,0],[1.68,0],[1.48,0]],"id":43167126},{"atb":[[1.28,0],[1.68,0],[1.48,0]],"id":43167125}],"con":true,"img":false}]}
{"op":"mcm","clk":"5353142877","pt":1646209710109,"mc":[{"id":"1.195503848","rc":[{"atb":[[2.08,27.06]],"id":43167126}],"con":true,"img":false}]}
{"op":"mcm","clk":"5353142885","pt":1646209710315,"mc":[{"id":"1.195503848","rc":[{"atl":[[1.93,0]],"id":43167125}],"con":true,"img":false}]}
{"op":"mcm","clk":"5353142892","pt":1646209710418,"mc":[{"id":"1.195503848","rc":[{"atb":[[2.04,28.1],[2.08,0]],"id":43167126},{"atl":[[2.06,0]],"id":43167125}],"con":true,"img":false}]}
{"op":"mcm","clk":"5353142899","pt":1646209710523,"mc":[{"id":"1.195503848","rc":[{"atl":[[2.04,2]],"id":43167125}],"con":true,"img":false}]}
{"op":"mcm","clk":"5353142904","pt":1646209710628,"mc":[{"id":"1.195503848","rc":[{"atl":[[1.97,16.91]],"id":43167125}],"con":true,"img":false}]}
{"op":"mcm","clk":"5353142958","pt":1646209711400,"mc":[{"id":"1.195503848","rc":[{"atl":[[2.28,14.04],[2.26,10.52]],"id":43167126}],"con":true,"img":false}]}
{"op":"mcm","clk":"5353142979","pt":1646209711812,"mc":[{"id":"1.195503848","rc":[{"atb":[[1.79,46.93]],"id":43167125}],"con":true,"img":false}]}
{"op":"mcm","clk":"5353143036","pt":1646209712619,"mc":[{"id":"1.195503848","rc":[{"atl":[[1.96,9.85]],"id":43167125}],"con":true,"img":false}]}
{"op":"mcm","clk":"5353143056","pt":1646209712931,"mc":[{"id":"1.195503848","rc":[{"atl":[[1.97,9.92]],"id":43167125}],"con":true,"img":false}]}
{"op":"mcm","clk":"5353143063","pt":1646209713035,"mc":[{"id":"1.195503848","rc":[{"atl":[[1.96,16.84]],"id":43167125}],"con":true,"img":false}]}
{"op":"mcm","clk":"5353143102","pt":1646209713607,"mc":[{"id":"1.195503848","rc":[{"atb":[[1.79,53.68]],"id":43167125}],"con":true,"img":false}]}
{"op":"mcm","clk":"5353143173","pt":1646209714858,"mc":[{"id":"1.195503848","marketDefinition":{"bspMarket":false,"turnInPlayEnabled":false,"persistenceEnabled":false,"marketBaseRate":7.0,"eventId":"31272499","eventTypeId":"4339","numberOfWinners":1,"bettingType":"ODDS","marketType":"MATCH_BET","marketTime":"2022-03-02T08:28:00.000Z","suspendTime":"2022-03-02T08:28:00.000Z","bspReconciled":false,"complete":true,"inPlay":false,"crossMatching":true,"runnersVoidable":false,"numberOfActiveRunners":2,"betDelay":0,"status":"SUSPENDED","runners":[{"status":"ACTIVE","sortPriority":1,"id":43167125,"name":"3. Lovely Result"},{"status":"ACTIVE","sortPriority":2,"id":43167126,"name":"4. Zipping Fern"}],"regulators":["MR_INT"],"venue":"Rockhampton","countryCode":"AU","discountAllowed":true,"timezone":"Australia/Queensland","openDate":"2022-03-02T08:28:00.000Z","version":4382833721,"name":"Lovely Result v Zipping Fern","eventName":"Rockhampton (AUS) 2nd Mar"},"rc":[],"con":true,"img":false}]}
{"op":"mcm","clk":"5353143173","pt":1646209714858,"mc":[{"id":"1.195503848","rc":[{"atb":[[2.02,0],[2.06,0],[2.04,0],[1.95,0],[2.1,0]],"id":43167126},{"atl":[[2.3,0],[2.32,0],[2.28,0],[2.26,0]],"id":43167126},{"atb":[[1.2,0],[1.44,0],[1.45,0],[1.43,0],[1.78,0],[1.33,0],[1.39,0],[1.76,0],[1.35,0],[1.41,0],[1.36,0],[1.79,0],[1.27,0],[1.25,0],[1.22,0],[1.42,0],[1.29,0],[1.77,0],[1.31,0],[1.47,0],[1.38,0]],"id":43167125},{"atl":[[2.82,0],[2.72,0],[2.54,0],[3.1,0],[2.04,0],[1.96,0],[2.6,0],[2.64,0],[2.58,0],[2.98,0],[2.62,0],[2.94,0],[2.76,0],[3.2,0],[2.86,0],[2.9,0],[1.97,0],[2.66,0],[2.78,0],[2.7,0]],"id":43167125}],"con":true,"img":false}]}
{"op":"mcm","clk":"5353145531","pt":1646209761791,"mc":[{"id":"1.195503848","rc":[{"trd":[[2.3,0],[2.2,0],[2.26,0],[1.87,0],[2.14,0]],"ltp":2.3,"tv":0.0,"id":43167126},{"trd":[[1.8,0],[1.82,0],[1.83,0],[1.81,0]],"ltp":1.8,"tv":0.0,"id":43167125}],"con":true,"img":false}]}
{"op":"mcm","clk":"5353145602","pt":1646209763269,"mc":[{"id":"1.195503848","marketDefinition":{"bspMarket":false,"turnInPlayEnabled":false,"persistenceEnabled":false,"marketBaseRate":7.0,"eventId":"31272499","eventTypeId":"4339","numberOfWinners":1,"bettingType":"ODDS","marketType":"MATCH_BET","marketTime":"2022-03-02T08:28:00.000Z","suspendTime":"2022-03-02T08:28:00.000Z","bspReconciled":false,"complete":true,"inPlay":false,"crossMatching":false,"runnersVoidable":false,"numberOfActiveRunners":0,"betDelay":0,"status":"CLOSED","settledTime":"2022-03-02T08:29:20.000Z","runners":[{"status":"LOSER","sortPriority":1,"id":43167125,"name":"3. Lovely Result"},{"status":"WINNER","sortPriority":2,"id":43167126,"name":"4. Zipping Fern"}],"regulators":["MR_INT"],"venue":"Rockhampton","countryCode":"AU","discountAllowed":true,"timezone":"Australia/Queensland","openDate":"2022-03-02T08:28:00.000Z","version":4382833827,"name":"Lovely Result v Zipping Fern","eventName":"Rockhampton (AUS) 2nd Mar"},"rc":[],"con":true,"img":false}]}
