{"op":"mcm","clk":"5317728512","pt":1646251399896,"mc":[{"id":"1.195532878","marketDefinition":{"bspMarket":true,"turnInPlayEnabled":false,"persistenceEnabled":false,"marketBaseRate":5.0,"eventId":"31275720","eventTypeId":"4339","numberOfWinners":1,"bettingType":"ODDS","marketType":"WIN","marketTime":"2022-03-03T18:02:00.000Z","suspendTime":"2022-03-03T18:02:00.000Z","bspReconciled":false,"complete":true,"inPlay":false,"crossMatching":false,"runnersVoidable":false,"numberOfActiveRunners":6,"betDelay":0,"status":"OPEN","runners":[{"status":"ACTIVE","sortPriority":1,"id":39632625,"name":"1. Knockane Harbour"},{"status":"ACTIVE","sortPriority":2,"id":38251452,"name":"2. Speak Out Aida"},{"status":"ACTIVE","sortPriority":3,"id":28753299,"name":"3. Huwearsdtrousers"},{"status":"ACTIVE","sortPriority":4,"id":40452329,"name":"4. Im Alright Botch"},{"status":"ACTIVE","sortPriority":5,"id":41555107,"name":"5. Theresas Pet"},{"status":"ACTIVE","sortPriority":6,"id":39059999,"name":"6. Conors Pickens"}],"regulators":["MR_INT"],"venue":"Romford","countryCode":"GB","discountAllowed":false,"timezone":"Europe/London","openDate":"2022-03-03T13:57:00.000Z","version":4384107324,"name":"A2 400m","eventName":"Romford 3rd Mar"},"rc":[],"con":true,"img":false}]}
{"op":"mcm","clk":"5317728868","pt":1646251401773,"mc":[{"id":"1.195532878","marketDefinition":{"bspMarket":true,"turnInPlayEnabled":false,"persistenceEnabled":false,"marketBaseRate":5.0,"eventId":"31275720","eventTypeId":"4339","numberOfWinners":1,"bettingType":"ODDS","marketType":"WIN","marketTime":"2022-03-03T18:02:00.000Z","suspendTime":"2022-03-03T18:02:00.000Z","bspReconciled":false,"complete":true,"inPlay":false,"crossMatching":false,"runnersVoidable":false,"numberOfActiveRunners":6,"betDelay":0,"status":"OPEN","runners":[{"status":"ACTIVE","sortPriority":1,"id":39632625,"name":"1. Knockane Harbour"},{"status":"ACTIVE","sortPriority":2,"id":38251452,"name":"2. Speak Out Aida"},{"status":"ACTIVE","sortPriority":3,"id":28753299,"name":"3. Huwearsdtrousers"},{"status":"ACTIVE","sortPriority":4,"id":40452329,"name":"4. Im Alright Botch"},{"status":"ACTIVE","sortPriority":5,"id":41555107,"name":"5. Theresas Pet"},{"status":"ACTIVE","sortPriority":6,"id":39059999,"name":"6. Conors Pickens"}],"regulators":["MR_INT"],"venue":"Romford","countryCode":"GB","discountAllowed":true,"timezone":"Europe/London","openDate":"2022-03-03T13:57:00.000Z","version":4384107324,"name":"A2 400m","eventName":"Romford 3rd Mar"},"rc":[],"con":true,"img":false}]}
{"op":"mcm","clk":"5318486527","pt":1646259103072,"mc":[{"id":"1.195532878","rc":[{"atb":[[1.12,30]],"id":41555107},{"atl":[[560,3]],"id":41555107},{"spn":280.56,"spf":"NaN","id":41555107},{"atb":[[1.12,30]],"id":40452329},{"atl":[[270,3]],"id":40452329},{"spn":135.56,"spf":"NaN","id":40452329},{"atb":[[1.12,30]],"id":38251452},{"atl":[[390,3]],"id":38251452},{"spn":195.56,"spf":"NaN","id":38251452},{"atb":[[1.12,30]],"id":39632625},{"atl":[[370,3]],"id":39632625},{"spn":185.56,"spf":"NaN","id":39632625},{"atb":[[1.14,30]],"id":39059999},{"atl":[[500,3]],"id":39059999},{"spn":250.57,"spf":"NaN","id":39059999},{"atb":[[1.12,30]],"id":28753299},{"atl":[[550,3]],"id":28753299},{"spn":275.56,"spf":"NaN","id":28753299}],"con":true,"img":false}]}
{"op":"mcm","clk":"5320255949","pt":1646291303422,"mc":[{"id":"1.195532878","rc":[{"atb":[[2.02,12.66]],"id":41555107},{"spn":281.01,"spf":"NaN","id":41555107},{"atb":[[2.1,13.16]],"id":40452329},{"spn":136.05,"spf":"NaN","id":40452329},{"atb":[[2.08,12.17]],"id":38251452},{"spn":196.04,"spf":"NaN","id":38251452},{"atb":[[2.08,11.3]],"id":39632625},{"spn":186.04,"spf":"NaN","id":39632625},{"atb":[[2.02,10.13]],"id":39059999},{"spn":251.01,"spf":"NaN","id":39059999},{"atb":[[2.06,11.19]],"id":28753299},{"spn":276.03,"spf":"NaN","id":28753299}],"con":true,"img":false}]}
{"op":"mcm","clk":"5320538817","pt":1646297202600,"mc":[{"id":"1.195532878","marketDefinition":{"bspMarket":true,"turnInPlayEnabled":false,"persistenceEnabled":false,"marketBaseRate":5.0,"eventId":"31275720","eventTypeId":"4339","numberOfWinners":1,"bettingType":"ODDS","marketType":"WIN","marketTime":"2022-03-03T18:02:00.000Z","suspendTime":"2022-03-03T18:02:00.000Z","bspReconciled":false,"complete":true,"inPlay":false,"crossMatching":false,"runnersVoidable":false,"numberOfActiveRunners":6,"betDelay":0,"status":"OPEN","runners":[{"status":"ACTIVE","sortPriority":1,"id":39632625,"name":"1. Knockane Harbour"},{"status":"ACTIVE","sortPriority":2,"id":38251452,"name":"2. Speak Out Aida"},{"status":"ACTIVE","sortPriority":3,"id":28753299,"name":"3. Huwearsdtrousers"},{"status":"ACTIVE","sortPriority":4,"id":40452329,"name":"4. Im Alright Botch"},{"status":"ACTIVE","sortPriority":5,"id":41555107,"name":"5. Theresas Pet"},{"status":"ACTIVE","sortPriority":6,"id":39059999,"name":"6. Conors Pickens"}],"regulators":["MR_INT"],"venue":"Romford","countryCode":"GB","discountAllowed":true,"timezone":"Europe/London","openDate":"2022-03-03T13:57:00.000Z","version":4384107324,"name":"A2 400m","eventName":"Romford 3rd Mar"},"rc":[{"atb":[[1.12,30],[2.02,12.67]],"id":41555107},{"atl":[[560,3]],"id":41555107},{"spn":281.01,"spf":"NaN","id":41555107},{"atb":[[1.12,30],[2.1,13.17]],"id":40452329},{"atl":[[270,3]],"id":40452329},{"spn":136.05,"spf":"NaN","id":40452329},{"atb":[[1.12,30],[2.08,12.17]],"id":38251452},{"atl":[[390,3]],"id":38251452},{"spn":196.04,"spf":"NaN","id":38251452},{"atb":[[1.12,30],[2.08,11.3]],"id":39632625},{"atl":[[370,3]],"id":39632625},{"spn":186.04,"spf":"NaN","id":39632625},{"atb":[[2.02,10.14],[1.14,30]],"id":39059999},{"atl":[[500,3]],"id":39059999},{"spn":251.01,"spf":"NaN","id":39059999},{"atb":[[1.12,30],[2.06,11.2]],"id":28753299},{"atl":[[550,3]],"id":28753299},{"spn":276.03,"spf":"NaN","id":28753299}],"con":true,"img":true}]}
{"op":"mcm","clk":"5320746138","pt":1646301073349,"mc":[{"id":"1.195532878","rc":[{"atb":[[2.02,12.67]],"id":41555107},{"spl":[[16,10]],"id":41555107},{"spn":9.01,"spf":1.0,"id":41555107},{"atb":[[2.1,13.17]],"id":40452329},{"spl":[[16,10]],"id":40452329},{"spn":9.05,"spf":1.0,"id":40452329},{"atb":[[2.08,12.17]],"id":38251452},{"spl":[[4.6,10]],"id":38251452},{"spn":3.34,"spf":1.0,"id":38251452},{"atb":[[2.08,11.3]],"id":39632625},{"spl":[[26,10]],"id":39632625},{"spn":14.04,"spf":1.0,"id":39632625},{"atb":[[2.02,10.14]],"id":39059999},{"atb":[[2.06,11.2]],"id":28753299},{"spl":[[5.1,10]],"id":28753299},{"spn":3.58,"spf":1.0,"id":28753299}],"con":true,"img":false}]}
{"op":"mcm","clk":"5320812751","pt":1646302342242,"mc":[{"id":"1.195532878","rc":[{"atb":[[2.02,12.67]],"id":41555107},{"spl":[[21,1]],"id":41555107},{"atb":[[2.1,13.16]],"id":40452329},{"spl":[[21,1]],"id":40452329},{"atb":[[2.08,12.17]],"id":38251452},{"spl":[[21,1]],"id":38251452},{"atb":[[2.08,11.3]],"id":39632625},{"spl":[[21,1]],"id":39632625},{"spn":11.54,"spf":1.0,"id":39632625},{"atb":[[2.02,10.13]],"id":39059999},{"spl":[[21,1]],"id":39059999},{"spn":11.51,"spf":1.0,"id":39059999},{"atb":[[2.06,11.19]],"id":28753299},{"spl":[[21,1]],"id":28753299}],"con":true,"img":false}]}
{"op":"mcm","clk":"5321039332","pt":1646305449090,"mc":[{"id":"1.195532878","marketDefinition":{"bspMarket":true,"turnInPlayEnabled":false,"persistenceEnabled":false,"marketBaseRate":5.0,"eventId":"31275720","eventTypeId":"4339","numberOfWinners":1,"bettingType":"ODDS","marketType":"WIN","marketTime":"2022-03-03T18:02:00.000Z","suspendTime":"2022-03-03T18:02:00.000Z","bspReconciled":false,"complete":true,"inPlay":false,"crossMatching":false,"runnersVoidable":false,"numberOfActiveRunners":6,"betDelay":0,"status":"OPEN","runners":[{"status":"ACTIVE","sortPriority":1,"id":39632625,"name":"1. Knockane Harbour"},{"status":"ACTIVE","sortPriority":2,"id":38251452,"name":"2. Speak Out Aida"},{"status":"ACTIVE","sortPriority":3,"id":28753299,"name":"3. Huwearsdtrousers"},{"status":"ACTIVE","sortPriority":4,"id":40452329,"name":"4. Im Alright Botch"},{"status":"ACTIVE","sortPriority":5,"id":41555107,"name":"5. Theresas Pet"},{"status":"ACTIVE","sortPriority":6,"id":39059999,"name":"6. Conors Pickens"}],"regulators":["MR_INT"],"venue":"Romford","countryCode":"GB","discountAllowed":true,"timezone":"Europe/London","openDate":"2022-03-03T13:57:00.000Z","version":4384107324,"name":"A2 400m","eventName":"Romford 3rd Mar"},"rc":[{"atb":[[1.12,30],[2.02,12.67]],"id":41555107},{"spl":[[16,10],[21,1]],"id":41555107},{"atl":[[560,3]],"id":41555107},{"spn":9.01,"spf":1.0,"id":41555107},{"atb":[[1.12,30],[2.1,13.17]],"id":40452329},{"spl":[[16,10],[21,1]],"id":40452329},{"atl":[[270,3]],"id":40452329},{"spn":9.05,"spf":1.0,"id":40452329},{"atb":[[1.12,30],[2.08,12.17]],"id":38251452},{"spl":[[4.6,10],[21,1]],"id":38251452},{"atl":[[390,3]],"id":38251452},{"spn":3.34,"spf":1.0,"id":38251452},{"atb":[[1.12,30],[2.08,11.3]],"id":39632625},{"spl":[[21,1],[26,10]],"id":39632625},{"atl":[[370,3]],"id":39632625},{"spn":11.54,"spf":1.0,"id":39632625},{"atb":[[2.02,10.14],[1.14,30]],"id":39059999},{"spl":[[21,1]],"id":39059999},{"atl":[[500,3]],"id":39059999},{"spn":11.51,"spf":1.0,"id":39059999},{"atb":[[1.12,30],[2.06,11.2]],"id":28753299},{"spl":[[5.1,10],[21,1]],"id":28753299},{"atl":[[550,3]],"id":28753299},{"spn":3.58,"spf":1.0,"id":28753299}],"con":true,"img":true}]}
{"op":"mcm","clk":"5321369395","pt":1646308872320,"mc":[{"id":"1.195532878","rc":[{"atb":[[4.3,2],[2.02,12.67]],"id":41555107},{"spn":10.15,"spf":1.0,"id":41555107},{"atb":[[3.9,2],[2.1,13.17]],"id":40452329},{"spn":9.95,"spf":1.0,"id":40452329},{"atb":[[2.08,12.17],[4.7,2]],"id":38251452},{"spn":4.6,"spf":1.0,"id":38251452},{"atb":[[4.3,2],[2.08,11.3]],"id":39632625},{"spn":12.65,"spf":1.0,"id":39632625},{"atb":[[2.02,10.14],[10,2]],"id":39059999},{"spn":15.5,"spf":1.0,"id":39059999},{"atb":[[8,2],[2.06,11.2]],"id":28753299},{"spn":5.1,"spf":1.0,"id":28753299}],"con":true,"img":false}]}
{"op":"mcm","clk":"5321370891","pt":1646308889540,"mc":[{"id":"1.195532878","marketDefinition":{"bspMarket":true,"turnInPlayEnabled":false,"persistenceEnabled":false,"marketBaseRate":5.0,"eventId":"31275720","eventTypeId":"4339","numberOfWinners":1,"bettingType":"ODDS","marketType":"WIN","marketTime":"2022-03-03T18:02:00.000Z","suspendTime":"2022-03-03T18:02:00.000Z","bspReconciled":false,"complete":true,"inPlay":false,"crossMatching":true,"runnersVoidable":false,"numberOfActiveRunners":6,"betDelay":0,"status":"OPEN","runners":[{"status":"ACTIVE","sortPriority":1,"id":39632625,"name":"1. Knockane Harbour"},{"status":"ACTIVE","sortPriority":2,"id":38251452,"name":"2. Speak Out Aida"},{"status":"ACTIVE","sortPriority":3,"id":28753299,"name":"3. Huwearsdtrousers"},{"status":"ACTIVE","sortPriority":4,"id":40452329,"name":"4. Im Alright Botch"},{"status":"ACTIVE","sortPriority":5,"id":41555107,"name":"5. Theresas Pet"},{"status":"ACTIVE","sortPriority":6,"id":39059999,"name":"6. Conors Pickens"}],"regulators":["MR_INT"],"venue":"Romford","countryCode":"GB","discountAllowed":true,"timezone":"Europe/London","openDate":"2022-03-03T13:57:00.000Z","version":4384107324,"name":"A2 400m","eventName":"Romford 3rd Mar"},"rc":[],"con":true,"img":false}]}
{"op":"mcm","clk":"5321440126","pt":1646309732027,"mc":[{"id":"1.195532878","rc":[{"atb":[[11.5,0.96]],"id":39059999},{"atl":[[36,0.3]],"id":39059999},{"spn":16.25,"spf":1.0,"id":39059999},{"atb":[[6.2,1.93]],"id":28753299},{"atl":[[13.5,0.81]],"id":28753299}],"con":true,"img":false}]}
{"op":"mcm","clk":"5321440138","pt":1646309732129,"mc":[{"id":"1.195532878","rc":[{"atb":[[3.8,2]],"id":41555107},{"atl":[[6.8,1.73]],"id":41555107},{"atb":[[3.55,2]],"id":40452329},{"atl":[[6.2,1.93]],"id":40452329},{"atb":[[4.1,2]],"id":38251452},{"atl":[[8,1.44]],"id":38251452},{"atb":[[3.8,2]],"id":39632625},{"atl":[[6.8,1.73]],"id":39632625}],"con":true,"img":false}]}
{"op":"mcm","clk":"5321473187","pt":1646310064807,"mc":[{"id":"1.195532878","rc":[{"atb":[[4.3,0]],"id":41555107},{"atl":[[4.3,1]],"id":41555107},{"trd":[[4.3,4]],"ltp":4.3,"tv":4.0,"id":41555107},{"spn":4.05,"spf":1.0,"id":41555107},{"spn":5.05,"spf":1.0,"id":40452329},{"spn":5.55,"spf":1.0,"id":39632625}],"con":true,"img":false}]}
{"op":"mcm","clk":"5321473222","pt":1646310064978,"mc":[{"id":"1.195532878","rc":[{"atb":[[3.8,0]],"id":41555107}],"con":true,"img":false}]}
{"op":"mcm","clk":"5321473238","pt":1646310065072,"mc":[{"id":"1.195532878","rc":[{"atb":[[2.58,2]],"id":41555107}],"con":true,"img":false}]}
{"op":"mcm","clk":"5321473252","pt":1646310065174,"mc":[{"id":"1.195532878","rc":[{"atb":[[2.04,2]],"id":41555107}],"con":true,"img":false}]}
{"op":"mcm","clk":"5321473552","pt":1646310067308,"mc":[{"id":"1.195532878","rc":[{"atb":[[2.66,6.75]],"id":39632625},{"atb":[[3.35,4.76]],"id":28753299}],"con":true,"img":false}]}
{"op":"mcm","clk":"5321473578","pt":1646310067467,"mc":[{"id":"1.195532878","rc":[{"atb":[[2.18,9.49]],"id":41555107},{"atb":[[3.9,3.86]],"id":39059999}],"con":true,"img":false}]}
{"op":"mcm","clk":"5321473604","pt":1646310067678,"mc":[{"id":"1.195532878","rc":[{"atb":[[2.82,6.15]],"id":38251452}],"con":true,"img":false}]}
{"op":"mcm","clk":"5321473617","pt":1646310067780,"mc":[{"id":"1.195532878","rc":[{"atb":[[2.58,7.09]],"id":40452329}],"con":true,"img":false}]}
{"op":"mcm","clk":"5321473686","pt":1646310068297,"mc":[{"id":"1.195532878","rc":[{"atb":[[3.9,2]],"id":41555107}],"con":true,"img":false}]}
{"op":"mcm","clk":"5321473720","pt":1646310068605,"mc":[{"id":"1.195532878","rc":[{"atb":[[2.04,0]],"id":41555107}],"con":true,"img":false}]}
{"op":"mcm","clk":"5321474924","pt":1646310079003,"mc":[{"id":"1.195532878","rc":[{"atb":[[2.7,7.3]],"id":39632625}],"con":true,"img":false}]}
{"op":"mcm","clk":"5321474940","pt":1646310079149,"mc":[{"id":"1.195532878","rc":[{"atb":[[2.62,7.67]],"id":41555107}],"con":true,"img":false}]}
{"op":"mcm","clk":"5321474962","pt":1646310079324,"mc":[{"id":"1.195532878","rc":[{"atb":[[2.62,7.67]],"id":40452329}],"con":true,"img":false}]}
{"op":"mcm","clk":"5321474990","pt":1646310079626,"mc":[{"id":"1.195532878","rc":[{"atb":[[2.86,6.67]],"id":38251452},{"atb":[[4,4.14]],"id":39059999}],"con":true,"img":false}]}
{"op":"mcm","clk":"5321475022","pt":1646310079936,"mc":[{"id":"1.195532878","rc":[{"atb":[[3.45,5.07]],"id":28753299}],"con":true,"img":false}]}
{"op":"mcm","clk":"5321486854","pt":1646310198775,"mc":[{"id":"1.195532878","rc":[{"atb":[[2.02,0]],"id":41555107},{"spn":4.1,"spf":1.0,"id":41555107}],"con":true,"img":false}]}
{"op":"mcm","clk":"5321486866","pt":1646310198875,"mc":[{"id":"1.195532878","rc":[{"atb":[[2.2,12.67]],"id":41555107}],"con":true,"img":false}]}
{"op":"mcm","clk":"5321496678","pt":1646310304079,"mc":[{"id":"1.195532878","rc":[{"atb":[[2.18,0]],"id":41555107}],"con":true,"img":false}]}
{"op":"mcm","clk":"5321496900","pt":1646310306984,"mc":[{"id":"1.195532878","rc":[{"atb":[[2.66,6.75]],"id":41555107}],"con":true,"img":false}]}
{"op":"mcm","clk":"5321497624","pt":1646310316119,"mc":[{"id":"1.195532878","rc":[{"atb":[[2.58,0]],"id":40452329},{"atb":[[2.82,0]],"id":38251452},{"atb":[[2.66,0]],"id":39632625},{"atb":[[3.9,0]],"id":39059999},{"atb":[[3.35,0]],"id":28753299}],"con":true,"img":false}]}
{"op":"mcm","clk":"5321497887","pt":1646310319120,"mc":[{"id":"1.195532878","rc":[{"atb":[[2.66,6.75]],"id":40452329},{"atb":[[3.55,4.39]],"id":28753299}],"con":true,"img":false}]}
{"op":"mcm","clk":"5321497896","pt":1646310319223,"mc":[{"id":"1.195532878","rc":[{"atb":[[4.2,3.5]],"id":39059999}],"con":true,"img":false}]}
{"op":"mcm","clk":"5321497904","pt":1646310319326,"mc":[{"id":"1.195532878","rc":[{"atb":[[2.74,6.44]],"id":39632625}],"con":true,"img":false}]}
{"op":"mcm","clk":"5321497913","pt":1646310319431,"mc":[{"id":"1.195532878","rc":[{"atb":[[2.9,5.89]],"id":38251452}],"con":true,"img":false}]}
{"op":"mcm","clk":"5321500520","pt":1646310348838,"mc":[{"id":"1.195532878","rc":[{"atl":[[4.3,0]],"id":41555107}],"con":true,"img":false}]}
{"op":"mcm","clk":"5321500531","pt":1646310348942,"mc":[{"id":"1.195532878","rc":[{"atl":[[4.9,1]],"id":41555107}],"con":true,"img":false}]}
{"op":"mcm","clk":"5321517487","pt":1646310566413,"mc":[{"id":"1.195532878","rc":[{"atb":[[2.62,0]],"id":41555107},{"spn":4.4,"spf":1.0,"id":41555107},{"atb":[[2.62,0]],"id":40452329},{"atb":[[2.86,0]],"id":38251452},{"atb":[[2.7,0]],"id":39632625},{"atb":[[4,0]],"id":39059999},{"atb":[[3.45,0]],"id":28753299}],"con":true,"img":false}]}
{"op":"mcm","clk":"5321518520","pt":1646310579305,"mc":[{"id":"1.195532878","rc":[{"atb":[[2.78,6.98]],"id":39632625}],"con":true,"img":false}]}
{"op":"mcm","clk":"5321518528","pt":1646310579413,"mc":[{"id":"1.195532878","rc":[{"atb":[[2.7,7.3]],"id":40452329}],"con":true,"img":false}]}
{"op":"mcm","clk":"5321518545","pt":1646310579620,"mc":[{"id":"1.195532878","rc":[{"atb":[[3.65,4.68]],"id":28753299}],"con":true,"img":false}]}
{"op":"mcm","clk":"5321518557","pt":1646310579720,"mc":[{"id":"1.195532878","rc":[{"atb":[[2.94,6.4]],"id":38251452}],"con":true,"img":false}]}
{"op":"mcm","clk":"5321518572","pt":1646310579928,"mc":[{"id":"1.195532878","rc":[{"atb":[[2.7,7.3]],"id":41555107}],"con":true,"img":false}]}
{"op":"mcm","clk":"5321518582","pt":1646310580135,"mc":[{"id":"1.195532878","rc":[{"atb":[[4.4,3.65]],"id":39059999}],"con":true,"img":false}]}
{"op":"mcm","clk":"5321541491","pt":1646310800759,"mc":[{"id":"1.195532878","rc":[{"atb":[[2.66,0]],"id":41555107},{"atb":[[2.66,0]],"id":40452329},{"atb":[[2.9,0]],"id":38251452},{"atb":[[2.74,0]],"id":39632625},{"atb":[[4.2,0]],"id":39059999},{"atb":[[3.55,0]],"id":28753299}],"con":true,"img":false}]}
{"op":"mcm","clk":"5321541832","pt":1646310803450,"mc":[{"id":"1.195532878","rc":[{"atb":[[2.98,5.66]],"id":38251452},{"atb":[[3.75,4.07]],"id":28753299}],"con":true,"img":false}]}
{"op":"mcm","clk":"5321541854","pt":1646310803659,"mc":[{"id":"1.195532878","rc":[{"atb":[[2.74,6.44]],"id":41555107},{"atb":[[2.74,6.44]],"id":40452329}],"con":true,"img":false}]}
{"op":"mcm","clk":"5321541862","pt":1646310803768,"mc":[{"id":"1.195532878","rc":[{"atb":[[2.82,6.15]],"id":39632625}],"con":true,"img":false}]}
{"op":"mcm","clk":"5321541874","pt":1646310803821,"mc":[{"id":"1.195532878","rc":[{"atb":[[4.6,3.11]],"id":39059999}],"con":true,"img":false}]}
{"op":"mcm","clk":"5321568534","pt":1646311049609,"mc":[{"id":"1.195532878","rc":[{"atb":[[2.7,0]],"id":41555107},{"atb":[[2.7,0]],"id":40452329},{"atb":[[2.94,0]],"id":38251452},{"atb":[[2.78,0]],"id":39632625},{"atb":[[4.4,0]],"id":39059999},{"atb":[[3.65,0]],"id":28753299}],"con":true,"img":false}]}
{"op":"mcm","clk":"5321569673","pt":1646311062512,"mc":[{"id":"1.195532878","rc":[{"atb":[[2.86,6.67]],"id":39632625}],"con":true,"img":false}]}
{"op":"mcm","clk":"5321569695","pt":1646311062819,"mc":[{"id":"1.195532878","rc":[{"atb":[[2.78,6.98]],"id":41555107}],"con":true,"img":false}]}
{"op":"mcm","clk":"5321569739","pt":1646311063435,"mc":[{"id":"1.195532878","rc":[{"atb":[[2.78,6.98]],"id":40452329},{"atb":[[4.8,3.27]],"id":39059999}],"con":true,"img":false}]}
{"op":"mcm","clk":"5321569764","pt":1646311063696,"mc":[{"id":"1.195532878","rc":[{"atb":[[3.05,6.06]],"id":38251452}],"con":true,"img":false}]}
{"op":"mcm","clk":"5321569770","pt":1646311063798,"mc":[{"id":"1.195532878","rc":[{"atb":[[3.85,4.35]],"id":28753299}],"con":true,"img":false}]}
{"op":"mcm","clk":"5321588821","pt":1646311284644,"mc":[{"id":"1.195532878","rc":[{"atb":[[2.74,0]],"id":41555107},{"atb":[[2.74,0]],"id":40452329},{"atb":[[2.98,0]],"id":38251452},{"atb":[[2.82,0]],"id":39632625},{"atb":[[4.6,0]],"id":39059999},{"atb":[[3.75,0]],"id":28753299}],"con":true,"img":false}]}
{"op":"mcm","clk":"5321589076","pt":1646311287417,"mc":[{"id":"1.195532878","rc":[{"atb":[[2.9,5.89]],"id":39632625}],"con":true,"img":false}]}
{"op":"mcm","clk":"5321589094","pt":1646311287523,"mc":[{"id":"1.195532878","rc":[{"atb":[[3.95,3.79]],"id":28753299}],"con":true,"img":false}]}
{"op":"mcm","clk":"5321589118","pt":1646311287738,"mc":[{"id":"1.195532878","rc":[{"atb":[[2.82,6.15]],"id":41555107},{"atb":[[2.82,6.15]],"id":40452329}],"con":true,"img":false}]}
{"op":"mcm","clk":"5321589140","pt":1646311287970,"mc":[{"id":"1.195532878","rc":[{"atb":[[3.15,5.21]],"id":38251452}],"con":true,"img":false}]}
{"op":"mcm","clk":"5321617159","pt":1646311586628,"mc":[{"id":"1.195532878","rc":[{"atb":[[2.78,0]],"id":41555107},{"atb":[[2.78,0]],"id":40452329},{"atb":[[3.05,0]],"id":38251452},{"atb":[[2.86,0]],"id":39632625},{"atb":[[4.8,0]],"id":39059999},{"atb":[[3.85,0]],"id":28753299}],"con":true,"img":false}]}
{"op":"mcm","clk":"5321617249","pt":1646311587862,"mc":[{"id":"1.195532878","rc":[{"atb":[[3.55,4.39]],"id":39059999}],"con":true,"img":false}]}
{"op":"mcm","clk":"5321619061","pt":1646311606575,"mc":[{"id":"1.195532878","rc":[{"atb":[[4.1,4]],"id":28753299}],"con":true,"img":false}]}
{"op":"mcm","clk":"5321619094","pt":1646311606789,"mc":[{"id":"1.195532878","rc":[{"atb":[[2.86,6.67]],"id":41555107}],"con":true,"img":false}]}
{"op":"mcm","clk":"5321619134","pt":1646311607095,"mc":[{"id":"1.195532878","rc":[{"atb":[[2.86,6.67]],"id":40452329},{"atb":[[3.25,5.52]],"id":38251452}],"con":true,"img":false}]}
{"op":"mcm","clk":"5321619173","pt":1646311607402,"mc":[{"id":"1.195532878","rc":[{"atb":[[3.65,4.68]],"id":39059999}],"con":true,"img":false}]}
{"op":"mcm","clk":"5321619224","pt":1646311607677,"mc":[{"id":"1.195532878","rc":[{"atb":[[2.94,6.4]],"id":39632625}],"con":true,"img":false}]}
{"op":"mcm","clk":"5321640742","pt":1646311819916,"mc":[{"id":"1.195532878","rc":[{"atb":[[2.82,0]],"id":41555107},{"atb":[[2.82,0]],"id":40452329},{"atb":[[3.15,0]],"id":38251452},{"atb":[[2.9,0]],"id":39632625},{"atb":[[3.95,0]],"id":28753299}],"con":true,"img":false}]}
{"op":"mcm","clk":"5321641324","pt":1646311823008,"mc":[{"id":"1.195532878","rc":[{"atb":[[2.9,5.89]],"id":41555107}],"con":true,"img":false}]}
{"op":"mcm","clk":"5321641336","pt":1646311823105,"mc":[{"id":"1.195532878","rc":[{"atb":[[3.35,4.76]],"id":38251452},{"atb":[[4.3,3.4]],"id":28753299}],"con":true,"img":false}]}
{"op":"mcm","clk":"5321641406","pt":1646311823422,"mc":[{"id":"1.195532878","rc":[{"atb":[[2.98,5.66]],"id":39632625}],"con":true,"img":false}]}
{"op":"mcm","clk":"5321641438","pt":1646311823651,"mc":[{"id":"1.195532878","rc":[{"atb":[[2.9,5.89]],"id":40452329}],"con":true,"img":false}]}
{"op":"mcm","clk":"5321644348","pt":1646311841569,"mc":[{"id":"1.195532878","rc":[{"atb":[[3.55,0]],"id":39059999}],"con":true,"img":false}]}
{"op":"mcm","clk":"5321644751","pt":1646311843853,"mc":[{"id":"1.195532878","rc":[{"atb":[[3.75,4.07]],"id":39059999}],"con":true,"img":false}]}
{"op":"mcm","clk":"5321673117","pt":1646312090752,"mc":[{"id":"1.195532878","rc":[{"atb":[[2.86,0]],"id":41555107},{"atb":[[2.86,0]],"id":40452329},{"atb":[[3.25,0]],"id":38251452},{"atb":[[2.94,0]],"id":39632625},{"atb":[[3.65,0]],"id":39059999},{"atb":[[4.1,0]],"id":28753299}],"con":true,"img":false}]}
{"op":"mcm","clk":"5321674745","pt":1646312107583,"mc":[{"id":"1.195532878","rc":[{"atb":[[2.62,7.67]],"id":38251452}],"con":true,"img":false}]}
{"op":"mcm","clk":"5321674782","pt":1646312107989,"mc":[{"id":"1.195532878","rc":[{"atb":[[4.5,3.55]],"id":28753299}],"con":true,"img":false}]}
{"op":"mcm","clk":"5321674800","pt":1646312108199,"mc":[{"id":"1.195532878","rc":[{"atb":[[2.94,6.4]],"id":40452329}],"con":true,"img":false}]}
{"op":"mcm","clk":"5321674810","pt":1646312108260,"mc":[{"id":"1.195532878","rc":[{"atb":[[2.94,6.4]],"id":41555107}],"con":true,"img":false}]}
{"op":"mcm","clk":"5321674835","pt":1646312108574,"mc":[{"id":"1.195532878","rc":[{"atb":[[3.05,6.06]],"id":39632625}],"con":true,"img":false}]}
{"op":"mcm","clk":"5321674892","pt":1646312109191,"mc":[{"id":"1.195532878","rc":[{"atb":[[3.85,4.35]],"id":39059999}],"con":true,"img":false}]}
{"op":"mcm","clk":"5321675417","pt":1646312115795,"mc":[{"id":"1.195532878","rc":[{"atb":[[2.58,0]],"id":41555107}],"con":true,"img":false}]}
{"op":"mcm","clk":"5321675427","pt":1646312115896,"mc":[{"id":"1.195532878","rc":[{"atb":[[2.78,2]],"id":41555107}],"con":true,"img":false}]}
{"op":"mcm","clk":"5321692935","pt":1646312324676,"mc":[{"id":"1.195532878","rc":[{"atb":[[2.9,0]],"id":41555107},{"atb":[[2.9,0]],"id":40452329},{"atb":[[3.35,0]],"id":38251452},{"atb":[[2.98,0]],"id":39632625},{"atb":[[3.75,0]],"id":39059999},{"atb":[[4.3,0]],"id":28753299}],"con":true,"img":false}]}
{"op":"mcm","clk":"5321693388","pt":1646312329700,"mc":[{"id":"1.195532878","rc":[{"atb":[[4.7,3.02]],"id":28753299}],"con":true,"img":false}]}
{"op":"mcm","clk":"5321693400","pt":1646312329804,"mc":[{"id":"1.195532878","rc":[{"atb":[[2.82,6.15]],"id":41555107}],"con":true,"img":false}]}
{"op":"mcm","clk":"5321693413","pt":1646312330000,"mc":[{"id":"1.195532878","rc":[{"atb":[[3.15,5.21]],"id":39632625}],"con":true,"img":false}]}
{"op":"mcm","clk":"5321693421","pt":1646312330107,"mc":[{"id":"1.195532878","rc":[{"atb":[[2.4,8]],"id":40452329}],"con":true,"img":false}]}
{"op":"mcm","clk":"5321693442","pt":1646312330315,"mc":[{"id":"1.195532878","rc":[{"atb":[[3.95,3.79]],"id":39059999}],"con":true,"img":false}]}
{"op":"mcm","clk":"5321693471","pt":1646312330587,"mc":[{"id":"1.195532878","rc":[{"atb":[[2.66,6.75]],"id":38251452}],"con":true,"img":false}]}
{"op":"mcm","clk":"5321715403","pt":1646312564121,"mc":[{"id":"1.195532878","rc":[{"atb":[[2.82,6.16],[2.2,12.66],[2.94,0]],"id":41555107},{"atb":[[2.4,8],[2.94,0],[2.1,13.16]],"id":40452329},{"atb":[[2.66,6.75],[2.62,7.66],[2.08,12.17]],"id":38251452},{"atb":[[3.15,5.21],[3.05,0],[2.08,11.3]],"id":39632625},{"atb":[[3.85,0],[2.02,10.13],[3.95,3.79]],"id":39059999},{"atb":[[4.5,0],[2.06,11.19],[4.7,3.02]],"id":28753299}],"con":true,"img":false}]}
{"op":"mcm","clk":"5321717077","pt":1646312583043,"mc":[{"id":"1.195532878","rc":[{"atb":[[2.62,0]],"id":38251452}],"con":true,"img":false}]}
{"op":"mcm","clk":"5321717085","pt":1646312583137,"mc":[{"id":"1.195532878","rc":[{"atb":[[2.44,8.62]],"id":40452329}],"con":true,"img":false}]}
{"op":"mcm","clk":"5321717098","pt":1646312583343,"mc":[{"id":"1.195532878","rc":[{"atb":[[2.48,8.39]],"id":39632625}],"con":true,"img":false}]}
{"op":"mcm","clk":"5321717128","pt":1646312583653,"mc":[{"id":"1.195532878","rc":[{"atb":[[4.1,4]],"id":39059999}],"con":true,"img":false}]}
{"op":"mcm","clk":"5321717137","pt":1646312583756,"mc":[{"id":"1.195532878","rc":[{"atb":[[2.86,6.67]],"id":41555107}],"con":true,"img":false}]}
{"op":"mcm","clk":"5321718998","pt":1646312604725,"mc":[{"id":"1.195532878","rc":[{"atb":[[2.7,7.3]],"id":38251452}],"con":true,"img":false}]}
{"op":"mcm","clk":"5321739002","pt":1646312797356,"mc":[{"id":"1.195532878","rc":[{"atb":[[3.15,0]],"id":39632625},{"atb":[[3.95,0]],"id":39059999},{"atb":[[4.7,0]],"id":28753299}],"con":true,"img":false}]}
{"op":"mcm","clk":"5321739364","pt":1646312801854,"mc":[{"id":"1.195532878","rc":[{"atb":[[3.05,6.06]],"id":28753299}],"con":true,"img":false}]}
{"op":"mcm","clk":"5321739581","pt":1646312804247,"mc":[{"id":"1.195532878","rc":[{"atb":[[2.52,7.37]],"id":39632625}],"con":true,"img":false}]}
{"op":"mcm","clk":"5321739603","pt":1646312804557,"mc":[{"id":"1.195532878","rc":[{"atb":[[4.3,3.4]],"id":39059999}],"con":true,"img":false}]}
{"op":"mcm","clk":"5321739620","pt":1646312804764,"mc":[{"id":"1.195532878","rc":[{"atb":[[3.15,5.21]],"id":28753299}],"con":true,"img":false}]}
{"op":"mcm","clk":"5321741214","pt":1646312817849,"mc":[{"id":"1.195532878","rc":[{"atb":[[2.82,0]],"id":41555107},{"atb":[[2.4,0]],"id":40452329},{"atb":[[2.66,0]],"id":38251452}],"con":true,"img":false}]}
{"op":"mcm","clk":"5321741513","pt":1646312820658,"mc":[{"id":"1.195532878","rc":[{"atb":[[2.74,6.44]],"id":38251452}],"con":true,"img":false}]}
{"op":"mcm","clk":"5321741524","pt":1646312820761,"mc":[{"id":"1.195532878","rc":[{"atb":[[2.48,7.58]],"id":40452329}],"con":true,"img":false}]}
{"op":"mcm","clk":"5321741535","pt":1646312820863,"mc":[{"id":"1.195532878","rc":[{"atb":[[2.9,5.89]],"id":41555107}],"con":true,"img":false}]}
{"op":"mcm","clk":"5321768434","pt":1646313040990,"mc":[{"id":"1.195532878","rc":[{"atb":[[4.1,0]],"id":39059999}],"con":true,"img":false}]}
{"op":"mcm","clk":"5321770487","pt":1646313058575,"mc":[{"id":"1.195532878","rc":[{"atb":[[4.5,3.55]],"id":39059999}],"con":true,"img":false}]}
{"op":"mcm","clk":"5321770538","pt":1646313058987,"mc":[{"id":"1.195532878","rc":[{"atb":[[2.48,0]],"id":39632625},{"atb":[[3.05,0]],"id":28753299}],"con":true,"img":false}]}
{"op":"mcm","clk":"5321772147","pt":1646313073633,"mc":[{"id":"1.195532878","rc":[{"atb":[[2.86,0]],"id":41555107},{"atb":[[2.44,0]],"id":40452329},{"atb":[[2.7,0]],"id":38251452}],"con":true,"img":false}]}
{"op":"mcm","clk":"5321772176","pt":1646313073942,"mc":[{"id":"1.195532878","rc":[{"atb":[[3.25,5.52]],"id":28753299}],"con":true,"img":false}]}
{"op":"mcm","clk":"5321772188","pt":1646313074045,"mc":[{"id":"1.195532878","rc":[{"atb":[[2.56,7.96]],"id":39632625}],"con":true,"img":false}]}
{"op":"mcm","clk":"5321773626","pt":1646313088359,"mc":[{"id":"1.195532878","rc":[{"atb":[[2.52,8.17]],"id":40452329}],"con":true,"img":false}]}
{"op":"mcm","clk":"5321773639","pt":1646313088466,"mc":[{"id":"1.195532878","rc":[{"atb":[[2.78,6.97]],"id":38251452}],"con":true,"img":false}]}
{"op":"mcm","clk":"5321773663","pt":1646313088761,"mc":[{"id":"1.195532878","rc":[{"atb":[[2.94,6.4]],"id":41555107}],"con":true,"img":false}]}
{"op":"mcm","clk":"5321794512","pt":1646313275272,"mc":[{"id":"1.195532878","rc":[{"atb":[[4.3,0]],"id":39059999}],"con":true,"img":false}]}
{"op":"mcm","clk":"5321794772","pt":1646313278375,"mc":[{"id":"1.195532878","rc":[{"atb":[[4.7,3.02]],"id":39059999}],"con":true,"img":false}]}
{"op":"mcm","clk":"5321796197","pt":1646313293271,"mc":[{"id":"1.195532878","rc":[{"atb":[[2.52,0]],"id":39632625},{"atb":[[3.15,0]],"id":28753299}],"con":true,"img":false}]}
{"op":"mcm","clk":"5321797069","pt":1646313302566,"mc":[{"id":"1.195532878","rc":[{"atb":[[2.6,7.01]],"id":39632625},{"atb":[[3.35,4.76]],"id":28753299}],"con":true,"img":false}]}
{"op":"mcm","clk":"5321797699","pt":1646313308500,"mc":[{"id":"1.195532878","rc":[{"atb":[[2.9,0]],"id":41555107},{"atb":[[2.48,0]],"id":40452329},{"atb":[[2.74,0]],"id":38251452}],"con":true,"img":false}]}
{"op":"mcm","clk":"5321798180","pt":1646313314214,"mc":[{"id":"1.195532878","rc":[{"atb":[[2.82,6.16]],"id":41555107}],"con":true,"img":false}]}
{"op":"mcm","clk":"5321798192","pt":1646313314319,"mc":[{"id":"1.195532878","rc":[{"atb":[[2.56,7.19]],"id":40452329}],"con":true,"img":false}]}
{"op":"mcm","clk":"5321798228","pt":1646313314682,"mc":[{"id":"1.195532878","rc":[{"atb":[[2.82,6.16]],"id":38251452}],"con":true,"img":false}]}
{"op":"mcm","clk":"5321826013","pt":1646313513770,"mc":[{"id":"1.195532878","rc":[{"atb":[[4.5,0]],"id":39059999}],"con":true,"img":false}]}
{"op":"mcm","clk":"5321827618","pt":1646313530792,"mc":[{"id":"1.195532878","rc":[{"atb":[[2.56,0]],"id":39632625},{"atb":[[3.25,0]],"id":28753299}],"con":true,"img":false}]}
{"op":"mcm","clk":"5321829074","pt":1646313546799,"mc":[{"id":"1.195532878","rc":[{"atb":[[2.64,7.57]],"id":39632625}],"con":true,"img":false}]}
{"op":"mcm","clk":"5321829087","pt":1646313546904,"mc":[{"id":"1.195532878","rc":[{"atb":[[3.45,5.06]],"id":28753299}],"con":true,"img":false}]}
{"op":"mcm","clk":"5321829130","pt":1646313547220,"mc":[{"id":"1.195532878","rc":[{"atb":[[2.94,0]],"id":41555107},{"atb":[[2.52,0]],"id":40452329},{"atb":[[2.78,0]],"id":38251452}],"con":true,"img":false}]}
{"op":"mcm","clk":"5321830608","pt":1646313561751,"mc":[{"id":"1.195532878","rc":[{"atb":[[2.86,6.67]],"id":38251452}],"con":true,"img":false}]}
{"op":"mcm","clk":"5321830641","pt":1646313561962,"mc":[{"id":"1.195532878","rc":[{"atb":[[2.86,6.67]],"id":41555107}],"con":true,"img":false}]}
{"op":"mcm","clk":"5321830652","pt":1646313562061,"mc":[{"id":"1.195532878","rc":[{"atb":[[2.6,7.76]],"id":40452329}],"con":true,"img":false}]}
{"op":"mcm","clk":"5321850404","pt":1646313747016,"mc":[{"id":"1.195532878","rc":[{"atb":[[4.7,0]],"id":39059999}],"con":true,"img":false}]}
{"op":"mcm","clk":"5321850782","pt":1646313750690,"mc":[{"id":"1.195532878","rc":[{"atb":[[3.55,4.39]],"id":39059999}],"con":true,"img":false}]}
{"op":"mcm","clk":"5321851156","pt":1646313754598,"mc":[{"id":"1.195532878","rc":[{"atb":[[3.65,4.68]],"id":39059999}],"con":true,"img":false}]}
{"op":"mcm","clk":"5321852488","pt":1646313767908,"mc":[{"id":"1.195532878","rc":[{"atb":[[2.6,0]],"id":39632625},{"atb":[[3.35,0]],"id":28753299}],"con":true,"img":false}]}
{"op":"mcm","clk":"5321852729","pt":1646313770783,"mc":[{"id":"1.195532878","rc":[{"atb":[[2.68,6.67]],"id":39632625}],"con":true,"img":false}]}
{"op":"mcm","clk":"5321852735","pt":1646313770887,"mc":[{"id":"1.195532878","rc":[{"atb":[[3.55,4.39]],"id":28753299}],"con":true,"img":false}]}
{"op":"mcm","clk":"5321853642","pt":1646313780118,"mc":[{"id":"1.195532878","rc":[{"atb":[[2.56,0]],"id":40452329},{"atb":[[2.82,0]],"id":38251452}],"con":true,"img":false}]}
{"op":"mcm","clk":"5321854027","pt":1646313783917,"mc":[{"id":"1.195532878","rc":[{"atb":[[2.9,5.89]],"id":38251452}],"con":true,"img":false}]}
{"op":"mcm","clk":"5321854048","pt":1646313784075,"mc":[{"id":"1.195532878","rc":[{"atb":[[2.64,6.84]],"id":40452329}],"con":true,"img":false}]}
{"op":"mcm","clk":"5321855241","pt":1646313797900,"mc":[{"id":"1.195532878","rc":[{"atb":[[2.82,0]],"id":41555107}],"con":true,"img":false}]}
{"op":"mcm","clk":"5321855596","pt":1646313801129,"mc":[{"id":"1.195532878","rc":[{"atb":[[2.9,5.89]],"id":41555107}],"con":true,"img":false}]}
{"op":"mcm","clk":"5321872516","pt":1646313987523,"mc":[{"id":"1.195532878","rc":[{"atb":[[3.55,0]],"id":39059999}],"con":true,"img":false}]}
{"op":"mcm","clk":"5321872906","pt":1646313993651,"mc":[{"id":"1.195532878","rc":[{"atb":[[3.75,4.07]],"id":39059999}],"con":true,"img":false}]}
{"op":"mcm","clk":"5321873958","pt":1646314007274,"mc":[{"id":"1.195532878","rc":[{"atb":[[2.64,0]],"id":39632625},{"atb":[[3.45,0]],"id":28753299}],"con":true,"img":false}]}
{"op":"mcm","clk":"5321875538","pt":1646314026389,"mc":[{"id":"1.195532878","rc":[{"atb":[[2.6,0]],"id":40452329},{"atb":[[2.86,0]],"id":38251452}],"con":true,"img":false}]}
{"op":"mcm","clk":"5321875545","pt":1646314026492,"mc":[{"id":"1.195532878","rc":[{"atb":[[3.65,4.68]],"id":28753299}],"con":true,"img":false}]}
{"op":"mcm","clk":"5321875562","pt":1646314026700,"mc":[{"id":"1.195532878","rc":[{"atb":[[2.72,7.21]],"id":39632625}],"con":true,"img":false}]}
{"op":"mcm","clk":"5321877169","pt":1646314047295,"mc":[{"id":"1.195532878","rc":[{"atb":[[2.86,0]],"id":41555107}],"con":true,"img":false}]}
{"op":"mcm","clk":"5321877226","pt":1646314047933,"mc":[{"id":"1.195532878","rc":[{"atb":[[2.68,7.39]],"id":40452329}],"con":true,"img":false}]}
{"op":"mcm","clk":"5321877237","pt":1646314048085,"mc":[{"id":"1.195532878","rc":[{"atb":[[2.94,6.4]],"id":38251452}],"con":true,"img":false}]}
{"op":"mcm","clk":"5321878828","pt":1646314068936,"mc":[{"id":"1.195532878","rc":[{"atb":[[2.94,6.4]],"id":41555107}],"con":true,"img":false}]}
{"op":"mcm","clk":"5321891852","pt":1646314224261,"mc":[{"id":"1.195532878","rc":[{"atb":[[3.65,0]],"id":39059999}],"con":true,"img":false}]}
{"op":"mcm","clk":"5321893304","pt":1646314239675,"mc":[{"id":"1.195532878","rc":[{"atb":[[3.85,4.35]],"id":39059999}],"con":true,"img":false}]}
{"op":"mcm","clk":"5321893386","pt":1646314240761,"mc":[{"id":"1.195532878","rc":[{"atb":[[2.68,0]],"id":39632625},{"atb":[[3.55,0]],"id":28753299}],"con":true,"img":false}]}
{"op":"mcm","clk":"5321893724","pt":1646314244703,"mc":[{"id":"1.195532878","rc":[{"atb":[[2.76,6.36]],"id":39632625}],"con":true,"img":false}]}
{"op":"mcm","clk":"5321893733","pt":1646314244804,"mc":[{"id":"1.195532878","rc":[{"atb":[[3.75,4.07]],"id":28753299}],"con":true,"img":false}]}
{"op":"mcm","clk":"5321895077","pt":1646314260006,"mc":[{"id":"1.195532878","rc":[{"atb":[[2.64,0]],"id":40452329},{"atb":[[2.9,0]],"id":38251452}],"con":true,"img":false}]}
{"op":"mcm","clk":"5321895453","pt":1646314265191,"mc":[{"id":"1.195532878","rc":[{"atb":[[2.72,6.51]],"id":40452329}],"con":true,"img":false}]}
{"op":"mcm","clk":"5321895469","pt":1646314265397,"mc":[{"id":"1.195532878","rc":[{"atb":[[2.98,5.66]],"id":38251452}],"con":true,"img":false}]}
{"op":"mcm","clk":"5321896454","pt":1646314280052,"mc":[{"id":"1.195532878","rc":[{"atb":[[2.9,0]],"id":41555107}],"con":true,"img":false}]}
{"op":"mcm","clk":"5321896704","pt":1646314282909,"mc":[{"id":"1.195532878","rc":[{"atb":[[2.82,6.16]],"id":41555107}],"con":true,"img":false}]}
{"op":"mcm","clk":"5321911344","pt":1646314460354,"mc":[{"id":"1.195532878","rc":[{"atb":[[3.75,0]],"id":39059999}],"con":true,"img":false}]}
{"op":"mcm","clk":"5321911610","pt":1646314463688,"mc":[{"id":"1.195532878","rc":[{"atb":[[3.95,3.79]],"id":39059999}],"con":true,"img":false}]}
{"op":"mcm","clk":"5321929302","pt":1646314631708,"mc":[{"id":"1.195532878","rc":[{"atb":[[2.94,0]],"id":41555107},{"atb":[[2.68,0]],"id":40452329},{"atb":[[2.94,0]],"id":38251452},{"atb":[[2.72,0]],"id":39632625},{"atb":[[3.65,0]],"id":28753299}],"con":true,"img":false}]}
{"op":"mcm","clk":"5321931218","pt":1646314648746,"mc":[{"id":"1.195532878","rc":[{"atb":[[2.8,6.89]],"id":39632625}],"con":true,"img":false}]}
{"op":"mcm","clk":"5321931253","pt":1646314649117,"mc":[{"id":"1.195532878","rc":[{"atb":[[3.05,6.06]],"id":38251452},{"atb":[[3.85,4.35]],"id":28753299}],"con":true,"img":false}]}
{"op":"mcm","clk":"5321931270","pt":1646314649322,"mc":[{"id":"1.195532878","rc":[{"atb":[[2.76,7.05]],"id":40452329}],"con":true,"img":false}]}
{"op":"mcm","clk":"5321931295","pt":1646314649632,"mc":[{"id":"1.195532878","rc":[{"atb":[[2.86,6.67]],"id":41555107}],"con":true,"img":false}]}
{"op":"mcm","clk":"5321937317","pt":1646314701328,"mc":[{"id":"1.195532878","rc":[{"atb":[[3.85,0]],"id":39059999},{"spn":5.11,"spf":1.0,"id":28753299}],"con":true,"img":false}]}
{"op":"mcm","clk":"5321939108","pt":1646314716794,"mc":[{"id":"1.195532878","rc":[{"atb":[[4.1,4]],"id":39059999}],"con":true,"img":false}]}
{"op":"mcm","clk":"5321955874","pt":1646314866789,"mc":[{"id":"1.195532878","rc":[{"atb":[[2.72,0]],"id":40452329},{"atb":[[2.98,0]],"id":38251452},{"atb":[[2.76,0]],"id":39632625},{"atb":[[3.75,0]],"id":28753299},{"spn":5.1,"spf":1.0,"id":28753299}],"con":true,"img":false}]}
{"op":"mcm","clk":"5321956507","pt":1646314873292,"mc":[{"id":"1.195532878","rc":[{"atb":[[2.84,6.09]],"id":39632625}],"con":true,"img":false}]}
{"op":"mcm","clk":"5321956519","pt":1646314873391,"mc":[{"id":"1.195532878","rc":[{"atb":[[3.15,5.21]],"id":38251452}],"con":true,"img":false}]}
{"op":"mcm","clk":"5321956529","pt":1646314873495,"mc":[{"id":"1.195532878","rc":[{"atb":[[3.95,3.79]],"id":28753299}],"con":true,"img":false}]}
{"op":"mcm","clk":"5321956560","pt":1646314873804,"mc":[{"id":"1.195532878","rc":[{"atb":[[2.8,6.22]],"id":40452329}],"con":true,"img":false}]}
{"op":"mcm","clk":"5321957840","pt":1646314887546,"mc":[{"id":"1.195532878","rc":[{"atb":[[2.82,0]],"id":41555107}],"con":true,"img":false}]}
{"op":"mcm","clk":"5321958096","pt":1646314890411,"mc":[{"id":"1.195532878","rc":[{"atb":[[2.9,5.89]],"id":41555107}],"con":true,"img":false}]}
{"op":"mcm","clk":"5321962245","pt":1646314935382,"mc":[{"id":"1.195532878","rc":[{"atb":[[3.95,0]],"id":39059999},{"spn":5.17,"spf":1.0,"id":28753299}],"con":true,"img":false}]}
{"op":"mcm","clk":"5321962617","pt":1646314938708,"mc":[{"id":"1.195532878","rc":[{"atb":[[4.3,3.4]],"id":39059999}],"con":true,"img":false}]}
{"op":"mcm","clk":"5321979276","pt":1646315110502,"mc":[{"id":"1.195532878","rc":[{"atb":[[2.76,0]],"id":40452329},{"atb":[[3.05,0]],"id":38251452},{"atb":[[2.8,0]],"id":39632625},{"atb":[[3.85,0]],"id":28753299},{"spn":5.1,"spf":1.0,"id":28753299}],"con":true,"img":false}]}
{"op":"mcm","clk":"5321981663","pt":1646315125673,"mc":[{"id":"1.195532878","rc":[{"atb":[[2.88,6.6]],"id":39632625}],"con":true,"img":false}]}
{"op":"mcm","clk":"5321981702","pt":1646315125876,"mc":[{"id":"1.195532878","rc":[{"atb":[[3.25,5.52]],"id":38251452}],"con":true,"img":false}]}
{"op":"mcm","clk":"5321981780","pt":1646315126294,"mc":[{"id":"1.195532878","rc":[{"atb":[[4.1,4]],"id":28753299}],"con":true,"img":false}]}
{"op":"mcm","clk":"5321981835","pt":1646315126704,"mc":[{"id":"1.195532878","rc":[{"atb":[[2.84,6.74]],"id":40452329}],"con":true,"img":false}]}
{"op":"mcm","clk":"5321983549","pt":1646315141593,"mc":[{"id":"1.195532878","rc":[{"atb":[[2.86,0]],"id":41555107}],"con":true,"img":false}]}
{"op":"mcm","clk":"5321985087","pt":1646315156016,"mc":[{"id":"1.195532878","rc":[{"atb":[[2.94,6.4]],"id":41555107}],"con":true,"img":false}]}
{"op":"mcm","clk":"5321988774","pt":1646315188986,"mc":[{"id":"1.195532878","rc":[{"atb":[[4.1,0]],"id":39059999},{"spn":5.25,"spf":1.0,"id":28753299}],"con":true,"img":false}]}
{"op":"mcm","clk":"5321990272","pt":1646315205809,"mc":[{"id":"1.195532878","rc":[{"atb":[[4.5,3.55]],"id":39059999}],"con":true,"img":false}]}
{"op":"mcm","clk":"5322005809","pt":1646315345159,"mc":[{"id":"1.195532878","rc":[{"atb":[[2.8,0]],"id":40452329},{"atb":[[3.15,0]],"id":38251452},{"atb":[[2.84,0]],"id":39632625},{"atb":[[3.95,0]],"id":28753299},{"spn":5.1,"spf":1.0,"id":28753299}],"con":true,"img":false}]}
{"op":"mcm","clk":"5322006069","pt":1646315347961,"mc":[{"id":"1.195532878","rc":[{"atb":[[2.92,5.83]],"id":39632625}],"con":true,"img":false}]}
{"op":"mcm","clk":"5322006079","pt":1646315348024,"mc":[{"id":"1.195532878","rc":[{"atb":[[3.35,4.76]],"id":38251452}],"con":true,"img":false}]}
{"op":"mcm","clk":"5322006090","pt":1646315348127,"mc":[{"id":"1.195532878","rc":[{"atb":[[4.3,3.4]],"id":28753299}],"con":true,"img":false}]}
{"op":"mcm","clk":"5322006099","pt":1646315348228,"mc":[{"id":"1.195532878","rc":[{"atb":[[2.88,5.96]],"id":40452329}],"con":true,"img":false}]}
{"op":"mcm","clk":"5322008765","pt":1646315376196,"mc":[{"id":"1.195532878","rc":[{"atb":[[2.9,0]],"id":41555107}],"con":true,"img":false}]}
{"op":"mcm","clk":"5322009450","pt":1646315381691,"mc":[{"id":"1.195532878","rc":[{"atb":[[2.82,6.16]],"id":41555107}],"con":true,"img":false}]}
{"op":"mcm","clk":"5322014715","pt":1646315426113,"mc":[{"id":"1.195532878","rc":[{"atb":[[4.3,0]],"id":39059999},{"spn":5.35,"spf":1.0,"id":28753299}],"con":true,"img":false}]}
{"op":"mcm","clk":"5322015007","pt":1646315429031,"mc":[{"id":"1.195532878","rc":[{"atb":[[4.7,3.02]],"id":39059999}],"con":true,"img":false}]}
{"op":"mcm","clk":"5322030971","pt":1646315605224,"mc":[{"id":"1.195532878","rc":[{"atb":[[2.84,0]],"id":40452329},{"atb":[[3.25,0]],"id":38251452},{"atb":[[2.88,0]],"id":39632625},{"atb":[[4.1,0]],"id":28753299},{"spn":5.1,"spf":1.0,"id":28753299}],"con":true,"img":false}]}
{"op":"mcm","clk":"5322032238","pt":1646315621038,"mc":[{"id":"1.195532878","rc":[{"atb":[[2.62,7.66]],"id":38251452}],"con":true,"img":false}]}
{"op":"mcm","clk":"5322032254","pt":1646315621299,"mc":[{"id":"1.195532878","rc":[{"atb":[[2.92,6.46]],"id":40452329}],"con":true,"img":false}]}
{"op":"mcm","clk":"5322032261","pt":1646315621396,"mc":[{"id":"1.195532878","rc":[{"atb":[[4.5,3.55]],"id":28753299}],"con":true,"img":false}]}
{"op":"mcm","clk":"5322032281","pt":1646315621712,"mc":[{"id":"1.195532878","rc":[{"atb":[[2.96,6.33]],"id":39632625}],"con":true,"img":false}]}
{"op":"mcm","clk":"5322033502","pt":1646315637116,"mc":[{"id":"1.195532878","rc":[{"atb":[[2.94,0]],"id":41555107}],"con":true,"img":false}]}
{"op":"mcm","clk":"5322034624","pt":1646315651262,"mc":[{"id":"1.195532878","rc":[{"atb":[[2.86,6.67]],"id":41555107}],"con":true,"img":false}]}
{"op":"mcm","clk":"5322036656","pt":1646315674550,"mc":[{"id":"1.195532878","rc":[{"atb":[[4.5,0]],"id":39059999},{"spn":5.47,"spf":1.0,"id":28753299}],"con":true,"img":false}]}
{"op":"mcm","clk":"5322050953","pt":1646315838241,"mc":[{"id":"1.195532878","rc":[{"atb":[[2.88,0]],"id":40452329},{"atb":[[3.35,0]],"id":38251452},{"atb":[[2.92,0]],"id":39632625},{"atb":[[4.3,0]],"id":28753299},{"spn":5.1,"spf":1.0,"id":28753299}],"con":true,"img":false}]}
{"op":"mcm","clk":"5322051204","pt":1646315841178,"mc":[{"id":"1.195532878","rc":[{"atb":[[2.66,6.75]],"id":38251452}],"con":true,"img":false}]}
{"op":"mcm","clk":"5322051212","pt":1646315841262,"mc":[{"id":"1.195532878","rc":[{"atb":[[2.96,5.71]],"id":40452329}],"con":true,"img":false}]}
{"op":"mcm","clk":"5322051237","pt":1646315841568,"mc":[{"id":"1.195532878","rc":[{"atb":[[4.7,3.02]],"id":28753299}],"con":true,"img":false}]}
{"op":"mcm","clk":"5322051254","pt":1646315841778,"mc":[{"id":"1.195532878","rc":[{"atb":[[3,5.6]],"id":39632625}],"con":true,"img":false}]}
{"op":"mcm","clk":"5322054475","pt":1646315883067,"mc":[{"id":"1.195532878","rc":[{"atb":[[2.82,0]],"id":41555107}],"con":true,"img":false}]}
{"op":"mcm","clk":"5322054672","pt":1646315885776,"mc":[{"id":"1.195532878","rc":[{"atb":[[2.9,5.89]],"id":41555107}],"con":true,"img":false}]}
{"op":"mcm","clk":"5322056384","pt":1646315907440,"mc":[{"id":"1.195532878","rc":[{"atb":[[4.7,0]],"id":39059999},{"spn":5.58,"spf":1.0,"id":28753299}],"con":true,"img":false}]}
{"op":"mcm","clk":"5322056535","pt":1646315909825,"mc":[{"id":"1.195532878","rc":[{"atb":[[3.55,4.86]],"id":39059999}],"con":true,"img":false}]}
{"op":"mcm","clk":"5322056565","pt":1646315910132,"mc":[{"id":"1.195532878","rc":[{"atb":[[3.55,9.26]],"id":39059999}],"con":true,"img":false}]}
{"op":"mcm","clk":"5322072105","pt":1646316084556,"mc":[{"id":"1.195532878","rc":[{"atb":[[2.92,0]],"id":40452329},{"atb":[[2.62,0]],"id":38251452},{"atb":[[2.96,0]],"id":39632625},{"atb":[[4.5,0]],"id":28753299},{"spn":5.1,"spf":1.0,"id":28753299}],"con":true,"img":false}]}
{"op":"mcm","clk":"5322073647","pt":1646316099155,"mc":[{"id":"1.195532878","rc":[{"atb":[[2.7,7.3]],"id":38251452}],"con":true,"img":false}]}
{"op":"mcm","clk":"5322073736","pt":1646316099877,"mc":[{"id":"1.195532878","rc":[{"atb":[[2.4,8.86]],"id":40452329}],"con":true,"img":false}]}
{"op":"mcm","clk":"5322073785","pt":1646316100451,"mc":[{"id":"1.195532878","rc":[{"atb":[[3.1,5.91]],"id":39632625}],"con":true,"img":false}]}
{"op":"mcm","clk":"5322076739","pt":1646316131120,"mc":[{"id":"1.195532878","rc":[{"atb":[[2.86,0]],"id":41555107}],"con":true,"img":false}]}
{"op":"mcm","clk":"5322078052","pt":1646316147431,"mc":[{"id":"1.195532878","rc":[{"atb":[[2.94,6.4]],"id":41555107}],"con":true,"img":false}]}
{"op":"mcm","clk":"5322081669","pt":1646316189190,"mc":[{"id":"1.195532878","rc":[{"atl":[[6.8,1.49],[4.9,0]],"id":41555107},{"trd":[[6.8,0.48]],"ltp":6.8,"tv":0.48,"id":41555107}],"con":true,"img":false}]}
{"op":"mcm","clk":"5322081677","pt":1646316189297,"mc":[{"id":"1.195532878","rc":[{"atb":[[3.95,2]],"id":41555107}],"con":true,"img":false}]}
{"op":"mcm","clk":"5322081692","pt":1646316189504,"mc":[{"id":"1.195532878","rc":[{"atb":[[2.78,0]],"id":41555107}],"con":true,"img":false}]}
{"op":"mcm","clk":"5322081703","pt":1646316189609,"mc":[{"id":"1.195532878","rc":[{"atb":[[3,2]],"id":41555107}],"con":true,"img":false}]}
{"op":"mcm","clk":"5322092414","pt":1646316318987,"mc":[{"id":"1.195532878","rc":[{"spn":5.37,"spf":1.0,"id":41555107},{"atb":[[2.96,0]],"id":40452329},{"atb":[[2.66,0]],"id":38251452},{"atb":[[3,0]],"id":39632625},{"atb":[[4.7,0]],"id":28753299}],"con":true,"img":false}]}
{"op":"mcm","clk":"5322092879","pt":1646316324794,"mc":[{"id":"1.195532878","rc":[{"atb":[[2.18,9.5]],"id":39632625}],"con":true,"img":false}]}
{"op":"mcm","clk":"5322092901","pt":1646316324962,"mc":[{"id":"1.195532878","rc":[{"atb":[[2.44,7.79]],"id":40452329},{"atb":[[2.74,6.44]],"id":38251452}],"con":true,"img":false}]}
{"op":"mcm","clk":"5322092923","pt":1646316325168,"mc":[{"id":"1.195532878","rc":[{"atb":[[2.58,7.09]],"id":28753299}],"con":true,"img":false}]}
{"op":"mcm","clk":"5322093545","pt":1646316331882,"mc":[{"id":"1.195532878","rc":[{"atb":[[2.62,7.66]],"id":28753299}],"con":true,"img":false}]}
{"op":"mcm","clk":"5322096737","pt":1646316363933,"mc":[{"id":"1.195532878","rc":[{"atb":[[2.9,0]],"id":41555107}],"con":true,"img":false}]}
{"op":"mcm","clk":"5322097030","pt":1646316366771,"mc":[{"id":"1.195532878","rc":[{"atb":[[2.98,5.66]],"id":41555107}],"con":true,"img":false}]}
{"op":"mcm","clk":"5322102917","pt":1646316427067,"mc":[{"id":"1.195532878","rc":[{"atb":[[3.55,4.86]],"id":39059999}],"con":true,"img":false}]}
{"op":"mcm","clk":"5322103176","pt":1646316429976,"mc":[{"id":"1.195532878","rc":[{"atb":[[3.65,4.23]],"id":39059999}],"con":true,"img":false}]}
{"op":"mcm","clk":"5322104457","pt":1646316441821,"mc":[{"id":"1.195532878","rc":[{"atb":[[2.4,0]],"id":40452329},{"atb":[[3.55,0]],"id":39059999}],"con":true,"img":false}]}
{"op":"mcm","clk":"5322105668","pt":1646316455415,"mc":[{"id":"1.195532878","rc":[{"atb":[[2.48,8.39]],"id":40452329}],"con":true,"img":false}]}
{"op":"mcm","clk":"5322105731","pt":1646316456097,"mc":[{"id":"1.195532878","rc":[{"atb":[[3.75,4.51]],"id":39059999}],"con":true,"img":false}]}
{"op":"mcm","clk":"5322109265","pt":1646316494593,"mc":[{"id":"1.195532878","rc":[{"atb":[[2.08,0]],"id":39632625}],"con":true,"img":false}]}
{"op":"mcm","clk":"5322109270","pt":1646316494657,"mc":[{"id":"1.195532878","rc":[{"atb":[[2.2,11.3]],"id":39632625}],"con":true,"img":false}]}
{"op":"mcm","clk":"5322115477","pt":1646316565154,"mc":[{"id":"1.195532878","rc":[{"atb":[[2.58,0]],"id":28753299}],"con":true,"img":false}]}
{"op":"mcm","clk":"5322115772","pt":1646316568356,"mc":[{"id":"1.195532878","rc":[{"atb":[[2.66,6.75]],"id":28753299}],"con":true,"img":false}]}
{"op":"mcm","clk":"5322115911","pt":1646316569975,"mc":[{"id":"1.195532878","rc":[{"atb":[[2.7,0]],"id":38251452},{"atb":[[3.1,0]],"id":39632625}],"con":true,"img":false}]}
{"op":"mcm","clk":"5322117294","pt":1646316586009,"mc":[{"id":"1.195532878","rc":[{"atb":[[2.24,10.01]],"id":39632625}],"con":true,"img":false}]}
{"op":"mcm","clk":"5322117370","pt":1646316586690,"mc":[{"id":"1.195532878","rc":[{"atb":[[2.78,6.97]],"id":38251452}],"con":true,"img":false}]}
{"op":"mcm","clk":"5322119975","pt":1646316614532,"mc":[{"id":"1.195532878","rc":[{"atb":[[2.94,0]],"id":41555107}],"con":true,"img":false}]}
{"op":"mcm","clk":"5322121024","pt":1646316626646,"mc":[{"id":"1.195532878","rc":[{"atb":[[2.24,10.01]],"id":41555107}],"con":true,"img":false}]}
{"op":"mcm","clk":"5322125346","pt":1646316673415,"mc":[{"id":"1.195532878","rc":[{"atb":[[2.44,0]],"id":40452329},{"atb":[[3.65,0]],"id":39059999}],"con":true,"img":false}]}
{"op":"mcm","clk":"5322125708","pt":1646316676699,"mc":[{"id":"1.195532878","rc":[{"atb":[[2.52,7.37]],"id":40452329}],"con":true,"img":false}]}
{"op":"mcm","clk":"5322125751","pt":1646316677114,"mc":[{"id":"1.195532878","rc":[{"atb":[[3.85,3.93]],"id":39059999}],"con":true,"img":false}]}
{"op":"mcm","clk":"5322130751","pt":1646316727578,"mc":[{"id":"1.195532878","rc":[{"atb":[[2.18,0]],"id":39632625}],"con":true,"img":false}]}
{"op":"mcm","clk":"5322131100","pt":1646316730953,"mc":[{"id":"1.195532878","rc":[{"atb":[[2.28,8.76]],"id":39632625}],"con":true,"img":false}]}
{"op":"mcm","clk":"5322136469","pt":1646316794395,"mc":[{"id":"1.195532878","rc":[{"atb":[[2.2,0]],"id":41555107},{"atb":[[2.2,0]],"id":39632625}],"con":true,"img":false}]}
{"op":"mcm","clk":"5322136479","pt":1646316794459,"mc":[{"id":"1.195532878","rc":[{"atb":[[2.26,12.66]],"id":41555107},{"atb":[[2.3,11.3]],"id":39632625}],"con":true,"img":false}]}
{"op":"mcm","clk":"5322137130","pt":1646316803079,"mc":[{"id":"1.195532878","rc":[{"atb":[[2.74,0]],"id":38251452}],"con":true,"img":false}]}
{"op":"mcm","clk":"5322137633","pt":1646316808972,"mc":[{"id":"1.195532878","rc":[{"atb":[[2.82,6.16]],"id":38251452}],"con":true,"img":false}]}
{"op":"mcm","clk":"5322141055","pt":1646316848051,"mc":[{"id":"1.195532878","rc":[{"atb":[[2.98,0]],"id":41555107}],"con":true,"img":false}]}
{"op":"mcm","clk":"5322141279","pt":1646316850791,"mc":[{"id":"1.195532878","rc":[{"atb":[[2.3,8.62]],"id":41555107}],"con":true,"img":false}]}
{"op":"mcm","clk":"5322141987","pt":1646316859299,"mc":[{"id":"1.195532878","rc":[{"atb":[[2.62,0]],"id":28753299}],"con":true,"img":false}]}
{"op":"mcm","clk":"5322143809","pt":1646316878819,"mc":[{"id":"1.195532878","rc":[{"atb":[[2.7,7.3]],"id":28753299}],"con":true,"img":false}]}
{"op":"mcm","clk":"5322147191","pt":1646316916184,"mc":[{"id":"1.195532878","rc":[{"atb":[[2.48,0]],"id":40452329},{"atb":[[3.75,0]],"id":39059999}],"con":true,"img":false}]}
{"op":"mcm","clk":"5322157169","pt":1646317028416,"mc":[{"id":"1.195532878","rc":[{"atb":[[2.28,0]],"id":39632625}],"con":true,"img":false}]}
{"op":"mcm","clk":"5322157473","pt":1646317031523,"mc":[{"id":"1.195532878","rc":[{"atb":[[2.34,8.36]],"id":39632625}],"con":true,"img":false}]}
{"op":"mcm","clk":"5322159505","pt":1646317054754,"mc":[{"id":"1.195532878","rc":[{"atb":[[2.24,0]],"id":39632625}],"con":true,"img":false}]}
{"op":"mcm","clk":"5322159521","pt":1646317055015,"mc":[{"id":"1.195532878","rc":[{"atb":[[3.95,4.2]],"id":39059999}],"con":true,"img":false}]}
{"op":"mcm","clk":"5322159545","pt":1646317055281,"mc":[{"id":"1.195532878","rc":[{"atb":[[2.56,7.96]],"id":40452329}],"con":true,"img":false}]}
{"op":"mcm","clk":"5322161043","pt":1646317071471,"mc":[{"id":"1.195532878","rc":[{"atb":[[2.38,8.99]],"id":39632625}],"con":true,"img":false}]}
{"op":"mcm","clk":"5322163024","pt":1646317092586,"mc":[{"id":"1.195532878","rc":[{"atb":[[2.66,0]],"id":28753299}],"con":true,"img":false}]}
{"op":"mcm","clk":"5322163217","pt":1646317094593,"mc":[{"id":"1.195532878","rc":[{"atb":[[2.26,0]],"id":41555107},{"atb":[[2.3,0]],"id":39632625}],"con":true,"img":false}]}
{"op":"mcm","clk":"5322163226","pt":1646317094697,"mc":[{"id":"1.195532878","rc":[{"atb":[[2.32,12.66]],"id":41555107},{"atb":[[2.36,11.3]],"id":39632625}],"con":true,"img":false}]}
{"op":"mcm","clk":"5322163259","pt":1646317095072,"mc":[{"id":"1.195532878","rc":[{"atb":[[2.74,6.44]],"id":28753299}],"con":true,"img":false}]}
{"op":"mcm","clk":"5322163285","pt":1646317095384,"mc":[{"id":"1.195532878","rc":[{"atb":[[2.24,0]],"id":41555107},{"atb":[[2.78,0]],"id":38251452}],"con":true,"img":false}]}
{"op":"mcm","clk":"5322164649","pt":1646317111032,"mc":[{"id":"1.195532878","rc":[{"atb":[[2.86,6.67]],"id":38251452}],"con":true,"img":false}]}
{"op":"mcm","clk":"5322164668","pt":1646317111349,"mc":[{"id":"1.195532878","rc":[{"atb":[[2.36,9.13]],"id":41555107}],"con":true,"img":false}]}
{"op":"mcm","clk":"5322168197","pt":1646317149052,"mc":[{"id":"1.195532878","rc":[{"atb":[[2.52,0]],"id":40452329},{"atb":[[3.85,0]],"id":39059999}],"con":true,"img":false}]}
{"op":"mcm","clk":"5322168453","pt":1646317151758,"mc":[{"id":"1.195532878","rc":[{"atb":[[2.6,7.01]],"id":40452329},{"atb":[[4.1,3.61]],"id":39059999}],"con":true,"img":false}]}
{"op":"mcm","clk":"5322176435","pt":1646317242799,"mc":[{"id":"1.195532878","rc":[{"atl":[[1000,2]],"id":39632625}],"con":true,"img":false}]}
{"op":"mcm","clk":"5322176541","pt":1646317244103,"mc":[{"id":"1.195532878","rc":[{"atl":[[1000,2.2]],"id":39632625}],"con":true,"img":false}]}
{"op":"mcm","clk":"5322176656","pt":1646317245512,"mc":[{"id":"1.195532878","rc":[{"atl":[[1000,2]],"id":39632625}],"con":true,"img":false}]}
{"op":"mcm","clk":"5322176661","pt":1646317245616,"mc":[{"id":"1.195532878","rc":[{"atl":[[9.4,0.2]],"id":39632625}],"con":true,"img":false}]}
{"op":"mcm","clk":"5322176757","pt":1646317246923,"mc":[{"id":"1.195532878","rc":[{"atl":[[1000,2]],"id":38251452}],"con":true,"img":false}]}
{"op":"mcm","clk":"5322176853","pt":1646317248225,"mc":[{"id":"1.195532878","rc":[{"atl":[[1000,2.2]],"id":38251452}],"con":true,"img":false}]}
{"op":"mcm","clk":"5322179152","pt":1646317275938,"mc":[{"id":"1.195532878","rc":[{"atl":[[1000,2]],"id":38251452}],"con":true,"img":false}]}
{"op":"mcm","clk":"5322179159","pt":1646317276041,"mc":[{"id":"1.195532878","rc":[{"atl":[[11.5,0.2]],"id":38251452}],"con":true,"img":false}]}
{"op":"mcm","clk":"5322179251","pt":1646317277344,"mc":[{"id":"1.195532878","rc":[{"atl":[[1000,2]],"id":28753299}],"con":true,"img":false}]}
{"op":"mcm","clk":"5322181617","pt":1646317305394,"mc":[{"id":"1.195532878","rc":[{"atb":[[2.34,0]],"id":39632625}],"con":true,"img":false}]}
{"op":"mcm","clk":"5322181889","pt":1646317308039,"mc":[{"id":"1.195532878","rc":[{"atb":[[2.42,7.89]],"id":39632625}],"con":true,"img":false}]}
{"op":"mcm","clk":"5322182514","pt":1646317314748,"mc":[{"id":"1.195532878","rc":[{"atl":[[1000,2.2]],"id":28753299}],"con":true,"img":false}]}
{"op":"mcm","clk":"5322182612","pt":1646317316056,"mc":[{"id":"1.195532878","rc":[{"atl":[[1000,2]],"id":28753299}],"con":true,"img":false}]}
{"op":"mcm","clk":"5322182622","pt":1646317316108,"mc":[{"id":"1.195532878","rc":[{"atl":[[16.5,0.2]],"id":28753299}],"con":true,"img":false}]}
{"op":"mcm","clk":"5322182732","pt":1646317317411,"mc":[{"id":"1.195532878","rc":[{"atl":[[1000,2]],"id":40452329}],"con":true,"img":false}]}
{"op":"mcm","clk":"5322182836","pt":1646317318768,"mc":[{"id":"1.195532878","rc":[{"atl":[[1000,2.2]],"id":40452329}],"con":true,"img":false}]}
{"op":"mcm","clk":"5322182935","pt":1646317320043,"mc":[{"id":"1.195532878","rc":[{"atl":[[1000,2]],"id":40452329}],"con":true,"img":false}]}
{"op":"mcm","clk":"5322182950","pt":1646317320146,"mc":[{"id":"1.195532878","rc":[{"atl":[[10.5,0.2]],"id":40452329}],"con":true,"img":false}]}
{"op":"mcm","clk":"5322183063","pt":1646317321457,"mc":[{"id":"1.195532878","rc":[{"atl":[[1000,2]],"id":41555107}],"con":true,"img":false}]}
{"op":"mcm","clk":"5322183188","pt":1646317322755,"mc":[{"id":"1.195532878","rc":[{"atl":[[1000,2.2]],"id":41555107}],"con":true,"img":false}]}
{"op":"mcm","clk":"5322183321","pt":1646317324164,"mc":[{"id":"1.195532878","rc":[{"atl":[[1000,2]],"id":41555107}],"con":true,"img":false}]}
{"op":"mcm","clk":"5322183334","pt":1646317324267,"mc":[{"id":"1.195532878","rc":[{"atl":[[9.4,0.2]],"id":41555107}],"con":true,"img":false}]}
{"op":"mcm","clk":"5322183450","pt":1646317325573,"mc":[{"id":"1.195532878","rc":[{"atl":[[1000,2]],"id":39059999}],"con":true,"img":false}]}
{"op":"mcm","clk":"5322183576","pt":1646317326941,"mc":[{"id":"1.195532878","rc":[{"atl":[[1000,2.2]],"id":39059999}],"con":true,"img":false}]}
{"op":"mcm","clk":"5322183700","pt":1646317328244,"mc":[{"id":"1.195532878","rc":[{"atl":[[1000,2]],"id":39059999}],"con":true,"img":false}]}
{"op":"mcm","clk":"5322183712","pt":1646317328348,"mc":[{"id":"1.195532878","rc":[{"atl":[[32,0.2]],"id":39059999}],"con":true,"img":false}]}
{"op":"mcm","clk":"5322183805","pt":1646317329343,"mc":[{"id":"1.195532878","rc":[{"atb":[[2.3,0]],"id":41555107},{"atb":[[2.82,0]],"id":38251452}],"con":true,"img":false}]}
{"op":"mcm","clk":"5322184116","pt":1646317332379,"mc":[{"id":"1.195532878","rc":[{"atb":[[2.4,8]],"id":41555107}],"con":true,"img":false}]}
{"op":"mcm","clk":"5322184194","pt":1646317333267,"mc":[{"id":"1.195532878","rc":[{"atb":[[2.9,5.89]],"id":38251452}],"con":true,"img":false}]}
{"op":"mcm","clk":"5322184485","pt":1646317336613,"mc":[{"id":"1.195532878","rc":[{"atb":[[2.7,0]],"id":28753299}],"con":true,"img":false}]}
{"op":"mcm","clk":"5322185518","pt":1646317347591,"mc":[{"id":"1.195532878","rc":[{"atb":[[2.38,0]],"id":39632625},{"atb":[[2.78,6.97]],"id":28753299}],"con":true,"img":false}]}
{"op":"mcm","clk":"5322186995","pt":1646317363619,"mc":[{"id":"1.195532878","rc":[{"atb":[[2.46,8.5]],"id":39632625}],"con":true,"img":false}]}
{"op":"mcm","clk":"5322191512","pt":1646317411991,"mc":[{"id":"1.195532878","rc":[{"atb":[[2.56,0]],"id":40452329},{"atb":[[3.95,0]],"id":39059999}],"con":true,"img":false}]}
{"op":"mcm","clk":"5322192402","pt":1646317421387,"mc":[{"id":"1.195532878","rc":[{"atb":[[2.64,7.57]],"id":40452329}],"con":true,"img":false}]}
{"op":"mcm","clk":"5322192425","pt":1646317421600,"mc":[{"id":"1.195532878","rc":[{"atb":[[4.3,3.76]],"id":39059999}],"con":true,"img":false}]}
{"op":"mcm","clk":"5322206121","pt":1646317570141,"mc":[{"id":"1.195532878","rc":[{"atb":[[2.74,0]],"id":28753299}],"con":true,"img":false}]}
{"op":"mcm","clk":"5322206390","pt":1646317573358,"mc":[{"id":"1.195532878","rc":[{"atb":[[2.82,6.16]],"id":28753299}],"con":true,"img":false}]}
{"op":"mcm","clk":"5322206624","pt":1646317575958,"mc":[{"id":"1.195532878","rc":[{"atb":[[2.36,0]],"id":41555107},{"atb":[[2.86,0]],"id":38251452}],"con":true,"img":false}]}
{"op":"mcm","clk":"5322207260","pt":1646317582585,"mc":[{"id":"1.195532878","rc":[{"atb":[[2.42,0]],"id":39632625}],"con":true,"img":false}]}
{"op":"mcm","clk":"5322207464","pt":1646317584787,"mc":[{"id":"1.195532878","rc":[{"atb":[[2.5,7.47]],"id":39632625}],"con":true,"img":false}]}
{"op":"mcm","clk":"5322207793","pt":1646317588159,"mc":[{"id":"1.195532878","rc":[{"atb":[[2.94,6.4]],"id":38251452}],"con":true,"img":false}]}
{"op":"mcm","clk":"5322207806","pt":1646317588362,"mc":[{"id":"1.195532878","rc":[{"atb":[[2.44,8.62]],"id":41555107}],"con":true,"img":false}]}
{"op":"mcm","clk":"5322213291","pt":1646317644892,"mc":[{"id":"1.195532878","rc":[{"atb":[[2.6,0]],"id":40452329},{"atb":[[4.1,0]],"id":39059999}],"con":true,"img":false}]}
{"op":"mcm","clk":"5322213606","pt":1646317647681,"mc":[{"id":"1.195532878","rc":[{"atb":[[2.68,6.67]],"id":40452329}],"con":true,"img":false}]}
{"op":"mcm","clk":"5322213622","pt":1646317647787,"mc":[{"id":"1.195532878","rc":[{"atb":[[4.5,3.2]],"id":39059999}],"con":true,"img":false}]}
{"op":"mcm","clk":"5322228443","pt":1646317808837,"mc":[{"id":"1.195532878","rc":[{"atb":[[2.78,0]],"id":28753299}],"con":true,"img":false}]}
{"op":"mcm","clk":"5322228607","pt":1646317810540,"mc":[{"id":"1.195532878","rc":[{"atb":[[2.4,0]],"id":41555107},{"atb":[[2.9,0]],"id":38251452}],"con":true,"img":false}]}
{"op":"mcm","clk":"5322228941","pt":1646317814246,"mc":[{"id":"1.195532878","rc":[{"atb":[[2.98,5.66]],"id":38251452}],"con":true,"img":false}]}
{"op":"mcm","clk":"5322228961","pt":1646317814452,"mc":[{"id":"1.195532878","rc":[{"atb":[[2.48,7.58]],"id":41555107}],"con":true,"img":false}]}
{"op":"mcm","clk":"5322229649","pt":1646317821458,"mc":[{"id":"1.195532878","rc":[{"atb":[[2.46,0]],"id":39632625}],"con":true,"img":false}]}
{"op":"mcm","clk":"5322229719","pt":1646317822223,"mc":[{"id":"1.195532878","rc":[{"atb":[[2.86,6.67]],"id":28753299}],"con":true,"img":false}]}
{"op":"mcm","clk":"5322231180","pt":1646317837499,"mc":[{"id":"1.195532878","rc":[{"atb":[[2.54,8.06]],"id":39632625}],"con":true,"img":false}]}
{"op":"mcm","clk":"5322235382","pt":1646317884541,"mc":[{"id":"1.195532878","rc":[{"atb":[[2.64,0]],"id":40452329},{"atb":[[4.3,0]],"id":39059999}],"con":true,"img":false}]}
{"op":"mcm","clk":"5322236607","pt":1646317899159,"mc":[{"id":"1.195532878","rc":[{"atb":[[4.7,3.35]],"id":39059999}],"con":true,"img":false}]}
{"op":"mcm","clk":"5322236627","pt":1646317899359,"mc":[{"id":"1.195532878","rc":[{"atb":[[2.72,7.21]],"id":40452329}],"con":true,"img":false}]}
{"op":"mcm","clk":"5322248025","pt":1646318042334,"mc":[{"id":"1.195532878","rc":[{"atb":[[2.82,0]],"id":28753299}],"con":true,"img":false}]}
{"op":"mcm","clk":"5322248254","pt":1646318045152,"mc":[{"id":"1.195532878","rc":[{"atb":[[2.9,5.89]],"id":28753299}],"con":true,"img":false}]}
{"op":"mcm","clk":"5322248904","pt":1646318053877,"mc":[{"id":"1.195532878","rc":[{"atb":[[2.5,0]],"id":39632625}],"con":true,"img":false}]}
{"op":"mcm","clk":"5322249094","pt":1646318056937,"mc":[{"id":"1.195532878","rc":[{"atb":[[2.58,7.09]],"id":39632625}],"con":true,"img":false}]}
{"op":"mcm","clk":"5322249262","pt":1646318059285,"mc":[{"id":"1.195532878","rc":[{"atb":[[2.44,0]],"id":41555107},{"atb":[[2.94,0]],"id":38251452}],"con":true,"img":false}]}
{"op":"mcm","clk":"5322250248","pt":1646318071987,"mc":[{"id":"1.195532878","rc":[{"atb":[[2.52,8.17]],"id":41555107}],"con":true,"img":false}]}
{"op":"mcm","clk":"5322250290","pt":1646318072458,"mc":[{"id":"1.195532878","rc":[{"atb":[[3.05,6.06]],"id":38251452}],"con":true,"img":false}]}
{"op":"mcm","clk":"5322253939","pt":1646318117107,"mc":[{"id":"1.195532878","rc":[{"atb":[[2.68,0]],"id":40452329},{"atb":[[4.5,0]],"id":39059999}],"con":true,"img":false}]}
{"op":"mcm","clk":"5322254156","pt":1646318119927,"mc":[{"id":"1.195532878","rc":[{"atb":[[2.76,6.36]],"id":40452329}],"con":true,"img":false}]}
{"op":"mcm","clk":"5322267767","pt":1646318278276,"mc":[{"id":"1.195532878","rc":[{"atb":[[2.86,0]],"id":28753299}],"con":true,"img":false}]}
{"op":"mcm","clk":"5322269053","pt":1646318291481,"mc":[{"id":"1.195532878","rc":[{"atb":[[2.48,0]],"id":41555107},{"atb":[[2.98,0]],"id":38251452}],"con":true,"img":false}]}
{"op":"mcm","clk":"5322269107","pt":1646318292105,"mc":[{"id":"1.195532878","rc":[{"atb":[[2.54,0]],"id":39632625}],"con":true,"img":false}]}
{"op":"mcm","clk":"5322269200","pt":1646318293101,"mc":[{"id":"1.195532878","rc":[{"atb":[[2.94,6.4]],"id":28753299}],"con":true,"img":false}]}
{"op":"mcm","clk":"5322269288","pt":1646318294296,"mc":[{"id":"1.195532878","rc":[{"atb":[[2.56,7.19]],"id":41555107}],"con":true,"img":false}]}
{"op":"mcm","clk":"5322269310","pt":1646318294515,"mc":[{"id":"1.195532878","rc":[{"atb":[[3.15,5.21]],"id":38251452}],"con":true,"img":false}]}
{"op":"mcm","clk":"5322271196","pt":1646318313839,"mc":[{"id":"1.195532878","rc":[{"atb":[[2.62,7.66]],"id":39632625}],"con":true,"img":false}]}
{"op":"mcm","clk":"5322276640","pt":1646318370441,"mc":[{"id":"1.195532878","rc":[{"atb":[[2.72,0]],"id":40452329},{"atb":[[4.7,0]],"id":39059999}],"con":true,"img":false}]}
{"op":"mcm","clk":"5322276865","pt":1646318372732,"mc":[{"id":"1.195532878","rc":[{"atb":[[2.92,5.83]],"id":39059999}],"con":true,"img":false}]}
{"op":"mcm","clk":"5322277906","pt":1646318383713,"mc":[{"id":"1.195532878","rc":[{"atb":[[2.8,6.89]],"id":40452329}],"con":true,"img":false}]}
{"op":"mcm","clk":"5322277930","pt":1646318384023,"mc":[{"id":"1.195532878","rc":[{"atb":[[2.96,6.33]],"id":39059999}],"con":true,"img":false}]}
{"op":"mcm","clk":"5322290154","pt":1646318511017,"mc":[{"id":"1.195532878","rc":[{"atb":[[2.9,0]],"id":28753299}],"con":true,"img":false}]}
{"op":"mcm","clk":"5322290435","pt":1646318513888,"mc":[{"id":"1.195532878","rc":[{"atb":[[2.98,5.66]],"id":28753299}],"con":true,"img":false}]}
{"op":"mcm","clk":"5322291600","pt":1646318525693,"mc":[{"id":"1.195532878","rc":[{"atb":[[2.58,0]],"id":39632625}],"con":true,"img":false}]}
{"op":"mcm","clk":"5322291944","pt":1646318528729,"mc":[{"id":"1.195532878","rc":[{"atb":[[2.66,6.75]],"id":39632625}],"con":true,"img":false}]}
{"op":"mcm","clk":"5322294009","pt":1646318549117,"mc":[{"id":"1.195532878","rc":[{"atb":[[2.52,0]],"id":41555107},{"atb":[[3.05,0]],"id":38251452}],"con":true,"img":false}]}
{"op":"mcm","clk":"5322295410","pt":1646318562946,"mc":[{"id":"1.195532878","rc":[{"atb":[[2.6,7.76]],"id":41555107}],"con":true,"img":false}]}
{"op":"mcm","clk":"5322295439","pt":1646318563259,"mc":[{"id":"1.195532878","rc":[{"atb":[[3.25,5.52]],"id":38251452}],"con":true,"img":false}]}
{"op":"mcm","clk":"5322299213","pt":1646318604049,"mc":[{"id":"1.195532878","rc":[{"atb":[[2.76,0]],"id":40452329}],"con":true,"img":false}]}
{"op":"mcm","clk":"5322299466","pt":1646318607044,"mc":[{"id":"1.195532878","rc":[{"atb":[[2.84,6.09]],"id":40452329}],"con":true,"img":false}]}
{"op":"mcm","clk":"5322300602","pt":1646318619163,"mc":[{"id":"1.195532878","rc":[{"atb":[[2.92,0]],"id":39059999}],"con":true,"img":false}]}
{"op":"mcm","clk":"5322301189","pt":1646318625160,"mc":[{"id":"1.195532878","rc":[{"atb":[[3,5.6]],"id":39059999}],"con":true,"img":false}]}
{"op":"mcm","clk":"5322310716","pt":1646318724202,"mc":[{"id":"1.195532878","rc":[{"atl":[[1000,12]],"id":41555107},{"atl":[[1000,12]],"id":40452329},{"atl":[[1000,12]],"id":38251452},{"atl":[[1000,12]],"id":39632625},{"atl":[[1000,12]],"id":39059999},{"atl":[[1000,12]],"id":28753299}],"con":true,"img":false}]}
{"op":"mcm","clk":"5322310747","pt":1646318724621,"mc":[{"id":"1.195532878","rc":[{"atb":[[1.01,1000]],"id":41555107},{"atb":[[1.01,1000]],"id":40452329},{"atb":[[1.01,1000]],"id":38251452},{"atb":[[1.01,1000]],"id":39632625},{"atb":[[1.01,1000]],"id":39059999},{"atb":[[1.01,1000]],"id":28753299}],"con":true,"img":false}]}
{"op":"mcm","clk":"5322310776","pt":1646318724887,"mc":[{"id":"1.195532878","rc":[{"atb":[[1.01,11000]],"id":41555107},{"atb":[[1.01,11000]],"id":40452329},{"atb":[[1.01,11000]],"id":38251452},{"atb":[[1.01,11000]],"id":39632625},{"atb":[[1.01,11000]],"id":39059999},{"atb":[[1.01,11000]],"id":28753299}],"con":true,"img":false}]}
{"op":"mcm","clk":"5322314317","pt":1646318761553,"mc":[{"id":"1.195532878","rc":[{"atb":[[2.94,0]],"id":28753299}],"con":true,"img":false}]}
{"op":"mcm","clk":"5322315381","pt":1646318773063,"mc":[{"id":"1.195532878","rc":[{"atb":[[2.62,0]],"id":39632625}],"con":true,"img":false}]}
{"op":"mcm","clk":"5322315445","pt":1646318773735,"mc":[{"id":"1.195532878","rc":[{"atb":[[3.05,6.06]],"id":28753299}],"con":true,"img":false}]}
{"op":"mcm","clk":"5322316167","pt":1646318781783,"mc":[{"id":"1.195532878","rc":[{"atb":[[2.56,0]],"id":41555107},{"atb":[[3.15,0]],"id":38251452}],"con":true,"img":false}]}
{"op":"mcm","clk":"5322316441","pt":1646318784592,"mc":[{"id":"1.195532878","rc":[{"atb":[[2.64,6.84]],"id":41555107}],"con":true,"img":false}]}
{"op":"mcm","clk":"5322316460","pt":1646318784801,"mc":[{"id":"1.195532878","rc":[{"atb":[[3.35,4.76]],"id":38251452}],"con":true,"img":false}]}
{"op":"mcm","clk":"5322316609","pt":1646318786364,"mc":[{"id":"1.195532878","rc":[{"atb":[[2.7,7.3]],"id":39632625}],"con":true,"img":false}]}
{"op":"mcm","clk":"5322331589","pt":1646318851886,"mc":[{"id":"1.195532878","rc":[{"atb":[[2.8,0]],"id":40452329}],"con":true,"img":false}]}
{"op":"mcm","clk":"5322332615","pt":1646318863191,"mc":[{"id":"1.195532878","rc":[{"atb":[[2.88,6.6]],"id":40452329},{"atb":[[2.96,0]],"id":39059999}],"con":true,"img":false}]}
{"op":"mcm","clk":"5322333524","pt":1646318874336,"mc":[{"id":"1.195532878","rc":[{"atb":[[3.1,5.91]],"id":39059999}],"con":true,"img":false}]}
{"op":"mcm","clk":"5322343601","pt":1646318995193,"mc":[{"id":"1.195532878","rc":[{"atb":[[2.98,0]],"id":28753299}],"con":true,"img":false}]}
{"op":"mcm","clk":"5322343856","pt":1646318998185,"mc":[{"id":"1.195532878","rc":[{"atb":[[3.15,5.21]],"id":28753299}],"con":true,"img":false}]}
{"op":"mcm","clk":"5322344581","pt":1646319007308,"mc":[{"id":"1.195532878","rc":[{"atb":[[2.66,0]],"id":39632625}],"con":true,"img":false}]}
{"op":"mcm","clk":"5322344835","pt":1646319010178,"mc":[{"id":"1.195532878","rc":[{"atb":[[2.74,6.44]],"id":39632625}],"con":true,"img":false}]}
{"op":"mcm","clk":"5322346307","pt":1646319028347,"mc":[{"id":"1.195532878","rc":[{"atb":[[2.6,0]],"id":41555107},{"atb":[[3.25,0]],"id":38251452}],"con":true,"img":false}]}
{"op":"mcm","clk":"5322347516","pt":1646319043344,"mc":[{"id":"1.195532878","rc":[{"atb":[[2.68,7.39]],"id":41555107}],"con":true,"img":false}]}
{"op":"mcm","clk":"5322347563","pt":1646319043917,"mc":[{"id":"1.195532878","rc":[{"atb":[[2.3,9.55]],"id":38251452}],"con":true,"img":false}]}
{"op":"mcm","clk":"5322350834","pt":1646319085085,"mc":[{"id":"1.195532878","rc":[{"atb":[[2.84,0]],"id":40452329}],"con":true,"img":false}]}
{"op":"mcm","clk":"5322351067","pt":1646319087955,"mc":[{"id":"1.195532878","rc":[{"atb":[[2.92,5.83]],"id":40452329}],"con":true,"img":false}]}
{"op":"mcm","clk":"5322351824","pt":1646319097272,"mc":[{"id":"1.195532878","rc":[{"atb":[[3,0]],"id":39059999}],"con":true,"img":false}]}
{"op":"mcm","clk":"5322352066","pt":1646319099965,"mc":[{"id":"1.195532878","rc":[{"atb":[[3.2,5.09]],"id":39059999}],"con":true,"img":false}]}
{"op":"mcm","clk":"5322359346","pt":1646319195383,"mc":[{"id":"1.195532878","rc":[{"atb":[[2.08,0]],"id":38251452}],"con":true,"img":false}]}
{"op":"mcm","clk":"5322359353","pt":1646319195489,"mc":[{"id":"1.195532878","rc":[{"atb":[[2.32,12.17]],"id":38251452}],"con":true,"img":false}]}
{"op":"mcm","clk":"5322361994","pt":1646319238855,"mc":[{"id":"1.195532878","rc":[{"atb":[[3.05,0]],"id":28753299}],"con":true,"img":false}]}
{"op":"mcm","clk":"5322362553","pt":1646319248897,"mc":[{"id":"1.195532878","rc":[{"atb":[[2.7,0]],"id":39632625}],"con":true,"img":false}]}
{"op":"mcm","clk":"5322362580","pt":1646319249465,"mc":[{"id":"1.195532878","rc":[{"atb":[[3.25,5.52]],"id":28753299}],"con":true,"img":false}]}
{"op":"mcm","clk":"5322363371","pt":1646319262611,"mc":[{"id":"1.195532878","rc":[{"atb":[[2.64,0]],"id":41555107},{"atb":[[3.35,0]],"id":38251452}],"con":true,"img":false}]}
{"op":"mcm","clk":"5322363381","pt":1646319262819,"mc":[{"id":"1.195532878","rc":[{"atb":[[2.78,6.97]],"id":39632625}],"con":true,"img":false}]}
{"op":"mcm","clk":"5322363537","pt":1646319265324,"mc":[{"id":"1.195532878","rc":[{"atb":[[2.36,8.24]],"id":38251452}],"con":true,"img":false}]}
{"op":"mcm","clk":"5322363549","pt":1646319265532,"mc":[{"id":"1.195532878","rc":[{"atb":[[2.72,6.51]],"id":41555107}],"con":true,"img":false}]}
{"op":"mcm","clk":"5322366931","pt":1646319319583,"mc":[{"id":"1.195532878","rc":[{"atb":[[2.88,0]],"id":40452329}],"con":true,"img":false}]}
{"op":"mcm","clk":"5322367706","pt":1646319331419,"mc":[{"id":"1.195532878","rc":[{"atb":[[2.96,6.33]],"id":40452329}],"con":true,"img":false}]}
{"op":"mcm","clk":"5322368406","pt":1646319342531,"mc":[{"id":"1.195532878","rc":[{"atb":[[3.1,0]],"id":39059999}],"con":true,"img":false}]}
{"op":"mcm","clk":"5322369231","pt":1646319354732,"mc":[{"id":"1.195532878","rc":[{"atb":[[3.3,5.39]],"id":39059999}],"con":true,"img":false}]}
{"op":"mcm","clk":"5322374868","pt":1646319441200,"mc":[{"id":"1.195532878","rc":[{"atb":[[2.3,0]],"id":38251452}],"con":true,"img":false}]}
{"op":"mcm","clk":"5322375882","pt":1646319455611,"mc":[{"id":"1.195532878","rc":[{"atb":[[2.4,8.86]],"id":38251452}],"con":true,"img":false}]}
{"op":"mcm","clk":"5322376986","pt":1646319473246,"mc":[{"id":"1.195532878","rc":[{"atb":[[3.15,0]],"id":28753299}],"con":true,"img":false}]}
{"op":"mcm","clk":"5322377155","pt":1646319476045,"mc":[{"id":"1.195532878","rc":[{"atb":[[3.35,4.76]],"id":28753299}],"con":true,"img":false}]}
{"op":"mcm","clk":"5322377555","pt":1646319482138,"mc":[{"id":"1.195532878","rc":[{"atb":[[2.74,0]],"id":39632625}],"con":true,"img":false}]}
{"op":"mcm","clk":"5322377774","pt":1646319485115,"mc":[{"id":"1.195532878","rc":[{"atb":[[2.82,6.16]],"id":39632625}],"con":true,"img":false}]}
{"op":"mcm","clk":"5322382486","pt":1646319554153,"mc":[{"id":"1.195532878","rc":[{"atb":[[2.92,0]],"id":40452329}],"con":true,"img":false}]}
{"op":"mcm","clk":"5322382735","pt":1646319557032,"mc":[{"id":"1.195532878","rc":[{"atb":[[2.14,9.83]],"id":40452329}],"con":true,"img":false}]}
{"op":"mcm","clk":"5322384094","pt":1646319575084,"mc":[{"id":"1.195532878","rc":[{"atb":[[3.2,0]],"id":39059999}],"con":true,"img":false}]}
{"op":"mcm","clk":"5322384360","pt":1646319578054,"mc":[{"id":"1.195532878","rc":[{"atb":[[3.4,4.67]],"id":39059999}],"con":true,"img":false}]}
{"op":"mcm","clk":"5322385013","pt":1646319587073,"mc":[{"id":"1.195532878","rc":[{"atb":[[2.68,0]],"id":41555107}],"con":true,"img":false}]}
{"op":"mcm","clk":"5322386996","pt":1646319612639,"mc":[{"id":"1.195532878","rc":[{"atb":[[2.72,6.52],[2.32,12.68],[2.76,7.06]],"id":41555107},{"atb":[[2.96,6.34],[2.14,9.84],[2.1,13.18]],"id":40452329},{"atb":[[2.4,8.87],[2.36,8.25],[2.32,12.18]],"id":38251452},{"atb":[[2.82,6.16],[2.36,11.31],[2.78,6.98]],"id":39632625},{"atb":[[2.02,10.14],[3.4,4.67],[3.3,5.4]],"id":39059999},{"atb":[[2.06,11.2],[3.35,4.77],[3.25,5.53]],"id":28753299}],"con":true,"img":false}]}
{"op":"mcm","clk":"5322393065","pt":1646319689648,"mc":[{"id":"1.195532878","rc":[{"atb":[[2.36,0]],"id":38251452}],"con":true,"img":false}]}
{"op":"mcm","clk":"5322393291","pt":1646319692537,"mc":[{"id":"1.195532878","rc":[{"atb":[[2.44,7.79]],"id":38251452}],"con":true,"img":false}]}
{"op":"mcm","clk":"5322401760","pt":1646319796299,"mc":[{"id":"1.195532878","rc":[{"atb":[[2.1,0]],"id":40452329}],"con":true,"img":false}]}
{"op":"mcm","clk":"5322401769","pt":1646319796406,"mc":[{"id":"1.195532878","rc":[{"atb":[[2.16,13.18]],"id":40452329}],"con":true,"img":false}]}
{"op":"mcm","clk":"5322402168","pt":1646319800886,"mc":[{"id":"1.195532878","rc":[{"atb":[[3.25,0]],"id":28753299}],"con":true,"img":false}]}
{"op":"mcm","clk":"5322403931","pt":1646319825078,"mc":[{"id":"1.195532878","rc":[{"atb":[[2.72,0]],"id":41555107}],"con":true,"img":false}]}
{"op":"mcm","clk":"5322404365","pt":1646319830561,"mc":[{"id":"1.195532878","rc":[{"atb":[[2.8,6.23]],"id":41555107}],"con":true,"img":false}]}
{"op":"mcm","clk":"5322404560","pt":1646319832799,"mc":[{"id":"1.195532878","rc":[{"atb":[[2.96,0]],"id":40452329},{"atb":[[2.78,0]],"id":39632625},{"atb":[[3.3,0]],"id":39059999}],"con":true,"img":false}]}
{"op":"mcm","clk":"5322404735","pt":1646319834984,"mc":[{"id":"1.195532878","rc":[{"atb":[[3.45,5.07]],"id":28753299}],"con":true,"img":false}]}
{"op":"mcm","clk":"5322406606","pt":1646319857006,"mc":[{"id":"1.195532878","rc":[{"atb":[[3.5,4.97]],"id":39059999}],"con":true,"img":false}]}
{"op":"mcm","clk":"5322406633","pt":1646319857317,"mc":[{"id":"1.195532878","rc":[{"atb":[[2.86,6.68]],"id":39632625}],"con":true,"img":false}]}
{"op":"mcm","clk":"5322406704","pt":1646319858208,"mc":[{"id":"1.195532878","rc":[{"atb":[[2.2,10.36]],"id":40452329}],"con":true,"img":false}]}
{"op":"mcm","clk":"5322420755","pt":1646320029050,"mc":[{"id":"1.195532878","rc":[{"atb":[[2.14,0]],"id":40452329}],"con":true,"img":false}]}
{"op":"mcm","clk":"5322421076","pt":1646320033102,"mc":[{"id":"1.195532878","rc":[{"atb":[[2.24,9.05]],"id":40452329}],"con":true,"img":false}]}
{"op":"mcm","clk":"5322421415","pt":1646320036262,"mc":[{"id":"1.195532878","rc":[{"atb":[[3.35,0]],"id":28753299}],"con":true,"img":false}]}
{"op":"mcm","clk":"5322421599","pt":1646320037946,"mc":[{"id":"1.195532878","rc":[{"atb":[[3.55,4.4]],"id":28753299}],"con":true,"img":false}]}
{"op":"mcm","clk":"5322422154","pt":1646320044866,"mc":[{"id":"1.195532878","rc":[{"atb":[[2.4,0]],"id":38251452}],"con":true,"img":false}]}
{"op":"mcm","clk":"5322423270","pt":1646320058379,"mc":[{"id":"1.195532878","rc":[{"atb":[[2.48,8.4]],"id":38251452}],"con":true,"img":false}]}
{"op":"mcm","clk":"5322424156","pt":1646320068092,"mc":[{"id":"1.195532878","rc":[{"atb":[[2.82,0]],"id":39632625},{"atb":[[3.4,0]],"id":39059999}],"con":true,"img":false}]}
{"op":"mcm","clk":"5322424417","pt":1646320071400,"mc":[{"id":"1.195532878","rc":[{"atb":[[2.9,5.9]],"id":39632625}],"con":true,"img":false}]}
{"op":"mcm","clk":"5322424490","pt":1646320072192,"mc":[{"id":"1.195532878","rc":[{"atb":[[3.6,4.31]],"id":39059999}],"con":true,"img":false}]}
{"op":"mcm","clk":"5322424769","pt":1646320075998,"mc":[{"id":"1.195532878","rc":[{"atb":[[2.76,0]],"id":41555107}],"con":true,"img":false}]}
{"op":"mcm","clk":"5322426047","pt":1646320092832,"mc":[{"id":"1.195532878","rc":[{"atb":[[2.84,6.75]],"id":41555107}],"con":true,"img":false}]}
{"op":"mcm","clk":"5322426235","pt":1646320095164,"mc":[{"id":"1.195532878","rc":[{"atb":[[2.16,0]],"id":40452329}],"con":true,"img":false}]}
{"op":"mcm","clk":"5322426244","pt":1646320095267,"mc":[{"id":"1.195532878","rc":[{"atb":[[2.26,13.18]],"id":40452329}],"con":true,"img":false}]}
{"op":"mcm","clk":"5322441830","pt":1646320278666,"mc":[{"id":"1.195532878","rc":[{"atb":[[2.44,0]],"id":38251452}],"con":true,"img":false}]}
{"op":"mcm","clk":"5322442071","pt":1646320281473,"mc":[{"id":"1.195532878","rc":[{"atb":[[2.52,7.38]],"id":38251452}],"con":true,"img":false}]}
{"op":"mcm","clk":"5322442384","pt":1646320284713,"mc":[{"id":"1.195532878","rc":[{"atb":[[2.2,0]],"id":40452329},{"atb":[[3.45,0]],"id":28753299}],"con":true,"img":false}]}
{"op":"mcm","clk":"5322445443","pt":1646320299324,"mc":[{"id":"1.195532878","rc":[{"atb":[[3.65,4.69]],"id":28753299}],"con":true,"img":false}]}
{"op":"mcm","clk":"5322445455","pt":1646320299536,"mc":[{"id":"1.195532878","rc":[{"atb":[[2.3,9.56]],"id":40452329}],"con":true,"img":false}]}
{"op":"mcm","clk":"5322446347","pt":1646320308674,"mc":[{"id":"1.195532878","rc":[{"atb":[[2.8,0]],"id":41555107}],"con":true,"img":false}]}
{"op":"mcm","clk":"5322446913","pt":1646320315175,"mc":[{"id":"1.195532878","rc":[{"atb":[[2.86,0]],"id":39632625},{"atb":[[3.5,0]],"id":39059999}],"con":true,"img":false}]}
{"op":"mcm","clk":"5322446921","pt":1646320315283,"mc":[{"id":"1.195532878","rc":[{"atb":[[2.88,5.97]],"id":41555107}],"con":true,"img":false}]}
{"op":"mcm","clk":"5322448105","pt":1646320329468,"mc":[{"id":"1.195532878","rc":[{"atb":[[2.94,6.4]],"id":39632625}],"con":true,"img":false}]}
{"op":"mcm","clk":"5322448143","pt":1646320329898,"mc":[{"id":"1.195532878","rc":[{"atb":[[2.24,0]],"id":40452329}],"con":true,"img":false}]}
{"op":"mcm","clk":"5322448153","pt":1646320330000,"mc":[{"id":"1.195532878","rc":[{"atb":[[3.7,4.6]],"id":39059999}],"con":true,"img":false}]}
{"op":"mcm","clk":"5322448386","pt":1646320332759,"mc":[{"id":"1.195532878","rc":[{"atb":[[2.34,8.37]],"id":40452329}],"con":true,"img":false}]}
{"op":"mcm","clk":"5322453749","pt":1646320394656,"mc":[{"id":"1.195532878","rc":[{"atb":[[2.26,0]],"id":40452329}],"con":true,"img":false}]}
{"op":"mcm","clk":"5322453760","pt":1646320394762,"mc":[{"id":"1.195532878","rc":[{"atb":[[2.36,13.18]],"id":40452329}],"con":true,"img":false}]}
{"op":"mcm","clk":"5322464032","pt":1646320520167,"mc":[{"id":"1.195532878","rc":[{"atb":[[3.55,0]],"id":28753299}],"con":true,"img":false}]}
{"op":"mcm","clk":"5322464155","pt":1646320521537,"mc":[{"id":"1.195532878","rc":[{"atb":[[2.48,0]],"id":38251452}],"con":true,"img":false}]}
{"op":"mcm","clk":"5322464315","pt":1646320523664,"mc":[{"id":"1.195532878","rc":[{"atb":[[3.75,4.07]],"id":28753299}],"con":true,"img":false}]}
{"op":"mcm","clk":"5322465259","pt":1646320534672,"mc":[{"id":"1.195532878","rc":[{"atb":[[2.56,7.97]],"id":38251452}],"con":true,"img":false}]}
{"op":"mcm","clk":"5322466307","pt":1646320547897,"mc":[{"id":"1.195532878","rc":[{"atb":[[2.84,0]],"id":41555107}],"con":true,"img":false}]}
{"op":"mcm","clk":"5322466784","pt":1646320553318,"mc":[{"id":"1.195532878","rc":[{"atb":[[2.9,0]],"id":39632625},{"atb":[[3.6,0]],"id":39059999}],"con":true,"img":false}]}
{"op":"mcm","clk":"5322467116","pt":1646320557110,"mc":[{"id":"1.195532878","rc":[{"atb":[[3.8,4.01]],"id":39059999}],"con":true,"img":false}]}
{"op":"mcm","clk":"5322467157","pt":1646320557529,"mc":[{"id":"1.195532878","rc":[{"atb":[[2.98,5.67]],"id":39632625}],"con":true,"img":false}]}
{"op":"mcm","clk":"5322467436","pt":1646320560460,"mc":[{"id":"1.195532878","rc":[{"atb":[[2.92,6.47]],"id":41555107}],"con":true,"img":false}]}
{"op":"mcm","clk":"5322468552","pt":1646320573336,"mc":[{"id":"1.195532878","rc":[{"atb":[[2.3,0]],"id":40452329}],"con":true,"img":false}]}
{"op":"mcm","clk":"5322469413","pt":1646320583565,"mc":[{"id":"1.195532878","rc":[{"atb":[[2.4,8.87]],"id":40452329}],"con":true,"img":false}]}
{"op":"mcm","clk":"5322472967","pt":1646320627940,"mc":[{"id":"1.195532878","rc":[{"atb":[[2.34,0]],"id":40452329}],"con":true,"img":false}]}
{"op":"mcm","clk":"5322473193","pt":1646320630610,"mc":[{"id":"1.195532878","rc":[{"atb":[[2.44,7.79]],"id":40452329}],"con":true,"img":false}]}
{"op":"mcm","clk":"5322482843","pt":1646320753976,"mc":[{"id":"1.195532878","rc":[{"atb":[[2.52,0]],"id":38251452}],"con":true,"img":false}]}
{"op":"mcm","clk":"5322483114","pt":1646320757007,"mc":[{"id":"1.195532878","rc":[{"atb":[[2.6,7.02]],"id":38251452}],"con":true,"img":false}]}
{"op":"mcm","clk":"5322483538","pt":1646320762099,"mc":[{"id":"1.195532878","rc":[{"atb":[[3.65,0]],"id":28753299}],"con":true,"img":false}]}
{"op":"mcm","clk":"5322484835","pt":1646320779216,"mc":[{"id":"1.195532878","rc":[{"atb":[[3.85,4.36]],"id":28753299}],"con":true,"img":false}]}
{"op":"mcm","clk":"5322484968","pt":1646320780995,"mc":[{"id":"1.195532878","rc":[{"atb":[[2.88,0]],"id":41555107}],"con":true,"img":false}]}
{"op":"mcm","clk":"5322485206","pt":1646320784211,"mc":[{"id":"1.195532878","rc":[{"atb":[[2.96,5.72]],"id":41555107}],"con":true,"img":false}]}
{"op":"mcm","clk":"5322486549","pt":1646320799756,"mc":[{"id":"1.195532878","rc":[{"atb":[[2.94,0]],"id":39632625},{"atb":[[3.7,0]],"id":39059999}],"con":true,"img":false}]}
{"op":"mcm","clk":"5322487780","pt":1646320814844,"mc":[{"id":"1.195532878","rc":[{"atb":[[3.9,4.28]],"id":39059999},{"spn":5.11,"spf":1.0,"id":28753299}],"con":true,"img":false}]}
{"op":"mcm","clk":"5322487841","pt":1646320815575,"mc":[{"id":"1.195532878","rc":[{"atb":[[3.05,6.06]],"id":39632625}],"con":true,"img":false}]}
{"op":"mcm","clk":"5322492796","pt":1646320874825,"mc":[{"id":"1.195532878","rc":[{"atb":[[2.4,0]],"id":40452329}],"con":true,"img":false}]}
{"op":"mcm","clk":"5322493670","pt":1646320886299,"mc":[{"id":"1.195532878","rc":[{"atb":[[2.48,8.4]],"id":40452329}],"con":true,"img":false}]}
{"op":"mcm","clk":"5322502579","pt":1646320994758,"mc":[{"id":"1.195532878","rc":[{"atb":[[3.75,0]],"id":28753299},{"spn":5.1,"spf":1.0,"id":28753299}],"con":true,"img":false}]}
{"op":"mcm","clk":"5322502815","pt":1646320997633,"mc":[{"id":"1.195532878","rc":[{"atb":[[2.56,0]],"id":38251452}],"con":true,"img":false}]}
{"op":"mcm","clk":"5322502844","pt":1646320998052,"mc":[{"id":"1.195532878","rc":[{"atb":[[3.95,3.8]],"id":28753299}],"con":true,"img":false}]}
{"op":"mcm","clk":"5322503658","pt":1646321009267,"mc":[{"id":"1.195532878","rc":[{"atb":[[2.64,7.58]],"id":38251452}],"con":true,"img":false}]}
{"op":"mcm","clk":"5322505154","pt":1646321030575,"mc":[{"id":"1.195532878","rc":[{"atb":[[2.92,0]],"id":41555107}],"con":true,"img":false}]}
{"op":"mcm","clk":"5322505423","pt":1646321034296,"mc":[{"id":"1.195532878","rc":[{"atb":[[2.98,0]],"id":39632625},{"atb":[[3.8,0]],"id":39059999}],"con":true,"img":false}]}
{"op":"mcm","clk":"5322505581","pt":1646321036424,"mc":[{"id":"1.195532878","rc":[{"atb":[[3.15,5.22]],"id":39632625}],"con":true,"img":false}]}
{"op":"mcm","clk":"5322505591","pt":1646321036580,"mc":[{"id":"1.195532878","rc":[{"atb":[[4,3.74]],"id":39059999}],"con":true,"img":false}]}
{"op":"mcm","clk":"5322506179","pt":1646321044851,"mc":[{"id":"1.195532878","rc":[{"atb":[[2.36,9.14]],"id":41555107}],"con":true,"img":false}]}
{"op":"mcm","clk":"5322510764","pt":1646321108913,"mc":[{"id":"1.195532878","rc":[{"atb":[[2.44,0]],"id":40452329},{"spn":5.17,"spf":1.0,"id":28753299}],"con":true,"img":false}]}
{"op":"mcm","clk":"5322510959","pt":1646321111797,"mc":[{"id":"1.195532878","rc":[{"atb":[[2.52,7.38]],"id":40452329}],"con":true,"img":false}]}
{"op":"mcm","clk":"5322519552","pt":1646321231508,"mc":[{"id":"1.195532878","rc":[{"atb":[[2.6,0]],"id":38251452}],"con":true,"img":false}]}
{"op":"mcm","clk":"5322519666","pt":1646321233102,"mc":[{"id":"1.195532878","rc":[{"atb":[[3.85,0]],"id":28753299}],"con":true,"img":false}]}
{"op":"mcm","clk":"5322519777","pt":1646321234616,"mc":[{"id":"1.195532878","rc":[{"atb":[[2.68,6.68]],"id":38251452}],"con":true,"img":false}]}
{"op":"mcm","clk":"5322520548","pt":1646321244122,"mc":[{"id":"1.195532878","rc":[{"atb":[[4.1,4.01]],"id":28753299}],"con":true,"img":false}]}
{"op":"mcm","clk":"5322522175","pt":1646321265263,"mc":[{"id":"1.195532878","rc":[{"atb":[[2.96,0]],"id":41555107}],"con":true,"img":false}]}
{"op":"mcm","clk":"5322522340","pt":1646321267560,"mc":[{"id":"1.195532878","rc":[{"atb":[[2.4,8.01]],"id":41555107}],"con":true,"img":false}]}
{"op":"mcm","clk":"5322523257","pt":1646321278944,"mc":[{"id":"1.195532878","rc":[{"atb":[[3.05,0]],"id":39632625},{"atb":[[3.9,0]],"id":39059999}],"con":true,"img":false}]}
{"op":"mcm","clk":"5322524514","pt":1646321295779,"mc":[{"id":"1.195532878","rc":[{"atb":[[2.4,8.87]],"id":39632625},{"spn":5.25,"spf":1.0,"id":28753299}],"con":true,"img":false}]}
{"op":"mcm","clk":"5322524560","pt":1646321296357,"mc":[{"id":"1.195532878","rc":[{"atb":[[4.2,3.88]],"id":39059999}],"con":true,"img":false}]}
{"op":"mcm","clk":"5322528572","pt":1646321350334,"mc":[{"id":"1.195532878","rc":[{"atb":[[2.48,0]],"id":40452329}],"con":true,"img":false}]}
{"op":"mcm","clk":"5322529354","pt":1646321361721,"mc":[{"id":"1.195532878","rc":[{"atb":[[2.56,7.97]],"id":40452329}],"con":true,"img":false}]}
{"op":"mcm","clk":"5322537567","pt":1646321466421,"mc":[{"id":"1.195532878","rc":[{"atb":[[3.95,0]],"id":28753299},{"spn":5.1,"spf":1.0,"id":28753299}],"con":true,"img":false}]}
{"op":"mcm","clk":"5322537814","pt":1646321469397,"mc":[{"id":"1.195532878","rc":[{"atb":[[4.3,3.4]],"id":28753299}],"con":true,"img":false}]}
{"op":"mcm","clk":"5322537946","pt":1646321471534,"mc":[{"id":"1.195532878","rc":[{"atb":[[2.64,0]],"id":38251452}],"con":true,"img":false}]}
{"op":"mcm","clk":"5322538002","pt":1646321472208,"mc":[{"id":"1.195532878","rc":[{"spl":[[1.01,8.24]],"id":39632625}],"con":true,"img":false}]}
{"op":"mcm","clk":"5322538921","pt":1646321484541,"mc":[{"id":"1.195532878","rc":[{"atb":[[2.72,7.22]],"id":38251452}],"con":true,"img":false}]}
{"op":"mcm","clk":"5322540867","pt":1646321511058,"mc":[{"id":"1.195532878","rc":[{"atb":[[2.36,0]],"id":41555107}],"con":true,"img":false}]}
{"op":"mcm","clk":"5322540903","pt":1646321511582,"mc":[{"id":"1.195532878","rc":[{"atb":[[3.15,0]],"id":39632625},{"atb":[[4,0]],"id":39059999}],"con":true,"img":false}]}
{"op":"mcm","clk":"5322541178","pt":1646321515384,"mc":[{"id":"1.195532878","rc":[{"atb":[[4.4,3.3]],"id":39059999}],"con":true,"img":false}]}
{"op":"mcm","clk":"5322541192","pt":1646321515540,"mc":[{"id":"1.195532878","rc":[{"atb":[[2.44,7.79]],"id":39632625}],"con":true,"img":false}]}
{"op":"mcm","clk":"5322542105","pt":1646321527500,"mc":[{"id":"1.195532878","rc":[{"atb":[[2.44,8.63]],"id":41555107},{"spn":3.22,"spf":1.0,"id":39632625},{"spn":5.35,"spf":1.0,"id":28753299}],"con":true,"img":false}]}
{"op":"mcm","clk":"5322546421","pt":1646321583265,"mc":[{"id":"1.195532878","rc":[{"atb":[[2.52,0]],"id":40452329}],"con":true,"img":false}]}
{"op":"mcm","clk":"5322546664","pt":1646321586349,"mc":[{"id":"1.195532878","rc":[{"atb":[[2.6,7.02]],"id":40452329}],"con":true,"img":false}]}
{"op":"mcm","clk":"5322556360","pt":1646321704020,"mc":[{"id":"1.195532878","rc":[{"atb":[[2.68,0]],"id":38251452}],"con":true,"img":false}]}
{"op":"mcm","clk":"5322556622","pt":1646321707123,"mc":[{"id":"1.195532878","rc":[{"atb":[[2.76,6.37]],"id":38251452}],"con":true,"img":false}]}
{"op":"mcm","clk":"5322556816","pt":1646321709531,"mc":[{"id":"1.195532878","rc":[{"atb":[[4.1,0]],"id":28753299}],"con":true,"img":false}]}
{"op":"mcm","clk":"5322557769","pt":1646321721721,"mc":[{"id":"1.195532878","rc":[{"atb":[[4.5,3.55]],"id":28753299}],"con":true,"img":false}]}
{"op":"mcm","clk":"5322559401","pt":1646321742634,"mc":[{"id":"1.195532878","rc":[{"atb":[[2.4,0]],"id":41555107}],"con":true,"img":false}]}
{"op":"mcm","clk":"5322559635","pt":1646321745875,"mc":[{"id":"1.195532878","rc":[{"atb":[[2.48,7.58]],"id":41555107}],"con":true,"img":false}]}
{"op":"mcm","clk":"5322560788","pt":1646321760604,"mc":[{"id":"1.195532878","rc":[{"atb":[[2.4,0]],"id":39632625},{"atb":[[4.2,0]],"id":39059999}],"con":true,"img":false}]}
{"op":"mcm","clk":"5322562084","pt":1646321775704,"mc":[{"id":"1.195532878","rc":[{"atb":[[2.48,8.4]],"id":39632625},{"spn":3.24,"spf":1.0,"id":39632625},{"spn":5.47,"spf":1.0,"id":28753299}],"con":true,"img":false}]}
{"op":"mcm","clk":"5322562142","pt":1646321776389,"mc":[{"id":"1.195532878","rc":[{"atb":[[4.6,3.45]],"id":39059999}],"con":true,"img":false}]}
{"op":"mcm","clk":"5322566322","pt":1646321827523,"mc":[{"id":"1.195532878","rc":[{"atb":[[2.56,0]],"id":40452329}],"con":true,"img":false}]}
{"op":"mcm","clk":"5322567173","pt":1646321838829,"mc":[{"id":"1.195532878","rc":[{"atb":[[2.64,7.58]],"id":40452329}],"con":true,"img":false}]}
{"op":"mcm","clk":"5322575779","pt":1646321944668,"mc":[{"id":"1.195532878","rc":[{"atb":[[4.3,0]],"id":28753299},{"spn":5.1,"spf":1.0,"id":28753299}],"con":true,"img":false}]}
{"op":"mcm","clk":"5322575966","pt":1646321946866,"mc":[{"id":"1.195532878","rc":[{"atb":[[4.7,3.03]],"id":28753299}],"con":true,"img":false}]}
{"op":"mcm","clk":"5322575982","pt":1646321947076,"mc":[{"id":"1.195532878","rc":[{"atb":[[2.72,0]],"id":38251452}],"con":true,"img":false}]}
{"op":"mcm","clk":"5322577265","pt":1646321962283,"mc":[{"id":"1.195532878","rc":[{"atb":[[2.8,6.9]],"id":38251452}],"con":true,"img":false}]}
{"op":"mcm","clk":"5322579478","pt":1646321989246,"mc":[{"id":"1.195532878","rc":[{"atb":[[2.44,0]],"id":41555107}],"con":true,"img":false}]}
{"op":"mcm","clk":"5322579990","pt":1646321996042,"mc":[{"id":"1.195532878","rc":[{"atb":[[2.44,0]],"id":39632625},{"atb":[[4.4,0]],"id":39059999}],"con":true,"img":false}]}
{"op":"mcm","clk":"5322580373","pt":1646322001049,"mc":[{"id":"1.195532878","rc":[{"atb":[[2.52,7.38]],"id":39632625}],"con":true,"img":false}]}
{"op":"mcm","clk":"5322580384","pt":1646322001178,"mc":[{"id":"1.195532878","rc":[{"atb":[[4.8,2.95]],"id":39059999}],"con":true,"img":false}]}
{"op":"mcm","clk":"5322580418","pt":1646322001473,"mc":[{"id":"1.195532878","rc":[{"atb":[[2.52,8.18]],"id":41555107}],"con":true,"img":false}]}
{"op":"mcm","clk":"5322585288","pt":1646322061243,"mc":[{"id":"1.195532878","rc":[{"atb":[[2.6,0]],"id":40452329},{"spn":3.26,"spf":1.0,"id":39632625},{"spn":5.58,"spf":1.0,"id":28753299}],"con":true,"img":false}]}
{"op":"mcm","clk":"5322585530","pt":1646322064443,"mc":[{"id":"1.195532878","rc":[{"atb":[[2.68,6.68]],"id":40452329}],"con":true,"img":false}]}
{"op":"mcm","clk":"5322595166","pt":1646322182222,"mc":[{"id":"1.195532878","rc":[{"atb":[[2.76,0]],"id":38251452}],"con":true,"img":false}]}
{"op":"mcm","clk":"5322595404","pt":1646322184845,"mc":[{"id":"1.195532878","rc":[{"atb":[[2.84,6.09]],"id":38251452}],"con":true,"img":false}]}
{"op":"mcm","clk":"5322595729","pt":1646322188206,"mc":[{"id":"1.195532878","rc":[{"atb":[[4.5,0]],"id":28753299}],"con":true,"img":false}]}
{"op":"mcm","clk":"5322598896","pt":1646322223881,"mc":[{"id":"1.195532878","rc":[{"atb":[[2.48,0]],"id":41555107}],"con":true,"img":false}]}
{"op":"mcm","clk":"5322599136","pt":1646322226706,"mc":[{"id":"1.195532878","rc":[{"atb":[[2.56,7.2]],"id":41555107}],"con":true,"img":false}]}
{"op":"mcm","clk":"5322600091","pt":1646322236924,"mc":[{"id":"1.195532878","rc":[{"atb":[[2.48,0]],"id":39632625},{"atb":[[4.6,0]],"id":39059999}],"con":true,"img":false}]}
{"op":"mcm","clk":"5322601492","pt":1646322251524,"mc":[{"id":"1.195532878","rc":[{"atb":[[2.56,7.97]],"id":39632625},{"spn":3.28,"spf":1.0,"id":39632625},{"spn":5.1,"spf":1.0,"id":28753299}],"con":true,"img":false}]}
{"op":"mcm","clk":"5322613585","pt":1646322381323,"mc":[{"id":"1.195532878","rc":[{"atb":[[2.64,0]],"id":40452329}],"con":true,"img":false}]}
{"op":"mcm","clk":"5322615056","pt":1646322396950,"mc":[{"id":"1.195532878","rc":[{"atb":[[2.72,7.22]],"id":40452329}],"con":true,"img":false}]}
{"op":"mcm","clk":"5322617256","pt":1646322419373,"mc":[{"id":"1.195532878","rc":[{"atb":[[2.8,0]],"id":38251452}],"con":true,"img":false}]}
{"op":"mcm","clk":"5322617498","pt":1646322422286,"mc":[{"id":"1.195532878","rc":[{"atb":[[4.7,0]],"id":28753299}],"con":true,"img":false}]}
{"op":"mcm","clk":"5322617756","pt":1646322425068,"mc":[{"id":"1.195532878","rc":[{"atb":[[2.6,7.02]],"id":28753299}],"con":true,"img":false}]}
{"op":"mcm","clk":"5322618614","pt":1646322434408,"mc":[{"id":"1.195532878","rc":[{"atb":[[2.88,6.61]],"id":38251452}],"con":true,"img":false}]}
{"op":"mcm","clk":"5322618620","pt":1646322434510,"mc":[{"id":"1.195532878","rc":[{"atb":[[2.64,7.58]],"id":28753299}],"con":true,"img":false}]}
{"op":"mcm","clk":"5322621243","pt":1646322465226,"mc":[{"id":"1.195532878","rc":[{"spb":[[1000,11]],"id":38251452},{"spn":4.6,"spf":4.6,"id":38251452}],"con":true,"img":false}]}
{"op":"mcm","clk":"5322621647","pt":1646322470242,"mc":[{"id":"1.195532878","rc":[{"atb":[[2.52,0]],"id":39632625},{"atb":[[4.8,0]],"id":39059999}],"con":true,"img":false}]}
{"op":"mcm","clk":"5322621920","pt":1646322473362,"mc":[{"id":"1.195532878","rc":[{"atb":[[2.92,5.84]],"id":39059999}],"con":true,"img":false}]}
{"op":"mcm","clk":"5322621993","pt":1646322474142,"mc":[{"id":"1.195532878","rc":[{"atb":[[2.6,7.02]],"id":39632625}],"con":true,"img":false}]}
{"op":"mcm","clk":"5322638852","pt":1646322610118,"mc":[{"id":"1.195532878","rc":[{"atb":[[2.52,0]],"id":41555107},{"spn":3.3,"spf":1.0,"id":39632625}],"con":true,"img":false}]}
{"op":"mcm","clk":"5322638879","pt":1646322610430,"mc":[{"id":"1.195532878","rc":[{"atb":[[2.96,6.34]],"id":39059999}],"con":true,"img":false}]}
{"op":"mcm","clk":"5322639210","pt":1646322614907,"mc":[{"id":"1.195532878","rc":[{"atb":[[2.68,0]],"id":40452329}],"con":true,"img":false}]}
{"op":"mcm","clk":"5322639392","pt":1646322617528,"mc":[{"id":"1.195532878","rc":[{"atb":[[2.76,6.37]],"id":40452329}],"con":true,"img":false}]}
{"op":"mcm","clk":"5322642742","pt":1646322644302,"mc":[{"id":"1.195532878","rc":[{"atb":[[2.6,7.77]],"id":41555107}],"con":true,"img":false}]}
{"op":"mcm","clk":"5322644196","pt":1646322654706,"mc":[{"id":"1.195532878","rc":[{"atb":[[2.84,0]],"id":38251452}],"con":true,"img":false}]}
{"op":"mcm","clk":"5322644633","pt":1646322656830,"mc":[{"id":"1.195532878","rc":[{"atb":[[2.92,5.84]],"id":38251452}],"con":true,"img":false}]}
{"op":"mcm","clk":"5322646422","pt":1646322668921,"mc":[{"id":"1.195532878","rc":[{"atb":[[2.6,0]],"id":28753299}],"con":true,"img":false}]}
{"op":"mcm","clk":"5322646842","pt":1646322671829,"mc":[{"id":"1.195532878","rc":[{"atb":[[2.68,6.68]],"id":28753299}],"con":true,"img":false}]}
{"op":"mcm","clk":"5322647250","pt":1646322675137,"mc":[{"id":"1.195532878","rc":[{"atb":[[2.72,0]],"id":40452329},{"atb":[[2.88,0]],"id":38251452},{"atb":[[2.56,0]],"id":39632625},{"atb":[[2.64,0]],"id":28753299}],"con":true,"img":false}]}
{"op":"mcm","clk":"5322647265","pt":1646322675239,"mc":[{"id":"1.195532878","rc":[{"atb":[[2.6,0]],"id":41555107},{"atb":[[2.96,0]],"id":39059999}],"con":true,"img":false}]}
{"op":"mcm","clk":"5322663937","pt":1646322843572,"mc":[{"id":"1.195532878","rc":[{"atb":[[2.56,0]],"id":41555107}],"con":true,"img":false}]}
{"op":"mcm","clk":"5322664239","pt":1646322846448,"mc":[{"id":"1.195532878","rc":[{"atb":[[2.36,8.25]],"id":41555107}],"con":true,"img":false}]}
{"op":"mcm","clk":"5322665324","pt":1646322856888,"mc":[{"id":"1.195532878","rc":[{"atb":[[2.64,7.58]],"id":39632625}],"con":true,"img":false}]}
{"op":"mcm","clk":"5322666445","pt":1646322869768,"mc":[{"id":"1.195532878","rc":[{"atb":[[2.96,6.34]],"id":38251452}],"con":true,"img":false}]}
{"op":"mcm","clk":"5322666457","pt":1646322869878,"mc":[{"id":"1.195532878","rc":[{"atb":[[2.96,6.34]],"id":39059999}],"con":true,"img":false}]}
{"op":"mcm","clk":"5322666478","pt":1646322870080,"mc":[{"id":"1.195532878","rc":[{"atb":[[2.72,7.22]],"id":28753299}],"con":true,"img":false}]}
{"op":"mcm","clk":"5322666510","pt":1646322870410,"mc":[{"id":"1.195532878","rc":[{"atb":[[2.4,8.87]],"id":41555107}],"con":true,"img":false}]}
{"op":"mcm","clk":"5322666543","pt":1646322870715,"mc":[{"id":"1.195532878","rc":[{"atb":[[2.8,6.9]],"id":40452329}],"con":true,"img":false}]}
{"op":"mcm","clk":"5322666774","pt":1646322873364,"mc":[{"id":"1.195532878","rc":[{"atb":[[2.92,0]],"id":39059999}],"con":true,"img":false}]}
{"op":"mcm","clk":"5322667002","pt":1646322876387,"mc":[{"id":"1.195532878","rc":[{"atb":[[3,5.61]],"id":39059999}],"con":true,"img":false}]}
{"op":"mcm","clk":"5322670159","pt":1646322910823,"mc":[{"id":"1.195532878","rc":[{"atb":[[2.76,0]],"id":40452329},{"atb":[[2.92,0]],"id":38251452},{"atb":[[2.6,0]],"id":39632625},{"spn":3.32,"spf":1.0,"id":39632625},{"atb":[[2.68,0]],"id":28753299}],"con":true,"img":false}]}
{"op":"mcm","clk":"5322670796","pt":1646322917850,"mc":[{"id":"1.195532878","rc":[{"atb":[[2.8,0]],"id":40452329},{"atb":[[2.96,0]],"id":38251452},{"atb":[[2.72,0]],"id":28753299}],"con":true,"img":false}]}
{"op":"mcm","clk":"5322670908","pt":1646322919048,"mc":[{"id":"1.195532878","rc":[{"atb":[[3,5.61]],"id":38251452}],"con":true,"img":false}]}
{"op":"mcm","clk":"5322670918","pt":1646322919152,"mc":[{"id":"1.195532878","rc":[{"atb":[[2.84,6.09]],"id":40452329},{"atb":[[2.68,6.68]],"id":39632625}],"con":true,"img":false}]}
{"op":"mcm","clk":"5322670926","pt":1646322919256,"mc":[{"id":"1.195532878","rc":[{"atb":[[2.76,6.37]],"id":28753299}],"con":true,"img":false}]}
{"op":"mcm","clk":"5322672068","pt":1646322933778,"mc":[{"id":"1.195532878","rc":[{"atb":[[2.88,6.61]],"id":40452329}],"con":true,"img":false}]}
{"op":"mcm","clk":"5322672085","pt":1646322934041,"mc":[{"id":"1.195532878","rc":[{"atb":[[2.8,6.9]],"id":28753299}],"con":true,"img":false}]}
{"op":"mcm","clk":"5322672123","pt":1646322934677,"mc":[{"id":"1.195532878","rc":[{"atb":[[3.1,5.91]],"id":38251452}],"con":true,"img":false}]}
{"op":"mcm","clk":"5322685737","pt":1646323104976,"mc":[{"id":"1.195532878","rc":[{"atb":[[2.36,0]],"id":41555107},{"spn":3.34,"spf":1.0,"id":39632625}],"con":true,"img":false}]}
{"op":"mcm","clk":"5322685967","pt":1646323107995,"mc":[{"id":"1.195532878","rc":[{"atb":[[2.44,7.79]],"id":41555107}],"con":true,"img":false}]}
{"op":"mcm","clk":"5322686405","pt":1646323113784,"mc":[{"id":"1.195532878","rc":[{"atb":[[2.4,0]],"id":41555107},{"atb":[[2.96,0]],"id":39059999}],"con":true,"img":false}]}
{"op":"mcm","clk":"5322687261","pt":1646323125499,"mc":[{"id":"1.195532878","rc":[{"atb":[[2.48,8.4]],"id":41555107}],"con":true,"img":false}]}
{"op":"mcm","clk":"5322687290","pt":1646323125766,"mc":[{"id":"1.195532878","rc":[{"atb":[[3.1,5.91]],"id":39059999}],"con":true,"img":false}]}
{"op":"mcm","clk":"5322689258","pt":1646323149900,"mc":[{"id":"1.195532878","rc":[{"atb":[[2.64,0]],"id":39632625}],"con":true,"img":false}]}
{"op":"mcm","clk":"5322689931","pt":1646323156437,"mc":[{"id":"1.195532878","rc":[{"atb":[[2.84,0]],"id":40452329},{"atb":[[3,0]],"id":38251452},{"atb":[[2.76,0]],"id":28753299}],"con":true,"img":false}]}
{"op":"mcm","clk":"5322690344","pt":1646323160458,"mc":[{"id":"1.195532878","rc":[{"atb":[[3.2,5.1]],"id":38251452},{"atb":[[2.84,6.09]],"id":28753299}],"con":true,"img":false}]}
{"op":"mcm","clk":"5322690384","pt":1646323160935,"mc":[{"id":"1.195532878","rc":[{"atb":[[2.92,5.84]],"id":40452329}],"con":true,"img":false}]}
{"op":"mcm","clk":"5322690785","pt":1646323164963,"mc":[{"id":"1.195532878","rc":[{"atb":[[2.72,7.22]],"id":39632625}],"con":true,"img":false}]}
{"op":"mcm","clk":"5322705738","pt":1646323334105,"mc":[{"id":"1.195532878","rc":[{"atb":[[2.32,12.68],[2.06,165.09],[2.44,7.81],[2.18,77.97],[2.48,8.4]],"id":41555107},{"atb":[[2.36,13.18],[2.92,5.85],[2.88,6.61]],"id":40452329},{"atl":[[17,9.5]],"id":40452329},{"atb":[[3.2,5.11],[2.32,12.18],[2.06,165.09],[3.1,5.92]],"id":38251452},{"atl":[[34,15.5]],"id":38251452},{"atb":[[2.36,11.31],[2.72,7.23],[2.06,165.09],[2.68,6.69]],"id":39632625},{"spl":[[1.01,8.22]],"id":39632625},{"spn":3.36,"spf":1.0,"id":39632625},{"atb":[[2.02,10.14],[4.6,25.56],[2.06,165.09],[3.1,5.92],[3.7,37.78],[3,5.62],[2.62,64.81]],"id":39059999},{"atb":[[2.8,6.9],[2.06,176.3],[2.84,6.1],[2.62,64.81]],"id":28753299}],"con":true,"img":false}]}
{"op":"mcm","clk":"5322705748","pt":1646323334216,"mc":[{"id":"1.195532878","rc":[{"atb":[[1.88,115.91]],"id":41555107},{"atl":[[34,15.5]],"id":41555107},{"atl":[[34,15.5],[150,5]],"id":40452329},{"atl":[[150,5]],"id":38251452},{"atl":[[34,15.5],[150,5]],"id":39632625},{"atl":[[150,5]],"id":28753299}],"con":true,"img":false}]}
{"op":"mcm","clk":"5322705757","pt":1646323334319,"mc":[{"id":"1.195532878","rc":[{"atl":[[150,5]],"id":41555107}],"con":true,"img":false}]}
{"op":"mcm","clk":"5322705765","pt":1646323334413,"mc":[{"id":"1.195532878","rc":[{"atl":[[150,5]],"id":39059999}],"con":true,"img":false}]}
{"op":"mcm","clk":"5322706014","pt":1646323337914,"mc":[{"id":"1.195532878","rc":[{"atl":[[16,1.65]],"id":28753299}],"con":true,"img":false}]}
{"op":"mcm","clk":"5322706041","pt":1646323338222,"mc":[{"id":"1.195532878","rc":[{"atb":[[3.95,1.65]],"id":40452329}],"con":true,"img":false}]}
{"op":"mcm","clk":"5322706786","pt":1646323347041,"mc":[{"id":"1.195532878","rc":[{"atb":[[2.44,0]],"id":41555107},{"atb":[[3,0]],"id":39059999}],"con":true,"img":false}]}
{"op":"mcm","clk":"5322706962","pt":1646323349538,"mc":[{"id":"1.195532878","rc":[{"atb":[[1.88,115.91],[2.18,77.97]],"id":40452329}],"con":true,"img":false}]}
{"op":"mcm","clk":"5322707135","pt":1646323351835,"mc":[{"id":"1.195532878","rc":[{"atb":[[2.52,7.39]],"id":41555107}],"con":true,"img":false}]}
{"op":"mcm","clk":"5322707156","pt":1646323352048,"mc":[{"id":"1.195532878","rc":[{"atb":[[4.8,2.96]],"id":39059999}],"con":true,"img":false}]}
{"op":"mcm","clk":"5322709716","pt":1646323383590,"mc":[{"id":"1.195532878","rc":[{"atb":[[2.68,0]],"id":39632625}],"con":true,"img":false}]}
{"op":"mcm","clk":"5322710071","pt":1646323388120,"mc":[{"id":"1.195532878","rc":[{"atb":[[2.76,6.38]],"id":39632625}],"con":true,"img":false}]}
{"op":"mcm","clk":"5322710352","pt":1646323391716,"mc":[{"id":"1.195532878","rc":[{"atb":[[2.02,0]],"id":39059999}],"con":true,"img":false}]}
{"op":"mcm","clk":"5322710360","pt":1646323391819,"mc":[{"id":"1.195532878","rc":[{"atb":[[2.08,10.14]],"id":39059999}],"con":true,"img":false}]}
{"op":"mcm","clk":"5322710688","pt":1646323396031,"mc":[{"id":"1.195532878","rc":[{"atb":[[2.88,0]],"id":40452329},{"spn":5.07,"spf":1.0,"id":40452329},{"atb":[[3.1,0]],"id":38251452},{"spn":3.38,"spf":1.0,"id":39632625},{"atb":[[2.8,0]],"id":28753299}],"con":true,"img":false}]}
{"op":"mcm","clk":"5322711872","pt":1646323409468,"mc":[{"id":"1.195532878","rc":[{"atb":[[3.3,5.4]],"id":38251452}],"con":true,"img":false}]}
{"op":"mcm","clk":"5322711888","pt":1646323409676,"mc":[{"id":"1.195532878","rc":[{"atb":[[2.88,6.61]],"id":28753299}],"con":true,"img":false}]}
{"op":"mcm","clk":"5322711917","pt":1646323409950,"mc":[{"id":"1.195532878","rc":[{"atb":[[2.96,6.34]],"id":40452329}],"con":true,"img":false}]}
{"op":"mcm","clk":"5322728586","pt":1646323586335,"mc":[{"id":"1.195532878","rc":[{"atb":[[3.1,0]],"id":39059999}],"con":true,"img":false}]}
{"op":"mcm","clk":"5322729920","pt":1646323600653,"mc":[{"id":"1.195532878","rc":[{"atb":[[2.48,0]],"id":41555107}],"con":true,"img":false}]}
{"op":"mcm","clk":"5322731157","pt":1646323613576,"mc":[{"id":"1.195532878","rc":[{"atb":[[2.56,7.97]],"id":41555107}],"con":true,"img":false}]}
{"op":"mcm","clk":"5322732813","pt":1646323628905,"mc":[{"id":"1.195532878","rc":[{"atb":[[2.92,0]],"id":40452329},{"atb":[[3.2,0]],"id":38251452},{"atb":[[2.72,0]],"id":39632625},{"atb":[[2.84,0]],"id":28753299}],"con":true,"img":false}]}
{"op":"mcm","clk":"5322733486","pt":1646323634726,"mc":[{"id":"1.195532878","rc":[{"atb":[[2.36,8.26]],"id":38251452}],"con":true,"img":false}]}
{"op":"mcm","clk":"5322733521","pt":1646323634974,"mc":[{"id":"1.195532878","rc":[{"atb":[[2.4,8.02]],"id":40452329},{"atb":[[2.92,5.85]],"id":28753299}],"con":true,"img":false}]}
{"op":"mcm","clk":"5322734850","pt":1646323644532,"mc":[{"id":"1.195532878","rc":[{"atb":[[2.8,6.9]],"id":39632625}],"con":true,"img":false}]}
{"op":"mcm","clk":"5322755017","pt":1646323835996,"mc":[{"id":"1.195532878","rc":[{"atb":[[2.52,0]],"id":41555107},{"spn":3.4,"spf":1.0,"id":39632625}],"con":true,"img":false}]}
{"op":"mcm","clk":"5322755369","pt":1646323838563,"mc":[{"id":"1.195532878","rc":[{"atb":[[2.6,7.03]],"id":41555107}],"con":true,"img":false}]}
{"op":"mcm","clk":"5322758706","pt":1646323865710,"mc":[{"id":"1.195532878","rc":[{"atb":[[2.76,0]],"id":39632625}],"con":true,"img":false}]}
{"op":"mcm","clk":"5322759628","pt":1646323873027,"mc":[{"id":"1.195532878","rc":[{"atb":[[2.84,6.1]],"id":39632625}],"con":true,"img":false}]}
{"op":"mcm","clk":"5322760620","pt":1646323881259,"mc":[{"id":"1.195532878","rc":[{"atb":[[2.96,0]],"id":40452329},{"atb":[[3.3,0]],"id":38251452},{"atb":[[2.88,0]],"id":28753299}],"con":true,"img":false}]}
{"op":"mcm","clk":"5322762555","pt":1646323897854,"mc":[{"id":"1.195532878","rc":[{"atb":[[2.44,8.64]],"id":40452329},{"spn":3.42,"spf":1.0,"id":39632625}],"con":true,"img":false}]}
{"op":"mcm","clk":"5322762601","pt":1646323898264,"mc":[{"id":"1.195532878","rc":[{"atb":[[2.96,6.34]],"id":28753299}],"con":true,"img":false}]}
{"op":"mcm","clk":"5322762701","pt":1646323898902,"mc":[{"id":"1.195532878","rc":[{"atb":[[2.4,8.88]],"id":38251452}],"con":true,"img":false}]}
{"op":"mcm","clk":"5322769663","pt":1646323957256,"mc":[{"id":"1.195532878","rc":[{"atb":[[2.06,165.09]],"id":40452329}],"con":true,"img":false}]}
{"op":"mcm","clk":"5322781609","pt":1646324068640,"mc":[{"id":"1.195532878","rc":[{"atb":[[2.56,0]],"id":41555107}],"con":true,"img":false}]}
{"op":"mcm","clk":"5322782841","pt":1646324080384,"mc":[{"id":"1.195532878","rc":[{"atb":[[2.64,7.58]],"id":41555107}],"con":true,"img":false}]}
{"op":"mcm","clk":"5322785573","pt":1646324104708,"mc":[{"id":"1.195532878","rc":[{"atb":[[2.8,0]],"id":39632625}],"con":true,"img":false}]}
{"op":"mcm","clk":"5322786946","pt":1646324115512,"mc":[{"id":"1.195532878","rc":[{"atb":[[2.92,0]],"id":28753299}],"con":true,"img":false}]}
{"op":"mcm","clk":"5322787442","pt":1646324119298,"mc":[{"id":"1.195532878","rc":[{"atb":[[3,5.62]],"id":28753299}],"con":true,"img":false}]}
{"op":"mcm","clk":"5322787665","pt":1646324121094,"mc":[{"id":"1.195532878","rc":[{"atb":[[2.88,6.61]],"id":39632625}],"con":true,"img":false}]}
{"op":"mcm","clk":"5322788650","pt":1646324130009,"mc":[{"id":"1.195532878","rc":[{"atb":[[2.4,0]],"id":40452329},{"spn":3.44,"spf":1.0,"id":39632625}],"con":true,"img":false}]}
{"op":"mcm","clk":"5322789049","pt":1646324133339,"mc":[{"id":"1.195532878","rc":[{"atb":[[2.48,7.6]],"id":40452329}],"con":true,"img":false}]}
{"op":"mcm","clk":"5322789060","pt":1646324133440,"mc":[{"id":"1.195532878","rc":[{"atb":[[2.36,0]],"id":38251452}],"con":true,"img":false}]}
{"op":"mcm","clk":"5322789425","pt":1646324136399,"mc":[{"id":"1.195532878","rc":[{"atb":[[2.44,7.81]],"id":38251452}],"con":true,"img":false}]}
{"op":"mcm","clk":"5322818014","pt":1646324305523,"mc":[{"id":"1.195532878","rc":[{"atb":[[2.6,0]],"id":41555107}],"con":true,"img":false}]}
{"op":"mcm","clk":"5322818521","pt":1646324310674,"mc":[{"id":"1.195532878","rc":[{"atb":[[2.68,6.69]],"id":41555107}],"con":true,"img":false}]}
{"op":"mcm","clk":"5322821342","pt":1646324338073,"mc":[{"id":"1.195532878","rc":[{"atb":[[2.84,0]],"id":39632625}],"con":true,"img":false}]}
{"op":"mcm","clk":"5322821602","pt":1646324340649,"mc":[{"id":"1.195532878","rc":[{"atb":[[2.92,5.85]],"id":39632625}],"con":true,"img":false}]}
{"op":"mcm","clk":"5322823629","pt":1646324360911,"mc":[{"id":"1.195532878","rc":[{"atb":[[2.96,0]],"id":28753299}],"con":true,"img":false}]}
{"op":"mcm","clk":"5322824771","pt":1646324373412,"mc":[{"id":"1.195532878","rc":[{"atb":[[4.3,1]],"id":39632625},{"trd":[[4.3,2]],"ltp":4.3,"tv":2.0,"id":39632625},{"spn":3.3,"spf":1.0,"id":39632625}],"con":true,"img":false}]}
{"op":"mcm","clk":"5322825049","pt":1646324376512,"mc":[{"id":"1.195532878","rc":[{"atb":[[2.44,0]],"id":40452329},{"atb":[[2.4,0]],"id":38251452}],"con":true,"img":false}]}
{"op":"mcm","clk":"5322825089","pt":1646324376934,"mc":[{"id":"1.195532878","rc":[{"atb":[[3.1,5.92]],"id":28753299}],"con":true,"img":false}]}
{"op":"mcm","clk":"5322825099","pt":1646324377027,"mc":[{"id":"1.195532878","rc":[{"atb":[[4.3,2]],"id":39632625}],"con":true,"img":false}]}
{"op":"mcm","clk":"5322826378","pt":1646324391310,"mc":[{"id":"1.195532878","rc":[{"atb":[[2.52,8.18]],"id":40452329}],"con":true,"img":false}]}
{"op":"mcm","clk":"5322826403","pt":1646324391599,"mc":[{"id":"1.195532878","rc":[{"atb":[[2.48,8.4]],"id":38251452}],"con":true,"img":false}]}
{"op":"mcm","clk":"5322840691","pt":1646324553122,"mc":[{"id":"1.195532878","rc":[{"atb":[[2.64,0]],"id":41555107},{"spn":3.46,"spf":1.0,"id":39632625}],"con":true,"img":false}]}
{"op":"mcm","clk":"5322842112","pt":1646324568561,"mc":[{"id":"1.195532878","rc":[{"atb":[[2.72,7.23]],"id":41555107}],"con":true,"img":false}]}
{"op":"mcm","clk":"5322843437","pt":1646324583077,"mc":[{"id":"1.195532878","rc":[{"atb":[[2.88,0]],"id":39632625}],"con":true,"img":false}]}
{"op":"mcm","clk":"5322844594","pt":1646324594074,"mc":[{"id":"1.195532878","rc":[{"atb":[[3,0]],"id":28753299}],"con":true,"img":false}]}
{"op":"mcm","clk":"5322844803","pt":1646324596265,"mc":[{"id":"1.195532878","rc":[{"atb":[[3.2,5.11]],"id":28753299}],"con":true,"img":false}]}
{"op":"mcm","clk":"5322844987","pt":1646324598355,"mc":[{"id":"1.195532878","rc":[{"atb":[[2.96,6.34]],"id":39632625}],"con":true,"img":false}]}
{"op":"mcm","clk":"5322846316","pt":1646324612309,"mc":[{"id":"1.195532878","rc":[{"atb":[[2.48,0]],"id":40452329},{"atb":[[2.44,0]],"id":38251452}],"con":true,"img":false}]}
{"op":"mcm","clk":"5322846762","pt":1646324617099,"mc":[{"id":"1.195532878","rc":[{"atb":[[2.52,7.39]],"id":38251452},{"spn":3.48,"spf":1.0,"id":39632625}],"con":true,"img":false}]}
{"op":"mcm","clk":"5322846782","pt":1646324617307,"mc":[{"id":"1.195532878","rc":[{"atb":[[2.56,7.21]],"id":40452329}],"con":true,"img":false}]}
{"op":"mcm","clk":"5322864881","pt":1646324786069,"mc":[{"id":"1.195532878","rc":[{"atb":[[2.68,0]],"id":41555107}],"con":true,"img":false}]}
{"op":"mcm","clk":"5322865134","pt":1646324788576,"mc":[{"id":"1.195532878","rc":[{"atb":[[2.76,6.38]],"id":41555107}],"con":true,"img":false}]}
{"op":"mcm","clk":"5322868046","pt":1646324815543,"mc":[{"id":"1.195532878","rc":[{"atb":[[2.92,0]],"id":39632625}],"con":true,"img":false}]}
{"op":"mcm","clk":"5322868311","pt":1646324818376,"mc":[{"id":"1.195532878","rc":[{"atb":[[3,5.62]],"id":39632625}],"con":true,"img":false}]}
{"op":"mcm","clk":"5322869423","pt":1646324829173,"mc":[{"id":"1.195532878","rc":[{"atb":[[3.1,0]],"id":28753299}],"con":true,"img":false}]}
{"op":"mcm","clk":"5322870759","pt":1646324841902,"mc":[{"id":"1.195532878","rc":[{"atb":[[3.3,5.4]],"id":28753299}],"con":true,"img":false}]}
{"op":"mcm","clk":"5322871884","pt":1646324854087,"mc":[{"id":"1.195532878","rc":[{"atb":[[2.52,0]],"id":40452329},{"atb":[[2.48,0]],"id":38251452},{"spn":3.51,"spf":1.0,"id":39632625}],"con":true,"img":false}]}
{"op":"mcm","clk":"5322872743","pt":1646324862970,"mc":[{"id":"1.195532878","rc":[{"atb":[[2.56,7.97]],"id":38251452}],"con":true,"img":false}]}
{"op":"mcm","clk":"5322872770","pt":1646324863293,"mc":[{"id":"1.195532878","rc":[{"atb":[[2.6,7.77]],"id":40452329}],"con":true,"img":false}]}
{"op":"mcm","clk":"5322889194","pt":1646325031808,"mc":[{"id":"1.195532878","rc":[{"atb":[[2.72,0]],"id":41555107}],"con":true,"img":false}]}
{"op":"mcm","clk":"5322890462","pt":1646325044541,"mc":[{"id":"1.195532878","rc":[{"atb":[[2.8,6.9]],"id":41555107}],"con":true,"img":false}]}
{"op":"mcm","clk":"5322891703","pt":1646325058038,"mc":[{"id":"1.195532878","rc":[{"atb":[[2.96,0]],"id":39632625}],"con":true,"img":false}]}
{"op":"mcm","clk":"5322892311","pt":1646325064943,"mc":[{"id":"1.195532878","rc":[{"atb":[[3.2,0]],"id":28753299}],"con":true,"img":false}]}
{"op":"mcm","clk":"5322892600","pt":1646325068167,"mc":[{"id":"1.195532878","rc":[{"atb":[[3.4,4.68]],"id":28753299}],"con":true,"img":false}]}
{"op":"mcm","clk":"5322893380","pt":1646325075506,"mc":[{"id":"1.195532878","rc":[{"atb":[[3.1,5.92]],"id":39632625}],"con":true,"img":false}]}
{"op":"mcm","clk":"5322894648","pt":1646325088994,"mc":[{"id":"1.195532878","rc":[{"atb":[[2.56,0]],"id":40452329},{"atb":[[2.52,0]],"id":38251452}],"con":true,"img":false}]}
{"op":"mcm","clk":"5322894866","pt":1646325091505,"mc":[{"id":"1.195532878","rc":[{"atb":[[2.6,7.03]],"id":38251452}],"con":true,"img":false}]}
{"op":"mcm","clk":"5322894881","pt":1646325091707,"mc":[{"id":"1.195532878","rc":[{"atb":[[2.64,6.85]],"id":40452329}],"con":true,"img":false}]}
{"op":"mcm","clk":"5322911635","pt":1646325266318,"mc":[{"id":"1.195532878","rc":[{"atb":[[2.76,0]],"id":41555107},{"spn":3.56,"spf":1.0,"id":39632625}],"con":true,"img":false}]}
{"op":"mcm","clk":"5322911894","pt":1646325269343,"mc":[{"id":"1.195532878","rc":[{"atb":[[2.84,6.1]],"id":41555107}],"con":true,"img":false}]}
{"op":"mcm","clk":"5322913685","pt":1646325290289,"mc":[{"id":"1.195532878","rc":[{"atb":[[3,0]],"id":39632625}],"con":true,"img":false}]}
{"op":"mcm","clk":"5322913970","pt":1646325293163,"mc":[{"id":"1.195532878","rc":[{"atb":[[2.4,8.02]],"id":39632625}],"con":true,"img":false}]}
{"op":"mcm","clk":"5322925872","pt":1646325422965,"mc":[{"id":"1.195532878","rc":[{"atb":[[2.6,0]],"id":40452329},{"atb":[[2.56,0]],"id":38251452},{"atb":[[3.3,0]],"id":28753299}],"con":true,"img":false}]}
{"op":"mcm","clk":"5322927742","pt":1646325441539,"mc":[{"id":"1.195532878","rc":[{"atb":[[2.64,7.58]],"id":38251452}],"con":true,"img":false}]}
{"op":"mcm","clk":"5322927750","pt":1646325441637,"mc":[{"id":"1.195532878","rc":[{"atb":[[3.5,4.97]],"id":28753299}],"con":true,"img":false}]}
{"op":"mcm","clk":"5322927768","pt":1646325441843,"mc":[{"id":"1.195532878","rc":[{"atb":[[2.68,7.4]],"id":40452329}],"con":true,"img":false}]}
{"op":"mcm","clk":"5322933517","pt":1646325506558,"mc":[{"id":"1.195532878","rc":[{"atb":[[2.8,0]],"id":41555107}],"con":true,"img":false}]}
{"op":"mcm","clk":"5322934724","pt":1646325520161,"mc":[{"id":"1.195532878","rc":[{"atb":[[2.88,6.61]],"id":41555107}],"con":true,"img":false}]}
{"op":"mcm","clk":"5322947244","pt":1646325657811,"mc":[{"id":"1.195532878","rc":[{"atb":[[3.1,0]],"id":39632625},{"spn":3.2,"spf":1.0,"id":39632625}],"con":true,"img":false}]}
{"op":"mcm","clk":"5322947306","pt":1646325658385,"mc":[{"id":"1.195532878","rc":[{"atb":[[2.64,0]],"id":40452329},{"atb":[[2.6,0]],"id":38251452},{"atb":[[3.4,0]],"id":28753299}],"con":true,"img":false}]}
{"op":"mcm","clk":"5322947766","pt":1646325663264,"mc":[{"id":"1.195532878","rc":[{"atb":[[2.72,6.53]],"id":40452329},{"atb":[[3.6,4.32]],"id":28753299}],"con":true,"img":false}]}
{"op":"mcm","clk":"5322947829","pt":1646325663995,"mc":[{"id":"1.195532878","rc":[{"atb":[[2.68,6.69]],"id":38251452}],"con":true,"img":false}]}
{"op":"mcm","clk":"5322948944","pt":1646325675613,"mc":[{"id":"1.195532878","rc":[{"atb":[[2.44,8.64]],"id":39632625}],"con":true,"img":false}]}
{"op":"mcm","clk":"5322955231","pt":1646325742955,"mc":[{"id":"1.195532878","rc":[{"atb":[[2.84,0]],"id":41555107},{"spn":3.22,"spf":1.0,"id":39632625}],"con":true,"img":false}]}
{"op":"mcm","clk":"5322955678","pt":1646325747523,"mc":[{"id":"1.195532878","rc":[{"atb":[[2.92,5.85]],"id":41555107}],"con":true,"img":false}]}
{"op":"mcm","clk":"5322970378","pt":1646325909916,"mc":[{"id":"1.195532878","rc":[{"atb":[[2.4,0]],"id":39632625}],"con":true,"img":false}]}
{"op":"mcm","clk":"5322970594","pt":1646325912128,"mc":[{"id":"1.195532878","rc":[{"atb":[[2.68,0]],"id":40452329},{"atb":[[2.64,0]],"id":38251452},{"atb":[[3.5,0]],"id":28753299}],"con":true,"img":false}]}
{"op":"mcm","clk":"5322970655","pt":1646325912747,"mc":[{"id":"1.195532878","rc":[{"atb":[[2.48,7.6]],"id":39632625}],"con":true,"img":false}]}
{"op":"mcm","clk":"5322971933","pt":1646325925068,"mc":[{"id":"1.195532878","rc":[{"atb":[[2.72,7.23]],"id":38251452}],"con":true,"img":false}]}
{"op":"mcm","clk":"5322971966","pt":1646325925380,"mc":[{"id":"1.195532878","rc":[{"atb":[[2.76,7.06]],"id":40452329}],"con":true,"img":false}]}
{"op":"mcm","clk":"5322971976","pt":1646325925436,"mc":[{"id":"1.195532878","rc":[{"atb":[[3.7,4.61]],"id":28753299}],"con":true,"img":false}]}
{"op":"mcm","clk":"5322978505","pt":1646325988474,"mc":[{"id":"1.195532878","rc":[{"atb":[[2.88,0]],"id":41555107},{"spn":3.24,"spf":1.0,"id":39632625}],"con":true,"img":false}]}
{"op":"mcm","clk":"5322979704","pt":1646325999603,"mc":[{"id":"1.195532878","rc":[{"atb":[[2.96,6.34]],"id":41555107}],"con":true,"img":false}]}
{"op":"mcm","clk":"5322993389","pt":1646326147331,"mc":[{"id":"1.195532878","rc":[{"atb":[[2.72,0]],"id":40452329},{"atb":[[2.68,0]],"id":38251452},{"atb":[[3.6,0]],"id":28753299}],"con":true,"img":false}]}
{"op":"mcm","clk":"5322993654","pt":1646326150477,"mc":[{"id":"1.195532878","rc":[{"atb":[[2.76,6.38]],"id":38251452}],"con":true,"img":false}]}
{"op":"mcm","clk":"5322993678","pt":1646326150687,"mc":[{"id":"1.195532878","rc":[{"atb":[[2.8,6.24]],"id":40452329}],"con":true,"img":false}]}
{"op":"mcm","clk":"5322993699","pt":1646326150896,"mc":[{"id":"1.195532878","rc":[{"atb":[[3.8,4.01]],"id":28753299}],"con":true,"img":false}]}
{"op":"mcm","clk":"5322993787","pt":1646326151840,"mc":[{"id":"1.195532878","rc":[{"atb":[[2.44,0]],"id":39632625}],"con":true,"img":false}]}
{"op":"mcm","clk":"5322994631","pt":1646326162173,"mc":[{"id":"1.195532878","rc":[{"atb":[[2.52,8.18]],"id":39632625}],"con":true,"img":false}]}
{"op":"mcm","clk":"5322999153","pt":1646326222137,"mc":[{"id":"1.195532878","rc":[{"atb":[[2.92,0]],"id":41555107},{"spn":3.26,"spf":1.0,"id":39632625}],"con":true,"img":false}]}
{"op":"mcm","clk":"5322999349","pt":1646326225140,"mc":[{"id":"1.195532878","rc":[{"atb":[[2.36,8.26]],"id":41555107}],"con":true,"img":false}]}
{"op":"mcm","clk":"5323008939","pt":1646326347349,"mc":[{"id":"1.195532878","rc":[{"atb":[[3.95,0]],"id":41555107},{"trd":[[3.95,4]],"ltp":3.95,"tv":4.0,"id":41555107},{"spn":5.35,"spf":1.0,"id":41555107}],"con":true,"img":false}]}
{"op":"mcm","clk":"5323011661","pt":1646326385013,"mc":[{"id":"1.195532878","rc":[{"atb":[[2.48,0]],"id":39632625}],"con":true,"img":false}]}
{"op":"mcm","clk":"5323011857","pt":1646326387561,"mc":[{"id":"1.195532878","rc":[{"atb":[[2.56,7.21]],"id":39632625}],"con":true,"img":false}]}
{"op":"mcm","clk":"5323011914","pt":1646326388345,"mc":[{"id":"1.195532878","rc":[{"atb":[[2.76,0]],"id":40452329},{"atb":[[2.72,0]],"id":38251452},{"atb":[[3.7,0]],"id":28753299}],"con":true,"img":false}]}
{"op":"mcm","clk":"5323013210","pt":1646326404856,"mc":[{"id":"1.195532878","rc":[{"atb":[[2.8,6.9]],"id":38251452}],"con":true,"img":false}]}
{"op":"mcm","clk":"5323013236","pt":1646326405387,"mc":[{"id":"1.195532878","rc":[{"atb":[[3.9,4.28]],"id":28753299}],"con":true,"img":false}]}
{"op":"mcm","clk":"5323013243","pt":1646326405475,"mc":[{"id":"1.195532878","rc":[{"atb":[[2.84,6.75]],"id":40452329}],"con":true,"img":false}]}
{"op":"mcm","clk":"5323017612","pt":1646326465598,"mc":[{"id":"1.195532878","rc":[{"atb":[[2.96,0]],"id":41555107},{"spn":3.28,"spf":1.0,"id":39632625},{"spn":5.14,"spf":1.0,"id":28753299}],"con":true,"img":false}]}
{"op":"mcm","clk":"5323018520","pt":1646326478213,"mc":[{"id":"1.195532878","rc":[{"atb":[[2.4,8.88]],"id":41555107}],"con":true,"img":false}]}
{"op":"mcm","clk":"5323028257","pt":1646326623063,"mc":[{"id":"1.195532878","rc":[{"atb":[[2.8,0]],"id":40452329},{"atb":[[2.76,0]],"id":38251452},{"atb":[[3.8,0]],"id":28753299},{"spn":5.1,"spf":1.0,"id":28753299}],"con":true,"img":false}]}
{"op":"mcm","clk":"5323028456","pt":1646326625836,"mc":[{"id":"1.195532878","rc":[{"atb":[[2.52,0]],"id":39632625}],"con":true,"img":false}]}
{"op":"mcm","clk":"5323028655","pt":1646326628553,"mc":[{"id":"1.195532878","rc":[{"atb":[[2.84,6.1]],"id":38251452}],"con":true,"img":false}]}
{"op":"mcm","clk":"5323028679","pt":1646326628864,"mc":[{"id":"1.195532878","rc":[{"atb":[[4,3.74]],"id":28753299}],"con":true,"img":false}]}
{"op":"mcm","clk":"5323028692","pt":1646326629073,"mc":[{"id":"1.195532878","rc":[{"atb":[[2.88,5.98]],"id":40452329}],"con":true,"img":false}]}
{"op":"mcm","clk":"5323029304","pt":1646326639667,"mc":[{"id":"1.195532878","rc":[{"atb":[[2.6,7.77]],"id":39632625}],"con":true,"img":false}]}
{"op":"mcm","clk":"5323033704","pt":1646326712229,"mc":[{"id":"1.195532878","rc":[{"atb":[[2.36,0]],"id":41555107},{"spn":3.3,"spf":1.0,"id":39632625},{"spn":5.2,"spf":1.0,"id":28753299}],"con":true,"img":false}]}
{"op":"mcm","clk":"5323033861","pt":1646326715345,"mc":[{"id":"1.195532878","rc":[{"atb":[[2.44,7.81]],"id":41555107}],"con":true,"img":false}]}
{"op":"mcm","clk":"5323043552","pt":1646326859696,"mc":[{"id":"1.195532878","rc":[{"atb":[[2.56,0]],"id":39632625}],"con":true,"img":false}]}
{"op":"mcm","clk":"5323043633","pt":1646326861024,"mc":[{"id":"1.195532878","rc":[{"atb":[[2.84,0]],"id":40452329},{"atb":[[2.8,0]],"id":38251452},{"atb":[[3.9,0]],"id":28753299}],"con":true,"img":false}]}
{"op":"mcm","clk":"5323043793","pt":1646326863220,"mc":[{"id":"1.195532878","rc":[{"atb":[[2.64,6.85]],"id":39632625}],"con":true,"img":false}]}
{"op":"mcm","clk":"5323044442","pt":1646326873530,"mc":[{"id":"1.195532878","rc":[{"atb":[[2.88,6.61]],"id":38251452}],"con":true,"img":false}]}
{"op":"mcm","clk":"5323044448","pt":1646326873635,"mc":[{"id":"1.195532878","rc":[{"atb":[[4.2,3.88]],"id":28753299}],"con":true,"img":false}]}
{"op":"mcm","clk":"5323044461","pt":1646326873844,"mc":[{"id":"1.195532878","rc":[{"atb":[[2.92,6.47]],"id":40452329}],"con":true,"img":false}]}
{"op":"mcm","clk":"5323050314","pt":1646326960381,"mc":[{"id":"1.195532878","rc":[{"atb":[[2.4,0]],"id":41555107},{"spn":3.32,"spf":1.0,"id":39632625},{"spn":5.3,"spf":1.0,"id":28753299}],"con":true,"img":false}]}
{"op":"mcm","clk":"5323051171","pt":1646326972239,"mc":[{"id":"1.195532878","rc":[{"atb":[[2.48,8.4]],"id":41555107}],"con":true,"img":false}]}
{"op":"mcm","clk":"5323061209","pt":1646327094169,"mc":[{"id":"1.195532878","rc":[{"atb":[[2.88,0]],"id":40452329},{"atb":[[2.84,0]],"id":38251452},{"atb":[[4,0]],"id":28753299},{"spn":5.1,"spf":1.0,"id":28753299}],"con":true,"img":false}]}
{"op":"mcm","clk":"5323061455","pt":1646327096985,"mc":[{"id":"1.195532878","rc":[{"atb":[[2.96,5.73]],"id":40452329},{"atb":[[4.4,3.3]],"id":28753299}],"con":true,"img":false}]}
{"op":"mcm","clk":"5323061471","pt":1646327097191,"mc":[{"id":"1.195532878","rc":[{"atb":[[2.92,5.85]],"id":38251452},{"atb":[[2.6,0]],"id":39632625}],"con":true,"img":false}]}
{"op":"mcm","clk":"5323062548","pt":1646327108813,"mc":[{"id":"1.195532878","rc":[{"atb":[[2.68,7.4]],"id":39632625}],"con":true,"img":false}]}
{"op":"mcm","clk":"5323064518","pt":1646327131088,"mc":[{"id":"1.195532878","rc":[{"atb":[[1.02,2.24]],"id":39059999}],"con":true,"img":false}]}
{"op":"mcm","clk":"5323064536","pt":1646327131292,"mc":[{"id":"1.195532878","rc":[{"atb":[[1.02,0.31]],"id":39059999}],"con":true,"img":false}]}
{"op":"mcm","clk":"5323064559","pt":1646327131501,"mc":[{"id":"1.195532878","rc":[{"atb":[[1.02,0]],"id":39059999}],"con":true,"img":false}]}
{"op":"mcm","clk":"5323064567","pt":1646327131600,"mc":[{"id":"1.195532878","rc":[{"atb":[[12,0.31]],"id":39059999}],"con":true,"img":false}]}
{"op":"mcm","clk":"5323070350","pt":1646327196520,"mc":[{"id":"1.195532878","rc":[{"atb":[[2.44,0]],"id":41555107},{"spn":3.34,"spf":1.0,"id":39632625},{"spn":16.5,"spf":1.0,"id":39059999},{"spn":5.41,"spf":1.0,"id":28753299}],"con":true,"img":false}]}
{"op":"mcm","clk":"5323070580","pt":1646327198811,"mc":[{"id":"1.195532878","rc":[{"atb":[[2.52,7.39]],"id":41555107}],"con":true,"img":false}]}
{"op":"mcm","clk":"5323082994","pt":1646327331207,"mc":[{"id":"1.195532878","rc":[{"atb":[[2.64,0]],"id":39632625}],"con":true,"img":false}]}
{"op":"mcm","clk":"5323083303","pt":1646327334379,"mc":[{"id":"1.195532878","rc":[{"atb":[[2.72,6.53]],"id":39632625}],"con":true,"img":false}]}
{"op":"mcm","clk":"5323083532","pt":1646327337018,"mc":[{"id":"1.195532878","rc":[{"atb":[[2.92,0]],"id":40452329},{"atb":[[2.88,0]],"id":38251452},{"atb":[[4.2,0]],"id":28753299}],"con":true,"img":false}]}
{"op":"mcm","clk":"5323085284","pt":1646327350659,"mc":[{"id":"1.195532878","rc":[{"atb":[[4.6,3.45]],"id":28753299}],"con":true,"img":false}]}
{"op":"mcm","clk":"5323085293","pt":1646327350768,"mc":[{"id":"1.195532878","rc":[{"atb":[[2.4,8.88]],"id":40452329}],"con":true,"img":false}]}
{"op":"mcm","clk":"5323085433","pt":1646327352174,"mc":[{"id":"1.195532878","rc":[{"atb":[[2.96,6.34]],"id":38251452}],"con":true,"img":false}]}
{"op":"mcm","clk":"5323095218","pt":1646327439956,"mc":[{"id":"1.195532878","rc":[{"atb":[[2.48,0]],"id":41555107},{"spn":3.36,"spf":1.0,"id":39632625},{"spn":5.53,"spf":1.0,"id":28753299}],"con":true,"img":false}]}
{"op":"mcm","clk":"5323096247","pt":1646327450930,"mc":[{"id":"1.195532878","rc":[{"atb":[[2.56,7.97]],"id":41555107}],"con":true,"img":false}]}
{"op":"mcm","clk":"5323107433","pt":1646327569871,"mc":[{"id":"1.195532878","rc":[{"atb":[[2.68,0]],"id":39632625}],"con":true,"img":false}]}
{"op":"mcm","clk":"5323107607","pt":1646327571902,"mc":[{"id":"1.195532878","rc":[{"atb":[[2.96,0]],"id":40452329},{"atb":[[2.92,0]],"id":38251452},{"atb":[[4.4,0]],"id":28753299}],"con":true,"img":false}]}
{"op":"mcm","clk":"5323107966","pt":1646327575581,"mc":[{"id":"1.195532878","rc":[{"atb":[[3,5.62]],"id":38251452}],"con":true,"img":false}]}
{"op":"mcm","clk":"5323107977","pt":1646327575689,"mc":[{"id":"1.195532878","rc":[{"atb":[[4.8,2.96]],"id":28753299}],"con":true,"img":false}]}
{"op":"mcm","clk":"5323107987","pt":1646327575789,"mc":[{"id":"1.195532878","rc":[{"atb":[[2.44,7.81]],"id":40452329}],"con":true,"img":false}]}
{"op":"mcm","clk":"5323108506","pt":1646327581124,"mc":[{"id":"1.195532878","rc":[{"atb":[[2.76,7.06]],"id":39632625}],"con":true,"img":false}]}
{"op":"mcm","clk":"5323114523","pt":1646327643731,"mc":[{"id":"1.195532878","rc":[{"atb":[[4.7,0]],"id":38251452},{"trd":[[4.7,4]],"ltp":4.7,"tv":4.0,"id":38251452},{"spn":3.38,"spf":1.0,"id":39632625},{"spn":5.64,"spf":1.0,"id":28753299}],"con":true,"img":false}]}
{"op":"mcm","clk":"5323114543","pt":1646327643933,"mc":[{"id":"1.195532878","rc":[{"atb":[[4.1,0]],"id":38251452}],"con":true,"img":false}]}
{"op":"mcm","clk":"5323114563","pt":1646327644106,"mc":[{"id":"1.195532878","rc":[{"atb":[[3,0]],"id":41555107},{"atb":[[2.36,2]],"id":38251452}],"con":true,"img":false}]}
{"op":"mcm","clk":"5323114590","pt":1646327644314,"mc":[{"id":"1.195532878","rc":[{"atb":[[3.15,2]],"id":41555107}],"con":true,"img":false}]}
{"op":"mcm","clk":"5323114632","pt":1646327644725,"mc":[{"id":"1.195532878","rc":[{"atb":[[3.05,1.65]],"id":38251452}],"con":true,"img":false}]}
{"op":"mcm","clk":"5323114892","pt":1646327647120,"mc":[{"id":"1.195532878","rc":[{"atb":[[4.2,2]],"id":38251452}],"con":true,"img":false}]}
{"op":"mcm","clk":"5323115841","pt":1646327655621,"mc":[{"id":"1.195532878","rc":[{"atb":[[3.05,0]],"id":38251452}],"con":true,"img":false}]}
{"op":"mcm","clk":"5323117719","pt":1646327673541,"mc":[{"id":"1.195532878","rc":[{"atb":[[2.52,0]],"id":41555107}],"con":true,"img":false}]}
{"op":"mcm","clk":"5323118082","pt":1646327677185,"mc":[{"id":"1.195532878","rc":[{"atb":[[2.6,7.03]],"id":41555107}],"con":true,"img":false}]}
{"op":"mcm","clk":"5323130379","pt":1646327803829,"mc":[{"id":"1.195532878","rc":[{"atb":[[2.72,0]],"id":39632625}],"con":true,"img":false}]}
{"op":"mcm","clk":"5323130545","pt":1646327805816,"mc":[{"id":"1.195532878","rc":[{"atb":[[2.8,6.24]],"id":39632625}],"con":true,"img":false}]}
{"op":"mcm","clk":"5323131888","pt":1646327819927,"mc":[{"id":"1.195532878","rc":[{"atb":[[2.4,0]],"id":40452329},{"atb":[[2.96,0]],"id":38251452},{"atb":[[4.6,0]],"id":28753299}],"con":true,"img":false}]}
{"op":"mcm","clk":"5323133097","pt":1646327831947,"mc":[{"id":"1.195532878","rc":[{"atb":[[3.1,5.92]],"id":38251452}],"con":true,"img":false}]}
{"op":"mcm","clk":"5323133118","pt":1646327832154,"mc":[{"id":"1.195532878","rc":[{"atb":[[2.48,8.4]],"id":40452329}],"con":true,"img":false}]}
{"op":"mcm","clk":"5323140869","pt":1646327915646,"mc":[{"id":"1.195532878","rc":[{"atb":[[2.56,0]],"id":41555107},{"spn":3.4,"spf":1.0,"id":39632625},{"spn":5.1,"spf":1.0,"id":28753299}],"con":true,"img":false}]}
{"op":"mcm","clk":"5323141996","pt":1646327928365,"mc":[{"id":"1.195532878","rc":[{"atb":[[2.64,7.58]],"id":41555107}],"con":true,"img":false}]}
{"op":"mcm","clk":"5323152785","pt":1646328052830,"mc":[{"id":"1.195532878","rc":[{"atb":[[2.44,0]],"id":40452329},{"atb":[[3,0]],"id":38251452},{"atb":[[4.8,0]],"id":28753299}],"con":true,"img":false}]}
{"op":"mcm","clk":"5323152973","pt":1646328055260,"mc":[{"id":"1.195532878","rc":[{"atb":[[2.4,8.02]],"id":38251452}],"con":true,"img":false}]}
{"op":"mcm","clk":"5323152989","pt":1646328055469,"mc":[{"id":"1.195532878","rc":[{"atb":[[2.52,7.39]],"id":40452329},{"atb":[[2.66,6.77]],"id":28753299}],"con":true,"img":false}]}
{"op":"mcm","clk":"5323153961","pt":1646328066467,"mc":[{"id":"1.195532878","rc":[{"atb":[[2.76,0]],"id":39632625}],"con":true,"img":false}]}
{"op":"mcm","clk":"5323154174","pt":1646328068540,"mc":[{"id":"1.195532878","rc":[{"atb":[[2.84,6.75]],"id":39632625}],"con":true,"img":false}]}
{"op":"mcm","clk":"5323154188","pt":1646328068752,"mc":[{"id":"1.195532878","rc":[{"atb":[[2.7,7.31]],"id":28753299}],"con":true,"img":false}]}
{"op":"mcm","clk":"5323161123","pt":1646328148440,"mc":[{"id":"1.195532878","rc":[{"atb":[[2.6,0]],"id":41555107},{"spn":3.42,"spf":1.0,"id":39632625}],"con":true,"img":false}]}
{"op":"mcm","clk":"5323161474","pt":1646328152244,"mc":[{"id":"1.195532878","rc":[{"atb":[[2.68,6.69]],"id":41555107}],"con":true,"img":false}]}
{"op":"mcm","clk":"5323175074","pt":1646328299334,"mc":[{"id":"1.195532878","rc":[{"atb":[[2.8,0]],"id":39632625}],"con":true,"img":false}]}
{"op":"mcm","clk":"5323175215","pt":1646328300438,"mc":[{"id":"1.195532878","rc":[{"atb":[[2.48,0]],"id":40452329},{"atb":[[3.1,0]],"id":38251452}],"con":true,"img":false}]}
{"op":"mcm","clk":"5323175448","pt":1646328302425,"mc":[{"id":"1.195532878","rc":[{"atb":[[2.88,5.98]],"id":39632625}],"con":true,"img":false}]}
{"op":"mcm","clk":"5323175473","pt":1646328302639,"mc":[{"id":"1.195532878","rc":[{"atb":[[2.66,0]],"id":28753299}],"con":true,"img":false}]}
{"op":"mcm","clk":"5323176085","pt":1646328308452,"mc":[{"id":"1.195532878","rc":[{"atb":[[2.74,6.46]],"id":28753299}],"con":true,"img":false}]}
{"op":"mcm","clk":"5323176605","pt":1646328313522,"mc":[{"id":"1.195532878","rc":[{"atb":[[2.44,8.64]],"id":38251452}],"con":true,"img":false}]}
{"op":"mcm","clk":"5323176633","pt":1646328313823,"mc":[{"id":"1.195532878","rc":[{"atb":[[2.56,7.97]],"id":40452329}],"con":true,"img":false}]}
{"op":"mcm","clk":"5323193054","pt":1646328476461,"mc":[{"id":"1.195532878","rc":[{"atb":[[2.64,0]],"id":41555107},{"spn":3.44,"spf":1.0,"id":39632625}],"con":true,"img":false}]}
{"op":"mcm","clk":"5323194018","pt":1646328486083,"mc":[{"id":"1.195532878","rc":[{"atb":[[2.72,7.23]],"id":41555107}],"con":true,"img":false}]}
{"op":"mcm","clk":"5323198532","pt":1646328533565,"mc":[{"id":"1.195532878","rc":[{"atb":[[2.52,0]],"id":40452329}],"con":true,"img":false}]}
{"op":"mcm","clk":"5323198879","pt":1646328536041,"mc":[{"id":"1.195532878","rc":[{"atb":[[2.6,7.03]],"id":40452329}],"con":true,"img":false}]}
{"op":"mcm","clk":"5323200068","pt":1646328547027,"mc":[{"id":"1.195532878","rc":[{"atb":[[2.84,0]],"id":39632625},{"atb":[[2.7,0]],"id":28753299}],"con":true,"img":false}]}
{"op":"mcm","clk":"5323200295","pt":1646328549282,"mc":[{"id":"1.195532878","rc":[{"atb":[[2.4,0]],"id":38251452}],"con":true,"img":false}]}
{"op":"mcm","clk":"5323200562","pt":1646328551543,"mc":[{"id":"1.195532878","rc":[{"atb":[[2.48,7.6]],"id":38251452}],"con":true,"img":false}]}
{"op":"mcm","clk":"5323201405","pt":1646328559967,"mc":[{"id":"1.195532878","rc":[{"atb":[[2.78,6.99]],"id":28753299}],"con":true,"img":false}]}
{"op":"mcm","clk":"5323201431","pt":1646328560279,"mc":[{"id":"1.195532878","rc":[{"atb":[[2.92,6.47]],"id":39632625}],"con":true,"img":false}]}
{"op":"mcm","clk":"5323216355","pt":1646328710247,"mc":[{"id":"1.195532878","rc":[{"atb":[[2.68,0]],"id":41555107},{"spn":3.46,"spf":1.0,"id":39632625}],"con":true,"img":false}]}
{"op":"mcm","clk":"5323216654","pt":1646328713149,"mc":[{"id":"1.195532878","rc":[{"atb":[[2.76,6.38]],"id":41555107}],"con":true,"img":false}]}
{"op":"mcm","clk":"5323217855","pt":1646328723390,"mc":[{"id":"1.195532878","rc":[{"atb":[[3.35,63.83],[3.55,15.69],[3.25,111.11],[3.45,40.82]],"id":41555107},{"atl":[[8,21.38],[7.2,6.44],[7.6,15.12],[8.4,33.71]],"id":41555107},{"atb":[[3.1,71.43],[3,125],[3.3,17.39],[3.2,45.45]],"id":40452329},{"atl":[[7.4,23.44],[6.6,7.14],[7,16.67],[7.8,36.76]],"id":40452329},{"atb":[[2.36,0],[3.45,102.04],[3.55,58.82],[3.75,14.55],[3.65,37.74]],"id":38251452},{"atl":[[9.6,29.07],[9.2,18.29],[8.8,12.82],[8.4,5.41]],"id":38251452},{"atb":[[3.45,40.82],[3.35,63.83],[3.55,15.69],[3.25,111.11]],"id":39632625},{"atl":[[8,21.43],[7.2,6.45],[6.8,0],[7.6,15.15],[8.4,33.78]],"id":39632625},{"atb":[[8,5.71],[6.8,43.1],[7.2,24.19],[7.6,15.15]],"id":39059999},{"atl":[[36,1.14],[40,2.56],[44,3.49],[48,5.32]],"id":39059999},{"atb":[[4,83.33],[4.6,11.11],[6.2,0],[4.4,29.41],[4.2,46.88]],"id":28753299},{"atl":[[16.5,9.88],[17.5,15.15],[13.5,0],[14.5,2.96],[15.5,6.9]],"id":28753299}],"con":true,"img":false}]}
{"op":"mcm","clk":"5323217877","pt":1646328723599,"mc":[{"id":"1.195532878","rc":[{"atl":[[9.2,1.23]],"id":39632625},{"atl":[[32,0.53]],"id":39059999},{"atb":[[4.6,13.11]],"id":28753299},{"atl":[[11.5,0.96]],"id":28753299}],"con":true,"img":false}]}
{"op":"mcm","clk":"5323218086","pt":1646328725220,"mc":[{"id":"1.195532878","rc":[{"atl":[[7.2,0],[7.6,6.06]],"id":39632625},{"atl":[[12.5,3.48],[14.5,0]],"id":28753299}],"con":true,"img":false}]}
{"op":"mcm","clk":"5323218956","pt":1646328732521,"mc":[{"id":"1.195532878","rc":[{"atl":[[12.5,9.2],[15.5,15.2]],"id":41555107},{"atl":[[11,9.2],[14,15.2]],"id":40452329},{"atl":[[18.5,15.2],[14.5,9.2]],"id":38251452},{"atl":[[17.5,15.2],[14,9.2]],"id":39632625}],"con":true,"img":false}]}
{"op":"mcm","clk":"5323219274","pt":1646328735202,"mc":[{"id":"1.195532878","rc":[{"atl":[[8,5.71],[7.6,0]],"id":39632625},{"atl":[[13.5,8]],"id":28753299}],"con":true,"img":false}]}
{"op":"mcm","clk":"5323220446","pt":1646328745315,"mc":[{"id":"1.195532878","rc":[{"atl":[[8.4,13.51]],"id":39632625},{"atl":[[17.5,0],[14.5,11.11]],"id":28753299}],"con":true,"img":false}]}
{"op":"mcm","clk":"5323221695","pt":1646328755258,"mc":[{"id":"1.195532878","rc":[{"atl":[[8,0],[8.4,5.41]],"id":39632625},{"atl":[[16.5,0.2],[15.5,17.24]],"id":28753299}],"con":true,"img":false}]}
{"op":"mcm","clk":"5323222818","pt":1646328765223,"mc":[{"id":"1.195532878","rc":[{"atl":[[8.8,5.13],[8.4,0]],"id":39632625}],"con":true,"img":false}]}
{"op":"mcm","clk":"5323222939","pt":1646328766327,"mc":[{"id":"1.195532878","rc":[{"atb":[[2.56,0]],"id":40452329}],"con":true,"img":false}]}
{"op":"mcm","clk":"5323223887","pt":1646328775257,"mc":[{"id":"1.195532878","rc":[{"atl":[[9.2,6.11]],"id":39632625},{"spn":3.79,"spf":1.0,"id":39632625},{"spn":5.28,"spf":1.0,"id":28753299}],"con":true,"img":false}]}
{"op":"mcm","clk":"5323223902","pt":1646328775393,"mc":[{"id":"1.195532878","rc":[{"atl":[[8.8,0]],"id":39632625}],"con":true,"img":false}]}
{"op":"mcm","clk":"5323224068","pt":1646328776681,"mc":[{"id":"1.195532878","rc":[{"atl":[[9,1.65]],"id":39632625}],"con":true,"img":false}]}
{"op":"mcm","clk":"5323224295","pt":1646328778617,"mc":[{"id":"1.195532878","rc":[{"atb":[[2.64,7.58]],"id":40452329}],"con":true,"img":false}]}
{"op":"mcm","clk":"5323224539","pt":1646328780940,"mc":[{"id":"1.195532878","rc":[{"atb":[[2.88,0]],"id":39632625},{"atb":[[2.74,0]],"id":28753299}],"con":true,"img":false}]}
{"op":"mcm","clk":"5323224594","pt":1646328781567,"mc":[{"id":"1.195532878","rc":[{"atl":[[16,0]],"id":28753299}],"con":true,"img":false}]}
{"op":"mcm","clk":"5323224647","pt":1646328782040,"mc":[{"id":"1.195532878","rc":[{"atl":[[12,1.65]],"id":28753299}],"con":true,"img":false}]}
{"op":"mcm","clk":"5323225181","pt":1646328785244,"mc":[{"id":"1.195532878","rc":[{"atl":[[9.2,1.23],[9.4,4.96]],"id":39632625}],"con":true,"img":false}]}
{"op":"mcm","clk":"5323225224","pt":1646328785674,"mc":[{"id":"1.195532878","rc":[{"atb":[[8,0]],"id":28753299},{"trd":[[8,3.99]],"ltp":8.0,"tv":3.99,"id":28753299}],"con":true,"img":false}]}
{"op":"mcm","clk":"5323225245","pt":1646328785828,"mc":[{"id":"1.195532878","rc":[{"atb":[[4.8,2.96]],"id":28753299}],"con":true,"img":false}]}
{"op":"mcm","clk":"5323225277","pt":1646328785933,"mc":[{"id":"1.195532878","rc":[{"atb":[[2.96,5.73]],"id":39632625}],"con":true,"img":false}]}
{"op":"mcm","clk":"5323225806","pt":1646328789246,"mc":[{"id":"1.195532878","rc":[{"atb":[[7,2]],"id":28753299}],"con":true,"img":false}]}
{"op":"mcm","clk":"5323226146","pt":1646328791032,"mc":[{"id":"1.195532878","rc":[{"atb":[[2.44,0]],"id":38251452}],"con":true,"img":false}]}
{"op":"mcm","clk":"5323226691","pt":1646328795270,"mc":[{"id":"1.195532878","rc":[{"atl":[[9.8,11.36]],"id":39632625},{"atb":[[4.5,5.05]],"id":28753299}],"con":true,"img":false}]}
{"op":"mcm","clk":"5323226711","pt":1646328795433,"mc":[{"id":"1.195532878","rc":[{"atb":[[4.5,0]],"id":28753299}],"con":true,"img":false}]}
{"op":"mcm","clk":"5323227868","pt":1646328805274,"mc":[{"id":"1.195532878","rc":[{"atl":[[10.5,15.79]],"id":39632625}],"con":true,"img":false}]}
{"op":"mcm","clk":"5323227895","pt":1646328805435,"mc":[{"id":"1.195532878","rc":[{"atb":[[2.52,8.18]],"id":38251452}],"con":true,"img":false}]}
{"op":"mcm","clk":"5323229237","pt":1646328815277,"mc":[{"id":"1.195532878","rc":[{"atl":[[10,4.26],[11.5,23.81]],"id":39632625}],"con":true,"img":false}]}
{"op":"mcm","clk":"5323229255","pt":1646328815484,"mc":[{"id":"1.195532878","rc":[{"atl":[[10,0]],"id":39632625}],"con":true,"img":false}]}
{"op":"mcm","clk":"5323245075","pt":1646328948193,"mc":[{"id":"1.195532878","rc":[{"atb":[[2.72,0]],"id":41555107},{"spn":5.13,"spf":1.0,"id":28753299}],"con":true,"img":false}]}
{"op":"mcm","clk":"5323246246","pt":1646328959315,"mc":[{"id":"1.195532878","rc":[{"atb":[[2.8,6.9]],"id":41555107},{"atb":[[2.78,0]],"id":28753299}],"con":true,"img":false}]}
{"op":"mcm","clk":"5323247846","pt":1646328972146,"mc":[{"id":"1.195532878","rc":[{"atb":[[4.4,33.06]],"id":28753299}],"con":true,"img":false}]}
{"op":"mcm","clk":"5323250999","pt":1646329000581,"mc":[{"id":"1.195532878","rc":[{"atb":[[2.6,0]],"id":40452329}],"con":true,"img":false}]}
{"op":"mcm","clk":"5323251591","pt":1646329005879,"mc":[{"id":"1.195532878","rc":[{"atb":[[2.68,6.69]],"id":40452329}],"con":true,"img":false}]}
{"op":"mcm","clk":"5323253286","pt":1646329020807,"mc":[{"id":"1.195532878","rc":[{"atb":[[4.8,0]],"id":28753299},{"spn":5.1,"spf":1.0,"id":28753299}],"con":true,"img":false}]}
{"op":"mcm","clk":"5323253634","pt":1646329023691,"mc":[{"id":"1.195532878","rc":[{"atb":[[4.4,36.37]],"id":28753299}],"con":true,"img":false}]}
{"op":"mcm","clk":"5323253646","pt":1646329023806,"mc":[{"id":"1.195532878","rc":[{"atb":[[2.48,0]],"id":38251452}],"con":true,"img":false}]}
{"op":"mcm","clk":"5323253993","pt":1646329026619,"mc":[{"id":"1.195532878","rc":[{"atb":[[2.56,7.21]],"id":38251452}],"con":true,"img":false}]}
{"op":"mcm","clk":"5323254630","pt":1646329032012,"mc":[{"id":"1.195532878","rc":[{"atb":[[2.92,0]],"id":39632625}],"con":true,"img":false}]}
{"op":"mcm","clk":"5323256187","pt":1646329044528,"mc":[{"id":"1.195532878","rc":[{"atb":[[3,6.21]],"id":39632625}],"con":true,"img":false}]}
{"op":"mcm","clk":"5323258702","pt":1646329066448,"mc":[{"id":"1.195532878","rc":[{"atl":[[22,9.2],[29,15.2]],"id":28753299}],"con":true,"img":false}]}
{"op":"mcm","clk":"5323259952","pt":1646329078141,"mc":[{"id":"1.195532878","rc":[{"atb":[[1.01,11002]],"id":39632625}],"con":true,"img":false}]}
{"op":"mcm","clk":"5323259972","pt":1646329078332,"mc":[{"id":"1.195532878","rc":[{"atb":[[1.01,11003.99]],"id":39632625}],"con":true,"img":false}]}
{"op":"mcm","clk":"5323260542","pt":1646329083538,"mc":[{"id":"1.195532878","rc":[{"atb":[[1.01,11002]],"id":39632625}],"con":true,"img":false}]}
{"op":"mcm","clk":"5323260555","pt":1646329083637,"mc":[{"id":"1.195532878","rc":[{"atb":[[4.4,1.99]],"id":39632625}],"con":true,"img":false}]}
{"op":"mcm","clk":"5323260563","pt":1646329083739,"mc":[{"id":"1.195532878","rc":[{"atb":[[1.01,11002]],"id":38251452}],"con":true,"img":false}]}
{"op":"mcm","clk":"5323260566","pt":1646329083842,"mc":[{"id":"1.195532878","rc":[{"atb":[[1.01,11003.99]],"id":38251452}],"con":true,"img":false}]}
{"op":"mcm","clk":"5323260593","pt":1646329084061,"mc":[{"id":"1.195532878","rc":[{"atb":[[1.01,11002]],"id":38251452}],"con":true,"img":false}]}
{"op":"mcm","clk":"5323260602","pt":1646329084153,"mc":[{"id":"1.195532878","rc":[{"atb":[[1.02,1.99]],"id":38251452}],"con":true,"img":false}]}
{"op":"mcm","clk":"5323261077","pt":1646329088890,"mc":[{"id":"1.195532878","rc":[{"atb":[[2.36,78.96],[2.02,100]],"id":39632625}],"con":true,"img":false}]}
{"op":"mcm","clk":"5323261705","pt":1646329094345,"mc":[{"id":"1.195532878","rc":[{"atb":[[1.01,11002]],"id":28753299}],"con":true,"img":false}]}
{"op":"mcm","clk":"5323261724","pt":1646329094542,"mc":[{"id":"1.195532878","rc":[{"atb":[[1.01,11003.99]],"id":28753299}],"con":true,"img":false}]}
{"op":"mcm","clk":"5323261747","pt":1646329094804,"mc":[{"id":"1.195532878","rc":[{"atb":[[1.01,11002]],"id":28753299}],"con":true,"img":false}]}
{"op":"mcm","clk":"5323261760","pt":1646329094911,"mc":[{"id":"1.195532878","rc":[{"atb":[[1.02,1.99]],"id":28753299}],"con":true,"img":false}]}
{"op":"mcm","clk":"5323261782","pt":1646329095120,"mc":[{"id":"1.195532878","rc":[{"atb":[[1.01,11002]],"id":40452329}],"con":true,"img":false}]}
{"op":"mcm","clk":"5323261793","pt":1646329095224,"mc":[{"id":"1.195532878","rc":[{"atb":[[1.01,11003.99]],"id":40452329}],"con":true,"img":false}]}
{"op":"mcm","clk":"5323261811","pt":1646329095433,"mc":[{"id":"1.195532878","rc":[{"atb":[[1.01,11002]],"id":40452329}],"con":true,"img":false}]}
{"op":"mcm","clk":"5323261824","pt":1646329095538,"mc":[{"id":"1.195532878","rc":[{"atb":[[3.95,3.64]],"id":40452329}],"con":true,"img":false}]}
{"op":"mcm","clk":"5323261844","pt":1646329095747,"mc":[{"id":"1.195532878","rc":[{"atb":[[1.01,11002]],"id":41555107}],"con":true,"img":false}]}
{"op":"mcm","clk":"5323262355","pt":1646329100934,"mc":[{"id":"1.195532878","rc":[{"atb":[[1.01,11003.99]],"id":41555107}],"con":true,"img":false}]}
{"op":"mcm","clk":"5323262909","pt":1646329106520,"mc":[{"id":"1.195532878","rc":[{"atb":[[1.01,11002]],"id":41555107}],"con":true,"img":false}]}
{"op":"mcm","clk":"5323262920","pt":1646329106623,"mc":[{"id":"1.195532878","rc":[{"atb":[[1.02,1.99]],"id":41555107}],"con":true,"img":false}]}
{"op":"mcm","clk":"5323262967","pt":1646329107138,"mc":[{"id":"1.195532878","rc":[{"atb":[[1.01,11002]],"id":39059999}],"con":true,"img":false}]}
{"op":"mcm","clk":"5323263018","pt":1646329107655,"mc":[{"id":"1.195532878","rc":[{"atb":[[1.01,11003.99]],"id":39059999}],"con":true,"img":false}]}
{"op":"mcm","clk":"5323263055","pt":1646329107921,"mc":[{"id":"1.195532878","rc":[{"atb":[[1.01,11002]],"id":39059999}],"con":true,"img":false}]}
{"op":"mcm","clk":"5323263062","pt":1646329108023,"mc":[{"id":"1.195532878","rc":[{"atb":[[1.02,1.99]],"id":39059999}],"con":true,"img":false}]}
{"op":"mcm","clk":"5323269718","pt":1646329171604,"mc":[{"id":"1.195532878","rc":[{"atb":[[1.01,11004.24]],"id":39632625},{"spn":3.99,"spf":1.0,"id":39632625}],"con":true,"img":false}]}
{"op":"mcm","clk":"5323269742","pt":1646329171813,"mc":[{"id":"1.195532878","rc":[{"atb":[[1.01,11002.83]],"id":39632625}],"con":true,"img":false}]}
{"op":"mcm","clk":"5323269763","pt":1646329172022,"mc":[{"id":"1.195532878","rc":[{"atb":[[1.01,11002]],"id":39632625}],"con":true,"img":false}]}
{"op":"mcm","clk":"5323269773","pt":1646329172124,"mc":[{"id":"1.195532878","rc":[{"atb":[[4.5,0.83]],"id":39632625}],"con":true,"img":false}]}
{"op":"mcm","clk":"5323270948","pt":1646329182817,"mc":[{"id":"1.195532878","rc":[{"atb":[[2.76,0]],"id":41555107}],"con":true,"img":false}]}
{"op":"mcm","clk":"5323271269","pt":1646329185783,"mc":[{"id":"1.195532878","rc":[{"atb":[[2.84,6.1]],"id":41555107}],"con":true,"img":false}]}
{"op":"mcm","clk":"5323277401","pt":1646329243207,"mc":[{"id":"1.195532878","rc":[{"atb":[[2.64,0]],"id":40452329},{"spn":4.09,"spf":1.0,"id":39632625}],"con":true,"img":false}]}
{"op":"mcm","clk":"5323278724","pt":1646329255083,"mc":[{"id":"1.195532878","rc":[{"atb":[[2.72,7.23]],"id":40452329}],"con":true,"img":false}]}
{"op":"mcm","clk":"5323279673","pt":1646329264226,"mc":[{"id":"1.195532878","rc":[{"atb":[[2.96,0]],"id":39632625}],"con":true,"img":false}]}
{"op":"mcm","clk":"5323279986","pt":1646329267004,"mc":[{"id":"1.195532878","rc":[{"atb":[[2.52,0]],"id":38251452}],"con":true,"img":false}]}
{"op":"mcm","clk":"5323280019","pt":1646329267319,"mc":[{"id":"1.195532878","rc":[{"atb":[[3.1,5.35]],"id":39632625}],"con":true,"img":false}]}
{"op":"mcm","clk":"5323281816","pt":1646329283727,"mc":[{"id":"1.195532878","rc":[{"atb":[[2.6,7.77]],"id":38251452}],"con":true,"img":false}]}
{"op":"mcm","clk":"5323284136","pt":1646329304148,"mc":[{"id":"1.195532878","rc":[{"atb":[[3.8,33.1]],"id":38251452},{"atb":[[8.2,13.13]],"id":39059999},{"atb":[[4.7,25.56]],"id":28753299},{"spn":5.16,"spf":1.0,"id":28753299}],"con":true,"img":false}]}
{"op":"mcm","clk":"5323284157","pt":1646329304358,"mc":[{"id":"1.195532878","rc":[{"atb":[[3.6,18.87]],"id":38251452}],"con":true,"img":false}]}
{"op":"mcm","clk":"5323284215","pt":1646329304975,"mc":[{"id":"1.195532878","rc":[{"atb":[[3.6,0]],"id":38251452}],"con":true,"img":false}]}
{"op":"mcm","clk":"5323286495","pt":1646329326739,"mc":[{"id":"1.195532878","rc":[{"atb":[[1.01,11004.52]],"id":38251452},{"atb":[[1.01,11004.52]],"id":28753299}],"con":true,"img":false}]}
{"op":"mcm","clk":"5323286520","pt":1646329326944,"mc":[{"id":"1.195532878","rc":[{"atb":[[1.01,11004.1]],"id":38251452},{"atb":[[1.01,11003.68]],"id":28753299}],"con":true,"img":false}]}
{"op":"mcm","clk":"5323286531","pt":1646329327001,"mc":[{"id":"1.195532878","rc":[{"atb":[[1.01,11002]],"id":38251452},{"atb":[[1.01,11002]],"id":28753299}],"con":true,"img":false}]}
{"op":"mcm","clk":"5323286542","pt":1646329327101,"mc":[{"id":"1.195532878","rc":[{"atb":[[4.3,2.1]],"id":38251452},{"atb":[[7.2,1.68]],"id":28753299}],"con":true,"img":false}]}
{"op":"mcm","clk":"5323286638","pt":1646329328036,"mc":[{"id":"1.195532878","rc":[{"atb":[[4.3,0]],"id":38251452},{"atb":[[7.2,0]],"id":28753299}],"con":true,"img":false}]}
{"op":"mcm","clk":"5323287133","pt":1646329332714,"mc":[{"id":"1.195532878","rc":[{"atb":[[1.01,11004.52]],"id":38251452},{"atb":[[1.01,11004.52]],"id":28753299}],"con":true,"img":false}]}
{"op":"mcm","clk":"5323287151","pt":1646329332921,"mc":[{"id":"1.195532878","rc":[{"atb":[[1.01,11004.1]],"id":38251452},{"atb":[[1.01,11003.68]],"id":28753299}],"con":true,"img":false}]}
{"op":"mcm","clk":"5323287163","pt":1646329333025,"mc":[{"id":"1.195532878","rc":[{"atb":[[1.01,11002]],"id":38251452},{"atb":[[1.01,11002]],"id":28753299}],"con":true,"img":false}]}
{"op":"mcm","clk":"5323287173","pt":1646329333129,"mc":[{"id":"1.195532878","rc":[{"atb":[[4.3,2.1]],"id":38251452},{"atb":[[7.2,1.68]],"id":28753299}],"con":true,"img":false}]}
{"op":"mcm","clk":"5323287196","pt":1646329333337,"mc":[{"id":"1.195532878","rc":[{"atb":[[4.5,4.6]],"id":28753299}],"con":true,"img":false}]}
{"op":"mcm","clk":"5323287209","pt":1646329333438,"mc":[{"id":"1.195532878","rc":[{"atb":[[4.3,0]],"id":38251452},{"atb":[[7.2,0]],"id":28753299}],"con":true,"img":false}]}
{"op":"mcm","clk":"5323287247","pt":1646329333755,"mc":[{"id":"1.195532878","rc":[{"atb":[[4.5,0]],"id":28753299}],"con":true,"img":false}]}
{"op":"mcm","clk":"5323287807","pt":1646329338439,"mc":[{"id":"1.195532878","rc":[{"atb":[[1.01,11004.52]],"id":38251452}],"con":true,"img":false}]}
{"op":"mcm","clk":"5323287819","pt":1646329338539,"mc":[{"id":"1.195532878","rc":[{"atb":[[1.01,11004.52]],"id":28753299}],"con":true,"img":false}]}
{"op":"mcm","clk":"5323287829","pt":1646329338645,"mc":[{"id":"1.195532878","rc":[{"atb":[[1.01,11004.1]],"id":38251452}],"con":true,"img":false}]}
{"op":"mcm","clk":"5323287842","pt":1646329338748,"mc":[{"id":"1.195532878","rc":[{"atb":[[1.01,11002]],"id":38251452},{"atb":[[1.01,11003.68]],"id":28753299}],"con":true,"img":false}]}
{"op":"mcm","clk":"5323287854","pt":1646329338851,"mc":[{"id":"1.195532878","rc":[{"atb":[[4.3,2.1]],"id":38251452}],"con":true,"img":false}]}
{"op":"mcm","clk":"5323287866","pt":1646329338959,"mc":[{"id":"1.195532878","rc":[{"atb":[[1.01,11002]],"id":28753299}],"con":true,"img":false}]}
{"op":"mcm","clk":"5323287880","pt":1646329339014,"mc":[{"id":"1.195532878","rc":[{"atb":[[7.2,1.68]],"id":28753299}],"con":true,"img":false}]}
{"op":"mcm","clk":"5323287894","pt":1646329339115,"mc":[{"id":"1.195532878","rc":[{"atb":[[4.3,0]],"id":38251452}],"con":true,"img":false}]}
{"op":"mcm","clk":"5323287923","pt":1646329339321,"mc":[{"id":"1.195532878","rc":[{"atb":[[7.2,0]],"id":28753299}],"con":true,"img":false}]}
{"op":"mcm","clk":"5323288501","pt":1646329344165,"mc":[{"id":"1.195532878","rc":[{"atb":[[1.01,11004.52]],"id":38251452}],"con":true,"img":false}]}
{"op":"mcm","clk":"5323288511","pt":1646329344222,"mc":[{"id":"1.195532878","rc":[{"atb":[[1.01,11004.52]],"id":28753299}],"con":true,"img":false}]}
{"op":"mcm","clk":"5323288524","pt":1646329344324,"mc":[{"id":"1.195532878","rc":[{"atb":[[1.01,11004.1]],"id":38251452}],"con":true,"img":false}]}
{"op":"mcm","clk":"5323288537","pt":1646329344428,"mc":[{"id":"1.195532878","rc":[{"atb":[[1.01,11003.68]],"id":28753299}],"con":true,"img":false}]}
{"op":"mcm","clk":"5323288546","pt":1646329344530,"mc":[{"id":"1.195532878","rc":[{"atb":[[1.01,11002]],"id":38251452}],"con":true,"img":false}]}
{"op":"mcm","clk":"5323288556","pt":1646329344635,"mc":[{"id":"1.195532878","rc":[{"atb":[[4.3,2.1]],"id":38251452},{"atb":[[1.01,11002]],"id":28753299}],"con":true,"img":false}]}
{"op":"mcm","clk":"5323288567","pt":1646329344737,"mc":[{"id":"1.195532878","rc":[{"atb":[[7.2,1.68]],"id":28753299}],"con":true,"img":false}]}
{"op":"mcm","clk":"5323288583","pt":1646329344945,"mc":[{"id":"1.195532878","rc":[{"atb":[[4.3,0]],"id":38251452},{"atb":[[7.2,0]],"id":28753299}],"con":true,"img":false}]}
{"op":"mcm","clk":"5323289170","pt":1646329350724,"mc":[{"id":"1.195532878","rc":[{"atb":[[1.01,11004.52]],"id":38251452},{"atb":[[1.01,11004.52]],"id":28753299}],"con":true,"img":false}]}
{"op":"mcm","clk":"5323289194","pt":1646329350886,"mc":[{"id":"1.195532878","rc":[{"atb":[[1.01,11004.1]],"id":38251452},{"atb":[[1.01,11003.68]],"id":28753299}],"con":true,"img":false}]}
{"op":"mcm","clk":"5323289202","pt":1646329350990,"mc":[{"id":"1.195532878","rc":[{"atb":[[1.01,11002]],"id":38251452},{"atb":[[1.01,11002]],"id":28753299}],"con":true,"img":false}]}
{"op":"mcm","clk":"5323289211","pt":1646329351099,"mc":[{"id":"1.195532878","rc":[{"atb":[[4.3,2.1]],"id":38251452},{"atb":[[7.2,1.68]],"id":28753299}],"con":true,"img":false}]}
{"op":"mcm","clk":"5323289231","pt":1646329351304,"mc":[{"id":"1.195532878","rc":[{"atb":[[4.3,0]],"id":38251452},{"atb":[[7.2,0]],"id":28753299}],"con":true,"img":false}]}
{"op":"mcm","clk":"5323289802","pt":1646329356726,"mc":[{"id":"1.195532878","rc":[{"atb":[[1.01,11004.52]],"id":38251452},{"atb":[[1.01,11004.52]],"id":28753299}],"con":true,"img":false}]}
{"op":"mcm","clk":"5323289816","pt":1646329356883,"mc":[{"id":"1.195532878","rc":[{"atb":[[1.01,11004.1]],"id":38251452},{"atb":[[1.01,11003.68]],"id":28753299}],"con":true,"img":false}]}
{"op":"mcm","clk":"5323289833","pt":1646329357109,"mc":[{"id":"1.195532878","rc":[{"atb":[[1.01,11002]],"id":38251452},{"atb":[[1.01,11002]],"id":28753299}],"con":true,"img":false}]}
{"op":"mcm","clk":"5323289842","pt":1646329357200,"mc":[{"id":"1.195532878","rc":[{"atb":[[4.3,2.1]],"id":38251452},{"atb":[[7.2,1.68]],"id":28753299}],"con":true,"img":false}]}
{"op":"mcm","clk":"5323289888","pt":1646329357616,"mc":[{"id":"1.195532878","rc":[{"atb":[[4.3,0]],"id":38251452},{"atb":[[7.2,0]],"id":28753299}],"con":true,"img":false}]}
{"op":"mcm","clk":"5323290312","pt":1646329361898,"mc":[{"id":"1.195532878","rc":[{"atb":[[1.01,11004.52]],"id":38251452},{"atb":[[1.01,11004.52]],"id":28753299}],"con":true,"img":false}]}
{"op":"mcm","clk":"5323290328","pt":1646329362100,"mc":[{"id":"1.195532878","rc":[{"atb":[[1.01,11004.1]],"id":38251452},{"atb":[[1.01,11003.68]],"id":28753299}],"con":true,"img":false}]}
{"op":"mcm","clk":"5323290353","pt":1646329362406,"mc":[{"id":"1.195532878","rc":[{"atb":[[1.01,11002]],"id":38251452},{"atb":[[1.01,11002]],"id":28753299}],"con":true,"img":false}]}
{"op":"mcm","clk":"5323290361","pt":1646329362513,"mc":[{"id":"1.195532878","rc":[{"atb":[[4.3,2.1]],"id":38251452},{"atb":[[7.2,1.68]],"id":28753299}],"con":true,"img":false}]}
{"op":"mcm","clk":"5323290393","pt":1646329362924,"mc":[{"id":"1.195532878","rc":[{"atb":[[4.3,0]],"id":38251452},{"atb":[[7.2,0]],"id":28753299}],"con":true,"img":false}]}
{"op":"mcm","clk":"5323290892","pt":1646329367925,"mc":[{"id":"1.195532878","rc":[{"atb":[[1.01,11004.52]],"id":38251452}],"con":true,"img":false}]}
{"op":"mcm","clk":"5323290902","pt":1646329368030,"mc":[{"id":"1.195532878","rc":[{"atb":[[1.01,11004.52]],"id":28753299}],"con":true,"img":false}]}
{"op":"mcm","clk":"5323290909","pt":1646329368087,"mc":[{"id":"1.195532878","rc":[{"atb":[[1.01,11004.1]],"id":38251452}],"con":true,"img":false}]}
{"op":"mcm","clk":"5323290923","pt":1646329368193,"mc":[{"id":"1.195532878","rc":[{"atb":[[1.01,11002]],"id":38251452},{"atb":[[1.01,11003.68]],"id":28753299}],"con":true,"img":false}]}
{"op":"mcm","clk":"5323290931","pt":1646329368297,"mc":[{"id":"1.195532878","rc":[{"atb":[[4.3,2.1]],"id":38251452},{"atb":[[1.01,11002]],"id":28753299}],"con":true,"img":false}]}
{"op":"mcm","clk":"5323290941","pt":1646329368408,"mc":[{"id":"1.195532878","rc":[{"atb":[[7.2,1.68]],"id":28753299}],"con":true,"img":false}]}
{"op":"mcm","clk":"5323290953","pt":1646329368505,"mc":[{"id":"1.195532878","rc":[{"atb":[[3.7,6.77]],"id":38251452}],"con":true,"img":false}]}
{"op":"mcm","clk":"5323290963","pt":1646329368607,"mc":[{"id":"1.195532878","rc":[{"atb":[[4.3,0]],"id":38251452},{"atb":[[7.2,0]],"id":28753299}],"con":true,"img":false}]}
{"op":"mcm","clk":"5323290986","pt":1646329368814,"mc":[{"id":"1.195532878","rc":[{"atb":[[3.7,0]],"id":38251452}],"con":true,"img":false}]}
{"op":"mcm","clk":"5323291498","pt":1646329374119,"mc":[{"id":"1.195532878","rc":[{"atb":[[1.01,11004.52]],"id":38251452}],"con":true,"img":false}]}
{"op":"mcm","clk":"5323291510","pt":1646329374227,"mc":[{"id":"1.195532878","rc":[{"atb":[[1.01,11004.52]],"id":28753299}],"con":true,"img":false}]}
{"op":"mcm","clk":"5323291525","pt":1646329374332,"mc":[{"id":"1.195532878","rc":[{"atb":[[1.01,11004.1]],"id":38251452}],"con":true,"img":false}]}
{"op":"mcm","clk":"5323291543","pt":1646329374543,"mc":[{"id":"1.195532878","rc":[{"atb":[[1.01,11002]],"id":38251452},{"atb":[[1.01,11003.68]],"id":28753299}],"con":true,"img":false}]}
{"op":"mcm","clk":"5323291553","pt":1646329374601,"mc":[{"id":"1.195532878","rc":[{"atb":[[4.3,2.1]],"id":38251452},{"atb":[[1.01,11002]],"id":28753299}],"con":true,"img":false}]}
{"op":"mcm","clk":"5323291563","pt":1646329374704,"mc":[{"id":"1.195532878","rc":[{"atb":[[7.2,1.68]],"id":28753299}],"con":true,"img":false}]}
{"op":"mcm","clk":"5323291577","pt":1646329374920,"mc":[{"id":"1.195532878","rc":[{"atb":[[4.3,0]],"id":38251452},{"atb":[[7.2,0]],"id":28753299}],"con":true,"img":false}]}
{"op":"mcm","clk":"5323292074","pt":1646329379825,"mc":[{"id":"1.195532878","rc":[{"atb":[[1.01,11004.52]],"id":38251452},{"atb":[[1.01,11004.52]],"id":28753299}],"con":true,"img":false}]}
{"op":"mcm","clk":"5323292096","pt":1646329380036,"mc":[{"id":"1.195532878","rc":[{"atb":[[1.01,11004.1]],"id":38251452},{"atb":[[1.01,11003.68]],"id":28753299}],"con":true,"img":false}]}
{"op":"mcm","clk":"5323292123","pt":1646329380244,"mc":[{"id":"1.195532878","rc":[{"atb":[[1.01,11002]],"id":38251452},{"atb":[[1.01,11002]],"id":28753299}],"con":true,"img":false}]}
{"op":"mcm","clk":"5323292138","pt":1646329380301,"mc":[{"id":"1.195532878","rc":[{"atb":[[4.3,2.1]],"id":38251452},{"atb":[[7.2,1.68]],"id":28753299}],"con":true,"img":false}]}
{"op":"mcm","clk":"5323292162","pt":1646329380509,"mc":[{"id":"1.195532878","rc":[{"atb":[[4.3,0]],"id":38251452}],"con":true,"img":false}]}
{"op":"mcm","clk":"5323292172","pt":1646329380609,"mc":[{"id":"1.195532878","rc":[{"atb":[[7.2,0]],"id":28753299}],"con":true,"img":false}]}
{"op":"mcm","clk":"5323292773","pt":1646329385748,"mc":[{"id":"1.195532878","rc":[{"atb":[[1.01,11004.52]],"id":38251452}],"con":true,"img":false}]}
{"op":"mcm","clk":"5323292788","pt":1646329385843,"mc":[{"id":"1.195532878","rc":[{"atb":[[1.01,11004.52]],"id":28753299}],"con":true,"img":false}]}
{"op":"mcm","clk":"5323292799","pt":1646329385897,"mc":[{"id":"1.195532878","rc":[{"atb":[[1.01,11004.1]],"id":38251452}],"con":true,"img":false}]}
{"op":"mcm","clk":"5323292813","pt":1646329386003,"mc":[{"id":"1.195532878","rc":[{"atb":[[1.01,11003.68]],"id":28753299}],"con":true,"img":false}]}
{"op":"mcm","clk":"5323292825","pt":1646329386104,"mc":[{"id":"1.195532878","rc":[{"atb":[[1.01,11002]],"id":38251452},{"atb":[[1.01,11002]],"id":28753299}],"con":true,"img":false}]}
{"op":"mcm","clk":"5323292835","pt":1646329386219,"mc":[{"id":"1.195532878","rc":[{"atb":[[4.3,2.1]],"id":38251452},{"atb":[[7.2,1.68]],"id":28753299}],"con":true,"img":false}]}
{"op":"mcm","clk":"5323292870","pt":1646329386525,"mc":[{"id":"1.195532878","rc":[{"atb":[[4.3,0]],"id":38251452},{"atb":[[7.2,0]],"id":28753299}],"con":true,"img":false}]}
{"op":"mcm","clk":"5323293462","pt":1646329391517,"mc":[{"id":"1.195532878","rc":[{"atb":[[1.01,11004.52]],"id":38251452}],"con":true,"img":false}]}
{"op":"mcm","clk":"5323293473","pt":1646329391630,"mc":[{"id":"1.195532878","rc":[{"atb":[[1.01,11004.52]],"id":28753299}],"con":true,"img":false}]}
{"op":"mcm","clk":"5323293485","pt":1646329391739,"mc":[{"id":"1.195532878","rc":[{"atb":[[1.01,11004.1]],"id":38251452}],"con":true,"img":false}]}
{"op":"mcm","clk":"5323293493","pt":1646329391835,"mc":[{"id":"1.195532878","rc":[{"atb":[[1.01,11003.68]],"id":28753299}],"con":true,"img":false}]}
{"op":"mcm","clk":"5323293505","pt":1646329391940,"mc":[{"id":"1.195532878","rc":[{"atb":[[1.01,11002]],"id":38251452}],"con":true,"img":false}]}
{"op":"mcm","clk":"5323293519","pt":1646329392045,"mc":[{"id":"1.195532878","rc":[{"atb":[[4.3,2.1]],"id":38251452}],"con":true,"img":false}]}
{"op":"mcm","clk":"5323293528","pt":1646329392100,"mc":[{"id":"1.195532878","rc":[{"atb":[[1.01,11002]],"id":28753299}],"con":true,"img":false}]}
{"op":"mcm","clk":"5323293537","pt":1646329392254,"mc":[{"id":"1.195532878","rc":[{"atb":[[4.3,0]],"id":38251452},{"atb":[[7.2,1.68]],"id":28753299}],"con":true,"img":false}]}
{"op":"mcm","clk":"5323293559","pt":1646329392415,"mc":[{"id":"1.195532878","rc":[{"atb":[[7.2,0]],"id":28753299}],"con":true,"img":false}]}
{"op":"mcm","clk":"5323293572","pt":1646329392523,"mc":[{"id":"1.195532878","rc":[{"atb":[[4.5,4.6]],"id":28753299}],"con":true,"img":false}]}
{"op":"mcm","clk":"5323293593","pt":1646329392730,"mc":[{"id":"1.195532878","rc":[{"atb":[[4.5,0]],"id":28753299}],"con":true,"img":false}]}
{"op":"mcm","clk":"5323294047","pt":1646329397324,"mc":[{"id":"1.195532878","rc":[{"atb":[[1.01,11004.52]],"id":38251452},{"atb":[[1.01,11004.52]],"id":28753299}],"con":true,"img":false}]}
{"op":"mcm","clk":"5323294066","pt":1646329397530,"mc":[{"id":"1.195532878","rc":[{"atb":[[1.01,11004.1]],"id":38251452},{"atb":[[1.01,11003.68]],"id":28753299}],"con":true,"img":false}]}
{"op":"mcm","clk":"5323294101","pt":1646329397850,"mc":[{"id":"1.195532878","rc":[{"atb":[[1.01,11002]],"id":38251452},{"atb":[[1.01,11002]],"id":28753299}],"con":true,"img":false}]}
{"op":"mcm","clk":"5323294110","pt":1646329397950,"mc":[{"id":"1.195532878","rc":[{"atb":[[4.3,2.1]],"id":38251452},{"atb":[[7.2,1.68]],"id":28753299}],"con":true,"img":false}]}
{"op":"mcm","clk":"5323294148","pt":1646329398372,"mc":[{"id":"1.195532878","rc":[{"atb":[[4.3,0]],"id":38251452}],"con":true,"img":false}]}
{"op":"mcm","clk":"5323294157","pt":1646329398426,"mc":[{"id":"1.195532878","rc":[{"atb":[[7.2,0]],"id":28753299}],"con":true,"img":false}]}
{"op":"mcm","clk":"5323294605","pt":1646329403032,"mc":[{"id":"1.195532878","rc":[{"atb":[[1.01,11004.52]],"id":28753299}],"con":true,"img":false}]}
{"op":"mcm","clk":"5323294619","pt":1646329403150,"mc":[{"id":"1.195532878","rc":[{"atb":[[1.01,11004.52]],"id":38251452},{"atb":[[1.01,11003.68]],"id":28753299}],"con":true,"img":false}]}
{"op":"mcm","clk":"5323294642","pt":1646329403341,"mc":[{"id":"1.195532878","rc":[{"atb":[[1.01,11004.1]],"id":38251452},{"atb":[[1.01,11002]],"id":28753299}],"con":true,"img":false}]}
{"op":"mcm","clk":"5323294649","pt":1646329403448,"mc":[{"id":"1.195532878","rc":[{"atb":[[7.2,1.68]],"id":28753299}],"con":true,"img":false}]}
{"op":"mcm","clk":"5323294663","pt":1646329403565,"mc":[{"id":"1.195532878","rc":[{"atb":[[1.01,11002]],"id":38251452}],"con":true,"img":false}]}
{"op":"mcm","clk":"5323294671","pt":1646329403662,"mc":[{"id":"1.195532878","rc":[{"atb":[[4.3,2.1]],"id":38251452},{"atb":[[7.2,0]],"id":28753299}],"con":true,"img":false}]}
{"op":"mcm","clk":"5323294708","pt":1646329403955,"mc":[{"id":"1.195532878","rc":[{"atb":[[4.3,0]],"id":38251452}],"con":true,"img":false}]}
{"op":"mcm","clk":"5323295228","pt":1646329408869,"mc":[{"id":"1.195532878","rc":[{"atb":[[1.01,11004.52]],"id":38251452},{"atb":[[1.01,11004.52]],"id":28753299}],"con":true,"img":false}]}
{"op":"mcm","clk":"5323295239","pt":1646329408975,"mc":[{"id":"1.195532878","rc":[{"atb":[[1.01,11003.68]],"id":28753299}],"con":true,"img":false}]}
{"op":"mcm","clk":"5323295248","pt":1646329409069,"mc":[{"id":"1.195532878","rc":[{"atb":[[1.01,11004.1]],"id":38251452},{"atb":[[1.01,11002]],"id":28753299}],"con":true,"img":false}]}
{"op":"mcm","clk":"5323295262","pt":1646329409174,"mc":[{"id":"1.195532878","rc":[{"atb":[[7.2,1.68]],"id":28753299}],"con":true,"img":false}]}
{"op":"mcm","clk":"5323295275","pt":1646329409282,"mc":[{"id":"1.195532878","rc":[{"atb":[[1.01,11002]],"id":38251452}],"con":true,"img":false}]}
{"op":"mcm","clk":"5323295284","pt":1646329409347,"mc":[{"id":"1.195532878","rc":[{"atb":[[4.3,2.1]],"id":38251452},{"atb":[[7.2,0]],"id":28753299}],"con":true,"img":false}]}
{"op":"mcm","clk":"5323295325","pt":1646329409770,"mc":[{"id":"1.195532878","rc":[{"atb":[[4.3,0]],"id":38251452}],"con":true,"img":false}]}
{"op":"mcm","clk":"5323295832","pt":1646329414977,"mc":[{"id":"1.195532878","rc":[{"atb":[[1.01,11004.52]],"id":38251452},{"atb":[[1.01,11004.52]],"id":28753299}],"con":true,"img":false}]}
{"op":"mcm","clk":"5323295855","pt":1646329415178,"mc":[{"id":"1.195532878","rc":[{"atb":[[1.01,11004.1]],"id":38251452},{"atb":[[1.01,11003.68]],"id":28753299}],"con":true,"img":false}]}
{"op":"mcm","clk":"5323295876","pt":1646329415385,"mc":[{"id":"1.195532878","rc":[{"atb":[[1.01,11002]],"id":38251452},{"atb":[[1.01,11002]],"id":28753299}],"con":true,"img":false}]}
{"op":"mcm","clk":"5323295886","pt":1646329415493,"mc":[{"id":"1.195532878","rc":[{"atb":[[4.3,2.1]],"id":38251452},{"atb":[[7.2,1.68]],"id":28753299}],"con":true,"img":false}]}
{"op":"mcm","clk":"5323295908","pt":1646329415653,"mc":[{"id":"1.195532878","rc":[{"atb":[[4.3,0]],"id":38251452},{"atb":[[7.2,0]],"id":28753299}],"con":true,"img":false}]}
{"op":"mcm","clk":"5323296349","pt":1646329419657,"mc":[{"id":"1.195532878","rc":[{"atb":[[2.8,0]],"id":41555107}],"con":true,"img":false}]}
{"op":"mcm","clk":"5323296464","pt":1646329420969,"mc":[{"id":"1.195532878","rc":[{"atb":[[1.01,11004.52]],"id":38251452},{"atb":[[1.01,11004.52]],"id":28753299}],"con":true,"img":false}]}
{"op":"mcm","clk":"5323296483","pt":1646329421173,"mc":[{"id":"1.195532878","rc":[{"atb":[[1.01,11004.1]],"id":38251452},{"atb":[[1.01,11003.68]],"id":28753299}],"con":true,"img":false}]}
{"op":"mcm","clk":"5323296499","pt":1646329421382,"mc":[{"id":"1.195532878","rc":[{"atb":[[1.01,11002]],"id":28753299}],"con":true,"img":false}]}
{"op":"mcm","clk":"5323296507","pt":1646329421487,"mc":[{"id":"1.195532878","rc":[{"atb":[[1.01,11002]],"id":38251452},{"atb":[[7.2,1.68]],"id":28753299}],"con":true,"img":false}]}
{"op":"mcm","clk":"5323296515","pt":1646329421585,"mc":[{"id":"1.195532878","rc":[{"atb":[[4.3,2.1]],"id":38251452}],"con":true,"img":false}]}
{"op":"mcm","clk":"5323296525","pt":1646329421692,"mc":[{"id":"1.195532878","rc":[{"atb":[[7.2,0]],"id":28753299}],"con":true,"img":false}]}
{"op":"mcm","clk":"5323296566","pt":1646329422103,"mc":[{"id":"1.195532878","rc":[{"atb":[[4.3,0]],"id":38251452}],"con":true,"img":false}]}
{"op":"mcm","clk":"5323297066","pt":1646329426866,"mc":[{"id":"1.195532878","rc":[{"atb":[[1.01,11004.52]],"id":38251452}],"con":true,"img":false}]}
{"op":"mcm","clk":"5323297077","pt":1646329427010,"mc":[{"id":"1.195532878","rc":[{"atb":[[1.01,11004.1]],"id":38251452},{"atb":[[1.01,11004.52]],"id":28753299}],"con":true,"img":false}]}
{"op":"mcm","clk":"5323297102","pt":1646329427181,"mc":[{"id":"1.195532878","rc":[{"atb":[[1.01,11002]],"id":38251452},{"atb":[[1.01,11003.68]],"id":28753299}],"con":true,"img":false}]}
{"op":"mcm","clk":"5323297112","pt":1646329427289,"mc":[{"id":"1.195532878","rc":[{"atb":[[4.3,2.1]],"id":38251452},{"atb":[[1.01,11002]],"id":28753299}],"con":true,"img":false}]}
{"op":"mcm","clk":"5323297127","pt":1646329427388,"mc":[{"id":"1.195532878","rc":[{"atb":[[7.2,1.68]],"id":28753299}],"con":true,"img":false}]}
{"op":"mcm","clk":"5323297137","pt":1646329427489,"mc":[{"id":"1.195532878","rc":[{"atb":[[3.7,6.77]],"id":38251452}],"con":true,"img":false}]}
{"op":"mcm","clk":"5323297151","pt":1646329427591,"mc":[{"id":"1.195532878","rc":[{"atb":[[4.3,0]],"id":38251452},{"atb":[[7.2,0]],"id":28753299}],"con":true,"img":false}]}
{"op":"mcm","clk":"5323297185","pt":1646329427911,"mc":[{"id":"1.195532878","rc":[{"atb":[[3.7,0]],"id":38251452}],"con":true,"img":false}]}
{"op":"mcm","clk":"5323297737","pt":1646329432886,"mc":[{"id":"1.195532878","rc":[{"atb":[[1.01,11004.52]],"id":38251452}],"con":true,"img":false}]}
{"op":"mcm","clk":"5323297748","pt":1646329432982,"mc":[{"id":"1.195532878","rc":[{"atb":[[1.01,11004.1]],"id":38251452},{"atb":[[1.01,11004.52]],"id":28753299}],"con":true,"img":false}]}
{"op":"mcm","clk":"5323297771","pt":1646329433194,"mc":[{"id":"1.195532878","rc":[{"atb":[[2.88,6.61]],"id":41555107},{"atb":[[1.01,11002]],"id":38251452},{"atb":[[1.01,11003.68]],"id":28753299}],"con":true,"img":false}]}
{"op":"mcm","clk":"5323297781","pt":1646329433292,"mc":[{"id":"1.195532878","rc":[{"atb":[[4.3,2.1]],"id":38251452}],"con":true,"img":false}]}
{"op":"mcm","clk":"5323297792","pt":1646329433397,"mc":[{"id":"1.195532878","rc":[{"atb":[[1.01,11002]],"id":28753299}],"con":true,"img":false}]}
{"op":"mcm","clk":"5323297799","pt":1646329433493,"mc":[{"id":"1.195532878","rc":[{"atb":[[4.3,0]],"id":38251452},{"atb":[[7.2,1.68]],"id":28753299}],"con":true,"img":false}]}
{"op":"mcm","clk":"5323297825","pt":1646329433703,"mc":[{"id":"1.195532878","rc":[{"atb":[[7.2,0]],"id":28753299}],"con":true,"img":false}]}
{"op":"mcm","clk":"5323298479","pt":1646329439402,"mc":[{"id":"1.195532878","rc":[{"atb":[[1.01,11004.52]],"id":38251452}],"con":true,"img":false}]}
{"op":"mcm","clk":"5323298493","pt":1646329439506,"mc":[{"id":"1.195532878","rc":[{"atb":[[3.8,31.98],[3.4,12.24],[4.2,0]],"id":38251452},{"atl":[[14,3.06]],"id":38251452},{"trd":[[3.8,2.23],[4.2,4]],"ltp":3.8,"tv":6.23,"id":38251452}],"con":true,"img":false}]}
{"op":"mcm","clk":"5323298502","pt":1646329439609,"mc":[{"id":"1.195532878","rc":[{"atb":[[1.01,11004.1]],"id":38251452},{"atl":[[14,2.16]],"id":38251452},{"atb":[[1.01,11004.52]],"id":28753299}],"con":true,"img":false}]}
{"op":"mcm","clk":"5323298512","pt":1646329439718,"mc":[{"id":"1.195532878","rc":[{"atb":[[1.01,11002],[3.8,22.53],[3.4,0]],"id":38251452},{"atl":[[14,0]],"id":38251452},{"trd":[[3.8,21.14]],"ltp":3.8,"tv":21.14,"id":38251452},{"atb":[[1.01,11003.68]],"id":28753299}],"con":true,"img":false}]}
{"op":"mcm","clk":"5323298523","pt":1646329439818,"mc":[{"id":"1.195532878","rc":[{"atb":[[4.3,2.1]],"id":38251452}],"con":true,"img":false}]}
{"op":"mcm","clk":"5323298530","pt":1646329439874,"mc":[{"id":"1.195532878","rc":[{"atb":[[1.01,11002]],"id":28753299}],"con":true,"img":false}]}
{"op":"mcm","clk":"5323298543","pt":1646329440031,"mc":[{"id":"1.195532878","rc":[{"atb":[[4.3,0]],"id":38251452},{"atb":[[7.2,1.68]],"id":28753299}],"con":true,"img":false}]}
{"op":"mcm","clk":"5323298574","pt":1646329440297,"mc":[{"id":"1.195532878","rc":[{"atb":[[3.75,0]],"id":38251452}],"con":true,"img":false}]}
{"op":"mcm","clk":"5323298582","pt":1646329440400,"mc":[{"id":"1.195532878","rc":[{"atb":[[1.02,0],[3.8,20.02]],"id":38251452},{"trd":[[3.8,26.16]],"ltp":3.8,"tv":26.16,"id":38251452},{"atb":[[7.2,0]],"id":28753299}],"con":true,"img":false}]}
{"op":"mcm","clk":"5323298594","pt":1646329440505,"mc":[{"id":"1.195532878","rc":[{"atb":[[3.85,1.99]],"id":38251452}],"con":true,"img":false}]}
{"op":"mcm","clk":"5323298601","pt":1646329440604,"mc":[{"id":"1.195532878","rc":[{"atb":[[3.85,0],[3.8,19.5]],"id":38251452},{"trd":[[3.8,27.2],[3.85,3.98]],"ltp":3.8,"tv":31.18,"id":38251452}],"con":true,"img":false}]}
{"op":"mcm","clk":"5323298625","pt":1646329440816,"mc":[{"id":"1.195532878","rc":[{"atb":[[3.8,16.25]],"id":38251452},{"trd":[[3.8,33.7]],"ltp":3.8,"tv":33.7,"id":38251452}],"con":true,"img":false}]}
{"op":"mcm","clk":"5323298639","pt":1646329440920,"mc":[{"id":"1.195532878","rc":[{"atb":[[3.8,13.22]],"id":38251452},{"trd":[[3.8,39.76]],"ltp":3.8,"tv":39.76,"id":38251452}],"con":true,"img":false}]}
{"op":"mcm","clk":"5323298656","pt":1646329441084,"mc":[{"id":"1.195532878","rc":[{"atb":[[3.6,1.42]],"id":41555107},{"atb":[[3.35,1.36]],"id":40452329},{"atb":[[3.85,1.38]],"id":38251452},{"atb":[[3.6,1.39]],"id":39632625},{"atb":[[8.4,1.4]],"id":39059999},{"atb":[[4.8,1.32]],"id":28753299}],"con":true,"img":false}]}
{"op":"mcm","clk":"5323298829","pt":1646329442696,"mc":[{"id":"1.195532878","rc":[{"atb":[[3.8,0]],"id":38251452}],"con":true,"img":false}]}
{"op":"mcm","clk":"5323298886","pt":1646329443292,"mc":[{"id":"1.195532878","rc":[{"atb":[[3.85,0]],"id":38251452}],"con":true,"img":false}]}
{"op":"mcm","clk":"5323298897","pt":1646329443400,"mc":[{"id":"1.195532878","rc":[{"atb":[[3.7,1.38]],"id":38251452}],"con":true,"img":false}]}
{"op":"mcm","clk":"5323298911","pt":1646329443499,"mc":[{"id":"1.195532878","rc":[{"atb":[[2.46,2]],"id":38251452}],"con":true,"img":false}]}
{"op":"mcm","clk":"5323298961","pt":1646329443912,"mc":[{"id":"1.195532878","rc":[{"atb":[[3.85,2]],"id":38251452}],"con":true,"img":false}]}
{"op":"mcm","clk":"5323298998","pt":1646329444185,"mc":[{"id":"1.195532878","rc":[{"atl":[[7.8,3.84]],"id":38251452}],"con":true,"img":false}]}
{"op":"mcm","clk":"5323299804","pt":1646329451378,"mc":[{"id":"1.195532878","rc":[{"atb":[[4.7,0]],"id":28753299}],"con":true,"img":false}]}
{"op":"mcm","clk":"5323299838","pt":1646329451635,"mc":[{"id":"1.195532878","rc":[{"atb":[[4.6,17.69]],"id":28753299}],"con":true,"img":false}]}
{"op":"mcm","clk":"5323299867","pt":1646329451955,"mc":[{"id":"1.195532878","rc":[{"atb":[[4.8,0]],"id":28753299}],"con":true,"img":false}]}
{"op":"mcm","clk":"5323299883","pt":1646329452065,"mc":[{"id":"1.195532878","rc":[{"atb":[[4.7,1.32]],"id":28753299}],"con":true,"img":false}]}
{"op":"mcm","clk":"5323299892","pt":1646329452165,"mc":[{"id":"1.195532878","rc":[{"atl":[[7,0.82]],"id":41555107},{"atl":[[6.4,0.82]],"id":40452329},{"atl":[[7.6,0.82]],"id":38251452},{"atl":[[9.2,2.05]],"id":39632625},{"atl":[[40,3.38]],"id":39059999},{"atl":[[12,2.48]],"id":28753299}],"con":true,"img":false}]}
{"op":"mcm","clk":"5323299960","pt":1646329452781,"mc":[{"id":"1.195532878","rc":[{"atl":[[7,0.48]],"id":41555107},{"atl":[[6.4,0.44]],"id":40452329},{"atl":[[7.6,0.44]],"id":38251452},{"atl":[[9.2,1.7]],"id":39632625},{"atl":[[40,3.04]],"id":39059999},{"atb":[[4.6,13.11]],"id":28753299},{"atl":[[12,2.1]],"id":28753299}],"con":true,"img":false}]}
{"op":"mcm","clk":"5323300004","pt":1646329453163,"mc":[{"id":"1.195532878","rc":[{"atb":[[3.6,3]],"id":41555107},{"atb":[[3.7,2.97]],"id":38251452},{"atb":[[8.4,2.98]],"id":39059999},{"atb":[[4.7,2.86]],"id":28753299}],"con":true,"img":false}]}
{"op":"mcm","clk":"5323300342","pt":1646329456554,"mc":[{"id":"1.195532878","rc":[{"atl":[[7.8,0]],"id":38251452}],"con":true,"img":false}]}
{"op":"mcm","clk":"5323300388","pt":1646329456960,"mc":[{"id":"1.195532878","rc":[{"atl":[[7.6,4.28]],"id":38251452}],"con":true,"img":false}]}
{"op":"mcm","clk":"5323300397","pt":1646329457063,"mc":[{"id":"1.195532878","rc":[{"atl":[[7.6,3.84]],"id":38251452}],"con":true,"img":false}]}
{"op":"mcm","clk":"5323300409","pt":1646329457172,"mc":[{"id":"1.195532878","rc":[{"atl":[[8.2,0.44]],"id":38251452}],"con":true,"img":false}]}
{"op":"mcm","clk":"5323300451","pt":1646329457589,"mc":[{"id":"1.195532878","rc":[{"atl":[[8.2,0]],"id":38251452}],"con":true,"img":false}]}
{"op":"mcm","clk":"5323300465","pt":1646329457692,"mc":[{"id":"1.195532878","rc":[{"atl":[[7.4,0.44]],"id":38251452}],"con":true,"img":false}]}
{"op":"mcm","clk":"5323300645","pt":1646329459294,"mc":[{"id":"1.195532878","rc":[{"atb":[[8.2,0]],"id":39059999}],"con":true,"img":false}]}
{"op":"mcm","clk":"5323300711","pt":1646329459979,"mc":[{"id":"1.195532878","rc":[{"atb":[[8.4,1.57]],"id":39059999}],"con":true,"img":false}]}
{"op":"mcm","clk":"5323300720","pt":1646329460078,"mc":[{"id":"1.195532878","rc":[{"atb":[[8.2,1.4]],"id":39059999}],"con":true,"img":false}]}
{"op":"mcm","clk":"5323300732","pt":1646329460187,"mc":[{"id":"1.195532878","rc":[{"atb":[[8.4,0]],"id":39059999}],"con":true,"img":false}]}
{"op":"mcm","clk":"5323300742","pt":1646329460289,"mc":[{"id":"1.195532878","rc":[{"atb":[[8.2,2.98]],"id":39059999}],"con":true,"img":false}]}
{"op":"mcm","clk":"5323301174","pt":1646329464098,"mc":[{"id":"1.195532878","rc":[{"atl":[[7.4,6.25]],"id":38251452}],"con":true,"img":false}]}
{"op":"mcm","clk":"5323301459","pt":1646329467153,"mc":[{"id":"1.195532878","rc":[{"atb":[[8.4,12.78]],"id":39059999}],"con":true,"img":false}]}
{"op":"mcm","clk":"5323301513","pt":1646329467675,"mc":[{"id":"1.195532878","rc":[{"atb":[[8.2,1.57]],"id":39059999}],"con":true,"img":false}]}
{"op":"mcm","clk":"5323301524","pt":1646329467780,"mc":[{"id":"1.195532878","rc":[{"atb":[[8.6,1.4]],"id":39059999}],"con":true,"img":false}]}
{"op":"mcm","clk":"5323301566","pt":1646329468296,"mc":[{"id":"1.195532878","rc":[{"atb":[[8.2,0]],"id":39059999}],"con":true,"img":false}]}
{"op":"mcm","clk":"5323301573","pt":1646329468399,"mc":[{"id":"1.195532878","rc":[{"atb":[[8.6,2.98]],"id":39059999}],"con":true,"img":false}]}
{"op":"mcm","clk":"5323301658","pt":1646329469269,"mc":[{"id":"1.195532878","rc":[{"atl":[[7.6,0]],"id":38251452}],"con":true,"img":false}]}
{"op":"mcm","clk":"5323301681","pt":1646329469481,"mc":[{"id":"1.195532878","rc":[{"atl":[[7.4,0.44]],"id":38251452}],"con":true,"img":false}]}
{"op":"mcm","clk":"5323301688","pt":1646329469587,"mc":[{"id":"1.195532878","rc":[{"atl":[[7.2,3.84]],"id":38251452}],"con":true,"img":false}]}
{"op":"mcm","clk":"5323301752","pt":1646329470206,"mc":[{"id":"1.195532878","rc":[{"atl":[[7.4,0]],"id":38251452}],"con":true,"img":false}]}
{"op":"mcm","clk":"5323301761","pt":1646329470255,"mc":[{"id":"1.195532878","rc":[{"atl":[[7,0.44]],"id":38251452}],"con":true,"img":false}]}
{"op":"mcm","clk":"5323301835","pt":1646329471083,"mc":[{"id":"1.195532878","rc":[{"atl":[[7.2,10.09]],"id":38251452}],"con":true,"img":false}]}
{"op":"mcm","clk":"5323302255","pt":1646329474977,"mc":[{"id":"1.195532878","rc":[{"atb":[[8.4,0]],"id":39059999}],"con":true,"img":false}]}
{"op":"mcm","clk":"5323302280","pt":1646329475280,"mc":[{"id":"1.195532878","rc":[{"atb":[[8.6,1.4]],"id":39059999}],"con":true,"img":false}]}
{"op":"mcm","clk":"5323302288","pt":1646329475383,"mc":[{"id":"1.195532878","rc":[{"atb":[[8.2,1.57]],"id":39059999}],"con":true,"img":false}]}
{"op":"mcm","clk":"5323302298","pt":1646329475491,"mc":[{"id":"1.195532878","rc":[{"atb":[[8.6,0]],"id":39059999}],"con":true,"img":false}]}
{"op":"mcm","clk":"5323302307","pt":1646329475591,"mc":[{"id":"1.195532878","rc":[{"atb":[[8.2,2.98]],"id":39059999}],"con":true,"img":false}]}
{"op":"mcm","clk":"5323302489","pt":1646329477458,"mc":[{"id":"1.195532878","rc":[{"atb":[[2.68,0]],"id":40452329}],"con":true,"img":false}]}
{"op":"mcm","clk":"5323302780","pt":1646329480461,"mc":[{"id":"1.195532878","rc":[{"atb":[[2.76,6.38]],"id":40452329}],"con":true,"img":false}]}
{"op":"mcm","clk":"5323302900","pt":1646329481821,"mc":[{"id":"1.195532878","rc":[{"atl":[[7.2,6.25]],"id":38251452}],"con":true,"img":false}]}
{"op":"mcm","clk":"5323303016","pt":1646329483006,"mc":[{"id":"1.195532878","rc":[{"atb":[[8.4,12.78]],"id":39059999}],"con":true,"img":false}]}
{"op":"mcm","clk":"5323303113","pt":1646329483994,"mc":[{"id":"1.195532878","rc":[{"atb":[[8.2,1.57]],"id":39059999}],"con":true,"img":false}]}
{"op":"mcm","clk":"5323303125","pt":1646329484098,"mc":[{"id":"1.195532878","rc":[{"atb":[[8.6,1.4]],"id":39059999}],"con":true,"img":false}]}
{"op":"mcm","clk":"5323303239","pt":1646329485191,"mc":[{"id":"1.195532878","rc":[{"atl":[[7,4.28]],"id":38251452}],"con":true,"img":false}]}
{"op":"mcm","clk":"5323303523","pt":1646329488191,"mc":[{"id":"1.195532878","rc":[{"atl":[[6.8,5.28]],"id":38251452}],"con":true,"img":false}]}
{"op":"mcm","clk":"5323303645","pt":1646329489385,"mc":[{"id":"1.195532878","rc":[{"atl":[[7,3.84]],"id":38251452}],"con":true,"img":false}]}
{"op":"mcm","clk":"5323303660","pt":1646329489491,"mc":[{"id":"1.195532878","rc":[{"atl":[[6.6,0.44]],"id":38251452}],"con":true,"img":false}]}
{"op":"mcm","clk":"5323303780","pt":1646329490580,"mc":[{"id":"1.195532878","rc":[{"atl":[[7.2,0]],"id":38251452}],"con":true,"img":false}]}
{"op":"mcm","clk":"5323304409","pt":1646329497405,"mc":[{"id":"1.195532878","rc":[{"atl":[[7,0]],"id":38251452},{"spn":4.1,"spf":1.0,"id":39632625},{"spn":5.1,"spf":1.0,"id":28753299}],"con":true,"img":false}]}
{"op":"mcm","clk":"5323304453","pt":1646329497820,"mc":[{"id":"1.195532878","rc":[{"atl":[[6.6,4.28]],"id":38251452}],"con":true,"img":false}]}
{"op":"mcm","clk":"5323304463","pt":1646329497921,"mc":[{"id":"1.195532878","rc":[{"atl":[[6.6,3.84]],"id":38251452}],"con":true,"img":false}]}
{"op":"mcm","clk":"5323304471","pt":1646329498024,"mc":[{"id":"1.195532878","rc":[{"atl":[[1000,12.44]],"id":38251452},{"atb":[[3,0]],"id":39632625}],"con":true,"img":false}]}
{"op":"mcm","clk":"5323304755","pt":1646329501002,"mc":[{"id":"1.195532878","rc":[{"atl":[[6.8,0]],"id":38251452},{"atb":[[7,0]],"id":28753299},{"trd":[[7,4]],"ltp":7.0,"tv":4.0,"id":28753299}],"con":true,"img":false}]}
{"op":"mcm","clk":"5323304799","pt":1646329501427,"mc":[{"id":"1.195532878","rc":[{"atb":[[1.01,11004.52]],"id":28753299}],"con":true,"img":false}]}
{"op":"mcm","clk":"5323304820","pt":1646329501638,"mc":[{"id":"1.195532878","rc":[{"atb":[[1.01,11003.68]],"id":28753299}],"con":true,"img":false}]}
{"op":"mcm","clk":"5323304838","pt":1646329501790,"mc":[{"id":"1.195532878","rc":[{"atb":[[1.01,11002]],"id":28753299}],"con":true,"img":false}]}
{"op":"mcm","clk":"5323304850","pt":1646329501894,"mc":[{"id":"1.195532878","rc":[{"atb":[[4.8,1.68]],"id":28753299}],"con":true,"img":false}]}
{"op":"mcm","clk":"5323304858","pt":1646329502002,"mc":[{"id":"1.195532878","rc":[{"atl":[[6.4,4.28]],"id":38251452}],"con":true,"img":false}]}
{"op":"mcm","clk":"5323304867","pt":1646329502105,"mc":[{"id":"1.195532878","rc":[{"atb":[[3.15,0]],"id":41555107},{"atb":[[2.56,0]],"id":38251452}],"con":true,"img":false}]}
{"op":"mcm","clk":"5323305180","pt":1646329504836,"mc":[{"id":"1.195532878","rc":[{"atb":[[2.64,6.85]],"id":38251452}],"con":true,"img":false}]}
{"op":"mcm","clk":"5323305731","pt":1646329510127,"mc":[{"id":"1.195532878","rc":[{"atl":[[6.6,0]],"id":38251452}],"con":true,"img":false}]}
{"op":"mcm","clk":"5323305745","pt":1646329510335,"mc":[{"id":"1.195532878","rc":[{"atb":[[3.2,5.65]],"id":39632625},{"atb":[[1.02,0]],"id":28753299}],"con":true,"img":false}]}
{"op":"mcm","clk":"5323305756","pt":1646329510387,"mc":[{"id":"1.195532878","rc":[{"atl":[[6.2,3.84]],"id":38251452},{"atb":[[4.8,3.67]],"id":28753299}],"con":true,"img":false}]}
{"op":"mcm","clk":"5323305857","pt":1646329511522,"mc":[{"id":"1.195532878","rc":[{"atb":[[4.7,1.32]],"id":28753299}],"con":true,"img":false}]}
{"op":"mcm","clk":"5323305868","pt":1646329511625,"mc":[{"id":"1.195532878","rc":[{"atb":[[4.9,1.54]],"id":28753299}],"con":true,"img":false}]}
{"op":"mcm","clk":"5323305887","pt":1646329511833,"mc":[{"id":"1.195532878","rc":[{"atb":[[4.5,4.56]],"id":28753299}],"con":true,"img":false}]}
{"op":"mcm","clk":"5323305899","pt":1646329511935,"mc":[{"id":"1.195532878","rc":[{"atl":[[6,4.06]],"id":38251452}],"con":true,"img":false}]}
{"op":"mcm","clk":"5323305930","pt":1646329512200,"mc":[{"id":"1.195532878","rc":[{"atb":[[4.8,1.99]],"id":28753299}],"con":true,"img":false}]}
{"op":"mcm","clk":"5323305964","pt":1646329512504,"mc":[{"id":"1.195532878","rc":[{"atl":[[1000,14.52]],"id":28753299}],"con":true,"img":false}]}
{"op":"mcm","clk":"5323305978","pt":1646329512610,"mc":[{"id":"1.195532878","rc":[{"atb":[[3.7,1.59]],"id":38251452}],"con":true,"img":false}]}
{"op":"mcm","clk":"5323305992","pt":1646329512714,"mc":[{"id":"1.195532878","rc":[{"atb":[[1.01,11003.38]],"id":38251452},{"atl":[[1000,13.68]],"id":28753299}],"con":true,"img":false}]}
{"op":"mcm","clk":"5323306020","pt":1646329513021,"mc":[{"id":"1.195532878","rc":[{"atl":[[1000,12]],"id":28753299}],"con":true,"img":false}]}
{"op":"mcm","clk":"5323306030","pt":1646329513124,"mc":[{"id":"1.195532878","rc":[{"atl":[[11.5,2.64]],"id":28753299}],"con":true,"img":false}]}
{"op":"mcm","clk":"5323306062","pt":1646329513435,"mc":[{"id":"1.195532878","rc":[{"atb":[[4.5,0],[4.9,0]],"id":28753299}],"con":true,"img":false}]}
{"op":"mcm","clk":"5323306075","pt":1646329513538,"mc":[{"id":"1.195532878","rc":[{"atb":[[4.7,2.86]],"id":28753299},{"atl":[[12,1.65]],"id":28753299}],"con":true,"img":false}]}
{"op":"mcm","clk":"5323306088","pt":1646329513643,"mc":[{"id":"1.195532878","rc":[{"atl":[[11.5,3.08]],"id":28753299}],"con":true,"img":false}]}
{"op":"mcm","clk":"5323306131","pt":1646329514004,"mc":[{"id":"1.195532878","rc":[{"atb":[[3.65,2.26]],"id":41555107}],"con":true,"img":false}]}
{"op":"mcm","clk":"5323306140","pt":1646329514108,"mc":[{"id":"1.195532878","rc":[{"atb":[[3.4,2.49]],"id":40452329}],"con":true,"img":false}]}
{"op":"mcm","clk":"5323306151","pt":1646329514216,"mc":[{"id":"1.195532878","rc":[{"atb":[[3.65,2.26]],"id":39632625}],"con":true,"img":false}]}
{"op":"mcm","clk":"5323306280","pt":1646329515566,"mc":[{"id":"1.195532878","rc":[{"atl":[[1000,14.52]],"id":41555107}],"con":true,"img":false}]}
{"op":"mcm","clk":"5323306291","pt":1646329515671,"mc":[{"id":"1.195532878","rc":[{"atl":[[1000,14.1]],"id":41555107}],"con":true,"img":false}]}
{"op":"mcm","clk":"5323306321","pt":1646329515831,"mc":[{"id":"1.195532878","rc":[{"atl":[[1000,12]],"id":41555107}],"con":true,"img":false}]}
{"op":"mcm","clk":"5323306331","pt":1646329515936,"mc":[{"id":"1.195532878","rc":[{"atl":[[6.6,2.1]],"id":41555107}],"con":true,"img":false}]}
{"op":"mcm","clk":"5323306455","pt":1646329517328,"mc":[{"id":"1.195532878","rc":[{"atb":[[3.45,3.05]],"id":40452329}],"con":true,"img":false}]}
{"op":"mcm","clk":"5323306528","pt":1646329518058,"mc":[{"id":"1.195532878","rc":[{"atl":[[6.4,0]],"id":38251452}],"con":true,"img":false}]}
{"op":"mcm","clk":"5323306989","pt":1646329522371,"mc":[{"id":"1.195532878","rc":[{"atl":[[8.8,13]],"id":28753299}],"con":true,"img":false}]}
{"op":"mcm","clk":"5323307020","pt":1646329522635,"mc":[{"id":"1.195532878","rc":[{"atl":[[6.2,0]],"id":38251452}],"con":true,"img":false}]}
{"op":"mcm","clk":"5323307078","pt":1646329523361,"mc":[{"id":"1.195532878","rc":[{"atl":[[11.5,1.4]],"id":28753299}],"con":true,"img":false}]}
{"op":"mcm","clk":"5323307106","pt":1646329523652,"mc":[{"id":"1.195532878","rc":[{"atl":[[6,0]],"id":38251452}],"con":true,"img":false}]}
{"op":"mcm","clk":"5323307132","pt":1646329523861,"mc":[{"id":"1.195532878","rc":[{"atl":[[1000,14.52]],"id":28753299}],"con":true,"img":false}]}
{"op":"mcm","clk":"5323307152","pt":1646329524060,"mc":[{"id":"1.195532878","rc":[{"atb":[[1.01,11002]],"id":38251452},{"atl":[[1000,14.1]],"id":28753299}],"con":true,"img":false}]}
{"op":"mcm","clk":"5323307160","pt":1646329524165,"mc":[{"id":"1.195532878","rc":[{"atb":[[3.7,2.97]],"id":38251452}],"con":true,"img":false}]}
{"op":"mcm","clk":"5323307172","pt":1646329524269,"mc":[{"id":"1.195532878","rc":[{"atl":[[1000,12]],"id":28753299}],"con":true,"img":false}]}
{"op":"mcm","clk":"5323307183","pt":1646329524371,"mc":[{"id":"1.195532878","rc":[{"atl":[[1000,12]],"id":38251452},{"atl":[[8.6,2.1]],"id":28753299}],"con":true,"img":false}]}
{"op":"mcm","clk":"5323307199","pt":1646329524473,"mc":[{"id":"1.195532878","rc":[{"atl":[[8.2,0.44]],"id":38251452}],"con":true,"img":false}]}
{"op":"mcm","clk":"5323307366","pt":1646329526140,"mc":[{"id":"1.195532878","rc":[{"atl":[[5.8,4.06]],"id":38251452}],"con":true,"img":false}]}
{"op":"mcm","clk":"5323307396","pt":1646329526451,"mc":[{"id":"1.195532878","rc":[{"atb":[[3.7,1.59]],"id":38251452}],"con":true,"img":false}]}
{"op":"mcm","clk":"5323307406","pt":1646329526555,"mc":[{"id":"1.195532878","rc":[{"atb":[[1.01,11003.38]],"id":38251452}],"con":true,"img":false}]}
{"op":"mcm","clk":"5323307545","pt":1646329527955,"mc":[{"id":"1.195532878","rc":[{"atl":[[5.7,5.48]],"id":38251452}],"con":true,"img":false}]}
{"op":"mcm","clk":"5323307584","pt":1646329528367,"mc":[{"id":"1.195532878","rc":[{"atl":[[12,0]],"id":28753299}],"con":true,"img":false}]}
{"op":"mcm","clk":"5323307631","pt":1646329528778,"mc":[{"id":"1.195532878","rc":[{"atl":[[5.8,3.6],[5.7,0]],"id":38251452},{"trd":[[5.8,0.91],[5.7,10.97]],"ltp":5.8,"tv":11.88,"id":38251452}],"con":true,"img":false}]}
{"op":"mcm","clk":"5323307650","pt":1646329528989,"mc":[{"id":"1.195532878","rc":[{"atb":[[3.9,2]],"id":38251452}],"con":true,"img":false}]}
{"op":"mcm","clk":"5323307672","pt":1646329529151,"mc":[{"id":"1.195532878","rc":[{"atb":[[3.6,4.49]],"id":38251452}],"con":true,"img":false}]}
{"op":"mcm","clk":"5323307724","pt":1646329529667,"mc":[{"id":"1.195532878","rc":[{"atb":[[3.6,0]],"id":38251452}],"con":true,"img":false}]}
{"op":"mcm","clk":"5323307872","pt":1646329531069,"mc":[{"id":"1.195532878","rc":[{"atb":[[2.98,4.49]],"id":38251452}],"con":true,"img":false}]}
{"op":"mcm","clk":"5323307903","pt":1646329531372,"mc":[{"id":"1.195532878","rc":[{"atb":[[2.98,0]],"id":38251452}],"con":true,"img":false}]}
{"op":"mcm","clk":"5323308120","pt":1646329533357,"mc":[{"id":"1.195532878","rc":[{"atb":[[3.65,6.29]],"id":39632625}],"con":true,"img":false}]}
{"op":"mcm","clk":"5323308131","pt":1646329533458,"mc":[{"id":"1.195532878","rc":[{"atb":[[3.65,6.29]],"id":41555107}],"con":true,"img":false}]}
{"op":"mcm","clk":"5323308139","pt":1646329533565,"mc":[{"id":"1.195532878","rc":[{"atb":[[3.6,0]],"id":39632625}],"con":true,"img":false}]}
{"op":"mcm","clk":"5323308149","pt":1646329533668,"mc":[{"id":"1.195532878","rc":[{"atb":[[3.4,6.94]],"id":40452329},{"atb":[[3.7,1.39]],"id":39632625}],"con":true,"img":false}]}
{"op":"mcm","clk":"5323308210","pt":1646329534286,"mc":[{"id":"1.195532878","rc":[{"atb":[[3.6,1.58]],"id":41555107},{"atb":[[3.35,0]],"id":40452329}],"con":true,"img":false}]}
{"op":"mcm","clk":"5323308223","pt":1646329534346,"mc":[{"id":"1.195532878","rc":[{"atb":[[3.7,1.42]],"id":41555107},{"atb":[[3.45,4.42]],"id":40452329}],"con":true,"img":false}]}
{"op":"mcm","clk":"5323308302","pt":1646329535082,"mc":[{"id":"1.195532878","rc":[{"atl":[[5.7,2.8]],"id":38251452}],"con":true,"img":false}]}
{"op":"mcm","clk":"5323308322","pt":1646329535282,"mc":[{"id":"1.195532878","rc":[{"atb":[[3.6,0]],"id":41555107}],"con":true,"img":false}]}
{"op":"mcm","clk":"5323308334","pt":1646329535385,"mc":[{"id":"1.195532878","rc":[{"atb":[[3.7,3]],"id":41555107}],"con":true,"img":false}]}
{"op":"mcm","clk":"5323308439","pt":1646329536271,"mc":[{"id":"1.195532878","rc":[{"atl":[[5.7,2.42]],"id":38251452},{"trd":[[5.7,11.73]],"ltp":5.7,"tv":11.73,"id":38251452}],"con":true,"img":false}]}
{"op":"mcm","clk":"5323308869","pt":1646329540269,"mc":[{"id":"1.195532878","rc":[{"atb":[[3.95,5.48]],"id":38251452}],"con":true,"img":false}]}
{"op":"mcm","clk":"5323308975","pt":1646329541257,"mc":[{"id":"1.195532878","rc":[{"atb":[[3.7,0]],"id":38251452}],"con":true,"img":false}]}
{"op":"mcm","clk":"5323308988","pt":1646329541356,"mc":[{"id":"1.195532878","rc":[{"atb":[[4,1.59]],"id":38251452}],"con":true,"img":false}]}
{"op":"mcm","clk":"5323309012","pt":1646329541563,"mc":[{"id":"1.195532878","rc":[{"atl":[[5.8,0]],"id":38251452}],"con":true,"img":false}]}
{"op":"mcm","clk":"5323309031","pt":1646329541772,"mc":[{"id":"1.195532878","rc":[{"atb":[[1.02,3.64]],"id":41555107},{"atb":[[1.02,1.65]],"id":40452329},{"atb":[[1.02,1.65],[3.9,0]],"id":38251452},{"atb":[[1.01,11003.65]],"id":39632625},{"atb":[[1.02,3.64]],"id":39059999},{"atb":[[1.01,11003.65]],"id":28753299}],"con":true,"img":false}]}
{"op":"mcm","clk":"5323309053","pt":1646329541975,"mc":[{"id":"1.195532878","rc":[{"atb":[[4.1,2]],"id":38251452}],"con":true,"img":false}]}
{"op":"mcm","clk":"5323309062","pt":1646329542080,"mc":[{"id":"1.195532878","rc":[{"atb":[[1.02,3.11]],"id":41555107},{"atb":[[1.02,1.06]],"id":40452329},{"atb":[[1.02,1.04]],"id":38251452},{"atb":[[1.01,11002.93]],"id":39632625},{"atb":[[1.02,2.4]],"id":39059999},{"atb":[[1.01,11002.87]],"id":28753299}],"con":true,"img":false}]}
{"op":"mcm","clk":"5323309074","pt":1646329542185,"mc":[{"id":"1.195532878","rc":[{"atb":[[1.01,11002]],"id":38251452}],"con":true,"img":false}]}
{"op":"mcm","clk":"5323309086","pt":1646329542285,"mc":[{"id":"1.195532878","rc":[{"atb":[[1.02,1.99]],"id":41555107},{"atb":[[1.02,0]],"id":40452329},{"atb":[[4,2.97],[1.02,0]],"id":38251452},{"atb":[[1.01,11002]],"id":39632625},{"atb":[[1.02,1.99]],"id":39059999},{"atb":[[1.01,11002]],"id":28753299}],"con":true,"img":false}]}
{"op":"mcm","clk":"5323309093","pt":1646329542393,"mc":[{"id":"1.195532878","rc":[{"atb":[[3.7,4.13]],"id":41555107},{"atb":[[3.9,3.06]],"id":40452329},{"atb":[[3.95,6.53]],"id":38251452},{"atb":[[4.4,2.92]],"id":39632625},{"atb":[[10,2.41]],"id":39059999},{"atb":[[4.7,3.74]],"id":28753299}],"con":true,"img":false}]}
{"op":"mcm","clk":"5323309173","pt":1646329543168,"mc":[{"id":"1.195532878","rc":[{"atb":[[4,1.55]],"id":40452329}],"con":true,"img":false}]}
{"op":"mcm","clk":"5323309768","pt":1646329549109,"mc":[{"id":"1.195532878","rc":[{"atl":[[5.6,2.42]],"id":38251452}],"con":true,"img":false}]}
{"op":"mcm","clk":"5323309794","pt":1646329549317,"mc":[{"id":"1.195532878","rc":[{"atl":[[5.7,0]],"id":38251452}],"con":true,"img":false}]}
{"op":"mcm","clk":"5323309966","pt":1646329550884,"mc":[{"id":"1.195532878","rc":[{"atl":[[5.6,2.15]],"id":38251452},{"trd":[[5.6,0.53]],"ltp":5.6,"tv":0.53,"id":38251452}],"con":true,"img":false}]}
{"op":"mcm","clk":"5323310043","pt":1646329551707,"mc":[{"id":"1.195532878","rc":[{"atl":[[5.6,0]],"id":38251452},{"trd":[[5.6,4.84]],"ltp":5.6,"tv":4.84,"id":38251452}],"con":true,"img":false}]}
{"op":"mcm","clk":"5323310072","pt":1646329552019,"mc":[{"id":"1.195532878","rc":[{"atb":[[4.1,0]],"id":38251452}],"con":true,"img":false}]}
{"op":"mcm","clk":"5323310127","pt":1646329552492,"mc":[{"id":"1.195532878","rc":[{"atb":[[3.95,1.04]],"id":38251452}],"con":true,"img":false}]}
{"op":"mcm","clk":"5323310160","pt":1646329552805,"mc":[{"id":"1.195532878","rc":[{"atb":[[4.2,5.48]],"id":38251452}],"con":true,"img":false}]}
{"op":"mcm","clk":"5323310198","pt":1646329553220,"mc":[{"id":"1.195532878","rc":[{"atb":[[4,1.59]],"id":38251452}],"con":true,"img":false}]}
{"op":"mcm","clk":"5323310210","pt":1646329553323,"mc":[{"id":"1.195532878","rc":[{"atb":[[4,0],[3.7,1.38]],"id":38251452}],"con":true,"img":false}]}
{"op":"mcm","clk":"5323310225","pt":1646329553430,"mc":[{"id":"1.195532878","rc":[{"atb":[[4.3,1.59]],"id":38251452}],"con":true,"img":false}]}
{"op":"mcm","clk":"5323310242","pt":1646329553488,"mc":[{"id":"1.195532878","rc":[{"atb":[[3.7,0]],"id":38251452}],"con":true,"img":false}]}
{"op":"mcm","clk":"5323310255","pt":1646329553593,"mc":[{"id":"1.195532878","rc":[{"atb":[[4.3,2.97]],"id":38251452}],"con":true,"img":false}]}
{"op":"mcm","clk":"5323310643","pt":1646329557015,"mc":[{"id":"1.195532878","rc":[{"atl":[[8.2,7.68]],"id":38251452}],"con":true,"img":false}]}
{"op":"mcm","clk":"5323311446","pt":1646329564929,"mc":[{"id":"1.195532878","rc":[{"spn":5.25,"spf":1.0,"id":41555107},{"spn":5.1,"spf":1.0,"id":40452329},{"atb":[[1.01,11004.24]],"id":38251452},{"spn":4.19,"spf":1.0,"id":39632625},{"spn":4.95,"spf":1.0,"id":28753299}],"con":true,"img":false}]}
{"op":"mcm","clk":"5323311458","pt":1646329565034,"mc":[{"id":"1.195532878","rc":[{"atb":[[4.2,0]],"id":38251452}],"con":true,"img":false}]}
{"op":"mcm","clk":"5323311489","pt":1646329565296,"mc":[{"id":"1.195532878","rc":[{"atb":[[4.3,1.38]],"id":38251452}],"con":true,"img":false}]}
{"op":"mcm","clk":"5323311502","pt":1646329565400,"mc":[{"id":"1.195532878","rc":[{"atb":[[1.01,11004.18],[4.4,5.48],[3.7,1.59]],"id":38251452}],"con":true,"img":false}]}
{"op":"mcm","clk":"5323311513","pt":1646329565507,"mc":[{"id":"1.195532878","rc":[{"atb":[[4.3,0]],"id":38251452}],"con":true,"img":false}]}
{"op":"mcm","clk":"5323311525","pt":1646329565612,"mc":[{"id":"1.195532878","rc":[{"atb":[[1.01,11002],[3.7,2.97]],"id":38251452}],"con":true,"img":false}]}
{"op":"mcm","clk":"5323311539","pt":1646329565715,"mc":[{"id":"1.195532878","rc":[{"atb":[[3.75,2.18]],"id":38251452}],"con":true,"img":false}]}
{"op":"mcm","clk":"5323311586","pt":1646329566232,"mc":[{"id":"1.195532878","rc":[{"atb":[[3.7,1.59]],"id":38251452}],"con":true,"img":false}]}
{"op":"mcm","clk":"5323311594","pt":1646329566332,"mc":[{"id":"1.195532878","rc":[{"atb":[[4.5,1.38],[3.7,0]],"id":38251452}],"con":true,"img":false}]}
{"op":"mcm","clk":"5323311605","pt":1646329566394,"mc":[{"id":"1.195532878","rc":[{"atb":[[4.5,2.97]],"id":38251452}],"con":true,"img":false}]}
{"op":"mcm","clk":"5323312003","pt":1646329570188,"mc":[{"id":"1.195532878","rc":[{"atb":[[3.75,6.07]],"id":38251452}],"con":true,"img":false}]}
{"op":"mcm","clk":"5323312818","pt":1646329577540,"mc":[{"id":"1.195532878","rc":[{"atb":[[3.75,4.29]],"id":41555107},{"atb":[[3.85,5.62]],"id":39632625},{"atb":[[4.8,6]],"id":28753299}],"con":true,"img":false}]}
{"op":"mcm","clk":"5323312848","pt":1646329577804,"mc":[{"id":"1.195532878","rc":[{"atb":[[4.4,0]],"id":38251452}],"con":true,"img":false}]}
{"op":"mcm","clk":"5323312874","pt":1646329578113,"mc":[{"id":"1.195532878","rc":[{"atb":[[3.7,0]],"id":39632625},{"atb":[[4.7,2.42]],"id":28753299}],"con":true,"img":false}]}
{"op":"mcm","clk":"5323312889","pt":1646329578211,"mc":[{"id":"1.195532878","rc":[{"atb":[[3.7,2.55]],"id":41555107},{"atb":[[4.5,1.38]],"id":38251452},{"atb":[[3.9,1.39]],"id":39632625},{"atb":[[4.9,1.32],[4.7,0.87]],"id":28753299}],"con":true,"img":false}]}
{"op":"mcm","clk":"5323312902","pt":1646329578314,"mc":[{"id":"1.195532878","rc":[{"atb":[[3.8,1.58]],"id":41555107},{"atb":[[3.8,1.59],[4.6,5.48]],"id":38251452},{"atb":[[4.9,2.86]],"id":28753299}],"con":true,"img":false}]}
{"op":"mcm","clk":"5323312917","pt":1646329578417,"mc":[{"id":"1.195532878","rc":[{"atb":[[4.5,4.39]],"id":28753299}],"con":true,"img":false}]}
{"op":"mcm","clk":"5323312966","pt":1646329578939,"mc":[{"id":"1.195532878","rc":[{"atb":[[4.5,0]],"id":38251452}],"con":true,"img":false}]}
{"op":"mcm","clk":"5323312976","pt":1646329579044,"mc":[{"id":"1.195532878","rc":[{"atb":[[4.7,1.38]],"id":38251452}],"con":true,"img":false}]}
{"op":"mcm","clk":"5323312985","pt":1646329579146,"mc":[{"id":"1.195532878","rc":[{"atb":[[4.8,4.01]],"id":28753299}],"con":true,"img":false}]}
{"op":"mcm","clk":"5323312996","pt":1646329579204,"mc":[{"id":"1.195532878","rc":[{"atb":[[5,1.99]],"id":28753299}],"con":true,"img":false}]}
{"op":"mcm","clk":"5323313052","pt":1646329579818,"mc":[{"id":"1.195532878","rc":[{"atb":[[4.9,1.54]],"id":28753299}],"con":true,"img":false}]}
{"op":"mcm","clk":"5323313062","pt":1646329579921,"mc":[{"id":"1.195532878","rc":[{"atb":[[4.7,2.2]],"id":28753299}],"con":true,"img":false}]}
{"op":"mcm","clk":"5323313112","pt":1646329580444,"mc":[{"id":"1.195532878","rc":[{"atb":[[4.5,0]],"id":28753299}],"con":true,"img":false}]}
