{"op":"mcm","clk":"5317728418","pt":1646251399772,"mc":[{"id":"1.195532852","marketDefinition":{"bspMarket":true,"turnInPlayEnabled":false,"persistenceEnabled":false,"marketBaseRate":5.0,"eventId":"31275720","eventTypeId":"4339","numberOfWinners":1,"bettingType":"ODDS","marketType":"WIN","marketTime":"2022-03-03T13:57:00.000Z","suspendTime":"2022-03-03T13:57:00.000Z","bspReconciled":false,"complete":true,"inPlay":false,"crossMatching":false,"runnersVoidable":false,"numberOfActiveRunners":6,"betDelay":0,"status":"OPEN","runners":[{"status":"ACTIVE","sortPriority":1,"id":38794071,"name":"1. Boynepark Zoom"},{"status":"ACTIVE","sortPriority":2,"id":41177799,"name":"2. Pantone Cheryl"},{"status":"ACTIVE","sortPriority":3,"id":41064273,"name":"3. Classic Bruno"},{"status":"ACTIVE","sortPriority":4,"id":36532033,"name":"4. To Tone Mars"},{"status":"ACTIVE","sortPriority":5,"id":36182808,"name":"5. Exve Alidocious"},{"status":"ACTIVE","sortPriority":6,"id":38386807,"name":"6. Underground Luke"}],"regulators":["MR_INT"],"venue":"Romford","countryCode":"GB","discountAllowed":false,"timezone":"Europe/London","openDate":"2022-03-03T13:57:00.000Z","version":4384107268,"name":"A6 400m","eventName":"Romford 3rd Mar"},"rc":[],"con":true,"img":false}]}
{"op":"mcm","clk":"5317728677","pt":1646251400805,"mc":[{"id":"1.195532852","marketDefinition":{"bspMarket":true,"turnInPlayEnabled":false,"persistenceEnabled":false,"marketBaseRate":5.0,"eventId":"31275720","eventTypeId":"4339","numberOfWinners":1,"bettingType":"ODDS","marketType":"WIN","marketTime":"2022-03-03T13:57:00.000Z","suspendTime":"2022-03-03T13:57:00.000Z","bspReconciled":false,"complete":true,"inPlay":false,"crossMatching":false,"runnersVoidable":false,"numberOfActiveRunners":6,"betDelay":0,"status":"OPEN","runners":[{"status":"ACTIVE","sortPriority":1,"id":38794071,"name":"1. Boynepark Zoom"},{"status":"ACTIVE","sortPriority":2,"id":41177799,"name":"2. Pantone Cheryl"},{"status":"ACTIVE","sortPriority":3,"id":41064273,"name":"3. Classic Bruno"},{"status":"ACTIVE","sortPriority":4,"id":36532033,"name":"4. To Tone Mars"},{"status":"ACTIVE","sortPriority":5,"id":36182808,"name":"5. Exve Alidocious"},{"status":"ACTIVE","sortPriority":6,"id":38386807,"name":"6. Underground Luke"}],"regulators":["MR_INT"],"venue":"Romford","countryCode":"GB","discountAllowed":true,"timezone":"Europe/London","openDate":"2022-03-03T13:57:00.000Z","version":4384107268,"name":"A6 400m","eventName":"Romford 3rd Mar"},"rc":[],"con":true,"img":false}]}
{"op":"mcm","clk":"5318488827","pt":1646259137991,"mc":[{"id":"1.195532852","rc":[{"atl":[[560,3]],"id":36182808},{"spn":1.0,"spf":"NaN","id":36182808},{"atb":[[1.12,30]],"id":38794071},{"spn":"Infinity","spf":"NaN","id":38794071},{"atl":[[500,3]],"id":38386807},{"spn":1.0,"spf":"NaN","id":38386807},{"atb":[[1.12,30]],"id":41177799},{"spn":"Infinity","spf":"NaN","id":41177799}],"con":true,"img":false}]}
{"op":"mcm","clk":"5318488836","pt":1646259138091,"mc":[{"id":"1.195532852","rc":[{"atb":[[1.12,30]],"id":41064273},{"atl":[[550,3]],"id":41064273},{"atb":[[1.12,30]],"id":36532033},{"atl":[[270,3]],"id":36532033},{"atb":[[1.12,30]],"id":36182808},{"atl":[[370,3]],"id":38794071},{"atb":[[1.14,30]],"id":38386807},{"atl":[[390,3]],"id":41177799}],"con":true,"img":false}]}
{"op":"mcm","clk":"5318509046","pt":1646259402464,"mc":[{"id":"1.195532852","marketDefinition":{"bspMarket":true,"turnInPlayEnabled":false,"persistenceEnabled":false,"marketBaseRate":5.0,"eventId":"31275720","eventTypeId":"4339","numberOfWinners":1,"bettingType":"ODDS","marketType":"WIN","marketTime":"2022-03-03T13:57:00.000Z","suspendTime":"2022-03-03T13:57:00.000Z","bspReconciled":false,"complete":true,"inPlay":false,"crossMatching":false,"runnersVoidable":false,"numberOfActiveRunners":6,"betDelay":0,"status":"OPEN","runners":[{"status":"ACTIVE","sortPriority":1,"id":38794071,"name":"1. Boynepark Zoom"},{"status":"ACTIVE","sortPriority":2,"id":41177799,"name":"2. Pantone Cheryl"},{"status":"ACTIVE","sortPriority":3,"id":41064273,"name":"3. Classic Bruno"},{"status":"ACTIVE","sortPriority":4,"id":36532033,"name":"4. To Tone Mars"},{"status":"ACTIVE","sortPriority":5,"id":36182808,"name":"5. Exve Alidocious"},{"status":"ACTIVE","sortPriority":6,"id":38386807,"name":"6. Underground Luke"}],"regulators":["MR_INT"],"venue":"Romford","countryCode":"GB","discountAllowed":true,"timezone":"Europe/London","openDate":"2022-03-03T13:57:00.000Z","version":4384107268,"name":"A6 400m","eventName":"Romford 3rd Mar"},"rc":[{"atb":[[1.12,30]],"id":41064273},{"atl":[[550,3]],"id":41064273},{"spn":275.56,"spf":"NaN","id":41064273},{"atb":[[1.12,30]],"id":36532033},{"atl":[[270,3]],"id":36532033},{"spn":135.56,"spf":"NaN","id":36532033},{"atb":[[1.12,30]],"id":36182808},{"atl":[[560,3]],"id":36182808},{"spn":280.56,"spf":"NaN","id":36182808},{"atb":[[1.12,30]],"id":38794071},{"atl":[[370,3]],"id":38794071},{"spn":185.56,"spf":"NaN","id":38794071},{"atb":[[1.14,30]],"id":38386807},{"atl":[[500,3]],"id":38386807},{"spn":250.57,"spf":"NaN","id":38386807},{"atb":[[1.12,30]],"id":41177799},{"atl":[[390,3]],"id":41177799},{"spn":195.56,"spf":"NaN","id":41177799}],"con":true,"img":true}]}
{"op":"mcm","clk":"5320139790","pt":1646287408855,"mc":[{"id":"1.195532852","rc":[{"atb":[[2.08,8.69]],"id":41064273},{"spn":276.04,"spf":"NaN","id":41064273},{"atb":[[2.02,8.44]],"id":36532033},{"spn":136.01,"spf":"NaN","id":36532033},{"atb":[[2.1,9.65]],"id":36182808},{"spn":281.05,"spf":"NaN","id":36182808},{"atb":[[2.1,11.41]],"id":38794071},{"spn":186.05,"spf":"NaN","id":38794071},{"atb":[[2.06,10.33]],"id":38386807},{"spn":251.03,"spf":"NaN","id":38386807},{"atb":[[2.08,9.56]],"id":41177799},{"spn":196.04,"spf":"NaN","id":41177799}],"con":true,"img":false}]}
{"op":"mcm","clk":"5320450469","pt":1646295779009,"mc":[{"id":"1.195532852","rc":[{"atb":[[2.02,8.45]],"id":36532033},{"spl":[[10,10]],"id":36532033},{"spn":6.01,"spf":1.0,"id":36532033},{"atb":[[2.08,8.69]],"id":41064273},{"spl":[[10,10]],"id":41064273},{"spn":6.04,"spf":1.0,"id":41064273},{"atb":[[2.1,9.66]],"id":36182808},{"spl":[[7.6,10]],"id":36182808},{"spn":4.85,"spf":1.0,"id":36182808},{"atb":[[2.1,11.41]],"id":38794071},{"spl":[[42,10]],"id":38794071},{"spn":22.05,"spf":1.0,"id":38794071},{"atb":[[2.06,10.33]],"id":38386807},{"spl":[[10,10]],"id":38386807},{"spn":6.03,"spf":1.0,"id":38386807},{"atb":[[2.08,9.56]],"id":41177799},{"spl":[[7.2,10]],"id":41177799},{"spn":4.64,"spf":1.0,"id":41177799}],"con":true,"img":false}]}
{"op":"mcm","clk":"5320546887","pt":1646297251086,"mc":[{"id":"1.195532852","rc":[{"spl":[[21,1]],"id":41064273},{"spl":[[21,1]],"id":36532033},{"spl":[[21,1]],"id":36182808},{"spl":[[21,1]],"id":38794071},{"spl":[[21,1]],"id":38386807},{"spl":[[21,1]],"id":41177799}],"con":true,"img":false}]}
{"op":"mcm","clk":"5320587199","pt":1646298075398,"mc":[{"id":"1.195532852","rc":[{"atb":[[10,2]],"id":41064273},{"spn":10.0,"spf":1.0,"id":41064273},{"atb":[[6.2,2]],"id":36532033},{"spn":8.1,"spf":1.0,"id":36532033},{"atb":[[9.2,2]],"id":36182808},{"spn":7.6,"spf":1.0,"id":36182808},{"atb":[[5.1,2]],"id":38794071},{"spn":13.05,"spf":1.0,"id":38794071},{"atb":[[5.1,2]],"id":38386807},{"spn":7.55,"spf":1.0,"id":38386807},{"atb":[[2.76,2]],"id":41177799},{"spn":4.98,"spf":1.0,"id":41177799}],"con":true,"img":false}]}
{"op":"mcm","clk":"5320587929","pt":1646298090941,"mc":[{"id":"1.195532852","marketDefinition":{"bspMarket":true,"turnInPlayEnabled":false,"persistenceEnabled":false,"marketBaseRate":5.0,"eventId":"31275720","eventTypeId":"4339","numberOfWinners":1,"bettingType":"ODDS","marketType":"WIN","marketTime":"2022-03-03T13:57:00.000Z","suspendTime":"2022-03-03T13:57:00.000Z","bspReconciled":false,"complete":true,"inPlay":false,"crossMatching":true,"runnersVoidable":false,"numberOfActiveRunners":6,"betDelay":0,"status":"OPEN","runners":[{"status":"ACTIVE","sortPriority":1,"id":38794071,"name":"1. Boynepark Zoom"},{"status":"ACTIVE","sortPriority":2,"id":41177799,"name":"2. Pantone Cheryl"},{"status":"ACTIVE","sortPriority":3,"id":41064273,"name":"3. Classic Bruno"},{"status":"ACTIVE","sortPriority":4,"id":36532033,"name":"4. To Tone Mars"},{"status":"ACTIVE","sortPriority":5,"id":36182808,"name":"5. Exve Alidocious"},{"status":"ACTIVE","sortPriority":6,"id":38386807,"name":"6. Underground Luke"}],"regulators":["MR_INT"],"venue":"Romford","countryCode":"GB","discountAllowed":true,"timezone":"Europe/London","openDate":"2022-03-03T13:57:00.000Z","version":4384107268,"name":"A6 400m","eventName":"Romford 3rd Mar"},"rc":[],"con":true,"img":false}]}
{"op":"mcm","clk":"5320622077","pt":1646298722792,"mc":[{"id":"1.195532852","rc":[{"atb":[[5.1,2]],"id":36532033},{"atl":[[11,1.01]],"id":36532033},{"atb":[[9.2,1.23]],"id":41064273},{"atl":[[29,0.37]],"id":41064273},{"atb":[[6.6,1.8]],"id":36182808},{"atl":[[15.5,0.7]],"id":36182808},{"atb":[[4.3,2]],"id":38794071},{"atl":[[8.6,1.33]],"id":38794071},{"spn":6.85,"spf":1.0,"id":38794071},{"atb":[[4.3,2]],"id":38386807},{"atl":[[8.6,1.33]],"id":38386807},{"spn":6.85,"spf":1.0,"id":38386807},{"atb":[[2.52,2]],"id":41177799},{"atl":[[4,2]],"id":41177799},{"spn":3.38,"spf":1.0,"id":41177799}],"con":true,"img":false}]}
{"op":"mcm","clk":"5320642424","pt":1646299009692,"mc":[{"id":"1.195532852","rc":[{"atl":[[1000,2]],"id":38794071}],"con":true,"img":false}]}
{"op":"mcm","clk":"5320643491","pt":1646299031436,"mc":[{"id":"1.195532852","rc":[{"atl":[[1000,2.2]],"id":38794071}],"con":true,"img":false}]}
{"op":"mcm","clk":"5320643538","pt":1646299032728,"mc":[{"id":"1.195532852","rc":[{"atl":[[1000,2]],"id":38794071}],"con":true,"img":false}]}
{"op":"mcm","clk":"5320643543","pt":1646299032831,"mc":[{"id":"1.195532852","rc":[{"atl":[[11.5,0.2]],"id":38794071}],"con":true,"img":false}]}
{"op":"mcm","clk":"5320643593","pt":1646299034116,"mc":[{"id":"1.195532852","rc":[{"atl":[[1000,2]],"id":41177799}],"con":true,"img":false}]}
{"op":"mcm","clk":"5320643639","pt":1646299035451,"mc":[{"id":"1.195532852","rc":[{"atl":[[1000,2.2]],"id":41177799}],"con":true,"img":false}]}
{"op":"mcm","clk":"5320643710","pt":1646299036838,"mc":[{"id":"1.195532852","rc":[{"atl":[[1000,2]],"id":41177799}],"con":true,"img":false}]}
{"op":"mcm","clk":"5320643718","pt":1646299036944,"mc":[{"id":"1.195532852","rc":[{"atl":[[5.7,0.2]],"id":41177799}],"con":true,"img":false}]}
{"op":"mcm","clk":"5320643786","pt":1646299038229,"mc":[{"id":"1.195532852","rc":[{"atl":[[1000,2]],"id":41064273}],"con":true,"img":false}]}
{"op":"mcm","clk":"5320643844","pt":1646299039511,"mc":[{"id":"1.195532852","rc":[{"atl":[[1000,2.2]],"id":41064273}],"con":true,"img":false}]}
{"op":"mcm","clk":"5320643947","pt":1646299040851,"mc":[{"id":"1.195532852","rc":[{"atl":[[1000,2]],"id":41064273}],"con":true,"img":false}]}
{"op":"mcm","clk":"5320643954","pt":1646299040953,"mc":[{"id":"1.195532852","rc":[{"atl":[[26,0.2]],"id":41064273}],"con":true,"img":false}]}
{"op":"mcm","clk":"5320644068","pt":1646299042239,"mc":[{"id":"1.195532852","rc":[{"atl":[[1000,2]],"id":36532033}],"con":true,"img":false}]}
{"op":"mcm","clk":"5320644118","pt":1646299043523,"mc":[{"id":"1.195532852","rc":[{"atl":[[1000,2.2]],"id":36532033}],"con":true,"img":false}]}
{"op":"mcm","clk":"5320644160","pt":1646299044856,"mc":[{"id":"1.195532852","rc":[{"atl":[[1000,2]],"id":36532033}],"con":true,"img":false}]}
{"op":"mcm","clk":"5320644163","pt":1646299044959,"mc":[{"id":"1.195532852","rc":[{"atl":[[13.5,0.2]],"id":36532033}],"con":true,"img":false}]}
{"op":"mcm","clk":"5320644207","pt":1646299046249,"mc":[{"id":"1.195532852","rc":[{"atl":[[1000,2]],"id":36182808}],"con":true,"img":false}]}
{"op":"mcm","clk":"5320644279","pt":1646299047536,"mc":[{"id":"1.195532852","rc":[{"atl":[[1000,2.2]],"id":36182808}],"con":true,"img":false}]}
{"op":"mcm","clk":"5320644348","pt":1646299048825,"mc":[{"id":"1.195532852","rc":[{"atl":[[1000,2]],"id":36182808}],"con":true,"img":false}]}
{"op":"mcm","clk":"5320644353","pt":1646299048928,"mc":[{"id":"1.195532852","rc":[{"atl":[[18,0.2]],"id":36182808}],"con":true,"img":false}]}
{"op":"mcm","clk":"5320644425","pt":1646299050265,"mc":[{"id":"1.195532852","rc":[{"atl":[[1000,2]],"id":38386807}],"con":true,"img":false}]}
{"op":"mcm","clk":"5320644484","pt":1646299051558,"mc":[{"id":"1.195532852","rc":[{"atl":[[1000,2.2]],"id":38386807}],"con":true,"img":false}]}
{"op":"mcm","clk":"5320644542","pt":1646299052850,"mc":[{"id":"1.195532852","rc":[{"atl":[[1000,2]],"id":38386807}],"con":true,"img":false}]}
{"op":"mcm","clk":"5320644547","pt":1646299052954,"mc":[{"id":"1.195532852","rc":[{"atl":[[11.5,0.2]],"id":38386807}],"con":true,"img":false}]}
{"op":"mcm","clk":"5320758047","pt":1646301292294,"mc":[{"id":"1.195532852","rc":[{"atb":[[2.52,0]],"id":41177799},{"atl":[[4,0]],"id":41177799},{"spn":4.23,"spf":1.0,"id":41177799}],"con":true,"img":false}]}
{"op":"mcm","clk":"5320758052","pt":1646301292396,"mc":[{"id":"1.195532852","rc":[{"atb":[[5.1,0]],"id":36532033},{"atl":[[11,0]],"id":36532033},{"atb":[[9.2,0]],"id":41064273},{"atl":[[29,0]],"id":41064273},{"atb":[[2.52,2]],"id":41177799},{"atl":[[4,2]],"id":41177799}],"con":true,"img":false}]}
{"op":"mcm","clk":"5320758063","pt":1646301292499,"mc":[{"id":"1.195532852","rc":[{"atb":[[6.6,0]],"id":36182808},{"atl":[[15.5,0]],"id":36182808}],"con":true,"img":false}]}
{"op":"mcm","clk":"5320758069","pt":1646301292603,"mc":[{"id":"1.195532852","rc":[{"atb":[[9.2,1.23]],"id":41064273},{"atl":[[29,0.37]],"id":41064273},{"atb":[[5.1,2]],"id":36532033},{"atl":[[11,1.01]],"id":36532033}],"con":true,"img":false}]}
{"op":"mcm","clk":"5320758078","pt":1646301292705,"mc":[{"id":"1.195532852","rc":[{"atb":[[6.6,1.8]],"id":36182808},{"atl":[[15.5,0.7]],"id":36182808}],"con":true,"img":false}]}
{"op":"mcm","clk":"5320830275","pt":1646302602590,"mc":[{"id":"1.195532852","marketDefinition":{"bspMarket":true,"turnInPlayEnabled":false,"persistenceEnabled":false,"marketBaseRate":5.0,"eventId":"31275720","eventTypeId":"4339","numberOfWinners":1,"bettingType":"ODDS","marketType":"WIN","marketTime":"2022-03-03T13:57:00.000Z","suspendTime":"2022-03-03T13:57:00.000Z","bspReconciled":false,"complete":true,"inPlay":false,"crossMatching":true,"runnersVoidable":false,"numberOfActiveRunners":6,"betDelay":0,"status":"OPEN","runners":[{"status":"ACTIVE","sortPriority":1,"id":38794071,"name":"1. Boynepark Zoom"},{"status":"ACTIVE","sortPriority":2,"id":41177799,"name":"2. Pantone Cheryl"},{"status":"ACTIVE","sortPriority":3,"id":41064273,"name":"3. Classic Bruno"},{"status":"ACTIVE","sortPriority":4,"id":36532033,"name":"4. To Tone Mars"},{"status":"ACTIVE","sortPriority":5,"id":36182808,"name":"5. Exve Alidocious"},{"status":"ACTIVE","sortPriority":6,"id":38386807,"name":"6. Underground Luke"}],"regulators":["MR_INT"],"venue":"Romford","countryCode":"GB","discountAllowed":true,"timezone":"Europe/London","openDate":"2022-03-03T13:57:00.000Z","version":4384107268,"name":"A6 400m","eventName":"Romford 3rd Mar"},"rc":[{"atb":[[1.12,30],[5.1,2],[2.02,8.44],[6.2,2]],"id":36532033},{"spl":[[10,10],[21,1]],"id":36532033},{"atl":[[270,3],[11,1.01],[13.5,0.2],[1000,2]],"id":36532033},{"spn":8.1,"spf":1.0,"id":36532033},{"atb":[[1.12,30],[10,2],[9.2,1.23],[2.08,8.69]],"id":41064273},{"spl":[[10,10],[21,1]],"id":41064273},{"atl":[[550,3],[26,0.2],[29,0.37],[1000,2]],"id":41064273},{"spn":10.0,"spf":1.0,"id":41064273},{"atb":[[1.12,30],[9.2,2],[6.6,1.8],[2.1,9.65]],"id":36182808},{"spl":[[21,1],[7.6,10]],"id":36182808},{"atl":[[560,3],[18,0.2],[15.5,0.7],[1000,2]],"id":36182808},{"spn":7.6,"spf":1.0,"id":36182808},{"atb":[[1.12,30],[5.1,2],[4.3,2],[2.1,11.41]],"id":38794071},{"spl":[[21,1],[42,10]],"id":38794071},{"atl":[[8.6,1.33],[11.5,0.2],[370,3],[1000,2]],"id":38794071},{"spn":6.85,"spf":1.0,"id":38794071},{"atb":[[5.1,2],[4.3,2],[2.06,10.33],[1.14,30]],"id":38386807},{"spl":[[10,10],[21,1]],"id":38386807},{"atl":[[8.6,1.33],[11.5,0.2],[500,3],[1000,2]],"id":38386807},{"spn":6.85,"spf":1.0,"id":38386807},{"atb":[[1.12,30],[2.52,2],[2.08,9.56],[2.76,2]],"id":41177799},{"spl":[[7.2,10],[21,1]],"id":41177799},{"atl":[[4,2],[390,3],[5.7,0.2],[1000,2]],"id":41177799},{"spn":3.38,"spf":1.0,"id":41177799}],"con":true,"img":true}]}
{"op":"mcm","clk":"5320915790","pt":1646303855610,"mc":[{"id":"1.195532852","rc":[{"atb":[[2.02,8.44],[6.2,0]],"id":36532033},{"atl":[[6.2,3]],"id":36532033},{"trd":[[6.2,4]],"ltp":6.2,"tv":4.0,"id":36532033},{"spn":5.65,"spf":1.0,"id":36532033},{"atb":[[2.08,8.69]],"id":41064273},{"atb":[[2.1,9.65]],"id":36182808},{"atb":[[2.1,11.41]],"id":38794071},{"atb":[[2.06,10.33]],"id":38386807},{"atb":[[2.08,9.56]],"id":41177799},{"spn":3.38,"spf":1.0,"id":41177799}],"con":true,"img":false}]}
{"op":"mcm","clk":"5320915968","pt":1646303857879,"mc":[{"id":"1.195532852","rc":[{"atb":[[3.2,5.09]],"id":36182808},{"atb":[[2.74,6.44]],"id":38794071}],"con":true,"img":false}]}
{"op":"mcm","clk":"5320915977","pt":1646303857981,"mc":[{"id":"1.195532852","rc":[{"atb":[[3.5,4.48]],"id":41064273}],"con":true,"img":false}]}
{"op":"mcm","clk":"5320915986","pt":1646303858090,"mc":[{"id":"1.195532852","rc":[{"atb":[[2.44,7.78]],"id":36532033},{"atb":[[2.12,10]],"id":41177799}],"con":true,"img":false}]}
{"op":"mcm","clk":"5320915994","pt":1646303858188,"mc":[{"id":"1.195532852","rc":[{"atb":[[2.74,6.44]],"id":38386807}],"con":true,"img":false}]}
{"op":"mcm","clk":"5320919666","pt":1646303905437,"mc":[{"id":"1.195532852","rc":[{"atb":[[2.08,0]],"id":41177799}],"con":true,"img":false}]}
{"op":"mcm","clk":"5320919676","pt":1646303905541,"mc":[{"id":"1.195532852","rc":[{"atb":[[2.14,9.56]],"id":41177799}],"con":true,"img":false}]}
{"op":"mcm","clk":"5320926523","pt":1646303996793,"mc":[{"id":"1.195532852","rc":[{"atb":[[2.78,6.98]],"id":38794071}],"con":true,"img":false}]}
{"op":"mcm","clk":"5320926532","pt":1646303996895,"mc":[{"id":"1.195532852","rc":[{"atb":[[2.48,8.39]],"id":36532033}],"con":true,"img":false}]}
{"op":"mcm","clk":"5320926545","pt":1646303997105,"mc":[{"id":"1.195532852","rc":[{"atb":[[3.6,4.77]],"id":41064273}],"con":true,"img":false}]}
{"op":"mcm","clk":"5320926553","pt":1646303997207,"mc":[{"id":"1.195532852","rc":[{"atb":[[2.78,6.98]],"id":38386807}],"con":true,"img":false}]}
{"op":"mcm","clk":"5320926580","pt":1646303997568,"mc":[{"id":"1.195532852","rc":[{"atb":[[3.3,5.39]],"id":36182808},{"atb":[[2.18,10.52]],"id":41177799}],"con":true,"img":false}]}
{"op":"mcm","clk":"5320943938","pt":1646304139746,"mc":[{"id":"1.195532852","rc":[{"atb":[[2.12,0]],"id":41177799}],"con":true,"img":false}]}
{"op":"mcm","clk":"5320944334","pt":1646304145943,"mc":[{"id":"1.195532852","rc":[{"atb":[[2.22,9.19]],"id":41177799}],"con":true,"img":false}]}
{"op":"mcm","clk":"5320948325","pt":1646304204989,"mc":[{"id":"1.195532852","rc":[{"atb":[[2.14,0]],"id":41177799}],"con":true,"img":false}]}
{"op":"mcm","clk":"5320948332","pt":1646304205043,"mc":[{"id":"1.195532852","rc":[{"atb":[[2.24,9.56]],"id":41177799}],"con":true,"img":false}]}
{"op":"mcm","clk":"5320949943","pt":1646304233384,"mc":[{"id":"1.195532852","rc":[{"atb":[[3.5,0]],"id":41064273},{"atb":[[2.44,0]],"id":36532033},{"atb":[[3.2,0]],"id":36182808},{"atb":[[2.74,0]],"id":38794071},{"atb":[[2.74,0]],"id":38386807}],"con":true,"img":false}]}
{"op":"mcm","clk":"5320950286","pt":1646304239199,"mc":[{"id":"1.195532852","rc":[{"atb":[[2.52,7.37]],"id":36532033},{"atb":[[2.82,6.15]],"id":38794071}],"con":true,"img":false}]}
{"op":"mcm","clk":"5320950291","pt":1646304239304,"mc":[{"id":"1.195532852","rc":[{"atb":[[2.82,6.15]],"id":38386807}],"con":true,"img":false}]}
{"op":"mcm","clk":"5320950296","pt":1646304239407,"mc":[{"id":"1.195532852","rc":[{"atb":[[3.4,4.67]],"id":36182808}],"con":true,"img":false}]}
{"op":"mcm","clk":"5320950302","pt":1646304239509,"mc":[{"id":"1.195532852","rc":[{"atb":[[3.7,4.15]],"id":41064273}],"con":true,"img":false}]}
{"op":"mcm","clk":"5320955913","pt":1646304326286,"mc":[{"id":"1.195532852","rc":[{"atl":[[1000,12]],"id":41064273},{"atl":[[1000,12]],"id":36532033},{"atl":[[1000,12]],"id":36182808},{"atl":[[1000,12]],"id":38794071},{"atl":[[1000,12]],"id":38386807},{"atl":[[1000,12]],"id":41177799}],"con":true,"img":false}]}
{"op":"mcm","clk":"5320955931","pt":1646304326702,"mc":[{"id":"1.195532852","rc":[{"atb":[[1.01,1000]],"id":36532033},{"atb":[[1.01,1000]],"id":41064273},{"atb":[[1.01,1000]],"id":36182808},{"atb":[[1.01,1000]],"id":38794071},{"atb":[[1.01,1000]],"id":38386807},{"atb":[[1.01,1000]],"id":41177799}],"con":true,"img":false}]}
{"op":"mcm","clk":"5320955946","pt":1646304327011,"mc":[{"id":"1.195532852","rc":[{"atb":[[1.01,11000]],"id":41064273},{"atb":[[1.01,11000]],"id":36532033},{"atb":[[1.01,11000]],"id":36182808},{"atb":[[1.01,11000]],"id":38794071},{"atb":[[1.01,11000]],"id":38386807},{"atb":[[1.01,11000]],"id":41177799}],"con":true,"img":false}]}
{"op":"mcm","clk":"5320959842","pt":1646304390006,"mc":[{"id":"1.195532852","rc":[{"atb":[[2.18,0]],"id":41177799}],"con":true,"img":false}]}
{"op":"mcm","clk":"5320960744","pt":1646304406317,"mc":[{"id":"1.195532852","rc":[{"atb":[[2.28,9.7]],"id":41177799}],"con":true,"img":false}]}
{"op":"mcm","clk":"5320962649","pt":1646304437583,"mc":[{"id":"1.195532852","rc":[{"atb":[[2.22,0]],"id":41177799}],"con":true,"img":false}]}
{"op":"mcm","clk":"5320963021","pt":1646304443089,"mc":[{"id":"1.195532852","rc":[{"atb":[[2.32,8.49]],"id":41177799}],"con":true,"img":false}]}
{"op":"mcm","clk":"5320965047","pt":1646304473543,"mc":[{"id":"1.195532852","rc":[{"atb":[[3.6,0]],"id":41064273},{"atb":[[2.48,0]],"id":36532033},{"atb":[[3.3,0]],"id":36182808},{"atb":[[2.78,0]],"id":38794071},{"atb":[[2.78,0]],"id":38386807}],"con":true,"img":false}]}
{"op":"mcm","clk":"5320966351","pt":1646304492901,"mc":[{"id":"1.195532852","rc":[{"atb":[[2.86,6.67]],"id":38794071}],"con":true,"img":false}]}
{"op":"mcm","clk":"5320966368","pt":1646304493103,"mc":[{"id":"1.195532852","rc":[{"atb":[[3.8,4.43]],"id":41064273}],"con":true,"img":false}]}
{"op":"mcm","clk":"5320966376","pt":1646304493204,"mc":[{"id":"1.195532852","rc":[{"atb":[[2.86,6.67]],"id":38386807}],"con":true,"img":false}]}
{"op":"mcm","clk":"5320966386","pt":1646304493360,"mc":[{"id":"1.195532852","rc":[{"atb":[[3.5,4.96]],"id":36182808}],"con":true,"img":false}]}
{"op":"mcm","clk":"5320966393","pt":1646304493463,"mc":[{"id":"1.195532852","rc":[{"atb":[[2.56,7.96]],"id":36532033}],"con":true,"img":false}]}
{"op":"mcm","clk":"5320967121","pt":1646304503598,"mc":[{"id":"1.195532852","rc":[{"atb":[[2.24,0]],"id":41177799}],"con":true,"img":false}]}
{"op":"mcm","clk":"5320967128","pt":1646304503700,"mc":[{"id":"1.195532852","rc":[{"atb":[[2.34,9.56]],"id":41177799}],"con":true,"img":false}]}
{"op":"mcm","clk":"5320980768","pt":1646304684384,"mc":[{"id":"1.195532852","rc":[{"atb":[[2.28,0]],"id":41177799}],"con":true,"img":false}]}
{"op":"mcm","clk":"5320982252","pt":1646304701911,"mc":[{"id":"1.195532852","rc":[{"atb":[[2.36,9.13]],"id":41177799}],"con":true,"img":false}]}
{"op":"mcm","clk":"5320982715","pt":1646304707745,"mc":[{"id":"1.195532852","rc":[{"atb":[[2.52,0]],"id":36532033},{"atb":[[3.7,0]],"id":41064273},{"atb":[[3.4,0]],"id":36182808},{"atb":[[2.82,0]],"id":38794071},{"atb":[[2.82,0]],"id":38386807}],"con":true,"img":false}]}
{"op":"mcm","clk":"5320982959","pt":1646304710744,"mc":[{"id":"1.195532852","rc":[{"atb":[[2.6,7.01]],"id":36532033},{"atb":[[2.9,5.89]],"id":38794071}],"con":true,"img":false}]}
{"op":"mcm","clk":"5320982981","pt":1646304710953,"mc":[{"id":"1.195532852","rc":[{"atb":[[3.6,4.31]],"id":36182808},{"atb":[[2.9,5.89]],"id":38386807}],"con":true,"img":false}]}
{"op":"mcm","clk":"5320982994","pt":1646304711156,"mc":[{"id":"1.195532852","rc":[{"atb":[[3.9,3.86]],"id":41064273}],"con":true,"img":false}]}
{"op":"mcm","clk":"5320999287","pt":1646304920241,"mc":[{"id":"1.195532852","rc":[{"atb":[[2.32,0]],"id":41177799}],"con":true,"img":false}]}
{"op":"mcm","clk":"5320999548","pt":1646304923845,"mc":[{"id":"1.195532852","rc":[{"atb":[[2,11.21]],"id":41177799}],"con":true,"img":false}]}
{"op":"mcm","clk":"5321001332","pt":1646304948980,"mc":[{"id":"1.195532852","rc":[{"atb":[[3.8,0]],"id":41064273},{"atb":[[2.56,0]],"id":36532033},{"atb":[[3.5,0]],"id":36182808},{"atb":[[2.86,0]],"id":38794071},{"atb":[[2.86,0]],"id":38386807}],"con":true,"img":false}]}
{"op":"mcm","clk":"5321002654","pt":1646304967892,"mc":[{"id":"1.195532852","rc":[{"atb":[[2.94,6.4]],"id":38794071}],"con":true,"img":false}]}
{"op":"mcm","clk":"5321002676","pt":1646304968197,"mc":[{"id":"1.195532852","rc":[{"atb":[[4,4.14]],"id":41064273},{"atb":[[2.64,7.57]],"id":36532033}],"con":true,"img":false}]}
{"op":"mcm","clk":"5321002698","pt":1646304968504,"mc":[{"id":"1.195532852","rc":[{"atb":[[3.7,4.6]],"id":36182808}],"con":true,"img":false}]}
{"op":"mcm","clk":"5321002708","pt":1646304968608,"mc":[{"id":"1.195532852","rc":[{"atb":[[2.94,6.4]],"id":38386807}],"con":true,"img":false}]}
{"op":"mcm","clk":"5321016799","pt":1646305173520,"mc":[{"id":"1.195532852","rc":[{"atb":[[2.36,0]],"id":41177799}],"con":true,"img":false}]}
{"op":"mcm","clk":"5321017504","pt":1646305182388,"mc":[{"id":"1.195532852","rc":[{"atb":[[2.6,0]],"id":36532033},{"atb":[[3.9,0]],"id":41064273},{"atb":[[3.6,0]],"id":36182808},{"atb":[[2.9,0]],"id":38794071},{"atb":[[2.9,0]],"id":38386807}],"con":true,"img":false}]}
{"op":"mcm","clk":"5321017746","pt":1646305185494,"mc":[{"id":"1.195532852","rc":[{"atb":[[2.68,6.67]],"id":36532033},{"atb":[[2.98,5.66]],"id":38794071}],"con":true,"img":false}]}
{"op":"mcm","clk":"5321017756","pt":1646305185598,"mc":[{"id":"1.195532852","rc":[{"atb":[[3.8,4]],"id":36182808},{"atb":[[2.98,5.66]],"id":38386807}],"con":true,"img":false}]}
{"op":"mcm","clk":"5321017766","pt":1646305185653,"mc":[{"id":"1.195532852","rc":[{"atb":[[4.2,3.5]],"id":41064273}],"con":true,"img":false}]}
{"op":"mcm","clk":"5321017981","pt":1646305188290,"mc":[{"id":"1.195532852","rc":[{"atb":[[2.04,11.94]],"id":41177799}],"con":true,"img":false}]}
{"op":"mcm","clk":"5321035190","pt":1646305419849,"mc":[{"id":"1.195532852","rc":[{"atb":[[4,4.14],[4.2,3.5],[2.08,8.69]],"id":41064273},{"atb":[[2.02,8.45],[2.64,7.58],[2.68,6.67]],"id":36532033},{"atb":[[3.7,4.6],[3.8,4],[2.1,9.65]],"id":36182808},{"atb":[[2.98,5.66],[2.94,6.4],[2.1,11.41]],"id":38794071},{"atb":[[2.06,10.33],[2.98,5.66],[2.94,6.4]],"id":38386807},{"atb":[[2,0],[2.04,11.94],[2.34,9.56]],"id":41177799}],"con":true,"img":false}]}
{"op":"mcm","clk":"5321035404","pt":1646305422746,"mc":[{"id":"1.195532852","rc":[{"atb":[[2.08,10.37]],"id":41177799}],"con":true,"img":false}]}
{"op":"mcm","clk":"5321035417","pt":1646305422854,"mc":[{"id":"1.195532852","rc":[{"atb":[[4,0]],"id":41064273},{"atb":[[2.64,0]],"id":36532033},{"atb":[[3.7,0]],"id":36182808},{"atb":[[2.94,0]],"id":38794071},{"atb":[[2.94,0]],"id":38386807}],"con":true,"img":false}]}
{"op":"mcm","clk":"5321036656","pt":1646305439781,"mc":[{"id":"1.195532852","rc":[{"atb":[[3.05,6.06]],"id":38794071}],"con":true,"img":false}]}
{"op":"mcm","clk":"5321036663","pt":1646305439886,"mc":[{"id":"1.195532852","rc":[{"atb":[[3.9,4.28]],"id":36182808}],"con":true,"img":false}]}
{"op":"mcm","clk":"5321036684","pt":1646305440195,"mc":[{"id":"1.195532852","rc":[{"atb":[[3.05,6.06]],"id":38386807}],"con":true,"img":false}]}
{"op":"mcm","clk":"5321036703","pt":1646305440408,"mc":[{"id":"1.195532852","rc":[{"atb":[[4.4,3.65]],"id":41064273}],"con":true,"img":false}]}
{"op":"mcm","clk":"5321036742","pt":1646305440781,"mc":[{"id":"1.195532852","rc":[{"atb":[[2.72,7.22]],"id":36532033}],"con":true,"img":false}]}
{"op":"mcm","clk":"5321059669","pt":1646305657422,"mc":[{"id":"1.195532852","rc":[{"atb":[[2.68,0]],"id":36532033},{"atb":[[4.2,0]],"id":41064273},{"atb":[[3.8,0]],"id":36182808},{"atb":[[2.98,0]],"id":38794071},{"atb":[[2.98,0]],"id":38386807}],"con":true,"img":false}]}
{"op":"mcm","clk":"5321059918","pt":1646305660492,"mc":[{"id":"1.195532852","rc":[{"atb":[[2.04,0]],"id":41177799}],"con":true,"img":false}]}
{"op":"mcm","clk":"5321060136","pt":1646305663387,"mc":[{"id":"1.195532852","rc":[{"atb":[[3.15,5.21]],"id":38794071}],"con":true,"img":false}]}
{"op":"mcm","clk":"5321060141","pt":1646305663489,"mc":[{"id":"1.195532852","rc":[{"atb":[[3.15,5.21]],"id":38386807}],"con":true,"img":false}]}
{"op":"mcm","clk":"5321060146","pt":1646305663594,"mc":[{"id":"1.195532852","rc":[{"atb":[[2.76,6.36]],"id":36532033}],"con":true,"img":false}]}
{"op":"mcm","clk":"5321060154","pt":1646305663697,"mc":[{"id":"1.195532852","rc":[{"atb":[[4.6,3.11]],"id":41064273}],"con":true,"img":false}]}
{"op":"mcm","clk":"5321060161","pt":1646305663800,"mc":[{"id":"1.195532852","rc":[{"atb":[[4,3.73]],"id":36182808}],"con":true,"img":false}]}
{"op":"mcm","clk":"5321061310","pt":1646305677748,"mc":[{"id":"1.195532852","rc":[{"atb":[[2.12,11.09]],"id":41177799}],"con":true,"img":false}]}
{"op":"mcm","clk":"5321077812","pt":1646305895030,"mc":[{"id":"1.195532852","rc":[{"atb":[[2.08,0]],"id":41177799}],"con":true,"img":false}]}
{"op":"mcm","clk":"5321077843","pt":1646305895643,"mc":[{"id":"1.195532852","rc":[{"atb":[[4.4,0]],"id":41064273},{"atb":[[2.72,0]],"id":36532033},{"atb":[[3.9,0]],"id":36182808},{"atb":[[3.05,0]],"id":38794071},{"atb":[[3.05,0]],"id":38386807}],"con":true,"img":false}]}
{"op":"mcm","clk":"5321077988","pt":1646305897721,"mc":[{"id":"1.195532852","rc":[{"atb":[[2.16,9.66]],"id":41177799}],"con":true,"img":false}]}
{"op":"mcm","clk":"5321079004","pt":1646305911646,"mc":[{"id":"1.195532852","rc":[{"atb":[[3.25,5.52]],"id":38794071}],"con":true,"img":false}]}
{"op":"mcm","clk":"5321079009","pt":1646305911749,"mc":[{"id":"1.195532852","rc":[{"atb":[[4.2,3.88]],"id":36182808}],"con":true,"img":false}]}
{"op":"mcm","clk":"5321079026","pt":1646305911956,"mc":[{"id":"1.195532852","rc":[{"atb":[[2.8,6.9]],"id":36532033}],"con":true,"img":false}]}
{"op":"mcm","clk":"5321079037","pt":1646305912160,"mc":[{"id":"1.195532852","rc":[{"atb":[[4.8,3.27]],"id":41064273}],"con":true,"img":false}]}
{"op":"mcm","clk":"5321079047","pt":1646305912365,"mc":[{"id":"1.195532852","rc":[{"atb":[[3.25,5.52]],"id":38386807}],"con":true,"img":false}]}
{"op":"mcm","clk":"5321096911","pt":1646306129611,"mc":[{"id":"1.195532852","rc":[{"atb":[[4.6,0]],"id":41064273},{"atb":[[2.76,0]],"id":36532033},{"atb":[[4,0]],"id":36182808},{"atb":[[3.15,0]],"id":38794071},{"atb":[[3.15,0]],"id":38386807}],"con":true,"img":false}]}
{"op":"mcm","clk":"5321097165","pt":1646306132626,"mc":[{"id":"1.195532852","rc":[{"atb":[[3.35,4.76]],"id":38794071}],"con":true,"img":false}]}
{"op":"mcm","clk":"5321097175","pt":1646306132732,"mc":[{"id":"1.195532852","rc":[{"atb":[[2.84,6.09]],"id":36532033}],"con":true,"img":false}]}
{"op":"mcm","clk":"5321097193","pt":1646306132942,"mc":[{"id":"1.195532852","rc":[{"atb":[[3.35,4.76]],"id":38386807}],"con":true,"img":false}]}
{"op":"mcm","clk":"5321097225","pt":1646306133256,"mc":[{"id":"1.195532852","rc":[{"atb":[[4.4,3.29]],"id":36182808}],"con":true,"img":false}]}
{"op":"mcm","clk":"5321099008","pt":1646306152091,"mc":[{"id":"1.195532852","rc":[{"atb":[[2.12,0]],"id":41177799}],"con":true,"img":false}]}
{"op":"mcm","clk":"5321100730","pt":1646306169724,"mc":[{"id":"1.195532852","rc":[{"atb":[[2.2,10.35]],"id":41177799}],"con":true,"img":false}]}
{"op":"mcm","clk":"5321125491","pt":1646306385397,"mc":[{"id":"1.195532852","rc":[{"atb":[[2.16,0]],"id":41177799}],"con":true,"img":false}]}
{"op":"mcm","clk":"5321125952","pt":1646306390932,"mc":[{"id":"1.195532852","rc":[{"atb":[[2.24,9.04]],"id":41177799}],"con":true,"img":false}]}
{"op":"mcm","clk":"5321134176","pt":1646306460789,"mc":[{"id":"1.195532852","rc":[{"atb":[[2.8,0]],"id":36532033},{"atb":[[4.8,0]],"id":41064273},{"atb":[[4.2,0]],"id":36182808},{"atb":[[3.25,0]],"id":38794071},{"atb":[[3.25,0]],"id":38386807}],"con":true,"img":false}]}
{"op":"mcm","clk":"5321134848","pt":1646306466078,"mc":[{"id":"1.195532852","rc":[{"atb":[[3.5,4.48]],"id":41064273}],"con":true,"img":false}]}
{"op":"mcm","clk":"5321137996","pt":1646306494001,"mc":[{"id":"1.195532852","rc":[{"atb":[[2.88,6.61]],"id":36532033}],"con":true,"img":false}]}
{"op":"mcm","clk":"5321138035","pt":1646306494311,"mc":[{"id":"1.195532852","rc":[{"atb":[[3.6,4.78]],"id":41064273},{"atb":[[3.45,5.07]],"id":38386807}],"con":true,"img":false}]}
{"op":"mcm","clk":"5321138075","pt":1646306494632,"mc":[{"id":"1.195532852","rc":[{"atb":[[4.6,3.45]],"id":36182808}],"con":true,"img":false}]}
{"op":"mcm","clk":"5321138116","pt":1646306494895,"mc":[{"id":"1.195532852","rc":[{"atb":[[3.45,5.07]],"id":38794071}],"con":true,"img":false}]}
{"op":"mcm","clk":"5321161531","pt":1646306698374,"mc":[{"id":"1.195532852","rc":[{"atb":[[2.84,0]],"id":36532033},{"atb":[[4.4,0]],"id":36182808},{"atb":[[3.35,0]],"id":38794071},{"atb":[[3.35,0]],"id":38386807}],"con":true,"img":false}]}
{"op":"mcm","clk":"5321161871","pt":1646306701357,"mc":[{"id":"1.195532852","rc":[{"atb":[[2.2,0]],"id":41177799}],"con":true,"img":false}]}
{"op":"mcm","clk":"5321162185","pt":1646306704168,"mc":[{"id":"1.195532852","rc":[{"atb":[[3.55,4.39]],"id":38794071}],"con":true,"img":false}]}
{"op":"mcm","clk":"5321162196","pt":1646306704270,"mc":[{"id":"1.195532852","rc":[{"atb":[[4.8,2.95]],"id":36182808}],"con":true,"img":false}]}
{"op":"mcm","clk":"5321162210","pt":1646306704372,"mc":[{"id":"1.195532852","rc":[{"atb":[[3.55,4.39]],"id":38386807}],"con":true,"img":false}]}
{"op":"mcm","clk":"5321162231","pt":1646306704582,"mc":[{"id":"1.195532852","rc":[{"atb":[[2.92,5.83]],"id":36532033}],"con":true,"img":false}]}
{"op":"mcm","clk":"5321164128","pt":1646306722669,"mc":[{"id":"1.195532852","rc":[{"atb":[[2.28,9.7]],"id":41177799}],"con":true,"img":false}]}
{"op":"mcm","clk":"5321164683","pt":1646306728410,"mc":[{"id":"1.195532852","rc":[{"atb":[[3.5,0]],"id":41064273}],"con":true,"img":false}]}
{"op":"mcm","clk":"5321165282","pt":1646306734347,"mc":[{"id":"1.195532852","rc":[{"atb":[[3.7,4.15]],"id":41064273}],"con":true,"img":false}]}
{"op":"mcm","clk":"5321183051","pt":1646306935806,"mc":[{"id":"1.195532852","rc":[{"atb":[[2.24,0]],"id":41177799}],"con":true,"img":false}]}
{"op":"mcm","clk":"5321183188","pt":1646306937518,"mc":[{"id":"1.195532852","rc":[{"atb":[[2.88,0]],"id":36532033},{"atb":[[4.6,0]],"id":36182808},{"atb":[[3.45,0]],"id":38794071},{"atb":[[3.45,0]],"id":38386807}],"con":true,"img":false}]}
{"op":"mcm","clk":"5321183592","pt":1646306942191,"mc":[{"id":"1.195532852","rc":[{"atb":[[2.32,8.48]],"id":41177799}],"con":true,"img":false}]}
{"op":"mcm","clk":"5321185280","pt":1646306960441,"mc":[{"id":"1.195532852","rc":[{"atb":[[2.74,7.14]],"id":38794071}],"con":true,"img":false}]}
{"op":"mcm","clk":"5321185313","pt":1646306960757,"mc":[{"id":"1.195532852","rc":[{"atb":[[2.96,6.33]],"id":36532033}],"con":true,"img":false}]}
{"op":"mcm","clk":"5321185377","pt":1646306961223,"mc":[{"id":"1.195532852","rc":[{"atb":[[2.74,7.14]],"id":38386807}],"con":true,"img":false}]}
{"op":"mcm","clk":"5321186771","pt":1646306977272,"mc":[{"id":"1.195532852","rc":[{"atb":[[3.6,0]],"id":41064273}],"con":true,"img":false}]}
{"op":"mcm","clk":"5321188063","pt":1646306992199,"mc":[{"id":"1.195532852","rc":[{"atb":[[3.8,4.44]],"id":41064273}],"con":true,"img":false}]}
{"op":"mcm","clk":"5321204837","pt":1646307172157,"mc":[{"id":"1.195532852","rc":[{"atb":[[2.92,0]],"id":36532033},{"atb":[[4.8,0]],"id":36182808},{"atb":[[3.55,0]],"id":38794071},{"atb":[[3.55,0]],"id":38386807}],"con":true,"img":false}]}
{"op":"mcm","clk":"5321205229","pt":1646307175890,"mc":[{"id":"1.195532852","rc":[{"atb":[[2.78,6.29]],"id":38794071}],"con":true,"img":false}]}
{"op":"mcm","clk":"5321205244","pt":1646307175994,"mc":[{"id":"1.195532852","rc":[{"atb":[[2.78,6.29]],"id":38386807}],"con":true,"img":false}]}
{"op":"mcm","clk":"5321205250","pt":1646307176097,"mc":[{"id":"1.195532852","rc":[{"atb":[[3.2,5.09]],"id":36182808}],"con":true,"img":false}]}
{"op":"mcm","clk":"5321205277","pt":1646307176256,"mc":[{"id":"1.195532852","rc":[{"atb":[[3,5.6]],"id":36532033}],"con":true,"img":false}]}
{"op":"mcm","clk":"5321206010","pt":1646307183633,"mc":[{"id":"1.195532852","rc":[{"atb":[[3.3,5.4]],"id":36182808}],"con":true,"img":false}]}
{"op":"mcm","clk":"5321207338","pt":1646307198235,"mc":[{"id":"1.195532852","rc":[{"atb":[[2.28,0]],"id":41177799}],"con":true,"img":false}]}
{"op":"mcm","clk":"5321207432","pt":1646307199267,"mc":[{"id":"1.195532852","rc":[{"atb":[[9.2,0]],"id":36182808},{"trd":[[9.2,4]],"ltp":9.2,"tv":4.0,"id":36182808}],"con":true,"img":false}]}
{"op":"mcm","clk":"5321207949","pt":1646307204445,"mc":[{"id":"1.195532852","rc":[{"atb":[[5.6,2]],"id":36532033}],"con":true,"img":false}]}
{"op":"mcm","clk":"5321208402","pt":1646307209666,"mc":[{"id":"1.195532852","rc":[{"atb":[[3.7,0]],"id":41064273}],"con":true,"img":false}]}
{"op":"mcm","clk":"5321208945","pt":1646307215460,"mc":[{"id":"1.195532852","rc":[{"atb":[[3.9,3.86]],"id":41064273}],"con":true,"img":false}]}
{"op":"mcm","clk":"5321209066","pt":1646307216857,"mc":[{"id":"1.195532852","rc":[{"atb":[[2.36,9.13]],"id":41177799}],"con":true,"img":false}]}
{"op":"mcm","clk":"5321229641","pt":1646307415909,"mc":[{"id":"1.195532852","rc":[{"spn":5.9,"spf":1.0,"id":36532033},{"atb":[[3.2,0]],"id":36182808},{"spn":7.1,"spf":1.0,"id":36182808}],"con":true,"img":false}]}
{"op":"mcm","clk":"5321229854","pt":1646307418904,"mc":[{"id":"1.195532852","rc":[{"atb":[[3.4,4.67]],"id":36182808}],"con":true,"img":false}]}
{"op":"mcm","clk":"5321230690","pt":1646307426905,"mc":[{"id":"1.195532852","rc":[{"atb":[[2.96,0]],"id":36532033},{"atb":[[2.74,0]],"id":38794071},{"atb":[[2.74,0]],"id":38386807}],"con":true,"img":false}]}
{"op":"mcm","clk":"5321231218","pt":1646307432442,"mc":[{"id":"1.195532852","rc":[{"atb":[[2.32,0]],"id":41177799}],"con":true,"img":false}]}
{"op":"mcm","clk":"5321231725","pt":1646307437834,"mc":[{"id":"1.195532852","rc":[{"atb":[[2,11.2]],"id":41177799}],"con":true,"img":false}]}
{"op":"mcm","clk":"5321232441","pt":1646307444972,"mc":[{"id":"1.195532852","rc":[{"atb":[[2.82,6.82]],"id":38794071}],"con":true,"img":false}]}
{"op":"mcm","clk":"5321232465","pt":1646307445229,"mc":[{"id":"1.195532852","rc":[{"atb":[[2.82,6.82]],"id":38386807}],"con":true,"img":false}]}
{"op":"mcm","clk":"5321232484","pt":1646307445436,"mc":[{"id":"1.195532852","rc":[{"atb":[[3.1,5.91]],"id":36532033}],"con":true,"img":false}]}
{"op":"mcm","clk":"5321233773","pt":1646307460084,"mc":[{"id":"1.195532852","rc":[{"atb":[[3.8,0]],"id":41064273}],"con":true,"img":false}]}
{"op":"mcm","clk":"5321235363","pt":1646307475021,"mc":[{"id":"1.195532852","rc":[{"atb":[[4,4.14]],"id":41064273}],"con":true,"img":false}]}
{"op":"mcm","clk":"5321252624","pt":1646307662905,"mc":[{"id":"1.195532852","rc":[{"atb":[[3,0]],"id":36532033},{"atb":[[2.78,0]],"id":38794071},{"atb":[[2.78,0]],"id":38386807}],"con":true,"img":false}]}
{"op":"mcm","clk":"5321252805","pt":1646307665093,"mc":[{"id":"1.195532852","rc":[{"atb":[[3.3,0]],"id":36182808}],"con":true,"img":false}]}
{"op":"mcm","clk":"5321252861","pt":1646307665675,"mc":[{"id":"1.195532852","rc":[{"atb":[[2.86,6.02]],"id":38794071},{"atb":[[2.86,6.02]],"id":38386807}],"con":true,"img":false}]}
{"op":"mcm","clk":"5321252866","pt":1646307665775,"mc":[{"id":"1.195532852","rc":[{"atb":[[3.2,5.09]],"id":36532033}],"con":true,"img":false}]}
{"op":"mcm","clk":"5321253902","pt":1646307679329,"mc":[{"id":"1.195532852","rc":[{"atb":[[3.5,4.97]],"id":36182808}],"con":true,"img":false}]}
{"op":"mcm","clk":"5321253942","pt":1646307679940,"mc":[{"id":"1.195532852","rc":[{"atb":[[2.36,0]],"id":41177799}],"con":true,"img":false}]}
{"op":"mcm","clk":"5321254998","pt":1646307692879,"mc":[{"id":"1.195532852","rc":[{"atb":[[3.9,0]],"id":41064273}],"con":true,"img":false}]}
{"op":"mcm","clk":"5321255386","pt":1646307697151,"mc":[{"id":"1.195532852","rc":[{"atb":[[4.2,3.5]],"id":41064273}],"con":true,"img":false}]}
{"op":"mcm","clk":"5321255480","pt":1646307698387,"mc":[{"id":"1.195532852","rc":[{"atb":[[2.04,11.94]],"id":41177799}],"con":true,"img":false}]}
{"op":"mcm","clk":"5321271848","pt":1646307897159,"mc":[{"id":"1.195532852","rc":[{"atb":[[3.4,0]],"id":36182808}],"con":true,"img":false}]}
{"op":"mcm","clk":"5321272013","pt":1646307899240,"mc":[{"id":"1.195532852","rc":[{"atb":[[3.1,0]],"id":36532033},{"atb":[[2.82,0]],"id":38794071},{"atb":[[2.82,0]],"id":38386807}],"con":true,"img":false}]}
{"op":"mcm","clk":"5321272087","pt":1646307900073,"mc":[{"id":"1.195532852","rc":[{"atb":[[3.6,4.31]],"id":36182808}],"con":true,"img":false}]}
{"op":"mcm","clk":"5321273708","pt":1646307917510,"mc":[{"id":"1.195532852","rc":[{"atb":[[2.9,6.53]],"id":38794071}],"con":true,"img":false}]}
{"op":"mcm","clk":"5321273728","pt":1646307917772,"mc":[{"id":"1.195532852","rc":[{"atb":[[2.9,6.53]],"id":38386807}],"con":true,"img":false}]}
{"op":"mcm","clk":"5321273756","pt":1646307918082,"mc":[{"id":"1.195532852","rc":[{"atb":[[3.3,5.4]],"id":36532033}],"con":true,"img":false}]}
{"op":"mcm","clk":"5321275163","pt":1646307933931,"mc":[{"id":"1.195532852","rc":[{"atb":[[2,0]],"id":41177799}],"con":true,"img":false}]}
{"op":"mcm","clk":"5321275349","pt":1646307936005,"mc":[{"id":"1.195532852","rc":[{"atb":[[4,0]],"id":41064273}],"con":true,"img":false}]}
{"op":"mcm","clk":"5321275679","pt":1646307939395,"mc":[{"id":"1.195532852","rc":[{"atb":[[2.08,10.37]],"id":41177799}],"con":true,"img":false}]}
{"op":"mcm","clk":"5321276581","pt":1646307949836,"mc":[{"id":"1.195532852","rc":[{"atb":[[4.4,3.65]],"id":41064273}],"con":true,"img":false}]}
{"op":"mcm","clk":"5321276882","pt":1646307953770,"mc":[{"id":"1.195532852","rc":[{"atl":[[29,0]],"id":41064273},{"atl":[[15.5,0]],"id":36182808},{"atl":[[8.6,0]],"id":38794071},{"atb":[[4.3,0]],"id":38386807},{"atl":[[8.6,0]],"id":38386807}],"con":true,"img":false}]}
{"op":"mcm","clk":"5321276893","pt":1646307953819,"mc":[{"id":"1.195532852","rc":[{"atl":[[27,0.39]],"id":41064273},{"atl":[[14.5,0.75]],"id":36182808},{"atl":[[9,1.26]],"id":38794071},{"atb":[[3.8,2]],"id":38386807},{"atl":[[8.2,1.4]],"id":38386807}],"con":true,"img":false}]}
{"op":"mcm","clk":"5321282950","pt":1646308002563,"mc":[{"id":"1.195532852","marketDefinition":{"bspMarket":true,"turnInPlayEnabled":false,"persistenceEnabled":false,"marketBaseRate":5.0,"eventId":"31275720","eventTypeId":"4339","numberOfWinners":1,"bettingType":"ODDS","marketType":"WIN","marketTime":"2022-03-03T13:57:00.000Z","suspendTime":"2022-03-03T13:57:00.000Z","bspReconciled":false,"complete":true,"inPlay":false,"crossMatching":true,"runnersVoidable":false,"numberOfActiveRunners":6,"betDelay":0,"status":"OPEN","runners":[{"status":"ACTIVE","sortPriority":1,"id":38794071,"name":"1. Boynepark Zoom"},{"status":"ACTIVE","sortPriority":2,"id":41177799,"name":"2. Pantone Cheryl"},{"status":"ACTIVE","sortPriority":3,"id":41064273,"name":"3. Classic Bruno"},{"status":"ACTIVE","sortPriority":4,"id":36532033,"name":"4. To Tone Mars"},{"status":"ACTIVE","sortPriority":5,"id":36182808,"name":"5. Exve Alidocious"},{"status":"ACTIVE","sortPriority":6,"id":38386807,"name":"6. Underground Luke"}],"regulators":["MR_INT"],"venue":"Romford","countryCode":"GB","discountAllowed":true,"timezone":"Europe/London","openDate":"2022-03-03T13:57:00.000Z","version":4384107268,"name":"A6 400m","eventName":"Romford 3rd Mar"},"rc":[{"atb":[[1.12,30],[1.01,11000],[10,2],[9.2,1.23],[4.4,3.65],[4.2,3.5],[2.08,8.69]],"id":41064273},{"spl":[[10,10],[21,1]],"id":41064273},{"atl":[[550,3],[26,0.2],[27,0.39],[1000,12]],"id":41064273},{"spn":10.0,"spf":1.0,"id":41064273},{"atb":[[5.6,2],[1.12,30],[5.1,2],[3.2,5.09],[2.02,8.45],[1.01,11000],[3.3,5.4]],"id":36532033},{"spl":[[10,10],[21,1]],"id":36532033},{"atl":[[270,3],[6.2,3],[11,1.01],[13.5,0.2],[1000,12]],"id":36532033},{"trd":[[6.2,4]],"ltp":6.2,"tv":4.0,"id":36532033},{"spn":5.9,"spf":1.0,"id":36532033},{"atb":[[1.12,30],[3.6,4.31],[1.01,11000],[6.6,1.8],[3.5,4.97],[2.1,9.65]],"id":36182808},{"spl":[[21,1],[7.6,10]],"id":36182808},{"atl":[[560,3],[18,0.2],[14.5,0.75],[1000,12]],"id":36182808},{"trd":[[9.2,4]],"ltp":9.2,"tv":4.0,"id":36182808},{"spn":7.1,"spf":1.0,"id":36182808},{"atb":[[1.12,30],[5.1,2],[4.3,2],[1.01,11000],[2.9,6.53],[2.86,6.02],[2.1,11.41]],"id":38794071},{"spl":[[21,1],[42,10]],"id":38794071},{"atl":[[9,1.26],[11.5,0.2],[370,3],[1000,12]],"id":38794071},{"spn":7.05,"spf":1.0,"id":38794071},{"atb":[[5.1,2],[1.01,11000],[2.9,6.53],[2.86,6.02],[2.06,10.33],[3.8,2],[1.14,30]],"id":38386807},{"spl":[[10,10],[21,1]],"id":38386807},{"atl":[[8.2,1.4],[11.5,0.2],[500,3],[1000,12]],"id":38386807},{"spn":6.65,"spf":1.0,"id":38386807},{"atb":[[1.12,30],[1.01,11000],[2.52,2],[2.04,11.94],[2.34,9.56],[2.08,10.37],[2.76,2]],"id":41177799},{"spl":[[7.2,10],[21,1]],"id":41177799},{"atl":[[4,2],[390,3],[5.7,0.2],[1000,12]],"id":41177799},{"spn":3.38,"spf":1.0,"id":41177799}],"con":true,"img":true}]}
{"op":"mcm","clk":"5321299827","pt":1646308131506,"mc":[{"id":"1.195532852","rc":[{"atb":[[3.2,0]],"id":36532033},{"atb":[[2.86,0]],"id":38794071},{"spn":7.05,"spf":1.0,"id":38794071},{"atb":[[2.86,0]],"id":38386807},{"spn":6.65,"spf":1.0,"id":38386807}],"con":true,"img":false}]}
{"op":"mcm","clk":"5321299973","pt":1646308133515,"mc":[{"id":"1.195532852","rc":[{"atb":[[3.5,0]],"id":36182808}],"con":true,"img":false}]}
{"op":"mcm","clk":"5321300336","pt":1646308138335,"mc":[{"id":"1.195532852","rc":[{"atb":[[3.4,4.67]],"id":36532033}],"con":true,"img":false}]}
{"op":"mcm","clk":"5321300344","pt":1646308138438,"mc":[{"id":"1.195532852","rc":[{"atb":[[2.94,5.77]],"id":38794071},{"atb":[[2.94,5.77]],"id":38386807}],"con":true,"img":false}]}
{"op":"mcm","clk":"5321300359","pt":1646308138600,"mc":[{"id":"1.195532852","rc":[{"atb":[[5.1,0]],"id":36532033}],"con":true,"img":false}]}
{"op":"mcm","clk":"5321300368","pt":1646308138704,"mc":[{"id":"1.195532852","rc":[{"atb":[[3.15,2]],"id":36532033}],"con":true,"img":false}]}
{"op":"mcm","clk":"5321301206","pt":1646308148622,"mc":[{"id":"1.195532852","rc":[{"atb":[[3.7,4.6]],"id":36182808}],"con":true,"img":false}]}
{"op":"mcm","clk":"5321302965","pt":1646308170895,"mc":[{"id":"1.195532852","rc":[{"atb":[[4.2,0]],"id":41064273}],"con":true,"img":false}]}
{"op":"mcm","clk":"5321303243","pt":1646308174017,"mc":[{"id":"1.195532852","rc":[{"atb":[[4.6,3.11]],"id":41064273}],"con":true,"img":false}]}
{"op":"mcm","clk":"5321303896","pt":1646308180609,"mc":[{"id":"1.195532852","rc":[{"atb":[[2.04,0]],"id":41177799}],"con":true,"img":false}]}
{"op":"mcm","clk":"5321305416","pt":1646308197037,"mc":[{"id":"1.195532852","rc":[{"atb":[[2.12,11.09]],"id":41177799}],"con":true,"img":false}]}
{"op":"mcm","clk":"5321320889","pt":1646308369213,"mc":[{"id":"1.195532852","rc":[{"atb":[[3.6,0]],"id":36182808}],"con":true,"img":false}]}
{"op":"mcm","clk":"5321321131","pt":1646308371713,"mc":[{"id":"1.195532852","rc":[{"atb":[[3.8,4]],"id":36182808}],"con":true,"img":false}]}
{"op":"mcm","clk":"5321321329","pt":1646308374035,"mc":[{"id":"1.195532852","rc":[{"atb":[[3.3,0]],"id":36532033},{"atb":[[2.9,0]],"id":38794071},{"atb":[[2.9,0]],"id":38386807}],"con":true,"img":false}]}
{"op":"mcm","clk":"5321322994","pt":1646308392157,"mc":[{"id":"1.195532852","rc":[{"atb":[[2.98,6.27]],"id":38794071}],"con":true,"img":false}]}
{"op":"mcm","clk":"5321323028","pt":1646308392466,"mc":[{"id":"1.195532852","rc":[{"atb":[[2.98,6.27]],"id":38386807}],"con":true,"img":false}]}
{"op":"mcm","clk":"5321323095","pt":1646308393039,"mc":[{"id":"1.195532852","rc":[{"atb":[[3.5,4.97]],"id":36532033}],"con":true,"img":false}]}
{"op":"mcm","clk":"5321325053","pt":1646308414091,"mc":[{"id":"1.195532852","rc":[{"atb":[[2.08,0]],"id":41177799}],"con":true,"img":false}]}
{"op":"mcm","clk":"5321325366","pt":1646308416994,"mc":[{"id":"1.195532852","rc":[{"atb":[[2.16,9.66]],"id":41177799}],"con":true,"img":false}]}
{"op":"mcm","clk":"5321325844","pt":1646308422218,"mc":[{"id":"1.195532852","rc":[{"atb":[[4.4,0]],"id":41064273}],"con":true,"img":false}]}
{"op":"mcm","clk":"5321327307","pt":1646308437577,"mc":[{"id":"1.195532852","rc":[{"atb":[[4.8,3.27]],"id":41064273}],"con":true,"img":false}]}
{"op":"mcm","clk":"5321345918","pt":1646308606318,"mc":[{"id":"1.195532852","rc":[{"atb":[[3.4,0]],"id":36532033},{"atb":[[2.94,0]],"id":38794071},{"atb":[[2.94,0]],"id":38386807}],"con":true,"img":false}]}
{"op":"mcm","clk":"5321345950","pt":1646308606626,"mc":[{"id":"1.195532852","rc":[{"atb":[[3.7,0]],"id":36182808}],"con":true,"img":false}]}
{"op":"mcm","clk":"5321346173","pt":1646308609625,"mc":[{"id":"1.195532852","rc":[{"atb":[[3.6,4.31]],"id":36532033}],"con":true,"img":false}]}
{"op":"mcm","clk":"5321346184","pt":1646308609727,"mc":[{"id":"1.195532852","rc":[{"atb":[[3.05,5.47]],"id":38794071}],"con":true,"img":false}]}
{"op":"mcm","clk":"5321346209","pt":1646308609906,"mc":[{"id":"1.195532852","rc":[{"atb":[[3.05,5.47]],"id":38386807}],"con":true,"img":false}]}
{"op":"mcm","clk":"5321347417","pt":1646308623934,"mc":[{"id":"1.195532852","rc":[{"atb":[[3.9,4.28]],"id":36182808}],"con":true,"img":false}]}
{"op":"mcm","clk":"5321347609","pt":1646308625947,"mc":[{"id":"1.195532852","rc":[{"atl":[[11,10.2]],"id":36532033}],"con":true,"img":false}]}
{"op":"mcm","clk":"5321347620","pt":1646308626050,"mc":[{"id":"1.195532852","rc":[{"atb":[[2.62,64.81]],"id":36532033},{"atl":[[17,9.5],[34,15.5],[14,15.2]],"id":36532033},{"atb":[[2.62,64.81]],"id":41064273},{"atb":[[2.62,64.81]],"id":36182808},{"atl":[[34,15.5]],"id":38794071},{"atl":[[34,15.5]],"id":38386807},{"atl":[[17,9.5],[34,15.5]],"id":41177799}],"con":true,"img":false}]}
{"op":"mcm","clk":"5321348984","pt":1646308642071,"mc":[{"id":"1.195532852","rc":[{"atl":[[8,1.65]],"id":38386807}],"con":true,"img":false}]}
{"op":"mcm","clk":"5321349887","pt":1646308653281,"mc":[{"id":"1.195532852","rc":[{"atl":[[18.5,15.2],[14.5,9.2]],"id":38386807}],"con":true,"img":false}]}
{"op":"mcm","clk":"5321349975","pt":1646308654580,"mc":[{"id":"1.195532852","rc":[{"atb":[[4.6,0]],"id":41064273}],"con":true,"img":false}]}
{"op":"mcm","clk":"5321350425","pt":1646308659809,"mc":[{"id":"1.195532852","rc":[{"atb":[[2.12,0]],"id":41177799}],"con":true,"img":false}]}
{"op":"mcm","clk":"5321352066","pt":1646308677832,"mc":[{"id":"1.195532852","rc":[{"spn":6.55,"spf":1.0,"id":38386807},{"atb":[[2.2,10.35]],"id":41177799}],"con":true,"img":false}]}
{"op":"mcm","clk":"5321366791","pt":1646308841407,"mc":[{"id":"1.195532852","rc":[{"atb":[[3.8,0]],"id":36182808}],"con":true,"img":false}]}
{"op":"mcm","clk":"5321367034","pt":1646308843922,"mc":[{"id":"1.195532852","rc":[{"atb":[[4,3.73]],"id":36182808}],"con":true,"img":false}]}
{"op":"mcm","clk":"5321368767","pt":1646308864428,"mc":[{"id":"1.195532852","rc":[{"atb":[[3.5,0]],"id":36532033},{"atb":[[2.98,0]],"id":38794071},{"atb":[[2.98,0]],"id":38386807}],"con":true,"img":false}]}
{"op":"mcm","clk":"5321370279","pt":1646308882530,"mc":[{"id":"1.195532852","rc":[{"atb":[[3.15,5.78]],"id":38794071}],"con":true,"img":false}]}
{"op":"mcm","clk":"5321370287","pt":1646308882636,"mc":[{"id":"1.195532852","rc":[{"atb":[[3.15,5.78]],"id":38386807}],"con":true,"img":false}]}
{"op":"mcm","clk":"5321370317","pt":1646308882903,"mc":[{"id":"1.195532852","rc":[{"atb":[[3.7,4.6]],"id":36532033}],"con":true,"img":false}]}
{"op":"mcm","clk":"5321371151","pt":1646308892545,"mc":[{"id":"1.195532852","rc":[{"atb":[[2.16,0]],"id":41177799}],"con":true,"img":false}]}
{"op":"mcm","clk":"5321371530","pt":1646308897550,"mc":[{"id":"1.195532852","rc":[{"atb":[[4.8,0]],"id":41064273}],"con":true,"img":false}]}
{"op":"mcm","clk":"5321371567","pt":1646308897961,"mc":[{"id":"1.195532852","rc":[{"atb":[[2.24,9.04]],"id":41177799}],"con":true,"img":false}]}
{"op":"mcm","clk":"5321371596","pt":1646308898119,"mc":[{"id":"1.195532852","rc":[{"atb":[[3.6,4.31]],"id":41064273}],"con":true,"img":false}]}
{"op":"mcm","clk":"5321380483","pt":1646309006233,"mc":[{"id":"1.195532852","rc":[{"atb":[[3.7,4.6]],"id":41064273}],"con":true,"img":false}]}
{"op":"mcm","clk":"5321388076","pt":1646309099940,"mc":[{"id":"1.195532852","rc":[{"atb":[[3.6,0]],"id":36532033},{"atb":[[3.05,0]],"id":38794071},{"atb":[[3.05,0]],"id":38386807}],"con":true,"img":false}]}
{"op":"mcm","clk":"5321388317","pt":1646309102758,"mc":[{"id":"1.195532852","rc":[{"atb":[[3.25,4.98]],"id":38794071},{"atb":[[3.25,4.98]],"id":38386807}],"con":true,"img":false}]}
{"op":"mcm","clk":"5321388330","pt":1646309102863,"mc":[{"id":"1.195532852","rc":[{"atb":[[3.8,4]],"id":36532033}],"con":true,"img":false}]}
{"op":"mcm","clk":"5321400167","pt":1646309241949,"mc":[{"id":"1.195532852","rc":[{"atb":[[3.6,0]],"id":41064273}],"con":true,"img":false}]}
{"op":"mcm","clk":"5321400485","pt":1646309246047,"mc":[{"id":"1.195532852","rc":[{"atb":[[3.9,0]],"id":36182808},{"atb":[[2.2,0]],"id":41177799}],"con":true,"img":false}]}
{"op":"mcm","clk":"5321400566","pt":1646309247233,"mc":[{"id":"1.195532852","rc":[{"atb":[[3.8,4]],"id":41064273}],"con":true,"img":false}]}
{"op":"mcm","clk":"5321402647","pt":1646309271522,"mc":[{"id":"1.195532852","rc":[{"atb":[[2.28,9.7]],"id":41177799}],"con":true,"img":false}]}
{"op":"mcm","clk":"5321402672","pt":1646309271788,"mc":[{"id":"1.195532852","rc":[{"atb":[[4.2,3.88]],"id":36182808}],"con":true,"img":false}]}
{"op":"mcm","clk":"5321418302","pt":1646309477332,"mc":[{"id":"1.195532852","rc":[{"atb":[[3.7,0]],"id":41064273},{"atb":[[3.7,0]],"id":36532033},{"atb":[[3.15,0]],"id":38794071},{"atb":[[3.15,0]],"id":38386807}],"con":true,"img":false}]}
{"op":"mcm","clk":"5321418527","pt":1646309480140,"mc":[{"id":"1.195532852","rc":[{"atb":[[4,0]],"id":36182808},{"atb":[[2.24,0]],"id":41177799}],"con":true,"img":false}]}
{"op":"mcm","clk":"5321419057","pt":1646309486466,"mc":[{"id":"1.195532852","rc":[{"atb":[[2.32,8.48]],"id":41177799}],"con":true,"img":false}]}
{"op":"mcm","clk":"5321419134","pt":1646309487346,"mc":[{"id":"1.195532852","rc":[{"atb":[[3.25,4.98]],"id":36182808}],"con":true,"img":false}]}
{"op":"mcm","clk":"5321420055","pt":1646309499260,"mc":[{"id":"1.195532852","rc":[{"atb":[[3.35,5.28]],"id":38794071}],"con":true,"img":false}]}
{"op":"mcm","clk":"5321420079","pt":1646309499572,"mc":[{"id":"1.195532852","rc":[{"atb":[[3.9,4.28]],"id":41064273},{"atb":[[3.25,5.52]],"id":36532033}],"con":true,"img":false}]}
{"op":"mcm","clk":"5321420123","pt":1646309500093,"mc":[{"id":"1.195532852","rc":[{"atb":[[3.35,5.28]],"id":38386807}],"con":true,"img":false}]}
{"op":"mcm","clk":"5321432527","pt":1646309656095,"mc":[{"id":"1.195532852","rc":[{"atl":[[11.5,0]],"id":38794071}],"con":true,"img":false}]}
{"op":"mcm","clk":"5321432541","pt":1646309656198,"mc":[{"id":"1.195532852","rc":[{"atl":[[13.5,0.2]],"id":38794071}],"con":true,"img":false}]}
{"op":"mcm","clk":"5321432677","pt":1646309657499,"mc":[{"id":"1.195532852","rc":[{"atl":[[5.7,0]],"id":41177799}],"con":true,"img":false}]}
{"op":"mcm","clk":"5321432687","pt":1646309657603,"mc":[{"id":"1.195532852","rc":[{"atl":[[7.2,0.2]],"id":41177799}],"con":true,"img":false}]}
{"op":"mcm","clk":"5321432839","pt":1646309658910,"mc":[{"id":"1.195532852","rc":[{"atl":[[11.5,0]],"id":38386807}],"con":true,"img":false}]}
{"op":"mcm","clk":"5321432855","pt":1646309659015,"mc":[{"id":"1.195532852","rc":[{"atl":[[11,0.2]],"id":38386807}],"con":true,"img":false}]}
{"op":"mcm","clk":"5321438066","pt":1646309712081,"mc":[{"id":"1.195532852","rc":[{"atb":[[3.8,0]],"id":41064273},{"atb":[[3.8,0]],"id":36532033},{"atb":[[3.25,0]],"id":38794071},{"atb":[[3.25,0]],"id":38386807}],"con":true,"img":false}]}
{"op":"mcm","clk":"5321438580","pt":1646309717384,"mc":[{"id":"1.195532852","rc":[{"atb":[[3.45,4.57]],"id":38386807}],"con":true,"img":false}]}
{"op":"mcm","clk":"5321438588","pt":1646309717487,"mc":[{"id":"1.195532852","rc":[{"atb":[[4,3.73]],"id":41064273}],"con":true,"img":false}]}
{"op":"mcm","clk":"5321438678","pt":1646309718478,"mc":[{"id":"1.195532852","rc":[{"atb":[[3.35,4.76]],"id":36532033}],"con":true,"img":false}]}
{"op":"mcm","clk":"5321438701","pt":1646309718689,"mc":[{"id":"1.195532852","rc":[{"atb":[[3.45,4.57]],"id":38794071}],"con":true,"img":false}]}
{"op":"mcm","clk":"5321440701","pt":1646309737268,"mc":[{"id":"1.195532852","rc":[{"atb":[[4.2,0]],"id":36182808},{"atb":[[2.28,0]],"id":41177799}],"con":true,"img":false}]}
{"op":"mcm","clk":"5321443090","pt":1646309758383,"mc":[{"id":"1.195532852","rc":[{"atb":[[2.36,9.13]],"id":41177799}],"con":true,"img":false}]}
{"op":"mcm","clk":"5321443172","pt":1646309759215,"mc":[{"id":"1.195532852","rc":[{"atb":[[3.35,5.28]],"id":36182808}],"con":true,"img":false}]}
{"op":"mcm","clk":"5321462363","pt":1646309956539,"mc":[{"id":"1.195532852","rc":[{"atb":[[3.9,0]],"id":41064273},{"atb":[[3.35,0]],"id":38794071},{"atb":[[3.35,0]],"id":38386807}],"con":true,"img":false}]}
{"op":"mcm","clk":"5321463654","pt":1646309972354,"mc":[{"id":"1.195532852","rc":[{"atb":[[2.32,0]],"id":41177799}],"con":true,"img":false}]}
{"op":"mcm","clk":"5321463864","pt":1646309974642,"mc":[{"id":"1.195532852","rc":[{"atb":[[3.55,4.87]],"id":38386807}],"con":true,"img":false}]}
{"op":"mcm","clk":"5321463874","pt":1646309974743,"mc":[{"id":"1.195532852","rc":[{"atb":[[4.2,3.88]],"id":41064273}],"con":true,"img":false}]}
{"op":"mcm","clk":"5321463889","pt":1646309974949,"mc":[{"id":"1.195532852","rc":[{"atb":[[3.55,4.87]],"id":38794071}],"con":true,"img":false}]}
{"op":"mcm","clk":"5321463915","pt":1646309975360,"mc":[{"id":"1.195532852","rc":[{"atb":[[3.25,0]],"id":36532033}],"con":true,"img":false}]}
{"op":"mcm","clk":"5321464236","pt":1646309979554,"mc":[{"id":"1.195532852","rc":[{"atb":[[2.04,10.77]],"id":41177799}],"con":true,"img":false}]}
{"op":"mcm","clk":"5321465513","pt":1646309991899,"mc":[{"id":"1.195532852","rc":[{"atb":[[3.45,5.07]],"id":36532033}],"con":true,"img":false}]}
{"op":"mcm","clk":"5321465613","pt":1646309993090,"mc":[{"id":"1.195532852","rc":[{"atb":[[3.25,0]],"id":36182808}],"con":true,"img":false}]}
{"op":"mcm","clk":"5321466355","pt":1646310000378,"mc":[{"id":"1.195532852","rc":[{"atb":[[3.45,4.57]],"id":36182808}],"con":true,"img":false}]}
{"op":"mcm","clk":"5321486331","pt":1646310194175,"mc":[{"id":"1.195532852","rc":[{"atb":[[4,0]],"id":41064273},{"atb":[[3.45,0]],"id":38794071},{"atb":[[3.45,0]],"id":38386807}],"con":true,"img":false}]}
{"op":"mcm","clk":"5321486962","pt":1646310200007,"mc":[{"id":"1.195532852","rc":[{"atb":[[2.84,6.09]],"id":38794071}],"con":true,"img":false}]}
{"op":"mcm","clk":"5321487006","pt":1646310200392,"mc":[{"id":"1.195532852","rc":[{"atb":[[2.74,6.44]],"id":38386807}],"con":true,"img":false}]}
{"op":"mcm","clk":"5321487023","pt":1646310200595,"mc":[{"id":"1.195532852","rc":[{"atb":[[4.4,3.29]],"id":41064273}],"con":true,"img":false}]}
{"op":"mcm","clk":"5321487623","pt":1646310206304,"mc":[{"id":"1.195532852","rc":[{"atb":[[2.36,0]],"id":41177799}],"con":true,"img":false}]}
{"op":"mcm","clk":"5321488231","pt":1646310212930,"mc":[{"id":"1.195532852","rc":[{"atb":[[3.35,0]],"id":36532033}],"con":true,"img":false}]}
{"op":"mcm","clk":"5321488688","pt":1646310217998,"mc":[{"id":"1.195532852","rc":[{"atb":[[3.55,4.39]],"id":36532033}],"con":true,"img":false}]}
{"op":"mcm","clk":"5321490205","pt":1646310231543,"mc":[{"id":"1.195532852","rc":[{"atb":[[2.08,11.5]],"id":41177799}],"con":true,"img":false}]}
{"op":"mcm","clk":"5321491968","pt":1646310250552,"mc":[{"id":"1.195532852","rc":[{"atb":[[3.35,0]],"id":36182808}],"con":true,"img":false}]}
{"op":"mcm","clk":"5321493358","pt":1646310266104,"mc":[{"id":"1.195532852","rc":[{"atb":[[3.55,4.87]],"id":36182808}],"con":true,"img":false}]}
{"op":"mcm","clk":"5321507608","pt":1646310437897,"mc":[{"id":"1.195532852","rc":[{"atb":[[4.2,0]],"id":41064273},{"atb":[[3.55,0]],"id":38794071},{"atb":[[3.55,0]],"id":38386807}],"con":true,"img":false}]}
{"op":"mcm","clk":"5321508487","pt":1646310449707,"mc":[{"id":"1.195532852","rc":[{"atb":[[2.88,6.61]],"id":38794071}],"con":true,"img":false}]}
{"op":"mcm","clk":"5321508497","pt":1646310449806,"mc":[{"id":"1.195532852","rc":[{"atb":[[4.6,3.45]],"id":41064273}],"con":true,"img":false}]}
{"op":"mcm","clk":"5321508512","pt":1646310450014,"mc":[{"id":"1.195532852","rc":[{"atb":[[2.78,6.98]],"id":38386807}],"con":true,"img":false}]}
{"op":"mcm","clk":"5321509611","pt":1646310464430,"mc":[{"id":"1.195532852","rc":[{"atb":[[3.45,0]],"id":36532033}],"con":true,"img":false}]}
{"op":"mcm","clk":"5321509897","pt":1646310467255,"mc":[{"id":"1.195532852","rc":[{"atb":[[2.04,0]],"id":41177799}],"con":true,"img":false}]}
{"op":"mcm","clk":"5321510868","pt":1646310479354,"mc":[{"id":"1.195532852","rc":[{"atb":[[3.65,4.68]],"id":36532033}],"con":true,"img":false}]}
{"op":"mcm","clk":"5321511108","pt":1646310482764,"mc":[{"id":"1.195532852","rc":[{"atb":[[3.45,0]],"id":36182808}],"con":true,"img":false}]}
{"op":"mcm","clk":"5321521301","pt":1646310610455,"mc":[{"id":"1.195532852","rc":[{"atb":[[3.65,4.22]],"id":36182808}],"con":true,"img":false}]}
{"op":"mcm","clk":"5321521460","pt":1646310611746,"mc":[{"id":"1.195532852","rc":[{"atb":[[2.12,10]],"id":41177799}],"con":true,"img":false}]}
{"op":"mcm","clk":"5321527258","pt":1646310672056,"mc":[{"id":"1.195532852","rc":[{"atb":[[4.4,0]],"id":41064273}],"con":true,"img":false}]}
{"op":"mcm","clk":"5321527535","pt":1646310674751,"mc":[{"id":"1.195532852","rc":[{"atb":[[4.8,2.95]],"id":41064273}],"con":true,"img":false}]}
{"op":"mcm","clk":"5321529517","pt":1646310685586,"mc":[{"id":"1.195532852","rc":[{"atb":[[2.84,0]],"id":38794071},{"atb":[[2.74,0]],"id":38386807}],"con":true,"img":false}]}
{"op":"mcm","clk":"5321529749","pt":1646310686785,"mc":[{"id":"1.195532852","rc":[{"spb":[[1000,20]],"id":41177799}],"con":true,"img":false}]}
{"op":"mcm","clk":"5321530234","pt":1646310689957,"mc":[{"id":"1.195532852","rc":[{"atb":[[2.92,5.83]],"id":38794071},{"atb":[[2.82,6.15]],"id":38386807}],"con":true,"img":false}]}
{"op":"mcm","clk":"5321531474","pt":1646310700695,"mc":[{"id":"1.195532852","rc":[{"atb":[[3.55,0]],"id":36532033}],"con":true,"img":false}]}
{"op":"mcm","clk":"5321531950","pt":1646310704995,"mc":[{"id":"1.195532852","rc":[{"atb":[[3.75,4.07]],"id":36532033}],"con":true,"img":false}]}
{"op":"mcm","clk":"5321533831","pt":1646310723012,"mc":[{"id":"1.195532852","rc":[{"atb":[[3.55,0]],"id":36182808},{"atb":[[2.08,0]],"id":41177799}],"con":true,"img":false}]}
{"op":"mcm","clk":"5321535507","pt":1646310738468,"mc":[{"id":"1.195532852","rc":[{"atb":[[2.16,10.71]],"id":41177799},{"spn":7.2,"spf":7.2,"id":41177799}],"con":true,"img":false}]}
{"op":"mcm","clk":"5321535525","pt":1646310738674,"mc":[{"id":"1.195532852","rc":[{"atb":[[3.75,4.51]],"id":36182808}],"con":true,"img":false}]}
{"op":"mcm","clk":"5321555668","pt":1646310926595,"mc":[{"id":"1.195532852","rc":[{"atb":[[4.6,0]],"id":41064273},{"atb":[[2.88,0]],"id":38794071},{"atb":[[2.78,0]],"id":38386807}],"con":true,"img":false}]}
{"op":"mcm","clk":"5321556914","pt":1646310939827,"mc":[{"id":"1.195532852","rc":[{"atb":[[3.65,0]],"id":36532033}],"con":true,"img":false}]}
{"op":"mcm","clk":"5321556926","pt":1646310939886,"mc":[{"id":"1.195532852","rc":[{"atb":[[2.96,6.33]],"id":38794071}],"con":true,"img":false}]}
{"op":"mcm","clk":"5321556952","pt":1646310940089,"mc":[{"id":"1.195532852","rc":[{"atb":[[2.86,6.67]],"id":38386807}],"con":true,"img":false}]}
{"op":"mcm","clk":"5321558443","pt":1646310955604,"mc":[{"id":"1.195532852","rc":[{"atb":[[3.25,5.52]],"id":36532033}],"con":true,"img":false}]}
{"op":"mcm","clk":"5321558628","pt":1646310957528,"mc":[{"id":"1.195532852","rc":[{"atb":[[3.65,0]],"id":36182808},{"atb":[[2.12,0]],"id":41177799}],"con":true,"img":false}]}
{"op":"mcm","clk":"5321558936","pt":1646310961324,"mc":[{"id":"1.195532852","rc":[{"atb":[[2.2,9.34]],"id":41177799}],"con":true,"img":false}]}
{"op":"mcm","clk":"5321558951","pt":1646310961530,"mc":[{"id":"1.195532852","rc":[{"atb":[[3.85,3.93]],"id":36182808}],"con":true,"img":false}]}
{"op":"mcm","clk":"5321578894","pt":1646311164471,"mc":[{"id":"1.195532852","rc":[{"atb":[[4.8,0]],"id":41064273},{"atb":[[2.92,0]],"id":38794071},{"atb":[[2.82,0]],"id":38386807}],"con":true,"img":false}]}
{"op":"mcm","clk":"5321579409","pt":1646311169553,"mc":[{"id":"1.195532852","rc":[{"atb":[[3,5.6]],"id":38794071}],"con":true,"img":false}]}
{"op":"mcm","clk":"5321579417","pt":1646311169656,"mc":[{"id":"1.195532852","rc":[{"atb":[[3.6,4.31]],"id":41064273},{"atb":[[2.9,5.89]],"id":38386807}],"con":true,"img":false}]}
{"op":"mcm","clk":"5321580494","pt":1646311176466,"mc":[{"id":"1.195532852","rc":[{"atb":[[3.75,0]],"id":36532033}],"con":true,"img":false}]}
{"op":"mcm","clk":"5321580921","pt":1646311180163,"mc":[{"id":"1.195532852","rc":[{"atb":[[3.35,4.76]],"id":36532033}],"con":true,"img":false}]}
{"op":"mcm","clk":"5321581320","pt":1646311183671,"mc":[{"id":"1.195532852","rc":[{"atb":[[3.7,4.6]],"id":41064273}],"con":true,"img":false}]}
{"op":"mcm","clk":"5321584110","pt":1646311210737,"mc":[{"id":"1.195532852","rc":[{"atb":[[3.75,0]],"id":36182808},{"atb":[[2.16,0]],"id":41177799}],"con":true,"img":false}]}
{"op":"mcm","clk":"5321584744","pt":1646311221667,"mc":[{"id":"1.195532852","rc":[{"atb":[[2.24,10.02]],"id":41177799}],"con":true,"img":false}]}
{"op":"mcm","clk":"5321584752","pt":1646311221770,"mc":[{"id":"1.195532852","rc":[{"atb":[[3.95,4.2]],"id":36182808}],"con":true,"img":false}]}
{"op":"mcm","clk":"5321601650","pt":1646311418461,"mc":[{"id":"1.195532852","rc":[{"atb":[[3.25,0]],"id":36532033},{"atb":[[2.96,0]],"id":38794071},{"atb":[[2.86,0]],"id":38386807}],"con":true,"img":false}]}
{"op":"mcm","clk":"5321601893","pt":1646311421164,"mc":[{"id":"1.195532852","rc":[{"atb":[[3.6,0]],"id":41064273}],"con":true,"img":false}]}
{"op":"mcm","clk":"5321602076","pt":1646311423239,"mc":[{"id":"1.195532852","rc":[{"atb":[[3.8,4]],"id":41064273}],"con":true,"img":false}]}
{"op":"mcm","clk":"5321603147","pt":1646311435953,"mc":[{"id":"1.195532852","rc":[{"atb":[[3.1,5.91]],"id":38794071}],"con":true,"img":false}]}
{"op":"mcm","clk":"5321603172","pt":1646311436265,"mc":[{"id":"1.195532852","rc":[{"atb":[[2.94,6.4]],"id":38386807}],"con":true,"img":false}]}
{"op":"mcm","clk":"5321603198","pt":1646311436574,"mc":[{"id":"1.195532852","rc":[{"atb":[[3.45,5.07]],"id":36532033}],"con":true,"img":false}]}
{"op":"mcm","clk":"5321604197","pt":1646311448302,"mc":[{"id":"1.195532852","rc":[{"atb":[[3.85,0]],"id":36182808},{"atb":[[2.2,0]],"id":41177799}],"con":true,"img":false}]}
{"op":"mcm","clk":"5321604642","pt":1646311453987,"mc":[{"id":"1.195532852","rc":[{"atb":[[4.1,3.61]],"id":36182808}],"con":true,"img":false}]}
{"op":"mcm","clk":"5321604711","pt":1646311454923,"mc":[{"id":"1.195532852","rc":[{"atb":[[2.28,8.75]],"id":41177799}],"con":true,"img":false}]}
{"op":"mcm","clk":"5321617442","pt":1646311589841,"mc":[{"id":"1.195532852","rc":[{"atl":[[12,13]],"id":36182808}],"con":true,"img":false}]}
{"op":"mcm","clk":"5321617476","pt":1646311590248,"mc":[{"id":"1.195532852","rc":[{"atb":[[6.6,0]],"id":36182808}],"con":true,"img":false}]}
{"op":"mcm","clk":"5321617483","pt":1646311590360,"mc":[{"id":"1.195532852","rc":[{"atb":[[5.3,2]],"id":36182808}],"con":true,"img":false}]}
{"op":"mcm","clk":"5321617505","pt":1646311590566,"mc":[{"id":"1.195532852","rc":[{"atb":[[3.15,0]],"id":36532033}],"con":true,"img":false}]}
{"op":"mcm","clk":"5321617520","pt":1646311590661,"mc":[{"id":"1.195532852","rc":[{"atb":[[3.2,2]],"id":36532033}],"con":true,"img":false}]}
{"op":"mcm","clk":"5321618014","pt":1646311595953,"mc":[{"id":"1.195532852","rc":[{"atb":[[5.4,1.65]],"id":36182808}],"con":true,"img":false}]}
{"op":"mcm","clk":"5321623956","pt":1646311652075,"mc":[{"id":"1.195532852","rc":[{"atb":[[3.35,0]],"id":36532033},{"spn":6.5,"spf":1.0,"id":36182808},{"atb":[[3,0]],"id":38794071},{"atb":[[2.9,0]],"id":38386807}],"con":true,"img":false}]}
{"op":"mcm","clk":"5321624278","pt":1646311655282,"mc":[{"id":"1.195532852","rc":[{"atb":[[3.55,4.39]],"id":36532033}],"con":true,"img":false}]}
{"op":"mcm","clk":"5321624291","pt":1646311655342,"mc":[{"id":"1.195532852","rc":[{"atb":[[3.2,5.09]],"id":38794071}],"con":true,"img":false}]}
{"op":"mcm","clk":"5321624379","pt":1646311656065,"mc":[{"id":"1.195532852","rc":[{"atb":[[2.98,5.66]],"id":38386807}],"con":true,"img":false}]}
{"op":"mcm","clk":"5321639069","pt":1646311809090,"mc":[{"id":"1.195532852","rc":[{"atb":[[3.7,0]],"id":41064273},{"atb":[[3.95,0]],"id":36182808},{"atb":[[2.24,0]],"id":41177799}],"con":true,"img":false}]}
{"op":"mcm","clk":"5321641827","pt":1646311825698,"mc":[{"id":"1.195532852","rc":[{"atb":[[4.1,0]],"id":36182808}],"con":true,"img":false}]}
{"op":"mcm","clk":"5321642580","pt":1646311830342,"mc":[{"id":"1.195532852","rc":[{"atb":[[3.25,4.98]],"id":36182808}],"con":true,"img":false}]}
{"op":"mcm","clk":"5321644023","pt":1646311839444,"mc":[{"id":"1.195532852","rc":[{"atb":[[3.35,5.28]],"id":36182808}],"con":true,"img":false}]}
{"op":"mcm","clk":"5321644052","pt":1646311839641,"mc":[{"id":"1.195532852","rc":[{"atb":[[3.9,4.28]],"id":41064273}],"con":true,"img":false}]}
{"op":"mcm","clk":"5321644100","pt":1646311839905,"mc":[{"id":"1.195532852","rc":[{"atb":[[2.32,9.41]],"id":41177799}],"con":true,"img":false}]}
{"op":"mcm","clk":"5321653435","pt":1646311922482,"mc":[{"id":"1.195532852","rc":[{"atb":[[2.76,52.27]],"id":36182808}],"con":true,"img":false}]}
{"op":"mcm","clk":"5321653455","pt":1646311922586,"mc":[{"id":"1.195532852","rc":[{"atb":[[2.32,77.27]],"id":36182808}],"con":true,"img":false}]}
{"op":"mcm","clk":"5321662124","pt":1646311998223,"mc":[{"id":"1.195532852","rc":[{"atb":[[2.1,0]],"id":36182808}],"con":true,"img":false}]}
{"op":"mcm","clk":"5321662136","pt":1646311998327,"mc":[{"id":"1.195532852","rc":[{"atb":[[2.34,9.65]],"id":36182808}],"con":true,"img":false}]}
{"op":"mcm","clk":"5321668025","pt":1646312043064,"mc":[{"id":"1.195532852","rc":[{"atb":[[2.28,0]],"id":41177799}],"con":true,"img":false}]}
{"op":"mcm","clk":"5321668391","pt":1646312046214,"mc":[{"id":"1.195532852","rc":[{"atb":[[2.36,8.24]],"id":41177799}],"con":true,"img":false}]}
{"op":"mcm","clk":"5321668778","pt":1646312049194,"mc":[{"id":"1.195532852","rc":[{"atb":[[3.45,0]],"id":36532033},{"atb":[[3.1,0]],"id":38794071},{"atb":[[2.94,0]],"id":38386807}],"con":true,"img":false}]}
{"op":"mcm","clk":"5321670658","pt":1646312065907,"mc":[{"id":"1.195532852","rc":[{"atb":[[3.3,5.4]],"id":38794071}],"con":true,"img":false}]}
{"op":"mcm","clk":"5321670677","pt":1646312066122,"mc":[{"id":"1.195532852","rc":[{"atb":[[3.65,4.68]],"id":36532033}],"con":true,"img":false}]}
{"op":"mcm","clk":"5321670721","pt":1646312066528,"mc":[{"id":"1.195532852","rc":[{"atb":[[3.05,6.06]],"id":38386807}],"con":true,"img":false}]}
{"op":"mcm","clk":"5321671771","pt":1646312076633,"mc":[{"id":"1.195532852","rc":[{"atb":[[3.8,0]],"id":41064273},{"atb":[[3.25,0]],"id":36182808}],"con":true,"img":false}]}
{"op":"mcm","clk":"5321672345","pt":1646312082862,"mc":[{"id":"1.195532852","rc":[{"atb":[[4,3.73]],"id":41064273}],"con":true,"img":false}]}
{"op":"mcm","clk":"5321672356","pt":1646312082918,"mc":[{"id":"1.195532852","rc":[{"atb":[[3.45,4.57]],"id":36182808}],"con":true,"img":false}]}
{"op":"mcm","clk":"5321684849","pt":1646312221762,"mc":[{"id":"1.195532852","rc":[{"atl":[[34,15.5]],"id":36182808}],"con":true,"img":false}]}
{"op":"mcm","clk":"5321689794","pt":1646312284093,"mc":[{"id":"1.195532852","rc":[{"atb":[[3.55,0]],"id":36532033},{"atb":[[3.2,0]],"id":38794071},{"atb":[[2.98,0]],"id":38386807}],"con":true,"img":false}]}
{"op":"mcm","clk":"5321690192","pt":1646312289347,"mc":[{"id":"1.195532852","rc":[{"atb":[[3.15,5.21]],"id":38386807}],"con":true,"img":false}]}
{"op":"mcm","clk":"5321690208","pt":1646312289528,"mc":[{"id":"1.195532852","rc":[{"atb":[[3.75,4.07]],"id":36532033},{"atb":[[3.4,4.67]],"id":38794071}],"con":true,"img":false}]}
{"op":"mcm","clk":"5321690443","pt":1646312292236,"mc":[{"id":"1.195532852","rc":[{"atb":[[2.32,0]],"id":41177799}],"con":true,"img":false}]}
{"op":"mcm","clk":"5321691518","pt":1646312305833,"mc":[{"id":"1.195532852","rc":[{"atb":[[2.1,11.29]],"id":41177799}],"con":true,"img":false}]}
{"op":"mcm","clk":"5321692637","pt":1646312321349,"mc":[{"id":"1.195532852","rc":[{"atb":[[3.9,0]],"id":41064273},{"atb":[[3.35,0]],"id":36182808}],"con":true,"img":false}]}
{"op":"mcm","clk":"5321694141","pt":1646312339713,"mc":[{"id":"1.195532852","rc":[{"atb":[[4.2,3.88]],"id":41064273}],"con":true,"img":false}]}
{"op":"mcm","clk":"5321694150","pt":1646312339815,"mc":[{"id":"1.195532852","rc":[{"atb":[[3.55,4.87]],"id":36182808}],"con":true,"img":false}]}
{"op":"mcm","clk":"5321700069","pt":1646312399436,"mc":[{"id":"1.195532852","rc":[{"atb":[[1.02,2.24]],"id":41064273}],"con":true,"img":false}]}
{"op":"mcm","clk":"5321700086","pt":1646312399540,"mc":[{"id":"1.195532852","rc":[{"atb":[[1.01,11002.24]],"id":36182808}],"con":true,"img":false}]}
{"op":"mcm","clk":"5321700111","pt":1646312399814,"mc":[{"id":"1.195532852","rc":[{"atb":[[1.02,0.35]],"id":41064273}],"con":true,"img":false}]}
{"op":"mcm","clk":"5321700130","pt":1646312400013,"mc":[{"id":"1.195532852","rc":[{"atb":[[1.02,0]],"id":41064273},{"atb":[[1.01,11000.68]],"id":36182808}],"con":true,"img":false}]}
{"op":"mcm","clk":"5321700143","pt":1646312400117,"mc":[{"id":"1.195532852","rc":[{"atb":[[10.5,0.35]],"id":41064273}],"con":true,"img":false}]}
{"op":"mcm","clk":"5321700163","pt":1646312400327,"mc":[{"id":"1.195532852","rc":[{"atb":[[1.01,11000]],"id":36182808}],"con":true,"img":false}]}
{"op":"mcm","clk":"5321700179","pt":1646312400439,"mc":[{"id":"1.195532852","rc":[{"atb":[[5.5,0.68]],"id":36182808}],"con":true,"img":false}]}
{"op":"mcm","clk":"5321710735","pt":1646312513959,"mc":[{"id":"1.195532852","rc":[{"atb":[[4,3.73],[10.5,0.35],[4.2,3.88],[2.08,8.69]],"id":41064273},{"atb":[[2.02,8.44],[3.75,4.07],[3.65,4.68]],"id":36532033},{"atb":[[3.45,4.57],[5.5,0.68],[3.55,4.86],[2.34,9.65],[5.4,1.65]],"id":36182808},{"atl":[[22,9.2],[29,15.2]],"id":36182808},{"spn":6.55,"spf":1.0,"id":36182808},{"atb":[[3.4,4.67],[3.3,5.39],[2.1,11.4]],"id":38794071},{"atb":[[2.06,10.33],[3.15,5.21],[3.05,6.06]],"id":38386807},{"atl":[[8,1.65]],"id":38386807},{"atb":[[2.36,8.24],[2.1,11.29],[2.34,9.56]],"id":41177799}],"con":true,"img":false}]}
{"op":"mcm","clk":"5321711957","pt":1646312526947,"mc":[{"id":"1.195532852","rc":[{"atb":[[2.36,0]],"id":41177799}],"con":true,"img":false}]}
{"op":"mcm","clk":"5321712068","pt":1646312528142,"mc":[{"id":"1.195532852","rc":[{"atb":[[3.65,0]],"id":36532033},{"atb":[[3.3,0]],"id":38794071},{"atb":[[3.05,0]],"id":38386807}],"con":true,"img":false}]}
{"op":"mcm","clk":"5321712338","pt":1646312530684,"mc":[{"id":"1.195532852","rc":[{"atb":[[2.14,9.83]],"id":41177799}],"con":true,"img":false}]}
{"op":"mcm","clk":"5321713674","pt":1646312544197,"mc":[{"id":"1.195532852","rc":[{"atb":[[3.5,4.96]],"id":38794071}],"con":true,"img":false}]}
{"op":"mcm","clk":"5321713695","pt":1646312544406,"mc":[{"id":"1.195532852","rc":[{"atb":[[3.3,5.39]],"id":36532033}],"con":true,"img":false}]}
{"op":"mcm","clk":"5321713711","pt":1646312544461,"mc":[{"id":"1.195532852","rc":[{"atb":[[3.25,5.52]],"id":38386807}],"con":true,"img":false}]}
{"op":"mcm","clk":"5321714869","pt":1646312558002,"mc":[{"id":"1.195532852","rc":[{"atb":[[4,0]],"id":41064273},{"atb":[[3.45,0]],"id":36182808}],"con":true,"img":false}]}
{"op":"mcm","clk":"5321715300","pt":1646312563033,"mc":[{"id":"1.195532852","rc":[{"atb":[[4.4,3.29]],"id":41064273},{"atb":[[3.65,4.23]],"id":36182808}],"con":true,"img":false}]}
{"op":"mcm","clk":"5321735235","pt":1646312761504,"mc":[{"id":"1.195532852","rc":[{"atb":[[3.75,0]],"id":36532033},{"atb":[[3.4,0]],"id":38794071},{"atb":[[3.15,0]],"id":38386807}],"con":true,"img":false}]}
{"op":"mcm","clk":"5321735525","pt":1646312764272,"mc":[{"id":"1.195532852","rc":[{"atb":[[2.96,5.71]],"id":38794071}],"con":true,"img":false}]}
{"op":"mcm","clk":"5321735539","pt":1646312764374,"mc":[{"id":"1.195532852","rc":[{"atb":[[3.4,4.67]],"id":36532033}],"con":true,"img":false}]}
{"op":"mcm","clk":"5321735551","pt":1646312764479,"mc":[{"id":"1.195532852","rc":[{"atb":[[3.35,4.76]],"id":38386807}],"con":true,"img":false}]}
{"op":"mcm","clk":"5321737213","pt":1646312780142,"mc":[{"id":"1.195532852","rc":[{"atb":[[2.1,0]],"id":41177799}],"con":true,"img":false}]}
{"op":"mcm","clk":"5321738865","pt":1646312795908,"mc":[{"id":"1.195532852","rc":[{"atb":[[2.18,10.52]],"id":41177799}],"con":true,"img":false}]}
{"op":"mcm","clk":"5321740222","pt":1646312811030,"mc":[{"id":"1.195532852","rc":[{"atb":[[4.2,0]],"id":41064273},{"atb":[[3.55,0]],"id":36182808}],"con":true,"img":false}]}
{"op":"mcm","clk":"5321742082","pt":1646312825847,"mc":[{"id":"1.195532852","rc":[{"atb":[[4.6,3.45]],"id":41064273}],"con":true,"img":false}]}
{"op":"mcm","clk":"5321742102","pt":1646312826052,"mc":[{"id":"1.195532852","rc":[{"atb":[[3.75,4.51]],"id":36182808}],"con":true,"img":false}]}
{"op":"mcm","clk":"5321761021","pt":1646312979176,"mc":[{"id":"1.195532852","rc":[{"atl":[[6.2,0]],"id":36532033},{"spn":7.8,"spf":1.0,"id":36532033}],"con":true,"img":false}]}
{"op":"mcm","clk":"5321761043","pt":1646312979387,"mc":[{"id":"1.195532852","rc":[{"atb":[[3.2,0]],"id":36532033}],"con":true,"img":false}]}
{"op":"mcm","clk":"5321761057","pt":1646312979500,"mc":[{"id":"1.195532852","rc":[{"atb":[[3.7,2]],"id":36532033}],"con":true,"img":false}]}
{"op":"mcm","clk":"5321761373","pt":1646312982503,"mc":[{"id":"1.195532852","rc":[{"atl":[[10.5,1.65]],"id":36532033}],"con":true,"img":false}]}
{"op":"mcm","clk":"5321764269","pt":1646313005933,"mc":[{"id":"1.195532852","rc":[{"atl":[[11,1.01],[14,0]],"id":36532033}],"con":true,"img":false}]}
{"op":"mcm","clk":"5321764344","pt":1646313006617,"mc":[{"id":"1.195532852","rc":[{"atb":[[3.3,0]],"id":36532033},{"atb":[[3.5,0]],"id":38794071},{"atb":[[3.25,0]],"id":38386807}],"con":true,"img":false}]}
{"op":"mcm","clk":"5321765722","pt":1646313018057,"mc":[{"id":"1.195532852","rc":[{"atb":[[2.14,0]],"id":41177799}],"con":true,"img":false}]}
{"op":"mcm","clk":"5321766138","pt":1646313021853,"mc":[{"id":"1.195532852","rc":[{"atb":[[3.8,4.43]],"id":36532033}],"con":true,"img":false}]}
{"op":"mcm","clk":"5321766147","pt":1646313021956,"mc":[{"id":"1.195532852","rc":[{"atb":[[3,6.2]],"id":38794071}],"con":true,"img":false}]}
{"op":"mcm","clk":"5321766176","pt":1646313022164,"mc":[{"id":"1.195532852","rc":[{"atb":[[3.45,5.06]],"id":38386807}],"con":true,"img":false}]}
{"op":"mcm","clk":"5321766446","pt":1646313024479,"mc":[{"id":"1.195532852","rc":[{"atb":[[2.22,9.19]],"id":41177799}],"con":true,"img":false}]}
{"op":"mcm","clk":"5321768833","pt":1646313044482,"mc":[{"id":"1.195532852","rc":[{"atb":[[4.4,0]],"id":41064273},{"atb":[[3.65,0]],"id":36182808}],"con":true,"img":false}]}
{"op":"mcm","clk":"5321769120","pt":1646313047174,"mc":[{"id":"1.195532852","rc":[{"atb":[[4.8,2.95]],"id":41064273}],"con":true,"img":false}]}
{"op":"mcm","clk":"5321769144","pt":1646313047380,"mc":[{"id":"1.195532852","rc":[{"atb":[[2.8,6.22]],"id":36182808}],"con":true,"img":false}]}
{"op":"mcm","clk":"5321787728","pt":1646313212850,"mc":[{"id":"1.195532852","rc":[{"atb":[[3.4,0]],"id":36532033},{"atb":[[2.96,0]],"id":38794071}],"con":true,"img":false}]}
{"op":"mcm","clk":"5321788084","pt":1646313216455,"mc":[{"id":"1.195532852","rc":[{"atb":[[3.1,5.33]],"id":38794071}],"con":true,"img":false}]}
{"op":"mcm","clk":"5321788101","pt":1646313216665,"mc":[{"id":"1.195532852","rc":[{"atb":[[3.8,8.44]],"id":36532033}],"con":true,"img":false}]}
{"op":"mcm","clk":"5321788942","pt":1646313225076,"mc":[{"id":"1.195532852","rc":[{"atb":[[5.6,0]],"id":36532033},{"atl":[[5.6,1]],"id":36532033},{"trd":[[5.6,4]],"ltp":5.6,"tv":4.0,"id":36532033}],"con":true,"img":false}]}
{"op":"mcm","clk":"5321788966","pt":1646313225282,"mc":[{"id":"1.195532852","rc":[{"atb":[[3.85,2]],"id":36532033}],"con":true,"img":false}]}
{"op":"mcm","clk":"5321790661","pt":1646313240199,"mc":[{"id":"1.195532852","rc":[{"atb":[[2.68,3.55]],"id":36532033}],"con":true,"img":false}]}
{"op":"mcm","clk":"5321790671","pt":1646313240303,"mc":[{"id":"1.195532852","rc":[{"atb":[[3.35,0]],"id":38386807}],"con":true,"img":false}]}
{"op":"mcm","clk":"5321791135","pt":1646313243354,"mc":[{"id":"1.195532852","rc":[{"atb":[[3.55,4.39]],"id":38386807}],"con":true,"img":false}]}
{"op":"mcm","clk":"5321791460","pt":1646313245514,"mc":[{"id":"1.195532852","rc":[{"atb":[[2.2,6.22]],"id":38794071}],"con":true,"img":false}]}
{"op":"mcm","clk":"5321791476","pt":1646313245620,"mc":[{"id":"1.195532852","rc":[{"atb":[[2.28,5.83]],"id":41177799}],"con":true,"img":false}]}
{"op":"mcm","clk":"5321791501","pt":1646313245824,"mc":[{"id":"1.195532852","rc":[{"atb":[[2.76,4.24]],"id":36532033},{"atb":[[2.76,4.24]],"id":41064273}],"con":true,"img":false}]}
{"op":"mcm","clk":"5321791511","pt":1646313245929,"mc":[{"id":"1.195532852","rc":[{"atb":[[2.9,3.93]],"id":36182808}],"con":true,"img":false}]}
{"op":"mcm","clk":"5321791538","pt":1646313246133,"mc":[{"id":"1.195532852","rc":[{"atl":[[10.5,0]],"id":36532033}],"con":true,"img":false}]}
{"op":"mcm","clk":"5321792456","pt":1646313254739,"mc":[{"id":"1.195532852","rc":[{"atb":[[2.38,4.87]],"id":41177799}],"con":true,"img":false}]}
{"op":"mcm","clk":"5321792509","pt":1646313255322,"mc":[{"id":"1.195532852","rc":[{"atb":[[2.68,8.8]],"id":36532033},{"atb":[[2.18,0]],"id":41177799}],"con":true,"img":false}]}
{"op":"mcm","clk":"5321792768","pt":1646313257920,"mc":[{"id":"1.195532852","rc":[{"atb":[[2.28,0]],"id":41177799}],"con":true,"img":false}]}
{"op":"mcm","clk":"5321794214","pt":1646313271857,"mc":[{"id":"1.195532852","rc":[{"atb":[[2.76,10.5]],"id":36532033},{"atb":[[2.9,9.72]],"id":36182808}],"con":true,"img":false}]}
{"op":"mcm","clk":"5321794239","pt":1646313272165,"mc":[{"id":"1.195532852","rc":[{"atb":[[2.26,9.85]],"id":41177799}],"con":true,"img":false}]}
{"op":"mcm","clk":"5321794267","pt":1646313272429,"mc":[{"id":"1.195532852","rc":[{"atb":[[2.76,10.5]],"id":41064273}],"con":true,"img":false}]}
{"op":"mcm","clk":"5321795994","pt":1646313290882,"mc":[{"id":"1.195532852","rc":[{"atb":[[4.6,0]],"id":41064273},{"spn":4.72,"spf":1.0,"id":36532033},{"atb":[[3.75,0]],"id":36182808}],"con":true,"img":false}]}
{"op":"mcm","clk":"5321796329","pt":1646313294776,"mc":[{"id":"1.195532852","rc":[{"atl":[[9.8,9.2],[12.5,15.2]],"id":36532033}],"con":true,"img":false}]}
{"op":"mcm","clk":"5321797237","pt":1646313304072,"mc":[{"id":"1.195532852","rc":[{"atb":[[2.42,6.98]],"id":41177799}],"con":true,"img":false}]}
{"op":"mcm","clk":"5321797273","pt":1646313304383,"mc":[{"id":"1.195532852","rc":[{"atb":[[3.45,5.06]],"id":36182808}],"con":true,"img":false}]}
{"op":"mcm","clk":"5321798350","pt":1646313315985,"mc":[{"id":"1.195532852","rc":[{"atb":[[2.38,0]],"id":41177799}],"con":true,"img":false}]}
{"op":"mcm","clk":"5321798362","pt":1646313316090,"mc":[{"id":"1.195532852","rc":[{"atb":[[1.46,16.25]],"id":41177799}],"con":true,"img":false}]}
{"op":"mcm","clk":"5321799868","pt":1646313331643,"mc":[{"id":"1.195532852","rc":[{"atb":[[1.46,40.21]],"id":41177799}],"con":true,"img":false}]}
{"op":"mcm","clk":"5321799879","pt":1646313331750,"mc":[{"id":"1.195532852","rc":[{"atb":[[2.42,0]],"id":41177799}],"con":true,"img":false}]}
{"op":"mcm","clk":"5321800001","pt":1646313332936,"mc":[{"id":"1.195532852","rc":[{"atb":[[1.46,23.96]],"id":41177799}],"con":true,"img":false}]}
{"op":"mcm","clk":"5321801271","pt":1646313347542,"mc":[{"id":"1.195532852","rc":[{"atb":[[2.38,7.18]],"id":41177799}],"con":true,"img":false}]}
{"op":"mcm","clk":"5321801292","pt":1646313347750,"mc":[{"id":"1.195532852","rc":[{"atb":[[1.53,14.1]],"id":41177799}],"con":true,"img":false}]}
{"op":"mcm","clk":"5321804867","pt":1646313378100,"mc":[{"id":"1.195532852","rc":[{"atb":[[2.42,4.73]],"id":41177799}],"con":true,"img":false}]}
{"op":"mcm","clk":"5321815967","pt":1646313406523,"mc":[{"id":"1.195532852","rc":[{"atb":[[2.38,0]],"id":41177799}],"con":true,"img":false}]}
{"op":"mcm","clk":"5321816819","pt":1646313414459,"mc":[{"id":"1.195532852","rc":[{"atb":[[2.42,0]],"id":41177799}],"con":true,"img":false}]}
{"op":"mcm","clk":"5321818799","pt":1646313435586,"mc":[{"id":"1.195532852","rc":[{"atb":[[2.38,4.87]],"id":41177799}],"con":true,"img":false}]}
{"op":"mcm","clk":"5321819946","pt":1646313448304,"mc":[{"id":"1.195532852","rc":[{"atb":[[3,0]],"id":38794071}],"con":true,"img":false}]}
{"op":"mcm","clk":"5321821001","pt":1646313459877,"mc":[{"id":"1.195532852","rc":[{"atb":[[3.8,4.43]],"id":36532033},{"atb":[[2.8,0]],"id":36182808},{"atb":[[3.1,0]],"id":38794071}],"con":true,"img":false}]}
{"op":"mcm","clk":"5321821104","pt":1646313460908,"mc":[{"id":"1.195532852","rc":[{"atb":[[3.15,5.77]],"id":38794071}],"con":true,"img":false}]}
{"op":"mcm","clk":"5321821325","pt":1646313463094,"mc":[{"id":"1.195532852","rc":[{"atb":[[3.55,4.39]],"id":36182808},{"atb":[[3.25,4.98]],"id":38794071}],"con":true,"img":false}]}
{"op":"mcm","clk":"5321821340","pt":1646313463195,"mc":[{"id":"1.195532852","rc":[{"atb":[[2.8,6.22]],"id":36532033}],"con":true,"img":false}]}
{"op":"mcm","clk":"5321822363","pt":1646313473612,"mc":[{"id":"1.195532852","rc":[{"atb":[[2.42,6.98]],"id":41177799}],"con":true,"img":false}]}
{"op":"mcm","clk":"5321822378","pt":1646313473714,"mc":[{"id":"1.195532852","rc":[{"atb":[[3.8,0]],"id":36532033}],"con":true,"img":false}]}
{"op":"mcm","clk":"5321823016","pt":1646313480643,"mc":[{"id":"1.195532852","rc":[{"atb":[[2.38,0]],"id":41177799}],"con":true,"img":false}]}
{"op":"mcm","clk":"5321823774","pt":1646313489720,"mc":[{"id":"1.195532852","rc":[{"atb":[[2.22,0]],"id":41177799}],"con":true,"img":false}]}
{"op":"mcm","clk":"5321823946","pt":1646313491437,"mc":[{"id":"1.195532852","rc":[{"atb":[[3.45,0]],"id":38386807}],"con":true,"img":false}]}
{"op":"mcm","clk":"5321823955","pt":1646313491535,"mc":[{"id":"1.195532852","rc":[{"atb":[[2.84,6.74]],"id":36532033}],"con":true,"img":false}]}
{"op":"mcm","clk":"5321824047","pt":1646313492521,"mc":[{"id":"1.195532852","rc":[{"atb":[[2.3,8.62]],"id":41177799}],"con":true,"img":false}]}
{"op":"mcm","clk":"5321824563","pt":1646313498026,"mc":[{"id":"1.195532852","rc":[{"atb":[[2.1,0]],"id":38794071}],"con":true,"img":false}]}
{"op":"mcm","clk":"5321824576","pt":1646313498142,"mc":[{"id":"1.195532852","rc":[{"atb":[[2.22,11.4]],"id":38794071}],"con":true,"img":false}]}
{"op":"mcm","clk":"5321824728","pt":1646313499430,"mc":[{"id":"1.195532852","rc":[{"atb":[[2.46,4.6]],"id":41177799}],"con":true,"img":false}]}
{"op":"mcm","clk":"5321824740","pt":1646313499530,"mc":[{"id":"1.195532852","rc":[{"atb":[[2.2,0]],"id":38794071}],"con":true,"img":false}]}
{"op":"mcm","clk":"5321825377","pt":1646313506175,"mc":[{"id":"1.195532852","rc":[{"atb":[[2.86,5.33]],"id":36532033}],"con":true,"img":false}]}
{"op":"mcm","clk":"5321825390","pt":1646313506282,"mc":[{"id":"1.195532852","rc":[{"atb":[[2.42,0]],"id":41177799}],"con":true,"img":false}]}
{"op":"mcm","clk":"5321825409","pt":1646313506439,"mc":[{"id":"1.195532852","rc":[{"atb":[[2.98,6.27]],"id":38386807}],"con":true,"img":false}]}
{"op":"mcm","clk":"5321826032","pt":1646313513976,"mc":[{"id":"1.195532852","rc":[{"atb":[[2.46,0]],"id":41177799}],"con":true,"img":false}]}
{"op":"mcm","clk":"5321826327","pt":1646313517662,"mc":[{"id":"1.195532852","rc":[{"atb":[[2.34,5.57]],"id":38794071}],"con":true,"img":false}]}
{"op":"mcm","clk":"5321826721","pt":1646313521465,"mc":[{"id":"1.195532852","rc":[{"atb":[[2.34,13.79]],"id":38794071}],"con":true,"img":false}]}
{"op":"mcm","clk":"5321827130","pt":1646313525660,"mc":[{"id":"1.195532852","rc":[{"atb":[[4.8,0]],"id":41064273}],"con":true,"img":false}]}
{"op":"mcm","clk":"5321827376","pt":1646313528401,"mc":[{"id":"1.195532852","rc":[{"atb":[[4.1,3.61]],"id":41064273}],"con":true,"img":false}]}
{"op":"mcm","clk":"5321827960","pt":1646313535304,"mc":[{"id":"1.195532852","rc":[{"atb":[[2.92,3.5]],"id":36532033}],"con":true,"img":false}]}
{"op":"mcm","clk":"5321827971","pt":1646313535402,"mc":[{"id":"1.195532852","rc":[{"atb":[[2.38,4.87]],"id":41177799}],"con":true,"img":false}]}
{"op":"mcm","clk":"5321828326","pt":1646313539405,"mc":[{"id":"1.195532852","rc":[{"atb":[[4.3,3.76]],"id":41064273}],"con":true,"img":false}]}
{"op":"mcm","clk":"5321829934","pt":1646313555190,"mc":[{"id":"1.195532852","rc":[{"atb":[[2.86,0]],"id":36532033}],"con":true,"img":false}]}
{"op":"mcm","clk":"5321830795","pt":1646313563265,"mc":[{"id":"1.195532852","rc":[{"atb":[[2.92,0]],"id":36532033}],"con":true,"img":false}]}
{"op":"mcm","clk":"5321831795","pt":1646313572565,"mc":[{"id":"1.195532852","rc":[{"atb":[[2.42,6.98]],"id":41177799}],"con":true,"img":false}]}
{"op":"mcm","clk":"5321832553","pt":1646313579861,"mc":[{"id":"1.195532852","rc":[{"atb":[[2.38,0]],"id":41177799}],"con":true,"img":false}]}
{"op":"mcm","clk":"5321832830","pt":1646313582559,"mc":[{"id":"1.195532852","rc":[{"atb":[[2.9,3.54]],"id":36532033}],"con":true,"img":false}]}
{"op":"mcm","clk":"5321834839","pt":1646313600684,"mc":[{"id":"1.195532852","rc":[{"atb":[[2.46,4.6]],"id":41177799}],"con":true,"img":false}]}
{"op":"mcm","clk":"5321834958","pt":1646313601682,"mc":[{"id":"1.195532852","rc":[{"atb":[[2.42,0]],"id":41177799}],"con":true,"img":false}]}
{"op":"mcm","clk":"5321836209","pt":1646313612699,"mc":[{"id":"1.195532852","rc":[{"atb":[[2.46,0]],"id":41177799}],"con":true,"img":false}]}
{"op":"mcm","clk":"5321836620","pt":1646313616709,"mc":[{"id":"1.195532852","rc":[{"atb":[[2.38,7.18]],"id":41177799}],"con":true,"img":false}]}
{"op":"mcm","clk":"5321836661","pt":1646313617026,"mc":[{"id":"1.195532852","rc":[{"atb":[[2.96,5.05]],"id":36532033}],"con":true,"img":false}]}
{"op":"mcm","clk":"5321837507","pt":1646313624729,"mc":[{"id":"1.195532852","rc":[{"atb":[[2.9,0]],"id":36532033}],"con":true,"img":false}]}
{"op":"mcm","clk":"5321839760","pt":1646313644604,"mc":[{"id":"1.195532852","rc":[{"atb":[[2.96,0]],"id":36532033}],"con":true,"img":false}]}
{"op":"mcm","clk":"5321839872","pt":1646313645702,"mc":[{"id":"1.195532852","rc":[{"atb":[[2.42,4.73]],"id":41177799}],"con":true,"img":false}]}
{"op":"mcm","clk":"5321840163","pt":1646313648214,"mc":[{"id":"1.195532852","rc":[{"atl":[[1000,12.3]],"id":38386807}],"con":true,"img":false}]}
{"op":"mcm","clk":"5321840186","pt":1646313648376,"mc":[{"id":"1.195532852","rc":[{"atl":[[1000,12]],"id":38386807}],"con":true,"img":false}]}
{"op":"mcm","clk":"5321840198","pt":1646313648476,"mc":[{"id":"1.195532852","rc":[{"atb":[[5.1,1.7]],"id":38386807},{"trd":[[5.1,0.6]],"ltp":5.1,"tv":0.6,"id":38386807}],"con":true,"img":false}]}
{"op":"mcm","clk":"5321840336","pt":1646313649815,"mc":[{"id":"1.195532852","rc":[{"atb":[[5.1,2]],"id":38386807}],"con":true,"img":false}]}
{"op":"mcm","clk":"5321841749","pt":1646313662734,"mc":[{"id":"1.195532852","rc":[{"atb":[[2.86,5.33]],"id":36532033}],"con":true,"img":false}]}
{"op":"mcm","clk":"5321843344","pt":1646313677653,"mc":[{"id":"1.195532852","rc":[{"atb":[[2.38,0]],"id":41177799}],"con":true,"img":false}]}
{"op":"mcm","clk":"5321844048","pt":1646313684932,"mc":[{"id":"1.195532852","rc":[{"atb":[[2.42,0]],"id":41177799}],"con":true,"img":false}]}
{"op":"mcm","clk":"5321844693","pt":1646313691262,"mc":[{"id":"1.195532852","rc":[{"atb":[[2.92,3.5]],"id":36532033}],"con":true,"img":false}]}
{"op":"mcm","clk":"5321846128","pt":1646313704069,"mc":[{"id":"1.195532852","rc":[{"atb":[[3.45,0]],"id":36182808},{"atb":[[3.15,0]],"id":38794071}],"con":true,"img":false}]}
{"op":"mcm","clk":"5321846398","pt":1646313706975,"mc":[{"id":"1.195532852","rc":[{"atb":[[2.38,4.87]],"id":41177799}],"con":true,"img":false}]}
{"op":"mcm","clk":"5321847586","pt":1646313718852,"mc":[{"id":"1.195532852","rc":[{"atb":[[2.86,0]],"id":36532033},{"atb":[[3.65,4.68]],"id":36182808}],"con":true,"img":false}]}
{"op":"mcm","clk":"5321847617","pt":1646313719160,"mc":[{"id":"1.195532852","rc":[{"atb":[[3.35,5.28]],"id":38794071}],"con":true,"img":false}]}
{"op":"mcm","clk":"5321847982","pt":1646313723666,"mc":[{"id":"1.195532852","rc":[{"atb":[[2.8,0]],"id":36532033},{"atb":[[3.55,0]],"id":38386807}],"con":true,"img":false}]}
{"op":"mcm","clk":"5321848274","pt":1646313726579,"mc":[{"id":"1.195532852","rc":[{"atb":[[2.88,5.96]],"id":36532033}],"con":true,"img":false}]}
{"op":"mcm","clk":"5321848282","pt":1646313726681,"mc":[{"id":"1.195532852","rc":[{"atb":[[2.92,0]],"id":36532033},{"atb":[[3.05,5.47]],"id":38386807}],"con":true,"img":false}]}
{"op":"mcm","clk":"5321848736","pt":1646313731198,"mc":[{"id":"1.195532852","rc":[{"atb":[[2.26,0]],"id":41177799}],"con":true,"img":false}]}
{"op":"mcm","clk":"5321850370","pt":1646313746706,"mc":[{"id":"1.195532852","rc":[{"atb":[[2.34,18.82]],"id":41177799}],"con":true,"img":false}]}
{"op":"mcm","clk":"5321850397","pt":1646313746919,"mc":[{"id":"1.195532852","rc":[{"atb":[[2.42,6.98]],"id":41177799}],"con":true,"img":false}]}
{"op":"mcm","clk":"5321850510","pt":1646313748017,"mc":[{"id":"1.195532852","rc":[{"atb":[[1.53,0]],"id":41177799}],"con":true,"img":false}]}
{"op":"mcm","clk":"5321850523","pt":1646313748130,"mc":[{"id":"1.195532852","rc":[{"atb":[[2.9,3.54]],"id":36532033}],"con":true,"img":false}]}
{"op":"mcm","clk":"5321851421","pt":1646313756763,"mc":[{"id":"1.195532852","rc":[{"atb":[[2.38,0]],"id":41177799}],"con":true,"img":false}]}
{"op":"mcm","clk":"5321852602","pt":1646313769202,"mc":[{"id":"1.195532852","rc":[{"atb":[[2.46,5.12]],"id":41177799}],"con":true,"img":false}]}
{"op":"mcm","clk":"5321852871","pt":1646313772284,"mc":[{"id":"1.195532852","rc":[{"atb":[[4.1,0]],"id":41064273}],"con":true,"img":false}]}
{"op":"mcm","clk":"5321853245","pt":1646313775813,"mc":[{"id":"1.195532852","rc":[{"atb":[[4.5,3.2]],"id":41064273}],"con":true,"img":false}]}
{"op":"mcm","clk":"5321853256","pt":1646313775918,"mc":[{"id":"1.195532852","rc":[{"atb":[[2.46,9.72]],"id":41177799}],"con":true,"img":false}]}
{"op":"mcm","clk":"5321853584","pt":1646313779496,"mc":[{"id":"1.195532852","rc":[{"atb":[[2.42,0]],"id":41177799}],"con":true,"img":false}]}
{"op":"mcm","clk":"5321854566","pt":1646313790620,"mc":[{"id":"1.195532852","rc":[{"atb":[[2.46,5.12]],"id":41177799}],"con":true,"img":false}]}
{"op":"mcm","clk":"5321855241","pt":1646313797900,"mc":[{"id":"1.195532852","rc":[{"atb":[[2.96,5.05]],"id":36532033}],"con":true,"img":false}]}
{"op":"mcm","clk":"5321855277","pt":1646313798219,"mc":[{"id":"1.195532852","rc":[{"atb":[[2.84,0]],"id":36532033},{"atb":[[2.22,0]],"id":38794071}],"con":true,"img":false}]}
{"op":"mcm","clk":"5321855292","pt":1646313798317,"mc":[{"id":"1.195532852","rc":[{"atb":[[2.36,11.4]],"id":38794071}],"con":true,"img":false}]}
{"op":"mcm","clk":"5321855402","pt":1646313799311,"mc":[{"id":"1.195532852","rc":[{"atb":[[2.34,8.22]],"id":38794071}],"con":true,"img":false}]}
{"op":"mcm","clk":"5321855769","pt":1646313802740,"mc":[{"id":"1.195532852","rc":[{"atl":[[12,10]],"id":36182808}],"con":true,"img":false}]}
{"op":"mcm","clk":"5321856041","pt":1646313805137,"mc":[{"id":"1.195532852","rc":[{"atb":[[2.9,0]],"id":36532033}],"con":true,"img":false}]}
{"op":"mcm","clk":"5321856379","pt":1646313808043,"mc":[{"id":"1.195532852","rc":[{"atb":[[2.38,4.87]],"id":41177799}],"con":true,"img":false}]}
{"op":"mcm","clk":"5321856843","pt":1646313812540,"mc":[{"id":"1.195532852","rc":[{"atb":[[2.5,6.61]],"id":41177799}],"con":true,"img":false}]}
{"op":"mcm","clk":"5321856913","pt":1646313813273,"mc":[{"id":"1.195532852","rc":[{"atb":[[2.34,0]],"id":38794071}],"con":true,"img":false}]}
{"op":"mcm","clk":"5321856985","pt":1646313813873,"mc":[{"id":"1.195532852","rc":[{"atb":[[2.92,6.46]],"id":36532033}],"con":true,"img":false}]}
{"op":"mcm","clk":"5321857394","pt":1646313817871,"mc":[{"id":"1.195532852","rc":[{"atb":[[2.48,5.05]],"id":38794071}],"con":true,"img":false}]}
{"op":"mcm","clk":"5321858116","pt":1646313823179,"mc":[{"id":"1.195532852","rc":[{"atb":[[2.38,0]],"id":41177799}],"con":true,"img":false}]}
{"op":"mcm","clk":"5321858477","pt":1646313825848,"mc":[{"id":"1.195532852","rc":[{"atb":[[3,3.36]],"id":36532033}],"con":true,"img":false}]}
{"op":"mcm","clk":"5321858791","pt":1646313828465,"mc":[{"id":"1.195532852","rc":[{"atb":[[2.96,0]],"id":36532033},{"atb":[[2.48,12.5]],"id":38794071}],"con":true,"img":false}]}
{"op":"mcm","clk":"5321859423","pt":1646313835051,"mc":[{"id":"1.195532852","rc":[{"atb":[[3,0]],"id":36532033}],"con":true,"img":false}]}
{"op":"mcm","clk":"5321860019","pt":1646313841180,"mc":[{"id":"1.195532852","rc":[{"atb":[[2.56,4.31]],"id":41177799}],"con":true,"img":false}]}
{"op":"mcm","clk":"5321861827","pt":1646313860452,"mc":[{"id":"1.195532852","rc":[{"atb":[[2.98,3.4]],"id":36532033}],"con":true,"img":false}]}
{"op":"mcm","clk":"5321862735","pt":1646313872637,"mc":[{"id":"1.195532852","rc":[{"atb":[[2.5,0]],"id":41177799}],"con":true,"img":false}]}
{"op":"mcm","clk":"5321863238","pt":1646313880253,"mc":[{"id":"1.195532852","rc":[{"atb":[[2.56,0]],"id":41177799}],"con":true,"img":false}]}
{"op":"mcm","clk":"5321864834","pt":1646313901070,"mc":[{"id":"1.195532852","rc":[{"atb":[[2.38,4.87]],"id":41177799}],"con":true,"img":false}]}
{"op":"mcm","clk":"5321865025","pt":1646313903375,"mc":[{"id":"1.195532852","rc":[{"atb":[[3.05,4.83]],"id":36532033}],"con":true,"img":false}]}
{"op":"mcm","clk":"5321865606","pt":1646313910381,"mc":[{"id":"1.195532852","rc":[{"atb":[[2.98,0]],"id":36532033}],"con":true,"img":false}]}
{"op":"mcm","clk":"5321866272","pt":1646313918015,"mc":[{"id":"1.195532852","rc":[{"atb":[[2.5,6.61]],"id":41177799}],"con":true,"img":false}]}
{"op":"mcm","clk":"5321867088","pt":1646313928345,"mc":[{"id":"1.195532852","rc":[{"atb":[[2.38,0]],"id":41177799}],"con":true,"img":false}]}
{"op":"mcm","clk":"5321867359","pt":1646313931710,"mc":[{"id":"1.195532852","rc":[{"atb":[[3.1,3.2]],"id":36532033}],"con":true,"img":false}]}
{"op":"mcm","clk":"5321867440","pt":1646313932754,"mc":[{"id":"1.195532852","rc":[{"atb":[[3.05,0]],"id":36532033}],"con":true,"img":false}]}
{"op":"mcm","clk":"5321867874","pt":1646313937833,"mc":[{"id":"1.195532852","rc":[{"atb":[[3.55,0]],"id":36182808},{"atb":[[3.25,0]],"id":38794071}],"con":true,"img":false}]}
{"op":"mcm","clk":"5321868108","pt":1646313940630,"mc":[{"id":"1.195532852","rc":[{"atb":[[3.1,0]],"id":36532033},{"atb":[[3.75,4.07]],"id":36182808}],"con":true,"img":false}]}
{"op":"mcm","clk":"5321868141","pt":1646313941043,"mc":[{"id":"1.195532852","rc":[{"atb":[[3.45,4.57]],"id":38794071}],"con":true,"img":false}]}
{"op":"mcm","clk":"5321868609","pt":1646313947168,"mc":[{"id":"1.195532852","rc":[{"atb":[[2.56,4.31]],"id":41177799}],"con":true,"img":false}]}
{"op":"mcm","clk":"5321868798","pt":1646313949048,"mc":[{"id":"1.195532852","rc":[{"atb":[[2.94,5.11]],"id":36532033}],"con":true,"img":false}]}
{"op":"mcm","clk":"5321870661","pt":1646313963687,"mc":[{"id":"1.195532852","rc":[{"atb":[[2.5,0]],"id":41177799}],"con":true,"img":false}]}
{"op":"mcm","clk":"5321870695","pt":1646313963952,"mc":[{"id":"1.195532852","rc":[{"atb":[[2.98,0]],"id":38386807}],"con":true,"img":false}]}
{"op":"mcm","clk":"5321870739","pt":1646313964378,"mc":[{"id":"1.195532852","rc":[{"atb":[[2.3,0]],"id":41177799}],"con":true,"img":false}]}
{"op":"mcm","clk":"5321871022","pt":1646313967359,"mc":[{"id":"1.195532852","rc":[{"atb":[[2.18,9.5]],"id":41177799}],"con":true,"img":false}]}
{"op":"mcm","clk":"5321871345","pt":1646313971572,"mc":[{"id":"1.195532852","rc":[{"atb":[[2.56,0]],"id":41177799}],"con":true,"img":false}]}
{"op":"mcm","clk":"5321872099","pt":1646313982012,"mc":[{"id":"1.195532852","rc":[{"atb":[[3.15,5.77]],"id":38386807}],"con":true,"img":false}]}
{"op":"mcm","clk":"5321872227","pt":1646313983682,"mc":[{"id":"1.195532852","rc":[{"atb":[[3,3.36]],"id":36532033}],"con":true,"img":false}]}
{"op":"mcm","clk":"5321872970","pt":1646313994635,"mc":[{"id":"1.195532852","rc":[{"atb":[[2.38,4.87]],"id":41177799}],"con":true,"img":false}]}
{"op":"mcm","clk":"5321874855","pt":1646314018251,"mc":[{"id":"1.195532852","rc":[{"atb":[[2.94,0]],"id":36532033}],"con":true,"img":false}]}
{"op":"mcm","clk":"5321874883","pt":1646314018664,"mc":[{"id":"1.195532852","rc":[{"atb":[[4.3,0]],"id":41064273}],"con":true,"img":false}]}
{"op":"mcm","clk":"5321874895","pt":1646314018871,"mc":[{"id":"1.195532852","rc":[{"atb":[[2.5,6.61]],"id":41177799}],"con":true,"img":false}]}
{"op":"mcm","clk":"5321875116","pt":1646314021678,"mc":[{"id":"1.195532852","rc":[{"atb":[[8,5.71],[6.8,43.1],[7.2,24.19],[7.6,15.15]],"id":41064273},{"atl":[[34,4.55],[38,6.76],[28,1.48],[30,3.45]],"id":41064273},{"atb":[[3.55,58.82],[3.75,14.55],[3.45,102.04],[3.65,37.74]],"id":36532033},{"atl":[[9,5],[10.5,26.32],[9.8,26.25],[9.4,11.9]],"id":36532033},{"atb":[[5.3,11.3],[4.9,38.46],[5.1,24.39],[4.7,67.57]],"id":36182808},{"atl":[[16,16.67],[13,3.33],[14,7.69],[15,10.71]],"id":36182808},{"atb":[[4,33.33],[4.3,0],[3.8,89.29],[3.9,51.72],[4.2,12.5]],"id":38794071},{"atl":[[9,0],[10.5,15.79],[11.5,23.81],[9.8,11.36],[9.4,4.76]],"id":38794071},{"atb":[[3.45,102.04],[3.55,58.82],[3.75,14.55],[3.65,37.74]],"id":38386807},{"atl":[[9.6,29.07],[9.2,18.29],[8.8,12.82],[8.4,5.41]],"id":38386807},{"atb":[[2.32,113.64],[2.4,28.57],[2.36,73.53],[2.28,195.31]],"id":41177799},{"atl":[[4.8,65.79],[4.6,41.67],[4.4,29.41],[4.2,12.5]],"id":41177799}],"con":true,"img":false}]}
{"op":"mcm","clk":"5321875124","pt":1646314021784,"mc":[{"id":"1.195532852","rc":[{"atl":[[8.6,5.26]],"id":36532033},{"atb":[[6.4,27.78],[6,50]],"id":41064273},{"atl":[[27,0]],"id":41064273}],"con":true,"img":false}]}
{"op":"mcm","clk":"5321875135","pt":1646314021886,"mc":[{"id":"1.195532852","rc":[{"atl":[[26,0.61]],"id":41064273},{"atb":[[1.01,11002.24],[5.5,0]],"id":36182808},{"atb":[[4.6,2]],"id":38794071},{"atl":[[9.8,12.51]],"id":38794071}],"con":true,"img":false}]}
{"op":"mcm","clk":"5321875155","pt":1646314022094,"mc":[{"id":"1.195532852","rc":[{"atb":[[2.76,6.25]],"id":41064273},{"atb":[[2.76,6.25]],"id":36532033},{"atb":[[1.01,11000.68],[2.9,5.79]],"id":36182808},{"atb":[[2.48,7.45]],"id":38794071},{"atb":[[2.46,0]],"id":41177799}],"con":true,"img":false}]}
{"op":"mcm","clk":"5321875168","pt":1646314022252,"mc":[{"id":"1.195532852","rc":[{"atb":[[1.01,11000]],"id":36182808}],"con":true,"img":false}]}
{"op":"mcm","clk":"5321875181","pt":1646314022359,"mc":[{"id":"1.195532852","rc":[{"atb":[[5.4,2.33]],"id":36182808}],"con":true,"img":false}]}
{"op":"mcm","clk":"5321875288","pt":1646314023668,"mc":[{"id":"1.195532852","rc":[{"atb":[[3.9,2.48]],"id":36532033},{"atb":[[5.5,2.48]],"id":36182808}],"con":true,"img":false}]}
{"op":"mcm","clk":"5321875487","pt":1646314025666,"mc":[{"id":"1.195532852","rc":[{"atb":[[3.8,14.29],[3.75,0]],"id":36532033},{"atl":[[10.5,0]],"id":36532033},{"spn":4.75,"spf":1.0,"id":36532033},{"atb":[[8,0],[7.2,6.45],[7.6,0]],"id":41064273},{"atl":[[9.8,5.7],[9.4,0]],"id":38794071},{"spn":7.45,"spf":1.0,"id":38794071},{"spn":4.13,"spf":7.2,"id":41177799}],"con":true,"img":false}]}
{"op":"mcm","clk":"5321875742","pt":1646314028906,"mc":[{"id":"1.195532852","rc":[{"atb":[[3,0]],"id":36532033},{"atb":[[2.38,0]],"id":41177799}],"con":true,"img":false}]}
{"op":"mcm","clk":"5321875762","pt":1646314029154,"mc":[{"id":"1.195532852","rc":[{"atb":[[2.68,5.24]],"id":36532033}],"con":true,"img":false}]}
{"op":"mcm","clk":"5321876060","pt":1646314033673,"mc":[{"id":"1.195532852","rc":[{"atb":[[2.88,0]],"id":36532033}],"con":true,"img":false}]}
{"op":"mcm","clk":"5321876080","pt":1646314033880,"mc":[{"id":"1.195532852","rc":[{"atb":[[1.01,11002.24]],"id":38386807}],"con":true,"img":false}]}
{"op":"mcm","clk":"5321876091","pt":1646314033984,"mc":[{"id":"1.195532852","rc":[{"atb":[[2.46,4.09]],"id":41177799}],"con":true,"img":false}]}
{"op":"mcm","clk":"5321876110","pt":1646314034191,"mc":[{"id":"1.195532852","rc":[{"atb":[[1.01,11002.1]],"id":38386807}],"con":true,"img":false}]}
{"op":"mcm","clk":"5321876128","pt":1646314034399,"mc":[{"id":"1.195532852","rc":[{"atb":[[1.01,11000]],"id":38386807}],"con":true,"img":false}]}
{"op":"mcm","clk":"5321876136","pt":1646314034502,"mc":[{"id":"1.195532852","rc":[{"atb":[[3.85,2.1]],"id":38386807}],"con":true,"img":false}]}
{"op":"mcm","clk":"5321876229","pt":1646314035707,"mc":[{"id":"1.195532852","rc":[{"atl":[[9,12.5]],"id":36532033},{"atb":[[6.8,17.24]],"id":41064273},{"atl":[[10.5,26.32]],"id":38794071}],"con":true,"img":false}]}
{"op":"mcm","clk":"5321876242","pt":1646314035812,"mc":[{"id":"1.195532852","rc":[{"atl":[[10.5,10.53]],"id":38794071}],"con":true,"img":false}]}
{"op":"mcm","clk":"5321876254","pt":1646314035870,"mc":[{"id":"1.195532852","rc":[{"atb":[[1.87,117.24],[2.16,79.31]],"id":36532033},{"atl":[[18,9.2],[23,15.2]],"id":38794071},{"atl":[[8.6,15.2],[6.8,9.2]],"id":41177799}],"con":true,"img":false}]}
{"op":"mcm","clk":"5321876366","pt":1646314037183,"mc":[{"id":"1.195532852","rc":[{"atb":[[2.96,5.71]],"id":36532033}],"con":true,"img":false}]}
{"op":"mcm","clk":"5321876563","pt":1646314039600,"mc":[{"id":"1.195532852","rc":[{"atb":[[2.76,0]],"id":36532033},{"atb":[[2.76,0]],"id":41064273},{"atb":[[2.9,0]],"id":36182808},{"atb":[[2.48,0]],"id":38794071},{"atb":[[1.46,0]],"id":41177799}],"con":true,"img":false}]}
{"op":"mcm","clk":"5321876586","pt":1646314039911,"mc":[{"id":"1.195532852","rc":[{"atb":[[4.7,3.35]],"id":41064273}],"con":true,"img":false}]}
{"op":"mcm","clk":"5321876604","pt":1646314040068,"mc":[{"id":"1.195532852","rc":[{"atb":[[2.52,6.91]],"id":41177799}],"con":true,"img":false}]}
{"op":"mcm","clk":"5321876862","pt":1646314043496,"mc":[{"id":"1.195532852","rc":[{"atl":[[9.8,0]],"id":38794071},{"trd":[[9.8,11.39]],"ltp":9.8,"tv":11.39,"id":38794071}],"con":true,"img":false}]}
{"op":"mcm","clk":"5321876871","pt":1646314043597,"mc":[{"id":"1.195532852","rc":[{"atb":[[5.2,7.24]],"id":38794071},{"atl":[[10.5,0],[11.5,0],[12,3.37]],"id":38794071}],"con":true,"img":false}]}
{"op":"mcm","clk":"5321877005","pt":1646314045311,"mc":[{"id":"1.195532852","rc":[{"atb":[[5.3,2.48]],"id":38794071}],"con":true,"img":false}]}
{"op":"mcm","clk":"5321877042","pt":1646314045678,"mc":[{"id":"1.195532852","rc":[{"atl":[[9.4,17.86]],"id":36532033}],"con":true,"img":false}]}
{"op":"mcm","clk":"5321877066","pt":1646314045990,"mc":[{"id":"1.195532852","rc":[{"atb":[[5.1,0]],"id":38794071}],"con":true,"img":false}]}
{"op":"mcm","clk":"5321877272","pt":1646314048498,"mc":[{"id":"1.195532852","rc":[{"atb":[[2.56,4.31]],"id":41177799}],"con":true,"img":false}]}
{"op":"mcm","clk":"5321877400","pt":1646314050215,"mc":[{"id":"1.195532852","rc":[{"atb":[[5.2,0]],"id":38794071}],"con":true,"img":false}]}
{"op":"mcm","clk":"5321877454","pt":1646314050997,"mc":[{"id":"1.195532852","rc":[{"atb":[[5.1,2]],"id":38794071}],"con":true,"img":false}]}
{"op":"mcm","clk":"5321877664","pt":1646314053602,"mc":[{"id":"1.195532852","rc":[{"atl":[[12,0],[14.5,2.75]],"id":38794071}],"con":true,"img":false}]}
{"op":"mcm","clk":"5321877818","pt":1646314055688,"mc":[{"id":"1.195532852","rc":[{"atl":[[9.8,37.61]],"id":36532033}],"con":true,"img":false}]}
{"op":"mcm","clk":"5321877913","pt":1646314056892,"mc":[{"id":"1.195532852","rc":[{"atb":[[2.28,79.69],[2.7,54.12]],"id":38794071},{"atl":[[18,0]],"id":38794071}],"con":true,"img":false}]}
{"op":"mcm","clk":"5321878274","pt":1646314061793,"mc":[{"id":"1.195532852","rc":[{"atb":[[2.52,14.17]],"id":41177799}],"con":true,"img":false}]}
{"op":"mcm","clk":"5321878302","pt":1646314062209,"mc":[{"id":"1.195532852","rc":[{"atb":[[2.68,0]],"id":36532033}],"con":true,"img":false}]}
{"op":"mcm","clk":"5321878332","pt":1646314062514,"mc":[{"id":"1.195532852","rc":[{"atb":[[2.46,10.13]],"id":41177799}],"con":true,"img":false}]}
{"op":"mcm","clk":"5321878365","pt":1646314062931,"mc":[{"id":"1.195532852","rc":[{"atb":[[3.85,5.19]],"id":38386807}],"con":true,"img":false}]}
{"op":"mcm","clk":"5321878416","pt":1646314063607,"mc":[{"id":"1.195532852","rc":[{"atl":[[16,2.47],[14.5,0]],"id":38794071}],"con":true,"img":false}]}
{"op":"mcm","clk":"5321878432","pt":1646314063813,"mc":[{"id":"1.195532852","rc":[{"atb":[[2.52,9.25]],"id":41177799}],"con":true,"img":false}]}
{"op":"mcm","clk":"5321878609","pt":1646314066421,"mc":[{"id":"1.195532852","rc":[{"atl":[[13.5,1.01]],"id":38794071}],"con":true,"img":false}]}
{"op":"mcm","clk":"5321878901","pt":1646314069614,"mc":[{"id":"1.195532852","rc":[{"atb":[[2.56,0]],"id":41177799}],"con":true,"img":false}]}
{"op":"mcm","clk":"5321878983","pt":1646314070496,"mc":[{"id":"1.195532852","rc":[{"atb":[[5.4,0.68]],"id":36182808}],"con":true,"img":false}]}
{"op":"mcm","clk":"5321879023","pt":1646314070917,"mc":[{"id":"1.195532852","rc":[{"atb":[[5.6,1.65]],"id":36182808}],"con":true,"img":false}]}
{"op":"mcm","clk":"5321879168","pt":1646314072424,"mc":[{"id":"1.195532852","rc":[{"atb":[[5.5,0]],"id":36182808}],"con":true,"img":false}]}
{"op":"mcm","clk":"5321879306","pt":1646314073733,"mc":[{"id":"1.195532852","rc":[{"atl":[[17,5.8]],"id":38794071}],"con":true,"img":false}]}
{"op":"mcm","clk":"5321880049","pt":1646314082210,"mc":[{"id":"1.195532852","rc":[{"atb":[[5.4,3.79]],"id":38794071}],"con":true,"img":false}]}
{"op":"mcm","clk":"5321880163","pt":1646314083625,"mc":[{"id":"1.195532852","rc":[{"atl":[[18,8.18]],"id":38794071}],"con":true,"img":false}]}
{"op":"mcm","clk":"5321880198","pt":1646314084067,"mc":[{"id":"1.195532852","rc":[{"atb":[[5.3,0]],"id":38794071}],"con":true,"img":false}]}
{"op":"mcm","clk":"5321880295","pt":1646314085440,"mc":[{"id":"1.195532852","rc":[{"atl":[[13.5,0]],"id":38794071},{"trd":[[13.5,2.02]],"ltp":13.5,"tv":2.02,"id":38794071}],"con":true,"img":false}]}
{"op":"mcm","clk":"5321880314","pt":1646314085645,"mc":[{"id":"1.195532852","rc":[{"atb":[[5.4,0]],"id":38794071}],"con":true,"img":false}]}
{"op":"mcm","clk":"5321880367","pt":1646314086218,"mc":[{"id":"1.195532852","rc":[{"spb":[[1000,11]],"id":36182808},{"spn":7.6,"spf":7.6,"id":36182808},{"spn":10.55,"spf":1.0,"id":38794071}],"con":true,"img":false}]}
{"op":"mcm","clk":"5321881035","pt":1646314093736,"mc":[{"id":"1.195532852","rc":[{"atl":[[16,0],[18.5,2.09]],"id":38794071}],"con":true,"img":false}]}
{"op":"mcm","clk":"5321881487","pt":1646314099260,"mc":[{"id":"1.195532852","rc":[{"atl":[[23,0]],"id":38794071}],"con":true,"img":false}]}
{"op":"mcm","clk":"5321881869","pt":1646314103689,"mc":[{"id":"1.195532852","rc":[{"atl":[[19.5,1.97]],"id":38794071}],"con":true,"img":false}]}
{"op":"mcm","clk":"5321881879","pt":1646314103743,"mc":[{"id":"1.195532852","rc":[{"atl":[[17,0]],"id":38794071}],"con":true,"img":false}]}
{"op":"mcm","clk":"5321882080","pt":1646314106390,"mc":[{"id":"1.195532852","rc":[{"atb":[[2.64,4.56]],"id":41177799}],"con":true,"img":false}]}
{"op":"mcm","clk":"5321882192","pt":1646314107942,"mc":[{"id":"1.195532852","rc":[{"atl":[[14,0.78]],"id":38794071}],"con":true,"img":false}]}
{"op":"mcm","clk":"5321882637","pt":1646314113677,"mc":[{"id":"1.195532852","rc":[{"atl":[[16.5,2.36]],"id":38794071}],"con":true,"img":false}]}
{"op":"mcm","clk":"5321882745","pt":1646314114976,"mc":[{"id":"1.195532852","rc":[{"atb":[[2.58,4.26]],"id":41177799}],"con":true,"img":false}]}
{"op":"mcm","clk":"5321883068","pt":1646314120008,"mc":[{"id":"1.195532852","rc":[{"atb":[[5.2,4.93]],"id":38794071}],"con":true,"img":false}]}
{"op":"mcm","clk":"5321883144","pt":1646314120990,"mc":[{"id":"1.195532852","rc":[{"atl":[[8.4,0.82]],"id":36532033},{"atl":[[29,0.82]],"id":41064273},{"atl":[[11.5,0.82]],"id":36182808},{"atl":[[16,0.82]],"id":38794071},{"atl":[[8.2,2.22]],"id":38386807},{"atl":[[4.1,0.82]],"id":41177799}],"con":true,"img":false}]}
{"op":"mcm","clk":"5321883228","pt":1646314122080,"mc":[{"id":"1.195532852","rc":[{"atl":[[29,0.48]],"id":41064273},{"atl":[[8.4,0.48]],"id":36532033},{"atl":[[11.5,0.47]],"id":36182808},{"atl":[[16,0.44]],"id":38794071},{"atl":[[8.2,1.87]],"id":38386807},{"atl":[[4.1,0.48]],"id":41177799}],"con":true,"img":false}]}
{"op":"mcm","clk":"5321884075","pt":1646314133317,"mc":[{"id":"1.195532852","rc":[{"atl":[[14,0.29]],"id":38794071},{"trd":[[14,0.97]],"ltp":14.0,"tv":0.97,"id":38794071}],"con":true,"img":false}]}
{"op":"mcm","clk":"5321884092","pt":1646314133523,"mc":[{"id":"1.195532852","rc":[{"atb":[[5.3,1.89]],"id":38794071}],"con":true,"img":false}]}
{"op":"mcm","clk":"5321884593","pt":1646314139602,"mc":[{"id":"1.195532852","rc":[{"atb":[[1.01,11002.24]],"id":36182808}],"con":true,"img":false}]}
{"op":"mcm","clk":"5321884613","pt":1646314139810,"mc":[{"id":"1.195532852","rc":[{"atb":[[1.01,11000.65],[5.4,0]],"id":36182808}],"con":true,"img":false}]}
{"op":"mcm","clk":"5321884632","pt":1646314140024,"mc":[{"id":"1.195532852","rc":[{"atb":[[1.01,11000]],"id":36182808}],"con":true,"img":false}]}
{"op":"mcm","clk":"5321884641","pt":1646314140130,"mc":[{"id":"1.195532852","rc":[{"atb":[[5.7,0.65]],"id":36182808}],"con":true,"img":false}]}
{"op":"mcm","clk":"5321884690","pt":1646314140743,"mc":[{"id":"1.195532852","rc":[{"atb":[[5.2,0]],"id":38794071}],"con":true,"img":false}]}
{"op":"mcm","clk":"5321886061","pt":1646314156924,"mc":[{"id":"1.195532852","rc":[{"atb":[[5.4,3.79]],"id":38794071},{"spn":9.7,"spf":1.0,"id":38794071},{"spn":4.12,"spf":7.2,"id":41177799}],"con":true,"img":false}]}
{"op":"mcm","clk":"5321886600","pt":1646314163257,"mc":[{"id":"1.195532852","rc":[{"atb":[[2.5,0]],"id":41177799}],"con":true,"img":false}]}
{"op":"mcm","clk":"5321886852","pt":1646314166263,"mc":[{"id":"1.195532852","rc":[{"atb":[[5.1,0]],"id":38386807},{"trd":[[5.1,4.6]],"ltp":5.1,"tv":4.6,"id":38386807}],"con":true,"img":false}]}
{"op":"mcm","clk":"5321887278","pt":1646314171233,"mc":[{"id":"1.195532852","rc":[{"atb":[[4.6,2]],"id":38386807}],"con":true,"img":false}]}
{"op":"mcm","clk":"5321889451","pt":1646314196503,"mc":[{"id":"1.195532852","rc":[{"atb":[[3.65,0]],"id":36182808},{"atb":[[3.35,0]],"id":38794071}],"con":true,"img":false}]}
{"op":"mcm","clk":"5321889633","pt":1646314198903,"mc":[{"id":"1.195532852","rc":[{"atb":[[3.05,0]],"id":38386807}],"con":true,"img":false}]}
{"op":"mcm","clk":"5321890115","pt":1646314204088,"mc":[{"id":"1.195532852","rc":[{"atb":[[3.25,4.98]],"id":38386807}],"con":true,"img":false}]}
{"op":"mcm","clk":"5321891356","pt":1646314218521,"mc":[{"id":"1.195532852","rc":[{"atb":[[3.55,4.86]],"id":38794071},{"spn":6.3,"spf":1.0,"id":38386807},{"atb":[[2.34,9.56]],"id":41177799}],"con":true,"img":false}]}
{"op":"mcm","clk":"5321891387","pt":1646314218844,"mc":[{"id":"1.195532852","rc":[{"atb":[[3.85,4.35]],"id":36182808}],"con":true,"img":false}]}
{"op":"mcm","clk":"5321892374","pt":1646314229757,"mc":[{"id":"1.195532852","rc":[{"atb":[[1.01,11002.24]],"id":38794071}],"con":true,"img":false}]}
{"op":"mcm","clk":"5321892382","pt":1646314229863,"mc":[{"id":"1.195532852","rc":[{"atb":[[1.01,11000.68]],"id":38794071}],"con":true,"img":false}]}
{"op":"mcm","clk":"5321892390","pt":1646314229964,"mc":[{"id":"1.195532852","rc":[{"atb":[[1.01,11000]],"id":38794071}],"con":true,"img":false}]}
{"op":"mcm","clk":"5321892400","pt":1646314230067,"mc":[{"id":"1.195532852","rc":[{"atb":[[5.5,0.68]],"id":38794071}],"con":true,"img":false}]}
{"op":"mcm","clk":"5321892424","pt":1646314230375,"mc":[{"id":"1.195532852","rc":[{"atb":[[5.3,0]],"id":38794071}],"con":true,"img":false}]}
{"op":"mcm","clk":"5321892443","pt":1646314230532,"mc":[{"id":"1.195532852","rc":[{"atb":[[5.6,1.79]],"id":38794071}],"con":true,"img":false}]}
{"op":"mcm","clk":"5321892724","pt":1646314233350,"mc":[{"id":"1.195532852","rc":[{"atb":[[2.7,5.82]],"id":41177799}],"con":true,"img":false}]}
{"op":"mcm","clk":"5321892753","pt":1646314233689,"mc":[{"id":"1.195532852","rc":[{"atb":[[2.36,82.66]],"id":41177799}],"con":true,"img":false}]}
{"op":"mcm","clk":"5321892986","pt":1646314236045,"mc":[{"id":"1.195532852","rc":[{"atb":[[5.4,0],[5.7,3.94]],"id":38794071}],"con":true,"img":false}]}
{"op":"mcm","clk":"5321893463","pt":1646314241649,"mc":[{"id":"1.195532852","rc":[{"atb":[[2.58,0]],"id":41177799}],"con":true,"img":false}]}
{"op":"mcm","clk":"5321894572","pt":1646314254025,"mc":[{"id":"1.195532852","rc":[{"atb":[[4.5,0]],"id":41064273},{"atb":[[2.18,0]],"id":41177799}],"con":true,"img":false}]}
{"op":"mcm","clk":"5321894849","pt":1646314257198,"mc":[{"id":"1.195532852","rc":[{"atb":[[2.36,90.9]],"id":41177799}],"con":true,"img":false}]}
{"op":"mcm","clk":"5321895229","pt":1646314261828,"mc":[{"id":"1.195532852","rc":[{"atb":[[2.76,5.82]],"id":41177799}],"con":true,"img":false}]}
{"op":"mcm","clk":"5321895743","pt":1646314269506,"mc":[{"id":"1.195532852","rc":[{"atb":[[1.64,143.75],[1.47,217.02]],"id":41177799}],"con":true,"img":false}]}
{"op":"mcm","clk":"5321899394","pt":1646314319925,"mc":[{"id":"1.195532852","rc":[{"atb":[[1.01,11002.24]],"id":38794071},{"spn":9.85,"spf":1.0,"id":38794071}],"con":true,"img":false}]}
{"op":"mcm","clk":"5321899409","pt":1646314320078,"mc":[{"id":"1.195532852","rc":[{"atb":[[1.01,11000.64],[5.5,0]],"id":38794071}],"con":true,"img":false}]}
{"op":"mcm","clk":"5321899426","pt":1646314320292,"mc":[{"id":"1.195532852","rc":[{"atb":[[1.01,11000]],"id":38794071}],"con":true,"img":false}]}
{"op":"mcm","clk":"5321899436","pt":1646314320396,"mc":[{"id":"1.195532852","rc":[{"atb":[[5.8,0.64]],"id":38794071}],"con":true,"img":false}]}
{"op":"mcm","clk":"5321899475","pt":1646314320810,"mc":[{"id":"1.195532852","rc":[{"atb":[[5.6,0]],"id":38794071}],"con":true,"img":false}]}
{"op":"mcm","clk":"5321899497","pt":1646314321017,"mc":[{"id":"1.195532852","rc":[{"atb":[[5.9,1.7]],"id":38794071}],"con":true,"img":false}]}
{"op":"mcm","clk":"5321899969","pt":1646314326317,"mc":[{"id":"1.195532852","rc":[{"atb":[[6,3.94],[5.7,0]],"id":38794071}],"con":true,"img":false}]}
{"op":"mcm","clk":"5321899992","pt":1646314326735,"mc":[{"id":"1.195532852","rc":[{"atb":[[5.1,0]],"id":38794071}],"con":true,"img":false}]}
{"op":"mcm","clk":"5321901085","pt":1646314340440,"mc":[{"id":"1.195532852","rc":[{"atl":[[8.4,0],[5.6,0],[8.6,1.28]],"id":36532033},{"trd":[[8.6,7.95],[5.6,6],[8.4,0.97]],"ltp":8.6,"tv":14.92,"id":36532033}],"con":true,"img":false}]}
{"op":"mcm","clk":"5321901089","pt":1646314340543,"mc":[{"id":"1.195532852","rc":[{"atb":[[3.95,4.1]],"id":36532033},{"atl":[[8.6,0],[9,0],[9.2,4.66],[9.8,9.2],[9.4,0]],"id":36532033}],"con":true,"img":false}]}
{"op":"mcm","clk":"5321901100","pt":1646314340757,"mc":[{"id":"1.195532852","rc":[{"atb":[[3.95,0]],"id":36532033}],"con":true,"img":false}]}
{"op":"mcm","clk":"5321901113","pt":1646314340913,"mc":[{"id":"1.195532852","rc":[{"atb":[[3.85,0]],"id":36532033}],"con":true,"img":false}]}
{"op":"mcm","clk":"5321901138","pt":1646314341333,"mc":[{"id":"1.195532852","rc":[{"atb":[[3.8,15.38]],"id":36532033}],"con":true,"img":false}]}
{"op":"mcm","clk":"5321901149","pt":1646314341541,"mc":[{"id":"1.195532852","rc":[{"atl":[[9,1.65]],"id":36532033}],"con":true,"img":false}]}
{"op":"mcm","clk":"5321901840","pt":1646314350536,"mc":[{"id":"1.195532852","rc":[{"atl":[[10,4.25]],"id":36532033}],"con":true,"img":false}]}
{"op":"mcm","clk":"5321901848","pt":1646314350643,"mc":[{"id":"1.195532852","rc":[{"atl":[[9.2,0]],"id":36532033}],"con":true,"img":false}]}
{"op":"mcm","clk":"5321902040","pt":1646314352721,"mc":[{"id":"1.195532852","rc":[{"atb":[[1.01,11002.24]],"id":36532033}],"con":true,"img":false}]}
{"op":"mcm","clk":"5321902051","pt":1646314352824,"mc":[{"id":"1.195532852","rc":[{"atb":[[1.01,11002.06]],"id":36532033}],"con":true,"img":false}]}
{"op":"mcm","clk":"5321902075","pt":1646314353029,"mc":[{"id":"1.195532852","rc":[{"atb":[[1.01,11000]],"id":36532033}],"con":true,"img":false}]}
{"op":"mcm","clk":"5321902087","pt":1646314353133,"mc":[{"id":"1.195532852","rc":[{"atb":[[3.9,4.54]],"id":36532033}],"con":true,"img":false}]}
{"op":"mcm","clk":"5321902110","pt":1646314353445,"mc":[{"id":"1.195532852","rc":[{"atb":[[3.8,14.29]],"id":36532033}],"con":true,"img":false}]}
{"op":"mcm","clk":"5321902123","pt":1646314353548,"mc":[{"id":"1.195532852","rc":[{"atb":[[3.9,5.64]],"id":36532033}],"con":true,"img":false}]}
{"op":"mcm","clk":"5321902197","pt":1646314354429,"mc":[{"id":"1.195532852","rc":[{"atl":[[9.8,0]],"id":36532033}],"con":true,"img":false}]}
{"op":"mcm","clk":"5321902679","pt":1646314360579,"mc":[{"id":"1.195532852","rc":[{"atl":[[11,10.57]],"id":36532033}],"con":true,"img":false}]}
{"op":"mcm","clk":"5321903294","pt":1646314368145,"mc":[{"id":"1.195532852","rc":[{"atb":[[1.01,11002]],"id":38794071}],"con":true,"img":false}]}
{"op":"mcm","clk":"5321903304","pt":1646314368252,"mc":[{"id":"1.195532852","rc":[{"atb":[[1.01,11003.99]],"id":38794071}],"con":true,"img":false}]}
{"op":"mcm","clk":"5321903320","pt":1646314368460,"mc":[{"id":"1.195532852","rc":[{"atb":[[1.01,11002]],"id":38794071}],"con":true,"img":false}]}
{"op":"mcm","clk":"5321903330","pt":1646314368564,"mc":[{"id":"1.195532852","rc":[{"atb":[[6.2,1.99]],"id":38794071}],"con":true,"img":false}]}
{"op":"mcm","clk":"5321903337","pt":1646314368671,"mc":[{"id":"1.195532852","rc":[{"atb":[[1.01,11002]],"id":41177799}],"con":true,"img":false}]}
{"op":"mcm","clk":"5321903347","pt":1646314368772,"mc":[{"id":"1.195532852","rc":[{"atb":[[1.01,11003.99]],"id":41177799}],"con":true,"img":false}]}
{"op":"mcm","clk":"5321903356","pt":1646314368874,"mc":[{"id":"1.195532852","rc":[{"atb":[[5.9,0]],"id":38794071},{"atb":[[1.01,11002]],"id":41177799}],"con":true,"img":false}]}
{"op":"mcm","clk":"5321903365","pt":1646314368980,"mc":[{"id":"1.195532852","rc":[{"atb":[[2.78,1.99]],"id":41177799}],"con":true,"img":false}]}
{"op":"mcm","clk":"5321903376","pt":1646314369082,"mc":[{"id":"1.195532852","rc":[{"atb":[[6.4,1.57]],"id":38794071}],"con":true,"img":false}]}
{"op":"mcm","clk":"5321903510","pt":1646314370589,"mc":[{"id":"1.195532852","rc":[{"atl":[[12,13.03]],"id":36532033}],"con":true,"img":false}]}
{"op":"mcm","clk":"5321903731","pt":1646314373179,"mc":[{"id":"1.195532852","rc":[{"atb":[[3.95,6.1]],"id":36532033}],"con":true,"img":false}]}
{"op":"mcm","clk":"5321903767","pt":1646314373491,"mc":[{"id":"1.195532852","rc":[{"atb":[[3.9,4.54]],"id":36532033}],"con":true,"img":false}]}
{"op":"mcm","clk":"5321903778","pt":1646314373546,"mc":[{"id":"1.195532852","rc":[{"atb":[[3.95,7.19]],"id":36532033}],"con":true,"img":false}]}
{"op":"mcm","clk":"5321903827","pt":1646314374063,"mc":[{"id":"1.195532852","rc":[{"atb":[[1.01,11002]],"id":41064273}],"con":true,"img":false}]}
{"op":"mcm","clk":"5321903842","pt":1646314374170,"mc":[{"id":"1.195532852","rc":[{"atb":[[1.01,11003.99]],"id":41064273}],"con":true,"img":false}]}
{"op":"mcm","clk":"5321903858","pt":1646314374380,"mc":[{"id":"1.195532852","rc":[{"atb":[[1.01,11002]],"id":41064273}],"con":true,"img":false}]}
{"op":"mcm","clk":"5321903872","pt":1646314374482,"mc":[{"id":"1.195532852","rc":[{"atb":[[1.02,1.99]],"id":41064273},{"atb":[[3.9,2.06]],"id":36532033}],"con":true,"img":false}]}
{"op":"mcm","clk":"5321903896","pt":1646314374691,"mc":[{"id":"1.195532852","rc":[{"atb":[[1.01,11002]],"id":36532033}],"con":true,"img":false}]}
{"op":"mcm","clk":"5321903915","pt":1646314374847,"mc":[{"id":"1.195532852","rc":[{"atb":[[1.01,11003.99]],"id":36532033}],"con":true,"img":false}]}
{"op":"mcm","clk":"5321903937","pt":1646314375053,"mc":[{"id":"1.195532852","rc":[{"atb":[[1.01,11002]],"id":36532033}],"con":true,"img":false}]}
{"op":"mcm","clk":"5321903948","pt":1646314375156,"mc":[{"id":"1.195532852","rc":[{"atb":[[3.95,9.18]],"id":36532033}],"con":true,"img":false}]}
{"op":"mcm","clk":"5321904071","pt":1646314376573,"mc":[{"id":"1.195532852","rc":[{"atb":[[6,0],[6.6,3.94]],"id":38794071}],"con":true,"img":false}]}
{"op":"mcm","clk":"5321904407","pt":1646314380265,"mc":[{"id":"1.195532852","rc":[{"spn":6.47,"spf":1.0,"id":36532033},{"atb":[[1.01,11002]],"id":36182808},{"spn":10.3,"spf":1.0,"id":38794071}],"con":true,"img":false}]}
{"op":"mcm","clk":"5321904416","pt":1646314380371,"mc":[{"id":"1.195532852","rc":[{"atb":[[1.01,11003.99]],"id":36182808}],"con":true,"img":false}]}
{"op":"mcm","clk":"5321904435","pt":1646314380578,"mc":[{"id":"1.195532852","rc":[{"atb":[[3.85,14.04],[3.8,0]],"id":36532033},{"atl":[[13,19.91]],"id":36532033},{"atb":[[1.01,11002]],"id":36182808}],"con":true,"img":false}]}
{"op":"mcm","clk":"5321904444","pt":1646314380681,"mc":[{"id":"1.195532852","rc":[{"atb":[[5.7,2.64]],"id":36182808}],"con":true,"img":false}]}
{"op":"mcm","clk":"5321904451","pt":1646314380786,"mc":[{"id":"1.195532852","rc":[{"atb":[[1.01,11002]],"id":38386807}],"con":true,"img":false}]}
{"op":"mcm","clk":"5321904470","pt":1646314380993,"mc":[{"id":"1.195532852","rc":[{"atb":[[1.01,11003.99]],"id":38386807}],"con":true,"img":false}]}
{"op":"mcm","clk":"5321904491","pt":1646314381201,"mc":[{"id":"1.195532852","rc":[{"atb":[[1.01,11002]],"id":38386807}],"con":true,"img":false}]}
{"op":"mcm","clk":"5321904504","pt":1646314381252,"mc":[{"id":"1.195532852","rc":[{"atb":[[1.02,1.99]],"id":38386807}],"con":true,"img":false}]}
{"op":"mcm","clk":"5321904607","pt":1646314382389,"mc":[{"id":"1.195532852","rc":[{"atb":[[6.2,0]],"id":38794071}],"con":true,"img":false}]}
{"op":"mcm","clk":"5321904618","pt":1646314382492,"mc":[{"id":"1.195532852","rc":[{"atb":[[6.8,1.99]],"id":38794071}],"con":true,"img":false}]}
{"op":"mcm","clk":"5321904634","pt":1646314382699,"mc":[{"id":"1.195532852","rc":[{"atb":[[5.7,0.65]],"id":36182808}],"con":true,"img":false}]}
{"op":"mcm","clk":"5321904647","pt":1646314382749,"mc":[{"id":"1.195532852","rc":[{"atb":[[5.4,1.99]],"id":36182808}],"con":true,"img":false}]}
{"op":"mcm","clk":"5321904660","pt":1646314382957,"mc":[{"id":"1.195532852","rc":[{"atb":[[6.4,0]],"id":38794071}],"con":true,"img":false}]}
{"op":"mcm","clk":"5321904770","pt":1646314384406,"mc":[{"id":"1.195532852","rc":[{"atb":[[5.4,0]],"id":36182808}],"con":true,"img":false}]}
{"op":"mcm","clk":"5321904783","pt":1646314384456,"mc":[{"id":"1.195532852","rc":[{"atb":[[5.7,2.64]],"id":36182808}],"con":true,"img":false}]}
{"op":"mcm","clk":"5321904792","pt":1646314384558,"mc":[{"id":"1.195532852","rc":[{"atb":[[7,1.43]],"id":38794071}],"con":true,"img":false}]}
{"op":"mcm","clk":"5321904912","pt":1646314386187,"mc":[{"id":"1.195532852","rc":[{"atb":[[5.7,0.65]],"id":36182808}],"con":true,"img":false}]}
{"op":"mcm","clk":"5321904919","pt":1646314386290,"mc":[{"id":"1.195532852","rc":[{"atb":[[5.4,1.99]],"id":36182808}],"con":true,"img":false}]}
{"op":"mcm","clk":"5321905055","pt":1646314387757,"mc":[{"id":"1.195532852","rc":[{"atb":[[5.4,0]],"id":36182808}],"con":true,"img":false}]}
{"op":"mcm","clk":"5321905063","pt":1646314387856,"mc":[{"id":"1.195532852","rc":[{"atb":[[5.7,2.64]],"id":36182808}],"con":true,"img":false}]}
{"op":"mcm","clk":"5321905136","pt":1646314388791,"mc":[{"id":"1.195532852","rc":[{"atb":[[5.7,0.65]],"id":36182808}],"con":true,"img":false}]}
{"op":"mcm","clk":"5321905146","pt":1646314388893,"mc":[{"id":"1.195532852","rc":[{"atb":[[5.4,1.99]],"id":36182808}],"con":true,"img":false}]}
{"op":"mcm","clk":"5321905234","pt":1646314390190,"mc":[{"id":"1.195532852","rc":[{"atb":[[3.9,0]],"id":36532033}],"con":true,"img":false}]}
{"op":"mcm","clk":"5321905263","pt":1646314390607,"mc":[{"id":"1.195532852","rc":[{"atb":[[3.75,36.36]],"id":36532033}],"con":true,"img":false}]}
{"op":"mcm","clk":"5321905273","pt":1646314390665,"mc":[{"id":"1.195532852","rc":[{"atb":[[5.4,0]],"id":36182808}],"con":true,"img":false}]}
{"op":"mcm","clk":"5321905284","pt":1646314390761,"mc":[{"id":"1.195532852","rc":[{"atb":[[5.7,2.64]],"id":36182808},{"atb":[[6.6,0]],"id":38794071}],"con":true,"img":false}]}
{"op":"mcm","clk":"5321905368","pt":1646314391855,"mc":[{"id":"1.195532852","rc":[{"atb":[[5.1,2]],"id":38794071}],"con":true,"img":false}]}
{"op":"mcm","clk":"5321905383","pt":1646314392062,"mc":[{"id":"1.195532852","rc":[{"atb":[[6.8,0]],"id":38794071}],"con":true,"img":false}]}
{"op":"mcm","clk":"5321905392","pt":1646314392166,"mc":[{"id":"1.195532852","rc":[{"atb":[[4.7,1.99]],"id":38794071}],"con":true,"img":false}]}
{"op":"mcm","clk":"5321905408","pt":1646314392371,"mc":[{"id":"1.195532852","rc":[{"atb":[[5.7,0.65]],"id":36182808}],"con":true,"img":false}]}
{"op":"mcm","clk":"5321905415","pt":1646314392476,"mc":[{"id":"1.195532852","rc":[{"atb":[[5.4,1.99],[5.6,0]],"id":36182808}],"con":true,"img":false}]}
{"op":"mcm","clk":"5321905637","pt":1646314395172,"mc":[{"id":"1.195532852","rc":[{"atb":[[1.01,11004.24]],"id":36532033}],"con":true,"img":false}]}
{"op":"mcm","clk":"5321905648","pt":1646314395276,"mc":[{"id":"1.195532852","rc":[{"atb":[[1.01,11004.02]],"id":36532033}],"con":true,"img":false}]}
{"op":"mcm","clk":"5321905657","pt":1646314395380,"mc":[{"id":"1.195532852","rc":[{"atb":[[1.01,11002]],"id":36532033}],"con":true,"img":false}]}
{"op":"mcm","clk":"5321905670","pt":1646314395483,"mc":[{"id":"1.195532852","rc":[{"atb":[[3.95,11.2]],"id":36532033}],"con":true,"img":false}]}
{"op":"mcm","clk":"5321905865","pt":1646314397864,"mc":[{"id":"1.195532852","rc":[{"atb":[[3.95,14.09]],"id":36532033}],"con":true,"img":false}]}
{"op":"mcm","clk":"5321906009","pt":1646314399171,"mc":[{"id":"1.195532852","rc":[{"atb":[[4.7,0]],"id":38794071}],"con":true,"img":false}]}
{"op":"mcm","clk":"5321906020","pt":1646314399280,"mc":[{"id":"1.195532852","rc":[{"atb":[[5.9,1.99]],"id":38794071}],"con":true,"img":false}]}
{"op":"mcm","clk":"5321906031","pt":1646314399384,"mc":[{"id":"1.195532852","rc":[{"atb":[[5.5,1.65]],"id":36182808}],"con":true,"img":false}]}
{"op":"mcm","clk":"5321906143","pt":1646314400573,"mc":[{"id":"1.195532852","rc":[{"atb":[[3.45,0],[3.65,56.6]],"id":36532033}],"con":true,"img":false}]}
{"op":"mcm","clk":"5321906227","pt":1646314401611,"mc":[{"id":"1.195532852","rc":[{"atb":[[5.9,0]],"id":38794071}],"con":true,"img":false}]}
{"op":"mcm","clk":"5321906234","pt":1646314401664,"mc":[{"id":"1.195532852","rc":[{"atb":[[5.2,1.99]],"id":38794071}],"con":true,"img":false}]}
{"op":"mcm","clk":"5321906250","pt":1646314401873,"mc":[{"id":"1.195532852","rc":[{"atb":[[5.4,0]],"id":36182808}],"con":true,"img":false}]}
{"op":"mcm","clk":"5321906259","pt":1646314401975,"mc":[{"id":"1.195532852","rc":[{"atb":[[5.6,1.99]],"id":36182808}],"con":true,"img":false}]}
{"op":"mcm","clk":"5321906415","pt":1646314403892,"mc":[{"id":"1.195532852","rc":[{"atb":[[5.2,0]],"id":38794071}],"con":true,"img":false}]}
{"op":"mcm","clk":"5321906425","pt":1646314403996,"mc":[{"id":"1.195532852","rc":[{"atb":[[5.9,1.99]],"id":38794071}],"con":true,"img":false}]}
{"op":"mcm","clk":"5321906435","pt":1646314404101,"mc":[{"id":"1.195532852","rc":[{"atb":[[5.6,0]],"id":36182808}],"con":true,"img":false}]}
{"op":"mcm","clk":"5321906446","pt":1646314404205,"mc":[{"id":"1.195532852","rc":[{"atb":[[5.4,1.99]],"id":36182808}],"con":true,"img":false}]}
{"op":"mcm","clk":"5321906530","pt":1646314404979,"mc":[{"id":"1.195532852","rc":[{"atb":[[5.9,0]],"id":38794071}],"con":true,"img":false}]}
{"op":"mcm","clk":"5321906541","pt":1646314405082,"mc":[{"id":"1.195532852","rc":[{"atb":[[5.2,1.99]],"id":38794071}],"con":true,"img":false}]}
{"op":"mcm","clk":"5321906557","pt":1646314405290,"mc":[{"id":"1.195532852","rc":[{"atb":[[5.4,0]],"id":36182808}],"con":true,"img":false}]}
{"op":"mcm","clk":"5321906567","pt":1646314405393,"mc":[{"id":"1.195532852","rc":[{"atb":[[5.6,1.99]],"id":36182808}],"con":true,"img":false}]}
{"op":"mcm","clk":"5321906848","pt":1646314408292,"mc":[{"id":"1.195532852","rc":[{"atb":[[5.2,0]],"id":38794071}],"con":true,"img":false}]}
{"op":"mcm","clk":"5321906852","pt":1646314408396,"mc":[{"id":"1.195532852","rc":[{"atb":[[5.9,1.99],[7.2,3.94]],"id":38794071}],"con":true,"img":false}]}
{"op":"mcm","clk":"5321906873","pt":1646314408706,"mc":[{"id":"1.195532852","rc":[{"atb":[[5.6,0]],"id":36182808}],"con":true,"img":false}]}
{"op":"mcm","clk":"5321906884","pt":1646314408808,"mc":[{"id":"1.195532852","rc":[{"atb":[[5.4,1.99]],"id":36182808}],"con":true,"img":false}]}
{"op":"mcm","clk":"5321907021","pt":1646314410099,"mc":[{"id":"1.195532852","rc":[{"atb":[[1.01,11004.24]],"id":36182808}],"con":true,"img":false}]}
{"op":"mcm","clk":"5321907031","pt":1646314410202,"mc":[{"id":"1.195532852","rc":[{"atb":[[5.7,0]],"id":36182808}],"con":true,"img":false}]}
{"op":"mcm","clk":"5321907041","pt":1646314410306,"mc":[{"id":"1.195532852","rc":[{"atb":[[1.01,11002.65]],"id":36182808}],"con":true,"img":false}]}
{"op":"mcm","clk":"5321907057","pt":1646314410513,"mc":[{"id":"1.195532852","rc":[{"atb":[[1.01,11002]],"id":36182808},{"atl":[[16,0]],"id":38794071}],"con":true,"img":false}]}
{"op":"mcm","clk":"5321907065","pt":1646314410616,"mc":[{"id":"1.195532852","rc":[{"atb":[[3.55,156.86]],"id":36532033},{"atb":[[5.6,0.65]],"id":36182808},{"atl":[[1000,12.44]],"id":38794071}],"con":true,"img":false}]}
{"op":"mcm","clk":"5321907078","pt":1646314410720,"mc":[{"id":"1.195532852","rc":[{"atb":[[3.55,98.04]],"id":36532033}],"con":true,"img":false}]}
{"op":"mcm","clk":"5321907115","pt":1646314411186,"mc":[{"id":"1.195532852","rc":[{"atb":[[5.9,0]],"id":38794071}],"con":true,"img":false}]}
{"op":"mcm","clk":"5321907125","pt":1646314411287,"mc":[{"id":"1.195532852","rc":[{"atb":[[1.02,1.99]],"id":38794071}],"con":true,"img":false}]}
{"op":"mcm","clk":"5321907149","pt":1646314411601,"mc":[{"id":"1.195532852","rc":[{"atb":[[5.4,0]],"id":36182808}],"con":true,"img":false}]}
{"op":"mcm","clk":"5321907157","pt":1646314411704,"mc":[{"id":"1.195532852","rc":[{"atb":[[5.6,2.64]],"id":36182808}],"con":true,"img":false}]}
{"op":"mcm","clk":"5321907174","pt":1646314411912,"mc":[{"id":"1.195532852","rc":[{"atb":[[5.1,0]],"id":38794071}],"con":true,"img":false}]}
{"op":"mcm","clk":"5321907310","pt":1646314413719,"mc":[{"id":"1.195532852","rc":[{"atb":[[2.92,0]],"id":36532033},{"atb":[[3.15,0]],"id":38386807}],"con":true,"img":false}]}
{"op":"mcm","clk":"5321908208","pt":1646314424612,"mc":[{"id":"1.195532852","rc":[{"atb":[[5.6,0.65]],"id":36182808}],"con":true,"img":false}]}
{"op":"mcm","clk":"5321908216","pt":1646314424711,"mc":[{"id":"1.195532852","rc":[{"atb":[[5.4,1.99]],"id":36182808}],"con":true,"img":false}]}
{"op":"mcm","clk":"5321908411","pt":1646314426839,"mc":[{"id":"1.195532852","rc":[{"atb":[[5.4,0]],"id":36182808}],"con":true,"img":false}]}
{"op":"mcm","clk":"5321908421","pt":1646314426934,"mc":[{"id":"1.195532852","rc":[{"atb":[[5.6,2.64]],"id":36182808}],"con":true,"img":false}]}
{"op":"mcm","clk":"5321908609","pt":1646314428861,"mc":[{"id":"1.195532852","rc":[{"atb":[[5.6,0.65]],"id":36182808}],"con":true,"img":false}]}
{"op":"mcm","clk":"5321908618","pt":1646314428958,"mc":[{"id":"1.195532852","rc":[{"atb":[[5.4,1.99]],"id":36182808}],"con":true,"img":false}]}
{"op":"mcm","clk":"5321908821","pt":1646314431349,"mc":[{"id":"1.195532852","rc":[{"atb":[[5.4,0]],"id":36182808}],"con":true,"img":false}]}
{"op":"mcm","clk":"5321908833","pt":1646314431458,"mc":[{"id":"1.195532852","rc":[{"atb":[[5.6,2.64]],"id":36182808}],"con":true,"img":false}]}
{"op":"mcm","clk":"5321908892","pt":1646314432126,"mc":[{"id":"1.195532852","rc":[{"atb":[[3.75,0]],"id":36182808},{"atb":[[3.45,0]],"id":38794071}],"con":true,"img":false}]}
{"op":"mcm","clk":"5321908970","pt":1646314433157,"mc":[{"id":"1.195532852","rc":[{"atb":[[5.6,0.65]],"id":36182808}],"con":true,"img":false}]}
{"op":"mcm","clk":"5321908981","pt":1646314433261,"mc":[{"id":"1.195532852","rc":[{"atb":[[5.4,1.99]],"id":36182808}],"con":true,"img":false}]}
{"op":"mcm","clk":"5321909088","pt":1646314434665,"mc":[{"id":"1.195532852","rc":[{"atb":[[4.4,3.29]],"id":38794071}],"con":true,"img":false}]}
{"op":"mcm","clk":"5321909098","pt":1646314434726,"mc":[{"id":"1.195532852","rc":[{"atb":[[2.8,6.22]],"id":36182808}],"con":true,"img":false}]}
{"op":"mcm","clk":"5321909258","pt":1646314436650,"mc":[{"id":"1.195532852","rc":[{"atb":[[5.4,0]],"id":36182808},{"atb":[[2.16,10.7]],"id":38386807}],"con":true,"img":false}]}
{"op":"mcm","clk":"5321909266","pt":1646314436748,"mc":[{"id":"1.195532852","rc":[{"atb":[[5.6,2.64]],"id":36182808}],"con":true,"img":false}]}
{"op":"mcm","clk":"5321909308","pt":1646314437267,"mc":[{"id":"1.195532852","rc":[{"atb":[[2.7,0]],"id":41177799}],"con":true,"img":false}]}
{"op":"mcm","clk":"5321909382","pt":1646314438150,"mc":[{"id":"1.195532852","rc":[{"atb":[[2.66,7.48]],"id":36532033},{"atb":[[5.6,0.65]],"id":36182808}],"con":true,"img":false}]}
{"op":"mcm","clk":"5321909391","pt":1646314438253,"mc":[{"id":"1.195532852","rc":[{"atb":[[5.4,1.99]],"id":36182808}],"con":true,"img":false}]}
{"op":"mcm","clk":"5321909588","pt":1646314440629,"mc":[{"id":"1.195532852","rc":[{"atb":[[5.4,0]],"id":36182808},{"spn":10.6,"spf":1.0,"id":38794071}],"con":true,"img":false}]}
{"op":"mcm","clk":"5321909597","pt":1646314440738,"mc":[{"id":"1.195532852","rc":[{"atb":[[5.6,2.64]],"id":36182808}],"con":true,"img":false}]}
{"op":"mcm","clk":"5321909769","pt":1646314442656,"mc":[{"id":"1.195532852","rc":[{"atb":[[5.6,0.65]],"id":36182808}],"con":true,"img":false}]}
{"op":"mcm","clk":"5321909781","pt":1646314442764,"mc":[{"id":"1.195532852","rc":[{"atb":[[5.4,1.99]],"id":36182808}],"con":true,"img":false}]}
{"op":"mcm","clk":"5321909969","pt":1646314444939,"mc":[{"id":"1.195532852","rc":[{"atb":[[5.4,0]],"id":36182808}],"con":true,"img":false}]}
{"op":"mcm","clk":"5321909984","pt":1646314445150,"mc":[{"id":"1.195532852","rc":[{"atb":[[5.6,2.64]],"id":36182808}],"con":true,"img":false}]}
{"op":"mcm","clk":"5321910102","pt":1646314446349,"mc":[{"id":"1.195532852","rc":[{"atb":[[2.76,2]],"id":41177799}],"con":true,"img":false}]}
{"op":"mcm","clk":"5321910139","pt":1646314446760,"mc":[{"id":"1.195532852","rc":[{"atb":[[5.6,0.65]],"id":36182808}],"con":true,"img":false}]}
{"op":"mcm","clk":"5321910148","pt":1646314446868,"mc":[{"id":"1.195532852","rc":[{"atb":[[5.4,1.99]],"id":36182808}],"con":true,"img":false}]}
{"op":"mcm","clk":"5321910824","pt":1646314454253,"mc":[{"id":"1.195532852","rc":[{"atb":[[5.4,0]],"id":36182808}],"con":true,"img":false}]}
{"op":"mcm","clk":"5321910831","pt":1646314454353,"mc":[{"id":"1.195532852","rc":[{"atb":[[5.6,2.64]],"id":36182808}],"con":true,"img":false}]}
{"op":"mcm","clk":"5321910971","pt":1646314455967,"mc":[{"id":"1.195532852","rc":[{"atb":[[5.6,0.65]],"id":36182808}],"con":true,"img":false}]}
{"op":"mcm","clk":"5321910978","pt":1646314456071,"mc":[{"id":"1.195532852","rc":[{"atb":[[5.4,1.99]],"id":36182808}],"con":true,"img":false}]}
{"op":"mcm","clk":"5321911128","pt":1646314457685,"mc":[{"id":"1.195532852","rc":[{"atb":[[5.4,0]],"id":36182808}],"con":true,"img":false}]}
{"op":"mcm","clk":"5321911135","pt":1646314457786,"mc":[{"id":"1.195532852","rc":[{"atb":[[5.6,2.64]],"id":36182808}],"con":true,"img":false}]}
{"op":"mcm","clk":"5321911220","pt":1646314458890,"mc":[{"id":"1.195532852","rc":[{"atb":[[5.6,0.65]],"id":36182808}],"con":true,"img":false}]}
{"op":"mcm","clk":"5321911229","pt":1646314458993,"mc":[{"id":"1.195532852","rc":[{"atb":[[5.4,1.99]],"id":36182808}],"con":true,"img":false}]}
{"op":"mcm","clk":"5321911288","pt":1646314459671,"mc":[{"id":"1.195532852","rc":[{"atb":[[5.4,0]],"id":36182808}],"con":true,"img":false}]}
{"op":"mcm","clk":"5321911297","pt":1646314459775,"mc":[{"id":"1.195532852","rc":[{"atb":[[5.6,2.64]],"id":36182808}],"con":true,"img":false}]}
{"op":"mcm","clk":"5321911310","pt":1646314459983,"mc":[{"id":"1.195532852","rc":[{"atb":[[4,1.6]],"id":36532033},{"atb":[[5.4,1.53]],"id":36182808},{"atb":[[3.9,1.75]],"id":38386807}],"con":true,"img":false}]}
{"op":"mcm","clk":"5321911415","pt":1646314461283,"mc":[{"id":"1.195532852","rc":[{"atb":[[5.6,0.65]],"id":36182808}],"con":true,"img":false}]}
{"op":"mcm","clk":"5321911423","pt":1646314461389,"mc":[{"id":"1.195532852","rc":[{"atb":[[3.95,11.2]],"id":36532033},{"atb":[[5.5,3.64]],"id":36182808}],"con":true,"img":false}]}
{"op":"mcm","clk":"5321911463","pt":1646314461961,"mc":[{"id":"1.195532852","rc":[{"atb":[[5.4,0]],"id":36182808}],"con":true,"img":false}]}
{"op":"mcm","clk":"5321911472","pt":1646314462066,"mc":[{"id":"1.195532852","rc":[{"atb":[[5.6,2.19]],"id":36182808}],"con":true,"img":false}]}
{"op":"mcm","clk":"5321911529","pt":1646314462796,"mc":[{"id":"1.195532852","rc":[{"atb":[[5.5,1.65]],"id":36182808}],"con":true,"img":false}]}
{"op":"mcm","clk":"5321911538","pt":1646314462854,"mc":[{"id":"1.195532852","rc":[{"atb":[[5.7,1.99]],"id":36182808}],"con":true,"img":false}]}
{"op":"mcm","clk":"5321911637","pt":1646314463947,"mc":[{"id":"1.195532852","rc":[{"atb":[[5.6,0.65]],"id":36182808}],"con":true,"img":false}]}
{"op":"mcm","clk":"5321911641","pt":1646314464057,"mc":[{"id":"1.195532852","rc":[{"atb":[[5.4,1.53]],"id":36182808}],"con":true,"img":false}]}
{"op":"mcm","clk":"5321911903","pt":1646314466764,"mc":[{"id":"1.195532852","rc":[{"atb":[[3.95,5.1],[4.1,5.42]],"id":36532033}],"con":true,"img":false}]}
{"op":"mcm","clk":"5321912020","pt":1646314468051,"mc":[{"id":"1.195532852","rc":[{"atb":[[4,0]],"id":36532033}],"con":true,"img":false}]}
{"op":"mcm","clk":"5321912027","pt":1646314468158,"mc":[{"id":"1.195532852","rc":[{"atb":[[4.2,1.6]],"id":36532033}],"con":true,"img":false}]}
{"op":"mcm","clk":"5321912040","pt":1646314468260,"mc":[{"id":"1.195532852","rc":[{"atb":[[3.95,3.11]],"id":36532033}],"con":true,"img":false}]}
{"op":"mcm","clk":"5321912044","pt":1646314468362,"mc":[{"id":"1.195532852","rc":[{"atb":[[4.2,3.59]],"id":36532033}],"con":true,"img":false}]}
{"op":"mcm","clk":"5321912179","pt":1646314470181,"mc":[{"id":"1.195532852","rc":[{"atb":[[1.03,2.24]],"id":38794071}],"con":true,"img":false}]}
{"op":"mcm","clk":"5321912196","pt":1646314470385,"mc":[{"id":"1.195532852","rc":[{"atb":[[5.8,0],[1.03,0.5]],"id":38794071}],"con":true,"img":false}]}
{"op":"mcm","clk":"5321912212","pt":1646314470594,"mc":[{"id":"1.195532852","rc":[{"atb":[[1.03,0]],"id":38794071}],"con":true,"img":false}]}
{"op":"mcm","clk":"5321912217","pt":1646314470697,"mc":[{"id":"1.195532852","rc":[{"atb":[[7.4,0.5]],"id":38794071}],"con":true,"img":false}]}
{"op":"mcm","clk":"5321912246","pt":1646314471063,"mc":[{"id":"1.195532852","rc":[{"atb":[[7,0]],"id":38794071}],"con":true,"img":false}]}
{"op":"mcm","clk":"5321912297","pt":1646314471586,"mc":[{"id":"1.195532852","rc":[{"atb":[[3.95,3.05]],"id":36532033}],"con":true,"img":false}]}
{"op":"mcm","clk":"5321912313","pt":1646314471788,"mc":[{"id":"1.195532852","rc":[{"atb":[[7.6,1.32]],"id":38794071}],"con":true,"img":false}]}
{"op":"mcm","clk":"5321912324","pt":1646314471891,"mc":[{"id":"1.195532852","rc":[{"atb":[[7.6,5.4]],"id":38794071}],"con":true,"img":false}]}
{"op":"mcm","clk":"5321912330","pt":1646314471995,"mc":[{"id":"1.195532852","rc":[{"atb":[[7.2,0]],"id":38794071}],"con":true,"img":false}]}
{"op":"mcm","clk":"5321912395","pt":1646314472673,"mc":[{"id":"1.195532852","rc":[{"atb":[[3.95,2.02]],"id":36532033}],"con":true,"img":false}]}
{"op":"mcm","clk":"5321912403","pt":1646314472773,"mc":[{"id":"1.195532852","rc":[{"atb":[[4.1,0],[4.2,4.62]],"id":36532033}],"con":true,"img":false}]}
{"op":"mcm","clk":"5321912432","pt":1646314473084,"mc":[{"id":"1.195532852","rc":[{"atb":[[4.2,3.01]],"id":36532033}],"con":true,"img":false}]}
{"op":"mcm","clk":"5321912442","pt":1646314473185,"mc":[{"id":"1.195532852","rc":[{"atb":[[1.01,11003.6]],"id":36532033}],"con":true,"img":false}]}
{"op":"mcm","clk":"5321912485","pt":1646314473662,"mc":[{"id":"1.195532852","rc":[{"atb":[[4.2,1.99]],"id":36532033}],"con":true,"img":false}]}
{"op":"mcm","clk":"5321912496","pt":1646314473768,"mc":[{"id":"1.195532852","rc":[{"atb":[[3.9,1.02]],"id":36532033}],"con":true,"img":false}]}
{"op":"mcm","clk":"5321912509","pt":1646314473869,"mc":[{"id":"1.195532852","rc":[{"atb":[[4.2,0]],"id":36532033}],"con":true,"img":false}]}
{"op":"mcm","clk":"5321912521","pt":1646314473974,"mc":[{"id":"1.195532852","rc":[{"atb":[[4,1.99]],"id":36532033}],"con":true,"img":false}]}
{"op":"mcm","clk":"5321912530","pt":1646314474076,"mc":[{"id":"1.195532852","rc":[{"atb":[[1.01,11002]],"id":36532033}],"con":true,"img":false}]}
{"op":"mcm","clk":"5321912539","pt":1646314474178,"mc":[{"id":"1.195532852","rc":[{"atb":[[3.9,2.63]],"id":36532033}],"con":true,"img":false}]}
{"op":"mcm","clk":"5321915001","pt":1646314496823,"mc":[{"id":"1.195532852","rc":[{"atb":[[4.1,2.33]],"id":36532033}],"con":true,"img":false}]}
{"op":"mcm","clk":"5321916284","pt":1646314508528,"mc":[{"id":"1.195532852","rc":[{"atb":[[4,0]],"id":36532033},{"spn":6.55,"spf":1.0,"id":36532033},{"spn":10.8,"spf":1.0,"id":38794071}],"con":true,"img":false}]}
{"op":"mcm","clk":"5321916292","pt":1646314508632,"mc":[{"id":"1.195532852","rc":[{"atb":[[4.2,1.99]],"id":36532033}],"con":true,"img":false}]}
{"op":"mcm","clk":"5321917012","pt":1646314514762,"mc":[{"id":"1.195532852","rc":[{"atb":[[3.95,8.5]],"id":36532033},{"atb":[[7.4,11.66]],"id":41064273},{"atb":[[4.5,26.71]],"id":38794071},{"atb":[[2.66,8.98]],"id":41177799}],"con":true,"img":false}]}
{"op":"mcm","clk":"5321917028","pt":1646314514925,"mc":[{"id":"1.195532852","rc":[{"atb":[[4.1,0]],"id":36532033}],"con":true,"img":false}]}
{"op":"mcm","clk":"5321917037","pt":1646314515026,"mc":[{"id":"1.195532852","rc":[{"atb":[[3.9,1.02]],"id":36532033},{"atb":[[2.68,1.61]],"id":41177799}],"con":true,"img":false}]}
{"op":"mcm","clk":"5321917050","pt":1646314515132,"mc":[{"id":"1.195532852","rc":[{"atb":[[4,1.6]],"id":36532033}],"con":true,"img":false}]}
{"op":"mcm","clk":"5321917088","pt":1646314515542,"mc":[{"id":"1.195532852","rc":[{"atb":[[4.2,0]],"id":36532033}],"con":true,"img":false}]}
{"op":"mcm","clk":"5321917097","pt":1646314515646,"mc":[{"id":"1.195532852","rc":[{"atb":[[4.1,1.99]],"id":36532033}],"con":true,"img":false}]}
{"op":"mcm","clk":"5321917122","pt":1646314515854,"mc":[{"id":"1.195532852","rc":[{"atb":[[3.9,0]],"id":36532033}],"con":true,"img":false}]}
{"op":"mcm","clk":"5321917134","pt":1646314515956,"mc":[{"id":"1.195532852","rc":[{"atb":[[4,2.63]],"id":36532033}],"con":true,"img":false}]}
{"op":"mcm","clk":"5321917414","pt":1646314518557,"mc":[{"id":"1.195532852","rc":[{"atb":[[2.64,0]],"id":41177799}],"con":true,"img":false}]}
{"op":"mcm","clk":"5321917738","pt":1646314521626,"mc":[{"id":"1.195532852","rc":[{"atb":[[5.5,0]],"id":36182808}],"con":true,"img":false}]}
{"op":"mcm","clk":"5321917769","pt":1646314521939,"mc":[{"id":"1.195532852","rc":[{"atb":[[2.66,0]],"id":41177799}],"con":true,"img":false}]}
{"op":"mcm","clk":"5321918199","pt":1646314525441,"mc":[{"id":"1.195532852","rc":[{"atb":[[2.54,14.96]],"id":41177799}],"con":true,"img":false}]}
{"op":"mcm","clk":"5321918296","pt":1646314526368,"mc":[{"id":"1.195532852","rc":[{"atb":[[4.2,5.57]],"id":36532033}],"con":true,"img":false}]}
{"op":"mcm","clk":"5321918358","pt":1646314526843,"mc":[{"id":"1.195532852","rc":[{"atb":[[4,1.6]],"id":36532033}],"con":true,"img":false}]}
{"op":"mcm","clk":"5321918370","pt":1646314526945,"mc":[{"id":"1.195532852","rc":[{"atb":[[4.2,6.59]],"id":36532033}],"con":true,"img":false}]}
{"op":"mcm","clk":"5321918404","pt":1646314527257,"mc":[{"id":"1.195532852","rc":[{"atb":[[4.1,0]],"id":36532033}],"con":true,"img":false}]}
{"op":"mcm","clk":"5321918416","pt":1646314527359,"mc":[{"id":"1.195532852","rc":[{"atb":[[4.3,1.99]],"id":36532033}],"con":true,"img":false}]}
{"op":"mcm","clk":"5321918613","pt":1646314529178,"mc":[{"id":"1.195532852","rc":[{"atb":[[3.95,2.02]],"id":36532033},{"atb":[[2.68,0]],"id":41177799}],"con":true,"img":false}]}
{"op":"mcm","clk":"5321918629","pt":1646314529283,"mc":[{"id":"1.195532852","rc":[{"atb":[[2.54,16.58]],"id":41177799}],"con":true,"img":false}]}
{"op":"mcm","clk":"5321918730","pt":1646314530172,"mc":[{"id":"1.195532852","rc":[{"atb":[[4,0]],"id":36532033}],"con":true,"img":false}]}
{"op":"mcm","clk":"5321918741","pt":1646314530276,"mc":[{"id":"1.195532852","rc":[{"atb":[[4.3,3.59]],"id":36532033}],"con":true,"img":false}]}
{"op":"mcm","clk":"5321918757","pt":1646314530380,"mc":[{"id":"1.195532852","rc":[{"atb":[[1.01,11004.24]],"id":36182808}],"con":true,"img":false}]}
{"op":"mcm","clk":"5321918767","pt":1646314530484,"mc":[{"id":"1.195532852","rc":[{"atb":[[5.6,0]],"id":36182808}],"con":true,"img":false}]}
{"op":"mcm","clk":"5321918781","pt":1646314530591,"mc":[{"id":"1.195532852","rc":[{"atb":[[1.01,11002.64]],"id":36182808}],"con":true,"img":false}]}
{"op":"mcm","clk":"5321918793","pt":1646314530651,"mc":[{"id":"1.195532852","rc":[{"atb":[[1.01,11002]],"id":36182808}],"con":true,"img":false}]}
{"op":"mcm","clk":"5321918804","pt":1646314530756,"mc":[{"id":"1.195532852","rc":[{"atb":[[5.8,0.64]],"id":36182808}],"con":true,"img":false}]}
{"op":"mcm","clk":"5321918814","pt":1646314530857,"mc":[{"id":"1.195532852","rc":[{"atb":[[4.2,6.54]],"id":36532033}],"con":true,"img":false}]}
{"op":"mcm","clk":"5321918897","pt":1646314531637,"mc":[{"id":"1.195532852","rc":[{"atb":[[5.7,0]],"id":36182808}],"con":true,"img":false}]}
{"op":"mcm","clk":"5321918910","pt":1646314531741,"mc":[{"id":"1.195532852","rc":[{"atb":[[5.4,3.52]],"id":36182808}],"con":true,"img":false}]}
{"op":"mcm","clk":"5321918922","pt":1646314531844,"mc":[{"id":"1.195532852","rc":[{"atb":[[4.2,5.57]],"id":36532033}],"con":true,"img":false}]}
{"op":"mcm","clk":"5321918932","pt":1646314531948,"mc":[{"id":"1.195532852","rc":[{"atb":[[4.3,4.57],[4.2,0]],"id":36532033}],"con":true,"img":false}]}
{"op":"mcm","clk":"5321919064","pt":1646314533151,"mc":[{"id":"1.195532852","rc":[{"atb":[[4.3,2.96]],"id":36532033}],"con":true,"img":false}]}
{"op":"mcm","clk":"5321919072","pt":1646314533256,"mc":[{"id":"1.195532852","rc":[{"atb":[[1.01,11003.6]],"id":36532033}],"con":true,"img":false}]}
{"op":"mcm","clk":"5321919113","pt":1646314533667,"mc":[{"id":"1.195532852","rc":[{"atb":[[4.3,0.97]],"id":36532033}],"con":true,"img":false}]}
{"op":"mcm","clk":"5321919124","pt":1646314533771,"mc":[{"id":"1.195532852","rc":[{"atb":[[4,1.99]],"id":36532033},{"atb":[[2.52,2]],"id":41177799}],"con":true,"img":false}]}
{"op":"mcm","clk":"5321919150","pt":1646314534085,"mc":[{"id":"1.195532852","rc":[{"atb":[[5.5,1.65]],"id":36182808}],"con":true,"img":false}]}
{"op":"mcm","clk":"5321919160","pt":1646314534191,"mc":[{"id":"1.195532852","rc":[{"atb":[[3.9,10.29]],"id":36532033}],"con":true,"img":false}]}
{"op":"mcm","clk":"5321919320","pt":1646314536069,"mc":[{"id":"1.195532852","rc":[{"atb":[[5.4,1.53]],"id":36182808}],"con":true,"img":false}]}
{"op":"mcm","clk":"5321919331","pt":1646314536175,"mc":[{"id":"1.195532852","rc":[{"atb":[[5.6,1.99]],"id":36182808}],"con":true,"img":false}]}
{"op":"mcm","clk":"5321919498","pt":1646314537951,"mc":[{"id":"1.195532852","rc":[{"atb":[[5.6,0]],"id":36182808}],"con":true,"img":false}]}
{"op":"mcm","clk":"5321919510","pt":1646314538057,"mc":[{"id":"1.195532852","rc":[{"atb":[[5.5,3.64]],"id":36182808}],"con":true,"img":false}]}
{"op":"mcm","clk":"5321919629","pt":1646314539150,"mc":[{"id":"1.195532852","rc":[{"atb":[[5.4,0]],"id":36182808}],"con":true,"img":false}]}
{"op":"mcm","clk":"5321919639","pt":1646314539257,"mc":[{"id":"1.195532852","rc":[{"atb":[[5.6,1.53]],"id":36182808}],"con":true,"img":false}]}
{"op":"mcm","clk":"5321919711","pt":1646314539980,"mc":[{"id":"1.195532852","rc":[{"atb":[[5.5,1.65]],"id":36182808}],"con":true,"img":false}]}
{"op":"mcm","clk":"5321919718","pt":1646314540087,"mc":[{"id":"1.195532852","rc":[{"atb":[[5.7,1.99]],"id":36182808}],"con":true,"img":false}]}
{"op":"mcm","clk":"5321919819","pt":1646314541177,"mc":[{"id":"1.195532852","rc":[{"atb":[[5.6,0]],"id":36182808}],"con":true,"img":false}]}
{"op":"mcm","clk":"5321919829","pt":1646314541283,"mc":[{"id":"1.195532852","rc":[{"atb":[[1.01,11003.53]],"id":36182808}],"con":true,"img":false}]}
{"op":"mcm","clk":"5321919881","pt":1646314541758,"mc":[{"id":"1.195532852","rc":[{"atb":[[5.7,0]],"id":36182808}],"con":true,"img":false}]}
{"op":"mcm","clk":"5321919890","pt":1646314541860,"mc":[{"id":"1.195532852","rc":[{"atb":[[5.4,1.99]],"id":36182808}],"con":true,"img":false}]}
{"op":"mcm","clk":"5321919905","pt":1646314541965,"mc":[{"id":"1.195532852","rc":[{"atb":[[2.54,1.61]],"id":41177799}],"con":true,"img":false}]}
{"op":"mcm","clk":"5321919928","pt":1646314542175,"mc":[{"id":"1.195532852","rc":[{"atb":[[1.01,11002]],"id":36182808}],"con":true,"img":false}]}
{"op":"mcm","clk":"5321919940","pt":1646314542278,"mc":[{"id":"1.195532852","rc":[{"atb":[[5.4,3.52]],"id":36182808}],"con":true,"img":false}]}
{"op":"mcm","clk":"5321920008","pt":1646314542963,"mc":[{"id":"1.195532852","rc":[{"atb":[[5.4,1.53]],"id":36182808}],"con":true,"img":false}]}
{"op":"mcm","clk":"5321920016","pt":1646314543068,"mc":[{"id":"1.195532852","rc":[{"atb":[[5.6,1.99]],"id":36182808}],"con":true,"img":false}]}
{"op":"mcm","clk":"5321920025","pt":1646314543175,"mc":[{"id":"1.195532852","rc":[{"atb":[[2.54,0]],"id":41177799}],"con":true,"img":false}]}
{"op":"mcm","clk":"5321920032","pt":1646314543273,"mc":[{"id":"1.195532852","rc":[{"atb":[[2.48,1.61]],"id":41177799}],"con":true,"img":false}]}
{"op":"mcm","clk":"5321920044","pt":1646314543375,"mc":[{"id":"1.195532852","rc":[{"atb":[[2.52,6.32]],"id":41177799}],"con":true,"img":false}]}
{"op":"mcm","clk":"5321920119","pt":1646314544171,"mc":[{"id":"1.195532852","rc":[{"atb":[[1.01,11002]],"id":36532033},{"atb":[[2.48,0]],"id":41177799}],"con":true,"img":false}]}
{"op":"mcm","clk":"5321920128","pt":1646314544271,"mc":[{"id":"1.195532852","rc":[{"atb":[[4,3.59]],"id":36532033},{"atb":[[2.54,1.61]],"id":41177799}],"con":true,"img":false}]}
{"op":"mcm","clk":"5321920148","pt":1646314544477,"mc":[{"id":"1.195532852","rc":[{"atb":[[2.52,5.51]],"id":41177799}],"con":true,"img":false}]}
{"op":"mcm","clk":"5321920158","pt":1646314544580,"mc":[{"id":"1.195532852","rc":[{"atb":[[5.6,0]],"id":36182808}],"con":true,"img":false}]}
{"op":"mcm","clk":"5321920168","pt":1646314544679,"mc":[{"id":"1.195532852","rc":[{"atb":[[5.5,3.64]],"id":36182808}],"con":true,"img":false}]}
{"op":"mcm","clk":"5321920211","pt":1646314545149,"mc":[{"id":"1.195532852","rc":[{"atb":[[5.4,0]],"id":36182808}],"con":true,"img":false}]}
{"op":"mcm","clk":"5321920222","pt":1646314545255,"mc":[{"id":"1.195532852","rc":[{"atb":[[5.6,1.53]],"id":36182808}],"con":true,"img":false}]}
{"op":"mcm","clk":"5321920312","pt":1646314546089,"mc":[{"id":"1.195532852","rc":[{"atb":[[2.54,16.58]],"id":41177799}],"con":true,"img":false}]}
{"op":"mcm","clk":"5321920416","pt":1646314547186,"mc":[{"id":"1.195532852","rc":[{"atb":[[2.52,2]],"id":41177799}],"con":true,"img":false}]}
{"op":"mcm","clk":"5321920768","pt":1646314550991,"mc":[{"id":"1.195532852","rc":[{"atb":[[5.5,1.65]],"id":36182808}],"con":true,"img":false}]}
{"op":"mcm","clk":"5321920778","pt":1646314551097,"mc":[{"id":"1.195532852","rc":[{"atb":[[5.7,1.99]],"id":36182808}],"con":true,"img":false}]}
{"op":"mcm","clk":"5321920890","pt":1646314552457,"mc":[{"id":"1.195532852","rc":[{"atb":[[5.6,0]],"id":36182808}],"con":true,"img":false}]}
{"op":"mcm","clk":"5321920900","pt":1646314552473,"mc":[{"id":"1.195532852","rc":[{"atb":[[1.01,11003.53]],"id":36182808}],"con":true,"img":false}]}
{"op":"mcm","clk":"5321921014","pt":1646314553408,"mc":[{"id":"1.195532852","rc":[{"atb":[[5.7,0]],"id":36182808}],"con":true,"img":false}]}
{"op":"mcm","clk":"5321921023","pt":1646314553506,"mc":[{"id":"1.195532852","rc":[{"atb":[[5.4,1.99]],"id":36182808}],"con":true,"img":false}]}
{"op":"mcm","clk":"5321921188","pt":1646314555193,"mc":[{"id":"1.195532852","rc":[{"atb":[[4.1,6.55]],"id":36532033}],"con":true,"img":false}]}
{"op":"mcm","clk":"5321921280","pt":1646314556226,"mc":[{"id":"1.195532852","rc":[{"atb":[[4,1.99]],"id":36532033}],"con":true,"img":false}]}
{"op":"mcm","clk":"5321921290","pt":1646314556329,"mc":[{"id":"1.195532852","rc":[{"atb":[[4.2,1.6]],"id":36532033}],"con":true,"img":false}]}
{"op":"mcm","clk":"5321921483","pt":1646314558105,"mc":[{"id":"1.195532852","rc":[{"atb":[[3.9,0]],"id":36532033}],"con":true,"img":false}]}
{"op":"mcm","clk":"5321921733","pt":1646314560447,"mc":[{"id":"1.195532852","rc":[{"atb":[[5.8,0]],"id":36182808}],"con":true,"img":false}]}
{"op":"mcm","clk":"5321921764","pt":1646314560611,"mc":[{"id":"1.195532852","rc":[{"atb":[[1.01,11005.78]],"id":36182808}],"con":true,"img":false}]}
{"op":"mcm","clk":"5321921791","pt":1646314560821,"mc":[{"id":"1.195532852","rc":[{"atb":[[7.4,0]],"id":38794071}],"con":true,"img":false}]}
{"op":"mcm","clk":"5321921801","pt":1646314560922,"mc":[{"id":"1.195532852","rc":[{"atb":[[4.1,0]],"id":36532033},{"atb":[[1.03,2.24]],"id":38794071}],"con":true,"img":false}]}
{"op":"mcm","clk":"5321921813","pt":1646314561028,"mc":[{"id":"1.195532852","rc":[{"atb":[[1.01,11004.18]],"id":36182808},{"atb":[[1.03,0.47]],"id":38794071}],"con":true,"img":false}]}
{"op":"mcm","clk":"5321921833","pt":1646314561237,"mc":[{"id":"1.195532852","rc":[{"atb":[[1.03,0]],"id":38794071}],"con":true,"img":false}]}
{"op":"mcm","clk":"5321921843","pt":1646314561295,"mc":[{"id":"1.195532852","rc":[{"atb":[[7.8,0.47]],"id":38794071}],"con":true,"img":false}]}
{"op":"mcm","clk":"5321921856","pt":1646314561400,"mc":[{"id":"1.195532852","rc":[{"atb":[[4.2,0]],"id":36532033}],"con":true,"img":false}]}
{"op":"mcm","clk":"5321921867","pt":1646314561508,"mc":[{"id":"1.195532852","rc":[{"atb":[[3.9,1.6]],"id":36532033},{"atb":[[1.01,11003.53]],"id":36182808}],"con":true,"img":false}]}
{"op":"mcm","clk":"5321921881","pt":1646314561608,"mc":[{"id":"1.195532852","rc":[{"atb":[[5.6,0.64]],"id":36182808}],"con":true,"img":false}]}
{"op":"mcm","clk":"5321921973","pt":1646314562504,"mc":[{"id":"1.195532852","rc":[{"atb":[[4.2,6.84]],"id":36532033}],"con":true,"img":false}]}
{"op":"mcm","clk":"5321924212","pt":1646314583541,"mc":[{"id":"1.195532852","rc":[{"atb":[[4.3,5.41]],"id":36532033},{"spn":6.65,"spf":1.0,"id":36532033},{"spn":10.9,"spf":1.0,"id":38794071}],"con":true,"img":false}]}
{"op":"mcm","clk":"5321924383","pt":1646314585423,"mc":[{"id":"1.195532852","rc":[{"atb":[[4,0]],"id":36532033}],"con":true,"img":false}]}
{"op":"mcm","clk":"5321924392","pt":1646314585532,"mc":[{"id":"1.195532852","rc":[{"atb":[[4.3,7.4]],"id":36532033}],"con":true,"img":false}]}
{"op":"mcm","clk":"5321924448","pt":1646314586051,"mc":[{"id":"1.195532852","rc":[{"atb":[[4.2,0]],"id":36532033}],"con":true,"img":false}]}
{"op":"mcm","clk":"5321924468","pt":1646314586255,"mc":[{"id":"1.195532852","rc":[{"atb":[[4.1,3.43]],"id":36532033}],"con":true,"img":false}]}
{"op":"mcm","clk":"5321924489","pt":1646314586420,"mc":[{"id":"1.195532852","rc":[{"atb":[[4.1,0]],"id":36532033}],"con":true,"img":false}]}
{"op":"mcm","clk":"5321924843","pt":1646314590032,"mc":[{"id":"1.195532852","rc":[{"atb":[[3.95,16.84]],"id":36532033}],"con":true,"img":false}]}
{"op":"mcm","clk":"5321924905","pt":1646314590750,"mc":[{"id":"1.195532852","rc":[{"atb":[[5.4,0]],"id":36182808}],"con":true,"img":false}]}
{"op":"mcm","clk":"5321924913","pt":1646314590851,"mc":[{"id":"1.195532852","rc":[{"atb":[[5.6,2.63]],"id":36182808}],"con":true,"img":false}]}
{"op":"mcm","clk":"5321924930","pt":1646314591055,"mc":[{"id":"1.195532852","rc":[{"atb":[[1.01,11005.78]],"id":36182808}],"con":true,"img":false}]}
{"op":"mcm","clk":"5321924947","pt":1646314591260,"mc":[{"id":"1.195532852","rc":[{"atb":[[5.6,1.99]],"id":36182808}],"con":true,"img":false}]}
{"op":"mcm","clk":"5321925029","pt":1646314591939,"mc":[{"id":"1.195532852","rc":[{"atb":[[1.01,11004.18]],"id":36182808}],"con":true,"img":false}]}
{"op":"mcm","clk":"5321925040","pt":1646314592052,"mc":[{"id":"1.195532852","rc":[{"atb":[[1.01,11003.53]],"id":36182808}],"con":true,"img":false}]}
{"op":"mcm","clk":"5321925054","pt":1646314592152,"mc":[{"id":"1.195532852","rc":[{"atb":[[5.4,0.64]],"id":36182808}],"con":true,"img":false}]}
{"op":"mcm","clk":"5321926060","pt":1646314602253,"mc":[{"id":"1.195532852","rc":[{"atb":[[2.36,82.66]],"id":41177799}],"con":true,"img":false}]}
{"op":"mcm","clk":"5321926128","pt":1646314603074,"mc":[{"id":"1.195532852","rc":[{"atb":[[3.9,0]],"id":36532033}],"con":true,"img":false}]}
{"op":"mcm","clk":"5321926141","pt":1646314603176,"mc":[{"id":"1.195532852","rc":[{"atb":[[4.4,1.6]],"id":36532033}],"con":true,"img":false}]}
{"op":"mcm","clk":"5321926485","pt":1646314606376,"mc":[{"id":"1.195532852","rc":[{"atb":[[2.38,8.12]],"id":41177799}],"con":true,"img":false}]}
{"op":"mcm","clk":"5321927098","pt":1646314611278,"mc":[{"id":"1.195532852","rc":[{"atb":[[4.3,2.96],[4.5,6.24]],"id":36532033}],"con":true,"img":false}]}
{"op":"mcm","clk":"5321927140","pt":1646314611653,"mc":[{"id":"1.195532852","rc":[{"atb":[[4.3,1.98]],"id":36532033}],"con":true,"img":false}]}
{"op":"mcm","clk":"5321927151","pt":1646314611753,"mc":[{"id":"1.195532852","rc":[{"atb":[[4.5,7.21]],"id":36532033}],"con":true,"img":false}]}
{"op":"mcm","clk":"5321927217","pt":1646314612373,"mc":[{"id":"1.195532852","rc":[{"atb":[[4.4,0]],"id":36532033},{"atb":[[1.01,11002]],"id":36182808}],"con":true,"img":false}]}
{"op":"mcm","clk":"5321927229","pt":1646314612487,"mc":[{"id":"1.195532852","rc":[{"atb":[[4.6,1.6]],"id":36532033},{"atb":[[5.4,2.18]],"id":36182808}],"con":true,"img":false}]}
{"op":"mcm","clk":"5321927239","pt":1646314612583,"mc":[{"id":"1.195532852","rc":[{"atb":[[4.3,0]],"id":36532033}],"con":true,"img":false}]}
{"op":"mcm","clk":"5321927252","pt":1646314612694,"mc":[{"id":"1.195532852","rc":[{"atb":[[4.6,3.59]],"id":36532033}],"con":true,"img":false}]}
{"op":"mcm","clk":"5321927346","pt":1646314613581,"mc":[{"id":"1.195532852","rc":[{"atb":[[4.5,7.15]],"id":36532033}],"con":true,"img":false}]}
{"op":"mcm","clk":"5321927431","pt":1646314614362,"mc":[{"id":"1.195532852","rc":[{"atb":[[3.95,2.02]],"id":36532033}],"con":true,"img":false}]}
{"op":"mcm","clk":"5321927450","pt":1646314614616,"mc":[{"id":"1.195532852","rc":[{"atb":[[4.5,6.24]],"id":36532033}],"con":true,"img":false}]}
{"op":"mcm","clk":"5321927466","pt":1646314614724,"mc":[{"id":"1.195532852","rc":[{"atb":[[4.6,4.51]],"id":36532033}],"con":true,"img":false}]}
{"op":"mcm","clk":"5321928125","pt":1646314620825,"mc":[{"id":"1.195532852","rc":[{"atb":[[4.5,0]],"id":36532033}],"con":true,"img":false}]}
{"op":"mcm","clk":"5321928218","pt":1646314621714,"mc":[{"id":"1.195532852","rc":[{"atb":[[4.6,2.9]],"id":36532033}],"con":true,"img":false}]}
{"op":"mcm","clk":"5321928228","pt":1646314621820,"mc":[{"id":"1.195532852","rc":[{"atb":[[1.01,11003.6]],"id":36532033}],"con":true,"img":false}]}
{"op":"mcm","clk":"5321928306","pt":1646314622601,"mc":[{"id":"1.195532852","rc":[{"atb":[[4.6,1.99]],"id":36532033}],"con":true,"img":false}]}
{"op":"mcm","clk":"5321928318","pt":1646314622705,"mc":[{"id":"1.195532852","rc":[{"atb":[[3.9,0.91]],"id":36532033}],"con":true,"img":false}]}
{"op":"mcm","clk":"5321928483","pt":1646314624209,"mc":[{"id":"1.195532852","rc":[{"atb":[[4,3.7]],"id":36532033}],"con":true,"img":false}]}
{"op":"mcm","clk":"5321928533","pt":1646314624625,"mc":[{"id":"1.195532852","rc":[{"atb":[[3.9,0]],"id":36532033}],"con":true,"img":false}]}
{"op":"mcm","clk":"5321928545","pt":1646314624682,"mc":[{"id":"1.195532852","rc":[{"atb":[[4,4.61]],"id":36532033}],"con":true,"img":false}]}
{"op":"mcm","clk":"5321928897","pt":1646314627919,"mc":[{"id":"1.195532852","rc":[{"atb":[[1.01,11004.52]],"id":38794071}],"con":true,"img":false}]}
{"op":"mcm","clk":"5321928911","pt":1646314628023,"mc":[{"id":"1.195532852","rc":[{"atl":[[1000,14.52]],"id":36182808}],"con":true,"img":false}]}
{"op":"mcm","clk":"5321928918","pt":1646314628126,"mc":[{"id":"1.195532852","rc":[{"atl":[[1000,13.68]],"id":36182808},{"atb":[[1.01,11003.68]],"id":38794071}],"con":true,"img":false}]}
{"op":"mcm","clk":"5321928944","pt":1646314628334,"mc":[{"id":"1.195532852","rc":[{"atl":[[1000,12]],"id":36182808},{"atb":[[1.01,11002]],"id":38794071}],"con":true,"img":false}]}
{"op":"mcm","clk":"5321928953","pt":1646314628435,"mc":[{"id":"1.195532852","rc":[{"atl":[[11.5,2.15]],"id":36182808},{"atb":[[7.8,2.16]],"id":38794071}],"con":true,"img":false}]}
{"op":"mcm","clk":"5321929041","pt":1646314629316,"mc":[{"id":"1.195532852","rc":[{"atl":[[11.5,0.47]],"id":36182808},{"atb":[[7.8,0.47]],"id":38794071}],"con":true,"img":false}]}
{"op":"mcm","clk":"5321929458","pt":1646314633105,"mc":[{"id":"1.195532852","rc":[{"atb":[[4.6,0]],"id":36532033}],"con":true,"img":false}]}
{"op":"mcm","clk":"5321929468","pt":1646314633209,"mc":[{"id":"1.195532852","rc":[{"atb":[[4.1,1.99]],"id":36532033}],"con":true,"img":false}]}
{"op":"mcm","clk":"5321929632","pt":1646314634994,"mc":[{"id":"1.195532852","rc":[{"atl":[[1000,14.52]],"id":36182808},{"atb":[[1.01,11004.52]],"id":38794071}],"con":true,"img":false}]}
{"op":"mcm","clk":"5321929644","pt":1646314635097,"mc":[{"id":"1.195532852","rc":[{"atl":[[1000,13.68]],"id":36182808},{"atb":[[1.01,11003.68]],"id":38794071}],"con":true,"img":false}]}
{"op":"mcm","clk":"5321929652","pt":1646314635197,"mc":[{"id":"1.195532852","rc":[{"atb":[[1.01,11002]],"id":38794071}],"con":true,"img":false}]}
{"op":"mcm","clk":"5321929666","pt":1646314635302,"mc":[{"id":"1.195532852","rc":[{"atl":[[1000,12]],"id":36182808},{"atb":[[7.8,2.16]],"id":38794071}],"con":true,"img":false}]}
{"op":"mcm","clk":"5321929677","pt":1646314635406,"mc":[{"id":"1.195532852","rc":[{"atl":[[11.5,2.15]],"id":36182808}],"con":true,"img":false}]}
{"op":"mcm","clk":"5321929693","pt":1646314635613,"mc":[{"id":"1.195532852","rc":[{"atb":[[7.8,0.47]],"id":38794071}],"con":true,"img":false}]}
{"op":"mcm","clk":"5321929717","pt":1646314635828,"mc":[{"id":"1.195532852","rc":[{"atl":[[11.5,0.47]],"id":36182808}],"con":true,"img":false}]}
{"op":"mcm","clk":"5321930024","pt":1646314638437,"mc":[{"id":"1.195532852","rc":[{"atb":[[4.2,3.32]],"id":36532033}],"con":true,"img":false}]}
{"op":"mcm","clk":"5321930057","pt":1646314638697,"mc":[{"id":"1.195532852","rc":[{"atb":[[4,3.7]],"id":36532033}],"con":true,"img":false}]}
{"op":"mcm","clk":"5321930069","pt":1646314638802,"mc":[{"id":"1.195532852","rc":[{"atb":[[4.2,4.23]],"id":36532033}],"con":true,"img":false}]}
{"op":"mcm","clk":"5321930114","pt":1646314639218,"mc":[{"id":"1.195532852","rc":[{"atb":[[1.01,11002]],"id":36532033}],"con":true,"img":false}]}
{"op":"mcm","clk":"5321930127","pt":1646314639324,"mc":[{"id":"1.195532852","rc":[{"atb":[[4.3,1.6]],"id":36532033}],"con":true,"img":false}]}
{"op":"mcm","clk":"5321930190","pt":1646314639840,"mc":[{"id":"1.195532852","rc":[{"atb":[[4.1,0]],"id":36532033}],"con":true,"img":false}]}
{"op":"mcm","clk":"5321930204","pt":1646314639942,"mc":[{"id":"1.195532852","rc":[{"atb":[[4.3,3.59]],"id":36532033}],"con":true,"img":false}]}
{"op":"mcm","clk":"5321930292","pt":1646314640618,"mc":[{"id":"1.195532852","rc":[{"atb":[[4.2,3.32]],"id":36532033}],"con":true,"img":false}]}
{"op":"mcm","clk":"5321930303","pt":1646314640722,"mc":[{"id":"1.195532852","rc":[{"atb":[[4.3,4.51]],"id":36532033}],"con":true,"img":false}]}
{"op":"mcm","clk":"5321930368","pt":1646314641250,"mc":[{"id":"1.195532852","rc":[{"atb":[[4,0]],"id":36532033}],"con":true,"img":false}]}
{"op":"mcm","clk":"5321930390","pt":1646314641408,"mc":[{"id":"1.195532852","rc":[{"atl":[[1000,14.52]],"id":36182808},{"atb":[[1.01,11004.52]],"id":38794071}],"con":true,"img":false}]}
{"op":"mcm","clk":"5321930409","pt":1646314641616,"mc":[{"id":"1.195532852","rc":[{"atl":[[1000,13.68]],"id":36182808},{"atb":[[1.01,11003.68]],"id":38794071}],"con":true,"img":false}]}
{"op":"mcm","clk":"5321930422","pt":1646314641723,"mc":[{"id":"1.195532852","rc":[{"atb":[[1.01,11002]],"id":38794071}],"con":true,"img":false}]}
{"op":"mcm","clk":"5321930430","pt":1646314641830,"mc":[{"id":"1.195532852","rc":[{"atl":[[1000,12]],"id":36182808},{"atb":[[7.8,2.16]],"id":38794071}],"con":true,"img":false}]}
{"op":"mcm","clk":"5321930439","pt":1646314641931,"mc":[{"id":"1.195532852","rc":[{"atl":[[11.5,2.15]],"id":36182808}],"con":true,"img":false}]}
{"op":"mcm","clk":"5321930480","pt":1646314642309,"mc":[{"id":"1.195532852","rc":[{"atl":[[11.5,0.47]],"id":36182808},{"atb":[[7.8,0.47]],"id":38794071}],"con":true,"img":false}]}
{"op":"mcm","clk":"5321931118","pt":1646314647825,"mc":[{"id":"1.195532852","rc":[{"atl":[[1000,14.52]],"id":36182808},{"atb":[[1.01,11004.52]],"id":38794071}],"con":true,"img":false}]}
{"op":"mcm","clk":"5321931140","pt":1646314648026,"mc":[{"id":"1.195532852","rc":[{"atl":[[1000,13.68]],"id":36182808},{"atb":[[1.01,11003.68]],"id":38794071}],"con":true,"img":false}]}
{"op":"mcm","clk":"5321931150","pt":1646314648122,"mc":[{"id":"1.195532852","rc":[{"atl":[[1000,12]],"id":36182808},{"atb":[[1.01,11002]],"id":38794071}],"con":true,"img":false}]}
{"op":"mcm","clk":"5321931163","pt":1646314648225,"mc":[{"id":"1.195532852","rc":[{"atl":[[11.5,2.15]],"id":36182808},{"atb":[[7.8,2.16]],"id":38794071}],"con":true,"img":false}]}
{"op":"mcm","clk":"5321931203","pt":1646314648642,"mc":[{"id":"1.195532852","rc":[{"atl":[[11.5,0.47]],"id":36182808},{"atb":[[7.8,0.47]],"id":38794071}],"con":true,"img":false}]}
{"op":"mcm","clk":"5321931295","pt":1646314649632,"mc":[{"id":"1.195532852","rc":[{"atb":[[5.5,0]],"id":36182808}],"con":true,"img":false}]}
{"op":"mcm","clk":"5321931409","pt":1646314650621,"mc":[{"id":"1.195532852","rc":[{"atb":[[1.01,11004.24]],"id":36182808}],"con":true,"img":false}]}
{"op":"mcm","clk":"5321931422","pt":1646314650727,"mc":[{"id":"1.195532852","rc":[{"atb":[[1.01,11002.65],[5.4,1.53]],"id":36182808}],"con":true,"img":false}]}
{"op":"mcm","clk":"5321931433","pt":1646314650829,"mc":[{"id":"1.195532852","rc":[{"atb":[[1.01,11002]],"id":36182808}],"con":true,"img":false}]}
{"op":"mcm","clk":"5321931443","pt":1646314650933,"mc":[{"id":"1.195532852","rc":[{"atb":[[5.7,0.65]],"id":36182808}],"con":true,"img":false}]}
{"op":"mcm","clk":"5321931453","pt":1646314651036,"mc":[{"id":"1.195532852","rc":[{"atb":[[4.2,0]],"id":36532033}],"con":true,"img":false}]}
{"op":"mcm","clk":"5321931491","pt":1646314651358,"mc":[{"id":"1.195532852","rc":[{"atb":[[4.3,2.9]],"id":36532033}],"con":true,"img":false}]}
{"op":"mcm","clk":"5321931503","pt":1646314651461,"mc":[{"id":"1.195532852","rc":[{"atb":[[1.01,11003.6]],"id":36532033}],"con":true,"img":false}]}
{"op":"mcm","clk":"5321931591","pt":1646314652249,"mc":[{"id":"1.195532852","rc":[{"atb":[[2.96,0]],"id":36532033},{"atb":[[3.25,0]],"id":38386807}],"con":true,"img":false}]}
{"op":"mcm","clk":"5321931814","pt":1646314654328,"mc":[{"id":"1.195532852","rc":[{"atb":[[4.3,0.91]],"id":36532033},{"atb":[[1.01,11004.52]],"id":38794071}],"con":true,"img":false}]}
{"op":"mcm","clk":"5321931820","pt":1646314654426,"mc":[{"id":"1.195532852","rc":[{"atb":[[4,1.99]],"id":36532033}],"con":true,"img":false}]}
{"op":"mcm","clk":"5321931827","pt":1646314654534,"mc":[{"id":"1.195532852","rc":[{"atl":[[1000,14.52]],"id":36182808},{"atb":[[1.01,11003.68]],"id":38794071}],"con":true,"img":false}]}
{"op":"mcm","clk":"5321931836","pt":1646314654634,"mc":[{"id":"1.195532852","rc":[{"atb":[[4,5.69]],"id":36532033}],"con":true,"img":false}]}
{"op":"mcm","clk":"5321931859","pt":1646314654739,"mc":[{"id":"1.195532852","rc":[{"atb":[[5.6,0]],"id":36182808},{"atl":[[1000,13.68]],"id":36182808},{"atb":[[1.01,11002]],"id":38794071}],"con":true,"img":false}]}
{"op":"mcm","clk":"5321931866","pt":1646314654842,"mc":[{"id":"1.195532852","rc":[{"atb":[[5.4,3.52]],"id":36182808},{"atl":[[1000,12]],"id":36182808},{"atb":[[7.8,2.16]],"id":38794071}],"con":true,"img":false}]}
{"op":"mcm","clk":"5321931878","pt":1646314654944,"mc":[{"id":"1.195532852","rc":[{"atl":[[11.5,2.15]],"id":36182808}],"con":true,"img":false}]}
{"op":"mcm","clk":"5321931895","pt":1646314655157,"mc":[{"id":"1.195532852","rc":[{"atl":[[11.5,0.47]],"id":36182808},{"atb":[[7.8,0.47]],"id":38794071}],"con":true,"img":false}]}
{"op":"mcm","clk":"5321931907","pt":1646314655361,"mc":[{"id":"1.195532852","rc":[{"atb":[[5.5,1.65]],"id":36182808}],"con":true,"img":false}]}
{"op":"mcm","clk":"5321932054","pt":1646314656668,"mc":[{"id":"1.195532852","rc":[{"atb":[[1.01,11006.12]],"id":36532033}],"con":true,"img":false}]}
{"op":"mcm","clk":"5321932068","pt":1646314656733,"mc":[{"id":"1.195532852","rc":[{"atb":[[5.4,1.53]],"id":36182808}],"con":true,"img":false}]}
{"op":"mcm","clk":"5321932082","pt":1646314656828,"mc":[{"id":"1.195532852","rc":[{"atb":[[1.01,11005.7]],"id":36532033},{"atb":[[5.6,1.99]],"id":36182808}],"con":true,"img":false}]}
{"op":"mcm","clk":"5321932099","pt":1646314657029,"mc":[{"id":"1.195532852","rc":[{"atb":[[1.01,11003.6]],"id":36532033}],"con":true,"img":false}]}
{"op":"mcm","clk":"5321932110","pt":1646314657130,"mc":[{"id":"1.195532852","rc":[{"atb":[[4.1,2.1],[2.7,6.59]],"id":36532033}],"con":true,"img":false}]}
{"op":"mcm","clk":"5321932125","pt":1646314657239,"mc":[{"id":"1.195532852","rc":[{"atb":[[2.3,8.62]],"id":38386807}],"con":true,"img":false}]}
{"op":"mcm","clk":"5321932356","pt":1646314659529,"mc":[{"id":"1.195532852","rc":[{"atb":[[4,3.7]],"id":36532033}],"con":true,"img":false}]}
{"op":"mcm","clk":"5321932368","pt":1646314659641,"mc":[{"id":"1.195532852","rc":[{"atb":[[4.2,1.99]],"id":36532033}],"con":true,"img":false}]}
{"op":"mcm","clk":"5321932407","pt":1646314659841,"mc":[{"id":"1.195532852","rc":[{"atb":[[5.6,0]],"id":36182808}],"con":true,"img":false}]}
{"op":"mcm","clk":"5321932418","pt":1646314659946,"mc":[{"id":"1.195532852","rc":[{"atb":[[5.5,3.64]],"id":36182808}],"con":true,"img":false}]}
{"op":"mcm","clk":"5321932462","pt":1646314660365,"mc":[{"id":"1.195532852","rc":[{"atb":[[1.01,11004.52]],"id":38794071}],"con":true,"img":false}]}
{"op":"mcm","clk":"5321932490","pt":1646314660543,"mc":[{"id":"1.195532852","rc":[{"atb":[[1.01,11003.68]],"id":38794071}],"con":true,"img":false}]}
{"op":"mcm","clk":"5321932503","pt":1646314660627,"mc":[{"id":"1.195532852","rc":[{"atb":[[5.4,0]],"id":36182808}],"con":true,"img":false}]}
{"op":"mcm","clk":"5321932516","pt":1646314660733,"mc":[{"id":"1.195532852","rc":[{"atb":[[5.6,1.53]],"id":36182808},{"atb":[[1.01,11002]],"id":38794071}],"con":true,"img":false}]}
{"op":"mcm","clk":"5321932530","pt":1646314660835,"mc":[{"id":"1.195532852","rc":[{"atb":[[7.8,2.16]],"id":38794071}],"con":true,"img":false}]}
{"op":"mcm","clk":"5321932541","pt":1646314660936,"mc":[{"id":"1.195532852","rc":[{"atb":[[4,0]],"id":36532033}],"con":true,"img":false}]}
{"op":"mcm","clk":"5321932552","pt":1646314661045,"mc":[{"id":"1.195532852","rc":[{"atb":[[7.8,0.47]],"id":38794071}],"con":true,"img":false}]}
{"op":"mcm","clk":"5321932655","pt":1646314662032,"mc":[{"id":"1.195532852","rc":[{"atb":[[5.5,1.65]],"id":36182808}],"con":true,"img":false}]}
{"op":"mcm","clk":"5321932666","pt":1646314662137,"mc":[{"id":"1.195532852","rc":[{"atb":[[5.7,2.64]],"id":36182808}],"con":true,"img":false}]}
{"op":"mcm","clk":"5321932681","pt":1646314662246,"mc":[{"id":"1.195532852","rc":[{"atb":[[4.7,0]],"id":41064273},{"atb":[[3.85,0]],"id":36182808},{"atb":[[3.55,0]],"id":38794071},{"atb":[[2.36,73.53]],"id":41177799}],"con":true,"img":false}]}
{"op":"mcm","clk":"5321932692","pt":1646314662346,"mc":[{"id":"1.195532852","rc":[{"atl":[[1000,14.52]],"id":36182808}],"con":true,"img":false}]}
{"op":"mcm","clk":"5321932705","pt":1646314662445,"mc":[{"id":"1.195532852","rc":[{"atb":[[5.6,0]],"id":36182808}],"con":true,"img":false}]}
{"op":"mcm","clk":"5321932715","pt":1646314662555,"mc":[{"id":"1.195532852","rc":[{"atb":[[1.01,11003.53]],"id":36182808},{"atl":[[1000,13.68]],"id":36182808}],"con":true,"img":false}]}
{"op":"mcm","clk":"5321932728","pt":1646314662654,"mc":[{"id":"1.195532852","rc":[{"atl":[[1000,12]],"id":36182808}],"con":true,"img":false}]}
{"op":"mcm","clk":"5321932739","pt":1646314662758,"mc":[{"id":"1.195532852","rc":[{"atl":[[11.5,2.15]],"id":36182808}],"con":true,"img":false}]}
{"op":"mcm","clk":"5321932772","pt":1646314663072,"mc":[{"id":"1.195532852","rc":[{"atb":[[5.7,0.65]],"id":36182808}],"con":true,"img":false}]}
{"op":"mcm","clk":"5321932787","pt":1646314663132,"mc":[{"id":"1.195532852","rc":[{"atb":[[5.4,1.99]],"id":36182808}],"con":true,"img":false}]}
{"op":"mcm","clk":"5321932797","pt":1646314663239,"mc":[{"id":"1.195532852","rc":[{"atl":[[11.5,0.47]],"id":36182808}],"con":true,"img":false}]}
{"op":"mcm","clk":"5321932821","pt":1646314663444,"mc":[{"id":"1.195532852","rc":[{"atb":[[1.01,11002]],"id":36182808}],"con":true,"img":false}]}
{"op":"mcm","clk":"5321932837","pt":1646314663547,"mc":[{"id":"1.195532852","rc":[{"atb":[[4.1,0]],"id":36532033},{"atb":[[5.4,3.52]],"id":36182808}],"con":true,"img":false}]}
{"op":"mcm","clk":"5321932849","pt":1646314663652,"mc":[{"id":"1.195532852","rc":[{"atb":[[2.84,6.09]],"id":41064273}],"con":true,"img":false}]}
{"op":"mcm","clk":"5321932987","pt":1646314664843,"mc":[{"id":"1.195532852","rc":[{"atb":[[3.9,8.76]],"id":36532033}],"con":true,"img":false}]}
{"op":"mcm","clk":"5321933011","pt":1646314665049,"mc":[{"id":"1.195532852","rc":[{"atb":[[4.3,6.31]],"id":36532033}],"con":true,"img":false}]}
{"op":"mcm","clk":"5321933172","pt":1646314666668,"mc":[{"id":"1.195532852","rc":[{"atb":[[1.01,11004.52]],"id":38794071}],"con":true,"img":false}]}
{"op":"mcm","clk":"5321933179","pt":1646314666765,"mc":[{"id":"1.195532852","rc":[{"atb":[[1.01,11003.68]],"id":38794071}],"con":true,"img":false}]}
{"op":"mcm","clk":"5321933191","pt":1646314666872,"mc":[{"id":"1.195532852","rc":[{"atb":[[1.01,11002]],"id":38794071}],"con":true,"img":false}]}
{"op":"mcm","clk":"5321933199","pt":1646314666972,"mc":[{"id":"1.195532852","rc":[{"atb":[[7.8,2.16]],"id":38794071}],"con":true,"img":false}]}
{"op":"mcm","clk":"5321933221","pt":1646314667130,"mc":[{"id":"1.195532852","rc":[{"atb":[[7.8,0.47]],"id":38794071}],"con":true,"img":false}]}
{"op":"mcm","clk":"5321933280","pt":1646314667655,"mc":[{"id":"1.195532852","rc":[{"atl":[[1000,14.52]],"id":36182808}],"con":true,"img":false}]}
{"op":"mcm","clk":"5321933303","pt":1646314667863,"mc":[{"id":"1.195532852","rc":[{"atl":[[1000,13.68]],"id":36182808}],"con":true,"img":false}]}
{"op":"mcm","clk":"5321933314","pt":1646314667962,"mc":[{"id":"1.195532852","rc":[{"atl":[[1000,12]],"id":36182808}],"con":true,"img":false}]}
{"op":"mcm","clk":"5321933326","pt":1646314668076,"mc":[{"id":"1.195532852","rc":[{"atl":[[11.5,2.15]],"id":36182808}],"con":true,"img":false}]}
{"op":"mcm","clk":"5321933362","pt":1646314668379,"mc":[{"id":"1.195532852","rc":[{"atl":[[11.5,0.47]],"id":36182808}],"con":true,"img":false}]}
{"op":"mcm","clk":"5321933465","pt":1646314669274,"mc":[{"id":"1.195532852","rc":[{"atb":[[3.9,0]],"id":36532033}],"con":true,"img":false}]}
{"op":"mcm","clk":"5321933488","pt":1646314669481,"mc":[{"id":"1.195532852","rc":[{"atb":[[4.2,0]],"id":36532033}],"con":true,"img":false}]}
{"op":"mcm","clk":"5321933498","pt":1646314669541,"mc":[{"id":"1.195532852","rc":[{"atb":[[4,1.99]],"id":36532033}],"con":true,"img":false}]}
{"op":"mcm","clk":"5321933524","pt":1646314669850,"mc":[{"id":"1.195532852","rc":[{"atb":[[5.4,1.53]],"id":36182808}],"con":true,"img":false}]}
{"op":"mcm","clk":"5321933539","pt":1646314669957,"mc":[{"id":"1.195532852","rc":[{"atb":[[5.6,1.99]],"id":36182808}],"con":true,"img":false}]}
{"op":"mcm","clk":"5321933677","pt":1646314671277,"mc":[{"id":"1.195532852","rc":[{"atb":[[4.3,0.91]],"id":36532033}],"con":true,"img":false}]}
{"op":"mcm","clk":"5321933792","pt":1646314672264,"mc":[{"id":"1.195532852","rc":[{"atb":[[5.6,0]],"id":36182808}],"con":true,"img":false}]}
{"op":"mcm","clk":"5321933802","pt":1646314672360,"mc":[{"id":"1.195532852","rc":[{"atb":[[5.5,3.64]],"id":36182808}],"con":true,"img":false}]}
{"op":"mcm","clk":"5321933843","pt":1646314672676,"mc":[{"id":"1.195532852","rc":[{"atb":[[5.4,0]],"id":36182808}],"con":true,"img":false}]}
{"op":"mcm","clk":"5321933863","pt":1646314672777,"mc":[{"id":"1.195532852","rc":[{"atb":[[5.6,1.53]],"id":36182808}],"con":true,"img":false}]}
{"op":"mcm","clk":"5321933909","pt":1646314673038,"mc":[{"id":"1.195532852","rc":[{"atb":[[1.01,11004.52]],"id":38794071}],"con":true,"img":false}]}
{"op":"mcm","clk":"5321933927","pt":1646314673150,"mc":[{"id":"1.195532852","rc":[{"atb":[[1.01,11003.68]],"id":38794071}],"con":true,"img":false}]}
{"op":"mcm","clk":"5321933944","pt":1646314673246,"mc":[{"id":"1.195532852","rc":[{"atb":[[1.01,11002]],"id":38794071}],"con":true,"img":false}]}
{"op":"mcm","clk":"5321933961","pt":1646314673382,"mc":[{"id":"1.195532852","rc":[{"atb":[[7.8,2.16]],"id":38794071}],"con":true,"img":false}]}
{"op":"mcm","clk":"5321933982","pt":1646314673461,"mc":[{"id":"1.195532852","rc":[{"atb":[[4,13.04]],"id":36532033}],"con":true,"img":false}]}
{"op":"mcm","clk":"5321934028","pt":1646314673879,"mc":[{"id":"1.195532852","rc":[{"atb":[[7.8,0.47]],"id":38794071}],"con":true,"img":false}]}
{"op":"mcm","clk":"5321934109","pt":1646314674559,"mc":[{"id":"1.195532852","rc":[{"atb":[[1.01,11002]],"id":36532033}],"con":true,"img":false}]}
{"op":"mcm","clk":"5321934119","pt":1646314674672,"mc":[{"id":"1.195532852","rc":[{"atb":[[4.1,1.6]],"id":36532033}],"con":true,"img":false}]}
{"op":"mcm","clk":"5321934150","pt":1646314674879,"mc":[{"id":"1.195532852","rc":[{"atb":[[5.5,1.65]],"id":36182808}],"con":true,"img":false}]}
{"op":"mcm","clk":"5321934165","pt":1646314674981,"mc":[{"id":"1.195532852","rc":[{"atb":[[5.7,2.64]],"id":36182808}],"con":true,"img":false}]}
{"op":"mcm","clk":"5321934195","pt":1646314675151,"mc":[{"id":"1.195532852","rc":[{"atl":[[1000,14.52]],"id":36182808}],"con":true,"img":false}]}
{"op":"mcm","clk":"5321934227","pt":1646314675359,"mc":[{"id":"1.195532852","rc":[{"atl":[[1000,13.68]],"id":36182808}],"con":true,"img":false}]}
{"op":"mcm","clk":"5321934240","pt":1646314675462,"mc":[{"id":"1.195532852","rc":[{"atb":[[5.6,0]],"id":36182808},{"atl":[[1000,12]],"id":36182808}],"con":true,"img":false}]}
{"op":"mcm","clk":"5321934251","pt":1646314675565,"mc":[{"id":"1.195532852","rc":[{"atb":[[1.01,11003.53]],"id":36182808},{"atl":[[11.5,2.15]],"id":36182808}],"con":true,"img":false}]}
{"op":"mcm","clk":"5321934281","pt":1646314675882,"mc":[{"id":"1.195532852","rc":[{"atl":[[11.5,0.47]],"id":36182808}],"con":true,"img":false}]}
{"op":"mcm","clk":"5321934418","pt":1646314676879,"mc":[{"id":"1.195532852","rc":[{"atb":[[4,1.99]],"id":36532033}],"con":true,"img":false}]}
{"op":"mcm","clk":"5321934441","pt":1646314677080,"mc":[{"id":"1.195532852","rc":[{"atb":[[4,0]],"id":36532033}],"con":true,"img":false}]}
{"op":"mcm","clk":"5321934455","pt":1646314677244,"mc":[{"id":"1.195532852","rc":[{"atb":[[4.2,1.99]],"id":36532033}],"con":true,"img":false}]}
{"op":"mcm","clk":"5321934472","pt":1646314677299,"mc":[{"id":"1.195532852","rc":[{"atb":[[4.1,0]],"id":36532033},{"atb":[[5.7,0.65]],"id":36182808}],"con":true,"img":false}]}
{"op":"mcm","clk":"5321934485","pt":1646314677407,"mc":[{"id":"1.195532852","rc":[{"atb":[[3.9,1.6]],"id":36532033},{"atb":[[5.4,1.99]],"id":36182808}],"con":true,"img":false}]}
{"op":"mcm","clk":"5321934501","pt":1646314677511,"mc":[{"id":"1.195532852","rc":[{"atb":[[2.38,17.12]],"id":41177799}],"con":true,"img":false}]}
{"op":"mcm","clk":"5321934531","pt":1646314677723,"mc":[{"id":"1.195532852","rc":[{"atb":[[4.8,3.27]],"id":38794071}],"con":true,"img":false}]}
{"op":"mcm","clk":"5321934544","pt":1646314677831,"mc":[{"id":"1.195532852","rc":[{"atb":[[2.88,6.6]],"id":41064273}],"con":true,"img":false}]}
{"op":"mcm","clk":"5321934582","pt":1646314678236,"mc":[{"id":"1.195532852","rc":[{"atb":[[2.84,6.74]],"id":36182808}],"con":true,"img":false}]}
{"op":"mcm","clk":"5321934845","pt":1646314680653,"mc":[{"id":"1.195532852","rc":[{"atb":[[5.7,0]],"id":36182808}],"con":true,"img":false}]}
{"op":"mcm","clk":"5321934856","pt":1646314680714,"mc":[{"id":"1.195532852","rc":[{"atb":[[1.01,11005.78]],"id":36182808},{"atb":[[4.5,0]],"id":38794071}],"con":true,"img":false}]}
{"op":"mcm","clk":"5321934873","pt":1646314680819,"mc":[{"id":"1.195532852","rc":[{"atb":[[4,3.7]],"id":36532033},{"atb":[[1.01,11004.19]],"id":36182808}],"con":true,"img":false}]}
{"op":"mcm","clk":"5321934901","pt":1646314681028,"mc":[{"id":"1.195532852","rc":[{"atb":[[1.01,11003.53]],"id":36182808}],"con":true,"img":false}]}
{"op":"mcm","clk":"5321934915","pt":1646314681139,"mc":[{"id":"1.195532852","rc":[{"atb":[[5.6,0.65]],"id":36182808}],"con":true,"img":false}]}
{"op":"mcm","clk":"5321934971","pt":1646314681550,"mc":[{"id":"1.195532852","rc":[{"atl":[[1000,14.52]],"id":36182808}],"con":true,"img":false}]}
{"op":"mcm","clk":"5321934986","pt":1646314681648,"mc":[{"id":"1.195532852","rc":[{"atl":[[1000,13.68]],"id":36182808}],"con":true,"img":false}]}
{"op":"mcm","clk":"5321934998","pt":1646314681705,"mc":[{"id":"1.195532852","rc":[{"atl":[[1000,12]],"id":36182808}],"con":true,"img":false}]}
{"op":"mcm","clk":"5321935012","pt":1646314681823,"mc":[{"id":"1.195532852","rc":[{"atl":[[11.5,2.15]],"id":36182808}],"con":true,"img":false}]}
{"op":"mcm","clk":"5321935057","pt":1646314682230,"mc":[{"id":"1.195532852","rc":[{"atl":[[11.5,0.47]],"id":36182808}],"con":true,"img":false}]}
{"op":"mcm","clk":"5321935313","pt":1646314684129,"mc":[{"id":"1.195532852","rc":[{"atb":[[4.2,0]],"id":36532033}],"con":true,"img":false}]}
{"op":"mcm","clk":"5321935319","pt":1646314684222,"mc":[{"id":"1.195532852","rc":[{"atb":[[4.1,1.99]],"id":36532033}],"con":true,"img":false}]}
{"op":"mcm","clk":"5321935355","pt":1646314684536,"mc":[{"id":"1.195532852","rc":[{"atb":[[5.4,0]],"id":36182808}],"con":true,"img":false}]}
{"op":"mcm","clk":"5321935366","pt":1646314684639,"mc":[{"id":"1.195532852","rc":[{"atb":[[5.6,2.64]],"id":36182808}],"con":true,"img":false}]}
{"op":"mcm","clk":"5321935383","pt":1646314684794,"mc":[{"id":"1.195532852","rc":[{"atb":[[4.9,23.97]],"id":38794071}],"con":true,"img":false}]}
{"op":"mcm","clk":"5321935393","pt":1646314684911,"mc":[{"id":"1.195532852","rc":[{"atb":[[1.03,2.24],[7.8,0]],"id":38794071}],"con":true,"img":false}]}
{"op":"mcm","clk":"5321935409","pt":1646314685014,"mc":[{"id":"1.195532852","rc":[{"atb":[[1.03,0.47]],"id":38794071}],"con":true,"img":false}]}
{"op":"mcm","clk":"5321935422","pt":1646314685120,"mc":[{"id":"1.195532852","rc":[{"atb":[[1.03,0]],"id":38794071}],"con":true,"img":false}]}
{"op":"mcm","clk":"5321935435","pt":1646314685228,"mc":[{"id":"1.195532852","rc":[{"atb":[[5,0.47]],"id":38794071}],"con":true,"img":false}]}
{"op":"mcm","clk":"5321935502","pt":1646314685856,"mc":[{"id":"1.195532852","rc":[{"atb":[[1.01,11004.52]],"id":38794071}],"con":true,"img":false}]}
{"op":"mcm","clk":"5321935529","pt":1646314686008,"mc":[{"id":"1.195532852","rc":[{"atb":[[1.01,11003.68]],"id":38794071}],"con":true,"img":false}]}
{"op":"mcm","clk":"5321935559","pt":1646314686317,"mc":[{"id":"1.195532852","rc":[{"atb":[[1.01,11002]],"id":38794071}],"con":true,"img":false}]}
{"op":"mcm","clk":"5321935564","pt":1646314686419,"mc":[{"id":"1.195532852","rc":[{"atl":[[1000,14.52]],"id":36182808},{"atb":[[7.8,1.68]],"id":38794071}],"con":true,"img":false}]}
{"op":"mcm","clk":"5321935582","pt":1646314686529,"mc":[{"id":"1.195532852","rc":[{"atl":[[1000,13.68]],"id":36182808}],"con":true,"img":false}]}
{"op":"mcm","clk":"5321935609","pt":1646314686745,"mc":[{"id":"1.195532852","rc":[{"atl":[[1000,12]],"id":36182808}],"con":true,"img":false}]}
{"op":"mcm","clk":"5321935626","pt":1646314686846,"mc":[{"id":"1.195532852","rc":[{"atl":[[11.5,2.15]],"id":36182808},{"atb":[[7.8,0]],"id":38794071}],"con":true,"img":false}]}
{"op":"mcm","clk":"5321935647","pt":1646314687055,"mc":[{"id":"1.195532852","rc":[{"atl":[[11.5,0.47]],"id":36182808}],"con":true,"img":false}]}
{"op":"mcm","clk":"5321936081","pt":1646314691124,"mc":[{"id":"1.195532852","rc":[{"atb":[[5.6,0.65]],"id":36182808}],"con":true,"img":false}]}
{"op":"mcm","clk":"5321936096","pt":1646314691234,"mc":[{"id":"1.195532852","rc":[{"atb":[[4.2,2.86]],"id":36532033},{"atb":[[5.4,1.99]],"id":36182808}],"con":true,"img":false}]}
{"op":"mcm","clk":"5321936150","pt":1646314691847,"mc":[{"id":"1.195532852","rc":[{"atb":[[1.01,11004.52]],"id":38794071}],"con":true,"img":false}]}
{"op":"mcm","clk":"5321936162","pt":1646314691959,"mc":[{"id":"1.195532852","rc":[{"atl":[[1000,14.52]],"id":36182808}],"con":true,"img":false}]}
{"op":"mcm","clk":"5321936175","pt":1646314692069,"mc":[{"id":"1.195532852","rc":[{"atb":[[1.01,11003.68]],"id":38794071}],"con":true,"img":false}]}
{"op":"mcm","clk":"5321936186","pt":1646314692116,"mc":[{"id":"1.195532852","rc":[{"atl":[[1000,13.68]],"id":36182808}],"con":true,"img":false}]}
{"op":"mcm","clk":"5321936194","pt":1646314692269,"mc":[{"id":"1.195532852","rc":[{"atl":[[1000,12]],"id":36182808},{"atb":[[1.01,11002]],"id":38794071}],"con":true,"img":false}]}
{"op":"mcm","clk":"5321936207","pt":1646314692331,"mc":[{"id":"1.195532852","rc":[{"atl":[[11.5,2.15]],"id":36182808},{"atb":[[7.8,1.68]],"id":38794071}],"con":true,"img":false}]}
{"op":"mcm","clk":"5321936236","pt":1646314692538,"mc":[{"id":"1.195532852","rc":[{"atl":[[11.5,0.47]],"id":36182808},{"atb":[[7.8,0]],"id":38794071}],"con":true,"img":false}]}
{"op":"mcm","clk":"5321936264","pt":1646314692846,"mc":[{"id":"1.195532852","rc":[{"atb":[[4.1,0]],"id":36532033}],"con":true,"img":false}]}
{"op":"mcm","clk":"5321936270","pt":1646314692944,"mc":[{"id":"1.195532852","rc":[{"atb":[[4.3,2.9]],"id":36532033}],"con":true,"img":false}]}
{"op":"mcm","clk":"5321936366","pt":1646314693833,"mc":[{"id":"1.195532852","rc":[{"atb":[[3.9,0]],"id":36532033}],"con":true,"img":false}]}
{"op":"mcm","clk":"5321936381","pt":1646314693935,"mc":[{"id":"1.195532852","rc":[{"atb":[[4.3,4.51]],"id":36532033}],"con":true,"img":false}]}
{"op":"mcm","clk":"5321936448","pt":1646314694454,"mc":[{"id":"1.195532852","rc":[{"atb":[[4,0]],"id":36532033},{"atb":[[2.06,0]],"id":38386807}],"con":true,"img":false}]}
{"op":"mcm","clk":"5321936459","pt":1646314694507,"mc":[{"id":"1.195532852","rc":[{"atb":[[2.32,10.33]],"id":38386807}],"con":true,"img":false}]}
{"op":"mcm","clk":"5321936839","pt":1646314697752,"mc":[{"id":"1.195532852","rc":[{"atb":[[1.01,11004.52]],"id":38794071}],"con":true,"img":false}]}
{"op":"mcm","clk":"5321936858","pt":1646314697868,"mc":[{"id":"1.195532852","rc":[{"atl":[[1000,14.52]],"id":36182808}],"con":true,"img":false}]}
{"op":"mcm","clk":"5321936865","pt":1646314697912,"mc":[{"id":"1.195532852","rc":[{"atb":[[1.01,11003.68]],"id":38794071}],"con":true,"img":false}]}
{"op":"mcm","clk":"5321936876","pt":1646314698065,"mc":[{"id":"1.195532852","rc":[{"atl":[[1000,13.68]],"id":36182808}],"con":true,"img":false}]}
{"op":"mcm","clk":"5321936885","pt":1646314698117,"mc":[{"id":"1.195532852","rc":[{"atb":[[1.01,11002]],"id":38794071}],"con":true,"img":false}]}
{"op":"mcm","clk":"5321936898","pt":1646314698224,"mc":[{"id":"1.195532852","rc":[{"atb":[[5.4,0]],"id":36182808},{"atl":[[1000,12]],"id":36182808},{"atb":[[7.8,1.68]],"id":38794071}],"con":true,"img":false}]}
{"op":"mcm","clk":"5321936911","pt":1646314698329,"mc":[{"id":"1.195532852","rc":[{"atb":[[4,7.9]],"id":36532033},{"atl":[[11.5,2.15]],"id":36182808}],"con":true,"img":false}]}
{"op":"mcm","clk":"5321936927","pt":1646314698441,"mc":[{"id":"1.195532852","rc":[{"atb":[[4.2,0]],"id":36532033},{"atb":[[5.6,2.64]],"id":36182808},{"atb":[[7.8,0]],"id":38794071}],"con":true,"img":false}]}
{"op":"mcm","clk":"5321936956","pt":1646314698651,"mc":[{"id":"1.195532852","rc":[{"atl":[[11.5,0.47]],"id":36182808}],"con":true,"img":false}]}
{"op":"mcm","clk":"5321937093","pt":1646314699549,"mc":[{"id":"1.195532852","rc":[{"atb":[[4.3,2.9]],"id":36532033}],"con":true,"img":false}]}
{"op":"mcm","clk":"5321937104","pt":1646314699652,"mc":[{"id":"1.195532852","rc":[{"atb":[[1.01,11003.6]],"id":36532033}],"con":true,"img":false}]}
{"op":"mcm","clk":"5321937139","pt":1646314699966,"mc":[{"id":"1.195532852","rc":[{"atb":[[4.3,0.91]],"id":36532033}],"con":true,"img":false}]}
{"op":"mcm","clk":"5321937148","pt":1646314700063,"mc":[{"id":"1.195532852","rc":[{"atb":[[4.1,1.99]],"id":36532033}],"con":true,"img":false}]}
{"op":"mcm","clk":"5321937185","pt":1646314700382,"mc":[{"id":"1.195532852","rc":[{"atb":[[5.6,0.65]],"id":36182808}],"con":true,"img":false}]}
{"op":"mcm","clk":"5321937193","pt":1646314700434,"mc":[{"id":"1.195532852","rc":[{"atb":[[5.4,1.99]],"id":36182808}],"con":true,"img":false}]}
{"op":"mcm","clk":"5321937432","pt":1646314702273,"mc":[{"id":"1.195532852","rc":[{"atb":[[4,0]],"id":36532033}],"con":true,"img":false}]}
{"op":"mcm","clk":"5321937609","pt":1646314703843,"mc":[{"id":"1.195532852","rc":[{"atl":[[1000,14.52]],"id":36182808},{"atb":[[1.01,11004.52]],"id":38794071}],"con":true,"img":false}]}
{"op":"mcm","clk":"5321937624","pt":1646314703944,"mc":[{"id":"1.195532852","rc":[{"atl":[[1000,13.68]],"id":36182808},{"atb":[[1.01,11003.68]],"id":38794071}],"con":true,"img":false}]}
{"op":"mcm","clk":"5321937633","pt":1646314704049,"mc":[{"id":"1.195532852","rc":[{"atb":[[1.01,11002]],"id":38794071}],"con":true,"img":false}]}
{"op":"mcm","clk":"5321937646","pt":1646314704152,"mc":[{"id":"1.195532852","rc":[{"atl":[[1000,12]],"id":36182808},{"atb":[[7.8,1.68]],"id":38794071}],"con":true,"img":false}]}
{"op":"mcm","clk":"5321937657","pt":1646314704255,"mc":[{"id":"1.195532852","rc":[{"atl":[[11.5,2.15]],"id":36182808}],"con":true,"img":false}]}
{"op":"mcm","clk":"5321937683","pt":1646314704464,"mc":[{"id":"1.195532852","rc":[{"atl":[[11.5,0.47]],"id":36182808}],"con":true,"img":false}]}
{"op":"mcm","clk":"5321937707","pt":1646314704674,"mc":[{"id":"1.195532852","rc":[{"atb":[[7.8,0]],"id":38794071}],"con":true,"img":false}]}
{"op":"mcm","clk":"5321937918","pt":1646314706651,"mc":[{"id":"1.195532852","rc":[{"atb":[[4,3.7]],"id":36532033}],"con":true,"img":false}]}
{"op":"mcm","clk":"5321938010","pt":1646314707583,"mc":[{"id":"1.195532852","rc":[{"atb":[[5.4,0]],"id":36182808}],"con":true,"img":false}]}
{"op":"mcm","clk":"5321938020","pt":1646314707638,"mc":[{"id":"1.195532852","rc":[{"atb":[[5.6,2.64]],"id":36182808}],"con":true,"img":false}]}
{"op":"mcm","clk":"5321938046","pt":1646314707947,"mc":[{"id":"1.195532852","rc":[{"atb":[[4.4,0]],"id":38794071},{"spn":10.8,"spf":1.0,"id":38794071}],"con":true,"img":false}]}
{"op":"mcm","clk":"5321938217","pt":1646314709470,"mc":[{"id":"1.195532852","rc":[{"atb":[[1.01,11004.52]],"id":38794071}],"con":true,"img":false}]}
{"op":"mcm","clk":"5321938231","pt":1646314709574,"mc":[{"id":"1.195532852","rc":[{"atl":[[1000,14.52]],"id":36182808}],"con":true,"img":false}]}
{"op":"mcm","clk":"5321938241","pt":1646314709673,"mc":[{"id":"1.195532852","rc":[{"atb":[[1.01,11003.68]],"id":38794071}],"con":true,"img":false}]}
{"op":"mcm","clk":"5321938254","pt":1646314709780,"mc":[{"id":"1.195532852","rc":[{"atb":[[1.01,11002]],"id":38794071}],"con":true,"img":false}]}
{"op":"mcm","clk":"5321938267","pt":1646314709882,"mc":[{"id":"1.195532852","rc":[{"atb":[[5.6,0.65]],"id":36182808},{"atb":[[7.8,1.68]],"id":38794071}],"con":true,"img":false}]}
{"op":"mcm","clk":"5321938284","pt":1646314709984,"mc":[{"id":"1.195532852","rc":[{"atb":[[5.4,1.99]],"id":36182808},{"atl":[[1000,13.68]],"id":36182808}],"con":true,"img":false}]}
{"op":"mcm","clk":"5321938312","pt":1646314710153,"mc":[{"id":"1.195532852","rc":[{"atl":[[1000,12]],"id":36182808}],"con":true,"img":false}]}
{"op":"mcm","clk":"5321938324","pt":1646314710296,"mc":[{"id":"1.195532852","rc":[{"atl":[[11.5,2.15]],"id":36182808}],"con":true,"img":false}]}
{"op":"mcm","clk":"5321938336","pt":1646314710355,"mc":[{"id":"1.195532852","rc":[{"atb":[[7.8,0]],"id":38794071}],"con":true,"img":false}]}
{"op":"mcm","clk":"5321938358","pt":1646314710560,"mc":[{"id":"1.195532852","rc":[{"atl":[[11.5,0.47]],"id":36182808}],"con":true,"img":false}]}
{"op":"mcm","clk":"5321938372","pt":1646314710668,"mc":[{"id":"1.195532852","rc":[{"atb":[[5.4,0]],"id":36182808}],"con":true,"img":false}]}
{"op":"mcm","clk":"5321938380","pt":1646314710767,"mc":[{"id":"1.195532852","rc":[{"atb":[[5.6,2.64]],"id":36182808}],"con":true,"img":false}]}
{"op":"mcm","clk":"5321938427","pt":1646314711187,"mc":[{"id":"1.195532852","rc":[{"atb":[[1.01,11005.78],[5.6,1.99]],"id":36182808},{"atb":[[4.8,6.22]],"id":38794071}],"con":true,"img":false}]}
{"op":"mcm","clk":"5321938457","pt":1646314711392,"mc":[{"id":"1.195532852","rc":[{"atb":[[1.01,11004.19]],"id":36182808}],"con":true,"img":false}]}
{"op":"mcm","clk":"5321938483","pt":1646314711551,"mc":[{"id":"1.195532852","rc":[{"atb":[[1.01,11003.53]],"id":36182808}],"con":true,"img":false}]}
{"op":"mcm","clk":"5321938493","pt":1646314711657,"mc":[{"id":"1.195532852","rc":[{"atb":[[5.4,0.65]],"id":36182808}],"con":true,"img":false}]}
{"op":"mcm","clk":"5321938554","pt":1646314712172,"mc":[{"id":"1.195532852","rc":[{"atb":[[2.66,0]],"id":36532033}],"con":true,"img":false}]}
{"op":"mcm","clk":"5321938617","pt":1646314712902,"mc":[{"id":"1.195532852","rc":[{"atb":[[5.5,0]],"id":36182808}],"con":true,"img":false}]}
{"op":"mcm","clk":"5321938850","pt":1646314714790,"mc":[{"id":"1.195532852","rc":[{"atb":[[1.01,11004.52]],"id":38794071}],"con":true,"img":false}]}
{"op":"mcm","clk":"5321938868","pt":1646314714845,"mc":[{"id":"1.195532852","rc":[{"atb":[[2.28,0]],"id":38794071}],"con":true,"img":false}]}
{"op":"mcm","clk":"5321938884","pt":1646314714951,"mc":[{"id":"1.195532852","rc":[{"atb":[[1.01,11003.68]],"id":38794071}],"con":true,"img":false}]}
{"op":"mcm","clk":"5321938907","pt":1646314715157,"mc":[{"id":"1.195532852","rc":[{"atb":[[1.01,11002]],"id":38794071}],"con":true,"img":false}]}
{"op":"mcm","clk":"5321938919","pt":1646314715265,"mc":[{"id":"1.195532852","rc":[{"atb":[[7.8,1.68]],"id":38794071}],"con":true,"img":false}]}
{"op":"mcm","clk":"5321938944","pt":1646314715470,"mc":[{"id":"1.195532852","rc":[{"atb":[[4.8,11.22]],"id":38794071}],"con":true,"img":false}]}
{"op":"mcm","clk":"5321938974","pt":1646314715683,"mc":[{"id":"1.195532852","rc":[{"atb":[[7.8,0]],"id":38794071}],"con":true,"img":false}]}
{"op":"mcm","clk":"5321939000","pt":1646314715894,"mc":[{"id":"1.195532852","rc":[{"atb":[[4.3,0]],"id":36532033},{"atb":[[4.8,6.22]],"id":38794071}],"con":true,"img":false}]}
{"op":"mcm","clk":"5321939014","pt":1646314715997,"mc":[{"id":"1.195532852","rc":[{"atb":[[4.1,2.9]],"id":36532033}],"con":true,"img":false}]}
{"op":"mcm","clk":"5321939108","pt":1646314716794,"mc":[{"id":"1.195532852","rc":[{"atb":[[4.2,3.3]],"id":36532033}],"con":true,"img":false}]}
{"op":"mcm","clk":"5321939247","pt":1646314717992,"mc":[{"id":"1.195532852","rc":[{"atb":[[4.1,1.99]],"id":36532033}],"con":true,"img":false}]}
{"op":"mcm","clk":"5321939257","pt":1646314718097,"mc":[{"id":"1.195532852","rc":[{"atb":[[4.2,4.21]],"id":36532033}],"con":true,"img":false}]}
{"op":"mcm","clk":"5321939435","pt":1646314719868,"mc":[{"id":"1.195532852","rc":[{"atb":[[4,0]],"id":36532033}],"con":true,"img":false}]}
{"op":"mcm","clk":"5321939486","pt":1646314720491,"mc":[{"id":"1.195532852","rc":[{"atb":[[1.01,11004.52]],"id":38794071}],"con":true,"img":false}]}
{"op":"mcm","clk":"5321939507","pt":1646314720698,"mc":[{"id":"1.195532852","rc":[{"atb":[[1.01,11003.68]],"id":38794071}],"con":true,"img":false}]}
{"op":"mcm","clk":"5321939541","pt":1646314720964,"mc":[{"id":"1.195532852","rc":[{"atb":[[1.01,11002]],"id":38794071}],"con":true,"img":false}]}
{"op":"mcm","clk":"5321939554","pt":1646314721074,"mc":[{"id":"1.195532852","rc":[{"atb":[[7.8,1.68]],"id":38794071}],"con":true,"img":false}]}
{"op":"mcm","clk":"5321939584","pt":1646314721400,"mc":[{"id":"1.195532852","rc":[{"atb":[[7.8,0]],"id":38794071}],"con":true,"img":false}]}
{"op":"mcm","clk":"5321939678","pt":1646314722175,"mc":[{"id":"1.195532852","rc":[{"atb":[[4.1,0]],"id":36532033}],"con":true,"img":false}]}
{"op":"mcm","clk":"5321939690","pt":1646314722278,"mc":[{"id":"1.195532852","rc":[{"atb":[[4.3,1.99]],"id":36532033}],"con":true,"img":false}]}
{"op":"mcm","clk":"5321939698","pt":1646314722379,"mc":[{"id":"1.195532852","rc":[{"atb":[[4.2,0.91]],"id":36532033}],"con":true,"img":false}]}
{"op":"mcm","clk":"5321939711","pt":1646314722488,"mc":[{"id":"1.195532852","rc":[{"atb":[[5.6,0]],"id":36182808}],"con":true,"img":false}]}
{"op":"mcm","clk":"5321939723","pt":1646314722593,"mc":[{"id":"1.195532852","rc":[{"atb":[[5.5,1.99]],"id":36182808}],"con":true,"img":false}]}
{"op":"mcm","clk":"5321939855","pt":1646314724006,"mc":[{"id":"1.195532852","rc":[{"atb":[[4,6.32]],"id":36532033}],"con":true,"img":false}]}
{"op":"mcm","clk":"5321939877","pt":1646314724169,"mc":[{"id":"1.195532852","rc":[{"atb":[[5.6,1.65]],"id":36182808}],"con":true,"img":false}]}
{"op":"mcm","clk":"5321939977","pt":1646314725059,"mc":[{"id":"1.195532852","rc":[{"atb":[[1.01,11002]],"id":36532033}],"con":true,"img":false}]}
