{"op":"mcm","clk":"5345985301","pt":1646174444265,"mc":[{"id":"1.195453628","marketDefinition":{"bspMarket":true,"turnInPlayEnabled":false,"persistenceEnabled":false,"marketBaseRate":7.0,"eventId":"31272494","eventTypeId":"4339","numberOfWinners":2,"bettingType":"ODDS","marketType":"PLACE","marketTime":"2022-03-02T11:32:00.000Z","suspendTime":"2022-03-02T11:32:00.000Z","bspReconciled":false,"complete":true,"inPlay":false,"crossMatching":false,"runnersVoidable":false,"numberOfActiveRunners":6,"betDelay":0,"status":"OPEN","runners":[{"status":"ACTIVE","sortPriority":1,"id":39734233,"name":"1. Bernadette"},{"status":"ACTIVE","sortPriority":2,"id":38761677,"name":"2. General Payton"},{"status":"ACTIVE","sortPriority":3,"id":40324291,"name":"4. Reiko Langer"},{"status":"ACTIVE","sortPriority":4,"id":41818958,"name":"6. Armatree Arrow"},{"status":"ACTIVE","sortPriority":5,"id":38214982,"name":"7. Two Phones"},{"status":"ACTIVE","sortPriority":6,"id":27868829,"name":"8. My Gem"}],"regulators":["MR_INT"],"venue":"Traralgon","countryCode":"AU","discountAllowed":true,"timezone":"Australia/Sydney","openDate":"2022-03-02T08:31:00.000Z","version":4382425385,"name":"To Be Placed","eventName":"Traralgon (AUS) 2nd Mar"},"rc":[],"con":true,"img":false}]}
{"op":"mcm","clk":"5346059623","pt":1646175788371,"mc":[{"id":"1.195453628","rc":[{"atb":[[1.8,124.62],[1.7,142.42],[1.75,132.93]],"id":39734233},{"atl":[[3.6,13.94],[5.2,17.26],[4.2,22.66]],"id":39734233},{"spn":2.7,"spf":"NaN","id":39734233},{"atb":[[1.98,101.73],[1.88,113.29],[1.93,107.2]],"id":41818958},{"atl":[[4.9,9.29],[7.8,10.66],[5.9,14.79]],"id":41818958},{"spn":3.44,"spf":"NaN","id":41818958},{"atb":[[2.4,71.21],[2.5,66.46],[2.3,76.69]],"id":38214982},{"atl":[[8,10.35],[10,8.05],[6,7.25]],"id":38214982},{"spn":4.25,"spf":"NaN","id":38214982},{"atb":[[3.45,40.69],[3.2,45.31],[2.98,50.35]],"id":27868829},{"atl":[[18.5,4.14],[13.5,5.8],[9.4,4.31]],"id":27868829},{"spn":6.42,"spf":"NaN","id":27868829},{"atb":[[1.2,498.5],[1.25,398.8],[1.3,332.33]],"id":38761677},{"atl":[[2.54,23.54],[2.74,41.67],[2.94,37.37]],"id":38761677},{"spn":1.92,"spf":"NaN","id":38761677},{"atb":[[2.3,76.69],[2.2,83.08],[2.1,90.63]],"id":40324291},{"atl":[[5.6,7.88],[7.2,11.69],[9.2,8.84]],"id":40324291},{"spn":3.95,"spf":"NaN","id":40324291}],"con":true,"img":false}]}
{"op":"mcm","clk":"5346061998","pt":1646175839944,"mc":[{"id":"1.195453628","rc":[{"atb":[[1.8,0],[1.7,0],[1.75,0]],"id":39734233},{"atl":[[3.6,0],[5.2,0],[4.2,0]],"id":39734233},{"atb":[[1.98,0],[1.88,0],[1.93,0]],"id":41818958},{"atl":[[4.9,0],[7.8,0],[5.9,0]],"id":41818958},{"atb":[[2.4,0],[2.5,0],[2.3,0]],"id":38214982},{"atl":[[8,0],[10,0],[6,0]],"id":38214982},{"atb":[[3.45,0],[3.2,0],[2.98,0]],"id":27868829},{"atl":[[18.5,0],[13.5,0],[9.4,0]],"id":27868829},{"atb":[[1.2,0],[1.25,0],[1.3,0]],"id":38761677},{"atl":[[2.54,0],[2.74,0],[2.94,0]],"id":38761677},{"atb":[[2.3,0],[2.2,0],[2.1,0]],"id":40324291},{"atl":[[5.6,0],[7.2,0],[9.2,0]],"id":40324291}],"con":true,"img":false}]}
{"op":"mcm","clk":"5346062228","pt":1646175844782,"mc":[{"id":"1.195453628","rc":[{"atb":[[1.8,124.62],[1.7,142.42],[1.75,132.93]],"id":39734233},{"atl":[[3.6,13.94],[5.2,17.26],[4.2,22.66]],"id":39734233},{"atb":[[1.98,101.73],[1.88,113.29],[1.93,107.2]],"id":41818958},{"atl":[[4.9,9.29],[7.8,10.66],[5.9,14.79]],"id":41818958},{"atb":[[2.4,71.21],[2.5,66.46],[2.3,76.69]],"id":38214982},{"atl":[[8,10.35],[10,8.05],[6,7.25]],"id":38214982},{"atb":[[3.45,40.69],[3.2,45.31],[2.98,50.35]],"id":27868829},{"atl":[[18.5,4.14],[13.5,5.8],[9.4,4.31]],"id":27868829},{"atb":[[1.2,498.5],[1.25,398.8],[1.3,332.33]],"id":38761677},{"atl":[[2.54,23.54],[2.74,41.67],[2.94,37.37]],"id":38761677},{"atb":[[2.3,76.69],[2.2,83.08],[2.1,90.63]],"id":40324291},{"atl":[[5.6,7.88],[7.2,11.69],[9.2,8.84]],"id":40324291}],"con":true,"img":false}]}
{"op":"mcm","clk":"5346105174","pt":1646176602702,"mc":[{"id":"1.195453628","marketDefinition":{"bspMarket":true,"turnInPlayEnabled":false,"persistenceEnabled":false,"marketBaseRate":7.0,"eventId":"31272494","eventTypeId":"4339","numberOfWinners":2,"bettingType":"ODDS","marketType":"PLACE","marketTime":"2022-03-02T11:32:00.000Z","suspendTime":"2022-03-02T11:32:00.000Z","bspReconciled":false,"complete":true,"inPlay":false,"crossMatching":false,"runnersVoidable":false,"numberOfActiveRunners":6,"betDelay":0,"status":"OPEN","runners":[{"status":"ACTIVE","sortPriority":1,"id":39734233,"name":"1. Bernadette"},{"status":"ACTIVE","sortPriority":2,"id":38761677,"name":"2. General Payton"},{"status":"ACTIVE","sortPriority":3,"id":40324291,"name":"4. Reiko Langer"},{"status":"ACTIVE","sortPriority":4,"id":41818958,"name":"6. Armatree Arrow"},{"status":"ACTIVE","sortPriority":5,"id":38214982,"name":"7. Two Phones"},{"status":"ACTIVE","sortPriority":6,"id":27868829,"name":"8. My Gem"}],"regulators":["MR_INT"],"venue":"Traralgon","countryCode":"AU","discountAllowed":true,"timezone":"Australia/Sydney","openDate":"2022-03-02T08:31:00.000Z","version":4382425385,"name":"To Be Placed","eventName":"Traralgon (AUS) 2nd Mar"},"rc":[{"atb":[[1.8,124.62],[1.7,142.42],[1.75,132.93]],"id":39734233},{"atl":[[3.6,13.94],[5.2,17.26],[4.2,22.66]],"id":39734233},{"spn":2.7,"spf":"NaN","id":39734233},{"atb":[[1.98,101.73],[1.88,113.29],[1.93,107.2]],"id":41818958},{"atl":[[4.9,9.29],[7.8,10.66],[5.9,14.79]],"id":41818958},{"spn":3.44,"spf":"NaN","id":41818958},{"atb":[[2.4,71.21],[2.5,66.46],[2.3,76.69]],"id":38214982},{"atl":[[8,10.35],[10,8.05],[6,7.25]],"id":38214982},{"spn":4.25,"spf":"NaN","id":38214982},{"atb":[[3.45,40.69],[3.2,45.31],[2.98,50.35]],"id":27868829},{"atl":[[18.5,4.14],[13.5,5.8],[9.4,4.31]],"id":27868829},{"spn":6.42,"spf":"NaN","id":27868829},{"atb":[[1.2,498.5],[1.25,398.8],[1.3,332.33]],"id":38761677},{"atl":[[2.54,23.54],[2.74,41.67],[2.94,37.37]],"id":38761677},{"spn":1.92,"spf":"NaN","id":38761677},{"atb":[[2.3,76.69],[2.2,83.08],[2.1,90.63]],"id":40324291},{"atl":[[5.6,7.88],[7.2,11.69],[9.2,8.84]],"id":40324291},{"spn":3.95,"spf":"NaN","id":40324291}],"con":true,"img":true}]}
{"op":"mcm","clk":"5346136707","pt":1646177154868,"mc":[{"id":"1.195453628","rc":[{"atb":[[2.4,0],[2.5,0],[2.3,0]],"id":38214982},{"atl":[[8,0],[10,0],[6,0]],"id":38214982},{"spn":"NaN","spf":"NaN","id":38214982}],"con":true,"img":false}]}
{"op":"mcm","clk":"5346137122","pt":1646177162517,"mc":[{"id":"1.195453628","rc":[{"atb":[[2.3,76.69],[2.2,83.08],[2.1,90.63]],"id":38214982},{"atl":[[5.6,7.88],[7.2,11.69],[9.2,8.84]],"id":38214982}],"con":true,"img":false}]}
{"op":"mcm","clk":"5346316482","pt":1646180692729,"mc":[{"id":"1.195453628","rc":[{"atb":[[1.8,124.64],[1.7,142.44],[1.75,132.94]],"id":39734233},{"atl":[[3.6,13.94],[5.2,17.26],[4.2,22.66]],"id":39734233},{"atb":[[1.98,101.74],[1.88,113.31],[1.93,107.21]],"id":41818958},{"atl":[[4.9,9.29],[7.8,10.66],[5.9,14.79]],"id":41818958},{"atb":[[2.3,0],[2.2,0],[2.1,0]],"id":38214982},{"atl":[[5.6,0],[7.2,0],[9.2,0]],"id":38214982},{"atb":[[3.45,0],[3.2,0],[2.98,0]],"id":27868829},{"atl":[[18.5,0],[13.5,0],[9.4,0]],"id":27868829},{"spn":"NaN","spf":"NaN","id":27868829},{"atb":[[1.2,498.55],[1.25,398.84],[1.3,332.37]],"id":38761677},{"atl":[[2.54,23.54],[2.74,41.67],[2.94,37.38]],"id":38761677},{"atb":[[2.3,0],[2.2,0],[2.1,0]],"id":40324291},{"atl":[[5.6,0],[7.2,0],[9.2,0]],"id":40324291},{"spn":"NaN","spf":"NaN","id":40324291}],"con":true,"img":false}]}
{"op":"mcm","clk":"5346317047","pt":1646180703260,"mc":[{"id":"1.195453628","rc":[{"atb":[[2.06,94.06],[1.98,101.74],[2.16,85.95]],"id":38214982},{"atl":[[6.8,12.5],[8.8,9.29],[5.4,8.24]],"id":38214982},{"atb":[[3.45,40.7],[3.95,33.79],[3.7,36.92]],"id":27868829},{"atl":[[18.5,4.14],[13.5,2.9],[27,2.78]],"id":27868829},{"atb":[[2.8,55.39],[2.6,62.32],[2.7,58.65]],"id":40324291},{"atl":[[7.2,5.84],[9.2,8.84],[13,6.04]],"id":40324291}],"con":true,"img":false}]}
{"op":"mcm","clk":"5346401632","pt":1646182002789,"mc":[{"id":"1.195453628","marketDefinition":{"bspMarket":true,"turnInPlayEnabled":false,"persistenceEnabled":false,"marketBaseRate":7.0,"eventId":"31272494","eventTypeId":"4339","numberOfWinners":2,"bettingType":"ODDS","marketType":"PLACE","marketTime":"2022-03-02T11:32:00.000Z","suspendTime":"2022-03-02T11:32:00.000Z","bspReconciled":false,"complete":true,"inPlay":false,"crossMatching":false,"runnersVoidable":false,"numberOfActiveRunners":6,"betDelay":0,"status":"OPEN","runners":[{"status":"ACTIVE","sortPriority":1,"id":39734233,"name":"1. Bernadette"},{"status":"ACTIVE","sortPriority":2,"id":38761677,"name":"2. General Payton"},{"status":"ACTIVE","sortPriority":3,"id":40324291,"name":"4. Reiko Langer"},{"status":"ACTIVE","sortPriority":4,"id":41818958,"name":"6. Armatree Arrow"},{"status":"ACTIVE","sortPriority":5,"id":38214982,"name":"7. Two Phones"},{"status":"ACTIVE","sortPriority":6,"id":27868829,"name":"8. My Gem"}],"regulators":["MR_INT"],"venue":"Traralgon","countryCode":"AU","discountAllowed":true,"timezone":"Australia/Sydney","openDate":"2022-03-02T08:31:00.000Z","version":4382425385,"name":"To Be Placed","eventName":"Traralgon (AUS) 2nd Mar"},"rc":[{"atb":[[1.8,124.64],[1.7,142.44],[1.75,132.94]],"id":39734233},{"atl":[[3.6,13.94],[5.2,17.26],[4.2,22.66]],"id":39734233},{"spn":2.7,"spf":"NaN","id":39734233},{"atb":[[1.98,101.74],[1.88,113.31],[1.93,107.21]],"id":41818958},{"atl":[[4.9,9.29],[7.8,10.66],[5.9,14.79]],"id":41818958},{"spn":3.44,"spf":"NaN","id":41818958},{"atb":[[2.06,94.06],[1.98,101.74],[2.16,85.95]],"id":38214982},{"atl":[[6.8,12.5],[8.8,9.29],[5.4,8.24]],"id":38214982},{"spn":3.78,"spf":"NaN","id":38214982},{"atb":[[3.45,40.7],[3.95,33.79],[3.7,36.92]],"id":27868829},{"atl":[[18.5,4.14],[13.5,2.9],[27,2.78]],"id":27868829},{"spn":8.72,"spf":"NaN","id":27868829},{"atb":[[1.2,498.55],[1.25,398.84],[1.3,332.37]],"id":38761677},{"atl":[[2.54,23.54],[2.74,41.67],[2.94,37.38]],"id":38761677},{"spn":1.92,"spf":"NaN","id":38761677},{"atb":[[2.8,55.39],[2.6,62.32],[2.7,58.65]],"id":40324291},{"atl":[[7.2,5.84],[9.2,8.84],[13,6.04]],"id":40324291},{"spn":5.0,"spf":"NaN","id":40324291}],"con":true,"img":true}]}
{"op":"mcm","clk":"5346591720","pt":1646184894416,"mc":[{"id":"1.195453628","rc":[{"atb":[[1.8,124.83],[1.7,142.66],[1.75,133.15]],"id":39734233},{"atl":[[3.6,13.97],[5.2,17.29],[4.2,22.7]],"id":39734233},{"atb":[[1.98,101.9],[1.88,113.49],[1.93,107.38]],"id":41818958},{"atl":[[4.9,9.31],[7.8,10.68],[5.9,14.82]],"id":41818958},{"atb":[[2.06,0],[1.98,0],[2.16,0]],"id":38214982},{"atl":[[6.8,0],[8.8,0],[5.4,0]],"id":38214982},{"atb":[[3.45,40.76],[3.95,33.85],[3.7,36.98]],"id":27868829},{"atl":[[18.5,4.14],[13.5,2.9],[27,2.79]],"id":27868829},{"spn":8.72,"spf":"NaN","id":27868829},{"atb":[[1.2,499.34],[1.25,399.47],[1.3,332.89]],"id":38761677},{"atl":[[2.54,23.58],[2.74,41.74],[2.94,37.43]],"id":38761677},{"atb":[[2.8,0],[2.6,0],[2.7,0]],"id":40324291},{"atl":[[7.2,0],[9.2,0],[13,0]],"id":40324291}],"con":true,"img":false}]}
{"op":"mcm","clk":"5346593216","pt":1646184920641,"mc":[{"id":"1.195453628","rc":[{"atb":[[2.06,94.21],[1.98,101.9],[2.16,86.09]],"id":38214982},{"atl":[[6.8,12.52],[8.8,9.31],[5.4,8.25]],"id":38214982},{"atb":[[2.8,55.48],[2.6,62.41],[2.7,58.74]],"id":40324291},{"atl":[[7.2,5.85],[9.2,8.85],[13,6.05]],"id":40324291}],"con":true,"img":false}]}
{"op":"mcm","clk":"5346767986","pt":1646187402734,"mc":[{"id":"1.195453628","marketDefinition":{"bspMarket":true,"turnInPlayEnabled":false,"persistenceEnabled":false,"marketBaseRate":7.0,"eventId":"31272494","eventTypeId":"4339","numberOfWinners":2,"bettingType":"ODDS","marketType":"PLACE","marketTime":"2022-03-02T11:32:00.000Z","suspendTime":"2022-03-02T11:32:00.000Z","bspReconciled":false,"complete":true,"inPlay":false,"crossMatching":false,"runnersVoidable":false,"numberOfActiveRunners":6,"betDelay":0,"status":"OPEN","runners":[{"status":"ACTIVE","sortPriority":1,"id":39734233,"name":"1. Bernadette"},{"status":"ACTIVE","sortPriority":2,"id":38761677,"name":"2. General Payton"},{"status":"ACTIVE","sortPriority":3,"id":40324291,"name":"4. Reiko Langer"},{"status":"ACTIVE","sortPriority":4,"id":41818958,"name":"6. Armatree Arrow"},{"status":"ACTIVE","sortPriority":5,"id":38214982,"name":"7. Two Phones"},{"status":"ACTIVE","sortPriority":6,"id":27868829,"name":"8. My Gem"}],"regulators":["MR_INT"],"venue":"Traralgon","countryCode":"AU","discountAllowed":true,"timezone":"Australia/Sydney","openDate":"2022-03-02T08:31:00.000Z","version":4382425385,"name":"To Be Placed","eventName":"Traralgon (AUS) 2nd Mar"},"rc":[{"atb":[[1.8,124.83],[1.7,142.66],[1.75,133.15]],"id":39734233},{"atl":[[3.6,13.97],[5.2,17.29],[4.2,22.7]],"id":39734233},{"spn":2.7,"spf":"NaN","id":39734233},{"atb":[[1.98,101.9],[1.88,113.49],[1.93,107.38]],"id":41818958},{"atl":[[4.9,9.31],[7.8,10.68],[5.9,14.82]],"id":41818958},{"spn":3.44,"spf":"NaN","id":41818958},{"atb":[[2.06,94.21],[1.98,101.9],[2.16,86.09]],"id":38214982},{"atl":[[6.8,12.52],[8.8,9.31],[5.4,8.25]],"id":38214982},{"spn":3.78,"spf":"NaN","id":38214982},{"atb":[[3.45,40.76],[3.95,33.85],[3.7,36.98]],"id":27868829},{"atl":[[18.5,4.14],[13.5,2.9],[27,2.79]],"id":27868829},{"spn":8.72,"spf":"NaN","id":27868829},{"atb":[[1.2,499.34],[1.25,399.47],[1.3,332.89]],"id":38761677},{"atl":[[2.54,23.58],[2.74,41.74],[2.94,37.43]],"id":38761677},{"spn":1.92,"spf":"NaN","id":38761677},{"atb":[[2.8,55.48],[2.6,62.41],[2.7,58.74]],"id":40324291},{"atl":[[7.2,5.85],[9.2,8.85],[13,6.05]],"id":40324291},{"spn":5.0,"spf":"NaN","id":40324291}],"con":true,"img":true}]}
{"op":"mcm","clk":"5347092537","pt":1646192802713,"mc":[{"id":"1.195453628","marketDefinition":{"bspMarket":true,"turnInPlayEnabled":false,"persistenceEnabled":false,"marketBaseRate":7.0,"eventId":"31272494","eventTypeId":"4339","numberOfWinners":2,"bettingType":"ODDS","marketType":"PLACE","marketTime":"2022-03-02T11:32:00.000Z","suspendTime":"2022-03-02T11:32:00.000Z","bspReconciled":false,"complete":true,"inPlay":false,"crossMatching":false,"runnersVoidable":false,"numberOfActiveRunners":6,"betDelay":0,"status":"OPEN","runners":[{"status":"ACTIVE","sortPriority":1,"id":39734233,"name":"1. Bernadette"},{"status":"ACTIVE","sortPriority":2,"id":38761677,"name":"2. General Payton"},{"status":"ACTIVE","sortPriority":3,"id":40324291,"name":"4. Reiko Langer"},{"status":"ACTIVE","sortPriority":4,"id":41818958,"name":"6. Armatree Arrow"},{"status":"ACTIVE","sortPriority":5,"id":38214982,"name":"7. Two Phones"},{"status":"ACTIVE","sortPriority":6,"id":27868829,"name":"8. My Gem"}],"regulators":["MR_INT"],"venue":"Traralgon","countryCode":"AU","discountAllowed":true,"timezone":"Australia/Sydney","openDate":"2022-03-02T08:31:00.000Z","version":4382425385,"name":"To Be Placed","eventName":"Traralgon (AUS) 2nd Mar"},"rc":[{"atb":[[1.8,125.04],[1.7,142.91],[1.75,133.38]],"id":39734233},{"atl":[[3.6,13.99],[5.2,17.32],[4.2,22.73]],"id":39734233},{"spn":2.7,"spf":"NaN","id":39734233},{"atb":[[1.98,102.08],[1.88,113.68],[1.93,107.57]],"id":41818958},{"atl":[[4.9,9.32],[7.8,10.7],[5.9,14.84]],"id":41818958},{"spn":3.44,"spf":"NaN","id":41818958},{"atb":[[2.06,94.37],[1.98,102.08],[2.16,86.24]],"id":38214982},{"atl":[[6.8,12.54],[8.8,9.32],[5.4,8.26]],"id":38214982},{"spn":3.78,"spf":"NaN","id":38214982},{"atb":[[3.45,40.83],[3.95,33.9],[3.7,37.04]],"id":27868829},{"atl":[[18.5,4.15],[13.5,2.91],[27,2.79]],"id":27868829},{"spn":8.72,"spf":"NaN","id":27868829},{"atb":[[1.2,500.19],[1.25,400.15],[1.3,333.46]],"id":38761677},{"atl":[[2.54,23.62],[2.74,41.81],[2.94,37.5]],"id":38761677},{"spn":1.92,"spf":"NaN","id":38761677},{"atb":[[2.8,55.57],[2.6,62.52],[2.7,58.84]],"id":40324291},{"atl":[[7.2,5.86],[9.2,8.87],[13,6.06]],"id":40324291},{"spn":5.0,"spf":"NaN","id":40324291}],"con":true,"img":true}]}
{"op":"mcm","clk":"5347381393","pt":1646198202731,"mc":[{"id":"1.195453628","marketDefinition":{"bspMarket":true,"turnInPlayEnabled":false,"persistenceEnabled":false,"marketBaseRate":7.0,"eventId":"31272494","eventTypeId":"4339","numberOfWinners":2,"bettingType":"ODDS","marketType":"PLACE","marketTime":"2022-03-02T11:32:00.000Z","suspendTime":"2022-03-02T11:32:00.000Z","bspReconciled":false,"complete":true,"inPlay":false,"crossMatching":false,"runnersVoidable":false,"numberOfActiveRunners":6,"betDelay":0,"status":"OPEN","runners":[{"status":"ACTIVE","sortPriority":1,"id":39734233,"name":"1. Bernadette"},{"status":"ACTIVE","sortPriority":2,"id":38761677,"name":"2. General Payton"},{"status":"ACTIVE","sortPriority":3,"id":40324291,"name":"4. Reiko Langer"},{"status":"ACTIVE","sortPriority":4,"id":41818958,"name":"6. Armatree Arrow"},{"status":"ACTIVE","sortPriority":5,"id":38214982,"name":"7. Two Phones"},{"status":"ACTIVE","sortPriority":6,"id":27868829,"name":"8. My Gem"}],"regulators":["MR_INT"],"venue":"Traralgon","countryCode":"AU","discountAllowed":true,"timezone":"Australia/Sydney","openDate":"2022-03-02T08:31:00.000Z","version":4382425385,"name":"To Be Placed","eventName":"Traralgon (AUS) 2nd Mar"},"rc":[{"atb":[[1.8,125],[1.7,142.85],[1.75,133.33]],"id":39734233},{"atl":[[3.6,13.98],[5.2,17.31],[4.2,22.73]],"id":39734233},{"spn":2.7,"spf":"NaN","id":39734233},{"atb":[[1.98,102.04],[1.88,113.63],[1.93,107.52]],"id":41818958},{"atl":[[4.9,9.32],[7.8,10.69],[5.9,14.84]],"id":41818958},{"spn":3.44,"spf":"NaN","id":41818958},{"atb":[[2.06,94.33],[1.98,102.04],[2.16,86.2]],"id":38214982},{"atl":[[6.8,12.54],[8.8,9.32],[5.4,8.26]],"id":38214982},{"spn":3.78,"spf":"NaN","id":38214982},{"atb":[[3.45,40.81],[3.95,33.89],[3.7,37.03]],"id":27868829},{"atl":[[18.5,4.15],[13.5,2.91],[27,2.79]],"id":27868829},{"spn":8.72,"spf":"NaN","id":27868829},{"atb":[[1.2,500],[1.25,400],[1.3,333.33]],"id":38761677},{"atl":[[2.54,23.61],[2.74,41.79],[2.94,37.48]],"id":38761677},{"spn":1.92,"spf":"NaN","id":38761677},{"atb":[[2.8,55.55],[2.6,62.5],[2.7,58.82]],"id":40324291},{"atl":[[7.2,5.86],[9.2,8.86],[13,6.06]],"id":40324291},{"spn":5.0,"spf":"NaN","id":40324291}],"con":true,"img":true}]}
{"op":"mcm","clk":"5347849090","pt":1646209002735,"mc":[{"id":"1.195453628","marketDefinition":{"bspMarket":true,"turnInPlayEnabled":false,"persistenceEnabled":false,"marketBaseRate":7.0,"eventId":"31272494","eventTypeId":"4339","numberOfWinners":2,"bettingType":"ODDS","marketType":"PLACE","marketTime":"2022-03-02T11:32:00.000Z","suspendTime":"2022-03-02T11:32:00.000Z","bspReconciled":false,"complete":true,"inPlay":false,"crossMatching":false,"runnersVoidable":false,"numberOfActiveRunners":6,"betDelay":0,"status":"OPEN","runners":[{"status":"ACTIVE","sortPriority":1,"id":39734233,"name":"1. Bernadette"},{"status":"ACTIVE","sortPriority":2,"id":38761677,"name":"2. General Payton"},{"status":"ACTIVE","sortPriority":3,"id":40324291,"name":"4. Reiko Langer"},{"status":"ACTIVE","sortPriority":4,"id":41818958,"name":"6. Armatree Arrow"},{"status":"ACTIVE","sortPriority":5,"id":38214982,"name":"7. Two Phones"},{"status":"ACTIVE","sortPriority":6,"id":27868829,"name":"8. My Gem"}],"regulators":["MR_INT"],"venue":"Traralgon","countryCode":"AU","discountAllowed":true,"timezone":"Australia/Sydney","openDate":"2022-03-02T08:31:00.000Z","version":4382425385,"name":"To Be Placed","eventName":"Traralgon (AUS) 2nd Mar"},"rc":[{"atb":[[1.8,124.96],[1.7,142.81],[1.75,133.29]],"id":39734233},{"atl":[[3.6,13.98],[5.2,17.3],[4.2,22.72]],"id":39734233},{"spn":2.7,"spf":"NaN","id":39734233},{"atb":[[1.98,102.01],[1.88,113.6],[1.93,107.5]],"id":41818958},{"atl":[[4.9,9.32],[7.8,10.69],[5.9,14.83]],"id":41818958},{"spn":3.44,"spf":"NaN","id":41818958},{"atb":[[2.06,94.31],[1.98,102.01],[2.16,86.18]],"id":38214982},{"atl":[[6.8,12.53],[8.8,9.32],[5.4,8.26]],"id":38214982},{"spn":3.78,"spf":"NaN","id":38214982},{"atb":[[3.45,40.8],[3.95,33.88],[3.7,37.02]],"id":27868829},{"atl":[[18.5,4.15],[13.5,2.9],[27,2.79]],"id":27868829},{"spn":8.72,"spf":"NaN","id":27868829},{"atb":[[1.2,499.86],[1.25,399.89],[1.3,333.24]],"id":38761677},{"atl":[[2.54,23.6],[2.74,41.78],[2.94,37.47]],"id":38761677},{"spn":1.92,"spf":"NaN","id":38761677},{"atb":[[2.8,55.54],[2.6,62.48],[2.7,58.81]],"id":40324291},{"atl":[[7.2,5.86],[9.2,8.86],[13,6.05]],"id":40324291},{"spn":5.0,"spf":"NaN","id":40324291}],"con":true,"img":true}]}
{"op":"mcm","clk":"5348049363","pt":1646213092428,"mc":[{"id":"1.195453628","rc":[{"atb":[[1.8,0],[1.7,0],[1.75,0]],"id":39734233},{"atl":[[3.6,0],[5.2,0],[4.2,0]],"id":39734233},{"spn":"NaN","spf":"NaN","id":39734233},{"atb":[[1.98,101.85],[1.88,113.42],[1.93,107.33]],"id":41818958},{"atl":[[4.9,9.3],[7.8,10.67],[5.9,14.81]],"id":41818958},{"atb":[[2.06,0],[1.98,0],[2.16,0]],"id":38214982},{"atl":[[6.8,0],[8.8,0],[5.4,0]],"id":38214982},{"atb":[[3.45,40.74],[3.95,33.83],[3.7,36.96]],"id":27868829},{"atl":[[18.5,4.14],[13.5,2.9],[27,2.79]],"id":27868829},{"atb":[[1.2,0],[1.25,0],[1.3,0]],"id":38761677},{"atl":[[2.54,0],[2.74,0],[2.94,0]],"id":38761677},{"spn":"NaN","spf":"NaN","id":38761677},{"atb":[[2.8,0],[2.6,0],[2.7,0]],"id":40324291},{"atl":[[7.2,0],[9.2,0],[13,0]],"id":40324291}],"con":true,"img":false}]}
{"op":"mcm","clk":"5348049914","pt":1646213102040,"mc":[{"id":"1.195453628","rc":[{"atb":[[1.98,101.85],[1.88,113.42],[1.93,107.33]],"id":39734233},{"atl":[[4.9,9.3],[7.8,10.67],[5.9,14.81]],"id":39734233},{"atb":[[2.06,94.16],[1.98,101.85],[2.16,86.04]],"id":38214982},{"atl":[[6.8,12.51],[8.8,9.3],[5.4,8.25]],"id":38214982},{"atb":[[1.2,499.07],[1.25,399.25],[1.3,332.71]],"id":38761677},{"atl":[[2.54,23.57],[2.74,41.71],[2.94,37.41]],"id":38761677},{"atb":[[2.3,76.77],[2.2,83.18],[2.1,90.74]],"id":40324291},{"atl":[[5.6,7.89],[7.2,11.7],[9.2,8.85]],"id":40324291}],"con":true,"img":false}]}
{"op":"mcm","clk":"5348133273","pt":1646214402746,"mc":[{"id":"1.195453628","marketDefinition":{"bspMarket":true,"turnInPlayEnabled":false,"persistenceEnabled":false,"marketBaseRate":7.0,"eventId":"31272494","eventTypeId":"4339","numberOfWinners":2,"bettingType":"ODDS","marketType":"PLACE","marketTime":"2022-03-02T11:32:00.000Z","suspendTime":"2022-03-02T11:32:00.000Z","bspReconciled":false,"complete":true,"inPlay":false,"crossMatching":false,"runnersVoidable":false,"numberOfActiveRunners":6,"betDelay":0,"status":"OPEN","runners":[{"status":"ACTIVE","sortPriority":1,"id":39734233,"name":"1. Bernadette"},{"status":"ACTIVE","sortPriority":2,"id":38761677,"name":"2. General Payton"},{"status":"ACTIVE","sortPriority":3,"id":40324291,"name":"4. Reiko Langer"},{"status":"ACTIVE","sortPriority":4,"id":41818958,"name":"6. Armatree Arrow"},{"status":"ACTIVE","sortPriority":5,"id":38214982,"name":"7. Two Phones"},{"status":"ACTIVE","sortPriority":6,"id":27868829,"name":"8. My Gem"}],"regulators":["MR_INT"],"venue":"Traralgon","countryCode":"AU","discountAllowed":true,"timezone":"Australia/Sydney","openDate":"2022-03-02T08:31:00.000Z","version":4382425385,"name":"To Be Placed","eventName":"Traralgon (AUS) 2nd Mar"},"rc":[{"atb":[[1.98,101.85],[1.88,113.42],[1.93,107.33]],"id":39734233},{"atl":[[4.9,9.3],[7.8,10.67],[5.9,14.81]],"id":39734233},{"spn":3.44,"spf":"NaN","id":39734233},{"atb":[[1.98,101.85],[1.88,113.42],[1.93,107.33]],"id":41818958},{"atl":[[4.9,9.3],[7.8,10.67],[5.9,14.81]],"id":41818958},{"spn":3.44,"spf":"NaN","id":41818958},{"atb":[[2.06,94.16],[1.98,101.85],[2.16,86.04]],"id":38214982},{"atl":[[6.8,12.51],[8.8,9.3],[5.4,8.25]],"id":38214982},{"spn":3.78,"spf":"NaN","id":38214982},{"atb":[[3.45,40.74],[3.95,33.83],[3.7,36.96]],"id":27868829},{"atl":[[18.5,4.14],[13.5,2.9],[27,2.79]],"id":27868829},{"spn":8.72,"spf":"NaN","id":27868829},{"atb":[[1.2,499.07],[1.25,399.25],[1.3,332.71]],"id":38761677},{"atl":[[2.54,23.57],[2.74,41.71],[2.94,37.41]],"id":38761677},{"spn":1.92,"spf":"NaN","id":38761677},{"atb":[[2.3,76.77],[2.2,83.18],[2.1,90.74]],"id":40324291},{"atl":[[5.6,7.89],[7.2,11.7],[9.2,8.85]],"id":40324291},{"spn":3.95,"spf":"NaN","id":40324291}],"con":true,"img":true}]}
{"op":"mcm","clk":"5348342101","pt":1646216662689,"mc":[{"id":"1.195453628","rc":[{"atb":[[1.99,44.04],[1.67,94.82]],"id":39734233},{"atl":[[5.8,13.07],[5.7,9.08]],"id":39734233},{"spn":3.44,"spf":"NaN","id":39734233},{"atb":[[1.99,44.04],[1.89,65.21]],"id":41818958},{"atl":[[5.8,9.08],[7,8.79]],"id":41818958},{"spn":3.44,"spf":"NaN","id":41818958},{"atb":[[2.3,33.53],[2.08,58.85]],"id":38214982},{"atl":[[8.6,8.17],[8.4,5.89]],"id":38214982},{"spn":3.85,"spf":"NaN","id":38214982},{"atb":[[4.1,14.06],[3.75,21.1]],"id":27868829},{"atl":[[20,2.72],[22,2.76]],"id":27868829},{"spn":8.8,"spf":"NaN","id":27868829},{"atb":[[1.37,117.83],[1.31,172.28]],"id":38761677},{"atl":[[2.72,25.34],[3.5,21.36]],"id":38761677},{"spn":1.95,"spf":"NaN","id":38761677},{"atb":[[1.92,67.38],[2.32,33.03]],"id":40324291},{"atl":[[7.4,6.81],[7,10.33]],"id":40324291},{"spn":3.96,"spf":"NaN","id":40324291}],"con":true,"img":false}]}
{"op":"mcm","clk":"5348342116","pt":1646216662902,"mc":[{"id":"1.195453628","rc":[{"atl":[[7,0]],"id":41818958},{"atb":[[2.08,0]],"id":38214982},{"atl":[[20,0],[22,0]],"id":27868829},{"atl":[[9,7.74],[7.4,0],[7,0]],"id":40324291}],"con":true,"img":false}]}
{"op":"mcm","clk":"5348342122","pt":1646216663007,"mc":[{"id":"1.195453628","rc":[{"atl":[[7.6,8.79]],"id":41818958},{"atb":[[1.99,58.85]],"id":38214982},{"atl":[[25,2.72],[27,5.55]],"id":27868829},{"atl":[[8.6,6.81]],"id":40324291}],"con":true,"img":false}]}
{"op":"mcm","clk":"5348342401","pt":1646216666003,"mc":[{"id":"1.195453628","rc":[{"atb":[[1.99,0],[1.7,91.01]],"id":38214982}],"con":true,"img":false}]}
{"op":"mcm","clk":"5348343534","pt":1646216676921,"mc":[{"id":"1.195453628","rc":[{"atb":[[2.3,0],[1.88,49.54]],"id":38214982},{"atb":[[1.37,0]],"id":38761677}],"con":true,"img":false}]}
{"op":"mcm","clk":"5348343544","pt":1646216677028,"mc":[{"id":"1.195453628","rc":[{"atb":[[1.32,117.83]],"id":38761677}],"con":true,"img":false}]}
{"op":"mcm","clk":"5348345545","pt":1646216697541,"mc":[{"id":"1.195453628","rc":[{"atb":[[4.1,0]],"id":27868829},{"atl":[[2.72,0]],"id":38761677}],"con":true,"img":false}]}
{"op":"mcm","clk":"5348345556","pt":1646216697641,"mc":[{"id":"1.195453628","rc":[{"atb":[[4.5,14.06]],"id":27868829},{"atl":[[2.52,25.34]],"id":38761677}],"con":true,"img":false}]}
{"op":"mcm","clk":"5348345922","pt":1646216701768,"mc":[{"id":"1.195453628","rc":[{"atl":[[8.4,0]],"id":38214982},{"atl":[[8.6,0]],"id":40324291}],"con":true,"img":false}]}
{"op":"mcm","clk":"5348345934","pt":1646216701873,"mc":[{"id":"1.195453628","rc":[{"atl":[[6.6,5.89]],"id":38214982},{"atl":[[7,6.81]],"id":40324291}],"con":true,"img":false}]}
{"op":"mcm","clk":"5348347526","pt":1646216719470,"mc":[{"id":"1.195453628","rc":[{"atb":[[1.88,0]],"id":38214982}],"con":true,"img":false}]}
{"op":"mcm","clk":"5348347532","pt":1646216719573,"mc":[{"id":"1.195453628","rc":[{"atb":[[2.08,49.54]],"id":38214982}],"con":true,"img":false}]}
{"op":"mcm","clk":"5348347995","pt":1646216725195,"mc":[{"id":"1.195453628","rc":[{"atb":[[1.89,0]],"id":41818958},{"spn":3.78,"spf":"NaN","id":38214982},{"atb":[[3.75,0]],"id":27868829},{"atl":[[27,2.79]],"id":27868829},{"spn":9.0,"spf":"NaN","id":27868829},{"spn":1.92,"spf":"NaN","id":38761677}],"con":true,"img":false}]}
{"op":"mcm","clk":"5348348002","pt":1646216725308,"mc":[{"id":"1.195453628","rc":[{"atb":[[1.94,65.21]],"id":41818958},{"atb":[[4,21.1]],"id":27868829},{"atl":[[26,2.76]],"id":27868829}],"con":true,"img":false}]}
{"op":"mcm","clk":"5348348493","pt":1646216731095,"mc":[{"id":"1.195453628","rc":[{"atb":[[1.92,0]],"id":40324291}],"con":true,"img":false}]}
{"op":"mcm","clk":"5348348501","pt":1646216731200,"mc":[{"id":"1.195453628","rc":[{"atb":[[2.12,55.34]],"id":40324291}],"con":true,"img":false}]}
{"op":"mcm","clk":"5348348785","pt":1646216734125,"mc":[{"id":"1.195453628","rc":[{"atl":[[7,0]],"id":40324291}],"con":true,"img":false}]}
{"op":"mcm","clk":"5348348790","pt":1646216734236,"mc":[{"id":"1.195453628","rc":[{"atl":[[8.4,6.81]],"id":40324291}],"con":true,"img":false}]}
{"op":"mcm","clk":"5348350039","pt":1646216747660,"mc":[{"id":"1.195453628","rc":[{"atb":[[1.7,0]],"id":38214982}],"con":true,"img":false}]}
{"op":"mcm","clk":"5348350043","pt":1646216747754,"mc":[{"id":"1.195453628","rc":[{"atb":[[1.8,91.01]],"id":38214982}],"con":true,"img":false}]}
{"op":"mcm","clk":"5348351333","pt":1646216762044,"mc":[{"id":"1.195453628","rc":[{"atb":[[4.5,0]],"id":27868829}],"con":true,"img":false}]}
{"op":"mcm","clk":"5348351346","pt":1646216762149,"mc":[{"id":"1.195453628","rc":[{"atb":[[4.6,14.06]],"id":27868829}],"con":true,"img":false}]}
{"op":"mcm","clk":"5348357806","pt":1646216828442,"mc":[{"id":"1.195453628","rc":[{"spn":9.05,"spf":"NaN","id":27868829},{"atl":[[8.4,0]],"id":40324291}],"con":true,"img":false}]}
{"op":"mcm","clk":"5348357815","pt":1646216828592,"mc":[{"id":"1.195453628","rc":[{"atl":[[7,6.81]],"id":40324291}],"con":true,"img":false}]}
{"op":"mcm","clk":"5348384288","pt":1646217120928,"mc":[{"id":"1.195453628","rc":[{"atb":[[1.71,140.85]],"id":39734233},{"atl":[[4.8,9.31]],"id":39734233},{"spn":3.39,"spf":"NaN","id":39734233},{"atb":[[1.88,227.06]],"id":41818958},{"atl":[[4.8,9.31]],"id":41818958},{"spn":3.39,"spf":"NaN","id":41818958},{"atl":[[38,2.7]],"id":27868829},{"atb":[[1.23,434.78]],"id":38761677},{"atl":[[6.4,18.52]],"id":38761677},{"atb":[[2.2,166.51]],"id":40324291},{"atl":[[7.6,15.15]],"id":40324291}],"con":true,"img":false}]}
{"op":"mcm","clk":"5348384307","pt":1646217121136,"mc":[{"id":"1.195453628","rc":[{"atb":[[2.18,84.75]],"id":38214982},{"atl":[[7.6,15.15]],"id":38214982}],"con":true,"img":false}]}
{"op":"mcm","clk":"5348386049","pt":1646217141153,"mc":[{"id":"1.195453628","rc":[{"atb":[[1.99,0],[1.67,0]],"id":39734233},{"atl":[[5.8,0],[5.7,0]],"id":39734233},{"atb":[[1.99,0],[1.94,0]],"id":41818958},{"atl":[[5.8,0],[7.6,0]],"id":41818958},{"atb":[[1.8,0],[2.08,0]],"id":38214982},{"atl":[[8.6,0],[6.6,0]],"id":38214982},{"atb":[[4,0],[4.6,0]],"id":27868829},{"atl":[[25,0],[26,0]],"id":27868829},{"atb":[[1.32,0],[1.31,0]],"id":38761677},{"atl":[[2.52,0],[3.5,0]],"id":38761677},{"atb":[[2.32,0],[2.12,0]],"id":40324291},{"atl":[[9,0],[7,0]],"id":40324291}],"con":true,"img":false}]}
{"op":"mcm","clk":"5348388420","pt":1646217168975,"mc":[{"id":"1.195453628","rc":[{"atb":[[1.73,60.55],[1.72,87.74]],"id":39734233},{"atl":[[5.8,13.07],[5.7,9.27]],"id":39734233},{"atb":[[1.99,44.04],[1.89,65.21]],"id":41818958},{"atl":[[5.8,9.08],[7.6,8.79]],"id":41818958},{"atb":[[1.8,79.56],[2.08,40.36]],"id":38214982},{"atl":[[7.4,9.8],[6.6,7.78]],"id":38214982},{"atb":[[4,21.1],[4.6,12.1]],"id":27868829},{"atl":[[25,2.72],[26,2.72]],"id":27868829},{"atb":[[1.32,140.63],[1.31,172.28]],"id":38761677},{"atl":[[2.72,25.34],[3.4,22.25]],"id":38761677},{"atb":[[2.32,33.03],[1.94,65.94]],"id":40324291},{"atl":[[9,7.74],[7,7.26]],"id":40324291}],"con":true,"img":false}]}
{"op":"mcm","clk":"5348393400","pt":1646217224962,"mc":[{"id":"1.195453628","rc":[{"atb":[[1.73,0]],"id":39734233},{"spn":3.39,"spf":"NaN","id":39734233},{"atb":[[1.89,0]],"id":41818958},{"spn":3.79,"spf":"NaN","id":38214982},{"atl":[[2.72,0]],"id":38761677},{"spn":1.93,"spf":"NaN","id":38761677}],"con":true,"img":false}]}
{"op":"mcm","clk":"5348393413","pt":1646217225030,"mc":[{"id":"1.195453628","rc":[{"atb":[[1.75,60.55]],"id":39734233},{"atb":[[1.94,65.21]],"id":41818958},{"atl":[[2.52,25.34]],"id":38761677}],"con":true,"img":false}]}
{"op":"mcm","clk":"5348394592","pt":1646217238072,"mc":[{"id":"1.195453628","rc":[{"atb":[[1.94,0]],"id":40324291}],"con":true,"img":false}]}
{"op":"mcm","clk":"5348394601","pt":1646217238125,"mc":[{"id":"1.195453628","rc":[{"atb":[[2.12,65.94]],"id":40324291}],"con":true,"img":false}]}
{"op":"mcm","clk":"5348399658","pt":1646217292944,"mc":[{"id":"1.195453628","rc":[{"atb":[[1.75,0]],"id":39734233},{"spn":1.92,"spf":"NaN","id":38761677}],"con":true,"img":false}]}
{"op":"mcm","clk":"5348399667","pt":1646217293060,"mc":[{"id":"1.195453628","rc":[{"atb":[[1.89,60.55]],"id":39734233}],"con":true,"img":false}]}
{"op":"mcm","clk":"5348402160","pt":1646217319203,"mc":[{"id":"1.195453628","rc":[{"atb":[[1.72,0],[1.53,119.35]],"id":39734233}],"con":true,"img":false}]}
{"op":"mcm","clk":"5348402665","pt":1646217324570,"mc":[{"id":"1.195453628","rc":[{"atb":[[1.89,0]],"id":39734233}],"con":true,"img":false}]}
{"op":"mcm","clk":"5348402680","pt":1646217324668,"mc":[{"id":"1.195453628","rc":[{"atb":[[1.72,60.55]],"id":39734233}],"con":true,"img":false}]}
{"op":"mcm","clk":"5348404561","pt":1646217343997,"mc":[{"id":"1.195453628","rc":[{"atb":[[4.6,0]],"id":27868829}],"con":true,"img":false}]}
{"op":"mcm","clk":"5348404571","pt":1646217344105,"mc":[{"id":"1.195453628","rc":[{"atb":[[4.7,12.1]],"id":27868829}],"con":true,"img":false}]}
{"op":"mcm","clk":"5348406954","pt":1646217370049,"mc":[{"id":"1.195453628","rc":[{"spn":9.1,"spf":"NaN","id":27868829},{"atl":[[2.92,27.81]],"id":38761677}],"con":true,"img":false}]}
{"op":"mcm","clk":"5348406962","pt":1646217370159,"mc":[{"id":"1.195453628","rc":[{"atl":[[3.4,0]],"id":38761677}],"con":true,"img":false}]}
{"op":"mcm","clk":"5348412965","pt":1646217436149,"mc":[{"id":"1.195453628","rc":[{"atb":[[1.6,166.67],[1.88,113.42]],"id":41818958},{"atl":[[4.8,0],[5.7,18.62]],"id":41818958},{"spn":3.44,"spf":"NaN","id":41818958},{"atl":[[6.8,28.55],[7.6,0]],"id":38214982},{"atl":[[38,0],[27,6.64]],"id":27868829},{"atb":[[1.16,625],[1.23,0]],"id":38761677},{"atb":[[2.2,83.18],[2.14,87.72]],"id":40324291},{"atl":[[7.6,0],[6.6,15.78]],"id":40324291}],"con":true,"img":false}]}
{"op":"mcm","clk":"5348412983","pt":1646217436357,"mc":[{"id":"1.195453628","rc":[{"atb":[[2.32,108.79],[2.14,0]],"id":40324291},{"atl":[[6.4,15.78],[6.6,0]],"id":40324291}],"con":true,"img":false}]}
{"op":"mcm","clk":"5348413152","pt":1646217438251,"mc":[{"id":"1.195453628","rc":[{"atl":[[7.4,0]],"id":38214982}],"con":true,"img":false}]}
{"op":"mcm","clk":"5348413163","pt":1646217438349,"mc":[{"id":"1.195453628","rc":[{"atl":[[8.6,9.8]],"id":38214982}],"con":true,"img":false}]}
{"op":"mcm","clk":"5348413467","pt":1646217441860,"mc":[{"id":"1.195453628","rc":[{"atl":[[5.8,0],[9.4,7.62]],"id":39734233},{"atb":[[1.94,0],[1.71,81.74]],"id":41818958},{"atb":[[4,0]],"id":27868829},{"atl":[[2.92,0],[3.55,20.94]],"id":38761677},{"atb":[[2.12,0]],"id":40324291}],"con":true,"img":false}]}
{"op":"mcm","clk":"5348413480","pt":1646217441963,"mc":[{"id":"1.195453628","rc":[{"atb":[[3.5,21.1]],"id":27868829},{"atb":[[1.83,65.94]],"id":40324291}],"con":true,"img":false}]}
{"op":"mcm","clk":"5348413804","pt":1646217445428,"mc":[{"id":"1.195453628","rc":[{"atb":[[3.2,26.38],[3.5,0]],"id":27868829},{"atl":[[2.52,0]],"id":38761677}],"con":true,"img":false}]}
{"op":"mcm","clk":"5348413814","pt":1646217445529,"mc":[{"id":"1.195453628","rc":[{"atl":[[2.72,25.34]],"id":38761677}],"con":true,"img":false}]}
{"op":"mcm","clk":"5348414124","pt":1646217449166,"mc":[{"id":"1.195453628","rc":[{"atl":[[5.7,0]],"id":39734233},{"atb":[[4.7,0]],"id":27868829}],"con":true,"img":false}]}
{"op":"mcm","clk":"5348414135","pt":1646217449239,"mc":[{"id":"1.195453628","rc":[{"atl":[[5.8,9.27]],"id":39734233},{"atb":[[4,12.1]],"id":27868829}],"con":true,"img":false}]}
{"op":"mcm","clk":"5348416112","pt":1646217470204,"mc":[{"id":"1.195453628","rc":[{"atb":[[1.6,0]],"id":41818958},{"atl":[[5.8,0]],"id":41818958},{"atl":[[6.2,16.5],[6.8,12.51]],"id":38214982},{"atl":[[25,0]],"id":27868829},{"atb":[[1.16,0],[1.32,0],[1.22,454.55]],"id":38761677},{"atl":[[7,0]],"id":40324291}],"con":true,"img":false}]}
{"op":"mcm","clk":"5348416121","pt":1646217470263,"mc":[{"id":"1.195453628","rc":[{"atb":[[1.82,121.95]],"id":41818958},{"atl":[[5.6,9.08],[5.1,18.62],[5.7,0]],"id":41818958},{"atl":[[19,2.72]],"id":27868829},{"atb":[[1.34,140.63]],"id":38761677},{"atl":[[6.2,7.26]],"id":40324291}],"con":true,"img":false}]}
{"op":"mcm","clk":"5348418592","pt":1646217496102,"mc":[{"id":"1.195453628","rc":[{"atl":[[8.6,0]],"id":38214982},{"atl":[[18,3.41],[26,0]],"id":27868829}],"con":true,"img":false}]}
{"op":"mcm","clk":"5348418604","pt":1646217496261,"mc":[{"id":"1.195453628","rc":[{"atl":[[6.6,17.59]],"id":38214982},{"spn":8.75,"spf":"NaN","id":27868829},{"spn":1.94,"spf":"NaN","id":38761677}],"con":true,"img":false}]}
{"op":"mcm","clk":"5348419844","pt":1646217508256,"mc":[{"id":"1.195453628","rc":[{"atl":[[5.6,0]],"id":41818958},{"atl":[[6.6,9.8]],"id":38214982}],"con":true,"img":false}]}
{"op":"mcm","clk":"5348419853","pt":1646217508361,"mc":[{"id":"1.195453628","rc":[{"atl":[[5,9.08]],"id":41818958},{"atl":[[6,7.78]],"id":38214982}],"con":true,"img":false}]}
{"op":"mcm","clk":"5348420457","pt":1646217514046,"mc":[{"id":"1.195453628","rc":[{"atb":[[3.2,0]],"id":27868829}],"con":true,"img":false}]}
{"op":"mcm","clk":"5348420468","pt":1646217514150,"mc":[{"id":"1.195453628","rc":[{"atb":[[3.5,26.38]],"id":27868829}],"con":true,"img":false}]}
{"op":"mcm","clk":"5348421650","pt":1646217526145,"mc":[{"id":"1.195453628","rc":[{"atb":[[1.71,0]],"id":41818958}],"con":true,"img":false}]}
{"op":"mcm","clk":"5348421659","pt":1646217526249,"mc":[{"id":"1.195453628","rc":[{"atb":[[1.83,81.74]],"id":41818958}],"con":true,"img":false}]}
{"op":"mcm","clk":"5348422988","pt":1646217542781,"mc":[{"id":"1.195453628","rc":[{"atl":[[2.72,0]],"id":38761677}],"con":true,"img":false}]}
{"op":"mcm","clk":"5348423000","pt":1646217542886,"mc":[{"id":"1.195453628","rc":[{"atl":[[2.52,25.34]],"id":38761677}],"con":true,"img":false}]}
{"op":"mcm","clk":"5348424121","pt":1646217556094,"mc":[{"id":"1.195453628","rc":[{"atb":[[1.82,0],[1.7,142.86]],"id":41818958},{"atl":[[5.1,0],[5.4,18.62]],"id":41818958},{"atb":[[2.32,33.03],[2.22,81.97]],"id":40324291}],"con":true,"img":false}]}
{"op":"mcm","clk":"5348424339","pt":1646217559129,"mc":[{"id":"1.195453628","rc":[{"atb":[[1.83,0]],"id":41818958},{"spn":1.93,"spf":"NaN","id":38761677}],"con":true,"img":false}]}
{"op":"mcm","clk":"5348424348","pt":1646217559185,"mc":[{"id":"1.195453628","rc":[{"atb":[[1.71,81.74]],"id":41818958}],"con":true,"img":false}]}
{"op":"mcm","clk":"5348425149","pt":1646217568942,"mc":[{"id":"1.195453628","rc":[{"atl":[[5,0]],"id":41818958}],"con":true,"img":false}]}
{"op":"mcm","clk":"5348425156","pt":1646217568998,"mc":[{"id":"1.195453628","rc":[{"atl":[[5.3,9.08]],"id":41818958}],"con":true,"img":false}]}
{"op":"mcm","clk":"5348428568","pt":1646217607974,"mc":[{"id":"1.195453628","rc":[{"atl":[[9,0],[7,10.33]],"id":40324291}],"con":true,"img":false}]}
{"op":"mcm","clk":"5348437240","pt":1646217697210,"mc":[{"id":"1.195453628","rc":[{"atb":[[1.72,0]],"id":39734233}],"con":true,"img":false}]}
{"op":"mcm","clk":"5348437245","pt":1646217697311,"mc":[{"id":"1.195453628","rc":[{"atb":[[1.99,60.55]],"id":39734233}],"con":true,"img":false}]}
{"op":"mcm","clk":"5348439802","pt":1646217723632,"mc":[{"id":"1.195453628","rc":[{"atb":[[1.72,87.74],[1.53,0]],"id":39734233}],"con":true,"img":false}]}
{"op":"mcm","clk":"5348441508","pt":1646217739163,"mc":[{"id":"1.195453628","rc":[{"atb":[[1.72,0],[1.53,119.35]],"id":39734233},{"atl":[[9,5.44],[5.8,0]],"id":39734233}],"con":true,"img":false}]}
{"op":"mcm","clk":"5348442764","pt":1646217751227,"mc":[{"id":"1.195453628","rc":[{"atb":[[1.99,0]],"id":39734233}],"con":true,"img":false}]}
{"op":"mcm","clk":"5348442772","pt":1646217751280,"mc":[{"id":"1.195453628","rc":[{"atb":[[1.72,60.55]],"id":39734233}],"con":true,"img":false}]}
{"op":"mcm","clk":"5348449201","pt":1646217814204,"mc":[{"id":"1.195453628","rc":[{"atb":[[1.72,0]],"id":39734233}],"con":true,"img":false}]}
{"op":"mcm","clk":"5348449215","pt":1646217814302,"mc":[{"id":"1.195453628","rc":[{"atb":[[1.75,60.55]],"id":39734233}],"con":true,"img":false}]}
{"op":"mcm","clk":"5348449536","pt":1646217817484,"mc":[{"id":"1.195453628","rc":[{"atb":[[1.7,0],[1.87,114.94]],"id":41818958},{"atl":[[4.8,9.31],[5.4,0]],"id":41818958},{"atl":[[22,4.76],[27,2.79]],"id":27868829},{"atb":[[2.22,0],[2.34,74.63]],"id":40324291}],"con":true,"img":false}]}
{"op":"mcm","clk":"5348450898","pt":1646217829723,"mc":[{"id":"1.195453628","rc":[{"atl":[[9,0],[5.8,9.08]],"id":39734233}],"con":true,"img":false}]}
{"op":"mcm","clk":"5348450912","pt":1646217829827,"mc":[{"id":"1.195453628","rc":[{"atl":[[5.3,0]],"id":41818958}],"con":true,"img":false}]}
{"op":"mcm","clk":"5348450925","pt":1646217829932,"mc":[{"id":"1.195453628","rc":[{"atl":[[5.8,9.08]],"id":41818958}],"con":true,"img":false}]}
{"op":"mcm","clk":"5348452152","pt":1646217840755,"mc":[{"id":"1.195453628","rc":[{"atb":[[1.72,87.74],[1.53,0]],"id":39734233}],"con":true,"img":false}]}
{"op":"mcm","clk":"5348452502","pt":1646217844120,"mc":[{"id":"1.195453628","rc":[{"atb":[[1.54,117.17]],"id":39734233}],"con":true,"img":false}]}
{"op":"mcm","clk":"5348452509","pt":1646217844226,"mc":[{"id":"1.195453628","rc":[{"atb":[[1.72,0]],"id":39734233}],"con":true,"img":false}]}
{"op":"mcm","clk":"5348452758","pt":1646217846336,"mc":[{"id":"1.195453628","rc":[{"atl":[[19,0]],"id":27868829},{"atb":[[2.32,0]],"id":40324291}],"con":true,"img":false}]}
{"op":"mcm","clk":"5348452767","pt":1646217846442,"mc":[{"id":"1.195453628","rc":[{"atl":[[18,6.13]],"id":27868829},{"atb":[[2.36,33.03]],"id":40324291}],"con":true,"img":false}]}
{"op":"mcm","clk":"5348452780","pt":1646217846546,"mc":[{"id":"1.195453628","rc":[{"atb":[[2.32,75.76],[2.34,0]],"id":40324291}],"con":true,"img":false}]}
{"op":"mcm","clk":"5348453671","pt":1646217854880,"mc":[{"id":"1.195453628","rc":[{"atb":[[1.9,111.11]],"id":41818958},{"atl":[[4.8,0],[4.9,27.92]],"id":41818958}],"con":true,"img":false}]}
{"op":"mcm","clk":"5348453682","pt":1646217854989,"mc":[{"id":"1.195453628","rc":[{"atb":[[1.87,0]],"id":41818958}],"con":true,"img":false}]}
{"op":"mcm","clk":"5348453693","pt":1646217855037,"mc":[{"id":"1.195453628","rc":[{"atl":[[4.9,9.3],[5.7,18.62]],"id":41818958}],"con":true,"img":false}]}
{"op":"mcm","clk":"5348453915","pt":1646217857171,"mc":[{"id":"1.195453628","rc":[{"atb":[[1.75,0]],"id":39734233},{"atb":[[2.36,0]],"id":40324291},{"atl":[[7,0]],"id":40324291}],"con":true,"img":false}]}
{"op":"mcm","clk":"5348453927","pt":1646217857285,"mc":[{"id":"1.195453628","rc":[{"atb":[[1.72,60.55]],"id":39734233},{"atb":[[2.34,33.03]],"id":40324291},{"atl":[[8.4,7.74]],"id":40324291}],"con":true,"img":false}]}
{"op":"mcm","clk":"5348453947","pt":1646217857490,"mc":[{"id":"1.195453628","rc":[{"atb":[[3.5,0]],"id":27868829}],"con":true,"img":false}]}
{"op":"mcm","clk":"5348453956","pt":1646217857547,"mc":[{"id":"1.195453628","rc":[{"atb":[[3.1,26.38]],"id":27868829}],"con":true,"img":false}]}
{"op":"mcm","clk":"5348456045","pt":1646217876366,"mc":[{"id":"1.195453628","rc":[{"atb":[[2.36,73.53]],"id":40324291},{"spn":3.98,"spf":"NaN","id":40324291}],"con":true,"img":false}]}
{"op":"mcm","clk":"5348456055","pt":1646217876466,"mc":[{"id":"1.195453628","rc":[{"atb":[[2.32,0]],"id":40324291}],"con":true,"img":false}]}
{"op":"mcm","clk":"5348457052","pt":1646217885220,"mc":[{"id":"1.195453628","rc":[{"atl":[[5.8,0]],"id":41818958}],"con":true,"img":false}]}
{"op":"mcm","clk":"5348457063","pt":1646217885277,"mc":[{"id":"1.195453628","rc":[{"atl":[[5.6,9.08]],"id":41818958}],"con":true,"img":false}]}
{"op":"mcm","clk":"5348457077","pt":1646217885378,"mc":[{"id":"1.195453628","rc":[{"atl":[[4.9,24.11],[5.7,0]],"id":41818958}],"con":true,"img":false}]}
{"op":"mcm","clk":"5348457088","pt":1646217885483,"mc":[{"id":"1.195453628","rc":[{"atl":[[5.5,18.62],[4.9,9.3]],"id":41818958}],"con":true,"img":false}]}
{"op":"mcm","clk":"5348457103","pt":1646217885587,"mc":[{"id":"1.195453628","rc":[{"atl":[[4.9,24.11]],"id":41818958}],"con":true,"img":false}]}
{"op":"mcm","clk":"5348457116","pt":1646217885689,"mc":[{"id":"1.195453628","rc":[{"atl":[[5.5,0]],"id":41818958}],"con":true,"img":false}]}
{"op":"mcm","clk":"5348458930","pt":1646217901723,"mc":[{"id":"1.195453628","rc":[{"atl":[[2.52,0]],"id":38761677}],"con":true,"img":false}]}
{"op":"mcm","clk":"5348458945","pt":1646217901825,"mc":[{"id":"1.195453628","rc":[{"atl":[[2.72,25.34]],"id":38761677}],"con":true,"img":false}]}
{"op":"mcm","clk":"5348459110","pt":1646217903112,"mc":[{"id":"1.195453628","rc":[{"atb":[[2.36,0],[2.34,107.66]],"id":40324291}],"con":true,"img":false}]}
{"op":"mcm","clk":"5348461732","pt":1646217924742,"mc":[{"id":"1.195453628","rc":[{"atl":[[5.6,0]],"id":41818958}],"con":true,"img":false}]}
{"op":"mcm","clk":"5348461756","pt":1646217924958,"mc":[{"id":"1.195453628","rc":[{"atl":[[4.8,9.08]],"id":41818958}],"con":true,"img":false}]}
{"op":"mcm","clk":"5348461775","pt":1646217925167,"mc":[{"id":"1.195453628","rc":[{"atl":[[4.8,23.89],[4.9,9.3]],"id":41818958}],"con":true,"img":false}]}
{"op":"mcm","clk":"5348464057","pt":1646217943604,"mc":[{"id":"1.195453628","rc":[{"atb":[[1.72,0]],"id":39734233},{"spn":3.39,"spf":"NaN","id":41818958},{"spn":1.94,"spf":"NaN","id":38761677},{"spn":3.97,"spf":"NaN","id":40324291}],"con":true,"img":false}]}
{"op":"mcm","clk":"5348464070","pt":1646217943729,"mc":[{"id":"1.195453628","rc":[{"atb":[[1.75,60.55]],"id":39734233}],"con":true,"img":false}]}
{"op":"mcm","clk":"5348464618","pt":1646217948303,"mc":[{"id":"1.195453628","rc":[{"atl":[[7,10.33],[8.4,0]],"id":40324291}],"con":true,"img":false}]}
{"op":"mcm","clk":"5348466351","pt":1646217962524,"mc":[{"id":"1.195453628","rc":[{"atl":[[4.8,14.81]],"id":41818958}],"con":true,"img":false}]}
{"op":"mcm","clk":"5348466365","pt":1646217962627,"mc":[{"id":"1.195453628","rc":[{"atl":[[4.7,9.08]],"id":41818958}],"con":true,"img":false}]}
{"op":"mcm","clk":"5348468143","pt":1646217976664,"mc":[{"id":"1.195453628","rc":[{"atb":[[1.72,87.74],[1.54,0]],"id":39734233}],"con":true,"img":false}]}
{"op":"mcm","clk":"5348468501","pt":1646217979147,"mc":[{"id":"1.195453628","rc":[{"atb":[[1.72,0],[1.55,114.99]],"id":39734233}],"con":true,"img":false}]}
{"op":"mcm","clk":"5348469829","pt":1646217991282,"mc":[{"id":"1.195453628","rc":[{"atb":[[1.75,0]],"id":39734233}],"con":true,"img":false}]}
{"op":"mcm","clk":"5348469842","pt":1646217991381,"mc":[{"id":"1.195453628","rc":[{"atb":[[1.72,60.55]],"id":39734233}],"con":true,"img":false}]}
{"op":"mcm","clk":"5348470310","pt":1646217995389,"mc":[{"id":"1.195453628","rc":[{"atl":[[2.72,0]],"id":38761677}],"con":true,"img":false}]}
{"op":"mcm","clk":"5348470319","pt":1646217995488,"mc":[{"id":"1.195453628","rc":[{"atl":[[2.52,25.34]],"id":38761677}],"con":true,"img":false}]}
{"op":"mcm","clk":"5348473677","pt":1646218023156,"mc":[{"id":"1.195453628","rc":[{"atb":[[1.9,0],[1.77,129.87]],"id":41818958},{"atl":[[4.8,0],[5.1,18.62]],"id":41818958},{"spn":3.34,"spf":"NaN","id":41818958},{"spn":1.93,"spf":"NaN","id":38761677},{"atb":[[2.24,80.65],[2.34,33.03]],"id":40324291}],"con":true,"img":false}]}
{"op":"mcm","clk":"5348475115","pt":1646218034353,"mc":[{"id":"1.195453628","rc":[{"atl":[[4.7,0]],"id":41818958},{"atb":[[2.34,0]],"id":40324291}],"con":true,"img":false}]}
{"op":"mcm","clk":"5348475129","pt":1646218034455,"mc":[{"id":"1.195453628","rc":[{"atl":[[5,9.08]],"id":41818958},{"atb":[[2.32,33.03]],"id":40324291}],"con":true,"img":false}]}
{"op":"mcm","clk":"5348476644","pt":1646218047250,"mc":[{"id":"1.195453628","rc":[{"atb":[[2.2,1.66]],"id":38214982},{"atb":[[4.1,1.66]],"id":27868829},{"atb":[[2.34,1.66]],"id":40324291}],"con":true,"img":false}]}
{"op":"mcm","clk":"5348478896","pt":1646218064868,"mc":[{"id":"1.195453628","rc":[{"atb":[[2.02,7.36]],"id":39734233},{"atb":[[2.04,7.23]],"id":41818958},{"atb":[[2.24,6.06]],"id":38214982},{"atb":[[1.37,20.32]],"id":38761677},{"atb":[[2.38,5.45]],"id":40324291}],"con":true,"img":false}]}
{"op":"mcm","clk":"5348478909","pt":1646218064982,"mc":[{"id":"1.195453628","rc":[{"atb":[[2.24,12.12]],"id":38214982}],"con":true,"img":false}]}
{"op":"mcm","clk":"5348478922","pt":1646218065083,"mc":[{"id":"1.195453628","rc":[{"atb":[[2.18,0]],"id":38214982}],"con":true,"img":false}]}
{"op":"mcm","clk":"5348479305","pt":1646218067797,"mc":[{"id":"1.195453628","rc":[{"atb":[[2.24,6.06]],"id":38214982}],"con":true,"img":false}]}
{"op":"mcm","clk":"5348479593","pt":1646218070194,"mc":[{"id":"1.195453628","rc":[{"atb":[[2.24,0],[2.2,42.03]],"id":38214982}],"con":true,"img":false}]}
{"op":"mcm","clk":"5348480439","pt":1646218076803,"mc":[{"id":"1.195453628","rc":[{"atb":[[2.26,5.96]],"id":38214982}],"con":true,"img":false}]}
{"op":"mcm","clk":"5348481002","pt":1646218081299,"mc":[{"id":"1.195453628","rc":[{"atb":[[2.2,40.37]],"id":38214982},{"atb":[[2.34,0]],"id":40324291}],"con":true,"img":false}]}
{"op":"mcm","clk":"5348481020","pt":1646218081511,"mc":[{"id":"1.195453628","rc":[{"atb":[[2.04,1.66]],"id":39734233},{"atb":[[2.06,1.66]],"id":41818958},{"atb":[[2.28,1.66]],"id":38214982},{"atb":[[2.4,1.66]],"id":40324291}],"con":true,"img":false}]}
{"op":"mcm","clk":"5348481145","pt":1646218082607,"mc":[{"id":"1.195453628","marketDefinition":{"bspMarket":true,"turnInPlayEnabled":false,"persistenceEnabled":false,"marketBaseRate":7.0,"eventId":"31272494","eventTypeId":"4339","numberOfWinners":2,"bettingType":"ODDS","marketType":"PLACE","marketTime":"2022-03-02T11:32:00.000Z","suspendTime":"2022-03-02T11:32:00.000Z","bspReconciled":false,"complete":true,"inPlay":false,"crossMatching":true,"runnersVoidable":false,"numberOfActiveRunners":6,"betDelay":0,"status":"OPEN","runners":[{"status":"ACTIVE","sortPriority":1,"id":39734233,"name":"1. Bernadette"},{"status":"ACTIVE","sortPriority":2,"id":38761677,"name":"2. General Payton"},{"status":"ACTIVE","sortPriority":3,"id":40324291,"name":"4. Reiko Langer"},{"status":"ACTIVE","sortPriority":4,"id":41818958,"name":"6. Armatree Arrow"},{"status":"ACTIVE","sortPriority":5,"id":38214982,"name":"7. Two Phones"},{"status":"ACTIVE","sortPriority":6,"id":27868829,"name":"8. My Gem"}],"regulators":["MR_INT"],"venue":"Traralgon","countryCode":"AU","discountAllowed":true,"timezone":"Australia/Sydney","openDate":"2022-03-02T08:31:00.000Z","version":4382425385,"name":"To Be Placed","eventName":"Traralgon (AUS) 2nd Mar"},"rc":[],"con":true,"img":false}]}
{"op":"mcm","clk":"5348481263","pt":1646218083614,"mc":[{"id":"1.195453628","rc":[{"spn":3.42,"spf":"NaN","id":39734233},{"atb":[[1.71,0]],"id":41818958},{"spn":3.48,"spf":"NaN","id":41818958},{"spn":3.84,"spf":"NaN","id":38214982},{"spn":8.8,"spf":"NaN","id":27868829},{"spn":1.94,"spf":"NaN","id":38761677},{"spn":4.0,"spf":"NaN","id":40324291}],"con":true,"img":false}]}
{"op":"mcm","clk":"5348481278","pt":1646218083713,"mc":[{"id":"1.195453628","rc":[{"atb":[[1.78,81.74]],"id":41818958},{"atb":[[1.34,84.77]],"id":38761677}],"con":true,"img":false}]}
{"op":"mcm","clk":"5348483054","pt":1646218097799,"mc":[{"id":"1.195453628","rc":[{"atb":[[2.24,40.37],[2.2,0]],"id":38214982}],"con":true,"img":false}]}
{"op":"mcm","clk":"5348483175","pt":1646218098953,"mc":[{"id":"1.195453628","rc":[{"atb":[[2.26,0]],"id":38214982}],"con":true,"img":false}]}
{"op":"mcm","clk":"5348483310","pt":1646218099916,"mc":[{"id":"1.195453628","rc":[{"atb":[[3.1,0]],"id":27868829}],"con":true,"img":false}]}
{"op":"mcm","clk":"5348483324","pt":1646218100021,"mc":[{"id":"1.195453628","rc":[{"atb":[[3.5,26.38]],"id":27868829}],"con":true,"img":false}]}
{"op":"mcm","clk":"5348483780","pt":1646218103843,"mc":[{"id":"1.195453628","rc":[{"atb":[[2.3,5.78]],"id":38214982}],"con":true,"img":false}]}
{"op":"mcm","clk":"5348485211","pt":1646218115228,"mc":[{"id":"1.195453628","rc":[{"atb":[[2.28,0]],"id":38214982}],"con":true,"img":false}]}
{"op":"mcm","clk":"5348485230","pt":1646218115437,"mc":[{"id":"1.195453628","rc":[{"atb":[[2.32,1.66]],"id":38214982}],"con":true,"img":false}]}
{"op":"mcm","clk":"5348486099","pt":1646218122970,"mc":[{"id":"1.195453628","rc":[{"atb":[[2.02,15.53]],"id":39734233}],"con":true,"img":false}]}
{"op":"mcm","clk":"5348486111","pt":1646218123074,"mc":[{"id":"1.195453628","rc":[{"atb":[[1.37,42.85]],"id":38761677}],"con":true,"img":false}]}
{"op":"mcm","clk":"5348486125","pt":1646218123178,"mc":[{"id":"1.195453628","rc":[{"atb":[[2.36,6.12]],"id":40324291}],"con":true,"img":false}]}
{"op":"mcm","clk":"5348486141","pt":1646218123333,"mc":[{"id":"1.195453628","rc":[{"atb":[[2.04,15.25]],"id":41818958}],"con":true,"img":false}]}
{"op":"mcm","clk":"5348486164","pt":1646218123544,"mc":[{"id":"1.195453628","rc":[{"atb":[[2.3,12.19]],"id":38214982}],"con":true,"img":false}]}
{"op":"mcm","clk":"5348486737","pt":1646218128555,"mc":[{"id":"1.195453628","rc":[{"atl":[[9.4,0]],"id":39734233}],"con":true,"img":false}]}
{"op":"mcm","clk":"5348486751","pt":1646218128660,"mc":[{"id":"1.195453628","rc":[{"atl":[[10,7.62]],"id":39734233}],"con":true,"img":false}]}
{"op":"mcm","clk":"5348493241","pt":1646218182067,"mc":[{"id":"1.195453628","rc":[{"atb":[[2.08,0]],"id":38214982},{"spn":3.86,"spf":"NaN","id":38214982}],"con":true,"img":false}]}
{"op":"mcm","clk":"5348493251","pt":1646218182170,"mc":[{"id":"1.195453628","rc":[{"atb":[[1.99,40.36]],"id":38214982}],"con":true,"img":false}]}
{"op":"mcm","clk":"5348495121","pt":1646218197386,"mc":[{"id":"1.195453628","rc":[{"atb":[[1.77,0],[1.87,114.94]],"id":41818958},{"atl":[[4.8,9.31],[5.1,0]],"id":41818958},{"atb":[[2.24,0],[2.32,13.85]],"id":38214982},{"atb":[[2.36,39.15],[2.24,0]],"id":40324291}],"con":true,"img":false}]}
{"op":"mcm","clk":"5348495212","pt":1646218198195,"mc":[{"id":"1.195453628","rc":[{"atb":[[2.3,6.41]],"id":38214982},{"atb":[[2.38,0]],"id":40324291}],"con":true,"img":false}]}
{"op":"mcm","clk":"5348495470","pt":1646218200306,"mc":[{"id":"1.195453628","rc":[{"atb":[[2.4,0]],"id":40324291}],"con":true,"img":false}]}
{"op":"mcm","clk":"5348495494","pt":1646218200463,"mc":[{"id":"1.195453628","rc":[{"atb":[[2.38,1.66]],"id":40324291}],"con":true,"img":false}]}
{"op":"mcm","clk":"5348495832","pt":1646218203191,"mc":[{"id":"1.195453628","rc":[{"atb":[[2.2,6.26]],"id":38214982},{"atb":[[2.42,5.29]],"id":40324291}],"con":true,"img":false}]}
{"op":"mcm","clk":"5348496345","pt":1646218207311,"mc":[{"id":"1.195453628","rc":[{"atl":[[5,0]],"id":41818958}],"con":true,"img":false}]}
{"op":"mcm","clk":"5348496355","pt":1646218207386,"mc":[{"id":"1.195453628","rc":[{"atl":[[5.8,9.08]],"id":41818958}],"con":true,"img":false}]}
{"op":"mcm","clk":"5348496939","pt":1646218212090,"mc":[{"id":"1.195453628","rc":[{"atb":[[2.02,113.57],[1.71,0]],"id":39734233},{"atl":[[8,14.29],[6.2,0]],"id":38214982},{"atl":[[6.4,0],[8.8,12.82]],"id":38761677},{"atl":[[7.2,27.83],[6.4,0]],"id":40324291}],"con":true,"img":false}]}
{"op":"mcm","clk":"5348497458","pt":1646218216322,"mc":[{"id":"1.195453628","rc":[{"atb":[[2.02,106.2]],"id":39734233},{"atb":[[2.38,0]],"id":40324291}],"con":true,"img":false}]}
{"op":"mcm","clk":"5348497481","pt":1646218216528,"mc":[{"id":"1.195453628","rc":[{"atb":[[2.44,1.66]],"id":40324291}],"con":true,"img":false}]}
{"op":"mcm","clk":"5348498893","pt":1646218224219,"mc":[{"id":"1.195453628","rc":[{"atb":[[2.06,7.09]],"id":39734233}],"con":true,"img":false}]}
{"op":"mcm","clk":"5348498991","pt":1646218224903,"mc":[{"id":"1.195453628","rc":[{"atb":[[1.72,0]],"id":39734233},{"atb":[[2.32,0]],"id":40324291},{"atl":[[6.2,0]],"id":40324291}],"con":true,"img":false}]}
{"op":"mcm","clk":"5348499008","pt":1646218225013,"mc":[{"id":"1.195453628","rc":[{"atb":[[1.66,60.55]],"id":39734233},{"atb":[[2.38,33.03]],"id":40324291},{"atl":[[7,17.59]],"id":40324291}],"con":true,"img":false}]}
{"op":"mcm","clk":"5348499376","pt":1646218227445,"mc":[{"id":"1.195453628","rc":[{"atb":[[2.3,0]],"id":38214982}],"con":true,"img":false}]}
{"op":"mcm","clk":"5348499410","pt":1646218227603,"mc":[{"id":"1.195453628","rc":[{"atb":[[2.42,0]],"id":40324291}],"con":true,"img":false}]}
{"op":"mcm","clk":"5348500060","pt":1646218232352,"mc":[{"id":"1.195453628","rc":[{"atb":[[2.04,0]],"id":39734233},{"atb":[[2.44,0]],"id":40324291}],"con":true,"img":false}]}
{"op":"mcm","clk":"5348500097","pt":1646218232556,"mc":[{"id":"1.195453628","rc":[{"atb":[[2.08,1.66]],"id":39734233},{"atb":[[2.4,1.66]],"id":40324291}],"con":true,"img":false}]}
{"op":"mcm","clk":"5348500212","pt":1646218233261,"mc":[{"id":"1.195453628","rc":[{"atb":[[2.44,5.21]],"id":40324291}],"con":true,"img":false}]}
{"op":"mcm","clk":"5348501632","pt":1646218243953,"mc":[{"id":"1.195453628","rc":[{"atb":[[2.02,98.04]],"id":39734233},{"spn":3.44,"spf":"NaN","id":39734233},{"spn":3.43,"spf":"NaN","id":41818958},{"atb":[[2.2,13.2]],"id":38214982},{"spn":4.02,"spf":"NaN","id":40324291}],"con":true,"img":false}]}
{"op":"mcm","clk":"5348502317","pt":1646218249264,"mc":[{"id":"1.195453628","rc":[{"atb":[[2.4,0]],"id":40324291}],"con":true,"img":false}]}
{"op":"mcm","clk":"5348502341","pt":1646218249471,"mc":[{"id":"1.195453628","rc":[{"atb":[[2.46,1.66]],"id":40324291}],"con":true,"img":false}]}
{"op":"mcm","clk":"5348503672","pt":1646218259692,"mc":[{"id":"1.195453628","rc":[{"atb":[[2.06,14.95]],"id":39734233}],"con":true,"img":false}]}
{"op":"mcm","clk":"5348505705","pt":1646218277180,"mc":[{"id":"1.195453628","rc":[{"atl":[[6,0],[6.6,0]],"id":38214982},{"atl":[[18,2.72],[26,2.72]],"id":27868829},{"atl":[[9,7.74],[7,7.26]],"id":40324291}],"con":true,"img":false}]}
{"op":"mcm","clk":"5348505723","pt":1646218277286,"mc":[{"id":"1.195453628","rc":[{"atl":[[6.6,7.78],[7.8,9.8]],"id":38214982}],"con":true,"img":false}]}
{"op":"mcm","clk":"5348507319","pt":1646218290112,"mc":[{"id":"1.195453628","rc":[{"atl":[[2.52,0]],"id":38761677}],"con":true,"img":false}]}
{"op":"mcm","clk":"5348507350","pt":1646218290426,"mc":[{"id":"1.195453628","rc":[{"atl":[[2.72,25.34]],"id":38761677}],"con":true,"img":false}]}
{"op":"mcm","clk":"5348507652","pt":1646218293297,"mc":[{"id":"1.195453628","rc":[{"atb":[[1.78,0],[1.94,61.74]],"id":41818958}],"con":true,"img":false}]}
{"op":"mcm","clk":"5348508603","pt":1646218302424,"mc":[{"id":"1.195453628","rc":[{"atb":[[4,0]],"id":27868829}],"con":true,"img":false}]}
{"op":"mcm","clk":"5348508617","pt":1646218302528,"mc":[{"id":"1.195453628","rc":[{"atb":[[4.7,12.1]],"id":27868829}],"con":true,"img":false}]}
{"op":"mcm","clk":"5348510620","pt":1646218319283,"mc":[{"id":"1.195453628","rc":[{"atb":[[4.1,0]],"id":27868829},{"spn":9.1,"spf":"NaN","id":27868829},{"spn":1.95,"spf":"NaN","id":38761677},{"spn":4.03,"spf":"NaN","id":40324291}],"con":true,"img":false}]}
{"op":"mcm","clk":"5348510630","pt":1646218319335,"mc":[{"id":"1.195453628","rc":[{"atb":[[4.8,1.66]],"id":27868829}],"con":true,"img":false}]}
{"op":"mcm","clk":"5348511708","pt":1646218328077,"mc":[{"id":"1.195453628","rc":[{"atb":[[2.02,0],[1.95,105.26]],"id":39734233},{"atb":[[1.77,129.87],[1.87,0]],"id":41818958},{"atl":[[4.8,0],[5.1,18.62]],"id":41818958},{"atb":[[2.32,1.66],[2.26,79.37]],"id":38214982},{"atb":[[2.36,6.12],[2.26,79.37]],"id":40324291}],"con":true,"img":false}]}
{"op":"mcm","clk":"5348511859","pt":1646218329486,"mc":[{"id":"1.195453628","rc":[{"atb":[[2.06,7.86]],"id":39734233},{"atb":[[2.2,6.94]],"id":38214982}],"con":true,"img":false}]}
{"op":"mcm","clk":"5348512038","pt":1646218331000,"mc":[{"id":"1.195453628","rc":[{"atb":[[4,19.34]],"id":27868829},{"atb":[[1.83,0]],"id":40324291}],"con":true,"img":false}]}
{"op":"mcm","clk":"5348512049","pt":1646218331105,"mc":[{"id":"1.195453628","rc":[{"atb":[[3.5,0]],"id":27868829},{"atb":[[2.12,65.94]],"id":40324291}],"con":true,"img":false}]}
{"op":"mcm","clk":"5348512590","pt":1646218335480,"mc":[{"id":"1.195453628","rc":[{"atb":[[2.02,7.36]],"id":39734233},{"atb":[[2.32,7.36]],"id":38214982}],"con":true,"img":false}]}
{"op":"mcm","clk":"5348512676","pt":1646218336468,"mc":[{"id":"1.195453628","rc":[{"atb":[[1.78,74.41]],"id":41818958}],"con":true,"img":false}]}
{"op":"mcm","clk":"5348512688","pt":1646218336572,"mc":[{"id":"1.195453628","rc":[{"atb":[[1.94,0]],"id":41818958},{"atb":[[4,0]],"id":27868829},{"atb":[[2.38,0],[2.12,0]],"id":40324291}],"con":true,"img":false}]}
{"op":"mcm","clk":"5348512697","pt":1646218336677,"mc":[{"id":"1.195453628","rc":[{"atb":[[3.5,19.34]],"id":27868829},{"atb":[[2.32,33.03],[1.84,65.94]],"id":40324291}],"con":true,"img":false}]}
{"op":"mcm","clk":"5348512980","pt":1646218339029,"mc":[{"id":"1.195453628","rc":[{"atb":[[2.44,0]],"id":40324291}],"con":true,"img":false}]}
{"op":"mcm","clk":"5348513696","pt":1646218344919,"mc":[{"id":"1.195453628","rc":[{"atb":[[2.38,5.45]],"id":40324291}],"con":true,"img":false}]}
{"op":"mcm","clk":"5348513958","pt":1646218347213,"mc":[{"id":"1.195453628","rc":[{"atb":[[4.7,0]],"id":27868829}],"con":true,"img":false}]}
{"op":"mcm","clk":"5348513970","pt":1646218347318,"mc":[{"id":"1.195453628","rc":[{"atb":[[4,12.1]],"id":27868829}],"con":true,"img":false}]}
{"op":"mcm","clk":"5348514471","pt":1646218351719,"mc":[{"id":"1.195453628","rc":[{"atb":[[2.06,0]],"id":39734233},{"atb":[[2.2,0]],"id":38214982}],"con":true,"img":false}]}
{"op":"mcm","clk":"5348514647","pt":1646218353285,"mc":[{"id":"1.195453628","rc":[{"atb":[[2.08,0]],"id":39734233},{"atb":[[4.8,0]],"id":27868829},{"atb":[[2.46,0]],"id":40324291}],"con":true,"img":false}]}
{"op":"mcm","clk":"5348514669","pt":1646218353497,"mc":[{"id":"1.195453628","rc":[{"atb":[[2.04,1.66]],"id":39734233},{"atb":[[4.1,1.66]],"id":27868829},{"atb":[[2.4,1.66]],"id":40324291}],"con":true,"img":false}]}
{"op":"mcm","clk":"5348515630","pt":1646218362034,"mc":[{"id":"1.195453628","rc":[{"atl":[[5.8,0]],"id":41818958}],"con":true,"img":false}]}
{"op":"mcm","clk":"5348515641","pt":1646218362138,"mc":[{"id":"1.195453628","rc":[{"atl":[[5,9.08]],"id":41818958}],"con":true,"img":false}]}
{"op":"mcm","clk":"5348516120","pt":1646218366424,"mc":[{"id":"1.195453628","rc":[{"atb":[[2.02,15.53]],"id":39734233}],"con":true,"img":false}]}
{"op":"mcm","clk":"5348516130","pt":1646218366527,"mc":[{"id":"1.195453628","rc":[{"atb":[[2.32,13.68]],"id":38214982}],"con":true,"img":false}]}
{"op":"mcm","clk":"5348518481","pt":1646218387767,"mc":[{"id":"1.195453628","rc":[{"spn":3.42,"spf":"NaN","id":39734233},{"spn":3.48,"spf":"NaN","id":41818958},{"atl":[[7.8,0]],"id":38214982},{"atl":[[18,6.13]],"id":27868829},{"spn":8.8,"spf":"NaN","id":27868829},{"spn":4.0,"spf":"NaN","id":40324291}],"con":true,"img":false}]}
{"op":"mcm","clk":"5348518486","pt":1646218387872,"mc":[{"id":"1.195453628","rc":[{"atl":[[6.6,17.59]],"id":38214982},{"atl":[[26,0]],"id":27868829}],"con":true,"img":false}]}
{"op":"mcm","clk":"5348525328","pt":1646218461563,"mc":[{"id":"1.195453628","rc":[{"atl":[[3.4,29.97]],"id":40324291},{"spn":2.9,"spf":"NaN","id":40324291}],"con":true,"img":false}]}
{"op":"mcm","clk":"5348526088","pt":1646218468654,"mc":[{"id":"1.195453628","rc":[{"atl":[[10,0]],"id":39734233},{"atl":[[6.6,7.78]],"id":38214982},{"atb":[[1.84,0],[1.68,91.16]],"id":40324291}],"con":true,"img":false}]}
{"op":"mcm","clk":"5348526100","pt":1646218468759,"mc":[{"id":"1.195453628","rc":[{"atl":[[11,7.62]],"id":39734233},{"atl":[[7.8,9.8]],"id":38214982}],"con":true,"img":false}]}
{"op":"mcm","clk":"5348527019","pt":1646218478382,"mc":[{"id":"1.195453628","rc":[{"atb":[[1.99,101.01],[1.95,0]],"id":39734233},{"atb":[[1.82,121.95],[1.77,0]],"id":41818958},{"atl":[[4.8,9.31],[5.1,0]],"id":41818958},{"atb":[[2.3,76.92]],"id":38214982},{"atb":[[2.3,153.69],[2.26,0]],"id":40324291}],"con":true,"img":false}]}
{"op":"mcm","clk":"5348527024","pt":1646218478488,"mc":[{"id":"1.195453628","rc":[{"atb":[[1.94,106.38]],"id":41818958},{"atb":[[2.26,0]],"id":38214982},{"atb":[[2.4,7.11]],"id":40324291}],"con":true,"img":false}]}
{"op":"mcm","clk":"5348527032","pt":1646218478591,"mc":[{"id":"1.195453628","rc":[{"atb":[[1.99,0],[2.04,17.2]],"id":39734233},{"atb":[[1.82,0]],"id":41818958},{"atb":[[2.3,0],[2.34,74.63]],"id":38214982},{"atb":[[2.3,76.77]],"id":40324291}],"con":true,"img":false}]}
{"op":"mcm","clk":"5348527154","pt":1646218479997,"mc":[{"id":"1.195453628","rc":[{"atb":[[2.32,7.98]],"id":38214982}],"con":true,"img":false}]}
{"op":"mcm","clk":"5348528249","pt":1646218486025,"mc":[{"id":"1.195453628","rc":[{"atb":[[2.4,5.36]],"id":38214982}],"con":true,"img":false}]}
{"op":"mcm","clk":"5348528292","pt":1646218486194,"mc":[{"id":"1.195453628","rc":[{"atb":[[2.42,7.99],[2.34,0]],"id":38214982}],"con":true,"img":false}]}
{"op":"mcm","clk":"5348528588","pt":1646218489012,"mc":[{"id":"1.195453628","rc":[{"atb":[[2.4,0]],"id":38214982}],"con":true,"img":false}]}
{"op":"mcm","clk":"5348528726","pt":1646218490649,"mc":[{"id":"1.195453628","rc":[{"atb":[[2.32,6.31]],"id":38214982}],"con":true,"img":false}]}
{"op":"mcm","clk":"5348528741","pt":1646218490795,"mc":[{"id":"1.195453628","rc":[{"atb":[[2.44,1.66]],"id":38214982}],"con":true,"img":false}]}
{"op":"mcm","clk":"5348528908","pt":1646218492092,"mc":[{"id":"1.195453628","rc":[{"atl":[[5,0]],"id":41818958},{"atl":[[6.8,10.33]],"id":40324291}],"con":true,"img":false}]}
{"op":"mcm","clk":"5348528917","pt":1646218492197,"mc":[{"id":"1.195453628","rc":[{"atl":[[5.8,9.08]],"id":41818958},{"atl":[[9,0]],"id":40324291}],"con":true,"img":false}]}
{"op":"mcm","clk":"5348529198","pt":1646218495004,"mc":[{"id":"1.195453628","rc":[{"atb":[[2.2,6.26]],"id":38214982}],"con":true,"img":false}]}
{"op":"mcm","clk":"5348529237","pt":1646218495531,"mc":[{"id":"1.195453628","rc":[{"atl":[[7,0]],"id":40324291}],"con":true,"img":false}]}
{"op":"mcm","clk":"5348529244","pt":1646218495637,"mc":[{"id":"1.195453628","rc":[{"atl":[[5.4,7.26]],"id":40324291}],"con":true,"img":false}]}
{"op":"mcm","clk":"5348529662","pt":1646218501003,"mc":[{"id":"1.195453628","rc":[{"atb":[[2.32,0]],"id":38214982}],"con":true,"img":false}]}
{"op":"mcm","clk":"5348531456","pt":1646218518463,"mc":[{"id":"1.195453628","rc":[{"atb":[[2.2,13.2]],"id":38214982}],"con":true,"img":false}]}
{"op":"mcm","clk":"5348533238","pt":1646218533452,"mc":[{"id":"1.195453628","rc":[{"atb":[[1.78,0]],"id":41818958},{"spn":3.43,"spf":"NaN","id":41818958},{"atl":[[7.8,0]],"id":38214982},{"spn":3.92,"spf":"NaN","id":38214982}],"con":true,"img":false}]}
{"op":"mcm","clk":"5348533249","pt":1646218533553,"mc":[{"id":"1.195453628","rc":[{"atb":[[1.89,74.41]],"id":41818958},{"atl":[[6.6,17.59]],"id":38214982}],"con":true,"img":false}]}
{"op":"mcm","clk":"5348538603","pt":1646218588755,"mc":[{"id":"1.195453628","rc":[{"atb":[[1.99,102.67],[1.89,0]],"id":41818958}],"con":true,"img":false}]}
{"op":"mcm","clk":"5348539444","pt":1646218598475,"mc":[{"id":"1.195453628","rc":[{"atb":[[1.99,101.01],[2.04,1.66]],"id":39734233},{"atb":[[1.82,121.95],[1.94,0]],"id":41818958},{"atl":[[4.8,0],[5.1,18.62]],"id":41818958},{"spn":3.48,"spf":"NaN","id":41818958},{"atb":[[2.32,75.76],[2.42,0]],"id":38214982},{"atb":[[2.4,1.66],[2.3,153.69]],"id":40324291}],"con":true,"img":false}]}
{"op":"mcm","clk":"5348539605","pt":1646218600310,"mc":[{"id":"1.195453628","rc":[{"atb":[[2.02,8.16]],"id":39734233},{"atb":[[2.2,6.94]],"id":38214982}],"con":true,"img":false}]}
{"op":"mcm","clk":"5348540156","pt":1646218606194,"mc":[{"id":"1.195453628","rc":[{"atb":[[2.04,8.9]],"id":39734233},{"atb":[[2.38,5.45]],"id":38214982}],"con":true,"img":false}]}
{"op":"mcm","clk":"5348540359","pt":1646218608521,"mc":[{"id":"1.195453628","rc":[{"atb":[[1.99,44.04]],"id":41818958},{"atl":[[6.6,7.78]],"id":38214982}],"con":true,"img":false}]}
{"op":"mcm","clk":"5348540369","pt":1646218608590,"mc":[{"id":"1.195453628","rc":[{"atb":[[1.83,58.62]],"id":41818958},{"atl":[[7.8,9.8]],"id":38214982}],"con":true,"img":false}]}
{"op":"mcm","clk":"5348540828","pt":1646218613702,"mc":[{"id":"1.195453628","rc":[{"atb":[[2.44,0]],"id":38214982}],"con":true,"img":false}]}
{"op":"mcm","clk":"5348540846","pt":1646218613916,"mc":[{"id":"1.195453628","rc":[{"atb":[[2.4,1.66]],"id":38214982}],"con":true,"img":false}]}
{"op":"mcm","clk":"5348541320","pt":1646218620032,"mc":[{"id":"1.195453628","rc":[{"atb":[[2.02,0]],"id":39734233},{"atb":[[2.2,0]],"id":38214982}],"con":true,"img":false}]}
{"op":"mcm","clk":"5348542639","pt":1646218634011,"mc":[{"id":"1.195453628","rc":[{"atb":[[2.04,16.91]],"id":39734233}],"con":true,"img":false}]}
{"op":"mcm","clk":"5348542659","pt":1646218634220,"mc":[{"id":"1.195453628","rc":[{"atb":[[2.38,11.49]],"id":38214982}],"con":true,"img":false}]}
{"op":"mcm","clk":"5348544771","pt":1646218658987,"mc":[{"id":"1.195453628","rc":[{"atl":[[5.8,0]],"id":41818958},{"spn":3.9,"spf":"NaN","id":38214982}],"con":true,"img":false}]}
{"op":"mcm","clk":"5348544779","pt":1646218659090,"mc":[{"id":"1.195453628","rc":[{"atl":[[5,9.08]],"id":41818958}],"con":true,"img":false}]}
{"op":"mcm","clk":"5348559160","pt":1646218829150,"mc":[{"id":"1.195453628","rc":[{"atb":[[1.99,0],[1.98,101.85],[2.06,94.34],[1.55,114.99],[2.04,16.9],[1.88,113.43],[1.93,107.33],[1.66,60.55]],"id":39734233},{"atl":[[5.8,9.08],[11,7.63],[4.9,9.3],[7.8,10.67],[5.9,14.81]],"id":39734233},{"spn":3.43,"spf":"NaN","id":39734233},{"atb":[[1.83,58.63],[1.82,0],[1.99,44.04],[2.06,1.66],[1.98,101.85],[2.04,15.23],[1.88,113.43],[1.93,214.66]],"id":41818958},{"atl":[[4.8,9.31],[5.1,0],[5,9.08],[7.6,8.79],[4.9,9.3],[7.8,10.67],[5.9,14.81]],"id":41818958},{"spn":3.43,"spf":"NaN","id":41818958},{"atb":[[2.4,13.15],[1.8,79.57],[1.99,40.36],[2.32,0],[2.06,94.16],[1.98,101.85],[2.38,11.48],[2.16,86.05]],"id":38214982},{"atl":[[6.8,12.51],[8.8,9.3],[6.6,7.78],[7.8,9.81],[5.4,8.25]],"id":38214982},{"atb":[[4,12.11],[3.45,40.74],[3.95,33.83],[4.1,1.66],[3.7,36.96],[3.5,19.34]],"id":27868829},{"atl":[[18,6.13],[18.5,4.14],[13.5,2.9],[27,2.79]],"id":27868829},{"atb":[[1.2,499.1],[1.37,42.8],[1.25,399.28],[1.3,332.73],[1.31,172.29],[1.34,84.78]],"id":38761677},{"atl":[[2.72,25.34],[2.54,23.57],[2.74,41.72],[3.55,20.94],[2.94,37.42]],"id":38761677},{"atb":[[2.4,7.11],[2.36,6.12],[2.32,33.03],[2.3,76.78],[2.38,5.44],[1.68,91.17],[2.2,83.18],[2.1,90.74]],"id":40324291},{"atl":[[5.6,7.89],[7.2,27.83],[9.2,8.85],[3.4,29.97],[6.8,10.33],[5.4,7.26]],"id":40324291}],"con":true,"img":false}]}
{"op":"mcm","clk":"5348559591","pt":1646218834269,"mc":[{"id":"1.195453628","rc":[{"atb":[[2.04,9.67]],"id":39734233},{"atb":[[2.38,6.03]],"id":38214982}],"con":true,"img":false}]}
{"op":"mcm","clk":"5348559656","pt":1646218835095,"mc":[{"id":"1.195453628","rc":[{"atb":[[2.04,8.01]],"id":39734233}],"con":true,"img":false}]}
{"op":"mcm","clk":"5348559680","pt":1646218835308,"mc":[{"id":"1.195453628","rc":[{"atb":[[2.08,1.66]],"id":39734233}],"con":true,"img":false}]}
{"op":"mcm","clk":"5348560046","pt":1646218839701,"mc":[{"id":"1.195453628","rc":[{"atl":[[5,0]],"id":41818958}],"con":true,"img":false}]}
{"op":"mcm","clk":"5348560054","pt":1646218839805,"mc":[{"id":"1.195453628","rc":[{"atl":[[5.8,9.08]],"id":41818958}],"con":true,"img":false}]}
{"op":"mcm","clk":"5348560096","pt":1646218840378,"mc":[{"id":"1.195453628","rc":[{"atb":[[2.1,6.82]],"id":39734233}],"con":true,"img":false}]}
{"op":"mcm","clk":"5348560105","pt":1646218840479,"mc":[{"id":"1.195453628","rc":[{"atb":[[2.2,6.25]],"id":38214982}],"con":true,"img":false}]}
{"op":"mcm","clk":"5348560698","pt":1646218847303,"mc":[{"id":"1.195453628","rc":[{"atb":[[2.04,0]],"id":39734233},{"atb":[[2.38,0]],"id":38214982}],"con":true,"img":false}]}
{"op":"mcm","clk":"5348561075","pt":1646218852118,"mc":[{"id":"1.195453628","rc":[{"atb":[[2.08,0]],"id":39734233}],"con":true,"img":false}]}
{"op":"mcm","clk":"5348561095","pt":1646218852323,"mc":[{"id":"1.195453628","rc":[{"atb":[[2.12,1.66]],"id":39734233}],"con":true,"img":false}]}
{"op":"mcm","clk":"5348562022","pt":1646218863304,"mc":[{"id":"1.195453628","rc":[{"atb":[[2.1,14.39]],"id":39734233}],"con":true,"img":false}]}
{"op":"mcm","clk":"5348562081","pt":1646218863925,"mc":[{"id":"1.195453628","rc":[{"atb":[[2.2,13.19]],"id":38214982}],"con":true,"img":false}]}
{"op":"mcm","clk":"5348563975","pt":1646218883354,"mc":[{"id":"1.195453628","rc":[{"atb":[[1.83,0]],"id":41818958}],"con":true,"img":false}]}
{"op":"mcm","clk":"5348563988","pt":1646218883412,"mc":[{"id":"1.195453628","rc":[{"atb":[[1.89,58.63]],"id":41818958}],"con":true,"img":false}]}
{"op":"mcm","clk":"5348565387","pt":1646218899465,"mc":[{"id":"1.195453628","rc":[{"spn":3.46,"spf":"NaN","id":39734233},{"atl":[[4.8,0],[4.9,27.92]],"id":41818958},{"spn":3.48,"spf":"NaN","id":41818958},{"atb":[[2.4,1.66],[2.38,19.68]],"id":40324291}],"con":true,"img":false}]}
{"op":"mcm","clk":"5348565569","pt":1646218900884,"mc":[{"id":"1.195453628","rc":[{"atb":[[1.89,0]],"id":41818958}],"con":true,"img":false}]}
{"op":"mcm","clk":"5348566302","pt":1646218905891,"mc":[{"id":"1.195453628","rc":[{"atb":[[2.36,39.15],[2.38,5.44]],"id":40324291}],"con":true,"img":false}]}
{"op":"mcm","clk":"5348566355","pt":1646218906288,"mc":[{"id":"1.195453628","rc":[{"atb":[[2.38,0]],"id":40324291}],"con":true,"img":false}]}
{"op":"mcm","clk":"5348566382","pt":1646218906501,"mc":[{"id":"1.195453628","rc":[{"atb":[[2.06,0],[2.08,92.59]],"id":39734233}],"con":true,"img":false}]}
{"op":"mcm","clk":"5348566764","pt":1646218909287,"mc":[{"id":"1.195453628","rc":[{"atb":[[2.1,7.57]],"id":39734233}],"con":true,"img":false}]}
{"op":"mcm","clk":"5348567083","pt":1646218911694,"mc":[{"id":"1.195453628","rc":[{"atb":[[2.06,94.34],[2.08,0]],"id":39734233}],"con":true,"img":false}]}
{"op":"mcm","clk":"5348567188","pt":1646218912466,"mc":[{"id":"1.195453628","rc":[{"atb":[[2.42,5.28]],"id":40324291}],"con":true,"img":false}]}
{"op":"mcm","clk":"5348568002","pt":1646218918308,"mc":[{"id":"1.195453628","rc":[{"atb":[[2.1,14.39]],"id":39734233}],"con":true,"img":false}]}
{"op":"mcm","clk":"5348568332","pt":1646218920601,"mc":[{"id":"1.195453628","rc":[{"atb":[[1.7,82.91]],"id":41818958}],"con":true,"img":false}]}
{"op":"mcm","clk":"5348568351","pt":1646218920710,"mc":[{"id":"1.195453628","rc":[{"atb":[[1.99,0]],"id":38214982}],"con":true,"img":false}]}
{"op":"mcm","clk":"5348568368","pt":1646218920810,"mc":[{"id":"1.195453628","rc":[{"atb":[[2.08,40.36]],"id":38214982}],"con":true,"img":false}]}
{"op":"mcm","clk":"5348568580","pt":1646218922225,"mc":[{"id":"1.195453628","rc":[{"atb":[[2.4,0]],"id":40324291}],"con":true,"img":false}]}
{"op":"mcm","clk":"5348568602","pt":1646218922413,"mc":[{"id":"1.195453628","rc":[{"atb":[[2.44,1.66]],"id":40324291}],"con":true,"img":false}]}
{"op":"mcm","clk":"5348568683","pt":1646218923101,"mc":[{"id":"1.195453628","rc":[{"atl":[[5.8,0]],"id":41818958}],"con":true,"img":false}]}
{"op":"mcm","clk":"5348568695","pt":1646218923201,"mc":[{"id":"1.195453628","rc":[{"atl":[[4.8,9.08]],"id":41818958}],"con":true,"img":false}]}
{"op":"mcm","clk":"5348568976","pt":1646218925217,"mc":[{"id":"1.195453628","rc":[{"atb":[[1.82,91.46],[1.8,156.25],[1.84,59.52],[1.86,23.26]],"id":39734233},{"atl":[[3.2,56.82],[3.1,35.71],[3,25],[2.96,10.2]],"id":39734233},{"atb":[[2.04,135.42],[2.12,44.64],[2.16,17.24],[2.08,69.44]],"id":41818958},{"atl":[[4.8,22.24],[4.6,5.56],[5,18.75],[5.2,29.76]],"id":41818958},{"atb":[[2.42,35.21],[2.38,54.35],[2.46,13.7],[2.34,93.28]],"id":38214982},{"atl":[[8.6,6.58],[9,9.38],[8.2,2.78],[9.4,14.88]],"id":38214982},{"atb":[[4.5,5.71],[4.3,15.15],[3.95,76.2],[4.1,25.85]],"id":27868829},{"atl":[[10.5,5.26],[11.5,7.14],[9.8,2.27],[12.5,10.87]],"id":27868829},{"atb":[[1.37,177.94],[1.33,250],[1.39,51.28],[1.35,214.29]],"id":38761677},{"atl":[[9.6,5.81],[9.2,2.44],[10,8.33],[11,12.5]],"id":38761677},{"atb":[[2.36,53.86],[2.24,100.81],[2.32,70.91],[2.28,58.59]],"id":40324291},{"atl":[[8.6,16.45],[8.2,10.42],[7.4,3.12],[7.8,7.35]],"id":40324291}],"con":true,"img":false}]}
{"op":"mcm","clk":"5348568991","pt":1646218925316,"mc":[{"id":"1.195453628","rc":[{"atl":[[3.75,9.31]],"id":39734233}],"con":true,"img":false}]}
{"op":"mcm","clk":"5348569002","pt":1646218925414,"mc":[{"id":"1.195453628","rc":[{"atl":[[4.8,0]],"id":39734233}],"con":true,"img":false}]}
{"op":"mcm","clk":"5348569028","pt":1646218925580,"mc":[{"id":"1.195453628","rc":[{"atl":[[18,2.72]],"id":27868829}],"con":true,"img":false}]}
{"op":"mcm","clk":"5348569044","pt":1646218925689,"mc":[{"id":"1.195453628","rc":[{"atl":[[20,3.41]],"id":27868829}],"con":true,"img":false}]}
{"op":"mcm","clk":"5348569228","pt":1646218927409,"mc":[{"id":"1.195453628","rc":[{"atb":[[2.04,128.2]],"id":41818958},{"atb":[[2.2,6.93]],"id":38214982},{"atb":[[1.37,157.65]],"id":38761677}],"con":true,"img":false}]}
{"op":"mcm","clk":"5348569656","pt":1646218931319,"mc":[{"id":"1.195453628","rc":[{"atl":[[4.9,9.3],[4.7,22.25]],"id":41818958},{"atl":[[18.5,9.85],[22,0]],"id":27868829}],"con":true,"img":false}]}
{"op":"mcm","clk":"5348569884","pt":1646218933310,"mc":[{"id":"1.195453628","rc":[{"atb":[[2.16,23.71]],"id":41818958},{"atb":[[2.48,5.07]],"id":38214982},{"atb":[[1.4,18.76]],"id":38761677}],"con":true,"img":false}]}
{"op":"mcm","clk":"5348569904","pt":1646218933514,"mc":[{"id":"1.195453628","rc":[{"atb":[[2.4,1.66],[2.46,27.4]],"id":38214982}],"con":true,"img":false}]}
{"op":"mcm","clk":"5348570568","pt":1646218940240,"mc":[{"id":"1.195453628","rc":[{"atb":[[2.06,0]],"id":41818958},{"atb":[[2.4,0]],"id":38214982},{"atb":[[4.1,24.19]],"id":27868829}],"con":true,"img":false}]}
{"op":"mcm","clk":"5348570591","pt":1646218940405,"mc":[{"id":"1.195453628","rc":[{"atb":[[2.18,1.66]],"id":41818958},{"atb":[[2.5,1.66]],"id":38214982},{"atb":[[4.6,1.66]],"id":27868829}],"con":true,"img":false}]}
{"op":"mcm","clk":"5348570668","pt":1646218941338,"mc":[{"id":"1.195453628","rc":[{"atb":[[2.36,39.15],[2.32,48.18]],"id":40324291}],"con":true,"img":false}]}
{"op":"mcm","clk":"5348570751","pt":1646218942112,"mc":[{"id":"1.195453628","rc":[{"atl":[[5.8,12.09],[7.6,0]],"id":41818958}],"con":true,"img":false}]}
{"op":"mcm","clk":"5348570981","pt":1646218944416,"mc":[{"id":"1.195453628","rc":[{"atl":[[3.4,41.67],[3.75,0]],"id":39734233}],"con":true,"img":false}]}
{"op":"mcm","clk":"5348571118","pt":1646218945617,"mc":[{"id":"1.195453628","rc":[{"atb":[[2.32,15.15]],"id":40324291}],"con":true,"img":false}]}
{"op":"mcm","clk":"5348571128","pt":1646218945722,"mc":[{"id":"1.195453628","rc":[{"atb":[[2.38,33.03]],"id":40324291}],"con":true,"img":false}]}
{"op":"mcm","clk":"5348571273","pt":1646218947121,"mc":[{"id":"1.195453628","rc":[{"atl":[[12,3.96]],"id":27868829}],"con":true,"img":false}]}
{"op":"mcm","clk":"5348571282","pt":1646218947225,"mc":[{"id":"1.195453628","rc":[{"atl":[[18,0]],"id":27868829}],"con":true,"img":false}]}
{"op":"mcm","clk":"5348571316","pt":1646218947639,"mc":[{"id":"1.195453628","rc":[{"atb":[[1.34,0]],"id":38761677}],"con":true,"img":false}]}
{"op":"mcm","clk":"5348571326","pt":1646218947749,"mc":[{"id":"1.195453628","rc":[{"atb":[[1.42,84.78]],"id":38761677}],"con":true,"img":false}]}
{"op":"mcm","clk":"5348571357","pt":1646218948101,"mc":[{"id":"1.195453628","rc":[{"atl":[[3.35,18.55]],"id":39734233}],"con":true,"img":false}]}
{"op":"mcm","clk":"5348571368","pt":1646218948218,"mc":[{"id":"1.195453628","rc":[{"atl":[[5.8,0]],"id":39734233}],"con":true,"img":false}]}
{"op":"mcm","clk":"5348571402","pt":1646218948631,"mc":[{"id":"1.195453628","rc":[{"atb":[[4,0]],"id":27868829},{"atb":[[1.4,0]],"id":38761677},{"atb":[[2.42,0]],"id":40324291}],"con":true,"img":false}]}
{"op":"mcm","clk":"5348571413","pt":1646218948734,"mc":[{"id":"1.195453628","rc":[{"atb":[[4.2,12.11]],"id":27868829}],"con":true,"img":false}]}
{"op":"mcm","clk":"5348571497","pt":1646218949616,"mc":[{"id":"1.195453628","rc":[{"atb":[[1.99,0]],"id":41818958}],"con":true,"img":false}]}
{"op":"mcm","clk":"5348571507","pt":1646218949719,"mc":[{"id":"1.195453628","rc":[{"atb":[[2.14,44.04]],"id":41818958}],"con":true,"img":false}]}
{"op":"mcm","clk":"5348571648","pt":1646218951217,"mc":[{"id":"1.195453628","rc":[{"spl":[[1.01,5.86]],"id":40324291}],"con":true,"img":false}]}
{"op":"mcm","clk":"5348571662","pt":1646218951323,"mc":[{"id":"1.195453628","rc":[{"atb":[[2.28,39.06]],"id":40324291}],"con":true,"img":false}]}
{"op":"mcm","clk":"5348571834","pt":1646218953242,"mc":[{"id":"1.195453628","rc":[{"atl":[[4.8,13.16]],"id":41818958}],"con":true,"img":false}]}
{"op":"mcm","clk":"5348571845","pt":1646218953343,"mc":[{"id":"1.195453628","rc":[{"atl":[[4.6,14.64]],"id":41818958}],"con":true,"img":false}]}
{"op":"mcm","clk":"5348571855","pt":1646218953440,"mc":[{"id":"1.195453628","rc":[{"atl":[[4.8,39.48],[4.7,0]],"id":41818958}],"con":true,"img":false}]}
{"op":"mcm","clk":"5348571971","pt":1646218954636,"mc":[{"id":"1.195453628","rc":[{"atb":[[2.16,17.24]],"id":41818958},{"atb":[[1.45,16.68]],"id":38761677},{"atb":[[2.44,6.87]],"id":40324291}],"con":true,"img":false}]}
{"op":"mcm","clk":"5348572273","pt":1646218957647,"mc":[{"id":"1.195453628","rc":[{"atb":[[2.08,40.36]],"id":39734233}],"con":true,"img":false}]}
{"op":"mcm","clk":"5348572278","pt":1646218957750,"mc":[{"id":"1.195453628","rc":[{"atb":[[1.66,0]],"id":39734233},{"atb":[[2.08,0]],"id":38214982}],"con":true,"img":false}]}
{"op":"mcm","clk":"5348572285","pt":1646218957802,"mc":[{"id":"1.195453628","rc":[{"atb":[[2.44,40.36]],"id":38214982}],"con":true,"img":false}]}
{"op":"mcm","clk":"5348572482","pt":1646218960454,"mc":[{"id":"1.195453628","rc":[{"atb":[[2.1,7.57]],"id":39734233},{"spn":2.54,"spf":"NaN","id":39734233},{"atb":[[2.18,8.02]],"id":41818958},{"spn":3.39,"spf":"NaN","id":41818958},{"atb":[[2.48,0]],"id":38214982},{"spn":3.95,"spf":"NaN","id":38214982},{"spn":7.2,"spf":"NaN","id":27868829},{"spn":1.99,"spf":"NaN","id":38761677},{"spn":2.44,"spf":1.0,"id":40324291}],"con":true,"img":false}]}
{"op":"mcm","clk":"5348572554","pt":1646218961147,"mc":[{"id":"1.195453628","rc":[{"atl":[[4.6,5.56]],"id":41818958}],"con":true,"img":false}]}
{"op":"mcm","clk":"5348572564","pt":1646218961242,"mc":[{"id":"1.195453628","rc":[{"atl":[[4.7,9.08]],"id":41818958}],"con":true,"img":false}]}
{"op":"mcm","clk":"5348572575","pt":1646218961363,"mc":[{"id":"1.195453628","rc":[{"atb":[[2.24,60.48]],"id":40324291}],"con":true,"img":false}]}
{"op":"mcm","clk":"5348573012","pt":1646218965773,"mc":[{"id":"1.195453628","rc":[{"atl":[[20,0]],"id":27868829}],"con":true,"img":false}]}
{"op":"mcm","clk":"5348573023","pt":1646218965862,"mc":[{"id":"1.195453628","rc":[{"atl":[[16.5,3.41]],"id":27868829}],"con":true,"img":false}]}
{"op":"mcm","clk":"5348573059","pt":1646218966124,"mc":[{"id":"1.195453628","rc":[{"atb":[[1.31,0],[1.38,140.55]],"id":38761677},{"atl":[[6.8,0],[5.9,12.64]],"id":40324291}],"con":true,"img":false}]}
{"op":"mcm","clk":"5348573110","pt":1646218966649,"mc":[{"id":"1.195453628","rc":[{"atb":[[2.12,8.37]],"id":39734233},{"atb":[[2.5,6.67]],"id":38214982},{"atb":[[1.68,0]],"id":40324291}],"con":true,"img":false}]}
{"op":"mcm","clk":"5348573120","pt":1646218966751,"mc":[{"id":"1.195453628","rc":[{"atb":[[1.77,91.17]],"id":40324291}],"con":true,"img":false}]}
{"op":"mcm","clk":"5348573160","pt":1646218967117,"mc":[{"id":"1.195453628","rc":[{"atl":[[2.92,27.81],[3.55,0]],"id":38761677}],"con":true,"img":false}]}
{"op":"mcm","clk":"5348573205","pt":1646218967646,"mc":[{"id":"1.195453628","rc":[{"atb":[[3.5,0]],"id":27868829}],"con":true,"img":false}]}
{"op":"mcm","clk":"5348573216","pt":1646218967749,"mc":[{"id":"1.195453628","rc":[{"atb":[[3.75,19.34]],"id":27868829}],"con":true,"img":false}]}
{"op":"mcm","clk":"5348573359","pt":1646218969153,"mc":[{"id":"1.195453628","rc":[{"atb":[[1.99,58.63],[1.7,0]],"id":41818958}],"con":true,"img":false}]}
{"op":"mcm","clk":"5348573394","pt":1646218969522,"mc":[{"id":"1.195453628","rc":[{"atl":[[4.9,25.65]],"id":39734233}],"con":true,"img":false}]}
{"op":"mcm","clk":"5348573401","pt":1646218969628,"mc":[{"id":"1.195453628","rc":[{"atl":[[11,0]],"id":39734233}],"con":true,"img":false}]}
{"op":"mcm","clk":"5348573563","pt":1646218971358,"mc":[{"id":"1.195453628","rc":[{"atb":[[2.2,187.35]],"id":40324291}],"con":true,"img":false}]}
{"op":"mcm","clk":"5348573662","pt":1646218972245,"mc":[{"id":"1.195453628","rc":[{"atl":[[4.8,13.16],[4.6,14.65]],"id":41818958}],"con":true,"img":false}]}
{"op":"mcm","clk":"5348574113","pt":1646218976561,"mc":[{"id":"1.195453628","rc":[{"atb":[[1.55,0]],"id":39734233},{"atb":[[2.38,0]],"id":40324291}],"con":true,"img":false}]}
{"op":"mcm","clk":"5348574119","pt":1646218976664,"mc":[{"id":"1.195453628","rc":[{"atb":[[1.62,114.99]],"id":39734233},{"atb":[[2.32,48.18]],"id":40324291}],"con":true,"img":false}]}
{"op":"mcm","clk":"5348574319","pt":1646218978746,"mc":[{"id":"1.195453628","rc":[{"atb":[[2.44,1.66]],"id":40324291}],"con":true,"img":false}]}
{"op":"mcm","clk":"5348574449","pt":1646218980155,"mc":[{"id":"1.195453628","rc":[{"atl":[[4.7,0]],"id":41818958}],"con":true,"img":false}]}
{"op":"mcm","clk":"5348574460","pt":1646218980258,"mc":[{"id":"1.195453628","rc":[{"atl":[[4.9,18.39]],"id":41818958}],"con":true,"img":false}]}
{"op":"mcm","clk":"5348574467","pt":1646218980361,"mc":[{"id":"1.195453628","rc":[{"atl":[[4.8,39.48],[4.6,5.56]],"id":41818958}],"con":true,"img":false}]}
{"op":"mcm","clk":"5348574494","pt":1646218980576,"mc":[{"id":"1.195453628","rc":[{"atb":[[1.8,0],[2.18,53.95]],"id":38214982}],"con":true,"img":false}]}
{"op":"mcm","clk":"5348574941","pt":1646218984656,"mc":[{"id":"1.195453628","rc":[{"atb":[[2.42,5.28]],"id":40324291}],"con":true,"img":false}]}
{"op":"mcm","clk":"5348576732","pt":1646219002181,"mc":[{"id":"1.195453628","rc":[{"atl":[[4.9,9.3]],"id":41818958}],"con":true,"img":false}]}
{"op":"mcm","clk":"5348576744","pt":1646219002286,"mc":[{"id":"1.195453628","rc":[{"atl":[[4.7,9.08]],"id":41818958}],"con":true,"img":false}]}
{"op":"mcm","clk":"5348576766","pt":1646219002494,"mc":[{"id":"1.195453628","rc":[{"atl":[[4.8,13.16],[4.6,14.65]],"id":41818958}],"con":true,"img":false}]}
{"op":"mcm","clk":"5348577574","pt":1646219010124,"mc":[{"id":"1.195453628","rc":[{"atl":[[4.7,0]],"id":41818958}],"con":true,"img":false}]}
{"op":"mcm","clk":"5348577583","pt":1646219010221,"mc":[{"id":"1.195453628","rc":[{"atl":[[4.9,18.39]],"id":41818958}],"con":true,"img":false}]}
{"op":"mcm","clk":"5348577593","pt":1646219010272,"mc":[{"id":"1.195453628","rc":[{"atl":[[4.8,39.48],[4.6,5.56]],"id":41818958}],"con":true,"img":false}]}
{"op":"mcm","clk":"5348578395","pt":1646219018099,"mc":[{"id":"1.195453628","rc":[{"atb":[[2.32,15.15]],"id":40324291}],"con":true,"img":false}]}
{"op":"mcm","clk":"5348578404","pt":1646219018203,"mc":[{"id":"1.195453628","rc":[{"atb":[[2.38,33.03]],"id":40324291}],"con":true,"img":false}]}
{"op":"mcm","clk":"5348578617","pt":1646219020389,"mc":[{"id":"1.195453628","rc":[{"atb":[[2.42,0]],"id":40324291}],"con":true,"img":false}]}
{"op":"mcm","clk":"5348579263","pt":1646219026529,"mc":[{"id":"1.195453628","rc":[{"atb":[[2.44,6.87]],"id":40324291}],"con":true,"img":false}]}
{"op":"mcm","clk":"5348579832","pt":1646219032217,"mc":[{"id":"1.195453628","rc":[{"atl":[[4.9,9.3]],"id":41818958}],"con":true,"img":false}]}
{"op":"mcm","clk":"5348579843","pt":1646219032321,"mc":[{"id":"1.195453628","rc":[{"atl":[[4.7,9.08]],"id":41818958}],"con":true,"img":false}]}
{"op":"mcm","clk":"5348579867","pt":1646219032520,"mc":[{"id":"1.195453628","rc":[{"atl":[[4.8,13.16],[4.6,14.65]],"id":41818958}],"con":true,"img":false}]}
{"op":"mcm","clk":"5348580675","pt":1646219040112,"mc":[{"id":"1.195453628","rc":[{"atl":[[4.7,0]],"id":41818958}],"con":true,"img":false}]}
{"op":"mcm","clk":"5348580684","pt":1646219040215,"mc":[{"id":"1.195453628","rc":[{"atl":[[4.8,39.48],[4.9,18.39]],"id":41818958}],"con":true,"img":false}]}
{"op":"mcm","clk":"5348580695","pt":1646219040322,"mc":[{"id":"1.195453628","rc":[{"atl":[[4.6,5.56]],"id":41818958}],"con":true,"img":false}]}
{"op":"mcm","clk":"5348581465","pt":1646219047613,"mc":[{"id":"1.195453628","rc":[{"atb":[[2.1,0]],"id":39734233},{"atb":[[2.04,120.19]],"id":41818958},{"atb":[[2.2,0]],"id":38214982},{"atb":[[1.37,135.14]],"id":38761677}],"con":true,"img":false}]}
{"op":"mcm","clk":"5348582829","pt":1646219062127,"mc":[{"id":"1.195453628","rc":[{"atl":[[4.9,9.3]],"id":41818958}],"con":true,"img":false}]}
{"op":"mcm","clk":"5348582837","pt":1646219062231,"mc":[{"id":"1.195453628","rc":[{"atl":[[4.7,9.08]],"id":41818958}],"con":true,"img":false}]}
{"op":"mcm","clk":"5348582847","pt":1646219062376,"mc":[{"id":"1.195453628","rc":[{"atl":[[4.8,13.16],[4.6,14.65]],"id":41818958}],"con":true,"img":false}]}
{"op":"mcm","clk":"5348583647","pt":1646219070152,"mc":[{"id":"1.195453628","rc":[{"atl":[[4.7,0]],"id":41818958}],"con":true,"img":false}]}
{"op":"mcm","clk":"5348583659","pt":1646219070255,"mc":[{"id":"1.195453628","rc":[{"atl":[[4.9,18.39]],"id":41818958}],"con":true,"img":false}]}
{"op":"mcm","clk":"5348583673","pt":1646219070362,"mc":[{"id":"1.195453628","rc":[{"atl":[[4.8,39.48],[4.6,5.56]],"id":41818958}],"con":true,"img":false}]}
{"op":"mcm","clk":"5348584067","pt":1646219074266,"mc":[{"id":"1.195453628","rc":[{"atb":[[2.12,15.8]],"id":39734233}],"con":true,"img":false}]}
{"op":"mcm","clk":"5348584088","pt":1646219074472,"mc":[{"id":"1.195453628","rc":[{"atb":[[1.45,35.18]],"id":38761677}],"con":true,"img":false}]}
{"op":"mcm","clk":"5348584098","pt":1646219074578,"mc":[{"id":"1.195453628","rc":[{"atb":[[2.18,15.07]],"id":41818958}],"con":true,"img":false}]}
{"op":"mcm","clk":"5348584126","pt":1646219074844,"mc":[{"id":"1.195453628","rc":[{"atb":[[2.5,12.22]],"id":38214982}],"con":true,"img":false}]}
{"op":"mcm","clk":"5348586451","pt":1646219092064,"mc":[{"id":"1.195453628","rc":[{"atl":[[4.9,9.3]],"id":41818958}],"con":true,"img":false}]}
{"op":"mcm","clk":"5348586460","pt":1646219092169,"mc":[{"id":"1.195453628","rc":[{"atl":[[4.7,9.08]],"id":41818958}],"con":true,"img":false}]}
{"op":"mcm","clk":"5348586484","pt":1646219092373,"mc":[{"id":"1.195453628","rc":[{"atl":[[4.8,13.16],[4.6,14.65]],"id":41818958}],"con":true,"img":false}]}
{"op":"mcm","clk":"5348587185","pt":1646219100096,"mc":[{"id":"1.195453628","rc":[{"atl":[[4.7,0]],"id":41818958}],"con":true,"img":false}]}
{"op":"mcm","clk":"5348587197","pt":1646219100200,"mc":[{"id":"1.195453628","rc":[{"atl":[[4.9,18.39]],"id":41818958}],"con":true,"img":false}]}
{"op":"mcm","clk":"5348587208","pt":1646219100305,"mc":[{"id":"1.195453628","rc":[{"atl":[[4.8,39.48],[4.6,5.56]],"id":41818958}],"con":true,"img":false}]}
{"op":"mcm","clk":"5348589495","pt":1646219117101,"mc":[{"id":"1.195453628","rc":[{"atb":[[2.18,0]],"id":38214982}],"con":true,"img":false}]}
{"op":"mcm","clk":"5348589511","pt":1646219117217,"mc":[{"id":"1.195453628","rc":[{"atb":[[2.36,53.95]],"id":38214982}],"con":true,"img":false}]}
{"op":"mcm","clk":"5348590199","pt":1646219122141,"mc":[{"id":"1.195453628","rc":[{"atl":[[4.9,9.3]],"id":41818958}],"con":true,"img":false}]}
{"op":"mcm","clk":"5348590211","pt":1646219122245,"mc":[{"id":"1.195453628","rc":[{"atl":[[4.7,9.08]],"id":41818958}],"con":true,"img":false}]}
{"op":"mcm","clk":"5348590232","pt":1646219122402,"mc":[{"id":"1.195453628","rc":[{"atl":[[4.8,13.16],[4.6,14.65]],"id":41818958}],"con":true,"img":false}]}
{"op":"mcm","clk":"5348591254","pt":1646219129627,"mc":[{"id":"1.195453628","rc":[{"atl":[[4.7,0]],"id":41818958}],"con":true,"img":false}]}
{"op":"mcm","clk":"5348591266","pt":1646219129724,"mc":[{"id":"1.195453628","rc":[{"atl":[[4.9,18.39]],"id":41818958}],"con":true,"img":false}]}
{"op":"mcm","clk":"5348591281","pt":1646219129843,"mc":[{"id":"1.195453628","rc":[{"atl":[[4.8,39.48],[4.6,5.56]],"id":41818958}],"con":true,"img":false}]}
{"op":"mcm","clk":"5348594132","pt":1646219151578,"mc":[{"id":"1.195453628","rc":[{"atl":[[4.9,9.3]],"id":41818958}],"con":true,"img":false}]}
{"op":"mcm","clk":"5348594145","pt":1646219151684,"mc":[{"id":"1.195453628","rc":[{"atl":[[4.7,9.08]],"id":41818958}],"con":true,"img":false}]}
{"op":"mcm","clk":"5348594183","pt":1646219151890,"mc":[{"id":"1.195453628","rc":[{"atl":[[4.8,13.16]],"id":41818958}],"con":true,"img":false}]}
{"op":"mcm","clk":"5348594230","pt":1646219152157,"mc":[{"id":"1.195453628","rc":[{"atl":[[4.6,14.65]],"id":41818958}],"con":true,"img":false}]}
{"op":"mcm","clk":"5348595094","pt":1646219159104,"mc":[{"id":"1.195453628","rc":[{"atl":[[4.7,0]],"id":41818958}],"con":true,"img":false}]}
{"op":"mcm","clk":"5348595106","pt":1646219159161,"mc":[{"id":"1.195453628","rc":[{"atl":[[4.9,18.39]],"id":41818958}],"con":true,"img":false}]}
{"op":"mcm","clk":"5348595116","pt":1646219159270,"mc":[{"id":"1.195453628","rc":[{"atl":[[4.8,39.48],[4.6,5.56]],"id":41818958}],"con":true,"img":false}]}
{"op":"mcm","clk":"5348597643","pt":1646219181110,"mc":[{"id":"1.195453628","rc":[{"atl":[[4.9,9.3]],"id":41818958}],"con":true,"img":false}]}
{"op":"mcm","clk":"5348597652","pt":1646219181216,"mc":[{"id":"1.195453628","rc":[{"atl":[[4.7,9.08]],"id":41818958}],"con":true,"img":false}]}
{"op":"mcm","clk":"5348597673","pt":1646219181424,"mc":[{"id":"1.195453628","rc":[{"atl":[[4.8,13.16],[4.6,14.65]],"id":41818958}],"con":true,"img":false}]}
{"op":"mcm","clk":"5348598571","pt":1646219189130,"mc":[{"id":"1.195453628","rc":[{"atl":[[4.7,0]],"id":41818958}],"con":true,"img":false}]}
{"op":"mcm","clk":"5348598580","pt":1646219189233,"mc":[{"id":"1.195453628","rc":[{"atl":[[4.9,18.39]],"id":41818958}],"con":true,"img":false}]}
{"op":"mcm","clk":"5348598591","pt":1646219189340,"mc":[{"id":"1.195453628","rc":[{"atl":[[4.8,39.48],[4.6,5.56]],"id":41818958}],"con":true,"img":false}]}
{"op":"mcm","clk":"5348599254","pt":1646219194916,"mc":[{"id":"1.195453628","rc":[{"atb":[[1.91,21.98],[1.86,0]],"id":39734233},{"atl":[[2.96,0],[3.05,9.76]],"id":39734233},{"atb":[[2.36,53.86],[2.32,0]],"id":40324291}],"con":true,"img":false}]}
{"op":"mcm","clk":"5348600369","pt":1646219204244,"mc":[{"id":"1.195453628","rc":[{"atl":[[3,0]],"id":39734233}],"con":true,"img":false}]}
{"op":"mcm","clk":"5348600447","pt":1646219204927,"mc":[{"id":"1.195453628","rc":[{"atb":[[1.89,56.18]],"id":39734233},{"atl":[[3.15,23.26]],"id":39734233},{"atb":[[2.32,37.88]],"id":40324291}],"con":true,"img":false}]}
{"op":"mcm","clk":"5348601168","pt":1646219211177,"mc":[{"id":"1.195453628","rc":[{"atl":[[4.9,9.3]],"id":41818958}],"con":true,"img":false}]}
{"op":"mcm","clk":"5348601179","pt":1646219211236,"mc":[{"id":"1.195453628","rc":[{"atl":[[4.7,9.08]],"id":41818958}],"con":true,"img":false}]}
{"op":"mcm","clk":"5348601199","pt":1646219211441,"mc":[{"id":"1.195453628","rc":[{"atl":[[4.8,13.16],[4.6,14.65]],"id":41818958}],"con":true,"img":false}]}
{"op":"mcm","clk":"5348601647","pt":1646219214958,"mc":[{"id":"1.195453628","rc":[{"atb":[[1.84,0],[1.87,86.21],[1.82,0],[1.8,0]],"id":39734233},{"atl":[[3.25,33.33]],"id":39734233},{"spn":2.58,"spf":"NaN","id":39734233},{"atb":[[2.28,58.59],[2.2,83.18]],"id":40324291}],"con":true,"img":false}]}
{"op":"mcm","clk":"5348602197","pt":1646219219553,"mc":[{"id":"1.195453628","rc":[{"atl":[[4.7,0]],"id":41818958}],"con":true,"img":false}]}
{"op":"mcm","clk":"5348602210","pt":1646219219653,"mc":[{"id":"1.195453628","rc":[{"atl":[[4.9,18.39]],"id":41818958}],"con":true,"img":false}]}
{"op":"mcm","clk":"5348602220","pt":1646219219764,"mc":[{"id":"1.195453628","rc":[{"atl":[[4.8,39.48],[4.6,5.56]],"id":41818958}],"con":true,"img":false}]}
{"op":"mcm","clk":"5348602869","pt":1646219224981,"mc":[{"id":"1.195453628","rc":[{"atb":[[1.85,147.06]],"id":39734233},{"atl":[[3.2,0],[3.1,0],[3.35,71.74]],"id":39734233},{"atb":[[2.24,100.81]],"id":40324291}],"con":true,"img":false}]}
{"op":"mcm","clk":"5348602930","pt":1646219225663,"mc":[{"id":"1.195453628","rc":[{"atb":[[2.36,0]],"id":38214982}],"con":true,"img":false}]}
{"op":"mcm","clk":"5348602939","pt":1646219225762,"mc":[{"id":"1.195453628","rc":[{"atb":[[2.18,53.95]],"id":38214982}],"con":true,"img":false}]}
{"op":"mcm","clk":"5348604733","pt":1646219241689,"mc":[{"id":"1.195453628","rc":[{"atl":[[4.9,9.3]],"id":41818958}],"con":true,"img":false}]}
{"op":"mcm","clk":"5348604744","pt":1646219241842,"mc":[{"id":"1.195453628","rc":[{"atl":[[4.7,9.08]],"id":41818958}],"con":true,"img":false}]}
{"op":"mcm","clk":"5348604767","pt":1646219242003,"mc":[{"id":"1.195453628","rc":[{"atl":[[4.8,13.16],[4.6,14.65]],"id":41818958}],"con":true,"img":false}]}
{"op":"mcm","clk":"5348605677","pt":1646219249623,"mc":[{"id":"1.195453628","rc":[{"atl":[[4.7,0]],"id":41818958}],"con":true,"img":false}]}
{"op":"mcm","clk":"5348605685","pt":1646219249723,"mc":[{"id":"1.195453628","rc":[{"atl":[[4.9,18.39]],"id":41818958}],"con":true,"img":false}]}
{"op":"mcm","clk":"5348605696","pt":1646219249829,"mc":[{"id":"1.195453628","rc":[{"atl":[[4.8,39.48],[4.6,5.56]],"id":41818958}],"con":true,"img":false}]}
{"op":"mcm","clk":"5348608373","pt":1646219271526,"mc":[{"id":"1.195453628","rc":[{"atl":[[4.9,9.3]],"id":41818958}],"con":true,"img":false}]}
{"op":"mcm","clk":"5348608386","pt":1646219271632,"mc":[{"id":"1.195453628","rc":[{"atl":[[4.7,9.08]],"id":41818958}],"con":true,"img":false}]}
{"op":"mcm","clk":"5348608397","pt":1646219271735,"mc":[{"id":"1.195453628","rc":[{"atl":[[4.6,14.65]],"id":41818958}],"con":true,"img":false}]}
{"op":"mcm","clk":"5348608406","pt":1646219271843,"mc":[{"id":"1.195453628","rc":[{"atl":[[4.8,13.16]],"id":41818958}],"con":true,"img":false}]}
{"op":"mcm","clk":"5348609397","pt":1646219279678,"mc":[{"id":"1.195453628","rc":[{"atl":[[4.7,0]],"id":41818958}],"con":true,"img":false}]}
{"op":"mcm","clk":"5348609409","pt":1646219279780,"mc":[{"id":"1.195453628","rc":[{"atl":[[4.9,18.39]],"id":41818958}],"con":true,"img":false}]}
{"op":"mcm","clk":"5348609421","pt":1646219279884,"mc":[{"id":"1.195453628","rc":[{"atl":[[4.8,39.48],[4.6,5.56]],"id":41818958}],"con":true,"img":false}]}
{"op":"mcm","clk":"5348612156","pt":1646219301622,"mc":[{"id":"1.195453628","rc":[{"atl":[[4.9,9.3]],"id":41818958}],"con":true,"img":false}]}
{"op":"mcm","clk":"5348612170","pt":1646219301687,"mc":[{"id":"1.195453628","rc":[{"atl":[[4.7,9.08]],"id":41818958}],"con":true,"img":false}]}
{"op":"mcm","clk":"5348612199","pt":1646219301895,"mc":[{"id":"1.195453628","rc":[{"atl":[[4.8,13.16],[4.6,14.65]],"id":41818958}],"con":true,"img":false}]}
{"op":"mcm","clk":"5348613159","pt":1646219309629,"mc":[{"id":"1.195453628","rc":[{"atl":[[4.7,0]],"id":41818958}],"con":true,"img":false}]}
{"op":"mcm","clk":"5348613170","pt":1646219309691,"mc":[{"id":"1.195453628","rc":[{"atl":[[4.9,18.39]],"id":41818958}],"con":true,"img":false}]}
{"op":"mcm","clk":"5348613181","pt":1646219309796,"mc":[{"id":"1.195453628","rc":[{"atl":[[4.8,39.48],[4.6,5.56]],"id":41818958}],"con":true,"img":false}]}
{"op":"mcm","clk":"5348613332","pt":1646219311116,"mc":[{"id":"1.195453628","rc":[{"atb":[[2.36,47.74]],"id":40324291}],"con":true,"img":false}]}
{"op":"mcm","clk":"5348614977","pt":1646219324344,"mc":[{"id":"1.195453628","rc":[{"atb":[[1.99,101.01],[2.06,0]],"id":39734233},{"atl":[[3.4,0],[3.55,39.22]],"id":39734233},{"atb":[[1.79,126.58],[1.93,107.33]],"id":41818958},{"atb":[[2.46,13.7],[2.34,167.91]],"id":38214982},{"atb":[[2.36,14.71],[2.24,181.46]],"id":40324291}],"con":true,"img":false}]}
{"op":"mcm","clk":"5348615839","pt":1646219331647,"mc":[{"id":"1.195453628","rc":[{"atl":[[4.9,9.3]],"id":41818958}],"con":true,"img":false}]}
{"op":"mcm","clk":"5348615851","pt":1646219331751,"mc":[{"id":"1.195453628","rc":[{"atl":[[4.7,9.08]],"id":41818958}],"con":true,"img":false}]}
{"op":"mcm","clk":"5348615877","pt":1646219331961,"mc":[{"id":"1.195453628","rc":[{"atl":[[4.8,13.16],[4.7,20.2]],"id":41818958}],"con":true,"img":false}]}
{"op":"mcm","clk":"5348615903","pt":1646219332177,"mc":[{"id":"1.195453628","rc":[{"atb":[[2.08,0]],"id":39734233},{"atb":[[2.38,0]],"id":40324291}],"con":true,"img":false}]}
{"op":"mcm","clk":"5348615913","pt":1646219332239,"mc":[{"id":"1.195453628","rc":[{"atb":[[2,40.36]],"id":39734233},{"atb":[[2.34,33.03]],"id":40324291}],"con":true,"img":false}]}
{"op":"mcm","clk":"5348616186","pt":1646219334451,"mc":[{"id":"1.195453628","rc":[{"atb":[[2.12,9.1]],"id":39734233},{"atb":[[2.44,1.66]],"id":40324291}],"con":true,"img":false}]}
{"op":"mcm","clk":"5348616824","pt":1646219339654,"mc":[{"id":"1.195453628","rc":[{"atl":[[4.7,11.12]],"id":41818958}],"con":true,"img":false}]}
{"op":"mcm","clk":"5348616842","pt":1646219339757,"mc":[{"id":"1.195453628","rc":[{"atl":[[4.9,18.39]],"id":41818958},{"atb":[[2.44,0]],"id":40324291},{"spn":2.36,"spf":1.0,"id":40324291}],"con":true,"img":false}]}
{"op":"mcm","clk":"5348616854","pt":1646219339868,"mc":[{"id":"1.195453628","rc":[{"atl":[[4.8,29.84],[4.7,0]],"id":41818958}],"con":true,"img":false}]}
{"op":"mcm","clk":"5348616870","pt":1646219339979,"mc":[{"id":"1.195453628","rc":[{"atb":[[2.38,1.66]],"id":40324291}],"con":true,"img":false}]}
{"op":"mcm","clk":"5348616925","pt":1646219340350,"mc":[{"id":"1.195453628","rc":[{"atb":[[2.04,7.22]],"id":39734233},{"atb":[[2.4,5.36]],"id":40324291}],"con":true,"img":false}]}
{"op":"mcm","clk":"5348618211","pt":1646219350672,"mc":[{"id":"1.195453628","rc":[{"atb":[[2.38,7.7]],"id":40324291}],"con":true,"img":false}]}
{"op":"mcm","clk":"5348618701","pt":1646219354891,"mc":[{"id":"1.195453628","rc":[{"atb":[[1.79,0]],"id":41818958}],"con":true,"img":false}]}
{"op":"mcm","clk":"5348618713","pt":1646219354991,"mc":[{"id":"1.195453628","rc":[{"atb":[[1.99,0],[2.04,47.59]],"id":39734233},{"atl":[[3.55,0],[3.3,43.48]],"id":39734233},{"atb":[[1.93,214.86]],"id":41818958},{"atb":[[2.46,48.91],[2.34,93.28]],"id":38214982},{"atb":[[2.36,47.74],[2.24,100.81]],"id":40324291}],"con":true,"img":false}]}
{"op":"mcm","clk":"5348618783","pt":1646219355677,"mc":[{"id":"1.195453628","rc":[{"atb":[[2.04,40.37]],"id":39734233},{"atb":[[2.5,7.22]],"id":38214982},{"atb":[[2.4,0]],"id":40324291}],"con":true,"img":false}]}
{"op":"mcm","clk":"5348619431","pt":1646219361411,"mc":[{"id":"1.195453628","rc":[{"atb":[[2.08,6.95]],"id":39734233},{"atb":[[2.52,4.93]],"id":38214982},{"atb":[[2.42,5.28]],"id":40324291}],"con":true,"img":false}]}
{"op":"mcm","clk":"5348619457","pt":1646219361626,"mc":[{"id":"1.195453628","rc":[{"atl":[[4.9,9.3]],"id":41818958}],"con":true,"img":false}]}
{"op":"mcm","clk":"5348619470","pt":1646219361677,"mc":[{"id":"1.195453628","rc":[{"atl":[[4.7,9.08]],"id":41818958}],"con":true,"img":false}]}
{"op":"mcm","clk":"5348619487","pt":1646219361787,"mc":[{"id":"1.195453628","rc":[{"atl":[[4.8,13.16],[4.6,14.65]],"id":41818958}],"con":true,"img":false}]}
{"op":"mcm","clk":"5348620361","pt":1646219369411,"mc":[{"id":"1.195453628","rc":[{"atb":[[2.12,1.66]],"id":39734233}],"con":true,"img":false}]}
{"op":"mcm","clk":"5348620390","pt":1646219369619,"mc":[{"id":"1.195453628","rc":[{"atl":[[4.7,0]],"id":41818958}],"con":true,"img":false}]}
{"op":"mcm","clk":"5348620410","pt":1646219369723,"mc":[{"id":"1.195453628","rc":[{"atl":[[4.9,18.39]],"id":41818958}],"con":true,"img":false}]}
{"op":"mcm","clk":"5348620425","pt":1646219369822,"mc":[{"id":"1.195453628","rc":[{"atl":[[4.8,39.48],[4.6,5.56]],"id":41818958}],"con":true,"img":false}]}
{"op":"mcm","clk":"5348620467","pt":1646219370097,"mc":[{"id":"1.195453628","rc":[{"atl":[[6.6,0]],"id":38214982}],"con":true,"img":false}]}
{"op":"mcm","clk":"5348620484","pt":1646219370197,"mc":[{"id":"1.195453628","rc":[{"atl":[[7.2,7.78]],"id":38214982}],"con":true,"img":false}]}
{"op":"mcm","clk":"5348621047","pt":1646219375100,"mc":[{"id":"1.195453628","rc":[{"atl":[[3.35,53.19]],"id":39734233}],"con":true,"img":false}]}
{"op":"mcm","clk":"5348621059","pt":1646219375232,"mc":[{"id":"1.195453628","rc":[{"atl":[[3.2,18.55]],"id":39734233}],"con":true,"img":false}]}
{"op":"mcm","clk":"5348621221","pt":1646219376611,"mc":[{"id":"1.195453628","rc":[{"atb":[[2,0]],"id":39734233},{"atb":[[2.34,0]],"id":40324291}],"con":true,"img":false}]}
{"op":"mcm","clk":"5348621236","pt":1646219376713,"mc":[{"id":"1.195453628","rc":[{"atb":[[2.06,40.36]],"id":39734233},{"atb":[[2.38,40.73]],"id":40324291}],"con":true,"img":false}]}
{"op":"mcm","clk":"5348621332","pt":1646219377510,"mc":[{"id":"1.195453628","rc":[{"atb":[[2.08,0]],"id":39734233},{"atb":[[2.42,0]],"id":40324291}],"con":true,"img":false}]}
{"op":"mcm","clk":"5348621341","pt":1646219377606,"mc":[{"id":"1.195453628","rc":[{"atb":[[2.44,0]],"id":38214982}],"con":true,"img":false}]}
{"op":"mcm","clk":"5348621351","pt":1646219377704,"mc":[{"id":"1.195453628","rc":[{"atb":[[2.48,40.36]],"id":38214982}],"con":true,"img":false}]}
{"op":"mcm","clk":"5348621452","pt":1646219378709,"mc":[{"id":"1.195453628","rc":[{"atb":[[2.12,0]],"id":39734233},{"atb":[[2.5,5.55]],"id":38214982}],"con":true,"img":false}]}
{"op":"mcm","clk":"5348621475","pt":1646219378910,"mc":[{"id":"1.195453628","rc":[{"atb":[[2.08,1.66]],"id":39734233},{"atb":[[2.54,1.66]],"id":38214982}],"con":true,"img":false}]}
{"op":"mcm","clk":"5348621884","pt":1646219382639,"mc":[{"id":"1.195453628","rc":[{"atb":[[2.1,6.82]],"id":39734233},{"atb":[[2.52,0]],"id":38214982},{"atb":[[2.44,5.21]],"id":40324291}],"con":true,"img":false}]}
{"op":"mcm","clk":"5348622043","pt":1646219383942,"mc":[{"id":"1.195453628","rc":[{"atb":[[2.5,0]],"id":38214982},{"atb":[[2.38,34.69]],"id":40324291}],"con":true,"img":false}]}
{"op":"mcm","clk":"5348622710","pt":1646219389470,"mc":[{"id":"1.195453628","rc":[{"atb":[[2.54,6.53]],"id":38214982}],"con":true,"img":false}]}
{"op":"mcm","clk":"5348623007","pt":1646219391632,"mc":[{"id":"1.195453628","rc":[{"atl":[[4.9,9.3]],"id":41818958}],"con":true,"img":false}]}
{"op":"mcm","clk":"5348623025","pt":1646219391733,"mc":[{"id":"1.195453628","rc":[{"atl":[[4.7,9.08]],"id":41818958}],"con":true,"img":false}]}
{"op":"mcm","clk":"5348623069","pt":1646219392148,"mc":[{"id":"1.195453628","rc":[{"atl":[[4.8,13.16],[4.6,14.65]],"id":41818958}],"con":true,"img":false}]}
{"op":"mcm","clk":"5348623820","pt":1646219398341,"mc":[{"id":"1.195453628","rc":[{"atb":[[2.54,11.94]],"id":38214982}],"con":true,"img":false}]}
{"op":"mcm","clk":"5348623841","pt":1646219398546,"mc":[{"id":"1.195453628","rc":[{"atb":[[2.44,10.99]],"id":40324291}],"con":true,"img":false}]}
{"op":"mcm","clk":"5348623876","pt":1646219398852,"mc":[{"id":"1.195453628","rc":[{"atb":[[2.08,0]],"id":39734233},{"atb":[[2.38,33.03]],"id":40324291}],"con":true,"img":false}]}
{"op":"mcm","clk":"5348623898","pt":1646219399060,"mc":[{"id":"1.195453628","rc":[{"atb":[[2.12,1.66]],"id":39734233},{"atb":[[2.46,1.66]],"id":40324291}],"con":true,"img":false}]}
{"op":"mcm","clk":"5348623911","pt":1646219399163,"mc":[{"id":"1.195453628","rc":[{"atl":[[7.2,0]],"id":38214982}],"con":true,"img":false}]}
{"op":"mcm","clk":"5348623918","pt":1646219399227,"mc":[{"id":"1.195453628","rc":[{"atl":[[6.6,7.78]],"id":38214982}],"con":true,"img":false}]}
{"op":"mcm","clk":"5348623942","pt":1646219399435,"mc":[{"id":"1.195453628","rc":[{"atb":[[2.1,14.39]],"id":39734233}],"con":true,"img":false}]}
{"op":"mcm","clk":"5348623962","pt":1646219399640,"mc":[{"id":"1.195453628","rc":[{"atl":[[4.7,0]],"id":41818958}],"con":true,"img":false}]}
{"op":"mcm","clk":"5348623978","pt":1646219399750,"mc":[{"id":"1.195453628","rc":[{"atl":[[4.9,18.39]],"id":41818958}],"con":true,"img":false}]}
{"op":"mcm","clk":"5348623990","pt":1646219399847,"mc":[{"id":"1.195453628","rc":[{"atl":[[4.8,39.48],[4.6,5.56]],"id":41818958},{"spn":3.97,"spf":"NaN","id":38214982},{"spn":2.44,"spf":1.0,"id":40324291}],"con":true,"img":false}]}
{"op":"mcm","clk":"5348624351","pt":1646219403092,"mc":[{"id":"1.195453628","rc":[{"atb":[[2.06,80.73],[2.04,0]],"id":39734233}],"con":true,"img":false}]}
{"op":"mcm","clk":"5348625275","pt":1646219411183,"mc":[{"id":"1.195453628","rc":[{"atl":[[3.2,0]],"id":39734233}],"con":true,"img":false}]}
{"op":"mcm","clk":"5348625284","pt":1646219411258,"mc":[{"id":"1.195453628","rc":[{"atl":[[3.25,51.88]],"id":39734233}],"con":true,"img":false}]}
{"op":"mcm","clk":"5348626583","pt":1646219421601,"mc":[{"id":"1.195453628","rc":[{"atl":[[4.9,9.3]],"id":41818958}],"con":true,"img":false}]}
{"op":"mcm","clk":"5348626594","pt":1646219421665,"mc":[{"id":"1.195453628","rc":[{"atl":[[4.7,9.08]],"id":41818958}],"con":true,"img":false}]}
{"op":"mcm","clk":"5348626611","pt":1646219421766,"mc":[{"id":"1.195453628","rc":[{"atl":[[4.6,14.65]],"id":41818958}],"con":true,"img":false}]}
{"op":"mcm","clk":"5348626627","pt":1646219421872,"mc":[{"id":"1.195453628","rc":[{"atl":[[4.8,13.16]],"id":41818958}],"con":true,"img":false}]}
{"op":"mcm","clk":"5348627554","pt":1646219429395,"mc":[{"id":"1.195453628","rc":[{"atb":[[2.44,5.21]],"id":40324291}],"con":true,"img":false}]}
{"op":"mcm","clk":"5348627603","pt":1646219429605,"mc":[{"id":"1.195453628","rc":[{"atl":[[4.7,0]],"id":41818958}],"con":true,"img":false}]}
{"op":"mcm","clk":"5348627620","pt":1646219429707,"mc":[{"id":"1.195453628","rc":[{"atl":[[4.9,18.39]],"id":41818958}],"con":true,"img":false}]}
{"op":"mcm","clk":"5348627629","pt":1646219429806,"mc":[{"id":"1.195453628","rc":[{"atl":[[4.8,39.48],[4.6,5.56]],"id":41818958}],"con":true,"img":false}]}
{"op":"mcm","clk":"5348629116","pt":1646219442725,"mc":[{"id":"1.195453628","rc":[{"atb":[[2.42,5.86]],"id":40324291}],"con":true,"img":false}]}
{"op":"mcm","clk":"5348630146","pt":1646219451638,"mc":[{"id":"1.195453628","rc":[{"atl":[[4.9,9.3]],"id":41818958}],"con":true,"img":false}]}
{"op":"mcm","clk":"5348630157","pt":1646219451749,"mc":[{"id":"1.195453628","rc":[{"atl":[[4.7,9.08]],"id":41818958}],"con":true,"img":false}]}
{"op":"mcm","clk":"5348630187","pt":1646219451953,"mc":[{"id":"1.195453628","rc":[{"atl":[[4.8,13.16],[4.6,14.65]],"id":41818958}],"con":true,"img":false}]}
{"op":"mcm","clk":"5348631061","pt":1646219459653,"mc":[{"id":"1.195453628","rc":[{"atl":[[4.7,0]],"id":41818958}],"con":true,"img":false}]}
{"op":"mcm","clk":"5348631075","pt":1646219459756,"mc":[{"id":"1.195453628","rc":[{"atl":[[4.9,18.39]],"id":41818958}],"con":true,"img":false}]}
{"op":"mcm","clk":"5348631086","pt":1646219459869,"mc":[{"id":"1.195453628","rc":[{"atl":[[4.8,39.48],[4.6,5.56]],"id":41818958}],"con":true,"img":false}]}
{"op":"mcm","clk":"5348633770","pt":1646219481698,"mc":[{"id":"1.195453628","rc":[{"atl":[[4.9,9.3]],"id":41818958}],"con":true,"img":false}]}
{"op":"mcm","clk":"5348633787","pt":1646219481801,"mc":[{"id":"1.195453628","rc":[{"atl":[[4.7,9.08]],"id":41818958}],"con":true,"img":false}]}
{"op":"mcm","clk":"5348633811","pt":1646219481965,"mc":[{"id":"1.195453628","rc":[{"atl":[[4.8,13.16],[4.6,14.65]],"id":41818958}],"con":true,"img":false}]}
{"op":"mcm","clk":"5348634751","pt":1646219490080,"mc":[{"id":"1.195453628","rc":[{"atl":[[4.7,0]],"id":41818958}],"con":true,"img":false}]}
{"op":"mcm","clk":"5348634762","pt":1646219490197,"mc":[{"id":"1.195453628","rc":[{"atl":[[4.9,18.39]],"id":41818958}],"con":true,"img":false}]}
{"op":"mcm","clk":"5348634773","pt":1646219490307,"mc":[{"id":"1.195453628","rc":[{"atl":[[4.8,39.48],[4.6,5.56]],"id":41818958}],"con":true,"img":false}]}
{"op":"mcm","clk":"5348636452","pt":1646219502735,"mc":[{"id":"1.195453628","rc":[{"atb":[[2.46,13.7],[2.44,69.44]],"id":38214982}],"con":true,"img":false}]}
{"op":"mcm","clk":"5348636747","pt":1646219505018,"mc":[{"id":"1.195453628","rc":[{"atl":[[4.6,0],[4.2,6.25]],"id":41818958},{"atl":[[8.2,0],[8.4,2.7]],"id":38214982},{"atl":[[9.2,0],[8.8,0],[7,20]],"id":38761677},{"atl":[[7.4,0],[7.6,3.03]],"id":40324291}],"con":true,"img":false}]}
{"op":"mcm","clk":"5348637701","pt":1646219512131,"mc":[{"id":"1.195453628","rc":[{"atl":[[4.9,9.3]],"id":41818958}],"con":true,"img":false}]}
{"op":"mcm","clk":"5348637716","pt":1646219512234,"mc":[{"id":"1.195453628","rc":[{"atl":[[4.7,9.08]],"id":41818958}],"con":true,"img":false}]}
{"op":"mcm","clk":"5348637730","pt":1646219512436,"mc":[{"id":"1.195453628","rc":[{"atl":[[4.8,13.16],[4.6,12.5]],"id":41818958}],"con":true,"img":false}]}
{"op":"mcm","clk":"5348638061","pt":1646219515016,"mc":[{"id":"1.195453628","rc":[{"atl":[[4.4,14.71]],"id":41818958},{"atl":[[8.8,15.71]],"id":38214982},{"atl":[[7.4,7.81]],"id":38761677},{"atl":[[8,7.14]],"id":40324291}],"con":true,"img":false}]}
{"op":"mcm","clk":"5348638676","pt":1646219520166,"mc":[{"id":"1.195453628","rc":[{"atl":[[4.7,0]],"id":41818958},{"spn":3.19,"spf":"NaN","id":41818958}],"con":true,"img":false}]}
{"op":"mcm","clk":"5348638688","pt":1646219520221,"mc":[{"id":"1.195453628","rc":[{"atl":[[4.9,18.39]],"id":41818958}],"con":true,"img":false}]}
{"op":"mcm","clk":"5348639387","pt":1646219525072,"mc":[{"id":"1.195453628","rc":[{"atl":[[4.6,33.33],[5.2,0]],"id":41818958},{"atl":[[8.6,0],[9,0],[9.2,9.15],[9.4,0]],"id":38214982},{"atl":[[9.6,0],[10,0],[11,0],[7.8,11.03]],"id":38761677},{"atl":[[8.6,0],[8.2,0],[7.8,0],[8.4,10.14]],"id":40324291}],"con":true,"img":false}]}
{"op":"mcm","clk":"5348640664","pt":1646219535083,"mc":[{"id":"1.195453628","rc":[{"atl":[[4.8,32.89],[5,0]],"id":41818958},{"atl":[[9.6,14.53]],"id":38214982},{"atl":[[8.2,17.36]],"id":38761677},{"atl":[[8.8,16.03]],"id":40324291}],"con":true,"img":false}]}
{"op":"mcm","clk":"5348642319","pt":1646219548132,"mc":[{"id":"1.195453628","rc":[{"atl":[[4.9,9.3]],"id":41818958}],"con":true,"img":false}]}
{"op":"mcm","clk":"5348642332","pt":1646219548183,"mc":[{"id":"1.195453628","rc":[{"atl":[[4.5,9.08]],"id":41818958}],"con":true,"img":false}]}
{"op":"mcm","clk":"5348642352","pt":1646219548393,"mc":[{"id":"1.195453628","rc":[{"atl":[[4.6,20.83],[4.4,29.42]],"id":41818958}],"con":true,"img":false}]}
{"op":"mcm","clk":"5348643439","pt":1646219557592,"mc":[{"id":"1.195453628","rc":[{"atb":[[2.18,0]],"id":38214982}],"con":true,"img":false}]}
{"op":"mcm","clk":"5348643453","pt":1646219557696,"mc":[{"id":"1.195453628","rc":[{"atb":[[2.36,53.95]],"id":38214982}],"con":true,"img":false}]}
{"op":"mcm","clk":"5348644831","pt":1646219570104,"mc":[{"id":"1.195453628","rc":[{"atl":[[4.5,0],[4.3,13.21]],"id":41818958}],"con":true,"img":false}]}
{"op":"mcm","clk":"5348650166","pt":1646219622797,"mc":[{"id":"1.195453628","rc":[{"atb":[[1.99,101.01],[2.06,40.36]],"id":39734233},{"atl":[[3.55,39.22],[3.3,0]],"id":39734233},{"atb":[[1.79,126.58],[1.93,107.33]],"id":41818958},{"atl":[[4.4,14.71],[4.7,27.03]],"id":41818958},{"atb":[[2.44,0],[2.34,167.91]],"id":38214982},{"atb":[[2.36,14.71],[2.24,181.46]],"id":40324291}],"con":true,"img":false}]}
{"op":"mcm","clk":"5348650207","pt":1646219623176,"mc":[{"id":"1.195453628","rc":[{"atb":[[2.36,0]],"id":38214982}],"con":true,"img":false}]}
{"op":"mcm","clk":"5348650217","pt":1646219623276,"mc":[{"id":"1.195453628","rc":[{"atb":[[2.18,53.95]],"id":38214982}],"con":true,"img":false}]}
{"op":"mcm","clk":"5348650959","pt":1646219630119,"mc":[{"id":"1.195453628","rc":[{"atb":[[2.06,0]],"id":39734233},{"atl":[[3.25,33.33]],"id":39734233},{"atl":[[4.3,0]],"id":41818958},{"atb":[[2.38,0]],"id":40324291}],"con":true,"img":false}]}
{"op":"mcm","clk":"5348650971","pt":1646219630223,"mc":[{"id":"1.195453628","rc":[{"atb":[[2,40.36]],"id":39734233},{"atl":[[3.3,18.55]],"id":39734233},{"atl":[[4.5,13.21]],"id":41818958},{"atb":[[2.34,33.03]],"id":40324291}],"con":true,"img":false}]}
{"op":"mcm","clk":"5348651342","pt":1646219633527,"mc":[{"id":"1.195453628","rc":[{"atb":[[2.1,7.57]],"id":39734233},{"atb":[[2.44,0]],"id":40324291}],"con":true,"img":false}]}
{"op":"mcm","clk":"5348651496","pt":1646219634941,"mc":[{"id":"1.195453628","rc":[{"atb":[[1.99,0],[2.1,47.94]],"id":39734233},{"atl":[[3.4,41.67],[3.55,0]],"id":39734233},{"atb":[[1.79,0],[1.94,106.38]],"id":41818958},{"atl":[[4.4,29.42],[4.7,0]],"id":41818958},{"atb":[[2.46,66.01],[2.34,93.28]],"id":38214982},{"atb":[[2.24,100.81],[2.34,70.91]],"id":40324291}],"con":true,"img":false}]}
{"op":"mcm","clk":"5348651721","pt":1646219636927,"mc":[{"id":"1.195453628","rc":[{"atb":[[2.46,0]],"id":40324291}],"con":true,"img":false}]}
{"op":"mcm","clk":"5348651742","pt":1646219637135,"mc":[{"id":"1.195453628","rc":[{"atb":[[2.44,1.66]],"id":40324291}],"con":true,"img":false}]}
{"op":"mcm","clk":"5348652274","pt":1646219641837,"mc":[{"id":"1.195453628","rc":[{"atb":[[2.16,2.16]],"id":39734233},{"atb":[[2.24,2.16]],"id":41818958},{"atb":[[2.6,2.16]],"id":38214982},{"atb":[[1.48,2.16]],"id":38761677},{"atb":[[2.42,8.02]],"id":40324291}],"con":true,"img":false}]}
{"op":"mcm","clk":"5348653392","pt":1646219651340,"mc":[{"id":"1.195453628","rc":[{"atb":[[2.1,40.37]],"id":39734233},{"atb":[[2.42,2.16]],"id":40324291}],"con":true,"img":false}]}
{"op":"mcm","clk":"5348653616","pt":1646219653132,"mc":[{"id":"1.195453628","rc":[{"atl":[[12,0]],"id":27868829}],"con":true,"img":false}]}
{"op":"mcm","clk":"5348653625","pt":1646219653230,"mc":[{"id":"1.195453628","rc":[{"atl":[[11,3.96]],"id":27868829}],"con":true,"img":false}]}
{"op":"mcm","clk":"5348653988","pt":1646219656631,"mc":[{"id":"1.195453628","rc":[{"atl":[[4.5,0]],"id":41818958}],"con":true,"img":false}]}
{"op":"mcm","clk":"5348653994","pt":1646219656733,"mc":[{"id":"1.195453628","rc":[{"atl":[[4.3,13.21],[4.6,48.61]],"id":41818958}],"con":true,"img":false}]}
{"op":"mcm","clk":"5348654005","pt":1646219656839,"mc":[{"id":"1.195453628","rc":[{"atb":[[2.12,0]],"id":39734233},{"atb":[[2.18,13.41]],"id":41818958},{"atl":[[4.4,14.71]],"id":41818958},{"atb":[[2.54,10.27]],"id":38214982}],"con":true,"img":false}]}
{"op":"mcm","clk":"5348654028","pt":1646219657074,"mc":[{"id":"1.195453628","rc":[{"atb":[[2.18,1.66]],"id":39734233},{"atb":[[2.26,1.66]],"id":41818958},{"atb":[[2.62,1.66]],"id":38214982}],"con":true,"img":false}]}
{"op":"mcm","clk":"5348654038","pt":1646219657133,"mc":[{"id":"1.195453628","rc":[{"atb":[[2,0]],"id":39734233}],"con":true,"img":false}]}
{"op":"mcm","clk":"5348654057","pt":1646219657343,"mc":[{"id":"1.195453628","rc":[{"atb":[[2.12,40.36]],"id":39734233}],"con":true,"img":false}]}
{"op":"mcm","clk":"5348654779","pt":1646219664185,"mc":[{"id":"1.195453628","rc":[{"atl":[[4.3,0]],"id":41818958}],"con":true,"img":false}]}
{"op":"mcm","clk":"5348654796","pt":1646219664245,"mc":[{"id":"1.195453628","rc":[{"atl":[[4.5,13.21]],"id":41818958}],"con":true,"img":false}]}
{"op":"mcm","clk":"5348655284","pt":1646219668599,"mc":[{"id":"1.195453628","rc":[{"atl":[[4.6,20.83],[4.4,29.42]],"id":41818958}],"con":true,"img":false}]}
{"op":"mcm","clk":"5348655374","pt":1646219669274,"mc":[{"id":"1.195453628","rc":[{"atb":[[2.4,5.94]],"id":40324291}],"con":true,"img":false}]}
{"op":"mcm","clk":"5348656230","pt":1646219677206,"mc":[{"id":"1.195453628","rc":[{"atb":[[2.18,0]],"id":38214982}],"con":true,"img":false}]}
{"op":"mcm","clk":"5348656242","pt":1646219677264,"mc":[{"id":"1.195453628","rc":[{"atb":[[2.36,53.95]],"id":38214982}],"con":true,"img":false}]}
{"op":"mcm","clk":"5348656599","pt":1646219680594,"mc":[{"id":"1.195453628","rc":[{"atb":[[4.2,0]],"id":27868829}],"con":true,"img":false}]}
{"op":"mcm","clk":"5348656614","pt":1646219680701,"mc":[{"id":"1.195453628","rc":[{"atb":[[4.4,12.11]],"id":27868829}],"con":true,"img":false}]}
{"op":"mcm","clk":"5348657143","pt":1646219685306,"mc":[{"id":"1.195453628","rc":[{"atb":[[2.16,9.34]],"id":39734233},{"spn":2.61,"spf":"NaN","id":39734233},{"spn":3.23,"spf":"NaN","id":41818958},{"spn":4.01,"spf":"NaN","id":38214982},{"spn":2.01,"spf":"NaN","id":38761677},{"spn":2.41,"spf":1.0,"id":40324291}],"con":true,"img":false}]}
{"op":"mcm","clk":"5348657638","pt":1646219690629,"mc":[{"id":"1.195453628","rc":[{"atl":[[4.5,0]],"id":41818958}],"con":true,"img":false}]}
{"op":"mcm","clk":"5348657652","pt":1646219690730,"mc":[{"id":"1.195453628","rc":[{"atl":[[4.3,13.21]],"id":41818958}],"con":true,"img":false}]}
{"op":"mcm","clk":"5348657665","pt":1646219690834,"mc":[{"id":"1.195453628","rc":[{"atl":[[4.6,48.61],[4.4,14.71]],"id":41818958}],"con":true,"img":false}]}
{"op":"mcm","clk":"5348657679","pt":1646219690945,"mc":[{"id":"1.195453628","rc":[{"atl":[[4.3,34.04],[4.6,20.83]],"id":41818958}],"con":true,"img":false}]}
{"op":"mcm","clk":"5348658992","pt":1646219702735,"mc":[{"id":"1.195453628","rc":[{"atb":[[2.16,15.81]],"id":39734233},{"atb":[[2.4,11.3]],"id":40324291}],"con":true,"img":false}]}
{"op":"mcm","clk":"5348665805","pt":1646219760124,"mc":[{"id":"1.195453628","rc":[{"atl":[[3.2,9.09],[3.15,0],[3.05,0]],"id":39734233},{"spn":2.69,"spf":"NaN","id":39734233},{"atb":[[2.12,17.86],[2.16,0]],"id":41818958},{"atl":[[9.2,2.44],[8.8,9.3],[8.4,0]],"id":38214982},{"atb":[[2.36,0],[2.34,85.84]],"id":40324291}],"con":true,"img":false}]}
{"op":"mcm","clk":"5348666646","pt":1646219768159,"mc":[{"id":"1.195453628","rc":[{"atb":[[2.14,0]],"id":41818958}],"con":true,"img":false}]}
{"op":"mcm","clk":"5348666661","pt":1646219768266,"mc":[{"id":"1.195453628","rc":[{"atb":[[2.1,44.04]],"id":41818958}],"con":true,"img":false}]}
{"op":"mcm","clk":"5348666738","pt":1646219768945,"mc":[{"id":"1.195453628","rc":[{"atb":[[2.18,7.05]],"id":41818958}],"con":true,"img":false}]}
{"op":"mcm","clk":"5348666870","pt":1646219770152,"mc":[{"id":"1.195453628","rc":[{"atl":[[3.3,40.29]],"id":39734233},{"atb":[[2.08,46.3]],"id":41818958},{"atl":[[9.6,5.81]],"id":38214982},{"atb":[[2.3,115.24]],"id":40324291}],"con":true,"img":false}]}
{"op":"mcm","clk":"5348667321","pt":1646219773957,"mc":[{"id":"1.195453628","rc":[{"atb":[[2.24,0],[2.32,0],[2.28,0]],"id":40324291}],"con":true,"img":false}]}
{"op":"mcm","clk":"5348667460","pt":1646219775148,"mc":[{"id":"1.195453628","rc":[{"atb":[[2.14,6.58]],"id":41818958}],"con":true,"img":false}]}
{"op":"mcm","clk":"5348668047","pt":1646219780186,"mc":[{"id":"1.195453628","rc":[{"atl":[[3.4,72.92]],"id":39734233},{"atb":[[2.04,72.12]],"id":41818958},{"atl":[[10,8.33]],"id":38214982},{"atb":[[2.26,59.52]],"id":40324291}],"con":true,"img":false}]}
{"op":"mcm","clk":"5348668656","pt":1646219785659,"mc":[{"id":"1.195453628","rc":[{"atl":[[3.35,0],[3.25,0]],"id":39734233}],"con":true,"img":false}]}
{"op":"mcm","clk":"5348668869","pt":1646219787693,"mc":[{"id":"1.195453628","rc":[{"atl":[[11,0]],"id":27868829}],"con":true,"img":false}]}
{"op":"mcm","clk":"5348668884","pt":1646219787793,"mc":[{"id":"1.195453628","rc":[{"atl":[[12,3.96]],"id":27868829}],"con":true,"img":false}]}
{"op":"mcm","clk":"5348669153","pt":1646219790197,"mc":[{"id":"1.195453628","rc":[{"atl":[[3.5,50]],"id":39734233},{"atb":[[2,125]],"id":41818958},{"atl":[[11,12.5]],"id":38214982},{"atb":[[2.22,102.46]],"id":40324291}],"con":true,"img":false}]}
{"op":"mcm","clk":"5348669509","pt":1646219792801,"mc":[{"id":"1.195453628","rc":[{"atb":[[2.18,0]],"id":41818958}],"con":true,"img":false}]}
{"op":"mcm","clk":"5348669648","pt":1646219793588,"mc":[{"id":"1.195453628","rc":[{"atl":[[3.3,21.74]],"id":39734233}],"con":true,"img":false}]}
{"op":"mcm","clk":"5348669668","pt":1646219793696,"mc":[{"id":"1.195453628","rc":[{"atl":[[3.35,18.55]],"id":39734233}],"con":true,"img":false}]}
{"op":"mcm","clk":"5348680310","pt":1646219806612,"mc":[{"id":"1.195453628","rc":[{"atb":[[2.12,0],[2.16,17.24]],"id":41818958},{"atl":[[9.2,0],[8.4,2.7]],"id":38214982},{"atb":[[2.36,14.71],[2.34,70.91]],"id":40324291}],"con":true,"img":false}]}
{"op":"mcm","clk":"5348680423","pt":1646219807522,"mc":[{"id":"1.195453628","rc":[{"atb":[[2.12,17.86],[2.16,0]],"id":41818958},{"atl":[[9.2,2.44],[8.4,0]],"id":38214982},{"atb":[[2.36,0],[2.34,85.84]],"id":40324291}],"con":true,"img":false}]}
{"op":"mcm","clk":"5348680755","pt":1646219809431,"mc":[{"id":"1.195453628","rc":[{"atb":[[2.14,13.88]],"id":41818958}],"con":true,"img":false}]}
{"op":"mcm","clk":"5348680930","pt":1646219810427,"mc":[{"id":"1.195453628","rc":[{"atl":[[3.6,7.69],[4.2,0]],"id":41818958},{"atl":[[9.6,2.33],[9.2,0]],"id":38214982},{"atl":[[7.2,3.23],[7,16.67]],"id":38761677},{"atl":[[8,2.86],[7.6,0]],"id":40324291}],"con":true,"img":false}]}
{"op":"mcm","clk":"5348682278","pt":1646219820445,"mc":[{"id":"1.195453628","rc":[{"atl":[[3.7,18.52]],"id":41818958},{"spn":2.93,"spf":"NaN","id":41818958},{"atl":[[10,5.56]],"id":38214982},{"atl":[[7.6,7.58]],"id":38761677},{"atl":[[8.4,6.76]],"id":40324291}],"con":true,"img":false}]}
{"op":"mcm","clk":"5348682309","pt":1646219820655,"mc":[{"id":"1.195453628","rc":[{"atl":[[4.4,16.71]],"id":41818958},{"atb":[[2.96,4]],"id":38214982},{"atl":[[7.4,2]],"id":40324291}],"con":true,"img":false}]}
{"op":"mcm","clk":"5348682448","pt":1646219821648,"mc":[{"id":"1.195453628","rc":[{"atb":[[1.99,0]],"id":41818958}],"con":true,"img":false}]}
{"op":"mcm","clk":"5348682460","pt":1646219821753,"mc":[{"id":"1.195453628","rc":[{"atb":[[1.94,165.01]],"id":41818958}],"con":true,"img":false}]}
{"op":"mcm","clk":"5348683112","pt":1646219827061,"mc":[{"id":"1.195453628","rc":[{"atb":[[2.22,4]],"id":39734233},{"atl":[[4.8,0],[4.3,38.04]],"id":41818958},{"atl":[[7.2,31.83]],"id":40324291}],"con":true,"img":false}]}
{"op":"mcm","clk":"5348683517","pt":1646219830474,"mc":[{"id":"1.195453628","rc":[{"atl":[[3.8,26.79]],"id":41818958},{"atl":[[11,7.5]],"id":38214982},{"atl":[[8,10.71],[8.2,0],[7.4,0],[7.8,0]],"id":38761677},{"atl":[[8.8,9.62]],"id":40324291}],"con":true,"img":false}]}
{"op":"mcm","clk":"5348683544","pt":1646219830637,"mc":[{"id":"1.195453628","rc":[{"atb":[[2.98,3]],"id":38214982}],"con":true,"img":false}]}
{"op":"mcm","clk":"5348683862","pt":1646219833155,"mc":[{"id":"1.195453628","rc":[{"atl":[[12,0]],"id":27868829}],"con":true,"img":false}]}
{"op":"mcm","clk":"5348683877","pt":1646219833253,"mc":[{"id":"1.195453628","rc":[{"atl":[[11,3.96]],"id":27868829}],"con":true,"img":false}]}
{"op":"mcm","clk":"5348683889","pt":1646219833363,"mc":[{"id":"1.195453628","rc":[{"atb":[[2.18,0]],"id":39734233},{"atb":[[2.62,0]],"id":38214982}],"con":true,"img":false}]}
{"op":"mcm","clk":"5348683907","pt":1646219833563,"mc":[{"id":"1.195453628","rc":[{"atb":[[3,1.66]],"id":38214982}],"con":true,"img":false}]}
{"op":"mcm","clk":"5348684289","pt":1646219836866,"mc":[{"id":"1.195453628","rc":[{"atb":[[2.24,3]],"id":39734233},{"atl":[[4.6,0],[4.2,3]],"id":41818958},{"atb":[[3,5.66]],"id":38214982},{"atl":[[7,3]],"id":40324291}],"con":true,"img":false}]}
{"op":"mcm","clk":"5348684318","pt":1646219837081,"mc":[{"id":"1.195453628","rc":[{"atb":[[2.22,0],[2.26,4]],"id":39734233},{"atl":[[4.1,3]],"id":41818958},{"atl":[[6.8,2]],"id":40324291}],"con":true,"img":false}]}
{"op":"mcm","clk":"5348684776","pt":1646219840477,"mc":[{"id":"1.195453628","rc":[{"atl":[[3.9,43.1]],"id":41818958},{"atl":[[12,11.36]],"id":38214982},{"atl":[[8.4,16.89]],"id":38761677},{"atl":[[9.2,24.09]],"id":40324291}],"con":true,"img":false}]}
{"op":"mcm","clk":"5348684841","pt":1646219841103,"mc":[{"id":"1.195453628","rc":[{"atl":[[5,10.9]],"id":40324291}],"con":true,"img":false}]}
{"op":"mcm","clk":"5348684850","pt":1646219841209,"mc":[{"id":"1.195453628","rc":[{"atl":[[5.4,0]],"id":40324291}],"con":true,"img":false}]}
{"op":"mcm","clk":"5348685507","pt":1646219846888,"mc":[{"id":"1.195453628","rc":[{"atb":[[3.05,2]],"id":38214982}],"con":true,"img":false}]}
{"op":"mcm","clk":"5348685522","pt":1646219846988,"mc":[{"id":"1.195453628","rc":[{"atb":[[2.28,2]],"id":39734233},{"atl":[[3.6,0],[3.8,0],[3.55,7.84],[4.4,2],[3.7,0],[3.9,0]],"id":41818958}],"con":true,"img":false}]}
{"op":"mcm","clk":"5348685553","pt":1646219847205,"mc":[{"id":"1.195453628","rc":[{"atb":[[2.3,3]],"id":39734233},{"atl":[[4.3,17.21],[4.2,34.25]],"id":41818958}],"con":true,"img":false}]}
{"op":"mcm","clk":"5348685565","pt":1646219847304,"mc":[{"id":"1.195453628","rc":[{"atb":[[2.24,0]],"id":39734233}],"con":true,"img":false}]}
{"op":"mcm","clk":"5348686291","pt":1646219852810,"mc":[{"id":"1.195453628","rc":[{"atb":[[2.32,2]],"id":39734233}],"con":true,"img":false}]}
{"op":"mcm","clk":"5348686337","pt":1646219853225,"mc":[{"id":"1.195453628","rc":[{"atl":[[4.3,4]],"id":41818958}],"con":true,"img":false}]}
{"op":"mcm","clk":"5348686350","pt":1646219853288,"mc":[{"id":"1.195453628","rc":[{"atl":[[4.1,16.21]],"id":41818958}],"con":true,"img":false}]}
{"op":"mcm","clk":"5348686359","pt":1646219853387,"mc":[{"id":"1.195453628","rc":[{"atb":[[3,4]],"id":38214982}],"con":true,"img":false}]}
{"op":"mcm","clk":"5348686372","pt":1646219853489,"mc":[{"id":"1.195453628","rc":[{"atb":[[2.32,4.16],[2.16,13.65]],"id":39734233}],"con":true,"img":false}]}
{"op":"mcm","clk":"5348686379","pt":1646219853593,"mc":[{"id":"1.195453628","rc":[{"atb":[[3.1,1.66]],"id":38214982}],"con":true,"img":false}]}
{"op":"mcm","clk":"5348686641","pt":1646219855893,"mc":[{"id":"1.195453628","rc":[{"atl":[[3.35,61.1],[3.4,31.25]],"id":39734233}],"con":true,"img":false}]}
{"op":"mcm","clk":"5348686752","pt":1646219856989,"mc":[{"id":"1.195453628","rc":[{"atl":[[3.65,18.87]],"id":41818958}],"con":true,"img":false}]}
{"op":"mcm","clk":"5348687005","pt":1646219859131,"mc":[{"id":"1.195453628","rc":[{"atb":[[1.42,0]],"id":38761677}],"con":true,"img":false}]}
{"op":"mcm","clk":"5348687018","pt":1646219859233,"mc":[{"id":"1.195453628","rc":[{"atb":[[1.46,84.78]],"id":38761677}],"con":true,"img":false}]}
{"op":"mcm","clk":"5348687381","pt":1646219862140,"mc":[{"id":"1.195453628","rc":[{"atb":[[1.45,18.5]],"id":38761677}],"con":true,"img":false}]}
{"op":"mcm","clk":"5348687983","pt":1646219867006,"mc":[{"id":"1.195453628","rc":[{"atl":[[3.75,27.27]],"id":41818958}],"con":true,"img":false}]}
{"op":"mcm","clk":"5348688097","pt":1646219868152,"mc":[{"id":"1.195453628","rc":[{"atb":[[1.49,15.32]],"id":38761677}],"con":true,"img":false}]}
{"op":"mcm","clk":"5348688155","pt":1646219868612,"mc":[{"id":"1.195453628","rc":[{"atb":[[1.52,2.16]],"id":38761677}],"con":true,"img":false}]}
{"op":"mcm","clk":"5348688166","pt":1646219868717,"mc":[{"id":"1.195453628","rc":[{"atb":[[1.48,0]],"id":38761677}],"con":true,"img":false}]}
{"op":"mcm","clk":"5348689162","pt":1646219876130,"mc":[{"id":"1.195453628","rc":[{"atb":[[1.38,0]],"id":38761677}],"con":true,"img":false}]}
{"op":"mcm","clk":"5348689176","pt":1646219876230,"mc":[{"id":"1.195453628","rc":[{"atb":[[1.4,140.55]],"id":38761677}],"con":true,"img":false}]}
{"op":"mcm","clk":"5348689263","pt":1646219877062,"mc":[{"id":"1.195453628","rc":[{"atl":[[3.85,43.86]],"id":41818958}],"con":true,"img":false}]}
{"op":"mcm","clk":"5348689576","pt":1646219879585,"mc":[{"id":"1.195453628","rc":[{"atb":[[1.98,0],[1.93,0],[1.88,0]],"id":39734233},{"atl":[[4.9,16.35],[7.8,0],[5.9,0]],"id":39734233},{"atb":[[1.98,0],[1.88,0],[1.93,0]],"id":41818958},{"atl":[[4.9,0],[7.8,0],[5.9,0]],"id":41818958},{"atb":[[1.98,0],[2.06,0],[2.16,0]],"id":38214982},{"atl":[[6.8,0],[8.8,0],[5.4,0]],"id":38214982},{"atb":[[3.45,0],[3.95,42.37],[3.7,0]],"id":27868829},{"atl":[[18.5,5.71],[13.5,0],[27,0]],"id":27868829},{"atb":[[1.2,0],[1.25,0],[1.3,0]],"id":38761677},{"atl":[[2.54,0],[2.74,0],[2.94,0]],"id":38761677},{"atb":[[2.3,38.46],[2.2,0],[2.1,0]],"id":40324291},{"atl":[[5.6,0],[7.2,20.13],[9.2,15.24]],"id":40324291}],"con":true,"img":false}]}
{"op":"mcm","clk":"5348689592","pt":1646219879748,"mc":[{"id":"1.195453628","rc":[{"atl":[[8,0],[8.8,12.82]],"id":38214982}],"con":true,"img":false}]}
{"op":"mcm","clk":"5348689645","pt":1646219880160,"mc":[{"id":"1.195453628","rc":[{"atb":[[1.94,106.38],[1.77,75.38]],"id":41818958},{"atb":[[3.45,23.69],[3.75,0]],"id":27868829},{"atl":[[2.92,0]],"id":38761677}],"con":true,"img":false}]}
{"op":"mcm","clk":"5348689660","pt":1646219880270,"mc":[{"id":"1.195453628","rc":[{"atl":[[3.2,27.81]],"id":38761677}],"con":true,"img":false}]}
{"op":"mcm","clk":"5348690076","pt":1646219883170,"mc":[{"id":"1.195453628","rc":[{"atb":[[1.98,101.85],[1.93,107.33],[1.88,113.43]],"id":39734233},{"atl":[[4.9,25.65],[7.8,10.67],[5.9,14.81]],"id":39734233},{"spn":2.76,"spf":"NaN","id":39734233},{"atb":[[1.98,101.85],[1.93,107.33],[1.88,113.43]],"id":41818958},{"atl":[[4.9,9.3],[7.8,10.67],[5.9,14.81]],"id":41818958},{"spn":2.9,"spf":"NaN","id":41818958},{"atb":[[1.98,101.85],[2.06,94.16],[2.16,86.05]],"id":38214982},{"atl":[[6.8,12.51],[8.8,22.12],[5.4,8.25]],"id":38214982},{"spn":4.25,"spf":"NaN","id":38214982},{"atb":[[3.45,64.43],[3.95,76.2],[3.7,36.96]],"id":27868829},{"atl":[[18.5,9.85],[13.5,2.9],[27,2.79]],"id":27868829},{"atb":[[1.2,499.1],[1.25,399.28],[1.3,332.73]],"id":38761677},{"atl":[[2.54,23.57],[2.74,41.72],[2.94,37.42]],"id":38761677},{"spn":2.03,"spf":"NaN","id":38761677},{"atb":[[2.3,115.24],[2.2,83.18],[2.1,90.74]],"id":40324291},{"atl":[[5.6,7.89],[7.2,31.83],[9.2,24.09]],"id":40324291}],"con":true,"img":false}]}
{"op":"mcm","clk":"5348690435","pt":1646219885689,"mc":[{"id":"1.195453628","rc":[{"atb":[[1.45,0]],"id":38761677}],"con":true,"img":false}]}
{"op":"mcm","clk":"5348691041","pt":1646219890065,"mc":[{"id":"1.195453628","rc":[{"atl":[[4.1,3]],"id":41818958}],"con":true,"img":false}]}
{"op":"mcm","clk":"5348691057","pt":1646219890176,"mc":[{"id":"1.195453628","rc":[{"atl":[[3.7,13.21]],"id":41818958}],"con":true,"img":false}]}
{"op":"mcm","clk":"5348691112","pt":1646219890593,"mc":[{"id":"1.195453628","rc":[{"atl":[[11,0]],"id":27868829}],"con":true,"img":false}]}
{"op":"mcm","clk":"5348691128","pt":1646219890641,"mc":[{"id":"1.195453628","rc":[{"atl":[[12,3.96]],"id":27868829}],"con":true,"img":false}]}
{"op":"mcm","clk":"5348692269","pt":1646219899206,"mc":[{"id":"1.195453628","rc":[{"atb":[[1.49,32.32]],"id":38761677}],"con":true,"img":false}]}
{"op":"mcm","clk":"5348695109","pt":1646219922125,"mc":[{"id":"1.195453628","rc":[{"atb":[[1.46,0]],"id":38761677}],"con":true,"img":false}]}
{"op":"mcm","clk":"5348695116","pt":1646219922231,"mc":[{"id":"1.195453628","rc":[{"atb":[[1.5,84.78]],"id":38761677}],"con":true,"img":false}]}
{"op":"mcm","clk":"5348695310","pt":1646219923639,"mc":[{"id":"1.195453628","rc":[{"atl":[[3.2,0]],"id":38761677}],"con":true,"img":false}]}
{"op":"mcm","clk":"5348695327","pt":1646219923755,"mc":[{"id":"1.195453628","rc":[{"atl":[[2.92,27.81]],"id":38761677}],"con":true,"img":false}]}
{"op":"mcm","clk":"5348695517","pt":1646219925150,"mc":[{"id":"1.195453628","rc":[{"atb":[[1.94,168.13],[1.77,0]],"id":41818958}],"con":true,"img":false}]}
{"op":"mcm","clk":"5348695530","pt":1646219925214,"mc":[{"id":"1.195453628","rc":[{"atb":[[1.49,16.99]],"id":38761677}],"con":true,"img":false}]}
{"op":"mcm","clk":"5348695545","pt":1646219925318,"mc":[{"id":"1.195453628","rc":[{"atb":[[3.45,40.74]],"id":27868829}],"con":true,"img":false}]}
{"op":"mcm","clk":"5348695559","pt":1646219925426,"mc":[{"id":"1.195453628","rc":[{"atb":[[3.75,23.69]],"id":27868829}],"con":true,"img":false}]}
{"op":"mcm","clk":"5348696359","pt":1646219931341,"mc":[{"id":"1.195453628","rc":[{"atb":[[1.53,14.16]],"id":38761677}],"con":true,"img":false}]}
{"op":"mcm","clk":"5348696464","pt":1646219932030,"mc":[{"id":"1.195453628","rc":[{"atb":[[1.56,2.16]],"id":38761677}],"con":true,"img":false}]}
{"op":"mcm","clk":"5348696481","pt":1646219932143,"mc":[{"id":"1.195453628","rc":[{"atb":[[1.52,0]],"id":38761677}],"con":true,"img":false}]}
{"op":"mcm","clk":"5348696614","pt":1646219933135,"mc":[{"id":"1.195453628","rc":[{"atb":[[1.5,0]],"id":38761677}],"con":true,"img":false}]}
{"op":"mcm","clk":"5348696629","pt":1646219933238,"mc":[{"id":"1.195453628","rc":[{"atb":[[1.43,84.78]],"id":38761677}],"con":true,"img":false}]}
{"op":"mcm","clk":"5348696734","pt":1646219934128,"mc":[{"id":"1.195453628","rc":[{"atb":[[2.32,2.16],[2.24,4]],"id":39734233},{"atl":[[3.6,7.69],[3.55,0]],"id":41818958}],"con":true,"img":false}]}
{"op":"mcm","clk":"5348696745","pt":1646219934234,"mc":[{"id":"1.195453628","rc":[{"atb":[[1.53,0]],"id":38761677}],"con":true,"img":false}]}
{"op":"mcm","clk":"5348697227","pt":1646219938059,"mc":[{"id":"1.195453628","rc":[{"atb":[[2.32,5.16],[2.26,0],[2.24,0],[2.28,0]],"id":39734233}],"con":true,"img":false}]}
{"op":"mcm","clk":"5348697272","pt":1646219938472,"mc":[{"id":"1.195453628","rc":[{"atb":[[2.3,0],[2.34,2]],"id":39734233}],"con":true,"img":false}]}
{"op":"mcm","clk":"5348697367","pt":1646219939157,"mc":[{"id":"1.195453628","rc":[{"atb":[[2.36,4]],"id":39734233}],"con":true,"img":false}]}
{"op":"mcm","clk":"5348697390","pt":1646219939370,"mc":[{"id":"1.195453628","rc":[{"atb":[[2.38,4]],"id":39734233}],"con":true,"img":false}]}
{"op":"mcm","clk":"5348697406","pt":1646219939471,"mc":[{"id":"1.195453628","rc":[{"atb":[[2.32,2.16]],"id":39734233}],"con":true,"img":false}]}
{"op":"mcm","clk":"5348697428","pt":1646219939673,"mc":[{"id":"1.195453628","rc":[{"atb":[[2.4,2]],"id":39734233}],"con":true,"img":false}]}
{"op":"mcm","clk":"5348697496","pt":1646219940265,"mc":[{"id":"1.195453628","rc":[{"atb":[[1.46,16.32]],"id":38761677}],"con":true,"img":false}]}
{"op":"mcm","clk":"5348697786","pt":1646219942698,"mc":[{"id":"1.195453628","rc":[{"atb":[[1.56,0],[1.52,2.16]],"id":38761677}],"con":true,"img":false}]}
{"op":"mcm","clk":"5348697836","pt":1646219943184,"mc":[{"id":"1.195453628","rc":[{"spn":2.8,"spf":"NaN","id":39734233},{"spn":2.93,"spf":"NaN","id":41818958},{"atb":[[2.36,0]],"id":38214982}],"con":true,"img":false}]}
{"op":"mcm","clk":"5348697843","pt":1646219943285,"mc":[{"id":"1.195453628","rc":[{"atb":[[2.4,53.95]],"id":38214982}],"con":true,"img":false}]}
{"op":"mcm","clk":"5348697943","pt":1646219944184,"mc":[{"id":"1.195453628","rc":[{"atl":[[3.7,31.73]],"id":41818958},{"atb":[[1.49,0]],"id":38761677}],"con":true,"img":false}]}
{"op":"mcm","clk":"5348698102","pt":1646219945506,"mc":[{"id":"1.195453628","rc":[{"atl":[[3.85,0],[3.75,0],[3.65,0]],"id":41818958}],"con":true,"img":false}]}
{"op":"mcm","clk":"5348698115","pt":1646219945603,"mc":[{"id":"1.195453628","rc":[{"atb":[[2.34,0],[2.42,4]],"id":39734233}],"con":true,"img":false}]}
{"op":"mcm","clk":"5348699056","pt":1646219953211,"mc":[{"id":"1.195453628","rc":[{"atl":[[3.7,18.52]],"id":41818958}],"con":true,"img":false}]}
{"op":"mcm","clk":"5348699069","pt":1646219953315,"mc":[{"id":"1.195453628","rc":[{"atl":[[4.1,16.21]],"id":41818958}],"con":true,"img":false}]}
{"op":"mcm","clk":"5348699186","pt":1646219954198,"mc":[{"id":"1.195453628","rc":[{"atl":[[3.8,26.79]],"id":41818958}],"con":true,"img":false}]}
{"op":"mcm","clk":"5348699228","pt":1646219954611,"mc":[{"id":"1.195453628","rc":[{"atl":[[3.2,5.45]],"id":40324291}],"con":true,"img":false}]}
{"op":"mcm","clk":"5348699342","pt":1646219955508,"mc":[{"id":"1.195453628","rc":[{"atb":[[1.46,34.42]],"id":38761677}],"con":true,"img":false}]}
{"op":"mcm","clk":"5348700393","pt":1646219964210,"mc":[{"id":"1.195453628","rc":[{"atl":[[3.9,43.1]],"id":41818958}],"con":true,"img":false}]}
{"op":"mcm","clk":"5348702141","pt":1646219977143,"mc":[{"id":"1.195453628","rc":[{"atl":[[4.1,3]],"id":41818958}],"con":true,"img":false}]}
{"op":"mcm","clk":"5348702154","pt":1646219977245,"mc":[{"id":"1.195453628","rc":[{"atl":[[3.75,13.21]],"id":41818958}],"con":true,"img":false}]}
{"op":"mcm","clk":"5348702284","pt":1646219978135,"mc":[{"id":"1.195453628","rc":[{"atb":[[1.43,0]],"id":38761677}],"con":true,"img":false}]}
{"op":"mcm","clk":"5348702300","pt":1646219978234,"mc":[{"id":"1.195453628","rc":[{"atb":[[1.47,84.78]],"id":38761677}],"con":true,"img":false}]}
{"op":"mcm","clk":"5348702353","pt":1646219978653,"mc":[{"id":"1.195453628","rc":[{"atl":[[5,0]],"id":40324291}],"con":true,"img":false}]}
{"op":"mcm","clk":"5348702372","pt":1646219978754,"mc":[{"id":"1.195453628","rc":[{"atl":[[4.7,10.9]],"id":40324291}],"con":true,"img":false}]}
{"op":"mcm","clk":"5348702477","pt":1646219979553,"mc":[{"id":"1.195453628","rc":[{"atb":[[1.46,18.1]],"id":38761677}],"con":true,"img":false}]}
{"op":"mcm","clk":"5348702761","pt":1646219981856,"mc":[{"id":"1.195453628","rc":[{"atl":[[4,3]],"id":41818958}],"con":true,"img":false}]}
{"op":"mcm","clk":"5348702776","pt":1646219981955,"mc":[{"id":"1.195453628","rc":[{"atl":[[4.4,0]],"id":41818958}],"con":true,"img":false}]}
{"op":"mcm","clk":"5348702787","pt":1646219982067,"mc":[{"id":"1.195453628","rc":[{"atl":[[4.3,0],[4,0],[3.95,3],[4.1,0],[4.2,31.25]],"id":41818958},{"atl":[[6.8,0],[7.8,2],[7,0]],"id":40324291}],"con":true,"img":false}]}
{"op":"mcm","clk":"5348702861","pt":1646219982572,"mc":[{"id":"1.195453628","rc":[{"atb":[[2,0],[2.04,0],[2.12,0],[1.94,61.75],[2.08,0],[1.35,118.42]],"id":41818958},{"atl":[[4.3,3]],"id":41818958},{"atl":[[10.5,10.53],[11.5,1.9],[8.8,9.3]],"id":38214982},{"atb":[[4.5,0],[4.3,0],[1.03,250],[3.95,33.83],[4.1,0]],"id":27868829},{"atl":[[8.6,2.63],[7,0]],"id":38761677},{"atl":[[7.4,0],[7.8,0],[9.4,11.9],[7.2,11.7]],"id":40324291}],"con":true,"img":false}]}
{"op":"mcm","clk":"5348702871","pt":1646219982638,"mc":[{"id":"1.195453628","rc":[{"atb":[[1.41,48.78]],"id":41818958},{"atl":[[3.95,0]],"id":41818958},{"atl":[[9.6,0],[10,0],[11,0]],"id":38214982},{"atl":[[8,0],[7.2,0],[8.6,15.79],[7.6,0]],"id":38761677},{"atl":[[8,0],[8.8,4],[8.4,0],[9.4,14.28]],"id":40324291}],"con":true,"img":false}]}
{"op":"mcm","clk":"5348702893","pt":1646219982743,"mc":[{"id":"1.195453628","rc":[{"atb":[[2.48,3],[2.4,0],[2.36,0],[2.42,0],[2.38,0]],"id":39734233},{"atb":[[1.45,44.44],[1.43,116.28],[1.39,250]],"id":41818958},{"atl":[[4.3,0]],"id":41818958},{"atb":[[3,0],[2.98,0],[3.05,0],[2.96,0]],"id":38214982},{"atl":[[10.5,12.64],[12,0]],"id":38214982},{"atb":[[2.36,14.71],[2.34,70.91]],"id":40324291}],"con":true,"img":false}]}
{"op":"mcm","clk":"5348702925","pt":1646219982952,"mc":[{"id":"1.195453628","rc":[{"atb":[[2.5,2]],"id":39734233},{"atl":[[8.4,0]],"id":38761677},{"atl":[[9.2,8.85],[8.8,0]],"id":40324291}],"con":true,"img":false}]}
{"op":"mcm","clk":"5348703026","pt":1646219983772,"mc":[{"id":"1.195453628","rc":[{"atb":[[2.5,0],[2.32,0],[2.22,2.16],[2.48,0],[2.36,2]],"id":39734233},{"atb":[[1.45,0],[1.43,0]],"id":41818958},{"atl":[[3.95,2]],"id":41818958},{"atb":[[2.96,2]],"id":38214982},{"atl":[[10.5,10.53]],"id":38214982},{"atb":[[2.36,0],[2.34,85.84]],"id":40324291},{"atl":[[8.8,4]],"id":40324291}],"con":true,"img":false}]}
{"op":"mcm","clk":"5348703050","pt":1646219983934,"mc":[{"id":"1.195453628","rc":[{"atb":[[2.38,4]],"id":39734233},{"atl":[[3.95,0],[3.9,45.1]],"id":41818958},{"atb":[[2.98,4]],"id":38214982},{"atl":[[8.6,4]],"id":40324291}],"con":true,"img":false}]}
{"op":"mcm","clk":"5348703242","pt":1646219985349,"mc":[{"id":"1.195453628","rc":[{"atb":[[1.5,15.01]],"id":38761677}],"con":true,"img":false}]}
{"op":"mcm","clk":"5348703316","pt":1646219986035,"mc":[{"id":"1.195453628","rc":[{"atl":[[3.85,3]],"id":41818958},{"atb":[[3,4]],"id":38214982},{"atl":[[8.4,4]],"id":40324291}],"con":true,"img":false}]}
{"op":"mcm","clk":"5348703330","pt":1646219986137,"mc":[{"id":"1.195453628","rc":[{"atb":[[2.4,3]],"id":39734233}],"con":true,"img":false}]}
{"op":"mcm","clk":"5348703340","pt":1646219986244,"mc":[{"id":"1.195453628","rc":[{"atl":[[3.8,29.79],[3.9,43.1]],"id":41818958},{"atb":[[3.05,4]],"id":38214982},{"atl":[[8.2,3]],"id":40324291}],"con":true,"img":false}]}
{"op":"mcm","clk":"5348703747","pt":1646219989471,"mc":[{"id":"1.195453628","rc":[{"atb":[[4.6,0]],"id":27868829}],"con":true,"img":false}]}
{"op":"mcm","clk":"5348703774","pt":1646219989678,"mc":[{"id":"1.195453628","rc":[{"atb":[[2.4,0],[2.36,0],[2.38,0]],"id":39734233},{"atb":[[4.5,1.66]],"id":27868829}],"con":true,"img":false}]}
{"op":"mcm","clk":"5348703805","pt":1646219989886,"mc":[{"id":"1.195453628","rc":[{"atb":[[2.12,80.73],[2.1,0]],"id":39734233},{"atl":[[3.9,46.1]],"id":41818958}],"con":true,"img":false}]}
{"op":"mcm","clk":"5348703907","pt":1646219990673,"mc":[{"id":"1.195453628","rc":[{"atb":[[2.1,0]],"id":41818958}],"con":true,"img":false}]}
{"op":"mcm","clk":"5348703926","pt":1646219990769,"mc":[{"id":"1.195453628","rc":[{"atb":[[1.99,44.04]],"id":41818958}],"con":true,"img":false}]}
{"op":"mcm","clk":"5348704014","pt":1646219991452,"mc":[{"id":"1.195453628","rc":[{"atl":[[3.45,40.82],[3.35,18.55]],"id":39734233},{"atl":[[3.6,0],[3.55,7.84],[3.75,15.21]],"id":41818958}],"con":true,"img":false}]}
{"op":"mcm","clk":"5348704038","pt":1646219991660,"mc":[{"id":"1.195453628","rc":[{"atb":[[2.14,7.3]],"id":41818958}],"con":true,"img":false}]}
{"op":"mcm","clk":"5348704133","pt":1646219992382,"mc":[{"id":"1.195453628","rc":[{"atl":[[3.95,2],[3.75,13.21]],"id":41818958}],"con":true,"img":false}]}
{"op":"mcm","clk":"5348704160","pt":1646219992546,"mc":[{"id":"1.195453628","rc":[{"atl":[[9,6.25]],"id":38761677}],"con":true,"img":false}]}
{"op":"mcm","clk":"5348704193","pt":1646219992754,"mc":[{"id":"1.195453628","rc":[{"atl":[[12.5,4.35]],"id":38214982}],"con":true,"img":false}]}
{"op":"mcm","clk":"5348704307","pt":1646219993686,"mc":[{"id":"1.195453628","rc":[{"atl":[[9.8,5.68]],"id":40324291}],"con":true,"img":false}]}
{"op":"mcm","clk":"5348704788","pt":1646219997284,"mc":[{"id":"1.195453628","rc":[{"atb":[[2.04,7.22]],"id":41818958}],"con":true,"img":false}]}
{"op":"mcm","clk":"5348705238","pt":1646220001194,"mc":[{"id":"1.195453628","rc":[{"atb":[[2.22,26.31],[2.12,129.03]],"id":39734233},{"atl":[[3.2,33.24],[3.35,66.85]],"id":39734233},{"atb":[[2.04,29.93],[2.44,5],[2.24,13.52],[2.36,10],[2.52,2.5]],"id":41818958},{"atl":[[5.6,5],[5.3,8.84],[6.8,32.7],[6,10],[5.2,2.5]],"id":38214982},{"atb":[[5.1,2.5],[4.3,10],[4.4,21.41],[3.75,55.07],[4.7,5]],"id":27868829},{"atl":[[9.8,11.36]],"id":27868829},{"atb":[[1.46,20.6],[1.47,158.16]],"id":38761677},{"atl":[[2.54,60.26],[2.74,115.1],[2.6,2.5],[2.68,5],[2.76,10]],"id":38761677},{"atb":[[2.5,10],[2.58,5],[2.34,119.16],[2.42,14.42],[2.66,2.5]],"id":40324291},{"atl":[[4.7,44.22]],"id":40324291}],"con":true,"img":false}]}
{"op":"mcm","clk":"5348705275","pt":1646220001460,"mc":[{"id":"1.195453628","rc":[{"atb":[[1.39,128.21]],"id":41818958}],"con":true,"img":false}]}
{"op":"mcm","clk":"5348705292","pt":1646220001571,"mc":[{"id":"1.195453628","rc":[{"atl":[[5.8,30.49]],"id":39734233},{"atb":[[1.68,79.93]],"id":41818958},{"atl":[[8.6,23.37]],"id":38214982},{"atb":[[3.5,30.15]],"id":27868829},{"atl":[[32,9.28]],"id":27868829},{"atb":[[1.31,79.64]],"id":38761677},{"atl":[[3.7,52.41]],"id":38761677},{"atl":[[7,17.65]],"id":40324291}],"con":true,"img":false}]}
{"op":"mcm","clk":"5348705303","pt":1646220001674,"mc":[{"id":"1.195453628","rc":[{"atl":[[4.9,9.3]],"id":39734233},{"atb":[[1.94,0]],"id":41818958},{"atb":[[2.4,0]],"id":38214982},{"atl":[[7.8,0]],"id":38214982},{"atb":[[3.75,31.38]],"id":27868829},{"atl":[[16.5,0]],"id":27868829},{"atb":[[1.4,0]],"id":38761677},{"atl":[[2.92,0]],"id":38761677},{"atl":[[5.9,0]],"id":40324291}],"con":true,"img":false}]}
{"op":"mcm","clk":"5348705319","pt":1646220001779,"mc":[{"id":"1.195453628","rc":[{"atb":[[1.99,53.95]],"id":38214982}],"con":true,"img":false}]}
{"op":"mcm","clk":"5348705332","pt":1646220001884,"mc":[{"id":"1.195453628","rc":[{"atb":[[2.56,2.16],[2.42,12.26]],"id":40324291}],"con":true,"img":false}]}
{"op":"mcm","clk":"5348705418","pt":1646220002560,"mc":[{"id":"1.195453628","rc":[{"atl":[[9.4,8.93]],"id":38761677}],"con":true,"img":false}]}
{"op":"mcm","clk":"5348705450","pt":1646220002812,"mc":[{"id":"1.195453628","rc":[{"atl":[[13.5,6]],"id":38214982}],"con":true,"img":false}]}
{"op":"mcm","clk":"5348705466","pt":1646220002880,"mc":[{"id":"1.195453628","rc":[{"atb":[[1.46,2.5]],"id":38761677}],"con":true,"img":false}]}
{"op":"mcm","clk":"5348705480","pt":1646220002987,"mc":[{"id":"1.195453628","rc":[{"atl":[[3.45,0],[3.3,65.22]],"id":39734233}],"con":true,"img":false}]}
{"op":"mcm","clk":"5348705566","pt":1646220003562,"mc":[{"id":"1.195453628","rc":[{"spn":2.71,"spf":"NaN","id":39734233},{"spn":3.03,"spf":"NaN","id":41818958},{"spn":4.15,"spf":"NaN","id":38214982},{"spn":7.45,"spf":"NaN","id":27868829},{"atl":[[7,0]],"id":40324291},{"spn":2.61,"spf":1.0,"id":40324291}],"con":true,"img":false}]}
{"op":"mcm","clk":"5348705580","pt":1646220003666,"mc":[{"id":"1.195453628","rc":[{"atl":[[8,17.65],[10.5,7.89]],"id":40324291}],"con":true,"img":false}]}
{"op":"mcm","clk":"5348705609","pt":1646220003872,"mc":[{"id":"1.195453628","rc":[{"atl":[[3.6,7.69],[3.55,0]],"id":41818958}],"con":true,"img":false}]}
{"op":"mcm","clk":"5348705634","pt":1646220004075,"mc":[{"id":"1.195453628","rc":[{"atl":[[12,0]],"id":27868829}],"con":true,"img":false}]}
{"op":"mcm","clk":"5348705648","pt":1646220004181,"mc":[{"id":"1.195453628","rc":[{"atl":[[11,3.96]],"id":27868829}],"con":true,"img":false}]}
{"op":"mcm","clk":"5348705972","pt":1646220006592,"mc":[{"id":"1.195453628","rc":[{"atb":[[1.62,64.47]],"id":39734233}],"con":true,"img":false}]}
{"op":"mcm","clk":"5348706337","pt":1646220009505,"mc":[{"id":"1.195453628","rc":[{"atb":[[2.26,0]],"id":41818958},{"atb":[[4.5,0]],"id":27868829},{"atb":[[2.44,0]],"id":40324291}],"con":true,"img":false}]}
{"op":"mcm","clk":"5348706355","pt":1646220009608,"mc":[{"id":"1.195453628","rc":[{"atb":[[2.54,1.66]],"id":41818958},{"atb":[[5.2,1.66]],"id":27868829},{"atb":[[2.68,1.66]],"id":40324291}],"con":true,"img":false}]}
{"op":"mcm","clk":"5348706544","pt":1646220010961,"mc":[{"id":"1.195453628","rc":[{"atl":[[3.6,0],[3.55,7.84]],"id":41818958}],"con":true,"img":false}]}
{"op":"mcm","clk":"5348706743","pt":1646220012589,"mc":[{"id":"1.195453628","rc":[{"atl":[[9.8,14.2]],"id":38761677}],"con":true,"img":false}]}
{"op":"mcm","clk":"5348706764","pt":1646220012790,"mc":[{"id":"1.195453628","rc":[{"atl":[[14.5,9.26]],"id":38214982}],"con":true,"img":false}]}
{"op":"mcm","clk":"5348706903","pt":1646220013785,"mc":[{"id":"1.195453628","rc":[{"atl":[[11.5,11.9]],"id":40324291}],"con":true,"img":false}]}
{"op":"mcm","clk":"5348706939","pt":1646220014093,"mc":[{"id":"1.195453628","rc":[{"atl":[[5.8,19.49]],"id":41818958}],"con":true,"img":false}]}
{"op":"mcm","clk":"5348707270","pt":1646220016624,"mc":[{"id":"1.195453628","rc":[{"atl":[[4.7,33.32]],"id":40324291}],"con":true,"img":false}]}
{"op":"mcm","clk":"5348707283","pt":1646220016703,"mc":[{"id":"1.195453628","rc":[{"atl":[[4.6,10.9]],"id":40324291}],"con":true,"img":false}]}
{"op":"mcm","clk":"5348707409","pt":1646220017605,"mc":[{"id":"1.195453628","rc":[{"atl":[[6.6,0]],"id":38214982}],"con":true,"img":false}]}
{"op":"mcm","clk":"5348707428","pt":1646220017702,"mc":[{"id":"1.195453628","rc":[{"atl":[[5.6,12.78]],"id":38214982}],"con":true,"img":false}]}
{"op":"mcm","clk":"5348707550","pt":1646220018585,"mc":[{"id":"1.195453628","rc":[{"atb":[[2.12,88.67]],"id":39734233}],"con":true,"img":false}]}
{"op":"mcm","clk":"5348707565","pt":1646220018699,"mc":[{"id":"1.195453628","rc":[{"atb":[[2.24,40.36]],"id":39734233},{"atb":[[2.04,7.22],[2.36,36.76]],"id":41818958},{"atl":[[6.8,12.51],[5.4,22.75],[5.1,6]],"id":38214982},{"atb":[[5.1,9.22],[4.4,36.8],[3.75,0]],"id":27868829},{"atl":[[2.74,41.72],[2.68,35.03]],"id":38761677},{"atb":[[2.34,85.84],[2.56,17.84],[2.66,10.34]],"id":40324291},{"atl":[[4.6,26.58],[4.7,0]],"id":40324291}],"con":true,"img":false}]}
{"op":"mcm","clk":"5348707580","pt":1646220018788,"mc":[{"id":"1.195453628","rc":[{"atl":[[5.3,0]],"id":38214982}],"con":true,"img":false}]}
{"op":"mcm","clk":"5348707594","pt":1646220018894,"mc":[{"id":"1.195453628","rc":[{"atb":[[2.24,95.57],[2.12,40.37],[2.16,124]],"id":39734233},{"atl":[[3.8,26.79],[4,4]],"id":41818958},{"atb":[[4.4,27.5]],"id":27868829},{"atb":[[2.42,0]],"id":40324291}],"con":true,"img":false}]}
{"op":"mcm","clk":"5348707622","pt":1646220019104,"mc":[{"id":"1.195453628","rc":[{"atb":[[2.22,2.16]],"id":39734233},{"atl":[[2.72,0]],"id":38761677}],"con":true,"img":false}]}
{"op":"mcm","clk":"5348707638","pt":1646220019208,"mc":[{"id":"1.195453628","rc":[{"atl":[[2.52,25.34]],"id":38761677}],"con":true,"img":false}]}
{"op":"mcm","clk":"5348707665","pt":1646220019413,"mc":[{"id":"1.195453628","rc":[{"atb":[[2.3,2.16],[2.22,0]],"id":39734233},{"atl":[[2.52,55.62]],"id":38761677}],"con":true,"img":false}]}
{"op":"mcm","clk":"5348707696","pt":1646220019619,"mc":[{"id":"1.195453628","rc":[{"atb":[[1.99,0]],"id":41818958},{"atl":[[2.54,23.57]],"id":38761677}],"con":true,"img":false}]}
{"op":"mcm","clk":"5348707710","pt":1646220019682,"mc":[{"id":"1.195453628","rc":[{"atb":[[2.26,44.04]],"id":41818958}],"con":true,"img":false}]}
{"op":"mcm","clk":"5348707848","pt":1646220020715,"mc":[{"id":"1.195453628","rc":[{"atl":[[11,0]],"id":27868829}],"con":true,"img":false}]}
{"op":"mcm","clk":"5348707862","pt":1646220020820,"mc":[{"id":"1.195453628","rc":[{"atl":[[9.6,3.96]],"id":27868829}],"con":true,"img":false}]}
{"op":"mcm","clk":"5348707877","pt":1646220020876,"mc":[{"id":"1.195453628","rc":[{"atb":[[1.37,202.7]],"id":41818958}],"con":true,"img":false}]}
{"op":"mcm","clk":"5348707918","pt":1646220021213,"mc":[{"id":"1.195453628","rc":[{"atl":[[9.6,11.66]],"id":27868829}],"con":true,"img":false}]}
{"op":"mcm","clk":"5348707941","pt":1646220021368,"mc":[{"id":"1.195453628","rc":[{"atb":[[2.16,117.52]],"id":39734233},{"atb":[[2.04,0]],"id":41818958},{"atl":[[9.8,2.27]],"id":27868829}],"con":true,"img":false}]}
{"op":"mcm","clk":"5348708082","pt":1646220022416,"mc":[{"id":"1.195453628","rc":[{"atb":[[2.12,0],[2.16,203.73]],"id":39734233},{"atl":[[3.6,7.69],[3.55,0]],"id":41818958}],"con":true,"img":false}]}
{"op":"mcm","clk":"5348708159","pt":1646220022886,"mc":[{"id":"1.195453628","rc":[{"atb":[[2.14,0]],"id":41818958}],"con":true,"img":false}]}
{"op":"mcm","clk":"5348708218","pt":1646220023407,"mc":[{"id":"1.195453628","rc":[{"atb":[[1.5,31.67]],"id":38761677}],"con":true,"img":false}]}
{"op":"mcm","clk":"5348708369","pt":1646220024704,"mc":[{"id":"1.195453628","rc":[{"atl":[[3.35,48.3]],"id":39734233},{"atl":[[3.75,0]],"id":41818958}],"con":true,"img":false}]}
{"op":"mcm","clk":"5348708389","pt":1646220024804,"mc":[{"id":"1.195453628","rc":[{"atl":[[3.45,18.55]],"id":39734233},{"atl":[[4.1,13.21]],"id":41818958}],"con":true,"img":false}]}
{"op":"mcm","clk":"5348708403","pt":1646220024911,"mc":[{"id":"1.195453628","rc":[{"atl":[[3.35,90.85],[3.3,21.74]],"id":39734233}],"con":true,"img":false}]}
{"op":"mcm","clk":"5348708624","pt":1646220026580,"mc":[{"id":"1.195453628","rc":[{"atl":[[9.6,7.7]],"id":27868829}],"con":true,"img":false}]}
{"op":"mcm","clk":"5348708639","pt":1646220026689,"mc":[{"id":"1.195453628","rc":[{"atl":[[12,3.96]],"id":27868829}],"con":true,"img":false}]}
{"op":"mcm","clk":"5348708691","pt":1646220027106,"mc":[{"id":"1.195453628","rc":[{"atb":[[2.34,52.81]],"id":40324291}],"con":true,"img":false}]}
{"op":"mcm","clk":"5348708706","pt":1646220027200,"mc":[{"id":"1.195453628","rc":[{"atb":[[2.58,38.03]],"id":40324291}],"con":true,"img":false}]}
{"op":"mcm","clk":"5348708734","pt":1646220027417,"mc":[{"id":"1.195453628","rc":[{"atb":[[2.3,7.93]],"id":39734233}],"con":true,"img":false}]}
{"op":"mcm","clk":"5348708748","pt":1646220027524,"mc":[{"id":"1.195453628","rc":[{"atb":[[2.42,5.28]],"id":41818958}],"con":true,"img":false}]}
{"op":"mcm","clk":"5348709053","pt":1646220030024,"mc":[{"id":"1.195453628","rc":[{"atb":[[2.48,2.16],[2.24,11.36]],"id":41818958}],"con":true,"img":false}]}
{"op":"mcm","clk":"5348709094","pt":1646220030401,"mc":[{"id":"1.195453628","rc":[{"atb":[[2.4,5.94]],"id":40324291}],"con":true,"img":false}]}
{"op":"mcm","clk":"5348709341","pt":1646220032379,"mc":[{"id":"1.195453628","rc":[{"atb":[[1.35,368.42]],"id":41818958}],"con":true,"img":false}]}
{"op":"mcm","clk":"5348709370","pt":1646220032594,"mc":[{"id":"1.195453628","rc":[{"atl":[[4.6,15.68]],"id":40324291}],"con":true,"img":false}]}
{"op":"mcm","clk":"5348709382","pt":1646220032696,"mc":[{"id":"1.195453628","rc":[{"atl":[[4.5,10.9]],"id":40324291}],"con":true,"img":false}]}
{"op":"mcm","clk":"5348709562","pt":1646220034118,"mc":[{"id":"1.195453628","rc":[{"atb":[[2.24,55.21]],"id":39734233},{"atb":[[3.5,0]],"id":27868829}],"con":true,"img":false}]}
{"op":"mcm","clk":"5348709577","pt":1646220034223,"mc":[{"id":"1.195453628","rc":[{"atb":[[2.26,40.36]],"id":39734233},{"atb":[[3.75,30.15]],"id":27868829}],"con":true,"img":false}]}
{"op":"mcm","clk":"5348709622","pt":1646220034636,"mc":[{"id":"1.195453628","rc":[{"atl":[[2.72,39.58],[3.7,0]],"id":38761677}],"con":true,"img":false}]}
{"op":"mcm","clk":"5348709634","pt":1646220034685,"mc":[{"id":"1.195453628","rc":[{"atl":[[8,0]],"id":40324291}],"con":true,"img":false}]}
{"op":"mcm","clk":"5348709650","pt":1646220034801,"mc":[{"id":"1.195453628","rc":[{"atl":[[7,17.65]],"id":40324291}],"con":true,"img":false}]}
{"op":"mcm","clk":"5348709777","pt":1646220035845,"mc":[{"id":"1.195453628","rc":[{"atl":[[2.68,5]],"id":38761677}],"con":true,"img":false}]}
{"op":"mcm","clk":"5348709789","pt":1646220035947,"mc":[{"id":"1.195453628","rc":[{"atb":[[2.44,24.04],[2.36,10]],"id":41818958},{"atl":[[2.6,85.36]],"id":38761677},{"atl":[[4.5,55.69],[4.6,0]],"id":40324291}],"con":true,"img":false}]}
{"op":"mcm","clk":"5348709816","pt":1646220036103,"mc":[{"id":"1.195453628","rc":[{"atb":[[2.24,165.63],[2.16,93.38]],"id":39734233},{"atb":[[1.68,0],[1.99,39.59]],"id":41818958}],"con":true,"img":false}]}
{"op":"mcm","clk":"5348709855","pt":1646220036428,"mc":[{"id":"1.195453628","rc":[{"atb":[[2.3,2.16]],"id":39734233},{"atb":[[2.42,0]],"id":41818958}],"con":true,"img":false}]}
{"op":"mcm","clk":"5348709875","pt":1646220036625,"mc":[{"id":"1.195453628","rc":[{"atb":[[2.26,0],[2.42,5.86],[2.38,29.62]],"id":41818958}],"con":true,"img":false}]}
{"op":"mcm","clk":"5348709895","pt":1646220036836,"mc":[{"id":"1.195453628","rc":[{"atb":[[2.16,86.21]],"id":39734233}],"con":true,"img":false}]}
{"op":"mcm","clk":"5348709938","pt":1646220037109,"mc":[{"id":"1.195453628","rc":[{"atl":[[5.6,5]],"id":38214982}],"con":true,"img":false}]}
{"op":"mcm","clk":"5348709952","pt":1646220037213,"mc":[{"id":"1.195453628","rc":[{"atl":[[5.3,7.78]],"id":38214982}],"con":true,"img":false}]}
{"op":"mcm","clk":"5348709979","pt":1646220037423,"mc":[{"id":"1.195453628","rc":[{"atl":[[5.3,22.28],[5.4,8.25]],"id":38214982}],"con":true,"img":false}]}
{"op":"mcm","clk":"5348710244","pt":1646220039635,"mc":[{"id":"1.195453628","rc":[{"atb":[[1.47,73.38]],"id":38761677}],"con":true,"img":false}]}
{"op":"mcm","clk":"5348710258","pt":1646220039736,"mc":[{"id":"1.195453628","rc":[{"atb":[[1.51,84.78]],"id":38761677}],"con":true,"img":false}]}
{"op":"mcm","clk":"5348710286","pt":1646220039941,"mc":[{"id":"1.195453628","rc":[{"atb":[[1.5,162.62],[1.47,0]],"id":38761677}],"con":true,"img":false}]}
{"op":"mcm","clk":"5348710308","pt":1646220040098,"mc":[{"id":"1.195453628","rc":[{"atb":[[4.4,15.39]],"id":27868829}],"con":true,"img":false}]}
{"op":"mcm","clk":"5348710320","pt":1646220040255,"mc":[{"id":"1.195453628","rc":[{"atb":[[5.2,13.77]],"id":27868829}],"con":true,"img":false}]}
{"op":"mcm","clk":"5348710347","pt":1646220040414,"mc":[{"id":"1.195453628","rc":[{"atb":[[5.2,23.49],[4.4,0],[4.7,24.44]],"id":27868829}],"con":true,"img":false}]}
{"op":"mcm","clk":"5348710356","pt":1646220040524,"mc":[{"id":"1.195453628","rc":[{"atb":[[5.1,2.5]],"id":27868829}],"con":true,"img":false}]}
{"op":"mcm","clk":"5348710574","pt":1646220042447,"mc":[{"id":"1.195453628","rc":[{"atb":[[2.32,5.69]],"id":39734233},{"atb":[[1.5,147.6]],"id":38761677}],"con":true,"img":false}]}
{"op":"mcm","clk":"5348710990","pt":1646220045555,"mc":[{"id":"1.195453628","rc":[{"atb":[[2.04,7.22]],"id":41818958}],"con":true,"img":false}]}
{"op":"mcm","clk":"5348711366","pt":1646220048567,"mc":[{"id":"1.195453628","rc":[{"atb":[[1.54,13.9]],"id":38761677}],"con":true,"img":false}]}
{"op":"mcm","clk":"5348711391","pt":1646220048738,"mc":[{"id":"1.195453628","rc":[{"atb":[[1.5,16.65]],"id":38761677}],"con":true,"img":false}]}
{"op":"mcm","clk":"5348711411","pt":1646220048943,"mc":[{"id":"1.195453628","rc":[{"atb":[[1.57,2.16],[1.52,0]],"id":38761677}],"con":true,"img":false}]}
{"op":"mcm","clk":"5348711728","pt":1646220051538,"mc":[{"id":"1.195453628","rc":[{"atl":[[3.6,0],[3.55,7.84]],"id":41818958}],"con":true,"img":false}]}
{"op":"mcm","clk":"5348711884","pt":1646220052944,"mc":[{"id":"1.195453628","rc":[{"atb":[[2.26,122.83],[2.24,55.21]],"id":39734233}],"con":true,"img":false}]}
{"op":"mcm","clk":"5348711907","pt":1646220053159,"mc":[{"id":"1.195453628","rc":[{"atl":[[2.52,30.28]],"id":38761677}],"con":true,"img":false}]}
{"op":"mcm","clk":"5348711920","pt":1646220053257,"mc":[{"id":"1.195453628","rc":[{"atl":[[2.5,25.34]],"id":38761677}],"con":true,"img":false}]}
{"op":"mcm","clk":"5348711939","pt":1646220053466,"mc":[{"id":"1.195453628","rc":[{"atl":[[2.54,96.95],[2.5,62.03],[2.6,2.5]],"id":38761677}],"con":true,"img":false}]}
{"op":"mcm","clk":"5348711965","pt":1646220053664,"mc":[{"id":"1.195453628","rc":[{"atb":[[2.38,0]],"id":41818958},{"atl":[[5.3,14.5]],"id":38214982},{"atl":[[2.52,0]],"id":38761677}],"con":true,"img":false}]}
{"op":"mcm","clk":"5348711978","pt":1646220053771,"mc":[{"id":"1.195453628","rc":[{"atb":[[2.46,29.62]],"id":41818958},{"atl":[[5.2,10.28]],"id":38214982}],"con":true,"img":false}]}
{"op":"mcm","clk":"5348711991","pt":1646220053874,"mc":[{"id":"1.195453628","rc":[{"atb":[[2.4,0]],"id":40324291}],"con":true,"img":false}]}
{"op":"mcm","clk":"5348712007","pt":1646220053974,"mc":[{"id":"1.195453628","rc":[{"atb":[[2.44,5]],"id":41818958}],"con":true,"img":false}]}
{"op":"mcm","clk":"5348712034","pt":1646220054139,"mc":[{"id":"1.195453628","rc":[{"atb":[[1.51,0]],"id":38761677}],"con":true,"img":false}]}
{"op":"mcm","clk":"5348712047","pt":1646220054288,"mc":[{"id":"1.195453628","rc":[{"atb":[[1.4,84.78]],"id":38761677}],"con":true,"img":false}]}
{"op":"mcm","clk":"5348712098","pt":1646220054667,"mc":[{"id":"1.195453628","rc":[{"atb":[[2.04,0],[1.99,0]],"id":41818958}],"con":true,"img":false}]}
{"op":"mcm","clk":"5348712116","pt":1646220054769,"mc":[{"id":"1.195453628","rc":[{"atb":[[1.94,39.59]],"id":41818958}],"con":true,"img":false}]}
{"op":"mcm","clk":"5348712170","pt":1646220055140,"mc":[{"id":"1.195453628","rc":[{"atl":[[12,0]],"id":27868829}],"con":true,"img":false}]}
{"op":"mcm","clk":"5348712184","pt":1646220055251,"mc":[{"id":"1.195453628","rc":[{"atl":[[11,3.96]],"id":27868829}],"con":true,"img":false}]}
{"op":"mcm","clk":"5348712357","pt":1646220056656,"mc":[{"id":"1.195453628","rc":[{"atb":[[1.5,62.49]],"id":38761677}],"con":true,"img":false}]}
{"op":"mcm","clk":"5348712417","pt":1646220057168,"mc":[{"id":"1.195453628","rc":[{"atb":[[5.2,11.38]],"id":27868829}],"con":true,"img":false}]}
{"op":"mcm","clk":"5348712431","pt":1646220057274,"mc":[{"id":"1.195453628","rc":[{"atb":[[5.3,12.11]],"id":27868829}],"con":true,"img":false}]}
{"op":"mcm","clk":"5348712456","pt":1646220057476,"mc":[{"id":"1.195453628","rc":[{"atb":[[5.1,21.94],[5.3,21.83],[4.7,4.99]],"id":27868829},{"atb":[[1.54,0]],"id":38761677}],"con":true,"img":false}]}
{"op":"mcm","clk":"5348712470","pt":1646220057545,"mc":[{"id":"1.195453628","rc":[{"atb":[[5.2,1.66]],"id":27868829},{"atl":[[2.72,0]],"id":38761677}],"con":true,"img":false}]}
{"op":"mcm","clk":"5348712484","pt":1646220057646,"mc":[{"id":"1.195453628","rc":[{"atl":[[2.92,39.58]],"id":38761677}],"con":true,"img":false}]}
{"op":"mcm","clk":"5348712732","pt":1646220059584,"mc":[{"id":"1.195453628","rc":[{"atb":[[2.46,0]],"id":41818958}],"con":true,"img":false}]}
{"op":"mcm","clk":"5348712742","pt":1646220059692,"mc":[{"id":"1.195453628","rc":[{"atb":[[2.08,29.62]],"id":41818958}],"con":true,"img":false}]}
{"op":"mcm","clk":"5348712758","pt":1646220059769,"mc":[{"id":"1.195453628","rc":[{"atb":[[2.44,24.26]],"id":41818958}],"con":true,"img":false}]}
{"op":"mcm","clk":"5348712958","pt":1646220061281,"mc":[{"id":"1.195453628","rc":[{"atl":[[2.54,23.57],[2.6,99.31]],"id":38761677}],"con":true,"img":false}]}
{"op":"mcm","clk":"5348713316","pt":1646220064477,"mc":[{"id":"1.195453628","rc":[{"spn":2.76,"spf":"NaN","id":39734233},{"spn":3.04,"spf":"NaN","id":41818958},{"spn":4.1,"spf":"NaN","id":38214982},{"atb":[[1.46,130.92],[1.5,16.65]],"id":38761677},{"spn":2.03,"spf":"NaN","id":38761677},{"spn":2.66,"spf":1.0,"id":40324291}],"con":true,"img":false}]}
{"op":"mcm","clk":"5348713361","pt":1646220064894,"mc":[{"id":"1.195453628","rc":[{"atb":[[1.53,2.16],[1.57,0]],"id":38761677}],"con":true,"img":false}]}
{"op":"mcm","clk":"5348713420","pt":1646220065276,"mc":[{"id":"1.195453628","rc":[{"atb":[[5.1,2.49],[4.7,24.44]],"id":27868829}],"con":true,"img":false}]}
{"op":"mcm","clk":"5348713580","pt":1646220066890,"mc":[{"id":"1.195453628","rc":[{"atb":[[2.42,0]],"id":41818958},{"atb":[[1.5,0]],"id":38761677}],"con":true,"img":false}]}
{"op":"mcm","clk":"5348713756","pt":1646220068466,"mc":[{"id":"1.195453628","rc":[{"atb":[[5.2,0]],"id":27868829}],"con":true,"img":false}]}
{"op":"mcm","clk":"5348713775","pt":1646220068686,"mc":[{"id":"1.195453628","rc":[{"atb":[[5.4,1.66]],"id":27868829}],"con":true,"img":false}]}
{"op":"mcm","clk":"5348714115","pt":1646220072207,"mc":[{"id":"1.195453628","rc":[{"atb":[[1.4,282.25],[1.46,2.5]],"id":38761677}],"con":true,"img":false}]}
{"op":"mcm","clk":"5348714517","pt":1646220075398,"mc":[{"id":"1.195453628","rc":[{"atb":[[1.43,2.16],[1.53,0]],"id":38761677}],"con":true,"img":false}]}
{"op":"mcm","clk":"5348714547","pt":1646220075602,"mc":[{"id":"1.195453628","rc":[{"atb":[[1.46,66.71]],"id":38761677}],"con":true,"img":false}]}
{"op":"mcm","clk":"5348715167","pt":1646220080616,"mc":[{"id":"1.195453628","rc":[{"atb":[[2.08,0]],"id":41818958}],"con":true,"img":false}]}
{"op":"mcm","clk":"5348715179","pt":1646220080725,"mc":[{"id":"1.195453628","rc":[{"atb":[[2.46,29.62]],"id":41818958}],"con":true,"img":false}]}
{"op":"mcm","clk":"5348715206","pt":1646220080894,"mc":[{"id":"1.195453628","rc":[{"atb":[[2.44,4.99],[2.46,69.16]],"id":41818958}],"con":true,"img":false}]}
{"op":"mcm","clk":"5348715327","pt":1646220081810,"mc":[{"id":"1.195453628","rc":[{"atb":[[2.32,12]],"id":39734233}],"con":true,"img":false}]}
{"op":"mcm","clk":"5348715350","pt":1646220082013,"mc":[{"id":"1.195453628","rc":[{"atb":[[1.49,15.32]],"id":38761677}],"con":true,"img":false}]}
{"op":"mcm","clk":"5348715375","pt":1646220082217,"mc":[{"id":"1.195453628","rc":[{"atb":[[2.02,8.16]],"id":41818958},{"atb":[[1.43,130.58],[1.4,84.78],[1.49,32.32]],"id":38761677}],"con":true,"img":false}]}
{"op":"mcm","clk":"5348715850","pt":1646220086024,"mc":[{"id":"1.195453628","rc":[{"atb":[[2.3,0],[2.38,2.16]],"id":39734233},{"atb":[[1.43,128.42],[1.52,2.16]],"id":38761677}],"con":true,"img":false}]}
{"op":"mcm","clk":"5348716141","pt":1646220088324,"mc":[{"id":"1.195453628","rc":[{"atb":[[1.46,208.25],[1.43,0]],"id":38761677}],"con":true,"img":false}]}
{"op":"mcm","clk":"5348716190","pt":1646220088633,"mc":[{"id":"1.195453628","rc":[{"atl":[[2.92,0]],"id":38761677}],"con":true,"img":false}]}
{"op":"mcm","clk":"5348716199","pt":1646220088734,"mc":[{"id":"1.195453628","rc":[{"atl":[[2.72,39.58]],"id":38761677}],"con":true,"img":false}]}
{"op":"mcm","clk":"5348716317","pt":1646220089631,"mc":[{"id":"1.195453628","rc":[{"atb":[[1.94,0]],"id":41818958}],"con":true,"img":false}]}
{"op":"mcm","clk":"5348716336","pt":1646220089732,"mc":[{"id":"1.195453628","rc":[{"atb":[[1.99,39.59]],"id":41818958}],"con":true,"img":false}]}
{"op":"mcm","clk":"5348716828","pt":1646220093637,"mc":[{"id":"1.195453628","rc":[{"atb":[[1.4,0]],"id":38761677}],"con":true,"img":false}]}
{"op":"mcm","clk":"5348716845","pt":1646220093739,"mc":[{"id":"1.195453628","rc":[{"atb":[[1.5,84.78]],"id":38761677}],"con":true,"img":false}]}
{"op":"mcm","clk":"5348717171","pt":1646220096143,"mc":[{"id":"1.195453628","rc":[{"atb":[[2.46,39.54]],"id":41818958}],"con":true,"img":false}]}
{"op":"mcm","clk":"5348717186","pt":1646220096249,"mc":[{"id":"1.195453628","rc":[{"atb":[[2.48,31.78]],"id":41818958}],"con":true,"img":false}]}
{"op":"mcm","clk":"5348717331","pt":1646220097243,"mc":[{"id":"1.195453628","rc":[{"atb":[[1.49,16.99]],"id":38761677}],"con":true,"img":false}]}
{"op":"mcm","clk":"5348717446","pt":1646220098134,"mc":[{"id":"1.195453628","rc":[{"atb":[[1.46,66.71],[1.49,145.41]],"id":38761677}],"con":true,"img":false}]}
{"op":"mcm","clk":"5348717665","pt":1646220099607,"mc":[{"id":"1.195453628","rc":[{"atb":[[2,16.35]],"id":38761677}],"con":true,"img":false}]}
{"op":"mcm","clk":"5348717814","pt":1646220100856,"mc":[{"id":"1.195453628","rc":[{"atb":[[2.38,0]],"id":39734233},{"atb":[[2.48,29.62]],"id":41818958},{"atb":[[2.6,0]],"id":38214982},{"atb":[[1.52,0]],"id":38761677},{"atb":[[2.56,15.68]],"id":40324291}],"con":true,"img":false}]}
{"op":"mcm","clk":"5348717840","pt":1646220101035,"mc":[{"id":"1.195453628","rc":[{"atb":[[2.24,187.81],[2.26,40.36]],"id":39734233}],"con":true,"img":false}]}
{"op":"mcm","clk":"5348718062","pt":1646220102651,"mc":[{"id":"1.195453628","rc":[{"atb":[[2.34,28.33]],"id":39734233},{"atb":[[2.54,9.99]],"id":41818958},{"atb":[[1.51,92.53]],"id":38761677}],"con":true,"img":false}]}
{"op":"mcm","clk":"5348718085","pt":1646220102857,"mc":[{"id":"1.195453628","rc":[{"atb":[[2.46,0]],"id":41818958}],"con":true,"img":false}]}
{"op":"mcm","clk":"5348718127","pt":1646220103138,"mc":[{"id":"1.195453628","rc":[{"atb":[[2.48,0]],"id":41818958}],"con":true,"img":false}]}
{"op":"mcm","clk":"5348718145","pt":1646220103250,"mc":[{"id":"1.195453628","rc":[{"atb":[[2.1,29.62]],"id":41818958}],"con":true,"img":false}]}
{"op":"mcm","clk":"5348718158","pt":1646220103356,"mc":[{"id":"1.195453628","rc":[{"atb":[[2.44,31.76]],"id":41818958}],"con":true,"img":false}]}
{"op":"mcm","clk":"5348718251","pt":1646220104129,"mc":[{"id":"1.195453628","rc":[{"atb":[[1.5,284.28],[1.49,16.99]],"id":38761677}],"con":true,"img":false}]}
{"op":"mcm","clk":"5348718492","pt":1646220106055,"mc":[{"id":"1.195453628","rc":[{"atl":[[3.85,0],[3.8,69.57],[3.55,29.23],[4,0],[3.95,0],[3.7,20.52],[3.9,43.1]],"id":41818958},{"atb":[[3.1,4.66],[2.98,21.5],[2.96,0]],"id":38214982},{"atb":[[1.46,64.21]],"id":38761677},{"atl":[[5.3,2.5]],"id":40324291}],"con":true,"img":false}]}
{"op":"mcm","clk":"5348718519","pt":1646220106265,"mc":[{"id":"1.195453628","rc":[{"atb":[[2.98,4]],"id":38214982}],"con":true,"img":false}]}
{"op":"mcm","clk":"5348718575","pt":1646220106675,"mc":[{"id":"1.195453628","rc":[{"atl":[[7,0]],"id":40324291}],"con":true,"img":false}]}
{"op":"mcm","clk":"5348718591","pt":1646220106739,"mc":[{"id":"1.195453628","rc":[{"atl":[[8,17.65]],"id":40324291}],"con":true,"img":false}]}
{"op":"mcm","clk":"5348718621","pt":1646220106953,"mc":[{"id":"1.195453628","rc":[{"atl":[[3.65,3]],"id":41818958}],"con":true,"img":false}]}
{"op":"mcm","clk":"5348718841","pt":1646220108661,"mc":[{"id":"1.195453628","rc":[{"atb":[[2.58,5]],"id":40324291}],"con":true,"img":false}]}
{"op":"mcm","clk":"5348718856","pt":1646220108733,"mc":[{"id":"1.195453628","rc":[{"atb":[[2.36,33.03]],"id":40324291}],"con":true,"img":false}]}
{"op":"mcm","clk":"5348718931","pt":1646220109357,"mc":[{"id":"1.195453628","rc":[{"atl":[[3.6,2],[3.7,18.52]],"id":41818958}],"con":true,"img":false}]}
{"op":"mcm","clk":"5348719008","pt":1646220109966,"mc":[{"id":"1.195453628","rc":[{"atb":[[2.54,1.66]],"id":41818958}],"con":true,"img":false}]}
{"op":"mcm","clk":"5348719090","pt":1646220110664,"mc":[{"id":"1.195453628","rc":[{"atb":[[2.44,5],[2.36,31.26]],"id":41818958}],"con":true,"img":false}]}
{"op":"mcm","clk":"5348719209","pt":1646220111664,"mc":[{"id":"1.195453628","rc":[{"atl":[[11,0]],"id":27868829}],"con":true,"img":false}]}
{"op":"mcm","clk":"5348719224","pt":1646220111770,"mc":[{"id":"1.195453628","rc":[{"atl":[[12,3.96]],"id":27868829}],"con":true,"img":false}]}
{"op":"mcm","clk":"5348719290","pt":1646220112290,"mc":[{"id":"1.195453628","rc":[{"atl":[[3.2,24.15],[3.1,9.52]],"id":39734233},{"atb":[[2.54,4.16],[2.44,0],[2.36,21.26],[2.52,0],[2.38,10],[2.46,5]],"id":41818958},{"atl":[[3.6,9.69],[3.55,24.39]],"id":41818958},{"atb":[[3.1,1.66],[3,0],[2.98,0],[3.05,0]],"id":38214982},{"atl":[[10.5,12.64],[11.5,0]],"id":38214982},{"atl":[[10,2.22],[9.8,0]],"id":27868829},{"atb":[[1.22,0],[1.29,344.83]],"id":38761677},{"atb":[[2.5,0],[2.6,5],[2.58,0],[2.66,7.84],[2.68,4.16]],"id":40324291}],"con":true,"img":false}]}
{"op":"mcm","clk":"5348719315","pt":1646220112463,"mc":[{"id":"1.195453628","rc":[{"atl":[[3.1,43.94],[3.35,42.55],[3.3,90.58]],"id":39734233},{"atb":[[2.54,25.7]],"id":38214982},{"atl":[[9.6,0]],"id":27868829},{"atb":[[2.56,0],[2.6,24.93],[2.68,14.13]],"id":40324291}],"con":true,"img":false}]}
{"op":"mcm","clk":"5348719343","pt":1646220112659,"mc":[{"id":"1.195453628","rc":[{"atl":[[3.2,0]],"id":39734233},{"atl":[[10,8.04]],"id":27868829},{"atb":[[2.66,0]],"id":40324291}],"con":true,"img":false}]}
{"op":"mcm","clk":"5348719422","pt":1646220113238,"mc":[{"id":"1.195453628","rc":[{"atb":[[2.38,26.66]],"id":41818958}],"con":true,"img":false}]}
{"op":"mcm","clk":"5348719655","pt":1646220115043,"mc":[{"id":"1.195453628","rc":[{"atb":[[2.34,0]],"id":39734233},{"atb":[[2.56,30.24]],"id":38214982}],"con":true,"img":false}]}
{"op":"mcm","clk":"5348720042","pt":1646220118072,"mc":[{"id":"1.195453628","rc":[{"atb":[[2.54,20.83]],"id":38214982}],"con":true,"img":false}]}
{"op":"mcm","clk":"5348720105","pt":1646220118581,"mc":[{"id":"1.195453628","rc":[{"atl":[[3.7,21.52]],"id":41818958},{"atb":[[5.3,9.72]],"id":27868829}],"con":true,"img":false}]}
{"op":"mcm","clk":"5348720122","pt":1646220118644,"mc":[{"id":"1.195453628","rc":[{"atb":[[4.8,12.11]],"id":27868829}],"con":true,"img":false}]}
{"op":"mcm","clk":"5348720134","pt":1646220118753,"mc":[{"id":"1.195453628","rc":[{"atb":[[2.34,24]],"id":39734233}],"con":true,"img":false}]}
{"op":"mcm","clk":"5348720141","pt":1646220118850,"mc":[{"id":"1.195453628","rc":[{"atb":[[2.36,0],[2.38,48.7]],"id":41818958},{"atb":[[4.8,34.88],[4.7,4.99]],"id":27868829}],"con":true,"img":false}]}
{"op":"mcm","clk":"5348720162","pt":1646220118972,"mc":[{"id":"1.195453628","rc":[{"atb":[[2.26,164.74],[2.24,55.21]],"id":39734233}],"con":true,"img":false}]}
{"op":"mcm","clk":"5348720177","pt":1646220119078,"mc":[{"id":"1.195453628","rc":[{"atb":[[1.5,199.5]],"id":38761677}],"con":true,"img":false}]}
{"op":"mcm","clk":"5348720192","pt":1646220119179,"mc":[{"id":"1.195453628","rc":[{"atb":[[1.52,84.78]],"id":38761677}],"con":true,"img":false}]}
{"op":"mcm","clk":"5348720217","pt":1646220119373,"mc":[{"id":"1.195453628","rc":[{"atb":[[1.51,297.92],[1.5,0]],"id":38761677}],"con":true,"img":false}]}
{"op":"mcm","clk":"5348720268","pt":1646220119751,"mc":[{"id":"1.195453628","rc":[{"atl":[[3.35,135.2],[3.3,21.74]],"id":39734233},{"atb":[[2.36,115.39],[2.6,5]],"id":40324291}],"con":true,"img":false}]}
{"op":"mcm","clk":"5348720302","pt":1646220120060,"mc":[{"id":"1.195453628","rc":[{"atl":[[7.6,25.02]],"id":41818958}],"con":true,"img":false}]}
{"op":"mcm","clk":"5348720312","pt":1646220120168,"mc":[{"id":"1.195453628","rc":[{"atl":[[5.8,0]],"id":41818958}],"con":true,"img":false}]}
{"op":"mcm","clk":"5348720387","pt":1646220120751,"mc":[{"id":"1.195453628","rc":[{"atl":[[3.25,2.15]],"id":39734233}],"con":true,"img":false}]}
{"op":"mcm","clk":"5348720444","pt":1646220121170,"mc":[{"id":"1.195453628","rc":[{"atl":[[4.5,44.79]],"id":40324291}],"con":true,"img":false}]}
{"op":"mcm","clk":"5348720461","pt":1646220121264,"mc":[{"id":"1.195453628","rc":[{"atl":[[4.4,10.9]],"id":40324291}],"con":true,"img":false}]}
{"op":"mcm","clk":"5348720494","pt":1646220121482,"mc":[{"id":"1.195453628","rc":[{"atl":[[3.8,26.79],[3.65,25.04]],"id":41818958},{"atb":[[2.48,93.37]],"id":38214982},{"atl":[[4.4,48.46],[4.5,0]],"id":40324291}],"con":true,"img":false}]}
{"op":"mcm","clk":"5348720523","pt":1646220121681,"mc":[{"id":"1.195453628","rc":[{"atb":[[1.51,205.39]],"id":38761677}],"con":true,"img":false}]}
{"op":"mcm","clk":"5348720588","pt":1646220122166,"mc":[{"id":"1.195453628","rc":[{"atl":[[3.25,0]],"id":39734233},{"atl":[[4.1,0]],"id":41818958}],"con":true,"img":false}]}
{"op":"mcm","clk":"5348720601","pt":1646220122276,"mc":[{"id":"1.195453628","rc":[{"atl":[[3.2,22.73]],"id":39734233},{"atl":[[3.85,13.21]],"id":41818958},{"atl":[[11.5,4.76]],"id":38214982},{"atl":[[11,5]],"id":27868829}],"con":true,"img":false}]}
{"op":"mcm","clk":"5348720651","pt":1646220122683,"mc":[{"id":"1.195453628","rc":[{"atl":[[3.15,2.1]],"id":39734233}],"con":true,"img":false}]}
{"op":"mcm","clk":"5348720669","pt":1646220122781,"mc":[{"id":"1.195453628","rc":[{"atl":[[3.5,0]],"id":39734233},{"atl":[[14.5,0]],"id":38214982},{"atl":[[10.5,0],[11.5,0],[12.5,0]],"id":27868829}],"con":true,"img":false}]}
{"op":"mcm","clk":"5348720693","pt":1646220122952,"mc":[{"id":"1.195453628","rc":[{"atb":[[2.02,0]],"id":41818958},{"atl":[[13.5,5.4]],"id":27868829},{"atb":[[1.49,0]],"id":38761677}],"con":true,"img":false}]}
{"op":"mcm","clk":"5348720713","pt":1646220123197,"mc":[{"id":"1.195453628","rc":[{"atb":[[2.1,0]],"id":41818958}],"con":true,"img":false}]}
{"op":"mcm","clk":"5348720728","pt":1646220123267,"mc":[{"id":"1.195453628","rc":[{"atb":[[2.4,29.62]],"id":41818958}],"con":true,"img":false}]}
{"op":"mcm","clk":"5348720982","pt":1646220125351,"mc":[{"id":"1.195453628","rc":[{"atb":[[2.34,0]],"id":39734233},{"spn":2.71,"spf":"NaN","id":39734233},{"spn":7.7,"spf":"NaN","id":27868829},{"atb":[[1.53,89.03]],"id":38761677},{"spn":2.25,"spf":"NaN","id":38761677},{"spn":2.68,"spf":1.0,"id":40324291}],"con":true,"img":false}]}
{"op":"mcm","clk":"5348721006","pt":1646220125561,"mc":[{"id":"1.195453628","rc":[{"atb":[[1.51,0]],"id":38761677}],"con":true,"img":false}]}
{"op":"mcm","clk":"5348721064","pt":1646220126086,"mc":[{"id":"1.195453628","rc":[{"atb":[[2.4,80.74],[2.38,26.66]],"id":41818958}],"con":true,"img":false}]}
{"op":"mcm","clk":"5348721073","pt":1646220126156,"mc":[{"id":"1.195453628","rc":[{"atb":[[2.24,155.21],[2.26,40.36]],"id":39734233},{"atl":[[2.72,0]],"id":38761677}],"con":true,"img":false}]}
{"op":"mcm","clk":"5348721084","pt":1646220126250,"mc":[{"id":"1.195453628","rc":[{"atl":[[2.92,39.58]],"id":38761677}],"con":true,"img":false}]}
{"op":"mcm","clk":"5348721181","pt":1646220127084,"mc":[{"id":"1.195453628","rc":[{"atl":[[3.15,0]],"id":39734233}],"con":true,"img":false}]}
{"op":"mcm","clk":"5348721223","pt":1646220127358,"mc":[{"id":"1.195453628","rc":[{"atl":[[3.1,46.18]],"id":39734233}],"con":true,"img":false}]}
{"op":"mcm","clk":"5348721280","pt":1646220127770,"mc":[{"id":"1.195453628","rc":[{"atl":[[3.35,42.55],[3.3,116.39]],"id":39734233},{"atb":[[2.56,48.83]],"id":38214982}],"con":true,"img":false}]}
{"op":"mcm","clk":"5348721295","pt":1646220127889,"mc":[{"id":"1.195453628","rc":[{"atb":[[2.54,5.4]],"id":38214982}],"con":true,"img":false}]}
{"op":"mcm","clk":"5348721404","pt":1646220128561,"mc":[{"id":"1.195453628","rc":[{"atb":[[3.1,0]],"id":38214982},{"atb":[[2.68,12.47]],"id":40324291}],"con":true,"img":false}]}
{"op":"mcm","clk":"5348721422","pt":1646220128668,"mc":[{"id":"1.195453628","rc":[{"atb":[[2.28,36.86]],"id":39734233},{"atb":[[2.38,10]],"id":41818958},{"atb":[[2.58,1.66]],"id":38214982}],"con":true,"img":false}]}
{"op":"mcm","clk":"5348721434","pt":1646220128762,"mc":[{"id":"1.195453628","rc":[{"atb":[[2.54,70.34],[2.46,13.7]],"id":38214982}],"con":true,"img":false}]}
{"op":"mcm","clk":"5348721451","pt":1646220128875,"mc":[{"id":"1.195453628","rc":[{"atb":[[2.24,55.21]],"id":39734233}],"con":true,"img":false}]}
{"op":"mcm","clk":"5348721599","pt":1646220130071,"mc":[{"id":"1.195453628","rc":[{"atb":[[2.32,6.31]],"id":39734233},{"atl":[[3.45,0]],"id":39734233}],"con":true,"img":false}]}
{"op":"mcm","clk":"5348721613","pt":1646220130181,"mc":[{"id":"1.195453628","rc":[{"atl":[[3.35,61.1]],"id":39734233}],"con":true,"img":false}]}
{"op":"mcm","clk":"5348721674","pt":1646220130601,"mc":[{"id":"1.195453628","rc":[{"atb":[[2.58,29.26],[2.48,53.01]],"id":38214982}],"con":true,"img":false}]}
{"op":"mcm","clk":"5348721711","pt":1646220130867,"mc":[{"id":"1.195453628","rc":[{"atb":[[2.24,0]],"id":39734233}],"con":true,"img":false}]}
{"op":"mcm","clk":"5348721723","pt":1646220130972,"mc":[{"id":"1.195453628","rc":[{"atl":[[3.1,43.94]],"id":39734233}],"con":true,"img":false}]}
{"op":"mcm","clk":"5348721765","pt":1646220131291,"mc":[{"id":"1.195453628","rc":[{"atl":[[3.1,46.18]],"id":39734233}],"con":true,"img":false}]}
{"op":"mcm","clk":"5348721816","pt":1646220131695,"mc":[{"id":"1.195453628","rc":[{"atb":[[2.42,15.62]],"id":41818958}],"con":true,"img":false}]}
{"op":"mcm","clk":"5348722022","pt":1646220133269,"mc":[{"id":"1.195453628","rc":[{"atl":[[3.3,127.26]],"id":39734233},{"atl":[[12.5,6.52]],"id":38214982},{"atl":[[12,10.78]],"id":27868829}],"con":true,"img":false}]}
{"op":"mcm","clk":"5348722034","pt":1646220133374,"mc":[{"id":"1.195453628","rc":[{"atb":[[2.56,18.59]],"id":38214982}],"con":true,"img":false}]}
{"op":"mcm","clk":"5348722109","pt":1646220134025,"mc":[{"id":"1.195453628","rc":[{"atb":[[2.4,29.62],[2.42,53.58]],"id":41818958}],"con":true,"img":false}]}
{"op":"mcm","clk":"5348722227","pt":1646220135067,"mc":[{"id":"1.195453628","rc":[{"atb":[[4,22.18]],"id":27868829}],"con":true,"img":false}]}
{"op":"mcm","clk":"5348722235","pt":1646220135164,"mc":[{"id":"1.195453628","rc":[{"atb":[[3.75,0]],"id":27868829}],"con":true,"img":false}]}
{"op":"mcm","clk":"5348722282","pt":1646220135594,"mc":[{"id":"1.195453628","rc":[{"atb":[[4.8,22.77]],"id":27868829}],"con":true,"img":false}]}
{"op":"mcm","clk":"5348722294","pt":1646220135696,"mc":[{"id":"1.195453628","rc":[{"atb":[[4.9,12.11]],"id":27868829}],"con":true,"img":false}]}
{"op":"mcm","clk":"5348722317","pt":1646220135905,"mc":[{"id":"1.195453628","rc":[{"atb":[[4.8,0],[4.9,40.34]],"id":27868829}],"con":true,"img":false}]}
{"op":"mcm","clk":"5348722398","pt":1646220136589,"mc":[{"id":"1.195453628","rc":[{"atb":[[2.54,119.98],[2.6,29.49]],"id":38214982}],"con":true,"img":false}]}
{"op":"mcm","clk":"5348722414","pt":1646220136693,"mc":[{"id":"1.195453628","rc":[{"atb":[[2.48,0]],"id":38214982}],"con":true,"img":false}]}
{"op":"mcm","clk":"5348722470","pt":1646220137113,"mc":[{"id":"1.195453628","rc":[{"atl":[[4.4,37.56]],"id":40324291}],"con":true,"img":false}]}
{"op":"mcm","clk":"5348722491","pt":1646220137316,"mc":[{"id":"1.195453628","rc":[{"atl":[[4.3,10.9]],"id":40324291}],"con":true,"img":false}]}
{"op":"mcm","clk":"5348722514","pt":1646220137477,"mc":[{"id":"1.195453628","rc":[{"atl":[[4.3,45.96],[4.4,0]],"id":40324291}],"con":true,"img":false}]}
{"op":"mcm","clk":"5348722659","pt":1646220138578,"mc":[{"id":"1.195453628","rc":[{"atb":[[2.58,1.66]],"id":38214982},{"atl":[[2.5,36.69]],"id":38761677}],"con":true,"img":false}]}
{"op":"mcm","clk":"5348722673","pt":1646220138679,"mc":[{"id":"1.195453628","rc":[{"atb":[[2.26,156.22]],"id":39734233},{"atb":[[2.56,46.18]],"id":38214982},{"atl":[[2.58,25.34]],"id":38761677}],"con":true,"img":false}]}
{"op":"mcm","clk":"5348722687","pt":1646220138780,"mc":[{"id":"1.195453628","rc":[{"atl":[[2.5,0]],"id":38761677}],"con":true,"img":false}]}
{"op":"mcm","clk":"5348722703","pt":1646220138887,"mc":[{"id":"1.195453628","rc":[{"atl":[[3.1,43.94]],"id":39734233},{"atl":[[2.6,2.5],[2.58,118.4]],"id":38761677}],"con":true,"img":false}]}
{"op":"mcm","clk":"5348722714","pt":1646220138987,"mc":[{"id":"1.195453628","rc":[{"atl":[[2.52,46.53]],"id":38761677}],"con":true,"img":false}]}
{"op":"mcm","clk":"5348722746","pt":1646220139203,"mc":[{"id":"1.195453628","rc":[{"atl":[[3.25,2.15]],"id":39734233}],"con":true,"img":false}]}
{"op":"mcm","clk":"5348722768","pt":1646220139363,"mc":[{"id":"1.195453628","rc":[{"atl":[[3.25,91.55],[3.3,32.61]],"id":39734233}],"con":true,"img":false}]}
{"op":"mcm","clk":"5348723029","pt":1646220141609,"mc":[{"id":"1.195453628","rc":[{"atb":[[1.52,0]],"id":38761677}],"con":true,"img":false}]}
{"op":"mcm","clk":"5348723044","pt":1646220141709,"mc":[{"id":"1.195453628","rc":[{"atb":[[1.54,84.78]],"id":38761677}],"con":true,"img":false}]}
{"op":"mcm","clk":"5348723053","pt":1646220141763,"mc":[{"id":"1.195453628","rc":[{"atb":[[1.46,230.32],[1.42,2.5]],"id":38761677}],"con":true,"img":false}]}
{"op":"mcm","clk":"5348723069","pt":1646220141865,"mc":[{"id":"1.195453628","rc":[{"atb":[[1.46,64.21]],"id":38761677}],"con":true,"img":false}]}
{"op":"mcm","clk":"5348723175","pt":1646220142782,"mc":[{"id":"1.195453628","rc":[{"atb":[[2.6,48.08]],"id":38214982}],"con":true,"img":false}]}
{"op":"mcm","clk":"5348723203","pt":1646220142989,"mc":[{"id":"1.195453628","rc":[{"atb":[[2.56,27.59]],"id":38214982}],"con":true,"img":false}]}
{"op":"mcm","clk":"5348723296","pt":1646220143720,"mc":[{"id":"1.195453628","rc":[{"atb":[[1.53,0]],"id":38761677}],"con":true,"img":false}]}
{"op":"mcm","clk":"5348723333","pt":1646220143992,"mc":[{"id":"1.195453628","rc":[{"atl":[[3.4,52.08]],"id":39734233},{"atl":[[13.5,10]],"id":38214982},{"atl":[[13,10.42]],"id":27868829}],"con":true,"img":false}]}
{"op":"mcm","clk":"5348723471","pt":1646220145087,"mc":[{"id":"1.195453628","rc":[{"atb":[[2.26,115.86]],"id":39734233}],"con":true,"img":false}]}
{"op":"mcm","clk":"5348723488","pt":1646220145195,"mc":[{"id":"1.195453628","rc":[{"atb":[[2.3,40.36]],"id":39734233}],"con":true,"img":false}]}
{"op":"mcm","clk":"5348723517","pt":1646220145413,"mc":[{"id":"1.195453628","rc":[{"atb":[[2.26,0],[2.28,152.72]],"id":39734233}],"con":true,"img":false}]}
{"op":"mcm","clk":"5348723710","pt":1646220146906,"mc":[{"id":"1.195453628","rc":[{"atb":[[1.47,100.4]],"id":38761677}],"con":true,"img":false}]}
{"op":"mcm","clk":"5348723941","pt":1646220148725,"mc":[{"id":"1.195453628","rc":[{"atb":[[2.28,115.86]],"id":39734233}],"con":true,"img":false}]}
{"op":"mcm","clk":"5348723998","pt":1646220149102,"mc":[{"id":"1.195453628","rc":[{"atb":[[1.54,0]],"id":38761677}],"con":true,"img":false}]}
{"op":"mcm","clk":"5348724013","pt":1646220149208,"mc":[{"id":"1.195453628","rc":[{"atb":[[1.48,84.78]],"id":38761677}],"con":true,"img":false}]}
{"op":"mcm","clk":"5348724055","pt":1646220149516,"mc":[{"id":"1.195453628","rc":[{"atb":[[2.58,0]],"id":38214982}],"con":true,"img":false}]}
{"op":"mcm","clk":"5348724085","pt":1646220149720,"mc":[{"id":"1.195453628","rc":[{"atb":[[2.62,1.66]],"id":38214982}],"con":true,"img":false}]}
{"op":"mcm","clk":"5348724133","pt":1646220150134,"mc":[{"id":"1.195453628","rc":[{"atb":[[2.4,0]],"id":41818958}],"con":true,"img":false}]}
{"op":"mcm","clk":"5348724149","pt":1646220150203,"mc":[{"id":"1.195453628","rc":[{"atb":[[2.44,29.62]],"id":41818958}],"con":true,"img":false}]}
{"op":"mcm","clk":"5348724171","pt":1646220150406,"mc":[{"id":"1.195453628","rc":[{"atb":[[2.44,80.74],[2.42,15.62]],"id":41818958}],"con":true,"img":false}]}
{"op":"mcm","clk":"5348724240","pt":1646220151051,"mc":[{"id":"1.195453628","rc":[{"atb":[[2.28,0]],"id":39734233},{"atl":[[3.5,4],[3.7,18.52],[3.65,22.04]],"id":41818958},{"atb":[[2.98,4],[2.58,5],[2.66,2.5]],"id":38214982},{"atl":[[10.5,10.53],[11.5,1.9]],"id":38214982}],"con":true,"img":false}]}
{"op":"mcm","clk":"5348724263","pt":1646220151241,"mc":[{"id":"1.195453628","rc":[{"atl":[[3.6,31.73],[3.5,15.02],[3.65,0]],"id":41818958}],"con":true,"img":false}]}
{"op":"mcm","clk":"5348724291","pt":1646220151399,"mc":[{"id":"1.195453628","rc":[{"atl":[[3.55,3]],"id":41818958},{"atb":[[2.54,70.34],[2.6,72.52]],"id":38214982}],"con":true,"img":false}]}
{"op":"mcm","clk":"5348724328","pt":1646220151714,"mc":[{"id":"1.195453628","rc":[{"atl":[[3.45,3]],"id":41818958},{"atb":[[3.3,4]],"id":38214982}],"con":true,"img":false}]}
{"op":"mcm","clk":"5348724340","pt":1646220151815,"mc":[{"id":"1.195453628","rc":[{"atb":[[2.98,0]],"id":38214982}],"con":true,"img":false}]}
{"op":"mcm","clk":"5348724372","pt":1646220152022,"mc":[{"id":"1.195453628","rc":[{"atb":[[3.35,3],[3.3,0]],"id":38214982}],"con":true,"img":false}]}
{"op":"mcm","clk":"5348724387","pt":1646220152131,"mc":[{"id":"1.195453628","rc":[{"atb":[[2.34,12.62]],"id":39734233},{"atb":[[1.47,0]],"id":38761677}],"con":true,"img":false}]}
{"op":"mcm","clk":"5348724451","pt":1646220152635,"mc":[{"id":"1.195453628","rc":[{"atb":[[4.9,28.23]],"id":27868829}],"con":true,"img":false}]}
{"op":"mcm","clk":"5348724465","pt":1646220152704,"mc":[{"id":"1.195453628","rc":[{"atb":[[5,12.11]],"id":27868829}],"con":true,"img":false}]}
{"op":"mcm","clk":"5348724492","pt":1646220152925,"mc":[{"id":"1.195453628","rc":[{"atb":[[5,40.34],[4.9,0]],"id":27868829}],"con":true,"img":false}]}
{"op":"mcm","clk":"5348724554","pt":1646220153470,"mc":[{"id":"1.195453628","rc":[{"atl":[[3.45,0],[3.65,4]],"id":41818958},{"atb":[[3.35,0],[3.4,3]],"id":38214982}],"con":true,"img":false}]}
{"op":"mcm","clk":"5348724583","pt":1646220153628,"mc":[{"id":"1.195453628","rc":[{"atb":[[2.56,0],[3.45,3]],"id":38214982}],"con":true,"img":false}]}
{"op":"mcm","clk":"5348724598","pt":1646220153742,"mc":[{"id":"1.195453628","rc":[{"atb":[[2.62,29.26]],"id":38214982}],"con":true,"img":false}]}
{"op":"mcm","clk":"5348724614","pt":1646220153833,"mc":[{"id":"1.195453628","rc":[{"atb":[[2.42,0]],"id":41818958},{"atb":[[2.6,43.03]],"id":38214982}],"con":true,"img":false}]}
{"op":"mcm","clk":"5348724662","pt":1646220154211,"mc":[{"id":"1.195453628","rc":[{"atb":[[3.5,4]],"id":38214982}],"con":true,"img":false}]}
{"op":"mcm","clk":"5348724686","pt":1646220154412,"mc":[{"id":"1.195453628","rc":[{"atb":[[2.6,18.59]],"id":38214982}],"con":true,"img":false}]}
{"op":"mcm","clk":"5348724737","pt":1646220154823,"mc":[{"id":"1.195453628","rc":[{"atb":[[3.55,2]],"id":38214982}],"con":true,"img":false}]}
{"op":"mcm","clk":"5348724760","pt":1646220155031,"mc":[{"id":"1.195453628","rc":[{"atl":[[3.35,18.55],[3.3,76.09]],"id":39734233},{"atl":[[3.45,2],[3.65,0]],"id":41818958}],"con":true,"img":false}]}
{"op":"mcm","clk":"5348724769","pt":1646220155134,"mc":[{"id":"1.195453628","rc":[{"atl":[[2.58,93.06]],"id":38761677}],"con":true,"img":false}]}
{"op":"mcm","clk":"5348724778","pt":1646220155203,"mc":[{"id":"1.195453628","rc":[{"atl":[[2.5,25.34]],"id":38761677}],"con":true,"img":false}]}
{"op":"mcm","clk":"5348724799","pt":1646220155411,"mc":[{"id":"1.195453628","rc":[{"atl":[[2.54,131.39],[2.58,0],[2.48,53.91]],"id":38761677}],"con":true,"img":false}]}
{"op":"mcm","clk":"5348724816","pt":1646220155516,"mc":[{"id":"1.195453628","rc":[{"atb":[[1.49,96.3]],"id":38761677}],"con":true,"img":false}]}
{"op":"mcm","clk":"5348724828","pt":1646220155615,"mc":[{"id":"1.195453628","rc":[{"atb":[[1.51,93.01]],"id":39734233},{"atb":[[1.77,72.66]],"id":38214982},{"atl":[[2.52,0]],"id":38761677}],"con":true,"img":false}]}
{"op":"mcm","clk":"5348724843","pt":1646220155726,"mc":[{"id":"1.195453628","rc":[{"atb":[[1.62,0]],"id":39734233},{"atb":[[1.99,0]],"id":38214982}],"con":true,"img":false}]}
{"op":"mcm","clk":"5348724890","pt":1646220156128,"mc":[{"id":"1.195453628","rc":[{"atl":[[3.85,0]],"id":41818958}],"con":true,"img":false}]}
{"op":"mcm","clk":"5348724902","pt":1646220156232,"mc":[{"id":"1.195453628","rc":[{"atl":[[4.1,13.21]],"id":41818958}],"con":true,"img":false}]}
{"op":"mcm","clk":"5348724938","pt":1646220156541,"mc":[{"id":"1.195453628","rc":[{"atb":[[1.48,292.82]],"id":38761677}],"con":true,"img":false}]}
{"op":"mcm","clk":"5348724959","pt":1646220156719,"mc":[{"id":"1.195453628","rc":[{"atb":[[2.3,0]],"id":39734233},{"atb":[[1.77,67.07]],"id":40324291}],"con":true,"img":false}]}
{"op":"mcm","clk":"5348724967","pt":1646220156817,"mc":[{"id":"1.195453628","rc":[{"atb":[[2.18,40.36]],"id":39734233}],"con":true,"img":false}]}
{"op":"mcm","clk":"5348724988","pt":1646220156937,"mc":[{"id":"1.195453628","rc":[{"atb":[[2.16,186.21]],"id":39734233}],"con":true,"img":false}]}
{"op":"mcm","clk":"5348725041","pt":1646220157334,"mc":[{"id":"1.195453628","rc":[{"atb":[[2.48,12.49]],"id":41818958}],"con":true,"img":false}]}
{"op":"mcm","clk":"5348725079","pt":1646220157650,"mc":[{"id":"1.195453628","rc":[{"atb":[[2.32,0]],"id":39734233},{"atb":[[2.54,64.94]],"id":38214982}],"con":true,"img":false}]}
{"op":"mcm","clk":"5348725268","pt":1646220159241,"mc":[{"id":"1.195453628","rc":[{"atb":[[2.34,0]],"id":39734233}],"con":true,"img":false}]}
{"op":"mcm","clk":"5348725306","pt":1646220159439,"mc":[{"id":"1.195453628","rc":[{"atb":[[2.18,108.16],[2.16,100],[2.14,87.72]],"id":39734233}],"con":true,"img":false}]}
{"op":"mcm","clk":"5348725369","pt":1646220159949,"mc":[{"id":"1.195453628","rc":[{"atl":[[3.45,48.98],[3.2,0],[3.1,34.42],[3.3,32.61]],"id":39734233},{"atb":[[1.71,128.21],[1.35,250],[1.41,0],[1.75,26.67]],"id":41818958},{"atl":[[9.2,12.2],[10,2.22],[10.5,0]],"id":38214982},{"atb":[[1.18,111.11],[1.08,250]],"id":27868829},{"atl":[[9,0],[11,12],[9.4,0],[8.6,0],[9.8,0]],"id":38761677},{"atb":[[1.83,24.1],[1.8,125]],"id":40324291},{"atl":[[3.35,3],[3.95,6.78],[4.7,27.03]],"id":40324291}],"con":true,"img":false}]}
{"op":"mcm","clk":"5348725388","pt":1646220160018,"mc":[{"id":"1.195453628","rc":[{"atb":[[2.3,76.78],[2.22,0],[2.26,0],[2.34,0]],"id":40324291},{"atl":[[8.2,0],[8.4,0],[9.4,0],[8.6,0],[8.8,0]],"id":40324291}],"con":true,"img":false}]}
{"op":"mcm","clk":"5348725395","pt":1646220160130,"mc":[{"id":"1.195453628","rc":[{"atb":[[1.89,0],[1.88,136.16],[1.91,0]],"id":39734233},{"atl":[[3.1,0],[3.25,5.15],[3.3,102.8]],"id":39734233},{"atl":[[4.3,10.9],[11.5,0],[3.3,4]],"id":40324291}],"con":true,"img":false}]}
{"op":"mcm","clk":"5348725421","pt":1646220160330,"mc":[{"id":"1.195453628","rc":[{"atl":[[3.2,4],[3.4,0],[3.3,137.58]],"id":39734233},{"atl":[[3.25,4]],"id":40324291}],"con":true,"img":false}]}
{"op":"mcm","clk":"5348725626","pt":1646220161948,"mc":[{"id":"1.195453628","rc":[{"atb":[[1.91,21.98]],"id":39734233},{"atl":[[3.2,0],[3.25,2.15]],"id":39734233},{"atb":[[1.81,24.69],[1.75,0]],"id":41818958},{"atl":[[3.6,29.73],[3.55,0],[3.5,11.02],[3.45,0]],"id":41818958},{"atb":[[3.55,0],[3.5,0],[3.45,0],[3.4,0]],"id":38214982},{"atl":[[9.2,14.64]],"id":38214982},{"atb":[[1.9,22.22]],"id":40324291},{"atl":[[3.35,0],[3.25,0],[3.3,0]],"id":40324291}],"con":true,"img":false}]}
{"op":"mcm","clk":"5348725638","pt":1646220162047,"mc":[{"id":"1.195453628","rc":[{"atl":[[4,33.33],[4.2,0]],"id":41818958},{"atb":[[2.54,0],[2.58,18.7],[2.66,10]],"id":38214982},{"atl":[[10,0]],"id":38214982}],"con":true,"img":false}]}
{"op":"mcm","clk":"5348725645","pt":1646220162111,"mc":[{"id":"1.195453628","rc":[{"atl":[[3.6,7.69],[3.7,53.8],[3.5,0]],"id":41818958},{"atl":[[3.95,35.66]],"id":40324291}],"con":true,"img":false}]}
{"op":"mcm","clk":"5348725657","pt":1646220162213,"mc":[{"id":"1.195453628","rc":[{"atb":[[2.6,0]],"id":38214982}],"con":true,"img":false}]}
{"op":"mcm","clk":"5348725669","pt":1646220162321,"mc":[{"id":"1.195453628","rc":[{"atl":[[3.7,63.32]],"id":41818958}],"con":true,"img":false}]}
{"op":"mcm","clk":"5348725688","pt":1646220162524,"mc":[{"id":"1.195453628","rc":[{"atb":[[2.2,39.32]],"id":39734233}],"con":true,"img":false}]}
{"op":"mcm","clk":"5348725734","pt":1646220162843,"mc":[{"id":"1.195453628","rc":[{"atb":[[2.42,14.08],[2.46,0]],"id":38214982},{"atl":[[8.4,3]],"id":38214982}],"con":true,"img":false}]}
{"op":"mcm","clk":"5348725741","pt":1646220162930,"mc":[{"id":"1.195453628","rc":[{"atl":[[5.1,9]],"id":38214982}],"con":true,"img":false}]}
{"op":"mcm","clk":"5348725795","pt":1646220163351,"mc":[{"id":"1.195453628","rc":[{"atl":[[5.1,6]],"id":38214982}],"con":true,"img":false}]}
{"op":"mcm","clk":"5348725826","pt":1646220163627,"mc":[{"id":"1.195453628","rc":[{"atl":[[5,2]],"id":38214982}],"con":true,"img":false}]}
{"op":"mcm","clk":"5348725849","pt":1646220163836,"mc":[{"id":"1.195453628","rc":[{"atl":[[5.3,0],[5,17.22],[5.2,40.72]],"id":38214982}],"con":true,"img":false}]}
{"op":"mcm","clk":"5348725866","pt":1646220163944,"mc":[{"id":"1.195453628","rc":[{"atl":[[8.2,3]],"id":38214982}],"con":true,"img":false}]}
{"op":"mcm","clk":"5348725878","pt":1646220164041,"mc":[{"id":"1.195453628","rc":[{"atl":[[5.1,0]],"id":38214982}],"con":true,"img":false}]}
{"op":"mcm","clk":"5348725889","pt":1646220164140,"mc":[{"id":"1.195453628","rc":[{"atb":[[2.68,20]],"id":38214982}],"con":true,"img":false}]}
{"op":"mcm","clk":"5348725905","pt":1646220164250,"mc":[{"id":"1.195453628","rc":[{"atl":[[3.25,0]],"id":39734233}],"con":true,"img":false}]}
{"op":"mcm","clk":"5348725939","pt":1646220164422,"mc":[{"id":"1.195453628","rc":[{"atl":[[4.3,2.5],[4.7,5]],"id":39734233}],"con":true,"img":false}]}
{"op":"mcm","clk":"5348725950","pt":1646220164561,"mc":[{"id":"1.195453628","rc":[{"atl":[[3.15,2.1]],"id":39734233}],"con":true,"img":false}]}
{"op":"mcm","clk":"5348725959","pt":1646220164630,"mc":[{"id":"1.195453628","rc":[{"atb":[[2.62,1.66]],"id":38214982}],"con":true,"img":false}]}
{"op":"mcm","clk":"5348725978","pt":1646220164728,"mc":[{"id":"1.195453628","rc":[{"atb":[[2.4,27.59]],"id":38214982}],"con":true,"img":false}]}
{"op":"mcm","clk":"5348726005","pt":1646220164945,"mc":[{"id":"1.195453628","rc":[{"atb":[[2.44,29.62],[2.46,35.29]],"id":41818958}],"con":true,"img":false}]}
{"op":"mcm","clk":"5348726074","pt":1646220165456,"mc":[{"id":"1.195453628","rc":[{"atl":[[8,2]],"id":38214982}],"con":true,"img":false}]}
{"op":"mcm","clk":"5348726095","pt":1646220165621,"mc":[{"id":"1.195453628","rc":[{"atl":[[3.35,0]],"id":39734233},{"atb":[[2.44,0]],"id":41818958}],"con":true,"img":false}]}
{"op":"mcm","clk":"5348726107","pt":1646220165725,"mc":[{"id":"1.195453628","rc":[{"atl":[[3.4,18.55]],"id":39734233},{"atb":[[2.46,64.91]],"id":41818958},{"atl":[[3.6,37.16]],"id":41818958}],"con":true,"img":false}]}
{"op":"mcm","clk":"5348726119","pt":1646220165830,"mc":[{"id":"1.195453628","rc":[{"atl":[[3.7,53.8]],"id":41818958}],"con":true,"img":false}]}
{"op":"mcm","clk":"5348726131","pt":1646220165938,"mc":[{"id":"1.195453628","rc":[{"atb":[[2.58,74.53]],"id":38214982}],"con":true,"img":false}]}
{"op":"mcm","clk":"5348726227","pt":1646220166757,"mc":[{"id":"1.195453628","rc":[{"atl":[[5.3,0]],"id":40324291}],"con":true,"img":false}]}
{"op":"mcm","clk":"5348726252","pt":1646220166931,"mc":[{"id":"1.195453628","rc":[{"atl":[[3.4,119.75],[3.3,34.78]],"id":39734233}],"con":true,"img":false}]}
{"op":"mcm","clk":"5348726280","pt":1646220167135,"mc":[{"id":"1.195453628","rc":[{"atb":[[1.48,208.04]],"id":38761677}],"con":true,"img":false}]}
{"op":"mcm","clk":"5348726293","pt":1646220167240,"mc":[{"id":"1.195453628","rc":[{"atb":[[1.5,84.78]],"id":38761677}],"con":true,"img":false}]}
{"op":"mcm","clk":"5348726374","pt":1646220168027,"mc":[{"id":"1.195453628","rc":[{"atl":[[7.8,4]],"id":38214982}],"con":true,"img":false}]}
{"op":"mcm","clk":"5348726433","pt":1646220168444,"mc":[{"id":"1.195453628","rc":[{"atl":[[3.15,0]],"id":39734233}],"con":true,"img":false}]}
{"op":"mcm","clk":"5348726462","pt":1646220168646,"mc":[{"id":"1.195453628","rc":[{"atl":[[3.3,0]],"id":39734233}],"con":true,"img":false}]}
{"op":"mcm","clk":"5348726480","pt":1646220168766,"mc":[{"id":"1.195453628","rc":[{"atl":[[3.4,153.08],[3.25,2.42]],"id":39734233}],"con":true,"img":false}]}
{"op":"mcm","clk":"5348726495","pt":1646220168864,"mc":[{"id":"1.195453628","rc":[{"atl":[[3.45,8.16],[4.3,32.8]],"id":39734233},{"atl":[[3.7,18.52],[3.8,117.71]],"id":41818958}],"con":true,"img":false}]}
{"op":"mcm","clk":"5348726555","pt":1646220169355,"mc":[{"id":"1.195453628","rc":[{"atb":[[1.49,0]],"id":38761677}],"con":true,"img":false}]}
{"op":"mcm","clk":"5348726642","pt":1646220170125,"mc":[{"id":"1.195453628","rc":[{"atl":[[2.92,0]],"id":38761677}],"con":true,"img":false}]}
{"op":"mcm","clk":"5348726665","pt":1646220170237,"mc":[{"id":"1.195453628","rc":[{"atb":[[1.16,250]],"id":27868829},{"atl":[[2.72,39.58],[12,4.55]],"id":38761677}],"con":true,"img":false}]}
{"op":"mcm","clk":"5348726698","pt":1646220170545,"mc":[{"id":"1.195453628","rc":[{"atb":[[2.62,0]],"id":38214982},{"atl":[[5.4,64.08],[5.2,10.28]],"id":38214982}],"con":true,"img":false}]}
{"op":"mcm","clk":"5348726715","pt":1646220170741,"mc":[{"id":"1.195453628","rc":[{"atb":[[2.22,1.66]],"id":39734233},{"atb":[[2.7,1.66]],"id":38214982}],"con":true,"img":false}]}
{"op":"mcm","clk":"5348726831","pt":1646220171655,"mc":[{"id":"1.195453628","rc":[{"atl":[[2.5,0]],"id":38761677}],"con":true,"img":false}]}
{"op":"mcm","clk":"5348726848","pt":1646220171753,"mc":[{"id":"1.195453628","rc":[{"atl":[[2.46,25.34]],"id":38761677}],"con":true,"img":false}]}
{"op":"mcm","clk":"5348726853","pt":1646220171845,"mc":[{"id":"1.195453628","rc":[{"atl":[[2.54,23.57],[2.6,136.2]],"id":38761677}],"con":true,"img":false}]}
{"op":"mcm","clk":"5348726877","pt":1646220171963,"mc":[{"id":"1.195453628","rc":[{"atl":[[2.46,80.13],[2.48,0]],"id":38761677}],"con":true,"img":false}]}
{"op":"mcm","clk":"5348726922","pt":1646220172261,"mc":[{"id":"1.195453628","rc":[{"atl":[[3.55,19.61]],"id":39734233},{"atb":[[1.79,63.29]],"id":41818958},{"atb":[[1.88,56.82]],"id":40324291},{"atl":[[4.1,16.13]],"id":40324291}],"con":true,"img":false}]}
{"op":"mcm","clk":"5348726984","pt":1646220172745,"mc":[{"id":"1.195453628","rc":[{"atb":[[1.51,92.53]],"id":38761677}],"con":true,"img":false}]}
{"op":"mcm","clk":"5348727006","pt":1646220172951,"mc":[{"id":"1.195453628","rc":[{"atb":[[1.48,0],[1.5,317.05]],"id":38761677}],"con":true,"img":false}]}
{"op":"mcm","clk":"5348727025","pt":1646220173154,"mc":[{"id":"1.195453628","rc":[{"atb":[[2.38,36.23]],"id":38214982},{"atl":[[9.6,5.81]],"id":38214982}],"con":true,"img":false}]}
{"op":"mcm","clk":"5348727044","pt":1646220173255,"mc":[{"id":"1.195453628","rc":[{"atb":[[1.98,0],[1.88,22.73],[1.93,0]],"id":39734233},{"atl":[[4.9,0],[7.8,0],[5.9,0]],"id":39734233}],"con":true,"img":false}]}
{"op":"mcm","clk":"5348727093","pt":1646220173671,"mc":[{"id":"1.195453628","rc":[{"atl":[[3.45,109.29],[3.4,51.88]],"id":39734233}],"con":true,"img":false}]}
{"op":"mcm","clk":"5348727121","pt":1646220173844,"mc":[{"id":"1.195453628","rc":[{"atb":[[2.2,105.99]],"id":39734233}],"con":true,"img":false}]}
