{"op":"mcm","clk":"5346220777","pt":1646178839810,"mc":[{"id":"1.195453651","marketDefinition":{"bspMarket":false,"turnInPlayEnabled":false,"persistenceEnabled":false,"marketBaseRate":7.0,"eventId":"31272494","eventTypeId":"4339","numberOfWinners":1,"bettingType":"ODDS","marketType":"MATCH_BET","marketTime":"2022-03-02T08:31:00.000Z","suspendTime":"2022-03-02T08:31:00.000Z","bspReconciled":false,"complete":true,"inPlay":false,"crossMatching":true,"runnersVoidable":false,"numberOfActiveRunners":2,"betDelay":0,"status":"OPEN","runners":[{"status":"ACTIVE","sortPriority":1,"id":43167166,"name":"3. Dolly Dagger"},{"status":"ACTIVE","sortPriority":2,"id":43016477,"name":"8. Before Noon"}],"regulators":["MR_INT"],"venue":"Traralgon","countryCode":"AU","discountAllowed":true,"timezone":"Australia/Sydney","openDate":"2022-03-02T08:31:00.000Z","version":4382489946,"name":"Dolly Dagger v Before Noon","eventName":"Traralgon (AUS) 2nd Mar"},"rc":[],"con":true,"img":false}]}
{"op":"mcm","clk":"5346224660","pt":1646178919306,"mc":[{"id":"1.195453651","rc":[{"atb":[[1.8,6.73],[1.6,8.98],[1.7,7.69]],"id":43167166},{"atb":[[1.8,6.73],[1.6,8.98],[1.7,7.69]],"id":43016477}],"con":true,"img":false}]}
{"op":"mcm","clk":"5346401472","pt":1646182002782,"mc":[{"id":"1.195453651","marketDefinition":{"bspMarket":false,"turnInPlayEnabled":false,"persistenceEnabled":false,"marketBaseRate":7.0,"eventId":"31272494","eventTypeId":"4339","numberOfWinners":1,"bettingType":"ODDS","marketType":"MATCH_BET","marketTime":"2022-03-02T08:31:00.000Z","suspendTime":"2022-03-02T08:31:00.000Z","bspReconciled":false,"complete":true,"inPlay":false,"crossMatching":true,"runnersVoidable":false,"numberOfActiveRunners":2,"betDelay":0,"status":"OPEN","runners":[{"status":"ACTIVE","sortPriority":1,"id":43167166,"name":"3. Dolly Dagger"},{"status":"ACTIVE","sortPriority":2,"id":43016477,"name":"8. Before Noon"}],"regulators":["MR_INT"],"venue":"Traralgon","countryCode":"AU","discountAllowed":true,"timezone":"Australia/Sydney","openDate":"2022-03-02T08:31:00.000Z","version":4382489946,"name":"Dolly Dagger v Before Noon","eventName":"Traralgon (AUS) 2nd Mar"},"rc":[{"atb":[[1.8,6.73],[1.6,8.98],[1.7,7.69]],"id":43167166},{"atb":[[1.8,6.73],[1.6,8.98],[1.7,7.69]],"id":43016477}],"con":true,"img":true}]}
{"op":"mcm","clk":"5346767827","pt":1646187402727,"mc":[{"id":"1.195453651","marketDefinition":{"bspMarket":false,"turnInPlayEnabled":false,"persistenceEnabled":false,"marketBaseRate":7.0,"eventId":"31272494","eventTypeId":"4339","numberOfWinners":1,"bettingType":"ODDS","marketType":"MATCH_BET","marketTime":"2022-03-02T08:31:00.000Z","suspendTime":"2022-03-02T08:31:00.000Z","bspReconciled":false,"complete":true,"inPlay":false,"crossMatching":true,"runnersVoidable":false,"numberOfActiveRunners":2,"betDelay":0,"status":"OPEN","runners":[{"status":"ACTIVE","sortPriority":1,"id":43167166,"name":"3. Dolly Dagger"},{"status":"ACTIVE","sortPriority":2,"id":43016477,"name":"8. Before Noon"}],"regulators":["MR_INT"],"venue":"Traralgon","countryCode":"AU","discountAllowed":true,"timezone":"Australia/Sydney","openDate":"2022-03-02T08:31:00.000Z","version":4382489946,"name":"Dolly Dagger v Before Noon","eventName":"Traralgon (AUS) 2nd Mar"},"rc":[{"atb":[[1.8,6.75],[1.6,8.99],[1.7,7.71]],"id":43167166},{"atb":[[1.8,6.75],[1.6,8.99],[1.7,7.71]],"id":43016477}],"con":true,"img":true}]}
{"op":"mcm","clk":"5347092378","pt":1646192802707,"mc":[{"id":"1.195453651","marketDefinition":{"bspMarket":false,"turnInPlayEnabled":false,"persistenceEnabled":false,"marketBaseRate":7.0,"eventId":"31272494","eventTypeId":"4339","numberOfWinners":1,"bettingType":"ODDS","marketType":"MATCH_BET","marketTime":"2022-03-02T08:31:00.000Z","suspendTime":"2022-03-02T08:31:00.000Z","bspReconciled":false,"complete":true,"inPlay":false,"crossMatching":true,"runnersVoidable":false,"numberOfActiveRunners":2,"betDelay":0,"status":"OPEN","runners":[{"status":"ACTIVE","sortPriority":1,"id":43167166,"name":"3. Dolly Dagger"},{"status":"ACTIVE","sortPriority":2,"id":43016477,"name":"8. Before Noon"}],"regulators":["MR_INT"],"venue":"Traralgon","countryCode":"AU","discountAllowed":true,"timezone":"Australia/Sydney","openDate":"2022-03-02T08:31:00.000Z","version":4382489946,"name":"Dolly Dagger v Before Noon","eventName":"Traralgon (AUS) 2nd Mar"},"rc":[{"atb":[[1.8,6.76],[1.6,9.01],[1.7,7.72]],"id":43167166},{"atb":[[1.8,6.76],[1.6,9.01],[1.7,7.72]],"id":43016477}],"con":true,"img":true}]}
{"op":"mcm","clk":"5347381239","pt":1646198202725,"mc":[{"id":"1.195453651","marketDefinition":{"bspMarket":false,"turnInPlayEnabled":false,"persistenceEnabled":false,"marketBaseRate":7.0,"eventId":"31272494","eventTypeId":"4339","numberOfWinners":1,"bettingType":"ODDS","marketType":"MATCH_BET","marketTime":"2022-03-02T08:31:00.000Z","suspendTime":"2022-03-02T08:31:00.000Z","bspReconciled":false,"complete":true,"inPlay":false,"crossMatching":true,"runnersVoidable":false,"numberOfActiveRunners":2,"betDelay":0,"status":"OPEN","runners":[{"status":"ACTIVE","sortPriority":1,"id":43167166,"name":"3. Dolly Dagger"},{"status":"ACTIVE","sortPriority":2,"id":43016477,"name":"8. Before Noon"}],"regulators":["MR_INT"],"venue":"Traralgon","countryCode":"AU","discountAllowed":true,"timezone":"Australia/Sydney","openDate":"2022-03-02T08:31:00.000Z","version":4382489946,"name":"Dolly Dagger v Before Noon","eventName":"Traralgon (AUS) 2nd Mar"},"rc":[{"atb":[[1.8,6.75],[1.6,9],[1.7,7.72]],"id":43167166},{"atb":[[1.8,6.75],[1.6,9],[1.7,7.72]],"id":43016477}],"con":true,"img":true}]}
{"op":"mcm","clk":"5347835291","pt":1646208873297,"mc":[{"id":"1.195453651","rc":[{"atb":[[1.8,6.75],[1.6,9],[1.81,2],[1.7,7.71]],"id":43167166},{"atl":[[2.48,2]],"id":43167166},{"atb":[[1.8,6.75],[1.6,9],[1.7,7.71],[1.65,2]],"id":43016477},{"atl":[[2.46,2]],"id":43016477}],"con":true,"img":false}]}
{"op":"mcm","clk":"5347837996","pt":1646208923133,"mc":[{"id":"1.195453651","rc":[{"atl":[[2.46,0],[2.44,2]],"id":43016477}],"con":true,"img":false}]}
{"op":"mcm","clk":"5347838590","pt":1646208933350,"mc":[{"id":"1.195453651","rc":[{"atb":[[1.81,0]],"id":43167166},{"atl":[[2.48,0]],"id":43167166},{"atb":[[1.65,0]],"id":43016477},{"atl":[[2.44,0]],"id":43016477}],"con":true,"img":false}]}
{"op":"mcm","clk":"5347851917","pt":1646209019514,"mc":[{"id":"1.195453651","rc":[{"atb":[[1.8,0],[1.6,0],[1.7,0]],"id":43167166},{"atb":[[1.8,0],[1.6,0],[1.7,0]],"id":43016477}],"con":true,"img":false}]}
{"op":"mcm","clk":"5347852148","pt":1646209023237,"mc":[{"id":"1.195453651","rc":[{"atb":[[1.8,6.75],[1.6,9],[1.7,7.71]],"id":43167166},{"atb":[[1.8,6.75],[1.6,9],[1.7,7.71]],"id":43016477}],"con":true,"img":false}]}
{"op":"mcm","clk":"5347854283","pt":1646209059262,"mc":[{"id":"1.195453651","rc":[{"atb":[[1.81,2]],"id":43167166},{"atl":[[2.48,2]],"id":43167166},{"atb":[[1.67,2]],"id":43016477},{"atl":[[2.4,2]],"id":43016477}],"con":true,"img":false}]}
{"op":"mcm","clk":"5347854603","pt":1646209064440,"mc":[{"id":"1.195453651","rc":[{"atl":[[2.4,0],[2.36,2]],"id":43016477}],"con":true,"img":false}]}
{"op":"mcm","clk":"5347854625","pt":1646209064852,"mc":[{"id":"1.195453651","rc":[{"atl":[[2.46,2],[2.48,0]],"id":43167166}],"con":true,"img":false}]}
{"op":"mcm","clk":"5347854926","pt":1646209070064,"mc":[{"id":"1.195453651","rc":[{"atl":[[2.46,0],[2.48,2]],"id":43167166}],"con":true,"img":false}]}
{"op":"mcm","clk":"5347856758","pt":1646209098510,"mc":[{"id":"1.195453651","rc":[{"atl":[[2.46,2],[2.48,0]],"id":43167166}],"con":true,"img":false}]}
{"op":"mcm","clk":"5347856799","pt":1646209099132,"mc":[{"id":"1.195453651","rc":[{"atl":[[2.36,0],[2.34,2]],"id":43016477}],"con":true,"img":false}]}
{"op":"mcm","clk":"5347858456","pt":1646209126534,"mc":[{"id":"1.195453651","rc":[{"atb":[[1.81,0],[1.89,2]],"id":43167166},{"atl":[[2.14,2],[2.34,0]],"id":43016477}],"con":true,"img":false}]}
{"op":"mcm","clk":"5347858462","pt":1646209126639,"mc":[{"id":"1.195453651","rc":[{"atb":[[1.89,0],[1.9,2]],"id":43167166},{"atl":[[2.12,2],[2.14,0]],"id":43016477}],"con":true,"img":false}]}
{"op":"mcm","clk":"5347858589","pt":1646209128960,"mc":[{"id":"1.195453651","rc":[{"atb":[[1.92,2],[1.9,0]],"id":43167166},{"atl":[[2.12,0],[2.1,2]],"id":43016477}],"con":true,"img":false}]}
{"op":"mcm","clk":"5347858988","pt":1646209136766,"mc":[{"id":"1.195453651","rc":[{"atb":[[1.92,0],[1.95,2]],"id":43167166},{"atl":[[2.1,0],[2.08,2]],"id":43016477}],"con":true,"img":false}]}
{"op":"mcm","clk":"5347859251","pt":1646209141870,"mc":[{"id":"1.195453651","rc":[{"atl":[[2.06,2],[2.08,0]],"id":43016477}],"con":true,"img":false}]}
{"op":"mcm","clk":"5347859260","pt":1646209141973,"mc":[{"id":"1.195453651","rc":[{"atb":[[1.98,2],[1.95,0]],"id":43167166}],"con":true,"img":false}]}
{"op":"mcm","clk":"5347859526","pt":1646209146984,"mc":[{"id":"1.195453651","rc":[{"atl":[[2.02,2]],"id":43016477}],"con":true,"img":false}]}
{"op":"mcm","clk":"5347859531","pt":1646209147089,"mc":[{"id":"1.195453651","rc":[{"atl":[[2.06,0]],"id":43016477}],"con":true,"img":false}]}
{"op":"mcm","clk":"5347859536","pt":1646209147190,"mc":[{"id":"1.195453651","rc":[{"atb":[[2,2],[1.98,0]],"id":43167166}],"con":true,"img":false}]}
{"op":"mcm","clk":"5347860642","pt":1646209168528,"mc":[{"id":"1.195453651","rc":[{"atb":[[2,0],[1.93,2]],"id":43167166}],"con":true,"img":false}]}
{"op":"mcm","clk":"5347860900","pt":1646209173646,"mc":[{"id":"1.195453651","rc":[{"atb":[[1.9,2],[1.93,0]],"id":43167166}],"con":true,"img":false}]}
{"op":"mcm","clk":"5347860960","pt":1646209174624,"mc":[{"id":"1.195453651","rc":[{"atb":[[1.9,0],[1.91,2]],"id":43167166}],"con":true,"img":false}]}
{"op":"mcm","clk":"5347861243","pt":1646209179727,"mc":[{"id":"1.195453651","rc":[{"atb":[[1.92,2],[1.91,0]],"id":43167166}],"con":true,"img":false}]}
{"op":"mcm","clk":"5347861687","pt":1646209189768,"mc":[{"id":"1.195453651","rc":[{"atb":[[1.92,0],[2.06,2]],"id":43167166},{"atl":[[2.02,0],[1.96,2]],"id":43016477}],"con":true,"img":false}]}
{"op":"mcm","clk":"5347861953","pt":1646209194857,"mc":[{"id":"1.195453651","rc":[{"atl":[[1.94,2]],"id":43016477}],"con":true,"img":false}]}
{"op":"mcm","clk":"5347861958","pt":1646209194960,"mc":[{"id":"1.195453651","rc":[{"atl":[[1.96,0]],"id":43016477}],"con":true,"img":false}]}
{"op":"mcm","clk":"5347864533","pt":1646209243945,"mc":[{"id":"1.195453651","rc":[{"atb":[[2.06,0],[1.81,2]],"id":43167166}],"con":true,"img":false}]}
{"op":"mcm","clk":"5347864752","pt":1646209249070,"mc":[{"id":"1.195453651","rc":[{"atb":[[1.92,2],[1.81,0]],"id":43167166}],"con":true,"img":false}]}
{"op":"mcm","clk":"5347865017","pt":1646209253750,"mc":[{"id":"1.195453651","rc":[{"atb":[[1.92,0],[1.85,2]],"id":43167166}],"con":true,"img":false}]}
{"op":"mcm","clk":"5347865291","pt":1646209258853,"mc":[{"id":"1.195453651","rc":[{"atb":[[1.85,0],[1.86,2]],"id":43167166}],"con":true,"img":false}]}
{"op":"mcm","clk":"5347865335","pt":1646209259767,"mc":[{"id":"1.195453651","rc":[{"atb":[[1.89,2],[1.86,0]],"id":43167166}],"con":true,"img":false}]}
{"op":"mcm","clk":"5347865404","pt":1646209261166,"mc":[{"id":"1.195453651","rc":[{"atb":[[1.88,2]],"id":43167166}],"con":true,"img":false}]}
{"op":"mcm","clk":"5347865411","pt":1646209261271,"mc":[{"id":"1.195453651","rc":[{"atb":[[1.89,0]],"id":43167166}],"con":true,"img":false}]}
{"op":"mcm","clk":"5347865724","pt":1646209266667,"mc":[{"id":"1.195453651","rc":[{"atb":[[1.89,2],[1.88,0]],"id":43167166}],"con":true,"img":false}]}
{"op":"mcm","clk":"5347865745","pt":1646209267079,"mc":[{"id":"1.195453651","rc":[{"atb":[[1.89,0],[1.91,2]],"id":43167166}],"con":true,"img":false}]}
{"op":"mcm","clk":"5347865941","pt":1646209270379,"mc":[{"id":"1.195453651","rc":[{"atb":[[1.89,2]],"id":43167166}],"con":true,"img":false}]}
{"op":"mcm","clk":"5347865950","pt":1646209270482,"mc":[{"id":"1.195453651","rc":[{"atb":[[1.91,0]],"id":43167166}],"con":true,"img":false}]}
{"op":"mcm","clk":"5347866001","pt":1646209271159,"mc":[{"id":"1.195453651","rc":[{"atb":[[1.89,0],[1.87,2]],"id":43167166}],"con":true,"img":false}]}
{"op":"mcm","clk":"5347866164","pt":1646209273976,"mc":[{"id":"1.195453651","rc":[{"atb":[[1.89,2],[1.87,0]],"id":43167166}],"con":true,"img":false}]}
{"op":"mcm","clk":"5347866491","pt":1646209279077,"mc":[{"id":"1.195453651","rc":[{"atb":[[1.88,2]],"id":43167166}],"con":true,"img":false}]}
{"op":"mcm","clk":"5347866495","pt":1646209279178,"mc":[{"id":"1.195453651","rc":[{"atb":[[1.89,0]],"id":43167166}],"con":true,"img":false}]}
{"op":"mcm","clk":"5347866918","pt":1646209286799,"mc":[{"id":"1.195453651","rc":[{"atb":[[1.89,2]],"id":43167166}],"con":true,"img":false}]}
{"op":"mcm","clk":"5347866925","pt":1646209286906,"mc":[{"id":"1.195453651","rc":[{"atb":[[1.88,0]],"id":43167166}],"con":true,"img":false}]}
{"op":"mcm","clk":"5347867191","pt":1646209291889,"mc":[{"id":"1.195453651","rc":[{"atb":[[1.88,2]],"id":43167166}],"con":true,"img":false}]}
{"op":"mcm","clk":"5347867197","pt":1646209291992,"mc":[{"id":"1.195453651","rc":[{"atb":[[1.89,0]],"id":43167166}],"con":true,"img":false}]}
{"op":"mcm","clk":"5347867524","pt":1646209298927,"mc":[{"id":"1.195453651","rc":[{"atb":[[1.88,0],[1.91,2]],"id":43167166}],"con":true,"img":false}]}
{"op":"mcm","clk":"5347867555","pt":1646209299435,"mc":[{"id":"1.195453651","rc":[{"atb":[[1.91,0],[1.9,2]],"id":43167166}],"con":true,"img":false}]}
{"op":"mcm","clk":"5347867779","pt":1646209304534,"mc":[{"id":"1.195453651","rc":[{"atb":[[1.9,0],[1.86,2]],"id":43167166}],"con":true,"img":false}]}
{"op":"mcm","clk":"5347868030","pt":1646209309611,"mc":[{"id":"1.195453651","rc":[{"atb":[[1.88,2]],"id":43167166}],"con":true,"img":false}]}
{"op":"mcm","clk":"5347868035","pt":1646209309722,"mc":[{"id":"1.195453651","rc":[{"atb":[[1.86,0]],"id":43167166}],"con":true,"img":false}]}
{"op":"mcm","clk":"5347868351","pt":1646209314725,"mc":[{"id":"1.195453651","rc":[{"atb":[[1.88,0],[1.85,2]],"id":43167166}],"con":true,"img":false}]}
{"op":"mcm","clk":"5347868958","pt":1646209327843,"mc":[{"id":"1.195453651","rc":[{"atb":[[1.81,2],[1.85,0]],"id":43167166}],"con":true,"img":false}]}
{"op":"mcm","clk":"5347869201","pt":1646209332965,"mc":[{"id":"1.195453651","rc":[{"atb":[[1.83,2]],"id":43167166}],"con":true,"img":false}]}
{"op":"mcm","clk":"5347869203","pt":1646209333049,"mc":[{"id":"1.195453651","rc":[{"atb":[[1.81,0]],"id":43167166}],"con":true,"img":false}]}
{"op":"mcm","clk":"5347869380","pt":1646209336461,"mc":[{"id":"1.195453651","rc":[{"atl":[[2.46,0],[2.44,2]],"id":43167166}],"con":true,"img":false}]}
{"op":"mcm","clk":"5347869471","pt":1646209338168,"mc":[{"id":"1.195453651","rc":[{"atb":[[1.83,0],[1.81,2]],"id":43167166}],"con":true,"img":false}]}
{"op":"mcm","clk":"5347870567","pt":1646209360204,"mc":[{"id":"1.195453651","rc":[{"atb":[[1.83,2],[1.81,0]],"id":43167166}],"con":true,"img":false}]}
{"op":"mcm","clk":"5347870675","pt":1646209362287,"mc":[{"id":"1.195453651","rc":[{"atb":[[1.83,0],[1.81,2]],"id":43167166}],"con":true,"img":false}]}
{"op":"mcm","clk":"5347871285","pt":1646209375399,"mc":[{"id":"1.195453651","rc":[{"atb":[[1.82,2],[1.81,0]],"id":43167166}],"con":true,"img":false}]}
{"op":"mcm","clk":"5347871543","pt":1646209380916,"mc":[{"id":"1.195453651","rc":[{"atb":[[1.81,2]],"id":43167166}],"con":true,"img":false}]}
{"op":"mcm","clk":"5347871547","pt":1646209381022,"mc":[{"id":"1.195453651","rc":[{"atb":[[1.82,0]],"id":43167166}],"con":true,"img":false}]}
{"op":"mcm","clk":"5347871849","pt":1646209387434,"mc":[{"id":"1.195453651","rc":[{"atb":[[1.83,2],[1.81,0]],"id":43167166}],"con":true,"img":false}]}
{"op":"mcm","clk":"5347872056","pt":1646209392632,"mc":[{"id":"1.195453651","rc":[{"atb":[[1.81,2]],"id":43167166}],"con":true,"img":false}]}
{"op":"mcm","clk":"5347872058","pt":1646209392734,"mc":[{"id":"1.195453651","rc":[{"atb":[[1.83,0]],"id":43167166}],"con":true,"img":false}]}
{"op":"mcm","clk":"5347872313","pt":1646209399436,"mc":[{"id":"1.195453651","rc":[{"atb":[[1.83,2],[1.81,0]],"id":43167166}],"con":true,"img":false}]}
{"op":"mcm","clk":"5347872427","pt":1646209402749,"mc":[{"id":"1.195453651","rc":[{"atb":[[1.83,0],[1.81,2]],"id":43167166}],"con":true,"img":false}]}
{"op":"mcm","clk":"5347872741","pt":1646209411466,"mc":[{"id":"1.195453651","rc":[{"atb":[[1.83,2],[1.81,0]],"id":43167166}],"con":true,"img":false}]}
{"op":"mcm","clk":"5347872817","pt":1646209413944,"mc":[{"id":"1.195453651","rc":[{"atl":[[2.46,2],[2.44,0]],"id":43167166}],"con":true,"img":false}]}
{"op":"mcm","clk":"5347872939","pt":1646209416930,"mc":[{"id":"1.195453651","rc":[{"atb":[[1.81,2]],"id":43167166}],"con":true,"img":false}]}
{"op":"mcm","clk":"5347872946","pt":1646209417034,"mc":[{"id":"1.195453651","rc":[{"atb":[[1.83,0]],"id":43167166}],"con":true,"img":false}]}
{"op":"mcm","clk":"5347873196","pt":1646209423775,"mc":[{"id":"1.195453651","rc":[{"atb":[[1.83,2]],"id":43167166}],"con":true,"img":false}]}
{"op":"mcm","clk":"5347873202","pt":1646209423880,"mc":[{"id":"1.195453651","rc":[{"atb":[[1.81,0]],"id":43167166}],"con":true,"img":false}]}
{"op":"mcm","clk":"5347873439","pt":1646209429971,"mc":[{"id":"1.195453651","rc":[{"atb":[[1.83,0],[1.81,2]],"id":43167166}],"con":true,"img":false}]}
{"op":"mcm","clk":"5347873679","pt":1646209435172,"mc":[{"id":"1.195453651","rc":[{"atb":[[1.83,2],[1.81,0]],"id":43167166}],"con":true,"img":false}]}
{"op":"mcm","clk":"5347874038","pt":1646209441594,"mc":[{"id":"1.195453651","rc":[{"atb":[[1.83,0],[1.85,2]],"id":43167166}],"con":true,"img":false}]}
{"op":"mcm","clk":"5347874261","pt":1646209444928,"mc":[{"id":"1.195453651","rc":[{"atl":[[46,1.42]],"id":43167166},{"atl":[[48,1.42]],"id":43016477}],"con":true,"img":false}]}
{"op":"mcm","clk":"5347874271","pt":1646209445088,"mc":[{"id":"1.195453651","rc":[{"atl":[[2.46,0],[2.48,2]],"id":43167166},{"atl":[[1.94,0],[2.2,2]],"id":43016477}],"con":true,"img":false}]}
{"op":"mcm","clk":"5347874436","pt":1646209448199,"mc":[{"id":"1.195453651","rc":[{"atb":[[1.85,0],[1.86,2]],"id":43167166},{"atl":[[48,1.42]],"id":43167166},{"atl":[[50,1.42]],"id":43016477}],"con":true,"img":false}]}
{"op":"mcm","clk":"5347874497","pt":1646209449192,"mc":[{"id":"1.195453651","rc":[{"atl":[[36,1.42]],"id":43167166},{"atl":[[36,1.42]],"id":43016477}],"con":true,"img":false}]}
{"op":"mcm","clk":"5347874561","pt":1646209450185,"mc":[{"id":"1.195453651","rc":[{"atl":[[2.52,2]],"id":43167166},{"atl":[[2.12,2]],"id":43016477}],"con":true,"img":false}]}
{"op":"mcm","clk":"5347874567","pt":1646209450288,"mc":[{"id":"1.195453651","rc":[{"atl":[[2.48,0]],"id":43167166},{"atl":[[2.2,0]],"id":43016477}],"con":true,"img":false}]}
{"op":"mcm","clk":"5347874628","pt":1646209451627,"mc":[{"id":"1.195453651","rc":[{"atl":[[32,1.42]],"id":43167166},{"atl":[[32,1.42]],"id":43016477}],"con":true,"img":false}]}
{"op":"mcm","clk":"5347874740","pt":1646209453291,"mc":[{"id":"1.195453651","rc":[{"atb":[[1.85,2],[1.86,0]],"id":43167166}],"con":true,"img":false}]}
{"op":"mcm","clk":"5347874819","pt":1646209454627,"mc":[{"id":"1.195453651","rc":[{"atl":[[29,1.42]],"id":43167166},{"atl":[[30,1.42]],"id":43016477}],"con":true,"img":false}]}
{"op":"mcm","clk":"5347874855","pt":1646209455320,"mc":[{"id":"1.195453651","rc":[{"atl":[[2.52,0],[2.48,2]],"id":43167166},{"atl":[[2.16,2]],"id":43016477}],"con":true,"img":false}]}
{"op":"mcm","clk":"5347874862","pt":1646209455416,"mc":[{"id":"1.195453651","rc":[{"atl":[[2.12,0]],"id":43016477}],"con":true,"img":false}]}
{"op":"mcm","clk":"5347874985","pt":1646209457736,"mc":[{"id":"1.195453651","rc":[{"atl":[[28,1.42]],"id":43167166},{"atl":[[29,1.42]],"id":43016477}],"con":true,"img":false}]}
{"op":"mcm","clk":"5347875085","pt":1646209459125,"mc":[{"id":"1.195453651","rc":[{"atb":[[1.86,2]],"id":43167166}],"con":true,"img":false}]}
{"op":"mcm","clk":"5347875089","pt":1646209459229,"mc":[{"id":"1.195453651","rc":[{"atb":[[1.85,0]],"id":43167166}],"con":true,"img":false}]}
{"op":"mcm","clk":"5347875169","pt":1646209460724,"mc":[{"id":"1.195453651","rc":[{"atl":[[2.46,2],[2.48,0]],"id":43167166},{"atl":[[2.2,2],[2.16,0]],"id":43016477}],"con":true,"img":false}]}
{"op":"mcm","clk":"5347875203","pt":1646209461197,"mc":[{"id":"1.195453651","rc":[{"atl":[[26,1.42]],"id":43167166},{"atl":[[27,1.42]],"id":43016477}],"con":true,"img":false}]}
{"op":"mcm","clk":"5347875355","pt":1646209464226,"mc":[{"id":"1.195453651","rc":[{"atb":[[1.86,0],[1.87,2]],"id":43167166}],"con":true,"img":false}]}
{"op":"mcm","clk":"5347875426","pt":1646209465834,"mc":[{"id":"1.195453651","rc":[{"atl":[[2.52,2],[2.46,0]],"id":43167166},{"atl":[[2.2,0],[2.16,2]],"id":43016477}],"con":true,"img":false}]}
{"op":"mcm","clk":"5347875479","pt":1646209466917,"mc":[{"id":"1.195453651","rc":[{"atl":[[2.5,2],[2.52,0]],"id":43167166}],"con":true,"img":false}]}
{"op":"mcm","clk":"5347875488","pt":1646209467120,"mc":[{"id":"1.195453651","rc":[{"atl":[[2.5,0],[2.48,2]],"id":43167166}],"con":true,"img":false}]}
{"op":"mcm","clk":"5347875499","pt":1646209467327,"mc":[{"id":"1.195453651","rc":[{"atl":[[21,1.42]],"id":43167166},{"atl":[[21,1.42]],"id":43016477}],"con":true,"img":false}]}
{"op":"mcm","clk":"5347875569","pt":1646209468314,"mc":[{"id":"1.195453651","rc":[{"atl":[[2.54,2],[2.48,0]],"id":43167166}],"con":true,"img":false}]}
{"op":"mcm","clk":"5347875652","pt":1646209469710,"mc":[{"id":"1.195453651","rc":[{"atl":[[19.5,1.42]],"id":43167166},{"atl":[[20,1.42]],"id":43016477}],"con":true,"img":false}]}
{"op":"mcm","clk":"5347875727","pt":1646209471210,"mc":[{"id":"1.195453651","rc":[{"atb":[[1.85,2],[1.87,0]],"id":43167166},{"atl":[[20,1.42]],"id":43167166},{"atl":[[20,2.84]],"id":43016477}],"con":true,"img":false}]}
{"op":"mcm","clk":"5347875813","pt":1646209473116,"mc":[{"id":"1.195453651","rc":[{"atl":[[19.5,0]],"id":43167166}],"con":true,"img":false}]}
{"op":"mcm","clk":"5347875824","pt":1646209473428,"mc":[{"id":"1.195453651","rc":[{"atl":[[2.54,0],[2.46,2]],"id":43167166}],"con":true,"img":false}]}
{"op":"mcm","clk":"5347875873","pt":1646209474519,"mc":[{"id":"1.195453651","rc":[{"atl":[[22,1.42]],"id":43167166},{"atl":[[22,1.42]],"id":43016477}],"con":true,"img":false}]}
{"op":"mcm","clk":"5347875926","pt":1646209475808,"mc":[{"id":"1.195453651","rc":[{"atl":[[19.5,1.42]],"id":43167166},{"atl":[[22,2.84]],"id":43016477}],"con":true,"img":false}]}
{"op":"mcm","clk":"5347875954","pt":1646209476423,"mc":[{"id":"1.195453651","rc":[{"atb":[[1.86,2]],"id":43167166}],"con":true,"img":false}]}
{"op":"mcm","clk":"5347875960","pt":1646209476530,"mc":[{"id":"1.195453651","rc":[{"atb":[[1.85,0]],"id":43167166}],"con":true,"img":false}]}
{"op":"mcm","clk":"5347876011","pt":1646209477784,"mc":[{"id":"1.195453651","rc":[{"atl":[[19.5,2.84]],"id":43167166},{"atl":[[19.5,1.42]],"id":43016477}],"con":true,"img":false}]}
{"op":"mcm","clk":"5347876057","pt":1646209478616,"mc":[{"id":"1.195453651","rc":[{"atl":[[2.5,2],[2.46,0]],"id":43167166}],"con":true,"img":false}]}
{"op":"mcm","clk":"5347876099","pt":1646209479645,"mc":[{"id":"1.195453651","rc":[{"atl":[[23,1.42]],"id":43167166},{"atl":[[19.5,2.84]],"id":43016477}],"con":true,"img":false}]}
{"op":"mcm","clk":"5347876237","pt":1646209482365,"mc":[{"id":"1.195453651","rc":[{"atl":[[23,2.84]],"id":43167166},{"atl":[[23,1.42]],"id":43016477}],"con":true,"img":false}]}
{"op":"mcm","clk":"5347876256","pt":1646209482835,"mc":[{"id":"1.195453651","rc":[{"atb":[[1.88,2],[1.86,0]],"id":43167166},{"atl":[[2.14,2],[2.16,0]],"id":43016477}],"con":true,"img":false}]}
{"op":"mcm","clk":"5347876299","pt":1646209483764,"mc":[{"id":"1.195453651","rc":[{"atl":[[2.5,0],[2.52,2]],"id":43167166}],"con":true,"img":false}]}
{"op":"mcm","clk":"5347876366","pt":1646209485342,"mc":[{"id":"1.195453651","rc":[{"atl":[[24,1.42]],"id":43167166},{"atl":[[23,2.84]],"id":43016477}],"con":true,"img":false}]}
{"op":"mcm","clk":"5347876486","pt":1646209487662,"mc":[{"id":"1.195453651","rc":[{"atl":[[19.5,0]],"id":43016477}],"con":true,"img":false}]}
{"op":"mcm","clk":"5347876560","pt":1646209488859,"mc":[{"id":"1.195453651","rc":[{"atb":[[1.88,0],[1.87,2]],"id":43167166},{"atl":[[2.58,2],[2.52,0]],"id":43167166},{"atl":[[2.14,0],[2.16,2]],"id":43016477}],"con":true,"img":false}]}
{"op":"mcm","clk":"5347876634","pt":1646209490347,"mc":[{"id":"1.195453651","rc":[{"atl":[[25,1.42]],"id":43167166},{"atl":[[24,1.42]],"id":43016477}],"con":true,"img":false}]}
{"op":"mcm","clk":"5347876641","pt":1646209490553,"mc":[{"id":"1.195453651","rc":[{"atb":[[1.86,2],[1.87,0]],"id":43167166}],"con":true,"img":false}]}
{"op":"mcm","clk":"5347876757","pt":1646209493559,"mc":[{"id":"1.195453651","rc":[{"atb":[[1.86,0],[1.87,2]],"id":43167166}],"con":true,"img":false}]}
{"op":"mcm","clk":"5347876777","pt":1646209493977,"mc":[{"id":"1.195453651","rc":[{"atl":[[2.58,0],[2.52,2]],"id":43167166},{"atl":[[2.14,2],[2.16,0]],"id":43016477}],"con":true,"img":false}]}
{"op":"mcm","clk":"5347876863","pt":1646209495837,"mc":[{"id":"1.195453651","rc":[{"atl":[[27,1.42]],"id":43167166},{"atl":[[25,1.42]],"id":43016477}],"con":true,"img":false}]}
{"op":"mcm","clk":"5347876980","pt":1646209498264,"mc":[{"id":"1.195453651","rc":[{"atl":[[26,1.42]],"id":43016477}],"con":true,"img":false}]}
{"op":"mcm","clk":"5347877004","pt":1646209498680,"mc":[{"id":"1.195453651","rc":[{"atb":[[1.88,2],[1.87,0]],"id":43167166}],"con":true,"img":false}]}
{"op":"mcm","clk":"5347877070","pt":1646209499769,"mc":[{"id":"1.195453651","rc":[{"atl":[[26,2.84]],"id":43016477}],"con":true,"img":false}]}
{"op":"mcm","clk":"5347877165","pt":1646209501576,"mc":[{"id":"1.195453651","rc":[{"atl":[[2.48,2],[2.52,0]],"id":43167166}],"con":true,"img":false}]}
{"op":"mcm","clk":"5347877167","pt":1646209501679,"mc":[{"id":"1.195453651","rc":[{"atl":[[19.5,0]],"id":43167166}],"con":true,"img":false}]}
{"op":"mcm","clk":"5347877171","pt":1646209501730,"mc":[{"id":"1.195453651","rc":[{"atl":[[2.48,10.57]],"id":43167166},{"atb":[[1.81,9.65]],"id":43016477},{"atl":[[2.14,11.33]],"id":43016477}],"con":true,"img":false}]}
{"op":"mcm","clk":"5347877242","pt":1646209503075,"mc":[{"id":"1.195453651","rc":[{"atl":[[28,1.42]],"id":43016477}],"con":true,"img":false}]}
{"op":"mcm","clk":"5347877309","pt":1646209504374,"mc":[{"id":"1.195453651","rc":[{"atl":[[20,0]],"id":43016477}],"con":true,"img":false}]}
{"op":"mcm","clk":"5347877344","pt":1646209505049,"mc":[{"id":"1.195453651","rc":[{"atb":[[1.89,2],[1.88,9.19]],"id":43167166}],"con":true,"img":false}]}
{"op":"mcm","clk":"5347877349","pt":1646209505258,"mc":[{"id":"1.195453651","rc":[{"atl":[[28,2.84]],"id":43016477}],"con":true,"img":false}]}
{"op":"mcm","clk":"5347877460","pt":1646209507755,"mc":[{"id":"1.195453651","rc":[{"atl":[[18.5,1.42]],"id":43167166}],"con":true,"img":false}]}
{"op":"mcm","clk":"5347877488","pt":1646209508372,"mc":[{"id":"1.195453651","rc":[{"atl":[[2.12,2],[2.14,9.33]],"id":43016477}],"con":true,"img":false}]}
{"op":"mcm","clk":"5347877584","pt":1646209510389,"mc":[{"id":"1.195453651","rc":[{"atl":[[2.12,11.33]],"id":43016477}],"con":true,"img":false}]}
{"op":"mcm","clk":"5347877612","pt":1646209510863,"mc":[{"id":"1.195453651","rc":[{"atl":[[18.5,2.84]],"id":43167166},{"atl":[[19,1.42]],"id":43016477}],"con":true,"img":false}]}
{"op":"mcm","clk":"5347877622","pt":1646209511060,"mc":[{"id":"1.195453651","rc":[{"atb":[[1.89,0],[1.9,2]],"id":43167166}],"con":true,"img":false}]}
{"op":"mcm","clk":"5347877700","pt":1646209512558,"mc":[{"id":"1.195453651","rc":[{"atl":[[18.5,1.42]],"id":43167166}],"con":true,"img":false}]}
{"op":"mcm","clk":"5347877827","pt":1646209515301,"mc":[{"id":"1.195453651","rc":[{"atb":[[1.91,2]],"id":43167166}],"con":true,"img":false}]}
{"op":"mcm","clk":"5347877832","pt":1646209515404,"mc":[{"id":"1.195453651","rc":[{"atb":[[1.89,2],[1.9,0]],"id":43167166},{"atl":[[18.5,0]],"id":43167166}],"con":true,"img":false}]}
{"op":"mcm","clk":"5347877837","pt":1646209515456,"mc":[{"id":"1.195453651","rc":[{"atb":[[1.91,0]],"id":43167166}],"con":true,"img":false}]}
{"op":"mcm","clk":"5347877876","pt":1646209516498,"mc":[{"id":"1.195453651","rc":[{"atl":[[19,1.42]],"id":43167166},{"atl":[[19.5,1.42]],"id":43016477}],"con":true,"img":false}]}
{"op":"mcm","clk":"5347877935","pt":1646209517590,"mc":[{"id":"1.195453651","rc":[{"atl":[[19,0]],"id":43016477}],"con":true,"img":false}]}
{"op":"mcm","clk":"5347878020","pt":1646209518995,"mc":[{"id":"1.195453651","rc":[{"atl":[[19.5,1.42]],"id":43167166},{"atl":[[20,1.42]],"id":43016477}],"con":true,"img":false}]}
{"op":"mcm","clk":"5347878066","pt":1646209520083,"mc":[{"id":"1.195453651","rc":[{"atl":[[19,0]],"id":43167166}],"con":true,"img":false}]}
{"op":"mcm","clk":"5347878087","pt":1646209520499,"mc":[{"id":"1.195453651","rc":[{"atb":[[1.89,0],[1.9,2]],"id":43167166}],"con":true,"img":false}]}
{"op":"mcm","clk":"5347878195","pt":1646209522669,"mc":[{"id":"1.195453651","rc":[{"atb":[[1.89,2],[1.9,0]],"id":43167166}],"con":true,"img":false}]}
{"op":"mcm","clk":"5347878321","pt":1646209524868,"mc":[{"id":"1.195453651","rc":[{"atl":[[19.5,0]],"id":43167166},{"atl":[[19.5,0]],"id":43016477}],"con":true,"img":false}]}
{"op":"mcm","clk":"5347878631","pt":1646209531175,"mc":[{"id":"1.195453651","rc":[{"atl":[[20,0]],"id":43016477}],"con":true,"img":false}]}
{"op":"mcm","clk":"5347879113","pt":1646209539918,"mc":[{"id":"1.195453651","rc":[{"atb":[[1.89,11.19]],"id":43167166}],"con":true,"img":false}]}
{"op":"mcm","clk":"5347879467","pt":1646209546543,"mc":[{"id":"1.195453651","rc":[{"atl":[[20,1.42]],"id":43016477}],"con":true,"img":false}]}
{"op":"mcm","clk":"5347879534","pt":1646209547933,"mc":[{"id":"1.195453651","rc":[{"atl":[[20,2.84]],"id":43016477}],"con":true,"img":false}]}
{"op":"mcm","clk":"5347880303","pt":1646209564467,"mc":[{"id":"1.195453651","rc":[{"atb":[[1.92,2],[1.89,9.19]],"id":43167166},{"atl":[[2.12,9.33],[2.1,2]],"id":43016477}],"con":true,"img":false}]}
{"op":"mcm","clk":"5347880524","pt":1646209569062,"mc":[{"id":"1.195453651","rc":[{"atl":[[20,0]],"id":43016477}],"con":true,"img":false}]}
{"op":"mcm","clk":"5347880545","pt":1646209569527,"mc":[{"id":"1.195453651","rc":[{"atb":[[1.92,0],[1.9,2]],"id":43167166}],"con":true,"img":false}]}
{"op":"mcm","clk":"5347880609","pt":1646209571130,"mc":[{"id":"1.195453651","rc":[{"atb":[[1.9,11.08]],"id":43167166},{"atl":[[2.1,11.43]],"id":43016477}],"con":true,"img":false}]}
{"op":"mcm","clk":"5347880613","pt":1646209571234,"mc":[{"id":"1.195453651","rc":[{"atl":[[20,0]],"id":43167166}],"con":true,"img":false}]}
{"op":"mcm","clk":"5347880681","pt":1646209572668,"mc":[{"id":"1.195453651","rc":[{"atl":[[30,1.42]],"id":43167166}],"con":true,"img":false}]}
{"op":"mcm","clk":"5347880731","pt":1646209573446,"mc":[{"id":"1.195453651","rc":[{"atl":[[21,0],[22,0]],"id":43167166}],"con":true,"img":false}]}
{"op":"mcm","clk":"5347880794","pt":1646209574270,"mc":[{"id":"1.195453651","rc":[{"atl":[[30,2.84]],"id":43167166}],"con":true,"img":false}]}
{"op":"mcm","clk":"5347880920","pt":1646209575971,"mc":[{"id":"1.195453651","rc":[{"atl":[[34,1.42]],"id":43167166}],"con":true,"img":false}]}
{"op":"mcm","clk":"5347881292","pt":1646209582772,"mc":[{"id":"1.195453651","rc":[{"atl":[[21,1.42]],"id":43167166}],"con":true,"img":false}]}
{"op":"mcm","clk":"5347881367","pt":1646209584266,"mc":[{"id":"1.195453651","rc":[{"atl":[[22,1.42]],"id":43167166}],"con":true,"img":false}]}
{"op":"mcm","clk":"5347881968","pt":1646209597008,"mc":[{"id":"1.195453651","rc":[{"atb":[[1.67,0]],"id":43016477}],"con":true,"img":false}]}
{"op":"mcm","clk":"5347881978","pt":1646209597167,"mc":[{"id":"1.195453651","rc":[{"atb":[[1.64,2]],"id":43016477}],"con":true,"img":false}]}
{"op":"mcm","clk":"5347882731","pt":1646209612498,"mc":[{"id":"1.195453651","rc":[{"atb":[[1.92,2],[1.9,9.08]],"id":43167166}],"con":true,"img":false}]}
{"op":"mcm","clk":"5347882775","pt":1646209613218,"mc":[{"id":"1.195453651","rc":[{"atb":[[1.92,10.85]],"id":43167166}],"con":true,"img":false}]}
{"op":"mcm","clk":"5347882967","pt":1646209617601,"mc":[{"id":"1.195453651","rc":[{"atb":[[1.92,8.85],[1.93,2]],"id":43167166}],"con":true,"img":false}]}
{"op":"mcm","clk":"5347882972","pt":1646209617704,"mc":[{"id":"1.195453651","rc":[{"atl":[[2.1,9.43],[2.08,2]],"id":43016477}],"con":true,"img":false}]}
{"op":"mcm","clk":"5347883016","pt":1646209618521,"mc":[{"id":"1.195453651","rc":[{"atb":[[1.93,10.74]],"id":43167166},{"atl":[[2.08,11.71]],"id":43016477}],"con":true,"img":false}]}
{"op":"mcm","clk":"5347883025","pt":1646209618739,"mc":[{"id":"1.195453651","rc":[{"atb":[[1.88,0],[1.94,2],[1.93,8.74]],"id":43167166}],"con":true,"img":false}]}
{"op":"mcm","clk":"5347883060","pt":1646209619508,"mc":[{"id":"1.195453651","rc":[{"atb":[[1.94,10.62]],"id":43167166}],"con":true,"img":false}]}
{"op":"mcm","clk":"5347883070","pt":1646209619718,"mc":[{"id":"1.195453651","rc":[{"atb":[[1.89,0]],"id":43167166}],"con":true,"img":false}]}
{"op":"mcm","clk":"5347883300","pt":1646209624199,"mc":[{"id":"1.195453651","rc":[{"atl":[[21,0]],"id":43167166},{"atl":[[21,0]],"id":43016477}],"con":true,"img":false}]}
{"op":"mcm","clk":"5347883343","pt":1646209625228,"mc":[{"id":"1.195453651","rc":[{"atb":[[1.94,8.62],[1.95,2]],"id":43167166}],"con":true,"img":false}]}
{"op":"mcm","clk":"5347883359","pt":1646209625847,"mc":[{"id":"1.195453651","rc":[{"atb":[[1.96,2]],"id":43167166},{"atl":[[2.08,9.71],[2.06,2]],"id":43016477}],"con":true,"img":false}]}
{"op":"mcm","clk":"5347883362","pt":1646209625906,"mc":[{"id":"1.195453651","rc":[{"atb":[[1.95,0]],"id":43167166}],"con":true,"img":false}]}
{"op":"mcm","clk":"5347883611","pt":1646209630919,"mc":[{"id":"1.195453651","rc":[{"atb":[[1.97,2],[1.96,0]],"id":43167166}],"con":true,"img":false}]}
{"op":"mcm","clk":"5347883622","pt":1646209631120,"mc":[{"id":"1.195453651","rc":[{"atl":[[22,0]],"id":43167166}],"con":true,"img":false}]}
{"op":"mcm","clk":"5347883639","pt":1646209631538,"mc":[{"id":"1.195453651","rc":[{"atb":[[1.97,10.29],[1.9,0]],"id":43167166},{"atb":[[1.81,0]],"id":43016477},{"atl":[[2.14,0],[2.06,12.24]],"id":43016477}],"con":true,"img":false}]}
{"op":"mcm","clk":"5347883798","pt":1646209635023,"mc":[{"id":"1.195453651","rc":[{"atl":[[23,0],[24,0],[25,0]],"id":43167166},{"atl":[[22,0]],"id":43016477}],"con":true,"img":false}]}
{"op":"mcm","clk":"5347883880","pt":1646209636816,"mc":[{"id":"1.195453651","rc":[{"atl":[[38,1.42]],"id":43167166},{"atl":[[34,1.42]],"id":43016477}],"con":true,"img":false}]}
{"op":"mcm","clk":"5347883943","pt":1646209638260,"mc":[{"id":"1.195453651","rc":[{"atl":[[40,1.42]],"id":43167166}],"con":true,"img":false}]}
{"op":"mcm","clk":"5347883973","pt":1646209638831,"mc":[{"id":"1.195453651","rc":[{"atl":[[26,0]],"id":43167166}],"con":true,"img":false}]}
{"op":"mcm","clk":"5347884001","pt":1646209639550,"mc":[{"id":"1.195453651","rc":[{"atl":[[40,2.84]],"id":43167166}],"con":true,"img":false}]}
{"op":"mcm","clk":"5347884166","pt":1646209641526,"mc":[{"id":"1.195453651","rc":[{"atl":[[23,0]],"id":43016477}],"con":true,"img":false}]}
{"op":"mcm","clk":"5347884244","pt":1646209642959,"mc":[{"id":"1.195453651","rc":[{"atl":[[42,1.42]],"id":43167166}],"con":true,"img":false}]}
{"op":"mcm","clk":"5347884486","pt":1646209646162,"mc":[{"id":"1.195453651","rc":[{"atb":[[1.71,10.42]],"id":43016477}],"con":true,"img":false}]}
{"op":"mcm","clk":"5347884623","pt":1646209648845,"mc":[{"id":"1.195453651","rc":[{"atl":[[25,1.42]],"id":43167166}],"con":true,"img":false}]}
{"op":"mcm","clk":"5347884722","pt":1646209650851,"mc":[{"id":"1.195453651","rc":[{"atl":[[24,1.42]],"id":43167166}],"con":true,"img":false}]}
{"op":"mcm","clk":"5347884802","pt":1646209652555,"mc":[{"id":"1.195453651","rc":[{"atl":[[24,2.84]],"id":43167166}],"con":true,"img":false}]}
{"op":"mcm","clk":"5347884949","pt":1646209656965,"mc":[{"id":"1.195453651","rc":[{"atl":[[26,1.42]],"id":43167166}],"con":true,"img":false}]}
{"op":"mcm","clk":"5347887230","pt":1646209702018,"mc":[{"id":"1.195453651","rc":[{"atb":[[1.99,2],[1.97,8.29]],"id":43167166},{"atl":[[2.04,2],[2.06,10.24]],"id":43016477}],"con":true,"img":false}]}
{"op":"mcm","clk":"5347887325","pt":1646209704233,"mc":[{"id":"1.195453651","rc":[{"atb":[[1.99,9.93]],"id":43167166},{"atl":[[2.04,12.72]],"id":43016477}],"con":true,"img":false}]}
{"op":"mcm","clk":"5347887336","pt":1646209704396,"mc":[{"id":"1.195453651","rc":[{"atb":[[1.92,0]],"id":43167166},{"atl":[[2.12,0]],"id":43016477}],"con":true,"img":false}]}
{"op":"mcm","clk":"5347887401","pt":1646209706102,"mc":[{"id":"1.195453651","rc":[{"atb":[[1.99,23.55]],"id":43167166},{"atl":[[2.48,19.87]],"id":43167166},{"atl":[[2.04,27.81]],"id":43016477}],"con":true,"img":false}]}
{"op":"mcm","clk":"5347887442","pt":1646209706827,"mc":[{"id":"1.195453651","rc":[{"atl":[[24,0]],"id":43167166}],"con":true,"img":false}]}
{"op":"mcm","clk":"5347887465","pt":1646209707402,"mc":[{"id":"1.195453651","rc":[{"atb":[[2,7.93]],"id":43167166},{"atl":[[2.02,10.73]],"id":43016477}],"con":true,"img":false}]}
{"op":"mcm","clk":"5347887470","pt":1646209707505,"mc":[{"id":"1.195453651","rc":[{"atb":[[2,9.93],[1.99,21.55]],"id":43167166},{"atl":[[2.04,25.81],[2.02,12.73]],"id":43016477}],"con":true,"img":false}]}
{"op":"mcm","clk":"5347887473","pt":1646209707608,"mc":[{"id":"1.195453651","rc":[{"atb":[[1.93,0]],"id":43167166},{"atl":[[2.1,0]],"id":43016477}],"con":true,"img":false}]}
{"op":"mcm","clk":"5347887484","pt":1646209707817,"mc":[{"id":"1.195453651","rc":[{"atb":[[1.99,7.93]],"id":43167166},{"atl":[[2.04,10.72]],"id":43016477}],"con":true,"img":false}]}
{"op":"mcm","clk":"5347887489","pt":1646209707920,"mc":[{"id":"1.195453651","rc":[{"atb":[[2,23.55]],"id":43167166},{"atl":[[2.02,27.82]],"id":43016477}],"con":true,"img":false}]}
{"op":"mcm","clk":"5347887504","pt":1646209708337,"mc":[{"id":"1.195453651","rc":[{"atb":[[2,9.93]],"id":43167166},{"atl":[[2.02,12.73]],"id":43016477}],"con":true,"img":false}]}
{"op":"mcm","clk":"5347887508","pt":1646209708439,"mc":[{"id":"1.195453651","rc":[{"atb":[[1.99,21.55]],"id":43167166},{"atl":[[2.04,25.81]],"id":43016477}],"con":true,"img":false}]}
{"op":"mcm","clk":"5347887512","pt":1646209708544,"mc":[{"id":"1.195453651","rc":[{"atb":[[1.8,0],[1.6,0],[1.7,0]],"id":43167166},{"atb":[[1.8,0],[1.6,0],[1.7,0]],"id":43016477}],"con":true,"img":false}]}
{"op":"mcm","clk":"5347887519","pt":1646209708702,"mc":[{"id":"1.195453651","rc":[{"atb":[[1.99,7.93]],"id":43167166},{"atb":[[1.64,0],[1.65,2]],"id":43016477},{"atl":[[2.04,10.72]],"id":43016477}],"con":true,"img":false}]}
{"op":"mcm","clk":"5347887522","pt":1646209708857,"mc":[{"id":"1.195453651","rc":[{"atb":[[2,23.55]],"id":43167166},{"atl":[[2.02,27.82]],"id":43016477}],"con":true,"img":false}]}
{"op":"mcm","clk":"5347887527","pt":1646209708912,"mc":[{"id":"1.195453651","rc":[{"atb":[[1.71,21.86]],"id":43016477}],"con":true,"img":false}]}
{"op":"mcm","clk":"5347887538","pt":1646209709223,"mc":[{"id":"1.195453651","rc":[{"atb":[[1.71,10.42]],"id":43016477}],"con":true,"img":false}]}
{"op":"mcm","clk":"5347887543","pt":1646209709328,"mc":[{"id":"1.195453651","rc":[{"atb":[[1.65,13.44]],"id":43016477}],"con":true,"img":false}]}
{"op":"mcm","clk":"5347887553","pt":1646209709531,"mc":[{"id":"1.195453651","rc":[{"atb":[[2.02,7.89]],"id":43167166},{"atl":[[2,10.77]],"id":43016477}],"con":true,"img":false}]}
{"op":"mcm","clk":"5347887558","pt":1646209709634,"mc":[{"id":"1.195453651","rc":[{"atb":[[2.06,1.42],[1.94,0]],"id":43167166},{"atl":[[2.08,0]],"id":43016477}],"con":true,"img":false}]}
{"op":"mcm","clk":"5347887567","pt":1646209709896,"mc":[{"id":"1.195453651","rc":[{"atb":[[2,9.93]],"id":43167166},{"atl":[[2.02,12.73]],"id":43016477}],"con":true,"img":false}]}
{"op":"mcm","clk":"5347887571","pt":1646209710001,"mc":[{"id":"1.195453651","rc":[{"atb":[[2.02,21.51]],"id":43167166},{"atl":[[2,25.86]],"id":43016477}],"con":true,"img":false}]}
{"op":"mcm","clk":"5347887574","pt":1646209710106,"mc":[{"id":"1.195453651","rc":[{"atb":[[2.06,9.21]],"id":43167166}],"con":true,"img":false}]}
{"op":"mcm","clk":"5347887578","pt":1646209710211,"mc":[{"id":"1.195453651","rc":[{"atb":[[1.97,0]],"id":43167166}],"con":true,"img":false}]}
{"op":"mcm","clk":"5347887591","pt":1646209710416,"mc":[{"id":"1.195453651","rc":[{"atb":[[2.02,7.89]],"id":43167166}],"con":true,"img":false}]}
{"op":"mcm","clk":"5347887593","pt":1646209710520,"mc":[{"id":"1.195453651","rc":[{"atb":[[2.06,22.83]],"id":43167166}],"con":true,"img":false}]}
{"op":"mcm","clk":"5347887607","pt":1646209710732,"mc":[{"id":"1.195453651","rc":[{"atl":[[25,0],[26,0]],"id":43167166}],"con":true,"img":false}]}
{"op":"mcm","clk":"5347887610","pt":1646209710836,"mc":[{"id":"1.195453651","rc":[{"atb":[[2.06,9.21]],"id":43167166}],"con":true,"img":false}]}
{"op":"mcm","clk":"5347887617","pt":1646209710937,"mc":[{"id":"1.195453651","rc":[{"atb":[[2.02,21.51],[2.04,28.1]],"id":43167166},{"atb":[[1.66,44.29]],"id":43016477}],"con":true,"img":false}]}
{"op":"mcm","clk":"5347887636","pt":1646209711299,"mc":[{"id":"1.195453651","rc":[{"atb":[[2.02,7.89]],"id":43167166},{"atl":[[1.99,10.92]],"id":43016477}],"con":true,"img":false}]}
{"op":"mcm","clk":"5347887643","pt":1646209711401,"mc":[{"id":"1.195453651","rc":[{"atb":[[2.06,22.83]],"id":43167166}],"con":true,"img":false}]}
{"op":"mcm","clk":"5347887648","pt":1646209711512,"mc":[{"id":"1.195453651","rc":[{"atl":[[2.06,0]],"id":43016477}],"con":true,"img":false}]}
{"op":"mcm","clk":"5347887662","pt":1646209711719,"mc":[{"id":"1.195453651","rc":[{"atl":[[2,10.77]],"id":43016477}],"con":true,"img":false}]}
{"op":"mcm","clk":"5347887671","pt":1646209711824,"mc":[{"id":"1.195453651","rc":[{"atl":[[1.99,26.01]],"id":43016477}],"con":true,"img":false}]}
{"op":"mcm","clk":"5347887688","pt":1646209712133,"mc":[{"id":"1.195453651","rc":[{"atb":[[2.08,7.74]],"id":43167166},{"atl":[[1.98,11.02]],"id":43016477}],"con":true,"img":false}]}
{"op":"mcm","clk":"5347887698","pt":1646209712366,"mc":[{"id":"1.195453651","rc":[{"atb":[[1.99,0]],"id":43167166},{"atl":[[2.04,0]],"id":43016477}],"con":true,"img":false}]}
{"op":"mcm","clk":"5347887702","pt":1646209712420,"mc":[{"id":"1.195453651","rc":[{"atb":[[2.06,9.21]],"id":43167166},{"atl":[[1.99,10.92]],"id":43016477}],"con":true,"img":false}]}
{"op":"mcm","clk":"5347887709","pt":1646209712512,"mc":[{"id":"1.195453651","rc":[{"atb":[[2.08,21.36]],"id":43167166},{"atl":[[1.98,26.11]],"id":43016477}],"con":true,"img":false}]}
{"op":"mcm","clk":"5347887712","pt":1646209712629,"mc":[{"id":"1.195453651","rc":[{"atl":[[32,0],[34,0],[36,0],[48,0],[50,0],[24,0],[25,0],[26,0],[27,0],[28,0],[29,0],[30,0]],"id":43016477}],"con":true,"img":false}]}
{"op":"mcm","clk":"5347887718","pt":1646209712726,"mc":[{"id":"1.195453651","rc":[{"atb":[[2,7.93],[2.1,2]],"id":43167166},{"atl":[[2.02,10.73],[1.94,2]],"id":43016477}],"con":true,"img":false}]}
{"op":"mcm","clk":"5347887723","pt":1646209712829,"mc":[{"id":"1.195453651","rc":[{"atb":[[2.08,48.42]],"id":43167166}],"con":true,"img":false}]}
{"op":"mcm","clk":"5347887732","pt":1646209713038,"mc":[{"id":"1.195453651","rc":[{"atb":[[2.08,40.75]],"id":43167166}],"con":true,"img":false}]}
{"op":"mcm","clk":"5347887735","pt":1646209713140,"mc":[{"id":"1.195453651","rc":[{"atb":[[2.1,9.69]],"id":43167166},{"atb":[[1.71,0]],"id":43016477},{"atl":[[1.98,11.02],[1.94,13.07]],"id":43016477}],"con":true,"img":false}]}
{"op":"mcm","clk":"5347887737","pt":1646209713243,"mc":[{"id":"1.195453651","rc":[{"atb":[[2,0]],"id":43167166},{"atl":[[2.02,0],[1.94,28.16]],"id":43016477}],"con":true,"img":false}]}
{"op":"mcm","clk":"5347887741","pt":1646209713345,"mc":[{"id":"1.195453651","rc":[{"atb":[[2.04,0],[2.08,13.69]],"id":43167166},{"atb":[[1.66,0]],"id":43016477}],"con":true,"img":false}]}
{"op":"mcm","clk":"5347887747","pt":1646209713504,"mc":[{"id":"1.195453651","rc":[{"atb":[[1.65,2]],"id":43016477}],"con":true,"img":false}]}
{"op":"mcm","clk":"5347887750","pt":1646209713609,"mc":[{"id":"1.195453651","rc":[{"atl":[[1.94,20.43]],"id":43016477}],"con":true,"img":false}]}
{"op":"mcm","clk":"5347887760","pt":1646209713918,"mc":[{"id":"1.195453651","rc":[{"atb":[[1.65,6]],"id":43016477}],"con":true,"img":false}]}
{"op":"mcm","clk":"5347887765","pt":1646209714022,"mc":[{"id":"1.195453651","rc":[{"atb":[[2.16,1.42]],"id":43167166}],"con":true,"img":false}]}
{"op":"mcm","clk":"5347887797","pt":1646209714638,"mc":[{"id":"1.195453651","rc":[{"atb":[[2.16,9.12]],"id":43167166},{"atl":[[2.46,7.66]],"id":43167166},{"atb":[[1.66,11.21]],"id":43016477},{"atl":[[1.93,11.07]],"id":43016477}],"con":true,"img":false}]}
{"op":"mcm","clk":"5347887807","pt":1646209714799,"mc":[{"id":"1.195453651","rc":[{"atb":[[2.02,0],[2.1,36.27]],"id":43167166},{"atb":[[1.67,43.63]],"id":43016477},{"atl":[[2,0]],"id":43016477}],"con":true,"img":false}]}
{"op":"mcm","clk":"5347887822","pt":1646209715101,"mc":[{"id":"1.195453651","rc":[{"atl":[[2.48,10.57]],"id":43167166},{"atb":[[1.65,2]],"id":43016477},{"atl":[[1.94,13.07]],"id":43016477}],"con":true,"img":false}]}
{"op":"mcm","clk":"5347887830","pt":1646209715205,"mc":[{"id":"1.195453651","rc":[{"atb":[[2.18,1.42]],"id":43167166},{"atl":[[1.85,1.42],[1.93,18.43]],"id":43016477}],"con":true,"img":false}]}
{"op":"mcm","clk":"5347887846","pt":1646209715412,"mc":[{"id":"1.195453651","rc":[{"atb":[[2.1,9.69]],"id":43167166},{"atl":[[2.46,17.72]],"id":43167166},{"atb":[[1.67,16.42]],"id":43016477}],"con":true,"img":false}]}
{"op":"mcm","clk":"5347887851","pt":1646209715514,"mc":[{"id":"1.195453651","rc":[{"atb":[[2.06,7.79],[2.16,7.69]],"id":43167166}],"con":true,"img":false}]}
{"op":"mcm","clk":"5347887871","pt":1646209715824,"mc":[{"id":"1.195453651","rc":[{"atb":[[1.67,0]],"id":43016477}],"con":true,"img":false}]}
{"op":"mcm","clk":"5347887877","pt":1646209715926,"mc":[{"id":"1.195453651","rc":[{"atb":[[2.1,36.27]],"id":43167166},{"atb":[[1.68,42.98]],"id":43016477}],"con":true,"img":false}]}
{"op":"mcm","clk":"5347887890","pt":1646209716133,"mc":[{"id":"1.195453651","rc":[{"atb":[[1.67,16.42]],"id":43016477}],"con":true,"img":false}]}
{"op":"mcm","clk":"5347887902","pt":1646209716337,"mc":[{"id":"1.195453651","rc":[{"atl":[[2.48,8.57],[2.46,19.72]],"id":43167166},{"atb":[[1.66,13.21],[1.65,0]],"id":43016477}],"con":true,"img":false}]}
{"op":"mcm","clk":"5347887906","pt":1646209716441,"mc":[{"id":"1.195453651","rc":[{"atl":[[2.44,7.66]],"id":43167166},{"atb":[[1.69,11.21]],"id":43016477}],"con":true,"img":false}]}
{"op":"mcm","clk":"5347887911","pt":1646209716545,"mc":[{"id":"1.195453651","rc":[{"atb":[[1.67,0]],"id":43016477}],"con":true,"img":false}]}
{"op":"mcm","clk":"5347887919","pt":1646209716597,"mc":[{"id":"1.195453651","rc":[{"atb":[[1.68,59.4]],"id":43016477}],"con":true,"img":false}]}
{"op":"mcm","clk":"5347887925","pt":1646209716699,"mc":[{"id":"1.195453651","rc":[{"atb":[[2.18,9.11]],"id":43167166},{"atl":[[1.85,12.51],[30,1.42]],"id":43016477}],"con":true,"img":false}]}
{"op":"mcm","clk":"5347887936","pt":1646209716904,"mc":[{"id":"1.195453651","rc":[{"atb":[[2.06,0]],"id":43167166},{"atl":[[2.46,9.66]],"id":43167166},{"atl":[[1.99,0]],"id":43016477}],"con":true,"img":false}]}
{"op":"mcm","clk":"5347887940","pt":1646209717007,"mc":[{"id":"1.195453651","rc":[{"atl":[[2.44,17.72]],"id":43167166},{"atb":[[1.68,42.98]],"id":43016477}],"con":true,"img":false}]}
{"op":"mcm","clk":"5347887948","pt":1646209717112,"mc":[{"id":"1.195453651","rc":[{"atb":[[1.69,27.63]],"id":43016477}],"con":true,"img":false}]}
{"op":"mcm","clk":"5347887965","pt":1646209717420,"mc":[{"id":"1.195453651","rc":[{"atl":[[2.44,12.63]],"id":43167166}],"con":true,"img":false}]}
{"op":"mcm","clk":"5347887971","pt":1646209717523,"mc":[{"id":"1.195453651","rc":[{"atb":[[1.69,18.85]],"id":43016477}],"con":true,"img":false}]}
{"op":"mcm","clk":"5347887991","pt":1646209717833,"mc":[{"id":"1.195453651","rc":[{"atb":[[2.18,33.88]],"id":43167166}],"con":true,"img":false}]}
{"op":"mcm","clk":"5347887997","pt":1646209717934,"mc":[{"id":"1.195453651","rc":[{"atl":[[1.91,2],[1.94,11.07]],"id":43016477}],"con":true,"img":false}]}
{"op":"mcm","clk":"5347888006","pt":1646209718141,"mc":[{"id":"1.195453651","rc":[{"atl":[[24,1.42]],"id":43167166},{"atl":[[32,1.42]],"id":43016477}],"con":true,"img":false}]}
{"op":"mcm","clk":"5347888019","pt":1646209718349,"mc":[{"id":"1.195453651","rc":[{"atb":[[2.12,2],[2.1,34.27]],"id":43167166},{"atb":[[1.66,11.21],[1.65,2]],"id":43016477}],"con":true,"img":false}]}
{"op":"mcm","clk":"5347888028","pt":1646209718502,"mc":[{"id":"1.195453651","rc":[{"atb":[[2.2,7.66],[2.08,5.95]],"id":43167166}],"con":true,"img":false}]}
{"op":"mcm","clk":"5347888039","pt":1646209718711,"mc":[{"id":"1.195453651","rc":[{"atl":[[2.44,7.66]],"id":43167166},{"atb":[[1.69,11.21]],"id":43016477}],"con":true,"img":false}]}
{"op":"mcm","clk":"5347888092","pt":1646209719639,"mc":[{"id":"1.195453651","rc":[{"atl":[[32,2.84]],"id":43016477}],"con":true,"img":false}]}
{"op":"mcm","clk":"5347888109","pt":1646209719845,"mc":[{"id":"1.195453651","rc":[{"atl":[[2.44,0]],"id":43167166},{"atb":[[1.69,0]],"id":43016477}],"con":true,"img":false}]}
{"op":"mcm","clk":"5347888128","pt":1646209720133,"mc":[{"id":"1.195453651","rc":[{"atl":[[24,0]],"id":43167166},{"atl":[[32,1.42],[30,0]],"id":43016477}],"con":true,"img":false}]}
{"op":"mcm","clk":"5347888137","pt":1646209720309,"mc":[{"id":"1.195453651","rc":[{"atb":[[2.18,9.11],[2.1,7.69]],"id":43167166},{"atb":[[1.68,0]],"id":43016477}],"con":true,"img":false}]}
{"op":"mcm","clk":"5347888171","pt":1646209720927,"mc":[{"id":"1.195453651","rc":[{"atb":[[2.24,1.42]],"id":43167166},{"atl":[[1.81,1.42]],"id":43016477}],"con":true,"img":false}]}
{"op":"mcm","clk":"5347888207","pt":1646209721646,"mc":[{"id":"1.195453651","rc":[{"atb":[[2.18,7.69]],"id":43167166},{"atl":[[27,0],[28,0]],"id":43167166},{"atl":[[1.85,11.08]],"id":43016477}],"con":true,"img":false}]}
{"op":"mcm","clk":"5347888242","pt":1646209722214,"mc":[{"id":"1.195453651","rc":[{"atb":[[2.24,9.05]],"id":43167166},{"atl":[[1.81,12.63]],"id":43016477}],"con":true,"img":false}]}
{"op":"mcm","clk":"5347888251","pt":1646209722419,"mc":[{"id":"1.195453651","rc":[{"atb":[[2.1,0]],"id":43167166},{"atl":[[1.98,0]],"id":43016477}],"con":true,"img":false}]}
{"op":"mcm","clk":"5347888254","pt":1646209722522,"mc":[{"id":"1.195453651","rc":[{"atl":[[44,1.42]],"id":43167166},{"atb":[[1.66,20.79]],"id":43016477},{"atl":[[34,1.42]],"id":43016477}],"con":true,"img":false}]}
{"op":"mcm","clk":"5347888270","pt":1646209722832,"mc":[{"id":"1.195453651","rc":[{"atb":[[2.22,23.96]],"id":43167166},{"atb":[[1.67,43.63]],"id":43016477}],"con":true,"img":false}]}
{"op":"mcm","clk":"5347888287","pt":1646209723246,"mc":[{"id":"1.195453651","rc":[{"atb":[[1.66,11.21]],"id":43016477}],"con":true,"img":false}]}
{"op":"mcm","clk":"5347888298","pt":1646209723354,"mc":[{"id":"1.195453651","rc":[{"atb":[[1.67,53.21]],"id":43016477}],"con":true,"img":false}]}
{"op":"mcm","clk":"5347888309","pt":1646209723510,"mc":[{"id":"1.195453651","rc":[{"atl":[[29,0]],"id":43167166},{"atl":[[1.81,11.2]],"id":43016477}],"con":true,"img":false}]}
{"op":"mcm","clk":"5347888346","pt":1646209724428,"mc":[{"id":"1.195453651","rc":[{"atl":[[44,2.84]],"id":43167166},{"atl":[[34,2.84]],"id":43016477}],"con":true,"img":false}]}
{"op":"mcm","clk":"5347888353","pt":1646209724633,"mc":[{"id":"1.195453651","rc":[{"atb":[[1.67,43.63]],"id":43016477}],"con":true,"img":false}]}
{"op":"mcm","clk":"5347888370","pt":1646209724943,"mc":[{"id":"1.195453651","rc":[{"atb":[[2.22,0]],"id":43167166},{"atb":[[1.67,0]],"id":43016477}],"con":true,"img":false}]}
{"op":"mcm","clk":"5347888392","pt":1646209725302,"mc":[{"id":"1.195453651","rc":[{"atb":[[1.66,18.87]],"id":43016477}],"con":true,"img":false}]}
{"op":"mcm","clk":"5347888401","pt":1646209725611,"mc":[{"id":"1.195453651","rc":[{"atl":[[36,1.42]],"id":43016477}],"con":true,"img":false}]}
{"op":"mcm","clk":"5347888412","pt":1646209725918,"mc":[{"id":"1.195453651","rc":[{"atb":[[2.22,23.96]],"id":43167166},{"atb":[[1.67,43.63]],"id":43016477}],"con":true,"img":false}]}
{"op":"mcm","clk":"5347888424","pt":1646209726229,"mc":[{"id":"1.195453651","rc":[{"atb":[[2.08,0]],"id":43167166},{"atl":[[1.93,11.07]],"id":43016477}],"con":true,"img":false}]}
{"op":"mcm","clk":"5347888431","pt":1646209726331,"mc":[{"id":"1.195453651","rc":[{"atb":[[2.24,15]],"id":43167166},{"atl":[[1.81,18.56]],"id":43016477}],"con":true,"img":false}]}
{"op":"mcm","clk":"5347888442","pt":1646209726537,"mc":[{"id":"1.195453651","rc":[{"atb":[[2.26,7.54]],"id":43167166}],"con":true,"img":false}]}
{"op":"mcm","clk":"5347888451","pt":1646209726744,"mc":[{"id":"1.195453651","rc":[{"atb":[[2.16,0]],"id":43167166},{"atl":[[2.46,2],[2.48,0]],"id":43167166},{"atl":[[1.8,11.47],[1.94,0]],"id":43016477}],"con":true,"img":false}]}
{"op":"mcm","clk":"5347888464","pt":1646209726957,"mc":[{"id":"1.195453651","rc":[{"atl":[[50,1.42],[2.46,0],[3.65,10.4]],"id":43167166},{"atl":[[40,1.42]],"id":43016477}],"con":true,"img":false}]}
{"op":"mcm","clk":"5347888475","pt":1646209727106,"mc":[{"id":"1.195453651","rc":[{"atl":[[30,0]],"id":43167166}],"con":true,"img":false}]}
{"op":"mcm","clk":"5347888485","pt":1646209727312,"mc":[{"id":"1.195453651","rc":[{"atb":[[2.22,0]],"id":43167166},{"atl":[[3.65,31.2]],"id":43167166},{"atb":[[1.67,0]],"id":43016477}],"con":true,"img":false}]}
{"op":"mcm","clk":"5347888492","pt":1646209727415,"mc":[{"id":"1.195453651","rc":[{"atb":[[1.66,7.66]],"id":43016477}],"con":true,"img":false}]}
{"op":"mcm","clk":"5347888514","pt":1646209727729,"mc":[{"id":"1.195453651","rc":[{"atb":[[1.66,0]],"id":43016477}],"con":true,"img":false}]}
{"op":"mcm","clk":"5347888520","pt":1646209727831,"mc":[{"id":"1.195453651","rc":[{"atb":[[2.18,32.46]],"id":43167166}],"con":true,"img":false}]}
{"op":"mcm","clk":"5347888535","pt":1646209728141,"mc":[{"id":"1.195453651","rc":[{"atb":[[1.65,6]],"id":43016477},{"atl":[[42,1.42]],"id":43016477}],"con":true,"img":false}]}
{"op":"mcm","clk":"5347888553","pt":1646209728354,"mc":[{"id":"1.195453651","rc":[{"atl":[[3.6,7.16]],"id":43167166}],"con":true,"img":false}]}
{"op":"mcm","clk":"5347888563","pt":1646209728452,"mc":[{"id":"1.195453651","rc":[{"atb":[[2.24,13.58]],"id":43167166},{"atl":[[1.89,2],[1.91,0]],"id":43016477}],"con":true,"img":false}]}
{"op":"mcm","clk":"5347888579","pt":1646209728719,"mc":[{"id":"1.195453651","rc":[{"atl":[[3.65,10.4]],"id":43167166},{"atb":[[1.64,2],[1.65,4]],"id":43016477}],"con":true,"img":false}]}
{"op":"mcm","clk":"5347888584","pt":1646209728822,"mc":[{"id":"1.195453651","rc":[{"atl":[[3.6,27.96]],"id":43167166}],"con":true,"img":false}]}
{"op":"mcm","clk":"5347888608","pt":1646209729134,"mc":[{"id":"1.195453651","rc":[{"atb":[[1.65,0]],"id":43016477}],"con":true,"img":false}]}
{"op":"mcm","clk":"5347888631","pt":1646209729444,"mc":[{"id":"1.195453651","rc":[{"atl":[[42,2.84]],"id":43016477}],"con":true,"img":false}]}
{"op":"mcm","clk":"5347888638","pt":1646209729547,"mc":[{"id":"1.195453651","rc":[{"atb":[[1.64,6]],"id":43016477}],"con":true,"img":false}]}
{"op":"mcm","clk":"5347888705","pt":1646209731049,"mc":[{"id":"1.195453651","rc":[{"atl":[[44,1.42]],"id":43016477}],"con":true,"img":false}]}
{"op":"mcm","clk":"5347888751","pt":1646209732029,"mc":[{"id":"1.195453651","rc":[{"atl":[[3.55,15.21],[3.65,0]],"id":43167166}],"con":true,"img":false}]}
{"op":"mcm","clk":"5347888766","pt":1646209732339,"mc":[{"id":"1.195453651","rc":[{"atl":[[3.6,7.16]],"id":43167166}],"con":true,"img":false}]}
{"op":"mcm","clk":"5347888775","pt":1646209732542,"mc":[{"id":"1.195453651","rc":[{"atl":[[44,2.84]],"id":43016477}],"con":true,"img":false}]}
{"op":"mcm","clk":"5347888779","pt":1646209732647,"mc":[{"id":"1.195453651","rc":[{"atl":[[3.55,37.4]],"id":43167166}],"con":true,"img":false}]}
{"op":"mcm","clk":"5347888796","pt":1646209732958,"mc":[{"id":"1.195453651","rc":[{"atl":[[3.55,15.21]],"id":43167166}],"con":true,"img":false}]}
{"op":"mcm","clk":"5347888811","pt":1646209733213,"mc":[{"id":"1.195453651","rc":[{"atl":[[3.55,37.4]],"id":43167166}],"con":true,"img":false}]}
{"op":"mcm","clk":"5347888817","pt":1646209733316,"mc":[{"id":"1.195453651","rc":[{"atb":[[2.18,7.69]],"id":43167166}],"con":true,"img":false}]}
{"op":"mcm","clk":"5347888840","pt":1646209733831,"mc":[{"id":"1.195453651","rc":[{"atl":[[46,1.42]],"id":43016477}],"con":true,"img":false}]}
{"op":"mcm","clk":"5347888887","pt":1646209735080,"mc":[{"id":"1.195453651","rc":[{"atl":[[48,1.42]],"id":43016477}],"con":true,"img":false}]}
{"op":"mcm","clk":"5347888936","pt":1646209736360,"mc":[{"id":"1.195453651","rc":[{"atl":[[3.5,6.91]],"id":43167166}],"con":true,"img":false}]}
{"op":"mcm","clk":"5347888945","pt":1646209736515,"mc":[{"id":"1.195453651","rc":[{"atl":[[3.55,22.19],[3.45,15.21]],"id":43167166}],"con":true,"img":false}]}
{"op":"mcm","clk":"5347888956","pt":1646209736720,"mc":[{"id":"1.195453651","rc":[{"atl":[[3.55,0]],"id":43167166}],"con":true,"img":false}]}
{"op":"mcm","clk":"5347888958","pt":1646209736822,"mc":[{"id":"1.195453651","rc":[{"atb":[[2.18,32.46]],"id":43167166},{"atl":[[3.5,29.1]],"id":43167166}],"con":true,"img":false}]}
{"op":"mcm","clk":"5347888971","pt":1646209737233,"mc":[{"id":"1.195453651","rc":[{"atl":[[3.5,6.91]],"id":43167166}],"con":true,"img":false}]}
{"op":"mcm","clk":"5347888974","pt":1646209737337,"mc":[{"id":"1.195453651","rc":[{"atl":[[3.45,37.4]],"id":43167166}],"con":true,"img":false}]}
{"op":"mcm","clk":"5347889102","pt":1646209740175,"mc":[{"id":"1.195453651","rc":[{"atl":[[38,1.42]],"id":43016477}],"con":true,"img":false}]}
{"op":"mcm","clk":"5347889220","pt":1646209742768,"mc":[{"id":"1.195453651","rc":[{"atl":[[3.4,6.99]],"id":43167166}],"con":true,"img":false}]}
{"op":"mcm","clk":"5347889233","pt":1646209742923,"mc":[{"id":"1.195453651","rc":[{"atl":[[3.35,15.21],[3.45,22.19]],"id":43167166}],"con":true,"img":false}]}
{"op":"mcm","clk":"5347889240","pt":1646209743026,"mc":[{"id":"1.195453651","rc":[{"atl":[[3.45,0]],"id":43167166}],"con":true,"img":false}]}
{"op":"mcm","clk":"5347889246","pt":1646209743133,"mc":[{"id":"1.195453651","rc":[{"atl":[[3.4,29.18]],"id":43167166}],"con":true,"img":false}]}
{"op":"mcm","clk":"5347889274","pt":1646209743542,"mc":[{"id":"1.195453651","rc":[{"atl":[[3.4,6.99]],"id":43167166}],"con":true,"img":false}]}
{"op":"mcm","clk":"5347889278","pt":1646209743644,"mc":[{"id":"1.195453651","rc":[{"atl":[[3.35,37.4]],"id":43167166}],"con":true,"img":false}]}
{"op":"mcm","clk":"5347889290","pt":1646209743955,"mc":[{"id":"1.195453651","rc":[{"atb":[[2.18,7.69]],"id":43167166}],"con":true,"img":false}]}
{"op":"mcm","clk":"5347889304","pt":1646209744268,"mc":[{"id":"1.195453651","rc":[{"atb":[[1.72,7.5],[1.62,8.71],[1.52,10.39]],"id":43167166},{"atb":[[1.75,7.2],[1.65,8.31]],"id":43016477},{"atl":[[1.8,5.12]],"id":43016477},{"trd":[[1.8,12.71]],"ltp":1.8,"tv":12.71,"id":43016477}],"con":true,"img":false}]}
{"op":"mcm","clk":"5347889313","pt":1646209744426,"mc":[{"id":"1.195453651","rc":[{"atl":[[3.3,7.04]],"id":43167166},{"atb":[[1.75,0]],"id":43016477},{"trd":[[1.75,14.41]],"ltp":1.75,"tv":14.41,"id":43016477}],"con":true,"img":false}]}
{"op":"mcm","clk":"5347889319","pt":1646209744526,"mc":[{"id":"1.195453651","rc":[{"atl":[[3.35,22.19],[3.25,15.21]],"id":43167166}],"con":true,"img":false}]}
{"op":"mcm","clk":"5347889330","pt":1646209744739,"mc":[{"id":"1.195453651","rc":[{"atl":[[3.35,0]],"id":43167166},{"atb":[[1.64,2]],"id":43016477}],"con":true,"img":false}]}
{"op":"mcm","clk":"5347889338","pt":1646209744836,"mc":[{"id":"1.195453651","rc":[{"atb":[[2.18,32.46]],"id":43167166},{"atl":[[3.3,29.23]],"id":43167166}],"con":true,"img":false}]}
{"op":"mcm","clk":"5347889349","pt":1646209745100,"mc":[{"id":"1.195453651","rc":[{"atb":[[1.65,19.08]],"id":43016477}],"con":true,"img":false}]}
{"op":"mcm","clk":"5347889363","pt":1646209745253,"mc":[{"id":"1.195453651","rc":[{"atl":[[3.3,7.04],[3.2,7.09]],"id":43167166}],"con":true,"img":false}]}
{"op":"mcm","clk":"5347889373","pt":1646209745357,"mc":[{"id":"1.195453651","rc":[{"atl":[[3.25,37.4]],"id":43167166}],"con":true,"img":false}]}
{"op":"mcm","clk":"5347889378","pt":1646209745462,"mc":[{"id":"1.195453651","rc":[{"atl":[[3.6,0]],"id":43167166}],"con":true,"img":false}]}
{"op":"mcm","clk":"5347889406","pt":1646209745826,"mc":[{"id":"1.195453651","rc":[{"atl":[[3.25,15.21]],"id":43167166}],"con":true,"img":false}]}
{"op":"mcm","clk":"5347889414","pt":1646209745929,"mc":[{"id":"1.195453651","rc":[{"atl":[[3.2,29.28]],"id":43167166}],"con":true,"img":false}]}
{"op":"mcm","clk":"5347889506","pt":1646209747534,"mc":[{"id":"1.195453651","rc":[{"atb":[[2.28,1.42]],"id":43167166}],"con":true,"img":false}]}
{"op":"mcm","clk":"5347889518","pt":1646209747837,"mc":[{"id":"1.195453651","rc":[{"atb":[[2.2,32.02]],"id":43167166},{"atb":[[1.46,63.55]],"id":43016477}],"con":true,"img":false}]}
{"op":"mcm","clk":"5347889560","pt":1646209748773,"mc":[{"id":"1.195453651","rc":[{"atb":[[2.12,0],[2.16,14.59]],"id":43167166},{"atb":[[1.64,0],[1.62,2]],"id":43016477},{"atl":[[1.89,0],[1.87,2]],"id":43016477}],"con":true,"img":false}]}
{"op":"mcm","clk":"5347889606","pt":1646209749334,"mc":[{"id":"1.195453651","rc":[{"atl":[[32,0],[34,0],[36,0],[38,0],[40,0],[42,0],[44,0],[46,0],[48,0],[50,0]],"id":43167166},{"atl":[[32,0],[34,0],[36,0],[38,0],[40,0],[42,0],[44,0],[46,0],[48,0]],"id":43016477}],"con":true,"img":false}]}
{"op":"mcm","clk":"5347889620","pt":1646209749651,"mc":[{"id":"1.195453651","rc":[{"atl":[[3.15,14.59]],"id":43167166}],"con":true,"img":false}]}
{"op":"mcm","clk":"5347889625","pt":1646209749746,"mc":[{"id":"1.195453651","rc":[{"atl":[[3.25,0]],"id":43167166}],"con":true,"img":false}]}
{"op":"mcm","clk":"5347889632","pt":1646209749850,"mc":[{"id":"1.195453651","rc":[{"atb":[[1.46,0]],"id":43016477}],"con":true,"img":false}]}
{"op":"mcm","clk":"5347889640","pt":1646209750055,"mc":[{"id":"1.195453651","rc":[{"atl":[[3.2,7.09]],"id":43167166}],"con":true,"img":false}]}
{"op":"mcm","clk":"5347889648","pt":1646209750158,"mc":[{"id":"1.195453651","rc":[{"atl":[[3.15,36.78]],"id":43167166}],"con":true,"img":false}]}
{"op":"mcm","clk":"5347889657","pt":1646209750368,"mc":[{"id":"1.195453651","rc":[{"atb":[[2.18,7.69],[2.26,30.75],[2.2,7.66]],"id":43167166},{"atb":[[1.47,62.19]],"id":43016477}],"con":true,"img":false}]}
{"op":"mcm","clk":"5347889661","pt":1646209750467,"mc":[{"id":"1.195453651","rc":[{"atb":[[1.63,2]],"id":43016477}],"con":true,"img":false}]}
{"op":"mcm","clk":"5347889667","pt":1646209750570,"mc":[{"id":"1.195453651","rc":[{"atb":[[1.62,0]],"id":43016477}],"con":true,"img":false}]}
{"op":"mcm","clk":"5347889802","pt":1646209752950,"mc":[{"id":"1.195453651","rc":[{"atb":[[2.34,1.42]],"id":43167166},{"atl":[[38,1.41]],"id":43167166},{"atl":[[38,1.41]],"id":43016477}],"con":true,"img":false}]}
{"op":"mcm","clk":"5347889912","pt":1646209755151,"mc":[{"id":"1.195453651","rc":[{"atb":[[2.32,1.42]],"id":43167166},{"atl":[[40,1.41]],"id":43167166},{"atl":[[40,1.41]],"id":43016477}],"con":true,"img":false}]}
{"op":"mcm","clk":"5347889934","pt":1646209755656,"mc":[{"id":"1.195453651","rc":[{"atb":[[2.34,0]],"id":43167166}],"con":true,"img":false}]}
{"op":"mcm","clk":"5347889946","pt":1646209755863,"mc":[{"id":"1.195453651","rc":[{"atl":[[3.1,14.01]],"id":43167166},{"atb":[[1.48,25.05]],"id":43016477}],"con":true,"img":false}]}
{"op":"mcm","clk":"5347889956","pt":1646209755965,"mc":[{"id":"1.195453651","rc":[{"atl":[[3.5,0]],"id":43167166}],"con":true,"img":false}]}
{"op":"mcm","clk":"5347889959","pt":1646209756065,"mc":[{"id":"1.195453651","rc":[{"atl":[[3.15,22.19],[3.05,21.11]],"id":43167166}],"con":true,"img":false}]}
{"op":"mcm","clk":"5347889972","pt":1646209756271,"mc":[{"id":"1.195453651","rc":[{"atl":[[3.15,0]],"id":43167166}],"con":true,"img":false}]}
{"op":"mcm","clk":"5347889977","pt":1646209756376,"mc":[{"id":"1.195453651","rc":[{"atl":[[3.1,36.2]],"id":43167166},{"atb":[[1.49,59.65],[1.47,0]],"id":43016477}],"con":true,"img":false}]}
{"op":"mcm","clk":"5347889998","pt":1646209756889,"mc":[{"id":"1.195453651","rc":[{"atl":[[3.1,14.01]],"id":43167166}],"con":true,"img":false}]}
{"op":"mcm","clk":"5347890003","pt":1646209756939,"mc":[{"id":"1.195453651","rc":[{"atl":[[3.05,43.3]],"id":43167166}],"con":true,"img":false}]}
{"op":"mcm","clk":"5347890020","pt":1646209757249,"mc":[{"id":"1.195453651","rc":[{"atb":[[2.36,1.42]],"id":43167166},{"atl":[[42,1.36]],"id":43167166},{"atl":[[42,1.36]],"id":43016477}],"con":true,"img":false}]}
{"op":"mcm","clk":"5347890040","pt":1646209757663,"mc":[{"id":"1.195453651","rc":[{"atl":[[38,0],[40,0]],"id":43167166},{"atl":[[38,0],[40,0]],"id":43016477}],"con":true,"img":false}]}
{"op":"mcm","clk":"5347890065","pt":1646209758282,"mc":[{"id":"1.195453651","rc":[{"atb":[[2.36,2.84]],"id":43167166}],"con":true,"img":false}]}
{"op":"mcm","clk":"5347890105","pt":1646209759159,"mc":[{"id":"1.195453651","rc":[{"atl":[[42,0]],"id":43167166},{"atl":[[42,0]],"id":43016477}],"con":true,"img":false}]}
{"op":"mcm","clk":"5347890251","pt":1646209762479,"mc":[{"id":"1.195453651","rc":[{"atb":[[1.65,10.89]],"id":43016477},{"trd":[[1.65,16.37]],"ltp":1.65,"tv":16.37,"id":43016477}],"con":true,"img":false}]}
{"op":"mcm","clk":"5347890257","pt":1646209762581,"mc":[{"id":"1.195453651","rc":[{"atb":[[1.65,0]],"id":43016477},{"trd":[[1.65,38.17]],"ltp":1.65,"tv":38.17,"id":43016477}],"con":true,"img":false}]}
{"op":"mcm","clk":"5347890260","pt":1646209762683,"mc":[{"id":"1.195453651","rc":[{"atb":[[1.5,12.55]],"id":43016477}],"con":true,"img":false}]}
{"op":"mcm","clk":"5347890265","pt":1646209762787,"mc":[{"id":"1.195453651","rc":[{"atb":[[1.63,0],[1.5,14.55]],"id":43016477}],"con":true,"img":false}]}
{"op":"mcm","clk":"5347890325","pt":1646209763867,"mc":[{"id":"1.195453651","rc":[{"atb":[[1.5,43.65]],"id":43016477}],"con":true,"img":false}]}
{"op":"mcm","clk":"5347890358","pt":1646209764690,"mc":[{"id":"1.195453651","rc":[{"atb":[[1.51,25.12]],"id":43016477}],"con":true,"img":false}]}
{"op":"mcm","clk":"5347890373","pt":1646209765051,"mc":[{"id":"1.195453651","rc":[{"atl":[[2.88,1.42]],"id":43167166},{"atb":[[1.53,1.42]],"id":43016477},{"atl":[[50,1.2]],"id":43016477}],"con":true,"img":false}]}
{"op":"mcm","clk":"5347890376","pt":1646209765154,"mc":[{"id":"1.195453651","rc":[{"atl":[[2.88,11.42],[3.05,22.19]],"id":43167166},{"atb":[[1.5,14.55]],"id":43016477}],"con":true,"img":false}]}
{"op":"mcm","clk":"5347890382","pt":1646209765358,"mc":[{"id":"1.195453651","rc":[{"atb":[[1.51,82.44]],"id":43016477}],"con":true,"img":false}]}
{"op":"mcm","clk":"5347890390","pt":1646209765563,"mc":[{"id":"1.195453651","rc":[{"atb":[[1.53,4.26]],"id":43016477}],"con":true,"img":false}]}
{"op":"mcm","clk":"5347890512","pt":1646209767883,"mc":[{"id":"1.195453651","rc":[{"atb":[[1.54,2],[1.5,12.55]],"id":43016477}],"con":true,"img":false}]}
{"op":"mcm","clk":"5347890540","pt":1646209768398,"mc":[{"id":"1.195453651","rc":[{"atb":[[2.3,1.42]],"id":43167166},{"atl":[[2.76,1.42]],"id":43167166},{"atb":[[1.57,1.42],[1.53,1.42]],"id":43016477},{"atl":[[42,1.36]],"id":43016477}],"con":true,"img":false}]}
{"op":"mcm","clk":"5347890555","pt":1646209768602,"mc":[{"id":"1.195453651","rc":[{"atl":[[2.88,1.42],[2.76,11.42]],"id":43167166},{"atb":[[1.57,3.42],[1.54,0]],"id":43016477}],"con":true,"img":false}]}
{"op":"mcm","clk":"5347890562","pt":1646209768657,"mc":[{"id":"1.195453651","rc":[{"atl":[[2.88,11.42],[2.76,1.42]],"id":43167166},{"atb":[[1.57,1.42],[1.54,2]],"id":43016477}],"con":true,"img":false}]}
{"op":"mcm","clk":"5347890568","pt":1646209768757,"mc":[{"id":"1.195453651","rc":[{"atl":[[2.88,1.42],[2.76,11.42]],"id":43167166},{"atb":[[1.57,3.42],[1.54,0]],"id":43016477}],"con":true,"img":false}]}
{"op":"mcm","clk":"5347890572","pt":1646209768865,"mc":[{"id":"1.195453651","rc":[{"atl":[[2.88,11.42],[2.76,1.42]],"id":43167166},{"atb":[[1.57,4.26],[1.54,2]],"id":43016477}],"con":true,"img":false}]}
{"op":"mcm","clk":"5347890578","pt":1646209768970,"mc":[{"id":"1.195453651","rc":[{"atb":[[1.57,6.26],[1.54,0]],"id":43016477}],"con":true,"img":false}]}
{"op":"mcm","clk":"5347890583","pt":1646209769067,"mc":[{"id":"1.195453651","rc":[{"atb":[[1.57,4.26],[1.54,2]],"id":43016477}],"con":true,"img":false}]}
{"op":"mcm","clk":"5347890587","pt":1646209769171,"mc":[{"id":"1.195453651","rc":[{"atb":[[1.58,2],[1.54,0]],"id":43016477}],"con":true,"img":false}]}
{"op":"mcm","clk":"5347890600","pt":1646209769481,"mc":[{"id":"1.195453651","rc":[{"atb":[[1.49,0]],"id":43016477}],"con":true,"img":false}]}
{"op":"mcm","clk":"5347890606","pt":1646209769583,"mc":[{"id":"1.195453651","rc":[{"atb":[[1.57,1.42]],"id":43016477}],"con":true,"img":false}]}
{"op":"mcm","clk":"5347890610","pt":1646209769686,"mc":[{"id":"1.195453651","rc":[{"atb":[[1.57,3.42]],"id":43016477}],"con":true,"img":false}]}
{"op":"mcm","clk":"5347890613","pt":1646209769789,"mc":[{"id":"1.195453651","rc":[{"atb":[[1.58,0]],"id":43016477}],"con":true,"img":false}]}
{"op":"mcm","clk":"5347890616","pt":1646209769893,"mc":[{"id":"1.195453651","rc":[{"atl":[[2.76,8.41]],"id":43167166},{"atb":[[1.58,12.57]],"id":43016477}],"con":true,"img":false}]}
{"op":"mcm","clk":"5347890619","pt":1646209769997,"mc":[{"id":"1.195453651","rc":[{"atb":[[1.58,16.57]],"id":43016477}],"con":true,"img":false}]}
{"op":"mcm","clk":"5347890621","pt":1646209770100,"mc":[{"id":"1.195453651","rc":[{"atl":[[2.88,1.42],[2.74,10]],"id":43167166}],"con":true,"img":false}]}
{"op":"mcm","clk":"5347890627","pt":1646209770256,"mc":[{"id":"1.195453651","rc":[{"atb":[[1.59,12.56]],"id":43016477}],"con":true,"img":false}]}
{"op":"mcm","clk":"5347890631","pt":1646209770358,"mc":[{"id":"1.195453651","rc":[{"atb":[[1.57,54.7],[1.51,25.12]],"id":43016477}],"con":true,"img":false}]}
{"op":"mcm","clk":"5347890637","pt":1646209770566,"mc":[{"id":"1.195453651","rc":[{"atl":[[2.84,1.42]],"id":43167166},{"atb":[[1.55,1.42]],"id":43016477},{"atl":[[40,1.41]],"id":43016477}],"con":true,"img":false}]}
{"op":"mcm","clk":"5347890644","pt":1646209770667,"mc":[{"id":"1.195453651","rc":[{"atb":[[1.58,12.57]],"id":43016477}],"con":true,"img":false}]}
{"op":"mcm","clk":"5347890645","pt":1646209770772,"mc":[{"id":"1.195453651","rc":[{"atl":[[42,0],[50,0]],"id":43016477}],"con":true,"img":false}]}
{"op":"mcm","clk":"5347890652","pt":1646209770980,"mc":[{"id":"1.195453651","rc":[{"atb":[[1.59,30.32]],"id":43016477}],"con":true,"img":false}]}
{"op":"mcm","clk":"5347890703","pt":1646209772067,"mc":[{"id":"1.195453651","rc":[{"atl":[[2.68,1.42]],"id":43167166},{"atb":[[1.6,1.42]],"id":43016477},{"atl":[[40,0]],"id":43016477}],"con":true,"img":false}]}
{"op":"mcm","clk":"5347890715","pt":1646209772271,"mc":[{"id":"1.195453651","rc":[{"atl":[[2.68,11.42]],"id":43167166}],"con":true,"img":false}]}
{"op":"mcm","clk":"5347890720","pt":1646209772376,"mc":[{"id":"1.195453651","rc":[{"atl":[[2.74,0]],"id":43167166}],"con":true,"img":false}]}
{"op":"mcm","clk":"5347890727","pt":1646209772482,"mc":[{"id":"1.195453651","rc":[{"atb":[[1.59,12.56]],"id":43016477}],"con":true,"img":false}]}
{"op":"mcm","clk":"5347890734","pt":1646209772584,"mc":[{"id":"1.195453651","rc":[{"atb":[[1.6,19.18]],"id":43016477}],"con":true,"img":false}]}
{"op":"mcm","clk":"5347890757","pt":1646209772995,"mc":[{"id":"1.195453651","rc":[{"atb":[[1.6,4.26]],"id":43016477}],"con":true,"img":false}]}
{"op":"mcm","clk":"5347890764","pt":1646209773202,"mc":[{"id":"1.195453651","rc":[{"atl":[[2.58,1.42]],"id":43167166},{"atb":[[1.62,1.42]],"id":43016477}],"con":true,"img":false}]}
{"op":"mcm","clk":"5347890778","pt":1646209773362,"mc":[{"id":"1.195453651","rc":[{"atl":[[2.66,6.98]],"id":43167166},{"atb":[[1.59,62.11],[1.62,13.99]],"id":43016477}],"con":true,"img":false}]}
{"op":"mcm","clk":"5347890794","pt":1646209773568,"mc":[{"id":"1.195453651","rc":[{"atb":[[1.6,1.42]],"id":43016477}],"con":true,"img":false}]}
{"op":"mcm","clk":"5347890797","pt":1646209773670,"mc":[{"id":"1.195453651","rc":[{"atb":[[1.62,16.83]],"id":43016477}],"con":true,"img":false}]}
{"op":"mcm","clk":"5347890841","pt":1646209774795,"mc":[{"id":"1.195453651","rc":[{"atb":[[1.63,2],[1.57,52.7]],"id":43016477}],"con":true,"img":false}]}
{"op":"mcm","clk":"5347890860","pt":1646209775158,"mc":[{"id":"1.195453651","rc":[{"atb":[[1.62,13.99]],"id":43016477}],"con":true,"img":false}]}
{"op":"mcm","clk":"5347890865","pt":1646209775266,"mc":[{"id":"1.195453651","rc":[{"atl":[[2.6,1.42]],"id":43167166},{"atb":[[1.61,1.42]],"id":43016477}],"con":true,"img":false}]}
{"op":"mcm","clk":"5347890877","pt":1646209775568,"mc":[{"id":"1.195453651","rc":[{"atl":[[3.05,0]],"id":43167166},{"atb":[[1.63,6]],"id":43016477}],"con":true,"img":false}]}
{"op":"mcm","clk":"5347890882","pt":1646209775675,"mc":[{"id":"1.195453651","rc":[{"atl":[[2.6,8.44],[2.58,23.61]],"id":43167166}],"con":true,"img":false}]}
{"op":"mcm","clk":"5347890885","pt":1646209775773,"mc":[{"id":"1.195453651","rc":[{"atb":[[1.63,18.45]],"id":43016477}],"con":true,"img":false}]}
{"op":"mcm","clk":"5347890892","pt":1646209775881,"mc":[{"id":"1.195453651","rc":[{"atb":[[1.48,12.52]],"id":43016477}],"con":true,"img":false}]}
{"op":"mcm","clk":"5347890897","pt":1646209775987,"mc":[{"id":"1.195453651","rc":[{"atl":[[2.58,4.26]],"id":43167166}],"con":true,"img":false}]}
{"op":"mcm","clk":"5347890919","pt":1646209776387,"mc":[{"id":"1.195453651","rc":[{"atb":[[1.63,64.86]],"id":43016477}],"con":true,"img":false}]}
{"op":"mcm","clk":"5347890926","pt":1646209776493,"mc":[{"id":"1.195453651","rc":[{"atl":[[2.58,11.32]],"id":43167166}],"con":true,"img":false}]}
{"op":"mcm","clk":"5347890930","pt":1646209776595,"mc":[{"id":"1.195453651","rc":[{"atl":[[2.54,1.42]],"id":43167166},{"atb":[[1.65,1.42]],"id":43016477}],"con":true,"img":false}]}
{"op":"mcm","clk":"5347890934","pt":1646209776700,"mc":[{"id":"1.195453651","rc":[{"atl":[[3.1,7]],"id":43167166}],"con":true,"img":false}]}
{"op":"mcm","clk":"5347890940","pt":1646209776802,"mc":[{"id":"1.195453651","rc":[{"atl":[[2.58,9.89]],"id":43167166}],"con":true,"img":false}]}
{"op":"mcm","clk":"5347890953","pt":1646209777008,"mc":[{"id":"1.195453651","rc":[{"atl":[[2.58,7.05]],"id":43167166},{"atb":[[1.63,60.86]],"id":43016477}],"con":true,"img":false}]}
{"op":"mcm","clk":"5347890957","pt":1646209777062,"mc":[{"id":"1.195453651","rc":[{"atl":[[2.54,4.26]],"id":43167166},{"atb":[[1.65,5.42]],"id":43016477}],"con":true,"img":false}]}
{"op":"mcm","clk":"5347890963","pt":1646209777167,"mc":[{"id":"1.195453651","rc":[{"atb":[[1.64,12.3],[1.51,12.56]],"id":43016477}],"con":true,"img":false}]}
{"op":"mcm","clk":"5347890977","pt":1646209777369,"mc":[{"id":"1.195453651","rc":[{"atl":[[2.52,10],[2.68,1.42]],"id":43167166}],"con":true,"img":false}]}
{"op":"mcm","clk":"5347890992","pt":1646209777677,"mc":[{"id":"1.195453651","rc":[{"atl":[[2.54,1.42]],"id":43167166}],"con":true,"img":false}]}
{"op":"mcm","clk":"5347890997","pt":1646209777780,"mc":[{"id":"1.195453651","rc":[{"atb":[[1.64,0]],"id":43016477}],"con":true,"img":false}]}
{"op":"mcm","clk":"5347891002","pt":1646209777887,"mc":[{"id":"1.195453651","rc":[{"atl":[[2.54,2.84]],"id":43167166},{"atb":[[1.65,6.84]],"id":43016477}],"con":true,"img":false}]}
{"op":"mcm","clk":"5347891015","pt":1646209778087,"mc":[{"id":"1.195453651","rc":[{"atl":[[2.52,16.1]],"id":43167166}],"con":true,"img":false}]}
{"op":"mcm","clk":"5347891025","pt":1646209778290,"mc":[{"id":"1.195453651","rc":[{"atb":[[1.64,12.28]],"id":43016477}],"con":true,"img":false}]}
{"op":"mcm","clk":"5347891055","pt":1646209778911,"mc":[{"id":"1.195453651","rc":[{"atb":[[1.57,1.42]],"id":43016477}],"con":true,"img":false}]}
{"op":"mcm","clk":"5347891106","pt":1646209779790,"mc":[{"id":"1.195453651","rc":[{"atl":[[2.56,1.42]],"id":43167166}],"con":true,"img":false}]}
{"op":"mcm","clk":"5347891118","pt":1646209779997,"mc":[{"id":"1.195453651","rc":[{"atb":[[1.64,14.28],[1.63,58.86]],"id":43016477}],"con":true,"img":false}]}
{"op":"mcm","clk":"5347891142","pt":1646209780408,"mc":[{"id":"1.195453651","rc":[{"atb":[[1.64,2],[1.65,51.82]],"id":43016477}],"con":true,"img":false}]}
{"op":"mcm","clk":"5347891151","pt":1646209780613,"mc":[{"id":"1.195453651","rc":[{"atl":[[2.76,1.42],[2.56,8.52]],"id":43167166},{"atb":[[1.64,14.3]],"id":43016477}],"con":true,"img":false}]}
{"op":"mcm","clk":"5347891178","pt":1646209781284,"mc":[{"id":"1.195453651","rc":[{"atl":[[2.58,0],[2.56,1.42]],"id":43167166},{"atb":[[1.64,2]],"id":43016477}],"con":true,"img":false}]}
{"op":"mcm","clk":"5347891198","pt":1646209781694,"mc":[{"id":"1.195453651","rc":[{"atl":[[2.5,1.42]],"id":43167166},{"atb":[[1.66,1.42]],"id":43016477}],"con":true,"img":false}]}
{"op":"mcm","clk":"5347891204","pt":1646209781902,"mc":[{"id":"1.195453651","rc":[{"atb":[[1.65,6.84]],"id":43016477}],"con":true,"img":false}]}
{"op":"mcm","clk":"5347891213","pt":1646209782107,"mc":[{"id":"1.195453651","rc":[{"atl":[[2.52,10]],"id":43167166},{"atb":[[1.65,2.84]],"id":43016477}],"con":true,"img":false}]}
{"op":"mcm","clk":"5347891216","pt":1646209782211,"mc":[{"id":"1.195453651","rc":[{"atl":[[2.5,7.52]],"id":43167166},{"atb":[[1.66,5.42]],"id":43016477}],"con":true,"img":false}]}
{"op":"mcm","clk":"5347891230","pt":1646209782521,"mc":[{"id":"1.195453651","rc":[{"atl":[[2.5,17.52],[2.52,0]],"id":43167166}],"con":true,"img":false}]}
{"op":"mcm","clk":"5347891240","pt":1646209782679,"mc":[{"id":"1.195453651","rc":[{"atl":[[2.5,14.26],[2.56,8.52]],"id":43167166},{"atb":[[1.64,14.28]],"id":43016477}],"con":true,"img":false}]}
{"op":"mcm","clk":"5347891248","pt":1646209782883,"mc":[{"id":"1.195453651","rc":[{"atb":[[1.65,47.82]],"id":43016477}],"con":true,"img":false}]}
{"op":"mcm","clk":"5347891284","pt":1646209783499,"mc":[{"id":"1.195453651","rc":[{"atl":[[2.56,1.42]],"id":43167166}],"con":true,"img":false}]}
{"op":"mcm","clk":"5347891300","pt":1646209783910,"mc":[{"id":"1.195453651","rc":[{"atl":[[2.5,15.68]],"id":43167166},{"atb":[[1.66,6.84]],"id":43016477}],"con":true,"img":false}]}
{"op":"mcm","clk":"5347891355","pt":1646209785204,"mc":[{"id":"1.195453651","rc":[{"atb":[[1.64,12.28],[1.63,60.86]],"id":43016477}],"con":true,"img":false}]}
{"op":"mcm","clk":"5347891369","pt":1646209785411,"mc":[{"id":"1.195453651","rc":[{"atl":[[2.64,1.42]],"id":43167166}],"con":true,"img":false}]}
{"op":"mcm","clk":"5347891439","pt":1646209786909,"mc":[{"id":"1.195453651","rc":[{"atl":[[2.64,2.84]],"id":43167166},{"atb":[[1.64,0]],"id":43016477}],"con":true,"img":false}]}
{"op":"mcm","clk":"5347891465","pt":1646209787426,"mc":[{"id":"1.195453651","rc":[{"atb":[[1.65,2.84]],"id":43016477}],"con":true,"img":false}]}
{"op":"mcm","clk":"5347891524","pt":1646209788981,"mc":[{"id":"1.195453651","rc":[{"atb":[[1.63,48.4]],"id":43016477}],"con":true,"img":false}]}
{"op":"mcm","clk":"5347891529","pt":1646209789192,"mc":[{"id":"1.195453651","rc":[{"atl":[[2.58,1.42]],"id":43167166}],"con":true,"img":false}]}
{"op":"mcm","clk":"5347891592","pt":1646209790400,"mc":[{"id":"1.195453651","rc":[{"atl":[[2.58,2.84]],"id":43167166},{"atb":[[1.64,2],[1.63,46.4]],"id":43016477}],"con":true,"img":false}]}
{"op":"mcm","clk":"5347891647","pt":1646209791698,"mc":[{"id":"1.195453651","rc":[{"atl":[[2.54,10.17],[2.48,7.32],[3.4,0]],"id":43167166},{"atb":[[1.48,0],[1.67,11.79],[1.65,14.63]],"id":43016477}],"con":true,"img":false}]}
{"op":"mcm","clk":"5347891659","pt":1646209791904,"mc":[{"id":"1.195453651","rc":[{"atb":[[1.67,55.42]],"id":43016477}],"con":true,"img":false}]}
{"op":"mcm","clk":"5347891670","pt":1646209792102,"mc":[{"id":"1.195453651","rc":[{"atl":[[2.5,12.84]],"id":43167166},{"atb":[[1.66,2.84]],"id":43016477}],"con":true,"img":false}]}
{"op":"mcm","clk":"5347891687","pt":1646209792511,"mc":[{"id":"1.195453651","rc":[{"atl":[[2.48,14.68]],"id":43167166},{"atb":[[1.67,66.96]],"id":43016477}],"con":true,"img":false}]}
{"op":"mcm","clk":"5347891696","pt":1646209792716,"mc":[{"id":"1.195453651","rc":[{"atl":[[2.54,2.84],[2.5,2.84],[2.48,17.36]],"id":43167166},{"atb":[[1.65,2.84]],"id":43016477}],"con":true,"img":false}]}
{"op":"mcm","clk":"5347891706","pt":1646209792924,"mc":[{"id":"1.195453651","rc":[{"atl":[[2.54,10.14],[2.5,10.14]],"id":43167166}],"con":true,"img":false}]}
{"op":"mcm","clk":"5347891718","pt":1646209793084,"mc":[{"id":"1.195453651","rc":[{"atl":[[2.54,2.84]],"id":43167166}],"con":true,"img":false}]}
{"op":"mcm","clk":"5347891733","pt":1646209793390,"mc":[{"id":"1.195453651","rc":[{"atb":[[1.72,0],[1.62,0],[1.52,0]],"id":43167166}],"con":true,"img":false}]}
{"op":"mcm","clk":"5347891751","pt":1646209793699,"mc":[{"id":"1.195453651","rc":[{"atl":[[1.72,4]],"id":43016477}],"con":true,"img":false}]}
{"op":"mcm","clk":"5347891758","pt":1646209793906,"mc":[{"id":"1.195453651","rc":[{"atb":[[1.67,23.33]],"id":43016477}],"con":true,"img":false}]}
{"op":"mcm","clk":"5347891791","pt":1646209794625,"mc":[{"id":"1.195453651","rc":[{"atl":[[1.72,15.8]],"id":43016477}],"con":true,"img":false}]}
{"op":"mcm","clk":"5347891795","pt":1646209794830,"mc":[{"id":"1.195453651","rc":[{"atl":[[1.93,0]],"id":43016477}],"con":true,"img":false}]}
{"op":"mcm","clk":"5347891831","pt":1646209795810,"mc":[{"id":"1.195453651","rc":[{"atb":[[2.36,0]],"id":43167166}],"con":true,"img":false}]}
{"op":"mcm","clk":"5347891846","pt":1646209796118,"mc":[{"id":"1.195453651","rc":[{"atb":[[2.24,7.63]],"id":43167166},{"atl":[[2.48,10]],"id":43167166},{"atb":[[1.67,11.79]],"id":43016477},{"atl":[[1.81,11.2]],"id":43016477}],"con":true,"img":false}]}
{"op":"mcm","clk":"5347891877","pt":1646209796706,"mc":[{"id":"1.195453651","rc":[{"atl":[[70,0.92]],"id":43016477}],"con":true,"img":false}]}
{"op":"mcm","clk":"5347891927","pt":1646209797521,"mc":[{"id":"1.195453651","rc":[{"atl":[[2.48,15.7]],"id":43167166},{"atb":[[1.67,20.87]],"id":43016477}],"con":true,"img":false}]}
{"op":"mcm","clk":"5347891940","pt":1646209797725,"mc":[{"id":"1.195453651","rc":[{"atl":[[2.48,23]],"id":43167166}],"con":true,"img":false}]}
{"op":"mcm","clk":"5347891946","pt":1646209797828,"mc":[{"id":"1.195453651","rc":[{"atl":[[2.48,15.7]],"id":43167166}],"con":true,"img":false}]}
{"op":"mcm","clk":"5347891954","pt":1646209797934,"mc":[{"id":"1.195453651","rc":[{"atl":[[75,0.88]],"id":43016477}],"con":true,"img":false}]}
{"op":"mcm","clk":"5347891993","pt":1646209798508,"mc":[{"id":"1.195453651","rc":[{"atl":[[2.5,12.84],[2.48,5.7]],"id":43167166},{"atl":[[1.71,11.92]],"id":43016477}],"con":true,"img":false}]}
{"op":"mcm","clk":"5347892003","pt":1646209798610,"mc":[{"id":"1.195453651","rc":[{"atb":[[1.67,9.08]],"id":43016477}],"con":true,"img":false}]}
{"op":"mcm","clk":"5347892007","pt":1646209798713,"mc":[{"id":"1.195453651","rc":[{"atl":[[1.85,0]],"id":43016477}],"con":true,"img":false}]}
{"op":"mcm","clk":"5347892022","pt":1646209798920,"mc":[{"id":"1.195453651","rc":[{"atb":[[2.32,23.57]],"id":43167166},{"atl":[[2.48,0]],"id":43167166},{"atb":[[1.65,47.82]],"id":43016477}],"con":true,"img":false}]}
{"op":"mcm","clk":"5347892029","pt":1646209799025,"mc":[{"id":"1.195453651","rc":[{"atb":[[1.67,0]],"id":43016477}],"con":true,"img":false}]}
{"op":"mcm","clk":"5347892035","pt":1646209799127,"mc":[{"id":"1.195453651","rc":[{"atb":[[2.32,22.14],[2.3,0],[2.28,0]],"id":43167166}],"con":true,"img":false}]}
{"op":"mcm","clk":"5347892039","pt":1646209799231,"mc":[{"id":"1.195453651","rc":[{"atb":[[1.66,14.81]],"id":43016477}],"con":true,"img":false}]}
{"op":"mcm","clk":"5347892044","pt":1646209799335,"mc":[{"id":"1.195453651","rc":[{"atl":[[2.5,18.95]],"id":43167166}],"con":true,"img":false}]}
{"op":"mcm","clk":"5347892048","pt":1646209799438,"mc":[{"id":"1.195453651","rc":[{"atb":[[2.32,0]],"id":43167166},{"atl":[[2.58,10.08],[2.52,7.23]],"id":43167166},{"atb":[[1.63,0],[1.65,2.84]],"id":43016477}],"con":true,"img":false}]}
{"op":"mcm","clk":"5347892054","pt":1646209799541,"mc":[{"id":"1.195453651","rc":[{"atb":[[1.66,20.51]],"id":43016477}],"con":true,"img":false}]}
{"op":"mcm","clk":"5347892071","pt":1646209799909,"mc":[{"id":"1.195453651","rc":[{"atb":[[1.62,61.14]],"id":43016477}],"con":true,"img":false}]}
{"op":"mcm","clk":"5347892077","pt":1646209800006,"mc":[{"id":"1.195453651","rc":[{"atl":[[80,0.88]],"id":43016477}],"con":true,"img":false}]}
{"op":"mcm","clk":"5347892083","pt":1646209800318,"mc":[{"id":"1.195453651","rc":[{"atb":[[2.26,40.73]],"id":43167166},{"atl":[[2.5,12.84]],"id":43167166},{"atb":[[1.66,14.81]],"id":43016477}],"con":true,"img":false}]}
{"op":"mcm","clk":"5347892139","pt":1646209801510,"mc":[{"id":"1.195453651","rc":[{"atl":[[80,1.74]],"id":43016477}],"con":true,"img":false}]}
{"op":"mcm","clk":"5347892297","pt":1646209804333,"mc":[{"id":"1.195453651","rc":[{"atl":[[85,0.85]],"id":43016477}],"con":true,"img":false}]}
{"op":"mcm","clk":"5347892372","pt":1646209805832,"mc":[{"id":"1.195453651","rc":[{"atl":[[90,0.81]],"id":43016477}],"con":true,"img":false}]}
{"op":"mcm","clk":"5347892425","pt":1646209806818,"mc":[{"id":"1.195453651","rc":[{"atb":[[1.96,5.62],[1.86,6.28],[1.76,7.11]],"id":43167166},{"atb":[[1.37,14.6],[1.57,10.9],[1.47,11.49]],"id":43016477}],"con":true,"img":false}]}
{"op":"mcm","clk":"5347892459","pt":1646209807336,"mc":[{"id":"1.195453651","rc":[{"atl":[[95,0.74]],"id":43016477}],"con":true,"img":false}]}
{"op":"mcm","clk":"5347892492","pt":1646209807851,"mc":[{"id":"1.195453651","rc":[{"atl":[[1.72,11.8]],"id":43016477}],"con":true,"img":false}]}
{"op":"mcm","clk":"5347892496","pt":1646209807906,"mc":[{"id":"1.195453651","rc":[{"atl":[[1.7,4]],"id":43016477}],"con":true,"img":false}]}
{"op":"mcm","clk":"5347892513","pt":1646209808315,"mc":[{"id":"1.195453651","rc":[{"atl":[[1.7,15.95]],"id":43016477}],"con":true,"img":false}]}
{"op":"mcm","clk":"5347892518","pt":1646209808420,"mc":[{"id":"1.195453651","rc":[{"atl":[[1.81,0]],"id":43016477}],"con":true,"img":false}]}
{"op":"mcm","clk":"5347892524","pt":1646209808521,"mc":[{"id":"1.195453651","rc":[{"atl":[[2.58,2.84]],"id":43167166},{"atb":[[1.66,2.84]],"id":43016477}],"con":true,"img":false}]}
{"op":"mcm","clk":"5347892530","pt":1646209808627,"mc":[{"id":"1.195453651","rc":[{"atl":[[2.52,0]],"id":43167166},{"atl":[[1.8,0],[1.69,12.19]],"id":43016477}],"con":true,"img":false}]}
{"op":"mcm","clk":"5347892542","pt":1646209808836,"mc":[{"id":"1.195453651","rc":[{"atl":[[70,0],[75,0],[80,0],[85,0],[90,0],[95,0]],"id":43016477}],"con":true,"img":false}]}
{"op":"mcm","clk":"5347892578","pt":1646209809413,"mc":[{"id":"1.195453651","rc":[{"atb":[[2.4,20.88]],"id":43167166}],"con":true,"img":false}]}
{"op":"mcm","clk":"5347892698","pt":1646209811733,"mc":[{"id":"1.195453651","rc":[{"atl":[[2.5,2.84],[2.52,10.48]],"id":43167166},{"atb":[[1.64,0],[1.62,63.14]],"id":43016477}],"con":true,"img":false}]}
{"op":"mcm","clk":"5347892711","pt":1646209812141,"mc":[{"id":"1.195453651","rc":[{"atb":[[1.63,12.38]],"id":43016477}],"con":true,"img":false}]}
{"op":"mcm","clk":"5347892718","pt":1646209812244,"mc":[{"id":"1.195453651","rc":[{"atl":[[2.5,8.54]],"id":43167166},{"atb":[[1.66,8.54]],"id":43016477}],"con":true,"img":false}]}
{"op":"mcm","clk":"5347892727","pt":1646209812448,"mc":[{"id":"1.195453651","rc":[{"atb":[[2.4,0]],"id":43167166},{"atl":[[2.58,9.93]],"id":43167166}],"con":true,"img":false}]}
{"op":"mcm","clk":"5347892736","pt":1646209812655,"mc":[{"id":"1.195453651","rc":[{"atb":[[2.18,22.98],[2.16,0]],"id":43167166}],"con":true,"img":false}]}
{"op":"mcm","clk":"5347892749","pt":1646209812812,"mc":[{"id":"1.195453651","rc":[{"atb":[[2.26,30.75]],"id":43167166}],"con":true,"img":false}]}
{"op":"mcm","clk":"5347892752","pt":1646209812917,"mc":[{"id":"1.195453651","rc":[{"atb":[[2.38,21.18]],"id":43167166},{"atb":[[1.64,45.67]],"id":43016477}],"con":true,"img":false}]}
{"op":"mcm","clk":"5347892766","pt":1646209813123,"mc":[{"id":"1.195453651","rc":[{"atl":[[1.7,11.95]],"id":43016477}],"con":true,"img":false}]}
{"op":"mcm","clk":"5347892770","pt":1646209813229,"mc":[{"id":"1.195453651","rc":[{"atl":[[1.68,4]],"id":43016477}],"con":true,"img":false}]}
{"op":"mcm","clk":"5347892785","pt":1646209813429,"mc":[{"id":"1.195453651","rc":[{"atl":[[1.68,0]],"id":43016477},{"trd":[[1.68,8]],"ltp":1.68,"tv":8.0,"id":43016477}],"con":true,"img":false}]}
{"op":"mcm","clk":"5347892800","pt":1646209813638,"mc":[{"id":"1.195453651","rc":[{"atl":[[2.56,8.52]],"id":43167166}],"con":true,"img":false}]}
{"op":"mcm","clk":"5347892833","pt":1646209814154,"mc":[{"id":"1.195453651","rc":[{"atl":[[2.5,2.84]],"id":43167166},{"atb":[[1.66,2.84]],"id":43016477}],"con":true,"img":false}]}
{"op":"mcm","clk":"5347892869","pt":1646209814933,"mc":[{"id":"1.195453651","rc":[{"atl":[[2.5,8.54]],"id":43167166},{"atb":[[1.66,8.54]],"id":43016477}],"con":true,"img":false}]}
{"op":"mcm","clk":"5347892875","pt":1646209815139,"mc":[{"id":"1.195453651","rc":[{"atb":[[1.65,15.03]],"id":43016477}],"con":true,"img":false}]}
{"op":"mcm","clk":"5347892892","pt":1646209815452,"mc":[{"id":"1.195453651","rc":[{"atb":[[2.36,21.49],[2.38,0]],"id":43167166},{"atb":[[1.59,12.56]],"id":43016477}],"con":true,"img":false}]}
{"op":"mcm","clk":"5347892930","pt":1646209816327,"mc":[{"id":"1.195453651","rc":[{"atb":[[1.65,2.84]],"id":43016477}],"con":true,"img":false}]}
{"op":"mcm","clk":"5347892965","pt":1646209816943,"mc":[{"id":"1.195453651","rc":[{"atb":[[2.38,21.18]],"id":43167166},{"atl":[[2.5,25.62],[2.52,0]],"id":43167166},{"atb":[[1.62,61.14],[1.63,36.26]],"id":43016477}],"con":true,"img":false}]}
{"op":"mcm","clk":"5347892969","pt":1646209817046,"mc":[{"id":"1.195453651","rc":[{"atl":[[2.5,8.54],[2.52,18.47]],"id":43167166}],"con":true,"img":false}]}
{"op":"mcm","clk":"5347892982","pt":1646209817354,"mc":[{"id":"1.195453651","rc":[{"atl":[[2.58,2.84],[2.56,1.42]],"id":43167166}],"con":true,"img":false}]}
{"op":"mcm","clk":"5347892987","pt":1646209817458,"mc":[{"id":"1.195453651","rc":[{"atb":[[2.38,0]],"id":43167166}],"con":true,"img":false}]}
{"op":"mcm","clk":"5347893007","pt":1646209817720,"mc":[{"id":"1.195453651","rc":[{"atl":[[2.54,10]],"id":43167166},{"atb":[[1.65,15.01]],"id":43016477}],"con":true,"img":false}]}
{"op":"mcm","clk":"5347893023","pt":1646209817931,"mc":[{"id":"1.195453651","rc":[{"atb":[[1.65,59.98]],"id":43016477}],"con":true,"img":false}]}
{"op":"mcm","clk":"5347893042","pt":1646209818233,"mc":[{"id":"1.195453651","rc":[{"atb":[[1.58,0],[1.66,20.52]],"id":43016477},{"atl":[[1.69,0]],"id":43016477},{"trd":[[1.69,18.63]],"ltp":1.69,"tv":18.63,"id":43016477}],"con":true,"img":false}]}
{"op":"mcm","clk":"5347893045","pt":1646209818337,"mc":[{"id":"1.195453651","rc":[{"atl":[[2.5,2.84]],"id":43167166},{"atb":[[1.66,14.82]],"id":43016477}],"con":true,"img":false}]}
{"op":"mcm","clk":"5347893050","pt":1646209818440,"mc":[{"id":"1.195453651","rc":[{"atl":[[2.5,10.1]],"id":43167166},{"atb":[[1.67,11.91]],"id":43016477},{"atl":[[1.7,0]],"id":43016477}],"con":true,"img":false}]}
{"op":"mcm","clk":"5347893058","pt":1646209818543,"mc":[{"id":"1.195453651","rc":[{"atb":[[1.62,48.57]],"id":43016477}],"con":true,"img":false}]}
{"op":"mcm","clk":"5347893072","pt":1646209818953,"mc":[{"id":"1.195453651","rc":[{"atb":[[2.36,0]],"id":43167166},{"atb":[[1.64,0],[1.63,82.66],[1.65,15.01]],"id":43016477}],"con":true,"img":false}]}
{"op":"mcm","clk":"5347893081","pt":1646209819159,"mc":[{"id":"1.195453651","rc":[{"atl":[[2.48,7.32],[2.66,0]],"id":43167166},{"atl":[[1.71,0]],"id":43016477}],"con":true,"img":false}]}
{"op":"mcm","clk":"5347893091","pt":1646209819319,"mc":[{"id":"1.195453651","rc":[{"atb":[[2.26,37.88]],"id":43167166}],"con":true,"img":false}]}
{"op":"mcm","clk":"5347893142","pt":1646209820551,"mc":[{"id":"1.195453651","rc":[{"atb":[[1.67,3.18]],"id":43016477},{"trd":[[1.67,17.46]],"ltp":1.67,"tv":17.46,"id":43016477}],"con":true,"img":false}]}
{"op":"mcm","clk":"5347893212","pt":1646209821636,"mc":[{"id":"1.195453651","rc":[{"atl":[[2.66,1.42]],"id":43167166}],"con":true,"img":false}]}
{"op":"mcm","clk":"5347893231","pt":1646209821944,"mc":[{"id":"1.195453651","rc":[{"atb":[[1.64,26.64]],"id":43016477}],"con":true,"img":false}]}
{"op":"mcm","clk":"5347893235","pt":1646209822047,"mc":[{"id":"1.195453651","rc":[{"atb":[[1.63,58.78]],"id":43016477}],"con":true,"img":false}]}
{"op":"mcm","clk":"5347893238","pt":1646209822149,"mc":[{"id":"1.195453651","rc":[{"atl":[[2.5,27.76],[2.52,0]],"id":43167166}],"con":true,"img":false}]}
{"op":"mcm","clk":"5347893247","pt":1646209822254,"mc":[{"id":"1.195453651","rc":[{"atl":[[1.72,23.84]],"id":43016477}],"con":true,"img":false}]}
{"op":"mcm","clk":"5347893277","pt":1646209822928,"mc":[{"id":"1.195453651","rc":[{"atb":[[1.58,1.42]],"id":43016477}],"con":true,"img":false}]}
{"op":"mcm","clk":"5347893299","pt":1646209823336,"mc":[{"id":"1.195453651","rc":[{"atl":[[2.44,5.45]],"id":43167166}],"con":true,"img":false}]}
{"op":"mcm","clk":"5347893329","pt":1646209823850,"mc":[{"id":"1.195453651","rc":[{"atl":[[1.72,12.04]],"id":43016477}],"con":true,"img":false}]}
{"op":"mcm","clk":"5347893333","pt":1646209823953,"mc":[{"id":"1.195453651","rc":[{"atb":[[1.65,59.98]],"id":43016477}],"con":true,"img":false}]}
{"op":"mcm","clk":"5347893341","pt":1646209824160,"mc":[{"id":"1.195453651","rc":[{"atl":[[1.72,0]],"id":43016477}],"con":true,"img":false}]}
{"op":"mcm","clk":"5347893344","pt":1646209824261,"mc":[{"id":"1.195453651","rc":[{"atl":[[1.87,14.04]],"id":43016477}],"con":true,"img":false}]}
{"op":"mcm","clk":"5347893349","pt":1646209824364,"mc":[{"id":"1.195453651","rc":[{"atl":[[1.86,29.66],[1.87,23.75]],"id":43016477}],"con":true,"img":false}]}
{"op":"mcm","clk":"5347893354","pt":1646209824418,"mc":[{"id":"1.195453651","rc":[{"atb":[[2.26,14.67]],"id":43167166},{"atb":[[1.62,1.42]],"id":43016477}],"con":true,"img":false}]}
{"op":"mcm","clk":"5347893364","pt":1646209824625,"mc":[{"id":"1.195453651","rc":[{"atl":[[1.87,11.71]],"id":43016477}],"con":true,"img":false}]}
{"op":"mcm","clk":"5347893375","pt":1646209824936,"mc":[{"id":"1.195453651","rc":[{"atb":[[2.22,23.96]],"id":43167166},{"atb":[[1.67,46.81]],"id":43016477}],"con":true,"img":false}]}
{"op":"mcm","clk":"5347893381","pt":1646209825037,"mc":[{"id":"1.195453651","rc":[{"atl":[[1.86,55.18]],"id":43016477}],"con":true,"img":false}]}
{"op":"mcm","clk":"5347893389","pt":1646209825241,"mc":[{"id":"1.195453651","rc":[{"atl":[[1.85,11.71]],"id":43016477}],"con":true,"img":false}]}
{"op":"mcm","clk":"5347893400","pt":1646209825549,"mc":[{"id":"1.195453651","rc":[{"atl":[[1.86,29.66]],"id":43016477}],"con":true,"img":false}]}
{"op":"mcm","clk":"5347893403","pt":1646209825653,"mc":[{"id":"1.195453651","rc":[{"atl":[[1.85,37.23]],"id":43016477}],"con":true,"img":false}]}
{"op":"mcm","clk":"5347893462","pt":1646209826842,"mc":[{"id":"1.195453651","rc":[{"atl":[[1.84,11.79]],"id":43016477}],"con":true,"img":false}]}
{"op":"mcm","clk":"5347893480","pt":1646209827152,"mc":[{"id":"1.195453651","rc":[{"atl":[[2.62,1.42]],"id":43167166},{"atb":[[1.68,1.42]],"id":43016477}],"con":true,"img":false}]}
{"op":"mcm","clk":"5347893483","pt":1646209827259,"mc":[{"id":"1.195453651","rc":[{"atb":[[1.68,13.22]],"id":43016477}],"con":true,"img":false}]}
{"op":"mcm","clk":"5347893485","pt":1646209827358,"mc":[{"id":"1.195453651","rc":[{"atb":[[1.63,46.4]],"id":43016477},{"atl":[[1.85,11.71]],"id":43016477}],"con":true,"img":false}]}
{"op":"mcm","clk":"5347893489","pt":1646209827464,"mc":[{"id":"1.195453651","rc":[{"atl":[[1.84,37.31]],"id":43016477}],"con":true,"img":false}]}
{"op":"mcm","clk":"5347893512","pt":1646209827827,"mc":[{"id":"1.195453651","rc":[{"atl":[[2.48,0]],"id":43167166},{"atb":[[1.68,1.42]],"id":43016477},{"atl":[[1.83,11.83],[1.84,11.79]],"id":43016477}],"con":true,"img":false}]}
{"op":"mcm","clk":"5347893536","pt":1646209828146,"mc":[{"id":"1.195453651","rc":[{"atl":[[1.83,35.49]],"id":43016477}],"con":true,"img":false}]}
{"op":"mcm","clk":"5347893548","pt":1646209828351,"mc":[{"id":"1.195453651","rc":[{"atl":[[2.48,7.3]],"id":43167166}],"con":true,"img":false}]}
{"op":"mcm","clk":"5347893592","pt":1646209829326,"mc":[{"id":"1.195453651","rc":[{"atl":[[1.82,11.79]],"id":43016477}],"con":true,"img":false}]}
{"op":"mcm","clk":"5347893600","pt":1646209829431,"mc":[{"id":"1.195453651","rc":[{"atl":[[1.87,0]],"id":43016477}],"con":true,"img":false}]}
{"op":"mcm","clk":"5347893614","pt":1646209829638,"mc":[{"id":"1.195453651","rc":[{"atb":[[2.28,1.42]],"id":43167166},{"atl":[[2.42,1.42]],"id":43167166},{"atb":[[1.7,1.42]],"id":43016477},{"atl":[[1.83,11.83],[1.79,1.42]],"id":43016477}],"con":true,"img":false}]}
{"op":"mcm","clk":"5347893618","pt":1646209829740,"mc":[{"id":"1.195453651","rc":[{"atl":[[1.82,35.45]],"id":43016477}],"con":true,"img":false}]}
{"op":"mcm","clk":"5347893621","pt":1646209829842,"mc":[{"id":"1.195453651","rc":[{"atb":[[1.68,13.17]],"id":43016477}],"con":true,"img":false}]}
{"op":"mcm","clk":"5347893624","pt":1646209829950,"mc":[{"id":"1.195453651","rc":[{"atb":[[2.26,37.88]],"id":43167166}],"con":true,"img":false}]}
{"op":"mcm","clk":"5347893635","pt":1646209830154,"mc":[{"id":"1.195453651","rc":[{"atl":[[2.5,10.1],[2.48,20.06]],"id":43167166}],"con":true,"img":false}]}
{"op":"mcm","clk":"5347893637","pt":1646209830258,"mc":[{"id":"1.195453651","rc":[{"atb":[[2.26,30.75]],"id":43167166}],"con":true,"img":false}]}
{"op":"mcm","clk":"5347893644","pt":1646209830364,"mc":[{"id":"1.195453651","rc":[{"atb":[[2.28,8.55]],"id":43167166},{"atl":[[1.82,11.79]],"id":43016477}],"con":true,"img":false}]}
{"op":"mcm","clk":"5347893650","pt":1646209830467,"mc":[{"id":"1.195453651","rc":[{"atb":[[2.26,7.54]],"id":43167166},{"atl":[[1.79,36.8],[1.85,0]],"id":43016477}],"con":true,"img":false}]}
{"op":"mcm","clk":"5347893669","pt":1646209830836,"mc":[{"id":"1.195453651","rc":[{"atb":[[2.28,4.26]],"id":43167166}],"con":true,"img":false}]}
{"op":"mcm","clk":"5347893675","pt":1646209830938,"mc":[{"id":"1.195453651","rc":[{"atb":[[2.28,27.09]],"id":43167166}],"con":true,"img":false}]}
{"op":"mcm","clk":"5347893679","pt":1646209831146,"mc":[{"id":"1.195453651","rc":[{"atb":[[2.14,1.42]],"id":43167166},{"atl":[[2.46,1.42]],"id":43167166},{"atl":[[1.78,1.42]],"id":43016477}],"con":true,"img":false}]}
{"op":"mcm","clk":"5347893694","pt":1646209831555,"mc":[{"id":"1.195453651","rc":[{"atl":[[1.79,13.14],[1.78,13.14]],"id":43016477}],"con":true,"img":false}]}
{"op":"mcm","clk":"5347893697","pt":1646209831657,"mc":[{"id":"1.195453651","rc":[{"atl":[[2.6,1.42],[2.46,8.78]],"id":43167166},{"atl":[[1.84,0],[1.78,36.8]],"id":43016477}],"con":true,"img":false}]}
{"op":"mcm","clk":"5347893715","pt":1646209832125,"mc":[{"id":"1.195453651","rc":[{"atb":[[1.04,1.45]],"id":43167166}],"con":true,"img":false}]}
{"op":"mcm","clk":"5347893728","pt":1646209832377,"mc":[{"id":"1.195453651","rc":[{"atb":[[1.04,0.15]],"id":43167166}],"con":true,"img":false}]}
{"op":"mcm","clk":"5347893744","pt":1646209832585,"mc":[{"id":"1.195453651","rc":[{"atb":[[2.3,1.42],[1.04,0]],"id":43167166}],"con":true,"img":false}]}
{"op":"mcm","clk":"5347893749","pt":1646209832637,"mc":[{"id":"1.195453651","rc":[{"atl":[[2.42,1.27]],"id":43167166},{"trd":[[2.42,0.29]],"ltp":2.42,"tv":0.29,"id":43167166}],"con":true,"img":false}]}
{"op":"mcm","clk":"5347893765","pt":1646209832950,"mc":[{"id":"1.195453651","rc":[{"atb":[[2.28,24.25]],"id":43167166},{"atl":[[1.78,35.37]],"id":43016477}],"con":true,"img":false}]}
{"op":"mcm","clk":"5347893772","pt":1646209833053,"mc":[{"id":"1.195453651","rc":[{"atb":[[2.3,4.26]],"id":43167166}],"con":true,"img":false}]}
{"op":"mcm","clk":"5347893781","pt":1646209833257,"mc":[{"id":"1.195453651","rc":[{"atl":[[1.83,0],[1.77,11.65]],"id":43016477}],"con":true,"img":false}]}
{"op":"mcm","clk":"5347893814","pt":1646209833827,"mc":[{"id":"1.195453651","rc":[{"atl":[[1.78,11.71]],"id":43016477}],"con":true,"img":false}]}
{"op":"mcm","clk":"5347893817","pt":1646209833929,"mc":[{"id":"1.195453651","rc":[{"atl":[[1.77,35.31]],"id":43016477}],"con":true,"img":false}]}
{"op":"mcm","clk":"5347893869","pt":1646209834863,"mc":[{"id":"1.195453651","rc":[{"atb":[[2.44,19.56]],"id":43167166},{"atl":[[2.44,0],[2.42,0]],"id":43167166},{"trd":[[2.44,11.91],[2.42,2.85]],"ltp":2.44,"tv":14.76,"id":43167166},{"atb":[[1.7,0]],"id":43016477},{"trd":[[1.7,1.42]],"ltp":1.7,"tv":1.42,"id":43016477}],"con":true,"img":false}]}
{"op":"mcm","clk":"5347893880","pt":1646209835067,"mc":[{"id":"1.195453651","rc":[{"atl":[[1.76,11.65]],"id":43016477}],"con":true,"img":false}]}
{"op":"mcm","clk":"5347893891","pt":1646209835272,"mc":[{"id":"1.195453651","rc":[{"atl":[[1.82,0]],"id":43016477}],"con":true,"img":false}]}
{"op":"mcm","clk":"5347893899","pt":1646209835476,"mc":[{"id":"1.195453651","rc":[{"atb":[[2.3,26.74]],"id":43167166},{"atb":[[1.64,72.31],[1.67,3.18],[1.65,15.01]],"id":43016477},{"atl":[[1.77,11.65]],"id":43016477}],"con":true,"img":false}]}
{"op":"mcm","clk":"5347893903","pt":1646209835608,"mc":[{"id":"1.195453651","rc":[{"atl":[[1.76,35.31]],"id":43016477}],"con":true,"img":false}]}
{"op":"mcm","clk":"5347893909","pt":1646209835664,"mc":[{"id":"1.195453651","rc":[{"atb":[[1.68,6.32]],"id":43016477},{"trd":[[1.68,21.7]],"ltp":1.68,"tv":21.7,"id":43016477}],"con":true,"img":false}]}
{"op":"mcm","clk":"5347893920","pt":1646209835865,"mc":[{"id":"1.195453651","rc":[{"atb":[[2.32,7.4],[2.18,15.29]],"id":43167166},{"atl":[[1.79,1.42],[1.75,11.66]],"id":43016477}],"con":true,"img":false}]}
{"op":"mcm","clk":"5347893943","pt":1646209836278,"mc":[{"id":"1.195453651","rc":[{"atl":[[1.76,11.65]],"id":43016477}],"con":true,"img":false}]}
{"op":"mcm","clk":"5347893947","pt":1646209836336,"mc":[{"id":"1.195453651","rc":[{"atl":[[1.75,35.32]],"id":43016477}],"con":true,"img":false}]}
{"op":"mcm","clk":"5347893956","pt":1646209836435,"mc":[{"id":"1.195453651","rc":[{"atl":[[2.46,1.42]],"id":43167166}],"con":true,"img":false}]}
{"op":"mcm","clk":"5347893964","pt":1646209836646,"mc":[{"id":"1.195453651","rc":[{"atl":[[1.83,1.42]],"id":43016477}],"con":true,"img":false}]}
{"op":"mcm","clk":"5347893976","pt":1646209836952,"mc":[{"id":"1.195453651","rc":[{"atb":[[2.22,0]],"id":43167166}],"con":true,"img":false}]}
{"op":"mcm","clk":"5347893984","pt":1646209837057,"mc":[{"id":"1.195453651","rc":[{"atb":[[2.3,23.9]],"id":43167166},{"atl":[[1.75,11.66]],"id":43016477}],"con":true,"img":false}]}
{"op":"mcm","clk":"5347893991","pt":1646209837262,"mc":[{"id":"1.195453651","rc":[{"atl":[[1.74,11.69],[1.78,0]],"id":43016477}],"con":true,"img":false}]}
{"op":"mcm","clk":"5347893997","pt":1646209837471,"mc":[{"id":"1.195453651","rc":[{"atb":[[2.32,29.55]],"id":43167166}],"con":true,"img":false}]}
{"op":"mcm","clk":"5347894012","pt":1646209837779,"mc":[{"id":"1.195453651","rc":[{"atb":[[2.44,31.67]],"id":43167166},{"atl":[[1.74,33.48]],"id":43016477}],"con":true,"img":false}]}
{"op":"mcm","clk":"5347894016","pt":1646209837883,"mc":[{"id":"1.195453651","rc":[{"atb":[[1.6,0],[1.58,0],[1.62,0],[1.53,0],[1.57,9.48],[1.55,0],[1.66,11.97],[1.65,12.16],[1.61,0]],"id":43016477}],"con":true,"img":false}]}
{"op":"mcm","clk":"5347894019","pt":1646209837937,"mc":[{"id":"1.195453651","rc":[{"atb":[[2.34,7.37],[2.2,0]],"id":43167166},{"atl":[[1.73,11.7],[1.77,0]],"id":43016477}],"con":true,"img":false}]}
{"op":"mcm","clk":"5347894025","pt":1646209838148,"mc":[{"id":"1.195453651","rc":[{"atb":[[1.64,45.67],[1.65,35.53]],"id":43016477},{"atl":[[1.74,11.69]],"id":43016477}],"con":true,"img":false}]}
{"op":"mcm","clk":"5347894035","pt":1646209838456,"mc":[{"id":"1.195453651","rc":[{"atb":[[2.36,1.42],[2.28,1.42]],"id":43167166},{"atl":[[1.73,13.13]],"id":43016477}],"con":true,"img":false}]}
{"op":"mcm","clk":"5347894038","pt":1646209838577,"mc":[{"id":"1.195453651","rc":[{"atl":[[1.73,35.05]],"id":43016477}],"con":true,"img":false}]}
{"op":"mcm","clk":"5347894066","pt":1646209839140,"mc":[{"id":"1.195453651","rc":[{"atl":[[2.46,8.78]],"id":43167166}],"con":true,"img":false}]}
{"op":"mcm","clk":"5347894072","pt":1646209839245,"mc":[{"id":"1.195453651","rc":[{"atb":[[2.36,8.82],[2.24,0]],"id":43167166},{"atl":[[2.46,1.42]],"id":43167166}],"con":true,"img":false}]}
{"op":"mcm","clk":"5347894140","pt":1646209840451,"mc":[{"id":"1.195453651","rc":[{"atb":[[2.38,1.42]],"id":43167166},{"atl":[[1.72,1.42]],"id":43016477}],"con":true,"img":false}]}
{"op":"mcm","clk":"5347894163","pt":1646209840857,"mc":[{"id":"1.195453651","rc":[{"atl":[[1.73,13.13]],"id":43016477}],"con":true,"img":false}]}
{"op":"mcm","clk":"5347894171","pt":1646209840965,"mc":[{"id":"1.195453651","rc":[{"atl":[[2.48,12.76]],"id":43167166},{"atb":[[1.68,0]],"id":43016477},{"atl":[[1.72,23.34]],"id":43016477}],"con":true,"img":false}]}
{"op":"mcm","clk":"5347894174","pt":1646209841066,"mc":[{"id":"1.195453651","rc":[{"atb":[[2.26,0],[2.38,8.76]],"id":43167166},{"atl":[[1.72,35.14],[1.76,0]],"id":43016477}],"con":true,"img":false}]}
{"op":"mcm","clk":"5347894186","pt":1646209841270,"mc":[{"id":"1.195453651","rc":[{"atl":[[2.46,0]],"id":43167166},{"trd":[[2.46,1.42]],"ltp":2.46,"tv":1.42,"id":43167166},{"trd":[[1.68,23.79]],"ltp":1.68,"tv":23.79,"id":43016477}],"con":true,"img":false}]}
{"op":"mcm","clk":"5347894191","pt":1646209841374,"mc":[{"id":"1.195453651","rc":[{"atl":[[2.48,20.07]],"id":43167166},{"atl":[[1.72,4.26]],"id":43016477}],"con":true,"img":false}]}
{"op":"mcm","clk":"5347894196","pt":1646209841473,"mc":[{"id":"1.195453651","rc":[{"atb":[[2.36,30.31],[2.38,1.42]],"id":43167166},{"atl":[[2.46,7.38]],"id":43167166}],"con":true,"img":false}]}
{"op":"mcm","clk":"5347894207","pt":1646209841678,"mc":[{"id":"1.195453651","rc":[{"atl":[[2.48,7.31],[2.46,24.87]],"id":43167166}],"con":true,"img":false}]}
{"op":"mcm","clk":"5347894211","pt":1646209841784,"mc":[{"id":"1.195453651","rc":[{"atb":[[2.38,8.77]],"id":43167166},{"atl":[[2.46,17.49]],"id":43167166},{"atl":[[1.72,16.02]],"id":43016477}],"con":true,"img":false}]}
{"op":"mcm","clk":"5347894224","pt":1646209841989,"mc":[{"id":"1.195453651","rc":[{"atb":[[2.24,1.42]],"id":43167166},{"atl":[[1.78,1.42]],"id":43016477}],"con":true,"img":false}]}
{"op":"mcm","clk":"5347894232","pt":1646209842043,"mc":[{"id":"1.195453651","rc":[{"atl":[[1.72,4.26]],"id":43016477}],"con":true,"img":false}]}
{"op":"mcm","clk":"5347894250","pt":1646209842355,"mc":[{"id":"1.195453651","rc":[{"atl":[[1.72,16.02]],"id":43016477}],"con":true,"img":false}]}
{"op":"mcm","clk":"5347894293","pt":1646209843286,"mc":[{"id":"1.195453651","rc":[{"atb":[[2.24,2.84]],"id":43167166},{"atl":[[1.78,2.84]],"id":43016477}],"con":true,"img":false}]}
{"op":"mcm","clk":"5347894375","pt":1646209844884,"mc":[{"id":"1.195453651","rc":[{"atl":[[1.8,1.42]],"id":43016477}],"con":true,"img":false}]}
{"op":"mcm","clk":"5347894385","pt":1646209845055,"mc":[{"id":"1.195453651","rc":[{"atl":[[2.48,27.41],[2.46,0]],"id":43167166}],"con":true,"img":false}]}
{"op":"mcm","clk":"5347894402","pt":1646209845460,"mc":[{"id":"1.195453651","rc":[{"atb":[[2.3,1.42]],"id":43167166},{"atb":[[1.65,80.5]],"id":43016477}],"con":true,"img":false}]}
{"op":"mcm","clk":"5347894446","pt":1646209846390,"mc":[{"id":"1.195453651","rc":[{"atb":[[1.64,70.78],[1.65,57.13]],"id":43016477}],"con":true,"img":false}]}
{"op":"mcm","clk":"5347894457","pt":1646209846597,"mc":[{"id":"1.195453651","rc":[{"atl":[[1.68,2.04]],"id":43016477}],"con":true,"img":false}]}
{"op":"mcm","clk":"5347894479","pt":1646209846968,"mc":[{"id":"1.195453651","rc":[{"atb":[[2.38,29.95]],"id":43167166},{"atb":[[1.64,25.11],[1.65,12.16]],"id":43016477}],"con":true,"img":false}]}
{"op":"mcm","clk":"5347894566","pt":1646209848672,"mc":[{"id":"1.195453651","rc":[{"atl":[[2.5,7.25]],"id":43167166}],"con":true,"img":false}]}
{"op":"mcm","clk":"5347894636","pt":1646209850063,"mc":[{"id":"1.195453651","rc":[{"atl":[[1000,1.69]],"id":43167166}],"con":true,"img":false}]}
{"op":"mcm","clk":"5347894650","pt":1646209850271,"mc":[{"id":"1.195453651","rc":[{"atl":[[2.5,47.2],[2.48,7.31],[1000,0.02]],"id":43167166}],"con":true,"img":false}]}
{"op":"mcm","clk":"5347894654","pt":1646209850375,"mc":[{"id":"1.195453651","rc":[{"atl":[[1000,0]],"id":43167166}],"con":true,"img":false}]}
{"op":"mcm","clk":"5347894661","pt":1646209850478,"mc":[{"id":"1.195453651","rc":[{"atl":[[2.56,1.44]],"id":43167166}],"con":true,"img":false}]}
{"op":"mcm","clk":"5347894666","pt":1646209850580,"mc":[{"id":"1.195453651","rc":[{"atl":[[1.68,0]],"id":43016477},{"trd":[[1.68,27.87]],"ltp":1.68,"tv":27.87,"id":43016477}],"con":true,"img":false}]}
{"op":"mcm","clk":"5347894684","pt":1646209850992,"mc":[{"id":"1.195453651","rc":[{"atb":[[1.64,70.78]],"id":43016477}],"con":true,"img":false}]}
{"op":"mcm","clk":"5347894726","pt":1646209851777,"mc":[{"id":"1.195453651","rc":[{"atl":[[1.72,4.26]],"id":43016477}],"con":true,"img":false}]}
{"op":"mcm","clk":"5347894741","pt":1646209852187,"mc":[{"id":"1.195453651","rc":[{"atb":[[2.38,22.6]],"id":43167166}],"con":true,"img":false}]}
{"op":"mcm","clk":"5347894766","pt":1646209852603,"mc":[{"id":"1.195453651","rc":[{"atl":[[1.72,16.02]],"id":43016477}],"con":true,"img":false}]}
{"op":"mcm","clk":"5347894774","pt":1646209852703,"mc":[{"id":"1.195453651","rc":[{"atb":[[1.64,45.67],[1.63,62.64]],"id":43016477}],"con":true,"img":false}]}
{"op":"mcm","clk":"5347894796","pt":1646209853069,"mc":[{"id":"1.195453651","rc":[{"atl":[[1.72,4.26]],"id":43016477}],"con":true,"img":false}]}
{"op":"mcm","clk":"5347894810","pt":1646209853481,"mc":[{"id":"1.195453651","rc":[{"atb":[[1.96,0],[1.76,0],[1.86,0]],"id":43167166},{"atb":[[1.37,0],[1.57,0],[1.47,0]],"id":43016477}],"con":true,"img":false}]}
{"op":"mcm","clk":"5347894890","pt":1646209855961,"mc":[{"id":"1.195453651","rc":[{"atl":[[1.73,1.42]],"id":43016477}],"con":true,"img":false}]}
{"op":"mcm","clk":"5347894932","pt":1646209856790,"mc":[{"id":"1.195453651","rc":[{"atl":[[1.73,13.02]],"id":43016477}],"con":true,"img":false}]}
{"op":"mcm","clk":"5347894954","pt":1646209857203,"mc":[{"id":"1.195453651","rc":[{"atl":[[2.5,7.25],[2.52,32.61]],"id":43167166}],"con":true,"img":false}]}
{"op":"mcm","clk":"5347894968","pt":1646209857461,"mc":[{"id":"1.195453651","rc":[{"atb":[[2.32,7.4]],"id":43167166}],"con":true,"img":false}]}
{"op":"mcm","clk":"5347894992","pt":1646209857880,"mc":[{"id":"1.195453651","rc":[{"atb":[[1.63,46.4],[1.62,16.24]],"id":43016477}],"con":true,"img":false}]}
{"op":"mcm","clk":"5347895103","pt":1646209860611,"mc":[{"id":"1.195453651","rc":[{"atl":[[1.68,0]],"id":43016477}],"con":true,"img":false}]}
{"op":"mcm","clk":"5347895120","pt":1646209860978,"mc":[{"id":"1.195453651","rc":[{"atb":[[2.4,20.88]],"id":43167166}],"con":true,"img":false}]}
{"op":"mcm","clk":"5347895178","pt":1646209862266,"mc":[{"id":"1.195453651","rc":[{"atb":[[2.44,12.11]],"id":43167166}],"con":true,"img":false}]}
{"op":"mcm","clk":"5347895184","pt":1646209862381,"mc":[{"id":"1.195453651","rc":[{"atb":[[2.48,12.24]],"id":43167166},{"atl":[[2.48,0]],"id":43167166},{"trd":[[2.48,14.62]],"ltp":2.48,"tv":14.62,"id":43167166}],"con":true,"img":false}]}
{"op":"mcm","clk":"5347895191","pt":1646209862488,"mc":[{"id":"1.195453651","rc":[{"atb":[[2.4,0],[2.36,8.82],[2.38,1.42],[2.34,29.19]],"id":43167166},{"atb":[[1.65,57.13]],"id":43016477}],"con":true,"img":false}]}
{"op":"mcm","clk":"5347895193","pt":1646209862588,"mc":[{"id":"1.195453651","rc":[{"atb":[[2.42,7.38]],"id":43167166},{"atb":[[1.67,0]],"id":43016477},{"atl":[[1.71,11.7]],"id":43016477},{"trd":[[1.67,23.83]],"ltp":1.67,"tv":23.83,"id":43016477}],"con":true,"img":false}]}
{"op":"mcm","clk":"5347895201","pt":1646209862692,"mc":[{"id":"1.195453651","rc":[{"atb":[[2.44,19.48]],"id":43167166}],"con":true,"img":false}]}
{"op":"mcm","clk":"5347895209","pt":1646209862797,"mc":[{"id":"1.195453651","rc":[{"atb":[[2.44,7.37]],"id":43167166}],"con":true,"img":false}]}
{"op":"mcm","clk":"5347895224","pt":1646209863008,"mc":[{"id":"1.195453651","rc":[{"atb":[[1.65,12.16]],"id":43016477}],"con":true,"img":false}]}
{"op":"mcm","clk":"5347895230","pt":1646209863117,"mc":[{"id":"1.195453651","rc":[{"atb":[[2.48,24.54]],"id":43167166},{"atl":[[1.72,1.42]],"id":43016477}],"con":true,"img":false}]}
{"op":"mcm","clk":"5347895243","pt":1646209863412,"mc":[{"id":"1.195453651","rc":[{"atb":[[2.36,7.39],[2.24,0],[2.3,0],[2.38,0],[2.28,0],[2.14,0]],"id":43167166},{"atl":[[2.54,7.15],[2.6,0],[2.64,0],[2.58,0],[2.84,0],[2.62,0],[2.76,0],[2.56,0.02],[2.88,0],[2.66,0],[2.68,0]],"id":43167166},{"atl":[[1.73,11.6],[1.8,0],[1.83,0],[1.79,0],[1.78,0]],"id":43016477}],"con":true,"img":false}]}
{"op":"mcm","clk":"5347895250","pt":1646209863515,"mc":[{"id":"1.195453651","rc":[{"atb":[[2.4,20.88]],"id":43167166},{"atb":[[1.64,0]],"id":43016477}],"con":true,"img":false}]}
{"op":"mcm","clk":"5347895255","pt":1646209863619,"mc":[{"id":"1.195453651","rc":[{"atl":[[1.71,33.36]],"id":43016477}],"con":true,"img":false}]}
{"op":"mcm","clk":"5347895279","pt":1646209864140,"mc":[{"id":"1.195453651","rc":[{"atb":[[2.06,5.09],[2.46,3.7],[2.26,4.29]],"id":43167166},{"atb":[[1.14,38.59],[1.34,15.89],[1.24,22.51]],"id":43016477}],"con":true,"img":false}]}
{"op":"mcm","clk":"5347895297","pt":1646209864432,"mc":[{"id":"1.195453651","rc":[{"atb":[[2.44,0]],"id":43167166}],"con":true,"img":false}]}
{"op":"mcm","clk":"5347895324","pt":1646209864819,"mc":[{"id":"1.195453651","rc":[{"atl":[[1.7,11.7]],"id":43016477}],"con":true,"img":false}]}
{"op":"mcm","clk":"5347895346","pt":1646209865285,"mc":[{"id":"1.195453651","rc":[{"atl":[[1.71,11.7]],"id":43016477}],"con":true,"img":false}]}
{"op":"mcm","clk":"5347895349","pt":1646209865388,"mc":[{"id":"1.195453651","rc":[{"atl":[[1.7,33.36]],"id":43016477}],"con":true,"img":false}]}
{"op":"mcm","clk":"5347895389","pt":1646209866011,"mc":[{"id":"1.195453651","rc":[{"atb":[[2.48,12.24]],"id":43167166},{"atl":[[1.7,11.7]],"id":43016477}],"con":true,"img":false}]}
{"op":"mcm","clk":"5347895416","pt":1646209866477,"mc":[{"id":"1.195453651","rc":[{"atb":[[2.4,0],[2.38,21.18]],"id":43167166},{"atb":[[1.63,23.68],[1.62,47.14]],"id":43016477}],"con":true,"img":false}]}
{"op":"mcm","clk":"5347895431","pt":1646209866784,"mc":[{"id":"1.195453651","rc":[{"atb":[[2.48,24.61]],"id":43167166},{"atl":[[1.7,32.48]],"id":43016477}],"con":true,"img":false}]}
{"op":"mcm","clk":"5347895435","pt":1646209866939,"mc":[{"id":"1.195453651","rc":[{"atl":[[1.69,11.77]],"id":43016477}],"con":true,"img":false}]}
{"op":"mcm","clk":"5347895462","pt":1646209867413,"mc":[{"id":"1.195453651","rc":[{"atb":[[2.4,20.88]],"id":43167166},{"atb":[[1.63,70.08]],"id":43016477}],"con":true,"img":false}]}
{"op":"mcm","clk":"5347895469","pt":1646209867524,"mc":[{"id":"1.195453651","rc":[{"atl":[[1.7,11.7]],"id":43016477}],"con":true,"img":false}]}
{"op":"mcm","clk":"5347895476","pt":1646209867625,"mc":[{"id":"1.195453651","rc":[{"atl":[[1.72,0],[1.69,32.55]],"id":43016477}],"con":true,"img":false}]}
{"op":"mcm","clk":"5347895588","pt":1646209870210,"mc":[{"id":"1.195453651","rc":[{"atl":[[1.67,7.04]],"id":43016477}],"con":true,"img":false}]}
{"op":"mcm","clk":"5347895602","pt":1646209870521,"mc":[{"id":"1.195453651","rc":[{"atl":[[1.69,11.77]],"id":43016477}],"con":true,"img":false}]}
{"op":"mcm","clk":"5347895607","pt":1646209870621,"mc":[{"id":"1.195453651","rc":[{"atb":[[1.04,2.86]],"id":43167166},{"atl":[[1.67,27.82]],"id":43016477}],"con":true,"img":false}]}
{"op":"mcm","clk":"5347895617","pt":1646209870824,"mc":[{"id":"1.195453651","rc":[{"atb":[[2.46,11],[1.04,0.13]],"id":43167166}],"con":true,"img":false}]}
{"op":"mcm","clk":"5347895624","pt":1646209870988,"mc":[{"id":"1.195453651","rc":[{"atb":[[1.04,0]],"id":43167166}],"con":true,"img":false}]}
{"op":"mcm","clk":"5347895629","pt":1646209871094,"mc":[{"id":"1.195453651","rc":[{"atl":[[2.5,7.11]],"id":43167166},{"trd":[[2.5,0.27]],"ltp":2.5,"tv":0.27,"id":43167166}],"con":true,"img":false}]}
{"op":"mcm","clk":"5347895635","pt":1646209871199,"mc":[{"id":"1.195453651","rc":[{"atl":[[2.5,3.9]],"id":43167166},{"trd":[[2.5,6.69]],"ltp":2.5,"tv":6.69,"id":43167166}],"con":true,"img":false}]}
{"op":"mcm","clk":"5347895733","pt":1646209873008,"mc":[{"id":"1.195453651","rc":[{"atb":[[2.48,12.37]],"id":43167166}],"con":true,"img":false}]}
{"op":"mcm","clk":"5347895738","pt":1646209873109,"mc":[{"id":"1.195453651","rc":[{"atb":[[2.5,8.34]],"id":43167166},{"atl":[[2.5,0]],"id":43167166},{"trd":[[2.5,14.5]],"ltp":2.5,"tv":14.5,"id":43167166}],"con":true,"img":false}]}
{"op":"mcm","clk":"5347895742","pt":1646209873315,"mc":[{"id":"1.195453651","rc":[{"atb":[[2.48,19.63]],"id":43167166},{"atl":[[2.52,4.84]],"id":43167166},{"trd":[[2.52,55.54]],"ltp":2.52,"tv":55.54,"id":43167166},{"atb":[[1.63,46.4],[1.62,71.28]],"id":43016477},{"atl":[[1.67,13.86]],"id":43016477},{"trd":[[1.67,51.77]],"ltp":1.67,"tv":51.77,"id":43016477}],"con":true,"img":false}]}
{"op":"mcm","clk":"5347895746","pt":1646209873419,"mc":[{"id":"1.195453651","rc":[{"atb":[[2.48,7.26],[2.34,7.37]],"id":43167166},{"atl":[[2.52,0]],"id":43167166},{"trd":[[2.52,65.22]],"ltp":2.52,"tv":65.22,"id":43167166},{"atb":[[1.66,0]],"id":43016477}],"con":true,"img":false}]}
{"op":"mcm","clk":"5347895749","pt":1646209873524,"mc":[{"id":"1.195453651","rc":[{"atb":[[2.5,34.91]],"id":43167166},{"atl":[[1.67,25.94]],"id":43016477}],"con":true,"img":false}]}
{"op":"mcm","clk":"5347895753","pt":1646209873626,"mc":[{"id":"1.195453651","rc":[{"atl":[[2.54,0]],"id":43167166}],"con":true,"img":false}]}
{"op":"mcm","clk":"5347895757","pt":1646209873727,"mc":[{"id":"1.195453651","rc":[{"atb":[[1.65,0]],"id":43016477}],"con":true,"img":false}]}
{"op":"mcm","clk":"5347895760","pt":1646209873826,"mc":[{"id":"1.195453651","rc":[{"atl":[[1.67,12.08]],"id":43016477}],"con":true,"img":false}]}
{"op":"mcm","clk":"5347895765","pt":1646209873938,"mc":[{"id":"1.195453651","rc":[{"atl":[[3.1,12.24]],"id":43167166},{"atb":[[1.63,0],[1.62,24.14]],"id":43016477}],"con":true,"img":false}]}
{"op":"mcm","clk":"5347895786","pt":1646209874397,"mc":[{"id":"1.195453651","rc":[{"atb":[[2.42,27.97]],"id":43167166},{"atb":[[1.51,69.88]],"id":43016477}],"con":true,"img":false}]}
{"op":"mcm","clk":"5347895801","pt":1646209874809,"mc":[{"id":"1.195453651","rc":[{"atb":[[2.52,7.15]],"id":43167166},{"atb":[[1.04,2.86]],"id":43016477}],"con":true,"img":false}]}
{"op":"mcm","clk":"5347895809","pt":1646209875019,"mc":[{"id":"1.195453651","rc":[{"atb":[[2.42,20.58]],"id":43167166},{"atb":[[1.04,0.13]],"id":43016477},{"atl":[[1.67,28.07]],"id":43016477}],"con":true,"img":false}]}
{"op":"mcm","clk":"5347895820","pt":1646209875221,"mc":[{"id":"1.195453651","rc":[{"atb":[[2.5,22.54]],"id":43167166},{"atb":[[1.04,0]],"id":43016477}],"con":true,"img":false}]}
{"op":"mcm","clk":"5347895825","pt":1646209875325,"mc":[{"id":"1.195453651","rc":[{"atb":[[2.52,19.43]],"id":43167166},{"trd":[[2.52,65.3]],"ltp":2.52,"tv":65.3,"id":43167166},{"trd":[[1.66,0.13]],"ltp":1.66,"tv":0.13,"id":43016477}],"con":true,"img":false}]}
{"op":"mcm","clk":"5347895832","pt":1646209875430,"mc":[{"id":"1.195453651","rc":[{"atb":[[2.38,0]],"id":43167166}],"con":true,"img":false}]}
{"op":"mcm","clk":"5347895840","pt":1646209875533,"mc":[{"id":"1.195453651","rc":[{"atl":[[1.66,12.22]],"id":43016477}],"con":true,"img":false}]}
{"op":"mcm","clk":"5347895844","pt":1646209875635,"mc":[{"id":"1.195453651","rc":[{"atl":[[1.71,0]],"id":43016477}],"con":true,"img":false}]}
{"op":"mcm","clk":"5347895866","pt":1646209876049,"mc":[{"id":"1.195453651","rc":[{"atl":[[1.67,12.08]],"id":43016477}],"con":true,"img":false}]}
{"op":"mcm","clk":"5347895871","pt":1646209876106,"mc":[{"id":"1.195453651","rc":[{"atl":[[1.66,28.21]],"id":43016477}],"con":true,"img":false}]}
{"op":"mcm","clk":"5347895883","pt":1646209876416,"mc":[{"id":"1.195453651","rc":[{"atb":[[2.44,20.3]],"id":43167166}],"con":true,"img":false}]}
{"op":"mcm","clk":"5347896009","pt":1646209878533,"mc":[{"id":"1.195453651","rc":[{"atb":[[1.6,25.12],[1.62,0]],"id":43016477}],"con":true,"img":false}]}
{"op":"mcm","clk":"5347896021","pt":1646209878737,"mc":[{"id":"1.195453651","rc":[{"atb":[[2.54,7]],"id":43167166},{"atl":[[1.65,12.51]],"id":43016477}],"con":true,"img":false}]}
{"op":"mcm","clk":"5347896033","pt":1646209878942,"mc":[{"id":"1.195453651","rc":[{"atb":[[2.4,0],[2.46,3.7]],"id":43167166},{"atl":[[2.56,0]],"id":43167166},{"trd":[[2.56,0.05]],"ltp":2.56,"tv":0.05,"id":43167166},{"atl":[[1.7,0]],"id":43016477}],"con":true,"img":false}]}
{"op":"mcm","clk":"5347896051","pt":1646209879201,"mc":[{"id":"1.195453651","rc":[{"atb":[[2.52,7.06]],"id":43167166},{"atl":[[1.66,12.22]],"id":43016477}],"con":true,"img":false}]}
{"op":"mcm","clk":"5347896053","pt":1646209879308,"mc":[{"id":"1.195453651","rc":[{"atb":[[2.54,19.37]],"id":43167166},{"atl":[[1.65,28.5]],"id":43016477}],"con":true,"img":false}]}
{"op":"mcm","clk":"5347896078","pt":1646209879920,"mc":[{"id":"1.195453651","rc":[{"atb":[[2.56,18.74]],"id":43167166}],"con":true,"img":false}]}
{"op":"mcm","clk":"5347896096","pt":1646209880339,"mc":[{"id":"1.195453651","rc":[{"atb":[[2.54,7]],"id":43167166}],"con":true,"img":false}]}
{"op":"mcm","clk":"5347896099","pt":1646209880442,"mc":[{"id":"1.195453651","rc":[{"atb":[[2.56,31.11]],"id":43167166}],"con":true,"img":false}]}
{"op":"mcm","clk":"5347896106","pt":1646209880647,"mc":[{"id":"1.195453651","rc":[{"atl":[[1.64,12.51],[1.69,0]],"id":43016477}],"con":true,"img":false}]}
{"op":"mcm","clk":"5347896130","pt":1646209881113,"mc":[{"id":"1.195453651","rc":[{"atl":[[1.65,12.51]],"id":43016477}],"con":true,"img":false}]}
{"op":"mcm","clk":"5347896140","pt":1646209881216,"mc":[{"id":"1.195453651","rc":[{"atl":[[1.64,28.5]],"id":43016477}],"con":true,"img":false}]}
{"op":"mcm","clk":"5347896171","pt":1646209881836,"mc":[{"id":"1.195453651","rc":[{"atb":[[2.58,6.77]],"id":43167166},{"atb":[[1.59,0]],"id":43016477},{"atl":[[1.63,13.08]],"id":43016477}],"con":true,"img":false}]}
{"op":"mcm","clk":"5347896189","pt":1646209882195,"mc":[{"id":"1.195453651","rc":[{"atb":[[2.58,0]],"id":43167166},{"atb":[[1.52,12.68]],"id":43016477},{"atl":[[1.63,0]],"id":43016477}],"con":true,"img":false}]}
{"op":"mcm","clk":"5347896199","pt":1646209882402,"mc":[{"id":"1.195453651","rc":[{"atb":[[2.48,27.01],[2.56,0]],"id":43167166},{"atl":[[1.64,12.51]],"id":43016477}],"con":true,"img":false}]}
{"op":"mcm","clk":"5347896203","pt":1646209882516,"mc":[{"id":"1.195453651","rc":[{"atb":[[2.58,12.37]],"id":43167166},{"atl":[[1.63,15.99]],"id":43016477}],"con":true,"img":false}]}
{"op":"mcm","clk":"5347896212","pt":1646209882713,"mc":[{"id":"1.195453651","rc":[{"atb":[[2.48,19.75]],"id":43167166},{"atl":[[1.62,12.86]],"id":43016477}],"con":true,"img":false}]}
{"op":"mcm","clk":"5347896217","pt":1646209882815,"mc":[{"id":"1.195453651","rc":[{"atb":[[2.6,6.87]],"id":43167166},{"atl":[[1.67,0]],"id":43016477}],"con":true,"img":false}]}
{"op":"mcm","clk":"5347896219","pt":1646209882920,"mc":[{"id":"1.195453651","rc":[{"atb":[[2.42,0]],"id":43167166}],"con":true,"img":false}]}
{"op":"mcm","clk":"5347896225","pt":1646209883027,"mc":[{"id":"1.195453651","rc":[{"atb":[[2.58,0]],"id":43167166},{"atb":[[1.6,0.02]],"id":43016477},{"trd":[[1.6,50.21]],"ltp":1.6,"tv":50.21,"id":43016477}],"con":true,"img":false}]}
{"op":"mcm","clk":"5347896235","pt":1646209883229,"mc":[{"id":"1.195453651","rc":[{"atb":[[1.6,0]],"id":43016477},{"atl":[[1.62,19.06]],"id":43016477},{"trd":[[1.6,50.25]],"ltp":1.6,"tv":50.25,"id":43016477}],"con":true,"img":false}]}
{"op":"mcm","clk":"5347896246","pt":1646209883438,"mc":[{"id":"1.195453651","rc":[{"atb":[[2.62,18.04]],"id":43167166},{"atb":[[1.51,12.56],[1.48,60.9]],"id":43016477}],"con":true,"img":false}]}
{"op":"mcm","clk":"5347896250","pt":1646209883537,"mc":[{"id":"1.195453651","rc":[{"atb":[[1.52,23.15]],"id":43016477}],"con":true,"img":false}]}
{"op":"mcm","clk":"5347896320","pt":1646209884832,"mc":[{"id":"1.195453651","rc":[{"atb":[[1.53,12.97]],"id":43016477}],"con":true,"img":false}]}
{"op":"mcm","clk":"5347896337","pt":1646209885147,"mc":[{"id":"1.195453651","rc":[{"atb":[[2.62,23.22]],"id":43167166},{"atb":[[1.52,12.68]],"id":43016477},{"atl":[[1.63,0]],"id":43016477}],"con":true,"img":false}]}
{"op":"mcm","clk":"5347896346","pt":1646209885251,"mc":[{"id":"1.195453651","rc":[{"atl":[[1.62,35.05]],"id":43016477}],"con":true,"img":false}]}
{"op":"mcm","clk":"5347896351","pt":1646209885308,"mc":[{"id":"1.195453651","rc":[{"atb":[[2.5,14.19]],"id":43167166}],"con":true,"img":false}]}
{"op":"mcm","clk":"5347896371","pt":1646209885736,"mc":[{"id":"1.195453651","rc":[{"atb":[[2.5,7],[2.64,6.86]],"id":43167166}],"con":true,"img":false}]}
{"op":"mcm","clk":"5347896382","pt":1646209885938,"mc":[{"id":"1.195453651","rc":[{"atl":[[1.61,12.89]],"id":43016477}],"con":true,"img":false}]}
{"op":"mcm","clk":"5347896386","pt":1646209886036,"mc":[{"id":"1.195453651","rc":[{"atl":[[1.66,0]],"id":43016477}],"con":true,"img":false}]}
{"op":"mcm","clk":"5347896405","pt":1646209886347,"mc":[{"id":"1.195453651","rc":[{"atl":[[1.62,19.06]],"id":43016477}],"con":true,"img":false}]}
{"op":"mcm","clk":"5347896410","pt":1646209886402,"mc":[{"id":"1.195453651","rc":[{"atl":[[1.61,28.88]],"id":43016477}],"con":true,"img":false}]}
{"op":"mcm","clk":"5347896436","pt":1646209886913,"mc":[{"id":"1.195453651","rc":[{"atl":[[1.61,20.38]],"id":43016477}],"con":true,"img":false}]}
{"op":"mcm","clk":"5347896452","pt":1646209887223,"mc":[{"id":"1.195453651","rc":[{"atb":[[2.62,18.04]],"id":43167166}],"con":true,"img":false}]}
{"op":"mcm","clk":"5347896474","pt":1646209887634,"mc":[{"id":"1.195453651","rc":[{"atb":[[2.64,14.01]],"id":43167166}],"con":true,"img":false}]}
{"op":"mcm","clk":"5347896507","pt":1646209888413,"mc":[{"id":"1.195453651","marketDefinition":{"bspMarket":false,"turnInPlayEnabled":false,"persistenceEnabled":false,"marketBaseRate":7.0,"eventId":"31272494","eventTypeId":"4339","numberOfWinners":1,"bettingType":"ODDS","marketType":"MATCH_BET","marketTime":"2022-03-02T08:31:00.000Z","suspendTime":"2022-03-02T08:31:00.000Z","bspReconciled":false,"complete":true,"inPlay":false,"crossMatching":true,"runnersVoidable":false,"numberOfActiveRunners":2,"betDelay":0,"status":"SUSPENDED","runners":[{"status":"ACTIVE","sortPriority":1,"id":43167166,"name":"3. Dolly Dagger"},{"status":"ACTIVE","sortPriority":2,"id":43016477,"name":"8. Before Noon"}],"regulators":["MR_INT"],"venue":"Traralgon","countryCode":"AU","discountAllowed":true,"timezone":"Australia/Sydney","openDate":"2022-03-02T08:31:00.000Z","version":4382836280,"name":"Dolly Dagger v Before Noon","eventName":"Traralgon (AUS) 2nd Mar"},"rc":[],"con":true,"img":false}]}
{"op":"mcm","clk":"5347896507","pt":1646209888413,"mc":[{"id":"1.195453651","rc":[{"atb":[[2.54,0],[2.5,0],[2.32,0],[2.64,0],[2.6,0],[2.44,0],[2.26,0],[2.62,0],[2.48,0],[2.34,0],[2.36,0],[2.06,0],[2.52,0],[2.46,0],[2.18,0]],"id":43167166},{"atl":[[3.2,0],[3.1,0],[3.3,0]],"id":43167166},{"atb":[[1.5,0],[1.14,0],[1.51,0],[1.53,0],[1.48,0],[1.34,0],[1.24,0],[1.52,0]],"id":43016477},{"atl":[[1.64,0],[1.73,0],[1.74,0],[1.62,0],[1.86,0],[1.65,0],[1.75,0],[1.61,0]],"id":43016477}],"con":true,"img":false}]}
{"op":"mcm","clk":"5347899281","pt":1646209957105,"mc":[{"id":"1.195453651","rc":[{"trd":[[2.56,0],[2.5,0],[2.42,0],[2.52,0],[2.46,0],[2.44,0],[2.48,0]],"ltp":2.56,"tv":0.0,"id":43167166},{"trd":[[1.8,0],[1.6,0],[1.67,0],[1.68,0],[1.7,0],[1.65,0],[1.66,0],[1.75,0],[1.69,0]],"ltp":1.8,"tv":0.0,"id":43016477}],"con":true,"img":false}]}
{"op":"mcm","clk":"5347899370","pt":1646209958660,"mc":[{"id":"1.195453651","marketDefinition":{"bspMarket":false,"turnInPlayEnabled":false,"persistenceEnabled":false,"marketBaseRate":7.0,"eventId":"31272494","eventTypeId":"4339","numberOfWinners":1,"bettingType":"ODDS","marketType":"MATCH_BET","marketTime":"2022-03-02T08:31:00.000Z","suspendTime":"2022-03-02T08:31:00.000Z","bspReconciled":false,"complete":true,"inPlay":false,"crossMatching":false,"runnersVoidable":false,"numberOfActiveRunners":0,"betDelay":0,"status":"CLOSED","settledTime":"2022-03-02T08:32:35.000Z","runners":[{"status":"LOSER","sortPriority":1,"id":43167166,"name":"3. Dolly Dagger"},{"status":"WINNER","sortPriority":2,"id":43016477,"name":"8. Before Noon"}],"regulators":["MR_INT"],"venue":"Traralgon","countryCode":"AU","discountAllowed":true,"timezone":"Australia/Sydney","openDate":"2022-03-02T08:31:00.000Z","version":4382837765,"name":"Dolly Dagger v Before Noon","eventName":"Traralgon (AUS) 2nd Mar"},"rc":[],"con":true,"img":false}]}
