{"op":"mcm","clk":"5345985292","pt":1646174444251,"mc":[{"id":"1.195453609","marketDefinition":{"bspMarket":true,"turnInPlayEnabled":false,"persistenceEnabled":false,"marketBaseRate":7.0,"eventId":"31272494","eventTypeId":"4339","numberOfWinners":1,"bettingType":"ODDS","marketType":"WIN","marketTime":"2022-03-02T08:31:00.000Z","suspendTime":"2022-03-02T08:31:00.000Z","bspReconciled":false,"complete":true,"inPlay":false,"crossMatching":false,"runnersVoidable":false,"numberOfActiveRunners":8,"betDelay":0,"status":"OPEN","runners":[{"status":"ACTIVE","sortPriority":1,"id":41719613,"name":"1. Gotham Prince"},{"status":"ACTIVE","sortPriority":2,"id":43167165,"name":"2. Bit Shakey"},{"status":"ACTIVE","sortPriority":3,"id":43167166,"name":"3. Dolly Dagger"},{"status":"ACTIVE","sortPriority":4,"id":43167167,"name":"4. Wild Apache"},{"status":"ACTIVE","sortPriority":5,"id":43167168,"name":"5. My Mate Sid"},{"status":"ACTIVE","sortPriority":6,"id":43167169,"name":"6. Flight Chaser"},{"status":"ACTIVE","sortPriority":7,"id":43167170,"name":"7. Dr Bambi"},{"status":"ACTIVE","sortPriority":8,"id":43016477,"name":"8. Before Noon"}],"regulators":["MR_INT"],"venue":"Traralgon","countryCode":"AU","discountAllowed":true,"timezone":"Australia/Sydney","openDate":"2022-03-02T08:31:00.000Z","version":4382425357,"name":"R1 350m Mdn","eventName":"Traralgon (AUS) 2nd Mar"},"rc":[],"con":true,"img":false}]}
{"op":"mcm","clk":"5346059516","pt":1646175786519,"mc":[{"id":"1.195453609","rc":[{"atb":[[4.8,21.48],[4.3,49.48],[5.8,8.5],[5.3,18.98],[7.6,6.18]],"id":43167166},{"atl":[[65,3.11],[36,3.79],[90,2.24],[46,2.95]],"id":43167166},{"spn":21.8,"spf":"NaN","id":43167166},{"atb":[[4.8,21.48],[4.3,49.48],[5.8,8.5],[5.3,18.98],[7.6,6.18]],"id":43167167},{"atl":[[65,3.11],[36,3.79],[90,2.24],[46,2.95]],"id":43167167},{"spn":21.8,"spf":"NaN","id":43167167},{"atb":[[4.8,21.48],[4.3,49.48],[5.8,8.5],[5.3,18.98],[7.6,6.18]],"id":43167168},{"atl":[[65,3.11],[36,3.79],[90,2.24],[46,2.95]],"id":43167168},{"spn":21.8,"spf":"NaN","id":43167168},{"atb":[[1.4,204.13],[1.6,68.04],[1.45,181.45],[1.5,81.65],[1.35,466.59]],"id":41719613},{"atl":[[3.45,81.45],[2.88,70.76],[3.2,90.71],[2.98,67.19]],"id":41719613},{"spn":2.24,"spf":"NaN","id":41719613},{"atb":[[4,27.21],[4.5,23.33],[5,10.2],[6,8.16],[3.75,59.38]],"id":43167169},{"atl":[[19.5,7.19],[38,5.39],[24,5.78],[29,7.12]],"id":43167169},{"spn":12.75,"spf":"NaN","id":43167169},{"atb":[[6.4,15.12],[7.4,6.37],[5.2,38.88],[5.7,17.37],[9.4,4.86]],"id":43167165},{"atl":[[80,1.68],[160,1.25],[55,2.46],[110,1.82]],"id":43167165},{"spn":32.2,"spf":"NaN","id":43167165},{"atb":[[8,5.83],[4.5,46.65],[5,20.41],[5.5,18.14],[6,8.16]],"id":43167170},{"atl":[[75,2.69],[40,3.41],[50,2.71],[100,2.01]],"id":43167170},{"spn":24.0,"spf":"NaN","id":43167170},{"atb":[[4.8,21.48],[4.3,49.48],[5.8,8.5],[5.3,18.98],[7.6,6.18]],"id":43016477},{"atl":[[65,3.11],[36,3.79],[90,2.24],[46,2.95]],"id":43016477},{"spn":21.8,"spf":"NaN","id":43016477}],"con":true,"img":false}]}
{"op":"mcm","clk":"5346061998","pt":1646175839944,"mc":[{"id":"1.195453609","rc":[{"atb":[[4.8,0],[4.3,0],[5.8,0],[5.3,0],[7.6,0]],"id":43167166},{"atl":[[65,0],[36,0],[90,0],[46,0]],"id":43167166},{"atb":[[4.8,0],[4.3,0],[5.8,0],[5.3,0],[7.6,0]],"id":43167167},{"atl":[[65,0],[36,0],[90,0],[46,0]],"id":43167167},{"atb":[[4.8,0],[4.3,0],[5.8,0],[5.3,0],[7.6,0]],"id":43167168},{"atl":[[65,0],[36,0],[90,0],[46,0]],"id":43167168},{"atb":[[1.4,0],[1.6,0],[1.45,0],[1.5,0],[1.35,0]],"id":41719613},{"atl":[[3.45,0],[2.88,0],[3.2,0],[2.98,0]],"id":41719613},{"atb":[[4,0],[4.5,0],[5,0],[6,0],[3.75,0]],"id":43167169},{"atl":[[19.5,0],[38,0],[24,0],[29,0]],"id":43167169},{"atb":[[6.4,0],[7.4,0],[5.2,0],[5.7,0],[9.4,0]],"id":43167165},{"atl":[[80,0],[160,0],[55,0],[110,0]],"id":43167165},{"atb":[[8,0],[4.5,0],[5,0],[5.5,0],[6,0]],"id":43167170},{"atl":[[75,0],[40,0],[50,0],[100,0]],"id":43167170},{"atb":[[4.8,0],[4.3,0],[5.8,0],[5.3,0],[7.6,0]],"id":43016477},{"atl":[[65,0],[36,0],[90,0],[46,0]],"id":43016477}],"con":true,"img":false}]}
{"op":"mcm","clk":"5346062134","pt":1646175843189,"mc":[{"id":"1.195453609","rc":[{"atb":[[4.8,21.48],[4.3,49.48],[5.8,8.5],[5.3,18.98],[7.6,6.18]],"id":43167166},{"atl":[[65,3.11],[36,3.79],[90,2.24],[46,2.95]],"id":43167166},{"atb":[[4.8,21.48],[4.3,49.48],[5.8,8.5],[5.3,18.98],[7.6,6.18]],"id":43167167},{"atl":[[65,3.11],[36,3.79],[90,2.24],[46,2.95]],"id":43167167},{"atb":[[1.4,204.13],[1.6,68.04],[1.45,181.45],[1.5,81.65],[1.35,466.59]],"id":41719613},{"atl":[[3.45,81.45],[2.88,70.76],[3.2,90.71],[2.98,67.19]],"id":41719613},{"atb":[[4.8,21.48],[4.3,49.48],[5.8,8.5],[5.3,18.98],[7.6,6.18]],"id":43167168},{"atl":[[65,3.11],[36,3.79],[90,2.24],[46,2.95]],"id":43167168},{"atb":[[4,27.21],[4.5,23.33],[5,10.2],[6,8.16],[3.75,59.38]],"id":43167169},{"atl":[[19.5,7.19],[38,5.39],[24,5.78],[29,7.12]],"id":43167169},{"atb":[[6.4,15.12],[7.4,6.37],[5.2,38.88],[5.7,17.37],[9.4,4.86]],"id":43167165},{"atl":[[80,1.68],[160,1.25],[55,2.46],[110,1.82]],"id":43167165},{"atb":[[8,5.83],[4.5,46.65],[5,20.41],[5.5,18.14],[6,8.16]],"id":43167170},{"atl":[[75,2.69],[40,3.41],[50,2.71],[100,2.01]],"id":43167170},{"atb":[[4.8,21.48],[4.3,49.48],[5.8,8.5],[5.3,18.98],[7.6,6.18]],"id":43016477},{"atl":[[65,3.11],[36,3.79],[90,2.24],[46,2.95]],"id":43016477}],"con":true,"img":false}]}
{"op":"mcm","clk":"5346105206","pt":1646176602710,"mc":[{"id":"1.195453609","marketDefinition":{"bspMarket":true,"turnInPlayEnabled":false,"persistenceEnabled":false,"marketBaseRate":7.0,"eventId":"31272494","eventTypeId":"4339","numberOfWinners":1,"bettingType":"ODDS","marketType":"WIN","marketTime":"2022-03-02T08:31:00.000Z","suspendTime":"2022-03-02T08:31:00.000Z","bspReconciled":false,"complete":true,"inPlay":false,"crossMatching":false,"runnersVoidable":false,"numberOfActiveRunners":8,"betDelay":0,"status":"OPEN","runners":[{"status":"ACTIVE","sortPriority":1,"id":41719613,"name":"1. Gotham Prince"},{"status":"ACTIVE","sortPriority":2,"id":43167165,"name":"2. Bit Shakey"},{"status":"ACTIVE","sortPriority":3,"id":43167166,"name":"3. Dolly Dagger"},{"status":"ACTIVE","sortPriority":4,"id":43167167,"name":"4. Wild Apache"},{"status":"ACTIVE","sortPriority":5,"id":43167168,"name":"5. My Mate Sid"},{"status":"ACTIVE","sortPriority":6,"id":43167169,"name":"6. Flight Chaser"},{"status":"ACTIVE","sortPriority":7,"id":43167170,"name":"7. Dr Bambi"},{"status":"ACTIVE","sortPriority":8,"id":43016477,"name":"8. Before Noon"}],"regulators":["MR_INT"],"venue":"Traralgon","countryCode":"AU","discountAllowed":true,"timezone":"Australia/Sydney","openDate":"2022-03-02T08:31:00.000Z","version":4382425357,"name":"R1 350m Mdn","eventName":"Traralgon (AUS) 2nd Mar"},"rc":[{"atb":[[4.8,21.48],[4.3,49.48],[5.8,8.5],[5.3,18.98],[7.6,6.18]],"id":43167166},{"atl":[[65,3.11],[36,3.79],[90,2.24],[46,2.95]],"id":43167166},{"spn":21.8,"spf":"NaN","id":43167166},{"atb":[[4.8,21.48],[4.3,49.48],[5.8,8.5],[5.3,18.98],[7.6,6.18]],"id":43167167},{"atl":[[65,3.11],[36,3.79],[90,2.24],[46,2.95]],"id":43167167},{"spn":21.8,"spf":"NaN","id":43167167},{"atb":[[4.8,21.48],[4.3,49.48],[5.8,8.5],[5.3,18.98],[7.6,6.18]],"id":43167168},{"atl":[[65,3.11],[36,3.79],[90,2.24],[46,2.95]],"id":43167168},{"spn":21.8,"spf":"NaN","id":43167168},{"atb":[[1.4,204.13],[1.6,68.04],[1.45,181.45],[1.5,81.65],[1.35,466.59]],"id":41719613},{"atl":[[3.45,81.45],[2.88,70.76],[3.2,90.71],[2.98,67.19]],"id":41719613},{"spn":2.24,"spf":"NaN","id":41719613},{"atb":[[4,27.21],[4.5,23.33],[5,10.2],[6,8.16],[3.75,59.38]],"id":43167169},{"atl":[[19.5,7.19],[38,5.39],[24,5.78],[29,7.12]],"id":43167169},{"spn":12.75,"spf":"NaN","id":43167169},{"atb":[[6.4,15.12],[7.4,6.37],[5.2,38.88],[5.7,17.37],[9.4,4.86]],"id":43167165},{"atl":[[80,1.68],[160,1.25],[55,2.46],[110,1.82]],"id":43167165},{"spn":32.2,"spf":"NaN","id":43167165},{"atb":[[8,5.83],[4.5,46.65],[5,20.41],[5.5,18.14],[6,8.16]],"id":43167170},{"atl":[[75,2.69],[40,3.41],[50,2.71],[100,2.01]],"id":43167170},{"spn":24.0,"spf":"NaN","id":43167170},{"atb":[[4.8,21.48],[4.3,49.48],[5.8,8.5],[5.3,18.98],[7.6,6.18]],"id":43016477},{"atl":[[65,3.11],[36,3.79],[90,2.24],[46,2.95]],"id":43016477},{"spn":21.8,"spf":"NaN","id":43016477}],"con":true,"img":true}]}
{"op":"mcm","clk":"5346401663","pt":1646182002790,"mc":[{"id":"1.195453609","marketDefinition":{"bspMarket":true,"turnInPlayEnabled":false,"persistenceEnabled":false,"marketBaseRate":7.0,"eventId":"31272494","eventTypeId":"4339","numberOfWinners":1,"bettingType":"ODDS","marketType":"WIN","marketTime":"2022-03-02T08:31:00.000Z","suspendTime":"2022-03-02T08:31:00.000Z","bspReconciled":false,"complete":true,"inPlay":false,"crossMatching":false,"runnersVoidable":false,"numberOfActiveRunners":8,"betDelay":0,"status":"OPEN","runners":[{"status":"ACTIVE","sortPriority":1,"id":41719613,"name":"1. Gotham Prince"},{"status":"ACTIVE","sortPriority":2,"id":43167165,"name":"2. Bit Shakey"},{"status":"ACTIVE","sortPriority":3,"id":43167166,"name":"3. Dolly Dagger"},{"status":"ACTIVE","sortPriority":4,"id":43167167,"name":"4. Wild Apache"},{"status":"ACTIVE","sortPriority":5,"id":43167168,"name":"5. My Mate Sid"},{"status":"ACTIVE","sortPriority":6,"id":43167169,"name":"6. Flight Chaser"},{"status":"ACTIVE","sortPriority":7,"id":43167170,"name":"7. Dr Bambi"},{"status":"ACTIVE","sortPriority":8,"id":43016477,"name":"8. Before Noon"}],"regulators":["MR_INT"],"venue":"Traralgon","countryCode":"AU","discountAllowed":true,"timezone":"Australia/Sydney","openDate":"2022-03-02T08:31:00.000Z","version":4382425357,"name":"R1 350m Mdn","eventName":"Traralgon (AUS) 2nd Mar"},"rc":[{"atb":[[4.8,21.48],[4.3,49.49],[5.8,8.5],[5.3,18.98],[7.6,6.18]],"id":43167166},{"atl":[[65,3.11],[36,3.8],[90,2.24],[46,2.95]],"id":43167166},{"spn":21.8,"spf":"NaN","id":43167166},{"atb":[[4.8,21.48],[4.3,49.49],[5.8,8.5],[5.3,18.98],[7.6,6.18]],"id":43167167},{"atl":[[65,3.11],[36,3.8],[90,2.24],[46,2.95]],"id":43167167},{"spn":21.8,"spf":"NaN","id":43167167},{"atb":[[4.8,21.48],[4.3,49.49],[5.8,8.5],[5.3,18.98],[7.6,6.18]],"id":43167168},{"atl":[[65,3.11],[36,3.8],[90,2.24],[46,2.95]],"id":43167168},{"spn":21.8,"spf":"NaN","id":43167168},{"atb":[[1.4,204.15],[1.6,68.05],[1.45,181.47],[1.5,81.66],[1.35,466.64]],"id":41719613},{"atl":[[3.45,81.46],[2.88,70.77],[3.2,90.72],[2.98,67.19]],"id":41719613},{"spn":2.24,"spf":"NaN","id":41719613},{"atb":[[4,27.22],[4.5,23.33],[5,10.2],[6,8.16],[3.75,59.39]],"id":43167169},{"atl":[[19.5,7.19],[38,5.39],[24,5.78],[29,7.12]],"id":43167169},{"spn":12.75,"spf":"NaN","id":43167169},{"atb":[[6.4,15.12],[7.4,6.38],[5.2,38.88],[5.7,17.37],[9.4,4.86]],"id":43167165},{"atl":[[80,1.68],[160,1.25],[55,2.46],[110,1.82]],"id":43167165},{"spn":32.2,"spf":"NaN","id":43167165},{"atb":[[8,5.83],[4.5,46.66],[5,20.41],[5.5,18.14],[6,8.16]],"id":43167170},{"atl":[[75,2.69],[40,3.41],[50,2.71],[100,2.01]],"id":43167170},{"spn":24.0,"spf":"NaN","id":43167170},{"atb":[[4.8,21.48],[4.3,49.49],[5.8,8.5],[5.3,18.98],[7.6,6.18]],"id":43016477},{"atl":[[65,3.11],[36,3.8],[90,2.24],[46,2.95]],"id":43016477},{"spn":21.8,"spf":"NaN","id":43016477}],"con":true,"img":true}]}
{"op":"mcm","clk":"5346768017","pt":1646187402736,"mc":[{"id":"1.195453609","marketDefinition":{"bspMarket":true,"turnInPlayEnabled":false,"persistenceEnabled":false,"marketBaseRate":7.0,"eventId":"31272494","eventTypeId":"4339","numberOfWinners":1,"bettingType":"ODDS","marketType":"WIN","marketTime":"2022-03-02T08:31:00.000Z","suspendTime":"2022-03-02T08:31:00.000Z","bspReconciled":false,"complete":true,"inPlay":false,"crossMatching":false,"runnersVoidable":false,"numberOfActiveRunners":8,"betDelay":0,"status":"OPEN","runners":[{"status":"ACTIVE","sortPriority":1,"id":41719613,"name":"1. Gotham Prince"},{"status":"ACTIVE","sortPriority":2,"id":43167165,"name":"2. Bit Shakey"},{"status":"ACTIVE","sortPriority":3,"id":43167166,"name":"3. Dolly Dagger"},{"status":"ACTIVE","sortPriority":4,"id":43167167,"name":"4. Wild Apache"},{"status":"ACTIVE","sortPriority":5,"id":43167168,"name":"5. My Mate Sid"},{"status":"ACTIVE","sortPriority":6,"id":43167169,"name":"6. Flight Chaser"},{"status":"ACTIVE","sortPriority":7,"id":43167170,"name":"7. Dr Bambi"},{"status":"ACTIVE","sortPriority":8,"id":43016477,"name":"8. Before Noon"}],"regulators":["MR_INT"],"venue":"Traralgon","countryCode":"AU","discountAllowed":true,"timezone":"Australia/Sydney","openDate":"2022-03-02T08:31:00.000Z","version":4382425357,"name":"R1 350m Mdn","eventName":"Traralgon (AUS) 2nd Mar"},"rc":[{"atb":[[4.8,21.52],[4.3,49.57],[5.8,8.52],[5.3,19.01],[7.6,6.19]],"id":43167166},{"atl":[[65,3.12],[36,3.8],[90,2.24],[46,2.96]],"id":43167166},{"spn":21.8,"spf":"NaN","id":43167166},{"atb":[[4.8,21.52],[4.3,49.57],[5.8,8.52],[5.3,19.01],[7.6,6.19]],"id":43167167},{"atl":[[65,3.12],[36,3.8],[90,2.24],[46,2.96]],"id":43167167},{"spn":21.8,"spf":"NaN","id":43167167},{"atb":[[4.8,21.52],[4.3,49.57],[5.8,8.52],[5.3,19.01],[7.6,6.19]],"id":43167168},{"atl":[[65,3.12],[36,3.8],[90,2.24],[46,2.96]],"id":43167168},{"spn":21.8,"spf":"NaN","id":43167168},{"atb":[[1.4,204.48],[1.6,68.16],[1.45,181.76],[1.5,81.79],[1.35,467.38]],"id":41719613},{"atl":[[3.45,81.59],[2.88,70.88],[3.2,90.86],[2.98,67.3]],"id":41719613},{"spn":2.24,"spf":"NaN","id":41719613},{"atb":[[4,27.26],[4.5,23.37],[5,10.22],[6,8.17],[3.75,59.48]],"id":43167169},{"atl":[[19.5,7.2],[38,5.4],[24,5.79],[29,7.13]],"id":43167169},{"spn":12.75,"spf":"NaN","id":43167169},{"atb":[[6.4,15.14],[7.4,6.39],[5.2,38.94],[5.7,17.4],[9.4,4.86]],"id":43167165},{"atl":[[80,1.68],[160,1.25],[55,2.47],[110,1.83]],"id":43167165},{"spn":32.2,"spf":"NaN","id":43167165},{"atb":[[8,5.84],[4.5,46.73],[5,20.44],[5.5,18.17],[6,8.17]],"id":43167170},{"atl":[[75,2.69],[40,3.41],[50,2.72],[100,2.01]],"id":43167170},{"spn":24.0,"spf":"NaN","id":43167170},{"atb":[[4.8,21.52],[4.3,49.57],[5.8,8.52],[5.3,19.01],[7.6,6.19]],"id":43016477},{"atl":[[65,3.12],[36,3.8],[90,2.24],[46,2.96]],"id":43016477},{"spn":21.8,"spf":"NaN","id":43016477}],"con":true,"img":true}]}
{"op":"mcm","clk":"5346929302","pt":1646190101170,"mc":[{"id":"1.195453609","rc":[{"atb":[[4.8,21.55],[4.3,49.65],[5.8,8.53],[5.3,19.05],[7.6,6.2]],"id":43167166},{"atl":[[65,3.12],[36,3.81],[90,2.25],[46,2.96]],"id":43167166},{"atb":[[4.8,21.55],[4.3,49.65],[5.8,8.53],[5.3,19.05],[7.6,6.2]],"id":43167167},{"atl":[[65,3.12],[36,3.81],[90,2.25],[46,2.96]],"id":43167167},{"atb":[[4.8,21.55],[4.3,49.65],[5.8,8.53],[5.3,19.05],[7.6,6.2]],"id":43167168},{"atl":[[65,3.12],[36,3.81],[90,2.25],[46,2.96]],"id":43167168},{"atb":[[1.4,204.82],[1.6,68.27],[1.45,182.06],[1.5,81.93],[1.35,468.17]],"id":41719613},{"atl":[[3.45,81.72],[2.88,79.2],[3.2,91.02],[2.98,67.41]],"id":41719613},{"atb":[[4,27.31],[4.5,23.41],[5,10.24],[6,8.19],[3.75,59.58]],"id":43167169},{"atl":[[19.5,7.21],[38,5.41],[24,5.8],[29,7.14]],"id":43167169},{"atb":[[6.4,15.17],[7.4,6.4],[5.2,39.01],[5.7,17.42],[9.4,4.87]],"id":43167165},{"atl":[[80,1.68],[160,1.26],[55,2.47],[110,1.83]],"id":43167165},{"atb":[[8,5.84],[4.5,46.81],[5,20.48],[5.5,18.2],[6,8.19]],"id":43167170},{"atl":[[75,2.7],[40,3.42],[50,2.72],[100,2.02]],"id":43167170},{"atb":[[4.8,21.55],[4.3,49.65],[5.8,8.53],[5.3,19.05],[7.6,6.2]],"id":43016477},{"atl":[[65,3.12],[36,3.81],[90,2.25],[46,2.96]],"id":43016477}],"con":true,"img":false}]}
{"op":"mcm","clk":"5347325433","pt":1646197078711,"mc":[{"id":"1.195453609","rc":[{"atl":[[1.9,6.19]],"id":41719613},{"spn":1.75,"spf":"NaN","id":41719613}],"con":true,"img":false}]}
{"op":"mcm","clk":"5347325625","pt":1646197083690,"mc":[{"id":"1.195453609","rc":[{"atl":[[2.2,6.19]],"id":41719613}],"con":true,"img":false}]}
{"op":"mcm","clk":"5347374824","pt":1646198201427,"mc":[{"id":"1.195453609","rc":[{"atb":[[4.8,21.55],[4.3,49.63],[5.8,8.53],[5.3,19.04],[7.6,6.2]],"id":43167166},{"atl":[[65,3.12],[36,3.81],[90,2.24],[46,2.96]],"id":43167166},{"atb":[[4.8,21.55],[4.3,49.63],[5.8,8.53],[5.3,19.04],[7.6,6.2]],"id":43167167},{"atl":[[65,3.12],[36,3.81],[90,2.24],[46,2.96]],"id":43167167},{"atb":[[1.4,204.75],[1.6,68.25],[1.45,181.99],[1.5,81.9],[1.35,467.99]],"id":41719613},{"atl":[[3.45,81.69],[2.88,70.98],[3.2,90.98],[1.9,6.2],[2.98,67.39],[2.2,6.2]],"id":41719613},{"atb":[[4.8,21.55],[4.3,49.63],[5.8,8.53],[5.3,19.04],[7.6,6.2]],"id":43167168},{"atl":[[65,3.12],[36,3.81],[90,2.24],[46,2.96]],"id":43167168},{"atb":[[4,27.3],[4.5,23.4],[5,10.23],[6,8.19],[3.75,59.56]],"id":43167169},{"atl":[[19.5,7.21],[38,5.41],[24,5.8],[29,7.14]],"id":43167169},{"atb":[[6.4,15.16],[7.4,6.39],[5.2,39],[5.7,17.42],[9.4,4.87]],"id":43167165},{"atl":[[80,1.68],[160,1.26],[55,2.47],[110,1.83]],"id":43167165},{"atb":[[8,5.84],[4.5,46.79],[5,20.47],[5.5,18.19],[6,8.19]],"id":43167170},{"atl":[[75,2.7],[40,3.42],[50,2.72],[100,2.02]],"id":43167170},{"atb":[[4.8,21.55],[4.3,49.63],[5.8,8.53],[5.3,19.04],[7.6,6.2]],"id":43016477},{"atl":[[65,3.12],[36,3.81],[90,2.24],[46,2.96]],"id":43016477}],"con":true,"img":false}]}
{"op":"mcm","clk":"5347374828","pt":1646198201528,"mc":[{"id":"1.195453609","rc":[{"atl":[[2.8,8.19]],"id":41719613}],"con":true,"img":false}]}
{"op":"mcm","clk":"5347396356","pt":1646198501514,"mc":[{"id":"1.195453609","rc":[{"atl":[[2.8,0]],"id":41719613}],"con":true,"img":false}]}
{"op":"mcm","clk":"5347396359","pt":1646198501566,"mc":[{"id":"1.195453609","rc":[{"atl":[[2.64,8.19]],"id":41719613}],"con":true,"img":false}]}
{"op":"mcm","clk":"5347506909","pt":1646200887075,"mc":[{"id":"1.195453609","rc":[{"atb":[[1.01,2.25]],"id":43167166},{"atb":[[1.01,2.25]],"id":43167167},{"atb":[[1.62,13.32]],"id":41719613},{"spn":1.76,"spf":"NaN","id":41719613},{"atb":[[1.01,2.25]],"id":43167168},{"atb":[[4.6,2.29]],"id":43167169},{"atb":[[1.01,2.25]],"id":43167165},{"atb":[[1.01,2.25]],"id":43167170},{"atb":[[1.01,2.25]],"id":43016477}],"con":true,"img":false}]}
{"op":"mcm","clk":"5347506913","pt":1646200887128,"mc":[{"id":"1.195453609","rc":[{"atb":[[1.01,1.87]],"id":43167166},{"atb":[[1.01,1.87]],"id":43167167},{"atb":[[1.01,1.87]],"id":43167168},{"atb":[[1.01,1.47]],"id":43167165},{"atb":[[1.01,1.79]],"id":43167170},{"atb":[[1.01,1.87]],"id":43016477}],"con":true,"img":false}]}
{"op":"mcm","clk":"5347506923","pt":1646200887332,"mc":[{"id":"1.195453609","rc":[{"atb":[[1.01,0]],"id":43167168}],"con":true,"img":false}]}
{"op":"mcm","clk":"5347506926","pt":1646200887434,"mc":[{"id":"1.195453609","rc":[{"atb":[[5.4,1.87]],"id":43167168}],"con":true,"img":false}]}
{"op":"mcm","clk":"5347506936","pt":1646200887640,"mc":[{"id":"1.195453609","rc":[{"atb":[[1.01,0]],"id":43167166}],"con":true,"img":false}]}
{"op":"mcm","clk":"5347506941","pt":1646200887745,"mc":[{"id":"1.195453609","rc":[{"atb":[[5.4,1.87]],"id":43167166}],"con":true,"img":false}]}
{"op":"mcm","clk":"5347506949","pt":1646200887949,"mc":[{"id":"1.195453609","rc":[{"atb":[[1.01,0]],"id":43016477}],"con":true,"img":false}]}
{"op":"mcm","clk":"5347506953","pt":1646200888050,"mc":[{"id":"1.195453609","rc":[{"atb":[[5.4,1.87]],"id":43016477}],"con":true,"img":false}]}
{"op":"mcm","clk":"5347506958","pt":1646200888155,"mc":[{"id":"1.195453609","rc":[{"atb":[[1.01,0]],"id":43167170}],"con":true,"img":false}]}
{"op":"mcm","clk":"5347506963","pt":1646200888257,"mc":[{"id":"1.195453609","rc":[{"atb":[[5.6,1.79]],"id":43167170}],"con":true,"img":false}]}
{"op":"mcm","clk":"5347506970","pt":1646200888360,"mc":[{"id":"1.195453609","rc":[{"atb":[[1.01,0]],"id":43167165}],"con":true,"img":false}]}
{"op":"mcm","clk":"5347506975","pt":1646200888462,"mc":[{"id":"1.195453609","rc":[{"atb":[[6.6,1.47]],"id":43167165}],"con":true,"img":false}]}
{"op":"mcm","clk":"5347506984","pt":1646200888667,"mc":[{"id":"1.195453609","rc":[{"atb":[[1.01,0]],"id":43167167}],"con":true,"img":false}]}
{"op":"mcm","clk":"5347506993","pt":1646200888771,"mc":[{"id":"1.195453609","rc":[{"atb":[[5.4,1.87]],"id":43167167}],"con":true,"img":false}]}
{"op":"mcm","clk":"5347508412","pt":1646200919318,"mc":[{"id":"1.195453609","marketDefinition":{"bspMarket":true,"turnInPlayEnabled":false,"persistenceEnabled":false,"marketBaseRate":7.0,"eventId":"31272494","eventTypeId":"4339","numberOfWinners":1,"bettingType":"ODDS","marketType":"WIN","marketTime":"2022-03-02T08:31:00.000Z","suspendTime":"2022-03-02T08:31:00.000Z","bspReconciled":false,"complete":true,"inPlay":false,"crossMatching":true,"runnersVoidable":false,"numberOfActiveRunners":8,"betDelay":0,"status":"OPEN","runners":[{"status":"ACTIVE","sortPriority":1,"id":41719613,"name":"1. Gotham Prince"},{"status":"ACTIVE","sortPriority":2,"id":43167165,"name":"2. Bit Shakey"},{"status":"ACTIVE","sortPriority":3,"id":43167166,"name":"3. Dolly Dagger"},{"status":"ACTIVE","sortPriority":4,"id":43167167,"name":"4. Wild Apache"},{"status":"ACTIVE","sortPriority":5,"id":43167168,"name":"5. My Mate Sid"},{"status":"ACTIVE","sortPriority":6,"id":43167169,"name":"6. Flight Chaser"},{"status":"ACTIVE","sortPriority":7,"id":43167170,"name":"7. Dr Bambi"},{"status":"ACTIVE","sortPriority":8,"id":43016477,"name":"8. Before Noon"}],"regulators":["MR_INT"],"venue":"Traralgon","countryCode":"AU","discountAllowed":true,"timezone":"Australia/Sydney","openDate":"2022-03-02T08:31:00.000Z","version":4382425357,"name":"R1 350m Mdn","eventName":"Traralgon (AUS) 2nd Mar"},"rc":[],"con":true,"img":false}]}
{"op":"mcm","clk":"5347510547","pt":1646200961529,"mc":[{"id":"1.195453609","rc":[{"atb":[[6.6,3.29]],"id":43167165}],"con":true,"img":false}]}
{"op":"mcm","clk":"5347510553","pt":1646200961633,"mc":[{"id":"1.195453609","rc":[{"atb":[[1.62,29.63]],"id":41719613}],"con":true,"img":false}]}
{"op":"mcm","clk":"5347510559","pt":1646200961836,"mc":[{"id":"1.195453609","rc":[{"atb":[[5.4,4.17]],"id":43167167}],"con":true,"img":false}]}
{"op":"mcm","clk":"5347510564","pt":1646200961938,"mc":[{"id":"1.195453609","rc":[{"atb":[[5.4,4.17]],"id":43016477}],"con":true,"img":false}]}
{"op":"mcm","clk":"5347510577","pt":1646200962245,"mc":[{"id":"1.195453609","rc":[{"atb":[[5.4,4.17]],"id":43167166}],"con":true,"img":false}]}
{"op":"mcm","clk":"5347510581","pt":1646200962347,"mc":[{"id":"1.195453609","rc":[{"atb":[[4.6,5.1]],"id":43167169}],"con":true,"img":false}]}
{"op":"mcm","clk":"5347510604","pt":1646200962859,"mc":[{"id":"1.195453609","rc":[{"atb":[[5.4,4.17]],"id":43167168}],"con":true,"img":false}]}
{"op":"mcm","clk":"5347510616","pt":1646200963168,"mc":[{"id":"1.195453609","rc":[{"atb":[[5.6,3.99]],"id":43167170}],"con":true,"img":false}]}
{"op":"mcm","clk":"5347580291","pt":1646202660152,"mc":[{"id":"1.195453609","rc":[{"atb":[[9,1.26]],"id":43167166},{"spn":22.5,"spf":"NaN","id":43167166},{"atb":[[9.2,1.23]],"id":43167167},{"spn":22.6,"spf":"NaN","id":43167167},{"atb":[[9,1.26]],"id":43167168},{"spn":22.5,"spf":"NaN","id":43167168},{"atb":[[1.56,2]],"id":41719613},{"atb":[[8.2,1.4]],"id":43167169},{"spn":13.85,"spf":"NaN","id":43167169},{"atb":[[12.5,0.88]],"id":43167165},{"spn":33.75,"spf":"NaN","id":43167165},{"atb":[[9.8,1.15]],"id":43167170},{"spn":24.9,"spf":"NaN","id":43167170},{"atb":[[9.2,1.23]],"id":43016477},{"spn":22.6,"spf":"NaN","id":43016477}],"con":true,"img":false}]}
{"op":"mcm","clk":"5347584232","pt":1646202743074,"mc":[{"id":"1.195453609","rc":[{"atb":[[5.9,8.09]],"id":43167166}],"con":true,"img":false}]}
{"op":"mcm","clk":"5347584240","pt":1646202743280,"mc":[{"id":"1.195453609","rc":[{"atb":[[5.9,8.09]],"id":43167167}],"con":true,"img":false}]}
{"op":"mcm","clk":"5347584246","pt":1646202743485,"mc":[{"id":"1.195453609","rc":[{"atb":[[5.9,8.09]],"id":43167168}],"con":true,"img":false}]}
{"op":"mcm","clk":"5347584253","pt":1646202743640,"mc":[{"id":"1.195453609","rc":[{"atb":[[5.1,9.57]],"id":43167169}],"con":true,"img":false}]}
{"op":"mcm","clk":"5347586862","pt":1646202805647,"mc":[{"id":"1.195453609","rc":[{"atb":[[5.9,0]],"id":43167166}],"con":true,"img":false}]}
{"op":"mcm","clk":"5347586869","pt":1646202805852,"mc":[{"id":"1.195453609","rc":[{"atb":[[5.5,8.79]],"id":43167166}],"con":true,"img":false}]}
{"op":"mcm","clk":"5347587164","pt":1646202813151,"mc":[{"id":"1.195453609","rc":[{"atb":[[5.9,0]],"id":43167168}],"con":true,"img":false}]}
{"op":"mcm","clk":"5347587173","pt":1646202813358,"mc":[{"id":"1.195453609","rc":[{"atb":[[5.5,8.79]],"id":43167168}],"con":true,"img":false}]}
{"op":"mcm","clk":"5347589250","pt":1646202866317,"mc":[{"id":"1.195453609","rc":[{"atb":[[5.5,0]],"id":43167166}],"con":true,"img":false}]}
{"op":"mcm","clk":"5347589260","pt":1646202866520,"mc":[{"id":"1.195453609","rc":[{"atb":[[6,7.86]],"id":43167166}],"con":true,"img":false}]}
{"op":"mcm","clk":"5347589519","pt":1646202872800,"mc":[{"id":"1.195453609","rc":[{"atb":[[5.9,0]],"id":43167167}],"con":true,"img":false}]}
{"op":"mcm","clk":"5347589527","pt":1646202873005,"mc":[{"id":"1.195453609","rc":[{"atb":[[5.5,8.79]],"id":43167167}],"con":true,"img":false}]}
{"op":"mcm","clk":"5347589604","pt":1646202874850,"mc":[{"id":"1.195453609","rc":[{"atb":[[5.5,0]],"id":43167168}],"con":true,"img":false}]}
{"op":"mcm","clk":"5347589613","pt":1646202875003,"mc":[{"id":"1.195453609","rc":[{"atb":[[5.9,8.09]],"id":43167168}],"con":true,"img":false}]}
{"op":"mcm","clk":"5347592304","pt":1646202926875,"mc":[{"id":"1.195453609","rc":[{"atb":[[6,0]],"id":43167166}],"con":true,"img":false}]}
{"op":"mcm","clk":"5347592315","pt":1646202927087,"mc":[{"id":"1.195453609","rc":[{"atb":[[5.5,8.79]],"id":43167166}],"con":true,"img":false}]}
{"op":"mcm","clk":"5347592712","pt":1646202934039,"mc":[{"id":"1.195453609","rc":[{"atb":[[5.5,0]],"id":43167167}],"con":true,"img":false}]}
{"op":"mcm","clk":"5347592725","pt":1646202934193,"mc":[{"id":"1.195453609","rc":[{"atb":[[6,7.86]],"id":43167167}],"con":true,"img":false}]}
{"op":"mcm","clk":"5347592794","pt":1646202935378,"mc":[{"id":"1.195453609","rc":[{"atb":[[5.9,0]],"id":43167168}],"con":true,"img":false}]}
{"op":"mcm","clk":"5347592805","pt":1646202935582,"mc":[{"id":"1.195453609","rc":[{"atb":[[5.5,8.79]],"id":43167168}],"con":true,"img":false}]}
{"op":"mcm","clk":"5347595811","pt":1646202987748,"mc":[{"id":"1.195453609","rc":[{"atb":[[5.5,0]],"id":43167166}],"con":true,"img":false}]}
{"op":"mcm","clk":"5347595823","pt":1646202987953,"mc":[{"id":"1.195453609","rc":[{"atb":[[5.9,8.09]],"id":43167166}],"con":true,"img":false}]}
{"op":"mcm","clk":"5347596182","pt":1646202994801,"mc":[{"id":"1.195453609","rc":[{"atb":[[6,0]],"id":43167167}],"con":true,"img":false}]}
{"op":"mcm","clk":"5347596193","pt":1646202994956,"mc":[{"id":"1.195453609","rc":[{"atb":[[5.5,8.79]],"id":43167167}],"con":true,"img":false}]}
{"op":"mcm","clk":"5347596246","pt":1646202996088,"mc":[{"id":"1.195453609","rc":[{"atb":[[5.5,0]],"id":43167168}],"con":true,"img":false}]}
{"op":"mcm","clk":"5347596255","pt":1646202996191,"mc":[{"id":"1.195453609","rc":[{"atb":[[5.9,8.09]],"id":43167168}],"con":true,"img":false}]}
{"op":"mcm","clk":"5347599058","pt":1646203055363,"mc":[{"id":"1.195453609","rc":[{"atb":[[5.5,0]],"id":43167167}],"con":true,"img":false}]}
{"op":"mcm","clk":"5347599066","pt":1646203055568,"mc":[{"id":"1.195453609","rc":[{"atb":[[6.2,7.63]],"id":43167167}],"con":true,"img":false}]}
{"op":"mcm","clk":"5347601276","pt":1646203109238,"mc":[{"id":"1.195453609","rc":[{"atb":[[5.9,0]],"id":43167166}],"con":true,"img":false}]}
{"op":"mcm","clk":"5347601284","pt":1646203109440,"mc":[{"id":"1.195453609","rc":[{"atb":[[5.5,8.79]],"id":43167166}],"con":true,"img":false}]}
{"op":"mcm","clk":"5347601594","pt":1646203117569,"mc":[{"id":"1.195453609","rc":[{"atb":[[5.9,0]],"id":43167168}],"con":true,"img":false}]}
{"op":"mcm","clk":"5347601603","pt":1646203117778,"mc":[{"id":"1.195453609","rc":[{"atb":[[5.5,8.79]],"id":43167168}],"con":true,"img":false}]}
{"op":"mcm","clk":"5347603694","pt":1646203169907,"mc":[{"id":"1.195453609","rc":[{"atb":[[5.5,0]],"id":43167166}],"con":true,"img":false}]}
{"op":"mcm","clk":"5347603703","pt":1646203170112,"mc":[{"id":"1.195453609","rc":[{"atb":[[6,7.86]],"id":43167166}],"con":true,"img":false}]}
{"op":"mcm","clk":"5347604037","pt":1646203176829,"mc":[{"id":"1.195453609","rc":[{"atb":[[6.2,0]],"id":43167167}],"con":true,"img":false}]}
{"op":"mcm","clk":"5347604051","pt":1646203177036,"mc":[{"id":"1.195453609","rc":[{"atb":[[5.5,8.79]],"id":43167167}],"con":true,"img":false}]}
{"op":"mcm","clk":"5347604123","pt":1646203178424,"mc":[{"id":"1.195453609","rc":[{"atb":[[5.5,0]],"id":43167168}],"con":true,"img":false}]}
{"op":"mcm","clk":"5347604130","pt":1646203178632,"mc":[{"id":"1.195453609","rc":[{"atb":[[6,7.86]],"id":43167168}],"con":true,"img":false}]}
{"op":"mcm","clk":"5347606433","pt":1646203230696,"mc":[{"id":"1.195453609","rc":[{"atb":[[6,0]],"id":43167166}],"con":true,"img":false}]}
{"op":"mcm","clk":"5347606440","pt":1646203230901,"mc":[{"id":"1.195453609","rc":[{"atb":[[5.5,8.79]],"id":43167166}],"con":true,"img":false}]}
{"op":"mcm","clk":"5347606710","pt":1646203237529,"mc":[{"id":"1.195453609","rc":[{"atb":[[5.5,0]],"id":43167167}],"con":true,"img":false}]}
{"op":"mcm","clk":"5347606718","pt":1646203237734,"mc":[{"id":"1.195453609","rc":[{"atb":[[6.4,7.31]],"id":43167167}],"con":true,"img":false}]}
{"op":"mcm","clk":"5347606785","pt":1646203239422,"mc":[{"id":"1.195453609","rc":[{"atb":[[6,0]],"id":43167168}],"con":true,"img":false}]}
{"op":"mcm","clk":"5347606792","pt":1646203239627,"mc":[{"id":"1.195453609","rc":[{"atb":[[5.9,8.09]],"id":43167168}],"con":true,"img":false}]}
{"op":"mcm","clk":"5347608948","pt":1646203291613,"mc":[{"id":"1.195453609","rc":[{"atb":[[5.5,0]],"id":43167166}],"con":true,"img":false}]}
{"op":"mcm","clk":"5347608956","pt":1646203291819,"mc":[{"id":"1.195453609","rc":[{"atb":[[5.9,8.09]],"id":43167166}],"con":true,"img":false}]}
{"op":"mcm","clk":"5347609267","pt":1646203300327,"mc":[{"id":"1.195453609","rc":[{"atb":[[5.9,0]],"id":43167168}],"con":true,"img":false}]}
{"op":"mcm","clk":"5347609273","pt":1646203300531,"mc":[{"id":"1.195453609","rc":[{"atb":[[6.2,7.63]],"id":43167168}],"con":true,"img":false}]}
{"op":"mcm","clk":"5347611087","pt":1646203358879,"mc":[{"id":"1.195453609","rc":[{"atb":[[6.4,0]],"id":43167167}],"con":true,"img":false}]}
{"op":"mcm","clk":"5347611094","pt":1646203359084,"mc":[{"id":"1.195453609","rc":[{"atb":[[5.5,8.79]],"id":43167167}],"con":true,"img":false}]}
{"op":"mcm","clk":"5347611136","pt":1646203361287,"mc":[{"id":"1.195453609","rc":[{"atb":[[6.2,0]],"id":43167168}],"con":true,"img":false}]}
{"op":"mcm","clk":"5347611142","pt":1646203361496,"mc":[{"id":"1.195453609","rc":[{"atb":[[5.5,8.79]],"id":43167168}],"con":true,"img":false}]}
{"op":"mcm","clk":"5347612496","pt":1646203413178,"mc":[{"id":"1.195453609","rc":[{"atb":[[5.9,0]],"id":43167166}],"con":true,"img":false}]}
{"op":"mcm","clk":"5347612500","pt":1646203413383,"mc":[{"id":"1.195453609","rc":[{"atb":[[5.5,8.79]],"id":43167166}],"con":true,"img":false}]}
{"op":"mcm","clk":"5347612668","pt":1646203419909,"mc":[{"id":"1.195453609","rc":[{"atb":[[5.5,0]],"id":43167167}],"con":true,"img":false}]}
{"op":"mcm","clk":"5347612671","pt":1646203420059,"mc":[{"id":"1.195453609","rc":[{"atb":[[5.9,8.09]],"id":43167167}],"con":true,"img":false}]}
{"op":"mcm","clk":"5347612715","pt":1646203421908,"mc":[{"id":"1.195453609","rc":[{"atb":[[5.5,0]],"id":43167168}],"con":true,"img":false}]}
{"op":"mcm","clk":"5347612720","pt":1646203422061,"mc":[{"id":"1.195453609","rc":[{"atb":[[6.4,7.31]],"id":43167168}],"con":true,"img":false}]}
{"op":"mcm","clk":"5347614128","pt":1646203473872,"mc":[{"id":"1.195453609","rc":[{"atb":[[5.5,0]],"id":43167166}],"con":true,"img":false}]}
{"op":"mcm","clk":"5347614141","pt":1646203474060,"mc":[{"id":"1.195453609","rc":[{"atb":[[5.9,8.09]],"id":43167166}],"con":true,"img":false}]}
{"op":"mcm","clk":"5347614358","pt":1646203480851,"mc":[{"id":"1.195453609","rc":[{"atb":[[5.9,0]],"id":43167167}],"con":true,"img":false}]}
{"op":"mcm","clk":"5347614369","pt":1646203481051,"mc":[{"id":"1.195453609","rc":[{"atb":[[6.6,7.08]],"id":43167167}],"con":true,"img":false}]}
{"op":"mcm","clk":"5347615984","pt":1646203534967,"mc":[{"id":"1.195453609","rc":[{"atb":[[5.9,0]],"id":43167166}],"con":true,"img":false}]}
{"op":"mcm","clk":"5347615989","pt":1646203535120,"mc":[{"id":"1.195453609","rc":[{"atb":[[5.5,8.79]],"id":43167166}],"con":true,"img":false}]}
{"op":"mcm","clk":"5347616146","pt":1646203541328,"mc":[{"id":"1.195453609","rc":[{"atb":[[6.6,0]],"id":43167167}],"con":true,"img":false}]}
{"op":"mcm","clk":"5347616149","pt":1646203541532,"mc":[{"id":"1.195453609","rc":[{"atb":[[5.9,8.09]],"id":43167167}],"con":true,"img":false}]}
{"op":"mcm","clk":"5347616184","pt":1646203543224,"mc":[{"id":"1.195453609","rc":[{"atb":[[6.4,0]],"id":43167168}],"con":true,"img":false}]}
{"op":"mcm","clk":"5347616189","pt":1646203543430,"mc":[{"id":"1.195453609","rc":[{"atb":[[5.5,8.79]],"id":43167168}],"con":true,"img":false}]}
{"op":"mcm","clk":"5347617789","pt":1646203595530,"mc":[{"id":"1.195453609","rc":[{"atb":[[5.5,0]],"id":43167166}],"con":true,"img":false}]}
{"op":"mcm","clk":"5347617798","pt":1646203595735,"mc":[{"id":"1.195453609","rc":[{"atb":[[5.9,8.09]],"id":43167166}],"con":true,"img":false}]}
{"op":"mcm","clk":"5347617947","pt":1646203601935,"mc":[{"id":"1.195453609","rc":[{"atb":[[5.9,0]],"id":43167167}],"con":true,"img":false}]}
{"op":"mcm","clk":"5347617951","pt":1646203602140,"mc":[{"id":"1.195453609","rc":[{"atb":[[6.8,6.85]],"id":43167167}],"con":true,"img":false}]}
{"op":"mcm","clk":"5347626406","pt":1646203604151,"mc":[{"id":"1.195453609","rc":[{"atb":[[5.5,0]],"id":43167168}],"con":true,"img":false}]}
{"op":"mcm","clk":"5347626411","pt":1646203604355,"mc":[{"id":"1.195453609","rc":[{"atb":[[6.6,7.08]],"id":43167168}],"con":true,"img":false}]}
{"op":"mcm","clk":"5347627908","pt":1646203656452,"mc":[{"id":"1.195453609","rc":[{"atb":[[5.9,0]],"id":43167166}],"con":true,"img":false}]}
{"op":"mcm","clk":"5347627911","pt":1646203656605,"mc":[{"id":"1.195453609","rc":[{"atb":[[5.5,8.79]],"id":43167166}],"con":true,"img":false}]}
{"op":"mcm","clk":"5347628080","pt":1646203662551,"mc":[{"id":"1.195453609","rc":[{"atb":[[6.8,0]],"id":43167167}],"con":true,"img":false}]}
{"op":"mcm","clk":"5347628085","pt":1646203662756,"mc":[{"id":"1.195453609","rc":[{"atb":[[5.5,8.79]],"id":43167167}],"con":true,"img":false}]}
{"op":"mcm","clk":"5347629859","pt":1646203717226,"mc":[{"id":"1.195453609","rc":[{"atb":[[5.5,0]],"id":43167166}],"con":true,"img":false}]}
{"op":"mcm","clk":"5347629862","pt":1646203717430,"mc":[{"id":"1.195453609","rc":[{"atb":[[6,7.86]],"id":43167166}],"con":true,"img":false}]}
{"op":"mcm","clk":"5347630018","pt":1646203723209,"mc":[{"id":"1.195453609","rc":[{"atb":[[5.5,0]],"id":43167167}],"con":true,"img":false}]}
{"op":"mcm","clk":"5347630022","pt":1646203723413,"mc":[{"id":"1.195453609","rc":[{"atb":[[6,7.86]],"id":43167167}],"con":true,"img":false}]}
{"op":"mcm","clk":"5347630064","pt":1646203725405,"mc":[{"id":"1.195453609","rc":[{"atb":[[6.6,0]],"id":43167168}],"con":true,"img":false}]}
{"op":"mcm","clk":"5347630066","pt":1646203725507,"mc":[{"id":"1.195453609","rc":[{"atb":[[5.9,8.09]],"id":43167168}],"con":true,"img":false}]}
{"op":"mcm","clk":"5347631211","pt":1646203778012,"mc":[{"id":"1.195453609","rc":[{"atb":[[6,0]],"id":43167166}],"con":true,"img":false}]}
{"op":"mcm","clk":"5347631218","pt":1646203778216,"mc":[{"id":"1.195453609","rc":[{"atb":[[5.5,8.79]],"id":43167166}],"con":true,"img":false}]}
{"op":"mcm","clk":"5347631352","pt":1646203784126,"mc":[{"id":"1.195453609","rc":[{"atb":[[6,0]],"id":43167167}],"con":true,"img":false}]}
{"op":"mcm","clk":"5347631356","pt":1646203784337,"mc":[{"id":"1.195453609","rc":[{"atb":[[5.5,8.79]],"id":43167167}],"con":true,"img":false}]}
{"op":"mcm","clk":"5347631394","pt":1646203786125,"mc":[{"id":"1.195453609","rc":[{"atb":[[5.9,0]],"id":43167168}],"con":true,"img":false}]}
{"op":"mcm","clk":"5347631401","pt":1646203786330,"mc":[{"id":"1.195453609","rc":[{"atb":[[6.8,6.85]],"id":43167168}],"con":true,"img":false}]}
{"op":"mcm","clk":"5347632527","pt":1646203838707,"mc":[{"id":"1.195453609","rc":[{"atb":[[5.5,0]],"id":43167166}],"con":true,"img":false}]}
{"op":"mcm","clk":"5347632538","pt":1646203838909,"mc":[{"id":"1.195453609","rc":[{"atb":[[5.9,8.09]],"id":43167166}],"con":true,"img":false}]}
{"op":"mcm","clk":"5347632696","pt":1646203845287,"mc":[{"id":"1.195453609","rc":[{"atb":[[5.5,0]],"id":43167167}],"con":true,"img":false}]}
{"op":"mcm","clk":"5347632699","pt":1646203845493,"mc":[{"id":"1.195453609","rc":[{"atb":[[6.2,7.63]],"id":43167167}],"con":true,"img":false}]}
{"op":"mcm","clk":"5347633832","pt":1646203899790,"mc":[{"id":"1.195453609","rc":[{"atb":[[5.9,0]],"id":43167166}],"con":true,"img":false}]}
{"op":"mcm","clk":"5347633837","pt":1646203899994,"mc":[{"id":"1.195453609","rc":[{"atb":[[6.2,7.63]],"id":43167166}],"con":true,"img":false}]}
{"op":"mcm","clk":"5347634032","pt":1646203907292,"mc":[{"id":"1.195453609","rc":[{"atb":[[6.8,0]],"id":43167168}],"con":true,"img":false}]}
{"op":"mcm","clk":"5347634037","pt":1646203907497,"mc":[{"id":"1.195453609","rc":[{"atb":[[5.5,8.79]],"id":43167168}],"con":true,"img":false}]}
{"op":"mcm","clk":"5347635798","pt":1646203960341,"mc":[{"id":"1.195453609","rc":[{"atb":[[6.2,0]],"id":43167166}],"con":true,"img":false}]}
{"op":"mcm","clk":"5347635806","pt":1646203960544,"mc":[{"id":"1.195453609","rc":[{"atb":[[5.9,8.09]],"id":43167166}],"con":true,"img":false}]}
{"op":"mcm","clk":"5347636012","pt":1646203966674,"mc":[{"id":"1.195453609","rc":[{"atb":[[6.2,0]],"id":43167167}],"con":true,"img":false}]}
{"op":"mcm","clk":"5347636023","pt":1646203966876,"mc":[{"id":"1.195453609","rc":[{"atb":[[5.5,8.79]],"id":43167167}],"con":true,"img":false}]}
{"op":"mcm","clk":"5347636068","pt":1646203968067,"mc":[{"id":"1.195453609","rc":[{"atb":[[5.5,0]],"id":43167168}],"con":true,"img":false}]}
{"op":"mcm","clk":"5347636075","pt":1646203968269,"mc":[{"id":"1.195453609","rc":[{"atb":[[7,6.61]],"id":43167168}],"con":true,"img":false}]}
{"op":"mcm","clk":"5347637928","pt":1646204020919,"mc":[{"id":"1.195453609","rc":[{"atb":[[5.9,0]],"id":43167166}],"con":true,"img":false}]}
{"op":"mcm","clk":"5347637940","pt":1646204021124,"mc":[{"id":"1.195453609","rc":[{"atb":[[6.4,7.31]],"id":43167166}],"con":true,"img":false}]}
{"op":"mcm","clk":"5347638164","pt":1646204027442,"mc":[{"id":"1.195453609","rc":[{"atb":[[5.5,0]],"id":43167167}],"con":true,"img":false}]}
{"op":"mcm","clk":"5347638170","pt":1646204027646,"mc":[{"id":"1.195453609","rc":[{"atb":[[5.9,8.09]],"id":43167167}],"con":true,"img":false}]}
{"op":"mcm","clk":"5347638213","pt":1646204028821,"mc":[{"id":"1.195453609","rc":[{"atb":[[7,0]],"id":43167168}],"con":true,"img":false}]}
{"op":"mcm","clk":"5347638218","pt":1646204029026,"mc":[{"id":"1.195453609","rc":[{"atb":[[5.5,8.79]],"id":43167168}],"con":true,"img":false}]}
{"op":"mcm","clk":"5347639939","pt":1646204081617,"mc":[{"id":"1.195453609","rc":[{"atb":[[6.4,0]],"id":43167166}],"con":true,"img":false}]}
{"op":"mcm","clk":"5347639950","pt":1646204081823,"mc":[{"id":"1.195453609","rc":[{"atb":[[6,7.86]],"id":43167166}],"con":true,"img":false}]}
{"op":"mcm","clk":"5347640214","pt":1646204089540,"mc":[{"id":"1.195453609","rc":[{"atb":[[5.5,0]],"id":43167168}],"con":true,"img":false}]}
{"op":"mcm","clk":"5347640222","pt":1646204089747,"mc":[{"id":"1.195453609","rc":[{"atb":[[7.2,6.38]],"id":43167168}],"con":true,"img":false}]}
{"op":"mcm","clk":"5347642231","pt":1646204148692,"mc":[{"id":"1.195453609","rc":[{"atb":[[5.9,0]],"id":43167167}],"con":true,"img":false}]}
{"op":"mcm","clk":"5347642237","pt":1646204148896,"mc":[{"id":"1.195453609","rc":[{"atb":[[5.5,8.79]],"id":43167167}],"con":true,"img":false}]}
{"op":"mcm","clk":"5347642332","pt":1646204151097,"mc":[{"id":"1.195453609","rc":[{"atb":[[7.2,0]],"id":43167168}],"con":true,"img":false}]}
{"op":"mcm","clk":"5347642342","pt":1646204151303,"mc":[{"id":"1.195453609","rc":[{"atb":[[5.5,8.79]],"id":43167168}],"con":true,"img":false}]}
{"op":"mcm","clk":"5347644190","pt":1646204203064,"mc":[{"id":"1.195453609","rc":[{"atb":[[6,0]],"id":43167166}],"con":true,"img":false}]}
{"op":"mcm","clk":"5347644197","pt":1646204203268,"mc":[{"id":"1.195453609","rc":[{"atb":[[6.6,7.08]],"id":43167166}],"con":true,"img":false}]}
{"op":"mcm","clk":"5347644450","pt":1646204210791,"mc":[{"id":"1.195453609","rc":[{"atb":[[5.5,0]],"id":43167167}],"con":true,"img":false}]}
{"op":"mcm","clk":"5347644454","pt":1646204210995,"mc":[{"id":"1.195453609","rc":[{"atb":[[5.9,8.09]],"id":43167167}],"con":true,"img":false}]}
{"op":"mcm","clk":"5347644465","pt":1646204211200,"mc":[{"id":"1.195453609","rc":[{"atb":[[5.5,0]],"id":43167168}],"con":true,"img":false}]}
{"op":"mcm","clk":"5347644474","pt":1646204211404,"mc":[{"id":"1.195453609","rc":[{"atb":[[5.9,8.09]],"id":43167168}],"con":true,"img":false}]}
{"op":"mcm","clk":"5347646382","pt":1646204263851,"mc":[{"id":"1.195453609","rc":[{"atb":[[6.6,0]],"id":43167166}],"con":true,"img":false}]}
{"op":"mcm","clk":"5347646387","pt":1646204264055,"mc":[{"id":"1.195453609","rc":[{"atb":[[5.5,8.79]],"id":43167166}],"con":true,"img":false}]}
{"op":"mcm","clk":"5347646638","pt":1646204271552,"mc":[{"id":"1.195453609","rc":[{"atb":[[5.9,0]],"id":43167167}],"con":true,"img":false}]}
{"op":"mcm","clk":"5347646647","pt":1646204271758,"mc":[{"id":"1.195453609","rc":[{"atb":[[5.5,8.79]],"id":43167167}],"con":true,"img":false}]}
{"op":"mcm","clk":"5347646655","pt":1646204272064,"mc":[{"id":"1.195453609","rc":[{"atb":[[5.9,0]],"id":43167168}],"con":true,"img":false}]}
{"op":"mcm","clk":"5347646664","pt":1646204272270,"mc":[{"id":"1.195453609","rc":[{"atb":[[5.5,8.79]],"id":43167168}],"con":true,"img":false}]}
{"op":"mcm","clk":"5347648587","pt":1646204324865,"mc":[{"id":"1.195453609","rc":[{"atb":[[5.5,0]],"id":43167166}],"con":true,"img":false}]}
{"op":"mcm","clk":"5347648595","pt":1646204325018,"mc":[{"id":"1.195453609","rc":[{"atb":[[5.9,8.09]],"id":43167166}],"con":true,"img":false}]}
{"op":"mcm","clk":"5347648854","pt":1646204332048,"mc":[{"id":"1.195453609","rc":[{"atb":[[5.5,0]],"id":43167167}],"con":true,"img":false}]}
{"op":"mcm","clk":"5347648864","pt":1646204332253,"mc":[{"id":"1.195453609","rc":[{"atb":[[5.9,8.09]],"id":43167167}],"con":true,"img":false}]}
{"op":"mcm","clk":"5347648874","pt":1646204332560,"mc":[{"id":"1.195453609","rc":[{"atb":[[5.5,0]],"id":43167168}],"con":true,"img":false}]}
{"op":"mcm","clk":"5347648882","pt":1646204332762,"mc":[{"id":"1.195453609","rc":[{"atb":[[5.9,8.09]],"id":43167168}],"con":true,"img":false}]}
{"op":"mcm","clk":"5347651091","pt":1646204386630,"mc":[{"id":"1.195453609","rc":[{"atb":[[5.9,0]],"id":43167166}],"con":true,"img":false}]}
{"op":"mcm","clk":"5347651097","pt":1646204386836,"mc":[{"id":"1.195453609","rc":[{"atb":[[5.5,8.79]],"id":43167166}],"con":true,"img":false}]}
{"op":"mcm","clk":"5347651344","pt":1646204392735,"mc":[{"id":"1.195453609","rc":[{"atb":[[5.9,0]],"id":43167167}],"con":true,"img":false}]}
{"op":"mcm","clk":"5347651353","pt":1646204392940,"mc":[{"id":"1.195453609","rc":[{"atb":[[5.5,8.79]],"id":43167167}],"con":true,"img":false}]}
{"op":"mcm","clk":"5347651366","pt":1646204393250,"mc":[{"id":"1.195453609","rc":[{"atb":[[5.9,0]],"id":43167168}],"con":true,"img":false}]}
{"op":"mcm","clk":"5347651378","pt":1646204393409,"mc":[{"id":"1.195453609","rc":[{"atb":[[5.5,8.79]],"id":43167168}],"con":true,"img":false}]}
{"op":"mcm","clk":"5347654720","pt":1646204447719,"mc":[{"id":"1.195453609","rc":[{"atb":[[4.8,21.54],[4.3,49.62],[5.8,8.53],[5.5,0],[5.3,19.03],[7.6,6.2],[5.4,4.17]],"id":43167166},{"atl":[[65,3.12],[36,3.81],[90,2.24],[46,2.96]],"id":43167166},{"atb":[[4.8,21.54],[4.3,49.62],[5.8,8.53],[5.5,8.79],[5.3,19.03],[7.6,6.2],[5.4,4.17]],"id":43167167},{"atl":[[65,3.12],[36,3.81],[90,2.24],[46,2.96]],"id":43167167},{"atb":[[4.8,21.54],[4.3,49.62],[5.8,8.53],[5.5,8.79],[5.3,19.03],[7.6,6.2],[5.4,4.17]],"id":43167168},{"atl":[[65,3.12],[36,3.81],[90,2.24],[46,2.96]],"id":43167168},{"atb":[[1.4,204.69],[1.6,68.23],[1.45,181.94],[1.62,29.65],[1.5,81.87],[1.35,467.87]],"id":41719613},{"atl":[[3.45,81.67],[2.88,70.96],[3.2,90.96],[1.9,6.21],[2.64,8.18],[2.98,67.37],[2.2,6.21]],"id":41719613},{"atb":[[4,27.29],[5.1,9.56],[4.5,23.39],[5,10.23],[4.6,5.1],[6,8.18],[3.75,59.54]],"id":43167169},{"atl":[[19.5,7.21],[38,5.4],[24,5.8],[29,7.14]],"id":43167169},{"atb":[[6.4,15.16],[7.4,6.39],[5.2,38.99],[5.7,17.41],[6.6,3.29],[9.4,4.87]],"id":43167165},{"atl":[[80,1.68],[160,1.26],[55,2.47],[110,1.83]],"id":43167165},{"atb":[[8,5.84],[5.6,3.99],[4.5,46.78],[5,20.46],[5.5,18.19],[6,8.18]],"id":43167170},{"atl":[[75,2.7],[40,3.42],[50,2.72],[100,2.01]],"id":43167170},{"atb":[[4.8,21.54],[4.3,49.62],[5.8,8.53],[5.3,19.03],[7.6,6.2],[5.4,4.17]],"id":43016477},{"atl":[[65,3.12],[36,3.81],[90,2.24],[46,2.96]],"id":43016477}],"con":true,"img":false}]}
{"op":"mcm","clk":"5347654731","pt":1646204447924,"mc":[{"id":"1.195453609","rc":[{"atb":[[5.9,8.08]],"id":43167166}],"con":true,"img":false}]}
{"op":"mcm","clk":"5347654998","pt":1646204453531,"mc":[{"id":"1.195453609","rc":[{"atb":[[5.5,0]],"id":43167167}],"con":true,"img":false}]}
{"op":"mcm","clk":"5347655008","pt":1646204453730,"mc":[{"id":"1.195453609","rc":[{"atb":[[5.9,8.08]],"id":43167167}],"con":true,"img":false}]}
{"op":"mcm","clk":"5347655015","pt":1646204453936,"mc":[{"id":"1.195453609","rc":[{"atb":[[5.5,0]],"id":43167168}],"con":true,"img":false}]}
{"op":"mcm","clk":"5347655025","pt":1646204454141,"mc":[{"id":"1.195453609","rc":[{"atb":[[5.9,8.08]],"id":43167168}],"con":true,"img":false}]}
{"op":"mcm","clk":"5347655302","pt":1646204461123,"mc":[{"id":"1.195453609","rc":[{"atb":[[4.3,71.44],[2.96,41.84]],"id":43167166},{"atb":[[4.3,71.44]],"id":43167167},{"atb":[[4.3,71.44]],"id":43167168},{"atb":[[3.5,28.8]],"id":43167169},{"atb":[[5.2,56.13],[3.5,32.8]],"id":43167165},{"atb":[[4.5,67.35]],"id":43167170},{"atb":[[4.3,71.44]],"id":43016477}],"con":true,"img":false}]}
{"op":"mcm","clk":"5347655306","pt":1646204461224,"mc":[{"id":"1.195453609","rc":[{"atl":[[130,8.2]],"id":43167166},{"atb":[[2.96,41.84]],"id":43167167},{"atl":[[130,8.2]],"id":43167167},{"atb":[[2.96,41.84]],"id":43167168},{"atl":[[130,8.2]],"id":43167168},{"atl":[[3.6,14.2],[3.1,8.2]],"id":41719613},{"atb":[[2.5,54.67]],"id":43167169},{"atl":[[48,8.2]],"id":43167169},{"atb":[[3.05,40]],"id":43167170},{"atb":[[2.96,41.84]],"id":43016477},{"atl":[[130,8.2]],"id":43016477}],"con":true,"img":false}]}
{"op":"mcm","clk":"5347655312","pt":1646204461328,"mc":[{"id":"1.195453609","rc":[{"atb":[[2.62,46.3]],"id":43167166},{"atl":[[150,14.2]],"id":43167166},{"atl":[[150,14.2]],"id":43167167},{"atb":[[2.62,46.3]],"id":43167168},{"atl":[[150,14.2]],"id":43167168},{"atl":[[60,14.2]],"id":43167169},{"atb":[[2.62,46.3]],"id":43167165},{"atl":[[170,14.2]],"id":43167170},{"atl":[[150,14.2]],"id":43016477}],"con":true,"img":false}]}
{"op":"mcm","clk":"5347655316","pt":1646204461428,"mc":[{"id":"1.195453609","rc":[{"atl":[[17,8.5],[34,13.5]],"id":41719613},{"atb":[[2.62,46.3]],"id":43167169},{"atb":[[2.62,46.3]],"id":43167170}],"con":true,"img":false}]}
{"op":"mcm","clk":"5347655320","pt":1646204461532,"mc":[{"id":"1.195453609","rc":[{"atb":[[2.62,46.3]],"id":43167167},{"atb":[[2.62,46.3]],"id":43016477}],"con":true,"img":false}]}
{"op":"mcm","clk":"5347656903","pt":1646204501006,"mc":[{"id":"1.195453609","rc":[{"atb":[[8,8.36],[6.6,23.47]],"id":43167166},{"atl":[[21,2.92],[29,3.82]],"id":43167166},{"atb":[[8.2,8.13],[6.8,21.83]],"id":43167167},{"atl":[[22,2.78],[30,3.82]],"id":43167167},{"atb":[[1.63,69.28],[1.61,218.34]],"id":41719613},{"atl":[[2.86,71.5],[2.64,43.88]],"id":41719613},{"atb":[[8,8.36],[6.6,19.59]],"id":43167168},{"atl":[[21,2.92],[30,3.32]],"id":43167168},{"atb":[[7.4,9.14],[6,30.56]],"id":43167169},{"atl":[[18.5,3.34],[19,6.21]],"id":43167169},{"atb":[[9,13.75],[11,5.85]],"id":43167165},{"atl":[[32,2.72],[46,2.72]],"id":43167165},{"atb":[[7.2,18.44],[8.8,7.5]],"id":43167170},{"atl":[[34,3.08],[24,2.72]],"id":43167170},{"atb":[[9.2,8.36],[7.8,16.85]],"id":43016477},{"atl":[[34,3.47],[25,2.72]],"id":43016477}],"con":true,"img":false}]}
{"op":"mcm","clk":"5347657242","pt":1646204508506,"mc":[{"id":"1.195453609","rc":[{"atb":[[5.4,2.29]],"id":43167166},{"atb":[[5.4,2.29]],"id":43167167},{"atb":[[5.4,2.29]],"id":43167168},{"atb":[[1.62,16.3]],"id":41719613},{"atb":[[4.6,2.8]],"id":43167169},{"atb":[[6.6,1.81]],"id":43167165},{"atb":[[5.6,2.19]],"id":43167170},{"atb":[[5.4,2.29]],"id":43016477}],"con":true,"img":false}]}
{"op":"mcm","clk":"5347657248","pt":1646204508604,"mc":[{"id":"1.195453609","rc":[{"atb":[[5.9,0]],"id":43167166}],"con":true,"img":false}]}
{"op":"mcm","clk":"5347657261","pt":1646204508808,"mc":[{"id":"1.195453609","rc":[{"atb":[[5.5,8.79]],"id":43167166}],"con":true,"img":false}]}
{"op":"mcm","clk":"5347657544","pt":1646204514129,"mc":[{"id":"1.195453609","rc":[{"spn":15.0,"spf":"NaN","id":43167166},{"atb":[[5.9,0]],"id":43167167},{"spn":15.6,"spf":"NaN","id":43167167},{"spn":15.0,"spf":"NaN","id":43167168},{"spn":1.76,"spf":"NaN","id":41719613},{"spn":13.35,"spf":"NaN","id":43167169},{"spn":22.25,"spf":"NaN","id":43167165},{"spn":16.9,"spf":"NaN","id":43167170},{"spn":17.1,"spf":"NaN","id":43016477}],"con":true,"img":false}]}
{"op":"mcm","clk":"5347657554","pt":1646204514289,"mc":[{"id":"1.195453609","rc":[{"atb":[[5.9,0]],"id":43167168}],"con":true,"img":false}]}
{"op":"mcm","clk":"5347657664","pt":1646204517524,"mc":[{"id":"1.195453609","rc":[{"atb":[[5.1,0]],"id":43167169}],"con":true,"img":false}]}
{"op":"mcm","clk":"5347657667","pt":1646204517625,"mc":[{"id":"1.195453609","rc":[{"atb":[[1.01,2.25]],"id":43167166},{"atb":[[1.01,2.25]],"id":43167168},{"atb":[[1.65,12.73]],"id":41719613},{"atb":[[1.01,2.25]],"id":43167169}],"con":true,"img":false}]}
{"op":"mcm","clk":"5347657673","pt":1646204517830,"mc":[{"id":"1.195453609","rc":[{"atb":[[1.01,1.42]],"id":43167166},{"atb":[[1.01,1.42]],"id":43167168},{"atb":[[1.01,1.58]],"id":43167169}],"con":true,"img":false}]}
{"op":"mcm","clk":"5347657679","pt":1646204518034,"mc":[{"id":"1.195453609","rc":[{"atb":[[1.01,0]],"id":43167166}],"con":true,"img":false}]}
{"op":"mcm","clk":"5347657683","pt":1646204518090,"mc":[{"id":"1.195453609","rc":[{"atb":[[6.8,1.42]],"id":43167166}],"con":true,"img":false}]}
{"op":"mcm","clk":"5347657689","pt":1646204518295,"mc":[{"id":"1.195453609","rc":[{"atb":[[1.01,0]],"id":43167168}],"con":true,"img":false}]}
{"op":"mcm","clk":"5347657696","pt":1646204518398,"mc":[{"id":"1.195453609","rc":[{"atb":[[6.8,1.42]],"id":43167168}],"con":true,"img":false}]}
{"op":"mcm","clk":"5347657700","pt":1646204518499,"mc":[{"id":"1.195453609","rc":[{"atb":[[1.01,0]],"id":43167169}],"con":true,"img":false}]}
{"op":"mcm","clk":"5347657704","pt":1646204518601,"mc":[{"id":"1.195453609","rc":[{"atb":[[6.2,1.58]],"id":43167169}],"con":true,"img":false}]}
{"op":"mcm","clk":"5347657899","pt":1646204523846,"mc":[{"id":"1.195453609","rc":[{"atb":[[5.4,0]],"id":43167166},{"atb":[[5.4,0]],"id":43167167},{"atb":[[5.4,0]],"id":43167168},{"atb":[[1.62,0]],"id":41719613},{"atb":[[4.6,0]],"id":43167169},{"atb":[[6.6,0]],"id":43167165},{"atb":[[5.6,0]],"id":43167170},{"atb":[[5.4,0]],"id":43016477}],"con":true,"img":false}]}
{"op":"mcm","clk":"5347658390","pt":1646204535751,"mc":[{"id":"1.195453609","rc":[{"atb":[[1.65,28.27]],"id":41719613}],"con":true,"img":false}]}
{"op":"mcm","clk":"5347658398","pt":1646204535955,"mc":[{"id":"1.195453609","rc":[{"atb":[[6.8,3.15]],"id":43167166}],"con":true,"img":false}]}
{"op":"mcm","clk":"5347658403","pt":1646204536066,"mc":[{"id":"1.195453609","rc":[{"atb":[[6.8,3.15]],"id":43167168}],"con":true,"img":false}]}
{"op":"mcm","clk":"5347658408","pt":1646204536114,"mc":[{"id":"1.195453609","rc":[{"atb":[[6.2,3.52]],"id":43167169}],"con":true,"img":false}]}
{"op":"mcm","clk":"5347658625","pt":1646204541247,"mc":[{"id":"1.195453609","rc":[{"atb":[[5.2,9.41]],"id":43167169}],"con":true,"img":false}]}
{"op":"mcm","clk":"5347659854","pt":1646204569295,"mc":[{"id":"1.195453609","rc":[{"atb":[[5.5,0]],"id":43167166}],"con":true,"img":false}]}
{"op":"mcm","clk":"5347659862","pt":1646204569503,"mc":[{"id":"1.195453609","rc":[{"atb":[[6,7.85]],"id":43167166}],"con":true,"img":false}]}
{"op":"mcm","clk":"5347660696","pt":1646204586632,"mc":[{"id":"1.195453609","rc":[{"atb":[[6.6,0],[7.8,16.13]],"id":43167168},{"spn":1.77,"spf":"NaN","id":41719613}],"con":true,"img":false}]}
{"op":"mcm","clk":"5347660702","pt":1646204586733,"mc":[{"id":"1.195453609","rc":[{"atb":[[6.6,0]],"id":43167166},{"atb":[[6.8,0]],"id":43167167},{"atb":[[6,8.18]],"id":43167169},{"atb":[[9,0]],"id":43167165},{"atb":[[7.2,0]],"id":43167170}],"con":true,"img":false}]}
{"op":"mcm","clk":"5347660706","pt":1646204586787,"mc":[{"id":"1.195453609","rc":[{"atb":[[7.8,23.47]],"id":43167166},{"atb":[[7.8,21.83]],"id":43167167},{"atb":[[6.2,25.9]],"id":43167169},{"atb":[[9.6,13.75]],"id":43167165},{"atb":[[8.2,18.44]],"id":43167170}],"con":true,"img":false}]}
{"op":"mcm","clk":"5347661081","pt":1646204595821,"mc":[{"id":"1.195453609","rc":[{"atb":[[6.8,1.73]],"id":43167166},{"atb":[[6.8,1.73]],"id":43167168},{"atb":[[6.2,24.31]],"id":43167169}],"con":true,"img":false}]}
{"op":"mcm","clk":"5347661354","pt":1646204601830,"mc":[{"id":"1.195453609","rc":[{"atb":[[6.8,0]],"id":43167166},{"atb":[[6.8,0]],"id":43167168},{"atb":[[6.2,22.37]],"id":43167169}],"con":true,"img":false}]}
{"op":"mcm","clk":"5347661376","pt":1646204602138,"mc":[{"id":"1.195453609","rc":[{"atb":[[5.2,0]],"id":43167169}],"con":true,"img":false}]}
{"op":"mcm","clk":"5347661489","pt":1646204604759,"mc":[{"id":"1.195453609","rc":[{"atb":[[1.01,2.25]],"id":43167169}],"con":true,"img":false}]}
{"op":"mcm","clk":"5347661494","pt":1646204604813,"mc":[{"id":"1.195453609","rc":[{"atb":[[1.01,1.53]],"id":43167169}],"con":true,"img":false}]}
{"op":"mcm","clk":"5347661501","pt":1646204605015,"mc":[{"id":"1.195453609","rc":[{"atb":[[1.01,0]],"id":43167169}],"con":true,"img":false}]}
{"op":"mcm","clk":"5347661506","pt":1646204605117,"mc":[{"id":"1.195453609","rc":[{"atb":[[6.4,1.53]],"id":43167169}],"con":true,"img":false}]}
{"op":"mcm","clk":"5347661733","pt":1646204610822,"mc":[{"id":"1.195453609","rc":[{"atb":[[6.4,3.4]],"id":43167169}],"con":true,"img":false}]}
{"op":"mcm","clk":"5347661880","pt":1646204614241,"mc":[{"id":"1.195453609","rc":[{"atb":[[1.63,0]],"id":41719613}],"con":true,"img":false}]}
{"op":"mcm","clk":"5347661887","pt":1646204614340,"mc":[{"id":"1.195453609","rc":[{"atb":[[1.66,69.28]],"id":41719613}],"con":true,"img":false}]}
{"op":"mcm","clk":"5347662094","pt":1646204619646,"mc":[{"id":"1.195453609","rc":[{"atb":[[1.3,240]],"id":41719613}],"con":true,"img":false}]}
{"op":"mcm","clk":"5347662181","pt":1646204622738,"mc":[{"id":"1.195453609","rc":[{"atb":[[1.65,15.54]],"id":41719613}],"con":true,"img":false}]}
{"op":"mcm","clk":"5347662426","pt":1646204630291,"mc":[{"id":"1.195453609","rc":[{"atb":[[6,0]],"id":43167166}],"con":true,"img":false}]}
{"op":"mcm","clk":"5347662659","pt":1646204637995,"mc":[{"id":"1.195453609","rc":[{"atb":[[1.65,0]],"id":41719613}],"con":true,"img":false}]}
{"op":"mcm","clk":"5347662780","pt":1646204642104,"mc":[{"id":"1.195453609","rc":[{"atb":[[1.66,0]],"id":41719613}],"con":true,"img":false}]}
{"op":"mcm","clk":"5347662783","pt":1646204642201,"mc":[{"id":"1.195453609","rc":[{"atb":[[1.62,69.28]],"id":41719613}],"con":true,"img":false}]}
{"op":"mcm","clk":"5347663348","pt":1646204658820,"mc":[{"id":"1.195453609","rc":[{"atb":[[1.64,12.92]],"id":41719613},{"spn":1.77,"spf":"NaN","id":41719613}],"con":true,"img":false}]}
{"op":"mcm","clk":"5347663589","pt":1646204665046,"mc":[{"id":"1.195453609","rc":[{"atb":[[1.64,28.71]],"id":41719613}],"con":true,"img":false}]}
{"op":"mcm","clk":"5347665497","pt":1646204724740,"mc":[{"id":"1.195453609","rc":[{"atb":[[1.62,0]],"id":41719613}],"con":true,"img":false}]}
{"op":"mcm","clk":"5347665500","pt":1646204724842,"mc":[{"id":"1.195453609","rc":[{"atb":[[1.65,69.28]],"id":41719613}],"con":true,"img":false}]}
{"op":"mcm","clk":"5347665822","pt":1646204737019,"mc":[{"id":"1.195453609","rc":[{"atb":[[1.64,15.78]],"id":41719613}],"con":true,"img":false}]}
{"op":"mcm","clk":"5347665974","pt":1646204742973,"mc":[{"id":"1.195453609","rc":[{"atb":[[1.67,11.23]],"id":41719613}],"con":true,"img":false}]}
{"op":"mcm","clk":"5347666067","pt":1646204746260,"mc":[{"id":"1.195453609","rc":[{"atb":[[1.64,0]],"id":41719613}],"con":true,"img":false}]}
{"op":"mcm","clk":"5347666202","pt":1646204751380,"mc":[{"id":"1.195453609","rc":[{"atb":[[1.65,0]],"id":41719613}],"con":true,"img":false}]}
{"op":"mcm","clk":"5347666206","pt":1646204751482,"mc":[{"id":"1.195453609","rc":[{"atb":[[1.62,69.28]],"id":41719613}],"con":true,"img":false}]}
{"op":"mcm","clk":"5347666394","pt":1646204758094,"mc":[{"id":"1.195453609","rc":[{"atb":[[1.67,0]],"id":41719613}],"con":true,"img":false}]}
{"op":"mcm","clk":"5347666702","pt":1646204767082,"mc":[{"id":"1.195453609","rc":[{"atb":[[1.64,11.75]],"id":41719613}],"con":true,"img":false}]}
{"op":"mcm","clk":"5347666863","pt":1646204773131,"mc":[{"id":"1.195453609","rc":[{"atb":[[1.64,27.54]],"id":41719613}],"con":true,"img":false}]}
{"op":"mcm","clk":"5347668254","pt":1646204822362,"mc":[{"id":"1.195453609","rc":[{"atb":[[2.5,0]],"id":43167169},{"atb":[[3.5,0]],"id":43167165},{"atl":[[130,14.2]],"id":43167165},{"atb":[[2.96,0]],"id":43016477}],"con":true,"img":false}]}
{"op":"mcm","clk":"5347668563","pt":1646204830374,"mc":[{"id":"1.195453609","rc":[{"atb":[[1.62,0]],"id":41719613}],"con":true,"img":false}]}
{"op":"mcm","clk":"5347668566","pt":1646204830478,"mc":[{"id":"1.195453609","rc":[{"atb":[[1.65,69.28]],"id":41719613}],"con":true,"img":false}]}
{"op":"mcm","clk":"5347668787","pt":1646204839213,"mc":[{"id":"1.195453609","rc":[{"atb":[[1.64,15.78]],"id":41719613}],"con":true,"img":false}]}
{"op":"mcm","clk":"5347669036","pt":1646204848195,"mc":[{"id":"1.195453609","rc":[{"atb":[[1.67,11.23]],"id":41719613}],"con":true,"img":false}]}
{"op":"mcm","clk":"5347669211","pt":1646204854400,"mc":[{"id":"1.195453609","rc":[{"atb":[[1.64,0]],"id":41719613}],"con":true,"img":false}]}
{"op":"mcm","clk":"5347669255","pt":1646204856405,"mc":[{"id":"1.195453609","rc":[{"atb":[[1.65,0]],"id":41719613}],"con":true,"img":false}]}
{"op":"mcm","clk":"5347669259","pt":1646204856506,"mc":[{"id":"1.195453609","rc":[{"atb":[[1.62,69.28]],"id":41719613}],"con":true,"img":false}]}
{"op":"mcm","clk":"5347669452","pt":1646204863320,"mc":[{"id":"1.195453609","rc":[{"atb":[[1.67,0]],"id":41719613}],"con":true,"img":false}]}
{"op":"mcm","clk":"5347669736","pt":1646204875215,"mc":[{"id":"1.195453609","rc":[{"atb":[[1.64,11.75]],"id":41719613}],"con":true,"img":false}]}
{"op":"mcm","clk":"5347669741","pt":1646204875320,"mc":[{"id":"1.195453609","rc":[{"atb":[[1.64,27.54]],"id":41719613}],"con":true,"img":false}]}
{"op":"mcm","clk":"5347671339","pt":1646204933419,"mc":[{"id":"1.195453609","rc":[{"atb":[[1.62,0]],"id":41719613}],"con":true,"img":false}]}
{"op":"mcm","clk":"5347671346","pt":1646204933521,"mc":[{"id":"1.195453609","rc":[{"atb":[[1.65,69.28]],"id":41719613}],"con":true,"img":false}]}
{"op":"mcm","clk":"5347671552","pt":1646204941538,"mc":[{"id":"1.195453609","rc":[{"atb":[[1.64,15.78]],"id":41719613}],"con":true,"img":false}]}
{"op":"mcm","clk":"5347671799","pt":1646204950380,"mc":[{"id":"1.195453609","rc":[{"atb":[[1.67,11.23]],"id":41719613}],"con":true,"img":false}]}
{"op":"mcm","clk":"5347671909","pt":1646204953669,"mc":[{"id":"1.195453609","rc":[{"atb":[[1.64,0]],"id":41719613}],"con":true,"img":false}]}
{"op":"mcm","clk":"5347672086","pt":1646204959684,"mc":[{"id":"1.195453609","rc":[{"atb":[[1.65,0]],"id":41719613}],"con":true,"img":false}]}
{"op":"mcm","clk":"5347672090","pt":1646204959787,"mc":[{"id":"1.195453609","rc":[{"atb":[[1.62,69.28]],"id":41719613}],"con":true,"img":false}]}
{"op":"mcm","clk":"5347672285","pt":1646204968467,"mc":[{"id":"1.195453609","rc":[{"atb":[[1.67,0]],"id":41719613}],"con":true,"img":false}]}
{"op":"mcm","clk":"5347672505","pt":1646204977500,"mc":[{"id":"1.195453609","rc":[{"atb":[[1.64,11.75]],"id":41719613}],"con":true,"img":false}]}
{"op":"mcm","clk":"5347672585","pt":1646204980990,"mc":[{"id":"1.195453609","rc":[{"atb":[[1.64,27.54]],"id":41719613}],"con":true,"img":false}]}
{"op":"mcm","clk":"5347674119","pt":1646205034310,"mc":[{"id":"1.195453609","rc":[{"atb":[[1.62,0]],"id":41719613}],"con":true,"img":false}]}
{"op":"mcm","clk":"5347674123","pt":1646205034411,"mc":[{"id":"1.195453609","rc":[{"atb":[[1.65,69.28]],"id":41719613}],"con":true,"img":false}]}
{"op":"mcm","clk":"5347674383","pt":1646205043633,"mc":[{"id":"1.195453609","rc":[{"atb":[[1.64,15.78]],"id":41719613}],"con":true,"img":false}]}
{"op":"mcm","clk":"5347674702","pt":1646205052533,"mc":[{"id":"1.195453609","rc":[{"atb":[[1.67,11.23]],"id":41719613}],"con":true,"img":false}]}
{"op":"mcm","clk":"5347674916","pt":1646205058913,"mc":[{"id":"1.195453609","rc":[{"atb":[[1.65,0]],"id":41719613}],"con":true,"img":false}]}
{"op":"mcm","clk":"5347674919","pt":1646205059018,"mc":[{"id":"1.195453609","rc":[{"atb":[[1.62,69.28]],"id":41719613}],"con":true,"img":false}]}
{"op":"mcm","clk":"5347675214","pt":1646205067557,"mc":[{"id":"1.195453609","rc":[{"atb":[[1.67,0]],"id":41719613}],"con":true,"img":false}]}
{"op":"mcm","clk":"5347675584","pt":1646205076569,"mc":[{"id":"1.195453609","rc":[{"atb":[[1.64,27.54]],"id":41719613}],"con":true,"img":false}]}
{"op":"mcm","clk":"5347677163","pt":1646205132131,"mc":[{"id":"1.195453609","rc":[{"atb":[[1.62,0]],"id":41719613}],"con":true,"img":false}]}
{"op":"mcm","clk":"5347677167","pt":1646205132231,"mc":[{"id":"1.195453609","rc":[{"atb":[[1.65,69.28]],"id":41719613}],"con":true,"img":false}]}
{"op":"mcm","clk":"5347677378","pt":1646205139758,"mc":[{"id":"1.195453609","rc":[{"atb":[[1.64,15.78]],"id":41719613}],"con":true,"img":false}]}
{"op":"mcm","clk":"5347677391","pt":1646205140121,"mc":[{"id":"1.195453609","rc":[{"atb":[[1.64,0]],"id":41719613}],"con":true,"img":false}]}
{"op":"mcm","clk":"5347677643","pt":1646205148673,"mc":[{"id":"1.195453609","rc":[{"atb":[[1.67,11.23]],"id":41719613}],"con":true,"img":false}]}
{"op":"mcm","clk":"5347677838","pt":1646205155437,"mc":[{"id":"1.195453609","rc":[{"atb":[[1.65,0]],"id":41719613}],"con":true,"img":false}]}
{"op":"mcm","clk":"5347677843","pt":1646205155548,"mc":[{"id":"1.195453609","rc":[{"atb":[[1.62,69.28]],"id":41719613}],"con":true,"img":false}]}
{"op":"mcm","clk":"5347678263","pt":1646205163792,"mc":[{"id":"1.195453609","rc":[{"atb":[[1.67,0]],"id":41719613}],"con":true,"img":false}]}
{"op":"mcm","clk":"5347678831","pt":1646205172684,"mc":[{"id":"1.195453609","rc":[{"atb":[[1.64,11.75]],"id":41719613}],"con":true,"img":false}]}
{"op":"mcm","clk":"5347678956","pt":1646205175876,"mc":[{"id":"1.195453609","rc":[{"atb":[[1.64,27.54]],"id":41719613}],"con":true,"img":false}]}
{"op":"mcm","clk":"5347680836","pt":1646205225875,"mc":[{"id":"1.195453609","rc":[{"atb":[[1.62,0]],"id":41719613}],"con":true,"img":false}]}
{"op":"mcm","clk":"5347680841","pt":1646205225983,"mc":[{"id":"1.195453609","rc":[{"atb":[[1.65,69.28]],"id":41719613}],"con":true,"img":false}]}
{"op":"mcm","clk":"5347681093","pt":1646205232789,"mc":[{"id":"1.195453609","rc":[{"atb":[[1.64,15.78]],"id":41719613}],"con":true,"img":false}]}
{"op":"mcm","clk":"5347681380","pt":1646205241799,"mc":[{"id":"1.195453609","rc":[{"atb":[[1.67,11.23]],"id":41719613}],"con":true,"img":false}]}
{"op":"mcm","clk":"5347681611","pt":1646205248307,"mc":[{"id":"1.195453609","rc":[{"atb":[[1.64,0]],"id":41719613}],"con":true,"img":false}]}
{"op":"mcm","clk":"5347682426","pt":1646205273024,"mc":[{"id":"1.195453609","rc":[{"atb":[[8,0]],"id":43167166},{"atl":[[22,0]],"id":43167167},{"atb":[[1.65,0]],"id":41719613},{"atb":[[8,0]],"id":43167168}],"con":true,"img":false}]}
{"op":"mcm","clk":"5347682432","pt":1646205273128,"mc":[{"id":"1.195453609","rc":[{"atb":[[8.2,8.36]],"id":43167166},{"atl":[[21,2.78]],"id":43167167},{"atb":[[1.62,69.28]],"id":41719613},{"atb":[[8.2,8.36]],"id":43167168}],"con":true,"img":false}]}
{"op":"mcm","clk":"5347682703","pt":1646205280957,"mc":[{"id":"1.195453609","rc":[{"atb":[[1.67,0]],"id":41719613}],"con":true,"img":false}]}
{"op":"mcm","clk":"5347683030","pt":1646205289966,"mc":[{"id":"1.195453609","rc":[{"spn":15.1,"spf":"NaN","id":43167167},{"atb":[[1.64,11.75]],"id":41719613}],"con":true,"img":false}]}
{"op":"mcm","clk":"5347683366","pt":1646205299349,"mc":[{"id":"1.195453609","rc":[{"atb":[[1.64,27.54]],"id":41719613}],"con":true,"img":false}]}
{"op":"mcm","clk":"5347687733","pt":1646205416944,"mc":[{"id":"1.195453609","rc":[{"atl":[[110,10.03]],"id":43167165},{"atl":[[60,8.2]],"id":43167170}],"con":true,"img":false}]}
{"op":"mcm","clk":"5347689928","pt":1646205473719,"mc":[{"id":"1.195453609","rc":[{"atb":[[1.62,0]],"id":41719613}],"con":true,"img":false}]}
{"op":"mcm","clk":"5347689935","pt":1646205473823,"mc":[{"id":"1.195453609","rc":[{"atb":[[1.65,69.28]],"id":41719613}],"con":true,"img":false}]}
{"op":"mcm","clk":"5347690221","pt":1646205482295,"mc":[{"id":"1.195453609","rc":[{"atb":[[1.64,15.78]],"id":41719613},{"spn":1.77,"spf":"NaN","id":41719613}],"con":true,"img":false}]}
{"op":"mcm","clk":"5347690428","pt":1646205488815,"mc":[{"id":"1.195453609","rc":[{"atb":[[1.64,0]],"id":41719613}],"con":true,"img":false}]}
{"op":"mcm","clk":"5347690525","pt":1646205491333,"mc":[{"id":"1.195453609","rc":[{"atb":[[1.67,11.23]],"id":41719613}],"con":true,"img":false}]}
{"op":"mcm","clk":"5347690761","pt":1646205499441,"mc":[{"id":"1.195453609","rc":[{"atb":[[1.65,0]],"id":41719613}],"con":true,"img":false}]}
{"op":"mcm","clk":"5347690765","pt":1646205499543,"mc":[{"id":"1.195453609","rc":[{"atb":[[1.62,69.28]],"id":41719613}],"con":true,"img":false}]}
{"op":"mcm","clk":"5347690973","pt":1646205506330,"mc":[{"id":"1.195453609","rc":[{"atb":[[1.67,0]],"id":41719613}],"con":true,"img":false}]}
{"op":"mcm","clk":"5347691252","pt":1646205515361,"mc":[{"id":"1.195453609","rc":[{"atb":[[1.64,11.75]],"id":41719613}],"con":true,"img":false}]}
{"op":"mcm","clk":"5347694223","pt":1646205602285,"mc":[{"id":"1.195453609","rc":[{"atb":[[9,0]],"id":43167166},{"spn":14.6,"spf":"NaN","id":43167166},{"atb":[[9.2,0]],"id":43167167},{"spn":14.6,"spf":"NaN","id":43167167},{"atb":[[1.56,0]],"id":41719613},{"spn":1.77,"spf":"NaN","id":41719613},{"atb":[[9,0]],"id":43167168},{"spn":14.6,"spf":"NaN","id":43167168},{"atb":[[8.2,0],[7.6,1.53]],"id":43167169},{"spn":13.05,"spf":"NaN","id":43167169},{"atb":[[12.5,0]],"id":43167165},{"spn":21.5,"spf":"NaN","id":43167165},{"atb":[[9.8,0]],"id":43167170},{"spn":16.4,"spf":"NaN","id":43167170},{"atb":[[9.2,7.13]],"id":43016477}],"con":true,"img":false}]}
{"op":"mcm","clk":"5347694232","pt":1646205602390,"mc":[{"id":"1.195453609","rc":[{"atb":[[1.56,2]],"id":41719613},{"atb":[[9,1.26]],"id":43167168},{"atb":[[9.8,1.15]],"id":43167170},{"atb":[[9.2,8.36]],"id":43016477}],"con":true,"img":false}]}
{"op":"mcm","clk":"5347694238","pt":1646205602493,"mc":[{"id":"1.195453609","rc":[{"atb":[[9,1.26]],"id":43167166},{"atb":[[9.2,1.23]],"id":43167167},{"atb":[[12.5,0.88]],"id":43167165}],"con":true,"img":false}]}
{"op":"mcm","clk":"5347694596","pt":1646205609464,"mc":[{"id":"1.195453609","rc":[{"atb":[[1.64,27.54]],"id":41719613}],"con":true,"img":false}]}
{"op":"mcm","clk":"5347697161","pt":1646205670283,"mc":[{"id":"1.195453609","rc":[{"spn":15.0,"spf":"NaN","id":43167166},{"spn":15.1,"spf":"NaN","id":43167167},{"atb":[[1.62,0]],"id":41719613},{"spn":15.0,"spf":"NaN","id":43167168},{"spn":22.25,"spf":"NaN","id":43167165},{"spn":16.9,"spf":"NaN","id":43167170}],"con":true,"img":false}]}
{"op":"mcm","clk":"5347697165","pt":1646205670333,"mc":[{"id":"1.195453609","rc":[{"atb":[[1.65,69.28]],"id":41719613}],"con":true,"img":false}]}
{"op":"mcm","clk":"5347697453","pt":1646205677578,"mc":[{"id":"1.195453609","rc":[{"atb":[[1.64,15.78]],"id":41719613}],"con":true,"img":false}]}
{"op":"mcm","clk":"5347697854","pt":1646205686673,"mc":[{"id":"1.195453609","rc":[{"atb":[[1.67,11.23]],"id":41719613}],"con":true,"img":false}]}
{"op":"mcm","clk":"5347698056","pt":1646205692058,"mc":[{"id":"1.195453609","rc":[{"atb":[[1.65,0]],"id":41719613}],"con":true,"img":false}]}
{"op":"mcm","clk":"5347698061","pt":1646205692160,"mc":[{"id":"1.195453609","rc":[{"atb":[[1.62,69.28]],"id":41719613}],"con":true,"img":false}]}
{"op":"mcm","clk":"5347698337","pt":1646205698679,"mc":[{"id":"1.195453609","rc":[{"atb":[[1.67,0]],"id":41719613}],"con":true,"img":false}]}
{"op":"mcm","clk":"5347698713","pt":1646205707731,"mc":[{"id":"1.195453609","rc":[{"atb":[[1.64,27.54]],"id":41719613}],"con":true,"img":false}]}
{"op":"mcm","clk":"5347700848","pt":1646205764096,"mc":[{"id":"1.195453609","rc":[{"atb":[[1.62,0]],"id":41719613}],"con":true,"img":false}]}
{"op":"mcm","clk":"5347700853","pt":1646205764198,"mc":[{"id":"1.195453609","rc":[{"atb":[[1.65,69.28]],"id":41719613}],"con":true,"img":false}]}
{"op":"mcm","clk":"5347701113","pt":1646205770812,"mc":[{"id":"1.195453609","rc":[{"atb":[[1.64,15.78]],"id":41719613}],"con":true,"img":false}]}
{"op":"mcm","clk":"5347701263","pt":1646205774196,"mc":[{"id":"1.195453609","rc":[{"atb":[[1.64,0]],"id":41719613}],"con":true,"img":false}]}
{"op":"mcm","clk":"5347701511","pt":1646205779805,"mc":[{"id":"1.195453609","rc":[{"atb":[[1.67,11.23]],"id":41719613}],"con":true,"img":false}]}
{"op":"mcm","clk":"5347701890","pt":1646205788128,"mc":[{"id":"1.195453609","rc":[{"atb":[[1.65,0]],"id":41719613}],"con":true,"img":false}]}
{"op":"mcm","clk":"5347701894","pt":1646205788231,"mc":[{"id":"1.195453609","rc":[{"atb":[[1.62,69.28]],"id":41719613}],"con":true,"img":false}]}
{"op":"mcm","clk":"5347702185","pt":1646205794801,"mc":[{"id":"1.195453609","rc":[{"atb":[[1.67,0]],"id":41719613}],"con":true,"img":false}]}
{"op":"mcm","clk":"5347702774","pt":1646205806875,"mc":[{"id":"1.195453609","rc":[{"atb":[[1.64,11.75]],"id":41719613}],"con":true,"img":false}]}
{"op":"mcm","clk":"5347702782","pt":1646205807131,"mc":[{"id":"1.195453609","rc":[{"atb":[[1.64,27.54]],"id":41719613}],"con":true,"img":false}]}
{"op":"mcm","clk":"5347704794","pt":1646205857417,"mc":[{"id":"1.195453609","rc":[{"atb":[[1.62,0]],"id":41719613}],"con":true,"img":false}]}
{"op":"mcm","clk":"5347704798","pt":1646205857519,"mc":[{"id":"1.195453609","rc":[{"atb":[[1.65,69.28]],"id":41719613}],"con":true,"img":false}]}
{"op":"mcm","clk":"5347705096","pt":1646205864041,"mc":[{"id":"1.195453609","rc":[{"atb":[[1.64,15.78]],"id":41719613}],"con":true,"img":false}]}
{"op":"mcm","clk":"5347705488","pt":1646205873043,"mc":[{"id":"1.195453609","rc":[{"atb":[[1.67,11.23]],"id":41719613}],"con":true,"img":false}]}
{"op":"mcm","clk":"5347705554","pt":1646205874837,"mc":[{"id":"1.195453609","rc":[{"atb":[[1.64,0]],"id":41719613}],"con":true,"img":false}]}
{"op":"mcm","clk":"5347705778","pt":1646205880645,"mc":[{"id":"1.195453609","rc":[{"atb":[[1.65,0]],"id":41719613}],"con":true,"img":false}]}
{"op":"mcm","clk":"5347705782","pt":1646205880748,"mc":[{"id":"1.195453609","rc":[{"atb":[[1.62,69.28]],"id":41719613}],"con":true,"img":false}]}
{"op":"mcm","clk":"5347706047","pt":1646205888051,"mc":[{"id":"1.195453609","rc":[{"atb":[[1.67,0]],"id":41719613}],"con":true,"img":false}]}
{"op":"mcm","clk":"5347706442","pt":1646205897030,"mc":[{"id":"1.195453609","rc":[{"atb":[[1.64,11.75]],"id":41719613}],"con":true,"img":false}]}
{"op":"mcm","clk":"5347706826","pt":1646205906570,"mc":[{"id":"1.195453609","rc":[{"atb":[[1.64,27.54]],"id":41719613}],"con":true,"img":false}]}
{"op":"mcm","clk":"5347709246","pt":1646205971931,"mc":[{"id":"1.195453609","rc":[{"atb":[[1.62,0]],"id":41719613}],"con":true,"img":false}]}
{"op":"mcm","clk":"5347709248","pt":1646205972030,"mc":[{"id":"1.195453609","rc":[{"atb":[[1.65,69.28]],"id":41719613}],"con":true,"img":false}]}
{"op":"mcm","clk":"5347709415","pt":1646205978227,"mc":[{"id":"1.195453609","rc":[{"atb":[[1.64,15.78]],"id":41719613}],"con":true,"img":false}]}
{"op":"mcm","clk":"5347709621","pt":1646205984742,"mc":[{"id":"1.195453609","rc":[{"atb":[[1.64,0]],"id":41719613}],"con":true,"img":false}]}
{"op":"mcm","clk":"5347709788","pt":1646205990217,"mc":[{"id":"1.195453609","rc":[{"atb":[[1.67,11.23]],"id":41719613}],"con":true,"img":false}]}
{"op":"mcm","clk":"5347709914","pt":1646205993145,"mc":[{"id":"1.195453609","rc":[{"atb":[[1.65,0]],"id":41719613}],"con":true,"img":false}]}
{"op":"mcm","clk":"5347709919","pt":1646205993250,"mc":[{"id":"1.195453609","rc":[{"atb":[[1.62,69.28]],"id":41719613}],"con":true,"img":false}]}
{"op":"mcm","clk":"5347710156","pt":1646206002369,"mc":[{"id":"1.195453609","rc":[{"atb":[[1.67,0]],"id":41719613}],"con":true,"img":false}]}
{"op":"mcm","clk":"5347710329","pt":1646206011283,"mc":[{"id":"1.195453609","rc":[{"atb":[[1.64,11.75]],"id":41719613}],"con":true,"img":false}]}
{"op":"mcm","clk":"5347710436","pt":1646206014874,"mc":[{"id":"1.195453609","rc":[{"atb":[[1.64,27.54]],"id":41719613}],"con":true,"img":false}]}
{"op":"mcm","clk":"5347711051","pt":1646206033396,"mc":[{"id":"1.195453609","rc":[{"atb":[[9,0]],"id":43167168},{"spn":14.6,"spf":"NaN","id":43167168}],"con":true,"img":false}]}
{"op":"mcm","clk":"5347711056","pt":1646206033498,"mc":[{"id":"1.195453609","rc":[{"atb":[[9,0]],"id":43167166},{"atb":[[9.2,1.23]],"id":43167168}],"con":true,"img":false}]}
{"op":"mcm","clk":"5347711059","pt":1646206033550,"mc":[{"id":"1.195453609","rc":[{"atb":[[9.2,1.23]],"id":43167166}],"con":true,"img":false}]}
{"op":"mcm","clk":"5347711807","pt":1646206059929,"mc":[{"id":"1.195453609","rc":[{"atb":[[1.62,0]],"id":41719613}],"con":true,"img":false}]}
{"op":"mcm","clk":"5347711811","pt":1646206060032,"mc":[{"id":"1.195453609","rc":[{"atb":[[1.65,69.28]],"id":41719613}],"con":true,"img":false}]}
{"op":"mcm","clk":"5347712059","pt":1646206068495,"mc":[{"id":"1.195453609","rc":[{"atb":[[1.64,15.78]],"id":41719613}],"con":true,"img":false}]}
{"op":"mcm","clk":"5347712412","pt":1646206080959,"mc":[{"id":"1.195453609","rc":[{"atb":[[1.64,0]],"id":41719613}],"con":true,"img":false}]}
{"op":"mcm","clk":"5347712447","pt":1646206081836,"mc":[{"id":"1.195453609","rc":[{"atb":[[1.65,0]],"id":41719613}],"con":true,"img":false}]}
{"op":"mcm","clk":"5347712449","pt":1646206081936,"mc":[{"id":"1.195453609","rc":[{"atb":[[1.62,69.28]],"id":41719613}],"con":true,"img":false}]}
{"op":"mcm","clk":"5347713108","pt":1646206105789,"mc":[{"id":"1.195453609","rc":[{"spn":15.1,"spf":"NaN","id":43167166},{"atb":[[1.64,15.78]],"id":41719613},{"spn":15.1,"spf":"NaN","id":43167168}],"con":true,"img":false}]}
{"op":"mcm","clk":"5347716855","pt":1646206203695,"mc":[{"id":"1.195453609","rc":[{"atb":[[1.64,27.54]],"id":41719613}],"con":true,"img":false}]}
{"op":"mcm","clk":"5347719394","pt":1646206257731,"mc":[{"id":"1.195453609","rc":[{"atb":[[1.62,0]],"id":41719613}],"con":true,"img":false}]}
{"op":"mcm","clk":"5347719399","pt":1646206257834,"mc":[{"id":"1.195453609","rc":[{"atb":[[1.65,69.28]],"id":41719613}],"con":true,"img":false}]}
{"op":"mcm","clk":"5347719868","pt":1646206266962,"mc":[{"id":"1.195453609","rc":[{"atb":[[1.64,15.78]],"id":41719613},{"spn":1.77,"spf":"NaN","id":41719613}],"con":true,"img":false}]}
{"op":"mcm","clk":"5347720270","pt":1646206275862,"mc":[{"id":"1.195453609","rc":[{"atb":[[1.67,11.23]],"id":41719613}],"con":true,"img":false}]}
{"op":"mcm","clk":"5347720357","pt":1646206277971,"mc":[{"id":"1.195453609","rc":[{"atb":[[1.65,0]],"id":41719613}],"con":true,"img":false}]}
{"op":"mcm","clk":"5347720365","pt":1646206278079,"mc":[{"id":"1.195453609","rc":[{"atb":[[1.62,69.28]],"id":41719613}],"con":true,"img":false}]}
{"op":"mcm","clk":"5347720568","pt":1646206282251,"mc":[{"id":"1.195453609","rc":[{"atb":[[5.3,40.57]],"id":43167166},{"atl":[[110,2]],"id":43167166},{"atb":[[4.7,27.03]],"id":43167167},{"atl":[[50,2.04]],"id":43167167},{"atb":[[1.28,163.76]],"id":41719613},{"atl":[[8.6,13.16]],"id":41719613},{"atb":[[4.4,29.41]],"id":43167168},{"atl":[[90,4.24]],"id":43167168},{"atb":[[2.88,46.3]],"id":43167169},{"atl":[[85,2]],"id":43167169},{"atb":[[4.4,29.41]],"id":43167165},{"atl":[[50,2.04]],"id":43167165},{"atb":[[4.1,32.26]],"id":43167170},{"atl":[[27,3.85]],"id":43167170},{"atb":[[4.4,29.41]],"id":43016477},{"atl":[[110,2]],"id":43016477}],"con":true,"img":false}]}
{"op":"mcm","clk":"5347720686","pt":1646206285079,"mc":[{"id":"1.195453609","rc":[{"atb":[[1.67,0]],"id":41719613}],"con":true,"img":false}]}
{"op":"mcm","clk":"5347720850","pt":1646206287977,"mc":[{"id":"1.195453609","rc":[{"atl":[[32,3.23],[27,0]],"id":43167170}],"con":true,"img":false}]}
{"op":"mcm","clk":"5347721090","pt":1646206293984,"mc":[{"id":"1.195453609","rc":[{"atb":[[1.64,27.54]],"id":41719613}],"con":true,"img":false}]}
{"op":"mcm","clk":"5347722730","pt":1646206338415,"mc":[{"id":"1.195453609","rc":[{"atb":[[1.62,0]],"id":41719613},{"spn":1.77,"spf":"NaN","id":41719613},{"atl":[[34,0],[30,3.94]],"id":43167170}],"con":true,"img":false}]}
{"op":"mcm","clk":"5347722732","pt":1646206338517,"mc":[{"id":"1.195453609","rc":[{"atb":[[1.65,69.28]],"id":41719613}],"con":true,"img":false}]}
{"op":"mcm","clk":"5347722922","pt":1646206343197,"mc":[{"id":"1.195453609","rc":[{"atb":[[1.64,11.75]],"id":41719613}],"con":true,"img":false}]}
{"op":"mcm","clk":"5347723004","pt":1646206345047,"mc":[{"id":"1.195453609","rc":[{"atb":[[1.64,0]],"id":41719613}],"con":true,"img":false}]}
{"op":"mcm","clk":"5347723340","pt":1646206354041,"mc":[{"id":"1.195453609","rc":[{"atb":[[1.67,11.23]],"id":41719613}],"con":true,"img":false}]}
{"op":"mcm","clk":"5347723480","pt":1646206358716,"mc":[{"id":"1.195453609","rc":[{"atb":[[1.65,0]],"id":41719613}],"con":true,"img":false}]}
{"op":"mcm","clk":"5347723485","pt":1646206358875,"mc":[{"id":"1.195453609","rc":[{"atb":[[1.62,69.28]],"id":41719613}],"con":true,"img":false}]}
{"op":"mcm","clk":"5347723776","pt":1646206366133,"mc":[{"id":"1.195453609","rc":[{"atb":[[1.67,0]],"id":41719613}],"con":true,"img":false}]}
{"op":"mcm","clk":"5347724166","pt":1646206375076,"mc":[{"id":"1.195453609","rc":[{"atb":[[1.64,11.75]],"id":41719613}],"con":true,"img":false}]}
{"op":"mcm","clk":"5347724316","pt":1646206379093,"mc":[{"id":"1.195453609","rc":[{"atb":[[1.64,27.54]],"id":41719613}],"con":true,"img":false}]}
{"op":"mcm","clk":"5347726421","pt":1646206437183,"mc":[{"id":"1.195453609","rc":[{"atb":[[1.02,2.25]],"id":43167166},{"atb":[[1.02,2.25]],"id":43167167},{"atb":[[1.02,2.25]],"id":43167168},{"atb":[[1.03,2.25]],"id":43167169},{"atb":[[1.02,2.25]],"id":43167170},{"atb":[[1.02,2.25]],"id":43016477}],"con":true,"img":false}]}
{"op":"mcm","clk":"5347726426","pt":1646206437390,"mc":[{"id":"1.195453609","rc":[{"atb":[[1.02,0.39]],"id":43167166},{"atb":[[1.02,0.39]],"id":43167167},{"atb":[[1.02,0.39]],"id":43167168},{"atb":[[1.03,0.48]],"id":43167169},{"atb":[[1.02,0.37]],"id":43167170},{"atb":[[1.02,0.39]],"id":43016477}],"con":true,"img":false}]}
{"op":"mcm","clk":"5347726433","pt":1646206437546,"mc":[{"id":"1.195453609","rc":[{"atb":[[1.02,0]],"id":43167170}],"con":true,"img":false}]}
{"op":"mcm","clk":"5347726437","pt":1646206437649,"mc":[{"id":"1.195453609","rc":[{"atb":[[10,0.37]],"id":43167170}],"con":true,"img":false}]}
{"op":"mcm","clk":"5347726445","pt":1646206437855,"mc":[{"id":"1.195453609","rc":[{"atb":[[1.02,0]],"id":43167168}],"con":true,"img":false}]}
{"op":"mcm","clk":"5347726448","pt":1646206437958,"mc":[{"id":"1.195453609","rc":[{"atb":[[9.4,0.39]],"id":43167168}],"con":true,"img":false}]}
{"op":"mcm","clk":"5347726455","pt":1646206438165,"mc":[{"id":"1.195453609","rc":[{"atb":[[1.03,0]],"id":43167169}],"con":true,"img":false}]}
{"op":"mcm","clk":"5347726459","pt":1646206438276,"mc":[{"id":"1.195453609","rc":[{"atb":[[7.8,0.48]],"id":43167169}],"con":true,"img":false}]}
{"op":"mcm","clk":"5347726465","pt":1646206438474,"mc":[{"id":"1.195453609","rc":[{"atb":[[1.02,0]],"id":43016477}],"con":true,"img":false}]}
{"op":"mcm","clk":"5347726470","pt":1646206438578,"mc":[{"id":"1.195453609","rc":[{"atb":[[9.4,0.39]],"id":43016477}],"con":true,"img":false}]}
{"op":"mcm","clk":"5347726478","pt":1646206438783,"mc":[{"id":"1.195453609","rc":[{"atb":[[1.02,0]],"id":43167166}],"con":true,"img":false}]}
{"op":"mcm","clk":"5347726484","pt":1646206438886,"mc":[{"id":"1.195453609","rc":[{"atb":[[9.4,0.39]],"id":43167166}],"con":true,"img":false}]}
{"op":"mcm","clk":"5347726491","pt":1646206439040,"mc":[{"id":"1.195453609","rc":[{"atb":[[1.02,0]],"id":43167167}],"con":true,"img":false}]}
{"op":"mcm","clk":"5347726495","pt":1646206439143,"mc":[{"id":"1.195453609","rc":[{"atb":[[9.4,0.39]],"id":43167167}],"con":true,"img":false}]}
{"op":"mcm","clk":"5347726569","pt":1646206440955,"mc":[{"id":"1.195453609","rc":[{"atb":[[1.62,0]],"id":41719613}],"con":true,"img":false}]}
{"op":"mcm","clk":"5347726572","pt":1646206441058,"mc":[{"id":"1.195453609","rc":[{"atb":[[1.65,69.28]],"id":41719613}],"con":true,"img":false}]}
{"op":"mcm","clk":"5347726798","pt":1646206447275,"mc":[{"id":"1.195453609","rc":[{"atb":[[1.64,15.78]],"id":41719613}],"con":true,"img":false}]}
{"op":"mcm","clk":"5347727012","pt":1646206453303,"mc":[{"id":"1.195453609","rc":[{"atl":[[32,0],[27,3.85]],"id":43167170}],"con":true,"img":false}]}
{"op":"mcm","clk":"5347727262","pt":1646206459312,"mc":[{"id":"1.195453609","rc":[{"atb":[[1.67,11.23]],"id":41719613}],"con":true,"img":false}]}
{"op":"mcm","clk":"5347727311","pt":1646206460907,"mc":[{"id":"1.195453609","rc":[{"atb":[[1.65,0]],"id":41719613}],"con":true,"img":false}]}
{"op":"mcm","clk":"5347727313","pt":1646206461008,"mc":[{"id":"1.195453609","rc":[{"atb":[[1.62,69.28]],"id":41719613}],"con":true,"img":false}]}
{"op":"mcm","clk":"5347727556","pt":1646206468311,"mc":[{"id":"1.195453609","rc":[{"atb":[[1.67,0]],"id":41719613}],"con":true,"img":false}]}
{"op":"mcm","clk":"5347727882","pt":1646206477305,"mc":[{"id":"1.195453609","rc":[{"atb":[[1.64,27.54]],"id":41719613}],"con":true,"img":false}]}
{"op":"mcm","clk":"5347727950","pt":1646206479509,"mc":[{"id":"1.195453609","rc":[{"atb":[[6.2,0]],"id":43167169}],"con":true,"img":false}]}
{"op":"mcm","clk":"5347727955","pt":1646206479613,"mc":[{"id":"1.195453609","rc":[{"atb":[[6.6,22.37]],"id":43167169}],"con":true,"img":false}]}
{"op":"mcm","clk":"5347728179","pt":1646206486343,"mc":[{"id":"1.195453609","rc":[{"atb":[[6.4,1.87]],"id":43167169}],"con":true,"img":false}]}
{"op":"mcm","clk":"5347728495","pt":1646206495355,"mc":[{"id":"1.195453609","rc":[{"atb":[[1.01,2.25]],"id":43167169}],"con":true,"img":false}]}
{"op":"mcm","clk":"5347728501","pt":1646206495456,"mc":[{"id":"1.195453609","rc":[{"atb":[[1.01,1.29]],"id":43167169}],"con":true,"img":false}]}
{"op":"mcm","clk":"5347728515","pt":1646206495669,"mc":[{"id":"1.195453609","rc":[{"atb":[[1.01,0]],"id":43167169}],"con":true,"img":false}]}
{"op":"mcm","clk":"5347728518","pt":1646206495763,"mc":[{"id":"1.195453609","rc":[{"atb":[[6.8,1.29]],"id":43167169}],"con":true,"img":false}]}
{"op":"mcm","clk":"5347728556","pt":1646206497147,"mc":[{"id":"1.195453609","rc":[{"atb":[[1.03,2.25]],"id":43167165}],"con":true,"img":false}]}
{"op":"mcm","clk":"5347728558","pt":1646206497353,"mc":[{"id":"1.195453609","rc":[{"spn":15.2,"spf":"NaN","id":43167166},{"spn":15.2,"spf":"NaN","id":43167167},{"spn":15.2,"spf":"NaN","id":43167168},{"spn":13.15,"spf":"NaN","id":43167169},{"atb":[[1.03,0.28]],"id":43167165},{"spn":17.0,"spf":"NaN","id":43167170},{"spn":17.2,"spf":"NaN","id":43016477}],"con":true,"img":false}]}
{"op":"mcm","clk":"5347728566","pt":1646206497557,"mc":[{"id":"1.195453609","rc":[{"atb":[[1.03,0]],"id":43167165}],"con":true,"img":false}]}
{"op":"mcm","clk":"5347728571","pt":1646206497660,"mc":[{"id":"1.195453609","rc":[{"atb":[[13,0.28]],"id":43167165}],"con":true,"img":false}]}
{"op":"mcm","clk":"5347728596","pt":1646206498329,"mc":[{"id":"1.195453609","rc":[{"atl":[[30,0]],"id":43167170}],"con":true,"img":false}]}
{"op":"mcm","clk":"5347728603","pt":1646206498432,"mc":[{"id":"1.195453609","rc":[{"atl":[[26,3.94]],"id":43167170}],"con":true,"img":false}]}
{"op":"mcm","clk":"5347728729","pt":1646206502545,"mc":[{"id":"1.195453609","rc":[{"atb":[[6.4,0]],"id":43167169}],"con":true,"img":false}]}
{"op":"mcm","clk":"5347729184","pt":1646206514660,"mc":[{"id":"1.195453609","rc":[{"atb":[[6.8,3.03]],"id":43167169}],"con":true,"img":false}]}
{"op":"mcm","clk":"5347729332","pt":1646206517494,"mc":[{"id":"1.195453609","rc":[{"atb":[[1.62,0]],"id":41719613}],"con":true,"img":false}]}
{"op":"mcm","clk":"5347729336","pt":1646206517597,"mc":[{"id":"1.195453609","rc":[{"atb":[[1.65,69.28]],"id":41719613}],"con":true,"img":false}]}
{"op":"mcm","clk":"5347729538","pt":1646206523499,"mc":[{"id":"1.195453609","rc":[{"atb":[[1.64,11.75]],"id":41719613}],"con":true,"img":false}]}
{"op":"mcm","clk":"5347729590","pt":1646206525399,"mc":[{"id":"1.195453609","rc":[{"atb":[[1.64,0]],"id":41719613}],"con":true,"img":false}]}
{"op":"mcm","clk":"5347729864","pt":1646206534415,"mc":[{"id":"1.195453609","rc":[{"atb":[[1.67,11.23]],"id":41719613}],"con":true,"img":false}]}
{"op":"mcm","clk":"5347729928","pt":1646206537183,"mc":[{"id":"1.195453609","rc":[{"atb":[[1.65,0]],"id":41719613}],"con":true,"img":false}]}
{"op":"mcm","clk":"5347729933","pt":1646206537337,"mc":[{"id":"1.195453609","rc":[{"atb":[[1.62,69.28]],"id":41719613}],"con":true,"img":false}]}
{"op":"mcm","clk":"5347730180","pt":1646206546529,"mc":[{"id":"1.195453609","rc":[{"atb":[[1.67,0]],"id":41719613}],"con":true,"img":false}]}
{"op":"mcm","clk":"5347730567","pt":1646206558460,"mc":[{"id":"1.195453609","rc":[{"atb":[[1.64,11.75]],"id":41719613},{"spn":22.5,"spf":"NaN","id":43167165}],"con":true,"img":false}]}
{"op":"mcm","clk":"5347730700","pt":1646206562632,"mc":[{"id":"1.195453609","rc":[{"atb":[[1.64,27.54]],"id":41719613}],"con":true,"img":false}]}
{"op":"mcm","clk":"5347732439","pt":1646206614344,"mc":[{"id":"1.195453609","rc":[{"atb":[[1.62,0]],"id":41719613},{"atb":[[6.6,0]],"id":43167169}],"con":true,"img":false}]}
{"op":"mcm","clk":"5347732441","pt":1646206614446,"mc":[{"id":"1.195453609","rc":[{"atb":[[1.65,69.28]],"id":41719613},{"atb":[[7,22.37]],"id":43167169}],"con":true,"img":false}]}
{"op":"mcm","clk":"5347732607","pt":1646206621661,"mc":[{"id":"1.195453609","rc":[{"atb":[[1.64,15.78]],"id":41719613},{"spn":1.77,"spf":"NaN","id":41719613},{"atb":[[6.8,1.73]],"id":43167169}],"con":true,"img":false}]}
{"op":"mcm","clk":"5347732908","pt":1646206630546,"mc":[{"id":"1.195453609","rc":[{"atb":[[1.67,11.23]],"id":41719613}],"con":true,"img":false}]}
{"op":"mcm","clk":"5347733219","pt":1646206640562,"mc":[{"id":"1.195453609","rc":[{"atb":[[1.64,0]],"id":41719613},{"atb":[[6.8,0]],"id":43167169}],"con":true,"img":false}]}
{"op":"mcm","clk":"5347733392","pt":1646206645506,"mc":[{"id":"1.195453609","rc":[{"atb":[[1.65,0]],"id":41719613},{"atb":[[7,0]],"id":43167169}],"con":true,"img":false}]}
{"op":"mcm","clk":"5347733397","pt":1646206645608,"mc":[{"id":"1.195453609","rc":[{"atb":[[1.62,69.28]],"id":41719613},{"atb":[[6.2,22.37]],"id":43167169}],"con":true,"img":false}]}
{"op":"mcm","clk":"5347733719","pt":1646206654588,"mc":[{"id":"1.195453609","rc":[{"atb":[[1.67,0]],"id":41719613}],"con":true,"img":false}]}
{"op":"mcm","clk":"5347734138","pt":1646206663598,"mc":[{"id":"1.195453609","rc":[{"atb":[[1.64,11.75]],"id":41719613},{"atb":[[1.01,2.25]],"id":43167169}],"con":true,"img":false}]}
{"op":"mcm","clk":"5347734151","pt":1646206663806,"mc":[{"id":"1.195453609","rc":[{"atb":[[1.01,1.39]],"id":43167169}],"con":true,"img":false}]}
{"op":"mcm","clk":"5347734161","pt":1646206664012,"mc":[{"id":"1.195453609","rc":[{"atb":[[1.01,0]],"id":43167169}],"con":true,"img":false}]}
{"op":"mcm","clk":"5347734165","pt":1646206664115,"mc":[{"id":"1.195453609","rc":[{"atb":[[6.4,1.39]],"id":43167169}],"con":true,"img":false}]}
{"op":"mcm","clk":"5347734317","pt":1646206667518,"mc":[{"id":"1.195453609","rc":[{"atb":[[12.5,0]],"id":43167165}],"con":true,"img":false}]}
{"op":"mcm","clk":"5347734321","pt":1646206667621,"mc":[{"id":"1.195453609","rc":[{"atb":[[11.5,0.96]],"id":43167165}],"con":true,"img":false}]}
{"op":"mcm","clk":"5347734335","pt":1646206668033,"mc":[{"id":"1.195453609","rc":[{"atb":[[1.64,27.54]],"id":41719613},{"atb":[[6.4,3.26]],"id":43167169}],"con":true,"img":false}]}
{"op":"mcm","clk":"5347734719","pt":1646206677551,"mc":[{"id":"1.195453609","rc":[{"atb":[[1.03,2.25],[13,0]],"id":43167165}],"con":true,"img":false}]}
{"op":"mcm","clk":"5347734723","pt":1646206677657,"mc":[{"id":"1.195453609","rc":[{"atb":[[1.03,0.28]],"id":43167165}],"con":true,"img":false}]}
{"op":"mcm","clk":"5347734732","pt":1646206677860,"mc":[{"id":"1.195453609","rc":[{"atb":[[1.03,0]],"id":43167165}],"con":true,"img":false}]}
{"op":"mcm","clk":"5347734737","pt":1646206677912,"mc":[{"id":"1.195453609","rc":[{"atb":[[12,0.28]],"id":43167165}],"con":true,"img":false}]}
{"op":"mcm","clk":"5347735061","pt":1646206685872,"mc":[{"id":"1.195453609","rc":[{"atb":[[5.3,19.03],[5.9,20.41]],"id":43167166},{"atb":[[5.4,21.54],[4.7,0]],"id":43167167},{"spn":1.77,"spf":"NaN","id":41719613},{"atb":[[4.4,0],[5.2,23.81]],"id":43167168},{"atb":[[2.9,46.3],[11.5,0],[4.4,0]],"id":43167165},{"atl":[[38,2.7],[50,0]],"id":43167165},{"spn":22.0,"spf":"NaN","id":43167165},{"atb":[[4.1,0],[4.7,27.03]],"id":43167170},{"atl":[[27,0],[28,3.7]],"id":43167170}],"con":true,"img":false}]}
{"op":"mcm","clk":"5347735067","pt":1646206686077,"mc":[{"id":"1.195453609","rc":[{"atb":[[10.5,1.06]],"id":43167165}],"con":true,"img":false}]}
{"op":"mcm","clk":"5347735707","pt":1646206699599,"mc":[{"id":"1.195453609","rc":[{"atl":[[26,0]],"id":43167170}],"con":true,"img":false}]}
{"op":"mcm","clk":"5347735712","pt":1646206699651,"mc":[{"id":"1.195453609","rc":[{"atl":[[27,3.94]],"id":43167170}],"con":true,"img":false}]}
{"op":"mcm","clk":"5347736078","pt":1646206707572,"mc":[{"id":"1.195453609","rc":[{"atb":[[1.03,2.25],[12,0]],"id":43167165}],"con":true,"img":false}]}
{"op":"mcm","clk":"5347736088","pt":1646206707776,"mc":[{"id":"1.195453609","rc":[{"atb":[[1.03,0.28]],"id":43167165}],"con":true,"img":false}]}
{"op":"mcm","clk":"5347736112","pt":1646206708290,"mc":[{"id":"1.195453609","rc":[{"atb":[[1.03,0]],"id":43167165}],"con":true,"img":false}]}
{"op":"mcm","clk":"5347736118","pt":1646206708393,"mc":[{"id":"1.195453609","rc":[{"atb":[[11.5,0.28]],"id":43167165}],"con":true,"img":false}]}
{"op":"mcm","clk":"5347736145","pt":1646206708907,"mc":[{"id":"1.195453609","rc":[{"atb":[[1.62,0]],"id":41719613}],"con":true,"img":false}]}
{"op":"mcm","clk":"5347736149","pt":1646206709009,"mc":[{"id":"1.195453609","rc":[{"atb":[[1.65,69.28]],"id":41719613}],"con":true,"img":false}]}
{"op":"mcm","clk":"5347736362","pt":1646206713435,"mc":[{"id":"1.195453609","rc":[{"atl":[[38,0],[46,4.94]],"id":43167165}],"con":true,"img":false}]}
{"op":"mcm","clk":"5347736392","pt":1646206714002,"mc":[{"id":"1.195453609","rc":[{"atb":[[11,0]],"id":43167165}],"con":true,"img":false}]}
{"op":"mcm","clk":"5347736398","pt":1646206714104,"mc":[{"id":"1.195453609","rc":[{"atb":[[10.5,6.91]],"id":43167165}],"con":true,"img":false}]}
{"op":"mcm","clk":"5347736579","pt":1646206718729,"mc":[{"id":"1.195453609","rc":[{"atb":[[1.64,15.78]],"id":41719613},{"atb":[[4.8,26.32],[2.9,0]],"id":43167165}],"con":true,"img":false}]}
{"op":"mcm","clk":"5347736584","pt":1646206718832,"mc":[{"id":"1.195453609","rc":[{"atl":[[25,4.17],[28,0]],"id":43167170}],"con":true,"img":false}]}
{"op":"mcm","clk":"5347736868","pt":1646206726641,"mc":[{"id":"1.195453609","rc":[{"atb":[[1.67,11.23]],"id":41719613}],"con":true,"img":false}]}
{"op":"mcm","clk":"5347737007","pt":1646206730214,"mc":[{"id":"1.195453609","rc":[{"atl":[[21,0]],"id":43167166},{"atl":[[21,0]],"id":43167167},{"atb":[[1.61,0]],"id":41719613},{"atl":[[21,0]],"id":43167168},{"atl":[[24,0]],"id":43167170}],"con":true,"img":false}]}
{"op":"mcm","clk":"5347737011","pt":1646206730319,"mc":[{"id":"1.195453609","rc":[{"atl":[[23,2.92]],"id":43167166},{"atl":[[44,2.33],[23,2.78],[50,0]],"id":43167167},{"atb":[[1.51,218.34]],"id":41719613},{"atl":[[23,2.92]],"id":43167168},{"atl":[[25,0],[26,6.72]],"id":43167170}],"con":true,"img":false}]}
{"op":"mcm","clk":"5347737041","pt":1646206731040,"mc":[{"id":"1.195453609","rc":[{"atb":[[1.64,0]],"id":41719613}],"con":true,"img":false}]}
{"op":"mcm","clk":"5347737231","pt":1646206735670,"mc":[{"id":"1.195453609","rc":[{"atb":[[10.5,1.06]],"id":43167165}],"con":true,"img":false}]}
{"op":"mcm","clk":"5347737234","pt":1646206735721,"mc":[{"id":"1.195453609","rc":[{"atb":[[9.6,19.6]],"id":43167165}],"con":true,"img":false}]}
{"op":"mcm","clk":"5347737302","pt":1646206737572,"mc":[{"id":"1.195453609","rc":[{"atb":[[1.03,2.25]],"id":43167165}],"con":true,"img":false}]}
{"op":"mcm","clk":"5347737307","pt":1646206737675,"mc":[{"id":"1.195453609","rc":[{"atb":[[1.03,0.28],[11.5,0]],"id":43167165}],"con":true,"img":false}]}
{"op":"mcm","clk":"5347737312","pt":1646206737726,"mc":[{"id":"1.195453609","rc":[{"atb":[[1.03,0]],"id":43167165}],"con":true,"img":false}]}
{"op":"mcm","clk":"5347737316","pt":1646206737828,"mc":[{"id":"1.195453609","rc":[{"atb":[[11,0.28]],"id":43167165}],"con":true,"img":false}]}
{"op":"mcm","clk":"5347737764","pt":1646206748156,"mc":[{"id":"1.195453609","rc":[{"spn":16.2,"spf":"NaN","id":43167166},{"spn":16.2,"spf":"NaN","id":43167167},{"atb":[[1.65,0]],"id":41719613},{"spn":1.78,"spf":"NaN","id":41719613},{"spn":16.2,"spf":"NaN","id":43167168},{"atl":[[32,0]],"id":43167165},{"spn":28.5,"spf":"NaN","id":43167165},{"atb":[[8.8,0]],"id":43167170},{"spn":18.0,"spf":"NaN","id":43167170}],"con":true,"img":false}]}
{"op":"mcm","clk":"5347737769","pt":1646206748258,"mc":[{"id":"1.195453609","rc":[{"atb":[[1.61,69.28]],"id":41719613},{"atl":[[28,2.72]],"id":43167165},{"atb":[[10,0],[9.2,7.5],[1.02,2.25]],"id":43167170}],"con":true,"img":false}]}
{"op":"mcm","clk":"5347737777","pt":1646206748464,"mc":[{"id":"1.195453609","rc":[{"atb":[[1.02,0.37]],"id":43167170}],"con":true,"img":false}]}
{"op":"mcm","clk":"5347737787","pt":1646206748669,"mc":[{"id":"1.195453609","rc":[{"atb":[[1.02,0]],"id":43167170}],"con":true,"img":false}]}
{"op":"mcm","clk":"5347737792","pt":1646206748773,"mc":[{"id":"1.195453609","rc":[{"atb":[[8.4,0.37]],"id":43167170}],"con":true,"img":false}]}
{"op":"mcm","clk":"5347738004","pt":1646206753600,"mc":[{"id":"1.195453609","rc":[{"atb":[[8.2,0]],"id":43167166},{"atb":[[8.2,0]],"id":43167167},{"atl":[[2.64,8.18]],"id":41719613},{"atb":[[8.2,0]],"id":43167168}],"con":true,"img":false}]}
{"op":"mcm","clk":"5347738008","pt":1646206753702,"mc":[{"id":"1.195453609","rc":[{"atb":[[8.6,8.36]],"id":43167166},{"atb":[[8.8,8.13]],"id":43167167},{"atb":[[8.6,8.36]],"id":43167168},{"atl":[[2.58,35.69]],"id":41719613}],"con":true,"img":false}]}
{"op":"mcm","clk":"5347738011","pt":1646206753753,"mc":[{"id":"1.195453609","rc":[{"atb":[[1.02,2.25]],"id":43167166}],"con":true,"img":false}]}
{"op":"mcm","clk":"5347738015","pt":1646206753856,"mc":[{"id":"1.195453609","rc":[{"atb":[[9.4,0]],"id":43167166},{"atb":[[9.4,0],[1.02,2.25]],"id":43167167}],"con":true,"img":false}]}
{"op":"mcm","clk":"5347738020","pt":1646206753959,"mc":[{"id":"1.195453609","rc":[{"atb":[[1.02,0.39]],"id":43167166},{"atb":[[1.02,2.25]],"id":43167168}],"con":true,"img":false}]}
{"op":"mcm","clk":"5347738023","pt":1646206754061,"mc":[{"id":"1.195453609","rc":[{"atb":[[9.4,0]],"id":43167168}],"con":true,"img":false}]}
{"op":"mcm","clk":"5347738026","pt":1646206754164,"mc":[{"id":"1.195453609","rc":[{"atb":[[1.02,0]],"id":43167166},{"atb":[[1.02,0.39]],"id":43167167}],"con":true,"img":false}]}
{"op":"mcm","clk":"5347738029","pt":1646206754268,"mc":[{"id":"1.195453609","rc":[{"atb":[[8,0.39]],"id":43167166}],"con":true,"img":false}]}
{"op":"mcm","clk":"5347738038","pt":1646206754475,"mc":[{"id":"1.195453609","rc":[{"atb":[[1.02,0]],"id":43167167},{"atb":[[1.02,0.39]],"id":43167168}],"con":true,"img":false}]}
{"op":"mcm","clk":"5347738047","pt":1646206754685,"mc":[{"id":"1.195453609","rc":[{"atb":[[9,0.39]],"id":43167167}],"con":true,"img":false}]}
{"op":"mcm","clk":"5347738056","pt":1646206754897,"mc":[{"id":"1.195453609","rc":[{"atb":[[1.02,0]],"id":43167168}],"con":true,"img":false}]}
{"op":"mcm","clk":"5347738060","pt":1646206755001,"mc":[{"id":"1.195453609","rc":[{"atb":[[8.8,0.39]],"id":43167168}],"con":true,"img":false}]}
{"op":"mcm","clk":"5347738129","pt":1646206756890,"mc":[{"id":"1.195453609","rc":[{"atb":[[1.67,0]],"id":41719613}],"con":true,"img":false}]}
{"op":"mcm","clk":"5347738268","pt":1646206760383,"mc":[{"id":"1.195453609","rc":[{"atb":[[9.6,5.85],[7.6,16.66]],"id":43167165},{"atl":[[36,3.08],[27,0]],"id":43167170}],"con":true,"img":false}]}
{"op":"mcm","clk":"5347738377","pt":1646206762996,"mc":[{"id":"1.195453609","rc":[{"atl":[[26,4]],"id":43167170}],"con":true,"img":false}]}
{"op":"mcm","clk":"5347738380","pt":1646206763099,"mc":[{"id":"1.195453609","rc":[{"atl":[[34,3.03],[25,2.72],[26,0]],"id":43167170}],"con":true,"img":false}]}
{"op":"mcm","clk":"5347738566","pt":1646206768687,"mc":[{"id":"1.195453609","rc":[{"atb":[[1.63,11.94]],"id":41719613}],"con":true,"img":false}]}
{"op":"mcm","clk":"5347738651","pt":1646206770590,"mc":[{"id":"1.195453609","rc":[{"atb":[[1.63,27.97]],"id":41719613}],"con":true,"img":false}]}
{"op":"mcm","clk":"5347738779","pt":1646206775323,"mc":[{"id":"1.195453609","rc":[{"atl":[[23,0]],"id":43167167}],"con":true,"img":false}]}
{"op":"mcm","clk":"5347738782","pt":1646206775425,"mc":[{"id":"1.195453609","rc":[{"atl":[[24,2.78]],"id":43167167}],"con":true,"img":false}]}
{"op":"mcm","clk":"5347738787","pt":1646206775528,"mc":[{"id":"1.195453609","rc":[{"atl":[[44,0],[55,2]],"id":43167167}],"con":true,"img":false}]}
{"op":"mcm","clk":"5347739262","pt":1646206790044,"mc":[{"id":"1.195453609","rc":[{"atl":[[28,0]],"id":43167165},{"atl":[[25,0]],"id":43167170}],"con":true,"img":false}]}
{"op":"mcm","clk":"5347739270","pt":1646206790147,"mc":[{"id":"1.195453609","rc":[{"atl":[[26,2.72]],"id":43167165},{"atl":[[26,2.72]],"id":43167170}],"con":true,"img":false}]}
{"op":"mcm","clk":"5347739276","pt":1646206790249,"mc":[{"id":"1.195453609","rc":[{"atl":[[46,2.72],[55,4.47]],"id":43167165}],"con":true,"img":false}]}
{"op":"mcm","clk":"5347739476","pt":1646206795239,"mc":[{"id":"1.195453609","rc":[{"atl":[[34,0],[29,3.57]],"id":43167170}],"con":true,"img":false}]}
{"op":"mcm","clk":"5347739871","pt":1646206805161,"mc":[{"id":"1.195453609","rc":[{"atb":[[8.8,0]],"id":43167167},{"atb":[[1.61,0]],"id":41719613}],"con":true,"img":false}]}
{"op":"mcm","clk":"5347739875","pt":1646206805264,"mc":[{"id":"1.195453609","rc":[{"atb":[[9,8.53]],"id":43167167},{"atb":[[1.64,69.28]],"id":41719613}],"con":true,"img":false}]}
{"op":"mcm","clk":"5347740184","pt":1646206813897,"mc":[{"id":"1.195453609","rc":[{"spn":16.1,"spf":"NaN","id":43167166},{"spn":16.6,"spf":"NaN","id":43167167},{"atb":[[1.63,16.03]],"id":41719613},{"spn":1.77,"spf":"NaN","id":41719613},{"spn":16.1,"spf":"NaN","id":43167168},{"spn":18.5,"spf":"NaN","id":43167165},{"spn":17.9,"spf":"NaN","id":43167170}],"con":true,"img":false}]}
{"op":"mcm","clk":"5347740217","pt":1646206814462,"mc":[{"id":"1.195453609","rc":[{"atl":[[2.64,0]],"id":41719613}],"con":true,"img":false}]}
{"op":"mcm","clk":"5347740561","pt":1646206822897,"mc":[{"id":"1.195453609","rc":[{"atb":[[1.66,11.4]],"id":41719613}],"con":true,"img":false}]}
{"op":"mcm","clk":"5347740713","pt":1646206827063,"mc":[{"id":"1.195453609","rc":[{"atb":[[1.63,0]],"id":41719613}],"con":true,"img":false}]}
{"op":"mcm","clk":"5347740739","pt":1646206827682,"mc":[{"id":"1.195453609","rc":[{"atb":[[8,0],[1.02,2.25]],"id":43167166},{"atb":[[9,8.13],[1.02,2.25]],"id":43167167},{"atb":[[1.02,2.25],[8.8,0]],"id":43167168},{"atb":[[8.4,0],[1.02,2.25]],"id":43167170}],"con":true,"img":false}]}
{"op":"mcm","clk":"5347740747","pt":1646206827888,"mc":[{"id":"1.195453609","rc":[{"atb":[[1.02,0.39]],"id":43167166},{"atb":[[1.02,0.39]],"id":43167167},{"atb":[[1.02,0.39]],"id":43167168},{"atb":[[1.02,0.37]],"id":43167170}],"con":true,"img":false}]}
{"op":"mcm","clk":"5347740759","pt":1646206828198,"mc":[{"id":"1.195453609","rc":[{"atb":[[1.02,0]],"id":43167166}],"con":true,"img":false}]}
{"op":"mcm","clk":"5347740762","pt":1646206828299,"mc":[{"id":"1.195453609","rc":[{"atb":[[9.4,0.39]],"id":43167166}],"con":true,"img":false}]}
{"op":"mcm","clk":"5347740768","pt":1646206828505,"mc":[{"id":"1.195453609","rc":[{"atb":[[1.02,0]],"id":43167167}],"con":true,"img":false}]}
{"op":"mcm","clk":"5347740772","pt":1646206828609,"mc":[{"id":"1.195453609","rc":[{"atb":[[9.4,0.39]],"id":43167167}],"con":true,"img":false}]}
{"op":"mcm","clk":"5347740819","pt":1646206829382,"mc":[{"id":"1.195453609","rc":[{"atb":[[1.64,0]],"id":41719613},{"atl":[[46,0]],"id":43167165},{"atb":[[1.02,0]],"id":43167170},{"atl":[[36,0],[28,4.23]],"id":43167170}],"con":true,"img":false}]}
{"op":"mcm","clk":"5347740827","pt":1646206829486,"mc":[{"id":"1.195453609","rc":[{"atb":[[1.61,69.28]],"id":41719613},{"atl":[[36,2.72]],"id":43167165},{"atb":[[10,0.37]],"id":43167170}],"con":true,"img":false}]}
{"op":"mcm","clk":"5347740834","pt":1646206829689,"mc":[{"id":"1.195453609","rc":[{"atb":[[1.02,0]],"id":43167168}],"con":true,"img":false}]}
{"op":"mcm","clk":"5347740839","pt":1646206829794,"mc":[{"id":"1.195453609","rc":[{"atb":[[9.4,0.39]],"id":43167168}],"con":true,"img":false}]}
{"op":"mcm","clk":"5347740884","pt":1646206831387,"mc":[{"id":"1.195453609","rc":[{"atl":[[26,6.29],[29,0]],"id":43167170}],"con":true,"img":false}]}
{"op":"mcm","clk":"5347740951","pt":1646206833395,"mc":[{"id":"1.195453609","rc":[{"atb":[[5.3,40.57],[5.9,0]],"id":43167166},{"atb":[[5.4,0],[4.7,27.03]],"id":43167167},{"atb":[[4.4,29.41],[5.2,0]],"id":43167168},{"atb":[[4.1,32.26],[4.7,0]],"id":43167170},{"atl":[[26,2.72],[27,3.85]],"id":43167170}],"con":true,"img":false}]}
{"op":"mcm","clk":"5347741035","pt":1646206835702,"mc":[{"id":"1.195453609","rc":[{"atb":[[4.4,0]],"id":43167168},{"atb":[[4.4,0],[3.05,46.3]],"id":43016477}],"con":true,"img":false}]}
{"op":"mcm","clk":"5347741045","pt":1646206835908,"mc":[{"id":"1.195453609","rc":[{"atb":[[4.8,47.86]],"id":43167168}],"con":true,"img":false}]}
{"op":"mcm","clk":"5347741138","pt":1646206837884,"mc":[{"id":"1.195453609","rc":[{"atb":[[1.66,0]],"id":41719613}],"con":true,"img":false}]}
{"op":"mcm","clk":"5347741468","pt":1646206846892,"mc":[{"id":"1.195453609","rc":[{"atb":[[1.63,11.94]],"id":41719613}],"con":true,"img":false}]}
{"op":"mcm","clk":"5347741874","pt":1646206857646,"mc":[{"id":"1.195453609","rc":[{"atb":[[1.63,27.97]],"id":41719613}],"con":true,"img":false}]}
{"op":"mcm","clk":"5347742194","pt":1646206864048,"mc":[{"id":"1.195453609","rc":[{"atl":[[26,0]],"id":43167165}],"con":true,"img":false}]}
{"op":"mcm","clk":"5347742198","pt":1646206864155,"mc":[{"id":"1.195453609","rc":[{"atl":[[25,2.72]],"id":43167165}],"con":true,"img":false}]}
{"op":"mcm","clk":"5347742217","pt":1646206864873,"mc":[{"id":"1.195453609","rc":[{"atb":[[5.3,19.03],[6,20]],"id":43167166},{"atb":[[5.3,40.57],[4.7,0]],"id":43167167}],"con":true,"img":false}]}
{"op":"mcm","clk":"5347742318","pt":1646206867139,"mc":[{"id":"1.195453609","rc":[{"atb":[[4.5,28.57],[3.05,0]],"id":43016477}],"con":true,"img":false}]}
{"op":"mcm","clk":"5347742824","pt":1646206880462,"mc":[{"id":"1.195453609","rc":[{"spn":16.2,"spf":"NaN","id":43167166},{"spn":16.7,"spf":"NaN","id":43167167},{"spn":1.76,"spf":"NaN","id":41719613},{"spn":16.2,"spf":"NaN","id":43167168},{"spn":18.0,"spf":"NaN","id":43167165},{"atl":[[26,0]],"id":43167170},{"spn":18.5,"spf":"NaN","id":43167170}],"con":true,"img":false}]}
{"op":"mcm","clk":"5347742828","pt":1646206880562,"mc":[{"id":"1.195453609","rc":[{"atl":[[25,2.72]],"id":43167170}],"con":true,"img":false}]}
{"op":"mcm","clk":"5347742836","pt":1646206880666,"mc":[{"id":"1.195453609","rc":[{"atl":[[25,6.57]],"id":43167170}],"con":true,"img":false}]}
{"op":"mcm","clk":"5347742842","pt":1646206880769,"mc":[{"id":"1.195453609","rc":[{"atl":[[27,0]],"id":43167170}],"con":true,"img":false}]}
{"op":"mcm","clk":"5347743360","pt":1646206892909,"mc":[{"id":"1.195453609","rc":[{"atl":[[25,2.72],[30,3.45]],"id":43167170}],"con":true,"img":false}]}
{"op":"mcm","clk":"5347743441","pt":1646206895230,"mc":[{"id":"1.195453609","rc":[{"atb":[[1.61,0]],"id":41719613},{"atl":[[28,0]],"id":43167170}],"con":true,"img":false}]}
{"op":"mcm","clk":"5347743446","pt":1646206895360,"mc":[{"id":"1.195453609","rc":[{"atb":[[1.64,69.28]],"id":41719613},{"atl":[[25,6.96]],"id":43167170}],"con":true,"img":false}]}
{"op":"mcm","clk":"5347743562","pt":1646206898212,"mc":[{"id":"1.195453609","rc":[{"atl":[[25,2.72]],"id":43167170}],"con":true,"img":false}]}
{"op":"mcm","clk":"5347743565","pt":1646206898316,"mc":[{"id":"1.195453609","rc":[{"atl":[[29,4.23]],"id":43167170}],"con":true,"img":false}]}
{"op":"mcm","clk":"5347743791","pt":1646206904131,"mc":[{"id":"1.195453609","rc":[{"atb":[[1.63,16.03]],"id":41719613}],"con":true,"img":false}]}
{"op":"mcm","clk":"5347744116","pt":1646206913005,"mc":[{"id":"1.195453609","rc":[{"atb":[[1.66,11.4]],"id":41719613}],"con":true,"img":false}]}
{"op":"mcm","clk":"5347744186","pt":1646206914919,"mc":[{"id":"1.195453609","rc":[{"atb":[[1.64,0]],"id":41719613}],"con":true,"img":false}]}
{"op":"mcm","clk":"5347744192","pt":1646206915015,"mc":[{"id":"1.195453609","rc":[{"atb":[[1.61,69.28]],"id":41719613}],"con":true,"img":false}]}
{"op":"mcm","clk":"5347744207","pt":1646206915323,"mc":[{"id":"1.195453609","rc":[{"atb":[[1.63,0]],"id":41719613}],"con":true,"img":false}]}
{"op":"mcm","clk":"5347744484","pt":1646206922125,"mc":[{"id":"1.195453609","rc":[{"atb":[[1.66,0]],"id":41719613}],"con":true,"img":false}]}
{"op":"mcm","clk":"5347744863","pt":1646206931055,"mc":[{"id":"1.195453609","rc":[{"atb":[[1.63,11.94]],"id":41719613}],"con":true,"img":false}]}
{"op":"mcm","clk":"5347745278","pt":1646206941463,"mc":[{"id":"1.195453609","rc":[{"atb":[[1.63,27.97]],"id":41719613},{"spn":17.5,"spf":"NaN","id":43167170}],"con":true,"img":false}]}
{"op":"mcm","clk":"5347745841","pt":1646206953576,"mc":[{"id":"1.195453609","rc":[{"atb":[[6.2,0]],"id":43167169}],"con":true,"img":false}]}
{"op":"mcm","clk":"5347745846","pt":1646206953686,"mc":[{"id":"1.195453609","rc":[{"atb":[[6.6,22.37]],"id":43167169}],"con":true,"img":false}]}
{"op":"mcm","clk":"5347745914","pt":1646206955680,"mc":[{"id":"1.195453609","rc":[{"atb":[[5.3,40.57],[6,0]],"id":43167166},{"atb":[[5.3,19.03],[4.7,27.03]],"id":43167167},{"atl":[[32,3.23],[30,0]],"id":43167170}],"con":true,"img":false}]}
{"op":"mcm","clk":"5347746177","pt":1646206961290,"mc":[{"id":"1.195453609","rc":[{"atb":[[6.4,1.87]],"id":43167169}],"con":true,"img":false}]}
{"op":"mcm","clk":"5347746544","pt":1646206970412,"mc":[{"id":"1.195453609","rc":[{"atb":[[1.01,2.25]],"id":43167169}],"con":true,"img":false}]}
{"op":"mcm","clk":"5347746549","pt":1646206970616,"mc":[{"id":"1.195453609","rc":[{"atb":[[1.01,1.29]],"id":43167169},{"atl":[[29,0]],"id":43167170}],"con":true,"img":false}]}
{"op":"mcm","clk":"5347746553","pt":1646206970721,"mc":[{"id":"1.195453609","rc":[{"atl":[[30,4.23]],"id":43167170}],"con":true,"img":false}]}
{"op":"mcm","clk":"5347746560","pt":1646206970823,"mc":[{"id":"1.195453609","rc":[{"atb":[[1.01,0]],"id":43167169}],"con":true,"img":false}]}
{"op":"mcm","clk":"5347746566","pt":1646206970928,"mc":[{"id":"1.195453609","rc":[{"atb":[[6.8,1.29]],"id":43167169}],"con":true,"img":false}]}
{"op":"mcm","clk":"5347746866","pt":1646206977217,"mc":[{"id":"1.195453609","rc":[{"atb":[[6.4,0]],"id":43167169}],"con":true,"img":false}]}
{"op":"mcm","clk":"5347747086","pt":1646206982232,"mc":[{"id":"1.195453609","rc":[{"atb":[[1.04,1.67]],"id":41719613}],"con":true,"img":false}]}
{"op":"mcm","clk":"5347747094","pt":1646206982438,"mc":[{"id":"1.195453609","rc":[{"atb":[[1.04,1.66]],"id":41719613}],"con":true,"img":false}]}
{"op":"mcm","clk":"5347747106","pt":1646206982746,"mc":[{"id":"1.195453609","rc":[{"atb":[[1.04,0]],"id":41719613}],"con":true,"img":false}]}
{"op":"mcm","clk":"5347747112","pt":1646206982808,"mc":[{"id":"1.195453609","rc":[{"atb":[[1.66,1.66]],"id":41719613}],"con":true,"img":false}]}
{"op":"mcm","clk":"5347747313","pt":1646206986827,"mc":[{"id":"1.195453609","rc":[{"atb":[[6.8,3.03]],"id":43167169}],"con":true,"img":false}]}
{"op":"mcm","clk":"5347747434","pt":1646206989447,"mc":[{"id":"1.195453609","rc":[{"atb":[[1.61,0]],"id":41719613}],"con":true,"img":false}]}
{"op":"mcm","clk":"5347747438","pt":1646206989547,"mc":[{"id":"1.195453609","rc":[{"atb":[[1.64,69.28]],"id":41719613}],"con":true,"img":false}]}
{"op":"mcm","clk":"5347747749","pt":1646206997331,"mc":[{"id":"1.195453609","rc":[{"atb":[[1.63,16.03]],"id":41719613}],"con":true,"img":false}]}
{"op":"mcm","clk":"5347748186","pt":1646207009287,"mc":[{"id":"1.195453609","rc":[{"atb":[[1.66,13.06]],"id":41719613},{"spn":1.78,"spf":"NaN","id":41719613}],"con":true,"img":false}]}
{"op":"mcm","clk":"5347748234","pt":1646207010575,"mc":[{"id":"1.195453609","rc":[{"atb":[[1.63,0]],"id":41719613}],"con":true,"img":false}]}
{"op":"mcm","clk":"5347748284","pt":1646207011759,"mc":[{"id":"1.195453609","rc":[{"atb":[[1.64,0]],"id":41719613}],"con":true,"img":false}]}
{"op":"mcm","clk":"5347748287","pt":1646207011860,"mc":[{"id":"1.195453609","rc":[{"atb":[[1.61,69.28]],"id":41719613}],"con":true,"img":false}]}
{"op":"mcm","clk":"5347748381","pt":1646207013966,"mc":[{"id":"1.195453609","rc":[{"atl":[[28,3.7]],"id":43167170}],"con":true,"img":false}]}
{"op":"mcm","clk":"5347748385","pt":1646207014070,"mc":[{"id":"1.195453609","rc":[{"atl":[[32,0]],"id":43167170}],"con":true,"img":false}]}
{"op":"mcm","clk":"5347748565","pt":1646207018394,"mc":[{"id":"1.195453609","rc":[{"atb":[[1.66,1.66]],"id":41719613}],"con":true,"img":false}]}
{"op":"mcm","clk":"5347748906","pt":1646207027406,"mc":[{"id":"1.195453609","rc":[{"atb":[[1.63,11.94]],"id":41719613}],"con":true,"img":false}]}
{"op":"mcm","clk":"5347749028","pt":1646207030902,"mc":[{"id":"1.195453609","rc":[{"atb":[[6.6,0]],"id":43167169}],"con":true,"img":false}]}
{"op":"mcm","clk":"5347749030","pt":1646207031002,"mc":[{"id":"1.195453609","rc":[{"atb":[[7,22.37]],"id":43167169}],"con":true,"img":false}]}
{"op":"mcm","clk":"5347749171","pt":1646207034707,"mc":[{"id":"1.195453609","rc":[{"atb":[[1.63,27.97]],"id":41719613}],"con":true,"img":false}]}
{"op":"mcm","clk":"5347749320","pt":1646207039347,"mc":[{"id":"1.195453609","rc":[{"atb":[[6.8,1.73]],"id":43167169}],"con":true,"img":false}]}
{"op":"mcm","clk":"5347749546","pt":1646207044944,"mc":[{"id":"1.195453609","rc":[{"atb":[[7,0]],"id":43167169}],"con":true,"img":false}]}
{"op":"mcm","clk":"5347749549","pt":1646207044997,"mc":[{"id":"1.195453609","rc":[{"atb":[[6.8,24.11]],"id":43167169}],"con":true,"img":false}]}
{"op":"mcm","clk":"5347749594","pt":1646207046637,"mc":[{"id":"1.195453609","rc":[{"atb":[[6.8,22.37]],"id":43167169}],"con":true,"img":false}]}
{"op":"mcm","clk":"5347750342","pt":1646207066164,"mc":[{"id":"1.195453609","rc":[{"atl":[[30,0]],"id":43167170}],"con":true,"img":false}]}
{"op":"mcm","clk":"5347750349","pt":1646207066267,"mc":[{"id":"1.195453609","rc":[{"atl":[[27,4.23]],"id":43167170}],"con":true,"img":false}]}
{"op":"mcm","clk":"5347750534","pt":1646207070988,"mc":[{"id":"1.195453609","rc":[{"atb":[[3.05,0]],"id":43167170}],"con":true,"img":false}]}
{"op":"mcm","clk":"5347751047","pt":1646207084598,"mc":[{"id":"1.195453609","rc":[{"atb":[[1.61,0]],"id":41719613}],"con":true,"img":false}]}
{"op":"mcm","clk":"5347751056","pt":1646207084708,"mc":[{"id":"1.195453609","rc":[{"atb":[[1.64,69.28]],"id":41719613}],"con":true,"img":false}]}
{"op":"mcm","clk":"5347751425","pt":1646207093522,"mc":[{"id":"1.195453609","rc":[{"atb":[[1.63,16.03]],"id":41719613}],"con":true,"img":false}]}
{"op":"mcm","clk":"5347751754","pt":1646207101009,"mc":[{"id":"1.195453609","rc":[{"atb":[[1.64,0]],"id":41719613}],"con":true,"img":false}]}
{"op":"mcm","clk":"5347751759","pt":1646207101113,"mc":[{"id":"1.195453609","rc":[{"atb":[[1.61,69.28]],"id":41719613}],"con":true,"img":false}]}
{"op":"mcm","clk":"5347752135","pt":1646207108929,"mc":[{"id":"1.195453609","rc":[{"atb":[[2.96,0]],"id":43167167}],"con":true,"img":false}]}
{"op":"mcm","clk":"5347752518","pt":1646207117424,"mc":[{"id":"1.195453609","rc":[{"atb":[[1.63,27.97]],"id":41719613}],"con":true,"img":false}]}
{"op":"mcm","clk":"5347753640","pt":1646207139456,"mc":[{"id":"1.195453609","rc":[{"atb":[[9.2,0]],"id":43167166},{"atb":[[9.2,0]],"id":43167168},{"atb":[[9.8,0]],"id":43167170}],"con":true,"img":false}]}
{"op":"mcm","clk":"5347753694","pt":1646207139581,"mc":[{"id":"1.195453609","rc":[{"atb":[[9.4,1.59]],"id":43167166},{"atb":[[9.4,1.59]],"id":43167168},{"atb":[[10.5,1.06]],"id":43167170}],"con":true,"img":false}]}
{"op":"mcm","clk":"5347755003","pt":1646207163895,"mc":[{"id":"1.195453609","rc":[{"atb":[[1.61,0]],"id":41719613}],"con":true,"img":false}]}
{"op":"mcm","clk":"5347755011","pt":1646207163989,"mc":[{"id":"1.195453609","rc":[{"atb":[[1.64,69.28]],"id":41719613}],"con":true,"img":false}]}
{"op":"mcm","clk":"5347755523","pt":1646207171512,"mc":[{"id":"1.195453609","rc":[{"atb":[[1.63,16.03]],"id":41719613}],"con":true,"img":false}]}
{"op":"mcm","clk":"5347755844","pt":1646207176113,"mc":[{"id":"1.195453609","rc":[{"atb":[[1.63,0]],"id":41719613}],"con":true,"img":false}]}
{"op":"mcm","clk":"5347756086","pt":1646207179929,"mc":[{"id":"1.195453609","rc":[{"atb":[[1.64,0]],"id":41719613}],"con":true,"img":false}]}
{"op":"mcm","clk":"5347756096","pt":1646207180034,"mc":[{"id":"1.195453609","rc":[{"atb":[[1.61,69.28]],"id":41719613}],"con":true,"img":false}]}
{"op":"mcm","clk":"5347757289","pt":1646207195674,"mc":[{"id":"1.195453609","rc":[{"atb":[[1.63,11.94]],"id":41719613}],"con":true,"img":false}]}
{"op":"mcm","clk":"5347757584","pt":1646207199957,"mc":[{"id":"1.195453609","rc":[{"atb":[[1.63,27.97]],"id":41719613},{"spn":17.75,"spf":"NaN","id":43167170}],"con":true,"img":false}]}
{"op":"mcm","clk":"5347758565","pt":1646207215280,"mc":[{"id":"1.195453609","rc":[{"atb":[[10,0],[1.02,2.25]],"id":43167170}],"con":true,"img":false}]}
{"op":"mcm","clk":"5347758578","pt":1646207215386,"mc":[{"id":"1.195453609","rc":[{"atb":[[1.02,0.33]],"id":43167170}],"con":true,"img":false}]}
{"op":"mcm","clk":"5347758585","pt":1646207215485,"mc":[{"id":"1.195453609","rc":[{"atb":[[1.02,0]],"id":43167170}],"con":true,"img":false}]}
{"op":"mcm","clk":"5347758593","pt":1646207215588,"mc":[{"id":"1.195453609","rc":[{"atb":[[11,0.33]],"id":43167170}],"con":true,"img":false}]}
{"op":"mcm","clk":"5347760538","pt":1646207251357,"mc":[{"id":"1.195453609","rc":[{"atb":[[1.61,0]],"id":41719613}],"con":true,"img":false}]}
{"op":"mcm","clk":"5347760544","pt":1646207251462,"mc":[{"id":"1.195453609","rc":[{"atb":[[1.64,69.28]],"id":41719613}],"con":true,"img":false}]}
{"op":"mcm","clk":"5347760883","pt":1646207258780,"mc":[{"id":"1.195453609","rc":[{"atb":[[1.63,16.03]],"id":41719613}],"con":true,"img":false}]}
{"op":"mcm","clk":"5347761307","pt":1646207266168,"mc":[{"id":"1.195453609","rc":[{"atb":[[1.63,0]],"id":41719613},{"spn":18.0,"spf":"NaN","id":43167170}],"con":true,"img":false}]}
{"op":"mcm","clk":"5347761321","pt":1646207266475,"mc":[{"id":"1.195453609","rc":[{"atb":[[1.64,0]],"id":41719613}],"con":true,"img":false}]}
{"op":"mcm","clk":"5347761327","pt":1646207266577,"mc":[{"id":"1.195453609","rc":[{"atb":[[1.61,69.28]],"id":41719613}],"con":true,"img":false}]}
{"op":"mcm","clk":"5347762174","pt":1646207282785,"mc":[{"id":"1.195453609","rc":[{"atb":[[1.63,11.94]],"id":41719613}],"con":true,"img":false}]}
{"op":"mcm","clk":"5347762888","pt":1646207296309,"mc":[{"id":"1.195453609","rc":[{"atb":[[1.63,27.97]],"id":41719613}],"con":true,"img":false}]}
{"op":"mcm","clk":"5347764569","pt":1646207329758,"mc":[{"id":"1.195453609","rc":[{"atb":[[1.61,0]],"id":41719613}],"con":true,"img":false}]}
{"op":"mcm","clk":"5347764573","pt":1646207329860,"mc":[{"id":"1.195453609","rc":[{"atb":[[1.64,69.28]],"id":41719613}],"con":true,"img":false}]}
{"op":"mcm","clk":"5347764915","pt":1646207336875,"mc":[{"id":"1.195453609","rc":[{"atb":[[1.63,16.03]],"id":41719613}],"con":true,"img":false}]}
{"op":"mcm","clk":"5347765254","pt":1646207343314,"mc":[{"id":"1.195453609","rc":[{"atl":[[28,0],[30,3.45]],"id":43167170}],"con":true,"img":false}]}
{"op":"mcm","clk":"5347765380","pt":1646207345911,"mc":[{"id":"1.195453609","rc":[{"atb":[[1.66,13.06]],"id":41719613}],"con":true,"img":false}]}
{"op":"mcm","clk":"5347765416","pt":1646207346581,"mc":[{"id":"1.195453609","rc":[{"atb":[[1.64,0]],"id":41719613},{"atl":[[27,0]],"id":43167170}],"con":true,"img":false}]}
{"op":"mcm","clk":"5347765420","pt":1646207346685,"mc":[{"id":"1.195453609","rc":[{"atb":[[1.61,69.28]],"id":41719613},{"atl":[[29,4.23]],"id":43167170}],"con":true,"img":false}]}
{"op":"mcm","clk":"5347765710","pt":1646207353121,"mc":[{"id":"1.195453609","rc":[{"atb":[[5.3,19.03],[3.9,34.48]],"id":43167166},{"atb":[[3.35,42.55],[4.7,0]],"id":43167167},{"atb":[[4.8,21.54],[3.2,44.07]],"id":43167168},{"atb":[[4.1,0],[4.7,27.03]],"id":43167170},{"atb":[[4.5,0],[3.7,37.04]],"id":43016477}],"con":true,"img":false}]}
{"op":"mcm","clk":"5347765719","pt":1646207353315,"mc":[{"id":"1.195453609","rc":[{"atb":[[6.4,18.52],[3.9,0]],"id":43167166}],"con":true,"img":false}]}
{"op":"mcm","clk":"5347765799","pt":1646207354913,"mc":[{"id":"1.195453609","rc":[{"atb":[[1.66,1.66]],"id":41719613}],"con":true,"img":false}]}
{"op":"mcm","clk":"5347766224","pt":1646207363928,"mc":[{"id":"1.195453609","rc":[{"atb":[[1.63,27.97]],"id":41719613}],"con":true,"img":false}]}
{"op":"mcm","clk":"5347766451","pt":1646207369636,"mc":[{"id":"1.195453609","rc":[{"atl":[[29,7.8],[30,0]],"id":43167170}],"con":true,"img":false}]}
{"op":"mcm","clk":"5347766631","pt":1646207373257,"mc":[{"id":"1.195453609","rc":[{"atb":[[4.8,0],[3.2,45.45]],"id":43167165},{"atb":[[4.1,32.26],[4.7,0]],"id":43167170},{"atl":[[28,3.7],[29,4.23]],"id":43167170}],"con":true,"img":false}]}
{"op":"mcm","clk":"5347766643","pt":1646207373461,"mc":[{"id":"1.195453609","rc":[{"atb":[[3.2,0],[4.9,25.64]],"id":43167165}],"con":true,"img":false}]}
{"op":"mcm","clk":"5347766901","pt":1646207379342,"mc":[{"id":"1.195453609","rc":[{"atb":[[3.35,0],[4.7,27.03]],"id":43167167},{"atb":[[4.8,47.86],[3.2,0]],"id":43167168},{"atb":[[4.3,101.74],[3.7,0]],"id":43016477}],"con":true,"img":false}]}
{"op":"mcm","clk":"5347768540","pt":1646207413219,"mc":[{"id":"1.195453609","rc":[{"atb":[[1.61,0]],"id":41719613}],"con":true,"img":false}]}
{"op":"mcm","clk":"5347768547","pt":1646207413274,"mc":[{"id":"1.195453609","rc":[{"atb":[[1.64,69.28]],"id":41719613}],"con":true,"img":false}]}
{"op":"mcm","clk":"5347768925","pt":1646207421089,"mc":[{"id":"1.195453609","rc":[{"atb":[[1.63,16.03]],"id":41719613}],"con":true,"img":false}]}
{"op":"mcm","clk":"5347769174","pt":1646207425725,"mc":[{"id":"1.195453609","rc":[{"atb":[[1.63,0]],"id":41719613}],"con":true,"img":false}]}
{"op":"mcm","clk":"5347769356","pt":1646207429638,"mc":[{"id":"1.195453609","rc":[{"atb":[[1.64,0]],"id":41719613},{"atl":[[29,0]],"id":43167170}],"con":true,"img":false}]}
{"op":"mcm","clk":"5347769363","pt":1646207429699,"mc":[{"id":"1.195453609","rc":[{"atb":[[1.61,69.28]],"id":41719613},{"atl":[[27,4.23]],"id":43167170}],"con":true,"img":false}]}
{"op":"mcm","clk":"5347770107","pt":1646207445132,"mc":[{"id":"1.195453609","rc":[{"atb":[[1.63,11.94]],"id":41719613}],"con":true,"img":false}]}
{"op":"mcm","clk":"5347770314","pt":1646207449125,"mc":[{"id":"1.195453609","rc":[{"atb":[[1.63,27.97]],"id":41719613}],"con":true,"img":false}]}
{"op":"mcm","clk":"5347772693","pt":1646207493290,"mc":[{"id":"1.195453609","rc":[{"atb":[[6.4,0],[5.3,40.57]],"id":43167166},{"atl":[[28,0],[30,3.45]],"id":43167170}],"con":true,"img":false}]}
{"op":"mcm","clk":"5347773014","pt":1646207499094,"mc":[{"id":"1.195453609","rc":[{"atb":[[1.61,0]],"id":41719613},{"atl":[[27,0]],"id":43167170}],"con":true,"img":false}]}
{"op":"mcm","clk":"5347773019","pt":1646207499195,"mc":[{"id":"1.195453609","rc":[{"atb":[[1.64,69.28]],"id":41719613},{"atl":[[29,4.23]],"id":43167170}],"con":true,"img":false}]}
{"op":"mcm","clk":"5347773551","pt":1646207508302,"mc":[{"id":"1.195453609","rc":[{"atb":[[1.63,16.03]],"id":41719613}],"con":true,"img":false}]}
{"op":"mcm","clk":"5347774051","pt":1646207517293,"mc":[{"id":"1.195453609","rc":[{"atb":[[1.66,13.06]],"id":41719613}],"con":true,"img":false}]}
{"op":"mcm","clk":"5347774098","pt":1646207518109,"mc":[{"id":"1.195453609","rc":[{"atb":[[1.64,0]],"id":41719613}],"con":true,"img":false}]}
{"op":"mcm","clk":"5347774107","pt":1646207518212,"mc":[{"id":"1.195453609","rc":[{"atb":[[1.61,69.28]],"id":41719613}],"con":true,"img":false}]}
{"op":"mcm","clk":"5347774121","pt":1646207518418,"mc":[{"id":"1.195453609","rc":[{"atb":[[1.63,0]],"id":41719613}],"con":true,"img":false}]}
{"op":"mcm","clk":"5347774580","pt":1646207526312,"mc":[{"id":"1.195453609","rc":[{"atb":[[1.66,1.66]],"id":41719613}],"con":true,"img":false}]}
{"op":"mcm","clk":"5347775138","pt":1646207536325,"mc":[{"id":"1.195453609","rc":[{"atb":[[1.63,11.94]],"id":41719613}],"con":true,"img":false}]}
{"op":"mcm","clk":"5347775702","pt":1646207545363,"mc":[{"id":"1.195453609","rc":[{"atb":[[1.63,27.97]],"id":41719613}],"con":true,"img":false}]}
{"op":"mcm","clk":"5347777787","pt":1646207582496,"mc":[{"id":"1.195453609","rc":[{"atb":[[1.61,0]],"id":41719613}],"con":true,"img":false}]}
{"op":"mcm","clk":"5347777797","pt":1646207582600,"mc":[{"id":"1.195453609","rc":[{"atb":[[1.64,69.28]],"id":41719613}],"con":true,"img":false}]}
{"op":"mcm","clk":"5347778136","pt":1646207589478,"mc":[{"id":"1.195453609","rc":[{"atb":[[1.63,16.03]],"id":41719613}],"con":true,"img":false}]}
{"op":"mcm","clk":"5347778476","pt":1646207596907,"mc":[{"id":"1.195453609","rc":[{"atb":[[1.64,0],[1.63,0]],"id":41719613}],"con":true,"img":false}]}
{"op":"mcm","clk":"5347778483","pt":1646207597009,"mc":[{"id":"1.195453609","rc":[{"atb":[[1.61,69.28]],"id":41719613}],"con":true,"img":false}]}
{"op":"mcm","clk":"5347779463","pt":1646207613514,"mc":[{"id":"1.195453609","rc":[{"atb":[[1.63,11.94]],"id":41719613}],"con":true,"img":false}]}
{"op":"mcm","clk":"5347779731","pt":1646207618600,"mc":[{"id":"1.195453609","rc":[{"atb":[[1.63,27.97]],"id":41719613}],"con":true,"img":false}]}
{"op":"mcm","clk":"5347782305","pt":1646207666958,"mc":[{"id":"1.195453609","rc":[{"atb":[[1.61,0]],"id":41719613}],"con":true,"img":false}]}
{"op":"mcm","clk":"5347782310","pt":1646207667061,"mc":[{"id":"1.195453609","rc":[{"atb":[[1.64,69.28]],"id":41719613}],"con":true,"img":false}]}
{"op":"mcm","clk":"5347782626","pt":1646207673686,"mc":[{"id":"1.195453609","rc":[{"atb":[[1.63,16.03]],"id":41719613}],"con":true,"img":false}]}
{"op":"mcm","clk":"5347783025","pt":1646207682684,"mc":[{"id":"1.195453609","rc":[{"atb":[[1.66,13.06]],"id":41719613}],"con":true,"img":false}]}
{"op":"mcm","clk":"5347783140","pt":1646207685008,"mc":[{"id":"1.195453609","rc":[{"atb":[[1.64,0]],"id":41719613}],"con":true,"img":false}]}
{"op":"mcm","clk":"5347783146","pt":1646207685106,"mc":[{"id":"1.195453609","rc":[{"atb":[[1.61,69.28]],"id":41719613}],"con":true,"img":false}]}
{"op":"mcm","clk":"5347783466","pt":1646207691692,"mc":[{"id":"1.195453609","rc":[{"atb":[[1.66,1.66]],"id":41719613}],"con":true,"img":false}]}
{"op":"mcm","clk":"5347783878","pt":1646207700685,"mc":[{"id":"1.195453609","rc":[{"atb":[[1.63,27.97]],"id":41719613}],"con":true,"img":false}]}
{"op":"mcm","clk":"5347786282","pt":1646207748666,"mc":[{"id":"1.195453609","rc":[{"atb":[[1.61,0]],"id":41719613}],"con":true,"img":false}]}
{"op":"mcm","clk":"5347786287","pt":1646207748768,"mc":[{"id":"1.195453609","rc":[{"atb":[[1.64,69.28]],"id":41719613}],"con":true,"img":false}]}
{"op":"mcm","clk":"5347786756","pt":1646207757887,"mc":[{"id":"1.195453609","rc":[{"atb":[[1.63,16.03]],"id":41719613}],"con":true,"img":false}]}
{"op":"mcm","clk":"5347786838","pt":1646207759684,"mc":[{"id":"1.195453609","rc":[{"atb":[[1.63,0]],"id":41719613}],"con":true,"img":false}]}
{"op":"mcm","clk":"5347787079","pt":1646207763902,"mc":[{"id":"1.195453609","rc":[{"atb":[[1.64,0]],"id":41719613}],"con":true,"img":false}]}
{"op":"mcm","clk":"5347787084","pt":1646207764002,"mc":[{"id":"1.195453609","rc":[{"atb":[[1.61,69.28]],"id":41719613}],"con":true,"img":false}]}
{"op":"mcm","clk":"5347787898","pt":1646207780375,"mc":[{"id":"1.195453609","rc":[{"atb":[[1.63,16.03]],"id":41719613}],"con":true,"img":false}]}
{"op":"mcm","clk":"5347787961","pt":1646207781804,"mc":[{"id":"1.195453609","rc":[{"atb":[[1.63,27.97]],"id":41719613}],"con":true,"img":false}]}
{"op":"mcm","clk":"5347789427","pt":1646207813621,"mc":[{"id":"1.195453609","rc":[{"atb":[[1.61,0]],"id":41719613}],"con":true,"img":false}]}
{"op":"mcm","clk":"5347789435","pt":1646207813724,"mc":[{"id":"1.195453609","rc":[{"atb":[[1.64,69.28]],"id":41719613}],"con":true,"img":false}]}
{"op":"mcm","clk":"5347789826","pt":1646207821034,"mc":[{"id":"1.195453609","rc":[{"atb":[[1.63,16.03]],"id":41719613}],"con":true,"img":false}]}
{"op":"mcm","clk":"5347790222","pt":1646207828652,"mc":[{"id":"1.195453609","rc":[{"atb":[[1.64,0]],"id":41719613}],"con":true,"img":false}]}
{"op":"mcm","clk":"5347790226","pt":1646207828754,"mc":[{"id":"1.195453609","rc":[{"atb":[[1.61,69.28]],"id":41719613}],"con":true,"img":false}]}
{"op":"mcm","clk":"5347791039","pt":1646207845065,"mc":[{"id":"1.195453609","rc":[{"atb":[[1.63,27.97]],"id":41719613}],"con":true,"img":false}]}
{"op":"mcm","clk":"5347793437","pt":1646207902938,"mc":[{"id":"1.195453609","rc":[{"atb":[[1.61,0]],"id":41719613}],"con":true,"img":false}]}
{"op":"mcm","clk":"5347793442","pt":1646207903039,"mc":[{"id":"1.195453609","rc":[{"atb":[[1.64,69.28]],"id":41719613}],"con":true,"img":false}]}
{"op":"mcm","clk":"5347793700","pt":1646207910063,"mc":[{"id":"1.195453609","rc":[{"atb":[[1.63,11.94]],"id":41719613}],"con":true,"img":false}]}
{"op":"mcm","clk":"5347793746","pt":1646207911142,"mc":[{"id":"1.195453609","rc":[{"atb":[[1.63,0]],"id":41719613}],"con":true,"img":false}]}
{"op":"mcm","clk":"5347794087","pt":1646207920173,"mc":[{"id":"1.195453609","rc":[{"atb":[[1.66,13.06]],"id":41719613}],"con":true,"img":false}]}
{"op":"mcm","clk":"5347794120","pt":1646207921259,"mc":[{"id":"1.195453609","rc":[{"atb":[[1.66,28.37]],"id":41719613}],"con":true,"img":false}]}
{"op":"mcm","clk":"5347795697","pt":1646207960794,"mc":[{"id":"1.195453609","rc":[{"atb":[[1.64,0]],"id":41719613}],"con":true,"img":false}]}
{"op":"mcm","clk":"5347795702","pt":1646207960896,"mc":[{"id":"1.195453609","rc":[{"atb":[[1.61,69.28]],"id":41719613}],"con":true,"img":false}]}
{"op":"mcm","clk":"5347795982","pt":1646207968314,"mc":[{"id":"1.195453609","rc":[{"atb":[[1.66,16.97]],"id":41719613}],"con":true,"img":false}]}
{"op":"mcm","clk":"5347796357","pt":1646207977236,"mc":[{"id":"1.195453609","rc":[{"atb":[[1.63,11.94]],"id":41719613}],"con":true,"img":false}]}
{"op":"mcm","clk":"5347796563","pt":1646207981568,"mc":[{"id":"1.195453609","rc":[{"atb":[[1.66,1.66]],"id":41719613}],"con":true,"img":false}]}
{"op":"mcm","clk":"5347797081","pt":1646207994090,"mc":[{"id":"1.195453609","rc":[{"atb":[[1.63,27.97]],"id":41719613}],"con":true,"img":false}]}
{"op":"mcm","clk":"5347799121","pt":1646208040926,"mc":[{"id":"1.195453609","rc":[{"atl":[[8.6,0],[6.2,19.23]],"id":41719613},{"atb":[[3.3,43.48],[2.88,0]],"id":43167169}],"con":true,"img":false}]}
{"op":"mcm","clk":"5347799135","pt":1646208041335,"mc":[{"id":"1.195453609","rc":[{"atb":[[1.61,0]],"id":41719613}],"con":true,"img":false}]}
{"op":"mcm","clk":"5347799139","pt":1646208041438,"mc":[{"id":"1.195453609","rc":[{"atb":[[1.64,69.28]],"id":41719613}],"con":true,"img":false}]}
{"op":"mcm","clk":"5347799450","pt":1646208049443,"mc":[{"id":"1.195453609","rc":[{"atb":[[1.63,16.03]],"id":41719613}],"con":true,"img":false}]}
{"op":"mcm","clk":"5347799622","pt":1646208054260,"mc":[{"id":"1.195453609","rc":[{"atb":[[1.63,0]],"id":41719613}],"con":true,"img":false}]}
{"op":"mcm","clk":"5347799662","pt":1646208055287,"mc":[{"id":"1.195453609","rc":[{"atb":[[1.64,0]],"id":41719613}],"con":true,"img":false}]}
{"op":"mcm","clk":"5347799665","pt":1646208055340,"mc":[{"id":"1.195453609","rc":[{"atb":[[1.61,69.28]],"id":41719613}],"con":true,"img":false}]}
{"op":"mcm","clk":"5347799923","pt":1646208061763,"mc":[{"id":"1.195453609","rc":[{"atb":[[9.2,0]],"id":43167167},{"atb":[[1.56,0]],"id":41719613}],"con":true,"img":false}]}
{"op":"mcm","clk":"5347799930","pt":1646208061971,"mc":[{"id":"1.195453609","rc":[{"atb":[[9.6,1.17]],"id":43167167},{"atb":[[1.61,71.28]],"id":41719613}],"con":true,"img":false}]}
{"op":"mcm","clk":"5347800101","pt":1646208066159,"mc":[{"id":"1.195453609","rc":[{"atb":[[8.2,2.78],[7.4,11.72],[7.8,30.82],[7,20.83]],"id":43167166},{"atl":[[32,1],[36,5.24],[40,1.92],[44,2.91]],"id":43167166},{"atb":[[8.2,2.78],[7.4,11.72],[7.8,29.18],[7,20.83]],"id":43167167},{"atl":[[22,1],[24,4.95],[26,3],[28,4.63]],"id":43167167},{"atb":[[1.46,250],[1.48,156.25],[1.5,181.87],[1.52,38.46]],"id":41719613},{"atl":[[7.4,19.53],[6.2,23.08],[6.6,8.93],[7,12.5]],"id":41719613},{"atb":[[6.4,3.7],[5.8,24.15],[5.6,27.17],[6,10]],"id":43167168},{"atl":[[24,1],[26,2],[28,2.78],[30,7.63]],"id":43167168},{"atb":[[3.5,36.8],[3.3,76.09],[3.2,56.82],[3.4,20.83]],"id":43167169},{"atl":[[32,4.03],[25,1],[27,1.92],[29,9.82]],"id":43167169},{"atb":[[5.9,10.2],[6.2,3.85],[5.5,27.78],[5.7,33.37]],"id":43167165},{"atl":[[32,4.03],[25,3.72],[27,1.92],[29,2.68]],"id":43167165},{"atb":[[8,12.98],[8.4,2.7],[7.2,20.16],[7.6,11.36]],"id":43167170},{"atl":[[32,4.03],[25,3.72],[27,1.92],[29,6.91]],"id":43167170},{"atb":[[4.3,139.62],[4.5,21.43],[4.9,5.13],[4.7,13.51]],"id":43016477},{"atl":[[32,2.42],[36,7.38],[27,1],[29,1.79]],"id":43016477}],"con":true,"img":false}]}
{"op":"mcm","clk":"5347800408","pt":1646208073364,"mc":[{"id":"1.195453609","rc":[{"atb":[[1.63,11.94]],"id":41719613}],"con":true,"img":false}]}
{"op":"mcm","clk":"5347800460","pt":1646208074491,"mc":[{"id":"1.195453609","rc":[{"atl":[[1.9,4.21]],"id":41719613},{"trd":[[1.9,3.99]],"ltp":1.9,"tv":3.99,"id":41719613}],"con":true,"img":false}]}
{"op":"mcm","clk":"5347800467","pt":1646208074695,"mc":[{"id":"1.195453609","rc":[{"atb":[[1.61,69.28]],"id":41719613}],"con":true,"img":false}]}
{"op":"mcm","clk":"5347800494","pt":1646208075312,"mc":[{"id":"1.195453609","rc":[{"atb":[[9.8,2.5]],"id":43167167},{"atb":[[7.8,2.98]],"id":43167169},{"atb":[[11,2.37]],"id":43167165}],"con":true,"img":false}]}
{"op":"mcm","clk":"5347800824","pt":1646208084518,"mc":[{"id":"1.195453609","rc":[{"atb":[[1.63,27.97]],"id":41719613}],"con":true,"img":false}]}
{"op":"mcm","clk":"5347801294","pt":1646208098611,"mc":[{"id":"1.195453609","rc":[{"atl":[[30,0]],"id":43167167},{"atb":[[1.51,0]],"id":41719613},{"atl":[[30,4.31]],"id":43167168},{"atl":[[36,0]],"id":43167165},{"atl":[[29,2.68]],"id":43167170},{"atl":[[34,0]],"id":43016477}],"con":true,"img":false}]}
{"op":"mcm","clk":"5347801298","pt":1646208098714,"mc":[{"id":"1.195453609","rc":[{"atb":[[1.53,218.34]],"id":41719613},{"atl":[[26,4.23]],"id":43167170}],"con":true,"img":false}]}
{"op":"mcm","clk":"5347801683","pt":1646208108630,"mc":[{"id":"1.195453609","rc":[{"spn":15.9,"spf":"NaN","id":43167167},{"atb":[[1.61,0]],"id":41719613}],"con":true,"img":false}]}
{"op":"mcm","clk":"5347801685","pt":1646208108732,"mc":[{"id":"1.195453609","rc":[{"atb":[[1.64,69.28]],"id":41719613}],"con":true,"img":false}]}
{"op":"mcm","clk":"5347801935","pt":1646208115767,"mc":[{"id":"1.195453609","rc":[{"atb":[[1.63,16.03]],"id":41719613}],"con":true,"img":false}]}
{"op":"mcm","clk":"5347802039","pt":1646208118556,"mc":[{"id":"1.195453609","rc":[{"atl":[[25,5.45]],"id":43167167},{"atl":[[25,4.57]],"id":43167168},{"atl":[[26,4.39]],"id":43167165},{"atl":[[28,4.24]],"id":43016477}],"con":true,"img":false}]}
{"op":"mcm","clk":"5347802045","pt":1646208118657,"mc":[{"id":"1.195453609","rc":[{"atb":[[1.64,0]],"id":41719613}],"con":true,"img":false}]}
{"op":"mcm","clk":"5347802050","pt":1646208118759,"mc":[{"id":"1.195453609","rc":[{"atb":[[1.61,69.28]],"id":41719613}],"con":true,"img":false}]}
{"op":"mcm","clk":"5347802265","pt":1646208123259,"mc":[{"id":"1.195453609","rc":[{"atb":[[5.3,19.03],[4.2,31.25]],"id":43167166},{"atl":[[32,0],[34,1]],"id":43167166},{"atb":[[3.55,39.22],[4.7,0]],"id":43167167},{"atb":[[1.51,39.22],[1.52,0]],"id":41719613},{"atb":[[4.8,21.54],[3.45,40.82]],"id":43167168},{"atl":[[24,0],[26,1]],"id":43167168},{"atl":[[25,0],[26,1]],"id":43167169},{"atb":[[4.9,0],[3.5,40]],"id":43167165},{"atb":[[9,2.5],[3.55,39.22],[8.4,0],[4.1,0]],"id":43167170},{"atl":[[32,7.26],[30,0]],"id":43167170},{"atl":[[27,0],[28,5.24]],"id":43016477}],"con":true,"img":false}]}
{"op":"mcm","clk":"5347802273","pt":1646208123456,"mc":[{"id":"1.195453609","rc":[{"atb":[[3.45,0],[5.1,24.39]],"id":43167168}],"con":true,"img":false}]}
{"op":"mcm","clk":"5347802463","pt":1646208128564,"mc":[{"id":"1.195453609","rc":[{"atl":[[25,0]],"id":43167168}],"con":true,"img":false}]}
{"op":"mcm","clk":"5347802469","pt":1646208128667,"mc":[{"id":"1.195453609","rc":[{"atl":[[27,4.57]],"id":43167168}],"con":true,"img":false}]}
{"op":"mcm","clk":"5347802604","pt":1646208131344,"mc":[{"id":"1.195453609","rc":[{"spl":[[1.01,30.02]],"id":43167166},{"spl":[[1.01,30.02]],"id":43167167},{"spl":[[1.01,30.02]],"id":43167168},{"spl":[[1.01,30.02]],"id":41719613},{"spl":[[1.01,30.02]],"id":43167169},{"spl":[[1.01,30.02]],"id":43167165},{"spl":[[1.01,30.02]],"id":43167170},{"spl":[[1.01,30.02]],"id":43016477}],"con":true,"img":false}]}
{"op":"mcm","clk":"5347802680","pt":1646208133248,"mc":[{"id":"1.195453609","rc":[{"atl":[[38,1.35]],"id":43167166},{"atb":[[1.49,102.04]],"id":41719613},{"atl":[[30,2.59]],"id":43167168},{"atl":[[28,1.85]],"id":43167169},{"atb":[[8.6,6.58]],"id":43167170},{"atl":[[30,1.72]],"id":43016477}],"con":true,"img":false}]}
{"op":"mcm","clk":"5347802903","pt":1646208139571,"mc":[{"id":"1.195453609","rc":[{"atb":[[1.63,27.97]],"id":41719613}],"con":true,"img":false}]}
{"op":"mcm","clk":"5347803004","pt":1646208141781,"mc":[{"id":"1.195453609","rc":[{"atb":[[6.4,18.52],[4.2,0]],"id":43167166},{"atb":[[4.9,25.64],[3.55,0]],"id":43167167},{"atb":[[3.5,0],[5.1,24.39]],"id":43167165},{"atb":[[4.3,30.3],[3.55,0]],"id":43167170}],"con":true,"img":false}]}
{"op":"mcm","clk":"5347803055","pt":1646208143269,"mc":[{"id":"1.195453609","rc":[{"atl":[[36,3.81],[40,0],[42,1.83],[44,0]],"id":43167166},{"atb":[[1.46,0],[1.48,0],[1.5,81.87],[1.47,159.57]],"id":41719613},{"atl":[[34,3.79]],"id":43167168},{"atl":[[32,0],[27,0],[29,7.14],[30,2.59]],"id":43167169},{"atb":[[8,5.84],[8.2,28.86],[7.2,0],[7.6,0]],"id":43167170},{"atl":[[32,0],[34,2.27],[36,3.81],[29,0]],"id":43016477}],"con":true,"img":false}]}
{"op":"mcm","clk":"5347803159","pt":1646208146608,"mc":[{"id":"1.195453609","rc":[{"atb":[[1.02,2.25]],"id":43167167}],"con":true,"img":false}]}
{"op":"mcm","clk":"5347803164","pt":1646208146662,"mc":[{"id":"1.195453609","rc":[{"atb":[[9.4,0]],"id":43167167}],"con":true,"img":false}]}
{"op":"mcm","clk":"5347803170","pt":1646208146765,"mc":[{"id":"1.195453609","rc":[{"atb":[[1.02,0.37]],"id":43167167}],"con":true,"img":false}]}
{"op":"mcm","clk":"5347803176","pt":1646208146868,"mc":[{"id":"1.195453609","rc":[{"atb":[[1.02,0]],"id":43167167}],"con":true,"img":false}]}
{"op":"mcm","clk":"5347803179","pt":1646208146973,"mc":[{"id":"1.195453609","rc":[{"atb":[[10,0.37]],"id":43167167}],"con":true,"img":false}]}
{"op":"mcm","clk":"5347803241","pt":1646208148673,"mc":[{"id":"1.195453609","rc":[{"atl":[[28,1]],"id":43016477}],"con":true,"img":false}]}
{"op":"mcm","clk":"5347803248","pt":1646208148776,"mc":[{"id":"1.195453609","rc":[{"atl":[[29,4.24]],"id":43016477}],"con":true,"img":false}]}
{"op":"mcm","clk":"5347803402","pt":1646208153301,"mc":[{"id":"1.195453609","rc":[{"atl":[[46,5.74]],"id":43167166},{"atb":[[1.45,431.94]],"id":41719613},{"atl":[[34,3.79]],"id":43167169},{"atb":[[7.8,18.38]],"id":43167170},{"atl":[[38,3.38]],"id":43016477}],"con":true,"img":false}]}
{"op":"mcm","clk":"5347804081","pt":1646208168732,"mc":[{"id":"1.195453609","rc":[{"spn":8.14,"spf":1.0,"id":43167166},{"spn":8.42,"spf":1.0,"id":43167167},{"atb":[[1.61,0]],"id":41719613},{"spn":1.63,"spf":1.0,"id":41719613},{"spn":8.08,"spf":1.0,"id":43167168},{"spn":7.12,"spf":1.0,"id":43167169},{"spn":8.65,"spf":1.0,"id":43167165},{"spn":8.71,"spf":1.0,"id":43167170},{"spn":8.18,"spf":1.0,"id":43016477}],"con":true,"img":false}]}
{"op":"mcm","clk":"5347804084","pt":1646208168783,"mc":[{"id":"1.195453609","rc":[{"atb":[[1.64,69.28]],"id":41719613}],"con":true,"img":false}]}
{"op":"mcm","clk":"5347804358","pt":1646208175796,"mc":[{"id":"1.195453609","rc":[{"atb":[[1.63,16.03]],"id":41719613}],"con":true,"img":false}]}
{"op":"mcm","clk":"5347804457","pt":1646208178621,"mc":[{"id":"1.195453609","rc":[{"atb":[[1.64,0]],"id":41719613},{"atb":[[8.8,14.66]],"id":43167170}],"con":true,"img":false}]}
{"op":"mcm","clk":"5347804464","pt":1646208178724,"mc":[{"id":"1.195453609","rc":[{"atb":[[1.61,69.28]],"id":41719613},{"atb":[[8.2,10.42]],"id":43167170}],"con":true,"img":false}]}
{"op":"mcm","clk":"5347805357","pt":1646208196765,"mc":[{"id":"1.195453609","rc":[{"atb":[[1.63,27.97]],"id":41719613}],"con":true,"img":false}]}
{"op":"mcm","clk":"5347806162","pt":1646208218691,"mc":[{"id":"1.195453609","rc":[{"atb":[[1.61,0]],"id":41719613}],"con":true,"img":false}]}
{"op":"mcm","clk":"5347806169","pt":1646208218791,"mc":[{"id":"1.195453609","rc":[{"atb":[[1.64,69.28]],"id":41719613}],"con":true,"img":false}]}
{"op":"mcm","clk":"5347806453","pt":1646208227008,"mc":[{"id":"1.195453609","rc":[{"atb":[[1.63,16.03]],"id":41719613}],"con":true,"img":false}]}
{"op":"mcm","clk":"5347806498","pt":1646208228598,"mc":[{"id":"1.195453609","rc":[{"atb":[[1.64,0]],"id":41719613}],"con":true,"img":false}]}
{"op":"mcm","clk":"5347806500","pt":1646208228705,"mc":[{"id":"1.195453609","rc":[{"atb":[[1.61,69.28]],"id":41719613}],"con":true,"img":false}]}
{"op":"mcm","clk":"5347807143","pt":1646208244901,"mc":[{"id":"1.195453609","rc":[{"atb":[[1.63,27.97]],"id":41719613},{"spn":1.63,"spf":1.0,"id":41719613},{"spn":8.97,"spf":1.0,"id":43167170}],"con":true,"img":false}]}
{"op":"mcm","clk":"5347807223","pt":1646208246906,"mc":[{"id":"1.195453609","rc":[{"atb":[[9.6,0]],"id":43167167}],"con":true,"img":false}]}
{"op":"mcm","clk":"5347807228","pt":1646208247006,"mc":[{"id":"1.195453609","rc":[{"atb":[[1.02,2.25]],"id":43167167}],"con":true,"img":false}]}
{"op":"mcm","clk":"5347807232","pt":1646208247108,"mc":[{"id":"1.195453609","rc":[{"atb":[[10,1.49]],"id":43167167}],"con":true,"img":false}]}
{"op":"mcm","clk":"5347807237","pt":1646208247212,"mc":[{"id":"1.195453609","rc":[{"atb":[[10,1.12],[1.02,0.37]],"id":43167167}],"con":true,"img":false}]}
{"op":"mcm","clk":"5347807248","pt":1646208247519,"mc":[{"id":"1.195453609","rc":[{"atb":[[1.02,0]],"id":43167167}],"con":true,"img":false}]}
{"op":"mcm","clk":"5347807250","pt":1646208247620,"mc":[{"id":"1.195453609","rc":[{"atb":[[9.2,0.37]],"id":43167167}],"con":true,"img":false}]}
{"op":"mcm","clk":"5347807259","pt":1646208247830,"mc":[{"id":"1.195453609","rc":[{"atb":[[9.2,0],[1.02,2.25],[9.8,0]],"id":43167167}],"con":true,"img":false}]}
{"op":"mcm","clk":"5347807264","pt":1646208248033,"mc":[{"id":"1.195453609","rc":[{"atb":[[1.02,0.36]],"id":43167167}],"con":true,"img":false}]}
{"op":"mcm","clk":"5347807268","pt":1646208248133,"mc":[{"id":"1.195453609","rc":[{"atb":[[1.02,0]],"id":43167167}],"con":true,"img":false}]}
{"op":"mcm","clk":"5347807274","pt":1646208248186,"mc":[{"id":"1.195453609","rc":[{"atb":[[10.5,0.36]],"id":43167167}],"con":true,"img":false}]}
{"op":"mcm","clk":"5347808220","pt":1646208268650,"mc":[{"id":"1.195453609","rc":[{"atb":[[1.61,0]],"id":41719613}],"con":true,"img":false}]}
{"op":"mcm","clk":"5347808226","pt":1646208268719,"mc":[{"id":"1.195453609","rc":[{"atb":[[1.64,69.28]],"id":41719613}],"con":true,"img":false}]}
{"op":"mcm","clk":"5347808532","pt":1646208277932,"mc":[{"id":"1.195453609","rc":[{"atb":[[1.63,16.03]],"id":41719613}],"con":true,"img":false}]}
{"op":"mcm","clk":"5347808555","pt":1646208278654,"mc":[{"id":"1.195453609","rc":[{"atb":[[1.64,0]],"id":41719613}],"con":true,"img":false}]}
{"op":"mcm","clk":"5347808564","pt":1646208278759,"mc":[{"id":"1.195453609","rc":[{"atb":[[1.61,69.28]],"id":41719613}],"con":true,"img":false}]}
{"op":"mcm","clk":"5347808614","pt":1646208280247,"mc":[{"id":"1.195453609","rc":[{"atb":[[1.63,0]],"id":41719613}],"con":true,"img":false}]}
{"op":"mcm","clk":"5347809418","pt":1646208298881,"mc":[{"id":"1.195453609","rc":[{"atb":[[1.63,11.94]],"id":41719613}],"con":true,"img":false}]}
{"op":"mcm","clk":"5347809622","pt":1646208303902,"mc":[{"id":"1.195453609","rc":[{"atb":[[1.63,27.97]],"id":41719613}],"con":true,"img":false}]}
{"op":"mcm","clk":"5347810548","pt":1646208328604,"mc":[{"id":"1.195453609","rc":[{"spn":8.27,"spf":1.0,"id":43167167},{"atb":[[1.61,0]],"id":41719613},{"spn":1.63,"spf":1.0,"id":41719613}],"con":true,"img":false}]}
{"op":"mcm","clk":"5347810554","pt":1646208328704,"mc":[{"id":"1.195453609","rc":[{"atb":[[1.64,69.28]],"id":41719613}],"con":true,"img":false}]}
{"op":"mcm","clk":"5347810871","pt":1646208334939,"mc":[{"id":"1.195453609","rc":[{"atb":[[2.72,46.3],[5.1,0]],"id":43167168},{"atl":[[23,3.92],[26,0]],"id":43167168},{"atl":[[26,0],[27,1]],"id":43167169},{"atb":[[3.6,38.46],[9,0],[4.3,0],[8.6,2.63]],"id":43167170},{"atl":[[32,4.03],[29,6.25]],"id":43167170},{"atl":[[28,0],[29,5.24]],"id":43016477}],"con":true,"img":false}]}
{"op":"mcm","clk":"5347810876","pt":1646208335043,"mc":[{"id":"1.195453609","rc":[{"atb":[[1.63,16.03]],"id":41719613},{"atb":[[3.6,0],[4.2,31.25]],"id":43167170}],"con":true,"img":false}]}
{"op":"mcm","clk":"5347811050","pt":1646208338640,"mc":[{"id":"1.195453609","rc":[{"atb":[[8.8,0]],"id":43167170}],"con":true,"img":false}]}
{"op":"mcm","clk":"5347811053","pt":1646208338742,"mc":[{"id":"1.195453609","rc":[{"atb":[[8.4,14.66]],"id":43167170}],"con":true,"img":false}]}
{"op":"mcm","clk":"5347811282","pt":1646208344066,"mc":[{"id":"1.195453609","rc":[{"atb":[[1.66,13.06]],"id":41719613}],"con":true,"img":false}]}
{"op":"mcm","clk":"5347811324","pt":1646208344952,"mc":[{"id":"1.195453609","rc":[{"atl":[[25,2.08]],"id":43167168},{"atl":[[29,8.93]],"id":43167169},{"atb":[[8.2,6.94]],"id":43167170},{"atl":[[32,1.61]],"id":43016477}],"con":true,"img":false}]}
{"op":"mcm","clk":"5347811510","pt":1646208348650,"mc":[{"id":"1.195453609","rc":[{"atb":[[1.64,0]],"id":41719613}],"con":true,"img":false}]}
{"op":"mcm","clk":"5347811514","pt":1646208348752,"mc":[{"id":"1.195453609","rc":[{"atb":[[1.61,69.28]],"id":41719613}],"con":true,"img":false}]}
{"op":"mcm","clk":"5347811658","pt":1646208351334,"mc":[{"id":"1.195453609","rc":[{"atb":[[2.72,0],[4.9,25.64]],"id":43167168}],"con":true,"img":false}]}
{"op":"mcm","clk":"5347811809","pt":1646208354960,"mc":[{"id":"1.195453609","rc":[{"atl":[[34,0],[27,7.45],[28,0],[30,0]],"id":43167168},{"atl":[[32,2.42],[34,0],[28,0],[30,0]],"id":43167169},{"atb":[[7.8,11.03]],"id":43167170},{"atl":[[34,0],[36,5.95],[38,0],[30,0]],"id":43016477}],"con":true,"img":false}]}
{"op":"mcm","clk":"5347811868","pt":1646208356080,"mc":[{"id":"1.195453609","rc":[{"atb":[[1.66,1.66]],"id":41719613}],"con":true,"img":false}]}
{"op":"mcm","clk":"5347812000","pt":1646208358589,"mc":[{"id":"1.195453609","rc":[{"atl":[[29,1]],"id":43016477}],"con":true,"img":false}]}
{"op":"mcm","clk":"5347812005","pt":1646208358647,"mc":[{"id":"1.195453609","rc":[{"atl":[[30,4.24]],"id":43016477}],"con":true,"img":false}]}
{"op":"mcm","clk":"5347812292","pt":1646208364974,"mc":[{"id":"1.195453609","rc":[{"atl":[[29,4.46]],"id":43167168},{"atl":[[36,3.57]],"id":43167169},{"atb":[[7.4,19.53]],"id":43167170},{"atl":[[40,3.21]],"id":43016477}],"con":true,"img":false}]}
{"op":"mcm","clk":"5347812441","pt":1646208368066,"mc":[{"id":"1.195453609","rc":[{"atb":[[1.63,27.97]],"id":41719613}],"con":true,"img":false}]}
{"op":"mcm","clk":"5347813289","pt":1646208388610,"mc":[{"id":"1.195453609","rc":[{"atb":[[1.61,0]],"id":41719613},{"atl":[[27,2.88]],"id":43167168},{"spn":8.69,"spf":1.0,"id":43167170}],"con":true,"img":false}]}
{"op":"mcm","clk":"5347813294","pt":1646208388712,"mc":[{"id":"1.195453609","rc":[{"atl":[[24,4.57]],"id":43167168},{"atb":[[1.64,69.28]],"id":41719613}],"con":true,"img":false}]}
{"op":"mcm","clk":"5347813565","pt":1646208395119,"mc":[{"id":"1.195453609","rc":[{"atb":[[1.63,16.03]],"id":41719613}],"con":true,"img":false}]}
{"op":"mcm","clk":"5347813711","pt":1646208398629,"mc":[{"id":"1.195453609","rc":[{"atb":[[1.64,0]],"id":41719613}],"con":true,"img":false}]}
{"op":"mcm","clk":"5347813717","pt":1646208398740,"mc":[{"id":"1.195453609","rc":[{"atb":[[1.61,69.28]],"id":41719613}],"con":true,"img":false}]}
{"op":"mcm","clk":"5347814336","pt":1646208413662,"mc":[{"id":"1.195453609","rc":[{"atb":[[10,0]],"id":43167167}],"con":true,"img":false}]}
{"op":"mcm","clk":"5347814341","pt":1646208413759,"mc":[{"id":"1.195453609","rc":[{"atb":[[10.5,1.42]],"id":43167167}],"con":true,"img":false}]}
{"op":"mcm","clk":"5347814542","pt":1646208419171,"mc":[{"id":"1.195453609","rc":[{"atb":[[1.63,27.97]],"id":41719613}],"con":true,"img":false}]}
{"op":"mcm","clk":"5347815816","pt":1646208448587,"mc":[{"id":"1.195453609","rc":[{"atb":[[1.61,0]],"id":41719613}],"con":true,"img":false}]}
{"op":"mcm","clk":"5347815823","pt":1646208448688,"mc":[{"id":"1.195453609","rc":[{"spn":8.28,"spf":1.0,"id":43167167},{"atb":[[1.64,69.28]],"id":41719613},{"spn":1.64,"spf":1.0,"id":41719613}],"con":true,"img":false}]}
{"op":"mcm","clk":"5347816078","pt":1646208454996,"mc":[{"id":"1.195453609","rc":[{"atl":[[32,7.26],[29,2.68]],"id":43167170}],"con":true,"img":false}]}
{"op":"mcm","clk":"5347816087","pt":1646208455304,"mc":[{"id":"1.195453609","rc":[{"atb":[[1.63,16.03]],"id":41719613}],"con":true,"img":false}]}
{"op":"mcm","clk":"5347816209","pt":1646208458697,"mc":[{"id":"1.195453609","rc":[{"atb":[[1.64,0]],"id":41719613}],"con":true,"img":false}]}
{"op":"mcm","clk":"5347816213","pt":1646208458801,"mc":[{"id":"1.195453609","rc":[{"atb":[[1.61,69.28]],"id":41719613}],"con":true,"img":false}]}
{"op":"mcm","clk":"5347816983","pt":1646208476206,"mc":[{"id":"1.195453609","rc":[{"atb":[[1.63,27.97]],"id":41719613}],"con":true,"img":false}]}
{"op":"mcm","clk":"5347818001","pt":1646208498626,"mc":[{"id":"1.195453609","rc":[{"atb":[[1.61,0]],"id":41719613}],"con":true,"img":false}]}
{"op":"mcm","clk":"5347818005","pt":1646208498730,"mc":[{"id":"1.195453609","rc":[{"atb":[[1.64,69.28]],"id":41719613}],"con":true,"img":false}]}
{"op":"mcm","clk":"5347818284","pt":1646208506343,"mc":[{"id":"1.195453609","rc":[{"atb":[[1.63,16.03]],"id":41719613}],"con":true,"img":false}]}
{"op":"mcm","clk":"5347818392","pt":1646208508650,"mc":[{"id":"1.195453609","rc":[{"atb":[[1.64,0]],"id":41719613}],"con":true,"img":false}]}
{"op":"mcm","clk":"5347818398","pt":1646208508753,"mc":[{"id":"1.195453609","rc":[{"atb":[[1.61,69.28]],"id":41719613},{"spn":1.62,"spf":1.0,"id":41719613}],"con":true,"img":false}]}
{"op":"mcm","clk":"5347819065","pt":1646208524259,"mc":[{"id":"1.195453609","rc":[{"atb":[[1.63,27.97]],"id":41719613}],"con":true,"img":false}]}
{"op":"mcm","clk":"5347820101","pt":1646208548591,"mc":[{"id":"1.195453609","rc":[{"atb":[[1.61,0]],"id":41719613}],"con":true,"img":false}]}
{"op":"mcm","clk":"5347820109","pt":1646208548693,"mc":[{"id":"1.195453609","rc":[{"atb":[[1.64,69.28]],"id":41719613}],"con":true,"img":false}]}
{"op":"mcm","clk":"5347820342","pt":1646208554891,"mc":[{"id":"1.195453609","rc":[{"atb":[[1.51,0],[1.52,38.46]],"id":41719613},{"atl":[[23,2.92],[24,5.57]],"id":43167168},{"atb":[[8.6,0],[8.8,2.56]],"id":43167170},{"atl":[[32,4.03],[29,6.25]],"id":43167170},{"atl":[[29,0]],"id":43016477}],"con":true,"img":false}]}
{"op":"mcm","clk":"5347820447","pt":1646208557375,"mc":[{"id":"1.195453609","rc":[{"atb":[[1.63,16.03]],"id":41719613}],"con":true,"img":false}]}
{"op":"mcm","clk":"5347820475","pt":1646208558707,"mc":[{"id":"1.195453609","rc":[{"atb":[[1.64,0]],"id":41719613}],"con":true,"img":false}]}
{"op":"mcm","clk":"5347820478","pt":1646208558810,"mc":[{"id":"1.195453609","rc":[{"atb":[[1.61,69.28]],"id":41719613}],"con":true,"img":false}]}
{"op":"mcm","clk":"5347820492","pt":1646208559179,"mc":[{"id":"1.195453609","rc":[{"atb":[[9.2,7.13]],"id":43016477}],"con":true,"img":false}]}
{"op":"mcm","clk":"5347820497","pt":1646208559280,"mc":[{"id":"1.195453609","rc":[{"atb":[[9.6,1.17]],"id":43016477}],"con":true,"img":false}]}
{"op":"mcm","clk":"5347820519","pt":1646208559903,"mc":[{"id":"1.195453609","rc":[{"atb":[[9.8,2.5]],"id":43016477}],"con":true,"img":false}]}
{"op":"mcm","clk":"5347820522","pt":1646208559999,"mc":[{"id":"1.195453609","rc":[{"atl":[[29,2.68],[30,3.45]],"id":43167170}],"con":true,"img":false}]}
{"op":"mcm","clk":"5347820696","pt":1646208564789,"mc":[{"id":"1.195453609","rc":[{"atl":[[40,1.92]],"id":43016477}],"con":true,"img":false}]}
{"op":"mcm","clk":"5347820700","pt":1646208564896,"mc":[{"id":"1.195453609","rc":[{"atl":[[26,2]],"id":43167168}],"con":true,"img":false}]}
{"op":"mcm","clk":"5347821116","pt":1646208574933,"mc":[{"id":"1.195453609","rc":[{"atl":[[25,0],[27,0],[28,2.78],[29,0]],"id":43167168},{"spn":8.71,"spf":1.0,"id":43167170},{"atl":[[44,2.91]],"id":43016477},{"spn":8.37,"spf":1.0,"id":43016477}],"con":true,"img":false}]}
{"op":"mcm","clk":"5347821280","pt":1646208578434,"mc":[{"id":"1.195453609","rc":[{"atb":[[1.63,27.97]],"id":41719613}],"con":true,"img":false}]}
{"op":"mcm","clk":"5347821288","pt":1646208578640,"mc":[{"id":"1.195453609","rc":[{"atl":[[24,1]],"id":43167168}],"con":true,"img":false}]}
{"op":"mcm","clk":"5347821292","pt":1646208578697,"mc":[{"id":"1.195453609","rc":[{"atl":[[25,4.57]],"id":43167168}],"con":true,"img":false}]}
{"op":"mcm","clk":"5347821554","pt":1646208584939,"mc":[{"id":"1.195453609","rc":[{"atl":[[30,4.31]],"id":43167168}],"con":true,"img":false}]}
{"op":"mcm","clk":"5347822632","pt":1646208608636,"mc":[{"id":"1.195453609","rc":[{"atb":[[1.61,0]],"id":41719613}],"con":true,"img":false}]}
{"op":"mcm","clk":"5347822640","pt":1646208608740,"mc":[{"id":"1.195453609","rc":[{"atb":[[1.64,69.28]],"id":41719613}],"con":true,"img":false}]}
{"op":"mcm","clk":"5347822882","pt":1646208613282,"mc":[{"id":"1.195453609","rc":[{"atb":[[1.63,11.94]],"id":41719613}],"con":true,"img":false}]}
{"op":"mcm","clk":"5347823111","pt":1646208617571,"mc":[{"id":"1.195453609","rc":[{"atb":[[1.63,0]],"id":41719613}],"con":true,"img":false}]}
{"op":"mcm","clk":"5347823165","pt":1646208618655,"mc":[{"id":"1.195453609","rc":[{"atb":[[1.64,0]],"id":41719613}],"con":true,"img":false}]}
{"op":"mcm","clk":"5347823169","pt":1646208618761,"mc":[{"id":"1.195453609","rc":[{"atb":[[1.61,69.28]],"id":41719613}],"con":true,"img":false}]}
{"op":"mcm","clk":"5347823610","pt":1646208627384,"mc":[{"id":"1.195453609","rc":[{"atb":[[1.02,2.25]],"id":43016477}],"con":true,"img":false}]}
{"op":"mcm","clk":"5347823616","pt":1646208627481,"mc":[{"id":"1.195453609","rc":[{"atb":[[9.4,0],[1.02,0.37]],"id":43016477}],"con":true,"img":false}]}
{"op":"mcm","clk":"5347823646","pt":1646208628304,"mc":[{"id":"1.195453609","rc":[{"atb":[[1.02,0]],"id":43016477}],"con":true,"img":false}]}
{"op":"mcm","clk":"5347823649","pt":1646208628377,"mc":[{"id":"1.195453609","rc":[{"atb":[[10,0.37]],"id":43016477}],"con":true,"img":false}]}
{"op":"mcm","clk":"5347823991","pt":1646208637094,"mc":[{"id":"1.195453609","rc":[{"atb":[[1.63,16.03]],"id":41719613},{"spn":8.38,"spf":1.0,"id":43016477}],"con":true,"img":false}]}
{"op":"mcm","clk":"5347824045","pt":1646208638585,"mc":[{"id":"1.195453609","rc":[{"atb":[[1.63,27.97]],"id":41719613}],"con":true,"img":false}]}
{"op":"mcm","clk":"5347824084","pt":1646208639306,"mc":[{"id":"1.195453609","rc":[{"spl":[[1.01,34.02]],"id":43167166},{"spl":[[1.01,34.02]],"id":43167167},{"spl":[[1.01,34.02]],"id":43167168},{"spl":[[1.01,34.02]],"id":43167169},{"spl":[[1.01,34.02]],"id":43167165},{"spl":[[1.01,34.02]],"id":43167170},{"spl":[[1.01,34.02]],"id":43016477}],"con":true,"img":false}]}
{"op":"mcm","clk":"5347824502","pt":1646208648321,"mc":[{"id":"1.195453609","rc":[{"atb":[[8.2,0],[7.4,0],[7.8,21.83],[5.4,4.55],[7,0]],"id":43167167},{"atb":[[6.4,0],[7.4,3.12]],"id":43167168},{"atl":[[7.2,3.23],[6.2,19.23],[6.6,0]],"id":41719613},{"atb":[[3.5,28.8],[3.3,32.61],[3.95,33.9],[4.1,6.45]],"id":43167169},{"atb":[[4.4,5.88],[5.9,0],[5.1,0],[6.2,0],[5.5,0],[5.7,17.41],[4.2,31.25]],"id":43167165},{"atb":[[4.3,109.32],[5.8,12.7],[4.9,0],[5.7,19.04]],"id":43016477}],"con":true,"img":false}]}
{"op":"mcm","clk":"5347824844","pt":1646208655520,"mc":[{"id":"1.195453609","rc":[{"spl":[[1.01,38.02]],"id":43167167},{"spl":[[1.01,38.02]],"id":43167168},{"spl":[[1.01,38.02]],"id":43167165},{"spl":[[1.01,38.02]],"id":43167170},{"spl":[[1.01,38.02]],"id":43016477}],"con":true,"img":false}]}
{"op":"mcm","clk":"5347824957","pt":1646208658345,"mc":[{"id":"1.195453609","rc":[{"atb":[[5.2,11.9]],"id":43167167},{"atb":[[7,8.33]],"id":43167168},{"atl":[[7.6,7.58],[7,0]],"id":41719613},{"atb":[[3.95,50.85]],"id":43167169},{"atb":[[4.2,46.87]],"id":43167165},{"atb":[[5.6,10.87]],"id":43016477}],"con":true,"img":false}]}
{"op":"mcm","clk":"5347825300","pt":1646208666045,"mc":[{"id":"1.195453609","rc":[{"atb":[[1.67,4.23]],"id":41719613}],"con":true,"img":false}]}
{"op":"mcm","clk":"5347825307","pt":1646208666243,"mc":[{"id":"1.195453609","rc":[{"atb":[[9.4,3.59]],"id":43167166},{"atb":[[10.5,3.42]],"id":43167167},{"atl":[[23,2]],"id":43167167},{"atb":[[9.4,3.59]],"id":43167168},{"atb":[[7.8,5.37]],"id":43167169},{"atb":[[11,4.37]],"id":43167165},{"atl":[[24,2]],"id":43167165},{"atl":[[24,2]],"id":43167170},{"atb":[[9.8,4.5]],"id":43016477}],"con":true,"img":false}]}
{"op":"mcm","clk":"5347825390","pt":1646208668349,"mc":[{"id":"1.195453609","rc":[{"atb":[[5,18.75]],"id":43167167},{"atb":[[5.8,8.53],[5.6,0],[6,0],[6.6,13.39]],"id":43167168},{"atl":[[8,10.71]],"id":41719613},{"atb":[[3.85,26.32],[3.3,0],[3.2,0],[3.4,0]],"id":43167169},{"atb":[[4,25]],"id":43167165},{"atb":[[4.3,71.44],[5.4,17.05],[4.5,0],[4.7,0]],"id":43016477}],"con":true,"img":false}]}
{"op":"mcm","clk":"5347825398","pt":1646208668615,"mc":[{"id":"1.195453609","rc":[{"atb":[[1.61,0]],"id":41719613}],"con":true,"img":false}]}
{"op":"mcm","clk":"5347825404","pt":1646208668726,"mc":[{"id":"1.195453609","rc":[{"atb":[[1.64,69.28]],"id":41719613}],"con":true,"img":false}]}
{"op":"mcm","clk":"5347825807","pt":1646208677755,"mc":[{"id":"1.195453609","rc":[{"atb":[[1.63,16.03]],"id":41719613}],"con":true,"img":false}]}
{"op":"mcm","clk":"5347825832","pt":1646208678328,"mc":[{"id":"1.195453609","rc":[{"atb":[[4.8,54.43]],"id":43167167},{"atl":[[8.4,16.89]],"id":41719613},{"atb":[[6.2,24.04]],"id":43167168},{"atb":[[3.75,104.99]],"id":43167169},{"atb":[[3.9,43.1]],"id":43167165},{"atb":[[5.2,29.76]],"id":43016477}],"con":true,"img":false}]}
{"op":"mcm","clk":"5347825840","pt":1646208678636,"mc":[{"id":"1.195453609","rc":[{"atb":[[1.64,0]],"id":41719613}],"con":true,"img":false}]}
{"op":"mcm","clk":"5347825847","pt":1646208678737,"mc":[{"id":"1.195453609","rc":[{"atb":[[1.61,69.28]],"id":41719613}],"con":true,"img":false}]}
{"op":"mcm","clk":"5347826235","pt":1646208688455,"mc":[{"id":"1.195453609","rc":[{"atl":[[7.4,0]],"id":41719613}],"con":true,"img":false}]}
{"op":"mcm","clk":"5347826520","pt":1646208695662,"mc":[{"id":"1.195453609","rc":[{"atb":[[1.63,27.97]],"id":41719613}],"con":true,"img":false}]}
{"op":"mcm","clk":"5347826633","pt":1646208698592,"mc":[{"id":"1.195453609","rc":[{"spn":8.19,"spf":1.0,"id":43167166},{"spn":8.27,"spf":1.0,"id":43167167},{"spn":1.63,"spf":1.0,"id":41719613},{"spn":8.04,"spf":1.0,"id":43167168},{"spn":7.15,"spf":1.0,"id":43167169},{"atl":[[25,1]],"id":43167165},{"spn":8.58,"spf":1.0,"id":43167165},{"atl":[[25,1]],"id":43167170},{"spn":8.57,"spf":1.0,"id":43167170},{"spn":8.25,"spf":1.0,"id":43016477}],"con":true,"img":false}]}
{"op":"mcm","clk":"5347826640","pt":1646208698696,"mc":[{"id":"1.195453609","rc":[{"atl":[[23,2.72]],"id":43167165},{"atl":[[23,2.72]],"id":43167170}],"con":true,"img":false}]}
{"op":"mcm","clk":"5347826781","pt":1646208702092,"mc":[{"id":"1.195453609","rc":[{"atb":[[9.4,1.59]],"id":43167166},{"atb":[[10.5,1.42]],"id":43167167},{"atl":[[23,0]],"id":43167167},{"atb":[[11,2.37]],"id":43167165},{"atl":[[24,0]],"id":43167165}],"con":true,"img":false}]}
{"op":"mcm","clk":"5347826786","pt":1646208702194,"mc":[{"id":"1.195453609","rc":[{"atb":[[9.4,1.59]],"id":43167168},{"atb":[[7.8,2.98]],"id":43167169},{"atl":[[24,0]],"id":43167170},{"atb":[[9.8,2.5]],"id":43016477}],"con":true,"img":false}]}
{"op":"mcm","clk":"5347827088","pt":1646208708684,"mc":[{"id":"1.195453609","rc":[{"atl":[[23,0]],"id":43167165},{"atl":[[23,0]],"id":43167170}],"con":true,"img":false}]}
{"op":"mcm","clk":"5347827095","pt":1646208708791,"mc":[{"id":"1.195453609","rc":[{"atl":[[25,3.72]],"id":43167165},{"atl":[[32,7.26],[25,3.72]],"id":43167170}],"con":true,"img":false}]}
{"op":"mcm","clk":"5347827098","pt":1646208708890,"mc":[{"id":"1.195453609","rc":[{"atl":[[30,0]],"id":43167170}],"con":true,"img":false}]}
{"op":"mcm","clk":"5347827531","pt":1646208718585,"mc":[{"id":"1.195453609","rc":[{"atb":[[1.61,0]],"id":41719613}],"con":true,"img":false}]}
{"op":"mcm","clk":"5347827539","pt":1646208718691,"mc":[{"id":"1.195453609","rc":[{"atb":[[1.64,69.28]],"id":41719613}],"con":true,"img":false}]}
{"op":"mcm","clk":"5347827685","pt":1646208721470,"mc":[{"id":"1.195453609","rc":[{"atb":[[1.63,11.94]],"id":41719613}],"con":true,"img":false}]}
{"op":"mcm","clk":"5347827919","pt":1646208725801,"mc":[{"id":"1.195453609","rc":[{"atb":[[1.63,0]],"id":41719613}],"con":true,"img":false}]}
{"op":"mcm","clk":"5347828041","pt":1646208728577,"mc":[{"id":"1.195453609","rc":[{"atb":[[1.64,0]],"id":41719613}],"con":true,"img":false}]}
{"op":"mcm","clk":"5347828048","pt":1646208728680,"mc":[{"id":"1.195453609","rc":[{"atb":[[1.61,69.28]],"id":41719613}],"con":true,"img":false}]}
{"op":"mcm","clk":"5347828867","pt":1646208746405,"mc":[{"id":"1.195453609","rc":[{"atb":[[1.63,16.03]],"id":41719613}],"con":true,"img":false}]}
{"op":"mcm","clk":"5347828885","pt":1646208746818,"mc":[{"id":"1.195453609","rc":[{"atb":[[1.63,27.97]],"id":41719613}],"con":true,"img":false}]}
{"op":"mcm","clk":"5347829317","pt":1646208755636,"mc":[{"id":"1.195453609","rc":[{"atb":[[8,13.55]],"id":43167166},{"atb":[[8,13.55]],"id":43167167},{"atb":[[1.64,7.4]],"id":41719613},{"atb":[[8,13.55]],"id":43167168},{"atb":[[8.6,12.48]],"id":43167170},{"atb":[[9.8,5.53]],"id":43016477}],"con":true,"img":false}]}
{"op":"mcm","clk":"5347829369","pt":1646208756820,"mc":[{"id":"1.195453609","rc":[{"atb":[[9.4,3.59]],"id":43167166},{"atb":[[10.5,3.42]],"id":43167167},{"atl":[[23,2]],"id":43167167},{"atb":[[9.4,3.59]],"id":43167168},{"atb":[[7.8,5.37]],"id":43167169},{"atl":[[24,2]],"id":43167170},{"atb":[[9.8,7.53]],"id":43016477}],"con":true,"img":false}]}
{"op":"mcm","clk":"5347829375","pt":1646208756922,"mc":[{"id":"1.195453609","rc":[{"atb":[[11,4.37]],"id":43167165},{"atl":[[24,2]],"id":43167165}],"con":true,"img":false}]}
{"op":"mcm","clk":"5347829609","pt":1646208762122,"mc":[{"id":"1.195453609","rc":[{"atb":[[8,0]],"id":43167166},{"atb":[[8,0]],"id":43167167},{"atb":[[8,0]],"id":43167168},{"spn":1.63,"spf":1.0,"id":41719613},{"spn":8.73,"spf":1.0,"id":43167170},{"spn":8.51,"spf":1.0,"id":43016477}],"con":true,"img":false}]}
{"op":"mcm","clk":"5347829906","pt":1646208768262,"mc":[{"id":"1.195453609","rc":[{"atb":[[8.8,6.29]],"id":43167166}],"con":true,"img":false}]}
{"op":"mcm","clk":"5347829919","pt":1646208768564,"mc":[{"id":"1.195453609","rc":[{"atb":[[1.61,0]],"id":41719613}],"con":true,"img":false}]}
{"op":"mcm","clk":"5347829923","pt":1646208768666,"mc":[{"id":"1.195453609","rc":[{"atb":[[1.64,76.69]],"id":41719613}],"con":true,"img":false}]}
{"op":"mcm","clk":"5347829940","pt":1646208768974,"mc":[{"id":"1.195453609","rc":[{"atb":[[9.6,2.5]],"id":43167166}],"con":true,"img":false}]}
{"op":"mcm","clk":"5347830339","pt":1646208776880,"mc":[{"id":"1.195453609","rc":[{"atb":[[1.63,16.03]],"id":41719613}],"con":true,"img":false}]}
{"op":"mcm","clk":"5347830924","pt":1646208788560,"mc":[{"id":"1.195453609","rc":[{"atb":[[8.6,0]],"id":43167166},{"atl":[[25,1]],"id":43167165},{"atl":[[25,1]],"id":43167170},{"atb":[[9.2,0]],"id":43016477}],"con":true,"img":false}]}
{"op":"mcm","clk":"5347830929","pt":1646208788663,"mc":[{"id":"1.195453609","rc":[{"atb":[[9,8.36]],"id":43167166},{"atl":[[23,2.72],[24,0],[25,3]],"id":43167165},{"atl":[[23,2.72],[24,0],[25,3]],"id":43167170},{"atb":[[10,7.51]],"id":43016477}],"con":true,"img":false}]}
{"op":"mcm","clk":"5347830935","pt":1646208788765,"mc":[{"id":"1.195453609","rc":[{"atl":[[25,1]],"id":43167165},{"atl":[[25,1]],"id":43167170},{"atb":[[10.5,2],[9.8,5.53]],"id":43016477}],"con":true,"img":false}]}
{"op":"mcm","clk":"5347830941","pt":1646208788867,"mc":[{"id":"1.195453609","rc":[{"atl":[[23,4.72]],"id":43167165},{"atl":[[23,4.72]],"id":43167170}],"con":true,"img":false}]}
{"op":"mcm","clk":"5347830948","pt":1646208788978,"mc":[{"id":"1.195453609","rc":[{"atb":[[1.66,13.06]],"id":41719613}],"con":true,"img":false}]}
{"op":"mcm","clk":"5347831001","pt":1646208789953,"mc":[{"id":"1.195453609","rc":[{"atb":[[9.8,3.03]],"id":43016477}],"con":true,"img":false}]}
{"op":"mcm","clk":"5347831025","pt":1646208790469,"mc":[{"id":"1.195453609","rc":[{"atb":[[1.63,0]],"id":41719613}],"con":true,"img":false}]}
{"op":"mcm","clk":"5347831064","pt":1646208791293,"mc":[{"id":"1.195453609","rc":[{"atb":[[11,2.08]],"id":43016477}],"con":true,"img":false}]}
{"op":"mcm","clk":"5347831208","pt":1646208793866,"mc":[{"id":"1.195453609","rc":[{"atb":[[8.8,0]],"id":43167166},{"atb":[[1.64,69.28]],"id":41719613},{"atb":[[9.8,0]],"id":43016477}],"con":true,"img":false}]}
{"op":"mcm","clk":"5347831423","pt":1646208798598,"mc":[{"id":"1.195453609","rc":[{"atb":[[9,0]],"id":43167166},{"atb":[[1.64,0]],"id":41719613},{"atl":[[23,2]],"id":43167165},{"atb":[[8.4,0]],"id":43167170},{"atl":[[23,2]],"id":43167170},{"atb":[[10,0.37]],"id":43016477}],"con":true,"img":false}]}
{"op":"mcm","clk":"5347831431","pt":1646208798706,"mc":[{"id":"1.195453609","rc":[{"atb":[[8.4,8.36]],"id":43167166},{"atb":[[1.61,69.28]],"id":41719613},{"atl":[[25,3.72]],"id":43167165},{"atb":[[8.8,17.22]],"id":43167170},{"atl":[[25,3.72]],"id":43167170},{"atb":[[9.2,7.13]],"id":43016477}],"con":true,"img":false}]}
{"op":"mcm","clk":"5347831436","pt":1646208798808,"mc":[{"id":"1.195453609","rc":[{"atl":[[23,0],[25,5.72]],"id":43167165},{"atl":[[23,0],[25,5.72]],"id":43167170}],"con":true,"img":false}]}
{"op":"mcm","clk":"5347831534","pt":1646208800507,"mc":[{"id":"1.195453609","rc":[{"atb":[[9.6,7.08]],"id":43167166},{"atb":[[1.68,3.17]],"id":41719613},{"atb":[[11,5.15]],"id":43016477}],"con":true,"img":false}]}
{"op":"mcm","clk":"5347831544","pt":1646208800706,"mc":[{"id":"1.195453609","rc":[{"atb":[[9.4,1.59],[9.8,2]],"id":43167166},{"atb":[[10.5,0],[11.5,2]],"id":43016477}],"con":true,"img":false}]}
{"op":"mcm","clk":"5347831553","pt":1646208800912,"mc":[{"id":"1.195453609","rc":[{"atb":[[9.8,0]],"id":43167166},{"atb":[[11.5,0]],"id":43016477}],"con":true,"img":false}]}
{"op":"mcm","clk":"5347831558","pt":1646208801014,"mc":[{"id":"1.195453609","rc":[{"atb":[[9.8,2]],"id":43167166},{"atb":[[1.67,0]],"id":41719613},{"atb":[[11.5,2]],"id":43016477}],"con":true,"img":false}]}
{"op":"mcm","clk":"5347831600","pt":1646208801797,"mc":[{"id":"1.195453609","rc":[{"atb":[[9.6,4.57]],"id":43167166},{"atb":[[11,3.06]],"id":43016477}],"con":true,"img":false}]}
{"op":"mcm","clk":"5347831650","pt":1646208802921,"mc":[{"id":"1.195453609","rc":[{"atb":[[8.6,0]],"id":43167170}],"con":true,"img":false}]}
{"op":"mcm","clk":"5347831674","pt":1646208803394,"mc":[{"id":"1.195453609","rc":[{"atb":[[10,2.5]],"id":43167166},{"atb":[[12,2.08]],"id":43016477}],"con":true,"img":false}]}
{"op":"mcm","clk":"5347831839","pt":1646208806893,"mc":[{"id":"1.195453609","rc":[{"atb":[[1.66,1.66]],"id":41719613}],"con":true,"img":false}]}
{"op":"mcm","clk":"5347831896","pt":1646208808530,"mc":[{"id":"1.195453609","rc":[{"atb":[[9.6,0]],"id":43167166},{"atb":[[11,0]],"id":43016477}],"con":true,"img":false}]}
{"op":"mcm","clk":"5347831900","pt":1646208808587,"mc":[{"id":"1.195453609","rc":[{"atb":[[8.8,2.56]],"id":43167170}],"con":true,"img":false}]}
{"op":"mcm","clk":"5347831905","pt":1646208808691,"mc":[{"id":"1.195453609","rc":[{"atb":[[8.4,14.66]],"id":43167170}],"con":true,"img":false}]}
{"op":"mcm","clk":"5347832007","pt":1646208811014,"mc":[{"id":"1.195453609","rc":[{"atb":[[1.68,0]],"id":41719613}],"con":true,"img":false}]}
{"op":"mcm","clk":"5347832055","pt":1646208812104,"mc":[{"id":"1.195453609","rc":[{"atb":[[1.67,4.23]],"id":41719613}],"con":true,"img":false}]}
{"op":"mcm","clk":"5347832074","pt":1646208812419,"mc":[{"id":"1.195453609","rc":[{"atb":[[1.67,0]],"id":41719613}],"con":true,"img":false}]}
{"op":"mcm","clk":"5347832189","pt":1646208814811,"mc":[{"id":"1.195453609","rc":[{"atb":[[8.6,11.27]],"id":43167166},{"atb":[[8.6,12.48]],"id":43167170},{"atb":[[9.4,10.21]],"id":43016477}],"con":true,"img":false}]}
{"op":"mcm","clk":"5347832234","pt":1646208815906,"mc":[{"id":"1.195453609","rc":[{"atb":[[1.63,11.94]],"id":41719613}],"con":true,"img":false}]}
{"op":"mcm","clk":"5347832290","pt":1646208816926,"mc":[{"id":"1.195453609","rc":[{"atb":[[9.8,0]],"id":43167166},{"atb":[[10.5,1.42]],"id":43167167},{"atl":[[23,0]],"id":43167167},{"atb":[[9.4,1.59]],"id":43167168},{"atb":[[7.8,2.98]],"id":43167169},{"atb":[[11,2.37]],"id":43167165},{"atl":[[25,3.72]],"id":43167165},{"atl":[[25,3.72]],"id":43167170},{"atb":[[11.5,0]],"id":43016477}],"con":true,"img":false}]}
{"op":"mcm","clk":"5347832318","pt":1646208817537,"mc":[{"id":"1.195453609","rc":[{"atb":[[1.63,27.97]],"id":41719613}],"con":true,"img":false}]}
{"op":"mcm","clk":"5347832331","pt":1646208817704,"mc":[{"id":"1.195453609","rc":[{"atb":[[1.54,175.67]],"id":41719613}],"con":true,"img":false}]}
{"op":"mcm","clk":"5347832373","pt":1646208818526,"mc":[{"id":"1.195453609","rc":[{"atb":[[1.67,4.23]],"id":41719613}],"con":true,"img":false}]}
{"op":"mcm","clk":"5347832392","pt":1646208818932,"mc":[{"id":"1.195453609","rc":[{"atb":[[1.67,0]],"id":41719613}],"con":true,"img":false}]}
{"op":"mcm","clk":"5347832512","pt":1646208821300,"mc":[{"id":"1.195453609","rc":[{"atb":[[8,13.55]],"id":43167167},{"atb":[[8,13.55]],"id":43167168}],"con":true,"img":false}]}
{"op":"mcm","clk":"5347832633","pt":1646208823941,"mc":[{"id":"1.195453609","rc":[{"spn":8.48,"spf":1.0,"id":43167166},{"spn":8.22,"spf":1.0,"id":43167167},{"spn":8.11,"spf":1.0,"id":43167168},{"atb":[[1.67,4.23]],"id":41719613},{"spn":1.63,"spf":1.0,"id":41719613},{"spn":7.08,"spf":1.0,"id":43167169},{"spn":8.37,"spf":1.0,"id":43167165},{"spn":8.79,"spf":1.0,"id":43016477}],"con":true,"img":false}]}
{"op":"mcm","clk":"5347832643","pt":1646208824139,"mc":[{"id":"1.195453609","rc":[{"atb":[[1.54,0]],"id":41719613}],"con":true,"img":false}]}
{"op":"mcm","clk":"5347832652","pt":1646208824197,"mc":[{"id":"1.195453609","rc":[{"atb":[[1.67,0]],"id":41719613}],"con":true,"img":false}]}
{"op":"mcm","clk":"5347832946","pt":1646208829432,"mc":[{"id":"1.195453609","rc":[{"atb":[[1.67,4.23]],"id":41719613}],"con":true,"img":false}]}
{"op":"mcm","clk":"5347832960","pt":1646208829743,"mc":[{"id":"1.195453609","rc":[{"atb":[[1.67,0]],"id":41719613}],"con":true,"img":false}]}
{"op":"mcm","clk":"5347832992","pt":1646208830313,"mc":[{"id":"1.195453609","rc":[{"atb":[[1.64,22.23]],"id":41719613}],"con":true,"img":false}]}
{"op":"mcm","clk":"5347833424","pt":1646208838717,"mc":[{"id":"1.195453609","rc":[{"atb":[[1.61,0]],"id":41719613}],"con":true,"img":false}]}
{"op":"mcm","clk":"5347833430","pt":1646208838820,"mc":[{"id":"1.195453609","rc":[{"atb":[[1.64,91.51]],"id":41719613}],"con":true,"img":false}]}
{"op":"mcm","clk":"5347833454","pt":1646208839329,"mc":[{"id":"1.195453609","rc":[{"atb":[[1.67,4.23]],"id":41719613}],"con":true,"img":false}]}
{"op":"mcm","clk":"5347833471","pt":1646208839642,"mc":[{"id":"1.195453609","rc":[{"atb":[[1.67,0]],"id":41719613}],"con":true,"img":false}]}
{"op":"mcm","clk":"5347833704","pt":1646208844352,"mc":[{"id":"1.195453609","rc":[{"atb":[[1.64,69.28]],"id":41719613}],"con":true,"img":false}]}
{"op":"mcm","clk":"5347833732","pt":1646208844969,"mc":[{"id":"1.195453609","rc":[{"atb":[[1.67,4.23]],"id":41719613}],"con":true,"img":false}]}
{"op":"mcm","clk":"5347833759","pt":1646208845441,"mc":[{"id":"1.195453609","rc":[{"atb":[[1.67,0]],"id":41719613}],"con":true,"img":false}]}
{"op":"mcm","clk":"5347833783","pt":1646208845954,"mc":[{"id":"1.195453609","rc":[{"atb":[[1.63,16.03]],"id":41719613}],"con":true,"img":false}]}
{"op":"mcm","clk":"5347833929","pt":1646208848631,"mc":[{"id":"1.195453609","rc":[{"atb":[[8.4,0]],"id":43167166},{"atb":[[1.64,0]],"id":41719613},{"atb":[[9.2,0]],"id":43016477}],"con":true,"img":false}]}
{"op":"mcm","clk":"5347833936","pt":1646208848737,"mc":[{"id":"1.195453609","rc":[{"atb":[[8.8,8.36]],"id":43167166},{"atb":[[1.61,69.28]],"id":41719613},{"atb":[[9.6,8.3]],"id":43016477}],"con":true,"img":false}]}
{"op":"mcm","clk":"5347834009","pt":1646208850275,"mc":[{"id":"1.195453609","rc":[{"atb":[[1.61,193.43]],"id":41719613}],"con":true,"img":false}]}
{"op":"mcm","clk":"5347834074","pt":1646208851458,"mc":[{"id":"1.195453609","rc":[{"atb":[[1.67,4.23]],"id":41719613}],"con":true,"img":false}]}
{"op":"mcm","clk":"5347834085","pt":1646208851770,"mc":[{"id":"1.195453609","rc":[{"atb":[[1.67,0]],"id":41719613}],"con":true,"img":false}]}
{"op":"mcm","clk":"5347834164","pt":1646208853159,"mc":[{"id":"1.195453609","rc":[{"atb":[[8.6,0]],"id":43167166},{"atb":[[9.4,0]],"id":43016477}],"con":true,"img":false}]}
{"op":"mcm","clk":"5347834370","pt":1646208857269,"mc":[{"id":"1.195453609","rc":[{"atb":[[1.67,4.23]],"id":41719613}],"con":true,"img":false}]}
{"op":"mcm","clk":"5347834404","pt":1646208857734,"mc":[{"id":"1.195453609","rc":[{"atb":[[1.67,0]],"id":41719613}],"con":true,"img":false}]}
{"op":"mcm","clk":"5347834452","pt":1646208858663,"mc":[{"id":"1.195453609","rc":[{"atb":[[8.8,0]],"id":43167166},{"atb":[[8.4,0]],"id":43167170}],"con":true,"img":false}]}
{"op":"mcm","clk":"5347834460","pt":1646208858765,"mc":[{"id":"1.195453609","rc":[{"atb":[[8.4,8.36]],"id":43167166},{"atb":[[8.8,17.22]],"id":43167170}],"con":true,"img":false}]}
{"op":"mcm","clk":"5347834527","pt":1646208859844,"mc":[{"id":"1.195453609","rc":[{"atb":[[9,6.15]],"id":43167166},{"atb":[[8,13.55]],"id":43016477}],"con":true,"img":false}]}
{"op":"mcm","clk":"5347834695","pt":1646208862567,"mc":[{"id":"1.195453609","rc":[{"atb":[[8.6,0]],"id":43167170}],"con":true,"img":false}]}
{"op":"mcm","clk":"5347834720","pt":1646208863085,"mc":[{"id":"1.195453609","rc":[{"atb":[[1.67,4.23]],"id":41719613}],"con":true,"img":false}]}
{"op":"mcm","clk":"5347834740","pt":1646208863343,"mc":[{"id":"1.195453609","rc":[{"atb":[[1.67,0]],"id":41719613}],"con":true,"img":false}]}
{"op":"mcm","clk":"5347834994","pt":1646208868094,"mc":[{"id":"1.195453609","rc":[{"atb":[[9.4,1.2],[1.02,2.25]],"id":43167166},{"atb":[[10,0],[1.02,2.25]],"id":43016477}],"con":true,"img":false}]}
{"op":"mcm","clk":"5347835005","pt":1646208868256,"mc":[{"id":"1.195453609","rc":[{"atb":[[1.02,0.36]],"id":43167166},{"atb":[[1.02,0.3]],"id":43016477}],"con":true,"img":false}]}
{"op":"mcm","clk":"5347835018","pt":1646208868463,"mc":[{"id":"1.195453609","rc":[{"atb":[[1.02,0]],"id":43167166}],"con":true,"img":false}]}
{"op":"mcm","clk":"5347835021","pt":1646208868559,"mc":[{"id":"1.195453609","rc":[{"atb":[[10.5,0.36]],"id":43167166}],"con":true,"img":false}]}
{"op":"mcm","clk":"5347835031","pt":1646208868668,"mc":[{"id":"1.195453609","rc":[{"atb":[[8.2,17.46],[7.8,0]],"id":43167167},{"atb":[[7.8,0]],"id":43167168},{"atb":[[8.8,2.56]],"id":43167170}],"con":true,"img":false}]}
{"op":"mcm","clk":"5347835034","pt":1646208868767,"mc":[{"id":"1.195453609","rc":[{"atb":[[8.2,16.13]],"id":43167168},{"atb":[[1.67,4.23]],"id":41719613},{"atb":[[8.4,14.66]],"id":43167170},{"atb":[[1.02,0]],"id":43016477}],"con":true,"img":false}]}
{"op":"mcm","clk":"5347835046","pt":1646208868875,"mc":[{"id":"1.195453609","rc":[{"atb":[[12.5,0.3]],"id":43016477}],"con":true,"img":false}]}
{"op":"mcm","clk":"5347835065","pt":1646208869186,"mc":[{"id":"1.195453609","rc":[{"atb":[[1.67,0]],"id":41719613}],"con":true,"img":false}]}
{"op":"mcm","clk":"5347835291","pt":1646208873297,"mc":[{"id":"1.195453609","rc":[{"atb":[[9.8,2]],"id":43167166},{"atb":[[10.5,3.42]],"id":43167167},{"atl":[[23,2]],"id":43167167},{"atb":[[9.4,3.59]],"id":43167168},{"atl":[[23,3.92],[24,0]],"id":43167168},{"atb":[[7.8,5.37]],"id":43167169},{"atb":[[11,4.37]],"id":43167165},{"atl":[[25,5.72]],"id":43167165},{"atb":[[8.6,2.63],[8.8,0]],"id":43167170},{"atl":[[32,4.03],[25,5.72],[29,6.25]],"id":43167170},{"atb":[[11.5,2]],"id":43016477}],"con":true,"img":false}]}
{"op":"mcm","clk":"5347835334","pt":1646208873972,"mc":[{"id":"1.195453609","rc":[{"atb":[[1.67,4.23]],"id":41719613}],"con":true,"img":false}]}
{"op":"mcm","clk":"5347835351","pt":1646208874280,"mc":[{"id":"1.195453609","rc":[{"atb":[[1.67,0]],"id":41719613}],"con":true,"img":false}]}
{"op":"mcm","clk":"5347835359","pt":1646208874380,"mc":[{"id":"1.195453609","rc":[{"atb":[[8,0]],"id":43167167},{"atb":[[8,0]],"id":43167168},{"atb":[[8.6,15.11]],"id":43167170}],"con":true,"img":false}]}
{"op":"mcm","clk":"5347835490","pt":1646208877204,"mc":[{"id":"1.195453609","rc":[{"atb":[[9,0]],"id":43167166},{"atb":[[8,0]],"id":43016477}],"con":true,"img":false}]}
{"op":"mcm","clk":"5347835556","pt":1646208878589,"mc":[{"id":"1.195453609","rc":[{"atb":[[8.2,0]],"id":43167168},{"atb":[[1.61,124.14]],"id":41719613},{"atl":[[34,3.47],[30,0]],"id":43016477}],"con":true,"img":false}]}
{"op":"mcm","clk":"5347835562","pt":1646208878693,"mc":[{"id":"1.195453609","rc":[{"atb":[[1.62,69.28]],"id":41719613},{"atb":[[7.8,16.13]],"id":43167168},{"atl":[[26,0]],"id":43167165},{"atl":[[26,0]],"id":43167170}],"con":true,"img":false}]}
{"op":"mcm","clk":"5347835567","pt":1646208878794,"mc":[{"id":"1.195453609","rc":[{"atl":[[28,4.39]],"id":43167165},{"atl":[[28,4.23]],"id":43167170}],"con":true,"img":false}]}
{"op":"mcm","clk":"5347835661","pt":1646208880907,"mc":[{"id":"1.195453609","rc":[{"atl":[[22,1]],"id":43167165}],"con":true,"img":false}]}
{"op":"mcm","clk":"5347835664","pt":1646208881009,"mc":[{"id":"1.195453609","rc":[{"atl":[[25,4.72]],"id":43167165}],"con":true,"img":false}]}
{"op":"mcm","clk":"5347835787","pt":1646208883588,"mc":[{"id":"1.195453609","rc":[{"atb":[[1.61,0]],"id":41719613}],"con":true,"img":false}]}
{"op":"mcm","clk":"5347835829","pt":1646208884313,"mc":[{"id":"1.195453609","rc":[{"spn":8.34,"spf":1.0,"id":43167166},{"spn":8.3,"spf":1.0,"id":43167167},{"spn":1.62,"spf":1.0,"id":41719613},{"spn":8.04,"spf":1.0,"id":43167168},{"spn":7.15,"spf":1.0,"id":43167169},{"spn":8.58,"spf":1.0,"id":43167165},{"atl":[[28,7.93],[29,2.68]],"id":43167170},{"spn":8.71,"spf":1.0,"id":43167170},{"spn":8.5,"spf":1.0,"id":43016477}],"con":true,"img":false}]}
{"op":"mcm","clk":"5347836050","pt":1646208888584,"mc":[{"id":"1.195453609","rc":[{"atb":[[1.62,0]],"id":41719613}],"con":true,"img":false}]}
{"op":"mcm","clk":"5347836056","pt":1646208888688,"mc":[{"id":"1.195453609","rc":[{"atb":[[1.61,69.28]],"id":41719613}],"con":true,"img":false}]}
{"op":"mcm","clk":"5347836128","pt":1646208889922,"mc":[{"id":"1.195453609","rc":[{"atb":[[8.6,12.16]],"id":43167166},{"atb":[[1.64,13.27]],"id":41719613},{"atb":[[9.8,8.77]],"id":43016477}],"con":true,"img":false}]}
{"op":"mcm","clk":"5347836179","pt":1646208890905,"mc":[{"id":"1.195453609","rc":[{"atl":[[24,2.17]],"id":43167165}],"con":true,"img":false}]}
{"op":"mcm","clk":"5347836555","pt":1646208898889,"mc":[{"id":"1.195453609","rc":[{"atb":[[1.65,10.46]],"id":41719613},{"atb":[[8.8,3.04]],"id":43167168},{"atb":[[8.8,3.04]],"id":43167170}],"con":true,"img":false}]}
{"op":"mcm","clk":"5347836612","pt":1646208899815,"mc":[{"id":"1.195453609","rc":[{"atb":[[9.6,2.5]],"id":43167168}],"con":true,"img":false}]}
{"op":"mcm","clk":"5347836664","pt":1646208900897,"mc":[{"id":"1.195453609","rc":[{"atl":[[32,0],[26,3],[27,0],[29,0]],"id":43167165}],"con":true,"img":false}]}
{"op":"mcm","clk":"5347836819","pt":1646208902942,"mc":[{"id":"1.195453609","rc":[{"atb":[[1.64,0]],"id":41719613},{"atb":[[8.6,2.63]],"id":43167170}],"con":true,"img":false}]}
{"op":"mcm","clk":"5347836855","pt":1646208903408,"mc":[{"id":"1.195453609","rc":[{"atb":[[8.8,0]],"id":43167168}],"con":true,"img":false}]}
{"op":"mcm","clk":"5347836998","pt":1646208905831,"mc":[{"id":"1.195453609","rc":[{"atb":[[1.65,0]],"id":41719613}],"con":true,"img":false}]}
{"op":"mcm","clk":"5347837008","pt":1646208906036,"mc":[{"id":"1.195453609","rc":[{"atb":[[1.63,27.97]],"id":41719613}],"con":true,"img":false}]}
{"op":"mcm","clk":"5347837073","pt":1646208907212,"mc":[{"id":"1.195453609","rc":[{"atb":[[1.67,4.23]],"id":41719613}],"con":true,"img":false}]}
{"op":"mcm","clk":"5347837092","pt":1646208907625,"mc":[{"id":"1.195453609","rc":[{"atb":[[1.67,0]],"id":41719613}],"con":true,"img":false}]}
{"op":"mcm","clk":"5347837126","pt":1646208908343,"mc":[{"id":"1.195453609","rc":[{"atb":[[9.6,2.75]],"id":43167166}],"con":true,"img":false}]}
{"op":"mcm","clk":"5347837170","pt":1646208909010,"mc":[{"id":"1.195453609","rc":[{"atb":[[1.66,10.75]],"id":41719613},{"atb":[[9.4,6.67]],"id":43167170}],"con":true,"img":false}]}
{"op":"mcm","clk":"5347837179","pt":1646208909122,"mc":[{"id":"1.195453609","rc":[{"atb":[[11,0],[1.02,2.25]],"id":43167170}],"con":true,"img":false}]}
{"op":"mcm","clk":"5347837196","pt":1646208909321,"mc":[{"id":"1.195453609","rc":[{"atb":[[1.02,0.33]],"id":43167170}],"con":true,"img":false}]}
{"op":"mcm","clk":"5347837213","pt":1646208909529,"mc":[{"id":"1.195453609","rc":[{"atb":[[1.02,0]],"id":43167170}],"con":true,"img":false}]}
{"op":"mcm","clk":"5347837222","pt":1646208909657,"mc":[{"id":"1.195453609","rc":[{"atb":[[9.6,0.33]],"id":43167170}],"con":true,"img":false}]}
{"op":"mcm","clk":"5347837244","pt":1646208909937,"mc":[{"id":"1.195453609","rc":[{"atb":[[8.4,0]],"id":43167170}],"con":true,"img":false}]}
{"op":"mcm","clk":"5347837251","pt":1646208910041,"mc":[{"id":"1.195453609","rc":[{"atb":[[8.8,17.7]],"id":43167170}],"con":true,"img":false}]}
{"op":"mcm","clk":"5347837282","pt":1646208910454,"mc":[{"id":"1.195453609","rc":[{"atb":[[8.8,3.04]],"id":43167170}],"con":true,"img":false}]}
{"op":"mcm","clk":"5347837295","pt":1646208910554,"mc":[{"id":"1.195453609","rc":[{"atb":[[8.6,17.29]],"id":43167170}],"con":true,"img":false}]}
{"op":"mcm","clk":"5347837319","pt":1646208910913,"mc":[{"id":"1.195453609","rc":[{"atl":[[28,9.02]],"id":43167165}],"con":true,"img":false}]}
{"op":"mcm","clk":"5347837333","pt":1646208911227,"mc":[{"id":"1.195453609","rc":[{"atb":[[1.64,20.74]],"id":41719613}],"con":true,"img":false}]}
{"op":"mcm","clk":"5347837357","pt":1646208911634,"mc":[{"id":"1.195453609","rc":[{"atb":[[8.6,0]],"id":43167166}],"con":true,"img":false}]}
{"op":"mcm","clk":"5347837494","pt":1646208913953,"mc":[{"id":"1.195453609","rc":[{"atb":[[8.8,0]],"id":43167170}],"con":true,"img":false}]}
{"op":"mcm","clk":"5347837650","pt":1646208916549,"mc":[{"id":"1.195453609","rc":[{"atb":[[9.6,0]],"id":43167166},{"atb":[[1.64,0]],"id":41719613}],"con":true,"img":false}]}
{"op":"mcm","clk":"5347837682","pt":1646208917366,"mc":[{"id":"1.195453609","rc":[{"atb":[[1.67,4.23]],"id":41719613}],"con":true,"img":false}]}
{"op":"mcm","clk":"5347837691","pt":1646208917523,"mc":[{"id":"1.195453609","rc":[{"atb":[[10,6.15]],"id":43167166},{"atb":[[9.4,0]],"id":43167170}],"con":true,"img":false}]}
{"op":"mcm","clk":"5347837698","pt":1646208917625,"mc":[{"id":"1.195453609","rc":[{"atb":[[10.5,2.36],[9.8,0]],"id":43167166},{"atb":[[1.67,0]],"id":41719613}],"con":true,"img":false}]}
{"op":"mcm","clk":"5347837760","pt":1646208918654,"mc":[{"id":"1.195453609","rc":[{"atb":[[1.61,0]],"id":41719613},{"atb":[[8.6,2.63]],"id":43167170},{"atl":[[28,3.7]],"id":43167170}],"con":true,"img":false}]}
{"op":"mcm","clk":"5347837770","pt":1646208918759,"mc":[{"id":"1.195453609","rc":[{"atb":[[1.64,69.28]],"id":41719613},{"atb":[[8.4,14.66]],"id":43167170},{"atl":[[27,6.15]],"id":43167170}],"con":true,"img":false}]}
{"op":"mcm","clk":"5347837781","pt":1646208918963,"mc":[{"id":"1.195453609","rc":[{"atb":[[10,3.64]],"id":43167166}],"con":true,"img":false}]}
{"op":"mcm","clk":"5347837822","pt":1646208919633,"mc":[{"id":"1.195453609","rc":[{"atb":[[9.6,3.09]],"id":43167170}],"con":true,"img":false}]}
{"op":"mcm","clk":"5347837835","pt":1646208920045,"mc":[{"id":"1.195453609","rc":[{"atb":[[1.66,1.66]],"id":41719613}],"con":true,"img":false}]}
{"op":"mcm","clk":"5347837858","pt":1646208920564,"mc":[{"id":"1.195453609","rc":[{"atb":[[11,2.08]],"id":43167170}],"con":true,"img":false}]}
{"op":"mcm","clk":"5347837973","pt":1646208922770,"mc":[{"id":"1.195453609","rc":[{"atb":[[1.67,7.52]],"id":41719613},{"atb":[[10,2.63]],"id":43016477}],"con":true,"img":false}]}
{"op":"mcm","clk":"5347837983","pt":1646208922974,"mc":[{"id":"1.195453609","rc":[{"atb":[[11,2.08],[8.4,0]],"id":43167166},{"atb":[[1.67,11.75]],"id":41719613},{"atl":[[28,4.63]],"id":43167165},{"atb":[[9.6,1.17]],"id":43016477}],"con":true,"img":false}]}
{"op":"mcm","clk":"5347837990","pt":1646208923078,"mc":[{"id":"1.195453609","rc":[{"atb":[[8.8,8.36]],"id":43167166},{"atl":[[25,9.12]],"id":43167165},{"atb":[[10,9.77]],"id":43016477}],"con":true,"img":false}]}
{"op":"mcm","clk":"5347837996","pt":1646208923133,"mc":[{"id":"1.195453609","rc":[{"atb":[[1.67,7.52]],"id":41719613}],"con":true,"img":false}]}
{"op":"mcm","clk":"5347838088","pt":1646208924943,"mc":[{"id":"1.195453609","rc":[{"atb":[[9.6,0.33]],"id":43167170}],"con":true,"img":false}]}
{"op":"mcm","clk":"5347838122","pt":1646208925559,"mc":[{"id":"1.195453609","rc":[{"atb":[[1.63,11.94]],"id":41719613}],"con":true,"img":false}]}
{"op":"mcm","clk":"5347838129","pt":1646208925660,"mc":[{"id":"1.195453609","rc":[{"atb":[[1.61,124.14]],"id":41719613}],"con":true,"img":false}]}
{"op":"mcm","clk":"5347838232","pt":1646208927155,"mc":[{"id":"1.195453609","rc":[{"atb":[[1.63,0]],"id":41719613}],"con":true,"img":false}]}
{"op":"mcm","clk":"5347838294","pt":1646208928283,"mc":[{"id":"1.195453609","rc":[{"atb":[[10,0]],"id":43167166},{"atb":[[9.8,0]],"id":43016477}],"con":true,"img":false}]}
{"op":"mcm","clk":"5347838315","pt":1646208928642,"mc":[{"id":"1.195453609","rc":[{"atb":[[8.8,0]],"id":43167166},{"atb":[[10,2.63]],"id":43016477}],"con":true,"img":false}]}
{"op":"mcm","clk":"5347838319","pt":1646208928744,"mc":[{"id":"1.195453609","rc":[{"atb":[[8.4,8.36]],"id":43167166},{"atb":[[9.2,7.13]],"id":43016477}],"con":true,"img":false}]}
{"op":"mcm","clk":"5347838387","pt":1646208929789,"mc":[{"id":"1.195453609","rc":[{"atb":[[1.67,0]],"id":41719613}],"con":true,"img":false}]}
{"op":"mcm","clk":"5347838450","pt":1646208930874,"mc":[{"id":"1.195453609","rc":[{"atb":[[1.67,4.23]],"id":41719613}],"con":true,"img":false}]}
{"op":"mcm","clk":"5347838468","pt":1646208931286,"mc":[{"id":"1.195453609","rc":[{"atb":[[1.67,0]],"id":41719613}],"con":true,"img":false}]}
{"op":"mcm","clk":"5347838526","pt":1646208932367,"mc":[{"id":"1.195453609","rc":[{"atb":[[10,0]],"id":43016477}],"con":true,"img":false}]}
{"op":"mcm","clk":"5347838532","pt":1646208932468,"mc":[{"id":"1.195453609","rc":[{"atb":[[8.6,3.11]],"id":43167166}],"con":true,"img":false}]}
{"op":"mcm","clk":"5347838590","pt":1646208933350,"mc":[{"id":"1.195453609","rc":[{"atb":[[10.5,0.36]],"id":43167166},{"atb":[[10.5,1.42]],"id":43167167},{"atl":[[23,0]],"id":43167167},{"atb":[[9.4,1.59]],"id":43167168},{"atb":[[7.8,2.98]],"id":43167169},{"atb":[[11,2.37]],"id":43167165},{"atl":[[25,7.12]],"id":43167165},{"atl":[[25,3.72]],"id":43167170},{"atb":[[11.5,0]],"id":43016477}],"con":true,"img":false}]}
{"op":"mcm","clk":"5347838597","pt":1646208933453,"mc":[{"id":"1.195453609","rc":[{"atb":[[1.02,2.25]],"id":43016477}],"con":true,"img":false}]}
{"op":"mcm","clk":"5347838603","pt":1646208933563,"mc":[{"id":"1.195453609","rc":[{"atb":[[12.5,0]],"id":43016477}],"con":true,"img":false}]}
{"op":"mcm","clk":"5347838611","pt":1646208933661,"mc":[{"id":"1.195453609","rc":[{"atb":[[1.02,0.3]],"id":43016477}],"con":true,"img":false}]}
{"op":"mcm","clk":"5347838620","pt":1646208933764,"mc":[{"id":"1.195453609","rc":[{"atb":[[1.02,0]],"id":43016477}],"con":true,"img":false}]}
{"op":"mcm","clk":"5347838625","pt":1646208933865,"mc":[{"id":"1.195453609","rc":[{"atb":[[9.8,0.3]],"id":43016477}],"con":true,"img":false}]}
{"op":"mcm","clk":"5347838651","pt":1646208934284,"mc":[{"id":"1.195453609","rc":[{"atb":[[8.6,15.6]],"id":43167166},{"atb":[[9.8,9.07]],"id":43016477}],"con":true,"img":false}]}
{"op":"mcm","clk":"5347838714","pt":1646208935064,"mc":[{"id":"1.195453609","rc":[{"atb":[[1.65,36.46]],"id":41719613},{"atb":[[9.8,11.77]],"id":43016477}],"con":true,"img":false}]}
{"op":"mcm","clk":"5347838744","pt":1646208935580,"mc":[{"id":"1.195453609","rc":[{"atb":[[1.64,0]],"id":41719613}],"con":true,"img":false}]}
{"op":"mcm","clk":"5347838754","pt":1646208935682,"mc":[{"id":"1.195453609","rc":[{"atb":[[1.62,69.28]],"id":41719613}],"con":true,"img":false}]}
{"op":"mcm","clk":"5347838792","pt":1646208936349,"mc":[{"id":"1.195453609","rc":[{"atb":[[1.67,4.23]],"id":41719613}],"con":true,"img":false}]}
{"op":"mcm","clk":"5347838818","pt":1646208936866,"mc":[{"id":"1.195453609","rc":[{"atb":[[8.4,12.82]],"id":43167167}],"con":true,"img":false}]}
{"op":"mcm","clk":"5347838893","pt":1646208938163,"mc":[{"id":"1.195453609","rc":[{"atb":[[9.8,9.07]],"id":43016477}],"con":true,"img":false}]}
{"op":"mcm","clk":"5347838924","pt":1646208938570,"mc":[{"id":"1.195453609","rc":[{"atl":[[25,4.39]],"id":43167165}],"con":true,"img":false}]}
{"op":"mcm","clk":"5347838937","pt":1646208938675,"mc":[{"id":"1.195453609","rc":[{"atl":[[24,4.89]],"id":43167165}],"con":true,"img":false}]}
{"op":"mcm","clk":"5347839016","pt":1646208939860,"mc":[{"id":"1.195453609","rc":[{"atb":[[1.61,0]],"id":41719613},{"atb":[[9.8,0.3]],"id":43016477}],"con":true,"img":false}]}
{"op":"mcm","clk":"5347839053","pt":1646208940579,"mc":[{"id":"1.195453609","rc":[{"atb":[[10.5,2.36]],"id":43167166},{"atb":[[10.5,3.42]],"id":43167167},{"atl":[[23,2]],"id":43167167},{"atb":[[9.4,3.59]],"id":43167168},{"atb":[[7.6,3.92]],"id":43167169},{"atb":[[11,4.37]],"id":43167165},{"atl":[[23,2]],"id":43167165},{"atl":[[25,5.72]],"id":43167170},{"atb":[[11.5,2]],"id":43016477}],"con":true,"img":false}]}
{"op":"mcm","clk":"5347839078","pt":1646208940993,"mc":[{"id":"1.195453609","rc":[{"atb":[[1.65,0]],"id":41719613}],"con":true,"img":false}]}
{"op":"mcm","clk":"5347839191","pt":1646208942696,"mc":[{"id":"1.195453609","rc":[{"atb":[[5.9,4.08],[5.4,0]],"id":43167167},{"atl":[[7.2,0],[6.2,0],[5.5,26.66]],"id":41719613},{"atb":[[7.4,0],[6.6,3.57]],"id":43167168},{"atb":[[4.4,5.88],[4.1,0]],"id":43167169},{"atb":[[4.4,0],[4.7,5.41]],"id":43167165},{"atl":[[25,4.72],[26,5],[28,0]],"id":43167170},{"atb":[[5.8,8.53],[6.2,3.85]],"id":43016477}],"con":true,"img":false}]}
{"op":"mcm","clk":"5347839237","pt":1646208943473,"mc":[{"id":"1.195453609","rc":[{"atb":[[9.4,2.82]],"id":43016477}],"con":true,"img":false}]}
{"op":"mcm","clk":"5347839303","pt":1646208944607,"mc":[{"id":"1.195453609","rc":[{"spn":8.78,"spf":1.0,"id":43167166},{"spn":8.64,"spf":1.0,"id":43167167},{"atb":[[7,0]],"id":43167168},{"spn":8.17,"spf":1.0,"id":43167168},{"spn":1.62,"spf":1.0,"id":41719613},{"spn":7.14,"spf":1.0,"id":43167169},{"atl":[[25,5.72],[26,4]],"id":43167170},{"spn":8.71,"spf":1.0,"id":43167170},{"spn":8.64,"spf":1.0,"id":43016477}],"con":true,"img":false}]}
{"op":"mcm","clk":"5347839388","pt":1646208946202,"mc":[{"id":"1.195453609","rc":[{"atb":[[8.4,0]],"id":43167167},{"atb":[[1.63,13.53]],"id":41719613},{"atb":[[9.4,13.03]],"id":43016477}],"con":true,"img":false}]}
{"op":"mcm","clk":"5347839604","pt":1646208949765,"mc":[{"id":"1.195453609","rc":[{"atb":[[1.64,15.78]],"id":41719613}],"con":true,"img":false}]}
{"op":"mcm","clk":"5347839646","pt":1646208950590,"mc":[{"id":"1.195453609","rc":[{"atb":[[8.4,0]],"id":43167166},{"atb":[[1.62,0]],"id":41719613}],"con":true,"img":false}]}
{"op":"mcm","clk":"5347839653","pt":1646208950693,"mc":[{"id":"1.195453609","rc":[{"atb":[[8.8,8.36]],"id":43167166},{"atb":[[1.61,69.28]],"id":41719613}],"con":true,"img":false}]}
{"op":"mcm","clk":"5347839759","pt":1646208952703,"mc":[{"id":"1.195453609","rc":[{"atb":[[5.7,10.64]],"id":43167167},{"atl":[[5.7,10.64]],"id":41719613},{"atb":[[6.2,9.62]],"id":43167168},{"atb":[[4.2,15.62]],"id":43167169},{"atb":[[4.5,14.29]],"id":43167165},{"atb":[[5.9,10.2]],"id":43016477}],"con":true,"img":false}]}
{"op":"mcm","clk":"5347839795","pt":1646208953271,"mc":[{"id":"1.195453609","rc":[{"atb":[[8.6,12.48]],"id":43167166},{"atb":[[1.63,8.45]],"id":41719613}],"con":true,"img":false}]}
{"op":"mcm","clk":"5347839834","pt":1646208953891,"mc":[{"id":"1.195453609","rc":[{"atb":[[8.6,0]],"id":43167166},{"atb":[[1.63,0]],"id":41719613}],"con":true,"img":false}]}
{"op":"mcm","clk":"5347840046","pt":1646208958215,"mc":[{"id":"1.195453609","rc":[{"atb":[[9.2,0]],"id":43016477}],"con":true,"img":false}]}
{"op":"mcm","clk":"5347840053","pt":1646208958319,"mc":[{"id":"1.195453609","rc":[{"atb":[[9.6,8.3]],"id":43016477}],"con":true,"img":false}]}
{"op":"mcm","clk":"5347840057","pt":1646208958372,"mc":[{"id":"1.195453609","rc":[{"atb":[[9,2.96]],"id":43167166},{"atb":[[1.62,5.5]],"id":41719613}],"con":true,"img":false}]}
{"op":"mcm","clk":"5347840067","pt":1646208958578,"mc":[{"id":"1.195453609","rc":[{"atb":[[8.8,0]],"id":43167166}],"con":true,"img":false}]}
{"op":"mcm","clk":"5347840074","pt":1646208958682,"mc":[{"id":"1.195453609","rc":[{"atb":[[8.4,8.36]],"id":43167166}],"con":true,"img":false}]}
{"op":"mcm","clk":"5347840123","pt":1646208959716,"mc":[{"id":"1.195453609","rc":[{"atb":[[9,14.08]],"id":43167166},{"atb":[[1.62,15.02]],"id":41719613}],"con":true,"img":false}]}
{"op":"mcm","clk":"5347840191","pt":1646208961008,"mc":[{"id":"1.195453609","rc":[{"atb":[[9.4,10.21]],"id":43016477}],"con":true,"img":false}]}
{"op":"mcm","clk":"5347840242","pt":1646208961986,"mc":[{"id":"1.195453609","rc":[{"atb":[[9.4,0]],"id":43016477}],"con":true,"img":false}]}
{"op":"mcm","clk":"5347840284","pt":1646208962706,"mc":[{"id":"1.195453609","rc":[{"atb":[[4.8,21.54],[5,0],[5.5,16.67],[5.2,0]],"id":43167167},{"atl":[[8,0],[8.4,0],[5.9,15.31],[7.6,0]],"id":41719613},{"atb":[[5.9,15.31]],"id":43167168},{"atb":[[3.85,0],[3.75,59.54],[4,52.29],[3.95,33.9]],"id":43167169},{"atb":[[4.3,22.73],[4,0],[3.9,0],[4.2,31.25]],"id":43167165},{"atb":[[5.4,0],[5.6,0],[5.2,0],[5.7,35]],"id":43016477}],"con":true,"img":false}]}
{"op":"mcm","clk":"5347840316","pt":1646208963322,"mc":[{"id":"1.195453609","rc":[{"atb":[[9,11.11]],"id":43167166}],"con":true,"img":false}]}
{"op":"mcm","clk":"5347840396","pt":1646208964818,"mc":[{"id":"1.195453609","rc":[{"atl":[[25,4.72],[26,5]],"id":43167170}],"con":true,"img":false}]}
{"op":"mcm","clk":"5347840442","pt":1646208965588,"mc":[{"id":"1.195453609","rc":[{"atb":[[9.8,2.99]],"id":43016477}],"con":true,"img":false}]}
{"op":"mcm","clk":"5347840473","pt":1646208966206,"mc":[{"id":"1.195453609","rc":[{"atb":[[1.63,11.94]],"id":41719613}],"con":true,"img":false}]}
{"op":"mcm","clk":"5347840555","pt":1646208967696,"mc":[{"id":"1.195453609","rc":[{"atb":[[9.8,11.16]],"id":43016477}],"con":true,"img":false}]}
{"op":"mcm","clk":"5347840587","pt":1646208968210,"mc":[{"id":"1.195453609","rc":[{"atb":[[9.2,2.88]],"id":43167166}],"con":true,"img":false}]}
{"op":"mcm","clk":"5347840614","pt":1646208968622,"mc":[{"id":"1.195453609","rc":[{"atl":[[24,2.17]],"id":43167165},{"atb":[[9.2,0]],"id":43167170}],"con":true,"img":false}]}
{"op":"mcm","clk":"5347840624","pt":1646208968725,"mc":[{"id":"1.195453609","rc":[{"atl":[[23,4.72]],"id":43167165},{"atb":[[9.4,7.5]],"id":43167170}],"con":true,"img":false}]}
{"op":"mcm","clk":"5347840636","pt":1646208968829,"mc":[{"id":"1.195453609","rc":[{"atl":[[23,2.72],[24,4.17]],"id":43167165}],"con":true,"img":false}]}
{"op":"mcm","clk":"5347840700","pt":1646208970116,"mc":[{"id":"1.195453609","rc":[{"atb":[[1.62,5.5]],"id":41719613}],"con":true,"img":false}]}
{"op":"mcm","clk":"5347840737","pt":1646208970834,"mc":[{"id":"1.195453609","rc":[{"atb":[[1.62,0]],"id":41719613}],"con":true,"img":false}]}
{"op":"mcm","clk":"5347840816","pt":1646208972734,"mc":[{"id":"1.195453609","rc":[{"atb":[[5.3,48.1]],"id":43167167},{"atl":[[6.2,24.04]],"id":41719613},{"atb":[[5.7,26.6]],"id":43167168},{"atb":[[3.9,43.1]],"id":43167169},{"atb":[[4.1,40.32]],"id":43167165},{"atb":[[5.5,27.78]],"id":43016477}],"con":true,"img":false}]}
{"op":"mcm","clk":"5347840823","pt":1646208972836,"mc":[{"id":"1.195453609","rc":[{"atb":[[9,0]],"id":43167166}],"con":true,"img":false}]}
{"op":"mcm","clk":"5347840883","pt":1646208974123,"mc":[{"id":"1.195453609","rc":[{"atb":[[1.64,0]],"id":41719613}],"con":true,"img":false}]}
{"op":"mcm","clk":"5347840918","pt":1646208974843,"mc":[{"id":"1.195453609","rc":[{"atl":[[28,1.85]],"id":43167170}],"con":true,"img":false}]}
{"op":"mcm","clk":"5347840961","pt":1646208975717,"mc":[{"id":"1.195453609","rc":[{"atb":[[1.68,3.17]],"id":41719613}],"con":true,"img":false}]}
{"op":"mcm","clk":"5347840964","pt":1646208975820,"mc":[{"id":"1.195453609","rc":[{"atb":[[9.2,0]],"id":43167166}],"con":true,"img":false}]}
{"op":"mcm","clk":"5347840970","pt":1646208975922,"mc":[{"id":"1.195453609","rc":[{"atb":[[1.68,6.13]],"id":41719613}],"con":true,"img":false}]}
{"op":"mcm","clk":"5347840983","pt":1646208976230,"mc":[{"id":"1.195453609","rc":[{"atb":[[1.67,0]],"id":41719613}],"con":true,"img":false}]}
{"op":"mcm","clk":"5347841090","pt":1646208978340,"mc":[{"id":"1.195453609","rc":[{"atb":[[8.6,3.11]],"id":43167166}],"con":true,"img":false}]}
{"op":"mcm","clk":"5347841109","pt":1646208978647,"mc":[{"id":"1.195453609","rc":[{"atl":[[27,1.92]],"id":43167170},{"atl":[[34,0]],"id":43016477}],"con":true,"img":false}]}
{"op":"mcm","clk":"5347841116","pt":1646208978751,"mc":[{"id":"1.195453609","rc":[{"atl":[[26,9.23]],"id":43167170},{"atl":[[30,3.47]],"id":43016477}],"con":true,"img":false}]}
{"op":"mcm","clk":"5347841139","pt":1646208979015,"mc":[{"id":"1.195453609","rc":[{"atb":[[9.4,10.09]],"id":43167166},{"atb":[[1.68,2.95]],"id":41719613}],"con":true,"img":false}]}
{"op":"mcm","clk":"5347841224","pt":1646208980552,"mc":[{"id":"1.195453609","rc":[{"atb":[[2.96,0]],"id":43167166}],"con":true,"img":false}]}
{"op":"mcm","clk":"5347841358","pt":1646208982819,"mc":[{"id":"1.195453609","rc":[{"atl":[[30,0]],"id":43016477}],"con":true,"img":false}]}
{"op":"mcm","clk":"5347841362","pt":1646208982922,"mc":[{"id":"1.195453609","rc":[{"atl":[[32,5.08]],"id":43016477}],"con":true,"img":false}]}
{"op":"mcm","clk":"5347841369","pt":1646208983025,"mc":[{"id":"1.195453609","rc":[{"atb":[[8.6,0]],"id":43167166}],"con":true,"img":false}]}
{"op":"mcm","clk":"5347841460","pt":1646208984415,"mc":[{"id":"1.195453609","rc":[{"atb":[[1.64,6.93]],"id":41719613}],"con":true,"img":false}]}
{"op":"mcm","clk":"5347841482","pt":1646208984821,"mc":[{"id":"1.195453609","rc":[{"atl":[[30,2.59]],"id":43167170}],"con":true,"img":false}]}
{"op":"mcm","clk":"5347841489","pt":1646208984926,"mc":[{"id":"1.195453609","rc":[{"atl":[[32,0],[27,0],[29,0]],"id":43167170}],"con":true,"img":false}]}
{"op":"mcm","clk":"5347841568","pt":1646208986263,"mc":[{"id":"1.195453609","rc":[{"atb":[[1.63,27.97]],"id":41719613}],"con":true,"img":false}]}
{"op":"mcm","clk":"5347841606","pt":1646208986934,"mc":[{"id":"1.195453609","rc":[{"atb":[[9.4,1.2]],"id":43167166}],"con":true,"img":false}]}
{"op":"mcm","clk":"5347841681","pt":1646208988035,"mc":[{"id":"1.195453609","rc":[{"atb":[[10.5,2],[1.02,2.25]],"id":43167166},{"atb":[[9.4,3.2],[1.02,2.25]],"id":43167168},{"atb":[[9.6,0],[1.02,2.25]],"id":43167170},{"atl":[[25,2]],"id":43167170}],"con":true,"img":false}]}
{"op":"mcm","clk":"5347841688","pt":1646208988127,"mc":[{"id":"1.195453609","rc":[{"atb":[[9.6,2.75]],"id":43167166},{"atb":[[1.68,0]],"id":41719613},{"atl":[[26,11.96]],"id":43167170}],"con":true,"img":false}]}
{"op":"mcm","clk":"5347841696","pt":1646208988230,"mc":[{"id":"1.195453609","rc":[{"atb":[[1.02,0.32]],"id":43167166},{"atb":[[1.02,0.38]],"id":43167168},{"atb":[[1.02,0.32]],"id":43167170}],"con":true,"img":false}]}
{"op":"mcm","clk":"5347841708","pt":1646208988434,"mc":[{"id":"1.195453609","rc":[{"atb":[[1.02,0]],"id":43167168}],"con":true,"img":false}]}
{"op":"mcm","clk":"5347841715","pt":1646208988539,"mc":[{"id":"1.195453609","rc":[{"atb":[[9.8,0.38]],"id":43167168}],"con":true,"img":false}]}
{"op":"mcm","clk":"5347841719","pt":1646208988640,"mc":[{"id":"1.195453609","rc":[{"atl":[[26,7.72]],"id":43167170}],"con":true,"img":false}]}
{"op":"mcm","clk":"5347841727","pt":1646208988745,"mc":[{"id":"1.195453609","rc":[{"atb":[[1.02,0]],"id":43167170},{"atl":[[27,4.23]],"id":43167170}],"con":true,"img":false}]}
{"op":"mcm","clk":"5347841736","pt":1646208988848,"mc":[{"id":"1.195453609","rc":[{"atb":[[11.5,0.32]],"id":43167170}],"con":true,"img":false}]}
{"op":"mcm","clk":"5347841750","pt":1646208989054,"mc":[{"id":"1.195453609","rc":[{"atb":[[1.02,0]],"id":43167166}],"con":true,"img":false}]}
{"op":"mcm","clk":"5347841756","pt":1646208989157,"mc":[{"id":"1.195453609","rc":[{"atb":[[11.5,0.32]],"id":43167166}],"con":true,"img":false}]}
{"op":"mcm","clk":"5347841943","pt":1646208992563,"mc":[{"id":"1.195453609","rc":[{"atb":[[9.6,10.47]],"id":43167166}],"con":true,"img":false}]}
{"op":"mcm","clk":"5347841999","pt":1646208993339,"mc":[{"id":"1.195453609","rc":[{"atl":[[26,3.72],[28,5.55]],"id":43167170}],"con":true,"img":false}]}
{"op":"mcm","clk":"5347842018","pt":1646208993643,"mc":[{"id":"1.195453609","rc":[{"atb":[[1.65,6.01]],"id":41719613}],"con":true,"img":false}]}
{"op":"mcm","clk":"5347842080","pt":1646208994833,"mc":[{"id":"1.195453609","rc":[{"atl":[[34,3.79]],"id":43167170}],"con":true,"img":false}]}
{"op":"mcm","clk":"5347842272","pt":1646208998660,"mc":[{"id":"1.195453609","rc":[{"atl":[[25,0]],"id":43167165},{"atb":[[9.6,1.17]],"id":43016477}],"con":true,"img":false}]}
{"op":"mcm","clk":"5347842278","pt":1646208998763,"mc":[{"id":"1.195453609","rc":[{"atl":[[23,7.12]],"id":43167165},{"atb":[[10,7.13]],"id":43016477}],"con":true,"img":false}]}
{"op":"mcm","clk":"5347842287","pt":1646208998968,"mc":[{"id":"1.195453609","rc":[{"atl":[[22,3],[24,2.17]],"id":43167165}],"con":true,"img":false}]}
{"op":"mcm","clk":"5347842419","pt":1646209001345,"mc":[{"id":"1.195453609","rc":[{"atb":[[9.8,8.47]],"id":43016477}],"con":true,"img":false}]}
{"op":"mcm","clk":"5347850933","pt":1646209002844,"mc":[{"id":"1.195453609","rc":[{"atb":[[9.8,0.3]],"id":43016477}],"con":true,"img":false}]}
{"op":"mcm","clk":"5347850951","pt":1646209002945,"mc":[{"id":"1.195453609","rc":[{"atb":[[2.96,0]],"id":43167168}],"con":true,"img":false}]}
{"op":"mcm","clk":"5347851136","pt":1646209007168,"mc":[{"id":"1.195453609","rc":[{"atb":[[10.5,0]],"id":43167166},{"spn":8.82,"spf":1.0,"id":43167166},{"atb":[[10.5,1.42]],"id":43167167},{"atl":[[23,0]],"id":43167167},{"spn":8.06,"spf":1.0,"id":43167167},{"atb":[[9.4,1.2]],"id":43167168},{"spn":8.03,"spf":1.0,"id":43167168},{"spn":1.63,"spf":1.0,"id":41719613},{"atb":[[7.6,1.53]],"id":43167169},{"spn":7.08,"spf":1.0,"id":43167169},{"atb":[[11,2.37]],"id":43167165},{"atl":[[22,1]],"id":43167165},{"spn":8.37,"spf":1.0,"id":43167165},{"atl":[[25,0]],"id":43167170},{"spn":8.77,"spf":1.0,"id":43167170},{"atb":[[11.5,0]],"id":43016477},{"spn":8.29,"spf":1.0,"id":43016477}],"con":true,"img":false}]}
