{"op":"mcm","clk":"5346195395","pt":1646178339824,"mc":[{"id":"1.195453749","marketDefinition":{"bspMarket":false,"turnInPlayEnabled":false,"persistenceEnabled":false,"marketBaseRate":7.0,"eventId":"31272494","eventTypeId":"4339","numberOfWinners":1,"bettingType":"ODDS","marketType":"QUINELLA","marketTime":"2022-03-02T08:51:00.000Z","suspendTime":"2022-03-02T08:51:00.000Z","bspReconciled":false,"complete":true,"inPlay":false,"crossMatching":false,"runnersVoidable":false,"numberOfActiveRunners":15,"betDelay":0,"status":"OPEN","runners":[{"status":"ACTIVE","sortPriority":1,"id":522741,"name":"1 - 2 / 2 - 1"},{"status":"ACTIVE","sortPriority":2,"id":522742,"name":"1 - 3 / 3 - 1"},{"status":"ACTIVE","sortPriority":3,"id":522743,"name":"1 - 4 / 4 - 1"},{"status":"ACTIVE","sortPriority":4,"id":522745,"name":"1 - 6 / 6 - 1"},{"status":"ACTIVE","sortPriority":5,"id":3805731,"name":"1 - 8 / 8 - 1"},{"status":"ACTIVE","sortPriority":6,"id":522746,"name":"2 - 3 / 3 - 2"},{"status":"ACTIVE","sortPriority":7,"id":522747,"name":"2 - 4 / 4 - 2"},{"status":"ACTIVE","sortPriority":8,"id":522749,"name":"2 - 6 / 6 - 2"},{"status":"ACTIVE","sortPriority":9,"id":3805740,"name":"2 - 8 / 8 - 2"},{"status":"ACTIVE","sortPriority":10,"id":522750,"name":"3 - 4 / 4 - 3"},{"status":"ACTIVE","sortPriority":11,"id":522752,"name":"3 - 6 / 6 - 3"},{"status":"ACTIVE","sortPriority":12,"id":3805747,"name":"3 - 8 / 8 - 3"},{"status":"ACTIVE","sortPriority":13,"id":522753,"name":"4 - 6 / 6 - 4"},{"status":"ACTIVE","sortPriority":14,"id":3805762,"name":"4 - 8 / 8 - 4"},{"status":"ACTIVE","sortPriority":15,"id":3805784,"name":"6 - 8 / 8 - 6"}],"regulators":["MR_INT"],"venue":"Traralgon","countryCode":"AU","discountAllowed":true,"timezone":"Australia/Sydney","openDate":"2022-03-02T08:31:00.000Z","version":4382480601,"name":"Quinella","eventName":"Traralgon (AUS) 2nd Mar"},"rc":[],"con":true,"img":false}]}
{"op":"mcm","clk":"5346200440","pt":1646178438338,"mc":[{"id":"1.195453749","rc":[{"atb":[[2.98,100.78],[2.68,118.78],[2.48,179.78]],"id":3805784},{"atb":[[18.5,11.4],[11,19.95],[8.4,35.95]],"id":3805747},{"atb":[[17.5,16.12],[50,4.07],[25,8.31]],"id":522746},{"atb":[[17.5,16.12],[50,4.07],[25,8.31]],"id":522747},{"atb":[[5.1,64.89],[9.2,24.33],[6.2,38.37]],"id":522749},{"atb":[[42,4.86],[26,10.64],[110,1.82]],"id":522750},{"atb":[[4.5,57.01],[3,133.04],[3.5,79.82]],"id":3805731},{"atb":[[16.5,12.87],[9.6,23.2],[7.6,40.31]],"id":522752},{"atb":[[18.5,11.4],[11,19.95],[8.4,35.95]],"id":3805762},{"atb":[[16.5,12.87],[9.6,23.2],[7.6,40.31]],"id":522753},{"atb":[[9,24.94],[7,44.34],[15,14.25]],"id":522741},{"atb":[[9.6,30.94],[23,9.06],[14,15.35]],"id":522742},{"atb":[[9.6,30.94],[23,9.06],[14,15.35]],"id":522743},{"atb":[[5.8,55.43],[11.5,19],[7.6,30.23]],"id":3805740},{"atb":[[3.7,73.91],[2.98,100.78],[2.78,149.48]],"id":522745}],"con":true,"img":false}]}
{"op":"mcm","clk":"5346401283","pt":1646182002774,"mc":[{"id":"1.195453749","marketDefinition":{"bspMarket":false,"turnInPlayEnabled":false,"persistenceEnabled":false,"marketBaseRate":7.0,"eventId":"31272494","eventTypeId":"4339","numberOfWinners":1,"bettingType":"ODDS","marketType":"QUINELLA","marketTime":"2022-03-02T08:51:00.000Z","suspendTime":"2022-03-02T08:51:00.000Z","bspReconciled":false,"complete":true,"inPlay":false,"crossMatching":false,"runnersVoidable":false,"numberOfActiveRunners":15,"betDelay":0,"status":"OPEN","runners":[{"status":"ACTIVE","sortPriority":1,"id":522741,"name":"1 - 2 / 2 - 1"},{"status":"ACTIVE","sortPriority":2,"id":522742,"name":"1 - 3 / 3 - 1"},{"status":"ACTIVE","sortPriority":3,"id":522743,"name":"1 - 4 / 4 - 1"},{"status":"ACTIVE","sortPriority":4,"id":522745,"name":"1 - 6 / 6 - 1"},{"status":"ACTIVE","sortPriority":5,"id":3805731,"name":"1 - 8 / 8 - 1"},{"status":"ACTIVE","sortPriority":6,"id":522746,"name":"2 - 3 / 3 - 2"},{"status":"ACTIVE","sortPriority":7,"id":522747,"name":"2 - 4 / 4 - 2"},{"status":"ACTIVE","sortPriority":8,"id":522749,"name":"2 - 6 / 6 - 2"},{"status":"ACTIVE","sortPriority":9,"id":3805740,"name":"2 - 8 / 8 - 2"},{"status":"ACTIVE","sortPriority":10,"id":522750,"name":"3 - 4 / 4 - 3"},{"status":"ACTIVE","sortPriority":11,"id":522752,"name":"3 - 6 / 6 - 3"},{"status":"ACTIVE","sortPriority":12,"id":3805747,"name":"3 - 8 / 8 - 3"},{"status":"ACTIVE","sortPriority":13,"id":522753,"name":"4 - 6 / 6 - 4"},{"status":"ACTIVE","sortPriority":14,"id":3805762,"name":"4 - 8 / 8 - 4"},{"status":"ACTIVE","sortPriority":15,"id":3805784,"name":"6 - 8 / 8 - 6"}],"regulators":["MR_INT"],"venue":"Traralgon","countryCode":"AU","discountAllowed":true,"timezone":"Australia/Sydney","openDate":"2022-03-02T08:31:00.000Z","version":4382480601,"name":"Quinella","eventName":"Traralgon (AUS) 2nd Mar"},"rc":[{"atb":[[2.98,100.8],[2.68,118.79],[2.48,179.8]],"id":3805784},{"atb":[[18.5,11.4],[11,19.95],[8.4,35.95]],"id":3805747},{"atb":[[17.5,16.12],[50,4.07],[25,8.31]],"id":522746},{"atb":[[17.5,16.12],[50,4.07],[25,8.31]],"id":522747},{"atb":[[5.1,64.9],[9.2,24.34],[6.2,38.38]],"id":522749},{"atb":[[42,4.86],[26,10.64],[110,1.82]],"id":522750},{"atb":[[4.5,57.02],[3,133.05],[3.5,79.83]],"id":3805731},{"atb":[[16.5,12.87],[9.6,23.2],[7.6,40.32]],"id":522752},{"atb":[[18.5,11.4],[11,19.95],[8.4,35.95]],"id":3805762},{"atb":[[16.5,12.87],[9.6,23.2],[7.6,40.32]],"id":522753},{"atb":[[9,24.94],[7,44.35],[15,14.25]],"id":522741},{"atb":[[9.6,30.94],[23,9.07],[14,15.35]],"id":522742},{"atb":[[9.6,30.94],[23,9.07],[14,15.35]],"id":522743},{"atb":[[5.8,55.43],[11.5,19],[7.6,30.24]],"id":3805740},{"atb":[[3.7,73.92],[2.98,100.8],[2.78,149.5]],"id":522745}],"con":true,"img":true}]}
{"op":"mcm","clk":"5346767644","pt":1646187402718,"mc":[{"id":"1.195453749","marketDefinition":{"bspMarket":false,"turnInPlayEnabled":false,"persistenceEnabled":false,"marketBaseRate":7.0,"eventId":"31272494","eventTypeId":"4339","numberOfWinners":1,"bettingType":"ODDS","marketType":"QUINELLA","marketTime":"2022-03-02T08:51:00.000Z","suspendTime":"2022-03-02T08:51:00.000Z","bspReconciled":false,"complete":true,"inPlay":false,"crossMatching":false,"runnersVoidable":false,"numberOfActiveRunners":15,"betDelay":0,"status":"OPEN","runners":[{"status":"ACTIVE","sortPriority":1,"id":522741,"name":"1 - 2 / 2 - 1"},{"status":"ACTIVE","sortPriority":2,"id":522742,"name":"1 - 3 / 3 - 1"},{"status":"ACTIVE","sortPriority":3,"id":522743,"name":"1 - 4 / 4 - 1"},{"status":"ACTIVE","sortPriority":4,"id":522745,"name":"1 - 6 / 6 - 1"},{"status":"ACTIVE","sortPriority":5,"id":3805731,"name":"1 - 8 / 8 - 1"},{"status":"ACTIVE","sortPriority":6,"id":522746,"name":"2 - 3 / 3 - 2"},{"status":"ACTIVE","sortPriority":7,"id":522747,"name":"2 - 4 / 4 - 2"},{"status":"ACTIVE","sortPriority":8,"id":522749,"name":"2 - 6 / 6 - 2"},{"status":"ACTIVE","sortPriority":9,"id":3805740,"name":"2 - 8 / 8 - 2"},{"status":"ACTIVE","sortPriority":10,"id":522750,"name":"3 - 4 / 4 - 3"},{"status":"ACTIVE","sortPriority":11,"id":522752,"name":"3 - 6 / 6 - 3"},{"status":"ACTIVE","sortPriority":12,"id":3805747,"name":"3 - 8 / 8 - 3"},{"status":"ACTIVE","sortPriority":13,"id":522753,"name":"4 - 6 / 6 - 4"},{"status":"ACTIVE","sortPriority":14,"id":3805762,"name":"4 - 8 / 8 - 4"},{"status":"ACTIVE","sortPriority":15,"id":3805784,"name":"6 - 8 / 8 - 6"}],"regulators":["MR_INT"],"venue":"Traralgon","countryCode":"AU","discountAllowed":true,"timezone":"Australia/Sydney","openDate":"2022-03-02T08:31:00.000Z","version":4382480601,"name":"Quinella","eventName":"Traralgon (AUS) 2nd Mar"},"rc":[{"atb":[[2.98,100.95],[2.68,118.98],[2.48,180.09]],"id":3805784},{"atb":[[18.5,11.42],[11,19.99],[8.4,36.01]],"id":3805747},{"atb":[[17.5,16.15],[50,4.07],[25,8.32]],"id":522746},{"atb":[[17.5,16.15],[50,4.07],[25,8.32]],"id":522747},{"atb":[[5.1,65],[9.2,24.37],[6.2,38.44]],"id":522749},{"atb":[[42,4.87],[26,10.66],[110,1.83]],"id":522750},{"atb":[[4.5,57.11],[3,133.26],[3.5,79.96]],"id":3805731},{"atb":[[16.5,12.89],[9.6,23.24],[7.6,40.38]],"id":522752},{"atb":[[18.5,11.42],[11,19.99],[8.4,36.01]],"id":3805762},{"atb":[[16.5,12.89],[9.6,23.24],[7.6,40.38]],"id":522753},{"atb":[[9,24.98],[7,44.42],[15,14.28]],"id":522741},{"atb":[[9.6,30.99],[23,9.08],[14,15.37]],"id":522742},{"atb":[[9.6,30.99],[23,9.08],[14,15.37]],"id":522743},{"atb":[[5.8,55.52],[11.5,19.03],[7.6,30.29]],"id":3805740},{"atb":[[3.7,74.03],[2.98,100.95],[2.78,149.74]],"id":522745}],"con":true,"img":true}]}
{"op":"mcm","clk":"5347092208","pt":1646192802700,"mc":[{"id":"1.195453749","marketDefinition":{"bspMarket":false,"turnInPlayEnabled":false,"persistenceEnabled":false,"marketBaseRate":7.0,"eventId":"31272494","eventTypeId":"4339","numberOfWinners":1,"bettingType":"ODDS","marketType":"QUINELLA","marketTime":"2022-03-02T08:51:00.000Z","suspendTime":"2022-03-02T08:51:00.000Z","bspReconciled":false,"complete":true,"inPlay":false,"crossMatching":false,"runnersVoidable":false,"numberOfActiveRunners":15,"betDelay":0,"status":"OPEN","runners":[{"status":"ACTIVE","sortPriority":1,"id":522741,"name":"1 - 2 / 2 - 1"},{"status":"ACTIVE","sortPriority":2,"id":522742,"name":"1 - 3 / 3 - 1"},{"status":"ACTIVE","sortPriority":3,"id":522743,"name":"1 - 4 / 4 - 1"},{"status":"ACTIVE","sortPriority":4,"id":522745,"name":"1 - 6 / 6 - 1"},{"status":"ACTIVE","sortPriority":5,"id":3805731,"name":"1 - 8 / 8 - 1"},{"status":"ACTIVE","sortPriority":6,"id":522746,"name":"2 - 3 / 3 - 2"},{"status":"ACTIVE","sortPriority":7,"id":522747,"name":"2 - 4 / 4 - 2"},{"status":"ACTIVE","sortPriority":8,"id":522749,"name":"2 - 6 / 6 - 2"},{"status":"ACTIVE","sortPriority":9,"id":3805740,"name":"2 - 8 / 8 - 2"},{"status":"ACTIVE","sortPriority":10,"id":522750,"name":"3 - 4 / 4 - 3"},{"status":"ACTIVE","sortPriority":11,"id":522752,"name":"3 - 6 / 6 - 3"},{"status":"ACTIVE","sortPriority":12,"id":3805747,"name":"3 - 8 / 8 - 3"},{"status":"ACTIVE","sortPriority":13,"id":522753,"name":"4 - 6 / 6 - 4"},{"status":"ACTIVE","sortPriority":14,"id":3805762,"name":"4 - 8 / 8 - 4"},{"status":"ACTIVE","sortPriority":15,"id":3805784,"name":"6 - 8 / 8 - 6"}],"regulators":["MR_INT"],"venue":"Traralgon","countryCode":"AU","discountAllowed":true,"timezone":"Australia/Sydney","openDate":"2022-03-02T08:31:00.000Z","version":4382480601,"name":"Quinella","eventName":"Traralgon (AUS) 2nd Mar"},"rc":[{"atb":[[2.98,101.13],[2.68,119.18],[2.48,180.39]],"id":3805784},{"atb":[[18.5,11.44],[11,20.02],[8.4,36.07]],"id":3805747},{"atb":[[17.5,16.17],[50,4.08],[25,8.34]],"id":522746},{"atb":[[17.5,16.17],[50,4.08],[25,8.34]],"id":522747},{"atb":[[5.1,65.11],[9.2,24.42],[6.2,38.5]],"id":522749},{"atb":[[42,4.88],[26,10.67],[110,1.83]],"id":522750},{"atb":[[4.5,57.2],[3,133.49],[3.5,80.09]],"id":3805731},{"atb":[[16.5,12.91],[9.6,23.28],[7.6,40.45]],"id":522752},{"atb":[[18.5,11.44],[11,20.02],[8.4,36.07]],"id":3805762},{"atb":[[16.5,12.91],[9.6,23.28],[7.6,40.45]],"id":522753},{"atb":[[9,25.02],[7,44.49],[15,14.3]],"id":522741},{"atb":[[9.6,31.04],[23,9.09],[14,15.4]],"id":522742},{"atb":[[9.6,31.04],[23,9.09],[14,15.4]],"id":522743},{"atb":[[5.8,55.62],[11.5,19.06],[7.6,30.34]],"id":3805740},{"atb":[[3.7,74.16],[2.98,101.13],[2.78,149.99]],"id":522745}],"con":true,"img":true}]}
{"op":"mcm","clk":"5347340073","pt":1646197402971,"mc":[{"id":"1.195453749","rc":[{"atb":[[2.98,0],[2.68,0],[2.48,0]],"id":3805784},{"atb":[[18.5,0],[11,0],[8.4,0]],"id":3805747},{"atb":[[17.5,0],[50,0],[25,0]],"id":522746},{"atb":[[17.5,0],[50,0],[25,0]],"id":522747},{"atb":[[5.1,0],[9.2,0],[6.2,0]],"id":522749},{"atb":[[42,0],[26,0],[110,0]],"id":522750},{"atb":[[4.5,0],[3,0],[3.5,0]],"id":3805731},{"atb":[[16.5,0],[9.6,0],[7.6,0]],"id":522752},{"atb":[[18.5,0],[11,0],[8.4,0]],"id":3805762},{"atb":[[16.5,0],[9.6,0],[7.6,0]],"id":522753},{"atb":[[9,0],[7,0],[15,0]],"id":522741},{"atb":[[9.6,0],[23,0],[14,0]],"id":522742},{"atb":[[9.6,0],[23,0],[14,0]],"id":522743},{"atb":[[5.8,0],[11.5,0],[7.6,0]],"id":3805740},{"atb":[[3.7,0],[2.98,0],[2.78,0]],"id":522745}],"con":true,"img":false}]}
{"op":"mcm","clk":"5347340415","pt":1646197411162,"mc":[{"id":"1.195453749","rc":[{"atb":[[2.54,129.97],[2.84,108.78],[2.34,199.17]],"id":3805784},{"atb":[[19.5,10.82],[12,18.19],[8.8,34.21]],"id":3805747},{"atb":[[36,5.71],[90,2.24],[23,12.13]],"id":522746},{"atb":[[70,2.89],[19.5,14.42],[29,7.14]],"id":522747},{"atb":[[6.2,51.32],[8.2,27.8],[13,16.68]],"id":522749},{"atb":[[150,1.34],[50,4.08],[30,9.2]],"id":522750},{"atb":[[3.2,90.98],[2.88,141.96],[3.95,67.85]],"id":3805731},{"atb":[[18.5,11.43],[11,20.01],[8.4,36.06]],"id":522752},{"atb":[[8,38.12],[17.5,12.13],[10,22.23]],"id":3805762},{"atb":[[16,13.34],[7.4,41.7],[9.4,23.82]],"id":522753},{"atb":[[18.5,11.43],[11,20.01],[8.4,36.06]],"id":522741},{"atb":[[10.5,28.09],[26,8],[15.5,13.8]],"id":522742},{"atb":[[22,9.53],[13.5,16.01],[9.4,31.77]],"id":522743},{"atb":[[8.6,26.33],[14,15.39],[6.6,47.66]],"id":3805740},{"atb":[[3.7,74.13],[2.98,101.09],[2.78,149.93]],"id":522745}],"con":true,"img":false}]}
{"op":"mcm","clk":"5347632960","pt":1646203860403,"mc":[{"id":"1.195453749","rc":[{"atb":[[2.38,2.73],[2.28,3.27]],"id":3805784},{"atb":[[11.5,3.27],[14,2.73]],"id":3805747},{"atb":[[32,3.27],[42,2.73]],"id":522746},{"atb":[[34,3.27],[44,2.73]],"id":522747},{"atb":[[8,2.73],[7,3.27]],"id":522749},{"atb":[[65,2.73],[46,3.27]],"id":522750},{"atb":[[4.3,2.73],[3.9,3.27]],"id":3805731},{"atb":[[11,23.29],[13.5,2.73]],"id":522752},{"atb":[[12,3.27],[14.5,2.73]],"id":522753},{"atb":[[11,23.29],[13.5,2.73]],"id":522741},{"atb":[[18,2.73],[15.5,17.07]],"id":522742},{"atb":[[16.5,3.27],[19,2.73]],"id":522743},{"atb":[[9.2,3.27],[10.5,2.73]],"id":3805740},{"atb":[[4.1,2.73],[3.8,3.27]],"id":522745}],"con":true,"img":false}]}
{"op":"mcm","clk":"5347632966","pt":1646203860711,"mc":[{"id":"1.195453749","rc":[{"atb":[[12.5,3.27],[15,2.73]],"id":3805762}],"con":true,"img":false}]}
{"op":"mcm","clk":"5347672793","pt":1646204988035,"mc":[{"id":"1.195453749","rc":[{"atb":[[2.54,129.93],[2.38,2.72],[2.28,3.27],[2.84,108.75],[2.34,199.11]],"id":3805784},{"atb":[[19.5,10.81],[11.5,3.27],[12,18.19],[8.8,34.2],[14,2.72]],"id":3805747},{"atb":[[32,3.27],[36,5.71],[42,2.72],[90,2.24],[23,12.12]],"id":522746},{"atb":[[70,2.89],[34,3.27],[19.5,14.42],[44,2.72],[29,7.14]],"id":522747},{"atb":[[8,0],[6.2,51.31],[8.2,27.79],[13,16.67],[7,0]],"id":522749},{"atb":[[65,2.72],[150,1.34],[46,3.27],[50,4.08],[30,9.2]],"id":522750},{"atb":[[4.3,2.72],[3.2,90.96],[2.88,141.92],[3.95,67.83],[3.9,3.27]],"id":3805731},{"atb":[[18.5,11.43],[11,23.28],[13.5,2.72],[8.4,36.05]],"id":522752},{"atb":[[8,38.11],[17.5,12.12],[10,22.23],[12.5,3.27],[15,2.72]],"id":3805762},{"atb":[[16,13.34],[7.4,41.69],[12,3.27],[14.5,2.72],[9.4,23.82]],"id":522753},{"atb":[[18.5,11.43],[11,23.28],[13.5,2.72],[8.4,36.05]],"id":522741},{"atb":[[18,2.72],[10.5,28.08],[26,8],[15.5,17.07]],"id":522742},{"atb":[[16.5,3.27],[19,2.72],[22,9.53],[13.5,16],[9.4,31.76]],"id":522743},{"atb":[[8.6,26.33],[9.2,3.27],[10.5,2.72],[14,15.39],[6.6,47.64]],"id":3805740},{"atb":[[4.1,2.72],[3.7,74.11],[3.8,3.27],[2.98,101.06],[2.78,149.89]],"id":522745}],"con":true,"img":false}]}
{"op":"mcm","clk":"5347672817","pt":1646204989015,"mc":[{"id":"1.195453749","rc":[{"atb":[[8.6,2.72],[7.6,3.27]],"id":522749}],"con":true,"img":false}]}
{"op":"mcm","clk":"5347675118","pt":1646205064049,"mc":[{"id":"1.195453749","rc":[{"atb":[[8.6,0],[7.6,0]],"id":522749}],"con":true,"img":false}]}
{"op":"mcm","clk":"5347675143","pt":1646205064730,"mc":[{"id":"1.195453749","rc":[{"atb":[[8,2.72],[7,3.27]],"id":522749}],"con":true,"img":false}]}
{"op":"mcm","clk":"5347676372","pt":1646205101003,"mc":[{"id":"1.195453749","rc":[{"atb":[[34,0],[44,0]],"id":522747}],"con":true,"img":false}]}
{"op":"mcm","clk":"5347676417","pt":1646205101982,"mc":[{"id":"1.195453749","rc":[{"atb":[[36,3.27],[46,2.72]],"id":522747}],"con":true,"img":false}]}
{"op":"mcm","clk":"5347694412","pt":1646205605952,"mc":[{"id":"1.195453749","rc":[{"atb":[[12,0],[14.5,0]],"id":522753}],"con":true,"img":false}]}
{"op":"mcm","clk":"5347694419","pt":1646205606064,"mc":[{"id":"1.195453749","rc":[{"atb":[[11.5,0],[14,0]],"id":3805747},{"atb":[[32,0],[42,0]],"id":522746},{"atb":[[36,0],[46,0]],"id":522747},{"atb":[[65,0],[46,0]],"id":522750},{"atb":[[4.3,0],[3.9,0]],"id":3805731},{"atb":[[11,20.01],[13.5,0]],"id":522752},{"atb":[[12.5,0],[15,0]],"id":3805762},{"atb":[[18,0],[15.5,13.79]],"id":522742},{"atb":[[16.5,0],[19,0]],"id":522743},{"atb":[[4.1,0],[3.8,0]],"id":522745}],"con":true,"img":false}]}
{"op":"mcm","clk":"5347694424","pt":1646205606170,"mc":[{"id":"1.195453749","rc":[{"atb":[[8,0],[7,0]],"id":522749}],"con":true,"img":false}]}
{"op":"mcm","clk":"5347694445","pt":1646205606684,"mc":[{"id":"1.195453749","rc":[{"atb":[[12,3.27],[14.5,2.72]],"id":522753}],"con":true,"img":false}]}
{"op":"mcm","clk":"5347694449","pt":1646205606782,"mc":[{"id":"1.195453749","rc":[{"atb":[[11.5,3.27],[14,2.72]],"id":3805747},{"atb":[[32,3.27],[42,2.72]],"id":522746},{"atb":[[36,3.27],[46,2.72]],"id":522747},{"atb":[[65,2.72],[46,3.27]],"id":522750},{"atb":[[4.3,2.72],[3.9,3.27]],"id":3805731},{"atb":[[11,23.28],[13.5,2.72]],"id":522752},{"atb":[[12.5,3.27],[15,2.72]],"id":3805762},{"atb":[[18,2.72],[15.5,17.07]],"id":522742},{"atb":[[16.5,3.27],[19,2.72]],"id":522743},{"atb":[[4.1,2.72],[3.8,3.27]],"id":522745}],"con":true,"img":false}]}
{"op":"mcm","clk":"5347694454","pt":1646205606891,"mc":[{"id":"1.195453749","rc":[{"atb":[[8,2.72],[7,3.27]],"id":522749}],"con":true,"img":false}]}
{"op":"mcm","clk":"5347712377","pt":1646206079930,"mc":[{"id":"1.195453749","rc":[{"atb":[[2.38,0],[2.28,0]],"id":3805784},{"atb":[[9.2,0],[10.5,0]],"id":3805740}],"con":true,"img":false}]}
{"op":"mcm","clk":"5347712412","pt":1646206080959,"mc":[{"id":"1.195453749","rc":[{"atb":[[2.24,3.27],[2.34,201.84]],"id":3805784},{"atb":[[11,2.72],[9.4,3.27]],"id":3805740}],"con":true,"img":false}]}
{"op":"mcm","clk":"5347712586","pt":1646206086866,"mc":[{"id":"1.195453749","rc":[{"atb":[[11,0],[9.4,0]],"id":3805740}],"con":true,"img":false}]}
{"op":"mcm","clk":"5347712612","pt":1646206087845,"mc":[{"id":"1.195453749","rc":[{"atb":[[9.2,3.27],[10.5,2.72]],"id":3805740}],"con":true,"img":false}]}
{"op":"mcm","clk":"5347714068","pt":1646206136035,"mc":[{"id":"1.195453749","rc":[{"atb":[[2.54,0],[2.84,0],[2.34,2.72]],"id":3805784},{"atb":[[19.5,0],[12,0],[8.8,0]],"id":3805747},{"atb":[[36,0],[90,0],[23,0]],"id":522746},{"atb":[[70,0],[19.5,0],[29,0]],"id":522747},{"atb":[[6.2,0],[8.2,0],[13,0]],"id":522749},{"atb":[[150,0],[50,0],[30,0]],"id":522750},{"atb":[[3.2,0],[2.88,0],[3.95,0]],"id":3805731},{"atb":[[18.5,0],[11,3.27],[8.4,0]],"id":522752},{"atb":[[8,0],[17.5,0],[10,0]],"id":3805762},{"atb":[[16,0],[7.4,0],[9.4,0]],"id":522753},{"atb":[[18.5,0],[11,3.27],[8.4,0]],"id":522741},{"atb":[[10.5,0],[26,0],[15.5,3.27]],"id":522742},{"atb":[[22,0],[13.5,0],[9.4,0]],"id":522743},{"atb":[[8.6,0],[14,0],[6.6,0]],"id":3805740},{"atb":[[3.7,0],[2.98,0],[2.78,0]],"id":522745}],"con":true,"img":false}]}
{"op":"mcm","clk":"5347714768","pt":1646206153365,"mc":[{"id":"1.195453749","rc":[{"atb":[[34,6.06],[85,2.37],[22,12.7]],"id":522746},{"atb":[[80,2.53],[42,6.5],[210,0.95]],"id":522747},{"atb":[[2.82,146.59],[3.8,71.46],[3.05,97.61]],"id":3805731},{"atb":[[18.5,11.43],[11,23.28],[8.4,36.05]],"id":522741},{"atb":[[24,8.7],[9.8,30.32],[14.5,14.82]],"id":522742},{"atb":[[32,6.45],[18,11.76],[13,22.23]],"id":522743},{"atb":[[3.6,76.96],[2.74,153.34],[2.94,103.14]],"id":522745}],"con":true,"img":false}]}
{"op":"mcm","clk":"5347714778","pt":1646206153480,"mc":[{"id":"1.195453749","rc":[{"atb":[[2.28,208.44],[2.78,112.42],[2.48,135.2]],"id":3805784},{"atb":[[18,11.76],[10.5,21.06],[8.2,37.05]],"id":3805747},{"atb":[[6.2,51.31],[8.2,27.79],[13,16.67]],"id":522749},{"atb":[[340,0.58],[190,1.05],[95,2.83]],"id":522750},{"atb":[[17,12.5],[9.8,22.74],[7.8,39.23]],"id":522752},{"atb":[[10.5,28.08],[26,8],[15.5,13.79]],"id":3805762},{"atb":[[10,29.64],[25,8.33],[15,14.29]],"id":522753},{"atb":[[8.6,26.33],[14,15.39],[6.6,47.64]],"id":3805740}],"con":true,"img":false}]}
{"op":"mcm","clk":"5347714939","pt":1646206157730,"mc":[{"id":"1.195453749","rc":[{"atb":[[14.5,0]],"id":522753}],"con":true,"img":false}]}
{"op":"mcm","clk":"5347714944","pt":1646206157831,"mc":[{"id":"1.195453749","rc":[{"atb":[[36,0],[46,0]],"id":522747},{"atb":[[46,0]],"id":522750},{"atb":[[12.5,0],[15,0]],"id":3805762},{"atb":[[16.5,0]],"id":522743}],"con":true,"img":false}]}
{"op":"mcm","clk":"5347714949","pt":1646206157934,"mc":[{"id":"1.195453749","rc":[{"atb":[[12,0]],"id":522753},{"atb":[[19,0]],"id":522743}],"con":true,"img":false}]}
{"op":"mcm","clk":"5347714954","pt":1646206158036,"mc":[{"id":"1.195453749","rc":[{"atb":[[65,0]],"id":522750}],"con":true,"img":false}]}
{"op":"mcm","clk":"5347714971","pt":1646206158446,"mc":[{"id":"1.195453749","rc":[{"atb":[[16,2.72]],"id":522753}],"con":true,"img":false}]}
{"op":"mcm","clk":"5347714977","pt":1646206158653,"mc":[{"id":"1.195453749","rc":[{"atb":[[42,9.78],[55,2.72]],"id":522747},{"atb":[[48,3.27]],"id":522750},{"atb":[[16.5,2.72],[14,3.27]],"id":3805762},{"atb":[[13.5,3.27]],"id":522753},{"atb":[[18,15.04],[21,2.72]],"id":522743}],"con":true,"img":false}]}
{"op":"mcm","clk":"5347714983","pt":1646206158756,"mc":[{"id":"1.195453749","rc":[{"atb":[[70,2.72]],"id":522750}],"con":true,"img":false}]}
{"op":"mcm","clk":"5347716718","pt":1646206201069,"mc":[{"id":"1.195453749","rc":[{"atb":[[8,0],[7,0]],"id":522749}],"con":true,"img":false}]}
{"op":"mcm","clk":"5347716796","pt":1646206202665,"mc":[{"id":"1.195453749","rc":[{"atb":[[8.8,2.72],[7.8,3.27]],"id":522749}],"con":true,"img":false}]}
{"op":"mcm","clk":"5347719540","pt":1646206260728,"mc":[{"id":"1.195453749","rc":[{"atb":[[4.1,0],[3.8,0]],"id":522745}],"con":true,"img":false}]}
{"op":"mcm","clk":"5347719579","pt":1646206261449,"mc":[{"id":"1.195453749","rc":[{"atb":[[4,2.72],[3.75,3.27]],"id":522745}],"con":true,"img":false}]}
{"op":"mcm","clk":"5347721090","pt":1646206293984,"mc":[{"id":"1.195453749","rc":[{"atb":[[8.8,0],[7.8,0]],"id":522749}],"con":true,"img":false}]}
{"op":"mcm","clk":"5347721119","pt":1646206294548,"mc":[{"id":"1.195453749","rc":[{"atb":[[8,2.72],[7,3.27]],"id":522749}],"con":true,"img":false}]}
{"op":"mcm","clk":"5347722619","pt":1646206335592,"mc":[{"id":"1.195453749","rc":[{"atb":[[32,0],[42,0]],"id":522746},{"atb":[[11,20.01],[13.5,0]],"id":522741}],"con":true,"img":false}]}
{"op":"mcm","clk":"5347722648","pt":1646206336309,"mc":[{"id":"1.195453749","rc":[{"atb":[[12,3.27],[14.5,2.72]],"id":522741}],"con":true,"img":false}]}
{"op":"mcm","clk":"5347722657","pt":1646206336515,"mc":[{"id":"1.195453749","rc":[{"atb":[[36,3.27],[46,2.72]],"id":522746}],"con":true,"img":false}]}
{"op":"mcm","clk":"5347731416","pt":1646206584597,"mc":[{"id":"1.195453749","rc":[{"atb":[[2.34,0]],"id":3805784}],"con":true,"img":false}]}
{"op":"mcm","clk":"5347731421","pt":1646206584903,"mc":[{"id":"1.195453749","rc":[{"atb":[[2.24,0]],"id":3805784}],"con":true,"img":false}]}
{"op":"mcm","clk":"5347731431","pt":1646206585269,"mc":[{"id":"1.195453749","rc":[{"atb":[[2.38,2.72]],"id":3805784}],"con":true,"img":false}]}
{"op":"mcm","clk":"5347731444","pt":1646206585578,"mc":[{"id":"1.195453749","rc":[{"atb":[[2.28,211.72]],"id":3805784}],"con":true,"img":false}]}
{"op":"mcm","clk":"5347741054","pt":1646206836114,"mc":[{"id":"1.195453749","rc":[{"atb":[[8,0],[7,0]],"id":522749},{"atb":[[9.2,0],[10.5,0]],"id":3805740}],"con":true,"img":false}]}
{"op":"mcm","clk":"5347741084","pt":1646206836781,"mc":[{"id":"1.195453749","rc":[{"atb":[[8.8,2.72],[7.8,3.27]],"id":522749},{"atb":[[9.6,3.27],[11.5,2.72]],"id":3805740}],"con":true,"img":false}]}
{"op":"mcm","clk":"5347749279","pt":1646207038518,"mc":[{"id":"1.195453749","rc":[{"atb":[[2.38,0]],"id":3805784}],"con":true,"img":false}]}
{"op":"mcm","clk":"5347749297","pt":1646207038827,"mc":[{"id":"1.195453749","rc":[{"atb":[[2.28,208.44]],"id":3805784}],"con":true,"img":false}]}
{"op":"mcm","clk":"5347749325","pt":1646207039498,"mc":[{"id":"1.195453749","rc":[{"atb":[[2.52,2.72]],"id":3805784}],"con":true,"img":false}]}
{"op":"mcm","clk":"5347749336","pt":1646207039806,"mc":[{"id":"1.195453749","rc":[{"atb":[[2.42,3.27]],"id":3805784}],"con":true,"img":false}]}
{"op":"mcm","clk":"5347771001","pt":1646207461978,"mc":[{"id":"1.195453749","rc":[{"atb":[[1.66,151.52]],"id":3805784},{"atl":[[220,2]],"id":3805784},{"atb":[[6.6,17.86]],"id":3805747},{"atl":[[630,2]],"id":3805747},{"atb":[[13,6.56]],"id":522746},{"atl":[[1000,2]],"id":522746},{"atb":[[21,5]],"id":522747},{"atl":[[1000,2]],"id":522747},{"atb":[[2.94,33.36]],"id":522749},{"atl":[[260,2]],"id":522749},{"atb":[[26,4]],"id":522750},{"atb":[[2.24,80.65]],"id":3805731},{"atl":[[290,2]],"id":3805731},{"atb":[[5.5,22.22]],"id":522752},{"atl":[[570,2]],"id":522752},{"atb":[[6,16]],"id":3805762},{"atl":[[570,2]],"id":3805762},{"atb":[[5,16.68]],"id":522753},{"atl":[[520,2]],"id":522753},{"atb":[[5.4,22.73]],"id":522741},{"atl":[[540,2]],"id":522741},{"atb":[[20,5.26]],"id":522742},{"atl":[[1000,2]],"id":522742},{"atb":[[13,30.56]],"id":522743},{"atl":[[990,2]],"id":522743},{"atb":[[3.2,30.78]],"id":3805740},{"atl":[[350,2]],"id":3805740},{"atb":[[2.76,56.82]],"id":522745},{"atl":[[210,2]],"id":522745}],"con":true,"img":false}]}
{"op":"mcm","clk":"5347771636","pt":1646207473950,"mc":[{"id":"1.195453749","rc":[{"atb":[[19,5.56],[20,0]],"id":522742}],"con":true,"img":false}]}
{"op":"mcm","clk":"5347771660","pt":1646207474255,"mc":[{"id":"1.195453749","rc":[{"atb":[[2.42,0],[2.52,0]],"id":3805784}],"con":true,"img":false}]}
{"op":"mcm","clk":"5347771668","pt":1646207474458,"mc":[{"id":"1.195453749","rc":[{"atb":[[8.8,0],[7.8,0]],"id":522749}],"con":true,"img":false}]}
{"op":"mcm","clk":"5347771714","pt":1646207475280,"mc":[{"id":"1.195453749","rc":[{"atb":[[2.38,3.27],[2.48,137.93]],"id":3805784},{"atb":[[9.8,2.72],[8.8,3.27]],"id":522749}],"con":true,"img":false}]}
{"op":"mcm","clk":"5347773014","pt":1646207499094,"mc":[{"id":"1.195453749","rc":[{"atl":[[600,2],[630,0]],"id":3805747},{"atb":[[21,0],[26,4]],"id":522747},{"atb":[[3.15,33.36],[2.94,0]],"id":522749},{"atl":[[290,0],[230,2]],"id":3805731},{"atl":[[570,0],[560,2]],"id":522752},{"atb":[[5.6,16.68],[5,0]],"id":522753},{"atb":[[5.9,20.41],[5.4,0]],"id":522741},{"atl":[[540,0],[530,2]],"id":522741},{"atl":[[970,2],[1000,0]],"id":522742},{"atl":[[990,0],[960,2]],"id":522743},{"atb":[[3.45,30.78],[3.2,0]],"id":3805740},{"atb":[[2.92,52.08],[2.76,0]],"id":522745},{"atl":[[210,0],[120,2]],"id":522745}],"con":true,"img":false}]}
{"op":"mcm","clk":"5347776138","pt":1646207553385,"mc":[{"id":"1.195453749","rc":[{"atl":[[600,0],[610,2]],"id":3805747},{"atl":[[990,2],[1000,0]],"id":522747},{"atl":[[260,0],[250,2]],"id":522749},{"atl":[[270,2],[230,0]],"id":3805731},{"atl":[[570,0],[550,2]],"id":3805762},{"atl":[[520,0],[510,2]],"id":522753},{"atb":[[19,0],[20,5.26]],"id":522742},{"atl":[[970,0],[990,2]],"id":522742},{"atl":[[940,2],[960,0]],"id":522743},{"atl":[[330,2],[350,0]],"id":3805740},{"atl":[[190,2],[120,0]],"id":522745}],"con":true,"img":false}]}
{"op":"mcm","clk":"5347776168","pt":1646207553745,"mc":[{"id":"1.195453749","rc":[{"atb":[[9.8,0],[8.8,0]],"id":522749}],"con":true,"img":false}]}
{"op":"mcm","clk":"5347776237","pt":1646207554569,"mc":[{"id":"1.195453749","rc":[{"atb":[[8.8,2.72],[7.8,3.27]],"id":522749}],"con":true,"img":false}]}
{"op":"mcm","clk":"5347777737","pt":1646207581675,"mc":[{"id":"1.195453749","rc":[{"atb":[[9.6,0],[11.5,0]],"id":3805740},{"atb":[[4,0],[3.75,0]],"id":522745}],"con":true,"img":false}]}
{"op":"mcm","clk":"5347777782","pt":1646207582393,"mc":[{"id":"1.195453749","rc":[{"atb":[[11,2.72],[9.4,3.27]],"id":3805740}],"con":true,"img":false}]}
{"op":"mcm","clk":"5347777797","pt":1646207582600,"mc":[{"id":"1.195453749","rc":[{"atb":[[4.1,2.72],[3.8,3.27]],"id":522745}],"con":true,"img":false}]}
{"op":"mcm","clk":"5347777831","pt":1646207583173,"mc":[{"id":"1.195453749","rc":[{"atl":[[80,2],[220,0]],"id":3805784},{"atb":[[10,9.34]],"id":522746},{"atb":[[2.24,0],[2.6,62.5]],"id":3805731},{"atl":[[530,0],[540,2]],"id":522741},{"atb":[[20,0],[12.5,8.7]],"id":522742}],"con":true,"img":false}]}
{"op":"mcm","clk":"5347777838","pt":1646207583281,"mc":[{"id":"1.195453749","rc":[{"atb":[[13,0]],"id":522746}],"con":true,"img":false}]}
{"op":"mcm","clk":"5347778140","pt":1646207589577,"mc":[{"id":"1.195453749","rc":[{"atl":[[160,2],[190,0]],"id":522745}],"con":true,"img":false}]}
{"op":"mcm","clk":"5347779493","pt":1646207614027,"mc":[{"id":"1.195453749","rc":[{"atb":[[4.3,0],[3.9,0]],"id":3805731}],"con":true,"img":false}]}
{"op":"mcm","clk":"5347779532","pt":1646207614702,"mc":[{"id":"1.195453749","rc":[{"atb":[[4.1,2.72],[3.8,74.74]],"id":3805731}],"con":true,"img":false}]}
{"op":"mcm","clk":"5347782609","pt":1646207673272,"mc":[{"id":"1.195453749","rc":[{"atb":[[5.9,0]],"id":522741},{"atl":[[190,2]],"id":522745}],"con":true,"img":false}]}
{"op":"mcm","clk":"5347782612","pt":1646207673377,"mc":[{"id":"1.195453749","rc":[{"atb":[[26,0]],"id":522747},{"atb":[[3.15,0],[2.94,44.47]],"id":522749},{"atl":[[560,0],[570,2]],"id":522752},{"atb":[[5.6,0],[5,22.64]],"id":522753},{"atb":[[5.1,24.39]],"id":522741},{"atl":[[160,0]],"id":522745}],"con":true,"img":false}]}
{"op":"mcm","clk":"5347782620","pt":1646207673582,"mc":[{"id":"1.195453749","rc":[{"atb":[[21,5]],"id":522747}],"con":true,"img":false}]}
{"op":"mcm","clk":"5347783935","pt":1646207701607,"mc":[{"id":"1.195453749","rc":[{"atb":[[70,0],[48,0]],"id":522750},{"atb":[[4.1,0],[3.8,71.46]],"id":3805731}],"con":true,"img":false}]}
{"op":"mcm","clk":"5347783974","pt":1646207702331,"mc":[{"id":"1.195453749","rc":[{"atb":[[75,2.72],[50,3.27]],"id":522750},{"atb":[[3.85,3.27],[4.2,2.72]],"id":3805731}],"con":true,"img":false}]}
{"op":"mcm","clk":"5347790800","pt":1646207839759,"mc":[{"id":"1.195453749","rc":[{"atb":[[2.38,0],[2.48,135.2]],"id":3805784}],"con":true,"img":false}]}
{"op":"mcm","clk":"5347790825","pt":1646207840477,"mc":[{"id":"1.195453749","rc":[{"atb":[[2.42,3.27],[2.52,2.72]],"id":3805784}],"con":true,"img":false}]}
{"op":"mcm","clk":"5347794727","pt":1646207935871,"mc":[{"id":"1.195453749","rc":[{"atb":[[11,0]],"id":3805740}],"con":true,"img":false}]}
{"op":"mcm","clk":"5347794735","pt":1646207936178,"mc":[{"id":"1.195453749","rc":[{"atb":[[9.4,0]],"id":3805740}],"con":true,"img":false}]}
{"op":"mcm","clk":"5347794757","pt":1646207936590,"mc":[{"id":"1.195453749","rc":[{"atb":[[11.5,2.72]],"id":3805740}],"con":true,"img":false}]}
{"op":"mcm","clk":"5347794769","pt":1646207936897,"mc":[{"id":"1.195453749","rc":[{"atb":[[9.6,3.27]],"id":3805740}],"con":true,"img":false}]}
{"op":"mcm","clk":"5347796987","pt":1646207992043,"mc":[{"id":"1.195453749","rc":[{"atb":[[3.85,0],[4.2,0]],"id":3805731}],"con":true,"img":false}]}
{"op":"mcm","clk":"5347797040","pt":1646207993071,"mc":[{"id":"1.195453749","rc":[{"atb":[[4.1,2.72],[3.8,74.74]],"id":3805731}],"con":true,"img":false}]}
{"op":"mcm","clk":"5347803523","pt":1646208156289,"mc":[{"id":"1.195453749","rc":[{"atb":[[9.6,0],[11.5,0]],"id":3805740}],"con":true,"img":false}]}
{"op":"mcm","clk":"5347803559","pt":1646208157214,"mc":[{"id":"1.195453749","rc":[{"atb":[[11,2.72],[9.4,3.27]],"id":3805740}],"con":true,"img":false}]}
{"op":"mcm","clk":"5347810876","pt":1646208335043,"mc":[{"id":"1.195453749","rc":[{"atb":[[3.1,44.47],[2.94,0]],"id":522749},{"atl":[[570,0],[560,2]],"id":522752},{"atb":[[5,0],[5.5,22.22]],"id":522753},{"atb":[[5.1,0],[5.8,20.83]],"id":522741},{"atl":[[160,2],[190,0]],"id":522745}],"con":true,"img":false}]}
{"op":"mcm","clk":"5347810900","pt":1646208335453,"mc":[{"id":"1.195453749","rc":[{"atb":[[2.42,0],[2.52,0]],"id":3805784},{"atb":[[8.8,0],[7.8,0]],"id":522749}],"con":true,"img":false}]}
{"op":"mcm","clk":"5347810933","pt":1646208336135,"mc":[{"id":"1.195453749","rc":[{"atb":[[2.32,3.27],[2.42,2.72]],"id":3805784},{"atb":[[9.2,2.72],[8.2,31.06]],"id":522749}],"con":true,"img":false}]}
{"op":"mcm","clk":"5347816078","pt":1646208454996,"mc":[{"id":"1.195453749","rc":[{"atb":[[1.58,172.41],[1.66,0]],"id":3805784}],"con":true,"img":false}]}
{"op":"mcm","clk":"5347820619","pt":1646208562994,"mc":[{"id":"1.195453749","rc":[{"atb":[[42,6.5],[55,0]],"id":522747},{"atb":[[4.1,0],[3.8,71.46]],"id":3805731},{"atb":[[11,0],[9.4,0]],"id":3805740}],"con":true,"img":false}]}
{"op":"mcm","clk":"5347820648","pt":1646208563700,"mc":[{"id":"1.195453749","rc":[{"atb":[[44,3.27],[60,2.72]],"id":522747}],"con":true,"img":false}]}
{"op":"mcm","clk":"5347820662","pt":1646208564009,"mc":[{"id":"1.195453749","rc":[{"atb":[[3.85,3.27],[4.2,2.72]],"id":3805731},{"atb":[[9.6,3.27],[11.5,2.72]],"id":3805740}],"con":true,"img":false}]}
{"op":"mcm","clk":"5347825717","pt":1646208675663,"mc":[{"id":"1.195453749","rc":[{"atb":[[3,50],[2.6,0]],"id":3805731},{"atb":[[6,17.4],[12.5,0]],"id":522742}],"con":true,"img":false}]}
{"op":"mcm","clk":"5347826160","pt":1646208686856,"mc":[{"id":"1.195453749","rc":[{"atl":[[1000,0]],"id":522746},{"atl":[[990,0]],"id":522747},{"atl":[[270,0],[230,2]],"id":3805731},{"atb":[[6,0],[7,16]],"id":3805762},{"atb":[[6.2,19.23],[5.5,0]],"id":522753},{"atl":[[160,0],[120,2]],"id":522745}],"con":true,"img":false}]}
{"op":"mcm","clk":"5347826189","pt":1646208687473,"mc":[{"id":"1.195453749","rc":[{"atb":[[2.32,0],[2.42,0]],"id":3805784},{"atb":[[9.2,0],[8.2,27.79]],"id":522749}],"con":true,"img":false}]}
{"op":"mcm","clk":"5347826239","pt":1646208688558,"mc":[{"id":"1.195453749","rc":[{"atb":[[2.38,2.72],[2.28,211.72]],"id":3805784},{"atb":[[9,3.27],[10,2.72]],"id":522749}],"con":true,"img":false}]}
{"op":"mcm","clk":"5347827776","pt":1646208723386,"mc":[{"id":"1.195453749","rc":[{"atl":[[1000,2]],"id":522746},{"atl":[[1000,2]],"id":522747},{"atb":[[6.2,0],[5.5,22.22]],"id":522753}],"con":true,"img":false}]}
{"op":"mcm","clk":"5347827812","pt":1646208723899,"mc":[{"id":"1.195453749","rc":[{"atb":[[9,0],[10,0]],"id":522749}],"con":true,"img":false}]}
{"op":"mcm","clk":"5347827854","pt":1646208724623,"mc":[{"id":"1.195453749","rc":[{"atb":[[9.2,2.72],[8.2,31.06]],"id":522749}],"con":true,"img":false}]}
{"op":"mcm","clk":"5347838497","pt":1646208931746,"mc":[{"id":"1.195453749","rc":[{"atb":[[2.38,0],[2.28,208.44]],"id":3805784}],"con":true,"img":false}]}
{"op":"mcm","clk":"5347838546","pt":1646208932675,"mc":[{"id":"1.195453749","rc":[{"atb":[[2.42,2.72]],"id":3805784}],"con":true,"img":false}]}
{"op":"mcm","clk":"5347838553","pt":1646208932778,"mc":[{"id":"1.195453749","rc":[{"atb":[[2.32,3.27]],"id":3805784}],"con":true,"img":false}]}
{"op":"mcm","clk":"5347865453","pt":1646209262001,"mc":[{"id":"1.195453749","rc":[{"atb":[[75,0],[50,0]],"id":522750},{"atb":[[16.5,0],[14,0]],"id":3805762},{"atb":[[16,0],[13.5,0]],"id":522753},{"atb":[[18,11.76],[21,0]],"id":522743},{"atb":[[9.6,0],[11.5,0]],"id":3805740}],"con":true,"img":false}]}
{"op":"mcm","clk":"5347865489","pt":1646209262670,"mc":[{"id":"1.195453749","rc":[{"atb":[[80,2.72],[55,3.27]],"id":522750},{"atb":[[17.5,2.72],[15,3.27]],"id":3805762},{"atb":[[17,2.72],[14.5,3.27]],"id":522753},{"atb":[[19,3.27],[23,2.72]],"id":522743}],"con":true,"img":false}]}
{"op":"mcm","clk":"5347865498","pt":1646209262773,"mc":[{"id":"1.195453749","rc":[{"atb":[[11,2.72],[9.4,3.27]],"id":3805740}],"con":true,"img":false}]}
{"op":"mcm","clk":"5347865523","pt":1646209263288,"mc":[{"id":"1.195453749","rc":[{"atl":[[600,2],[610,0]],"id":3805747},{"atb":[[5.5,0],[6,20]],"id":522752},{"atl":[[530,2],[560,0]],"id":522752},{"atl":[[990,0],[980,2]],"id":522742}],"con":true,"img":false}]}
{"op":"mcm","clk":"5347865561","pt":1646209263863,"mc":[{"id":"1.195453749","rc":[{"atb":[[9.2,0],[8.2,27.79]],"id":522749}],"con":true,"img":false}]}
{"op":"mcm","clk":"5347865606","pt":1646209264785,"mc":[{"id":"1.195453749","rc":[{"atb":[[9.6,2.72],[8.6,3.27]],"id":522749}],"con":true,"img":false}]}
{"op":"mcm","clk":"5347866690","pt":1646209282578,"mc":[{"id":"1.195453749","rc":[{"atl":[[80,0],[12.5,2]],"id":3805784},{"atb":[[10,0],[12.5,8.7]],"id":522746},{"atb":[[21,0],[26,4]],"id":522747},{"atb":[[7.4,15.62],[6,0]],"id":522742}],"con":true,"img":false}]}
{"op":"mcm","clk":"5347869334","pt":1646209335687,"mc":[{"id":"1.195453749","rc":[{"atl":[[1000,0]],"id":522747},{"atb":[[5.5,0],[6,20]],"id":522753}],"con":true,"img":false}]}
{"op":"mcm","clk":"5347869355","pt":1646209336094,"mc":[{"id":"1.195453749","rc":[{"atb":[[2.32,0],[2.42,0]],"id":3805784}],"con":true,"img":false}]}
{"op":"mcm","clk":"5347869398","pt":1646209336783,"mc":[{"id":"1.195453749","rc":[{"atb":[[2.4,2.72],[2.3,3.27]],"id":3805784}],"con":true,"img":false}]}
{"op":"mcm","clk":"5347873293","pt":1646209426252,"mc":[{"id":"1.195453749","rc":[{"atb":[[3.85,0],[4.2,0]],"id":3805731}],"con":true,"img":false}]}
{"op":"mcm","clk":"5347873307","pt":1646209426966,"mc":[{"id":"1.195453749","rc":[{"atb":[[4.1,2.72],[3.8,74.74]],"id":3805731}],"con":true,"img":false}]}
{"op":"mcm","clk":"5347874552","pt":1646209450019,"mc":[{"id":"1.195453749","rc":[{"atb":[[9.6,0]],"id":522749}],"con":true,"img":false}]}
{"op":"mcm","clk":"5347874556","pt":1646209450124,"mc":[{"id":"1.195453749","rc":[{"atb":[[8.6,0]],"id":522749}],"con":true,"img":false}]}
{"op":"mcm","clk":"5347874584","pt":1646209450700,"mc":[{"id":"1.195453749","rc":[{"atb":[[9.8,2.72]],"id":522749}],"con":true,"img":false}]}
{"op":"mcm","clk":"5347874592","pt":1646209450906,"mc":[{"id":"1.195453749","rc":[{"atb":[[8.8,3.27]],"id":522749}],"con":true,"img":false}]}
{"op":"mcm","clk":"5347874880","pt":1646209455725,"mc":[{"id":"1.195453749","rc":[{"atl":[[1000,0]],"id":522746},{"atb":[[2.92,0],[2.78,56.18]],"id":522745}],"con":true,"img":false}]}
{"op":"mcm","clk":"5347877862","pt":1646209516084,"mc":[{"id":"1.195453749","rc":[{"atl":[[1000,2]],"id":522746},{"atb":[[2.92,52.08],[2.78,0]],"id":522745}],"con":true,"img":false}]}
{"op":"mcm","clk":"5347883852","pt":1646209636154,"mc":[{"id":"1.195453749","rc":[{"atl":[[1000,0]],"id":522746},{"atb":[[2.92,0],[2.78,56.18]],"id":522745}],"con":true,"img":false}]}
{"op":"mcm","clk":"5347886854","pt":1646209695138,"mc":[{"id":"1.195453749","rc":[{"atb":[[2.9,52.63],[2.78,0]],"id":522745},{"atl":[[110,2],[120,0]],"id":522745}],"con":true,"img":false}]}
{"op":"mcm","clk":"5347886878","pt":1646209695403,"mc":[{"id":"1.195453749","rc":[{"atb":[[9.8,0],[8.8,0]],"id":522749}],"con":true,"img":false}]}
{"op":"mcm","clk":"5347886929","pt":1646209696127,"mc":[{"id":"1.195453749","rc":[{"atb":[[9,3.27],[10,2.72]],"id":522749}],"con":true,"img":false}]}
{"op":"mcm","clk":"5347888652","pt":1646209729755,"mc":[{"id":"1.195453749","rc":[{"atb":[[2.4,0],[2.3,0]],"id":3805784}],"con":true,"img":false}]}
{"op":"mcm","clk":"5347888680","pt":1646209730532,"mc":[{"id":"1.195453749","rc":[{"atb":[[2.32,3.27],[2.42,2.72]],"id":3805784}],"con":true,"img":false}]}
{"op":"mcm","clk":"5347890184","pt":1646209760957,"mc":[{"id":"1.195453749","rc":[{"atb":[[2.32,0],[2.42,0]],"id":3805784}],"con":true,"img":false}]}
{"op":"mcm","clk":"5347890215","pt":1646209761677,"mc":[{"id":"1.195453749","rc":[{"atb":[[2.4,2.72],[2.3,3.27]],"id":3805784}],"con":true,"img":false}]}
{"op":"mcm","clk":"5347890897","pt":1646209775987,"mc":[{"id":"1.195453749","rc":[{"atb":[[2.4,0],[2.3,0]],"id":3805784}],"con":true,"img":false}]}
{"op":"mcm","clk":"5347890934","pt":1646209776700,"mc":[{"id":"1.195453749","rc":[{"atb":[[2.38,2.72],[2.28,211.72]],"id":3805784}],"con":true,"img":false}]}
{"op":"mcm","clk":"5347893880","pt":1646209835067,"mc":[{"id":"1.195453749","rc":[{"atl":[[220,2],[230,0]],"id":3805731},{"atl":[[980,0],[970,2]],"id":522742},{"atl":[[100,2],[110,0]],"id":522745}],"con":true,"img":false}]}
{"op":"mcm","clk":"5347894027","pt":1646209838250,"mc":[{"id":"1.195453749","rc":[{"atb":[[9,0],[10,0]],"id":522749}],"con":true,"img":false}]}
{"op":"mcm","clk":"5347894059","pt":1646209838981,"mc":[{"id":"1.195453749","rc":[{"atb":[[9.2,3.27],[10.5,2.72]],"id":522749}],"con":true,"img":false}]}
{"op":"mcm","clk":"5347896891","pt":1646209898018,"mc":[{"id":"1.195453749","rc":[{"atb":[[3.1,0],[3.35,42.55]],"id":522749},{"atl":[[200,2],[220,0]],"id":3805731},{"atl":[[95,2],[100,0]],"id":522745}],"con":true,"img":false}]}
{"op":"mcm","clk":"5347896912","pt":1646209898735,"mc":[{"id":"1.195453749","rc":[{"atb":[[2.38,0],[2.28,208.44]],"id":3805784}],"con":true,"img":false}]}
{"op":"mcm","clk":"5347896936","pt":1646209899460,"mc":[{"id":"1.195453749","rc":[{"atb":[[2.36,2.72],[2.26,3.27]],"id":3805784}],"con":true,"img":false}]}
{"op":"mcm","clk":"5347897266","pt":1646209907427,"mc":[{"id":"1.195453749","rc":[{"atb":[[1.94,106.38]],"id":3805784},{"atl":[[600,0],[580,2]],"id":3805747},{"atb":[[3.6,38.46],[3.35,0]],"id":522749},{"atb":[[3,0]],"id":3805731},{"atl":[[200,0]],"id":3805731},{"atb":[[5.8,0]],"id":522741},{"atl":[[540,0]],"id":522741},{"atb":[[10,11.11]],"id":522743},{"atl":[[830,2]],"id":522743},{"atb":[[2.9,0],[2.68,59.52]],"id":522745},{"atl":[[75,2],[95,0]],"id":522745}],"con":true,"img":false}]}
{"op":"mcm","clk":"5347897272","pt":1646209907589,"mc":[{"id":"1.195453749","rc":[{"atb":[[1.58,0]],"id":3805784},{"atb":[[6.6,0],[7.8,14.71]],"id":3805747},{"atl":[[1000,2]],"id":522746},{"atb":[[32,3.23],[26,0]],"id":522747},{"atl":[[1000,2]],"id":522747},{"atb":[[32,3.23],[26,0]],"id":522750},{"atb":[[2.46,68.49]],"id":3805731},{"atl":[[46,2]],"id":3805731},{"atb":[[6,0],[8.8,12.82]],"id":522752},{"atl":[[530,0],[520,2]],"id":522752},{"atb":[[7,0],[9.4,11.9]],"id":3805762},{"atl":[[540,2],[550,0]],"id":3805762},{"atb":[[8.6,13.16],[6,0]],"id":522753},{"atb":[[4.8,26.32]],"id":522741},{"atl":[[520,2]],"id":522741},{"atl":[[800,2],[970,0]],"id":522742},{"atb":[[13,22.23]],"id":522743},{"atl":[[940,0]],"id":522743},{"atb":[[3.45,0],[4.3,30.3]],"id":3805740}],"con":true,"img":false}]}
{"op":"mcm","clk":"5347897756","pt":1646209920159,"mc":[{"id":"1.195453749","rc":[{"atb":[[1.94,0],[2.14,87.72]],"id":3805784},{"atl":[[530,2],[580,0]],"id":3805747},{"atb":[[3.6,0],[4.4,29.41]],"id":522749},{"atb":[[10,0],[13,30.56]],"id":522743},{"atl":[[710,2],[830,0]],"id":522743},{"atb":[[3.1,47.62],[2.68,0]],"id":522745},{"atl":[[75,0],[46,2]],"id":522745}],"con":true,"img":false}]}
{"op":"mcm","clk":"5347897763","pt":1646209920267,"mc":[{"id":"1.195453749","rc":[{"atb":[[2.46,0],[2.84,54.35]],"id":3805731},{"atl":[[46,0],[29,2]],"id":3805731},{"atb":[[4.8,0],[6,20]],"id":522741},{"atl":[[520,0],[460,2]],"id":522741},{"atl":[[680,2],[800,0]],"id":522742}],"con":true,"img":false}]}
{"op":"mcm","clk":"5347899705","pt":1646209967127,"mc":[{"id":"1.195453749","rc":[{"atb":[[9.2,0],[10.5,0]],"id":522749}],"con":true,"img":false}]}
{"op":"mcm","clk":"5347899735","pt":1646209967797,"mc":[{"id":"1.195453749","rc":[{"atb":[[9.4,3.27]],"id":522749}],"con":true,"img":false}]}
{"op":"mcm","clk":"5347899748","pt":1646209968104,"mc":[{"id":"1.195453749","rc":[{"atb":[[11,2.72]],"id":522749}],"con":true,"img":false}]}
{"op":"mcm","clk":"5347900072","pt":1646209976931,"mc":[{"id":"1.195453749","rc":[{"atb":[[9.2,12.2],[7.8,0]],"id":3805747},{"atl":[[1000,0]],"id":522747},{"atl":[[520,0],[530,2]],"id":522752},{"atl":[[710,0],[720,2]],"id":522743},{"atl":[[38,2],[46,0]],"id":522745}],"con":true,"img":false}]}
{"op":"mcm","clk":"5347900365","pt":1646209983132,"mc":[{"id":"1.195453749","rc":[{"atl":[[530,0],[520,2]],"id":3805747},{"atl":[[1000,2]],"id":522747},{"atb":[[2.84,0],[2.96,51.02]],"id":3805731}],"con":true,"img":false}]}
{"op":"mcm","clk":"5347900671","pt":1646209988859,"mc":[{"id":"1.195453749","rc":[{"atl":[[530,0]],"id":522752}],"con":true,"img":false}]}
{"op":"mcm","clk":"5347900677","pt":1646209988962,"mc":[{"id":"1.195453749","rc":[{"atl":[[510,2]],"id":522752}],"con":true,"img":false}]}
{"op":"mcm","clk":"5347902020","pt":1646210021417,"mc":[{"id":"1.195453749","rc":[{"atb":[[2.36,0],[2.26,0]],"id":3805784}],"con":true,"img":false}]}
{"op":"mcm","clk":"5347902051","pt":1646210022088,"mc":[{"id":"1.195453749","rc":[{"atb":[[2.88,3.27],[2.98,2.72]],"id":3805784}],"con":true,"img":false}]}
{"op":"mcm","clk":"5347906383","pt":1646210139750,"mc":[{"id":"1.195453749","rc":[{"atb":[[7.6,15.15],[9.4,0]],"id":3805762},{"atl":[[540,0],[520,2]],"id":3805762},{"atl":[[510,0],[500,2]],"id":522753},{"atl":[[670,2],[720,0]],"id":522743}],"con":true,"img":false}]}
{"op":"mcm","clk":"5347910028","pt":1646210221476,"mc":[{"id":"1.195453749","rc":[{"atb":[[2.28,0],[2.78,0],[2.48,0]],"id":3805784},{"atb":[[18,0],[10.5,0],[8.2,0]],"id":3805747},{"atb":[[34,0],[85,0],[22,0]],"id":522746},{"atb":[[80,0],[42,0],[210,0]],"id":522747},{"atb":[[6.2,0],[8.2,0],[13,0]],"id":522749},{"atb":[[340,0],[190,0],[95,0]],"id":522750},{"atb":[[2.82,0],[3.8,3.27],[3.05,0]],"id":3805731},{"atb":[[17,0],[9.8,0],[7.8,0]],"id":522752},{"atb":[[10.5,0],[26,0],[15.5,0]],"id":3805762},{"atb":[[10,0],[25,0],[15,0]],"id":522753},{"atb":[[18.5,0],[11,0],[8.4,0]],"id":522741},{"atb":[[24,0],[9.8,0],[14.5,0]],"id":522742},{"atb":[[32,0],[18,0],[13,8.33]],"id":522743},{"atb":[[8.6,0],[14,0],[6.6,0]],"id":3805740},{"atb":[[3.6,0],[2.74,0],[2.94,0]],"id":522745}],"con":true,"img":false}]}
{"op":"mcm","clk":"5347910179","pt":1646210224669,"mc":[{"id":"1.195453749","rc":[{"atb":[[1.94,283.84],[2.48,90.14],[2.08,247.04]],"id":3805784},{"atb":[[5.1,65.07],[10.5,14.04],[6.2,51.31]],"id":3805747},{"atb":[[16,17.78],[34,4.04],[11,26.68]],"id":522746},{"atb":[[18,15.69],[80,1.68],[26,10.67]],"id":522747},{"atb":[[5.1,65.07],[8.2,18.52],[4.1,86.06]],"id":522749},{"atb":[[190,0.7],[48,5.67],[29,9.53]],"id":522750},{"atb":[[2.42,187.89],[2.62,164.69],[3.05,65.07]],"id":3805731},{"atb":[[9.8,15.15],[4.9,68.41],[5.9,54.45]],"id":522752},{"atb":[[6.2,51.31],[8.2,37.05],[15.5,9.2]],"id":3805762},{"atb":[[8,38.11],[6,53.36],[15,9.53]],"id":522753},{"atb":[[6.4,49.41],[11,13.34],[5.2,63.52]],"id":522741},{"atb":[[7.8,39.23],[14.5,9.87],[5.9,54.45]],"id":522742},{"atb":[[7.2,43.03],[18,7.84],[9.2,32.53]],"id":522743},{"atb":[[4.3,111.15],[8.6,17.55],[5.3,62.04]],"id":3805740},{"atb":[[2.54,173.25],[2.94,68.76],[2.34,199.11]],"id":522745}],"con":true,"img":false}]}
{"op":"mcm","clk":"5347911812","pt":1646210261361,"mc":[{"id":"1.195453749","rc":[{"atb":[[7.6,15.15],[8.8,0]],"id":522752}],"con":true,"img":false}]}
{"op":"mcm","clk":"5347914388","pt":1646210321953,"mc":[{"id":"1.195453749","rc":[{"atb":[[8.6,13.16],[7.6,0]],"id":522752}],"con":true,"img":false}]}
{"op":"mcm","clk":"5347915115","pt":1646210344264,"mc":[{"id":"1.195453749","rc":[{"atb":[[12.5,0],[15,7.14]],"id":522746},{"atb":[[32,0],[13.5,6.51]],"id":522747},{"atb":[[10,11.11],[7.4,0]],"id":522742},{"atb":[[9.2,44.73],[13,0]],"id":522743}],"con":true,"img":false}]}
{"op":"mcm","clk":"5347916471","pt":1646210381742,"mc":[{"id":"1.195453749","rc":[{"atb":[[2.88,0],[2.98,0]],"id":3805784},{"atb":[[11,0],[9.4,0]],"id":522749},{"atb":[[4.1,0],[3.8,0]],"id":3805731}],"con":true,"img":false}]}
{"op":"mcm","clk":"5347916481","pt":1646210381898,"mc":[{"id":"1.195453749","rc":[{"atb":[[3.1,47.62],[2.96,0]],"id":3805731}],"con":true,"img":false}]}
{"op":"mcm","clk":"5347916507","pt":1646210382411,"mc":[{"id":"1.195453749","rc":[{"atb":[[2.92,3.27],[3.05,2.72]],"id":3805784},{"atb":[[9.2,3.27],[10.5,2.72]],"id":522749},{"atb":[[3.85,3.27],[4.2,2.72]],"id":3805731}],"con":true,"img":false}]}
{"op":"mcm","clk":"5347919251","pt":1646210461418,"mc":[{"id":"1.195453749","rc":[{"atb":[[10.5,22.99]],"id":3805747},{"atl":[[540,2.28]],"id":3805747},{"atb":[[44,10.31]],"id":522747},{"atb":[[19,9.92],[22,4.96]],"id":522752},{"atl":[[44,4.96],[55,9.92]],"id":522752},{"atb":[[19.5,9.92],[23,4.96]],"id":522753},{"atl":[[46,4.96],[60,9.92]],"id":522753},{"atb":[[18.5,18.87],[21,4.96]],"id":522742},{"atl":[[670,0.23],[95,4.96]],"id":522742},{"atb":[[3.1,56.56]],"id":522745},{"atl":[[42,8.94]],"id":522745}],"con":true,"img":false}]}
{"op":"mcm","clk":"5347919254","pt":1646210461522,"mc":[{"id":"1.195453749","rc":[{"atb":[[2.82,4.96],[2.74,9.92],[2.48,99.08]],"id":3805784},{"atl":[[4.8,4.96],[12,8.94],[5.2,9.92],[13.5,8.94]],"id":3805784},{"atb":[[17.5,9.92],[19.5,4.96],[14.5,8.94]],"id":3805747},{"atl":[[65,9.92],[48,4.96],[510,0.31]],"id":3805747},{"atb":[[34,12.99],[75,9.92],[95,4.96],[48,3.37]],"id":522746},{"atl":[[220,4.96],[990,0.15]],"id":522746},{"atb":[[80,11.61],[85,1.88],[100,4.96]],"id":522747},{"atl":[[230,4.96],[990,0.15]],"id":522747},{"atb":[[9.2,13.19],[10,4.96],[8.2,27.47]],"id":522749},{"atl":[[270,4.56],[22,4.96],[26,9.92],[240,0.66]],"id":522749},{"atb":[[160,4.96],[200,0.79],[55,11.4],[120,9.92]],"id":522750},{"atl":[[1000,0.15]],"id":522750},{"atb":[[4.6,4.96],[3.1,56.56],[4.2,21.59]],"id":3805731},{"atl":[[32,8.94],[7,4.96],[7.8,9.92],[28,5.87]],"id":3805731},{"atb":[[9.8,24.1],[14,8.94]],"id":522752},{"atl":[[530,2.32],[500,0.31]],"id":522752},{"atb":[[18,8.94],[19.5,9.92],[23,4.96],[15,12.22]],"id":3805762},{"atl":[[540,2.28],[70,9.92],[50,4.96],[510,0.31]],"id":3805762},{"atb":[[17.5,8.94],[14.5,12.22]],"id":522753},{"atl":[[520,2.36],[490,0.32]],"id":522753},{"atb":[[16.5,4.96],[11,22.28],[14.5,21.59]],"id":522741},{"atl":[[34,4.96],[42,9.92],[450,0.35],[480,2.56]],"id":522741},{"atb":[[14.5,18.82]],"id":522742},{"atl":[[700,1.75]],"id":522742},{"atb":[[18,16.79],[38,4.96],[24,6.9],[30,9.92]],"id":522743},{"atl":[[660,0.24],[690,1.77],[95,4.96]],"id":522743},{"atb":[[8.6,26.5],[10,4.96],[9.2,9.92],[11,11.67]],"id":3805740},{"atl":[[18.5,4.96],[320,0.49],[21,9.92],[350,3.52]],"id":3805740},{"atb":[[4.5,9.92],[4.1,11.67],[4.9,4.96]],"id":522745},{"atl":[[8,9.92],[7.2,4.96],[36,4.53]],"id":522745}],"con":true,"img":false}]}
{"op":"mcm","clk":"5347919256","pt":1646210461589,"mc":[{"id":"1.195453749","rc":[{"atl":[[520,0],[540,4.28]],"id":3805747},{"atl":[[130,2],[510,0]],"id":522752},{"atl":[[130,2],[500,0]],"id":522753},{"atl":[[680,0],[370,2]],"id":522742},{"atl":[[38,0],[40,2.56]],"id":522745}],"con":true,"img":false}]}
{"op":"mcm","clk":"5347919260","pt":1646210461685,"mc":[{"id":"1.195453749","rc":[{"atl":[[12.5,0],[4.9,9.92]],"id":3805784},{"atl":[[700,2],[1000,0]],"id":522746},{"atl":[[750,2],[1000,0]],"id":522747},{"atl":[[38,2.7],[250,0]],"id":522749},{"atl":[[11.5,9.52],[29,0]],"id":3805731},{"atl":[[520,0],[170,2]],"id":3805762},{"atl":[[110,2],[460,0]],"id":522741},{"atl":[[670,0],[360,2]],"id":522743},{"atl":[[330,0],[44,2.33]],"id":3805740}],"con":true,"img":false}]}
{"op":"mcm","clk":"5347919272","pt":1646210461996,"mc":[{"id":"1.195453749","rc":[{"atl":[[1000,1.22]],"id":522746},{"atl":[[1000,1.22]],"id":522747}],"con":true,"img":false}]}
{"op":"mcm","clk":"5347919295","pt":1646210462605,"mc":[{"id":"1.195453749","rc":[{"atb":[[17.5,0],[17,9.92],[19.5,0],[19,4.96]],"id":3805747}],"con":true,"img":false}]}
{"op":"mcm","clk":"5347919322","pt":1646210463285,"mc":[{"id":"1.195453749","rc":[{"atb":[[2.26,79.37],[2.14,0]],"id":3805784},{"atb":[[4.4,0]],"id":522749},{"atb":[[42,2.44]],"id":522750},{"atb":[[3.1,8.94],[3.75,36.36]],"id":3805731},{"atb":[[12,9.09]],"id":522752},{"atb":[[10.5,10.53]],"id":3805762},{"atb":[[8.6,0],[11.5,9.52]],"id":522753},{"atb":[[6,0],[7,16.67]],"id":522741},{"atb":[[5.5,22.22]],"id":3805740},{"atb":[[3.1,8.94],[3.7,37.04]],"id":522745}],"con":true,"img":false}]}
{"op":"mcm","clk":"5347919329","pt":1646210463392,"mc":[{"id":"1.195453749","rc":[{"atb":[[9.2,0],[12.5,8.7]],"id":3805747},{"atb":[[5.2,23.81]],"id":522749},{"atb":[[32,0]],"id":522750},{"atb":[[8.6,0]],"id":522752},{"atb":[[7.6,0]],"id":3805762},{"atb":[[4.3,80.85]],"id":3805740}],"con":true,"img":false}]}
{"op":"mcm","clk":"5347919345","pt":1646210463693,"mc":[{"id":"1.195453749","rc":[{"atl":[[4.8,0],[5.3,9.92],[4.9,14.88],[5.2,0]],"id":3805784}],"con":true,"img":false}]}
{"op":"mcm","clk":"5347919376","pt":1646210464619,"mc":[{"id":"1.195453749","rc":[{"atl":[[5.3,0],[4.9,9.92]],"id":3805784}],"con":true,"img":false}]}
{"op":"mcm","clk":"5347919403","pt":1646210465398,"mc":[{"id":"1.195453749","rc":[{"atl":[[4.8,4.96],[5.2,9.92]],"id":3805784}],"con":true,"img":false}]}
{"op":"mcm","clk":"5347919439","pt":1646210466731,"mc":[{"id":"1.195453749","rc":[{"atl":[[4.8,0],[5.3,9.92],[4.9,14.88],[5.2,0]],"id":3805784},{"atl":[[670,2.23],[370,0]],"id":522742}],"con":true,"img":false}]}
{"op":"mcm","clk":"5347919446","pt":1646210466836,"mc":[{"id":"1.195453749","rc":[{"atl":[[4.9,4.96],[5.2,14.88]],"id":3805784},{"atl":[[700,0],[950,2]],"id":522746},{"atl":[[750,0],[990,2.15]],"id":522747},{"atb":[[4.5,4.96],[4.6,0],[4.1,9.92],[4.2,11.67]],"id":3805731},{"atb":[[36,4.96],[38,0],[29,9.92],[30,0]],"id":522743},{"atl":[[660,2.24],[360,0]],"id":522743}],"con":true,"img":false}]}
{"op":"mcm","clk":"5347919624","pt":1646210471628,"mc":[{"id":"1.195453749","rc":[{"atb":[[2.92,0],[3.05,0]],"id":3805784}],"con":true,"img":false}]}
{"op":"mcm","clk":"5347919631","pt":1646210471989,"mc":[{"id":"1.195453749","rc":[{"atl":[[5.3,29.76]],"id":3805784}],"con":true,"img":false}]}
{"op":"mcm","clk":"5347919635","pt":1646210472091,"mc":[{"id":"1.195453749","rc":[{"atl":[[5.2,0]],"id":3805784}],"con":true,"img":false}]}
{"op":"mcm","clk":"5347919643","pt":1646210472298,"mc":[{"id":"1.195453749","rc":[{"atb":[[2.82,19.72],[2.9,3.27],[3,2.72]],"id":3805784}],"con":true,"img":false}]}
{"op":"mcm","clk":"5347919818","pt":1646210477120,"mc":[{"id":"1.195453749","rc":[{"atl":[[12,18.03]],"id":3805784},{"atl":[[540,2],[510,2.81]],"id":3805747},{"atb":[[80,22.21],[44,3.27]],"id":522747},{"atb":[[22,7.56]],"id":522742},{"atl":[[95,6.64]],"id":522742},{"atb":[[3.1,0],[4.1,33.82]],"id":522745},{"atl":[[36,26.68],[42,0]],"id":522745}],"con":true,"img":false}]}
{"op":"mcm","clk":"5347919821","pt":1646210477224,"mc":[{"id":"1.195453749","rc":[{"atb":[[2.82,40.43],[2.48,90.14]],"id":3805784},{"atl":[[4.8,20.7],[5.3,9.92],[12,38.74],[13.5,0]],"id":3805784},{"atb":[[19.5,8.58],[10.5,14.04],[14.5,29.65]],"id":3805747},{"atl":[[48,8.34]],"id":3805747},{"atb":[[95,6.64],[48,15.79]],"id":522746},{"atl":[[220,5.68]],"id":522746},{"atb":[[100,6.56]],"id":522747},{"atl":[[230,5.65]],"id":522747},{"atb":[[9.2,27.96],[8.2,18.52]],"id":522749},{"atl":[[270,0],[38,17.46],[21,7.94]],"id":522749},{"atb":[[160,7.19],[55,3.27]],"id":522750},{"atb":[[3.1,0],[4.1,60.42]],"id":3805731},{"atl":[[32,0],[11.5,38.46],[7,26.51]],"id":3805731},{"atb":[[22,12.52],[9.8,15.15],[14,29.65]],"id":522752},{"atl":[[130,11.84],[530,0]],"id":522752},{"atb":[[18,29.65],[23,12.17],[15,3.27]],"id":3805762},{"atl":[[540,0],[170,9.52],[50,8.2]],"id":3805762},{"atb":[[17.5,29.65],[23,12.17],[14.5,3.27]],"id":522753},{"atl":[[520,0],[46,8.48]],"id":522753},{"atb":[[16.5,15.2],[11,13.34],[12,18.04]],"id":522741},{"atl":[[34,9.77],[110,13.63],[480,0]],"id":522741},{"atb":[[18,7.84],[24,21.67],[25,5.98]],"id":522743},{"atl":[[95,6.64]],"id":522743},{"atb":[[8.6,17.55],[9.4,18.04]],"id":3805740},{"atl":[[18.5,14.03],[350,0],[44,17.09]],"id":3805740},{"atb":[[4.9,27.11]],"id":522745},{"atl":[[7.2,27.11]],"id":522745}],"con":true,"img":false}]}
{"op":"mcm","clk":"5347919825","pt":1646210477328,"mc":[{"id":"1.195453749","rc":[{"atl":[[38,14.76],[30,3.45]],"id":522749},{"atl":[[9.6,11.63],[11.5,28.94]],"id":3805731},{"atl":[[44,8.65]],"id":522752},{"atl":[[130,11.84]],"id":522753},{"atb":[[18,14.17],[14.5,9.87]],"id":522742},{"atl":[[40,0],[9.4,11.9]],"id":522745}],"con":true,"img":false}]}
{"op":"mcm","clk":"5347919842","pt":1646210477843,"mc":[{"id":"1.195453749","rc":[{"atl":[[990,1.44],[1000,0]],"id":522746},{"atb":[[18.5,9.92]],"id":522742},{"atl":[[670,2]],"id":522742}],"con":true,"img":false}]}
{"op":"mcm","clk":"5347919846","pt":1646210478051,"mc":[{"id":"1.195453749","rc":[{"atl":[[12,29.79]],"id":3805784},{"atb":[[14.5,20.7]],"id":3805747},{"atl":[[510,2.5]],"id":3805747},{"atl":[[990,1.28]],"id":522746},{"atb":[[85,0]],"id":522747},{"atl":[[990,2]],"id":522747},{"atl":[[240,0]],"id":522749},{"atb":[[4.1,38.86]],"id":3805731},{"atl":[[28,0]],"id":3805731},{"atb":[[14,20.7]],"id":522752},{"atb":[[18,20.7]],"id":3805762},{"atl":[[510,0]],"id":3805762},{"atb":[[17.5,20.7]],"id":522753},{"atl":[[490,0]],"id":522753},{"atb":[[14.5,12.65]],"id":522741},{"atl":[[450,0]],"id":522741},{"atb":[[24,14.76]],"id":522743},{"atl":[[660,2]],"id":522743},{"atb":[[4.1,24.87]],"id":522745},{"atl":[[36,22.15]],"id":522745}],"con":true,"img":false}]}
{"op":"mcm","clk":"5347919849","pt":1646210478111,"mc":[{"id":"1.195453749","rc":[{"atb":[[34,4.04],[48,12.41]],"id":522746},{"atl":[[500,0]],"id":522752},{"atl":[[320,0]],"id":3805740}],"con":true,"img":false}]}
{"op":"mcm","clk":"5347919884","pt":1646210479028,"mc":[{"id":"1.195453749","rc":[{"atl":[[5.3,33.18],[12,20.7]],"id":3805784}],"con":true,"img":false}]}
{"op":"mcm","clk":"5347920088","pt":1646210484741,"mc":[{"id":"1.195453749","rc":[{"atb":[[80,11.61],[60,15.21]],"id":522747}],"con":true,"img":false}]}
{"op":"mcm","clk":"5347920156","pt":1646210486338,"mc":[{"id":"1.195453749","rc":[{"atb":[[4,9.92],[4.5,0],[4.1,28.94],[4.4,4.96]],"id":3805731}],"con":true,"img":false}]}
{"op":"mcm","clk":"5347920231","pt":1646210487936,"mc":[{"id":"1.195453749","rc":[{"atb":[[2.9,0],[3,0]],"id":3805784},{"atb":[[9.2,24.68],[10.5,0]],"id":522749},{"atb":[[11,8.94],[9.4,14.76]],"id":3805740}],"con":true,"img":false}]}
{"op":"mcm","clk":"5347920257","pt":1646210488558,"mc":[{"id":"1.195453749","rc":[{"atb":[[2.82,19.72],[2.48,170.36]],"id":3805784},{"atb":[[10,22.6],[9.2,9.92],[8.2,45.11]],"id":522749}],"con":true,"img":false}]}
{"op":"mcm","clk":"5347920259","pt":1646210488615,"mc":[{"id":"1.195453749","rc":[{"atb":[[2.84,3.27],[2.94,2.72]],"id":3805784},{"atb":[[11,2.72],[9.4,3.27]],"id":522749},{"atb":[[9.6,3.27],[11.5,2.72]],"id":3805740}],"con":true,"img":false}]}
{"op":"mcm","clk":"5347920287","pt":1646210489332,"mc":[{"id":"1.195453749","rc":[{"atb":[[2.48,90.14]],"id":3805784}],"con":true,"img":false}]}
{"op":"mcm","clk":"5347920458","pt":1646210492534,"mc":[{"id":"1.195453749","rc":[{"atl":[[36,0],[9.4,66.65]],"id":522745}],"con":true,"img":false}]}
{"op":"mcm","clk":"5347920464","pt":1646210492634,"mc":[{"id":"1.195453749","rc":[{"atb":[[2.82,56.48]],"id":3805784},{"atl":[[5.3,69.94],[12,0]],"id":3805784},{"atb":[[17,35.11],[14.5,0]],"id":3805747},{"atb":[[8.2,18.52],[9.4,22.47]],"id":522749},{"atl":[[38,0],[26,29.12]],"id":522749},{"atl":[[9.6,46.32],[11.5,0]],"id":3805731},{"atb":[[38,4.29],[24,0],[25,22.27]],"id":522743},{"atb":[[10,33.05],[9.4,0]],"id":3805740}],"con":true,"img":false}]}
{"op":"mcm","clk":"5347920468","pt":1646210492734,"mc":[{"id":"1.195453749","rc":[{"atb":[[18,2.72]],"id":522742}],"con":true,"img":false}]}
{"op":"mcm","clk":"5347920471","pt":1646210492836,"mc":[{"id":"1.195453749","rc":[{"atb":[[18.5,27.2]],"id":522742}],"con":true,"img":false}]}
{"op":"mcm","clk":"5347920475","pt":1646210493145,"mc":[{"id":"1.195453749","rc":[{"atb":[[4.4,51.66]],"id":3805731}],"con":true,"img":false}]}
{"op":"mcm","clk":"5347920487","pt":1646210493353,"mc":[{"id":"1.195453749","rc":[{"atb":[[25,16.28]],"id":522743}],"con":true,"img":false}]}
{"op":"mcm","clk":"5347920507","pt":1646210493923,"mc":[{"id":"1.195453749","rc":[{"atb":[[4.2,2.72]],"id":3805731}],"con":true,"img":false}]}
{"op":"mcm","clk":"5347920515","pt":1646210494233,"mc":[{"id":"1.195453749","rc":[{"atl":[[18.5,0],[19,4.96],[21,0],[22,9.92]],"id":3805740}],"con":true,"img":false}]}
{"op":"mcm","clk":"5347920544","pt":1646210495051,"mc":[{"id":"1.195453749","rc":[{"atl":[[42,3.87]],"id":3805740}],"con":true,"img":false}]}
{"op":"mcm","clk":"5347920566","pt":1646210495626,"mc":[{"id":"1.195453749","rc":[{"atl":[[42,24.58],[44,2.33]],"id":3805740}],"con":true,"img":false}]}
{"op":"mcm","clk":"5347920600","pt":1646210496753,"mc":[{"id":"1.195453749","rc":[{"atl":[[230,0],[250,4.96]],"id":522747},{"atl":[[19,0],[19.5,4.96],[22,0],[23,9.92]],"id":3805740},{"atb":[[4.5,0],[4.9,0]],"id":522745}],"con":true,"img":false}]}
{"op":"mcm","clk":"5347920605","pt":1646210496856,"mc":[{"id":"1.195453749","rc":[{"atl":[[600,2],[990,0]],"id":522747}],"con":true,"img":false}]}
{"op":"mcm","clk":"5347920613","pt":1646210497062,"mc":[{"id":"1.195453749","rc":[{"atb":[[4.3,9.92],[4.7,4.96]],"id":522745}],"con":true,"img":false}]}
{"op":"mcm","clk":"5347920630","pt":1646210497430,"mc":[{"id":"1.195453749","rc":[{"atb":[[4.1,2.72],[3.7,114.43]],"id":522745}],"con":true,"img":false}]}
{"op":"mcm","clk":"5347920638","pt":1646210497638,"mc":[{"id":"1.195453749","rc":[{"atl":[[65,0],[70,9.92],[48,3.37],[50,4.96]],"id":3805747},{"atl":[[250,5.6]],"id":522747},{"atb":[[3.8,55.08]],"id":522745}],"con":true,"img":false}]}
{"op":"mcm","clk":"5347920642","pt":1646210497740,"mc":[{"id":"1.195453749","rc":[{"atl":[[540,0],[120,2]],"id":3805747}],"con":true,"img":false}]}
{"op":"mcm","clk":"5347920654","pt":1646210498043,"mc":[{"id":"1.195453749","rc":[{"atl":[[70,29.06],[510,0]],"id":3805747}],"con":true,"img":false}]}
{"op":"mcm","clk":"5347920734","pt":1646210499743,"mc":[{"id":"1.195453749","rc":[{"atl":[[250,4.96]],"id":522747},{"atl":[[65,9.92],[46,0],[48,4.96],[60,0]],"id":522753}],"con":true,"img":false}]}
{"op":"mcm","clk":"5347920740","pt":1646210499846,"mc":[{"id":"1.195453749","rc":[{"atl":[[130,9.84],[95,2]],"id":522753}],"con":true,"img":false}]}
{"op":"mcm","clk":"5347920746","pt":1646210499951,"mc":[{"id":"1.195453749","rc":[{"atl":[[250,0]],"id":522747},{"atl":[[70,0],[80,9.92],[50,0],[60,4.96]],"id":3805762},{"atl":[[19.5,0],[27,9.92]],"id":3805740},{"atb":[[4.3,0],[3.9,9.92],[4.2,4.96],[4.7,0]],"id":522745}],"con":true,"img":false}]}
{"op":"mcm","clk":"5347920752","pt":1646210500055,"mc":[{"id":"1.195453749","rc":[{"atl":[[130,2],[170,7.52]],"id":3805762},{"atl":[[38,2.7],[44,0]],"id":3805740}],"con":true,"img":false}]}
{"op":"mcm","clk":"5347920761","pt":1646210500260,"mc":[{"id":"1.195453749","rc":[{"atl":[[130,0],[95,16.16]],"id":522753}],"con":true,"img":false}]}
{"op":"mcm","clk":"5347920767","pt":1646210500364,"mc":[{"id":"1.195453749","rc":[{"atl":[[620,2.16],[1000,0]],"id":522747}],"con":true,"img":false}]}
{"op":"mcm","clk":"5347920772","pt":1646210500468,"mc":[{"id":"1.195453749","rc":[{"atl":[[65,0],[70,9.92],[48,0],[50,4.96]],"id":522753}],"con":true,"img":false}]}
{"op":"mcm","clk":"5347920776","pt":1646210500572,"mc":[{"id":"1.195453749","rc":[{"atl":[[990,0.15]],"id":522747},{"atl":[[130,12.35],[170,0]],"id":3805762},{"atl":[[90,1.78]],"id":522753}],"con":true,"img":false}]}
{"op":"mcm","clk":"5347920782","pt":1646210500675,"mc":[{"id":"1.195453749","rc":[{"atl":[[75,12.06],[80,0],[55,4.96],[60,0]],"id":3805762},{"atb":[[4,9.92],[4.4,4.96],[3.9,0],[4.2,0]],"id":522745}],"con":true,"img":false}]}
{"op":"mcm","clk":"5347920811","pt":1646210501245,"mc":[{"id":"1.195453749","rc":[{"atl":[[75,9.92],[55,4.96]],"id":3805747},{"atl":[[220,0.72],[240,4.96]],"id":522746},{"atl":[[65,9.92],[44,3.69],[48,4.96],[55,0]],"id":522752},{"atl":[[70,0],[75,9.92],[50,0],[55,4.96]],"id":522753},{"atl":[[95,1.68]],"id":522742}],"con":true,"img":false}]}
{"op":"mcm","clk":"5347920819","pt":1646210501346,"mc":[{"id":"1.195453749","rc":[{"atl":[[70,19.13],[50,0]],"id":3805747},{"atl":[[630,2],[950,0]],"id":522746},{"atl":[[100,4.96]],"id":522742}],"con":true,"img":false}]}
{"op":"mcm","clk":"5347920823","pt":1646210501449,"mc":[{"id":"1.195453749","rc":[{"atl":[[300,2],[670,0]],"id":522742}],"con":true,"img":false}]}
{"op":"mcm","clk":"5347920826","pt":1646210501552,"mc":[{"id":"1.195453749","rc":[{"atb":[[4,0],[4.3,4.96],[3.95,9.92],[4.4,0]],"id":522745}],"con":true,"img":false}]}
{"op":"mcm","clk":"5347920828","pt":1646210501655,"mc":[{"id":"1.195453749","rc":[{"atl":[[65,30.68],[130,2]],"id":522752}],"con":true,"img":false}]}
{"op":"mcm","clk":"5347920832","pt":1646210501759,"mc":[{"id":"1.195453749","rc":[{"atl":[[70,0]],"id":3805747},{"atl":[[950,1.41],[990,0]],"id":522746}],"con":true,"img":false}]}
{"op":"mcm","clk":"5347920838","pt":1646210501864,"mc":[{"id":"1.195453749","rc":[{"atl":[[670,2],[700,0]],"id":522742}],"con":true,"img":false}]}
{"op":"mcm","clk":"5347920842","pt":1646210501967,"mc":[{"id":"1.195453749","rc":[{"atl":[[600,0],[990,2.15]],"id":522747}],"con":true,"img":false}]}
{"op":"mcm","clk":"5347921078","pt":1646210507641,"mc":[{"id":"1.195453749","rc":[{"atl":[[620,0],[640,2.12]],"id":522747},{"atb":[[25,0],[29,23.69]],"id":522743}],"con":true,"img":false}]}
{"op":"mcm","clk":"5347921190","pt":1646210510257,"mc":[{"id":"1.195453749","rc":[{"atl":[[22,7.56]],"id":3805740}],"con":true,"img":false}]}
{"op":"mcm","clk":"5347921204","pt":1646210510669,"mc":[{"id":"1.195453749","rc":[{"atl":[[38,30.78]],"id":3805740}],"con":true,"img":false}]}
{"op":"mcm","clk":"5347921208","pt":1646210510772,"mc":[{"id":"1.195453749","rc":[{"atl":[[42,3.87]],"id":3805740}],"con":true,"img":false}]}
{"op":"mcm","clk":"5347921225","pt":1646210511080,"mc":[{"id":"1.195453749","rc":[{"atl":[[42,0]],"id":3805740}],"con":true,"img":false}]}
{"op":"mcm","clk":"5347921289","pt":1646210512678,"mc":[{"id":"1.195453749","rc":[{"atl":[[980,0.16]],"id":522747},{"atb":[[3.95,39.45],[4.1,24.87],[3.7,37.04]],"id":522745}],"con":true,"img":false}]}
{"op":"mcm","clk":"5347921310","pt":1646210513047,"mc":[{"id":"1.195453749","rc":[{"atl":[[75,28.34]],"id":3805747}],"con":true,"img":false}]}
{"op":"mcm","clk":"5347921326","pt":1646210513459,"mc":[{"id":"1.195453749","rc":[{"atl":[[990,2]],"id":522747},{"atb":[[3.8,3.27]],"id":522745}],"con":true,"img":false}]}
{"op":"mcm","clk":"5347921346","pt":1646210513969,"mc":[{"id":"1.195453749","rc":[{"atb":[[4.3,0],[3.95,29.53],[3.9,9.92],[4.2,4.96]],"id":522745}],"con":true,"img":false}]}
{"op":"mcm","clk":"5347921388","pt":1646210515055,"mc":[{"id":"1.195453749","rc":[{"atl":[[640,0],[990,3.39]],"id":522747}],"con":true,"img":false}]}
{"op":"mcm","clk":"5347921398","pt":1646210515357,"mc":[{"id":"1.195453749","rc":[{"atl":[[90,17.2]],"id":522753}],"con":true,"img":false}]}
{"op":"mcm","clk":"5347921401","pt":1646210515460,"mc":[{"id":"1.195453749","rc":[{"atl":[[95,2]],"id":522753}],"con":true,"img":false}]}
{"op":"mcm","clk":"5347921408","pt":1646210515666,"mc":[{"id":"1.195453749","rc":[{"atl":[[630,0.25]],"id":522747},{"atl":[[55,7.9]],"id":3805762},{"atl":[[85,1.88]],"id":522753}],"con":true,"img":false}]}
{"op":"mcm","clk":"5347921442","pt":1646210516490,"mc":[{"id":"1.195453749","rc":[{"atl":[[75,9.92]],"id":3805762},{"atl":[[90,15.42]],"id":522753}],"con":true,"img":false}]}
{"op":"mcm","clk":"5347921444","pt":1646210516549,"mc":[{"id":"1.195453749","rc":[{"atl":[[980,0]],"id":522747}],"con":true,"img":false}]}
{"op":"mcm","clk":"5347921449","pt":1646210516650,"mc":[{"id":"1.195453749","rc":[{"atl":[[630,4.19],[950,0]],"id":522746}],"con":true,"img":false}]}
{"op":"mcm","clk":"5347921452","pt":1646210516753,"mc":[{"id":"1.195453749","rc":[{"atl":[[300,6.63],[670,0]],"id":522742}],"con":true,"img":false}]}
{"op":"mcm","clk":"5347921630","pt":1646210521383,"mc":[{"id":"1.195453749","rc":[{"atl":[[4.5,4.96],[5.3,60.01]],"id":3805784},{"atb":[[17,25.19],[19,0],[23,9.92],[27,4.96]],"id":3805747},{"atb":[[75,0],[95,1.68]],"id":522746},{"atb":[[4.6,4.96],[4.2,12.65]],"id":3805731},{"atb":[[19,0]],"id":522752},{"atb":[[19.5,0],[20,9.92],[23,7.21],[24,4.96]],"id":3805762},{"atb":[[19.5,0],[20,9.92],[23,7.21],[24,4.96]],"id":522753},{"atl":[[32,4.96],[40,9.92]],"id":522741},{"atb":[[18.5,17.28],[21,0],[24,9.92],[28,4.96]],"id":522742},{"atb":[[34,9.92],[36,0],[42,4.96],[29,13.77]],"id":522743},{"atb":[[10,28.08],[9.2,0],[10.5,4.96]],"id":3805740},{"atb":[[4.3,4.96],[3.95,39.45],[3.9,0],[4.2,0]],"id":522745}],"con":true,"img":false}]}
{"op":"mcm","clk":"5347921632","pt":1646210521487,"mc":[{"id":"1.195453749","rc":[{"atl":[[5.3,36.75]],"id":3805784},{"atb":[[85,9.92],[110,4.96]],"id":522746},{"atl":[[19.5,4.96],[22,0],[23,9.92],[26,19.2]],"id":522749},{"atb":[[4,0],[4.4,46.7]],"id":3805731},{"atb":[[26,4.96]],"id":522752},{"atl":[[34,4.81],[42,0],[110,11.63]],"id":522741}],"con":true,"img":false}]}
{"op":"mcm","clk":"5347921634","pt":1646210521590,"mc":[{"id":"1.195453749","rc":[{"atl":[[4.9,30.6]],"id":3805784},{"atl":[[80,2]],"id":522741}],"con":true,"img":false}]}
{"op":"mcm","clk":"5347921643","pt":1646210521796,"mc":[{"id":"1.195453749","rc":[{"atb":[[17,0],[19.5,28.73],[28,5.87]],"id":3805747},{"atb":[[48,0]],"id":522746},{"atb":[[10,0]],"id":3805740}],"con":true,"img":false}]}
{"op":"mcm","clk":"5347921649","pt":1646210521901,"mc":[{"id":"1.195453749","rc":[{"atl":[[4.5,19.72],[5.3,0],[4.9,45.36]],"id":3805784},{"atb":[[46,13.04],[120,1.33]],"id":522746},{"atb":[[4.6,49.07],[4.1,0],[4.2,70.96]],"id":3805731},{"atb":[[13.5,28.75],[14,0]],"id":522752},{"atb":[[18,0],[20,36.45],[25,6.61]],"id":3805762},{"atb":[[17.5,0],[20,28.05],[25,6.61]],"id":522753},{"atl":[[40,43.52],[110,0],[30,5.47]],"id":522741},{"atb":[[18.5,0],[22,24.81],[28,10.84]],"id":522742},{"atb":[[44,3.69]],"id":522743},{"atb":[[10.5,29.54]],"id":3805740}],"con":true,"img":false}]}
{"op":"mcm","clk":"5347921654","pt":1646210521960,"mc":[{"id":"1.195453749","rc":[{"atl":[[19.5,13.54],[23,36.51],[26,0]],"id":522749},{"atb":[[26,11.31]],"id":522752}],"con":true,"img":false}]}
{"op":"mcm","clk":"5347921659","pt":1646210522060,"mc":[{"id":"1.195453749","rc":[{"atl":[[65,9.92],[75,0],[48,4.96],[55,0]],"id":522753},{"atl":[[22,12.52],[23,0],[26,9.92],[27,0]],"id":3805740},{"atl":[[8,0],[7.2,22.15],[7,4.96],[7.8,9.92]],"id":522745}],"con":true,"img":false}]}
{"op":"mcm","clk":"5347921664","pt":1646210522172,"mc":[{"id":"1.195453749","rc":[{"atl":[[9,12.5],[9.4,54.75]],"id":522745}],"con":true,"img":false}]}
{"op":"mcm","clk":"5347921682","pt":1646210522470,"mc":[{"id":"1.195453749","rc":[{"atb":[[19.5,20.15]],"id":3805747},{"atl":[[650,2.15],[990,2]],"id":522747},{"atb":[[38,16.18],[29,0]],"id":522743},{"atl":[[22,4.96]],"id":3805740},{"atl":[[9.4,0]],"id":522745}],"con":true,"img":false}]}
{"op":"mcm","clk":"5347921688","pt":1646210522574,"mc":[{"id":"1.195453749","rc":[{"atl":[[4.8,0]],"id":3805784},{"atb":[[95,0]],"id":522746},{"atl":[[650,4.15],[990,0]],"id":522747},{"atb":[[4.4,0]],"id":3805731},{"atb":[[23,0]],"id":3805762},{"atb":[[23,0]],"id":522753},{"atl":[[34,0]],"id":522741},{"atb":[[22,17.25],[28,4.96]],"id":522742},{"atb":[[38,11.89]],"id":522743},{"atl":[[6.8,27.37],[7.8,57.66]],"id":522745}],"con":true,"img":false}]}
{"op":"mcm","clk":"5347921698","pt":1646210522779,"mc":[{"id":"1.195453749","rc":[{"atl":[[21,0]],"id":522749},{"atb":[[22,4.96]],"id":522752},{"atl":[[22,0],[26,0]],"id":3805740},{"atb":[[4.3,0],[3.85,9.92],[3.95,29.53],[4.1,29.84]],"id":522745}],"con":true,"img":false}]}
{"op":"mcm","clk":"5347921702","pt":1646210522881,"mc":[{"id":"1.195453749","rc":[{"atl":[[23,4.96],[27,9.92]],"id":3805740}],"con":true,"img":false}]}
{"op":"mcm","clk":"5347921715","pt":1646210523190,"mc":[{"id":"1.195453749","rc":[{"atl":[[38,2.7],[42,33.59]],"id":3805740},{"atb":[[3.85,83.65],[3.95,0]],"id":522745}],"con":true,"img":false}]}
{"op":"mcm","clk":"5347921718","pt":1646210523293,"mc":[{"id":"1.195453749","rc":[{"atl":[[25,6.61]],"id":3805740}],"con":true,"img":false}]}
{"op":"mcm","clk":"5347921721","pt":1646210523395,"mc":[{"id":"1.195453749","rc":[{"atb":[[25,6.61]],"id":522742}],"con":true,"img":false}]}
{"op":"mcm","clk":"5347921728","pt":1646210523558,"mc":[{"id":"1.195453749","rc":[{"atl":[[7.2,0]],"id":522745}],"con":true,"img":false}]}
{"op":"mcm","clk":"5347921739","pt":1646210523864,"mc":[{"id":"1.195453749","rc":[{"atl":[[42,0]],"id":3805740}],"con":true,"img":false}]}
{"op":"mcm","clk":"5347921768","pt":1646210524685,"mc":[{"id":"1.195453749","rc":[{"atl":[[75,0],[80,9.92],[55,0],[60,4.96]],"id":3805762},{"atl":[[23,0],[27,0]],"id":3805740},{"atb":[[4,4.96],[3.85,73.73],[4.1,2.72],[3.8,13.19]],"id":522745}],"con":true,"img":false}]}
{"op":"mcm","clk":"5347921770","pt":1646210524787,"mc":[{"id":"1.195453749","rc":[{"atl":[[24,4.96],[28,9.92]],"id":3805740}],"con":true,"img":false}]}
{"op":"mcm","clk":"5347921779","pt":1646210525096,"mc":[{"id":"1.195453749","rc":[{"atl":[[4.8,9.92],[4.5,14.76],[4.9,40.4],[4.4,4.96]],"id":3805784},{"atl":[[24,11.86]],"id":3805740}],"con":true,"img":false}]}
{"op":"mcm","clk":"5347921788","pt":1646210525356,"mc":[{"id":"1.195453749","rc":[{"atl":[[28,33.1]],"id":3805740}],"con":true,"img":false}]}
{"op":"mcm","clk":"5347921793","pt":1646210525464,"mc":[{"id":"1.195453749","rc":[{"atl":[[120,1.33]],"id":3805762},{"atb":[[4,53.1]],"id":522745}],"con":true,"img":false}]}
{"op":"mcm","clk":"5347921804","pt":1646210525765,"mc":[{"id":"1.195453749","rc":[{"atl":[[25,0]],"id":3805740}],"con":true,"img":false}]}
{"op":"mcm","clk":"5347921815","pt":1646210526074,"mc":[{"id":"1.195453749","rc":[{"atl":[[130,2],[120,13.14]],"id":3805762}],"con":true,"img":false}]}
{"op":"mcm","clk":"5347921868","pt":1646210527102,"mc":[{"id":"1.195453749","rc":[{"atb":[[21,9.92],[22,0],[25,4.96],[26,0]],"id":522752}],"con":true,"img":false}]}
{"op":"mcm","clk":"5347921893","pt":1646210527671,"mc":[{"id":"1.195453749","rc":[{"atl":[[990,2]],"id":522747}],"con":true,"img":false}]}
{"op":"mcm","clk":"5347921894","pt":1646210527769,"mc":[{"id":"1.195453749","rc":[{"atl":[[650,2.15]],"id":522747}],"con":true,"img":false}]}
{"op":"mcm","clk":"5347921901","pt":1646210527975,"mc":[{"id":"1.195453749","rc":[{"atb":[[21,17.86]],"id":522752}],"con":true,"img":false}]}
{"op":"mcm","clk":"5347921912","pt":1646210528387,"mc":[{"id":"1.195453749","rc":[{"atb":[[4.1,53.95]],"id":522745}],"con":true,"img":false}]}
{"op":"mcm","clk":"5347921922","pt":1646210528600,"mc":[{"id":"1.195453749","rc":[{"atl":[[75,9.92],[80,0],[55,4.96],[60,0]],"id":3805762}],"con":true,"img":false}]}
{"op":"mcm","clk":"5347921928","pt":1646210528696,"mc":[{"id":"1.195453749","rc":[{"atb":[[11.5,17.85]],"id":3805740}],"con":true,"img":false}]}
{"op":"mcm","clk":"5347921942","pt":1646210529004,"mc":[{"id":"1.195453749","rc":[{"atl":[[4.8,0],[4.5,19.72],[4.9,50.32],[4.4,0]],"id":3805784},{"atb":[[3.85,111.72],[4.2,12.65]],"id":3805731}],"con":true,"img":false}]}
{"op":"mcm","clk":"5347921955","pt":1646210529211,"mc":[{"id":"1.195453749","rc":[{"atl":[[23,9.92],[30,51.04]],"id":522749},{"atb":[[4,4.96]],"id":522745}],"con":true,"img":false}]}
{"op":"mcm","clk":"5347921960","pt":1646210529478,"mc":[{"id":"1.195453749","rc":[{"atb":[[11,0]],"id":3805740}],"con":true,"img":false}]}
{"op":"mcm","clk":"5347921963","pt":1646210529571,"mc":[{"id":"1.195453749","rc":[{"atl":[[650,0],[990,3.43]],"id":522747}],"con":true,"img":false}]}
{"op":"mcm","clk":"5347921967","pt":1646210529778,"mc":[{"id":"1.195453749","rc":[{"atl":[[75,0],[55,0]],"id":3805762},{"atb":[[4.1,2.72]],"id":522745}],"con":true,"img":false}]}
{"op":"mcm","clk":"5347921969","pt":1646210529881,"mc":[{"id":"1.195453749","rc":[{"atl":[[140,2],[80,9.92],[60,4.96]],"id":3805762},{"atb":[[9.6,47.51],[10.5,4.96]],"id":3805740}],"con":true,"img":false}]}
{"op":"mcm","clk":"5347921973","pt":1646210529984,"mc":[{"id":"1.195453749","rc":[{"atb":[[11,0],[9.4,19.2]],"id":522749},{"atl":[[130,0]],"id":3805762}],"con":true,"img":false}]}
{"op":"mcm","clk":"5347921981","pt":1646210530086,"mc":[{"id":"1.195453749","rc":[{"atl":[[85,18.71],[90,0]],"id":522753}],"con":true,"img":false}]}
{"op":"mcm","clk":"5347921989","pt":1646210530292,"mc":[{"id":"1.195453749","rc":[{"atl":[[110,1.45]],"id":3805762},{"atl":[[48,8.34]],"id":522753},{"atl":[[38,40.36]],"id":3805740}],"con":true,"img":false}]}
{"op":"mcm","clk":"5347921993","pt":1646210530396,"mc":[{"id":"1.195453749","rc":[{"atb":[[9.2,58.66],[9.4,0]],"id":522749},{"atl":[[28,9.92]],"id":3805740}],"con":true,"img":false}]}
{"op":"mcm","clk":"5347921996","pt":1646210530498,"mc":[{"id":"1.195453749","rc":[{"atb":[[4,53.1]],"id":522745}],"con":true,"img":false}]}
{"op":"mcm","clk":"5347922004","pt":1646210530704,"mc":[{"id":"1.195453749","rc":[{"atb":[[9.2,61.93],[10.5,2.72]],"id":522749}],"con":true,"img":false}]}
{"op":"mcm","clk":"5347922014","pt":1646210531068,"mc":[{"id":"1.195453749","rc":[{"atl":[[120,11.81]],"id":3805762},{"atl":[[85,16.82]],"id":522753}],"con":true,"img":false}]}
{"op":"mcm","clk":"5347922022","pt":1646210531275,"mc":[{"id":"1.195453749","rc":[{"atl":[[19.5,0],[23,0]],"id":522749}],"con":true,"img":false}]}
{"op":"mcm","clk":"5347922026","pt":1646210531372,"mc":[{"id":"1.195453749","rc":[{"atl":[[20,4.96],[24,9.92]],"id":522749}],"con":true,"img":false}]}
{"op":"mcm","clk":"5347922094","pt":1646210532101,"mc":[{"id":"1.195453749","rc":[{"atl":[[23,7.21]],"id":522749}],"con":true,"img":false}]}
{"op":"mcm","clk":"5347922108","pt":1646210532409,"mc":[{"id":"1.195453749","rc":[{"atb":[[44,0]],"id":522743}],"con":true,"img":false}]}
{"op":"mcm","clk":"5347922137","pt":1646210532876,"mc":[{"id":"1.195453749","rc":[{"atb":[[34,27.2],[38,0]],"id":522743}],"con":true,"img":false}]}
{"op":"mcm","clk":"5347922142","pt":1646210532974,"mc":[{"id":"1.195453749","rc":[{"atl":[[290,4.96]],"id":522747},{"atb":[[23,9.92],[24,0],[27,4.96],[28,0]],"id":522742}],"con":true,"img":false}]}
{"op":"mcm","clk":"5347922146","pt":1646210533076,"mc":[{"id":"1.195453749","rc":[{"atl":[[610,2]],"id":522747}],"con":true,"img":false}]}
{"op":"mcm","clk":"5347922150","pt":1646210533179,"mc":[{"id":"1.195453749","rc":[{"atl":[[990,1.43]],"id":522747},{"atb":[[40,4.07]],"id":522743}],"con":true,"img":false}]}
{"op":"mcm","clk":"5347922165","pt":1646210533487,"mc":[{"id":"1.195453749","rc":[{"atl":[[290,5.51]],"id":522747}],"con":true,"img":false}]}
{"op":"mcm","clk":"5347922193","pt":1646210534210,"mc":[{"id":"1.195453749","rc":[{"atl":[[630,0]],"id":522747},{"atb":[[9.6,44.24],[11.5,0]],"id":3805740}],"con":true,"img":false}]}
{"op":"mcm","clk":"5347922233","pt":1646210534882,"mc":[{"id":"1.195453749","rc":[{"atl":[[290,0]],"id":522747},{"atb":[[11,2.72],[9.4,3.27]],"id":3805740}],"con":true,"img":false}]}
{"op":"mcm","clk":"5347922244","pt":1646210535202,"mc":[{"id":"1.195453749","rc":[{"atb":[[9.6,62.7]],"id":3805740}],"con":true,"img":false}]}
{"op":"mcm","clk":"5347922266","pt":1646210535710,"mc":[{"id":"1.195453749","rc":[{"atl":[[980,0.16]],"id":522747}],"con":true,"img":false}]}
{"op":"mcm","clk":"5347922286","pt":1646210536172,"mc":[{"id":"1.195453749","rc":[{"atb":[[19.5,0]],"id":3805747}],"con":true,"img":false}]}
{"op":"mcm","clk":"5347922290","pt":1646210536275,"mc":[{"id":"1.195453749","rc":[{"atb":[[23,26.05]],"id":3805747}],"con":true,"img":false}]}
{"op":"mcm","clk":"5347922297","pt":1646210536378,"mc":[{"id":"1.195453749","rc":[{"atl":[[4.9,35.56],[4.7,58.74]],"id":3805784},{"atb":[[42,8.83]],"id":522743}],"con":true,"img":false}]}
{"op":"mcm","clk":"5347922305","pt":1646210536482,"mc":[{"id":"1.195453749","rc":[{"atb":[[85,23.55],[46,2.72]],"id":522746},{"atl":[[20,13.31],[24,35.44],[30,3.45]],"id":522749},{"atb":[[25,11.57]],"id":522752},{"atb":[[22,0],[23,27.16],[26,6.35]],"id":522742}],"con":true,"img":false}]}
{"op":"mcm","clk":"5347922335","pt":1646210537102,"mc":[{"id":"1.195453749","rc":[{"atb":[[40,0]],"id":522743}],"con":true,"img":false}]}
{"op":"mcm","clk":"5347922344","pt":1646210537308,"mc":[{"id":"1.195453749","rc":[{"atl":[[4.5,0],[5.1,9.92],[4.9,25.64],[4.7,63.7]],"id":3805784},{"atl":[[260,4.96]],"id":522747},{"atl":[[23,0]],"id":522749},{"atb":[[21,9.92]],"id":522752},{"atb":[[23,17.23],[25,0],[27,0]],"id":522742},{"atb":[[32,9.92],[34,17.28],[40,4.96],[42,0]],"id":522743}],"con":true,"img":false}]}
{"op":"mcm","clk":"5347922353","pt":1646210537514,"mc":[{"id":"1.195453749","rc":[{"atb":[[26,11.31]],"id":522742}],"con":true,"img":false}]}
{"op":"mcm","clk":"5347922368","pt":1646210537779,"mc":[{"id":"1.195453749","rc":[{"atl":[[980,1.63],[990,0]],"id":522747}],"con":true,"img":false}]}
{"op":"mcm","clk":"5347922373","pt":1646210537880,"mc":[{"id":"1.195453749","rc":[{"atb":[[28,0]],"id":3805747}],"con":true,"img":false}]}
{"op":"mcm","clk":"5347922376","pt":1646210537979,"mc":[{"id":"1.195453749","rc":[{"atl":[[4.7,106.62]],"id":3805784},{"atb":[[32,0],[34,22.09],[38,4.96],[40,0],[30,9.92]],"id":522743}],"con":true,"img":false}]}
{"op":"mcm","clk":"5347922379","pt":1646210538081,"mc":[{"id":"1.195453749","rc":[{"atl":[[5.1,34.31],[4.9,0]],"id":3805784}],"con":true,"img":false}]}
{"op":"mcm","clk":"5347922381","pt":1646210538186,"mc":[{"id":"1.195453749","rc":[{"atl":[[970,2]],"id":522747}],"con":true,"img":false}]}
{"op":"mcm","clk":"5347922385","pt":1646210538288,"mc":[{"id":"1.195453749","rc":[{"atl":[[610,0]],"id":522747}],"con":true,"img":false}]}
{"op":"mcm","clk":"5347922397","pt":1646210538596,"mc":[{"id":"1.195453749","rc":[{"atb":[[23,33.27]],"id":3805747}],"con":true,"img":false}]}
{"op":"mcm","clk":"5347922430","pt":1646210539882,"mc":[{"id":"1.195453749","rc":[{"atb":[[30,27.2]],"id":522743},{"atb":[[4.1,53.95]],"id":522745}],"con":true,"img":false}]}
{"op":"mcm","clk":"5347922432","pt":1646210539985,"mc":[{"id":"1.195453749","rc":[{"atl":[[60,7.65]],"id":3805762},{"atb":[[34,4.81]],"id":522743}],"con":true,"img":false}]}
{"op":"mcm","clk":"5347922453","pt":1646210540501,"mc":[{"id":"1.195453749","rc":[{"atl":[[120,0]],"id":3805762}],"con":true,"img":false}]}
{"op":"mcm","clk":"5347922456","pt":1646210540606,"mc":[{"id":"1.195453749","rc":[{"atl":[[110,14.72]],"id":3805762}],"con":true,"img":false}]}
{"op":"mcm","clk":"5347922461","pt":1646210540709,"mc":[{"id":"1.195453749","rc":[{"atb":[[4,4.96]],"id":522745}],"con":true,"img":false}]}
{"op":"mcm","clk":"5347922464","pt":1646210540811,"mc":[{"id":"1.195453749","rc":[{"atl":[[110,13.26]],"id":3805762}],"con":true,"img":false}]}
{"op":"mcm","clk":"5347922558","pt":1646210542978,"mc":[{"id":"1.195453749","rc":[{"atb":[[11,18.6]],"id":3805740}],"con":true,"img":false}]}
{"op":"mcm","clk":"5347922567","pt":1646210543287,"mc":[{"id":"1.195453749","rc":[{"atl":[[4.9,102.15]],"id":3805784},{"atb":[[23,17.13],[14,17.49]],"id":3805747}],"con":true,"img":false}]}
{"op":"mcm","clk":"5347922571","pt":1646210543383,"mc":[{"id":"1.195453749","rc":[{"atl":[[4.7,47.87]],"id":3805784}],"con":true,"img":false}]}
{"op":"mcm","clk":"5347922575","pt":1646210543486,"mc":[{"id":"1.195453749","rc":[{"atl":[[24,9.92],[30,52.4]],"id":522749},{"atb":[[18,19.98],[23,0]],"id":522742}],"con":true,"img":false}]}
{"op":"mcm","clk":"5347922592","pt":1646210543896,"mc":[{"id":"1.195453749","rc":[{"atb":[[9.6,44.24]],"id":3805740}],"con":true,"img":false}]}
{"op":"mcm","clk":"5347922698","pt":1646210546483,"mc":[{"id":"1.195453749","rc":[{"atb":[[22,9.92],[26,4.96]],"id":3805747}],"con":true,"img":false}]}
{"op":"mcm","clk":"5347922701","pt":1646210546587,"mc":[{"id":"1.195453749","rc":[{"atb":[[23,7.21],[27,0]],"id":3805747}],"con":true,"img":false}]}
{"op":"mcm","clk":"5347922744","pt":1646210547502,"mc":[{"id":"1.195453749","rc":[{"atb":[[38,9.25]],"id":522743}],"con":true,"img":false}]}
{"op":"mcm","clk":"5347922760","pt":1646210547811,"mc":[{"id":"1.195453749","rc":[{"atl":[[260,5.57]],"id":522747}],"con":true,"img":false}]}
{"op":"mcm","clk":"5347922776","pt":1646210548281,"mc":[{"id":"1.195453749","rc":[{"atb":[[34,0]],"id":522743}],"con":true,"img":false}]}
{"op":"mcm","clk":"5347922783","pt":1646210548484,"mc":[{"id":"1.195453749","rc":[{"atl":[[980,1.47]],"id":522747}],"con":true,"img":false}]}
{"op":"mcm","clk":"5347922792","pt":1646210548690,"mc":[{"id":"1.195453749","rc":[{"atb":[[23,16.69],[30,9.92]],"id":522743}],"con":true,"img":false}]}
{"op":"mcm","clk":"5347922839","pt":1646210550229,"mc":[{"id":"1.195453749","rc":[{"atl":[[5.1,156.66]],"id":3805784}],"con":true,"img":false}]}
{"op":"mcm","clk":"5347922845","pt":1646210550288,"mc":[{"id":"1.195453749","rc":[{"atl":[[4.9,0]],"id":3805784}],"con":true,"img":false}]}
{"op":"mcm","clk":"5347922850","pt":1646210550390,"mc":[{"id":"1.195453749","rc":[{"atb":[[18,2.72],[15.5,20.52]],"id":522742}],"con":true,"img":false}]}
{"op":"mcm","clk":"5347922854","pt":1646210550492,"mc":[{"id":"1.195453749","rc":[{"atb":[[22,28.05],[14,2.72]],"id":3805747}],"con":true,"img":false}]}
{"op":"mcm","clk":"5347922879","pt":1646210551107,"mc":[{"id":"1.195453749","rc":[{"atl":[[5.1,34.31]],"id":3805784}],"con":true,"img":false}]}
{"op":"mcm","clk":"5347922929","pt":1646210552705,"mc":[{"id":"1.195453749","rc":[{"atb":[[26,11.31]],"id":3805747}],"con":true,"img":false}]}
{"op":"mcm","clk":"5347922958","pt":1646210553427,"mc":[{"id":"1.195453749","rc":[{"atb":[[23,0]],"id":3805747}],"con":true,"img":false}]}
{"op":"mcm","clk":"5347923102","pt":1646210557333,"mc":[{"id":"1.195453749","rc":[{"atb":[[22,9.92],[14,26.96]],"id":3805747}],"con":true,"img":false}]}
{"op":"mcm","clk":"5347923108","pt":1646210557490,"mc":[{"id":"1.195453749","rc":[{"atl":[[4.9,102.15]],"id":3805784}],"con":true,"img":false}]}
{"op":"mcm","clk":"5347923112","pt":1646210557595,"mc":[{"id":"1.195453749","rc":[{"atl":[[5.1,9.92],[4.9,127.79]],"id":3805784}],"con":true,"img":false}]}
{"op":"mcm","clk":"5347923116","pt":1646210557698,"mc":[{"id":"1.195453749","rc":[{"atb":[[2.26,0]],"id":3805784},{"atb":[[3.55,39.22]],"id":522745}],"con":true,"img":false}]}
{"op":"mcm","clk":"5347923119","pt":1646210557802,"mc":[{"id":"1.195453749","rc":[{"atb":[[2.44,69.44]],"id":3805784},{"atb":[[3.7,0]],"id":522745}],"con":true,"img":false}]}
{"op":"mcm","clk":"5347923123","pt":1646210557905,"mc":[{"id":"1.195453749","rc":[{"atl":[[5.1,34.31],[4.9,102.15]],"id":3805784}],"con":true,"img":false}]}
{"op":"mcm","clk":"5347923130","pt":1646210558016,"mc":[{"id":"1.195453749","rc":[{"atb":[[2.94,55.03]],"id":3805784},{"atl":[[230,4.96]],"id":522746},{"atb":[[10.5,19.44]],"id":522749},{"atl":[[7.4,9.92],[6.6,4.96]],"id":3805731},{"atl":[[90,4.96],[95,1.68],[120,9.92]],"id":522743}],"con":true,"img":false}]}
{"op":"mcm","clk":"5347923135","pt":1646210558107,"mc":[{"id":"1.195453749","rc":[{"atb":[[2.82,51.52],[2.74,0],[2.86,9.92],[2.94,59.99]],"id":3805784},{"atl":[[240,0]],"id":522746},{"atl":[[7,21.55],[7.8,0]],"id":3805731},{"atl":[[130,9.92],[95,6.64],[100,0]],"id":522742}],"con":true,"img":false}]}
{"op":"mcm","clk":"5347923142","pt":1646210558210,"mc":[{"id":"1.195453749","rc":[{"atl":[[9.6,34.69],[8.8,12.82]],"id":3805731},{"atl":[[280,2],[660,0]],"id":522743}],"con":true,"img":false}]}
{"op":"mcm","clk":"5347923151","pt":1646210558418,"mc":[{"id":"1.195453749","rc":[{"atl":[[630,2],[240,6.28]],"id":522746},{"atl":[[6.4,29.4],[7.4,68.23]],"id":3805731},{"atl":[[690,0]],"id":522743}],"con":true,"img":false}]}
{"op":"mcm","clk":"5347923155","pt":1646210558520,"mc":[{"id":"1.195453749","rc":[{"atl":[[9.6,0]],"id":3805731},{"atl":[[85,1.98],[120,22.51]],"id":522743}],"con":true,"img":false}]}
{"op":"mcm","clk":"5347923160","pt":1646210558622,"mc":[{"id":"1.195453749","rc":[{"atb":[[2.84,125.62]],"id":3805784}],"con":true,"img":false}]}
{"op":"mcm","clk":"5347923164","pt":1646210558726,"mc":[{"id":"1.195453749","rc":[{"atb":[[2.82,0]],"id":3805784},{"atb":[[10,4.96]],"id":522749}],"con":true,"img":false}]}
{"op":"mcm","clk":"5347923185","pt":1646210559139,"mc":[{"id":"1.195453749","rc":[{"atl":[[7,0]],"id":3805731}],"con":true,"img":false}]}
{"op":"mcm","clk":"5347923195","pt":1646210559347,"mc":[{"id":"1.195453749","rc":[{"atl":[[95,0],[120,9.92]],"id":522743}],"con":true,"img":false}]}
{"op":"mcm","clk":"5347923226","pt":1646210560018,"mc":[{"id":"1.195453749","rc":[{"atb":[[3.85,108.44],[4.2,9.92]],"id":3805731}],"con":true,"img":false}]}
{"op":"mcm","clk":"5347923263","pt":1646210560738,"mc":[{"id":"1.195453749","rc":[{"atb":[[4.3,2.72],[3.9,3.27]],"id":3805731}],"con":true,"img":false}]}
{"op":"mcm","clk":"5347923276","pt":1646210561205,"mc":[{"id":"1.195453749","rc":[{"atb":[[3.85,0],[4.2,68.47]],"id":3805731}],"con":true,"img":false}]}
{"op":"mcm","clk":"5347923384","pt":1646210564341,"mc":[{"id":"1.195453749","rc":[{"atl":[[5.1,194.89],[4.9,0]],"id":3805784}],"con":true,"img":false}]}
{"op":"mcm","clk":"5347923559","pt":1646210568718,"mc":[{"id":"1.195453749","rc":[{"atb":[[20,9.92],[24,4.96],[25,4.96]],"id":522752}],"con":true,"img":false}]}
{"op":"mcm","clk":"5347923563","pt":1646210568820,"mc":[{"id":"1.195453749","rc":[{"atb":[[21,0],[25,0]],"id":522752}],"con":true,"img":false}]}
{"op":"mcm","clk":"5347923568","pt":1646210568923,"mc":[{"id":"1.195453749","rc":[{"atl":[[290,4.96]],"id":522747},{"atb":[[4.1,2.72]],"id":522745}],"con":true,"img":false}]}
{"op":"mcm","clk":"5347923571","pt":1646210569027,"mc":[{"id":"1.195453749","rc":[{"atb":[[2.84,122.35],[2.94,57.26]],"id":3805784},{"atl":[[260,0],[600,2]],"id":522747}],"con":true,"img":false}]}
{"op":"mcm","clk":"5347923576","pt":1646210569130,"mc":[{"id":"1.195453749","rc":[{"atl":[[970,0]],"id":522747}],"con":true,"img":false}]}
{"op":"mcm","clk":"5347923582","pt":1646210569232,"mc":[{"id":"1.195453749","rc":[{"atb":[[21,14.76],[13.5,2.72]],"id":522752}],"con":true,"img":false}]}
{"op":"mcm","clk":"5347923591","pt":1646210569438,"mc":[{"id":"1.195453749","rc":[{"atl":[[980,0],[970,1.57]],"id":522747},{"atb":[[21,22.7]],"id":522752}],"con":true,"img":false}]}
{"op":"mcm","clk":"5347923601","pt":1646210569642,"mc":[{"id":"1.195453749","rc":[{"atb":[[4,53.1]],"id":522745}],"con":true,"img":false}]}
{"op":"mcm","clk":"5347923604","pt":1646210569744,"mc":[{"id":"1.195453749","rc":[{"atb":[[2.82,3.27],[2.92,2.72]],"id":3805784},{"atl":[[290,5.51]],"id":522747}],"con":true,"img":false}]}
{"op":"mcm","clk":"5347923614","pt":1646210570053,"mc":[{"id":"1.195453749","rc":[{"atl":[[290,0.55],[300,4.96]],"id":522747}],"con":true,"img":false}]}
{"op":"mcm","clk":"5347923641","pt":1646210570726,"mc":[{"id":"1.195453749","rc":[{"atl":[[290,0]],"id":522747}],"con":true,"img":false}]}
{"op":"mcm","clk":"5347923661","pt":1646210571344,"mc":[{"id":"1.195453749","rc":[{"atl":[[4.9,142.55]],"id":3805784}],"con":true,"img":false}]}
{"op":"mcm","clk":"5347923667","pt":1646210571448,"mc":[{"id":"1.195453749","rc":[{"atl":[[5.1,9.92],[4.9,168.19]],"id":3805784}],"con":true,"img":false}]}
{"op":"mcm","clk":"5347923680","pt":1646210571654,"mc":[{"id":"1.195453749","rc":[{"atl":[[300,0.52]],"id":522747}],"con":true,"img":false}]}
{"op":"mcm","clk":"5347923684","pt":1646210571757,"mc":[{"id":"1.195453749","rc":[{"atl":[[5.1,34.31],[4.9,142.55]],"id":3805784},{"atl":[[310,4.96]],"id":522747}],"con":true,"img":false}]}
{"op":"mcm","clk":"5347923696","pt":1646210572017,"mc":[{"id":"1.195453749","rc":[{"atl":[[4.9,0]],"id":3805784}],"con":true,"img":false}]}
{"op":"mcm","clk":"5347923713","pt":1646210572324,"mc":[{"id":"1.195453749","rc":[{"atb":[[2.86,132.27]],"id":3805784},{"atl":[[120,22.83]],"id":522743}],"con":true,"img":false}]}
{"op":"mcm","clk":"5347923719","pt":1646210572427,"mc":[{"id":"1.195453749","rc":[{"atb":[[2.84,0]],"id":3805784}],"con":true,"img":false}]}
{"op":"mcm","clk":"5347923847","pt":1646210576037,"mc":[{"id":"1.195453749","rc":[{"atb":[[20,32.07],[21,7.94]],"id":522752}],"con":true,"img":false}]}
{"op":"mcm","clk":"5347923898","pt":1646210577934,"mc":[{"id":"1.195453749","rc":[{"atl":[[4.9,142.55]],"id":3805784}],"con":true,"img":false}]}
{"op":"mcm","clk":"5347923902","pt":1646210578036,"mc":[{"id":"1.195453749","rc":[{"atl":[[5.1,9.92],[4.9,168.19]],"id":3805784}],"con":true,"img":false}]}
{"op":"mcm","clk":"5347923910","pt":1646210578345,"mc":[{"id":"1.195453749","rc":[{"atl":[[5.1,0],[4.5,4.96],[4.9,178.11],[4.7,42.91]],"id":3805784},{"atl":[[18,4.96],[24,0]],"id":522749},{"atb":[[4.3,12.65],[4.6,44.11],[4.2,58.54],[4.7,4.96]],"id":3805731},{"atb":[[20,26.52],[21,9.92],[24,0],[25,11.57]],"id":3805762},{"atl":[[32,0],[38,9.92],[40,33.59],[30,10.43]],"id":522741},{"atb":[[24,9.92],[26,6.35],[28,4.96]],"id":522742},{"atb":[[32,9.92],[38,4.29],[40,4.96],[30,0]],"id":522743}],"con":true,"img":false}]}
{"op":"mcm","clk":"5347923925","pt":1646210578757,"mc":[{"id":"1.195453749","rc":[{"atl":[[4.5,50.33]],"id":3805784},{"atl":[[18,14.3]],"id":522749},{"atb":[[4.8,41.79],[4.3,75.26],[4.2,0]],"id":3805731},{"atb":[[28,10.84],[15.5,3.27]],"id":522742},{"atb":[[32,24.68],[42,3.87],[23,2.72]],"id":522743}],"con":true,"img":false}]}
{"op":"mcm","clk":"5347923929","pt":1646210578962,"mc":[{"id":"1.195453749","rc":[{"atb":[[24,29.69]],"id":522742},{"atl":[[6.8,32.34],[7.6,9.92],[7,0],[7.8,47.74]],"id":522745}],"con":true,"img":false}]}
{"op":"mcm","clk":"5347923945","pt":1646210579481,"mc":[{"id":"1.195453749","rc":[{"atl":[[4.7,0]],"id":3805784},{"atl":[[20,4.96]],"id":522749},{"atb":[[4.6,0]],"id":3805731},{"atb":[[26,0],[28,4.96]],"id":522742},{"atb":[[38,0]],"id":522743}],"con":true,"img":false}]}
{"op":"mcm","clk":"5347923990","pt":1646210580357,"mc":[{"id":"1.195453749","rc":[{"atb":[[25,6.61]],"id":522742}],"con":true,"img":false}]}
{"op":"mcm","clk":"5347924031","pt":1646210581032,"mc":[{"id":"1.195453749","rc":[{"atb":[[4,0],[3.95,4.96],[3.8,3.27]],"id":522745}],"con":true,"img":false}]}
{"op":"mcm","clk":"5347924038","pt":1646210581135,"mc":[{"id":"1.195453749","rc":[{"atl":[[300,0]],"id":522747}],"con":true,"img":false}]}
{"op":"mcm","clk":"5347924050","pt":1646210581445,"mc":[{"id":"1.195453749","rc":[{"atb":[[2.32,75.76],[2.44,0]],"id":3805784},{"atb":[[3.4,41.67],[3.75,0]],"id":3805731}],"con":true,"img":false}]}
{"op":"mcm","clk":"5347924054","pt":1646210581549,"mc":[{"id":"1.195453749","rc":[{"atl":[[310,0]],"id":522747},{"atb":[[20,22.15],[24,0]],"id":522752},{"atl":[[60,4.96]],"id":3805762},{"atl":[[24,0],[26,4.96],[28,0],[30,9.92]],"id":3805740},{"atb":[[3.85,0]],"id":522745}],"con":true,"img":false}]}
{"op":"mcm","clk":"5347924058","pt":1646210581651,"mc":[{"id":"1.195453749","rc":[{"atl":[[600,0],[970,3.57]],"id":522747},{"atb":[[19.5,9.92],[23,4.96]],"id":522752},{"atl":[[65,4.96],[80,0],[85,9.92],[60,0]],"id":3805762}],"con":true,"img":false}]}
{"op":"mcm","clk":"5347924068","pt":1646210581962,"mc":[{"id":"1.195453749","rc":[{"atb":[[22,0],[23,9.92],[26,6.35],[27,4.96]],"id":3805747},{"atl":[[310,0.51]],"id":522747},{"atb":[[4,4.96],[3.95,0],[3.8,35.34]],"id":522745}],"con":true,"img":false}]}
{"op":"mcm","clk":"5347924073","pt":1646210582168,"mc":[{"id":"1.195453749","rc":[{"atl":[[970,2],[990,1.58]],"id":522747}],"con":true,"img":false}]}
{"op":"mcm","clk":"5347924080","pt":1646210582272,"mc":[{"id":"1.195453749","rc":[{"atl":[[310,5.47]],"id":522747},{"atl":[[65,7.44]],"id":3805762},{"atl":[[36,4.53],[24,4.96],[26,0],[28,9.92],[30,0]],"id":3805740}],"con":true,"img":false}]}
{"op":"mcm","clk":"5347924084","pt":1646210582378,"mc":[{"id":"1.195453749","rc":[{"atb":[[23,26.76],[14,2.72]],"id":3805747},{"atb":[[19.5,0],[20,32.07],[23,0],[24,4.96]],"id":522752},{"atl":[[65,2.48],[85,0]],"id":3805762}],"con":true,"img":false}]}
{"op":"mcm","clk":"5347924087","pt":1646210582434,"mc":[{"id":"1.195453749","rc":[{"atb":[[28,5.87]],"id":3805747}],"con":true,"img":false}]}
{"op":"mcm","clk":"5347924097","pt":1646210582750,"mc":[{"id":"1.195453749","rc":[{"atl":[[140,0],[150,2]],"id":3805762},{"atl":[[36,26.68],[38,2.7]],"id":3805740}],"con":true,"img":false}]}
{"op":"mcm","clk":"5347924104","pt":1646210582847,"mc":[{"id":"1.195453749","rc":[{"atl":[[140,11.27],[110,0]],"id":3805762}],"con":true,"img":false}]}
{"op":"mcm","clk":"5347924109","pt":1646210582949,"mc":[{"id":"1.195453749","rc":[{"atb":[[24,11.86]],"id":522752}],"con":true,"img":false}]}
{"op":"mcm","clk":"5347924123","pt":1646210583155,"mc":[{"id":"1.195453749","rc":[{"atl":[[5.3,23.26],[4.9,152.47]],"id":3805784},{"atl":[[80,9.92],[60,4.96]],"id":3805762}],"con":true,"img":false}]}
{"op":"mcm","clk":"5347924130","pt":1646210583266,"mc":[{"id":"1.195453749","rc":[{"atb":[[26,0]],"id":3805747}],"con":true,"img":false}]}
{"op":"mcm","clk":"5347924150","pt":1646210583736,"mc":[{"id":"1.195453749","rc":[{"atb":[[21,0]],"id":522752}],"con":true,"img":false}]}
{"op":"mcm","clk":"5347924170","pt":1646210584457,"mc":[{"id":"1.195453749","rc":[{"atb":[[20,9.92],[13.5,27.78]],"id":522752}],"con":true,"img":false}]}
{"op":"mcm","clk":"5347924175","pt":1646210584768,"mc":[{"id":"1.195453749","rc":[{"atl":[[4.5,0],[4.6,4.96],[5,9.92],[5.3,183.44],[4.9,0]],"id":3805784}],"con":true,"img":false}]}
{"op":"mcm","clk":"5347924182","pt":1646210585087,"mc":[{"id":"1.195453749","rc":[{"atb":[[4,0],[3.95,4.96],[3.8,25.42],[3.75,9.92]],"id":522745}],"con":true,"img":false}]}
{"op":"mcm","clk":"5347924195","pt":1646210585440,"mc":[{"id":"1.195453749","rc":[{"atl":[[4.5,4.96],[4.6,0],[5,0],[4.9,21.37]],"id":3805784}],"con":true,"img":false}]}
{"op":"mcm","clk":"5347924348","pt":1646210588954,"mc":[{"id":"1.195453749","rc":[{"atl":[[4.5,0],[5.1,9.92],[4.9,11.44],[4.7,4.96]],"id":3805784},{"atl":[[75,9.92],[80,0],[55,4.96],[60,0]],"id":3805762},{"atb":[[24,19.77],[28,0]],"id":522742},{"atb":[[42,0]],"id":522743},{"atb":[[4.1,24.87]],"id":522745}],"con":true,"img":false}]}
{"op":"mcm","clk":"5347924352","pt":1646210589055,"mc":[{"id":"1.195453749","rc":[{"atb":[[23,9.92],[27,4.96]],"id":522742}],"con":true,"img":false}]}
{"op":"mcm","clk":"5347924365","pt":1646210589364,"mc":[{"id":"1.195453749","rc":[{"atl":[[290,4.96],[310,0.51]],"id":522747}],"con":true,"img":false}]}
{"op":"mcm","clk":"5347924373","pt":1646210589570,"mc":[{"id":"1.195453749","rc":[{"atl":[[610,2],[970,0]],"id":522747}],"con":true,"img":false}]}
{"op":"mcm","clk":"5347924377","pt":1646210589672,"mc":[{"id":"1.195453749","rc":[{"atb":[[18,22.5],[24,0]],"id":522742},{"atb":[[32,9.92],[34,4.81],[23,17.49]],"id":522743},{"atb":[[4.1,2.72]],"id":522745}],"con":true,"img":false}]}
{"op":"mcm","clk":"5347924385","pt":1646210589879,"mc":[{"id":"1.195453749","rc":[{"atl":[[290,5.51],[990,0],[970,1.63]],"id":522747},{"atl":[[18,0],[18.5,4.96],[20,0],[21,9.92]],"id":522749},{"atb":[[23,0],[26,4.96],[27,0]],"id":522742},{"atb":[[32,0],[38,4.96],[40,0],[30,9.92]],"id":522743}],"con":true,"img":false}]}
{"op":"mcm","clk":"5347924413","pt":1646210590447,"mc":[{"id":"1.195453749","rc":[{"atb":[[3.95,57.58]],"id":522745}],"con":true,"img":false}]}
{"op":"mcm","clk":"5347924416","pt":1646210590550,"mc":[{"id":"1.195453749","rc":[{"atl":[[310,0]],"id":522747},{"atl":[[18.5,0],[20,8.35],[21,0]],"id":522749}],"con":true,"img":false}]}
{"op":"mcm","clk":"5347924437","pt":1646210591075,"mc":[{"id":"1.195453749","rc":[{"atl":[[22,57.88],[30,3.45]],"id":522749}],"con":true,"img":false}]}
{"op":"mcm","clk":"5347924446","pt":1646210591279,"mc":[{"id":"1.195453749","rc":[{"atl":[[5.1,41.73]],"id":3805784},{"atl":[[290,4.96]],"id":522747},{"atl":[[18,4.96],[20,18.28]],"id":522749},{"atl":[[75,0],[80,9.92],[55,0],[60,4.96]],"id":3805762}],"con":true,"img":false}]}
{"op":"mcm","clk":"5347924451","pt":1646210591376,"mc":[{"id":"1.195453749","rc":[{"atl":[[5.3,23.26]],"id":3805784},{"atl":[[290,0],[300,4.96]],"id":522747}],"con":true,"img":false}]}
{"op":"mcm","clk":"5347924456","pt":1646210591582,"mc":[{"id":"1.195453749","rc":[{"atb":[[17.5,0],[15,0]],"id":3805762},{"atb":[[17,0],[14.5,0]],"id":522753},{"atb":[[19,0],[23,14.76]],"id":522743}],"con":true,"img":false}]}
{"op":"mcm","clk":"5347924477","pt":1646210592047,"mc":[{"id":"1.195453749","rc":[{"atl":[[4.7,47.87]],"id":3805784},{"atl":[[300,5.49]],"id":522747},{"atl":[[18,14.3]],"id":522749},{"atb":[[26,11.31]],"id":522742},{"atb":[[40,4.07],[23,0],[30,24.68]],"id":522743}],"con":true,"img":false}]}
{"op":"mcm","clk":"5347924493","pt":1646210592356,"mc":[{"id":"1.195453749","rc":[{"atb":[[18,2.72],[15.5,12.47]],"id":3805762},{"atb":[[17.5,2.72],[15,12.8]],"id":522753},{"atb":[[19.5,3.27],[24,2.72]],"id":522743}],"con":true,"img":false}]}
{"op":"mcm","clk":"5347924513","pt":1646210592771,"mc":[{"id":"1.195453749","rc":[{"atl":[[4.9,0]],"id":3805784},{"atl":[[300,0],[310,4.96]],"id":522747},{"atl":[[20,9.92]],"id":522749},{"atb":[[25,0]],"id":522742},{"atb":[[34,0]],"id":522743}],"con":true,"img":false}]}
{"op":"mcm","clk":"5347924568","pt":1646210593647,"mc":[{"id":"1.195453749","rc":[{"atl":[[600,0.26]],"id":522747}],"con":true,"img":false}]}
{"op":"mcm","clk":"5347924603","pt":1646210594267,"mc":[{"id":"1.195453749","rc":[{"atb":[[24,4.96]],"id":522752}],"con":true,"img":false}]}
{"op":"mcm","clk":"5347924607","pt":1646210594369,"mc":[{"id":"1.195453749","rc":[{"atl":[[280,4.96],[310,0]],"id":522747},{"atb":[[19.5,9.92],[20,0],[23,4.96],[24,0]],"id":522752}],"con":true,"img":false}]}
{"op":"mcm","clk":"5347924616","pt":1646210594577,"mc":[{"id":"1.195453749","rc":[{"atb":[[44,0],[60,12.48]],"id":522747},{"atb":[[9.2,58.66],[10.5,16.71]],"id":522749},{"atb":[[18,19.77],[15.5,0]],"id":522742}],"con":true,"img":false}]}
{"op":"mcm","clk":"5347924636","pt":1646210595052,"mc":[{"id":"1.195453749","rc":[{"atb":[[20,8.35]],"id":522752}],"con":true,"img":false}]}
{"op":"mcm","clk":"5347924644","pt":1646210595153,"mc":[{"id":"1.195453749","rc":[{"atb":[[19.5,0],[19,9.92],[22,4.96],[23,0]],"id":522752}],"con":true,"img":false}]}
{"op":"mcm","clk":"5347924650","pt":1646210595249,"mc":[{"id":"1.195453749","rc":[{"atb":[[22,9.92],[23,16.83],[26,4.96],[27,0],[28,0]],"id":3805747},{"atb":[[65,2.72],[46,3.27]],"id":522747},{"atl":[[280,5.52]],"id":522747},{"atb":[[11,2.72],[9.4,3.27]],"id":522749},{"atb":[[16,3.27],[18.5,2.72]],"id":522742}],"con":true,"img":false}]}
{"op":"mcm","clk":"5347924658","pt":1646210595455,"mc":[{"id":"1.195453749","rc":[{"atl":[[610,4.64],[970,0]],"id":522747},{"atb":[[19.5,19.83]],"id":522752}],"con":true,"img":false}]}
{"op":"mcm","clk":"5347924662","pt":1646210595559,"mc":[{"id":"1.195453749","rc":[{"atb":[[13.5,2.72]],"id":522752},{"atl":[[60,7.65]],"id":3805762},{"atl":[[23,7.21]],"id":3805740}],"con":true,"img":false}]}
{"op":"mcm","clk":"5347924669","pt":1646210595766,"mc":[{"id":"1.195453749","rc":[{"atb":[[22,32.07],[23,0]],"id":3805747},{"atb":[[65,15.02],[60,0]],"id":522747},{"atb":[[10,41.01],[9.2,9.92]],"id":522749}],"con":true,"img":false}]}
{"op":"mcm","clk":"5347924673","pt":1646210595868,"mc":[{"id":"1.195453749","rc":[{"atb":[[18.5,9.92],[19,0],[21,4.96],[22,0]],"id":522752}],"con":true,"img":false}]}
{"op":"mcm","clk":"5347924677","pt":1646210595972,"mc":[{"id":"1.195453749","rc":[{"atb":[[23,7.21]],"id":3805747},{"atl":[[600,0]],"id":522747},{"atl":[[36,4.53]],"id":3805740}],"con":true,"img":false}]}
{"op":"mcm","clk":"5347924682","pt":1646210596079,"mc":[{"id":"1.195453749","rc":[{"atl":[[28,35.44]],"id":3805740}],"con":true,"img":false}]}
{"op":"mcm","clk":"5347924687","pt":1646210596178,"mc":[{"id":"1.195453749","rc":[{"atl":[[140,0],[80,30.14]],"id":3805762}],"con":true,"img":false}]}
{"op":"mcm","clk":"5347924695","pt":1646210596384,"mc":[{"id":"1.195453749","rc":[{"atl":[[65,0]],"id":3805762},{"atl":[[36,0]],"id":3805740}],"con":true,"img":false}]}
{"op":"mcm","clk":"5347924696","pt":1646210596485,"mc":[{"id":"1.195453749","rc":[{"atb":[[21,12.9]],"id":522752}],"con":true,"img":false}]}
{"op":"mcm","clk":"5347924715","pt":1646210596847,"mc":[{"id":"1.195453749","rc":[{"atl":[[80,9.92]],"id":3805762}],"con":true,"img":false}]}
{"op":"mcm","clk":"5347924730","pt":1646210597259,"mc":[{"id":"1.195453749","rc":[{"atb":[[20,0]],"id":522752}],"con":true,"img":false}]}
{"op":"mcm","clk":"5347924747","pt":1646210597677,"mc":[{"id":"1.195453749","rc":[{"atl":[[5.1,9.92],[5.3,156.67]],"id":3805784}],"con":true,"img":false}]}
{"op":"mcm","clk":"5347924881","pt":1646210599960,"mc":[{"id":"1.195453749","rc":[{"atl":[[630,0],[730,2]],"id":522746},{"atl":[[610,2.64],[850,2]],"id":522747},{"atl":[[95,0]],"id":522753},{"atl":[[9,0],[8.4,13.51]],"id":522745}],"con":true,"img":false}]}
{"op":"mcm","clk":"5347924898","pt":1646210600166,"mc":[{"id":"1.195453749","rc":[{"atl":[[140,2]],"id":522753}],"con":true,"img":false}]}
{"op":"mcm","clk":"5347924904","pt":1646210600270,"mc":[{"id":"1.195453749","rc":[{"atb":[[2.94,52.3]],"id":3805784},{"atl":[[270,4.96],[230,0],[240,0]],"id":522746},{"atb":[[80,1.68],[90,9.92],[100,1.6],[120,4.96]],"id":522747},{"atl":[[610,0]],"id":522747},{"atb":[[10,36.05],[9.2,0],[10.5,21.67],[9.4,13.19]],"id":522749},{"atb":[[4.3,72.53],[3.9,0]],"id":3805731},{"atl":[[65,20.76],[75,9.92],[48,0],[55,4.96]],"id":522752},{"atb":[[20,18.13],[23,9.92],[24,0],[27,4.96]],"id":522753},{"atl":[[65,0],[80,9.92],[48,3.37],[60,4.96]],"id":522753},{"atl":[[130,0],[150,9.92],[95,1.68],[110,4.96]],"id":522742},{"atl":[[150,9.92],[90,0],[110,4.96],[120,12.91]],"id":522743}],"con":true,"img":false}]}
{"op":"mcm","clk":"5347924916","pt":1646210600579,"mc":[{"id":"1.195453749","rc":[{"atl":[[850,3.91]],"id":522747}],"con":true,"img":false}]}
{"op":"mcm","clk":"5347924921","pt":1646210600687,"mc":[{"id":"1.195453749","rc":[{"atb":[[20,0],[23,27.16],[28,5.87]],"id":522753},{"atl":[[80,27.16],[85,0]],"id":522753},{"atl":[[150,20.79],[300,2]],"id":522742}],"con":true,"img":false}]}
{"op":"mcm","clk":"5347924925","pt":1646210600789,"mc":[{"id":"1.195453749","rc":[{"atl":[[730,4.22]],"id":522746},{"atb":[[130,1.23]],"id":522747}],"con":true,"img":false}]}
{"op":"mcm","clk":"5347924938","pt":1646210601047,"mc":[{"id":"1.195453749","rc":[{"atb":[[3.85,3.27],[4.2,2.72]],"id":3805731}],"con":true,"img":false}]}
{"op":"mcm","clk":"5347924959","pt":1646210601461,"mc":[{"id":"1.195453749","rc":[{"atl":[[850,2]],"id":522747},{"atb":[[25,0]],"id":522753}],"con":true,"img":false}]}
{"op":"mcm","clk":"5347924975","pt":1646210601768,"mc":[{"id":"1.195453749","rc":[{"atb":[[100,0]],"id":522747}],"con":true,"img":false}]}
{"op":"mcm","clk":"5347924987","pt":1646210601974,"mc":[{"id":"1.195453749","rc":[{"atb":[[18.5,43.89],[19.5,0]],"id":522752}],"con":true,"img":false}]}
{"op":"mcm","clk":"5347925000","pt":1646210602280,"mc":[{"id":"1.195453749","rc":[{"atb":[[4.1,53.95]],"id":522745}],"con":true,"img":false}]}
{"op":"mcm","clk":"5347925039","pt":1646210603166,"mc":[{"id":"1.195453749","rc":[{"atb":[[3.95,4.96]],"id":522745}],"con":true,"img":false}]}
{"op":"mcm","clk":"5347925271","pt":1646210608280,"mc":[{"id":"1.195453749","rc":[{"atb":[[18.5,9.92],[13.5,29.31]],"id":522752}],"con":true,"img":false}]}
{"op":"mcm","clk":"5347925287","pt":1646210608794,"mc":[{"id":"1.195453749","rc":[{"atb":[[90,24.68]],"id":522747}],"con":true,"img":false}]}
{"op":"mcm","clk":"5347925291","pt":1646210608899,"mc":[{"id":"1.195453749","rc":[{"atb":[[65,2.72]],"id":522747}],"con":true,"img":false}]}
{"op":"mcm","clk":"5347925300","pt":1646210609058,"mc":[{"id":"1.195453749","rc":[{"atb":[[26,11.31]],"id":3805747}],"con":true,"img":false}]}
{"op":"mcm","clk":"5347925312","pt":1646210609267,"mc":[{"id":"1.195453749","rc":[{"atl":[[150,13.02]],"id":3805762}],"con":true,"img":false}]}
{"op":"mcm","clk":"5347925337","pt":1646210609779,"mc":[{"id":"1.195453749","rc":[{"atb":[[23,0]],"id":3805747}],"con":true,"img":false}]}
{"op":"mcm","clk":"5347925368","pt":1646210610296,"mc":[{"id":"1.195453749","rc":[{"atb":[[22,9.92],[14,26.96]],"id":3805747}],"con":true,"img":false}]}
{"op":"mcm","clk":"5347925486","pt":1646210613177,"mc":[{"id":"1.195453749","rc":[{"atl":[[7.2,9.92],[6.4,34.36],[7.4,58.31],[6.6,0]],"id":3805731}],"con":true,"img":false}]}
{"op":"mcm","clk":"5347925497","pt":1646210613485,"mc":[{"id":"1.195453749","rc":[{"atb":[[21,9.92],[25,4.96]],"id":3805747}],"con":true,"img":false}]}
{"op":"mcm","clk":"5347925500","pt":1646210613588,"mc":[{"id":"1.195453749","rc":[{"atb":[[22,0],[26,0]],"id":3805747}],"con":true,"img":false}]}
{"op":"mcm","clk":"5347925527","pt":1646210614306,"mc":[{"id":"1.195453749","rc":[{"atb":[[22,7.56]],"id":3805747}],"con":true,"img":false}]}
{"op":"mcm","clk":"5347925750","pt":1646210619507,"mc":[{"id":"1.195453749","rc":[{"atl":[[8.4,13.51]],"id":3805731}],"con":true,"img":false}]}
{"op":"mcm","clk":"5347925753","pt":1646210619610,"mc":[{"id":"1.195453749","rc":[{"atl":[[8.8,0]],"id":3805731}],"con":true,"img":false}]}
{"op":"mcm","clk":"5347925757","pt":1646210619816,"mc":[{"id":"1.195453749","rc":[{"atb":[[11,18.6]],"id":522749}],"con":true,"img":false}]}
{"op":"mcm","clk":"5347925785","pt":1646210620487,"mc":[{"id":"1.195453749","rc":[{"atb":[[10.5,4.96]],"id":522749}],"con":true,"img":false}]}
{"op":"mcm","clk":"5347925797","pt":1646210620799,"mc":[{"id":"1.195453749","rc":[{"atl":[[7.2,16.13]],"id":3805784},{"atb":[[20,5.26]],"id":522746},{"atb":[[21,5],[13.5,0]],"id":522747},{"atb":[[42,0],[55,5.27]],"id":522750},{"atb":[[3.4,0],[2.6,62.5]],"id":3805731},{"atb":[[10,0],[14.5,17.28]],"id":522742},{"atl":[[38,0],[50,2.04]],"id":3805740}],"con":true,"img":false}]}
{"op":"mcm","clk":"5347925802","pt":1646210620904,"mc":[{"id":"1.195453749","rc":[{"atl":[[5.3,133.41]],"id":3805784},{"atb":[[15,0]],"id":522746}],"con":true,"img":false}]}
{"op":"mcm","clk":"5347925824","pt":1646210621419,"mc":[{"id":"1.195453749","rc":[{"atl":[[140,9.92],[150,10.86],[100,4.96],[110,0]],"id":522742}],"con":true,"img":false}]}
{"op":"mcm","clk":"5347925847","pt":1646210621884,"mc":[{"id":"1.195453749","rc":[{"atb":[[25,11.57]],"id":3805747},{"atl":[[140,21.99]],"id":522742}],"con":true,"img":false}]}
{"op":"mcm","clk":"5347925854","pt":1646210621985,"mc":[{"id":"1.195453749","rc":[{"atl":[[150,0]],"id":522742}],"con":true,"img":false}]}
{"op":"mcm","clk":"5347925886","pt":1646210622704,"mc":[{"id":"1.195453749","rc":[{"atb":[[22,0]],"id":3805747}],"con":true,"img":false}]}
{"op":"mcm","clk":"5347925904","pt":1646210623115,"mc":[{"id":"1.195453749","rc":[{"atb":[[14,2.72]],"id":3805747}],"con":true,"img":false}]}
{"op":"mcm","clk":"5347925910","pt":1646210623218,"mc":[{"id":"1.195453749","rc":[{"atb":[[21,35.94]],"id":3805747}],"con":true,"img":false}]}
{"op":"mcm","clk":"5347925977","pt":1646210624609,"mc":[{"id":"1.195453749","rc":[{"atb":[[2.82,0],[2.92,0]],"id":3805784}],"con":true,"img":false}]}
{"op":"mcm","clk":"5347926018","pt":1646210625235,"mc":[{"id":"1.195453749","rc":[{"atb":[[2.86,9.92],[2.48,302.18]],"id":3805784}],"con":true,"img":false}]}
{"op":"mcm","clk":"5347926025","pt":1646210625330,"mc":[{"id":"1.195453749","rc":[{"atb":[[2.86,13.19],[2.96,2.72]],"id":3805784}],"con":true,"img":false}]}
{"op":"mcm","clk":"5347926052","pt":1646210625896,"mc":[{"id":"1.195453749","rc":[{"atb":[[2.48,90.14]],"id":3805784}],"con":true,"img":false}]}
{"op":"mcm","clk":"5347926209","pt":1646210629493,"mc":[{"id":"1.195453749","rc":[{"atb":[[21,9.92],[14,27.35]],"id":3805747}],"con":true,"img":false}]}
{"op":"mcm","clk":"5347926239","pt":1646210630318,"mc":[{"id":"1.195453749","rc":[{"atb":[[20,9.92],[21,0],[24,4.96],[25,0]],"id":3805747}],"con":true,"img":false}]}
{"op":"mcm","clk":"5347926266","pt":1646210631095,"mc":[{"id":"1.195453749","rc":[{"atb":[[21,7.94]],"id":3805747}],"con":true,"img":false}]}
{"op":"mcm","clk":"5347926322","pt":1646210632441,"mc":[{"id":"1.195453749","rc":[{"atb":[[21,0],[25,6.61]],"id":3805762},{"atb":[[30,4.96]],"id":522742},{"atb":[[38,0],[40,13.99],[48,4.96],[30,14.76]],"id":522743}],"con":true,"img":false}]}
{"op":"mcm","clk":"5347926330","pt":1646210632543,"mc":[{"id":"1.195453749","rc":[{"atl":[[4,4.96],[5.1,0],[4.4,9.92],[4.7,42.91]],"id":3805784},{"atl":[[17,4.96],[18,9.33],[19,9.92],[20,0]],"id":522749},{"atb":[[23,9.92],[27,4.96]],"id":3805762}],"con":true,"img":false}]}
{"op":"mcm","clk":"5347926343","pt":1646210632804,"mc":[{"id":"1.195453749","rc":[{"atb":[[18,28.88],[20,0]],"id":3805762},{"atb":[[18.5,17.49],[18,0]],"id":522742}],"con":true,"img":false}]}
{"op":"mcm","clk":"5347926355","pt":1646210633008,"mc":[{"id":"1.195453749","rc":[{"atl":[[4,39.37],[5.3,0],[4.7,77.33]],"id":3805784},{"atl":[[17,14.88],[19,38.59],[22,0]],"id":522749},{"atb":[[28,5.87]],"id":3805762},{"atb":[[30,10.43]],"id":522742},{"atb":[[48,8.34]],"id":522743}],"con":true,"img":false}]}
{"op":"mcm","clk":"5347926369","pt":1646210633318,"mc":[{"id":"1.195453749","rc":[{"atb":[[5.2,0],[5.7,21.28]],"id":522749},{"atb":[[10.5,0],[13,8.33]],"id":3805762},{"atb":[[11.5,0],[14.5,7.41]],"id":522753},{"atb":[[3.55,0],[3.65,37.74]],"id":522745}],"con":true,"img":false}]}
{"op":"mcm","clk":"5347926377","pt":1646210633527,"mc":[{"id":"1.195453749","rc":[{"atb":[[1.94,0],[2.48,0],[2.08,0]],"id":3805784},{"atb":[[5.1,0],[10.5,0],[6.2,0]],"id":3805747},{"atb":[[16,0],[34,0],[11,0]],"id":522746},{"atb":[[18,0],[80,0],[26,0]],"id":522747},{"atb":[[5.1,0],[8.2,0],[4.1,0]],"id":522749},{"atb":[[190,0],[48,0],[29,0]],"id":522750},{"atb":[[2.42,0],[2.62,0],[3.05,0]],"id":3805731},{"atb":[[9.8,0],[4.9,0],[5.9,0]],"id":522752},{"atb":[[6.2,0],[8.2,0],[15.5,3.27]],"id":3805762},{"atb":[[8,0],[6,0],[15,3.27]],"id":522753},{"atb":[[6.4,0],[11,0],[5.2,0]],"id":522741},{"atb":[[7.8,0],[14.5,7.41],[5.9,0]],"id":522742},{"atb":[[7.2,0],[18,0],[9.2,12.2]],"id":522743},{"atb":[[8.6,0],[4.3,0],[5.3,0]],"id":3805740},{"atb":[[2.54,0],[2.94,0],[2.34,0]],"id":522745}],"con":true,"img":false}]}
{"op":"mcm","clk":"5347926384","pt":1646210633736,"mc":[{"id":"1.195453749","rc":[{"atl":[[4.7,34.41]],"id":3805784},{"atl":[[18,0]],"id":522749},{"atb":[[25,0]],"id":3805762},{"atb":[[26,4.96]],"id":522742},{"atb":[[40,9.92]],"id":522743}],"con":true,"img":false}]}
{"op":"mcm","clk":"5347926394","pt":1646210633944,"mc":[{"id":"1.195453749","rc":[{"atb":[[120,21.81]],"id":522750}],"con":true,"img":false}]}
{"op":"mcm","clk":"5347926397","pt":1646210634001,"mc":[{"id":"1.195453749","rc":[{"atb":[[160,4.96]],"id":522750}],"con":true,"img":false}]}
{"op":"mcm","clk":"5347926411","pt":1646210634411,"mc":[{"id":"1.195453749","rc":[{"atb":[[24,11.86]],"id":3805747}],"con":true,"img":false}]}
{"op":"mcm","clk":"5347926436","pt":1646210635235,"mc":[{"id":"1.195453749","rc":[{"atb":[[21,0]],"id":3805747}],"con":true,"img":false}]}
{"op":"mcm","clk":"5347926451","pt":1646210635646,"mc":[{"id":"1.195453749","rc":[{"atb":[[20,36.51]],"id":3805747},{"atl":[[17,9.92],[19,28.67]],"id":522749}],"con":true,"img":false}]}
{"op":"mcm","clk":"5347926458","pt":1646210635698,"mc":[{"id":"1.195453749","rc":[{"atb":[[14,2.72]],"id":3805747},{"atl":[[17,0],[17.5,4.96],[19.5,9.92]],"id":522749},{"atb":[[25,9.92],[26,0],[29,4.96],[30,0]],"id":522742}],"con":true,"img":false}]}
{"op":"mcm","clk":"5347926469","pt":1646210636007,"mc":[{"id":"1.195453749","rc":[{"atb":[[4.6,4.96],[3.95,0],[4.2,9.92],[3.75,0]],"id":522745}],"con":true,"img":false}]}
{"op":"mcm","clk":"5347926473","pt":1646210636211,"mc":[{"id":"1.195453749","rc":[{"atl":[[4,0],[4.5,9.92],[4.1,4.96],[4.4,0]],"id":3805784},{"atl":[[18.5,4.96],[21,9.92],[24,0],[28,25.51]],"id":3805740}],"con":true,"img":false}]}
{"op":"mcm","clk":"5347926477","pt":1646210636313,"mc":[{"id":"1.195453749","rc":[{"atb":[[20,9.92]],"id":3805747},{"atb":[[18.5,0],[19.5,9.92],[21,7.94],[23,4.96]],"id":522752}],"con":true,"img":false}]}
{"op":"mcm","clk":"5347926484","pt":1646210636417,"mc":[{"id":"1.195453749","rc":[{"atl":[[19,37.49]],"id":522749},{"atb":[[26,6.35]],"id":522742},{"atb":[[4.1,116.86],[3.8,3.27],[4.7,42.91]],"id":522745}],"con":true,"img":false}]}
{"op":"mcm","clk":"5347926493","pt":1646210636621,"mc":[{"id":"1.195453749","rc":[{"atl":[[28,0]],"id":3805740}],"con":true,"img":false}]}
{"op":"mcm","clk":"5347926497","pt":1646210636724,"mc":[{"id":"1.195453749","rc":[{"atl":[[18.5,14.03],[23,32.73]],"id":3805740}],"con":true,"img":false}]}
{"op":"mcm","clk":"5347926505","pt":1646210636828,"mc":[{"id":"1.195453749","rc":[{"atb":[[19.5,29.12],[23,12.17],[13.5,2.72]],"id":522752}],"con":true,"img":false}]}
{"op":"mcm","clk":"5347926515","pt":1646210637033,"mc":[{"id":"1.195453749","rc":[{"atl":[[4.6,11.44]],"id":3805784}],"con":true,"img":false}]}
{"op":"mcm","clk":"5347926524","pt":1646210637237,"mc":[{"id":"1.195453749","rc":[{"atb":[[4.1,65.63]],"id":522745}],"con":true,"img":false}]}
{"op":"mcm","clk":"5347926535","pt":1646210637546,"mc":[{"id":"1.195453749","rc":[{"atl":[[23,25.51]],"id":3805740}],"con":true,"img":false}]}
{"op":"mcm","clk":"5347926543","pt":1646210637704,"mc":[{"id":"1.195453749","rc":[{"atb":[[2.86,45.01]],"id":3805784},{"atb":[[21,0]],"id":522752}],"con":true,"img":false}]}
{"op":"mcm","clk":"5347926581","pt":1646210639047,"mc":[{"id":"1.195453749","rc":[{"atl":[[19.5,52.39]],"id":522749}],"con":true,"img":false}]}
{"op":"mcm","clk":"5347926583","pt":1646210639151,"mc":[{"id":"1.195453749","rc":[{"atl":[[19,8.82]],"id":522749}],"con":true,"img":false}]}
{"op":"mcm","clk":"5347926600","pt":1646210639640,"mc":[{"id":"1.195453749","rc":[{"atl":[[17.5,0],[18,4.96],[19.5,42.47],[20,9.92]],"id":522749},{"atb":[[38,9.92],[40,0],[46,4.96],[48,0]],"id":522743}],"con":true,"img":false}]}
{"op":"mcm","clk":"5347926639","pt":1646210640313,"mc":[{"id":"1.195453749","rc":[{"atb":[[32,5.12]],"id":522743}],"con":true,"img":false}]}
{"op":"mcm","clk":"5347926667","pt":1646210640832,"mc":[{"id":"1.195453749","rc":[{"atb":[[19.5,9.92],[20,0],[23,4.96],[24,0]],"id":3805747},{"atb":[[32,20.12],[30,0]],"id":522743}],"con":true,"img":false}]}
{"op":"mcm","clk":"5347926703","pt":1646210641715,"mc":[{"id":"1.195453749","rc":[{"atb":[[14.5,11.76]],"id":3805747}],"con":true,"img":false}]}
{"op":"mcm","clk":"5347926723","pt":1646210642131,"mc":[{"id":"1.195453749","rc":[{"atb":[[14,17.49]],"id":3805747}],"con":true,"img":false}]}
{"op":"mcm","clk":"5347926755","pt":1646210642811,"mc":[{"id":"1.195453749","rc":[{"atb":[[19.5,9.92],[13.5,28.24]],"id":522752}],"con":true,"img":false}]}
{"op":"mcm","clk":"5347926783","pt":1646210643432,"mc":[{"id":"1.195453749","rc":[{"atb":[[23,12.17]],"id":3805747}],"con":true,"img":false}]}
{"op":"mcm","clk":"5347926797","pt":1646210643746,"mc":[{"id":"1.195453749","rc":[{"atl":[[4.5,0],[4.6,21.37],[4.1,0],[4.2,4.96]],"id":3805784},{"atb":[[19.5,0],[19,9.92],[22,4.96],[23,7.21]],"id":3805747},{"atl":[[18,0],[19,13.78],[20,0]],"id":522749},{"atb":[[24,9.92],[25,0],[28,4.96],[29,0]],"id":522742},{"atb":[[36,9.92],[38,0],[44,4.96],[46,0]],"id":522743}],"con":true,"img":false}]}
{"op":"mcm","clk":"5347926813","pt":1646210644054,"mc":[{"id":"1.195453749","rc":[{"atb":[[17.5,16.16],[40,3.42],[12.5,23.19]],"id":522746},{"atb":[[32,8.6],[21,18.34],[110,1.22]],"id":522747},{"atb":[[2.4,190.57],[3,66.7],[2.6,229.25]],"id":3805731},{"atb":[[5.3,62.04],[11.5,12.7],[6.6,47.64]],"id":522741},{"atb":[[8,38.11],[6,53.36],[15,9.53]],"id":522742},{"atb":[[18.5,7.62],[7.4,41.69],[9.4,31.76]],"id":522743},{"atb":[[2.92,69.48],[2.32,202.12],[2.52,175.53]],"id":522745}],"con":true,"img":false}]}
{"op":"mcm","clk":"5347926819","pt":1646210644161,"mc":[{"id":"1.195453749","rc":[{"atb":[[2.06,251.7],[2.46,91.37],[1.93,286.89]],"id":3805784},{"atb":[[6.4,49.41],[11,13.34],[5.2,63.52],[14.5,0]],"id":3805747},{"atb":[[5.2,63.52],[8.4,18.02],[4.2,83.37]],"id":522749},{"atb":[[270,0.49],[85,3.17],[44,6.2]],"id":522750},{"atb":[[5.1,65.07],[10.5,14.04],[6.2,51.31]],"id":522752},{"atb":[[6.2,51.31],[8.2,37.05],[15.5,12.47]],"id":3805762},{"atb":[[6.2,51.31],[8.2,37.05],[15.5,9.2]],"id":522753},{"atb":[[8.8,17.1],[4.4,78.47],[5.4,60.63]],"id":3805740}],"con":true,"img":false}]}
{"op":"mcm","clk":"5347926835","pt":1646210644422,"mc":[{"id":"1.195453749","rc":[{"atl":[[4.5,9.92],[4.1,4.96]],"id":3805784},{"atb":[[19,0],[19.5,9.92],[22,0],[23,12.17]],"id":3805747},{"atl":[[18.5,4.96],[19,8.82],[21,9.92]],"id":522749}],"con":true,"img":false}]}
{"op":"mcm","clk":"5347926840","pt":1646210644526,"mc":[{"id":"1.195453749","rc":[{"atl":[[4.6,11.44],[4.2,0]],"id":3805784},{"atb":[[90,9.92],[110,7.17]],"id":522747}],"con":true,"img":false}]}
{"op":"mcm","clk":"5347926845","pt":1646210644628,"mc":[{"id":"1.195453749","rc":[{"atb":[[280,0.56]],"id":522750}],"con":true,"img":false}]}
{"op":"mcm","clk":"5347926863","pt":1646210645040,"mc":[{"id":"1.195453749","rc":[{"atb":[[24,26.76]],"id":522742}],"con":true,"img":false}]}
{"op":"mcm","clk":"5347926870","pt":1646210645143,"mc":[{"id":"1.195453749","rc":[{"atb":[[18,2.72],[23,36.08]],"id":3805762},{"atb":[[18.5,2.72]],"id":522742}],"con":true,"img":false}]}
{"op":"mcm","clk":"5347926876","pt":1646210645246,"mc":[{"id":"1.195453749","rc":[{"atl":[[4.6,43.25],[4.7,0]],"id":3805784},{"atl":[[18.5,14.03]],"id":522749},{"atb":[[29,5.67]],"id":522742},{"atb":[[46,3.52]],"id":522743}],"con":true,"img":false}]}
{"op":"mcm","clk":"5347926881","pt":1646210645350,"mc":[{"id":"1.195453749","rc":[{"atl":[[4.1,27.11]],"id":3805784},{"atb":[[200,0]],"id":522750}],"con":true,"img":false}]}
{"op":"mcm","clk":"5347926925","pt":1646210646025,"mc":[{"id":"1.195453749","rc":[{"atb":[[2.96,39.15]],"id":3805784},{"atl":[[19,0]],"id":522749},{"atb":[[26,0]],"id":522742},{"atb":[[32,15]],"id":522743}],"con":true,"img":false}]}
{"op":"mcm","clk":"5347926929","pt":1646210646129,"mc":[{"id":"1.195453749","rc":[{"atl":[[4.6,31.81]],"id":3805784},{"atb":[[160,6.55],[120,9.92]],"id":522750}],"con":true,"img":false}]}
{"op":"mcm","clk":"5347926944","pt":1646210646438,"mc":[{"id":"1.195453749","rc":[{"atl":[[19.5,0],[21,58.51]],"id":522749}],"con":true,"img":false}]}
{"op":"mcm","clk":"5347926964","pt":1646210646953,"mc":[{"id":"1.195453749","rc":[{"atb":[[2.94,0]],"id":3805784}],"con":true,"img":false}]}
{"op":"mcm","clk":"5347926984","pt":1646210647626,"mc":[{"id":"1.195453749","rc":[{"atb":[[2.86,13.19],[2.46,197.01]],"id":3805784}],"con":true,"img":false}]}
{"op":"mcm","clk":"5347927028","pt":1646210648553,"mc":[{"id":"1.195453749","rc":[{"atb":[[4.2,72.83]],"id":522745}],"con":true,"img":false}]}
{"op":"mcm","clk":"5347927035","pt":1646210648655,"mc":[{"id":"1.195453749","rc":[{"atb":[[4.1,2.72]],"id":522745}],"con":true,"img":false}]}
{"op":"mcm","clk":"5347927041","pt":1646210648759,"mc":[{"id":"1.195453749","rc":[{"atb":[[80,0],[55,2]],"id":522750},{"atb":[[11,0],[13.5,25.51]],"id":522752},{"atb":[[17.5,0],[15,0]],"id":522753},{"atb":[[4.1,0],[3.8,0]],"id":522745}],"con":true,"img":false}]}
{"op":"mcm","clk":"5347927059","pt":1646210649226,"mc":[{"id":"1.195453749","rc":[{"atb":[[29,0]],"id":522742},{"atl":[[18.5,0],[19,4.96],[21,0],[22,9.92]],"id":3805740}],"con":true,"img":false}]}
{"op":"mcm","clk":"5347927067","pt":1646210649430,"mc":[{"id":"1.195453749","rc":[{"atb":[[85,5.9],[60,3.27]],"id":522750},{"atb":[[16,3.27],[18.5,2.72]],"id":522753},{"atb":[[4.3,2.72],[3.9,3.27]],"id":522745}],"con":true,"img":false}]}
{"op":"mcm","clk":"5347927071","pt":1646210649534,"mc":[{"id":"1.195453749","rc":[{"atb":[[11.5,3.27],[14,2.72]],"id":522752}],"con":true,"img":false}]}
{"op":"mcm","clk":"5347927087","pt":1646210649948,"mc":[{"id":"1.195453749","rc":[{"atl":[[4.5,0],[4.6,41.73],[4.1,0],[4.2,4.96]],"id":3805784},{"atl":[[22,17.48]],"id":3805740}],"con":true,"img":false}]}
{"op":"mcm","clk":"5347927089","pt":1646210650051,"mc":[{"id":"1.195453749","rc":[{"atb":[[13.5,0],[14,24.87]],"id":522752},{"atb":[[25,6.61]],"id":522742}],"con":true,"img":false}]}
{"op":"mcm","clk":"5347927119","pt":1646210650723,"mc":[{"id":"1.195453749","rc":[{"atl":[[4.6,68.77]],"id":3805784}],"con":true,"img":false}]}
{"op":"mcm","clk":"5347927133","pt":1646210651133,"mc":[{"id":"1.195453749","rc":[{"atl":[[7.2,98.42],[4.6,36.95]],"id":3805784},{"atl":[[280,0],[310,4.96]],"id":522747},{"atl":[[18.5,9.07],[18,4.96],[20,9.92],[21,48.59]],"id":522749},{"atb":[[19.5,0],[19,9.92],[22,4.96],[23,0]],"id":522752},{"atl":[[19,0],[20,4.96],[22,7.56],[24,9.92]],"id":3805740}],"con":true,"img":false}]}
{"op":"mcm","clk":"5347927137","pt":1646210651237,"mc":[{"id":"1.195453749","rc":[{"atl":[[800,2],[850,0]],"id":522747}],"con":true,"img":false}]}
{"op":"mcm","clk":"5347927148","pt":1646210651547,"mc":[{"id":"1.195453749","rc":[{"atl":[[330,5.37]],"id":522747},{"atl":[[20,38.19],[21,0]],"id":522749}],"con":true,"img":false}]}
{"op":"mcm","clk":"5347927158","pt":1646210651858,"mc":[{"id":"1.195453749","rc":[{"atl":[[300,4.96],[310,0.51]],"id":522747},{"atl":[[18,0],[18.5,14.03],[20,28.26],[21,9.92]],"id":522749},{"atb":[[19,0],[22,0],[14.5,11.76]],"id":522752}],"con":true,"img":false}]}
{"op":"mcm","clk":"5347927169","pt":1646210652063,"mc":[{"id":"1.195453749","rc":[{"atb":[[12,0],[13,8.33]],"id":522752}],"con":true,"img":false}]}
{"op":"mcm","clk":"5347927185","pt":1646210652324,"mc":[{"id":"1.195453749","rc":[{"atl":[[20,0],[21,58.51]],"id":522749}],"con":true,"img":false}]}
{"op":"mcm","clk":"5347927197","pt":1646210652531,"mc":[{"id":"1.195453749","rc":[{"atl":[[800,0],[860,2]],"id":522747}],"con":true,"img":false}]}
{"op":"mcm","clk":"5347927203","pt":1646210652633,"mc":[{"id":"1.195453749","rc":[{"atb":[[19.5,9.92],[23,4.96]],"id":522752}],"con":true,"img":false}]}
{"op":"mcm","clk":"5347927215","pt":1646210652840,"mc":[{"id":"1.195453749","rc":[{"atb":[[11.5,0],[14,14.76]],"id":3805747},{"atb":[[36,0],[46,0]],"id":522746},{"atb":[[18,0],[15.5,9.2]],"id":3805762},{"atb":[[16,0],[18.5,0]],"id":522742},{"atb":[[19.5,0],[24,0]],"id":522743}],"con":true,"img":false}]}
{"op":"mcm","clk":"5347927219","pt":1646210652942,"mc":[{"id":"1.195453749","rc":[{"atb":[[32,0],[36,24.68]],"id":522743}],"con":true,"img":false}]}
{"op":"mcm","clk":"5347927239","pt":1646210653356,"mc":[{"id":"1.195453749","rc":[{"atb":[[23,17.23],[24,9.92],[27,0],[28,10.84]],"id":522753}],"con":true,"img":false}]}
{"op":"mcm","clk":"5347927248","pt":1646210653562,"mc":[{"id":"1.195453749","rc":[{"atb":[[12,3.27],[14.5,2.72]],"id":3805747},{"atb":[[40,6.69],[50,2.72]],"id":522746},{"atb":[[19.5,0],[19,9.92],[22,4.96],[23,0]],"id":522752},{"atb":[[16.5,3.27],[19,2.72]],"id":3805762},{"atb":[[17,3.27],[19.5,2.72]],"id":522742},{"atb":[[20,3.27],[25,2.72]],"id":522743}],"con":true,"img":false}]}
{"op":"mcm","clk":"5347927268","pt":1646210654031,"mc":[{"id":"1.195453749","rc":[{"atb":[[14,0],[14.5,24.87]],"id":3805747}],"con":true,"img":false}]}
{"op":"mcm","clk":"5347927276","pt":1646210654341,"mc":[{"id":"1.195453749","rc":[{"atb":[[19.5,0],[19,9.92],[22,4.96],[23,0]],"id":3805747},{"atl":[[18.5,4.96],[19,4.96],[22,9.92]],"id":522749},{"atb":[[46,0]],"id":522743}],"con":true,"img":false}]}
{"op":"mcm","clk":"5347927280","pt":1646210654455,"mc":[{"id":"1.195453749","rc":[{"atl":[[18.5,0],[21,48.59]],"id":522749}],"con":true,"img":false}]}
{"op":"mcm","clk":"5347927311","pt":1646210655075,"mc":[{"id":"1.195453749","rc":[{"atb":[[15,11.34]],"id":3805747},{"atl":[[19,0],[20,8.35],[22,0]],"id":522749},{"atb":[[14,2.72],[14.5,33.91]],"id":522752},{"atb":[[38,4.29]],"id":522743}],"con":true,"img":false}]}
{"op":"mcm","clk":"5347927361","pt":1646210655846,"mc":[{"id":"1.195453749","rc":[{"atl":[[800,2],[860,0]],"id":522747},{"atl":[[18.5,4.96],[21,58.51]],"id":522749}],"con":true,"img":false}]}
{"op":"mcm","clk":"5347927378","pt":1646210656155,"mc":[{"id":"1.195453749","rc":[{"atl":[[270,0],[260,4.96]],"id":522746}],"con":true,"img":false}]}
{"op":"mcm","clk":"5347927390","pt":1646210656361,"mc":[{"id":"1.195453749","rc":[{"atl":[[660,2],[730,2.22]],"id":522746}],"con":true,"img":false}]}
{"op":"mcm","clk":"5347927414","pt":1646210656878,"mc":[{"id":"1.195453749","rc":[{"atl":[[660,4.7],[730,0]],"id":522746}],"con":true,"img":false}]}
{"op":"mcm","clk":"5347927432","pt":1646210657237,"mc":[{"id":"1.195453749","rc":[{"atl":[[18.5,14.03]],"id":522749},{"atb":[[28,10.84]],"id":522742},{"atb":[[46,3.52]],"id":522743}],"con":true,"img":false}]}
{"op":"mcm","clk":"5347927442","pt":1646210657444,"mc":[{"id":"1.195453749","rc":[{"atl":[[4.2,54.58]],"id":3805784}],"con":true,"img":false}]}
{"op":"mcm","clk":"5347927473","pt":1646210658062,"mc":[{"id":"1.195453749","rc":[{"atl":[[20,0]],"id":522749},{"atb":[[25,0],[28,4.96]],"id":522742},{"atb":[[38,0]],"id":522743}],"con":true,"img":false}]}
{"op":"mcm","clk":"5347927476","pt":1646210658165,"mc":[{"id":"1.195453749","rc":[{"atl":[[4.6,9.92]],"id":3805784}],"con":true,"img":false}]}
{"op":"mcm","clk":"5347927497","pt":1646210658578,"mc":[{"id":"1.195453749","rc":[{"atl":[[21,9.92],[30,52.04]],"id":522749},{"atb":[[19.5,17.49],[24,9.92]],"id":522742}],"con":true,"img":false}]}
{"op":"mcm","clk":"5347927505","pt":1646210658735,"mc":[{"id":"1.195453749","rc":[{"atb":[[25,6.61]],"id":522742}],"con":true,"img":false}]}
{"op":"mcm","clk":"5347927586","pt":1646210660494,"mc":[{"id":"1.195453749","rc":[{"atb":[[4.3,65.63],[4.2,9.92]],"id":522745}],"con":true,"img":false}]}
{"op":"mcm","clk":"5347927626","pt":1646210661265,"mc":[{"id":"1.195453749","rc":[{"atb":[[2.8,9.92],[2.88,4.96],[2.86,3.27]],"id":3805784}],"con":true,"img":false}]}
{"op":"mcm","clk":"5347927650","pt":1646210661781,"mc":[{"id":"1.195453749","rc":[{"atb":[[2.86,76.32],[2.46,91.37]],"id":3805784}],"con":true,"img":false}]}
{"op":"mcm","clk":"5347927661","pt":1646210661988,"mc":[{"id":"1.195453749","rc":[{"atb":[[29,5.67]],"id":522742}],"con":true,"img":false}]}
{"op":"mcm","clk":"5347927689","pt":1646210662659,"mc":[{"id":"1.195453749","rc":[{"atb":[[25,0]],"id":522742}],"con":true,"img":false}]}
{"op":"mcm","clk":"5347927742","pt":1646210663751,"mc":[{"id":"1.195453749","rc":[{"atl":[[300,5.49]],"id":522747},{"atb":[[22,12.52]],"id":522752}],"con":true,"img":false}]}
{"op":"mcm","clk":"5347927777","pt":1646210664574,"mc":[{"id":"1.195453749","rc":[{"atl":[[310,0]],"id":522747},{"atb":[[14.5,22.15]],"id":522752}],"con":true,"img":false}]}
{"op":"mcm","clk":"5347927802","pt":1646210665182,"mc":[{"id":"1.195453749","rc":[{"atl":[[330,0],[800,4.25]],"id":522747}],"con":true,"img":false}]}
{"op":"mcm","clk":"5347927831","pt":1646210665854,"mc":[{"id":"1.195453749","rc":[{"atb":[[14.5,2.72],[15,33.49]],"id":3805747}],"con":true,"img":false}]}
{"op":"mcm","clk":"5347927877","pt":1646210666986,"mc":[{"id":"1.195453749","rc":[{"atb":[[23,7.21]],"id":3805747}],"con":true,"img":false}]}
{"op":"mcm","clk":"5347927895","pt":1646210667244,"mc":[{"id":"1.195453749","rc":[{"atb":[[4.3,62.61],[4.4,4.96],[4.7,0]],"id":3805731}],"con":true,"img":false}]}
{"op":"mcm","clk":"5347927914","pt":1646210667656,"mc":[{"id":"1.195453749","rc":[{"atb":[[15,22.15]],"id":3805747}],"con":true,"img":false}]}
{"op":"mcm","clk":"5347928047","pt":1646210670386,"mc":[{"id":"1.195453749","rc":[{"atb":[[19.5,2.72],[24,25.74]],"id":522742}],"con":true,"img":false}]}
{"op":"mcm","clk":"5347928078","pt":1646210670857,"mc":[{"id":"1.195453749","rc":[{"atl":[[18.5,4.96],[19,4.96],[22,9.92]],"id":522749}],"con":true,"img":false}]}
{"op":"mcm","clk":"5347928085","pt":1646210670958,"mc":[{"id":"1.195453749","rc":[{"atb":[[23,0]],"id":3805747},{"atl":[[18.5,0],[21,0]],"id":522749}],"con":true,"img":false}]}
{"op":"mcm","clk":"5347928101","pt":1646210671267,"mc":[{"id":"1.195453749","rc":[{"atb":[[120,0]],"id":522746},{"atl":[[21,22.15]],"id":522749}],"con":true,"img":false}]}
{"op":"mcm","clk":"5347928104","pt":1646210671372,"mc":[{"id":"1.195453749","rc":[{"atl":[[30,3.45]],"id":522749},{"atb":[[29,0]],"id":522742}],"con":true,"img":false}]}
{"op":"mcm","clk":"5347928113","pt":1646210671577,"mc":[{"id":"1.195453749","rc":[{"atl":[[19.5,4.96],[21,30.09],[23,9.92]],"id":522749}],"con":true,"img":false}]}
{"op":"mcm","clk":"5347928116","pt":1646210671680,"mc":[{"id":"1.195453749","rc":[{"atl":[[19,0],[22,0]],"id":522749}],"con":true,"img":false}]}
{"op":"mcm","clk":"5347928120","pt":1646210671784,"mc":[{"id":"1.195453749","rc":[{"atb":[[19.5,8.58]],"id":3805747},{"atb":[[85,9.92],[50,17.11]],"id":522746}],"con":true,"img":false}]}
{"op":"mcm","clk":"5347928136","pt":1646210672093,"mc":[{"id":"1.195453749","rc":[{"atb":[[110,6.41]],"id":522746},{"atl":[[21,7.94]],"id":522749}],"con":true,"img":false}]}
{"op":"mcm","clk":"5347928144","pt":1646210672251,"mc":[{"id":"1.195453749","rc":[{"atb":[[25,6.61]],"id":522742}],"con":true,"img":false}]}
{"op":"mcm","clk":"5347928152","pt":1646210672457,"mc":[{"id":"1.195453749","rc":[{"atb":[[4.8,0]],"id":3805731}],"con":true,"img":false}]}
{"op":"mcm","clk":"5347928171","pt":1646210672971,"mc":[{"id":"1.195453749","rc":[{"atb":[[4.3,0],[4.2,68.66]],"id":3805731}],"con":true,"img":false}]}
{"op":"mcm","clk":"5347928182","pt":1646210673285,"mc":[{"id":"1.195453749","rc":[{"atb":[[4.3,48.11]],"id":3805731}],"con":true,"img":false}]}
{"op":"mcm","clk":"5347928200","pt":1646210673700,"mc":[{"id":"1.195453749","rc":[{"atb":[[28,10.84]],"id":522742}],"con":true,"img":false}]}
{"op":"mcm","clk":"5347928230","pt":1646210674501,"mc":[{"id":"1.195453749","rc":[{"atb":[[2.86,73.05]],"id":3805784},{"atb":[[25,0],[28,4.96]],"id":522742}],"con":true,"img":false}]}
{"op":"mcm","clk":"5347928237","pt":1646210674659,"mc":[{"id":"1.195453749","rc":[{"atb":[[2.96,36.42]],"id":3805784}],"con":true,"img":false}]}
{"op":"mcm","clk":"5347928262","pt":1646210675284,"mc":[{"id":"1.195453749","rc":[{"atb":[[2.88,8.23]],"id":3805784},{"atb":[[25,6.61]],"id":522742}],"con":true,"img":false}]}
{"op":"mcm","clk":"5347928269","pt":1646210675491,"mc":[{"id":"1.195453749","rc":[{"atb":[[2.98,2.72]],"id":3805784}],"con":true,"img":false}]}
{"op":"mcm","clk":"5347928291","pt":1646210675962,"mc":[{"id":"1.195453749","rc":[{"atb":[[2.88,77.22]],"id":3805784}],"con":true,"img":false}]}
{"op":"mcm","clk":"5347928293","pt":1646210676066,"mc":[{"id":"1.195453749","rc":[{"atb":[[2.86,0],[2.98,38.55]],"id":3805784}],"con":true,"img":false}]}
{"op":"mcm","clk":"5347928327","pt":1646210676888,"mc":[{"id":"1.195453749","rc":[{"atb":[[2.96,0]],"id":3805784},{"atl":[[320,5.76],[800,2]],"id":522747}],"con":true,"img":false}]}
{"op":"mcm","clk":"5347928343","pt":1646210677294,"mc":[{"id":"1.195453749","rc":[{"atl":[[860,2]],"id":522747}],"con":true,"img":false}]}
{"op":"mcm","clk":"5347928347","pt":1646210677403,"mc":[{"id":"1.195453749","rc":[{"atl":[[800,0]],"id":522747}],"con":true,"img":false}]}
{"op":"mcm","clk":"5347928365","pt":1646210677715,"mc":[{"id":"1.195453749","rc":[{"atb":[[19,30.08]],"id":3805747}],"con":true,"img":false}]}
{"op":"mcm","clk":"5347928369","pt":1646210677810,"mc":[{"id":"1.195453749","rc":[{"atb":[[15,0]],"id":3805747},{"atl":[[320,0]],"id":522747}],"con":true,"img":false}]}
{"op":"mcm","clk":"5347928414","pt":1646210678688,"mc":[{"id":"1.195453749","rc":[{"atb":[[22,12.52]],"id":3805747}],"con":true,"img":false}]}
{"op":"mcm","clk":"5347928455","pt":1646210679413,"mc":[{"id":"1.195453749","rc":[{"atl":[[660,2.7],[730,2]],"id":522746}],"con":true,"img":false}]}
{"op":"mcm","clk":"5347928464","pt":1646210679672,"mc":[{"id":"1.195453749","rc":[{"atb":[[19.5,0]],"id":3805747},{"atl":[[7.2,0],[6.4,29.4],[6.2,4.96],[7,9.92]],"id":3805731},{"atb":[[4.3,62.9],[3.9,0]],"id":522745},{"atl":[[7.4,9.92],[6.8,27.37],[7.6,0],[6.6,4.96]],"id":522745}],"con":true,"img":false}]}
{"op":"mcm","clk":"5347928476","pt":1646210680078,"mc":[{"id":"1.195453749","rc":[{"atl":[[7.4,0],[6,31.75],[7,68.47]],"id":3805731},{"atl":[[6.4,29.4]],"id":522745}],"con":true,"img":false}]}
{"op":"mcm","clk":"5347928483","pt":1646210680181,"mc":[{"id":"1.195453749","rc":[{"atl":[[7.4,65.45],[7.8,0]],"id":522745}],"con":true,"img":false}]}
{"op":"mcm","clk":"5347928498","pt":1646210680493,"mc":[{"id":"1.195453749","rc":[{"atb":[[3.85,3.27],[4.2,12.65]],"id":522745}],"con":true,"img":false}]}
{"op":"mcm","clk":"5347928518","pt":1646210680812,"mc":[{"id":"1.195453749","rc":[{"atl":[[65,9.92],[75,18.42],[48,8.34],[55,0]],"id":3805747},{"atb":[[9.6,9.92],[10.5,0],[11,23.56],[9.4,3.27]],"id":522749},{"atl":[[75,0],[55,0]],"id":522752},{"atl":[[140,12.06],[90,4.96],[100,0],[120,9.92]],"id":522742}],"con":true,"img":false}]}
{"op":"mcm","clk":"5347928521","pt":1646210680910,"mc":[{"id":"1.195453749","rc":[{"atl":[[6.4,0]],"id":3805731},{"atl":[[46,4.96],[60,9.92]],"id":522752},{"atl":[[6.8,0]],"id":522745}],"con":true,"img":false}]}
{"op":"mcm","clk":"5347928531","pt":1646210681276,"mc":[{"id":"1.195453749","rc":[{"atb":[[9.6,39.45],[10,0]],"id":522749},{"atl":[[130,16.29]],"id":522752},{"atl":[[140,0],[85,1.88],[120,25.4]],"id":522742}],"con":true,"img":false}]}
{"op":"mcm","clk":"5347928535","pt":1646210681379,"mc":[{"id":"1.195453749","rc":[{"atl":[[65,0]],"id":522752}],"con":true,"img":false}]}
{"op":"mcm","clk":"5347928541","pt":1646210681489,"mc":[{"id":"1.195453749","rc":[{"atb":[[2.8,148.58],[2.88,8.23]],"id":3805784}],"con":true,"img":false}]}
{"op":"mcm","clk":"5347928562","pt":1646210682120,"mc":[{"id":"1.195453749","rc":[{"atl":[[95,0]],"id":522742}],"con":true,"img":false}]}
{"op":"mcm","clk":"5347928565","pt":1646210682207,"mc":[{"id":"1.195453749","rc":[{"atl":[[860,0],[940,2]],"id":522747},{"atl":[[130,2]],"id":522752}],"con":true,"img":false}]}
{"op":"mcm","clk":"5347928581","pt":1646210682780,"mc":[{"id":"1.195453749","rc":[{"atl":[[23,36.51]],"id":522749}],"con":true,"img":false}]}
{"op":"mcm","clk":"5347928595","pt":1646210683094,"mc":[{"id":"1.195453749","rc":[{"atl":[[19.5,13.54]],"id":522749}],"con":true,"img":false}]}
{"op":"mcm","clk":"5347928599","pt":1646210683199,"mc":[{"id":"1.195453749","rc":[{"atb":[[19,9.92],[14.5,36.13]],"id":3805747}],"con":true,"img":false}]}
{"op":"mcm","clk":"5347928630","pt":1646210683815,"mc":[{"id":"1.195453749","rc":[{"atl":[[21,0]],"id":522749},{"atb":[[28,10.84]],"id":522742}],"con":true,"img":false}]}
{"op":"mcm","clk":"5347928634","pt":1646210683919,"mc":[{"id":"1.195453749","rc":[{"atb":[[23,26.15],[24,9.92],[27,0],[28,10.84]],"id":3805762},{"atb":[[36,14.76],[40,9.92],[44,0],[48,4.96]],"id":522743}],"con":true,"img":false}]}
{"op":"mcm","clk":"5347928659","pt":1646210684389,"mc":[{"id":"1.195453749","rc":[{"atb":[[36,0],[40,24.68],[48,8.34]],"id":522743}],"con":true,"img":false}]}
{"op":"mcm","clk":"5347928668","pt":1646210684606,"mc":[{"id":"1.195453749","rc":[{"atl":[[660,4.7],[730,0]],"id":522746},{"atb":[[25,0],[28,4.96]],"id":522742}],"con":true,"img":false}]}
{"op":"mcm","clk":"5347928674","pt":1646210684804,"mc":[{"id":"1.195453749","rc":[{"atb":[[4.4,51.66]],"id":3805731}],"con":true,"img":false}]}
{"op":"mcm","clk":"5347928687","pt":1646210685018,"mc":[{"id":"1.195453749","rc":[{"atb":[[19.5,17.49]],"id":522742}],"con":true,"img":false}]}
{"op":"mcm","clk":"5347928694","pt":1646210685122,"mc":[{"id":"1.195453749","rc":[{"atl":[[19.5,8.58],[19,4.96],[22,9.92],[23,26.58]],"id":522749},{"atb":[[24,9.92]],"id":522742}],"con":true,"img":false}]}
{"op":"mcm","clk":"5347928699","pt":1646210685220,"mc":[{"id":"1.195453749","rc":[{"atb":[[46,0]],"id":522743}],"con":true,"img":false}]}
{"op":"mcm","clk":"5347928709","pt":1646210685377,"mc":[{"id":"1.195453749","rc":[{"atb":[[25,6.61]],"id":522742}],"con":true,"img":false}]}
{"op":"mcm","clk":"5347928717","pt":1646210685481,"mc":[{"id":"1.195453749","rc":[{"atb":[[4.3,0]],"id":3805731}],"con":true,"img":false}]}
{"op":"mcm","clk":"5347928745","pt":1646210685892,"mc":[{"id":"1.195453749","rc":[{"atb":[[3.85,127.46],[4.2,2.72]],"id":3805731}],"con":true,"img":false}]}
{"op":"mcm","clk":"5347928758","pt":1646210686201,"mc":[{"id":"1.195453749","rc":[{"atl":[[19,0],[19.5,13.54],[22,0],[23,36.51]],"id":522749}],"con":true,"img":false}]}
{"op":"mcm","clk":"5347928762","pt":1646210686303,"mc":[{"id":"1.195453749","rc":[{"atb":[[48,4.96]],"id":522743}],"con":true,"img":false}]}
{"op":"mcm","clk":"5347928769","pt":1646210686413,"mc":[{"id":"1.195453749","rc":[{"atb":[[38,9.92],[40,14.76],[46,4.96],[48,0]],"id":522743}],"con":true,"img":false}]}
{"op":"mcm","clk":"5347928779","pt":1646210686718,"mc":[{"id":"1.195453749","rc":[{"atb":[[28,10.84]],"id":522742}],"con":true,"img":false}]}
{"op":"mcm","clk":"5347928787","pt":1646210686925,"mc":[{"id":"1.195453749","rc":[{"atb":[[9.6,9.92],[9.4,58.52]],"id":522749}],"con":true,"img":false}]}
{"op":"mcm","clk":"5347928796","pt":1646210687080,"mc":[{"id":"1.195453749","rc":[{"atb":[[42,3.87]],"id":522743}],"con":true,"img":false}]}
{"op":"mcm","clk":"5347928810","pt":1646210687394,"mc":[{"id":"1.195453749","rc":[{"atb":[[25,0],[28,4.96]],"id":522742},{"atl":[[18.5,4.96],[20,0],[21,9.92],[24,0]],"id":3805740}],"con":true,"img":false}]}
{"op":"mcm","clk":"5347928816","pt":1646210687489,"mc":[{"id":"1.195453749","rc":[{"atb":[[20,9.92],[24,4.96]],"id":522752}],"con":true,"img":false}]}
{"op":"mcm","clk":"5347928820","pt":1646210687589,"mc":[{"id":"1.195453749","rc":[{"atb":[[19,0],[22,7.56]],"id":522752}],"con":true,"img":false}]}
{"op":"mcm","clk":"5347928830","pt":1646210687800,"mc":[{"id":"1.195453749","rc":[{"atl":[[18,9.33],[22,33.58],[23,0]],"id":3805740}],"con":true,"img":false}]}
{"op":"mcm","clk":"5347928833","pt":1646210687897,"mc":[{"id":"1.195453749","rc":[{"atb":[[20,32.07],[14.5,0]],"id":522752}],"con":true,"img":false}]}
{"op":"mcm","clk":"5347928851","pt":1646210688213,"mc":[{"id":"1.195453749","rc":[{"atl":[[30,58.69]],"id":522749},{"atb":[[20,8.35]],"id":522742}],"con":true,"img":false}]}
{"op":"mcm","clk":"5347928856","pt":1646210688318,"mc":[{"id":"1.195453749","rc":[{"atl":[[23,9.92]],"id":522749},{"atb":[[19.5,9.92],[20,22.15],[23,4.96],[24,0]],"id":522752}],"con":true,"img":false}]}
{"op":"mcm","clk":"5347928863","pt":1646210688522,"mc":[{"id":"1.195453749","rc":[{"atl":[[18,0],[22,26.02]],"id":3805740}],"con":true,"img":false}]}
{"op":"mcm","clk":"5347928888","pt":1646210688927,"mc":[{"id":"1.195453749","rc":[{"atb":[[23,12.17]],"id":522752}],"con":true,"img":false}]}
{"op":"mcm","clk":"5347928914","pt":1646210689399,"mc":[{"id":"1.195453749","rc":[{"atl":[[21,17.86]],"id":3805740}],"con":true,"img":false}]}
{"op":"mcm","clk":"5347928927","pt":1646210689708,"mc":[{"id":"1.195453749","rc":[{"atb":[[22,0]],"id":522752}],"con":true,"img":false}]}
{"op":"mcm","clk":"5347928932","pt":1646210689913,"mc":[{"id":"1.195453749","rc":[{"atb":[[2.88,4.96],[2.98,35.82]],"id":3805784},{"atb":[[65,0],[46,0]],"id":522747},{"atb":[[3.85,124.18],[4.2,0]],"id":3805731}],"con":true,"img":false}]}
{"op":"mcm","clk":"5347928957","pt":1646210690637,"mc":[{"id":"1.195453749","rc":[{"atb":[[2.86,3.27],[2.96,2.72]],"id":3805784},{"atb":[[4.1,2.72],[3.8,3.27]],"id":3805731}],"con":true,"img":false}]}
{"op":"mcm","clk":"5347928967","pt":1646210690788,"mc":[{"id":"1.195453749","rc":[{"atb":[[70,2.72],[48,3.27]],"id":522747}],"con":true,"img":false}]}
{"op":"mcm","clk":"5347928981","pt":1646210691100,"mc":[{"id":"1.195453749","rc":[{"atb":[[2.8,9.92],[2.88,73.05]],"id":3805784}],"con":true,"img":false}]}
{"op":"mcm","clk":"5347929002","pt":1646210691718,"mc":[{"id":"1.195453749","rc":[{"atl":[[4.5,9.92],[4.6,0],[4.1,4.96],[4.2,49.62]],"id":3805784},{"atb":[[25,9.92],[29,4.96]],"id":522742},{"atl":[[18.5,0],[21,7.94]],"id":3805740}],"con":true,"img":false}]}
{"op":"mcm","clk":"5347929006","pt":1646210691819,"mc":[{"id":"1.195453749","rc":[{"atb":[[24,0],[28,0]],"id":522742},{"atl":[[19,4.96],[22,35.94]],"id":3805740}],"con":true,"img":false}]}
{"op":"mcm","clk":"5347929019","pt":1646210692224,"mc":[{"id":"1.195453749","rc":[{"atl":[[7.2,16.13],[4.5,78.01],[4.1,56.18]],"id":3805784}],"con":true,"img":false}]}
{"op":"mcm","clk":"5347929039","pt":1646210692591,"mc":[{"id":"1.195453749","rc":[{"atl":[[60,39.45]],"id":522752}],"con":true,"img":false}]}
{"op":"mcm","clk":"5347929051","pt":1646210693001,"mc":[{"id":"1.195453749","rc":[{"atl":[[4.2,0]],"id":3805784}],"con":true,"img":false}]}
{"op":"mcm","clk":"5347929064","pt":1646210693416,"mc":[{"id":"1.195453749","rc":[{"atb":[[19.5,42.82],[20,0]],"id":522752}],"con":true,"img":false}]}
{"op":"mcm","clk":"5347929133","pt":1646210695030,"mc":[{"id":"1.195453749","rc":[{"atb":[[29,10.63]],"id":522742}],"con":true,"img":false}]}
{"op":"mcm","clk":"5347929141","pt":1646210695129,"mc":[{"id":"1.195453749","rc":[{"atl":[[4.6,9.92],[4.1,4.96],[4.2,4.96]],"id":3805784}],"con":true,"img":false}]}
{"op":"mcm","clk":"5347929148","pt":1646210695234,"mc":[{"id":"1.195453749","rc":[{"atl":[[4.5,68.09],[4.1,0]],"id":3805784},{"atb":[[24,9.92],[28,4.96]],"id":522742}],"con":true,"img":false}]}
{"op":"mcm","clk":"5347929153","pt":1646210695287,"mc":[{"id":"1.195453749","rc":[{"atb":[[19,0],[19.5,9.92],[22,7.56],[23,4.96]],"id":3805747},{"atb":[[25,0],[29,5.67]],"id":522742}],"con":true,"img":false}]}
{"op":"mcm","clk":"5347929180","pt":1646210695701,"mc":[{"id":"1.195453749","rc":[{"atb":[[48,3.37]],"id":522743}],"con":true,"img":false}]}
{"op":"mcm","clk":"5347929186","pt":1646210695803,"mc":[{"id":"1.195453749","rc":[{"atb":[[19.5,37.1],[14.5,2.72]],"id":3805747},{"atb":[[20,0]],"id":522742}],"con":true,"img":false}]}
{"op":"mcm","clk":"5347929192","pt":1646210695907,"mc":[{"id":"1.195453749","rc":[{"atl":[[4.5,113.46],[4.6,0],[4.2,0]],"id":3805784}],"con":true,"img":false}]}
{"op":"mcm","clk":"5347929197","pt":1646210696010,"mc":[{"id":"1.195453749","rc":[{"atl":[[4.5,123.38],[4.1,4.96]],"id":3805784},{"atb":[[19.5,27.18],[19,9.92],[22,12.52],[23,0]],"id":3805747},{"atb":[[24,0],[28,0]],"id":522742}],"con":true,"img":false}]}
{"op":"mcm","clk":"5347929203","pt":1646210696114,"mc":[{"id":"1.195453749","rc":[{"atb":[[42,17.03]],"id":522743}],"con":true,"img":false}]}
{"op":"mcm","clk":"5347929208","pt":1646210696217,"mc":[{"id":"1.195453749","rc":[{"atb":[[85,3.17],[60,0]],"id":522750},{"atb":[[16,0],[18.5,0]],"id":522753},{"atb":[[40,0]],"id":522743}],"con":true,"img":false}]}
{"op":"mcm","clk":"5347929212","pt":1646210696322,"mc":[{"id":"1.195453749","rc":[{"atb":[[19.5,2.72],[24,15.82]],"id":522742}],"con":true,"img":false}]}
{"op":"mcm","clk":"5347929215","pt":1646210696426,"mc":[{"id":"1.195453749","rc":[{"atb":[[11.5,0],[14,0]],"id":522752}],"con":true,"img":false}]}
{"op":"mcm","clk":"5347929221","pt":1646210696529,"mc":[{"id":"1.195453749","rc":[{"atb":[[19.5,0]],"id":3805747},{"atb":[[42,13.16]],"id":522743}],"con":true,"img":false}]}
{"op":"mcm","clk":"5347929233","pt":1646210696790,"mc":[{"id":"1.195453749","rc":[{"atb":[[28,4.96]],"id":522753},{"atb":[[25,9.92],[29,10.63]],"id":522742}],"con":true,"img":false}]}
{"op":"mcm","clk":"5347929236","pt":1646210696891,"mc":[{"id":"1.195453749","rc":[{"atb":[[95,2.72]],"id":522750},{"atb":[[16.5,3.27],[19,2.72]],"id":522753}],"con":true,"img":false}]}
{"op":"mcm","clk":"5347929242","pt":1646210696996,"mc":[{"id":"1.195453749","rc":[{"atb":[[70,3.27]],"id":522750}],"con":true,"img":false}]}
{"op":"mcm","clk":"5347929254","pt":1646210697200,"mc":[{"id":"1.195453749","rc":[{"atb":[[12,3.27],[14.5,2.72]],"id":522752}],"con":true,"img":false}]}
{"op":"mcm","clk":"5347929269","pt":1646210697511,"mc":[{"id":"1.195453749","rc":[{"atb":[[25,6.61]],"id":522753}],"con":true,"img":false}]}
{"op":"mcm","clk":"5347929276","pt":1646210697615,"mc":[{"id":"1.195453749","rc":[{"atl":[[7.2,93.46],[4.5,55.29]],"id":3805784}],"con":true,"img":false}]}
{"op":"mcm","clk":"5347929293","pt":1646210698030,"mc":[{"id":"1.195453749","rc":[{"atb":[[23,0],[24,27.16]],"id":522753}],"con":true,"img":false}]}
{"op":"mcm","clk":"5347929325","pt":1646210698807,"mc":[{"id":"1.195453749","rc":[{"atb":[[19.5,9.92],[14.5,28.24]],"id":522752}],"con":true,"img":false}]}
{"op":"mcm","clk":"5347929424","pt":1646210701514,"mc":[{"id":"1.195453749","rc":[{"atb":[[40,3.42],[50,14.38]],"id":522746},{"atl":[[300,0.52],[320,4.96]],"id":522747},{"atb":[[11,20.84],[9.4,55.24]],"id":522749},{"atb":[[19.5,0],[19,9.92],[22,4.96],[23,0]],"id":522752},{"atb":[[16.5,0],[19,0]],"id":522753},{"atb":[[24,25.74],[25,0],[28,4.96],[29,0]],"id":522742},{"atb":[[20,0],[25,0]],"id":522743}],"con":true,"img":false}]}
{"op":"mcm","clk":"5347929430","pt":1646210701613,"mc":[{"id":"1.195453749","rc":[{"atl":[[18.5,4.96],[19.5,8.58],[21,9.92],[23,0]],"id":522749},{"atb":[[2.6,166.75],[2.7,58.82]],"id":3805731}],"con":true,"img":false}]}
{"op":"mcm","clk":"5347929448","pt":1646210702033,"mc":[{"id":"1.195453749","rc":[{"atl":[[940,4.03]],"id":522747},{"atl":[[21,39.45],[30,3.45]],"id":522749},{"atb":[[19.5,17.49],[24,9.92]],"id":522742}],"con":true,"img":false}]}
{"op":"mcm","clk":"5347929453","pt":1646210702240,"mc":[{"id":"1.195453749","rc":[{"atb":[[42,3.27],[55,2.72]],"id":522746},{"atb":[[9.6,13.19],[11.5,2.72]],"id":522749},{"atb":[[19,0],[22,0]],"id":522752},{"atb":[[17,3.27],[19.5,2.72]],"id":522753},{"atb":[[24,0],[28,0]],"id":522742}],"con":true,"img":false}]}
{"op":"mcm","clk":"5347929454","pt":1646210702342,"mc":[{"id":"1.195453749","rc":[{"atl":[[18.5,14.03]],"id":522749},{"atb":[[19.5,8.58]],"id":522752},{"atb":[[25,6.61]],"id":522742},{"atb":[[21,3.27],[26,2.72]],"id":522743}],"con":true,"img":false}]}
{"op":"mcm","clk":"5347929456","pt":1646210702446,"mc":[{"id":"1.195453749","rc":[{"atb":[[13,0],[13.5,8]],"id":522752}],"con":true,"img":false}]}
{"op":"mcm","clk":"5347929466","pt":1646210702707,"mc":[{"id":"1.195453749","rc":[{"atb":[[50,0]],"id":522746},{"atb":[[9.6,45.62],[11.5,17.85],[9.4,0]],"id":522749}],"con":true,"img":false}]}
{"op":"mcm","clk":"5347929472","pt":1646210702812,"mc":[{"id":"1.195453749","rc":[{"atb":[[55,17.11]],"id":522746}],"con":true,"img":false}]}
{"op":"mcm","clk":"5347929478","pt":1646210702915,"mc":[{"id":"1.195453749","rc":[{"atb":[[19.5,18.5],[23,4.96]],"id":522752},{"atb":[[25,16.53],[29,4.96]],"id":522742}],"con":true,"img":false}]}
{"op":"mcm","clk":"5347929484","pt":1646210703017,"mc":[{"id":"1.195453749","rc":[{"atl":[[19.5,0]],"id":522749}],"con":true,"img":false}]}
{"op":"mcm","clk":"5347929498","pt":1646210703327,"mc":[{"id":"1.195453749","rc":[{"atl":[[4.1,56.18]],"id":3805784}],"con":true,"img":false}]}
{"op":"mcm","clk":"5347929508","pt":1646210703534,"mc":[{"id":"1.195453749","rc":[{"atb":[[11,4.96]],"id":522749}],"con":true,"img":false}]}
{"op":"mcm","clk":"5347929512","pt":1646210703637,"mc":[{"id":"1.195453749","rc":[{"atb":[[24,17.23],[25,16.53],[28,0],[29,4.96]],"id":522753}],"con":true,"img":false}]}
{"op":"mcm","clk":"5347929525","pt":1646210703947,"mc":[{"id":"1.195453749","rc":[{"atb":[[19.5,8.58],[19,9.92],[22,4.96],[23,0]],"id":522752}],"con":true,"img":false}]}
{"op":"mcm","clk":"5347929542","pt":1646210704104,"mc":[{"id":"1.195453749","rc":[{"atl":[[4.5,9.92]],"id":3805784}],"con":true,"img":false}]}
{"op":"mcm","clk":"5347929551","pt":1646210704417,"mc":[{"id":"1.195453749","rc":[{"atl":[[18.5,0],[19,4.96],[21,29.53],[22,9.92]],"id":522749},{"atb":[[24,9.92],[25,6.61],[28,4.96],[29,0]],"id":522742}],"con":true,"img":false}]}
{"op":"mcm","clk":"5347929560","pt":1646210704631,"mc":[{"id":"1.195453749","rc":[{"atb":[[19.5,18.5],[19,30.08],[23,4.96],[14.5,2.72]],"id":522752}],"con":true,"img":false}]}
{"op":"mcm","clk":"5347929563","pt":1646210704722,"mc":[{"id":"1.195453749","rc":[{"atb":[[19,20.15],[22,0]],"id":522752}],"con":true,"img":false}]}
{"op":"mcm","clk":"5347929579","pt":1646210705240,"mc":[{"id":"1.195453749","rc":[{"atl":[[20,8.35]],"id":522749},{"atb":[[24,0],[28,0]],"id":522742}],"con":true,"img":false}]}
{"op":"mcm","clk":"5347929584","pt":1646210705346,"mc":[{"id":"1.195453749","rc":[{"atb":[[9.6,35.69],[10.5,4.96],[11,0],[9.4,9.92]],"id":522749}],"con":true,"img":false}]}
{"op":"mcm","clk":"5347929593","pt":1646210705504,"mc":[{"id":"1.195453749","rc":[{"atb":[[19.5,8.58],[19,30.08],[22,4.96],[23,0]],"id":522752}],"con":true,"img":false}]}
{"op":"mcm","clk":"5347929609","pt":1646210706023,"mc":[{"id":"1.195453749","rc":[{"atb":[[17.5,9.62],[25,16.53],[29,4.96]],"id":522742}],"con":true,"img":false}]}
{"op":"mcm","clk":"5347929615","pt":1646210706127,"mc":[{"id":"1.195453749","rc":[{"atl":[[18.5,4.96],[19,0],[21,39.45],[22,0]],"id":522749}],"con":true,"img":false}]}
{"op":"mcm","clk":"5347929624","pt":1646210706441,"mc":[{"id":"1.195453749","rc":[{"atl":[[260,0],[240,4.96]],"id":522746}],"con":true,"img":false}]}
{"op":"mcm","clk":"5347929640","pt":1646210706849,"mc":[{"id":"1.195453749","rc":[{"atb":[[14.5,32.26]],"id":3805747},{"atb":[[17.5,0]],"id":522742}],"con":true,"img":false}]}
{"op":"mcm","clk":"5347929670","pt":1646210707521,"mc":[{"id":"1.195453749","rc":[{"atb":[[24,9.92],[25,6.61],[28,4.96],[29,0]],"id":522742}],"con":true,"img":false}]}
{"op":"mcm","clk":"5347929691","pt":1646210707933,"mc":[{"id":"1.195453749","rc":[{"atb":[[19.5,2.72],[24,27.16]],"id":522742}],"con":true,"img":false}]}
{"op":"mcm","clk":"5347929713","pt":1646210708449,"mc":[{"id":"1.195453749","rc":[{"atb":[[29,10.63]],"id":522753}],"con":true,"img":false}]}
{"op":"mcm","clk":"5347929747","pt":1646210709229,"mc":[{"id":"1.195453749","rc":[{"atb":[[25,9.92]],"id":522753}],"con":true,"img":false}]}
{"op":"mcm","clk":"5347929759","pt":1646210709531,"mc":[{"id":"1.195453749","rc":[{"atl":[[18.5,0],[19,4.96],[21,29.53],[22,9.92]],"id":522749}],"con":true,"img":false}]}
{"op":"mcm","clk":"5347929835","pt":1646210711241,"mc":[{"id":"1.195453749","rc":[{"atb":[[2.8,0],[2.88,68.09],[2.9,4.96]],"id":3805784}],"con":true,"img":false}]}
{"op":"mcm","clk":"5347929838","pt":1646210711338,"mc":[{"id":"1.195453749","rc":[{"atb":[[18.5,9.92],[19,0],[21,4.96],[22,0]],"id":3805747}],"con":true,"img":false}]}
{"op":"mcm","clk":"5347929856","pt":1646210711750,"mc":[{"id":"1.195453749","rc":[{"atb":[[2.88,0],[2.9,73.05]],"id":3805784}],"con":true,"img":false}]}
{"op":"mcm","clk":"5347929876","pt":1646210712115,"mc":[{"id":"1.195453749","rc":[{"atb":[[19,8.82]],"id":3805747}],"con":true,"img":false}]}
{"op":"mcm","clk":"5347929883","pt":1646210712217,"mc":[{"id":"1.195453749","rc":[{"atb":[[18.5,9.92],[19,20.15],[21,4.96],[22,0]],"id":522752},{"atb":[[23,9.92],[24,17.23],[27,4.96],[28,0]],"id":522742}],"con":true,"img":false}]}
{"op":"mcm","clk":"5347929920","pt":1646210713244,"mc":[{"id":"1.195453749","rc":[{"atb":[[26,6.35]],"id":522742}],"con":true,"img":false}]}
{"op":"mcm","clk":"5347929939","pt":1646210713813,"mc":[{"id":"1.195453749","rc":[{"atb":[[24,0],[25,23.45]],"id":522742}],"con":true,"img":false}]}
{"op":"mcm","clk":"5347929943","pt":1646210713923,"mc":[{"id":"1.195453749","rc":[{"atb":[[25,16.83]],"id":522742}],"con":true,"img":false}]}
{"op":"mcm","clk":"5347930037","pt":1646210715571,"mc":[{"id":"1.195453749","rc":[{"atb":[[95,0]],"id":522750},{"atb":[[16.5,0],[19,0]],"id":3805762},{"atb":[[17,0],[19.5,0]],"id":522753},{"atb":[[21,0],[26,0]],"id":522743}],"con":true,"img":false}]}
{"op":"mcm","clk":"5347930069","pt":1646210716144,"mc":[{"id":"1.195453749","rc":[{"atb":[[28,4.96]],"id":3805762}],"con":true,"img":false}]}
{"op":"mcm","clk":"5347930073","pt":1646210716244,"mc":[{"id":"1.195453749","rc":[{"atb":[[110,2.72]],"id":522750},{"atb":[[18,3.27],[21,2.72]],"id":3805762},{"atb":[[18,3.27],[21,2.72]],"id":522753},{"atb":[[23,3.27],[28,2.72]],"id":522743}],"con":true,"img":false}]}
{"op":"mcm","clk":"5347930084","pt":1646210716452,"mc":[{"id":"1.195453749","rc":[{"atl":[[19,0],[19.5,4.96],[22,26.02],[23,9.92]],"id":3805740}],"con":true,"img":false}]}
{"op":"mcm","clk":"5347930110","pt":1646210716923,"mc":[{"id":"1.195453749","rc":[{"atb":[[25,6.61]],"id":3805762},{"atb":[[27,11.06]],"id":522742},{"atl":[[19.5,13.54]],"id":3805740}],"con":true,"img":false}]}
{"op":"mcm","clk":"5347930112","pt":1646210717025,"mc":[{"id":"1.195453749","rc":[{"atl":[[19,0],[19.5,4.96],[22,0]],"id":522749}],"con":true,"img":false}]}
{"op":"mcm","clk":"5347930124","pt":1646210717334,"mc":[{"id":"1.195453749","rc":[{"atb":[[23,0],[24,36.08]],"id":3805762}],"con":true,"img":false}]}
{"op":"mcm","clk":"5347930127","pt":1646210717437,"mc":[{"id":"1.195453749","rc":[{"atl":[[19.5,13.54]],"id":522749}],"con":true,"img":false}]}
{"op":"mcm","clk":"5347930135","pt":1646210717640,"mc":[{"id":"1.195453749","rc":[{"atb":[[18.5,37.82],[14.5,2.72]],"id":3805747}],"con":true,"img":false}]}
{"op":"mcm","clk":"5347930137","pt":1646210717743,"mc":[{"id":"1.195453749","rc":[{"atb":[[26,0]],"id":522742},{"atl":[[21,0]],"id":3805740}],"con":true,"img":false}]}
{"op":"mcm","clk":"5347930154","pt":1646210718255,"mc":[{"id":"1.195453749","rc":[{"atl":[[20,0]],"id":522749},{"atl":[[22,0]],"id":3805740}],"con":true,"img":false}]}
{"op":"mcm","clk":"5347930155","pt":1646210718357,"mc":[{"id":"1.195453749","rc":[{"atl":[[23,57.78]],"id":3805740}],"con":true,"img":false}]}
{"op":"mcm","clk":"5347930164","pt":1646210718822,"mc":[{"id":"1.195453749","rc":[{"atl":[[21,0],[30,50.18]],"id":522749}],"con":true,"img":false}]}
{"op":"mcm","clk":"5347930177","pt":1646210719138,"mc":[{"id":"1.195453749","rc":[{"atb":[[23,41.17],[25,0]],"id":522742}],"con":true,"img":false}]}
{"op":"mcm","clk":"5347930334","pt":1646210722755,"mc":[{"id":"1.195453749","rc":[{"atb":[[21,12.9]],"id":3805747}],"con":true,"img":false}]}
{"op":"mcm","clk":"5347930357","pt":1646210723166,"mc":[{"id":"1.195453749","rc":[{"atl":[[300,0]],"id":522747},{"atl":[[19.5,0],[20,4.96],[23,47.86],[24,9.92]],"id":3805740}],"con":true,"img":false}]}
{"op":"mcm","clk":"5347930369","pt":1646210723476,"mc":[{"id":"1.195453749","rc":[{"atb":[[19,0]],"id":3805747},{"atl":[[23,0],[50,41.61]],"id":3805740}],"con":true,"img":false}]}
{"op":"mcm","clk":"5347930379","pt":1646210723633,"mc":[{"id":"1.195453749","rc":[{"atl":[[940,2]],"id":522747}],"con":true,"img":false}]}
{"op":"mcm","clk":"5347930391","pt":1646210723839,"mc":[{"id":"1.195453749","rc":[{"atl":[[22,7.56]],"id":3805740}],"con":true,"img":false}]}
{"op":"mcm","clk":"5347930394","pt":1646210723942,"mc":[{"id":"1.195453749","rc":[{"atb":[[18.5,9.92],[14.5,36.7]],"id":3805747},{"atl":[[320,5.45]],"id":522747}],"con":true,"img":false}]}
{"op":"mcm","clk":"5347930409","pt":1646210724256,"mc":[{"id":"1.195453749","rc":[{"atb":[[19.5,26.59]],"id":522742}],"con":true,"img":false}]}
{"op":"mcm","clk":"5347930415","pt":1646210724356,"mc":[{"id":"1.195453749","rc":[{"atb":[[23,9.92]],"id":522742}],"con":true,"img":false}]}
{"op":"mcm","clk":"5347930533","pt":1646210727554,"mc":[{"id":"1.195453749","rc":[{"atb":[[28,10.84]],"id":3805762},{"atl":[[20,13.31]],"id":3805740}],"con":true,"img":false}]}
{"op":"mcm","clk":"5347930570","pt":1646210728376,"mc":[{"id":"1.195453749","rc":[{"atb":[[25,0],[28,4.96]],"id":3805762},{"atl":[[22,0]],"id":3805740}],"con":true,"img":false}]}
{"op":"mcm","clk":"5347930597","pt":1646210728855,"mc":[{"id":"1.195453749","rc":[{"atb":[[21,28.88],[24,9.92]],"id":3805762}],"con":true,"img":false}]}
{"op":"mcm","clk":"5347930609","pt":1646210729150,"mc":[{"id":"1.195453749","rc":[{"atb":[[25,6.61]],"id":3805762}],"con":true,"img":false}]}
{"op":"mcm","clk":"5347930622","pt":1646210729473,"mc":[{"id":"1.195453749","rc":[{"atl":[[21,53.14]],"id":522749}],"con":true,"img":false}]}
{"op":"mcm","clk":"5347930625","pt":1646210729577,"mc":[{"id":"1.195453749","rc":[{"atl":[[30,3.45]],"id":522749},{"atb":[[21,2.72]],"id":3805762}],"con":true,"img":false}]}
{"op":"mcm","clk":"5347930656","pt":1646210730150,"mc":[{"id":"1.195453749","rc":[{"atl":[[21,0]],"id":522749}],"con":true,"img":false}]}
{"op":"mcm","clk":"5347930667","pt":1646210730357,"mc":[{"id":"1.195453749","rc":[{"atl":[[340,5.86]],"id":522747}],"con":true,"img":false}]}
{"op":"mcm","clk":"5347930682","pt":1646210730667,"mc":[{"id":"1.195453749","rc":[{"atl":[[320,0.49],[330,4.96]],"id":522747}],"con":true,"img":false}]}
{"op":"mcm","clk":"5347930691","pt":1646210730878,"mc":[{"id":"1.195453749","rc":[{"atl":[[48,0]],"id":522753}],"con":true,"img":false}]}
{"op":"mcm","clk":"5347930704","pt":1646210731183,"mc":[{"id":"1.195453749","rc":[{"atl":[[340,0]],"id":522747}],"con":true,"img":false}]}
{"op":"mcm","clk":"5347930713","pt":1646210731366,"mc":[{"id":"1.195453749","rc":[{"atl":[[330,0],[340,4.96]],"id":522747},{"atl":[[140,16.28],[80,9.92]],"id":522753}],"con":true,"img":false}]}
{"op":"mcm","clk":"5347930721","pt":1646210731549,"mc":[{"id":"1.195453749","rc":[{"atl":[[75,2.14]],"id":522753}],"con":true,"img":false}]}
{"op":"mcm","clk":"5347930726","pt":1646210731813,"mc":[{"id":"1.195453749","rc":[{"atl":[[320,0]],"id":522747}],"con":true,"img":false}]}
{"op":"mcm","clk":"5347930745","pt":1646210732253,"mc":[{"id":"1.195453749","rc":[{"atl":[[340,0],[350,4.96]],"id":522747},{"atl":[[140,2]],"id":522753}],"con":true,"img":false}]}
{"op":"mcm","clk":"5347930765","pt":1646210732477,"mc":[{"id":"1.195453749","rc":[{"atl":[[340,0.46]],"id":522747}],"con":true,"img":false}]}
{"op":"mcm","clk":"5347930772","pt":1646210732675,"mc":[{"id":"1.195453749","rc":[{"atb":[[42,23.08],[50,4.96]],"id":522743}],"con":true,"img":false}]}
{"op":"mcm","clk":"5347930778","pt":1646210732782,"mc":[{"id":"1.195453749","rc":[{"atb":[[38,0],[46,0]],"id":522743}],"con":true,"img":false}]}
{"op":"mcm","clk":"5347930786","pt":1646210732984,"mc":[{"id":"1.195453749","rc":[{"atl":[[350,0],[360,4.96]],"id":522747}],"con":true,"img":false}]}
{"op":"mcm","clk":"5347930795","pt":1646210733241,"mc":[{"id":"1.195453749","rc":[{"atb":[[2.96,0]],"id":3805784},{"atb":[[42,9.92],[46,14.76],[55,2.94]],"id":522743}],"con":true,"img":false}]}
{"op":"mcm","clk":"5347930797","pt":1646210733344,"mc":[{"id":"1.195453749","rc":[{"atb":[[2.86,0]],"id":3805784},{"atl":[[340,0]],"id":522747}],"con":true,"img":false}]}
{"op":"mcm","clk":"5347930802","pt":1646210733450,"mc":[{"id":"1.195453749","rc":[{"atb":[[70,0]],"id":522747}],"con":true,"img":false}]}
{"op":"mcm","clk":"5347930806","pt":1646210733552,"mc":[{"id":"1.195453749","rc":[{"atb":[[48,0]],"id":522747}],"con":true,"img":false}]}
{"op":"mcm","clk":"5347930810","pt":1646210733654,"mc":[{"id":"1.195453749","rc":[{"atb":[[2.9,4.96],[2.86,136.95]],"id":3805784}],"con":true,"img":false}]}
{"op":"mcm","clk":"5347930813","pt":1646210733758,"mc":[{"id":"1.195453749","rc":[{"atl":[[340,4.96],[360,0]],"id":522747}],"con":true,"img":false}]}
{"op":"mcm","clk":"5347930816","pt":1646210733859,"mc":[{"id":"1.195453749","rc":[{"atl":[[19.5,8.58],[19,4.96],[22,9.92]],"id":522749}],"con":true,"img":false}]}
{"op":"mcm","clk":"5347930825","pt":1646210734065,"mc":[{"id":"1.195453749","rc":[{"atb":[[2.98,38.55]],"id":3805784},{"atl":[[360,0.44]],"id":522747},{"atb":[[48,0]],"id":522743}],"con":true,"img":false}]}
{"op":"mcm","clk":"5347930830","pt":1646210734168,"mc":[{"id":"1.195453749","rc":[{"atb":[[2.88,3.27]],"id":3805784},{"atb":[[80,2.72]],"id":522747}],"con":true,"img":false}]}
{"op":"mcm","clk":"5347930835","pt":1646210734273,"mc":[{"id":"1.195453749","rc":[{"atb":[[55,3.27]],"id":522747},{"atl":[[19,13.78]],"id":522749}],"con":true,"img":false}]}
{"op":"mcm","clk":"5347930863","pt":1646210735045,"mc":[{"id":"1.195453749","rc":[{"atl":[[19.5,0]],"id":522749}],"con":true,"img":false}]}
{"op":"mcm","clk":"5347930893","pt":1646210736082,"mc":[{"id":"1.195453749","rc":[{"atl":[[280,0],[340,2]],"id":522743}],"con":true,"img":false}]}
{"op":"mcm","clk":"5347930910","pt":1646210736390,"mc":[{"id":"1.195453749","rc":[{"atl":[[340,0],[360,5.4]],"id":522747},{"atl":[[19,0],[19.5,4.96],[22,0],[23,9.92]],"id":522749},{"atb":[[18.5,0],[19,30.08],[20,8.35],[21,0],[22,4.96]],"id":522752},{"atl":[[65,4.96],[80,0],[85,9.92],[60,0]],"id":522753},{"atl":[[150,0],[85,0],[110,0],[120,17.87]],"id":522743},{"atl":[[19.5,4.96],[20,8.35],[23,9.92],[24,0]],"id":3805740},{"atb":[[4.3,72.83],[4.6,0],[4.2,2.72],[4.7,47.87]],"id":522745}],"con":true,"img":false}]}
{"op":"mcm","clk":"5347930914","pt":1646210736493,"mc":[{"id":"1.195453749","rc":[{"atb":[[24,0],[25,16.53],[28,0],[29,4.96]],"id":3805762},{"atl":[[65,4.96],[80,0],[85,9.92],[60,2.69]],"id":3805762}],"con":true,"img":false}]}
{"op":"mcm","clk":"5347930933","pt":1646210736854,"mc":[{"id":"1.195453749","rc":[{"atl":[[150,2]],"id":3805762},{"atl":[[120,4.96]],"id":522743},{"atl":[[23,37.13],[50,2.04]],"id":3805740},{"atb":[[4.3,9.92],[4.2,117.78]],"id":522745}],"con":true,"img":false}]}
{"op":"mcm","clk":"5347930937","pt":1646210736957,"mc":[{"id":"1.195453749","rc":[{"atb":[[19.5,28.41],[19,9.92]],"id":522752},{"atl":[[85,24.68]],"id":3805762},{"atl":[[140,14.39]],"id":522743},{"atl":[[19.5,13.54]],"id":3805740}],"con":true,"img":false}]}
{"op":"mcm","clk":"5347930942","pt":1646210737061,"mc":[{"id":"1.195453749","rc":[{"atl":[[29,5.67]],"id":522749},{"atb":[[19.5,19.83],[19,0],[22,0]],"id":522752},{"atl":[[65,9.92],[46,0],[48,4.96],[60,29.53]],"id":522752},{"atl":[[160,9.92],[120,6.29]],"id":522743}],"con":true,"img":false}]}
{"op":"mcm","clk":"5347930982","pt":1646210737880,"mc":[{"id":"1.195453749","rc":[{"atb":[[18.5,9.92],[21,4.96]],"id":522752},{"atb":[[29,10.63]],"id":3805762},{"atl":[[20,0]],"id":3805740}],"con":true,"img":false}]}
{"op":"mcm","clk":"5347931023","pt":1646210738768,"mc":[{"id":"1.195453749","rc":[{"atb":[[25,9.92]],"id":3805762}],"con":true,"img":false}]}
{"op":"mcm","clk":"5347931041","pt":1646210739070,"mc":[{"id":"1.195453749","rc":[{"atb":[[70,0]],"id":522750}],"con":true,"img":false}]}
{"op":"mcm","clk":"5347931054","pt":1646210739273,"mc":[{"id":"1.195453749","rc":[{"atb":[[21,24.87]],"id":3805762}],"con":true,"img":false}]}
{"op":"mcm","clk":"5347931084","pt":1646210739886,"mc":[{"id":"1.195453749","rc":[{"atl":[[29,28.88]],"id":522749}],"con":true,"img":false}]}
{"op":"mcm","clk":"5347931092","pt":1646210740094,"mc":[{"id":"1.195453749","rc":[{"atb":[[22,9.92],[23,0],[26,4.96],[27,0]],"id":522742}],"con":true,"img":false}]}
{"op":"mcm","clk":"5347931108","pt":1646210740504,"mc":[{"id":"1.195453749","rc":[{"atl":[[4.5,0],[4.6,9.92],[4.1,0],[4.2,4.96]],"id":3805784}],"con":true,"img":false}]}
{"op":"mcm","clk":"5347931119","pt":1646210740661,"mc":[{"id":"1.195453749","rc":[{"atl":[[380,5.32]],"id":522747}],"con":true,"img":false}]}
{"op":"mcm","clk":"5347931124","pt":1646210740763,"mc":[{"id":"1.195453749","rc":[{"atb":[[20,8.35]],"id":522742}],"con":true,"img":false}]}
{"op":"mcm","clk":"5347931142","pt":1646210741275,"mc":[{"id":"1.195453749","rc":[{"atl":[[4.5,9.92],[4.6,0],[4.1,4.96],[7,12.26],[4.2,0]],"id":3805784},{"atb":[[19.5,2.72],[20,28.18]],"id":522742}],"con":true,"img":false}]}
{"op":"mcm","clk":"5347931149","pt":1646210741688,"mc":[{"id":"1.195453749","rc":[{"atl":[[7.2,16.13]],"id":3805784},{"atl":[[85,33.81]],"id":522753}],"con":true,"img":false}]}
{"op":"mcm","clk":"5347931154","pt":1646210741792,"mc":[{"id":"1.195453749","rc":[{"atl":[[7,34.41]],"id":3805784}],"con":true,"img":false}]}
{"op":"mcm","clk":"5347931159","pt":1646210741896,"mc":[{"id":"1.195453749","rc":[{"atl":[[23,9.92],[50,42.66]],"id":3805740}],"con":true,"img":false}]}
{"op":"mcm","clk":"5347931168","pt":1646210742100,"mc":[{"id":"1.195453749","rc":[{"atl":[[660,2.7],[500,2]],"id":522746},{"atb":[[23,9.92],[27,4.96]],"id":522742},{"atl":[[300,0],[240,2]],"id":522742},{"atl":[[140,0],[160,22.61]],"id":522743}],"con":true,"img":false}]}
{"op":"mcm","clk":"5347931171","pt":1646210742202,"mc":[{"id":"1.195453749","rc":[{"atl":[[65,7.44]],"id":522753},{"atb":[[22,0],[26,0]],"id":522742}],"con":true,"img":false}]}
{"op":"mcm","clk":"5347931176","pt":1646210742404,"mc":[{"id":"1.195453749","rc":[{"atl":[[65,0],[42,4.96],[48,3.37],[50,9.92]],"id":3805747},{"atl":[[65,0],[42,4.96],[48,0],[50,9.92]],"id":522752},{"atl":[[150,9.92],[160,12.69],[110,4.96],[120,1.33]],"id":522743}],"con":true,"img":false}]}
{"op":"mcm","clk":"5347931190","pt":1646210742668,"mc":[{"id":"1.195453749","rc":[{"atl":[[660,0],[500,6.05]],"id":522746}],"con":true,"img":false}]}
{"op":"mcm","clk":"5347931194","pt":1646210742773,"mc":[{"id":"1.195453749","rc":[{"atl":[[50,39.45]],"id":3805747},{"atl":[[40,4.07],[50,29.75],[60,0]],"id":522752},{"atl":[[80,4.96],[90,0],[100,9.92],[120,15.48]],"id":522742}],"con":true,"img":false}]}
{"op":"mcm","clk":"5347931198","pt":1646210742873,"mc":[{"id":"1.195453749","rc":[{"atl":[[75,0],[40,4.07]],"id":3805747}],"con":true,"img":false}]}
{"op":"mcm","clk":"5347931202","pt":1646210742977,"mc":[{"id":"1.195453749","rc":[{"atl":[[75,0]],"id":522753}],"con":true,"img":false}]}
{"op":"mcm","clk":"5347931207","pt":1646210743180,"mc":[{"id":"1.195453749","rc":[{"atl":[[75,2.14],[100,30.26],[120,0]],"id":522742}],"con":true,"img":false}]}
{"op":"mcm","clk":"5347931219","pt":1646210743485,"mc":[{"id":"1.195453749","rc":[{"atl":[[44,0]],"id":522752}],"con":true,"img":false}]}
{"op":"mcm","clk":"5347931223","pt":1646210743589,"mc":[{"id":"1.195453749","rc":[{"atb":[[18.5,0],[19,9.92],[21,7.94],[22,4.96]],"id":3805747}],"con":true,"img":false}]}
{"op":"mcm","clk":"5347931226","pt":1646210743690,"mc":[{"id":"1.195453749","rc":[{"atl":[[48,0]],"id":3805747}],"con":true,"img":false}]}
{"op":"mcm","clk":"5347931233","pt":1646210743895,"mc":[{"id":"1.195453749","rc":[{"atb":[[2.88,25.42],[2.86,0]],"id":3805784},{"atl":[[85,0]],"id":522742}],"con":true,"img":false}]}
{"op":"mcm","clk":"5347931243","pt":1646210744100,"mc":[{"id":"1.195453749","rc":[{"atb":[[19,24.68],[22,12.52],[14.5,2.72]],"id":3805747}],"con":true,"img":false}]}
{"op":"mcm","clk":"5347931266","pt":1646210744465,"mc":[{"id":"1.195453749","rc":[{"atl":[[19.5,13.54]],"id":522749}],"con":true,"img":false}]}
{"op":"mcm","clk":"5347931276","pt":1646210744772,"mc":[{"id":"1.195453749","rc":[{"atb":[[21,0]],"id":3805747}],"con":true,"img":false}]}
{"op":"mcm","clk":"5347931298","pt":1646210745182,"mc":[{"id":"1.195453749","rc":[{"atl":[[4.5,0],[4.1,0]],"id":3805784},{"atl":[[29,23.2]],"id":522749},{"atb":[[22,9.92],[26,4.96]],"id":522742}],"con":true,"img":false}]}
{"op":"mcm","clk":"5347931301","pt":1646210745285,"mc":[{"id":"1.195453749","rc":[{"atl":[[4.6,9.92],[4.2,4.96]],"id":3805784},{"atb":[[23,0],[27,0]],"id":522742}],"con":true,"img":false}]}
{"op":"mcm","clk":"5347931305","pt":1646210745490,"mc":[{"id":"1.195453749","rc":[{"atl":[[19.5,0],[20,4.96],[23,0],[24,9.92]],"id":3805740}],"con":true,"img":false}]}
{"op":"mcm","clk":"5347931308","pt":1646210745593,"mc":[{"id":"1.195453749","rc":[{"atl":[[380,0],[940,4.16]],"id":522747}],"con":true,"img":false}]}
{"op":"mcm","clk":"5347931316","pt":1646210745898,"mc":[{"id":"1.195453749","rc":[{"atb":[[18.5,9.92],[19,14.76],[21,4.96],[22,0]],"id":3805747}],"con":true,"img":false}]}
{"op":"mcm","clk":"5347931332","pt":1646210746309,"mc":[{"id":"1.195453749","rc":[{"atl":[[940,2]],"id":522747},{"atl":[[48,3.37]],"id":3805740}],"con":true,"img":false}]}
{"op":"mcm","clk":"5347931347","pt":1646210746575,"mc":[{"id":"1.195453749","rc":[{"atb":[[18.5,0],[21,0]],"id":3805747},{"atb":[[21,12.9]],"id":522752},{"atl":[[140,16.59],[85,9.92]],"id":522753}],"con":true,"img":false}]}
{"op":"mcm","clk":"5347931352","pt":1646210746672,"mc":[{"id":"1.195453749","rc":[{"atb":[[18.5,9.07]],"id":3805747}],"con":true,"img":false}]}
{"op":"mcm","clk":"5347931356","pt":1646210746801,"mc":[{"id":"1.195453749","rc":[{"atl":[[19.5,0],[23,0]],"id":522749}],"con":true,"img":false}]}
{"op":"mcm","clk":"5347931359","pt":1646210746878,"mc":[{"id":"1.195453749","rc":[{"atl":[[20,4.96],[24,9.92]],"id":522749}],"con":true,"img":false}]}
{"op":"mcm","clk":"5347931363","pt":1646210746983,"mc":[{"id":"1.195453749","rc":[{"atl":[[36,2.86],[30,0]],"id":522749}],"con":true,"img":false}]}
{"op":"mcm","clk":"5347931367","pt":1646210747094,"mc":[{"id":"1.195453749","rc":[{"atl":[[48,25.52]],"id":3805740}],"con":true,"img":false}]}
{"op":"mcm","clk":"5347931369","pt":1646210747187,"mc":[{"id":"1.195453749","rc":[{"atl":[[32,53.14],[29,0]],"id":522749},{"atl":[[150,23.55],[160,0]],"id":522743},{"atl":[[20,13.31],[50,2.04]],"id":3805740}],"con":true,"img":false}]}
{"op":"mcm","clk":"5347931371","pt":1646210747290,"mc":[{"id":"1.195453749","rc":[{"atb":[[19,24.68],[22,4.96]],"id":3805747},{"atb":[[20,0]],"id":522752}],"con":true,"img":false}]}
{"op":"mcm","clk":"5347931386","pt":1646210747496,"mc":[{"id":"1.195453749","rc":[{"atl":[[23,7.21]],"id":522749}],"con":true,"img":false}]}
{"op":"mcm","clk":"5347931396","pt":1646210747803,"mc":[{"id":"1.195453749","rc":[{"atb":[[18.5,43.89],[19.5,0]],"id":522752}],"con":true,"img":false}]}
{"op":"mcm","clk":"5347931404","pt":1646210748009,"mc":[{"id":"1.195453749","rc":[{"atl":[[110,6.41]],"id":522743},{"atl":[[48,22.15]],"id":3805740}],"con":true,"img":false}]}
{"op":"mcm","clk":"5347931432","pt":1646210748786,"mc":[{"id":"1.195453749","rc":[{"atl":[[120,0]],"id":522743}],"con":true,"img":false}]}
{"op":"mcm","clk":"5347931441","pt":1646210748990,"mc":[{"id":"1.195453749","rc":[{"atb":[[18.5,29.95],[19,9.92]],"id":3805747}],"con":true,"img":false}]}
{"op":"mcm","clk":"5347931466","pt":1646210749610,"mc":[{"id":"1.195453749","rc":[{"atl":[[19.5,4.96],[20,0],[23,17.13],[24,0]],"id":522749}],"con":true,"img":false}]}
{"op":"mcm","clk":"5347931485","pt":1646210749980,"mc":[{"id":"1.195453749","rc":[{"atl":[[32,0],[24,25.51]],"id":522749}],"con":true,"img":false}]}
{"op":"mcm","clk":"5347931533","pt":1646210751002,"mc":[{"id":"1.195453749","rc":[{"atl":[[380,5.4]],"id":522747},{"atb":[[21,7.94]],"id":522742}],"con":true,"img":false}]}
{"op":"mcm","clk":"5347931544","pt":1646210751410,"mc":[{"id":"1.195453749","rc":[{"atl":[[6.8,14.76]],"id":3805784}],"con":true,"img":false}]}
{"op":"mcm","clk":"5347931549","pt":1646210751615,"mc":[{"id":"1.195453749","rc":[{"atb":[[25,0],[26,9.92],[29,5.67],[30,4.96]],"id":522753},{"atb":[[20,8.35],[21,27.14]],"id":522742}],"con":true,"img":false}]}
{"op":"mcm","clk":"5347931554","pt":1646210751821,"mc":[{"id":"1.195453749","rc":[{"atb":[[20,0]],"id":522742}],"con":true,"img":false}]}
{"op":"mcm","clk":"5347931558","pt":1646210751882,"mc":[{"id":"1.195453749","rc":[{"atl":[[6.8,51.52]],"id":3805784}],"con":true,"img":false}]}
{"op":"mcm","clk":"5347931561","pt":1646210751982,"mc":[{"id":"1.195453749","rc":[{"atl":[[7,12.26]],"id":3805784},{"atb":[[32,5.12],[24,0],[26,35.78]],"id":522753},{"atl":[[150,9.92],[340,8.04]],"id":522743}],"con":true,"img":false}]}
{"op":"mcm","clk":"5347931575","pt":1646210752289,"mc":[{"id":"1.195453749","rc":[{"atl":[[7,0]],"id":3805784}],"con":true,"img":false}]}
{"op":"mcm","clk":"5347931598","pt":1646210752699,"mc":[{"id":"1.195453749","rc":[{"atb":[[18.5,9.92],[14.5,29.31]],"id":522752}],"con":true,"img":false}]}
{"op":"mcm","clk":"5347931608","pt":1646210752929,"mc":[{"id":"1.195453749","rc":[{"atb":[[29,0]],"id":522753}],"con":true,"img":false}]}
{"op":"mcm","clk":"5347931641","pt":1646210753812,"mc":[{"id":"1.195453749","rc":[{"atl":[[19.5,0],[19,4.96],[22,9.92],[23,7.21]],"id":522749}],"con":true,"img":false}]}
{"op":"mcm","clk":"5347931653","pt":1646210754120,"mc":[{"id":"1.195453749","rc":[{"atb":[[22,12.52]],"id":3805747},{"atl":[[210,4.96]],"id":522746}],"con":true,"img":false}]}
{"op":"mcm","clk":"5347931656","pt":1646210754178,"mc":[{"id":"1.195453749","rc":[{"atl":[[240,0]],"id":522746}],"con":true,"img":false}]}
{"op":"mcm","clk":"5347931670","pt":1646210754595,"mc":[{"id":"1.195453749","rc":[{"atl":[[200,0.79],[240,8.6],[500,2]],"id":522746},{"atl":[[19,13.78]],"id":522749}],"con":true,"img":false}]}
{"op":"mcm","clk":"5347931679","pt":1646210754794,"mc":[{"id":"1.195453749","rc":[{"atb":[[18.5,20.88]],"id":3805747}],"con":true,"img":false}]}
{"op":"mcm","clk":"5347931700","pt":1646210755309,"mc":[{"id":"1.195453749","rc":[{"atl":[[220,0]],"id":522746},{"atl":[[23,0]],"id":522749}],"con":true,"img":false}]}
{"op":"mcm","clk":"5347931708","pt":1646210755617,"mc":[{"id":"1.195453749","rc":[{"atl":[[130,0],[90,2]],"id":522752}],"con":true,"img":false}]}
{"op":"mcm","clk":"5347931719","pt":1646210755928,"mc":[{"id":"1.195453749","rc":[{"atl":[[380,0],[940,4.19]],"id":522747},{"atl":[[19,0],[20,4.96],[22,0],[24,35.44]],"id":522749},{"atl":[[20,0],[24,0]],"id":3805740}],"con":true,"img":false}]}
{"op":"mcm","clk":"5347931722","pt":1646210755990,"mc":[{"id":"1.195453749","rc":[{"atl":[[21,4.96],[25,9.92]],"id":3805740}],"con":true,"img":false}]}
{"op":"mcm","clk":"5347931728","pt":1646210756188,"mc":[{"id":"1.195453749","rc":[{"atb":[[2.88,22.15],[2.98,35.82]],"id":3805784},{"atb":[[9.6,32.42],[11.5,15.12]],"id":522749},{"atb":[[12,14.76],[14.5,9.92]],"id":522741}],"con":true,"img":false}]}
{"op":"mcm","clk":"5347931733","pt":1646210756395,"mc":[{"id":"1.195453749","rc":[{"atl":[[36,36.81],[24,9.92]],"id":522749},{"atl":[[48,0],[55,37.67]],"id":3805740}],"con":true,"img":false}]}
{"op":"mcm","clk":"5347931739","pt":1646210756601,"mc":[{"id":"1.195453749","rc":[{"atl":[[940,2]],"id":522747},{"atl":[[19.5,4.96],[20,0],[23,17.13],[24,0]],"id":522749},{"atl":[[46,3.52]],"id":3805740}],"con":true,"img":false}]}
{"op":"mcm","clk":"5347931753","pt":1646210756911,"mc":[{"id":"1.195453749","rc":[{"atb":[[2.86,3.27],[2.96,2.72]],"id":3805784},{"atb":[[12,2.72],[9.8,3.27]],"id":522749},{"atb":[[13,3.27],[15.5,2.72]],"id":522741}],"con":true,"img":false}]}
{"op":"mcm","clk":"5347931766","pt":1646210757324,"mc":[{"id":"1.195453749","rc":[{"atb":[[2.88,0],[2.9,27.11]],"id":3805784},{"atb":[[9.6,0],[10.5,34.86]],"id":522749},{"atb":[[12,0],[14.5,40.23]],"id":522741}],"con":true,"img":false}]}
{"op":"mcm","clk":"5347931771","pt":1646210757427,"mc":[{"id":"1.195453749","rc":[{"atb":[[4.1,0],[3.8,0]],"id":3805731},{"atb":[[3.85,0],[4.2,115.06]],"id":522745}],"con":true,"img":false}]}
{"op":"mcm","clk":"5347931777","pt":1646210757477,"mc":[{"id":"1.195453749","rc":[{"atl":[[19.5,13.54]],"id":522749}],"con":true,"img":false}]}
{"op":"mcm","clk":"5347931785","pt":1646210757692,"mc":[{"id":"1.195453749","rc":[{"atb":[[12,0],[9.8,0]],"id":522749}],"con":true,"img":false}]}
{"op":"mcm","clk":"5347931792","pt":1646210757897,"mc":[{"id":"1.195453749","rc":[{"atb":[[3.85,0],[3,242.9]],"id":3805731}],"con":true,"img":false}]}
{"op":"mcm","clk":"5347931802","pt":1646210758207,"mc":[{"id":"1.195453749","rc":[{"atb":[[3.85,3.27],[4.2,2.72]],"id":3805731},{"atb":[[4.3,12.65],[3.9,3.27]],"id":522745}],"con":true,"img":false}]}
{"op":"mcm","clk":"5347931806","pt":1646210758304,"mc":[{"id":"1.195453749","rc":[{"atl":[[23,9.92]],"id":522749}],"con":true,"img":false}]}
{"op":"mcm","clk":"5347931817","pt":1646210758512,"mc":[{"id":"1.195453749","rc":[{"atb":[[9.6,3.27],[11.5,17.85]],"id":522749}],"con":true,"img":false}]}
{"op":"mcm","clk":"5347931827","pt":1646210758723,"mc":[{"id":"1.195453749","rc":[{"atb":[[2.9,22.15]],"id":3805784},{"atl":[[19.5,0],[23,0]],"id":522749},{"atb":[[21,37.06],[25,4.96]],"id":522742}],"con":true,"img":false}]}
{"op":"mcm","clk":"5347931829","pt":1646210758822,"mc":[{"id":"1.195453749","rc":[{"atb":[[2.88,9.92],[2.96,7.69]],"id":3805784},{"atl":[[20,4.96],[24,9.92]],"id":522749},{"atb":[[22,0],[26,0]],"id":522742}],"con":true,"img":false}]}
{"op":"mcm","clk":"5347931846","pt":1646210759388,"mc":[{"id":"1.195453749","rc":[{"atb":[[19.5,17.49],[21,17.86]],"id":522742}],"con":true,"img":false}]}
{"op":"mcm","clk":"5347931848","pt":1646210759490,"mc":[{"id":"1.195453749","rc":[{"atl":[[34,4.81]],"id":522749}],"con":true,"img":false}]}
{"op":"mcm","clk":"5347931863","pt":1646210760008,"mc":[{"id":"1.195453749","rc":[{"atl":[[34,26.96],[36,2.86]],"id":522749}],"con":true,"img":false}]}
{"op":"mcm","clk":"5347931889","pt":1646210760691,"mc":[{"id":"1.195453749","rc":[{"atb":[[12,0],[14.5,26.58]],"id":522752}],"con":true,"img":false}]}
{"op":"mcm","clk":"5347931901","pt":1646210760899,"mc":[{"id":"1.195453749","rc":[{"atl":[[380,5.47]],"id":522747},{"atb":[[25,11.57]],"id":522742}],"con":true,"img":false}]}
{"op":"mcm","clk":"5347931903","pt":1646210761002,"mc":[{"id":"1.195453749","rc":[{"atb":[[2.96,51.02],[2.7,0]],"id":3805731},{"atb":[[10.5,24.57],[13.5,0]],"id":522752}],"con":true,"img":false}]}
{"op":"mcm","clk":"5347931914","pt":1646210761317,"mc":[{"id":"1.195453749","rc":[{"atl":[[4.2,52.7]],"id":3805784}],"con":true,"img":false}]}
{"op":"mcm","clk":"5347931918","pt":1646210761420,"mc":[{"id":"1.195453749","rc":[{"atb":[[12,3.27],[14.5,29.31]],"id":522752}],"con":true,"img":false}]}
{"op":"mcm","clk":"5347931933","pt":1646210761788,"mc":[{"id":"1.195453749","rc":[{"atb":[[21,9.92]],"id":522742}],"con":true,"img":false}]}
{"op":"mcm","clk":"5347931939","pt":1646210761989,"mc":[{"id":"1.195453749","rc":[{"atl":[[6.8,36.75]],"id":3805784}],"con":true,"img":false}]}
{"op":"mcm","clk":"5347931942","pt":1646210762096,"mc":[{"id":"1.195453749","rc":[{"atl":[[4.5,9.92],[4.6,0],[4.1,4.96],[4.2,47.74]],"id":3805784},{"atb":[[18.5,30.8],[19,0],[21,4.96],[22,0]],"id":3805747},{"atl":[[360,0],[390,4.96]],"id":522747},{"atl":[[21,4.96],[25,9.92]],"id":522749},{"atb":[[21,0],[25,6.61]],"id":522742}],"con":true,"img":false}]}
{"op":"mcm","clk":"5347931946","pt":1646210762201,"mc":[{"id":"1.195453749","rc":[{"atb":[[9.6,44.61],[10.5,4.96]],"id":522749},{"atl":[[20,0],[24,0]],"id":522749},{"atb":[[22,9.92],[26,4.96]],"id":522742}],"con":true,"img":false}]}
{"op":"mcm","clk":"5347931948","pt":1646210762402,"mc":[{"id":"1.195453749","rc":[{"atb":[[18.5,0],[19,9.92],[21,7.94],[22,4.96]],"id":522752}],"con":true,"img":false}]}
{"op":"mcm","clk":"5347931953","pt":1646210762505,"mc":[{"id":"1.195453749","rc":[{"atl":[[4.5,57.66],[6.8,0]],"id":3805784},{"atb":[[14.5,17.49]],"id":3805747}],"con":true,"img":false}]}
{"op":"mcm","clk":"5347931962","pt":1646210762710,"mc":[{"id":"1.195453749","rc":[{"atb":[[18.5,9.92]],"id":3805747},{"atb":[[19.5,2.72],[22,27.16]],"id":522742}],"con":true,"img":false}]}
{"op":"mcm","clk":"5347931964","pt":1646210762813,"mc":[{"id":"1.195453749","rc":[{"atb":[[18.5,18.99]],"id":3805747},{"atl":[[390,0],[400,4.96]],"id":522747},{"atb":[[19,29.12],[22,12.52],[14.5,2.72]],"id":522752}],"con":true,"img":false}]}
{"op":"mcm","clk":"5347932000","pt":1646210763487,"mc":[{"id":"1.195453749","rc":[{"atb":[[21,0]],"id":522752}],"con":true,"img":false}]}
{"op":"mcm","clk":"5347932013","pt":1646210763901,"mc":[{"id":"1.195453749","rc":[{"atb":[[21,12.9]],"id":3805747},{"atb":[[3.85,0],[4.2,0]],"id":3805731}],"con":true,"img":false}]}
{"op":"mcm","clk":"5347932039","pt":1646210764521,"mc":[{"id":"1.195453749","rc":[{"atl":[[32,5.12]],"id":522749},{"atb":[[3,66.7],[2.96,203.88]],"id":3805731}],"con":true,"img":false}]}
{"op":"mcm","clk":"5347932043","pt":1646210764631,"mc":[{"id":"1.195453749","rc":[{"atb":[[18.5,9.92]],"id":3805747},{"atb":[[4.1,2.72],[3.8,3.27]],"id":3805731}],"con":true,"img":false}]}
{"op":"mcm","clk":"5347932050","pt":1646210764828,"mc":[{"id":"1.195453749","rc":[{"atl":[[890,2],[940,0]],"id":522747},{"atl":[[7.8,14.71],[8.4,0]],"id":3805731}],"con":true,"img":false}]}
{"op":"mcm","clk":"5347932069","pt":1646210765291,"mc":[{"id":"1.195453749","rc":[{"atl":[[34,22.15]],"id":522749}],"con":true,"img":false}]}
{"op":"mcm","clk":"5347932076","pt":1646210765599,"mc":[{"id":"1.195453749","rc":[{"atl":[[380,0],[890,4.33]],"id":522747}],"con":true,"img":false}]}
{"op":"mcm","clk":"5347932096","pt":1646210766223,"mc":[{"id":"1.195453749","rc":[{"atl":[[400,5.36]],"id":522747},{"atl":[[32,27.51],[34,0]],"id":522749},{"atl":[[46,25.67],[55,0]],"id":3805740}],"con":true,"img":false}]}
{"op":"mcm","clk":"5347932099","pt":1646210766324,"mc":[{"id":"1.195453749","rc":[{"atl":[[890,2]],"id":522747}],"con":true,"img":false}]}
{"op":"mcm","clk":"5347932105","pt":1646210766421,"mc":[{"id":"1.195453749","rc":[{"atl":[[21,12.9]],"id":522749}],"con":true,"img":false}]}
{"op":"mcm","clk":"5347932108","pt":1646210766522,"mc":[{"id":"1.195453749","rc":[{"atl":[[21,12.9]],"id":3805740}],"con":true,"img":false}]}
{"op":"mcm","clk":"5347932131","pt":1646210767090,"mc":[{"id":"1.195453749","rc":[{"atl":[[400,0],[410,4.96]],"id":522747}],"con":true,"img":false}]}
{"op":"mcm","clk":"5347932134","pt":1646210767191,"mc":[{"id":"1.195453749","rc":[{"atl":[[32,22.39]],"id":522749}],"con":true,"img":false}]}
{"op":"mcm","clk":"5347932138","pt":1646210767303,"mc":[{"id":"1.195453749","rc":[{"atl":[[46,22.15]],"id":3805740}],"con":true,"img":false}]}
{"op":"mcm","clk":"5347932146","pt":1646210767503,"mc":[{"id":"1.195453749","rc":[{"atb":[[19,9.92],[14.5,28.75]],"id":522752}],"con":true,"img":false}]}
{"op":"mcm","clk":"5347932153","pt":1646210767713,"mc":[{"id":"1.195453749","rc":[{"atb":[[3.8,57.94],[2.96,51.02]],"id":3805731}],"con":true,"img":false}]}
{"op":"mcm","clk":"5347932157","pt":1646210767810,"mc":[{"id":"1.195453749","rc":[{"atl":[[400,0.39]],"id":522747}],"con":true,"img":false}]}
{"op":"mcm","clk":"5347932161","pt":1646210767918,"mc":[{"id":"1.195453749","rc":[{"atb":[[18.5,9.92],[19,0],[21,4.96],[22,0]],"id":522752}],"con":true,"img":false}]}
{"op":"mcm","clk":"5347932206","pt":1646210768737,"mc":[{"id":"1.195453749","rc":[{"atb":[[18.5,18.99]],"id":522752}],"con":true,"img":false}]}
{"op":"mcm","clk":"5347932232","pt":1646210769411,"mc":[{"id":"1.195453749","rc":[{"atl":[[890,0],[950,2]],"id":522747}],"con":true,"img":false}]}
{"op":"mcm","clk":"5347932281","pt":1646210770639,"mc":[{"id":"1.195453749","rc":[{"atb":[[26,11.31]],"id":522742}],"con":true,"img":false}]}
{"op":"mcm","clk":"5347932289","pt":1646210770742,"mc":[{"id":"1.195453749","rc":[{"atl":[[400,0],[950,4.18]],"id":522747}],"con":true,"img":false}]}
{"op":"mcm","clk":"5347932315","pt":1646210771310,"mc":[{"id":"1.195453749","rc":[{"atl":[[4.1,56.18]],"id":3805784},{"atl":[[410,0]],"id":522747},{"atb":[[9.6,54.54],[10.5,0],[11,4.96],[9.4,0]],"id":522749}],"con":true,"img":false}]}
{"op":"mcm","clk":"5347932318","pt":1646210771410,"mc":[{"id":"1.195453749","rc":[{"atl":[[960,2]],"id":522747}],"con":true,"img":false}]}
{"op":"mcm","clk":"5347932320","pt":1646210771513,"mc":[{"id":"1.195453749","rc":[{"atl":[[950,2.18]],"id":522747}],"con":true,"img":false}]}
{"op":"mcm","clk":"5347932325","pt":1646210771618,"mc":[{"id":"1.195453749","rc":[{"atl":[[950,0]],"id":522747},{"atb":[[25,0]],"id":522742}],"con":true,"img":false}]}
{"op":"mcm","clk":"5347932334","pt":1646210771828,"mc":[{"id":"1.195453749","rc":[{"atl":[[940,0.16]],"id":522747}],"con":true,"img":false}]}
{"op":"mcm","clk":"5347932345","pt":1646210772033,"mc":[{"id":"1.195453749","rc":[{"atb":[[19.5,26.96]],"id":522742}],"con":true,"img":false}]}
{"op":"mcm","clk":"5347932351","pt":1646210772136,"mc":[{"id":"1.195453749","rc":[{"atl":[[4.2,0]],"id":3805784},{"atb":[[22,9.92]],"id":522742}],"con":true,"img":false}]}
{"op":"mcm","clk":"5347932361","pt":1646210772447,"mc":[{"id":"1.195453749","rc":[{"atb":[[21,12.9]],"id":522752}],"con":true,"img":false}]}
{"op":"mcm","clk":"5347932363","pt":1646210772499,"mc":[{"id":"1.195453749","rc":[{"atb":[[80,0],[55,0]],"id":522747}],"con":true,"img":false}]}
{"op":"mcm","clk":"5347932368","pt":1646210772602,"mc":[{"id":"1.195453749","rc":[{"atl":[[7.2,102.42],[4.5,9.92]],"id":3805784}],"con":true,"img":false}]}
{"op":"mcm","clk":"5347932377","pt":1646210772912,"mc":[{"id":"1.195453749","rc":[{"atb":[[18.5,0],[18,9.92],[20,4.96],[21,0]],"id":3805747},{"atl":[[420,4.96]],"id":522747}],"con":true,"img":false}]}
{"op":"mcm","clk":"5347932391","pt":1646210773225,"mc":[{"id":"1.195453749","rc":[{"atb":[[85,2.72],[60,3.27]],"id":522747},{"atb":[[18.5,9.92]],"id":522752}],"con":true,"img":false}]}
{"op":"mcm","clk":"5347932410","pt":1646210773638,"mc":[{"id":"1.195453749","rc":[{"atb":[[18,9.33],[20,0]],"id":3805747},{"atl":[[420,0]],"id":522747}],"con":true,"img":false}]}
{"op":"mcm","clk":"5347932441","pt":1646210774212,"mc":[{"id":"1.195453749","rc":[{"atb":[[12.5,35.55],[14.5,2.72]],"id":3805747}],"con":true,"img":false}]}
{"op":"mcm","clk":"5347932455","pt":1646210774413,"mc":[{"id":"1.195453749","rc":[{"atb":[[18.5,9.92],[21,4.96]],"id":3805747},{"atl":[[410,4.96]],"id":522747}],"con":true,"img":false}]}
{"op":"mcm","clk":"5347932492","pt":1646210775240,"mc":[{"id":"1.195453749","rc":[{"atb":[[18.5,0],[21,0]],"id":3805747},{"atl":[[410,0],[960,4.16]],"id":522747}],"con":true,"img":false}]}
{"op":"mcm","clk":"5347932499","pt":1646210775444,"mc":[{"id":"1.195453749","rc":[{"atb":[[18,19.26],[20,4.96]],"id":3805747}],"con":true,"img":false}]}
{"op":"mcm","clk":"5347932527","pt":1646210775912,"mc":[{"id":"1.195453749","rc":[{"atl":[[360,4.96],[930,0.16]],"id":522747}],"con":true,"img":false}]}
{"op":"mcm","clk":"5347932557","pt":1646210776428,"mc":[{"id":"1.195453749","rc":[{"atb":[[9.6,44.61],[10.5,4.96],[11,0],[9.4,9.92]],"id":522749}],"con":true,"img":false}]}
{"op":"mcm","clk":"5347932573","pt":1646210776736,"mc":[{"id":"1.195453749","rc":[{"atl":[[940,0]],"id":522747}],"con":true,"img":false}]}
{"op":"mcm","clk":"5347932615","pt":1646210777309,"mc":[{"id":"1.195453749","rc":[{"atl":[[360,5.4]],"id":522747}],"con":true,"img":false}]}
{"op":"mcm","clk":"5347932657","pt":1646210778145,"mc":[{"id":"1.195453749","rc":[{"atl":[[930,0]],"id":522747}],"con":true,"img":false}]}
{"op":"mcm","clk":"5347932664","pt":1646210778302,"mc":[{"id":"1.195453749","rc":[{"atb":[[18.5,0],[18,9.92],[20,4.96],[21,0]],"id":522752}],"con":true,"img":false}]}
{"op":"mcm","clk":"5347932704","pt":1646210779134,"mc":[{"id":"1.195453749","rc":[{"atb":[[15,11.34]],"id":522752}],"con":true,"img":false}]}
{"op":"mcm","clk":"5347932723","pt":1646210779549,"mc":[{"id":"1.195453749","rc":[{"atb":[[14.5,2.72],[15,33.49]],"id":522752}],"con":true,"img":false}]}
{"op":"mcm","clk":"5347932751","pt":1646210780128,"mc":[{"id":"1.195453749","rc":[{"atl":[[350,4.96],[360,0.44]],"id":522747}],"con":true,"img":false}]}
{"op":"mcm","clk":"5347932758","pt":1646210780238,"mc":[{"id":"1.195453749","rc":[{"atb":[[17.5,9.92],[18,9.33],[19.5,4.96],[20,0]],"id":3805747},{"atl":[[380,5.47],[960,2]],"id":522747},{"atl":[[19.5,4.96],[21,7.94],[23,9.92],[25,0]],"id":522749}],"con":true,"img":false}]}
{"op":"mcm","clk":"5347932784","pt":1646210780652,"mc":[{"id":"1.195453749","rc":[{"atl":[[32,0],[23,36.51]],"id":522749}],"con":true,"img":false}]}
{"op":"mcm","clk":"5347932789","pt":1646210780752,"mc":[{"id":"1.195453749","rc":[{"atl":[[19.5,13.54]],"id":522749}],"con":true,"img":false}]}
{"op":"mcm","clk":"5347932800","pt":1646210780963,"mc":[{"id":"1.195453749","rc":[{"atl":[[350,0],[360,5.4]],"id":522747}],"con":true,"img":false}]}
{"op":"mcm","clk":"5347932805","pt":1646210781062,"mc":[{"id":"1.195453749","rc":[{"atl":[[380,0]],"id":522747}],"con":true,"img":false}]}
{"op":"mcm","clk":"5347932819","pt":1646210781423,"mc":[{"id":"1.195453749","rc":[{"atl":[[21,0]],"id":522749},{"atl":[[150,0],[160,9.92],[110,1.45],[120,4.96]],"id":522743}],"con":true,"img":false}]}
{"op":"mcm","clk":"5347932831","pt":1646210781732,"mc":[{"id":"1.195453749","rc":[{"atl":[[950,0.16]],"id":522747}],"con":true,"img":false}]}
{"op":"mcm","clk":"5347932836","pt":1646210781837,"mc":[{"id":"1.195453749","rc":[{"atl":[[160,22.94]],"id":522743}],"con":true,"img":false}]}
{"op":"mcm","clk":"5347932839","pt":1646210781938,"mc":[{"id":"1.195453749","rc":[{"atb":[[20,13.31]],"id":522752},{"atl":[[340,2]],"id":522743}],"con":true,"img":false}]}
{"op":"mcm","clk":"5347932857","pt":1646210782351,"mc":[{"id":"1.195453749","rc":[{"atl":[[19,4.96],[21,7.94],[22,9.92],[25,0]],"id":3805740}],"con":true,"img":false}]}
{"op":"mcm","clk":"5347932862","pt":1646210782454,"mc":[{"id":"1.195453749","rc":[{"atl":[[950,0]],"id":522747}],"con":true,"img":false}]}
{"op":"mcm","clk":"5347932874","pt":1646210782620,"mc":[{"id":"1.195453749","rc":[{"atb":[[15,22.15]],"id":522752}],"con":true,"img":false}]}
{"op":"mcm","clk":"5347932882","pt":1646210782715,"mc":[{"id":"1.195453749","rc":[{"atl":[[19,13.78],[22,36.51]],"id":3805740}],"con":true,"img":false}]}
{"op":"mcm","clk":"5347932888","pt":1646210782818,"mc":[{"id":"1.195453749","rc":[{"atb":[[18,0],[18.5,9.92],[20,8.35],[21,4.96]],"id":522752},{"atl":[[46,0]],"id":3805740}],"con":true,"img":false}]}
{"op":"mcm","clk":"5347932908","pt":1646210783126,"mc":[{"id":"1.195453749","rc":[{"atb":[[17.5,19.54]],"id":3805747}],"con":true,"img":false}]}
{"op":"mcm","clk":"5347932932","pt":1646210783543,"mc":[{"id":"1.195453749","rc":[{"atb":[[18.5,0],[18,9.92],[20,13.31],[21,0]],"id":522752},{"atl":[[21,0]],"id":3805740}],"con":true,"img":false}]}
{"op":"mcm","clk":"5347932938","pt":1646210783744,"mc":[{"id":"1.195453749","rc":[{"atb":[[17.5,40.83],[12.5,8.7]],"id":3805747}],"con":true,"img":false}]}
{"op":"mcm","clk":"5347932942","pt":1646210783848,"mc":[{"id":"1.195453749","rc":[{"atb":[[17.5,21.28],[17,9.92],[19.5,0],[19,4.96]],"id":3805747}],"con":true,"img":false}]}
{"op":"mcm","clk":"5347932969","pt":1646210784517,"mc":[{"id":"1.195453749","rc":[{"atb":[[80,9.92],[85,0],[100,4.96],[110,0]],"id":522746}],"con":true,"img":false}]}
{"op":"mcm","clk":"5347932972","pt":1646210784620,"mc":[{"id":"1.195453749","rc":[{"atl":[[380,5.47]],"id":522747}],"con":true,"img":false}]}
{"op":"mcm","clk":"5347932989","pt":1646210785134,"mc":[{"id":"1.195453749","rc":[{"atl":[[36,49.59],[23,9.92]],"id":522749}],"con":true,"img":false}]}
{"op":"mcm","clk":"5347932992","pt":1646210785238,"mc":[{"id":"1.195453749","rc":[{"atb":[[60,2.69]],"id":522746}],"con":true,"img":false}]}
{"op":"mcm","clk":"5347933012","pt":1646210785755,"mc":[{"id":"1.195453749","rc":[{"atb":[[55,2.72],[60,17.45]],"id":522746},{"atb":[[17.5,9.92],[18,0],[19.5,4.96],[20,0]],"id":522752}],"con":true,"img":false}]}
{"op":"mcm","clk":"5347933044","pt":1646210786528,"mc":[{"id":"1.195453749","rc":[{"atb":[[15.5,10.94]],"id":522752},{"atb":[[4.8,4.96],[4.3,2.72],[4.4,9.92],[4.7,42.91]],"id":522745}],"con":true,"img":false}]}
{"op":"mcm","clk":"5347933058","pt":1646210786940,"mc":[{"id":"1.195453749","rc":[{"atb":[[4.9,40.71],[4.4,68.47],[4.2,0]],"id":522745}],"con":true,"img":false}]}
{"op":"mcm","clk":"5347933076","pt":1646210787247,"mc":[{"id":"1.195453749","rc":[{"atl":[[4,4.96],[4.5,0],[4.1,51.22],[4.4,9.92]],"id":3805784},{"atl":[[50,43.71]],"id":3805740}],"con":true,"img":false}]}
{"op":"mcm","clk":"5347933083","pt":1646210787350,"mc":[{"id":"1.195453749","rc":[{"atb":[[17,0],[18.5,4.96],[19,0]],"id":3805747},{"atb":[[280,0]],"id":522750},{"atb":[[17.5,0],[17,9.92],[19.5,0],[19,4.96]],"id":522752},{"atl":[[22,9.92]],"id":3805740}],"con":true,"img":false}]}
{"op":"mcm","clk":"5347933095","pt":1646210787659,"mc":[{"id":"1.195453749","rc":[{"atl":[[3.95,47.74],[4.4,57.66]],"id":3805784}],"con":true,"img":false}]}
{"op":"mcm","clk":"5347933098","pt":1646210787761,"mc":[{"id":"1.195453749","rc":[{"atb":[[4.7,0]],"id":522745}],"con":true,"img":false}]}
{"op":"mcm","clk":"5347933100","pt":1646210787865,"mc":[{"id":"1.195453749","rc":[{"atl":[[7.2,16.13]],"id":3805784},{"atb":[[120,20.43],[60,3.27]],"id":522750}],"con":true,"img":false}]}
{"op":"mcm","clk":"5347933105","pt":1646210787919,"mc":[{"id":"1.195453749","rc":[{"atb":[[160,4.96]],"id":522750}],"con":true,"img":false}]}
{"op":"mcm","clk":"5347933110","pt":1646210788024,"mc":[{"id":"1.195453749","rc":[{"atb":[[170,0.93]],"id":522750}],"con":true,"img":false}]}
{"op":"mcm","clk":"5347933114","pt":1646210788127,"mc":[{"id":"1.195453749","rc":[{"atb":[[22,0],[25,9.92],[26,6.35],[29,4.96]],"id":522742}],"con":true,"img":false}]}
{"op":"mcm","clk":"5347933126","pt":1646210788330,"mc":[{"id":"1.195453749","rc":[{"atl":[[4.1,0]],"id":3805784},{"atb":[[16,9.92],[18.5,0],[18,14.3]],"id":3805747},{"atb":[[75,9.92],[80,0],[95,4.96],[100,0]],"id":522746}],"con":true,"img":false}]}
{"op":"mcm","clk":"5347933143","pt":1646210788537,"mc":[{"id":"1.195453749","rc":[{"atb":[[16,10.58]],"id":522752}],"con":true,"img":false}]}
{"op":"mcm","clk":"5347933149","pt":1646210788642,"mc":[{"id":"1.195453749","rc":[{"atb":[[120,9.92]],"id":522750},{"atb":[[19.5,2.72],[25,26.76],[29,10.63]],"id":522742}],"con":true,"img":false}]}
{"op":"mcm","clk":"5347933156","pt":1646210788843,"mc":[{"id":"1.195453749","rc":[{"atb":[[16,45.97],[17.5,0]],"id":3805747}],"con":true,"img":false}]}
{"op":"mcm","clk":"5347933161","pt":1646210788946,"mc":[{"id":"1.195453749","rc":[{"atb":[[15,0],[15.5,33.1]],"id":522752}],"con":true,"img":false}]}
{"op":"mcm","clk":"5347933173","pt":1646210789154,"mc":[{"id":"1.195453749","rc":[{"atb":[[75,0],[80,9.92],[95,0],[100,4.96]],"id":522746},{"atl":[[380,0],[960,4.16]],"id":522747}],"con":true,"img":false}]}
{"op":"mcm","clk":"5347933185","pt":1646210789359,"mc":[{"id":"1.195453749","rc":[{"atb":[[15.5,22.15]],"id":522752},{"atb":[[24,9.92],[25,16.83],[28,4.96],[29,5.67]],"id":522742}],"con":true,"img":false}]}
{"op":"mcm","clk":"5347933191","pt":1646210789462,"mc":[{"id":"1.195453749","rc":[{"atb":[[16,36.05],[17,9.92],[18,9.33],[19,4.96]],"id":3805747},{"atb":[[26,0],[29,0]],"id":522742}],"con":true,"img":false}]}
{"op":"mcm","clk":"5347933227","pt":1646210790032,"mc":[{"id":"1.195453749","rc":[{"atb":[[17,0],[17.5,9.92],[19,0],[19.5,4.96]],"id":522752},{"atb":[[24,0],[28,0]],"id":522742}],"con":true,"img":false}]}
{"op":"mcm","clk":"5347933232","pt":1646210790135,"mc":[{"id":"1.195453749","rc":[{"atb":[[25,23.45]],"id":522742}],"con":true,"img":false}]}
{"op":"mcm","clk":"5347933273","pt":1646210790853,"mc":[{"id":"1.195453749","rc":[{"atb":[[25,33.37],[29,4.96]],"id":522742}],"con":true,"img":false}]}
{"op":"mcm","clk":"5347933291","pt":1646210791164,"mc":[{"id":"1.195453749","rc":[{"atl":[[960,2]],"id":522747},{"atb":[[17.5,0],[17,9.92],[19.5,0],[19,4.96]],"id":522752}],"con":true,"img":false}]}
{"op":"mcm","clk":"5347933319","pt":1646210791629,"mc":[{"id":"1.195453749","rc":[{"atb":[[19,13.78]],"id":522752}],"con":true,"img":false}]}
{"op":"mcm","clk":"5347933327","pt":1646210791835,"mc":[{"id":"1.195453749","rc":[{"atb":[[4.5,4.96],[4.1,12.65],[4.4,46.7]],"id":3805731}],"con":true,"img":false}]}
{"op":"mcm","clk":"5347933347","pt":1646210792249,"mc":[{"id":"1.195453749","rc":[{"atb":[[4.6,44.11],[4.1,78.76],[3.8,3.27]],"id":3805731}],"con":true,"img":false}]}
{"op":"mcm","clk":"5347933358","pt":1646210792454,"mc":[{"id":"1.195453749","rc":[{"atb":[[19,13.78]],"id":3805747},{"atb":[[16,0]],"id":522752}],"con":true,"img":false}]}
{"op":"mcm","clk":"5347933376","pt":1646210792969,"mc":[{"id":"1.195453749","rc":[{"atb":[[2.86,0],[2.96,4.96]],"id":3805784},{"atb":[[16,0],[17,28.67],[18,19.26],[19,8.82],[20,4.96]],"id":3805747},{"atb":[[4.4,0]],"id":3805731}],"con":true,"img":false}]}
{"op":"mcm","clk":"5347933385","pt":1646210793127,"mc":[{"id":"1.195453749","rc":[{"atb":[[19.5,17.49],[25,16.53]],"id":522742}],"con":true,"img":false}]}
{"op":"mcm","clk":"5347933389","pt":1646210793231,"mc":[{"id":"1.195453749","rc":[{"atb":[[18,9.92]],"id":3805747}],"con":true,"img":false}]}
{"op":"mcm","clk":"5347933409","pt":1646210793847,"mc":[{"id":"1.195453749","rc":[{"atb":[[2.92,3.27],[3.05,2.72]],"id":3805784},{"atl":[[380,5.47]],"id":522747}],"con":true,"img":false}]}
{"op":"mcm","clk":"5347933415","pt":1646210794052,"mc":[{"id":"1.195453749","rc":[{"atl":[[890,2],[960,0]],"id":522747}],"con":true,"img":false}]}
{"op":"mcm","clk":"5347933420","pt":1646210794156,"mc":[{"id":"1.195453749","rc":[{"atb":[[4.3,0],[3.9,0]],"id":522745}],"con":true,"img":false}]}
{"op":"mcm","clk":"5347933428","pt":1646210794260,"mc":[{"id":"1.195453749","rc":[{"atb":[[2.9,0],[2.96,65.67]],"id":3805784},{"atl":[[360,4.96]],"id":522747},{"atl":[[19,4.96]],"id":3805740}],"con":true,"img":false}]}
{"op":"mcm","clk":"5347933434","pt":1646210794362,"mc":[{"id":"1.195453749","rc":[{"atl":[[360,0],[370,4.96]],"id":522747},{"atl":[[19,0],[19.5,4.96],[22,0],[23,9.92]],"id":3805740}],"con":true,"img":false}]}
{"op":"mcm","clk":"5347933441","pt":1646210794467,"mc":[{"id":"1.195453749","rc":[{"atb":[[100,6.56]],"id":522746}],"con":true,"img":false}]}
{"op":"mcm","clk":"5347933475","pt":1646210794935,"mc":[{"id":"1.195453749","rc":[{"atb":[[3.95,3.27],[4.4,71.2]],"id":522745}],"con":true,"img":false}]}
{"op":"mcm","clk":"5347933479","pt":1646210795036,"mc":[{"id":"1.195453749","rc":[{"atl":[[370,5.39]],"id":522747},{"atl":[[22,7.56]],"id":3805740}],"con":true,"img":false}]}
{"op":"mcm","clk":"5347933485","pt":1646210795139,"mc":[{"id":"1.195453749","rc":[{"atb":[[60,14.76]],"id":522746},{"atl":[[19.5,8.58],[19,4.96],[22,9.92],[23,0]],"id":522749}],"con":true,"img":false}]}
{"op":"mcm","clk":"5347933496","pt":1646210795444,"mc":[{"id":"1.195453749","rc":[{"atl":[[23,35.94],[50,2.04]],"id":3805740}],"con":true,"img":false}]}
{"op":"mcm","clk":"5347933506","pt":1646210795650,"mc":[{"id":"1.195453749","rc":[{"atl":[[36,2.86],[19,13.78],[22,37.46]],"id":522749}],"con":true,"img":false}]}
{"op":"mcm","clk":"5347933536","pt":1646210796371,"mc":[{"id":"1.195453749","rc":[{"atl":[[85,2],[120,0]],"id":3805747}],"con":true,"img":false}]}
{"op":"mcm","clk":"5347933538","pt":1646210796473,"mc":[{"id":"1.195453749","rc":[{"atl":[[19.5,0]],"id":522749}],"con":true,"img":false}]}
{"op":"mcm","clk":"5347933548","pt":1646210796630,"mc":[{"id":"1.195453749","rc":[{"atl":[[40,9.03],[48,9.92]],"id":522752}],"con":true,"img":false}]}
{"op":"mcm","clk":"5347933553","pt":1646210796736,"mc":[{"id":"1.195453749","rc":[{"atl":[[42,0],[50,19.83]],"id":522752}],"con":true,"img":false}]}
{"op":"mcm","clk":"5347933558","pt":1646210796839,"mc":[{"id":"1.195453749","rc":[{"atb":[[3.05,39.07]],"id":3805784}],"con":true,"img":false}]}
{"op":"mcm","clk":"5347933563","pt":1646210796942,"mc":[{"id":"1.195453749","rc":[{"atb":[[160,7.1]],"id":522750}],"con":true,"img":false}]}
{"op":"mcm","clk":"5347933568","pt":1646210797045,"mc":[{"id":"1.195453749","rc":[{"atb":[[17,38.59],[18,0],[19,13.78],[20,0]],"id":3805747},{"atl":[[48,39.45],[50,0]],"id":522752},{"atb":[[24,9.92],[25,6.61],[28,4.96],[29,0]],"id":522742}],"con":true,"img":false}]}
{"op":"mcm","clk":"5347933569","pt":1646210797146,"mc":[{"id":"1.195453749","rc":[{"atb":[[280,0.56]],"id":522750}],"con":true,"img":false}]}
{"op":"mcm","clk":"5347933591","pt":1646210797558,"mc":[{"id":"1.195453749","rc":[{"atb":[[17,9.92],[14.5,30.62]],"id":3805747}],"con":true,"img":false}]}
{"op":"mcm","clk":"5347933598","pt":1646210797662,"mc":[{"id":"1.195453749","rc":[{"atb":[[2.98,0]],"id":3805784}],"con":true,"img":false}]}
