{"op":"mcm","clk":"5345985312","pt":1646174444270,"mc":[{"id":"1.195453612","marketDefinition":{"bspMarket":true,"turnInPlayEnabled":false,"persistenceEnabled":false,"marketBaseRate":7.0,"eventId":"31272494","eventTypeId":"4339","numberOfWinners":2,"bettingType":"ODDS","marketType":"PLACE","marketTime":"2022-03-02T08:51:00.000Z","suspendTime":"2022-03-02T08:51:00.000Z","bspReconciled":false,"complete":true,"inPlay":false,"crossMatching":false,"runnersVoidable":false,"numberOfActiveRunners":6,"betDelay":0,"status":"OPEN","runners":[{"status":"ACTIVE","sortPriority":1,"id":43066529,"name":"1. Piopio"},{"status":"ACTIVE","sortPriority":2,"id":41676292,"name":"2. Jasper Bale"},{"status":"ACTIVE","sortPriority":3,"id":41762566,"name":"3. Afro Boy"},{"status":"ACTIVE","sortPriority":4,"id":42651625,"name":"4. Average Axel"},{"status":"ACTIVE","sortPriority":5,"id":43167172,"name":"6. Fancy Like"},{"status":"ACTIVE","sortPriority":6,"id":43167173,"name":"8. Simon Rose"}],"regulators":["MR_INT"],"venue":"Traralgon","countryCode":"AU","discountAllowed":true,"timezone":"Australia/Sydney","openDate":"2022-03-02T08:31:00.000Z","version":4382425393,"name":"To Be Placed","eventName":"Traralgon (AUS) 2nd Mar"},"rc":[],"con":true,"img":false}]}
{"op":"mcm","clk":"5346059509","pt":1646175786400,"mc":[{"id":"1.195453612","rc":[{"atb":[[4,33.23],[4.5,28.48],[3.75,36.25]],"id":41762566},{"atl":[[16,2.41],[34,2.19],[22,3.45]],"id":41762566},{"spn":10.25,"spf":"NaN","id":41762566},{"atb":[[1.45,221.55],[1.55,181.27],[1.5,199.4]],"id":43066529},{"atl":[[2.82,19.91],[3.55,28.43],[3.05,35.37]],"id":43066529},{"spn":2.18,"spf":"NaN","id":43066529},{"atb":[[4,33.23],[4.5,28.48],[3.75,36.25]],"id":42651625},{"atl":[[16,2.41],[34,2.19],[22,3.45]],"id":42651625},{"spn":10.25,"spf":"NaN","id":42651625},{"atb":[[2.86,53.6],[3.15,46.37],[2.96,50.86]],"id":41676292},{"atl":[[16,4.83],[11,7.25],[8.4,4.89]],"id":41676292},{"spn":5.77,"spf":"NaN","id":41676292},{"atb":[[1.2,498.5],[1.25,398.8],[1.3,332.33]],"id":43167172},{"atl":[[2.54,23.54],[2.74,41.67],[2.94,37.37]],"id":43167172},{"spn":1.92,"spf":"NaN","id":43167172},{"atb":[[1.25,398.8],[1.3,332.33],[1.35,284.86]],"id":43167173},{"atl":[[2.8,40.28],[3,36.25],[2.6,22.66]],"id":43167173},{"spn":1.97,"spf":"NaN","id":43167173}],"con":true,"img":false}]}
{"op":"mcm","clk":"5346061998","pt":1646175839944,"mc":[{"id":"1.195453612","rc":[{"atb":[[4,0],[4.5,0],[3.75,0]],"id":41762566},{"atl":[[16,0],[34,0],[22,0]],"id":41762566},{"atb":[[1.45,0],[1.55,0],[1.5,0]],"id":43066529},{"atl":[[2.82,0],[3.55,0],[3.05,0]],"id":43066529},{"atb":[[4,0],[4.5,0],[3.75,0]],"id":42651625},{"atl":[[16,0],[34,0],[22,0]],"id":42651625},{"atb":[[2.86,0],[3.15,0],[2.96,0]],"id":41676292},{"atl":[[16,0],[11,0],[8.4,0]],"id":41676292},{"atb":[[1.2,0],[1.25,0],[1.3,0]],"id":43167172},{"atl":[[2.54,0],[2.74,0],[2.94,0]],"id":43167172},{"atb":[[1.25,0],[1.3,0],[1.35,0]],"id":43167173},{"atl":[[2.8,0],[3,0],[2.6,0]],"id":43167173}],"con":true,"img":false}]}
{"op":"mcm","clk":"5346062130","pt":1646175843036,"mc":[{"id":"1.195453612","rc":[{"atb":[[4,33.23],[4.5,28.48],[3.75,36.25]],"id":41762566},{"atl":[[16,2.41],[34,2.19],[22,3.45]],"id":41762566},{"atb":[[1.45,221.55],[1.55,181.27],[1.5,199.4]],"id":43066529},{"atl":[[2.82,19.91],[3.55,28.43],[3.05,35.37]],"id":43066529},{"atb":[[4,33.23],[4.5,28.48],[3.75,36.25]],"id":42651625},{"atl":[[16,2.41],[34,2.19],[22,3.45]],"id":42651625},{"atb":[[2.86,53.6],[3.15,46.37],[2.96,50.86]],"id":41676292},{"atl":[[16,4.83],[11,7.25],[8.4,4.89]],"id":41676292},{"atb":[[1.2,498.5],[1.25,398.8],[1.3,332.33]],"id":43167172},{"atl":[[2.54,23.54],[2.74,41.67],[2.94,37.37]],"id":43167172},{"atb":[[1.25,398.8],[1.3,332.33],[1.35,284.86]],"id":43167173},{"atl":[[2.8,40.28],[3,36.25],[2.6,22.66]],"id":43167173}],"con":true,"img":false}]}
{"op":"mcm","clk":"5346105157","pt":1646176602701,"mc":[{"id":"1.195453612","marketDefinition":{"bspMarket":true,"turnInPlayEnabled":false,"persistenceEnabled":false,"marketBaseRate":7.0,"eventId":"31272494","eventTypeId":"4339","numberOfWinners":2,"bettingType":"ODDS","marketType":"PLACE","marketTime":"2022-03-02T08:51:00.000Z","suspendTime":"2022-03-02T08:51:00.000Z","bspReconciled":false,"complete":true,"inPlay":false,"crossMatching":false,"runnersVoidable":false,"numberOfActiveRunners":6,"betDelay":0,"status":"OPEN","runners":[{"status":"ACTIVE","sortPriority":1,"id":43066529,"name":"1. Piopio"},{"status":"ACTIVE","sortPriority":2,"id":41676292,"name":"2. Jasper Bale"},{"status":"ACTIVE","sortPriority":3,"id":41762566,"name":"3. Afro Boy"},{"status":"ACTIVE","sortPriority":4,"id":42651625,"name":"4. Average Axel"},{"status":"ACTIVE","sortPriority":5,"id":43167172,"name":"6. Fancy Like"},{"status":"ACTIVE","sortPriority":6,"id":43167173,"name":"8. Simon Rose"}],"regulators":["MR_INT"],"venue":"Traralgon","countryCode":"AU","discountAllowed":true,"timezone":"Australia/Sydney","openDate":"2022-03-02T08:31:00.000Z","version":4382425393,"name":"To Be Placed","eventName":"Traralgon (AUS) 2nd Mar"},"rc":[{"atb":[[4,33.23],[4.5,28.48],[3.75,36.25]],"id":41762566},{"atl":[[16,2.41],[34,2.19],[22,3.45]],"id":41762566},{"spn":10.25,"spf":"NaN","id":41762566},{"atb":[[1.45,221.55],[1.55,181.27],[1.5,199.4]],"id":43066529},{"atl":[[2.82,19.91],[3.55,28.43],[3.05,35.37]],"id":43066529},{"spn":2.18,"spf":"NaN","id":43066529},{"atb":[[4,33.23],[4.5,28.48],[3.75,36.25]],"id":42651625},{"atl":[[16,2.41],[34,2.19],[22,3.45]],"id":42651625},{"spn":10.25,"spf":"NaN","id":42651625},{"atb":[[2.86,53.6],[3.15,46.37],[2.96,50.86]],"id":41676292},{"atl":[[16,4.83],[11,7.25],[8.4,4.89]],"id":41676292},{"spn":5.77,"spf":"NaN","id":41676292},{"atb":[[1.2,498.5],[1.25,398.8],[1.3,332.33]],"id":43167172},{"atl":[[2.54,23.54],[2.74,41.67],[2.94,37.37]],"id":43167172},{"spn":1.92,"spf":"NaN","id":43167172},{"atb":[[1.25,398.8],[1.3,332.33],[1.35,284.86]],"id":43167173},{"atl":[[2.8,40.28],[3,36.25],[2.6,22.66]],"id":43167173},{"spn":1.97,"spf":"NaN","id":43167173}],"con":true,"img":true}]}
{"op":"mcm","clk":"5346401615","pt":1646182002788,"mc":[{"id":"1.195453612","marketDefinition":{"bspMarket":true,"turnInPlayEnabled":false,"persistenceEnabled":false,"marketBaseRate":7.0,"eventId":"31272494","eventTypeId":"4339","numberOfWinners":2,"bettingType":"ODDS","marketType":"PLACE","marketTime":"2022-03-02T08:51:00.000Z","suspendTime":"2022-03-02T08:51:00.000Z","bspReconciled":false,"complete":true,"inPlay":false,"crossMatching":false,"runnersVoidable":false,"numberOfActiveRunners":6,"betDelay":0,"status":"OPEN","runners":[{"status":"ACTIVE","sortPriority":1,"id":43066529,"name":"1. Piopio"},{"status":"ACTIVE","sortPriority":2,"id":41676292,"name":"2. Jasper Bale"},{"status":"ACTIVE","sortPriority":3,"id":41762566,"name":"3. Afro Boy"},{"status":"ACTIVE","sortPriority":4,"id":42651625,"name":"4. Average Axel"},{"status":"ACTIVE","sortPriority":5,"id":43167172,"name":"6. Fancy Like"},{"status":"ACTIVE","sortPriority":6,"id":43167173,"name":"8. Simon Rose"}],"regulators":["MR_INT"],"venue":"Traralgon","countryCode":"AU","discountAllowed":true,"timezone":"Australia/Sydney","openDate":"2022-03-02T08:31:00.000Z","version":4382425393,"name":"To Be Placed","eventName":"Traralgon (AUS) 2nd Mar"},"rc":[{"atb":[[4,33.23],[4.5,28.48],[3.75,36.25]],"id":41762566},{"atl":[[16,2.41],[34,2.19],[22,3.45]],"id":41762566},{"spn":10.25,"spf":"NaN","id":41762566},{"atb":[[1.45,221.58],[1.55,181.29],[1.5,199.42]],"id":43066529},{"atl":[[2.82,19.92],[3.55,28.44],[3.05,35.37]],"id":43066529},{"spn":2.18,"spf":"NaN","id":43066529},{"atb":[[4,33.23],[4.5,28.48],[3.75,36.25]],"id":42651625},{"atl":[[16,2.41],[34,2.19],[22,3.45]],"id":42651625},{"spn":10.25,"spf":"NaN","id":42651625},{"atb":[[2.86,53.6],[3.15,46.37],[2.96,50.87]],"id":41676292},{"atl":[[16,4.83],[11,7.25],[8.4,4.89]],"id":41676292},{"spn":5.77,"spf":"NaN","id":41676292},{"atb":[[1.2,498.55],[1.25,398.84],[1.3,332.37]],"id":43167172},{"atl":[[2.54,23.54],[2.74,41.67],[2.94,37.38]],"id":43167172},{"spn":1.92,"spf":"NaN","id":43167172},{"atb":[[1.25,398.84],[1.3,332.37],[1.35,284.89]],"id":43167173},{"atl":[[2.8,40.28],[3,36.25],[2.6,22.66]],"id":43167173},{"spn":1.97,"spf":"NaN","id":43167173}],"con":true,"img":true}]}
{"op":"mcm","clk":"5346767969","pt":1646187402733,"mc":[{"id":"1.195453612","marketDefinition":{"bspMarket":true,"turnInPlayEnabled":false,"persistenceEnabled":false,"marketBaseRate":7.0,"eventId":"31272494","eventTypeId":"4339","numberOfWinners":2,"bettingType":"ODDS","marketType":"PLACE","marketTime":"2022-03-02T08:51:00.000Z","suspendTime":"2022-03-02T08:51:00.000Z","bspReconciled":false,"complete":true,"inPlay":false,"crossMatching":false,"runnersVoidable":false,"numberOfActiveRunners":6,"betDelay":0,"status":"OPEN","runners":[{"status":"ACTIVE","sortPriority":1,"id":43066529,"name":"1. Piopio"},{"status":"ACTIVE","sortPriority":2,"id":41676292,"name":"2. Jasper Bale"},{"status":"ACTIVE","sortPriority":3,"id":41762566,"name":"3. Afro Boy"},{"status":"ACTIVE","sortPriority":4,"id":42651625,"name":"4. Average Axel"},{"status":"ACTIVE","sortPriority":5,"id":43167172,"name":"6. Fancy Like"},{"status":"ACTIVE","sortPriority":6,"id":43167173,"name":"8. Simon Rose"}],"regulators":["MR_INT"],"venue":"Traralgon","countryCode":"AU","discountAllowed":true,"timezone":"Australia/Sydney","openDate":"2022-03-02T08:31:00.000Z","version":4382425393,"name":"To Be Placed","eventName":"Traralgon (AUS) 2nd Mar"},"rc":[{"atb":[[4,33.28],[4.5,28.53],[3.75,36.31]],"id":41762566},{"atl":[[16,2.42],[34,2.2],[22,3.45]],"id":41762566},{"spn":10.25,"spf":"NaN","id":41762566},{"atb":[[1.45,221.93],[1.55,181.58],[1.5,199.73]],"id":43066529},{"atl":[[2.82,19.95],[3.55,28.48],[3.05,35.43]],"id":43066529},{"spn":2.18,"spf":"NaN","id":43066529},{"atb":[[4,33.28],[4.5,28.53],[3.75,36.31]],"id":42651625},{"atl":[[16,2.42],[34,2.2],[22,3.45]],"id":42651625},{"spn":10.25,"spf":"NaN","id":42651625},{"atb":[[2.86,53.69],[3.15,46.45],[2.96,50.95]],"id":41676292},{"atl":[[16,4.84],[11,7.26],[8.4,4.9]],"id":41676292},{"spn":5.77,"spf":"NaN","id":41676292},{"atb":[[1.2,499.34],[1.25,399.47],[1.3,332.89]],"id":43167172},{"atl":[[2.54,23.58],[2.74,41.74],[2.94,37.43]],"id":43167172},{"spn":1.92,"spf":"NaN","id":43167172},{"atb":[[1.25,399.47],[1.3,332.89],[1.35,285.34]],"id":43167173},{"atl":[[2.8,40.35],[3,36.31],[2.6,22.7]],"id":43167173},{"spn":1.97,"spf":"NaN","id":43167173}],"con":true,"img":true}]}
{"op":"mcm","clk":"5347092520","pt":1646192802713,"mc":[{"id":"1.195453612","marketDefinition":{"bspMarket":true,"turnInPlayEnabled":false,"persistenceEnabled":false,"marketBaseRate":7.0,"eventId":"31272494","eventTypeId":"4339","numberOfWinners":2,"bettingType":"ODDS","marketType":"PLACE","marketTime":"2022-03-02T08:51:00.000Z","suspendTime":"2022-03-02T08:51:00.000Z","bspReconciled":false,"complete":true,"inPlay":false,"crossMatching":false,"runnersVoidable":false,"numberOfActiveRunners":6,"betDelay":0,"status":"OPEN","runners":[{"status":"ACTIVE","sortPriority":1,"id":43066529,"name":"1. Piopio"},{"status":"ACTIVE","sortPriority":2,"id":41676292,"name":"2. Jasper Bale"},{"status":"ACTIVE","sortPriority":3,"id":41762566,"name":"3. Afro Boy"},{"status":"ACTIVE","sortPriority":4,"id":42651625,"name":"4. Average Axel"},{"status":"ACTIVE","sortPriority":5,"id":43167172,"name":"6. Fancy Like"},{"status":"ACTIVE","sortPriority":6,"id":43167173,"name":"8. Simon Rose"}],"regulators":["MR_INT"],"venue":"Traralgon","countryCode":"AU","discountAllowed":true,"timezone":"Australia/Sydney","openDate":"2022-03-02T08:31:00.000Z","version":4382425393,"name":"To Be Placed","eventName":"Traralgon (AUS) 2nd Mar"},"rc":[{"atb":[[4,33.34],[4.5,28.58],[3.75,36.37]],"id":41762566},{"atl":[[16,2.42],[34,2.2],[22,3.46]],"id":41762566},{"spn":10.25,"spf":"NaN","id":41762566},{"atb":[[1.45,222.3],[1.55,181.88],[1.5,200.07]],"id":43066529},{"atl":[[2.82,19.98],[3.55,28.53],[3.05,35.49]],"id":43066529},{"spn":2.18,"spf":"NaN","id":43066529},{"atb":[[4,33.34],[4.5,28.58],[3.75,36.37]],"id":42651625},{"atl":[[16,2.42],[34,2.2],[22,3.46]],"id":42651625},{"spn":10.25,"spf":"NaN","id":42651625},{"atb":[[2.86,53.78],[3.15,46.53],[2.96,51.03]],"id":41676292},{"atl":[[16,4.85],[11,7.27],[8.4,4.91]],"id":41676292},{"spn":5.77,"spf":"NaN","id":41676292},{"atb":[[1.2,500.19],[1.25,400.15],[1.3,333.46]],"id":43167172},{"atl":[[2.54,23.62],[2.74,41.81],[2.94,37.5]],"id":43167172},{"spn":1.92,"spf":"NaN","id":43167172},{"atb":[[1.25,400.15],[1.3,333.46],[1.35,285.82]],"id":43167173},{"atl":[[2.8,40.41],[3,36.37],[2.6,22.73]],"id":43167173},{"spn":1.97,"spf":"NaN","id":43167173}],"con":true,"img":true}]}
{"op":"mcm","clk":"5347340056","pt":1646197402658,"mc":[{"id":"1.195453612","rc":[{"atb":[[4,0],[4.5,0],[3.75,0]],"id":41762566},{"atl":[[16,0],[34,0],[22,0]],"id":41762566},{"spn":"NaN","spf":"NaN","id":41762566},{"atb":[[1.45,0],[1.55,0],[1.5,0]],"id":43066529},{"atl":[[2.82,0],[3.55,0],[3.05,0]],"id":43066529},{"spn":"NaN","spf":"NaN","id":43066529},{"atb":[[4,33.33],[4.5,28.57],[3.75,36.36]],"id":42651625},{"atl":[[16,2.42],[34,2.2],[22,3.46]],"id":42651625},{"atb":[[2.86,0],[3.15,0],[2.96,0]],"id":41676292},{"atl":[[16,0],[11,0],[8.4,0]],"id":41676292},{"spn":"NaN","spf":"NaN","id":41676292},{"atb":[[1.2,0],[1.25,0],[1.3,0]],"id":43167172},{"atl":[[2.54,0],[2.74,0],[2.94,0]],"id":43167172},{"spn":"NaN","spf":"NaN","id":43167172},{"atb":[[1.25,0],[1.3,0],[1.35,0]],"id":43167173},{"atl":[[2.8,0],[3,0],[2.6,0]],"id":43167173},{"spn":"NaN","spf":"NaN","id":43167173}],"con":true,"img":false}]}
{"op":"mcm","clk":"5347340415","pt":1646197411162,"mc":[{"id":"1.195453612","rc":[{"atb":[[4.5,28.57],[5,25],[5.5,22.22]],"id":41762566},{"atl":[[18.5,2.08],[44,1.69],[27,2.79]],"id":41762566},{"atb":[[1.4,250],[1.45,222.22],[1.5,200]],"id":43066529},{"atl":[[3.45,29.68],[2.98,36.72],[2.78,20.43]],"id":43066529},{"atb":[[3.4,41.66],[3.15,46.51],[3.65,37.73]],"id":41676292},{"atl":[[10.5,3.82],[21,3.63],[15.5,5.01]],"id":41676292},{"atb":[[1.2,500],[1.25,400],[1.3,333.33]],"id":43167172},{"atl":[[2.54,23.61],[2.74,41.79],[2.94,37.48]],"id":43167172},{"atb":[[1.25,400],[1.3,333.33],[1.35,285.71]],"id":43167173},{"atl":[[2.8,40.4],[3,36.36],[2.6,22.73]],"id":43167173}],"con":true,"img":false}]}
{"op":"mcm","clk":"5347381376","pt":1646198202730,"mc":[{"id":"1.195453612","marketDefinition":{"bspMarket":true,"turnInPlayEnabled":false,"persistenceEnabled":false,"marketBaseRate":7.0,"eventId":"31272494","eventTypeId":"4339","numberOfWinners":2,"bettingType":"ODDS","marketType":"PLACE","marketTime":"2022-03-02T08:51:00.000Z","suspendTime":"2022-03-02T08:51:00.000Z","bspReconciled":false,"complete":true,"inPlay":false,"crossMatching":false,"runnersVoidable":false,"numberOfActiveRunners":6,"betDelay":0,"status":"OPEN","runners":[{"status":"ACTIVE","sortPriority":1,"id":43066529,"name":"1. Piopio"},{"status":"ACTIVE","sortPriority":2,"id":41676292,"name":"2. Jasper Bale"},{"status":"ACTIVE","sortPriority":3,"id":41762566,"name":"3. Afro Boy"},{"status":"ACTIVE","sortPriority":4,"id":42651625,"name":"4. Average Axel"},{"status":"ACTIVE","sortPriority":5,"id":43167172,"name":"6. Fancy Like"},{"status":"ACTIVE","sortPriority":6,"id":43167173,"name":"8. Simon Rose"}],"regulators":["MR_INT"],"venue":"Traralgon","countryCode":"AU","discountAllowed":true,"timezone":"Australia/Sydney","openDate":"2022-03-02T08:31:00.000Z","version":4382425393,"name":"To Be Placed","eventName":"Traralgon (AUS) 2nd Mar"},"rc":[{"atb":[[4.5,28.57],[5,25],[5.5,22.22]],"id":41762566},{"atl":[[18.5,2.08],[44,1.69],[27,2.79]],"id":41762566},{"spn":12.0,"spf":"NaN","id":41762566},{"atb":[[1.4,250],[1.45,222.22],[1.5,200]],"id":43066529},{"atl":[[3.45,29.68],[2.98,36.72],[2.78,20.43]],"id":43066529},{"spn":2.14,"spf":"NaN","id":43066529},{"atb":[[4,33.33],[4.5,28.57],[3.75,36.36]],"id":42651625},{"atl":[[16,2.42],[34,2.2],[22,3.46]],"id":42651625},{"spn":10.25,"spf":"NaN","id":42651625},{"atb":[[3.4,41.66],[3.15,46.51],[3.65,37.73]],"id":41676292},{"atl":[[10.5,3.82],[21,3.63],[15.5,5.01]],"id":41676292},{"spn":7.07,"spf":"NaN","id":41676292},{"atb":[[1.2,500],[1.25,400],[1.3,333.33]],"id":43167172},{"atl":[[2.54,23.61],[2.74,41.79],[2.94,37.48]],"id":43167172},{"spn":1.92,"spf":"NaN","id":43167172},{"atb":[[1.25,400],[1.3,333.33],[1.35,285.71]],"id":43167173},{"atl":[[2.8,40.4],[3,36.36],[2.6,22.73]],"id":43167173},{"spn":1.97,"spf":"NaN","id":43167173}],"con":true,"img":true}]}
{"op":"mcm","clk":"5347697979","pt":1646205690212,"mc":[{"id":"1.195453612","rc":[{"atb":[[4.5,28.56],[5,24.99],[5.5,22.21],[4.2,13.64],[3.65,21.16]],"id":41762566},{"atl":[[18.5,2.07],[44,1.69],[48,2.72],[50,2.72],[27,2.79]],"id":41762566},{"spn":12.0,"spf":"NaN","id":41762566},{"atb":[[1.4,249.93],[1.41,158.84],[1.45,222.16],[1.5,199.94],[1.51,85.62]],"id":43066529},{"atl":[[3.45,29.67],[3.4,27.29],[2.98,36.71],[2.78,20.42],[2.96,22.28]],"id":43066529},{"spn":2.14,"spf":"NaN","id":43066529},{"atb":[[4,33.32],[4.5,28.56],[7.4,8.97],[8.8,5.6],[3.75,36.35]],"id":42651625},{"atl":[[16,2.42],[65,2.72],[34,2.2],[70,2.72],[22,3.46]],"id":42651625},{"spn":12.4,"spf":"NaN","id":42651625},{"atb":[[3.45,22.28],[3.4,41.65],[3.15,46.5],[3.9,15.06],[3.65,37.72]],"id":41676292},{"atl":[[34,2.72],[10.5,3.82],[21,3.63],[30,2.72],[15.5,5.01]],"id":41676292},{"spn":7.2,"spf":"NaN","id":41676292},{"atb":[[1.2,499.86],[1.25,399.89],[1.26,220.96],[1.3,333.24],[1.31,86.21]],"id":43167172},{"atl":[[2.72,33.4],[2.54,23.6],[2.74,41.78],[2.52,28.72],[2.94,37.47]],"id":43167172},{"spn":1.91,"spf":"NaN","id":43167172},{"atb":[[1.36,83.04],[1.25,399.89],[1.26,227.78],[1.3,333.24],[1.35,285.63]],"id":43167173},{"atl":[[2.8,40.39],[3,36.35],[2.6,22.72],[2.66,24.53],[2.78,33.27]],"id":43167173},{"spn":1.98,"spf":"NaN","id":43167173}],"con":true,"img":false}]}
{"op":"mcm","clk":"5347700329","pt":1646205751263,"mc":[{"id":"1.195453612","rc":[{"atb":[[4.2,0]],"id":41762566},{"atl":[[2.96,0]],"id":43066529},{"atl":[[2.66,0]],"id":43167173}],"con":true,"img":false}]}
{"op":"mcm","clk":"5347700333","pt":1646205751364,"mc":[{"id":"1.195453612","rc":[{"atb":[[4.6,13.64]],"id":41762566},{"atl":[[2.76,22.28]],"id":43066529},{"atl":[[2.58,24.53]],"id":43167173}],"con":true,"img":false}]}
{"op":"mcm","clk":"5347700890","pt":1646205764967,"mc":[{"id":"1.195453612","rc":[{"atl":[[2.72,0]],"id":43167172}],"con":true,"img":false}]}
{"op":"mcm","clk":"5347700893","pt":1646205765072,"mc":[{"id":"1.195453612","rc":[{"atl":[[2.52,62.12]],"id":43167172}],"con":true,"img":false}]}
{"op":"mcm","clk":"5347701468","pt":1646205779142,"mc":[{"id":"1.195453612","rc":[{"atl":[[2.76,0]],"id":43066529}],"con":true,"img":false}]}
{"op":"mcm","clk":"5347701476","pt":1646205779187,"mc":[{"id":"1.195453612","rc":[{"atl":[[2.96,22.28]],"id":43066529}],"con":true,"img":false}]}
{"op":"mcm","clk":"5347713132","pt":1646206106456,"mc":[{"id":"1.195453612","rc":[{"atl":[[65,0],[70,0]],"id":42651625},{"spn":1.97,"spf":"NaN","id":43167173}],"con":true,"img":false}]}
{"op":"mcm","clk":"5347713137","pt":1646206106558,"mc":[{"id":"1.195453612","rc":[{"atl":[[75,2.72],[85,2.72]],"id":42651625}],"con":true,"img":false}]}
{"op":"mcm","clk":"5347714056","pt":1646206135725,"mc":[{"id":"1.195453612","rc":[{"atb":[[4.5,0],[5,0],[5.5,0]],"id":41762566},{"atl":[[18.5,0],[44,0],[27,0]],"id":41762566},{"atb":[[4,0],[4.5,0],[3.75,0]],"id":42651625},{"atl":[[16,0],[34,0],[22,0]],"id":42651625},{"atb":[[3.4,0],[3.15,0],[3.65,0]],"id":41676292},{"atl":[[10.5,0],[21,0],[15.5,0]],"id":41676292}],"con":true,"img":false}]}
{"op":"mcm","clk":"5347714114","pt":1646206137011,"mc":[{"id":"1.195453612","rc":[{"atb":[[4.6,0]],"id":41762566}],"con":true,"img":false}]}
{"op":"mcm","clk":"5347714121","pt":1646206137114,"mc":[{"id":"1.195453612","rc":[{"atb":[[4.2,13.64]],"id":41762566}],"con":true,"img":false}]}
{"op":"mcm","clk":"5347714768","pt":1646206153365,"mc":[{"id":"1.195453612","rc":[{"atb":[[4,33.32],[4.5,28.56],[5,24.99]],"id":41762566},{"atl":[[17,2.27],[38,1.96],[24,3.16]],"id":41762566},{"atb":[[5.8,20.82],[5.3,23.24],[6.6,17.85]],"id":42651625},{"atl":[[70,1.05],[38,1.96],[24,1.58]],"id":42651625},{"atb":[[3.4,41.65],[3.15,46.5],[3.65,37.72]],"id":41676292},{"atl":[[10.5,3.82],[21,3.63],[15.5,5.01]],"id":41676292}],"con":true,"img":false}]}
{"op":"mcm","clk":"5347715018","pt":1646206159527,"mc":[{"id":"1.195453612","rc":[{"atb":[[8.8,0]],"id":42651625},{"atb":[[3.9,0]],"id":41676292}],"con":true,"img":false}]}
{"op":"mcm","clk":"5347715026","pt":1646206159636,"mc":[{"id":"1.195453612","rc":[{"atb":[[9.6,5.6]],"id":42651625},{"atb":[[4,15.06]],"id":41676292}],"con":true,"img":false}]}
{"op":"mcm","clk":"5347715361","pt":1646206168523,"mc":[{"id":"1.195453612","rc":[{"spn":11.0,"spf":"NaN","id":41762566},{"spn":16.8,"spf":"NaN","id":42651625},{"spn":7.25,"spf":"NaN","id":41676292},{"atl":[[2.78,0]],"id":43167173}],"con":true,"img":false}]}
{"op":"mcm","clk":"5347715366","pt":1646206168626,"mc":[{"id":"1.195453612","rc":[{"atl":[[2.58,57.8]],"id":43167173}],"con":true,"img":false}]}
{"op":"mcm","clk":"5347715974","pt":1646206182548,"mc":[{"id":"1.195453612","rc":[{"atl":[[48,0]],"id":41762566},{"atl":[[2.52,28.72]],"id":43167172},{"atl":[[2.58,24.53]],"id":43167173}],"con":true,"img":false}]}
{"op":"mcm","clk":"5347715980","pt":1646206182650,"mc":[{"id":"1.195453612","rc":[{"atl":[[42,2.72]],"id":41762566},{"atl":[[2.72,33.4]],"id":43167172},{"atl":[[2.78,33.27]],"id":43167173}],"con":true,"img":false}]}
{"op":"mcm","clk":"5347717209","pt":1646206211770,"mc":[{"id":"1.195453612","rc":[{"atb":[[4.2,0]],"id":41762566}],"con":true,"img":false}]}
{"op":"mcm","clk":"5347717218","pt":1646206211874,"mc":[{"id":"1.195453612","rc":[{"atb":[[4.6,13.64]],"id":41762566}],"con":true,"img":false}]}
{"op":"mcm","clk":"5347718001","pt":1646206230999,"mc":[{"id":"1.195453612","rc":[{"atl":[[2.96,0]],"id":43066529},{"atb":[[9.6,0]],"id":42651625},{"spn":15.7,"spf":"NaN","id":42651625}],"con":true,"img":false}]}
{"op":"mcm","clk":"5347718009","pt":1646206231097,"mc":[{"id":"1.195453612","rc":[{"atl":[[2.76,22.28]],"id":43066529},{"atb":[[10,5.6]],"id":42651625}],"con":true,"img":false}]}
{"op":"mcm","clk":"5347718491","pt":1646206243137,"mc":[{"id":"1.195453612","rc":[{"atl":[[42,0]],"id":41762566}],"con":true,"img":false}]}
{"op":"mcm","clk":"5347718494","pt":1646206243239,"mc":[{"id":"1.195453612","rc":[{"atl":[[36,2.72]],"id":41762566}],"con":true,"img":false}]}
{"op":"mcm","clk":"5347719355","pt":1646206256959,"mc":[{"id":"1.195453612","rc":[{"atl":[[2.72,0]],"id":43167172},{"atl":[[2.78,0]],"id":43167173}],"con":true,"img":false}]}
{"op":"mcm","clk":"5347719359","pt":1646206257010,"mc":[{"id":"1.195453612","rc":[{"atl":[[2.52,62.12]],"id":43167172},{"atl":[[2.58,57.8]],"id":43167173}],"con":true,"img":false}]}
{"op":"mcm","clk":"5347719975","pt":1646206268922,"mc":[{"id":"1.195453612","rc":[{"atb":[[7.4,0]],"id":42651625},{"atl":[[2.52,28.72]],"id":43167172},{"atl":[[2.58,24.53]],"id":43167173}],"con":true,"img":false}]}
{"op":"mcm","clk":"5347719979","pt":1646206269025,"mc":[{"id":"1.195453612","rc":[{"atb":[[8.6,8.97]],"id":42651625},{"atl":[[2.72,33.4]],"id":43167172},{"atl":[[2.78,33.27]],"id":43167173}],"con":true,"img":false}]}
{"op":"mcm","clk":"5347720588","pt":1646206282656,"mc":[{"id":"1.195453612","rc":[{"atl":[[50,0]],"id":41762566},{"atl":[[2.76,0]],"id":43066529}],"con":true,"img":false}]}
{"op":"mcm","clk":"5347720593","pt":1646206282759,"mc":[{"id":"1.195453612","rc":[{"atl":[[36,5.45]],"id":41762566},{"atl":[[2.96,22.28]],"id":43066529}],"con":true,"img":false}]}
{"op":"mcm","clk":"5347721748","pt":1646206310483,"mc":[{"id":"1.195453612","rc":[{"atb":[[10,0]],"id":42651625},{"spn":16.3,"spf":"NaN","id":42651625}],"con":true,"img":false}]}
{"op":"mcm","clk":"5347721749","pt":1646206310578,"mc":[{"id":"1.195453612","rc":[{"atb":[[10.5,5.6]],"id":42651625}],"con":true,"img":false}]}
{"op":"mcm","clk":"5347722228","pt":1646206324583,"mc":[{"id":"1.195453612","rc":[{"atl":[[36,2.72]],"id":41762566},{"atl":[[2.96,0]],"id":43066529},{"atl":[[75,0.55]],"id":42651625}],"con":true,"img":false}]}
{"op":"mcm","clk":"5347722233","pt":1646206324686,"mc":[{"id":"1.195453612","rc":[{"atl":[[32,2.72]],"id":41762566},{"atl":[[2.76,22.28]],"id":43066529}],"con":true,"img":false}]}
{"op":"mcm","clk":"5347722804","pt":1646206340718,"mc":[{"id":"1.195453612","rc":[{"atl":[[2.72,0]],"id":43167172}],"con":true,"img":false}]}
{"op":"mcm","clk":"5347722807","pt":1646206340820,"mc":[{"id":"1.195453612","rc":[{"atl":[[2.52,62.12]],"id":43167172}],"con":true,"img":false}]}
{"op":"mcm","clk":"5347723348","pt":1646206354452,"mc":[{"id":"1.195453612","rc":[{"atl":[[2.76,0]],"id":43066529}],"con":true,"img":false}]}
{"op":"mcm","clk":"5347723352","pt":1646206354554,"mc":[{"id":"1.195453612","rc":[{"atl":[[2.96,22.28]],"id":43066529}],"con":true,"img":false}]}
{"op":"mcm","clk":"5347724058","pt":1646206372767,"mc":[{"id":"1.195453612","rc":[{"atl":[[65,2.72],[75,0]],"id":42651625},{"spn":17.25,"spf":"NaN","id":42651625}],"con":true,"img":false}]}
{"op":"mcm","clk":"5347726209","pt":1646206431554,"mc":[{"id":"1.195453612","rc":[{"atl":[[65,0],[85,0]],"id":42651625},{"atb":[[1.26,0]],"id":43167173}],"con":true,"img":false}]}
{"op":"mcm","clk":"5347726212","pt":1646206431656,"mc":[{"id":"1.195453612","rc":[{"atl":[[65,2.72],[60,2.72]],"id":42651625},{"atb":[[1.31,227.78]],"id":43167173}],"con":true,"img":false}]}
{"op":"mcm","clk":"5347728864","pt":1646206506542,"mc":[{"id":"1.195453612","rc":[{"atb":[[3.45,0]],"id":41676292}],"con":true,"img":false}]}
{"op":"mcm","clk":"5347728868","pt":1646206506645,"mc":[{"id":"1.195453612","rc":[{"atb":[[3.7,22.28]],"id":41676292}],"con":true,"img":false}]}
{"op":"mcm","clk":"5347729568","pt":1646206524577,"mc":[{"id":"1.195453612","rc":[{"atb":[[1.31,0]],"id":43167173}],"con":true,"img":false}]}
{"op":"mcm","clk":"5347729572","pt":1646206524680,"mc":[{"id":"1.195453612","rc":[{"atb":[[1.26,227.78]],"id":43167173}],"con":true,"img":false}]}
{"op":"mcm","clk":"5347732383","pt":1646206612421,"mc":[{"id":"1.195453612","rc":[{"atb":[[10.5,0]],"id":42651625},{"spn":16.3,"spf":"NaN","id":42651625}],"con":true,"img":false}]}
{"op":"mcm","clk":"5347732388","pt":1646206612550,"mc":[{"id":"1.195453612","rc":[{"atb":[[11,5.6]],"id":42651625}],"con":true,"img":false}]}
{"op":"mcm","clk":"5347735338","pt":1646206692191,"mc":[{"id":"1.195453612","rc":[{"atl":[[32,0]],"id":41762566},{"spn":17.5,"spf":"NaN","id":42651625}],"con":true,"img":false}]}
{"op":"mcm","clk":"5347735346","pt":1646206692243,"mc":[{"id":"1.195453612","rc":[{"atl":[[38,4.69]],"id":41762566}],"con":true,"img":false}]}
{"op":"mcm","clk":"5347736746","pt":1646206723308,"mc":[{"id":"1.195453612","rc":[{"atl":[[60,0]],"id":42651625},{"atl":[[2.78,0]],"id":43167173}],"con":true,"img":false}]}
{"op":"mcm","clk":"5347736752","pt":1646206723410,"mc":[{"id":"1.195453612","rc":[{"atl":[[70,3.78]],"id":42651625},{"atl":[[2.58,57.8]],"id":43167173}],"con":true,"img":false}]}
{"op":"mcm","clk":"5347737217","pt":1646206735361,"mc":[{"id":"1.195453612","rc":[{"atl":[[2.52,28.72]],"id":43167172},{"atl":[[2.58,24.53]],"id":43167173}],"con":true,"img":false}]}
{"op":"mcm","clk":"5347737221","pt":1646206735464,"mc":[{"id":"1.195453612","rc":[{"atl":[[2.72,33.4]],"id":43167172},{"atl":[[2.78,33.27]],"id":43167173}],"con":true,"img":false}]}
{"op":"mcm","clk":"5347738881","pt":1646206778402,"mc":[{"id":"1.195453612","rc":[{"atl":[[2.96,0]],"id":43066529},{"atl":[[70,1.05]],"id":42651625}],"con":true,"img":false}]}
{"op":"mcm","clk":"5347738887","pt":1646206778503,"mc":[{"id":"1.195453612","rc":[{"atl":[[2.76,22.28]],"id":43066529},{"atl":[[65,5.45]],"id":42651625}],"con":true,"img":false}]}
{"op":"mcm","clk":"5347739753","pt":1646206802229,"mc":[{"id":"1.195453612","rc":[{"atl":[[2.72,0]],"id":43167172},{"atl":[[2.78,0]],"id":43167173}],"con":true,"img":false}]}
{"op":"mcm","clk":"5347739761","pt":1646206802331,"mc":[{"id":"1.195453612","rc":[{"atl":[[2.52,62.12]],"id":43167172},{"atl":[[2.58,57.8]],"id":43167173}],"con":true,"img":false}]}
{"op":"mcm","clk":"5347740209","pt":1646206814359,"mc":[{"id":"1.195453612","rc":[{"atl":[[2.76,0]],"id":43066529},{"atb":[[11,0]],"id":42651625},{"atl":[[65,2.72]],"id":42651625},{"atl":[[2.52,28.72]],"id":43167172},{"atl":[[2.58,24.53]],"id":43167173}],"con":true,"img":false}]}
{"op":"mcm","clk":"5347740217","pt":1646206814462,"mc":[{"id":"1.195453612","rc":[{"atl":[[2.96,22.28]],"id":43066529},{"atb":[[10,5.6]],"id":42651625},{"atl":[[55,2.72]],"id":42651625},{"atl":[[2.72,33.4]],"id":43167172},{"atl":[[2.78,33.27]],"id":43167173}],"con":true,"img":false}]}
{"op":"mcm","clk":"5347742652","pt":1646206875943,"mc":[{"id":"1.195453612","rc":[{"atl":[[2.96,0]],"id":43066529},{"spn":17.0,"spf":"NaN","id":42651625},{"atl":[[2.72,0]],"id":43167172}],"con":true,"img":false}]}
{"op":"mcm","clk":"5347742657","pt":1646206876043,"mc":[{"id":"1.195453612","rc":[{"atl":[[2.76,22.28]],"id":43066529},{"atl":[[2.52,62.12]],"id":43167172}],"con":true,"img":false}]}
{"op":"mcm","clk":"5347743153","pt":1646206887970,"mc":[{"id":"1.195453612","rc":[{"atl":[[36,0]],"id":41762566},{"atl":[[2.76,0]],"id":43066529}],"con":true,"img":false}]}
{"op":"mcm","clk":"5347743157","pt":1646206888066,"mc":[{"id":"1.195453612","rc":[{"atl":[[44,2.72]],"id":41762566},{"atl":[[2.96,22.28]],"id":43066529}],"con":true,"img":false}]}
{"op":"mcm","clk":"5347744255","pt":1646206916522,"mc":[{"id":"1.195453612","rc":[{"atl":[[2.78,0]],"id":43167173}],"con":true,"img":false}]}
{"op":"mcm","clk":"5347744261","pt":1646206916629,"mc":[{"id":"1.195453612","rc":[{"atl":[[2.58,57.8]],"id":43167173}],"con":true,"img":false}]}
{"op":"mcm","clk":"5347744725","pt":1646206927146,"mc":[{"id":"1.195453612","rc":[{"atl":[[2.52,28.72]],"id":43167172},{"atl":[[2.58,24.53]],"id":43167173}],"con":true,"img":false}]}
{"op":"mcm","clk":"5347744731","pt":1646206927249,"mc":[{"id":"1.195453612","rc":[{"atl":[[2.72,33.4]],"id":43167172},{"atl":[[2.78,33.27]],"id":43167173}],"con":true,"img":false}]}
{"op":"mcm","clk":"5347745914","pt":1646206955680,"mc":[{"id":"1.195453612","rc":[{"atl":[[38,1.96]],"id":41762566},{"atb":[[10,0]],"id":42651625},{"spn":16.3,"spf":"NaN","id":42651625}],"con":true,"img":false}]}
{"op":"mcm","clk":"5347745918","pt":1646206955783,"mc":[{"id":"1.195453612","rc":[{"atl":[[34,2.72]],"id":41762566},{"atb":[[10.5,5.6]],"id":42651625}],"con":true,"img":false}]}
{"op":"mcm","clk":"5347747428","pt":1646206989343,"mc":[{"id":"1.195453612","rc":[{"atl":[[44,0]],"id":41762566},{"atl":[[2.96,0]],"id":43066529},{"atb":[[10.5,0]],"id":42651625},{"atl":[[2.72,0]],"id":43167172}],"con":true,"img":false}]}
{"op":"mcm","clk":"5347747434","pt":1646206989447,"mc":[{"id":"1.195453612","rc":[{"atl":[[36,2.72]],"id":41762566},{"atl":[[2.76,22.28]],"id":43066529},{"atb":[[11,5.6]],"id":42651625},{"atl":[[2.52,62.12]],"id":43167172}],"con":true,"img":false}]}
{"op":"mcm","clk":"5347748093","pt":1646207006874,"mc":[{"id":"1.195453612","rc":[{"atl":[[2.76,0]],"id":43066529},{"atl":[[55,0]],"id":42651625}],"con":true,"img":false}]}
{"op":"mcm","clk":"5347748101","pt":1646207006977,"mc":[{"id":"1.195453612","rc":[{"atl":[[2.96,22.28]],"id":43066529},{"atl":[[65,5.45]],"id":42651625}],"con":true,"img":false}]}
{"op":"mcm","clk":"5347748852","pt":1646207025871,"mc":[{"id":"1.195453612","rc":[{"atl":[[34,0]],"id":41762566},{"spn":17.5,"spf":"NaN","id":42651625}],"con":true,"img":false}]}
{"op":"mcm","clk":"5347748858","pt":1646207025972,"mc":[{"id":"1.195453612","rc":[{"atl":[[30,2.72]],"id":41762566}],"con":true,"img":false}]}
{"op":"mcm","clk":"5347750403","pt":1646207068165,"mc":[{"id":"1.195453612","rc":[{"atb":[[11,0]],"id":42651625},{"atl":[[65,2.72]],"id":42651625}],"con":true,"img":false}]}
{"op":"mcm","clk":"5347750406","pt":1646207068262,"mc":[{"id":"1.195453612","rc":[{"atb":[[10,5.6]],"id":42651625},{"atl":[[55,2.72]],"id":42651625}],"con":true,"img":false}]}
{"op":"mcm","clk":"5347751305","pt":1646207090793,"mc":[{"id":"1.195453612","rc":[{"spn":17.0,"spf":"NaN","id":42651625},{"atb":[[1.26,0]],"id":43167173}],"con":true,"img":false}]}
{"op":"mcm","clk":"5347751307","pt":1646207090897,"mc":[{"id":"1.195453612","rc":[{"atb":[[1.31,227.78]],"id":43167173}],"con":true,"img":false}]}
{"op":"mcm","clk":"5347754958","pt":1646207163419,"mc":[{"id":"1.195453612","rc":[{"atb":[[3.65,0]],"id":41762566}],"con":true,"img":false}]}
{"op":"mcm","clk":"5347754970","pt":1646207163525,"mc":[{"id":"1.195453612","rc":[{"atb":[[4.1,21.16]],"id":41762566}],"con":true,"img":false}]}
{"op":"mcm","clk":"5347756885","pt":1646207188961,"mc":[{"id":"1.195453612","rc":[{"atb":[[10,0]],"id":42651625}],"con":true,"img":false}]}
{"op":"mcm","clk":"5347756894","pt":1646207189065,"mc":[{"id":"1.195453612","rc":[{"atb":[[10.5,5.6]],"id":42651625}],"con":true,"img":false}]}
{"op":"mcm","clk":"5347757568","pt":1646207199750,"mc":[{"id":"1.195453612","rc":[{"atb":[[4.1,0]],"id":41762566},{"atb":[[1.31,0]],"id":43167173}],"con":true,"img":false}]}
{"op":"mcm","clk":"5347757574","pt":1646207199852,"mc":[{"id":"1.195453612","rc":[{"atb":[[3.65,21.16]],"id":41762566},{"atb":[[1.26,227.78]],"id":43167173}],"con":true,"img":false}]}
{"op":"mcm","clk":"5347759788","pt":1646207237022,"mc":[{"id":"1.195453612","rc":[{"atb":[[10.5,0]],"id":42651625},{"spn":16.3,"spf":"NaN","id":42651625}],"con":true,"img":false}]}
{"op":"mcm","clk":"5347759791","pt":1646207237126,"mc":[{"id":"1.195453612","rc":[{"atb":[[11,5.6]],"id":42651625}],"con":true,"img":false}]}
{"op":"mcm","clk":"5347761217","pt":1646207264677,"mc":[{"id":"1.195453612","rc":[{"atl":[[55,0]],"id":42651625}],"con":true,"img":false}]}
{"op":"mcm","clk":"5347761223","pt":1646207264780,"mc":[{"id":"1.195453612","rc":[{"atl":[[65,5.45]],"id":42651625}],"con":true,"img":false}]}
{"op":"mcm","clk":"5347762046","pt":1646207280474,"mc":[{"id":"1.195453612","rc":[{"atl":[[30,0]],"id":41762566}],"con":true,"img":false}]}
{"op":"mcm","clk":"5347762052","pt":1646207280577,"mc":[{"id":"1.195453612","rc":[{"atl":[[34,2.72]],"id":41762566}],"con":true,"img":false}]}
{"op":"mcm","clk":"5347764024","pt":1646207319070,"mc":[{"id":"1.195453612","rc":[{"atb":[[11,0]],"id":42651625}],"con":true,"img":false}]}
{"op":"mcm","clk":"5347764029","pt":1646207319174,"mc":[{"id":"1.195453612","rc":[{"atb":[[10,5.6]],"id":42651625}],"con":true,"img":false}]}
{"op":"mcm","clk":"5347764596","pt":1646207330377,"mc":[{"id":"1.195453612","rc":[{"atl":[[65,2.72]],"id":42651625}],"con":true,"img":false}]}
{"op":"mcm","clk":"5347764601","pt":1646207330480,"mc":[{"id":"1.195453612","rc":[{"atl":[[60,2.72]],"id":42651625}],"con":true,"img":false}]}
{"op":"mcm","clk":"5347771001","pt":1646207461978,"mc":[{"id":"1.195453612","rc":[{"atb":[[2.06,49.98]],"id":41762566},{"atl":[[75,2]],"id":41762566},{"atl":[[7.6,15.15]],"id":43066529},{"atb":[[4,33.33]],"id":42651625},{"atl":[[48,2.13]],"id":42651625},{"spn":17.0,"spf":"NaN","id":42651625},{"atb":[[2.38,72.46]],"id":41676292},{"atl":[[10,3.83]],"id":41676292},{"spn":7.0,"spf":"NaN","id":41676292},{"atb":[[1.16,625]],"id":43167172},{"atl":[[3.1,47.62]],"id":43167172},{"atb":[[1.21,476.19]],"id":43167173},{"atl":[[13,8.33]],"id":43167173}],"con":true,"img":false}]}
{"op":"mcm","clk":"5347771076","pt":1646207463368,"mc":[{"id":"1.195453612","rc":[{"atl":[[2.52,28.72]],"id":43167172}],"con":true,"img":false}]}
{"op":"mcm","clk":"5347771081","pt":1646207463471,"mc":[{"id":"1.195453612","rc":[{"atl":[[2.72,33.4]],"id":43167172}],"con":true,"img":false}]}
{"op":"mcm","clk":"5347771151","pt":1646207464753,"mc":[{"id":"1.195453612","rc":[{"atl":[[3.1,0]],"id":43167172}],"con":true,"img":false}]}
{"op":"mcm","clk":"5347771156","pt":1646207464856,"mc":[{"id":"1.195453612","rc":[{"atl":[[10.5,10.53]],"id":43167172}],"con":true,"img":false}]}
{"op":"mcm","clk":"5347771270","pt":1646207467069,"mc":[{"id":"1.195453612","rc":[{"atl":[[14,7.66]],"id":41676292}],"con":true,"img":false}]}
{"op":"mcm","clk":"5347771273","pt":1646207467172,"mc":[{"id":"1.195453612","rc":[{"atl":[[10,0]],"id":41676292},{"atl":[[42,2.44],[13,0]],"id":43167173}],"con":true,"img":false}]}
{"op":"mcm","clk":"5347771358","pt":1646207468975,"mc":[{"id":"1.195453612","rc":[{"atl":[[4,21.83],[3.4,0]],"id":43066529},{"atb":[[3.7,0]],"id":41676292},{"atl":[[2.78,0]],"id":43167173}],"con":true,"img":false}]}
{"op":"mcm","clk":"5347771363","pt":1646207469068,"mc":[{"id":"1.195453612","rc":[{"atb":[[3.2,22.28]],"id":41676292},{"atl":[[2.98,33.27]],"id":43167173}],"con":true,"img":false}]}
{"op":"mcm","clk":"5347771903","pt":1646207479081,"mc":[{"id":"1.195453612","rc":[{"atb":[[4,0]],"id":41676292}],"con":true,"img":false}]}
{"op":"mcm","clk":"5347771909","pt":1646207479182,"mc":[{"id":"1.195453612","rc":[{"atb":[[3.7,15.06]],"id":41676292}],"con":true,"img":false}]}
{"op":"mcm","clk":"5347771950","pt":1646207480063,"mc":[{"id":"1.195453612","rc":[{"atl":[[2.58,0]],"id":43167173}],"con":true,"img":false}]}
{"op":"mcm","clk":"5347771956","pt":1646207480158,"mc":[{"id":"1.195453612","rc":[{"atl":[[2.78,24.53]],"id":43167173}],"con":true,"img":false}]}
{"op":"mcm","clk":"5347772393","pt":1646207488604,"mc":[{"id":"1.195453612","rc":[{"atb":[[1.26,0]],"id":43167173}],"con":true,"img":false}]}
{"op":"mcm","clk":"5347772400","pt":1646207488705,"mc":[{"id":"1.195453612","rc":[{"atb":[[1.31,227.78]],"id":43167173}],"con":true,"img":false}]}
{"op":"mcm","clk":"5347772529","pt":1646207490776,"mc":[{"id":"1.195453612","rc":[{"atl":[[34,0]],"id":41762566}],"con":true,"img":false}]}
{"op":"mcm","clk":"5347772539","pt":1646207490869,"mc":[{"id":"1.195453612","rc":[{"atl":[[25,2.72]],"id":41762566}],"con":true,"img":false}]}
{"op":"mcm","clk":"5347772657","pt":1646207492670,"mc":[{"id":"1.195453612","rc":[{"atb":[[10,0]],"id":42651625}],"con":true,"img":false}]}
{"op":"mcm","clk":"5347772662","pt":1646207492773,"mc":[{"id":"1.195453612","rc":[{"atb":[[11,5.6]],"id":42651625}],"con":true,"img":false}]}
{"op":"mcm","clk":"5347772809","pt":1646207495083,"mc":[{"id":"1.195453612","rc":[{"atb":[[1.31,0]],"id":43167172}],"con":true,"img":false}]}
{"op":"mcm","clk":"5347772817","pt":1646207495186,"mc":[{"id":"1.195453612","rc":[{"atb":[[1.32,86.21]],"id":43167172}],"con":true,"img":false}]}
{"op":"mcm","clk":"5347772900","pt":1646207496987,"mc":[{"id":"1.195453612","rc":[{"atl":[[30,0]],"id":41676292}],"con":true,"img":false}]}
{"op":"mcm","clk":"5347772903","pt":1646207497090,"mc":[{"id":"1.195453612","rc":[{"atl":[[13.5,2.72]],"id":41676292}],"con":true,"img":false}]}
{"op":"mcm","clk":"5347773014","pt":1646207499094,"mc":[{"id":"1.195453612","rc":[{"atb":[[4.3,30.3],[2.06,0]],"id":41762566},{"atl":[[6.4,18.52],[7.6,0]],"id":43066529},{"atb":[[2.5,66.67],[2.38,0]],"id":41676292}],"con":true,"img":false}]}
{"op":"mcm","clk":"5347773626","pt":1646207509585,"mc":[{"id":"1.195453612","rc":[{"atl":[[2.96,0]],"id":43066529},{"atl":[[2.78,0]],"id":43167173}],"con":true,"img":false}]}
{"op":"mcm","clk":"5347773634","pt":1646207509690,"mc":[{"id":"1.195453612","rc":[{"atl":[[2.76,22.28]],"id":43066529},{"atl":[[2.58,24.53]],"id":43167173}],"con":true,"img":false}]}
{"op":"mcm","clk":"5347774186","pt":1646207519299,"mc":[{"id":"1.195453612","rc":[{"atl":[[36,0]],"id":41762566}],"con":true,"img":false}]}
{"op":"mcm","clk":"5347774191","pt":1646207519399,"mc":[{"id":"1.195453612","rc":[{"atl":[[23,2.72]],"id":41762566}],"con":true,"img":false}]}
{"op":"mcm","clk":"5347774274","pt":1646207520938,"mc":[{"id":"1.195453612","rc":[{"atl":[[2.76,0]],"id":43066529},{"atl":[[2.58,0]],"id":43167173}],"con":true,"img":false}]}
{"op":"mcm","clk":"5347774281","pt":1646207520997,"mc":[{"id":"1.195453612","rc":[{"atl":[[2.96,22.28]],"id":43066529},{"atl":[[2.78,24.53]],"id":43167173}],"con":true,"img":false}]}
{"op":"mcm","clk":"5347774335","pt":1646207522026,"mc":[{"id":"1.195453612","rc":[{"atb":[[1.41,0]],"id":43066529},{"spn":17.5,"spf":"NaN","id":42651625},{"spn":7.1,"spf":"NaN","id":41676292},{"atb":[[1.26,0]],"id":43167172},{"spn":1.92,"spf":"NaN","id":43167172},{"spn":1.98,"spf":"NaN","id":43167173}],"con":true,"img":false}]}
{"op":"mcm","clk":"5347774341","pt":1646207522129,"mc":[{"id":"1.195453612","rc":[{"atb":[[1.46,158.84]],"id":43066529},{"atb":[[1.31,220.96]],"id":43167172}],"con":true,"img":false}]}
{"op":"mcm","clk":"5347774551","pt":1646207525801,"mc":[{"id":"1.195453612","rc":[{"atl":[[34,0],[13.5,7.09]],"id":41676292}],"con":true,"img":false}]}
{"op":"mcm","clk":"5347775177","pt":1646207536932,"mc":[{"id":"1.195453612","rc":[{"atb":[[1.32,0]],"id":43167172}],"con":true,"img":false}]}
{"op":"mcm","clk":"5347775189","pt":1646207537034,"mc":[{"id":"1.195453612","rc":[{"atb":[[1.34,86.21]],"id":43167172}],"con":true,"img":false}]}
{"op":"mcm","clk":"5347776015","pt":1646207551068,"mc":[{"id":"1.195453612","rc":[{"atl":[[2.96,0]],"id":43066529},{"atl":[[2.78,0]],"id":43167173}],"con":true,"img":false}]}
{"op":"mcm","clk":"5347776020","pt":1646207551172,"mc":[{"id":"1.195453612","rc":[{"atl":[[2.76,22.28]],"id":43066529},{"atl":[[2.58,24.53]],"id":43167173}],"con":true,"img":false}]}
{"op":"mcm","clk":"5347776138","pt":1646207553385,"mc":[{"id":"1.195453612","rc":[{"atb":[[2.5,0],[2.38,72.46]],"id":41676292}],"con":true,"img":false}]}
{"op":"mcm","clk":"5347776146","pt":1646207553440,"mc":[{"id":"1.195453612","rc":[{"atb":[[3.65,0]],"id":41762566}],"con":true,"img":false}]}
{"op":"mcm","clk":"5347776152","pt":1646207553546,"mc":[{"id":"1.195453612","rc":[{"atb":[[4.1,21.16]],"id":41762566}],"con":true,"img":false}]}
{"op":"mcm","clk":"5347776292","pt":1646207555654,"mc":[{"id":"1.195453612","rc":[{"atl":[[2.98,0]],"id":43167173}],"con":true,"img":false}]}
{"op":"mcm","clk":"5347776297","pt":1646207555756,"mc":[{"id":"1.195453612","rc":[{"atl":[[2.78,33.27]],"id":43167173}],"con":true,"img":false}]}
{"op":"mcm","clk":"5347776798","pt":1646207564792,"mc":[{"id":"1.195453612","rc":[{"atl":[[4,0],[3.4,27.29]],"id":43066529}],"con":true,"img":false}]}
{"op":"mcm","clk":"5347778285","pt":1646207592579,"mc":[{"id":"1.195453612","rc":[{"spn":2.13,"spf":"NaN","id":43066529},{"atl":[[60,0]],"id":42651625},{"spn":1.93,"spf":"NaN","id":43167172},{"spn":1.97,"spf":"NaN","id":43167173}],"con":true,"img":false}]}
{"op":"mcm","clk":"5347778290","pt":1646207592680,"mc":[{"id":"1.195453612","rc":[{"atl":[[46,2.72]],"id":42651625}],"con":true,"img":false}]}
{"op":"mcm","clk":"5347779949","pt":1646207622199,"mc":[{"id":"1.195453612","rc":[{"atl":[[46,0]],"id":42651625}],"con":true,"img":false}]}
{"op":"mcm","clk":"5347779954","pt":1646207622301,"mc":[{"id":"1.195453612","rc":[{"atl":[[44,2.72]],"id":42651625}],"con":true,"img":false}]}
{"op":"mcm","clk":"5347781570","pt":1646207652741,"mc":[{"id":"1.195453612","rc":[{"atl":[[44,0]],"id":42651625}],"con":true,"img":false}]}
{"op":"mcm","clk":"5347781576","pt":1646207652843,"mc":[{"id":"1.195453612","rc":[{"atl":[[42,2.72]],"id":42651625}],"con":true,"img":false}]}
{"op":"mcm","clk":"5347782444","pt":1646207670084,"mc":[{"id":"1.195453612","rc":[{"atl":[[2.76,0]],"id":43066529}],"con":true,"img":false}]}
{"op":"mcm","clk":"5347782450","pt":1646207670188,"mc":[{"id":"1.195453612","rc":[{"atl":[[2.96,22.28]],"id":43066529}],"con":true,"img":false}]}
{"op":"mcm","clk":"5347782612","pt":1646207673377,"mc":[{"id":"1.195453612","rc":[{"atb":[[4,66.65],[4.3,0]],"id":41762566},{"atl":[[6.4,0],[7.6,15.15]],"id":43066529}],"con":true,"img":false}]}
{"op":"mcm","clk":"5347783070","pt":1646207683608,"mc":[{"id":"1.195453612","rc":[{"atl":[[42,0]],"id":42651625}],"con":true,"img":false}]}
{"op":"mcm","clk":"5347783076","pt":1646207683664,"mc":[{"id":"1.195453612","rc":[{"atl":[[40,2.72]],"id":42651625}],"con":true,"img":false}]}
{"op":"mcm","clk":"5347784509","pt":1646207713905,"mc":[{"id":"1.195453612","rc":[{"spn":2.14,"spf":"NaN","id":43066529},{"atl":[[40,0]],"id":42651625},{"atb":[[1.36,247.55],[1.31,0]],"id":43167173}],"con":true,"img":false}]}
{"op":"mcm","clk":"5347784513","pt":1646207714006,"mc":[{"id":"1.195453612","rc":[{"atl":[[38,4.69]],"id":42651625}],"con":true,"img":false}]}
{"op":"mcm","clk":"5347785090","pt":1646207724754,"mc":[{"id":"1.195453612","rc":[{"atl":[[38,1.96]],"id":42651625}],"con":true,"img":false}]}
{"op":"mcm","clk":"5347785097","pt":1646207724856,"mc":[{"id":"1.195453612","rc":[{"atl":[[46,2.72]],"id":42651625}],"con":true,"img":false}]}
{"op":"mcm","clk":"5347785912","pt":1646207740558,"mc":[{"id":"1.195453612","rc":[{"atl":[[2.96,0]],"id":43066529}],"con":true,"img":false}]}
{"op":"mcm","clk":"5347785920","pt":1646207740660,"mc":[{"id":"1.195453612","rc":[{"atl":[[2.76,22.28]],"id":43066529}],"con":true,"img":false}]}
{"op":"mcm","clk":"5347786595","pt":1646207754555,"mc":[{"id":"1.195453612","rc":[{"atl":[[46,0]],"id":42651625}],"con":true,"img":false}]}
{"op":"mcm","clk":"5347786601","pt":1646207754659,"mc":[{"id":"1.195453612","rc":[{"atl":[[44,2.72]],"id":42651625}],"con":true,"img":false}]}
{"op":"mcm","clk":"5347788099","pt":1646207784893,"mc":[{"id":"1.195453612","rc":[{"spn":2.13,"spf":"NaN","id":43066529},{"atl":[[44,0]],"id":42651625}],"con":true,"img":false}]}
{"op":"mcm","clk":"5347788103","pt":1646207784994,"mc":[{"id":"1.195453612","rc":[{"atl":[[42,2.72]],"id":42651625}],"con":true,"img":false}]}
{"op":"mcm","clk":"5347789479","pt":1646207814546,"mc":[{"id":"1.195453612","rc":[{"atl":[[42,0]],"id":42651625}],"con":true,"img":false}]}
{"op":"mcm","clk":"5347789485","pt":1646207814648,"mc":[{"id":"1.195453612","rc":[{"atl":[[40,2.72]],"id":42651625}],"con":true,"img":false}]}
{"op":"mcm","clk":"5347791074","pt":1646207845781,"mc":[{"id":"1.195453612","rc":[{"atl":[[40,0]],"id":42651625}],"con":true,"img":false}]}
{"op":"mcm","clk":"5347791076","pt":1646207845886,"mc":[{"id":"1.195453612","rc":[{"atl":[[38,4.69]],"id":42651625}],"con":true,"img":false}]}
{"op":"mcm","clk":"5347791550","pt":1646207856671,"mc":[{"id":"1.195453612","rc":[{"atl":[[38,1.96]],"id":42651625}],"con":true,"img":false}]}
{"op":"mcm","clk":"5347791556","pt":1646207856772,"mc":[{"id":"1.195453612","rc":[{"atl":[[46,2.72]],"id":42651625}],"con":true,"img":false}]}
{"op":"mcm","clk":"5347792787","pt":1646207885927,"mc":[{"id":"1.195453612","rc":[{"atl":[[46,0]],"id":42651625}],"con":true,"img":false}]}
{"op":"mcm","clk":"5347792795","pt":1646207886026,"mc":[{"id":"1.195453612","rc":[{"atl":[[44,2.72]],"id":42651625}],"con":true,"img":false}]}
{"op":"mcm","clk":"5347793943","pt":1646207916582,"mc":[{"id":"1.195453612","rc":[{"atl":[[44,0]],"id":42651625}],"con":true,"img":false}]}
{"op":"mcm","clk":"5347793946","pt":1646207916638,"mc":[{"id":"1.195453612","rc":[{"atl":[[42,2.72]],"id":42651625}],"con":true,"img":false}]}
{"op":"mcm","clk":"5347795135","pt":1646207947218,"mc":[{"id":"1.195453612","rc":[{"atl":[[42,0]],"id":42651625}],"con":true,"img":false}]}
{"op":"mcm","clk":"5347795141","pt":1646207947275,"mc":[{"id":"1.195453612","rc":[{"atl":[[40,2.72]],"id":42651625}],"con":true,"img":false}]}
{"op":"mcm","clk":"5347796350","pt":1646207977031,"mc":[{"id":"1.195453612","rc":[{"atl":[[40,0]],"id":42651625}],"con":true,"img":false}]}
{"op":"mcm","clk":"5347796354","pt":1646207977133,"mc":[{"id":"1.195453612","rc":[{"atl":[[38,4.69]],"id":42651625}],"con":true,"img":false}]}
{"op":"mcm","clk":"5347796825","pt":1646207987638,"mc":[{"id":"1.195453612","rc":[{"atl":[[38,1.96]],"id":42651625}],"con":true,"img":false}]}
{"op":"mcm","clk":"5347796828","pt":1646207987740,"mc":[{"id":"1.195453612","rc":[{"atl":[[46,2.72]],"id":42651625}],"con":true,"img":false}]}
{"op":"mcm","clk":"5347798105","pt":1646208016687,"mc":[{"id":"1.195453612","rc":[{"atl":[[46,0]],"id":42651625}],"con":true,"img":false}]}
{"op":"mcm","clk":"5347798107","pt":1646208016790,"mc":[{"id":"1.195453612","rc":[{"atl":[[44,2.72]],"id":42651625}],"con":true,"img":false}]}
{"op":"mcm","clk":"5347799330","pt":1646208046670,"mc":[{"id":"1.195453612","rc":[{"atl":[[44,0]],"id":42651625}],"con":true,"img":false}]}
{"op":"mcm","clk":"5347799334","pt":1646208046772,"mc":[{"id":"1.195453612","rc":[{"atl":[[42,2.72]],"id":42651625}],"con":true,"img":false}]}
{"op":"mcm","clk":"5347800552","pt":1646208076804,"mc":[{"id":"1.195453612","rc":[{"atl":[[42,0]],"id":42651625}],"con":true,"img":false}]}
{"op":"mcm","clk":"5347800558","pt":1646208076907,"mc":[{"id":"1.195453612","rc":[{"atl":[[40,2.72]],"id":42651625}],"con":true,"img":false}]}
{"op":"mcm","clk":"5347801591","pt":1646208106938,"mc":[{"id":"1.195453612","rc":[{"atl":[[40,0]],"id":42651625}],"con":true,"img":false}]}
{"op":"mcm","clk":"5347801594","pt":1646208107039,"mc":[{"id":"1.195453612","rc":[{"atl":[[38,4.69]],"id":42651625}],"con":true,"img":false}]}
{"op":"mcm","clk":"5347802010","pt":1646208117936,"mc":[{"id":"1.195453612","rc":[{"atl":[[38,1.96]],"id":42651625}],"con":true,"img":false}]}
{"op":"mcm","clk":"5347802015","pt":1646208118041,"mc":[{"id":"1.195453612","rc":[{"atl":[[46,2.72]],"id":42651625}],"con":true,"img":false}]}
{"op":"mcm","clk":"5347803218","pt":1646208148102,"mc":[{"id":"1.195453612","rc":[{"atl":[[46,0]],"id":42651625}],"con":true,"img":false}]}
{"op":"mcm","clk":"5347803221","pt":1646208148206,"mc":[{"id":"1.195453612","rc":[{"atl":[[44,2.72]],"id":42651625}],"con":true,"img":false}]}
{"op":"mcm","clk":"5347804413","pt":1646208177806,"mc":[{"id":"1.195453612","rc":[{"atl":[[44,0]],"id":42651625}],"con":true,"img":false}]}
{"op":"mcm","clk":"5347804422","pt":1646208177902,"mc":[{"id":"1.195453612","rc":[{"atl":[[42,2.72]],"id":42651625}],"con":true,"img":false}]}
{"op":"mcm","clk":"5347805775","pt":1646208208376,"mc":[{"id":"1.195453612","rc":[{"atl":[[42,0]],"id":42651625}],"con":true,"img":false}]}
{"op":"mcm","clk":"5347805783","pt":1646208208483,"mc":[{"id":"1.195453612","rc":[{"atl":[[40,2.72]],"id":42651625}],"con":true,"img":false}]}
{"op":"mcm","clk":"5347806914","pt":1646208238889,"mc":[{"id":"1.195453612","rc":[{"atl":[[40,0]],"id":42651625}],"con":true,"img":false}]}
{"op":"mcm","clk":"5347806919","pt":1646208238992,"mc":[{"id":"1.195453612","rc":[{"atl":[[38,4.69]],"id":42651625}],"con":true,"img":false}]}
{"op":"mcm","clk":"5347807365","pt":1646208250087,"mc":[{"id":"1.195453612","rc":[{"atl":[[38,1.96]],"id":42651625}],"con":true,"img":false}]}
{"op":"mcm","clk":"5347807372","pt":1646208250191,"mc":[{"id":"1.195453612","rc":[{"atl":[[46,2.72]],"id":42651625}],"con":true,"img":false}]}
{"op":"mcm","clk":"5347808635","pt":1646208280766,"mc":[{"id":"1.195453612","rc":[{"atl":[[46,0]],"id":42651625}],"con":true,"img":false}]}
{"op":"mcm","clk":"5347808641","pt":1646208280862,"mc":[{"id":"1.195453612","rc":[{"atl":[[44,2.72]],"id":42651625}],"con":true,"img":false}]}
{"op":"mcm","clk":"5347809927","pt":1646208311184,"mc":[{"id":"1.195453612","rc":[{"atl":[[44,0]],"id":42651625}],"con":true,"img":false}]}
{"op":"mcm","clk":"5347809932","pt":1646208311288,"mc":[{"id":"1.195453612","rc":[{"atl":[[42,2.72]],"id":42651625}],"con":true,"img":false}]}
{"op":"mcm","clk":"5347810876","pt":1646208335043,"mc":[{"id":"1.195453612","rc":[{"atb":[[4,33.32],[4.4,29.41]],"id":41762566}],"con":true,"img":false}]}
{"op":"mcm","clk":"5347811127","pt":1646208340867,"mc":[{"id":"1.195453612","rc":[{"atl":[[42,0]],"id":42651625}],"con":true,"img":false}]}
{"op":"mcm","clk":"5347811135","pt":1646208340922,"mc":[{"id":"1.195453612","rc":[{"atl":[[40,2.72]],"id":42651625}],"con":true,"img":false}]}
{"op":"mcm","clk":"5347812483","pt":1646208369097,"mc":[{"id":"1.195453612","rc":[{"atb":[[5.1,1.67]],"id":41762566},{"atb":[[3.75,1.67]],"id":41676292}],"con":true,"img":false}]}
{"op":"mcm","clk":"5347812587","pt":1646208371360,"mc":[{"id":"1.195453612","rc":[{"spn":11.05,"spf":"NaN","id":41762566},{"atl":[[40,0]],"id":42651625},{"spn":7.12,"spf":"NaN","id":41676292}],"con":true,"img":false}]}
{"op":"mcm","clk":"5347812590","pt":1646208371463,"mc":[{"id":"1.195453612","rc":[{"atl":[[38,4.69]],"id":42651625}],"con":true,"img":false}]}
{"op":"mcm","clk":"5347812987","pt":1646208381910,"mc":[{"id":"1.195453612","rc":[{"atl":[[38,1.96]],"id":42651625}],"con":true,"img":false}]}
{"op":"mcm","clk":"5347812990","pt":1646208382010,"mc":[{"id":"1.195453612","rc":[{"atl":[[46,2.72]],"id":42651625}],"con":true,"img":false}]}
{"op":"mcm","clk":"5347813343","pt":1646208389612,"mc":[{"id":"1.195453612","marketDefinition":{"bspMarket":true,"turnInPlayEnabled":false,"persistenceEnabled":false,"marketBaseRate":7.0,"eventId":"31272494","eventTypeId":"4339","numberOfWinners":2,"bettingType":"ODDS","marketType":"PLACE","marketTime":"2022-03-02T08:51:00.000Z","suspendTime":"2022-03-02T08:51:00.000Z","bspReconciled":false,"complete":true,"inPlay":false,"crossMatching":true,"runnersVoidable":false,"numberOfActiveRunners":6,"betDelay":0,"status":"OPEN","runners":[{"status":"ACTIVE","sortPriority":1,"id":43066529,"name":"1. Piopio"},{"status":"ACTIVE","sortPriority":2,"id":41676292,"name":"2. Jasper Bale"},{"status":"ACTIVE","sortPriority":3,"id":41762566,"name":"3. Afro Boy"},{"status":"ACTIVE","sortPriority":4,"id":42651625,"name":"4. Average Axel"},{"status":"ACTIVE","sortPriority":5,"id":43167172,"name":"6. Fancy Like"},{"status":"ACTIVE","sortPriority":6,"id":43167173,"name":"8. Simon Rose"}],"regulators":["MR_INT"],"venue":"Traralgon","countryCode":"AU","discountAllowed":true,"timezone":"Australia/Sydney","openDate":"2022-03-02T08:31:00.000Z","version":4382425393,"name":"To Be Placed","eventName":"Traralgon (AUS) 2nd Mar"},"rc":[],"con":true,"img":false}]}
{"op":"mcm","clk":"5347813378","pt":1646208390410,"mc":[{"id":"1.195453612","rc":[{"atl":[[6.6,17.86]],"id":43066529}],"con":true,"img":false}]}
{"op":"mcm","clk":"5347813383","pt":1646208390514,"mc":[{"id":"1.195453612","rc":[{"atl":[[7.6,0]],"id":43066529}],"con":true,"img":false}]}
{"op":"mcm","clk":"5347814223","pt":1646208410529,"mc":[{"id":"1.195453612","rc":[{"atl":[[46,0]],"id":42651625}],"con":true,"img":false}]}
{"op":"mcm","clk":"5347814232","pt":1646208410632,"mc":[{"id":"1.195453612","rc":[{"atl":[[44,2.72]],"id":42651625}],"con":true,"img":false}]}
{"op":"mcm","clk":"5347815473","pt":1646208440903,"mc":[{"id":"1.195453612","rc":[{"atl":[[44,0]],"id":42651625}],"con":true,"img":false}]}
{"op":"mcm","clk":"5347815481","pt":1646208441013,"mc":[{"id":"1.195453612","rc":[{"atl":[[42,2.72]],"id":42651625}],"con":true,"img":false}]}
{"op":"mcm","clk":"5347816081","pt":1646208455098,"mc":[{"id":"1.195453612","rc":[{"atb":[[4.1,53.42],[4.4,0]],"id":41762566}],"con":true,"img":false}]}
{"op":"mcm","clk":"5347816325","pt":1646208461527,"mc":[{"id":"1.195453612","rc":[{"atb":[[1.54,13.93]],"id":43066529},{"atb":[[3.75,4.4]],"id":41676292},{"atb":[[1.37,20.34]],"id":43167172},{"atb":[[1.39,19.29]],"id":43167173}],"con":true,"img":false}]}
{"op":"mcm","clk":"5347816773","pt":1646208471104,"mc":[{"id":"1.195453612","rc":[{"atl":[[42,0]],"id":42651625}],"con":true,"img":false}]}
{"op":"mcm","clk":"5347816780","pt":1646208471208,"mc":[{"id":"1.195453612","rc":[{"atl":[[40,2.72]],"id":42651625}],"con":true,"img":false}]}
{"op":"mcm","clk":"5347818095","pt":1646208501141,"mc":[{"id":"1.195453612","rc":[{"spn":2.15,"spf":"NaN","id":43066529},{"atl":[[40,0]],"id":42651625},{"spn":1.94,"spf":"NaN","id":43167172},{"spn":1.98,"spf":"NaN","id":43167173}],"con":true,"img":false}]}
{"op":"mcm","clk":"5347818098","pt":1646208501244,"mc":[{"id":"1.195453612","rc":[{"atl":[[38,4.69]],"id":42651625}],"con":true,"img":false}]}
{"op":"mcm","clk":"5347818532","pt":1646208512152,"mc":[{"id":"1.195453612","rc":[{"atl":[[38,1.96]],"id":42651625}],"con":true,"img":false}]}
{"op":"mcm","clk":"5347818534","pt":1646208512249,"mc":[{"id":"1.195453612","rc":[{"atl":[[46,2.72]],"id":42651625}],"con":true,"img":false}]}
{"op":"mcm","clk":"5347819847","pt":1646208541985,"mc":[{"id":"1.195453612","rc":[{"atl":[[46,0]],"id":42651625}],"con":true,"img":false}]}
{"op":"mcm","clk":"5347819851","pt":1646208542081,"mc":[{"id":"1.195453612","rc":[{"atl":[[44,2.72]],"id":42651625}],"con":true,"img":false}]}
{"op":"mcm","clk":"5347820392","pt":1646208555882,"mc":[{"id":"1.195453612","rc":[{"atb":[[4.1,21.16],[4.4,29.41]],"id":41762566},{"atl":[[21,8.63],[14,0]],"id":41676292},{"atl":[[10.5,0],[7.8,14.71]],"id":43167172},{"atl":[[65,2],[42,0]],"id":43167173}],"con":true,"img":false}]}
{"op":"mcm","clk":"5347820421","pt":1646208556702,"mc":[{"id":"1.195453612","rc":[{"atl":[[13.5,2.72]],"id":41676292}],"con":true,"img":false}]}
{"op":"mcm","clk":"5347820427","pt":1646208556805,"mc":[{"id":"1.195453612","rc":[{"atl":[[15,4.36]],"id":41676292}],"con":true,"img":false}]}
{"op":"mcm","clk":"5347821025","pt":1646208572411,"mc":[{"id":"1.195453612","rc":[{"atl":[[44,0]],"id":42651625}],"con":true,"img":false}]}
{"op":"mcm","clk":"5347821031","pt":1646208572512,"mc":[{"id":"1.195453612","rc":[{"atl":[[42,2.72]],"id":42651625}],"con":true,"img":false}]}
{"op":"mcm","clk":"5347822325","pt":1646208602361,"mc":[{"id":"1.195453612","rc":[{"atl":[[42,0]],"id":42651625}],"con":true,"img":false}]}
{"op":"mcm","clk":"5347822330","pt":1646208602464,"mc":[{"id":"1.195453612","rc":[{"atl":[[40,2.72]],"id":42651625}],"con":true,"img":false}]}
{"op":"mcm","clk":"5347823782","pt":1646208632091,"mc":[{"id":"1.195453612","rc":[{"atl":[[40,0]],"id":42651625}],"con":true,"img":false}]}
{"op":"mcm","clk":"5347823786","pt":1646208632194,"mc":[{"id":"1.195453612","rc":[{"atl":[[38,4.69]],"id":42651625}],"con":true,"img":false}]}
{"op":"mcm","clk":"5347824276","pt":1646208643224,"mc":[{"id":"1.195453612","rc":[{"atl":[[38,1.96]],"id":42651625}],"con":true,"img":false}]}
{"op":"mcm","clk":"5347824279","pt":1646208643278,"mc":[{"id":"1.195453612","rc":[{"atl":[[46,2.72]],"id":42651625}],"con":true,"img":false}]}
{"op":"mcm","clk":"5347824377","pt":1646208645387,"mc":[{"id":"1.195453612","rc":[{"atb":[[1.54,29.4]],"id":43066529}],"con":true,"img":false}]}
{"op":"mcm","clk":"5347824386","pt":1646208645594,"mc":[{"id":"1.195453612","rc":[{"atb":[[1.39,40.71]],"id":43167173}],"con":true,"img":false}]}
{"op":"mcm","clk":"5347824401","pt":1646208646005,"mc":[{"id":"1.195453612","rc":[{"atb":[[3.75,7.44]],"id":41676292}],"con":true,"img":false}]}
{"op":"mcm","clk":"5347824404","pt":1646208646107,"mc":[{"id":"1.195453612","rc":[{"atb":[[1.37,42.91]],"id":43167172}],"con":true,"img":false}]}
{"op":"mcm","clk":"5347825376","pt":1646208668046,"mc":[{"id":"1.195453612","rc":[{"atb":[[3.2,0]],"id":41676292}],"con":true,"img":false}]}
{"op":"mcm","clk":"5347825381","pt":1646208668144,"mc":[{"id":"1.195453612","rc":[{"atb":[[3.45,22.28]],"id":41676292}],"con":true,"img":false}]}
{"op":"mcm","clk":"5347825578","pt":1646208672824,"mc":[{"id":"1.195453612","rc":[{"atl":[[46,0]],"id":42651625}],"con":true,"img":false}]}
{"op":"mcm","clk":"5347825586","pt":1646208672929,"mc":[{"id":"1.195453612","rc":[{"atl":[[44,2.72]],"id":42651625}],"con":true,"img":false}]}
{"op":"mcm","clk":"5347826160","pt":1646208686856,"mc":[{"id":"1.195453612","rc":[{"atb":[[4.8,26.32],[4.4,0]],"id":41762566},{"atb":[[4,0],[1.99,38.68]],"id":42651625},{"atb":[[2.38,0],[2.16,75.44]],"id":41676292}],"con":true,"img":false}]}
{"op":"mcm","clk":"5347826826","pt":1646208702967,"mc":[{"id":"1.195453612","rc":[{"atl":[[44,0]],"id":42651625}],"con":true,"img":false}]}
{"op":"mcm","clk":"5347826832","pt":1646208703071,"mc":[{"id":"1.195453612","rc":[{"atl":[[42,2.72]],"id":42651625}],"con":true,"img":false}]}
{"op":"mcm","clk":"5347827229","pt":1646208711677,"mc":[{"id":"1.195453612","rc":[{"atb":[[1.99,0],[4.3,30.3]],"id":42651625},{"atb":[[2.58,63.29],[2.16,0]],"id":41676292}],"con":true,"img":false}]}
{"op":"mcm","clk":"5347827776","pt":1646208723386,"mc":[{"id":"1.195453612","rc":[{"atb":[[4.3,0],[1.99,38.68]],"id":42651625},{"atb":[[2.58,0],[2.16,75.44]],"id":41676292}],"con":true,"img":false}]}
{"op":"mcm","clk":"5347827917","pt":1646208725704,"mc":[{"id":"1.195453612","rc":[{"atb":[[1.36,83.04]],"id":43167173}],"con":true,"img":false}]}
{"op":"mcm","clk":"5347827919","pt":1646208725801,"mc":[{"id":"1.195453612","rc":[{"atb":[[1.31,164.51]],"id":43167173}],"con":true,"img":false}]}
{"op":"mcm","clk":"5347828255","pt":1646208733414,"mc":[{"id":"1.195453612","rc":[{"atl":[[42,0]],"id":42651625}],"con":true,"img":false}]}
{"op":"mcm","clk":"5347828260","pt":1646208733517,"mc":[{"id":"1.195453612","rc":[{"atl":[[40,2.72]],"id":42651625}],"con":true,"img":false}]}
{"op":"mcm","clk":"5347828945","pt":1646208747900,"mc":[{"id":"1.195453612","rc":[{"atb":[[1.99,0],[4.1,32.26]],"id":42651625},{"atb":[[2.44,69.44],[2.16,0]],"id":41676292}],"con":true,"img":false}]}
{"op":"mcm","clk":"5347829666","pt":1646208763349,"mc":[{"id":"1.195453612","rc":[{"atl":[[40,0]],"id":42651625}],"con":true,"img":false}]}
{"op":"mcm","clk":"5347829672","pt":1646208763453,"mc":[{"id":"1.195453612","rc":[{"atl":[[38,4.69]],"id":42651625}],"con":true,"img":false}]}
{"op":"mcm","clk":"5347830176","pt":1646208773874,"mc":[{"id":"1.195453612","rc":[{"atl":[[38,1.96]],"id":42651625}],"con":true,"img":false}]}
{"op":"mcm","clk":"5347830181","pt":1646208773975,"mc":[{"id":"1.195453612","rc":[{"atl":[[46,2.72]],"id":42651625}],"con":true,"img":false}]}
{"op":"mcm","clk":"5347831683","pt":1646208803805,"mc":[{"id":"1.195453612","rc":[{"atl":[[46,0]],"id":42651625}],"con":true,"img":false}]}
{"op":"mcm","clk":"5347831686","pt":1646208803904,"mc":[{"id":"1.195453612","rc":[{"atl":[[44,2.72]],"id":42651625}],"con":true,"img":false}]}
{"op":"mcm","clk":"5347833186","pt":1646208833926,"mc":[{"id":"1.195453612","rc":[{"atl":[[44,0]],"id":42651625}],"con":true,"img":false}]}
{"op":"mcm","clk":"5347833192","pt":1646208834030,"mc":[{"id":"1.195453612","rc":[{"atl":[[42,2.72]],"id":42651625}],"con":true,"img":false}]}
{"op":"mcm","clk":"5347833662","pt":1646208843500,"mc":[{"id":"1.195453612","rc":[{"atb":[[4.8,0],[4.4,29.41]],"id":41762566}],"con":true,"img":false}]}
{"op":"mcm","clk":"5347834726","pt":1646208863185,"mc":[{"id":"1.195453612","rc":[{"atl":[[42,0]],"id":42651625}],"con":true,"img":false}]}
{"op":"mcm","clk":"5347834732","pt":1646208863240,"mc":[{"id":"1.195453612","rc":[{"atl":[[40,2.72]],"id":42651625}],"con":true,"img":false}]}
{"op":"mcm","clk":"5347836284","pt":1646208893016,"mc":[{"id":"1.195453612","rc":[{"atl":[[40,0]],"id":42651625}],"con":true,"img":false}]}
{"op":"mcm","clk":"5347836290","pt":1646208893113,"mc":[{"id":"1.195453612","rc":[{"atl":[[38,4.69]],"id":42651625}],"con":true,"img":false}]}
{"op":"mcm","clk":"5347836905","pt":1646208904234,"mc":[{"id":"1.195453612","rc":[{"atl":[[38,1.96]],"id":42651625}],"con":true,"img":false}]}
{"op":"mcm","clk":"5347836912","pt":1646208904335,"mc":[{"id":"1.195453612","rc":[{"atl":[[46,2.72]],"id":42651625}],"con":true,"img":false}]}
{"op":"mcm","clk":"5347838603","pt":1646208933563,"mc":[{"id":"1.195453612","rc":[{"atl":[[46,0]],"id":42651625}],"con":true,"img":false}]}
{"op":"mcm","clk":"5347838611","pt":1646208933661,"mc":[{"id":"1.195453612","rc":[{"atl":[[44,2.72]],"id":42651625}],"con":true,"img":false}]}
{"op":"mcm","clk":"5347840334","pt":1646208963581,"mc":[{"id":"1.195453612","rc":[{"atl":[[44,0]],"id":42651625}],"con":true,"img":false}]}
{"op":"mcm","clk":"5347840342","pt":1646208963683,"mc":[{"id":"1.195453612","rc":[{"atl":[[42,2.72]],"id":42651625}],"con":true,"img":false}]}
{"op":"mcm","clk":"5347842011","pt":1646208993541,"mc":[{"id":"1.195453612","rc":[{"atl":[[42,0]],"id":42651625}],"con":true,"img":false}]}
{"op":"mcm","clk":"5347842018","pt":1646208993643,"mc":[{"id":"1.195453612","rc":[{"atl":[[40,2.72]],"id":42651625}],"con":true,"img":false}]}
{"op":"mcm","clk":"5347852167","pt":1646209023493,"mc":[{"id":"1.195453612","rc":[{"atl":[[40,0]],"id":42651625}],"con":true,"img":false}]}
{"op":"mcm","clk":"5347852174","pt":1646209023596,"mc":[{"id":"1.195453612","rc":[{"atl":[[38,4.69]],"id":42651625}],"con":true,"img":false}]}
{"op":"mcm","clk":"5347852858","pt":1646209034723,"mc":[{"id":"1.195453612","rc":[{"atl":[[38,1.96]],"id":42651625}],"con":true,"img":false}]}
{"op":"mcm","clk":"5347852865","pt":1646209034826,"mc":[{"id":"1.195453612","rc":[{"atl":[[46,2.72]],"id":42651625}],"con":true,"img":false}]}
{"op":"mcm","clk":"5347854577","pt":1646209063969,"mc":[{"id":"1.195453612","rc":[{"atl":[[46,0]],"id":42651625}],"con":true,"img":false}]}
{"op":"mcm","clk":"5347854583","pt":1646209064071,"mc":[{"id":"1.195453612","rc":[{"atl":[[44,2.72]],"id":42651625}],"con":true,"img":false}]}
{"op":"mcm","clk":"5347856454","pt":1646209093492,"mc":[{"id":"1.195453612","rc":[{"atl":[[44,0]],"id":42651625}],"con":true,"img":false}]}
{"op":"mcm","clk":"5347856460","pt":1646209093602,"mc":[{"id":"1.195453612","rc":[{"atl":[[42,2.72]],"id":42651625}],"con":true,"img":false}]}
{"op":"mcm","clk":"5347858296","pt":1646209123348,"mc":[{"id":"1.195453612","rc":[{"atl":[[42,0]],"id":42651625}],"con":true,"img":false}]}
{"op":"mcm","clk":"5347858303","pt":1646209123449,"mc":[{"id":"1.195453612","rc":[{"atl":[[40,2.72]],"id":42651625}],"con":true,"img":false}]}
{"op":"mcm","clk":"5347859846","pt":1646209153292,"mc":[{"id":"1.195453612","rc":[{"atl":[[40,0]],"id":42651625}],"con":true,"img":false}]}
{"op":"mcm","clk":"5347859850","pt":1646209153394,"mc":[{"id":"1.195453612","rc":[{"atl":[[38,4.69]],"id":42651625}],"con":true,"img":false}]}
{"op":"mcm","clk":"5347860399","pt":1646209163933,"mc":[{"id":"1.195453612","rc":[{"atl":[[38,1.96]],"id":42651625}],"con":true,"img":false}]}
{"op":"mcm","clk":"5347860403","pt":1646209164035,"mc":[{"id":"1.195453612","rc":[{"atl":[[46,2.72]],"id":42651625}],"con":true,"img":false}]}
{"op":"mcm","clk":"5347861862","pt":1646209192992,"mc":[{"id":"1.195453612","rc":[{"atl":[[46,0]],"id":42651625}],"con":true,"img":false}]}
{"op":"mcm","clk":"5347861868","pt":1646209193054,"mc":[{"id":"1.195453612","rc":[{"atl":[[44,2.72]],"id":42651625}],"con":true,"img":false}]}
{"op":"mcm","clk":"5347863437","pt":1646209223119,"mc":[{"id":"1.195453612","rc":[{"atl":[[44,0]],"id":42651625}],"con":true,"img":false}]}
{"op":"mcm","clk":"5347863441","pt":1646209223226,"mc":[{"id":"1.195453612","rc":[{"atl":[[42,2.72]],"id":42651625}],"con":true,"img":false}]}
{"op":"mcm","clk":"5347864930","pt":1646209252254,"mc":[{"id":"1.195453612","rc":[{"atl":[[42,0]],"id":42651625}],"con":true,"img":false}]}
{"op":"mcm","clk":"5347864938","pt":1646209252356,"mc":[{"id":"1.195453612","rc":[{"atl":[[40,2.72]],"id":42651625}],"con":true,"img":false}]}
{"op":"mcm","clk":"5347865507","pt":1646209262979,"mc":[{"id":"1.195453612","rc":[{"atb":[[5.1,13.87],[5.3,4.65],[4.9,19.23],[4.7,33.78]],"id":41762566},{"atl":[[19.5,1.08],[21,2.5],[23,6.13],[25,7.93]],"id":41762566},{"atb":[[1.54,66.44],[1.5,349.94],[1.48,250],[1.52,96.15]],"id":43066529},{"atl":[[4.8,32.89],[4.6,20.83],[4.4,14.71],[4.2,6.25]],"id":43066529},{"atb":[[7.2,8.06],[6.4,23.15],[7.6,3.03],[6.8,12.93]],"id":42651625},{"atl":[[270,1],[290,1],[310,1],[250,1]],"id":42651625},{"atb":[[3.85,17.54],[3.95,6.78],[3.75,34.71],[3.65,84.89]],"id":41676292},{"atl":[[21,9.63],[23,2.27],[25,3.12],[27,4.81]],"id":41676292},{"atb":[[1.33,151.52],[1.29,250],[1.31,462.9],[1.35,57.14]],"id":43167172},{"atl":[[8.6,9.87],[9,15.62],[8.2,6.94],[7.8,17.65]],"id":43167172},{"atb":[[1.33,151.52],[1.29,250],[1.31,406.45],[1.35,342.77]],"id":43167173},{"atl":[[270,1],[290,1],[310,1],[250,1]],"id":43167173}],"con":true,"img":false}]}
{"op":"mcm","clk":"5347865523","pt":1646209263288,"mc":[{"id":"1.195453612","rc":[{"atb":[[3,46.15]],"id":41762566},{"atl":[[75,0],[18,1.18],[19.5,0],[50,2.04]],"id":41762566},{"atl":[[4.1,6.45],[4.2,0]],"id":43066529},{"atb":[[3.95,0],[4.1,6.45]],"id":41676292}],"con":true,"img":false}]}
{"op":"mcm","clk":"5347865529","pt":1646209263391,"mc":[{"id":"1.195453612","rc":[{"atb":[[4.4,0]],"id":41762566}],"con":true,"img":false}]}
{"op":"mcm","clk":"5347865534","pt":1646209263455,"mc":[{"id":"1.195453612","rc":[{"atb":[[5.1,12.2]],"id":41762566},{"atb":[[3.75,33.04]],"id":41676292}],"con":true,"img":false}]}
{"op":"mcm","clk":"5347865542","pt":1646209263556,"mc":[{"id":"1.195453612","rc":[{"atb":[[4.1,0]],"id":41762566}],"con":true,"img":false}]}
{"op":"mcm","clk":"5347865549","pt":1646209263658,"mc":[{"id":"1.195453612","rc":[{"atb":[[3.65,21.16],[5.4,1.67]],"id":41762566},{"atb":[[4,1.67]],"id":41676292}],"con":true,"img":false}]}
{"op":"mcm","clk":"5347865571","pt":1646209264069,"mc":[{"id":"1.195453612","rc":[{"atb":[[1.54,52.5]],"id":43066529},{"atb":[[3.75,30.31]],"id":41676292},{"atb":[[1.37,22.57]],"id":43167172}],"con":true,"img":false}]}
{"op":"mcm","clk":"5347865575","pt":1646209264174,"mc":[{"id":"1.195453612","rc":[{"atl":[[2.72,0]],"id":43167172}],"con":true,"img":false}]}
{"op":"mcm","clk":"5347865579","pt":1646209264277,"mc":[{"id":"1.195453612","rc":[{"atl":[[2.92,33.4]],"id":43167172}],"con":true,"img":false}]}
{"op":"mcm","clk":"5347865888","pt":1646209269462,"mc":[{"id":"1.195453612","rc":[{"atb":[[4,0]],"id":41676292}],"con":true,"img":false}]}
{"op":"mcm","clk":"5347865902","pt":1646209269665,"mc":[{"id":"1.195453612","rc":[{"atb":[[4.2,1.67]],"id":41676292}],"con":true,"img":false}]}
{"op":"mcm","clk":"5347865919","pt":1646209269973,"mc":[{"id":"1.195453612","rc":[{"atb":[[1.58,12.97]],"id":43066529},{"atb":[[1.38,19.8]],"id":43167172}],"con":true,"img":false}]}
{"op":"mcm","clk":"5347866025","pt":1646209271572,"mc":[{"id":"1.195453612","rc":[{"atl":[[2.76,0]],"id":43066529}],"con":true,"img":false}]}
{"op":"mcm","clk":"5347866029","pt":1646209271670,"mc":[{"id":"1.195453612","rc":[{"atl":[[2.96,22.28]],"id":43066529}],"con":true,"img":false}]}
{"op":"mcm","clk":"5347866110","pt":1646209273268,"mc":[{"id":"1.195453612","rc":[{"atl":[[19,2.78]],"id":41762566},{"atb":[[3.95,16.95]],"id":41676292}],"con":true,"img":false}]}
{"op":"mcm","clk":"5347866248","pt":1646209275172,"mc":[{"id":"1.195453612","rc":[{"atl":[[40,0]],"id":42651625}],"con":true,"img":false}]}
{"op":"mcm","clk":"5347866256","pt":1646209275272,"mc":[{"id":"1.195453612","rc":[{"atl":[[38,4.69]],"id":42651625}],"con":true,"img":false}]}
{"op":"mcm","clk":"5347866412","pt":1646209277785,"mc":[{"id":"1.195453612","rc":[{"atb":[[3.65,37.72]],"id":41676292}],"con":true,"img":false}]}
{"op":"mcm","clk":"5347866516","pt":1646209279587,"mc":[{"id":"1.195453612","rc":[{"atb":[[1.54,37.04]],"id":43066529},{"atb":[[3.75,27.27]],"id":41676292}],"con":true,"img":false}]}
{"op":"mcm","clk":"5347866656","pt":1646209281999,"mc":[{"id":"1.195453612","rc":[{"atb":[[1.58,0]],"id":43066529}],"con":true,"img":false}]}
{"op":"mcm","clk":"5347866680","pt":1646209282413,"mc":[{"id":"1.195453612","rc":[{"atb":[[3,0],[4.7,60.81]],"id":41762566}],"con":true,"img":false}]}
{"op":"mcm","clk":"5347866726","pt":1646209283085,"mc":[{"id":"1.195453612","rc":[{"atl":[[38,1.96]],"id":42651625}],"con":true,"img":false}]}
{"op":"mcm","clk":"5347866733","pt":1646209283190,"mc":[{"id":"1.195453612","rc":[{"spn":11.2,"spf":"NaN","id":41762566},{"spn":2.16,"spf":"NaN","id":43066529},{"atl":[[46,2.72]],"id":42651625},{"spn":7.35,"spf":"NaN","id":41676292},{"spn":1.95,"spf":"NaN","id":43167172}],"con":true,"img":false}]}
{"op":"mcm","clk":"5347866739","pt":1646209283293,"mc":[{"id":"1.195453612","rc":[{"atl":[[20,3.95],[21,0],[23,2.72],[25,2.72]],"id":41762566},{"atb":[[3.85,26.32]],"id":41676292}],"con":true,"img":false}]}
{"op":"mcm","clk":"5347866756","pt":1646209283601,"mc":[{"id":"1.195453612","rc":[{"atb":[[1.34,0]],"id":43167172}],"con":true,"img":false}]}
{"op":"mcm","clk":"5347866762","pt":1646209283697,"mc":[{"id":"1.195453612","rc":[{"atb":[[1.37,108.78]],"id":43167172}],"con":true,"img":false}]}
{"op":"mcm","clk":"5347866806","pt":1646209284581,"mc":[{"id":"1.195453612","rc":[{"atl":[[25,0]],"id":41762566},{"atb":[[1.51,0]],"id":43066529}],"con":true,"img":false}]}
{"op":"mcm","clk":"5347866812","pt":1646209284685,"mc":[{"id":"1.195453612","rc":[{"atl":[[17.5,2.72]],"id":41762566},{"atb":[[1.53,85.62]],"id":43066529}],"con":true,"img":false}]}
{"op":"mcm","clk":"5347866825","pt":1646209285002,"mc":[{"id":"1.195453612","rc":[{"atb":[[1.38,0]],"id":43167172}],"con":true,"img":false}]}
{"op":"mcm","clk":"5347866885","pt":1646209286188,"mc":[{"id":"1.195453612","rc":[{"atb":[[3.7,0]],"id":41676292}],"con":true,"img":false}]}
{"op":"mcm","clk":"5347866890","pt":1646209286287,"mc":[{"id":"1.195453612","rc":[{"atb":[[3.8,15.06]],"id":41676292}],"con":true,"img":false}]}
{"op":"mcm","clk":"5347867157","pt":1646209291217,"mc":[{"id":"1.195453612","rc":[{"atb":[[1.57,13.19]],"id":43066529},{"atb":[[1.4,18.81]],"id":43167172}],"con":true,"img":false}]}
{"op":"mcm","clk":"5347867266","pt":1646209293320,"mc":[{"id":"1.195453612","rc":[{"atl":[[22,5.95]],"id":41762566},{"atb":[[3.75,45.45]],"id":41676292}],"con":true,"img":false}]}
{"op":"mcm","clk":"5347867699","pt":1646209302628,"mc":[{"id":"1.195453612","rc":[{"atb":[[1.34,168.97]],"id":43167172}],"con":true,"img":false}]}
{"op":"mcm","clk":"5347867704","pt":1646209302730,"mc":[{"id":"1.195453612","rc":[{"atb":[[1.31,241.94]],"id":43167172}],"con":true,"img":false}]}
{"op":"mcm","clk":"5347867727","pt":1646209303135,"mc":[{"id":"1.195453612","rc":[{"atb":[[1.46,0]],"id":43066529}],"con":true,"img":false}]}
{"op":"mcm","clk":"5347867731","pt":1646209303244,"mc":[{"id":"1.195453612","rc":[{"atb":[[1.49,158.84]],"id":43066529}],"con":true,"img":false}]}
{"op":"mcm","clk":"5347867749","pt":1646209303608,"mc":[{"id":"1.195453612","rc":[{"atb":[[1.31,241.94]],"id":43167173}],"con":true,"img":false}]}
{"op":"mcm","clk":"5347867754","pt":1646209303706,"mc":[{"id":"1.195453612","rc":[{"atb":[[1.36,247.55]],"id":43167173}],"con":true,"img":false}]}
{"op":"mcm","clk":"5347867805","pt":1646209305111,"mc":[{"id":"1.195453612","rc":[{"atl":[[17.5,6.12],[23,0]],"id":41762566},{"atl":[[46,0]],"id":42651625}],"con":true,"img":false}]}
{"op":"mcm","clk":"5347867809","pt":1646209305207,"mc":[{"id":"1.195453612","rc":[{"atl":[[44,2.72]],"id":42651625}],"con":true,"img":false}]}
{"op":"mcm","clk":"5347867813","pt":1646209305310,"mc":[{"id":"1.195453612","rc":[{"atb":[[3.45,0]],"id":41676292}],"con":true,"img":false}]}
{"op":"mcm","clk":"5347867818","pt":1646209305439,"mc":[{"id":"1.195453612","rc":[{"atb":[[3.7,22.28]],"id":41676292}],"con":true,"img":false}]}
{"op":"mcm","clk":"5347867852","pt":1646209306212,"mc":[{"id":"1.195453612","rc":[{"atb":[[3.8,0]],"id":41676292}],"con":true,"img":false}]}
{"op":"mcm","clk":"5347867858","pt":1646209306313,"mc":[{"id":"1.195453612","rc":[{"atb":[[3.9,15.06]],"id":41676292}],"con":true,"img":false}]}
{"op":"mcm","clk":"5347867872","pt":1646209306621,"mc":[{"id":"1.195453612","rc":[{"atb":[[3.65,0]],"id":41762566}],"con":true,"img":false}]}
{"op":"mcm","clk":"5347867879","pt":1646209306724,"mc":[{"id":"1.195453612","rc":[{"atb":[[4.1,21.16]],"id":41762566}],"con":true,"img":false}]}
{"op":"mcm","clk":"5347867884","pt":1646209306827,"mc":[{"id":"1.195453612","rc":[{"atb":[[1.37,86.21]],"id":43167172}],"con":true,"img":false}]}
{"op":"mcm","clk":"5347867891","pt":1646209306929,"mc":[{"id":"1.195453612","rc":[{"atb":[[1.57,27.84]],"id":43066529}],"con":true,"img":false}]}
{"op":"mcm","clk":"5347867902","pt":1646209307134,"mc":[{"id":"1.195453612","rc":[{"atl":[[2.96,0]],"id":43066529}],"con":true,"img":false}]}
{"op":"mcm","clk":"5347867910","pt":1646209307241,"mc":[{"id":"1.195453612","rc":[{"atl":[[2.76,22.28]],"id":43066529}],"con":true,"img":false}]}
{"op":"mcm","clk":"5347868498","pt":1646209318055,"mc":[{"id":"1.195453612","rc":[{"atb":[[1.4,39.69]],"id":43167172}],"con":true,"img":false}]}
{"op":"mcm","clk":"5347868920","pt":1646209327069,"mc":[{"id":"1.195453612","rc":[{"atl":[[44,0]],"id":42651625}],"con":true,"img":false}]}
{"op":"mcm","clk":"5347868924","pt":1646209327165,"mc":[{"id":"1.195453612","rc":[{"atl":[[42,2.72]],"id":42651625}],"con":true,"img":false}]}
{"op":"mcm","clk":"5347869334","pt":1646209335687,"mc":[{"id":"1.195453612","rc":[{"atl":[[18,0],[18.5,1.14]],"id":41762566},{"atl":[[3.95,6.78],[4.1,0]],"id":43066529},{"atb":[[2.54,64.94],[2.44,0]],"id":41676292},{"atb":[[1.34,227.79],[1.35,0]],"id":43167172}],"con":true,"img":false}]}
{"op":"mcm","clk":"5347869355","pt":1646209336094,"mc":[{"id":"1.195453612","rc":[{"atl":[[17.5,2.72]],"id":41762566}],"con":true,"img":false}]}
{"op":"mcm","clk":"5347869357","pt":1646209336152,"mc":[{"id":"1.195453612","rc":[{"atl":[[18,3.4]],"id":41762566}],"con":true,"img":false}]}
{"op":"mcm","clk":"5347869904","pt":1646209345710,"mc":[{"id":"1.195453612","rc":[{"atl":[[19.5,2.7]],"id":41762566},{"atl":[[4.1,16.13]],"id":43066529},{"spn":2.16,"spf":"NaN","id":43066529},{"atb":[[1.32,156.25]],"id":43167172},{"spn":1.96,"spf":"NaN","id":43167172}],"con":true,"img":false}]}
{"op":"mcm","clk":"5347870129","pt":1646209349603,"mc":[{"id":"1.195453612","rc":[{"atl":[[42,0]],"id":42651625}],"con":true,"img":false}]}
{"op":"mcm","clk":"5347870133","pt":1646209349704,"mc":[{"id":"1.195453612","rc":[{"atl":[[40,2.72]],"id":42651625}],"con":true,"img":false}]}
{"op":"mcm","clk":"5347870371","pt":1646209355675,"mc":[{"id":"1.195453612","rc":[{"atl":[[19,0],[20,0],[21,3.75],[22,0]],"id":41762566},{"atl":[[4.8,0],[4.3,22.73],[4.6,0],[4.4,0]],"id":43066529},{"atb":[[1.33,0],[1.3,583.24],[1.29,0],[1.31,0]],"id":43167172}],"con":true,"img":false}]}
{"op":"mcm","clk":"5347870389","pt":1646209356084,"mc":[{"id":"1.195453612","rc":[{"atb":[[1.34,58.82]],"id":43167172}],"con":true,"img":false}]}
{"op":"mcm","clk":"5347870392","pt":1646209356190,"mc":[{"id":"1.195453612","rc":[{"atb":[[1.33,168.97]],"id":43167172}],"con":true,"img":false}]}
{"op":"mcm","clk":"5347870853","pt":1646209365706,"mc":[{"id":"1.195453612","rc":[{"atl":[[23,5.68]],"id":41762566},{"atl":[[4.5,35.71]],"id":43066529},{"atb":[[1.28,250]],"id":43167172}],"con":true,"img":false}]}
{"op":"mcm","clk":"5347871138","pt":1646209372097,"mc":[{"id":"1.195453612","rc":[{"atl":[[40,0]],"id":42651625}],"con":true,"img":false}]}
{"op":"mcm","clk":"5347871144","pt":1646209372200,"mc":[{"id":"1.195453612","rc":[{"atl":[[38,4.69]],"id":42651625}],"con":true,"img":false}]}
{"op":"mcm","clk":"5347871501","pt":1646209380091,"mc":[{"id":"1.195453612","rc":[{"atl":[[38,1.96]],"id":42651625}],"con":true,"img":false}]}
{"op":"mcm","clk":"5347871508","pt":1646209380196,"mc":[{"id":"1.195453612","rc":[{"atl":[[46,2.72]],"id":42651625}],"con":true,"img":false}]}
{"op":"mcm","clk":"5347872402","pt":1646209402135,"mc":[{"id":"1.195453612","rc":[{"atl":[[46,0]],"id":42651625}],"con":true,"img":false}]}
{"op":"mcm","clk":"5347872407","pt":1646209402233,"mc":[{"id":"1.195453612","rc":[{"atl":[[44,2.72]],"id":42651625}],"con":true,"img":false}]}
{"op":"mcm","clk":"5347873214","pt":1646209424085,"mc":[{"id":"1.195453612","rc":[{"atl":[[44,0]],"id":42651625}],"con":true,"img":false}]}
{"op":"mcm","clk":"5347873221","pt":1646209424142,"mc":[{"id":"1.195453612","rc":[{"atl":[[42,2.72]],"id":42651625}],"con":true,"img":false}]}
{"op":"mcm","clk":"5347874320","pt":1646209446117,"mc":[{"id":"1.195453612","rc":[{"atl":[[42,0]],"id":42651625}],"con":true,"img":false}]}
{"op":"mcm","clk":"5347874326","pt":1646209446219,"mc":[{"id":"1.195453612","rc":[{"atl":[[40,2.72]],"id":42651625}],"con":true,"img":false}]}
{"op":"mcm","clk":"5347874880","pt":1646209455725,"mc":[{"id":"1.195453612","rc":[{"atb":[[4.3,30.3],[4.7,33.78]],"id":41762566}],"con":true,"img":false}]}
{"op":"mcm","clk":"5347875590","pt":1646209468623,"mc":[{"id":"1.195453612","rc":[{"atl":[[40,0]],"id":42651625}],"con":true,"img":false}]}
{"op":"mcm","clk":"5347875597","pt":1646209468727,"mc":[{"id":"1.195453612","rc":[{"atl":[[38,4.69]],"id":42651625}],"con":true,"img":false}]}
{"op":"mcm","clk":"5347875960","pt":1646209476530,"mc":[{"id":"1.195453612","rc":[{"atl":[[38,1.96]],"id":42651625}],"con":true,"img":false}]}
{"op":"mcm","clk":"5347875965","pt":1646209476628,"mc":[{"id":"1.195453612","rc":[{"atl":[[46,2.72]],"id":42651625}],"con":true,"img":false}]}
{"op":"mcm","clk":"5347876999","pt":1646209498577,"mc":[{"id":"1.195453612","rc":[{"atl":[[46,0]],"id":42651625}],"con":true,"img":false}]}
{"op":"mcm","clk":"5347877004","pt":1646209498680,"mc":[{"id":"1.195453612","rc":[{"atl":[[44,2.72]],"id":42651625}],"con":true,"img":false}]}
{"op":"mcm","clk":"5347877862","pt":1646209516084,"mc":[{"id":"1.195453612","rc":[{"atb":[[4.3,0],[4.7,60.81]],"id":41762566}],"con":true,"img":false}]}
{"op":"mcm","clk":"5347878093","pt":1646209520603,"mc":[{"id":"1.195453612","rc":[{"atl":[[44,0]],"id":42651625}],"con":true,"img":false}]}
{"op":"mcm","clk":"5347878100","pt":1646209520654,"mc":[{"id":"1.195453612","rc":[{"atl":[[42,2.72]],"id":42651625}],"con":true,"img":false}]}
{"op":"mcm","clk":"5347879253","pt":1646209542616,"mc":[{"id":"1.195453612","rc":[{"atl":[[42,0]],"id":42651625}],"con":true,"img":false}]}
{"op":"mcm","clk":"5347879257","pt":1646209542721,"mc":[{"id":"1.195453612","rc":[{"atl":[[40,2.72]],"id":42651625}],"con":true,"img":false}]}
{"op":"mcm","clk":"5347880329","pt":1646209565037,"mc":[{"id":"1.195453612","rc":[{"atl":[[40,0]],"id":42651625}],"con":true,"img":false}]}
{"op":"mcm","clk":"5347880337","pt":1646209565311,"mc":[{"id":"1.195453612","rc":[{"atl":[[38,4.69]],"id":42651625}],"con":true,"img":false}]}
{"op":"mcm","clk":"5347880678","pt":1646209572564,"mc":[{"id":"1.195453612","rc":[{"atl":[[38,1.96]],"id":42651625}],"con":true,"img":false}]}
{"op":"mcm","clk":"5347880681","pt":1646209572668,"mc":[{"id":"1.195453612","rc":[{"atl":[[46,2.72]],"id":42651625}],"con":true,"img":false}]}
{"op":"mcm","clk":"5347881868","pt":1646209594583,"mc":[{"id":"1.195453612","rc":[{"atl":[[46,0]],"id":42651625}],"con":true,"img":false}]}
{"op":"mcm","clk":"5347881874","pt":1646209594687,"mc":[{"id":"1.195453612","rc":[{"atl":[[44,2.72]],"id":42651625}],"con":true,"img":false}]}
{"op":"mcm","clk":"5347882911","pt":1646209616511,"mc":[{"id":"1.195453612","rc":[{"atl":[[44,0]],"id":42651625}],"con":true,"img":false}]}
{"op":"mcm","clk":"5347882917","pt":1646209616611,"mc":[{"id":"1.195453612","rc":[{"atl":[[42,2.72]],"id":42651625}],"con":true,"img":false}]}
{"op":"mcm","clk":"5347883852","pt":1646209636154,"mc":[{"id":"1.195453612","rc":[{"atb":[[4.4,29.41],[4.7,33.78]],"id":41762566}],"con":true,"img":false}]}
{"op":"mcm","clk":"5347883964","pt":1646209638623,"mc":[{"id":"1.195453612","rc":[{"atl":[[42,0]],"id":42651625}],"con":true,"img":false}]}
{"op":"mcm","clk":"5347883970","pt":1646209638725,"mc":[{"id":"1.195453612","rc":[{"atl":[[40,2.72]],"id":42651625}],"con":true,"img":false}]}
{"op":"mcm","clk":"5347885134","pt":1646209661042,"mc":[{"id":"1.195453612","rc":[{"atl":[[40,0]],"id":42651625}],"con":true,"img":false}]}
{"op":"mcm","clk":"5347885140","pt":1646209661147,"mc":[{"id":"1.195453612","rc":[{"atl":[[38,4.69]],"id":42651625}],"con":true,"img":false}]}
{"op":"mcm","clk":"5347885511","pt":1646209668572,"mc":[{"id":"1.195453612","rc":[{"atl":[[38,1.96]],"id":42651625}],"con":true,"img":false}]}
{"op":"mcm","clk":"5347885515","pt":1646209668675,"mc":[{"id":"1.195453612","rc":[{"atl":[[46,2.72]],"id":42651625}],"con":true,"img":false}]}
{"op":"mcm","clk":"5347886624","pt":1646209690615,"mc":[{"id":"1.195453612","rc":[{"atl":[[46,0]],"id":42651625}],"con":true,"img":false}]}
{"op":"mcm","clk":"5347886634","pt":1646209690718,"mc":[{"id":"1.195453612","rc":[{"atl":[[44,2.72]],"id":42651625}],"con":true,"img":false}]}
{"op":"mcm","clk":"5347886854","pt":1646209695138,"mc":[{"id":"1.195453612","rc":[{"atb":[[4.6,41.42],[4.4,0]],"id":41762566},{"atl":[[18.5,0],[19,1.11]],"id":41762566},{"atl":[[3.85,7.02],[3.95,0]],"id":43066529}],"con":true,"img":false}]}
{"op":"mcm","clk":"5347886895","pt":1646209695614,"mc":[{"id":"1.195453612","rc":[{"atl":[[18,0]],"id":41762566}],"con":true,"img":false}]}
{"op":"mcm","clk":"5347886903","pt":1646209695707,"mc":[{"id":"1.195453612","rc":[{"atl":[[18.5,3.4]],"id":41762566}],"con":true,"img":false}]}
{"op":"mcm","clk":"5347887362","pt":1646209705121,"mc":[{"id":"1.195453612","rc":[{"atl":[[20,2.63]],"id":41762566},{"atl":[[3.95,16.95]],"id":43066529}],"con":true,"img":false}]}
{"op":"mcm","clk":"5347887631","pt":1646209711198,"mc":[{"id":"1.195453612","rc":[{"atb":[[4.8,26.32],[4.6,13.64]],"id":41762566},{"atl":[[19.5,0],[21,0],[23,0]],"id":41762566},{"atl":[[4.5,0]],"id":43066529}],"con":true,"img":false}]}
{"op":"mcm","clk":"5347887712","pt":1646209712629,"mc":[{"id":"1.195453612","rc":[{"atl":[[44,0]],"id":42651625}],"con":true,"img":false}]}
{"op":"mcm","clk":"5347887718","pt":1646209712726,"mc":[{"id":"1.195453612","rc":[{"atl":[[42,2.72]],"id":42651625}],"con":true,"img":false}]}
{"op":"mcm","clk":"5347887822","pt":1646209715101,"mc":[{"id":"1.195453612","rc":[{"atl":[[22,3.57]],"id":41762566},{"atl":[[4.1,24.19]],"id":43066529}],"con":true,"img":false}]}
{"op":"mcm","clk":"5347888380","pt":1646209725156,"mc":[{"id":"1.195453612","rc":[{"atl":[[24,8.59]],"id":41762566},{"atl":[[4.3,37.88]],"id":43066529}],"con":true,"img":false}]}
{"op":"mcm","clk":"5347888631","pt":1646209729444,"mc":[{"id":"1.195453612","rc":[{"atl":[[18.5,4.54],[19,0]],"id":41762566},{"atl":[[5.8,20.83],[6.6,0]],"id":43066529}],"con":true,"img":false}]}
{"op":"mcm","clk":"5347888872","pt":1646209734552,"mc":[{"id":"1.195453612","rc":[{"atl":[[42,0]],"id":42651625}],"con":true,"img":false}]}
{"op":"mcm","clk":"5347888874","pt":1646209734660,"mc":[{"id":"1.195453612","rc":[{"atl":[[40,2.72]],"id":42651625}],"con":true,"img":false}]}
{"op":"mcm","clk":"5347888883","pt":1646209734917,"mc":[{"id":"1.195453612","rc":[{"atb":[[8.6,0]],"id":42651625},{"atl":[[13.5,0]],"id":41676292}],"con":true,"img":false}]}
{"op":"mcm","clk":"5347888887","pt":1646209735080,"mc":[{"id":"1.195453612","rc":[{"atb":[[6.8,21.9]],"id":42651625},{"atl":[[15.5,7.74]],"id":41676292}],"con":true,"img":false}]}
{"op":"mcm","clk":"5347889378","pt":1646209745462,"mc":[{"id":"1.195453612","rc":[{"atl":[[18.5,3.4],[19,1.11]],"id":41762566}],"con":true,"img":false}]}
{"op":"mcm","clk":"5347889983","pt":1646209756581,"mc":[{"id":"1.195453612","rc":[{"atl":[[40,0]],"id":42651625}],"con":true,"img":false}]}
{"op":"mcm","clk":"5347889988","pt":1646209756684,"mc":[{"id":"1.195453612","rc":[{"atl":[[38,4.69]],"id":42651625}],"con":true,"img":false}]}
{"op":"mcm","clk":"5347890334","pt":1646209764075,"mc":[{"id":"1.195453612","rc":[{"atl":[[38,1.96]],"id":42651625}],"con":true,"img":false}]}
{"op":"mcm","clk":"5347890341","pt":1646209764176,"mc":[{"id":"1.195453612","rc":[{"atl":[[46,2.72]],"id":42651625}],"con":true,"img":false}]}
{"op":"mcm","clk":"5347890882","pt":1646209775675,"mc":[{"id":"1.195453612","rc":[{"atl":[[3.85,0],[3.9,6.9]],"id":43066529}],"con":true,"img":false}]}
{"op":"mcm","clk":"5347891213","pt":1646209782107,"mc":[{"id":"1.195453612","rc":[{"atb":[[6.8,12.93]],"id":42651625}],"con":true,"img":false}]}
{"op":"mcm","clk":"5347891216","pt":1646209782211,"mc":[{"id":"1.195453612","rc":[{"atb":[[8.6,8.97]],"id":42651625}],"con":true,"img":false}]}
{"op":"mcm","clk":"5347891378","pt":1646209785723,"mc":[{"id":"1.195453612","rc":[{"atl":[[4,16.67]],"id":43066529}],"con":true,"img":false}]}
{"op":"mcm","clk":"5347891398","pt":1646209786085,"mc":[{"id":"1.195453612","rc":[{"atl":[[46,0]],"id":42651625}],"con":true,"img":false}]}
{"op":"mcm","clk":"5347891404","pt":1646209786241,"mc":[{"id":"1.195453612","rc":[{"atl":[[44,2.72]],"id":42651625}],"con":true,"img":false}]}
{"op":"mcm","clk":"5347891559","pt":1646209789782,"mc":[{"id":"1.195453612","rc":[{"atl":[[4.3,0],[3.95,0],[4.1,0]],"id":43066529}],"con":true,"img":false}]}
{"op":"mcm","clk":"5347891828","pt":1646209795707,"mc":[{"id":"1.195453612","rc":[{"atl":[[4.2,23.44]],"id":43066529}],"con":true,"img":false}]}
{"op":"mcm","clk":"5347892367","pt":1646209805730,"mc":[{"id":"1.195453612","rc":[{"atl":[[4.4,36.76]],"id":43066529}],"con":true,"img":false}]}
{"op":"mcm","clk":"5347892505","pt":1646209808114,"mc":[{"id":"1.195453612","rc":[{"atl":[[44,0]],"id":42651625}],"con":true,"img":false}]}
{"op":"mcm","clk":"5347892509","pt":1646209808213,"mc":[{"id":"1.195453612","rc":[{"atl":[[42,2.72]],"id":42651625}],"con":true,"img":false}]}
{"op":"mcm","clk":"5347893122","pt":1646209820036,"mc":[{"id":"1.195453612","rc":[{"atl":[[3.8,7.14],[3.9,0]],"id":43066529}],"con":true,"img":false}]}
{"op":"mcm","clk":"5347893630","pt":1646209830051,"mc":[{"id":"1.195453612","rc":[{"atl":[[3.9,17.24]],"id":43066529},{"atl":[[42,0]],"id":42651625}],"con":true,"img":false}]}
{"op":"mcm","clk":"5347893635","pt":1646209830154,"mc":[{"id":"1.195453612","rc":[{"atl":[[40,2.72]],"id":42651625}],"con":true,"img":false}]}
{"op":"mcm","clk":"5347893880","pt":1646209835067,"mc":[{"id":"1.195453612","rc":[{"atl":[[4,0],[3.8,0],[4.4,0],[3.9,0],[4.2,0]],"id":43066529}],"con":true,"img":false}]}
{"op":"mcm","clk":"5347893888","pt":1646209835170,"mc":[{"id":"1.195453612","rc":[{"atl":[[3.75,7.27]],"id":43066529}],"con":true,"img":false}]}
{"op":"mcm","clk":"5347894385","pt":1646209845055,"mc":[{"id":"1.195453612","rc":[{"atl":[[3.85,17.54]],"id":43066529}],"con":true,"img":false}]}
{"op":"mcm","clk":"5347894766","pt":1646209852603,"mc":[{"id":"1.195453612","rc":[{"atl":[[40,0]],"id":42651625}],"con":true,"img":false}]}
{"op":"mcm","clk":"5347894774","pt":1646209852703,"mc":[{"id":"1.195453612","rc":[{"atl":[[38,4.69]],"id":42651625}],"con":true,"img":false}]}
{"op":"mcm","clk":"5347894855","pt":1646209855086,"mc":[{"id":"1.195453612","rc":[{"atl":[[3.95,25.42]],"id":43066529}],"con":true,"img":false}]}
{"op":"mcm","clk":"5347894856","pt":1646209855185,"mc":[{"id":"1.195453612","rc":[{"atl":[[19,0],[19.5,1.08]],"id":41762566}],"con":true,"img":false}]}
{"op":"mcm","clk":"5347895103","pt":1646209860611,"mc":[{"id":"1.195453612","rc":[{"atl":[[38,1.96]],"id":42651625}],"con":true,"img":false}]}
{"op":"mcm","clk":"5347895107","pt":1646209860666,"mc":[{"id":"1.195453612","rc":[{"atl":[[46,2.72]],"id":42651625}],"con":true,"img":false}]}
{"op":"mcm","clk":"5347895336","pt":1646209865122,"mc":[{"id":"1.195453612","rc":[{"atl":[[4.1,40.32]],"id":43066529}],"con":true,"img":false}]}
{"op":"mcm","clk":"5347895341","pt":1646209865229,"mc":[{"id":"1.195453612","rc":[{"atl":[[21,2.5]],"id":41762566}],"con":true,"img":false}]}
{"op":"mcm","clk":"5347895476","pt":1646209867625,"mc":[{"id":"1.195453612","rc":[{"atb":[[11,0]],"id":42651625}],"con":true,"img":false}]}
{"op":"mcm","clk":"5347895482","pt":1646209867725,"mc":[{"id":"1.195453612","rc":[{"atb":[[10,5.6]],"id":42651625}],"con":true,"img":false}]}
{"op":"mcm","clk":"5347895742","pt":1646209873315,"mc":[{"id":"1.195453612","rc":[{"atl":[[20,0],[22,0],[24,3.16]],"id":41762566},{"atb":[[1.34,0],[1.35,57.14]],"id":43167172}],"con":true,"img":false}]}
{"op":"mcm","clk":"5347895820","pt":1646209875221,"mc":[{"id":"1.195453612","rc":[{"atl":[[23,3.41]],"id":41762566}],"con":true,"img":false}]}
{"op":"mcm","clk":"5347896209","pt":1646209882613,"mc":[{"id":"1.195453612","rc":[{"atl":[[46,0]],"id":42651625}],"con":true,"img":false}]}
{"op":"mcm","clk":"5347896212","pt":1646209882713,"mc":[{"id":"1.195453612","rc":[{"atl":[[44,2.72]],"id":42651625}],"con":true,"img":false}]}
{"op":"mcm","clk":"5347896351","pt":1646209885308,"mc":[{"id":"1.195453612","rc":[{"atl":[[25,5.21]],"id":41762566}],"con":true,"img":false}]}
{"op":"mcm","clk":"5347896783","pt":1646209895130,"mc":[{"id":"1.195453612","rc":[{"atl":[[18.5,0]],"id":41762566}],"con":true,"img":false}]}
{"op":"mcm","clk":"5347896787","pt":1646209895235,"mc":[{"id":"1.195453612","rc":[{"atl":[[19,3.4]],"id":41762566}],"con":true,"img":false}]}
{"op":"mcm","clk":"5347896891","pt":1646209898018,"mc":[{"id":"1.195453612","rc":[{"atb":[[4.8,0],[4.9,44.87]],"id":41762566},{"atl":[[19.5,0],[21,1]],"id":41762566},{"atl":[[3.75,0],[3.65,7.55]],"id":43066529},{"atb":[[2.54,0],[2.7,58.82]],"id":41676292},{"atb":[[1.34,58.82],[1.35,0]],"id":43167172}],"con":true,"img":false}]}
{"op":"mcm","clk":"5347897114","pt":1646209904537,"mc":[{"id":"1.195453612","rc":[{"atl":[[44,0]],"id":42651625}],"con":true,"img":false}]}
{"op":"mcm","clk":"5347897119","pt":1646209904638,"mc":[{"id":"1.195453612","rc":[{"atl":[[42,2.72]],"id":42651625}],"con":true,"img":false}]}
{"op":"mcm","clk":"5347897266","pt":1646209907427,"mc":[{"id":"1.195453612","rc":[{"atl":[[16.5,1.29]],"id":41762566},{"spn":10.95,"spf":"NaN","id":41762566},{"spn":17.0,"spf":"NaN","id":42651625}],"con":true,"img":false}]}
{"op":"mcm","clk":"5347897272","pt":1646209907589,"mc":[{"id":"1.195453612","rc":[{"atb":[[4.5,57.12],[4.9,19.23]],"id":41762566},{"atl":[[36,2.86],[50,0]],"id":41762566},{"atl":[[5.8,0],[4.6,27.78],[2.66,12.05],[3.65,0]],"id":43066529},{"atb":[[4.1,0],[5.9,20.41]],"id":42651625},{"atb":[[3.15,93.01],[2.7,0]],"id":41676292},{"atb":[[1.16,0],[1.34,0],[1.08,418.97],[1.35,57.14]],"id":43167172}],"con":true,"img":false}]}
{"op":"mcm","clk":"5347897647","pt":1646209917445,"mc":[{"id":"1.195453612","rc":[{"atl":[[17.5,5.75]],"id":41762566}],"con":true,"img":false}]}
{"op":"mcm","clk":"5347897651","pt":1646209917546,"mc":[{"id":"1.195453612","rc":[{"atl":[[2.7,29.41]],"id":43066529}],"con":true,"img":false}]}
{"op":"mcm","clk":"5347897657","pt":1646209917648,"mc":[{"id":"1.195453612","rc":[{"atl":[[25,0]],"id":41762566}],"con":true,"img":false}]}
{"op":"mcm","clk":"5347897698","pt":1646209918671,"mc":[{"id":"1.195453612","rc":[{"atb":[[1.49,0]],"id":43066529}],"con":true,"img":false}]}
{"op":"mcm","clk":"5347897705","pt":1646209918774,"mc":[{"id":"1.195453612","rc":[{"atb":[[1.46,158.84]],"id":43066529}],"con":true,"img":false}]}
{"op":"mcm","clk":"5347897763","pt":1646209920267,"mc":[{"id":"1.195453612","rc":[{"atb":[[4.5,28.56],[5.4,6.32]],"id":41762566},{"atl":[[4.6,0],[4.1,72.58]],"id":43066529}],"con":true,"img":false}]}
{"op":"mcm","clk":"5347897966","pt":1646209925461,"mc":[{"id":"1.195453612","rc":[{"atl":[[4.1,32.26]],"id":43066529}],"con":true,"img":false}]}
{"op":"mcm","clk":"5347898030","pt":1646209926650,"mc":[{"id":"1.195453612","rc":[{"atl":[[42,0]],"id":42651625}],"con":true,"img":false}]}
{"op":"mcm","clk":"5347898037","pt":1646209926754,"mc":[{"id":"1.195453612","rc":[{"atl":[[40,2.72]],"id":42651625}],"con":true,"img":false}]}
{"op":"mcm","clk":"5347898057","pt":1646209927471,"mc":[{"id":"1.195453612","rc":[{"atl":[[18.5,4.29]],"id":41762566},{"atl":[[2.74,43.1]],"id":43066529}],"con":true,"img":false}]}
{"op":"mcm","clk":"5347898455","pt":1646209937462,"mc":[{"id":"1.195453612","rc":[{"atl":[[19.5,6.76],[23,0]],"id":41762566},{"atl":[[3.95,0],[2.78,90.64]],"id":43066529}],"con":true,"img":false}]}
{"op":"mcm","clk":"5347898487","pt":1646209938179,"mc":[{"id":"1.195453612","rc":[{"atl":[[40,0]],"id":42651625}],"con":true,"img":false}]}
{"op":"mcm","clk":"5347898492","pt":1646209938282,"mc":[{"id":"1.195453612","rc":[{"atl":[[55,2.72]],"id":42651625}],"con":true,"img":false}]}
{"op":"mcm","clk":"5347898522","pt":1646209939106,"mc":[{"id":"1.195453612","rc":[{"atl":[[2.76,0]],"id":43066529},{"atb":[[10,0]],"id":42651625}],"con":true,"img":false}]}
{"op":"mcm","clk":"5347898527","pt":1646209939157,"mc":[{"id":"1.195453612","rc":[{"atl":[[2.68,22.28]],"id":43066529},{"atb":[[10.5,5.6]],"id":42651625}],"con":true,"img":false}]}
{"op":"mcm","clk":"5347898780","pt":1646209945108,"mc":[{"id":"1.195453612","rc":[{"atl":[[2.52,0]],"id":43167172},{"atl":[[2.58,0]],"id":43167173}],"con":true,"img":false}]}
{"op":"mcm","clk":"5347898784","pt":1646209945208,"mc":[{"id":"1.195453612","rc":[{"atl":[[2.72,28.72]],"id":43167172},{"atl":[[2.78,57.8]],"id":43167173}],"con":true,"img":false}]}
{"op":"mcm","clk":"5347898879","pt":1646209947523,"mc":[{"id":"1.195453612","rc":[{"atl":[[21,0]],"id":41762566},{"atl":[[3.85,0]],"id":43066529}],"con":true,"img":false}]}
{"op":"mcm","clk":"5347899307","pt":1646209957622,"mc":[{"id":"1.195453612","rc":[{"atl":[[19,0]],"id":41762566}],"con":true,"img":false}]}
{"op":"mcm","clk":"5347899315","pt":1646209957720,"mc":[{"id":"1.195453612","rc":[{"atl":[[17,5.67]],"id":41762566}],"con":true,"img":false}]}
{"op":"mcm","clk":"5347899364","pt":1646209958585,"mc":[{"id":"1.195453612","rc":[{"atb":[[3.7,0]],"id":41676292}],"con":true,"img":false}]}
{"op":"mcm","clk":"5347899373","pt":1646209958695,"mc":[{"id":"1.195453612","rc":[{"atb":[[3.8,22.28]],"id":41676292}],"con":true,"img":false}]}
{"op":"mcm","clk":"5347900072","pt":1646209976931,"mc":[{"id":"1.195453612","rc":[{"atl":[[16.5,0],[18.5,1.14]],"id":41762566},{"spn":11.2,"spf":"NaN","id":41762566},{"spn":2.11,"spf":"NaN","id":43066529},{"spn":17.25,"spf":"NaN","id":42651625},{"spn":1.97,"spf":"NaN","id":43167172},{"spn":1.99,"spf":"NaN","id":43167173}],"con":true,"img":false}]}
{"op":"mcm","clk":"5347900289","pt":1646209981730,"mc":[{"id":"1.195453612","rc":[{"atb":[[1.6,2.17]],"id":43066529},{"atb":[[1.43,2.17]],"id":43167172},{"atb":[[1.42,2.17]],"id":43167173}],"con":true,"img":false}]}
{"op":"mcm","clk":"5347900332","pt":1646209982561,"mc":[{"id":"1.195453612","rc":[{"atl":[[17.5,2.72]],"id":41762566}],"con":true,"img":false}]}
{"op":"mcm","clk":"5347900365","pt":1646209983132,"mc":[{"id":"1.195453612","rc":[{"atl":[[17,3.52]],"id":41762566},{"atl":[[2.72,11.63],[2.66,0]],"id":43066529},{"atb":[[4.4,29.41],[5.9,0]],"id":42651625},{"atb":[[2.66,48.6],[3.15,46.5]],"id":41676292},{"atb":[[1.21,0],[1.26,384.62]],"id":43167173}],"con":true,"img":false}]}
{"op":"mcm","clk":"5347900370","pt":1646209983234,"mc":[{"id":"1.195453612","rc":[{"atl":[[19,3.4]],"id":41762566}],"con":true,"img":false}]}
{"op":"mcm","clk":"5347900837","pt":1646209993145,"mc":[{"id":"1.195453612","rc":[{"atl":[[2.7,0],[2.76,28.41]],"id":43066529}],"con":true,"img":false}]}
{"op":"mcm","clk":"5347900918","pt":1646209995051,"mc":[{"id":"1.195453612","rc":[{"atb":[[5.3,46.5],[4.4,0]],"id":42651625},{"atb":[[2.82,48.6]],"id":41676292}],"con":true,"img":false}]}
{"op":"mcm","clk":"5347900923","pt":1646209995162,"mc":[{"id":"1.195453612","rc":[{"atb":[[2.66,0]],"id":41676292}],"con":true,"img":false}]}
{"op":"mcm","clk":"5347901174","pt":1646210000678,"mc":[{"id":"1.195453612","rc":[{"atl":[[2.68,0]],"id":43066529}],"con":true,"img":false}]}
{"op":"mcm","clk":"5347901182","pt":1646210000781,"mc":[{"id":"1.195453612","rc":[{"atl":[[2.72,33.91]],"id":43066529}],"con":true,"img":false}]}
{"op":"mcm","clk":"5347901273","pt":1646210003155,"mc":[{"id":"1.195453612","rc":[{"atl":[[2.8,41.67]],"id":43066529}],"con":true,"img":false}]}
{"op":"mcm","clk":"5347901326","pt":1646210004594,"mc":[{"id":"1.195453612","rc":[{"atb":[[3.9,0]],"id":41676292}],"con":true,"img":false}]}
{"op":"mcm","clk":"5347901331","pt":1646210004652,"mc":[{"id":"1.195453612","rc":[{"atb":[[4,15.06]],"id":41676292}],"con":true,"img":false}]}
{"op":"mcm","clk":"5347901707","pt":1646210013189,"mc":[{"id":"1.195453612","rc":[{"atl":[[2.74,0],[2.84,67.93],[2.78,20.42]],"id":43066529}],"con":true,"img":false}]}
{"op":"mcm","clk":"5347901992","pt":1646210020597,"mc":[{"id":"1.195453612","rc":[{"atl":[[2.72,11.63]],"id":43066529}],"con":true,"img":false}]}
{"op":"mcm","clk":"5347901994","pt":1646210020698,"mc":[{"id":"1.195453612","rc":[{"atl":[[2.74,22.28]],"id":43066529}],"con":true,"img":false}]}
{"op":"mcm","clk":"5347902068","pt":1646210022603,"mc":[{"id":"1.195453612","rc":[{"atl":[[19,0]],"id":41762566}],"con":true,"img":false}]}
{"op":"mcm","clk":"5347902074","pt":1646210022705,"mc":[{"id":"1.195453612","rc":[{"atl":[[18,3.4]],"id":41762566}],"con":true,"img":false}]}
{"op":"mcm","clk":"5347905399","pt":1646210111317,"mc":[{"id":"1.195453612","rc":[{"atb":[[1.58,21.01]],"id":43066529},{"spn":2.16,"spf":"NaN","id":43066529},{"atb":[[1.38,41.86]],"id":43167172},{"spn":1.98,"spf":"NaN","id":43167172},{"atb":[[1.4,30.01]],"id":43167173},{"spn":2.01,"spf":"NaN","id":43167173}],"con":true,"img":false}]}
{"op":"mcm","clk":"5347906082","pt":1646210131565,"mc":[{"id":"1.195453612","rc":[{"atb":[[1.36,164.51]],"id":43167173}],"con":true,"img":false}]}
{"op":"mcm","clk":"5347906085","pt":1646210131665,"mc":[{"id":"1.195453612","rc":[{"atb":[[1.38,83.04]],"id":43167173}],"con":true,"img":false}]}
{"op":"mcm","clk":"5347906118","pt":1646210132645,"mc":[{"id":"1.195453612","rc":[{"atb":[[1.39,21.41]],"id":43167173}],"con":true,"img":false}]}
{"op":"mcm","clk":"5347906341","pt":1646210138664,"mc":[{"id":"1.195453612","rc":[{"atb":[[1.41,18.35]],"id":43167173}],"con":true,"img":false}]}
{"op":"mcm","clk":"5347906383","pt":1646210139750,"mc":[{"id":"1.195453612","rc":[{"atl":[[16.5,1.29]],"id":41762566},{"atl":[[2.72,0],[2.78,31.66]],"id":43066529}],"con":true,"img":false}]}
{"op":"mcm","clk":"5347906479","pt":1646210141860,"mc":[{"id":"1.195453612","rc":[{"atb":[[1.4,0]],"id":43167173}],"con":true,"img":false}]}
{"op":"mcm","clk":"5347906550","pt":1646210143762,"mc":[{"id":"1.195453612","rc":[{"atl":[[2.76,0]],"id":43066529},{"atl":[[260,1],[250,0]],"id":42651625},{"atl":[[10.5,10.3],[21,3.63]],"id":41676292},{"atl":[[8,2.86],[7.8,14.71]],"id":43167172},{"atl":[[260,1],[250,0]],"id":43167173}],"con":true,"img":false}]}
{"op":"mcm","clk":"5347906566","pt":1646210144384,"mc":[{"id":"1.195453612","rc":[{"atb":[[1.54,0],[1.51,39.22],[1.52,0]],"id":43066529}],"con":true,"img":false}]}
{"op":"mcm","clk":"5347906571","pt":1646210144539,"mc":[{"id":"1.195453612","rc":[{"atb":[[1.58,0]],"id":43066529},{"atb":[[3.8,0]],"id":41676292},{"atb":[[1.42,16.54]],"id":43167173}],"con":true,"img":false}]}
{"op":"mcm","clk":"5347906573","pt":1646210144641,"mc":[{"id":"1.195453612","rc":[{"atb":[[3.2,22.28]],"id":41676292}],"con":true,"img":false}]}
{"op":"mcm","clk":"5347906665","pt":1646210146860,"mc":[{"id":"1.195453612","rc":[{"atb":[[1.54,37.04]],"id":43066529}],"con":true,"img":false}]}
{"op":"mcm","clk":"5347906751","pt":1646210149182,"mc":[{"id":"1.195453612","rc":[{"atb":[[1.54,70.06]],"id":43066529}],"con":true,"img":false}]}
{"op":"mcm","clk":"5347906775","pt":1646210149764,"mc":[{"id":"1.195453612","rc":[{"atl":[[17.5,5.75]],"id":41762566}],"con":true,"img":false}]}
{"op":"mcm","clk":"5347906783","pt":1646210150062,"mc":[{"id":"1.195453612","rc":[{"atl":[[17,2.27]],"id":41762566}],"con":true,"img":false}]}
{"op":"mcm","clk":"5347906812","pt":1646210150883,"mc":[{"id":"1.195453612","rc":[{"atb":[[1.57,14.64]],"id":43066529}],"con":true,"img":false}]}
{"op":"mcm","clk":"5347906818","pt":1646210151089,"mc":[{"id":"1.195453612","rc":[{"atl":[[2.74,0]],"id":43066529}],"con":true,"img":false}]}
{"op":"mcm","clk":"5347906821","pt":1646210151155,"mc":[{"id":"1.195453612","rc":[{"atl":[[2.76,22.28]],"id":43066529}],"con":true,"img":false}]}
{"op":"mcm","clk":"5347906910","pt":1646210153577,"mc":[{"id":"1.195453612","rc":[{"atb":[[1.39,0]],"id":43167173}],"con":true,"img":false}]}
{"op":"mcm","clk":"5347906916","pt":1646210153791,"mc":[{"id":"1.195453612","rc":[{"atl":[[280,1]],"id":42651625},{"atl":[[11.5,4.76]],"id":41676292},{"atl":[[8.4,6.76]],"id":43167172},{"atl":[[280,1]],"id":43167173}],"con":true,"img":false}]}
{"op":"mcm","clk":"5347906945","pt":1646210154560,"mc":[{"id":"1.195453612","rc":[{"atb":[[1.37,0]],"id":43167172}],"con":true,"img":false}]}
{"op":"mcm","clk":"5347906949","pt":1646210154669,"mc":[{"id":"1.195453612","rc":[{"atb":[[1.39,86.21]],"id":43167172}],"con":true,"img":false}]}
{"op":"mcm","clk":"5347907018","pt":1646210156779,"mc":[{"id":"1.195453612","rc":[{"atb":[[1.58,12.97]],"id":43066529},{"atb":[[1.4,20.88]],"id":43167172}],"con":true,"img":false}]}
{"op":"mcm","clk":"5347907023","pt":1646210156883,"mc":[{"id":"1.195453612","rc":[{"atl":[[2.82,27.47]],"id":43066529}],"con":true,"img":false}]}
{"op":"mcm","clk":"5347907038","pt":1646210157396,"mc":[{"id":"1.195453612","rc":[{"atb":[[1.38,0]],"id":43167172},{"atb":[[1.42,2.17]],"id":43167173}],"con":true,"img":false}]}
{"op":"mcm","clk":"5347907102","pt":1646210159558,"mc":[{"id":"1.195453612","rc":[{"atb":[[1.54,37.04]],"id":43066529}],"con":true,"img":false}]}
{"op":"mcm","clk":"5347907108","pt":1646210159761,"mc":[{"id":"1.195453612","rc":[{"atl":[[18.5,4.29]],"id":41762566}],"con":true,"img":false}]}
{"op":"mcm","clk":"5347907224","pt":1646210162397,"mc":[{"id":"1.195453612","rc":[{"atb":[[1.36,27.66]],"id":43167172},{"atb":[[1.39,20.52]],"id":43167173}],"con":true,"img":false}]}
{"op":"mcm","clk":"5347907247","pt":1646210162758,"mc":[{"id":"1.195453612","rc":[{"atb":[[1.58,0]],"id":43066529},{"atb":[[1.42,17.91]],"id":43167172}],"con":true,"img":false}]}
{"op":"mcm","clk":"5347907295","pt":1646210163787,"mc":[{"id":"1.195453612","rc":[{"atl":[[270,0],[290,0],[300,1],[310,0]],"id":42651625},{"atl":[[12.5,6.52],[27,0]],"id":41676292},{"atl":[[8.6,0],[9,0],[8.2,0],[8.8,9.62]],"id":43167172},{"atl":[[270,0],[290,0],[300,1],[310,0]],"id":43167173}],"con":true,"img":false}]}
{"op":"mcm","clk":"5347907331","pt":1646210164766,"mc":[{"id":"1.195453612","rc":[{"atb":[[1.55,16.66]],"id":43066529}],"con":true,"img":false}]}
{"op":"mcm","clk":"5347907337","pt":1646210164868,"mc":[{"id":"1.195453612","rc":[{"atb":[[1.41,38.72]],"id":43167173}],"con":true,"img":false}]}
{"op":"mcm","clk":"5347907346","pt":1646210165075,"mc":[{"id":"1.195453612","rc":[{"atb":[[10.5,0]],"id":42651625}],"con":true,"img":false}]}
{"op":"mcm","clk":"5347907352","pt":1646210165183,"mc":[{"id":"1.195453612","rc":[{"atb":[[11,5.6]],"id":42651625}],"con":true,"img":false}]}
{"op":"mcm","clk":"5347907372","pt":1646210165588,"mc":[{"id":"1.195453612","rc":[{"atl":[[10,4.85],[15.5,5.01]],"id":41676292}],"con":true,"img":false}]}
{"op":"mcm","clk":"5347907451","pt":1646210166880,"mc":[{"id":"1.195453612","rc":[{"atl":[[2.86,40.32]],"id":43066529}],"con":true,"img":false}]}
{"op":"mcm","clk":"5347907469","pt":1646210167188,"mc":[{"id":"1.195453612","rc":[{"atb":[[1.36,0]],"id":43167172}],"con":true,"img":false}]}
{"op":"mcm","clk":"5347907528","pt":1646210168807,"mc":[{"id":"1.195453612","rc":[{"atb":[[1.57,27.84]],"id":43066529}],"con":true,"img":false}]}
{"op":"mcm","clk":"5347907606","pt":1646210170569,"mc":[{"id":"1.195453612","rc":[{"atb":[[1.53,0]],"id":43066529}],"con":true,"img":false}]}
{"op":"mcm","clk":"5347907610","pt":1646210170670,"mc":[{"id":"1.195453612","rc":[{"atb":[[1.55,102.28]],"id":43066529}],"con":true,"img":false}]}
{"op":"mcm","clk":"5347907640","pt":1646210171389,"mc":[{"id":"1.195453612","rc":[{"spn":10.95,"spf":"NaN","id":41762566},{"spn":2.18,"spf":"NaN","id":43066529},{"spn":17.5,"spf":"NaN","id":42651625},{"spn":7.1,"spf":"NaN","id":41676292},{"atb":[[1.43,16.23]],"id":43167172}],"con":true,"img":false}]}
{"op":"mcm","clk":"5347907670","pt":1646210171906,"mc":[{"id":"1.195453612","rc":[{"atb":[[1.57,14.64]],"id":43066529}],"con":true,"img":false}]}
{"op":"mcm","clk":"5347907751","pt":1646210173813,"mc":[{"id":"1.195453612","rc":[{"atl":[[320,1]],"id":42651625},{"atl":[[25,0],[13.5,10]],"id":41676292},{"atl":[[9.2,15.24]],"id":43167172},{"atl":[[320,1]],"id":43167173}],"con":true,"img":false}]}
{"op":"mcm","clk":"5347907867","pt":1646210176636,"mc":[{"id":"1.195453612","rc":[{"atb":[[1.57,0]],"id":43066529},{"atb":[[1.4,0]],"id":43167172}],"con":true,"img":false}]}
{"op":"mcm","clk":"5347907884","pt":1646210176893,"mc":[{"id":"1.195453612","rc":[{"atl":[[2.8,0],[2.9,65.79],[2.84,0]],"id":43066529}],"con":true,"img":false}]}
{"op":"mcm","clk":"5347907939","pt":1646210177671,"mc":[{"id":"1.195453612","rc":[{"atb":[[1.59,12.75]],"id":43066529}],"con":true,"img":false}]}
{"op":"mcm","clk":"5347907996","pt":1646210178703,"mc":[{"id":"1.195453612","rc":[{"atb":[[1.55,16.66]],"id":43066529}],"con":true,"img":false}]}
{"op":"mcm","clk":"5347908001","pt":1646210178805,"mc":[{"id":"1.195453612","rc":[{"atb":[[1.51,124.84]],"id":43066529}],"con":true,"img":false}]}
{"op":"mcm","clk":"5347908033","pt":1646210179783,"mc":[{"id":"1.195453612","rc":[{"atb":[[1.55,0]],"id":43066529},{"atb":[[1.43,2.17]],"id":43167172}],"con":true,"img":false}]}
{"op":"mcm","clk":"5347908066","pt":1646210180708,"mc":[{"id":"1.195453612","rc":[{"atb":[[1.59,0]],"id":43066529}],"con":true,"img":false}]}
{"op":"mcm","clk":"5347908217","pt":1646210183602,"mc":[{"id":"1.195453612","rc":[{"atb":[[1.46,0]],"id":43066529}],"con":true,"img":false}]}
{"op":"mcm","clk":"5347908223","pt":1646210183704,"mc":[{"id":"1.195453612","rc":[{"atb":[[1.49,158.84]],"id":43066529}],"con":true,"img":false}]}
{"op":"mcm","clk":"5347908231","pt":1646210183813,"mc":[{"id":"1.195453612","rc":[{"atl":[[23,0]],"id":41676292}],"con":true,"img":false}]}
{"op":"mcm","clk":"5347908242","pt":1646210184069,"mc":[{"id":"1.195453612","rc":[{"atb":[[1.55,27.44]],"id":43066529},{"atb":[[1.36,28.13]],"id":43167172}],"con":true,"img":false}]}
{"op":"mcm","clk":"5347908387","pt":1646210186807,"mc":[{"id":"1.195453612","rc":[{"atb":[[1.54,50.97]],"id":43066529}],"con":true,"img":false}]}
{"op":"mcm","clk":"5347908484","pt":1646210189126,"mc":[{"id":"1.195453612","rc":[{"atl":[[18,0]],"id":41762566}],"con":true,"img":false}]}
{"op":"mcm","clk":"5347908490","pt":1646210189177,"mc":[{"id":"1.195453612","rc":[{"atl":[[17,5.67]],"id":41762566}],"con":true,"img":false}]}
{"op":"mcm","clk":"5347908511","pt":1646210189690,"mc":[{"id":"1.195453612","rc":[{"atb":[[1.42,37.8]],"id":43167172}],"con":true,"img":false}]}
{"op":"mcm","clk":"5347909125","pt":1646210201013,"mc":[{"id":"1.195453612","rc":[{"atb":[[1.54,66.44]],"id":43066529}],"con":true,"img":false}]}
{"op":"mcm","clk":"5347909163","pt":1646210201896,"mc":[{"id":"1.195453612","rc":[{"atb":[[1.54,52.5]],"id":43066529}],"con":true,"img":false}]}
{"op":"mcm","clk":"5347909275","pt":1646210204622,"mc":[{"id":"1.195453612","rc":[{"atb":[[1.51,39.22]],"id":43066529},{"atl":[[15,0]],"id":41676292}],"con":true,"img":false}]}
{"op":"mcm","clk":"5347909281","pt":1646210204724,"mc":[{"id":"1.195453612","rc":[{"atb":[[1.55,113.06]],"id":43066529},{"atl":[[12,4.36]],"id":41676292}],"con":true,"img":false}]}
{"op":"mcm","clk":"5347909692","pt":1646210213858,"mc":[{"id":"1.195453612","rc":[{"atb":[[1.59,12.75]],"id":43066529}],"con":true,"img":false}]}
{"op":"mcm","clk":"5347909822","pt":1646210217154,"mc":[{"id":"1.195453612","rc":[{"atb":[[1.55,85.62]],"id":43066529}],"con":true,"img":false}]}
{"op":"mcm","clk":"5347910028","pt":1646210221476,"mc":[{"id":"1.195453612","rc":[{"atb":[[4,0],[4.5,0],[5,0]],"id":41762566},{"atl":[[17,3.4],[38,0],[24,0]],"id":41762566},{"atb":[[1.4,0],[1.56,16.42],[1.45,0],[1.5,150]],"id":43066529},{"atl":[[3.45,0],[2.98,0],[2.78,11.24]],"id":43066529},{"atb":[[5.8,0],[5.3,23.26],[6.6,0]],"id":42651625},{"atl":[[70,0],[38,0],[24,0]],"id":42651625},{"atb":[[3.4,0],[3.15,0],[3.65,0]],"id":41676292},{"atl":[[10.5,6.48],[21,0],[15.5,0]],"id":41676292},{"atb":[[1.2,0],[1.25,0],[1.3,250]],"id":43167172},{"atl":[[2.54,0],[2.74,0],[2.94,0]],"id":43167172},{"atb":[[1.25,0],[1.3,0],[1.35,57.14]],"id":43167173},{"atl":[[2.8,0],[3,0],[2.6,0]],"id":43167173}],"con":true,"img":false}]}
{"op":"mcm","clk":"5347910036","pt":1646210221631,"mc":[{"id":"1.195453612","rc":[{"atl":[[65,4.72],[48,0]],"id":42651625}],"con":true,"img":false}]}
{"op":"mcm","clk":"5347910054","pt":1646210222042,"mc":[{"id":"1.195453612","rc":[{"atb":[[4.1,0]],"id":41762566},{"atl":[[3.4,0],[3.75,21.83]],"id":43066529},{"atl":[[12,0]],"id":41676292},{"atl":[[2.92,0],[3.15,26.71]],"id":43167172},{"atl":[[3.15,27.54],[2.78,24.53]],"id":43167173}],"con":true,"img":false}]}
{"op":"mcm","clk":"5347910060","pt":1646210222143,"mc":[{"id":"1.195453612","rc":[{"atb":[[3.65,21.16]],"id":41762566},{"atl":[[13,4.36]],"id":41676292}],"con":true,"img":false}]}
{"op":"mcm","clk":"5347910083","pt":1646210222555,"mc":[{"id":"1.195453612","rc":[{"atl":[[17,0]],"id":41762566},{"atb":[[8.6,0],[11,0]],"id":42651625}],"con":true,"img":false}]}
{"op":"mcm","clk":"5347910089","pt":1646210222657,"mc":[{"id":"1.195453612","rc":[{"atl":[[18,3.4]],"id":41762566},{"atb":[[8.6,5.6],[7.4,8.97]],"id":42651625},{"atb":[[2.82,0]],"id":41676292}],"con":true,"img":false}]}
{"op":"mcm","clk":"5347910093","pt":1646210222760,"mc":[{"id":"1.195453612","rc":[{"atb":[[2.7,39.23]],"id":41676292}],"con":true,"img":false}]}
{"op":"mcm","clk":"5347910136","pt":1646210223533,"mc":[{"id":"1.195453612","rc":[{"atb":[[1.33,0]],"id":43167172}],"con":true,"img":false}]}
{"op":"mcm","clk":"5347910143","pt":1646210223636,"mc":[{"id":"1.195453612","rc":[{"atb":[[1.36,197.1]],"id":43167172}],"con":true,"img":false}]}
{"op":"mcm","clk":"5347910179","pt":1646210224669,"mc":[{"id":"1.195453612","rc":[{"atb":[[4,33.32],[4.5,28.56],[5,24.99]],"id":41762566},{"atl":[[17,2.27],[38,1.96],[24,3.16]],"id":41762566},{"atb":[[1.4,249.93],[1.45,222.16],[1.5,349.94]],"id":43066529},{"atl":[[3.45,29.67],[2.98,36.71],[2.78,31.66]],"id":43066529},{"atb":[[5.8,20.82],[5.3,46.5],[6.6,17.85]],"id":42651625},{"atl":[[70,1.05],[38,1.96],[24,1.58]],"id":42651625},{"atb":[[3.4,41.65],[3.15,46.5],[3.65,37.72]],"id":41676292},{"atl":[[10.5,10.3],[21,3.63],[15.5,5.01]],"id":41676292},{"atb":[[1.2,499.86],[1.25,399.89],[1.3,583.24]],"id":43167172},{"atl":[[2.54,23.6],[2.74,41.78],[2.94,37.47]],"id":43167172},{"atb":[[1.25,399.89],[1.3,333.24],[1.35,342.77]],"id":43167173},{"atl":[[2.8,40.39],[3,36.35],[2.6,22.72]],"id":43167173}],"con":true,"img":false}]}
{"op":"mcm","clk":"5347910199","pt":1646210225234,"mc":[{"id":"1.195453612","rc":[{"atb":[[1.36,168.97]],"id":43167172}],"con":true,"img":false}]}
{"op":"mcm","clk":"5347910272","pt":1646210227138,"mc":[{"id":"1.195453612","rc":[{"atb":[[1.54,37.04]],"id":43066529}],"con":true,"img":false}]}
{"op":"mcm","clk":"5347910389","pt":1646210229870,"mc":[{"id":"1.195453612","rc":[{"atb":[[1.37,51.97]],"id":43167172}],"con":true,"img":false}]}
{"op":"mcm","clk":"5347910500","pt":1646210232238,"mc":[{"id":"1.195453612","rc":[{"spn":16.3,"spf":"NaN","id":42651625},{"atb":[[2.82,48.6],[2.7,0]],"id":41676292}],"con":true,"img":false}]}
{"op":"mcm","clk":"5347910706","pt":1646210236766,"mc":[{"id":"1.195453612","rc":[{"atb":[[1.59,26.91]],"id":43066529}],"con":true,"img":false}]}
{"op":"mcm","clk":"5347910976","pt":1646210243137,"mc":[{"id":"1.195453612","rc":[{"atl":[[55,0]],"id":42651625}],"con":true,"img":false}]}
{"op":"mcm","clk":"5347910982","pt":1646210243242,"mc":[{"id":"1.195453612","rc":[{"atl":[[40,2.72]],"id":42651625}],"con":true,"img":false}]}
{"op":"mcm","clk":"5347911038","pt":1646210244629,"mc":[{"id":"1.195453612","rc":[{"atb":[[1.39,0]],"id":43167172},{"atb":[[1.38,0]],"id":43167173}],"con":true,"img":false}]}
{"op":"mcm","clk":"5347911042","pt":1646210244739,"mc":[{"id":"1.195453612","rc":[{"atb":[[1.43,88.38]],"id":43167172},{"atb":[[1.42,85.21]],"id":43167173}],"con":true,"img":false}]}
{"op":"mcm","clk":"5347911058","pt":1646210245041,"mc":[{"id":"1.195453612","rc":[{"atb":[[1.42,2.17]],"id":43167173}],"con":true,"img":false}]}
{"op":"mcm","clk":"5347911063","pt":1646210245142,"mc":[{"id":"1.195453612","rc":[{"atb":[[1.39,103.57]],"id":43167173}],"con":true,"img":false}]}
{"op":"mcm","clk":"5347911154","pt":1646210246945,"mc":[{"id":"1.195453612","rc":[{"atb":[[1.42,19.88]],"id":43167172},{"atb":[[1.41,20.37]],"id":43167173}],"con":true,"img":false}]}
{"op":"mcm","clk":"5347911226","pt":1646210248442,"mc":[{"id":"1.195453612","rc":[{"atb":[[1.37,0]],"id":43167172},{"atb":[[1.39,83.04]],"id":43167173}],"con":true,"img":false}]}
{"op":"mcm","clk":"5347911251","pt":1646210249059,"mc":[{"id":"1.195453612","rc":[{"atb":[[1.43,2.17]],"id":43167172}],"con":true,"img":false}]}
{"op":"mcm","clk":"5347911255","pt":1646210249163,"mc":[{"id":"1.195453612","rc":[{"atb":[[1.39,86.21]],"id":43167172}],"con":true,"img":false}]}
{"op":"mcm","clk":"5347911406","pt":1646210252969,"mc":[{"id":"1.195453612","rc":[{"atb":[[1.42,20.08]],"id":43167173}],"con":true,"img":false}]}
{"op":"mcm","clk":"5347911419","pt":1646210253175,"mc":[{"id":"1.195453612","rc":[{"atb":[[1.37,28.67]],"id":43167172},{"atb":[[1.37,27.04]],"id":43167173}],"con":true,"img":false}]}
{"op":"mcm","clk":"5347911550","pt":1646210255954,"mc":[{"id":"1.195453612","rc":[{"atb":[[1.42,37.8]],"id":43167172}],"con":true,"img":false}]}
{"op":"mcm","clk":"5347911604","pt":1646210257098,"mc":[{"id":"1.195453612","rc":[{"atb":[[1.37,0]],"id":43167173}],"con":true,"img":false}]}
{"op":"mcm","clk":"5347911710","pt":1646210258994,"mc":[{"id":"1.195453612","rc":[{"atb":[[1.02,3]],"id":43066529}],"con":true,"img":false}]}
{"op":"mcm","clk":"5347911803","pt":1646210261154,"mc":[{"id":"1.195453612","rc":[{"atb":[[1.43,14.06]],"id":43167173}],"con":true,"img":false}]}
{"op":"mcm","clk":"5347911807","pt":1646210261257,"mc":[{"id":"1.195453612","rc":[{"atb":[[1.03,4]],"id":43066529}],"con":true,"img":false}]}
{"op":"mcm","clk":"5347911812","pt":1646210261361,"mc":[{"id":"1.195453612","rc":[{"atb":[[1.02,0]],"id":43066529},{"atl":[[2.8,11.11],[2.78,20.42]],"id":43066529},{"atb":[[1.46,2.17],[1.42,17.91]],"id":43167173}],"con":true,"img":false}]}
{"op":"mcm","clk":"5347911876","pt":1646210262901,"mc":[{"id":"1.195453612","rc":[{"atb":[[1.03,0]],"id":43066529}],"con":true,"img":false}]}
{"op":"mcm","clk":"5347911914","pt":1646210263572,"mc":[{"id":"1.195453612","rc":[{"atl":[[65,2]],"id":42651625}],"con":true,"img":false}]}
{"op":"mcm","clk":"5347911920","pt":1646210263676,"mc":[{"id":"1.195453612","rc":[{"atl":[[46,2.72]],"id":42651625}],"con":true,"img":false}]}
{"op":"mcm","clk":"5347911939","pt":1646210264088,"mc":[{"id":"1.195453612","rc":[{"atl":[[18,0]],"id":41762566}],"con":true,"img":false}]}
{"op":"mcm","clk":"5347911943","pt":1646210264190,"mc":[{"id":"1.195453612","rc":[{"atl":[[17,5.67]],"id":41762566}],"con":true,"img":false}]}
{"op":"mcm","clk":"5347911971","pt":1646210264603,"mc":[{"id":"1.195453612","rc":[{"atl":[[3.15,0]],"id":43167172}],"con":true,"img":false}]}
{"op":"mcm","clk":"5347911976","pt":1646210264705,"mc":[{"id":"1.195453612","rc":[{"atl":[[2.92,26.71]],"id":43167172}],"con":true,"img":false}]}
{"op":"mcm","clk":"5347911986","pt":1646210264910,"mc":[{"id":"1.195453612","rc":[{"atb":[[1.41,0]],"id":43167173}],"con":true,"img":false}]}
{"op":"mcm","clk":"5347911994","pt":1646210265072,"mc":[{"id":"1.195453612","rc":[{"atl":[[3.4,27.29],[3.75,0]],"id":43066529},{"atl":[[13,0]],"id":41676292}],"con":true,"img":false}]}
{"op":"mcm","clk":"5347912000","pt":1646210265167,"mc":[{"id":"1.195453612","rc":[{"atl":[[12,4.36]],"id":41676292}],"con":true,"img":false}]}
{"op":"mcm","clk":"5347912023","pt":1646210265578,"mc":[{"id":"1.195453612","rc":[{"atl":[[3.15,0],[2.78,57.8]],"id":43167173}],"con":true,"img":false}]}
{"op":"mcm","clk":"5347912102","pt":1646210267480,"mc":[{"id":"1.195453612","rc":[{"atb":[[1.43,0]],"id":43167173}],"con":true,"img":false}]}
{"op":"mcm","clk":"5347912107","pt":1646210267584,"mc":[{"id":"1.195453612","rc":[{"atb":[[3.65,0]],"id":41762566}],"con":true,"img":false}]}
{"op":"mcm","clk":"5347912111","pt":1646210267687,"mc":[{"id":"1.195453612","rc":[{"atb":[[4.1,21.16]],"id":41762566}],"con":true,"img":false}]}
{"op":"mcm","clk":"5347912155","pt":1646210268614,"mc":[{"id":"1.195453612","rc":[{"atl":[[2.76,0]],"id":43066529}],"con":true,"img":false}]}
{"op":"mcm","clk":"5347912163","pt":1646210268720,"mc":[{"id":"1.195453612","rc":[{"atl":[[2.8,33.39]],"id":43066529}],"con":true,"img":false}]}
{"op":"mcm","clk":"5347912294","pt":1646210271416,"mc":[{"id":"1.195453612","rc":[{"atl":[[2.84,27.17]],"id":43066529}],"con":true,"img":false}]}
{"op":"mcm","clk":"5347912302","pt":1646210271569,"mc":[{"id":"1.195453612","rc":[{"atl":[[2.82,0],[2.86,0],[2.9,0]],"id":43066529}],"con":true,"img":false}]}
{"op":"mcm","clk":"5347912310","pt":1646210271775,"mc":[{"id":"1.195453612","rc":[{"atb":[[1.37,26.12]],"id":43167173}],"con":true,"img":false}]}
{"op":"mcm","clk":"5347912610","pt":1646210278397,"mc":[{"id":"1.195453612","rc":[{"atb":[[1.42,37.8]],"id":43167173}],"con":true,"img":false}]}
{"op":"mcm","clk":"5347912617","pt":1646210278610,"mc":[{"id":"1.195453612","rc":[{"atb":[[1.39,0]],"id":43167172}],"con":true,"img":false}]}
{"op":"mcm","clk":"5347912623","pt":1646210278707,"mc":[{"id":"1.195453612","rc":[{"atb":[[1.43,88.38]],"id":43167172}],"con":true,"img":false}]}
{"op":"mcm","clk":"5347912663","pt":1646210279589,"mc":[{"id":"1.195453612","rc":[{"atl":[[2.8,11.11]],"id":43066529}],"con":true,"img":false}]}
{"op":"mcm","clk":"5347912666","pt":1646210279693,"mc":[{"id":"1.195453612","rc":[{"atl":[[2.82,22.28]],"id":43066529}],"con":true,"img":false}]}
{"op":"mcm","clk":"5347912674","pt":1646210280002,"mc":[{"id":"1.195453612","rc":[{"atb":[[1.42,19.88]],"id":43167172}],"con":true,"img":false}]}
{"op":"mcm","clk":"5347912703","pt":1646210280624,"mc":[{"id":"1.195453612","rc":[{"atb":[[1.43,2.17]],"id":43167172}],"con":true,"img":false}]}
{"op":"mcm","clk":"5347912708","pt":1646210280730,"mc":[{"id":"1.195453612","rc":[{"atb":[[1.39,86.21]],"id":43167172}],"con":true,"img":false}]}
{"op":"mcm","clk":"5347912755","pt":1646210281398,"mc":[{"id":"1.195453612","rc":[{"atl":[[2.88,39.89]],"id":43066529}],"con":true,"img":false}]}
{"op":"mcm","clk":"5347912807","pt":1646210282794,"mc":[{"id":"1.195453612","rc":[{"atb":[[1.37,0]],"id":43167172}],"con":true,"img":false}]}
{"op":"mcm","clk":"5347912826","pt":1646210283412,"mc":[{"id":"1.195453612","rc":[{"atl":[[2.78,31.66]],"id":43066529}],"con":true,"img":false}]}
{"op":"mcm","clk":"5347912979","pt":1646210287387,"mc":[{"id":"1.195453612","rc":[{"atb":[[1.37,28.67]],"id":43167172}],"con":true,"img":false}]}
{"op":"mcm","clk":"5347913056","pt":1646210289037,"mc":[{"id":"1.195453612","rc":[{"atb":[[1.42,37.8]],"id":43167172}],"con":true,"img":false}]}
{"op":"mcm","clk":"5347913234","pt":1646210293411,"mc":[{"id":"1.195453612","rc":[{"atl":[[2.82,49.75]],"id":43066529},{"spn":2.19,"spf":"NaN","id":43066529},{"spn":2.03,"spf":"NaN","id":43167173}],"con":true,"img":false}]}
{"op":"mcm","clk":"5347913522","pt":1646210300741,"mc":[{"id":"1.195453612","rc":[{"atb":[[1.39,0]],"id":43167173}],"con":true,"img":false}]}
{"op":"mcm","clk":"5347913529","pt":1646210300844,"mc":[{"id":"1.195453612","rc":[{"atb":[[1.43,83.04]],"id":43167173}],"con":true,"img":false}]}
{"op":"mcm","clk":"5347913682","pt":1646210303453,"mc":[{"id":"1.195453612","rc":[{"atl":[[2.8,0],[2.88,0],[2.86,40.32],[2.84,0]],"id":43066529}],"con":true,"img":false}]}
{"op":"mcm","clk":"5347913710","pt":1646210303970,"mc":[{"id":"1.195453612","rc":[{"atb":[[1.42,19.88]],"id":43167173}],"con":true,"img":false}]}
{"op":"mcm","clk":"5347913714","pt":1646210304021,"mc":[{"id":"1.195453612","rc":[{"atl":[[2.82,27.47]],"id":43066529}],"con":true,"img":false}]}
{"op":"mcm","clk":"5347913719","pt":1646210304125,"mc":[{"id":"1.195453612","rc":[{"atl":[[2.76,22.28]],"id":43066529},{"atb":[[1.37,0]],"id":43167173}],"con":true,"img":false}]}
{"op":"mcm","clk":"5347913735","pt":1646210304540,"mc":[{"id":"1.195453612","rc":[{"atb":[[1.43,0]],"id":43167173}],"con":true,"img":false}]}
{"op":"mcm","clk":"5347913740","pt":1646210304643,"mc":[{"id":"1.195453612","rc":[{"atb":[[1.38,83.04]],"id":43167173}],"con":true,"img":false}]}
{"op":"mcm","clk":"5347913916","pt":1646210308968,"mc":[{"id":"1.195453612","rc":[{"atb":[[1.39,24.26]],"id":43167173}],"con":true,"img":false}]}
{"op":"mcm","clk":"5347914023","pt":1646210311549,"mc":[{"id":"1.195453612","rc":[{"atb":[[1.39,0]],"id":43167172}],"con":true,"img":false}]}
{"op":"mcm","clk":"5347914029","pt":1646210311653,"mc":[{"id":"1.195453612","rc":[{"atb":[[1.43,88.38]],"id":43167172}],"con":true,"img":false}]}
{"op":"mcm","clk":"5347914096","pt":1646210313048,"mc":[{"id":"1.195453612","rc":[{"atb":[[1.42,0]],"id":43167172},{"atb":[[1.41,18.35],[1.42,0]],"id":43167173}],"con":true,"img":false}]}
{"op":"mcm","clk":"5347914112","pt":1646210313469,"mc":[{"id":"1.195453612","rc":[{"atl":[[2.9,65.79]],"id":43066529}],"con":true,"img":false}]}
{"op":"mcm","clk":"5347914119","pt":1646210313566,"mc":[{"id":"1.195453612","rc":[{"atb":[[1.43,2.17]],"id":43167172}],"con":true,"img":false}]}
{"op":"mcm","clk":"5347914124","pt":1646210313667,"mc":[{"id":"1.195453612","rc":[{"atb":[[1.39,86.21]],"id":43167172}],"con":true,"img":false}]}
{"op":"mcm","clk":"5347914144","pt":1646210314235,"mc":[{"id":"1.195453612","rc":[{"atb":[[1.37,0]],"id":43167172}],"con":true,"img":false}]}
{"op":"mcm","clk":"5347914295","pt":1646210318969,"mc":[{"id":"1.195453612","rc":[{"atb":[[1.4,61.86]],"id":43167172}],"con":true,"img":false}]}
{"op":"mcm","clk":"5347914329","pt":1646210319950,"mc":[{"id":"1.195453612","rc":[{"atl":[[42,2.44],[170,1]],"id":42651625},{"atb":[[3.2,31.37]],"id":41676292},{"atl":[[8.8,2.56]],"id":41676292},{"atl":[[8,0],[8.4,2.7]],"id":43167172},{"atl":[[65,0],[4.3,36.36]],"id":43167173}],"con":true,"img":false}]}
{"op":"mcm","clk":"5347914332","pt":1646210320052,"mc":[{"id":"1.195453612","rc":[{"atl":[[2.82,10.99],[2.78,20.42]],"id":43066529},{"atl":[[65,0],[260,0]],"id":42651625},{"atb":[[2.82,0],[3.85,0],[3.95,0],[4.1,0],[3.75,0],[3.05,48.6]],"id":41676292},{"atl":[[10.5,3.82],[9.8,4.85]],"id":41676292},{"atl":[[260,0]],"id":43167173}],"con":true,"img":false}]}
{"op":"mcm","clk":"5347914356","pt":1646210320670,"mc":[{"id":"1.195453612","rc":[{"atb":[[1.54,0]],"id":43066529},{"atl":[[1.82,2]],"id":43066529}],"con":true,"img":false}]}
{"op":"mcm","clk":"5347914360","pt":1646210320874,"mc":[{"id":"1.195453612","rc":[{"atl":[[1.82,0],[1.8,2]],"id":43066529}],"con":true,"img":false}]}
{"op":"mcm","clk":"5347914388","pt":1646210321953,"mc":[{"id":"1.195453612","rc":[{"atl":[[1.79,3]],"id":43066529}],"con":true,"img":false}]}
{"op":"mcm","clk":"5347914393","pt":1646210322159,"mc":[{"id":"1.195453612","rc":[{"atl":[[1.8,0]],"id":43066529}],"con":true,"img":false}]}
{"op":"mcm","clk":"5347914400","pt":1646210322366,"mc":[{"id":"1.195453612","rc":[{"atl":[[16.5,0],[16,1.33]],"id":41762566},{"atl":[[2.82,0],[1.78,2],[2.84,10.87]],"id":43066529}],"con":true,"img":false}]}
{"op":"mcm","clk":"5347914411","pt":1646210322570,"mc":[{"id":"1.195453612","rc":[{"atl":[[1.79,0],[1.77,3]],"id":43066529}],"con":true,"img":false}]}
{"op":"mcm","clk":"5347914429","pt":1646210322932,"mc":[{"id":"1.195453612","rc":[{"atb":[[1.36,0]],"id":43167173},{"atl":[[2.78,24.53]],"id":43167173}],"con":true,"img":false}]}
{"op":"mcm","clk":"5347914436","pt":1646210323036,"mc":[{"id":"1.195453612","rc":[{"atb":[[1.34,164.51]],"id":43167173},{"atl":[[2.98,33.27]],"id":43167173}],"con":true,"img":false}]}
{"op":"mcm","clk":"5347914452","pt":1646210323550,"mc":[{"id":"1.195453612","rc":[{"atl":[[1.76,4]],"id":43066529}],"con":true,"img":false}]}
{"op":"mcm","clk":"5347914464","pt":1646210323962,"mc":[{"id":"1.195453612","rc":[{"atb":[[1.41,38.72]],"id":43167173}],"con":true,"img":false}]}
{"op":"mcm","clk":"5347914470","pt":1646210324270,"mc":[{"id":"1.195453612","rc":[{"atb":[[1.54,37.04]],"id":43066529},{"atl":[[1.78,0],[1.77,0],[1.76,0]],"id":43066529}],"con":true,"img":false}]}
{"op":"mcm","clk":"5347914476","pt":1646210324579,"mc":[{"id":"1.195453612","rc":[{"atb":[[4.2,0]],"id":41676292}],"con":true,"img":false}]}
{"op":"mcm","clk":"5347914483","pt":1646210324734,"mc":[{"id":"1.195453612","rc":[{"atb":[[4.1,1.67]],"id":41676292}],"con":true,"img":false}]}
{"op":"mcm","clk":"5347914567","pt":1646210328085,"mc":[{"id":"1.195453612","rc":[{"atb":[[3.75,2.73]],"id":41676292},{"atb":[[1.43,19.67]],"id":43167172}],"con":true,"img":false}]}
{"op":"mcm","clk":"5347914573","pt":1646210328137,"mc":[{"id":"1.195453612","rc":[{"atb":[[4,0]],"id":41676292},{"atl":[[10,0]],"id":41676292}],"con":true,"img":false}]}
{"op":"mcm","clk":"5347914575","pt":1646210328241,"mc":[{"id":"1.195453612","rc":[{"atb":[[3.7,15.06]],"id":41676292},{"atl":[[10,7.41],[12,9.21],[9.8,0]],"id":41676292}],"con":true,"img":false}]}
{"op":"mcm","clk":"5347914598","pt":1646210329169,"mc":[{"id":"1.195453612","rc":[{"atb":[[7.4,0]],"id":42651625}],"con":true,"img":false}]}
{"op":"mcm","clk":"5347914601","pt":1646210329272,"mc":[{"id":"1.195453612","rc":[{"atb":[[7,8.97]],"id":42651625}],"con":true,"img":false}]}
{"op":"mcm","clk":"5347914615","pt":1646210330042,"mc":[{"id":"1.195453612","rc":[{"atl":[[190,1]],"id":42651625},{"atb":[[3.1,23.81]],"id":41676292},{"atl":[[9.2,6.1]],"id":41676292},{"atl":[[8.8,6.41]],"id":43167172},{"atl":[[4.5,14.29]],"id":43167173}],"con":true,"img":false}]}
{"op":"mcm","clk":"5347914620","pt":1646210330145,"mc":[{"id":"1.195453612","rc":[{"atl":[[9,6.1],[10,0]],"id":41676292}],"con":true,"img":false}]}
{"op":"mcm","clk":"5347914632","pt":1646210330557,"mc":[{"id":"1.195453612","rc":[{"atb":[[4.1,0]],"id":41676292},{"atb":[[1.38,0]],"id":43167173}],"con":true,"img":false}]}
{"op":"mcm","clk":"5347914635","pt":1646210330660,"mc":[{"id":"1.195453612","rc":[{"atb":[[1.36,83.04]],"id":43167173}],"con":true,"img":false}]}
{"op":"mcm","clk":"5347914640","pt":1646210330763,"mc":[{"id":"1.195453612","rc":[{"atb":[[3.8,1.67]],"id":41676292}],"con":true,"img":false}]}
{"op":"mcm","clk":"5347914649","pt":1646210330968,"mc":[{"id":"1.195453612","rc":[{"atb":[[1.4,0]],"id":43167172}],"con":true,"img":false}]}
{"op":"mcm","clk":"5347914656","pt":1646210331071,"mc":[{"id":"1.195453612","rc":[{"atb":[[1.41,20.37]],"id":43167173}],"con":true,"img":false}]}
{"op":"mcm","clk":"5347914693","pt":1646210332148,"mc":[{"id":"1.195453612","rc":[{"atl":[[2.76,0]],"id":43066529}],"con":true,"img":false}]}
{"op":"mcm","clk":"5347914700","pt":1646210332252,"mc":[{"id":"1.195453612","rc":[{"atl":[[2.84,33.15]],"id":43066529}],"con":true,"img":false}]}
{"op":"mcm","clk":"5347914730","pt":1646210333178,"mc":[{"id":"1.195453612","rc":[{"atb":[[1.39,0]],"id":43167173}],"con":true,"img":false}]}
{"op":"mcm","clk":"5347914747","pt":1646210333647,"mc":[{"id":"1.195453612","rc":[{"atl":[[280,0],[300,0],[320,0]],"id":42651625},{"atl":[[11.5,0],[12.5,0],[13.5,0]],"id":41676292},{"atl":[[280,0],[300,0],[320,0]],"id":43167173}],"con":true,"img":false}]}
{"op":"mcm","clk":"5347914764","pt":1646210334165,"mc":[{"id":"1.195453612","rc":[{"atl":[[12,4.85]],"id":41676292}],"con":true,"img":false}]}
{"op":"mcm","clk":"5347914768","pt":1646210334268,"mc":[{"id":"1.195453612","rc":[{"atl":[[2.88,26.6]],"id":43066529},{"atl":[[13.5,4.36]],"id":41676292}],"con":true,"img":false}]}
{"op":"mcm","clk":"5347914794","pt":1646210335046,"mc":[{"id":"1.195453612","rc":[{"atb":[[1.43,2.17]],"id":43167172}],"con":true,"img":false}]}
{"op":"mcm","clk":"5347914803","pt":1646210335251,"mc":[{"id":"1.195453612","rc":[{"atl":[[9,0],[9.2,14.76]],"id":41676292}],"con":true,"img":false}]}
{"op":"mcm","clk":"5347914806","pt":1646210335355,"mc":[{"id":"1.195453612","rc":[{"atl":[[9.2,6.1],[10,11.11]],"id":41676292}],"con":true,"img":false}]}
{"op":"mcm","clk":"5347914812","pt":1646210335458,"mc":[{"id":"1.195453612","rc":[{"atb":[[1.37,27.55]],"id":43167172}],"con":true,"img":false}]}
{"op":"mcm","clk":"5347914870","pt":1646210337054,"mc":[{"id":"1.195453612","rc":[{"atb":[[1.39,19.29]],"id":43167173}],"con":true,"img":false}]}
{"op":"mcm","clk":"5347914893","pt":1646210337671,"mc":[{"id":"1.195453612","rc":[{"atb":[[1.37,27.04]],"id":43167173}],"con":true,"img":false}]}
{"op":"mcm","clk":"5347914965","pt":1646210340090,"mc":[{"id":"1.195453612","rc":[{"atl":[[210,1]],"id":42651625},{"atb":[[3,37.5]],"id":41676292},{"atl":[[9.6,8.72]],"id":41676292},{"atl":[[9.2,9.15]],"id":43167172},{"atl":[[4.7,20.27]],"id":43167173}],"con":true,"img":false}]}
{"op":"mcm","clk":"5347914968","pt":1646210340295,"mc":[{"id":"1.195453612","rc":[{"atb":[[7.2,16.7],[8.6,9.92]],"id":42651625},{"atl":[[40,8.34],[22,2.5],[23,3.64],[26,5]],"id":42651625},{"atb":[[3.8,4.17],[3.75,6.71],[3.65,63.54]],"id":41676292},{"atl":[[9.6,17.38],[8.6,3.98],[10,22.5],[9.4,2.5]],"id":41676292},{"atb":[[1.37,30.05]],"id":43167172},{"atl":[[2.88,2.5],[2.74,123.91],[2.52,42.21]],"id":43167172},{"atb":[[1.39,83.93],[1.4,2.5]],"id":43167173},{"atl":[[2.8,105.03],[2.58,32.32],[2.78,34.53],[2.62,2.5],[2.7,5]],"id":43167173}],"con":true,"img":false}]}
{"op":"mcm","clk":"5347914971","pt":1646210340352,"mc":[{"id":"1.195453612","rc":[{"atl":[[9.2,14.82]],"id":41676292}],"con":true,"img":false}]}
{"op":"mcm","clk":"5347914974","pt":1646210340450,"mc":[{"id":"1.195453612","rc":[{"atl":[[9.6,8.72]],"id":41676292}],"con":true,"img":false}]}
{"op":"mcm","clk":"5347914980","pt":1646210340658,"mc":[{"id":"1.195453612","rc":[{"atl":[[17,2.27]],"id":41762566},{"atl":[[40,5.62]],"id":42651625}],"con":true,"img":false}]}
{"op":"mcm","clk":"5347914983","pt":1646210340760,"mc":[{"id":"1.195453612","rc":[{"atb":[[5.1,27.82],[5.5,7.81]],"id":41762566},{"atl":[[16,6.31],[18,3.4]],"id":41762566},{"atl":[[36,2.72]],"id":42651625}],"con":true,"img":false}]}
{"op":"mcm","clk":"5347914986","pt":1646210340864,"mc":[{"id":"1.195453612","rc":[{"atb":[[5.5,14.13],[5.4,1.67]],"id":41762566}],"con":true,"img":false}]}
{"op":"mcm","clk":"5347914993","pt":1646210341172,"mc":[{"id":"1.195453612","rc":[{"atb":[[7,0]],"id":42651625}],"con":true,"img":false}]}
{"op":"mcm","clk":"5347914999","pt":1646210341276,"mc":[{"id":"1.195453612","rc":[{"atb":[[6.8,15.43],[6.6,26.83]],"id":42651625}],"con":true,"img":false}]}
{"op":"mcm","clk":"5347915026","pt":1646210341948,"mc":[{"id":"1.195453612","rc":[{"atb":[[1.37,0]],"id":43167173}],"con":true,"img":false}]}
{"op":"mcm","clk":"5347915034","pt":1646210342153,"mc":[{"id":"1.195453612","rc":[{"atb":[[3.75,9.75]],"id":41676292}],"con":true,"img":false}]}
{"op":"mcm","clk":"5347915043","pt":1646210342461,"mc":[{"id":"1.195453612","rc":[{"atb":[[5.4,0]],"id":41762566}],"con":true,"img":false}]}
{"op":"mcm","clk":"5347915050","pt":1646210342667,"mc":[{"id":"1.195453612","rc":[{"atb":[[5.6,1.67]],"id":41762566}],"con":true,"img":false}]}
{"op":"mcm","clk":"5347915066","pt":1646210343079,"mc":[{"id":"1.195453612","rc":[{"atb":[[1.42,17.91]],"id":43167172},{"atb":[[1.39,64.64]],"id":43167173}],"con":true,"img":false}]}
{"op":"mcm","clk":"5347915086","pt":1646210343491,"mc":[{"id":"1.195453612","rc":[{"atb":[[1.56,87.43],[1.6,37.68]],"id":43066529},{"atl":[[2.78,55.93]],"id":43066529}],"con":true,"img":false}]}
{"op":"mcm","clk":"5347915115","pt":1646210344264,"mc":[{"id":"1.195453612","rc":[{"atl":[[2.92,39.06]],"id":43066529}],"con":true,"img":false}]}
{"op":"mcm","clk":"5347915126","pt":1646210344677,"mc":[{"id":"1.195453612","rc":[{"atb":[[1.55,88.12]],"id":43066529},{"atl":[[2.86,0],[2.9,0]],"id":43066529}],"con":true,"img":false}]}
{"op":"mcm","clk":"5347915214","pt":1646210346378,"mc":[{"id":"1.195453612","rc":[{"atb":[[1.59,14.15]],"id":43066529}],"con":true,"img":false}]}
{"op":"mcm","clk":"5347915217","pt":1646210346481,"mc":[{"id":"1.195453612","rc":[{"atb":[[1.56,71.01]],"id":43066529},{"atb":[[1.37,2.5]],"id":43167172},{"atb":[[1.42,15.78]],"id":43167173}],"con":true,"img":false}]}
{"op":"mcm","clk":"5347915314","pt":1646210348698,"mc":[{"id":"1.195453612","rc":[{"atb":[[8.6,4.32]],"id":42651625}],"con":true,"img":false}]}
{"op":"mcm","clk":"5347915317","pt":1646210348801,"mc":[{"id":"1.195453612","rc":[{"atb":[[7.4,5.6]],"id":42651625}],"con":true,"img":false}]}
{"op":"mcm","clk":"5347915320","pt":1646210348910,"mc":[{"id":"1.195453612","rc":[{"atb":[[8.6,0]],"id":42651625}],"con":true,"img":false}]}
{"op":"mcm","clk":"5347915324","pt":1646210348958,"mc":[{"id":"1.195453612","rc":[{"atb":[[7.6,8.03]],"id":42651625}],"con":true,"img":false}]}
{"op":"mcm","clk":"5347915327","pt":1646210349057,"mc":[{"id":"1.195453612","rc":[{"atb":[[1.42,33.69]],"id":43167173}],"con":true,"img":false}]}
{"op":"mcm","clk":"5347915368","pt":1646210350088,"mc":[{"id":"1.195453612","rc":[{"atl":[[230,1]],"id":42651625},{"atb":[[2.96,63.78]],"id":41676292},{"atl":[[10,36.39]],"id":41676292},{"atl":[[9.6,14.53]],"id":43167172},{"atl":[[4.9,32.05]],"id":43167173}],"con":true,"img":false}]}
{"op":"mcm","clk":"5347915399","pt":1646210350864,"mc":[{"id":"1.195453612","rc":[{"atb":[[1.57,41.45]],"id":43066529},{"atb":[[1.4,20.09]],"id":43167172}],"con":true,"img":false}]}
{"op":"mcm","clk":"5347915415","pt":1646210351173,"mc":[{"id":"1.195453612","rc":[{"atb":[[1.42,37.8]],"id":43167172}],"con":true,"img":false}]}
{"op":"mcm","clk":"5347915437","pt":1646210351790,"mc":[{"id":"1.195453612","rc":[{"atb":[[1.41,0]],"id":43167173}],"con":true,"img":false}]}
{"op":"mcm","clk":"5347915450","pt":1646210352106,"mc":[{"id":"1.195453612","rc":[{"atb":[[1.6,50.22]],"id":43066529}],"con":true,"img":false}]}
{"op":"mcm","clk":"5347915516","pt":1646210354264,"mc":[{"id":"1.195453612","rc":[{"spn":10.8,"spf":"NaN","id":41762566},{"atl":[[2.96,63.78]],"id":43066529},{"spn":14.8,"spf":"NaN","id":42651625},{"spn":6.2,"spf":"NaN","id":41676292},{"spn":1.97,"spf":"NaN","id":43167172},{"spn":2.02,"spf":"NaN","id":43167173}],"con":true,"img":false}]}
{"op":"mcm","clk":"5347915611","pt":1646210357774,"mc":[{"id":"1.195453612","rc":[{"atl":[[40,0],[21,4],[24,11.47]],"id":42651625},{"atb":[[3.7,35.96],[3.8,14.62],[3.65,37.72]],"id":41676292},{"atl":[[9.2,35.72],[10,13.89]],"id":41676292},{"atl":[[2.72,107.23],[2.74,41.78]],"id":43167172},{"atb":[[1.39,0],[1.4,40.33]],"id":43167173},{"atl":[[2.8,40.39],[2.62,40.33]],"id":43167173}],"con":true,"img":false}]}
{"op":"mcm","clk":"5347915618","pt":1646210357981,"mc":[{"id":"1.195453612","rc":[{"atl":[[23,0]],"id":42651625},{"atb":[[3.75,5.77]],"id":41676292}],"con":true,"img":false}]}
{"op":"mcm","clk":"5347915634","pt":1646210358293,"mc":[{"id":"1.195453612","rc":[{"atb":[[5.6,9.48]],"id":41762566}],"con":true,"img":false}]}
{"op":"mcm","clk":"5347915640","pt":1646210358386,"mc":[{"id":"1.195453612","rc":[{"atb":[[5.5,0],[5.3,27.91]],"id":41762566}],"con":true,"img":false}]}
{"op":"mcm","clk":"5347915646","pt":1646210358498,"mc":[{"id":"1.195453612","rc":[{"atb":[[5.1,12.2],[5.3,22.75],[5.5,18.96]],"id":41762566}],"con":true,"img":false}]}
{"op":"mcm","clk":"5347915744","pt":1646210360871,"mc":[{"id":"1.195453612","rc":[{"atb":[[1.56,0],[1.57,153.35]],"id":43066529}],"con":true,"img":false}]}
{"op":"mcm","clk":"5347915755","pt":1646210361085,"mc":[{"id":"1.195453612","rc":[{"atl":[[12,0]],"id":41676292}],"con":true,"img":false}]}
{"op":"mcm","clk":"5347915763","pt":1646210361175,"mc":[{"id":"1.195453612","rc":[{"atb":[[3.75,3.04]],"id":41676292},{"atl":[[9,4.85]],"id":41676292},{"atb":[[1.42,15.78]],"id":43167173}],"con":true,"img":false}]}
{"op":"mcm","clk":"5347915769","pt":1646210361286,"mc":[{"id":"1.195453612","rc":[{"atl":[[9.2,27],[8.8,10.52]],"id":41676292}],"con":true,"img":false}]}
{"op":"mcm","clk":"5347915779","pt":1646210361492,"mc":[{"id":"1.195453612","rc":[{"atb":[[1.42,0]],"id":43167173}],"con":true,"img":false}]}
{"op":"mcm","clk":"5347915783","pt":1646210361596,"mc":[{"id":"1.195453612","rc":[{"atl":[[46,0]],"id":42651625}],"con":true,"img":false}]}
{"op":"mcm","clk":"5347915788","pt":1646210361690,"mc":[{"id":"1.195453612","rc":[{"atl":[[32,2.72]],"id":42651625}],"con":true,"img":false}]}
{"op":"mcm","clk":"5347915804","pt":1646210362101,"mc":[{"id":"1.195453612","rc":[{"atb":[[1.51,166.94]],"id":43066529},{"atl":[[36,0]],"id":42651625}],"con":true,"img":false}]}
{"op":"mcm","clk":"5347915808","pt":1646210362204,"mc":[{"id":"1.195453612","rc":[{"atb":[[1.49,0]],"id":43066529},{"atl":[[23,2.72]],"id":42651625}],"con":true,"img":false}]}
{"op":"mcm","clk":"5347915839","pt":1646210363181,"mc":[{"id":"1.195453612","rc":[{"atl":[[2.72,78.51]],"id":43167172}],"con":true,"img":false}]}
{"op":"mcm","clk":"5347915841","pt":1646210363283,"mc":[{"id":"1.195453612","rc":[{"atl":[[2.5,28.72]],"id":43167172}],"con":true,"img":false}]}
{"op":"mcm","clk":"5347915845","pt":1646210363387,"mc":[{"id":"1.195453612","rc":[{"atl":[[2.48,39.26]],"id":43167172}],"con":true,"img":false}]}
{"op":"mcm","clk":"5347915852","pt":1646210363593,"mc":[{"id":"1.195453612","rc":[{"atl":[[2.52,0]],"id":43167172}],"con":true,"img":false}]}
{"op":"mcm","clk":"5347915867","pt":1646210364110,"mc":[{"id":"1.195453612","rc":[{"atb":[[1.6,37.68]],"id":43066529}],"con":true,"img":false}]}
{"op":"mcm","clk":"5347915898","pt":1646210365091,"mc":[{"id":"1.195453612","rc":[{"atl":[[2.84,10.87]],"id":43066529}],"con":true,"img":false}]}
{"op":"mcm","clk":"5347915903","pt":1646210365194,"mc":[{"id":"1.195453612","rc":[{"atl":[[2.76,22.28]],"id":43066529}],"con":true,"img":false}]}
{"op":"mcm","clk":"5347915908","pt":1646210365297,"mc":[{"id":"1.195453612","rc":[{"atl":[[2.76,57.08]],"id":43066529}],"con":true,"img":false}]}
{"op":"mcm","clk":"5347915916","pt":1646210365504,"mc":[{"id":"1.195453612","rc":[{"atl":[[2.78,20.42]],"id":43066529}],"con":true,"img":false}]}
{"op":"mcm","clk":"5347915921","pt":1646210365607,"mc":[{"id":"1.195453612","rc":[{"atb":[[1.55,2.5]],"id":43066529}],"con":true,"img":false}]}
{"op":"mcm","clk":"5347915924","pt":1646210365709,"mc":[{"id":"1.195453612","rc":[{"atb":[[1.58,85.62]],"id":43066529}],"con":true,"img":false}]}
{"op":"mcm","clk":"5347915929","pt":1646210365814,"mc":[{"id":"1.195453612","rc":[{"atb":[[1.37,46.75]],"id":43167173}],"con":true,"img":false}]}
{"op":"mcm","clk":"5347915935","pt":1646210366019,"mc":[{"id":"1.195453612","rc":[{"atb":[[1.4,2.5],[1.37,155.73]],"id":43167173}],"con":true,"img":false}]}
{"op":"mcm","clk":"5347915982","pt":1646210367099,"mc":[{"id":"1.195453612","rc":[{"atb":[[3.8,17.3]],"id":41676292}],"con":true,"img":false}]}
{"op":"mcm","clk":"5347916008","pt":1646210368026,"mc":[{"id":"1.195453612","rc":[{"atb":[[1.57,111.9]],"id":43066529}],"con":true,"img":false}]}
{"op":"mcm","clk":"5347916086","pt":1646210370498,"mc":[{"id":"1.195453612","rc":[{"atb":[[1.61,26.37]],"id":43066529}],"con":true,"img":false}]}
{"op":"mcm","clk":"5347916091","pt":1646210370601,"mc":[{"id":"1.195453612","rc":[{"atb":[[1.61,61.48]],"id":43066529}],"con":true,"img":false}]}
{"op":"mcm","clk":"5347916100","pt":1646210370808,"mc":[{"id":"1.195453612","rc":[{"atb":[[1.6,2.17]],"id":43066529}],"con":true,"img":false}]}
{"op":"mcm","clk":"5347916121","pt":1646210371585,"mc":[{"id":"1.195453612","rc":[{"atb":[[1.64,2.17],[1.6,0]],"id":43066529}],"con":true,"img":false}]}
{"op":"mcm","clk":"5347916175","pt":1646210373086,"mc":[{"id":"1.195453612","rc":[{"atb":[[1.4,21.31]],"id":43167173}],"con":true,"img":false}]}
{"op":"mcm","clk":"5347916206","pt":1646210374007,"mc":[{"id":"1.195453612","rc":[{"atb":[[1.59,0]],"id":43066529},{"atb":[[3.75,0]],"id":41676292}],"con":true,"img":false}]}
{"op":"mcm","clk":"5347916211","pt":1646210374110,"mc":[{"id":"1.195453612","rc":[{"atb":[[3.7,15.06],[3.65,79.46]],"id":41676292}],"con":true,"img":false}]}
{"op":"mcm","clk":"5347916246","pt":1646210375014,"mc":[{"id":"1.195453612","rc":[{"atl":[[23,13.58]],"id":42651625},{"atl":[[9,32.61],[9.2,6.1]],"id":41676292},{"atl":[[2.72,0],[2.54,102.11]],"id":43167172}],"con":true,"img":false}]}
{"op":"mcm","clk":"5347916248","pt":1646210375091,"mc":[{"id":"1.195453612","rc":[{"atl":[[24,1.58]],"id":42651625},{"atl":[[9,45.11],[8.8,2.56]],"id":41676292}],"con":true,"img":false}]}
{"op":"mcm","clk":"5347916276","pt":1646210376219,"mc":[{"id":"1.195453612","rc":[{"atb":[[3.8,14.62]],"id":41676292}],"con":true,"img":false}]}
{"op":"mcm","clk":"5347916283","pt":1646210376425,"mc":[{"id":"1.195453612","rc":[{"atb":[[1.61,35.11]],"id":43066529}],"con":true,"img":false}]}
{"op":"mcm","clk":"5347916324","pt":1646210378034,"mc":[{"id":"1.195453612","rc":[{"atb":[[1.58,168.93],[1.57,0]],"id":43066529}],"con":true,"img":false}]}
{"op":"mcm","clk":"5347916372","pt":1646210379624,"mc":[{"id":"1.195453612","rc":[{"atl":[[2.78,10]],"id":43167173}],"con":true,"img":false}]}
{"op":"mcm","clk":"5347916377","pt":1646210379727,"mc":[{"id":"1.195453612","rc":[{"atl":[[2.6,47.25]],"id":43167173}],"con":true,"img":false}]}
{"op":"mcm","clk":"5347916410","pt":1646210380503,"mc":[{"id":"1.195453612","rc":[{"atl":[[2.72,33.4]],"id":43167172}],"con":true,"img":false}]}
{"op":"mcm","clk":"5347916414","pt":1646210380606,"mc":[{"id":"1.195453612","rc":[{"atl":[[2.92,0]],"id":43167172},{"atl":[[2.98,0]],"id":43167173}],"con":true,"img":false}]}
{"op":"mcm","clk":"5347916420","pt":1646210380709,"mc":[{"id":"1.195453612","rc":[{"atl":[[2.78,43.27]],"id":43167173}],"con":true,"img":false}]}
{"op":"mcm","clk":"5347916429","pt":1646210380813,"mc":[{"id":"1.195453612","rc":[{"atb":[[1.56,48.46]],"id":43066529}],"con":true,"img":false}]}
{"op":"mcm","clk":"5347916453","pt":1646210381432,"mc":[{"id":"1.195453612","rc":[{"atb":[[1.56,84.17],[1.54,0]],"id":43066529},{"atl":[[8.2,2.78],[8.8,0]],"id":41676292}],"con":true,"img":false}]}
{"op":"mcm","clk":"5347916461","pt":1646210381535,"mc":[{"id":"1.195453612","rc":[{"atl":[[8.4,10.81]],"id":41676292}],"con":true,"img":false}]}
{"op":"mcm","clk":"5347916471","pt":1646210381742,"mc":[{"id":"1.195453612","rc":[{"atl":[[8.6,0]],"id":41676292}],"con":true,"img":false}]}
{"op":"mcm","clk":"5347916492","pt":1646210382103,"mc":[{"id":"1.195453612","rc":[{"atb":[[3.75,2.73]],"id":41676292}],"con":true,"img":false}]}
{"op":"mcm","clk":"5347916498","pt":1646210382204,"mc":[{"id":"1.195453612","rc":[{"atb":[[3.7,53.2]],"id":41676292}],"con":true,"img":false}]}
{"op":"mcm","clk":"5347916502","pt":1646210382307,"mc":[{"id":"1.195453612","rc":[{"atb":[[3.65,37.72]],"id":41676292}],"con":true,"img":false}]}
{"op":"mcm","clk":"5347916553","pt":1646210384112,"mc":[{"id":"1.195453612","rc":[{"atl":[[2.5,0]],"id":43167172}],"con":true,"img":false}]}
{"op":"mcm","clk":"5347916557","pt":1646210384216,"mc":[{"id":"1.195453612","rc":[{"atl":[[2.72,127.7],[2.54,23.6],[2.46,28.72],[2.48,0]],"id":43167172}],"con":true,"img":false}]}
{"op":"mcm","clk":"5347916561","pt":1646210384319,"mc":[{"id":"1.195453612","rc":[{"atl":[[2.52,52.63]],"id":43167172}],"con":true,"img":false}]}
{"op":"mcm","clk":"5347916574","pt":1646210384834,"mc":[{"id":"1.195453612","rc":[{"atb":[[1.4,42.19]],"id":43167173}],"con":true,"img":false}]}
{"op":"mcm","clk":"5347916577","pt":1646210384937,"mc":[{"id":"1.195453612","rc":[{"atb":[[3.8,17.6]],"id":41676292}],"con":true,"img":false}]}
{"op":"mcm","clk":"5347916580","pt":1646210385159,"mc":[{"id":"1.195453612","rc":[{"atl":[[17.5,3.03]],"id":41762566},{"atb":[[1.62,12.13]],"id":43066529},{"atb":[[3.75,0]],"id":41676292}],"con":true,"img":false}]}
{"op":"mcm","clk":"5347916585","pt":1646210385207,"mc":[{"id":"1.195453612","rc":[{"atl":[[15.5,2.72]],"id":41762566}],"con":true,"img":false}]}
{"op":"mcm","clk":"5347916587","pt":1646210385307,"mc":[{"id":"1.195453612","rc":[{"atl":[[15.5,7.24]],"id":41762566}],"con":true,"img":false}]}
{"op":"mcm","clk":"5347916592","pt":1646210385512,"mc":[{"id":"1.195453612","rc":[{"atl":[[16,1.32]],"id":41762566}],"con":true,"img":false}]}
{"op":"mcm","clk":"5347916598","pt":1646210385720,"mc":[{"id":"1.195453612","rc":[{"atl":[[2.76,34.8]],"id":43066529}],"con":true,"img":false}]}
{"op":"mcm","clk":"5347916602","pt":1646210385823,"mc":[{"id":"1.195453612","rc":[{"atl":[[2.74,22.28]],"id":43066529}],"con":true,"img":false}]}
{"op":"mcm","clk":"5347916607","pt":1646210385927,"mc":[{"id":"1.195453612","rc":[{"atl":[[2.74,54.31]],"id":43066529}],"con":true,"img":false}]}
{"op":"mcm","clk":"5347916618","pt":1646210386134,"mc":[{"id":"1.195453612","rc":[{"atl":[[2.76,0]],"id":43066529}],"con":true,"img":false}]}
{"op":"mcm","clk":"5347916647","pt":1646210387114,"mc":[{"id":"1.195453612","rc":[{"atb":[[1.36,0]],"id":43167173}],"con":true,"img":false}]}
{"op":"mcm","clk":"5347916649","pt":1646210387217,"mc":[{"id":"1.195453612","rc":[{"atb":[[1.38,83.04]],"id":43167173}],"con":true,"img":false}]}
{"op":"mcm","clk":"5347916655","pt":1646210387424,"mc":[{"id":"1.195453612","rc":[{"atb":[[1.37,46.75],[1.38,206.82]],"id":43167173}],"con":true,"img":false}]}
{"op":"mcm","clk":"5347916659","pt":1646210387526,"mc":[{"id":"1.195453612","rc":[{"atb":[[1.64,26.6]],"id":43066529}],"con":true,"img":false}]}
{"op":"mcm","clk":"5347916666","pt":1646210387733,"mc":[{"id":"1.195453612","rc":[{"atb":[[1.61,0]],"id":43066529}],"con":true,"img":false}]}
{"op":"mcm","clk":"5347916686","pt":1646210388198,"mc":[{"id":"1.195453612","rc":[{"atb":[[1.4,23.38]],"id":43167173}],"con":true,"img":false}]}
{"op":"mcm","clk":"5347916709","pt":1646210388916,"mc":[{"id":"1.195453612","rc":[{"atb":[[1.56,35.71]],"id":43066529}],"con":true,"img":false}]}
{"op":"mcm","clk":"5347916738","pt":1646210390107,"mc":[{"id":"1.195453612","rc":[{"atb":[[3.7,15.06],[3.65,109.14]],"id":41676292}],"con":true,"img":false}]}
{"op":"mcm","clk":"5347916791","pt":1646210391340,"mc":[{"id":"1.195453612","rc":[{"atb":[[1.37,0]],"id":43167173}],"con":true,"img":false}]}
{"op":"mcm","clk":"5347916793","pt":1646210391450,"mc":[{"id":"1.195453612","rc":[{"atb":[[1.54,92.59]],"id":43066529},{"atl":[[8.6,6.58]],"id":41676292}],"con":true,"img":false}]}
{"op":"mcm","clk":"5347916798","pt":1646210391548,"mc":[{"id":"1.195453612","rc":[{"atl":[[8.6,19.74],[9,32.61]],"id":41676292}],"con":true,"img":false}]}
{"op":"mcm","clk":"5347916808","pt":1646210391808,"mc":[{"id":"1.195453612","rc":[{"atl":[[8.6,50.19],[9,4.85]],"id":41676292},{"atl":[[2.54,102.11]],"id":43167172}],"con":true,"img":false}]}
{"op":"mcm","clk":"5347916812","pt":1646210391913,"mc":[{"id":"1.195453612","rc":[{"atl":[[2.72,33.4]],"id":43167172}],"con":true,"img":false}]}
{"op":"mcm","clk":"5347916816","pt":1646210392115,"mc":[{"id":"1.195453612","rc":[{"atl":[[2.46,0]],"id":43167172}],"con":true,"img":false}]}
{"op":"mcm","clk":"5347916817","pt":1646210392218,"mc":[{"id":"1.195453612","rc":[{"atl":[[2.72,129.8],[2.54,23.6],[2.5,28.72]],"id":43167172}],"con":true,"img":false}]}
{"op":"mcm","clk":"5347916843","pt":1646210393513,"mc":[{"id":"1.195453612","rc":[{"atb":[[1.59,34.58]],"id":43066529}],"con":true,"img":false}]}
{"op":"mcm","clk":"5347916848","pt":1646210393719,"mc":[{"id":"1.195453612","rc":[{"atl":[[15.5,4.52]],"id":41762566}],"con":true,"img":false}]}
{"op":"mcm","clk":"5347916851","pt":1646210393820,"mc":[{"id":"1.195453612","rc":[{"atl":[[18,6.12]],"id":41762566}],"con":true,"img":false}]}
{"op":"mcm","clk":"5347916857","pt":1646210394023,"mc":[{"id":"1.195453612","rc":[{"atl":[[9.6,0],[9.2,0],[10,0]],"id":41676292}],"con":true,"img":false}]}
{"op":"mcm","clk":"5347916860","pt":1646210394134,"mc":[{"id":"1.195453612","rc":[{"atb":[[5.5,0],[5.4,22.73]],"id":41762566},{"atb":[[1.51,127.72]],"id":43066529}],"con":true,"img":false}]}
{"op":"mcm","clk":"5347916865","pt":1646210394230,"mc":[{"id":"1.195453612","rc":[{"atb":[[1.41,18.35]],"id":43167173}],"con":true,"img":false}]}
{"op":"mcm","clk":"5347916879","pt":1646210394846,"mc":[{"id":"1.195453612","rc":[{"atb":[[1.59,105.12]],"id":43066529}],"con":true,"img":false}]}
{"op":"mcm","clk":"5347916881","pt":1646210394949,"mc":[{"id":"1.195453612","rc":[{"atb":[[1.58,85.62]],"id":43066529}],"con":true,"img":false}]}
{"op":"mcm","clk":"5347916895","pt":1646210395520,"mc":[{"id":"1.195453612","rc":[{"atb":[[1.62,25.61]],"id":43066529}],"con":true,"img":false}]}
{"op":"mcm","clk":"5347916910","pt":1646210395825,"mc":[{"id":"1.195453612","rc":[{"atb":[[1.36,30.65]],"id":43167173}],"con":true,"img":false}]}
{"op":"mcm","clk":"5347916957","pt":1646210397223,"mc":[{"id":"1.195453612","rc":[{"atb":[[1.62,13.47]],"id":43066529},{"atb":[[3.75,2.73]],"id":41676292}],"con":true,"img":false}]}
{"op":"mcm","clk":"5347916962","pt":1646210397326,"mc":[{"id":"1.195453612","rc":[{"atb":[[3.7,53.86]],"id":41676292}],"con":true,"img":false}]}
{"op":"mcm","clk":"5347916967","pt":1646210397430,"mc":[{"id":"1.195453612","rc":[{"atb":[[3.65,37.72]],"id":41676292}],"con":true,"img":false}]}
{"op":"mcm","clk":"5347916993","pt":1646210398216,"mc":[{"id":"1.195453612","rc":[{"atl":[[8,11.43]],"id":41676292}],"con":true,"img":false}]}
{"op":"mcm","clk":"5347917000","pt":1646210398420,"mc":[{"id":"1.195453612","rc":[{"atl":[[8.4,0]],"id":41676292}],"con":true,"img":false}]}
{"op":"mcm","clk":"5347917042","pt":1646210399814,"mc":[{"id":"1.195453612","rc":[{"atb":[[1.36,0]],"id":43167173}],"con":true,"img":false}]}
{"op":"mcm","clk":"5347917065","pt":1646210400843,"mc":[{"id":"1.195453612","rc":[{"atl":[[2.72,33.4],[2.54,102.11]],"id":43167172}],"con":true,"img":false}]}
{"op":"mcm","clk":"5347917069","pt":1646210400946,"mc":[{"id":"1.195453612","rc":[{"atl":[[2.48,39.26]],"id":43167172}],"con":true,"img":false}]}
{"op":"mcm","clk":"5347917075","pt":1646210401155,"mc":[{"id":"1.195453612","rc":[{"atl":[[2.52,0]],"id":43167172}],"con":true,"img":false}]}
{"op":"mcm","clk":"5347917080","pt":1646210401215,"mc":[{"id":"1.195453612","rc":[{"atb":[[3.75,0]],"id":41676292}],"con":true,"img":false}]}
{"op":"mcm","clk":"5347917085","pt":1646210401312,"mc":[{"id":"1.195453612","rc":[{"atb":[[3.7,15.06],[3.65,111.34]],"id":41676292}],"con":true,"img":false}]}
{"op":"mcm","clk":"5347917089","pt":1646210401418,"mc":[{"id":"1.195453612","rc":[{"atb":[[1.52,144.23]],"id":43066529},{"atl":[[9,14.23]],"id":41676292}],"con":true,"img":false}]}
{"op":"mcm","clk":"5347917118","pt":1646210402138,"mc":[{"id":"1.195453612","rc":[{"atl":[[2.74,32.03]],"id":43066529}],"con":true,"img":false}]}
{"op":"mcm","clk":"5347917121","pt":1646210402241,"mc":[{"id":"1.195453612","rc":[{"atl":[[2.9,22.28]],"id":43066529}],"con":true,"img":false}]}
{"op":"mcm","clk":"5347917123","pt":1646210402346,"mc":[{"id":"1.195453612","rc":[{"atl":[[2.74,0]],"id":43066529}],"con":true,"img":false}]}
{"op":"mcm","clk":"5347917128","pt":1646210402450,"mc":[{"id":"1.195453612","rc":[{"atl":[[2.78,55.69]],"id":43066529}],"con":true,"img":false}]}
{"op":"mcm","clk":"5347917172","pt":1646210403125,"mc":[{"id":"1.195453612","rc":[{"atb":[[1.63,11.94]],"id":43066529}],"con":true,"img":false}]}
{"op":"mcm","clk":"5347917218","pt":1646210404055,"mc":[{"id":"1.195453612","rc":[{"atb":[[1.4,106.93]],"id":43167173}],"con":true,"img":false}]}
{"op":"mcm","clk":"5347917222","pt":1646210404159,"mc":[{"id":"1.195453612","rc":[{"atb":[[1.38,83.04]],"id":43167173}],"con":true,"img":false}]}
{"op":"mcm","clk":"5347917239","pt":1646210404421,"mc":[{"id":"1.195453612","rc":[{"atb":[[1.48,0]],"id":43066529}],"con":true,"img":false}]}
{"op":"mcm","clk":"5347917242","pt":1646210404525,"mc":[{"id":"1.195453612","rc":[{"atb":[[1.42,14.37]],"id":43167173}],"con":true,"img":false}]}
{"op":"mcm","clk":"5347917310","pt":1646210406139,"mc":[{"id":"1.195453612","rc":[{"atb":[[1.41,0]],"id":43167173}],"con":true,"img":false}]}
{"op":"mcm","clk":"5347917326","pt":1646210406539,"mc":[{"id":"1.195453612","rc":[{"atb":[[1.59,70.54]],"id":43066529}],"con":true,"img":false}]}
{"op":"mcm","clk":"5347917333","pt":1646210406643,"mc":[{"id":"1.195453612","rc":[{"atb":[[3.8,14.62]],"id":41676292},{"atb":[[1.4,86.05]],"id":43167173}],"con":true,"img":false}]}
{"op":"mcm","clk":"5347917367","pt":1646210407319,"mc":[{"id":"1.195453612","rc":[{"atl":[[9.4,0]],"id":41676292}],"con":true,"img":false}]}
{"op":"mcm","clk":"5347917427","pt":1646210409123,"mc":[{"id":"1.195453612","rc":[{"atb":[[3.75,2.73]],"id":41676292}],"con":true,"img":false}]}
{"op":"mcm","clk":"5347917431","pt":1646210409227,"mc":[{"id":"1.195453612","rc":[{"atb":[[3.7,54.13],[3.65,37.72]],"id":41676292}],"con":true,"img":false}]}
{"op":"mcm","clk":"5347917440","pt":1646210409659,"mc":[{"id":"1.195453612","rc":[{"atb":[[1.38,0]],"id":43167173}],"con":true,"img":false}]}
{"op":"mcm","clk":"5347917443","pt":1646210409763,"mc":[{"id":"1.195453612","rc":[{"atb":[[1.36,83.04]],"id":43167173}],"con":true,"img":false}]}
{"op":"mcm","clk":"5347917487","pt":1646210411265,"mc":[{"id":"1.195453612","rc":[{"atb":[[1.59,0],[1.62,73.57],[1.65,18.62]],"id":43066529}],"con":true,"img":false}]}
{"op":"mcm","clk":"5347917494","pt":1646210411424,"mc":[{"id":"1.195453612","rc":[{"atb":[[1.5,449.94],[1.65,52.54]],"id":43066529},{"atl":[[9.4,14.88]],"id":41676292}],"con":true,"img":false}]}
{"op":"mcm","clk":"5347917499","pt":1646210411630,"mc":[{"id":"1.195453612","rc":[{"atb":[[1.64,2.17]],"id":43066529}],"con":true,"img":false}]}
{"op":"mcm","clk":"5347917509","pt":1646210411840,"mc":[{"id":"1.195453612","rc":[{"atb":[[1.64,0],[1.68,2.17]],"id":43066529}],"con":true,"img":false}]}
{"op":"mcm","clk":"5347917516","pt":1646210412142,"mc":[{"id":"1.195453612","rc":[{"atb":[[1.63,0]],"id":43066529},{"atb":[[3.75,0]],"id":41676292},{"atb":[[1.43,17.5]],"id":43167173}],"con":true,"img":false}]}
{"op":"mcm","clk":"5347917546","pt":1646210413125,"mc":[{"id":"1.195453612","rc":[{"atb":[[1.42,0]],"id":43167173}],"con":true,"img":false}]}
{"op":"mcm","clk":"5347917565","pt":1646210413639,"mc":[{"id":"1.195453612","rc":[{"atl":[[9,9.38]],"id":41676292}],"con":true,"img":false}]}
{"op":"mcm","clk":"5347917568","pt":1646210413742,"mc":[{"id":"1.195453612","rc":[{"atl":[[8.4,4.85]],"id":41676292}],"con":true,"img":false}]}
{"op":"mcm","clk":"5347917570","pt":1646210413846,"mc":[{"id":"1.195453612","rc":[{"atl":[[8.6,6.58],[8.2,16.67],[8.4,37.9]],"id":41676292}],"con":true,"img":false}]}
{"op":"mcm","clk":"5347917628","pt":1646210416072,"mc":[{"id":"1.195453612","rc":[{"spn":10.55,"spf":"NaN","id":41762566},{"atb":[[1.58,0]],"id":43066529},{"spn":2.23,"spf":"NaN","id":43066529},{"spn":14.3,"spf":"NaN","id":42651625},{"spn":5.9,"spf":"NaN","id":41676292},{"spn":1.95,"spf":"NaN","id":43167172}],"con":true,"img":false}]}
{"op":"mcm","clk":"5347917635","pt":1646210416127,"mc":[{"id":"1.195453612","rc":[{"atb":[[1.66,85.62]],"id":43066529}],"con":true,"img":false}]}
{"op":"mcm","clk":"5347917663","pt":1646210416852,"mc":[{"id":"1.195453612","rc":[{"atb":[[5.5,22.22],[5.4,0]],"id":41762566},{"atb":[[3.7,15.06],[3.65,114.38]],"id":41676292}],"con":true,"img":false}]}
{"op":"mcm","clk":"5347917685","pt":1646210417371,"mc":[{"id":"1.195453612","rc":[{"atb":[[1.37,27.55]],"id":43167173}],"con":true,"img":false}]}
{"op":"mcm","clk":"5347917730","pt":1646210419438,"mc":[{"id":"1.195453612","rc":[{"atb":[[1.65,33.92]],"id":43066529}],"con":true,"img":false}]}
{"op":"mcm","clk":"5347917793","pt":1646210422168,"mc":[{"id":"1.195453612","rc":[{"atl":[[2.5,0]],"id":43167172}],"con":true,"img":false}]}
{"op":"mcm","clk":"5347917795","pt":1646210422271,"mc":[{"id":"1.195453612","rc":[{"atl":[[2.46,28.72]],"id":43167172}],"con":true,"img":false}]}
{"op":"mcm","clk":"5347917797","pt":1646210422374,"mc":[{"id":"1.195453612","rc":[{"atl":[[2.72,137.69],[2.54,23.6],[2.48,0]],"id":43167172}],"con":true,"img":false}]}
{"op":"mcm","clk":"5347917801","pt":1646210422478,"mc":[{"id":"1.195453612","rc":[{"atl":[[2.44,49.9]],"id":43167172}],"con":true,"img":false}]}
{"op":"mcm","clk":"5347917834","pt":1646210423873,"mc":[{"id":"1.195453612","rc":[{"atb":[[1.63,56.44]],"id":43066529}],"con":true,"img":false}]}
{"op":"mcm","clk":"5347917839","pt":1646210423977,"mc":[{"id":"1.195453612","rc":[{"atb":[[1.43,36.93]],"id":43167173}],"con":true,"img":false}]}
{"op":"mcm","clk":"5347917846","pt":1646210424139,"mc":[{"id":"1.195453612","rc":[{"atb":[[1.7,10.75]],"id":43066529}],"con":true,"img":false}]}
{"op":"mcm","clk":"5347917854","pt":1646210424243,"mc":[{"id":"1.195453612","rc":[{"atb":[[3.75,2.73]],"id":41676292}],"con":true,"img":false}]}
{"op":"mcm","clk":"5347917858","pt":1646210424343,"mc":[{"id":"1.195453612","rc":[{"atb":[[1.62,60.1]],"id":43066529},{"atb":[[3.7,59.58],[3.65,37.72]],"id":41676292}],"con":true,"img":false}]}
{"op":"mcm","clk":"5347917869","pt":1646210424646,"mc":[{"id":"1.195453612","rc":[{"atb":[[1.73,2.17],[1.68,0]],"id":43066529},{"atl":[[2.9,0]],"id":43066529}],"con":true,"img":false}]}
{"op":"mcm","clk":"5347917871","pt":1646210424755,"mc":[{"id":"1.195453612","rc":[{"atl":[[2.76,22.28]],"id":43066529}],"con":true,"img":false}]}
{"op":"mcm","clk":"5347917873","pt":1646210424851,"mc":[{"id":"1.195453612","rc":[{"atl":[[2.76,47.14]],"id":43066529}],"con":true,"img":false}]}
{"op":"mcm","clk":"5347917879","pt":1646210425058,"mc":[{"id":"1.195453612","rc":[{"atl":[[2.78,20.42]],"id":43066529}],"con":true,"img":false}]}
{"op":"mcm","clk":"5347917948","pt":1646210427273,"mc":[{"id":"1.195453612","rc":[{"atb":[[3.75,0]],"id":41676292}],"con":true,"img":false}]}
{"op":"mcm","clk":"5347917955","pt":1646210427376,"mc":[{"id":"1.195453612","rc":[{"atb":[[1.62,0]],"id":43066529}],"con":true,"img":false}]}
{"op":"mcm","clk":"5347917960","pt":1646210427482,"mc":[{"id":"1.195453612","rc":[{"atb":[[1.66,132.57]],"id":43066529}],"con":true,"img":false}]}
{"op":"mcm","clk":"5347917965","pt":1646210427539,"mc":[{"id":"1.195453612","rc":[{"atb":[[1.73,25.65]],"id":43066529}],"con":true,"img":false}]}
{"op":"mcm","clk":"5347917978","pt":1646210427744,"mc":[{"id":"1.195453612","rc":[{"atb":[[1.65,0]],"id":43066529}],"con":true,"img":false}]}
{"op":"mcm","clk":"5347917983","pt":1646210427846,"mc":[{"id":"1.195453612","rc":[{"atb":[[1.63,0]],"id":43066529}],"con":true,"img":false}]}
{"op":"mcm","clk":"5347918051","pt":1646210430063,"mc":[{"id":"1.195453612","rc":[{"atb":[[7.4,0]],"id":42651625}],"con":true,"img":false}]}
{"op":"mcm","clk":"5347918059","pt":1646210430166,"mc":[{"id":"1.195453612","rc":[{"atb":[[7.2,8.06],[6.8,47.86],[7.8,5.6]],"id":42651625}],"con":true,"img":false}]}
{"op":"mcm","clk":"5347918063","pt":1646210430268,"mc":[{"id":"1.195453612","rc":[{"atb":[[7.8,15.82]],"id":42651625}],"con":true,"img":false}]}
{"op":"mcm","clk":"5347918066","pt":1646210430474,"mc":[{"id":"1.195453612","rc":[{"atb":[[7.6,3.03]],"id":42651625}],"con":true,"img":false}]}
{"op":"mcm","clk":"5347918119","pt":1646210431866,"mc":[{"id":"1.195453612","rc":[{"atb":[[3.7,15.06],[3.65,117.31]],"id":41676292}],"con":true,"img":false}]}
{"op":"mcm","clk":"5347918141","pt":1646210432539,"mc":[{"id":"1.195453612","rc":[{"atb":[[1.67,35.91]],"id":43066529}],"con":true,"img":false}]}
{"op":"mcm","clk":"5347918166","pt":1646210433051,"mc":[{"id":"1.195453612","rc":[{"atl":[[2.76,24.86]],"id":43066529}],"con":true,"img":false}]}
{"op":"mcm","clk":"5347918175","pt":1646210433155,"mc":[{"id":"1.195453612","rc":[{"atl":[[2.9,22.28]],"id":43066529}],"con":true,"img":false}]}
{"op":"mcm","clk":"5347918281","pt":1646210435685,"mc":[{"id":"1.195453612","rc":[{"atl":[[8.4,33.05]],"id":41676292}],"con":true,"img":false}]}
{"op":"mcm","clk":"5347918287","pt":1646210435742,"mc":[{"id":"1.195453612","rc":[{"atl":[[8,16.28]],"id":41676292}],"con":true,"img":false}]}
{"op":"mcm","clk":"5347918291","pt":1646210435844,"mc":[{"id":"1.195453612","rc":[{"atl":[[8.2,2.78],[8.4,46.56]],"id":41676292}],"con":true,"img":false}]}
{"op":"mcm","clk":"5347918380","pt":1646210438269,"mc":[{"id":"1.195453612","rc":[{"atb":[[1.02,4]],"id":43066529},{"atl":[[2.72,33.4],[2.54,102.11]],"id":43167172},{"atl":[[2.6,49.75],[2.68,5]],"id":43167173}],"con":true,"img":false}]}
{"op":"mcm","clk":"5347918386","pt":1646210438374,"mc":[{"id":"1.195453612","rc":[{"atl":[[2.62,37.83],[2.78,33.27],[2.7,0]],"id":43167173}],"con":true,"img":false}]}
{"op":"mcm","clk":"5347918425","pt":1646210439155,"mc":[{"id":"1.195453612","rc":[{"atb":[[1.03,4]],"id":43066529},{"atb":[[3.75,2.73]],"id":41676292}],"con":true,"img":false}]}
{"op":"mcm","clk":"5347918431","pt":1646210439262,"mc":[{"id":"1.195453612","rc":[{"atb":[[3.7,59.58],[3.65,37.72]],"id":41676292}],"con":true,"img":false}]}
{"op":"mcm","clk":"5347918488","pt":1646210440760,"mc":[{"id":"1.195453612","rc":[{"atb":[[1.7,22.68]],"id":43066529}],"con":true,"img":false}]}
{"op":"mcm","clk":"5347918501","pt":1646210441067,"mc":[{"id":"1.195453612","rc":[{"atb":[[1.51,0]],"id":43066529}],"con":true,"img":false}]}
{"op":"mcm","clk":"5347918504","pt":1646210441169,"mc":[{"id":"1.195453612","rc":[{"atb":[[1.55,130.22]],"id":43066529}],"con":true,"img":false}]}
{"op":"mcm","clk":"5347918510","pt":1646210441273,"mc":[{"id":"1.195453612","rc":[{"atb":[[1.04,3]],"id":43066529}],"con":true,"img":false}]}
{"op":"mcm","clk":"5347918525","pt":1646210441686,"mc":[{"id":"1.195453612","rc":[{"atl":[[2.46,0]],"id":43167172}],"con":true,"img":false}]}
{"op":"mcm","clk":"5347918531","pt":1646210441792,"mc":[{"id":"1.195453612","rc":[{"atl":[[2.42,28.72]],"id":43167172}],"con":true,"img":false}]}
{"op":"mcm","clk":"5347918536","pt":1646210441897,"mc":[{"id":"1.195453612","rc":[{"atl":[[2.44,0]],"id":43167172}],"con":true,"img":false}]}
{"op":"mcm","clk":"5347918539","pt":1646210441956,"mc":[{"id":"1.195453612","rc":[{"atl":[[2.4,49.9]],"id":43167172}],"con":true,"img":false}]}
{"op":"mcm","clk":"5347918546","pt":1646210442077,"mc":[{"id":"1.195453612","rc":[{"atb":[[5.5,0],[5.4,22.73]],"id":41762566},{"atb":[[1.05,3]],"id":43066529}],"con":true,"img":false}]}
{"op":"mcm","clk":"5347918552","pt":1646210442267,"mc":[{"id":"1.195453612","rc":[{"atb":[[3.75,0]],"id":41676292}],"con":true,"img":false}]}
{"op":"mcm","clk":"5347918604","pt":1646210443297,"mc":[{"id":"1.195453612","rc":[{"atb":[[1.67,107.23]],"id":43066529},{"atl":[[8,30.57],[8.4,33.05]],"id":41676292}],"con":true,"img":false}]}
{"op":"mcm","clk":"5347918610","pt":1646210443356,"mc":[{"id":"1.195453612","rc":[{"atb":[[1.66,85.62]],"id":43066529}],"con":true,"img":false}]}
{"op":"mcm","clk":"5347918625","pt":1646210443666,"mc":[{"id":"1.195453612","rc":[{"atb":[[1.36,0]],"id":43167172}],"con":true,"img":false}]}
{"op":"mcm","clk":"5347918632","pt":1646210443769,"mc":[{"id":"1.195453612","rc":[{"atb":[[1.33,168.97]],"id":43167172}],"con":true,"img":false}]}
{"op":"mcm","clk":"5347918676","pt":1646210445364,"mc":[{"id":"1.195453612","rc":[{"atb":[[1.7,11.93]],"id":43066529}],"con":true,"img":false}]}
{"op":"mcm","clk":"5347918699","pt":1646210445874,"mc":[{"id":"1.195453612","rc":[{"atb":[[7.2,26.15],[6.8,15.43]],"id":42651625}],"con":true,"img":false}]}
{"op":"mcm","clk":"5347918724","pt":1646210446593,"mc":[{"id":"1.195453612","rc":[{"atb":[[3.7,15.06],[3.65,120.2]],"id":41676292}],"con":true,"img":false}]}
{"op":"mcm","clk":"5347918857","pt":1646210451272,"mc":[{"id":"1.195453612","rc":[{"atb":[[1.71,10.59]],"id":43066529}],"con":true,"img":false}]}
{"op":"mcm","clk":"5347918908","pt":1646210452668,"mc":[{"id":"1.195453612","rc":[{"atb":[[7.8,10.22]],"id":42651625}],"con":true,"img":false}]}
{"op":"mcm","clk":"5347918911","pt":1646210452770,"mc":[{"id":"1.195453612","rc":[{"atb":[[8,5.6]],"id":42651625}],"con":true,"img":false}]}
{"op":"mcm","clk":"5347918915","pt":1646210452875,"mc":[{"id":"1.195453612","rc":[{"atb":[[8,12.8]],"id":42651625}],"con":true,"img":false}]}
{"op":"mcm","clk":"5347918920","pt":1646210452972,"mc":[{"id":"1.195453612","rc":[{"atb":[[7.8,0]],"id":42651625}],"con":true,"img":false}]}
{"op":"mcm","clk":"5347918963","pt":1646210454371,"mc":[{"id":"1.195453612","rc":[{"atb":[[3.75,2.73]],"id":41676292}],"con":true,"img":false}]}
{"op":"mcm","clk":"5347918965","pt":1646210454466,"mc":[{"id":"1.195453612","rc":[{"atb":[[3.7,59.58]],"id":41676292}],"con":true,"img":false}]}
{"op":"mcm","clk":"5347918970","pt":1646210454577,"mc":[{"id":"1.195453612","rc":[{"atb":[[1.67,71.32]],"id":43066529},{"atb":[[3.65,37.72]],"id":41676292}],"con":true,"img":false}]}
{"op":"mcm","clk":"5347919006","pt":1646210455707,"mc":[{"id":"1.195453612","rc":[{"atl":[[8,25.72]],"id":41676292}],"con":true,"img":false}]}
{"op":"mcm","clk":"5347919009","pt":1646210455809,"mc":[{"id":"1.195453612","rc":[{"atl":[[7.8,4.85]],"id":41676292}],"con":true,"img":false}]}
{"op":"mcm","clk":"5347919013","pt":1646210455911,"mc":[{"id":"1.195453612","rc":[{"atl":[[8,11.43],[8.4,46.56]],"id":41676292}],"con":true,"img":false}]}
{"op":"mcm","clk":"5347919017","pt":1646210455969,"mc":[{"id":"1.195453612","rc":[{"atl":[[8.2,31.98],[7.6,12.12],[8.4,13.51]],"id":41676292}],"con":true,"img":false}]}
{"op":"mcm","clk":"5347919022","pt":1646210456069,"mc":[{"id":"1.195453612","rc":[{"atl":[[8,25.72],[8.4,0]],"id":41676292}],"con":true,"img":false}]}
{"op":"mcm","clk":"5347919031","pt":1646210456277,"mc":[{"id":"1.195453612","rc":[{"atl":[[8,14.29]],"id":41676292}],"con":true,"img":false}]}
{"op":"mcm","clk":"5347919041","pt":1646210456480,"mc":[{"id":"1.195453612","rc":[{"atb":[[1.55,127.72]],"id":43066529}],"con":true,"img":false}]}
{"op":"mcm","clk":"5347919080","pt":1646210457196,"mc":[{"id":"1.195453612","rc":[{"atb":[[3.75,0]],"id":41676292}],"con":true,"img":false}]}
{"op":"mcm","clk":"5347919151","pt":1646210458790,"mc":[{"id":"1.195453612","rc":[{"atb":[[1.7,60.48],[1.67,0],[1.74,17.95]],"id":43066529}],"con":true,"img":false}]}
{"op":"mcm","clk":"5347919156","pt":1646210458900,"mc":[{"id":"1.195453612","rc":[{"atb":[[1.74,46.74]],"id":43066529}],"con":true,"img":false}]}
{"op":"mcm","clk":"5347919166","pt":1646210459100,"mc":[{"id":"1.195453612","rc":[{"atb":[[1.73,2.17]],"id":43066529}],"con":true,"img":false}]}
{"op":"mcm","clk":"5347919171","pt":1646210459409,"mc":[{"id":"1.195453612","rc":[{"atb":[[1.73,0],[1.77,2.17]],"id":43066529}],"con":true,"img":false}]}
{"op":"mcm","clk":"5347919178","pt":1646210459723,"mc":[{"id":"1.195453612","rc":[{"atb":[[1.66,0]],"id":43066529}],"con":true,"img":false}]}
{"op":"mcm","clk":"5347919184","pt":1646210459774,"mc":[{"id":"1.195453612","rc":[{"atb":[[1.68,85.62]],"id":43066529}],"con":true,"img":false}]}
{"op":"mcm","clk":"5347919198","pt":1646210460388,"mc":[{"id":"1.195453612","rc":[{"atb":[[1.71,0]],"id":43066529}],"con":true,"img":false}]}
{"op":"mcm","clk":"5347919213","pt":1646210460696,"mc":[{"id":"1.195453612","rc":[{"atb":[[8,7.2]],"id":42651625}],"con":true,"img":false}]}
{"op":"mcm","clk":"5347919220","pt":1646210460805,"mc":[{"id":"1.195453612","rc":[{"atb":[[7.4,5.6]],"id":42651625}],"con":true,"img":false}]}
{"op":"mcm","clk":"5347919228","pt":1646210460903,"mc":[{"id":"1.195453612","rc":[{"atb":[[8,0]],"id":42651625}],"con":true,"img":false}]}
{"op":"mcm","clk":"5347919232","pt":1646210461012,"mc":[{"id":"1.195453612","rc":[{"atb":[[7.6,10.23]],"id":42651625}],"con":true,"img":false}]}
{"op":"mcm","clk":"5347919236","pt":1646210461114,"mc":[{"id":"1.195453612","rc":[{"atl":[[2.42,0]],"id":43167172}],"con":true,"img":false}]}
{"op":"mcm","clk":"5347919245","pt":1646210461211,"mc":[{"id":"1.195453612","rc":[{"atb":[[1.03,0],[1.02,0],[1.05,0],[1.04,0]],"id":43066529},{"atl":[[2.38,28.72]],"id":43167172}],"con":true,"img":false}]}
{"op":"mcm","clk":"5347919249","pt":1646210461313,"mc":[{"id":"1.195453612","rc":[{"atl":[[2.4,0],[2.72,140.2],[2.54,23.6]],"id":43167172}],"con":true,"img":false}]}
{"op":"mcm","clk":"5347919251","pt":1646210461418,"mc":[{"id":"1.195453612","rc":[{"atl":[[2.36,49.9]],"id":43167172}],"con":true,"img":false}]}
{"op":"mcm","clk":"5347919260","pt":1646210461685,"mc":[{"id":"1.195453612","rc":[{"atb":[[3.7,15.06],[3.65,81.08]],"id":41676292}],"con":true,"img":false}]}
{"op":"mcm","clk":"5347919431","pt":1646210466321,"mc":[{"id":"1.195453612","rc":[{"atb":[[1.78,9.64]],"id":43066529}],"con":true,"img":false}]}
{"op":"mcm","clk":"5347919472","pt":1646210467504,"mc":[{"id":"1.195453612","rc":[{"atl":[[2.88,0]],"id":43167172}],"con":true,"img":false}]}
{"op":"mcm","clk":"5347919525","pt":1646210468998,"mc":[{"id":"1.195453612","rc":[{"atb":[[1.74,28.79]],"id":43066529}],"con":true,"img":false}]}
{"op":"mcm","clk":"5347919573","pt":1646210470330,"mc":[{"id":"1.195453612","rc":[{"atb":[[1.78,0]],"id":43066529},{"atb":[[3.75,2.73]],"id":41676292}],"con":true,"img":false}]}
{"op":"mcm","clk":"5347919581","pt":1646210470491,"mc":[{"id":"1.195453612","rc":[{"atb":[[3.7,54.67],[3.65,37.72]],"id":41676292}],"con":true,"img":false}]}
{"op":"mcm","clk":"5347919606","pt":1646210471209,"mc":[{"id":"1.195453612","rc":[{"atl":[[8,53.9],[8.2,2.78]],"id":41676292}],"con":true,"img":false}]}
{"op":"mcm","clk":"5347919611","pt":1646210471306,"mc":[{"id":"1.195453612","rc":[{"atb":[[5.5,22.22],[5.4,0]],"id":41762566},{"atl":[[16,0],[16.5,1.29]],"id":41762566}],"con":true,"img":false}]}
{"op":"mcm","clk":"5347919627","pt":1646210471723,"mc":[{"id":"1.195453612","rc":[{"atb":[[1.7,48.55]],"id":43066529}],"con":true,"img":false}]}
{"op":"mcm","clk":"5347919643","pt":1646210472298,"mc":[{"id":"1.195453612","rc":[{"atb":[[3.75,0]],"id":41676292}],"con":true,"img":false}]}
{"op":"mcm","clk":"5347919678","pt":1646210473315,"mc":[{"id":"1.195453612","rc":[{"atb":[[1.71,34.05]],"id":43066529}],"con":true,"img":false}]}
{"op":"mcm","clk":"5347919704","pt":1646210473934,"mc":[{"id":"1.195453612","rc":[{"atb":[[1.7,0],[1.71,101.99]],"id":43066529}],"con":true,"img":false}]}
{"op":"mcm","clk":"5347919710","pt":1646210474036,"mc":[{"id":"1.195453612","rc":[{"atb":[[1.77,36.14]],"id":43066529}],"con":true,"img":false}]}
{"op":"mcm","clk":"5347919718","pt":1646210474197,"mc":[{"id":"1.195453612","rc":[{"atb":[[1.74,0]],"id":43066529}],"con":true,"img":false}]}
{"op":"mcm","clk":"5347919720","pt":1646210474298,"mc":[{"id":"1.195453612","rc":[{"atb":[[1.57,2.5]],"id":43066529}],"con":true,"img":false}]}
{"op":"mcm","clk":"5347919791","pt":1646210476405,"mc":[{"id":"1.195453612","rc":[{"spn":2.26,"spf":"NaN","id":43066529},{"spn":5.7,"spf":"NaN","id":41676292},{"atl":[[2.54,102.11]],"id":43167172},{"spn":1.89,"spf":"NaN","id":43167172}],"con":true,"img":false}]}
{"op":"mcm","clk":"5347919797","pt":1646210476506,"mc":[{"id":"1.195453612","rc":[{"atl":[[2.72,33.4]],"id":43167172}],"con":true,"img":false}]}
{"op":"mcm","clk":"5347919831","pt":1646210477534,"mc":[{"id":"1.195453612","rc":[{"atb":[[1.71,67.94]],"id":43066529},{"atb":[[3.7,15.06],[3.65,116.23]],"id":41676292}],"con":true,"img":false}]}
{"op":"mcm","clk":"5347919849","pt":1646210478111,"mc":[{"id":"1.195453612","rc":[{"atl":[[7.4,6.82]],"id":41676292}],"con":true,"img":false}]}
{"op":"mcm","clk":"5347919851","pt":1646210478210,"mc":[{"id":"1.195453612","rc":[{"atl":[[7.4,19.32],[7.8,0]],"id":41676292}],"con":true,"img":false}]}
{"op":"mcm","clk":"5347919863","pt":1646210478416,"mc":[{"id":"1.195453612","rc":[{"atl":[[7.6,0]],"id":41676292}],"con":true,"img":false}]}
{"op":"mcm","clk":"5347919866","pt":1646210478513,"mc":[{"id":"1.195453612","rc":[{"atl":[[8,14.29],[8.2,42.27]],"id":41676292}],"con":true,"img":false}]}
{"op":"mcm","clk":"5347919934","pt":1646210480524,"mc":[{"id":"1.195453612","rc":[{"atb":[[7.8,1.67]],"id":42651625}],"con":true,"img":false}]}
{"op":"mcm","clk":"5347919938","pt":1646210480628,"mc":[{"id":"1.195453612","rc":[{"atb":[[1.72,60.64],[1.68,0]],"id":43066529},{"atb":[[7.2,8.06],[7.4,20]],"id":42651625}],"con":true,"img":false}]}
{"op":"mcm","clk":"5347919942","pt":1646210480730,"mc":[{"id":"1.195453612","rc":[{"atb":[[7.8,8.87]],"id":42651625}],"con":true,"img":false}]}
{"op":"mcm","clk":"5347919949","pt":1646210480936,"mc":[{"id":"1.195453612","rc":[{"atb":[[7.6,3.03]],"id":42651625}],"con":true,"img":false}]}
{"op":"mcm","clk":"5347919982","pt":1646210481713,"mc":[{"id":"1.195453612","rc":[{"atb":[[1.69,51.53]],"id":43066529}],"con":true,"img":false}]}
{"op":"mcm","clk":"5347919993","pt":1646210482116,"mc":[{"id":"1.195453612","rc":[{"atl":[[2.38,0]],"id":43167172}],"con":true,"img":false}]}
{"op":"mcm","clk":"5347919998","pt":1646210482218,"mc":[{"id":"1.195453612","rc":[{"atl":[[2.34,28.72]],"id":43167172}],"con":true,"img":false}]}
{"op":"mcm","clk":"5347920002","pt":1646210482322,"mc":[{"id":"1.195453612","rc":[{"atl":[[2.36,0]],"id":43167172}],"con":true,"img":false}]}
{"op":"mcm","clk":"5347920008","pt":1646210482425,"mc":[{"id":"1.195453612","rc":[{"atl":[[2.34,78.62]],"id":43167172}],"con":true,"img":false}]}
{"op":"mcm","clk":"5347920043","pt":1646210483412,"mc":[{"id":"1.195453612","rc":[{"atl":[[2.72,140.2]],"id":43167172}],"con":true,"img":false}]}
{"op":"mcm","clk":"5347920048","pt":1646210483515,"mc":[{"id":"1.195453612","rc":[{"atl":[[2.54,23.6]],"id":43167172}],"con":true,"img":false}]}
{"op":"mcm","clk":"5347920052","pt":1646210483618,"mc":[{"id":"1.195453612","rc":[{"atb":[[3.75,3.04]],"id":41676292}],"con":true,"img":false}]}
{"op":"mcm","clk":"5347920076","pt":1646210484330,"mc":[{"id":"1.195453612","rc":[{"atb":[[3.75,5.77]],"id":41676292}],"con":true,"img":false}]}
{"op":"mcm","clk":"5347920097","pt":1646210485106,"mc":[{"id":"1.195453612","rc":[{"atb":[[7.4,14.4]],"id":42651625}],"con":true,"img":false}]}
{"op":"mcm","clk":"5347920100","pt":1646210485210,"mc":[{"id":"1.195453612","rc":[{"atb":[[8,5.6]],"id":42651625}],"con":true,"img":false}]}
{"op":"mcm","clk":"5347920110","pt":1646210485417,"mc":[{"id":"1.195453612","rc":[{"atb":[[3.7,59.58],[3.65,37.72]],"id":41676292}],"con":true,"img":false}]}
{"op":"mcm","clk":"5347920145","pt":1646210486132,"mc":[{"id":"1.195453612","rc":[{"atb":[[1.69,0]],"id":43066529}],"con":true,"img":false}]}
{"op":"mcm","clk":"5347920170","pt":1646210486645,"mc":[{"id":"1.195453612","rc":[{"atb":[[7.8,7.2]],"id":42651625}],"con":true,"img":false}]}
{"op":"mcm","clk":"5347920175","pt":1646210486748,"mc":[{"id":"1.195453612","rc":[{"atb":[[8.2,1.67]],"id":42651625}],"con":true,"img":false}]}
{"op":"mcm","clk":"5347920198","pt":1646210487218,"mc":[{"id":"1.195453612","rc":[{"atb":[[1.76,9.9]],"id":43066529},{"atb":[[3.75,3.04]],"id":41676292}],"con":true,"img":false}]}
{"op":"mcm","clk":"5347920265","pt":1646210488820,"mc":[{"id":"1.195453612","rc":[{"atb":[[1.72,128.58],[1.71,0]],"id":43066529}],"con":true,"img":false}]}
{"op":"mcm","clk":"5347920347","pt":1646210490518,"mc":[{"id":"1.195453612","rc":[{"atb":[[1.73,43.36]],"id":43066529}],"con":true,"img":false}]}
{"op":"mcm","clk":"5347920487","pt":1646210493353,"mc":[{"id":"1.195453612","rc":[{"atb":[[1.76,0]],"id":43066529},{"atb":[[3.8,17.3]],"id":41676292}],"con":true,"img":false}]}
{"op":"mcm","clk":"5347920503","pt":1646210493826,"mc":[{"id":"1.195453612","rc":[{"atl":[[2.82,3.9]],"id":43066529},{"atb":[[1.34,0]],"id":43167173}],"con":true,"img":false}]}
{"op":"mcm","clk":"5347920507","pt":1646210493923,"mc":[{"id":"1.195453612","rc":[{"atb":[[1.32,164.51]],"id":43167173}],"con":true,"img":false}]}
{"op":"mcm","clk":"5347920557","pt":1646210495362,"mc":[{"id":"1.195453612","rc":[{"atb":[[7.4,0],[7.8,21.6]],"id":42651625}],"con":true,"img":false}]}
{"op":"mcm","clk":"5347920560","pt":1646210495465,"mc":[{"id":"1.195453612","rc":[{"atb":[[8.2,8.87]],"id":42651625}],"con":true,"img":false}]}
{"op":"mcm","clk":"5347920566","pt":1646210495626,"mc":[{"id":"1.195453612","rc":[{"atb":[[7.8,14.4]],"id":42651625}],"con":true,"img":false}]}
{"op":"mcm","clk":"5347920587","pt":1646210496443,"mc":[{"id":"1.195453612","rc":[{"atl":[[2.7,2.5]],"id":43167172}],"con":true,"img":false}]}
{"op":"mcm","clk":"5347920591","pt":1646210496547,"mc":[{"id":"1.195453612","rc":[{"atl":[[2.82,0]],"id":43066529},{"atl":[[2.72,33.4],[2.7,68.05]],"id":43167172}],"con":true,"img":false}]}
{"op":"mcm","clk":"5347920605","pt":1646210496856,"mc":[{"id":"1.195453612","rc":[{"atl":[[2.78,23.41]],"id":43066529}],"con":true,"img":false}]}
{"op":"mcm","clk":"5347920632","pt":1646210497579,"mc":[{"id":"1.195453612","rc":[{"atl":[[2.78,20.42]],"id":43066529},{"atb":[[6.8,12.93]],"id":42651625}],"con":true,"img":false}]}
{"op":"mcm","clk":"5347920654","pt":1646210498043,"mc":[{"id":"1.195453612","rc":[{"atb":[[5.1,14.7]],"id":41762566}],"con":true,"img":false}]}
{"op":"mcm","clk":"5347920657","pt":1646210498146,"mc":[{"id":"1.195453612","rc":[{"atl":[[15.5,0]],"id":41762566}],"con":true,"img":false}]}
{"op":"mcm","clk":"5347920662","pt":1646210498248,"mc":[{"id":"1.195453612","rc":[{"atl":[[16.5,6.45]],"id":41762566}],"con":true,"img":false}]}
{"op":"mcm","clk":"5347920692","pt":1646210498863,"mc":[{"id":"1.195453612","rc":[{"atl":[[16.5,5.16],[17,3.52]],"id":41762566},{"atl":[[2.82,10.99],[2.84,0]],"id":43066529},{"atb":[[1.37,32.55],[1.4,83.55],[1.41,2.5]],"id":43167173}],"con":true,"img":false}]}
{"op":"mcm","clk":"5347920697","pt":1646210498966,"mc":[{"id":"1.195453612","rc":[{"atb":[[1.41,106.38],[1.4,0]],"id":43167173}],"con":true,"img":false}]}
{"op":"mcm","clk":"5347920717","pt":1646210499330,"mc":[{"id":"1.195453612","rc":[{"atb":[[1.56,0],[1.54,37.04],[1.77,45.91],[1.76,10.99]],"id":43066529},{"atl":[[1.9,3]],"id":43066529},{"atb":[[1.43,19.42],[1.33,60.61],[1.35,285.63]],"id":43167173},{"atl":[[3.9,2]],"id":43167173}],"con":true,"img":false}]}
{"op":"mcm","clk":"5347920724","pt":1646210499440,"mc":[{"id":"1.195453612","rc":[{"atl":[[1.89,4]],"id":43066529},{"atl":[[3.85,2],[2.6,47.25],[2.58,34.82],[2.66,5],[2.68,0]],"id":43167173}],"con":true,"img":false}]}
{"op":"mcm","clk":"5347920726","pt":1646210499537,"mc":[{"id":"1.195453612","rc":[{"atl":[[7.4,12.5]],"id":41676292},{"atb":[[1.33,229.58]],"id":43167172}],"con":true,"img":false}]}
{"op":"mcm","clk":"5347920730","pt":1646210499639,"mc":[{"id":"1.195453612","rc":[{"atl":[[1.88,2],[1.9,0]],"id":43066529},{"atl":[[8,0],[7.2,6.82],[8.2,56.16]],"id":41676292},{"atb":[[1.35,0]],"id":43167172},{"atl":[[8.2,2]],"id":43167172},{"atl":[[3.8,2]],"id":43167173}],"con":true,"img":false}]}
{"op":"mcm","clk":"5347920734","pt":1646210499743,"mc":[{"id":"1.195453612","rc":[{"atl":[[7.2,19.72],[7.4,0]],"id":41676292}],"con":true,"img":false}]}
{"op":"mcm","clk":"5347920740","pt":1646210499846,"mc":[{"id":"1.195453612","rc":[{"atl":[[8.6,46],[8.2,16.67]],"id":41676292},{"atl":[[8,3]],"id":43167172},{"atl":[[3.75,3]],"id":43167173}],"con":true,"img":false}]}
{"op":"mcm","clk":"5347920752","pt":1646210500055,"mc":[{"id":"1.195453612","rc":[{"atl":[[1.87,3]],"id":43066529},{"atb":[[1.33,168.97],[1.35,57.14]],"id":43167172},{"atl":[[8,0],[8.2,0]],"id":43167172},{"atb":[[1.35,342.77]],"id":43167173},{"atl":[[3.85,0],[3.8,0],[3.75,0],[3.9,0]],"id":43167173}],"con":true,"img":false}]}
{"op":"mcm","clk":"5347920761","pt":1646210500260,"mc":[{"id":"1.195453612","rc":[{"atb":[[1.56,35.71]],"id":43066529},{"atl":[[1.89,0],[1.87,0],[1.88,0]],"id":43066529},{"atb":[[1.33,229.58],[1.35,0]],"id":43167172},{"atl":[[7.8,18.71]],"id":43167172}],"con":true,"img":false}]}
{"op":"mcm","clk":"5347920772","pt":1646210500468,"mc":[{"id":"1.195453612","rc":[{"atl":[[170,0],[180,1]],"id":42651625},{"atb":[[3.2,22.28],[3.3,8.7]],"id":41676292},{"atl":[[8.4,0],[8.6,2.63],[7.6,4]],"id":43167172},{"atl":[[3.45,48.98],[4.3,0]],"id":43167173}],"con":true,"img":false}]}
{"op":"mcm","clk":"5347920776","pt":1646210500572,"mc":[{"id":"1.195453612","rc":[{"atl":[[7.8,14.71]],"id":43167172}],"con":true,"img":false}]}
{"op":"mcm","clk":"5347920782","pt":1646210500675,"mc":[{"id":"1.195453612","rc":[{"atl":[[2.74,1.72]],"id":43066529}],"con":true,"img":false}]}
{"op":"mcm","clk":"5347920785","pt":1646210500740,"mc":[{"id":"1.195453612","rc":[{"atl":[[7.6,0]],"id":43167172}],"con":true,"img":false}]}
{"op":"mcm","clk":"5347920802","pt":1646210501041,"mc":[{"id":"1.195453612","rc":[{"atb":[[4.6,0]],"id":41762566},{"atl":[[17,2.27],[17.5,1.21]],"id":41762566},{"atl":[[2.82,0],[2.78,31.66]],"id":43066529}],"con":true,"img":false}]}
{"op":"mcm","clk":"5347920808","pt":1646210501140,"mc":[{"id":"1.195453612","rc":[{"atb":[[4.1,34.8]],"id":41762566}],"con":true,"img":false}]}
{"op":"mcm","clk":"5347920864","pt":1646210502335,"mc":[{"id":"1.195453612","rc":[{"atb":[[1.33,168.97],[1.35,57.14]],"id":43167172}],"con":true,"img":false}]}
{"op":"mcm","clk":"5347920880","pt":1646210502640,"mc":[{"id":"1.195453612","rc":[{"atb":[[1.56,0]],"id":43066529},{"atl":[[1.89,4]],"id":43066529},{"atl":[[8.6,0],[9.2,0],[8.8,0],[9.4,2.38]],"id":43167172}],"con":true,"img":false}]}
{"op":"mcm","clk":"5347920883","pt":1646210502745,"mc":[{"id":"1.195453612","rc":[{"atl":[[1.89,0]],"id":43066529},{"trd":[[1.89,8]],"ltp":1.89,"tv":8.0,"id":43066529},{"atb":[[1.37,5]],"id":43167173}],"con":true,"img":false}]}
{"op":"mcm","clk":"5347920887","pt":1646210502842,"mc":[{"id":"1.195453612","rc":[{"atb":[[1.78,4],[1.76,15.29]],"id":43066529},{"atl":[[2.76,0]],"id":43066529},{"atb":[[1.47,2.96]],"id":43167173}],"con":true,"img":false}]}
{"op":"mcm","clk":"5347920890","pt":1646210502945,"mc":[{"id":"1.195453612","rc":[{"atb":[[1.78,35.42]],"id":43066529}],"con":true,"img":false}]}
{"op":"mcm","clk":"5347920899","pt":1646210503151,"mc":[{"id":"1.195453612","rc":[{"atb":[[1.77,11.94]],"id":43066529}],"con":true,"img":false}]}
{"op":"mcm","clk":"5347920905","pt":1646210503255,"mc":[{"id":"1.195453612","rc":[{"atl":[[2.76,3.19]],"id":43066529},{"atl":[[2.32,4.11]],"id":43167172}],"con":true,"img":false}]}
{"op":"mcm","clk":"5347920909","pt":1646210503357,"mc":[{"id":"1.195453612","rc":[{"atb":[[1.76,88.61]],"id":43066529},{"atl":[[2.32,36.89]],"id":43167172}],"con":true,"img":false}]}
{"op":"mcm","clk":"5347920913","pt":1646210503459,"mc":[{"id":"1.195453612","rc":[{"atb":[[1.72,60.64]],"id":43066529},{"atl":[[2.54,89.15],[2.7,2.5]],"id":43167172}],"con":true,"img":false}]}
{"op":"mcm","clk":"5347920918","pt":1646210503563,"mc":[{"id":"1.195453612","rc":[{"atl":[[2.34,28.72]],"id":43167172}],"con":true,"img":false}]}
{"op":"mcm","clk":"5347920926","pt":1646210503871,"mc":[{"id":"1.195453612","rc":[{"atb":[[1.81,2.17],[1.77,9.77]],"id":43066529}],"con":true,"img":false}]}
{"op":"mcm","clk":"5347920954","pt":1646210504542,"mc":[{"id":"1.195453612","rc":[{"atl":[[3.95,21.83],[3.4,0]],"id":43066529}],"con":true,"img":false}]}
{"op":"mcm","clk":"5347920969","pt":1646210504954,"mc":[{"id":"1.195453612","rc":[{"atb":[[1.73,0]],"id":43066529}],"con":true,"img":false}]}
{"op":"mcm","clk":"5347920991","pt":1646210505366,"mc":[{"id":"1.195453612","rc":[{"atb":[[1.77,0]],"id":43066529},{"atb":[[1.44,17.1]],"id":43167173}],"con":true,"img":false}]}
{"op":"mcm","clk":"5347921004","pt":1646210505675,"mc":[{"id":"1.195453612","rc":[{"atb":[[1.82,2.53]],"id":43066529}],"con":true,"img":false}]}
{"op":"mcm","clk":"5347921011","pt":1646210505735,"mc":[{"id":"1.195453612","rc":[{"atl":[[2.74,0]],"id":43066529}],"con":true,"img":false}]}
{"op":"mcm","clk":"5347921027","pt":1646210506352,"mc":[{"id":"1.195453612","rc":[{"atl":[[7.8,14.71]],"id":41676292},{"atb":[[1.44,3.33]],"id":43167172}],"con":true,"img":false}]}
{"op":"mcm","clk":"5347921030","pt":1646210506449,"mc":[{"id":"1.195453612","rc":[{"atl":[[8.2,2.78]],"id":41676292}],"con":true,"img":false}]}
{"op":"mcm","clk":"5347921056","pt":1646210507171,"mc":[{"id":"1.195453612","rc":[{"atb":[[1.44,20.35]],"id":43167173}],"con":true,"img":false}]}
{"op":"mcm","clk":"5347921068","pt":1646210507477,"mc":[{"id":"1.195453612","rc":[{"atb":[[1.81,6.35],[1.76,84.31]],"id":43066529}],"con":true,"img":false}]}
{"op":"mcm","clk":"5347921073","pt":1646210507581,"mc":[{"id":"1.195453612","rc":[{"atl":[[7.2,12.9]],"id":41676292}],"con":true,"img":false}]}
{"op":"mcm","clk":"5347921078","pt":1646210507641,"mc":[{"id":"1.195453612","rc":[{"atl":[[8,6.82]],"id":41676292}],"con":true,"img":false}]}
{"op":"mcm","clk":"5347921084","pt":1646210507740,"mc":[{"id":"1.195453612","rc":[{"atl":[[7.2,0]],"id":41676292}],"con":true,"img":false}]}
{"op":"mcm","clk":"5347921090","pt":1646210507843,"mc":[{"id":"1.195453612","rc":[{"atl":[[7.6,12.12]],"id":41676292}],"con":true,"img":false}]}
{"op":"mcm","clk":"5347921100","pt":1646210508145,"mc":[{"id":"1.195453612","rc":[{"atb":[[3.7,44.52]],"id":41676292}],"con":true,"img":false}]}
{"op":"mcm","clk":"5347921105","pt":1646210508248,"mc":[{"id":"1.195453612","rc":[{"atb":[[3.85,15.06]],"id":41676292}],"con":true,"img":false}]}
{"op":"mcm","clk":"5347921109","pt":1646210508352,"mc":[{"id":"1.195453612","rc":[{"atb":[[3.85,35.18],[3.75,43.28]],"id":41676292}],"con":true,"img":false}]}
{"op":"mcm","clk":"5347921117","pt":1646210508557,"mc":[{"id":"1.195453612","rc":[{"atb":[[3.8,6.85],[3.7,0]],"id":41676292}],"con":true,"img":false}]}
{"op":"mcm","clk":"5347921159","pt":1646210509440,"mc":[{"id":"1.195453612","rc":[{"atb":[[1.47,0]],"id":43167173}],"con":true,"img":false}]}
{"op":"mcm","clk":"5347921163","pt":1646210509543,"mc":[{"id":"1.195453612","rc":[{"atb":[[1.46,5.65]],"id":43167173}],"con":true,"img":false}]}
{"op":"mcm","clk":"5347921168","pt":1646210509647,"mc":[{"id":"1.195453612","rc":[{"atb":[[1.79,2.79]],"id":43066529},{"atb":[[1.4,0]],"id":43167172}],"con":true,"img":false}]}
{"op":"mcm","clk":"5347921204","pt":1646210510669,"mc":[{"id":"1.195453612","rc":[{"atb":[[1.72,0]],"id":43066529}],"con":true,"img":false}]}
{"op":"mcm","clk":"5347921208","pt":1646210510772,"mc":[{"id":"1.195453612","rc":[{"atb":[[1.77,60.64]],"id":43066529},{"atl":[[200,1]],"id":42651625},{"atb":[[3.2,45.01],[3.8,5.18]],"id":41676292},{"atb":[[1.33,151.52]],"id":43167173},{"atl":[[3.55,19.61]],"id":43167173}],"con":true,"img":false}]}
{"op":"mcm","clk":"5347921220","pt":1646210510977,"mc":[{"id":"1.195453612","rc":[{"atb":[[3.9,1.67]],"id":41676292}],"con":true,"img":false}]}
{"op":"mcm","clk":"5347921225","pt":1646210511080,"mc":[{"id":"1.195453612","rc":[{"atl":[[2.34,0]],"id":43167172}],"con":true,"img":false}]}
{"op":"mcm","clk":"5347921231","pt":1646210511182,"mc":[{"id":"1.195453612","rc":[{"atl":[[190,0],[210,0],[230,0]],"id":42651625},{"atb":[[2.96,0]],"id":41676292},{"atl":[[2.52,28.72]],"id":43167172},{"atl":[[4.9,0]],"id":43167173}],"con":true,"img":false}]}
{"op":"mcm","clk":"5347921235","pt":1646210511240,"mc":[{"id":"1.195453612","rc":[{"atl":[[2.54,23.6],[2.7,62.84]],"id":43167172}],"con":true,"img":false}]}
{"op":"mcm","clk":"5347921241","pt":1646210511344,"mc":[{"id":"1.195453612","rc":[{"atl":[[18.5,2.86]],"id":41762566},{"atb":[[1.52,96.15]],"id":43066529},{"atl":[[2.82,26.93]],"id":43066529},{"atb":[[3.8,2.5]],"id":41676292}],"con":true,"img":false}]}
{"op":"mcm","clk":"5347921303","pt":1646210512944,"mc":[{"id":"1.195453612","rc":[{"atl":[[2.92,0],[2.88,0],[2.96,0]],"id":43066529},{"atl":[[9.8,5.68]],"id":43167172}],"con":true,"img":false}]}
{"op":"mcm","clk":"5347921323","pt":1646210513355,"mc":[{"id":"1.195453612","rc":[{"atb":[[1.43,102.19]],"id":43167173}],"con":true,"img":false}]}
{"op":"mcm","clk":"5347921326","pt":1646210513459,"mc":[{"id":"1.195453612","rc":[{"atl":[[2.8,3.32]],"id":43066529},{"atb":[[1.41,2.5]],"id":43167173}],"con":true,"img":false}]}
{"op":"mcm","clk":"5347921332","pt":1646210513557,"mc":[{"id":"1.195453612","rc":[{"atb":[[8,0]],"id":42651625}],"con":true,"img":false}]}
{"op":"mcm","clk":"5347921335","pt":1646210513660,"mc":[{"id":"1.195453612","rc":[{"atb":[[7.4,2.5],[7.6,22.33],[7.8,0],[8.4,5.6]],"id":42651625}],"con":true,"img":false}]}
{"op":"mcm","clk":"5347921339","pt":1646210513763,"mc":[{"id":"1.195453612","rc":[{"atb":[[8.4,12.8]],"id":42651625}],"con":true,"img":false}]}
{"op":"mcm","clk":"5347921342","pt":1646210513865,"mc":[{"id":"1.195453612","rc":[{"atb":[[1.79,0]],"id":43066529},{"atb":[[1.4,3.98]],"id":43167172}],"con":true,"img":false}]}
{"op":"mcm","clk":"5347921346","pt":1646210513969,"mc":[{"id":"1.195453612","rc":[{"atb":[[8.2,1.67]],"id":42651625}],"con":true,"img":false}]}
{"op":"mcm","clk":"5347921351","pt":1646210514174,"mc":[{"id":"1.195453612","rc":[{"atl":[[8,47.06],[8.6,6.58]],"id":41676292}],"con":true,"img":false}]}
{"op":"mcm","clk":"5347921353","pt":1646210514277,"mc":[{"id":"1.195453612","rc":[{"atl":[[8,61.35],[7.8,0]],"id":41676292}],"con":true,"img":false}]}
{"op":"mcm","clk":"5347921356","pt":1646210514381,"mc":[{"id":"1.195453612","rc":[{"atb":[[1.46,2.17]],"id":43167173}],"con":true,"img":false}]}
{"op":"mcm","clk":"5347921361","pt":1646210514484,"mc":[{"id":"1.195453612","rc":[{"atl":[[7.6,0]],"id":41676292},{"atb":[[1.44,3.25],[1.45,3.56]],"id":43167173}],"con":true,"img":false}]}
{"op":"mcm","clk":"5347921364","pt":1646210514542,"mc":[{"id":"1.195453612","rc":[{"atl":[[7.8,11.18]],"id":41676292}],"con":true,"img":false}]}
{"op":"mcm","clk":"5347921401","pt":1646210515460,"mc":[{"id":"1.195453612","rc":[{"atb":[[1.45,0]],"id":43167173}],"con":true,"img":false}]}
{"op":"mcm","clk":"5347921452","pt":1646210516753,"mc":[{"id":"1.195453612","rc":[{"atb":[[8.2,0]],"id":42651625}],"con":true,"img":false}]}
{"op":"mcm","clk":"5347921459","pt":1646210516956,"mc":[{"id":"1.195453612","rc":[{"atb":[[8.6,1.67]],"id":42651625}],"con":true,"img":false}]}
{"op":"mcm","clk":"5347921471","pt":1646210517159,"mc":[{"id":"1.195453612","rc":[{"atb":[[1.83,4]],"id":43066529}],"con":true,"img":false}]}
{"op":"mcm","clk":"5347921484","pt":1646210517367,"mc":[{"id":"1.195453612","rc":[{"atb":[[1.78,31.42],[1.81,15.64]],"id":43066529},{"atb":[[1.47,2.96]],"id":43167173}],"con":true,"img":false}]}
{"op":"mcm","clk":"5347921501","pt":1646210517675,"mc":[{"id":"1.195453612","rc":[{"atb":[[1.76,10.99],[1.81,26.62]],"id":43066529}],"con":true,"img":false}]}
{"op":"mcm","clk":"5347921506","pt":1646210517779,"mc":[{"id":"1.195453612","rc":[{"atl":[[2.54,102.11]],"id":43167172}],"con":true,"img":false}]}
{"op":"mcm","clk":"5347921509","pt":1646210517881,"mc":[{"id":"1.195453612","rc":[{"atl":[[2.7,2.5]],"id":43167172}],"con":true,"img":false}]}
{"op":"mcm","clk":"5347921514","pt":1646210518087,"mc":[{"id":"1.195453612","rc":[{"atb":[[1.81,22.44]],"id":43066529}],"con":true,"img":false}]}
{"op":"mcm","clk":"5347921518","pt":1646210518191,"mc":[{"id":"1.195453612","rc":[{"atb":[[1.82,0],[1.79,2.79]],"id":43066529}],"con":true,"img":false}]}
{"op":"mcm","clk":"5347921525","pt":1646210518349,"mc":[{"id":"1.195453612","rc":[{"atb":[[1.83,0]],"id":43066529}],"con":true,"img":false}]}
{"op":"mcm","clk":"5347921528","pt":1646210518454,"mc":[{"id":"1.195453612","rc":[{"atb":[[1.82,4],[1.81,27.93]],"id":43066529}],"con":true,"img":false}]}
{"op":"mcm","clk":"5347921533","pt":1646210518667,"mc":[{"id":"1.195453612","rc":[{"atb":[[1.78,0]],"id":43066529}],"con":true,"img":false}]}
{"op":"mcm","clk":"5347921553","pt":1646210519169,"mc":[{"id":"1.195453612","rc":[{"atl":[[18,2.72]],"id":41762566},{"atb":[[1.55,0]],"id":43066529}],"con":true,"img":false}]}
{"op":"mcm","clk":"5347921557","pt":1646210519271,"mc":[{"id":"1.195453612","rc":[{"atl":[[19,3.4]],"id":41762566},{"atb":[[1.53,127.72]],"id":43066529}],"con":true,"img":false}]}
{"op":"mcm","clk":"5347921596","pt":1646210520355,"mc":[{"id":"1.195453612","rc":[{"atb":[[1.46,18.53]],"id":43167173}],"con":true,"img":false}]}
{"op":"mcm","clk":"5347921613","pt":1646210520763,"mc":[{"id":"1.195453612","rc":[{"atl":[[8,21.11],[8.2,45.94]],"id":41676292}],"con":true,"img":false}]}
{"op":"mcm","clk":"5347921615","pt":1646210520866,"mc":[{"id":"1.195453612","rc":[{"atl":[[8,6.82],[8.2,59.83]],"id":41676292}],"con":true,"img":false}]}
{"op":"mcm","clk":"5347921618","pt":1646210520969,"mc":[{"id":"1.195453612","rc":[{"atb":[[1.76,0]],"id":43066529},{"atl":[[220,1]],"id":42651625},{"atb":[[3.1,35.71],[3.75,40.24]],"id":41676292},{"atb":[[1.43,82.77]],"id":43167173},{"atl":[[3.65,28.3]],"id":43167173}],"con":true,"img":false}]}
{"op":"mcm","clk":"5347921621","pt":1646210521071,"mc":[{"id":"1.195453612","rc":[{"atl":[[8.2,45.94],[7.8,22.36]],"id":41676292}],"con":true,"img":false}]}
{"op":"mcm","clk":"5347921632","pt":1646210521487,"mc":[{"id":"1.195453612","rc":[{"atl":[[19.5,4.05]],"id":41762566},{"atb":[[1.5,199.94]],"id":43066529}],"con":true,"img":false}]}
{"op":"mcm","clk":"5347921634","pt":1646210521590,"mc":[{"id":"1.195453612","rc":[{"atb":[[1.5,349.94]],"id":43066529},{"atl":[[2.86,39.53]],"id":43066529}],"con":true,"img":false}]}
{"op":"mcm","clk":"5347921659","pt":1646210522060,"mc":[{"id":"1.195453612","rc":[{"atl":[[4.7,0]],"id":43167173}],"con":true,"img":false}]}
{"op":"mcm","clk":"5347921688","pt":1646210522574,"mc":[{"id":"1.195453612","rc":[{"atb":[[1.44,8.6]],"id":43167172},{"atl":[[2.32,32.78]],"id":43167172}],"con":true,"img":false}]}
{"op":"mcm","clk":"5347921698","pt":1646210522779,"mc":[{"id":"1.195453612","rc":[{"atl":[[2.32,0]],"id":43167172}],"con":true,"img":false}]}
{"op":"mcm","clk":"5347921702","pt":1646210522881,"mc":[{"id":"1.195453612","rc":[{"atl":[[2.5,46.13]],"id":43167172}],"con":true,"img":false}]}
{"op":"mcm","clk":"5347921708","pt":1646210522984,"mc":[{"id":"1.195453612","rc":[{"atl":[[2.54,23.6],[2.7,58.51]],"id":43167172}],"con":true,"img":false}]}
{"op":"mcm","clk":"5347921711","pt":1646210523088,"mc":[{"id":"1.195453612","rc":[{"atl":[[10.5,7.89]],"id":43167172}],"con":true,"img":false}]}
{"op":"mcm","clk":"5347921715","pt":1646210523190,"mc":[{"id":"1.195453612","rc":[{"atl":[[2.7,2.5]],"id":43167172}],"con":true,"img":false}]}
{"op":"mcm","clk":"5347921718","pt":1646210523293,"mc":[{"id":"1.195453612","rc":[{"atb":[[1.8,4.2]],"id":43066529},{"atl":[[2.5,49.14]],"id":43167172}],"con":true,"img":false}]}
{"op":"mcm","clk":"5347921755","pt":1646210524271,"mc":[{"id":"1.195453612","rc":[{"atb":[[1.8,16.5],[1.81,16.95]],"id":43066529},{"atb":[[1.44,0]],"id":43167173}],"con":true,"img":false}]}
{"op":"mcm","clk":"5347921768","pt":1646210524685,"mc":[{"id":"1.195453612","rc":[{"atl":[[2.9,0]],"id":43066529},{"atl":[[2.5,46.13]],"id":43167172}],"con":true,"img":false}]}
{"op":"mcm","clk":"5347921770","pt":1646210524787,"mc":[{"id":"1.195453612","rc":[{"atl":[[2.76,25.48]],"id":43066529}],"con":true,"img":false}]}
{"op":"mcm","clk":"5347921774","pt":1646210524992,"mc":[{"id":"1.195453612","rc":[{"atb":[[1.39,0]],"id":43167172}],"con":true,"img":false}]}
{"op":"mcm","clk":"5347921779","pt":1646210525096,"mc":[{"id":"1.195453612","rc":[{"atb":[[1.77,0]],"id":43066529},{"atb":[[1.43,88.38]],"id":43167172}],"con":true,"img":false}]}
{"op":"mcm","clk":"5347921781","pt":1646210525199,"mc":[{"id":"1.195453612","rc":[{"atb":[[1.6,60.64]],"id":43066529}],"con":true,"img":false}]}
{"op":"mcm","clk":"5347921788","pt":1646210525356,"mc":[{"id":"1.195453612","rc":[{"atl":[[2.54,123.4]],"id":43167172}],"con":true,"img":false}]}
{"op":"mcm","clk":"5347921831","pt":1646210526484,"mc":[{"id":"1.195453612","rc":[{"atb":[[1.79,0]],"id":43066529},{"atb":[[1.4,0]],"id":43167172}],"con":true,"img":false}]}
{"op":"mcm","clk":"5347921836","pt":1646210526587,"mc":[{"id":"1.195453612","rc":[{"atb":[[1.81,7.66]],"id":43066529},{"atb":[[1.42,19.88]],"id":43167172}],"con":true,"img":false}]}
{"op":"mcm","clk":"5347921868","pt":1646210527102,"mc":[{"id":"1.195453612","rc":[{"atb":[[1.43,2.17]],"id":43167172}],"con":true,"img":false}]}
{"op":"mcm","clk":"5347921874","pt":1646210527158,"mc":[{"id":"1.195453612","rc":[{"atb":[[1.39,86.21]],"id":43167172}],"con":true,"img":false}]}
{"op":"mcm","clk":"5347921889","pt":1646210527567,"mc":[{"id":"1.195453612","rc":[{"atl":[[2.48,2.69]],"id":43167172}],"con":true,"img":false}]}
{"op":"mcm","clk":"5347921893","pt":1646210527671,"mc":[{"id":"1.195453612","rc":[{"atl":[[2.6,22.72]],"id":43167173}],"con":true,"img":false}]}
{"op":"mcm","clk":"5347921894","pt":1646210527769,"mc":[{"id":"1.195453612","rc":[{"atl":[[2.56,24.53]],"id":43167173}],"con":true,"img":false}]}
{"op":"mcm","clk":"5347921898","pt":1646210527872,"mc":[{"id":"1.195453612","rc":[{"atb":[[8.6,12.2]],"id":42651625},{"atl":[[2.54,35.44],[2.6,93.6],[2.62,0]],"id":43167173}],"con":true,"img":false}]}
{"op":"mcm","clk":"5347921901","pt":1646210527975,"mc":[{"id":"1.195453612","rc":[{"atb":[[8.4,5.6]],"id":42651625},{"atl":[[2.58,2.5]],"id":43167173}],"con":true,"img":false}]}
{"op":"mcm","clk":"5347921907","pt":1646210528181,"mc":[{"id":"1.195453612","rc":[{"atl":[[2.42,3.01]],"id":43167172}],"con":true,"img":false}]}
{"op":"mcm","clk":"5347921912","pt":1646210528387,"mc":[{"id":"1.195453612","rc":[{"atl":[[17.5,0],[18,3.9]],"id":41762566},{"atb":[[1.8,12.3]],"id":43066529},{"atl":[[2.8,14.21],[2.78,20.42]],"id":43066529}],"con":true,"img":false}]}
{"op":"mcm","clk":"5347921922","pt":1646210528600,"mc":[{"id":"1.195453612","rc":[{"atb":[[8.4,0]],"id":42651625},{"atb":[[1.47,5.19]],"id":43167173}],"con":true,"img":false}]}
{"op":"mcm","clk":"5347921928","pt":1646210528696,"mc":[{"id":"1.195453612","rc":[{"atb":[[7.8,5.6]],"id":42651625},{"atb":[[1.44,3.25]],"id":43167173}],"con":true,"img":false}]}
{"op":"mcm","clk":"5347921933","pt":1646210528797,"mc":[{"id":"1.195453612","rc":[{"atb":[[7.4,26.8]],"id":42651625}],"con":true,"img":false}]}
{"op":"mcm","clk":"5347921937","pt":1646210528900,"mc":[{"id":"1.195453612","rc":[{"atb":[[7.6,3.03]],"id":42651625},{"atb":[[1.44,38.83]],"id":43167173}],"con":true,"img":false}]}
{"op":"mcm","clk":"5347921942","pt":1646210529004,"mc":[{"id":"1.195453612","rc":[{"atb":[[7.4,2.5]],"id":42651625},{"atb":[[1.43,0]],"id":43167173}],"con":true,"img":false}]}
{"op":"mcm","clk":"5347921960","pt":1646210529478,"mc":[{"id":"1.195453612","rc":[{"atb":[[1.46,2.17]],"id":43167173}],"con":true,"img":false}]}
{"op":"mcm","clk":"5347921963","pt":1646210529571,"mc":[{"id":"1.195453612","rc":[{"atb":[[7.8,0]],"id":42651625},{"atb":[[3.85,20.12]],"id":41676292}],"con":true,"img":false}]}
{"op":"mcm","clk":"5347921964","pt":1646210529674,"mc":[{"id":"1.195453612","rc":[{"atb":[[1.54,0],[1.53,165.46]],"id":43066529},{"atb":[[7,5.6]],"id":42651625},{"atb":[[3.9,16.73]],"id":41676292},{"atl":[[8.6,9.21],[8.2,59.83]],"id":41676292}],"con":true,"img":false}]}
{"op":"mcm","clk":"5347921967","pt":1646210529778,"mc":[{"id":"1.195453612","rc":[{"atb":[[3.8,57.78],[3.9,44.32],[3.75,0]],"id":41676292},{"atl":[[8.6,2.63],[8.2,57.05],[7.8,11.18]],"id":41676292}],"con":true,"img":false}]}
