{"op":"mcm","clk":"5317728629","pt":1646251400751,"mc":[{"id":"1.195532874","marketDefinition":{"bspMarket":true,"turnInPlayEnabled":false,"persistenceEnabled":false,"marketBaseRate":5.0,"eventId":"31275720","eventTypeId":"4339","numberOfWinners":1,"bettingType":"ODDS","marketType":"WIN","marketTime":"2022-03-03T17:28:00.000Z","suspendTime":"2022-03-03T17:28:00.000Z","bspReconciled":false,"complete":true,"inPlay":false,"crossMatching":false,"runnersVoidable":false,"numberOfActiveRunners":6,"betDelay":0,"status":"OPEN","runners":[{"status":"ACTIVE","sortPriority":1,"id":40883678,"name":"1. Kincora For Real"},{"status":"ACTIVE","sortPriority":2,"id":40642034,"name":"2. Maple Patsy"},{"status":"ACTIVE","sortPriority":3,"id":39614765,"name":"3. Puttfor Juney"},{"status":"ACTIVE","sortPriority":4,"id":41469398,"name":"4. Droopys Good One"},{"status":"ACTIVE","sortPriority":5,"id":37306244,"name":"5. Ballyard Hilary"},{"status":"ACTIVE","sortPriority":6,"id":35985721,"name":"6. Waste House Izzy"}],"regulators":["MR_INT"],"venue":"Romford","countryCode":"GB","discountAllowed":false,"timezone":"Europe/London","openDate":"2022-03-03T13:57:00.000Z","version":4384107348,"name":"S1 575m","eventName":"Romford 3rd Mar"},"rc":[],"con":true,"img":false}]}
{"op":"mcm","clk":"5317728887","pt":1646251401783,"mc":[{"id":"1.195532874","marketDefinition":{"bspMarket":true,"turnInPlayEnabled":false,"persistenceEnabled":false,"marketBaseRate":5.0,"eventId":"31275720","eventTypeId":"4339","numberOfWinners":1,"bettingType":"ODDS","marketType":"WIN","marketTime":"2022-03-03T17:28:00.000Z","suspendTime":"2022-03-03T17:28:00.000Z","bspReconciled":false,"complete":true,"inPlay":false,"crossMatching":false,"runnersVoidable":false,"numberOfActiveRunners":6,"betDelay":0,"status":"OPEN","runners":[{"status":"ACTIVE","sortPriority":1,"id":40883678,"name":"1. Kincora For Real"},{"status":"ACTIVE","sortPriority":2,"id":40642034,"name":"2. Maple Patsy"},{"status":"ACTIVE","sortPriority":3,"id":39614765,"name":"3. Puttfor Juney"},{"status":"ACTIVE","sortPriority":4,"id":41469398,"name":"4. Droopys Good One"},{"status":"ACTIVE","sortPriority":5,"id":37306244,"name":"5. Ballyard Hilary"},{"status":"ACTIVE","sortPriority":6,"id":35985721,"name":"6. Waste House Izzy"}],"regulators":["MR_INT"],"venue":"Romford","countryCode":"GB","discountAllowed":true,"timezone":"Europe/London","openDate":"2022-03-03T13:57:00.000Z","version":4384107348,"name":"S1 575m","eventName":"Romford 3rd Mar"},"rc":[],"con":true,"img":false}]}
{"op":"mcm","clk":"5318486448","pt":1646259102043,"mc":[{"id":"1.195532874","rc":[{"atl":[[560,3]],"id":37306244},{"spn":1.0,"spf":"NaN","id":37306244},{"atl":[[270,3]],"id":41469398},{"spn":1.0,"spf":"NaN","id":41469398},{"atb":[[1.12,30]],"id":39614765},{"atl":[[550,3]],"id":39614765},{"spn":275.56,"spf":"NaN","id":39614765},{"atl":[[390,3]],"id":40642034},{"spn":1.0,"spf":"NaN","id":40642034},{"atl":[[370,3]],"id":40883678},{"spn":1.0,"spf":"NaN","id":40883678}],"con":true,"img":false}]}
{"op":"mcm","clk":"5318486454","pt":1646259102149,"mc":[{"id":"1.195532874","rc":[{"atb":[[1.12,30]],"id":37306244},{"atb":[[1.12,30]],"id":41469398},{"atb":[[1.14,30]],"id":35985721},{"atl":[[500,3]],"id":35985721},{"atb":[[1.12,30]],"id":40642034},{"atb":[[1.12,30]],"id":40883678}],"con":true,"img":false}]}
{"op":"mcm","clk":"5318509069","pt":1646259402465,"mc":[{"id":"1.195532874","marketDefinition":{"bspMarket":true,"turnInPlayEnabled":false,"persistenceEnabled":false,"marketBaseRate":5.0,"eventId":"31275720","eventTypeId":"4339","numberOfWinners":1,"bettingType":"ODDS","marketType":"WIN","marketTime":"2022-03-03T17:28:00.000Z","suspendTime":"2022-03-03T17:28:00.000Z","bspReconciled":false,"complete":true,"inPlay":false,"crossMatching":false,"runnersVoidable":false,"numberOfActiveRunners":6,"betDelay":0,"status":"OPEN","runners":[{"status":"ACTIVE","sortPriority":1,"id":40883678,"name":"1. Kincora For Real"},{"status":"ACTIVE","sortPriority":2,"id":40642034,"name":"2. Maple Patsy"},{"status":"ACTIVE","sortPriority":3,"id":39614765,"name":"3. Puttfor Juney"},{"status":"ACTIVE","sortPriority":4,"id":41469398,"name":"4. Droopys Good One"},{"status":"ACTIVE","sortPriority":5,"id":37306244,"name":"5. Ballyard Hilary"},{"status":"ACTIVE","sortPriority":6,"id":35985721,"name":"6. Waste House Izzy"}],"regulators":["MR_INT"],"venue":"Romford","countryCode":"GB","discountAllowed":true,"timezone":"Europe/London","openDate":"2022-03-03T13:57:00.000Z","version":4384107348,"name":"S1 575m","eventName":"Romford 3rd Mar"},"rc":[{"atb":[[1.12,30]],"id":37306244},{"atl":[[560,3]],"id":37306244},{"spn":280.56,"spf":"NaN","id":37306244},{"atb":[[1.12,30]],"id":41469398},{"atl":[[270,3]],"id":41469398},{"spn":135.56,"spf":"NaN","id":41469398},{"atb":[[1.14,30]],"id":35985721},{"atl":[[500,3]],"id":35985721},{"spn":250.57,"spf":"NaN","id":35985721},{"atb":[[1.12,30]],"id":39614765},{"atl":[[550,3]],"id":39614765},{"spn":275.56,"spf":"NaN","id":39614765},{"atb":[[1.12,30]],"id":40642034},{"atl":[[390,3]],"id":40642034},{"spn":195.56,"spf":"NaN","id":40642034},{"atb":[[1.12,30]],"id":40883678},{"atl":[[370,3]],"id":40883678},{"spn":185.56,"spf":"NaN","id":40883678}],"con":true,"img":true}]}
{"op":"mcm","clk":"5320255942","pt":1646291303216,"mc":[{"id":"1.195532874","rc":[{"atb":[[2.02,8.44]],"id":37306244},{"spn":281.01,"spf":"NaN","id":37306244},{"atb":[[2.02,11.82]],"id":41469398},{"spn":136.01,"spf":"NaN","id":41469398},{"atb":[[2.08,10.43]],"id":35985721},{"spn":251.04,"spf":"NaN","id":35985721},{"atb":[[2.1,11.41]],"id":39614765},{"spn":276.05,"spf":"NaN","id":39614765},{"atb":[[2.02,8.44]],"id":40642034},{"spn":196.01,"spf":"NaN","id":40642034},{"atb":[[2.06,9.47]],"id":40883678},{"spn":186.03,"spf":"NaN","id":40883678}],"con":true,"img":false}]}
{"op":"mcm","clk":"5320538822","pt":1646297202603,"mc":[{"id":"1.195532874","marketDefinition":{"bspMarket":true,"turnInPlayEnabled":false,"persistenceEnabled":false,"marketBaseRate":5.0,"eventId":"31275720","eventTypeId":"4339","numberOfWinners":1,"bettingType":"ODDS","marketType":"WIN","marketTime":"2022-03-03T17:28:00.000Z","suspendTime":"2022-03-03T17:28:00.000Z","bspReconciled":false,"complete":true,"inPlay":false,"crossMatching":false,"runnersVoidable":false,"numberOfActiveRunners":6,"betDelay":0,"status":"OPEN","runners":[{"status":"ACTIVE","sortPriority":1,"id":40883678,"name":"1. Kincora For Real"},{"status":"ACTIVE","sortPriority":2,"id":40642034,"name":"2. Maple Patsy"},{"status":"ACTIVE","sortPriority":3,"id":39614765,"name":"3. Puttfor Juney"},{"status":"ACTIVE","sortPriority":4,"id":41469398,"name":"4. Droopys Good One"},{"status":"ACTIVE","sortPriority":5,"id":37306244,"name":"5. Ballyard Hilary"},{"status":"ACTIVE","sortPriority":6,"id":35985721,"name":"6. Waste House Izzy"}],"regulators":["MR_INT"],"venue":"Romford","countryCode":"GB","discountAllowed":true,"timezone":"Europe/London","openDate":"2022-03-03T13:57:00.000Z","version":4384107348,"name":"S1 575m","eventName":"Romford 3rd Mar"},"rc":[{"atb":[[1.12,30],[2.02,8.45]],"id":37306244},{"atl":[[560,3]],"id":37306244},{"spn":281.01,"spf":"NaN","id":37306244},{"atb":[[1.12,30],[2.02,11.83]],"id":41469398},{"atl":[[270,3]],"id":41469398},{"spn":136.01,"spf":"NaN","id":41469398},{"atb":[[1.12,30],[2.1,11.41]],"id":39614765},{"atl":[[550,3]],"id":39614765},{"spn":276.05,"spf":"NaN","id":39614765},{"atb":[[1.14,30],[2.08,10.43]],"id":35985721},{"atl":[[500,3]],"id":35985721},{"spn":251.04,"spf":"NaN","id":35985721},{"atb":[[1.12,30],[2.02,8.45]],"id":40642034},{"atl":[[390,3]],"id":40642034},{"spn":196.01,"spf":"NaN","id":40642034},{"atb":[[1.12,30],[2.06,9.47]],"id":40883678},{"atl":[[370,3]],"id":40883678},{"spn":186.03,"spf":"NaN","id":40883678}],"con":true,"img":true}]}
{"op":"mcm","clk":"5320739335","pt":1646300935988,"mc":[{"id":"1.195532874","rc":[{"atb":[[2.02,8.45]],"id":37306244},{"spl":[[21,1]],"id":37306244},{"spn":11.51,"spf":1.0,"id":37306244},{"atb":[[2.02,11.83]],"id":41469398},{"spl":[[21,1]],"id":41469398},{"spn":11.51,"spf":1.0,"id":41469398},{"atb":[[2.1,11.41]],"id":39614765},{"spl":[[21,1]],"id":39614765},{"spn":11.55,"spf":1.0,"id":39614765},{"atb":[[2.08,10.43]],"id":35985721},{"spl":[[21,1]],"id":35985721},{"spn":11.54,"spf":1.0,"id":35985721},{"atb":[[2.02,8.45]],"id":40642034},{"spl":[[21,1]],"id":40642034},{"spn":11.51,"spf":1.0,"id":40642034},{"atb":[[2.06,9.47]],"id":40883678},{"spl":[[21,1]],"id":40883678},{"spn":11.53,"spf":1.0,"id":40883678}],"con":true,"img":false}]}
{"op":"mcm","clk":"5320830295","pt":1646302602595,"mc":[{"id":"1.195532874","marketDefinition":{"bspMarket":true,"turnInPlayEnabled":false,"persistenceEnabled":false,"marketBaseRate":5.0,"eventId":"31275720","eventTypeId":"4339","numberOfWinners":1,"bettingType":"ODDS","marketType":"WIN","marketTime":"2022-03-03T17:28:00.000Z","suspendTime":"2022-03-03T17:28:00.000Z","bspReconciled":false,"complete":true,"inPlay":false,"crossMatching":false,"runnersVoidable":false,"numberOfActiveRunners":6,"betDelay":0,"status":"OPEN","runners":[{"status":"ACTIVE","sortPriority":1,"id":40883678,"name":"1. Kincora For Real"},{"status":"ACTIVE","sortPriority":2,"id":40642034,"name":"2. Maple Patsy"},{"status":"ACTIVE","sortPriority":3,"id":39614765,"name":"3. Puttfor Juney"},{"status":"ACTIVE","sortPriority":4,"id":41469398,"name":"4. Droopys Good One"},{"status":"ACTIVE","sortPriority":5,"id":37306244,"name":"5. Ballyard Hilary"},{"status":"ACTIVE","sortPriority":6,"id":35985721,"name":"6. Waste House Izzy"}],"regulators":["MR_INT"],"venue":"Romford","countryCode":"GB","discountAllowed":true,"timezone":"Europe/London","openDate":"2022-03-03T13:57:00.000Z","version":4384107348,"name":"S1 575m","eventName":"Romford 3rd Mar"},"rc":[{"atb":[[1.12,30],[2.02,8.44]],"id":37306244},{"spl":[[21,1]],"id":37306244},{"atl":[[560,3]],"id":37306244},{"spn":11.51,"spf":1.0,"id":37306244},{"atb":[[1.12,30],[2.02,11.82]],"id":41469398},{"spl":[[21,1]],"id":41469398},{"atl":[[270,3]],"id":41469398},{"spn":11.51,"spf":1.0,"id":41469398},{"atb":[[1.14,30],[2.08,10.43]],"id":35985721},{"spl":[[21,1]],"id":35985721},{"atl":[[500,3]],"id":35985721},{"spn":11.54,"spf":1.0,"id":35985721},{"atb":[[1.12,30],[2.1,11.41]],"id":39614765},{"spl":[[21,1]],"id":39614765},{"atl":[[550,3]],"id":39614765},{"spn":11.55,"spf":1.0,"id":39614765},{"atb":[[1.12,30],[2.02,8.44]],"id":40642034},{"spl":[[21,1]],"id":40642034},{"atl":[[390,3]],"id":40642034},{"spn":11.51,"spf":1.0,"id":40642034},{"atb":[[1.12,30],[2.06,9.47]],"id":40883678},{"spl":[[21,1]],"id":40883678},{"atl":[[370,3]],"id":40883678},{"spn":11.53,"spf":1.0,"id":40883678}],"con":true,"img":true}]}
{"op":"mcm","clk":"5321027072","pt":1646305307090,"mc":[{"id":"1.195532874","rc":[{"atb":[[5.6,2],[2.02,8.45]],"id":37306244},{"spn":13.3,"spf":1.0,"id":37306244},{"atb":[[9,2],[2.02,11.83]],"id":41469398},{"spn":15.0,"spf":1.0,"id":41469398},{"atb":[[9,2],[2.08,10.43]],"id":35985721},{"spn":15.0,"spf":1.0,"id":35985721},{"atb":[[5.1,2],[2.1,11.41]],"id":39614765},{"spn":13.05,"spf":1.0,"id":39614765},{"atb":[[2.02,8.45],[3.75,2]],"id":40642034},{"spn":12.37,"spf":1.0,"id":40642034},{"atb":[[4.3,2],[2.06,9.47]],"id":40883678},{"spn":12.65,"spf":1.0,"id":40883678}],"con":true,"img":false}]}
{"op":"mcm","clk":"5321028078","pt":1646305320242,"mc":[{"id":"1.195532874","marketDefinition":{"bspMarket":true,"turnInPlayEnabled":false,"persistenceEnabled":false,"marketBaseRate":5.0,"eventId":"31275720","eventTypeId":"4339","numberOfWinners":1,"bettingType":"ODDS","marketType":"WIN","marketTime":"2022-03-03T17:28:00.000Z","suspendTime":"2022-03-03T17:28:00.000Z","bspReconciled":false,"complete":true,"inPlay":false,"crossMatching":true,"runnersVoidable":false,"numberOfActiveRunners":6,"betDelay":0,"status":"OPEN","runners":[{"status":"ACTIVE","sortPriority":1,"id":40883678,"name":"1. Kincora For Real"},{"status":"ACTIVE","sortPriority":2,"id":40642034,"name":"2. Maple Patsy"},{"status":"ACTIVE","sortPriority":3,"id":39614765,"name":"3. Puttfor Juney"},{"status":"ACTIVE","sortPriority":4,"id":41469398,"name":"4. Droopys Good One"},{"status":"ACTIVE","sortPriority":5,"id":37306244,"name":"5. Ballyard Hilary"},{"status":"ACTIVE","sortPriority":6,"id":35985721,"name":"6. Waste House Izzy"}],"regulators":["MR_INT"],"venue":"Romford","countryCode":"GB","discountAllowed":true,"timezone":"Europe/London","openDate":"2022-03-03T13:57:00.000Z","version":4384107348,"name":"S1 575m","eventName":"Romford 3rd Mar"},"rc":[],"con":true,"img":false}]}
{"op":"mcm","clk":"5321178427","pt":1646306882728,"mc":[{"id":"1.195532874","rc":[{"atb":[[4.6,2]],"id":37306244},{"atl":[[9.4,1.2]],"id":37306244},{"spn":7.5,"spf":1.0,"id":37306244},{"atb":[[6.6,1.8]],"id":41469398},{"atl":[[15.5,0.7]],"id":41469398},{"spn":12.25,"spf":1.0,"id":41469398},{"atb":[[6.6,1.8]],"id":35985721},{"atl":[[15.5,0.7]],"id":35985721},{"spn":12.25,"spf":1.0,"id":35985721},{"atb":[[4.3,2]],"id":39614765},{"atl":[[8.4,1.36]],"id":39614765},{"spn":6.75,"spf":1.0,"id":39614765},{"atb":[[3.3,2]],"id":40642034},{"atl":[[5.6,2]],"id":40642034},{"spn":4.67,"spf":1.0,"id":40642034},{"atb":[[3.8,2]],"id":40883678},{"atl":[[6.8,1.73]],"id":40883678},{"spn":5.55,"spf":1.0,"id":40883678}],"con":true,"img":false}]}
{"op":"mcm","clk":"5321383964","pt":1646309047504,"mc":[{"id":"1.195532874","rc":[{"atl":[[15.5,0]],"id":41469398},{"spn":15.0,"spf":1.0,"id":41469398},{"atl":[[15.5,0]],"id":35985721},{"spn":15.0,"spf":1.0,"id":35985721},{"atl":[[6.8,0]],"id":40883678},{"spn":12.65,"spf":1.0,"id":40883678}],"con":true,"img":false}]}
{"op":"mcm","clk":"5321383973","pt":1646309047605,"mc":[{"id":"1.195532874","rc":[{"atl":[[9.4,0]],"id":37306244},{"atl":[[15,0.72]],"id":35985721},{"atl":[[6.6,1.8]],"id":40883678}],"con":true,"img":false}]}
{"op":"mcm","clk":"5321383981","pt":1646309047711,"mc":[{"id":"1.195532874","rc":[{"atl":[[15,0.72]],"id":41469398}],"con":true,"img":false}]}
{"op":"mcm","clk":"5321383989","pt":1646309047815,"mc":[{"id":"1.195532874","rc":[{"atl":[[9,1.26]],"id":37306244}],"con":true,"img":false}]}
{"op":"mcm","clk":"5321809203","pt":1646313402556,"mc":[{"id":"1.195532874","marketDefinition":{"bspMarket":true,"turnInPlayEnabled":false,"persistenceEnabled":false,"marketBaseRate":5.0,"eventId":"31275720","eventTypeId":"4339","numberOfWinners":1,"bettingType":"ODDS","marketType":"WIN","marketTime":"2022-03-03T17:28:00.000Z","suspendTime":"2022-03-03T17:28:00.000Z","bspReconciled":false,"complete":true,"inPlay":false,"crossMatching":true,"runnersVoidable":false,"numberOfActiveRunners":6,"betDelay":0,"status":"OPEN","runners":[{"status":"ACTIVE","sortPriority":1,"id":40883678,"name":"1. Kincora For Real"},{"status":"ACTIVE","sortPriority":2,"id":40642034,"name":"2. Maple Patsy"},{"status":"ACTIVE","sortPriority":3,"id":39614765,"name":"3. Puttfor Juney"},{"status":"ACTIVE","sortPriority":4,"id":41469398,"name":"4. Droopys Good One"},{"status":"ACTIVE","sortPriority":5,"id":37306244,"name":"5. Ballyard Hilary"},{"status":"ACTIVE","sortPriority":6,"id":35985721,"name":"6. Waste House Izzy"}],"regulators":["MR_INT"],"venue":"Romford","countryCode":"GB","discountAllowed":true,"timezone":"Europe/London","openDate":"2022-03-03T13:57:00.000Z","version":4384107348,"name":"S1 575m","eventName":"Romford 3rd Mar"},"rc":[{"atb":[[5.6,2],[1.12,30],[2.02,8.44],[4.6,2]],"id":37306244},{"spl":[[21,1]],"id":37306244},{"atl":[[560,3],[9,1.26]],"id":37306244},{"spn":7.3,"spf":1.0,"id":37306244},{"atb":[[1.12,30],[9,2],[2.02,11.82],[6.6,1.8]],"id":41469398},{"spl":[[21,1]],"id":41469398},{"atl":[[270,3],[15,0.72]],"id":41469398},{"spn":12.0,"spf":1.0,"id":41469398},{"atb":[[9,2],[1.14,30],[6.6,1.8],[2.08,10.43]],"id":35985721},{"spl":[[21,1]],"id":35985721},{"atl":[[15,0.72],[500,3]],"id":35985721},{"spn":12.0,"spf":1.0,"id":35985721},{"atb":[[1.12,30],[5.1,2],[4.3,2],[2.1,11.4]],"id":39614765},{"spl":[[21,1]],"id":39614765},{"atl":[[550,3],[8.4,1.36]],"id":39614765},{"spn":6.75,"spf":1.0,"id":39614765},{"atb":[[1.12,30],[2.02,8.44],[3.3,2],[3.75,2]],"id":40642034},{"spl":[[21,1]],"id":40642034},{"atl":[[5.6,2],[390,3]],"id":40642034},{"spn":4.67,"spf":1.0,"id":40642034},{"atb":[[1.12,30],[4.3,2],[2.06,9.47],[3.8,2]],"id":40883678},{"spl":[[21,1]],"id":40883678},{"atl":[[370,3],[6.6,1.8]],"id":40883678},{"spn":5.45,"spf":1.0,"id":40883678}],"con":true,"img":true}]}
{"op":"mcm","clk":"5321848567","pt":1646313729584,"mc":[{"id":"1.195532874","rc":[{"atb":[[2.02,8.44]],"id":37306244},{"spn":7.3,"spf":1.0,"id":37306244},{"atb":[[2.02,11.82]],"id":41469398},{"atl":[[1000,2]],"id":41469398},{"spn":12.0,"spf":1.0,"id":41469398},{"atb":[[2.08,10.43]],"id":35985721},{"spn":12.0,"spf":1.0,"id":35985721},{"atb":[[2.1,11.4]],"id":39614765},{"atb":[[2.02,8.44]],"id":40642034},{"atb":[[2.06,9.47]],"id":40883678},{"spn":5.45,"spf":1.0,"id":40883678}],"con":true,"img":false}]}
{"op":"mcm","clk":"5321848697","pt":1646313730884,"mc":[{"id":"1.195532874","rc":[{"atl":[[1000,2.2]],"id":41469398}],"con":true,"img":false}]}
{"op":"mcm","clk":"5321848866","pt":1646313732183,"mc":[{"id":"1.195532874","rc":[{"atl":[[1000,2]],"id":41469398}],"con":true,"img":false}]}
{"op":"mcm","clk":"5321848873","pt":1646313732289,"mc":[{"id":"1.195532874","rc":[{"atl":[[18,0.2]],"id":41469398}],"con":true,"img":false}]}
{"op":"mcm","clk":"5321853507","pt":1646313778721,"mc":[{"id":"1.195532874","rc":[{"atl":[[1000,2]],"id":37306244}],"con":true,"img":false}]}
{"op":"mcm","clk":"5321853630","pt":1646313780013,"mc":[{"id":"1.195532874","rc":[{"atl":[[1000,2.2]],"id":37306244}],"con":true,"img":false}]}
{"op":"mcm","clk":"5321853734","pt":1646313781218,"mc":[{"id":"1.195532874","rc":[{"atl":[[1000,2]],"id":37306244}],"con":true,"img":false}]}
{"op":"mcm","clk":"5321853745","pt":1646313781316,"mc":[{"id":"1.195532874","rc":[{"atl":[[12,0.2]],"id":37306244}],"con":true,"img":false}]}
{"op":"mcm","clk":"5321853884","pt":1646313782619,"mc":[{"id":"1.195532874","rc":[{"atl":[[1000,2]],"id":35985721}],"con":true,"img":false}]}
{"op":"mcm","clk":"5321854027","pt":1646313783917,"mc":[{"id":"1.195532874","rc":[{"atl":[[1000,2.2]],"id":35985721}],"con":true,"img":false}]}
{"op":"mcm","clk":"5321854159","pt":1646313785220,"mc":[{"id":"1.195532874","rc":[{"atl":[[1000,2]],"id":35985721}],"con":true,"img":false}]}
{"op":"mcm","clk":"5321854164","pt":1646313785326,"mc":[{"id":"1.195532874","rc":[{"atl":[[18,0.2]],"id":35985721}],"con":true,"img":false}]}
{"op":"mcm","clk":"5321870497","pt":1646313962066,"mc":[{"id":"1.195532874","rc":[{"atl":[[1000,0.5]],"id":40883678}],"con":true,"img":false}]}
{"op":"mcm","clk":"5321870510","pt":1646313962273,"mc":[{"id":"1.195532874","rc":[{"atl":[[1000,0]],"id":40883678}],"con":true,"img":false}]}
{"op":"mcm","clk":"5321870517","pt":1646313962376,"mc":[{"id":"1.195532874","rc":[{"atb":[[4.3,1.5]],"id":40883678},{"trd":[[4.3,1]],"ltp":4.3,"tv":1.0,"id":40883678}],"con":true,"img":false}]}
{"op":"mcm","clk":"5321870580","pt":1646313962854,"mc":[{"id":"1.195532874","rc":[{"atb":[[4.3,3.5]],"id":40883678}],"con":true,"img":false}]}
{"op":"mcm","clk":"5321870589","pt":1646313962961,"mc":[{"id":"1.195532874","rc":[{"atb":[[4.3,2]],"id":40883678}],"con":true,"img":false}]}
{"op":"mcm","clk":"5321896896","pt":1646314285650,"mc":[{"id":"1.195532874","rc":[{"atb":[[4.3,0]],"id":40883678},{"atl":[[4.3,13]],"id":40883678},{"trd":[[4.3,5]],"ltp":4.3,"tv":5.0,"id":40883678},{"spn":4.05,"spf":1.0,"id":40883678}],"con":true,"img":false}]}
{"op":"mcm","clk":"5321896906","pt":1646314285804,"mc":[{"id":"1.195532874","rc":[{"atb":[[3.8,0]],"id":40883678},{"atl":[[4.3,16.36]],"id":40883678}],"con":true,"img":false}]}
{"op":"mcm","clk":"5321896913","pt":1646314285907,"mc":[{"id":"1.195532874","rc":[{"atb":[[2.08,2]],"id":40883678}],"con":true,"img":false}]}
{"op":"mcm","clk":"5321896921","pt":1646314286011,"mc":[{"id":"1.195532874","rc":[{"atb":[[1.69,2]],"id":40883678}],"con":true,"img":false}]}
{"op":"mcm","clk":"5321897136","pt":1646314288785,"mc":[{"id":"1.195532874","rc":[{"atb":[[3.5,4.48]],"id":41469398},{"atb":[[2.5,7.47]],"id":40642034}],"con":true,"img":false}]}
{"op":"mcm","clk":"5321897142","pt":1646314288888,"mc":[{"id":"1.195532874","rc":[{"atb":[[2.94,5.77]],"id":39614765}],"con":true,"img":false}]}
{"op":"mcm","clk":"5321897150","pt":1646314288994,"mc":[{"id":"1.195532874","rc":[{"atb":[[3,5.6]],"id":37306244},{"atb":[[3.5,4.48]],"id":35985721}],"con":true,"img":false}]}
{"op":"mcm","clk":"5321898699","pt":1646314310509,"mc":[{"id":"1.195532874","rc":[{"atl":[[4.3,3.36]],"id":40883678}],"con":true,"img":false}]}
{"op":"mcm","clk":"5321898706","pt":1646314310612,"mc":[{"id":"1.195532874","rc":[{"atl":[[3.5,13]],"id":40883678}],"con":true,"img":false}]}
{"op":"mcm","clk":"5321898712","pt":1646314310717,"mc":[{"id":"1.195532874","rc":[{"atl":[[4.3,0]],"id":40883678}],"con":true,"img":false}]}
{"op":"mcm","clk":"5321898720","pt":1646314310818,"mc":[{"id":"1.195532874","rc":[{"atl":[[4.1,3.53]],"id":40883678}],"con":true,"img":false}]}
{"op":"mcm","clk":"5321899092","pt":1646314315997,"mc":[{"id":"1.195532874","rc":[{"atb":[[2.22,5.51]],"id":40883678}],"con":true,"img":false}]}
{"op":"mcm","clk":"5321899115","pt":1646314316309,"mc":[{"id":"1.195532874","rc":[{"atb":[[2.08,0]],"id":40883678}],"con":true,"img":false}]}
{"op":"mcm","clk":"5321899131","pt":1646314316519,"mc":[{"id":"1.195532874","rc":[{"atb":[[2.24,2]],"id":40883678}],"con":true,"img":false}]}
{"op":"mcm","clk":"5321899842","pt":1646314325018,"mc":[{"id":"1.195532874","rc":[{"spl":[[1.01,3]],"id":40883678}],"con":true,"img":false}]}
{"op":"mcm","clk":"5321901061","pt":1646314340131,"mc":[{"id":"1.195532874","rc":[{"atb":[[2.9,3.54]],"id":40642034}],"con":true,"img":false}]}
{"op":"mcm","clk":"5321905950","pt":1646314398706,"mc":[{"id":"1.195532874","rc":[{"atb":[[2.06,0]],"id":40883678},{"spn":2.23,"spf":1.0,"id":40883678}],"con":true,"img":false}]}
{"op":"mcm","clk":"5321905961","pt":1646314398810,"mc":[{"id":"1.195532874","rc":[{"atb":[[2.24,11.47]],"id":40883678}],"con":true,"img":false}]}
{"op":"mcm","clk":"5321906109","pt":1646314400212,"mc":[{"id":"1.195532874","rc":[{"atb":[[3.5,4.96]],"id":39614765}],"con":true,"img":false}]}
{"op":"mcm","clk":"5321906171","pt":1646314400885,"mc":[{"id":"1.195532874","rc":[{"atb":[[2.88,6.6]],"id":40642034}],"con":true,"img":false}]}
{"op":"mcm","clk":"5321906194","pt":1646314401197,"mc":[{"id":"1.195532874","rc":[{"atb":[[4.3,3.76]],"id":41469398},{"atb":[[4.3,3.76]],"id":35985721}],"con":true,"img":false}]}
{"op":"mcm","clk":"5321906218","pt":1646314401508,"mc":[{"id":"1.195532874","rc":[{"atb":[[3.6,4.77]],"id":37306244}],"con":true,"img":false}]}
{"op":"mcm","clk":"5321906664","pt":1646314406323,"mc":[{"id":"1.195532874","rc":[{"atb":[[2.22,0]],"id":40883678}],"con":true,"img":false}]}
{"op":"mcm","clk":"5321906983","pt":1646314409895,"mc":[{"id":"1.195532874","rc":[{"atb":[[2.9,0]],"id":40642034}],"con":true,"img":false}]}
{"op":"mcm","clk":"5321908469","pt":1646314427367,"mc":[{"id":"1.195532874","rc":[{"atb":[[2.28,5.25]],"id":40883678}],"con":true,"img":false}]}
{"op":"mcm","clk":"5321908514","pt":1646314427824,"mc":[{"id":"1.195532874","rc":[{"atb":[[2.24,9.47]],"id":40883678}],"con":true,"img":false}]}
{"op":"mcm","clk":"5321908521","pt":1646314427921,"mc":[{"id":"1.195532874","rc":[{"atb":[[2.3,2]],"id":40883678}],"con":true,"img":false}]}
{"op":"mcm","clk":"5321908792","pt":1646314430942,"mc":[{"id":"1.195532874","rc":[{"atb":[[2.94,3.46]],"id":40642034}],"con":true,"img":false}]}
{"op":"mcm","clk":"5321913429","pt":1646314481600,"mc":[{"id":"1.195532874","rc":[{"atb":[[2.32,7.51]],"id":40883678},{"spn":2.32,"spf":1.0,"id":40883678}],"con":true,"img":false}]}
{"op":"mcm","clk":"5321913471","pt":1646314481907,"mc":[{"id":"1.195532874","rc":[{"atb":[[3,4.95]],"id":40642034}],"con":true,"img":false}]}
{"op":"mcm","clk":"5321914658","pt":1646314493812,"mc":[{"id":"1.195532874","rc":[{"atb":[[2.94,0]],"id":40642034},{"atb":[[2.28,0]],"id":40883678}],"con":true,"img":false}]}
{"op":"mcm","clk":"5321916463","pt":1646314510138,"mc":[{"id":"1.195532874","rc":[{"atb":[[3,0]],"id":40642034},{"atb":[[2.32,0]],"id":40883678}],"con":true,"img":false}]}
{"op":"mcm","clk":"5321918277","pt":1646314526160,"mc":[{"id":"1.195532874","rc":[{"atb":[[2.9,5.22]],"id":40642034}],"con":true,"img":false}]}
{"op":"mcm","clk":"5321918286","pt":1646314526265,"mc":[{"id":"1.195532874","rc":[{"atb":[[2.28,7.74]],"id":40883678}],"con":true,"img":false}]}
{"op":"mcm","clk":"5321920168","pt":1646314544679,"mc":[{"id":"1.195532874","rc":[{"atb":[[3,0]],"id":37306244},{"atb":[[3.5,0]],"id":41469398},{"atb":[[3.5,0]],"id":35985721},{"atb":[[2.94,0]],"id":39614765},{"atb":[[2.5,0]],"id":40642034},{"spn":2.29,"spf":1.0,"id":40883678}],"con":true,"img":false}]}
{"op":"mcm","clk":"5321920498","pt":1646314547973,"mc":[{"id":"1.195532874","rc":[{"atb":[[2.88,12.57]],"id":40642034}],"con":true,"img":false}]}
{"op":"mcm","clk":"5321920518","pt":1646314548177,"mc":[{"id":"1.195532874","rc":[{"atb":[[3.5,9.45]],"id":39614765}],"con":true,"img":false}]}
{"op":"mcm","clk":"5321920531","pt":1646314548283,"mc":[{"id":"1.195532874","rc":[{"atb":[[4.5,3.2]],"id":41469398}],"con":true,"img":false}]}
{"op":"mcm","clk":"5321920543","pt":1646314548386,"mc":[{"id":"1.195532874","rc":[{"atb":[[3.7,4.15]],"id":37306244}],"con":true,"img":false}]}
{"op":"mcm","clk":"5321920564","pt":1646314548593,"mc":[{"id":"1.195532874","rc":[{"atb":[[4.5,3.2]],"id":35985721}],"con":true,"img":false}]}
{"op":"mcm","clk":"5321921318","pt":1646314556591,"mc":[{"id":"1.195532874","rc":[{"atb":[[2.32,5.09]],"id":40883678}],"con":true,"img":false}]}
{"op":"mcm","clk":"5321921339","pt":1646314556796,"mc":[{"id":"1.195532874","rc":[{"atb":[[2.96,3.43]],"id":40642034}],"con":true,"img":false}]}
{"op":"mcm","clk":"5321922254","pt":1646314565308,"mc":[{"id":"1.195532874","rc":[{"atb":[[2.9,0]],"id":40642034}],"con":true,"img":false}]}
{"op":"mcm","clk":"5321922895","pt":1646314571930,"mc":[{"id":"1.195532874","rc":[{"atb":[[2.96,0]],"id":40642034}],"con":true,"img":false}]}
{"op":"mcm","clk":"5321923456","pt":1646314576947,"mc":[{"id":"1.195532874","rc":[{"atb":[[2.28,0]],"id":40883678}],"con":true,"img":false}]}
{"op":"mcm","clk":"5321924231","pt":1646314583748,"mc":[{"id":"1.195532874","rc":[{"atb":[[2.32,0]],"id":40883678}],"con":true,"img":false}]}
{"op":"mcm","clk":"5321925091","pt":1646314592568,"mc":[{"id":"1.195532874","rc":[{"atb":[[2.94,3.46]],"id":40642034}],"con":true,"img":false}]}
{"op":"mcm","clk":"5321926313","pt":1646314604748,"mc":[{"id":"1.195532874","rc":[{"atb":[[2.28,5.25]],"id":40883678}],"con":true,"img":false}]}
{"op":"mcm","clk":"5321929510","pt":1646314633629,"mc":[{"id":"1.195532874","rc":[{"atb":[[3,4.95]],"id":40642034}],"con":true,"img":false}]}
{"op":"mcm","clk":"5321930759","pt":1646314644750,"mc":[{"id":"1.195532874","rc":[{"atb":[[2.94,0]],"id":40642034}],"con":true,"img":false}]}
{"op":"mcm","clk":"5321931354","pt":1646314650148,"mc":[{"id":"1.195532874","rc":[{"atb":[[2.32,7.51]],"id":40883678}],"con":true,"img":false}]}
{"op":"mcm","clk":"5321932681","pt":1646314662246,"mc":[{"id":"1.195532874","rc":[{"atb":[[3.05,3.28]],"id":40642034}],"con":true,"img":false}]}
{"op":"mcm","clk":"5321932728","pt":1646314662654,"mc":[{"id":"1.195532874","rc":[{"atb":[[2.28,0]],"id":40883678}],"con":true,"img":false}]}
{"op":"mcm","clk":"5321933232","pt":1646314667239,"mc":[{"id":"1.195532874","rc":[{"atb":[[3,0]],"id":40642034},{"spn":2.32,"spf":1.0,"id":40883678}],"con":true,"img":false}]}
{"op":"mcm","clk":"5321934086","pt":1646314674355,"mc":[{"id":"1.195532874","rc":[{"atb":[[3.05,0]],"id":40642034}],"con":true,"img":false}]}
{"op":"mcm","clk":"5321935232","pt":1646314683542,"mc":[{"id":"1.195532874","rc":[{"atb":[[2.36,4.94]],"id":40883678}],"con":true,"img":false}]}
{"op":"mcm","clk":"5321935276","pt":1646314683831,"mc":[{"id":"1.195532874","rc":[{"atb":[[2.3,0]],"id":40883678}],"con":true,"img":false}]}
{"op":"mcm","clk":"5321935293","pt":1646314684014,"mc":[{"id":"1.195532874","rc":[{"atb":[[2.38,2]],"id":40883678}],"con":true,"img":false}]}
{"op":"mcm","clk":"5321935456","pt":1646314685430,"mc":[{"id":"1.195532874","rc":[{"atb":[[2.32,0]],"id":40883678}],"con":true,"img":false}]}
{"op":"mcm","clk":"5321936576","pt":1646314695552,"mc":[{"id":"1.195532874","rc":[{"atb":[[2.36,0]],"id":40883678}],"con":true,"img":false}]}
{"op":"mcm","clk":"5321936603","pt":1646314695764,"mc":[{"id":"1.195532874","rc":[{"atb":[[2.94,3.46]],"id":40642034}],"con":true,"img":false}]}
{"op":"mcm","clk":"5321936645","pt":1646314696133,"mc":[{"id":"1.195532874","rc":[{"atb":[[2.24,0]],"id":40883678}],"con":true,"img":false}]}
{"op":"mcm","clk":"5321936655","pt":1646314696233,"mc":[{"id":"1.195532874","rc":[{"atb":[[2.34,9.47]],"id":40883678}],"con":true,"img":false}]}
{"op":"mcm","clk":"5321940029","pt":1646314725580,"mc":[{"id":"1.195532874","rc":[{"atb":[[2.38,6.87]],"id":40883678}],"con":true,"img":false}]}
{"op":"mcm","clk":"5321940993","pt":1646314735211,"mc":[{"id":"1.195532874","rc":[{"atb":[[3,4.95]],"id":40642034},{"spn":2.38,"spf":1.0,"id":40883678}],"con":true,"img":false}]}
{"op":"mcm","clk":"5321942001","pt":1646314743898,"mc":[{"id":"1.195532874","rc":[{"atb":[[2.94,0]],"id":40642034}],"con":true,"img":false}]}
{"op":"mcm","clk":"5321944003","pt":1646314761535,"mc":[{"id":"1.195532874","rc":[{"atb":[[2.42,6.98]],"id":40883678}],"con":true,"img":false}]}
{"op":"mcm","clk":"5321944052","pt":1646314761911,"mc":[{"id":"1.195532874","rc":[{"atb":[[2.38,4.87]],"id":40883678}],"con":true,"img":false}]}
{"op":"mcm","clk":"5321944072","pt":1646314762112,"mc":[{"id":"1.195532874","rc":[{"atb":[[2.44,2]],"id":40883678}],"con":true,"img":false}]}
{"op":"mcm","clk":"5321944099","pt":1646314762319,"mc":[{"id":"1.195532874","rc":[{"atb":[[3,0]],"id":40642034}],"con":true,"img":false}]}
{"op":"mcm","clk":"5321945012","pt":1646314770297,"mc":[{"id":"1.195532874","rc":[{"atb":[[2.38,0]],"id":40883678}],"con":true,"img":false}]}
{"op":"mcm","clk":"5321947074","pt":1646314787581,"mc":[{"id":"1.195532874","rc":[{"atb":[[2.42,0]],"id":40883678}],"con":true,"img":false}]}
{"op":"mcm","clk":"5321947100","pt":1646314787780,"mc":[{"id":"1.195532874","rc":[{"atb":[[3.6,0]],"id":37306244},{"atb":[[4.3,0]],"id":41469398},{"atb":[[4.3,0]],"id":35985721}],"con":true,"img":false}]}
{"op":"mcm","clk":"5321948698","pt":1646314801362,"mc":[{"id":"1.195532874","rc":[{"atb":[[3.8,4.43]],"id":37306244},{"atb":[[4.7,3.35]],"id":35985721},{"spn":2.4,"spf":1.0,"id":40883678}],"con":true,"img":false}]}
{"op":"mcm","clk":"5321948742","pt":1646314801774,"mc":[{"id":"1.195532874","rc":[{"atb":[[4.7,3.35]],"id":41469398}],"con":true,"img":false}]}
{"op":"mcm","clk":"5321958409","pt":1646314893628,"mc":[{"id":"1.195532874","rc":[{"atb":[[5.6,0],[5.5,2]],"id":37306244},{"spn":7.25,"spf":1.0,"id":37306244},{"atb":[[9,0],[9.8,2]],"id":41469398},{"spn":12.4,"spf":1.0,"id":41469398},{"atb":[[9,0],[9.8,2]],"id":35985721},{"spn":12.4,"spf":1.0,"id":35985721},{"atb":[[5.1,0],[5,2]],"id":39614765},{"spn":6.7,"spf":1.0,"id":39614765},{"atb":[[3.7,2],[3.75,0]],"id":40642034},{"spn":4.65,"spf":1.0,"id":40642034}],"con":true,"img":false}]}
{"op":"mcm","clk":"5321970626","pt":1646315019980,"mc":[{"id":"1.195532874","rc":[{"atb":[[3.7,0]],"id":37306244},{"atb":[[4.5,0]],"id":41469398},{"atb":[[4.5,0]],"id":35985721}],"con":true,"img":false}]}
{"op":"mcm","clk":"5321970917","pt":1646315023106,"mc":[{"id":"1.195532874","rc":[{"atb":[[3.6,4.31]],"id":37306244}],"con":true,"img":false}]}
{"op":"mcm","clk":"5321973516","pt":1646315049635,"mc":[{"id":"1.195532874","rc":[{"atl":[[15,0]],"id":35985721},{"atl":[[8.4,0]],"id":39614765}],"con":true,"img":false}]}
{"op":"mcm","clk":"5321973529","pt":1646315049841,"mc":[{"id":"1.195532874","rc":[{"atl":[[8.2,1.4]],"id":39614765},{"atl":[[14.5,0.75]],"id":35985721}],"con":true,"img":false}]}
{"op":"mcm","clk":"5321973566","pt":1646315050257,"mc":[{"id":"1.195532874","rc":[{"atb":[[1.58,19.33]],"id":40883678}],"con":true,"img":false}]}
{"op":"mcm","clk":"5321973886","pt":1646315052650,"mc":[{"id":"1.195532874","rc":[{"atb":[[1.6,20.69]],"id":40883678}],"con":true,"img":false}]}
{"op":"mcm","clk":"5321981997","pt":1646315127782,"mc":[{"id":"1.195532874","rc":[{"atl":[[1000,12]],"id":37306244},{"atl":[[1000,12]],"id":41469398},{"atl":[[1000,10]],"id":39614765},{"spn":6.6,"spf":1.0,"id":39614765},{"atl":[[1000,12]],"id":35985721},{"spn":12.15,"spf":1.0,"id":35985721},{"atl":[[1000,10]],"id":40642034},{"atl":[[1000,10]],"id":40883678}],"con":true,"img":false}]}
{"op":"mcm","clk":"5321982065","pt":1646315128310,"mc":[{"id":"1.195532874","rc":[{"atb":[[1.01,1000]],"id":37306244},{"atb":[[1.01,1000]],"id":41469398},{"atb":[[1.01,1000]],"id":39614765},{"atb":[[1.01,1000]],"id":35985721},{"atb":[[1.01,1000]],"id":40642034},{"atb":[[1.01,1000]],"id":40883678}],"con":true,"img":false}]}
{"op":"mcm","clk":"5321983577","pt":1646315141894,"mc":[{"id":"1.195532874","rc":[{"atb":[[3.8,0]],"id":37306244}],"con":true,"img":false}]}
{"op":"mcm","clk":"5321985146","pt":1646315156626,"mc":[{"id":"1.195532874","rc":[{"atb":[[3.7,4.6]],"id":37306244}],"con":true,"img":false}]}
{"op":"mcm","clk":"5321995899","pt":1646315258990,"mc":[{"id":"1.195532874","rc":[{"atb":[[4.7,0]],"id":41469398},{"atb":[[4.7,0]],"id":35985721}],"con":true,"img":false}]}
{"op":"mcm","clk":"5321996120","pt":1646315260704,"mc":[{"id":"1.195532874","rc":[{"atb":[[4.4,3.29]],"id":41469398}],"con":true,"img":false}]}
{"op":"mcm","clk":"5321996146","pt":1646315260911,"mc":[{"id":"1.195532874","rc":[{"atb":[[4.4,3.29]],"id":35985721}],"con":true,"img":false}]}
{"op":"mcm","clk":"5321997770","pt":1646315274622,"mc":[{"id":"1.195532874","rc":[{"atb":[[4.6,3.45]],"id":41469398},{"atb":[[4.6,3.45]],"id":35985721}],"con":true,"img":false}]}
{"op":"mcm","clk":"5321998597","pt":1646315281578,"mc":[{"id":"1.195532874","rc":[{"atb":[[3.6,0]],"id":37306244},{"atb":[[3.5,4.96]],"id":39614765},{"atb":[[2.88,6.6]],"id":40642034}],"con":true,"img":false}]}
{"op":"mcm","clk":"5321998992","pt":1646315284858,"mc":[{"id":"1.195532874","rc":[{"atb":[[1.58,0]],"id":40883678}],"con":true,"img":false}]}
{"op":"mcm","clk":"5321999023","pt":1646315285064,"mc":[{"id":"1.195532874","rc":[{"atb":[[2.14,9.83]],"id":39614765},{"atb":[[2.06,10.57]],"id":40642034}],"con":true,"img":false}]}
{"op":"mcm","clk":"5321999048","pt":1646315285219,"mc":[{"id":"1.195532874","rc":[{"atb":[[3.65,4.23]],"id":37306244}],"con":true,"img":false}]}
{"op":"mcm","clk":"5321999535","pt":1646315289140,"mc":[{"id":"1.195532874","rc":[{"atb":[[1.62,18.08]],"id":40883678}],"con":true,"img":false}]}
{"op":"mcm","clk":"5321999630","pt":1646315289882,"mc":[{"id":"1.195532874","rc":[{"atb":[[3.5,0]],"id":39614765},{"atb":[[2.88,0]],"id":40642034}],"con":true,"img":false}]}
{"op":"mcm","clk":"5322001327","pt":1646315303161,"mc":[{"id":"1.195532874","rc":[{"atb":[[2.18,10.52]],"id":39614765},{"atb":[[2.1,11.29]],"id":40642034}],"con":true,"img":false}]}
{"op":"mcm","clk":"5322022624","pt":1646315507562,"mc":[{"id":"1.195532874","rc":[{"atb":[[4.4,0]],"id":41469398},{"atb":[[4.4,0]],"id":35985721}],"con":true,"img":false}]}
{"op":"mcm","clk":"5322022934","pt":1646315510835,"mc":[{"id":"1.195532874","rc":[{"atb":[[4.8,2.95]],"id":41469398}],"con":true,"img":false}]}
{"op":"mcm","clk":"5322022939","pt":1646315510940,"mc":[{"id":"1.195532874","rc":[{"atb":[[4.8,2.95]],"id":35985721}],"con":true,"img":false}]}
{"op":"mcm","clk":"5322024007","pt":1646315523164,"mc":[{"id":"1.195532874","rc":[{"atb":[[3.7,0]],"id":37306244},{"atb":[[1.6,0]],"id":40883678}],"con":true,"img":false}]}
{"op":"mcm","clk":"5322025406","pt":1646315537547,"mc":[{"id":"1.195532874","rc":[{"atb":[[2.14,0]],"id":39614765},{"atb":[[2.06,0]],"id":40642034}],"con":true,"img":false}]}
{"op":"mcm","clk":"5322025566","pt":1646315539257,"mc":[{"id":"1.195532874","rc":[{"atb":[[1.64,19.4]],"id":40883678}],"con":true,"img":false}]}
{"op":"mcm","clk":"5322025593","pt":1646315539513,"mc":[{"id":"1.195532874","rc":[{"atb":[[3.75,4.51]],"id":37306244}],"con":true,"img":false}]}
{"op":"mcm","clk":"5322025675","pt":1646315540545,"mc":[{"id":"1.195532874","rc":[{"atb":[[2.22,9.19]],"id":39614765},{"atb":[[2.14,9.83]],"id":40642034}],"con":true,"img":false}]}
{"op":"mcm","clk":"5322030129","pt":1646315594604,"mc":[{"id":"1.195532874","rc":[{"atb":[[2.1,0]],"id":39614765},{"atb":[[2.02,0]],"id":40642034}],"con":true,"img":false}]}
{"op":"mcm","clk":"5322030138","pt":1646315594713,"mc":[{"id":"1.195532874","rc":[{"atb":[[2.24,11.4]],"id":39614765},{"atb":[[2.16,8.44]],"id":40642034}],"con":true,"img":false}]}
{"op":"mcm","clk":"5322042657","pt":1646315742527,"mc":[{"id":"1.195532874","rc":[{"atb":[[4.6,0]],"id":41469398},{"atb":[[4.6,0]],"id":35985721}],"con":true,"img":false}]}
{"op":"mcm","clk":"5322043908","pt":1646315757929,"mc":[{"id":"1.195532874","rc":[{"atb":[[1.62,0]],"id":40883678}],"con":true,"img":false}]}
{"op":"mcm","clk":"5322044069","pt":1646315760054,"mc":[{"id":"1.195532874","rc":[{"atb":[[1.66,16.99]],"id":40883678}],"con":true,"img":false}]}
{"op":"mcm","clk":"5322045911","pt":1646315780580,"mc":[{"id":"1.195532874","rc":[{"atb":[[2.18,0]],"id":39614765},{"atb":[[2.1,0]],"id":40642034}],"con":true,"img":false}]}
{"op":"mcm","clk":"5322046964","pt":1646315793705,"mc":[{"id":"1.195532874","rc":[{"atb":[[2.2,10.34]],"id":40642034}],"con":true,"img":false}]}
{"op":"mcm","clk":"5322046989","pt":1646315793985,"mc":[{"id":"1.195532874","rc":[{"atb":[[2.28,9.7]],"id":39614765}],"con":true,"img":false}]}
{"op":"mcm","clk":"5322050135","pt":1646315829044,"mc":[{"id":"1.195532874","rc":[{"atb":[[2.22,0]],"id":39614765},{"atb":[[2.14,0]],"id":40642034}],"con":true,"img":false}]}
{"op":"mcm","clk":"5322050402","pt":1646315832254,"mc":[{"id":"1.195532874","rc":[{"atb":[[2.24,9.04]],"id":40642034}],"con":true,"img":false}]}
{"op":"mcm","clk":"5322050419","pt":1646315832456,"mc":[{"id":"1.195532874","rc":[{"atb":[[2.32,8.49]],"id":39614765}],"con":true,"img":false}]}
{"op":"mcm","clk":"5322053357","pt":1646315869265,"mc":[{"id":"1.195532874","rc":[{"atb":[[6.6,0]],"id":41469398},{"atl":[[3.8,3.8]],"id":40883678}],"con":true,"img":false}]}
{"op":"mcm","clk":"5322053364","pt":1646315869370,"mc":[{"id":"1.195532874","rc":[{"atb":[[7.2,1.62]],"id":41469398},{"atl":[[4.1,0]],"id":40883678}],"con":true,"img":false}]}
{"op":"mcm","clk":"5322055339","pt":1646315894278,"mc":[{"id":"1.195532874","rc":[{"atb":[[2.24,0]],"id":39614765},{"atb":[[2.16,0]],"id":40642034}],"con":true,"img":false}]}
{"op":"mcm","clk":"5322055348","pt":1646315894383,"mc":[{"id":"1.195532874","rc":[{"atb":[[2.34,11.4]],"id":39614765},{"atb":[[2.26,8.44]],"id":40642034}],"con":true,"img":false}]}
{"op":"mcm","clk":"5322061916","pt":1646315976654,"mc":[{"id":"1.195532874","rc":[{"atb":[[4.8,0]],"id":41469398},{"atb":[[4.8,0]],"id":35985721}],"con":true,"img":false}]}
{"op":"mcm","clk":"5322062115","pt":1646315979245,"mc":[{"id":"1.195532874","rc":[{"atb":[[4.4,3.29]],"id":41469398}],"con":true,"img":false}]}
{"op":"mcm","clk":"5322062133","pt":1646315979454,"mc":[{"id":"1.195532874","rc":[{"atb":[[4.4,3.29]],"id":35985721}],"con":true,"img":false}]}
{"op":"mcm","clk":"5322062383","pt":1646315982071,"mc":[{"id":"1.195532874","rc":[{"atb":[[4.6,3.45]],"id":41469398}],"con":true,"img":false}]}
{"op":"mcm","clk":"5322062418","pt":1646315982361,"mc":[{"id":"1.195532874","rc":[{"atb":[[4.6,3.45]],"id":35985721}],"con":true,"img":false}]}
{"op":"mcm","clk":"5322065393","pt":1646316006768,"mc":[{"id":"1.195532874","rc":[{"atb":[[1.64,0]],"id":40883678}],"con":true,"img":false}]}
{"op":"mcm","clk":"5322066583","pt":1646316019312,"mc":[{"id":"1.195532874","rc":[{"atb":[[1.68,18.26]],"id":40883678}],"con":true,"img":false}]}
{"op":"mcm","clk":"5322072237","pt":1646316086127,"mc":[{"id":"1.195532874","rc":[{"atb":[[2.28,0]],"id":39614765},{"atb":[[2.2,0]],"id":40642034}],"con":true,"img":false}]}
{"op":"mcm","clk":"5322073895","pt":1646316101646,"mc":[{"id":"1.195532874","rc":[{"atb":[[2.38,8.99]],"id":39614765}],"con":true,"img":false}]}
{"op":"mcm","clk":"5322073903","pt":1646316101752,"mc":[{"id":"1.195532874","rc":[{"atb":[[2.3,9.55]],"id":40642034}],"con":true,"img":false}]}
{"op":"mcm","clk":"5322076615","pt":1646316129817,"mc":[{"id":"1.195532874","rc":[{"atb":[[2.32,0]],"id":39614765},{"atb":[[2.24,0]],"id":40642034}],"con":true,"img":false}]}
{"op":"mcm","clk":"5322076870","pt":1646316132630,"mc":[{"id":"1.195532874","rc":[{"atb":[[2.42,7.89]],"id":39614765}],"con":true,"img":false}]}
{"op":"mcm","clk":"5322076877","pt":1646316132734,"mc":[{"id":"1.195532874","rc":[{"atb":[[2.34,8.36]],"id":40642034}],"con":true,"img":false}]}
{"op":"mcm","clk":"5322082043","pt":1646316194232,"mc":[{"id":"1.195532874","rc":[{"atb":[[2.26,0]],"id":40642034}],"con":true,"img":false}]}
{"op":"mcm","clk":"5322082046","pt":1646316194287,"mc":[{"id":"1.195532874","rc":[{"atb":[[2.36,8.44]],"id":40642034}],"con":true,"img":false}]}
{"op":"mcm","clk":"5322084136","pt":1646316219861,"mc":[{"id":"1.195532874","rc":[{"atb":[[4.4,0]],"id":41469398},{"atb":[[4.4,0]],"id":35985721}],"con":true,"img":false}]}
{"op":"mcm","clk":"5322084386","pt":1646316222861,"mc":[{"id":"1.195532874","rc":[{"atb":[[4.8,2.95]],"id":41469398}],"con":true,"img":false}]}
{"op":"mcm","clk":"5322084402","pt":1646316223067,"mc":[{"id":"1.195532874","rc":[{"atb":[[4.8,2.95]],"id":35985721}],"con":true,"img":false}]}
{"op":"mcm","clk":"5322085821","pt":1646316241265,"mc":[{"id":"1.195532874","rc":[{"atb":[[1.66,0]],"id":40883678}],"con":true,"img":false}]}
{"op":"mcm","clk":"5322086047","pt":1646316244670,"mc":[{"id":"1.195532874","rc":[{"atb":[[1.7,16.02]],"id":40883678}],"con":true,"img":false}]}
{"op":"mcm","clk":"5322098363","pt":1646316380085,"mc":[{"id":"1.195532874","rc":[{"atb":[[2.38,0]],"id":39614765},{"atb":[[2.3,0]],"id":40642034}],"con":true,"img":false}]}
{"op":"mcm","clk":"5322099836","pt":1646316395418,"mc":[{"id":"1.195532874","rc":[{"atb":[[2.4,8.86]],"id":40642034}],"con":true,"img":false}]}
{"op":"mcm","clk":"5322099845","pt":1646316395515,"mc":[{"id":"1.195532874","rc":[{"atb":[[2.46,8.5]],"id":39614765}],"con":true,"img":false}]}
{"op":"mcm","clk":"5322102945","pt":1646316427285,"mc":[{"id":"1.195532874","rc":[{"atb":[[2.34,0]],"id":40642034}],"con":true,"img":false}]}
{"op":"mcm","clk":"5322103200","pt":1646316430194,"mc":[{"id":"1.195532874","rc":[{"atb":[[2.44,7.79]],"id":40642034}],"con":true,"img":false}]}
{"op":"mcm","clk":"5322105748","pt":1646316456305,"mc":[{"id":"1.195532874","rc":[{"atb":[[4.6,0]],"id":41469398},{"atb":[[4.6,0]],"id":35985721}],"con":true,"img":false}]}
{"op":"mcm","clk":"5322109169","pt":1646316493688,"mc":[{"id":"1.195532874","rc":[{"atb":[[1.68,0]],"id":40883678}],"con":true,"img":false}]}
{"op":"mcm","clk":"5322110368","pt":1646316506468,"mc":[{"id":"1.195532874","rc":[{"atb":[[1.72,17.24]],"id":40883678}],"con":true,"img":false}]}
{"op":"mcm","clk":"5322119949","pt":1646316614219,"mc":[{"id":"1.195532874","rc":[{"atb":[[2.42,0]],"id":39614765}],"con":true,"img":false}]}
{"op":"mcm","clk":"5322120195","pt":1646316617005,"mc":[{"id":"1.195532874","rc":[{"atb":[[2.5,7.47]],"id":39614765}],"con":true,"img":false}]}
{"op":"mcm","clk":"5322125853","pt":1646316678108,"mc":[{"id":"1.195532874","rc":[{"atb":[[2.4,0]],"id":40642034}],"con":true,"img":false}]}
{"op":"mcm","clk":"5322126941","pt":1646316688628,"mc":[{"id":"1.195532874","rc":[{"atb":[[4.8,0]],"id":41469398},{"atb":[[4.8,0]],"id":35985721}],"con":true,"img":false}]}
{"op":"mcm","clk":"5322127247","pt":1646316691613,"mc":[{"id":"1.195532874","rc":[{"atb":[[4.4,3.29]],"id":41469398}],"con":true,"img":false}]}
{"op":"mcm","clk":"5322127258","pt":1646316691721,"mc":[{"id":"1.195532874","rc":[{"atb":[[2.48,8.39]],"id":40642034}],"con":true,"img":false}]}
{"op":"mcm","clk":"5322127279","pt":1646316691935,"mc":[{"id":"1.195532874","rc":[{"atb":[[4.4,6.94]],"id":35985721}],"con":true,"img":false}]}
{"op":"mcm","clk":"5322127306","pt":1646316692204,"mc":[{"id":"1.195532874","rc":[{"atb":[[4.4,6.94]],"id":41469398}],"con":true,"img":false}]}
{"op":"mcm","clk":"5322130774","pt":1646316727744,"mc":[{"id":"1.195532874","rc":[{"atb":[[1.7,0]],"id":40883678}],"con":true,"img":false}]}
{"op":"mcm","clk":"5322131100","pt":1646316730953,"mc":[{"id":"1.195532874","rc":[{"atb":[[1.74,15.15]],"id":40883678}],"con":true,"img":false}]}
{"op":"mcm","clk":"5322142115","pt":1646316860561,"mc":[{"id":"1.195532874","rc":[{"atb":[[2.46,0]],"id":39614765}],"con":true,"img":false}]}
{"op":"mcm","clk":"5322143969","pt":1646316880666,"mc":[{"id":"1.195532874","rc":[{"atb":[[2.54,8.06]],"id":39614765}],"con":true,"img":false}]}
{"op":"mcm","clk":"5322146791","pt":1646316911411,"mc":[{"id":"1.195532874","rc":[{"atb":[[2.44,0]],"id":40642034}],"con":true,"img":false}]}
{"op":"mcm","clk":"5322147051","pt":1646316914300,"mc":[{"id":"1.195532874","rc":[{"atb":[[2.52,7.37]],"id":40642034}],"con":true,"img":false}]}
{"op":"mcm","clk":"5322159613","pt":1646317055961,"mc":[{"id":"1.195532874","rc":[{"atb":[[1.72,0]],"id":40883678}],"con":true,"img":false}]}
{"op":"mcm","clk":"5322160551","pt":1646317066244,"mc":[{"id":"1.195532874","rc":[{"atl":[[1000,12]],"id":40883678}],"con":true,"img":false}]}
{"op":"mcm","clk":"5322160657","pt":1646317067550,"mc":[{"id":"1.195532874","rc":[{"atl":[[1000,12.2]],"id":40883678}],"con":true,"img":false}]}
{"op":"mcm","clk":"5322160789","pt":1646317068850,"mc":[{"id":"1.195532874","rc":[{"atl":[[1000,12]],"id":40883678}],"con":true,"img":false}]}
{"op":"mcm","clk":"5322160801","pt":1646317068953,"mc":[{"id":"1.195532874","rc":[{"atl":[[8.8,0.2]],"id":40883678}],"con":true,"img":false}]}
{"op":"mcm","clk":"5322160921","pt":1646317070261,"mc":[{"id":"1.195532874","rc":[{"atl":[[1000,12]],"id":40642034}],"con":true,"img":false}]}
{"op":"mcm","clk":"5322161052","pt":1646317071573,"mc":[{"id":"1.195532874","rc":[{"atl":[[1000,12.2]],"id":40642034}],"con":true,"img":false}]}
{"op":"mcm","clk":"5322161106","pt":1646317072052,"mc":[{"id":"1.195532874","rc":[{"atb":[[1.76,16.34]],"id":40883678}],"con":true,"img":false}]}
{"op":"mcm","clk":"5322161186","pt":1646317072948,"mc":[{"id":"1.195532874","rc":[{"atl":[[1000,12]],"id":40642034}],"con":true,"img":false}]}
{"op":"mcm","clk":"5322161192","pt":1646317073052,"mc":[{"id":"1.195532874","rc":[{"atl":[[9.4,0.2]],"id":40642034}],"con":true,"img":false}]}
{"op":"mcm","clk":"5322161290","pt":1646317074365,"mc":[{"id":"1.195532874","rc":[{"atl":[[1000,12]],"id":39614765}],"con":true,"img":false}]}
{"op":"mcm","clk":"5322161429","pt":1646317075692,"mc":[{"id":"1.195532874","rc":[{"atl":[[1000,12.2]],"id":39614765}],"con":true,"img":false}]}
{"op":"mcm","clk":"5322161592","pt":1646317077063,"mc":[{"id":"1.195532874","rc":[{"atl":[[1000,12]],"id":39614765}],"con":true,"img":false}]}
{"op":"mcm","clk":"5322161598","pt":1646317077157,"mc":[{"id":"1.195532874","rc":[{"atl":[[11.5,0.2]],"id":39614765}],"con":true,"img":false}]}
{"op":"mcm","clk":"5322161731","pt":1646317078462,"mc":[{"id":"1.195532874","rc":[{"atl":[[18,0]],"id":41469398}],"con":true,"img":false}]}
{"op":"mcm","clk":"5322161736","pt":1646317078565,"mc":[{"id":"1.195532874","rc":[{"atl":[[21,0.2]],"id":41469398}],"con":true,"img":false}]}
{"op":"mcm","clk":"5322161870","pt":1646317079879,"mc":[{"id":"1.195532874","rc":[{"atl":[[18,0]],"id":35985721}],"con":true,"img":false}]}
{"op":"mcm","clk":"5322161879","pt":1646317079980,"mc":[{"id":"1.195532874","rc":[{"atl":[[21,0.2]],"id":35985721}],"con":true,"img":false}]}
{"op":"mcm","clk":"5322163513","pt":1646317097904,"mc":[{"id":"1.195532874","rc":[{"atb":[[2.5,0]],"id":39614765}],"con":true,"img":false}]}
{"op":"mcm","clk":"5322163787","pt":1646317101102,"mc":[{"id":"1.195532874","rc":[{"atb":[[2.58,7.09]],"id":39614765}],"con":true,"img":false}]}
{"op":"mcm","clk":"5322168347","pt":1646317150565,"mc":[{"id":"1.195532874","rc":[{"atb":[[2.48,0]],"id":40642034}],"con":true,"img":false}]}
{"op":"mcm","clk":"5322169866","pt":1646317167740,"mc":[{"id":"1.195532874","rc":[{"atb":[[2.56,7.96]],"id":40642034}],"con":true,"img":false}]}
{"op":"mcm","clk":"5322180374","pt":1646317290586,"mc":[{"id":"1.195532874","rc":[{"atb":[[1.74,0]],"id":40883678}],"con":true,"img":false}]}
{"op":"mcm","clk":"5322180579","pt":1646317293140,"mc":[{"id":"1.195532874","rc":[{"atb":[[1.78,14.37]],"id":40883678}],"con":true,"img":false}]}
{"op":"mcm","clk":"5322185595","pt":1646317348474,"mc":[{"id":"1.195532874","rc":[{"atb":[[2.54,0]],"id":39614765}],"con":true,"img":false}]}
{"op":"mcm","clk":"5322187146","pt":1646317365031,"mc":[{"id":"1.195532874","rc":[{"atb":[[2.62,7.66]],"id":39614765}],"con":true,"img":false}]}
{"op":"mcm","clk":"5322188912","pt":1646317383673,"mc":[{"id":"1.195532874","rc":[{"atb":[[2.52,0]],"id":40642034}],"con":true,"img":false}]}
{"op":"mcm","clk":"5322189180","pt":1646317386762,"mc":[{"id":"1.195532874","rc":[{"atb":[[2.6,7.01]],"id":40642034}],"con":true,"img":false}]}
{"op":"mcm","clk":"5322203287","pt":1646317540293,"mc":[{"id":"1.195532874","rc":[{"atb":[[1.76,0]],"id":40883678}],"con":true,"img":false}]}
{"op":"mcm","clk":"5322204459","pt":1646317553020,"mc":[{"id":"1.195532874","rc":[{"atb":[[1.8,15.52]],"id":40883678}],"con":true,"img":false}]}
{"op":"mcm","clk":"5322207240","pt":1646317582386,"mc":[{"id":"1.195532874","rc":[{"atb":[[2.58,0]],"id":39614765}],"con":true,"img":false}]}
{"op":"mcm","clk":"5322207540","pt":1646317585569,"mc":[{"id":"1.195532874","rc":[{"atb":[[2.66,6.75]],"id":39614765}],"con":true,"img":false}]}
{"op":"mcm","clk":"5322212715","pt":1646317638657,"mc":[{"id":"1.195532874","rc":[{"atb":[[2.56,0]],"id":40642034}],"con":true,"img":false}]}
{"op":"mcm","clk":"5322213825","pt":1646317649782,"mc":[{"id":"1.195532874","rc":[{"atb":[[2.64,7.57]],"id":40642034}],"con":true,"img":false}]}
{"op":"mcm","clk":"5322225470","pt":1646317774858,"mc":[{"id":"1.195532874","rc":[{"atb":[[1.78,0]],"id":40883678}],"con":true,"img":false}]}
{"op":"mcm","clk":"5322225756","pt":1646317778197,"mc":[{"id":"1.195532874","rc":[{"atb":[[1.82,13.67]],"id":40883678}],"con":true,"img":false}]}
{"op":"mcm","clk":"5322229790","pt":1646317823054,"mc":[{"id":"1.195532874","rc":[{"atb":[[2.62,0]],"id":39614765}],"con":true,"img":false}]}
{"op":"mcm","clk":"5322231377","pt":1646317839501,"mc":[{"id":"1.195532874","rc":[{"atb":[[2.7,7.3]],"id":39614765}],"con":true,"img":false}]}
{"op":"mcm","clk":"5322234502","pt":1646317873716,"mc":[{"id":"1.195532874","rc":[{"atb":[[2.6,0]],"id":40642034}],"con":true,"img":false}]}
{"op":"mcm","clk":"5322234724","pt":1646317876635,"mc":[{"id":"1.195532874","rc":[{"atb":[[2.68,6.67]],"id":40642034}],"con":true,"img":false}]}
{"op":"mcm","clk":"5322246195","pt":1646318020201,"mc":[{"id":"1.195532874","rc":[{"atb":[[1.8,0]],"id":40883678}],"con":true,"img":false}]}
{"op":"mcm","clk":"5322247275","pt":1646318032720,"mc":[{"id":"1.195532874","rc":[{"atb":[[1.84,14.78]],"id":40883678}],"con":true,"img":false}]}
{"op":"mcm","clk":"5322249127","pt":1646318057456,"mc":[{"id":"1.195532874","rc":[{"atb":[[2.66,0]],"id":39614765}],"con":true,"img":false}]}
{"op":"mcm","clk":"5322249327","pt":1646318059855,"mc":[{"id":"1.195532874","rc":[{"atb":[[2.74,6.44]],"id":39614765}],"con":true,"img":false}]}
{"op":"mcm","clk":"5322253847","pt":1646318116113,"mc":[{"id":"1.195532874","rc":[{"atb":[[2.64,0]],"id":40642034}],"con":true,"img":false}]}
{"op":"mcm","clk":"5322254974","pt":1646318128927,"mc":[{"id":"1.195532874","rc":[{"atb":[[2.72,7.21]],"id":40642034}],"con":true,"img":false}]}
{"op":"mcm","clk":"5322265319","pt":1646318252354,"mc":[{"id":"1.195532874","rc":[{"atb":[[1.82,0]],"id":40883678}],"con":true,"img":false}]}
{"op":"mcm","clk":"5322265736","pt":1646318255662,"mc":[{"id":"1.195532874","rc":[{"atb":[[1.86,13.03]],"id":40883678}],"con":true,"img":false}]}
{"op":"mcm","clk":"5322269173","pt":1646318292786,"mc":[{"id":"1.195532874","rc":[{"atb":[[2.7,0]],"id":39614765}],"con":true,"img":false}]}
{"op":"mcm","clk":"5322271294","pt":1646318314816,"mc":[{"id":"1.195532874","rc":[{"atb":[[2.78,6.97]],"id":39614765}],"con":true,"img":false}]}
{"op":"mcm","clk":"5322274661","pt":1646318348661,"mc":[{"id":"1.195532874","rc":[{"atb":[[2.68,0]],"id":40642034}],"con":true,"img":false}]}
{"op":"mcm","clk":"5322274951","pt":1646318351912,"mc":[{"id":"1.195532874","rc":[{"atb":[[2.76,6.36]],"id":40642034}],"con":true,"img":false}]}
{"op":"mcm","clk":"5322287984","pt":1646318489259,"mc":[{"id":"1.195532874","rc":[{"atb":[[1.84,0]],"id":40883678}],"con":true,"img":false}]}
{"op":"mcm","clk":"5322289114","pt":1646318500679,"mc":[{"id":"1.195532874","rc":[{"atb":[[1.88,14.11]],"id":40883678}],"con":true,"img":false}]}
{"op":"mcm","clk":"5322291661","pt":1646318526224,"mc":[{"id":"1.195532874","rc":[{"atb":[[2.74,0]],"id":39614765}],"con":true,"img":false}]}
{"op":"mcm","clk":"5322291966","pt":1646318528894,"mc":[{"id":"1.195532874","rc":[{"atb":[[2.82,6.16]],"id":39614765}],"con":true,"img":false}]}
{"op":"mcm","clk":"5322298239","pt":1646318592730,"mc":[{"id":"1.195532874","rc":[{"atb":[[2.72,0]],"id":40642034}],"con":true,"img":false}]}
{"op":"mcm","clk":"5322299350","pt":1646318605639,"mc":[{"id":"1.195532874","rc":[{"atb":[[2.8,6.89]],"id":40642034}],"con":true,"img":false}]}
{"op":"mcm","clk":"5322310475","pt":1646318721495,"mc":[{"id":"1.195532874","rc":[{"atb":[[1.86,0]],"id":40883678}],"con":true,"img":false}]}
{"op":"mcm","clk":"5322310747","pt":1646318724621,"mc":[{"id":"1.195532874","rc":[{"atb":[[1.9,12.46]],"id":40883678}],"con":true,"img":false}]}
{"op":"mcm","clk":"5322315510","pt":1646318774460,"mc":[{"id":"1.195532874","rc":[{"atb":[[2.78,0]],"id":39614765}],"con":true,"img":false}]}
{"op":"mcm","clk":"5322316706","pt":1646318787362,"mc":[{"id":"1.195532874","rc":[{"atb":[[2.86,6.67]],"id":39614765}],"con":true,"img":false}]}
{"op":"mcm","clk":"5322329333","pt":1646318826980,"mc":[{"id":"1.195532874","rc":[{"atb":[[2.76,0]],"id":40642034}],"con":true,"img":false}]}
{"op":"mcm","clk":"5322329565","pt":1646318829670,"mc":[{"id":"1.195532874","rc":[{"atb":[[2.84,6.09]],"id":40642034}],"con":true,"img":false}]}
{"op":"mcm","clk":"5322341073","pt":1646318962044,"mc":[{"id":"1.195532874","rc":[{"atb":[[1.88,0]],"id":40883678}],"con":true,"img":false}]}
{"op":"mcm","clk":"5322341994","pt":1646318974126,"mc":[{"id":"1.195532874","rc":[{"atb":[[1.92,13.49]],"id":40883678}],"con":true,"img":false}]}
{"op":"mcm","clk":"5322344590","pt":1646319007414,"mc":[{"id":"1.195532874","rc":[{"atb":[[2.82,0]],"id":39614765}],"con":true,"img":false}]}
{"op":"mcm","clk":"5322344913","pt":1646319011117,"mc":[{"id":"1.195532874","rc":[{"atb":[[2.9,5.89]],"id":39614765}],"con":true,"img":false}]}
{"op":"mcm","clk":"5322349904","pt":1646319072811,"mc":[{"id":"1.195532874","rc":[{"atb":[[2.8,0]],"id":40642034}],"con":true,"img":false}]}
{"op":"mcm","clk":"5322351000","pt":1646319087172,"mc":[{"id":"1.195532874","rc":[{"atb":[[2.88,6.6]],"id":40642034}],"con":true,"img":false}]}
{"op":"mcm","clk":"5322359402","pt":1646319196317,"mc":[{"id":"1.195532874","rc":[{"atb":[[1.9,0]],"id":40883678}],"con":true,"img":false}]}
{"op":"mcm","clk":"5322359596","pt":1646319199280,"mc":[{"id":"1.195532874","rc":[{"atb":[[1.94,11.93]],"id":40883678}],"con":true,"img":false}]}
{"op":"mcm","clk":"5322362615","pt":1646319250086,"mc":[{"id":"1.195532874","rc":[{"atb":[[2.86,0]],"id":39614765}],"con":true,"img":false}]}
{"op":"mcm","clk":"5322363439","pt":1646319263710,"mc":[{"id":"1.195532874","rc":[{"atb":[[2.94,6.4]],"id":39614765}],"con":true,"img":false}]}
{"op":"mcm","clk":"5322366149","pt":1646319307664,"mc":[{"id":"1.195532874","rc":[{"atb":[[2.84,0]],"id":40642034}],"con":true,"img":false}]}
{"op":"mcm","clk":"5322366339","pt":1646319310860,"mc":[{"id":"1.195532874","rc":[{"atb":[[2.4,8]],"id":40642034}],"con":true,"img":false}]}
{"op":"mcm","clk":"5322374904","pt":1646319441674,"mc":[{"id":"1.195532874","rc":[{"atb":[[1.92,0]],"id":40883678}],"con":true,"img":false}]}
{"op":"mcm","clk":"5322375892","pt":1646319455915,"mc":[{"id":"1.195532874","rc":[{"atb":[[1.96,12.93]],"id":40883678}],"con":true,"img":false}]}
{"op":"mcm","clk":"5322377809","pt":1646319485540,"mc":[{"id":"1.195532874","rc":[{"atb":[[2.9,0]],"id":39614765}],"con":true,"img":false}]}
{"op":"mcm","clk":"5322378018","pt":1646319488349,"mc":[{"id":"1.195532874","rc":[{"atb":[[2.98,5.66]],"id":39614765}],"con":true,"img":false}]}
{"op":"mcm","clk":"5322385125","pt":1646319588687,"mc":[{"id":"1.195532874","rc":[{"atb":[[2.88,0]],"id":40642034}],"con":true,"img":false}]}
{"op":"mcm","clk":"5322385203","pt":1646319589980,"mc":[{"id":"1.195532874","rc":[{"atb":[[2.44,8.62]],"id":40642034}],"con":true,"img":false}]}
{"op":"mcm","clk":"5322391812","pt":1646319674408,"mc":[{"id":"1.195532874","rc":[{"atb":[[2.02,8.45],[3.75,4.51],[3.65,4.23]],"id":37306244},{"atb":[[2.02,11.83],[4.4,6.95]],"id":41469398},{"atb":[[2.98,5.67],[2.94,6.4],[2.34,11.42]],"id":39614765},{"atb":[[4.4,6.95],[2.08,10.44]],"id":35985721},{"atb":[[2.4,8.01],[2.36,8.45],[2.44,8.63]],"id":40642034},{"atb":[[1.96,12.95],[1.94,0],[2.34,9.48]],"id":40883678}],"con":true,"img":false}]}
{"op":"mcm","clk":"5322392057","pt":1646319677312,"mc":[{"id":"1.195532874","rc":[{"atb":[[1.98,11.45]],"id":40883678}],"con":true,"img":false}]}
{"op":"mcm","clk":"5322403985","pt":1646319825758,"mc":[{"id":"1.195532874","rc":[{"atb":[[2.4,0]],"id":40642034}],"con":true,"img":false}]}
{"op":"mcm","clk":"5322404457","pt":1646319831499,"mc":[{"id":"1.195532874","rc":[{"atb":[[2.48,7.58]],"id":40642034}],"con":true,"img":false}]}
{"op":"mcm","clk":"5322405074","pt":1646319839010,"mc":[{"id":"1.195532874","rc":[{"atb":[[2.94,0]],"id":39614765}],"con":true,"img":false}]}
{"op":"mcm","clk":"5322406956","pt":1646319861436,"mc":[{"id":"1.195532874","rc":[{"atb":[[3.05,6.06]],"id":39614765}],"con":true,"img":false}]}
{"op":"mcm","clk":"5322420021","pt":1646320020925,"mc":[{"id":"1.195532874","rc":[{"atb":[[1.96,0]],"id":40883678}],"con":true,"img":false}]}
{"op":"mcm","clk":"5322421181","pt":1646320033768,"mc":[{"id":"1.195532874","rc":[{"atb":[[2,12.43]],"id":40883678}],"con":true,"img":false}]}
{"op":"mcm","clk":"5322424509","pt":1646320072414,"mc":[{"id":"1.195532874","rc":[{"atb":[[2.98,0]],"id":39614765}],"con":true,"img":false}]}
{"op":"mcm","clk":"5322424638","pt":1646320074324,"mc":[{"id":"1.195532874","rc":[{"atb":[[3.15,5.22]],"id":39614765}],"con":true,"img":false}]}
{"op":"mcm","clk":"5322424973","pt":1646320078503,"mc":[{"id":"1.195532874","rc":[{"atb":[[2.44,0]],"id":40642034}],"con":true,"img":false}]}
{"op":"mcm","clk":"5322426380","pt":1646320096934,"mc":[{"id":"1.195532874","rc":[{"atb":[[2.52,8.18]],"id":40642034}],"con":true,"img":false}]}
{"op":"mcm","clk":"5322439235","pt":1646320250053,"mc":[{"id":"1.195532874","rc":[{"atl":[[3.25,60]],"id":40883678}],"con":true,"img":false}]}
{"op":"mcm","clk":"5322439622","pt":1646320254668,"mc":[{"id":"1.195532874","rc":[{"atb":[[1.98,0]],"id":40883678}],"con":true,"img":false}]}
{"op":"mcm","clk":"5322439858","pt":1646320257542,"mc":[{"id":"1.195532874","rc":[{"atb":[[2.04,10.79]],"id":40883678}],"con":true,"img":false}]}
{"op":"mcm","clk":"5322446987","pt":1646320315961,"mc":[{"id":"1.195532874","rc":[{"atb":[[2.48,0]],"id":40642034}],"con":true,"img":false}]}
{"op":"mcm","clk":"5322447068","pt":1646320316852,"mc":[{"id":"1.195532874","rc":[{"atb":[[3.05,0]],"id":39614765}],"con":true,"img":false}]}
{"op":"mcm","clk":"5322447448","pt":1646320321573,"mc":[{"id":"1.195532874","rc":[{"atb":[[2.56,7.2]],"id":40642034}],"con":true,"img":false}]}
{"op":"mcm","clk":"5322448254","pt":1646320331300,"mc":[{"id":"1.195532874","rc":[{"atb":[[3.25,5.53]],"id":39614765}],"con":true,"img":false}]}
{"op":"mcm","clk":"5322461169","pt":1646320483141,"mc":[{"id":"1.195532874","rc":[{"atb":[[3.65,0]],"id":37306244},{"atb":[[4.4,3.65]],"id":41469398},{"atb":[[4.4,3.65]],"id":35985721}],"con":true,"img":false}]}
{"op":"mcm","clk":"5322461369","pt":1646320485646,"mc":[{"id":"1.195532874","rc":[{"atb":[[4.4,0]],"id":41469398},{"atb":[[4.4,0]],"id":35985721}],"con":true,"img":false}]}
{"op":"mcm","clk":"5322461423","pt":1646320486329,"mc":[{"id":"1.195532874","rc":[{"atb":[[2.06,10.59]],"id":37306244}],"con":true,"img":false}]}
{"op":"mcm","clk":"5322461431","pt":1646320486488,"mc":[{"id":"1.195532874","rc":[{"atb":[[4.8,2.95]],"id":35985721}],"con":true,"img":false}]}
{"op":"mcm","clk":"5322462210","pt":1646320497100,"mc":[{"id":"1.195532874","rc":[{"atb":[[2,0]],"id":40883678}],"con":true,"img":false}]}
{"op":"mcm","clk":"5322466802","pt":1646320553526,"mc":[{"id":"1.195532874","rc":[{"atb":[[3.15,0]],"id":39614765}],"con":true,"img":false}]}
{"op":"mcm","clk":"5322467185","pt":1646320557842,"mc":[{"id":"1.195532874","rc":[{"atb":[[3.35,4.77]],"id":39614765}],"con":true,"img":false}]}
{"op":"mcm","clk":"5322467676","pt":1646320563143,"mc":[{"id":"1.195532874","rc":[{"atb":[[2.52,0]],"id":40642034}],"con":true,"img":false}]}
{"op":"mcm","clk":"5322468713","pt":1646320575163,"mc":[{"id":"1.195532874","rc":[{"atb":[[2.6,7.77]],"id":40642034}],"con":true,"img":false}]}
{"op":"mcm","clk":"5322478457","pt":1646320694905,"mc":[{"id":"1.195532874","rc":[{"atb":[[2.02,0]],"id":37306244}],"con":true,"img":false}]}
{"op":"mcm","clk":"5322478473","pt":1646320695113,"mc":[{"id":"1.195532874","rc":[{"atb":[[2.08,8.45]],"id":37306244}],"con":true,"img":false}]}
{"op":"mcm","clk":"5322480458","pt":1646320722879,"mc":[{"id":"1.195532874","rc":[{"atb":[[3.75,0]],"id":37306244}],"con":true,"img":false}]}
{"op":"mcm","clk":"5322480836","pt":1646320727962,"mc":[{"id":"1.195532874","rc":[{"atb":[[2.04,0]],"id":40883678}],"con":true,"img":false}]}
{"op":"mcm","clk":"5322481161","pt":1646320731885,"mc":[{"id":"1.195532874","rc":[{"atb":[[2.12,11.1]],"id":37306244}],"con":true,"img":false}]}
{"op":"mcm","clk":"5322486501","pt":1646320799133,"mc":[{"id":"1.195532874","rc":[{"atb":[[2.56,0]],"id":40642034}],"con":true,"img":false}]}
{"op":"mcm","clk":"5322486698","pt":1646320801121,"mc":[{"id":"1.195532874","rc":[{"atb":[[3.25,0]],"id":39614765}],"con":true,"img":false}]}
{"op":"mcm","clk":"5322486790","pt":1646320802266,"mc":[{"id":"1.195532874","rc":[{"atb":[[2.64,6.84]],"id":40642034}],"con":true,"img":false}]}
{"op":"mcm","clk":"5322488170","pt":1646320819182,"mc":[{"id":"1.195532874","rc":[{"atb":[[3.45,5.07]],"id":39614765}],"con":true,"img":false}]}
{"op":"mcm","clk":"5322497441","pt":1646320929011,"mc":[{"id":"1.195532874","rc":[{"atb":[[2.06,0]],"id":37306244}],"con":true,"img":false}]}
{"op":"mcm","clk":"5322497633","pt":1646320931503,"mc":[{"id":"1.195532874","rc":[{"atb":[[2.16,9.67]],"id":37306244}],"con":true,"img":false}]}
{"op":"mcm","clk":"5322502355","pt":1646320991943,"mc":[{"id":"1.195532874","rc":[{"atb":[[2.08,0]],"id":37306244}],"con":true,"img":false}]}
{"op":"mcm","clk":"5322502363","pt":1646320992049,"mc":[{"id":"1.195532874","rc":[{"atb":[[2.18,8.45]],"id":37306244}],"con":true,"img":false}]}
{"op":"mcm","clk":"5322505453","pt":1646321034709,"mc":[{"id":"1.195532874","rc":[{"atb":[[3.35,0]],"id":39614765}],"con":true,"img":false}]}
{"op":"mcm","clk":"5322505496","pt":1646321035276,"mc":[{"id":"1.195532874","rc":[{"atb":[[2.6,0]],"id":40642034}],"con":true,"img":false}]}
{"op":"mcm","clk":"5322505621","pt":1646321036992,"mc":[{"id":"1.195532874","rc":[{"atb":[[2.38,8.13]],"id":39614765}],"con":true,"img":false}]}
{"op":"mcm","clk":"5322506405","pt":1646321047921,"mc":[{"id":"1.195532874","rc":[{"atb":[[2.68,7.4]],"id":40642034}],"con":true,"img":false}]}
{"op":"mcm","clk":"5322515616","pt":1646321175528,"mc":[{"id":"1.195532874","rc":[{"atb":[[2.12,0]],"id":37306244}],"con":true,"img":false}]}
{"op":"mcm","clk":"5322516441","pt":1646321187425,"mc":[{"id":"1.195532874","rc":[{"atb":[[2.22,10.19]],"id":37306244}],"con":true,"img":false}]}
{"op":"mcm","clk":"5322519083","pt":1646321225785,"mc":[{"id":"1.195532874","rc":[{"atb":[[2.16,0]],"id":37306244}],"con":true,"img":false}]}
{"op":"mcm","clk":"5322519350","pt":1646321229114,"mc":[{"id":"1.195532874","rc":[{"atb":[[2.26,8.9]],"id":37306244}],"con":true,"img":false}]}
{"op":"mcm","clk":"5322522377","pt":1646321267933,"mc":[{"id":"1.195532874","rc":[{"atb":[[2.64,0]],"id":40642034}],"con":true,"img":false}]}
{"op":"mcm","clk":"5322522591","pt":1646321270654,"mc":[{"id":"1.195532874","rc":[{"atb":[[2.72,6.52]],"id":40642034}],"con":true,"img":false}]}
{"op":"mcm","clk":"5322523585","pt":1646321283153,"mc":[{"id":"1.195532874","rc":[{"atl":[[5.3,9.2]],"id":40883678}],"con":true,"img":false}]}
{"op":"mcm","clk":"5322523593","pt":1646321283263,"mc":[{"id":"1.195532874","rc":[{"atb":[[2.62,64.81]],"id":37306244},{"atl":[[34,15.5],[150,5]],"id":37306244},{"atb":[[2.06,165.09],[2.62,64.81]],"id":41469398},{"atl":[[150,5]],"id":41469398},{"atb":[[2.06,165.09]],"id":39614765},{"atl":[[34,15.5],[150,5]],"id":39614765},{"atb":[[2.06,165.09],[2.62,64.81]],"id":35985721},{"atl":[[17,9.5],[34,15.5],[150,5]],"id":40642034},{"atl":[[17,9.5],[34,15.5],[150,5],[6.8,15.2]],"id":40883678}],"con":true,"img":false}]}
{"op":"mcm","clk":"5322523618","pt":1646321283571,"mc":[{"id":"1.195532874","rc":[{"atb":[[2.06,165.09]],"id":37306244}],"con":true,"img":false}]}
{"op":"mcm","clk":"5322523625","pt":1646321283676,"mc":[{"id":"1.195532874","rc":[{"atb":[[3.45,0]],"id":39614765},{"atl":[[150,5]],"id":35985721}],"con":true,"img":false}]}
{"op":"mcm","clk":"5322524168","pt":1646321291369,"mc":[{"id":"1.195532874","rc":[{"atb":[[2.18,0]],"id":37306244}],"con":true,"img":false}]}
{"op":"mcm","clk":"5322524174","pt":1646321291479,"mc":[{"id":"1.195532874","rc":[{"atb":[[2.28,8.45]],"id":37306244}],"con":true,"img":false}]}
{"op":"mcm","clk":"5322524701","pt":1646321298236,"mc":[{"id":"1.195532874","rc":[{"atb":[[2.42,8.75]],"id":39614765}],"con":true,"img":false}]}
{"op":"mcm","clk":"5322524782","pt":1646321299331,"mc":[{"id":"1.195532874","rc":[{"atb":[[3.75,1.65]],"id":40642034}],"con":true,"img":false}]}
{"op":"mcm","clk":"5322524813","pt":1646321299745,"mc":[{"id":"1.195532874","rc":[{"atb":[[1.82,124.39],[2.1,83.64]],"id":40642034}],"con":true,"img":false}]}
{"op":"mcm","clk":"5322538083","pt":1646321473301,"mc":[{"id":"1.195532874","rc":[{"atb":[[2.22,0]],"id":37306244},{"spn":4.67,"spf":1.0,"id":40642034}],"con":true,"img":false}]}
{"op":"mcm","clk":"5322539121","pt":1646321487559,"mc":[{"id":"1.195532874","rc":[{"atb":[[2.66,7.49]],"id":37306244}],"con":true,"img":false}]}
{"op":"mcm","clk":"5322541206","pt":1646321515755,"mc":[{"id":"1.195532874","rc":[{"atb":[[2.68,0]],"id":40642034}],"con":true,"img":false}]}
{"op":"mcm","clk":"5322541408","pt":1646321518568,"mc":[{"id":"1.195532874","rc":[{"atb":[[2.26,0]],"id":37306244}],"con":true,"img":false}]}
{"op":"mcm","clk":"5322541805","pt":1646321523685,"mc":[{"id":"1.195532874","rc":[{"atb":[[2.7,6.6]],"id":37306244}],"con":true,"img":false}]}
{"op":"mcm","clk":"5322542378","pt":1646321530585,"mc":[{"id":"1.195532874","rc":[{"atb":[[2.76,7.06]],"id":40642034}],"con":true,"img":false}]}
{"op":"mcm","clk":"5322542552","pt":1646321532519,"mc":[{"id":"1.195532874","rc":[{"atb":[[2.38,0]],"id":39614765}],"con":true,"img":false}]}
{"op":"mcm","clk":"5322542796","pt":1646321535186,"mc":[{"id":"1.195532874","rc":[{"atb":[[2.46,7.68]],"id":39614765}],"con":true,"img":false}]}
{"op":"mcm","clk":"5322547099","pt":1646321591661,"mc":[{"id":"1.195532874","rc":[{"atb":[[2.02,0]],"id":41469398}],"con":true,"img":false}]}
{"op":"mcm","clk":"5322547113","pt":1646321591757,"mc":[{"id":"1.195532874","rc":[{"atb":[[2.08,11.83]],"id":41469398}],"con":true,"img":false}]}
{"op":"mcm","clk":"5322559946","pt":1646321749573,"mc":[{"id":"1.195532874","rc":[{"atb":[[2.72,0]],"id":40642034}],"con":true,"img":false}]}
{"op":"mcm","clk":"5322560121","pt":1646321752076,"mc":[{"id":"1.195532874","rc":[{"atb":[[2.8,6.23]],"id":40642034}],"con":true,"img":false}]}
{"op":"mcm","clk":"5322560907","pt":1646321761981,"mc":[{"id":"1.195532874","rc":[{"atb":[[2.66,0]],"id":37306244}],"con":true,"img":false}]}
{"op":"mcm","clk":"5322562222","pt":1646321777389,"mc":[{"id":"1.195532874","rc":[{"atb":[[2.74,7.14]],"id":37306244}],"con":true,"img":false}]}
{"op":"mcm","clk":"5322562246","pt":1646321777599,"mc":[{"id":"1.195532874","rc":[{"atb":[[2.42,0]],"id":39614765}],"con":true,"img":false}]}
{"op":"mcm","clk":"5322563455","pt":1646321792543,"mc":[{"id":"1.195532874","rc":[{"atb":[[2.5,8.29]],"id":39614765}],"con":true,"img":false}]}
{"op":"mcm","clk":"5322579982","pt":1646321995941,"mc":[{"id":"1.195532874","rc":[{"atb":[[2.7,0]],"id":37306244}],"con":true,"img":false}]}
{"op":"mcm","clk":"5322580431","pt":1646322001574,"mc":[{"id":"1.195532874","rc":[{"atb":[[2.78,6.3]],"id":37306244}],"con":true,"img":false}]}
{"op":"mcm","clk":"5322580598","pt":1646322003461,"mc":[{"id":"1.195532874","rc":[{"atb":[[2.76,0]],"id":40642034}],"con":true,"img":false}]}
{"op":"mcm","clk":"5322581229","pt":1646322011072,"mc":[{"id":"1.195532874","rc":[{"atb":[[2.46,0]],"id":39614765}],"con":true,"img":false}]}
{"op":"mcm","clk":"5322581429","pt":1646322013775,"mc":[{"id":"1.195532874","rc":[{"atb":[[2.54,7.28]],"id":39614765}],"con":true,"img":false}]}
{"op":"mcm","clk":"5322581722","pt":1646322017163,"mc":[{"id":"1.195532874","rc":[{"atb":[[2.84,6.75]],"id":40642034}],"con":true,"img":false}]}
{"op":"mcm","clk":"5322600015","pt":1646322235986,"mc":[{"id":"1.195532874","rc":[{"atb":[[2.8,0]],"id":40642034}],"con":true,"img":false}]}
{"op":"mcm","clk":"5322600161","pt":1646322237718,"mc":[{"id":"1.195532874","rc":[{"atb":[[2.74,0]],"id":37306244}],"con":true,"img":false}]}
{"op":"mcm","clk":"5322600269","pt":1646322238900,"mc":[{"id":"1.195532874","rc":[{"atb":[[2.88,5.97]],"id":40642034}],"con":true,"img":false}]}
{"op":"mcm","clk":"5322601570","pt":1646322252314,"mc":[{"id":"1.195532874","rc":[{"atb":[[2.82,6.83]],"id":37306244}],"con":true,"img":false}]}
{"op":"mcm","clk":"5322601587","pt":1646322252528,"mc":[{"id":"1.195532874","rc":[{"atb":[[2.5,0]],"id":39614765}],"con":true,"img":false}]}
{"op":"mcm","clk":"5322603091","pt":1646322267548,"mc":[{"id":"1.195532874","rc":[{"atb":[[2.58,7.86]],"id":39614765}],"con":true,"img":false}]}
{"op":"mcm","clk":"5322621685","pt":1646322470667,"mc":[{"id":"1.195532874","rc":[{"atb":[[2.78,0]],"id":37306244}],"con":true,"img":false}]}
{"op":"mcm","clk":"5322622020","pt":1646322474465,"mc":[{"id":"1.195532874","rc":[{"atb":[[2.86,6.03]],"id":37306244}],"con":true,"img":false}]}
{"op":"mcm","clk":"5322622983","pt":1646322485792,"mc":[{"id":"1.195532874","rc":[{"atb":[[2.54,0]],"id":39614765}],"con":true,"img":false}]}
{"op":"mcm","clk":"5322623227","pt":1646322488466,"mc":[{"id":"1.195532874","rc":[{"atb":[[2.62,6.93]],"id":39614765}],"con":true,"img":false}]}
{"op":"mcm","clk":"5322632434","pt":1646322539651,"mc":[{"id":"1.195532874","rc":[{"atl":[[34,3.1]],"id":35985721}],"con":true,"img":false}]}
{"op":"mcm","clk":"5322636378","pt":1646322576869,"mc":[{"id":"1.195532874","rc":[{"atb":[[2.46,51]],"id":40883678}],"con":true,"img":false}]}
{"op":"mcm","clk":"5322637523","pt":1646322592318,"mc":[{"id":"1.195532874","rc":[{"atb":[[1.53,173.58],[1.39,261.54]],"id":40883678}],"con":true,"img":false}]}
{"op":"mcm","clk":"5322637614","pt":1646322593620,"mc":[{"id":"1.195532874","rc":[{"atb":[[1.55,20.41]],"id":40883678}],"con":true,"img":false}]}
{"op":"mcm","clk":"5322639147","pt":1646322614009,"mc":[{"id":"1.195532874","rc":[{"atb":[[2.84,0]],"id":40642034},{"spn":2.46,"spf":1.0,"id":40883678}],"con":true,"img":false}]}
{"op":"mcm","clk":"5322639218","pt":1646322615012,"mc":[{"id":"1.195532874","rc":[{"atb":[[1.57,21.82]],"id":40883678}],"con":true,"img":false}]}
{"op":"mcm","clk":"5322643221","pt":1646322647442,"mc":[{"id":"1.195532874","rc":[{"atb":[[2.4,8.87]],"id":40642034}],"con":true,"img":false}]}
{"op":"mcm","clk":"5322647250","pt":1646322675137,"mc":[{"id":"1.195532874","rc":[{"atb":[[2.82,0]],"id":37306244},{"atb":[[2.58,0]],"id":39614765}],"con":true,"img":false}]}
{"op":"mcm","clk":"5322647265","pt":1646322675239,"mc":[{"id":"1.195532874","rc":[{"atb":[[2.4,0]],"id":40642034},{"atb":[[1.57,0]],"id":40883678}],"con":true,"img":false}]}
{"op":"mcm","clk":"5322664305","pt":1646322847079,"mc":[{"id":"1.195532874","rc":[{"atb":[[2.88,0]],"id":40642034}],"con":true,"img":false}]}
{"op":"mcm","clk":"5322664740","pt":1646322850985,"mc":[{"id":"1.195532874","rc":[{"atb":[[2.4,8.01]],"id":40642034}],"con":true,"img":false}]}
{"op":"mcm","clk":"5322665516","pt":1646322858470,"mc":[{"id":"1.195532874","rc":[{"atb":[[2.9,6.54]],"id":37306244}],"con":true,"img":false}]}
{"op":"mcm","clk":"5322665522","pt":1646322858576,"mc":[{"id":"1.195532874","rc":[{"atb":[[2.66,7.49]],"id":39614765}],"con":true,"img":false}]}
{"op":"mcm","clk":"5322666704","pt":1646322872388,"mc":[{"id":"1.195532874","rc":[{"atb":[[2.44,8.63]],"id":40642034}],"con":true,"img":false}]}
{"op":"mcm","clk":"5322666718","pt":1646322872582,"mc":[{"id":"1.195532874","rc":[{"atb":[[1.57,21.82]],"id":40883678}],"con":true,"img":false}]}
{"op":"mcm","clk":"5322666809","pt":1646322873781,"mc":[{"id":"1.195532874","rc":[{"atb":[[1.55,0]],"id":40883678}],"con":true,"img":false}]}
{"op":"mcm","clk":"5322667019","pt":1646322876611,"mc":[{"id":"1.195532874","rc":[{"atb":[[1.59,19.02]],"id":40883678}],"con":true,"img":false}]}
{"op":"mcm","clk":"5322670218","pt":1646322911442,"mc":[{"id":"1.195532874","rc":[{"atb":[[2.86,0]],"id":37306244},{"atb":[[2.62,0]],"id":39614765}],"con":true,"img":false}]}
{"op":"mcm","clk":"5322670983","pt":1646322919944,"mc":[{"id":"1.195532874","rc":[{"atb":[[2.7,6.6]],"id":39614765}],"con":true,"img":false}]}
{"op":"mcm","clk":"5322671049","pt":1646322920633,"mc":[{"id":"1.195532874","rc":[{"atb":[[2.94,5.78]],"id":37306244}],"con":true,"img":false}]}
{"op":"mcm","clk":"5322685801","pt":1646323105554,"mc":[{"id":"1.195532874","rc":[{"atb":[[2.4,0]],"id":40642034}],"con":true,"img":false}]}
{"op":"mcm","clk":"5322686008","pt":1646323108572,"mc":[{"id":"1.195532874","rc":[{"atb":[[2.48,7.58]],"id":40642034}],"con":true,"img":false}]}
{"op":"mcm","clk":"5322686508","pt":1646323115595,"mc":[{"id":"1.195532874","rc":[{"atb":[[1.57,0]],"id":40883678}],"con":true,"img":false}]}
{"op":"mcm","clk":"5322687354","pt":1646323126697,"mc":[{"id":"1.195532874","rc":[{"atb":[[1.61,20.38]],"id":40883678}],"con":true,"img":false}]}
{"op":"mcm","clk":"5322689403","pt":1646323151228,"mc":[{"id":"1.195532874","rc":[{"atb":[[2.9,0]],"id":37306244},{"atb":[[2.66,0]],"id":39614765}],"con":true,"img":false}]}
{"op":"mcm","clk":"5322690870","pt":1646323165846,"mc":[{"id":"1.195532874","rc":[{"atb":[[2.98,6.28]],"id":37306244}],"con":true,"img":false}]}
{"op":"mcm","clk":"5322690889","pt":1646323166055,"mc":[{"id":"1.195532874","rc":[{"atb":[[2.74,7.14]],"id":39614765}],"con":true,"img":false}]}
{"op":"mcm","clk":"5322696530","pt":1646323231708,"mc":[{"id":"1.195532874","rc":[{"atb":[[2.28,8.45],[2.98,6.28],[2.94,5.79]],"id":37306244},{"atb":[[2.08,11.84]],"id":41469398},{"atb":[[2.74,7.14],[2.34,11.42],[2.7,6.61]],"id":39614765},{"atb":[[4.8,2.96],[2.08,10.44]],"id":35985721},{"atb":[[2.36,8.45],[2.44,8.64],[3.75,1.65],[2.48,7.6]],"id":40642034},{"atb":[[1.59,19.05],[1.61,20.38],[2.34,9.48]],"id":40883678},{"atl":[[3.5,53]],"id":40883678}],"con":true,"img":false}]}
{"op":"mcm","clk":"5322706682","pt":1646323345800,"mc":[{"id":"1.195532874","rc":[{"atb":[[2.44,0]],"id":40642034}],"con":true,"img":false}]}
{"op":"mcm","clk":"5322706802","pt":1646323347207,"mc":[{"id":"1.195532874","rc":[{"atb":[[1.59,0]],"id":40883678}],"con":true,"img":false}]}
{"op":"mcm","clk":"5322707164","pt":1646323352139,"mc":[{"id":"1.195532874","rc":[{"atb":[[1.63,17.84]],"id":40883678}],"con":true,"img":false}]}
{"op":"mcm","clk":"5322707664","pt":1646323357948,"mc":[{"id":"1.195532874","rc":[{"atb":[[2.52,8.18]],"id":40642034}],"con":true,"img":false}]}
{"op":"mcm","clk":"5322709734","pt":1646323383901,"mc":[{"id":"1.195532874","rc":[{"atb":[[2.94,0]],"id":37306244},{"atb":[[2.7,0]],"id":39614765}],"con":true,"img":false}]}
{"op":"mcm","clk":"5322710106","pt":1646323388534,"mc":[{"id":"1.195532874","rc":[{"atb":[[3.05,5.48]],"id":37306244}],"con":true,"img":false}]}
{"op":"mcm","clk":"5322710119","pt":1646323388748,"mc":[{"id":"1.195532874","rc":[{"atb":[[2.78,6.31]],"id":39614765}],"con":true,"img":false}]}
{"op":"mcm","clk":"5322717528","pt":1646323471644,"mc":[{"id":"1.195532874","rc":[{"atl":[[140,9.2]],"id":35985721}],"con":true,"img":false}]}
{"op":"mcm","clk":"5322727685","pt":1646323577329,"mc":[{"id":"1.195532874","rc":[{"atb":[[2.48,0]],"id":40642034}],"con":true,"img":false}]}
{"op":"mcm","clk":"5322727971","pt":1646323580330,"mc":[{"id":"1.195532874","rc":[{"atb":[[2.56,7.21]],"id":40642034}],"con":true,"img":false}]}
{"op":"mcm","clk":"5322730073","pt":1646323602329,"mc":[{"id":"1.195532874","rc":[{"atb":[[1.61,0]],"id":40883678}],"con":true,"img":false}]}
{"op":"mcm","clk":"5322731314","pt":1646323615039,"mc":[{"id":"1.195532874","rc":[{"atb":[[1.65,19.13]],"id":40883678}],"con":true,"img":false}]}
{"op":"mcm","clk":"5322732998","pt":1646323630593,"mc":[{"id":"1.195532874","rc":[{"atb":[[2.98,0]],"id":37306244},{"atb":[[2.74,0]],"id":39614765}],"con":true,"img":false}]}
{"op":"mcm","clk":"5322735046","pt":1646323646630,"mc":[{"id":"1.195532874","rc":[{"atb":[[2.82,6.83]],"id":39614765}],"con":true,"img":false}]}
{"op":"mcm","clk":"5322735054","pt":1646323646727,"mc":[{"id":"1.195532874","rc":[{"atb":[[3.15,5.78]],"id":37306244}],"con":true,"img":false}]}
{"op":"mcm","clk":"5322752860","pt":1646323818837,"mc":[{"id":"1.195532874","rc":[{"atb":[[2.52,0]],"id":40642034}],"con":true,"img":false}]}
{"op":"mcm","clk":"5322754332","pt":1646323830077,"mc":[{"id":"1.195532874","rc":[{"atb":[[2.6,7.77]],"id":40642034}],"con":true,"img":false}]}
{"op":"mcm","clk":"5322755076","pt":1646323836464,"mc":[{"id":"1.195532874","rc":[{"atb":[[1.63,0]],"id":40883678}],"con":true,"img":false}]}
{"op":"mcm","clk":"5322755383","pt":1646323838670,"mc":[{"id":"1.195532874","rc":[{"atb":[[1.67,16.78]],"id":40883678}],"con":true,"img":false}]}
{"op":"mcm","clk":"5322758883","pt":1646323867027,"mc":[{"id":"1.195532874","rc":[{"atb":[[3.05,0]],"id":37306244},{"atb":[[2.78,0]],"id":39614765}],"con":true,"img":false}]}
{"op":"mcm","clk":"5322759641","pt":1646323873131,"mc":[{"id":"1.195532874","rc":[{"atb":[[2.86,6.04]],"id":39614765}],"con":true,"img":false}]}
{"op":"mcm","clk":"5322759661","pt":1646323873341,"mc":[{"id":"1.195532874","rc":[{"atb":[[3.25,4.99]],"id":37306244}],"con":true,"img":false}]}
{"op":"mcm","clk":"5322780089","pt":1646324052310,"mc":[{"id":"1.195532874","rc":[{"atb":[[2.56,0]],"id":40642034}],"con":true,"img":false}]}
{"op":"mcm","clk":"5322780337","pt":1646324055229,"mc":[{"id":"1.195532874","rc":[{"atb":[[2.64,6.85]],"id":40642034}],"con":true,"img":false}]}
{"op":"mcm","clk":"5322781719","pt":1646324069829,"mc":[{"id":"1.195532874","rc":[{"atb":[[1.65,0]],"id":40883678}],"con":true,"img":false}]}
{"op":"mcm","clk":"5322782956","pt":1646324081455,"mc":[{"id":"1.195532874","rc":[{"atb":[[1.69,20.02]],"id":40883678}],"con":true,"img":false}]}
{"op":"mcm","clk":"5322785697","pt":1646324105699,"mc":[{"id":"1.195532874","rc":[{"atb":[[3.15,0]],"id":37306244},{"atb":[[2.82,0]],"id":39614765}],"con":true,"img":false}]}
{"op":"mcm","clk":"5322787814","pt":1646324122406,"mc":[{"id":"1.195532874","rc":[{"atb":[[3.35,5.29]],"id":37306244}],"con":true,"img":false}]}
{"op":"mcm","clk":"5322787837","pt":1646324122618,"mc":[{"id":"1.195532874","rc":[{"atb":[[2.9,6.54]],"id":39614765}],"con":true,"img":false}]}
{"op":"mcm","clk":"5322816396","pt":1646324288826,"mc":[{"id":"1.195532874","rc":[{"atb":[[2.6,0]],"id":40642034}],"con":true,"img":false}]}
{"op":"mcm","clk":"5322817507","pt":1646324300866,"mc":[{"id":"1.195532874","rc":[{"atb":[[2.68,7.4]],"id":40642034}],"con":true,"img":false}]}
{"op":"mcm","clk":"5322818080","pt":1646324306259,"mc":[{"id":"1.195532874","rc":[{"atb":[[1.67,0]],"id":40883678}],"con":true,"img":false}]}
{"op":"mcm","clk":"5322818554","pt":1646324310938,"mc":[{"id":"1.195532874","rc":[{"atb":[[1.71,15.83]],"id":40883678}],"con":true,"img":false}]}
{"op":"mcm","clk":"5322821369","pt":1646324338293,"mc":[{"id":"1.195532874","rc":[{"atb":[[3.25,0]],"id":37306244},{"atb":[[2.86,0]],"id":39614765}],"con":true,"img":false}]}
{"op":"mcm","clk":"5322821686","pt":1646324341490,"mc":[{"id":"1.195532874","rc":[{"atb":[[3.45,4.58]],"id":37306244}],"con":true,"img":false}]}
{"op":"mcm","clk":"5322821750","pt":1646324342078,"mc":[{"id":"1.195532874","rc":[{"atb":[[2.94,5.79]],"id":39614765}],"con":true,"img":false}]}
{"op":"mcm","clk":"5322837752","pt":1646324521099,"mc":[{"id":"1.195532874","rc":[{"atb":[[2.64,0]],"id":40642034}],"con":true,"img":false}]}
{"op":"mcm","clk":"5322838108","pt":1646324524174,"mc":[{"id":"1.195532874","rc":[{"atb":[[2.72,6.53]],"id":40642034}],"con":true,"img":false}]}
{"op":"mcm","clk":"5322840804","pt":1646324554376,"mc":[{"id":"1.195532874","rc":[{"atb":[[1.69,2]],"id":40883678}],"con":true,"img":false}]}
{"op":"mcm","clk":"5322842426","pt":1646324571819,"mc":[{"id":"1.195532874","rc":[{"atb":[[3.35,0]],"id":37306244},{"atb":[[2.9,0]],"id":39614765}],"con":true,"img":false}]}
{"op":"mcm","clk":"5322842497","pt":1646324572443,"mc":[{"id":"1.195532874","rc":[{"atb":[[1.73,17.03]],"id":40883678}],"con":true,"img":false}]}
{"op":"mcm","clk":"5322843777","pt":1646324586390,"mc":[{"id":"1.195532874","rc":[{"atb":[[3.55,4.87]],"id":37306244},{"atb":[[2.98,6.28]],"id":39614765}],"con":true,"img":false}]}
{"op":"mcm","clk":"5322862311","pt":1646324762167,"mc":[{"id":"1.195532874","rc":[{"atb":[[2.68,0]],"id":40642034}],"con":true,"img":false}]}
{"op":"mcm","clk":"5322863456","pt":1646324773380,"mc":[{"id":"1.195532874","rc":[{"atb":[[2.76,7.06]],"id":40642034}],"con":true,"img":false}]}
{"op":"mcm","clk":"5322865186","pt":1646324789096,"mc":[{"id":"1.195532874","rc":[{"atb":[[1.71,0]],"id":40883678}],"con":true,"img":false}]}
{"op":"mcm","clk":"5322865437","pt":1646324791496,"mc":[{"id":"1.195532874","rc":[{"atb":[[1.75,14.99]],"id":40883678}],"con":true,"img":false}]}
{"op":"mcm","clk":"5322866718","pt":1646324803121,"mc":[{"id":"1.195532874","rc":[{"atb":[[3.45,0]],"id":37306244},{"atb":[[2.94,0]],"id":39614765}],"con":true,"img":false}]}
{"op":"mcm","clk":"5322867087","pt":1646324806266,"mc":[{"id":"1.195532874","rc":[{"atb":[[3.65,4.24]],"id":37306244}],"con":true,"img":false}]}
{"op":"mcm","clk":"5322867095","pt":1646324806371,"mc":[{"id":"1.195532874","rc":[{"atb":[[3.05,5.48]],"id":39614765}],"con":true,"img":false}]}
{"op":"mcm","clk":"5322885856","pt":1646324996671,"mc":[{"id":"1.195532874","rc":[{"atb":[[2.72,0]],"id":40642034}],"con":true,"img":false}]}
{"op":"mcm","clk":"5322886014","pt":1646324998599,"mc":[{"id":"1.195532874","rc":[{"atb":[[2.8,6.24]],"id":40642034}],"con":true,"img":false}]}
{"op":"mcm","clk":"5322889286","pt":1646325032844,"mc":[{"id":"1.195532874","rc":[{"atb":[[1.73,0]],"id":40883678}],"con":true,"img":false}]}
{"op":"mcm","clk":"5322890601","pt":1646325046256,"mc":[{"id":"1.195532874","rc":[{"atb":[[3.55,0]],"id":37306244},{"atb":[[2.98,0]],"id":39614765}],"con":true,"img":false}]}
{"op":"mcm","clk":"5322890629","pt":1646325046569,"mc":[{"id":"1.195532874","rc":[{"atb":[[1.77,16.15]],"id":40883678}],"con":true,"img":false}]}
{"op":"mcm","clk":"5322891921","pt":1646325060659,"mc":[{"id":"1.195532874","rc":[{"atb":[[3.75,4.51]],"id":37306244}],"con":true,"img":false}]}
{"op":"mcm","clk":"5322891973","pt":1646325061180,"mc":[{"id":"1.195532874","rc":[{"atb":[[3.15,5.78]],"id":39614765}],"con":true,"img":false}]}
{"op":"mcm","clk":"5322909159","pt":1646325239685,"mc":[{"id":"1.195532874","rc":[{"atb":[[2.76,0]],"id":40642034}],"con":true,"img":false}]}
{"op":"mcm","clk":"5322910336","pt":1646325252435,"mc":[{"id":"1.195532874","rc":[{"atb":[[2.84,6.75]],"id":40642034}],"con":true,"img":false}]}
{"op":"mcm","clk":"5322911682","pt":1646325266837,"mc":[{"id":"1.195532874","rc":[{"atb":[[1.75,0]],"id":40883678}],"con":true,"img":false}]}
{"op":"mcm","clk":"5322911933","pt":1646325269758,"mc":[{"id":"1.195532874","rc":[{"atb":[[1.79,14.23]],"id":40883678}],"con":true,"img":false}]}
{"op":"mcm","clk":"5322912750","pt":1646325279349,"mc":[{"id":"1.195532874","rc":[{"atb":[[3.65,0]],"id":37306244},{"atb":[[3.05,0]],"id":39614765}],"con":true,"img":false}]}
{"op":"mcm","clk":"5322912897","pt":1646325281057,"mc":[{"id":"1.195532874","rc":[{"atb":[[3.25,4.99]],"id":39614765}],"con":true,"img":false}]}
{"op":"mcm","clk":"5322912908","pt":1646325281263,"mc":[{"id":"1.195532874","rc":[{"atb":[[2.66,6.77]],"id":37306244}],"con":true,"img":false}]}
{"op":"mcm","clk":"5322919959","pt":1646325361108,"mc":[{"id":"1.195532874","rc":[{"atl":[[3.25,49.03]],"id":40883678},{"trd":[[3.25,21.94]],"ltp":3.25,"tv":21.94,"id":40883678}],"con":true,"img":false}]}
{"op":"mcm","clk":"5322920487","pt":1646325366305,"mc":[{"id":"1.195532874","rc":[{"atb":[[5.6,2],[5.5,0]],"id":37306244},{"atb":[[10,2],[9.8,0]],"id":41469398},{"atb":[[5.1,2],[5,0]],"id":39614765},{"atb":[[10,2],[9.8,0]],"id":35985721},{"atb":[[3.7,0],[3.75,3.65]],"id":40642034}],"con":true,"img":false}]}
{"op":"mcm","clk":"5322921329","pt":1646325375412,"mc":[{"id":"1.195532874","rc":[{"atb":[[2.52,4.34]],"id":40883678}],"con":true,"img":false}]}
{"op":"mcm","clk":"5322921369","pt":1646325375828,"mc":[{"id":"1.195532874","rc":[{"atb":[[2.44,0]],"id":40883678}],"con":true,"img":false}]}
{"op":"mcm","clk":"5322921387","pt":1646325375988,"mc":[{"id":"1.195532874","rc":[{"atb":[[2.54,2]],"id":40883678}],"con":true,"img":false}]}
{"op":"mcm","clk":"5322927860","pt":1646325442835,"mc":[{"id":"1.195532874","rc":[{"spn":7.3,"spf":1.0,"id":37306244},{"spn":12.5,"spf":1.0,"id":41469398},{"spn":6.65,"spf":1.0,"id":39614765},{"spn":12.25,"spf":1.0,"id":35985721},{"atb":[[2.52,10.72]],"id":40883678},{"spn":2.53,"spf":1.0,"id":40883678}],"con":true,"img":false}]}
{"op":"mcm","clk":"5322930579","pt":1646325473464,"mc":[{"id":"1.195532874","rc":[{"atb":[[2.8,0]],"id":40642034}],"con":true,"img":false}]}
{"op":"mcm","clk":"5322930819","pt":1646325476608,"mc":[{"id":"1.195532874","rc":[{"atb":[[2.88,5.98]],"id":40642034}],"con":true,"img":false}]}
{"op":"mcm","clk":"5322933603","pt":1646325507544,"mc":[{"id":"1.195532874","rc":[{"atb":[[1.77,0]],"id":40883678}],"con":true,"img":false}]}
{"op":"mcm","clk":"5322934894","pt":1646325521884,"mc":[{"id":"1.195532874","rc":[{"atb":[[1.81,15.35]],"id":40883678}],"con":true,"img":false}]}
{"op":"mcm","clk":"5322947354","pt":1646325658908,"mc":[{"id":"1.195532874","rc":[{"atb":[[3.75,0]],"id":37306244},{"atb":[[3.15,0]],"id":39614765}],"con":true,"img":false}]}
{"op":"mcm","clk":"5322949178","pt":1646325677804,"mc":[{"id":"1.195532874","rc":[{"atb":[[2.7,7.31]],"id":37306244},{"atb":[[3.35,5.29]],"id":39614765}],"con":true,"img":false}]}
{"op":"mcm","clk":"5322953479","pt":1646325724207,"mc":[{"id":"1.195532874","rc":[{"atb":[[2.84,0]],"id":40642034}],"con":true,"img":false}]}
{"op":"mcm","clk":"5322954587","pt":1646325736175,"mc":[{"id":"1.195532874","rc":[{"atb":[[2.4,8.88]],"id":40642034}],"con":true,"img":false}]}
{"op":"mcm","clk":"5322954639","pt":1646325736695,"mc":[{"id":"1.195532874","rc":[{"atl":[[3.2,0.82]],"id":40883678}],"con":true,"img":false}]}
{"op":"mcm","clk":"5322954693","pt":1646325737377,"mc":[{"id":"1.195532874","rc":[{"atl":[[3.2,0.43]],"id":40883678}],"con":true,"img":false}]}
{"op":"mcm","clk":"5322955241","pt":1646325743052,"mc":[{"id":"1.195532874","rc":[{"atb":[[1.79,0]],"id":40883678}],"con":true,"img":false}]}
{"op":"mcm","clk":"5322955725","pt":1646325748051,"mc":[{"id":"1.195532874","rc":[{"atb":[[1.83,13.54]],"id":40883678}],"con":true,"img":false}]}
{"op":"mcm","clk":"5322968985","pt":1646325896106,"mc":[{"id":"1.195532874","rc":[{"atb":[[3.25,0]],"id":39614765}],"con":true,"img":false}]}
{"op":"mcm","clk":"5322969631","pt":1646325902384,"mc":[{"id":"1.195532874","rc":[{"atb":[[3.45,4.58]],"id":39614765}],"con":true,"img":false}]}
{"op":"mcm","clk":"5322970677","pt":1646325912957,"mc":[{"id":"1.195532874","rc":[{"atb":[[2.66,0]],"id":37306244}],"con":true,"img":false}]}
{"op":"mcm","clk":"5322970989","pt":1646325915935,"mc":[{"id":"1.195532874","rc":[{"atb":[[2.74,6.46]],"id":37306244}],"con":true,"img":false}]}
{"op":"mcm","clk":"5322971636","pt":1646325922052,"mc":[{"id":"1.195532874","rc":[{"atb":[[3.3,0]],"id":40642034}],"con":true,"img":false}]}
{"op":"mcm","clk":"5322971644","pt":1646325922147,"mc":[{"id":"1.195532874","rc":[{"atb":[[3.55,2]],"id":40642034}],"con":true,"img":false}]}
{"op":"mcm","clk":"5322975303","pt":1646325958221,"mc":[{"id":"1.195532874","rc":[{"atb":[[2.88,0]],"id":40642034}],"con":true,"img":false}]}
{"op":"mcm","clk":"5322975718","pt":1646325961995,"mc":[{"id":"1.195532874","rc":[{"atb":[[2.44,7.81]],"id":40642034}],"con":true,"img":false}]}
{"op":"mcm","clk":"5322977359","pt":1646325977860,"mc":[{"id":"1.195532874","rc":[{"atb":[[1.81,0]],"id":40883678}],"con":true,"img":false}]}
{"op":"mcm","clk":"5322978704","pt":1646325990259,"mc":[{"id":"1.195532874","rc":[{"atb":[[1.85,14.63]],"id":40883678}],"con":true,"img":false}]}
{"op":"mcm","clk":"5322992559","pt":1646326136920,"mc":[{"id":"1.195532874","rc":[{"atb":[[3.35,0]],"id":39614765}],"con":true,"img":false}]}
{"op":"mcm","clk":"5322994021","pt":1646326154355,"mc":[{"id":"1.195532874","rc":[{"atb":[[3.55,4.87]],"id":39614765}],"con":true,"img":false}]}
{"op":"mcm","clk":"5322994708","pt":1646326163113,"mc":[{"id":"1.195532874","rc":[{"atb":[[2.7,0]],"id":37306244}],"con":true,"img":false}]}
{"op":"mcm","clk":"5322995367","pt":1646326172079,"mc":[{"id":"1.195532874","rc":[{"atb":[[2.78,6.99]],"id":37306244}],"con":true,"img":false}]}
{"op":"mcm","clk":"5322997992","pt":1646326207145,"mc":[{"id":"1.195532874","rc":[{"atb":[[2.4,0]],"id":40642034}],"con":true,"img":false}]}
{"op":"mcm","clk":"5322998274","pt":1646326210750,"mc":[{"id":"1.195532874","rc":[{"atb":[[1.83,0]],"id":40883678}],"con":true,"img":false}]}
{"op":"mcm","clk":"5322998507","pt":1646326213573,"mc":[{"id":"1.195532874","rc":[{"atb":[[1.87,12.92]],"id":40883678}],"con":true,"img":false}]}
{"op":"mcm","clk":"5322998803","pt":1646326217396,"mc":[{"id":"1.195532874","rc":[{"atb":[[2.48,8.4]],"id":40642034}],"con":true,"img":false}]}
{"op":"mcm","clk":"5323000557","pt":1646326240226,"mc":[{"id":"1.195532874","rc":[{"atl":[[3.25,47.47],[3.2,0]],"id":40883678},{"trd":[[3.25,25.06],[3.2,0.87]],"ltp":3.25,"tv":25.93,"id":40883678}],"con":true,"img":false}]}
{"op":"mcm","clk":"5323000599","pt":1646326240754,"mc":[{"id":"1.195532874","rc":[{"atb":[[2.52,11.55]],"id":40883678}],"con":true,"img":false}]}
{"op":"mcm","clk":"5323000658","pt":1646326241755,"mc":[{"id":"1.195532874","rc":[{"atb":[[2.52,11.3]],"id":40883678}],"con":true,"img":false}]}
{"op":"mcm","clk":"5323001269","pt":1646326250292,"mc":[{"id":"1.195532874","rc":[{"atb":[[10,0]],"id":35985721},{"atl":[[10,3]],"id":35985721},{"trd":[[10,4]],"ltp":10.0,"tv":4.0,"id":35985721}],"con":true,"img":false}]}
{"op":"mcm","clk":"5323001292","pt":1646326250452,"mc":[{"id":"1.195532874","rc":[{"atb":[[6.8,1.48]],"id":35985721}],"con":true,"img":false}]}
{"op":"mcm","clk":"5323001524","pt":1646326253751,"mc":[{"id":"1.195532874","rc":[{"atb":[[6.8,0]],"id":35985721}],"con":true,"img":false}]}
{"op":"mcm","clk":"5323001963","pt":1646326259562,"mc":[{"id":"1.195532874","rc":[{"atb":[[2.66,7.49]],"id":35985721}],"con":true,"img":false}]}
{"op":"mcm","clk":"5323001968","pt":1646326259668,"mc":[{"id":"1.195532874","rc":[{"atb":[[6.8,1.48]],"id":35985721}],"con":true,"img":false}]}
{"op":"mcm","clk":"5323002201","pt":1646326262904,"mc":[{"id":"1.195532874","rc":[{"atb":[[6.8,0]],"id":35985721}],"con":true,"img":false}]}
{"op":"mcm","clk":"5323002219","pt":1646326263159,"mc":[{"id":"1.195532874","rc":[{"atb":[[6.8,1.48]],"id":35985721}],"con":true,"img":false}]}
{"op":"mcm","clk":"5323002494","pt":1646326266610,"mc":[{"id":"1.195532874","rc":[{"atb":[[6.8,0]],"id":35985721}],"con":true,"img":false}]}
{"op":"mcm","clk":"5323002517","pt":1646326266769,"mc":[{"id":"1.195532874","rc":[{"atb":[[6.8,1.48]],"id":35985721}],"con":true,"img":false}]}
{"op":"mcm","clk":"5323002648","pt":1646326268399,"mc":[{"id":"1.195532874","rc":[{"spn":8.4,"spf":1.0,"id":35985721},{"atb":[[2.58,5.21]],"id":40883678},{"spn":2.58,"spf":1.0,"id":40883678}],"con":true,"img":false}]}
{"op":"mcm","clk":"5323002656","pt":1646326268505,"mc":[{"id":"1.195532874","rc":[{"atb":[[2.76,4.68]],"id":35985721},{"atb":[[2.2,6.86]],"id":40642034}],"con":true,"img":false}]}
{"op":"mcm","clk":"5323002667","pt":1646326268611,"mc":[{"id":"1.195532874","rc":[{"atb":[[2.46,5.65]],"id":39614765}],"con":true,"img":false}]}
{"op":"mcm","clk":"5323002679","pt":1646326268724,"mc":[{"id":"1.195532874","rc":[{"atb":[[2.76,4.68]],"id":41469398},{"atb":[[2.54,0]],"id":40883678}],"con":true,"img":false}]}
{"op":"mcm","clk":"5323002685","pt":1646326268765,"mc":[{"id":"1.195532874","rc":[{"atb":[[2.76,4.68]],"id":37306244}],"con":true,"img":false}]}
{"op":"mcm","clk":"5323002694","pt":1646326268871,"mc":[{"id":"1.195532874","rc":[{"atb":[[2.6,2]],"id":40883678}],"con":true,"img":false}]}
{"op":"mcm","clk":"5323002719","pt":1646326269289,"mc":[{"id":"1.195532874","rc":[{"atb":[[2.52,10.72]],"id":40883678}],"con":true,"img":false}]}
{"op":"mcm","clk":"5323002728","pt":1646326269394,"mc":[{"id":"1.195532874","rc":[{"atb":[[2.6,2.58]],"id":40883678}],"con":true,"img":false}]}
{"op":"mcm","clk":"5323002780","pt":1646326270140,"mc":[{"id":"1.195532874","rc":[{"atb":[[6.8,0]],"id":35985721}],"con":true,"img":false}]}
{"op":"mcm","clk":"5323002796","pt":1646326270285,"mc":[{"id":"1.195532874","rc":[{"atb":[[6.8,1.48]],"id":35985721}],"con":true,"img":false}]}
{"op":"mcm","clk":"5323002809","pt":1646326270498,"mc":[{"id":"1.195532874","rc":[{"atb":[[2.58,0]],"id":40883678}],"con":true,"img":false}]}
{"op":"mcm","clk":"5323002862","pt":1646326271032,"mc":[{"id":"1.195532874","rc":[{"atb":[[2.6,2]],"id":40883678}],"con":true,"img":false}]}
{"op":"mcm","clk":"5323002871","pt":1646326271127,"mc":[{"id":"1.195532874","rc":[{"atb":[[2.54,0.58]],"id":40883678}],"con":true,"img":false}]}
{"op":"mcm","clk":"5323003077","pt":1646326273620,"mc":[{"id":"1.195532874","rc":[{"atb":[[6.8,0]],"id":35985721}],"con":true,"img":false}]}
{"op":"mcm","clk":"5323003097","pt":1646326273777,"mc":[{"id":"1.195532874","rc":[{"atb":[[6.8,1.48]],"id":35985721}],"con":true,"img":false}]}
{"op":"mcm","clk":"5323003162","pt":1646326274718,"mc":[{"id":"1.195532874","rc":[{"atb":[[2.8,1.69]],"id":37306244}],"con":true,"img":false}]}
{"op":"mcm","clk":"5323003337","pt":1646326277029,"mc":[{"id":"1.195532874","rc":[{"atb":[[6.8,0]],"id":35985721}],"con":true,"img":false}]}
{"op":"mcm","clk":"5323003357","pt":1646326277222,"mc":[{"id":"1.195532874","rc":[{"atb":[[6.8,1.48]],"id":35985721}],"con":true,"img":false}]}
{"op":"mcm","clk":"5323003722","pt":1646326280408,"mc":[{"id":"1.195532874","rc":[{"atb":[[6.8,0]],"id":35985721}],"con":true,"img":false}]}
{"op":"mcm","clk":"5323003732","pt":1646326280511,"mc":[{"id":"1.195532874","rc":[{"atb":[[6.8,1.48]],"id":35985721}],"con":true,"img":false}]}
{"op":"mcm","clk":"5323004004","pt":1646326283831,"mc":[{"id":"1.195532874","rc":[{"atb":[[6.8,0]],"id":35985721}],"con":true,"img":false}]}
{"op":"mcm","clk":"5323004024","pt":1646326284053,"mc":[{"id":"1.195532874","rc":[{"atb":[[6.8,1.48]],"id":35985721}],"con":true,"img":false}]}
{"op":"mcm","clk":"5323004282","pt":1646326287246,"mc":[{"id":"1.195532874","rc":[{"atb":[[6.8,0]],"id":35985721}],"con":true,"img":false}]}
{"op":"mcm","clk":"5323004301","pt":1646326287442,"mc":[{"id":"1.195532874","rc":[{"atb":[[6.8,1.48]],"id":35985721}],"con":true,"img":false}]}
{"op":"mcm","clk":"5323004550","pt":1646326290961,"mc":[{"id":"1.195532874","rc":[{"atb":[[6.8,0]],"id":35985721}],"con":true,"img":false}]}
{"op":"mcm","clk":"5323004593","pt":1646326291099,"mc":[{"id":"1.195532874","rc":[{"atb":[[6.8,1.48]],"id":35985721}],"con":true,"img":false}]}
{"op":"mcm","clk":"5323004848","pt":1646326294308,"mc":[{"id":"1.195532874","rc":[{"atb":[[6.8,0]],"id":35985721}],"con":true,"img":false}]}
{"op":"mcm","clk":"5323010644","pt":1646326370207,"mc":[{"id":"1.195532874","rc":[{"spn":8.3,"spf":1.0,"id":35985721},{"atb":[[3.45,0]],"id":39614765},{"spn":2.57,"spf":1.0,"id":40883678}],"con":true,"img":false}]}
{"op":"mcm","clk":"5323010655","pt":1646326370407,"mc":[{"id":"1.195532874","rc":[{"atb":[[6.8,1.48]],"id":35985721}],"con":true,"img":false}]}
{"op":"mcm","clk":"5323010852","pt":1646326373385,"mc":[{"id":"1.195532874","rc":[{"atb":[[2.38,8.14]],"id":39614765}],"con":true,"img":false}]}
{"op":"mcm","clk":"5323010868","pt":1646326373593,"mc":[{"id":"1.195532874","rc":[{"atb":[[6.8,0]],"id":35985721}],"con":true,"img":false}]}
{"op":"mcm","clk":"5323010875","pt":1646326373697,"mc":[{"id":"1.195532874","rc":[{"atb":[[6.8,1.48]],"id":35985721}],"con":true,"img":false}]}
{"op":"mcm","clk":"5323011091","pt":1646326376890,"mc":[{"id":"1.195532874","rc":[{"atb":[[6.8,0]],"id":35985721}],"con":true,"img":false}]}
{"op":"mcm","clk":"5323011099","pt":1646326376993,"mc":[{"id":"1.195532874","rc":[{"atb":[[6.8,1.48]],"id":35985721}],"con":true,"img":false}]}
{"op":"mcm","clk":"5323011307","pt":1646326380208,"mc":[{"id":"1.195532874","rc":[{"atb":[[6.8,0]],"id":35985721}],"con":true,"img":false}]}
{"op":"mcm","clk":"5323011314","pt":1646326380316,"mc":[{"id":"1.195532874","rc":[{"atb":[[6.8,1.48]],"id":35985721}],"con":true,"img":false}]}
{"op":"mcm","clk":"5323011535","pt":1646326383501,"mc":[{"id":"1.195532874","rc":[{"atb":[[6.8,0]],"id":35985721}],"con":true,"img":false}]}
{"op":"mcm","clk":"5323011543","pt":1646326383605,"mc":[{"id":"1.195532874","rc":[{"atb":[[6.8,1.48]],"id":35985721}],"con":true,"img":false}]}
{"op":"mcm","clk":"5323011800","pt":1646326386835,"mc":[{"id":"1.195532874","rc":[{"atb":[[6.8,0]],"id":35985721}],"con":true,"img":false}]}
{"op":"mcm","clk":"5323011808","pt":1646326386954,"mc":[{"id":"1.195532874","rc":[{"atb":[[6.8,1.48]],"id":35985721}],"con":true,"img":false}]}
{"op":"mcm","clk":"5323012062","pt":1646326390267,"mc":[{"id":"1.195532874","rc":[{"atb":[[6.8,0]],"id":35985721}],"con":true,"img":false}]}
{"op":"mcm","clk":"5323012082","pt":1646326390428,"mc":[{"id":"1.195532874","rc":[{"atb":[[6.8,1.48]],"id":35985721}],"con":true,"img":false}]}
{"op":"mcm","clk":"5323012351","pt":1646326393653,"mc":[{"id":"1.195532874","rc":[{"atb":[[6.8,0]],"id":35985721}],"con":true,"img":false}]}
{"op":"mcm","clk":"5323012369","pt":1646326393867,"mc":[{"id":"1.195532874","rc":[{"atb":[[6.8,1.48]],"id":35985721}],"con":true,"img":false}]}
{"op":"mcm","clk":"5323012637","pt":1646326397175,"mc":[{"id":"1.195532874","rc":[{"atb":[[2.74,0]],"id":37306244},{"atb":[[6.8,0]],"id":35985721}],"con":true,"img":false}]}
{"op":"mcm","clk":"5323012650","pt":1646326397383,"mc":[{"id":"1.195532874","rc":[{"atb":[[6.8,1.48]],"id":35985721}],"con":true,"img":false}]}
{"op":"mcm","clk":"5323012802","pt":1646326399574,"mc":[{"id":"1.195532874","rc":[{"atb":[[2.84,6.1]],"id":37306244}],"con":true,"img":false}]}
{"op":"mcm","clk":"5323012826","pt":1646326399883,"mc":[{"id":"1.195532874","rc":[{"atb":[[2.8,0]],"id":37306244}],"con":true,"img":false}]}
{"op":"mcm","clk":"5323012832","pt":1646326399988,"mc":[{"id":"1.195532874","rc":[{"atb":[[2.86,1.69]],"id":37306244}],"con":true,"img":false}]}
{"op":"mcm","clk":"5323012887","pt":1646326400689,"mc":[{"id":"1.195532874","rc":[{"atb":[[6.8,0]],"id":35985721}],"con":true,"img":false}]}
{"op":"mcm","clk":"5323012901","pt":1646326400889,"mc":[{"id":"1.195532874","rc":[{"atb":[[6.8,1.48]],"id":35985721}],"con":true,"img":false}]}
{"op":"mcm","clk":"5323013160","pt":1646326404076,"mc":[{"id":"1.195532874","rc":[{"atb":[[6.8,0]],"id":35985721}],"con":true,"img":false}]}
{"op":"mcm","clk":"5323013174","pt":1646326404281,"mc":[{"id":"1.195532874","rc":[{"atb":[[6.8,1.48]],"id":35985721}],"con":true,"img":false}]}
{"op":"mcm","clk":"5323013377","pt":1646326407473,"mc":[{"id":"1.195532874","rc":[{"atb":[[6.8,0]],"id":35985721}],"con":true,"img":false}]}
{"op":"mcm","clk":"5323013390","pt":1646326407685,"mc":[{"id":"1.195532874","rc":[{"atb":[[6.8,1.48]],"id":35985721}],"con":true,"img":false}]}
{"op":"mcm","clk":"5323013629","pt":1646326410906,"mc":[{"id":"1.195532874","rc":[{"atb":[[6.8,0]],"id":35985721}],"con":true,"img":false}]}
{"op":"mcm","clk":"5323013643","pt":1646326411082,"mc":[{"id":"1.195532874","rc":[{"atb":[[6.8,1.48]],"id":35985721}],"con":true,"img":false}]}
{"op":"mcm","clk":"5323013867","pt":1646326414410,"mc":[{"id":"1.195532874","rc":[{"atb":[[6.8,0]],"id":35985721}],"con":true,"img":false}]}
{"op":"mcm","clk":"5323013882","pt":1646326414569,"mc":[{"id":"1.195532874","rc":[{"atb":[[6.8,1.48]],"id":35985721}],"con":true,"img":false}]}
{"op":"mcm","clk":"5323014103","pt":1646326417912,"mc":[{"id":"1.195532874","rc":[{"atb":[[6.8,0]],"id":35985721}],"con":true,"img":false}]}
{"op":"mcm","clk":"5323014117","pt":1646326418069,"mc":[{"id":"1.195532874","rc":[{"atb":[[6.8,1.48]],"id":35985721}],"con":true,"img":false}]}
{"op":"mcm","clk":"5323014321","pt":1646326421322,"mc":[{"id":"1.195532874","rc":[{"atb":[[6.8,0]],"id":35985721}],"con":true,"img":false}]}
{"op":"mcm","clk":"5323014337","pt":1646326421479,"mc":[{"id":"1.195532874","rc":[{"atb":[[6.8,1.48]],"id":35985721}],"con":true,"img":false}]}
{"op":"mcm","clk":"5323014552","pt":1646326424827,"mc":[{"id":"1.195532874","rc":[{"atb":[[6.8,0]],"id":35985721}],"con":true,"img":false}]}
{"op":"mcm","clk":"5323014572","pt":1646326424977,"mc":[{"id":"1.195532874","rc":[{"atb":[[6.8,1.48]],"id":35985721}],"con":true,"img":false}]}
{"op":"mcm","clk":"5323014826","pt":1646326428226,"mc":[{"id":"1.195532874","rc":[{"atb":[[6.8,0]],"id":35985721}],"con":true,"img":false}]}
{"op":"mcm","clk":"5323014839","pt":1646326428430,"mc":[{"id":"1.195532874","rc":[{"atb":[[6.8,1.48]],"id":35985721}],"con":true,"img":false}]}
{"op":"mcm","clk":"5323015135","pt":1646326431840,"mc":[{"id":"1.195532874","rc":[{"atb":[[6.8,0]],"id":35985721}],"con":true,"img":false}]}
{"op":"mcm","clk":"5323015153","pt":1646326432015,"mc":[{"id":"1.195532874","rc":[{"atb":[[6.8,1.48]],"id":35985721}],"con":true,"img":false}]}
{"op":"mcm","clk":"5323015420","pt":1646326435338,"mc":[{"id":"1.195532874","rc":[{"atb":[[6.8,0]],"id":35985721}],"con":true,"img":false}]}
{"op":"mcm","clk":"5323015437","pt":1646326435504,"mc":[{"id":"1.195532874","rc":[{"atb":[[6.8,1.48]],"id":35985721}],"con":true,"img":false}]}
{"op":"mcm","clk":"5323015669","pt":1646326438734,"mc":[{"id":"1.195532874","rc":[{"atb":[[6.8,0]],"id":35985721}],"con":true,"img":false}]}
{"op":"mcm","clk":"5323015933","pt":1646326442250,"mc":[{"id":"1.195532874","rc":[{"atb":[[2.44,0]],"id":40642034}],"con":true,"img":false}]}
{"op":"mcm","clk":"5323015951","pt":1646326442443,"mc":[{"id":"1.195532874","rc":[{"atb":[[6.8,1.48]],"id":35985721}],"con":true,"img":false}]}
{"op":"mcm","clk":"5323016197","pt":1646326445374,"mc":[{"id":"1.195532874","rc":[{"atb":[[2.52,7.39]],"id":40642034}],"con":true,"img":false}]}
{"op":"mcm","clk":"5323016228","pt":1646326445645,"mc":[{"id":"1.195532874","rc":[{"atb":[[6.8,0]],"id":35985721}],"con":true,"img":false}]}
{"op":"mcm","clk":"5323016241","pt":1646326445846,"mc":[{"id":"1.195532874","rc":[{"atb":[[6.8,1.48]],"id":35985721}],"con":true,"img":false}]}
{"op":"mcm","clk":"5323016513","pt":1646326449068,"mc":[{"id":"1.195532874","rc":[{"atb":[[6.8,0]],"id":35985721}],"con":true,"img":false}]}
{"op":"mcm","clk":"5323016523","pt":1646326449211,"mc":[{"id":"1.195532874","rc":[{"atb":[[6.8,1.48]],"id":35985721}],"con":true,"img":false}]}
{"op":"mcm","clk":"5323016633","pt":1646326450792,"mc":[{"id":"1.195532874","rc":[{"atb":[[1.85,0]],"id":40883678}],"con":true,"img":false}]}
{"op":"mcm","clk":"5323016730","pt":1646326452395,"mc":[{"id":"1.195532874","rc":[{"atb":[[6.8,0]],"id":35985721}],"con":true,"img":false}]}
{"op":"mcm","clk":"5323016752","pt":1646326452552,"mc":[{"id":"1.195532874","rc":[{"atb":[[6.8,1.48]],"id":35985721}],"con":true,"img":false}]}
{"op":"mcm","clk":"5323016992","pt":1646326455874,"mc":[{"id":"1.195532874","rc":[{"atb":[[6.8,0]],"id":35985721}],"con":true,"img":false}]}
{"op":"mcm","clk":"5323017693","pt":1646326466797,"mc":[{"id":"1.195532874","rc":[{"atb":[[1.89,13.97]],"id":40883678}],"con":true,"img":false}]}
{"op":"mcm","clk":"5323017702","pt":1646326466901,"mc":[{"id":"1.195532874","rc":[{"atb":[[6.8,1.48]],"id":35985721}],"con":true,"img":false}]}
{"op":"mcm","clk":"5323017979","pt":1646326470234,"mc":[{"id":"1.195532874","rc":[{"atb":[[6.8,0]],"id":35985721}],"con":true,"img":false}]}
{"op":"mcm","clk":"5323017993","pt":1646326470391,"mc":[{"id":"1.195532874","rc":[{"atb":[[6.8,1.48]],"id":35985721}],"con":true,"img":false}]}
{"op":"mcm","clk":"5323018205","pt":1646326473703,"mc":[{"id":"1.195532874","rc":[{"atb":[[6.8,0]],"id":35985721}],"con":true,"img":false}]}
{"op":"mcm","clk":"5323018896","pt":1646326484256,"mc":[{"id":"1.195532874","rc":[{"atb":[[4.8,0]],"id":35985721}],"con":true,"img":false}]}
{"op":"mcm","clk":"5323018909","pt":1646326484474,"mc":[{"id":"1.195532874","rc":[{"atb":[[6.8,1.48]],"id":35985721}],"con":true,"img":false}]}
{"op":"mcm","clk":"5323019063","pt":1646326487218,"mc":[{"id":"1.195532874","rc":[{"atb":[[2.7,6.61]],"id":35985721}],"con":true,"img":false}]}
{"op":"mcm","clk":"5323019077","pt":1646326487427,"mc":[{"id":"1.195532874","rc":[{"atb":[[2.78,1.63]],"id":35985721}],"con":true,"img":false}]}
{"op":"mcm","clk":"5323019096","pt":1646326487739,"mc":[{"id":"1.195532874","rc":[{"atb":[[6.8,0]],"id":35985721}],"con":true,"img":false}]}
{"op":"mcm","clk":"5323019104","pt":1646326487845,"mc":[{"id":"1.195532874","rc":[{"atb":[[6.8,1.48]],"id":35985721}],"con":true,"img":false}]}
{"op":"mcm","clk":"5323019369","pt":1646326491065,"mc":[{"id":"1.195532874","rc":[{"atb":[[6.8,0]],"id":35985721}],"con":true,"img":false}]}
{"op":"mcm","clk":"5323019382","pt":1646326491274,"mc":[{"id":"1.195532874","rc":[{"atb":[[6.8,1.48]],"id":35985721}],"con":true,"img":false}]}
{"op":"mcm","clk":"5323019596","pt":1646326494459,"mc":[{"id":"1.195532874","rc":[{"atb":[[6.8,0]],"id":35985721}],"con":true,"img":false}]}
{"op":"mcm","clk":"5323019601","pt":1646326494565,"mc":[{"id":"1.195532874","rc":[{"atb":[[6.8,1.48]],"id":35985721}],"con":true,"img":false}]}
{"op":"mcm","clk":"5323019811","pt":1646326497743,"mc":[{"id":"1.195532874","rc":[{"atb":[[6.8,0]],"id":35985721}],"con":true,"img":false}]}
{"op":"mcm","clk":"5323020804","pt":1646326512309,"mc":[{"id":"1.195532874","rc":[{"atb":[[2.78,0]],"id":37306244},{"atb":[[2.66,0]],"id":35985721}],"con":true,"img":false}]}
{"op":"mcm","clk":"5323020821","pt":1646326512516,"mc":[{"id":"1.195532874","rc":[{"atb":[[6.8,1.48]],"id":35985721}],"con":true,"img":false}]}
{"op":"mcm","clk":"5323021018","pt":1646326515788,"mc":[{"id":"1.195532874","rc":[{"atb":[[6.8,0]],"id":35985721}],"con":true,"img":false}]}
{"op":"mcm","clk":"5323021037","pt":1646326515995,"mc":[{"id":"1.195532874","rc":[{"atb":[[6.8,1.48]],"id":35985721}],"con":true,"img":false}]}
{"op":"mcm","clk":"5323021234","pt":1646326519219,"mc":[{"id":"1.195532874","rc":[{"atb":[[6.8,0]],"id":35985721}],"con":true,"img":false}]}
{"op":"mcm","clk":"5323021351","pt":1646326521110,"mc":[{"id":"1.195532874","rc":[{"atb":[[2.9,6.54]],"id":37306244}],"con":true,"img":false}]}
{"op":"mcm","clk":"5323021369","pt":1646326521317,"mc":[{"id":"1.195532874","rc":[{"atb":[[6.8,1.48]],"id":35985721}],"con":true,"img":false}]}
{"op":"mcm","clk":"5323021376","pt":1646326521422,"mc":[{"id":"1.195532874","rc":[{"atb":[[2.82,6.83]],"id":35985721}],"con":true,"img":false}]}
{"op":"mcm","clk":"5323021459","pt":1646326522312,"mc":[{"id":"1.195532874","rc":[{"atb":[[2.86,0]],"id":37306244},{"atb":[[2.78,0]],"id":35985721}],"con":true,"img":false}]}
{"op":"mcm","clk":"5323021467","pt":1646326522420,"mc":[{"id":"1.195532874","rc":[{"atb":[[2.92,1.69]],"id":37306244},{"atb":[[2.84,1.63]],"id":35985721}],"con":true,"img":false}]}
{"op":"mcm","clk":"5323021644","pt":1646326524509,"mc":[{"id":"1.195532874","rc":[{"atb":[[6.8,0]],"id":35985721}],"con":true,"img":false}]}
{"op":"mcm","clk":"5323021652","pt":1646326524616,"mc":[{"id":"1.195532874","rc":[{"atb":[[6.8,1.48]],"id":35985721}],"con":true,"img":false}]}
{"op":"mcm","clk":"5323021897","pt":1646326528031,"mc":[{"id":"1.195532874","rc":[{"atb":[[6.8,0]],"id":35985721}],"con":true,"img":false}]}
{"op":"mcm","clk":"5323025650","pt":1646326581714,"mc":[{"id":"1.195532874","rc":[{"atl":[[24,15.2]],"id":35985721},{"atb":[[1.39,0]],"id":40883678}],"con":true,"img":false}]}
{"op":"mcm","clk":"5323025663","pt":1646326581861,"mc":[{"id":"1.195532874","rc":[{"atb":[[6.8,1.48]],"id":35985721}],"con":true,"img":false}]}
{"op":"mcm","clk":"5323025872","pt":1646326585201,"mc":[{"id":"1.195532874","rc":[{"atb":[[6.8,0]],"id":35985721}],"con":true,"img":false}]}
{"op":"mcm","clk":"5323025888","pt":1646326585361,"mc":[{"id":"1.195532874","rc":[{"atb":[[6.8,1.48]],"id":35985721}],"con":true,"img":false}]}
{"op":"mcm","clk":"5323026080","pt":1646326588593,"mc":[{"id":"1.195532874","rc":[{"atb":[[6.8,0]],"id":35985721}],"con":true,"img":false}]}
{"op":"mcm","clk":"5323027423","pt":1646326610541,"mc":[{"id":"1.195532874","rc":[{"atb":[[3.55,0]],"id":39614765}],"con":true,"img":false}]}
{"op":"mcm","clk":"5323027435","pt":1646326610702,"mc":[{"id":"1.195532874","rc":[{"atb":[[6.8,1.48]],"id":35985721}],"con":true,"img":false}]}
{"op":"mcm","clk":"5323027487","pt":1646326611535,"mc":[{"id":"1.195532874","rc":[{"atb":[[2.48,1.67]],"id":39614765}],"con":true,"img":false}]}
{"op":"mcm","clk":"5323027688","pt":1646326614105,"mc":[{"id":"1.195532874","rc":[{"atb":[[6.8,0]],"id":35985721}],"con":true,"img":false}]}
{"op":"mcm","clk":"5323028588","pt":1646326627661,"mc":[{"id":"1.195532874","rc":[{"atb":[[2.52,8.18]],"id":39614765}],"con":true,"img":false}]}
{"op":"mcm","clk":"5323028600","pt":1646326627870,"mc":[{"id":"1.195532874","rc":[{"atb":[[6.8,1.48]],"id":35985721}],"con":true,"img":false}]}
{"op":"mcm","clk":"5323028655","pt":1646326628553,"mc":[{"id":"1.195532874","rc":[{"atb":[[2.48,0]],"id":39614765}],"con":true,"img":false}]}
{"op":"mcm","clk":"5323028665","pt":1646326628652,"mc":[{"id":"1.195532874","rc":[{"atb":[[2.54,1.67]],"id":39614765}],"con":true,"img":false}]}
{"op":"mcm","clk":"5323028817","pt":1646326631067,"mc":[{"id":"1.195532874","rc":[{"atb":[[6.8,0]],"id":35985721}],"con":true,"img":false}]}
{"op":"mcm","clk":"5323028830","pt":1646326631276,"mc":[{"id":"1.195532874","rc":[{"atb":[[6.8,1.48]],"id":35985721}],"con":true,"img":false}]}
{"op":"mcm","clk":"5323029017","pt":1646326634495,"mc":[{"id":"1.195532874","rc":[{"atb":[[6.8,0]],"id":35985721}],"con":true,"img":false}]}
{"op":"mcm","clk":"5323029028","pt":1646326634654,"mc":[{"id":"1.195532874","rc":[{"atb":[[2.84,0]],"id":37306244},{"atb":[[6.8,1.48]],"id":35985721}],"con":true,"img":false}]}
{"op":"mcm","clk":"5323029068","pt":1646326635278,"mc":[{"id":"1.195532874","rc":[{"atb":[[3.3,40],[2.74,58.62]],"id":35985721}],"con":true,"img":false}]}
{"op":"mcm","clk":"5323029169","pt":1646326637262,"mc":[{"id":"1.195532874","rc":[{"atb":[[2.76,0]],"id":35985721}],"con":true,"img":false}]}
{"op":"mcm","clk":"5323029177","pt":1646326637370,"mc":[{"id":"1.195532874","rc":[{"atb":[[2.96,5.73]],"id":37306244}],"con":true,"img":false}]}
{"op":"mcm","clk":"5323029191","pt":1646326637679,"mc":[{"id":"1.195532874","rc":[{"atb":[[2.84,0]],"id":35985721}],"con":true,"img":false}]}
{"op":"mcm","clk":"5323029198","pt":1646326637785,"mc":[{"id":"1.195532874","rc":[{"atb":[[3.35,1.63]],"id":35985721}],"con":true,"img":false}]}
{"op":"mcm","clk":"5323029205","pt":1646326637888,"mc":[{"id":"1.195532874","rc":[{"atb":[[6.8,0]],"id":35985721}],"con":true,"img":false}]}
{"op":"mcm","clk":"5323029241","pt":1646326638461,"mc":[{"id":"1.195532874","rc":[{"atb":[[2.92,0]],"id":37306244}],"con":true,"img":false}]}
{"op":"mcm","clk":"5323029247","pt":1646326638565,"mc":[{"id":"1.195532874","rc":[{"atb":[[2.98,1.69]],"id":37306244},{"atb":[[6.8,1.48]],"id":35985721}],"con":true,"img":false}]}
{"op":"mcm","clk":"5323029439","pt":1646326641861,"mc":[{"id":"1.195532874","rc":[{"atb":[[6.8,0]],"id":35985721}],"con":true,"img":false}]}
{"op":"mcm","clk":"5323029445","pt":1646326641963,"mc":[{"id":"1.195532874","rc":[{"atb":[[6.8,1.48]],"id":35985721}],"con":true,"img":false}]}
{"op":"mcm","clk":"5323029632","pt":1646326645202,"mc":[{"id":"1.195532874","rc":[{"atb":[[6.8,0]],"id":35985721}],"con":true,"img":false}]}
{"op":"mcm","clk":"5323029640","pt":1646326645413,"mc":[{"id":"1.195532874","rc":[{"atb":[[6.8,1.48]],"id":35985721}],"con":true,"img":false}]}
{"op":"mcm","clk":"5323029823","pt":1646326648592,"mc":[{"id":"1.195532874","rc":[{"atb":[[6.8,0]],"id":35985721}],"con":true,"img":false}]}
{"op":"mcm","clk":"5323029829","pt":1646326648697,"mc":[{"id":"1.195532874","rc":[{"atb":[[6.8,1.48]],"id":35985721}],"con":true,"img":false}]}
{"op":"mcm","clk":"5323029877","pt":1646326649476,"mc":[{"id":"1.195532874","rc":[{"atb":[[3.4,2.49]],"id":35985721}],"con":true,"img":false}]}
{"op":"mcm","clk":"5323029999","pt":1646326651925,"mc":[{"id":"1.195532874","rc":[{"atb":[[6.8,0]],"id":35985721}],"con":true,"img":false}]}
{"op":"mcm","clk":"5323030017","pt":1646326652083,"mc":[{"id":"1.195532874","rc":[{"atb":[[6.8,1.48]],"id":35985721}],"con":true,"img":false}]}
{"op":"mcm","clk":"5323030135","pt":1646326653910,"mc":[{"id":"1.195532874","rc":[{"atb":[[3.4,6.54]],"id":35985721}],"con":true,"img":false}]}
{"op":"mcm","clk":"5323030164","pt":1646326654483,"mc":[{"id":"1.195532874","rc":[{"atb":[[3.35,0]],"id":35985721}],"con":true,"img":false}]}
{"op":"mcm","clk":"5323030169","pt":1646326654638,"mc":[{"id":"1.195532874","rc":[{"atb":[[3.45,1.63]],"id":35985721}],"con":true,"img":false}]}
{"op":"mcm","clk":"5323030224","pt":1646326655421,"mc":[{"id":"1.195532874","rc":[{"atb":[[6.8,0]],"id":35985721}],"con":true,"img":false}]}
{"op":"mcm","clk":"5323030313","pt":1646326656883,"mc":[{"id":"1.195532874","rc":[{"atb":[[5.6,0],[5.5,2]],"id":37306244}],"con":true,"img":false}]}
{"op":"mcm","clk":"5323030323","pt":1646326657040,"mc":[{"id":"1.195532874","rc":[{"atb":[[6.8,1.48]],"id":35985721}],"con":true,"img":false}]}
{"op":"mcm","clk":"5323030354","pt":1646326657562,"mc":[{"id":"1.195532874","rc":[{"atl":[[3.25,0]],"id":40883678},{"trd":[[3.25,120]],"ltp":3.25,"tv":120.0,"id":40883678}],"con":true,"img":false}]}
{"op":"mcm","clk":"5323030361","pt":1646326657668,"mc":[{"id":"1.195532874","rc":[{"atb":[[1.69,0]],"id":40883678},{"atl":[[3.8,0],[3.55,10.86]],"id":40883678}],"con":true,"img":false}]}
{"op":"mcm","clk":"5323030378","pt":1646326657980,"mc":[{"id":"1.195532874","rc":[{"atb":[[2.6,0]],"id":40883678}],"con":true,"img":false}]}
{"op":"mcm","clk":"5323030428","pt":1646326658614,"mc":[{"id":"1.195532874","rc":[{"atb":[[2.54,2.23]],"id":40883678}],"con":true,"img":false}]}
{"op":"mcm","clk":"5323030529","pt":1646326660176,"mc":[{"id":"1.195532874","rc":[{"atb":[[6.8,0]],"id":35985721}],"con":true,"img":false}]}
{"op":"mcm","clk":"5323030532","pt":1646326660283,"mc":[{"id":"1.195532874","rc":[{"atb":[[6.8,1.48]],"id":35985721}],"con":true,"img":false}]}
{"op":"mcm","clk":"5323030722","pt":1646326663505,"mc":[{"id":"1.195532874","rc":[{"atb":[[6.8,0]],"id":35985721}],"con":true,"img":false}]}
{"op":"mcm","clk":"5323030736","pt":1646326663715,"mc":[{"id":"1.195532874","rc":[{"atb":[[6.8,1.48]],"id":35985721}],"con":true,"img":false}]}
{"op":"mcm","clk":"5323030771","pt":1646326664185,"mc":[{"id":"1.195532874","rc":[{"atb":[[1.01,1001.65]],"id":37306244},{"atb":[[1.03,1.65]],"id":41469398},{"atb":[[1.03,1.65]],"id":35985721},{"atb":[[1.01,1001.65]],"id":39614765},{"atb":[[1.02,1.65]],"id":40642034},{"atb":[[1.01,1001.65]],"id":40883678}],"con":true,"img":false}]}
{"op":"mcm","clk":"5323030790","pt":1646326664502,"mc":[{"id":"1.195532874","rc":[{"atb":[[1.01,1000.89]],"id":37306244},{"atb":[[1.03,0.57]],"id":41469398},{"atb":[[1.01,1000.96]],"id":39614765},{"atb":[[1.03,0.62]],"id":35985721},{"atb":[[1.02,1.16]],"id":40642034},{"atb":[[1.01,1001.64]],"id":40883678}],"con":true,"img":false}]}
{"op":"mcm","clk":"5323030812","pt":1646326664815,"mc":[{"id":"1.195532874","rc":[{"atb":[[1.01,1000]],"id":37306244},{"atb":[[1.03,0]],"id":41469398},{"atb":[[1.03,0]],"id":35985721},{"atb":[[1.01,1000]],"id":39614765},{"atb":[[1.02,0]],"id":40642034},{"atb":[[1.01,1000]],"id":40883678}],"con":true,"img":false}]}
{"op":"mcm","clk":"5323030819","pt":1646326664930,"mc":[{"id":"1.195532874","rc":[{"atb":[[4.6,2.89]],"id":37306244},{"atb":[[7.2,2.19]],"id":41469398},{"atb":[[4.3,2.96]],"id":39614765},{"atb":[[6.6,2.42]],"id":35985721},{"atb":[[3.55,3.16]],"id":40642034},{"atb":[[2.52,12.36]],"id":40883678}],"con":true,"img":false}]}
{"op":"mcm","clk":"5323030949","pt":1646326666911,"mc":[{"id":"1.195532874","rc":[{"atb":[[6.8,0]],"id":35985721}],"con":true,"img":false}]}
{"op":"mcm","clk":"5323030955","pt":1646326667015,"mc":[{"id":"1.195532874","rc":[{"atb":[[6.8,1.48]],"id":35985721}],"con":true,"img":false}]}
{"op":"mcm","clk":"5323031156","pt":1646326670231,"mc":[{"id":"1.195532874","rc":[{"atb":[[6.8,0]],"id":35985721}],"con":true,"img":false}]}
{"op":"mcm","clk":"5323031170","pt":1646326670441,"mc":[{"id":"1.195532874","rc":[{"atb":[[6.8,1.48]],"id":35985721}],"con":true,"img":false}]}
{"op":"mcm","clk":"5323031356","pt":1646326673646,"mc":[{"id":"1.195532874","rc":[{"atl":[[3.55,0],[3.5,64.02]],"id":40883678}],"con":true,"img":false}]}
{"op":"mcm","clk":"5323031364","pt":1646326673726,"mc":[{"id":"1.195532874","rc":[{"atb":[[6.8,0]],"id":35985721}],"con":true,"img":false}]}
{"op":"mcm","clk":"5323031377","pt":1646326673933,"mc":[{"id":"1.195532874","rc":[{"atb":[[6.8,1.48]],"id":35985721}],"con":true,"img":false}]}
{"op":"mcm","clk":"5323031501","pt":1646326676314,"mc":[{"id":"1.195532874","rc":[{"atb":[[2.58,4.74]],"id":40883678}],"con":true,"img":false}]}
{"op":"mcm","clk":"5323031512","pt":1646326676522,"mc":[{"id":"1.195532874","rc":[{"atb":[[3.45,4.69]],"id":35985721}],"con":true,"img":false}]}
{"op":"mcm","clk":"5323031519","pt":1646326676626,"mc":[{"id":"1.195532874","rc":[{"atb":[[2.54,1.65]],"id":40883678}],"con":true,"img":false}]}
{"op":"mcm","clk":"5323031525","pt":1646326676733,"mc":[{"id":"1.195532874","rc":[{"atb":[[2.54,0],[2.6,0.58]],"id":40883678}],"con":true,"img":false}]}
{"op":"mcm","clk":"5323031535","pt":1646326676836,"mc":[{"id":"1.195532874","rc":[{"atb":[[2.6,2.23]],"id":40883678}],"con":true,"img":false}]}
{"op":"mcm","clk":"5323031558","pt":1646326677149,"mc":[{"id":"1.195532874","rc":[{"atb":[[6.8,0]],"id":35985721}],"con":true,"img":false}]}
{"op":"mcm","clk":"5323031574","pt":1646326677309,"mc":[{"id":"1.195532874","rc":[{"atb":[[6.8,1.48]],"id":35985721}],"con":true,"img":false}]}
{"op":"mcm","clk":"5323031806","pt":1646326680554,"mc":[{"id":"1.195532874","rc":[{"atb":[[6.8,0]],"id":35985721}],"con":true,"img":false}]}
{"op":"mcm","clk":"5323031818","pt":1646326680767,"mc":[{"id":"1.195532874","rc":[{"atb":[[6.8,1.48]],"id":35985721}],"con":true,"img":false}]}
{"op":"mcm","clk":"5323031924","pt":1646326682039,"mc":[{"id":"1.195532874","rc":[{"atb":[[3.8,89.29],[4,33.33],[3.9,51.72],[4.2,12.5]],"id":37306244},{"atl":[[10.5,15.79],[11.5,23.81],[9.8,11.36],[9.4,4.76]],"id":37306244},{"atb":[[6.2,19.23],[5.7,53.19],[6.6,7.14],[5.9,30.61]],"id":41469398},{"atl":[[16,2.67],[17,6.25],[18,8.82],[19,13.89]],"id":41469398},{"atb":[[5.9,20.41],[6.2,7.69],[5.5,55.56],[5.7,31.91]],"id":35985721},{"atl":[[16.5,9.68],[17.5,15.15],[14.5,3.71],[15.5,6.9]],"id":35985721},{"atb":[[3.85,35.09],[3.75,54.55],[3.95,13.56],[3.65,94.34]],"id":39614765},{"atl":[[8.6,5.26],[9,12.5],[9.8,28.41],[9.4,17.86]],"id":39614765},{"atb":[[3.1,71.43],[3,125],[3.3,17.39],[3.2,45.45]],"id":40642034},{"atl":[[6.4,27.78],[5.8,8.33],[6,20],[6.8,43.1]],"id":40642034},{"atb":[[2.44,125.88],[2.48,73.48],[2.56,18.59],[2.52,60.06]],"id":40883678},{"atl":[[5.3,44.08],[4.9,10.26],[5.1,24.39],[5.5,55.56],[4.7,10.81]],"id":40883678}],"con":true,"img":false}]}
{"op":"mcm","clk":"5323031946","pt":1646326682455,"mc":[{"id":"1.195532874","rc":[{"atl":[[9.2,0.82]],"id":37306244},{"atl":[[15.5,0.82]],"id":41469398},{"atl":[[8.4,0.82]],"id":39614765},{"atl":[[5.7,0.82]],"id":40642034}],"con":true,"img":false}]}
{"op":"mcm","clk":"5323031969","pt":1646326682719,"mc":[{"id":"1.195532874","rc":[{"atb":[[6.8,1.57]],"id":41469398},{"atb":[[3.45,3.05]],"id":35985721},{"atb":[[2.62,3.29]],"id":40883678}],"con":true,"img":false}]}
{"op":"mcm","clk":"5323031977","pt":1646326682825,"mc":[{"id":"1.195532874","rc":[{"atb":[[6.4,1.63]],"id":35985721}],"con":true,"img":false}]}
{"op":"mcm","clk":"5323031998","pt":1646326683238,"mc":[{"id":"1.195532874","rc":[{"atl":[[9.2,0.43]],"id":37306244},{"atl":[[15.5,0.45]],"id":41469398},{"atl":[[8.4,0.42]],"id":39614765},{"atl":[[5.7,0.46]],"id":40642034},{"atb":[[2.6,1.65]],"id":40883678}],"con":true,"img":false}]}
{"op":"mcm","clk":"5323032005","pt":1646326683342,"mc":[{"id":"1.195532874","rc":[{"atb":[[2.62,3.87]],"id":40883678}],"con":true,"img":false}]}
{"op":"mcm","clk":"5323032029","pt":1646326683761,"mc":[{"id":"1.195532874","rc":[{"atb":[[2.76,0]],"id":37306244},{"atb":[[2.76,0]],"id":41469398},{"atb":[[2.46,0]],"id":39614765},{"atb":[[3.45,0]],"id":35985721},{"atb":[[2.2,0]],"id":40642034},{"atb":[[2.64,2.48],[2.58,0]],"id":40883678}],"con":true,"img":false}]}
{"op":"mcm","clk":"5323032035","pt":1646326683815,"mc":[{"id":"1.195532874","rc":[{"atb":[[2.6,0]],"id":40883678}],"con":true,"img":false}]}
{"op":"mcm","clk":"5323032043","pt":1646326683930,"mc":[{"id":"1.195532874","rc":[{"atb":[[6.8,0]],"id":35985721},{"atb":[[2.64,4.13]],"id":40883678}],"con":true,"img":false}]}
{"op":"mcm","clk":"5323032087","pt":1646326684864,"mc":[{"id":"1.195532874","rc":[{"atb":[[7.2,8.64]],"id":41469398},{"atl":[[16,0],[16.5,2.58],[17,2.5]],"id":41469398},{"atl":[[14,3.08],[14.5,0.75],[15.5,2.76]],"id":35985721},{"atb":[[2.6,18.13],[2.56,0]],"id":40883678},{"atl":[[5.5,0]],"id":40883678}],"con":true,"img":false}]}
{"op":"mcm","clk":"5323032095","pt":1646326684922,"mc":[{"id":"1.195532874","rc":[{"atb":[[6.6,0]],"id":41469398},{"atb":[[2.62,3.29]],"id":40883678},{"atl":[[6.6,0]],"id":40883678}],"con":true,"img":false}]}
{"op":"mcm","clk":"5323032104","pt":1646326685024,"mc":[{"id":"1.195532874","rc":[{"atb":[[6.8,1.48]],"id":35985721},{"atb":[[2.64,4.71]],"id":40883678},{"atl":[[6.4,1.86]],"id":40883678}],"con":true,"img":false}]}
{"op":"mcm","clk":"5323032120","pt":1646326685238,"mc":[{"id":"1.195532874","rc":[{"atb":[[6.4,9.04],[6.2,0]],"id":35985721},{"atl":[[14,0]],"id":35985721}],"con":true,"img":false}]}
{"op":"mcm","clk":"5323032157","pt":1646326685759,"mc":[{"id":"1.195532874","rc":[{"atl":[[15.5,0]],"id":41469398}],"con":true,"img":false}]}
{"op":"mcm","clk":"5323032164","pt":1646326685816,"mc":[{"id":"1.195532874","rc":[{"atb":[[6.8,0]],"id":41469398},{"atl":[[16.5,3.03]],"id":41469398}],"con":true,"img":false}]}
{"op":"mcm","clk":"5323032172","pt":1646326685927,"mc":[{"id":"1.195532874","rc":[{"atb":[[7.4,1.57]],"id":41469398}],"con":true,"img":false}]}
{"op":"mcm","clk":"5323032181","pt":1646326686023,"mc":[{"id":"1.195532874","rc":[{"atb":[[1.87,0]],"id":40883678}],"con":true,"img":false}]}
{"op":"mcm","clk":"5323032245","pt":1646326687126,"mc":[{"id":"1.195532874","rc":[{"atl":[[16.5,9.2]],"id":37306244},{"atl":[[15,9.2],[19,15.2]],"id":39614765},{"atl":[[12.5,15.2],[9.8,9.2]],"id":40642034}],"con":true,"img":false}]}
{"op":"mcm","clk":"5323032251","pt":1646326687138,"mc":[{"id":"1.195532874","rc":[{"atl":[[21,15.2]],"id":37306244}],"con":true,"img":false}]}
{"op":"mcm","clk":"5323032284","pt":1646326687751,"mc":[{"id":"1.195532874","rc":[{"atb":[[2.48,0]],"id":40642034}],"con":true,"img":false}]}
{"op":"mcm","clk":"5323032326","pt":1646326688329,"mc":[{"id":"1.195532874","rc":[{"atb":[[6.8,0]],"id":35985721}],"con":true,"img":false}]}
{"op":"mcm","clk":"5323032371","pt":1646326689058,"mc":[{"id":"1.195532874","rc":[{"atb":[[3.4,4.04]],"id":35985721},{"atb":[[2.52,55.72]],"id":40883678}],"con":true,"img":false}]}
{"op":"mcm","clk":"5323032376","pt":1646326689162,"mc":[{"id":"1.195532874","rc":[{"atb":[[6.8,1.48]],"id":35985721}],"con":true,"img":false}]}
{"op":"mcm","clk":"5323032380","pt":1646326689267,"mc":[{"id":"1.195532874","rc":[{"atb":[[2.14,9.86]],"id":40883678}],"con":true,"img":false}]}
{"op":"mcm","clk":"5323032561","pt":1646326692459,"mc":[{"id":"1.195532874","rc":[{"atb":[[6.8,0]],"id":35985721}],"con":true,"img":false}]}
{"op":"mcm","clk":"5323032569","pt":1646326692664,"mc":[{"id":"1.195532874","rc":[{"atb":[[6.8,1.48]],"id":35985721}],"con":true,"img":false}]}
{"op":"mcm","clk":"5323032697","pt":1646326694767,"mc":[{"id":"1.195532874","rc":[{"atb":[[3.4,2.49]],"id":40642034}],"con":true,"img":false}]}
{"op":"mcm","clk":"5323032704","pt":1646326694883,"mc":[{"id":"1.195532874","rc":[{"atb":[[6.8,17.24]],"id":41469398},{"atl":[[17.5,6.06]],"id":41469398},{"atb":[[2.56,46.48]],"id":40883678},{"atl":[[4.9,35.9]],"id":40883678}],"con":true,"img":false}]}
{"op":"mcm","clk":"5323032713","pt":1646326694979,"mc":[{"id":"1.195532874","rc":[{"atb":[[2.62,0]],"id":40883678},{"atl":[[4.9,25.64]],"id":40883678}],"con":true,"img":false}]}
{"op":"mcm","clk":"5323032732","pt":1646326695248,"mc":[{"id":"1.195532874","rc":[{"atl":[[16.5,6.45]],"id":35985721}],"con":true,"img":false}]}
{"op":"mcm","clk":"5323032781","pt":1646326696072,"mc":[{"id":"1.195532874","rc":[{"atb":[[6.8,0]],"id":35985721}],"con":true,"img":false}]}
{"op":"mcm","clk":"5323032798","pt":1646326696242,"mc":[{"id":"1.195532874","rc":[{"atb":[[6.8,1.48]],"id":35985721}],"con":true,"img":false}]}
{"op":"mcm","clk":"5323032860","pt":1646326697344,"mc":[{"id":"1.195532874","rc":[{"atb":[[2.66,3.61]],"id":40883678}],"con":true,"img":false}]}
{"op":"mcm","clk":"5323032879","pt":1646326697643,"mc":[{"id":"1.195532874","rc":[{"atb":[[2.68,3.29]],"id":40883678}],"con":true,"img":false}]}
{"op":"mcm","clk":"5323032924","pt":1646326698386,"mc":[{"id":"1.195532874","rc":[{"atb":[[2.64,4.13]],"id":40883678}],"con":true,"img":false}]}
{"op":"mcm","clk":"5323032929","pt":1646326698479,"mc":[{"id":"1.195532874","rc":[{"atb":[[2.68,3.87]],"id":40883678}],"con":true,"img":false}]}
{"op":"mcm","clk":"5323032952","pt":1646326698844,"mc":[{"id":"1.195532874","rc":[{"atb":[[2.64,1.65]],"id":40883678}],"con":true,"img":false}]}
{"op":"mcm","clk":"5323032986","pt":1646326699379,"mc":[{"id":"1.195532874","rc":[{"atb":[[3.4,6.54]],"id":40642034}],"con":true,"img":false}]}
{"op":"mcm","clk":"5323032991","pt":1646326699485,"mc":[{"id":"1.195532874","rc":[{"atb":[[6.8,0],[3.4,0]],"id":35985721},{"atb":[[2.52,49.34]],"id":40883678}],"con":true,"img":false}]}
{"op":"mcm","clk":"5323033001","pt":1646326699644,"mc":[{"id":"1.195532874","rc":[{"atb":[[6.8,1.48]],"id":35985721}],"con":true,"img":false}]}
{"op":"mcm","clk":"5323033017","pt":1646326699945,"mc":[{"id":"1.195532874","rc":[{"atb":[[7.2,2.19],[6.2,7.69],[6.8,0]],"id":41469398},{"atl":[[16.5,0.45],[16,2.67],[17,0],[17.5,0],[18,0],[19,0]],"id":41469398},{"atb":[[6.4,1.63],[6.2,7.69]],"id":35985721},{"atl":[[14.5,3.71]],"id":35985721},{"atb":[[2.64,19.33],[2.6,0]],"id":40883678},{"atl":[[4.6,11.11],[4.7,0]],"id":40883678}],"con":true,"img":false}]}
{"op":"mcm","clk":"5323033029","pt":1646326700157,"mc":[{"id":"1.195532874","rc":[{"atb":[[2.8,6.9]],"id":40642034}],"con":true,"img":false}]}
{"op":"mcm","clk":"5323033059","pt":1646326700688,"mc":[{"id":"1.195532874","rc":[{"atb":[[2.66,0]],"id":40883678}],"con":true,"img":false}]}
{"op":"mcm","clk":"5323033072","pt":1646326700881,"mc":[{"id":"1.195532874","rc":[{"atb":[[7.4,0]],"id":41469398},{"atl":[[16.5,0]],"id":41469398}],"con":true,"img":false}]}
{"op":"mcm","clk":"5323033076","pt":1646326700948,"mc":[{"id":"1.195532874","rc":[{"atb":[[6.4,1.57]],"id":41469398},{"atl":[[1000,12.45]],"id":41469398}],"con":true,"img":false}]}
{"op":"mcm","clk":"5323033185","pt":1646326702984,"mc":[{"id":"1.195532874","rc":[{"spn":7.25,"spf":1.0,"id":37306244},{"atb":[[6.8,0]],"id":35985721},{"spn":2.68,"spf":1.0,"id":40883678}],"con":true,"img":false}]}
{"op":"mcm","clk":"5323033198","pt":1646326703152,"mc":[{"id":"1.195532874","rc":[{"atb":[[6.8,1.48]],"id":35985721}],"con":true,"img":false}]}
{"op":"mcm","clk":"5323033366","pt":1646326706362,"mc":[{"id":"1.195532874","rc":[{"atb":[[6.8,0]],"id":35985721}],"con":true,"img":false}]}
{"op":"mcm","clk":"5323033380","pt":1646326706573,"mc":[{"id":"1.195532874","rc":[{"atb":[[6.8,1.48]],"id":35985721}],"con":true,"img":false}]}
{"op":"mcm","clk":"5323033569","pt":1646326709837,"mc":[{"id":"1.195532874","rc":[{"atb":[[6.8,0]],"id":35985721}],"con":true,"img":false}]}
{"op":"mcm","clk":"5323033575","pt":1646326709942,"mc":[{"id":"1.195532874","rc":[{"atb":[[5.9,20.41]],"id":41469398},{"atl":[[17,6.25]],"id":41469398},{"atl":[[15.5,6.9]],"id":35985721},{"atb":[[2.44,0],[2.6,45.32],[2.68,0.58]],"id":40883678}],"con":true,"img":false}]}
{"op":"mcm","clk":"5323033581","pt":1646326710044,"mc":[{"id":"1.195532874","rc":[{"atb":[[6.8,1.48]],"id":35985721}],"con":true,"img":false}]}
{"op":"mcm","clk":"5323033598","pt":1646326710408,"mc":[{"id":"1.195532874","rc":[{"atb":[[2.68,0]],"id":40883678}],"con":true,"img":false}]}
{"op":"mcm","clk":"5323033603","pt":1646326710514,"mc":[{"id":"1.195532874","rc":[{"atb":[[2.66,0.58]],"id":40883678}],"con":true,"img":false}]}
{"op":"mcm","clk":"5323033680","pt":1646326711920,"mc":[{"id":"1.195532874","rc":[{"atb":[[2.66,3.06]],"id":40883678}],"con":true,"img":false}]}
{"op":"mcm","clk":"5323033739","pt":1646326712905,"mc":[{"id":"1.195532874","rc":[{"atb":[[2.68,3.29]],"id":40883678}],"con":true,"img":false}]}
{"op":"mcm","clk":"5323033760","pt":1646326713217,"mc":[{"id":"1.195532874","rc":[{"atb":[[6.8,0]],"id":35985721}],"con":true,"img":false}]}
{"op":"mcm","clk":"5323033790","pt":1646326713742,"mc":[{"id":"1.195532874","rc":[{"atb":[[2.66,2.48]],"id":40883678}],"con":true,"img":false}]}
{"op":"mcm","clk":"5323033795","pt":1646326713845,"mc":[{"id":"1.195532874","rc":[{"atb":[[2.68,3.87]],"id":40883678}],"con":true,"img":false}]}
{"op":"mcm","clk":"5323033800","pt":1646326713940,"mc":[{"id":"1.195532874","rc":[{"atb":[[6.8,1.48]],"id":35985721}],"con":true,"img":false}]}
{"op":"mcm","clk":"5323033823","pt":1646326714462,"mc":[{"id":"1.195532874","rc":[{"atb":[[2.66,0]],"id":40883678}],"con":true,"img":false}]}
{"op":"mcm","clk":"5323033968","pt":1646326717125,"mc":[{"id":"1.195532874","rc":[{"atb":[[6.8,0]],"id":35985721}],"con":true,"img":false}]}
{"op":"mcm","clk":"5323033974","pt":1646326717229,"mc":[{"id":"1.195532874","rc":[{"atb":[[6.8,1.48]],"id":35985721}],"con":true,"img":false}]}
{"op":"mcm","clk":"5323034132","pt":1646326719954,"mc":[{"id":"1.195532874","rc":[{"atb":[[5.7,31.91]],"id":41469398},{"atl":[[18,8.82]],"id":41469398},{"atl":[[16.5,9.68]],"id":35985721},{"atb":[[2.48,0],[2.56,69.72]],"id":40883678}],"con":true,"img":false}]}
{"op":"mcm","clk":"5323034164","pt":1646326720424,"mc":[{"id":"1.195532874","rc":[{"atb":[[6.8,0]],"id":35985721}],"con":true,"img":false}]}
{"op":"mcm","clk":"5323034171","pt":1646326720529,"mc":[{"id":"1.195532874","rc":[{"atb":[[6.8,1.48]],"id":35985721}],"con":true,"img":false}]}
{"op":"mcm","clk":"5323034186","pt":1646326720741,"mc":[{"id":"1.195532874","rc":[{"atl":[[1000,12]],"id":41469398}],"con":true,"img":false}]}
{"op":"mcm","clk":"5323034192","pt":1646326720843,"mc":[{"id":"1.195532874","rc":[{"atl":[[15.5,0.45]],"id":41469398}],"con":true,"img":false}]}
{"op":"mcm","clk":"5323034225","pt":1646326721460,"mc":[{"id":"1.195532874","rc":[{"atb":[[2.7,0]],"id":35985721}],"con":true,"img":false}]}
{"op":"mcm","clk":"5323034363","pt":1646326723742,"mc":[{"id":"1.195532874","rc":[{"atb":[[6.8,0]],"id":35985721}],"con":true,"img":false}]}
{"op":"mcm","clk":"5323034375","pt":1646326723948,"mc":[{"id":"1.195532874","rc":[{"atb":[[6.8,1.48]],"id":35985721}],"con":true,"img":false}]}
{"op":"mcm","clk":"5323034440","pt":1646326725146,"mc":[{"id":"1.195532874","rc":[{"atb":[[2.68,0.58]],"id":40883678}],"con":true,"img":false}]}
{"op":"mcm","clk":"5323034501","pt":1646326726033,"mc":[{"id":"1.195532874","rc":[{"atb":[[4.4,3.3]],"id":35985721}],"con":true,"img":false}]}
{"op":"mcm","clk":"5323034556","pt":1646326726969,"mc":[{"id":"1.195532874","rc":[{"atb":[[2.66,2.48]],"id":40883678}],"con":true,"img":false}]}
{"op":"mcm","clk":"5323034567","pt":1646326727173,"mc":[{"id":"1.195532874","rc":[{"atb":[[6.8,0]],"id":35985721}],"con":true,"img":false}]}
{"op":"mcm","clk":"5323034578","pt":1646326727330,"mc":[{"id":"1.195532874","rc":[{"atb":[[6.8,1.48]],"id":35985721}],"con":true,"img":false}]}
{"op":"mcm","clk":"5323034628","pt":1646326728159,"mc":[{"id":"1.195532874","rc":[{"atb":[[2.68,3.87]],"id":40883678}],"con":true,"img":false}]}
{"op":"mcm","clk":"5323034703","pt":1646326729455,"mc":[{"id":"1.195532874","rc":[{"atb":[[2.66,0]],"id":40883678}],"con":true,"img":false}]}
{"op":"mcm","clk":"5323034735","pt":1646326730009,"mc":[{"id":"1.195532874","rc":[{"atb":[[5.5,55.56]],"id":41469398},{"atl":[[19,13.89]],"id":41469398},{"atb":[[2.52,120.89]],"id":40883678}],"con":true,"img":false}]}
{"op":"mcm","clk":"5323034773","pt":1646326730645,"mc":[{"id":"1.195532874","rc":[{"atb":[[6.8,0]],"id":35985721}],"con":true,"img":false}]}
{"op":"mcm","clk":"5323034788","pt":1646326730851,"mc":[{"id":"1.195532874","rc":[{"atb":[[6.8,1.48]],"id":35985721}],"con":true,"img":false}]}
{"op":"mcm","clk":"5323034949","pt":1646326734063,"mc":[{"id":"1.195532874","rc":[{"atb":[[6.8,0]],"id":35985721}],"con":true,"img":false}]}
{"op":"mcm","clk":"5323034965","pt":1646326734269,"mc":[{"id":"1.195532874","rc":[{"atb":[[6.8,1.48]],"id":35985721}],"con":true,"img":false}]}
{"op":"mcm","clk":"5323035162","pt":1646326737488,"mc":[{"id":"1.195532874","rc":[{"atb":[[6.8,0]],"id":35985721}],"con":true,"img":false}]}
{"op":"mcm","clk":"5323035172","pt":1646326737646,"mc":[{"id":"1.195532874","rc":[{"atb":[[6.8,1.48]],"id":35985721}],"con":true,"img":false}]}
{"op":"mcm","clk":"5323035352","pt":1646326740448,"mc":[{"id":"1.195532874","rc":[{"atb":[[2.68,0.58]],"id":40883678}],"con":true,"img":false}]}
{"op":"mcm","clk":"5323035380","pt":1646326740870,"mc":[{"id":"1.195532874","rc":[{"atb":[[6.8,0]],"id":35985721}],"con":true,"img":false}]}
{"op":"mcm","clk":"5323035389","pt":1646326740973,"mc":[{"id":"1.195532874","rc":[{"atb":[[6.8,1.48]],"id":35985721}],"con":true,"img":false}]}
{"op":"mcm","clk":"5323035500","pt":1646326742278,"mc":[{"id":"1.195532874","rc":[{"atb":[[2.66,2.48]],"id":40883678}],"con":true,"img":false}]}
{"op":"mcm","clk":"5323035546","pt":1646326742904,"mc":[{"id":"1.195532874","rc":[{"atb":[[2.68,3.87]],"id":40883678}],"con":true,"img":false}]}
{"op":"mcm","clk":"5323035669","pt":1646326744302,"mc":[{"id":"1.195532874","rc":[{"atb":[[6.8,0]],"id":35985721}],"con":true,"img":false}]}
{"op":"mcm","clk":"5323035676","pt":1646326744364,"mc":[{"id":"1.195532874","rc":[{"atb":[[6.8,1.48]],"id":35985721}],"con":true,"img":false}]}
{"op":"mcm","clk":"5323035702","pt":1646326744776,"mc":[{"id":"1.195532874","rc":[{"atb":[[2.66,0]],"id":40883678}],"con":true,"img":false}]}
{"op":"mcm","clk":"5323035868","pt":1646326747579,"mc":[{"id":"1.195532874","rc":[{"atb":[[6.8,0]],"id":35985721}],"con":true,"img":false}]}
{"op":"mcm","clk":"5323035924","pt":1646326748511,"mc":[{"id":"1.195532874","rc":[{"atl":[[15,0]],"id":41469398},{"trd":[[15,1.43]],"ltp":15.0,"tv":1.43,"id":41469398}],"con":true,"img":false}]}
{"op":"mcm","clk":"5323035944","pt":1646326748671,"mc":[{"id":"1.195532874","rc":[{"atb":[[1.02,2.24]],"id":41469398},{"atb":[[6.8,1.48]],"id":35985721}],"con":true,"img":false}]}
{"op":"mcm","clk":"5323035963","pt":1646326748986,"mc":[{"id":"1.195532874","rc":[{"atb":[[1.02,0.35]],"id":41469398}],"con":true,"img":false}]}
{"op":"mcm","clk":"5323035972","pt":1646326749085,"mc":[{"id":"1.195532874","rc":[{"atb":[[1.02,0]],"id":41469398}],"con":true,"img":false}]}
{"op":"mcm","clk":"5323035981","pt":1646326749192,"mc":[{"id":"1.195532874","rc":[{"atb":[[10.5,0.35]],"id":41469398}],"con":true,"img":false}]}
{"op":"mcm","clk":"5323036021","pt":1646326749977,"mc":[{"id":"1.195532874","rc":[{"atb":[[2.62,9.31]],"id":40883678}],"con":true,"img":false}]}
{"op":"mcm","clk":"5323036164","pt":1646326751906,"mc":[{"id":"1.195532874","rc":[{"atb":[[6.8,0]],"id":35985721}],"con":true,"img":false}]}
{"op":"mcm","clk":"5323036179","pt":1646326752112,"mc":[{"id":"1.195532874","rc":[{"atb":[[6.8,1.48]],"id":35985721}],"con":true,"img":false}]}
{"op":"mcm","clk":"5323036404","pt":1646326755099,"mc":[{"id":"1.195532874","rc":[{"atb":[[2.68,0.58]],"id":40883678}],"con":true,"img":false}]}
{"op":"mcm","clk":"5323036420","pt":1646326755410,"mc":[{"id":"1.195532874","rc":[{"atb":[[6.8,0]],"id":35985721}],"con":true,"img":false}]}
{"op":"mcm","clk":"5323036437","pt":1646326755619,"mc":[{"id":"1.195532874","rc":[{"atb":[[6.8,1.48]],"id":35985721}],"con":true,"img":false}]}
{"op":"mcm","clk":"5323036453","pt":1646326755830,"mc":[{"id":"1.195532874","rc":[{"atb":[[2.62,0]],"id":40883678}],"con":true,"img":false}]}
{"op":"mcm","clk":"5323036476","pt":1646326756289,"mc":[{"id":"1.195532874","rc":[{"atb":[[2.66,2.48]],"id":40883678}],"con":true,"img":false}]}
{"op":"mcm","clk":"5323036576","pt":1646326758319,"mc":[{"id":"1.195532874","rc":[{"atb":[[2.68,3.87]],"id":40883678}],"con":true,"img":false}]}
{"op":"mcm","clk":"5323036614","pt":1646326758891,"mc":[{"id":"1.195532874","rc":[{"atb":[[6.8,0]],"id":35985721}],"con":true,"img":false}]}
{"op":"mcm","clk":"5323036704","pt":1646326760290,"mc":[{"id":"1.195532874","rc":[{"atb":[[2.66,0]],"id":40883678}],"con":true,"img":false}]}
{"op":"mcm","clk":"5323036709","pt":1646326760393,"mc":[{"id":"1.195532874","rc":[{"atb":[[6.8,1.48]],"id":35985721}],"con":true,"img":false}]}
{"op":"mcm","clk":"5323036819","pt":1646326762431,"mc":[{"id":"1.195532874","rc":[{"atb":[[2.9,0]],"id":37306244},{"atb":[[2.82,0]],"id":35985721}],"con":true,"img":false}]}
{"op":"mcm","clk":"5323036893","pt":1646326763736,"mc":[{"id":"1.195532874","rc":[{"spn":13.0,"spf":1.0,"id":41469398},{"atb":[[6.8,0]],"id":35985721}],"con":true,"img":false}]}
{"op":"mcm","clk":"5323036908","pt":1646326763891,"mc":[{"id":"1.195532874","rc":[{"atb":[[6.8,1.48]],"id":35985721}],"con":true,"img":false}]}
{"op":"mcm","clk":"5323037103","pt":1646326767136,"mc":[{"id":"1.195532874","rc":[{"atb":[[6.8,0]],"id":35985721}],"con":true,"img":false}]}
{"op":"mcm","clk":"5323037113","pt":1646326767341,"mc":[{"id":"1.195532874","rc":[{"atb":[[6.8,1.48]],"id":35985721}],"con":true,"img":false}]}
{"op":"mcm","clk":"5323037267","pt":1646326769741,"mc":[{"id":"1.195532874","rc":[{"atl":[[15.5,0]],"id":41469398},{"trd":[[15.5,0.91]],"ltp":15.5,"tv":0.91,"id":41469398},{"atb":[[6.8,0]],"id":35985721},{"trd":[[6.8,2.96]],"ltp":6.8,"tv":2.96,"id":35985721}],"con":true,"img":false}]}
{"op":"mcm","clk":"5323037298","pt":1646326770211,"mc":[{"id":"1.195532874","rc":[{"atb":[[6.2,8.81]],"id":41469398}],"con":true,"img":false}]}
{"op":"mcm","clk":"5323037331","pt":1646326770630,"mc":[{"id":"1.195532874","rc":[{"atb":[[2.68,0.58]],"id":40883678}],"con":true,"img":false}]}
{"op":"mcm","clk":"5323037364","pt":1646326771146,"mc":[{"id":"1.195532874","rc":[{"atl":[[26,0.41]],"id":41469398}],"con":true,"img":false}]}
{"op":"mcm","clk":"5323037442","pt":1646326772245,"mc":[{"id":"1.195532874","rc":[{"atb":[[2.66,2.48]],"id":40883678}],"con":true,"img":false}]}
{"op":"mcm","clk":"5323037471","pt":1646326772616,"mc":[{"id":"1.195532874","rc":[{"atb":[[2.68,3.87]],"id":40883678}],"con":true,"img":false}]}
{"op":"mcm","clk":"5323037538","pt":1646326773815,"mc":[{"id":"1.195532874","rc":[{"atb":[[2.66,0]],"id":40883678}],"con":true,"img":false}]}
{"op":"mcm","clk":"5323037624","pt":1646326775171,"mc":[{"id":"1.195532874","rc":[{"atb":[[4.3,3.77]],"id":35985721}],"con":true,"img":false}]}
{"op":"mcm","clk":"5323037629","pt":1646326775229,"mc":[{"id":"1.195532874","rc":[{"atb":[[3.45,5.07]],"id":37306244}],"con":true,"img":false}]}
{"op":"mcm","clk":"5323038224","pt":1646326784979,"mc":[{"id":"1.195532874","rc":[{"atb":[[2.68,0.58]],"id":40883678}],"con":true,"img":false}]}
{"op":"mcm","clk":"5323038365","pt":1646326787060,"mc":[{"id":"1.195532874","rc":[{"atb":[[2.66,3.29]],"id":40883678}],"con":true,"img":false}]}
{"op":"mcm","clk":"5323038374","pt":1646326787161,"mc":[{"id":"1.195532874","rc":[{"atl":[[16,0]],"id":41469398},{"trd":[[16,5.34]],"ltp":16.0,"tv":5.34,"id":41469398},{"atb":[[2.66,5.77]],"id":40883678}],"con":true,"img":false}]}
{"op":"mcm","clk":"5323038382","pt":1646326787265,"mc":[{"id":"1.195532874","rc":[{"atb":[[10,3.34]],"id":41469398},{"atl":[[18.5,2.13]],"id":41469398}],"con":true,"img":false}]}
{"op":"mcm","clk":"5323038387","pt":1646326787373,"mc":[{"id":"1.195532874","rc":[{"atl":[[17,0],[18,0],[19,0]],"id":41469398}],"con":true,"img":false}]}
{"op":"mcm","clk":"5323038411","pt":1646326787784,"mc":[{"id":"1.195532874","rc":[{"atb":[[4.6,2.74]],"id":37306244},{"atb":[[7.2,2.01]],"id":41469398},{"atb":[[4.3,2.8]],"id":39614765}],"con":true,"img":false}]}
{"op":"mcm","clk":"5323038431","pt":1646326788101,"mc":[{"id":"1.195532874","rc":[{"atb":[[4.6,2]],"id":37306244},{"atb":[[7.2,1.62]],"id":41469398},{"atb":[[4.3,2]],"id":39614765},{"atb":[[3.55,2]],"id":40642034},{"atb":[[2.52,119.25]],"id":40883678}],"con":true,"img":false}]}
{"op":"mcm","clk":"5323038437","pt":1646326788156,"mc":[{"id":"1.195532874","rc":[{"atb":[[5.6,0.74]],"id":37306244},{"atb":[[10.5,0.75]],"id":41469398},{"atb":[[5.2,0.8]],"id":39614765},{"atb":[[3.8,1.16]],"id":40642034},{"atb":[[2.68,2.22]],"id":40883678}],"con":true,"img":false}]}
{"op":"mcm","clk":"5323038533","pt":1646326789570,"mc":[{"id":"1.195532874","rc":[{"atb":[[3.85,2.48]],"id":40642034},{"atb":[[2.66,3.29]],"id":40883678}],"con":true,"img":false}]}
{"op":"mcm","clk":"5323038570","pt":1646326790295,"mc":[{"id":"1.195532874","rc":[{"atb":[[6.6,0]],"id":35985721},{"trd":[[6.6,4.84]],"ltp":6.6,"tv":4.84,"id":35985721}],"con":true,"img":false}]}
{"op":"mcm","clk":"5323038659","pt":1646326791601,"mc":[{"id":"1.195532874","rc":[{"atb":[[2.8,51.11],[2.34,76.12]],"id":37306244},{"atb":[[4.6,25.56],[3.7,37.78]],"id":41469398},{"atb":[[2.22,83.61],[2.64,56.1]],"id":39614765}],"con":true,"img":false}]}
{"op":"mcm","clk":"5323038706","pt":1646326792285,"mc":[{"id":"1.195532874","rc":[{"atb":[[6.6,2.48]],"id":35985721}],"con":true,"img":false}]}
{"op":"mcm","clk":"5323039007","pt":1646326797295,"mc":[{"id":"1.195532874","rc":[{"atl":[[22,1.77]],"id":41469398}],"con":true,"img":false}]}
{"op":"mcm","clk":"5323039014","pt":1646326797401,"mc":[{"id":"1.195532874","rc":[{"atl":[[18.5,0]],"id":41469398}],"con":true,"img":false}]}
{"op":"mcm","clk":"5323039135","pt":1646326799283,"mc":[{"id":"1.195532874","rc":[{"atb":[[2.66,0]],"id":40883678}],"con":true,"img":false}]}
{"op":"mcm","clk":"5323039386","pt":1646326802019,"mc":[{"id":"1.195532874","rc":[{"atb":[[6.2,1.12],[6,2.97],[6.6,7.14]],"id":41469398},{"atl":[[22,0],[26,1.9]],"id":41469398},{"atb":[[5.5,61.01]],"id":35985721}],"con":true,"img":false}]}
{"op":"mcm","clk":"5323039393","pt":1646326802121,"mc":[{"id":"1.195532874","rc":[{"atb":[[2.7,3.29]],"id":40883678}],"con":true,"img":false}]}
{"op":"mcm","clk":"5323039397","pt":1646326802179,"mc":[{"id":"1.195532874","rc":[{"atb":[[6,0]],"id":41469398}],"con":true,"img":false}]}
{"op":"mcm","clk":"5323039559","pt":1646326803988,"mc":[{"id":"1.195532874","rc":[{"atb":[[4.3,1.3]],"id":37306244},{"atb":[[6.4,3.02]],"id":35985721},{"atb":[[4,1.38]],"id":39614765},{"atb":[[3.45,1.36]],"id":40642034},{"atb":[[2.68,1.64]],"id":40883678}],"con":true,"img":false}]}
{"op":"mcm","clk":"5323039565","pt":1646326804095,"mc":[{"id":"1.195532874","rc":[{"atb":[[2.7,3.87]],"id":40883678}],"con":true,"img":false}]}
{"op":"mcm","clk":"5323039575","pt":1646326804199,"mc":[{"id":"1.195532874","rc":[{"atl":[[8.2,0]],"id":39614765},{"atb":[[2.64,1.65],[2.66,17.47]],"id":40883678}],"con":true,"img":false}]}
{"op":"mcm","clk":"5323039587","pt":1646326804305,"mc":[{"id":"1.195532874","rc":[{"atl":[[8.6,6.59]],"id":39614765}],"con":true,"img":false}]}
{"op":"mcm","clk":"5323039729","pt":1646326805847,"mc":[{"id":"1.195532874","rc":[{"atb":[[5.5,55.56]],"id":35985721}],"con":true,"img":false}]}
{"op":"mcm","clk":"5323039770","pt":1646326806425,"mc":[{"id":"1.195532874","rc":[{"atb":[[6.6,0]],"id":35985721},{"trd":[[6.6,9.81]],"ltp":6.6,"tv":9.81,"id":35985721}],"con":true,"img":false}]}
{"op":"mcm","clk":"5323039790","pt":1646326806634,"mc":[{"id":"1.195532874","rc":[{"atb":[[5.2,2]],"id":35985721}],"con":true,"img":false}]}
{"op":"mcm","clk":"5323040078","pt":1646326810108,"mc":[{"id":"1.195532874","rc":[{"atb":[[5.2,0]],"id":39614765},{"atb":[[3.8,0]],"id":40642034},{"atb":[[2.68,0]],"id":40883678}],"con":true,"img":false}]}
{"op":"mcm","clk":"5323040086","pt":1646326810210,"mc":[{"id":"1.195532874","rc":[{"atb":[[5.2,0.8]],"id":39614765},{"atb":[[3.9,1.16]],"id":40642034},{"atb":[[2.72,1.64]],"id":40883678}],"con":true,"img":false}]}
{"op":"mcm","clk":"5323040098","pt":1646326810420,"mc":[{"id":"1.195532874","rc":[{"atl":[[8.6,1.33],[8.8,5.13]],"id":39614765},{"atb":[[6.2,0],[6,7.88]],"id":35985721},{"atb":[[2.66,0],[2.68,17.26]],"id":40883678}],"con":true,"img":false}]}
{"op":"mcm","clk":"5323040112","pt":1646326810622,"mc":[{"id":"1.195532874","rc":[{"atl":[[9.2,3.04]],"id":39614765}],"con":true,"img":false}]}
{"op":"mcm","clk":"5323040116","pt":1646326810729,"mc":[{"id":"1.195532874","rc":[{"atb":[[6.4,0]],"id":35985721}],"con":true,"img":false}]}
{"op":"mcm","clk":"5323040128","pt":1646326810832,"mc":[{"id":"1.195532874","rc":[{"atb":[[6.2,3.02]],"id":35985721},{"atl":[[8.4,0]],"id":39614765}],"con":true,"img":false}]}
{"op":"mcm","clk":"5323040133","pt":1646326810935,"mc":[{"id":"1.195532874","rc":[{"atl":[[8.6,1.75]],"id":39614765}],"con":true,"img":false}]}
{"op":"mcm","clk":"5323040141","pt":1646326811017,"mc":[{"id":"1.195532874","rc":[{"atb":[[3.85,0]],"id":40642034}],"con":true,"img":false}]}
{"op":"mcm","clk":"5323040204","pt":1646326812033,"mc":[{"id":"1.195532874","rc":[{"atb":[[6.2,20.35]],"id":41469398},{"atl":[[28,3.45]],"id":41469398}],"con":true,"img":false}]}
{"op":"mcm","clk":"5323040263","pt":1646326812821,"mc":[{"id":"1.195532874","rc":[{"atb":[[3.95,2.48]],"id":40642034}],"con":true,"img":false}]}
{"op":"mcm","clk":"5323040326","pt":1646326813935,"mc":[{"id":"1.195532874","rc":[{"atb":[[6.2,0.02]],"id":35985721},{"trd":[[6.2,6]],"ltp":6.2,"tv":6.0,"id":35985721}],"con":true,"img":false}]}
{"op":"mcm","clk":"5323040356","pt":1646326814338,"mc":[{"id":"1.195532874","rc":[{"atb":[[2.7,0.58]],"id":40883678}],"con":true,"img":false}]}
{"op":"mcm","clk":"5323040383","pt":1646326814725,"mc":[{"id":"1.195532874","rc":[{"atb":[[6.2,0]],"id":35985721}],"con":true,"img":false}]}
{"op":"mcm","clk":"5323040451","pt":1646326815805,"mc":[{"id":"1.195532874","rc":[{"atl":[[9.2,0]],"id":39614765}],"con":true,"img":false}]}
{"op":"mcm","clk":"5323040468","pt":1646326816008,"mc":[{"id":"1.195532874","rc":[{"atb":[[2.74,3.29]],"id":40883678}],"con":true,"img":false}]}
{"op":"mcm","clk":"5323040482","pt":1646326816319,"mc":[{"id":"1.195532874","rc":[{"atb":[[2.7,0.53]],"id":40883678}],"con":true,"img":false}]}
{"op":"mcm","clk":"5323040523","pt":1646326817045,"mc":[{"id":"1.195532874","rc":[{"atb":[[2.7,0]],"id":40883678}],"con":true,"img":false}]}
{"op":"mcm","clk":"5323040529","pt":1646326817101,"mc":[{"id":"1.195532874","rc":[{"atb":[[2.74,3.83]],"id":40883678}],"con":true,"img":false}]}
{"op":"mcm","clk":"5323040641","pt":1646326818308,"mc":[{"id":"1.195532874","rc":[{"atb":[[3.75,2]],"id":40642034}],"con":true,"img":false}]}
{"op":"mcm","clk":"5323040658","pt":1646326818625,"mc":[{"id":"1.195532874","rc":[{"atb":[[4,1.65]],"id":40642034}],"con":true,"img":false}]}
{"op":"mcm","clk":"5323040664","pt":1646326818727,"mc":[{"id":"1.195532874","rc":[{"atb":[[3.45,3.04]],"id":40642034}],"con":true,"img":false}]}
{"op":"mcm","clk":"5323040762","pt":1646326820454,"mc":[{"id":"1.195532874","rc":[{"atl":[[9,5],[8.8,0]],"id":39614765},{"atb":[[5.8,8.2],[6,0]],"id":35985721},{"atb":[[3.95,0]],"id":40642034},{"atb":[[2.68,0],[2.7,17.06]],"id":40883678}],"con":true,"img":false}]}
{"op":"mcm","clk":"5323040807","pt":1646326821352,"mc":[{"id":"1.195532874","rc":[{"atl":[[8.6,1.33]],"id":39614765}],"con":true,"img":false}]}
{"op":"mcm","clk":"5323040813","pt":1646326821450,"mc":[{"id":"1.195532874","rc":[{"atl":[[8.8,0.42]],"id":39614765}],"con":true,"img":false}]}
{"op":"mcm","clk":"5323040838","pt":1646326822030,"mc":[{"id":"1.195532874","rc":[{"atb":[[5.9,30.61],[5.5,0]],"id":41469398},{"atl":[[30,4.81]],"id":41469398}],"con":true,"img":false}]}
{"op":"mcm","clk":"5323040856","pt":1646326822344,"mc":[{"id":"1.195532874","rc":[{"atb":[[4.1,2.48]],"id":40642034}],"con":true,"img":false}]}
{"op":"mcm","clk":"5323040928","pt":1646326823335,"mc":[{"id":"1.195532874","rc":[{"atb":[[2.66,5.85]],"id":40883678}],"con":true,"img":false}]}
{"op":"mcm","clk":"5323041003","pt":1646326824223,"mc":[{"id":"1.195532874","rc":[{"spn":7.3,"spf":1.0,"id":37306244},{"spn":15.75,"spf":1.0,"id":41469398},{"spn":6.9,"spf":1.0,"id":39614765},{"spn":7.95,"spf":1.0,"id":35985721},{"spn":4.85,"spf":1.0,"id":40642034},{"atb":[[2.6,53.63]],"id":40883678},{"spn":2.74,"spf":1.0,"id":40883678}],"con":true,"img":false}]}
{"op":"mcm","clk":"5323041115","pt":1646326825845,"mc":[{"id":"1.195532874","rc":[{"atb":[[2.6,45.32]],"id":40883678}],"con":true,"img":false}]}
{"op":"mcm","clk":"5323041276","pt":1646326828369,"mc":[{"id":"1.195532874","rc":[{"atb":[[2.74,0.53]],"id":40883678}],"con":true,"img":false}]}
{"op":"mcm","clk":"5323041292","pt":1646326828667,"mc":[{"id":"1.195532874","rc":[{"atb":[[5.7,40.29]],"id":35985721}],"con":true,"img":false}]}
{"op":"mcm","clk":"5323041301","pt":1646326828771,"mc":[{"id":"1.195532874","rc":[{"atb":[[5.9,0],[5.7,8.38]],"id":35985721},{"atl":[[5.6,0]],"id":40642034}],"con":true,"img":false}]}
{"op":"mcm","clk":"5323041319","pt":1646326828971,"mc":[{"id":"1.195532874","rc":[{"atl":[[6.4,29.64]],"id":40642034}],"con":true,"img":false}]}
{"op":"mcm","clk":"5323041428","pt":1646326830478,"mc":[{"id":"1.195532874","rc":[{"atl":[[9.4,11.9]],"id":39614765},{"atb":[[2.74,3.83],[2.66,49.53]],"id":40883678}],"con":true,"img":false}]}
{"op":"mcm","clk":"5323041564","pt":1646326832066,"mc":[{"id":"1.195532874","rc":[{"atb":[[5.7,53.19]],"id":41469398},{"atl":[[34,7.05]],"id":41469398}],"con":true,"img":false}]}
{"op":"mcm","clk":"5323041887","pt":1646326835886,"mc":[{"id":"1.195532874","rc":[{"atb":[[2.66,43.68]],"id":40883678}],"con":true,"img":false}]}
{"op":"mcm","clk":"5323041910","pt":1646326836093,"mc":[{"id":"1.195532874","rc":[{"atl":[[5.8,0],[5.9,8.16]],"id":40642034},{"atb":[[2.6,0],[2.56,0],[2.52,0]],"id":40883678}],"con":true,"img":false}]}
{"op":"mcm","clk":"5323041921","pt":1646326836161,"mc":[{"id":"1.195532874","rc":[{"atb":[[5.8,0]],"id":35985721},{"atl":[[5.9,11.83]],"id":40642034}],"con":true,"img":false}]}
{"op":"mcm","clk":"5323041944","pt":1646326836471,"mc":[{"id":"1.195532874","rc":[{"atl":[[5.7,0]],"id":40642034}],"con":true,"img":false}]}
{"op":"mcm","clk":"5323041951","pt":1646326836578,"mc":[{"id":"1.195532874","rc":[{"atl":[[5.8,0.46]],"id":40642034}],"con":true,"img":false}]}
{"op":"mcm","clk":"5323042080","pt":1646326838671,"mc":[{"id":"1.195532874","rc":[{"atb":[[5.6,8.56],[5.7,0]],"id":35985721}],"con":true,"img":false}]}
{"op":"mcm","clk":"5323042198","pt":1646326840382,"mc":[{"id":"1.195532874","rc":[{"atl":[[9.8,17.05]],"id":39614765},{"atb":[[2.62,67.13]],"id":40883678}],"con":true,"img":false}]}
{"op":"mcm","clk":"5323042368","pt":1646326842694,"mc":[{"id":"1.195532874","rc":[{"atb":[[2.74,0.53]],"id":40883678}],"con":true,"img":false}]}
{"op":"mcm","clk":"5323042427","pt":1646326843594,"mc":[{"id":"1.195532874","rc":[{"atb":[[2.74,0]],"id":40883678}],"con":true,"img":false}]}
{"op":"mcm","clk":"5323042434","pt":1646326843700,"mc":[{"id":"1.195532874","rc":[{"atb":[[2.72,2.18]],"id":40883678}],"con":true,"img":false}]}
{"op":"mcm","clk":"5323042498","pt":1646326844489,"mc":[{"id":"1.195532874","rc":[{"atb":[[2.74,3.29]],"id":40883678}],"con":true,"img":false}]}
{"op":"mcm","clk":"5323042527","pt":1646326844904,"mc":[{"id":"1.195532874","rc":[{"atb":[[2.72,1.64]],"id":40883678}],"con":true,"img":false}]}
{"op":"mcm","clk":"5323042533","pt":1646326844959,"mc":[{"id":"1.195532874","rc":[{"atb":[[2.74,3.83]],"id":40883678}],"con":true,"img":false}]}
{"op":"mcm","clk":"5323042595","pt":1646326845997,"mc":[{"id":"1.195532874","rc":[{"atl":[[5.9,8.16]],"id":40642034}],"con":true,"img":false}]}
{"op":"mcm","clk":"5323042603","pt":1646326846097,"mc":[{"id":"1.195532874","rc":[{"atl":[[5.9,0],[6,8]],"id":40642034}],"con":true,"img":false}]}
{"op":"mcm","clk":"5323042795","pt":1646326848673,"mc":[{"id":"1.195532874","rc":[{"atb":[[2.38,0]],"id":39614765},{"atb":[[5.6,0],[5.5,8.75]],"id":35985721}],"con":true,"img":false}]}
{"op":"mcm","clk":"5323042830","pt":1646326849085,"mc":[{"id":"1.195532874","rc":[{"atl":[[5.8,0]],"id":40642034}],"con":true,"img":false}]}
{"op":"mcm","clk":"5323042838","pt":1646326849190,"mc":[{"id":"1.195532874","rc":[{"atl":[[5.9,0.46]],"id":40642034}],"con":true,"img":false}]}
{"op":"mcm","clk":"5323042929","pt":1646326850401,"mc":[{"id":"1.195532874","rc":[{"atl":[[10.5,26.32]],"id":39614765},{"atb":[[2.58,114.72]],"id":40883678}],"con":true,"img":false}]}
{"op":"mcm","clk":"5323043220","pt":1646326854405,"mc":[{"id":"1.195532874","rc":[{"atb":[[3.55,4.4]],"id":39614765}],"con":true,"img":false}]}
{"op":"mcm","clk":"5323043330","pt":1646326856083,"mc":[{"id":"1.195532874","rc":[{"atl":[[6.2,7.69],[6,0]],"id":40642034}],"con":true,"img":false}]}
{"op":"mcm","clk":"5323043372","pt":1646326856812,"mc":[{"id":"1.195532874","rc":[{"atb":[[2.74,0.53]],"id":40883678}],"con":true,"img":false}]}
{"op":"mcm","clk":"5323043382","pt":1646326857125,"mc":[{"id":"1.195532874","rc":[{"atl":[[5.9,0]],"id":40642034}],"con":true,"img":false}]}
{"op":"mcm","clk":"5323043389","pt":1646326857187,"mc":[{"id":"1.195532874","rc":[{"atl":[[6,0.46]],"id":40642034}],"con":true,"img":false}]}
{"op":"mcm","clk":"5323043482","pt":1646326858696,"mc":[{"id":"1.195532874","rc":[{"atb":[[5.5,0],[5.4,8.95]],"id":35985721}],"con":true,"img":false}]}
{"op":"mcm","clk":"5323043502","pt":1646326859014,"mc":[{"id":"1.195532874","rc":[{"atb":[[2.74,3.83]],"id":40883678}],"con":true,"img":false}]}
{"op":"mcm","clk":"5323043633","pt":1646326861024,"mc":[{"id":"1.195532874","rc":[{"atb":[[5.5,4.3]],"id":35985721}],"con":true,"img":false}]}
{"op":"mcm","clk":"5323043975","pt":1646326865933,"mc":[{"id":"1.195532874","rc":[{"atb":[[5.5,0]],"id":35985721}],"con":true,"img":false}]}
{"op":"mcm","clk":"5323043987","pt":1646326866092,"mc":[{"id":"1.195532874","rc":[{"atl":[[6.4,9.27],[6.2,0]],"id":40642034}],"con":true,"img":false}]}
{"op":"mcm","clk":"5323044052","pt":1646326867140,"mc":[{"id":"1.195532874","rc":[{"atl":[[6,0]],"id":40642034}],"con":true,"img":false}]}
{"op":"mcm","clk":"5323044060","pt":1646326867195,"mc":[{"id":"1.195532874","rc":[{"atl":[[6.2,0.46]],"id":40642034}],"con":true,"img":false}]}
{"op":"mcm","clk":"5323044151","pt":1646326868711,"mc":[{"id":"1.195532874","rc":[{"atb":[[5.2,11.38],[5.4,0]],"id":35985721}],"con":true,"img":false}]}
{"op":"mcm","clk":"5323044272","pt":1646326870721,"mc":[{"id":"1.195532874","rc":[{"atl":[[3.45,3.36]],"id":40883678}],"con":true,"img":false}]}
{"op":"mcm","clk":"5323044315","pt":1646326871339,"mc":[{"id":"1.195532874","rc":[{"atb":[[2.74,0.53]],"id":40883678}],"con":true,"img":false}]}
{"op":"mcm","clk":"5323044326","pt":1646326871548,"mc":[{"id":"1.195532874","rc":[{"atl":[[3.5,53],[3.45,9.64]],"id":40883678}],"con":true,"img":false}]}
{"op":"mcm","clk":"5323044334","pt":1646326871604,"mc":[{"id":"1.195532874","rc":[{"atb":[[2.96,0]],"id":37306244}],"con":true,"img":false}]}
{"op":"mcm","clk":"5323044495","pt":1646326874220,"mc":[{"id":"1.195532874","rc":[{"atb":[[2.74,3.83]],"id":40883678}],"con":true,"img":false}]}
{"op":"mcm","clk":"5323044533","pt":1646326874740,"mc":[{"id":"1.195532874","rc":[{"atb":[[3.55,4.4]],"id":37306244}],"con":true,"img":false}]}
{"op":"mcm","clk":"5323044556","pt":1646326875005,"mc":[{"id":"1.195532874","rc":[{"atb":[[2.52,0]],"id":39614765}],"con":true,"img":false}]}
{"op":"mcm","clk":"5323044615","pt":1646326876147,"mc":[{"id":"1.195532874","rc":[{"atl":[[6.4,1.86],[6.6,7.14]],"id":40642034}],"con":true,"img":false}]}
{"op":"mcm","clk":"5323044762","pt":1646326878748,"mc":[{"id":"1.195532874","rc":[{"atb":[[5,24.62]],"id":35985721},{"atb":[[4,0]],"id":40642034}],"con":true,"img":false}]}
{"op":"mcm","clk":"5323044781","pt":1646326879010,"mc":[{"id":"1.195532874","rc":[{"atb":[[4.2,1.65]],"id":40642034}],"con":true,"img":false}]}
{"op":"mcm","clk":"5323044887","pt":1646326880690,"mc":[{"id":"1.195532874","rc":[{"atb":[[4.1,0]],"id":40642034}],"con":true,"img":false}]}
{"op":"mcm","clk":"5323045232","pt":1646326886122,"mc":[{"id":"1.195532874","rc":[{"spn":7.6,"spf":1.0,"id":35985721},{"atl":[[7,16.67]],"id":40642034},{"spn":5.2,"spf":1.0,"id":40642034}],"con":true,"img":false}]}
{"op":"mcm","clk":"5323045259","pt":1646326886489,"mc":[{"id":"1.195532874","rc":[{"atb":[[2.74,0.53]],"id":40883678}],"con":true,"img":false}]}
{"op":"mcm","clk":"5323045316","pt":1646326887326,"mc":[{"id":"1.195532874","rc":[{"atb":[[2.74,3.83]],"id":40883678}],"con":true,"img":false}]}
{"op":"mcm","clk":"5323045417","pt":1646326888733,"mc":[{"id":"1.195532874","rc":[{"atb":[[5,34.47]],"id":35985721}],"con":true,"img":false}]}
{"op":"mcm","clk":"5323045423","pt":1646326888840,"mc":[{"id":"1.195532874","rc":[{"atb":[[5,9.85],[5.2,1.99]],"id":35985721}],"con":true,"img":false}]}
{"op":"mcm","clk":"5323045549","pt":1646326890817,"mc":[{"id":"1.195532874","rc":[{"atb":[[3.35,5.29]],"id":39614765}],"con":true,"img":false}]}
{"op":"mcm","clk":"5323045878","pt":1646326896146,"mc":[{"id":"1.195532874","rc":[{"atl":[[7.4,23.44]],"id":40642034}],"con":true,"img":false}]}
{"op":"mcm","clk":"5323046035","pt":1646326898744,"mc":[{"id":"1.195532874","rc":[{"atb":[[4.8,25.91]],"id":35985721}],"con":true,"img":false}]}
{"op":"mcm","clk":"5323046090","pt":1646326899626,"mc":[{"id":"1.195532874","rc":[{"atb":[[2.74,0.53]],"id":40883678}],"con":true,"img":false}]}
{"op":"mcm","clk":"5323046173","pt":1646326901131,"mc":[{"id":"1.195532874","rc":[{"atb":[[2.74,3.83]],"id":40883678}],"con":true,"img":false}]}
{"op":"mcm","clk":"5323046467","pt":1646326905533,"mc":[{"id":"1.195532874","rc":[{"atl":[[8.8,0]],"id":40883678}],"con":true,"img":false}]}
{"op":"mcm","clk":"5323046476","pt":1646326905639,"mc":[{"id":"1.195532874","rc":[{"atl":[[8,0.2]],"id":40883678}],"con":true,"img":false}]}
{"op":"mcm","clk":"5323046507","pt":1646326906163,"mc":[{"id":"1.195532874","rc":[{"atl":[[7.8,36.76]],"id":40642034}],"con":true,"img":false}]}
{"op":"mcm","clk":"5323046564","pt":1646326907053,"mc":[{"id":"1.195532874","rc":[{"atl":[[21,0]],"id":41469398}],"con":true,"img":false}]}
{"op":"mcm","clk":"5323046571","pt":1646326907155,"mc":[{"id":"1.195532874","rc":[{"atl":[[27,0.2]],"id":41469398}],"con":true,"img":false}]}
{"op":"mcm","clk":"5323046670","pt":1646326908626,"mc":[{"id":"1.195532874","rc":[{"atl":[[21,0]],"id":35985721}],"con":true,"img":false}]}
{"op":"mcm","clk":"5323046677","pt":1646326908732,"mc":[{"id":"1.195532874","rc":[{"atb":[[4.6,41.03]],"id":35985721},{"atl":[[27,0.2]],"id":35985721}],"con":true,"img":false}]}
{"op":"mcm","clk":"5323046972","pt":1646326913448,"mc":[{"id":"1.195532874","rc":[{"atb":[[2.74,0.53]],"id":40883678}],"con":true,"img":false}]}
{"op":"mcm","clk":"5323047003","pt":1646326913863,"mc":[{"id":"1.195532874","rc":[{"atb":[[2.52,0]],"id":40642034}],"con":true,"img":false}]}
{"op":"mcm","clk":"5323047096","pt":1646326915274,"mc":[{"id":"1.195532874","rc":[{"atb":[[2.74,3.83]],"id":40883678}],"con":true,"img":false}]}
{"op":"mcm","clk":"5323047152","pt":1646326916167,"mc":[{"id":"1.195532874","rc":[{"atl":[[6.8,0]],"id":40642034}],"con":true,"img":false}]}
{"op":"mcm","clk":"5323047160","pt":1646326916271,"mc":[{"id":"1.195532874","rc":[{"atl":[[7,21.07]],"id":40642034}],"con":true,"img":false}]}
{"op":"mcm","clk":"5323047195","pt":1646326916745,"mc":[{"id":"1.195532874","rc":[{"atb":[[3.1,76.78]],"id":40642034}],"con":true,"img":false}]}
{"op":"mcm","clk":"5323047347","pt":1646326918777,"mc":[{"id":"1.195532874","rc":[{"atb":[[4.4,75.7]],"id":35985721}],"con":true,"img":false}]}
{"op":"mcm","clk":"5323047825","pt":1646326926084,"mc":[{"id":"1.195532874","rc":[{"atl":[[7,16.67]],"id":40642034}],"con":true,"img":false}]}
{"op":"mcm","clk":"5323047830","pt":1646326926189,"mc":[{"id":"1.195532874","rc":[{"atb":[[1.89,0]],"id":40883678}],"con":true,"img":false}]}
{"op":"mcm","clk":"5323047933","pt":1646326927452,"mc":[{"id":"1.195532874","rc":[{"atb":[[2.74,0.53]],"id":40883678}],"con":true,"img":false}]}
{"op":"mcm","clk":"5323048143","pt":1646326929860,"mc":[{"id":"1.195532874","rc":[{"atb":[[2.74,3.83]],"id":40883678}],"con":true,"img":false}]}
{"op":"mcm","clk":"5323048823","pt":1646326938915,"mc":[{"id":"1.195532874","rc":[{"atb":[[2.18,10.53]],"id":40883678}],"con":true,"img":false}]}
{"op":"mcm","clk":"5323049044","pt":1646326942095,"mc":[{"id":"1.195532874","rc":[{"atb":[[2.74,0.53]],"id":40883678}],"con":true,"img":false}]}
{"op":"mcm","clk":"5323049205","pt":1646326944335,"mc":[{"id":"1.195532874","rc":[{"atb":[[2.74,3.83]],"id":40883678}],"con":true,"img":false}]}
{"op":"mcm","clk":"5323050065","pt":1646326956665,"mc":[{"id":"1.195532874","rc":[{"atb":[[2.74,0.53]],"id":40883678},{"spn":2.71,"spf":1.0,"id":40883678}],"con":true,"img":false}]}
{"op":"mcm","clk":"5323050231","pt":1646326959064,"mc":[{"id":"1.195532874","rc":[{"atb":[[2.74,3.83]],"id":40883678}],"con":true,"img":false}]}
{"op":"mcm","clk":"5323051112","pt":1646326971350,"mc":[{"id":"1.195532874","rc":[{"atb":[[2.74,0.53]],"id":40883678}],"con":true,"img":false}]}
{"op":"mcm","clk":"5323051323","pt":1646326974439,"mc":[{"id":"1.195532874","rc":[{"atb":[[2.74,3.83]],"id":40883678}],"con":true,"img":false}]}
{"op":"mcm","clk":"5323051791","pt":1646326980163,"mc":[{"id":"1.195532874","rc":[{"atb":[[4.4,72.4]],"id":35985721}],"con":true,"img":false}]}
{"op":"mcm","clk":"5323052007","pt":1646326983186,"mc":[{"id":"1.195532874","rc":[{"atb":[[3.55,4.4]],"id":35985721}],"con":true,"img":false}]}
{"op":"mcm","clk":"5323052275","pt":1646326986684,"mc":[{"id":"1.195532874","rc":[{"atb":[[2.74,0.53]],"id":40883678}],"con":true,"img":false}]}
{"op":"mcm","clk":"5323052499","pt":1646326989782,"mc":[{"id":"1.195532874","rc":[{"atb":[[2.74,3.83]],"id":40883678}],"con":true,"img":false}]}
{"op":"mcm","clk":"5323053474","pt":1646327002119,"mc":[{"id":"1.195532874","rc":[{"atb":[[2.74,0.53]],"id":40883678}],"con":true,"img":false}]}
{"op":"mcm","clk":"5323053619","pt":1646327003649,"mc":[{"id":"1.195532874","rc":[{"atb":[[2.74,3.83]],"id":40883678}],"con":true,"img":false}]}
{"op":"mcm","clk":"5323054653","pt":1646327015958,"mc":[{"id":"1.195532874","rc":[{"atb":[[2.74,0.53]],"id":40883678}],"con":true,"img":false}]}
{"op":"mcm","clk":"5323054696","pt":1646327016433,"mc":[{"id":"1.195532874","rc":[{"atb":[[2.74,0]],"id":40883678}],"con":true,"img":false}]}
{"op":"mcm","clk":"5323054703","pt":1646327016537,"mc":[{"id":"1.195532874","rc":[{"atb":[[2.72,2.18]],"id":40883678}],"con":true,"img":false}]}
{"op":"mcm","clk":"5323054798","pt":1646327017746,"mc":[{"id":"1.195532874","rc":[{"atb":[[2.74,3.29]],"id":40883678},{"spn":2.74,"spf":1.0,"id":40883678}],"con":true,"img":false}]}
{"op":"mcm","clk":"5323054852","pt":1646327018425,"mc":[{"id":"1.195532874","rc":[{"atb":[[2.72,1.64]],"id":40883678}],"con":true,"img":false}]}
{"op":"mcm","clk":"5323054860","pt":1646327018530,"mc":[{"id":"1.195532874","rc":[{"atb":[[2.74,3.83]],"id":40883678}],"con":true,"img":false}]}
{"op":"mcm","clk":"5323055265","pt":1646327023080,"mc":[{"id":"1.195532874","rc":[{"atb":[[2.14,0]],"id":40883678}],"con":true,"img":false}]}
{"op":"mcm","clk":"5323055422","pt":1646327024687,"mc":[{"id":"1.195532874","rc":[{"atb":[[2.22,9.21]],"id":40883678}],"con":true,"img":false}]}
{"op":"mcm","clk":"5323055926","pt":1646327030059,"mc":[{"id":"1.195532874","rc":[{"atb":[[2.74,0.53]],"id":40883678}],"con":true,"img":false}]}
{"op":"mcm","clk":"5323056085","pt":1646327032075,"mc":[{"id":"1.195532874","rc":[{"atb":[[2.74,3.83]],"id":40883678}],"con":true,"img":false}]}
{"op":"mcm","clk":"5323056187","pt":1646327033278,"mc":[{"id":"1.195532874","rc":[{"atb":[[1.01,1002]],"id":40883678}],"con":true,"img":false}]}
{"op":"mcm","clk":"5323056197","pt":1646327033382,"mc":[{"id":"1.195532874","rc":[{"atb":[[1.01,1003.99]],"id":40883678}],"con":true,"img":false}]}
{"op":"mcm","clk":"5323056216","pt":1646327033591,"mc":[{"id":"1.195532874","rc":[{"atb":[[1.01,1002]],"id":40883678}],"con":true,"img":false}]}
{"op":"mcm","clk":"5323056226","pt":1646327033696,"mc":[{"id":"1.195532874","rc":[{"atb":[[2.76,1.99]],"id":40883678}],"con":true,"img":false}]}
{"op":"mcm","clk":"5323056248","pt":1646327033866,"mc":[{"id":"1.195532874","rc":[{"atb":[[3.45,0]],"id":37306244},{"atb":[[4.3,0]],"id":35985721},{"atb":[[2.8,0],[1.01,1002]],"id":40642034},{"atb":[[2.68,8.03]],"id":40883678}],"con":true,"img":false}]}
{"op":"mcm","clk":"5323056270","pt":1646327034069,"mc":[{"id":"1.195532874","rc":[{"atb":[[1.01,1003.99]],"id":40642034}],"con":true,"img":false}]}
{"op":"mcm","clk":"5323056288","pt":1646327034276,"mc":[{"id":"1.195532874","rc":[{"atb":[[1.01,1002]],"id":40642034}],"con":true,"img":false}]}
{"op":"mcm","clk":"5323056299","pt":1646327034380,"mc":[{"id":"1.195532874","rc":[{"atb":[[3.95,1.99]],"id":40642034}],"con":true,"img":false}]}
{"op":"mcm","clk":"5323056317","pt":1646327034587,"mc":[{"id":"1.195532874","rc":[{"atb":[[1.01,1002]],"id":39614765}],"con":true,"img":false}]}
{"op":"mcm","clk":"5323056332","pt":1646327034751,"mc":[{"id":"1.195532874","rc":[{"atb":[[1.01,1003.99]],"id":39614765}],"con":true,"img":false}]}
{"op":"mcm","clk":"5323056351","pt":1646327034960,"mc":[{"id":"1.195532874","rc":[{"atb":[[1.01,1002]],"id":39614765},{"atb":[[4.3,2.48]],"id":40642034}],"con":true,"img":false}]}
{"op":"mcm","clk":"5323056360","pt":1646327035067,"mc":[{"id":"1.195532874","rc":[{"atb":[[5.2,2.79]],"id":39614765}],"con":true,"img":false}]}
{"op":"mcm","clk":"5323056369","pt":1646327035170,"mc":[{"id":"1.195532874","rc":[{"atb":[[1.01,1002]],"id":41469398}],"con":true,"img":false}]}
{"op":"mcm","clk":"5323056375","pt":1646327035273,"mc":[{"id":"1.195532874","rc":[{"atb":[[1.01,1003.99]],"id":41469398}],"con":true,"img":false}]}
{"op":"mcm","clk":"5323056394","pt":1646327035484,"mc":[{"id":"1.195532874","rc":[{"atb":[[1.01,1002]],"id":41469398}],"con":true,"img":false}]}
{"op":"mcm","clk":"5323056401","pt":1646327035589,"mc":[{"id":"1.195532874","rc":[{"atb":[[1.02,1.99]],"id":41469398}],"con":true,"img":false}]}
{"op":"mcm","clk":"5323056419","pt":1646327035795,"mc":[{"id":"1.195532874","rc":[{"atb":[[1.01,1002]],"id":37306244}],"con":true,"img":false}]}
{"op":"mcm","clk":"5323056433","pt":1646327035957,"mc":[{"id":"1.195532874","rc":[{"atb":[[1.01,1003.99]],"id":37306244}],"con":true,"img":false}]}
{"op":"mcm","clk":"5323056440","pt":1646327036064,"mc":[{"id":"1.195532874","rc":[{"atb":[[1.01,1002]],"id":37306244}],"con":true,"img":false}]}
{"op":"mcm","clk":"5323056451","pt":1646327036169,"mc":[{"id":"1.195532874","rc":[{"atb":[[1.02,1.99]],"id":37306244}],"con":true,"img":false}]}
{"op":"mcm","clk":"5323056458","pt":1646327036272,"mc":[{"id":"1.195532874","rc":[{"atb":[[1.01,1002]],"id":35985721}],"con":true,"img":false}]}
{"op":"mcm","clk":"5323056464","pt":1646327036376,"mc":[{"id":"1.195532874","rc":[{"atb":[[1.01,1003.99]],"id":35985721},{"atb":[[2.68,0]],"id":40883678}],"con":true,"img":false}]}
{"op":"mcm","clk":"5323056481","pt":1646327036585,"mc":[{"id":"1.195532874","rc":[{"atb":[[1.01,1002]],"id":35985721}],"con":true,"img":false}]}
{"op":"mcm","clk":"5323056492","pt":1646327036688,"mc":[{"id":"1.195532874","rc":[{"atb":[[5.1,1.99]],"id":35985721}],"con":true,"img":false}]}
{"op":"mcm","clk":"5323056557","pt":1646327037477,"mc":[{"id":"1.195532874","rc":[{"atb":[[5.3,2.48]],"id":39614765}],"con":true,"img":false}]}
{"op":"mcm","clk":"5323056619","pt":1646327038264,"mc":[{"id":"1.195532874","rc":[{"atb":[[3.95,0]],"id":40642034}],"con":true,"img":false}]}
{"op":"mcm","clk":"5323056627","pt":1646327038367,"mc":[{"id":"1.195532874","rc":[{"atb":[[4.4,1.99]],"id":40642034}],"con":true,"img":false}]}
{"op":"mcm","clk":"5323056645","pt":1646327038578,"mc":[{"id":"1.195532874","rc":[{"atb":[[5.2,0.8]],"id":39614765}],"con":true,"img":false}]}
{"op":"mcm","clk":"5323056654","pt":1646327038677,"mc":[{"id":"1.195532874","rc":[{"atb":[[5.4,1.99]],"id":39614765}],"con":true,"img":false}]}
{"op":"mcm","clk":"5323056786","pt":1646327040304,"mc":[{"id":"1.195532874","rc":[{"atb":[[5.3,0]],"id":39614765},{"atb":[[4.3,0]],"id":40642034}],"con":true,"img":false}]}
{"op":"mcm","clk":"5323056891","pt":1646327041568,"mc":[{"id":"1.195532874","rc":[{"atb":[[4.4,0]],"id":40642034}],"con":true,"img":false}]}
{"op":"mcm","clk":"5323056901","pt":1646327041669,"mc":[{"id":"1.195532874","rc":[{"atb":[[4.3,1.99]],"id":40642034}],"con":true,"img":false}]}
{"op":"mcm","clk":"5323056917","pt":1646327041883,"mc":[{"id":"1.195532874","rc":[{"atl":[[26,0.41],[28,1.38]],"id":41469398},{"atb":[[2.72,18.5],[2.7,0]],"id":40883678}],"con":true,"img":false}]}
{"op":"mcm","clk":"5323056926","pt":1646327041986,"mc":[{"id":"1.195532874","rc":[{"atb":[[5.4,0]],"id":39614765}],"con":true,"img":false}]}
{"op":"mcm","clk":"5323056938","pt":1646327042091,"mc":[{"id":"1.195532874","rc":[{"atb":[[5.3,1.99]],"id":39614765}],"con":true,"img":false}]}
{"op":"mcm","clk":"5323057003","pt":1646327042879,"mc":[{"id":"1.195532874","rc":[{"atb":[[5.4,2.48]],"id":39614765},{"atb":[[4.4,2.48]],"id":40642034}],"con":true,"img":false}]}
{"op":"mcm","clk":"5323057036","pt":1646327043303,"mc":[{"id":"1.195532874","rc":[{"atb":[[4.3,0]],"id":40642034}],"con":true,"img":false}]}
{"op":"mcm","clk":"5323057050","pt":1646327043514,"mc":[{"id":"1.195532874","rc":[{"atb":[[4.5,1.99]],"id":40642034}],"con":true,"img":false}]}
{"op":"mcm","clk":"5323057060","pt":1646327043627,"mc":[{"id":"1.195532874","rc":[{"atb":[[5.3,0]],"id":39614765}],"con":true,"img":false}]}
{"op":"mcm","clk":"5323057070","pt":1646327043694,"mc":[{"id":"1.195532874","rc":[{"atb":[[5.5,1.99]],"id":39614765}],"con":true,"img":false}]}
{"op":"mcm","clk":"5323057101","pt":1646327044000,"mc":[{"id":"1.195532874","rc":[{"atb":[[4.4,0]],"id":40642034}],"con":true,"img":false}]}
{"op":"mcm","clk":"5323057132","pt":1646327044317,"mc":[{"id":"1.195532874","rc":[{"atb":[[2.74,0.53]],"id":40883678}],"con":true,"img":false}]}
{"op":"mcm","clk":"5323057182","pt":1646327044799,"mc":[{"id":"1.195532874","rc":[{"atb":[[4.5,0]],"id":40642034}],"con":true,"img":false}]}
{"op":"mcm","clk":"5323057188","pt":1646327044899,"mc":[{"id":"1.195532874","rc":[{"atb":[[4.3,1.99]],"id":40642034}],"con":true,"img":false}]}
{"op":"mcm","clk":"5323057242","pt":1646327045533,"mc":[{"id":"1.195532874","rc":[{"atb":[[5.4,0]],"id":39614765},{"atb":[[4.4,2.48]],"id":40642034}],"con":true,"img":false}]}
{"op":"mcm","clk":"5323057257","pt":1646327045707,"mc":[{"id":"1.195532874","rc":[{"atb":[[3.2,51.1]],"id":40642034}],"con":true,"img":false}]}
{"op":"mcm","clk":"5323057356","pt":1646327046911,"mc":[{"id":"1.195532874","rc":[{"atb":[[3.65,4.69]],"id":37306244},{"atb":[[2.78,3.29]],"id":40883678}],"con":true,"img":false}]}
{"op":"mcm","clk":"5323057374","pt":1646327047134,"mc":[{"id":"1.195532874","rc":[{"atb":[[3.55,9.28]],"id":35985721}],"con":true,"img":false}]}
{"op":"mcm","clk":"5323057379","pt":1646327047229,"mc":[{"id":"1.195532874","rc":[{"atb":[[4.3,0]],"id":40642034}],"con":true,"img":false}]}
{"op":"mcm","clk":"5323057386","pt":1646327047345,"mc":[{"id":"1.195532874","rc":[{"atb":[[10,2]],"id":41469398},{"atb":[[4.5,1.99]],"id":40642034},{"atb":[[2.72,1.64],[2.74,17.2]],"id":40883678}],"con":true,"img":false}]}
{"op":"mcm","clk":"5323057397","pt":1646327047501,"mc":[{"id":"1.195532874","rc":[{"atb":[[5.5,0]],"id":39614765}],"con":true,"img":false}]}
{"op":"mcm","clk":"5323057405","pt":1646327047615,"mc":[{"id":"1.195532874","rc":[{"atb":[[5.3,1.99]],"id":39614765}],"con":true,"img":false}]}
{"op":"mcm","clk":"5323057413","pt":1646327047727,"mc":[{"id":"1.195532874","rc":[{"atb":[[10.5,3.25]],"id":41469398}],"con":true,"img":false}]}
{"op":"mcm","clk":"5323057449","pt":1646327048131,"mc":[{"id":"1.195532874","rc":[{"atb":[[4.4,0]],"id":40642034}],"con":true,"img":false}]}
{"op":"mcm","clk":"5323057471","pt":1646327048293,"mc":[{"id":"1.195532874","rc":[{"atb":[[10,0]],"id":41469398}],"con":true,"img":false}]}
{"op":"mcm","clk":"5323057606","pt":1646327049521,"mc":[{"id":"1.195532874","rc":[{"atb":[[5.4,2.48]],"id":39614765},{"atb":[[4.6,2.48]],"id":40642034}],"con":true,"img":false}]}
{"op":"mcm","clk":"5323057619","pt":1646327049724,"mc":[{"id":"1.195532874","rc":[{"atb":[[2.76,0]],"id":40883678}],"con":true,"img":false}]}
{"op":"mcm","clk":"5323057631","pt":1646327049825,"mc":[{"id":"1.195532874","rc":[{"atb":[[2.8,1.99]],"id":40883678}],"con":true,"img":false}]}
{"op":"mcm","clk":"5323057650","pt":1646327050038,"mc":[{"id":"1.195532874","rc":[{"atb":[[4.5,0]],"id":40642034}],"con":true,"img":false}]}
{"op":"mcm","clk":"5323057658","pt":1646327050138,"mc":[{"id":"1.195532874","rc":[{"atb":[[4.3,1.99]],"id":40642034}],"con":true,"img":false}]}
{"op":"mcm","clk":"5323057791","pt":1646327051912,"mc":[{"id":"1.195532874","rc":[{"atl":[[30,3.21]],"id":41469398}],"con":true,"img":false}]}
{"op":"mcm","clk":"5323057859","pt":1646327052703,"mc":[{"id":"1.195532874","rc":[{"atb":[[4.3,0]],"id":40642034}],"con":true,"img":false}]}
{"op":"mcm","clk":"5323057866","pt":1646327052803,"mc":[{"id":"1.195532874","rc":[{"atb":[[4.7,1.99]],"id":40642034}],"con":true,"img":false}]}
{"op":"mcm","clk":"5323057885","pt":1646327053019,"mc":[{"id":"1.195532874","rc":[{"atb":[[10.5,0.75]],"id":41469398},{"atb":[[5.2,0]],"id":35985721},{"atb":[[2.76,16.48],[2.74,0.53]],"id":40883678}],"con":true,"img":false}]}
{"op":"mcm","clk":"5323057896","pt":1646327053116,"mc":[{"id":"1.195532874","rc":[{"atb":[[5.3,0]],"id":39614765}],"con":true,"img":false}]}
{"op":"mcm","clk":"5323057905","pt":1646327053219,"mc":[{"id":"1.195532874","rc":[{"atb":[[5.5,1.99]],"id":39614765},{"atb":[[4.4,74.4]],"id":35985721}],"con":true,"img":false}]}
{"op":"mcm","clk":"5323057911","pt":1646327053324,"mc":[{"id":"1.195532874","rc":[{"atb":[[10,2]],"id":41469398},{"atb":[[3.75,0]],"id":40642034}],"con":true,"img":false}]}
{"op":"mcm","clk":"5323058030","pt":1646327054849,"mc":[{"id":"1.195532874","rc":[{"atb":[[5.4,0]],"id":39614765},{"atb":[[4.6,0]],"id":40642034}],"con":true,"img":false}]}
{"op":"mcm","clk":"5323058133","pt":1646327056142,"mc":[{"id":"1.195532874","rc":[{"atb":[[4.7,0]],"id":40642034}],"con":true,"img":false}]}
{"op":"mcm","clk":"5323058140","pt":1646327056254,"mc":[{"id":"1.195532874","rc":[{"atb":[[4.3,1.99]],"id":40642034}],"con":true,"img":false}]}
{"op":"mcm","clk":"5323058155","pt":1646327056451,"mc":[{"id":"1.195532874","rc":[{"atb":[[5.5,0]],"id":39614765}],"con":true,"img":false}]}
{"op":"mcm","clk":"5323058161","pt":1646327056506,"mc":[{"id":"1.195532874","rc":[{"atb":[[5.3,1.99]],"id":39614765}],"con":true,"img":false}]}
{"op":"mcm","clk":"5323058217","pt":1646327057336,"mc":[{"id":"1.195532874","rc":[{"atb":[[5.4,2.48]],"id":39614765},{"atb":[[4.4,2.48]],"id":40642034}],"con":true,"img":false}]}
{"op":"mcm","clk":"5323058249","pt":1646327057709,"mc":[{"id":"1.195532874","rc":[{"atb":[[4.3,0]],"id":40642034}],"con":true,"img":false}]}
{"op":"mcm","clk":"5323058268","pt":1646327057918,"mc":[{"id":"1.195532874","rc":[{"atb":[[4.5,1.99]],"id":40642034}],"con":true,"img":false}]}
{"op":"mcm","clk":"5323058282","pt":1646327058123,"mc":[{"id":"1.195532874","rc":[{"atb":[[5.3,0]],"id":39614765},{"atb":[[4.9,10.1],[5,0]],"id":35985721}],"con":true,"img":false}]}
{"op":"mcm","clk":"5323058291","pt":1646327058225,"mc":[{"id":"1.195532874","rc":[{"atb":[[5.5,1.99]],"id":39614765}],"con":true,"img":false}]}
{"op":"mcm","clk":"5323058299","pt":1646327058330,"mc":[{"id":"1.195532874","rc":[{"atb":[[3.75,2]],"id":40642034}],"con":true,"img":false}]}
{"op":"mcm","clk":"5323058371","pt":1646327059229,"mc":[{"id":"1.195532874","rc":[{"atb":[[2.78,0]],"id":40883678}],"con":true,"img":false}]}
{"op":"mcm","clk":"5323058435","pt":1646327060051,"mc":[{"id":"1.195532874","rc":[{"atb":[[5.4,0]],"id":39614765},{"atb":[[4.4,0]],"id":40642034}],"con":true,"img":false}]}
{"op":"mcm","clk":"5323058544","pt":1646327061253,"mc":[{"id":"1.195532874","rc":[{"atb":[[4.6,2.48]],"id":40642034},{"atb":[[2.8,0]],"id":40883678}],"con":true,"img":false}]}
{"op":"mcm","clk":"5323058553","pt":1646327061350,"mc":[{"id":"1.195532874","rc":[{"atb":[[2.78,1.99]],"id":40883678}],"con":true,"img":false}]}
{"op":"mcm","clk":"5323058571","pt":1646327061510,"mc":[{"id":"1.195532874","rc":[{"atb":[[4.5,0]],"id":40642034}],"con":true,"img":false}]}
{"op":"mcm","clk":"5323058582","pt":1646327061612,"mc":[{"id":"1.195532874","rc":[{"atb":[[4.3,1.99]],"id":40642034}],"con":true,"img":false}]}
{"op":"mcm","clk":"5323058600","pt":1646327061814,"mc":[{"id":"1.195532874","rc":[{"atb":[[5.5,0]],"id":39614765}],"con":true,"img":false}]}
{"op":"mcm","clk":"5323058607","pt":1646327061924,"mc":[{"id":"1.195532874","rc":[{"atl":[[34,4.23]],"id":41469398},{"atb":[[5.3,1.99]],"id":39614765}],"con":true,"img":false}]}
{"op":"mcm","clk":"5323058626","pt":1646327062129,"mc":[{"id":"1.195532874","rc":[{"atb":[[5.1,0]],"id":35985721}],"con":true,"img":false}]}
{"op":"mcm","clk":"5323058641","pt":1646327062235,"mc":[{"id":"1.195532874","rc":[{"atb":[[5,1.99]],"id":35985721}],"con":true,"img":false}]}
{"op":"mcm","clk":"5323058708","pt":1646327062958,"mc":[{"id":"1.195532874","rc":[{"atb":[[2.76,0],[2.74,17.2]],"id":40883678}],"con":true,"img":false}]}
{"op":"mcm","clk":"5323058728","pt":1646327063118,"mc":[{"id":"1.195532874","rc":[{"atb":[[4.8,10.36],[4.9,0]],"id":35985721}],"con":true,"img":false}]}
{"op":"mcm","clk":"5323058735","pt":1646327063223,"mc":[{"id":"1.195532874","rc":[{"atb":[[4.7,3.19]],"id":35985721}],"con":true,"img":false}]}
{"op":"mcm","clk":"5323058745","pt":1646327063320,"mc":[{"id":"1.195532874","rc":[{"atb":[[4.7,0]],"id":35985721}],"con":true,"img":false}]}
{"op":"mcm","clk":"5323058771","pt":1646327063736,"mc":[{"id":"1.195532874","rc":[{"atb":[[5.4,2.48]],"id":39614765}],"con":true,"img":false}]}
{"op":"mcm","clk":"5323058913","pt":1646327065339,"mc":[{"id":"1.195532874","rc":[{"atb":[[2.78,0]],"id":40883678}],"con":true,"img":false}]}
{"op":"mcm","clk":"5323058921","pt":1646327065443,"mc":[{"id":"1.195532874","rc":[{"atb":[[2.76,1.99]],"id":40883678}],"con":true,"img":false}]}
{"op":"mcm","clk":"5323058931","pt":1646327065661,"mc":[{"id":"1.195532874","rc":[{"atb":[[4.3,0]],"id":40642034}],"con":true,"img":false}]}
{"op":"mcm","clk":"5323058942","pt":1646327066110,"mc":[{"id":"1.195532874","rc":[{"atb":[[4.7,1.99]],"id":40642034}],"con":true,"img":false}]}
{"op":"mcm","clk":"5323058955","pt":1646327066135,"mc":[{"id":"1.195532874","rc":[{"atb":[[5.3,0]],"id":39614765}],"con":true,"img":false}]}
{"op":"mcm","clk":"5323058961","pt":1646327066152,"mc":[{"id":"1.195532874","rc":[{"atb":[[5.5,1.99]],"id":39614765}],"con":true,"img":false}]}
{"op":"mcm","clk":"5323058969","pt":1646327066166,"mc":[{"id":"1.195532874","rc":[{"atb":[[5,0]],"id":35985721}],"con":true,"img":false}]}
{"op":"mcm","clk":"5323058974","pt":1646327066222,"mc":[{"id":"1.195532874","rc":[{"atb":[[4.9,1.99]],"id":35985721}],"con":true,"img":false}]}
{"op":"mcm","clk":"5323058988","pt":1646327066426,"mc":[{"id":"1.195532874","rc":[{"atb":[[4.2,0]],"id":40642034}],"con":true,"img":false}]}
{"op":"mcm","clk":"5323059091","pt":1646327067825,"mc":[{"id":"1.195532874","rc":[{"atb":[[5.4,0]],"id":39614765},{"atb":[[4.6,0]],"id":40642034}],"con":true,"img":false}]}
{"op":"mcm","clk":"5323059120","pt":1646327068242,"mc":[{"id":"1.195532874","rc":[{"atb":[[2.78,3.29]],"id":40883678}],"con":true,"img":false}]}
{"op":"mcm","clk":"5323059134","pt":1646327068450,"mc":[{"id":"1.195532874","rc":[{"atb":[[4.8,0],[4.7,10.64]],"id":35985721}],"con":true,"img":false}]}
{"op":"mcm","clk":"5323059145","pt":1646327068657,"mc":[{"id":"1.195532874","rc":[{"atb":[[4.7,23.9]],"id":35985721}],"con":true,"img":false}]}
{"op":"mcm","clk":"5323059152","pt":1646327068764,"mc":[{"id":"1.195532874","rc":[{"atb":[[2.76,0]],"id":40883678}],"con":true,"img":false}]}
{"op":"mcm","clk":"5323059163","pt":1646327068867,"mc":[{"id":"1.195532874","rc":[{"atb":[[2.8,1.99]],"id":40883678}],"con":true,"img":false}]}
{"op":"mcm","clk":"5323059175","pt":1646327069075,"mc":[{"id":"1.195532874","rc":[{"atb":[[4.7,0]],"id":40642034}],"con":true,"img":false}]}
{"op":"mcm","clk":"5323059183","pt":1646327069133,"mc":[{"id":"1.195532874","rc":[{"atb":[[3.95,1.99]],"id":40642034}],"con":true,"img":false}]}
{"op":"mcm","clk":"5323059198","pt":1646327069342,"mc":[{"id":"1.195532874","rc":[{"atb":[[5.5,0]],"id":39614765}],"con":true,"img":false}]}
{"op":"mcm","clk":"5323059211","pt":1646327069458,"mc":[{"id":"1.195532874","rc":[{"atb":[[5.3,1.99]],"id":39614765}],"con":true,"img":false}]}
{"op":"mcm","clk":"5323059237","pt":1646327069663,"mc":[{"id":"1.195532874","rc":[{"atb":[[4.9,0]],"id":35985721}],"con":true,"img":false}]}
{"op":"mcm","clk":"5323059245","pt":1646327069755,"mc":[{"id":"1.195532874","rc":[{"atb":[[4.8,1.99]],"id":35985721}],"con":true,"img":false}]}
{"op":"mcm","clk":"5323059279","pt":1646327070170,"mc":[{"id":"1.195532874","rc":[{"atb":[[5.4,2.48]],"id":39614765},{"atb":[[4,2.48]],"id":40642034}],"con":true,"img":false}]}
{"op":"mcm","clk":"5323059302","pt":1646327070439,"mc":[{"id":"1.195532874","rc":[{"atb":[[3.95,0]],"id":40642034}],"con":true,"img":false}]}
{"op":"mcm","clk":"5323059310","pt":1646327070540,"mc":[{"id":"1.195532874","rc":[{"atb":[[4.1,1.99]],"id":40642034}],"con":true,"img":false}]}
{"op":"mcm","clk":"5323059337","pt":1646327070644,"mc":[{"id":"1.195532874","rc":[{"atb":[[5.3,0]],"id":39614765}],"con":true,"img":false}]}
{"op":"mcm","clk":"5323059342","pt":1646327070747,"mc":[{"id":"1.195532874","rc":[{"atb":[[5.5,1.99]],"id":39614765}],"con":true,"img":false}]}
{"op":"mcm","clk":"5323059368","pt":1646327071166,"mc":[{"id":"1.195532874","rc":[{"atb":[[4,0]],"id":40642034}],"con":true,"img":false}]}
{"op":"mcm","clk":"5323059392","pt":1646327071539,"mc":[{"id":"1.195532874","rc":[{"atb":[[4.1,0]],"id":40642034}],"con":true,"img":false}]}
{"op":"mcm","clk":"5323059400","pt":1646327071637,"mc":[{"id":"1.195532874","rc":[{"atb":[[3.95,1.99]],"id":40642034}],"con":true,"img":false}]}
{"op":"mcm","clk":"5323059408","pt":1646327071742,"mc":[{"id":"1.195532874","rc":[{"atb":[[4.2,1.65]],"id":40642034}],"con":true,"img":false}]}
{"op":"mcm","clk":"5323059422","pt":1646327071948,"mc":[{"id":"1.195532874","rc":[{"atl":[[38,6.29]],"id":41469398}],"con":true,"img":false}]}
{"op":"mcm","clk":"5323059438","pt":1646327072157,"mc":[{"id":"1.195532874","rc":[{"atb":[[3.95,0]],"id":40642034}],"con":true,"img":false}]}
{"op":"mcm","clk":"5323059445","pt":1646327072259,"mc":[{"id":"1.195532874","rc":[{"atb":[[3.8,1.99]],"id":40642034}],"con":true,"img":false}]}
{"op":"mcm","clk":"5323059452","pt":1646327072363,"mc":[{"id":"1.195532874","rc":[{"atb":[[4.8,4.92]],"id":35985721}],"con":true,"img":false}]}
{"op":"mcm","clk":"5323059496","pt":1646327072674,"mc":[{"id":"1.195532874","rc":[{"atb":[[5.4,0]],"id":39614765},{"atb":[[4.3,2.48]],"id":40642034}],"con":true,"img":false}]}
{"op":"mcm","clk":"5323059520","pt":1646327072938,"mc":[{"id":"1.195532874","rc":[{"atb":[[2.76,16.48],[2.74,0.53]],"id":40883678}],"con":true,"img":false}]}
{"op":"mcm","clk":"5323059545","pt":1646327073253,"mc":[{"id":"1.195532874","rc":[{"atb":[[3.8,0]],"id":40642034}],"con":true,"img":false}]}
{"op":"mcm","clk":"5323059550","pt":1646327073351,"mc":[{"id":"1.195532874","rc":[{"atb":[[4.4,1.99]],"id":40642034}],"con":true,"img":false}]}
{"op":"mcm","clk":"5323059565","pt":1646327073559,"mc":[{"id":"1.195532874","rc":[{"atb":[[5.5,0]],"id":39614765},{"atb":[[4.6,10.94],[4.7,13.26]],"id":35985721}],"con":true,"img":false}]}
{"op":"mcm","clk":"5323059569","pt":1646327073662,"mc":[{"id":"1.195532874","rc":[{"atb":[[5.3,1.99]],"id":39614765}],"con":true,"img":false}]}
{"op":"mcm","clk":"5323059723","pt":1646327075642,"mc":[{"id":"1.195532874","rc":[{"atb":[[5.4,2.48]],"id":39614765},{"atb":[[4.3,0]],"id":40642034}],"con":true,"img":false}]}
{"op":"mcm","clk":"5323059786","pt":1646327076575,"mc":[{"id":"1.195532874","rc":[{"atb":[[4.7,0]],"id":35985721}],"con":true,"img":false}]}
{"op":"mcm","clk":"5323059895","pt":1646327077941,"mc":[{"id":"1.195532874","rc":[{"spn":7.4,"spf":1.0,"id":35985721},{"spn":7.0,"spf":1.0,"id":39614765},{"atb":[[4.5,2.48]],"id":40642034},{"spn":5.35,"spf":1.0,"id":40642034},{"spn":2.79,"spf":1.0,"id":40883678}],"con":true,"img":false}]}
{"op":"mcm","clk":"5323059907","pt":1646327078043,"mc":[{"id":"1.195532874","rc":[{"atb":[[4.4,0]],"id":40642034}],"con":true,"img":false}]}
{"op":"mcm","clk":"5323059916","pt":1646327078147,"mc":[{"id":"1.195532874","rc":[{"atb":[[4.3,1.99]],"id":40642034}],"con":true,"img":false}]}
{"op":"mcm","clk":"5323059935","pt":1646327078351,"mc":[{"id":"1.195532874","rc":[{"atb":[[5.3,0]],"id":39614765}],"con":true,"img":false}]}
{"op":"mcm","clk":"5323059944","pt":1646327078453,"mc":[{"id":"1.195532874","rc":[{"atb":[[5.5,1.99]],"id":39614765}],"con":true,"img":false}]}
{"op":"mcm","clk":"5323059995","pt":1646327079140,"mc":[{"id":"1.195532874","rc":[{"atb":[[5.4,0]],"id":39614765}],"con":true,"img":false}]}
{"op":"mcm","clk":"5323060006","pt":1646327079346,"mc":[{"id":"1.195532874","rc":[{"atb":[[10.5,3.25]],"id":41469398},{"atb":[[4.3,0]],"id":40642034}],"con":true,"img":false}]}
{"op":"mcm","clk":"5323060015","pt":1646327079450,"mc":[{"id":"1.195532874","rc":[{"atb":[[4.6,1.99]],"id":40642034}],"con":true,"img":false}]}
{"op":"mcm","clk":"5323060026","pt":1646327079561,"mc":[{"id":"1.195532874","rc":[{"atb":[[5.5,0]],"id":39614765}],"con":true,"img":false}]}
{"op":"mcm","clk":"5323060035","pt":1646327079657,"mc":[{"id":"1.195532874","rc":[{"atb":[[5.3,1.99]],"id":39614765}],"con":true,"img":false}]}
{"op":"mcm","clk":"5323060104","pt":1646327080449,"mc":[{"id":"1.195532874","rc":[{"atb":[[2.78,0]],"id":40883678}],"con":true,"img":false}]}
{"op":"mcm","clk":"5323060218","pt":1646327081951,"mc":[{"id":"1.195532874","rc":[{"atb":[[5.4,2.48]],"id":39614765}],"con":true,"img":false}]}
{"op":"mcm","clk":"5323060225","pt":1646327082058,"mc":[{"id":"1.195532874","rc":[{"atb":[[4.5,0]],"id":40642034}],"con":true,"img":false}]}
{"op":"mcm","clk":"5323060275","pt":1646327082788,"mc":[{"id":"1.195532874","rc":[{"atb":[[2.8,0]],"id":40883678}],"con":true,"img":false}]}
{"op":"mcm","clk":"5323060286","pt":1646327082843,"mc":[{"id":"1.195532874","rc":[{"atb":[[2.78,1.99]],"id":40883678}],"con":true,"img":false}]}
{"op":"mcm","clk":"5323060293","pt":1646327082950,"mc":[{"id":"1.195532874","rc":[{"atb":[[2.76,0],[2.74,17.2]],"id":40883678}],"con":true,"img":false}]}
{"op":"mcm","clk":"5323060336","pt":1646327083468,"mc":[{"id":"1.195532874","rc":[{"atb":[[10,0]],"id":41469398}],"con":true,"img":false}]}
{"op":"mcm","clk":"5323060345","pt":1646327083567,"mc":[{"id":"1.195532874","rc":[{"atb":[[4.4,30.96]],"id":35985721}],"con":true,"img":false}]}
{"op":"mcm","clk":"5323060374","pt":1646327083881,"mc":[{"id":"1.195532874","rc":[{"atb":[[10.5,0.75]],"id":41469398}],"con":true,"img":false}]}
{"op":"mcm","clk":"5323060421","pt":1646327084501,"mc":[{"id":"1.195532874","rc":[{"atb":[[6.2,20.29]],"id":41469398}],"con":true,"img":false}]}
{"op":"mcm","clk":"5323060480","pt":1646327085180,"mc":[{"id":"1.195532874","rc":[{"atb":[[6.4,0],[6.2,19.23]],"id":41469398}],"con":true,"img":false}]}
{"op":"mcm","clk":"5323060487","pt":1646327085285,"mc":[{"id":"1.195532874","rc":[{"atb":[[6.8,2.63]],"id":41469398}],"con":true,"img":false}]}
{"op":"mcm","clk":"5323060694","pt":1646327088053,"mc":[{"id":"1.195532874","rc":[{"atb":[[4.6,0]],"id":40642034}],"con":true,"img":false}]}
{"op":"mcm","clk":"5323060701","pt":1646327088160,"mc":[{"id":"1.195532874","rc":[{"atb":[[4.3,1.99]],"id":40642034}],"con":true,"img":false}]}
{"op":"mcm","clk":"5323060723","pt":1646327088466,"mc":[{"id":"1.195532874","rc":[{"atb":[[10,2]],"id":41469398},{"atb":[[3.55,0]],"id":39614765}],"con":true,"img":false}]}
{"op":"mcm","clk":"5323060784","pt":1646327089195,"mc":[{"id":"1.195532874","rc":[{"atb":[[4.4,2.48]],"id":40642034}],"con":true,"img":false}]}
{"op":"mcm","clk":"5323060978","pt":1646327091494,"mc":[{"id":"1.195532874","rc":[{"atb":[[3.45,4.58]],"id":39614765}],"con":true,"img":false}]}
{"op":"mcm","clk":"5323061092","pt":1646327092861,"mc":[{"id":"1.195532874","rc":[{"atb":[[2.74,25.72]],"id":40883678}],"con":true,"img":false}]}
{"op":"mcm","clk":"5323061100","pt":1646327092964,"mc":[{"id":"1.195532874","rc":[{"atb":[[2.7,42.65]],"id":40883678}],"con":true,"img":false}]}
{"op":"mcm","clk":"5323061125","pt":1646327093380,"mc":[{"id":"1.195532874","rc":[{"atb":[[5.3,0]],"id":39614765}],"con":true,"img":false}]}
{"op":"mcm","clk":"5323061138","pt":1646327093483,"mc":[{"id":"1.195532874","rc":[{"atb":[[5.5,1.99]],"id":39614765}],"con":true,"img":false}]}
{"op":"mcm","clk":"5323061148","pt":1646327093586,"mc":[{"id":"1.195532874","rc":[{"atb":[[4.2,46.15]],"id":35985721}],"con":true,"img":false}]}
{"op":"mcm","clk":"5323061235","pt":1646327094377,"mc":[{"id":"1.195532874","rc":[{"atb":[[5.4,0]],"id":39614765}],"con":true,"img":false}]}
{"op":"mcm","clk":"5323061342","pt":1646327095575,"mc":[{"id":"1.195532874","rc":[{"atb":[[2.78,0]],"id":40883678}],"con":true,"img":false}]}
{"op":"mcm","clk":"5323061353","pt":1646327095680,"mc":[{"id":"1.195532874","rc":[{"atb":[[2.76,1.99]],"id":40883678}],"con":true,"img":false}]}
{"op":"mcm","clk":"5323061368","pt":1646327095888,"mc":[{"id":"1.195532874","rc":[{"atb":[[4.3,0]],"id":40642034}],"con":true,"img":false}]}
{"op":"mcm","clk":"5323061374","pt":1646327095994,"mc":[{"id":"1.195532874","rc":[{"atb":[[4.5,1.99]],"id":40642034}],"con":true,"img":false}]}
{"op":"mcm","clk":"5323061405","pt":1646327096308,"mc":[{"id":"1.195532874","rc":[{"atb":[[5.5,0]],"id":39614765}],"con":true,"img":false}]}
{"op":"mcm","clk":"5323061410","pt":1646327096410,"mc":[{"id":"1.195532874","rc":[{"atb":[[5.3,1.99]],"id":39614765}],"con":true,"img":false}]}
{"op":"mcm","clk":"5323061418","pt":1646327096512,"mc":[{"id":"1.195532874","rc":[{"atb":[[2.74,17.2]],"id":40883678}],"con":true,"img":false}]}
{"op":"mcm","clk":"5323061463","pt":1646327097087,"mc":[{"id":"1.195532874","rc":[{"atb":[[5.4,2.48]],"id":39614765},{"atb":[[4.4,0]],"id":40642034}],"con":true,"img":false}]}
{"op":"mcm","clk":"5323061504","pt":1646327097709,"mc":[{"id":"1.195532874","rc":[{"atb":[[4.5,0]],"id":40642034}],"con":true,"img":false}]}
{"op":"mcm","clk":"5323061510","pt":1646327097814,"mc":[{"id":"1.195532874","rc":[{"atb":[[4.3,1.99]],"id":40642034},{"atb":[[2.78,3.29]],"id":40883678}],"con":true,"img":false}]}
{"op":"mcm","clk":"5323061524","pt":1646327097976,"mc":[{"id":"1.195532874","rc":[{"atb":[[5.3,0]],"id":39614765}],"con":true,"img":false}]}
{"op":"mcm","clk":"5323061531","pt":1646327098077,"mc":[{"id":"1.195532874","rc":[{"atb":[[5.5,1.99]],"id":39614765}],"con":true,"img":false}]}
{"op":"mcm","clk":"5323061662","pt":1646327099588,"mc":[{"id":"1.195532874","rc":[{"atb":[[5.4,0]],"id":39614765},{"atb":[[4.4,2.48]],"id":40642034}],"con":true,"img":false}]}
{"op":"mcm","clk":"5323061960","pt":1646327102991,"mc":[{"id":"1.195532874","rc":[{"atb":[[2.58,0],[2.66,65.52]],"id":40883678}],"con":true,"img":false}]}
{"op":"mcm","clk":"5323062022","pt":1646327103616,"mc":[{"id":"1.195532874","rc":[{"atb":[[4,82.05]],"id":35985721}],"con":true,"img":false}]}
{"op":"mcm","clk":"5323062106","pt":1646327104402,"mc":[{"id":"1.195532874","rc":[{"atb":[[2.76,0]],"id":40883678}],"con":true,"img":false}]}
{"op":"mcm","clk":"5323062118","pt":1646327104506,"mc":[{"id":"1.195532874","rc":[{"atb":[[2.8,1.99]],"id":40883678}],"con":true,"img":false}]}
{"op":"mcm","clk":"5323062224","pt":1646327105406,"mc":[{"id":"1.195532874","rc":[{"atb":[[4.3,0]],"id":40642034}],"con":true,"img":false}]}
{"op":"mcm","clk":"5323062240","pt":1646327105512,"mc":[{"id":"1.195532874","rc":[{"atb":[[4.5,1.99]],"id":40642034}],"con":true,"img":false}]}
{"op":"mcm","clk":"5323062263","pt":1646327105716,"mc":[{"id":"1.195532874","rc":[{"atb":[[5.5,0]],"id":39614765}],"con":true,"img":false}]}
{"op":"mcm","clk":"5323062274","pt":1646327105820,"mc":[{"id":"1.195532874","rc":[{"atb":[[5.3,1.99]],"id":39614765}],"con":true,"img":false}]}
{"op":"mcm","clk":"5323062375","pt":1646327106813,"mc":[{"id":"1.195532874","rc":[{"atb":[[5.4,2.48]],"id":39614765},{"atb":[[4.4,0]],"id":40642034}],"con":true,"img":false}]}
{"op":"mcm","clk":"5323062421","pt":1646327107287,"mc":[{"id":"1.195532874","rc":[{"atb":[[4.5,0]],"id":40642034}],"con":true,"img":false}]}
{"op":"mcm","clk":"5323062431","pt":1646327107397,"mc":[{"id":"1.195532874","rc":[{"atb":[[4.3,1.99]],"id":40642034}],"con":true,"img":false}]}
{"op":"mcm","clk":"5323062642","pt":1646327109912,"mc":[{"id":"1.195532874","rc":[{"atb":[[4.4,2.48]],"id":40642034}],"con":true,"img":false}]}
{"op":"mcm","clk":"5323062655","pt":1646327110121,"mc":[{"id":"1.195532874","rc":[{"atb":[[2.78,0]],"id":40883678}],"con":true,"img":false}]}
{"op":"mcm","clk":"5323062674","pt":1646327110328,"mc":[{"id":"1.195532874","rc":[{"atb":[[10.5,4.75]],"id":41469398}],"con":true,"img":false}]}
{"op":"mcm","clk":"5323062886","pt":1646327112635,"mc":[{"id":"1.195532874","rc":[{"atb":[[5.3,0]],"id":39614765}],"con":true,"img":false}]}
{"op":"mcm","clk":"5323062894","pt":1646327112691,"mc":[{"id":"1.195532874","rc":[{"atb":[[5.5,1.99]],"id":39614765}],"con":true,"img":false}]}
{"op":"mcm","clk":"5323062920","pt":1646327113000,"mc":[{"id":"1.195532874","rc":[{"atb":[[2.76,16.48],[2.74,0.53]],"id":40883678}],"con":true,"img":false}]}
{"op":"mcm","clk":"5323062967","pt":1646327113625,"mc":[{"id":"1.195532874","rc":[{"atb":[[10,0]],"id":41469398}],"con":true,"img":false}]}
{"op":"mcm","clk":"5323062977","pt":1646327113729,"mc":[{"id":"1.195532874","rc":[{"atb":[[2.8,0]],"id":40883678}],"con":true,"img":false}]}
{"op":"mcm","clk":"5323062993","pt":1646327113833,"mc":[{"id":"1.195532874","rc":[{"atb":[[2.78,1.99]],"id":40883678}],"con":true,"img":false}]}
{"op":"mcm","clk":"5323063011","pt":1646327113995,"mc":[{"id":"1.195532874","rc":[{"atb":[[4.3,0]],"id":40642034}],"con":true,"img":false}]}
{"op":"mcm","clk":"5323063021","pt":1646327114099,"mc":[{"id":"1.195532874","rc":[{"atb":[[4.5,1.99]],"id":40642034}],"con":true,"img":false}]}
{"op":"mcm","clk":"5323063092","pt":1646327114932,"mc":[{"id":"1.195532874","rc":[{"atb":[[5.4,0]],"id":39614765},{"atb":[[4.4,0]],"id":40642034}],"con":true,"img":false}]}
{"op":"mcm","clk":"5323063208","pt":1646327116032,"mc":[{"id":"1.195532874","rc":[{"atb":[[4.5,0]],"id":40642034}],"con":true,"img":false}]}
{"op":"mcm","clk":"5323063217","pt":1646327116134,"mc":[{"id":"1.195532874","rc":[{"atb":[[4.3,1.99]],"id":40642034}],"con":true,"img":false}]}
{"op":"mcm","clk":"5323063250","pt":1646327116502,"mc":[{"id":"1.195532874","rc":[{"atb":[[10.5,0.75]],"id":41469398}],"con":true,"img":false}]}
{"op":"mcm","clk":"5323063324","pt":1646327117229,"mc":[{"id":"1.195532874","rc":[{"atb":[[4.4,2.48]],"id":40642034}],"con":true,"img":false}]}
{"op":"mcm","clk":"5323063444","pt":1646327118631,"mc":[{"id":"1.195532874","rc":[{"atb":[[10,2]],"id":41469398}],"con":true,"img":false}]}
{"op":"mcm","clk":"5323063673","pt":1646327121345,"mc":[{"id":"1.195532874","rc":[{"atb":[[5.5,0]],"id":39614765}],"con":true,"img":false}]}
{"op":"mcm","clk":"5323063683","pt":1646327121450,"mc":[{"id":"1.195532874","rc":[{"atb":[[5.3,1.99]],"id":39614765}],"con":true,"img":false}]}
{"op":"mcm","clk":"5323063751","pt":1646327122231,"mc":[{"id":"1.195532874","rc":[{"atb":[[5.4,2.48]],"id":39614765}],"con":true,"img":false}]}
{"op":"mcm","clk":"5323063802","pt":1646327122807,"mc":[{"id":"1.195532874","rc":[{"atb":[[4.3,0]],"id":40642034}],"con":true,"img":false}]}
{"op":"mcm","clk":"5323063810","pt":1646327122912,"mc":[{"id":"1.195532874","rc":[{"atb":[[4.5,1.99]],"id":40642034}],"con":true,"img":false}]}
{"op":"mcm","clk":"5323063821","pt":1646327123015,"mc":[{"id":"1.195532874","rc":[{"atb":[[2.74,17.2]],"id":40883678}],"con":true,"img":false}]}
{"op":"mcm","clk":"5323063830","pt":1646327123117,"mc":[{"id":"1.195532874","rc":[{"atb":[[2.76,0]],"id":40883678}],"con":true,"img":false}]}
{"op":"mcm","clk":"5323063838","pt":1646327123223,"mc":[{"id":"1.195532874","rc":[{"atb":[[5.3,0]],"id":39614765}],"con":true,"img":false}]}
{"op":"mcm","clk":"5323063846","pt":1646327123328,"mc":[{"id":"1.195532874","rc":[{"atb":[[5.5,1.99]],"id":39614765}],"con":true,"img":false}]}
{"op":"mcm","clk":"5323063938","pt":1646327124547,"mc":[{"id":"1.195532874","rc":[{"atb":[[5.4,0]],"id":39614765},{"atb":[[4.4,0]],"id":40642034}],"con":true,"img":false}]}
{"op":"mcm","clk":"5323063969","pt":1646327124915,"mc":[{"id":"1.195532874","rc":[{"atb":[[2.78,0]],"id":40883678}],"con":true,"img":false}]}
{"op":"mcm","clk":"5323063983","pt":1646327125018,"mc":[{"id":"1.195532874","rc":[{"atb":[[2.76,1.99]],"id":40883678}],"con":true,"img":false}]}
{"op":"mcm","clk":"5323063993","pt":1646327125122,"mc":[{"id":"1.195532874","rc":[{"atb":[[4.5,0]],"id":40642034}],"con":true,"img":false}]}
{"op":"mcm","clk":"5323064008","pt":1646327125226,"mc":[{"id":"1.195532874","rc":[{"atb":[[4.3,1.99]],"id":40642034}],"con":true,"img":false}]}
{"op":"mcm","clk":"5323064034","pt":1646327125440,"mc":[{"id":"1.195532874","rc":[{"atb":[[5.5,0]],"id":39614765}],"con":true,"img":false}]}
{"op":"mcm","clk":"5323064046","pt":1646327125544,"mc":[{"id":"1.195532874","rc":[{"atb":[[5.3,1.99]],"id":39614765}],"con":true,"img":false}]}
{"op":"mcm","clk":"5323064109","pt":1646327126320,"mc":[{"id":"1.195532874","rc":[{"atb":[[5.4,2.48]],"id":39614765},{"atb":[[4.4,2.48]],"id":40642034}],"con":true,"img":false}]}
{"op":"mcm","clk":"5323064140","pt":1646327126636,"mc":[{"id":"1.195532874","rc":[{"atb":[[4.3,0]],"id":40642034}],"con":true,"img":false}]}
{"op":"mcm","clk":"5323064148","pt":1646327126741,"mc":[{"id":"1.195532874","rc":[{"atb":[[4.5,1.99]],"id":40642034}],"con":true,"img":false}]}
{"op":"mcm","clk":"5323064163","pt":1646327126943,"mc":[{"id":"1.195532874","rc":[{"atb":[[5.3,0]],"id":39614765}],"con":true,"img":false}]}
{"op":"mcm","clk":"5323064169","pt":1646327127048,"mc":[{"id":"1.195532874","rc":[{"atb":[[5.5,1.99]],"id":39614765}],"con":true,"img":false}]}
{"op":"mcm","clk":"5323064187","pt":1646327127254,"mc":[{"id":"1.195532874","rc":[{"atb":[[2.78,3.29]],"id":40883678}],"con":true,"img":false}]}
{"op":"mcm","clk":"5323064225","pt":1646327127626,"mc":[{"id":"1.195532874","rc":[{"atb":[[2.76,0]],"id":40883678}],"con":true,"img":false}]}
{"op":"mcm","clk":"5323064235","pt":1646327127726,"mc":[{"id":"1.195532874","rc":[{"atb":[[6,3.2]],"id":35985721},{"atb":[[2.8,1.99]],"id":40883678}],"con":true,"img":false}]}
{"op":"mcm","clk":"5323064305","pt":1646327128678,"mc":[{"id":"1.195532874","rc":[{"atb":[[4.8,2.93]],"id":35985721}],"con":true,"img":false}]}
{"op":"mcm","clk":"5323064311","pt":1646327128776,"mc":[{"id":"1.195532874","rc":[{"atb":[[6.2,1.99]],"id":35985721}],"con":true,"img":false}]}
