{"op":"mcm","clk":"5352092080","pt":1646182319000,"mc":[{"id":"1.195503866","marketDefinition":{"bspMarket":false,"turnInPlayEnabled":false,"persistenceEnabled":false,"marketBaseRate":7.0,"eventId":"31272499","eventTypeId":"4339","numberOfWinners":1,"bettingType":"ODDS","marketType":"EXACTA","marketTime":"2022-03-02T10:32:00.000Z","suspendTime":"2022-03-02T10:32:00.000Z","bspReconciled":false,"complete":true,"inPlay":false,"crossMatching":false,"runnersVoidable":false,"numberOfActiveRunners":42,"betDelay":0,"status":"OPEN","runners":[{"status":"ACTIVE","sortPriority":1,"id":41419585,"name":"1 - 2"},{"status":"ACTIVE","sortPriority":2,"id":41419586,"name":"1 - 3"},{"status":"ACTIVE","sortPriority":3,"id":41419587,"name":"1 - 4"},{"status":"ACTIVE","sortPriority":4,"id":41419589,"name":"1 - 6"},{"status":"ACTIVE","sortPriority":5,"id":41419590,"name":"1 - 7"},{"status":"ACTIVE","sortPriority":6,"id":41419591,"name":"1 - 8"},{"status":"ACTIVE","sortPriority":7,"id":41419592,"name":"2 - 1"},{"status":"ACTIVE","sortPriority":8,"id":41419593,"name":"2 - 3"},{"status":"ACTIVE","sortPriority":9,"id":41419594,"name":"2 - 4"},{"status":"ACTIVE","sortPriority":10,"id":41419596,"name":"2 - 6"},{"status":"ACTIVE","sortPriority":11,"id":41419597,"name":"2 - 7"},{"status":"ACTIVE","sortPriority":12,"id":41419598,"name":"2 - 8"},{"status":"ACTIVE","sortPriority":13,"id":41419599,"name":"3 - 1"},{"status":"ACTIVE","sortPriority":14,"id":41419600,"name":"3 - 2"},{"status":"ACTIVE","sortPriority":15,"id":41419601,"name":"3 - 4"},{"status":"ACTIVE","sortPriority":16,"id":41419603,"name":"3 - 6"},{"status":"ACTIVE","sortPriority":17,"id":41419604,"name":"3 - 7"},{"status":"ACTIVE","sortPriority":18,"id":41419605,"name":"3 - 8"},{"status":"ACTIVE","sortPriority":19,"id":41419606,"name":"4 - 1"},{"status":"ACTIVE","sortPriority":20,"id":41419607,"name":"4 - 2"},{"status":"ACTIVE","sortPriority":21,"id":41419608,"name":"4 - 3"},{"status":"ACTIVE","sortPriority":22,"id":41419610,"name":"4 - 6"},{"status":"ACTIVE","sortPriority":23,"id":41419611,"name":"4 - 7"},{"status":"ACTIVE","sortPriority":24,"id":41419612,"name":"4 - 8"},{"status":"ACTIVE","sortPriority":25,"id":41419620,"name":"6 - 1"},{"status":"ACTIVE","sortPriority":26,"id":41419621,"name":"6 - 2"},{"status":"ACTIVE","sortPriority":27,"id":41419622,"name":"6 - 3"},{"status":"ACTIVE","sortPriority":28,"id":41419623,"name":"6 - 4"},{"status":"ACTIVE","sortPriority":29,"id":41419625,"name":"6 - 7"},{"status":"ACTIVE","sortPriority":30,"id":41419626,"name":"6 - 8"},{"status":"ACTIVE","sortPriority":31,"id":41419627,"name":"7 - 1"},{"status":"ACTIVE","sortPriority":32,"id":41419628,"name":"7 - 2"},{"status":"ACTIVE","sortPriority":33,"id":41419629,"name":"7 - 3"},{"status":"ACTIVE","sortPriority":34,"id":41419630,"name":"7 - 4"},{"status":"ACTIVE","sortPriority":35,"id":41419632,"name":"7 - 6"},{"status":"ACTIVE","sortPriority":36,"id":41419633,"name":"7 - 8"},{"status":"ACTIVE","sortPriority":37,"id":41419634,"name":"8 - 1"},{"status":"ACTIVE","sortPriority":38,"id":41419635,"name":"8 - 2"},{"status":"ACTIVE","sortPriority":39,"id":41419636,"name":"8 - 3"},{"status":"ACTIVE","sortPriority":40,"id":41419637,"name":"8 - 4"},{"status":"ACTIVE","sortPriority":41,"id":41419639,"name":"8 - 6"},{"status":"ACTIVE","sortPriority":42,"id":41419640,"name":"8 - 7"}],"regulators":["MR_INT"],"venue":"Rockhampton","countryCode":"AU","discountAllowed":true,"timezone":"Australia/Queensland","openDate":"2022-03-02T08:34:00.000Z","version":4382565146,"name":"Exacta","eventName":"Rockhampton (AUS) 2nd Mar"},"rc":[],"con":true,"img":false}]}
{"op":"mcm","clk":"5352095595","pt":1646182411189,"mc":[{"id":"1.195503866","rc":[{"atb":[[16,13.3],[11,26.61],[27,7.67]],"id":41419640},{"atb":[[22,9.5],[13.5,15.96],[9.4,31.68]],"id":41419607},{"atb":[[65,3.11],[19,14.78],[28,7.39]],"id":41419605},{"atb":[[17,16.63],[48,4.24],[24,8.67]],"id":41419636},{"atb":[[540,0.37],[690,0.28],[440,0.6]],"id":41419603},{"atb":[[4.5,57.02],[6,39.91],[3.75,96.77]],"id":41419634},{"atb":[[36,5.7],[19,11.08],[14,20.47]],"id":41419611},{"atb":[[95,2.12],[48,5.66],[240,0.83]],"id":41419593},{"atb":[[4,66.52],[5.5,44.35],[3.5,106.44]],"id":41419591},{"atb":[[520,0.38],[670,0.29],[420,0.63]],"id":41419622},{"atb":[[19.5,10.79],[12,18.14],[8.8,34.11]],"id":41419589},{"atb":[[10.5,28.01],[26,7.98],[15.5,13.76]],"id":41419620},{"atb":[[7.4,31.18],[5.2,47.52],[4.2,83.16]],"id":41419587},{"atb":[[42,4.86],[26,10.64],[110,1.82]],"id":41419601},{"atb":[[70,2.89],[38,7.19],[190,1.05]],"id":41419632},{"atb":[[17,16.63],[48,4.24],[24,8.67]],"id":41419599},{"atb":[[42,4.86],[21,9.97],[15.5,18.35]],"id":41419630},{"atb":[[18,15.65],[26,7.98],[55,3.69]],"id":41419597},{"atb":[[18.5,15.2],[27,7.67],[60,3.38]],"id":41419628},{"atb":[[17.5,12.09],[12.5,23.13],[30,6.88]],"id":41419626},{"atb":[[34,6.04],[85,2.37],[22,12.67]],"id":41419608},{"atb":[[16,13.3],[11,26.61],[27,7.67]],"id":41419639},{"atb":[[4.8,70.02],[8.6,26.26],[5.8,41.58]],"id":41419606},{"atb":[[10,22.17],[5.5,59.13],[7,33.26]],"id":41419637},{"atb":[[540,0.37],[690,0.28],[440,0.6]],"id":41419604},{"atb":[[17,12.47],[9.8,22.68],[7.8,39.13]],"id":41419635},{"atb":[[11,19.95],[7.4,31.18],[5.7,56.62]],"id":41419585},{"atb":[[5.8,55.43],[11.5,19],[7.6,30.24]],"id":41419612},{"atb":[[36,5.7],[19,11.08],[14,20.47]],"id":41419610},{"atb":[[70,2.89],[38,7.19],[190,1.05]],"id":41419625},{"atb":[[9,24.94],[7,44.35],[15,14.25]],"id":41419592},{"atb":[[42,4.86],[21,9.97],[15.5,18.35]],"id":41419623},{"atb":[[19.5,10.79],[12,18.14],[8.8,34.11]],"id":41419590},{"atb":[[18.5,15.2],[27,7.67],[60,3.38]],"id":41419621},{"atb":[[36,5.7],[19,11.08],[14,20.47]],"id":41419586},{"atb":[[17.5,12.09],[12.5,23.13],[30,6.88]],"id":41419633},{"atb":[[270,0.74],[120,1.67],[60,4.5]],"id":41419600},{"atb":[[18.5,11.4],[11,19.95],[8.4,35.95]],"id":41419598},{"atb":[[520,0.38],[670,0.29],[420,0.63]],"id":41419629},{"atb":[[18,15.65],[26,7.98],[55,3.69]],"id":41419596},{"atb":[[10.5,28.01],[26,7.98],[15.5,13.76]],"id":41419627},{"atb":[[24,8.67],[9.8,30.24],[14.5,14.78]],"id":41419594}],"con":true,"img":false}]}
{"op":"mcm","clk":"5352146181","pt":1646183572644,"mc":[{"id":"1.195503866","marketDefinition":{"bspMarket":false,"turnInPlayEnabled":false,"persistenceEnabled":false,"marketBaseRate":7.0,"eventId":"31272499","eventTypeId":"4339","numberOfWinners":1,"bettingType":"ODDS","marketType":"EXACTA","marketTime":"2022-03-02T10:32:00.000Z","suspendTime":"2022-03-02T10:32:00.000Z","bspReconciled":false,"complete":true,"inPlay":false,"crossMatching":false,"runnersVoidable":false,"numberOfActiveRunners":42,"betDelay":0,"status":"OPEN","runners":[{"status":"ACTIVE","sortPriority":1,"id":41419585,"name":"1 - 2"},{"status":"ACTIVE","sortPriority":2,"id":41419586,"name":"1 - 3"},{"status":"ACTIVE","sortPriority":3,"id":41419587,"name":"1 - 4"},{"status":"ACTIVE","sortPriority":4,"id":41419589,"name":"1 - 6"},{"status":"ACTIVE","sortPriority":5,"id":41419590,"name":"1 - 7"},{"status":"ACTIVE","sortPriority":6,"id":41419591,"name":"1 - 8"},{"status":"ACTIVE","sortPriority":7,"id":41419592,"name":"2 - 1"},{"status":"ACTIVE","sortPriority":8,"id":41419593,"name":"2 - 3"},{"status":"ACTIVE","sortPriority":9,"id":41419594,"name":"2 - 4"},{"status":"ACTIVE","sortPriority":10,"id":41419596,"name":"2 - 6"},{"status":"ACTIVE","sortPriority":11,"id":41419597,"name":"2 - 7"},{"status":"ACTIVE","sortPriority":12,"id":41419598,"name":"2 - 8"},{"status":"ACTIVE","sortPriority":13,"id":41419599,"name":"3 - 1"},{"status":"ACTIVE","sortPriority":14,"id":41419600,"name":"3 - 2"},{"status":"ACTIVE","sortPriority":15,"id":41419601,"name":"3 - 4"},{"status":"ACTIVE","sortPriority":16,"id":41419603,"name":"3 - 6"},{"status":"ACTIVE","sortPriority":17,"id":41419604,"name":"3 - 7"},{"status":"ACTIVE","sortPriority":18,"id":41419605,"name":"3 - 8"},{"status":"ACTIVE","sortPriority":19,"id":41419606,"name":"4 - 1"},{"status":"ACTIVE","sortPriority":20,"id":41419607,"name":"4 - 2"},{"status":"ACTIVE","sortPriority":21,"id":41419608,"name":"4 - 3"},{"status":"ACTIVE","sortPriority":22,"id":41419610,"name":"4 - 6"},{"status":"ACTIVE","sortPriority":23,"id":41419611,"name":"4 - 7"},{"status":"ACTIVE","sortPriority":24,"id":41419612,"name":"4 - 8"},{"status":"ACTIVE","sortPriority":25,"id":41419620,"name":"6 - 1"},{"status":"ACTIVE","sortPriority":26,"id":41419621,"name":"6 - 2"},{"status":"ACTIVE","sortPriority":27,"id":41419622,"name":"6 - 3"},{"status":"ACTIVE","sortPriority":28,"id":41419623,"name":"6 - 4"},{"status":"ACTIVE","sortPriority":29,"id":41419625,"name":"6 - 7"},{"status":"ACTIVE","sortPriority":30,"id":41419626,"name":"6 - 8"},{"status":"ACTIVE","sortPriority":31,"id":41419627,"name":"7 - 1"},{"status":"ACTIVE","sortPriority":32,"id":41419628,"name":"7 - 2"},{"status":"ACTIVE","sortPriority":33,"id":41419629,"name":"7 - 3"},{"status":"ACTIVE","sortPriority":34,"id":41419630,"name":"7 - 4"},{"status":"ACTIVE","sortPriority":35,"id":41419632,"name":"7 - 6"},{"status":"ACTIVE","sortPriority":36,"id":41419633,"name":"7 - 8"},{"status":"ACTIVE","sortPriority":37,"id":41419634,"name":"8 - 1"},{"status":"ACTIVE","sortPriority":38,"id":41419635,"name":"8 - 2"},{"status":"ACTIVE","sortPriority":39,"id":41419636,"name":"8 - 3"},{"status":"ACTIVE","sortPriority":40,"id":41419637,"name":"8 - 4"},{"status":"ACTIVE","sortPriority":41,"id":41419639,"name":"8 - 6"},{"status":"ACTIVE","sortPriority":42,"id":41419640,"name":"8 - 7"}],"regulators":["MR_INT"],"venue":"Rockhampton","countryCode":"AU","discountAllowed":true,"timezone":"Australia/Queensland","openDate":"2022-03-02T08:28:00.000Z","version":4382597900,"name":"Exacta","eventName":"Rockhampton (AUS) 2nd Mar"},"rc":[],"con":true,"img":false}]}
{"op":"mcm","clk":"5352160754","pt":1646183957460,"mc":[{"id":"1.195503866","marketDefinition":{"bspMarket":false,"turnInPlayEnabled":false,"persistenceEnabled":false,"marketBaseRate":7.0,"eventId":"31272499","eventTypeId":"4339","numberOfWinners":1,"bettingType":"ODDS","marketType":"EXACTA","marketTime":"2022-03-02T10:24:00.000Z","suspendTime":"2022-03-02T10:24:00.000Z","bspReconciled":false,"complete":true,"inPlay":false,"crossMatching":false,"runnersVoidable":false,"numberOfActiveRunners":42,"betDelay":0,"status":"OPEN","runners":[{"status":"ACTIVE","sortPriority":1,"id":41419585,"name":"1 - 2"},{"status":"ACTIVE","sortPriority":2,"id":41419586,"name":"1 - 3"},{"status":"ACTIVE","sortPriority":3,"id":41419587,"name":"1 - 4"},{"status":"ACTIVE","sortPriority":4,"id":41419589,"name":"1 - 6"},{"status":"ACTIVE","sortPriority":5,"id":41419590,"name":"1 - 7"},{"status":"ACTIVE","sortPriority":6,"id":41419591,"name":"1 - 8"},{"status":"ACTIVE","sortPriority":7,"id":41419592,"name":"2 - 1"},{"status":"ACTIVE","sortPriority":8,"id":41419593,"name":"2 - 3"},{"status":"ACTIVE","sortPriority":9,"id":41419594,"name":"2 - 4"},{"status":"ACTIVE","sortPriority":10,"id":41419596,"name":"2 - 6"},{"status":"ACTIVE","sortPriority":11,"id":41419597,"name":"2 - 7"},{"status":"ACTIVE","sortPriority":12,"id":41419598,"name":"2 - 8"},{"status":"ACTIVE","sortPriority":13,"id":41419599,"name":"3 - 1"},{"status":"ACTIVE","sortPriority":14,"id":41419600,"name":"3 - 2"},{"status":"ACTIVE","sortPriority":15,"id":41419601,"name":"3 - 4"},{"status":"ACTIVE","sortPriority":16,"id":41419603,"name":"3 - 6"},{"status":"ACTIVE","sortPriority":17,"id":41419604,"name":"3 - 7"},{"status":"ACTIVE","sortPriority":18,"id":41419605,"name":"3 - 8"},{"status":"ACTIVE","sortPriority":19,"id":41419606,"name":"4 - 1"},{"status":"ACTIVE","sortPriority":20,"id":41419607,"name":"4 - 2"},{"status":"ACTIVE","sortPriority":21,"id":41419608,"name":"4 - 3"},{"status":"ACTIVE","sortPriority":22,"id":41419610,"name":"4 - 6"},{"status":"ACTIVE","sortPriority":23,"id":41419611,"name":"4 - 7"},{"status":"ACTIVE","sortPriority":24,"id":41419612,"name":"4 - 8"},{"status":"ACTIVE","sortPriority":25,"id":41419620,"name":"6 - 1"},{"status":"ACTIVE","sortPriority":26,"id":41419621,"name":"6 - 2"},{"status":"ACTIVE","sortPriority":27,"id":41419622,"name":"6 - 3"},{"status":"ACTIVE","sortPriority":28,"id":41419623,"name":"6 - 4"},{"status":"ACTIVE","sortPriority":29,"id":41419625,"name":"6 - 7"},{"status":"ACTIVE","sortPriority":30,"id":41419626,"name":"6 - 8"},{"status":"ACTIVE","sortPriority":31,"id":41419627,"name":"7 - 1"},{"status":"ACTIVE","sortPriority":32,"id":41419628,"name":"7 - 2"},{"status":"ACTIVE","sortPriority":33,"id":41419629,"name":"7 - 3"},{"status":"ACTIVE","sortPriority":34,"id":41419630,"name":"7 - 4"},{"status":"ACTIVE","sortPriority":35,"id":41419632,"name":"7 - 6"},{"status":"ACTIVE","sortPriority":36,"id":41419633,"name":"7 - 8"},{"status":"ACTIVE","sortPriority":37,"id":41419634,"name":"8 - 1"},{"status":"ACTIVE","sortPriority":38,"id":41419635,"name":"8 - 2"},{"status":"ACTIVE","sortPriority":39,"id":41419636,"name":"8 - 3"},{"status":"ACTIVE","sortPriority":40,"id":41419637,"name":"8 - 4"},{"status":"ACTIVE","sortPriority":41,"id":41419639,"name":"8 - 6"},{"status":"ACTIVE","sortPriority":42,"id":41419640,"name":"8 - 7"}],"regulators":["MR_INT"],"venue":"Rockhampton","countryCode":"AU","discountAllowed":true,"timezone":"Australia/Queensland","openDate":"2022-03-02T08:28:00.000Z","version":4382604931,"name":"Exacta","eventName":"Rockhampton (AUS) 2nd Mar"},"rc":[],"con":true,"img":false}]}
{"op":"mcm","clk":"5352239443","pt":1646185602749,"mc":[{"id":"1.195503866","marketDefinition":{"bspMarket":false,"turnInPlayEnabled":false,"persistenceEnabled":false,"marketBaseRate":7.0,"eventId":"31272499","eventTypeId":"4339","numberOfWinners":1,"bettingType":"ODDS","marketType":"EXACTA","marketTime":"2022-03-02T10:24:00.000Z","suspendTime":"2022-03-02T10:24:00.000Z","bspReconciled":false,"complete":true,"inPlay":false,"crossMatching":false,"runnersVoidable":false,"numberOfActiveRunners":42,"betDelay":0,"status":"OPEN","runners":[{"status":"ACTIVE","sortPriority":1,"id":41419585,"name":"1 - 2"},{"status":"ACTIVE","sortPriority":2,"id":41419586,"name":"1 - 3"},{"status":"ACTIVE","sortPriority":3,"id":41419587,"name":"1 - 4"},{"status":"ACTIVE","sortPriority":4,"id":41419589,"name":"1 - 6"},{"status":"ACTIVE","sortPriority":5,"id":41419590,"name":"1 - 7"},{"status":"ACTIVE","sortPriority":6,"id":41419591,"name":"1 - 8"},{"status":"ACTIVE","sortPriority":7,"id":41419592,"name":"2 - 1"},{"status":"ACTIVE","sortPriority":8,"id":41419593,"name":"2 - 3"},{"status":"ACTIVE","sortPriority":9,"id":41419594,"name":"2 - 4"},{"status":"ACTIVE","sortPriority":10,"id":41419596,"name":"2 - 6"},{"status":"ACTIVE","sortPriority":11,"id":41419597,"name":"2 - 7"},{"status":"ACTIVE","sortPriority":12,"id":41419598,"name":"2 - 8"},{"status":"ACTIVE","sortPriority":13,"id":41419599,"name":"3 - 1"},{"status":"ACTIVE","sortPriority":14,"id":41419600,"name":"3 - 2"},{"status":"ACTIVE","sortPriority":15,"id":41419601,"name":"3 - 4"},{"status":"ACTIVE","sortPriority":16,"id":41419603,"name":"3 - 6"},{"status":"ACTIVE","sortPriority":17,"id":41419604,"name":"3 - 7"},{"status":"ACTIVE","sortPriority":18,"id":41419605,"name":"3 - 8"},{"status":"ACTIVE","sortPriority":19,"id":41419606,"name":"4 - 1"},{"status":"ACTIVE","sortPriority":20,"id":41419607,"name":"4 - 2"},{"status":"ACTIVE","sortPriority":21,"id":41419608,"name":"4 - 3"},{"status":"ACTIVE","sortPriority":22,"id":41419610,"name":"4 - 6"},{"status":"ACTIVE","sortPriority":23,"id":41419611,"name":"4 - 7"},{"status":"ACTIVE","sortPriority":24,"id":41419612,"name":"4 - 8"},{"status":"ACTIVE","sortPriority":25,"id":41419620,"name":"6 - 1"},{"status":"ACTIVE","sortPriority":26,"id":41419621,"name":"6 - 2"},{"status":"ACTIVE","sortPriority":27,"id":41419622,"name":"6 - 3"},{"status":"ACTIVE","sortPriority":28,"id":41419623,"name":"6 - 4"},{"status":"ACTIVE","sortPriority":29,"id":41419625,"name":"6 - 7"},{"status":"ACTIVE","sortPriority":30,"id":41419626,"name":"6 - 8"},{"status":"ACTIVE","sortPriority":31,"id":41419627,"name":"7 - 1"},{"status":"ACTIVE","sortPriority":32,"id":41419628,"name":"7 - 2"},{"status":"ACTIVE","sortPriority":33,"id":41419629,"name":"7 - 3"},{"status":"ACTIVE","sortPriority":34,"id":41419630,"name":"7 - 4"},{"status":"ACTIVE","sortPriority":35,"id":41419632,"name":"7 - 6"},{"status":"ACTIVE","sortPriority":36,"id":41419633,"name":"7 - 8"},{"status":"ACTIVE","sortPriority":37,"id":41419634,"name":"8 - 1"},{"status":"ACTIVE","sortPriority":38,"id":41419635,"name":"8 - 2"},{"status":"ACTIVE","sortPriority":39,"id":41419636,"name":"8 - 3"},{"status":"ACTIVE","sortPriority":40,"id":41419637,"name":"8 - 4"},{"status":"ACTIVE","sortPriority":41,"id":41419639,"name":"8 - 6"},{"status":"ACTIVE","sortPriority":42,"id":41419640,"name":"8 - 7"}],"regulators":["MR_INT"],"venue":"Rockhampton","countryCode":"AU","discountAllowed":true,"timezone":"Australia/Queensland","openDate":"2022-03-02T08:28:00.000Z","version":4382604931,"name":"Exacta","eventName":"Rockhampton (AUS) 2nd Mar"},"rc":[{"atb":[[16,13.32],[11,26.65],[27,7.68]],"id":41419640},{"atb":[[22,9.52],[13.5,15.99],[9.4,31.73]],"id":41419607},{"atb":[[65,3.12],[19,14.8],[28,7.4]],"id":41419605},{"atb":[[17,16.65],[48,4.25],[24,8.69]],"id":41419636},{"atb":[[540,0.37],[690,0.28],[440,0.6]],"id":41419603},{"atb":[[4.5,57.11],[6,39.98],[3.75,96.92]],"id":41419634},{"atb":[[36,5.7],[19,11.1],[14,20.5]],"id":41419611},{"atb":[[95,2.12],[48,5.67],[240,0.83]],"id":41419593},{"atb":[[4,66.63],[5.5,44.42],[3.5,106.61]],"id":41419591},{"atb":[[520,0.38],[670,0.29],[420,0.63]],"id":41419622},{"atb":[[19.5,10.8],[12,18.17],[8.8,34.17]],"id":41419589},{"atb":[[10.5,28.05],[26,7.99],[15.5,13.78]],"id":41419620},{"atb":[[7.4,31.23],[5.2,47.59],[4.2,83.29]],"id":41419587},{"atb":[[42,4.87],[26,10.66],[110,1.83]],"id":41419601},{"atb":[[70,2.89],[38,7.2],[190,1.05]],"id":41419632},{"atb":[[17,16.65],[48,4.25],[24,8.69]],"id":41419599},{"atb":[[42,4.87],[21,9.99],[15.5,18.38]],"id":41419630},{"atb":[[18,15.67],[26,7.99],[55,3.7]],"id":41419597},{"atb":[[18.5,15.22],[27,7.68],[60,3.38]],"id":41419628},{"atb":[[17.5,12.11],[12.5,23.17],[30,6.89]],"id":41419626},{"atb":[[34,6.05],[85,2.37],[22,12.69]],"id":41419608},{"atb":[[16,13.32],[11,26.65],[27,7.68]],"id":41419639},{"atb":[[4.8,70.14],[8.6,26.3],[5.8,41.64]],"id":41419606},{"atb":[[10,22.2],[5.5,59.22],[7,33.31]],"id":41419637},{"atb":[[540,0.37],[690,0.28],[440,0.6]],"id":41419604},{"atb":[[17,12.49],[9.8,22.71],[7.8,39.19]],"id":41419635},{"atb":[[11,19.99],[7.4,31.23],[5.7,56.7]],"id":41419585},{"atb":[[5.8,55.52],[11.5,19.03],[7.6,30.29]],"id":41419612},{"atb":[[36,5.7],[19,11.1],[14,20.5]],"id":41419610},{"atb":[[70,2.89],[38,7.2],[190,1.05]],"id":41419625},{"atb":[[9,24.98],[7,44.42],[15,14.28]],"id":41419592},{"atb":[[42,4.87],[21,9.99],[15.5,18.38]],"id":41419623},{"atb":[[19.5,10.8],[12,18.17],[8.8,34.17]],"id":41419590},{"atb":[[18.5,15.22],[27,7.68],[60,3.38]],"id":41419621},{"atb":[[36,5.7],[19,11.1],[14,20.5]],"id":41419586},{"atb":[[17.5,12.11],[12.5,23.17],[30,6.89]],"id":41419633},{"atb":[[270,0.74],[120,1.67],[60,4.51]],"id":41419600},{"atb":[[18.5,11.42],[11,19.99],[8.4,36.01]],"id":41419598},{"atb":[[520,0.38],[670,0.29],[420,0.63]],"id":41419629},{"atb":[[18,15.67],[26,7.99],[55,3.7]],"id":41419596},{"atb":[[10.5,28.05],[26,7.99],[15.5,13.78]],"id":41419627},{"atb":[[24,8.69],[9.8,30.29],[14.5,14.8]],"id":41419594}],"con":true,"img":true}]}
{"op":"mcm","clk":"5352466730","pt":1646191002692,"mc":[{"id":"1.195503866","marketDefinition":{"bspMarket":false,"turnInPlayEnabled":false,"persistenceEnabled":false,"marketBaseRate":7.0,"eventId":"31272499","eventTypeId":"4339","numberOfWinners":1,"bettingType":"ODDS","marketType":"EXACTA","marketTime":"2022-03-02T10:24:00.000Z","suspendTime":"2022-03-02T10:24:00.000Z","bspReconciled":false,"complete":true,"inPlay":false,"crossMatching":false,"runnersVoidable":false,"numberOfActiveRunners":42,"betDelay":0,"status":"OPEN","runners":[{"status":"ACTIVE","sortPriority":1,"id":41419585,"name":"1 - 2"},{"status":"ACTIVE","sortPriority":2,"id":41419586,"name":"1 - 3"},{"status":"ACTIVE","sortPriority":3,"id":41419587,"name":"1 - 4"},{"status":"ACTIVE","sortPriority":4,"id":41419589,"name":"1 - 6"},{"status":"ACTIVE","sortPriority":5,"id":41419590,"name":"1 - 7"},{"status":"ACTIVE","sortPriority":6,"id":41419591,"name":"1 - 8"},{"status":"ACTIVE","sortPriority":7,"id":41419592,"name":"2 - 1"},{"status":"ACTIVE","sortPriority":8,"id":41419593,"name":"2 - 3"},{"status":"ACTIVE","sortPriority":9,"id":41419594,"name":"2 - 4"},{"status":"ACTIVE","sortPriority":10,"id":41419596,"name":"2 - 6"},{"status":"ACTIVE","sortPriority":11,"id":41419597,"name":"2 - 7"},{"status":"ACTIVE","sortPriority":12,"id":41419598,"name":"2 - 8"},{"status":"ACTIVE","sortPriority":13,"id":41419599,"name":"3 - 1"},{"status":"ACTIVE","sortPriority":14,"id":41419600,"name":"3 - 2"},{"status":"ACTIVE","sortPriority":15,"id":41419601,"name":"3 - 4"},{"status":"ACTIVE","sortPriority":16,"id":41419603,"name":"3 - 6"},{"status":"ACTIVE","sortPriority":17,"id":41419604,"name":"3 - 7"},{"status":"ACTIVE","sortPriority":18,"id":41419605,"name":"3 - 8"},{"status":"ACTIVE","sortPriority":19,"id":41419606,"name":"4 - 1"},{"status":"ACTIVE","sortPriority":20,"id":41419607,"name":"4 - 2"},{"status":"ACTIVE","sortPriority":21,"id":41419608,"name":"4 - 3"},{"status":"ACTIVE","sortPriority":22,"id":41419610,"name":"4 - 6"},{"status":"ACTIVE","sortPriority":23,"id":41419611,"name":"4 - 7"},{"status":"ACTIVE","sortPriority":24,"id":41419612,"name":"4 - 8"},{"status":"ACTIVE","sortPriority":25,"id":41419620,"name":"6 - 1"},{"status":"ACTIVE","sortPriority":26,"id":41419621,"name":"6 - 2"},{"status":"ACTIVE","sortPriority":27,"id":41419622,"name":"6 - 3"},{"status":"ACTIVE","sortPriority":28,"id":41419623,"name":"6 - 4"},{"status":"ACTIVE","sortPriority":29,"id":41419625,"name":"6 - 7"},{"status":"ACTIVE","sortPriority":30,"id":41419626,"name":"6 - 8"},{"status":"ACTIVE","sortPriority":31,"id":41419627,"name":"7 - 1"},{"status":"ACTIVE","sortPriority":32,"id":41419628,"name":"7 - 2"},{"status":"ACTIVE","sortPriority":33,"id":41419629,"name":"7 - 3"},{"status":"ACTIVE","sortPriority":34,"id":41419630,"name":"7 - 4"},{"status":"ACTIVE","sortPriority":35,"id":41419632,"name":"7 - 6"},{"status":"ACTIVE","sortPriority":36,"id":41419633,"name":"7 - 8"},{"status":"ACTIVE","sortPriority":37,"id":41419634,"name":"8 - 1"},{"status":"ACTIVE","sortPriority":38,"id":41419635,"name":"8 - 2"},{"status":"ACTIVE","sortPriority":39,"id":41419636,"name":"8 - 3"},{"status":"ACTIVE","sortPriority":40,"id":41419637,"name":"8 - 4"},{"status":"ACTIVE","sortPriority":41,"id":41419639,"name":"8 - 6"},{"status":"ACTIVE","sortPriority":42,"id":41419640,"name":"8 - 7"}],"regulators":["MR_INT"],"venue":"Rockhampton","countryCode":"AU","discountAllowed":true,"timezone":"Australia/Queensland","openDate":"2022-03-02T08:28:00.000Z","version":4382604931,"name":"Exacta","eventName":"Rockhampton (AUS) 2nd Mar"},"rc":[{"atb":[[16,13.34],[11,26.69],[27,7.7]],"id":41419640},{"atb":[[22,9.53],[13.5,16.02],[9.4,31.78]],"id":41419607},{"atb":[[65,3.12],[19,14.83],[28,7.41]],"id":41419605},{"atb":[[17,16.68],[48,4.26],[24,8.7]],"id":41419636},{"atb":[[540,0.37],[690,0.28],[440,0.6]],"id":41419603},{"atb":[[4.5,57.2],[6,40.04],[3.75,97.08]],"id":41419634},{"atb":[[36,5.71],[19,11.12],[14,20.53]],"id":41419611},{"atb":[[95,2.13],[48,5.68],[240,0.83]],"id":41419593},{"atb":[[4,66.74],[5.5,44.49],[3.5,106.79]],"id":41419591},{"atb":[[520,0.38],[670,0.3],[420,0.63]],"id":41419622},{"atb":[[19.5,10.82],[12,18.2],[8.8,34.23]],"id":41419589},{"atb":[[10.5,28.1],[26,8],[15.5,13.8]],"id":41419620},{"atb":[[7.4,31.28],[5.2,47.67],[4.2,83.43]],"id":41419587},{"atb":[[42,4.88],[26,10.67],[110,1.83]],"id":41419601},{"atb":[[70,2.9],[38,7.21],[190,1.05]],"id":41419632},{"atb":[[17,16.68],[48,4.26],[24,8.7]],"id":41419599},{"atb":[[42,4.88],[21,10.01],[15.5,18.41]],"id":41419630},{"atb":[[18,15.7],[26,8],[55,3.7]],"id":41419597},{"atb":[[18.5,15.25],[27,7.7],[60,3.39]],"id":41419628},{"atb":[[17.5,12.13],[12.5,23.21],[30,6.9]],"id":41419626},{"atb":[[34,6.06],[85,2.38],[22,12.71]],"id":41419608},{"atb":[[16,13.34],[11,26.69],[27,7.7]],"id":41419639},{"atb":[[4.8,70.25],[8.6,26.34],[5.8,41.71]],"id":41419606},{"atb":[[10,22.24],[5.5,59.32],[7,33.37]],"id":41419637},{"atb":[[540,0.37],[690,0.28],[440,0.6]],"id":41419604},{"atb":[[17,12.51],[9.8,22.75],[7.8,39.26]],"id":41419635},{"atb":[[11,20.02],[7.4,31.28],[5.7,56.8]],"id":41419585},{"atb":[[5.8,55.62],[11.5,19.06],[7.6,30.34]],"id":41419612},{"atb":[[36,5.71],[19,11.12],[14,20.53]],"id":41419610},{"atb":[[70,2.9],[38,7.21],[190,1.05]],"id":41419625},{"atb":[[9,25.02],[7,44.49],[15,14.3]],"id":41419592},{"atb":[[42,4.88],[21,10.01],[15.5,18.41]],"id":41419623},{"atb":[[19.5,10.82],[12,18.2],[8.8,34.23]],"id":41419590},{"atb":[[18.5,15.25],[27,7.7],[60,3.39]],"id":41419621},{"atb":[[36,5.71],[19,11.12],[14,20.53]],"id":41419586},{"atb":[[17.5,12.13],[12.5,23.21],[30,6.9]],"id":41419633},{"atb":[[270,0.74],[120,1.68],[60,4.52]],"id":41419600},{"atb":[[18.5,11.44],[11,20.02],[8.4,36.07]],"id":41419598},{"atb":[[520,0.38],[670,0.3],[420,0.63]],"id":41419629},{"atb":[[18,15.7],[26,8],[55,3.7]],"id":41419596},{"atb":[[10.5,28.1],[26,8],[15.5,13.8]],"id":41419627},{"atb":[[24,8.7],[9.8,30.34],[14.5,14.83]],"id":41419594}],"con":true,"img":true}]}
{"op":"mcm","clk":"5352606097","pt":1646194854162,"mc":[{"id":"1.195503866","rc":[{"atb":[[16,13.34],[11,26.69],[27,7.7]],"id":41419640},{"atb":[[22,0],[13.5,0],[9.4,0]],"id":41419607},{"atb":[[65,0],[19,0],[28,0]],"id":41419605},{"atb":[[17,16.68],[48,4.26],[24,8.7]],"id":41419636},{"atb":[[540,0],[690,0],[440,0]],"id":41419603},{"atb":[[4.5,57.2],[6,40.04],[3.75,97.08]],"id":41419634},{"atb":[[36,5.71],[19,11.12],[14,20.53]],"id":41419611},{"atb":[[95,0],[48,0],[240,0]],"id":41419593},{"atb":[[4,0],[5.5,0],[3.5,0]],"id":41419591},{"atb":[[520,0.38],[670,0.3],[420,0.63]],"id":41419622},{"atb":[[19.5,0],[12,0],[8.8,0]],"id":41419589},{"atb":[[10.5,28.1],[26,8],[15.5,13.8]],"id":41419620},{"atb":[[7.4,0],[5.2,0],[4.2,0]],"id":41419587},{"atb":[[42,0],[26,0],[110,0]],"id":41419601},{"atb":[[70,2.9],[38,7.21],[190,1.05]],"id":41419632},{"atb":[[17,0],[48,0],[24,0]],"id":41419599},{"atb":[[42,4.88],[21,10.01],[15.5,18.41]],"id":41419630},{"atb":[[18,0],[26,0],[55,0]],"id":41419597},{"atb":[[18.5,15.25],[27,7.7],[60,3.39]],"id":41419628},{"atb":[[17.5,12.13],[12.5,23.21],[30,6.9]],"id":41419626},{"atb":[[34,6.06],[85,2.38],[22,12.71]],"id":41419608},{"atb":[[16,13.34],[11,26.69],[27,7.7]],"id":41419639},{"atb":[[4.8,0],[8.6,0],[5.8,0]],"id":41419606},{"atb":[[10,22.24],[5.5,59.32],[7,33.37]],"id":41419637},{"atb":[[540,0],[690,0],[440,0]],"id":41419604},{"atb":[[17,12.51],[9.8,22.75],[7.8,39.26]],"id":41419635},{"atb":[[11,0],[7.4,0],[5.7,0]],"id":41419585},{"atb":[[5.8,55.62],[11.5,19.06],[7.6,30.34]],"id":41419612},{"atb":[[36,5.71],[19,11.12],[14,20.53]],"id":41419610},{"atb":[[70,2.9],[38,7.21],[190,1.05]],"id":41419625},{"atb":[[9,0],[7,0],[15,0]],"id":41419592},{"atb":[[42,4.88],[21,10.01],[15.5,18.41]],"id":41419623},{"atb":[[19.5,0],[12,0],[8.8,0]],"id":41419590},{"atb":[[18.5,15.25],[27,7.7],[60,3.39]],"id":41419621},{"atb":[[36,0],[19,0],[14,0]],"id":41419586},{"atb":[[17.5,12.13],[12.5,23.21],[30,6.9]],"id":41419633},{"atb":[[270,0],[120,0],[60,0]],"id":41419600},{"atb":[[18.5,0],[11,0],[8.4,0]],"id":41419598},{"atb":[[520,0.38],[670,0.3],[420,0.63]],"id":41419629},{"atb":[[18,0],[26,0],[55,0]],"id":41419596},{"atb":[[10.5,28.1],[26,8],[15.5,13.8]],"id":41419627},{"atb":[[24,0],[9.8,0],[14.5,0]],"id":41419594}],"con":true,"img":false}]}
{"op":"mcm","clk":"5352606104","pt":1646194854267,"mc":[{"id":"1.195503866","rc":[{"atb":[[16,0],[11,0],[27,0]],"id":41419640},{"atb":[[17,0],[48,0],[24,0]],"id":41419636},{"atb":[[4.5,0],[6,0],[3.75,0]],"id":41419634},{"atb":[[36,0],[19,0],[14,0]],"id":41419611},{"atb":[[520,0],[670,0],[420,0]],"id":41419622},{"atb":[[10.5,0],[26,0],[15.5,0]],"id":41419620},{"atb":[[70,0],[38,0],[190,0]],"id":41419632},{"atb":[[42,0],[21,0],[15.5,0]],"id":41419630},{"atb":[[18.5,0],[27,0],[60,0]],"id":41419628},{"atb":[[17.5,0],[12.5,0],[30,0]],"id":41419626},{"atb":[[34,0],[85,0],[22,0]],"id":41419608},{"atb":[[16,0],[11,0],[27,0]],"id":41419639},{"atb":[[10,0],[5.5,0],[7,0]],"id":41419637},{"atb":[[17,0],[9.8,0],[7.8,0]],"id":41419635},{"atb":[[5.8,0],[11.5,0],[7.6,0]],"id":41419612},{"atb":[[36,0],[19,0],[14,0]],"id":41419610},{"atb":[[70,0],[38,0],[190,0]],"id":41419625},{"atb":[[42,0],[21,0],[15.5,0]],"id":41419623},{"atb":[[18.5,0],[27,0],[60,0]],"id":41419621},{"atb":[[17.5,0],[12.5,0],[30,0]],"id":41419633},{"atb":[[520,0],[670,0],[420,0]],"id":41419629},{"atb":[[10.5,0],[26,0],[15.5,0]],"id":41419627}],"con":true,"img":false}]}
{"op":"mcm","clk":"5352606640","pt":1646194869169,"mc":[{"id":"1.195503866","rc":[{"atb":[[16,13.34],[11,26.69],[27,7.7]],"id":41419640},{"atb":[[22,9.53],[13.5,16.02],[9.4,31.78]],"id":41419607},{"atb":[[65,3.12],[19,14.83],[28,7.41]],"id":41419605},{"atb":[[17,16.68],[48,4.26],[24,8.7]],"id":41419636},{"atb":[[600,0.33],[750,0.26],[500,0.53]],"id":41419603},{"atb":[[4.5,57.2],[6,40.04],[3.75,97.08]],"id":41419634},{"atb":[[36,5.71],[19,11.12],[14,20.53]],"id":41419611},{"atb":[[90,2.25],[46,5.93],[230,0.87]],"id":41419593},{"atb":[[3.45,108.97],[3.95,67.87],[5.4,45.51]],"id":41419591},{"atb":[[570,0.34],[720,0.27],[470,0.56]],"id":41419622},{"atb":[[9,33.37],[20,10.53],[12.5,17.41]],"id":41419589},{"atb":[[16,13.34],[11,26.69],[27,7.7]],"id":41419620},{"atb":[[7.4,31.28],[5.2,47.67],[4.2,83.43]],"id":41419587},{"atb":[[40,5.13],[100,2.02],[25,11.12]],"id":41419601},{"atb":[[80,2.53],[42,6.51],[210,0.95]],"id":41419632},{"atb":[[17,16.68],[48,4.26],[24,8.7]],"id":41419599},{"atb":[[40,5.13],[20,10.53],[15,19.06]],"id":41419630},{"atb":[[18,15.7],[26,8],[55,3.7]],"id":41419597},{"atb":[[18.5,15.25],[27,7.7],[60,3.39]],"id":41419628},{"atb":[[32,6.46],[18,11.77],[13,22.24]],"id":41419626},{"atb":[[32,6.46],[80,2.53],[21,13.34]],"id":41419608},{"atb":[[16.5,12.91],[11.5,25.42],[28,7.41]],"id":41419639},{"atb":[[4.8,70.25],[8.6,26.34],[5.8,41.71]],"id":41419606},{"atb":[[6.8,34.52],[9.8,22.75],[5.4,60.67]],"id":41419637},{"atb":[[540,0.37],[690,0.28],[440,0.6]],"id":41419604},{"atb":[[17,12.51],[9.8,22.75],[7.8,39.26]],"id":41419635},{"atb":[[11,20.02],[7.4,31.28],[5.7,56.8]],"id":41419585},{"atb":[[11,20.02],[7.4,31.28],[5.7,56.8]],"id":41419612},{"atb":[[38,5.41],[19.5,10.82],[14.5,19.77]],"id":41419610},{"atb":[[80,2.53],[42,6.51],[210,0.95]],"id":41419625},{"atb":[[9,25.02],[7,44.49],[15,14.3]],"id":41419592},{"atb":[[42,4.88],[21,10.01],[15.5,18.41]],"id":41419623},{"atb":[[19.5,10.82],[12,18.2],[8.8,34.23]],"id":41419590},{"atb":[[65,3.12],[19,14.83],[28,7.41]],"id":41419621},{"atb":[[36,5.71],[19,11.12],[14,20.53]],"id":41419586},{"atb":[[17.5,12.13],[12.5,23.21],[30,6.9]],"id":41419633},{"atb":[[270,0.74],[120,1.68],[60,4.52]],"id":41419600},{"atb":[[18.5,11.44],[11,20.02],[8.4,36.07]],"id":41419598},{"atb":[[660,0.3],[410,0.65],[510,0.39]],"id":41419629},{"atb":[[18.5,15.25],[27,7.7],[60,3.39]],"id":41419596},{"atb":[[10.5,28.1],[26,8],[15.5,13.8]],"id":41419627},{"atb":[[24,8.7],[9.8,30.34],[14.5,14.83]],"id":41419594}],"con":true,"img":false}]}
{"op":"mcm","clk":"5352823533","pt":1646201802743,"mc":[{"id":"1.195503866","marketDefinition":{"bspMarket":false,"turnInPlayEnabled":false,"persistenceEnabled":false,"marketBaseRate":7.0,"eventId":"31272499","eventTypeId":"4339","numberOfWinners":1,"bettingType":"ODDS","marketType":"EXACTA","marketTime":"2022-03-02T10:24:00.000Z","suspendTime":"2022-03-02T10:24:00.000Z","bspReconciled":false,"complete":true,"inPlay":false,"crossMatching":false,"runnersVoidable":false,"numberOfActiveRunners":42,"betDelay":0,"status":"OPEN","runners":[{"status":"ACTIVE","sortPriority":1,"id":41419585,"name":"1 - 2"},{"status":"ACTIVE","sortPriority":2,"id":41419586,"name":"1 - 3"},{"status":"ACTIVE","sortPriority":3,"id":41419587,"name":"1 - 4"},{"status":"ACTIVE","sortPriority":4,"id":41419589,"name":"1 - 6"},{"status":"ACTIVE","sortPriority":5,"id":41419590,"name":"1 - 7"},{"status":"ACTIVE","sortPriority":6,"id":41419591,"name":"1 - 8"},{"status":"ACTIVE","sortPriority":7,"id":41419592,"name":"2 - 1"},{"status":"ACTIVE","sortPriority":8,"id":41419593,"name":"2 - 3"},{"status":"ACTIVE","sortPriority":9,"id":41419594,"name":"2 - 4"},{"status":"ACTIVE","sortPriority":10,"id":41419596,"name":"2 - 6"},{"status":"ACTIVE","sortPriority":11,"id":41419597,"name":"2 - 7"},{"status":"ACTIVE","sortPriority":12,"id":41419598,"name":"2 - 8"},{"status":"ACTIVE","sortPriority":13,"id":41419599,"name":"3 - 1"},{"status":"ACTIVE","sortPriority":14,"id":41419600,"name":"3 - 2"},{"status":"ACTIVE","sortPriority":15,"id":41419601,"name":"3 - 4"},{"status":"ACTIVE","sortPriority":16,"id":41419603,"name":"3 - 6"},{"status":"ACTIVE","sortPriority":17,"id":41419604,"name":"3 - 7"},{"status":"ACTIVE","sortPriority":18,"id":41419605,"name":"3 - 8"},{"status":"ACTIVE","sortPriority":19,"id":41419606,"name":"4 - 1"},{"status":"ACTIVE","sortPriority":20,"id":41419607,"name":"4 - 2"},{"status":"ACTIVE","sortPriority":21,"id":41419608,"name":"4 - 3"},{"status":"ACTIVE","sortPriority":22,"id":41419610,"name":"4 - 6"},{"status":"ACTIVE","sortPriority":23,"id":41419611,"name":"4 - 7"},{"status":"ACTIVE","sortPriority":24,"id":41419612,"name":"4 - 8"},{"status":"ACTIVE","sortPriority":25,"id":41419620,"name":"6 - 1"},{"status":"ACTIVE","sortPriority":26,"id":41419621,"name":"6 - 2"},{"status":"ACTIVE","sortPriority":27,"id":41419622,"name":"6 - 3"},{"status":"ACTIVE","sortPriority":28,"id":41419623,"name":"6 - 4"},{"status":"ACTIVE","sortPriority":29,"id":41419625,"name":"6 - 7"},{"status":"ACTIVE","sortPriority":30,"id":41419626,"name":"6 - 8"},{"status":"ACTIVE","sortPriority":31,"id":41419627,"name":"7 - 1"},{"status":"ACTIVE","sortPriority":32,"id":41419628,"name":"7 - 2"},{"status":"ACTIVE","sortPriority":33,"id":41419629,"name":"7 - 3"},{"status":"ACTIVE","sortPriority":34,"id":41419630,"name":"7 - 4"},{"status":"ACTIVE","sortPriority":35,"id":41419632,"name":"7 - 6"},{"status":"ACTIVE","sortPriority":36,"id":41419633,"name":"7 - 8"},{"status":"ACTIVE","sortPriority":37,"id":41419634,"name":"8 - 1"},{"status":"ACTIVE","sortPriority":38,"id":41419635,"name":"8 - 2"},{"status":"ACTIVE","sortPriority":39,"id":41419636,"name":"8 - 3"},{"status":"ACTIVE","sortPriority":40,"id":41419637,"name":"8 - 4"},{"status":"ACTIVE","sortPriority":41,"id":41419639,"name":"8 - 6"},{"status":"ACTIVE","sortPriority":42,"id":41419640,"name":"8 - 7"}],"regulators":["MR_INT"],"venue":"Rockhampton","countryCode":"AU","discountAllowed":true,"timezone":"Australia/Queensland","openDate":"2022-03-02T08:28:00.000Z","version":4382604931,"name":"Exacta","eventName":"Rockhampton (AUS) 2nd Mar"},"rc":[{"atb":[[16,13.34],[11,26.68],[27,7.69]],"id":41419640},{"atb":[[22,9.53],[13.5,16.01],[9.4,31.77]],"id":41419607},{"atb":[[65,3.12],[19,14.82],[28,7.41]],"id":41419605},{"atb":[[17,16.68],[48,4.25],[24,8.7]],"id":41419636},{"atb":[[600,0.33],[750,0.26],[500,0.53]],"id":41419603},{"atb":[[4.5,57.18],[6,40.03],[3.75,97.05]],"id":41419634},{"atb":[[36,5.71],[19,11.12],[14,20.52]],"id":41419611},{"atb":[[90,2.24],[46,5.92],[230,0.87]],"id":41419593},{"atb":[[3.45,108.93],[3.95,67.85],[5.4,45.49]],"id":41419591},{"atb":[[570,0.34],[720,0.27],[470,0.56]],"id":41419622},{"atb":[[9,33.36],[20,10.53],[12.5,17.4]],"id":41419589},{"atb":[[16,13.34],[11,26.68],[27,7.69]],"id":41419620},{"atb":[[7.4,31.27],[5.2,47.66],[4.2,83.4]],"id":41419587},{"atb":[[40,5.13],[100,2.02],[25,11.12]],"id":41419601},{"atb":[[80,2.53],[42,6.5],[210,0.95]],"id":41419632},{"atb":[[17,16.68],[48,4.25],[24,8.7]],"id":41419599},{"atb":[[40,5.13],[20,10.53],[15,19.06]],"id":41419630},{"atb":[[18,15.69],[26,8],[55,3.7]],"id":41419597},{"atb":[[18.5,15.24],[27,7.69],[60,3.39]],"id":41419628},{"atb":[[32,6.45],[18,11.77],[13,22.23]],"id":41419626},{"atb":[[32,6.45],[80,2.53],[21,13.34]],"id":41419608},{"atb":[[16.5,12.91],[11.5,25.41],[28,7.41]],"id":41419639},{"atb":[[4.8,70.23],[8.6,26.33],[5.8,41.7]],"id":41419606},{"atb":[[6.8,34.51],[9.8,22.74],[5.4,60.65]],"id":41419637},{"atb":[[540,0.37],[690,0.28],[440,0.6]],"id":41419604},{"atb":[[17,12.5],[9.8,22.74],[7.8,39.24]],"id":41419635},{"atb":[[11,20.01],[7.4,31.27],[5.7,56.78]],"id":41419585},{"atb":[[11,20.01],[7.4,31.27],[5.7,56.78]],"id":41419612},{"atb":[[38,5.41],[19.5,10.82],[14.5,19.77]],"id":41419610},{"atb":[[80,2.53],[42,6.5],[210,0.95]],"id":41419625},{"atb":[[9,25.01],[7,44.48],[15,14.29]],"id":41419592},{"atb":[[42,4.88],[21,10],[15.5,18.4]],"id":41419623},{"atb":[[19.5,10.82],[12,18.19],[8.8,34.21]],"id":41419590},{"atb":[[65,3.12],[19,14.82],[28,7.41]],"id":41419621},{"atb":[[36,5.71],[19,11.12],[14,20.52]],"id":41419586},{"atb":[[17.5,12.13],[12.5,23.2],[30,6.9]],"id":41419633},{"atb":[[270,0.74],[120,1.68],[60,4.52]],"id":41419600},{"atb":[[18.5,11.43],[11,20.01],[8.4,36.06]],"id":41419598},{"atb":[[660,0.3],[410,0.65],[510,0.39]],"id":41419629},{"atb":[[18.5,15.24],[27,7.69],[60,3.39]],"id":41419596},{"atb":[[10.5,28.09],[26,8],[15.5,13.8]],"id":41419627},{"atb":[[24,8.7],[9.8,30.33],[14.5,14.82]],"id":41419594}],"con":true,"img":true}]}
{"op":"mcm","clk":"5353028903","pt":1646207202760,"mc":[{"id":"1.195503866","marketDefinition":{"bspMarket":false,"turnInPlayEnabled":false,"persistenceEnabled":false,"marketBaseRate":7.0,"eventId":"31272499","eventTypeId":"4339","numberOfWinners":1,"bettingType":"ODDS","marketType":"EXACTA","marketTime":"2022-03-02T10:24:00.000Z","suspendTime":"2022-03-02T10:24:00.000Z","bspReconciled":false,"complete":true,"inPlay":false,"crossMatching":false,"runnersVoidable":false,"numberOfActiveRunners":42,"betDelay":0,"status":"OPEN","runners":[{"status":"ACTIVE","sortPriority":1,"id":41419585,"name":"1 - 2"},{"status":"ACTIVE","sortPriority":2,"id":41419586,"name":"1 - 3"},{"status":"ACTIVE","sortPriority":3,"id":41419587,"name":"1 - 4"},{"status":"ACTIVE","sortPriority":4,"id":41419589,"name":"1 - 6"},{"status":"ACTIVE","sortPriority":5,"id":41419590,"name":"1 - 7"},{"status":"ACTIVE","sortPriority":6,"id":41419591,"name":"1 - 8"},{"status":"ACTIVE","sortPriority":7,"id":41419592,"name":"2 - 1"},{"status":"ACTIVE","sortPriority":8,"id":41419593,"name":"2 - 3"},{"status":"ACTIVE","sortPriority":9,"id":41419594,"name":"2 - 4"},{"status":"ACTIVE","sortPriority":10,"id":41419596,"name":"2 - 6"},{"status":"ACTIVE","sortPriority":11,"id":41419597,"name":"2 - 7"},{"status":"ACTIVE","sortPriority":12,"id":41419598,"name":"2 - 8"},{"status":"ACTIVE","sortPriority":13,"id":41419599,"name":"3 - 1"},{"status":"ACTIVE","sortPriority":14,"id":41419600,"name":"3 - 2"},{"status":"ACTIVE","sortPriority":15,"id":41419601,"name":"3 - 4"},{"status":"ACTIVE","sortPriority":16,"id":41419603,"name":"3 - 6"},{"status":"ACTIVE","sortPriority":17,"id":41419604,"name":"3 - 7"},{"status":"ACTIVE","sortPriority":18,"id":41419605,"name":"3 - 8"},{"status":"ACTIVE","sortPriority":19,"id":41419606,"name":"4 - 1"},{"status":"ACTIVE","sortPriority":20,"id":41419607,"name":"4 - 2"},{"status":"ACTIVE","sortPriority":21,"id":41419608,"name":"4 - 3"},{"status":"ACTIVE","sortPriority":22,"id":41419610,"name":"4 - 6"},{"status":"ACTIVE","sortPriority":23,"id":41419611,"name":"4 - 7"},{"status":"ACTIVE","sortPriority":24,"id":41419612,"name":"4 - 8"},{"status":"ACTIVE","sortPriority":25,"id":41419620,"name":"6 - 1"},{"status":"ACTIVE","sortPriority":26,"id":41419621,"name":"6 - 2"},{"status":"ACTIVE","sortPriority":27,"id":41419622,"name":"6 - 3"},{"status":"ACTIVE","sortPriority":28,"id":41419623,"name":"6 - 4"},{"status":"ACTIVE","sortPriority":29,"id":41419625,"name":"6 - 7"},{"status":"ACTIVE","sortPriority":30,"id":41419626,"name":"6 - 8"},{"status":"ACTIVE","sortPriority":31,"id":41419627,"name":"7 - 1"},{"status":"ACTIVE","sortPriority":32,"id":41419628,"name":"7 - 2"},{"status":"ACTIVE","sortPriority":33,"id":41419629,"name":"7 - 3"},{"status":"ACTIVE","sortPriority":34,"id":41419630,"name":"7 - 4"},{"status":"ACTIVE","sortPriority":35,"id":41419632,"name":"7 - 6"},{"status":"ACTIVE","sortPriority":36,"id":41419633,"name":"7 - 8"},{"status":"ACTIVE","sortPriority":37,"id":41419634,"name":"8 - 1"},{"status":"ACTIVE","sortPriority":38,"id":41419635,"name":"8 - 2"},{"status":"ACTIVE","sortPriority":39,"id":41419636,"name":"8 - 3"},{"status":"ACTIVE","sortPriority":40,"id":41419637,"name":"8 - 4"},{"status":"ACTIVE","sortPriority":41,"id":41419639,"name":"8 - 6"},{"status":"ACTIVE","sortPriority":42,"id":41419640,"name":"8 - 7"}],"regulators":["MR_INT"],"venue":"Rockhampton","countryCode":"AU","discountAllowed":true,"timezone":"Australia/Queensland","openDate":"2022-03-02T08:28:00.000Z","version":4382604931,"name":"Exacta","eventName":"Rockhampton (AUS) 2nd Mar"},"rc":[{"atb":[[16,13.34],[11,26.68],[27,7.69]],"id":41419640},{"atb":[[22,9.53],[13.5,16],[9.4,31.76]],"id":41419607},{"atb":[[65,3.12],[19,14.82],[28,7.41]],"id":41419605},{"atb":[[17,16.67],[48,4.25],[24,8.7]],"id":41419636},{"atb":[[600,0.33],[750,0.26],[500,0.53]],"id":41419603},{"atb":[[4.5,57.17],[6,40.02],[3.75,97.02]],"id":41419634},{"atb":[[36,5.71],[19,11.11],[14,20.52]],"id":41419611},{"atb":[[90,2.24],[46,5.92],[230,0.87]],"id":41419593},{"atb":[[3.45,108.9],[3.95,67.83],[5.4,45.48]],"id":41419591},{"atb":[[570,0.34],[720,0.27],[470,0.56]],"id":41419622},{"atb":[[9,33.35],[20,10.52],[12.5,17.4]],"id":41419589},{"atb":[[16,13.34],[11,26.68],[27,7.69]],"id":41419620},{"atb":[[7.4,31.26],[5.2,47.64],[4.2,83.37]],"id":41419587},{"atb":[[40,5.13],[100,2.01],[25,11.11]],"id":41419601},{"atb":[[80,2.53],[42,6.5],[210,0.95]],"id":41419632},{"atb":[[17,16.67],[48,4.25],[24,8.7]],"id":41419599},{"atb":[[40,5.13],[20,10.52],[15,19.05]],"id":41419630},{"atb":[[18,15.69],[26,8],[55,3.7]],"id":41419597},{"atb":[[18.5,15.24],[27,7.69],[60,3.38]],"id":41419628},{"atb":[[32,6.45],[18,11.76],[13,22.23]],"id":41419626},{"atb":[[32,6.45],[80,2.53],[21,13.34]],"id":41419608},{"atb":[[16.5,12.9],[11.5,25.4],[28,7.41]],"id":41419639},{"atb":[[4.8,70.21],[8.6,26.33],[5.8,41.69]],"id":41419606},{"atb":[[6.8,34.5],[9.8,22.74],[5.4,60.63]],"id":41419637},{"atb":[[540,0.37],[690,0.28],[440,0.6]],"id":41419604},{"atb":[[17,12.5],[9.8,22.74],[7.8,39.23]],"id":41419635},{"atb":[[11,20.01],[7.4,31.26],[5.7,56.76]],"id":41419585},{"atb":[[11,20.01],[7.4,31.26],[5.7,56.76]],"id":41419612},{"atb":[[38,5.4],[19.5,10.81],[14.5,19.76]],"id":41419610},{"atb":[[80,2.53],[42,6.5],[210,0.95]],"id":41419625},{"atb":[[9,25.01],[7,44.47],[15,14.29]],"id":41419592},{"atb":[[42,4.87],[21,10],[15.5,18.4]],"id":41419623},{"atb":[[19.5,10.81],[12,18.19],[8.8,34.2]],"id":41419590},{"atb":[[65,3.12],[19,14.82],[28,7.41]],"id":41419621},{"atb":[[36,5.71],[19,11.11],[14,20.52]],"id":41419586},{"atb":[[17.5,12.12],[12.5,23.19],[30,6.89]],"id":41419633},{"atb":[[270,0.74],[120,1.68],[60,4.51]],"id":41419600},{"atb":[[18.5,11.43],[11,20.01],[8.4,36.05]],"id":41419598},{"atb":[[660,0.3],[410,0.65],[510,0.39]],"id":41419629},{"atb":[[18.5,15.24],[27,7.69],[60,3.38]],"id":41419596},{"atb":[[10.5,28.08],[26,8],[15.5,13.79]],"id":41419627},{"atb":[[24,8.7],[9.8,30.32],[14.5,14.82]],"id":41419594}],"con":true,"img":true}]}
{"op":"mcm","clk":"5353127435","pt":1646209440391,"mc":[{"id":"1.195503866","rc":[{"atb":[[16,13.34],[21,3.27],[11,26.68],[26,2.72],[27,7.69]],"id":41419640},{"atb":[[20,3.27],[22,9.53],[25,2.72],[13.5,16],[9.4,31.76]],"id":41419607},{"atb":[[65,3.12],[19,14.82],[80,2.72],[55,3.27],[28,7.41]],"id":41419605},{"atb":[[17,16.67],[38,2.72],[48,4.25],[24,8.7],[29,3.27]],"id":41419636},{"atb":[[600,0.33],[160,2.72],[750,0.26],[110,3.27],[500,0.53]],"id":41419603},{"atb":[[4.5,57.17],[6,40.02],[8.8,2.72],[7.8,3.27],[3.75,97.02]],"id":41419634},{"atb":[[36,5.71],[19,11.11],[14,20.52]],"id":41419611},{"atb":[[70,2.72],[90,2.24],[46,5.92],[48,3.27],[230,0.87]],"id":41419593},{"atb":[[3.45,108.9],[3.95,67.83],[5.4,45.48]],"id":41419591},{"atb":[[130,2.72],[570,0.34],[720,0.27],[90,3.27],[470,0.56]],"id":41419622},{"atb":[[16,3.27],[9,33.35],[18.5,2.72],[20,10.52],[12.5,17.4]],"id":41419589},{"atb":[[16,13.34],[38,2.72],[11,26.68],[27,7.69],[29,3.27]],"id":41419620},{"atb":[[8.6,2.72],[7.4,31.26],[7.6,3.27],[5.2,47.64],[4.2,83.37]],"id":41419587},{"atb":[[70,3.27],[40,5.13],[95,2.72],[100,2.01],[25,11.11]],"id":41419601},{"atb":[[80,2.53],[42,6.5],[85,2.72],[210,0.95],[60,3.27]],"id":41419632},{"atb":[[17,16.67],[70,2.72],[48,7.53],[24,8.7]],"id":41419599},{"atb":[[40,8.4],[20,10.52],[50,2.72],[15,19.05]],"id":41419630},{"atb":[[18,15.69],[36,3.27],[46,2.72],[26,8],[55,3.7]],"id":41419597},{"atb":[[18.5,15.24],[44,3.27],[27,7.69],[60,6.11]],"id":41419628},{"atb":[[32,6.45],[18,11.76],[36,3.27],[46,2.72],[13,22.23]],"id":41419626},{"atb":[[32,6.45],[80,2.53],[21,13.34],[42,3.27],[55,2.72]],"id":41419608},{"atb":[[16.5,12.9],[22,3.27],[11.5,25.4],[27,2.72],[28,7.41]],"id":41419639},{"atb":[[4.8,70.21],[8.6,26.33],[5.8,41.69],[10.5,3.27],[13,2.72]],"id":41419606},{"atb":[[11.5,3.27],[6.8,34.5],[9.8,22.74],[14,2.72],[5.4,60.63]],"id":41419637},{"atb":[[540,0.37],[160,2.72],[690,0.28],[440,0.6],[110,3.27]],"id":41419604},{"atb":[[17,12.5],[17.5,2.72],[9.8,22.74],[7.8,39.23],[15,3.27]],"id":41419635},{"atb":[[11,22.74],[7.4,31.26],[5.7,56.76],[9.4,3.27]],"id":41419585},{"atb":[[16.5,2.72],[11,20.01],[7.4,31.26],[5.7,56.76],[14,3.27]],"id":41419612},{"atb":[[36,2.72],[38,5.4],[19.5,10.81],[28,3.27],[14.5,19.76]],"id":41419610},{"atb":[[65,3.27],[80,2.53],[42,6.5],[90,2.72],[210,0.95]],"id":41419625},{"atb":[[17,3.27],[9,25.01],[19.5,2.72],[7,44.47],[15,14.29]],"id":41419592},{"atb":[[42,8.15],[21,10],[55,2.72],[15.5,18.4]],"id":41419623},{"atb":[[17.5,2.72],[19.5,10.81],[12,18.19],[8.8,34.2],[15,3.27]],"id":41419590},{"atb":[[65,5.85],[19,14.82],[46,3.27],[28,7.41]],"id":41419621},{"atb":[[36,5.71],[19,11.11],[23,3.27],[14,20.52],[28,2.72]],"id":41419586},{"atb":[[17.5,12.12],[34,3.27],[44,2.72],[12.5,23.19],[30,6.89]],"id":41419633},{"atb":[[270,0.74],[80,3.27],[110,2.72],[120,1.68],[60,4.51]],"id":41419600},{"atb":[[18.5,11.43],[19.5,3.27],[11,20.01],[24,2.72],[8.4,36.05]],"id":41419598},{"atb":[[660,0.3],[85,3.27],[410,0.65],[120,2.72],[510,0.39]],"id":41419629},{"atb":[[18.5,15.24],[27,7.69],[60,3.38]],"id":41419596},{"atb":[[36,2.72],[10.5,28.08],[26,8],[28,3.27],[15.5,13.79]],"id":41419627},{"atb":[[23,3.27],[24,8.7],[9.8,30.32],[28,2.72],[14.5,14.82]],"id":41419594}],"con":true,"img":false}]}
{"op":"mcm","clk":"5353127440","pt":1646209440494,"mc":[{"id":"1.195503866","rc":[{"atb":[[36,8.44],[28,3.27]],"id":41419611},{"atb":[[6,3.27],[7,2.72]],"id":41419591},{"atb":[[38,3.27],[48,2.72]],"id":41419596}],"con":true,"img":false}]}
{"op":"mcm","clk":"5353300290","pt":1646212602763,"mc":[{"id":"1.195503866","marketDefinition":{"bspMarket":false,"turnInPlayEnabled":false,"persistenceEnabled":false,"marketBaseRate":7.0,"eventId":"31272499","eventTypeId":"4339","numberOfWinners":1,"bettingType":"ODDS","marketType":"EXACTA","marketTime":"2022-03-02T10:24:00.000Z","suspendTime":"2022-03-02T10:24:00.000Z","bspReconciled":false,"complete":true,"inPlay":false,"crossMatching":false,"runnersVoidable":false,"numberOfActiveRunners":42,"betDelay":0,"status":"OPEN","runners":[{"status":"ACTIVE","sortPriority":1,"id":41419585,"name":"1 - 2"},{"status":"ACTIVE","sortPriority":2,"id":41419586,"name":"1 - 3"},{"status":"ACTIVE","sortPriority":3,"id":41419587,"name":"1 - 4"},{"status":"ACTIVE","sortPriority":4,"id":41419589,"name":"1 - 6"},{"status":"ACTIVE","sortPriority":5,"id":41419590,"name":"1 - 7"},{"status":"ACTIVE","sortPriority":6,"id":41419591,"name":"1 - 8"},{"status":"ACTIVE","sortPriority":7,"id":41419592,"name":"2 - 1"},{"status":"ACTIVE","sortPriority":8,"id":41419593,"name":"2 - 3"},{"status":"ACTIVE","sortPriority":9,"id":41419594,"name":"2 - 4"},{"status":"ACTIVE","sortPriority":10,"id":41419596,"name":"2 - 6"},{"status":"ACTIVE","sortPriority":11,"id":41419597,"name":"2 - 7"},{"status":"ACTIVE","sortPriority":12,"id":41419598,"name":"2 - 8"},{"status":"ACTIVE","sortPriority":13,"id":41419599,"name":"3 - 1"},{"status":"ACTIVE","sortPriority":14,"id":41419600,"name":"3 - 2"},{"status":"ACTIVE","sortPriority":15,"id":41419601,"name":"3 - 4"},{"status":"ACTIVE","sortPriority":16,"id":41419603,"name":"3 - 6"},{"status":"ACTIVE","sortPriority":17,"id":41419604,"name":"3 - 7"},{"status":"ACTIVE","sortPriority":18,"id":41419605,"name":"3 - 8"},{"status":"ACTIVE","sortPriority":19,"id":41419606,"name":"4 - 1"},{"status":"ACTIVE","sortPriority":20,"id":41419607,"name":"4 - 2"},{"status":"ACTIVE","sortPriority":21,"id":41419608,"name":"4 - 3"},{"status":"ACTIVE","sortPriority":22,"id":41419610,"name":"4 - 6"},{"status":"ACTIVE","sortPriority":23,"id":41419611,"name":"4 - 7"},{"status":"ACTIVE","sortPriority":24,"id":41419612,"name":"4 - 8"},{"status":"ACTIVE","sortPriority":25,"id":41419620,"name":"6 - 1"},{"status":"ACTIVE","sortPriority":26,"id":41419621,"name":"6 - 2"},{"status":"ACTIVE","sortPriority":27,"id":41419622,"name":"6 - 3"},{"status":"ACTIVE","sortPriority":28,"id":41419623,"name":"6 - 4"},{"status":"ACTIVE","sortPriority":29,"id":41419625,"name":"6 - 7"},{"status":"ACTIVE","sortPriority":30,"id":41419626,"name":"6 - 8"},{"status":"ACTIVE","sortPriority":31,"id":41419627,"name":"7 - 1"},{"status":"ACTIVE","sortPriority":32,"id":41419628,"name":"7 - 2"},{"status":"ACTIVE","sortPriority":33,"id":41419629,"name":"7 - 3"},{"status":"ACTIVE","sortPriority":34,"id":41419630,"name":"7 - 4"},{"status":"ACTIVE","sortPriority":35,"id":41419632,"name":"7 - 6"},{"status":"ACTIVE","sortPriority":36,"id":41419633,"name":"7 - 8"},{"status":"ACTIVE","sortPriority":37,"id":41419634,"name":"8 - 1"},{"status":"ACTIVE","sortPriority":38,"id":41419635,"name":"8 - 2"},{"status":"ACTIVE","sortPriority":39,"id":41419636,"name":"8 - 3"},{"status":"ACTIVE","sortPriority":40,"id":41419637,"name":"8 - 4"},{"status":"ACTIVE","sortPriority":41,"id":41419639,"name":"8 - 6"},{"status":"ACTIVE","sortPriority":42,"id":41419640,"name":"8 - 7"}],"regulators":["MR_INT"],"venue":"Rockhampton","countryCode":"AU","discountAllowed":true,"timezone":"Australia/Queensland","openDate":"2022-03-02T08:28:00.000Z","version":4382604931,"name":"Exacta","eventName":"Rockhampton (AUS) 2nd Mar"},"rc":[{"atb":[[16,13.31],[21,3.26],[11,26.63],[26,2.72],[27,7.68]],"id":41419640},{"atb":[[20,3.26],[22,9.51],[25,2.72],[13.5,15.98],[9.4,31.71]],"id":41419607},{"atb":[[65,3.12],[19,14.8],[80,2.72],[55,3.26],[28,7.4]],"id":41419605},{"atb":[[17,16.64],[38,2.72],[48,4.25],[24,8.68],[29,3.26]],"id":41419636},{"atb":[[600,0.33],[160,2.72],[750,0.26],[110,3.26],[500,0.53]],"id":41419603},{"atb":[[4.5,57.08],[6,39.95],[8.8,2.72],[7.8,3.26],[3.75,96.87]],"id":41419634},{"atb":[[36,8.43],[19,11.1],[28,3.26],[14,20.49]],"id":41419611},{"atb":[[70,2.72],[90,2.24],[46,5.91],[48,3.26],[230,0.87]],"id":41419593},{"atb":[[3.45,108.73],[3.95,67.72],[6,3.26],[7,2.72],[5.4,45.4]],"id":41419591},{"atb":[[130,2.72],[570,0.34],[720,0.27],[90,3.26],[470,0.56]],"id":41419622},{"atb":[[16,3.26],[18.5,2.72],[9,33.29],[20,10.51],[12.5,17.37]],"id":41419589},{"atb":[[16,13.31],[38,2.72],[11,26.63],[27,7.68],[29,3.26]],"id":41419620},{"atb":[[8.6,2.72],[7.4,31.21],[7.6,3.26],[5.2,47.57],[4.2,83.24]],"id":41419587},{"atb":[[70,3.26],[40,5.12],[95,2.72],[100,2.01],[25,11.1]],"id":41419601},{"atb":[[80,2.52],[85,2.72],[42,6.49],[210,0.95],[60,3.26]],"id":41419632},{"atb":[[70,2.72],[17,16.64],[48,7.52],[24,8.68]],"id":41419599},{"atb":[[40,8.39],[20,10.51],[50,2.72],[15,19.02]],"id":41419630},{"atb":[[36,3.26],[18,15.66],[46,2.72],[26,7.98],[55,3.7]],"id":41419597},{"atb":[[18.5,15.22],[44,3.26],[27,7.68],[60,6.1]],"id":41419628},{"atb":[[32,6.44],[36,3.26],[18,11.74],[46,2.72],[13,22.19]],"id":41419626},{"atb":[[32,6.44],[80,2.52],[42,3.26],[21,13.31],[55,2.72]],"id":41419608},{"atb":[[16.5,12.88],[22,3.26],[11.5,25.36],[27,2.72],[28,7.4]],"id":41419639},{"atb":[[4.8,70.1],[8.6,26.29],[5.8,41.62],[10.5,3.26],[13,2.72]],"id":41419606},{"atb":[[11.5,3.26],[6.8,34.44],[9.8,22.7],[14,2.72],[5.4,60.54]],"id":41419637},{"atb":[[540,0.37],[160,2.72],[690,0.28],[440,0.6],[110,3.26]],"id":41419604},{"atb":[[17.5,2.72],[17,12.48],[9.8,22.7],[7.8,39.17],[15,3.26]],"id":41419635},{"atb":[[11,22.7],[7.4,31.21],[5.7,56.67],[9.4,3.26]],"id":41419585},{"atb":[[16.5,2.72],[11,19.97],[7.4,31.21],[5.7,56.67],[14,3.26]],"id":41419612},{"atb":[[36,2.72],[38,5.4],[19.5,10.8],[28,3.26],[14.5,19.73]],"id":41419610},{"atb":[[65,3.26],[80,2.52],[42,6.49],[90,2.72],[210,0.95]],"id":41419625},{"atb":[[17,3.26],[9,24.97],[19.5,2.72],[7,44.4],[15,14.27]],"id":41419592},{"atb":[[42,8.14],[21,9.98],[55,2.72],[15.5,18.37]],"id":41419623},{"atb":[[17.5,2.72],[19.5,10.8],[12,18.16],[8.8,34.15],[15,3.26]],"id":41419590},{"atb":[[65,5.84],[19,14.8],[46,3.26],[28,7.4]],"id":41419621},{"atb":[[36,5.7],[19,11.1],[23,3.26],[28,2.72],[14,20.49]],"id":41419586},{"atb":[[34,3.26],[17.5,12.1],[44,2.72],[12.5,23.16],[30,6.88]],"id":41419633},{"atb":[[270,0.74],[80,3.26],[110,2.72],[120,1.67],[60,4.51]],"id":41419600},{"atb":[[18.5,11.41],[19.5,3.26],[11,19.97],[24,2.72],[8.4,35.99]],"id":41419598},{"atb":[[660,0.3],[85,3.26],[410,0.65],[120,2.72],[510,0.39]],"id":41419629},{"atb":[[18.5,15.22],[38,3.26],[48,2.72],[27,7.68],[60,3.38]],"id":41419596},{"atb":[[36,2.72],[10.5,28.03],[26,7.98],[28,3.26],[15.5,13.77]],"id":41419627},{"atb":[[23,3.26],[24,8.68],[9.8,30.27],[28,2.72],[14.5,14.8]],"id":41419594}],"con":true,"img":true}]}
{"op":"mcm","clk":"5353317939","pt":1646212896992,"mc":[{"id":"1.195503866","rc":[{"atb":[[16,13.31],[21,3.26],[11,26.63],[26,2.72],[27,7.68]],"id":41419640},{"atb":[[20,3.26],[22,9.51],[25,2.72],[13.5,15.98],[9.4,31.71]],"id":41419607},{"atb":[[65,3.12],[19,14.8],[80,2.72],[55,3.26],[28,7.4]],"id":41419605},{"atb":[[17,16.64],[38,2.72],[48,4.25],[24,8.68],[29,3.26]],"id":41419636},{"atb":[[600,0.33],[160,2.72],[750,0.26],[110,3.26],[500,0.53]],"id":41419603},{"atb":[[4.5,57.08],[6,39.95],[8.8,2.72],[7.8,3.26],[3.75,96.87]],"id":41419634},{"atb":[[36,8.43],[19,11.1],[28,3.26],[14,20.49]],"id":41419611},{"atb":[[70,2.72],[90,2.24],[46,5.91],[48,3.26],[230,0.87]],"id":41419593},{"atb":[[3.45,108.73],[3.95,67.72],[6,3.26],[7,2.72],[5.4,45.4]],"id":41419591},{"atb":[[130,2.72],[570,0.34],[720,0.27],[90,3.26],[470,0.56]],"id":41419622},{"atb":[[16,3.26],[18.5,2.72],[9,33.29],[20,10.51],[12.5,17.37]],"id":41419589},{"atb":[[16,13.31],[38,2.72],[11,26.63],[27,7.68],[29,3.26]],"id":41419620},{"atb":[[8.6,2.72],[7.4,31.21],[7.6,3.26],[5.2,47.57],[4.2,83.24]],"id":41419587},{"atb":[[70,3.26],[40,5.12],[95,2.72],[100,2.01],[25,11.1]],"id":41419601},{"atb":[[80,2.52],[85,2.72],[42,6.49],[210,0.95],[60,3.26]],"id":41419632},{"atb":[[70,2.72],[17,16.64],[48,7.52],[24,8.68]],"id":41419599},{"atb":[[40,8.39],[20,10.51],[50,2.72],[15,19.02]],"id":41419630},{"atb":[[36,3.26],[18,15.66],[46,2.72],[26,7.98],[55,3.7]],"id":41419597},{"atb":[[18.5,15.22],[44,3.26],[27,7.68],[60,6.1]],"id":41419628},{"atb":[[32,6.44],[36,3.26],[18,11.74],[46,2.72],[13,22.19]],"id":41419626},{"atb":[[32,6.44],[80,2.52],[42,3.26],[21,13.31],[55,2.72]],"id":41419608},{"atb":[[16.5,12.88],[22,3.26],[11.5,25.36],[27,2.72],[28,7.4]],"id":41419639},{"atb":[[4.8,70.1],[8.6,26.29],[5.8,41.62],[10.5,3.26],[13,2.72]],"id":41419606},{"atb":[[11.5,0],[6.8,34.44],[9.8,22.7],[14,0],[5.4,60.54]],"id":41419637},{"atb":[[540,0.37],[160,2.72],[690,0.28],[440,0.6],[110,3.26]],"id":41419604},{"atb":[[17.5,2.72],[17,12.48],[9.8,22.7],[7.8,39.17],[15,3.26]],"id":41419635},{"atb":[[11,22.7],[7.4,31.21],[5.7,56.67],[9.4,3.26]],"id":41419585},{"atb":[[16.5,2.72],[11,19.97],[7.4,31.21],[5.7,56.67],[14,3.26]],"id":41419612},{"atb":[[36,2.72],[38,5.4],[19.5,10.8],[28,3.26],[14.5,19.73]],"id":41419610},{"atb":[[65,3.26],[80,2.52],[42,6.49],[90,2.72],[210,0.95]],"id":41419625},{"atb":[[17,3.26],[9,24.97],[19.5,2.72],[7,44.4],[15,14.27]],"id":41419592},{"atb":[[42,8.14],[21,9.98],[55,2.72],[15.5,18.37]],"id":41419623},{"atb":[[17.5,2.72],[19.5,10.8],[12,18.16],[8.8,34.15],[15,3.26]],"id":41419590},{"atb":[[65,5.84],[19,14.8],[46,3.26],[28,7.4]],"id":41419621},{"atb":[[36,5.7],[19,11.1],[23,3.26],[28,2.72],[14,20.49]],"id":41419586},{"atb":[[34,3.26],[17.5,12.1],[44,2.72],[12.5,23.16],[30,6.88]],"id":41419633},{"atb":[[270,0.74],[80,3.26],[110,2.72],[120,1.67],[60,4.51]],"id":41419600},{"atb":[[18.5,11.41],[19.5,3.26],[11,19.97],[24,2.72],[8.4,35.99]],"id":41419598},{"atb":[[660,0.3],[85,3.26],[410,0.65],[120,2.72],[510,0.39]],"id":41419629},{"atb":[[18.5,15.22],[38,3.26],[48,2.72],[27,7.68],[60,3.38]],"id":41419596},{"atb":[[36,2.72],[10.5,28.03],[26,7.98],[28,3.26],[15.5,13.77]],"id":41419627},{"atb":[[23,3.26],[24,8.68],[9.8,30.27],[28,2.72],[14.5,14.8]],"id":41419594}],"con":true,"img":false}]}
{"op":"mcm","clk":"5353317984","pt":1646212897814,"mc":[{"id":"1.195503866","rc":[{"atb":[[11,3.26],[13.5,2.72]],"id":41419637}],"con":true,"img":false}]}
{"op":"mcm","clk":"5353329907","pt":1646213097348,"mc":[{"id":"1.195503866","rc":[{"atb":[[5.1,15.36]],"id":41419640},{"atl":[[580,2]],"id":41419640},{"atb":[[6.2,19.04]],"id":41419607},{"atl":[[630,2]],"id":41419607},{"atb":[[3,50]],"id":41419634},{"atl":[[320,2]],"id":41419634},{"atb":[[6.2,19.23]],"id":41419589},{"atl":[[710,2]],"id":41419589},{"atb":[[25,15.27]],"id":41419601},{"atb":[[13.5,5.44]],"id":41419632},{"atb":[[12.5,6.54]],"id":41419608},{"atl":[[1000,2]],"id":41419608},{"atb":[[3.4,41.67]],"id":41419606},{"atl":[[430,2]],"id":41419606},{"atb":[[3.55,39.22]],"id":41419637},{"atl":[[410,2]],"id":41419637},{"atb":[[26,2]],"id":41419604},{"atb":[[4.4,21.6]],"id":41419590},{"atl":[[520,2]],"id":41419590},{"atb":[[6.2,11.42]],"id":41419586},{"atl":[[700,2]],"id":41419586},{"atb":[[25,2]],"id":41419629}],"con":true,"img":false}]}
{"op":"mcm","clk":"5353329914","pt":1646213097448,"mc":[{"id":"1.195503866","rc":[{"atb":[[25,4.17]],"id":41419605},{"atb":[[8.6,8.5]],"id":41419636},{"atl":[[920,2]],"id":41419636},{"atb":[[27,2]],"id":41419603},{"atb":[[6.2,19.23]],"id":41419611},{"atl":[[720,2]],"id":41419611},{"atb":[[25,4.17]],"id":41419593},{"atb":[[2.76,56.82]],"id":41419591},{"atl":[[320,2]],"id":41419591},{"atb":[[26,2]],"id":41419622},{"atb":[[24,4.35]],"id":41419620},{"atb":[[2.9,52.63]],"id":41419587},{"atl":[[320,2]],"id":41419587},{"atb":[[24,13.03]],"id":41419599},{"atb":[[8,14.29]],"id":41419630},{"atl":[[900,2]],"id":41419630},{"atb":[[23,4.55]],"id":41419597},{"atl":[[1000,2]],"id":41419597},{"atb":[[23,4.55]],"id":41419628},{"atl":[[1000,2]],"id":41419628},{"atb":[[13.5,8]],"id":41419626},{"atb":[[7.2,14.8]],"id":41419639},{"atl":[[870,2]],"id":41419639},{"atb":[[5.2,23.81]],"id":41419635},{"atl":[[550,2]],"id":41419635},{"atb":[[3.6,38.46]],"id":41419585},{"atl":[[480,2]],"id":41419585},{"atb":[[3.6,38.46]],"id":41419612},{"atl":[[480,2]],"id":41419612},{"atb":[[11.5,9.52]],"id":41419610},{"atl":[[1000,2]],"id":41419610},{"atb":[[13.5,5.44]],"id":41419625},{"atb":[[6,20]],"id":41419592},{"atl":[[670,2]],"id":41419592},{"atb":[[13.5,8]],"id":41419623},{"atb":[[26,4]],"id":41419621},{"atb":[[6.8,13.78]],"id":41419633},{"atl":[[830,2]],"id":41419633},{"atb":[[26,4]],"id":41419600},{"atb":[[6.6,17.86]],"id":41419598},{"atl":[[790,2]],"id":41419598},{"atb":[[25,4.17]],"id":41419596},{"atb":[[6.6,15.98]],"id":41419627},{"atl":[[790,2]],"id":41419627},{"atb":[[6.8,17.24]],"id":41419594},{"atl":[[820,2]],"id":41419594}],"con":true,"img":false}]}
{"op":"mcm","clk":"5353337758","pt":1646213235304,"mc":[{"id":"1.195503866","rc":[{"atb":[[24,8.68]],"id":41419599},{"atb":[[3.6,0]],"id":41419612},{"atl":[[480,0]],"id":41419612},{"atb":[[13.5,0]],"id":41419623}],"con":true,"img":false}]}
{"op":"mcm","clk":"5353337763","pt":1646213235407,"mc":[{"id":"1.195503866","rc":[{"atb":[[6.2,0]],"id":41419611},{"atl":[[720,0]],"id":41419611},{"atb":[[25,0]],"id":41419593},{"atb":[[2.9,0]],"id":41419587},{"atl":[[320,0]],"id":41419587},{"atb":[[13.5,0]],"id":41419632},{"atb":[[23,0]],"id":41419628},{"atl":[[1000,0]],"id":41419628},{"atb":[[5.2,0]],"id":41419635},{"atl":[[550,0]],"id":41419635},{"atb":[[13.5,0]],"id":41419625},{"atb":[[6,0]],"id":41419592},{"atl":[[670,0]],"id":41419592},{"atb":[[26,0]],"id":41419621},{"atb":[[6.8,0]],"id":41419594},{"atl":[[820,0]],"id":41419594}],"con":true,"img":false}]}
{"op":"mcm","clk":"5353337767","pt":1646213235520,"mc":[{"id":"1.195503866","rc":[{"atb":[[5.1,0]],"id":41419640},{"atl":[[580,0]],"id":41419640},{"atb":[[25,0]],"id":41419605},{"atb":[[8.6,0]],"id":41419636},{"atl":[[920,0]],"id":41419636},{"atb":[[27,0]],"id":41419603},{"atb":[[3,0]],"id":41419634},{"atl":[[320,0]],"id":41419634},{"atb":[[26,0]],"id":41419622},{"atb":[[24,0]],"id":41419620},{"atb":[[23,0]],"id":41419597},{"atl":[[1000,0]],"id":41419597},{"atb":[[7.2,0]],"id":41419639},{"atl":[[870,0]],"id":41419639},{"atb":[[3.6,0]],"id":41419585},{"atl":[[480,0]],"id":41419585},{"atb":[[11.5,0]],"id":41419610},{"atl":[[1000,0]],"id":41419610},{"atb":[[26,0]],"id":41419600},{"atb":[[25,0]],"id":41419596},{"atb":[[6.6,0]],"id":41419627},{"atl":[[790,0]],"id":41419627}],"con":true,"img":false}]}
{"op":"mcm","clk":"5353337771","pt":1646213235622,"mc":[{"id":"1.195503866","rc":[{"atb":[[6.2,0]],"id":41419589},{"atl":[[710,0]],"id":41419589},{"atb":[[70,0],[48,4.25]],"id":41419599},{"atb":[[8,0]],"id":41419630},{"atl":[[900,0]],"id":41419630},{"atb":[[13.5,0]],"id":41419626},{"atb":[[3.4,0]],"id":41419606},{"atl":[[430,0]],"id":41419606},{"atb":[[26,0]],"id":41419604},{"atb":[[65,0],[90,0]],"id":41419625},{"atb":[[42,4.87],[55,0]],"id":41419623},{"atb":[[65,3.12],[46,0]],"id":41419621},{"atb":[[6.2,0]],"id":41419586},{"atl":[[700,0]],"id":41419586},{"atb":[[6.8,0]],"id":41419633},{"atl":[[830,0]],"id":41419633}],"con":true,"img":false}]}
{"op":"mcm","clk":"5353337779","pt":1646213235728,"mc":[{"id":"1.195503866","rc":[{"atb":[[6.2,0]],"id":41419607},{"atl":[[630,0]],"id":41419607},{"atb":[[160,0],[110,0]],"id":41419603},{"atb":[[8.8,0],[7.8,0]],"id":41419634},{"atb":[[70,0],[48,0]],"id":41419593},{"atb":[[2.76,0]],"id":41419591},{"atl":[[320,0]],"id":41419591},{"atb":[[8.6,0],[7.6,0]],"id":41419587},{"atb":[[25,11.1]],"id":41419601},{"atb":[[85,0],[60,0]],"id":41419632},{"atb":[[44,0],[60,3.38]],"id":41419628},{"atb":[[12.5,0]],"id":41419608},{"atl":[[1000,0]],"id":41419608},{"atb":[[3.55,0]],"id":41419637},{"atl":[[410,0]],"id":41419637},{"atb":[[17.5,0],[15,0]],"id":41419635},{"atb":[[4.4,0]],"id":41419590},{"atl":[[520,0]],"id":41419590},{"atb":[[25,0]],"id":41419629},{"atb":[[23,0],[28,0]],"id":41419594}],"con":true,"img":false}]}
{"op":"mcm","clk":"5353337784","pt":1646213235781,"mc":[{"id":"1.195503866","rc":[{"atb":[[21,0],[26,0]],"id":41419640},{"atb":[[38,0],[29,0]],"id":41419636},{"atb":[[36,5.7],[28,0]],"id":41419611},{"atb":[[38,0],[29,0]],"id":41419620},{"atb":[[36,0],[46,0]],"id":41419597},{"atb":[[22,0],[27,0]],"id":41419639},{"atb":[[11,19.97],[9.4,0]],"id":41419585},{"atb":[[36,0],[28,0]],"id":41419610},{"atb":[[80,0],[110,0]],"id":41419600},{"atb":[[6.6,0]],"id":41419598},{"atl":[[790,0]],"id":41419598},{"atb":[[38,0],[48,0]],"id":41419596},{"atb":[[36,0],[28,0]],"id":41419627}],"con":true,"img":false}]}
{"op":"mcm","clk":"5353337788","pt":1646213235882,"mc":[{"id":"1.195503866","rc":[{"atb":[[16,0],[18.5,0]],"id":41419589},{"atb":[[40,5.12],[50,0]],"id":41419630},{"atb":[[36,0],[46,0]],"id":41419626},{"atb":[[10.5,0],[13,0]],"id":41419606},{"atb":[[160,0],[110,0]],"id":41419604},{"atb":[[23,0],[28,0]],"id":41419586},{"atb":[[34,0],[44,0]],"id":41419633}],"con":true,"img":false}]}
{"op":"mcm","clk":"5353337808","pt":1646213236295,"mc":[{"id":"1.195503866","rc":[{"atb":[[70,2.72],[48,7.52]],"id":41419599},{"atb":[[65,3.26],[90,2.72]],"id":41419625},{"atb":[[42,8.14],[55,2.72]],"id":41419623},{"atb":[[65,5.84],[46,3.26]],"id":41419621}],"con":true,"img":false}]}
{"op":"mcm","clk":"5353337814","pt":1646213236397,"mc":[{"id":"1.195503866","rc":[{"atb":[[160,2.72],[110,3.26]],"id":41419603},{"atb":[[8.8,2.72],[7.8,3.26]],"id":41419634},{"atb":[[70,2.72],[48,3.26]],"id":41419593},{"atb":[[8.6,2.72],[7.6,3.26]],"id":41419587},{"atb":[[85,2.72],[60,3.26]],"id":41419632},{"atb":[[44,3.26],[60,6.1]],"id":41419628}],"con":true,"img":false}]}
{"op":"mcm","clk":"5353337819","pt":1646213236500,"mc":[{"id":"1.195503866","rc":[{"atb":[[38,2.72],[29,3.26]],"id":41419636},{"atb":[[36,8.43],[28,3.26]],"id":41419611},{"atb":[[38,2.72],[29,3.26]],"id":41419620},{"atb":[[36,3.26],[46,2.72]],"id":41419597},{"atb":[[22,3.26],[27,2.72]],"id":41419639},{"atb":[[17.5,2.72],[15,3.26]],"id":41419635},{"atb":[[11,22.7],[9.4,3.26]],"id":41419585},{"atb":[[36,2.72],[28,3.26]],"id":41419610},{"atb":[[80,3.26],[110,2.72]],"id":41419600},{"atb":[[38,3.26],[48,2.72]],"id":41419596},{"atb":[[36,2.72],[28,3.26]],"id":41419627},{"atb":[[23,3.26],[28,2.72]],"id":41419594}],"con":true,"img":false}]}
{"op":"mcm","clk":"5353337829","pt":1646213236605,"mc":[{"id":"1.195503866","rc":[{"atb":[[21,3.26],[26,2.72]],"id":41419640},{"atb":[[16,3.26],[18.5,2.72]],"id":41419589},{"atb":[[40,8.39],[50,2.72]],"id":41419630},{"atb":[[36,3.26],[46,2.72]],"id":41419626},{"atb":[[10.5,3.26],[13,2.72]],"id":41419606},{"atb":[[160,2.72],[110,3.26]],"id":41419604},{"atb":[[23,3.26],[28,2.72]],"id":41419586},{"atb":[[34,3.26],[44,2.72]],"id":41419633}],"con":true,"img":false}]}
{"op":"mcm","clk":"5353373962","pt":1646213895210,"mc":[{"id":"1.195503866","rc":[{"atb":[[11,0],[13.5,0]],"id":41419637}],"con":true,"img":false}]}
{"op":"mcm","clk":"5353374002","pt":1646213895929,"mc":[{"id":"1.195503866","rc":[{"atb":[[10.5,3.26],[13,2.72]],"id":41419637}],"con":true,"img":false}]}
{"op":"mcm","clk":"5353385608","pt":1646214075301,"mc":[{"id":"1.195503866","rc":[{"atb":[[8.8,0],[7.8,0]],"id":41419634},{"atb":[[10.5,0],[13,0]],"id":41419637}],"con":true,"img":false}]}
{"op":"mcm","clk":"5353385664","pt":1646214076123,"mc":[{"id":"1.195503866","rc":[{"atb":[[8.6,2.72],[7.6,3.26]],"id":41419634},{"atb":[[12,2.72],[9.8,25.97]],"id":41419637}],"con":true,"img":false}]}
{"op":"mcm","clk":"5353400159","pt":1646214289776,"mc":[{"id":"1.195503866","rc":[{"atb":[[8.6,0],[7.6,0]],"id":41419587}],"con":true,"img":false}]}
{"op":"mcm","clk":"5353400197","pt":1646214290497,"mc":[{"id":"1.195503866","rc":[{"atb":[[7.4,34.48],[8.4,2.72]],"id":41419587}],"con":true,"img":false}]}
{"op":"mcm","clk":"5353403647","pt":1646214338164,"mc":[{"id":"1.195503866","rc":[{"atb":[[8.6,0]],"id":41419634}],"con":true,"img":false}]}
{"op":"mcm","clk":"5353403657","pt":1646214338269,"mc":[{"id":"1.195503866","rc":[{"atb":[[7.6,0]],"id":41419634},{"atb":[[12,0],[9.8,22.7]],"id":41419637}],"con":true,"img":false}]}
{"op":"mcm","clk":"5353403707","pt":1646214338945,"mc":[{"id":"1.195503866","rc":[{"atb":[[8.8,2.72],[7.8,3.26]],"id":41419634},{"atb":[[10,3.26],[12.5,2.72]],"id":41419637}],"con":true,"img":false}]}
{"op":"mcm","clk":"5353408170","pt":1646214401415,"mc":[{"id":"1.195503866","rc":[{"atb":[[5.6,15.36]],"id":41419640},{"atl":[[570,2]],"id":41419640},{"atb":[[6.8,17.24]],"id":41419607},{"atl":[[610,2]],"id":41419607},{"atb":[[28,11.1]],"id":41419605},{"atb":[[10,8.5]],"id":41419636},{"atl":[[920,2]],"id":41419636},{"atb":[[29,2]],"id":41419603},{"atb":[[3.05,48.78]],"id":41419634},{"atl":[[320,2]],"id":41419634},{"atb":[[7,16.67]],"id":41419611},{"atl":[[730,2]],"id":41419611},{"atb":[[27,3.85]],"id":41419593},{"atb":[[2.82,54.95]],"id":41419591},{"atl":[[320,2]],"id":41419591},{"atb":[[29,2]],"id":41419622},{"atb":[[6.8,17.24]],"id":41419589},{"atl":[[720,2]],"id":41419589},{"atb":[[26,4]],"id":41419620},{"atb":[[3,50]],"id":41419587},{"atl":[[320,2]],"id":41419587},{"atb":[[28,3.7]],"id":41419601},{"atb":[[13.5,5.44]],"id":41419632},{"atb":[[27,3.85]],"id":41419599},{"atb":[[10.5,10.53]],"id":41419630},{"atl":[[920,2]],"id":41419630},{"atb":[[25,4.17]],"id":41419597},{"atl":[[1000,2]],"id":41419597},{"atb":[[26,4]],"id":41419628},{"atl":[[1000,2]],"id":41419628},{"atb":[[13.5,8]],"id":41419626},{"atb":[[16.5,6.45]],"id":41419608},{"atl":[[1000,2]],"id":41419608},{"atb":[[8.4,13.51]],"id":41419639},{"atl":[[850,2]],"id":41419639},{"atb":[[3.6,38.46]],"id":41419606},{"atl":[[420,2]],"id":41419606},{"atb":[[3.65,37.74]],"id":41419637},{"atl":[[370,2]],"id":41419637},{"atb":[[29,2]],"id":41419604},{"atb":[[5.4,22.73]],"id":41419635},{"atl":[[540,2]],"id":41419635},{"atb":[[3.8,35.71]],"id":41419585},{"atl":[[460,2]],"id":41419585},{"atb":[[3.8,35.71]],"id":41419612},{"atl":[[460,2]],"id":41419612},{"atb":[[13.5,8]],"id":41419610},{"atl":[[1000,2]],"id":41419610},{"atb":[[13.5,5.44]],"id":41419625},{"atb":[[6.6,17.86]],"id":41419592},{"atl":[[660,2]],"id":41419592},{"atb":[[13.5,8]],"id":41419623},{"atb":[[4.9,21.6]],"id":41419590},{"atl":[[520,2]],"id":41419590},{"atb":[[28,11.1]],"id":41419621},{"atb":[[7,11.42]],"id":41419586},{"atl":[[730,2]],"id":41419586},{"atb":[[8.4,13.51]],"id":41419633},{"atl":[[850,2]],"id":41419633},{"atb":[[29,3.57]],"id":41419600},{"atb":[[7.2,16.13]],"id":41419598},{"atl":[[780,2]],"id":41419598},{"atb":[[28,2]],"id":41419629},{"atb":[[27,11.53]],"id":41419596},{"atb":[[7.8,14.71]],"id":41419627},{"atl":[[830,2]],"id":41419627},{"atb":[[7.4,15.62]],"id":41419594},{"atl":[[810,2]],"id":41419594}],"con":true,"img":false}]}
{"op":"mcm","clk":"5353408864","pt":1646214410624,"mc":[{"id":"1.195503866","rc":[{"atb":[[7.4,31.21],[8.4,0]],"id":41419587}],"con":true,"img":false}]}
{"op":"mcm","clk":"5353408906","pt":1646214411308,"mc":[{"id":"1.195503866","rc":[{"atb":[[7.2,3.26],[8.2,2.72]],"id":41419587}],"con":true,"img":false}]}
{"op":"mcm","clk":"5353409834","pt":1646214424945,"mc":[{"id":"1.195503866","rc":[{"atl":[[700,2],[720,0]],"id":41419589},{"atl":[[730,0],[720,2]],"id":41419586},{"atl":[[780,0],[770,2]],"id":41419598}],"con":true,"img":false}]}
{"op":"mcm","clk":"5353410856","pt":1646214439542,"mc":[{"id":"1.195503866","rc":[{"atl":[[1000,0]],"id":41419628},{"atl":[[850,0],[840,2]],"id":41419639},{"atl":[[540,0],[530,2]],"id":41419635},{"atl":[[660,0],[650,2]],"id":41419592}],"con":true,"img":false}]}
{"op":"mcm","clk":"5353411790","pt":1646214454583,"mc":[{"id":"1.195503866","rc":[{"atl":[[1000,2]],"id":41419628}],"con":true,"img":false}]}
{"op":"mcm","clk":"5353412147","pt":1646214460781,"mc":[{"id":"1.195503866","rc":[{"atb":[[5.6,0],[6.4,15.36]],"id":41419640},{"atl":[[890,2],[920,0]],"id":41419636},{"atb":[[7,0],[8.4,13.51]],"id":41419611},{"atb":[[2.82,0],[2.7,58.82]],"id":41419591},{"atb":[[6.8,0],[7.8,14.71]],"id":41419589},{"atb":[[26,0],[28,3.7]],"id":41419620},{"atl":[[1000,2]],"id":41419620},{"atb":[[10.5,0],[13.5,8]],"id":41419630},{"atl":[[1000,0]],"id":41419597},{"atl":[[1000,0]],"id":41419628},{"atb":[[16.5,0],[25,4.17]],"id":41419608},{"atb":[[8.4,0],[9.4,11.9]],"id":41419639},{"atb":[[3.6,0],[3.9,34.48]],"id":41419606},{"atl":[[350,2],[370,0]],"id":41419637},{"atb":[[3.8,0],[4.2,31.25]],"id":41419585},{"atl":[[430,2],[460,0]],"id":41419585},{"atb":[[4.1,32.26],[3.8,0]],"id":41419612},{"atb":[[4.9,0],[5.7,21.28]],"id":41419590},{"atb":[[11,10],[8.4,0]],"id":41419633},{"atl":[[700,2],[770,0]],"id":41419598},{"atb":[[9.8,11.36],[7.8,0]],"id":41419627},{"atl":[[790,2],[810,0]],"id":41419594}],"con":true,"img":false}]}
{"op":"mcm","clk":"5353412165","pt":1646214461069,"mc":[{"id":"1.195503866","rc":[{"atb":[[8.8,0],[7.8,0]],"id":41419634},{"atb":[[6,0],[7,0]],"id":41419591},{"atb":[[10,0],[12.5,0]],"id":41419637}],"con":true,"img":false}]}
{"op":"mcm","clk":"5353412172","pt":1646214461133,"mc":[{"id":"1.195503866","rc":[{"atl":[[1000,2]],"id":41419597}],"con":true,"img":false}]}
{"op":"mcm","clk":"5353412204","pt":1646214461695,"mc":[{"id":"1.195503866","rc":[{"atb":[[8,2.72],[7,3.26]],"id":41419634},{"atb":[[6.4,2.72],[5.7,3.26]],"id":41419591},{"atb":[[12,2.72],[9.8,25.97]],"id":41419637}],"con":true,"img":false}]}
{"op":"mcm","clk":"5353412266","pt":1646214462691,"mc":[{"id":"1.195503866","rc":[{"atl":[[530,0],[510,2]],"id":41419635},{"atl":[[610,2],[650,0]],"id":41419592}],"con":true,"img":false}]}
{"op":"mcm","clk":"5353413200","pt":1646214479323,"mc":[{"id":"1.195503866","rc":[{"atb":[[20,0],[25,0]],"id":41419607},{"atb":[[80,0],[55,0]],"id":41419605},{"atb":[[38,0],[29,0]],"id":41419636},{"atb":[[160,0],[110,0]],"id":41419603},{"atb":[[70,0],[48,0]],"id":41419593},{"atb":[[130,0],[90,0]],"id":41419622},{"atb":[[70,0],[95,0]],"id":41419601},{"atb":[[70,0],[48,4.25]],"id":41419599},{"atb":[[36,0],[46,0]],"id":41419597},{"atb":[[160,0],[110,0]],"id":41419604},{"atb":[[17.5,0],[15,0]],"id":41419635},{"atb":[[11,19.97],[9.4,0]],"id":41419585},{"atb":[[17,0],[19.5,0]],"id":41419592},{"atb":[[23,0],[28,0]],"id":41419586},{"atb":[[80,0],[110,0]],"id":41419600},{"atb":[[19.5,0],[24,0]],"id":41419598},{"atb":[[85,0],[120,0]],"id":41419629},{"atb":[[38,0],[48,0]],"id":41419596},{"atb":[[23,0],[28,0]],"id":41419594}],"con":true,"img":false}]}
{"op":"mcm","clk":"5353413240","pt":1646214480042,"mc":[{"id":"1.195503866","rc":[{"atb":[[21,3.26],[26,2.72]],"id":41419607},{"atb":[[65,6.39],[90,2.72]],"id":41419605},{"atb":[[40,2.72],[30,3.26]],"id":41419636},{"atb":[[140,2.72],[95,3.26]],"id":41419622},{"atb":[[80,3.26],[110,2.72]],"id":41419601},{"atb":[[75,2.72],[50,3.26]],"id":41419599},{"atb":[[40,3.26],[50,2.72]],"id":41419597},{"atb":[[9.6,3.26],[11.5,2.72]],"id":41419585},{"atb":[[18,3.26],[21,2.72]],"id":41419592},{"atb":[[24,3.26],[29,2.72]],"id":41419586},{"atb":[[130,2.72],[90,3.26]],"id":41419600},{"atb":[[20,3.26],[25,2.72]],"id":41419598},{"atb":[[130,2.72],[90,3.26]],"id":41419629},{"atb":[[40,3.26],[50,2.72]],"id":41419596},{"atb":[[25,3.26],[30,2.72]],"id":41419594}],"con":true,"img":false}]}
{"op":"mcm","clk":"5353413245","pt":1646214480146,"mc":[{"id":"1.195503866","rc":[{"atb":[[130,3.26],[180,2.72]],"id":41419603},{"atb":[[75,2.72],[50,3.26]],"id":41419593},{"atb":[[170,2.72],[120,3.26]],"id":41419604},{"atb":[[18,2.72],[15.5,3.26]],"id":41419635}],"con":true,"img":false}]}
{"op":"mcm","clk":"5353413441","pt":1646214483827,"mc":[{"id":"1.195503866","rc":[{"atb":[[2.82,54.95],[2.7,0]],"id":41419591},{"atl":[[430,0],[420,2]],"id":41419585},{"atl":[[700,0],[680,2]],"id":41419598},{"atl":[[760,2],[790,0]],"id":41419594}],"con":true,"img":false}]}
{"op":"mcm","clk":"5353418603","pt":1646214580712,"mc":[{"id":"1.195503866","rc":[{"atb":[[2.82,0],[2.7,58.82]],"id":41419591},{"atl":[[1000,0]],"id":41419620},{"atl":[[1000,0]],"id":41419597},{"atl":[[420,0],[430,2]],"id":41419585},{"atl":[[680,0],[700,2]],"id":41419598},{"atl":[[760,0],[790,2]],"id":41419594}],"con":true,"img":false}]}
{"op":"mcm","clk":"5353421013","pt":1646214628190,"mc":[{"id":"1.195503866","rc":[{"atb":[[6.4,0],[7.8,14.71]],"id":41419640},{"atl":[[570,0],[560,2]],"id":41419640},{"atb":[[9,12.5],[6.8,0]],"id":41419607},{"atl":[[590,2],[610,0]],"id":41419607},{"atb":[[10,0],[13,8.33]],"id":41419636},{"atl":[[890,0]],"id":41419636},{"atb":[[40,2],[29,0]],"id":41419603},{"atb":[[3.4,41.67],[3.05,0]],"id":41419634},{"atl":[[690,2],[730,0]],"id":41419611},{"atb":[[27,0]],"id":41419593},{"atb":[[3.2,45.45],[2.7,0]],"id":41419591},{"atb":[[38,2],[29,0]],"id":41419622},{"atl":[[650,2],[700,0]],"id":41419589},{"atb":[[10.5,10.53],[28,0]],"id":41419620},{"atl":[[860,2]],"id":41419620},{"atb":[[3.35,42.55],[3,0]],"id":41419587},{"atb":[[36,2.86],[28,0]],"id":41419601},{"atb":[[36,2.86],[27,0]],"id":41419599},{"atb":[[10,11.11],[13.5,0]],"id":41419630},{"atl":[[850,2],[920,0]],"id":41419630},{"atl":[[1000,2]],"id":41419597},{"atb":[[34,3.03],[26,0]],"id":41419628},{"atl":[[1000,2]],"id":41419628},{"atb":[[13.5,0]],"id":41419626},{"atl":[[870,2]],"id":41419626},{"atb":[[18,5.88],[25,0]],"id":41419608},{"atl":[[990,2],[1000,0]],"id":41419608},{"atb":[[7.6,15.15],[9.4,0]],"id":41419639},{"atl":[[720,2],[840,0]],"id":41419639},{"atb":[[3.9,0]],"id":41419606},{"atl":[[400,2],[420,0]],"id":41419606},{"atb":[[3.9,34.48],[3.65,0]],"id":41419637},{"atl":[[320,2],[350,0]],"id":41419637},{"atb":[[29,0]],"id":41419604},{"atb":[[6.2,19.23],[5.4,0]],"id":41419635},{"atb":[[4.2,0]],"id":41419585},{"atb":[[4.8,26.32],[4.1,0]],"id":41419612},{"atl":[[410,2],[460,0]],"id":41419612},{"atb":[[9.6,11.63],[13.5,0]],"id":41419610},{"atl":[[830,2],[1000,0]],"id":41419610},{"atb":[[5.5,22.22],[6.6,0]],"id":41419592},{"atl":[[540,2],[610,0]],"id":41419592},{"atl":[[910,2]],"id":41419623},{"atb":[[5.7,0],[7,16.67]],"id":41419590},{"atl":[[1000,2]],"id":41419621},{"atb":[[9.2,11.42],[7,0]],"id":41419586},{"atb":[[8.6,13.16],[11,0]],"id":41419633},{"atl":[[800,2],[850,0]],"id":41419633},{"atb":[[38,2.7],[29,0]],"id":41419600},{"atl":[[600,2],[700,0]],"id":41419598},{"atb":[[38,2],[28,0]],"id":41419629},{"atb":[[32,3.23],[27,7.68]],"id":41419596},{"atl":[[1000,2]],"id":41419596},{"atb":[[12.5,8.7]],"id":41419627},{"atl":[[780,2]],"id":41419627},{"atl":[[630,2],[790,0]],"id":41419594}],"con":true,"img":false}]}
{"op":"mcm","clk":"5353421017","pt":1646214628282,"mc":[{"id":"1.195503866","rc":[{"atl":[[830,2]],"id":41419636},{"atb":[[34,3.03]],"id":41419593},{"atl":[[1000,2]],"id":41419593},{"atb":[[4.3,30.3]],"id":41419606},{"atb":[[40,2]],"id":41419604},{"atb":[[4.8,26.32]],"id":41419585},{"atb":[[9.8,0]],"id":41419627},{"atl":[[830,0]],"id":41419627}],"con":true,"img":false}]}
{"op":"mcm","clk":"5353421024","pt":1646214628384,"mc":[{"id":"1.195503866","rc":[{"atb":[[13,30.52]],"id":41419626},{"atb":[[9.2,12.2],[7.6,0]],"id":41419639},{"atl":[[670,2],[720,0]],"id":41419639}],"con":true,"img":false}]}
{"op":"mcm","clk":"5353421035","pt":1646214628592,"mc":[{"id":"1.195503866","rc":[{"atb":[[16.5,0],[14,0]],"id":41419612}],"con":true,"img":false}]}
{"op":"mcm","clk":"5353421071","pt":1646214629269,"mc":[{"id":"1.195503866","rc":[{"atb":[[12,3.26],[14.5,2.72]],"id":41419612}],"con":true,"img":false}]}
{"op":"mcm","clk":"5353421605","pt":1646214639862,"mc":[{"id":"1.195503866","rc":[{"atb":[[7.2,0]],"id":41419587}],"con":true,"img":false}]}
{"op":"mcm","clk":"5353421627","pt":1646214640274,"mc":[{"id":"1.195503866","rc":[{"atb":[[8.2,0]],"id":41419587}],"con":true,"img":false}]}
{"op":"mcm","clk":"5353421641","pt":1646214640584,"mc":[{"id":"1.195503866","rc":[{"atb":[[7.6,3.26]],"id":41419587}],"con":true,"img":false}]}
{"op":"mcm","clk":"5353421669","pt":1646214640996,"mc":[{"id":"1.195503866","rc":[{"atb":[[8.6,2.72]],"id":41419587}],"con":true,"img":false}]}
{"op":"mcm","clk":"5353422046","pt":1646214649536,"mc":[{"id":"1.195503866","rc":[{"atl":[[560,2],[590,0]],"id":41419607},{"atb":[[16,6.67],[13,0]],"id":41419636},{"atb":[[3.4,0],[3.9,34.48]],"id":41419634},{"atl":[[640,2],[690,0]],"id":41419611},{"atb":[[3.2,0],[3.65,37.74]],"id":41419591},{"atl":[[600,2],[650,0]],"id":41419589},{"atl":[[780,2],[860,0]],"id":41419620},{"atb":[[3.35,0],[3.8,35.71]],"id":41419587},{"atb":[[10,0],[12.5,8.7]],"id":41419630},{"atl":[[770,2],[850,0]],"id":41419630},{"atl":[[1000,0]],"id":41419597},{"atl":[[790,2],[870,0]],"id":41419626},{"atb":[[18,0],[21,18.31]],"id":41419608},{"atl":[[890,2],[990,0]],"id":41419608},{"atl":[[360,2],[400,0]],"id":41419606},{"atb":[[4.5,28.57],[3.9,0]],"id":41419637},{"atb":[[6.2,0],[7.6,15.15]],"id":41419635},{"atl":[[370,2],[410,0]],"id":41419612},{"atb":[[9.6,0],[11.5,9.52]],"id":41419610},{"atl":[[750,2],[830,0]],"id":41419610},{"atb":[[5.5,0],[6.6,17.86]],"id":41419592},{"atl":[[540,0],[520,2]],"id":41419592},{"atl":[[820,2],[910,0]],"id":41419623},{"atb":[[8.6,13.16],[7,0]],"id":41419590},{"atb":[[9.2,0],[11,10]],"id":41419586},{"atb":[[8.6,0],[10,11.11]],"id":41419633},{"atl":[[730,2],[800,0]],"id":41419633},{"atl":[[570,2],[600,0]],"id":41419598},{"atl":[[590,2],[630,0]],"id":41419594}],"con":true,"img":false}]}
{"op":"mcm","clk":"5353422049","pt":1646214649583,"mc":[{"id":"1.195503866","rc":[{"atl":[[940,2]],"id":41419597}],"con":true,"img":false}]}
{"op":"mcm","clk":"5353423630","pt":1646214685284,"mc":[{"id":"1.195503866","rc":[{"atb":[[8,0]],"id":41419634}],"con":true,"img":false}]}
{"op":"mcm","clk":"5353423647","pt":1646214685689,"mc":[{"id":"1.195503866","rc":[{"atb":[[7,0]],"id":41419634},{"atb":[[6.4,0],[5.7,0]],"id":41419591},{"atb":[[12,0],[9.8,22.7]],"id":41419637}],"con":true,"img":false}]}
{"op":"mcm","clk":"5353423660","pt":1646214685951,"mc":[{"id":"1.195503866","rc":[{"atb":[[8.6,2.72]],"id":41419634}],"con":true,"img":false}]}
{"op":"mcm","clk":"5353423677","pt":1646214686364,"mc":[{"id":"1.195503866","rc":[{"atb":[[12.5,2.72]],"id":41419637}],"con":true,"img":false}]}
{"op":"mcm","clk":"5353423687","pt":1646214686669,"mc":[{"id":"1.195503866","rc":[{"atb":[[7.6,3.26]],"id":41419634},{"atb":[[6,3.26],[7,2.72]],"id":41419591},{"atb":[[10,3.26]],"id":41419637}],"con":true,"img":false}]}
{"op":"mcm","clk":"5353427638","pt":1646214762911,"mc":[{"id":"1.195503866","rc":[{"atl":[[560,0],[570,2]],"id":41419640},{"atl":[[1000,0]],"id":41419593},{"atl":[[600,0],[620,2]],"id":41419589}],"con":true,"img":false}]}
{"op":"mcm","clk":"5353430991","pt":1646214827406,"mc":[{"id":"1.195503866","rc":[{"atl":[[570,0],[560,2]],"id":41419640},{"atl":[[520,2],[560,0]],"id":41419607},{"atb":[[8.8,12.82],[7.8,0]],"id":41419589},{"atb":[[10.5,0],[14,7.69]],"id":41419620},{"atb":[[19,5.56],[25,0]],"id":41419597},{"atl":[[860,2],[940,0]],"id":41419597},{"atl":[[960,2],[1000,0]],"id":41419628},{"atb":[[6.4,18.52],[7.6,0]],"id":41419635},{"atl":[[480,2],[510,0]],"id":41419635},{"atl":[[520,0],[510,2]],"id":41419592},{"atl":[[530,2],[570,0]],"id":41419598},{"atl":[[730,2],[780,0]],"id":41419627},{"atl":[[550,2],[590,0]],"id":41419594}],"con":true,"img":false}]}
{"op":"mcm","clk":"5353431000","pt":1646214827513,"mc":[{"id":"1.195503866","rc":[{"atl":[[1000,2]],"id":41419593}],"con":true,"img":false}]}
{"op":"mcm","clk":"5353431015","pt":1646214827767,"mc":[{"id":"1.195503866","rc":[{"atb":[[12,0],[14.5,0]],"id":41419612}],"con":true,"img":false}]}
{"op":"mcm","clk":"5353431074","pt":1646214828590,"mc":[{"id":"1.195503866","rc":[{"atb":[[13,3.26],[15.5,2.72]],"id":41419612}],"con":true,"img":false}]}
{"op":"mcm","clk":"5353431832","pt":1646214841697,"mc":[{"id":"1.195503866","rc":[{"atb":[[9,0],[7.8,14.71]],"id":41419607},{"atb":[[16,0]],"id":41419636},{"atb":[[21,13.31],[27,3.85]],"id":41419608},{"atl":[[950,2],[1000,0]],"id":41419596}],"con":true,"img":false}]}
{"op":"mcm","clk":"5353431836","pt":1646214841801,"mc":[{"id":"1.195503866","rc":[{"atb":[[19,5.56]],"id":41419636}],"con":true,"img":false}]}
{"op":"mcm","clk":"5353431889","pt":1646214842729,"mc":[{"id":"1.195503866","rc":[{"atb":[[21,0],[26,0]],"id":41419640},{"atb":[[16,0],[18.5,0]],"id":41419589},{"atb":[[38,0],[29,0]],"id":41419620},{"atb":[[85,0],[60,0]],"id":41419632},{"atb":[[40,5.12],[50,0]],"id":41419630},{"atb":[[44,0],[60,3.38]],"id":41419628},{"atb":[[36,0],[46,0]],"id":41419626},{"atb":[[22,0],[27,0]],"id":41419639},{"atb":[[170,0],[120,0]],"id":41419604},{"atb":[[36,0],[28,0]],"id":41419610},{"atb":[[65,0],[90,0]],"id":41419625},{"atb":[[17.5,0],[15,0]],"id":41419590},{"atb":[[65,3.12],[46,0]],"id":41419621},{"atb":[[34,0],[44,0]],"id":41419633},{"atb":[[40,0],[50,0]],"id":41419596},{"atb":[[36,0],[28,0]],"id":41419627},{"atb":[[25,0],[30,0]],"id":41419594}],"con":true,"img":false}]}
{"op":"mcm","clk":"5353431895","pt":1646214842829,"mc":[{"id":"1.195503866","rc":[{"atb":[[130,0],[90,0]],"id":41419629}],"con":true,"img":false}]}
{"op":"mcm","clk":"5353431909","pt":1646214843086,"mc":[{"id":"1.195503866","rc":[{"atb":[[32,3.23],[34,0]],"id":41419628}],"con":true,"img":false}]}
{"op":"mcm","clk":"5353431922","pt":1646214843393,"mc":[{"id":"1.195503866","rc":[{"atb":[[16.5,3.26],[19,2.72]],"id":41419589},{"atb":[[40,2.72],[30,3.26]],"id":41419620},{"atb":[[70,3.26],[95,2.72]],"id":41419632},{"atb":[[42,3.26],[55,2.72]],"id":41419630},{"atb":[[65,2.72],[46,3.26]],"id":41419628},{"atb":[[38,3.26],[48,2.72]],"id":41419626},{"atb":[[23,3.26],[28,10.12]],"id":41419639},{"atb":[[130,3.26],[180,2.72]],"id":41419604},{"atb":[[38,8.12],[29,3.26]],"id":41419610},{"atb":[[70,3.26],[95,2.72]],"id":41419625},{"atb":[[18,2.72],[15.5,3.26]],"id":41419590},{"atb":[[70,2.72],[48,3.26]],"id":41419621},{"atb":[[36,3.26],[46,2.72]],"id":41419633},{"atb":[[42,3.26],[55,2.72]],"id":41419596},{"atb":[[38,2.72],[29,3.26]],"id":41419627},{"atb":[[24,11.95],[29,2.72]],"id":41419594}],"con":true,"img":false}]}
{"op":"mcm","clk":"5353431935","pt":1646214843703,"mc":[{"id":"1.195503866","rc":[{"atb":[[22,3.26],[27,10.4]],"id":41419640},{"atb":[[140,2.72],[95,3.26]],"id":41419629}],"con":true,"img":false}]}
{"op":"mcm","clk":"5353432079","pt":1646214846588,"mc":[{"id":"1.195503866","rc":[{"atl":[[540,2],[550,0]],"id":41419594}],"con":true,"img":false}]}
{"op":"mcm","clk":"5353432085","pt":1646214846692,"mc":[{"id":"1.195503866","rc":[{"atl":[[470,2],[480,0]],"id":41419635}],"con":true,"img":false}]}
{"op":"mcm","clk":"5353434203","pt":1646214887504,"mc":[{"id":"1.195503866","rc":[{"atb":[[12.5,0]],"id":41419637}],"con":true,"img":false}]}
{"op":"mcm","clk":"5353434218","pt":1646214887763,"mc":[{"id":"1.195503866","rc":[{"atb":[[10,0]],"id":41419637}],"con":true,"img":false}]}
{"op":"mcm","clk":"5353434243","pt":1646214888174,"mc":[{"id":"1.195503866","rc":[{"atb":[[13,2.72]],"id":41419637}],"con":true,"img":false}]}
{"op":"mcm","clk":"5353434259","pt":1646214888482,"mc":[{"id":"1.195503866","rc":[{"atb":[[10.5,3.26]],"id":41419637}],"con":true,"img":false}]}
{"op":"mcm","clk":"5353436017","pt":1646214921939,"mc":[{"id":"1.195503866","rc":[{"atb":[[6,0],[7,0]],"id":41419591}],"con":true,"img":false}]}
{"op":"mcm","clk":"5353436048","pt":1646214922660,"mc":[{"id":"1.195503866","rc":[{"atb":[[6.8,2.72],[5.9,3.26]],"id":41419591}],"con":true,"img":false}]}
{"op":"mcm","clk":"5353438397","pt":1646214963013,"mc":[{"id":"1.195503866","rc":[{"atl":[[1000,0]],"id":41419593},{"atb":[[5.7,21.28],[6.6,0]],"id":41419592},{"atb":[[7.2,16.13],[8.6,0]],"id":41419590},{"atl":[[540,0],[550,2]],"id":41419594}],"con":true,"img":false}]}
{"op":"mcm","clk":"5353457247","pt":1646215269321,"mc":[{"id":"1.195503866","rc":[{"atl":[[1000,2]],"id":41419593},{"atl":[[540,2],[550,0]],"id":41419594}],"con":true,"img":false}]}
{"op":"mcm","clk":"5353468582","pt":1646215421653,"mc":[{"id":"1.195503866","rc":[{"atl":[[1000,0]],"id":41419593}],"con":true,"img":false}]}
{"op":"mcm","clk":"5353468807","pt":1646215424590,"mc":[{"id":"1.195503866","rc":[{"atl":[[1000,2]],"id":41419593}],"con":true,"img":false}]}
{"op":"mcm","clk":"5353478361","pt":1646215540082,"mc":[{"id":"1.195503866","rc":[{"atl":[[620,0],[610,2]],"id":41419589},{"atl":[[530,0],[520,2]],"id":41419598},{"atl":[[950,0],[940,2]],"id":41419596}],"con":true,"img":false}]}
{"op":"mcm","clk":"5353478442","pt":1646215541120,"mc":[{"id":"1.195503866","rc":[{"atl":[[560,0]],"id":41419640},{"atl":[[580,2]],"id":41419611},{"atl":[[730,2],[770,0]],"id":41419630},{"atb":[[19,0]],"id":41419597},{"atl":[[860,0]],"id":41419597},{"atb":[[27,0]],"id":41419608},{"atb":[[9.2,0],[12.5,8.7]],"id":41419639},{"atb":[[6.4,18.52],[5.7,0]],"id":41419592},{"atl":[[520,0]],"id":41419590},{"atl":[[730,0],[710,2]],"id":41419633},{"atb":[[12.5,0],[9.8,11.36]],"id":41419627},{"atl":[[730,0],[720,2]],"id":41419627}],"con":true,"img":false}]}
{"op":"mcm","clk":"5353478449","pt":1646215541176,"mc":[{"id":"1.195503866","rc":[{"atl":[[540,2]],"id":41419640},{"atl":[[640,0]],"id":41419611},{"atb":[[16,6.67]],"id":41419597},{"atl":[[830,2]],"id":41419597},{"atb":[[22,4.76]],"id":41419608},{"atl":[[500,2]],"id":41419590}],"con":true,"img":false}]}
{"op":"mcm","clk":"5353478468","pt":1646215541392,"mc":[{"id":"1.195503866","rc":[{"atb":[[10.5,0],[13,0]],"id":41419637},{"atb":[[13,0],[15.5,0]],"id":41419612}],"con":true,"img":false}]}
{"op":"mcm","clk":"5353478527","pt":1646215542177,"mc":[{"id":"1.195503866","rc":[{"atb":[[10,3.26],[12.5,2.72]],"id":41419637},{"atb":[[12.5,3.26],[15,2.72]],"id":41419612}],"con":true,"img":false}]}
{"op":"mcm","clk":"5353495814","pt":1646215738181,"mc":[{"id":"1.195503866","rc":[{"atl":[[540,0],[530,2]],"id":41419640}],"con":true,"img":false}]}
{"op":"mcm","clk":"5353496529","pt":1646215746711,"mc":[{"id":"1.195503866","rc":[{"atb":[[22,0],[27,7.68]],"id":41419640}],"con":true,"img":false}]}
{"op":"mcm","clk":"5353496598","pt":1646215747498,"mc":[{"id":"1.195503866","rc":[{"atb":[[21,3.26],[26,2.72]],"id":41419640}],"con":true,"img":false}]}
{"op":"mcm","clk":"5353497390","pt":1646215756616,"mc":[{"id":"1.195503866","rc":[{"atb":[[21,0],[26,0]],"id":41419640}],"con":true,"img":false}]}
{"op":"mcm","clk":"5353497452","pt":1646215757342,"mc":[{"id":"1.195503866","rc":[{"atb":[[22,3.26],[27,10.4]],"id":41419640}],"con":true,"img":false}]}
{"op":"mcm","clk":"5353499296","pt":1646215779668,"mc":[{"id":"1.195503866","rc":[{"atb":[[16,0],[11,0],[27,2.72]],"id":41419640},{"atb":[[22,0],[13.5,0],[9.4,0]],"id":41419607},{"atb":[[65,3.26],[19,0],[28,3.7]],"id":41419605},{"atb":[[17,0],[48,0],[24,0]],"id":41419636},{"atb":[[600,0],[750,0],[500,0]],"id":41419603},{"atb":[[4.5,0],[6,0],[3.75,0]],"id":41419634},{"atb":[[36,2.72],[19,0],[14,0]],"id":41419611},{"atb":[[90,0],[46,0],[230,0]],"id":41419593},{"atb":[[3.45,0],[3.95,0],[5.4,0]],"id":41419591},{"atb":[[570,0],[720,0],[470,0]],"id":41419622},{"atb":[[9,0],[20,0],[12.5,0]],"id":41419589},{"atb":[[16,0],[11,0],[27,0]],"id":41419620},{"atb":[[7.4,0],[5.2,0],[4.2,0]],"id":41419587},{"atb":[[40,0],[100,0],[25,0]],"id":41419601},{"atb":[[80,0],[42,0],[210,0]],"id":41419632},{"atb":[[17,0],[48,0],[24,0]],"id":41419599},{"atb":[[40,0],[20,0],[15,0]],"id":41419630},{"atb":[[18,0],[26,0],[55,0]],"id":41419597},{"atb":[[18.5,0],[27,0],[60,0]],"id":41419628},{"atb":[[32,0],[18,0],[13,8.33]],"id":41419626},{"atb":[[32,0],[80,0],[21,0]],"id":41419608},{"atb":[[16.5,0],[11.5,0],[28,2.72]],"id":41419639},{"atb":[[4.8,0],[8.6,0],[5.8,0]],"id":41419606},{"atb":[[6.8,0],[9.8,0],[5.4,0]],"id":41419637},{"atb":[[540,0],[690,0],[440,0]],"id":41419604},{"atb":[[17,0],[9.8,0],[7.8,0]],"id":41419635},{"atb":[[11,0],[7.4,0],[5.7,0]],"id":41419585},{"atb":[[11,0],[7.4,0],[5.7,0]],"id":41419612},{"atb":[[38,2.72],[19.5,0],[14.5,0]],"id":41419610},{"atb":[[80,0],[42,0],[210,0]],"id":41419625},{"atb":[[9,0],[7,0],[15,0]],"id":41419592},{"atb":[[42,3.26],[21,0],[15.5,0]],"id":41419623},{"atb":[[19.5,0],[12,0],[8.8,0]],"id":41419590},{"atb":[[65,0],[19,0],[28,3.7]],"id":41419621},{"atb":[[36,0],[19,0],[14,0]],"id":41419586},{"atb":[[17.5,0],[12.5,0],[30,0]],"id":41419633},{"atb":[[270,0],[120,0],[60,0]],"id":41419600},{"atb":[[18.5,0],[11,0],[8.4,0]],"id":41419598},{"atb":[[660,0],[410,0],[510,0]],"id":41419629},{"atb":[[18.5,0],[27,0],[60,0]],"id":41419596},{"atb":[[10.5,0],[26,0],[15.5,0]],"id":41419627},{"atb":[[24,3.26],[9.8,0],[14.5,0]],"id":41419594}],"con":true,"img":false}]}
{"op":"mcm","clk":"5353499458","pt":1646215781731,"mc":[{"id":"1.195503866","rc":[{"atl":[[710,2]],"id":41419627}],"con":true,"img":false}]}
{"op":"mcm","clk":"5353499462","pt":1646215781842,"mc":[{"id":"1.195503866","rc":[{"atl":[[720,0]],"id":41419627}],"con":true,"img":false}]}
{"op":"mcm","clk":"5353499632","pt":1646215784083,"mc":[{"id":"1.195503866","rc":[{"atb":[[7.4,41.62],[13.5,10.65],[5.7,56.67]],"id":41419607},{"atb":[[9.6,30.97],[28,8.63],[14,20.49]],"id":41419605},{"atb":[[600,0.22],[300,0.88],[400,0.67]],"id":41419603},{"atb":[[19,14.8],[90,1.49],[28,9.86]],"id":41419593},{"atb":[[3.95,45.15],[2.98,134.54],[2.78,149.65]],"id":41419591},{"atb":[[5.5,59.19],[12.5,11.58],[7,44.4]],"id":41419589},{"atb":[[3.6,102.45],[3.1,126.85],[5.2,31.71]],"id":41419587},{"atb":[[17.5,16.14],[40,3.41],[12.5,23.16]],"id":41419601},{"atb":[[24,5.79],[12,24.21],[8.8,34.15]],"id":41419599},{"atb":[[9.2,32.48],[26,5.32],[13,22.19]],"id":41419597},{"atb":[[32,4.29],[10.5,28.03],[15.5,18.37]],"id":41419608},{"atb":[[5.8,27.75],[3.4,110.99],[3.9,91.85]],"id":41419606},{"atb":[[540,0.24],[340,0.78],[240,1.11]],"id":41419604},{"atb":[[3.85,93.47],[7.4,20.81],[4.7,71.99]],"id":41419585},{"atb":[[9,16.64],[4.5,76.11],[5.5,59.19]],"id":41419592},{"atb":[[12,12.1],[6.8,45.93],[5.4,60.54]],"id":41419590},{"atb":[[9.6,30.97],[19,7.4],[7.6,40.36]],"id":41419586},{"atb":[[34,8.07],[22,12.68],[120,1.11]],"id":41419600},{"atb":[[6.4,49.33],[11,13.31],[5.2,63.42]],"id":41419598},{"atb":[[27,5.12],[13.5,21.3],[9.4,31.71]],"id":41419596},{"atb":[[7.8,39.17],[14.5,9.86],[5.9,54.36]],"id":41419594}],"con":true,"img":false}]}
{"op":"mcm","clk":"5353499644","pt":1646215784198,"mc":[{"id":"1.195503866","rc":[{"atb":[[16,8.87],[6.4,49.33],[8.4,35.99]],"id":41419640},{"atb":[[24,5.79],[12,24.21],[8.8,34.15]],"id":41419636},{"atb":[[4.5,38.05],[2.9,140.2],[3.25,118.39]],"id":41419634},{"atb":[[9.6,30.97],[19,7.4],[7.6,40.36]],"id":41419611},{"atb":[[270,0.99],[570,0.23],[370,0.71]],"id":41419622},{"atb":[[16,8.87],[6.4,49.33],[8.4,35.99]],"id":41419620},{"atb":[[18,15.66],[80,1.68],[26,10.65]],"id":41419632},{"atb":[[8,38.05],[20,7],[10,29.59]],"id":41419630},{"atb":[[27,5.12],[13.5,21.3],[9.4,31.71]],"id":41419628},{"atb":[[7.2,42.96],[18,7.83],[9.2,32.48]],"id":41419626},{"atb":[[16.5,8.59],[8.6,35.05],[6.6,47.57]],"id":41419639},{"atb":[[3.7,98.66],[6.8,22.96],[4.4,78.34]],"id":41419637},{"atb":[[9.8,15.13],[4.9,68.3],[5.9,54.36]],"id":41419635},{"atb":[[3.85,93.47],[7.4,20.81],[4.7,71.99]],"id":41419612},{"atb":[[19.5,7.19],[9.8,30.27],[7.8,39.17]],"id":41419610},{"atb":[[18,15.66],[80,1.68],[26,10.65]],"id":41419625},{"atb":[[21,6.65],[10.5,28.03],[8.2,36.99]],"id":41419623},{"atb":[[9.6,30.97],[28,8.63],[14,20.49]],"id":41419621},{"atb":[[17.5,8.07],[9,33.29],[7,44.4]],"id":41419633},{"atb":[[310,0.86],[210,1.27],[510,0.26]],"id":41419629},{"atb":[[6.2,51.22],[8.2,36.99],[15.5,9.18]],"id":41419627}],"con":true,"img":false}]}
{"op":"mcm","clk":"5353509546","pt":1646215903495,"mc":[{"id":"1.195503866","rc":[{"atb":[[8.8,0]],"id":41419589},{"atb":[[13.5,0]],"id":41419632},{"atb":[[16,6.67],[13,0]],"id":41419626},{"atb":[[5.3,23.26]],"id":41419585},{"atb":[[11.5,0]],"id":41419610},{"atb":[[13.5,0]],"id":41419623},{"atl":[[710,0]],"id":41419627}],"con":true,"img":false}]}
{"op":"mcm","clk":"5353509556","pt":1646215903602,"mc":[{"id":"1.195503866","rc":[{"atb":[[10.5,10.53]],"id":41419589},{"atb":[[18,21.54]],"id":41419632},{"atl":[[1000,2]],"id":41419599},{"atl":[[890,0],[880,2]],"id":41419608},{"atb":[[4.8,0]],"id":41419585},{"atb":[[16.5,6.45]],"id":41419610},{"atb":[[18,21.54],[13.5,0]],"id":41419625},{"atb":[[18,5.88]],"id":41419623},{"atb":[[11,0],[14,7.69]],"id":41419586},{"atl":[[650,2],[720,0]],"id":41419586},{"atl":[[680,2]],"id":41419627}],"con":true,"img":false}]}
{"op":"mcm","clk":"5353509565","pt":1646215903707,"mc":[{"id":"1.195503866","rc":[{"atb":[[10.5,10.53]],"id":41419586}],"con":true,"img":false}]}
{"op":"mcm","clk":"5353509578","pt":1646215903808,"mc":[{"id":"1.195503866","rc":[{"atb":[[14,0]],"id":41419586}],"con":true,"img":false}]}
{"op":"mcm","clk":"5353509590","pt":1646215903911,"mc":[{"id":"1.195503866","rc":[{"atb":[[12.5,0],[15,0]],"id":41419612}],"con":true,"img":false}]}
{"op":"mcm","clk":"5353509621","pt":1646215904279,"mc":[{"id":"1.195503866","rc":[{"atb":[[10,0],[12.5,0]],"id":41419637}],"con":true,"img":false}]}
{"op":"mcm","clk":"5353509645","pt":1646215904589,"mc":[{"id":"1.195503866","rc":[{"atb":[[13,3.26],[15.5,2.72]],"id":41419612}],"con":true,"img":false}]}
{"op":"mcm","clk":"5353509682","pt":1646215905003,"mc":[{"id":"1.195503866","rc":[{"atb":[[10.5,3.26],[13,2.72]],"id":41419637}],"con":true,"img":false}]}
{"op":"mcm","clk":"5353509742","pt":1646215905679,"mc":[{"id":"1.195503866","rc":[{"atb":[[10.5,0],[13,0]],"id":41419637}],"con":true,"img":false}]}
{"op":"mcm","clk":"5353509803","pt":1646215906411,"mc":[{"id":"1.195503866","rc":[{"atb":[[10,3.26],[12.5,2.72]],"id":41419637}],"con":true,"img":false}]}
{"op":"mcm","clk":"5353517667","pt":1646215985506,"mc":[{"id":"1.195503866","rc":[{"atb":[[12.5,0]],"id":41419637}],"con":true,"img":false}]}
{"op":"mcm","clk":"5353517689","pt":1646215985821,"mc":[{"id":"1.195503866","rc":[{"atb":[[10,0]],"id":41419637}],"con":true,"img":false}]}
{"op":"mcm","clk":"5353517730","pt":1646215986196,"mc":[{"id":"1.195503866","rc":[{"atb":[[13,2.72]],"id":41419637}],"con":true,"img":false}]}
{"op":"mcm","clk":"5353517757","pt":1646215986502,"mc":[{"id":"1.195503866","rc":[{"atb":[[10.5,3.26]],"id":41419637}],"con":true,"img":false}]}
{"op":"mcm","clk":"5353522619","pt":1646216039626,"mc":[{"id":"1.195503866","rc":[{"atb":[[16,0],[6.4,0],[8.4,0]],"id":41419640},{"atb":[[7.4,0],[13.5,0],[5.7,0]],"id":41419607},{"atb":[[9.6,0],[28,3.7],[14,0]],"id":41419605},{"atb":[[24,0],[12,0],[8.8,0]],"id":41419636},{"atb":[[600,0],[300,0],[400,0]],"id":41419603},{"atb":[[4.5,0],[2.9,0],[3.25,0]],"id":41419634},{"atb":[[9.6,0],[19,0],[7.6,0]],"id":41419611},{"atb":[[19,0],[90,0],[28,0]],"id":41419593},{"atb":[[3.95,0],[2.98,0],[2.78,0]],"id":41419591},{"atb":[[270,0],[570,0],[370,0]],"id":41419622},{"atb":[[5.5,0],[12.5,0],[7,0]],"id":41419589},{"atb":[[16,0],[6.4,0],[8.4,0]],"id":41419620},{"atb":[[3.6,0],[3.1,0],[5.2,0]],"id":41419587},{"atb":[[17.5,0],[40,0],[12.5,0]],"id":41419601},{"atb":[[18,5.88],[80,0],[26,0]],"id":41419632},{"atb":[[24,0],[12,0],[8.8,0]],"id":41419599},{"atb":[[8,0],[20,0],[10,0]],"id":41419630},{"atb":[[9.2,0],[26,0],[13,0]],"id":41419597},{"atb":[[27,0],[13.5,0],[9.4,0]],"id":41419628},{"atb":[[7.2,0],[18,0],[9.2,0]],"id":41419626},{"atb":[[32,0],[10.5,0],[15.5,0]],"id":41419608},{"atb":[[16.5,0],[8.6,0],[6.6,0]],"id":41419639},{"atb":[[5.8,0],[3.4,0],[3.9,0]],"id":41419606},{"atb":[[3.7,0],[6.8,0],[4.4,0]],"id":41419637},{"atb":[[540,0],[340,0],[240,0]],"id":41419604},{"atb":[[9.8,0],[4.9,0],[5.9,0]],"id":41419635},{"atb":[[3.85,0],[7.4,0],[4.7,0]],"id":41419585},{"atb":[[3.85,0],[7.4,0],[4.7,0]],"id":41419612},{"atb":[[19.5,0],[9.8,0],[7.8,0]],"id":41419610},{"atb":[[18,5.88],[80,0],[26,0]],"id":41419625},{"atb":[[9,0],[4.5,0],[5.5,0]],"id":41419592},{"atb":[[21,0],[10.5,0],[8.2,0]],"id":41419623},{"atb":[[12,0],[6.8,0],[5.4,0]],"id":41419590},{"atb":[[9.6,0],[28,3.7],[14,0]],"id":41419621},{"atb":[[9.6,0],[19,0],[7.6,0]],"id":41419586},{"atb":[[17.5,0],[9,0],[7,0]],"id":41419633},{"atb":[[34,0],[22,0],[120,0]],"id":41419600},{"atb":[[6.4,0],[11,0],[5.2,0]],"id":41419598},{"atb":[[310,0],[210,0],[510,0]],"id":41419629},{"atb":[[27,0],[13.5,0],[9.4,0]],"id":41419596},{"atb":[[6.2,0],[8.2,0],[15.5,0]],"id":41419627},{"atb":[[7.8,0],[14.5,0],[5.9,0]],"id":41419594}],"con":true,"img":false}]}
{"op":"mcm","clk":"5353522745","pt":1646216041094,"mc":[{"id":"1.195503866","rc":[{"atb":[[19,14.46]],"id":41419636},{"atl":[[850,1.43]],"id":41419636},{"atb":[[160,4.95],[120,9.9]],"id":41419622},{"atb":[[18,15.6]],"id":41419625},{"atb":[[28,12.6]],"id":41419621},{"atb":[[7.2,25.03]],"id":41419598},{"atl":[[540,2.27]],"id":41419598},{"atb":[[7.4,24.52]],"id":41419594},{"atl":[[560,2.19]],"id":41419594}],"con":true,"img":false}]}
{"op":"mcm","clk":"5353522751","pt":1646216041199,"mc":[{"id":"1.195503866","rc":[{"atb":[[18.5,9.9],[21,4.95],[7.8,23.61]],"id":41419640},{"atl":[[520,0.3],[550,2.23],[44,4.95],[55,9.9]],"id":41419640},{"atb":[[18.5,9.9],[21,8.22],[7.8,23.61]],"id":41419607},{"atl":[[540,2.27],[44,4.95],[55,9.9],[510,0.31]],"id":41419607},{"atb":[[150,4.95],[95,1.68],[110,9.9],[28,13.42]],"id":41419605},{"atl":[[1000,0.15]],"id":41419605},{"atb":[[42,3.86],[46,9.9],[60,4.95]],"id":41419636},{"atl":[[130,4.95],[820,0.19]],"id":41419636},{"atb":[[40,10.08],[160,4.95],[190,0.83],[120,9.9]],"id":41419603},{"atb":[[8.6,11.63],[9,4.95],[8.2,9.9],[3.9,43.38]],"id":41419634},{"atl":[[16.5,9.9],[310,0.51],[340,3.61],[14.5,4.95]],"id":41419634},{"atb":[[24,9.9],[28,8.22],[8.4,22.41]],"id":41419611},{"atl":[[70,4.95],[570,0.27],[600,2.04],[90,9.9]],"id":41419611},{"atb":[[34,11.57],[80,2],[90,9.9],[120,4.95]],"id":41419593},{"atl":[[240,4.95],[990,0.15]],"id":41419593},{"atb":[[8,4.95],[7.2,9.9],[6.8,11.63],[3.65,46.64]],"id":41419591},{"atl":[[310,0.51],[340,3.61],[12,4.95],[14,9.9]],"id":41419591},{"atb":[[150,1.06],[38,10.08]],"id":41419622},{"atl":[[1000,0.15]],"id":41419622},{"atb":[[19.5,8.56],[10.5,19.43],[22,9.9],[26,4.95]],"id":41419589},{"atl":[[600,0.26],[630,1.94],[80,4.95],[100,9.9]],"id":41419589},{"atb":[[42,13.77],[50,4.95],[14,16.59]],"id":41419620},{"atl":[[770,0.2],[800,1.53],[120,4.95]],"id":41419620},{"atb":[[7.6,8.22],[3.8,44.61],[6.8,9.9]],"id":41419587},{"atl":[[310,0.51],[340,3.61],[12,4.95],[14,9.9]],"id":41419587},{"atb":[[36,11.36],[90,9.9],[120,6.28]],"id":41419601},{"atl":[[1000,0.15]],"id":41419601},{"atb":[[18,15.6],[160,4.95],[100,1.6],[120,9.9]],"id":41419632},{"atl":[[1000,0.15]],"id":41419632},{"atb":[[36,11.15],[80,2],[85,9.9],[110,4.95]],"id":41419599},{"atl":[[230,4.95],[990,0.15]],"id":41419599},{"atb":[[36,4.95],[12.5,17.6],[29,9.9]],"id":41419630},{"atl":[[750,1.63],[120,4.95]],"id":41419630},{"atb":[[16,15.57],[42,9.9],[50,10.91]],"id":41419597},{"atl":[[130,4.95],[820,0.19],[850,1.43]],"id":41419597},{"atb":[[32,12.07],[70,2.29],[75,9.9],[95,4.95]],"id":41419628},{"atl":[[200,4.95],[950,0.16],[980,1.24]],"id":41419628},{"atb":[[16,15.57],[44,9.9],[50,3.23],[55,4.95]],"id":41419626},{"atl":[[130,4.95],[780,0.2],[810,1.51]],"id":41419626},{"atb":[[70,4.95],[22,13.66],[50,9.9],[60,2.68]],"id":41419608},{"atl":[[150,4.95],[870,0.17],[900,1.36]],"id":41419608},{"atb":[[38,4.95],[12.5,17.6],[29,5.66],[30,9.9]],"id":41419639},{"atl":[[660,0.23],[690,1.77],[100,4.95]],"id":41419639},{"atb":[[4.3,39.2],[9,9.9],[9.8,4.95]],"id":41419606},{"atl":[[19.5,4.95],[350,0.45],[23,9.9],[380,3.23]],"id":41419606},{"atb":[[4.5,37.47],[9,9.9],[9.8,4.95]],"id":41419637},{"atl":[[19,4.95],[310,0.51],[340,3.61],[22,9.9]],"id":41419637},{"atb":[[40,10.08],[160,4.95],[190,0.83],[120,9.9]],"id":41419604},{"atl":[[1000,0.15]],"id":41419604},{"atb":[[16.5,9.9],[18,11.63],[18.5,4.95],[6.4,27.42]],"id":41419635},{"atl":[[36,4.95],[44,9.9],[460,0.34],[490,2.5]],"id":41419635},{"atb":[[5.3,32.16],[11,9.9],[11.5,11.63],[13,4.95]],"id":41419585},{"atl":[[24,4.95],[420,0.37],[28,9.9],[450,2.73]],"id":41419585},{"atb":[[4.8,35.22],[9.6,9.9],[11,4.95]],"id":41419612},{"atl":[[360,0.44],[390,3.15],[25,4.95],[29,9.9]],"id":41419612},{"atb":[[16.5,15.35],[40,4.06],[46,9.9],[60,4.95]],"id":41419610},{"atl":[[740,0.21],[770,1.59],[120,4.95]],"id":41419610},{"atb":[[130,4.95],[95,12.63],[100,1.6]],"id":41419625},{"atl":[[1000,0.15]],"id":41419625},{"atb":[[16,9.9],[18,8.22],[6.4,27.42]],"id":41419592},{"atl":[[530,2.31],[34,4.95],[42,9.9],[500,0.31]],"id":41419592},{"atb":[[18,14.78],[46,9.9],[55,5.66],[60,4.95]],"id":41419623},{"atl":[[140,4.95],[810,0.19],[840,1.46]],"id":41419623},{"atb":[[7.2,25.03],[18,21.53],[20,4.95]],"id":41419590},{"atl":[[520,2.35],[34,4.95],[42,9.9],[490,0.32]],"id":41419590},{"atb":[[75,2.14],[85,9.9],[110,4.95]],"id":41419621},{"atl":[[990,0.15]],"id":41419621},{"atb":[[32,4.95],[10.5,19.43],[27,9.9],[30,5.46]],"id":41419586},{"atl":[[75,4.95],[640,0.25],[670,1.83],[95,9.9]],"id":41419586},{"atb":[[36,8.22],[10,20.01],[29,9.9]],"id":41419633},{"atl":[[85,4.95],[700,0.22],[730,1.67],[110,9.9]],"id":41419633},{"atb":[[140,1.13],[38,10.78],[160,4.95],[120,9.9]],"id":41419600},{"atl":[[1000,0.15]],"id":41419600},{"atb":[[18,9.9],[20,8.22]],"id":41419598},{"atl":[[42,4.95],[50,9.9],[510,0.31]],"id":41419598},{"atb":[[150,1.06],[38,10.08],[160,4.95],[120,9.9]],"id":41419629},{"atl":[[1000,0.15]],"id":41419629},{"atb":[[32,12.07],[80,9.9],[100,4.95],[60,2.68]],"id":41419596},{"atl":[[930,0.16],[240,4.95],[960,1.27]],"id":41419596},{"atb":[[34,4.95],[38,7],[9.8,20.26],[28,9.9]],"id":41419627},{"atl":[[80,4.95],[670,0.23],[700,1.75],[100,9.9]],"id":41419627},{"atb":[[18.5,9.9],[21,4.95]],"id":41419594},{"atl":[[530,0.29],[75,9.9],[55,4.95]],"id":41419594}],"con":true,"img":false}]}
{"op":"mcm","clk":"5353522761","pt":1646216041262,"mc":[{"id":"1.195503866","rc":[{"atl":[[830,0],[840,2]],"id":41419636},{"atl":[[720,0.21]],"id":41419630},{"atl":[[520,0],[540,4.27]],"id":41419598}],"con":true,"img":false}]}
{"op":"mcm","clk":"5353522770","pt":1646216041409,"mc":[{"id":"1.195503866","rc":[{"atl":[[530,0],[140,2]],"id":41419640},{"atl":[[520,0],[130,2]],"id":41419607},{"atb":[[36,2.86],[28,9.72]],"id":41419605},{"atl":[[34,3.03],[320,0]],"id":41419634},{"atl":[[580,0],[190,2]],"id":41419611},{"atl":[[870,2],[1000,0]],"id":41419593},{"atl":[[34,3.03],[320,0]],"id":41419591},{"atl":[[280,2],[610,0]],"id":41419589},{"atl":[[780,0],[430,2]],"id":41419620},{"atl":[[34,3.03],[320,0]],"id":41419587},{"atl":[[790,2],[1000,0]],"id":41419599},{"atl":[[340,2],[730,0]],"id":41419630},{"atl":[[830,0],[440,2]],"id":41419597},{"atl":[[580,2],[960,0]],"id":41419628},{"atl":[[790,0],[440,2]],"id":41419626},{"atl":[[880,0],[480,2]],"id":41419608},{"atl":[[670,0],[380,2]],"id":41419639},{"atl":[[360,0],[44,2.33]],"id":41419606},{"atl":[[36,2.86],[320,0]],"id":41419637},{"atl":[[100,2],[470,0]],"id":41419635},{"atl":[[430,0]],"id":41419585},{"atl":[[370,0],[46,2.22]],"id":41419612},{"atl":[[750,0],[440,2]],"id":41419610},{"atl":[[110,2],[510,0]],"id":41419592},{"atl":[[820,0],[460,2]],"id":41419623},{"atl":[[100,2],[500,0]],"id":41419590},{"atl":[[650,0],[250,2]],"id":41419586},{"atl":[[320,2],[710,0]],"id":41419633},{"atl":[[850,2],[940,0]],"id":41419596},{"atl":[[280,2],[680,0]],"id":41419627},{"atl":[[540,0],[140,2]],"id":41419594}],"con":true,"img":false}]}
{"op":"mcm","clk":"5353522776","pt":1646216041480,"mc":[{"id":"1.195503866","rc":[{"atl":[[70,2]],"id":41419585}],"con":true,"img":false}]}
{"op":"mcm","clk":"5353522792","pt":1646216041675,"mc":[{"id":"1.195503866","rc":[{"atl":[[1000,1.22]],"id":41419593}],"con":true,"img":false}]}
{"op":"mcm","clk":"5353522812","pt":1646216041881,"mc":[{"id":"1.195503866","rc":[{"atb":[[21,9.9],[25,4.95]],"id":41419589},{"atl":[[85,0],[90,4.95],[110,0],[120,9.9]],"id":41419633}],"con":true,"img":false}]}
{"op":"mcm","clk":"5353522823","pt":1646216041988,"mc":[{"id":"1.195503866","rc":[{"atl":[[70,0],[75,4.95],[90,0],[95,9.9]],"id":41419611},{"atb":[[22,0],[26,0]],"id":41419589},{"atl":[[1000,1.22]],"id":41419599}],"con":true,"img":false}]}
{"op":"mcm","clk":"5353522931","pt":1646216043199,"mc":[{"id":"1.195503866","rc":[{"atb":[[9.8,11.36],[7.8,8.9]],"id":41419640},{"atb":[[11.5,9.52],[7.8,8.9]],"id":41419607},{"atb":[[19,8.9],[23,4.55]],"id":41419636},{"atb":[[40,8.08],[60,2]],"id":41419603},{"atb":[[5,25],[3.9,8.9]],"id":41419634},{"atb":[[11,10],[8.4,8.9]],"id":41419611},{"atb":[[34,8.54],[48,2.13]],"id":41419593},{"atb":[[4.6,27.78],[3.65,8.9]],"id":41419591},{"atb":[[38,8.08]],"id":41419622},{"atb":[[10.5,8.9],[15.5,6.9]],"id":41419589},{"atb":[[22,4.76],[14,8.9]],"id":41419620},{"atb":[[4.6,27.78],[3.8,8.9]],"id":41419587},{"atb":[[36,8.5],[50,2.04]],"id":41419601},{"atb":[[36,8.29],[48,2.13]],"id":41419599},{"atb":[[12.5,8.9],[15,7.14]],"id":41419630},{"atb":[[16,8.9],[23,4.55]],"id":41419597},{"atb":[[32,8.84],[44,2.33]],"id":41419628},{"atb":[[22,8.9],[28,3.7]],"id":41419608},{"atb":[[17.5,6.06],[12.5,8.9]],"id":41419639},{"atb":[[4.3,8.9],[5.5,22.22]],"id":41419606},{"atb":[[4.5,8.9],[6,20]],"id":41419637},{"atb":[[40,8.08],[55,2]],"id":41419604},{"atb":[[6.4,8.9],[9.8,11.36]],"id":41419635},{"atb":[[7.2,16.13],[5.3,8.9]],"id":41419585},{"atb":[[4.8,8.9],[6.4,18.52]],"id":41419612},{"atb":[[6.4,8.9],[8.4,13.51]],"id":41419592},{"atb":[[7.2,8.9],[9.8,11.36]],"id":41419590},{"atb":[[48,5.39],[28,8.9]],"id":41419621},{"atb":[[10.5,8.9],[15,7.14]],"id":41419586},{"atb":[[10,8.9],[13.5,8]],"id":41419633},{"atb":[[38,8.08],[55,2]],"id":41419600},{"atb":[[7.2,8.9],[9.8,11.36]],"id":41419598},{"atb":[[38,8.08],[50,2.04]],"id":41419629},{"atb":[[32,8.84],[48,2.13]],"id":41419596},{"atb":[[16,6.67],[9.8,8.9]],"id":41419627},{"atb":[[10,11.11],[7.4,8.9]],"id":41419594}],"con":true,"img":false}]}
{"op":"mcm","clk":"5353522939","pt":1646216043302,"mc":[{"id":"1.195503866","rc":[{"atb":[[16,8.87],[6.4,49.33],[8.4,35.99]],"id":41419640},{"atb":[[7.4,41.62],[13.5,10.65],[5.7,56.67]],"id":41419607},{"atb":[[9.6,30.97],[28,14.65],[14,20.49]],"id":41419605},{"atb":[[24,5.79],[12,24.21],[8.8,34.15]],"id":41419636},{"atb":[[600,0.22],[300,0.88],[400,0.67]],"id":41419603},{"atb":[[4.5,38.05],[2.9,140.2],[3.25,118.39]],"id":41419634},{"atb":[[9.6,30.97],[19,7.4],[7.6,40.36]],"id":41419611},{"atb":[[19,14.8],[90,11.4],[28,9.86]],"id":41419593},{"atb":[[3.95,45.15],[2.98,134.54],[2.78,149.65]],"id":41419591},{"atb":[[270,0.99],[570,0.23],[370,0.71],[50,2.04]],"id":41419622},{"atb":[[5.5,59.19],[12.5,11.58],[7,44.4]],"id":41419589},{"atb":[[16,8.87],[6.4,49.33],[8.4,35.99]],"id":41419620},{"atb":[[3.6,102.45],[3.1,126.85],[5.2,31.71]],"id":41419587},{"atb":[[17.5,16.14],[40,3.41],[12.5,23.16]],"id":41419601},{"atb":[[18,31.27],[80,1.68],[26,10.65]],"id":41419632},{"atb":[[24,5.79],[12,24.21],[8.8,34.15]],"id":41419599},{"atb":[[8,38.05],[20,7],[10,29.59]],"id":41419630},{"atb":[[9.2,32.48],[26,5.32],[13,22.19]],"id":41419597},{"atb":[[27,5.12],[13.5,21.3],[9.4,31.71]],"id":41419628},{"atb":[[7.2,42.96],[18,7.83],[9.2,32.48]],"id":41419626},{"atb":[[32,4.29],[10.5,28.03],[15.5,18.37]],"id":41419608},{"atb":[[16.5,8.59],[8.6,35.05],[6.6,47.57]],"id":41419639},{"atb":[[5.8,27.75],[3.4,110.99],[3.9,91.85]],"id":41419606},{"atb":[[3.7,98.66],[6.8,22.96],[4.4,78.34]],"id":41419637},{"atb":[[540,0.24],[340,0.78],[240,1.11]],"id":41419604},{"atb":[[9.8,26.49],[4.9,68.3],[5.9,54.36]],"id":41419635},{"atb":[[3.85,93.47],[7.4,20.81],[4.7,71.99]],"id":41419585},{"atb":[[3.85,93.47],[7.4,20.81],[4.7,71.99]],"id":41419612},{"atb":[[19.5,7.19],[9.8,30.27],[7.8,39.17]],"id":41419610},{"atb":[[18,31.27],[80,1.68],[26,10.65]],"id":41419625},{"atb":[[9,16.64],[4.5,76.11],[5.5,59.19]],"id":41419592},{"atb":[[21,6.65],[10.5,28.03],[8.2,36.99]],"id":41419623},{"atb":[[12,12.1],[6.8,45.93],[5.4,60.54]],"id":41419590},{"atb":[[9.6,30.97],[28,13.83],[14,20.49]],"id":41419621},{"atb":[[9.6,30.97],[19,7.4],[7.6,40.36]],"id":41419586},{"atb":[[17.5,8.07],[9,33.29],[7,44.4]],"id":41419633},{"atb":[[34,8.07],[22,12.68],[120,11.02]],"id":41419600},{"atb":[[6.4,49.33],[11,13.31],[5.2,63.42]],"id":41419598},{"atb":[[310,0.86],[210,1.27],[510,0.26]],"id":41419629},{"atb":[[27,5.12],[13.5,21.3],[9.4,31.71]],"id":41419596},{"atb":[[6.2,51.22],[8.2,36.99],[15.5,9.18]],"id":41419627},{"atb":[[7.8,39.17],[14.5,9.86],[5.9,54.36]],"id":41419594}],"con":true,"img":false}]}
{"op":"mcm","clk":"5353522957","pt":1646216043510,"mc":[{"id":"1.195503866","rc":[{"atl":[[250,4.95]],"id":41419621}],"con":true,"img":false}]}
{"op":"mcm","clk":"5353522988","pt":1646216043779,"mc":[{"id":"1.195503866","rc":[{"atb":[[38,0]],"id":41419622},{"atl":[[1000,0]],"id":41419604}],"con":true,"img":false}]}
{"op":"mcm","clk":"5353522999","pt":1646216043878,"mc":[{"id":"1.195503866","rc":[{"atl":[[1000,0]],"id":41419622}],"con":true,"img":false}]}
{"op":"mcm","clk":"5353523030","pt":1646216044192,"mc":[{"id":"1.195503866","rc":[{"atl":[[1000,3.23]],"id":41419621}],"con":true,"img":false}]}
{"op":"mcm","clk":"5353523264","pt":1646216046599,"mc":[{"id":"1.195503866","rc":[{"atl":[[870,0],[990,2.15]],"id":41419593},{"atl":[[770,2.2],[430,0]],"id":41419620},{"atl":[[790,0],[990,2.15]],"id":41419599},{"atl":[[340,0],[720,2.21]],"id":41419630},{"atl":[[820,2.19],[440,0]],"id":41419597},{"atl":[[580,0],[950,2.16]],"id":41419628},{"atl":[[780,2.2],[440,0]],"id":41419626},{"atl":[[870,2.17],[480,0]],"id":41419608},{"atl":[[660,2.23],[380,0]],"id":41419639},{"atl":[[740,2.21],[440,0]],"id":41419610},{"atl":[[810,2.19],[460,0]],"id":41419623},{"atl":[[850,0],[930,2.16]],"id":41419596}],"con":true,"img":false}]}
{"op":"mcm","clk":"5353523432","pt":1646216048584,"mc":[{"id":"1.195503866","rc":[{"atb":[[36,0],[50,2.04]],"id":41419605}],"con":true,"img":false}]}
{"op":"mcm","clk":"5353523572","pt":1646216049998,"mc":[{"id":"1.195503866","rc":[{"atl":[[140,0]],"id":41419623}],"con":true,"img":false}]}
{"op":"mcm","clk":"5353523590","pt":1646216050195,"mc":[{"id":"1.195503866","rc":[{"atl":[[810,0.19],[840,3.46]],"id":41419623}],"con":true,"img":false}]}
{"op":"mcm","clk":"5353523603","pt":1646216050303,"mc":[{"id":"1.195503866","rc":[{"atl":[[150,4.95]],"id":41419623}],"con":true,"img":false}]}
{"op":"mcm","clk":"5353523624","pt":1646216050509,"mc":[{"id":"1.195503866","rc":[{"atl":[[840,1.46],[460,2]],"id":41419623}],"con":true,"img":false}]}
{"op":"mcm","clk":"5353523954","pt":1646216053593,"mc":[{"id":"1.195503866","rc":[{"atl":[[120,0]],"id":41419630}],"con":true,"img":false}]}
{"op":"mcm","clk":"5353523970","pt":1646216053800,"mc":[{"id":"1.195503866","rc":[{"atl":[[720,0.21],[740,2]],"id":41419630}],"con":true,"img":false}]}
{"op":"mcm","clk":"5353523985","pt":1646216053904,"mc":[{"id":"1.195503866","rc":[{"atl":[[130,4.95]],"id":41419630}],"con":true,"img":false}]}
{"op":"mcm","clk":"5353524150","pt":1646216055587,"mc":[{"id":"1.195503866","rc":[{"atl":[[810,2.19],[460,0]],"id":41419623}],"con":true,"img":false}]}
{"op":"mcm","clk":"5353524249","pt":1646216056811,"mc":[{"id":"1.195503866","rc":[{"atl":[[850,0]],"id":41419636},{"atb":[[18,21.54],[95,22.36]],"id":41419625},{"atb":[[28,4.93]],"id":41419621}],"con":true,"img":false}]}
{"op":"mcm","clk":"5353524255","pt":1646216056915,"mc":[{"id":"1.195503866","rc":[{"atb":[[95,11.53]],"id":41419605},{"atb":[[8,27.04],[6.8,33.71]],"id":41419591},{"atl":[[340,0]],"id":41419591},{"atb":[[170,0.93]],"id":41419632},{"atb":[[80,12.57]],"id":41419599},{"atl":[[740,3.71],[750,0]],"id":41419630},{"atb":[[70,13.07],[95,6.63]],"id":41419628},{"atl":[[36,15.07]],"id":41419637},{"atl":[[390,0]],"id":41419612},{"atb":[[140,1.13]],"id":41419625},{"atl":[[530,0]],"id":41419592},{"atb":[[46,24.62]],"id":41419623},{"atb":[[110,6.4]],"id":41419621},{"atl":[[250,7.1]],"id":41419586},{"atb":[[10,0],[29,29.48]],"id":41419633},{"atb":[[170,0.93]],"id":41419600},{"atl":[[510,2.8]],"id":41419598},{"atl":[[700,0]],"id":41419627},{"atb":[[21,17.17]],"id":41419594},{"atl":[[560,0]],"id":41419594}],"con":true,"img":false}]}
{"op":"mcm","clk":"5353524263","pt":1646216057019,"mc":[{"id":"1.195503866","rc":[{"atb":[[7.8,0]],"id":41419640},{"atl":[[550,0]],"id":41419640},{"atb":[[18.5,29.48],[7.8,0]],"id":41419607},{"atl":[[540,0]],"id":41419607},{"atb":[[8.2,31.99]],"id":41419634},{"atl":[[34,25.11],[14.5,16.69]],"id":41419634},{"atb":[[24,29.48],[8.4,0]],"id":41419611},{"atl":[[190,8.71]],"id":41419611},{"atb":[[26,6.34]],"id":41419589},{"atl":[[280,6.55],[630,0],[80,6.95]],"id":41419589},{"atb":[[14,0]],"id":41419620},{"atl":[[120,6.28]],"id":41419620},{"atb":[[3.8,0]],"id":41419587},{"atb":[[100,11.33]],"id":41419632},{"atl":[[130,6.18]],"id":41419597},{"atb":[[70,7.25]],"id":41419608},{"atb":[[38,9.23]],"id":41419639},{"atb":[[9.8,17.17]],"id":41419637},{"atl":[[19,13.76]],"id":41419637},{"atb":[[5.3,0],[13,18.16]],"id":41419585},{"atb":[[11,17.17]],"id":41419612},{"atb":[[15.5,17.98]],"id":41419590},{"atl":[[520,0],[34,9.76]],"id":41419590},{"atb":[[130,8.46]],"id":41419600},{"atl":[[240,5.61]],"id":41419596}],"con":true,"img":false}]}
{"op":"mcm","clk":"5353524300","pt":1646216057692,"mc":[{"id":"1.195503866","rc":[{"atb":[[100,0]],"id":41419625}],"con":true,"img":false}]}
{"op":"mcm","clk":"5353524307","pt":1646216057793,"mc":[{"id":"1.195503866","rc":[{"atb":[[6.8,24.81]],"id":41419591},{"atl":[[600,0]],"id":41419589},{"atb":[[40,14.12]],"id":41419620},{"atl":[[770,2]],"id":41419620},{"atb":[[29,0]],"id":41419639},{"atl":[[310,0]],"id":41419637},{"atb":[[11.5,2.72]],"id":41419585},{"atb":[[75,0]],"id":41419621},{"atb":[[140,0]],"id":41419600}],"con":true,"img":false}]}
{"op":"mcm","clk":"5353524768","pt":1646216063908,"mc":[{"id":"1.195503866","rc":[{"atl":[[230,5.64]],"id":41419599}],"con":true,"img":false}]}
{"op":"mcm","clk":"5353524784","pt":1646216064114,"mc":[{"id":"1.195503866","rc":[{"atl":[[130,11.82]],"id":41419607},{"atb":[[60,14.04]],"id":41419596}],"con":true,"img":false}]}
{"op":"mcm","clk":"5353524793","pt":1646216064219,"mc":[{"id":"1.195503866","rc":[{"atb":[[4.3,0]],"id":41419606}],"con":true,"img":false}]}
{"op":"mcm","clk":"5353525086","pt":1646216065206,"mc":[{"id":"1.195503866","rc":[{"atl":[[820,2]],"id":41419597}],"con":true,"img":false}]}
{"op":"mcm","clk":"5353525255","pt":1646216065642,"mc":[{"id":"1.195503866","rc":[{"atb":[[60,0]],"id":41419608}],"con":true,"img":false}]}
{"op":"mcm","clk":"5353525289","pt":1646216065704,"mc":[{"id":"1.195503866","rc":[{"atb":[[100,9.73]],"id":41419632}],"con":true,"img":false}]}
{"op":"mcm","clk":"5353525475","pt":1646216066513,"mc":[{"id":"1.195503866","rc":[{"atl":[[990,2]],"id":41419599}],"con":true,"img":false}]}
{"op":"mcm","clk":"5353526183","pt":1646216070010,"mc":[{"id":"1.195503866","rc":[{"atb":[[42,16.97]],"id":41419636},{"atl":[[100,14.77]],"id":41419590}],"con":true,"img":false}]}
{"op":"mcm","clk":"5353526225","pt":1646216070345,"mc":[{"id":"1.195503866","rc":[{"atl":[[340,0]],"id":41419634},{"atl":[[490,0]],"id":41419635}],"con":true,"img":false}]}
{"op":"mcm","clk":"5353526240","pt":1646216070402,"mc":[{"id":"1.195503866","rc":[{"atl":[[34,22.6]],"id":41419587}],"con":true,"img":false}]}
{"op":"mcm","clk":"5353526272","pt":1646216070626,"mc":[{"id":"1.195503866","rc":[{"atb":[[11,31.99]],"id":41419585}],"con":true,"img":false}]}
{"op":"mcm","clk":"5353526318","pt":1646216070948,"mc":[{"id":"1.195503866","rc":[{"atb":[[4.5,0]],"id":41419637},{"atb":[[10.5,0]],"id":41419586}],"con":true,"img":false}]}
{"op":"mcm","clk":"5353526364","pt":1646216071138,"mc":[{"id":"1.195503866","rc":[{"atb":[[21,17.17]],"id":41419640},{"atb":[[20,13.29]],"id":41419590},{"atl":[[280,6.55]],"id":41419627}],"con":true,"img":false}]}
{"op":"mcm","clk":"5353526538","pt":1646216071876,"mc":[{"id":"1.195503866","rc":[{"atb":[[28,4.93]],"id":41419605},{"atb":[[19,0]],"id":41419636},{"atl":[[75,7.09]],"id":41419611},{"atb":[[34,0]],"id":41419593},{"atl":[[12,19.36]],"id":41419591},{"atb":[[19.5,28.66]],"id":41419589},{"atl":[[340,0],[12,19.36]],"id":41419587},{"atb":[[36,0]],"id":41419601},{"atb":[[18,21.54]],"id":41419632},{"atb":[[40,15.48]],"id":41419597},{"atl":[[200,5.74]],"id":41419628},{"atb":[[29,14.71]],"id":41419639},{"atl":[[36,9.48],[100,14.77]],"id":41419635},{"atl":[[24,11.84]],"id":41419585},{"atb":[[4.8,0]],"id":41419612},{"atl":[[120,6.28]],"id":41419610},{"atb":[[16,29.48]],"id":41419592},{"atl":[[110,13.6]],"id":41419592},{"atb":[[18,5.88]],"id":41419623},{"atb":[[75,12.15]],"id":41419621},{"atb":[[210,2.93]],"id":41419629},{"atb":[[32,0]],"id":41419596}],"con":true,"img":false}]}
{"op":"mcm","clk":"5353526547","pt":1646216071939,"mc":[{"id":"1.195503866","rc":[{"atb":[[300,2.87]],"id":41419603},{"atb":[[120,6.28]],"id":41419593},{"atl":[[240,5.61]],"id":41419593},{"atl":[[34,25.11]],"id":41419591},{"atb":[[90,23.28]],"id":41419601},{"atb":[[32,0]],"id":41419628},{"atb":[[55,7.89]],"id":41419626},{"atb":[[55,10.76]],"id":41419608},{"atl":[[100,6.55]],"id":41419639},{"atb":[[16.5,31.99],[18.5,14.01]],"id":41419635},{"atb":[[60,7.64]],"id":41419610},{"atb":[[6.4,0]],"id":41419592},{"atb":[[32,10.06]],"id":41419586},{"atl":[[540,2]],"id":41419598}],"con":true,"img":false}]}
{"op":"mcm","clk":"5353526573","pt":1646216072012,"mc":[{"id":"1.195503866","rc":[{"atb":[[29,17.98]],"id":41419627}],"con":true,"img":false}]}
{"op":"mcm","clk":"5353526590","pt":1646216072116,"mc":[{"id":"1.195503866","rc":[{"atb":[[80,12.57]],"id":41419593}],"con":true,"img":false}]}
{"op":"mcm","clk":"5353526614","pt":1646216072323,"mc":[{"id":"1.195503866","rc":[{"atb":[[9,24.76]],"id":41419634},{"atb":[[3.65,0]],"id":41419591},{"atb":[[36,13.85]],"id":41419630},{"atl":[[130,6.18]],"id":41419626},{"atb":[[22,0]],"id":41419608},{"atl":[[70,20.25]],"id":41419585},{"atl":[[46,14.43],[25,11.55]],"id":41419612},{"atb":[[18,29.48]],"id":41419598}],"con":true,"img":false}]}
{"op":"mcm","clk":"5353526627","pt":1646216072428,"mc":[{"id":"1.195503866","rc":[{"atb":[[50,8.19]],"id":41419620},{"atb":[[110,6.4]],"id":41419599},{"atb":[[16,0]],"id":41419597},{"atb":[[48,11.58]],"id":41419626},{"atl":[[44,14.54],[380,0]],"id":41419606},{"atb":[[240,2.64]],"id":41419604},{"atb":[[40,17.47]],"id":41419610},{"atb":[[9.8,0]],"id":41419627}],"con":true,"img":false}]}
{"op":"mcm","clk":"5353526654","pt":1646216072638,"mc":[{"id":"1.195503866","rc":[{"atl":[[310,0]],"id":41419634}],"con":true,"img":false}]}
{"op":"mcm","clk":"5353526704","pt":1646216073013,"mc":[{"id":"1.195503866","rc":[{"atl":[[930,2]],"id":41419596}],"con":true,"img":false}]}
{"op":"mcm","clk":"5353526709","pt":1646216073113,"mc":[{"id":"1.195503866","rc":[{"atb":[[12.5,0]],"id":41419639}],"con":true,"img":false}]}
{"op":"mcm","clk":"5353526738","pt":1646216073327,"mc":[{"id":"1.195503866","rc":[{"atl":[[130,6.18]],"id":41419630}],"con":true,"img":false}]}
{"op":"mcm","clk":"5353527424","pt":1646216078056,"mc":[{"id":"1.195503866","rc":[{"atl":[[1000,2.15]],"id":41419601},{"atb":[[21,5],[28,0]],"id":41419608},{"atl":[[820,2],[870,0.17]],"id":41419608}],"con":true,"img":false}]}
{"op":"mcm","clk":"5353527758","pt":1646216079324,"mc":[{"id":"1.195503866","rc":[{"atb":[[40,0]],"id":41419603}],"con":true,"img":false}]}
{"op":"mcm","clk":"5353527797","pt":1646216079705,"mc":[{"id":"1.195503866","rc":[{"atb":[[18,2.72],[6.4,0]],"id":41419635},{"atl":[[460,0]],"id":41419635}],"con":true,"img":false}]}
{"op":"mcm","clk":"5353527828","pt":1646216079911,"mc":[{"id":"1.195503866","rc":[{"atb":[[12.5,0]],"id":41419630},{"atl":[[720,0]],"id":41419630},{"atl":[[420,0],[450,0]],"id":41419585},{"atb":[[16.5,6.45]],"id":41419610},{"atb":[[30,0]],"id":41419586},{"atl":[[670,0]],"id":41419586},{"atb":[[7.2,0]],"id":41419598}],"con":true,"img":false}]}
{"op":"mcm","clk":"5353527867","pt":1646216080094,"mc":[{"id":"1.195503866","rc":[{"atb":[[16,6.67],[50,0]],"id":41419626},{"atl":[[780,2]],"id":41419626},{"atb":[[40,0]],"id":41419604},{"atb":[[40,13.4],[60,4.95]],"id":41419610},{"atl":[[740,2]],"id":41419610}],"con":true,"img":false}]}
{"op":"mcm","clk":"5353528014","pt":1646216080920,"mc":[{"id":"1.195503866","rc":[{"atb":[[8.6,2.72]],"id":41419634},{"atl":[[570,0],[600,0]],"id":41419611},{"atl":[[310,0]],"id":41419591},{"atb":[[19.5,20.09],[10.5,0]],"id":41419589},{"atb":[[42,9.9]],"id":41419620},{"atl":[[310,0]],"id":41419587},{"atb":[[36,0],[80,10.56]],"id":41419599},{"atb":[[70,2.29],[50,0],[55,15.71]],"id":41419608},{"atl":[[660,2]],"id":41419639},{"atl":[[340,0]],"id":41419637},{"atb":[[13,0],[15.5,0]],"id":41419612},{"atl":[[360,0]],"id":41419612},{"atb":[[60,7.64]],"id":41419610},{"atl":[[130,4.95],[120,1.32]],"id":41419610},{"atb":[[7.2,0]],"id":41419590},{"atb":[[38,0]],"id":41419600},{"atb":[[38,0],[210,1.27]],"id":41419629},{"atb":[[7.4,0]],"id":41419594}],"con":true,"img":false}]}
{"op":"mcm","clk":"5353528050","pt":1646216080983,"mc":[{"id":"1.195503866","rc":[{"atb":[[3.9,0]],"id":41419634},{"atb":[[80,10.56]],"id":41419593},{"atl":[[990,2]],"id":41419593},{"atb":[[8,22.08],[7.2,0],[7.8,4.95],[7,9.9]],"id":41419591},{"atb":[[70,10.77]],"id":41419628},{"atl":[[950,2]],"id":41419628},{"atb":[[55,7.67]],"id":41419608},{"atl":[[900,0]],"id":41419608},{"atb":[[18,12.63]],"id":41419590},{"atl":[[490,0]],"id":41419590},{"atl":[[260,4.95],[250,0]],"id":41419621}],"con":true,"img":false}]}
{"op":"mcm","clk":"5353528064","pt":1646216081096,"mc":[{"id":"1.195503866","rc":[{"atl":[[740,0],[460,2]],"id":41419610}],"con":true,"img":false}]}
{"op":"mcm","clk":"5353528083","pt":1646216081200,"mc":[{"id":"1.195503866","rc":[{"atl":[[150,8.96],[740,2]],"id":41419630},{"atb":[[44,30.83],[48,2.72]],"id":41419626},{"atb":[[50,18.13]],"id":41419608},{"atl":[[870,1.71]],"id":41419608}],"con":true,"img":false}]}
{"op":"mcm","clk":"5353528109","pt":1646216081388,"mc":[{"id":"1.195503866","rc":[{"atl":[[340,2],[740,0]],"id":41419630}],"con":true,"img":false}]}
{"op":"mcm","clk":"5353528128","pt":1646216081514,"mc":[{"id":"1.195503866","rc":[{"atb":[[6.8,2.72],[7,53.42]],"id":41419591},{"atb":[[11,20.8],[7.4,59.45]],"id":41419612},{"atl":[[740,1.8],[770,0]],"id":41419610}],"con":true,"img":false}]}
{"op":"mcm","clk":"5353528156","pt":1646216081674,"mc":[{"id":"1.195503866","rc":[{"atb":[[70,0]],"id":41419608}],"con":true,"img":false}]}
{"op":"mcm","clk":"5353528169","pt":1646216081815,"mc":[{"id":"1.195503866","rc":[{"atb":[[44,9.9]],"id":41419608}],"con":true,"img":false}]}
{"op":"mcm","clk":"5353528186","pt":1646216081879,"mc":[{"id":"1.195503866","rc":[{"atb":[[16,2.72],[13.5,3.26]],"id":41419612}],"con":true,"img":false}]}
{"op":"mcm","clk":"5353528266","pt":1646216082391,"mc":[{"id":"1.195503866","rc":[{"atl":[[150,0]],"id":41419630}],"con":true,"img":false}]}
{"op":"mcm","clk":"5353528329","pt":1646216082539,"mc":[{"id":"1.195503866","rc":[{"atb":[[55,10.61]],"id":41419608}],"con":true,"img":false}]}
{"op":"mcm","clk":"5353529043","pt":1646216085167,"mc":[{"id":"1.195503866","rc":[{"atl":[[150,6.01]],"id":41419608}],"con":true,"img":false}]}
{"op":"mcm","clk":"5353529182","pt":1646216085521,"mc":[{"id":"1.195503866","rc":[{"atb":[[9.8,19.66]],"id":41419606}],"con":true,"img":false}]}
{"op":"mcm","clk":"5353529327","pt":1646216085908,"mc":[{"id":"1.195503866","rc":[{"atl":[[870,1.53]],"id":41419608}],"con":true,"img":false}]}
{"op":"mcm","clk":"5353529351","pt":1646216086020,"mc":[{"id":"1.195503866","rc":[{"atl":[[65,9.9],[44,0],[48,4.95],[55,0]],"id":41419607},{"atl":[[75,0],[80,4.95],[95,0],[100,9.9]],"id":41419611},{"atb":[[26,0]],"id":41419589},{"atl":[[12,0],[13,4.95],[14,0],[15,9.9]],"id":41419587},{"atl":[[150,0],[160,4.95]],"id":41419608},{"atl":[[19.5,0],[22,4.95],[23,0],[26,9.9]],"id":41419606},{"atl":[[19,0],[20,4.95],[22,0],[24,9.9]],"id":41419637},{"atl":[[34,9.9],[25,0],[28,4.95],[29,0]],"id":41419612},{"atb":[[70,9.9],[80,0],[90,4.95],[100,0]],"id":41419596}],"con":true,"img":false}]}
{"op":"mcm","clk":"5353529411","pt":1646216086188,"mc":[{"id":"1.195503866","rc":[{"atl":[[820,0],[420,2]],"id":41419608}],"con":true,"img":false}]}
{"op":"mcm","clk":"5353529483","pt":1646216086506,"mc":[{"id":"1.195503866","rc":[{"atl":[[48,8.32]],"id":41419607}],"con":true,"img":false}]}
{"op":"mcm","clk":"5353529558","pt":1646216086824,"mc":[{"id":"1.195503866","rc":[{"atb":[[60,7.64]],"id":41419636},{"atl":[[840,3.61]],"id":41419636},{"atl":[[80,6.95]],"id":41419611},{"atb":[[22,7.54]],"id":41419589},{"atl":[[14.5,11.4]],"id":41419587},{"atl":[[410,0.38]],"id":41419608},{"atl":[[42,3.86]],"id":41419606},{"atl":[[34,4.8]],"id":41419637},{"atl":[[32,5.11]],"id":41419612},{"atl":[[75,7.09]],"id":41419586},{"atl":[[140,11.72],[55,7.89]],"id":41419594}],"con":true,"img":false}]}
{"op":"mcm","clk":"5353529619","pt":1646216087088,"mc":[{"id":"1.195503866","rc":[{"atl":[[320,6.25],[730,0]],"id":41419633},{"atb":[[65,2.47]],"id":41419596},{"atl":[[80,6.95]],"id":41419627}],"con":true,"img":false}]}
{"op":"mcm","clk":"5353529659","pt":1646216087362,"mc":[{"id":"1.195503866","rc":[{"atl":[[510,0]],"id":41419607},{"atb":[[19.5,0],[21,31.47]],"id":41419589},{"atb":[[6.8,36.85]],"id":41419587},{"atl":[[34,3.03],[15,36.85]],"id":41419587},{"atl":[[34,19.31],[36,2.86]],"id":41419637}],"con":true,"img":false}]}
{"op":"mcm","clk":"5353529696","pt":1646216087498,"mc":[{"id":"1.195503866","rc":[{"atl":[[140,11.73]],"id":41419640},{"atb":[[150,6.01]],"id":41419605},{"atl":[[130,6.18]],"id":41419636},{"atl":[[34,24.86],[46,2.22]],"id":41419612},{"atb":[[60,7.64]],"id":41419623},{"atl":[[150,6.01]],"id":41419623},{"atl":[[980,0.16]],"id":41419621},{"atb":[[27,35.18]],"id":41419586}],"con":true,"img":false}]}
{"op":"mcm","clk":"5353529711","pt":1646216087558,"mc":[{"id":"1.195503866","rc":[{"atb":[[42,13.1]],"id":41419636},{"atl":[[42,16.97],[350,0],[44,2.33]],"id":41419606},{"atl":[[640,0]],"id":41419586},{"atb":[[60,2.68]],"id":41419596},{"atl":[[530,0]],"id":41419594}],"con":true,"img":false}]}
{"op":"mcm","clk":"5353529735","pt":1646216087637,"mc":[{"id":"1.195503866","rc":[{"atb":[[65,13.52]],"id":41419596}],"con":true,"img":false}]}
{"op":"mcm","clk":"5353529789","pt":1646216087921,"mc":[{"id":"1.195503866","rc":[{"atb":[[60,0]],"id":41419596},{"atl":[[670,0]],"id":41419627}],"con":true,"img":false}]}
{"op":"mcm","clk":"5353529880","pt":1646216088087,"mc":[{"id":"1.195503866","rc":[{"atl":[[990,1.52],[1000,2]],"id":41419621}],"con":true,"img":false}]}
{"op":"mcm","clk":"5353529965","pt":1646216088412,"mc":[{"id":"1.195503866","rc":[{"atb":[[95,9.85]],"id":41419605},{"atl":[[820,0]],"id":41419636},{"atb":[[55,2.72]],"id":41419623},{"atl":[[810,2]],"id":41419623},{"atl":[[990,1.36]],"id":41419621}],"con":true,"img":false}]}
{"op":"mcm","clk":"5353530062","pt":1646216088736,"mc":[{"id":"1.195503866","rc":[{"atb":[[44,31.99],[50,0]],"id":41419608}],"con":true,"img":false}]}
{"op":"mcm","clk":"5353530461","pt":1646216090223,"mc":[{"id":"1.195503866","rc":[{"atl":[[65,0],[70,9.9],[48,0],[50,4.95]],"id":41419607},{"atl":[[80,0],[85,4.95],[100,0],[110,9.9]],"id":41419611},{"atb":[[36,4.95],[38,0],[29,24.62],[30,0]],"id":41419639},{"atl":[[22,0],[24,4.95],[26,0],[28,9.9]],"id":41419606},{"atl":[[20,0],[21,4.95],[24,0],[25,9.9]],"id":41419637},{"atl":[[34,14.95],[38,9.9],[28,0],[30,4.95]],"id":41419612},{"atb":[[210,2.93]],"id":41419629}],"con":true,"img":false}]}
{"op":"mcm","clk":"5353530511","pt":1646216090440,"mc":[{"id":"1.195503866","rc":[{"atl":[[160,0],[170,4.95]],"id":41419608}],"con":true,"img":false}]}
{"op":"mcm","clk":"5353530656","pt":1646216090925,"mc":[{"id":"1.195503866","rc":[{"atb":[[30,5.46]],"id":41419639},{"atl":[[150,4.95],[160,4.95]],"id":41419623}],"con":true,"img":false}]}
{"op":"mcm","clk":"5353530679","pt":1646216090982,"mc":[{"id":"1.195503866","rc":[{"atl":[[70,0],[75,9.9],[50,0],[55,4.95],[120,1.32]],"id":41419607},{"atl":[[85,6.83]],"id":41419611},{"atl":[[13,0],[13.5,4.95],[15,26.94],[15.5,9.9]],"id":41419587},{"atl":[[150,0]],"id":41419623}],"con":true,"img":false}]}
{"op":"mcm","clk":"5353530705","pt":1646216091095,"mc":[{"id":"1.195503866","rc":[{"atl":[[810,0],[470,2]],"id":41419623}],"con":true,"img":false}]}
{"op":"mcm","clk":"5353530788","pt":1646216091409,"mc":[{"id":"1.195503866","rc":[{"atl":[[840,0]],"id":41419623}],"con":true,"img":false}]}
{"op":"mcm","clk":"5353530819","pt":1646216091510,"mc":[{"id":"1.195503866","rc":[{"atl":[[130,2]],"id":41419607},{"atb":[[21,21.56],[25,0]],"id":41419589},{"atl":[[38,0],[30,0]],"id":41419612},{"atl":[[810,1.68]],"id":41419623}],"con":true,"img":false}]}
{"op":"mcm","clk":"5353530831","pt":1646216091614,"mc":[{"id":"1.195503866","rc":[{"atl":[[120,12.78]],"id":41419607},{"atl":[[32,10.06]],"id":41419612}],"con":true,"img":false}]}
{"op":"mcm","clk":"5353530864","pt":1646216091728,"mc":[{"id":"1.195503866","rc":[{"atl":[[85,0],[90,4.95],[110,0],[120,9.9]],"id":41419611},{"atb":[[20,9.9],[24,4.95]],"id":41419589},{"atl":[[160,5.95]],"id":41419623}],"con":true,"img":false}]}
{"op":"mcm","clk":"5353531046","pt":1646216092309,"mc":[{"id":"1.195503866","rc":[{"atb":[[70,0],[90,0]],"id":41419596}],"con":true,"img":false}]}
{"op":"mcm","clk":"5353531139","pt":1646216092631,"mc":[{"id":"1.195503866","rc":[{"atl":[[90,6.73]],"id":41419611},{"atb":[[100,0],[120,18.66]],"id":41419632},{"atb":[[65,23.42],[85,4.95]],"id":41419596}],"con":true,"img":false}]}
{"op":"mcm","clk":"5353531348","pt":1646216093429,"mc":[{"id":"1.195503866","rc":[{"atl":[[170,0],[180,4.95]],"id":41419608},{"atl":[[24,0],[25,4.95],[28,0],[29,9.9]],"id":41419606},{"atl":[[32,0],[34,19.9],[42,9.9]],"id":41419612}],"con":true,"img":false}]}
{"op":"mcm","clk":"5353531557","pt":1646216094102,"mc":[{"id":"1.195503866","rc":[{"atl":[[34,24.71]],"id":41419612}],"con":true,"img":false}]}
{"op":"mcm","clk":"5353531747","pt":1646216094791,"mc":[{"id":"1.195503866","rc":[{"atl":[[34,9.76],[46,21.81]],"id":41419612}],"con":true,"img":false}]}
{"op":"mcm","clk":"5353531847","pt":1646216095217,"mc":[{"id":"1.195503866","rc":[{"atb":[[65,12.38],[55,14.12]],"id":41419596}],"con":true,"img":false}]}
{"op":"mcm","clk":"5353531879","pt":1646216095324,"mc":[{"id":"1.195503866","rc":[{"atl":[[46,19.59],[48,2.13]],"id":41419612}],"con":true,"img":false}]}
{"op":"mcm","clk":"5353532048","pt":1646216096022,"mc":[{"id":"1.195503866","rc":[{"atb":[[44,9.9]],"id":41419608}],"con":true,"img":false}]}
{"op":"mcm","clk":"5353532147","pt":1646216096295,"mc":[{"id":"1.195503866","rc":[{"atl":[[150,9.24]],"id":41419630},{"atb":[[42,15.48]],"id":41419608},{"atl":[[420,5.29],[870,0]],"id":41419608},{"atl":[[810,3.68],[470,0]],"id":41419623}],"con":true,"img":false}]}
{"op":"mcm","clk":"5353532234","pt":1646216096711,"mc":[{"id":"1.195503866","rc":[{"atb":[[11,50.04],[7.4,20.81]],"id":41419612},{"atl":[[740,0],[460,5.01]],"id":41419610}],"con":true,"img":false}]}
{"op":"mcm","clk":"5353532542","pt":1646216098345,"mc":[{"id":"1.195503866","rc":[{"atl":[[1000,0.15]],"id":41419604}],"con":true,"img":false}]}
{"op":"mcm","clk":"5353532613","pt":1646216098616,"mc":[{"id":"1.195503866","rc":[{"atb":[[270,3.13]],"id":41419622}],"con":true,"img":false}]}
{"op":"mcm","clk":"5353532899","pt":1646216100030,"mc":[{"id":"1.195503866","rc":[{"atl":[[170,0.93]],"id":41419608}],"con":true,"img":false}]}
{"op":"mcm","clk":"5353533030","pt":1646216100717,"mc":[{"id":"1.195503866","rc":[{"atl":[[410,0]],"id":41419608}],"con":true,"img":false}]}
{"op":"mcm","clk":"5353533147","pt":1646216101115,"mc":[{"id":"1.195503866","rc":[{"atl":[[75,0],[44,4.95]],"id":41419607},{"atl":[[130,1.23],[120,4.95]],"id":41419636},{"atb":[[9,19.81],[9.2,4.95],[8.2,22.08],[8.4,9.9]],"id":41419634},{"atl":[[75,4.95],[90,1.78],[95,9.9],[120,0]],"id":41419611},{"atl":[[230,4.95],[240,0.66]],"id":41419593},{"atl":[[11.5,4.95],[12,14.41],[13.5,9.9],[14,0]],"id":41419591},{"atb":[[20,0],[22,17.45],[24,0],[26,4.95]],"id":41419589},{"atb":[[42,0],[44,9.9],[50,3.23],[55,4.95]],"id":41419620},{"atl":[[12,4.95],[13.5,0],[14,9.9],[15.5,0]],"id":41419587},{"atb":[[36,8.9],[38,4.95],[29,0],[30,9.9]],"id":41419630},{"atl":[[150,4.95]],"id":41419608},{"atb":[[32,9.9],[36,0],[40,4.95],[29,14.71]],"id":41419639},{"atb":[[9,0],[10,4.95],[9.2,9.9],[9.8,14.71]],"id":41419606},{"atb":[[9,0],[10,4.95],[9.2,9.9],[9.8,12.21]],"id":41419637},{"atl":[[23,4.95],[24,6.89],[27,9.9],[28,0]],"id":41419585},{"atl":[[34,4.8],[42,0],[25,4.95],[29,9.9]],"id":41419612},{"atb":[[65,4.95],[46,14.71],[48,9.9],[60,2.68]],"id":41419623},{"atl":[[70,4.95],[75,2.14],[90,9.9],[95,0]],"id":41419586},{"atb":[[36,3.26],[38,4.95],[29,19.57],[30,9.9]],"id":41419633},{"atb":[[65,2.47],[75,9.9],[85,0],[95,4.95]],"id":41419596},{"atb":[[34,0],[36,4.95],[28,0],[29,27.89]],"id":41419627},{"atl":[[70,9.9],[75,0],[50,4.95],[55,2.93]],"id":41419594}],"con":true,"img":false}]}
{"op":"mcm","clk":"5353533241","pt":1646216101450,"mc":[{"id":"1.195503866","rc":[{"atl":[[50,3.23]],"id":41419607}],"con":true,"img":false}]}
{"op":"mcm","clk":"5353533277","pt":1646216101514,"mc":[{"id":"1.195503866","rc":[{"atl":[[840,1.61],[420,2]],"id":41419636}],"con":true,"img":false}]}
{"op":"mcm","clk":"5353533304","pt":1646216101617,"mc":[{"id":"1.195503866","rc":[{"atl":[[810,2],[990,0]],"id":41419593}],"con":true,"img":false}]}
{"op":"mcm","clk":"5353533334","pt":1646216101724,"mc":[{"id":"1.195503866","rc":[{"atl":[[840,0]],"id":41419636},{"atb":[[23,7.2]],"id":41419589},{"atl":[[40,4.06]],"id":41419606},{"atl":[[32,5.11]],"id":41419637}],"con":true,"img":false}]}
{"op":"mcm","clk":"5353533359","pt":1646216101836,"mc":[{"id":"1.195503866","rc":[{"atl":[[150,9.35]],"id":41419636},{"atb":[[8.6,42.27],[8.2,0],[9.4,18.87]],"id":41419634},{"atl":[[95,24.69],[190,2]],"id":41419611},{"atl":[[220,0.81],[990,1.41],[1000,0]],"id":41419593},{"atl":[[34,3.03],[11,15.85],[13.5,46.05]],"id":41419591},{"atb":[[22,7.54],[26,0]],"id":41419589},{"atb":[[40,2.72],[44,22.08],[60,2.68]],"id":41419620},{"atl":[[12.5,4.95],[14.5,21.3]],"id":41419587},{"atb":[[36,0]],"id":41419630},{"atb":[[29,0],[30,20.95]],"id":41419639},{"atb":[[10,19.66],[9.8,0]],"id":41419606},{"atb":[[10,19.66],[9.8,0]],"id":41419637},{"atl":[[70,2],[22,7.54],[27,34.87]],"id":41419585},{"atb":[[46,0],[55,13.69]],"id":41419623},{"atl":[[65,2.47],[90,25.51],[250,2]],"id":41419586},{"atb":[[36,17.98],[29,0]],"id":41419633},{"atl":[[70,22.12],[140,2]],"id":41419594}],"con":true,"img":false}]}
{"op":"mcm","clk":"5353533376","pt":1646216101901,"mc":[{"id":"1.195503866","rc":[{"atl":[[44,0],[46,4.95],[55,0],[60,9.9]],"id":41419607},{"atl":[[75,0],[80,4.95],[95,14.78],[100,9.9]],"id":41419611},{"atb":[[21,31.47],[25,4.95]],"id":41419589},{"atl":[[12,0],[14,0]],"id":41419587},{"atb":[[38,17.17]],"id":41419630},{"atl":[[150,0],[160,4.95],[180,0]],"id":41419608},{"atb":[[32,0],[38,4.95],[40,0],[30,30.86]],"id":41419639},{"atl":[[22,4.95],[25,0],[26,9.9],[29,0]],"id":41419606},{"atl":[[32,9.9],[25,0],[27,4.95],[29,0]],"id":41419612},{"atl":[[85,4.95],[90,0],[110,9.9],[120,0]],"id":41419633},{"atl":[[70,12.21],[75,9.9],[50,0],[55,7.89]],"id":41419594}],"con":true,"img":false}]}
{"op":"mcm","clk":"5353533412","pt":1646216102108,"mc":[{"id":"1.195503866","rc":[{"atl":[[14.5,48.25],[15,0]],"id":41419587},{"atl":[[20,4.95],[21,0],[24,9.9],[25,0]],"id":41419637},{"atl":[[150,4.95],[160,0.99]],"id":41419623},{"atb":[[95,6.63]],"id":41419596}],"con":true,"img":false}]}
{"op":"mcm","clk":"5353533431","pt":1646216102211,"mc":[{"id":"1.195503866","rc":[{"atl":[[120,11.45]],"id":41419607},{"atb":[[22,28.59]],"id":41419589},{"atl":[[32,19.82],[34,4.8]],"id":41419637},{"atl":[[34,19.31],[46,0]],"id":41419612},{"atb":[[65,7.43]],"id":41419623},{"atl":[[260,5.56]],"id":41419621}],"con":true,"img":false}]}
{"op":"mcm","clk":"5353533447","pt":1646216102313,"mc":[{"id":"1.195503866","rc":[{"atb":[[21,9.9]],"id":41419589}],"con":true,"img":false}]}
{"op":"mcm","clk":"5353533460","pt":1646216102417,"mc":[{"id":"1.195503866","rc":[{"atl":[[120,6.28]],"id":41419636},{"atl":[[80,6.95]],"id":41419611},{"atl":[[12.5,16.35]],"id":41419587},{"atl":[[160,5.95]],"id":41419608},{"atl":[[40,17.47],[42,3.86]],"id":41419606},{"atl":[[34,0]],"id":41419637},{"atb":[[65,13.52],[70,9.9],[75,0],[90,4.95],[95,1.68],[55,2.72]],"id":41419596}],"con":true,"img":false}]}
{"op":"mcm","clk":"5353533475","pt":1646216102520,"mc":[{"id":"1.195503866","rc":[{"atb":[[9,0]],"id":41419634},{"atl":[[12,0]],"id":41419591},{"atb":[[22,21.04]],"id":41419589},{"atl":[[42,0]],"id":41419606},{"atl":[[24,0]],"id":41419585}],"con":true,"img":false}]}
{"op":"mcm","clk":"5353533492","pt":1646216102627,"mc":[{"id":"1.195503866","rc":[{"atl":[[240,0],[990,0]],"id":41419593},{"atb":[[50,0]],"id":41419620},{"atl":[[32,0],[27,0]],"id":41419612},{"atl":[[150,6.01]],"id":41419623},{"atl":[[75,0],[90,9.9]],"id":41419586},{"atl":[[70,0]],"id":41419594}],"con":true,"img":false}]}
{"op":"mcm","clk":"5353533509","pt":1646216102734,"mc":[{"id":"1.195503866","rc":[{"atl":[[65,9.9],[46,0],[48,4.95],[60,0]],"id":41419607},{"atl":[[32,5.11],[34,29.22],[28,4.95]],"id":41419612},{"atl":[[70,2.29]],"id":41419594}],"con":true,"img":false}]}
{"op":"mcm","clk":"5353533527","pt":1646216102801,"mc":[{"id":"1.195503866","rc":[{"atb":[[65,11.04],[95,0]],"id":41419596}],"con":true,"img":false}]}
{"op":"mcm","clk":"5353533555","pt":1646216102998,"mc":[{"id":"1.195503866","rc":[{"atb":[[60,0]],"id":41419623},{"atl":[[980,0]],"id":41419621}],"con":true,"img":false}]}
{"op":"mcm","clk":"5353533575","pt":1646216103123,"mc":[{"id":"1.195503866","rc":[{"atl":[[130,0]],"id":41419636},{"atl":[[90,0]],"id":41419611},{"atl":[[14.5,36.85]],"id":41419587},{"atl":[[170,0]],"id":41419608}],"con":true,"img":false}]}
{"op":"mcm","clk":"5353533663","pt":1646216103455,"mc":[{"id":"1.195503866","rc":[{"atl":[[160,0]],"id":41419623}],"con":true,"img":false}]}
{"op":"mcm","clk":"5353533688","pt":1646216103522,"mc":[{"id":"1.195503866","rc":[{"atl":[[34,24.41]],"id":41419612},{"atl":[[990,0],[1000,3.4]],"id":41419621},{"atl":[[70,0]],"id":41419594}],"con":true,"img":false}]}
{"op":"mcm","clk":"5353533762","pt":1646216103763,"mc":[{"id":"1.195503866","rc":[{"atl":[[150,0],[340,6.13]],"id":41419630},{"atb":[[90,6.73]],"id":41419596}],"con":true,"img":false}]}
{"op":"mcm","clk":"5353533877","pt":1646216104251,"mc":[{"id":"1.195503866","rc":[{"atl":[[70,9.9],[50,8.19]],"id":41419607},{"atl":[[80,0],[85,4.95],[100,0],[110,9.9]],"id":41419611},{"atl":[[12.5,0],[13,4.95],[14.5,26.94],[15,9.9]],"id":41419587},{"atl":[[160,4.95],[170,4.95]],"id":41419608},{"atl":[[22,0],[26,0]],"id":41419606},{"atl":[[20,0],[21,4.95],[24,0],[25,9.9]],"id":41419637},{"atl":[[34,14.5],[36,9.9],[28,0],[29,4.95]],"id":41419612},{"atl":[[1000,2]],"id":41419621}],"con":true,"img":false}]}
{"op":"mcm","clk":"5353533895","pt":1646216104313,"mc":[{"id":"1.195503866","rc":[{"atl":[[65,0],[48,0]],"id":41419607},{"atl":[[160,0]],"id":41419608}],"con":true,"img":false}]}
{"op":"mcm","clk":"5353533931","pt":1646216104432,"mc":[{"id":"1.195503866","rc":[{"atl":[[44,0],[46,2.22]],"id":41419606}],"con":true,"img":false}]}
{"op":"mcm","clk":"5353533966","pt":1646216104542,"mc":[{"id":"1.195503866","rc":[{"atl":[[23,4.95],[27,9.9]],"id":41419606}],"con":true,"img":false}]}
{"op":"mcm","clk":"5353534064","pt":1646216104912,"mc":[{"id":"1.195503866","rc":[{"atl":[[85,6.83]],"id":41419611}],"con":true,"img":false}]}
{"op":"mcm","clk":"5353534223","pt":1646216105440,"mc":[{"id":"1.195503866","rc":[{"atl":[[130,0],[100,2]],"id":41419607},{"atl":[[1000,2.15]],"id":41419605},{"atl":[[160,2],[190,0]],"id":41419611},{"atl":[[14.5,38.69]],"id":41419587},{"atl":[[740,2],[820,0]],"id":41419597},{"atl":[[870,2],[950,0]],"id":41419628},{"atl":[[170,5.89]],"id":41419608},{"atl":[[36,0],[29,3.57]],"id":41419637},{"atl":[[70,0],[48,2.13]],"id":41419585},{"atl":[[38,2.7],[48,0]],"id":41419612},{"atl":[[180,2],[250,0]],"id":41419586},{"atl":[[260,2],[320,4.25]],"id":41419633}],"con":true,"img":false}]}
{"op":"mcm","clk":"5353534396","pt":1646216105862,"mc":[{"id":"1.195503866","rc":[{"atb":[[32,5.11]],"id":41419639}],"con":true,"img":false}]}
{"op":"mcm","clk":"5353534479","pt":1646216106020,"mc":[{"id":"1.195503866","rc":[{"atl":[[110,1.45]],"id":41419607},{"atl":[[260,7.43],[320,0]],"id":41419633}],"con":true,"img":false}]}
{"op":"mcm","clk":"5353534616","pt":1646216106483,"mc":[{"id":"1.195503866","rc":[{"atl":[[130,1.23]],"id":41419630}],"con":true,"img":false}]}
{"op":"mcm","clk":"5353534653","pt":1646216106542,"mc":[{"id":"1.195503866","rc":[{"atl":[[100,16.16],[120,0]],"id":41419607},{"atl":[[120,4.95]],"id":41419630},{"atl":[[170,8.32],[810,2]],"id":41419623}],"con":true,"img":false}]}
{"op":"mcm","clk":"5353534728","pt":1646216106746,"mc":[{"id":"1.195503866","rc":[{"atl":[[270,2],[340,4.13]],"id":41419630},{"atb":[[30,25.39]],"id":41419639},{"atl":[[370,2],[810,0]],"id":41419623}],"con":true,"img":false}]}
{"op":"mcm","clk":"5353534805","pt":1646216107009,"mc":[{"id":"1.195503866","rc":[{"atl":[[110,0]],"id":41419607},{"atl":[[120,6.28]],"id":41419630},{"atl":[[85,0],[90,4.95],[110,0],[120,9.9]],"id":41419633}],"con":true,"img":false}]}
{"op":"mcm","clk":"5353534971","pt":1646216107466,"mc":[{"id":"1.195503866","rc":[{"atl":[[170,0]],"id":41419623}],"con":true,"img":false}]}
{"op":"mcm","clk":"5353535213","pt":1646216107944,"mc":[{"id":"1.195503866","rc":[{"atl":[[250,0.63]],"id":41419633}],"con":true,"img":false}]}
{"op":"mcm","clk":"5353535253","pt":1646216108045,"mc":[{"id":"1.195503866","rc":[{"atl":[[130,0]],"id":41419630}],"con":true,"img":false}]}
{"op":"mcm","clk":"5353535310","pt":1646216108156,"mc":[{"id":"1.195503866","rc":[{"atl":[[330,2],[420,0]],"id":41419636},{"atl":[[640,2],[810,0]],"id":41419593}],"con":true,"img":false}]}
{"op":"mcm","clk":"5353535494","pt":1646216108553,"mc":[{"id":"1.195503866","rc":[{"atb":[[26,9.06]],"id":41419607}],"con":true,"img":false}]}
{"op":"mcm","clk":"5353535568","pt":1646216108756,"mc":[{"id":"1.195503866","rc":[{"atl":[[700,0]],"id":41419633}],"con":true,"img":false}]}
{"op":"mcm","clk":"5353535684","pt":1646216109016,"mc":[{"id":"1.195503866","rc":[{"atl":[[150,0],[330,6.31]],"id":41419636},{"atl":[[95,0],[110,22.85]],"id":41419611},{"atl":[[28,5.86]],"id":41419612},{"atb":[[48,31.99],[55,2.72]],"id":41419623}],"con":true,"img":false}]}
{"op":"mcm","clk":"5353535790","pt":1646216109340,"mc":[{"id":"1.195503866","rc":[{"atl":[[14.5,11.74],[15,36.85]],"id":41419587}],"con":true,"img":false}]}
{"op":"mcm","clk":"5353535939","pt":1646216109739,"mc":[{"id":"1.195503866","rc":[{"atl":[[32,20.06],[34,0]],"id":41419612}],"con":true,"img":false}]}
{"op":"mcm","clk":"5353536042","pt":1646216110016,"mc":[{"id":"1.195503866","rc":[{"atl":[[130,4.95],[120,0]],"id":41419630},{"atl":[[32,14.95],[28,0]],"id":41419612}],"con":true,"img":false}]}
{"op":"mcm","clk":"5353536238","pt":1646216110824,"mc":[{"id":"1.195503866","rc":[{"atl":[[260,0.61]],"id":41419630},{"atl":[[30,5.46]],"id":41419612}],"con":true,"img":false}]}
{"op":"mcm","clk":"5353536314","pt":1646216111136,"mc":[{"id":"1.195503866","rc":[{"atl":[[190,7.52],[420,2]],"id":41419608}],"con":true,"img":false}]}
{"op":"mcm","clk":"5353536356","pt":1646216111345,"mc":[{"id":"1.195503866","rc":[{"atl":[[330,2],[420,0]],"id":41419608}],"con":true,"img":false}]}
{"op":"mcm","clk":"5353536394","pt":1646216111451,"mc":[{"id":"1.195503866","rc":[{"atl":[[270,7.29],[340,0]],"id":41419630}],"con":true,"img":false}]}
{"op":"mcm","clk":"5353537539","pt":1646216116021,"mc":[{"id":"1.195503866","rc":[{"atl":[[110,9.9]],"id":41419611}],"con":true,"img":false}]}
{"op":"mcm","clk":"5353537613","pt":1646216116333,"mc":[{"id":"1.195503866","rc":[{"atl":[[140,10.32],[330,2]],"id":41419636},{"atl":[[160,11.02]],"id":41419611},{"atl":[[640,4.25]],"id":41419593},{"atb":[[25,11.55]],"id":41419589},{"atl":[[23,12.15]],"id":41419606},{"atl":[[21,12.88]],"id":41419637},{"atl":[[90,25.96]],"id":41419586},{"atl":[[140,12.32]],"id":41419594}],"con":true,"img":false}]}
{"op":"mcm","clk":"5353537653","pt":1646216116542,"mc":[{"id":"1.195503866","rc":[{"atl":[[38,2.7],[46,0]],"id":41419606}],"con":true,"img":false}]}
{"op":"mcm","clk":"5353537698","pt":1646216116715,"mc":[{"id":"1.195503866","rc":[{"atl":[[32,5.11]],"id":41419637}],"con":true,"img":false}]}
{"op":"mcm","clk":"5353537772","pt":1646216117018,"mc":[{"id":"1.195503866","rc":[{"atl":[[13,18.16]],"id":41419587},{"atl":[[38,22.29]],"id":41419606},{"atl":[[29,16.23]],"id":41419637}],"con":true,"img":false}]}
{"op":"mcm","clk":"5353537800","pt":1646216117122,"mc":[{"id":"1.195503866","rc":[{"atl":[[40,4.06]],"id":41419606}],"con":true,"img":false}]}
{"op":"mcm","clk":"5353537839","pt":1646216117335,"mc":[{"id":"1.195503866","rc":[{"atb":[[23,0]],"id":41419589},{"atl":[[32,0]],"id":41419637}],"con":true,"img":false}]}
{"op":"mcm","clk":"5353537857","pt":1646216117443,"mc":[{"id":"1.195503866","rc":[{"atl":[[40,0]],"id":41419606},{"atl":[[29,10.61]],"id":41419612}],"con":true,"img":false}]}
{"op":"mcm","clk":"5353537967","pt":1646216117820,"mc":[{"id":"1.195503866","rc":[{"atl":[[14.5,0]],"id":41419587}],"con":true,"img":false}]}
{"op":"mcm","clk":"5353538050","pt":1646216118129,"mc":[{"id":"1.195503866","rc":[{"atb":[[21,39.36],[22,0]],"id":41419589},{"atl":[[150,0],[160,4.95]],"id":41419623}],"con":true,"img":false}]}
{"op":"mcm","clk":"5353538106","pt":1646216118343,"mc":[{"id":"1.195503866","rc":[{"atl":[[34,42.24],[15,9.9]],"id":41419587},{"atl":[[330,6.38],[190,0]],"id":41419608},{"atl":[[29,4.95],[30,10.42]],"id":41419612}],"con":true,"img":false}]}
{"op":"mcm","clk":"5353538129","pt":1646216118448,"mc":[{"id":"1.195503866","rc":[{"atl":[[36,0],[29,0],[30,4.95]],"id":41419612}],"con":true,"img":false}]}
{"op":"mcm","clk":"5353538225","pt":1646216118820,"mc":[{"id":"1.195503866","rc":[{"atl":[[360,0.44]],"id":41419623}],"con":true,"img":false}]}
{"op":"mcm","clk":"5353538307","pt":1646216119241,"mc":[{"id":"1.195503866","rc":[{"atl":[[330,2]],"id":41419608},{"atl":[[32,0],[38,24.82],[30,10.42]],"id":41419612}],"con":true,"img":false}]}
{"op":"mcm","clk":"5353538505","pt":1646216120245,"mc":[{"id":"1.195503866","rc":[{"atb":[[38,9.23]],"id":41419639}],"con":true,"img":false}]}
{"op":"mcm","clk":"5353538583","pt":1646216120617,"mc":[{"id":"1.195503866","rc":[{"atl":[[260,2],[250,6.45]],"id":41419633}],"con":true,"img":false}]}
{"op":"mcm","clk":"5353538644","pt":1646216120928,"mc":[{"id":"1.195503866","rc":[{"atl":[[13,0],[13.5,4.95],[15,0],[15.5,9.9]],"id":41419587},{"atb":[[32,0],[36,4.95],[38,0],[29,9.9],[30,15.48]],"id":41419639},{"atl":[[23,0],[24,4.95],[27,0],[28,9.9]],"id":41419606},{"atb":[[65,20.94],[70,0],[85,4.95],[90,0]],"id":41419596}],"con":true,"img":false}]}
{"op":"mcm","clk":"5353538669","pt":1646216121032,"mc":[{"id":"1.195503866","rc":[{"atl":[[370,5.93]],"id":41419623}],"con":true,"img":false}]}
{"op":"mcm","clk":"5353538730","pt":1646216121344,"mc":[{"id":"1.195503866","rc":[{"atb":[[30,0]],"id":41419639}],"con":true,"img":false}]}
{"op":"mcm","clk":"5353538783","pt":1646216121658,"mc":[{"id":"1.195503866","rc":[{"atl":[[130,6.18]],"id":41419630},{"atb":[[32,5.11],[29,27.01]],"id":41419639},{"atl":[[27,6.09]],"id":41419606},{"atb":[[65,9.9],[70,2.29],[55,14.12]],"id":41419596}],"con":true,"img":false}]}
{"op":"mcm","clk":"5353538804","pt":1646216121719,"mc":[{"id":"1.195503866","rc":[{"atl":[[32,5.11]],"id":41419587}],"con":true,"img":false}]}
{"op":"mcm","clk":"5353538897","pt":1646216122337,"mc":[{"id":"1.195503866","rc":[{"atb":[[55,2.72]],"id":41419596}],"con":true,"img":false}]}
{"op":"mcm","clk":"5353538944","pt":1646216122654,"mc":[{"id":"1.195503866","rc":[{"atl":[[260,0]],"id":41419630}],"con":true,"img":false}]}
{"op":"mcm","clk":"5353539078","pt":1646216123363,"mc":[{"id":"1.195503866","rc":[{"atl":[[140,0]],"id":41419636}],"con":true,"img":false}]}
{"op":"mcm","clk":"5353539147","pt":1646216123638,"mc":[{"id":"1.195503866","rc":[{"atl":[[330,6.43]],"id":41419636},{"atl":[[270,2],[150,9.76]],"id":41419630}],"con":true,"img":false}]}
{"op":"mcm","clk":"5353539231","pt":1646216123962,"mc":[{"id":"1.195503866","rc":[{"atl":[[32,24.92],[34,3.03]],"id":41419587}],"con":true,"img":false}]}
{"op":"mcm","clk":"5353539338","pt":1646216124343,"mc":[{"id":"1.195503866","rc":[{"atl":[[34,30.97],[38,12.6]],"id":41419612}],"con":true,"img":false}]}
{"op":"mcm","clk":"5353539520","pt":1646216125161,"mc":[{"id":"1.195503866","rc":[{"atb":[[21,9.9]],"id":41419589}],"con":true,"img":false}]}
{"op":"mcm","clk":"5353539597","pt":1646216125438,"mc":[{"id":"1.195503866","rc":[{"atb":[[19,27.79]],"id":41419589}],"con":true,"img":false}]}
{"op":"mcm","clk":"5353539683","pt":1646216125767,"mc":[{"id":"1.195503866","rc":[{"atl":[[190,7.73]],"id":41419608}],"con":true,"img":false}]}
{"op":"mcm","clk":"5353539812","pt":1646216126257,"mc":[{"id":"1.195503866","rc":[{"atl":[[34,0]],"id":41419612}],"con":true,"img":false}]}
{"op":"mcm","clk":"5353539885","pt":1646216126541,"mc":[{"id":"1.195503866","rc":[{"atl":[[38,46.83]],"id":41419612}],"con":true,"img":false}]}
{"op":"mcm","clk":"5353539985","pt":1646216126977,"mc":[{"id":"1.195503866","rc":[{"atl":[[70,0],[50,3.23]],"id":41419607}],"con":true,"img":false}]}
{"op":"mcm","clk":"5353540018","pt":1646216127050,"mc":[{"id":"1.195503866","rc":[{"atl":[[75,9.9],[50,0],[55,4.95]],"id":41419607},{"atl":[[32,4.95],[38,36.93],[40,9.9],[30,0]],"id":41419612}],"con":true,"img":false}]}
{"op":"mcm","clk":"5353540150","pt":1646216127638,"mc":[{"id":"1.195503866","rc":[{"atl":[[100,2],[60,24.62]],"id":41419607}],"con":true,"img":false}]}
{"op":"mcm","clk":"5353540214","pt":1646216127957,"mc":[{"id":"1.195503866","rc":[{"atl":[[95,1.68]],"id":41419607},{"atl":[[36,4.52]],"id":41419612}],"con":true,"img":false}]}
{"op":"mcm","clk":"5353540310","pt":1646216128342,"mc":[{"id":"1.195503866","rc":[{"atb":[[20,9.9],[21,0],[24,4.95],[25,0]],"id":41419589}],"con":true,"img":false}]}
{"op":"mcm","clk":"5353540410","pt":1646216128732,"mc":[{"id":"1.195503866","rc":[{"atl":[[60,0]],"id":41419607}],"con":true,"img":false}]}
{"op":"mcm","clk":"5353540510","pt":1646216129047,"mc":[{"id":"1.195503866","rc":[{"atb":[[19.5,8.56]],"id":41419589}],"con":true,"img":false}]}
{"op":"mcm","clk":"5353540672","pt":1646216129740,"mc":[{"id":"1.195503866","rc":[{"atl":[[85,4.95]],"id":41419611}],"con":true,"img":false}]}
{"op":"mcm","clk":"5353540711","pt":1646216130054,"mc":[{"id":"1.195503866","rc":[{"atl":[[85,0],[110,0]],"id":41419611}],"con":true,"img":false}]}
{"op":"mcm","clk":"5353540728","pt":1646216130157,"mc":[{"id":"1.195503866","rc":[{"atl":[[90,4.95],[120,9.9]],"id":41419611}],"con":true,"img":false}]}
{"op":"mcm","clk":"5353540795","pt":1646216130530,"mc":[{"id":"1.195503866","rc":[{"atl":[[300,4.95]],"id":41419605},{"atl":[[330,2]],"id":41419636},{"atl":[[150,1.06],[160,2],[180,8.25]],"id":41419611},{"atl":[[270,7.49],[150,0]],"id":41419630},{"atl":[[24,11.84]],"id":41419606}],"con":true,"img":false}]}
{"op":"mcm","clk":"5353540815","pt":1646216130740,"mc":[{"id":"1.195503866","rc":[{"atl":[[140,10.61]],"id":41419636},{"atb":[[24,11.84]],"id":41419589}],"con":true,"img":false}]}
{"op":"mcm","clk":"5353540860","pt":1646216131048,"mc":[{"id":"1.195503866","rc":[{"atl":[[290,0.66]],"id":41419605}],"con":true,"img":false}]}
{"op":"mcm","clk":"5353540881","pt":1646216131212,"mc":[{"id":"1.195503866","rc":[{"atl":[[13.5,17.63]],"id":41419587},{"atl":[[130,0],[270,2],[140,4.95]],"id":41419630},{"atl":[[38,2.7],[27,0],[28,33.7]],"id":41419606}],"con":true,"img":false}]}
{"op":"mcm","clk":"5353540929","pt":1646216131530,"mc":[{"id":"1.195503866","rc":[{"atl":[[1000,3.63]],"id":41419605},{"atb":[[19.5,0]],"id":41419589}],"con":true,"img":false}]}
{"op":"mcm","clk":"5353540960","pt":1646216131739,"mc":[{"id":"1.195503866","rc":[{"atl":[[640,2.25],[790,2]],"id":41419593},{"atb":[[23,0],[28,3.7]],"id":41419597},{"atb":[[8.4,0],[9.4,11.9]],"id":41419592},{"atb":[[10,0],[12.5,8.7]],"id":41419594}],"con":true,"img":false}]}
{"op":"mcm","clk":"5353540978","pt":1646216131847,"mc":[{"id":"1.195503866","rc":[{"atl":[[1000,3.47]],"id":41419605},{"atl":[[30,5.46]],"id":41419612}],"con":true,"img":false}]}
{"op":"mcm","clk":"5353540991","pt":1646216131948,"mc":[{"id":"1.195503866","rc":[{"atl":[[32,19.81]],"id":41419587},{"atl":[[28,9.9]],"id":41419606}],"con":true,"img":false}]}
{"op":"mcm","clk":"5353541010","pt":1646216132059,"mc":[{"id":"1.195503866","rc":[{"atb":[[26,2.72]],"id":41419607},{"atb":[[44,9.9],[46,0],[55,4.95],[60,2.68]],"id":41419636},{"atl":[[270,4.95],[230,0]],"id":41419593},{"atl":[[220,4.95],[230,0.69]],"id":41419599},{"atl":[[130,1.23],[140,0]],"id":41419630},{"atb":[[65,4.95],[42,0],[48,9.9],[50,5.96]],"id":41419597},{"atl":[[130,1.23],[150,4.95]],"id":41419597},{"atb":[[75,0],[80,9.9],[95,1.68],[100,4.95]],"id":41419628},{"atb":[[16.5,22.08],[17,9.9],[18.5,9.05],[19,4.95]],"id":41419635},{"atb":[[16,0],[13.5,0]],"id":41419612},{"atl":[[36,7.38],[38,34.23]],"id":41419612},{"atl":[[130,0],[120,6.28]],"id":41419610},{"atb":[[16,19.57],[20,4.95],[21,10.65]],"id":41419592},{"atl":[[34,3.24],[40,4.95],[42,0],[48,9.9]],"id":41419592},{"atb":[[25,9.33]],"id":41419598},{"atl":[[42,8.29]],"id":41419598},{"atl":[[280,4.95],[240,0.66]],"id":41419596},{"atb":[[18.5,0],[19.5,9.9],[21,12.21],[23,4.95]],"id":41419594}],"con":true,"img":false}]}
{"op":"mcm","clk":"5353541031","pt":1646216132212,"mc":[{"id":"1.195503866","rc":[{"atl":[[600,2]],"id":41419599},{"atl":[[740,0],[380,2]],"id":41419597},{"atl":[[350,2],[460,3.01]],"id":41419610},{"atb":[[18,19.57],[19.5,9.9],[20,3.26],[23,4.95]],"id":41419598},{"atl":[[65,9.9],[42,3.34],[48,4.95],[50,0]],"id":41419598},{"atl":[[840,2],[930,0]],"id":41419596}],"con":true,"img":false}]}
{"op":"mcm","clk":"5353541047","pt":1646216132321,"mc":[{"id":"1.195503866","rc":[{"atl":[[990,0]],"id":41419599},{"atl":[[540,0],[130,2]],"id":41419598}],"con":true,"img":false}]}
{"op":"mcm","clk":"5353541066","pt":1646216132426,"mc":[{"id":"1.195503866","rc":[{"atl":[[990,1.49]],"id":41419599},{"atb":[[70,0]],"id":41419628}],"con":true,"img":false}]}
{"op":"mcm","clk":"5353541078","pt":1646216132530,"mc":[{"id":"1.195503866","rc":[{"atb":[[42,0],[44,26.6]],"id":41419636},{"atl":[[210,0.75],[1000,0]],"id":41419599},{"atb":[[70,2.29],[40,3.26],[48,24.62]],"id":41419597},{"atl":[[740,2],[850,0]],"id":41419597},{"atb":[[80,20.23],[110,1.45]],"id":41419628},{"atb":[[16.5,0],[18,30.27],[19.5,8.56]],"id":41419635},{"atb":[[11,20.8],[7.4,46.52]],"id":41419612},{"atl":[[140,10.64],[460,0]],"id":41419610},{"atb":[[16,0],[18,27.79]],"id":41419592},{"atl":[[48,29.48],[110,2]],"id":41419592},{"atl":[[930,1.59],[960,0]],"id":41419596},{"atb":[[21,0],[23,24.03]],"id":41419594}],"con":true,"img":false}]}
{"op":"mcm","clk":"5353541106","pt":1646216132738,"mc":[{"id":"1.195503866","rc":[{"atb":[[21,16.15]],"id":41419607},{"atl":[[330,6.51],[190,0]],"id":41419608},{"atl":[[36,2.86]],"id":41419612},{"atb":[[18,0],[20,17.98]],"id":41419598},{"atl":[[65,24.62],[510,0.31]],"id":41419598}],"con":true,"img":false}]}
{"op":"mcm","clk":"5353541122","pt":1646216132841,"mc":[{"id":"1.195503866","rc":[{"atl":[[130,0],[140,4.95]],"id":41419630},{"atb":[[12.5,3.26],[15,2.72]],"id":41419612},{"atl":[[500,0]],"id":41419592},{"atl":[[510,0]],"id":41419598}],"con":true,"img":false}]}
{"op":"mcm","clk":"5353541153","pt":1646216133046,"mc":[{"id":"1.195503866","rc":[{"atl":[[150,1.06]],"id":41419623}],"con":true,"img":false}]}
{"op":"mcm","clk":"5353541167","pt":1646216133152,"mc":[{"id":"1.195503866","rc":[{"atl":[[990,0]],"id":41419599}],"con":true,"img":false}]}
{"op":"mcm","clk":"5353541187","pt":1646216133362,"mc":[{"id":"1.195503866","rc":[{"atl":[[230,0]],"id":41419599},{"atb":[[50,2.72]],"id":41419597},{"atb":[[95,0]],"id":41419628},{"atb":[[18.5,0]],"id":41419635}],"con":true,"img":false}]}
{"op":"mcm","clk":"5353541221","pt":1646216133522,"mc":[{"id":"1.195503866","rc":[{"atl":[[36,15.07],[38,0]],"id":41419612}],"con":true,"img":false}]}
{"op":"mcm","clk":"5353541238","pt":1646216133628,"mc":[{"id":"1.195503866","rc":[{"atl":[[140,6.09]],"id":41419630}],"con":true,"img":false}]}
{"op":"mcm","clk":"5353541266","pt":1646216133839,"mc":[{"id":"1.195503866","rc":[{"atl":[[360,0]],"id":41419623}],"con":true,"img":false}]}
{"op":"mcm","clk":"5353541342","pt":1646216134326,"mc":[{"id":"1.195503866","rc":[{"atb":[[36,9.48]],"id":41419639}],"con":true,"img":false}]}
{"op":"mcm","clk":"5353541441","pt":1646216135060,"mc":[{"id":"1.195503866","rc":[{"atb":[[32,0]],"id":41419639}],"con":true,"img":false}]}
{"op":"mcm","clk":"5353541484","pt":1646216135327,"mc":[{"id":"1.195503866","rc":[{"atl":[[130,9.9],[90,0],[95,4.95],[120,0]],"id":41419633}],"con":true,"img":false}]}
{"op":"mcm","clk":"5353541527","pt":1646216135640,"mc":[{"id":"1.195503866","rc":[{"atb":[[28,16.51]],"id":41419639}],"con":true,"img":false}]}
{"op":"mcm","clk":"5353541538","pt":1646216135743,"mc":[{"id":"1.195503866","rc":[{"atb":[[29,9.9]],"id":41419639}],"con":true,"img":false}]}
{"op":"mcm","clk":"5353541581","pt":1646216136009,"mc":[{"id":"1.195503866","rc":[{"atl":[[95,6.63]],"id":41419633},{"atb":[[65,20.68],[90,1.78]],"id":41419596}],"con":true,"img":false}]}
{"op":"mcm","clk":"5353541669","pt":1646216136742,"mc":[{"id":"1.195503866","rc":[{"atb":[[70,0]],"id":41419596}],"con":true,"img":false}]}
{"op":"mcm","clk":"5353541704","pt":1646216137021,"mc":[{"id":"1.195503866","rc":[{"atl":[[1000,1.47]],"id":41419605},{"atl":[[670,2]],"id":41419620},{"atl":[[730,2],[780,0]],"id":41419626},{"atb":[[17.5,0],[14,7.69]],"id":41419639},{"atl":[[1000,2.15]],"id":41419625},{"atl":[[950,2],[1000,0]],"id":41419621},{"atb":[[12.5,0]],"id":41419594}],"con":true,"img":false}]}
{"op":"mcm","clk":"5353541716","pt":1646216137055,"mc":[{"id":"1.195503866","rc":[{"atl":[[770,0]],"id":41419620},{"atl":[[250,5.82]],"id":41419633},{"atb":[[10.5,10.53]],"id":41419594}],"con":true,"img":false}]}
{"op":"mcm","clk":"5353541746","pt":1646216137269,"mc":[{"id":"1.195503866","rc":[{"atb":[[18.5,0],[19,9.9],[21,12.21],[22,8.22],[27,8.82]],"id":41419640},{"atl":[[44,8.64]],"id":41419640},{"atb":[[21,12.88],[26,0]],"id":41419607},{"atl":[[300,0]],"id":41419605},{"atb":[[65,4.95],[44,16.69],[48,9.9],[55,0]],"id":41419636},{"atb":[[24,19.57],[25,9.9],[28,3.26],[29,4.95]],"id":41419611},{"atl":[[65,4.95],[80,2],[85,9.9],[100,0]],"id":41419589},{"atb":[[60,0]],"id":41419620},{"atl":[[150,9.9],[110,4.95],[120,1.32]],"id":41419620},{"atl":[[220,0],[240,4.95]],"id":41419599},{"atl":[[140,4.95],[150,0]],"id":41419597},{"atb":[[110,0]],"id":41419628},{"atl":[[190,4.95],[200,0.79]],"id":41419628},{"atl":[[130,1.23],[120,4.95]],"id":41419626},{"atb":[[44,0],[46,9.9],[55,5.66],[60,4.95]],"id":41419608},{"atl":[[85,4.95],[100,1.6],[110,9.9]],"id":41419639},{"atb":[[10.5,0],[13,0]],"id":41419637},{"atl":[[1000,0]],"id":41419604},{"atb":[[19,0]],"id":41419635},{"atl":[[34,4.95],[36,4.52],[42,9.9],[44,0]],"id":41419635},{"atb":[[11,22.08],[11.5,7.67],[9.8,9.9],[13,13.21]],"id":41419585},{"atb":[[9.6,0],[11,15.85],[11.5,4.95],[9.8,9.9]],"id":41419612},{"atl":[[36,12.21],[40,12.46]],"id":41419612},{"atb":[[40,23.31],[46,0],[48,4.95],[60,0]],"id":41419610},{"atl":[[38,4.95],[40,0],[46,9.9],[48,19.57]],"id":41419592},{"atb":[[65,2.47],[44,9.9],[48,22.08],[55,7.67]],"id":41419623},{"atl":[[260,0.61],[280,5.36],[210,4.95]],"id":41419621},{"atb":[[46,6.24]],"id":41419633},{"atl":[[65,14.71],[46,4.95],[48,0],[60,9.9]],"id":41419598},{"atl":[[280,0],[210,4.95]],"id":41419596},{"atl":[[80,2],[85,4.95],[100,0],[110,9.9]],"id":41419627}],"con":true,"img":false}]}
{"op":"mcm","clk":"5353541768","pt":1646216137422,"mc":[{"id":"1.195503866","rc":[{"atl":[[280,4.55],[160,2]],"id":41419589},{"atl":[[870,0],[440,2]],"id":41419628},{"atl":[[260,2],[660,0]],"id":41419639},{"atl":[[70,2],[100,12.77]],"id":41419635},{"atl":[[280,4.55],[230,2]],"id":41419627}],"con":true,"img":false}]}
{"op":"mcm","clk":"5353541783","pt":1646216137528,"mc":[{"id":"1.195503866","rc":[{"atl":[[140,0],[330,6.55]],"id":41419636}],"con":true,"img":false}]}
{"op":"mcm","clk":"5353541817","pt":1646216137733,"mc":[{"id":"1.195503866","rc":[{"atb":[[18.5,9.9],[13.5,41.21]],"id":41419607},{"atl":[[1000,0]],"id":41419605},{"atb":[[24,0],[28,15.48]],"id":41419611},{"atl":[[280,0],[85,27.62],[60,2.68]],"id":41419589},{"atb":[[40,17.43],[44,9.9]],"id":41419620},{"atl":[[150,19.94],[800,0]],"id":41419620},{"atl":[[160,9.4]],"id":41419630},{"atl":[[190,5.79],[870,1.72],[980,0]],"id":41419628},{"atl":[[730,4.05],[810,0],[110,1.45]],"id":41419626},{"atb":[[65,2.47],[42,3.26],[46,27.41]],"id":41419608},{"atb":[[10,22.56],[6.8,66.24]],"id":41419637},{"atl":[[34,9.76],[42,37.37],[100,0]],"id":41419635},{"atb":[[38,19.41],[40,9.9]],"id":41419610},{"atb":[[18,2.72],[18.5,9.9],[20,8.34],[21,4.95]],"id":41419590},{"atl":[[34,4.8],[36,4.95],[42,0],[44,9.9]],"id":41419590},{"atl":[[200,0.79]],"id":41419621},{"atl":[[200,0.79]],"id":41419596},{"atl":[[280,0],[110,23.59]],"id":41419627}],"con":true,"img":false}]}
{"op":"mcm","clk":"5353541846","pt":1646216137945,"mc":[{"id":"1.195503866","rc":[{"atl":[[520,0],[65,9.9],[44,3.68],[48,4.95],[55,0]],"id":41419640},{"atb":[[20,3.26],[25,2.72]],"id":41419607},{"atb":[[70,2.29]],"id":41419636},{"atl":[[130,4.95],[120,1.32]],"id":41419636},{"atb":[[55,7.89]],"id":41419620},{"atl":[[80,2],[690,0],[110,23.59]],"id":41419639},{"atb":[[48,8.32]],"id":41419610}],"con":true,"img":false}]}
{"op":"mcm","clk":"5353541861","pt":1646216138046,"mc":[{"id":"1.195503866","rc":[{"atb":[[100,6.55]],"id":41419628},{"atb":[[11,3.26],[13.5,2.72]],"id":41419637}],"con":true,"img":false}]}
{"op":"mcm","clk":"5353541891","pt":1646216138257,"mc":[{"id":"1.195503866","rc":[{"atl":[[110,6.4]],"id":41419620},{"atb":[[18.5,29.66],[21,12.88],[15.5,3.26]],"id":41419590},{"atl":[[44,29.66],[100,2]],"id":41419590}],"con":true,"img":false}]}
{"op":"mcm","clk":"5353541919","pt":1646216138416,"mc":[{"id":"1.195503866","rc":[{"atl":[[65,33.11],[140,2]],"id":41419640},{"atb":[[13.5,10.65]],"id":41419607},{"atl":[[80,0]],"id":41419589},{"atl":[[130,0]],"id":41419626},{"atb":[[55,2.72]],"id":41419608},{"atl":[[260,0]],"id":41419621},{"atl":[[560,2],[840,0],[240,0]],"id":41419596}],"con":true,"img":false}]}
{"op":"mcm","clk":"5353541950","pt":1646216138629,"mc":[{"id":"1.195503866","rc":[{"atl":[[200,0]],"id":41419628},{"atl":[[36,0]],"id":41419635}],"con":true,"img":false}]}
{"op":"mcm","clk":"5353541964","pt":1646216138731,"mc":[{"id":"1.195503866","rc":[{"atb":[[60,0]],"id":41419636},{"atl":[[100,0]],"id":41419639}],"con":true,"img":false}]}
{"op":"mcm","clk":"5353542001","pt":1646216139043,"mc":[{"id":"1.195503866","rc":[{"atl":[[120,0]],"id":41419620},{"atb":[[20,0]],"id":41419590}],"con":true,"img":false}]}
{"op":"mcm","clk":"5353542035","pt":1646216139360,"mc":[{"id":"1.195503866","rc":[{"atl":[[210,0]],"id":41419599}],"con":true,"img":false}]}
{"op":"mcm","clk":"5353542069","pt":1646216139622,"mc":[{"id":"1.195503866","rc":[{"atb":[[65,15.37],[80,9.9]],"id":41419628},{"atb":[[17,39.14]],"id":41419635},{"atl":[[350,6.31]],"id":41419610}],"con":true,"img":false}]}
{"op":"mcm","clk":"5353542087","pt":1646216139727,"mc":[{"id":"1.195503866","rc":[{"atl":[[840,2],[440,0]],"id":41419628},{"atb":[[18,2.72]],"id":41419635},{"atl":[[140,0]],"id":41419610}],"con":true,"img":false}]}
{"op":"mcm","clk":"5353542113","pt":1646216139936,"mc":[{"id":"1.195503866","rc":[{"atl":[[330,2],[190,7.95]],"id":41419608},{"atl":[[130,0],[140,9.9],[95,1.68],[100,4.95]],"id":41419633}],"con":true,"img":false}]}
{"op":"mcm","clk":"5353542161","pt":1646216140365,"mc":[{"id":"1.195503866","rc":[{"atl":[[240,5.61]],"id":41419599}],"con":true,"img":false}]}
{"op":"mcm","clk":"5353542192","pt":1646216140627,"mc":[{"id":"1.195503866","rc":[{"atl":[[350,2]],"id":41419610},{"atl":[[140,20.71],[250,0]],"id":41419633}],"con":true,"img":false}]}
{"op":"mcm","clk":"5353542231","pt":1646216140942,"mc":[{"id":"1.195503866","rc":[{"atl":[[190,0]],"id":41419608}],"con":true,"img":false}]}
{"op":"mcm","clk":"5353542305","pt":1646216141533,"mc":[{"id":"1.195503866","rc":[{"atl":[[95,13.9]],"id":41419607}],"con":true,"img":false}]}
{"op":"mcm","clk":"5353542318","pt":1646216141640,"mc":[{"id":"1.195503866","rc":[{"atl":[[90,2],[100,0]],"id":41419607}],"con":true,"img":false}]}
{"op":"mcm","clk":"5353542362","pt":1646216141942,"mc":[{"id":"1.195503866","rc":[{"atl":[[50,3.23]],"id":41419607}],"con":true,"img":false}]}
{"op":"mcm","clk":"5353542461","pt":1646216142626,"mc":[{"id":"1.195503866","rc":[{"atl":[[95,12.21]],"id":41419607}],"con":true,"img":false}]}
{"op":"mcm","clk":"5353542529","pt":1646216143149,"mc":[{"id":"1.195503866","rc":[{"atl":[[270,2],[670,0]],"id":41419620},{"atl":[[330,2],[730,2.05]],"id":41419626},{"atl":[[550,2],[950,0]],"id":41419621}],"con":true,"img":false}]}
{"op":"mcm","clk":"5353542553","pt":1646216143451,"mc":[{"id":"1.195503866","rc":[{"atl":[[38,2.7],[40,9.9]],"id":41419612}],"con":true,"img":false}]}
{"op":"mcm","clk":"5353542674","pt":1646216144441,"mc":[{"id":"1.195503866","rc":[{"atl":[[150,11.22],[85,1.88],[180,0]],"id":41419611},{"atl":[[270,7.64],[150,9.9]],"id":41419620},{"atl":[[270,7.64],[160,0]],"id":41419630},{"atl":[[70,23.79],[42,9.9]],"id":41419635}],"con":true,"img":false}]}
{"op":"mcm","clk":"5353542734","pt":1646216144963,"mc":[{"id":"1.195503866","rc":[{"atb":[[18.5,9.9],[18,29.22]],"id":41419590}],"con":true,"img":false}]}
{"op":"mcm","clk":"5353542765","pt":1646216145273,"mc":[{"id":"1.195503866","rc":[{"atl":[[38,22.29]],"id":41419606}],"con":true,"img":false}]}
{"op":"mcm","clk":"5353542778","pt":1646216145329,"mc":[{"id":"1.195503866","rc":[{"atl":[[150,10.16]],"id":41419611}],"con":true,"img":false}]}
{"op":"mcm","clk":"5353542889","pt":1646216146263,"mc":[{"id":"1.195503866","rc":[{"atl":[[260,5.88]],"id":41419599}],"con":true,"img":false}]}
{"op":"mcm","clk":"5353542910","pt":1646216146465,"mc":[{"id":"1.195503866","rc":[{"atb":[[44,0],[48,24.62]],"id":41419636},{"atl":[[380,6.02],[740,0]],"id":41419597},{"atb":[[11.5,19.66],[7.4,20.81]],"id":41419612},{"atl":[[46,31.99],[48,0]],"id":41419592}],"con":true,"img":false}]}
{"op":"mcm","clk":"5353542919","pt":1646216146574,"mc":[{"id":"1.195503866","rc":[{"atb":[[48,9.9],[50,10.18]],"id":41419597},{"atl":[[190,8.05]],"id":41419608},{"atl":[[140,10.93]],"id":41419610},{"atl":[[65,0],[60,31.13]],"id":41419598},{"atl":[[560,4.72],[930,0]],"id":41419596}],"con":true,"img":false}]}
{"op":"mcm","clk":"5353542938","pt":1646216146749,"mc":[{"id":"1.195503866","rc":[{"atl":[[290,2],[350,0]],"id":41419610}],"con":true,"img":false}]}
{"op":"mcm","clk":"5353543076","pt":1646216147876,"mc":[{"id":"1.195503866","rc":[{"atl":[[310,4.95]],"id":41419625}],"con":true,"img":false}]}
{"op":"mcm","clk":"5353543160","pt":1646216148544,"mc":[{"id":"1.195503866","rc":[{"atl":[[300,0.52]],"id":41419625}],"con":true,"img":false}]}
{"op":"mcm","clk":"5353543201","pt":1646216148960,"mc":[{"id":"1.195503866","rc":[{"atl":[[1000,3.68]],"id":41419625}],"con":true,"img":false}]}
{"op":"mcm","clk":"5353543240","pt":1646216149327,"mc":[{"id":"1.195503866","rc":[{"atl":[[1000,3.53]],"id":41419625}],"con":true,"img":false}]}
{"op":"mcm","clk":"5353543484","pt":1646216151465,"mc":[{"id":"1.195503866","rc":[{"atb":[[20,15.48]],"id":41419607},{"atl":[[270,2],[160,9.65]],"id":41419630},{"atl":[[330,6.67],[730,0]],"id":41419626},{"atb":[[46,9.9],[55,14.12]],"id":41419608},{"atb":[[10,56.43],[6.8,22.96]],"id":41419637}],"con":true,"img":false}]}
{"op":"mcm","clk":"5353543580","pt":1646216152146,"mc":[{"id":"1.195503866","rc":[{"atl":[[160,0]],"id":41419630}],"con":true,"img":false}]}
{"op":"mcm","clk":"5353543664","pt":1646216152980,"mc":[{"id":"1.195503866","rc":[{"atl":[[260,0]],"id":41419599}],"con":true,"img":false}]}
{"op":"mcm","clk":"5353543693","pt":1646216153247,"mc":[{"id":"1.195503866","rc":[{"atl":[[600,4.57]],"id":41419599},{"atl":[[330,6.69],[190,0]],"id":41419608},{"atl":[[140,0],[290,7.33]],"id":41419610}],"con":true,"img":false}]}
{"op":"mcm","clk":"5353543857","pt":1646216154659,"mc":[{"id":"1.195503866","rc":[{"atl":[[140,10.8],[100,0]],"id":41419633}],"con":true,"img":false}]}
{"op":"mcm","clk":"5353543882","pt":1646216154863,"mc":[{"id":"1.195503866","rc":[{"atl":[[600,2]],"id":41419599},{"atl":[[150,9.9],[110,4.95]],"id":41419633}],"con":true,"img":false}]}
{"op":"mcm","clk":"5353543893","pt":1646216154966,"mc":[{"id":"1.195503866","rc":[{"atl":[[290,0]],"id":41419605},{"atl":[[240,0.66],[250,4.95]],"id":41419599},{"atl":[[95,0]],"id":41419633}],"con":true,"img":false}]}
{"op":"mcm","clk":"5353543916","pt":1646216155172,"mc":[{"id":"1.195503866","rc":[{"atl":[[260,7.97],[140,0]],"id":41419633}],"con":true,"img":false}]}
{"op":"mcm","clk":"5353543943","pt":1646216155392,"mc":[{"id":"1.195503866","rc":[{"atl":[[75,30.65],[95,0]],"id":41419607}],"con":true,"img":false}]}
{"op":"mcm","clk":"5353543979","pt":1646216155650,"mc":[{"id":"1.195503866","rc":[{"atl":[[100,1.6]],"id":41419633}],"con":true,"img":false}]}
{"op":"mcm","clk":"5353544018","pt":1646216155955,"mc":[{"id":"1.195503866","rc":[{"atl":[[1000,0.15]],"id":41419605}],"con":true,"img":false}]}
{"op":"mcm","clk":"5353544277","pt":1646216157971,"mc":[{"id":"1.195503866","rc":[{"atl":[[600,0],[670,2]],"id":41419599}],"con":true,"img":false}]}
{"op":"mcm","clk":"5353544286","pt":1646216158073,"mc":[{"id":"1.195503866","rc":[{"atl":[[75,20.74],[40,4.95],[48,9.9],[55,0]],"id":41419607},{"atb":[[9.6,4.95],[9.2,0],[8.8,9.9],[8.4,0]],"id":41419634},{"atl":[[70,4.95],[150,0],[120,13.03]],"id":41419611},{"atb":[[20,0],[21,9.9],[24,6.89],[25,4.95]],"id":41419589},{"atl":[[12,4.95],[13.5,12.68],[14,9.9],[15.5,0]],"id":41419587},{"atb":[[32,9.9],[38,12.21],[40,4.95],[30,0]],"id":41419630},{"atl":[[160,9.72]],"id":41419630},{"atl":[[140,4.95],[170,0.93]],"id":41419608},{"atb":[[36,4.52],[38,4.95],[29,0],[30,9.9]],"id":41419639},{"atb":[[10,51.48],[9.2,0],[10.5,4.95],[9.4,9.9]],"id":41419637},{"atl":[[21,4.95],[23,0],[25,9.9],[27,24.97]],"id":41419585},{"atl":[[32,0],[40,0],[23,4.95],[27,9.9]],"id":41419612},{"atb":[[34,9.9],[38,0],[42,4.95],[30,0]],"id":41419633},{"atb":[[65,10.77],[75,9.9],[85,0],[95,4.95]],"id":41419596},{"atb":[[36,0],[29,17.98]],"id":41419627},{"atl":[[65,9.9],[75,0],[48,4.95],[55,2.93]],"id":41419594}],"con":true,"img":false}]}
{"op":"mcm","clk":"5353544316","pt":1646216158384,"mc":[{"id":"1.195503866","rc":[{"atb":[[8,27.04],[7.2,9.9],[7.8,0],[7,43.51]],"id":41419591},{"atb":[[65,0]],"id":41419608},{"atb":[[38,11.96],[30,9.9]],"id":41419627}],"con":true,"img":false}]}
{"op":"mcm","clk":"5353544328","pt":1646216158476,"mc":[{"id":"1.195503866","rc":[{"atb":[[8.6,2.72],[9.8,18.01],[8.8,49.45]],"id":41419634},{"atl":[[70,7.25]],"id":41419611},{"atb":[[19,2.72],[21,27.5],[25,11.55]],"id":41419589},{"atl":[[14,36.85]],"id":41419587},{"atb":[[38,0],[40,17.17]],"id":41419630},{"atb":[[28,2.72],[30,24.62]],"id":41419639},{"atl":[[27,0]],"id":41419585},{"atl":[[36,0],[30,20.95]],"id":41419612},{"atb":[[65,0]],"id":41419596},{"atl":[[65,22.12]],"id":41419594}],"con":true,"img":false}]}
{"op":"mcm","clk":"5353544340","pt":1646216158579,"mc":[{"id":"1.195503866","rc":[{"atl":[[40,9.01]],"id":41419607},{"atl":[[32,0],[11.5,15.1]],"id":41419587},{"atb":[[38,9.23]],"id":41419639},{"atl":[[25,36.05]],"id":41419585},{"atl":[[23,12.15]],"id":41419612},{"atl":[[140,2]],"id":41419594}],"con":true,"img":false}]}
{"op":"mcm","clk":"5353544354","pt":1646216158688,"mc":[{"id":"1.195503866","rc":[{"atb":[[75,24.27]],"id":41419596}],"con":true,"img":false}]}
{"op":"mcm","clk":"5353544358","pt":1646216158794,"mc":[{"id":"1.195503866","rc":[{"atl":[[140,6.09]],"id":41419608},{"atl":[[17.5,4.95],[19.5,9.9],[24,6.89],[28,0]],"id":41419606},{"atl":[[18.5,4.95],[25,0]],"id":41419637},{"atl":[[20,8.34]],"id":41419585},{"atl":[[130,4.95]],"id":41419623},{"atl":[[150,0],[110,0]],"id":41419633},{"atb":[[95,6.63]],"id":41419596},{"atb":[[16,27],[29,3.26]],"id":41419627}],"con":true,"img":false}]}
{"op":"mcm","clk":"5353544368","pt":1646216158844,"mc":[{"id":"1.195503866","rc":[{"atl":[[160,0]],"id":41419623},{"atl":[[140,9.9],[100,6.55]],"id":41419633}],"con":true,"img":false}]}
{"op":"mcm","clk":"5353544392","pt":1646216159053,"mc":[{"id":"1.195503866","rc":[{"atb":[[46,27.21],[55,2.72],[60,7.64]],"id":41419608}],"con":true,"img":false}]}
{"op":"mcm","clk":"5353544403","pt":1646216159154,"mc":[{"id":"1.195503866","rc":[{"atb":[[9.4,0]],"id":41419634},{"atl":[[17.5,14.56],[24,24.49]],"id":41419606},{"atl":[[160,9.78],[370,2]],"id":41419623}],"con":true,"img":false}]}
{"op":"mcm","clk":"5353544408","pt":1646216159257,"mc":[{"id":"1.195503866","rc":[{"atl":[[85,0]],"id":41419611},{"atb":[[24,0]],"id":41419589},{"atl":[[38,2.7]],"id":41419606}],"con":true,"img":false}]}
{"op":"mcm","clk":"5353544419","pt":1646216159364,"mc":[{"id":"1.195503866","rc":[{"atl":[[50,0]],"id":41419607},{"atl":[[13.5,0]],"id":41419587},{"atb":[[36,0]],"id":41419639},{"atl":[[30,15.48]],"id":41419612},{"atl":[[130,6.18]],"id":41419623}],"con":true,"img":false}]}
{"op":"mcm","clk":"5353544427","pt":1646216159473,"mc":[{"id":"1.195503866","rc":[{"atl":[[18.5,14.01]],"id":41419637}],"con":true,"img":false}]}
{"op":"mcm","clk":"5353544440","pt":1646216159581,"mc":[{"id":"1.195503866","rc":[{"atl":[[170,0]],"id":41419608},{"atl":[[22,0]],"id":41419585},{"atb":[[90,0]],"id":41419596}],"con":true,"img":false}]}
{"op":"mcm","clk":"5353544470","pt":1646216159794,"mc":[{"id":"1.195503866","rc":[{"atl":[[140,0],[150,9.9],[100,0],[110,4.95]],"id":41419633}],"con":true,"img":false}]}
{"op":"mcm","clk":"5353544484","pt":1646216159849,"mc":[{"id":"1.195503866","rc":[{"atl":[[670,4.33]],"id":41419599}],"con":true,"img":false}]}
{"op":"mcm","clk":"5353544519","pt":1646216160063,"mc":[{"id":"1.195503866","rc":[{"atl":[[260,4.95],[240,0],[250,0]],"id":41419599},{"atl":[[24,17.59]],"id":41419606}],"con":true,"img":false}]}
{"op":"mcm","clk":"5353544529","pt":1646216160161,"mc":[{"id":"1.195503866","rc":[{"atl":[[160,9.8]],"id":41419608},{"atl":[[140,11.21]],"id":41419610},{"atl":[[150,0]],"id":41419623}],"con":true,"img":false}]}
{"op":"mcm","clk":"5353544542","pt":1646216160270,"mc":[{"id":"1.195503866","rc":[{"atl":[[330,2]],"id":41419608},{"atl":[[290,2]],"id":41419610}],"con":true,"img":false}]}
{"op":"mcm","clk":"5353544572","pt":1646216160485,"mc":[{"id":"1.195503866","rc":[{"atl":[[21,4.95]],"id":41419637}],"con":true,"img":false}]}
{"op":"mcm","clk":"5353544595","pt":1646216160594,"mc":[{"id":"1.195503866","rc":[{"atl":[[110,6.4]],"id":41419633}],"con":true,"img":false}]}
{"op":"mcm","clk":"5353544641","pt":1646216160866,"mc":[{"id":"1.195503866","rc":[{"atl":[[260,5.56]],"id":41419599},{"atl":[[160,0]],"id":41419608},{"atl":[[140,0]],"id":41419610}],"con":true,"img":false}]}
{"op":"mcm","clk":"5353544884","pt":1646216162764,"mc":[{"id":"1.195503866","rc":[{"atl":[[140,1.13]],"id":41419630}],"con":true,"img":false}]}
{"op":"mcm","clk":"5353544906","pt":1646216162964,"mc":[{"id":"1.195503866","rc":[{"atl":[[130,4.95]],"id":41419630}],"con":true,"img":false}]}
{"op":"mcm","clk":"5353544970","pt":1646216163384,"mc":[{"id":"1.195503866","rc":[{"atl":[[130,6.18]],"id":41419630}],"con":true,"img":false}]}
{"op":"mcm","clk":"5353545069","pt":1646216164077,"mc":[{"id":"1.195503866","rc":[{"atl":[[140,0]],"id":41419630}],"con":true,"img":false}]}
{"op":"mcm","clk":"5353545155","pt":1646216164674,"mc":[{"id":"1.195503866","rc":[{"atl":[[160,0]],"id":41419630}],"con":true,"img":false}]}
{"op":"mcm","clk":"5353545168","pt":1646216164774,"mc":[{"id":"1.195503866","rc":[{"atb":[[5,0],[5.5,22.22]],"id":41419634},{"atb":[[18,5.88],[15,0]],"id":41419630},{"atb":[[16.5,6.45],[13.5,0]],"id":41419633},{"atb":[[16,20.33],[20,5.26]],"id":41419627}],"con":true,"img":false}]}
{"op":"mcm","clk":"5353545195","pt":1646216164983,"mc":[{"id":"1.195503866","rc":[{"atl":[[40,0],[42,4.95],[48,0],[50,9.9]],"id":41419607},{"atl":[[70,0],[75,4.95],[90,0],[95,9.9]],"id":41419611},{"atl":[[11.5,0]],"id":41419587},{"atl":[[270,7.85]],"id":41419630},{"atl":[[140,0],[150,4.95]],"id":41419608},{"atl":[[17.5,0],[19.5,0],[19,4.95],[22,9.9]],"id":41419606},{"atb":[[10,17.61],[10.5,19.66]],"id":41419637},{"atl":[[18.5,0],[19,4.95],[21,0],[22,9.9]],"id":41419637},{"atl":[[23,0],[27,0]],"id":41419612},{"atb":[[70,9.9],[75,14.37],[90,4.95],[95,0]],"id":41419596},{"atl":[[65,12.21],[70,9.9],[48,0],[50,4.95]],"id":41419594}],"con":true,"img":false}]}
{"op":"mcm","clk":"5353545212","pt":1646216165190,"mc":[{"id":"1.195503866","rc":[{"atb":[[19,27.26],[21,9.9]],"id":41419589},{"atb":[[28,23.81],[30,9.9]],"id":41419639},{"atl":[[24,4.95],[28,9.9]],"id":41419612},{"atb":[[75,0],[55,17.09]],"id":41419596}],"con":true,"img":false}]}
{"op":"mcm","clk":"5353545256","pt":1646216165458,"mc":[{"id":"1.195503866","rc":[{"atl":[[320,4.95]],"id":41419605},{"atl":[[34,22.6],[14,9.9]],"id":41419587},{"atl":[[34,9.72],[30,0]],"id":41419612},{"atl":[[50,8.19]],"id":41419594}],"con":true,"img":false}]}
{"op":"mcm","clk":"5353545286","pt":1646216165670,"mc":[{"id":"1.195503866","rc":[{"atl":[[70,2.29],[75,0],[95,0]],"id":41419611},{"atl":[[14,22.1]],"id":41419587},{"atl":[[21,7.92]],"id":41419637},{"atl":[[160,0],[370,6.27]],"id":41419623},{"atb":[[60,2.68]],"id":41419596}],"con":true,"img":false}]}
{"op":"mcm","clk":"5353545318","pt":1646216165880,"mc":[{"id":"1.195503866","rc":[{"atl":[[70,2.29]],"id":41419607},{"atl":[[320,0.49]],"id":41419608},{"atl":[[23,7.2]],"id":41419606},{"atl":[[19,0],[22,0]],"id":41419637},{"atl":[[29,5.66]],"id":41419612}],"con":true,"img":false}]}
{"op":"mcm","clk":"5353545356","pt":1646216166192,"mc":[{"id":"1.195503866","rc":[{"atl":[[160,11.91],[120,0]],"id":41419611},{"atl":[[22,19.14],[29,3.57]],"id":41419637},{"atl":[[55,0]],"id":41419594}],"con":true,"img":false}]}
{"op":"mcm","clk":"5353545388","pt":1646216166456,"mc":[{"id":"1.195503866","rc":[{"atl":[[70,7.25],[90,9.9]],"id":41419611},{"atl":[[370,2]],"id":41419623}],"con":true,"img":false}]}
{"op":"mcm","clk":"5353545412","pt":1646216166665,"mc":[{"id":"1.195503866","rc":[{"atl":[[280,5.66]],"id":41419599},{"atl":[[330,6.8]],"id":41419608},{"atl":[[18.5,4.95],[21,17.83]],"id":41419637},{"atl":[[140,11.34]],"id":41419610},{"atl":[[65,0],[70,32.59]],"id":41419594}],"con":true,"img":false}]}
{"op":"mcm","clk":"5353545436","pt":1646216166826,"mc":[{"id":"1.195503866","rc":[{"atl":[[670,2]],"id":41419599}],"con":true,"img":false}]}
{"op":"mcm","clk":"5353545492","pt":1646216167353,"mc":[{"id":"1.195503866","rc":[{"atl":[[280,0]],"id":41419599}],"con":true,"img":false}]}
{"op":"mcm","clk":"5353545677","pt":1646216168877,"mc":[{"id":"1.195503866","rc":[{"atl":[[75,0]],"id":41419607}],"con":true,"img":false}]}
{"op":"mcm","clk":"5353545691","pt":1646216168982,"mc":[{"id":"1.195503866","rc":[{"atl":[[70,24.38]],"id":41419607},{"atl":[[70,0],[75,4.95],[90,0],[95,9.9]],"id":41419611},{"atl":[[18.5,0],[19,4.95],[21,7.92],[22,29.05]],"id":41419637}],"con":true,"img":false}]}
{"op":"mcm","clk":"5353545739","pt":1646216169353,"mc":[{"id":"1.195503866","rc":[{"atl":[[320,5.44]],"id":41419605}],"con":true,"img":false}]}
{"op":"mcm","clk":"5353545780","pt":1646216169675,"mc":[{"id":"1.195503866","rc":[{"atl":[[75,0],[95,0]],"id":41419611}],"con":true,"img":false}]}
{"op":"mcm","clk":"5353545846","pt":1646216170100,"mc":[{"id":"1.195503866","rc":[{"atl":[[70,2.29]],"id":41419611}],"con":true,"img":false}]}
{"op":"mcm","clk":"5353545884","pt":1646216170368,"mc":[{"id":"1.195503866","rc":[{"atl":[[1000,0]],"id":41419605}],"con":true,"img":false}]}
{"op":"mcm","clk":"5353545952","pt":1646216170787,"mc":[{"id":"1.195503866","rc":[{"atl":[[70,7.25],[90,9.9]],"id":41419611}],"con":true,"img":false}]}
{"op":"mcm","clk":"5353546053","pt":1646216171477,"mc":[{"id":"1.195503866","rc":[{"atl":[[270,2]],"id":41419630}],"con":true,"img":false}]}
{"op":"mcm","clk":"5353546102","pt":1646216171794,"mc":[{"id":"1.195503866","rc":[{"atl":[[70,0],[75,4.95],[90,0],[95,9.9]],"id":41419611},{"atl":[[150,10.67]],"id":41419630}],"con":true,"img":false}]}
{"op":"mcm","clk":"5353546144","pt":1646216172061,"mc":[{"id":"1.195503866","rc":[{"atl":[[42,8.82]],"id":41419607},{"atl":[[12,19.36]],"id":41419587},{"atl":[[34,0],[23,7.2],[29,21.43]],"id":41419612},{"atb":[[90,6.73],[55,2.72],[60,17.05]],"id":41419596}],"con":true,"img":false}]}
{"op":"mcm","clk":"5353546157","pt":1646216172167,"mc":[{"id":"1.195503866","rc":[{"atl":[[140,1.13]],"id":41419608},{"atb":[[16,0],[29,25.35]],"id":41419627}],"con":true,"img":false}]}
{"op":"mcm","clk":"5353546206","pt":1646216172482,"mc":[{"id":"1.195503866","rc":[{"atl":[[150,10.69]],"id":41419623}],"con":true,"img":false}]}
{"op":"mcm","clk":"5353546269","pt":1646216172794,"mc":[{"id":"1.195503866","rc":[{"atl":[[150,1.06]],"id":41419611},{"atl":[[19,13.76],[23,25.26],[24,0]],"id":41419606}],"con":true,"img":false}]}
{"op":"mcm","clk":"5353546284","pt":1646216172901,"mc":[{"id":"1.195503866","rc":[{"atl":[[70,22.08]],"id":41419607},{"atl":[[14,9.9]],"id":41419587},{"atl":[[29,15.77]],"id":41419612},{"atb":[[60,14.37]],"id":41419596}],"con":true,"img":false}]}
{"op":"mcm","clk":"5353546318","pt":1646216173064,"mc":[{"id":"1.195503866","rc":[{"atl":[[320,0]],"id":41419608}],"con":true,"img":false}]}
{"op":"mcm","clk":"5353546328","pt":1646216173171,"mc":[{"id":"1.195503866","rc":[{"atl":[[140,0],[290,7.53]],"id":41419610},{"atl":[[70,9.9],[140,13.47]],"id":41419594}],"con":true,"img":false}]}
{"op":"mcm","clk":"5353546370","pt":1646216173479,"mc":[{"id":"1.195503866","rc":[{"atl":[[280,5.73]],"id":41419599},{"atl":[[330,2],[320,5.01]],"id":41419608}],"con":true,"img":false}]}
{"op":"mcm","clk":"5353546381","pt":1646216173583,"mc":[{"id":"1.195503866","rc":[{"atl":[[23,18.06]],"id":41419606}],"con":true,"img":false}]}
{"op":"mcm","clk":"5353546415","pt":1646216173793,"mc":[{"id":"1.195503866","rc":[{"atl":[[150,11.77],[160,2]],"id":41419611},{"atl":[[140,0]],"id":41419608},{"atl":[[23,0]],"id":41419612}],"con":true,"img":false}]}
{"op":"mcm","clk":"5353546506","pt":1646216174483,"mc":[{"id":"1.195503866","rc":[{"atl":[[27,6.09]],"id":41419612}],"con":true,"img":false}]}
{"op":"mcm","clk":"5353546586","pt":1646216174901,"mc":[{"id":"1.195503866","rc":[{"atl":[[140,1.13]],"id":41419608}],"con":true,"img":false}]}
{"op":"mcm","clk":"5353546933","pt":1646216177378,"mc":[{"id":"1.195503866","rc":[{"atb":[[36,4.95],[38,0],[29,9.9],[30,0]],"id":41419639},{"atl":[[19,8.8],[22,0]],"id":41419606},{"atl":[[24,0],[25,4.95],[28,0],[29,25.67]],"id":41419612}],"con":true,"img":false}]}
{"op":"mcm","clk":"5353546979","pt":1646216177686,"mc":[{"id":"1.195503866","rc":[{"atl":[[130,0],[140,4.95]],"id":41419630},{"atl":[[140,0]],"id":41419608},{"atl":[[19,0],[19.5,4.95],[23,27.96]],"id":41419606}],"con":true,"img":false}]}
{"op":"mcm","clk":"5353547038","pt":1646216178104,"mc":[{"id":"1.195503866","rc":[{"atb":[[36,0],[29,0]],"id":41419639}],"con":true,"img":false}]}
{"op":"mcm","clk":"5353547090","pt":1646216178509,"mc":[{"id":"1.195503866","rc":[{"atl":[[270,7.99],[130,1.23],[150,0]],"id":41419630},{"atl":[[140,1.13]],"id":41419608},{"atb":[[29,5.66]],"id":41419639},{"atl":[[22,7.54]],"id":41419606}],"con":true,"img":false}]}
{"op":"mcm","clk":"5353547131","pt":1646216178771,"mc":[{"id":"1.195503866","rc":[{"atb":[[16.5,28.72],[28,2.72]],"id":41419639}],"con":true,"img":false}]}
{"op":"mcm","clk":"5353547173","pt":1646216179186,"mc":[{"id":"1.195503866","rc":[{"atl":[[70,2.29]],"id":41419611},{"atb":[[38,4.95],[30,9.9]],"id":41419639},{"atl":[[26,6.34]],"id":41419612},{"atl":[[150,0],[370,6.37]],"id":41419623}],"con":true,"img":false}]}
{"op":"mcm","clk":"5353547232","pt":1646216179707,"mc":[{"id":"1.195503866","rc":[{"atl":[[150,1.06]],"id":41419611}],"con":true,"img":false}]}
{"op":"mcm","clk":"5353547260","pt":1646216179876,"mc":[{"id":"1.195503866","rc":[{"atl":[[70,0],[150,0],[95,24.62]],"id":41419611},{"atl":[[280,0],[670,4.41]],"id":41419599},{"atl":[[27,16.42],[29,9.9]],"id":41419612}],"con":true,"img":false}]}
{"op":"mcm","clk":"5353547282","pt":1646216180025,"mc":[{"id":"1.195503866","rc":[{"atl":[[140,11.6],[290,2]],"id":41419610}],"con":true,"img":false}]}
{"op":"mcm","clk":"5353547352","pt":1646216180596,"mc":[{"id":"1.195503866","rc":[{"atl":[[75,7.09]],"id":41419611}],"con":true,"img":false}]}
{"op":"mcm","clk":"5353547468","pt":1646216181602,"mc":[{"id":"1.195503866","rc":[{"atl":[[1000,0.15]],"id":41419604}],"con":true,"img":false}]}
{"op":"mcm","clk":"5353547793","pt":1646216183987,"mc":[{"id":"1.195503866","rc":[{"atl":[[44,4.95],[55,9.9]],"id":41419607},{"atl":[[75,4.95],[80,4.95],[100,9.9]],"id":41419611},{"atl":[[140,0]],"id":41419608},{"atb":[[36,4.95],[29,15.57]],"id":41419639},{"atl":[[20,4.95],[24,9.9]],"id":41419606},{"atl":[[25,0],[26,11.29],[29,0]],"id":41419612}],"con":true,"img":false}]}
{"op":"mcm","clk":"5353547807","pt":1646216184090,"mc":[{"id":"1.195503866","rc":[{"atl":[[42,0],[50,0]],"id":41419607},{"atl":[[75,0],[95,14.71]],"id":41419611},{"atb":[[21,0],[25,0]],"id":41419589},{"atl":[[130,0]],"id":41419630},{"atb":[[38,0],[30,0]],"id":41419639},{"atl":[[19.5,0],[23,18.06]],"id":41419606},{"atl":[[19,0],[19.5,4.95],[22,19.14],[23,9.9]],"id":41419637}],"con":true,"img":false}]}
{"op":"mcm","clk":"5353547822","pt":1646216184196,"mc":[{"id":"1.195503866","rc":[{"atb":[[14,7.69]],"id":41419589}],"con":true,"img":false}]}
{"op":"mcm","clk":"5353547838","pt":1646216184301,"mc":[{"id":"1.195503866","rc":[{"atb":[[20,9.9],[24,4.95],[15.5,0]],"id":41419589}],"con":true,"img":false}]}
{"op":"mcm","clk":"5353547883","pt":1646216184676,"mc":[{"id":"1.195503866","rc":[{"atl":[[70,0],[50,27.83]],"id":41419607},{"atb":[[19,2.72],[15.5,17.61]],"id":41419589},{"atl":[[320,0],[330,6.95]],"id":41419608},{"atl":[[19.5,13.52]],"id":41419637}],"con":true,"img":false}]}
{"op":"mcm","clk":"5353547902","pt":1646216184785,"mc":[{"id":"1.195503866","rc":[{"atl":[[75,2.14],[80,0],[100,0]],"id":41419611},{"atb":[[19.5,8.56]],"id":41419589},{"atl":[[130,1.23]],"id":41419630},{"atl":[[140,1.13]],"id":41419608},{"atb":[[36,0],[29,5.66]],"id":41419639}],"con":true,"img":false}]}
{"op":"mcm","clk":"5353547927","pt":1646216184992,"mc":[{"id":"1.195503866","rc":[{"atl":[[65,2.47]],"id":41419607},{"atl":[[270,2],[160,10.24]],"id":41419630}],"con":true,"img":false}]}
{"op":"mcm","clk":"5353547985","pt":1646216185413,"mc":[{"id":"1.195503866","rc":[{"atl":[[25,6.6]],"id":41419612}],"con":true,"img":false}]}
{"op":"mcm","clk":"5353547999","pt":1646216185519,"mc":[{"id":"1.195503866","rc":[{"atl":[[50,0]],"id":41419607},{"atl":[[75,7.09],[95,24.62]],"id":41419611},{"atl":[[140,0]],"id":41419608},{"atb":[[38,4.95],[30,9.9]],"id":41419639},{"atl":[[21,0]],"id":41419637},{"atl":[[370,2]],"id":41419623}],"con":true,"img":false}]}
{"op":"mcm","clk":"5353548029","pt":1646216185687,"mc":[{"id":"1.195503866","rc":[{"atl":[[150,10.93]],"id":41419623}],"con":true,"img":false}]}
{"op":"mcm","clk":"5353548093","pt":1646216186109,"mc":[{"id":"1.195503866","rc":[{"atl":[[21,7.92]],"id":41419606},{"atl":[[22,0],[23,44.73]],"id":41419637}],"con":true,"img":false}]}
{"op":"mcm","clk":"5353548129","pt":1646216186419,"mc":[{"id":"1.195503866","rc":[{"atl":[[160,12.26],[95,9.9]],"id":41419611},{"atl":[[150,6.01]],"id":41419608},{"atl":[[26,4.95]],"id":41419612},{"atl":[[140,0],[290,7.66]],"id":41419610}],"con":true,"img":false}]}
{"op":"mcm","clk":"5353548187","pt":1646216186700,"mc":[{"id":"1.195503866","rc":[{"atl":[[280,5.86]],"id":41419599},{"atl":[[330,2],[170,9.66]],"id":41419608},{"atl":[[23,0]],"id":41419606}],"con":true,"img":false}]}
{"op":"mcm","clk":"5353548206","pt":1646216186795,"mc":[{"id":"1.195503866","rc":[{"atl":[[670,2]],"id":41419599},{"atl":[[22,26.12]],"id":41419606}],"con":true,"img":false}]}
{"op":"mcm","clk":"5353548251","pt":1646216187117,"mc":[{"id":"1.195503866","rc":[{"atl":[[130,0]],"id":41419630},{"atb":[[36,4.95],[38,0],[29,15.57],[30,0]],"id":41419639},{"atl":[[22,18.57]],"id":41419606}],"con":true,"img":false}]}
{"op":"mcm","clk":"5353548295","pt":1646216187384,"mc":[{"id":"1.195503866","rc":[{"atl":[[280,0]],"id":41419599}],"con":true,"img":false}]}
{"op":"mcm","clk":"5353548358","pt":1646216187814,"mc":[{"id":"1.195503866","rc":[{"atl":[[260,0.61],[240,4.95]],"id":41419599},{"atl":[[130,9.9],[95,4.95],[120,1.32]],"id":41419610}],"con":true,"img":false}]}
{"op":"mcm","clk":"5353548406","pt":1646216188117,"mc":[{"id":"1.195503866","rc":[{"atl":[[140,6.09]],"id":41419630}],"con":true,"img":false}]}
{"op":"mcm","clk":"5353548456","pt":1646216188396,"mc":[{"id":"1.195503866","rc":[{"atl":[[230,0.69]],"id":41419599}],"con":true,"img":false}]}
{"op":"mcm","clk":"5353548474","pt":1646216188505,"mc":[{"id":"1.195503866","rc":[{"atl":[[90,1.79]],"id":41419610}],"con":true,"img":false}]}
{"op":"mcm","clk":"5353548579","pt":1646216189092,"mc":[{"id":"1.195503866","rc":[{"atl":[[260,0]],"id":41419599}],"con":true,"img":false}]}
{"op":"mcm","clk":"5353548643","pt":1646216189511,"mc":[{"id":"1.195503866","rc":[{"atb":[[12.5,0],[15,0]],"id":41419612},{"atl":[[120,0]],"id":41419610}],"con":true,"img":false}]}
{"op":"mcm","clk":"5353548716","pt":1646216189986,"mc":[{"id":"1.195503866","rc":[{"atb":[[11.5,4.95]],"id":41419612}],"con":true,"img":false}]}
{"op":"mcm","clk":"5353548746","pt":1646216190301,"mc":[{"id":"1.195503866","rc":[{"atb":[[11.5,20.05],[9.8,48.19],[13,3.26],[15.5,2.72]],"id":41419612}],"con":true,"img":false}]}
{"op":"mcm","clk":"5353548840","pt":1646216190981,"mc":[{"id":"1.195503866","rc":[{"atb":[[11,0]],"id":41419612}],"con":true,"img":false}]}
{"op":"mcm","clk":"5353548874","pt":1646216191294,"mc":[{"id":"1.195503866","rc":[{"atl":[[270,8.13],[160,0]],"id":41419630},{"atl":[[330,7.01],[170,0]],"id":41419608}],"con":true,"img":false}]}
{"op":"mcm","clk":"5353548899","pt":1646216191508,"mc":[{"id":"1.195503866","rc":[{"atb":[[36,9.48]],"id":41419639},{"atl":[[20,13.29]],"id":41419606}],"con":true,"img":false}]}
{"op":"mcm","clk":"5353548933","pt":1646216191819,"mc":[{"id":"1.195503866","rc":[{"atb":[[16.5,8.59],[28,17.43]],"id":41419639}],"con":true,"img":false}]}
{"op":"mcm","clk":"5353548959","pt":1646216191980,"mc":[{"id":"1.195503866","rc":[{"atl":[[150,0],[370,6.47]],"id":41419623}],"con":true,"img":false}]}
{"op":"mcm","clk":"5353548977","pt":1646216192187,"mc":[{"id":"1.195503866","rc":[{"atl":[[270,0],[260,4.95]],"id":41419593},{"atb":[[13,0],[15.5,0]],"id":41419612}],"con":true,"img":false}]}
{"op":"mcm","clk":"5353549001","pt":1646216192394,"mc":[{"id":"1.195503866","rc":[{"atb":[[29,9.9]],"id":41419639},{"atl":[[21,0]],"id":41419606}],"con":true,"img":false}]}
{"op":"mcm","clk":"5353549010","pt":1646216192499,"mc":[{"id":"1.195503866","rc":[{"atl":[[23,9.9],[29,28.97]],"id":41419637}],"con":true,"img":false}]}
{"op":"mcm","clk":"5353549032","pt":1646216192711,"mc":[{"id":"1.195503866","rc":[{"atl":[[370,2]],"id":41419623}],"con":true,"img":false}]}
{"op":"mcm","clk":"5353549047","pt":1646216192813,"mc":[{"id":"1.195503866","rc":[{"atl":[[670,4.47]],"id":41419599}],"con":true,"img":false}]}
{"op":"mcm","clk":"5353549089","pt":1646216193077,"mc":[{"id":"1.195503866","rc":[{"atl":[[22,0],[24,44.4]],"id":41419606},{"atb":[[16,2.72],[13.5,3.26]],"id":41419612},{"atl":[[130,22.69],[290,2]],"id":41419610}],"con":true,"img":false}]}
{"op":"mcm","clk":"5353549625","pt":1646216196520,"mc":[{"id":"1.195503866","rc":[{"atl":[[80,2],[90,0]],"id":41419607}],"con":true,"img":false}]}
{"op":"mcm","clk":"5353549655","pt":1646216196790,"mc":[{"id":"1.195503866","rc":[{"atl":[[320,0.49],[330,4.95]],"id":41419605},{"atl":[[75,0],[80,4.95],[95,0],[100,9.9]],"id":41419611},{"atb":[[7.6,3.26],[6.8,26.94],[7.8,4.95],[7,9.9]],"id":41419587},{"atl":[[12,4.95]],"id":41419587},{"atl":[[150,0],[160,4.95]],"id":41419608},{"atl":[[20,0],[21,4.95],[24,34.49],[25,9.9]],"id":41419606},{"atl":[[1000,0]],"id":41419604},{"atb":[[19.5,0]],"id":41419635},{"atl":[[32,4.95],[34,4.8],[40,9.9],[42,0]],"id":41419635},{"atb":[[16,0],[13.5,0]],"id":41419612},{"atl":[[25,0]],"id":41419612},{"atl":[[130,0],[140,4.95]],"id":41419623},{"atl":[[70,0],[80,4.95],[90,16.06],[100,9.9]],"id":41419586},{"atl":[[44,4.95],[46,0],[55,9.9],[60,21.22]],"id":41419598}],"con":true,"img":false}]}
{"op":"mcm","clk":"5353549701","pt":1646216197205,"mc":[{"id":"1.195503866","rc":[{"atl":[[330,4.55],[460,2]],"id":41419636},{"atl":[[790,0],[1000,2]],"id":41419593},{"atl":[[270,5.64],[360,2]],"id":41419620},{"atb":[[7.6,17.98]],"id":41419587},{"atl":[[1000,0.15]],"id":41419601},{"atl":[[670,2.47],[860,2]],"id":41419599},{"atl":[[270,6.13],[370,2]],"id":41419630},{"atl":[[380,4.02],[460,2]],"id":41419597},{"atl":[[330,4.67],[420,2]],"id":41419626},{"atl":[[330,5.01],[430,2]],"id":41419608},{"atl":[[260,0],[330,2]],"id":41419639},{"atl":[[40,2.56],[29,25.4]],"id":41419637},{"atb":[[17,9.9],[15.5,17.77]],"id":41419635},{"atl":[[32,10.06],[70,2],[40,24.41]],"id":41419635},{"atb":[[9.8,9.9]],"id":41419612},{"atl":[[27,0]],"id":41419612},{"atl":[[290,0],[370,2]],"id":41419610},{"atl":[[1000,1.53]],"id":41419625},{"atl":[[370,0],[430,2]],"id":41419623},{"atl":[[550,0],[690,2]],"id":41419621},{"atl":[[260,2],[180,0]],"id":41419586},{"atl":[[260,5.97],[340,2]],"id":41419633},{"atl":[[55,31.13]],"id":41419598},{"atl":[[560,2.72],[700,2]],"id":41419596},{"atl":[[300,2],[230,0]],"id":41419627}],"con":true,"img":false}]}
{"op":"mcm","clk":"5353549711","pt":1646216197307,"mc":[{"id":"1.195503866","rc":[{"atb":[[6.8,0]],"id":41419587},{"atl":[[60,0]],"id":41419598}],"con":true,"img":false}]}
{"op":"mcm","clk":"5353549736","pt":1646216197517,"mc":[{"id":"1.195503866","rc":[{"atb":[[20,12.21],[25,0]],"id":41419607},{"atl":[[150,1.06]],"id":41419611},{"atb":[[6.8,0],[5.9,0]],"id":41419591},{"atl":[[12,0],[12.5,4.95],[14,12.19],[14.5,9.9]],"id":41419587},{"atl":[[23,7.2]],"id":41419606},{"atb":[[17,19.81]],"id":41419635},{"atb":[[7.4,75.05],[13,3.26],[15.5,2.72]],"id":41419612},{"atl":[[38,46.78],[26,11.29]],"id":41419612},{"atl":[[140,6.09]],"id":41419623},{"atb":[[24,0],[29,0]],"id":41419594}],"con":true,"img":false}]}
{"op":"mcm","clk":"5353549748","pt":1646216197625,"mc":[{"id":"1.195503866","rc":[{"atl":[[65,24.56]],"id":41419607},{"atb":[[19.5,28.66],[24,11.84],[15.5,0]],"id":41419589},{"atl":[[270,0]],"id":41419630},{"atl":[[330,0],[320,0.49],[180,9.3]],"id":41419608}],"con":true,"img":false}]}
{"op":"mcm","clk":"5353549768","pt":1646216197786,"mc":[{"id":"1.195503866","rc":[{"atl":[[370,6.52]],"id":41419630}],"con":true,"img":false}]}
{"op":"mcm","clk":"5353549781","pt":1646216197889,"mc":[{"id":"1.195503866","rc":[{"atb":[[18.5,39.36]],"id":41419607},{"atl":[[44,3.68],[46,4.95],[55,0],[60,9.9]],"id":41419607},{"atl":[[150,12.23],[160,2]],"id":41419611},{"atl":[[34,0]],"id":41419635},{"atl":[[32,9.9],[26,6.34],[27,4.95]],"id":41419612},{"atb":[[65,9.9],[70,0],[85,4.95],[90,0]],"id":41419596},{"atb":[[23,31.24],[14.5,39.32]],"id":41419594}],"con":true,"img":false}]}
{"op":"mcm","clk":"5353549789","pt":1646216197992,"mc":[{"id":"1.195503866","rc":[{"atb":[[20,0]],"id":41419607}],"con":true,"img":false}]}
{"op":"mcm","clk":"5353549798","pt":1646216198122,"mc":[{"id":"1.195503866","rc":[{"atl":[[34,3.03],[14.5,31.99]],"id":41419587},{"atb":[[23,12.15]],"id":41419594}],"con":true,"img":false}]}
{"op":"mcm","clk":"5353549806","pt":1646216198182,"mc":[{"id":"1.195503866","rc":[{"atb":[[6,3.26],[7,46.24]],"id":41419591},{"atb":[[25,3.26],[30,2.72]],"id":41419594}],"con":true,"img":false}]}
{"op":"mcm","clk":"5353549814","pt":1646216198285,"mc":[{"id":"1.195503866","rc":[{"atb":[[21,16.15],[26,2.72]],"id":41419607},{"atb":[[19.5,20.09]],"id":41419589},{"atl":[[180,0]],"id":41419608},{"atl":[[26,0]],"id":41419612}],"con":true,"img":false}]}
{"op":"mcm","clk":"5353549853","pt":1646216198598,"mc":[{"id":"1.195503866","rc":[{"atl":[[160,10.48]],"id":41419623}],"con":true,"img":false}]}
{"op":"mcm","clk":"5353549877","pt":1646216198808,"mc":[{"id":"1.195503866","rc":[{"atl":[[65,22.08],[44,0]],"id":41419607},{"atl":[[20,4.95],[24,9.9]],"id":41419637},{"atb":[[65,12.38]],"id":41419596}],"con":true,"img":false}]}
{"op":"mcm","clk":"5353549893","pt":1646216198915,"mc":[{"id":"1.195503866","rc":[{"atl":[[360,2],[460,0]],"id":41419636},{"atl":[[80,0],[85,4.95],[100,0],[110,9.9]],"id":41419611},{"atl":[[280,2],[360,0]],"id":41419620},{"atl":[[1000,2.15]],"id":41419601},{"atl":[[680,2],[860,0]],"id":41419599},{"atl":[[330,6.67],[420,0]],"id":41419626},{"atl":[[340,2],[430,0]],"id":41419608},{"atl":[[21,0],[22,4.95],[25,0]],"id":41419606},{"atl":[[19.5,0],[23,0]],"id":41419637},{"atl":[[1000,3.53]],"id":41419625},{"atl":[[550,2],[690,0]],"id":41419621},{"atl":[[260,0],[200,2]],"id":41419586},{"atl":[[560,4.72],[700,0]],"id":41419596},{"atb":[[14.5,9.86]],"id":41419594}],"con":true,"img":false}]}
{"op":"mcm","clk":"5353549905","pt":1646216199018,"mc":[{"id":"1.195503866","rc":[{"atl":[[30,5.46]],"id":41419612}],"con":true,"img":false}]}
{"op":"mcm","clk":"5353549939","pt":1646216199289,"mc":[{"id":"1.195503866","rc":[{"atl":[[160,5.95]],"id":41419608},{"atl":[[23,22.08],[29,0]],"id":41419637}],"con":true,"img":false}]}
{"op":"mcm","clk":"5353549952","pt":1646216199388,"mc":[{"id":"1.195503866","rc":[{"atl":[[22,12.5]],"id":41419606}],"con":true,"img":false}]}
{"op":"mcm","clk":"5353549977","pt":1646216199591,"mc":[{"id":"1.195503866","rc":[{"atl":[[55,2.93]],"id":41419607},{"atl":[[340,6.93]],"id":41419608}],"con":true,"img":false}]}
{"op":"mcm","clk":"5353549989","pt":1646216199697,"mc":[{"id":"1.195503866","rc":[{"atl":[[28,5.86]],"id":41419637}],"con":true,"img":false}]}
{"op":"mcm","clk":"5353549997","pt":1646216199801,"mc":[{"id":"1.195503866","rc":[{"atl":[[65,31.99],[46,0],[48,4.95],[60,0]],"id":41419607},{"atl":[[32,0],[34,9.9],[27,0],[28,4.95]],"id":41419612},{"atl":[[70,0],[50,3.23]],"id":41419594}],"con":true,"img":false}]}
{"op":"mcm","clk":"5353550022","pt":1646216200014,"mc":[{"id":"1.195503866","rc":[{"atl":[[960,2]],"id":41419605},{"atb":[[70,0]],"id":41419636},{"atl":[[12.5,0],[13,4.95],[14.5,22.08],[15,9.9]],"id":41419587},{"atl":[[34,3.03],[38,0]],"id":41419606},{"atl":[[36,2.86],[38,44.08]],"id":41419612},{"atl":[[1000,1.53]],"id":41419625},{"atl":[[75,9.9],[50,0],[55,4.95]],"id":41419594}],"con":true,"img":false}]}
