{"op":"mcm","clk":"5317728451","pt":1646251399791,"mc":[{"id":"1.195532858","marketDefinition":{"bspMarket":true,"turnInPlayEnabled":false,"persistenceEnabled":false,"marketBaseRate":5.0,"eventId":"31275720","eventTypeId":"4339","numberOfWinners":1,"bettingType":"ODDS","marketType":"WIN","marketTime":"2022-03-03T14:52:00.000Z","suspendTime":"2022-03-03T14:52:00.000Z","bspReconciled":false,"complete":true,"inPlay":false,"crossMatching":false,"runnersVoidable":false,"numberOfActiveRunners":6,"betDelay":0,"status":"OPEN","runners":[{"status":"ACTIVE","sortPriority":1,"id":41288595,"name":"1. Corten Steel"},{"status":"ACTIVE","sortPriority":2,"id":38324360,"name":"2. Slippy Bull"},{"status":"ACTIVE","sortPriority":3,"id":39290878,"name":"3. Crohane Ollie"},{"status":"ACTIVE","sortPriority":4,"id":38357910,"name":"4. Kincora Beauty"},{"status":"ACTIVE","sortPriority":5,"id":40124755,"name":"5. Right Joe"},{"status":"ACTIVE","sortPriority":6,"id":38983972,"name":"6. Roll On Bucko"}],"regulators":["MR_INT"],"venue":"Romford","countryCode":"GB","discountAllowed":false,"timezone":"Europe/London","openDate":"2022-03-03T13:57:00.000Z","version":4384107290,"name":"A1 400m","eventName":"Romford 3rd Mar"},"rc":[],"con":true,"img":false}]}
{"op":"mcm","clk":"5317728848","pt":1646251401756,"mc":[{"id":"1.195532858","marketDefinition":{"bspMarket":true,"turnInPlayEnabled":false,"persistenceEnabled":false,"marketBaseRate":5.0,"eventId":"31275720","eventTypeId":"4339","numberOfWinners":1,"bettingType":"ODDS","marketType":"WIN","marketTime":"2022-03-03T14:52:00.000Z","suspendTime":"2022-03-03T14:52:00.000Z","bspReconciled":false,"complete":true,"inPlay":false,"crossMatching":false,"runnersVoidable":false,"numberOfActiveRunners":6,"betDelay":0,"status":"OPEN","runners":[{"status":"ACTIVE","sortPriority":1,"id":41288595,"name":"1. Corten Steel"},{"status":"ACTIVE","sortPriority":2,"id":38324360,"name":"2. Slippy Bull"},{"status":"ACTIVE","sortPriority":3,"id":39290878,"name":"3. Crohane Ollie"},{"status":"ACTIVE","sortPriority":4,"id":38357910,"name":"4. Kincora Beauty"},{"status":"ACTIVE","sortPriority":5,"id":40124755,"name":"5. Right Joe"},{"status":"ACTIVE","sortPriority":6,"id":38983972,"name":"6. Roll On Bucko"}],"regulators":["MR_INT"],"venue":"Romford","countryCode":"GB","discountAllowed":true,"timezone":"Europe/London","openDate":"2022-03-03T13:57:00.000Z","version":4384107290,"name":"A1 400m","eventName":"Romford 3rd Mar"},"rc":[],"con":true,"img":false}]}
{"op":"mcm","clk":"5318486121","pt":1646259098046,"mc":[{"id":"1.195532858","rc":[{"atb":[[1.12,30]],"id":41288595},{"atl":[[370,3]],"id":41288595},{"spn":185.56,"spf":"NaN","id":41288595},{"atb":[[1.14,30]],"id":38983972},{"atl":[[500,3]],"id":38983972},{"spn":250.57,"spf":"NaN","id":38983972},{"atb":[[1.12,30]],"id":38324360},{"atl":[[390,3]],"id":38324360},{"spn":195.56,"spf":"NaN","id":38324360},{"atb":[[1.12,30]],"id":39290878},{"atl":[[550,3]],"id":39290878},{"spn":275.56,"spf":"NaN","id":39290878},{"atb":[[1.12,30]],"id":38357910},{"atl":[[270,3]],"id":38357910},{"spn":135.56,"spf":"NaN","id":38357910},{"atb":[[1.12,30]],"id":40124755},{"atl":[[560,3]],"id":40124755},{"spn":280.56,"spf":"NaN","id":40124755}],"con":true,"img":false}]}
{"op":"mcm","clk":"5320139807","pt":1646287409160,"mc":[{"id":"1.195532858","rc":[{"atb":[[2.1,10.53]],"id":41288595},{"spn":186.05,"spf":"NaN","id":41288595},{"atb":[[2.04,11.08]],"id":38983972},{"spn":251.02,"spf":"NaN","id":38983972},{"atb":[[2.04,12.79]],"id":38324360},{"spn":196.02,"spf":"NaN","id":38324360},{"atb":[[2.1,8.77]],"id":39290878},{"spn":276.05,"spf":"NaN","id":39290878},{"atb":[[2.08,10.43]],"id":38357910},{"spn":136.04,"spf":"NaN","id":38357910},{"atb":[[2.04,9.38]],"id":40124755},{"spn":281.02,"spf":"NaN","id":40124755}],"con":true,"img":false}]}
{"op":"mcm","clk":"5320234797","pt":1646290704281,"mc":[{"id":"1.195532858","rc":[{"spb":[[1000,50]],"id":39290878},{"spn":550.0,"spf":"Infinity","id":39290878}],"con":true,"img":false}]}
{"op":"mcm","clk":"5320496296","pt":1646296489510,"mc":[{"id":"1.195532858","rc":[{"atb":[[2.1,10.53]],"id":41288595},{"atb":[[2.04,11.09]],"id":38983972},{"spl":[[10,10]],"id":38983972},{"spn":6.02,"spf":1.0,"id":38983972},{"atb":[[2.04,12.8]],"id":38324360},{"spl":[[28,10]],"id":38324360},{"spn":15.02,"spf":1.0,"id":38324360},{"atb":[[2.1,8.78]],"id":39290878},{"spl":[[8.2,10]],"id":39290878},{"spn":8.2,"spf":8.2,"id":39290878},{"atb":[[2.08,10.43]],"id":38357910},{"spl":[[10,10]],"id":38357910},{"spn":6.04,"spf":1.0,"id":38357910},{"atb":[[2.04,9.38]],"id":40124755},{"spl":[[4.7,10]],"id":40124755},{"spn":3.37,"spf":1.0,"id":40124755}],"con":true,"img":false}]}
{"op":"mcm","clk":"5320557283","pt":1646297473361,"mc":[{"id":"1.195532858","rc":[{"spl":[[1.01,2]],"id":39290878}],"con":true,"img":false}]}
{"op":"mcm","clk":"5320558581","pt":1646297498563,"mc":[{"id":"1.195532858","rc":[{"spl":[[21,1]],"id":41288595},{"spl":[[21,1]],"id":38983972},{"spl":[[21,1]],"id":38324360},{"spl":[[21,1]],"id":39290878},{"spl":[[21,1]],"id":38357910},{"spl":[[21,1]],"id":40124755}],"con":true,"img":false}]}
{"op":"mcm","clk":"5320624723","pt":1646298761386,"mc":[{"id":"1.195532858","rc":[{"atl":[[44,1]],"id":41288595},{"spn":11.55,"spf":1.0,"id":41288595},{"atl":[[44,1]],"id":38983972},{"spn":11.52,"spf":1.0,"id":38324360},{"atl":[[44,1]],"id":39290878},{"atl":[[44,1]],"id":38357910}],"con":true,"img":false}]}
{"op":"mcm","clk":"5320626308","pt":1646298777619,"mc":[{"id":"1.195532858","rc":[{"atl":[[44,1.1]],"id":41288595},{"atl":[[44,1.1]],"id":38983972},{"atl":[[44,1.1]],"id":39290878},{"atl":[[44,1.1]],"id":38357910}],"con":true,"img":false}]}
{"op":"mcm","clk":"5320627853","pt":1646298793737,"mc":[{"id":"1.195532858","rc":[{"atl":[[44,0.1]],"id":41288595},{"atl":[[44,0.1]],"id":38983972},{"atl":[[44,0.1]],"id":39290878},{"atl":[[44,0.1]],"id":38357910}],"con":true,"img":false}]}
{"op":"mcm","clk":"5320830269","pt":1646302602585,"mc":[{"id":"1.195532858","marketDefinition":{"bspMarket":true,"turnInPlayEnabled":false,"persistenceEnabled":false,"marketBaseRate":5.0,"eventId":"31275720","eventTypeId":"4339","numberOfWinners":1,"bettingType":"ODDS","marketType":"WIN","marketTime":"2022-03-03T14:52:00.000Z","suspendTime":"2022-03-03T14:52:00.000Z","bspReconciled":false,"complete":true,"inPlay":false,"crossMatching":false,"runnersVoidable":false,"numberOfActiveRunners":6,"betDelay":0,"status":"OPEN","runners":[{"status":"ACTIVE","sortPriority":1,"id":41288595,"name":"1. Corten Steel"},{"status":"ACTIVE","sortPriority":2,"id":38324360,"name":"2. Slippy Bull"},{"status":"ACTIVE","sortPriority":3,"id":39290878,"name":"3. Crohane Ollie"},{"status":"ACTIVE","sortPriority":4,"id":38357910,"name":"4. Kincora Beauty"},{"status":"ACTIVE","sortPriority":5,"id":40124755,"name":"5. Right Joe"},{"status":"ACTIVE","sortPriority":6,"id":38983972,"name":"6. Roll On Bucko"}],"regulators":["MR_INT"],"venue":"Romford","countryCode":"GB","discountAllowed":true,"timezone":"Europe/London","openDate":"2022-03-03T13:57:00.000Z","version":4384107290,"name":"A1 400m","eventName":"Romford 3rd Mar"},"rc":[{"atb":[[1.12,30],[2.1,10.53]],"id":41288595},{"spl":[[21,1]],"id":41288595},{"atl":[[44,0.1],[370,3]],"id":41288595},{"spn":11.55,"spf":1.0,"id":41288595},{"atb":[[2.04,11.08],[1.14,30]],"id":38983972},{"spl":[[10,10],[21,1]],"id":38983972},{"atl":[[44,0.1],[500,3]],"id":38983972},{"spn":6.02,"spf":1.0,"id":38983972},{"atb":[[1.12,30],[2.04,12.79]],"id":38324360},{"spl":[[21,1],[28,10]],"id":38324360},{"atl":[[390,3]],"id":38324360},{"spn":11.52,"spf":1.0,"id":38324360},{"atb":[[1.12,30],[2.1,8.77]],"id":39290878},{"spl":[[1.01,2],[21,1],[8.2,10]],"id":39290878},{"atl":[[550,3],[44,0.1]],"id":39290878},{"spb":[[1000,50]],"id":39290878},{"spn":8.2,"spf":8.2,"id":39290878},{"atb":[[1.12,30],[2.08,10.43]],"id":38357910},{"spl":[[10,10],[21,1]],"id":38357910},{"atl":[[270,3],[44,0.1]],"id":38357910},{"spn":6.04,"spf":1.0,"id":38357910},{"atb":[[1.12,30],[2.04,9.38]],"id":40124755},{"spl":[[21,1],[4.7,10]],"id":40124755},{"atl":[[560,3]],"id":40124755},{"spn":3.37,"spf":1.0,"id":40124755}],"con":true,"img":true}]}
{"op":"mcm","clk":"5321025883","pt":1646305291957,"mc":[{"id":"1.195532858","rc":[{"atb":[[9.8,2],[2.1,10.53]],"id":41288595},{"spn":15.4,"spf":1.0,"id":41288595},{"atb":[[2.04,11.09],[5.7,2]],"id":38983972},{"spn":7.85,"spf":1.0,"id":38983972},{"atb":[[10,2],[2.04,12.79]],"id":38324360},{"spn":15.5,"spf":1.0,"id":38324360},{"atb":[[3.9,2],[2.1,8.78]],"id":39290878},{"atb":[[2.98,2],[2.08,10.43]],"id":38357910},{"spn":6.49,"spf":1.0,"id":38357910},{"atb":[[2.04,9.38],[5.2,2]],"id":40124755},{"spn":4.7,"spf":1.0,"id":40124755}],"con":true,"img":false}]}
{"op":"mcm","clk":"5321028074","pt":1646305320235,"mc":[{"id":"1.195532858","marketDefinition":{"bspMarket":true,"turnInPlayEnabled":false,"persistenceEnabled":false,"marketBaseRate":5.0,"eventId":"31275720","eventTypeId":"4339","numberOfWinners":1,"bettingType":"ODDS","marketType":"WIN","marketTime":"2022-03-03T14:52:00.000Z","suspendTime":"2022-03-03T14:52:00.000Z","bspReconciled":false,"complete":true,"inPlay":false,"crossMatching":true,"runnersVoidable":false,"numberOfActiveRunners":6,"betDelay":0,"status":"OPEN","runners":[{"status":"ACTIVE","sortPriority":1,"id":41288595,"name":"1. Corten Steel"},{"status":"ACTIVE","sortPriority":2,"id":38324360,"name":"2. Slippy Bull"},{"status":"ACTIVE","sortPriority":3,"id":39290878,"name":"3. Crohane Ollie"},{"status":"ACTIVE","sortPriority":4,"id":38357910,"name":"4. Kincora Beauty"},{"status":"ACTIVE","sortPriority":5,"id":40124755,"name":"5. Right Joe"},{"status":"ACTIVE","sortPriority":6,"id":38983972,"name":"6. Roll On Bucko"}],"regulators":["MR_INT"],"venue":"Romford","countryCode":"GB","discountAllowed":true,"timezone":"Europe/London","openDate":"2022-03-03T13:57:00.000Z","version":4384107290,"name":"A1 400m","eventName":"Romford 3rd Mar"},"rc":[],"con":true,"img":false}]}
{"op":"mcm","clk":"5321057202","pt":1646305622250,"mc":[{"id":"1.195532858","rc":[{"atb":[[7.6,1.53]],"id":41288595},{"atl":[[22,0.49]],"id":41288595},{"atb":[[4.8,2]],"id":38983972},{"atl":[[10,1.12]],"id":38983972},{"atb":[[11.5,0.96]],"id":38324360},{"atl":[[36,0.3]],"id":38324360},{"spn":16.25,"spf":1.0,"id":38324360},{"atb":[[3.55,2]],"id":39290878},{"atl":[[6.2,1.93]],"id":39290878},{"atb":[[2.76,2]],"id":38357910},{"atl":[[4.5,2]],"id":38357910},{"spn":3.74,"spf":1.0,"id":38357910},{"atb":[[4.4,2]],"id":40124755},{"atl":[[8.8,1.29]],"id":40124755}],"con":true,"img":false}]}
{"op":"mcm","clk":"5321079267","pt":1646305915474,"mc":[{"id":"1.195532858","rc":[{"atb":[[10,5]],"id":38324360}],"con":true,"img":false}]}
{"op":"mcm","clk":"5321079605","pt":1646305920548,"mc":[{"id":"1.195532858","rc":[{"atb":[[10,3]],"id":38324360}],"con":true,"img":false}]}
{"op":"mcm","clk":"5321254945","pt":1646307692364,"mc":[{"id":"1.195532858","rc":[{"atb":[[3.55,0]],"id":39290878}],"con":true,"img":false}]}
{"op":"mcm","clk":"5321254964","pt":1646307692567,"mc":[{"id":"1.195532858","rc":[{"atb":[[2.76,2]],"id":39290878}],"con":true,"img":false}]}
{"op":"mcm","clk":"5321274323","pt":1646307924502,"mc":[{"id":"1.195532858","rc":[{"atl":[[1000,2.5]],"id":41288595},{"atl":[[1000,2.5]],"id":38983972},{"atl":[[1000,2.5]],"id":38324360},{"atl":[[1000,2.5]],"id":39290878},{"atl":[[1000,2.5]],"id":38357910},{"atl":[[1000,2.5]],"id":40124755}],"con":true,"img":false}]}
{"op":"mcm","clk":"5321274364","pt":1646307924920,"mc":[{"id":"1.195532858","rc":[{"atl":[[1000,12.5]],"id":41288595},{"atl":[[1000,12.5]],"id":38983972},{"atl":[[1000,12.5]],"id":38324360},{"atl":[[1000,12.5]],"id":39290878},{"atl":[[1000,12.5]],"id":38357910},{"atl":[[1000,12.5]],"id":40124755}],"con":true,"img":false}]}
{"op":"mcm","clk":"5321274402","pt":1646307925393,"mc":[{"id":"1.195532858","rc":[{"atb":[[1.01,1000]],"id":41288595},{"atb":[[1.01,1000]],"id":38983972},{"atb":[[1.01,1000]],"id":38324360},{"atb":[[1.01,1000]],"id":39290878},{"atb":[[1.01,1000]],"id":38357910},{"atb":[[1.01,1000]],"id":40124755}],"con":true,"img":false}]}
{"op":"mcm","clk":"5321274429","pt":1646307925708,"mc":[{"id":"1.195532858","rc":[{"atb":[[1.01,11000]],"id":41288595},{"atb":[[1.01,11000]],"id":38983972},{"atb":[[1.01,11000]],"id":38324360},{"atb":[[1.01,11000]],"id":39290878},{"atb":[[1.01,11000]],"id":38357910},{"atb":[[1.01,11000]],"id":40124755}],"con":true,"img":false}]}
{"op":"mcm","clk":"5321275505","pt":1646307937630,"mc":[{"id":"1.195532858","rc":[{"atb":[[4.4,0]],"id":40124755}],"con":true,"img":false}]}
{"op":"mcm","clk":"5321275515","pt":1646307937733,"mc":[{"id":"1.195532858","rc":[{"atb":[[4.3,2]],"id":40124755}],"con":true,"img":false}]}
{"op":"mcm","clk":"5321417101","pt":1646309461997,"mc":[{"id":"1.195532858","rc":[{"spl":[[1.01,8.18]],"id":41288595},{"spn":5.0,"spf":1.0,"id":41288595}],"con":true,"img":false}]}
{"op":"mcm","clk":"5321438617","pt":1646309717804,"mc":[{"id":"1.195532858","rc":[{"atb":[[4.8,0]],"id":38983972},{"atl":[[10,0]],"id":38983972},{"atl":[[4.5,0]],"id":38357910},{"spn":6.49,"spf":1.0,"id":38357910}],"con":true,"img":false}]}
{"op":"mcm","clk":"5321438623","pt":1646309717908,"mc":[{"id":"1.195532858","rc":[{"atb":[[4.4,2]],"id":38983972},{"atl":[[9.8,1.15]],"id":38983972}],"con":true,"img":false}]}
{"op":"mcm","clk":"5321438636","pt":1646309718016,"mc":[{"id":"1.195532858","rc":[{"atl":[[4.6,2]],"id":38357910}],"con":true,"img":false}]}
{"op":"mcm","clk":"5321491550","pt":1646310245940,"mc":[{"id":"1.195532858","rc":[{"atl":[[1000,14.5]],"id":41288595},{"spn":7.75,"spf":1.0,"id":38983972},{"spn":3.79,"spf":1.0,"id":38357910}],"con":true,"img":false}]}
{"op":"mcm","clk":"5321491667","pt":1646310247280,"mc":[{"id":"1.195532858","rc":[{"atl":[[1000,14.7]],"id":41288595}],"con":true,"img":false}]}
{"op":"mcm","clk":"5321491789","pt":1646310248577,"mc":[{"id":"1.195532858","rc":[{"atl":[[1000,14.5]],"id":41288595}],"con":true,"img":false}]}
{"op":"mcm","clk":"5321491796","pt":1646310248677,"mc":[{"id":"1.195532858","rc":[{"atl":[[21,0.2]],"id":41288595}],"con":true,"img":false}]}
{"op":"mcm","clk":"5321491913","pt":1646310249973,"mc":[{"id":"1.195532858","rc":[{"atl":[[1000,14.5]],"id":38324360}],"con":true,"img":false}]}
{"op":"mcm","clk":"5321492042","pt":1646310251270,"mc":[{"id":"1.195532858","rc":[{"atl":[[1000,14.7]],"id":38324360}],"con":true,"img":false}]}
{"op":"mcm","clk":"5321492157","pt":1646310252565,"mc":[{"id":"1.195532858","rc":[{"atl":[[1000,14.5]],"id":38324360}],"con":true,"img":false}]}
{"op":"mcm","clk":"5321492162","pt":1646310252669,"mc":[{"id":"1.195532858","rc":[{"atl":[[32,0.2]],"id":38324360}],"con":true,"img":false}]}
{"op":"mcm","clk":"5321492268","pt":1646310253956,"mc":[{"id":"1.195532858","rc":[{"atl":[[1000,14.5]],"id":39290878}],"con":true,"img":false}]}
{"op":"mcm","clk":"5321492371","pt":1646310255258,"mc":[{"id":"1.195532858","rc":[{"atl":[[1000,14.7]],"id":39290878}],"con":true,"img":false}]}
{"op":"mcm","clk":"5321492497","pt":1646310256558,"mc":[{"id":"1.195532858","rc":[{"atl":[[1000,14.5]],"id":39290878}],"con":true,"img":false}]}
{"op":"mcm","clk":"5321492508","pt":1646310256660,"mc":[{"id":"1.195532858","rc":[{"atl":[[8.8,0.2]],"id":39290878}],"con":true,"img":false}]}
{"op":"mcm","clk":"5321492639","pt":1646310257957,"mc":[{"id":"1.195532858","rc":[{"atl":[[1000,14.5]],"id":38357910}],"con":true,"img":false}]}
{"op":"mcm","clk":"5321492746","pt":1646310259257,"mc":[{"id":"1.195532858","rc":[{"atl":[[1000,14.7]],"id":38357910}],"con":true,"img":false}]}
{"op":"mcm","clk":"5321492861","pt":1646310260557,"mc":[{"id":"1.195532858","rc":[{"atl":[[1000,14.5]],"id":38357910}],"con":true,"img":false}]}
{"op":"mcm","clk":"5321492871","pt":1646310260661,"mc":[{"id":"1.195532858","rc":[{"atl":[[7.2,0.2]],"id":38357910}],"con":true,"img":false}]}
{"op":"mcm","clk":"5321492992","pt":1646310261961,"mc":[{"id":"1.195532858","rc":[{"atl":[[1000,14.5]],"id":40124755}],"con":true,"img":false}]}
{"op":"mcm","clk":"5321493100","pt":1646310263299,"mc":[{"id":"1.195532858","rc":[{"atl":[[1000,14.7]],"id":40124755}],"con":true,"img":false}]}
{"op":"mcm","clk":"5321493234","pt":1646310264701,"mc":[{"id":"1.195532858","rc":[{"atl":[[1000,14.5]],"id":40124755}],"con":true,"img":false}]}
{"op":"mcm","clk":"5321493243","pt":1646310264803,"mc":[{"id":"1.195532858","rc":[{"atl":[[12,0.2]],"id":40124755}],"con":true,"img":false}]}
{"op":"mcm","clk":"5321493358","pt":1646310266104,"mc":[{"id":"1.195532858","rc":[{"atl":[[1000,14.5]],"id":38983972}],"con":true,"img":false}]}
{"op":"mcm","clk":"5321493474","pt":1646310267401,"mc":[{"id":"1.195532858","rc":[{"atl":[[1000,14.7]],"id":38983972}],"con":true,"img":false}]}
{"op":"mcm","clk":"5321493582","pt":1646310268694,"mc":[{"id":"1.195532858","rc":[{"atl":[[1000,14.5]],"id":38983972}],"con":true,"img":false}]}
{"op":"mcm","clk":"5321493595","pt":1646310268796,"mc":[{"id":"1.195532858","rc":[{"atl":[[12.5,0.2]],"id":38983972}],"con":true,"img":false}]}
{"op":"mcm","clk":"5321653694","pt":1646311924565,"mc":[{"id":"1.195532858","rc":[{"atb":[[2.62,64.81]],"id":41288595},{"spn":5.3,"spf":1.0,"id":41288595},{"atb":[[2.62,64.81]],"id":38983972},{"atb":[[4.6,25.56],[3.7,37.78],[2.62,64.81]],"id":38324360},{"atl":[[17,9.5]],"id":39290878}],"con":true,"img":false}]}
{"op":"mcm","clk":"5321653709","pt":1646311924666,"mc":[{"id":"1.195532858","rc":[{"atl":[[34,15.5]],"id":38983972},{"atl":[[34,15.5]],"id":39290878},{"atl":[[17,9.5],[34,15.5]],"id":38357910},{"atl":[[34,15.5]],"id":40124755}],"con":true,"img":false}]}
{"op":"mcm","clk":"5321655483","pt":1646311938086,"mc":[{"id":"1.195532858","rc":[{"atl":[[6,1.65]],"id":39290878}],"con":true,"img":false}]}
{"op":"mcm","clk":"5321655524","pt":1646311938492,"mc":[{"id":"1.195532858","rc":[{"atb":[[10.5,1.65]],"id":38324360}],"con":true,"img":false}]}
{"op":"mcm","clk":"5321656523","pt":1646311947351,"mc":[{"id":"1.195532858","rc":[{"atl":[[10.5,9.2],[13.5,15.2]],"id":39290878}],"con":true,"img":false}]}
{"op":"mcm","clk":"5321809179","pt":1646313402548,"mc":[{"id":"1.195532858","marketDefinition":{"bspMarket":true,"turnInPlayEnabled":false,"persistenceEnabled":false,"marketBaseRate":5.0,"eventId":"31275720","eventTypeId":"4339","numberOfWinners":1,"bettingType":"ODDS","marketType":"WIN","marketTime":"2022-03-03T14:52:00.000Z","suspendTime":"2022-03-03T14:52:00.000Z","bspReconciled":false,"complete":true,"inPlay":false,"crossMatching":true,"runnersVoidable":false,"numberOfActiveRunners":6,"betDelay":0,"status":"OPEN","runners":[{"status":"ACTIVE","sortPriority":1,"id":41288595,"name":"1. Corten Steel"},{"status":"ACTIVE","sortPriority":2,"id":38324360,"name":"2. Slippy Bull"},{"status":"ACTIVE","sortPriority":3,"id":39290878,"name":"3. Crohane Ollie"},{"status":"ACTIVE","sortPriority":4,"id":38357910,"name":"4. Kincora Beauty"},{"status":"ACTIVE","sortPriority":5,"id":40124755,"name":"5. Right Joe"},{"status":"ACTIVE","sortPriority":6,"id":38983972,"name":"6. Roll On Bucko"}],"regulators":["MR_INT"],"venue":"Romford","countryCode":"GB","discountAllowed":true,"timezone":"Europe/London","openDate":"2022-03-03T13:57:00.000Z","version":4384107290,"name":"A1 400m","eventName":"Romford 3rd Mar"},"rc":[{"atb":[[1.12,30],[1.01,11000],[7.6,1.53],[9.8,2],[2.62,64.81],[2.1,10.53]],"id":41288595},{"spl":[[1.01,8.19],[21,1]],"id":41288595},{"atl":[[21,0.2],[22,0.49],[44,0.1],[370,3],[1000,14.5]],"id":41288595},{"spn":5.3,"spf":1.0,"id":41288595},{"atb":[[1.01,11000],[2.04,11.08],[1.14,30],[5.7,2],[4.4,2],[2.62,64.81]],"id":38983972},{"spl":[[10,10],[21,1]],"id":38983972},{"atl":[[34,15.5],[44,0.1],[9.8,1.15],[12.5,0.2],[500,3],[1000,14.5]],"id":38983972},{"spn":7.75,"spf":1.0,"id":38983972},{"atb":[[1.12,30],[1.01,11000],[10,3],[4.6,25.56],[10.5,1.65],[11.5,0.96],[3.7,37.78],[2.04,12.79],[2.62,64.81]],"id":38324360},{"spl":[[21,1],[28,10]],"id":38324360},{"atl":[[32,0.2],[36,0.3],[390,3],[1000,14.5]],"id":38324360},{"spn":16.25,"spf":1.0,"id":38324360},{"atb":[[1.12,30],[1.01,11000],[3.9,2],[2.1,8.77],[2.76,2]],"id":39290878},{"spl":[[1.01,2],[21,1],[8.2,10]],"id":39290878},{"atl":[[17,9.5],[34,15.5],[550,3],[6.2,1.93],[10.5,9.2],[44,0.1],[6,1.65],[8.8,0.2],[13.5,15.2],[1000,14.5]],"id":39290878},{"spb":[[1000,50]],"id":39290878},{"spn":7.6,"spf":8.2,"id":39290878},{"atb":[[1.12,30],[1.01,11000],[2.98,2],[2.08,10.43],[2.76,2]],"id":38357910},{"spl":[[10,10],[21,1]],"id":38357910},{"atl":[[270,3],[7.2,0.2],[17,9.5],[34,15.5],[4.6,2],[44,0.1],[1000,14.5]],"id":38357910},{"spn":3.79,"spf":1.0,"id":38357910},{"atb":[[1.12,30],[4.3,2],[1.01,11000],[2.04,9.38],[5.2,2]],"id":40124755},{"spl":[[21,1],[4.7,10]],"id":40124755},{"atl":[[34,15.5],[560,3],[12,0.2],[8.8,1.29],[1000,14.5]],"id":40124755},{"spn":4.7,"spf":1.0,"id":40124755}],"con":true,"img":true}]}
{"op":"mcm","clk":"5321850104","pt":1646313743992,"mc":[{"id":"1.195532858","rc":[{"atb":[[2.1,10.53]],"id":41288595},{"spl":[[1.01,8.19]],"id":41288595},{"spn":5.3,"spf":1.0,"id":41288595},{"atb":[[2.04,11.08]],"id":38983972},{"atb":[[10.5,1.65],[2.04,12.79]],"id":38324360},{"atb":[[2.1,8.77]],"id":39290878},{"atl":[[6,1.65],[1000,15]],"id":39290878},{"spn":7.6,"spf":8.2,"id":39290878},{"atb":[[2.08,10.43]],"id":38357910},{"atb":[[2.04,9.38]],"id":40124755}],"con":true,"img":false}]}
{"op":"mcm","clk":"5321851892","pt":1646313762073,"mc":[{"id":"1.195532858","rc":[{"atl":[[1000,14.5]],"id":39290878}],"con":true,"img":false}]}
{"op":"mcm","clk":"5321851905","pt":1646313762175,"mc":[{"id":"1.195532858","rc":[{"atb":[[3.9,1.5]],"id":39290878},{"trd":[[3.9,1]],"ltp":3.9,"tv":1.0,"id":39290878}],"con":true,"img":false}]}
{"op":"mcm","clk":"5321851946","pt":1646313762583,"mc":[{"id":"1.195532858","rc":[{"atb":[[2.12,10.01]],"id":38357910}],"con":true,"img":false}]}
{"op":"mcm","clk":"5321851964","pt":1646313762693,"mc":[{"id":"1.195532858","rc":[{"atb":[[4.8,2.95]],"id":38324360}],"con":true,"img":false}]}
{"op":"mcm","clk":"5321851971","pt":1646313762792,"mc":[{"id":"1.195532858","rc":[{"atb":[[2.74,6.44]],"id":41288595}],"con":true,"img":false}]}
{"op":"mcm","clk":"5321851983","pt":1646313762898,"mc":[{"id":"1.195532858","rc":[{"atb":[[2.66,6.75]],"id":38983972},{"atb":[[2.8,6.22]],"id":39290878}],"con":true,"img":false}]}
{"op":"mcm","clk":"5321852000","pt":1646313763008,"mc":[{"id":"1.195532858","rc":[{"atb":[[2.32,8.49]],"id":40124755}],"con":true,"img":false}]}
{"op":"mcm","clk":"5321852068","pt":1646313763680,"mc":[{"id":"1.195532858","rc":[{"atb":[[4.8,6.22]],"id":38324360},{"atb":[[2.12,21.09]],"id":38357910}],"con":true,"img":false}]}
{"op":"mcm","clk":"5321852093","pt":1646313763988,"mc":[{"id":"1.195532858","rc":[{"atb":[[2.74,13.58]],"id":41288595}],"con":true,"img":false}]}
{"op":"mcm","clk":"5321852107","pt":1646313764091,"mc":[{"id":"1.195532858","rc":[{"atb":[[2.66,14.24]],"id":38983972}],"con":true,"img":false}]}
{"op":"mcm","clk":"5321852126","pt":1646313764300,"mc":[{"id":"1.195532858","rc":[{"atb":[[2.32,17.89]],"id":40124755}],"con":true,"img":false}]}
{"op":"mcm","clk":"5321852139","pt":1646313764404,"mc":[{"id":"1.195532858","rc":[{"atb":[[2.8,13.12]],"id":39290878}],"con":true,"img":false}]}
{"op":"mcm","clk":"5321852381","pt":1646313766705,"mc":[{"id":"1.195532858","rc":[{"atb":[[3.9,3.5]],"id":39290878}],"con":true,"img":false}]}
{"op":"mcm","clk":"5321852390","pt":1646313766760,"mc":[{"id":"1.195532858","rc":[{"atb":[[3.9,2]],"id":39290878}],"con":true,"img":false}]}
{"op":"mcm","clk":"5321855314","pt":1646313798535,"mc":[{"id":"1.195532858","rc":[{"atb":[[2.08,0]],"id":38357910},{"atb":[[2.04,0]],"id":40124755}],"con":true,"img":false}]}
{"op":"mcm","clk":"5321855323","pt":1646313798637,"mc":[{"id":"1.195532858","rc":[{"atb":[[2.14,10.43]],"id":38357910},{"atb":[[2.34,9.38]],"id":40124755}],"con":true,"img":false}]}
{"op":"mcm","clk":"5321873380","pt":1646314000955,"mc":[{"id":"1.195532858","rc":[{"atb":[[2.74,7.13]],"id":41288595},{"spn":5.36,"spf":1.0,"id":41288595},{"atb":[[2.66,7.48]],"id":38983972},{"atb":[[2.8,6.89]],"id":39290878},{"atb":[[2.12,11.08]],"id":38357910},{"atb":[[2.32,9.4]],"id":40124755}],"con":true,"img":false}]}
{"op":"mcm","clk":"5321873559","pt":1646314003236,"mc":[{"id":"1.195532858","rc":[{"atb":[[2.78,6.3]],"id":41288595}],"con":true,"img":false}]}
{"op":"mcm","clk":"5321873578","pt":1646314003440,"mc":[{"id":"1.195532858","rc":[{"atb":[[2.38,8.12]],"id":40124755}],"con":true,"img":false}]}
{"op":"mcm","clk":"5321873589","pt":1646314003547,"mc":[{"id":"1.195532858","rc":[{"atb":[[2.7,6.59]],"id":38983972}],"con":true,"img":false}]}
{"op":"mcm","clk":"5321873595","pt":1646314003648,"mc":[{"id":"1.195532858","rc":[{"atb":[[2.18,9.5]],"id":38357910}],"con":true,"img":false}]}
{"op":"mcm","clk":"5321873698","pt":1646314004739,"mc":[{"id":"1.195532858","rc":[{"atb":[[2.84,6.09]],"id":39290878}],"con":true,"img":false}]}
{"op":"mcm","clk":"5321874719","pt":1646314016280,"mc":[{"id":"1.195532858","rc":[{"atb":[[2.8,0]],"id":39290878},{"atb":[[2.12,0]],"id":38357910}],"con":true,"img":false}]}
{"op":"mcm","clk":"5321876407","pt":1646314037603,"mc":[{"id":"1.195532858","rc":[{"atb":[[2.88,6.6]],"id":39290878}],"con":true,"img":false}]}
{"op":"mcm","clk":"5321876434","pt":1646314037865,"mc":[{"id":"1.195532858","rc":[{"atb":[[2.22,10.18]],"id":38357910}],"con":true,"img":false}]}
{"op":"mcm","clk":"5321878040","pt":1646314058816,"mc":[{"id":"1.195532858","rc":[{"atb":[[2.32,0]],"id":40124755}],"con":true,"img":false}]}
{"op":"mcm","clk":"5321879818","pt":1646314079742,"mc":[{"id":"1.195532858","rc":[{"spn":5.39,"spf":1.0,"id":41288595},{"atb":[[2.42,8.74]],"id":40124755}],"con":true,"img":false}]}
{"op":"mcm","clk":"5321881331","pt":1646314097533,"mc":[{"id":"1.195532858","rc":[{"atb":[[2.14,0]],"id":38357910}],"con":true,"img":false}]}
{"op":"mcm","clk":"5321881341","pt":1646314097635,"mc":[{"id":"1.195532858","rc":[{"atb":[[2.24,10.43]],"id":38357910}],"con":true,"img":false}]}
{"op":"mcm","clk":"5321893887","pt":1646314246321,"mc":[{"id":"1.195532858","rc":[{"atb":[[2.74,0]],"id":41288595},{"atb":[[2.66,0]],"id":38983972}],"con":true,"img":false}]}
{"op":"mcm","clk":"5321894316","pt":1646314251089,"mc":[{"id":"1.195532858","rc":[{"atb":[[2.84,0]],"id":39290878}],"con":true,"img":false}]}
{"op":"mcm","clk":"5321894521","pt":1646314253429,"mc":[{"id":"1.195532858","rc":[{"atb":[[2.92,5.83]],"id":39290878}],"con":true,"img":false}]}
{"op":"mcm","clk":"5321895883","pt":1646314271894,"mc":[{"id":"1.195532858","rc":[{"atb":[[2.18,0]],"id":38357910}],"con":true,"img":false}]}
{"op":"mcm","clk":"5321896045","pt":1646314274431,"mc":[{"id":"1.195532858","rc":[{"atb":[[2.28,8.76]],"id":38357910}],"con":true,"img":false}]}
{"op":"mcm","clk":"5321898892","pt":1646314313404,"mc":[{"id":"1.195532858","rc":[{"atb":[[2.38,0]],"id":40124755}],"con":true,"img":false}]}
{"op":"mcm","clk":"5321899131","pt":1646314316519,"mc":[{"id":"1.195532858","rc":[{"atb":[[2.46,7.67]],"id":40124755}],"con":true,"img":false}]}
{"op":"mcm","clk":"5321905855","pt":1646314397657,"mc":[{"id":"1.195532858","rc":[{"atb":[[2.24,0]],"id":38357910}],"con":true,"img":false}]}
{"op":"mcm","clk":"5321905858","pt":1646314397760,"mc":[{"id":"1.195532858","rc":[{"atb":[[2.3,10.43]],"id":38357910}],"con":true,"img":false}]}
{"op":"mcm","clk":"5321907106","pt":1646314411081,"mc":[{"id":"1.195532858","rc":[{"atb":[[2.22,0]],"id":38357910}],"con":true,"img":false}]}
{"op":"mcm","clk":"5321907115","pt":1646314411186,"mc":[{"id":"1.195532858","rc":[{"atb":[[2.82,6.82]],"id":41288595}],"con":true,"img":false}]}
{"op":"mcm","clk":"5321907129","pt":1646314411393,"mc":[{"id":"1.195532858","rc":[{"atb":[[2.74,7.13]],"id":38983972}],"con":true,"img":false}]}
{"op":"mcm","clk":"5321908970","pt":1646314433157,"mc":[{"id":"1.195532858","rc":[{"atb":[[2.34,9.26]],"id":38357910}],"con":true,"img":false}]}
{"op":"mcm","clk":"5321913495","pt":1646314482116,"mc":[{"id":"1.195532858","rc":[{"atb":[[2.78,0]],"id":41288595},{"spn":5.41,"spf":1.0,"id":41288595},{"atb":[[2.7,0]],"id":38983972}],"con":true,"img":false}]}
{"op":"mcm","clk":"5321913811","pt":1646314485086,"mc":[{"id":"1.195532858","rc":[{"atb":[[2.86,6.02]],"id":41288595}],"con":true,"img":false}]}
{"op":"mcm","clk":"5321913829","pt":1646314485292,"mc":[{"id":"1.195532858","rc":[{"atb":[[2.78,6.3]],"id":38983972}],"con":true,"img":false}]}
{"op":"mcm","clk":"5321929479","pt":1646314633324,"mc":[{"id":"1.195532858","rc":[{"spn":5.43,"spf":1.0,"id":41288595},{"atb":[[2.28,0]],"id":38357910}],"con":true,"img":false}]}
{"op":"mcm","clk":"5321929829","pt":1646314636714,"mc":[{"id":"1.195532858","rc":[{"atb":[[2.38,8.12]],"id":38357910}],"con":true,"img":false}]}
{"op":"mcm","clk":"5321932431","pt":1646314660054,"mc":[{"id":"1.195532858","rc":[{"atb":[[2.88,0]],"id":39290878},{"atb":[[2.42,0]],"id":40124755}],"con":true,"img":false}]}
{"op":"mcm","clk":"5321934086","pt":1646314674355,"mc":[{"id":"1.195532858","rc":[{"atb":[[2.96,6.33]],"id":39290878}],"con":true,"img":false}]}
{"op":"mcm","clk":"5321934150","pt":1646314674879,"mc":[{"id":"1.195532858","rc":[{"atb":[[2.5,8.27]],"id":40124755}],"con":true,"img":false}]}
{"op":"mcm","clk":"5321936471","pt":1646314694609,"mc":[{"id":"1.195532858","rc":[{"atb":[[2.3,0]],"id":38357910}],"con":true,"img":false}]}
{"op":"mcm","clk":"5321936485","pt":1646314694715,"mc":[{"id":"1.195532858","rc":[{"atb":[[2.36,10.43]],"id":38357910}],"con":true,"img":false}]}
{"op":"mcm","clk":"5321940264","pt":1646314727881,"mc":[{"id":"1.195532858","rc":[{"atb":[[2.82,0]],"id":41288595},{"atb":[[2.74,0]],"id":38983972}],"con":true,"img":false}]}
{"op":"mcm","clk":"5321941799","pt":1646314742010,"mc":[{"id":"1.195532858","rc":[{"atb":[[2.9,6.53]],"id":41288595}],"con":true,"img":false}]}
{"op":"mcm","clk":"5321941824","pt":1646314742169,"mc":[{"id":"1.195532858","rc":[{"atb":[[2.82,6.82]],"id":38983972}],"con":true,"img":false}]}
{"op":"mcm","clk":"5321957174","pt":1646314880412,"mc":[{"id":"1.195532858","rc":[{"spn":5.46,"spf":1.0,"id":41288595},{"atb":[[2.34,0]],"id":38357910}],"con":true,"img":false}]}
{"op":"mcm","clk":"5321958442","pt":1646314894042,"mc":[{"id":"1.195532858","rc":[{"atb":[[2.92,0]],"id":39290878},{"atb":[[2.46,0]],"id":40124755}],"con":true,"img":false}]}
{"op":"mcm","clk":"5321958730","pt":1646314897615,"mc":[{"id":"1.195532858","rc":[{"atb":[[2.8,6.22]],"id":39290878}],"con":true,"img":false}]}
{"op":"mcm","clk":"5321958748","pt":1646314897822,"mc":[{"id":"1.195532858","rc":[{"atb":[[2.42,8.74]],"id":38357910},{"atb":[[2.54,7.28]],"id":40124755}],"con":true,"img":false}]}
{"op":"mcm","clk":"5321961482","pt":1646314927695,"mc":[{"id":"1.195532858","rc":[{"atb":[[2.38,0]],"id":38357910}],"con":true,"img":false}]}
{"op":"mcm","clk":"5321961742","pt":1646314930080,"mc":[{"id":"1.195532858","rc":[{"atb":[[2.46,7.67]],"id":38357910}],"con":true,"img":false}]}
{"op":"mcm","clk":"5321964855","pt":1646314960422,"mc":[{"id":"1.195532858","rc":[{"atb":[[2.86,0]],"id":41288595},{"atb":[[2.78,0]],"id":38983972}],"con":true,"img":false}]}
{"op":"mcm","clk":"5321965185","pt":1646314963438,"mc":[{"id":"1.195532858","rc":[{"atb":[[2.94,5.77]],"id":41288595}],"con":true,"img":false}]}
{"op":"mcm","clk":"5321965202","pt":1646314963601,"mc":[{"id":"1.195532858","rc":[{"atb":[[2.86,6.02]],"id":38983972}],"con":true,"img":false}]}
{"op":"mcm","clk":"5321978928","pt":1646315106728,"mc":[{"id":"1.195532858","rc":[{"spn":5.48,"spf":1.0,"id":41288595},{"atb":[[10.5,3.78]],"id":38324360}],"con":true,"img":false}]}
{"op":"mcm","clk":"5321982825","pt":1646315134617,"mc":[{"id":"1.195532858","rc":[{"atb":[[2.96,0]],"id":39290878},{"atb":[[2.5,0]],"id":40124755}],"con":true,"img":false}]}
{"op":"mcm","clk":"5321984265","pt":1646315148592,"mc":[{"id":"1.195532858","rc":[{"atb":[[2.84,6.74]],"id":39290878}],"con":true,"img":false}]}
{"op":"mcm","clk":"5321984356","pt":1646315149530,"mc":[{"id":"1.195532858","rc":[{"atb":[[2.58,7.85]],"id":40124755}],"con":true,"img":false}]}
{"op":"mcm","clk":"5321987772","pt":1646315178772,"mc":[{"id":"1.195532858","rc":[{"atb":[[2.42,0]],"id":38357910}],"con":true,"img":false}]}
{"op":"mcm","clk":"5321989565","pt":1646315197778,"mc":[{"id":"1.195532858","rc":[{"atb":[[2.5,8.27]],"id":38357910}],"con":true,"img":false}]}
{"op":"mcm","clk":"5321991043","pt":1646315215303,"mc":[{"id":"1.195532858","rc":[{"atb":[[2.9,0]],"id":41288595},{"atb":[[2.82,0]],"id":38983972}],"con":true,"img":false}]}
{"op":"mcm","clk":"5321992166","pt":1646315226805,"mc":[{"id":"1.195532858","rc":[{"atb":[[2.9,6.53]],"id":38983972}],"con":true,"img":false}]}
{"op":"mcm","clk":"5321992198","pt":1646315227112,"mc":[{"id":"1.195532858","rc":[{"atb":[[2.98,6.27]],"id":41288595}],"con":true,"img":false}]}
{"op":"mcm","clk":"5322008157","pt":1646315369377,"mc":[{"id":"1.195532858","rc":[{"spn":5.5,"spf":1.0,"id":41288595},{"atb":[[2.54,0]],"id":40124755}],"con":true,"img":false}]}
{"op":"mcm","clk":"5322008483","pt":1646315372861,"mc":[{"id":"1.195532858","rc":[{"atb":[[2.62,6.92]],"id":40124755}],"con":true,"img":false}]}
{"op":"mcm","clk":"5322009560","pt":1646315382672,"mc":[{"id":"1.195532858","rc":[{"atb":[[2.8,0]],"id":39290878}],"con":true,"img":false}]}
{"op":"mcm","clk":"5322009760","pt":1646315384802,"mc":[{"id":"1.195532858","rc":[{"atb":[[2.88,5.96]],"id":39290878}],"con":true,"img":false}]}
{"op":"mcm","clk":"5322012734","pt":1646315411820,"mc":[{"id":"1.195532858","rc":[{"atb":[[2.46,0]],"id":38357910}],"con":true,"img":false}]}
{"op":"mcm","clk":"5322013310","pt":1646315415338,"mc":[{"id":"1.195532858","rc":[{"atb":[[2.54,7.28]],"id":38357910}],"con":true,"img":false}]}
{"op":"mcm","clk":"5322016831","pt":1646315447949,"mc":[{"id":"1.195532858","rc":[{"atb":[[2.94,0]],"id":41288595},{"atb":[[2.86,0]],"id":38983972}],"con":true,"img":false}]}
{"op":"mcm","clk":"5322017174","pt":1646315450660,"mc":[{"id":"1.195532858","rc":[{"atb":[[3.05,5.47]],"id":41288595},{"atb":[[2.94,5.77]],"id":38983972}],"con":true,"img":false}]}
{"op":"mcm","clk":"5322031639","pt":1646315613414,"mc":[{"id":"1.195532858","rc":[{"spn":5.54,"spf":1.0,"id":41288595},{"atb":[[2.58,0]],"id":40124755}],"con":true,"img":false}]}
{"op":"mcm","clk":"5322032999","pt":1646315630240,"mc":[{"id":"1.195532858","rc":[{"atb":[[2.84,0]],"id":39290878}],"con":true,"img":false}]}
{"op":"mcm","clk":"5322033005","pt":1646315630297,"mc":[{"id":"1.195532858","rc":[{"atb":[[2.66,7.48]],"id":40124755}],"con":true,"img":false}]}
{"op":"mcm","clk":"5322034056","pt":1646315644336,"mc":[{"id":"1.195532858","rc":[{"atb":[[2.5,0]],"id":38357910}],"con":true,"img":false}]}
{"op":"mcm","clk":"5322034102","pt":1646315644916,"mc":[{"id":"1.195532858","rc":[{"atb":[[2.92,6.46]],"id":39290878}],"con":true,"img":false}]}
{"op":"mcm","clk":"5322035180","pt":1646315658142,"mc":[{"id":"1.195532858","rc":[{"atb":[[2.58,7.85]],"id":38357910}],"con":true,"img":false}]}
{"op":"mcm","clk":"5322038144","pt":1646315694080,"mc":[{"id":"1.195532858","rc":[{"atb":[[2.98,0]],"id":41288595},{"atb":[[2.9,0]],"id":38983972}],"con":true,"img":false}]}
{"op":"mcm","clk":"5322039542","pt":1646315710379,"mc":[{"id":"1.195532858","rc":[{"atb":[[2.98,6.27]],"id":38983972}],"con":true,"img":false}]}
{"op":"mcm","clk":"5322039551","pt":1646315710473,"mc":[{"id":"1.195532858","rc":[{"atb":[[3.15,5.77]],"id":41288595}],"con":true,"img":false}]}
{"op":"mcm","clk":"5322041440","pt":1646315729275,"mc":[{"id":"1.195532858","rc":[{"atb":[[1.02,2.24]],"id":38324360}],"con":true,"img":false}]}
{"op":"mcm","clk":"5322041444","pt":1646315729372,"mc":[{"id":"1.195532858","rc":[{"atb":[[1.02,0.31]],"id":38324360}],"con":true,"img":false}]}
{"op":"mcm","clk":"5322041460","pt":1646315729595,"mc":[{"id":"1.195532858","rc":[{"atb":[[1.02,0]],"id":38324360}],"con":true,"img":false}]}
{"op":"mcm","clk":"5322041469","pt":1646315729696,"mc":[{"id":"1.195532858","rc":[{"atb":[[12,0.31]],"id":38324360}],"con":true,"img":false}]}
{"op":"mcm","clk":"5322042722","pt":1646315743293,"mc":[{"id":"1.195532858","rc":[{"atb":[[10.5,2.13]],"id":38324360}],"con":true,"img":false}]}
{"op":"mcm","clk":"5322042747","pt":1646315743614,"mc":[{"id":"1.195532858","rc":[{"atb":[[12,1.96]],"id":38324360}],"con":true,"img":false}]}
{"op":"mcm","clk":"5322051821","pt":1646315848440,"mc":[{"id":"1.195532858","rc":[{"spn":5.6,"spf":1.0,"id":41288595},{"spn":16.5,"spf":1.0,"id":38324360},{"atb":[[2.62,0]],"id":40124755}],"con":true,"img":false}]}
{"op":"mcm","clk":"5322052291","pt":1646315854656,"mc":[{"id":"1.195532858","rc":[{"atb":[[2.7,6.59]],"id":40124755}],"con":true,"img":false}]}
{"op":"mcm","clk":"5322052862","pt":1646315862586,"mc":[{"id":"1.195532858","rc":[{"atb":[[2.88,0]],"id":39290878}],"con":true,"img":false}]}
{"op":"mcm","clk":"5322053090","pt":1646315865962,"mc":[{"id":"1.195532858","rc":[{"atb":[[2.96,5.71]],"id":39290878}],"con":true,"img":false}]}
{"op":"mcm","clk":"5322054047","pt":1646315877668,"mc":[{"id":"1.195532858","rc":[{"atb":[[2.54,0]],"id":38357910}],"con":true,"img":false}]}
{"op":"mcm","clk":"5322054271","pt":1646315880607,"mc":[{"id":"1.195532858","rc":[{"atb":[[2.4,8]],"id":38357910}],"con":true,"img":false}]}
{"op":"mcm","clk":"5322057910","pt":1646315928758,"mc":[{"id":"1.195532858","rc":[{"atb":[[3.05,0]],"id":41288595},{"atb":[[2.94,0]],"id":38983972}],"con":true,"img":false}]}
{"op":"mcm","clk":"5322058194","pt":1646315932683,"mc":[{"id":"1.195532858","rc":[{"atb":[[3.25,4.98]],"id":41288595}],"con":true,"img":false}]}
{"op":"mcm","clk":"5322058211","pt":1646315932787,"mc":[{"id":"1.195532858","rc":[{"atb":[[3.05,5.47]],"id":38983972}],"con":true,"img":false}]}
{"op":"mcm","clk":"5322071122","pt":1646316072536,"mc":[{"id":"1.195532858","rc":[{"spn":5.65,"spf":1.0,"id":41288595},{"atb":[[3.7,0]],"id":38324360}],"con":true,"img":false}]}
{"op":"mcm","clk":"5322072839","pt":1646316093115,"mc":[{"id":"1.195532858","rc":[{"atb":[[2.66,0]],"id":40124755}],"con":true,"img":false}]}
{"op":"mcm","clk":"5322074545","pt":1646316109183,"mc":[{"id":"1.195532858","rc":[{"atb":[[2.92,0]],"id":39290878}],"con":true,"img":false}]}
{"op":"mcm","clk":"5322074559","pt":1646316109252,"mc":[{"id":"1.195532858","rc":[{"atb":[[2.74,7.13]],"id":40124755}],"con":true,"img":false}]}
{"op":"mcm","clk":"5322076086","pt":1646316124416,"mc":[{"id":"1.195532858","rc":[{"atb":[[2.8,6.89]],"id":39290878}],"con":true,"img":false}]}
{"op":"mcm","clk":"5322076097","pt":1646316124517,"mc":[{"id":"1.195532858","rc":[{"atb":[[2.58,0]],"id":38357910}],"con":true,"img":false}]}
{"op":"mcm","clk":"5322077437","pt":1646316139941,"mc":[{"id":"1.195532858","rc":[{"atb":[[2.44,8.62]],"id":38357910}],"con":true,"img":false}]}
{"op":"mcm","clk":"5322079722","pt":1646316166632,"mc":[{"id":"1.195532858","rc":[{"atb":[[3.15,0]],"id":41288595},{"atb":[[2.98,0]],"id":38983972}],"con":true,"img":false}]}
{"op":"mcm","clk":"5322080843","pt":1646316178883,"mc":[{"id":"1.195532858","rc":[{"atb":[[3.15,5.77]],"id":38983972}],"con":true,"img":false}]}
{"op":"mcm","clk":"5322080857","pt":1646316179091,"mc":[{"id":"1.195532858","rc":[{"atb":[[3.35,5.28]],"id":41288595}],"con":true,"img":false}]}
{"op":"mcm","clk":"5322093074","pt":1646316326685,"mc":[{"id":"1.195532858","rc":[{"spn":5.71,"spf":1.0,"id":41288595},{"atb":[[2.7,0]],"id":40124755}],"con":true,"img":false}]}
{"op":"mcm","clk":"5322093556","pt":1646316331988,"mc":[{"id":"1.195532858","rc":[{"atb":[[2.78,6.3]],"id":40124755}],"con":true,"img":false}]}
{"op":"mcm","clk":"5322094652","pt":1646316343882,"mc":[{"id":"1.195532858","rc":[{"atb":[[2.96,0]],"id":39290878}],"con":true,"img":false}]}
{"op":"mcm","clk":"5322094940","pt":1646316346612,"mc":[{"id":"1.195532858","rc":[{"atb":[[2.84,6.09]],"id":39290878}],"con":true,"img":false}]}
{"op":"mcm","clk":"5322097370","pt":1646316370385,"mc":[{"id":"1.195532858","rc":[{"atb":[[4.2,35.94]],"id":38324360}],"con":true,"img":false}]}
{"op":"mcm","clk":"5322097660","pt":1646316373449,"mc":[{"id":"1.195532858","rc":[{"atb":[[2.4,0]],"id":38357910}],"con":true,"img":false}]}
{"op":"mcm","clk":"5322098090","pt":1646316377668,"mc":[{"id":"1.195532858","rc":[{"atb":[[2.48,7.58]],"id":38357910}],"con":true,"img":false}]}
{"op":"mcm","clk":"5322100329","pt":1646316400640,"mc":[{"id":"1.195532858","rc":[{"atb":[[3.25,0]],"id":41288595},{"atb":[[3.05,0]],"id":38983972}],"con":true,"img":false}]}
{"op":"mcm","clk":"5322100630","pt":1646316403426,"mc":[{"id":"1.195532858","rc":[{"atb":[[3.45,4.57]],"id":41288595}],"con":true,"img":false}]}
{"op":"mcm","clk":"5322100635","pt":1646316403532,"mc":[{"id":"1.195532858","rc":[{"atb":[[3.25,4.98]],"id":38983972}],"con":true,"img":false}]}
{"op":"mcm","clk":"5322111567","pt":1646316519607,"mc":[{"id":"1.195532858","rc":[{"spn":5.77,"spf":1.0,"id":41288595},{"atb":[[2.98,1.17]],"id":38357910},{"trd":[[2.98,1.65]],"ltp":2.98,"tv":1.65,"id":38357910}],"con":true,"img":false}]}
{"op":"mcm","clk":"5322111582","pt":1646316519815,"mc":[{"id":"1.195532858","rc":[{"atb":[[1.02,2.24]],"id":41288595},{"atl":[[4.6,0]],"id":38357910}],"con":true,"img":false}]}
{"op":"mcm","clk":"5322111597","pt":1646316519983,"mc":[{"id":"1.195532858","rc":[{"atb":[[1.02,0.37]],"id":41288595},{"atl":[[5.9,2]],"id":38357910}],"con":true,"img":false}]}
{"op":"mcm","clk":"5322111607","pt":1646316520091,"mc":[{"id":"1.195532858","rc":[{"atb":[[1.02,0]],"id":41288595}],"con":true,"img":false}]}
{"op":"mcm","clk":"5322111617","pt":1646316520194,"mc":[{"id":"1.195532858","rc":[{"atb":[[10,0.37]],"id":41288595}],"con":true,"img":false}]}
{"op":"mcm","clk":"5322111956","pt":1646316524102,"mc":[{"id":"1.195532858","rc":[{"atb":[[2.98,2]],"id":38357910}],"con":true,"img":false}]}
{"op":"mcm","clk":"5322116726","pt":1646316579693,"mc":[{"id":"1.195532858","rc":[{"spn":6.07,"spf":1.0,"id":41288595},{"spn":4.44,"spf":1.0,"id":38357910},{"atb":[[2.74,0]],"id":40124755}],"con":true,"img":false}]}
{"op":"mcm","clk":"5322118141","pt":1646316594891,"mc":[{"id":"1.195532858","rc":[{"atb":[[2.8,0]],"id":39290878}],"con":true,"img":false}]}
{"op":"mcm","clk":"5322118159","pt":1646316595095,"mc":[{"id":"1.195532858","rc":[{"atb":[[2.82,6.82]],"id":40124755}],"con":true,"img":false}]}
{"op":"mcm","clk":"5322119482","pt":1646316609297,"mc":[{"id":"1.195532858","rc":[{"atb":[[2.88,6.6]],"id":39290878}],"con":true,"img":false}]}
{"op":"mcm","clk":"5322120678","pt":1646316622534,"mc":[{"id":"1.195532858","rc":[{"atb":[[2.44,0]],"id":38357910}],"con":true,"img":false}]}
{"op":"mcm","clk":"5322121678","pt":1646316633638,"mc":[{"id":"1.195532858","rc":[{"atb":[[2.52,8.17]],"id":38357910}],"con":true,"img":false}]}
{"op":"mcm","clk":"5322122862","pt":1646316647072,"mc":[{"id":"1.195532858","rc":[{"atb":[[3.35,0]],"id":41288595},{"atb":[[3.15,0]],"id":38983972}],"con":true,"img":false}]}
{"op":"mcm","clk":"5322124178","pt":1646316661591,"mc":[{"id":"1.195532858","rc":[{"atb":[[3.55,4.86]],"id":41288595}],"con":true,"img":false}]}
{"op":"mcm","clk":"5322124207","pt":1646316661857,"mc":[{"id":"1.195532858","rc":[{"atb":[[3.35,5.28]],"id":38983972}],"con":true,"img":false}]}
{"op":"mcm","clk":"5322138282","pt":1646316816233,"mc":[{"id":"1.195532858","rc":[{"spn":6.12,"spf":1.0,"id":41288595},{"atb":[[2.78,0]],"id":40124755}],"con":true,"img":false}]}
{"op":"mcm","clk":"5322138486","pt":1646316818178,"mc":[{"id":"1.195532858","rc":[{"atb":[[2.86,6.02]],"id":40124755}],"con":true,"img":false}]}
{"op":"mcm","clk":"5322139367","pt":1646316827831,"mc":[{"id":"1.195532858","rc":[{"atb":[[2.84,0]],"id":39290878}],"con":true,"img":false}]}
{"op":"mcm","clk":"5322139570","pt":1646316830334,"mc":[{"id":"1.195532858","rc":[{"atb":[[2.92,5.83]],"id":39290878}],"con":true,"img":false}]}
{"op":"mcm","clk":"5322141846","pt":1646316857768,"mc":[{"id":"1.195532858","rc":[{"atb":[[2.48,0]],"id":38357910}],"con":true,"img":false}]}
{"op":"mcm","clk":"5322142236","pt":1646316861875,"mc":[{"id":"1.195532858","rc":[{"atb":[[2.56,7.19]],"id":38357910}],"con":true,"img":false}]}
{"op":"mcm","clk":"5322143798","pt":1646316878766,"mc":[{"id":"1.195532858","rc":[{"atb":[[3.45,0]],"id":41288595},{"atb":[[3.25,0]],"id":38983972}],"con":true,"img":false}]}
{"op":"mcm","clk":"5322144062","pt":1646316881668,"mc":[{"id":"1.195532858","rc":[{"atb":[[3.65,4.23]],"id":41288595}],"con":true,"img":false}]}
{"op":"mcm","clk":"5322144114","pt":1646316882139,"mc":[{"id":"1.195532858","rc":[{"atb":[[3.45,4.57]],"id":38983972}],"con":true,"img":false}]}
{"op":"mcm","clk":"5322164226","pt":1646317106088,"mc":[{"id":"1.195532858","rc":[{"spn":6.17,"spf":1.0,"id":41288595},{"atb":[[2.88,0]],"id":39290878},{"atb":[[2.52,0]],"id":38357910},{"atb":[[2.82,0]],"id":40124755}],"con":true,"img":false}]}
{"op":"mcm","clk":"5322165429","pt":1646317119955,"mc":[{"id":"1.195532858","rc":[{"atb":[[2.9,6.53]],"id":40124755}],"con":true,"img":false}]}
{"op":"mcm","clk":"5322165446","pt":1646317120161,"mc":[{"id":"1.195532858","rc":[{"atb":[[2.4,8.86]],"id":38357910}],"con":true,"img":false}]}
{"op":"mcm","clk":"5322165485","pt":1646317120741,"mc":[{"id":"1.195532858","rc":[{"atb":[[2.96,6.33]],"id":39290878}],"con":true,"img":false}]}
{"op":"mcm","clk":"5322166331","pt":1646317131775,"mc":[{"id":"1.195532858","rc":[{"atb":[[3.55,0]],"id":41288595},{"atb":[[3.35,0]],"id":38983972}],"con":true,"img":false}]}
{"op":"mcm","clk":"5322167464","pt":1646317143576,"mc":[{"id":"1.195532858","rc":[{"atb":[[3.55,4.86]],"id":38983972}],"con":true,"img":false}]}
{"op":"mcm","clk":"5322167501","pt":1646317143793,"mc":[{"id":"1.195532858","rc":[{"atb":[[3.75,4.51]],"id":41288595}],"con":true,"img":false}]}
{"op":"mcm","clk":"5322174462","pt":1646317220501,"mc":[{"id":"1.195532858","rc":[{"spn":6.22,"spf":1.0,"id":41288595},{"atb":[[3.6,21]],"id":38983972},{"atb":[[2.98,16.67]],"id":39290878},{"atb":[[2.58,18]],"id":38357910},{"atb":[[2.92,35.99]],"id":40124755}],"con":true,"img":false}]}
{"op":"mcm","clk":"5322183127","pt":1646317322084,"mc":[{"id":"1.195532858","rc":[{"atb":[[5.3,23.26],[4.9,64.1],[5.1,36.59],[5.5,8.89],[7.6,0]],"id":41288595},{"atl":[[22,0],[23,1.82],[25,4.17],[27,5.77],[29,8.93]],"id":41288595},{"spn":6.75,"spf":1.0,"id":41288595},{"atb":[[3.8,89.29],[4.4,0],[4,33.33],[3.9,51.72],[4.2,12.5]],"id":38983972},{"atl":[[10.5,4.21],[11.5,9.52],[12.5,13.24],[13.5,20]],"id":38983972},{"atb":[[8,21.43],[8.4,13.51],[7.6,37.88],[8.8,5.13]],"id":38324360},{"atl":[[36,1.44],[40,2.56],[44,3.49],[48,5.32]],"id":38324360},{"atb":[[2.92,136.04],[3.1,19.05],[3,50],[2.96,82.86],[2.76,0]],"id":39290878},{"atl":[[6.4,7.41],[6.8,17.24],[7.2,24.19],[7.6,37.88]],"id":39290878},{"spn":6.26,"spf":8.2,"id":39290878},{"atb":[[2.56,103.34],[2.52,164.47],[2.64,24.39],[2.6,62.5]],"id":38357910},{"atl":[[6.2,7.69],[7.4,39.06],[6.6,17.86],[7,25]],"id":38357910},{"atb":[[4,13.33],[3.7,92.59],[3.8,53.57],[3.9,34.48]],"id":40124755},{"atl":[[9.6,11.63],[9.2,4.88],[10,16.67],[11,25]],"id":40124755}],"con":true,"img":false}]}
{"op":"mcm","clk":"5322183140","pt":1646317322235,"mc":[{"id":"1.195532858","rc":[{"atb":[[10,0],[6.2,1.93],[1.02,2.24]],"id":41288595},{"atl":[[15,0.72]],"id":41288595},{"atb":[[4.5,2]],"id":38983972},{"atb":[[2.78,2]],"id":39290878}],"con":true,"img":false}]}
{"op":"mcm","clk":"5322183150","pt":1646317322343,"mc":[{"id":"1.195532858","rc":[{"atb":[[1.02,0.37]],"id":41288595}],"con":true,"img":false}]}
{"op":"mcm","clk":"5322183163","pt":1646317322545,"mc":[{"id":"1.195532858","rc":[{"atb":[[1.02,0]],"id":41288595}],"con":true,"img":false}]}
{"op":"mcm","clk":"5322183174","pt":1646317322652,"mc":[{"id":"1.195532858","rc":[{"atb":[[5.6,0.37]],"id":41288595}],"con":true,"img":false}]}
{"op":"mcm","clk":"5322183371","pt":1646317324642,"mc":[{"id":"1.195532858","rc":[{"atb":[[5.6,19.39]],"id":41288595},{"atb":[[3.6,0]],"id":38983972},{"atb":[[2.98,0]],"id":39290878},{"atb":[[2.58,0]],"id":38357910},{"atb":[[2.92,0]],"id":40124755}],"con":true,"img":false}]}
{"op":"mcm","clk":"5322183450","pt":1646317325573,"mc":[{"id":"1.195532858","rc":[{"atl":[[16,2.67],[23,0]],"id":41288595}],"con":true,"img":false}]}
{"op":"mcm","clk":"5322183841","pt":1646317329767,"mc":[{"id":"1.195532858","rc":[{"atb":[[4.3,10.99]],"id":38983972},{"atb":[[3.15,42.1]],"id":39290878},{"atb":[[2.66,14]],"id":38357910}],"con":true,"img":false}]}
{"op":"mcm","clk":"5322184392","pt":1646317335558,"mc":[{"id":"1.195532858","rc":[{"atl":[[17,6.25]],"id":41288595}],"con":true,"img":false}]}
{"op":"mcm","clk":"5322184675","pt":1646317338560,"mc":[{"id":"1.195532858","rc":[{"atl":[[10.5,9.2]],"id":38357910},{"atl":[[16,9.2]],"id":40124755}],"con":true,"img":false}]}
{"op":"mcm","clk":"5322184680","pt":1646317338659,"mc":[{"id":"1.195532858","rc":[{"atl":[[18,9.2],[23,15.2]],"id":38983972},{"atl":[[13.5,15.2]],"id":38357910},{"atl":[[21,15.2]],"id":40124755}],"con":true,"img":false}]}
{"op":"mcm","clk":"5322184805","pt":1646317339874,"mc":[{"id":"1.195532858","rc":[{"atb":[[2.92,130.21]],"id":39290878},{"atb":[[2.86,0]],"id":40124755}],"con":true,"img":false}]}
{"op":"mcm","clk":"5322184814","pt":1646317339967,"mc":[{"id":"1.195532858","rc":[{"atb":[[5.6,0.37]],"id":41288595}],"con":true,"img":false}]}
{"op":"mcm","clk":"5322185349","pt":1646317345600,"mc":[{"id":"1.195532858","rc":[{"atl":[[18,8.82],[25,0],[27,0],[29,0]],"id":41288595}],"con":true,"img":false}]}
{"op":"mcm","clk":"5322185386","pt":1646317346060,"mc":[{"id":"1.195532858","rc":[{"atb":[[2.96,88.58]],"id":39290878}],"con":true,"img":false}]}
{"op":"mcm","clk":"5322185420","pt":1646317346480,"mc":[{"id":"1.195532858","rc":[{"atb":[[2.94,5.77]],"id":40124755}],"con":true,"img":false}]}
{"op":"mcm","clk":"5322186266","pt":1646317355590,"mc":[{"id":"1.195532858","rc":[{"atl":[[19,13.89]],"id":41288595}],"con":true,"img":false}]}
{"op":"mcm","clk":"5322187208","pt":1646317365605,"mc":[{"id":"1.195532858","rc":[{"atb":[[3.65,0]],"id":41288595},{"atb":[[3.45,0]],"id":38983972}],"con":true,"img":false}]}
{"op":"mcm","clk":"5322187479","pt":1646317368621,"mc":[{"id":"1.195532858","rc":[{"atb":[[9.8,0]],"id":41288595},{"trd":[[9.8,4]],"ltp":9.8,"tv":4.0,"id":41288595}],"con":true,"img":false}]}
{"op":"mcm","clk":"5322187520","pt":1646317369039,"mc":[{"id":"1.195532858","rc":[{"atb":[[3.65,4.23]],"id":38983972}],"con":true,"img":false}]}
{"op":"mcm","clk":"5322187610","pt":1646317369825,"mc":[{"id":"1.195532858","rc":[{"atl":[[5.8,1.65]],"id":38357910}],"con":true,"img":false}]}
{"op":"mcm","clk":"5322187813","pt":1646317371920,"mc":[{"id":"1.195532858","rc":[{"atb":[[3.85,3.93]],"id":41288595}],"con":true,"img":false}]}
{"op":"mcm","clk":"5322188752","pt":1646317382149,"mc":[{"id":"1.195532858","rc":[{"atb":[[6.2,0]],"id":41288595},{"trd":[[6.2,3.85]],"ltp":6.2,"tv":3.85,"id":41288595},{"spn":5.5,"spf":1.0,"id":41288595},{"spn":4.39,"spf":1.0,"id":38357910}],"con":true,"img":false}]}
{"op":"mcm","clk":"5322188773","pt":1646317382357,"mc":[{"id":"1.195532858","rc":[{"atb":[[1.01,11002.24]],"id":38983972}],"con":true,"img":false}]}
{"op":"mcm","clk":"5322188795","pt":1646317382524,"mc":[{"id":"1.195532858","rc":[{"atb":[[1.01,11000.64]],"id":38983972}],"con":true,"img":false}]}
{"op":"mcm","clk":"5322188818","pt":1646317382728,"mc":[{"id":"1.195532858","rc":[{"atb":[[1.01,11000]],"id":38983972}],"con":true,"img":false}]}
{"op":"mcm","clk":"5322188832","pt":1646317382831,"mc":[{"id":"1.195532858","rc":[{"atb":[[5.8,0.64]],"id":38983972}],"con":true,"img":false}]}
{"op":"mcm","clk":"5322189980","pt":1646317395559,"mc":[{"id":"1.195532858","rc":[{"atb":[[2.4,72.86],[2.88,48.94]],"id":38983972}],"con":true,"img":false}]}
{"op":"mcm","clk":"5322190847","pt":1646317404685,"mc":[{"id":"1.195532858","rc":[{"atb":[[4.2,2]],"id":41288595}],"con":true,"img":false}]}
{"op":"mcm","clk":"5322196119","pt":1646317462538,"mc":[{"id":"1.195532858","rc":[{"atb":[[3.55,0]],"id":38983972},{"spn":7.8,"spf":1.0,"id":38983972},{"atb":[[2.9,0]],"id":40124755}],"con":true,"img":false}]}
{"op":"mcm","clk":"5322196751","pt":1646317469678,"mc":[{"id":"1.195532858","rc":[{"atl":[[1000,16.74]],"id":41288595}],"con":true,"img":false}]}
{"op":"mcm","clk":"5322196768","pt":1646317469850,"mc":[{"id":"1.195532858","rc":[{"atl":[[1000,14.75]],"id":41288595}],"con":true,"img":false}]}
{"op":"mcm","clk":"5322196786","pt":1646317470043,"mc":[{"id":"1.195532858","rc":[{"atl":[[1000,14.5]],"id":41288595}],"con":true,"img":false}]}
{"op":"mcm","clk":"5322196794","pt":1646317470153,"mc":[{"id":"1.195532858","rc":[{"atl":[[14.5,0.25]],"id":41288595}],"con":true,"img":false}]}
{"op":"mcm","clk":"5322197186","pt":1646317474482,"mc":[{"id":"1.195532858","rc":[{"atb":[[2.98,6.27]],"id":40124755}],"con":true,"img":false}]}
{"op":"mcm","clk":"5322197194","pt":1646317474590,"mc":[{"id":"1.195532858","rc":[{"atb":[[3.9,56]],"id":38983972}],"con":true,"img":false}]}
{"op":"mcm","clk":"5322205105","pt":1646317559949,"mc":[{"id":"1.195532858","rc":[{"atb":[[3.75,0]],"id":41288595},{"atb":[[2.4,0]],"id":38357910}],"con":true,"img":false}]}
{"op":"mcm","clk":"5322206170","pt":1646317570769,"mc":[{"id":"1.195532858","rc":[{"atb":[[2.66,7.48]],"id":41288595}],"con":true,"img":false}]}
{"op":"mcm","clk":"5322206197","pt":1646317571065,"mc":[{"id":"1.195532858","rc":[{"atb":[[2.56,111.3]],"id":38357910}],"con":true,"img":false}]}
{"op":"mcm","clk":"5322210551","pt":1646317615909,"mc":[{"id":"1.195532858","rc":[{"atb":[[3.85,0]],"id":41288595},{"atb":[[3.65,0]],"id":38983972}],"con":true,"img":false}]}
{"op":"mcm","clk":"5322210843","pt":1646317619354,"mc":[{"id":"1.195532858","rc":[{"atb":[[2.7,6.59]],"id":41288595}],"con":true,"img":false}]}
{"op":"mcm","clk":"5322210856","pt":1646317619562,"mc":[{"id":"1.195532858","rc":[{"atb":[[3.9,59.86]],"id":38983972}],"con":true,"img":false}]}
{"op":"mcm","clk":"5322215212","pt":1646317664702,"mc":[{"id":"1.195532858","rc":[{"spl":[[4,15]],"id":38983972},{"spn":4.57,"spf":1.0,"id":38983972}],"con":true,"img":false}]}
{"op":"mcm","clk":"5322216558","pt":1646317677531,"mc":[{"id":"1.195532858","rc":[{"atb":[[2.8,51.11],[2.34,76.12]],"id":41288595}],"con":true,"img":false}]}
{"op":"mcm","clk":"5322216779","pt":1646317679529,"mc":[{"id":"1.195532858","rc":[{"atb":[[1.01,11002]],"id":41288595}],"con":true,"img":false}]}
{"op":"mcm","clk":"5322216798","pt":1646317679739,"mc":[{"id":"1.195532858","rc":[{"atb":[[1.01,11003.99]],"id":41288595}],"con":true,"img":false}]}
{"op":"mcm","clk":"5322216824","pt":1646317680005,"mc":[{"id":"1.195532858","rc":[{"atb":[[1.01,11002]],"id":41288595}],"con":true,"img":false}]}
{"op":"mcm","clk":"5322216832","pt":1646317680107,"mc":[{"id":"1.195532858","rc":[{"atb":[[5.6,2.36]],"id":41288595}],"con":true,"img":false}]}
{"op":"mcm","clk":"5322217334","pt":1646317685239,"mc":[{"id":"1.195532858","rc":[{"atb":[[1.01,11002]],"id":39290878}],"con":true,"img":false}]}
{"op":"mcm","clk":"5322217359","pt":1646317685448,"mc":[{"id":"1.195532858","rc":[{"atb":[[1.01,11003.99]],"id":39290878}],"con":true,"img":false}]}
{"op":"mcm","clk":"5322217375","pt":1646317685621,"mc":[{"id":"1.195532858","rc":[{"atb":[[1.01,11002]],"id":39290878}],"con":true,"img":false}]}
{"op":"mcm","clk":"5322217387","pt":1646317685720,"mc":[{"id":"1.195532858","rc":[{"atb":[[1.02,1.99]],"id":39290878}],"con":true,"img":false}]}
{"op":"mcm","clk":"5322217880","pt":1646317690861,"mc":[{"id":"1.195532858","rc":[{"atb":[[1.01,11002]],"id":38357910}],"con":true,"img":false}]}
{"op":"mcm","clk":"5322217887","pt":1646317690915,"mc":[{"id":"1.195532858","rc":[{"atb":[[1.01,11003.99]],"id":38357910}],"con":true,"img":false}]}
{"op":"mcm","clk":"5322218364","pt":1646317696636,"mc":[{"id":"1.195532858","rc":[{"atb":[[2.94,0]],"id":40124755}],"con":true,"img":false}]}
{"op":"mcm","clk":"5322218653","pt":1646317699464,"mc":[{"id":"1.195532858","rc":[{"atb":[[3.05,5.47]],"id":40124755}],"con":true,"img":false}]}
{"op":"mcm","clk":"5322218811","pt":1646317701046,"mc":[{"id":"1.195532858","rc":[{"atb":[[1.01,11002]],"id":38357910}],"con":true,"img":false}]}
{"op":"mcm","clk":"5322218824","pt":1646317701160,"mc":[{"id":"1.195532858","rc":[{"atb":[[3,1.99]],"id":38357910}],"con":true,"img":false}]}
{"op":"mcm","clk":"5322218835","pt":1646317701249,"mc":[{"id":"1.195532858","rc":[{"atb":[[1.01,11002]],"id":40124755}],"con":true,"img":false}]}
{"op":"mcm","clk":"5322218963","pt":1646317702563,"mc":[{"id":"1.195532858","rc":[{"atb":[[2.56,104.11]],"id":38357910}],"con":true,"img":false}]}
{"op":"mcm","clk":"5322219225","pt":1646317705659,"mc":[{"id":"1.195532858","rc":[{"atb":[[2.6,69.51]],"id":38357910}],"con":true,"img":false}]}
{"op":"mcm","clk":"5322219310","pt":1646317706448,"mc":[{"id":"1.195532858","rc":[{"atb":[[1.01,11003.99]],"id":40124755}],"con":true,"img":false}]}
{"op":"mcm","clk":"5322219328","pt":1646317706655,"mc":[{"id":"1.195532858","rc":[{"atb":[[1.01,11002]],"id":40124755}],"con":true,"img":false}]}
{"op":"mcm","clk":"5322219336","pt":1646317706759,"mc":[{"id":"1.195532858","rc":[{"atb":[[5.3,1.99]],"id":40124755}],"con":true,"img":false}]}
{"op":"mcm","clk":"5322219344","pt":1646317706872,"mc":[{"id":"1.195532858","rc":[{"atb":[[1.01,11002]],"id":38983972}],"con":true,"img":false}]}
{"op":"mcm","clk":"5322219351","pt":1646317706969,"mc":[{"id":"1.195532858","rc":[{"atb":[[1.01,11003.99]],"id":38983972}],"con":true,"img":false}]}
{"op":"mcm","clk":"5322219838","pt":1646317712160,"mc":[{"id":"1.195532858","rc":[{"atb":[[1.01,11002]],"id":38983972}],"con":true,"img":false}]}
{"op":"mcm","clk":"5322219849","pt":1646317712261,"mc":[{"id":"1.195532858","rc":[{"atb":[[1.02,1.99]],"id":38983972}],"con":true,"img":false}]}
{"op":"mcm","clk":"5322220107","pt":1646317715081,"mc":[{"id":"1.195532858","rc":[{"atb":[[2.7,54.12]],"id":40124755}],"con":true,"img":false}]}
{"op":"mcm","clk":"5322220116","pt":1646317715195,"mc":[{"id":"1.195532858","rc":[{"atb":[[1.73,126.03],[1.55,185.45]],"id":38357910},{"atb":[[2.28,79.69]],"id":40124755}],"con":true,"img":false}]}
{"op":"mcm","clk":"5322234728","pt":1646317876741,"mc":[{"id":"1.195532858","rc":[{"atb":[[2.66,0]],"id":41288595},{"spn":5.52,"spf":1.0,"id":41288595},{"spn":4.4,"spf":1.0,"id":38357910}],"con":true,"img":false}]}
{"op":"mcm","clk":"5322236091","pt":1646317893343,"mc":[{"id":"1.195532858","rc":[{"atb":[[2.84,6.74]],"id":41288595}],"con":true,"img":false}]}
{"op":"mcm","clk":"5322236708","pt":1646317900256,"mc":[{"id":"1.195532858","rc":[{"atb":[[3.2,11.04]],"id":39290878},{"atb":[[2.68,9.18]],"id":38357910},{"atb":[[4.1,7.58]],"id":40124755}],"con":true,"img":false}]}
{"op":"mcm","clk":"5322236725","pt":1646317900464,"mc":[{"id":"1.195532858","rc":[{"atb":[[3.05,9.03]],"id":39290878}],"con":true,"img":false}]}
{"op":"mcm","clk":"5322236764","pt":1646317900837,"mc":[{"id":"1.195532858","rc":[{"atb":[[3.05,0]],"id":39290878}],"con":true,"img":false}]}
{"op":"mcm","clk":"5322236946","pt":1646317903037,"mc":[{"id":"1.195532858","rc":[{"atb":[[3.15,0]],"id":39290878},{"atb":[[2.66,0]],"id":38357910}],"con":true,"img":false}]}
{"op":"mcm","clk":"5322237246","pt":1646317906740,"mc":[{"id":"1.195532858","rc":[{"atb":[[2.7,22.95]],"id":38357910}],"con":true,"img":false}]}
{"op":"mcm","clk":"5322237473","pt":1646317909782,"mc":[{"id":"1.195532858","rc":[{"atb":[[2.7,0]],"id":41288595}],"con":true,"img":false}]}
{"op":"mcm","clk":"5322237742","pt":1646317912457,"mc":[{"id":"1.195532858","rc":[{"atb":[[2.68,0]],"id":38357910}],"con":true,"img":false}]}
{"op":"mcm","clk":"5322237812","pt":1646317913280,"mc":[{"id":"1.195532858","rc":[{"atb":[[2.88,5.96]],"id":41288595}],"con":true,"img":false}]}
{"op":"mcm","clk":"5322238042","pt":1646317915852,"mc":[{"id":"1.195532858","rc":[{"atb":[[2.7,0]],"id":38357910}],"con":true,"img":false}]}
{"op":"mcm","clk":"5322238414","pt":1646317919866,"mc":[{"id":"1.195532858","rc":[{"atb":[[2.66,24.95]],"id":38357910}],"con":true,"img":false}]}
{"op":"mcm","clk":"5322238651","pt":1646317922271,"mc":[{"id":"1.195532858","rc":[{"atb":[[2.66,34.53]],"id":38357910}],"con":true,"img":false}]}
{"op":"mcm","clk":"5322240294","pt":1646317941711,"mc":[{"id":"1.195532858","rc":[{"atb":[[2.56,96.15]],"id":38357910},{"atb":[[2.98,0]],"id":40124755}],"con":true,"img":false}]}
{"op":"mcm","clk":"5322241090","pt":1646317952020,"mc":[{"id":"1.195532858","rc":[{"atb":[[2.6,77.27]],"id":38357910}],"con":true,"img":false}]}
{"op":"mcm","clk":"5322241115","pt":1646317952330,"mc":[{"id":"1.195532858","rc":[{"atb":[[3.15,5.77]],"id":40124755}],"con":true,"img":false}]}
{"op":"mcm","clk":"5322243197","pt":1646317980262,"mc":[{"id":"1.195532858","rc":[{"atb":[[3.2,0]],"id":39290878},{"atb":[[2.66,24.95]],"id":38357910},{"atb":[[4.1,0]],"id":40124755}],"con":true,"img":false}]}
{"op":"mcm","clk":"5322243215","pt":1646317980459,"mc":[{"id":"1.195532858","rc":[{"atb":[[3.15,5.28]],"id":39290878}],"con":true,"img":false}]}
{"op":"mcm","clk":"5322243316","pt":1646317981658,"mc":[{"id":"1.195532858","rc":[{"atb":[[3.15,0]],"id":39290878}],"con":true,"img":false}]}
{"op":"mcm","clk":"5322243615","pt":1646317985050,"mc":[{"id":"1.195532858","rc":[{"atb":[[3.15,42.1]],"id":39290878}],"con":true,"img":false}]}
{"op":"mcm","clk":"5322244160","pt":1646317992380,"mc":[{"id":"1.195532858","rc":[{"atb":[[12.5,1.47]],"id":38324360}],"con":true,"img":false}]}
{"op":"mcm","clk":"5322246359","pt":1646318022222,"mc":[{"id":"1.195532858","rc":[{"atb":[[12,0.31]],"id":38324360},{"spn":16.75,"spf":1.0,"id":38324360}],"con":true,"img":false}]}
{"op":"mcm","clk":"5322246392","pt":1646318022597,"mc":[{"id":"1.195532858","rc":[{"atb":[[13,1.65]],"id":38324360}],"con":true,"img":false}]}
{"op":"mcm","clk":"5322248580","pt":1646318049444,"mc":[{"id":"1.195532858","rc":[{"atl":[[3.1,50.3]],"id":38357910}],"con":true,"img":false}]}
{"op":"mcm","clk":"5322248602","pt":1646318049756,"mc":[{"id":"1.195532858","rc":[{"atb":[[5.4,8.95],[5.5,0],[4.2,0]],"id":41288595},{"atl":[[16,0],[15.5,2.76]],"id":41288595},{"atb":[[2.76,0]],"id":38357910},{"atl":[[6.2,0],[4.2,12.5]],"id":38357910}],"con":true,"img":false}]}
{"op":"mcm","clk":"5322248608","pt":1646318049858,"mc":[{"id":"1.195532858","rc":[{"atb":[[5.4,12.89]],"id":41288595}],"con":true,"img":false}]}
{"op":"mcm","clk":"5322248617","pt":1646318049959,"mc":[{"id":"1.195532858","rc":[{"atb":[[4.5,2]],"id":41288595},{"atb":[[2.74,3.5]],"id":38357910}],"con":true,"img":false}]}
{"op":"mcm","clk":"5322248644","pt":1646318050345,"mc":[{"id":"1.195532858","rc":[{"atb":[[5.6,0.37]],"id":41288595}],"con":true,"img":false}]}
{"op":"mcm","clk":"5322248654","pt":1646318050436,"mc":[{"id":"1.195532858","rc":[{"atb":[[5.4,8.95],[5.5,1.99]],"id":41288595},{"atb":[[2.74,0]],"id":38357910}],"con":true,"img":false}]}
{"op":"mcm","clk":"5322248678","pt":1646318050756,"mc":[{"id":"1.195532858","rc":[{"atb":[[5.7,2.48]],"id":41288595},{"atb":[[5.4,2.48]],"id":40124755}],"con":true,"img":false}]}
{"op":"mcm","clk":"5322248701","pt":1646318051064,"mc":[{"id":"1.195532858","rc":[{"atb":[[5.5,0]],"id":41288595}],"con":true,"img":false}]}
{"op":"mcm","clk":"5322248710","pt":1646318051167,"mc":[{"id":"1.195532858","rc":[{"atb":[[5.8,1.99]],"id":41288595}],"con":true,"img":false}]}
{"op":"mcm","clk":"5322248729","pt":1646318051433,"mc":[{"id":"1.195532858","rc":[{"atb":[[5.3,0]],"id":40124755}],"con":true,"img":false}]}
{"op":"mcm","clk":"5322248737","pt":1646318051535,"mc":[{"id":"1.195532858","rc":[{"atb":[[5.5,1.99]],"id":40124755}],"con":true,"img":false}]}
{"op":"mcm","clk":"5322248893","pt":1646318053669,"mc":[{"id":"1.195532858","rc":[{"atb":[[5.7,0]],"id":41288595},{"atb":[[5.4,0]],"id":40124755}],"con":true,"img":false}]}
{"op":"mcm","clk":"5322248919","pt":1646318054037,"mc":[{"id":"1.195532858","rc":[{"atb":[[5.8,0]],"id":41288595}],"con":true,"img":false}]}
{"op":"mcm","clk":"5322248926","pt":1646318054136,"mc":[{"id":"1.195532858","rc":[{"atb":[[5.7,1.99]],"id":41288595}],"con":true,"img":false}]}
{"op":"mcm","clk":"5322248942","pt":1646318054448,"mc":[{"id":"1.195532858","rc":[{"atb":[[5.5,0]],"id":40124755}],"con":true,"img":false}]}
{"op":"mcm","clk":"5322248952","pt":1646318054553,"mc":[{"id":"1.195532858","rc":[{"atb":[[5.3,1.99]],"id":40124755}],"con":true,"img":false}]}
{"op":"mcm","clk":"5322248959","pt":1646318054648,"mc":[{"id":"1.195532858","rc":[{"atb":[[5.5,2.48]],"id":41288595},{"atb":[[5.6,2.48]],"id":40124755}],"con":true,"img":false}]}
{"op":"mcm","clk":"5322248966","pt":1646318054765,"mc":[{"id":"1.195532858","rc":[{"atb":[[5.4,0],[5.5,11.23]],"id":41288595}],"con":true,"img":false}]}
{"op":"mcm","clk":"5322248986","pt":1646318055174,"mc":[{"id":"1.195532858","rc":[{"atb":[[5.3,0]],"id":40124755}],"con":true,"img":false}]}
{"op":"mcm","clk":"5322248993","pt":1646318055271,"mc":[{"id":"1.195532858","rc":[{"atb":[[5.7,1.99]],"id":40124755}],"con":true,"img":false}]}
{"op":"mcm","clk":"5322249094","pt":1646318056937,"mc":[{"id":"1.195532858","rc":[{"atb":[[5.5,8.75]],"id":41288595},{"atb":[[5.6,0]],"id":40124755}],"con":true,"img":false}]}
{"op":"mcm","clk":"5322249139","pt":1646318057663,"mc":[{"id":"1.195532858","rc":[{"atb":[[5.7,0]],"id":40124755}],"con":true,"img":false}]}
{"op":"mcm","clk":"5322249145","pt":1646318057770,"mc":[{"id":"1.195532858","rc":[{"atb":[[5.3,1.99]],"id":40124755}],"con":true,"img":false}]}
{"op":"mcm","clk":"5322249229","pt":1646318058855,"mc":[{"id":"1.195532858","rc":[{"atb":[[5.8,2.48]],"id":41288595},{"atb":[[5.4,2.48]],"id":40124755}],"con":true,"img":false}]}
{"op":"mcm","clk":"5322249262","pt":1646318059285,"mc":[{"id":"1.195532858","rc":[{"atb":[[5.7,0]],"id":41288595}],"con":true,"img":false}]}
{"op":"mcm","clk":"5322249275","pt":1646318059382,"mc":[{"id":"1.195532858","rc":[{"atb":[[5.9,1.99]],"id":41288595}],"con":true,"img":false}]}
{"op":"mcm","clk":"5322249302","pt":1646318059645,"mc":[{"id":"1.195532858","rc":[{"atb":[[5.3,0]],"id":40124755}],"con":true,"img":false}]}
{"op":"mcm","clk":"5322249316","pt":1646318059749,"mc":[{"id":"1.195532858","rc":[{"atl":[[4.4,29.41]],"id":38357910},{"atb":[[5.5,1.99]],"id":40124755}],"con":true,"img":false}]}
{"op":"mcm","clk":"5322249339","pt":1646318059971,"mc":[{"id":"1.195532858","rc":[{"atl":[[7.4,0],[6.6,0],[7,0]],"id":38357910}],"con":true,"img":false}]}
{"op":"mcm","clk":"5322249433","pt":1646318061176,"mc":[{"id":"1.195532858","rc":[{"atb":[[5.8,0]],"id":41288595},{"atb":[[5.4,0]],"id":40124755}],"con":true,"img":false}]}
{"op":"mcm","clk":"5322249502","pt":1646318062056,"mc":[{"id":"1.195532858","rc":[{"atb":[[5.9,0]],"id":41288595}],"con":true,"img":false}]}
{"op":"mcm","clk":"5322249507","pt":1646318062153,"mc":[{"id":"1.195532858","rc":[{"atb":[[5.7,1.99]],"id":41288595}],"con":true,"img":false}]}
{"op":"mcm","clk":"5322249518","pt":1646318062266,"mc":[{"id":"1.195532858","rc":[{"atb":[[5.5,0]],"id":40124755}],"con":true,"img":false}]}
{"op":"mcm","clk":"5322249527","pt":1646318062374,"mc":[{"id":"1.195532858","rc":[{"atb":[[5.3,1.99]],"id":40124755}],"con":true,"img":false}]}
{"op":"mcm","clk":"5322249547","pt":1646318062587,"mc":[{"id":"1.195532858","rc":[{"atb":[[3.95,5]],"id":40124755}],"con":true,"img":false}]}
{"op":"mcm","clk":"5322249555","pt":1646318062676,"mc":[{"id":"1.195532858","rc":[{"atb":[[3.95,0]],"id":40124755}],"con":true,"img":false}]}
{"op":"mcm","clk":"5322249620","pt":1646318063464,"mc":[{"id":"1.195532858","rc":[{"atb":[[5.8,2.48]],"id":41288595},{"atb":[[5.4,2.48]],"id":40124755}],"con":true,"img":false}]}
{"op":"mcm","clk":"5322249793","pt":1646318065750,"mc":[{"id":"1.195532858","rc":[{"atb":[[5.7,0]],"id":41288595}],"con":true,"img":false}]}
{"op":"mcm","clk":"5322249797","pt":1646318065855,"mc":[{"id":"1.195532858","rc":[{"atb":[[5.9,1.99]],"id":41288595}],"con":true,"img":false}]}
{"op":"mcm","clk":"5322249818","pt":1646318066176,"mc":[{"id":"1.195532858","rc":[{"atb":[[5.3,0]],"id":40124755}],"con":true,"img":false}]}
{"op":"mcm","clk":"5322249826","pt":1646318066270,"mc":[{"id":"1.195532858","rc":[{"atb":[[5.5,1.99]],"id":40124755}],"con":true,"img":false}]}
{"op":"mcm","clk":"5322249874","pt":1646318067055,"mc":[{"id":"1.195532858","rc":[{"atb":[[5.8,0]],"id":41288595},{"atb":[[5.4,0]],"id":40124755}],"con":true,"img":false}]}
{"op":"mcm","clk":"5322249905","pt":1646318067470,"mc":[{"id":"1.195532858","rc":[{"atb":[[5.9,0]],"id":41288595},{"atl":[[5,20]],"id":39290878}],"con":true,"img":false}]}
{"op":"mcm","clk":"5322249924","pt":1646318067689,"mc":[{"id":"1.195532858","rc":[{"atb":[[5.7,1.99]],"id":41288595}],"con":true,"img":false}]}
{"op":"mcm","clk":"5322249934","pt":1646318067734,"mc":[{"id":"1.195532858","rc":[{"atl":[[3.1,26.78]],"id":38357910},{"trd":[[3.1,47.01]],"ltp":3.1,"tv":47.01,"id":38357910}],"con":true,"img":false}]}
{"op":"mcm","clk":"5322249937","pt":1646318067848,"mc":[{"id":"1.195532858","rc":[{"atb":[[1.01,11004.52]],"id":41288595},{"atb":[[5.5,0]],"id":40124755}],"con":true,"img":false}]}
{"op":"mcm","clk":"5322249949","pt":1646318067954,"mc":[{"id":"1.195532858","rc":[{"atb":[[5.6,1.72]],"id":41288595},{"atb":[[4.4,1.4]],"id":38983972},{"atb":[[9,1.36]],"id":38324360},{"atb":[[3.2,1.33]],"id":39290878},{"atb":[[5.3,1.99],[4.1,1.33]],"id":40124755}],"con":true,"img":false}]}
{"op":"mcm","clk":"5322249955","pt":1646318068052,"mc":[{"id":"1.195532858","rc":[{"atb":[[1.01,11003.68]],"id":41288595}],"con":true,"img":false}]}
{"op":"mcm","clk":"5322249967","pt":1646318068156,"mc":[{"id":"1.195532858","rc":[{"atb":[[3.05,4.91]],"id":39290878}],"con":true,"img":false}]}
{"op":"mcm","clk":"5322249973","pt":1646318068263,"mc":[{"id":"1.195532858","rc":[{"atb":[[1.01,11002]],"id":41288595}],"con":true,"img":false}]}
{"op":"mcm","clk":"5322249981","pt":1646318068366,"mc":[{"id":"1.195532858","rc":[{"atb":[[5.6,3.4]],"id":41288595}],"con":true,"img":false}]}
{"op":"mcm","clk":"5322250000","pt":1646318068679,"mc":[{"id":"1.195532858","rc":[{"atb":[[3.05,0]],"id":39290878}],"con":true,"img":false}]}
{"op":"mcm","clk":"5322250076","pt":1646318069675,"mc":[{"id":"1.195532858","rc":[{"atb":[[5.8,2.48]],"id":41288595},{"atb":[[5.4,2.48]],"id":40124755}],"con":true,"img":false}]}
{"op":"mcm","clk":"5322250085","pt":1646318069778,"mc":[{"id":"1.195532858","rc":[{"atl":[[4.6,41.67]],"id":38357910}],"con":true,"img":false}]}
{"op":"mcm","clk":"5322250101","pt":1646318069943,"mc":[{"id":"1.195532858","rc":[{"atl":[[6.4,0],[5.3,9.3]],"id":39290878}],"con":true,"img":false}]}
{"op":"mcm","clk":"5322250112","pt":1646318070150,"mc":[{"id":"1.195532858","rc":[{"atl":[[4.9,2.52]],"id":39290878}],"con":true,"img":false}]}
{"op":"mcm","clk":"5322250132","pt":1646318070471,"mc":[{"id":"1.195532858","rc":[{"atb":[[5.7,0]],"id":41288595}],"con":true,"img":false}]}
{"op":"mcm","clk":"5322250138","pt":1646318070571,"mc":[{"id":"1.195532858","rc":[{"atb":[[5.9,1.99]],"id":41288595}],"con":true,"img":false}]}
{"op":"mcm","clk":"5322250155","pt":1646318070789,"mc":[{"id":"1.195532858","rc":[{"atb":[[5.3,0]],"id":40124755}],"con":true,"img":false}]}
{"op":"mcm","clk":"5322250166","pt":1646318070890,"mc":[{"id":"1.195532858","rc":[{"atb":[[5.5,1.99]],"id":40124755}],"con":true,"img":false}]}
{"op":"mcm","clk":"5322250187","pt":1646318071147,"mc":[{"id":"1.195532858","rc":[{"atb":[[4.3,0]],"id":38983972},{"atb":[[3.15,0]],"id":39290878}],"con":true,"img":false}]}
{"op":"mcm","clk":"5322250224","pt":1646318071676,"mc":[{"id":"1.195532858","rc":[{"atb":[[4.4,0]],"id":38983972},{"atb":[[3.2,0]],"id":39290878}],"con":true,"img":false}]}
{"op":"mcm","clk":"5322250234","pt":1646318071782,"mc":[{"id":"1.195532858","rc":[{"atb":[[4.3,1.4]],"id":38983972},{"atb":[[3.15,1.33]],"id":39290878}],"con":true,"img":false}]}
{"op":"mcm","clk":"5322250290","pt":1646318072458,"mc":[{"id":"1.195532858","rc":[{"atb":[[5.8,0]],"id":41288595},{"atb":[[5.4,0]],"id":40124755}],"con":true,"img":false}]}
{"op":"mcm","clk":"5322250353","pt":1646318073289,"mc":[{"id":"1.195532858","rc":[{"atb":[[5.9,0]],"id":41288595}],"con":true,"img":false}]}
{"op":"mcm","clk":"5322250360","pt":1646318073349,"mc":[{"id":"1.195532858","rc":[{"atb":[[5.7,1.99]],"id":41288595}],"con":true,"img":false}]}
{"op":"mcm","clk":"5322250368","pt":1646318073550,"mc":[{"id":"1.195532858","rc":[{"atb":[[5.5,0]],"id":40124755}],"con":true,"img":false}]}
{"op":"mcm","clk":"5322250373","pt":1646318073655,"mc":[{"id":"1.195532858","rc":[{"atb":[[5.3,1.99]],"id":40124755}],"con":true,"img":false}]}
{"op":"mcm","clk":"5322250456","pt":1646318074964,"mc":[{"id":"1.195532858","rc":[{"atb":[[5.8,2.48]],"id":41288595},{"atb":[[5.4,2.48]],"id":40124755}],"con":true,"img":false}]}
{"op":"mcm","clk":"5322250469","pt":1646318075173,"mc":[{"id":"1.195532858","rc":[{"atb":[[5.7,0]],"id":41288595}],"con":true,"img":false}]}
{"op":"mcm","clk":"5322250477","pt":1646318075279,"mc":[{"id":"1.195532858","rc":[{"atb":[[5.9,1.99]],"id":41288595}],"con":true,"img":false}]}
{"op":"mcm","clk":"5322250491","pt":1646318075489,"mc":[{"id":"1.195532858","rc":[{"atb":[[5.3,0]],"id":40124755}],"con":true,"img":false}]}
{"op":"mcm","clk":"5322250500","pt":1646318075591,"mc":[{"id":"1.195532858","rc":[{"atb":[[5.5,1.99]],"id":40124755}],"con":true,"img":false}]}
{"op":"mcm","clk":"5322250559","pt":1646318076175,"mc":[{"id":"1.195532858","rc":[{"atl":[[15,1.54]],"id":41288595},{"atl":[[10,0.82]],"id":38983972},{"atl":[[40,3.38]],"id":38324360},{"atl":[[4.9,3.35]],"id":39290878},{"atl":[[9,0.82]],"id":40124755}],"con":true,"img":false}]}
{"op":"mcm","clk":"5322250570","pt":1646318076276,"mc":[{"id":"1.195532858","rc":[{"atb":[[5.9,0]],"id":41288595},{"trd":[[5.9,3.97]],"ltp":5.9,"tv":3.97,"id":41288595},{"atl":[[3.1,5.82]],"id":38357910},{"trd":[[3.1,88.91]],"ltp":3.1,"tv":88.91,"id":38357910}],"con":true,"img":false}]}
{"op":"mcm","clk":"5322250583","pt":1646318076480,"mc":[{"id":"1.195532858","rc":[{"atb":[[5.6,1.72]],"id":41288595}],"con":true,"img":false}]}
{"op":"mcm","clk":"5322250628","pt":1646318076953,"mc":[{"id":"1.195532858","rc":[{"atl":[[1000,17.02]],"id":41288595}],"con":true,"img":false}]}
{"op":"mcm","clk":"5322250634","pt":1646318077156,"mc":[{"id":"1.195532858","rc":[{"atl":[[1000,16.18]],"id":41288595}],"con":true,"img":false}]}
{"op":"mcm","clk":"5322250643","pt":1646318077260,"mc":[{"id":"1.195532858","rc":[{"atb":[[5.6,3.46]],"id":41288595},{"atl":[[16.5,1],[15,1.17]],"id":41288595},{"atl":[[10,0.46]],"id":38983972},{"atl":[[40,3]],"id":38324360},{"atl":[[4.9,2.97]],"id":39290878},{"atb":[[3,5.99]],"id":38357910},{"atl":[[4.1,2.58]],"id":38357910},{"atl":[[9,0.46]],"id":40124755}],"con":true,"img":false}]}
{"op":"mcm","clk":"5322250655","pt":1646318077467,"mc":[{"id":"1.195532858","rc":[{"atl":[[1000,14.5]],"id":41288595}],"con":true,"img":false}]}
{"op":"mcm","clk":"5322250661","pt":1646318077581,"mc":[{"id":"1.195532858","rc":[{"atl":[[15,2.85]],"id":41288595}],"con":true,"img":false}]}
{"op":"mcm","clk":"5322250669","pt":1646318077690,"mc":[{"id":"1.195532858","rc":[{"atb":[[5.4,0]],"id":40124755}],"con":true,"img":false}]}
{"op":"mcm","clk":"5322250729","pt":1646318078463,"mc":[{"id":"1.195532858","rc":[{"atb":[[5.5,0]],"id":40124755}],"con":true,"img":false}]}
{"op":"mcm","clk":"5322250735","pt":1646318078568,"mc":[{"id":"1.195532858","rc":[{"atl":[[15,3.85]],"id":41288595},{"atb":[[5.3,1.99]],"id":40124755}],"con":true,"img":false}]}
{"op":"mcm","clk":"5322250747","pt":1646318078676,"mc":[{"id":"1.195532858","rc":[{"atb":[[5.8,4.04]],"id":41288595},{"atb":[[3.15,2.98]],"id":39290878},{"atb":[[4.1,2.91]],"id":40124755}],"con":true,"img":false}]}
{"op":"mcm","clk":"5322250837","pt":1646318079777,"mc":[{"id":"1.195532858","rc":[{"atb":[[2.66,0]],"id":38357910},{"atl":[[4.8,65.79]],"id":38357910}],"con":true,"img":false}]}
{"op":"mcm","clk":"5322250861","pt":1646318079990,"mc":[{"id":"1.195532858","rc":[{"atl":[[5.5,22.22]],"id":39290878}],"con":true,"img":false}]}
{"op":"mcm","clk":"5322250871","pt":1646318080094,"mc":[{"id":"1.195532858","rc":[{"atb":[[5.4,2.48]],"id":40124755}],"con":true,"img":false}]}
{"op":"mcm","clk":"5322250929","pt":1646318080773,"mc":[{"id":"1.195532858","rc":[{"atb":[[5.3,0]],"id":40124755}],"con":true,"img":false}]}
{"op":"mcm","clk":"5322250938","pt":1646318080880,"mc":[{"id":"1.195532858","rc":[{"atb":[[5.5,1.99]],"id":40124755}],"con":true,"img":false}]}
{"op":"mcm","clk":"5322251074","pt":1646318082511,"mc":[{"id":"1.195532858","rc":[{"spn":5.69,"spf":1.0,"id":41288595},{"spn":4.51,"spf":1.0,"id":38983972},{"spn":17.0,"spf":1.0,"id":38324360},{"spn":4.97,"spf":8.2,"id":39290878},{"spn":3.05,"spf":1.0,"id":38357910},{"atb":[[5.4,0]],"id":40124755}],"con":true,"img":false}]}
{"op":"mcm","clk":"5322251116","pt":1646318082990,"mc":[{"id":"1.195532858","rc":[{"atb":[[5.5,0]],"id":40124755}],"con":true,"img":false}]}
{"op":"mcm","clk":"5322251127","pt":1646318083092,"mc":[{"id":"1.195532858","rc":[{"atb":[[5.3,1.99]],"id":40124755}],"con":true,"img":false}]}
{"op":"mcm","clk":"5322251156","pt":1646318083404,"mc":[{"id":"1.195532858","rc":[{"atl":[[6.8,0],[7.2,0],[7.6,0]],"id":39290878}],"con":true,"img":false}]}
{"op":"mcm","clk":"5322251188","pt":1646318083760,"mc":[{"id":"1.195532858","rc":[{"atb":[[5.4,2.48]],"id":40124755}],"con":true,"img":false}]}
{"op":"mcm","clk":"5322251309","pt":1646318084979,"mc":[{"id":"1.195532858","rc":[{"atb":[[5.3,0]],"id":40124755}],"con":true,"img":false}]}
{"op":"mcm","clk":"5322251313","pt":1646318085075,"mc":[{"id":"1.195532858","rc":[{"atb":[[5.5,1.99]],"id":40124755}],"con":true,"img":false}]}
{"op":"mcm","clk":"5322251432","pt":1646318086293,"mc":[{"id":"1.195532858","rc":[{"atb":[[5.4,0]],"id":40124755}],"con":true,"img":false}]}
{"op":"mcm","clk":"5322251442","pt":1646318086398,"mc":[{"id":"1.195532858","rc":[{"atl":[[6,0]],"id":39290878},{"atl":[[5.8,0]],"id":38357910}],"con":true,"img":false}]}
{"op":"mcm","clk":"5322251479","pt":1646318086816,"mc":[{"id":"1.195532858","rc":[{"atb":[[5.5,0]],"id":40124755}],"con":true,"img":false}]}
{"op":"mcm","clk":"5322251488","pt":1646318086917,"mc":[{"id":"1.195532858","rc":[{"atb":[[5.3,1.99]],"id":40124755}],"con":true,"img":false}]}
{"op":"mcm","clk":"5322251552","pt":1646318087702,"mc":[{"id":"1.195532858","rc":[{"atb":[[5.4,2.48]],"id":40124755}],"con":true,"img":false}]}
{"op":"mcm","clk":"5322251578","pt":1646318088014,"mc":[{"id":"1.195532858","rc":[{"atb":[[5.3,0]],"id":40124755}],"con":true,"img":false}]}
{"op":"mcm","clk":"5322251593","pt":1646318088119,"mc":[{"id":"1.195532858","rc":[{"atb":[[5.5,1.99]],"id":40124755}],"con":true,"img":false}]}
{"op":"mcm","clk":"5322251603","pt":1646318088213,"mc":[{"id":"1.195532858","rc":[{"spb":[[1000,25]],"id":38324360}],"con":true,"img":false}]}
{"op":"mcm","clk":"5322251664","pt":1646318088896,"mc":[{"id":"1.195532858","rc":[{"atb":[[5.4,0]],"id":40124755}],"con":true,"img":false}]}
{"op":"mcm","clk":"5322251714","pt":1646318089586,"mc":[{"id":"1.195532858","rc":[{"atb":[[5.8,1.47]],"id":41288595},{"trd":[[5.8,5.14]],"ltp":5.8,"tv":5.14,"id":41288595}],"con":true,"img":false}]}
{"op":"mcm","clk":"5322251732","pt":1646318089795,"mc":[{"id":"1.195532858","rc":[{"atb":[[5.5,0]],"id":40124755}],"con":true,"img":false}]}
{"op":"mcm","clk":"5322251735","pt":1646318089890,"mc":[{"id":"1.195532858","rc":[{"atb":[[5.3,1.99]],"id":40124755}],"con":true,"img":false}]}
{"op":"mcm","clk":"5322251743","pt":1646318089994,"mc":[{"id":"1.195532858","rc":[{"atl":[[5.7,31.91]],"id":39290878}],"con":true,"img":false}]}
{"op":"mcm","clk":"5322251803","pt":1646318090789,"mc":[{"id":"1.195532858","rc":[{"atb":[[5.8,0]],"id":41288595}],"con":true,"img":false}]}
{"op":"mcm","clk":"5322251814","pt":1646318090887,"mc":[{"id":"1.195532858","rc":[{"atb":[[5.7,1.47]],"id":41288595}],"con":true,"img":false}]}
{"op":"mcm","clk":"5322251845","pt":1646318091308,"mc":[{"id":"1.195532858","rc":[{"atb":[[5.4,2.48]],"id":40124755}],"con":true,"img":false}]}
{"op":"mcm","clk":"5322251875","pt":1646318091683,"mc":[{"id":"1.195532858","rc":[{"atb":[[5.3,0]],"id":40124755}],"con":true,"img":false}]}
{"op":"mcm","clk":"5322251885","pt":1646318091786,"mc":[{"id":"1.195532858","rc":[{"atb":[[5.5,1.99]],"id":40124755}],"con":true,"img":false}]}
{"op":"mcm","clk":"5322251973","pt":1646318092892,"mc":[{"id":"1.195532858","rc":[{"atb":[[5.4,0]],"id":40124755}],"con":true,"img":false}]}
{"op":"mcm","clk":"5322252054","pt":1646318093781,"mc":[{"id":"1.195532858","rc":[{"atb":[[5.6,2.48]],"id":40124755}],"con":true,"img":false}]}
{"op":"mcm","clk":"5322252197","pt":1646318095198,"mc":[{"id":"1.195532858","rc":[{"atb":[[5.5,0]],"id":40124755}],"con":true,"img":false}]}
{"op":"mcm","clk":"5322252207","pt":1646318095301,"mc":[{"id":"1.195532858","rc":[{"atb":[[5.7,1.99]],"id":40124755}],"con":true,"img":false}]}
{"op":"mcm","clk":"5322252301","pt":1646318096407,"mc":[{"id":"1.195532858","rc":[{"atb":[[5.6,0]],"id":40124755}],"con":true,"img":false}]}
{"op":"mcm","clk":"5322252373","pt":1646318097299,"mc":[{"id":"1.195532858","rc":[{"atb":[[5.7,0]],"id":40124755}],"con":true,"img":false}]}
{"op":"mcm","clk":"5322252383","pt":1646318097418,"mc":[{"id":"1.195532858","rc":[{"atb":[[5.3,1.99]],"id":40124755}],"con":true,"img":false}]}
{"op":"mcm","clk":"5322252510","pt":1646318098983,"mc":[{"id":"1.195532858","rc":[{"atb":[[5.4,2.48]],"id":40124755}],"con":true,"img":false}]}
{"op":"mcm","clk":"5322252556","pt":1646318099615,"mc":[{"id":"1.195532858","rc":[{"atb":[[5.3,0]],"id":40124755}],"con":true,"img":false}]}
{"op":"mcm","clk":"5322252568","pt":1646318099719,"mc":[{"id":"1.195532858","rc":[{"atb":[[5.5,1.99]],"id":40124755}],"con":true,"img":false}]}
{"op":"mcm","clk":"5322252589","pt":1646318099980,"mc":[{"id":"1.195532858","rc":[{"atl":[[5.9,51.02]],"id":39290878}],"con":true,"img":false}]}
{"op":"mcm","clk":"5322252612","pt":1646318100297,"mc":[{"id":"1.195532858","rc":[{"atb":[[5.4,0]],"id":40124755}],"con":true,"img":false}]}
{"op":"mcm","clk":"5322252624","pt":1646318100509,"mc":[{"id":"1.195532858","rc":[{"atb":[[1.03,2.24]],"id":38324360}],"con":true,"img":false}]}
{"op":"mcm","clk":"5322252632","pt":1646318100615,"mc":[{"id":"1.195532858","rc":[{"atb":[[12,0]],"id":38324360}],"con":true,"img":false}]}
{"op":"mcm","clk":"5322252643","pt":1646318100719,"mc":[{"id":"1.195532858","rc":[{"atb":[[1.03,0.27]],"id":38324360}],"con":true,"img":false}]}
{"op":"mcm","clk":"5322252652","pt":1646318100823,"mc":[{"id":"1.195532858","rc":[{"atb":[[1.03,0]],"id":38324360}],"con":true,"img":false}]}
{"op":"mcm","clk":"5322252659","pt":1646318100877,"mc":[{"id":"1.195532858","rc":[{"atb":[[13.5,0.27]],"id":38324360}],"con":true,"img":false}]}
{"op":"mcm","clk":"5322252691","pt":1646318101402,"mc":[{"id":"1.195532858","rc":[{"atb":[[5.5,0]],"id":40124755}],"con":true,"img":false}]}
{"op":"mcm","clk":"5322252700","pt":1646318101507,"mc":[{"id":"1.195532858","rc":[{"atb":[[5.3,1.99]],"id":40124755}],"con":true,"img":false}]}
{"op":"mcm","clk":"5322252714","pt":1646318101718,"mc":[{"id":"1.195532858","rc":[{"atb":[[11,1.69]],"id":38324360}],"con":true,"img":false}]}
{"op":"mcm","clk":"5322252798","pt":1646318102614,"mc":[{"id":"1.195532858","rc":[{"atb":[[5.4,2.48]],"id":40124755}],"con":true,"img":false}]}
{"op":"mcm","clk":"5322252814","pt":1646318102828,"mc":[{"id":"1.195532858","rc":[{"atb":[[11,0]],"id":38324360}],"con":true,"img":false}]}
{"op":"mcm","clk":"5322252822","pt":1646318102931,"mc":[{"id":"1.195532858","rc":[{"atb":[[1.01,11001.69]],"id":38324360}],"con":true,"img":false}]}
{"op":"mcm","clk":"5322252865","pt":1646318103403,"mc":[{"id":"1.195532858","rc":[{"atb":[[5.3,0]],"id":40124755}],"con":true,"img":false}]}
{"op":"mcm","clk":"5322252876","pt":1646318103505,"mc":[{"id":"1.195532858","rc":[{"atb":[[5.5,1.99]],"id":40124755}],"con":true,"img":false}]}
{"op":"mcm","clk":"5322252893","pt":1646318103718,"mc":[{"id":"1.195532858","rc":[{"atb":[[1.01,11000]],"id":38324360}],"con":true,"img":false}]}
{"op":"mcm","clk":"5322252908","pt":1646318103821,"mc":[{"id":"1.195532858","rc":[{"atb":[[11,1.69]],"id":38324360}],"con":true,"img":false}]}
{"op":"mcm","clk":"5322252979","pt":1646318104709,"mc":[{"id":"1.195532858","rc":[{"atb":[[11,0]],"id":38324360}],"con":true,"img":false}]}
{"op":"mcm","clk":"5322252987","pt":1646318104812,"mc":[{"id":"1.195532858","rc":[{"atb":[[1.01,11001.69]],"id":38324360}],"con":true,"img":false}]}
{"op":"mcm","clk":"5322253028","pt":1646318105334,"mc":[{"id":"1.195532858","rc":[{"atb":[[5.4,0]],"id":40124755}],"con":true,"img":false}]}
{"op":"mcm","clk":"5322253081","pt":1646318106015,"mc":[{"id":"1.195532858","rc":[{"atb":[[5.5,0]],"id":40124755}],"con":true,"img":false}]}
{"op":"mcm","clk":"5322253091","pt":1646318106119,"mc":[{"id":"1.195532858","rc":[{"atb":[[5.3,1.99]],"id":40124755}],"con":true,"img":false}]}
{"op":"mcm","clk":"5322253211","pt":1646318107639,"mc":[{"id":"1.195532858","rc":[{"atb":[[5.4,2.48]],"id":40124755}],"con":true,"img":false}]}
{"op":"mcm","clk":"5322253234","pt":1646318108002,"mc":[{"id":"1.195532858","rc":[{"atb":[[5.3,0]],"id":40124755}],"con":true,"img":false}]}
{"op":"mcm","clk":"5322253243","pt":1646318108120,"mc":[{"id":"1.195532858","rc":[{"atb":[[5.5,1.99]],"id":40124755}],"con":true,"img":false}]}
{"op":"mcm","clk":"5322253311","pt":1646318109103,"mc":[{"id":"1.195532858","rc":[{"atb":[[5.4,0]],"id":40124755}],"con":true,"img":false}]}
{"op":"mcm","clk":"5322253334","pt":1646318109417,"mc":[{"id":"1.195532858","rc":[{"atb":[[5.5,0]],"id":40124755}],"con":true,"img":false}]}
{"op":"mcm","clk":"5322253340","pt":1646318109521,"mc":[{"id":"1.195532858","rc":[{"atb":[[5.3,1.99]],"id":40124755}],"con":true,"img":false}]}
{"op":"mcm","clk":"5322253377","pt":1646318109943,"mc":[{"id":"1.195532858","rc":[{"atb":[[5.6,2.48]],"id":40124755}],"con":true,"img":false}]}
{"op":"mcm","clk":"5322253429","pt":1646318110740,"mc":[{"id":"1.195532858","rc":[{"atb":[[5.3,0]],"id":40124755}],"con":true,"img":false}]}
{"op":"mcm","clk":"5322253441","pt":1646318110840,"mc":[{"id":"1.195532858","rc":[{"atb":[[5.7,1.99]],"id":40124755}],"con":true,"img":false}]}
{"op":"mcm","clk":"5322253571","pt":1646318112525,"mc":[{"id":"1.195532858","rc":[{"atb":[[5.6,0]],"id":40124755}],"con":true,"img":false}]}
{"op":"mcm","clk":"5322253639","pt":1646318113531,"mc":[{"id":"1.195532858","rc":[{"atb":[[5.7,0]],"id":40124755}],"con":true,"img":false}]}
{"op":"mcm","clk":"5322253645","pt":1646318113632,"mc":[{"id":"1.195532858","rc":[{"atb":[[5.3,1.99]],"id":40124755}],"con":true,"img":false}]}
{"op":"mcm","clk":"5322253738","pt":1646318114728,"mc":[{"id":"1.195532858","rc":[{"atb":[[5.4,2.48]],"id":40124755}],"con":true,"img":false}]}
{"op":"mcm","clk":"5322253778","pt":1646318115246,"mc":[{"id":"1.195532858","rc":[{"atb":[[5.3,0]],"id":40124755}],"con":true,"img":false}]}
{"op":"mcm","clk":"5322253782","pt":1646318115349,"mc":[{"id":"1.195532858","rc":[{"atb":[[5.5,1.99]],"id":40124755}],"con":true,"img":false}]}
{"op":"mcm","clk":"5322253879","pt":1646318116427,"mc":[{"id":"1.195532858","rc":[{"atb":[[5.4,0]],"id":40124755}],"con":true,"img":false}]}
{"op":"mcm","clk":"5322253946","pt":1646318117216,"mc":[{"id":"1.195532858","rc":[{"atb":[[5.5,0]],"id":40124755}],"con":true,"img":false}]}
{"op":"mcm","clk":"5322253957","pt":1646318117316,"mc":[{"id":"1.195532858","rc":[{"atb":[[5.3,1.99]],"id":40124755}],"con":true,"img":false}]}
{"op":"mcm","clk":"5322253965","pt":1646318117420,"mc":[{"id":"1.195532858","rc":[{"atb":[[3.1,3.8]],"id":38357910},{"atl":[[3.1,0]],"id":38357910},{"trd":[[3.1,100.5]],"ltp":3.1,"tv":100.5,"id":38357910}],"con":true,"img":false}]}
{"op":"mcm","clk":"5322253980","pt":1646318117629,"mc":[{"id":"1.195532858","rc":[{"atb":[[2.62,5.57]],"id":38357910}],"con":true,"img":false}]}
{"op":"mcm","clk":"5322253989","pt":1646318117733,"mc":[{"id":"1.195532858","rc":[{"atl":[[4,3.36]],"id":38357910}],"con":true,"img":false}]}
{"op":"mcm","clk":"5322254001","pt":1646318117942,"mc":[{"id":"1.195532858","rc":[{"atb":[[3,4]],"id":38357910}],"con":true,"img":false}]}
{"op":"mcm","clk":"5322254007","pt":1646318118048,"mc":[{"id":"1.195532858","rc":[{"atb":[[3.15,1.99]],"id":38357910}],"con":true,"img":false}]}
{"op":"mcm","clk":"5322254080","pt":1646318119041,"mc":[{"id":"1.195532858","rc":[{"atb":[[2.66,1.33]],"id":38357910}],"con":true,"img":false}]}
{"op":"mcm","clk":"5322254104","pt":1646318119354,"mc":[{"id":"1.195532858","rc":[{"atb":[[2.62,0]],"id":38357910},{"atl":[[3.95,0.82]],"id":38357910}],"con":true,"img":false}]}
{"op":"mcm","clk":"5322254199","pt":1646318120353,"mc":[{"id":"1.195532858","rc":[{"atl":[[3.95,0.43]],"id":38357910}],"con":true,"img":false}]}
{"op":"mcm","clk":"5322254217","pt":1646318120558,"mc":[{"id":"1.195532858","rc":[{"atb":[[3.2,3.64]],"id":38357910}],"con":true,"img":false}]}
{"op":"mcm","clk":"5322254273","pt":1646318121236,"mc":[{"id":"1.195532858","rc":[{"atb":[[3.15,0]],"id":38357910}],"con":true,"img":false}]}
{"op":"mcm","clk":"5322254285","pt":1646318121342,"mc":[{"id":"1.195532858","rc":[{"atb":[[1.02,1.99]],"id":38357910}],"con":true,"img":false}]}
{"op":"mcm","clk":"5322254613","pt":1646318124852,"mc":[{"id":"1.195532858","rc":[{"atb":[[3.55,8],[2.98,27],[3.2,18],[3.4,12],[3.65,5]],"id":39290878}],"con":true,"img":false}]}
{"op":"mcm","clk":"5322254635","pt":1646318125066,"mc":[{"id":"1.195532858","rc":[{"atb":[[3.05,9.02]],"id":39290878},{"atb":[[3.2,0]],"id":38357910}],"con":true,"img":false}]}
{"op":"mcm","clk":"5322254665","pt":1646318125422,"mc":[{"id":"1.195532858","rc":[{"atb":[[3.05,0]],"id":39290878}],"con":true,"img":false}]}
{"op":"mcm","clk":"5322254748","pt":1646318126467,"mc":[{"id":"1.195532858","rc":[{"atb":[[1.02,0]],"id":38357910}],"con":true,"img":false}]}
{"op":"mcm","clk":"5322254757","pt":1646318126576,"mc":[{"id":"1.195532858","rc":[{"atl":[[8,27],[5.8,8],[5.6,5],[6.2,13.93],[7,18]],"id":39290878},{"atb":[[3.15,1.99]],"id":38357910}],"con":true,"img":false}]}
{"op":"mcm","clk":"5322255477","pt":1646318135269,"mc":[{"id":"1.195532858","rc":[{"atb":[[10,15],[9.2,18],[8.2,27],[11.5,8.96],[12.5,6.47]],"id":38324360}],"con":true,"img":false}]}
{"op":"mcm","clk":"5322255493","pt":1646318135431,"mc":[{"id":"1.195532858","rc":[{"atb":[[1.03,2.24],[13.5,0]],"id":38324360}],"con":true,"img":false}]}
{"op":"mcm","clk":"5322255512","pt":1646318135640,"mc":[{"id":"1.195532858","rc":[{"atb":[[1.03,0.27]],"id":38324360}],"con":true,"img":false}]}
{"op":"mcm","clk":"5322255529","pt":1646318135851,"mc":[{"id":"1.195532858","rc":[{"atb":[[1.01,11000],[1.03,0]],"id":38324360}],"con":true,"img":false}]}
{"op":"mcm","clk":"5322255542","pt":1646318135954,"mc":[{"id":"1.195532858","rc":[{"atb":[[13,3.62]],"id":38324360}],"con":true,"img":false}]}
{"op":"mcm","clk":"5322255561","pt":1646318136163,"mc":[{"id":"1.195532858","rc":[{"atb":[[9,0]],"id":38324360}],"con":true,"img":false}]}
{"op":"mcm","clk":"5322255570","pt":1646318136267,"mc":[{"id":"1.195532858","rc":[{"atb":[[13,4.99]],"id":38324360}],"con":true,"img":false}]}
{"op":"mcm","clk":"5322255587","pt":1646318136476,"mc":[{"id":"1.195532858","rc":[{"atb":[[3.2,3.64]],"id":38357910}],"con":true,"img":false}]}
{"op":"mcm","clk":"5322255629","pt":1646318136952,"mc":[{"id":"1.195532858","rc":[{"atb":[[2.98,0]],"id":38357910}],"con":true,"img":false}]}
{"op":"mcm","clk":"5322255641","pt":1646318137161,"mc":[{"id":"1.195532858","rc":[{"atb":[[3.15,0]],"id":38357910}],"con":true,"img":false}]}
{"op":"mcm","clk":"5322255649","pt":1646318137268,"mc":[{"id":"1.195532858","rc":[{"atb":[[1.02,1.99]],"id":38357910}],"con":true,"img":false}]}
{"op":"mcm","clk":"5322255989","pt":1646318141513,"mc":[{"id":"1.195532858","rc":[{"atl":[[34,8],[70,27],[40,15],[48,23.32],[30,5]],"id":38324360}],"con":true,"img":false}]}
{"op":"mcm","clk":"5322256010","pt":1646318141769,"mc":[{"id":"1.195532858","rc":[{"atl":[[34,9.21],[36,0.3]],"id":38324360},{"atb":[[3.2,0]],"id":38357910}],"con":true,"img":false}]}
{"op":"mcm","clk":"5322256028","pt":1646318141979,"mc":[{"id":"1.195532858","rc":[{"atb":[[2.98,2]],"id":38357910}],"con":true,"img":false}]}
{"op":"mcm","clk":"5322256147","pt":1646318143657,"mc":[{"id":"1.195532858","rc":[{"spn":5.57,"spf":1.0,"id":41288595},{"spn":26.0,"spf":26.0,"id":38324360},{"atb":[[1.02,0]],"id":38357910},{"spn":3.52,"spf":1.0,"id":38357910}],"con":true,"img":false}]}
{"op":"mcm","clk":"5322256156","pt":1646318143763,"mc":[{"id":"1.195532858","rc":[{"atb":[[3.15,1.99]],"id":38357910}],"con":true,"img":false}]}
{"op":"mcm","clk":"5322256322","pt":1646318145761,"mc":[{"id":"1.195532858","rc":[{"atb":[[3.1,0]],"id":38357910}],"con":true,"img":false}]}
{"op":"mcm","clk":"5322256366","pt":1646318146384,"mc":[{"id":"1.195532858","rc":[{"atb":[[2.84,0]],"id":41288595}],"con":true,"img":false}]}
{"op":"mcm","clk":"5322256370","pt":1646318146489,"mc":[{"id":"1.195532858","rc":[{"atb":[[3.15,0]],"id":38357910}],"con":true,"img":false}]}
{"op":"mcm","clk":"5322256378","pt":1646318146599,"mc":[{"id":"1.195532858","rc":[{"atb":[[3.05,1.99]],"id":38357910}],"con":true,"img":false}]}
{"op":"mcm","clk":"5322256633","pt":1646318149600,"mc":[{"id":"1.195532858","rc":[{"atb":[[3.05,13.99]],"id":38357910}],"con":true,"img":false}]}
{"op":"mcm","clk":"5322256829","pt":1646318152069,"mc":[{"id":"1.195532858","rc":[{"atb":[[2.98,0]],"id":38357910}],"con":true,"img":false}]}
{"op":"mcm","clk":"5322256881","pt":1646318152599,"mc":[{"id":"1.195532858","rc":[{"atb":[[1.03,2.91]],"id":41288595}],"con":true,"img":false}]}
{"op":"mcm","clk":"5322256889","pt":1646318152705,"mc":[{"id":"1.195532858","rc":[{"atb":[[1.02,4.96]],"id":38983972},{"atb":[[1.06,2.81]],"id":38324360},{"atb":[[1.02,5.01]],"id":39290878},{"atb":[[1.02,3.07]],"id":38357910},{"atb":[[1.02,2.97]],"id":40124755}],"con":true,"img":false}]}
{"op":"mcm","clk":"5322256926","pt":1646318153080,"mc":[{"id":"1.195532858","rc":[{"atb":[[1.03,0.18]],"id":41288595},{"atb":[[1.02,2.23]],"id":38983972},{"atb":[[1.02,2.27]],"id":39290878}],"con":true,"img":false}]}
{"op":"mcm","clk":"5322256935","pt":1646318153183,"mc":[{"id":"1.195532858","rc":[{"atb":[[1.06,0.08]],"id":38324360},{"atb":[[1.02,0.33]],"id":38357910},{"atb":[[1.02,0.24]],"id":40124755}],"con":true,"img":false}]}
{"op":"mcm","clk":"5322256962","pt":1646318153503,"mc":[{"id":"1.195532858","rc":[{"atb":[[1.03,0]],"id":41288595},{"atb":[[1.02,1.99]],"id":38983972}],"con":true,"img":false}]}
{"op":"mcm","clk":"5322256972","pt":1646318153558,"mc":[{"id":"1.195532858","rc":[{"atb":[[5.9,0.18]],"id":41288595},{"atb":[[4.4,0.24]],"id":38983972},{"atb":[[1.06,0]],"id":38324360},{"atb":[[1.02,1.99]],"id":39290878},{"atb":[[1.02,0]],"id":38357910},{"atb":[[1.02,0]],"id":40124755}],"con":true,"img":false}]}
{"op":"mcm","clk":"5322256981","pt":1646318153663,"mc":[{"id":"1.195532858","rc":[{"atb":[[13,5.07]],"id":38324360},{"atb":[[3.75,0.28]],"id":39290878},{"atb":[[3.25,0.33]],"id":38357910},{"atb":[[4.4,0.24]],"id":40124755}],"con":true,"img":false}]}
{"op":"mcm","clk":"5322256990","pt":1646318153772,"mc":[{"id":"1.195532858","rc":[{"atb":[[5.4,3.88]],"id":41288595}],"con":true,"img":false}]}
{"op":"mcm","clk":"5322257006","pt":1646318153994,"mc":[{"id":"1.195532858","rc":[{"atb":[[5.4,0]],"id":41288595}],"con":true,"img":false}]}
{"op":"mcm","clk":"5322257233","pt":1646318156864,"mc":[{"id":"1.195532858","rc":[{"atl":[[4,1.02],[3.95,0]],"id":38357910},{"trd":[[4,4.65],[3.95,0.87]],"ltp":4.0,"tv":5.52,"id":38357910}],"con":true,"img":false}]}
{"op":"mcm","clk":"5322257241","pt":1646318156968,"mc":[{"id":"1.195532858","rc":[{"atb":[[3.3,2]],"id":38357910}],"con":true,"img":false}]}
{"op":"mcm","clk":"5322257296","pt":1646318157699,"mc":[{"id":"1.195532858","rc":[{"atb":[[3.05,14.81]],"id":38357910}],"con":true,"img":false}]}
{"op":"mcm","clk":"5322257314","pt":1646318157859,"mc":[{"id":"1.195532858","rc":[{"atb":[[3.05,12.82]],"id":38357910}],"con":true,"img":false}]}
{"op":"mcm","clk":"5322257324","pt":1646318157964,"mc":[{"id":"1.195532858","rc":[{"atb":[[1.02,1.99]],"id":38357910}],"con":true,"img":false}]}
{"op":"mcm","clk":"5322257402","pt":1646318158798,"mc":[{"id":"1.195532858","rc":[{"atb":[[3.05,12.58]],"id":38357910}],"con":true,"img":false}]}
{"op":"mcm","clk":"5322257520","pt":1646318160269,"mc":[{"id":"1.195532858","rc":[{"atb":[[3.3,0]],"id":38357910}],"con":true,"img":false}]}
{"op":"mcm","clk":"5322257583","pt":1646318160899,"mc":[{"id":"1.195532858","rc":[{"atb":[[3.4,5.17]],"id":41288595}],"con":true,"img":false}]}
{"op":"mcm","clk":"5322257607","pt":1646318161107,"mc":[{"id":"1.195532858","rc":[{"atb":[[3.3,2],[1.02,0]],"id":38357910}],"con":true,"img":false}]}
{"op":"mcm","clk":"5322257617","pt":1646318161212,"mc":[{"id":"1.195532858","rc":[{"atb":[[3.1,1.99]],"id":38357910}],"con":true,"img":false}]}
{"op":"mcm","clk":"5322257701","pt":1646318162208,"mc":[{"id":"1.195532858","rc":[{"atb":[[3.1,0]],"id":38357910}],"con":true,"img":false}]}
{"op":"mcm","clk":"5322257712","pt":1646318162313,"mc":[{"id":"1.195532858","rc":[{"atb":[[1.02,1.99]],"id":38357910}],"con":true,"img":false}]}
{"op":"mcm","clk":"5322257881","pt":1646318164413,"mc":[{"id":"1.195532858","rc":[{"atb":[[3.3,0]],"id":38357910}],"con":true,"img":false}]}
{"op":"mcm","clk":"5322257907","pt":1646318164574,"mc":[{"id":"1.195532858","rc":[{"atb":[[3.3,2]],"id":38357910}],"con":true,"img":false}]}
{"op":"mcm","clk":"5322258211","pt":1646318167884,"mc":[{"id":"1.195532858","rc":[{"atb":[[3.3,0]],"id":38357910}],"con":true,"img":false}]}
{"op":"mcm","clk":"5322258256","pt":1646318168515,"mc":[{"id":"1.195532858","rc":[{"atb":[[1.02,0]],"id":38357910}],"con":true,"img":false}]}
{"op":"mcm","clk":"5322258264","pt":1646318168619,"mc":[{"id":"1.195532858","rc":[{"atb":[[3.1,1.99]],"id":38357910}],"con":true,"img":false}]}
{"op":"mcm","clk":"5322258270","pt":1646318168680,"mc":[{"id":"1.195532858","rc":[{"atb":[[3.3,2]],"id":38357910}],"con":true,"img":false}]}
{"op":"mcm","clk":"5322258292","pt":1646318168984,"mc":[{"id":"1.195532858","rc":[{"atb":[[3,8.99]],"id":38357910}],"con":true,"img":false}]}
{"op":"mcm","clk":"5322258317","pt":1646318169404,"mc":[{"id":"1.195532858","rc":[{"atb":[[3.1,0]],"id":38357910}],"con":true,"img":false}]}
{"op":"mcm","clk":"5322258328","pt":1646318169508,"mc":[{"id":"1.195532858","rc":[{"atb":[[1.02,1.99]],"id":38357910}],"con":true,"img":false}]}
{"op":"mcm","clk":"5322258346","pt":1646318169716,"mc":[{"id":"1.195532858","rc":[{"atb":[[3,4]],"id":38357910}],"con":true,"img":false}]}
{"op":"mcm","clk":"5322258540","pt":1646318172082,"mc":[{"id":"1.195532858","rc":[{"atb":[[3.3,0]],"id":38357910}],"con":true,"img":false}]}
{"op":"mcm","clk":"5322258561","pt":1646318172394,"mc":[{"id":"1.195532858","rc":[{"atb":[[1.02,0]],"id":38357910}],"con":true,"img":false}]}
{"op":"mcm","clk":"5322258570","pt":1646318172497,"mc":[{"id":"1.195532858","rc":[{"atb":[[3.1,1.99]],"id":38357910}],"con":true,"img":false}]}
{"op":"mcm","clk":"5322258575","pt":1646318172600,"mc":[{"id":"1.195532858","rc":[{"atb":[[3.3,2]],"id":38357910}],"con":true,"img":false}]}
{"op":"mcm","clk":"5322258612","pt":1646318173123,"mc":[{"id":"1.195532858","rc":[{"atb":[[3.1,0]],"id":38357910}],"con":true,"img":false}]}
{"op":"mcm","clk":"5322258624","pt":1646318173230,"mc":[{"id":"1.195532858","rc":[{"atb":[[1.02,1.99]],"id":38357910}],"con":true,"img":false}]}
{"op":"mcm","clk":"5322258723","pt":1646318174590,"mc":[{"id":"1.195532858","rc":[{"atb":[[3.05,0]],"id":40124755}],"con":true,"img":false}]}
{"op":"mcm","clk":"5322258829","pt":1646318176015,"mc":[{"id":"1.195532858","rc":[{"atb":[[3.3,0]],"id":38357910}],"con":true,"img":false}]}
{"op":"mcm","clk":"5322258852","pt":1646318176431,"mc":[{"id":"1.195532858","rc":[{"atb":[[1.02,0]],"id":38357910}],"con":true,"img":false}]}
{"op":"mcm","clk":"5322258860","pt":1646318176486,"mc":[{"id":"1.195532858","rc":[{"atb":[[3.1,1.99]],"id":38357910}],"con":true,"img":false}]}
{"op":"mcm","clk":"5322258868","pt":1646318176588,"mc":[{"id":"1.195532858","rc":[{"atb":[[3.3,2]],"id":38357910}],"con":true,"img":false}]}
{"op":"mcm","clk":"5322258874","pt":1646318176695,"mc":[{"id":"1.195532858","rc":[{"atl":[[4.4,35.12]],"id":38357910}],"con":true,"img":false}]}
{"op":"mcm","clk":"5322258924","pt":1646318177321,"mc":[{"id":"1.195532858","rc":[{"atb":[[3.1,0]],"id":38357910}],"con":true,"img":false}]}
{"op":"mcm","clk":"5322258931","pt":1646318177431,"mc":[{"id":"1.195532858","rc":[{"atb":[[1.02,1.99]],"id":38357910}],"con":true,"img":false}]}
{"op":"mcm","clk":"5322258941","pt":1646318177536,"mc":[{"id":"1.195532858","rc":[{"atb":[[3.25,4.98]],"id":40124755}],"con":true,"img":false}]}
{"op":"mcm","clk":"5322259019","pt":1646318178315,"mc":[{"id":"1.195532858","rc":[{"atl":[[4.4,29.41]],"id":38357910}],"con":true,"img":false}]}
{"op":"mcm","clk":"5322259032","pt":1646318178523,"mc":[{"id":"1.195532858","rc":[{"atb":[[3.35,3.4]],"id":38357910}],"con":true,"img":false}]}
{"op":"mcm","clk":"5322259059","pt":1646318178838,"mc":[{"id":"1.195532858","rc":[{"atb":[[3.05,12.53]],"id":38357910}],"con":true,"img":false}]}
{"op":"mcm","clk":"5322259139","pt":1646318179940,"mc":[{"id":"1.195532858","rc":[{"atb":[[3.05,12]],"id":38357910}],"con":true,"img":false}]}
{"op":"mcm","clk":"5322259147","pt":1646318179995,"mc":[{"id":"1.195532858","rc":[{"atb":[[3.35,3.93],[3.3,0]],"id":38357910}],"con":true,"img":false}]}
{"op":"mcm","clk":"5322262752","pt":1646318223610,"mc":[{"id":"1.195532858","rc":[{"spn":5.58,"spf":1.0,"id":41288595},{"spn":4.52,"spf":1.0,"id":38983972},{"atb":[[8.2,40.89]],"id":38324360},{"atl":[[34,12.24],[30,0]],"id":38324360},{"spn":3.67,"spf":1.0,"id":38357910}],"con":true,"img":false}]}
{"op":"mcm","clk":"5322262770","pt":1646318223817,"mc":[{"id":"1.195532858","rc":[{"atb":[[5.1,60.98]],"id":41288595},{"atl":[[14.5,3.01]],"id":41288595},{"atb":[[3.8,125]],"id":38983972},{"atl":[[10.5,13.73]],"id":38983972},{"atl":[[34,11.03],[36,1.44]],"id":38324360},{"atb":[[3.05,48.78]],"id":39290878},{"atl":[[5.3,32.27]],"id":39290878},{"atb":[[2.92,24.39]],"id":38357910},{"atl":[[4.9,25.64]],"id":38357910},{"atb":[[3.75,5.78]],"id":40124755},{"atl":[[9.2,16.51]],"id":40124755}],"con":true,"img":false}]}
{"op":"mcm","clk":"5322262780","pt":1646318223878,"mc":[{"id":"1.195532858","rc":[{"atl":[[40,14.56]],"id":38324360}],"con":true,"img":false}]}
{"op":"mcm","clk":"5322262790","pt":1646318223986,"mc":[{"id":"1.195532858","rc":[{"atl":[[32,0.64]],"id":38324360}],"con":true,"img":false}]}
{"op":"mcm","clk":"5322262832","pt":1646318224499,"mc":[{"id":"1.195532858","rc":[{"atl":[[15,2.17]],"id":41288595}],"con":true,"img":false}]}
{"op":"mcm","clk":"5322262867","pt":1646318224920,"mc":[{"id":"1.195532858","rc":[{"atl":[[15,1.72]],"id":41288595}],"con":true,"img":false}]}
{"op":"mcm","clk":"5322262875","pt":1646318224993,"mc":[{"id":"1.195532858","rc":[{"atl":[[14.5,3.46]],"id":41288595}],"con":true,"img":false}]}
{"op":"mcm","clk":"5322262889","pt":1646318225092,"mc":[{"id":"1.195532858","rc":[{"atl":[[14.5,4.46]],"id":41288595}],"con":true,"img":false}]}
{"op":"mcm","clk":"5322263039","pt":1646318226920,"mc":[{"id":"1.195532858","rc":[{"atl":[[38,18],[48,50.32],[25,5],[27,8],[30,12]],"id":38324360}],"con":true,"img":false}]}
{"op":"mcm","clk":"5322263050","pt":1646318226987,"mc":[{"id":"1.195532858","rc":[{"atl":[[32,8.89]],"id":38324360}],"con":true,"img":false}]}
{"op":"mcm","clk":"5322263075","pt":1646318227300,"mc":[{"id":"1.195532858","rc":[{"atl":[[32,0.64]],"id":38324360}],"con":true,"img":false}]}
{"op":"mcm","clk":"5322263092","pt":1646318227499,"mc":[{"id":"1.195532858","rc":[{"atb":[[13,3.71]],"id":38324360}],"con":true,"img":false}]}
{"op":"mcm","clk":"5322263098","pt":1646318227609,"mc":[{"id":"1.195532858","rc":[{"atb":[[1.01,11001.36]],"id":38324360}],"con":true,"img":false}]}
{"op":"mcm","clk":"5322263121","pt":1646318227920,"mc":[{"id":"1.195532858","rc":[{"atl":[[32,0.2]],"id":38324360}],"con":true,"img":false}]}
{"op":"mcm","clk":"5322263131","pt":1646318228021,"mc":[{"id":"1.195532858","rc":[{"atl":[[24,0.44]],"id":38324360}],"con":true,"img":false}]}
{"op":"mcm","clk":"5322263553","pt":1646318233686,"mc":[{"id":"1.195532858","rc":[{"atl":[[30,15.45]],"id":38324360}],"con":true,"img":false}]}
{"op":"mcm","clk":"5322263565","pt":1646318233785,"mc":[{"id":"1.195532858","rc":[{"atl":[[34,8],[36,0.3],[26,1.6]],"id":38324360}],"con":true,"img":false}]}
{"op":"mcm","clk":"5322263577","pt":1646318233891,"mc":[{"id":"1.195532858","rc":[{"atl":[[29,3.57],[30,12]],"id":38324360},{"atb":[[2.96,24.39]],"id":38357910}],"con":true,"img":false}]}
{"op":"mcm","clk":"5322263586","pt":1646318234008,"mc":[{"id":"1.195532858","rc":[{"atb":[[2.92,0]],"id":38357910}],"con":true,"img":false}]}
{"op":"mcm","clk":"5322264100","pt":1646318239598,"mc":[{"id":"1.195532858","rc":[{"atl":[[24,0]],"id":38324360},{"trd":[[24,0.89]],"ltp":24.0,"tv":0.89,"id":38324360}],"con":true,"img":false}]}
{"op":"mcm","clk":"5322264119","pt":1646318239819,"mc":[{"id":"1.195532858","rc":[{"atl":[[26,0],[27,9.54]],"id":38324360}],"con":true,"img":false}]}
{"op":"mcm","clk":"5322264127","pt":1646318239916,"mc":[{"id":"1.195532858","rc":[{"atb":[[13,4.55]],"id":38324360}],"con":true,"img":false}]}
{"op":"mcm","clk":"5322264230","pt":1646318240914,"mc":[{"id":"1.195532858","rc":[{"atl":[[14.5,15.46]],"id":41288595}],"con":true,"img":false}]}
{"op":"mcm","clk":"5322264335","pt":1646318242115,"mc":[{"id":"1.195532858","rc":[{"atl":[[1000,17.02]],"id":41288595}],"con":true,"img":false}]}
{"op":"mcm","clk":"5322264344","pt":1646318242220,"mc":[{"id":"1.195532858","rc":[{"atl":[[1000,16.18]],"id":41288595}],"con":true,"img":false}]}
{"op":"mcm","clk":"5322264363","pt":1646318242435,"mc":[{"id":"1.195532858","rc":[{"atl":[[1000,14.5]],"id":41288595}],"con":true,"img":false}]}
{"op":"mcm","clk":"5322264372","pt":1646318242532,"mc":[{"id":"1.195532858","rc":[{"atl":[[14,1.68]],"id":41288595}],"con":true,"img":false}]}
{"op":"mcm","clk":"5322264506","pt":1646318243935,"mc":[{"id":"1.195532858","rc":[{"atl":[[15,4.58],[15.5,0]],"id":41288595}],"con":true,"img":false}]}
{"op":"mcm","clk":"5322265027","pt":1646318249847,"mc":[{"id":"1.195532858","rc":[{"atl":[[29,7.14]],"id":38324360}],"con":true,"img":false}]}
{"op":"mcm","clk":"5322265045","pt":1646318250010,"mc":[{"id":"1.195532858","rc":[{"atl":[[48,45]],"id":38324360}],"con":true,"img":false}]}
{"op":"mcm","clk":"5322265527","pt":1646318253936,"mc":[{"id":"1.195532858","rc":[{"atl":[[16,6.67]],"id":41288595}],"con":true,"img":false}]}
{"op":"mcm","clk":"5322266159","pt":1646318259840,"mc":[{"id":"1.195532858","rc":[{"atl":[[32,5.04]],"id":38324360}],"con":true,"img":false}]}
{"op":"mcm","clk":"5322266500","pt":1646318263937,"mc":[{"id":"1.195532858","rc":[{"atl":[[17,9.38],[19,0]],"id":41288595}],"con":true,"img":false}]}
{"op":"mcm","clk":"5322267035","pt":1646318269869,"mc":[{"id":"1.195532858","rc":[{"atl":[[36,7.44],[44,0]],"id":38324360}],"con":true,"img":false}]}
{"op":"mcm","clk":"5322267387","pt":1646318273963,"mc":[{"id":"1.195532858","rc":[{"atl":[[18,14.71]],"id":41288595}],"con":true,"img":false}]}
{"op":"mcm","clk":"5322267417","pt":1646318274381,"mc":[{"id":"1.195532858","rc":[{"atb":[[2,1]],"id":40124755}],"con":true,"img":false}]}
{"op":"mcm","clk":"5322267905","pt":1646318279792,"mc":[{"id":"1.195532858","rc":[{"atl":[[40,12]],"id":38324360}],"con":true,"img":false}]}
{"op":"mcm","clk":"5322267960","pt":1646318280378,"mc":[{"id":"1.195532858","rc":[{"atb":[[2,1.5]],"id":40124755}],"con":true,"img":false}]}
{"op":"mcm","clk":"5322268076","pt":1646318281685,"mc":[{"id":"1.195532858","rc":[{"atb":[[1.03,2.89]],"id":38357910}],"con":true,"img":false}]}
{"op":"mcm","clk":"5322268094","pt":1646318281896,"mc":[{"id":"1.195532858","rc":[{"atb":[[1.04,2.85]],"id":38983972},{"atb":[[1.04,2.87]],"id":39290878},{"atb":[[1.04,2.85]],"id":40124755}],"con":true,"img":false}]}
{"op":"mcm","clk":"5322268116","pt":1646318282095,"mc":[{"id":"1.195532858","rc":[{"atb":[[1.03,0.16]],"id":38357910}],"con":true,"img":false}]}
{"op":"mcm","clk":"5322268139","pt":1646318282375,"mc":[{"id":"1.195532858","rc":[{"atb":[[1.04,0.12]],"id":38983972},{"atb":[[1.04,0.14]],"id":39290878},{"atb":[[1.04,0.12]],"id":40124755}],"con":true,"img":false}]}
{"op":"mcm","clk":"5322268160","pt":1646318282582,"mc":[{"id":"1.195532858","rc":[{"atb":[[1.03,0]],"id":38357910}],"con":true,"img":false}]}
{"op":"mcm","clk":"5322268167","pt":1646318282690,"mc":[{"id":"1.195532858","rc":[{"atb":[[3.3,0.16]],"id":38357910}],"con":true,"img":false}]}
{"op":"mcm","clk":"5322268174","pt":1646318282797,"mc":[{"id":"1.195532858","rc":[{"atb":[[1.04,0]],"id":38983972},{"atb":[[1.04,0]],"id":39290878},{"atb":[[1.04,0]],"id":40124755}],"con":true,"img":false}]}
{"op":"mcm","clk":"5322268185","pt":1646318282896,"mc":[{"id":"1.195532858","rc":[{"atb":[[4.4,0.36]],"id":38983972},{"atb":[[3.75,0.43]],"id":39290878},{"atb":[[3,8.5]],"id":38357910},{"atb":[[4.4,0.36]],"id":40124755}],"con":true,"img":false}]}
{"op":"mcm","clk":"5322268276","pt":1646318283794,"mc":[{"id":"1.195532858","rc":[{"spn":4.52,"spf":1.0,"id":38983972},{"spn":25.0,"spf":26.0,"id":38324360},{"atb":[[3,4]],"id":38357910}],"con":true,"img":false}]}
{"op":"mcm","clk":"5322268434","pt":1646318285264,"mc":[{"id":"1.195532858","rc":[{"atb":[[2.88,0]],"id":41288595}],"con":true,"img":false}]}
{"op":"mcm","clk":"5322268704","pt":1646318287796,"mc":[{"id":"1.195532858","rc":[{"atb":[[3.15,0]],"id":40124755}],"con":true,"img":false}]}
{"op":"mcm","clk":"5322268809","pt":1646318289002,"mc":[{"id":"1.195532858","rc":[{"atb":[[3.5,4.48]],"id":41288595}],"con":true,"img":false}]}
{"op":"mcm","clk":"5322269027","pt":1646318291208,"mc":[{"id":"1.195532858","rc":[{"atb":[[5.3,0]],"id":40124755},{"atl":[[5.3,13.01]],"id":40124755},{"trd":[[5.3,3.98]],"ltp":5.3,"tv":3.98,"id":40124755}],"con":true,"img":false}]}
{"op":"mcm","clk":"5322269043","pt":1646318291373,"mc":[{"id":"1.195532858","rc":[{"atl":[[14,3.68]],"id":41288595},{"atb":[[13,6.55]],"id":38324360},{"atb":[[3.35,5.93]],"id":38357910}],"con":true,"img":false}]}
{"op":"mcm","clk":"5322269053","pt":1646318291481,"mc":[{"id":"1.195532858","rc":[{"atl":[[13.5,4.58],[14.5,12.7]],"id":41288595},{"atl":[[9.4,4.11]],"id":40124755}],"con":true,"img":false}]}
{"op":"mcm","clk":"5322269087","pt":1646318291900,"mc":[{"id":"1.195532858","rc":[{"atb":[[4.1,1.58]],"id":40124755},{"atl":[[9.4,0]],"id":40124755}],"con":true,"img":false}]}
{"op":"mcm","clk":"5322269096","pt":1646318292002,"mc":[{"id":"1.195532858","rc":[{"atb":[[1.01,11003.33]],"id":40124755}],"con":true,"img":false}]}
{"op":"mcm","clk":"5322269107","pt":1646318292105,"mc":[{"id":"1.195532858","rc":[{"atl":[[14.5,12.25]],"id":41288595}],"con":true,"img":false}]}
{"op":"mcm","clk":"5322269117","pt":1646318292211,"mc":[{"id":"1.195532858","rc":[{"atl":[[13,0.45],[13.5,6.58],[14,0]],"id":41288595}],"con":true,"img":false}]}
{"op":"mcm","clk":"5322269142","pt":1646318292518,"mc":[{"id":"1.195532858","rc":[{"atb":[[4.1,0]],"id":40124755}],"con":true,"img":false}]}
{"op":"mcm","clk":"5322269154","pt":1646318292572,"mc":[{"id":"1.195532858","rc":[{"atb":[[1.01,11004.91]],"id":40124755}],"con":true,"img":false}]}
{"op":"mcm","clk":"5322269262","pt":1646318293881,"mc":[{"id":"1.195532858","rc":[{"atl":[[1000,17.02]],"id":41288595}],"con":true,"img":false}]}
{"op":"mcm","clk":"5322269282","pt":1646318294197,"mc":[{"id":"1.195532858","rc":[{"atl":[[1000,16.18]],"id":41288595}],"con":true,"img":false}]}
{"op":"mcm","clk":"5322269302","pt":1646318294407,"mc":[{"id":"1.195532858","rc":[{"atb":[[5.3,46.52],[5.1,36.59],[4.5,0]],"id":41288595},{"atl":[[14,3.08],[15,1.72],[1000,14.5]],"id":41288595},{"atb":[[3.8,89.29],[4.1,32.26]],"id":38983972},{"atb":[[9.2,30.2],[8.2,27]],"id":38324360},{"atl":[[29,3.57],[30,15.45]],"id":38324360},{"atl":[[5.3,9.3],[5.5,44.44]],"id":39290878},{"atb":[[4.3,0],[3.75,0],[4,46.66]],"id":40124755},{"atl":[[8,5.71],[9.2,0],[7.2,16.13]],"id":40124755}],"con":true,"img":false}]}
{"op":"mcm","clk":"5322269310","pt":1646318294515,"mc":[{"id":"1.195532858","rc":[{"atl":[[13,2.13]],"id":41288595}],"con":true,"img":false}]}
{"op":"mcm","clk":"5322269686","pt":1646318298297,"mc":[{"id":"1.195532858","rc":[{"atb":[[1.01,11003.65]],"id":41288595},{"atl":[[1000,16.15]],"id":41288595}],"con":true,"img":false}]}
{"op":"mcm","clk":"5322269698","pt":1646318298400,"mc":[{"id":"1.195532858","rc":[{"atb":[[1.01,11002.68]],"id":41288595},{"atb":[[1.03,1.65]],"id":38324360}],"con":true,"img":false}]}
{"op":"mcm","clk":"5322269708","pt":1646318298499,"mc":[{"id":"1.195532858","rc":[{"atl":[[13.5,7.58]],"id":41288595}],"con":true,"img":false}]}
{"op":"mcm","clk":"5322269719","pt":1646318298607,"mc":[{"id":"1.195532858","rc":[{"atl":[[1000,14.83]],"id":41288595}],"con":true,"img":false}]}
{"op":"mcm","clk":"5322269729","pt":1646318298711,"mc":[{"id":"1.195532858","rc":[{"atb":[[5.7,3.47]],"id":41288595},{"atl":[[13,4.13],[13.5,5.58]],"id":41288595}],"con":true,"img":false}]}
{"op":"mcm","clk":"5322269740","pt":1646318298813,"mc":[{"id":"1.195532858","rc":[{"atb":[[1.01,11002]],"id":41288595}],"con":true,"img":false}]}
{"op":"mcm","clk":"5322269757","pt":1646318298912,"mc":[{"id":"1.195532858","rc":[{"atb":[[6,0.68]],"id":41288595},{"atl":[[12.5,4.14],[13.5,1]],"id":41288595}],"con":true,"img":false}]}
{"op":"mcm","clk":"5322269773","pt":1646318299125,"mc":[{"id":"1.195532858","rc":[{"atl":[[1000,14.5]],"id":41288595},{"atb":[[1.03,0.3]],"id":38324360}],"con":true,"img":false}]}
{"op":"mcm","clk":"5322269784","pt":1646318299191,"mc":[{"id":"1.195532858","rc":[{"atl":[[12.5,4.47],[13,3.68]],"id":41288595}],"con":true,"img":false}]}
{"op":"mcm","clk":"5322269795","pt":1646318299292,"mc":[{"id":"1.195532858","rc":[{"atl":[[12,0.45]],"id":41288595},{"atb":[[1.01,11003.65]],"id":38983972}],"con":true,"img":false}]}
{"op":"mcm","clk":"5322269804","pt":1646318299393,"mc":[{"id":"1.195532858","rc":[{"atl":[[12.5,6.47],[13,1.68]],"id":41288595},{"atb":[[1.03,0]],"id":38324360}],"con":true,"img":false}]}
{"op":"mcm","clk":"5322269820","pt":1646318299503,"mc":[{"id":"1.195532858","rc":[{"atb":[[5.6,2.11]],"id":41288595},{"atl":[[13,5.01],[14,0]],"id":41288595},{"atb":[[13.5,0.3]],"id":38324360}],"con":true,"img":false}]}
{"op":"mcm","clk":"5322269828","pt":1646318299603,"mc":[{"id":"1.195532858","rc":[{"atb":[[5.7,4.82]],"id":41288595}],"con":true,"img":false}]}
{"op":"mcm","clk":"5322269836","pt":1646318299711,"mc":[{"id":"1.195532858","rc":[{"atb":[[1.01,11002.7]],"id":38983972}],"con":true,"img":false}]}
{"op":"mcm","clk":"5322269854","pt":1646318299910,"mc":[{"id":"1.195532858","rc":[{"atl":[[12.5,7.47]],"id":41288595},{"atb":[[1.01,11002]],"id":38983972}],"con":true,"img":false}]}
{"op":"mcm","clk":"5322269863","pt":1646318300016,"mc":[{"id":"1.195532858","rc":[{"atb":[[5.9,0.7]],"id":38983972}],"con":true,"img":false}]}
{"op":"mcm","clk":"5322269899","pt":1646318300387,"mc":[{"id":"1.195532858","rc":[{"atb":[[4.3,2.96]],"id":38983972}],"con":true,"img":false}]}
{"op":"mcm","clk":"5322269993","pt":1646318301227,"mc":[{"id":"1.195532858","rc":[{"atl":[[13,3.33]],"id":41288595}],"con":true,"img":false}]}
{"op":"mcm","clk":"5322270035","pt":1646318301608,"mc":[{"id":"1.195532858","rc":[{"atb":[[5.9,3.18]],"id":38983972}],"con":true,"img":false}]}
{"op":"mcm","clk":"5322270244","pt":1646318303811,"mc":[{"id":"1.195532858","rc":[{"atb":[[5.3,23.26],[5.6,10.86]],"id":41288595}],"con":true,"img":false}]}
{"op":"mcm","clk":"5322270258","pt":1646318304016,"mc":[{"id":"1.195532858","rc":[{"atb":[[2,1]],"id":40124755}],"con":true,"img":false}]}
{"op":"mcm","clk":"5322270265","pt":1646318304121,"mc":[{"id":"1.195532858","rc":[{"atb":[[4.8,3.27]],"id":38324360}],"con":true,"img":false}]}
{"op":"mcm","clk":"5322270293","pt":1646318304394,"mc":[{"id":"1.195532858","rc":[{"atl":[[8.4,13.51]],"id":40124755}],"con":true,"img":false}]}
{"op":"mcm","clk":"5322270314","pt":1646318304610,"mc":[{"id":"1.195532858","rc":[{"atl":[[32,8.27],[30,12]],"id":38324360},{"atl":[[11,0]],"id":40124755}],"con":true,"img":false}]}
{"op":"mcm","clk":"5322270592","pt":1646318307424,"mc":[{"id":"1.195532858","rc":[{"atb":[[3.35,5.28]],"id":40124755}],"con":true,"img":false}]}
{"op":"mcm","clk":"5322270724","pt":1646318308927,"mc":[{"id":"1.195532858","rc":[{"atb":[[5.6,2.11],[5.5,30.97]],"id":41288595}],"con":true,"img":false}]}
{"op":"mcm","clk":"5322270783","pt":1646318309501,"mc":[{"id":"1.195532858","rc":[{"atl":[[14,7.69]],"id":41288595}],"con":true,"img":false}]}
{"op":"mcm","clk":"5322270808","pt":1646318309712,"mc":[{"id":"1.195532858","rc":[{"atb":[[5.7,2.82]],"id":41288595},{"atl":[[12.5,5.47]],"id":41288595}],"con":true,"img":false}]}
{"op":"mcm","clk":"5322270874","pt":1646318310437,"mc":[{"id":"1.195532858","rc":[{"atb":[[5.7,1.34]],"id":41288595}],"con":true,"img":false}]}
{"op":"mcm","clk":"5322270886","pt":1646318310547,"mc":[{"id":"1.195532858","rc":[{"atb":[[5.6,3.58]],"id":41288595}],"con":true,"img":false}]}
{"op":"mcm","clk":"5322270911","pt":1646318310707,"mc":[{"id":"1.195532858","rc":[{"atb":[[5.7,0]],"id":41288595}],"con":true,"img":false}]}
{"op":"mcm","clk":"5322270919","pt":1646318310824,"mc":[{"id":"1.195532858","rc":[{"atb":[[5.6,4.93]],"id":41288595},{"atl":[[5.3,0]],"id":40124755},{"trd":[[5.3,30]],"ltp":5.3,"tv":30.0,"id":40124755}],"con":true,"img":false}]}
{"op":"mcm","clk":"5322270938","pt":1646318311032,"mc":[{"id":"1.195532858","rc":[{"atb":[[3.35,6.91]],"id":38357910},{"atl":[[4,1.86]],"id":38357910},{"atb":[[5.2,2.45]],"id":40124755},{"atl":[[8.4,27.02],[7.2,0.34]],"id":40124755}],"con":true,"img":false}]}
{"op":"mcm","clk":"5322270954","pt":1646318311233,"mc":[{"id":"1.195532858","rc":[{"atl":[[9,0]],"id":40124755}],"con":true,"img":false}]}
{"op":"mcm","clk":"5322270964","pt":1646318311337,"mc":[{"id":"1.195532858","rc":[{"atl":[[7,0.46]],"id":40124755}],"con":true,"img":false}]}
{"op":"mcm","clk":"5322270985","pt":1646318311536,"mc":[{"id":"1.195532858","rc":[{"atb":[[13,4.55]],"id":38324360},{"atb":[[3.35,4.91]],"id":38357910},{"atl":[[8,11.42],[8.4,13.51],[7,0.81]],"id":40124755}],"con":true,"img":false}]}
{"op":"mcm","clk":"5322270994","pt":1646318311604,"mc":[{"id":"1.195532858","rc":[{"atb":[[1.01,11003.58]],"id":40124755}],"con":true,"img":false}]}
{"op":"mcm","clk":"5322271006","pt":1646318311710,"mc":[{"id":"1.195532858","rc":[{"atb":[[4.1,3.91]],"id":40124755}],"con":true,"img":false}]}
{"op":"mcm","clk":"5322271051","pt":1646318312426,"mc":[{"id":"1.195532858","rc":[{"atl":[[7,0.35]],"id":40124755}],"con":true,"img":false}]}
{"op":"mcm","clk":"5322271060","pt":1646318312435,"mc":[{"id":"1.195532858","rc":[{"atl":[[7.8,0.46]],"id":40124755}],"con":true,"img":false}]}
{"op":"mcm","clk":"5322271073","pt":1646318312669,"mc":[{"id":"1.195532858","rc":[{"atb":[[2,1.5]],"id":40124755}],"con":true,"img":false}]}
{"op":"mcm","clk":"5322271253","pt":1646318314402,"mc":[{"id":"1.195532858","rc":[{"atl":[[8.8,20.52]],"id":40124755}],"con":true,"img":false}]}
{"op":"mcm","clk":"5322271776","pt":1646318319520,"mc":[{"id":"1.195532858","rc":[{"atl":[[15,12.43],[18,0]],"id":41288595}],"con":true,"img":false}]}
{"op":"mcm","clk":"5322271810","pt":1646318319735,"mc":[{"id":"1.195532858","rc":[{"atl":[[17,0]],"id":41288595},{"atl":[[32,5.04],[30,15.45]],"id":38324360},{"atl":[[5.4,22.73],[5.5,22.22]],"id":39290878},{"atb":[[4,13.33],[4.2,31.25]],"id":40124755},{"atl":[[10,0]],"id":40124755}],"con":true,"img":false}]}
{"op":"mcm","clk":"5322271851","pt":1646318320137,"mc":[{"id":"1.195532858","rc":[{"atb":[[4.1,2.58]],"id":40124755}],"con":true,"img":false}]}
{"op":"mcm","clk":"5322271859","pt":1646318320247,"mc":[{"id":"1.195532858","rc":[{"atb":[[4.3,1.33]],"id":40124755}],"con":true,"img":false}]}
{"op":"mcm","clk":"5322271880","pt":1646318320407,"mc":[{"id":"1.195532858","rc":[{"atb":[[2,1],[4.1,4.58]],"id":40124755}],"con":true,"img":false}]}
{"op":"mcm","clk":"5322271890","pt":1646318320511,"mc":[{"id":"1.195532858","rc":[{"atb":[[5,0.5]],"id":40124755}],"con":true,"img":false}]}
{"op":"mcm","clk":"5322272077","pt":1646318322234,"mc":[{"id":"1.195532858","rc":[{"atb":[[4.1,2.58]],"id":40124755}],"con":true,"img":false}]}
{"op":"mcm","clk":"5322272100","pt":1646318322447,"mc":[{"id":"1.195532858","rc":[{"atb":[[4.4,2.71]],"id":40124755}],"con":true,"img":false}]}
{"op":"mcm","clk":"5322272251","pt":1646318323942,"mc":[{"id":"1.195532858","rc":[{"atl":[[1000,17.02]],"id":40124755}],"con":true,"img":false}]}
{"op":"mcm","clk":"5322272278","pt":1646318324116,"mc":[{"id":"1.195532858","rc":[{"atl":[[1000,16.6]],"id":40124755}],"con":true,"img":false}]}
{"op":"mcm","clk":"5322272293","pt":1646318324215,"mc":[{"id":"1.195532858","rc":[{"atl":[[1000,14.5]],"id":40124755}],"con":true,"img":false}]}
{"op":"mcm","clk":"5322272302","pt":1646318324310,"mc":[{"id":"1.195532858","rc":[{"atl":[[7.6,2.1]],"id":40124755}],"con":true,"img":false}]}
{"op":"mcm","clk":"5322272317","pt":1646318324416,"mc":[{"id":"1.195532858","rc":[{"atl":[[8,5.71],[9.2,30.49],[7.6,4.2]],"id":40124755}],"con":true,"img":false}]}
{"op":"mcm","clk":"5322272401","pt":1646318325251,"mc":[{"id":"1.195532858","rc":[{"atl":[[7.8,0]],"id":40124755}],"con":true,"img":false}]}
{"op":"mcm","clk":"5322272412","pt":1646318325303,"mc":[{"id":"1.195532858","rc":[{"atl":[[7.4,0.46]],"id":40124755}],"con":true,"img":false}]}
{"op":"mcm","clk":"5322272705","pt":1646318328539,"mc":[{"id":"1.195532858","rc":[{"atb":[[1.01,11003]],"id":41288595}],"con":true,"img":false}]}
{"op":"mcm","clk":"5322272808","pt":1646318329539,"mc":[{"id":"1.195532858","rc":[{"atl":[[16,23.34]],"id":41288595}],"con":true,"img":false}]}
{"op":"mcm","clk":"5322272817","pt":1646318329640,"mc":[{"id":"1.195532858","rc":[{"atl":[[16,16.67]],"id":41288595}],"con":true,"img":false}]}
{"op":"mcm","clk":"5322272970","pt":1646318331150,"mc":[{"id":"1.195532858","rc":[{"atl":[[7.6,2.1]],"id":40124755}],"con":true,"img":false}]}
{"op":"mcm","clk":"5322272988","pt":1646318331358,"mc":[{"id":"1.195532858","rc":[{"atl":[[8.2,1.11]],"id":40124755}],"con":true,"img":false}]}
{"op":"mcm","clk":"5322273053","pt":1646318332041,"mc":[{"id":"1.195532858","rc":[{"atb":[[3.9,0]],"id":39290878},{"atl":[[3.9,0.22]],"id":39290878},{"trd":[[3.9,4.98]],"ltp":3.9,"tv":4.98,"id":39290878},{"atb":[[3.35,3.42]],"id":38357910},{"trd":[[3.35,2.96]],"ltp":3.35,"tv":2.96,"id":38357910}],"con":true,"img":false}]}
{"op":"mcm","clk":"5322273073","pt":1646318332248,"mc":[{"id":"1.195532858","rc":[{"atb":[[3.05,0],[3.2,36]],"id":39290878},{"atl":[[7.4,0]],"id":40124755}],"con":true,"img":false}]}
{"op":"mcm","clk":"5322273088","pt":1646318332355,"mc":[{"id":"1.195532858","rc":[{"atl":[[7.8,0.46]],"id":40124755}],"con":true,"img":false}]}
{"op":"mcm","clk":"5322273168","pt":1646318333232,"mc":[{"id":"1.195532858","rc":[{"atl":[[7.8,0]],"id":40124755}],"con":true,"img":false}]}
{"op":"mcm","clk":"5322273180","pt":1646318333337,"mc":[{"id":"1.195532858","rc":[{"atl":[[7.8,1.18],[7.6,2.56]],"id":40124755}],"con":true,"img":false}]}
{"op":"mcm","clk":"5322273237","pt":1646318333861,"mc":[{"id":"1.195532858","rc":[{"atb":[[3.65,7]],"id":39290878}],"con":true,"img":false}]}
{"op":"mcm","clk":"5322273298","pt":1646318334433,"mc":[{"id":"1.195532858","rc":[{"atl":[[9.6,0]],"id":40124755}],"con":true,"img":false}]}
{"op":"mcm","clk":"5322275016","pt":1646318352814,"mc":[{"id":"1.195532858","rc":[{"spn":5.61,"spf":1.0,"id":41288595},{"spn":4.89,"spf":1.0,"id":38983972},{"spn":4.94,"spf":8.2,"id":39290878},{"atb":[[2.6,70.26]],"id":38357910}],"con":true,"img":false}]}
{"op":"mcm","clk":"5322275031","pt":1646318353021,"mc":[{"id":"1.195532858","rc":[{"atb":[[5.6,26.67],[5.5,8.75]],"id":41288595},{"atl":[[32,8.27],[30,12]],"id":38324360},{"atb":[[3.55,0],[3.65,2]],"id":39290878},{"atl":[[4.9,12.27],[5.4,0]],"id":39290878},{"atl":[[8,11.42],[7.6,0.46]],"id":40124755}],"con":true,"img":false}]}
{"op":"mcm","clk":"5322275040","pt":1646318353117,"mc":[{"id":"1.195532858","rc":[{"atb":[[3.85,3.94]],"id":38983972},{"atb":[[3.5,4.88]],"id":39290878},{"atl":[[7.8,4.87]],"id":40124755}],"con":true,"img":false}]}
{"op":"mcm","clk":"5322275052","pt":1646318353177,"mc":[{"id":"1.195532858","rc":[{"atb":[[4.9,69.11]],"id":41288595}],"con":true,"img":false}]}
{"op":"mcm","clk":"5322275060","pt":1646318353286,"mc":[{"id":"1.195532858","rc":[{"atb":[[3.85,0]],"id":38983972},{"atb":[[3.5,0]],"id":39290878},{"atl":[[7.6,0]],"id":40124755}],"con":true,"img":false}]}
{"op":"mcm","clk":"5322275077","pt":1646318353392,"mc":[{"id":"1.195532858","rc":[{"atl":[[7.8,5.33]],"id":40124755}],"con":true,"img":false}]}
{"op":"mcm","clk":"5322275086","pt":1646318353497,"mc":[{"id":"1.195532858","rc":[{"atl":[[4.9,15.22]],"id":39290878}],"con":true,"img":false}]}
{"op":"mcm","clk":"5322275099","pt":1646318353600,"mc":[{"id":"1.195532858","rc":[{"atb":[[4.9,64.1]],"id":41288595}],"con":true,"img":false}]}
{"op":"mcm","clk":"5322275193","pt":1646318354592,"mc":[{"id":"1.195532858","rc":[{"atl":[[7.8,1.64]],"id":40124755}],"con":true,"img":false}]}
{"op":"mcm","clk":"5322275232","pt":1646318355002,"mc":[{"id":"1.195532858","rc":[{"atl":[[1000,17.02]],"id":40124755}],"con":true,"img":false}]}
{"op":"mcm","clk":"5322275241","pt":1646318355117,"mc":[{"id":"1.195532858","rc":[{"atl":[[1000,16.6]],"id":40124755}],"con":true,"img":false}]}
{"op":"mcm","clk":"5322275268","pt":1646318355429,"mc":[{"id":"1.195532858","rc":[{"atl":[[1000,14.5]],"id":40124755}],"con":true,"img":false}]}
{"op":"mcm","clk":"5322275280","pt":1646318355521,"mc":[{"id":"1.195532858","rc":[{"atb":[[2.7,6.59]],"id":38357910},{"atl":[[7.6,2.1]],"id":40124755}],"con":true,"img":false}]}
{"op":"mcm","clk":"5322275489","pt":1646318358090,"mc":[{"id":"1.195532858","rc":[{"atl":[[8.2,4.36]],"id":40124755}],"con":true,"img":false}]}
{"op":"mcm","clk":"5322275502","pt":1646318358197,"mc":[{"id":"1.195532858","rc":[{"atl":[[8.2,1.11]],"id":40124755}],"con":true,"img":false}]}
{"op":"mcm","clk":"5322276064","pt":1646318364123,"mc":[{"id":"1.195532858","rc":[{"atb":[[2.6,62.5]],"id":38357910}],"con":true,"img":false}]}
{"op":"mcm","clk":"5322277425","pt":1646318378440,"mc":[{"id":"1.195532858","rc":[{"atb":[[2.74,7.13]],"id":38357910}],"con":true,"img":false}]}
{"op":"mcm","clk":"5322278338","pt":1646318388150,"mc":[{"id":"1.195532858","rc":[{"atl":[[25,0]],"id":38324360}],"con":true,"img":false}]}
{"op":"mcm","clk":"5322278358","pt":1646318388358,"mc":[{"id":"1.195532858","rc":[{"atl":[[26,3.75]],"id":38324360}],"con":true,"img":false}]}
{"op":"mcm","clk":"5322278375","pt":1646318388522,"mc":[{"id":"1.195532858","rc":[{"atl":[[27,8],[28,1.48]],"id":38324360}],"con":true,"img":false}]}
{"op":"mcm","clk":"5322278411","pt":1646318388935,"mc":[{"id":"1.195532858","rc":[{"atl":[[27,0]],"id":38324360}],"con":true,"img":false}]}
{"op":"mcm","clk":"5322278420","pt":1646318389037,"mc":[{"id":"1.195532858","rc":[{"atl":[[26,0]],"id":38324360}],"con":true,"img":false}]}
{"op":"mcm","clk":"5322278433","pt":1646318389241,"mc":[{"id":"1.195532858","rc":[{"atl":[[28,0],[30,13.38]],"id":38324360}],"con":true,"img":false}]}
{"op":"mcm","clk":"5322278473","pt":1646318389663,"mc":[{"id":"1.195532858","rc":[{"atb":[[1.01,11000]],"id":38324360}],"con":true,"img":false}]}
{"op":"mcm","clk":"5322278479","pt":1646318389716,"mc":[{"id":"1.195532858","rc":[{"atb":[[13.5,1.67]],"id":38324360}],"con":true,"img":false}]}
{"op":"mcm","clk":"5322278649","pt":1646318391663,"mc":[{"id":"1.195532858","rc":[{"atb":[[1.01,11004.24],[5.8,0]],"id":38983972}],"con":true,"img":false}]}
{"op":"mcm","clk":"5322278671","pt":1646318391833,"mc":[{"id":"1.195532858","rc":[{"atb":[[1.01,11002.62]],"id":38983972}],"con":true,"img":false}]}
{"op":"mcm","clk":"5322278679","pt":1646318391933,"mc":[{"id":"1.195532858","rc":[{"atb":[[1.01,11002]],"id":38983972}],"con":true,"img":false}]}
{"op":"mcm","clk":"5322278683","pt":1646318392027,"mc":[{"id":"1.195532858","rc":[{"atb":[[6,0.62]],"id":38983972}],"con":true,"img":false}]}
{"op":"mcm","clk":"5322278829","pt":1646318393037,"mc":[{"id":"1.195532858","rc":[{"atb":[[3.35,15.42]],"id":38357910}],"con":true,"img":false}]}
{"op":"mcm","clk":"5322279064","pt":1646318395636,"mc":[{"id":"1.195532858","rc":[{"atb":[[3.4,2.94]],"id":38357910}],"con":true,"img":false}]}
{"op":"mcm","clk":"5322279079","pt":1646318395759,"mc":[{"id":"1.195532858","rc":[{"atb":[[3.4,4.03]],"id":38357910}],"con":true,"img":false}]}
{"op":"mcm","clk":"5322279100","pt":1646318395945,"mc":[{"id":"1.195532858","rc":[{"atb":[[5.6,4.93],[5.5,35.78]],"id":41288595},{"atb":[[9.2,18],[9.6,11.63]],"id":38324360},{"atl":[[32,4.72],[29,0]],"id":38324360},{"atl":[[4.3,17.87],[4.2,0]],"id":38357910},{"atl":[[8,5.71],[7.8,3.64]],"id":40124755}],"con":true,"img":false}]}
{"op":"mcm","clk":"5322279116","pt":1646318396149,"mc":[{"id":"1.195532858","rc":[{"atb":[[5,5.02]],"id":41288595},{"atl":[[12.5,5.14],[1000,16.15]],"id":41288595}],"con":true,"img":false}]}
{"op":"mcm","clk":"5322279125","pt":1646318396260,"mc":[{"id":"1.195532858","rc":[{"atb":[[3.35,14.89]],"id":38357910}],"con":true,"img":false}]}
{"op":"mcm","clk":"5322279127","pt":1646318396357,"mc":[{"id":"1.195532858","rc":[{"atb":[[5,0]],"id":41288595},{"atl":[[12.5,1],[13,8.93],[1000,14.85]],"id":41288595},{"atb":[[3.4,4.56]],"id":38357910}],"con":true,"img":false}]}
{"op":"mcm","clk":"5322279153","pt":1646318396567,"mc":[{"id":"1.195532858","rc":[{"atl":[[1000,14.5]],"id":41288595}],"con":true,"img":false}]}
{"op":"mcm","clk":"5322279161","pt":1646318396625,"mc":[{"id":"1.195532858","rc":[{"atl":[[11.5,0.35]],"id":41288595}],"con":true,"img":false}]}
{"op":"mcm","clk":"5322279207","pt":1646318397248,"mc":[{"id":"1.195532858","rc":[{"atb":[[5.5,30.97]],"id":41288595},{"atl":[[12,0]],"id":41288595},{"atl":[[4.3,12.12]],"id":38357910}],"con":true,"img":false}]}
{"op":"mcm","clk":"5322279213","pt":1646318397350,"mc":[{"id":"1.195532858","rc":[{"atl":[[12.5,1.45]],"id":41288595}],"con":true,"img":false}]}
{"op":"mcm","clk":"5322279305","pt":1646318398547,"mc":[{"id":"1.195532858","rc":[{"atl":[[12.5,4.93],[13,5.6]],"id":41288595}],"con":true,"img":false}]}
{"op":"mcm","clk":"5322279394","pt":1646318399645,"mc":[{"id":"1.195532858","rc":[{"atb":[[13,2.9]],"id":38324360}],"con":true,"img":false}]}
{"op":"mcm","clk":"5322279402","pt":1646318399750,"mc":[{"id":"1.195532858","rc":[{"atl":[[34,11.03]],"id":38324360}],"con":true,"img":false}]}
{"op":"mcm","clk":"5322279419","pt":1646318399957,"mc":[{"id":"1.195532858","rc":[{"atb":[[13.5,0.3]],"id":38324360},{"atl":[[32,1.49]],"id":38324360}],"con":true,"img":false}]}
{"op":"mcm","clk":"5322279428","pt":1646318400063,"mc":[{"id":"1.195532858","rc":[{"atb":[[1.01,11001.36]],"id":38324360}],"con":true,"img":false}]}
{"op":"mcm","clk":"5322279798","pt":1646318404554,"mc":[{"id":"1.195532858","rc":[{"atb":[[25,2.94]],"id":38324360}],"con":true,"img":false}]}
{"op":"mcm","clk":"5322279804","pt":1646318404654,"mc":[{"id":"1.195532858","rc":[{"atb":[[25,0.02]],"id":38324360},{"trd":[[25,5.87]],"ltp":25.0,"tv":5.87,"id":38324360}],"con":true,"img":false}]}
{"op":"mcm","clk":"5322279821","pt":1646318404862,"mc":[{"id":"1.195532858","rc":[{"atb":[[9.6,0],[6,20]],"id":38324360},{"atl":[[34,9.21],[46,2.22],[30,12]],"id":38324360},{"atl":[[4.3,0],[4.2,12.5]],"id":38357910}],"con":true,"img":false}]}
{"op":"mcm","clk":"5322280643","pt":1646318413579,"mc":[{"id":"1.195532858","rc":[{"spn":4.9,"spf":1.0,"id":38983972},{"atb":[[4.8,0]],"id":38324360},{"spn":26.0,"spf":26.0,"id":38324360},{"spn":4.87,"spf":8.2,"id":39290878},{"spn":3.7,"spf":1.0,"id":38357910}],"con":true,"img":false}]}
{"op":"mcm","clk":"5322280772","pt":1646318414881,"mc":[{"id":"1.195532858","rc":[{"atl":[[32,0.2],[38,20.7]],"id":38324360}],"con":true,"img":false}]}
{"op":"mcm","clk":"5322281089","pt":1646318418609,"mc":[{"id":"1.195532858","rc":[{"atl":[[11.5,0],[1000,16.15]],"id":41288595}],"con":true,"img":false}]}
{"op":"mcm","clk":"5322281120","pt":1646318418872,"mc":[{"id":"1.195532858","rc":[{"atl":[[1000,14.85]],"id":41288595}],"con":true,"img":false}]}
{"op":"mcm","clk":"5322281185","pt":1646318419606,"mc":[{"id":"1.195532858","rc":[{"atl":[[1000,14.5]],"id":41288595}],"con":true,"img":false}]}
{"op":"mcm","clk":"5322281195","pt":1646318419722,"mc":[{"id":"1.195532858","rc":[{"atl":[[12,0.35]],"id":41288595}],"con":true,"img":false}]}
{"op":"mcm","clk":"5322281502","pt":1646318423281,"mc":[{"id":"1.195532858","rc":[{"atb":[[1.01,11002]],"id":41288595}],"con":true,"img":false}]}
{"op":"mcm","clk":"5322281518","pt":1646318423486,"mc":[{"id":"1.195532858","rc":[{"atb":[[5.4,22.73],[5.5,8.75]],"id":41288595},{"atl":[[12.5,1.45],[13,8.93]],"id":41288595},{"atl":[[7.8,1.64],[7.6,5.74]],"id":40124755}],"con":true,"img":false}]}
{"op":"mcm","clk":"5322281538","pt":1646318423696,"mc":[{"id":"1.195532858","rc":[{"atb":[[3.8,93.23]],"id":38983972},{"atl":[[1000,16.15]],"id":40124755}],"con":true,"img":false}]}
{"op":"mcm","clk":"5322281553","pt":1646318423902,"mc":[{"id":"1.195532858","rc":[{"atl":[[1000,15.06]],"id":40124755}],"con":true,"img":false}]}
{"op":"mcm","clk":"5322281563","pt":1646318424010,"mc":[{"id":"1.195532858","rc":[{"atb":[[3.8,89.29]],"id":38983972}],"con":true,"img":false}]}
{"op":"mcm","clk":"5322281572","pt":1646318424114,"mc":[{"id":"1.195532858","rc":[{"atl":[[1000,14.5]],"id":40124755}],"con":true,"img":false}]}
{"op":"mcm","clk":"5322281579","pt":1646318424217,"mc":[{"id":"1.195532858","rc":[{"atl":[[7.4,0.56],[7.8,1.18]],"id":40124755}],"con":true,"img":false}]}
{"op":"mcm","clk":"5322281591","pt":1646318424310,"mc":[{"id":"1.195532858","rc":[{"atl":[[7.4,1.02]],"id":40124755}],"con":true,"img":false}]}
{"op":"mcm","clk":"5322281605","pt":1646318424413,"mc":[{"id":"1.195532858","rc":[{"atb":[[3.75,2]],"id":40124755},{"atl":[[8.4,15.51]],"id":40124755}],"con":true,"img":false}]}
{"op":"mcm","clk":"5322281613","pt":1646318424479,"mc":[{"id":"1.195532858","rc":[{"atl":[[8,7.71]],"id":40124755}],"con":true,"img":false}]}
{"op":"mcm","clk":"5322281625","pt":1646318424583,"mc":[{"id":"1.195532858","rc":[{"atb":[[3.75,0]],"id":40124755},{"atl":[[8.4,13.51]],"id":40124755}],"con":true,"img":false}]}
{"op":"mcm","clk":"5322281643","pt":1646318424790,"mc":[{"id":"1.195532858","rc":[{"atl":[[7.6,3.64]],"id":40124755}],"con":true,"img":false}]}
{"op":"mcm","clk":"5322281651","pt":1646318424891,"mc":[{"id":"1.195532858","rc":[{"atl":[[42,3.66]],"id":38324360}],"con":true,"img":false}]}
{"op":"mcm","clk":"5322281694","pt":1646318425412,"mc":[{"id":"1.195532858","rc":[{"atl":[[8,5.71]],"id":40124755}],"con":true,"img":false}]}
{"op":"mcm","clk":"5322282143","pt":1646318430533,"mc":[{"id":"1.195532858","rc":[{"atb":[[5.9,2.8],[6,0]],"id":38983972},{"trd":[[5.9,0.76],[6,1.24]],"ltp":5.9,"tv":2.0,"id":38983972},{"atb":[[3.75,0],[3.65,1.43]],"id":39290878},{"trd":[[3.65,1.14],[3.75,0.86]],"ltp":3.65,"tv":2.0,"id":39290878},{"atb":[[3.4,3.56]],"id":38357910},{"trd":[[3.4,2]],"ltp":3.4,"tv":2.0,"id":38357910}],"con":true,"img":false}]}
{"op":"mcm","clk":"5322282161","pt":1646318430703,"mc":[{"id":"1.195532858","rc":[{"atb":[[1.01,11003.65],[6,0]],"id":41288595},{"atl":[[5.7,37.35]],"id":39290878}],"con":true,"img":false}]}
{"op":"mcm","clk":"5322282172","pt":1646318430802,"mc":[{"id":"1.195532858","rc":[{"atb":[[1.01,11000]],"id":38324360},{"atb":[[1.02,0]],"id":39290878},{"atl":[[4.3,12.12],[4.2,0]],"id":38357910}],"con":true,"img":false}]}
{"op":"mcm","clk":"5322282183","pt":1646318430911,"mc":[{"id":"1.195532858","rc":[{"atb":[[1.01,11002.68],[5.4,0],[5.1,60.98]],"id":41288595},{"atl":[[1000,16.15]],"id":38983972},{"atb":[[13,4.26]],"id":38324360},{"atb":[[3.45,1.99]],"id":39290878},{"atl":[[7.8,3.18],[7.6,0]],"id":40124755}],"con":true,"img":false}]}
{"op":"mcm","clk":"5322282202","pt":1646318431130,"mc":[{"id":"1.195532858","rc":[{"atb":[[1.01,11002]],"id":41288595},{"atl":[[5.7,31.91]],"id":39290878}],"con":true,"img":false}]}
{"op":"mcm","clk":"5322282213","pt":1646318431237,"mc":[{"id":"1.195532858","rc":[{"atb":[[5.6,5.62]],"id":41288595}],"con":true,"img":false}]}
{"op":"mcm","clk":"5322282228","pt":1646318431402,"mc":[{"id":"1.195532858","rc":[{"atl":[[1000,14.93]],"id":38983972}],"con":true,"img":false}]}
{"op":"mcm","clk":"5322282239","pt":1646318431604,"mc":[{"id":"1.195532858","rc":[{"atl":[[1000,14.5]],"id":38983972}],"con":true,"img":false}]}
{"op":"mcm","clk":"5322282247","pt":1646318431712,"mc":[{"id":"1.195532858","rc":[{"atl":[[9.6,0.43]],"id":38983972}],"con":true,"img":false}]}
{"op":"mcm","clk":"5322282308","pt":1646318432341,"mc":[{"id":"1.195532858","rc":[{"atl":[[1000,17.02]],"id":38983972},{"atl":[[7.4,0.56]],"id":40124755}],"con":true,"img":false}]}
{"op":"mcm","clk":"5322282318","pt":1646318432435,"mc":[{"id":"1.195532858","rc":[{"atl":[[7.8,3.64]],"id":40124755}],"con":true,"img":false}]}
{"op":"mcm","clk":"5322282325","pt":1646318432504,"mc":[{"id":"1.195532858","rc":[{"atl":[[1000,16.6]],"id":38983972}],"con":true,"img":false}]}
{"op":"mcm","clk":"5322282344","pt":1646318432713,"mc":[{"id":"1.195532858","rc":[{"atl":[[1000,14.5]],"id":38983972}],"con":true,"img":false}]}
{"op":"mcm","clk":"5322282351","pt":1646318432811,"mc":[{"id":"1.195532858","rc":[{"atl":[[9.6,2.53]],"id":38983972}],"con":true,"img":false}]}
{"op":"mcm","clk":"5322282367","pt":1646318433023,"mc":[{"id":"1.195532858","rc":[{"atl":[[10.5,4.21],[9.6,4.53]],"id":38983972}],"con":true,"img":false}]}
{"op":"mcm","clk":"5322282379","pt":1646318433132,"mc":[{"id":"1.195532858","rc":[{"atb":[[3.15,1.33]],"id":39290878}],"con":true,"img":false}]}
{"op":"mcm","clk":"5322282389","pt":1646318433234,"mc":[{"id":"1.195532858","rc":[{"atb":[[3.45,3.64]],"id":39290878}],"con":true,"img":false}]}
{"op":"mcm","clk":"5322282418","pt":1646318433497,"mc":[{"id":"1.195532858","rc":[{"atl":[[10,4.9],[10.5,0]],"id":38983972}],"con":true,"img":false}]}
{"op":"mcm","clk":"5322282429","pt":1646318433601,"mc":[{"id":"1.195532858","rc":[{"atb":[[1.01,11003.65],[5.6,4.93]],"id":41288595}],"con":true,"img":false}]}
{"op":"mcm","clk":"5322282452","pt":1646318433810,"mc":[{"id":"1.195532858","rc":[{"atb":[[1.01,11002.68]],"id":41288595}],"con":true,"img":false}]}
{"op":"mcm","clk":"5322282462","pt":1646318433915,"mc":[{"id":"1.195532858","rc":[{"atb":[[1.01,11002]],"id":41288595}],"con":true,"img":false}]}
{"op":"mcm","clk":"5322282473","pt":1646318434017,"mc":[{"id":"1.195532858","rc":[{"atb":[[6,0.68]],"id":41288595}],"con":true,"img":false}]}
{"op":"mcm","clk":"5322282554","pt":1646318434906,"mc":[{"id":"1.195532858","rc":[{"atl":[[46,7.78]],"id":38324360}],"con":true,"img":false}]}
{"op":"mcm","clk":"5322282565","pt":1646318435014,"mc":[{"id":"1.195532858","rc":[{"atb":[[3.65,0]],"id":39290878}],"con":true,"img":false}]}
{"op":"mcm","clk":"5322282589","pt":1646318435216,"mc":[{"id":"1.195532858","rc":[{"atb":[[3.25,19.05],[3.2,18]],"id":39290878}],"con":true,"img":false}]}
{"op":"mcm","clk":"5322282608","pt":1646318435425,"mc":[{"id":"1.195532858","rc":[{"atb":[[3.15,5.19]],"id":39290878}],"con":true,"img":false}]}
{"op":"mcm","clk":"5322282630","pt":1646318435630,"mc":[{"id":"1.195532858","rc":[{"atb":[[3.15,1.33]],"id":39290878}],"con":true,"img":false}]}
{"op":"mcm","clk":"5322282654","pt":1646318435801,"mc":[{"id":"1.195532858","rc":[{"atl":[[36,0.3]],"id":38324360}],"con":true,"img":false}]}
{"op":"mcm","clk":"5322282825","pt":1646318437518,"mc":[{"id":"1.195532858","rc":[{"atb":[[1.55,0]],"id":38357910}],"con":true,"img":false}]}
{"op":"mcm","clk":"5322283097","pt":1646318440416,"mc":[{"id":"1.195532858","rc":[{"atb":[[3.25,0],[3.2,42]],"id":39290878}],"con":true,"img":false}]}
{"op":"mcm","clk":"5322283134","pt":1646318440830,"mc":[{"id":"1.195532858","rc":[{"atl":[[4.5,28.57]],"id":38357910}],"con":true,"img":false}]}
{"op":"mcm","clk":"5322284050","pt":1646318450833,"mc":[{"id":"1.195532858","rc":[{"atl":[[4.7,40.54]],"id":38357910}],"con":true,"img":false}]}
{"op":"mcm","clk":"5322284061","pt":1646318450937,"mc":[{"id":"1.195532858","rc":[{"atl":[[4.8,0],[4.4,0],[4.6,0],[4.7,46.1]],"id":38357910}],"con":true,"img":false}]}
{"op":"mcm","clk":"5322284112","pt":1646318451358,"mc":[{"id":"1.195532858","rc":[{"atl":[[4.7,40.54]],"id":38357910}],"con":true,"img":false}]}
{"op":"mcm","clk":"5322284450","pt":1646318454946,"mc":[{"id":"1.195532858","rc":[{"atb":[[5.7,4.06]],"id":41288595},{"atb":[[4.6,5.89]],"id":38983972}],"con":true,"img":false}]}
{"op":"mcm","clk":"5322284488","pt":1646318455356,"mc":[{"id":"1.195532858","rc":[{"atb":[[5.6,3.46]],"id":41288595}],"con":true,"img":false}]}
{"op":"mcm","clk":"5322284498","pt":1646318455462,"mc":[{"id":"1.195532858","rc":[{"atb":[[5.8,1.47]],"id":41288595}],"con":true,"img":false}]}
{"op":"mcm","clk":"5322284508","pt":1646318455559,"mc":[{"id":"1.195532858","rc":[{"atb":[[5.6,2.11]],"id":41288595},{"atb":[[4.3,1.55]],"id":38983972},{"atb":[[13,2.9]],"id":38324360}],"con":true,"img":false}]}
{"op":"mcm","clk":"5322284520","pt":1646318455664,"mc":[{"id":"1.195532858","rc":[{"atb":[[5.8,2.82]],"id":41288595},{"atb":[[4.7,1.4]],"id":38983972},{"atb":[[1.01,11001.36]],"id":38324360}],"con":true,"img":false}]}
{"op":"mcm","clk":"5322284594","pt":1646318456462,"mc":[{"id":"1.195532858","rc":[{"atb":[[5.8,1.47]],"id":41288595}],"con":true,"img":false}]}
{"op":"mcm","clk":"5322284602","pt":1646318456562,"mc":[{"id":"1.195532858","rc":[{"atb":[[5.6,3.46]],"id":41288595}],"con":true,"img":false}]}
{"op":"mcm","clk":"5322284611","pt":1646318456656,"mc":[{"id":"1.195532858","rc":[{"atb":[[5.8,3.14]],"id":41288595}],"con":true,"img":false}]}
{"op":"mcm","clk":"5322284693","pt":1646318457809,"mc":[{"id":"1.195532858","rc":[{"atl":[[8,1]],"id":41288595},{"atb":[[25,0]],"id":38324360},{"atl":[[20,0.98]],"id":38324360},{"trd":[[25,5.91]],"ltp":25.0,"tv":5.91,"id":38324360}],"con":true,"img":false}]}
{"op":"mcm","clk":"5322284710","pt":1646318458021,"mc":[{"id":"1.195532858","rc":[{"atl":[[36,3.8]],"id":38324360}],"con":true,"img":false}]}
{"op":"mcm","clk":"5322284737","pt":1646318458333,"mc":[{"id":"1.195532858","rc":[{"atb":[[3.4,0]],"id":41288595}],"con":true,"img":false}]}
{"op":"mcm","clk":"5322284746","pt":1646318458426,"mc":[{"id":"1.195532858","rc":[{"atb":[[3.5,2.48]],"id":39290878}],"con":true,"img":false}]}
{"op":"mcm","clk":"5322284759","pt":1646318458539,"mc":[{"id":"1.195532858","rc":[{"atb":[[5.7,0]],"id":41288595},{"atb":[[4.6,0]],"id":38983972}],"con":true,"img":false}]}
{"op":"mcm","clk":"5322284815","pt":1646318459114,"mc":[{"id":"1.195532858","rc":[{"atb":[[3.45,1.65]],"id":39290878}],"con":true,"img":false}]}
{"op":"mcm","clk":"5322284824","pt":1646318459223,"mc":[{"id":"1.195532858","rc":[{"atb":[[3.45,0],[1.02,1.99]],"id":39290878}],"con":true,"img":false}]}
{"op":"mcm","clk":"5322284830","pt":1646318459329,"mc":[{"id":"1.195532858","rc":[{"atb":[[4.7,0]],"id":38983972},{"atl":[[9.6,6.53]],"id":38983972},{"atb":[[1.01,11000],[13,4.9]],"id":38324360},{"atl":[[30,14]],"id":38324360},{"atb":[[3.5,4.13]],"id":39290878},{"atl":[[4.9,17.22]],"id":39290878},{"atl":[[4,3.86]],"id":38357910},{"atl":[[7.4,2.56]],"id":40124755}],"con":true,"img":false}]}
{"op":"mcm","clk":"5322284845","pt":1646318459430,"mc":[{"id":"1.195532858","rc":[{"atb":[[4.3,2.96]],"id":38983972},{"atb":[[13,6.26]],"id":38324360}],"con":true,"img":false}]}
{"op":"mcm","clk":"5322284969","pt":1646318459967,"mc":[{"id":"1.195532858","rc":[{"atl":[[36,0.3]],"id":38324360}],"con":true,"img":false}]}
{"op":"mcm","clk":"5322285026","pt":1646318460338,"mc":[{"id":"1.195532858","rc":[{"atl":[[7.8,3.18]],"id":40124755}],"con":true,"img":false}]}
{"op":"mcm","clk":"5322285044","pt":1646318460439,"mc":[{"id":"1.195532858","rc":[{"atl":[[7.2,0.8]],"id":40124755}],"con":true,"img":false}]}
{"op":"mcm","clk":"5322285066","pt":1646318460642,"mc":[{"id":"1.195532858","rc":[{"atl":[[20,0]],"id":38324360},{"trd":[[20,1.95]],"ltp":20.0,"tv":1.95,"id":38324360}],"con":true,"img":false}]}
{"op":"mcm","clk":"5322285092","pt":1646318460808,"mc":[{"id":"1.195532858","rc":[{"atl":[[7.4,0.56],[7.2,2.8]],"id":40124755}],"con":true,"img":false}]}
{"op":"mcm","clk":"5322285103","pt":1646318460913,"mc":[{"id":"1.195532858","rc":[{"atl":[[4.9,89.74]],"id":38357910}],"con":true,"img":false}]}
{"op":"mcm","clk":"5322285267","pt":1646318462600,"mc":[{"id":"1.195532858","rc":[{"atb":[[4.6,5.89]],"id":38983972}],"con":true,"img":false}]}
{"op":"mcm","clk":"5322285289","pt":1646318462822,"mc":[{"id":"1.195532858","rc":[{"atb":[[5,2.11]],"id":41288595},{"atl":[[12.5,4.93],[13,5.6]],"id":41288595},{"atl":[[9.6,4.53],[9.8,12.51]],"id":38983972},{"atb":[[9,12.5],[6,0]],"id":38324360},{"atl":[[36,3.16],[46,5.56]],"id":38324360},{"atb":[[3.3,19.05],[3.2,18]],"id":39290878},{"atl":[[4.3,0],[4.4,17.32]],"id":38357910},{"atl":[[8,14.98],[7.8,1.18]],"id":40124755}],"con":true,"img":false}]}
{"op":"mcm","clk":"5322285295","pt":1646318462912,"mc":[{"id":"1.195532858","rc":[{"atb":[[4.3,1.55]],"id":38983972}],"con":true,"img":false}]}
{"op":"mcm","clk":"5322285305","pt":1646318463017,"mc":[{"id":"1.195532858","rc":[{"atb":[[4.7,1.4]],"id":38983972}],"con":true,"img":false}]}
{"op":"mcm","clk":"5322285315","pt":1646318463125,"mc":[{"id":"1.195532858","rc":[{"atb":[[5,0]],"id":41288595},{"atl":[[4.4,11.76]],"id":38357910},{"atl":[[8,11.42]],"id":40124755}],"con":true,"img":false}]}
{"op":"mcm","clk":"5322285349","pt":1646318463450,"mc":[{"id":"1.195532858","rc":[{"atl":[[10,4.44]],"id":38983972}],"con":true,"img":false}]}
{"op":"mcm","clk":"5322285355","pt":1646318463538,"mc":[{"id":"1.195532858","rc":[{"atl":[[9.4,0.46]],"id":38983972}],"con":true,"img":false}]}
{"op":"mcm","clk":"5322285587","pt":1646318466228,"mc":[{"id":"1.195532858","rc":[{"atb":[[4.6,0]],"id":38983972}],"con":true,"img":false}]}
{"op":"mcm","clk":"5322285611","pt":1646318466537,"mc":[{"id":"1.195532858","rc":[{"atb":[[4.7,0]],"id":38983972}],"con":true,"img":false}]}
{"op":"mcm","clk":"5322285619","pt":1646318466639,"mc":[{"id":"1.195532858","rc":[{"atb":[[4.3,2.96]],"id":38983972}],"con":true,"img":false}]}
{"op":"mcm","clk":"5322285880","pt":1646318469831,"mc":[{"id":"1.195532858","rc":[{"atb":[[4.6,5.89]],"id":38983972}],"con":true,"img":false}]}
{"op":"mcm","clk":"5322285897","pt":1646318470046,"mc":[{"id":"1.195532858","rc":[{"atb":[[3.8,4.43]],"id":41288595},{"atl":[[10,0],[9.8,17.06]],"id":38983972}],"con":true,"img":false}]}
{"op":"mcm","clk":"5322285914","pt":1646318470245,"mc":[{"id":"1.195532858","rc":[{"atb":[[4.3,1.55]],"id":38983972}],"con":true,"img":false}]}
{"op":"mcm","clk":"5322285926","pt":1646318470354,"mc":[{"id":"1.195532858","rc":[{"atb":[[4.7,1.4]],"id":38983972},{"atl":[[10.5,4.22]],"id":38983972}],"con":true,"img":false}]}
{"op":"mcm","clk":"5322285945","pt":1646318470566,"mc":[{"id":"1.195532858","rc":[{"atl":[[10.5,0]],"id":38983972}],"con":true,"img":false}]}
{"op":"mcm","clk":"5322286240","pt":1646318472830,"mc":[{"id":"1.195532858","rc":[{"atl":[[4.6,27.78]],"id":38357910}],"con":true,"img":false}]}
{"op":"mcm","clk":"5322286306","pt":1646318473550,"mc":[{"id":"1.195532858","rc":[{"atb":[[4.6,0]],"id":38983972}],"con":true,"img":false}]}
{"op":"mcm","clk":"5322286339","pt":1646318473855,"mc":[{"id":"1.195532858","rc":[{"spn":5.7,"spf":1.0,"id":41288595},{"atb":[[4.7,0]],"id":38983972},{"spn":4.77,"spf":1.0,"id":38983972}],"con":true,"img":false}]}
{"op":"mcm","clk":"5322286351","pt":1646318473918,"mc":[{"id":"1.195532858","rc":[{"atb":[[4.3,2.96]],"id":38983972}],"con":true,"img":false}]}
{"op":"mcm","clk":"5322286676","pt":1646318477052,"mc":[{"id":"1.195532858","rc":[{"atb":[[4.6,5.89]],"id":38983972}],"con":true,"img":false}]}
{"op":"mcm","clk":"5322286723","pt":1646318477535,"mc":[{"id":"1.195532858","rc":[{"atb":[[4.3,1.55]],"id":38983972}],"con":true,"img":false}]}
{"op":"mcm","clk":"5322286734","pt":1646318477633,"mc":[{"id":"1.195532858","rc":[{"atb":[[4.7,1.4]],"id":38983972}],"con":true,"img":false}]}
{"op":"mcm","clk":"5322286847","pt":1646318478632,"mc":[{"id":"1.195532858","rc":[{"atl":[[9.6,4.1],[1000,16.15]],"id":38983972}],"con":true,"img":false}]}
{"op":"mcm","clk":"5322286867","pt":1646318478841,"mc":[{"id":"1.195532858","rc":[{"atl":[[1000,14.94]],"id":38983972}],"con":true,"img":false}]}
{"op":"mcm","clk":"5322286886","pt":1646318479041,"mc":[{"id":"1.195532858","rc":[{"atl":[[1000,14.5]],"id":38983972}],"con":true,"img":false}]}
{"op":"mcm","clk":"5322286896","pt":1646318479145,"mc":[{"id":"1.195532858","rc":[{"atl":[[9.2,0.44]],"id":38983972}],"con":true,"img":false}]}
{"op":"mcm","clk":"5322286992","pt":1646318480028,"mc":[{"id":"1.195532858","rc":[{"atl":[[9.6,8.75],[9.8,12.51]],"id":38983972}],"con":true,"img":false}]}
{"op":"mcm","clk":"5322287041","pt":1646318480551,"mc":[{"id":"1.195532858","rc":[{"atb":[[4.6,0]],"id":38983972}],"con":true,"img":false}]}
{"op":"mcm","clk":"5322287108","pt":1646318481137,"mc":[{"id":"1.195532858","rc":[{"atb":[[4.7,0]],"id":38983972}],"con":true,"img":false}]}
{"op":"mcm","clk":"5322287118","pt":1646318481244,"mc":[{"id":"1.195532858","rc":[{"atb":[[4.3,2.96]],"id":38983972}],"con":true,"img":false}]}
{"op":"mcm","clk":"5322287260","pt":1646318482543,"mc":[{"id":"1.195532858","rc":[{"atb":[[4.8,3.27]],"id":38324360}],"con":true,"img":false}]}
{"op":"mcm","clk":"5322287286","pt":1646318482761,"mc":[{"id":"1.195532858","rc":[{"atl":[[4.9,25.64],[4.5,0],[4.7,0]],"id":38357910}],"con":true,"img":false}]}
{"op":"mcm","clk":"5322287298","pt":1646318482857,"mc":[{"id":"1.195532858","rc":[{"atl":[[4.8,39.47]],"id":38357910}],"con":true,"img":false}]}
{"op":"mcm","clk":"5322287427","pt":1646318484059,"mc":[{"id":"1.195532858","rc":[{"atb":[[4.6,5.89]],"id":38983972}],"con":true,"img":false}]}
{"op":"mcm","clk":"5322287497","pt":1646318484748,"mc":[{"id":"1.195532858","rc":[{"atb":[[4.3,1.55]],"id":38983972}],"con":true,"img":false}]}
{"op":"mcm","clk":"5322287510","pt":1646318484864,"mc":[{"id":"1.195532858","rc":[{"atb":[[4.7,1.4]],"id":38983972}],"con":true,"img":false}]}
{"op":"mcm","clk":"5322287766","pt":1646318487353,"mc":[{"id":"1.195532858","rc":[{"atb":[[4.6,0]],"id":38983972}],"con":true,"img":false}]}
{"op":"mcm","clk":"5322287817","pt":1646318487770,"mc":[{"id":"1.195532858","rc":[{"atb":[[4.7,0]],"id":38983972}],"con":true,"img":false}]}
{"op":"mcm","clk":"5322287828","pt":1646318487874,"mc":[{"id":"1.195532858","rc":[{"atb":[[4.3,2.96]],"id":38983972}],"con":true,"img":false}]}
{"op":"mcm","clk":"5322287890","pt":1646318488447,"mc":[{"id":"1.195532858","rc":[{"atb":[[3.05,6.37]],"id":39290878}],"con":true,"img":false}]}
{"op":"mcm","clk":"5322287923","pt":1646318488760,"mc":[{"id":"1.195532858","rc":[{"atb":[[3.05,0]],"id":39290878}],"con":true,"img":false}]}
{"op":"mcm","clk":"5322288069","pt":1646318490088,"mc":[{"id":"1.195532858","rc":[{"atl":[[10,11.11]],"id":38983972}],"con":true,"img":false}]}
{"op":"mcm","clk":"5322288153","pt":1646318490874,"mc":[{"id":"1.195532858","rc":[{"atb":[[4.6,5.89]],"id":38983972}],"con":true,"img":false}]}
{"op":"mcm","clk":"5322288196","pt":1646318491380,"mc":[{"id":"1.195532858","rc":[{"atb":[[4.3,1.55]],"id":38983972}],"con":true,"img":false}]}
{"op":"mcm","clk":"5322288206","pt":1646318491442,"mc":[{"id":"1.195532858","rc":[{"atb":[[4.7,1.4]],"id":38983972}],"con":true,"img":false}]}
{"op":"mcm","clk":"5322288345","pt":1646318492849,"mc":[{"id":"1.195532858","rc":[{"atl":[[5,62.5]],"id":38357910}],"con":true,"img":false}]}
{"op":"mcm","clk":"5322288508","pt":1646318494469,"mc":[{"id":"1.195532858","rc":[{"atb":[[4.6,0]],"id":38983972}],"con":true,"img":false}]}
{"op":"mcm","clk":"5322288585","pt":1646318495294,"mc":[{"id":"1.195532858","rc":[{"atb":[[4.7,0]],"id":38983972}],"con":true,"img":false}]}
{"op":"mcm","clk":"5322288595","pt":1646318495363,"mc":[{"id":"1.195532858","rc":[{"atb":[[4.3,2.96]],"id":38983972}],"con":true,"img":false}]}
{"op":"mcm","clk":"5322288882","pt":1646318498175,"mc":[{"id":"1.195532858","rc":[{"atb":[[4.6,5.89]],"id":38983972}],"con":true,"img":false}]}
{"op":"mcm","clk":"5322288948","pt":1646318498802,"mc":[{"id":"1.195532858","rc":[{"atb":[[4.3,1.55]],"id":38983972}],"con":true,"img":false}]}
{"op":"mcm","clk":"5322288959","pt":1646318498859,"mc":[{"id":"1.195532858","rc":[{"atb":[[4.7,1.4]],"id":38983972}],"con":true,"img":false}]}
{"op":"mcm","clk":"5322289057","pt":1646318500097,"mc":[{"id":"1.195532858","rc":[{"atl":[[11,15],[11.5,0],[12.5,0.2],[13.5,0]],"id":38983972}],"con":true,"img":false}]}
{"op":"mcm","clk":"5322289085","pt":1646318500370,"mc":[{"id":"1.195532858","rc":[{"atl":[[8,1.5]],"id":41288595}],"con":true,"img":false}]}
{"op":"mcm","clk":"5322289341","pt":1646318502975,"mc":[{"id":"1.195532858","rc":[{"atb":[[4.6,0]],"id":38983972}],"con":true,"img":false}]}
{"op":"mcm","clk":"5322289442","pt":1646318504005,"mc":[{"id":"1.195532858","rc":[{"atb":[[4.7,0]],"id":38983972}],"con":true,"img":false}]}
{"op":"mcm","clk":"5322289450","pt":1646318504082,"mc":[{"id":"1.195532858","rc":[{"atb":[[4.3,2.96]],"id":38983972}],"con":true,"img":false}]}
{"op":"mcm","clk":"5322289700","pt":1646318506694,"mc":[{"id":"1.195532858","rc":[{"atb":[[4.6,5.89]],"id":38983972}],"con":true,"img":false}]}
{"op":"mcm","clk":"5322289760","pt":1646318507310,"mc":[{"id":"1.195532858","rc":[{"atb":[[4.3,1.55]],"id":38983972}],"con":true,"img":false}]}
{"op":"mcm","clk":"5322289768","pt":1646318507416,"mc":[{"id":"1.195532858","rc":[{"atb":[[4.7,1.4]],"id":38983972}],"con":true,"img":false}]}
{"op":"mcm","clk":"5322290032","pt":1646318509981,"mc":[{"id":"1.195532858","rc":[{"atb":[[4.6,0]],"id":38983972}],"con":true,"img":false}]}
{"op":"mcm","clk":"5322290041","pt":1646318510125,"mc":[{"id":"1.195532858","rc":[{"atl":[[12,22.73]],"id":38983972}],"con":true,"img":false}]}
{"op":"mcm","clk":"5322290070","pt":1646318510293,"mc":[{"id":"1.195532858","rc":[{"atb":[[4.7,0]],"id":38983972}],"con":true,"img":false}]}
{"op":"mcm","clk":"5322290086","pt":1646318510401,"mc":[{"id":"1.195532858","rc":[{"atb":[[4.3,2.96]],"id":38983972}],"con":true,"img":false}]}
{"op":"mcm","clk":"5322290247","pt":1646318511908,"mc":[{"id":"1.195532858","rc":[{"atl":[[8,1]],"id":41288595}],"con":true,"img":false}]}
{"op":"mcm","clk":"5322290254","pt":1646318512013,"mc":[{"id":"1.195532858","rc":[{"atb":[[6,0.19]],"id":41288595},{"trd":[[6,0.99]],"ltp":6.0,"tv":0.99,"id":41288595}],"con":true,"img":false}]}
{"op":"mcm","clk":"5322290351","pt":1646318513107,"mc":[{"id":"1.195532858","rc":[{"atb":[[5.8,1.67]],"id":41288595}],"con":true,"img":false}]}
{"op":"mcm","clk":"5322290361","pt":1646318513211,"mc":[{"id":"1.195532858","rc":[{"atb":[[5.7,1.47]],"id":41288595}],"con":true,"img":false}]}
{"op":"mcm","clk":"5322290374","pt":1646318513315,"mc":[{"id":"1.195532858","rc":[{"atl":[[8,3]],"id":41288595}],"con":true,"img":false}]}
{"op":"mcm","clk":"5322290557","pt":1646318515203,"mc":[{"id":"1.195532858","rc":[{"atb":[[4.6,5.89]],"id":38983972}],"con":true,"img":false}]}
{"op":"mcm","clk":"5322290623","pt":1646318515777,"mc":[{"id":"1.195532858","rc":[{"atb":[[5.6,2.11]],"id":41288595}],"con":true,"img":false}]}
{"op":"mcm","clk":"5322290634","pt":1646318515883,"mc":[{"id":"1.195532858","rc":[{"atb":[[1.01,11003.34]],"id":41288595}],"con":true,"img":false}]}
{"op":"mcm","clk":"5322290702","pt":1646318516610,"mc":[{"id":"1.195532858","rc":[{"atl":[[1000,17.02]],"id":41288595}],"con":true,"img":false}]}
{"op":"mcm","clk":"5322290716","pt":1646318516816,"mc":[{"id":"1.195532858","rc":[{"atl":[[1000,16.6]],"id":41288595}],"con":true,"img":false}]}
{"op":"mcm","clk":"5322290739","pt":1646318517019,"mc":[{"id":"1.195532858","rc":[{"atb":[[5.7,0]],"id":41288595},{"atl":[[1000,14.5]],"id":41288595}],"con":true,"img":false}]}
{"op":"mcm","clk":"5322290750","pt":1646318517076,"mc":[{"id":"1.195532858","rc":[{"atb":[[5.6,3.58]],"id":41288595},{"atl":[[7.8,2.1]],"id":41288595}],"con":true,"img":false}]}
{"op":"mcm","clk":"5322290759","pt":1646318517183,"mc":[{"id":"1.195532858","rc":[{"atb":[[6,0],[1.04,1.65]],"id":41288595},{"atl":[[9.6,19.86],[9.8,1.15]],"id":38983972}],"con":true,"img":false}]}
{"op":"mcm","clk":"5322290776","pt":1646318517389,"mc":[{"id":"1.195532858","rc":[{"atb":[[1.04,0.19]],"id":41288595},{"atl":[[10,16.3]],"id":38983972}],"con":true,"img":false}]}
{"op":"mcm","clk":"5322290789","pt":1646318517497,"mc":[{"id":"1.195532858","rc":[{"atb":[[1.04,0]],"id":41288595}],"con":true,"img":false}]}
{"op":"mcm","clk":"5322290801","pt":1646318517601,"mc":[{"id":"1.195532858","rc":[{"atb":[[5.7,0.19]],"id":41288595}],"con":true,"img":false}]}
{"op":"mcm","clk":"5322290812","pt":1646318517708,"mc":[{"id":"1.195532858","rc":[{"atl":[[10,11.11]],"id":38983972}],"con":true,"img":false}]}
{"op":"mcm","clk":"5322290846","pt":1646318518019,"mc":[{"id":"1.195532858","rc":[{"atl":[[8,1],[7.8,4.1]],"id":41288595}],"con":true,"img":false}]}
{"op":"mcm","clk":"5322290952","pt":1646318519329,"mc":[{"id":"1.195532858","rc":[{"atb":[[4.3,1.55]],"id":38983972}],"con":true,"img":false}]}
{"op":"mcm","clk":"5322290960","pt":1646318519427,"mc":[{"id":"1.195532858","rc":[{"atb":[[4.7,1.4]],"id":38983972}],"con":true,"img":false}]}
{"op":"mcm","clk":"5322291026","pt":1646318520104,"mc":[{"id":"1.195532858","rc":[{"atl":[[8,0]],"id":41288595}],"con":true,"img":false}]}
{"op":"mcm","clk":"5322291035","pt":1646318520214,"mc":[{"id":"1.195532858","rc":[{"atb":[[4.6,0]],"id":38983972}],"con":true,"img":false}]}
{"op":"mcm","clk":"5322291045","pt":1646318520313,"mc":[{"id":"1.195532858","rc":[{"atl":[[1000,16.5]],"id":41288595},{"atl":[[1000,16.5]],"id":38983972},{"atl":[[1000,16.5]],"id":38324360},{"atl":[[1000,16.5]],"id":39290878},{"atl":[[1000,16.5]],"id":38357910},{"atl":[[1000,16.5]],"id":40124755}],"con":true,"img":false}]}
{"op":"mcm","clk":"5322291062","pt":1646318520528,"mc":[{"id":"1.195532858","rc":[{"atl":[[1000,15.5]],"id":41288595},{"atl":[[1000,15.5]],"id":38983972},{"atl":[[1000,15.5]],"id":38324360},{"atl":[[1000,15.5]],"id":39290878},{"atl":[[1000,15.5]],"id":38357910},{"atl":[[1000,15.5]],"id":40124755}],"con":true,"img":false}]}
{"op":"mcm","clk":"5322291076","pt":1646318520633,"mc":[{"id":"1.195532858","rc":[{"atb":[[3.25,0]],"id":40124755}],"con":true,"img":false}]}
{"op":"mcm","clk":"5322291084","pt":1646318520685,"mc":[{"id":"1.195532858","rc":[{"atl":[[1000,14.5]],"id":41288595},{"atl":[[1000,14.5]],"id":38983972},{"atl":[[1000,14.5]],"id":38324360},{"atl":[[1000,14.5]],"id":39290878},{"atl":[[1000,14.5]],"id":38357910},{"atl":[[1000,14.5]],"id":40124755}],"con":true,"img":false}]}
{"op":"mcm","clk":"5322291096","pt":1646318520786,"mc":[{"id":"1.195532858","rc":[{"atl":[[7.6,1]],"id":41288595},{"atl":[[9.4,1.46]],"id":38983972},{"atl":[[29,1]],"id":38324360},{"atl":[[4.8,1]],"id":39290878},{"atl":[[3.95,1]],"id":38357910},{"atl":[[7,1.35]],"id":40124755}],"con":true,"img":false}]}
{"op":"mcm","clk":"5322291101","pt":1646318520887,"mc":[{"id":"1.195532858","rc":[{"atl":[[3.95,1.58]],"id":38357910}],"con":true,"img":false}]}
{"op":"mcm","clk":"5322291115","pt":1646318520995,"mc":[{"id":"1.195532858","rc":[{"atl":[[36,7.27]],"id":38324360},{"atl":[[4.9,14.69]],"id":39290878},{"atl":[[4.5,5.88]],"id":38357910}],"con":true,"img":false}]}
{"op":"mcm","clk":"5322291127","pt":1646318521103,"mc":[{"id":"1.195532858","rc":[{"atl":[[9.6,17.76]],"id":38983972},{"atl":[[4,2.84]],"id":38357910}],"con":true,"img":false}]}
{"op":"mcm","clk":"5322291156","pt":1646318521407,"mc":[{"id":"1.195532858","rc":[{"atb":[[1.01,11004.34]],"id":41288595},{"atl":[[36,3.15]],"id":38324360},{"atl":[[4.5,0]],"id":38357910}],"con":true,"img":false}]}
{"op":"mcm","clk":"5322291163","pt":1646318521509,"mc":[{"id":"1.195532858","rc":[{"atl":[[1000,17.02]],"id":38983972}],"con":true,"img":false}]}
{"op":"mcm","clk":"5322291171","pt":1646318521617,"mc":[{"id":"1.195532858","rc":[{"atl":[[7.8,2.1],[7.6,3]],"id":41288595},{"atl":[[9.4,3.46],[9.6,15.76]],"id":38983972},{"atl":[[29,3],[30,12]],"id":38324360},{"atb":[[3.5,6.13]],"id":39290878},{"atl":[[4.8,3],[4.9,12.69]],"id":39290878},{"atl":[[4,0.84]],"id":38357910},{"atl":[[7.2,0.8]],"id":40124755}],"con":true,"img":false}]}
{"op":"mcm","clk":"5322291185","pt":1646318521720,"mc":[{"id":"1.195532858","rc":[{"atb":[[4.4,12.12],[4.2,0]],"id":38983972},{"atl":[[1000,16.6]],"id":38983972},{"atl":[[32,1.49],[34,8]],"id":38324360},{"atb":[[3.3,0]],"id":39290878},{"atb":[[3.45,2.71]],"id":38357910},{"atl":[[8,5.71],[7.8,7.06]],"id":40124755}],"con":true,"img":false}]}
{"op":"mcm","clk":"5322291198","pt":1646318521780,"mc":[{"id":"1.195532858","rc":[{"atb":[[3.25,34.87]],"id":39290878},{"atl":[[3.95,0.58]],"id":38357910},{"atl":[[7,0.35]],"id":40124755}],"con":true,"img":false}]}
{"op":"mcm","clk":"5322291209","pt":1646318521884,"mc":[{"id":"1.195532858","rc":[{"atb":[[5.9,1.18]],"id":41288595},{"atb":[[6,1]],"id":38983972},{"atb":[[3.1,30.68],[3.55,1]],"id":39290878},{"atb":[[3.45,3.71]],"id":38357910},{"atl":[[4,1],[3.95,0],[4.1,3.16]],"id":38357910},{"atb":[[5.3,1]],"id":40124755},{"atl":[[7.8,8.06]],"id":40124755}],"con":true,"img":false}]}
{"op":"mcm","clk":"5322291219","pt":1646318521988,"mc":[{"id":"1.195532858","rc":[{"atb":[[4.7,0]],"id":38983972},{"atl":[[1000,14.5]],"id":38983972},{"atb":[[3.25,24]],"id":39290878},{"atb":[[3.45,4.36]],"id":38357910},{"atl":[[4,1.57]],"id":38357910},{"atb":[[5.3,1.38]],"id":40124755},{"atl":[[7.4,0],[1000,16.15]],"id":40124755}],"con":true,"img":false}]}
{"op":"mcm","clk":"5322291225","pt":1646318522091,"mc":[{"id":"1.195532858","rc":[{"atb":[[4.3,2.96],[1.01,11003.65]],"id":38983972},{"atl":[[9.2,2.54]],"id":38983972},{"atb":[[3.1,19.05],[3.5,4.13]],"id":39290878},{"atb":[[3.4,1.62]],"id":38357910},{"atl":[[4,3.57]],"id":38357910}],"con":true,"img":false}]}
{"op":"mcm","clk":"5322291232","pt":1646318522190,"mc":[{"id":"1.195532858","rc":[{"atb":[[5.9,2.48]],"id":38983972}],"con":true,"img":false}]}
{"op":"mcm","clk":"5322291243","pt":1646318522302,"mc":[{"id":"1.195532858","rc":[{"atb":[[1.01,11002.67]],"id":38983972},{"atl":[[9.4,2.46],[9.6,4.65],[9.8,12.26]],"id":38983972},{"atb":[[2.98,9.91]],"id":38357910}],"con":true,"img":false}]}
{"op":"mcm","clk":"5322291253","pt":1646318522401,"mc":[{"id":"1.195532858","rc":[{"atb":[[4.3,1.55]],"id":38983972},{"atl":[[9,1]],"id":38983972},{"atl":[[4.9,9.74]],"id":39290878},{"atl":[[1000,15.06]],"id":40124755}],"con":true,"img":false}]}
{"op":"mcm","clk":"5322291261","pt":1646318522511,"mc":[{"id":"1.195532858","rc":[{"atb":[[1.01,11002],[4.5,3.4]],"id":38983972},{"atl":[[9.4,2]],"id":38983972},{"atl":[[4.9,9.3]],"id":39290878},{"atl":[[7.2,0.34]],"id":40124755}],"con":true,"img":false}]}
{"op":"mcm","clk":"5322291273","pt":1646318522619,"mc":[{"id":"1.195532858","rc":[{"atl":[[7.6,4.21]],"id":41288595},{"atb":[[6.2,0.67]],"id":38983972},{"atl":[[9.2,3.01],[9.4,0]],"id":38983972},{"atl":[[4.7,0.44]],"id":39290878},{"atb":[[2.98,0],[3.45,7.63]],"id":38357910},{"atl":[[7.6,0.46]],"id":40124755}],"con":true,"img":false}]}
{"op":"mcm","clk":"5322291282","pt":1646318522724,"mc":[{"id":"1.195532858","rc":[{"atb":[[5.9,0]],"id":38983972},{"atl":[[9,3]],"id":38983972},{"atb":[[3.5,1.65]],"id":39290878},{"atl":[[7.8,10.06],[1000,14.5]],"id":40124755}],"con":true,"img":false}]}
{"op":"mcm","clk":"5322291293","pt":1646318522824,"mc":[{"id":"1.195532858","rc":[{"atl":[[7.6,1.02]],"id":40124755}],"con":true,"img":false}]}
{"op":"mcm","clk":"5322291334","pt":1646318523195,"mc":[{"id":"1.195532858","rc":[{"atl":[[4.7,2.97]],"id":39290878},{"atb":[[5.3,3.24]],"id":40124755}],"con":true,"img":false}]}
{"op":"mcm","clk":"5322291346","pt":1646318523291,"mc":[{"id":"1.195532858","rc":[{"atl":[[1000,17.02]],"id":40124755}],"con":true,"img":false}]}
{"op":"mcm","clk":"5322291354","pt":1646318523398,"mc":[{"id":"1.195532858","rc":[{"atl":[[4.8,0]],"id":39290878},{"atl":[[3.95,2.71]],"id":38357910},{"atl":[[7.8,8.06]],"id":40124755}],"con":true,"img":false}]}
{"op":"mcm","clk":"5322291363","pt":1646318523504,"mc":[{"id":"1.195532858","rc":[{"atl":[[9.2,2.54]],"id":38983972},{"atl":[[4.6,1],[4.7,4.97]],"id":39290878},{"atl":[[1000,16.6]],"id":40124755}],"con":true,"img":false}]}
{"op":"mcm","clk":"5322291373","pt":1646318523610,"mc":[{"id":"1.195532858","rc":[{"atl":[[9,3.46]],"id":38983972},{"atl":[[4,3]],"id":38357910}],"con":true,"img":false}]}
{"op":"mcm","clk":"5322291385","pt":1646318523709,"mc":[{"id":"1.195532858","rc":[{"atb":[[4.3,0]],"id":38983972},{"atb":[[3.5,0]],"id":39290878},{"atl":[[4,2]],"id":38357910},{"atb":[[1.01,11002]],"id":40124755},{"atl":[[1000,14.5]],"id":40124755}],"con":true,"img":false}]}
{"op":"mcm","clk":"5322291391","pt":1646318523814,"mc":[{"id":"1.195532858","rc":[{"atl":[[7.8,0]],"id":41288595},{"atb":[[4.6,1.55]],"id":38983972},{"atb":[[3.45,1.65]],"id":39290878},{"atl":[[3.9,1]],"id":38357910},{"atb":[[5.4,1.58]],"id":40124755},{"atl":[[7.4,2.1]],"id":40124755}],"con":true,"img":false}]}
{"op":"mcm","clk":"5322291403","pt":1646318523920,"mc":[{"id":"1.195532858","rc":[{"atb":[[6,0]],"id":38983972},{"atb":[[3.55,0]],"id":39290878},{"atb":[[5.4,4.06]],"id":40124755}],"con":true,"img":false}]}
{"op":"mcm","clk":"5322291412","pt":1646318524028,"mc":[{"id":"1.195532858","rc":[{"atb":[[5.8,1]],"id":38983972},{"atb":[[3.45,2.65]],"id":39290878},{"atl":[[4.6,3],[4.7,2.97]],"id":39290878},{"atl":[[4,2.59]],"id":38357910},{"atb":[[3.5,4.48],[5.4,4.42]],"id":40124755}],"con":true,"img":false}]}
{"op":"mcm","clk":"5322291424","pt":1646318524129,"mc":[{"id":"1.195532858","rc":[{"atl":[[1000,17.02]],"id":41288595},{"atl":[[9.2,2.1],[1000,16.15]],"id":38983972},{"atl":[[7.8,7.06]],"id":40124755}],"con":true,"img":false}]}
{"op":"mcm","clk":"5322291433","pt":1646318524184,"mc":[{"id":"1.195532858","rc":[{"atb":[[4.6,8.3]],"id":38983972},{"atl":[[1000,14.97]],"id":38983972},{"atl":[[5,24.15]],"id":39290878},{"atl":[[7.2,1.34]],"id":40124755}],"con":true,"img":false}]}
{"op":"mcm","clk":"5322291442","pt":1646318524285,"mc":[{"id":"1.195532858","rc":[{"atl":[[1000,16.6]],"id":41288595}],"con":true,"img":false}]}
{"op":"mcm","clk":"5322291454","pt":1646318524390,"mc":[{"id":"1.195532858","rc":[{"atl":[[1000,14.5]],"id":38983972},{"atb":[[13,4.9]],"id":38324360}],"con":true,"img":false}]}
{"op":"mcm","clk":"5322291461","pt":1646318524489,"mc":[{"id":"1.195532858","rc":[{"atl":[[1000,14.5]],"id":41288595},{"atl":[[8.8,0.47]],"id":38983972},{"atb":[[1.01,11001.36]],"id":38324360},{"atb":[[1.02,0]],"id":39290878}],"con":true,"img":false}]}
{"op":"mcm","clk":"5322291474","pt":1646318524599,"mc":[{"id":"1.195532858","rc":[{"atl":[[7.4,2.1]],"id":41288595},{"atb":[[3.5,1.99],[3.45,4.65]],"id":39290878},{"atl":[[5,20],[4.7,2.52]],"id":39290878}],"con":true,"img":false}]}
{"op":"mcm","clk":"5322291481","pt":1646318524697,"mc":[{"id":"1.195532858","rc":[{"atb":[[3.45,3]],"id":39290878},{"atl":[[4.5,0.44]],"id":39290878},{"atb":[[5.4,2.84]],"id":40124755}],"con":true,"img":false}]}
{"op":"mcm","clk":"5322291491","pt":1646318524800,"mc":[{"id":"1.195532858","rc":[{"atl":[[7.6,3.21]],"id":41288595},{"atb":[[1.01,11003.65]],"id":39290878},{"atb":[[1.01,11003.58]],"id":40124755},{"atl":[[7.4,3.35]],"id":40124755}],"con":true,"img":false}]}
{"op":"mcm","clk":"5322291500","pt":1646318524910,"mc":[{"id":"1.195532858","rc":[{"atl":[[7.2,1]],"id":41288595},{"atb":[[3.45,2]],"id":39290878},{"atb":[[5.3,2.24],[5.5,1.78]],"id":40124755}],"con":true,"img":false}]}
{"op":"mcm","clk":"5322291513","pt":1646318525008,"mc":[{"id":"1.195532858","rc":[{"atl":[[7.6,1.21]],"id":41288595},{"atb":[[3.55,1],[3.45,0]],"id":39290878},{"atb":[[5.5,3.13]],"id":40124755}],"con":true,"img":false}]}
{"op":"mcm","clk":"5322291526","pt":1646318525119,"mc":[{"id":"1.195532858","rc":[{"atb":[[4.5,2]],"id":38983972},{"atb":[[1.01,11000]],"id":38324360}],"con":true,"img":false}]}
{"op":"mcm","clk":"5322291538","pt":1646318525225,"mc":[{"id":"1.195532858","rc":[{"atb":[[4.7,1.4]],"id":38983972},{"atb":[[13.5,1.67]],"id":38324360}],"con":true,"img":false}]}
{"op":"mcm","clk":"5322291588","pt":1646318525595,"mc":[{"id":"1.195532858","rc":[{"atb":[[5.6,2.11]],"id":41288595},{"atl":[[7.6,0.56]],"id":40124755}],"con":true,"img":false}]}
{"op":"mcm","clk":"5322291600","pt":1646318525693,"mc":[{"id":"1.195532858","rc":[{"atb":[[1.01,11005.82]],"id":41288595},{"atl":[[7.2,1.8]],"id":40124755}],"con":true,"img":false}]}
{"op":"mcm","clk":"5322291612","pt":1646318525799,"mc":[{"id":"1.195532858","rc":[{"atb":[[13,2.9],[13.5,3.67]],"id":38324360},{"atb":[[3.5,0]],"id":39290878},{"atl":[[4,0.59]],"id":38357910}],"con":true,"img":false}]}
{"op":"mcm","clk":"5322291625","pt":1646318525906,"mc":[{"id":"1.195532858","rc":[{"atb":[[5.8,3],[5.7,0]],"id":38983972},{"atb":[[3.45,1.99]],"id":39290878},{"atb":[[5.2,0.45]],"id":40124755}],"con":true,"img":false}]}
{"op":"mcm","clk":"5322291661","pt":1646318526224,"mc":[{"id":"1.195532858","rc":[{"atb":[[13.5,2.3]],"id":38324360}],"con":true,"img":false}]}
{"op":"mcm","clk":"5322291673","pt":1646318526328,"mc":[{"id":"1.195532858","rc":[{"atb":[[1.01,11001.36]],"id":38324360}],"con":true,"img":false}]}
{"op":"mcm","clk":"5322291684","pt":1646318526430,"mc":[{"id":"1.195532858","rc":[{"atb":[[5.4,0.36]],"id":40124755}],"con":true,"img":false}]}
{"op":"mcm","clk":"5322291749","pt":1646318527014,"mc":[{"id":"1.195532858","rc":[{"atb":[[5.8,2]],"id":38983972},{"atb":[[3.55,0]],"id":39290878},{"atb":[[5.5,2.13]],"id":40124755}],"con":true,"img":false}]}
{"op":"mcm","clk":"5322291775","pt":1646318527217,"mc":[{"id":"1.195532858","rc":[{"atb":[[5.9,1]],"id":38983972},{"atb":[[3.5,1]],"id":39290878},{"atb":[[5.6,1]],"id":40124755}],"con":true,"img":false}]}
{"op":"mcm","clk":"5322291798","pt":1646318527424,"mc":[{"id":"1.195532858","rc":[{"atl":[[9.2,6.98],[9.6,0]],"id":38983972},{"atl":[[8,0],[8.2,14.62]],"id":40124755}],"con":true,"img":false}]}
{"op":"mcm","clk":"5322291819","pt":1646318527629,"mc":[{"id":"1.195532858","rc":[{"atl":[[5.1,3.74]],"id":39290878}],"con":true,"img":false}]}
{"op":"mcm","clk":"5322291839","pt":1646318527836,"mc":[{"id":"1.195532858","rc":[{"atb":[[3.5,3]],"id":39290878},{"atl":[[5.1,0]],"id":39290878}],"con":true,"img":false}]}
{"op":"mcm","clk":"5322291864","pt":1646318527999,"mc":[{"id":"1.195532858","rc":[{"atb":[[4.2,3.75]],"id":38983972}],"con":true,"img":false}]}
{"op":"mcm","clk":"5322291886","pt":1646318528208,"mc":[{"id":"1.195532858","rc":[{"atb":[[4.2,0]],"id":38983972}],"con":true,"img":false}]}
{"op":"mcm","clk":"5322291982","pt":1646318529131,"mc":[{"id":"1.195532858","rc":[{"atb":[[6,2.48]],"id":38983972}],"con":true,"img":false}]}
{"op":"mcm","clk":"5322292015","pt":1646318529394,"mc":[{"id":"1.195532858","rc":[{"atl":[[9.2,4.88]],"id":38983972},{"atb":[[3.45,0]],"id":39290878}],"con":true,"img":false}]}
{"op":"mcm","clk":"5322292024","pt":1646318529498,"mc":[{"id":"1.195532858","rc":[{"atb":[[1.02,1.99]],"id":39290878}],"con":true,"img":false}]}
{"op":"mcm","clk":"5322292055","pt":1646318529810,"mc":[{"id":"1.195532858","rc":[{"atl":[[1000,17.02]],"id":38983972}],"con":true,"img":false}]}
{"op":"mcm","clk":"5322292066","pt":1646318529914,"mc":[{"id":"1.195532858","rc":[{"atb":[[5.9,0]],"id":38983972},{"atb":[[3.5,2]],"id":39290878}],"con":true,"img":false}]}
{"op":"mcm","clk":"5322292075","pt":1646318530013,"mc":[{"id":"1.195532858","rc":[{"atb":[[6.2,1.67]],"id":38983972},{"atl":[[1000,16.6]],"id":38983972},{"atb":[[3.55,1]],"id":39290878}],"con":true,"img":false}]}
{"op":"mcm","clk":"5322292088","pt":1646318530116,"mc":[{"id":"1.195532858","rc":[{"atb":[[1.03,2]],"id":41288595},{"atl":[[1000,14.75]],"id":41288595}],"con":true,"img":false}]}
{"op":"mcm","clk":"5322292097","pt":1646318530226,"mc":[{"id":"1.195532858","rc":[{"atb":[[1.03,2.3]],"id":41288595},{"atl":[[1000,14.5]],"id":41288595},{"atl":[[1000,14.5]],"id":38983972}],"con":true,"img":false}]}
{"op":"mcm","clk":"5322292111","pt":1646318530330,"mc":[{"id":"1.195532858","rc":[{"atb":[[1.25,20]],"id":41288595},{"atl":[[7.4,2.35]],"id":41288595},{"atb":[[1.25,20]],"id":38983972},{"atl":[[8.8,2.57]],"id":38983972},{"atb":[[1.25,20]],"id":38324360},{"atb":[[1.25,20]],"id":39290878},{"atb":[[1.25,20]],"id":38357910},{"atb":[[1.25,20]],"id":40124755}],"con":true,"img":false}]}
{"op":"mcm","clk":"5322292116","pt":1646318530429,"mc":[{"id":"1.195532858","rc":[{"atb":[[1.03,0.3]],"id":41288595},{"atl":[[4.7,0]],"id":39290878},{"atl":[[7.4,1.25]],"id":40124755}],"con":true,"img":false}]}
{"op":"mcm","clk":"5322292126","pt":1646318530535,"mc":[{"id":"1.195532858","rc":[{"atb":[[1.03,0]],"id":41288595},{"atl":[[9,2]],"id":38983972}],"con":true,"img":false}]}
{"op":"mcm","clk":"5322292138","pt":1646318530595,"mc":[{"id":"1.195532858","rc":[{"atb":[[5.9,1.48]],"id":41288595},{"atl":[[7.2,3]],"id":41288595},{"atl":[[9,0],[8.6,1],[8.8,5.03]],"id":38983972},{"atb":[[3.5,0]],"id":39290878}],"con":true,"img":false}]}
{"op":"mcm","clk":"5322292151","pt":1646318530695,"mc":[{"id":"1.195532858","rc":[{"atl":[[1000,17.02]],"id":40124755}],"con":true,"img":false}]}
{"op":"mcm","clk":"5322292160","pt":1646318530800,"mc":[{"id":"1.195532858","rc":[{"atl":[[1000,16.6],[7.2,0.8]],"id":40124755}],"con":true,"img":false}]}
{"op":"mcm","clk":"5322292171","pt":1646318530909,"mc":[{"id":"1.195532858","rc":[{"atb":[[3.55,0]],"id":39290878},{"atl":[[7.6,1.56]],"id":40124755}],"con":true,"img":false}]}
{"op":"mcm","clk":"5322292182","pt":1646318531010,"mc":[{"id":"1.195532858","rc":[{"atb":[[3.45,1]],"id":39290878},{"atl":[[1000,14.5]],"id":40124755}],"con":true,"img":false}]}
{"op":"mcm","clk":"5322292193","pt":1646318531119,"mc":[{"id":"1.195532858","rc":[{"atb":[[3.25,0],[3.2,54]],"id":39290878},{"atl":[[7,2.45]],"id":40124755}],"con":true,"img":false}]}
{"op":"mcm","clk":"5322292202","pt":1646318531218,"mc":[{"id":"1.195532858","rc":[{"atl":[[7.4,0.25]],"id":41288595},{"atl":[[8.6,3],[8.8,3.03]],"id":38983972},{"atb":[[3.45,3]],"id":39290878}],"con":true,"img":false}]}
{"op":"mcm","clk":"5322292211","pt":1646318531328,"mc":[{"id":"1.195532858","rc":[{"atb":[[4.6,1.55]],"id":38983972},{"atb":[[3.25,19.05],[1.02,0]],"id":39290878}],"con":true,"img":false}]}
{"op":"mcm","clk":"5322292224","pt":1646318531434,"mc":[{"id":"1.195532858","rc":[{"atb":[[3.45,4.99],[3.2,18]],"id":39290878},{"atl":[[7.6,0.56]],"id":40124755}],"con":true,"img":false}]}
{"op":"mcm","clk":"5322292234","pt":1646318531532,"mc":[{"id":"1.195532858","rc":[{"atl":[[8.8,2.57]],"id":38983972},{"atl":[[6.8,1],[7.2,0.34]],"id":40124755}],"con":true,"img":false}]}
{"op":"mcm","clk":"5322292246","pt":1646318531636,"mc":[{"id":"1.195532858","rc":[{"atb":[[6,0]],"id":38983972},{"atl":[[8.6,3.46]],"id":38983972},{"atl":[[7,2.91]],"id":40124755}],"con":true,"img":false}]}
{"op":"mcm","clk":"5322292257","pt":1646318531689,"mc":[{"id":"1.195532858","rc":[{"atl":[[6.8,1.27],[7.6,3.06]],"id":40124755}],"con":true,"img":false}]}
{"op":"mcm","clk":"5322292270","pt":1646318531796,"mc":[{"id":"1.195532858","rc":[{"atb":[[4.7,0]],"id":38983972},{"atl":[[8.4,16.01]],"id":40124755}],"con":true,"img":false}]}
{"op":"mcm","clk":"5322292281","pt":1646318531903,"mc":[{"id":"1.195532858","rc":[{"atb":[[4.5,3.4],[6.2,0.67]],"id":38983972}],"con":true,"img":false}]}
{"op":"mcm","clk":"5322292292","pt":1646318532005,"mc":[{"id":"1.195532858","rc":[{"atb":[[5.9,1]],"id":38983972}],"con":true,"img":false}]}
{"op":"mcm","clk":"5322292300","pt":1646318532108,"mc":[{"id":"1.195532858","rc":[{"atl":[[7.6,0.56]],"id":40124755}],"con":true,"img":false}]}
{"op":"mcm","clk":"5322292320","pt":1646318532321,"mc":[{"id":"1.195532858","rc":[{"atl":[[8.4,13.51]],"id":40124755}],"con":true,"img":false}]}
{"op":"mcm","clk":"5322292341","pt":1646318532525,"mc":[{"id":"1.195532858","rc":[{"atl":[[9,5],[9.2,0],[9.6,11.63],[9.8,1.15]],"id":38983972}],"con":true,"img":false}]}
{"op":"mcm","clk":"5322292484","pt":1646318534039,"mc":[{"id":"1.195532858","rc":[{"spn":5.66,"spf":1.0,"id":41288595},{"atb":[[6,2.48]],"id":38983972},{"spn":5.07,"spf":1.0,"id":38983972},{"spn":4.78,"spf":8.2,"id":39290878},{"spn":3.67,"spf":1.0,"id":38357910},{"spn":5.05,"spf":1.0,"id":40124755}],"con":true,"img":false}]}
{"op":"mcm","clk":"5322292577","pt":1646318534935,"mc":[{"id":"1.195532858","rc":[{"atb":[[5.9,0]],"id":38983972}],"con":true,"img":false}]}
{"op":"mcm","clk":"5322292589","pt":1646318535040,"mc":[{"id":"1.195532858","rc":[{"atb":[[6.2,1.67]],"id":38983972}],"con":true,"img":false}]}
{"op":"mcm","clk":"5322292748","pt":1646318536405,"mc":[{"id":"1.195532858","rc":[{"atb":[[6,0]],"id":38983972}],"con":true,"img":false}]}
{"op":"mcm","clk":"5322292789","pt":1646318536923,"mc":[{"id":"1.195532858","rc":[{"atb":[[6.2,0.67]],"id":38983972}],"con":true,"img":false}]}
{"op":"mcm","clk":"5322292800","pt":1646318537029,"mc":[{"id":"1.195532858","rc":[{"atb":[[5.9,1]],"id":38983972}],"con":true,"img":false}]}
{"op":"mcm","clk":"5322292860","pt":1646318537500,"mc":[{"id":"1.195532858","rc":[{"atl":[[8.8,0.47]],"id":38983972}],"con":true,"img":false}]}
{"op":"mcm","clk":"5322292893","pt":1646318537814,"mc":[{"id":"1.195532858","rc":[{"atl":[[1000,17.02]],"id":38983972},{"atl":[[7,0.81]],"id":40124755}],"con":true,"img":false}]}
{"op":"mcm","clk":"5322292900","pt":1646318537917,"mc":[{"id":"1.195532858","rc":[{"atl":[[1000,16.6]],"id":38983972}],"con":true,"img":false}]}
{"op":"mcm","clk":"5322292910","pt":1646318538026,"mc":[{"id":"1.195532858","rc":[{"atl":[[1000,14.5]],"id":38983972},{"atl":[[6.8,0.27]],"id":40124755}],"con":true,"img":false}]}
{"op":"mcm","clk":"5322292923","pt":1646318538131,"mc":[{"id":"1.195532858","rc":[{"atl":[[8.4,2.1]],"id":38983972},{"atl":[[7.6,1.56]],"id":40124755}],"con":true,"img":false}]}
{"op":"mcm","clk":"5322292981","pt":1646318538605,"mc":[{"id":"1.195532858","rc":[{"atl":[[7,0.35]],"id":40124755}],"con":true,"img":false}]}
{"op":"mcm","clk":"5322292991","pt":1646318538706,"mc":[{"id":"1.195532858","rc":[{"atb":[[1.01,11003.65],[6.2,0]],"id":38983972},{"atl":[[7.6,2.02]],"id":40124755}],"con":true,"img":false}]}
{"op":"mcm","clk":"5322293000","pt":1646318538812,"mc":[{"id":"1.195532858","rc":[{"atb":[[6,2.48]],"id":38983972},{"atl":[[8.4,4.1],[8.6,0.46]],"id":38983972}],"con":true,"img":false}]}
{"op":"mcm","clk":"5322293010","pt":1646318538913,"mc":[{"id":"1.195532858","rc":[{"atb":[[1.01,11002.67]],"id":38983972},{"atl":[[8.2,1]],"id":38983972}],"con":true,"img":false}]}
{"op":"mcm","clk":"5322293020","pt":1646318539018,"mc":[{"id":"1.195532858","rc":[{"atb":[[1.01,11002]],"id":38983972}],"con":true,"img":false}]}
{"op":"mcm","clk":"5322293031","pt":1646318539135,"mc":[{"id":"1.195532858","rc":[{"atb":[[6,3.15]],"id":38983972}],"con":true,"img":false}]}
{"op":"mcm","clk":"5322293054","pt":1646318539337,"mc":[{"id":"1.195532858","rc":[{"atl":[[8.2,3],[8.4,2.1]],"id":38983972}],"con":true,"img":false}]}
{"op":"mcm","clk":"5322293088","pt":1646318539601,"mc":[{"id":"1.195532858","rc":[{"atl":[[8.6,0]],"id":38983972},{"atl":[[1000,17.02]],"id":40124755}],"con":true,"img":false}]}
{"op":"mcm","clk":"5322293101","pt":1646318539704,"mc":[{"id":"1.195532858","rc":[{"atl":[[8.2,3.46]],"id":38983972}],"con":true,"img":false}]}
{"op":"mcm","clk":"5322293111","pt":1646318539810,"mc":[{"id":"1.195532858","rc":[{"atl":[[1000,16.6]],"id":40124755}],"con":true,"img":false}]}
{"op":"mcm","clk":"5322293121","pt":1646318539913,"mc":[{"id":"1.195532858","rc":[{"atb":[[5.9,0]],"id":38983972},{"atl":[[1000,14.5]],"id":40124755}],"con":true,"img":false}]}
{"op":"mcm","clk":"5322293132","pt":1646318540017,"mc":[{"id":"1.195532858","rc":[{"atb":[[5.9,0.94]],"id":41288595},{"trd":[[5.9,5.06]],"ltp":5.9,"tv":5.06,"id":41288595},{"atb":[[6.2,1]],"id":38983972},{"atl":[[7.2,2.44]],"id":40124755}],"con":true,"img":false}]}
{"op":"mcm","clk":"5322293151","pt":1646318540228,"mc":[{"id":"1.195532858","rc":[{"atl":[[7.6,1.02]],"id":40124755}],"con":true,"img":false}]}
{"op":"mcm","clk":"5322293163","pt":1646318540341,"mc":[{"id":"1.195532858","rc":[{"atb":[[5.9,0.88]],"id":41288595},{"atl":[[7.4,0.14]],"id":41288595},{"atl":[[7,1.35]],"id":40124755}],"con":true,"img":false}]}
{"op":"mcm","clk":"5322293193","pt":1646318540645,"mc":[{"id":"1.195532858","rc":[{"atl":[[8.2,3]],"id":38983972},{"atl":[[7.6,0.56]],"id":40124755}],"con":true,"img":false}]}
{"op":"mcm","clk":"5322293205","pt":1646318540748,"mc":[{"id":"1.195532858","rc":[{"atl":[[1000,14.96]],"id":38983972},{"atl":[[7.2,2.9]],"id":40124755}],"con":true,"img":false}]}
{"op":"mcm","clk":"5322293276","pt":1646318541402,"mc":[{"id":"1.195532858","rc":[{"atb":[[6,0.67]],"id":38983972}],"con":true,"img":false}]}
{"op":"mcm","clk":"5322293320","pt":1646318541923,"mc":[{"id":"1.195532858","rc":[{"atb":[[6.2,0]],"id":38983972}],"con":true,"img":false}]}
{"op":"mcm","clk":"5322293333","pt":1646318542025,"mc":[{"id":"1.195532858","rc":[{"atb":[[5.9,1]],"id":38983972}],"con":true,"img":false}]}
{"op":"mcm","clk":"5322293341","pt":1646318542128,"mc":[{"id":"1.195532858","rc":[{"atb":[[5.8,3.67]],"id":41288595}],"con":true,"img":false}]}
{"op":"mcm","clk":"5322293462","pt":1646318543332,"mc":[{"id":"1.195532858","rc":[{"atb":[[4.2,31.25]],"id":38983972},{"atl":[[9,0],[8.8,5.6]],"id":38983972}],"con":true,"img":false}]}
{"op":"mcm","clk":"5322293482","pt":1646318543541,"mc":[{"id":"1.195532858","rc":[{"atb":[[3.8,0]],"id":38983972},{"atl":[[4.4,0],[4.5,11.43]],"id":38357910}],"con":true,"img":false}]}
{"op":"mcm","clk":"5322293702","pt":1646318546025,"mc":[{"id":"1.195532858","rc":[{"atl":[[8.4,0]],"id":38983972}],"con":true,"img":false}]}
{"op":"mcm","clk":"5322293750","pt":1646318546546,"mc":[{"id":"1.195532858","rc":[{"atb":[[4.6,7.25]],"id":39290878},{"atl":[[4.5,0],[4.6,0],[3.9,0]],"id":39290878},{"trd":[[4.6,6],[4.5,0.89],[3.9,5.43]],"ltp":4.6,"tv":12.32,"id":39290878}],"con":true,"img":false}]}
{"op":"mcm","clk":"5322293760","pt":1646318546650,"mc":[{"id":"1.195532858","rc":[{"atb":[[4.6,0]],"id":39290878},{"trd":[[4.6,20.51]],"ltp":4.6,"tv":20.51,"id":39290878}],"con":true,"img":false}]}
{"op":"mcm","clk":"5322293770","pt":1646318546755,"mc":[{"id":"1.195532858","rc":[{"atb":[[5.8,1.67]],"id":41288595},{"atb":[[3.45,2.99]],"id":39290878},{"atl":[[4.9,0],[5,40]],"id":39290878},{"atl":[[3.9,3]],"id":38357910},{"atl":[[7.2,0.8]],"id":40124755}],"con":true,"img":false}]}
{"op":"mcm","clk":"5322293778","pt":1646318546806,"mc":[{"id":"1.195532858","rc":[{"atb":[[3.45,4.06],[1.02,2]],"id":39290878},{"atl":[[4.9,0.78]],"id":39290878}],"con":true,"img":false}]}
{"op":"mcm","clk":"5322293787","pt":1646318546964,"mc":[{"id":"1.195532858","rc":[{"atb":[[1.01,11002]],"id":39290878},{"atl":[[3.9,3.48]],"id":38357910}],"con":true,"img":false}]}
{"op":"mcm","clk":"5322293800","pt":1646318547017,"mc":[{"id":"1.195532858","rc":[{"atb":[[3.5,1.65],[1.02,1.31]],"id":39290878}],"con":true,"img":false}]}
{"op":"mcm","clk":"5322293809","pt":1646318547120,"mc":[{"id":"1.195532858","rc":[{"atb":[[3.5,2.71]],"id":39290878}],"con":true,"img":false}]}
{"op":"mcm","clk":"5322293821","pt":1646318547224,"mc":[{"id":"1.195532858","rc":[{"atb":[[3.5,4.83],[1.02,0],[3.15,0]],"id":39290878},{"atl":[[5,42]],"id":39290878}],"con":true,"img":false}]}
{"op":"mcm","clk":"5322293833","pt":1646318547344,"mc":[{"id":"1.195532858","rc":[{"atb":[[3.5,6.14],[3.45,5.39]],"id":39290878}],"con":true,"img":false}]}
{"op":"mcm","clk":"5322293853","pt":1646318547544,"mc":[{"id":"1.195532858","rc":[{"atb":[[3.5,6.97]],"id":39290878}],"con":true,"img":false}]}
{"op":"mcm","clk":"5322293860","pt":1646318547648,"mc":[{"id":"1.195532858","rc":[{"atl":[[7.2,0.34]],"id":40124755}],"con":true,"img":false}]}
{"op":"mcm","clk":"5322293870","pt":1646318547752,"mc":[{"id":"1.195532858","rc":[{"atl":[[7.6,1.02],[7,0.35]],"id":40124755}],"con":true,"img":false}]}
{"op":"mcm","clk":"5322293880","pt":1646318547858,"mc":[{"id":"1.195532858","rc":[{"atb":[[3.45,2.07]],"id":39290878},{"atl":[[7.6,2.02]],"id":40124755}],"con":true,"img":false}]}
{"op":"mcm","clk":"5322293893","pt":1646318547912,"mc":[{"id":"1.195532858","rc":[{"atb":[[1.01,11003.33],[3.45,1.07],[1.02,1.99]],"id":39290878}],"con":true,"img":false}]}
{"op":"mcm","clk":"5322293900","pt":1646318548017,"mc":[{"id":"1.195532858","rc":[{"atb":[[3.55,4.14]],"id":39290878}],"con":true,"img":false}]}
{"op":"mcm","clk":"5322293911","pt":1646318548122,"mc":[{"id":"1.195532858","rc":[{"atb":[[3.55,5.19]],"id":39290878}],"con":true,"img":false}]}
{"op":"mcm","clk":"5322293920","pt":1646318548223,"mc":[{"id":"1.195532858","rc":[{"atl":[[1000,17.48]],"id":38983972},{"atb":[[3.5,5.66]],"id":39290878}],"con":true,"img":false}]}
{"op":"mcm","clk":"5322293929","pt":1646318548329,"mc":[{"id":"1.195532858","rc":[{"atb":[[3.5,3.54],[1.02,3.99]],"id":39290878}],"con":true,"img":false}]}
{"op":"mcm","clk":"5322293939","pt":1646318548431,"mc":[{"id":"1.195532858","rc":[{"atb":[[3.55,7.29]],"id":39290878}],"con":true,"img":false}]}
{"op":"mcm","clk":"5322293947","pt":1646318548538,"mc":[{"id":"1.195532858","rc":[{"atl":[[1000,17.06]],"id":38983972},{"atb":[[3.5,3.31],[1.02,3.27]],"id":39290878}],"con":true,"img":false}]}
{"op":"mcm","clk":"5322293960","pt":1646318548643,"mc":[{"id":"1.195532858","rc":[{"atl":[[1000,14.96]],"id":38983972},{"atb":[[3.6,2.48]],"id":39290878}],"con":true,"img":false}]}
{"op":"mcm","clk":"5322293967","pt":1646318548751,"mc":[{"id":"1.195532858","rc":[{"atb":[[5.1,36.59]],"id":41288595},{"atl":[[8,2.1],[9,11.11],[9.6,0]],"id":38983972},{"atl":[[34,11.03],[36,0.29]],"id":38324360},{"atb":[[3.25,0],[3.05,48.78],[1.02,1.99]],"id":39290878},{"atl":[[5,22]],"id":39290878},{"atl":[[4.3,12.12],[4.5,0],[5.1,6.25]],"id":38357910},{"atl":[[8.2,1.11],[7.8,20.57]],"id":40124755}],"con":true,"img":false}]}
{"op":"mcm","clk":"5322293978","pt":1646318548853,"mc":[{"id":"1.195532858","rc":[{"atb":[[3.6,4.8],[3.5,1.65]],"id":39290878}],"con":true,"img":false}]}
{"op":"mcm","clk":"5322293989","pt":1646318548960,"mc":[{"id":"1.195532858","rc":[{"atb":[[4.7,10.86]],"id":41288595},{"atl":[[8,4.1],[8.2,1]],"id":38983972},{"atb":[[3.6,8.52],[3.55,4.19]],"id":39290878},{"atl":[[5.8,28.83]],"id":39290878},{"atl":[[5.1,0]],"id":38357910}],"con":true,"img":false}]}
{"op":"mcm","clk":"5322293997","pt":1646318549010,"mc":[{"id":"1.195532858","rc":[{"atl":[[8.2,0]],"id":38983972},{"atb":[[3.65,1]],"id":39290878}],"con":true,"img":false}]}
{"op":"mcm","clk":"5322294009","pt":1646318549117,"mc":[{"id":"1.195532858","rc":[{"atl":[[7.8,1]],"id":38983972},{"atb":[[3.65,2.02]],"id":39290878},{"atl":[[4.9,3.73]],"id":39290878}],"con":true,"img":false}]}
{"op":"mcm","clk":"5322294029","pt":1646318549323,"mc":[{"id":"1.195532858","rc":[{"atl":[[9.2,3.43]],"id":38983972}],"con":true,"img":false}]}
{"op":"mcm","clk":"5322294038","pt":1646318549428,"mc":[{"id":"1.195532858","rc":[{"atl":[[8,2.1]],"id":38983972},{"atb":[[3.6,6.45]],"id":39290878},{"atl":[[5,20]],"id":39290878}],"con":true,"img":false}]}
{"op":"mcm","clk":"5322294048","pt":1646318549531,"mc":[{"id":"1.195532858","rc":[{"atl":[[7.8,3]],"id":38983972},{"atb":[[3.6,5.17],[3.65,4.05]],"id":39290878},{"atl":[[4.9,5.73]],"id":39290878}],"con":true,"img":false}]}
{"op":"mcm","clk":"5322294067","pt":1646318549739,"mc":[{"id":"1.195532858","rc":[{"atb":[[1.01,11005.33]],"id":39290878}],"con":true,"img":false}]}
{"op":"mcm","clk":"5322294084","pt":1646318549949,"mc":[{"id":"1.195532858","rc":[{"atl":[[9.2,0]],"id":38983972},{"atb":[[1.01,11004.57]],"id":39290878}],"con":true,"img":false}]}
{"op":"mcm","clk":"5322294095","pt":1646318550053,"mc":[{"id":"1.195532858","rc":[{"atb":[[3.7,2.96]],"id":39290878},{"atl":[[4.9,7.78]],"id":39290878}],"con":true,"img":false}]}
{"op":"mcm","clk":"5322294104","pt":1646318550158,"mc":[{"id":"1.195532858","rc":[{"atl":[[7.8,1]],"id":38983972},{"atb":[[1.01,11003.33],[3.7,3.97]],"id":39290878},{"atl":[[3.9,1.48]],"id":38357910}],"con":true,"img":false}]}
{"op":"mcm","clk":"5322294114","pt":1646318550215,"mc":[{"id":"1.195532858","rc":[{"atb":[[5.9,0.86]],"id":41288595},{"atl":[[1000,14.66]],"id":41288595},{"atb":[[3.7,5.21]],"id":39290878}],"con":true,"img":false}]}
{"op":"mcm","clk":"5322294121","pt":1646318550321,"mc":[{"id":"1.195532858","rc":[{"atl":[[1000,14.5]],"id":41288595}],"con":true,"img":false}]}
{"op":"mcm","clk":"5322294132","pt":1646318550426,"mc":[{"id":"1.195532858","rc":[{"atl":[[7.4,0.3]],"id":41288595}],"con":true,"img":false}]}
{"op":"mcm","clk":"5322294140","pt":1646318550527,"mc":[{"id":"1.195532858","rc":[{"atl":[[1000,17.02]],"id":40124755}],"con":true,"img":false}]}
{"op":"mcm","clk":"5322294163","pt":1646318550739,"mc":[{"id":"1.195532858","rc":[{"atl":[[1000,16.6]],"id":40124755}],"con":true,"img":false}]}
{"op":"mcm","clk":"5322294187","pt":1646318550950,"mc":[{"id":"1.195532858","rc":[{"atb":[[3.65,3.05]],"id":39290878},{"atl":[[1000,14.5]],"id":40124755}],"con":true,"img":false}]}
{"op":"mcm","clk":"5322294198","pt":1646318551053,"mc":[{"id":"1.195532858","rc":[{"atb":[[3.75,1]],"id":39290878},{"atl":[[7.2,2.44]],"id":40124755}],"con":true,"img":false}]}
{"op":"mcm","clk":"5322294207","pt":1646318551156,"mc":[{"id":"1.195532858","rc":[{"atb":[[3.7,7.21],[3.65,1.02]],"id":39290878}],"con":true,"img":false}]}
{"op":"mcm","clk":"5322294217","pt":1646318551262,"mc":[{"id":"1.195532858","rc":[{"atb":[[3.6,2.69],[3.75,1.99]],"id":39290878},{"atl":[[7.6,1.02]],"id":40124755}],"con":true,"img":false}]}
{"op":"mcm","clk":"5322294229","pt":1646318551316,"mc":[{"id":"1.195532858","rc":[{"atl":[[7,1.35]],"id":40124755}],"con":true,"img":false}]}
{"op":"mcm","clk":"5322294298","pt":1646318552148,"mc":[{"id":"1.195532858","rc":[{"atl":[[7.2,0.34]],"id":40124755}],"con":true,"img":false}]}
{"op":"mcm","clk":"5322294320","pt":1646318552356,"mc":[{"id":"1.195532858","rc":[{"atb":[[3.8,2.86],[3.75,3.99],[3.7,3.97]],"id":39290878}],"con":true,"img":false}]}
{"op":"mcm","clk":"5322294331","pt":1646318552458,"mc":[{"id":"1.195532858","rc":[{"atl":[[7,0.35]],"id":40124755}],"con":true,"img":false}]}
{"op":"mcm","clk":"5322294343","pt":1646318552564,"mc":[{"id":"1.195532858","rc":[{"atb":[[3.8,3.83]],"id":39290878},{"atl":[[7.6,2.02]],"id":40124755}],"con":true,"img":false}]}
{"op":"mcm","clk":"5322294351","pt":1646318552613,"mc":[{"id":"1.195532858","rc":[{"atb":[[1.01,11005.33],[3.5,1.06]],"id":39290878}],"con":true,"img":false}]}
{"op":"mcm","clk":"5322294360","pt":1646318552719,"mc":[{"id":"1.195532858","rc":[{"atb":[[3.65,1.61]],"id":39290878}],"con":true,"img":false}]}
{"op":"mcm","clk":"5322294370","pt":1646318552825,"mc":[{"id":"1.195532858","rc":[{"atb":[[1.01,11004.54]],"id":39290878}],"con":true,"img":false}]}
{"op":"mcm","clk":"5322294382","pt":1646318552928,"mc":[{"id":"1.195532858","rc":[{"atb":[[3.8,5.83],[3.75,1.99]],"id":39290878},{"atb":[[3.95,2]],"id":40124755}],"con":true,"img":false}]}
{"op":"mcm","clk":"5322294389","pt":1646318553032,"mc":[{"id":"1.195532858","rc":[{"atb":[[1.01,11003.33],[3.75,0.99]],"id":39290878}],"con":true,"img":false}]}
{"op":"mcm","clk":"5322294406","pt":1646318553138,"mc":[{"id":"1.195532858","rc":[{"atb":[[3.85,1],[3.8,7.04]],"id":39290878},{"atb":[[3.95,0]],"id":40124755}],"con":true,"img":false}]}
{"op":"mcm","clk":"5322294426","pt":1646318553347,"mc":[{"id":"1.195532858","rc":[{"atb":[[3.85,1.96]],"id":39290878}],"con":true,"img":false}]}
{"op":"mcm","clk":"5322294448","pt":1646318553554,"mc":[{"id":"1.195532858","rc":[{"atb":[[3.85,3.96],[3.8,3.83],[3.7,7.85]],"id":39290878}],"con":true,"img":false}]}
{"op":"mcm","clk":"5322294461","pt":1646318553659,"mc":[{"id":"1.195532858","rc":[{"atb":[[1.01,11005.33],[3.7,3.97],[3.65,1.56]],"id":39290878}],"con":true,"img":false}]}
{"op":"mcm","clk":"5322294477","pt":1646318553815,"mc":[{"id":"1.195532858","rc":[{"atb":[[1.01,11004.51]],"id":39290878}],"con":true,"img":false}]}
{"op":"mcm","clk":"5322294483","pt":1646318553922,"mc":[{"id":"1.195532858","rc":[{"atb":[[4,50]],"id":38983972},{"atl":[[9.2,12.2]],"id":38983972}],"con":true,"img":false}]}
{"op":"mcm","clk":"5322294493","pt":1646318554026,"mc":[{"id":"1.195532858","rc":[{"atb":[[1.01,11003.33]],"id":39290878},{"atl":[[5.3,14.06]],"id":39290878}],"con":true,"img":false}]}
{"op":"mcm","clk":"5322294501","pt":1646318554131,"mc":[{"id":"1.195532858","rc":[{"atb":[[3.9,1.18]],"id":39290878},{"atl":[[5.3,9.3]],"id":39290878}],"con":true,"img":false}]}
{"op":"mcm","clk":"5322294510","pt":1646318554235,"mc":[{"id":"1.195532858","rc":[{"atb":[[3.9,2.12]],"id":39290878}],"con":true,"img":false}]}
{"op":"mcm","clk":"5322294547","pt":1646318554653,"mc":[{"id":"1.195532858","rc":[{"atb":[[3.65,1.02]],"id":39290878}],"con":true,"img":false}]}
{"op":"mcm","clk":"5322294558","pt":1646318554757,"mc":[{"id":"1.195532858","rc":[{"atb":[[3.85,4.5]],"id":39290878}],"con":true,"img":false}]}
{"op":"mcm","clk":"5322294565","pt":1646318554863,"mc":[{"id":"1.195532858","rc":[{"atb":[[3.85,2.5],[3.9,4.12]],"id":39290878}],"con":true,"img":false}]}
{"op":"mcm","clk":"5322294576","pt":1646318554916,"mc":[{"id":"1.195532858","rc":[{"atb":[[3.85,1.5]],"id":39290878}],"con":true,"img":false}]}
{"op":"mcm","clk":"5322294586","pt":1646318555021,"mc":[{"id":"1.195532858","rc":[{"atb":[[3.95,1]],"id":39290878}],"con":true,"img":false}]}
{"op":"mcm","clk":"5322294605","pt":1646318555232,"mc":[{"id":"1.195532858","rc":[{"atb":[[3.45,0],[3.95,3.71]],"id":39290878}],"con":true,"img":false}]}
{"op":"mcm","clk":"5322294621","pt":1646318555441,"mc":[{"id":"1.195532858","rc":[{"atb":[[3.95,5.71],[3.9,2.12]],"id":39290878}],"con":true,"img":false}]}
{"op":"mcm","clk":"5322294629","pt":1646318555544,"mc":[{"id":"1.195532858","rc":[{"atb":[[3.9,0.94]],"id":39290878}],"con":true,"img":false}]}
{"op":"mcm","clk":"5322294643","pt":1646318555648,"mc":[{"id":"1.195532858","rc":[{"atb":[[1.01,11005.33]],"id":39290878}],"con":true,"img":false}]}
{"op":"mcm","clk":"5322294663","pt":1646318555858,"mc":[{"id":"1.195532858","rc":[{"atb":[[1.01,11004.48]],"id":39290878}],"con":true,"img":false}]}
{"op":"mcm","clk":"5322294680","pt":1646318556026,"mc":[{"id":"1.195532858","rc":[{"atb":[[1.01,11003.33],[3.95,4.71]],"id":39290878}],"con":true,"img":false}]}
{"op":"mcm","clk":"5322294690","pt":1646318556122,"mc":[{"id":"1.195532858","rc":[{"atb":[[4,2.15]],"id":39290878}],"con":true,"img":false}]}
{"op":"mcm","clk":"5322294704","pt":1646318556226,"mc":[{"id":"1.195532858","rc":[{"atl":[[8,0]],"id":38983972},{"atb":[[3.5,0],[4,3.05]],"id":39290878},{"atl":[[1000,17.02]],"id":40124755}],"con":true,"img":false}]}
{"op":"mcm","clk":"5322294717","pt":1646318556332,"mc":[{"id":"1.195532858","rc":[{"atl":[[1000,16.6]],"id":40124755}],"con":true,"img":false}]}
{"op":"mcm","clk":"5322294722","pt":1646318556435,"mc":[{"id":"1.195532858","rc":[{"atb":[[5.9,5.3]],"id":41288595},{"atl":[[7.8,0]],"id":38983972},{"atb":[[13.5,4.04]],"id":38324360},{"atl":[[29,3.77]],"id":38324360},{"atl":[[4.9,13.36]],"id":39290878},{"atb":[[5.5,6.96]],"id":40124755},{"atl":[[7.4,4.65]],"id":40124755}],"con":true,"img":false}]}
{"op":"mcm","clk":"5322294730","pt":1646318556541,"mc":[{"id":"1.195532858","rc":[{"atl":[[9.2,24.4],[8.6,1]],"id":38983972},{"atl":[[1000,14.5]],"id":40124755}],"con":true,"img":false}]}
{"op":"mcm","clk":"5322294741","pt":1646318556642,"mc":[{"id":"1.195532858","rc":[{"atl":[[9,0]],"id":38983972},{"atl":[[7.2,2.44]],"id":40124755}],"con":true,"img":false}]}
{"op":"mcm","clk":"5322294759","pt":1646318556852,"mc":[{"id":"1.195532858","rc":[{"atb":[[3.5,0]],"id":41288595},{"atl":[[8.6,3]],"id":38983972},{"atb":[[4,5.05],[3.95,2.71]],"id":39290878},{"atl":[[7.6,1.02]],"id":40124755}],"con":true,"img":false}]}
{"op":"mcm","clk":"5322294770","pt":1646318556956,"mc":[{"id":"1.195532858","rc":[{"atl":[[9,11.11],[9.2,12.2]],"id":38983972},{"atl":[[7,1.35]],"id":40124755}],"con":true,"img":false}]}
{"op":"mcm","clk":"5322294821","pt":1646318557323,"mc":[{"id":"1.195532858","rc":[{"atb":[[6,3.15]],"id":38983972}],"con":true,"img":false}]}
{"op":"mcm","clk":"5322294830","pt":1646318557427,"mc":[{"id":"1.195532858","rc":[{"atl":[[8.6,5.86]],"id":38983972}],"con":true,"img":false}]}
{"op":"mcm","clk":"5322294848","pt":1646318557636,"mc":[{"id":"1.195532858","rc":[{"atb":[[13,1.2]],"id":38324360}],"con":true,"img":false}]}
{"op":"mcm","clk":"5322294856","pt":1646318557742,"mc":[{"id":"1.195532858","rc":[{"atb":[[14,1.69]],"id":38324360}],"con":true,"img":false}]}
{"op":"mcm","clk":"5322294865","pt":1646318557846,"mc":[{"id":"1.195532858","rc":[{"atb":[[1.03,1.65]],"id":38324360}],"con":true,"img":false}]}
{"op":"mcm","clk":"5322294879","pt":1646318557950,"mc":[{"id":"1.195532858","rc":[{"atb":[[13.5,3.73]],"id":38324360}],"con":true,"img":false}]}
{"op":"mcm","clk":"5322294891","pt":1646318558055,"mc":[{"id":"1.195532858","rc":[{"atb":[[5.9,0]],"id":38983972},{"atb":[[1.03,0.28]],"id":38324360}],"con":true,"img":false}]}
{"op":"mcm","clk":"5322294900","pt":1646318558158,"mc":[{"id":"1.195532858","rc":[{"atb":[[6.2,1]],"id":38983972},{"atb":[[13.5,1.73],[14,3.69]],"id":38324360}],"con":true,"img":false}]}
{"op":"mcm","clk":"5322294911","pt":1646318558265,"mc":[{"id":"1.195532858","rc":[{"atb":[[1.03,0]],"id":38324360}],"con":true,"img":false}]}
{"op":"mcm","clk":"5322294924","pt":1646318558366,"mc":[{"id":"1.195532858","rc":[{"atl":[[1000,17.48]],"id":38983972},{"atb":[[13.5,1.67],[14.5,0.28]],"id":38324360},{"atl":[[7.2,0.34]],"id":40124755}],"con":true,"img":false}]}
{"op":"mcm","clk":"5322294931","pt":1646318558420,"mc":[{"id":"1.195532858","rc":[{"atb":[[5.9,4.44]],"id":38983972}],"con":true,"img":false}]}
{"op":"mcm","clk":"5322294944","pt":1646318558528,"mc":[{"id":"1.195532858","rc":[{"atl":[[9,16.11],[9.2,0],[10,0],[11,0],[12,0],[1000,17.06],[8.8,0.47]],"id":38983972},{"atb":[[13.5,0],[14,2]],"id":38324360},{"atl":[[34,8],[36,3.15]],"id":38324360},{"atl":[[4.3,0],[4.2,12.5]],"id":38357910},{"atl":[[7,0.35]],"id":40124755}],"con":true,"img":false}]}
{"op":"mcm","clk":"5322294954","pt":1646318558628,"mc":[{"id":"1.195532858","rc":[{"atb":[[13,2.9],[14,3.67]],"id":38324360},{"atl":[[7.2,1.34]],"id":40124755}],"con":true,"img":false}]}
{"op":"mcm","clk":"5322294964","pt":1646318558733,"mc":[{"id":"1.195532858","rc":[{"atb":[[6,0.67]],"id":38983972},{"atl":[[1000,14.96]],"id":38983972},{"atl":[[7.4,6.65]],"id":40124755}],"con":true,"img":false}]}
{"op":"mcm","clk":"5322294976","pt":1646318558837,"mc":[{"id":"1.195532858","rc":[{"atl":[[8.4,2.1]],"id":38983972}],"con":true,"img":false}]}
{"op":"mcm","clk":"5322294989","pt":1646318559043,"mc":[{"id":"1.195532858","rc":[{"atb":[[6.2,0]],"id":38983972},{"atl":[[8.6,4.86]],"id":38983972}],"con":true,"img":false}]}
{"op":"mcm","clk":"5322294998","pt":1646318559147,"mc":[{"id":"1.195532858","rc":[{"atb":[[6,1.67]],"id":38983972},{"atl":[[8.2,1],[8.6,2]],"id":38983972}],"con":true,"img":false}]}
{"op":"mcm","clk":"5322295010","pt":1646318559252,"mc":[{"id":"1.195532858","rc":[{"atl":[[8.6,0]],"id":38983972},{"atl":[[7.4,4.65]],"id":40124755}],"con":true,"img":false}]}
{"op":"mcm","clk":"5322295044","pt":1646318559562,"mc":[{"id":"1.195532858","rc":[{"atb":[[3.9,3.86]],"id":41288595}],"con":true,"img":false}]}
{"op":"mcm","clk":"5322295056","pt":1646318559665,"mc":[{"id":"1.195532858","rc":[{"atb":[[13,2.84]],"id":38324360}],"con":true,"img":false}]}
{"op":"mcm","clk":"5322295110","pt":1646318560137,"mc":[{"id":"1.195532858","rc":[{"atl":[[7.4,0]],"id":41288595}],"con":true,"img":false}]}
{"op":"mcm","clk":"5322295122","pt":1646318560240,"mc":[{"id":"1.195532858","rc":[{"atb":[[5.9,5.08]],"id":41288595},{"atl":[[8.2,4.02]],"id":38983972}],"con":true,"img":false}]}
{"op":"mcm","clk":"5322295161","pt":1646318560656,"mc":[{"id":"1.195532858","rc":[{"atb":[[13,2.05]],"id":38324360}],"con":true,"img":false}]}
{"op":"mcm","clk":"5322295176","pt":1646318560758,"mc":[{"id":"1.195532858","rc":[{"atb":[[14,4.45]],"id":38324360}],"con":true,"img":false}]}
{"op":"mcm","clk":"5322295210","pt":1646318561123,"mc":[{"id":"1.195532858","rc":[{"atb":[[5.8,0]],"id":38983972}],"con":true,"img":false}]}
{"op":"mcm","clk":"5322295257","pt":1646318561543,"mc":[{"id":"1.195532858","rc":[{"atb":[[5.7,4.36]],"id":38983972}],"con":true,"img":false}]}
{"op":"mcm","clk":"5322295288","pt":1646318561749,"mc":[{"id":"1.195532858","rc":[{"atb":[[5.7,0]],"id":38983972},{"atb":[[14,2.45]],"id":38324360},{"atl":[[29,1.77]],"id":38324360}],"con":true,"img":false}]}
{"op":"mcm","clk":"5322295314","pt":1646318562060,"mc":[{"id":"1.195532858","rc":[{"atl":[[9,5],[9.2,6.12]],"id":38983972}],"con":true,"img":false}]}
{"op":"mcm","clk":"5322295378","pt":1646318562636,"mc":[{"id":"1.195532858","rc":[{"atb":[[14,1.67]],"id":38324360}],"con":true,"img":false}]}
{"op":"mcm","clk":"5322295390","pt":1646318562740,"mc":[{"id":"1.195532858","rc":[{"atb":[[13,2.84]],"id":38324360}],"con":true,"img":false}]}
