{"op":"mcm","clk":"5352092071","pt":1646182318990,"mc":[{"id":"1.195503864","marketDefinition":{"bspMarket":false,"turnInPlayEnabled":false,"persistenceEnabled":false,"marketBaseRate":7.0,"eventId":"31272499","eventTypeId":"4339","numberOfWinners":1,"bettingType":"ODDS","marketType":"EXACTA","marketTime":"2022-03-02T09:54:00.000Z","suspendTime":"2022-03-02T09:54:00.000Z","bspReconciled":false,"complete":true,"inPlay":false,"crossMatching":false,"runnersVoidable":false,"numberOfActiveRunners":56,"betDelay":0,"status":"OPEN","runners":[{"status":"ACTIVE","sortPriority":1,"id":41419585,"name":"1 - 2"},{"status":"ACTIVE","sortPriority":2,"id":41419586,"name":"1 - 3"},{"status":"ACTIVE","sortPriority":3,"id":41419587,"name":"1 - 4"},{"status":"ACTIVE","sortPriority":4,"id":41419588,"name":"1 - 5"},{"status":"ACTIVE","sortPriority":5,"id":41419589,"name":"1 - 6"},{"status":"ACTIVE","sortPriority":6,"id":41419590,"name":"1 - 7"},{"status":"ACTIVE","sortPriority":7,"id":41419591,"name":"1 - 8"},{"status":"ACTIVE","sortPriority":8,"id":41419592,"name":"2 - 1"},{"status":"ACTIVE","sortPriority":9,"id":41419593,"name":"2 - 3"},{"status":"ACTIVE","sortPriority":10,"id":41419594,"name":"2 - 4"},{"status":"ACTIVE","sortPriority":11,"id":41419595,"name":"2 - 5"},{"status":"ACTIVE","sortPriority":12,"id":41419596,"name":"2 - 6"},{"status":"ACTIVE","sortPriority":13,"id":41419597,"name":"2 - 7"},{"status":"ACTIVE","sortPriority":14,"id":41419598,"name":"2 - 8"},{"status":"ACTIVE","sortPriority":15,"id":41419599,"name":"3 - 1"},{"status":"ACTIVE","sortPriority":16,"id":41419600,"name":"3 - 2"},{"status":"ACTIVE","sortPriority":17,"id":41419601,"name":"3 - 4"},{"status":"ACTIVE","sortPriority":18,"id":41419602,"name":"3 - 5"},{"status":"ACTIVE","sortPriority":19,"id":41419603,"name":"3 - 6"},{"status":"ACTIVE","sortPriority":20,"id":41419604,"name":"3 - 7"},{"status":"ACTIVE","sortPriority":21,"id":41419605,"name":"3 - 8"},{"status":"ACTIVE","sortPriority":22,"id":41419606,"name":"4 - 1"},{"status":"ACTIVE","sortPriority":23,"id":41419607,"name":"4 - 2"},{"status":"ACTIVE","sortPriority":24,"id":41419608,"name":"4 - 3"},{"status":"ACTIVE","sortPriority":25,"id":41419609,"name":"4 - 5"},{"status":"ACTIVE","sortPriority":26,"id":41419610,"name":"4 - 6"},{"status":"ACTIVE","sortPriority":27,"id":41419611,"name":"4 - 7"},{"status":"ACTIVE","sortPriority":28,"id":41419612,"name":"4 - 8"},{"status":"ACTIVE","sortPriority":29,"id":41419613,"name":"5 - 1"},{"status":"ACTIVE","sortPriority":30,"id":41419614,"name":"5 - 2"},{"status":"ACTIVE","sortPriority":31,"id":41419615,"name":"5 - 3"},{"status":"ACTIVE","sortPriority":32,"id":41419616,"name":"5 - 4"},{"status":"ACTIVE","sortPriority":33,"id":41419617,"name":"5 - 6"},{"status":"ACTIVE","sortPriority":34,"id":41419618,"name":"5 - 7"},{"status":"ACTIVE","sortPriority":35,"id":41419619,"name":"5 - 8"},{"status":"ACTIVE","sortPriority":36,"id":41419620,"name":"6 - 1"},{"status":"ACTIVE","sortPriority":37,"id":41419621,"name":"6 - 2"},{"status":"ACTIVE","sortPriority":38,"id":41419622,"name":"6 - 3"},{"status":"ACTIVE","sortPriority":39,"id":41419623,"name":"6 - 4"},{"status":"ACTIVE","sortPriority":40,"id":41419624,"name":"6 - 5"},{"status":"ACTIVE","sortPriority":41,"id":41419625,"name":"6 - 7"},{"status":"ACTIVE","sortPriority":42,"id":41419626,"name":"6 - 8"},{"status":"ACTIVE","sortPriority":43,"id":41419627,"name":"7 - 1"},{"status":"ACTIVE","sortPriority":44,"id":41419628,"name":"7 - 2"},{"status":"ACTIVE","sortPriority":45,"id":41419629,"name":"7 - 3"},{"status":"ACTIVE","sortPriority":46,"id":41419630,"name":"7 - 4"},{"status":"ACTIVE","sortPriority":47,"id":41419631,"name":"7 - 5"},{"status":"ACTIVE","sortPriority":48,"id":41419632,"name":"7 - 6"},{"status":"ACTIVE","sortPriority":49,"id":41419633,"name":"7 - 8"},{"status":"ACTIVE","sortPriority":50,"id":41419634,"name":"8 - 1"},{"status":"ACTIVE","sortPriority":51,"id":41419635,"name":"8 - 2"},{"status":"ACTIVE","sortPriority":52,"id":41419636,"name":"8 - 3"},{"status":"ACTIVE","sortPriority":53,"id":41419637,"name":"8 - 4"},{"status":"ACTIVE","sortPriority":54,"id":41419638,"name":"8 - 5"},{"status":"ACTIVE","sortPriority":55,"id":41419639,"name":"8 - 6"},{"status":"ACTIVE","sortPriority":56,"id":41419640,"name":"8 - 7"}],"regulators":["MR_INT"],"venue":"Rockhampton","countryCode":"AU","discountAllowed":true,"timezone":"Australia/Queensland","openDate":"2022-03-02T08:34:00.000Z","version":4382565131,"name":"Exacta","eventName":"Rockhampton (AUS) 2nd Mar"},"rc":[],"con":true,"img":false}]}
{"op":"mcm","clk":"5352095595","pt":1646182411189,"mc":[{"id":"1.195503864","rc":[{"atb":[[16.5,12.87],[11.5,25.34],[28,7.39]],"id":41419609},{"atb":[[18,15.65],[26,7.98],[55,3.69]],"id":41419638},{"atb":[[18.5,15.2],[27,7.67],[60,3.38]],"id":41419605},{"atb":[[65,3.11],[19,14.78],[28,7.39]],"id":41419634},{"atb":[[40,5.11],[20,10.5],[15,19]],"id":41419617},{"atb":[[280,0.71],[180,1.48],[430,0.46]],"id":41419613},{"atb":[[270,0.74],[170,1.57],[420,0.47]],"id":41419593},{"atb":[[17.5,12.09],[12.5,23.13],[30,6.88]],"id":41419622},{"atb":[[42,4.86],[21,9.97],[15.5,18.35]],"id":41419589},{"atb":[[42,4.86],[21,9.97],[15.5,18.35]],"id":41419618},{"atb":[[32,6.44],[18,11.73],[13,22.17]],"id":41419601},{"atb":[[4.9,68.23],[8.8,25.58],[5.9,40.73]],"id":41419630},{"atb":[[16.5,17.17],[46,4.43],[23,9.07]],"id":41419597},{"atb":[[16,13.3],[7.4,41.58],[9.4,23.75]],"id":41419626},{"atb":[[8,38.01],[17.5,12.09],[10,22.17]],"id":41419639},{"atb":[[17.5,12.09],[12.5,23.13],[30,6.88]],"id":41419606},{"atb":[[70,2.89],[19.5,14.38],[29,7.12]],"id":41419635},{"atb":[[330,0.6],[180,1.11],[90,2.98]],"id":41419602},{"atb":[[540,0.37],[290,0.92],[390,0.51]],"id":41419585},{"atb":[[310,0.64],[210,1.27],[460,0.43]],"id":41419614},{"atb":[[4.4,78.26],[7.8,29.34],[5.4,45.36]],"id":41419610},{"atb":[[8,28.51],[4.5,76.03],[5.5,44.35]],"id":41419623},{"atb":[[16,17.74],[44,4.64],[22,9.5]],"id":41419590},{"atb":[[65,3.11],[19,14.78],[28,7.39]],"id":41419619},{"atb":[[140,1.91],[390,0.51],[240,0.83]],"id":41419586},{"atb":[[36,5.7],[19,11.08],[14,20.47]],"id":41419631},{"atb":[[32,6.44],[80,2.52],[21,13.3]],"id":41419598},{"atb":[[40,5.11],[20,10.5],[15,19]],"id":41419627},{"atb":[[40,5.11],[20,10.5],[15,19]],"id":41419594},{"atb":[[18.5,11.4],[11,19.95],[8.4,35.95]],"id":41419640},{"atb":[[32,6.44],[18,11.73],[13,22.17]],"id":41419607},{"atb":[[17.5,16.12],[50,4.07],[25,8.31]],"id":41419636},{"atb":[[36,5.7],[19,11.08],[14,20.47]],"id":41419603},{"atb":[[330,0.6],[180,1.11],[90,2.98]],"id":41419615},{"atb":[[5.7,42.46],[8.4,26.97],[4.7,71.92]],"id":41419611},{"atb":[[32,6.44],[18,11.73],[13,22.17]],"id":41419624},{"atb":[[75,2.69],[20,14],[30,6.88]],"id":41419591},{"atb":[[36,5.7],[19,11.08],[14,20.47]],"id":41419620},{"atb":[[38,5.39],[19.5,10.79],[14.5,19.71]],"id":41419587},{"atb":[[9.6,23.2],[5.3,61.88],[6.6,35.63]],"id":41419632},{"atb":[[140,1.91],[390,0.51],[240,0.83]],"id":41419599},{"atb":[[42,4.86],[21,9.97],[15.5,18.35]],"id":41419628},{"atb":[[310,0.64],[210,1.27],[460,0.43]],"id":41419595},{"atb":[[16,13.3],[11,26.61],[27,7.67]],"id":41419608},{"atb":[[7.2,42.92],[9.2,24.34],[15.5,13.76]],"id":41419637},{"atb":[[40,5.11],[20,10.5],[15,19]],"id":41419604},{"atb":[[34,6.04],[18.5,11.4],[13.5,21.28]],"id":41419616},{"atb":[[6.4,49.28],[13.5,15.96],[8.4,26.97]],"id":41419612},{"atb":[[6.4,36.96],[5.2,63.36],[9.4,23.75]],"id":41419625},{"atb":[[540,0.37],[290,0.92],[390,0.51]],"id":41419592},{"atb":[[38,5.39],[19.5,10.79],[14.5,19.71]],"id":41419621},{"atb":[[280,0.71],[180,1.48],[430,0.46]],"id":41419588},{"atb":[[8,38.01],[17.5,12.09],[10,22.17]],"id":41419633},{"atb":[[270,0.74],[170,1.57],[420,0.47]],"id":41419600},{"atb":[[34,6.04],[18.5,11.4],[13.5,21.28]],"id":41419629},{"atb":[[16,17.74],[44,4.64],[22,9.5]],"id":41419596}],"con":true,"img":false}]}
{"op":"mcm","clk":"5352146182","pt":1646183572644,"mc":[{"id":"1.195503864","marketDefinition":{"bspMarket":false,"turnInPlayEnabled":false,"persistenceEnabled":false,"marketBaseRate":7.0,"eventId":"31272499","eventTypeId":"4339","numberOfWinners":1,"bettingType":"ODDS","marketType":"EXACTA","marketTime":"2022-03-02T09:54:00.000Z","suspendTime":"2022-03-02T09:54:00.000Z","bspReconciled":false,"complete":true,"inPlay":false,"crossMatching":false,"runnersVoidable":false,"numberOfActiveRunners":56,"betDelay":0,"status":"OPEN","runners":[{"status":"ACTIVE","sortPriority":1,"id":41419585,"name":"1 - 2"},{"status":"ACTIVE","sortPriority":2,"id":41419586,"name":"1 - 3"},{"status":"ACTIVE","sortPriority":3,"id":41419587,"name":"1 - 4"},{"status":"ACTIVE","sortPriority":4,"id":41419588,"name":"1 - 5"},{"status":"ACTIVE","sortPriority":5,"id":41419589,"name":"1 - 6"},{"status":"ACTIVE","sortPriority":6,"id":41419590,"name":"1 - 7"},{"status":"ACTIVE","sortPriority":7,"id":41419591,"name":"1 - 8"},{"status":"ACTIVE","sortPriority":8,"id":41419592,"name":"2 - 1"},{"status":"ACTIVE","sortPriority":9,"id":41419593,"name":"2 - 3"},{"status":"ACTIVE","sortPriority":10,"id":41419594,"name":"2 - 4"},{"status":"ACTIVE","sortPriority":11,"id":41419595,"name":"2 - 5"},{"status":"ACTIVE","sortPriority":12,"id":41419596,"name":"2 - 6"},{"status":"ACTIVE","sortPriority":13,"id":41419597,"name":"2 - 7"},{"status":"ACTIVE","sortPriority":14,"id":41419598,"name":"2 - 8"},{"status":"ACTIVE","sortPriority":15,"id":41419599,"name":"3 - 1"},{"status":"ACTIVE","sortPriority":16,"id":41419600,"name":"3 - 2"},{"status":"ACTIVE","sortPriority":17,"id":41419601,"name":"3 - 4"},{"status":"ACTIVE","sortPriority":18,"id":41419602,"name":"3 - 5"},{"status":"ACTIVE","sortPriority":19,"id":41419603,"name":"3 - 6"},{"status":"ACTIVE","sortPriority":20,"id":41419604,"name":"3 - 7"},{"status":"ACTIVE","sortPriority":21,"id":41419605,"name":"3 - 8"},{"status":"ACTIVE","sortPriority":22,"id":41419606,"name":"4 - 1"},{"status":"ACTIVE","sortPriority":23,"id":41419607,"name":"4 - 2"},{"status":"ACTIVE","sortPriority":24,"id":41419608,"name":"4 - 3"},{"status":"ACTIVE","sortPriority":25,"id":41419609,"name":"4 - 5"},{"status":"ACTIVE","sortPriority":26,"id":41419610,"name":"4 - 6"},{"status":"ACTIVE","sortPriority":27,"id":41419611,"name":"4 - 7"},{"status":"ACTIVE","sortPriority":28,"id":41419612,"name":"4 - 8"},{"status":"ACTIVE","sortPriority":29,"id":41419613,"name":"5 - 1"},{"status":"ACTIVE","sortPriority":30,"id":41419614,"name":"5 - 2"},{"status":"ACTIVE","sortPriority":31,"id":41419615,"name":"5 - 3"},{"status":"ACTIVE","sortPriority":32,"id":41419616,"name":"5 - 4"},{"status":"ACTIVE","sortPriority":33,"id":41419617,"name":"5 - 6"},{"status":"ACTIVE","sortPriority":34,"id":41419618,"name":"5 - 7"},{"status":"ACTIVE","sortPriority":35,"id":41419619,"name":"5 - 8"},{"status":"ACTIVE","sortPriority":36,"id":41419620,"name":"6 - 1"},{"status":"ACTIVE","sortPriority":37,"id":41419621,"name":"6 - 2"},{"status":"ACTIVE","sortPriority":38,"id":41419622,"name":"6 - 3"},{"status":"ACTIVE","sortPriority":39,"id":41419623,"name":"6 - 4"},{"status":"ACTIVE","sortPriority":40,"id":41419624,"name":"6 - 5"},{"status":"ACTIVE","sortPriority":41,"id":41419625,"name":"6 - 7"},{"status":"ACTIVE","sortPriority":42,"id":41419626,"name":"6 - 8"},{"status":"ACTIVE","sortPriority":43,"id":41419627,"name":"7 - 1"},{"status":"ACTIVE","sortPriority":44,"id":41419628,"name":"7 - 2"},{"status":"ACTIVE","sortPriority":45,"id":41419629,"name":"7 - 3"},{"status":"ACTIVE","sortPriority":46,"id":41419630,"name":"7 - 4"},{"status":"ACTIVE","sortPriority":47,"id":41419631,"name":"7 - 5"},{"status":"ACTIVE","sortPriority":48,"id":41419632,"name":"7 - 6"},{"status":"ACTIVE","sortPriority":49,"id":41419633,"name":"7 - 8"},{"status":"ACTIVE","sortPriority":50,"id":41419634,"name":"8 - 1"},{"status":"ACTIVE","sortPriority":51,"id":41419635,"name":"8 - 2"},{"status":"ACTIVE","sortPriority":52,"id":41419636,"name":"8 - 3"},{"status":"ACTIVE","sortPriority":53,"id":41419637,"name":"8 - 4"},{"status":"ACTIVE","sortPriority":54,"id":41419638,"name":"8 - 5"},{"status":"ACTIVE","sortPriority":55,"id":41419639,"name":"8 - 6"},{"status":"ACTIVE","sortPriority":56,"id":41419640,"name":"8 - 7"}],"regulators":["MR_INT"],"venue":"Rockhampton","countryCode":"AU","discountAllowed":true,"timezone":"Australia/Queensland","openDate":"2022-03-02T08:28:00.000Z","version":4382597896,"name":"Exacta","eventName":"Rockhampton (AUS) 2nd Mar"},"rc":[],"con":true,"img":false}]}
{"op":"mcm","clk":"5352155934","pt":1646183840216,"mc":[{"id":"1.195503864","marketDefinition":{"bspMarket":false,"turnInPlayEnabled":false,"persistenceEnabled":false,"marketBaseRate":7.0,"eventId":"31272499","eventTypeId":"4339","numberOfWinners":1,"bettingType":"ODDS","marketType":"EXACTA","marketTime":"2022-03-02T09:47:00.000Z","suspendTime":"2022-03-02T09:47:00.000Z","bspReconciled":false,"complete":true,"inPlay":false,"crossMatching":false,"runnersVoidable":false,"numberOfActiveRunners":56,"betDelay":0,"status":"OPEN","runners":[{"status":"ACTIVE","sortPriority":1,"id":41419585,"name":"1 - 2"},{"status":"ACTIVE","sortPriority":2,"id":41419586,"name":"1 - 3"},{"status":"ACTIVE","sortPriority":3,"id":41419587,"name":"1 - 4"},{"status":"ACTIVE","sortPriority":4,"id":41419588,"name":"1 - 5"},{"status":"ACTIVE","sortPriority":5,"id":41419589,"name":"1 - 6"},{"status":"ACTIVE","sortPriority":6,"id":41419590,"name":"1 - 7"},{"status":"ACTIVE","sortPriority":7,"id":41419591,"name":"1 - 8"},{"status":"ACTIVE","sortPriority":8,"id":41419592,"name":"2 - 1"},{"status":"ACTIVE","sortPriority":9,"id":41419593,"name":"2 - 3"},{"status":"ACTIVE","sortPriority":10,"id":41419594,"name":"2 - 4"},{"status":"ACTIVE","sortPriority":11,"id":41419595,"name":"2 - 5"},{"status":"ACTIVE","sortPriority":12,"id":41419596,"name":"2 - 6"},{"status":"ACTIVE","sortPriority":13,"id":41419597,"name":"2 - 7"},{"status":"ACTIVE","sortPriority":14,"id":41419598,"name":"2 - 8"},{"status":"ACTIVE","sortPriority":15,"id":41419599,"name":"3 - 1"},{"status":"ACTIVE","sortPriority":16,"id":41419600,"name":"3 - 2"},{"status":"ACTIVE","sortPriority":17,"id":41419601,"name":"3 - 4"},{"status":"ACTIVE","sortPriority":18,"id":41419602,"name":"3 - 5"},{"status":"ACTIVE","sortPriority":19,"id":41419603,"name":"3 - 6"},{"status":"ACTIVE","sortPriority":20,"id":41419604,"name":"3 - 7"},{"status":"ACTIVE","sortPriority":21,"id":41419605,"name":"3 - 8"},{"status":"ACTIVE","sortPriority":22,"id":41419606,"name":"4 - 1"},{"status":"ACTIVE","sortPriority":23,"id":41419607,"name":"4 - 2"},{"status":"ACTIVE","sortPriority":24,"id":41419608,"name":"4 - 3"},{"status":"ACTIVE","sortPriority":25,"id":41419609,"name":"4 - 5"},{"status":"ACTIVE","sortPriority":26,"id":41419610,"name":"4 - 6"},{"status":"ACTIVE","sortPriority":27,"id":41419611,"name":"4 - 7"},{"status":"ACTIVE","sortPriority":28,"id":41419612,"name":"4 - 8"},{"status":"ACTIVE","sortPriority":29,"id":41419613,"name":"5 - 1"},{"status":"ACTIVE","sortPriority":30,"id":41419614,"name":"5 - 2"},{"status":"ACTIVE","sortPriority":31,"id":41419615,"name":"5 - 3"},{"status":"ACTIVE","sortPriority":32,"id":41419616,"name":"5 - 4"},{"status":"ACTIVE","sortPriority":33,"id":41419617,"name":"5 - 6"},{"status":"ACTIVE","sortPriority":34,"id":41419618,"name":"5 - 7"},{"status":"ACTIVE","sortPriority":35,"id":41419619,"name":"5 - 8"},{"status":"ACTIVE","sortPriority":36,"id":41419620,"name":"6 - 1"},{"status":"ACTIVE","sortPriority":37,"id":41419621,"name":"6 - 2"},{"status":"ACTIVE","sortPriority":38,"id":41419622,"name":"6 - 3"},{"status":"ACTIVE","sortPriority":39,"id":41419623,"name":"6 - 4"},{"status":"ACTIVE","sortPriority":40,"id":41419624,"name":"6 - 5"},{"status":"ACTIVE","sortPriority":41,"id":41419625,"name":"6 - 7"},{"status":"ACTIVE","sortPriority":42,"id":41419626,"name":"6 - 8"},{"status":"ACTIVE","sortPriority":43,"id":41419627,"name":"7 - 1"},{"status":"ACTIVE","sortPriority":44,"id":41419628,"name":"7 - 2"},{"status":"ACTIVE","sortPriority":45,"id":41419629,"name":"7 - 3"},{"status":"ACTIVE","sortPriority":46,"id":41419630,"name":"7 - 4"},{"status":"ACTIVE","sortPriority":47,"id":41419631,"name":"7 - 5"},{"status":"ACTIVE","sortPriority":48,"id":41419632,"name":"7 - 6"},{"status":"ACTIVE","sortPriority":49,"id":41419633,"name":"7 - 8"},{"status":"ACTIVE","sortPriority":50,"id":41419634,"name":"8 - 1"},{"status":"ACTIVE","sortPriority":51,"id":41419635,"name":"8 - 2"},{"status":"ACTIVE","sortPriority":52,"id":41419636,"name":"8 - 3"},{"status":"ACTIVE","sortPriority":53,"id":41419637,"name":"8 - 4"},{"status":"ACTIVE","sortPriority":54,"id":41419638,"name":"8 - 5"},{"status":"ACTIVE","sortPriority":55,"id":41419639,"name":"8 - 6"},{"status":"ACTIVE","sortPriority":56,"id":41419640,"name":"8 - 7"}],"regulators":["MR_INT"],"venue":"Rockhampton","countryCode":"AU","discountAllowed":true,"timezone":"Australia/Queensland","openDate":"2022-03-02T08:28:00.000Z","version":4382601914,"name":"Exacta","eventName":"Rockhampton (AUS) 2nd Mar"},"rc":[],"con":true,"img":false}]}
{"op":"mcm","clk":"5352239427","pt":1646185602748,"mc":[{"id":"1.195503864","marketDefinition":{"bspMarket":false,"turnInPlayEnabled":false,"persistenceEnabled":false,"marketBaseRate":7.0,"eventId":"31272499","eventTypeId":"4339","numberOfWinners":1,"bettingType":"ODDS","marketType":"EXACTA","marketTime":"2022-03-02T09:47:00.000Z","suspendTime":"2022-03-02T09:47:00.000Z","bspReconciled":false,"complete":true,"inPlay":false,"crossMatching":false,"runnersVoidable":false,"numberOfActiveRunners":56,"betDelay":0,"status":"OPEN","runners":[{"status":"ACTIVE","sortPriority":1,"id":41419585,"name":"1 - 2"},{"status":"ACTIVE","sortPriority":2,"id":41419586,"name":"1 - 3"},{"status":"ACTIVE","sortPriority":3,"id":41419587,"name":"1 - 4"},{"status":"ACTIVE","sortPriority":4,"id":41419588,"name":"1 - 5"},{"status":"ACTIVE","sortPriority":5,"id":41419589,"name":"1 - 6"},{"status":"ACTIVE","sortPriority":6,"id":41419590,"name":"1 - 7"},{"status":"ACTIVE","sortPriority":7,"id":41419591,"name":"1 - 8"},{"status":"ACTIVE","sortPriority":8,"id":41419592,"name":"2 - 1"},{"status":"ACTIVE","sortPriority":9,"id":41419593,"name":"2 - 3"},{"status":"ACTIVE","sortPriority":10,"id":41419594,"name":"2 - 4"},{"status":"ACTIVE","sortPriority":11,"id":41419595,"name":"2 - 5"},{"status":"ACTIVE","sortPriority":12,"id":41419596,"name":"2 - 6"},{"status":"ACTIVE","sortPriority":13,"id":41419597,"name":"2 - 7"},{"status":"ACTIVE","sortPriority":14,"id":41419598,"name":"2 - 8"},{"status":"ACTIVE","sortPriority":15,"id":41419599,"name":"3 - 1"},{"status":"ACTIVE","sortPriority":16,"id":41419600,"name":"3 - 2"},{"status":"ACTIVE","sortPriority":17,"id":41419601,"name":"3 - 4"},{"status":"ACTIVE","sortPriority":18,"id":41419602,"name":"3 - 5"},{"status":"ACTIVE","sortPriority":19,"id":41419603,"name":"3 - 6"},{"status":"ACTIVE","sortPriority":20,"id":41419604,"name":"3 - 7"},{"status":"ACTIVE","sortPriority":21,"id":41419605,"name":"3 - 8"},{"status":"ACTIVE","sortPriority":22,"id":41419606,"name":"4 - 1"},{"status":"ACTIVE","sortPriority":23,"id":41419607,"name":"4 - 2"},{"status":"ACTIVE","sortPriority":24,"id":41419608,"name":"4 - 3"},{"status":"ACTIVE","sortPriority":25,"id":41419609,"name":"4 - 5"},{"status":"ACTIVE","sortPriority":26,"id":41419610,"name":"4 - 6"},{"status":"ACTIVE","sortPriority":27,"id":41419611,"name":"4 - 7"},{"status":"ACTIVE","sortPriority":28,"id":41419612,"name":"4 - 8"},{"status":"ACTIVE","sortPriority":29,"id":41419613,"name":"5 - 1"},{"status":"ACTIVE","sortPriority":30,"id":41419614,"name":"5 - 2"},{"status":"ACTIVE","sortPriority":31,"id":41419615,"name":"5 - 3"},{"status":"ACTIVE","sortPriority":32,"id":41419616,"name":"5 - 4"},{"status":"ACTIVE","sortPriority":33,"id":41419617,"name":"5 - 6"},{"status":"ACTIVE","sortPriority":34,"id":41419618,"name":"5 - 7"},{"status":"ACTIVE","sortPriority":35,"id":41419619,"name":"5 - 8"},{"status":"ACTIVE","sortPriority":36,"id":41419620,"name":"6 - 1"},{"status":"ACTIVE","sortPriority":37,"id":41419621,"name":"6 - 2"},{"status":"ACTIVE","sortPriority":38,"id":41419622,"name":"6 - 3"},{"status":"ACTIVE","sortPriority":39,"id":41419623,"name":"6 - 4"},{"status":"ACTIVE","sortPriority":40,"id":41419624,"name":"6 - 5"},{"status":"ACTIVE","sortPriority":41,"id":41419625,"name":"6 - 7"},{"status":"ACTIVE","sortPriority":42,"id":41419626,"name":"6 - 8"},{"status":"ACTIVE","sortPriority":43,"id":41419627,"name":"7 - 1"},{"status":"ACTIVE","sortPriority":44,"id":41419628,"name":"7 - 2"},{"status":"ACTIVE","sortPriority":45,"id":41419629,"name":"7 - 3"},{"status":"ACTIVE","sortPriority":46,"id":41419630,"name":"7 - 4"},{"status":"ACTIVE","sortPriority":47,"id":41419631,"name":"7 - 5"},{"status":"ACTIVE","sortPriority":48,"id":41419632,"name":"7 - 6"},{"status":"ACTIVE","sortPriority":49,"id":41419633,"name":"7 - 8"},{"status":"ACTIVE","sortPriority":50,"id":41419634,"name":"8 - 1"},{"status":"ACTIVE","sortPriority":51,"id":41419635,"name":"8 - 2"},{"status":"ACTIVE","sortPriority":52,"id":41419636,"name":"8 - 3"},{"status":"ACTIVE","sortPriority":53,"id":41419637,"name":"8 - 4"},{"status":"ACTIVE","sortPriority":54,"id":41419638,"name":"8 - 5"},{"status":"ACTIVE","sortPriority":55,"id":41419639,"name":"8 - 6"},{"status":"ACTIVE","sortPriority":56,"id":41419640,"name":"8 - 7"}],"regulators":["MR_INT"],"venue":"Rockhampton","countryCode":"AU","discountAllowed":true,"timezone":"Australia/Queensland","openDate":"2022-03-02T08:28:00.000Z","version":4382601914,"name":"Exacta","eventName":"Rockhampton (AUS) 2nd Mar"},"rc":[{"atb":[[16.5,12.89],[11.5,25.38],[28,7.4]],"id":41419609},{"atb":[[18,15.67],[26,7.99],[55,3.7]],"id":41419638},{"atb":[[18.5,15.22],[27,7.68],[60,3.38]],"id":41419605},{"atb":[[65,3.12],[19,14.8],[28,7.4]],"id":41419634},{"atb":[[40,5.12],[20,10.51],[15,19.03]],"id":41419617},{"atb":[[280,0.71],[180,1.48],[430,0.46]],"id":41419613},{"atb":[[270,0.74],[170,1.57],[420,0.47]],"id":41419593},{"atb":[[17.5,12.11],[12.5,23.17],[30,6.89]],"id":41419622},{"atb":[[42,4.87],[21,9.99],[15.5,18.38]],"id":41419589},{"atb":[[42,4.87],[21,9.99],[15.5,18.38]],"id":41419618},{"atb":[[32,6.45],[18,11.75],[13,22.2]],"id":41419601},{"atb":[[4.9,68.34],[8.8,25.62],[5.9,40.79]],"id":41419630},{"atb":[[16.5,17.19],[46,4.44],[23,9.08]],"id":41419597},{"atb":[[16,13.32],[7.4,41.64],[9.4,23.79]],"id":41419626},{"atb":[[8,38.07],[17.5,12.11],[10,22.2]],"id":41419639},{"atb":[[17.5,12.11],[12.5,23.17],[30,6.89]],"id":41419606},{"atb":[[70,2.89],[19.5,14.4],[29,7.13]],"id":41419635},{"atb":[[330,0.6],[180,1.11],[90,2.99]],"id":41419602},{"atb":[[540,0.37],[290,0.92],[390,0.51]],"id":41419585},{"atb":[[310,0.64],[210,1.27],[460,0.43]],"id":41419614},{"atb":[[4.4,78.39],[7.8,29.39],[5.4,45.43]],"id":41419610},{"atb":[[8,28.55],[4.5,76.15],[5.5,44.42]],"id":41419623},{"atb":[[16,17.77],[44,4.65],[22,9.52]],"id":41419590},{"atb":[[65,3.12],[19,14.8],[28,7.4]],"id":41419619},{"atb":[[140,1.91],[390,0.51],[240,0.83]],"id":41419586},{"atb":[[36,5.7],[19,11.1],[14,20.5]],"id":41419631},{"atb":[[32,6.45],[80,2.53],[21,13.32]],"id":41419598},{"atb":[[40,5.12],[20,10.51],[15,19.03]],"id":41419627},{"atb":[[40,5.12],[20,10.51],[15,19.03]],"id":41419594},{"atb":[[18.5,11.42],[11,19.99],[8.4,36.01]],"id":41419640},{"atb":[[32,6.45],[18,11.75],[13,22.2]],"id":41419607},{"atb":[[17.5,16.15],[50,4.07],[25,8.32]],"id":41419636},{"atb":[[36,5.7],[19,11.1],[14,20.5]],"id":41419603},{"atb":[[330,0.6],[180,1.11],[90,2.99]],"id":41419615},{"atb":[[5.7,42.53],[8.4,27.01],[4.7,72.03]],"id":41419611},{"atb":[[32,6.45],[18,11.75],[13,22.2]],"id":41419624},{"atb":[[75,2.69],[20,14.03],[30,6.89]],"id":41419591},{"atb":[[36,5.7],[19,11.1],[14,20.5]],"id":41419620},{"atb":[[38,5.4],[19.5,10.8],[14.5,19.74]],"id":41419587},{"atb":[[9.6,23.24],[5.3,61.98],[6.6,35.69]],"id":41419632},{"atb":[[140,1.91],[390,0.51],[240,0.83]],"id":41419599},{"atb":[[42,4.87],[21,9.99],[15.5,18.38]],"id":41419628},{"atb":[[310,0.64],[210,1.27],[460,0.43]],"id":41419595},{"atb":[[16,13.32],[11,26.65],[27,7.68]],"id":41419608},{"atb":[[7.2,42.99],[9.2,24.37],[15.5,13.78]],"id":41419637},{"atb":[[40,5.12],[20,10.51],[15,19.03]],"id":41419604},{"atb":[[34,6.05],[18.5,11.42],[13.5,21.32]],"id":41419616},{"atb":[[6.4,49.35],[13.5,15.99],[8.4,27.01]],"id":41419612},{"atb":[[6.4,37.01],[5.2,63.46],[9.4,23.79]],"id":41419625},{"atb":[[540,0.37],[290,0.92],[390,0.51]],"id":41419592},{"atb":[[38,5.4],[19.5,10.8],[14.5,19.74]],"id":41419621},{"atb":[[280,0.71],[180,1.48],[430,0.46]],"id":41419588},{"atb":[[8,38.07],[17.5,12.11],[10,22.2]],"id":41419633},{"atb":[[270,0.74],[170,1.57],[420,0.47]],"id":41419600},{"atb":[[34,6.05],[18.5,11.42],[13.5,21.32]],"id":41419629},{"atb":[[16,17.77],[44,4.65],[22,9.52]],"id":41419596}],"con":true,"img":true}]}
{"op":"mcm","clk":"5352466715","pt":1646191002691,"mc":[{"id":"1.195503864","marketDefinition":{"bspMarket":false,"turnInPlayEnabled":false,"persistenceEnabled":false,"marketBaseRate":7.0,"eventId":"31272499","eventTypeId":"4339","numberOfWinners":1,"bettingType":"ODDS","marketType":"EXACTA","marketTime":"2022-03-02T09:47:00.000Z","suspendTime":"2022-03-02T09:47:00.000Z","bspReconciled":false,"complete":true,"inPlay":false,"crossMatching":false,"runnersVoidable":false,"numberOfActiveRunners":56,"betDelay":0,"status":"OPEN","runners":[{"status":"ACTIVE","sortPriority":1,"id":41419585,"name":"1 - 2"},{"status":"ACTIVE","sortPriority":2,"id":41419586,"name":"1 - 3"},{"status":"ACTIVE","sortPriority":3,"id":41419587,"name":"1 - 4"},{"status":"ACTIVE","sortPriority":4,"id":41419588,"name":"1 - 5"},{"status":"ACTIVE","sortPriority":5,"id":41419589,"name":"1 - 6"},{"status":"ACTIVE","sortPriority":6,"id":41419590,"name":"1 - 7"},{"status":"ACTIVE","sortPriority":7,"id":41419591,"name":"1 - 8"},{"status":"ACTIVE","sortPriority":8,"id":41419592,"name":"2 - 1"},{"status":"ACTIVE","sortPriority":9,"id":41419593,"name":"2 - 3"},{"status":"ACTIVE","sortPriority":10,"id":41419594,"name":"2 - 4"},{"status":"ACTIVE","sortPriority":11,"id":41419595,"name":"2 - 5"},{"status":"ACTIVE","sortPriority":12,"id":41419596,"name":"2 - 6"},{"status":"ACTIVE","sortPriority":13,"id":41419597,"name":"2 - 7"},{"status":"ACTIVE","sortPriority":14,"id":41419598,"name":"2 - 8"},{"status":"ACTIVE","sortPriority":15,"id":41419599,"name":"3 - 1"},{"status":"ACTIVE","sortPriority":16,"id":41419600,"name":"3 - 2"},{"status":"ACTIVE","sortPriority":17,"id":41419601,"name":"3 - 4"},{"status":"ACTIVE","sortPriority":18,"id":41419602,"name":"3 - 5"},{"status":"ACTIVE","sortPriority":19,"id":41419603,"name":"3 - 6"},{"status":"ACTIVE","sortPriority":20,"id":41419604,"name":"3 - 7"},{"status":"ACTIVE","sortPriority":21,"id":41419605,"name":"3 - 8"},{"status":"ACTIVE","sortPriority":22,"id":41419606,"name":"4 - 1"},{"status":"ACTIVE","sortPriority":23,"id":41419607,"name":"4 - 2"},{"status":"ACTIVE","sortPriority":24,"id":41419608,"name":"4 - 3"},{"status":"ACTIVE","sortPriority":25,"id":41419609,"name":"4 - 5"},{"status":"ACTIVE","sortPriority":26,"id":41419610,"name":"4 - 6"},{"status":"ACTIVE","sortPriority":27,"id":41419611,"name":"4 - 7"},{"status":"ACTIVE","sortPriority":28,"id":41419612,"name":"4 - 8"},{"status":"ACTIVE","sortPriority":29,"id":41419613,"name":"5 - 1"},{"status":"ACTIVE","sortPriority":30,"id":41419614,"name":"5 - 2"},{"status":"ACTIVE","sortPriority":31,"id":41419615,"name":"5 - 3"},{"status":"ACTIVE","sortPriority":32,"id":41419616,"name":"5 - 4"},{"status":"ACTIVE","sortPriority":33,"id":41419617,"name":"5 - 6"},{"status":"ACTIVE","sortPriority":34,"id":41419618,"name":"5 - 7"},{"status":"ACTIVE","sortPriority":35,"id":41419619,"name":"5 - 8"},{"status":"ACTIVE","sortPriority":36,"id":41419620,"name":"6 - 1"},{"status":"ACTIVE","sortPriority":37,"id":41419621,"name":"6 - 2"},{"status":"ACTIVE","sortPriority":38,"id":41419622,"name":"6 - 3"},{"status":"ACTIVE","sortPriority":39,"id":41419623,"name":"6 - 4"},{"status":"ACTIVE","sortPriority":40,"id":41419624,"name":"6 - 5"},{"status":"ACTIVE","sortPriority":41,"id":41419625,"name":"6 - 7"},{"status":"ACTIVE","sortPriority":42,"id":41419626,"name":"6 - 8"},{"status":"ACTIVE","sortPriority":43,"id":41419627,"name":"7 - 1"},{"status":"ACTIVE","sortPriority":44,"id":41419628,"name":"7 - 2"},{"status":"ACTIVE","sortPriority":45,"id":41419629,"name":"7 - 3"},{"status":"ACTIVE","sortPriority":46,"id":41419630,"name":"7 - 4"},{"status":"ACTIVE","sortPriority":47,"id":41419631,"name":"7 - 5"},{"status":"ACTIVE","sortPriority":48,"id":41419632,"name":"7 - 6"},{"status":"ACTIVE","sortPriority":49,"id":41419633,"name":"7 - 8"},{"status":"ACTIVE","sortPriority":50,"id":41419634,"name":"8 - 1"},{"status":"ACTIVE","sortPriority":51,"id":41419635,"name":"8 - 2"},{"status":"ACTIVE","sortPriority":52,"id":41419636,"name":"8 - 3"},{"status":"ACTIVE","sortPriority":53,"id":41419637,"name":"8 - 4"},{"status":"ACTIVE","sortPriority":54,"id":41419638,"name":"8 - 5"},{"status":"ACTIVE","sortPriority":55,"id":41419639,"name":"8 - 6"},{"status":"ACTIVE","sortPriority":56,"id":41419640,"name":"8 - 7"}],"regulators":["MR_INT"],"venue":"Rockhampton","countryCode":"AU","discountAllowed":true,"timezone":"Australia/Queensland","openDate":"2022-03-02T08:28:00.000Z","version":4382601914,"name":"Exacta","eventName":"Rockhampton (AUS) 2nd Mar"},"rc":[{"atb":[[16.5,12.91],[11.5,25.42],[28,7.41]],"id":41419609},{"atb":[[18,15.7],[26,8],[55,3.7]],"id":41419638},{"atb":[[18.5,15.25],[27,7.7],[60,3.39]],"id":41419605},{"atb":[[65,3.12],[19,14.83],[28,7.41]],"id":41419634},{"atb":[[40,5.13],[20,10.53],[15,19.06]],"id":41419617},{"atb":[[280,0.71],[180,1.49],[430,0.46]],"id":41419613},{"atb":[[270,0.74],[170,1.57],[420,0.47]],"id":41419593},{"atb":[[17.5,12.13],[12.5,23.21],[30,6.9]],"id":41419622},{"atb":[[42,4.88],[21,10.01],[15.5,18.41]],"id":41419589},{"atb":[[42,4.88],[21,10.01],[15.5,18.41]],"id":41419618},{"atb":[[32,6.46],[18,11.77],[13,22.24]],"id":41419601},{"atb":[[4.9,68.45],[8.8,25.67],[5.9,40.86]],"id":41419630},{"atb":[[16.5,17.22],[46,4.45],[23,9.09]],"id":41419597},{"atb":[[16,13.34],[7.4,41.71],[9.4,23.83]],"id":41419626},{"atb":[[8,38.14],[17.5,12.13],[10,22.24]],"id":41419639},{"atb":[[17.5,12.13],[12.5,23.21],[30,6.9]],"id":41419606},{"atb":[[70,2.9],[19.5,14.43],[29,7.14]],"id":41419635},{"atb":[[330,0.6],[180,1.11],[90,2.99]],"id":41419602},{"atb":[[540,0.37],[290,0.92],[390,0.51]],"id":41419585},{"atb":[[310,0.64],[210,1.27],[460,0.43]],"id":41419614},{"atb":[[4.4,78.52],[7.8,29.44],[5.4,45.51]],"id":41419610},{"atb":[[8,28.6],[4.5,76.28],[5.5,44.49]],"id":41419623},{"atb":[[16,17.8],[44,4.65],[22,9.53]],"id":41419590},{"atb":[[65,3.12],[19,14.83],[28,7.41]],"id":41419619},{"atb":[[140,1.92],[390,0.51],[240,0.83]],"id":41419586},{"atb":[[36,5.71],[19,11.12],[14,20.53]],"id":41419631},{"atb":[[32,6.46],[80,2.53],[21,13.34]],"id":41419598},{"atb":[[40,5.13],[20,10.53],[15,19.06]],"id":41419627},{"atb":[[40,5.13],[20,10.53],[15,19.06]],"id":41419594},{"atb":[[18.5,11.44],[11,20.02],[8.4,36.07]],"id":41419640},{"atb":[[32,6.46],[18,11.77],[13,22.24]],"id":41419607},{"atb":[[17.5,16.17],[50,4.08],[25,8.34]],"id":41419636},{"atb":[[36,5.71],[19,11.12],[14,20.53]],"id":41419603},{"atb":[[330,0.6],[180,1.11],[90,2.99]],"id":41419615},{"atb":[[5.7,42.6],[8.4,27.05],[4.7,72.15]],"id":41419611},{"atb":[[32,6.46],[18,11.77],[13,22.24]],"id":41419624},{"atb":[[75,2.7],[20,14.05],[30,6.9]],"id":41419591},{"atb":[[36,5.71],[19,11.12],[14,20.53]],"id":41419620},{"atb":[[38,5.41],[19.5,10.82],[14.5,19.77]],"id":41419587},{"atb":[[9.6,23.28],[5.3,62.08],[6.6,35.75]],"id":41419632},{"atb":[[140,1.92],[390,0.51],[240,0.83]],"id":41419599},{"atb":[[42,4.88],[21,10.01],[15.5,18.41]],"id":41419628},{"atb":[[310,0.64],[210,1.27],[460,0.43]],"id":41419595},{"atb":[[16,13.34],[11,26.69],[27,7.7]],"id":41419608},{"atb":[[7.2,43.06],[9.2,24.42],[15.5,13.8]],"id":41419637},{"atb":[[40,5.13],[20,10.53],[15,19.06]],"id":41419604},{"atb":[[34,6.06],[18.5,11.44],[13.5,21.35]],"id":41419616},{"atb":[[6.4,49.44],[13.5,16.02],[8.4,27.05]],"id":41419612},{"atb":[[6.4,37.08],[5.2,63.56],[9.4,23.83]],"id":41419625},{"atb":[[540,0.37],[290,0.92],[390,0.51]],"id":41419592},{"atb":[[38,5.41],[19.5,10.82],[14.5,19.77]],"id":41419621},{"atb":[[280,0.71],[180,1.49],[430,0.46]],"id":41419588},{"atb":[[8,38.14],[17.5,12.13],[10,22.24]],"id":41419633},{"atb":[[270,0.74],[170,1.57],[420,0.47]],"id":41419600},{"atb":[[34,6.06],[18.5,11.44],[13.5,21.35]],"id":41419629},{"atb":[[16,17.8],[44,4.65],[22,9.53]],"id":41419596}],"con":true,"img":true}]}
{"op":"mcm","clk":"5352823521","pt":1646201802742,"mc":[{"id":"1.195503864","marketDefinition":{"bspMarket":false,"turnInPlayEnabled":false,"persistenceEnabled":false,"marketBaseRate":7.0,"eventId":"31272499","eventTypeId":"4339","numberOfWinners":1,"bettingType":"ODDS","marketType":"EXACTA","marketTime":"2022-03-02T09:47:00.000Z","suspendTime":"2022-03-02T09:47:00.000Z","bspReconciled":false,"complete":true,"inPlay":false,"crossMatching":false,"runnersVoidable":false,"numberOfActiveRunners":56,"betDelay":0,"status":"OPEN","runners":[{"status":"ACTIVE","sortPriority":1,"id":41419585,"name":"1 - 2"},{"status":"ACTIVE","sortPriority":2,"id":41419586,"name":"1 - 3"},{"status":"ACTIVE","sortPriority":3,"id":41419587,"name":"1 - 4"},{"status":"ACTIVE","sortPriority":4,"id":41419588,"name":"1 - 5"},{"status":"ACTIVE","sortPriority":5,"id":41419589,"name":"1 - 6"},{"status":"ACTIVE","sortPriority":6,"id":41419590,"name":"1 - 7"},{"status":"ACTIVE","sortPriority":7,"id":41419591,"name":"1 - 8"},{"status":"ACTIVE","sortPriority":8,"id":41419592,"name":"2 - 1"},{"status":"ACTIVE","sortPriority":9,"id":41419593,"name":"2 - 3"},{"status":"ACTIVE","sortPriority":10,"id":41419594,"name":"2 - 4"},{"status":"ACTIVE","sortPriority":11,"id":41419595,"name":"2 - 5"},{"status":"ACTIVE","sortPriority":12,"id":41419596,"name":"2 - 6"},{"status":"ACTIVE","sortPriority":13,"id":41419597,"name":"2 - 7"},{"status":"ACTIVE","sortPriority":14,"id":41419598,"name":"2 - 8"},{"status":"ACTIVE","sortPriority":15,"id":41419599,"name":"3 - 1"},{"status":"ACTIVE","sortPriority":16,"id":41419600,"name":"3 - 2"},{"status":"ACTIVE","sortPriority":17,"id":41419601,"name":"3 - 4"},{"status":"ACTIVE","sortPriority":18,"id":41419602,"name":"3 - 5"},{"status":"ACTIVE","sortPriority":19,"id":41419603,"name":"3 - 6"},{"status":"ACTIVE","sortPriority":20,"id":41419604,"name":"3 - 7"},{"status":"ACTIVE","sortPriority":21,"id":41419605,"name":"3 - 8"},{"status":"ACTIVE","sortPriority":22,"id":41419606,"name":"4 - 1"},{"status":"ACTIVE","sortPriority":23,"id":41419607,"name":"4 - 2"},{"status":"ACTIVE","sortPriority":24,"id":41419608,"name":"4 - 3"},{"status":"ACTIVE","sortPriority":25,"id":41419609,"name":"4 - 5"},{"status":"ACTIVE","sortPriority":26,"id":41419610,"name":"4 - 6"},{"status":"ACTIVE","sortPriority":27,"id":41419611,"name":"4 - 7"},{"status":"ACTIVE","sortPriority":28,"id":41419612,"name":"4 - 8"},{"status":"ACTIVE","sortPriority":29,"id":41419613,"name":"5 - 1"},{"status":"ACTIVE","sortPriority":30,"id":41419614,"name":"5 - 2"},{"status":"ACTIVE","sortPriority":31,"id":41419615,"name":"5 - 3"},{"status":"ACTIVE","sortPriority":32,"id":41419616,"name":"5 - 4"},{"status":"ACTIVE","sortPriority":33,"id":41419617,"name":"5 - 6"},{"status":"ACTIVE","sortPriority":34,"id":41419618,"name":"5 - 7"},{"status":"ACTIVE","sortPriority":35,"id":41419619,"name":"5 - 8"},{"status":"ACTIVE","sortPriority":36,"id":41419620,"name":"6 - 1"},{"status":"ACTIVE","sortPriority":37,"id":41419621,"name":"6 - 2"},{"status":"ACTIVE","sortPriority":38,"id":41419622,"name":"6 - 3"},{"status":"ACTIVE","sortPriority":39,"id":41419623,"name":"6 - 4"},{"status":"ACTIVE","sortPriority":40,"id":41419624,"name":"6 - 5"},{"status":"ACTIVE","sortPriority":41,"id":41419625,"name":"6 - 7"},{"status":"ACTIVE","sortPriority":42,"id":41419626,"name":"6 - 8"},{"status":"ACTIVE","sortPriority":43,"id":41419627,"name":"7 - 1"},{"status":"ACTIVE","sortPriority":44,"id":41419628,"name":"7 - 2"},{"status":"ACTIVE","sortPriority":45,"id":41419629,"name":"7 - 3"},{"status":"ACTIVE","sortPriority":46,"id":41419630,"name":"7 - 4"},{"status":"ACTIVE","sortPriority":47,"id":41419631,"name":"7 - 5"},{"status":"ACTIVE","sortPriority":48,"id":41419632,"name":"7 - 6"},{"status":"ACTIVE","sortPriority":49,"id":41419633,"name":"7 - 8"},{"status":"ACTIVE","sortPriority":50,"id":41419634,"name":"8 - 1"},{"status":"ACTIVE","sortPriority":51,"id":41419635,"name":"8 - 2"},{"status":"ACTIVE","sortPriority":52,"id":41419636,"name":"8 - 3"},{"status":"ACTIVE","sortPriority":53,"id":41419637,"name":"8 - 4"},{"status":"ACTIVE","sortPriority":54,"id":41419638,"name":"8 - 5"},{"status":"ACTIVE","sortPriority":55,"id":41419639,"name":"8 - 6"},{"status":"ACTIVE","sortPriority":56,"id":41419640,"name":"8 - 7"}],"regulators":["MR_INT"],"venue":"Rockhampton","countryCode":"AU","discountAllowed":true,"timezone":"Australia/Queensland","openDate":"2022-03-02T08:28:00.000Z","version":4382601914,"name":"Exacta","eventName":"Rockhampton (AUS) 2nd Mar"},"rc":[{"atb":[[16.5,12.91],[11.5,25.41],[28,7.41]],"id":41419609},{"atb":[[18,15.69],[26,8],[55,3.7]],"id":41419638},{"atb":[[18.5,15.24],[27,7.69],[60,3.39]],"id":41419605},{"atb":[[65,3.12],[19,14.82],[28,7.41]],"id":41419634},{"atb":[[40,5.13],[20,10.53],[15,19.06]],"id":41419617},{"atb":[[280,0.71],[180,1.49],[430,0.46]],"id":41419613},{"atb":[[270,0.74],[170,1.57],[420,0.47]],"id":41419593},{"atb":[[17.5,12.13],[12.5,23.2],[30,6.9]],"id":41419622},{"atb":[[42,4.88],[21,10],[15.5,18.4]],"id":41419589},{"atb":[[42,4.88],[21,10],[15.5,18.4]],"id":41419618},{"atb":[[32,6.45],[18,11.77],[13,22.23]],"id":41419601},{"atb":[[4.9,68.43],[8.8,25.66],[5.9,40.85]],"id":41419630},{"atb":[[16.5,17.22],[46,4.44],[23,9.09]],"id":41419597},{"atb":[[16,13.34],[7.4,41.7],[9.4,23.82]],"id":41419626},{"atb":[[8,38.12],[17.5,12.13],[10,22.23]],"id":41419639},{"atb":[[17.5,12.13],[12.5,23.2],[30,6.9]],"id":41419606},{"atb":[[70,2.89],[19.5,14.42],[29,7.14]],"id":41419635},{"atb":[[330,0.6],[180,1.11],[90,2.99]],"id":41419602},{"atb":[[540,0.37],[290,0.92],[390,0.51]],"id":41419585},{"atb":[[310,0.64],[210,1.27],[460,0.43]],"id":41419614},{"atb":[[4.4,78.49],[7.8,29.43],[5.4,45.49]],"id":41419610},{"atb":[[8,28.59],[4.5,76.25],[5.5,44.48]],"id":41419623},{"atb":[[16,17.79],[44,4.65],[22,9.53]],"id":41419590},{"atb":[[65,3.12],[19,14.82],[28,7.41]],"id":41419619},{"atb":[[140,1.92],[390,0.51],[240,0.83]],"id":41419586},{"atb":[[36,5.71],[19,11.12],[14,20.52]],"id":41419631},{"atb":[[32,6.45],[80,2.53],[21,13.34]],"id":41419598},{"atb":[[40,5.13],[20,10.53],[15,19.06]],"id":41419627},{"atb":[[40,5.13],[20,10.53],[15,19.06]],"id":41419594},{"atb":[[18.5,11.43],[11,20.01],[8.4,36.06]],"id":41419640},{"atb":[[32,6.45],[18,11.77],[13,22.23]],"id":41419607},{"atb":[[17.5,16.17],[50,4.08],[25,8.33]],"id":41419636},{"atb":[[36,5.71],[19,11.12],[14,20.52]],"id":41419603},{"atb":[[330,0.6],[180,1.11],[90,2.99]],"id":41419615},{"atb":[[5.7,42.58],[8.4,27.04],[4.7,72.13]],"id":41419611},{"atb":[[32,6.45],[18,11.77],[13,22.23]],"id":41419624},{"atb":[[75,2.7],[20,14.04],[30,6.9]],"id":41419591},{"atb":[[36,5.71],[19,11.12],[14,20.52]],"id":41419620},{"atb":[[38,5.41],[19.5,10.82],[14.5,19.77]],"id":41419587},{"atb":[[9.6,23.27],[5.3,62.06],[6.6,35.74]],"id":41419632},{"atb":[[140,1.92],[390,0.51],[240,0.83]],"id":41419599},{"atb":[[42,4.88],[21,10],[15.5,18.4]],"id":41419628},{"atb":[[310,0.64],[210,1.27],[460,0.43]],"id":41419595},{"atb":[[16,13.34],[11,26.68],[27,7.69]],"id":41419608},{"atb":[[7.2,43.04],[9.2,24.41],[15.5,13.8]],"id":41419637},{"atb":[[40,5.13],[20,10.53],[15,19.06]],"id":41419604},{"atb":[[34,6.06],[18.5,11.43],[13.5,21.34]],"id":41419616},{"atb":[[6.4,49.42],[13.5,16.01],[8.4,27.04]],"id":41419612},{"atb":[[6.4,37.06],[5.2,63.54],[9.4,23.82]],"id":41419625},{"atb":[[540,0.37],[290,0.92],[390,0.51]],"id":41419592},{"atb":[[38,5.41],[19.5,10.82],[14.5,19.77]],"id":41419621},{"atb":[[280,0.71],[180,1.49],[430,0.46]],"id":41419588},{"atb":[[8,38.12],[17.5,12.13],[10,22.23]],"id":41419633},{"atb":[[270,0.74],[170,1.57],[420,0.47]],"id":41419600},{"atb":[[34,6.06],[18.5,11.43],[13.5,21.34]],"id":41419629},{"atb":[[16,17.79],[44,4.65],[22,9.53]],"id":41419596}],"con":true,"img":true}]}
{"op":"mcm","clk":"5353028891","pt":1646207202759,"mc":[{"id":"1.195503864","marketDefinition":{"bspMarket":false,"turnInPlayEnabled":false,"persistenceEnabled":false,"marketBaseRate":7.0,"eventId":"31272499","eventTypeId":"4339","numberOfWinners":1,"bettingType":"ODDS","marketType":"EXACTA","marketTime":"2022-03-02T09:47:00.000Z","suspendTime":"2022-03-02T09:47:00.000Z","bspReconciled":false,"complete":true,"inPlay":false,"crossMatching":false,"runnersVoidable":false,"numberOfActiveRunners":56,"betDelay":0,"status":"OPEN","runners":[{"status":"ACTIVE","sortPriority":1,"id":41419585,"name":"1 - 2"},{"status":"ACTIVE","sortPriority":2,"id":41419586,"name":"1 - 3"},{"status":"ACTIVE","sortPriority":3,"id":41419587,"name":"1 - 4"},{"status":"ACTIVE","sortPriority":4,"id":41419588,"name":"1 - 5"},{"status":"ACTIVE","sortPriority":5,"id":41419589,"name":"1 - 6"},{"status":"ACTIVE","sortPriority":6,"id":41419590,"name":"1 - 7"},{"status":"ACTIVE","sortPriority":7,"id":41419591,"name":"1 - 8"},{"status":"ACTIVE","sortPriority":8,"id":41419592,"name":"2 - 1"},{"status":"ACTIVE","sortPriority":9,"id":41419593,"name":"2 - 3"},{"status":"ACTIVE","sortPriority":10,"id":41419594,"name":"2 - 4"},{"status":"ACTIVE","sortPriority":11,"id":41419595,"name":"2 - 5"},{"status":"ACTIVE","sortPriority":12,"id":41419596,"name":"2 - 6"},{"status":"ACTIVE","sortPriority":13,"id":41419597,"name":"2 - 7"},{"status":"ACTIVE","sortPriority":14,"id":41419598,"name":"2 - 8"},{"status":"ACTIVE","sortPriority":15,"id":41419599,"name":"3 - 1"},{"status":"ACTIVE","sortPriority":16,"id":41419600,"name":"3 - 2"},{"status":"ACTIVE","sortPriority":17,"id":41419601,"name":"3 - 4"},{"status":"ACTIVE","sortPriority":18,"id":41419602,"name":"3 - 5"},{"status":"ACTIVE","sortPriority":19,"id":41419603,"name":"3 - 6"},{"status":"ACTIVE","sortPriority":20,"id":41419604,"name":"3 - 7"},{"status":"ACTIVE","sortPriority":21,"id":41419605,"name":"3 - 8"},{"status":"ACTIVE","sortPriority":22,"id":41419606,"name":"4 - 1"},{"status":"ACTIVE","sortPriority":23,"id":41419607,"name":"4 - 2"},{"status":"ACTIVE","sortPriority":24,"id":41419608,"name":"4 - 3"},{"status":"ACTIVE","sortPriority":25,"id":41419609,"name":"4 - 5"},{"status":"ACTIVE","sortPriority":26,"id":41419610,"name":"4 - 6"},{"status":"ACTIVE","sortPriority":27,"id":41419611,"name":"4 - 7"},{"status":"ACTIVE","sortPriority":28,"id":41419612,"name":"4 - 8"},{"status":"ACTIVE","sortPriority":29,"id":41419613,"name":"5 - 1"},{"status":"ACTIVE","sortPriority":30,"id":41419614,"name":"5 - 2"},{"status":"ACTIVE","sortPriority":31,"id":41419615,"name":"5 - 3"},{"status":"ACTIVE","sortPriority":32,"id":41419616,"name":"5 - 4"},{"status":"ACTIVE","sortPriority":33,"id":41419617,"name":"5 - 6"},{"status":"ACTIVE","sortPriority":34,"id":41419618,"name":"5 - 7"},{"status":"ACTIVE","sortPriority":35,"id":41419619,"name":"5 - 8"},{"status":"ACTIVE","sortPriority":36,"id":41419620,"name":"6 - 1"},{"status":"ACTIVE","sortPriority":37,"id":41419621,"name":"6 - 2"},{"status":"ACTIVE","sortPriority":38,"id":41419622,"name":"6 - 3"},{"status":"ACTIVE","sortPriority":39,"id":41419623,"name":"6 - 4"},{"status":"ACTIVE","sortPriority":40,"id":41419624,"name":"6 - 5"},{"status":"ACTIVE","sortPriority":41,"id":41419625,"name":"6 - 7"},{"status":"ACTIVE","sortPriority":42,"id":41419626,"name":"6 - 8"},{"status":"ACTIVE","sortPriority":43,"id":41419627,"name":"7 - 1"},{"status":"ACTIVE","sortPriority":44,"id":41419628,"name":"7 - 2"},{"status":"ACTIVE","sortPriority":45,"id":41419629,"name":"7 - 3"},{"status":"ACTIVE","sortPriority":46,"id":41419630,"name":"7 - 4"},{"status":"ACTIVE","sortPriority":47,"id":41419631,"name":"7 - 5"},{"status":"ACTIVE","sortPriority":48,"id":41419632,"name":"7 - 6"},{"status":"ACTIVE","sortPriority":49,"id":41419633,"name":"7 - 8"},{"status":"ACTIVE","sortPriority":50,"id":41419634,"name":"8 - 1"},{"status":"ACTIVE","sortPriority":51,"id":41419635,"name":"8 - 2"},{"status":"ACTIVE","sortPriority":52,"id":41419636,"name":"8 - 3"},{"status":"ACTIVE","sortPriority":53,"id":41419637,"name":"8 - 4"},{"status":"ACTIVE","sortPriority":54,"id":41419638,"name":"8 - 5"},{"status":"ACTIVE","sortPriority":55,"id":41419639,"name":"8 - 6"},{"status":"ACTIVE","sortPriority":56,"id":41419640,"name":"8 - 7"}],"regulators":["MR_INT"],"venue":"Rockhampton","countryCode":"AU","discountAllowed":true,"timezone":"Australia/Queensland","openDate":"2022-03-02T08:28:00.000Z","version":4382601914,"name":"Exacta","eventName":"Rockhampton (AUS) 2nd Mar"},"rc":[{"atb":[[16.5,12.9],[11.5,25.4],[28,7.41]],"id":41419609},{"atb":[[18,15.69],[26,8],[55,3.7]],"id":41419638},{"atb":[[18.5,15.24],[27,7.69],[60,3.38]],"id":41419605},{"atb":[[65,3.12],[19,14.82],[28,7.41]],"id":41419634},{"atb":[[40,5.13],[20,10.52],[15,19.05]],"id":41419617},{"atb":[[280,0.71],[180,1.49],[430,0.46]],"id":41419613},{"atb":[[270,0.74],[170,1.57],[420,0.47]],"id":41419593},{"atb":[[17.5,12.12],[12.5,23.19],[30,6.89]],"id":41419622},{"atb":[[42,4.87],[21,10],[15.5,18.4]],"id":41419589},{"atb":[[42,4.87],[21,10],[15.5,18.4]],"id":41419618},{"atb":[[32,6.45],[18,11.76],[13,22.23]],"id":41419601},{"atb":[[4.9,68.41],[8.8,25.65],[5.9,40.84]],"id":41419630},{"atb":[[16.5,17.21],[46,4.44],[23,9.09]],"id":41419597},{"atb":[[16,13.34],[7.4,41.69],[9.4,23.82]],"id":41419626},{"atb":[[8,38.11],[17.5,12.12],[10,22.23]],"id":41419639},{"atb":[[17.5,12.12],[12.5,23.19],[30,6.89]],"id":41419606},{"atb":[[70,2.89],[19.5,14.42],[29,7.14]],"id":41419635},{"atb":[[330,0.6],[180,1.11],[90,2.99]],"id":41419602},{"atb":[[540,0.37],[290,0.92],[390,0.51]],"id":41419585},{"atb":[[310,0.64],[210,1.27],[460,0.43]],"id":41419614},{"atb":[[4.4,78.47],[7.8,29.42],[5.4,45.48]],"id":41419610},{"atb":[[8,28.58],[4.5,76.23],[5.5,44.47]],"id":41419623},{"atb":[[16,17.78],[44,4.65],[22,9.53]],"id":41419590},{"atb":[[65,3.12],[19,14.82],[28,7.41]],"id":41419619},{"atb":[[140,1.92],[390,0.51],[240,0.83]],"id":41419586},{"atb":[[36,5.71],[19,11.11],[14,20.52]],"id":41419631},{"atb":[[32,6.45],[80,2.53],[21,13.34]],"id":41419598},{"atb":[[40,5.13],[20,10.52],[15,19.05]],"id":41419627},{"atb":[[40,5.13],[20,10.52],[15,19.05]],"id":41419594},{"atb":[[18.5,11.43],[11,20.01],[8.4,36.05]],"id":41419640},{"atb":[[32,6.45],[18,11.76],[13,22.23]],"id":41419607},{"atb":[[17.5,16.16],[50,4.08],[25,8.33]],"id":41419636},{"atb":[[36,5.71],[19,11.11],[14,20.52]],"id":41419603},{"atb":[[330,0.6],[180,1.11],[90,2.99]],"id":41419615},{"atb":[[5.7,42.57],[8.4,27.04],[4.7,72.11]],"id":41419611},{"atb":[[32,6.45],[18,11.76],[13,22.23]],"id":41419624},{"atb":[[75,2.7],[20,14.04],[30,6.89]],"id":41419591},{"atb":[[36,5.71],[19,11.11],[14,20.52]],"id":41419620},{"atb":[[38,5.4],[19.5,10.81],[14.5,19.76]],"id":41419587},{"atb":[[9.6,23.26],[5.3,62.04],[6.6,35.73]],"id":41419632},{"atb":[[140,1.92],[390,0.51],[240,0.83]],"id":41419599},{"atb":[[42,4.87],[21,10],[15.5,18.4]],"id":41419628},{"atb":[[310,0.64],[210,1.27],[460,0.43]],"id":41419595},{"atb":[[16,13.34],[11,26.68],[27,7.69]],"id":41419608},{"atb":[[7.2,43.03],[9.2,24.4],[15.5,13.79]],"id":41419637},{"atb":[[40,5.13],[20,10.52],[15,19.05]],"id":41419604},{"atb":[[34,6.06],[18.5,11.43],[13.5,21.34]],"id":41419616},{"atb":[[6.4,49.41],[13.5,16],[8.4,27.04]],"id":41419612},{"atb":[[6.4,37.05],[5.2,63.52],[9.4,23.82]],"id":41419625},{"atb":[[540,0.37],[290,0.92],[390,0.51]],"id":41419592},{"atb":[[38,5.4],[19.5,10.81],[14.5,19.76]],"id":41419621},{"atb":[[280,0.71],[180,1.49],[430,0.46]],"id":41419588},{"atb":[[8,38.11],[17.5,12.12],[10,22.23]],"id":41419633},{"atb":[[270,0.74],[170,1.57],[420,0.47]],"id":41419600},{"atb":[[34,6.06],[18.5,11.43],[13.5,21.34]],"id":41419629},{"atb":[[16,17.78],[44,4.65],[22,9.53]],"id":41419596}],"con":true,"img":true}]}
{"op":"mcm","clk":"5353031176","pt":1646207220431,"mc":[{"id":"1.195503864","rc":[{"atb":[[16.5,12.9],[11.5,25.4],[23,3.27],[28,10.14]],"id":41419609},{"atb":[[70,2.72],[18,15.69],[48,3.27],[26,8],[55,3.7]],"id":41419638},{"atb":[[18.5,15.24],[85,2.72],[27,7.69],[60,6.66]],"id":41419605},{"atb":[[65,3.12],[70,2.72],[19,14.82],[48,3.27],[28,7.41]],"id":41419634},{"atb":[[40,5.13],[20,10.52],[44,3.27],[15,19.05],[60,2.72]],"id":41419617},{"atb":[[280,0.71],[85,3.27],[180,1.49],[430,0.46],[120,2.72]],"id":41419613},{"atb":[[270,0.74],[140,2.72],[170,1.57],[95,3.27],[420,0.47]],"id":41419593},{"atb":[[32,2.72],[17.5,12.12],[12.5,23.19],[26,3.27],[30,6.89]],"id":41419622},{"atb":[[42,4.87],[21,10],[44,3.27],[60,2.72],[15.5,18.4]],"id":41419589},{"atb":[[42,4.87],[21,10],[44,3.27],[60,2.72],[15.5,18.4]],"id":41419618},{"atb":[[32,6.45],[18,11.76],[42,3.27],[13,22.23],[55,2.72]],"id":41419601},{"atb":[[12,2.72],[4.9,68.41],[9.8,3.27],[8.8,25.65],[5.9,40.84]],"id":41419630},{"atb":[[16.5,17.21],[70,2.72],[46,4.44],[23,9.09],[48,3.27]],"id":41419597},{"atb":[[16,13.34],[18.5,3.27],[22,2.72],[7.4,41.69],[9.4,23.82]],"id":41419626},{"atb":[[8,38.11],[32,2.72],[17.5,12.12],[10,22.23],[26,3.27]],"id":41419639},{"atb":[[17.5,12.12],[20,3.27],[12.5,23.19],[25,2.72],[30,6.89]],"id":41419606},{"atb":[[70,2.89],[19.5,14.42],[29,7.14]],"id":41419635},{"atb":[[330,0.6],[85,3.27],[180,1.11],[90,2.99],[120,2.72]],"id":41419602},{"atb":[[540,0.37],[140,2.72],[290,0.92],[95,3.27],[390,0.51]],"id":41419585},{"atb":[[140,2.72],[310,0.64],[95,3.27],[210,1.27],[460,0.43]],"id":41419614},{"atb":[[9.8,2.72],[4.4,78.47],[8.8,3.27],[7.8,29.42],[5.4,45.48]],"id":41419610},{"atb":[[8,28.58],[4.5,76.23],[5.5,44.47],[11,2.72],[9.4,3.27]],"id":41419623},{"atb":[[16,17.78],[44,7.93],[22,9.53],[60,2.72]],"id":41419590},{"atb":[[65,3.12],[19,14.82],[85,2.72],[28,7.41],[60,3.27]],"id":41419619},{"atb":[[140,1.92],[85,3.27],[390,0.51],[240,0.83],[120,2.72]],"id":41419586},{"atb":[[36,8.44],[19,11.11],[14,20.52],[28,3.27]],"id":41419631},{"atb":[[32,6.45],[75,3.27],[80,2.53],[21,13.34],[100,2.72]],"id":41419598},{"atb":[[36,2.72],[40,5.13],[20,10.52],[28,3.27],[15,19.05]],"id":41419627},{"atb":[[65,2.72],[40,5.13],[20,10.52],[46,3.27],[15,19.05]],"id":41419594},{"atb":[[34,2.72],[18.5,11.43],[11,20.01],[27,3.27],[8.4,36.05]],"id":41419640},{"atb":[[32,9.18],[18,11.76],[13,22.23],[26,3.27]],"id":41419607},{"atb":[[17.5,16.16],[70,2.72],[48,3.27],[50,4.08],[25,8.33]],"id":41419636},{"atb":[[36,5.71],[19,11.11],[44,3.27],[14,20.52],[60,2.72]],"id":41419603},{"atb":[[330,0.6],[85,3.27],[180,1.11],[90,2.99],[120,2.72]],"id":41419615},{"atb":[[9.2,3.27],[10.5,2.72],[5.7,42.57],[8.4,27.04],[4.7,72.11]],"id":41419611},{"atb":[[32,6.45],[34,2.72],[18,11.76],[13,22.23],[27,3.27]],"id":41419624},{"atb":[[65,3.27],[75,2.7],[20,14.04],[90,2.72],[30,6.89]],"id":41419591},{"atb":[[36,5.71],[19,11.11],[23,3.27],[14,20.52],[28,2.72]],"id":41419620},{"atb":[[38,5.4],[19.5,10.81],[42,3.27],[55,2.72],[14.5,19.76]],"id":41419587},{"atb":[[9.6,23.26],[10.5,3.27],[5.3,62.04],[13,2.72],[6.6,35.73]],"id":41419632},{"atb":[[140,1.92],[85,3.27],[390,0.51],[240,0.83],[120,2.72]],"id":41419599},{"atb":[[38,2.72],[42,4.87],[21,10],[29,3.27],[15.5,18.4]],"id":41419628},{"atb":[[140,2.72],[310,0.64],[95,3.27],[210,1.27],[460,0.43]],"id":41419595},{"atb":[[16,13.34],[11,26.68],[22,3.27],[27,10.42]],"id":41419608},{"atb":[[7.2,43.03],[9.2,24.4],[25,3.27],[30,2.72],[15.5,13.79]],"id":41419637},{"atb":[[40,5.13],[20,10.52],[44,3.27],[15,19.05],[60,2.72]],"id":41419604},{"atb":[[34,6.06],[18.5,11.43],[42,3.27],[13.5,21.34],[55,2.72]],"id":41419616},{"atb":[[17.5,2.72],[6.4,49.41],[13.5,16],[8.4,27.04],[15,3.27]],"id":41419612},{"atb":[[6.4,37.05],[10,3.27],[5.2,63.52],[12.5,2.72],[9.4,23.82]],"id":41419625},{"atb":[[540,0.37],[140,2.72],[290,0.92],[95,3.27],[390,0.51]],"id":41419592},{"atb":[[36,2.72],[38,5.4],[19.5,10.81],[28,3.27],[14.5,19.76]],"id":41419621},{"atb":[[280,0.71],[85,3.27],[180,1.49],[430,0.46],[120,2.72]],"id":41419588},{"atb":[[8,38.11],[17.5,12.12],[19,3.27],[10,22.23],[23,2.72]],"id":41419633},{"atb":[[270,0.74],[140,2.72],[170,1.57],[95,3.27],[420,0.47]],"id":41419600},{"atb":[[34,6.06],[18.5,11.43],[36,2.72],[13.5,21.34],[28,3.27]],"id":41419629},{"atb":[[16,17.78],[70,2.72],[44,4.65],[22,9.53],[48,3.27]],"id":41419596}],"con":true,"img":false}]}
{"op":"mcm","clk":"5353031183","pt":1646207220535,"mc":[{"id":"1.195503864","rc":[{"atb":[[75,2.72],[50,3.27]],"id":41419635}],"con":true,"img":false}]}
{"op":"mcm","clk":"5353050919","pt":1646207723515,"mc":[{"id":"1.195503864","rc":[{"atb":[[9.8,0],[8.8,0]],"id":41419610}],"con":true,"img":false}]}
{"op":"mcm","clk":"5353050940","pt":1646207723925,"mc":[{"id":"1.195503864","rc":[{"atb":[[11,0],[9.4,0]],"id":41419623},{"atb":[[9.2,0],[10.5,0]],"id":41419611},{"atb":[[17.5,0],[15,0]],"id":41419612}],"con":true,"img":false}]}
{"op":"mcm","clk":"5353050951","pt":1646207724233,"mc":[{"id":"1.195503864","rc":[{"atb":[[8.4,3.27],[9.4,2.72]],"id":41419610}],"con":true,"img":false}]}
{"op":"mcm","clk":"5353050975","pt":1646207724599,"mc":[{"id":"1.195503864","rc":[{"atb":[[17,2.72],[14.5,3.27]],"id":41419612}],"con":true,"img":false}]}
{"op":"mcm","clk":"5353050980","pt":1646207724703,"mc":[{"id":"1.195503864","rc":[{"atb":[[9.2,3.27],[10.5,2.72]],"id":41419623},{"atb":[[9.8,2.72],[8.8,3.27]],"id":41419611}],"con":true,"img":false}]}
{"op":"mcm","clk":"5353059613","pt":1646207946092,"mc":[{"id":"1.195503864","rc":[{"atb":[[19,0]],"id":41419633}],"con":true,"img":false}]}
{"op":"mcm","clk":"5353059624","pt":1646207946402,"mc":[{"id":"1.195503864","rc":[{"atb":[[23,0]],"id":41419633}],"con":true,"img":false}]}
{"op":"mcm","clk":"5353059640","pt":1646207946809,"mc":[{"id":"1.195503864","rc":[{"atb":[[19.5,3.27]],"id":41419633}],"con":true,"img":false}]}
{"op":"mcm","clk":"5353059658","pt":1646207947121,"mc":[{"id":"1.195503864","rc":[{"atb":[[24,2.72]],"id":41419633}],"con":true,"img":false}]}
{"op":"mcm","clk":"5353059971","pt":1646207955530,"mc":[{"id":"1.195503864","rc":[{"atb":[[20,0],[25,0]],"id":41419606},{"atb":[[23,0],[28,0]],"id":41419620},{"atb":[[22,0],[27,7.69]],"id":41419608}],"con":true,"img":false}]}
{"op":"mcm","clk":"5353060016","pt":1646207956210,"mc":[{"id":"1.195503864","rc":[{"atb":[[21,3.27],[26,2.72]],"id":41419606},{"atb":[[25,3.27],[30,2.72]],"id":41419620},{"atb":[[21,3.27],[26,2.72]],"id":41419608}],"con":true,"img":false}]}
{"op":"mcm","clk":"5353060729","pt":1646207973540,"mc":[{"id":"1.195503864","rc":[{"atb":[[21,0],[26,0]],"id":41419606},{"atb":[[25,0],[30,0]],"id":41419620},{"atb":[[21,0],[26,0]],"id":41419608}],"con":true,"img":false}]}
{"op":"mcm","clk":"5353060752","pt":1646207974256,"mc":[{"id":"1.195503864","rc":[{"atb":[[20,3.27],[25,2.72]],"id":41419606},{"atb":[[23,3.27],[28,2.72]],"id":41419620},{"atb":[[22,3.27],[27,10.42]],"id":41419608}],"con":true,"img":false}]}
{"op":"mcm","clk":"5353128266","pt":1646209455311,"mc":[{"id":"1.195503864","rc":[{"atb":[[20,0],[25,0]],"id":41419606},{"atb":[[23,0],[28,0]],"id":41419620},{"atb":[[22,0],[27,7.69]],"id":41419608}],"con":true,"img":false}]}
{"op":"mcm","clk":"5353128307","pt":1646209456031,"mc":[{"id":"1.195503864","rc":[{"atb":[[21,3.27],[26,2.72]],"id":41419608}],"con":true,"img":false}]}
{"op":"mcm","clk":"5353128312","pt":1646209456091,"mc":[{"id":"1.195503864","rc":[{"atb":[[21,3.27],[26,2.72]],"id":41419606},{"atb":[[25,3.27],[30,2.72]],"id":41419620}],"con":true,"img":false}]}
{"op":"mcm","clk":"5353129281","pt":1646209473328,"mc":[{"id":"1.195503864","rc":[{"atb":[[21,0],[26,0]],"id":41419606},{"atb":[[25,0],[30,0]],"id":41419620}],"con":true,"img":false}]}
{"op":"mcm","clk":"5353129330","pt":1646209474149,"mc":[{"id":"1.195503864","rc":[{"atb":[[20,3.27],[25,2.72]],"id":41419606},{"atb":[[23,3.27],[28,2.72]],"id":41419620}],"con":true,"img":false}]}
{"op":"mcm","clk":"5353155772","pt":1646209958172,"mc":[{"id":"1.195503864","rc":[{"atb":[[21,0]],"id":41419608}],"con":true,"img":false}]}
{"op":"mcm","clk":"5353155790","pt":1646209958584,"mc":[{"id":"1.195503864","rc":[{"atb":[[26,0]],"id":41419608}],"con":true,"img":false}]}
{"op":"mcm","clk":"5353155809","pt":1646209958849,"mc":[{"id":"1.195503864","rc":[{"atb":[[22,3.27]],"id":41419608}],"con":true,"img":false}]}
{"op":"mcm","clk":"5353155849","pt":1646209959568,"mc":[{"id":"1.195503864","rc":[{"atb":[[27,10.42]],"id":41419608}],"con":true,"img":false}]}
{"op":"mcm","clk":"5353200755","pt":1646210821555,"mc":[{"id":"1.195503864","rc":[{"atb":[[7,16.67]],"id":41419609},{"atl":[[750,2]],"id":41419609},{"atb":[[27,3.85]],"id":41419638},{"atb":[[26,4]],"id":41419605},{"atb":[[25,4.17]],"id":41419634},{"atl":[[1000,2]],"id":41419634},{"atb":[[22,4.76]],"id":41419617},{"atl":[[1000,2]],"id":41419617},{"atb":[[27,2.98]],"id":41419613},{"atb":[[27,3.16]],"id":41419593},{"atb":[[5.6,13.8]],"id":41419622},{"atl":[[570,2]],"id":41419622},{"atb":[[9.8,9.76]],"id":41419589},{"atl":[[900,2]],"id":41419589},{"atb":[[25,4.17]],"id":41419618},{"atl":[[1000,2]],"id":41419618},{"atb":[[9,12.5]],"id":41419601},{"atl":[[870,2]],"id":41419601},{"atb":[[4,33.33]],"id":41419630},{"atl":[[450,2]],"id":41419630},{"atb":[[25,4.17]],"id":41419597},{"atl":[[1000,2]],"id":41419597},{"atb":[[5.5,22.22]],"id":41419626},{"atl":[[570,2]],"id":41419626},{"atb":[[8.8,12.82]],"id":41419639},{"atl":[[870,2]],"id":41419639},{"atb":[[4.6,13.8]],"id":41419606},{"atl":[[530,2]],"id":41419606},{"atb":[[27,3.85]],"id":41419635},{"atb":[[28,3.7]],"id":41419602},{"atb":[[6.2,2]],"id":41419585},{"atb":[[28,2.56]],"id":41419614},{"atb":[[3.6,38.46]],"id":41419610},{"atl":[[350,2]],"id":41419610},{"atb":[[3.65,37.74]],"id":41419623},{"atl":[[370,2]],"id":41419623},{"atb":[[11.5,9.52]],"id":41419590},{"atl":[[960,2]],"id":41419590},{"atb":[[27,3.85]],"id":41419619},{"atb":[[26,3.84]],"id":41419586},{"atl":[[1000,2]],"id":41419586},{"atb":[[12,9.09]],"id":41419631},{"atl":[[970,2]],"id":41419631},{"atb":[[27,3.85]],"id":41419598},{"atb":[[6.4,10.26]],"id":41419627},{"atl":[[640,2]],"id":41419627},{"atb":[[17.5,6.06]],"id":41419594},{"atl":[[1000,2]],"id":41419594},{"atb":[[10,11.11]],"id":41419640},{"atl":[[900,2]],"id":41419640},{"atb":[[6.8,17.24]],"id":41419607},{"atl":[[720,2]],"id":41419607},{"atb":[[25,12.5]],"id":41419636},{"atl":[[1000,2]],"id":41419636},{"atb":[[10.5,10.53]],"id":41419603},{"atl":[[930,2]],"id":41419603},{"atb":[[27,3.85]],"id":41419615},{"atb":[[3.7,37.04]],"id":41419611},{"atl":[[390,2]],"id":41419611},{"atb":[[7.4,12.92]],"id":41419624},{"atl":[[820,2]],"id":41419624},{"atb":[[26,4]],"id":41419591},{"atb":[[5.1,11.44]],"id":41419620},{"atl":[[550,2]],"id":41419620},{"atb":[[8.8,10.82]],"id":41419587},{"atl":[[870,2]],"id":41419587},{"atb":[[4.1,32.26]],"id":41419632},{"atl":[[470,2]],"id":41419632},{"atb":[[25,3.84]],"id":41419599},{"atl":[[1000,2]],"id":41419599},{"atb":[[11.5,9.52]],"id":41419628},{"atl":[[950,2]],"id":41419628},{"atb":[[28,2.56]],"id":41419595},{"atb":[[4.9,23.77]],"id":41419608},{"atl":[[540,2]],"id":41419608},{"atb":[[8.2,13.89]],"id":41419637},{"atl":[[840,2]],"id":41419637},{"atb":[[12,9.09]],"id":41419604},{"atl":[[970,2]],"id":41419604},{"atb":[[19,5.56]],"id":41419616},{"atl":[[1000,2]],"id":41419616},{"atb":[[5.1,24.39]],"id":41419612},{"atl":[[550,2]],"id":41419612},{"atb":[[3.85,35.09]],"id":41419625},{"atl":[[420,2]],"id":41419625},{"atb":[[27,2]],"id":41419592},{"atb":[[7.4,10.82]],"id":41419621},{"atl":[[820,2]],"id":41419621},{"atb":[[28,2.98]],"id":41419588},{"atb":[[6.4,18.52]],"id":41419633},{"atl":[[660,2]],"id":41419633},{"atb":[[27,3.16]],"id":41419600},{"atb":[[6.6,12.12]],"id":41419629},{"atl":[[670,2]],"id":41419629},{"atb":[[23,4.55]],"id":41419596},{"atl":[[1000,2]],"id":41419596}],"con":true,"img":false}]}
{"op":"mcm","clk":"5353202437","pt":1646210857018,"mc":[{"id":"1.195503864","rc":[{"atl":[[1000,0]],"id":41419586}],"con":true,"img":false}]}
{"op":"mcm","clk":"5353202458","pt":1646210857325,"mc":[{"id":"1.195503864","rc":[{"atb":[[20,0],[25,0]],"id":41419606},{"atb":[[23,0],[28,0]],"id":41419620},{"atb":[[22,0],[27,7.69]],"id":41419608}],"con":true,"img":false}]}
{"op":"mcm","clk":"5353202490","pt":1646210857995,"mc":[{"id":"1.195503864","rc":[{"atb":[[21,3.27],[26,2.72]],"id":41419606},{"atb":[[21,3.27],[26,2.72]],"id":41419608}],"con":true,"img":false}]}
{"op":"mcm","clk":"5353202498","pt":1646210858098,"mc":[{"id":"1.195503864","rc":[{"atb":[[25,3.27],[30,2.72]],"id":41419620}],"con":true,"img":false}]}
{"op":"mcm","clk":"5353202532","pt":1646210858714,"mc":[{"id":"1.195503864","rc":[{"atl":[[700,2],[750,0]],"id":41419609},{"atl":[[570,0],[560,2]],"id":41419622},{"atb":[[9.8,0],[12.5,8.7]],"id":41419589},{"atb":[[9,0],[10,11.11]],"id":41419601},{"atl":[[840,2],[870,0]],"id":41419601},{"atl":[[440,2],[450,0]],"id":41419630},{"atl":[[570,0],[550,2]],"id":41419626},{"atl":[[820,2],[870,0]],"id":41419639},{"atb":[[5.1,13.8],[4.6,0]],"id":41419606},{"atl":[[530,0],[520,2]],"id":41419606},{"atl":[[320,2],[350,0]],"id":41419610},{"atl":[[340,2],[370,0]],"id":41419623},{"atb":[[16.5,6.45],[11.5,0]],"id":41419590},{"atl":[[930,2],[970,0]],"id":41419631},{"atl":[[860,2],[900,0]],"id":41419640},{"atl":[[670,2],[720,0]],"id":41419607},{"atl":[[890,2],[930,0]],"id":41419603},{"atl":[[360,2],[390,0]],"id":41419611},{"atl":[[760,2]],"id":41419624},{"atb":[[5.1,0],[5.7,11.44]],"id":41419620},{"atl":[[540,2],[550,0]],"id":41419620},{"atb":[[11,10],[8.8,0]],"id":41419587},{"atl":[[460,2],[470,0]],"id":41419632},{"atl":[[920,2],[950,0]],"id":41419628},{"atl":[[540,0],[530,2]],"id":41419608},{"atl":[[800,2],[840,0]],"id":41419637},{"atb":[[12,0],[14.5,7.41]],"id":41419604},{"atl":[[940,2],[970,0]],"id":41419604},{"atl":[[530,2],[550,0]],"id":41419612},{"atl":[[410,2],[420,0]],"id":41419625},{"atl":[[760,2],[820,0]],"id":41419621},{"atl":[[660,0],[650,2]],"id":41419633}],"con":true,"img":false}]}
{"op":"mcm","clk":"5353202535","pt":1646210858817,"mc":[{"id":"1.195503864","rc":[{"atl":[[820,0]],"id":41419624}],"con":true,"img":false}]}
{"op":"mcm","clk":"5353203729","pt":1646210883294,"mc":[{"id":"1.195503864","rc":[{"atl":[[700,0],[720,2]],"id":41419609},{"atl":[[860,2],[900,0]],"id":41419589},{"atl":[[550,0],[560,2]],"id":41419626},{"atl":[[820,0],[830,2]],"id":41419639},{"atl":[[320,0],[340,2]],"id":41419610},{"atl":[[340,0],[350,2]],"id":41419623},{"atb":[[16.5,0],[13,8.33]],"id":41419590},{"atl":[[910,2],[960,0]],"id":41419590},{"atl":[[1000,2]],"id":41419586},{"atl":[[920,2],[930,0]],"id":41419631},{"atl":[[620,2],[640,0]],"id":41419627},{"atl":[[670,0],[690,2]],"id":41419607},{"atb":[[3.95,33.9],[3.7,0]],"id":41419611},{"atl":[[360,0],[370,2]],"id":41419611},{"atl":[[1000,2]],"id":41419591},{"atl":[[830,2],[870,0]],"id":41419587},{"atl":[[920,0],[910,2]],"id":41419628},{"atl":[[800,0],[810,2]],"id":41419637},{"atl":[[920,2],[940,0]],"id":41419604},{"atl":[[530,0],[540,2]],"id":41419612},{"atl":[[760,0],[780,2]],"id":41419621},{"atl":[[650,0],[640,2]],"id":41419633},{"atl":[[670,0],[650,2]],"id":41419629}],"con":true,"img":false}]}
{"op":"mcm","clk":"5353203736","pt":1646210883444,"mc":[{"id":"1.195503864","rc":[{"atb":[[21,0],[26,0]],"id":41419606}],"con":true,"img":false}]}
{"op":"mcm","clk":"5353203740","pt":1646210883495,"mc":[{"id":"1.195503864","rc":[{"atb":[[25,0],[30,0]],"id":41419620}],"con":true,"img":false}]}
{"op":"mcm","clk":"5353203743","pt":1646210883652,"mc":[{"id":"1.195503864","rc":[{"atb":[[8.4,0],[9.4,0]],"id":41419610},{"atb":[[36,0],[28,0]],"id":41419627},{"atb":[[9.8,0],[8.8,0]],"id":41419611}],"con":true,"img":false}]}
{"op":"mcm","clk":"5353203772","pt":1646210884223,"mc":[{"id":"1.195503864","rc":[{"atb":[[20,3.27],[25,2.72]],"id":41419606},{"atb":[[23,3.27],[28,2.72]],"id":41419620}],"con":true,"img":false}]}
{"op":"mcm","clk":"5353203777","pt":1646210884328,"mc":[{"id":"1.195503864","rc":[{"atb":[[9.6,2.72],[8.6,3.27]],"id":41419610},{"atb":[[34,2.72],[27,3.27]],"id":41419627},{"atb":[[9,3.27],[10,2.72]],"id":41419611}],"con":true,"img":false}]}
{"op":"mcm","clk":"5353208237","pt":1646211003108,"mc":[{"id":"1.195503864","rc":[{"atb":[[12.5,0],[9.8,11.36]],"id":41419589},{"atl":[[1000,0]],"id":41419591},{"atb":[[5.1,16.84],[5.7,0]],"id":41419620},{"atb":[[11,0],[8.8,12.82]],"id":41419587}],"con":true,"img":false}]}
{"op":"mcm","clk":"5353216634","pt":1646211219942,"mc":[{"id":"1.195503864","rc":[{"atb":[[26,0]],"id":41419608}],"con":true,"img":false}]}
{"op":"mcm","clk":"5353216653","pt":1646211220361,"mc":[{"id":"1.195503864","rc":[{"atb":[[21,0]],"id":41419608}],"con":true,"img":false}]}
{"op":"mcm","clk":"5353216665","pt":1646211220673,"mc":[{"id":"1.195503864","rc":[{"atb":[[27,10.42]],"id":41419608}],"con":true,"img":false}]}
{"op":"mcm","clk":"5353216697","pt":1646211221376,"mc":[{"id":"1.195503864","rc":[{"atb":[[22,3.27]],"id":41419608}],"con":true,"img":false}]}
{"op":"mcm","clk":"5353217746","pt":1646211248222,"mc":[{"id":"1.195503864","rc":[{"atb":[[34,0],[27,0]],"id":41419627}],"con":true,"img":false}]}
{"op":"mcm","clk":"5353217757","pt":1646211248624,"mc":[{"id":"1.195503864","rc":[{"atb":[[9.6,0],[8.6,0]],"id":41419610}],"con":true,"img":false}]}
{"op":"mcm","clk":"5353217766","pt":1646211248887,"mc":[{"id":"1.195503864","rc":[{"atb":[[36,2.72],[28,3.27]],"id":41419627}],"con":true,"img":false}]}
{"op":"mcm","clk":"5353217781","pt":1646211249300,"mc":[{"id":"1.195503864","rc":[{"atb":[[8.4,3.27],[9.4,2.72]],"id":41419610}],"con":true,"img":false}]}
{"op":"mcm","clk":"5353225464","pt":1646211423895,"mc":[{"id":"1.195503864","rc":[{"atb":[[36,0],[28,0]],"id":41419627}],"con":true,"img":false}]}
{"op":"mcm","clk":"5353225504","pt":1646211424572,"mc":[{"id":"1.195503864","rc":[{"atb":[[34,2.72],[27,3.27]],"id":41419627}],"con":true,"img":false}]}
{"op":"mcm","clk":"5353232843","pt":1646211572046,"mc":[{"id":"1.195503864","rc":[{"atb":[[9.4,0]],"id":41419610}],"con":true,"img":false}]}
{"op":"mcm","clk":"5353232850","pt":1646211572148,"mc":[{"id":"1.195503864","rc":[{"atb":[[8.4,0]],"id":41419610}],"con":true,"img":false}]}
{"op":"mcm","clk":"5353232879","pt":1646211572716,"mc":[{"id":"1.195503864","rc":[{"atb":[[9.6,2.72]],"id":41419610}],"con":true,"img":false}]}
{"op":"mcm","clk":"5353232893","pt":1646211573028,"mc":[{"id":"1.195503864","rc":[{"atb":[[8.6,3.27]],"id":41419610}],"con":true,"img":false}]}
{"op":"mcm","clk":"5353234316","pt":1646211600803,"mc":[{"id":"1.195503864","rc":[{"atb":[[9.6,0],[8.6,0]],"id":41419610}],"con":true,"img":false}]}
{"op":"mcm","clk":"5353234409","pt":1646211601598,"mc":[{"id":"1.195503864","rc":[{"atb":[[8.4,3.27],[9.4,2.72]],"id":41419610}],"con":true,"img":false}]}
{"op":"mcm","clk":"5353242226","pt":1646211730000,"mc":[{"id":"1.195503864","rc":[{"atb":[[16.5,12.88],[23,3.26],[11.5,25.36],[28,10.12]],"id":41419609},{"atb":[[70,2.72],[18,15.66],[48,3.26],[26,7.98],[55,3.7]],"id":41419638},{"atb":[[18.5,15.22],[85,2.72],[27,7.68],[60,6.65]],"id":41419605},{"atb":[[65,3.12],[70,2.72],[19,14.8],[48,3.26],[28,7.4]],"id":41419634},{"atb":[[40,5.12],[20,10.51],[44,3.26],[60,2.72],[15,19.02]],"id":41419617},{"atb":[[280,0.71],[85,3.26],[180,1.48],[430,0.46],[120,2.72]],"id":41419613},{"atb":[[270,0.74],[140,2.72],[170,1.57],[95,3.26],[420,0.47]],"id":41419593},{"atb":[[32,2.72],[17.5,12.1],[12.5,23.16],[26,3.26],[30,6.88]],"id":41419622},{"atb":[[42,4.87],[21,9.98],[44,3.26],[60,2.72],[15.5,18.37]],"id":41419589},{"atb":[[42,4.87],[21,9.98],[44,3.26],[60,2.72],[15.5,18.37]],"id":41419618},{"atb":[[32,6.44],[18,11.74],[42,3.26],[13,22.19],[55,2.72]],"id":41419601},{"atb":[[12,2.72],[9.8,3.26],[4.9,68.3],[8.8,25.61],[5.9,40.77]],"id":41419630},{"atb":[[16.5,17.18],[70,2.72],[46,4.44],[23,9.07],[48,3.26]],"id":41419597},{"atb":[[16,13.31],[18.5,3.26],[22,2.72],[7.4,41.62],[9.4,23.78]],"id":41419626},{"atb":[[32,2.72],[8,38.05],[17.5,12.1],[10,22.19],[26,3.26]],"id":41419639},{"atb":[[17.5,12.1],[20,3.26],[25,2.72],[12.5,23.16],[30,6.88]],"id":41419606},{"atb":[[70,2.89],[75,2.72],[19.5,14.39],[50,3.26],[29,7.13]],"id":41419635},{"atb":[[330,0.6],[85,3.26],[180,1.11],[90,2.99],[120,2.72]],"id":41419602},{"atb":[[540,0.37],[140,2.72],[290,0.92],[95,3.26],[390,0.51]],"id":41419585},{"atb":[[140,2.72],[310,0.64],[95,3.26],[210,1.27],[460,0.43]],"id":41419614},{"atb":[[4.4,78.34],[7.8,29.38],[8.4,3.26],[9.4,2.72],[5.4,45.4]],"id":41419610},{"atb":[[8,28.54],[4.5,76.11],[9.2,3.26],[10.5,2.72],[5.5,44.4]],"id":41419623},{"atb":[[16,17.76],[44,7.91],[22,9.51],[60,2.72]],"id":41419590},{"atb":[[65,3.12],[19,14.8],[85,2.72],[28,7.4],[60,3.26]],"id":41419619},{"atb":[[140,1.91],[85,3.26],[390,0.51],[240,0.83],[120,2.72]],"id":41419586},{"atb":[[36,8.43],[19,11.1],[28,3.26],[14,20.49]],"id":41419631},{"atb":[[32,6.44],[75,3.26],[80,2.52],[21,13.31],[100,2.72]],"id":41419598},{"atb":[[34,0],[40,5.12],[20,10.51],[27,0],[15,19.02]],"id":41419627},{"atb":[[65,2.72],[40,5.12],[20,10.51],[46,3.26],[15,19.02]],"id":41419594},{"atb":[[34,2.72],[18.5,11.41],[11,19.97],[27,3.26],[8.4,35.99]],"id":41419640},{"atb":[[32,9.17],[18,11.74],[26,3.26],[13,22.19]],"id":41419607},{"atb":[[70,2.72],[17.5,16.14],[48,3.26],[50,4.07],[25,12.49]],"id":41419636},{"atb":[[36,5.7],[19,11.1],[44,3.26],[14,20.49],[60,2.72]],"id":41419603},{"atb":[[330,0.6],[85,3.26],[180,1.11],[90,2.99],[120,2.72]],"id":41419615},{"atb":[[9,3.26],[10,2.72],[5.7,42.5],[8.4,26.99],[4.7,71.99]],"id":41419611},{"atb":[[32,6.44],[34,2.72],[18,11.74],[13,22.19],[27,3.26]],"id":41419624},{"atb":[[65,3.26],[75,2.69],[20,14.02],[90,2.72],[30,6.88]],"id":41419591},{"atb":[[36,5.7],[19,11.1],[23,3.26],[28,2.72],[14,20.49]],"id":41419620},{"atb":[[38,5.4],[19.5,10.8],[42,3.26],[55,2.72],[14.5,19.73]],"id":41419587},{"atb":[[9.6,23.23],[10.5,3.26],[5.3,61.94],[13,2.72],[6.6,35.67]],"id":41419632},{"atb":[[140,1.91],[85,3.26],[390,0.51],[240,0.83],[120,2.72]],"id":41419599},{"atb":[[38,2.72],[42,4.87],[21,9.98],[29,3.26],[15.5,18.37]],"id":41419628},{"atb":[[140,2.72],[310,0.64],[95,3.26],[210,1.27],[460,0.43]],"id":41419595},{"atb":[[16,13.31],[22,3.26],[11,26.63],[27,10.4]],"id":41419608},{"atb":[[7.2,42.96],[9.2,24.36],[25,3.26],[30,2.72],[15.5,13.77]],"id":41419637},{"atb":[[40,5.12],[20,10.51],[44,3.26],[60,2.72],[15,19.02]],"id":41419604},{"atb":[[34,6.05],[18.5,11.41],[42,3.26],[55,2.72],[13.5,21.3]],"id":41419616},{"atb":[[17,2.72],[6.4,49.33],[13.5,15.98],[14.5,3.26],[8.4,26.99]],"id":41419612},{"atb":[[6.4,36.99],[10,3.26],[12.5,2.72],[5.2,63.42],[9.4,23.78]],"id":41419625},{"atb":[[540,0.37],[140,2.72],[290,0.92],[95,3.26],[390,0.51]],"id":41419592},{"atb":[[36,2.72],[38,5.4],[19.5,10.8],[28,3.26],[14.5,19.73]],"id":41419621},{"atb":[[280,0.71],[85,3.26],[180,1.48],[430,0.46],[120,2.72]],"id":41419588},{"atb":[[8,38.05],[17.5,12.1],[19.5,3.26],[10,22.19],[24,2.72]],"id":41419633},{"atb":[[270,0.74],[140,2.72],[170,1.57],[95,3.26],[420,0.47]],"id":41419600},{"atb":[[34,6.05],[36,2.72],[18.5,11.41],[13.5,21.3],[28,3.26]],"id":41419629},{"atb":[[16,17.76],[70,2.72],[44,4.64],[22,9.51],[48,3.26]],"id":41419596}],"con":true,"img":false}]}
{"op":"mcm","clk":"5353242292","pt":1646211730774,"mc":[{"id":"1.195503864","rc":[{"atb":[[36,2.72],[28,3.26]],"id":41419627}],"con":true,"img":false}]}
{"op":"mcm","clk":"5353251744","pt":1646211894982,"mc":[{"id":"1.195503864","rc":[{"atb":[[8.4,0],[9.4,0]],"id":41419610}],"con":true,"img":false}]}
{"op":"mcm","clk":"5353251787","pt":1646211895807,"mc":[{"id":"1.195503864","rc":[{"atb":[[9.6,2.72],[8.6,3.26]],"id":41419610}],"con":true,"img":false}]}
{"op":"mcm","clk":"5353251842","pt":1646211896992,"mc":[{"id":"1.195503864","rc":[{"atb":[[36,0],[28,0]],"id":41419627}],"con":true,"img":false}]}
{"op":"mcm","clk":"5353251878","pt":1646211897812,"mc":[{"id":"1.195503864","rc":[{"atb":[[34,2.72],[27,3.26]],"id":41419627}],"con":true,"img":false}]}
{"op":"mcm","clk":"5353255397","pt":1646211954985,"mc":[{"id":"1.195503864","rc":[{"atb":[[9.6,0],[8.6,0]],"id":41419610}],"con":true,"img":false}]}
{"op":"mcm","clk":"5353255451","pt":1646211955708,"mc":[{"id":"1.195503864","rc":[{"atb":[[8.4,3.26],[9.4,2.72]],"id":41419610}],"con":true,"img":false}]}
{"op":"mcm","clk":"5353267564","pt":1646212154764,"mc":[{"id":"1.195503864","rc":[{"atl":[[700,2],[720,0]],"id":41419609},{"atb":[[9.8,0],[12.5,8.7]],"id":41419589},{"atl":[[560,0],[550,2]],"id":41419626},{"atl":[[830,0],[820,2]],"id":41419639},{"atl":[[320,2],[340,0]],"id":41419610},{"atl":[[350,0],[340,2]],"id":41419623},{"atb":[[16.5,6.45],[13,0]],"id":41419590},{"atl":[[1000,0]],"id":41419586},{"atl":[[670,2],[690,0]],"id":41419607},{"atl":[[360,2],[370,0]],"id":41419611},{"atb":[[5.1,0],[5.7,16.84]],"id":41419620},{"atb":[[11,10],[8.8,0]],"id":41419587},{"atl":[[810,0],[800,2]],"id":41419637},{"atl":[[540,0],[530,2]],"id":41419612},{"atl":[[760,2],[780,0]],"id":41419621}],"con":true,"img":false}]}
{"op":"mcm","clk":"5353267593","pt":1646212155275,"mc":[{"id":"1.195503864","rc":[{"atb":[[20,0],[25,0]],"id":41419606},{"atb":[[23,0],[28,0]],"id":41419620},{"atb":[[22,0],[27,7.68]],"id":41419608}],"con":true,"img":false}]}
{"op":"mcm","clk":"5353267634","pt":1646212155894,"mc":[{"id":"1.195503864","rc":[{"atb":[[34,0],[27,0]],"id":41419627}],"con":true,"img":false}]}
{"op":"mcm","clk":"5353267643","pt":1646212155994,"mc":[{"id":"1.195503864","rc":[{"atb":[[21,3.26],[26,2.72]],"id":41419606},{"atb":[[25,3.26],[30,2.72]],"id":41419620}],"con":true,"img":false}]}
{"op":"mcm","clk":"5353267646","pt":1646212156046,"mc":[{"id":"1.195503864","rc":[{"atb":[[21,3.26],[26,2.72]],"id":41419608}],"con":true,"img":false}]}
{"op":"mcm","clk":"5353267681","pt":1646212156671,"mc":[{"id":"1.195503864","rc":[{"atb":[[36,2.72],[28,3.26]],"id":41419627}],"con":true,"img":false}]}
{"op":"mcm","clk":"5353268532","pt":1646212172996,"mc":[{"id":"1.195503864","rc":[{"atl":[[700,0]],"id":41419609},{"atl":[[550,0],[560,2]],"id":41419626},{"atl":[[820,0]],"id":41419639},{"atl":[[320,0]],"id":41419610},{"atl":[[350,2]],"id":41419623},{"atl":[[540,2]],"id":41419612}],"con":true,"img":false}]}
{"op":"mcm","clk":"5353268540","pt":1646212173099,"mc":[{"id":"1.195503864","rc":[{"atl":[[720,2]],"id":41419609},{"atl":[[830,2]],"id":41419639},{"atl":[[340,2]],"id":41419610},{"atl":[[340,0]],"id":41419623},{"atb":[[16.5,0],[13,8.33]],"id":41419590},{"atl":[[1000,2]],"id":41419586},{"atl":[[670,0],[690,2]],"id":41419607},{"atl":[[360,0],[370,2]],"id":41419611},{"atl":[[1000,2]],"id":41419591},{"atl":[[800,0],[810,2]],"id":41419637},{"atl":[[530,0]],"id":41419612},{"atl":[[760,0],[780,2]],"id":41419621}],"con":true,"img":false}]}
{"op":"mcm","clk":"5353268558","pt":1646212173510,"mc":[{"id":"1.195503864","rc":[{"atb":[[21,0],[26,0]],"id":41419606},{"atb":[[25,0],[30,0]],"id":41419620}],"con":true,"img":false}]}
{"op":"mcm","clk":"5353268598","pt":1646212174326,"mc":[{"id":"1.195503864","rc":[{"atb":[[20,3.26],[25,2.72]],"id":41419606},{"atb":[[23,3.26],[28,2.72]],"id":41419620}],"con":true,"img":false}]}
{"op":"mcm","clk":"5353275238","pt":1646212292993,"mc":[{"id":"1.195503864","rc":[{"atl":[[1000,0]],"id":41419591},{"atb":[[5.1,16.81]],"id":41419620}],"con":true,"img":false}]}
{"op":"mcm","clk":"5353275245","pt":1646212293096,"mc":[{"id":"1.195503864","rc":[{"atb":[[12.5,0],[9.8,11.36]],"id":41419589},{"atb":[[5.7,0]],"id":41419620},{"atb":[[11,0],[8.8,12.82]],"id":41419587}],"con":true,"img":false}]}
{"op":"mcm","clk":"5353277495","pt":1646212331074,"mc":[{"id":"1.195503864","rc":[{"atb":[[8.4,0],[9.4,0]],"id":41419610}],"con":true,"img":false}]}
{"op":"mcm","clk":"5353277534","pt":1646212331796,"mc":[{"id":"1.195503864","rc":[{"atb":[[9.6,2.72],[8.6,3.26]],"id":41419610}],"con":true,"img":false}]}
{"op":"mcm","clk":"5353280948","pt":1646212388284,"mc":[{"id":"1.195503864","rc":[{"atb":[[21,0]],"id":41419608}],"con":true,"img":false}]}
{"op":"mcm","clk":"5353280965","pt":1646212388591,"mc":[{"id":"1.195503864","rc":[{"atb":[[26,0]],"id":41419608}],"con":true,"img":false}]}
{"op":"mcm","clk":"5353280986","pt":1646212388951,"mc":[{"id":"1.195503864","rc":[{"atb":[[22,3.26]],"id":41419608}],"con":true,"img":false}]}
{"op":"mcm","clk":"5353281013","pt":1646212389262,"mc":[{"id":"1.195503864","rc":[{"atb":[[27,10.4]],"id":41419608}],"con":true,"img":false}]}
{"op":"mcm","clk":"5353283684","pt":1646212434250,"mc":[{"id":"1.195503864","rc":[{"atb":[[9.6,0],[8.6,0]],"id":41419610}],"con":true,"img":false}]}
{"op":"mcm","clk":"5353283722","pt":1646212434926,"mc":[{"id":"1.195503864","rc":[{"atb":[[8.4,3.26],[9.4,2.72]],"id":41419610}],"con":true,"img":false}]}
{"op":"mcm","clk":"5353302532","pt":1646212622993,"mc":[{"id":"1.195503864","rc":[{"atb":[[5.5,0],[6,20]],"id":41419626},{"atb":[[10,33.3],[8.8,0]],"id":41419639},{"atl":[[330,2],[340,0]],"id":41419610},{"atl":[[360,2],[370,0]],"id":41419611},{"atl":[[540,0],[530,2]],"id":41419620},{"atl":[[460,0],[450,2]],"id":41419632},{"atl":[[910,0],[900,2]],"id":41419628},{"atb":[[9.2,36.56],[8.2,0]],"id":41419637}],"con":true,"img":false}]}
{"op":"mcm","clk":"5353305281","pt":1646212673780,"mc":[{"id":"1.195503864","rc":[{"atb":[[8.4,0],[9.4,0]],"id":41419610}],"con":true,"img":false}]}
{"op":"mcm","clk":"5353305303","pt":1646212674092,"mc":[{"id":"1.195503864","rc":[{"atb":[[9.2,0],[10.5,0]],"id":41419623},{"atb":[[36,0],[28,0]],"id":41419627},{"atb":[[10.5,0],[13,0]],"id":41419632},{"atb":[[10,0],[12.5,0]],"id":41419625}],"con":true,"img":false}]}
{"op":"mcm","clk":"5353305333","pt":1646212674506,"mc":[{"id":"1.195503864","rc":[{"atb":[[9.6,2.72],[8.6,3.26]],"id":41419610}],"con":true,"img":false}]}
{"op":"mcm","clk":"5353305349","pt":1646212674817,"mc":[{"id":"1.195503864","rc":[{"atb":[[11,2.72],[9.4,3.26]],"id":41419623},{"atb":[[34,2.72],[27,3.26]],"id":41419627},{"atb":[[11,3.26],[13.5,2.72]],"id":41419632},{"atb":[[10.5,3.26],[13,2.72]],"id":41419625}],"con":true,"img":false}]}
{"op":"mcm","clk":"5353305808","pt":1646212683601,"mc":[{"id":"1.195503864","rc":[{"atb":[[12,0],[9.8,0]],"id":41419630}],"con":true,"img":false}]}
{"op":"mcm","clk":"5353305849","pt":1646212684320,"mc":[{"id":"1.195503864","rc":[{"atb":[[9.6,3.26],[11.5,2.72]],"id":41419630}],"con":true,"img":false}]}
{"op":"mcm","clk":"5353309240","pt":1646212743100,"mc":[{"id":"1.195503864","rc":[{"atl":[[1000,0]],"id":41419636},{"atl":[[360,0],[370,2]],"id":41419611},{"atl":[[530,0],[540,2]],"id":41419620},{"atl":[[900,0],[910,2]],"id":41419628}],"con":true,"img":false}]}
{"op":"mcm","clk":"5353337154","pt":1646213223945,"mc":[{"id":"1.195503864","rc":[{"atb":[[27,0]],"id":41419619},{"atb":[[19,0]],"id":41419616},{"atl":[[1000,0]],"id":41419616},{"atb":[[28,0]],"id":41419588}],"con":true,"img":false}]}
{"op":"mcm","clk":"5353337157","pt":1646213224052,"mc":[{"id":"1.195503864","rc":[{"atb":[[27,0]],"id":41419638},{"atb":[[10,0]],"id":41419601},{"atl":[[840,0]],"id":41419601},{"atb":[[13,0]],"id":41419590},{"atl":[[910,0]],"id":41419590},{"atb":[[27,0]],"id":41419598},{"atb":[[10,0]],"id":41419640},{"atl":[[860,0]],"id":41419640},{"atb":[[26,0]],"id":41419591},{"atb":[[25,0]],"id":41419599},{"atl":[[1000,0]],"id":41419599},{"atb":[[11.5,0]],"id":41419628},{"atl":[[910,0]],"id":41419628},{"atb":[[28,0]],"id":41419595},{"atb":[[3.85,0]],"id":41419625},{"atl":[[410,0]],"id":41419625},{"atb":[[6.6,0]],"id":41419629},{"atl":[[650,0]],"id":41419629}],"con":true,"img":false}]}
{"op":"mcm","clk":"5353337164","pt":1646213224153,"mc":[{"id":"1.195503864","rc":[{"atb":[[25,0]],"id":41419634},{"atl":[[1000,0]],"id":41419634},{"atb":[[6,0]],"id":41419626},{"atl":[[560,0]],"id":41419626},{"atb":[[5.1,0]],"id":41419606},{"atl":[[520,0]],"id":41419606},{"atb":[[27,0]],"id":41419635},{"atb":[[3.6,0]],"id":41419610},{"atl":[[330,0]],"id":41419610},{"atb":[[6.4,0]],"id":41419627},{"atl":[[620,0]],"id":41419627},{"atb":[[7.4,0]],"id":41419624},{"atl":[[760,0]],"id":41419624},{"atb":[[5.1,0]],"id":41419612},{"atl":[[540,0]],"id":41419612},{"atb":[[23,0]],"id":41419596},{"atl":[[1000,0]],"id":41419596}],"con":true,"img":false}]}
{"op":"mcm","clk":"5353337173","pt":1646213224263,"mc":[{"id":"1.195503864","rc":[{"atb":[[9.8,0]],"id":41419589},{"atl":[[860,0]],"id":41419589},{"atb":[[25,0]],"id":41419618},{"atl":[[1000,0]],"id":41419618},{"atb":[[10,22.19]],"id":41419639},{"atl":[[830,0]],"id":41419639},{"atb":[[6.2,0]],"id":41419585},{"atb":[[28,0]],"id":41419614},{"atb":[[3.65,0]],"id":41419623},{"atl":[[350,0]],"id":41419623},{"atb":[[75,0],[100,0]],"id":41419598},{"atb":[[34,0],[27,0]],"id":41419640},{"atb":[[6.8,0]],"id":41419607},{"atl":[[690,0]],"id":41419607},{"atb":[[25,8.32]],"id":41419636},{"atb":[[10.5,0]],"id":41419603},{"atl":[[890,0]],"id":41419603},{"atb":[[65,0],[85,2.72],[90,0],[60,3.26]],"id":41419591},{"atb":[[4.1,0]],"id":41419632},{"atl":[[450,0]],"id":41419632},{"atb":[[36,0],[28,0]],"id":41419629}],"con":true,"img":false}]}
{"op":"mcm","clk":"5353337179","pt":1646213224362,"mc":[{"id":"1.195503864","rc":[{"atb":[[70,0],[48,0]],"id":41419638},{"atb":[[70,0],[48,0]],"id":41419634},{"atb":[[42,0],[55,0]],"id":41419601},{"atb":[[4,0]],"id":41419630},{"atl":[[440,0]],"id":41419630},{"atb":[[25,0]],"id":41419597},{"atl":[[1000,0]],"id":41419597},{"atb":[[18.5,0],[22,0]],"id":41419626},{"atb":[[44,4.64],[60,0]],"id":41419590},{"atb":[[34,0],[27,0]],"id":41419627},{"atb":[[27,0]],"id":41419615},{"atb":[[85,0],[120,0]],"id":41419599},{"atb":[[38,0],[29,0]],"id":41419628},{"atb":[[140,0],[95,0]],"id":41419595},{"atb":[[4.9,0]],"id":41419608},{"atl":[[530,0]],"id":41419608},{"atb":[[9.2,24.36]],"id":41419637},{"atl":[[810,0]],"id":41419637},{"atb":[[10.5,0],[13,0]],"id":41419625},{"atb":[[70,0],[48,0]],"id":41419596}],"con":true,"img":false}]}
{"op":"mcm","clk":"5353337184","pt":1646213224468,"mc":[{"id":"1.195503864","rc":[{"atb":[[7,0]],"id":41419609},{"atl":[[720,0]],"id":41419609},{"atb":[[22,0]],"id":41419617},{"atl":[[1000,0]],"id":41419617},{"atb":[[44,0],[60,0]],"id":41419618},{"atb":[[75,0],[50,0]],"id":41419635},{"atb":[[28,0]],"id":41419602},{"atb":[[130,2.72],[140,0],[90,3.26],[95,0]],"id":41419585},{"atb":[[11,0],[9.4,0]],"id":41419623},{"atb":[[32,6.44],[26,0]],"id":41419607},{"atb":[[44,0],[60,0]],"id":41419603},{"atb":[[3.95,0]],"id":41419611},{"atl":[[370,0]],"id":41419611},{"atb":[[34,0],[27,0]],"id":41419624},{"atb":[[8.8,0]],"id":41419587},{"atl":[[830,0]],"id":41419587},{"atb":[[17,0],[14.5,0]],"id":41419612},{"atb":[[27,0]],"id":41419592},{"atb":[[7.4,0]],"id":41419621},{"atl":[[780,0]],"id":41419621},{"atb":[[6.4,0]],"id":41419633},{"atl":[[640,0]],"id":41419633},{"atb":[[27,0]],"id":41419600}],"con":true,"img":false}]}
{"op":"mcm","clk":"5353337189","pt":1646213224574,"mc":[{"id":"1.195503864","rc":[{"atb":[[26,0]],"id":41419605},{"atb":[[42,8.14],[44,0],[55,2.72],[60,0]],"id":41419589},{"atb":[[130,2.72],[140,0],[90,3.26],[95,0]],"id":41419614},{"atb":[[70,0],[48,0]],"id":41419636},{"atb":[[11,0],[13.5,0]],"id":41419632},{"atb":[[25,0],[30,0]],"id":41419637},{"atb":[[14.5,0]],"id":41419604},{"atl":[[920,0]],"id":41419604}],"con":true,"img":false}]}
{"op":"mcm","clk":"5353337194","pt":1646213224678,"mc":[{"id":"1.195503864","rc":[{"atb":[[27,0]],"id":41419613},{"atb":[[27,0]],"id":41419593},{"atb":[[9.6,0],[11.5,0]],"id":41419630},{"atb":[[70,0],[48,0]],"id":41419597},{"atb":[[17.5,0]],"id":41419594},{"atl":[[1000,0]],"id":41419594},{"atb":[[85,0],[120,0]],"id":41419615},{"atb":[[22,0],[27,7.68]],"id":41419608}],"con":true,"img":false}]}
{"op":"mcm","clk":"5353337200","pt":1646213224783,"mc":[{"id":"1.195503864","rc":[{"atb":[[44,0],[60,0]],"id":41419617},{"atb":[[5.6,0]],"id":41419622},{"atl":[[560,0]],"id":41419622},{"atb":[[26,0]],"id":41419586},{"atl":[[1000,0]],"id":41419586},{"atb":[[12,0]],"id":41419631},{"atl":[[920,0]],"id":41419631},{"atb":[[5.1,0]],"id":41419620},{"atl":[[540,0]],"id":41419620},{"atb":[[130,2.72],[140,0],[90,3.26],[95,0]],"id":41419600}],"con":true,"img":false}]}
{"op":"mcm","clk":"5353337206","pt":1646213224886,"mc":[{"id":"1.195503864","rc":[{"atb":[[44,0],[60,0]],"id":41419604}],"con":true,"img":false}]}
{"op":"mcm","clk":"5353337211","pt":1646213224989,"mc":[{"id":"1.195503864","rc":[{"atb":[[85,0],[120,0]],"id":41419613},{"atb":[[75,3.26],[100,2.72]],"id":41419598},{"atb":[[65,0],[46,0]],"id":41419594},{"atb":[[34,2.72],[27,3.26]],"id":41419640},{"atb":[[36,2.72],[28,3.26]],"id":41419629}],"con":true,"img":false}]}
{"op":"mcm","clk":"5353337218","pt":1646213225093,"mc":[{"id":"1.195503864","rc":[{"atb":[[70,2.72],[48,3.26]],"id":41419638},{"atb":[[70,2.72],[48,3.26]],"id":41419634},{"atb":[[32,0],[26,0]],"id":41419622},{"atb":[[42,3.26],[55,2.72]],"id":41419601},{"atb":[[18.5,3.26],[22,2.72]],"id":41419626},{"atb":[[44,7.91],[60,2.72]],"id":41419590},{"atb":[[85,0],[120,0]],"id":41419586},{"atb":[[36,5.7],[28,0]],"id":41419631},{"atb":[[34,2.72],[27,3.26]],"id":41419627},{"atb":[[85,3.26],[120,2.72]],"id":41419599},{"atb":[[38,2.72],[29,3.26]],"id":41419628},{"atb":[[140,2.72],[95,3.26]],"id":41419595},{"atb":[[10.5,3.26],[13,2.72]],"id":41419625},{"atb":[[70,2.72],[48,3.26]],"id":41419596}],"con":true,"img":false}]}
{"op":"mcm","clk":"5353337225","pt":1646213225199,"mc":[{"id":"1.195503864","rc":[{"atb":[[44,3.26],[60,2.72]],"id":41419618},{"atb":[[75,2.72],[50,3.26]],"id":41419635},{"atb":[[11,2.72],[9.4,3.26]],"id":41419623},{"atb":[[32,9.17],[26,3.26]],"id":41419607},{"atb":[[34,2.72],[27,3.26]],"id":41419624},{"atb":[[17,2.72],[14.5,3.26]],"id":41419612}],"con":true,"img":false}]}
{"op":"mcm","clk":"5353337230","pt":1646213225300,"mc":[{"id":"1.195503864","rc":[{"atb":[[70,2.72],[48,3.26]],"id":41419636},{"atb":[[44,3.26],[60,2.72]],"id":41419603},{"atb":[[11,3.26],[13.5,2.72]],"id":41419632},{"atb":[[25,3.26],[30,2.72]],"id":41419637}],"con":true,"img":false}]}
{"op":"mcm","clk":"5353337234","pt":1646213225408,"mc":[{"id":"1.195503864","rc":[{"atb":[[70,2.72],[48,3.26]],"id":41419597}],"con":true,"img":false}]}
{"op":"mcm","clk":"5353337242","pt":1646213225460,"mc":[{"id":"1.195503864","rc":[{"atb":[[44,3.26],[60,2.72]],"id":41419617},{"atb":[[9.6,3.26],[11.5,2.72]],"id":41419630},{"atb":[[85,3.26],[120,2.72]],"id":41419615},{"atb":[[22,3.26],[27,10.4]],"id":41419608}],"con":true,"img":false}]}
{"op":"mcm","clk":"5353337247","pt":1646213225565,"mc":[{"id":"1.195503864","rc":[{"atb":[[44,3.26],[60,2.72]],"id":41419604}],"con":true,"img":false}]}
{"op":"mcm","clk":"5353337252","pt":1646213225666,"mc":[{"id":"1.195503864","rc":[{"atb":[[85,3.26],[120,2.72]],"id":41419613},{"atb":[[65,2.72],[46,3.26]],"id":41419594}],"con":true,"img":false}]}
{"op":"mcm","clk":"5353337258","pt":1646213225769,"mc":[{"id":"1.195503864","rc":[{"atb":[[32,2.72],[26,3.26]],"id":41419622},{"atb":[[85,3.26],[120,2.72]],"id":41419586},{"atb":[[36,8.43],[28,3.26]],"id":41419631}],"con":true,"img":false}]}
{"op":"mcm","clk":"5353343515","pt":1646213349926,"mc":[{"id":"1.195503864","rc":[{"atb":[[42,4.87],[55,0]],"id":41419589}],"con":true,"img":false}]}
{"op":"mcm","clk":"5353343534","pt":1646213350340,"mc":[{"id":"1.195503864","rc":[{"atb":[[34,0],[27,0]],"id":41419627}],"con":true,"img":false}]}
{"op":"mcm","clk":"5353343554","pt":1646213350855,"mc":[{"id":"1.195503864","rc":[{"atb":[[44,3.26],[60,2.72]],"id":41419589}],"con":true,"img":false}]}
{"op":"mcm","clk":"5353343568","pt":1646213351278,"mc":[{"id":"1.195503864","rc":[{"atb":[[36,2.72],[28,3.26]],"id":41419627}],"con":true,"img":false}]}
{"op":"mcm","clk":"5353343795","pt":1646213355267,"mc":[{"id":"1.195503864","rc":[{"atb":[[20,0],[25,0]],"id":41419606},{"atb":[[23,0],[28,0]],"id":41419620},{"atb":[[22,0],[27,7.68]],"id":41419608}],"con":true,"img":false}]}
{"op":"mcm","clk":"5353343837","pt":1646213355935,"mc":[{"id":"1.195503864","rc":[{"atb":[[21,3.26],[26,2.72]],"id":41419606}],"con":true,"img":false}]}
{"op":"mcm","clk":"5353343844","pt":1646213356037,"mc":[{"id":"1.195503864","rc":[{"atb":[[25,3.26],[30,2.72]],"id":41419620},{"atb":[[21,3.26],[26,2.72]],"id":41419608}],"con":true,"img":false}]}
{"op":"mcm","clk":"5353344667","pt":1646213373363,"mc":[{"id":"1.195503864","rc":[{"atb":[[21,0],[26,0]],"id":41419606},{"atb":[[25,0],[30,0]],"id":41419620},{"atb":[[21,0],[26,0]],"id":41419608}],"con":true,"img":false}]}
{"op":"mcm","clk":"5353344707","pt":1646213374089,"mc":[{"id":"1.195503864","rc":[{"atb":[[20,3.26],[25,2.72]],"id":41419606}],"con":true,"img":false}]}
{"op":"mcm","clk":"5353344726","pt":1646213374503,"mc":[{"id":"1.195503864","rc":[{"atb":[[23,3.26],[28,2.72]],"id":41419620},{"atb":[[22,3.26],[27,10.4]],"id":41419608}],"con":true,"img":false}]}
{"op":"mcm","clk":"5353346491","pt":1646213407817,"mc":[{"id":"1.195503864","rc":[{"atb":[[32,0],[26,0]],"id":41419622}],"con":true,"img":false}]}
{"op":"mcm","clk":"5353346498","pt":1646213407925,"mc":[{"id":"1.195503864","rc":[{"atb":[[36,0],[28,0]],"id":41419627}],"con":true,"img":false}]}
{"op":"mcm","clk":"5353346546","pt":1646213408801,"mc":[{"id":"1.195503864","rc":[{"atb":[[34,2.72],[27,3.26]],"id":41419622},{"atb":[[34,2.72],[27,3.26]],"id":41419627}],"con":true,"img":false}]}
{"op":"mcm","clk":"5353347007","pt":1646213417712,"mc":[{"id":"1.195503864","rc":[{"atb":[[44,0],[60,0]],"id":41419589}],"con":true,"img":false}]}
{"op":"mcm","clk":"5353347044","pt":1646213418435,"mc":[{"id":"1.195503864","rc":[{"atb":[[42,8.14],[55,2.72]],"id":41419589}],"con":true,"img":false}]}
{"op":"mcm","clk":"5353348720","pt":1646213451180,"mc":[{"id":"1.195503864","rc":[{"atb":[[70,0],[48,0]],"id":41419638},{"atb":[[85,0],[60,3.38]],"id":41419605},{"atb":[[85,0],[120,0]],"id":41419613},{"atb":[[140,0],[95,0]],"id":41419593},{"atb":[[44,0],[60,0]],"id":41419618},{"atb":[[32,0],[26,0]],"id":41419639},{"atb":[[75,0],[50,0]],"id":41419635},{"atb":[[85,0],[120,0]],"id":41419602},{"atb":[[130,0],[90,0]],"id":41419614},{"atb":[[85,0],[60,0]],"id":41419619},{"atb":[[75,0],[100,0]],"id":41419598},{"atb":[[34,0],[27,0]],"id":41419640},{"atb":[[70,0],[48,0]],"id":41419636},{"atb":[[85,0],[120,0]],"id":41419599},{"atb":[[38,0],[29,0]],"id":41419628},{"atb":[[140,0],[95,0]],"id":41419595},{"atb":[[25,0],[30,0]],"id":41419637},{"atb":[[44,0],[60,0]],"id":41419604},{"atb":[[17,0],[14.5,0]],"id":41419612},{"atb":[[140,0],[95,0]],"id":41419592},{"atb":[[36,0],[28,0]],"id":41419621},{"atb":[[19.5,0],[24,0]],"id":41419633},{"atb":[[130,0],[90,0]],"id":41419600}],"con":true,"img":false}]}
{"op":"mcm","clk":"5353348728","pt":1646213451282,"mc":[{"id":"1.195503864","rc":[{"atb":[[70,0],[48,0]],"id":41419597},{"atb":[[85,0],[120,0]],"id":41419615}],"con":true,"img":false}]}
{"op":"mcm","clk":"5353348755","pt":1646213451854,"mc":[{"id":"1.195503864","rc":[{"atb":[[75,2.72],[50,3.26]],"id":41419638},{"atb":[[70,3.26],[95,2.72]],"id":41419605},{"atb":[[150,2.72],[100,3.26]],"id":41419593},{"atb":[[65,2.72],[46,3.26]],"id":41419618},{"atb":[[34,2.72],[27,3.26]],"id":41419639},{"atb":[[80,2.72],[55,3.26]],"id":41419635},{"atb":[[130,2.72],[90,6.26]],"id":41419602},{"atb":[[140,2.72],[95,3.26]],"id":41419614},{"atb":[[80,5.79],[110,2.72]],"id":41419598},{"atb":[[36,2.72],[28,3.26]],"id":41419640},{"atb":[[75,2.72],[50,7.34]],"id":41419636},{"atb":[[130,2.72],[90,3.26]],"id":41419599},{"atb":[[40,2.72],[30,3.26]],"id":41419628},{"atb":[[150,2.72],[100,3.26]],"id":41419595},{"atb":[[32,2.72],[26,3.26]],"id":41419637},{"atb":[[65,2.72],[46,3.26]],"id":41419604},{"atb":[[17.5,2.72],[15,3.26]],"id":41419612},{"atb":[[150,2.72],[100,3.26]],"id":41419592},{"atb":[[38,8.12],[29,3.26]],"id":41419621},{"atb":[[20,3.26],[25,2.72]],"id":41419633},{"atb":[[140,2.72],[95,3.26]],"id":41419600}],"con":true,"img":false}]}
{"op":"mcm","clk":"5353348766","pt":1646213452059,"mc":[{"id":"1.195503864","rc":[{"atb":[[130,2.72],[90,3.26]],"id":41419613},{"atb":[[75,2.72],[50,3.26]],"id":41419597},{"atb":[[70,3.26],[95,2.72]],"id":41419619},{"atb":[[130,2.72],[90,6.26]],"id":41419615}],"con":true,"img":false}]}
{"op":"mcm","clk":"5353350418","pt":1646213484794,"mc":[{"id":"1.195503864","rc":[{"atb":[[23,0],[28,0]],"id":41419620},{"atb":[[22,0],[27,7.68]],"id":41419608}],"con":true,"img":false}]}
{"op":"mcm","clk":"5353350455","pt":1646213485720,"mc":[{"id":"1.195503864","rc":[{"atb":[[32,2.72],[26,3.26]],"id":41419620},{"atb":[[23,3.26],[28,2.72]],"id":41419608}],"con":true,"img":false}]}
{"op":"mcm","clk":"5353355339","pt":1646213577456,"mc":[{"id":"1.195503864","rc":[{"atb":[[16.5,0],[11.5,0],[28,2.72]],"id":41419609},{"atb":[[18,0],[26,0],[55,0]],"id":41419638},{"atb":[[18.5,0],[27,0],[60,0]],"id":41419605},{"atb":[[65,0],[19,0],[28,0]],"id":41419634},{"atb":[[40,0],[20,0],[15,0]],"id":41419617},{"atb":[[280,0],[180,0],[430,0]],"id":41419613},{"atb":[[270,0],[170,0],[420,0]],"id":41419593},{"atb":[[17.5,0],[12.5,0],[30,0]],"id":41419622},{"atb":[[42,3.26],[21,0],[15.5,0]],"id":41419589},{"atb":[[42,0],[21,0],[15.5,0]],"id":41419618},{"atb":[[32,0],[18,0],[13,0]],"id":41419601},{"atb":[[4.9,0],[8.8,0],[5.9,0]],"id":41419630},{"atb":[[16.5,0],[46,0],[23,0]],"id":41419597},{"atb":[[16,0],[7.4,0],[9.4,0]],"id":41419626},{"atb":[[8,0],[17.5,0],[10,0]],"id":41419639},{"atb":[[17.5,0],[12.5,0],[30,0]],"id":41419606},{"atb":[[70,0],[19.5,0],[29,0]],"id":41419635},{"atb":[[330,0],[180,0],[90,3.26]],"id":41419602},{"atb":[[540,0],[290,0],[390,0]],"id":41419585},{"atb":[[310,0],[210,0],[460,0]],"id":41419614},{"atb":[[4.4,0],[7.8,0],[5.4,0]],"id":41419610},{"atb":[[8,0],[4.5,0],[5.5,0]],"id":41419623},{"atb":[[16,0],[44,3.26],[22,0]],"id":41419590},{"atb":[[65,0],[19,0],[28,0]],"id":41419619},{"atb":[[140,0],[390,0],[240,0]],"id":41419586},{"atb":[[36,2.72],[19,0],[14,0]],"id":41419631},{"atb":[[32,0],[80,3.26],[21,0]],"id":41419598},{"atb":[[40,0],[20,0],[15,0]],"id":41419627},{"atb":[[40,0],[20,0],[15,0]],"id":41419594},{"atb":[[18.5,0],[11,0],[8.4,0]],"id":41419640},{"atb":[[32,2.72],[18,0],[13,0]],"id":41419607},{"atb":[[17.5,0],[50,3.26],[25,0]],"id":41419636},{"atb":[[36,0],[19,0],[14,0]],"id":41419603},{"atb":[[330,0],[180,0],[90,3.26]],"id":41419615},{"atb":[[5.7,0],[8.4,0],[4.7,0]],"id":41419611},{"atb":[[32,0],[18,0],[13,0]],"id":41419624},{"atb":[[75,0],[20,0],[30,0]],"id":41419591},{"atb":[[36,0],[19,0],[14,0]],"id":41419620},{"atb":[[38,0],[19.5,0],[14.5,0]],"id":41419587},{"atb":[[9.6,0],[5.3,0],[6.6,0]],"id":41419632},{"atb":[[140,0],[390,0],[240,0]],"id":41419599},{"atb":[[42,0],[21,0],[15.5,0]],"id":41419628},{"atb":[[310,0],[210,0],[460,0]],"id":41419595},{"atb":[[16,0],[11,0],[27,0]],"id":41419608},{"atb":[[7.2,0],[9.2,0],[15.5,0]],"id":41419637},{"atb":[[40,0],[20,0],[15,0]],"id":41419604},{"atb":[[34,0],[18.5,0],[13.5,0]],"id":41419616},{"atb":[[6.4,0],[13.5,0],[8.4,0]],"id":41419612},{"atb":[[6.4,0],[5.2,0],[9.4,0]],"id":41419625},{"atb":[[540,0],[290,0],[390,0]],"id":41419592},{"atb":[[38,2.72],[19.5,0],[14.5,0]],"id":41419621},{"atb":[[280,0],[180,0],[430,0]],"id":41419588},{"atb":[[8,0],[17.5,0],[10,0]],"id":41419633},{"atb":[[270,0],[170,0],[420,0]],"id":41419600},{"atb":[[34,0],[18.5,0],[13.5,0]],"id":41419629},{"atb":[[16,0],[44,0],[22,0]],"id":41419596}],"con":true,"img":false}]}
{"op":"mcm","clk":"5353355541","pt":1646213581150,"mc":[{"id":"1.195503864","rc":[{"atb":[[16.5,8.59],[8.6,35.05],[6.6,47.57]],"id":41419609},{"atb":[[27,5.12],[13.5,21.3],[9.4,31.71]],"id":41419605},{"atb":[[270,0.49],[85,3.17],[44,6.19]],"id":41419593},{"atb":[[21,6.65],[10.5,28.03],[8.2,36.99]],"id":41419589},{"atb":[[7.2,42.96],[18,7.83],[9.2,32.48]],"id":41419601},{"atb":[[8.6,35.05],[23,6.05],[11.5,25.36]],"id":41419597},{"atb":[[17.5,8.07],[9,33.29],[7,44.4]],"id":41419606},{"atb":[[180,0.74],[46,5.91],[28,9.86]],"id":41419602},{"atb":[[190,1.41],[95,2.83],[390,0.34]],"id":41419585},{"atb":[[3.2,121.08],[3.7,98.66],[5.4,30.27]],"id":41419610},{"atb":[[22,6.34],[11,26.63],[8.4,35.99]],"id":41419590},{"atb":[[70,3.85],[38,7.19],[240,0.55]],"id":41419586},{"atb":[[32,4.29],[10.5,28.03],[15.5,18.37]],"id":41419598},{"atb":[[8,38.05],[20,7],[10,29.59]],"id":41419594},{"atb":[[7.2,42.96],[18,7.83],[9.2,32.48]],"id":41419607},{"atb":[[9.6,30.97],[19,7.4],[7.6,40.36]],"id":41419603},{"atb":[[3.85,93.47],[3.35,113.35],[5.7,28.33]],"id":41419611},{"atb":[[10,29.59],[30,4.59],[15,19.02]],"id":41419591},{"atb":[[19.5,7.19],[9.8,30.27],[7.8,39.17]],"id":41419587},{"atb":[[70,3.85],[38,7.19],[240,0.55]],"id":41419599},{"atb":[[310,0.43],[110,2.44],[55,4.93]],"id":41419595},{"atb":[[16,8.87],[6.4,49.33],[8.4,35.99]],"id":41419608},{"atb":[[8,38.05],[20,7],[10,29.59]],"id":41419604},{"atb":[[5.2,63.42],[8.4,18],[4.2,83.24]],"id":41419612},{"atb":[[190,1.41],[95,2.83],[390,0.34]],"id":41419592},{"atb":[[280,0.47],[90,2.99],[46,5.91]],"id":41419588},{"atb":[[270,0.49],[85,3.17],[44,6.19]],"id":41419600},{"atb":[[22,6.34],[11,26.63],[8.4,35.99]],"id":41419596}],"con":true,"img":false}]}
{"op":"mcm","clk":"5353355548","pt":1646213581204,"mc":[{"id":"1.195503864","rc":[{"atb":[[9.2,32.48],[26,5.32],[13,22.19]],"id":41419638},{"atb":[[9.6,30.97],[28,4.93],[14,20.49]],"id":41419634},{"atb":[[8,38.05],[20,7],[10,29.59]],"id":41419617},{"atb":[[280,0.47],[90,6.26],[46,5.91]],"id":41419613},{"atb":[[17.5,8.07],[9,33.29],[7,44.4]],"id":41419622},{"atb":[[21,6.65],[10.5,28.03],[8.2,36.99]],"id":41419618},{"atb":[[3.45,108.73],[3.95,90.29],[5.9,27.18]],"id":41419630},{"atb":[[5.7,56.67],[9.4,15.85],[4.7,71.99]],"id":41419626},{"atb":[[10,14.8],[5,66.59],[6,53.27]],"id":41419639},{"atb":[[9.8,30.27],[29,4.75],[14.5,19.73]],"id":41419635},{"atb":[[310,0.43],[110,2.44],[55,4.93]],"id":41419614},{"atb":[[5.5,29.59],[3.25,118.39],[3.75,96.87]],"id":41419623},{"atb":[[9.6,30.97],[28,4.93],[14,20.49]],"id":41419619},{"atb":[[9.6,30.97],[19,7.4],[7.6,40.36]],"id":41419631},{"atb":[[8,38.05],[20,7],[10,29.59]],"id":41419627},{"atb":[[6.4,49.33],[11,13.31],[5.2,63.42]],"id":41419640},{"atb":[[9,33.29],[25,5.54],[12.5,23.16]],"id":41419636},{"atb":[[180,0.74],[46,5.91],[28,9.86]],"id":41419615},{"atb":[[7.2,42.96],[18,7.83],[9.2,32.48]],"id":41419624},{"atb":[[9.6,30.97],[19,7.4],[7.6,40.36]],"id":41419620},{"atb":[[4.3,80.72],[6.6,23.78],[3.65,100.52]],"id":41419632},{"atb":[[21,6.65],[10.5,28.03],[8.2,36.99]],"id":41419628},{"atb":[[5.6,57.91],[9.2,16.24],[4.6,73.99]],"id":41419637},{"atb":[[18.5,7.61],[7.4,41.62],[9.4,31.71]],"id":41419616},{"atb":[[3.6,102.45],[6.4,24.66],[4.2,83.24]],"id":41419625},{"atb":[[19.5,7.19],[9.8,30.27],[7.8,39.17]],"id":41419621},{"atb":[[10,14.8],[5,66.59],[6,53.27]],"id":41419633},{"atb":[[18.5,7.61],[7.4,41.62],[9.4,31.71]],"id":41419629}],"con":true,"img":false}]}
{"op":"mcm","clk":"5353360979","pt":1646213683507,"mc":[{"id":"1.195503864","rc":[{"atb":[[9.2,12.2]],"id":41419609},{"atl":[[650,2]],"id":41419609},{"atb":[[27,3.85]],"id":41419638},{"atb":[[28,3.7]],"id":41419605},{"atl":[[950,2]],"id":41419605},{"atb":[[21,5]],"id":41419634},{"atl":[[890,2]],"id":41419634},{"atb":[[17,6.25]],"id":41419617},{"atl":[[840,2]],"id":41419617},{"atb":[[34,3.03]],"id":41419613},{"atl":[[1000,2]],"id":41419613},{"atb":[[34,3.03]],"id":41419593},{"atl":[[1000,2]],"id":41419593},{"atb":[[8,14.29]],"id":41419622},{"atl":[[580,2]],"id":41419622},{"atb":[[11,10]],"id":41419589},{"atl":[[740,2]],"id":41419589},{"atb":[[22,4.76]],"id":41419618},{"atl":[[920,2]],"id":41419618},{"atb":[[11.5,9.52]],"id":41419601},{"atl":[[750,2]],"id":41419601},{"atb":[[5.2,23.81]],"id":41419630},{"atl":[[420,2]],"id":41419630},{"atb":[[24,4.35]],"id":41419597},{"atl":[[930,2]],"id":41419597},{"atb":[[7.2,16.13]],"id":41419626},{"atl":[[530,2]],"id":41419626},{"atb":[[9.4,11.9]],"id":41419639},{"atl":[[690,2]],"id":41419639},{"atb":[[6.2,16.14]],"id":41419606},{"atl":[[510,2]],"id":41419606},{"atb":[[30,3.45]],"id":41419635},{"atl":[[1000,2]],"id":41419635},{"atb":[[36,2.86]],"id":41419602},{"atb":[[7.8,5.44]],"id":41419585},{"atl":[[1000,2]],"id":41419585},{"atb":[[36,2.86]],"id":41419614},{"atb":[[4.7,27.03]],"id":41419610},{"atl":[[340,2]],"id":41419610},{"atb":[[5.1,24.39]],"id":41419623},{"atl":[[410,2]],"id":41419623},{"atb":[[14.5,7.41]],"id":41419590},{"atl":[[810,2]],"id":41419590},{"atb":[[29,3.57]],"id":41419619},{"atl":[[1000,2]],"id":41419619},{"atb":[[29,3.57]],"id":41419586},{"atl":[[940,2]],"id":41419586},{"atb":[[11.5,9.52]],"id":41419631},{"atl":[[760,2]],"id":41419631},{"atb":[[34,3.03]],"id":41419598},{"atl":[[1000,2]],"id":41419598},{"atb":[[7.6,14.02]],"id":41419627},{"atl":[[550,2]],"id":41419627},{"atb":[[21,5]],"id":41419594},{"atl":[[930,2]],"id":41419594},{"atb":[[11.5,9.52]],"id":41419640},{"atl":[[760,2]],"id":41419640},{"atb":[[8.8,12.82]],"id":41419607},{"atl":[[620,2]],"id":41419607},{"atb":[[25,9.71]],"id":41419636},{"atl":[[920,2]],"id":41419636},{"atb":[[13.5,8]],"id":41419603},{"atl":[[790,2]],"id":41419603},{"atb":[[36,2.86]],"id":41419615},{"atb":[[5,25]],"id":41419611},{"atl":[[400,2]],"id":41419611},{"atb":[[10,11.11]],"id":41419624},{"atl":[[730,2]],"id":41419624},{"atb":[[30,8.04]],"id":41419591},{"atl":[[940,2]],"id":41419591},{"atb":[[7,14.8]],"id":41419620},{"atl":[[530,2]],"id":41419620},{"atb":[[12,9.09]],"id":41419587},{"atl":[[760,2]],"id":41419587},{"atb":[[5.2,23.81]],"id":41419632},{"atl":[[420,2]],"id":41419632},{"atb":[[26,4]],"id":41419599},{"atl":[[920,2]],"id":41419599},{"atb":[[9.2,12.2]],"id":41419628},{"atl":[[660,2]],"id":41419628},{"atb":[[38,2.7]],"id":41419595},{"atb":[[6.4,67.85]],"id":41419608},{"atl":[[520,2]],"id":41419608},{"atb":[[9.4,11.9]],"id":41419637},{"atl":[[720,2]],"id":41419637},{"atb":[[15,7.14]],"id":41419604},{"atl":[[810,2]],"id":41419604},{"atb":[[17,6.25]],"id":41419616},{"atl":[[840,2]],"id":41419616},{"atb":[[6.4,18.52]],"id":41419612},{"atl":[[520,2]],"id":41419612},{"atb":[[4.9,25.64]],"id":41419625},{"atl":[[450,2]],"id":41419625},{"atb":[[34,3.03]],"id":41419592},{"atl":[[1000,2]],"id":41419592},{"atb":[[8.6,13.16]],"id":41419621},{"atl":[[620,2]],"id":41419621},{"atb":[[36,2.86]],"id":41419588},{"atb":[[7.6,15.15]],"id":41419633},{"atl":[[550,2]],"id":41419633},{"atb":[[34,3.03]],"id":41419600},{"atl":[[1000,2]],"id":41419600},{"atb":[[7.8,14.71]],"id":41419629},{"atl":[[560,2]],"id":41419629},{"atb":[[18.5,5.71]],"id":41419596},{"atl":[[860,2]],"id":41419596}],"con":true,"img":false}]}
{"op":"mcm","clk":"5353361021","pt":1646213684021,"mc":[{"id":"1.195503864","rc":[{"atb":[[130,0],[90,0]],"id":41419599}],"con":true,"img":false}]}
{"op":"mcm","clk":"5353361104","pt":1646213685016,"mc":[{"id":"1.195503864","rc":[{"atb":[[85,3.26],[120,2.72]],"id":41419599}],"con":true,"img":false}]}
{"op":"mcm","clk":"5353361610","pt":1646213692046,"mc":[{"id":"1.195503864","rc":[{"atl":[[920,0],[910,2]],"id":41419618},{"atl":[[810,0],[800,2]],"id":41419590},{"atl":[[940,0],[930,2]],"id":41419586},{"atl":[[540,2],[550,0]],"id":41419627},{"atl":[[920,2],[930,0]],"id":41419594},{"atl":[[610,2]],"id":41419607},{"atl":[[730,0],[720,2]],"id":41419624},{"atl":[[520,0],[510,2]],"id":41419608},{"atl":[[510,2]],"id":41419612},{"atl":[[620,0],[610,2]],"id":41419621}],"con":true,"img":false}]}
{"op":"mcm","clk":"5353361616","pt":1646213692108,"mc":[{"id":"1.195503864","rc":[{"atl":[[620,0]],"id":41419607},{"atl":[[520,0]],"id":41419612}],"con":true,"img":false}]}
{"op":"mcm","clk":"5353361625","pt":1646213692208,"mc":[{"id":"1.195503864","rc":[{"atl":[[650,2]],"id":41419628}],"con":true,"img":false}]}
{"op":"mcm","clk":"5353361632","pt":1646213692311,"mc":[{"id":"1.195503864","rc":[{"atl":[[660,0]],"id":41419628}],"con":true,"img":false}]}
{"op":"mcm","clk":"5353362669","pt":1646213707465,"mc":[{"id":"1.195503864","rc":[{"atl":[[570,2],[580,0]],"id":41419622},{"atl":[[730,2],[740,0]],"id":41419589},{"atl":[[480,2],[510,0]],"id":41419606},{"atl":[[390,2],[400,0]],"id":41419611},{"atl":[[760,0],[750,2]],"id":41419587},{"atl":[[920,0],[910,2]],"id":41419599},{"atl":[[860,0],[850,2]],"id":41419596}],"con":true,"img":false}]}
{"op":"mcm","clk":"5353365158","pt":1646213749009,"mc":[{"id":"1.195503864","rc":[{"atl":[[880,2]],"id":41419634}],"con":true,"img":false}]}
{"op":"mcm","clk":"5353365162","pt":1646213749114,"mc":[{"id":"1.195503864","rc":[{"atl":[[890,0]],"id":41419634},{"atl":[[720,0],[710,2]],"id":41419637}],"con":true,"img":false}]}
{"op":"mcm","clk":"5353368224","pt":1646213801583,"mc":[{"id":"1.195503864","rc":[{"atl":[[940,0],[930,2]],"id":41419591}],"con":true,"img":false}]}
{"op":"mcm","clk":"5353368242","pt":1646213801892,"mc":[{"id":"1.195503864","rc":[{"atb":[[32,0],[26,0]],"id":41419620}],"con":true,"img":false}]}
{"op":"mcm","clk":"5353368284","pt":1646213802564,"mc":[{"id":"1.195503864","rc":[{"atb":[[25,3.26],[30,2.72]],"id":41419620}],"con":true,"img":false}]}
{"op":"mcm","clk":"5353369162","pt":1646213817522,"mc":[{"id":"1.195503864","rc":[{"atb":[[16.5,0],[8.6,0],[6.6,0]],"id":41419609},{"atb":[[9.2,0],[26,0],[13,0]],"id":41419638},{"atb":[[27,0],[13.5,0],[9.4,0]],"id":41419605},{"atb":[[9.6,0],[28,0],[14,0]],"id":41419634},{"atb":[[8,0],[20,0],[10,0]],"id":41419617},{"atb":[[280,0],[90,3.26],[46,0]],"id":41419613},{"atb":[[270,0],[85,0],[44,0]],"id":41419593},{"atb":[[17.5,0],[9,0],[7,0]],"id":41419622},{"atb":[[21,0],[10.5,0],[8.2,0]],"id":41419589},{"atb":[[21,0],[10.5,0],[8.2,0]],"id":41419618},{"atb":[[7.2,0],[18,0],[9.2,0]],"id":41419601},{"atb":[[3.45,0],[3.95,0],[5.9,0]],"id":41419630},{"atb":[[8.6,0],[23,0],[11.5,0]],"id":41419597},{"atb":[[5.7,0],[9.4,0],[4.7,0]],"id":41419626},{"atb":[[10,0],[5,0],[6,0]],"id":41419639},{"atb":[[17.5,0],[9,0],[7,0]],"id":41419606},{"atb":[[9.8,0],[29,0],[14.5,0]],"id":41419635},{"atb":[[180,0],[46,0],[28,0]],"id":41419602},{"atb":[[190,0],[95,0],[390,0]],"id":41419585},{"atb":[[310,0],[110,0],[55,0]],"id":41419614},{"atb":[[3.2,0],[3.7,0],[5.4,0]],"id":41419610},{"atb":[[5.5,0],[3.25,0],[3.75,0]],"id":41419623},{"atb":[[22,0],[11,0],[8.4,0]],"id":41419590},{"atb":[[9.6,0],[28,0],[14,0]],"id":41419619},{"atb":[[70,0],[38,0],[240,0]],"id":41419586},{"atb":[[9.6,0],[19,0],[7.6,0]],"id":41419631},{"atb":[[32,0],[10.5,0],[15.5,0]],"id":41419598},{"atb":[[8,0],[20,0],[10,0]],"id":41419627},{"atb":[[8,0],[20,0],[10,0]],"id":41419594},{"atb":[[6.4,0],[11,0],[5.2,0]],"id":41419640},{"atb":[[7.2,0],[18,0],[9.2,0]],"id":41419607},{"atb":[[9,0],[25,4.17],[12.5,0]],"id":41419636},{"atb":[[9.6,0],[19,0],[7.6,0]],"id":41419603},{"atb":[[180,0],[46,0],[28,0]],"id":41419615},{"atb":[[3.85,0],[3.35,0],[5.7,0]],"id":41419611},{"atb":[[7.2,0],[18,0],[9.2,0]],"id":41419624},{"atb":[[10,0],[30,3.45],[15,0]],"id":41419591},{"atb":[[9.6,0],[19,0],[7.6,0]],"id":41419620},{"atb":[[19.5,0],[9.8,0],[7.8,0]],"id":41419587},{"atb":[[4.3,0],[6.6,0],[3.65,0]],"id":41419632},{"atb":[[70,0],[38,0],[240,0]],"id":41419599},{"atb":[[21,0],[10.5,0],[8.2,0]],"id":41419628},{"atb":[[310,0],[110,0],[55,0]],"id":41419595},{"atb":[[16,0],[6.4,18.52],[8.4,0]],"id":41419608},{"atb":[[5.6,0],[9.2,0],[4.6,0]],"id":41419637},{"atb":[[8,0],[20,0],[10,0]],"id":41419604},{"atb":[[18.5,0],[7.4,0],[9.4,0]],"id":41419616},{"atb":[[5.2,0],[8.4,0],[4.2,0]],"id":41419612},{"atb":[[3.6,0],[6.4,0],[4.2,0]],"id":41419625},{"atb":[[190,0],[95,0],[390,0]],"id":41419592},{"atb":[[19.5,0],[9.8,0],[7.8,0]],"id":41419621},{"atb":[[280,0],[90,0],[46,0]],"id":41419588},{"atb":[[10,0],[5,0],[6,0]],"id":41419633},{"atb":[[270,0],[85,0],[44,0]],"id":41419600},{"atb":[[18.5,0],[7.4,0],[9.4,0]],"id":41419629},{"atb":[[22,0],[11,0],[8.4,0]],"id":41419596}],"con":true,"img":false}]}
{"op":"mcm","clk":"5353369376","pt":1646213821035,"mc":[{"id":"1.195503864","rc":[{"atb":[[16.5,8.59],[8.6,35.05],[6.6,47.57]],"id":41419609},{"atb":[[9.2,32.48],[26,5.32],[13,22.19]],"id":41419638},{"atb":[[27,5.12],[13.5,21.3],[9.4,31.71]],"id":41419605},{"atb":[[9.6,30.97],[28,4.93],[14,20.49]],"id":41419634},{"atb":[[8,38.05],[20,7],[10,29.59]],"id":41419617},{"atb":[[280,0.47],[90,6.26],[46,5.91]],"id":41419613},{"atb":[[270,0.49],[85,3.17],[44,6.19]],"id":41419593},{"atb":[[17.5,8.07],[9,33.29],[7,44.4]],"id":41419622},{"atb":[[21,6.65],[10.5,28.03],[8.2,36.99]],"id":41419589},{"atb":[[21,6.65],[10.5,28.03],[8.2,36.99]],"id":41419618},{"atb":[[7.2,42.96],[18,7.83],[9.2,32.48]],"id":41419601},{"atb":[[3.45,108.73],[3.95,90.29],[5.9,27.18]],"id":41419630},{"atb":[[8.6,35.05],[23,6.05],[11.5,25.36]],"id":41419597},{"atb":[[5.7,56.67],[9.4,15.85],[4.7,71.99]],"id":41419626},{"atb":[[10,14.8],[5,66.59],[6,53.27]],"id":41419639},{"atb":[[17.5,8.07],[9,33.29],[7,44.4]],"id":41419606},{"atb":[[9.8,30.27],[29,4.75],[14.5,19.73]],"id":41419635},{"atb":[[180,0.74],[46,5.91],[28,9.86]],"id":41419602},{"atb":[[190,1.41],[95,2.83],[390,0.34]],"id":41419585},{"atb":[[310,0.43],[110,2.44],[55,4.93]],"id":41419614},{"atb":[[3.2,121.08],[3.7,98.66],[5.4,30.27]],"id":41419610},{"atb":[[5.5,29.59],[3.25,118.39],[3.75,96.87]],"id":41419623},{"atb":[[22,6.34],[11,26.63],[8.4,35.99]],"id":41419590},{"atb":[[9.6,30.97],[28,4.93],[14,20.49]],"id":41419619},{"atb":[[70,3.85],[38,7.19],[240,0.55]],"id":41419586},{"atb":[[9.6,30.97],[19,7.4],[7.6,40.36]],"id":41419631},{"atb":[[32,4.29],[10.5,28.03],[15.5,18.37]],"id":41419598},{"atb":[[8,38.05],[20,7],[10,29.59]],"id":41419627},{"atb":[[8,38.05],[20,7],[10,29.59]],"id":41419594},{"atb":[[6.4,49.33],[11,13.31],[5.2,63.42]],"id":41419640},{"atb":[[7.2,42.96],[18,7.83],[9.2,32.48]],"id":41419607},{"atb":[[9,33.29],[25,9.71],[12.5,23.16]],"id":41419636},{"atb":[[9.6,30.97],[19,7.4],[7.6,40.36]],"id":41419603},{"atb":[[180,0.74],[46,5.91],[28,9.86]],"id":41419615},{"atb":[[3.85,93.47],[3.35,113.35],[5.7,28.33]],"id":41419611},{"atb":[[7.2,42.96],[18,7.83],[9.2,32.48]],"id":41419624},{"atb":[[10,29.59],[30,8.04],[15,19.02]],"id":41419591},{"atb":[[9.6,30.97],[19,7.4],[7.6,40.36]],"id":41419620},{"atb":[[19.5,7.19],[9.8,30.27],[7.8,39.17]],"id":41419587},{"atb":[[4.3,80.72],[6.6,23.78],[3.65,100.52]],"id":41419632},{"atb":[[70,3.85],[38,7.19],[240,0.55]],"id":41419599},{"atb":[[21,6.65],[10.5,28.03],[8.2,36.99]],"id":41419628},{"atb":[[310,0.43],[110,2.44],[55,4.93]],"id":41419595},{"atb":[[16,8.87],[6.4,67.85],[8.4,35.99]],"id":41419608},{"atb":[[5.6,57.91],[9.2,16.24],[4.6,73.99]],"id":41419637},{"atb":[[8,38.05],[20,7],[10,29.59]],"id":41419604},{"atb":[[18.5,7.61],[7.4,41.62],[9.4,31.71]],"id":41419616},{"atb":[[5.2,63.42],[8.4,18],[4.2,83.24]],"id":41419612},{"atb":[[3.6,102.45],[6.4,24.66],[4.2,83.24]],"id":41419625},{"atb":[[190,1.41],[95,2.83],[390,0.34]],"id":41419592},{"atb":[[19.5,7.19],[9.8,30.27],[7.8,39.17]],"id":41419621},{"atb":[[280,0.47],[90,2.99],[46,5.91]],"id":41419588},{"atb":[[10,14.8],[5,66.59],[6,53.27]],"id":41419633},{"atb":[[270,0.49],[85,3.17],[44,6.19]],"id":41419600},{"atb":[[18.5,7.61],[7.4,41.62],[9.4,31.71]],"id":41419629},{"atb":[[22,6.34],[11,26.63],[8.4,35.99]],"id":41419596}],"con":true,"img":false}]}
{"op":"mcm","clk":"5353369409","pt":1646213821551,"mc":[{"id":"1.195503864","rc":[{"atb":[[16.5,17.49],[32,4.95],[27,9.9],[28,8.59]],"id":41419609},{"atl":[[65,4.95],[640,0.25],[670,1.83],[85,9.9]],"id":41419609},{"atb":[[130,4.95],[95,9.9],[27,13.57]],"id":41419638},{"atb":[[75,9.9],[95,9.36],[28,12.6]],"id":41419605},{"atl":[[940,0.16],[970,1.26]],"id":41419605},{"atb":[[70,5.02],[75,4.95],[55,9.9]],"id":41419634},{"atl":[[180,4.95],[870,0.17]],"id":41419634},{"atb":[[20,15.91],[42,9.9],[50,4.95]],"id":41419617},{"atl":[[150,4.95],[860,1.42]],"id":41419617},{"atb":[[90,16.16],[120,4.95]],"id":41419613},{"atl":[[990,0.15]],"id":41419613},{"atb":[[85,13.07],[100,10.28],[110,4.95]],"id":41419593},{"atl":[[990,0.15]],"id":41419593},{"atb":[[17.5,16.97],[19.5,9.9],[23,4.95]],"id":41419622},{"atl":[[560,0.28],[75,9.9],[590,2.08],[55,4.95]],"id":41419622},{"atb":[[38,4.95],[21,15.56],[30,9.9]],"id":41419589},{"atl":[[130,4.95],[720,0.21],[750,1.63]],"id":41419589},{"atb":[[65,5.2],[80,4.95],[22,13.66],[60,9.9]],"id":41419618},{"atl":[[160,4.95],[900,0.17],[930,1.31]],"id":41419618},{"atb":[[18,16.74],[36,9.9],[44,4.95]],"id":41419601},{"atl":[[740,0.21],[770,1.59],[120,4.95]],"id":41419601},{"atb":[[11,9.9],[13,4.95]],"id":41419630},{"atl":[[23,4.95],[27,9.9]],"id":41419630},{"atb":[[75,12.63],[95,4.95],[24,13.25]],"id":41419597},{"atl":[[210,4.95],[950,1.29]],"id":41419597},{"atb":[[19,9.9],[22,7.67]],"id":41419626},{"atl":[[40,4.95],[48,9.9]],"id":41419626},{"atb":[[34,7.67],[28,9.9]],"id":41419639},{"atl":[[80,4.95],[100,9.9]],"id":41419639},{"atb":[[16.5,4.95],[17.5,16.97],[14.5,9.9]],"id":41419606},{"atl":[[38,4.95],[46,9.9],[470,0.33],[500,2.45]],"id":41419606},{"atb":[[80,12.63],[100,4.95]],"id":41419635},{"atl":[[240,4.95]],"id":41419635},{"atb":[[160,4.95],[180,1.63],[90,11.35],[120,9.9]],"id":41419602},{"atl":[[1000,0.15]],"id":41419602},{"atb":[[85,9.9],[110,4.95]],"id":41419585},{"atl":[[990,0.15]],"id":41419585},{"atb":[[130,4.95],[95,13.17],[110,9.69]],"id":41419614},{"atl":[[1000,0.15]],"id":41419614},{"atb":[[10,4.95],[9.2,9.9],[5.4,39.17]],"id":41419610},{"atl":[[16,4.95],[18,9.9],[360,3.41]],"id":41419610},{"atb":[[10.5,9.9],[11,11.63],[5.5,38.5],[12.5,4.95]],"id":41419623},{"atl":[[21,4.95],[25,9.9],[400,0.39],[430,2.86]],"id":41419623},{"atb":[[42,9.9],[22,15.24],[50,4.95]],"id":41419590},{"atl":[[140,4.95],[790,0.2],[820,1.49]],"id":41419590},{"atb":[[90,9.9],[29,12.47],[120,4.95]],"id":41419619},{"atb":[[70,13.76],[85,10.28],[90,4.95]],"id":41419586},{"atl":[[920,0.17],[950,1.29]],"id":41419586},{"atb":[[19,16.3],[42,9.9],[50,4.95]],"id":41419631},{"atl":[[780,1.57],[110,4.95]],"id":41419631},{"atb":[[34,11.57],[90,9.9],[110,4.18],[120,4.95]],"id":41419598},{"atl":[[990,0.15]],"id":41419598},{"atb":[[19.5,9.9],[20,15.91],[23,4.95]],"id":41419627},{"atl":[[530,0.29],[560,2.19],[80,9.9],[60,4.95]],"id":41419627},{"atb":[[65,12.63],[70,2.29],[21,13.9],[85,4.95]],"id":41419594},{"atl":[[170,4.95],[910,0.17],[940,1.3]],"id":41419594},{"atb":[[32,9.9],[38,4.28],[40,4.95]],"id":41419640},{"atl":[[90,4.95],[750,0.21],[120,9.9]],"id":41419640},{"atb":[[18,16.74],[22,9.9],[26,8.22]],"id":41419607},{"atl":[[600,0.26],[630,1.95],[80,9.9],[60,4.95]],"id":41419607},{"atb":[[65,9.9],[85,4.95]],"id":41419636},{"atl":[[190,4.95]],"id":41419636},{"atb":[[19,16.3],[38,9.9],[46,4.95]],"id":41419603},{"atl":[[140,4.95],[780,0.2],[810,1.51]],"id":41419603},{"atb":[[130,7.67],[90,11.35],[95,9.9]],"id":41419615},{"atl":[[1000,0.15]],"id":41419615},{"atb":[[9.6,9.9],[11,4.95],[5.7,37.24]],"id":41419611},{"atl":[[20,4.95],[24,9.9],[410,3]],"id":41419611},{"atb":[[32,4.95],[27,13.17]],"id":41419624},{"atl":[[80,4.95],[100,9.9]],"id":41419624},{"atb":[[80,9.9],[85,4.61],[100,4.95],[30,16.94]],"id":41419591},{"atl":[[920,0.17],[950,1.29]],"id":41419591},{"atb":[[19,26.21],[22,4.95]],"id":41419620},{"atl":[[520,0.3],[550,2.23],[75,9.9],[55,4.95]],"id":41419620},{"atb":[[19.5,16.1],[38,4.95],[30,9.9]],"id":41419587},{"atl":[[740,0.21],[770,1.59],[110,4.95]],"id":41419587},{"atb":[[10.5,9.9],[12.5,4.95],[6.6,32.68]],"id":41419632},{"atl":[[24,4.95],[440,2.79],[28,9.9]],"id":41419632},{"atb":[[80,4.95],[85,10.28],[60,9.9]],"id":41419599},{"atl":[[900,0.17],[930,1.31]],"id":41419599},{"atb":[[21,15.56],[26,9.9],[30,8.22]],"id":41419628},{"atl":[[80,4.95],[670,1.83],[100,9.9]],"id":41419628},{"atb":[[160,4.95],[110,9.69],[120,9.9]],"id":41419595},{"atl":[[1000,0.15]],"id":41419595},{"atb":[[16,17.78],[17,4.95],[15,9.9]],"id":41419608},{"atl":[[530,2.32],[40,4.95],[48,9.9],[500,0.31]],"id":41419608},{"atb":[[34,4.95],[28,9.9]],"id":41419637},{"atl":[[80,4.95],[100,9.9]],"id":41419637},{"atb":[[20,15.91],[42,9.9],[50,4.95]],"id":41419604},{"atl":[[150,4.95],[800,0.19],[830,1.47]],"id":41419604},{"atb":[[44,9.9],[55,7.67]],"id":41419616},{"atl":[[130,4.95]],"id":41419616},{"atb":[[17.5,11.63],[8.4,26.9]],"id":41419612},{"atl":[[530,2.32],[500,0.31]],"id":41419612},{"atb":[[6.4,33.57],[10.5,13.17],[12.5,4.95]],"id":41419625},{"atl":[[24,4.95],[28,9.9],[470,2.61]],"id":41419625},{"atb":[[85,9.9],[110,4.95]],"id":41419592},{"atl":[[990,0.15]],"id":41419592},{"atb":[[22,9.9],[26,4.95]],"id":41419621},{"atl":[[70,4.95],[90,9.9]],"id":41419621},{"atb":[[140,4.95],[90,11.07],[100,9.9]],"id":41419588},{"atl":[[1000,0.15]],"id":41419588},{"atb":[[23,9.9],[25,9.33],[27,4.95]],"id":41419633},{"atl":[[65,9.9],[540,0.29],[48,4.95]],"id":41419633},{"atb":[[85,13.07],[110,4.95]],"id":41419600},{"atb":[[19.5,9.9],[23,4.95]],"id":41419629},{"atl":[[65,4.95],[550,0.28],[85,9.9]],"id":41419629},{"atb":[[22,15.24],[46,9.9],[60,4.95]],"id":41419596},{"atl":[[200,4.95],[870,1.41]],"id":41419596}],"con":true,"img":false}]}
{"op":"mcm","clk":"5353369417","pt":1646213821608,"mc":[{"id":"1.195503864","rc":[{"atb":[[80,2]],"id":41419638},{"atl":[[1000,0.15]],"id":41419638},{"atb":[[28,13.83]],"id":41419634},{"atl":[[900,1.36]],"id":41419634},{"atb":[[60,5.41]],"id":41419617},{"atl":[[830,0.19]],"id":41419617},{"atb":[[90,23.18]],"id":41419613},{"atb":[[11.5,11.63],[5.9,36.08]],"id":41419630},{"atl":[[410,0.38],[440,2.79]],"id":41419630},{"atb":[[75,14.77]],"id":41419597},{"atl":[[920,0.17]],"id":41419597},{"atb":[[22,15.22],[9.4,24.76]],"id":41419626},{"atl":[[520,0.3],[550,2.23]],"id":41419626},{"atb":[[34,12.48],[10,23.7]],"id":41419639},{"atl":[[680,0.23],[710,1.72]],"id":41419639},{"atb":[[85,1.88],[30,12.35]],"id":41419635},{"atl":[[990,0.15]],"id":41419635},{"atb":[[9.6,11.63]],"id":41419610},{"atl":[[330,0.47]],"id":41419610},{"atb":[[100,1.6]],"id":41419619},{"atl":[[990,0.15]],"id":41419619},{"atb":[[38,4.28]],"id":41419631},{"atl":[[750,0.21]],"id":41419631},{"atb":[[11.5,18.42]],"id":41419640},{"atl":[[780,1.57]],"id":41419640},{"atb":[[75,4.86],[25,18.62]],"id":41419636},{"atl":[[910,0.17],[940,1.3]],"id":41419636},{"atb":[[10,11.63]],"id":41419611},{"atl":[[380,0.41]],"id":41419611},{"atb":[[34,7.53],[18,16.74]],"id":41419624},{"atl":[[710,0.22],[740,1.65]],"id":41419624},{"atb":[[13.5,11.63]],"id":41419632},{"atl":[[410,0.38]],"id":41419632},{"atl":[[640,0.25]],"id":41419628},{"atb":[[34,9.76],[9.4,20.8]],"id":41419637},{"atl":[[700,0.22],[730,1.67]],"id":41419637},{"atb":[[18.5,16.51],[55,10.61]],"id":41419616},{"atl":[[830,0.19],[860,1.42]],"id":41419616},{"atb":[[16,9.9],[18,4.95]],"id":41419612},{"atl":[[34,4.95],[42,9.9]],"id":41419612},{"atb":[[13,11.63]],"id":41419625},{"atl":[[440,0.35]],"id":41419625},{"atb":[[19.5,16.1]],"id":41419621},{"atl":[[600,0.26],[630,1.95]],"id":41419621},{"atb":[[10,23.7]],"id":41419633},{"atl":[[570,2.15]],"id":41419633},{"atb":[[95,10.28]],"id":41419600},{"atl":[[990,0.15]],"id":41419600},{"atb":[[18.5,16.51]],"id":41419629},{"atl":[[580,2.12]],"id":41419629},{"atl":[[840,0.19]],"id":41419596}],"con":true,"img":false}]}
{"op":"mcm","clk":"5353369427","pt":1646213821717,"mc":[{"id":"1.195503864","rc":[{"atl":[[650,0],[250,2]],"id":41419609},{"atb":[[36,2.86],[27,9.72]],"id":41419638},{"atl":[[880,0],[480,2]],"id":41419634},{"atl":[[840,0],[440,2]],"id":41419617},{"atl":[[570,0],[170,2]],"id":41419622},{"atl":[[330,2],[730,0]],"id":41419589},{"atl":[[510,2]],"id":41419618},{"atl":[[350,2],[750,0]],"id":41419601},{"atl":[[65,2],[420,0]],"id":41419630},{"atl":[[530,2],[930,0]],"id":41419597},{"atl":[[130,2]],"id":41419626},{"atl":[[290,2],[690,0]],"id":41419639},{"atl":[[90,2],[480,0]],"id":41419606},{"atl":[[680,2],[1000,0]],"id":41419635},{"atl":[[38,2.7],[340,0]],"id":41419610},{"atl":[[410,0],[55,2]],"id":41419623},{"atl":[[800,0],[400,2]],"id":41419590},{"atl":[[760,0],[380,2]],"id":41419631},{"atl":[[540,0],[150,2]],"id":41419627},{"atb":[[21,8.9],[26,4]],"id":41419594},{"atl":[[520,2],[920,0]],"id":41419594},{"atl":[[360,2],[760,0]],"id":41419640},{"atl":[[610,0],[210,2]],"id":41419607},{"atl":[[520,2],[920,0]],"id":41419636},{"atl":[[790,0],[390,2]],"id":41419603},{"atl":[[390,0],[50,2.04]],"id":41419611},{"atl":[[320,2],[720,0]],"id":41419624},{"atl":[[930,0],[940,2]],"id":41419591},{"atl":[[530,0],[130,2]],"id":41419620},{"atl":[[350,2],[750,0]],"id":41419587},{"atl":[[65,2],[420,0]],"id":41419632},{"atl":[[280,2],[650,0]],"id":41419628},{"atl":[[110,2],[510,0]],"id":41419608},{"atl":[[310,2],[710,0]],"id":41419637},{"atl":[[810,0],[410,2]],"id":41419604},{"atl":[[840,0],[440,2]],"id":41419616},{"atl":[[75,2],[450,0]],"id":41419625},{"atl":[[610,0],[210,2]],"id":41419621},{"atl":[[550,0],[160,2]],"id":41419633},{"atl":[[560,0],[180,2]],"id":41419629},{"atl":[[850,0],[450,2]],"id":41419596}],"con":true,"img":false}]}
{"op":"mcm","clk":"5353369436","pt":1646213821812,"mc":[{"id":"1.195503864","rc":[{"atl":[[910,0]],"id":41419618},{"atl":[[530,0]],"id":41419626},{"atl":[[110,2],[510,0]],"id":41419612}],"con":true,"img":false}]}
{"op":"mcm","clk":"5353369444","pt":1646213821919,"mc":[{"id":"1.195503864","rc":[{"atb":[[9.2,0]],"id":41419609},{"atb":[[28,8.9]],"id":41419605},{"atb":[[17,0]],"id":41419617},{"atb":[[34,0]],"id":41419613},{"atb":[[48,2.13]],"id":41419593},{"atb":[[8,0]],"id":41419622},{"atb":[[36,0]],"id":41419602},{"atb":[[29,8.9]],"id":41419619},{"atb":[[34,8.54]],"id":41419598},{"atb":[[6.6,17.86]],"id":41419611},{"atb":[[14,7.69]],"id":41419624},{"atb":[[12,0]],"id":41419587},{"atb":[[20,21.17],[15,0]],"id":41419604},{"atb":[[4.9,0]],"id":41419625},{"atb":[[46,2.22]],"id":41419592},{"atb":[[10.5,10.53],[7.6,0]],"id":41419633},{"atb":[[7.8,0]],"id":41419629}],"con":true,"img":false}]}
{"op":"mcm","clk":"5353369449","pt":1646213822021,"mc":[{"id":"1.195503864","rc":[{"atb":[[12,9.09]],"id":41419609},{"atb":[[44,2.33]],"id":41419605},{"atb":[[21,0],[28,17.53]],"id":41419634},{"atl":[[870,2.17],[480,0]],"id":41419634},{"atb":[[23,4.55]],"id":41419617},{"atb":[[46,8.13]],"id":41419613},{"atb":[[34,0]],"id":41419593},{"atb":[[9.6,11.63]],"id":41419622},{"atb":[[11,0],[14.5,7.41]],"id":41419589},{"atb":[[34,3.03],[22,8.9]],"id":41419618},{"atb":[[11.5,0],[15.5,6.9]],"id":41419601},{"atb":[[7.2,16.13],[5.2,0]],"id":41419630},{"atb":[[38,2.7],[24,8.9]],"id":41419597},{"atb":[[9.6,11.63],[7.2,0]],"id":41419626},{"atb":[[13,8.33],[9.4,0]],"id":41419639},{"atb":[[9.2,12.2],[6.2,0]],"id":41419606},{"atb":[[46,2.22],[30,8.9]],"id":41419635},{"atl":[[260,4.74]],"id":41419635},{"atb":[[50,2.04]],"id":41419602},{"atb":[[36,0],[50,2.04]],"id":41419614},{"atb":[[6,20],[4.7,0]],"id":41419610},{"atb":[[5.1,0],[6.8,17.24]],"id":41419623},{"atb":[[19.5,5.41],[14.5,0]],"id":41419590},{"atb":[[48,2.13]],"id":41419619},{"atb":[[17.5,6.06],[11.5,0]],"id":41419631},{"atb":[[48,2.13]],"id":41419598},{"atb":[[10,40.7],[7.6,0]],"id":41419627},{"atb":[[16,6.67],[11.5,8.9]],"id":41419640},{"atb":[[11.5,9.52],[8.8,0]],"id":41419607},{"atb":[[34,3.03],[25,14.45]],"id":41419636},{"atb":[[18.5,5.71],[13.5,0]],"id":41419603},{"atb":[[36,0],[50,2.04]],"id":41419615},{"atb":[[5,0]],"id":41419611},{"atb":[[10,0]],"id":41419624},{"atb":[[9.2,12.2],[7,0]],"id":41419620},{"atb":[[15.5,6.9]],"id":41419587},{"atb":[[7.2,16.13],[5.2,0]],"id":41419632},{"atb":[[32,3.23],[26,0]],"id":41419599},{"atb":[[9.2,0],[12.5,8.7]],"id":41419628},{"atb":[[38,0],[55,6.93]],"id":41419595},{"atb":[[6.4,49.33],[8.4,49.5]],"id":41419608},{"atb":[[13.5,8],[9.4,8.9]],"id":41419637},{"atb":[[17,0],[23,4.55]],"id":41419616},{"atb":[[6.4,0],[8.4,40.41]],"id":41419612},{"atb":[[6.4,52.09]],"id":41419625},{"atb":[[34,0]],"id":41419592},{"atb":[[8.6,0],[11.5,9.52]],"id":41419621},{"atb":[[36,0],[50,2.04]],"id":41419588},{"atb":[[34,0],[48,2.13]],"id":41419600},{"atb":[[11,10]],"id":41419629},{"atb":[[18.5,0],[25,4.17]],"id":41419596}],"con":true,"img":false}]}
{"op":"mcm","clk":"5353369470","pt":1646213822329,"mc":[{"id":"1.195503864","rc":[{"atl":[[180,0],[190,4.95]],"id":41419634},{"atb":[[180,0.74]],"id":41419602},{"atl":[[190,0],[200,4.95]],"id":41419636},{"atb":[[75,9.9],[80,0],[95,4.95],[100,0]],"id":41419591}],"con":true,"img":false}]}
{"op":"mcm","clk":"5353369477","pt":1646213822383,"mc":[{"id":"1.195503864","rc":[{"atb":[[10,9.9],[10.5,0],[12,4.95],[12.5,0]],"id":41419623}],"con":true,"img":false}]}
{"op":"mcm","clk":"5353369518","pt":1646213823029,"mc":[{"id":"1.195503864","rc":[{"atl":[[250,4.95]],"id":41419591}],"con":true,"img":false}]}
{"op":"mcm","clk":"5353369541","pt":1646213823311,"mc":[{"id":"1.195503864","rc":[{"atb":[[170,0.93]],"id":41419602}],"con":true,"img":false}]}
{"op":"mcm","clk":"5353369617","pt":1646213824607,"mc":[{"id":"1.195503864","rc":[{"atl":[[40,0],[48,0]],"id":41419608}],"con":true,"img":false}]}
{"op":"mcm","clk":"5353369645","pt":1646213825017,"mc":[{"id":"1.195503864","rc":[{"atl":[[42,4.95],[50,9.9]],"id":41419608}],"con":true,"img":false}]}
{"op":"mcm","clk":"5353369747","pt":1646213826211,"mc":[{"id":"1.195503864","rc":[{"atl":[[250,0]],"id":41419591}],"con":true,"img":false}]}
{"op":"mcm","clk":"5353369795","pt":1646213826922,"mc":[{"id":"1.195503864","rc":[{"atl":[[830,2.19],[440,0]],"id":41419617},{"atl":[[330,0],[720,2.21]],"id":41419589},{"atl":[[900,2.17],[510,0]],"id":41419618},{"atl":[[350,0],[740,2.21]],"id":41419601},{"atl":[[530,0],[920,2.17]],"id":41419597},{"atl":[[790,2.2],[400,0]],"id":41419590},{"atl":[[380,0],[750,2.21]],"id":41419631},{"atl":[[520,0],[910,2.17]],"id":41419594},{"atl":[[390,0],[780,2.2]],"id":41419603},{"atl":[[350,0],[740,2.21]],"id":41419587},{"atl":[[410,0],[800,2.19]],"id":41419604},{"atl":[[830,2.19],[440,0]],"id":41419616},{"atl":[[840,2.19],[450,0]],"id":41419596}],"con":true,"img":false}]}
{"op":"mcm","clk":"5353369900","pt":1646213828831,"mc":[{"id":"1.195503864","rc":[{"atb":[[34,3.03],[26,0]],"id":41419594},{"atl":[[930,2]],"id":41419591},{"atl":[[150,0]],"id":41419604}],"con":true,"img":false}]}
{"op":"mcm","clk":"5353369903","pt":1646213828932,"mc":[{"id":"1.195503864","rc":[{"atb":[[36,0],[50,5.3]],"id":41419638},{"atl":[[940,0]],"id":41419591}],"con":true,"img":false}]}
{"op":"mcm","clk":"5353369911","pt":1646213829092,"mc":[{"id":"1.195503864","rc":[{"atl":[[240,0],[250,4.95]],"id":41419635},{"atl":[[210,4.95]],"id":41419636},{"atl":[[250,4.95]],"id":41419591},{"atl":[[160,4.95]],"id":41419604}],"con":true,"img":false}]}
{"op":"mcm","clk":"5353369918","pt":1646213829194,"mc":[{"id":"1.195503864","rc":[{"atl":[[200,0]],"id":41419636}],"con":true,"img":false}]}
{"op":"mcm","clk":"5353369941","pt":1646213829713,"mc":[{"id":"1.195503864","rc":[{"atl":[[260,0]],"id":41419635}],"con":true,"img":false}]}
{"op":"mcm","clk":"5353369959","pt":1646213830021,"mc":[{"id":"1.195503864","rc":[{"atl":[[680,3.84]],"id":41419635}],"con":true,"img":false}]}
{"op":"mcm","clk":"5353369967","pt":1646213830226,"mc":[{"id":"1.195503864","rc":[{"atl":[[250,0]],"id":41419591}],"con":true,"img":false}]}
{"op":"mcm","clk":"5353369981","pt":1646213830432,"mc":[{"id":"1.195503864","rc":[{"atl":[[680,1.84],[990,2.15]],"id":41419635}],"con":true,"img":false}]}
{"op":"mcm","clk":"5353370406","pt":1646213837242,"mc":[{"id":"1.195503864","rc":[{"atb":[[27,30.03]],"id":41419609},{"atl":[[65,7.43],[670,0]],"id":41419609},{"atb":[[80,12.34],[27,0]],"id":41419638},{"atb":[[20,7]],"id":41419617},{"atl":[[590,0],[170,9.51]],"id":41419622},{"atb":[[80,6.95],[60,24.62]],"id":41419618},{"atl":[[160,5.95]],"id":41419618},{"atb":[[24,0],[50,15.48]],"id":41419597},{"atl":[[38,9.23],[500,0]],"id":41419606},{"atb":[[90,3.26]],"id":41419602},{"atb":[[110,2.44]],"id":41419614},{"atb":[[9.2,31.99]],"id":41419610},{"atb":[[44,12.17]],"id":41419590},{"atl":[[140,6.09]],"id":41419590},{"atb":[[38,18],[19,7.4]],"id":41419631},{"atb":[[23,17.17]],"id":41419627},{"atl":[[60,7.64]],"id":41419627},{"atb":[[85,6.83]],"id":41419594},{"atb":[[40,9.01]],"id":41419640},{"atl":[[630,0],[210,8.08]],"id":41419607},{"atb":[[44,12.17]],"id":41419603},{"atb":[[75,19.73],[30,8.04]],"id":41419591},{"atb":[[19,17.3],[22,17.17]],"id":41419620},{"atl":[[130,11.83],[550,0]],"id":41419620},{"atb":[[11,17.98]],"id":41419632},{"atl":[[440,0]],"id":41419632},{"atb":[[21,6.65]],"id":41419628},{"atb":[[150,7.4],[110,2.44]],"id":41419595},{"atb":[[16,8.87]],"id":41419608},{"atl":[[150,1.06]],"id":41419604},{"atl":[[110,13.61]],"id":41419612},{"atl":[[470,0]],"id":41419625},{"atb":[[90,2.99]],"id":41419588},{"atl":[[65,7.43]],"id":41419629}],"con":true,"img":false}]}
{"op":"mcm","clk":"5353370410","pt":1646213837347,"mc":[{"id":"1.195503864","rc":[{"atb":[[32,10.06],[16.5,8.59]],"id":41419609},{"atl":[[250,7.1]],"id":41419609},{"atb":[[130,6.18]],"id":41419638},{"atb":[[70,11.1],[28,0]],"id":41419605},{"atb":[[75,7.09],[55,24.62],[28,8.63]],"id":41419634},{"atl":[[860,0.18]],"id":41419634},{"atb":[[44,15.48]],"id":41419617},{"atl":[[150,6.01]],"id":41419617},{"atb":[[90,16.16],[120,10.89]],"id":41419613},{"atb":[[100,3.26],[110,10.89]],"id":41419593},{"atb":[[17.5,8.07],[23,17.17]],"id":41419622},{"atl":[[55,7.89]],"id":41419622},{"atb":[[38,13.85],[21,6.65]],"id":41419589},{"atl":[[120,1.32]],"id":41419589},{"atb":[[22,0]],"id":41419618},{"atb":[[18,7.83],[42,12.17]],"id":41419601},{"atl":[[120,6.28]],"id":41419601},{"atb":[[11,31.99],[13,18.16],[5.9,27.18]],"id":41419630},{"atl":[[65,21.67],[23,12.15],[440,0]],"id":41419630},{"atb":[[95,6.63]],"id":41419597},{"atb":[[18.5,25.35],[9.4,15.85]],"id":41419626},{"atl":[[130,11.83],[550,0]],"id":41419626},{"atb":[[10,14.8],[27,25.35]],"id":41419639},{"atl":[[290,6.4],[80,6.95],[710,0]],"id":41419639},{"atl":[[90,14.21]],"id":41419606},{"atb":[[80,23.2],[100,6.55],[30,0]],"id":41419635},{"atl":[[250,5.59]],"id":41419635},{"atb":[[160,7.46],[180,1.63]],"id":41419602},{"atb":[[130,9.63]],"id":41419614},{"atb":[[10,22.56],[5.4,30.27]],"id":41419610},{"atl":[[16,15.52],[38,24.78],[360,0]],"id":41419610},{"atb":[[10,31.99],[5.5,29.59]],"id":41419623},{"atl":[[21,12.88],[430,0],[55,24.08]],"id":41419623},{"atb":[[22,6.34]],"id":41419590},{"atb":[[95,8.67],[29,0],[120,6.28]],"id":41419619},{"atb":[[85,3.26],[90,9.84]],"id":41419586},{"atb":[[50,8.19]],"id":41419631},{"atl":[[110,6.4]],"id":41419631},{"atb":[[34,0],[90,22.33],[120,6.28]],"id":41419598},{"atb":[[20,7]],"id":41419627},{"atl":[[560,0],[150,10.51]],"id":41419627},{"atb":[[65,23.4],[21,0]],"id":41419594},{"atl":[[170,5.89]],"id":41419594},{"atb":[[36,16.44],[11.5,0]],"id":41419640},{"atl":[[90,6.73],[360,5.54],[780,0]],"id":41419640},{"atb":[[18,7.83],[22,29.48]],"id":41419607},{"atb":[[65,24.5],[85,6.83],[25,5.54]],"id":41419636},{"atl":[[910,1.56],[940,0],[510,0.31]],"id":41419636},{"atb":[[19,7.4]],"id":41419603},{"atl":[[140,6.09]],"id":41419603},{"atb":[[90,3.26],[95,22.43]],"id":41419615},{"atb":[[9.6,31.99],[11,20.8],[5.7,28.33]],"id":41419611},{"atl":[[20,13.29],[50,24.12],[410,0]],"id":41419611},{"atb":[[18,7.83],[27,31.72]],"id":41419624},{"atl":[[80,6.95],[320,5.98],[740,0]],"id":41419624},{"atb":[[95,6.63]],"id":41419591},{"atl":[[50,3.23]],"id":41419620},{"atb":[[38,13.85],[19.5,7.19]],"id":41419587},{"atl":[[110,6.4]],"id":41419587},{"atb":[[6.6,23.78]],"id":41419632},{"atl":[[65,16.71],[24,11.84]],"id":41419632},{"atb":[[26,29.48]],"id":41419628},{"atl":[[280,6.55],[670,0]],"id":41419628},{"atb":[[17,17.17]],"id":41419608},{"atl":[[530,0],[42,8.82],[110,13.61]],"id":41419608},{"atb":[[28,31.77],[9.4,0]],"id":41419637},{"atl":[[310,6.11],[80,6.95],[730,0]],"id":41419637},{"atb":[[20,12.26],[46,12.17]],"id":41419604},{"atl":[[410,2]],"id":41419604},{"atb":[[18.5,7.61],[42,15.48]],"id":41419616},{"atl":[[130,6.18]],"id":41419616},{"atb":[[16,31.99],[18,14.27],[8.4,31.51]],"id":41419612},{"atl":[[530,0],[34,9.76]],"id":41419612},{"atb":[[6.4,43.18],[10.5,35.26]],"id":41419625},{"atl":[[75,19.04],[24,11.84]],"id":41419625},{"atb":[[19.5,7.19],[26,17.17]],"id":41419621},{"atl":[[630,0],[210,8.08]],"id":41419621},{"atb":[[120,7.48]],"id":41419588},{"atb":[[10,14.8],[27,11.05]],"id":41419633},{"atl":[[570,0],[160,9.98],[48,8.32]],"id":41419633},{"atb":[[95,3.26],[110,10.89]],"id":41419600},{"atb":[[18.5,7.61],[23,17.17]],"id":41419629},{"atl":[[580,0],[180,9.09]],"id":41419629},{"atb":[[22,6.34],[48,12.17]],"id":41419596},{"atl":[[190,0.83]],"id":41419596}],"con":true,"img":false}]}
{"op":"mcm","clk":"5353370413","pt":1646213837403,"mc":[{"id":"1.195503864","rc":[{"atl":[[800,0.19]],"id":41419604}],"con":true,"img":false}]}
{"op":"mcm","clk":"5353370416","pt":1646213837505,"mc":[{"id":"1.195503864","rc":[{"atl":[[330,2],[720,0.21]],"id":41419589},{"atl":[[40,9.01]],"id":41419626},{"atl":[[70,7.25]],"id":41419621}],"con":true,"img":false}]}
{"op":"mcm","clk":"5353370425","pt":1646213837714,"mc":[{"id":"1.195503864","rc":[{"atl":[[870,3.64]],"id":41419634},{"atl":[[680,0],[990,3.43]],"id":41419635},{"atl":[[830,0]],"id":41419604},{"atl":[[840,3.7],[870,0]],"id":41419596}],"con":true,"img":false}]}
{"op":"mcm","clk":"5353370431","pt":1646213837815,"mc":[{"id":"1.195503864","rc":[{"atl":[[900,0]],"id":41419634},{"atl":[[750,0]],"id":41419589},{"atb":[[12,19.36]],"id":41419623},{"atl":[[800,1.78]],"id":41419604}],"con":true,"img":false}]}
{"op":"mcm","clk":"5353370439","pt":1646213837919,"mc":[{"id":"1.195503864","rc":[{"atl":[[720,1.98]],"id":41419589},{"atb":[[65,2.72]],"id":41419618},{"atl":[[790,2]],"id":41419590},{"atl":[[530,0]],"id":41419627}],"con":true,"img":false}]}
{"op":"mcm","clk":"5353370444","pt":1646213838018,"mc":[{"id":"1.195503864","rc":[{"atl":[[640,0]],"id":41419609},{"atb":[[80,10.34]],"id":41419638},{"atb":[[70,2.72]],"id":41419634},{"atl":[[870,3.46]],"id":41419634},{"atl":[[830,2]],"id":41419617},{"atl":[[560,0]],"id":41419622},{"atl":[[720,1.77]],"id":41419589},{"atl":[[900,2]],"id":41419618},{"atl":[[740,2]],"id":41419601},{"atb":[[11.5,2.72]],"id":41419630},{"atb":[[75,12.63]],"id":41419597},{"atl":[[210,5.71]],"id":41419597},{"atl":[[680,0]],"id":41419639},{"atl":[[470,0]],"id":41419606},{"atb":[[85,0]],"id":41419635},{"atl":[[990,3.28]],"id":41419635},{"atb":[[170,0]],"id":41419602},{"atb":[[9.6,2.72]],"id":41419610},{"atl":[[330,0]],"id":41419610},{"atl":[[400,0]],"id":41419623},{"atb":[[100,0]],"id":41419619},{"atb":[[38,13.71]],"id":41419631},{"atl":[[750,2]],"id":41419631},{"atb":[[110,2.72]],"id":41419598},{"atb":[[70,0]],"id":41419594},{"atl":[[910,2]],"id":41419594},{"atb":[[38,0]],"id":41419640},{"atl":[[750,0]],"id":41419640},{"atb":[[75,2.72]],"id":41419636},{"atl":[[910,1.39]],"id":41419636},{"atl":[[780,2]],"id":41419603},{"atb":[[10,2.72]],"id":41419611},{"atl":[[380,0]],"id":41419611},{"atl":[[710,0]],"id":41419624},{"atb":[[85,2.72]],"id":41419591},{"atl":[[520,0]],"id":41419620},{"atl":[[740,2]],"id":41419587},{"atl":[[410,0]],"id":41419632},{"atl":[[500,0]],"id":41419608},{"atl":[[700,0]],"id":41419637},{"atl":[[800,1.59]],"id":41419604},{"atl":[[830,2]],"id":41419616},{"atb":[[17.5,2.72]],"id":41419612},{"atl":[[500,0]],"id":41419612},{"atl":[[440,0]],"id":41419625},{"atb":[[23,31.13],[25,2.72]],"id":41419633},{"atl":[[540,0]],"id":41419633},{"atl":[[550,0]],"id":41419629},{"atl":[[840,3.51]],"id":41419596}],"con":true,"img":false}]}
{"op":"mcm","clk":"5353370447","pt":1646213838125,"mc":[{"id":"1.195503864","rc":[{"atl":[[410,0]],"id":41419630}],"con":true,"img":false}]}
{"op":"mcm","clk":"5353370458","pt":1646213838329,"mc":[{"id":"1.195503864","rc":[{"atb":[[28,2.72]],"id":41419609},{"atl":[[520,0]],"id":41419626},{"atl":[[600,0]],"id":41419621}],"con":true,"img":false}]}
{"op":"mcm","clk":"5353370467","pt":1646213838533,"mc":[{"id":"1.195503864","rc":[{"atb":[[11,2.72]],"id":41419623}],"con":true,"img":false}]}
{"op":"mcm","clk":"5353370490","pt":1646213838970,"mc":[{"id":"1.195503864","rc":[{"atl":[[920,2]],"id":41419597}],"con":true,"img":false}]}
{"op":"mcm","clk":"5353370619","pt":1646213841410,"mc":[{"id":"1.195503864","rc":[{"atl":[[260,4.95]],"id":41419591}],"con":true,"img":false}]}
{"op":"mcm","clk":"5353370624","pt":1646213841512,"mc":[{"id":"1.195503864","rc":[{"atl":[[530,2]],"id":41419591}],"con":true,"img":false}]}
{"op":"mcm","clk":"5353370629","pt":1646213841619,"mc":[{"id":"1.195503864","rc":[{"atl":[[930,0]],"id":41419591}],"con":true,"img":false}]}
{"op":"mcm","clk":"5353370650","pt":1646213841926,"mc":[{"id":"1.195503864","rc":[{"atl":[[950,0]],"id":41419591}],"con":true,"img":false}]}
{"op":"mcm","clk":"5353370666","pt":1646213842234,"mc":[{"id":"1.195503864","rc":[{"atl":[[260,5.56],[930,1.37]],"id":41419591}],"con":true,"img":false}]}
{"op":"mcm","clk":"5353370712","pt":1646213842908,"mc":[{"id":"1.195503864","rc":[{"atl":[[920,0]],"id":41419591}],"con":true,"img":false}]}
{"op":"mcm","clk":"5353370798","pt":1646213844808,"mc":[{"id":"1.195503864","rc":[{"atb":[[80,12.63],[55,19.88]],"id":41419635},{"atb":[[130,9.18],[160,4.95]],"id":41419602},{"atb":[[65,12.63],[46,16.88]],"id":41419594},{"atb":[[32,38.04],[36,2.72]],"id":41419640}],"con":true,"img":false}]}
{"op":"mcm","clk":"5353370803","pt":1646213844915,"mc":[{"id":"1.195503864","rc":[{"atb":[[90,24.35],[95,2.72]],"id":41419619}],"con":true,"img":false}]}
{"op":"mcm","clk":"5353370827","pt":1646213845330,"mc":[{"id":"1.195503864","rc":[{"atb":[[180,0.74]],"id":41419602}],"con":true,"img":false}]}
{"op":"mcm","clk":"5353370848","pt":1646213845638,"mc":[{"id":"1.195503864","rc":[{"atl":[[270,4.81],[990,2]],"id":41419635}],"con":true,"img":false}]}
{"op":"mcm","clk":"5353370865","pt":1646213845842,"mc":[{"id":"1.195503864","rc":[{"atl":[[690,2],[990,0]],"id":41419635}],"con":true,"img":false}]}
{"op":"mcm","clk":"5353370888","pt":1646213846355,"mc":[{"id":"1.195503864","rc":[{"atb":[[170,0.93]],"id":41419602}],"con":true,"img":false}]}
{"op":"mcm","clk":"5353370916","pt":1646213846770,"mc":[{"id":"1.195503864","rc":[{"atl":[[530,0],[920,2]],"id":41419591}],"con":true,"img":false}]}
{"op":"mcm","clk":"5353370925","pt":1646213846830,"mc":[{"id":"1.195503864","rc":[{"atl":[[260,4.95]],"id":41419605},{"atb":[[10,22.08],[12,14.41]],"id":41419623},{"atl":[[70,4.95],[80,0],[90,9.9],[60,0]],"id":41419627},{"atl":[[80,0],[90,4.95],[100,0],[120,9.9]],"id":41419628},{"atl":[[65,0],[75,4.95],[85,0],[95,9.9]],"id":41419629}],"con":true,"img":false}]}
{"op":"mcm","clk":"5353370930","pt":1646213846929,"mc":[{"id":"1.195503864","rc":[{"atl":[[550,2]],"id":41419605}],"con":true,"img":false}]}
{"op":"mcm","clk":"5353370939","pt":1646213847039,"mc":[{"id":"1.195503864","rc":[{"atl":[[950,0]],"id":41419605},{"atb":[[11.5,4.95],[12,0],[9.8,9.9]],"id":41419623}],"con":true,"img":false}]}
{"op":"mcm","clk":"5353370955","pt":1646213847342,"mc":[{"id":"1.195503864","rc":[{"atl":[[950,1.36],[970,0]],"id":41419605},{"atl":[[85,1.88]],"id":41419628}],"con":true,"img":false}]}
{"op":"mcm","clk":"5353370983","pt":1646213847754,"mc":[{"id":"1.195503864","rc":[{"atl":[[250,0.63]],"id":41419605},{"atl":[[70,7.25]],"id":41419627},{"atl":[[75,7.09]],"id":41419629}],"con":true,"img":false}]}
{"op":"mcm","clk":"5353371002","pt":1646213848062,"mc":[{"id":"1.195503864","rc":[{"atl":[[260,0]],"id":41419605},{"atb":[[11,18.57]],"id":41419623},{"atb":[[32,7.83]],"id":41419607},{"atl":[[60,7.64]],"id":41419607},{"atl":[[640,0]],"id":41419628}],"con":true,"img":false}]}
{"op":"mcm","clk":"5353371043","pt":1646213848527,"mc":[{"id":"1.195503864","rc":[{"atl":[[940,0],[250,0]],"id":41419605}],"con":true,"img":false}]}
{"op":"mcm","clk":"5353371057","pt":1646213848785,"mc":[{"id":"1.195503864","rc":[{"atl":[[600,0]],"id":41419607}],"con":true,"img":false}]}
{"op":"mcm","clk":"5353371090","pt":1646213849252,"mc":[{"id":"1.195503864","rc":[{"atl":[[540,0.29]],"id":41419605}],"con":true,"img":false}]}
{"op":"mcm","clk":"5353371152","pt":1646213850128,"mc":[{"id":"1.195503864","rc":[{"atl":[[190,0]],"id":41419634}],"con":true,"img":false}]}
{"op":"mcm","clk":"5353371167","pt":1646213850439,"mc":[{"id":"1.195503864","rc":[{"atl":[[200,4.95]],"id":41419634},{"atl":[[120,0]],"id":41419589},{"atl":[[260,4.95],[250,0]],"id":41419635},{"atl":[[50,0]],"id":41419620}],"con":true,"img":false}]}
{"op":"mcm","clk":"5353371172","pt":1646213850543,"mc":[{"id":"1.195503864","rc":[{"atl":[[870,1.46],[480,2]],"id":41419634}],"con":true,"img":false}]}
{"op":"mcm","clk":"5353371185","pt":1646213850749,"mc":[{"id":"1.195503864","rc":[{"atl":[[870,0],[880,1.48]],"id":41419634}],"con":true,"img":false}]}
{"op":"mcm","clk":"5353371208","pt":1646213851157,"mc":[{"id":"1.195503864","rc":[{"atb":[[32,2.72]],"id":41419607},{"atl":[[60,4.95]],"id":41419607}],"con":true,"img":false}]}
{"op":"mcm","clk":"5353371227","pt":1646213851465,"mc":[{"id":"1.195503864","rc":[{"atl":[[130,6.18]],"id":41419589},{"atl":[[260,5.56]],"id":41419635},{"atl":[[260,0]],"id":41419591},{"atl":[[70,2.29]],"id":41419620},{"atl":[[190,0]],"id":41419596}],"con":true,"img":false}]}
{"op":"mcm","clk":"5353371238","pt":1646213851625,"mc":[{"id":"1.195503864","rc":[{"atl":[[330,0],[720,3.77]],"id":41419589}],"con":true,"img":false}]}
{"op":"mcm","clk":"5353371250","pt":1646213851835,"mc":[{"id":"1.195503864","rc":[{"atb":[[26,14.56]],"id":41419607},{"atl":[[920,0],[930,3.37]],"id":41419591}],"con":true,"img":false}]}
{"op":"mcm","clk":"5353371261","pt":1646213852040,"mc":[{"id":"1.195503864","rc":[{"atl":[[940,2]],"id":41419605}],"con":true,"img":false}]}
{"op":"mcm","clk":"5353371267","pt":1646213852141,"mc":[{"id":"1.195503864","rc":[{"atl":[[550,0]],"id":41419605},{"atl":[[920,0.17],[930,2],[940,1.39]],"id":41419591},{"atl":[[200,5.74]],"id":41419596}],"con":true,"img":false}]}
{"op":"mcm","clk":"5353371291","pt":1646213852655,"mc":[{"id":"1.195503864","rc":[{"atb":[[130,2.72],[180,1.63]],"id":41419602},{"atl":[[520,4.53],[210,5.71],[910,0]],"id":41419636},{"atl":[[130,2],[75,22.12]],"id":41419620},{"atl":[[280,2],[120,20.92]],"id":41419628}],"con":true,"img":false}]}
{"op":"mcm","clk":"5353371310","pt":1646213852961,"mc":[{"id":"1.195503864","rc":[{"atl":[[200,5.74]],"id":41419634},{"atb":[[160,7.46]],"id":41419602},{"atl":[[55,7.89]],"id":41419620}],"con":true,"img":false}]}
{"op":"mcm","clk":"5353371322","pt":1646213853168,"mc":[{"id":"1.195503864","rc":[{"atl":[[860,1.71],[880,0]],"id":41419634},{"atl":[[270,0],[690,3.9]],"id":41419635},{"atb":[[11.5,20.05]],"id":41419623},{"atl":[[800,0]],"id":41419604},{"atl":[[840,2],[220,6]],"id":41419596}],"con":true,"img":false}]}
{"op":"mcm","clk":"5353371337","pt":1646213853273,"mc":[{"id":"1.195503864","rc":[{"atl":[[410,5.22]],"id":41419604}],"con":true,"img":false}]}
{"op":"mcm","clk":"5353371347","pt":1646213853374,"mc":[{"id":"1.195503864","rc":[{"atl":[[840,0],[450,2]],"id":41419596}],"con":true,"img":false}]}
{"op":"mcm","clk":"5353371355","pt":1646213853433,"mc":[{"id":"1.195503864","rc":[{"atl":[[150,8.82],[720,2]],"id":41419589}],"con":true,"img":false}]}
{"op":"mcm","clk":"5353371362","pt":1646213853534,"mc":[{"id":"1.195503864","rc":[{"atb":[[170,0]],"id":41419602},{"atl":[[510,0]],"id":41419636}],"con":true,"img":false}]}
{"op":"mcm","clk":"5353371384","pt":1646213853841,"mc":[{"id":"1.195503864","rc":[{"atl":[[70,0]],"id":41419620}],"con":true,"img":false}]}
{"op":"mcm","clk":"5353371393","pt":1646213853944,"mc":[{"id":"1.195503864","rc":[{"atl":[[860,1.53]],"id":41419634}],"con":true,"img":false}]}
{"op":"mcm","clk":"5353371412","pt":1646213854249,"mc":[{"id":"1.195503864","rc":[{"atb":[[11,2.72]],"id":41419623}],"con":true,"img":false}]}
{"op":"mcm","clk":"5353371497","pt":1646213855640,"mc":[{"id":"1.195503864","rc":[{"atl":[[860,3.53],[480,0]],"id":41419634}],"con":true,"img":false}]}
{"op":"mcm","clk":"5353371623","pt":1646213857855,"mc":[{"id":"1.195503864","rc":[{"atl":[[150,0],[160,4.95]],"id":41419617},{"atl":[[60,7.64]],"id":41419607},{"atl":[[210,0],[220,4.95]],"id":41419636},{"atl":[[270,4.95]],"id":41419591}],"con":true,"img":false}]}
{"op":"mcm","clk":"5353371632","pt":1646213857951,"mc":[{"id":"1.195503864","rc":[{"atb":[[70,5.02]],"id":41419596}],"con":true,"img":false}]}
{"op":"mcm","clk":"5353371639","pt":1646213858056,"mc":[{"id":"1.195503864","rc":[{"atl":[[830,0],[440,2]],"id":41419617},{"atl":[[75,0],[80,9.9],[55,2.93],[60,4.95]],"id":41419622},{"atl":[[130,4.95],[120,0]],"id":41419601},{"atl":[[38,0],[40,4.95],[46,0],[48,9.9]],"id":41419606},{"atl":[[140,0],[150,4.95]],"id":41419603},{"atl":[[530,2],[930,0]],"id":41419591}],"con":true,"img":false}]}
{"op":"mcm","clk":"5353371646","pt":1646213858156,"mc":[{"id":"1.195503864","rc":[{"atl":[[55,0]],"id":41419622},{"atl":[[260,4.95]],"id":41419635}],"con":true,"img":false}]}
{"op":"mcm","clk":"5353371655","pt":1646213858263,"mc":[{"id":"1.195503864","rc":[{"atl":[[350,2],[740,0]],"id":41419601},{"atl":[[260,0],[270,4.95]],"id":41419635},{"atl":[[780,0],[390,2]],"id":41419603}],"con":true,"img":false}]}
{"op":"mcm","clk":"5353371666","pt":1646213858364,"mc":[{"id":"1.195503864","rc":[{"atl":[[930,1.42]],"id":41419591}],"con":true,"img":false}]}
{"op":"mcm","clk":"5353371673","pt":1646213858468,"mc":[{"id":"1.195503864","rc":[{"atl":[[940,0]],"id":41419591}],"con":true,"img":false}]}
{"op":"mcm","clk":"5353371682","pt":1646213858570,"mc":[{"id":"1.195503864","rc":[{"atl":[[430,0.37]],"id":41419617},{"atl":[[80,22.12],[170,2]],"id":41419622},{"atl":[[220,5.67]],"id":41419636},{"atl":[[270,0]],"id":41419591}],"con":true,"img":false}]}
{"op":"mcm","clk":"5353371695","pt":1646213858776,"mc":[{"id":"1.195503864","rc":[{"atl":[[130,6.18]],"id":41419601},{"atl":[[150,6.01]],"id":41419603}],"con":true,"img":false}]}
{"op":"mcm","clk":"5353371703","pt":1646213858879,"mc":[{"id":"1.195503864","rc":[{"atl":[[46,3.52]],"id":41419606},{"atl":[[270,5.54]],"id":41419635}],"con":true,"img":false}]}
{"op":"mcm","clk":"5353371709","pt":1646213858935,"mc":[{"id":"1.195503864","rc":[{"atl":[[160,0.99]],"id":41419622}],"con":true,"img":false}]}
{"op":"mcm","clk":"5353371716","pt":1646213859035,"mc":[{"id":"1.195503864","rc":[{"atl":[[210,4.95]],"id":41419634},{"atl":[[520,0.3]],"id":41419591}],"con":true,"img":false}]}
{"op":"mcm","clk":"5353371721","pt":1646213859142,"mc":[{"id":"1.195503864","rc":[{"atl":[[200,0],[470,2]],"id":41419634},{"atl":[[860,0],[440,5.03]],"id":41419617}],"con":true,"img":false}]}
{"op":"mcm","clk":"5353371726","pt":1646213859242,"mc":[{"id":"1.195503864","rc":[{"atl":[[860,1.53]],"id":41419634}],"con":true,"img":false}]}
{"op":"mcm","clk":"5353371736","pt":1646213859448,"mc":[{"id":"1.195503864","rc":[{"atl":[[90,2],[48,22.49]],"id":41419606}],"con":true,"img":false}]}
{"op":"mcm","clk":"5353371754","pt":1646213859760,"mc":[{"id":"1.195503864","rc":[{"atl":[[160,0.99],[170,4.95]],"id":41419618},{"atl":[[920,0]],"id":41419591},{"atl":[[130,1.23],[140,4.95]],"id":41419616}],"con":true,"img":false}]}
{"op":"mcm","clk":"5353371766","pt":1646213859963,"mc":[{"id":"1.195503864","rc":[{"atl":[[520,2],[900,0]],"id":41419618},{"atl":[[830,0],[440,2]],"id":41419616}],"con":true,"img":false}]}
{"op":"mcm","clk":"5353371781","pt":1646213860170,"mc":[{"id":"1.195503864","rc":[{"atl":[[210,5.71]],"id":41419634},{"atl":[[130,12.32],[75,9.9]],"id":41419620}],"con":true,"img":false}]}
{"op":"mcm","clk":"5353371804","pt":1646213860478,"mc":[{"id":"1.195503864","rc":[{"atl":[[900,1.48],[930,0]],"id":41419618},{"atb":[[130,9.18],[160,4.95]],"id":41419602},{"atl":[[830,1.6],[860,0]],"id":41419616}],"con":true,"img":false}]}
{"op":"mcm","clk":"5353371827","pt":1646213860843,"mc":[{"id":"1.195503864","rc":[{"atl":[[150,0],[720,3.85]],"id":41419589},{"atl":[[290,4.63],[690,2]],"id":41419635},{"atl":[[220,0],[450,4.98]],"id":41419596}],"con":true,"img":false}]}
{"op":"mcm","clk":"5353371847","pt":1646213861255,"mc":[{"id":"1.195503864","rc":[{"atb":[[180,0.74]],"id":41419602}],"con":true,"img":false}]}
{"op":"mcm","clk":"5353371865","pt":1646213861563,"mc":[{"id":"1.195503864","rc":[{"atl":[[720,2]],"id":41419589}],"con":true,"img":false}]}
{"op":"mcm","clk":"5353371892","pt":1646213861975,"mc":[{"id":"1.195503864","rc":[{"atl":[[450,2]],"id":41419596}],"con":true,"img":false}]}
{"op":"mcm","clk":"5353371901","pt":1646213862179,"mc":[{"id":"1.195503864","rc":[{"atb":[[170,0.93]],"id":41419602}],"con":true,"img":false}]}
{"op":"mcm","clk":"5353371966","pt":1646213863161,"mc":[{"id":"1.195503864","rc":[{"atb":[[32,7.83]],"id":41419607},{"atl":[[920,2]],"id":41419591}],"con":true,"img":false}]}
{"op":"mcm","clk":"5353371974","pt":1646213863265,"mc":[{"id":"1.195503864","rc":[{"atl":[[530,0]],"id":41419591}],"con":true,"img":false}]}
{"op":"mcm","clk":"5353371982","pt":1646213863368,"mc":[{"id":"1.195503864","rc":[{"atb":[[70,7.67],[75,2.14],[50,9.9],[55,14.71]],"id":41419634},{"atl":[[270,4.95]],"id":41419591},{"atb":[[19,7.4],[21,4.95],[22,12.21]],"id":41419620},{"atb":[[70,2.72]],"id":41419596}],"con":true,"img":false}]}
{"op":"mcm","clk":"5353371988","pt":1646213863472,"mc":[{"id":"1.195503864","rc":[{"atl":[[350,0],[750,2]],"id":41419601},{"atl":[[390,0],[790,2]],"id":41419603}],"con":true,"img":false}]}
{"op":"mcm","clk":"5353371995","pt":1646213863574,"mc":[{"id":"1.195503864","rc":[{"atl":[[130,0]],"id":41419616}],"con":true,"img":false}]}
{"op":"mcm","clk":"5353372031","pt":1646213863945,"mc":[{"id":"1.195503864","rc":[{"atb":[[26,8.22]],"id":41419607}],"con":true,"img":false}]}
{"op":"mcm","clk":"5353372056","pt":1646213864254,"mc":[{"id":"1.195503864","rc":[{"atl":[[860,3.53],[470,0]],"id":41419634},{"atb":[[60,7.64]],"id":41419596}],"con":true,"img":false}]}
{"op":"mcm","clk":"5353372082","pt":1646213864567,"mc":[{"id":"1.195503864","rc":[{"atl":[[140,6.09]],"id":41419616}],"con":true,"img":false}]}
{"op":"mcm","clk":"5353372116","pt":1646213865176,"mc":[{"id":"1.195503864","rc":[{"atl":[[830,3.6],[440,0]],"id":41419616}],"con":true,"img":false}]}
{"op":"mcm","clk":"5353372164","pt":1646213865955,"mc":[{"id":"1.195503864","rc":[{"atl":[[860,2]],"id":41419634}],"con":true,"img":false}]}
{"op":"mcm","clk":"5353372170","pt":1646213866060,"mc":[{"id":"1.195503864","rc":[{"atl":[[230,5.9]],"id":41419634},{"atl":[[80,9.9],[160,9.48]],"id":41419622}],"con":true,"img":false}]}
{"op":"mcm","clk":"5353372177","pt":1646213866168,"mc":[{"id":"1.195503864","rc":[{"atl":[[860,0],[470,2]],"id":41419634}],"con":true,"img":false}]}
{"op":"mcm","clk":"5353372255","pt":1646213867292,"mc":[{"id":"1.195503864","rc":[{"atl":[[270,5.54],[920,3.47]],"id":41419591}],"con":true,"img":false}]}
{"op":"mcm","clk":"5353372260","pt":1646213867358,"mc":[{"id":"1.195503864","rc":[{"atl":[[930,0]],"id":41419591}],"con":true,"img":false}]}
{"op":"mcm","clk":"5353372283","pt":1646213867662,"mc":[{"id":"1.195503864","rc":[{"atb":[[180,1.63]],"id":41419602}],"con":true,"img":false}]}
{"op":"mcm","clk":"5353372306","pt":1646213868066,"mc":[{"id":"1.195503864","rc":[{"atb":[[130,2.72],[160,7.46]],"id":41419602},{"atl":[[520,2],[240,5.67]],"id":41419636},{"atl":[[520,0]],"id":41419591}],"con":true,"img":false}]}
{"op":"mcm","clk":"5353372326","pt":1646213868374,"mc":[{"id":"1.195503864","rc":[{"atl":[[290,0],[690,3.97]],"id":41419635},{"atl":[[220,6.2]],"id":41419596}],"con":true,"img":false}]}
{"op":"mcm","clk":"5353372332","pt":1646213868476,"mc":[{"id":"1.195503864","rc":[{"atb":[[170,0]],"id":41419602}],"con":true,"img":false}]}
{"op":"mcm","clk":"5353372347","pt":1646213868681,"mc":[{"id":"1.195503864","rc":[{"atl":[[150,9.1]],"id":41419589}],"con":true,"img":false}]}
{"op":"mcm","clk":"5353372353","pt":1646213868782,"mc":[{"id":"1.195503864","rc":[{"atl":[[320,2]],"id":41419589}],"con":true,"img":false}]}
{"op":"mcm","clk":"5353372362","pt":1646213868987,"mc":[{"id":"1.195503864","rc":[{"atl":[[720,0]],"id":41419589}],"con":true,"img":false}]}
{"op":"mcm","clk":"5353372367","pt":1646213869089,"mc":[{"id":"1.195503864","rc":[{"atl":[[270,0],[920,2]],"id":41419591}],"con":true,"img":false}]}
{"op":"mcm","clk":"5353372385","pt":1646213869454,"mc":[{"id":"1.195503864","rc":[{"atl":[[690,2]],"id":41419635}],"con":true,"img":false}]}
{"op":"mcm","clk":"5353372408","pt":1646213869764,"mc":[{"id":"1.195503864","rc":[{"atl":[[910,0.17]],"id":41419591}],"con":true,"img":false}]}
{"op":"mcm","clk":"5353372548","pt":1646213872378,"mc":[{"id":"1.195503864","rc":[{"atl":[[270,4.95]],"id":41419591}],"con":true,"img":false}]}
{"op":"mcm","clk":"5353372557","pt":1646213872507,"mc":[{"id":"1.195503864","rc":[{"atl":[[530,2]],"id":41419591}],"con":true,"img":false}]}
{"op":"mcm","clk":"5353372566","pt":1646213872668,"mc":[{"id":"1.195503864","rc":[{"atl":[[920,0]],"id":41419591}],"con":true,"img":false}]}
{"op":"mcm","clk":"5353372574","pt":1646213872777,"mc":[{"id":"1.195503864","rc":[{"atl":[[530,0],[910,2.17]],"id":41419591}],"con":true,"img":false}]}
{"op":"mcm","clk":"5353372577","pt":1646213872872,"mc":[{"id":"1.195503864","rc":[{"atb":[[70,5.02]],"id":41419596}],"con":true,"img":false}]}
{"op":"mcm","clk":"5353372597","pt":1646213873286,"mc":[{"id":"1.195503864","rc":[{"atl":[[290,4.75]],"id":41419591}],"con":true,"img":false}]}
{"op":"mcm","clk":"5353372622","pt":1646213873697,"mc":[{"id":"1.195503864","rc":[{"atl":[[230,0],[470,4.92]],"id":41419634},{"atl":[[160,5.95]],"id":41419617},{"atb":[[60,4.95]],"id":41419596}],"con":true,"img":false}]}
{"op":"mcm","clk":"5353372639","pt":1646213873859,"mc":[{"id":"1.195503864","rc":[{"atl":[[60,7.64]],"id":41419622}],"con":true,"img":false}]}
{"op":"mcm","clk":"5353372646","pt":1646213873965,"mc":[{"id":"1.195503864","rc":[{"atl":[[40,9.01]],"id":41419606}],"con":true,"img":false}]}
{"op":"mcm","clk":"5353372668","pt":1646213874275,"mc":[{"id":"1.195503864","rc":[{"atl":[[270,5.54]],"id":41419591}],"con":true,"img":false}]}
{"op":"mcm","clk":"5353372685","pt":1646213874584,"mc":[{"id":"1.195503864","rc":[{"atl":[[430,0]],"id":41419617},{"atl":[[160,8.49]],"id":41419622},{"atl":[[910,3.68]],"id":41419591}],"con":true,"img":false}]}
{"op":"mcm","clk":"5353372696","pt":1646213874789,"mc":[{"id":"1.195503864","rc":[{"atl":[[290,0]],"id":41419591}],"con":true,"img":false}]}
{"op":"mcm","clk":"5353372701","pt":1646213874894,"mc":[{"id":"1.195503864","rc":[{"atl":[[46,0]],"id":41419606}],"con":true,"img":false}]}
{"op":"mcm","clk":"5353372724","pt":1646213875158,"mc":[{"id":"1.195503864","rc":[{"atl":[[180,7.68],[440,2]],"id":41419617},{"atl":[[910,3.5]],"id":41419591}],"con":true,"img":false}]}
{"op":"mcm","clk":"5353372738","pt":1646213875362,"mc":[{"id":"1.195503864","rc":[{"atl":[[90,17.4],[48,9.9]],"id":41419606},{"atb":[[130,9.18],[160,4.95]],"id":41419602},{"atl":[[520,4.65]],"id":41419636}],"con":true,"img":false}]}
{"op":"mcm","clk":"5353372744","pt":1646213875468,"mc":[{"id":"1.195503864","rc":[{"atl":[[520,4.65],[900,0]],"id":41419618},{"atl":[[240,0]],"id":41419636},{"atl":[[910,2]],"id":41419591},{"atl":[[160,8.65],[830,2]],"id":41419616}],"con":true,"img":false}]}
{"op":"mcm","clk":"5353372751","pt":1646213875577,"mc":[{"id":"1.195503864","rc":[{"atl":[[830,0],[430,2]],"id":41419616}],"con":true,"img":false}]}
{"op":"mcm","clk":"5353372758","pt":1646213875673,"mc":[{"id":"1.195503864","rc":[{"atl":[[220,0],[450,5.07]],"id":41419596}],"con":true,"img":false}]}
{"op":"mcm","clk":"5353372767","pt":1646213875777,"mc":[{"id":"1.195503864","rc":[{"atb":[[180,0.74]],"id":41419602}],"con":true,"img":false}]}
{"op":"mcm","clk":"5353372773","pt":1646213875877,"mc":[{"id":"1.195503864","rc":[{"atl":[[290,4.77]],"id":41419635}],"con":true,"img":false}]}
{"op":"mcm","clk":"5353372779","pt":1646213875984,"mc":[{"id":"1.195503864","rc":[{"atl":[[180,0]],"id":41419617},{"atl":[[150,0],[320,6.32]],"id":41419589}],"con":true,"img":false}]}
{"op":"mcm","clk":"5353372791","pt":1646213876188,"mc":[{"id":"1.195503864","rc":[{"atl":[[520,2]],"id":41419636}],"con":true,"img":false}]}
{"op":"mcm","clk":"5353372800","pt":1646213876392,"mc":[{"id":"1.195503864","rc":[{"atl":[[160,0]],"id":41419616}],"con":true,"img":false}]}
{"op":"mcm","clk":"5353372807","pt":1646213876494,"mc":[{"id":"1.195503864","rc":[{"atb":[[170,0.93]],"id":41419602}],"con":true,"img":false}]}
{"op":"mcm","clk":"5353372828","pt":1646213876758,"mc":[{"id":"1.195503864","rc":[{"atl":[[320,2]],"id":41419589}],"con":true,"img":false}]}
{"op":"mcm","clk":"5353372909","pt":1646213878100,"mc":[{"id":"1.195503864","rc":[{"atl":[[260,4.95]],"id":41419605}],"con":true,"img":false}]}
{"op":"mcm","clk":"5353372916","pt":1646213878205,"mc":[{"id":"1.195503864","rc":[{"atl":[[550,2]],"id":41419605}],"con":true,"img":false}]}
{"op":"mcm","clk":"5353372925","pt":1646213878305,"mc":[{"id":"1.195503864","rc":[{"atl":[[940,0]],"id":41419605}],"con":true,"img":false}]}
{"op":"mcm","clk":"5353372935","pt":1646213878466,"mc":[{"id":"1.195503864","rc":[{"atl":[[950,0]],"id":41419605}],"con":true,"img":false}]}
{"op":"mcm","clk":"5353372957","pt":1646213878882,"mc":[{"id":"1.195503864","rc":[{"atl":[[260,5.56],[940,1.47]],"id":41419605}],"con":true,"img":false}]}
{"op":"mcm","clk":"5353372999","pt":1646213879599,"mc":[{"id":"1.195503864","rc":[{"atl":[[540,0]],"id":41419605}],"con":true,"img":false}]}
{"op":"mcm","clk":"5353373020","pt":1646213879907,"mc":[{"id":"1.195503864","rc":[{"atl":[[260,0],[270,4.95]],"id":41419605}],"con":true,"img":false}]}
{"op":"mcm","clk":"5353373061","pt":1646213880586,"mc":[{"id":"1.195503864","rc":[{"atl":[[270,0],[540,0.29]],"id":41419605}],"con":true,"img":false}]}
{"op":"mcm","clk":"5353373089","pt":1646213880993,"mc":[{"id":"1.195503864","rc":[{"atl":[[230,6.08],[470,2]],"id":41419634}],"con":true,"img":false}]}
{"op":"mcm","clk":"5353373111","pt":1646213881301,"mc":[{"id":"1.195503864","rc":[{"atl":[[260,4.95]],"id":41419605}],"con":true,"img":false}]}
{"op":"mcm","clk":"5353373115","pt":1646213881404,"mc":[{"id":"1.195503864","rc":[{"atl":[[210,0.75]],"id":41419634},{"atl":[[170,0]],"id":41419618},{"atl":[[130,1.23]],"id":41419601},{"atl":[[80,2],[100,0]],"id":41419639},{"atl":[[240,4.95]],"id":41419635},{"atb":[[11.5,15.1],[9.8,0]],"id":41419623},{"atl":[[130,4.95]],"id":41419590},{"atl":[[65,4.95],[85,9.9]],"id":41419627},{"atl":[[160,4.95],[170,0.93]],"id":41419594},{"atl":[[120,4.95]],"id":41419603},{"atl":[[75,0],[46,4.95],[55,2.93],[60,9.9]],"id":41419620},{"atb":[[80,0],[85,15.23],[60,0]],"id":41419599},{"atl":[[80,4.95],[100,9.9]],"id":41419628},{"atl":[[80,2],[100,0]],"id":41419637},{"atl":[[140,4.95],[160,0]],"id":41419604},{"atl":[[140,1.13]],"id":41419616},{"atl":[[70,2.29],[90,0]],"id":41419621},{"atl":[[75,2.14],[95,0]],"id":41419629},{"atl":[[200,0.79]],"id":41419596}],"con":true,"img":false}]}
{"op":"mcm","clk":"5353373122","pt":1646213881507,"mc":[{"id":"1.195503864","rc":[{"atl":[[180,4.95]],"id":41419634},{"atl":[[140,4.95],[160,0.99]],"id":41419617},{"atl":[[70,9.9],[80,0],[50,4.95],[60,2.68]],"id":41419622},{"atl":[[130,1.23],[120,4.95]],"id":41419589},{"atl":[[160,5.95]],"id":41419618},{"atl":[[110,4.95]],"id":41419601},{"atl":[[200,4.95],[210,0.75]],"id":41419597},{"atl":[[75,4.95],[95,9.9]],"id":41419639},{"atl":[[38,4.95],[40,4.06],[46,9.9],[48,0]],"id":41419606},{"atl":[[270,0.58]],"id":41419635},{"atb":[[10,31.99],[12,4.95]],"id":41419623},{"atl":[[140,1.13]],"id":41419590},{"atl":[[70,2.29],[90,0]],"id":41419627},{"atb":[[32,28.13],[34,9.9],[40,4.06],[42,4.95]],"id":41419640},{"atl":[[190,4.95],[220,0.72]],"id":41419636},{"atl":[[150,1.06]],"id":41419603},{"atl":[[270,0.58],[240,4.95]],"id":41419591},{"atl":[[90,0],[120,11.01]],"id":41419628},{"atb":[[17,12.21],[17.5,4.95],[15,0]],"id":41419608},{"atl":[[75,4.95],[95,9.9]],"id":41419637},{"atl":[[130,4.95]],"id":41419616},{"atl":[[80,9.9],[60,4.95]],"id":41419621},{"atl":[[65,4.95],[85,9.9]],"id":41419629},{"atl":[[180,4.95]],"id":41419596}],"con":true,"img":false}]}
{"op":"mcm","clk":"5353373129","pt":1646213881569,"mc":[{"id":"1.195503864","rc":[{"atl":[[790,0],[400,2]],"id":41419590},{"atl":[[520,2]],"id":41419594},{"atl":[[790,0],[390,2]],"id":41419603}],"con":true,"img":false}]}
{"op":"mcm","clk":"5353373139","pt":1646213881673,"mc":[{"id":"1.195503864","rc":[{"atl":[[350,2],[750,0]],"id":41419601},{"atl":[[540,2],[920,0]],"id":41419597},{"atl":[[910,0]],"id":41419594},{"atl":[[530,2],[910,0]],"id":41419591}],"con":true,"img":false}]}
{"op":"mcm","clk":"5353373149","pt":1646213881773,"mc":[{"id":"1.195503864","rc":[{"atl":[[60,22.12]],"id":41419620},{"atl":[[90,14.71],[120,0]],"id":41419628},{"atl":[[310,2]],"id":41419637},{"atl":[[210,2]],"id":41419621}],"con":true,"img":false}]}
{"op":"mcm","clk":"5353373153","pt":1646213881872,"mc":[{"id":"1.195503864","rc":[{"atl":[[180,5.84]],"id":41419634},{"atl":[[70,22.12],[160,0]],"id":41419622},{"atl":[[120,6.28]],"id":41419589},{"atl":[[750,1.86],[770,0],[110,6.4]],"id":41419601},{"atl":[[200,5.74],[950,0]],"id":41419597},{"atl":[[290,2],[90,15.6]],"id":41419639},{"atl":[[240,5.61]],"id":41419635},{"atb":[[10,9.9],[12,19.36]],"id":41419623},{"atl":[[130,6.18],[790,1.77],[820,0]],"id":41419590},{"atl":[[65,7.43],[150,2],[85,26.43]],"id":41419627},{"atl":[[150,1.11],[910,1.53],[940,0]],"id":41419594},{"atb":[[36,18.31]],"id":41419640},{"atl":[[790,1.77],[810,0],[120,6.28]],"id":41419603},{"atl":[[130,2],[46,8.47]],"id":41419620},{"atb":[[17.5,25.41],[17,0]],"id":41419608},{"atl":[[70,2.41],[90,15.6]],"id":41419637},{"atl":[[140,6.09]],"id":41419604},{"atl":[[80,19.63]],"id":41419621},{"atl":[[65,7.43],[180,2]],"id":41419629},{"atl":[[180,5.84]],"id":41419596}],"con":true,"img":false}]}
{"op":"mcm","clk":"5353373161","pt":1646213881979,"mc":[{"id":"1.195503864","rc":[{"atl":[[920,1.52]],"id":41419597},{"atb":[[11,36.59]],"id":41419623},{"atb":[[32,0]],"id":41419640},{"atl":[[130,6.18]],"id":41419616},{"atl":[[85,19.63]],"id":41419629}],"con":true,"img":false}]}
{"op":"mcm","clk":"5353373167","pt":1646213882078,"mc":[{"id":"1.195503864","rc":[{"atb":[[44,3.68]],"id":41419640},{"atl":[[190,5.79]],"id":41419636}],"con":true,"img":false}]}
{"op":"mcm","clk":"5353373174","pt":1646213882183,"mc":[{"id":"1.195503864","rc":[{"atl":[[70,2.29]],"id":41419639},{"atl":[[910,1.53],[240,5.61]],"id":41419591},{"atl":[[40,4.95],[42,3.86],[48,9.9],[50,0]],"id":41419608}],"con":true,"img":false}]}
{"op":"mcm","clk":"5353373189","pt":1646213882487,"mc":[{"id":"1.195503864","rc":[{"atb":[[180,1.63]],"id":41419602}],"con":true,"img":false}]}
{"op":"mcm","clk":"5353373202","pt":1646213882694,"mc":[{"id":"1.195503864","rc":[{"atl":[[210,0]],"id":41419634},{"atl":[[130,0]],"id":41419589},{"atl":[[130,0]],"id":41419601},{"atl":[[210,0]],"id":41419597},{"atl":[[270,0]],"id":41419635},{"atb":[[11.5,0]],"id":41419623},{"atl":[[140,0]],"id":41419590},{"atl":[[70,0]],"id":41419627},{"atl":[[170,0]],"id":41419594},{"atl":[[150,0]],"id":41419603},{"atl":[[55,0]],"id":41419620},{"atl":[[80,0],[90,0]],"id":41419637},{"atl":[[150,0]],"id":41419604},{"atl":[[75,0]],"id":41419629},{"atl":[[200,0]],"id":41419596}],"con":true,"img":false}]}
{"op":"mcm","clk":"5353373209","pt":1646213882800,"mc":[{"id":"1.195503864","rc":[{"atb":[[130,2.72],[160,7.46]],"id":41419602},{"atb":[[40,0]],"id":41419640},{"atl":[[520,4.69],[220,0]],"id":41419636},{"atl":[[40,9.01],[48,23.01],[110,2]],"id":41419608},{"atl":[[140,0]],"id":41419616}],"con":true,"img":false}]}
{"op":"mcm","clk":"5353373227","pt":1646213883105,"mc":[{"id":"1.195503864","rc":[{"atl":[[80,0]],"id":41419639},{"atl":[[270,0]],"id":41419591}],"con":true,"img":false}]}
{"op":"mcm","clk":"5353373233","pt":1646213883208,"mc":[{"id":"1.195503864","rc":[{"atl":[[290,0],[690,4.03]],"id":41419635},{"atl":[[160,8.79],[410,2]],"id":41419604},{"atl":[[200,7.03],[450,2]],"id":41419596}],"con":true,"img":false}]}
{"op":"mcm","clk":"5353373244","pt":1646213883467,"mc":[{"id":"1.195503864","rc":[{"atl":[[140,9.72]],"id":41419589},{"atb":[[170,0]],"id":41419602}],"con":true,"img":false}]}
{"op":"mcm","clk":"5353373267","pt":1646213883878,"mc":[{"id":"1.195503864","rc":[{"atb":[[11,22.08],[11.5,12.63],[13,13.21],[13.5,4.95]],"id":41419630},{"atl":[[200,4.95],[210,4.95]],"id":41419597},{"atl":[[38,0],[46,0]],"id":41419606},{"atl":[[690,2]],"id":41419635},{"atb":[[19.5,0],[20,16.91],[23,12.21],[24,4.95]],"id":41419627},{"atl":[[130,4.95],[120,0]],"id":41419603},{"atl":[[42,0]],"id":41419608},{"atl":[[140,0],[150,4.95],[160,0]],"id":41419604},{"atb":[[19.5,0],[20,9.9],[23,12.21],[24,4.95]],"id":41419629},{"atl":[[200,0]],"id":41419596}],"con":true,"img":false}]}
{"op":"mcm","clk":"5353373276","pt":1646213884086,"mc":[{"id":"1.195503864","rc":[{"atl":[[200,0]],"id":41419597},{"atl":[[40,9.01],[48,9.9]],"id":41419606}],"con":true,"img":false}]}
{"op":"mcm","clk":"5353373303","pt":1646213884500,"mc":[{"id":"1.195503864","rc":[{"atb":[[11,0],[11.5,49.47],[14,12.19]],"id":41419630},{"atb":[[23,0],[24,17.17]],"id":41419627},{"atb":[[23,0],[24,17.17]],"id":41419629}],"con":true,"img":false}]}
{"op":"mcm","clk":"5353373316","pt":1646213884807,"mc":[{"id":"1.195503864","rc":[{"atl":[[130,6.18]],"id":41419603}],"con":true,"img":false}]}
{"op":"mcm","clk":"5353373322","pt":1646213884914,"mc":[{"id":"1.195503864","rc":[{"atl":[[210,5.71]],"id":41419597},{"atl":[[1000,0.15]],"id":41419604}],"con":true,"img":false}]}
{"op":"mcm","clk":"5353373331","pt":1646213885069,"mc":[{"id":"1.195503864","rc":[{"atl":[[540,0],[920,3.52]],"id":41419597},{"atl":[[410,0],[820,2]],"id":41419604}],"con":true,"img":false}]}
{"op":"mcm","clk":"5353373345","pt":1646213885278,"mc":[{"id":"1.195503864","rc":[{"atb":[[13,0]],"id":41419630}],"con":true,"img":false}]}
{"op":"mcm","clk":"5353373376","pt":1646213885792,"mc":[{"id":"1.195503864","rc":[{"atl":[[130,1.23]],"id":41419590}],"con":true,"img":false}]}
{"op":"mcm","clk":"5353373385","pt":1646213885892,"mc":[{"id":"1.195503864","rc":[{"atl":[[260,0]],"id":41419605},{"atl":[[160,0.99],[170,4.95]],"id":41419618},{"atl":[[110,0],[120,4.95]],"id":41419601},{"atb":[[10,0],[11.5,4.95],[12,0],[9.8,9.9]],"id":41419623},{"atl":[[130,0],[140,4.95]],"id":41419590},{"atl":[[150,0],[170,4.95]],"id":41419594},{"atl":[[240,0],[250,4.95]],"id":41419591},{"atl":[[80,0],[85,6.83],[100,0]],"id":41419628},{"atl":[[40,4.06],[42,4.95],[48,13.1],[50,9.9]],"id":41419608}],"con":true,"img":false}]}
{"op":"mcm","clk":"5353373389","pt":1646213885994,"mc":[{"id":"1.195503864","rc":[{"atl":[[270,4.95]],"id":41419605},{"atl":[[160,0]],"id":41419594},{"atl":[[40,0]],"id":41419608},{"atl":[[65,2.47],[70,4.95],[85,9.72],[90,9.9]],"id":41419629}],"con":true,"img":false}]}
{"op":"mcm","clk":"5353373395","pt":1646213886099,"mc":[{"id":"1.195503864","rc":[{"atl":[[65,0]],"id":41419629}],"con":true,"img":false}]}
{"op":"mcm","clk":"5353373442","pt":1646213886615,"mc":[{"id":"1.195503864","rc":[{"atb":[[11,52.44]],"id":41419623}],"con":true,"img":false}]}
{"op":"mcm","clk":"5353373449","pt":1646213886670,"mc":[{"id":"1.195503864","rc":[{"atl":[[790,3.77]],"id":41419603}],"con":true,"img":false}]}
{"op":"mcm","clk":"5353373458","pt":1646213886776,"mc":[{"id":"1.195503864","rc":[{"atl":[[120,6.28]],"id":41419601},{"atl":[[390,0.4]],"id":41419590},{"atl":[[170,5.89]],"id":41419594},{"atl":[[390,0]],"id":41419603},{"atl":[[520,0.3]],"id":41419591},{"atl":[[90,16.49]],"id":41419628},{"atl":[[48,16.48]],"id":41419608},{"atl":[[85,11.6]],"id":41419629}],"con":true,"img":false}]}
{"op":"mcm","clk":"5353373463","pt":1646213886871,"mc":[{"id":"1.195503864","rc":[{"atl":[[350,0],[750,3.86]],"id":41419601},{"atl":[[520,0],[910,3.53]],"id":41419594}],"con":true,"img":false}]}
{"op":"mcm","clk":"5353373502","pt":1646213887592,"mc":[{"id":"1.195503864","rc":[{"atl":[[90,14.71]],"id":41419628}],"con":true,"img":false}]}
{"op":"mcm","clk":"5353373522","pt":1646213888007,"mc":[{"id":"1.195503864","rc":[{"atl":[[910,0]],"id":41419591}],"con":true,"img":false}]}
{"op":"mcm","clk":"5353373533","pt":1646213888208,"mc":[{"id":"1.195503864","rc":[{"atl":[[530,4.67]],"id":41419591}],"con":true,"img":false}]}
{"op":"mcm","clk":"5353373538","pt":1646213888317,"mc":[{"id":"1.195503864","rc":[{"atl":[[230,0],[470,5.01]],"id":41419634},{"atl":[[210,0],[220,4.95]],"id":41419597}],"con":true,"img":false}]}
{"op":"mcm","clk":"5353373556","pt":1646213888586,"mc":[{"id":"1.195503864","rc":[{"atl":[[140,6.09]],"id":41419617},{"atl":[[85,1.88]],"id":41419606},{"atb":[[9.6,9.9],[11,57.4],[11.5,0],[9.8,0]],"id":41419623}],"con":true,"img":false}]}
{"op":"mcm","clk":"5353373569","pt":1646213888783,"mc":[{"id":"1.195503864","rc":[{"atb":[[38,9.89],[29,0]],"id":41419586}],"con":true,"img":false}]}
{"op":"mcm","clk":"5353373576","pt":1646213888886,"mc":[{"id":"1.195503864","rc":[{"atl":[[250,5.59]],"id":41419591},{"atl":[[90,0]],"id":41419628}],"con":true,"img":false}]}
{"op":"mcm","clk":"5353373580","pt":1646213888989,"mc":[{"id":"1.195503864","rc":[{"atl":[[130,12.95],[60,9.9]],"id":41419620},{"atl":[[280,7.07]],"id":41419628}],"con":true,"img":false}]}
{"op":"mcm","clk":"5353373585","pt":1646213889094,"mc":[{"id":"1.195503864","rc":[{"atl":[[470,2]],"id":41419634},{"atb":[[85,3.17],[110,5.94],[120,4.95]],"id":41419593},{"atl":[[910,0.17]],"id":41419597},{"atl":[[38,4.95],[40,4.06],[46,9.9],[48,0]],"id":41419626},{"atl":[[150,11.49],[85,9.9]],"id":41419627},{"atb":[[22,19.57],[23,9.9],[26,3.26],[27,4.95]],"id":41419607},{"atl":[[85,1.88],[90,25.73]],"id":41419629}],"con":true,"img":false}]}
{"op":"mcm","clk":"5353373592","pt":1646213889198,"mc":[{"id":"1.195503864","rc":[{"atl":[[130,4.95]],"id":41419616},{"atl":[[190,4.95]],"id":41419596}],"con":true,"img":false}]}
{"op":"mcm","clk":"5353373600","pt":1646213889295,"mc":[{"id":"1.195503864","rc":[{"atl":[[270,0],[280,4.95]],"id":41419605},{"atl":[[180,0],[190,4.95]],"id":41419634},{"atl":[[140,1.13],[150,4.95]],"id":41419617},{"atl":[[160,0]],"id":41419618},{"atb":[[9.6,0],[11,18.57],[9.4,37.14]],"id":41419623},{"atl":[[20,4.95],[21,7.92],[24,9.9],[25,0]],"id":41419623},{"atl":[[190,0],[200,4.95]],"id":41419636},{"atl":[[260,4.95],[250,0.63]],"id":41419591},{"atl":[[130,0],[140,4.95]],"id":41419616},{"atl":[[180,0]],"id":41419596}],"con":true,"img":false}]}
{"op":"mcm","clk":"5353373605","pt":1646213889402,"mc":[{"id":"1.195503864","rc":[{"atl":[[140,0],[160,0]],"id":41419617},{"atl":[[85,0]],"id":41419606}],"con":true,"img":false}]}
{"op":"mcm","clk":"5353373612","pt":1646213889502,"mc":[{"id":"1.195503864","rc":[{"atb":[[110,0],[120,10.89]],"id":41419593},{"atl":[[36,4.22],[46,39.36]],"id":41419626},{"atb":[[22,0]],"id":41419607}],"con":true,"img":false}]}
{"op":"mcm","clk":"5353373617","pt":1646213889603,"mc":[{"id":"1.195503864","rc":[{"atl":[[130,2]],"id":41419626},{"atb":[[26,26.27]],"id":41419607}],"con":true,"img":false}]}
{"op":"mcm","clk":"5353373635","pt":1646213889814,"mc":[{"id":"1.195503864","rc":[{"atl":[[520,0],[250,0]],"id":41419591}],"con":true,"img":false}]}
{"op":"mcm","clk":"5353373639","pt":1646213889913,"mc":[{"id":"1.195503864","rc":[{"atl":[[160,8.91]],"id":41419617},{"atb":[[130,9.18]],"id":41419602},{"atl":[[19.5,8.56],[24,50.26],[55,2]],"id":41419623},{"atl":[[530,2],[520,2.73]],"id":41419591},{"atl":[[48,3.37],[50,31.99]],"id":41419608}],"con":true,"img":false}]}
{"op":"mcm","clk":"5353373650","pt":1646213890020,"mc":[{"id":"1.195503864","rc":[{"atl":[[190,5.79]],"id":41419634},{"atl":[[170,5.89]],"id":41419618},{"atb":[[160,4.95]],"id":41419602},{"atb":[[11.5,4.95],[9.8,9.9]],"id":41419623},{"atl":[[520,2],[190,0.83],[220,6.48]],"id":41419636},{"atl":[[140,6.09]],"id":41419616}],"con":true,"img":false}]}
{"op":"mcm","clk":"5353373655","pt":1646213890119,"mc":[{"id":"1.195503864","rc":[{"atl":[[270,4.95],[280,0]],"id":41419605},{"atl":[[200,0]],"id":41419636},{"atl":[[190,5.79]],"id":41419596}],"con":true,"img":false}]}
{"op":"mcm","clk":"5353373661","pt":1646213890177,"mc":[{"id":"1.195503864","rc":[{"atl":[[430,0.37]],"id":41419617},{"atl":[[520,2],[190,7.5]],"id":41419618},{"atl":[[46,9.9]],"id":41419626},{"atl":[[160,8.92]],"id":41419616}],"con":true,"img":false}]}
{"op":"mcm","clk":"5353373668","pt":1646213890280,"mc":[{"id":"1.195503864","rc":[{"atl":[[40,0]],"id":41419626},{"atl":[[210,6.79]],"id":41419596}],"con":true,"img":false}]}
{"op":"mcm","clk":"5353373680","pt":1646213890485,"mc":[{"id":"1.195503864","rc":[{"atl":[[260,5.48]],"id":41419635},{"atb":[[180,0.74]],"id":41419602},{"atl":[[260,5.56]],"id":41419591}],"con":true,"img":false}]}
{"op":"mcm","clk":"5353373686","pt":1646213890589,"mc":[{"id":"1.195503864","rc":[{"atl":[[140,0],[320,6.45]],"id":41419589}],"con":true,"img":false}]}
{"op":"mcm","clk":"5353373691","pt":1646213890688,"mc":[{"id":"1.195503864","rc":[{"atl":[[21,0]],"id":41419623}],"con":true,"img":false}]}
{"op":"mcm","clk":"5353373699","pt":1646213890794,"mc":[{"id":"1.195503864","rc":[{"atl":[[190,5.79]],"id":41419636}],"con":true,"img":false}]}
{"op":"mcm","clk":"5353373711","pt":1646213890999,"mc":[{"id":"1.195503864","rc":[{"atl":[[65,9.9],[48,4.95]],"id":41419620}],"con":true,"img":false}]}
{"op":"mcm","clk":"5353373717","pt":1646213891103,"mc":[{"id":"1.195503864","rc":[{"atl":[[260,0.61],[250,4.95]],"id":41419591},{"atl":[[46,0],[60,0]],"id":41419620},{"atl":[[80,9.72],[60,0]],"id":41419621}],"con":true,"img":false}]}
{"op":"mcm","clk":"5353373721","pt":1646213891206,"mc":[{"id":"1.195503864","rc":[{"atl":[[65,4.95],[85,9.9]],"id":41419621}],"con":true,"img":false}]}
{"op":"mcm","clk":"5353373725","pt":1646213891306,"mc":[{"id":"1.195503864","rc":[{"atb":[[170,0.93]],"id":41419602}],"con":true,"img":false}]}
{"op":"mcm","clk":"5353373738","pt":1646213891514,"mc":[{"id":"1.195503864","rc":[{"atl":[[80,0],[210,8.81]],"id":41419621}],"con":true,"img":false}]}
{"op":"mcm","clk":"5353373750","pt":1646213891721,"mc":[{"id":"1.195503864","rc":[{"atl":[[65,7.43]],"id":41419621}],"con":true,"img":false}]}
{"op":"mcm","clk":"5353373761","pt":1646213891925,"mc":[{"id":"1.195503864","rc":[{"atl":[[120,1.32]],"id":41419620}],"con":true,"img":false}]}
{"op":"mcm","clk":"5353373796","pt":1646213892607,"mc":[{"id":"1.195503864","rc":[{"atl":[[70,0]],"id":41419621}],"con":true,"img":false}]}
{"op":"mcm","clk":"5353373843","pt":1646213893393,"mc":[{"id":"1.195503864","rc":[{"atl":[[270,5.54]],"id":41419605}],"con":true,"img":false}]}
{"op":"mcm","clk":"5353373866","pt":1646213893805,"mc":[{"id":"1.195503864","rc":[{"atl":[[550,4.6],[940,0]],"id":41419605}],"con":true,"img":false}]}
{"op":"mcm","clk":"5353373872","pt":1646213893908,"mc":[{"id":"1.195503864","rc":[{"atl":[[1000,0]],"id":41419593},{"atl":[[930,0],[940,2]],"id":41419586},{"atb":[[40,2.56],[30,4.59]],"id":41419591},{"atl":[[910,0],[920,2]],"id":41419599}],"con":true,"img":false}]}
{"op":"mcm","clk":"5353373886","pt":1646213894118,"mc":[{"id":"1.195503864","rc":[{"atl":[[260,5.56],[250,0]],"id":41419591}],"con":true,"img":false}]}
{"op":"mcm","clk":"5353373894","pt":1646213894222,"mc":[{"id":"1.195503864","rc":[{"atb":[[32,5.11],[34,4.95],[27,20.12],[28,12.63]],"id":41419609},{"atl":[[65,2.47],[70,4.95],[85,0],[90,9.9]],"id":41419609},{"atl":[[540,0]],"id":41419605},{"atb":[[70,2.72],[75,7.09],[50,0],[55,24.62]],"id":41419634},{"atl":[[50,8.19]],"id":41419622},{"atb":[[65,12.63],[80,2],[85,4.95],[60,14.71]],"id":41419618},{"atb":[[36,0],[38,9.9],[44,0],[46,4.95]],"id":41419601},{"atl":[[23,7.2],[25,4.95],[27,0],[29,9.9]],"id":41419630},{"atb":[[75,2.72],[80,9.9],[95,1.68],[100,4.95]],"id":41419597},{"atb":[[17.5,9.9],[19,0],[19.5,4.95],[22,2.72]],"id":41419626},{"atl":[[36,0]],"id":41419626},{"atb":[[16.5,0],[17,4.95],[14.5,0]],"id":41419606},{"atb":[[85,0],[110,0],[120,4.95]],"id":41419585},{"atb":[[60,5.41]],"id":41419590},{"atb":[[70,3.85],[90,4.88],[95,4.95]],"id":41419586},{"atb":[[65,2.72],[70,9.9],[85,1.88],[90,4.95]],"id":41419594},{"atl":[[130,9.9],[90,1.78],[95,4.95],[120,0]],"id":41419640},{"atb":[[65,14.59],[70,9.9],[85,1.88],[90,4.95]],"id":41419636},{"atb":[[38,0],[40,9.9],[46,0],[48,4.95]],"id":41419603},{"atb":[[9.6,22.08],[11,15.85],[11.5,4.95],[9.8,9.9]],"id":41419611},{"atl":[[20,8.34],[22,4.95],[24,0],[26,9.9]],"id":41419611},{"atl":[[70,4.95],[80,2],[90,9.9],[100,0]],"id":41419624},{"atb":[[21,0],[22,0],[25,0],[30,0]],"id":41419620},{"atb":[[85,11.96],[120,0]],"id":41419599},{"atb":[[40,6.79]],"id":41419628},{"atb":[[34,4.8],[36,4.95],[28,21.86],[29,9.9]],"id":41419637},{"atl":[[75,0],[80,4.95],[95,0],[100,9.9]],"id":41419637},{"atb":[[65,5.2],[42,0],[44,9.9],[50,0],[55,4.95]],"id":41419604},{"atb":[[16,22.08],[16.5,9.9],[18,9.32],[18.5,4.95]],"id":41419612},{"atl":[[22,4.95],[24,6.89],[26,9.9],[28,0]],"id":41419625},{"atb":[[23,21.22],[24,9.9],[27,6.09],[28,4.95]],"id":41419633},{"atl":[[65,0],[70,9.9],[48,3.37],[50,4.95]],"id":41419633},{"atb":[[85,3.17],[110,5.94]],"id":41419600}],"con":true,"img":false}]}
{"op":"mcm","clk":"5353373905","pt":1646213894430,"mc":[{"id":"1.195503864","rc":[{"atb":[[120,4.95]],"id":41419600}],"con":true,"img":false}]}
{"op":"mcm","clk":"5353373915","pt":1646213894634,"mc":[{"id":"1.195503864","rc":[{"atb":[[27,0],[28,27.58]],"id":41419609},{"atl":[[90,24.86],[250,2]],"id":41419609},{"atb":[[65,28.74],[90,1.78]],"id":41419618},{"atl":[[65,2],[29,35.33]],"id":41419630},{"atb":[[80,22.49],[50,3.26]],"id":41419597},{"atb":[[46,3.26],[95,1.68]],"id":41419594},{"atl":[[130,20.98],[360,2]],"id":41419640},{"atb":[[75,14.12],[95,1.68]],"id":41419636},{"atl":[[320,2]],"id":41419624},{"atb":[[17.5,9.9],[19,9.37],[19.5,4.95],[9.2,37.92]],"id":41419620},{"atb":[[32,17.23],[38,4.28]],"id":41419637},{"atb":[[16,0],[17.5,31.08],[19,8.8]],"id":41419612},{"atl":[[75,2],[21,7.92],[26,34.87]],"id":41419625},{"atb":[[25,17.43],[29,5.66]],"id":41419633},{"atl":[[70,24.62]],"id":41419633}],"con":true,"img":false}]}
{"op":"mcm","clk":"5353373923","pt":1646213894736,"mc":[{"id":"1.195503864","rc":[{"atb":[[36,4.52]],"id":41419609},{"atb":[[60,0]],"id":41419618},{"atb":[[110,1.45]],"id":41419597},{"atb":[[90,0],[95,9.84]],"id":41419586},{"atb":[[70,24.62]],"id":41419594},{"atb":[[65,0]],"id":41419636},{"atb":[[9.6,0]],"id":41419611},{"atl":[[50,2.04]],"id":41419611},{"atl":[[65,2.57],[90,25.91]],"id":41419624},{"atb":[[70,8.79],[85,4.95]],"id":41419599},{"atb":[[28,0]],"id":41419637},{"atb":[[23,0]],"id":41419633},{"atl":[[160,2]],"id":41419633}],"con":true,"img":false}]}
{"op":"mcm","clk":"5353373927","pt":1646213894797,"mc":[{"id":"1.195503864","rc":[{"atb":[[10,22.48],[12,14.41]],"id":41419611},{"atl":[[26,29.66]],"id":41419611},{"atb":[[75,9.82],[80,9.9],[95,1.68],[100,4.95]],"id":41419591},{"atb":[[110,0],[120,10.89]],"id":41419600}],"con":true,"img":false}]}
{"op":"mcm","clk":"5353373936","pt":1646213894903,"mc":[{"id":"1.195503864","rc":[{"atl":[[60,0]],"id":41419622},{"atb":[[19.5,13.52]],"id":41419626},{"atl":[[44,3.68]],"id":41419626},{"atb":[[22,3.26],[27,2.72]],"id":41419620},{"atb":[[130,2.72],[90,3.26]],"id":41419599}],"con":true,"img":false}]}
{"op":"mcm","clk":"5353373962","pt":1646213895210,"mc":[{"id":"1.195503864","rc":[{"atb":[[75,0],[85,10.83],[100,6.55]],"id":41419591},{"atl":[[520,0],[530,4.71]],"id":41419591}],"con":true,"img":false}]}
{"op":"mcm","clk":"5353373969","pt":1646213895317,"mc":[{"id":"1.195503864","rc":[{"atb":[[80,0]],"id":41419618},{"atb":[[85,0]],"id":41419594},{"atb":[[85,0]],"id":41419636},{"atb":[[34,0]],"id":41419637},{"atb":[[18,0]],"id":41419612},{"atl":[[24,0]],"id":41419625},{"atb":[[27,0]],"id":41419633}],"con":true,"img":false}]}
{"op":"mcm","clk":"5353373979","pt":1646213895520,"mc":[{"id":"1.195503864","rc":[{"atb":[[32,0]],"id":41419609},{"atl":[[70,9.9]],"id":41419622},{"atb":[[95,0]],"id":41419597},{"atl":[[80,0],[90,9.9]],"id":41419624}],"con":true,"img":false}]}
{"op":"mcm","clk":"5353373984","pt":1646213895623,"mc":[{"id":"1.195503864","rc":[{"atl":[[210,6.86]],"id":41419634},{"atl":[[170,10.48]],"id":41419622},{"atb":[[11,0]],"id":41419611}],"con":true,"img":false}]}
{"op":"mcm","clk":"5353374010","pt":1646213896036,"mc":[{"id":"1.195503864","rc":[{"atb":[[95,0]],"id":41419591}],"con":true,"img":false}]}
{"op":"mcm","clk":"5353374022","pt":1646213896296,"mc":[{"id":"1.195503864","rc":[{"atl":[[220,5.67]],"id":41419597},{"atl":[[790,0],[400,5.6]],"id":41419590},{"atl":[[190,7.6],[910,2]],"id":41419594},{"atl":[[130,2],[120,13.37]],"id":41419620},{"atl":[[280,2],[95,15.21]],"id":41419628},{"atl":[[100,24.36]],"id":41419637},{"atl":[[150,6.01]],"id":41419604},{"atl":[[65,2.47]],"id":41419629}],"con":true,"img":false}]}
{"op":"mcm","clk":"5353374028","pt":1646213896398,"mc":[{"id":"1.195503864","rc":[{"atl":[[140,10.32]],"id":41419601},{"atb":[[11.5,20.05],[9.4,3.26]],"id":41419623},{"atl":[[140,6.09]],"id":41419590},{"atl":[[530,2],[910,0]],"id":41419594}],"con":true,"img":false}]}
{"op":"mcm","clk":"5353374038","pt":1646213896504,"mc":[{"id":"1.195503864","rc":[{"atl":[[750,0],[370,2]],"id":41419601},{"atl":[[150,9.63],[790,2]],"id":41419603},{"atl":[[48,8.32]],"id":41419620}],"con":true,"img":false}]}
{"op":"mcm","clk":"5353374046","pt":1646213896658,"mc":[{"id":"1.195503864","rc":[{"atb":[[9.8,37.37]],"id":41419623},{"atl":[[390,2]],"id":41419603}],"con":true,"img":false}]}
{"op":"mcm","clk":"5353374053","pt":1646213896715,"mc":[{"id":"1.195503864","rc":[{"atl":[[790,0]],"id":41419603},{"atl":[[85,10.79],[90,9.9]],"id":41419629}],"con":true,"img":false}]}
{"op":"mcm","clk":"5353374058","pt":1646213896819,"mc":[{"id":"1.195503864","rc":[{"atl":[[530,2],[280,5.16]],"id":41419591}],"con":true,"img":false}]}
{"op":"mcm","clk":"5353374064","pt":1646213896919,"mc":[{"id":"1.195503864","rc":[{"atl":[[160,0]],"id":41419617},{"atb":[[190,0.83]],"id":41419602}],"con":true,"img":false}]}
{"op":"mcm","clk":"5353374069","pt":1646213897026,"mc":[{"id":"1.195503864","rc":[{"atl":[[430,3.72]],"id":41419617},{"atb":[[34,0],[27,0]],"id":41419622},{"atl":[[910,0]],"id":41419597},{"atl":[[520,4.77],[220,0]],"id":41419636},{"atl":[[1000,0]],"id":41419604},{"atb":[[150,0],[100,0]],"id":41419592},{"atl":[[85,8.9]],"id":41419629}],"con":true,"img":false}]}
{"op":"mcm","clk":"5353374076","pt":1646213897126,"mc":[{"id":"1.195503864","rc":[{"atb":[[9.6,0],[11.5,46.75]],"id":41419630},{"atb":[[38,0],[29,0]],"id":41419621}],"con":true,"img":false}]}
{"op":"mcm","clk":"5353374083","pt":1646213897230,"mc":[{"id":"1.195503864","rc":[{"atl":[[140,0]],"id":41419601},{"atb":[[160,7.46]],"id":41419602},{"atl":[[120,12.04]],"id":41419620},{"atl":[[42,8.82]],"id":41419608},{"atl":[[160,0]],"id":41419616}],"con":true,"img":false}]}
{"op":"mcm","clk":"5353374091","pt":1646213897333,"mc":[{"id":"1.195503864","rc":[{"atl":[[520,4.77]],"id":41419618},{"atb":[[130,2.72]],"id":41419602},{"atb":[[11,2.72]],"id":41419623},{"atl":[[390,0]],"id":41419590},{"atl":[[430,5.36]],"id":41419616}],"con":true,"img":false}]}
{"op":"mcm","clk":"5353374098","pt":1646213897435,"mc":[{"id":"1.195503864","rc":[{"atl":[[190,0]],"id":41419618},{"atb":[[110,9.14]],"id":41419592},{"atl":[[210,0],[450,5.2]],"id":41419596}],"con":true,"img":false}]}
{"op":"mcm","clk":"5353374103","pt":1646213897534,"mc":[{"id":"1.195503864","rc":[{"atb":[[17.5,37.52],[23,12.15]],"id":41419622},{"atl":[[920,2],[240,6.03]],"id":41419597}],"con":true,"img":false}]}
{"op":"mcm","clk":"5353374112","pt":1646213897640,"mc":[{"id":"1.195503864","rc":[{"atl":[[260,0],[690,4.09]],"id":41419635},{"atb":[[170,0]],"id":41419602},{"atl":[[280,0]],"id":41419591},{"atl":[[1000,1.43]],"id":41419604},{"atb":[[19.5,35.02],[26,11.29]],"id":41419621}],"con":true,"img":false}]}
{"op":"mcm","clk":"5353374124","pt":1646213897700,"mc":[{"id":"1.195503864","rc":[{"atl":[[550,2],[920,0]],"id":41419597}],"con":true,"img":false}]}
{"op":"mcm","clk":"5353374130","pt":1646213897808,"mc":[{"id":"1.195503864","rc":[{"atb":[[32,2.72],[26,3.26]],"id":41419622},{"atb":[[140,2.72],[95,6.1]],"id":41419592}],"con":true,"img":false}]}
{"op":"mcm","clk":"5353374134","pt":1646213897907,"mc":[{"id":"1.195503864","rc":[{"atb":[[12,2.72],[9.8,3.26]],"id":41419630},{"atb":[[36,2.72],[28,3.26]],"id":41419621}],"con":true,"img":false}]}
{"op":"mcm","clk":"5353374143","pt":1646213898007,"mc":[{"id":"1.195503864","rc":[{"atl":[[140,10.35],[320,2]],"id":41419589},{"atl":[[48,0]],"id":41419608}],"con":true,"img":false}]}
{"op":"mcm","clk":"5353374157","pt":1646213898219,"mc":[{"id":"1.195503864","rc":[{"atl":[[520,2]],"id":41419618}],"con":true,"img":false}]}
{"op":"mcm","clk":"5353374164","pt":1646213898320,"mc":[{"id":"1.195503864","rc":[{"atl":[[240,0]],"id":41419597},{"atl":[[690,2]],"id":41419635},{"atb":[[110,4.95]],"id":41419592}],"con":true,"img":false}]}
{"op":"mcm","clk":"5353374174","pt":1646213898526,"mc":[{"id":"1.195503864","rc":[{"atl":[[50,9.9],[110,15.19]],"id":41419608}],"con":true,"img":false}]}
{"op":"mcm","clk":"5353374192","pt":1646213898838,"mc":[{"id":"1.195503864","rc":[{"atl":[[140,0]],"id":41419589}],"con":true,"img":false}]}
{"op":"mcm","clk":"5353374214","pt":1646213899201,"mc":[{"id":"1.195503864","rc":[{"atb":[[11.5,9.9],[12,20.78]],"id":41419630}],"con":true,"img":false}]}
{"op":"mcm","clk":"5353374266","pt":1646213900024,"mc":[{"id":"1.195503864","rc":[{"atl":[[170,0.93],[180,4.95]],"id":41419618},{"atl":[[220,0],[230,4.95]],"id":41419597},{"atl":[[140,0],[150,4.95]],"id":41419590},{"atl":[[65,0]],"id":41419629}],"con":true,"img":false}]}
{"op":"mcm","clk":"5353374287","pt":1646213900336,"mc":[{"id":"1.195503864","rc":[{"atl":[[130,4.95],[120,0]],"id":41419589}],"con":true,"img":false}]}
{"op":"mcm","clk":"5353374308","pt":1646213900744,"mc":[{"id":"1.195503864","rc":[{"atl":[[260,0.61],[250,4.95]],"id":41419591},{"atb":[[130,0],[90,0]],"id":41419599}],"con":true,"img":false}]}
{"op":"mcm","clk":"5353374331","pt":1646213901007,"mc":[{"id":"1.195503864","rc":[{"atl":[[130,0]],"id":41419589},{"atl":[[180,0]],"id":41419618},{"atl":[[220,0.72]],"id":41419597},{"atl":[[390,0.4]],"id":41419590},{"atl":[[70,7.25]],"id":41419629}],"con":true,"img":false}]}
{"op":"mcm","clk":"5353374352","pt":1646213901317,"mc":[{"id":"1.195503864","rc":[{"atl":[[310,0.51]],"id":41419589}],"con":true,"img":false}]}
{"op":"mcm","clk":"5353374364","pt":1646213901421,"mc":[{"id":"1.195503864","rc":[{"atl":[[250,5.59]],"id":41419591}],"con":true,"img":false}]}
{"op":"mcm","clk":"5353374381","pt":1646213901730,"mc":[{"id":"1.195503864","rc":[{"atl":[[170,5.89]],"id":41419618},{"atb":[[85,8.22],[120,2.72]],"id":41419599}],"con":true,"img":false}]}
{"op":"mcm","clk":"5353374402","pt":1646213902044,"mc":[{"id":"1.195503864","rc":[{"atl":[[120,4.95]],"id":41419589}],"con":true,"img":false}]}
{"op":"mcm","clk":"5353374424","pt":1646213902408,"mc":[{"id":"1.195503864","rc":[{"atb":[[80,27.96],[85,2.72]],"id":41419591},{"atl":[[260,0]],"id":41419591}],"con":true,"img":false}]}
{"op":"mcm","clk":"5353374449","pt":1646213902721,"mc":[{"id":"1.195503864","rc":[{"atl":[[210,0],[470,5.1]],"id":41419634},{"atl":[[530,4.75]],"id":41419591}],"con":true,"img":false}]}
{"op":"mcm","clk":"5353374468","pt":1646213903128,"mc":[{"id":"1.195503864","rc":[{"atl":[[150,6.01]],"id":41419617}],"con":true,"img":false}]}
{"op":"mcm","clk":"5353374485","pt":1646213903436,"mc":[{"id":"1.195503864","rc":[{"atl":[[130,4.95],[120,0]],"id":41419589},{"atl":[[170,0],[180,4.95]],"id":41419618},{"atl":[[220,0]],"id":41419597},{"atb":[[130,6.91]],"id":41419585},{"atl":[[530,4.75],[170,0.93],[180,4.95],[190,0]],"id":41419594},{"atl":[[150,0]],"id":41419603},{"atl":[[110,0]],"id":41419587},{"atl":[[280,7.22],[95,0]],"id":41419628},{"atl":[[150,0],[160,4.95]],"id":41419604}],"con":true,"img":false}]}
{"op":"mcm","clk":"5353374489","pt":1646213903541,"mc":[{"id":"1.195503864","rc":[{"atl":[[120,4.95]],"id":41419587}],"con":true,"img":false}]}
{"op":"mcm","clk":"5353374491","pt":1646213903644,"mc":[{"id":"1.195503864","rc":[{"atl":[[740,0],[750,2]],"id":41419587},{"atl":[[820,0],[430,2]],"id":41419604}],"con":true,"img":false}]}
{"op":"mcm","clk":"5353374496","pt":1646213903744,"mc":[{"id":"1.195503864","rc":[{"atl":[[390,5.74]],"id":41419603},{"atl":[[85,0],[90,26.2]],"id":41419629}],"con":true,"img":false}]}
{"op":"mcm","clk":"5353374523","pt":1646213904116,"mc":[{"id":"1.195503864","rc":[{"atl":[[430,0],[440,5.32]],"id":41419617},{"atl":[[38,9.23],[46,31.99]],"id":41419626},{"atl":[[760,1.92],[770,0]],"id":41419587}],"con":true,"img":false}]}
{"op":"mcm","clk":"5353374529","pt":1646213904216,"mc":[{"id":"1.195503864","rc":[{"atl":[[180,5.84]],"id":41419618},{"atl":[[230,5.64]],"id":41419597},{"atl":[[40,0],[42,4.95],[48,0],[50,9.9]],"id":41419606},{"atl":[[530,2],[270,5.42]],"id":41419591},{"atl":[[110,6.4],[120,0]],"id":41419587},{"atl":[[280,2]],"id":41419628},{"atl":[[150,1.06],[160,0]],"id":41419604}],"con":true,"img":false}]}
{"op":"mcm","clk":"5353374553","pt":1646213904423,"mc":[{"id":"1.195503864","rc":[{"atl":[[65,4.95],[70,4.95],[90,9.9]],"id":41419627},{"atl":[[520,2],[210,6.98]],"id":41419636}],"con":true,"img":false}]}
{"op":"mcm","clk":"5353374562","pt":1646213904528,"mc":[{"id":"1.195503864","rc":[{"atl":[[200,7.34]],"id":41419618},{"atl":[[65,0],[85,0]],"id":41419627},{"atl":[[160,9.17],[430,2]],"id":41419616}],"con":true,"img":false}]}
{"op":"mcm","clk":"5353374578","pt":1646213904843,"mc":[{"id":"1.195503864","rc":[{"atl":[[44,0]],"id":41419626},{"atl":[[260,5.64]],"id":41419635},{"atl":[[210,6.99],[450,2]],"id":41419596}],"con":true,"img":false}]}
{"op":"mcm","clk":"5353374580","pt":1646213904941,"mc":[{"id":"1.195503864","rc":[{"atl":[[320,6.58]],"id":41419589},{"atl":[[48,3.37]],"id":41419606},{"atl":[[150,2],[85,14.71]],"id":41419627},{"atl":[[110,0],[120,4.95]],"id":41419587},{"atl":[[150,6.01]],"id":41419604}],"con":true,"img":false}]}
{"op":"mcm","clk":"5353374593","pt":1646213905145,"mc":[{"id":"1.195503864","rc":[{"atl":[[70,7.25]],"id":41419627}],"con":true,"img":false}]}
{"op":"mcm","clk":"5353374617","pt":1646213905419,"mc":[{"id":"1.195503864","rc":[{"atl":[[50,22.27]],"id":41419606}],"con":true,"img":false}]}
{"op":"mcm","clk":"5353374621","pt":1646213905518,"mc":[{"id":"1.195503864","rc":[{"atl":[[90,2]],"id":41419606}],"con":true,"img":false}]}
{"op":"mcm","clk":"5353374640","pt":1646213905828,"mc":[{"id":"1.195503864","rc":[{"atl":[[270,0.58],[260,4.95]],"id":41419605},{"atl":[[740,0.21]],"id":41419587},{"atl":[[210,0]],"id":41419596}],"con":true,"img":false}]}
{"op":"mcm","clk":"5353374669","pt":1646213906241,"mc":[{"id":"1.195503864","rc":[{"atl":[[260,5.56]],"id":41419605}],"con":true,"img":false}]}
{"op":"mcm","clk":"5353374726","pt":1646213907115,"mc":[{"id":"1.195503864","rc":[{"atl":[[270,0]],"id":41419605}],"con":true,"img":false}]}
{"op":"mcm","clk":"5353374791","pt":1646213908040,"mc":[{"id":"1.195503864","rc":[{"atl":[[550,2],[280,5.27]],"id":41419605}],"con":true,"img":false}]}
{"op":"mcm","clk":"5353374832","pt":1646213908718,"mc":[{"id":"1.195503864","rc":[{"atl":[[830,2],[430,0]],"id":41419604}],"con":true,"img":false}]}
{"op":"mcm","clk":"5353374837","pt":1646213908823,"mc":[{"id":"1.195503864","rc":[{"atb":[[9.2,12.2]],"id":41419620}],"con":true,"img":false}]}
{"op":"mcm","clk":"5353374855","pt":1646213909133,"mc":[{"id":"1.195503864","rc":[{"atl":[[90,26.36]],"id":41419624},{"atb":[[19.5,24.69]],"id":41419620},{"atb":[[70,3.85],[85,13.15]],"id":41419599}],"con":true,"img":false}]}
{"op":"mcm","clk":"5353374881","pt":1646213909542,"mc":[{"id":"1.195503864","rc":[{"atl":[[290,4.95]],"id":41419619},{"atl":[[150,0],[160,4.95]],"id":41419604}],"con":true,"img":false}]}
{"op":"mcm","clk":"5353374885","pt":1646213909645,"mc":[{"id":"1.195503864","rc":[{"atl":[[850,2],[1000,0]],"id":41419619}],"con":true,"img":false}]}
{"op":"mcm","clk":"5353374893","pt":1646213909851,"mc":[{"id":"1.195503864","rc":[{"atl":[[210,7.05],[470,2]],"id":41419634},{"atl":[[270,0],[530,4.79]],"id":41419591}],"con":true,"img":false}]}
{"op":"mcm","clk":"5353374898","pt":1646213909954,"mc":[{"id":"1.195503864","rc":[{"atl":[[990,2.15]],"id":41419619}],"con":true,"img":false}]}
{"op":"mcm","clk":"5353374902","pt":1646213910063,"mc":[{"id":"1.195503864","rc":[{"atl":[[290,5.5],[850,0],[1000,1.47]],"id":41419619},{"atl":[[130,0],[140,4.95]],"id":41419603},{"atl":[[42,0],[50,0]],"id":41419608}],"con":true,"img":false}]}
{"op":"mcm","clk":"5353374908","pt":1646213910162,"mc":[{"id":"1.195503864","rc":[{"atl":[[44,4.95],[55,9.9]],"id":41419608}],"con":true,"img":false}]}
{"op":"mcm","clk":"5353374913","pt":1646213910221,"mc":[{"id":"1.195503864","rc":[{"atl":[[110,13.19],[120,2]],"id":41419608}],"con":true,"img":false}]}
{"op":"mcm","clk":"5353374920","pt":1646213910326,"mc":[{"id":"1.195503864","rc":[{"atl":[[160,5.95]],"id":41419604}],"con":true,"img":false}]}
{"op":"mcm","clk":"5353374935","pt":1646213910631,"mc":[{"id":"1.195503864","rc":[{"atl":[[140,10.61]],"id":41419601},{"atl":[[150,6.01]],"id":41419590},{"atl":[[95,15.63]],"id":41419628},{"atl":[[130,11.42],[110,0]],"id":41419608},{"atl":[[90,9.9],[180,10.25]],"id":41419629}],"con":true,"img":false}]}
{"op":"mcm","clk":"5353374949","pt":1646213910839,"mc":[{"id":"1.195503864","rc":[{"atl":[[990,2]],"id":41419619},{"atl":[[160,9.28],[380,0.41],[390,2]],"id":41419603},{"atl":[[50,3.23]],"id":41419608}],"con":true,"img":false}]}
{"op":"mcm","clk":"5353374967","pt":1646213911154,"mc":[{"id":"1.195503864","rc":[{"atl":[[130,13.43],[46,9.9]],"id":41419626},{"atl":[[530,2],[270,5.49]],"id":41419591}],"con":true,"img":false}]}
{"op":"mcm","clk":"5353374980","pt":1646213911355,"mc":[{"id":"1.195503864","rc":[{"atl":[[170,8.74]],"id":41419617}],"con":true,"img":false}]}
{"op":"mcm","clk":"5353374986","pt":1646213911457,"mc":[{"id":"1.195503864","rc":[{"atl":[[440,2]],"id":41419617},{"atl":[[520,4.85],[200,0]],"id":41419618},{"atl":[[520,4.85],[210,0]],"id":41419636},{"atl":[[160,0]],"id":41419616}],"con":true,"img":false}]}
{"op":"mcm","clk":"5353374994","pt":1646213911561,"mc":[{"id":"1.195503864","rc":[{"atl":[[390,0]],"id":41419590},{"atl":[[430,5.45]],"id":41419616}],"con":true,"img":false}]}
{"op":"mcm","clk":"5353375000","pt":1646213911664,"mc":[{"id":"1.195503864","rc":[{"atl":[[210,7.08]],"id":41419596}],"con":true,"img":false}]}
{"op":"mcm","clk":"5353375005","pt":1646213911724,"mc":[{"id":"1.195503864","rc":[{"atb":[[17.5,8.07],[23,39.05]],"id":41419622},{"atl":[[250,5.95]],"id":41419597}],"con":true,"img":false}]}
{"op":"mcm","clk":"5353375011","pt":1646213911828,"mc":[{"id":"1.195503864","rc":[{"atl":[[690,4.14]],"id":41419635},{"atl":[[85,0],[90,26.45]],"id":41419627},{"atl":[[270,0]],"id":41419591},{"atb":[[19.5,7.19],[26,35.43]],"id":41419621}],"con":true,"img":false}]}
{"op":"mcm","clk":"5353375014","pt":1646213911928,"mc":[{"id":"1.195503864","rc":[{"atl":[[260,0]],"id":41419635}],"con":true,"img":false}]}
{"op":"mcm","clk":"5353375019","pt":1646213912031,"mc":[{"id":"1.195503864","rc":[{"atl":[[170,8.75],[400,2]],"id":41419590}],"con":true,"img":false}]}
{"op":"mcm","clk":"5353375032","pt":1646213912238,"mc":[{"id":"1.195503864","rc":[{"atl":[[170,0]],"id":41419617},{"atl":[[520,2]],"id":41419618},{"atl":[[520,2]],"id":41419636}],"con":true,"img":false}]}
{"op":"mcm","clk":"5353375058","pt":1646213912654,"mc":[{"id":"1.195503864","rc":[{"atl":[[690,2]],"id":41419635}],"con":true,"img":false}]}
{"op":"mcm","clk":"5353375072","pt":1646213912860,"mc":[{"id":"1.195503864","rc":[{"atl":[[170,0]],"id":41419590},{"atl":[[55,22.12]],"id":41419608}],"con":true,"img":false}]}
{"op":"mcm","clk":"5353375077","pt":1646213912964,"mc":[{"id":"1.195503864","rc":[{"atl":[[130,0]],"id":41419608}],"con":true,"img":false}]}
{"op":"mcm","clk":"5353375176","pt":1646213914673,"mc":[{"id":"1.195503864","rc":[{"atl":[[1000,2]],"id":41419593}],"con":true,"img":false}]}
{"op":"mcm","clk":"5353375194","pt":1646213914942,"mc":[{"id":"1.195503864","rc":[{"atl":[[280,0]],"id":41419605}],"con":true,"img":false}]}
{"op":"mcm","clk":"5353375211","pt":1646213915257,"mc":[{"id":"1.195503864","rc":[{"atl":[[550,4.71]],"id":41419605}],"con":true,"img":false}]}
{"op":"mcm","clk":"5353375229","pt":1646213915568,"mc":[{"id":"1.195503864","rc":[{"atl":[[130,6.18]],"id":41419589}],"con":true,"img":false}]}
{"op":"mcm","clk":"5353375255","pt":1646213916042,"mc":[{"id":"1.195503864","rc":[{"atl":[[250,0.63]],"id":41419591}],"con":true,"img":false}]}
{"op":"mcm","clk":"5353375269","pt":1646213916386,"mc":[{"id":"1.195503864","rc":[{"atl":[[240,4.95]],"id":41419591}],"con":true,"img":false}]}
{"op":"mcm","clk":"5353375275","pt":1646213916461,"mc":[{"id":"1.195503864","rc":[{"atl":[[310,0]],"id":41419589},{"atl":[[540,2]],"id":41419591}],"con":true,"img":false}]}
{"op":"mcm","clk":"5353375279","pt":1646213916566,"mc":[{"id":"1.195503864","rc":[{"atl":[[530,0]],"id":41419591}],"con":true,"img":false}]}
{"op":"mcm","clk":"5353375292","pt":1646213916775,"mc":[{"id":"1.195503864","rc":[{"atl":[[550,2.71],[660,2]],"id":41419605},{"atl":[[210,0],[470,5.18]],"id":41419634},{"atl":[[1000,0]],"id":41419593},{"atl":[[690,0],[770,2]],"id":41419635},{"atl":[[42,2.44],[55,0]],"id":41419623},{"atl":[[940,0],[950,3.29]],"id":41419586},{"atl":[[1000,0]],"id":41419598},{"atb":[[32,0],[42,2.44]],"id":41419599},{"atl":[[920,0],[930,3.31]],"id":41419599},{"atb":[[8.4,35.99],[9.4,11.9]],"id":41419608},{"atl":[[1000,0]],"id":41419600}],"con":true,"img":false}]}
{"op":"mcm","clk":"5353375300","pt":1646213916837,"mc":[{"id":"1.195503864","rc":[{"atl":[[270,5.56],[240,5.61]],"id":41419591}],"con":true,"img":false}]}
{"op":"mcm","clk":"5353375315","pt":1646213917044,"mc":[{"id":"1.195503864","rc":[{"atb":[[75,0],[80,9.9],[95,4.4],[100,4.95]],"id":41419605},{"atl":[[150,10.02],[320,2]],"id":41419589},{"atl":[[24,4.95],[25,0],[28,9.9],[29,25.42]],"id":41419630},{"atb":[[17.5,0],[18,9.9],[19.5,8.56],[20,4.95]],"id":41419626},{"atl":[[16,10.56],[18,0]],"id":41419610},{"atb":[[9.6,9.9],[11,7.67],[11.5,15.1],[9.8,27.46]],"id":41419623},{"atb":[[42,0],[44,22.08],[50,0],[55,4.95]],"id":41419590},{"atb":[[130,4.95],[90,14.44],[95,12.63],[120,1.32]],"id":41419619},{"atb":[[42,0],[44,9.9],[50,3.23],[55,4.95]],"id":41419631},{"atl":[[21,4.95],[22,0],[25,9.9],[26,19.75]],"id":41419611},{"atb":[[32,4.95],[26,19.57],[27,9.9],[30,3.26]],"id":41419628},{"atl":[[34,4.8],[36,4.95],[42,0],[44,9.9]],"id":41419612},{"atb":[[85,0],[110,0],[120,4.95]],"id":41419592},{"atb":[[140,0],[150,4.95],[100,0],[110,9.9]],"id":41419588}],"con":true,"img":false}]}
{"op":"mcm","clk":"5353375321","pt":1646213917149,"mc":[{"id":"1.195503864","rc":[{"atb":[[110,0]],"id":41419597},{"atl":[[17.5,9.9],[15.5,4.95]],"id":41419610},{"atb":[[130,2.72],[140,4.95],[95,12.52],[100,9.9]],"id":41419615}],"con":true,"img":false}]}
{"op":"mcm","clk":"5353375333","pt":1646213917356,"mc":[{"id":"1.195503864","rc":[{"atl":[[950,2],[940,1.59]],"id":41419586},{"atl":[[920,1.62],[930,2]],"id":41419599}],"con":true,"img":false}]}
{"op":"mcm","clk":"5353375341","pt":1646213917460,"mc":[{"id":"1.195503864","rc":[{"atb":[[70,3.26],[80,23.82],[110,1.45]],"id":41419605},{"atl":[[140,0],[370,6.06]],"id":41419601},{"atl":[[28,35.33],[29,0]],"id":41419630},{"atb":[[18.5,3.26]],"id":41419626},{"atl":[[17,67.09],[38,2.7]],"id":41419610},{"atb":[[140,1.13],[90,0],[95,22.96]],"id":41419619},{"atb":[[38,0],[44,22.08],[55,7.89]],"id":41419631},{"atl":[[25,37.03],[26,0]],"id":41419611},{"atb":[[26,0],[30,20.72]],"id":41419628},{"atl":[[280,7.36],[95,0]],"id":41419628},{"atl":[[44,30.36],[110,2]],"id":41419612}],"con":true,"img":false}]}
{"op":"mcm","clk":"5353375349","pt":1646213917563,"mc":[{"id":"1.195503864","rc":[{"atb":[[19.5,35.03]],"id":41419626}],"con":true,"img":false}]}
{"op":"mcm","clk":"5353375353","pt":1646213917667,"mc":[{"id":"1.195503864","rc":[{"atb":[[75,18.48],[80,9.9]],"id":41419597},{"atl":[[15.5,15.88]],"id":41419610},{"atl":[[160,0],[380,4.37]],"id":41419603},{"atb":[[130,7.88],[95,0]],"id":41419615},{"atl":[[250,0]],"id":41419591}],"con":true,"img":false}]}
{"op":"mcm","clk":"5353375365","pt":1646213917876,"mc":[{"id":"1.195503864","rc":[{"atl":[[320,2],[250,0]],"id":41419609},{"atl":[[990,0]],"id":41419619},{"atb":[[17.5,0],[22,4.76]],"id":41419631},{"atb":[[34,0],[44,2.33]],"id":41419636},{"atl":[[540,0],[600,2]],"id":41419591},{"atb":[[8,14.29],[9.2,0]],"id":41419620},{"atb":[[8.4,18],[9.4,11.9]],"id":41419612},{"atl":[[1000,2]],"id":41419600}],"con":true,"img":false}]}
{"op":"mcm","clk":"5353375372","pt":1646213917934,"mc":[{"id":"1.195503864","rc":[{"atb":[[100,6.55]],"id":41419597}],"con":true,"img":false}]}
