{"op":"mcm","clk":"5317728509","pt":1646251399892,"mc":[{"id":"1.195532875","marketDefinition":{"bspMarket":true,"turnInPlayEnabled":false,"persistenceEnabled":false,"marketBaseRate":5.0,"eventId":"31275720","eventTypeId":"4339","numberOfWinners":2,"bettingType":"ODDS","marketType":"PLACE","marketTime":"2022-03-03T17:28:00.000Z","suspendTime":"2022-03-03T17:28:00.000Z","bspReconciled":false,"complete":true,"inPlay":false,"crossMatching":false,"runnersVoidable":false,"numberOfActiveRunners":6,"betDelay":0,"status":"OPEN","runners":[{"status":"ACTIVE","sortPriority":1,"id":40883678,"name":"1. Kincora For Real"},{"status":"ACTIVE","sortPriority":2,"id":40642034,"name":"2. Maple Patsy"},{"status":"ACTIVE","sortPriority":3,"id":39614765,"name":"3. Puttfor Juney"},{"status":"ACTIVE","sortPriority":4,"id":41469398,"name":"4. Droopys Good One"},{"status":"ACTIVE","sortPriority":5,"id":37306244,"name":"5. Ballyard Hilary"},{"status":"ACTIVE","sortPriority":6,"id":35985721,"name":"6. Waste House Izzy"}],"regulators":["MR_INT"],"venue":"Romford","countryCode":"GB","discountAllowed":false,"timezone":"Europe/London","openDate":"2022-03-03T13:57:00.000Z","version":4384107318,"name":"To Be Placed","eventName":"Romford 3rd Mar"},"rc":[],"con":true,"img":false}]}
{"op":"mcm","clk":"5317728863","pt":1646251401769,"mc":[{"id":"1.195532875","marketDefinition":{"bspMarket":true,"turnInPlayEnabled":false,"persistenceEnabled":false,"marketBaseRate":5.0,"eventId":"31275720","eventTypeId":"4339","numberOfWinners":2,"bettingType":"ODDS","marketType":"PLACE","marketTime":"2022-03-03T17:28:00.000Z","suspendTime":"2022-03-03T17:28:00.000Z","bspReconciled":false,"complete":true,"inPlay":false,"crossMatching":false,"runnersVoidable":false,"numberOfActiveRunners":6,"betDelay":0,"status":"OPEN","runners":[{"status":"ACTIVE","sortPriority":1,"id":40883678,"name":"1. Kincora For Real"},{"status":"ACTIVE","sortPriority":2,"id":40642034,"name":"2. Maple Patsy"},{"status":"ACTIVE","sortPriority":3,"id":39614765,"name":"3. Puttfor Juney"},{"status":"ACTIVE","sortPriority":4,"id":41469398,"name":"4. Droopys Good One"},{"status":"ACTIVE","sortPriority":5,"id":37306244,"name":"5. Ballyard Hilary"},{"status":"ACTIVE","sortPriority":6,"id":35985721,"name":"6. Waste House Izzy"}],"regulators":["MR_INT"],"venue":"Romford","countryCode":"GB","discountAllowed":true,"timezone":"Europe/London","openDate":"2022-03-03T13:57:00.000Z","version":4384107318,"name":"To Be Placed","eventName":"Romford 3rd Mar"},"rc":[],"con":true,"img":false}]}
{"op":"mcm","clk":"5320506858","pt":1646296630951,"mc":[{"id":"1.195532875","rc":[{"spl":[[1.01,10]],"id":39614765},{"spn":1.0,"spf":1.0,"id":39614765}],"con":true,"img":false}]}
{"op":"mcm","clk":"5321882305","pt":1646314109391,"mc":[{"id":"1.195532875","rc":[{"atb":[[1.01,102.04]],"id":40883678},{"spn":"Infinity","spf":"NaN","id":40883678}],"con":true,"img":false}]}
{"op":"mcm","clk":"5321882314","pt":1646314109493,"mc":[{"id":"1.195532875","rc":[{"atb":[[1.01,102.04]],"id":40642034}],"con":true,"img":false}]}
{"op":"mcm","clk":"5321882321","pt":1646314109596,"mc":[{"id":"1.195532875","rc":[{"atb":[[1.01,102.04]],"id":39614765}],"con":true,"img":false}]}
{"op":"mcm","clk":"5321882335","pt":1646314109758,"mc":[{"id":"1.195532875","rc":[{"atb":[[1.01,102.04]],"id":37306244},{"atb":[[1.01,102.04]],"id":41469398}],"con":true,"img":false}]}
{"op":"mcm","clk":"5321882342","pt":1646314109859,"mc":[{"id":"1.195532875","rc":[{"atb":[[1.01,102.04]],"id":35985721}],"con":true,"img":false}]}
{"op":"mcm","clk":"5321918730","pt":1646314530172,"mc":[{"id":"1.195532875","rc":[{"atl":[[1000,5]],"id":37306244},{"spn":500.5,"spf":"NaN","id":37306244},{"atl":[[1000,5]],"id":41469398},{"spn":500.5,"spf":"NaN","id":41469398},{"atl":[[1000,5]],"id":35985721},{"spn":500.5,"spf":"NaN","id":35985721},{"atl":[[1000,5]],"id":39614765},{"spn":1.01,"spf":1.0,"id":39614765},{"atl":[[1000,5]],"id":40642034},{"spn":500.5,"spf":"NaN","id":40642034},{"atl":[[1000,5]],"id":40883678},{"spn":500.5,"spf":"NaN","id":40883678}],"con":true,"img":false}]}
{"op":"mcm","clk":"5321918757","pt":1646314530380,"mc":[{"id":"1.195532875","rc":[{"atb":[[1.01,4802.04]],"id":37306244},{"atb":[[1.01,4802.04]],"id":41469398},{"atb":[[1.01,4802.04]],"id":35985721},{"atb":[[1.01,4802.04]],"id":39614765},{"atb":[[1.01,4802.04]],"id":40642034},{"atb":[[1.01,4802.04]],"id":40883678}],"con":true,"img":false}]}
{"op":"mcm","clk":"5322617796","pt":1646322425383,"mc":[{"id":"1.195532875","rc":[{"spl":[[1.01,1]],"id":37306244},{"spn":1.01,"spf":1.0,"id":37306244},{"spl":[[1.01,1]],"id":41469398},{"spn":1.01,"spf":1.0,"id":41469398}],"con":true,"img":false}]}
{"op":"mcm","clk":"5322953569","pt":1646325725110,"mc":[{"id":"1.195532875","rc":[{"atl":[[46,2.74]],"id":37306244},{"atl":[[46,2.74]],"id":41469398},{"atl":[[46,2.74]],"id":35985721},{"spn":23.5,"spf":"NaN","id":35985721},{"atl":[[46,2.74]],"id":39614765},{"atl":[[46,2.74]],"id":40642034},{"spn":23.5,"spf":"NaN","id":40642034},{"atl":[[46,2.74]],"id":40883678},{"spn":23.5,"spf":"NaN","id":40883678}],"con":true,"img":false}]}
{"op":"mcm","clk":"5323002162","pt":1646326262371,"mc":[{"id":"1.195532875","rc":[{"spl":[[1.01,9.24]],"id":35985721},{"spn":1.01,"spf":1.0,"id":35985721}],"con":true,"img":false}]}
{"op":"mcm","clk":"5323031818","pt":1646326680767,"mc":[{"id":"1.195532875","rc":[{"atb":[[1.01,5052.04]],"id":37306244},{"atl":[[70,2.17],[80,3.16],[50,1],[60,1.69]],"id":37306244},{"atb":[[1.01,5052.04]],"id":41469398},{"atl":[[70,2.17],[80,3.16],[50,1],[60,1.69]],"id":41469398},{"atb":[[1.01,5052.04]],"id":35985721},{"atl":[[70,2.17],[80,3.16],[50,1],[60,1.69]],"id":35985721},{"atb":[[1.01,5052.04]],"id":39614765},{"atl":[[70,2.17],[80,3.16],[50,1],[60,1.69]],"id":39614765},{"atb":[[1.01,5052.04]],"id":40642034},{"atl":[[70,2.17],[80,3.16],[50,1],[60,1.69]],"id":40642034},{"atb":[[1.01,5052.04]],"id":40883678},{"atl":[[70,2.17],[80,3.16],[50,1],[60,1.69]],"id":40883678}],"con":true,"img":false}]}
{"op":"mcm","clk":"5323033610","pt":1646326710636,"mc":[{"id":"1.195532875","marketDefinition":{"bspMarket":true,"turnInPlayEnabled":false,"persistenceEnabled":false,"marketBaseRate":5.0,"eventId":"31275720","eventTypeId":"4339","numberOfWinners":2,"bettingType":"ODDS","marketType":"PLACE","marketTime":"2022-03-03T17:28:00.000Z","suspendTime":"2022-03-03T17:28:00.000Z","bspReconciled":false,"complete":true,"inPlay":false,"crossMatching":true,"runnersVoidable":false,"numberOfActiveRunners":6,"betDelay":0,"status":"OPEN","runners":[{"status":"ACTIVE","sortPriority":1,"id":40883678,"name":"1. Kincora For Real"},{"status":"ACTIVE","sortPriority":2,"id":40642034,"name":"2. Maple Patsy"},{"status":"ACTIVE","sortPriority":3,"id":39614765,"name":"3. Puttfor Juney"},{"status":"ACTIVE","sortPriority":4,"id":41469398,"name":"4. Droopys Good One"},{"status":"ACTIVE","sortPriority":5,"id":37306244,"name":"5. Ballyard Hilary"},{"status":"ACTIVE","sortPriority":6,"id":35985721,"name":"6. Waste House Izzy"}],"regulators":["MR_INT"],"venue":"Romford","countryCode":"GB","discountAllowed":true,"timezone":"Europe/London","openDate":"2022-03-03T13:57:00.000Z","version":4384107318,"name":"To Be Placed","eventName":"Romford 3rd Mar"},"rc":[],"con":true,"img":false}]}
{"op":"mcm","clk":"5323108431","pt":1646327580395,"mc":[{"id":"1.195532875","rc":[{"atb":[[1.69,144.93]],"id":37306244},{"atl":[[9.2,2]],"id":37306244},{"spn":1.69,"spf":1.0,"id":37306244},{"atb":[[1.76,131.58]],"id":41469398},{"atl":[[42,2]],"id":41469398},{"spn":1.76,"spf":1.0,"id":41469398},{"atb":[[1.73,136.99]],"id":35985721},{"atl":[[18,2]],"id":35985721},{"spn":1.73,"spf":1.0,"id":35985721},{"atb":[[1.55,181.82]],"id":39614765},{"atl":[[13.5,2]],"id":39614765},{"spn":1.55,"spf":1.0,"id":39614765},{"atb":[[1.27,370.37]],"id":40642034},{"atl":[[6.6,2]],"id":40642034},{"spn":3.93,"spf":"NaN","id":40642034},{"atb":[[1.04,2500]],"id":40883678},{"atl":[[3.85,2]],"id":40883678},{"spn":2.44,"spf":"NaN","id":40883678}],"con":true,"img":false}]}
{"op":"mcm","clk":"5323108483","pt":1646327580916,"mc":[{"id":"1.195532875","rc":[{"atb":[[1.67,59.7]],"id":37306244},{"atl":[[9.6,4.65],[50,0]],"id":37306244},{"atl":[[50,0]],"id":41469398},{"atb":[[1.71,56.34]],"id":35985721},{"atl":[[19,2.22],[50,0]],"id":35985721},{"atb":[[1.53,75.47]],"id":39614765},{"atl":[[50,0],[14.5,2.96]],"id":39614765},{"atb":[[1.25,160]],"id":40642034},{"atl":[[50,0],[7,6.67]],"id":40642034},{"atb":[[1.02,250]],"id":40883678},{"atl":[[3.95,13.56],[50,0]],"id":40883678}],"con":true,"img":false}]}
{"op":"mcm","clk":"5323108495","pt":1646327581020,"mc":[{"id":"1.195532875","rc":[{"atb":[[1.74,54.05]],"id":41469398},{"atl":[[46,3.74]],"id":41469398}],"con":true,"img":false}]}
{"op":"mcm","clk":"5323108761","pt":1646327583695,"mc":[{"id":"1.195532875","rc":[{"atb":[[1.02,1109.12]],"id":39614765},{"atb":[[1.02,1222.21]],"id":40642034}],"con":true,"img":false}]}
{"op":"mcm","clk":"5323109452","pt":1646327590538,"mc":[{"id":"1.195532875","rc":[{"atb":[[1.8,125],[1.69,0]],"id":37306244},{"atb":[[2.16,86.21],[1.76,0]],"id":41469398},{"atb":[[1.73,0],[1.85,117.65]],"id":35985721},{"atl":[[17,2.22]],"id":35985721},{"atb":[[1.73,136.99],[1.55,0]],"id":39614765},{"atb":[[1.45,222.22]],"id":40642034},{"atb":[[1.15,666.67],[1.04,0]],"id":40883678}],"con":true,"img":false}]}
{"op":"mcm","clk":"5323109461","pt":1646327590637,"mc":[{"id":"1.195532875","rc":[{"atl":[[18,0]],"id":35985721}],"con":true,"img":false}]}
{"op":"mcm","clk":"5323109471","pt":1646327590746,"mc":[{"id":"1.195532875","rc":[{"atb":[[1.27,0]],"id":40642034}],"con":true,"img":false}]}
{"op":"mcm","clk":"5323109488","pt":1646327590914,"mc":[{"id":"1.195532875","rc":[{"atb":[[1.78,51.28]],"id":37306244},{"atl":[[10,11.11]],"id":37306244},{"atb":[[2.12,35.71]],"id":41469398},{"atl":[[50,2.04]],"id":41469398},{"atb":[[1.83,48.19]],"id":35985721},{"atl":[[18,2.35],[19,0]],"id":35985721},{"atb":[[1.71,56.34]],"id":39614765},{"atl":[[15.5,6.9]],"id":39614765},{"atb":[[1.43,93.02]],"id":40642034},{"atl":[[7.4,15.62]],"id":40642034},{"atb":[[1.13,250]],"id":40883678},{"atl":[[4.1,32.26]],"id":40883678}],"con":true,"img":false}]}
{"op":"mcm","clk":"5323109539","pt":1646327591427,"mc":[{"id":"1.195532875","rc":[{"atl":[[80,0]],"id":37306244},{"atl":[[80,0]],"id":41469398},{"atl":[[70,0],[80,0],[60,0]],"id":39614765},{"atl":[[70,0],[80,0],[60,0]],"id":40642034},{"atl":[[70,0],[80,0],[60,0]],"id":40883678}],"con":true,"img":false}]}
{"op":"mcm","clk":"5323109638","pt":1646327592631,"mc":[{"id":"1.195532875","rc":[{"atb":[[2.18,1.65]],"id":41469398}],"con":true,"img":false}]}
{"op":"mcm","clk":"5323109671","pt":1646327593051,"mc":[{"id":"1.195532875","rc":[{"atb":[[2.14,35.09]],"id":41469398}],"con":true,"img":false}]}
{"op":"mcm","clk":"5323109722","pt":1646327593622,"mc":[{"id":"1.195532875","rc":[{"atl":[[6.4,6.67],[6.6,0]],"id":40642034}],"con":true,"img":false}]}
{"op":"mcm","clk":"5323109757","pt":1646327594054,"mc":[{"id":"1.195532875","rc":[{"atb":[[2.22,2.15]],"id":41469398}],"con":true,"img":false}]}
{"op":"mcm","clk":"5323109788","pt":1646327594356,"mc":[{"id":"1.195532875","rc":[{"atb":[[2.18,35.55],[2.14,0]],"id":41469398},{"atl":[[6.8,6.9]],"id":40642034}],"con":true,"img":false}]}
{"op":"mcm","clk":"5323109855","pt":1646327595039,"mc":[{"id":"1.195532875","rc":[{"atb":[[1.02,0]],"id":39614765},{"atb":[[1.02,0]],"id":40642034},{"atb":[[1.03,1219.54]],"id":40883678}],"con":true,"img":false}]}
{"op":"mcm","clk":"5323110261","pt":1646327599968,"mc":[{"id":"1.195532875","rc":[{"atb":[[1.54,67.75]],"id":39614765},{"atb":[[1.26,140.71]],"id":40642034}],"con":true,"img":false}]}
{"op":"mcm","clk":"5323110316","pt":1646327600540,"mc":[{"id":"1.195532875","rc":[{"atb":[[2.22,37.71]],"id":41469398}],"con":true,"img":false}]}
{"op":"mcm","clk":"5323110323","pt":1646327600642,"mc":[{"id":"1.195532875","rc":[{"atb":[[2.18,33.9],[2.16,0]],"id":41469398},{"atb":[[1.15,0],[1.16,625]],"id":40883678}],"con":true,"img":false}]}
{"op":"mcm","clk":"5323110337","pt":1646327600844,"mc":[{"id":"1.195532875","rc":[{"atb":[[2.24,1.65]],"id":41469398}],"con":true,"img":false}]}
{"op":"mcm","clk":"5323110350","pt":1646327600958,"mc":[{"id":"1.195532875","rc":[{"atb":[[1.76,131.58]],"id":37306244},{"atl":[[11,15]],"id":37306244},{"atb":[[1.81,123.46]],"id":35985721},{"atl":[[19,5.56]],"id":35985721},{"atb":[[1.69,144.93]],"id":39614765},{"atl":[[16.5,9.68]],"id":39614765},{"atb":[[1.14,250]],"id":40883678},{"atl":[[4.3,45.45]],"id":40883678}],"con":true,"img":false}]}
{"op":"mcm","clk":"5323110399","pt":1646327601430,"mc":[{"id":"1.195532875","rc":[{"atb":[[1.83,2.15]],"id":37306244},{"atb":[[1.88,2.15]],"id":35985721},{"atb":[[1.76,2.15]],"id":39614765}],"con":true,"img":false}]}
{"op":"mcm","clk":"5323110409","pt":1646327601532,"mc":[{"id":"1.195532875","rc":[{"atb":[[1.83,53.43]],"id":37306244},{"atb":[[1.88,50.34],[1.85,0]],"id":35985721},{"atb":[[1.76,58.49]],"id":39614765}],"con":true,"img":false}]}
{"op":"mcm","clk":"5323110414","pt":1646327601633,"mc":[{"id":"1.195532875","rc":[{"atb":[[1.8,0]],"id":37306244},{"atb":[[1.73,0]],"id":39614765}],"con":true,"img":false}]}
{"op":"mcm","clk":"5323110663","pt":1646327604349,"mc":[{"id":"1.195532875","rc":[{"atb":[[2.18,0],[2.2,33.33]],"id":41469398},{"atl":[[70,3.62]],"id":41469398},{"atb":[[1.54,0]],"id":39614765},{"atb":[[1.41,243.9]],"id":40642034},{"atl":[[7.2,16.13]],"id":40642034},{"atb":[[1.03,0]],"id":40883678}],"con":true,"img":false}]}
{"op":"mcm","clk":"5323110704","pt":1646327604763,"mc":[{"id":"1.195532875","rc":[{"atb":[[1.48,2.15]],"id":40642034}],"con":true,"img":false}]}
{"op":"mcm","clk":"5323110720","pt":1646327604935,"mc":[{"id":"1.195532875","rc":[{"atb":[[1.45,0],[1.48,95.17]],"id":40642034}],"con":true,"img":false}]}
{"op":"mcm","clk":"5323111052","pt":1646327609070,"mc":[{"id":"1.195532875","rc":[{"atb":[[1.26,0]],"id":40642034}],"con":true,"img":false}]}
{"op":"mcm","clk":"5323111063","pt":1646327609173,"mc":[{"id":"1.195532875","rc":[{"atb":[[1.72,50.81]],"id":39614765},{"atb":[[1.17,215.21]],"id":40883678}],"con":true,"img":false}]}
{"op":"mcm","clk":"5323111075","pt":1646327609377,"mc":[{"id":"1.195532875","rc":[{"atb":[[1.18,250],[1.16,0]],"id":40883678}],"con":true,"img":false}]}
{"op":"mcm","clk":"5323111108","pt":1646327609650,"mc":[{"id":"1.195532875","rc":[{"atb":[[1.81,49.38],[1.78,0]],"id":37306244},{"atl":[[70,0]],"id":37306244},{"atb":[[1.74,54.05],[1.71,0]],"id":39614765},{"atb":[[1.46,86.96],[1.43,0]],"id":40642034},{"atb":[[1.16,250],[1.14,0]],"id":40883678}],"con":true,"img":false}]}
{"op":"mcm","clk":"5323111151","pt":1646327610173,"mc":[{"id":"1.195532875","rc":[{"atb":[[1.83,0],[1.86,46.51]],"id":35985721},{"atl":[[80,0]],"id":35985721},{"atl":[[13.5,0],[14,6.9]],"id":39614765}],"con":true,"img":false}]}
{"op":"mcm","clk":"5323111269","pt":1646327611582,"mc":[{"id":"1.195532875","rc":[{"atb":[[2.3,33.33],[2.22,2.15]],"id":41469398},{"atb":[[1.44,83.14]],"id":40642034}],"con":true,"img":false}]}
{"op":"mcm","clk":"5323111279","pt":1646327611688,"mc":[{"id":"1.195532875","rc":[{"atl":[[15,2.86]],"id":39614765}],"con":true,"img":false}]}
{"op":"mcm","clk":"5323111290","pt":1646327611794,"mc":[{"id":"1.195532875","rc":[{"atl":[[14.5,0]],"id":39614765}],"con":true,"img":false}]}
{"op":"mcm","clk":"5323111325","pt":1646327612166,"mc":[{"id":"1.195532875","rc":[{"atb":[[2.36,2.15],[2.22,0]],"id":41469398}],"con":true,"img":false}]}
{"op":"mcm","clk":"5323111488","pt":1646327613874,"mc":[{"id":"1.195532875","rc":[{"atb":[[1.72,0]],"id":39614765},{"atb":[[1.17,0]],"id":40883678}],"con":true,"img":false}]}
{"op":"mcm","clk":"5323111532","pt":1646327614385,"mc":[{"id":"1.195532875","rc":[{"atb":[[2.32,30.3],[2.2,0]],"id":41469398}],"con":true,"img":false}]}
{"op":"mcm","clk":"5323111541","pt":1646327614513,"mc":[{"id":"1.195532875","rc":[{"atb":[[1.18,0],[1.16,750]],"id":40883678}],"con":true,"img":false}]}
{"op":"mcm","clk":"5323111625","pt":1646327615363,"mc":[{"id":"1.195532875","rc":[{"atl":[[6.4,0],[6.6,13.34]],"id":40642034},{"atb":[[1.16,500],[1.14,250]],"id":40883678}],"con":true,"img":false}]}
{"op":"mcm","clk":"5323111645","pt":1646327615577,"mc":[{"id":"1.195532875","rc":[{"atl":[[6.8,0]],"id":40642034}],"con":true,"img":false}]}
{"op":"mcm","clk":"5323111695","pt":1646327615985,"mc":[{"id":"1.195532875","rc":[{"atb":[[1.44,0]],"id":40642034}],"con":true,"img":false}]}
{"op":"mcm","clk":"5323111778","pt":1646327616570,"mc":[{"id":"1.195532875","rc":[{"atb":[[2.24,0]],"id":41469398}],"con":true,"img":false}]}
{"op":"mcm","clk":"5323111805","pt":1646327616781,"mc":[{"id":"1.195532875","rc":[{"atb":[[2.38,1.65]],"id":41469398}],"con":true,"img":false}]}
{"op":"mcm","clk":"5323111876","pt":1646327617465,"mc":[{"id":"1.195532875","rc":[{"atb":[[2.32,0],[2.34,29.85]],"id":41469398}],"con":true,"img":false}]}
{"op":"mcm","clk":"5323112033","pt":1646327618990,"mc":[{"id":"1.195532875","rc":[{"atb":[[1.7,52.26]],"id":39614765},{"atb":[[1.17,215.21]],"id":40883678}],"con":true,"img":false}]}
{"op":"mcm","clk":"5323112071","pt":1646327619399,"mc":[{"id":"1.195532875","rc":[{"atb":[[1.15,250],[1.14,0]],"id":40883678}],"con":true,"img":false}]}
{"op":"mcm","clk":"5323112100","pt":1646327619669,"mc":[{"id":"1.195532875","rc":[{"atb":[[1.79,126.58]],"id":37306244},{"atl":[[12,22.73]],"id":37306244},{"atb":[[1.44,227.27]],"id":40642034},{"atl":[[7.8,22.06]],"id":40642034}],"con":true,"img":false}]}
{"op":"mcm","clk":"5323112151","pt":1646327620195,"mc":[{"id":"1.195532875","rc":[{"atb":[[1.84,119.05]],"id":35985721},{"atl":[[20,7.89]],"id":35985721}],"con":true,"img":false}]}
{"op":"mcm","clk":"5323112205","pt":1646327620777,"mc":[{"id":"1.195532875","rc":[{"atb":[[1.76,0]],"id":37306244},{"atl":[[60,0]],"id":37306244},{"atb":[[1.01,4802.04],[1.81,0],[1.71,0]],"id":35985721},{"atl":[[70,0]],"id":35985721},{"atl":[[13.5,6.9],[14,0]],"id":39614765},{"atb":[[1.41,0],[1.01,4802.04],[1.25,0]],"id":40642034}],"con":true,"img":false}]}
{"op":"mcm","clk":"5323112256","pt":1646327621299,"mc":[{"id":"1.195532875","rc":[{"atb":[[1.42,87.1]],"id":40642034}],"con":true,"img":false}]}
{"op":"mcm","clk":"5323112266","pt":1646327621397,"mc":[{"id":"1.195532875","rc":[{"atb":[[2.3,0],[2.38,3.81]],"id":41469398}],"con":true,"img":false}]}
{"op":"mcm","clk":"5323112273","pt":1646327621496,"mc":[{"id":"1.195532875","rc":[{"atl":[[14.5,2.96]],"id":39614765}],"con":true,"img":false}]}
{"op":"mcm","clk":"5323112555","pt":1646327624295,"mc":[{"id":"1.195532875","rc":[{"atb":[[1.18,250],[1.16,0]],"id":40883678}],"con":true,"img":false}]}
{"op":"mcm","clk":"5323112612","pt":1646327624868,"mc":[{"id":"1.195532875","rc":[{"atb":[[1.15,0],[1.16,250]],"id":40883678}],"con":true,"img":false}]}
{"op":"mcm","clk":"5323112714","pt":1646327625804,"mc":[{"id":"1.195532875","rc":[{"atb":[[1.7,0]],"id":39614765},{"atb":[[1.42,0]],"id":40642034},{"atl":[[6.4,13.34],[6.6,0]],"id":40642034}],"con":true,"img":false}]}
{"op":"mcm","clk":"5323112746","pt":1646327626092,"mc":[{"id":"1.195532875","rc":[{"atl":[[6.8,6.67]],"id":40642034}],"con":true,"img":false}]}
{"op":"mcm","clk":"5323112756","pt":1646327626189,"mc":[{"id":"1.195532875","rc":[{"atl":[[6.8,13.57],[7,0]],"id":40642034}],"con":true,"img":false}]}
{"op":"mcm","clk":"5323112769","pt":1646327626294,"mc":[{"id":"1.195532875","rc":[{"atl":[[6.8,6.9]],"id":40642034}],"con":true,"img":false}]}
{"op":"mcm","clk":"5323112898","pt":1646327627508,"mc":[{"id":"1.195532875","rc":[{"atb":[[2.3,76.92]],"id":41469398}],"con":true,"img":false}]}
{"op":"mcm","clk":"5323112982","pt":1646327628080,"mc":[{"id":"1.195532875","rc":[{"atb":[[1.17,0]],"id":40883678}],"con":true,"img":false}]}
{"op":"mcm","clk":"5323113046","pt":1646327628604,"mc":[{"id":"1.195532875","rc":[{"atb":[[1.74,0],[2.12,0]],"id":41469398}],"con":true,"img":false}]}
{"op":"mcm","clk":"5323113135","pt":1646327629388,"mc":[{"id":"1.195532875","rc":[{"atb":[[1.18,0],[1.17,500]],"id":40883678}],"con":true,"img":false}]}
{"op":"mcm","clk":"5323113163","pt":1646327629710,"mc":[{"id":"1.195532875","rc":[{"atb":[[1.77,194.81]],"id":37306244}],"con":true,"img":false}]}
{"op":"mcm","clk":"5323113211","pt":1646327630211,"mc":[{"id":"1.195532875","rc":[{"atb":[[1.01,4802.04]],"id":37306244},{"atb":[[1.82,182.93]],"id":35985721},{"atl":[[22,11.9]],"id":35985721}],"con":true,"img":false}]}
{"op":"mcm","clk":"5323113233","pt":1646327630412,"mc":[{"id":"1.195532875","rc":[{"atb":[[1.16,0],[1.15,250]],"id":40883678}],"con":true,"img":false}]}
{"op":"mcm","clk":"5323113242","pt":1646327630488,"mc":[{"id":"1.195532875","rc":[{"atl":[[60,0]],"id":35985721}],"con":true,"img":false}]}
{"op":"mcm","clk":"5323113270","pt":1646327630792,"mc":[{"id":"1.195532875","rc":[{"atb":[[1.7,52.26]],"id":39614765},{"atb":[[1.49,66.62]],"id":40642034}],"con":true,"img":false}]}
{"op":"mcm","clk":"5323113291","pt":1646327631000,"mc":[{"id":"1.195532875","rc":[{"atb":[[1.5,86.96],[1.48,2.15]],"id":40642034}],"con":true,"img":false}]}
{"op":"mcm","clk":"5323113296","pt":1646327631102,"mc":[{"id":"1.195532875","rc":[{"atl":[[40,2.04],[42,0]],"id":41469398},{"atb":[[1.47,85.11]],"id":40642034},{"atl":[[3.85,0],[3.9,32.26]],"id":40883678}],"con":true,"img":false}]}
{"op":"mcm","clk":"5323113315","pt":1646327631313,"mc":[{"id":"1.195532875","rc":[{"atb":[[1.48,0],[1.52,2.15]],"id":40642034},{"atl":[[4.2,16.13]],"id":40883678}],"con":true,"img":false}]}
{"op":"mcm","clk":"5323113323","pt":1646327631414,"mc":[{"id":"1.195532875","rc":[{"atl":[[44,1],[46,2.74]],"id":41469398},{"atb":[[1.48,83.33]],"id":40642034},{"atl":[[4,13.33],[3.95,0]],"id":40883678}],"con":true,"img":false}]}
{"op":"mcm","clk":"5323113335","pt":1646327631509,"mc":[{"id":"1.195532875","rc":[{"atb":[[1.72,138.89]],"id":39614765},{"atl":[[17.5,15.15]],"id":39614765},{"atl":[[4.2,0]],"id":40883678}],"con":true,"img":false}]}
{"op":"mcm","clk":"5323113401","pt":1646327632104,"mc":[{"id":"1.195532875","rc":[{"atb":[[1.01,4802.04],[1.53,0],[1.69,0]],"id":39614765},{"atl":[[15,0]],"id":39614765},{"atb":[[1.5,166.96],[1.48,0]],"id":40642034}],"con":true,"img":false}]}
{"op":"mcm","clk":"5323113533","pt":1646327633404,"mc":[{"id":"1.195532875","rc":[{"atb":[[1.18,203.26]],"id":40883678}],"con":true,"img":false}]}
{"op":"mcm","clk":"5323113726","pt":1646327635412,"mc":[{"id":"1.195532875","rc":[{"atb":[[1.16,62.5]],"id":40883678}],"con":true,"img":false}]}
{"op":"mcm","clk":"5323113746","pt":1646327635618,"mc":[{"id":"1.195532875","rc":[{"atb":[[1.16,0]],"id":40883678}],"con":true,"img":false}]}
{"op":"mcm","clk":"5323113771","pt":1646327635883,"mc":[{"id":"1.195532875","rc":[{"atb":[[1.43,36.84]],"id":40642034}],"con":true,"img":false}]}
{"op":"mcm","clk":"5323113787","pt":1646327636100,"mc":[{"id":"1.195532875","rc":[{"atb":[[1.43,0]],"id":40642034}],"con":true,"img":false}]}
{"op":"mcm","clk":"5323113871","pt":1646327637023,"mc":[{"id":"1.195532875","rc":[{"atl":[[9,4.65],[9.2,0]],"id":37306244},{"atb":[[1.15,0],[1.16,250]],"id":40883678}],"con":true,"img":false}]}
{"op":"mcm","clk":"5323113882","pt":1646327637083,"mc":[{"id":"1.195532875","rc":[{"atb":[[1.99,25]],"id":37306244}],"con":true,"img":false}]}
{"op":"mcm","clk":"5323113893","pt":1646327637196,"mc":[{"id":"1.195532875","rc":[{"atb":[[1.99,0]],"id":37306244},{"atl":[[10.5,5.55]],"id":37306244}],"con":true,"img":false}]}
{"op":"mcm","clk":"5323113903","pt":1646327637293,"mc":[{"id":"1.195532875","rc":[{"atl":[[10.5,0]],"id":37306244}],"con":true,"img":false}]}
{"op":"mcm","clk":"5323113941","pt":1646327637714,"mc":[{"id":"1.195532875","rc":[{"atb":[[1.7,0]],"id":39614765},{"atb":[[1.49,0]],"id":40642034}],"con":true,"img":false}]}
{"op":"mcm","clk":"5323114061","pt":1646327639018,"mc":[{"id":"1.195532875","rc":[{"atb":[[1.19,250]],"id":40883678}],"con":true,"img":false}]}
{"op":"mcm","clk":"5323114071","pt":1646327639119,"mc":[{"id":"1.195532875","rc":[{"atb":[[1.17,0]],"id":40883678}],"con":true,"img":false}]}
{"op":"mcm","clk":"5323114108","pt":1646327639488,"mc":[{"id":"1.195532875","rc":[{"atb":[[1.83,18.11]],"id":39614765}],"con":true,"img":false}]}
{"op":"mcm","clk":"5323114117","pt":1646327639591,"mc":[{"id":"1.195532875","rc":[{"atb":[[1.83,0]],"id":39614765}],"con":true,"img":false}]}
{"op":"mcm","clk":"5323114125","pt":1646327639704,"mc":[{"id":"1.195532875","rc":[{"atb":[[1.75,250]],"id":37306244},{"atl":[[9.6,0],[9.4,4.76]],"id":37306244}],"con":true,"img":false}]}
{"op":"mcm","clk":"5323114169","pt":1646327640216,"mc":[{"id":"1.195532875","rc":[{"atb":[[1.8,250]],"id":35985721}],"con":true,"img":false}]}
{"op":"mcm","clk":"5323114180","pt":1646327640321,"mc":[{"id":"1.195532875","rc":[{"atb":[[1.01,5054.04]],"id":40883678}],"con":true,"img":false}]}
{"op":"mcm","clk":"5323114206","pt":1646327640626,"mc":[{"id":"1.195532875","rc":[{"spn":1.83,"spf":1.0,"id":37306244},{"spn":2.38,"spf":1.0,"id":41469398},{"spn":1.88,"spf":1.0,"id":35985721},{"spn":1.76,"spf":1.0,"id":39614765},{"atb":[[1.5,80],[1.52,87.26]],"id":40642034},{"spn":3.96,"spf":"NaN","id":40642034},{"spn":2.54,"spf":"NaN","id":40883678}],"con":true,"img":false}]}
{"op":"mcm","clk":"5323114216","pt":1646327640698,"mc":[{"id":"1.195532875","rc":[{"atb":[[2.06,23.36]],"id":35985721}],"con":true,"img":false}]}
{"op":"mcm","clk":"5323114236","pt":1646327640906,"mc":[{"id":"1.195532875","rc":[{"atb":[[1.67,0]],"id":37306244},{"atb":[[2.02,39.22],[1.86,0]],"id":35985721},{"atb":[[1.16,0],[1.17,235.29]],"id":40883678}],"con":true,"img":false}]}
{"op":"mcm","clk":"5323114246","pt":1646327641002,"mc":[{"id":"1.195532875","rc":[{"atb":[[2.04,50.35]],"id":35985721}],"con":true,"img":false}]}
{"op":"mcm","clk":"5323114257","pt":1646327641107,"mc":[{"id":"1.195532875","rc":[{"atb":[[1.88,2.15]],"id":35985721}],"con":true,"img":false}]}
{"op":"mcm","clk":"5323114269","pt":1646327641206,"mc":[{"id":"1.195532875","rc":[{"atb":[[2.06,0],[1.89,112.36],[2.04,0]],"id":35985721}],"con":true,"img":false}]}
{"op":"mcm","clk":"5323114292","pt":1646327641416,"mc":[{"id":"1.195532875","rc":[{"atb":[[2.26,119.05]],"id":41469398},{"atb":[[2.02,112.93],[1.89,0]],"id":35985721}],"con":true,"img":false}]}
{"op":"mcm","clk":"5323114299","pt":1646327641520,"mc":[{"id":"1.195532875","rc":[{"atb":[[1.7,214.29]],"id":39614765}],"con":true,"img":false}]}
{"op":"mcm","clk":"5323114351","pt":1646327642113,"mc":[{"id":"1.195532875","rc":[{"atl":[[7.6,22.73]],"id":40642034}],"con":true,"img":false}]}
{"op":"mcm","clk":"5323114386","pt":1646327642417,"mc":[{"id":"1.195532875","rc":[{"atb":[[1.99,40.4],[2.02,73.71]],"id":35985721},{"atl":[[7.4,0],[7.8,0]],"id":40642034},{"atb":[[1.2,235.29],[1.19,0]],"id":40883678},{"atl":[[3.95,33.9],[3.9,0]],"id":40883678}],"con":true,"img":false}]}
{"op":"mcm","clk":"5323114398","pt":1646327642516,"mc":[{"id":"1.195532875","rc":[{"atb":[[1.18,0],[1.54,45.46]],"id":40883678}],"con":true,"img":false}]}
{"op":"mcm","clk":"5323114410","pt":1646327642621,"mc":[{"id":"1.195532875","rc":[{"atb":[[1.77,40.94]],"id":39614765},{"atb":[[1.51,71.74]],"id":40642034}],"con":true,"img":false}]}
{"op":"mcm","clk":"5323114426","pt":1646327642830,"mc":[{"id":"1.195532875","rc":[{"atb":[[1.78,54.05],[1.76,2.15]],"id":39614765}],"con":true,"img":false}]}
{"op":"mcm","clk":"5323114446","pt":1646327642993,"mc":[{"id":"1.195532875","rc":[{"atb":[[1.8,2.15],[1.76,0]],"id":39614765},{"atb":[[1.57,2.15]],"id":40883678}],"con":true,"img":false}]}
{"op":"mcm","clk":"5323114458","pt":1646327643101,"mc":[{"id":"1.195532875","rc":[{"atb":[[1.8,43.1]],"id":39614765},{"atb":[[1.2,0],[1.57,47.61]],"id":40883678}],"con":true,"img":false}]}
{"op":"mcm","clk":"5323114473","pt":1646327643205,"mc":[{"id":"1.195532875","rc":[{"atb":[[1.78,0]],"id":39614765}],"con":true,"img":false}]}
{"op":"mcm","clk":"5323114576","pt":1646327644203,"mc":[{"id":"1.195532875","rc":[{"atb":[[1.54,0]],"id":40883678}],"con":true,"img":false}]}
{"op":"mcm","clk":"5323114672","pt":1646327645138,"mc":[{"id":"1.195532875","rc":[{"atb":[[1.18,200.02]],"id":40883678}],"con":true,"img":false}]}
{"op":"mcm","clk":"5323114713","pt":1646327645510,"mc":[{"id":"1.195532875","rc":[{"atb":[[1.01,5056.03]],"id":40883678}],"con":true,"img":false}]}
{"op":"mcm","clk":"5323114745","pt":1646327645816,"mc":[{"id":"1.195532875","rc":[{"atb":[[1.01,5054.04]],"id":40883678}],"con":true,"img":false}]}
{"op":"mcm","clk":"5323114757","pt":1646327645929,"mc":[{"id":"1.195532875","rc":[{"atb":[[1.19,1.99]],"id":40883678}],"con":true,"img":false}]}
{"op":"mcm","clk":"5323114794","pt":1646327646240,"mc":[{"id":"1.195532875","rc":[{"atb":[[1.01,4804.04]],"id":40642034}],"con":true,"img":false}]}
{"op":"mcm","clk":"5323114825","pt":1646327646506,"mc":[{"id":"1.195532875","rc":[{"atb":[[1.01,4806.03]],"id":40642034}],"con":true,"img":false}]}
{"op":"mcm","clk":"5323114838","pt":1646327646602,"mc":[{"id":"1.195532875","rc":[{"atb":[[2.02,0],[1.89,112.36]],"id":35985721}],"con":true,"img":false}]}
{"op":"mcm","clk":"5323114849","pt":1646327646705,"mc":[{"id":"1.195532875","rc":[{"atb":[[1.01,4804.04]],"id":40642034}],"con":true,"img":false}]}
{"op":"mcm","clk":"5323114861","pt":1646327646808,"mc":[{"id":"1.195532875","rc":[{"atb":[[1.53,1.99]],"id":40642034}],"con":true,"img":false}]}
{"op":"mcm","clk":"5323114881","pt":1646327647017,"mc":[{"id":"1.195532875","rc":[{"atb":[[1.01,4804.04]],"id":39614765}],"con":true,"img":false}]}
{"op":"mcm","clk":"5323114892","pt":1646327647120,"mc":[{"id":"1.195532875","rc":[{"atb":[[1.01,4806.03]],"id":39614765}],"con":true,"img":false}]}
{"op":"mcm","clk":"5323114902","pt":1646327647227,"mc":[{"id":"1.195532875","rc":[{"atb":[[1.01,4804.04]],"id":39614765}],"con":true,"img":false}]}
{"op":"mcm","clk":"5323114909","pt":1646327647320,"mc":[{"id":"1.195532875","rc":[{"atb":[[1.77,42.93]],"id":39614765}],"con":true,"img":false}]}
{"op":"mcm","clk":"5323114932","pt":1646327647527,"mc":[{"id":"1.195532875","rc":[{"atb":[[1.01,5054.04]],"id":41469398}],"con":true,"img":false}]}
{"op":"mcm","clk":"5323114942","pt":1646327647636,"mc":[{"id":"1.195532875","rc":[{"atb":[[1.01,5056.03]],"id":41469398},{"atb":[[1.77,1.99]],"id":39614765},{"atb":[[1.51,0]],"id":40642034}],"con":true,"img":false}]}
{"op":"mcm","clk":"5323114967","pt":1646327647808,"mc":[{"id":"1.195532875","rc":[{"atb":[[1.01,5054.04]],"id":41469398}],"con":true,"img":false}]}
{"op":"mcm","clk":"5323114978","pt":1646327647901,"mc":[{"id":"1.195532875","rc":[{"atb":[[2.4,1.99]],"id":41469398}],"con":true,"img":false}]}
{"op":"mcm","clk":"5323115048","pt":1646327648646,"mc":[{"id":"1.195532875","rc":[{"atb":[[2.38,2.16]],"id":41469398}],"con":true,"img":false}]}
{"op":"mcm","clk":"5323115066","pt":1646327648789,"mc":[{"id":"1.195532875","rc":[{"atb":[[2.42,1.65]],"id":41469398}],"con":true,"img":false}]}
{"op":"mcm","clk":"5323115072","pt":1646327648901,"mc":[{"id":"1.195532875","rc":[{"atb":[[2.42,3.65],[2.38,0]],"id":41469398}],"con":true,"img":false}]}
{"op":"mcm","clk":"5323115269","pt":1646327650924,"mc":[{"id":"1.195532875","rc":[{"atb":[[1.55,72.73],[1.17,0]],"id":40883678},{"atl":[[4,0],[4.1,12.9]],"id":40883678}],"con":true,"img":false}]}
{"op":"mcm","clk":"5323115318","pt":1646327651400,"mc":[{"id":"1.195532875","rc":[{"atb":[[2.38,28.99],[2.34,3.68]],"id":41469398}],"con":true,"img":false}]}
{"op":"mcm","clk":"5323115326","pt":1646327651498,"mc":[{"id":"1.195532875","rc":[{"atb":[[1.78,51.28]],"id":39614765}],"con":true,"img":false}]}
{"op":"mcm","clk":"5323115348","pt":1646327652288,"mc":[{"id":"1.195532875","rc":[{"atb":[[2.34,0]],"id":41469398}],"con":true,"img":false}]}
{"op":"mcm","clk":"5323115375","pt":1646327652434,"mc":[{"id":"1.195532875","rc":[{"atb":[[1.5,0],[1.51,78.43]],"id":40642034},{"atl":[[8,35.71]],"id":40642034}],"con":true,"img":false}]}
{"op":"mcm","clk":"5323115404","pt":1646327652471,"mc":[{"id":"1.195532875","rc":[{"atb":[[1.99,0],[1.97,41.24]],"id":35985721},{"atb":[[1.75,48.78]],"id":39614765},{"atb":[[1.48,76.22]],"id":40642034}],"con":true,"img":false}]}
{"op":"mcm","clk":"5323115420","pt":1646327652653,"mc":[{"id":"1.195532875","rc":[{"atb":[[1.89,0],[1.97,144.33]],"id":35985721}],"con":true,"img":false}]}
{"op":"mcm","clk":"5323115488","pt":1646327653215,"mc":[{"id":"1.195532875","rc":[{"atb":[[1.01,4804.04]],"id":37306244}],"con":true,"img":false}]}
{"op":"mcm","clk":"5323115535","pt":1646327653423,"mc":[{"id":"1.195532875","rc":[{"atb":[[1.01,4806.03]],"id":37306244}],"con":true,"img":false}]}
{"op":"mcm","clk":"5323115550","pt":1646327653640,"mc":[{"id":"1.195532875","rc":[{"atb":[[1.01,4804.04]],"id":37306244},{"atb":[[2.36,0],[2.44,2.15]],"id":41469398}],"con":true,"img":false}]}
{"op":"mcm","clk":"5323115561","pt":1646327653740,"mc":[{"id":"1.195532875","rc":[{"atb":[[1.84,1.99]],"id":37306244}],"con":true,"img":false}]}
{"op":"mcm","clk":"5323115580","pt":1646327653957,"mc":[{"id":"1.195532875","rc":[{"atb":[[1.01,4804.04]],"id":35985721}],"con":true,"img":false}]}
{"op":"mcm","clk":"5323115639","pt":1646327654147,"mc":[{"id":"1.195532875","rc":[{"atb":[[1.01,4806.03]],"id":35985721}],"con":true,"img":false}]}
{"op":"mcm","clk":"5323115670","pt":1646327654355,"mc":[{"id":"1.195532875","rc":[{"atb":[[1.82,48.78],[1.81,0]],"id":37306244},{"atb":[[2.4,30.56],[2.38,0]],"id":41469398},{"atb":[[1.01,4804.04],[1.97,103.09],[1.95,42.11]],"id":35985721}],"con":true,"img":false}]}
{"op":"mcm","clk":"5323115679","pt":1646327654408,"mc":[{"id":"1.195532875","rc":[{"atb":[[1.89,1.99]],"id":35985721}],"con":true,"img":false}]}
{"op":"mcm","clk":"5323115688","pt":1646327654512,"mc":[{"id":"1.195532875","rc":[{"atb":[[1.18,0]],"id":40883678}],"con":true,"img":false}]}
{"op":"mcm","clk":"5323115986","pt":1646327656651,"mc":[{"id":"1.195532875","rc":[{"atb":[[2.42,2]],"id":41469398}],"con":true,"img":false}]}
{"op":"mcm","clk":"5323115993","pt":1646327656756,"mc":[{"id":"1.195532875","rc":[{"atb":[[1.75,0]],"id":39614765}],"con":true,"img":false}]}
{"op":"mcm","clk":"5323116000","pt":1646327656810,"mc":[{"id":"1.195532875","rc":[{"atb":[[2.46,1.65]],"id":41469398}],"con":true,"img":false}]}
{"op":"mcm","clk":"5323116069","pt":1646327657747,"mc":[{"id":"1.195532875","rc":[{"atb":[[1.9,111.11]],"id":35985721}],"con":true,"img":false}]}
{"op":"mcm","clk":"5323116077","pt":1646327657846,"mc":[{"id":"1.195532875","rc":[{"atb":[[1.97,0]],"id":35985721}],"con":true,"img":false}]}
{"op":"mcm","clk":"5323116122","pt":1646327658332,"mc":[{"id":"1.195532875","rc":[{"atb":[[2.42,0],[2.46,3.65]],"id":41469398}],"con":true,"img":false}]}
{"op":"mcm","clk":"5323116197","pt":1646327659250,"mc":[{"id":"1.195532875","rc":[{"atb":[[1.14,242.82]],"id":40883678}],"con":true,"img":false}]}
{"op":"mcm","clk":"5323116251","pt":1646327659669,"mc":[{"id":"1.195532875","rc":[{"atb":[[2.4,1.99],[2.42,28.17]],"id":41469398},{"atb":[[1.93,43.01]],"id":35985721}],"con":true,"img":false}]}
{"op":"mcm","clk":"5323116260","pt":1646327659722,"mc":[{"id":"1.195532875","rc":[{"atb":[[1.95,0]],"id":35985721}],"con":true,"img":false}]}
{"op":"mcm","clk":"5323116308","pt":1646327660353,"mc":[{"id":"1.195532875","rc":[{"atb":[[1.19,0]],"id":40883678}],"con":true,"img":false}]}
{"op":"mcm","clk":"5323116320","pt":1646327660469,"mc":[{"id":"1.195532875","rc":[{"atb":[[1.58,1.99]],"id":40883678}],"con":true,"img":false}]}
{"op":"mcm","clk":"5323116339","pt":1646327660662,"mc":[{"id":"1.195532875","rc":[{"atb":[[1.77,0]],"id":39614765}],"con":true,"img":false}]}
{"op":"mcm","clk":"5323116348","pt":1646327660764,"mc":[{"id":"1.195532875","rc":[{"atb":[[1.81,1.99]],"id":39614765}],"con":true,"img":false}]}
{"op":"mcm","clk":"5323116368","pt":1646327660926,"mc":[{"id":"1.195532875","rc":[{"atb":[[1.56,71.43],[1.55,0]],"id":40883678},{"atl":[[4.3,30.3]],"id":40883678}],"con":true,"img":false}]}
{"op":"mcm","clk":"5323116431","pt":1646327661552,"mc":[{"id":"1.195532875","rc":[{"atb":[[1.79,50.63],[1.78,0]],"id":39614765}],"con":true,"img":false}]}
{"op":"mcm","clk":"5323116453","pt":1646327661759,"mc":[{"id":"1.195532875","rc":[{"atb":[[1.75,48.78]],"id":39614765}],"con":true,"img":false}]}
{"op":"mcm","clk":"5323116492","pt":1646327662184,"mc":[{"id":"1.195532875","rc":[{"atb":[[1.49,204.08]],"id":40642034}],"con":true,"img":false}]}
{"op":"mcm","clk":"5323116691","pt":1646327664374,"mc":[{"id":"1.195532875","rc":[{"atb":[[1.88,0],[1.96,2.15]],"id":35985721}],"con":true,"img":false}]}
{"op":"mcm","clk":"5323116876","pt":1646327665950,"mc":[{"id":"1.195532875","rc":[{"atb":[[2.4,0]],"id":41469398}],"con":true,"img":false}]}
{"op":"mcm","clk":"5323116882","pt":1646327666056,"mc":[{"id":"1.195532875","rc":[{"atb":[[2.48,1.99]],"id":41469398}],"con":true,"img":false}]}
{"op":"mcm","clk":"5323116892","pt":1646327666149,"mc":[{"id":"1.195532875","rc":[{"atb":[[1.48,0]],"id":40642034}],"con":true,"img":false}]}
{"op":"mcm","clk":"5323116901","pt":1646327666252,"mc":[{"id":"1.195532875","rc":[{"atb":[[1.89,0]],"id":35985721}],"con":true,"img":false}]}
{"op":"mcm","clk":"5323116910","pt":1646327666359,"mc":[{"id":"1.195532875","rc":[{"atb":[[1.94,1.99]],"id":35985721}],"con":true,"img":false}]}
{"op":"mcm","clk":"5323116960","pt":1646327666875,"mc":[{"id":"1.195532875","rc":[{"atb":[[1.94,0]],"id":35985721}],"con":true,"img":false}]}
{"op":"mcm","clk":"5323116971","pt":1646327666934,"mc":[{"id":"1.195532875","rc":[{"atb":[[1.97,1.99]],"id":35985721}],"con":true,"img":false}]}
{"op":"mcm","clk":"5323116981","pt":1646327667036,"mc":[{"id":"1.195532875","rc":[{"atb":[[1.97,4.15],[1.9,0]],"id":35985721}],"con":true,"img":false}]}
{"op":"mcm","clk":"5323117200","pt":1646327669068,"mc":[{"id":"1.195532875","rc":[{"atl":[[16.5,2.35],[17,0]],"id":35985721},{"atl":[[3.95,0],[3.9,30.3]],"id":40883678}],"con":true,"img":false}]}
{"op":"mcm","clk":"5323117233","pt":1646327669275,"mc":[{"id":"1.195532875","rc":[{"atb":[[2.42,0],[2.44,29.93]],"id":41469398},{"atb":[[1.93,0],[1.95,42.11]],"id":35985721},{"atl":[[17.5,2.42],[18,0]],"id":35985721},{"atl":[[13,6.9],[13.5,0]],"id":39614765},{"atb":[[1.46,0],[1.44,0]],"id":40642034},{"atl":[[4,13.33]],"id":40883678}],"con":true,"img":false}]}
{"op":"mcm","clk":"5323117244","pt":1646327669378,"mc":[{"id":"1.195532875","rc":[{"atl":[[18.5,3.68]],"id":35985721}],"con":true,"img":false}]}
{"op":"mcm","clk":"5323117260","pt":1646327669483,"mc":[{"id":"1.195532875","rc":[{"atl":[[18.5,0]],"id":35985721},{"atl":[[16,3.45]],"id":39614765}],"con":true,"img":false}]}
{"op":"mcm","clk":"5323117275","pt":1646327669543,"mc":[{"id":"1.195532875","rc":[{"atl":[[16,0]],"id":39614765}],"con":true,"img":false}]}
{"op":"mcm","clk":"5323117444","pt":1646327671045,"mc":[{"id":"1.195532875","rc":[{"atb":[[1.53,64.47]],"id":40642034}],"con":true,"img":false}]}
{"op":"mcm","clk":"5323117456","pt":1646327671150,"mc":[{"id":"1.195532875","rc":[{"atb":[[1.54,78.43],[1.52,2.15]],"id":40642034}],"con":true,"img":false}]}
{"op":"mcm","clk":"5323117475","pt":1646327671354,"mc":[{"id":"1.195532875","rc":[{"atl":[[14,3.08],[14.5,0]],"id":39614765},{"atb":[[1.52,79.07]],"id":40642034}],"con":true,"img":false}]}
{"op":"mcm","clk":"5323117523","pt":1646327671769,"mc":[{"id":"1.195532875","rc":[{"atb":[[1.53,62.48]],"id":40642034}],"con":true,"img":false}]}
{"op":"mcm","clk":"5323117536","pt":1646327671871,"mc":[{"id":"1.195532875","rc":[{"atb":[[1.55,1.99]],"id":40642034}],"con":true,"img":false}]}
{"op":"mcm","clk":"5323117621","pt":1646327672663,"mc":[{"id":"1.195532875","rc":[{"atb":[[2.46,2]],"id":41469398}],"con":true,"img":false}]}
{"op":"mcm","clk":"5323117644","pt":1646327672866,"mc":[{"id":"1.195532875","rc":[{"atb":[[2.5,1.65]],"id":41469398}],"con":true,"img":false}]}
{"op":"mcm","clk":"5323117653","pt":1646327672971,"mc":[{"id":"1.195532875","rc":[{"atb":[[1.53,137.95],[1.52,2.15]],"id":40642034}],"con":true,"img":false}]}
{"op":"mcm","clk":"5323117665","pt":1646327673067,"mc":[{"id":"1.195532875","rc":[{"atb":[[2.5,3.65],[2.46,0]],"id":41469398}],"con":true,"img":false}]}
{"op":"mcm","clk":"5323117677","pt":1646327673173,"mc":[{"id":"1.195532875","rc":[{"atb":[[1.75,0]],"id":39614765},{"atb":[[1.14,0]],"id":40883678}],"con":true,"img":false}]}
{"op":"mcm","clk":"5323117740","pt":1646327673751,"mc":[{"id":"1.195532875","rc":[{"atb":[[2.48,0]],"id":41469398}],"con":true,"img":false}]}
{"op":"mcm","clk":"5323117753","pt":1646327673868,"mc":[{"id":"1.195532875","rc":[{"atb":[[2.52,1.99]],"id":41469398}],"con":true,"img":false}]}
{"op":"mcm","clk":"5323117765","pt":1646327673960,"mc":[{"id":"1.195532875","rc":[{"atb":[[2.46,27.4],[2.44,2.15]],"id":41469398}],"con":true,"img":false}]}
{"op":"mcm","clk":"5323117777","pt":1646327674063,"mc":[{"id":"1.195532875","rc":[{"atb":[[2.48,27.03]],"id":41469398}],"con":true,"img":false}]}
{"op":"mcm","clk":"5323117833","pt":1646327674583,"mc":[{"id":"1.195532875","rc":[{"atb":[[1.01,4804.04],[2.3,0],[2.46,0],[2.26,0]],"id":41469398},{"atl":[[40,0],[44,3.33]],"id":41469398}],"con":true,"img":false}]}
{"op":"mcm","clk":"5323117860","pt":1646327674847,"mc":[{"id":"1.195532875","rc":[{"atb":[[1.52,0]],"id":40642034}],"con":true,"img":false}]}
{"op":"mcm","clk":"5323117871","pt":1646327674953,"mc":[{"id":"1.195532875","rc":[{"atb":[[1.57,2.15]],"id":40642034}],"con":true,"img":false}]}
{"op":"mcm","clk":"5323117880","pt":1646327675054,"mc":[{"id":"1.195532875","rc":[{"atb":[[1.57,4.31],[1.54,0]],"id":40642034}],"con":true,"img":false}]}
{"op":"mcm","clk":"5323117901","pt":1646327675261,"mc":[{"id":"1.195532875","rc":[{"atl":[[44,2.33],[48,1]],"id":41469398},{"atb":[[1.55,74.72],[1.53,62.48]],"id":40642034}],"con":true,"img":false}]}
{"op":"mcm","clk":"5323117926","pt":1646327675466,"mc":[{"id":"1.195532875","rc":[{"atb":[[1.53,0]],"id":40642034}],"con":true,"img":false}]}
{"op":"mcm","clk":"5323117969","pt":1646327675882,"mc":[{"id":"1.195532875","rc":[{"atb":[[1.55,72.73]],"id":40642034}],"con":true,"img":false}]}
{"op":"mcm","clk":"5323117979","pt":1646327675985,"mc":[{"id":"1.195532875","rc":[{"atb":[[1.58,1.99]],"id":40642034}],"con":true,"img":false}]}
{"op":"mcm","clk":"5323118082","pt":1646327677185,"mc":[{"id":"1.195532875","rc":[{"atb":[[1.56,71.43],[1.55,0]],"id":40642034}],"con":true,"img":false}]}
{"op":"mcm","clk":"5323118193","pt":1646327678273,"mc":[{"id":"1.195532875","rc":[{"atl":[[2.98,3.79]],"id":40883678}],"con":true,"img":false}]}
{"op":"mcm","clk":"5323118201","pt":1646327678374,"mc":[{"id":"1.195532875","rc":[{"atb":[[1.75,48.78]],"id":39614765},{"atb":[[1.14,252.99]],"id":40883678}],"con":true,"img":false}]}
{"op":"mcm","clk":"5323118210","pt":1646327678465,"mc":[{"id":"1.195532875","rc":[{"atl":[[2.98,0],[4.2,16.13]],"id":40883678}],"con":true,"img":false}]}
{"op":"mcm","clk":"5323118230","pt":1646327678675,"mc":[{"id":"1.195532875","rc":[{"atl":[[4.2,0]],"id":40883678}],"con":true,"img":false}]}
{"op":"mcm","clk":"5323118281","pt":1646327679252,"mc":[{"id":"1.195532875","rc":[{"atb":[[1.93,107.53]],"id":35985721},{"atb":[[1.54,185.19]],"id":40883678},{"atl":[[4.2,31.25]],"id":40883678}],"con":true,"img":false}]}
{"op":"mcm","clk":"5323118409","pt":1646327680562,"mc":[{"id":"1.195532875","rc":[{"atb":[[1.99,19.84]],"id":37306244},{"atl":[[9,0],[9.2,3.13],[8.8,4.76]],"id":37306244},{"atl":[[44,0],[46,4.96]],"id":41469398},{"atb":[[1.82,0],[1.8,0],[1.84,0]],"id":35985721},{"atl":[[13,0],[13.5,8]],"id":39614765},{"atb":[[1.12,38.46],[1.01,4804.04],[1.13,0]],"id":40883678}],"con":true,"img":false}]}
{"op":"mcm","clk":"5323118416","pt":1646327680673,"mc":[{"id":"1.195532875","rc":[{"atb":[[2,19.84],[1.83,2.15]],"id":37306244},{"atb":[[2.5,2]],"id":41469398}],"con":true,"img":false}]}
{"op":"mcm","clk":"5323118429","pt":1646327680786,"mc":[{"id":"1.195532875","rc":[{"atl":[[9.2,0]],"id":37306244}],"con":true,"img":false}]}
{"op":"mcm","clk":"5323118437","pt":1646327680875,"mc":[{"id":"1.195532875","rc":[{"atb":[[2.54,1.65]],"id":41469398},{"atb":[[1.52,8.19]],"id":40642034}],"con":true,"img":false}]}
{"op":"mcm","clk":"5323118453","pt":1646327681088,"mc":[{"id":"1.195532875","rc":[{"atb":[[1.99,0]],"id":37306244},{"atb":[[1.12,0]],"id":40883678}],"con":true,"img":false}]}
{"op":"mcm","clk":"5323118469","pt":1646327681294,"mc":[{"id":"1.195532875","rc":[{"atb":[[1.84,0]],"id":37306244}],"con":true,"img":false}]}
{"op":"mcm","clk":"5323118478","pt":1646327681356,"mc":[{"id":"1.195532875","rc":[{"atb":[[2.02,1.99]],"id":37306244},{"atb":[[1.77,129.87]],"id":39614765},{"atl":[[14,0],[14.5,2.96]],"id":39614765}],"con":true,"img":false}]}
{"op":"mcm","clk":"5323118511","pt":1646327681773,"mc":[{"id":"1.195532875","rc":[{"atb":[[1.82,0],[1.99,40.4]],"id":37306244},{"atl":[[9.2,4.88],[9.4,0]],"id":37306244},{"atb":[[2.5,28.67]],"id":41469398},{"atl":[[48,0],[50,1]],"id":41469398},{"atb":[[1.73,6.76],[1.72,0],[1.74,0],[1.7,0]],"id":39614765}],"con":true,"img":false}]}
{"op":"mcm","clk":"5323118521","pt":1646327681880,"mc":[{"id":"1.195532875","rc":[{"atb":[[2.04,11.9]],"id":37306244}],"con":true,"img":false}]}
{"op":"mcm","clk":"5323118529","pt":1646327681982,"mc":[{"id":"1.195532875","rc":[{"atb":[[1.73,0]],"id":39614765}],"con":true,"img":false}]}
{"op":"mcm","clk":"5323118558","pt":1646327682300,"mc":[{"id":"1.195532875","rc":[{"atb":[[2.54,3.65],[2.5,26.67]],"id":41469398}],"con":true,"img":false}]}
{"op":"mcm","clk":"5323118598","pt":1646327682672,"mc":[{"id":"1.195532875","rc":[{"atb":[[2.52,0]],"id":41469398}],"con":true,"img":false}]}
{"op":"mcm","clk":"5323118605","pt":1646327682783,"mc":[{"id":"1.195532875","rc":[{"atb":[[2.04,0]],"id":37306244},{"atb":[[2.56,1.99]],"id":41469398}],"con":true,"img":false}]}
{"op":"mcm","clk":"5323118624","pt":1646327682992,"mc":[{"id":"1.195532875","rc":[{"atb":[[2.02,0]],"id":37306244}],"con":true,"img":false}]}
{"op":"mcm","clk":"5323118634","pt":1646327683093,"mc":[{"id":"1.195532875","rc":[{"atb":[[2.06,1.99]],"id":37306244}],"con":true,"img":false}]}
{"op":"mcm","clk":"5323118644","pt":1646327683196,"mc":[{"id":"1.195532875","rc":[{"atb":[[1.14,0]],"id":40883678}],"con":true,"img":false}]}
{"op":"mcm","clk":"5323118683","pt":1646327683573,"mc":[{"id":"1.195532875","rc":[{"atb":[[1.99,0],[2.02,39.22]],"id":37306244},{"atb":[[2.52,26.32]],"id":41469398}],"con":true,"img":false}]}
{"op":"mcm","clk":"5323118866","pt":1646327685644,"mc":[{"id":"1.195532875","rc":[{"atb":[[2.44,0],[2.58,2.15]],"id":41469398},{"atb":[[1.75,0]],"id":39614765}],"con":true,"img":false}]}
{"op":"mcm","clk":"5323118987","pt":1646327687063,"mc":[{"id":"1.195532875","rc":[{"atb":[[2.54,29.62]],"id":41469398}],"con":true,"img":false}]}
{"op":"mcm","clk":"5323118995","pt":1646327687163,"mc":[{"id":"1.195532875","rc":[{"atb":[[1.54,185.19],[1.48,25.3]],"id":40642034}],"con":true,"img":false}]}
{"op":"mcm","clk":"5323119019","pt":1646327687478,"mc":[{"id":"1.195532875","rc":[{"atb":[[1.48,0]],"id":40642034}],"con":true,"img":false}]}
{"op":"mcm","clk":"5323119080","pt":1646327688202,"mc":[{"id":"1.195532875","rc":[{"atb":[[1.58,36.71]],"id":40883678}],"con":true,"img":false}]}
{"op":"mcm","clk":"5323119099","pt":1646327688411,"mc":[{"id":"1.195532875","rc":[{"atb":[[1.59,47.62],[1.57,2.15]],"id":40883678}],"con":true,"img":false}]}
{"op":"mcm","clk":"5323119109","pt":1646327688466,"mc":[{"id":"1.195532875","rc":[{"atb":[[1.49,0],[1.51,0],[1.47,0]],"id":40642034}],"con":true,"img":false}]}
{"op":"mcm","clk":"5323119130","pt":1646327688682,"mc":[{"id":"1.195532875","rc":[{"atb":[[2.54,27.97]],"id":41469398}],"con":true,"img":false}]}
{"op":"mcm","clk":"5323119148","pt":1646327688886,"mc":[{"id":"1.195532875","rc":[{"atb":[[2.08,1.65]],"id":37306244},{"atb":[[2.6,1.65]],"id":41469398}],"con":true,"img":false}]}
{"op":"mcm","clk":"5323119202","pt":1646327689266,"mc":[{"id":"1.195532875","rc":[{"atb":[[1.91,164.84]],"id":35985721},{"atb":[[1.57,72.33]],"id":40883678},{"atl":[[4.4,44.12]],"id":40883678}],"con":true,"img":false}]}
{"op":"mcm","clk":"5323119226","pt":1646327689470,"mc":[{"id":"1.195532875","rc":[{"atb":[[2.02,0],[2.04,38.46]],"id":37306244},{"atb":[[2.56,27.63],[2.54,2]],"id":41469398}],"con":true,"img":false}]}
{"op":"mcm","clk":"5323119234","pt":1646327689574,"mc":[{"id":"1.195532875","rc":[{"atb":[[1.58,34.72]],"id":40883678}],"con":true,"img":false}]}
{"op":"mcm","clk":"5323119244","pt":1646327689677,"mc":[{"id":"1.195532875","rc":[{"atb":[[1.6,1.99]],"id":40883678}],"con":true,"img":false}]}
{"op":"mcm","clk":"5323119260","pt":1646327689884,"mc":[{"id":"1.195532875","rc":[{"atb":[[2.08,3.65]],"id":37306244}],"con":true,"img":false}]}
{"op":"mcm","clk":"5323119267","pt":1646327689988,"mc":[{"id":"1.195532875","rc":[{"atb":[[2,0]],"id":37306244},{"atb":[[2.56,25.64]],"id":41469398}],"con":true,"img":false}]}
{"op":"mcm","clk":"5323119279","pt":1646327690092,"mc":[{"id":"1.195532875","rc":[{"atb":[[2.6,3.64]],"id":41469398}],"con":true,"img":false}]}
{"op":"mcm","clk":"5323119293","pt":1646327690301,"mc":[{"id":"1.195532875","rc":[{"atb":[[2.06,0]],"id":37306244}],"con":true,"img":false}]}
{"op":"mcm","clk":"5323119301","pt":1646327690403,"mc":[{"id":"1.195532875","rc":[{"atb":[[2.04,40.45]],"id":37306244}],"con":true,"img":false}]}
{"op":"mcm","clk":"5323119323","pt":1646327690670,"mc":[{"id":"1.195532875","rc":[{"atb":[[1.52,0]],"id":40642034}],"con":true,"img":false}]}
{"op":"mcm","clk":"5323119332","pt":1646327690777,"mc":[{"id":"1.195532875","rc":[{"atb":[[1.81,33.55]],"id":39614765}],"con":true,"img":false}]}
{"op":"mcm","clk":"5323119340","pt":1646327690876,"mc":[{"id":"1.195532875","rc":[{"atb":[[1.8,2.15],[1.82,43.11]],"id":39614765}],"con":true,"img":false}]}
{"op":"mcm","clk":"5323119380","pt":1646327691293,"mc":[{"id":"1.195532875","rc":[{"atb":[[1.8,52.15]],"id":39614765},{"atb":[[1.58,103.69],[1.57,2.15]],"id":40883678},{"atl":[[4.3,0],[4.1,0]],"id":40883678}],"con":true,"img":false}]}
{"op":"mcm","clk":"5323119392","pt":1646327691397,"mc":[{"id":"1.195532875","rc":[{"atb":[[2.54,0],[2.62,3.65]],"id":41469398}],"con":true,"img":false}]}
{"op":"mcm","clk":"5323119412","pt":1646327691605,"mc":[{"id":"1.195532875","rc":[{"atb":[[2.56,0],[2.58,27.47]],"id":41469398}],"con":true,"img":false}]}
{"op":"mcm","clk":"5323119445","pt":1646327691878,"mc":[{"id":"1.195532875","rc":[{"atl":[[9,11.11],[8.8,0]],"id":37306244},{"atl":[[38,2],[46,2.74]],"id":41469398},{"atb":[[2.04,8.21]],"id":35985721}],"con":true,"img":false}]}
{"op":"mcm","clk":"5323119462","pt":1646327692086,"mc":[{"id":"1.195532875","rc":[{"atb":[[2.06,4.15],[1.97,1.99]],"id":35985721}],"con":true,"img":false}]}
{"op":"mcm","clk":"5323119474","pt":1646327692186,"mc":[{"id":"1.195532875","rc":[{"atb":[[2.04,0]],"id":35985721}],"con":true,"img":false}]}
{"op":"mcm","clk":"5323119520","pt":1646327692600,"mc":[{"id":"1.195532875","rc":[{"atl":[[9.2,0],[9.4,4.76]],"id":37306244},{"atl":[[42,1]],"id":41469398},{"atb":[[2.02,39.22]],"id":35985721}],"con":true,"img":false}]}
{"op":"mcm","clk":"5323119558","pt":1646327692978,"mc":[{"id":"1.195532875","rc":[{"atb":[[1.58,68.97]],"id":40883678}],"con":true,"img":false}]}
{"op":"mcm","clk":"5323119569","pt":1646327693180,"mc":[{"id":"1.195532875","rc":[{"atb":[[2.66,7.99]],"id":41469398}],"con":true,"img":false}]}
{"op":"mcm","clk":"5323119607","pt":1646327693595,"mc":[{"id":"1.195532875","rc":[{"atb":[[2.66,0]],"id":41469398}],"con":true,"img":false}]}
{"op":"mcm","clk":"5323119819","pt":1646327695693,"mc":[{"id":"1.195532875","rc":[{"atb":[[1.81,1.99]],"id":39614765},{"atb":[[1.58,6.4]],"id":40642034}],"con":true,"img":false}]}
{"op":"mcm","clk":"5323119833","pt":1646327695791,"mc":[{"id":"1.195532875","rc":[{"atb":[[1.59,6.4],[1.57,2.15]],"id":40642034}],"con":true,"img":false}]}
{"op":"mcm","clk":"5323119856","pt":1646327696102,"mc":[{"id":"1.195532875","rc":[{"atb":[[1.82,0],[1.81,88.21]],"id":39614765}],"con":true,"img":false}]}
{"op":"mcm","clk":"5323119881","pt":1646327696307,"mc":[{"id":"1.195532875","rc":[{"atb":[[1.96,0],[2.08,2.15]],"id":35985721},{"atb":[[1.8,50],[1.81,109.24],[1.85,2.15]],"id":39614765},{"atb":[[1.57,0],[1.61,2.15]],"id":40642034},{"atb":[[1.57,0],[1.62,2.15]],"id":40883678}],"con":true,"img":false}]}
{"op":"mcm","clk":"5323119898","pt":1646327696480,"mc":[{"id":"1.195532875","rc":[{"atb":[[1.59,0],[1.6,49.61]],"id":40883678}],"con":true,"img":false}]}
{"op":"mcm","clk":"5323119912","pt":1646327696682,"mc":[{"id":"1.195532875","rc":[{"atb":[[2.6,1.99]],"id":41469398}],"con":true,"img":false}]}
{"op":"mcm","clk":"5323119918","pt":1646327696784,"mc":[{"id":"1.195532875","rc":[{"atb":[[2.6,28.31],[2.62,0]],"id":41469398}],"con":true,"img":false}]}
{"op":"mcm","clk":"5323119929","pt":1646327696887,"mc":[{"id":"1.195532875","rc":[{"atb":[[2.64,1.65]],"id":41469398},{"atb":[[2.1,1.65]],"id":35985721}],"con":true,"img":false}]}
{"op":"mcm","clk":"5323119940","pt":1646327696996,"mc":[{"id":"1.195532875","rc":[{"atb":[[1.81,88.21]],"id":39614765}],"con":true,"img":false}]}
{"op":"mcm","clk":"5323119959","pt":1646327697205,"mc":[{"id":"1.195532875","rc":[{"atb":[[1.59,74.2]],"id":40642034}],"con":true,"img":false}]}
{"op":"mcm","clk":"5323120019","pt":1646327697889,"mc":[{"id":"1.195532875","rc":[{"atb":[[1.6,47.62]],"id":40883678}],"con":true,"img":false}]}
{"op":"mcm","clk":"5323120028","pt":1646327697989,"mc":[{"id":"1.195532875","rc":[{"atb":[[1.63,1.99]],"id":40883678}],"con":true,"img":false}]}
{"op":"mcm","clk":"5323120037","pt":1646327698091,"mc":[{"id":"1.195532875","rc":[{"atb":[[1.58,4.41]],"id":40642034}],"con":true,"img":false}]}
{"op":"mcm","clk":"5323120048","pt":1646327698197,"mc":[{"id":"1.195532875","rc":[{"atb":[[1.62,1.99]],"id":40642034}],"con":true,"img":false}]}
{"op":"mcm","clk":"5323120057","pt":1646327698307,"mc":[{"id":"1.195532875","rc":[{"atb":[[1.81,86.22]],"id":39614765}],"con":true,"img":false}]}
{"op":"mcm","clk":"5323120067","pt":1646327698412,"mc":[{"id":"1.195532875","rc":[{"atb":[[1.86,1.99]],"id":39614765}],"con":true,"img":false}]}
{"op":"mcm","clk":"5323120076","pt":1646327698515,"mc":[{"id":"1.195532875","rc":[{"atb":[[1.6,66.67]],"id":40642034}],"con":true,"img":false}]}
{"op":"mcm","clk":"5323120086","pt":1646327698621,"mc":[{"id":"1.195532875","rc":[{"atb":[[2.6,53.31],[2.58,2.15]],"id":41469398},{"atl":[[38,0],[40,2.56]],"id":41469398},{"atb":[[2.02,0],[2.06,41.89]],"id":35985721},{"atb":[[1.83,48.19],[1.84,47.62]],"id":39614765},{"atb":[[1.58,0],[1.61,65.57]],"id":40883678}],"con":true,"img":false}]}
{"op":"mcm","clk":"5323120102","pt":1646327698791,"mc":[{"id":"1.195532875","rc":[{"atb":[[1.83,78.36]],"id":39614765},{"atb":[[1.6,82.34]],"id":40883678}],"con":true,"img":false}]}
{"op":"mcm","clk":"5323120268","pt":1646327700420,"mc":[{"id":"1.195532875","rc":[{"atb":[[2.64,3.81],[2.6,26.99]],"id":41469398}],"con":true,"img":false}]}
{"op":"mcm","clk":"5323120281","pt":1646327700515,"mc":[{"id":"1.195532875","rc":[{"atb":[[2.64,1.65],[2.6,53.31]],"id":41469398}],"con":true,"img":false}]}
{"op":"mcm","clk":"5323120305","pt":1646327700677,"mc":[{"id":"1.195532875","rc":[{"spn":2.08,"spf":1.0,"id":37306244},{"spn":2.64,"spf":1.0,"id":41469398},{"spn":2.07,"spf":1.0,"id":35985721},{"spn":1.84,"spf":1.0,"id":39614765},{"atb":[[1.58,0]],"id":40642034},{"spn":4.01,"spf":"NaN","id":40642034},{"spn":2.76,"spf":"NaN","id":40883678}],"con":true,"img":false}]}
{"op":"mcm","clk":"5323120353","pt":1646327701098,"mc":[{"id":"1.195532875","rc":[{"atb":[[2.06,37.74],[2.1,3.81]],"id":35985721}],"con":true,"img":false}]}
{"op":"mcm","clk":"5323120498","pt":1646327702588,"mc":[{"id":"1.195532875","rc":[{"atb":[[2,100]],"id":37306244}],"con":true,"img":false}]}
{"op":"mcm","clk":"5323120673","pt":1646327704312,"mc":[{"id":"1.195532875","rc":[{"atb":[[1.79,0],[1.77,0],[1.75,0]],"id":37306244},{"atl":[[38,2.56],[40,0],[42,0],[44,1]],"id":41469398},{"atb":[[1.83,30.17],[1.79,0],[1.77,0]],"id":39614765}],"con":true,"img":false}]}
{"op":"mcm","clk":"5323120715","pt":1646327704590,"mc":[{"id":"1.195532875","rc":[{"atb":[[2.64,0]],"id":41469398}],"con":true,"img":false}]}
{"op":"mcm","clk":"5323120737","pt":1646327704794,"mc":[{"id":"1.195532875","rc":[{"atb":[[2.62,1.65]],"id":41469398},{"atb":[[1.59,67.8],[1.62,4.15]],"id":40642034}],"con":true,"img":false}]}
{"op":"mcm","clk":"5323120752","pt":1646327704893,"mc":[{"id":"1.195532875","rc":[{"atb":[[2.56,25.64],[2.6,28.31]],"id":41469398},{"atl":[[42,1],[44,0]],"id":41469398}],"con":true,"img":false}]}
{"op":"mcm","clk":"5323120761","pt":1646327704997,"mc":[{"id":"1.195532875","rc":[{"atb":[[2.58,27.47]],"id":41469398}],"con":true,"img":false}]}
{"op":"mcm","clk":"5323120770","pt":1646327705103,"mc":[{"id":"1.195532875","rc":[{"atb":[[1.83,0],[1.81,0],[1.86,4.15]],"id":39614765},{"atb":[[1.6,47.62]],"id":40883678}],"con":true,"img":false}]}
{"op":"mcm","clk":"5323120917","pt":1646327706609,"mc":[{"id":"1.195532875","rc":[{"atb":[[2.56,0],[2.52,0],[2.48,0]],"id":41469398}],"con":true,"img":false}]}
{"op":"mcm","clk":"5323121032","pt":1646327707842,"mc":[{"id":"1.195532875","rc":[{"atb":[[1.63,2.9]],"id":40642034}],"con":true,"img":false}]}
{"op":"mcm","clk":"5323121083","pt":1646327708291,"mc":[{"id":"1.195532875","rc":[{"atb":[[1.6,0],[1.61,67.72]],"id":40642034}],"con":true,"img":false}]}
{"op":"mcm","clk":"5323121091","pt":1646327708388,"mc":[{"id":"1.195532875","rc":[{"atl":[[16.5,0],[15.5,2.42]],"id":35985721},{"atl":[[3.95,33.9],[3.9,0]],"id":40883678}],"con":true,"img":false}]}
{"op":"mcm","clk":"5323121099","pt":1646327708502,"mc":[{"id":"1.195532875","rc":[{"atb":[[2.48,7.8]],"id":35985721},{"atl":[[17.5,0]],"id":35985721},{"atb":[[1.59,169.49]],"id":40883678},{"atl":[[4,0],[4.1,12.9]],"id":40883678}],"con":true,"img":false}]}
{"op":"mcm","clk":"5323121106","pt":1646327708593,"mc":[{"id":"1.195532875","rc":[{"atb":[[2.04,38.46]],"id":37306244},{"atb":[[2.02,98.04]],"id":35985721},{"atl":[[16.5,2.58]],"id":35985721},{"atb":[[1.82,121.95]],"id":39614765}],"con":true,"img":false}]}
{"op":"mcm","clk":"5323121112","pt":1646327708703,"mc":[{"id":"1.195532875","rc":[{"atb":[[2.1,1.99]],"id":37306244}],"con":true,"img":false}]}
{"op":"mcm","clk":"5323121130","pt":1646327708906,"mc":[{"id":"1.195532875","rc":[{"atb":[[1.97,0]],"id":35985721}],"con":true,"img":false}]}
{"op":"mcm","clk":"5323121139","pt":1646327709011,"mc":[{"id":"1.195532875","rc":[{"atb":[[2.1,5.8],[2.16,2.15],[2.08,0]],"id":35985721}],"con":true,"img":false}]}
{"op":"mcm","clk":"5323121165","pt":1646327709321,"mc":[{"id":"1.195532875","rc":[{"atb":[[2.48,0]],"id":35985721}],"con":true,"img":false}]}
{"op":"mcm","clk":"5323121228","pt":1646327710007,"mc":[{"id":"1.195532875","rc":[{"atb":[[2.16,7.96]],"id":35985721}],"con":true,"img":false}]}
{"op":"mcm","clk":"5323121234","pt":1646327710107,"mc":[{"id":"1.195532875","rc":[{"atb":[[2.1,3.64]],"id":35985721}],"con":true,"img":false}]}
{"op":"mcm","clk":"5323121274","pt":1646327710521,"mc":[{"id":"1.195532875","rc":[{"atb":[[1.81,5.39]],"id":39614765},{"atb":[[1.63,4.89]],"id":40883678}],"con":true,"img":false}]}
{"op":"mcm","clk":"5323121465","pt":1646327712557,"mc":[{"id":"1.195532875","rc":[{"atb":[[2.06,37.74]],"id":37306244}],"con":true,"img":false}]}
{"op":"mcm","clk":"5323121474","pt":1646327712660,"mc":[{"id":"1.195532875","rc":[{"atb":[[2.08,2]],"id":37306244},{"atb":[[2.1,1.99]],"id":35985721}],"con":true,"img":false}]}
{"op":"mcm","clk":"5323121499","pt":1646327712880,"mc":[{"id":"1.195532875","rc":[{"atb":[[2.12,1.65]],"id":37306244},{"atb":[[2.18,1.65]],"id":35985721}],"con":true,"img":false}]}
{"op":"mcm","clk":"5323121520","pt":1646327713078,"mc":[{"id":"1.195532875","rc":[{"atb":[[2.12,3.65],[2.08,0]],"id":37306244}],"con":true,"img":false}]}
{"op":"mcm","clk":"5323121712","pt":1646327714952,"mc":[{"id":"1.195532875","rc":[{"atb":[[2.54,64.94]],"id":41469398},{"atl":[[46,4.96]],"id":41469398}],"con":true,"img":false}]}
{"op":"mcm","clk":"5323121729","pt":1646327715067,"mc":[{"id":"1.195532875","rc":[{"atb":[[1.81,0]],"id":39614765},{"atb":[[1.62,2.16]],"id":40642034}],"con":true,"img":false}]}
{"op":"mcm","clk":"5323121739","pt":1646327715160,"mc":[{"id":"1.195532875","rc":[{"atb":[[1.64,1.99]],"id":40642034}],"con":true,"img":false}]}
{"op":"mcm","clk":"5323121748","pt":1646327715266,"mc":[{"id":"1.195532875","rc":[{"atb":[[2.08,37.04]],"id":37306244},{"atl":[[70,0]],"id":41469398},{"atb":[[2.06,0],[2.14,35.09]],"id":35985721}],"con":true,"img":false}]}
{"op":"mcm","clk":"5323121760","pt":1646327715389,"mc":[{"id":"1.195532875","rc":[{"atb":[[1.64,4.15],[1.62,64.52],[1.61,2.15]],"id":40642034}],"con":true,"img":false}]}
{"op":"mcm","clk":"5323121775","pt":1646327715581,"mc":[{"id":"1.195532875","rc":[{"atb":[[2.1,0]],"id":37306244},{"atl":[[16,3.19]],"id":39614765}],"con":true,"img":false}]}
{"op":"mcm","clk":"5323121786","pt":1646327715686,"mc":[{"id":"1.195532875","rc":[{"atb":[[2.14,1.99]],"id":37306244}],"con":true,"img":false}]}
{"op":"mcm","clk":"5323121793","pt":1646327715789,"mc":[{"id":"1.195532875","rc":[{"atl":[[16,0]],"id":39614765}],"con":true,"img":false}]}
{"op":"mcm","clk":"5323121817","pt":1646327716051,"mc":[{"id":"1.195532875","rc":[{"atb":[[2.1,0]],"id":35985721}],"con":true,"img":false}]}
{"op":"mcm","clk":"5323121841","pt":1646327716263,"mc":[{"id":"1.195532875","rc":[{"atb":[[2.18,3.64]],"id":35985721}],"con":true,"img":false}]}
{"op":"mcm","clk":"5323121888","pt":1646327716780,"mc":[{"id":"1.195532875","rc":[{"atb":[[2.1,36.36],[2.08,0]],"id":37306244},{"atb":[[1.91,0]],"id":35985721}],"con":true,"img":false}]}
{"op":"mcm","clk":"5323122053","pt":1646327718593,"mc":[{"id":"1.195532875","rc":[{"atb":[[1.56,0],[1.57,250],[1.54,0],[1.02,0]],"id":40883678},{"atl":[[4.3,30.3]],"id":40883678}],"con":true,"img":false}]}
{"op":"mcm","clk":"5323122061","pt":1646327718697,"mc":[{"id":"1.195532875","rc":[{"atb":[[1.8,187.5]],"id":39614765}],"con":true,"img":false}]}
{"op":"mcm","clk":"5323122080","pt":1646327718857,"mc":[{"id":"1.195532875","rc":[{"atb":[[2.2,7.97],[2.16,2.15]],"id":35985721}],"con":true,"img":false}]}
{"op":"mcm","clk":"5323122132","pt":1646327719380,"mc":[{"id":"1.195532875","rc":[{"atb":[[2.18,1.65]],"id":35985721}],"con":true,"img":false}]}
{"op":"mcm","clk":"5323122145","pt":1646327719503,"mc":[{"id":"1.195532875","rc":[{"atb":[[1.83,0],[2.16,2.15]],"id":37306244},{"atb":[[2.24,2.15],[2.22,1.99],[2.16,0]],"id":35985721},{"atb":[[1.65,2.15],[1.61,0]],"id":40642034}],"con":true,"img":false}]}
{"op":"mcm","clk":"5323122196","pt":1646327719954,"mc":[{"id":"1.195532875","rc":[{"atb":[[1.63,0]],"id":40642034}],"con":true,"img":false}]}
{"op":"mcm","clk":"5323122207","pt":1646327720058,"mc":[{"id":"1.195532875","rc":[{"atb":[[1.87,2.9]],"id":39614765}],"con":true,"img":false}]}
{"op":"mcm","clk":"5323122215","pt":1646327720171,"mc":[{"id":"1.195532875","rc":[{"atb":[[1.64,2.16]],"id":40642034}],"con":true,"img":false}]}
{"op":"mcm","clk":"5323122222","pt":1646327720265,"mc":[{"id":"1.195532875","rc":[{"atb":[[1.66,1.99]],"id":40642034}],"con":true,"img":false}]}
{"op":"mcm","clk":"5323122250","pt":1646327720588,"mc":[{"id":"1.195532875","rc":[{"atb":[[2.2,41.3],[2.14,0]],"id":35985721},{"atb":[[1.85,49.21]],"id":39614765},{"atb":[[1.64,64.66],[1.62,0]],"id":40642034}],"con":true,"img":false}]}
{"op":"mcm","clk":"5323122258","pt":1646327720691,"mc":[{"id":"1.195532875","rc":[{"atb":[[2.12,2]],"id":37306244},{"atb":[[2.18,0]],"id":35985721}],"con":true,"img":false}]}
{"op":"mcm","clk":"5323122279","pt":1646327720902,"mc":[{"id":"1.195532875","rc":[{"atb":[[2.18,1.65]],"id":37306244},{"atb":[[2.26,1.65]],"id":35985721}],"con":true,"img":false}]}
{"op":"mcm","clk":"5323122365","pt":1646327721895,"mc":[{"id":"1.195532875","rc":[{"atb":[[2.18,3.65]],"id":37306244}],"con":true,"img":false}]}
{"op":"mcm","clk":"5323122372","pt":1646327722003,"mc":[{"id":"1.195532875","rc":[{"atb":[[2.12,0]],"id":37306244}],"con":true,"img":false}]}
{"op":"mcm","clk":"5323122434","pt":1646327722687,"mc":[{"id":"1.195532875","rc":[{"atb":[[1.6,7.56]],"id":40642034}],"con":true,"img":false}]}
{"op":"mcm","clk":"5323122590","pt":1646327724208,"mc":[{"id":"1.195532875","rc":[{"atb":[[1.64,62.5],[1.66,4.15]],"id":40642034}],"con":true,"img":false}]}
{"op":"mcm","clk":"5323122602","pt":1646327724264,"mc":[{"id":"1.195532875","rc":[{"atb":[[1.66,1.99],[1.65,9.71]],"id":40642034}],"con":true,"img":false}]}
{"op":"mcm","clk":"5323122694","pt":1646327724999,"mc":[{"id":"1.195532875","rc":[{"atb":[[2.5,100]],"id":41469398},{"atl":[[50,3.06]],"id":41469398}],"con":true,"img":false}]}
{"op":"mcm","clk":"5323122734","pt":1646327725303,"mc":[{"id":"1.195532875","rc":[{"atb":[[2.06,42.37]],"id":37306244}],"con":true,"img":false}]}
{"op":"mcm","clk":"5323122748","pt":1646327725407,"mc":[{"id":"1.195532875","rc":[{"atb":[[2.06,37.74],[2.14,0]],"id":37306244}],"con":true,"img":false}]}
{"op":"mcm","clk":"5323122756","pt":1646327725512,"mc":[{"id":"1.195532875","rc":[{"atb":[[2.18,5.64]],"id":37306244}],"con":true,"img":false}]}
{"op":"mcm","clk":"5323122778","pt":1646327725673,"mc":[{"id":"1.195532875","rc":[{"atb":[[2.22,0]],"id":35985721}],"con":true,"img":false}]}
{"op":"mcm","clk":"5323122787","pt":1646327725772,"mc":[{"id":"1.195532875","rc":[{"atb":[[2.26,3.64]],"id":35985721}],"con":true,"img":false}]}
{"op":"mcm","clk":"5323122799","pt":1646327725879,"mc":[{"id":"1.195532875","rc":[{"atb":[[2.22,32.79],[2.2,7.97]],"id":35985721}],"con":true,"img":false}]}
{"op":"mcm","clk":"5323122811","pt":1646327725982,"mc":[{"id":"1.195532875","rc":[{"atb":[[1.85,63.02]],"id":39614765},{"atl":[[6.4,0],[6.6,17.86]],"id":40642034}],"con":true,"img":false}]}
{"op":"mcm","clk":"5323122823","pt":1646327726084,"mc":[{"id":"1.195532875","rc":[{"atl":[[6.6,22.49]],"id":40642034}],"con":true,"img":false}]}
{"op":"mcm","clk":"5323122855","pt":1646327726396,"mc":[{"id":"1.195532875","rc":[{"atb":[[1.85,49.21]],"id":39614765}],"con":true,"img":false}]}
{"op":"mcm","clk":"5323122892","pt":1646327726703,"mc":[{"id":"1.195532875","rc":[{"atl":[[6.8,0],[7,6.67]],"id":40642034}],"con":true,"img":false}]}
{"op":"mcm","clk":"5323122902","pt":1646327726806,"mc":[{"id":"1.195532875","rc":[{"atb":[[2.06,94.34]],"id":37306244},{"atl":[[6.6,17.86]],"id":40642034}],"con":true,"img":false}]}
{"op":"mcm","clk":"5323122938","pt":1646327727080,"mc":[{"id":"1.195532875","rc":[{"atb":[[1.86,2.16]],"id":39614765}],"con":true,"img":false}]}
{"op":"mcm","clk":"5323122951","pt":1646327727179,"mc":[{"id":"1.195532875","rc":[{"atb":[[1.88,1.99]],"id":39614765}],"con":true,"img":false}]}
{"op":"mcm","clk":"5323122963","pt":1646327727278,"mc":[{"id":"1.195532875","rc":[{"atb":[[1.88,4.15],[1.86,0]],"id":39614765}],"con":true,"img":false}]}
{"op":"mcm","clk":"5323122995","pt":1646327727591,"mc":[{"id":"1.195532875","rc":[{"atb":[[2.28,3.65],[2.2,0]],"id":35985721}],"con":true,"img":false}]}
{"op":"mcm","clk":"5323123090","pt":1646327728583,"mc":[{"id":"1.195532875","rc":[{"atb":[[2.26,1.99]],"id":35985721},{"atb":[[1.55,250]],"id":40883678},{"atl":[[4.5,42.86]],"id":40883678}],"con":true,"img":false}]}
{"op":"mcm","clk":"5323123108","pt":1646327728786,"mc":[{"id":"1.195532875","rc":[{"atb":[[2.3,1.65]],"id":35985721}],"con":true,"img":false}]}
{"op":"mcm","clk":"5323123190","pt":1646327729576,"mc":[{"id":"1.195532875","rc":[{"atb":[[1.6,0]],"id":40642034}],"con":true,"img":false}]}
{"op":"mcm","clk":"5323123276","pt":1646327730616,"mc":[{"id":"1.195532875","rc":[{"atb":[[1.85,2.15],[1.86,46.51]],"id":39614765}],"con":true,"img":false}]}
{"op":"mcm","clk":"5323123355","pt":1646327731399,"mc":[{"id":"1.195532875","rc":[{"atb":[[1.89,2.15],[1.85,0]],"id":39614765}],"con":true,"img":false}]}
{"op":"mcm","clk":"5323123381","pt":1646327731709,"mc":[{"id":"1.195532875","rc":[{"atb":[[1.87,0]],"id":39614765}],"con":true,"img":false}]}
{"op":"mcm","clk":"5323123525","pt":1646327733224,"mc":[{"id":"1.195532875","rc":[{"atb":[[2.26,0]],"id":35985721}],"con":true,"img":false}]}
{"op":"mcm","clk":"5323123537","pt":1646327733325,"mc":[{"id":"1.195532875","rc":[{"atb":[[2.3,3.64]],"id":35985721}],"con":true,"img":false}]}
{"op":"mcm","clk":"5323123560","pt":1646327733509,"mc":[{"id":"1.195532875","rc":[{"atb":[[2.22,0],[2.26,31.75]],"id":35985721},{"atb":[[1.86,0],[1.87,45.98]],"id":39614765},{"atl":[[4.3,34.2],[4.4,0],[4.2,0]],"id":40883678}],"con":true,"img":false}]}
{"op":"mcm","clk":"5323123573","pt":1646327733591,"mc":[{"id":"1.195532875","rc":[{"atb":[[2.22,4.03]],"id":35985721},{"atl":[[4.3,45.92]],"id":40883678}],"con":true,"img":false}]}
{"op":"mcm","clk":"5323123607","pt":1646327733899,"mc":[{"id":"1.195532875","rc":[{"atb":[[2.22,0]],"id":35985721}],"con":true,"img":false}]}
{"op":"mcm","clk":"5323123617","pt":1646327734000,"mc":[{"id":"1.195532875","rc":[{"atl":[[4.3,42.02]],"id":40883678}],"con":true,"img":false}]}
{"op":"mcm","clk":"5323123641","pt":1646327734319,"mc":[{"id":"1.195532875","rc":[{"atb":[[1.88,2.16]],"id":39614765}],"con":true,"img":false}]}
{"op":"mcm","clk":"5323123656","pt":1646327734424,"mc":[{"id":"1.195532875","rc":[{"atb":[[1.9,1.99]],"id":39614765}],"con":true,"img":false}]}
{"op":"mcm","clk":"5323123687","pt":1646327734689,"mc":[{"id":"1.195532875","rc":[{"atl":[[6.4,16.13],[6.6,0]],"id":40642034}],"con":true,"img":false}]}
{"op":"mcm","clk":"5323123719","pt":1646327735002,"mc":[{"id":"1.195532875","rc":[{"atb":[[2.46,171.23]],"id":41469398},{"atl":[[60,4.24]],"id":41469398}],"con":true,"img":false}]}
{"op":"mcm","clk":"5323123779","pt":1646327735624,"mc":[{"id":"1.195532875","rc":[{"atl":[[4.3,30.3]],"id":40883678}],"con":true,"img":false}]}
{"op":"mcm","clk":"5323123807","pt":1646327736002,"mc":[{"id":"1.195532875","rc":[{"atb":[[1.88,0],[1.9,4.15]],"id":39614765}],"con":true,"img":false}]}
{"op":"mcm","clk":"5323123816","pt":1646327736099,"mc":[{"id":"1.195532875","rc":[{"atb":[[1.89,6.13],[1.9,1.99]],"id":39614765}],"con":true,"img":false}]}
{"op":"mcm","clk":"5323123827","pt":1646327736199,"mc":[{"id":"1.195532875","rc":[{"atb":[[2.32,3.65],[2.28,0]],"id":35985721}],"con":true,"img":false}]}
{"op":"mcm","clk":"5323123866","pt":1646327736724,"mc":[{"id":"1.195532875","rc":[{"atb":[[2.3,1.99]],"id":35985721},{"atb":[[1.85,6.93]],"id":39614765},{"atb":[[1.6,15.22],[1.55,32.31],[1.62,161.29]],"id":40642034},{"atl":[[6.8,6.9],[7,0]],"id":40642034}],"con":true,"img":false}]}
{"op":"mcm","clk":"5323123877","pt":1646327736825,"mc":[{"id":"1.195532875","rc":[{"atb":[[2.02,147.06]],"id":37306244}],"con":true,"img":false}]}
{"op":"mcm","clk":"5323123884","pt":1646327736885,"mc":[{"id":"1.195532875","rc":[{"atb":[[2.34,1.65]],"id":35985721}],"con":true,"img":false}]}
{"op":"mcm","clk":"5323123889","pt":1646327736988,"mc":[{"id":"1.195532875","rc":[{"atb":[[1.55,0]],"id":40642034}],"con":true,"img":false}]}
{"op":"mcm","clk":"5323123969","pt":1646327737818,"mc":[{"id":"1.195532875","rc":[{"atb":[[2.3,0]],"id":35985721}],"con":true,"img":false}]}
{"op":"mcm","clk":"5323123979","pt":1646327737924,"mc":[{"id":"1.195532875","rc":[{"atb":[[2.34,3.64]],"id":35985721}],"con":true,"img":false}]}
{"op":"mcm","clk":"5323124044","pt":1646327738604,"mc":[{"id":"1.195532875","rc":[{"atl":[[4.7,67.57]],"id":40883678}],"con":true,"img":false}]}
{"op":"mcm","clk":"5323124276","pt":1646327740799,"mc":[{"id":"1.195532875","rc":[{"atb":[[1.6,0]],"id":40642034}],"con":true,"img":false}]}
{"op":"mcm","clk":"5323124289","pt":1646327740907,"mc":[{"id":"1.195532875","rc":[{"atb":[[2,0],[2.04,0]],"id":37306244},{"atb":[[2.3,30.77],[2.26,0]],"id":35985721},{"atb":[[1.88,45.45],[1.87,0]],"id":39614765},{"atb":[[1.59,0]],"id":40642034}],"con":true,"img":false}]}
{"op":"mcm","clk":"5323124596","pt":1646327744294,"mc":[{"id":"1.195532875","rc":[{"atb":[[1.76,25.98]],"id":40642034}],"con":true,"img":false}]}
{"op":"mcm","clk":"5323124654","pt":1646327744823,"mc":[{"id":"1.195532875","rc":[{"atb":[[2.36,3.65],[2.32,0]],"id":35985721},{"atb":[[1.66,0]],"id":40642034}],"con":true,"img":false}]}
{"op":"mcm","clk":"5323124667","pt":1646327744919,"mc":[{"id":"1.195532875","rc":[{"atb":[[1.77,1.99]],"id":40642034}],"con":true,"img":false}]}
{"op":"mcm","clk":"5323124688","pt":1646327745129,"mc":[{"id":"1.195532875","rc":[{"atb":[[1.77,11.71],[1.65,2.15]],"id":40642034}],"con":true,"img":false}]}
{"op":"mcm","clk":"5323124735","pt":1646327745607,"mc":[{"id":"1.195532875","rc":[{"atb":[[1.76,0]],"id":40642034}],"con":true,"img":false}]}
{"op":"mcm","clk":"5323124787","pt":1646327746128,"mc":[{"id":"1.195532875","rc":[{"atb":[[1.85,0]],"id":39614765},{"atb":[[1.66,8.19]],"id":40642034}],"con":true,"img":false}]}
{"op":"mcm","clk":"5323124795","pt":1646327746232,"mc":[{"id":"1.195532875","rc":[{"atb":[[2.34,1.65]],"id":35985721}],"con":true,"img":false}]}
{"op":"mcm","clk":"5323124807","pt":1646327746333,"mc":[{"id":"1.195532875","rc":[{"atb":[[2.38,1.99]],"id":35985721}],"con":true,"img":false}]}
{"op":"mcm","clk":"5323124815","pt":1646327746442,"mc":[{"id":"1.195532875","rc":[{"atb":[[2.36,0],[2.34,8.95]],"id":35985721}],"con":true,"img":false}]}
{"op":"mcm","clk":"5323124852","pt":1646327746704,"mc":[{"id":"1.195532875","rc":[{"atb":[[1.64,0],[1.75,53.33]],"id":40642034}],"con":true,"img":false}]}
{"op":"mcm","clk":"5323124860","pt":1646327746807,"mc":[{"id":"1.195532875","rc":[{"atb":[[1.99,250]],"id":37306244}],"con":true,"img":false}]}
{"op":"mcm","clk":"5323125208","pt":1646327750926,"mc":[{"id":"1.195532875","rc":[{"atb":[[2.3,0],[2.34,38.8]],"id":35985721},{"atl":[[17.5,6.06]],"id":35985721},{"atb":[[1.86,116.28]],"id":39614765}],"con":true,"img":false}]}
{"op":"mcm","clk":"5323125217","pt":1646327751026,"mc":[{"id":"1.195532875","rc":[{"atb":[[1.85,9.75]],"id":39614765},{"atb":[[1.66,0]],"id":40642034}],"con":true,"img":false}]}
{"op":"mcm","clk":"5323125300","pt":1646327751808,"mc":[{"id":"1.195532875","rc":[{"atl":[[19,0],[20,0],[22,0]],"id":35985721},{"atb":[[1.8,0]],"id":39614765}],"con":true,"img":false}]}
{"op":"mcm","clk":"5323125330","pt":1646327752120,"mc":[{"id":"1.195532875","rc":[{"atl":[[19.5,4.58]],"id":35985721},{"atl":[[6.4,0],[6.6,17.86]],"id":40642034}],"con":true,"img":false}]}
{"op":"mcm","clk":"5323125353","pt":1646327752657,"mc":[{"id":"1.195532875","rc":[{"atb":[[2.38,0]],"id":35985721}],"con":true,"img":false}]}
{"op":"mcm","clk":"5323125360","pt":1646327752676,"mc":[{"id":"1.195532875","rc":[{"atb":[[2.36,1.99]],"id":35985721}],"con":true,"img":false}]}
{"op":"mcm","clk":"5323125377","pt":1646327752722,"mc":[{"id":"1.195532875","rc":[{"atb":[[2.34,37.15]],"id":35985721}],"con":true,"img":false}]}
{"op":"mcm","clk":"5323125392","pt":1646327752849,"mc":[{"id":"1.195532875","rc":[{"atb":[[2.4,1.65]],"id":35985721}],"con":true,"img":false}]}
{"op":"mcm","clk":"5323125450","pt":1646327753433,"mc":[{"id":"1.195532875","rc":[{"atb":[[2.36,31.4],[2.34,7.3]],"id":35985721},{"atl":[[6.8,0],[7,6.67]],"id":40642034}],"con":true,"img":false}]}
{"op":"mcm","clk":"5323125493","pt":1646327753851,"mc":[{"id":"1.195532875","rc":[{"atl":[[19.5,0]],"id":35985721}],"con":true,"img":false}]}
{"op":"mcm","clk":"5323125568","pt":1646327754320,"mc":[{"id":"1.195532875","rc":[{"atb":[[1.85,0]],"id":39614765}],"con":true,"img":false}]}
{"op":"mcm","clk":"5323125615","pt":1646327754430,"mc":[{"id":"1.195532875","rc":[{"atb":[[1.63,25.75]],"id":40642034}],"con":true,"img":false}]}
{"op":"mcm","clk":"5323125662","pt":1646327754947,"mc":[{"id":"1.195532875","rc":[{"atb":[[2.4,8.95],[2.34,0]],"id":35985721}],"con":true,"img":false}]}
{"op":"mcm","clk":"5323125677","pt":1646327755052,"mc":[{"id":"1.195532875","rc":[{"atb":[[2.4,1.65],[2.36,38.7]],"id":35985721}],"con":true,"img":false}]}
{"op":"mcm","clk":"5323125696","pt":1646327755112,"mc":[{"id":"1.195532875","rc":[{"atb":[[2.4,10.61]],"id":35985721}],"con":true,"img":false}]}
{"op":"mcm","clk":"5323125705","pt":1646327755224,"mc":[{"id":"1.195532875","rc":[{"atb":[[2.36,31.4]],"id":35985721}],"con":true,"img":false}]}
{"op":"mcm","clk":"5323125875","pt":1646327756534,"mc":[{"id":"1.195532875","rc":[{"atb":[[2.36,29.41]],"id":35985721}],"con":true,"img":false}]}
{"op":"mcm","clk":"5323125885","pt":1646327756644,"mc":[{"id":"1.195532875","rc":[{"atb":[[2.42,1.99]],"id":35985721}],"con":true,"img":false}]}
{"op":"mcm","clk":"5323125920","pt":1646327756941,"mc":[{"id":"1.195532875","rc":[{"atb":[[1.9,7.67]],"id":39614765}],"con":true,"img":false}]}
{"op":"mcm","clk":"5323125942","pt":1646327757146,"mc":[{"id":"1.195532875","rc":[{"atb":[[1.89,2.15],[1.91,7.68]],"id":39614765}],"con":true,"img":false}]}
{"op":"mcm","clk":"5323125973","pt":1646327757410,"mc":[{"id":"1.195532875","rc":[{"atb":[[2.36,0],[2.38,28.99]],"id":35985721},{"atb":[[1.89,47.09],[1.88,0]],"id":39614765},{"atl":[[6.4,16.13],[6.6,0]],"id":40642034}],"con":true,"img":false}]}
{"op":"mcm","clk":"5323125982","pt":1646327757514,"mc":[{"id":"1.195532875","rc":[{"atl":[[6.8,6.9],[7,0]],"id":40642034}],"con":true,"img":false}]}
{"op":"mcm","clk":"5323126016","pt":1646327757932,"mc":[{"id":"1.195532875","rc":[{"atb":[[1.89,44.94],[1.93,2.15]],"id":39614765}],"con":true,"img":false}]}
{"op":"mcm","clk":"5323126028","pt":1646327758036,"mc":[{"id":"1.195532875","rc":[{"atb":[[1.91,0],[1.9,5.68]],"id":39614765}],"con":true,"img":false}]}
{"op":"mcm","clk":"5323126035","pt":1646327758141,"mc":[{"id":"1.195532875","rc":[{"atb":[[1.92,1.99],[1.93,9.83]],"id":39614765}],"con":true,"img":false}]}
{"op":"mcm","clk":"5323126049","pt":1646327758248,"mc":[{"id":"1.195532875","rc":[{"atb":[[1.9,9.52]],"id":39614765}],"con":true,"img":false}]}
{"op":"mcm","clk":"5323126079","pt":1646327758507,"mc":[{"id":"1.195532875","rc":[{"atb":[[1.91,43.96]],"id":39614765}],"con":true,"img":false}]}
{"op":"mcm","clk":"5323126087","pt":1646327758618,"mc":[{"id":"1.195532875","rc":[{"atb":[[1.89,0],[1.9,5.68]],"id":39614765}],"con":true,"img":false}]}
{"op":"mcm","clk":"5323126247","pt":1646327760452,"mc":[{"id":"1.195532875","rc":[{"atb":[[2.54,105.49],[3.8,5.64]],"id":41469398},{"atl":[[46,9.85],[29,2.86]],"id":41469398},{"atb":[[1.85,20.88],[1.65,36.95]],"id":40642034},{"atl":[[7.2,47.4],[6.2,15.38]],"id":40642034}],"con":true,"img":false}]}
{"op":"mcm","clk":"5323126261","pt":1646327760658,"mc":[{"id":"1.195532875","rc":[{"atb":[[2.36,2.5],[2.24,12.57],[2.28,5],[2.2,10],[2.1,57.31]],"id":37306244},{"atl":[[10,33.63],[6.2,5],[5.7,2.5],[7,10],[7.8,11.76]],"id":37306244},{"atb":[[3.45,5],[2.72,6.78],[3.25,10],[3.65,2.5]],"id":41469398},{"atl":[[10,2.5],[12,5],[14,10],[28,2.96],[29,0]],"id":41469398},{"atb":[[2.4,11.46],[2.24,22.95],[2.32,5],[2.46,6.48]],"id":35985721},{"atl":[[17.5,18.93],[6.4,10],[5.8,5],[5.4,2.5],[9.4,6.48]],"id":35985721},{"atb":[[2.42,2.5],[1.9,24.3],[2.26,10],[2.14,11.18],[2.34,5]],"id":39614765},{"atl":[[9,10],[6.2,2.5],[7,5],[7.8,10],[15.5,21.43]],"id":39614765},{"atb":[[1.98,10],[2.04,5],[2.12,2.5]],"id":40642034},{"atl":[[4.5,2.5],[5.3,10],[4.9,5]],"id":40642034},{"atb":[[1.63,37.29],[1.55,294.64],[1.61,119.57]],"id":40883678},{"atl":[[3.45,2.5],[4.3,82.7],[3.85,10],[3,32.4],[3.65,5]],"id":40883678}],"con":true,"img":false}]}
{"op":"mcm","clk":"5323126266","pt":1646327760718,"mc":[{"id":"1.195532875","rc":[{"atb":[[2.12,7.06]],"id":37306244},{"atl":[[9.2,3.12]],"id":37306244},{"spn":2.36,"spf":1.0,"id":37306244},{"spn":3.8,"spf":1.0,"id":41469398},{"spn":2.44,"spf":1.0,"id":35985721},{"spn":2.34,"spf":1.0,"id":39614765},{"spn":3.31,"spf":"NaN","id":40642034},{"spn":2.31,"spf":"NaN","id":40883678}],"con":true,"img":false}]}
{"op":"mcm","clk":"5323126271","pt":1646327760872,"mc":[{"id":"1.195532875","rc":[{"atb":[[2.24,18.22],[2.18,3.64]],"id":37306244},{"atl":[[9,0],[7,21.11]],"id":37306244},{"atb":[[3.45,32.48],[2.6,1.99]],"id":41469398},{"atl":[[38,0],[14,12.56]],"id":41469398},{"atb":[[2.4,2.49],[2.46,12.96],[2.44,1.65]],"id":35985721},{"atl":[[6.4,12.58],[15.5,0]],"id":35985721},{"atl":[[13.5,0],[7.8,16.9],[14,6]],"id":39614765},{"atb":[[1.84,41.76],[1.77,1.98],[1.65,2.15]],"id":40642034},{"atl":[[6.4,0],[5.3,25.38]],"id":40642034},{"atl":[[3.85,40.3],[3.95,0]],"id":40883678}],"con":true,"img":false}]}
{"op":"mcm","clk":"5323126288","pt":1646327761035,"mc":[{"id":"1.195532875","rc":[{"atb":[[2.46,6.48],[2.44,27.57]],"id":35985721}],"con":true,"img":false}]}
{"op":"mcm","clk":"5323126302","pt":1646327761250,"mc":[{"id":"1.195532875","rc":[{"atb":[[2.72,0]],"id":41469398},{"atb":[[1.55,250]],"id":40883678}],"con":true,"img":false}]}
{"op":"mcm","clk":"5323126325","pt":1646327761552,"mc":[{"id":"1.195532875","rc":[{"atb":[[1.9,18.62]],"id":39614765},{"atb":[[1.63,0]],"id":40642034}],"con":true,"img":false}]}
{"op":"mcm","clk":"5323126354","pt":1646327761865,"mc":[{"id":"1.195532875","rc":[{"atb":[[3.7,14.81],[2.58,2.15]],"id":41469398},{"atl":[[42,0],[11,4]],"id":41469398}],"con":true,"img":false}]}
{"op":"mcm","clk":"5323126366","pt":1646327761928,"mc":[{"id":"1.195532875","rc":[{"atb":[[2.12,0]],"id":37306244},{"atl":[[9.2,0]],"id":37306244},{"atl":[[14,0]],"id":39614765}],"con":true,"img":false}]}
{"op":"mcm","clk":"5323126384","pt":1646327762135,"mc":[{"id":"1.195532875","rc":[{"atl":[[3.1,19.05],[4.1,0]],"id":40883678}],"con":true,"img":false}]}
{"op":"mcm","clk":"5323126508","pt":1646327763688,"mc":[{"id":"1.195532875","rc":[{"atb":[[1.92,0]],"id":39614765}],"con":true,"img":false}]}
{"op":"mcm","clk":"5323126518","pt":1646327763749,"mc":[{"id":"1.195532875","rc":[{"atb":[[1.94,1.99]],"id":39614765}],"con":true,"img":false}]}
{"op":"mcm","clk":"5323126603","pt":1646327764691,"mc":[{"id":"1.195532875","rc":[{"atl":[[5.9,8.16],[9.4,0]],"id":37306244},{"atb":[[2.42,30.16],[2.38,0]],"id":35985721},{"atl":[[5.6,8.7]],"id":35985721},{"atb":[[2,40],[1.91,0]],"id":39614765},{"atl":[[6.6,7.14],[14.5,0]],"id":39614765},{"atb":[[1.77,53.94],[1.75,0]],"id":40642034},{"atl":[[6.8,0],[4.7,10.81]],"id":40642034}],"con":true,"img":false}]}
{"op":"mcm","clk":"5323126610","pt":1646327764735,"mc":[{"id":"1.195532875","rc":[{"atl":[[3,0]],"id":40883678}],"con":true,"img":false}]}
{"op":"mcm","clk":"5323126621","pt":1646327764841,"mc":[{"id":"1.195532875","rc":[{"atl":[[7,15],[7.8,10]],"id":39614765},{"atl":[[5.4,5]],"id":40642034},{"atl":[[3.05,16.16]],"id":40883678}],"con":true,"img":false}]}
{"op":"mcm","clk":"5323126635","pt":1646327765051,"mc":[{"id":"1.195532875","rc":[{"atb":[[1.77,51.95]],"id":40642034}],"con":true,"img":false}]}
{"op":"mcm","clk":"5323126643","pt":1646327765156,"mc":[{"id":"1.195532875","rc":[{"atb":[[2.14,1.99]],"id":40642034}],"con":true,"img":false}]}
{"op":"mcm","clk":"5323126662","pt":1646327765359,"mc":[{"id":"1.195532875","rc":[{"atl":[[3.1,0],[3.15,18.6]],"id":40883678}],"con":true,"img":false}]}
{"op":"mcm","clk":"5323126708","pt":1646327765984,"mc":[{"id":"1.195532875","rc":[{"atl":[[5.4,0]],"id":40642034}],"con":true,"img":false}]}
{"op":"mcm","clk":"5323126755","pt":1646327766573,"mc":[{"id":"1.195532875","rc":[{"atb":[[2.26,21.18],[1.93,2.15]],"id":39614765}],"con":true,"img":false}]}
{"op":"mcm","clk":"5323126798","pt":1646327767045,"mc":[{"id":"1.195532875","rc":[{"atb":[[2.3,2.75]],"id":37306244},{"atb":[[1.99,3.75]],"id":40642034}],"con":true,"img":false}]}
{"op":"mcm","clk":"5323126933","pt":1646327768663,"mc":[{"id":"1.195532875","rc":[{"atb":[[2.34,2.15],[2.18,1.99],[2.16,0]],"id":37306244},{"atb":[[2.62,0]],"id":41469398},{"atb":[[2.44,25.92]],"id":35985721},{"atb":[[2.32,2.15],[1.93,0]],"id":39614765},{"atb":[[1.62,0],[1.66,2.15]],"id":40883678}],"con":true,"img":false}]}
{"op":"mcm","clk":"5323126954","pt":1646327768883,"mc":[{"id":"1.195532875","rc":[{"atb":[[2.38,1.65]],"id":37306244},{"atb":[[3.85,1.65]],"id":41469398},{"atb":[[2.48,1.65]],"id":35985721},{"atb":[[2.44,1.65]],"id":39614765},{"atb":[[2.16,1.65]],"id":40642034},{"atb":[[1.61,123]],"id":40883678}],"con":true,"img":false}]}
{"op":"mcm","clk":"5323126972","pt":1646327769077,"mc":[{"id":"1.195532875","rc":[{"atb":[[2.46,32.4],[2.44,0]],"id":35985721}],"con":true,"img":false}]}
{"op":"mcm","clk":"5323126978","pt":1646327769184,"mc":[{"id":"1.195532875","rc":[{"atl":[[14,10]],"id":41469398},{"atl":[[6.4,10]],"id":35985721},{"atl":[[3.45,37.26]],"id":40883678}],"con":true,"img":false}]}
{"op":"mcm","clk":"5323126985","pt":1646327769289,"mc":[{"id":"1.195532875","rc":[{"atb":[[2.24,12.57],[2.38,3.81]],"id":37306244},{"atl":[[6.2,16.76],[7,10]],"id":37306244},{"atb":[[3.45,5],[3.65,13.78]],"id":41469398},{"atl":[[12,11.5]],"id":41469398},{"atl":[[5.8,16.2]],"id":35985721},{"atl":[[5.3,10],[4.9,20.38]],"id":40642034},{"atl":[[3.85,10]],"id":40883678}],"con":true,"img":false}]}
{"op":"mcm","clk":"5323127032","pt":1646327769774,"mc":[{"id":"1.195532875","rc":[{"atb":[[3.75,14.55],[3.7,0]],"id":41469398},{"atb":[[2.42,1.99],[2.44,27.78]],"id":35985721},{"atb":[[1.63,100.78],[1.61,57.43]],"id":40883678}],"con":true,"img":false}]}
{"op":"mcm","clk":"5323127050","pt":1646327769972,"mc":[{"id":"1.195532875","rc":[{"atb":[[1.61,54]],"id":40883678}],"con":true,"img":false}]}
{"op":"mcm","clk":"5323127093","pt":1646327770444,"mc":[{"id":"1.195532875","rc":[{"atb":[[1.94,0]],"id":39614765}],"con":true,"img":false}]}
{"op":"mcm","clk":"5323127101","pt":1646327770555,"mc":[{"id":"1.195532875","rc":[{"atb":[[2.44,3.64]],"id":39614765}],"con":true,"img":false}]}
{"op":"mcm","clk":"5323127105","pt":1646327770658,"mc":[{"id":"1.195532875","rc":[{"atb":[[2.6,0]],"id":41469398}],"con":true,"img":false}]}
{"op":"mcm","clk":"5323127116","pt":1646327770759,"mc":[{"id":"1.195532875","rc":[{"atb":[[3.85,3.64]],"id":41469398}],"con":true,"img":false}]}
{"op":"mcm","clk":"5323127134","pt":1646327770969,"mc":[{"id":"1.195532875","rc":[{"atb":[[2.18,0]],"id":37306244}],"con":true,"img":false}]}
{"op":"mcm","clk":"5323127145","pt":1646327771072,"mc":[{"id":"1.195532875","rc":[{"atb":[[1.02,1.99]],"id":37306244}],"con":true,"img":false}]}
{"op":"mcm","clk":"5323127165","pt":1646327771277,"mc":[{"id":"1.195532875","rc":[{"atb":[[2.42,0]],"id":35985721}],"con":true,"img":false}]}
{"op":"mcm","clk":"5323127175","pt":1646327771382,"mc":[{"id":"1.195532875","rc":[{"atb":[[2.48,3.64]],"id":35985721}],"con":true,"img":false}]}
{"op":"mcm","clk":"5323127213","pt":1646327771858,"mc":[{"id":"1.195532875","rc":[{"atb":[[2.3,0]],"id":37306244},{"atb":[[1.99,0]],"id":40642034}],"con":true,"img":false}]}
{"op":"mcm","clk":"5323127312","pt":1646327772860,"mc":[{"id":"1.195532875","rc":[{"atl":[[2.9,5.1]],"id":40883678}],"con":true,"img":false}]}
{"op":"mcm","clk":"5323127343","pt":1646327773273,"mc":[{"id":"1.195532875","rc":[{"atl":[[2.9,0]],"id":40883678}],"con":true,"img":false}]}
{"op":"mcm","clk":"5323127445","pt":1646327774490,"mc":[{"id":"1.195532875","rc":[{"atb":[[3.6,19.42],[3.65,2.5]],"id":41469398}],"con":true,"img":false}]}
{"op":"mcm","clk":"5323127460","pt":1646327774705,"mc":[{"id":"1.195532875","rc":[{"atl":[[6.2,35.99]],"id":37306244},{"atb":[[1.98,102.04]],"id":39614765},{"atl":[[7,31.67]],"id":39614765},{"atb":[[1.75,133.33]],"id":40642034},{"atl":[[4.9,46.02]],"id":40642034}],"con":true,"img":false}]}
{"op":"mcm","clk":"5323127692","pt":1646327776869,"mc":[{"id":"1.195532875","rc":[{"atb":[[2.3,4.57]],"id":37306244},{"atb":[[2.06,4.37]],"id":40642034}],"con":true,"img":false}]}
{"op":"mcm","clk":"5323127748","pt":1646327777501,"mc":[{"id":"1.195532875","rc":[{"atl":[[10,22.52],[11,0],[12,0]],"id":37306244},{"atb":[[1.82,0]],"id":39614765},{"atl":[[17.5,0]],"id":39614765},{"atb":[[1.62,0],[1.56,0],[1.54,0]],"id":40642034},{"atl":[[8,0],[7.2,31.27],[7.6,0]],"id":40642034},{"atl":[[3.45,2.5],[3.15,50.92]],"id":40883678}],"con":true,"img":false}]}
{"op":"mcm","clk":"5323127757","pt":1646327777559,"mc":[{"id":"1.195532875","rc":[{"atb":[[2.4,7.59],[2.6,3.12]],"id":35985721}],"con":true,"img":false}]}
{"op":"mcm","clk":"5323127766","pt":1646327777665,"mc":[{"id":"1.195532875","rc":[{"atl":[[3.45,43.32],[3.15,18.6]],"id":40883678}],"con":true,"img":false}]}
{"op":"mcm","clk":"5323127781","pt":1646327777762,"mc":[{"id":"1.195532875","rc":[{"atb":[[2.4,2.49]],"id":35985721}],"con":true,"img":false}]}
{"op":"mcm","clk":"5323127801","pt":1646327777970,"mc":[{"id":"1.195532875","rc":[{"atb":[[2.54,64.94],[3.75,26.6],[3.9,7.23]],"id":41469398},{"atl":[[46,4.96],[12,30.78],[9.8,7.23]],"id":41469398},{"atl":[[7.2,0],[4.9,62.08],[4.4,3.75]],"id":40642034}],"con":true,"img":false}]}
{"op":"mcm","clk":"5323127812","pt":1646327778074,"mc":[{"id":"1.195532875","rc":[{"atb":[[2.22,7.9]],"id":37306244},{"atl":[[9.6,4]],"id":41469398},{"atl":[[4.3,3.75],[4.9,46.7]],"id":40642034}],"con":true,"img":false}]}
{"op":"mcm","clk":"5323127821","pt":1646327778179,"mc":[{"id":"1.195532875","rc":[{"atb":[[2.1,36.36],[2.34,10.05],[2.38,8.55]],"id":37306244},{"atl":[[10,0],[6.2,48.63]],"id":37306244},{"atb":[[3.8,0]],"id":41469398},{"atl":[[12,24.28],[28,0]],"id":41469398},{"atb":[[2.24,12.15],[2.46,47.84],[2.6,9.26]],"id":35985721},{"atl":[[17.5,6.06],[5.8,40.9],[5.3,9.26]],"id":35985721},{"atb":[[1.9,0],[2.34,15.81]],"id":39614765},{"atl":[[6,6.49],[7,48.97],[15.5,6.9]],"id":39614765},{"atl":[[6.2,0]],"id":40642034},{"atb":[[1.66,45.72]],"id":40883678},{"atl":[[3.45,112.27],[4.3,30.3]],"id":40883678}],"con":true,"img":false}]}
{"op":"mcm","clk":"5323127831","pt":1646327778294,"mc":[{"id":"1.195532875","rc":[{"atb":[[2.22,0]],"id":37306244},{"atl":[[5.6,4.74]],"id":37306244},{"atl":[[9.6,0],[10,13.61],[9.4,7.23]],"id":41469398},{"atb":[[2.44,10.13]],"id":39614765},{"atl":[[2.9,42.11]],"id":40883678}],"con":true,"img":false}]}
{"op":"mcm","clk":"5323127839","pt":1646327778393,"mc":[{"id":"1.195532875","rc":[{"atb":[[2.24,0]],"id":37306244},{"atl":[[11.5,3.88]],"id":41469398},{"atb":[[2.46,41.36],[2.6,0]],"id":35985721},{"atl":[[5.8,29.7],[5.2,8.7],[9.4,0]],"id":35985721},{"atl":[[9,0],[7,38.97],[5.9,6.49]],"id":39614765},{"atb":[[1.63,68.38]],"id":40883678},{"atl":[[3.05,26.16]],"id":40883678}],"con":true,"img":false}]}
{"op":"mcm","clk":"5323127849","pt":1646327778495,"mc":[{"id":"1.195532875","rc":[{"atl":[[6.2,36.87],[7.8,0],[5.9,18.16]],"id":37306244},{"atl":[[9.8,0],[9.4,0]],"id":41469398},{"atb":[[2.14,0]],"id":39614765},{"atl":[[3.05,10]],"id":40883678}],"con":true,"img":false}]}
{"op":"mcm","clk":"5323127855","pt":1646327778599,"mc":[{"id":"1.195532875","rc":[{"atl":[[9.8,9.09]],"id":41469398},{"atb":[[2.46,50.62]],"id":35985721},{"atl":[[5.2,0],[5.4,20.46]],"id":35985721},{"atl":[[6.2,15.48],[5.9,0]],"id":39614765}],"con":true,"img":false}]}
{"op":"mcm","clk":"5323127876","pt":1646327778807,"mc":[{"id":"1.195532875","rc":[{"atl":[[11.5,0]],"id":41469398},{"atl":[[5.6,30.44],[5.4,2.5]],"id":35985721},{"atb":[[1.63,66.39]],"id":40883678}],"con":true,"img":false}]}
{"op":"mcm","clk":"5323127886","pt":1646327778860,"mc":[{"id":"1.195532875","rc":[{"atb":[[1.67,1.99]],"id":40883678}],"con":true,"img":false}]}
{"op":"mcm","clk":"5323127908","pt":1646327779071,"mc":[{"id":"1.195532875","rc":[{"atb":[[3.85,1.65]],"id":41469398}],"con":true,"img":false}]}
{"op":"mcm","clk":"5323127916","pt":1646327779180,"mc":[{"id":"1.195532875","rc":[{"atb":[[3.95,1.99]],"id":41469398}],"con":true,"img":false}]}
{"op":"mcm","clk":"5323127929","pt":1646327779280,"mc":[{"id":"1.195532875","rc":[{"atb":[[2.34,7.9],[2.42,2.15]],"id":37306244},{"atb":[[2.32,0],[2.5,2.15]],"id":39614765}],"con":true,"img":false}]}
{"op":"mcm","clk":"5323127944","pt":1646327779488,"mc":[{"id":"1.195532875","rc":[{"atb":[[2.42,4.65],[2.38,6.39]],"id":37306244}],"con":true,"img":false}]}
{"op":"mcm","clk":"5323127956","pt":1646327779594,"mc":[{"id":"1.195532875","rc":[{"atb":[[2.42,2.15],[2.38,14.29]],"id":37306244}],"con":true,"img":false}]}
{"op":"mcm","clk":"5323127968","pt":1646327779802,"mc":[{"id":"1.195532875","rc":[{"atb":[[2.42,6.81],[2.38,6.39]],"id":37306244},{"atb":[[3.85,15.69],[3.75,12.05]],"id":41469398},{"atl":[[10.5,4.21],[11,0]],"id":41469398},{"atb":[[2.4,73.93]],"id":35985721},{"atl":[[5.5,8.89]],"id":35985721},{"atb":[[1.61,217.93]],"id":40883678},{"atl":[[3.15,0],[2.94,20.62]],"id":40883678}],"con":true,"img":false}]}
{"op":"mcm","clk":"5323127984","pt":1646327779963,"mc":[{"id":"1.195532875","rc":[{"atl":[[3.05,0]],"id":40883678}],"con":true,"img":false}]}
{"op":"mcm","clk":"5323128098","pt":1646327781471,"mc":[{"id":"1.195532875","rc":[{"atb":[[2.3,0]],"id":37306244},{"atb":[[1.63,63.49]],"id":40883678}],"con":true,"img":false}]}
{"op":"mcm","clk":"5323128297","pt":1646327783290,"mc":[{"id":"1.195532875","rc":[{"atl":[[4.3,0],[4.5,13.31]],"id":40642034}],"con":true,"img":false}]}
{"op":"mcm","clk":"5323128318","pt":1646327783498,"mc":[{"id":"1.195532875","rc":[{"atl":[[10,2.5],[10.5,14.74]],"id":41469398}],"con":true,"img":false}]}
{"op":"mcm","clk":"5323128351","pt":1646327783809,"mc":[{"id":"1.195532875","rc":[{"atl":[[6.2,2.5],[6.6,25]],"id":39614765}],"con":true,"img":false}]}
{"op":"mcm","clk":"5323128425","pt":1646327784492,"mc":[{"id":"1.195532875","rc":[{"atb":[[2.48,1.65]],"id":35985721}],"con":true,"img":false}]}
{"op":"mcm","clk":"5323128436","pt":1646327784598,"mc":[{"id":"1.195532875","rc":[{"atb":[[2.62,1.99]],"id":35985721}],"con":true,"img":false}]}
{"op":"mcm","clk":"5323128447","pt":1646327784700,"mc":[{"id":"1.195532875","rc":[{"atb":[[2.38,4.74]],"id":37306244},{"atl":[[5.8,8.33]],"id":37306244},{"atb":[[3.85,14.04]],"id":41469398},{"atb":[[2.02,0],[1.95,0],[1.93,0]],"id":35985721},{"atb":[[2.44,8.48]],"id":39614765},{"atl":[[6.4,7.41],[6.6,17.86]],"id":39614765},{"atl":[[4.6,11.11]],"id":40642034}],"con":true,"img":false}]}
{"op":"mcm","clk":"5323128456","pt":1646327784801,"mc":[{"id":"1.195532875","rc":[{"atb":[[2.44,0],[2.58,25.32]],"id":35985721}],"con":true,"img":false}]}
{"op":"mcm","clk":"5323128464","pt":1646327784908,"mc":[{"id":"1.195532875","rc":[{"atb":[[2.44,1.65]],"id":37306244},{"atb":[[4,1.65]],"id":41469398},{"atb":[[2.52,1.65]],"id":39614765},{"atl":[[4.5,2.5],[4.6,28.17]],"id":40642034},{"atb":[[1.55,0]],"id":40883678}],"con":true,"img":false}]}
{"op":"mcm","clk":"5323128543","pt":1646327785694,"mc":[{"id":"1.195532875","rc":[{"atb":[[2.44,6.49]],"id":39614765}],"con":true,"img":false}]}
{"op":"mcm","clk":"5323128550","pt":1646327785794,"mc":[{"id":"1.195532875","rc":[{"atb":[[2.52,3.64]],"id":39614765}],"con":true,"img":false}]}
{"op":"mcm","clk":"5323128567","pt":1646327786000,"mc":[{"id":"1.195532875","rc":[{"atb":[[3.85,0],[3.9,21.02]],"id":41469398}],"con":true,"img":false}]}
{"op":"mcm","clk":"5323128578","pt":1646327786107,"mc":[{"id":"1.195532875","rc":[{"atb":[[3.8,7.58]],"id":41469398}],"con":true,"img":false}]}
{"op":"mcm","clk":"5323128594","pt":1646327786289,"mc":[{"id":"1.195532875","rc":[{"atb":[[2.06,0]],"id":40642034}],"con":true,"img":false}]}
{"op":"mcm","clk":"5323128605","pt":1646327786394,"mc":[{"id":"1.195532875","rc":[{"atb":[[2.44,6.42]],"id":37306244},{"atb":[[3.8,0]],"id":41469398},{"atb":[[2.4,119.64],[2.46,35.18]],"id":35985721},{"atb":[[1.64,47.71]],"id":40883678}],"con":true,"img":false}]}
{"op":"mcm","clk":"5323128622","pt":1646327786599,"mc":[{"id":"1.195532875","rc":[{"atb":[[1.63,182.79],[1.61,163.93]],"id":40883678}],"con":true,"img":false}]}
{"op":"mcm","clk":"5323128813","pt":1646327788696,"mc":[{"id":"1.195532875","rc":[{"atb":[[2.06,4.37]],"id":40642034}],"con":true,"img":false}]}
{"op":"mcm","clk":"5323128920","pt":1646327789790,"mc":[{"id":"1.195532875","rc":[{"atb":[[1.59,250]],"id":40883678},{"atl":[[2.98,50.51]],"id":40883678}],"con":true,"img":false}]}
{"op":"mcm","clk":"5323128932","pt":1646327789894,"mc":[{"id":"1.195532875","rc":[{"atb":[[2.24,10],[2.64,2.15]],"id":35985721},{"atl":[[3.45,71.45],[2.98,101.02]],"id":40883678}],"con":true,"img":false}]}
{"op":"mcm","clk":"5323128995","pt":1646327790412,"mc":[{"id":"1.195532875","rc":[{"atb":[[2.6,25]],"id":35985721},{"atl":[[4.7,0]],"id":40883678}],"con":true,"img":false}]}
{"op":"mcm","clk":"5323129064","pt":1646327790985,"mc":[{"id":"1.195532875","rc":[{"atb":[[2.62,0]],"id":35985721}],"con":true,"img":false}]}
{"op":"mcm","clk":"5323129074","pt":1646327791091,"mc":[{"id":"1.195532875","rc":[{"atb":[[2.6,26.99]],"id":35985721}],"con":true,"img":false}]}
{"op":"mcm","clk":"5323129209","pt":1646327792614,"mc":[{"id":"1.195532875","rc":[{"atb":[[2.48,0]],"id":35985721}],"con":true,"img":false}]}
{"op":"mcm","clk":"5323129229","pt":1646327792784,"mc":[{"id":"1.195532875","rc":[{"atb":[[2.66,1.65]],"id":35985721}],"con":true,"img":false}]}
{"op":"mcm","clk":"5323129418","pt":1646327794713,"mc":[{"id":"1.195532875","rc":[{"atl":[[6,20]],"id":37306244},{"atb":[[1.96,156.25]],"id":39614765},{"atb":[[1.73,205.48]],"id":40642034},{"atl":[[4.8,26.32]],"id":40642034}],"con":true,"img":false}]}
{"op":"mcm","clk":"5323129469","pt":1646327795226,"mc":[{"id":"1.195532875","rc":[{"atb":[[4,10.34]],"id":41469398},{"atl":[[10.5,38.54],[12,5]],"id":41469398},{"atl":[[4.6,42.97],[4.9,30.64]],"id":40642034}],"con":true,"img":false}]}
{"op":"mcm","clk":"5323129491","pt":1646327795400,"mc":[{"id":"1.195532875","rc":[{"atb":[[2.44,14.8],[2.34,0],[2.38,18.7]],"id":37306244},{"atl":[[5.8,30.67],[6.2,24.23]],"id":37306244},{"atb":[[3.9,13.79]],"id":41469398},{"atb":[[2.4,73.93],[2.58,48.01]],"id":35985721},{"atl":[[5.8,5],[5.5,45.19]],"id":35985721},{"atb":[[2.44,19.17],[2.34,5]],"id":39614765},{"atl":[[6.4,27.69],[7,21.67]],"id":39614765},{"atl":[[3.45,2.5],[2.98,184.97]],"id":40883678}],"con":true,"img":false}]}
{"op":"mcm","clk":"5323129514","pt":1646327795611,"mc":[{"id":"1.195532875","rc":[{"atb":[[2.38,13.96]],"id":37306244}],"con":true,"img":false}]}
{"op":"mcm","clk":"5323129551","pt":1646327796020,"mc":[{"id":"1.195532875","rc":[{"atb":[[3.8,35.71]],"id":41469398},{"atl":[[11.5,9.52]],"id":41469398}],"con":true,"img":false}]}
{"op":"mcm","clk":"5323129568","pt":1646327796188,"mc":[{"id":"1.195532875","rc":[{"atb":[[3.8,68.37],[3.75,0]],"id":41469398}],"con":true,"img":false}]}
{"op":"mcm","clk":"5323129635","pt":1646327796819,"mc":[{"id":"1.195532875","rc":[{"atb":[[2.54,0],[2.5,0],[2.46,0]],"id":41469398},{"atl":[[46,2.74],[50,0],[60,0]],"id":41469398},{"atb":[[2.62,24.69]],"id":35985721},{"atb":[[1.84,0]],"id":39614765},{"atb":[[1.57,425.44],[1.66,2.15]],"id":40883678}],"con":true,"img":false}]}
{"op":"mcm","clk":"5323129645","pt":1646327796916,"mc":[{"id":"1.195532875","rc":[{"atl":[[5.8,34.92]],"id":37306244},{"atb":[[1.6,0]],"id":40883678},{"atl":[[2.9,0]],"id":40883678}],"con":true,"img":false}]}
{"op":"mcm","clk":"5323129665","pt":1646327797084,"mc":[{"id":"1.195532875","rc":[{"atb":[[1.59,258.33]],"id":40883678},{"atl":[[3.45,43.32],[2.9,42.11],[2.98,134.46]],"id":40883678}],"con":true,"img":false}]}
{"op":"mcm","clk":"5323129674","pt":1646327797184,"mc":[{"id":"1.195532875","rc":[{"atl":[[3.45,2.5],[2.98,175.7]],"id":40883678}],"con":true,"img":false}]}
{"op":"mcm","clk":"5323129701","pt":1646327797496,"mc":[{"id":"1.195532875","rc":[{"atb":[[1.59,250]],"id":40883678}],"con":true,"img":false}]}
{"op":"mcm","clk":"5323129793","pt":1646327798482,"mc":[{"id":"1.195532875","rc":[{"atl":[[5.8,30.67]],"id":37306244}],"con":true,"img":false}]}
{"op":"mcm","clk":"5323129950","pt":1646327799795,"mc":[{"id":"1.195532875","rc":[{"atl":[[3.05,73.17]],"id":40883678}],"con":true,"img":false}]}
{"op":"mcm","clk":"5323130082","pt":1646327801004,"mc":[{"id":"1.195532875","rc":[{"atl":[[4.5,0]],"id":40883678}],"con":true,"img":false}]}
{"op":"mcm","clk":"5323130206","pt":1646327802347,"mc":[{"id":"1.195532875","rc":[{"atb":[[2.4,21.63],[2.42,2.15]],"id":37306244}],"con":true,"img":false}]}
{"op":"mcm","clk":"5323130284","pt":1646327802825,"mc":[{"id":"1.195532875","rc":[{"atb":[[2.5,2.15],[2.42,0]],"id":37306244}],"con":true,"img":false}]}
{"op":"mcm","clk":"5323130320","pt":1646327803205,"mc":[{"id":"1.195532875","rc":[{"atb":[[2.36,5.99]],"id":37306244}],"con":true,"img":false}]}
{"op":"mcm","clk":"5323130340","pt":1646327803415,"mc":[{"id":"1.195532875","rc":[{"atb":[[2.6,69.43],[2.58,25.32]],"id":35985721}],"con":true,"img":false}]}
{"op":"mcm","clk":"5323130447","pt":1646327804718,"mc":[{"id":"1.195532875","rc":[{"atl":[[6.4,27.78]],"id":37306244},{"atb":[[1.94,250]],"id":39614765},{"atb":[[1.71,250]],"id":40642034},{"atl":[[5,37.5]],"id":40642034},{"atl":[[2.9,0]],"id":40883678}],"con":true,"img":false}]}
{"op":"mcm","clk":"5323130465","pt":1646327804924,"mc":[{"id":"1.195532875","rc":[{"atb":[[2.36,2.5]],"id":37306244},{"atl":[[2.92,41.67],[2.98,50.51],[3.05,206.19]],"id":40883678}],"con":true,"img":false}]}
{"op":"mcm","clk":"5323130476","pt":1646327805040,"mc":[{"id":"1.195532875","rc":[{"atb":[[2.04,38.46],[2.1,0]],"id":37306244},{"atl":[[6.2,5],[5.9,10]],"id":37306244},{"atb":[[2.62,0]],"id":35985721},{"atb":[[1.86,0]],"id":39614765},{"atl":[[4.9,5],[4.7,0]],"id":40642034},{"atl":[[2.98,0],[2.94,0]],"id":40883678}],"con":true,"img":false}]}
{"op":"mcm","clk":"5323130486","pt":1646327805092,"mc":[{"id":"1.195532875","rc":[{"atl":[[4.8,31.72]],"id":40642034},{"atl":[[2.98,20.2]],"id":40883678}],"con":true,"img":false}]}
{"op":"mcm","clk":"5323130564","pt":1646327806022,"mc":[{"id":"1.195532875","rc":[{"atb":[[3.7,55.56]],"id":41469398},{"atl":[[12.5,13.04]],"id":41469398}],"con":true,"img":false}]}
{"op":"mcm","clk":"5323130609","pt":1646327806494,"mc":[{"id":"1.195532875","rc":[{"atb":[[2.06,0]],"id":37306244}],"con":true,"img":false}]}
{"op":"mcm","clk":"5323130627","pt":1646327806701,"mc":[{"id":"1.195532875","rc":[{"atl":[[4.8,26.32]],"id":40642034}],"con":true,"img":false}]}
{"op":"mcm","clk":"5323130634","pt":1646327806805,"mc":[{"id":"1.195532875","rc":[{"atb":[[2.56,64.1]],"id":35985721},{"atl":[[5.7,21.28]],"id":35985721}],"con":true,"img":false}]}
{"op":"mcm","clk":"5323130706","pt":1646327807794,"mc":[{"id":"1.195532875","rc":[{"atl":[[5.6,21.74]],"id":35985721},{"atl":[[2.96,20.41]],"id":40883678}],"con":true,"img":false}]}
{"op":"mcm","clk":"5323130773","pt":1646327808594,"mc":[{"id":"1.195532875","rc":[{"atb":[[2.44,13.14]],"id":37306244}],"con":true,"img":false}]}
{"op":"mcm","clk":"5323130791","pt":1646327808803,"mc":[{"id":"1.195532875","rc":[{"atb":[[2.52,1.65]],"id":37306244}],"con":true,"img":false}]}
{"op":"mcm","clk":"5323130875","pt":1646327809704,"mc":[{"id":"1.195532875","rc":[{"atl":[[2.86,10.7]],"id":40883678}],"con":true,"img":false}]}
{"op":"mcm","clk":"5323130883","pt":1646327809804,"mc":[{"id":"1.195532875","rc":[{"atl":[[2.92,0],[2.9,16.93]],"id":40883678}],"con":true,"img":false}]}
{"op":"mcm","clk":"5323130902","pt":1646327810015,"mc":[{"id":"1.195532875","rc":[{"atl":[[2.86,0]],"id":40883678}],"con":true,"img":false}]}
{"op":"mcm","clk":"5323130929","pt":1646327810224,"mc":[{"id":"1.195532875","rc":[{"atb":[[2.4,0],[2.42,13.96]],"id":37306244}],"con":true,"img":false}]}
{"op":"mcm","clk":"5323131035","pt":1646327811320,"mc":[{"id":"1.195532875","rc":[{"atb":[[2.6,26.99],[2.58,68.54]],"id":35985721}],"con":true,"img":false}]}
{"op":"mcm","clk":"5323131124","pt":1646327812212,"mc":[{"id":"1.195532875","rc":[{"atb":[[2.5,7.58],[2.42,36.32],[2.38,0]],"id":37306244},{"atl":[[2.98,101.42],[3.05,121.95]],"id":40883678}],"con":true,"img":false}]}
{"op":"mcm","clk":"5323131134","pt":1646327812317,"mc":[{"id":"1.195532875","rc":[{"atb":[[2.44,4.76]],"id":37306244}],"con":true,"img":false}]}
{"op":"mcm","clk":"5323131154","pt":1646327812528,"mc":[{"id":"1.195532875","rc":[{"atb":[[3.95,0]],"id":41469398}],"con":true,"img":false}]}
{"op":"mcm","clk":"5323131164","pt":1646327812627,"mc":[{"id":"1.195532875","rc":[{"atb":[[4.1,1.99]],"id":41469398}],"con":true,"img":false}]}
{"op":"mcm","clk":"5323131185","pt":1646327812797,"mc":[{"id":"1.195532875","rc":[{"atb":[[4.1,16.57]],"id":41469398},{"atb":[[2.6,25]],"id":35985721},{"atl":[[2.98,151.93],[3.05,73.17]],"id":40883678}],"con":true,"img":false}]}
{"op":"mcm","clk":"5323131196","pt":1646327812897,"mc":[{"id":"1.195532875","rc":[{"atb":[[4,1.65]],"id":41469398},{"atb":[[2.66,3.64]],"id":35985721}],"con":true,"img":false}]}
{"op":"mcm","clk":"5323131206","pt":1646327813009,"mc":[{"id":"1.195532875","rc":[{"atb":[[3.8,35.71],[3.9,43.97]],"id":41469398},{"atb":[[2.6,41.14],[2.58,25.32]],"id":35985721}],"con":true,"img":false}]}
{"op":"mcm","clk":"5323131217","pt":1646327813105,"mc":[{"id":"1.195532875","rc":[{"atb":[[3.95,13.56]],"id":41469398},{"atl":[[2.96,0],[2.94,20.62]],"id":40883678}],"con":true,"img":false}]}
{"op":"mcm","clk":"5323131227","pt":1646327813207,"mc":[{"id":"1.195532875","rc":[{"atb":[[2.44,0]],"id":37306244}],"con":true,"img":false}]}
{"op":"mcm","clk":"5323131251","pt":1646327813521,"mc":[{"id":"1.195532875","rc":[{"atl":[[2.98,169.41]],"id":40883678}],"con":true,"img":false}]}
{"op":"mcm","clk":"5323131354","pt":1646327814736,"mc":[{"id":"1.195532875","rc":[{"atl":[[5.2,59.52]],"id":40642034}],"con":true,"img":false}]}
{"op":"mcm","clk":"5323131364","pt":1646327814847,"mc":[{"id":"1.195532875","rc":[{"atl":[[2.98,151.93]],"id":40883678}],"con":true,"img":false}]}
{"op":"mcm","clk":"5323131389","pt":1646327815056,"mc":[{"id":"1.195532875","rc":[{"atb":[[2,100]],"id":37306244},{"atl":[[6.8,43.1]],"id":37306244}],"con":true,"img":false}]}
{"op":"mcm","clk":"5323131435","pt":1646327815526,"mc":[{"id":"1.195532875","rc":[{"atb":[[2.42,6.55]],"id":35985721},{"atl":[[5.7,25.63]],"id":35985721}],"con":true,"img":false}]}
{"op":"mcm","clk":"5323131469","pt":1646327815841,"mc":[{"id":"1.195532875","rc":[{"atb":[[2.38,12.93]],"id":37306244}],"con":true,"img":false}]}
{"op":"mcm","clk":"5323131497","pt":1646327816158,"mc":[{"id":"1.195532875","rc":[{"atb":[[2.42,0]],"id":35985721}],"con":true,"img":false}]}
{"op":"mcm","clk":"5323131550","pt":1646327816636,"mc":[{"id":"1.195532875","rc":[{"atb":[[4,0]],"id":41469398}],"con":true,"img":false}]}
{"op":"mcm","clk":"5323131560","pt":1646327816732,"mc":[{"id":"1.195532875","rc":[{"atl":[[5.7,21.28]],"id":35985721}],"con":true,"img":false}]}
{"op":"mcm","clk":"5323131568","pt":1646327816839,"mc":[{"id":"1.195532875","rc":[{"atb":[[4.2,1.65]],"id":41469398},{"atb":[[2.52,98.68]],"id":35985721},{"atl":[[5.9,30.61]],"id":35985721}],"con":true,"img":false}]}
{"op":"mcm","clk":"5323131770","pt":1646327818761,"mc":[{"id":"1.195532875","rc":[{"atb":[[2.58,0]],"id":35985721},{"atl":[[17.5,0]],"id":35985721},{"atb":[[1.84,0],[1.78,128.21]],"id":40642034},{"atb":[[1.63,63.49]],"id":40883678},{"atl":[[2.9,0]],"id":40883678}],"con":true,"img":false}]}
{"op":"mcm","clk":"5323131795","pt":1646327818920,"mc":[{"id":"1.195532875","rc":[{"atl":[[2.92,28.16],[2.98,20.2],[3.05,209.48]],"id":40883678}],"con":true,"img":false}]}
{"op":"mcm","clk":"5323131805","pt":1646327819076,"mc":[{"id":"1.195532875","rc":[{"atl":[[2.98,70.71],[3.05,160.7]],"id":40883678}],"con":true,"img":false}]}
{"op":"mcm","clk":"5323131821","pt":1646327819237,"mc":[{"id":"1.195532875","rc":[{"atl":[[2.96,20.41],[2.94,0]],"id":40883678}],"con":true,"img":false}]}
{"op":"mcm","clk":"5323131898","pt":1646327820031,"mc":[{"id":"1.195532875","rc":[{"atb":[[2.42,13.96],[2.38,40.67]],"id":37306244}],"con":true,"img":false}]}
{"op":"mcm","clk":"5323132068","pt":1646327821546,"mc":[{"id":"1.195532875","rc":[{"spn":2.52,"spf":1.0,"id":37306244},{"spn":4.2,"spf":1.0,"id":41469398},{"spn":2.63,"spf":1.0,"id":35985721},{"spn":2.48,"spf":1.0,"id":39614765},{"spn":3.28,"spf":"NaN","id":40642034},{"atl":[[2.88,36.43],[2.98,160.93],[3.05,73.17]],"id":40883678},{"spn":2.27,"spf":"NaN","id":40883678}],"con":true,"img":false}]}
{"op":"mcm","clk":"5323132086","pt":1646327821753,"mc":[{"id":"1.195532875","rc":[{"atl":[[2.92,0]],"id":40883678}],"con":true,"img":false}]}
{"op":"mcm","clk":"5323132228","pt":1646327823162,"mc":[{"id":"1.195532875","rc":[{"atb":[[3.85,35.09]],"id":41469398},{"atl":[[13.5,20]],"id":41469398}],"con":true,"img":false}]}
{"op":"mcm","clk":"5323132289","pt":1646327823736,"mc":[{"id":"1.195532875","rc":[{"atb":[[3.8,0],[3.7,0],[3.9,30.18]],"id":41469398},{"atb":[[2.52,11.24]],"id":39614765},{"atl":[[2.92,20.83],[2.96,0]],"id":40883678}],"con":true,"img":false}]}
{"op":"mcm","clk":"5323132302","pt":1646327823839,"mc":[{"id":"1.195532875","rc":[{"atb":[[2.52,3.64]],"id":39614765}],"con":true,"img":false}]}
{"op":"mcm","clk":"5323132316","pt":1646327823945,"mc":[{"id":"1.195532875","rc":[{"atb":[[2.5,8.79],[2.44,12.68]],"id":39614765},{"atb":[[1.57,250],[1.51,196.08]],"id":40883678}],"con":true,"img":false}]}
{"op":"mcm","clk":"5323132350","pt":1646327824328,"mc":[{"id":"1.195532875","rc":[{"atb":[[2.5,2.15]],"id":39614765}],"con":true,"img":false}]}
{"op":"mcm","clk":"5323132430","pt":1646327825061,"mc":[{"id":"1.195532875","rc":[{"atb":[[1.98,153.06]],"id":37306244}],"con":true,"img":false}]}
{"op":"mcm","clk":"5323132562","pt":1646327826549,"mc":[{"id":"1.195532875","rc":[{"atb":[[3.45,0],[3.25,0],[3.65,0]],"id":41469398},{"atb":[[2.42,0],[2.44,15.18],[2.26,11.18],[2.34,0]],"id":39614765},{"atb":[[1.98,0],[2.04,0],[2.28,2.5],[2.2,5]],"id":40642034},{"atl":[[3.45,0],[3.85,0],[3.65,0]],"id":40883678}],"con":true,"img":false}]}
{"op":"mcm","clk":"5323132571","pt":1646327826658,"mc":[{"id":"1.195532875","rc":[{"atl":[[2.86,42.94]],"id":40883678}],"con":true,"img":false}]}
{"op":"mcm","clk":"5323132585","pt":1646327826862,"mc":[{"id":"1.195532875","rc":[{"atb":[[2.48,168.92]],"id":35985721},{"atl":[[6.2,48.08]],"id":35985721},{"atl":[[2.92,72.91],[2.88,0],[2.98,110.42]],"id":40883678}],"con":true,"img":false}]}
{"op":"mcm","clk":"5323132607","pt":1646327827065,"mc":[{"id":"1.195532875","rc":[{"atb":[[2.14,0]],"id":40642034}],"con":true,"img":false}]}
{"op":"mcm","clk":"5323132616","pt":1646327827134,"mc":[{"id":"1.195532875","rc":[{"atb":[[2.3,1.99]],"id":40642034}],"con":true,"img":false}]}
{"op":"mcm","clk":"5323132792","pt":1646327829039,"mc":[{"id":"1.195532875","rc":[{"atb":[[2.06,0]],"id":40642034}],"con":true,"img":false}]}
{"op":"mcm","clk":"5323133004","pt":1646327831138,"mc":[{"id":"1.195532875","rc":[{"atb":[[3.95,22.77]],"id":41469398}],"con":true,"img":false}]}
{"op":"mcm","clk":"5323133059","pt":1646327831680,"mc":[{"id":"1.195532875","rc":[{"atb":[[3.95,13.56]],"id":41469398},{"atb":[[2.16,0]],"id":40642034}],"con":true,"img":false}]}
{"op":"mcm","clk":"5323133107","pt":1646327832039,"mc":[{"id":"1.195532875","rc":[{"atl":[[2.92,20.83],[2.98,160.93]],"id":40883678}],"con":true,"img":false}]}
{"op":"mcm","clk":"5323133199","pt":1646327833154,"mc":[{"id":"1.195532875","rc":[{"atb":[[3.75,54.55]],"id":41469398}],"con":true,"img":false}]}
{"op":"mcm","clk":"5323133253","pt":1646327833737,"mc":[{"id":"1.195532875","rc":[{"atl":[[2.92,0]],"id":40883678}],"con":true,"img":false}]}
{"op":"mcm","clk":"5323133266","pt":1646327833886,"mc":[{"id":"1.195532875","rc":[{"atl":[[3.6,10],[3.2,2.5],[2.9,21.05],[3.4,5],[3.05,164.2]],"id":40883678}],"con":true,"img":false}]}
{"op":"mcm","clk":"5323133280","pt":1646327833945,"mc":[{"id":"1.195532875","rc":[{"atb":[[2.52,11.24]],"id":39614765},{"atb":[[2.14,6.73]],"id":40642034},{"atl":[[2.98,70.71]],"id":40883678}],"con":true,"img":false}]}
{"op":"mcm","clk":"5323133294","pt":1646327834053,"mc":[{"id":"1.195532875","rc":[{"atl":[[3.05,73.17]],"id":40883678}],"con":true,"img":false}]}
{"op":"mcm","clk":"5323133403","pt":1646327834952,"mc":[{"id":"1.195532875","rc":[{"atl":[[2.86,0]],"id":40883678}],"con":true,"img":false}]}
{"op":"mcm","clk":"5323133409","pt":1646327835045,"mc":[{"id":"1.195532875","rc":[{"atb":[[1.96,250],[1.99,0],[2.02,0]],"id":37306244},{"atl":[[2.88,42.55]],"id":40883678}],"con":true,"img":false}]}
{"op":"mcm","clk":"5323133439","pt":1646327835357,"mc":[{"id":"1.195532875","rc":[{"atl":[[2.86,43.01],[2.98,164.23]],"id":40883678}],"con":true,"img":false}]}
{"op":"mcm","clk":"5323133460","pt":1646327835564,"mc":[{"id":"1.195532875","rc":[{"atl":[[2.88,0]],"id":40883678}],"con":true,"img":false}]}
{"op":"mcm","clk":"5323133585","pt":1646327836875,"mc":[{"id":"1.195532875","rc":[{"atb":[[2.4,2.49]],"id":35985721},{"atl":[[16.5,0]],"id":35985721}],"con":true,"img":false}]}
{"op":"mcm","clk":"5323133869","pt":1646327839667,"mc":[{"id":"1.195532875","rc":[{"atb":[[2.32,1.65]],"id":40642034}],"con":true,"img":false}]}
{"op":"mcm","clk":"5323134144","pt":1646327842662,"mc":[{"id":"1.195532875","rc":[{"atb":[[2.14,0]],"id":40642034}],"con":true,"img":false}]}
{"op":"mcm","clk":"5323134186","pt":1646327843174,"mc":[{"id":"1.195532875","rc":[{"atb":[[3.65,94.34]],"id":41469398}],"con":true,"img":false}]}
{"op":"mcm","clk":"5323134245","pt":1646327843789,"mc":[{"id":"1.195532875","rc":[{"atl":[[2.94,51.55]],"id":40883678}],"con":true,"img":false}]}
{"op":"mcm","clk":"5323134267","pt":1646327843979,"mc":[{"id":"1.195532875","rc":[{"atl":[[2.92,52.08],[2.98,20.2],[2.94,148.43]],"id":40883678}],"con":true,"img":false}]}
{"op":"mcm","clk":"5323134311","pt":1646327844352,"mc":[{"id":"1.195532875","rc":[{"atb":[[2.26,3.05]],"id":37306244}],"con":true,"img":false}]}
{"op":"mcm","clk":"5323134354","pt":1646327844761,"mc":[{"id":"1.195532875","rc":[{"atb":[[2.26,0]],"id":37306244}],"con":true,"img":false}]}
{"op":"mcm","clk":"5323134390","pt":1646327845088,"mc":[{"id":"1.195532875","rc":[{"atb":[[4.1,1.99]],"id":41469398},{"atl":[[4.3,0]],"id":40883678}],"con":true,"img":false}]}
{"op":"mcm","clk":"5323134427","pt":1646327845455,"mc":[{"id":"1.195532875","rc":[{"atb":[[4.1,0]],"id":41469398}],"con":true,"img":false}]}
{"op":"mcm","clk":"5323134435","pt":1646327845550,"mc":[{"id":"1.195532875","rc":[{"atb":[[4,18.97],[3.85,91.84],[3.9,0]],"id":41469398}],"con":true,"img":false}]}
{"op":"mcm","clk":"5323134611","pt":1646327847355,"mc":[{"id":"1.195532875","rc":[{"atb":[[2.22,4.37]],"id":40642034}],"con":true,"img":false}]}
{"op":"mcm","clk":"5323134641","pt":1646327847671,"mc":[{"id":"1.195532875","rc":[{"atb":[[4.2,0]],"id":41469398}],"con":true,"img":false}]}
{"op":"mcm","clk":"5323134663","pt":1646327847879,"mc":[{"id":"1.195532875","rc":[{"atb":[[4.1,1.65],[3.8,2.5]],"id":41469398}],"con":true,"img":false}]}
{"op":"mcm","clk":"5323134857","pt":1646327849970,"mc":[{"id":"1.195532875","rc":[{"atl":[[2.92,151.1],[2.94,51.55]],"id":40883678}],"con":true,"img":false}]}
{"op":"mcm","clk":"5323135183","pt":1646327853801,"mc":[{"id":"1.195532875","rc":[{"atl":[[2.98,75.76]],"id":40883678}],"con":true,"img":false}]}
{"op":"mcm","clk":"5323135632","pt":1646327858562,"mc":[{"id":"1.195532875","rc":[{"atb":[[2.62,9.15]],"id":35985721}],"con":true,"img":false}]}
{"op":"mcm","clk":"5323135642","pt":1646327858673,"mc":[{"id":"1.195532875","rc":[{"atb":[[2.6,25],[2.62,25.15]],"id":35985721}],"con":true,"img":false}]}
{"op":"mcm","clk":"5323135651","pt":1646327858779,"mc":[{"id":"1.195532875","rc":[{"atb":[[2.62,16]],"id":35985721}],"con":true,"img":false}]}
{"op":"mcm","clk":"5323135912","pt":1646327861383,"mc":[{"id":"1.195532875","rc":[{"atb":[[4.1,18.64]],"id":41469398}],"con":true,"img":false}]}
{"op":"mcm","clk":"5323135930","pt":1646327861548,"mc":[{"id":"1.195532875","rc":[{"atb":[[4,1.99],[3.85,35.09],[3.95,53.82]],"id":41469398}],"con":true,"img":false}]}
{"op":"mcm","clk":"5323135956","pt":1646327861858,"mc":[{"id":"1.195532875","rc":[{"atb":[[4,0]],"id":41469398}],"con":true,"img":false}]}
{"op":"mcm","clk":"5323135964","pt":1646327861957,"mc":[{"id":"1.195532875","rc":[{"atb":[[4.2,1.99]],"id":41469398}],"con":true,"img":false}]}
{"op":"mcm","clk":"5323136091","pt":1646327863660,"mc":[{"id":"1.195532875","rc":[{"atb":[[4.1,16.99]],"id":41469398}],"con":true,"img":false}]}
{"op":"mcm","clk":"5323136100","pt":1646327863768,"mc":[{"id":"1.195532875","rc":[{"atl":[[3.05,121.95]],"id":40883678}],"con":true,"img":false}]}
{"op":"mcm","clk":"5323136109","pt":1646327863867,"mc":[{"id":"1.195532875","rc":[{"atb":[[4.3,1.65]],"id":41469398}],"con":true,"img":false}]}
{"op":"mcm","clk":"5323136124","pt":1646327864076,"mc":[{"id":"1.195532875","rc":[{"atb":[[3.9,6.78]],"id":41469398}],"con":true,"img":false}]}
{"op":"mcm","clk":"5323136146","pt":1646327864283,"mc":[{"id":"1.195532875","rc":[{"atb":[[3.9,0]],"id":41469398}],"con":true,"img":false}]}
{"op":"mcm","clk":"5323137665","pt":1646327880575,"mc":[{"id":"1.195532875","rc":[{"atl":[[5.6,27.29]],"id":35985721},{"atl":[[4.8,32.57]],"id":40642034},{"atl":[[2.94,64.57]],"id":40883678}],"con":true,"img":false}]}
{"op":"mcm","clk":"5323137675","pt":1646327880682,"mc":[{"id":"1.195532875","rc":[{"atl":[[6.6,22.49]],"id":39614765}],"con":true,"img":false}]}
{"op":"mcm","clk":"5323137684","pt":1646327880782,"mc":[{"id":"1.195532875","rc":[{"atl":[[5.6,8.59]],"id":37306244},{"atl":[[4.5,4.5]],"id":40642034}],"con":true,"img":false}]}
{"op":"mcm","clk":"5323137692","pt":1646327880891,"mc":[{"id":"1.195532875","rc":[{"atl":[[5.5,8.59]],"id":37306244}],"con":true,"img":false}]}
{"op":"mcm","clk":"5323137701","pt":1646327880993,"mc":[{"id":"1.195532875","rc":[{"atl":[[5.9,0]],"id":37306244}],"con":true,"img":false}]}
{"op":"mcm","clk":"5323137712","pt":1646327881096,"mc":[{"id":"1.195532875","rc":[{"atl":[[5.8,8.33],[5.9,4.16],[5.4,12.14],[5.7,38.18]],"id":37306244},{"atl":[[5.6,21.74]],"id":35985721},{"atl":[[6.6,17.86]],"id":39614765},{"atl":[[4.8,26.32]],"id":40642034},{"atl":[[2.94,51.55]],"id":40883678}],"con":true,"img":false}]}
{"op":"mcm","clk":"5323137723","pt":1646327881199,"mc":[{"id":"1.195532875","rc":[{"atl":[[5.6,3.85]],"id":37306244}],"con":true,"img":false}]}
{"op":"mcm","clk":"5323137757","pt":1646327881625,"mc":[{"id":"1.195532875","rc":[{"atl":[[5.9,0]],"id":37306244},{"spn":4.3,"spf":1.0,"id":41469398},{"spn":2.64,"spf":1.0,"id":35985721},{"spn":2.52,"spf":1.0,"id":39614765},{"spn":3.36,"spf":"NaN","id":40642034},{"spn":2.26,"spf":"NaN","id":40883678}],"con":true,"img":false}]}
{"op":"mcm","clk":"5323137833","pt":1646327882408,"mc":[{"id":"1.195532875","rc":[{"atl":[[5.6,12.55],[5.8,0]],"id":37306244},{"atl":[[6.4,0],[5.8,0],[5.3,11.76],[5.4,0]],"id":35985721}],"con":true,"img":false}]}
{"op":"mcm","clk":"5323137852","pt":1646327882572,"mc":[{"id":"1.195532875","rc":[{"atl":[[5.6,77.26],[5.5,8.89]],"id":35985721}],"con":true,"img":false}]}
{"op":"mcm","clk":"5323137863","pt":1646327882675,"mc":[{"id":"1.195532875","rc":[{"atl":[[4.5,2.5]],"id":40642034}],"con":true,"img":false}]}
{"op":"mcm","clk":"5323137878","pt":1646327882883,"mc":[{"id":"1.195532875","rc":[{"atl":[[5.6,8.7]],"id":37306244}],"con":true,"img":false}]}
{"op":"mcm","clk":"5323137909","pt":1646327883195,"mc":[{"id":"1.195532875","rc":[{"atl":[[5.6,11.55]],"id":37306244}],"con":true,"img":false}]}
{"op":"mcm","clk":"5323137949","pt":1646327883614,"mc":[{"id":"1.195532875","rc":[{"atl":[[4.6,45.97]],"id":40642034}],"con":true,"img":false}]}
{"op":"mcm","clk":"5323138057","pt":1646327884609,"mc":[{"id":"1.195532875","rc":[{"atb":[[2.38,27.74]],"id":37306244}],"con":true,"img":false}]}
{"op":"mcm","clk":"5323138346","pt":1646327887731,"mc":[{"id":"1.195532875","rc":[{"atb":[[2.56,70.16]],"id":35985721}],"con":true,"img":false}]}
{"op":"mcm","clk":"5323138382","pt":1646327888108,"mc":[{"id":"1.195532875","rc":[{"atb":[[2.56,64.1]],"id":35985721}],"con":true,"img":false}]}
{"op":"mcm","clk":"5323138430","pt":1646327888588,"mc":[{"id":"1.195532875","rc":[{"atb":[[1.08,50]],"id":37306244},{"atb":[[1.08,50]],"id":41469398},{"atb":[[1.08,50]],"id":35985721},{"atb":[[1.08,50]],"id":39614765},{"atb":[[1.08,50]],"id":40642034},{"atb":[[1.08,50]],"id":40883678}],"con":true,"img":false}]}
{"op":"mcm","clk":"5323138509","pt":1646327889335,"mc":[{"id":"1.195532875","rc":[{"atb":[[2.3,4.49],[2.22,9.37],[2.12,0],[2.28,0],[2.2,0]],"id":40642034}],"con":true,"img":false}]}
{"op":"mcm","clk":"5323138522","pt":1646327889442,"mc":[{"id":"1.195532875","rc":[{"atb":[[2.44,10.16]],"id":37306244}],"con":true,"img":false}]}
{"op":"mcm","clk":"5323138535","pt":1646327889492,"mc":[{"id":"1.195532875","rc":[{"atb":[[1.85,40.29]],"id":40642034}],"con":true,"img":false}]}
{"op":"mcm","clk":"5323138546","pt":1646327889597,"mc":[{"id":"1.195532875","rc":[{"atb":[[2.42,41.1],[2.38,0]],"id":37306244}],"con":true,"img":false}]}
{"op":"mcm","clk":"5323138555","pt":1646327889709,"mc":[{"id":"1.195532875","rc":[{"atb":[[2.4,4.23]],"id":37306244}],"con":true,"img":false}]}
{"op":"mcm","clk":"5323138593","pt":1646327890130,"mc":[{"id":"1.195532875","rc":[{"atb":[[2.4,0]],"id":37306244}],"con":true,"img":false}]}
{"op":"mcm","clk":"5323138733","pt":1646327891600,"mc":[{"id":"1.195532875","rc":[{"atb":[[2.22,5]],"id":40642034}],"con":true,"img":false}]}
{"op":"mcm","clk":"5323138824","pt":1646327892495,"mc":[{"id":"1.195532875","rc":[{"atb":[[3.8,6.89]],"id":41469398}],"con":true,"img":false}]}
{"op":"mcm","clk":"5323138837","pt":1646327892723,"mc":[{"id":"1.195532875","rc":[{"atb":[[3.8,2.5]],"id":41469398}],"con":true,"img":false}]}
{"op":"mcm","clk":"5323138888","pt":1646327893426,"mc":[{"id":"1.195532875","rc":[{"atl":[[5.8,20.83]],"id":37306244}],"con":true,"img":false}]}
{"op":"mcm","clk":"5323139098","pt":1646327896206,"mc":[{"id":"1.195532875","rc":[{"atl":[[5.6,54.97],[5.7,2.5]],"id":37306244}],"con":true,"img":false}]}
{"op":"mcm","clk":"5323139106","pt":1646327896322,"mc":[{"id":"1.195532875","rc":[{"atb":[[2.52,15.52]],"id":37306244},{"atl":[[5.6,75.8],[5.5,0]],"id":37306244},{"atb":[[4.3,7.13]],"id":41469398},{"atb":[[2.68,5.47]],"id":35985721},{"atb":[[2.28,36.77]],"id":39614765},{"atb":[[1.86,54.72]],"id":40642034},{"atb":[[1.67,8.21]],"id":40883678}],"con":true,"img":false}]}
{"op":"mcm","clk":"5323139114","pt":1646327896409,"mc":[{"id":"1.195532875","rc":[{"atb":[[1.86,77.46]],"id":40642034}],"con":true,"img":false}]}
{"op":"mcm","clk":"5323139128","pt":1646327896531,"mc":[{"id":"1.195532875","rc":[{"atb":[[2.54,16.73]],"id":37306244},{"atl":[[5.4,0]],"id":37306244},{"atb":[[2.62,0]],"id":35985721}],"con":true,"img":false}]}
{"op":"mcm","clk":"5323139145","pt":1646327896717,"mc":[{"id":"1.195532875","rc":[{"atb":[[2.5,2.15]],"id":37306244},{"atl":[[5.5,14.8]],"id":37306244}],"con":true,"img":false}]}
{"op":"mcm","clk":"5323139161","pt":1646327896928,"mc":[{"id":"1.195532875","rc":[{"atb":[[2.5,0],[2.6,2.15]],"id":37306244}],"con":true,"img":false}]}
{"op":"mcm","clk":"5323139196","pt":1646327897300,"mc":[{"id":"1.195532875","rc":[{"atb":[[4.2,0]],"id":41469398}],"con":true,"img":false}]}
{"op":"mcm","clk":"5323139205","pt":1646327897404,"mc":[{"id":"1.195532875","rc":[{"atb":[[4.4,1.99]],"id":41469398}],"con":true,"img":false}]}
{"op":"mcm","clk":"5323139223","pt":1646327897618,"mc":[{"id":"1.195532875","rc":[{"atb":[[2.66,1.65]],"id":35985721}],"con":true,"img":false}]}
{"op":"mcm","clk":"5323139235","pt":1646327897711,"mc":[{"id":"1.195532875","rc":[{"atb":[[2.7,1.99]],"id":35985721}],"con":true,"img":false}]}
{"op":"mcm","clk":"5323139244","pt":1646327897815,"mc":[{"id":"1.195532875","rc":[{"atb":[[2.6,50.81]],"id":35985721}],"con":true,"img":false}]}
{"op":"mcm","clk":"5323139252","pt":1646327897918,"mc":[{"id":"1.195532875","rc":[{"atb":[[4.1,20.49]],"id":41469398}],"con":true,"img":false}]}
{"op":"mcm","clk":"5323139268","pt":1646327898124,"mc":[{"id":"1.195532875","rc":[{"atb":[[4.1,16.99]],"id":41469398}],"con":true,"img":false}]}
{"op":"mcm","clk":"5323139280","pt":1646327898282,"mc":[{"id":"1.195532875","rc":[{"atl":[[5.7,11.01]],"id":37306244}],"con":true,"img":false}]}
{"op":"mcm","clk":"5323139287","pt":1646327898388,"mc":[{"id":"1.195532875","rc":[{"atl":[[5.6,67.1],[6.4,0],[5.8,0],[6,0],[6.8,0]],"id":37306244},{"atl":[[2.86,0]],"id":40883678}],"con":true,"img":false}]}
{"op":"mcm","clk":"5323139296","pt":1646327898492,"mc":[{"id":"1.195532875","rc":[{"atl":[[2.92,52.08],[2.94,161.7]],"id":40883678}],"con":true,"img":false}]}
{"op":"mcm","clk":"5323139304","pt":1646327898598,"mc":[{"id":"1.195532875","rc":[{"atb":[[2.44,0]],"id":37306244},{"atl":[[2.92,55.24],[2.88,21.94],[2.94,213.25]],"id":40883678}],"con":true,"img":false}]}
{"op":"mcm","clk":"5323139312","pt":1646327898701,"mc":[{"id":"1.195532875","rc":[{"atl":[[2.92,0]],"id":40883678}],"con":true,"img":false}]}
{"op":"mcm","clk":"5323139463","pt":1646327900319,"mc":[{"id":"1.195532875","rc":[{"atl":[[2.92,20.83],[2.9,0]],"id":40883678}],"con":true,"img":false}]}
{"op":"mcm","clk":"5323139581","pt":1646327901627,"mc":[{"id":"1.195532875","rc":[{"atb":[[2.52,1.65]],"id":37306244}],"con":true,"img":false}]}
{"op":"mcm","clk":"5323139641","pt":1646327902296,"mc":[{"id":"1.195532875","rc":[{"atl":[[5.6,69.6],[6.2,0],[6,5],[5.7,8.51],[7,0]],"id":37306244}],"con":true,"img":false}]}
{"op":"mcm","clk":"5323139649","pt":1646327902413,"mc":[{"id":"1.195532875","rc":[{"atl":[[5.6,48.77],[5.7,29.79]],"id":37306244}],"con":true,"img":false}]}
{"op":"mcm","clk":"5323139725","pt":1646327903193,"mc":[{"id":"1.195532875","rc":[{"atl":[[5.6,5.35],[5.7,87.18]],"id":37306244}],"con":true,"img":false}]}
{"op":"mcm","clk":"5323139737","pt":1646327903300,"mc":[{"id":"1.195532875","rc":[{"atl":[[5.4,2.15]],"id":37306244},{"atl":[[5.2,2.34]],"id":35985721},{"atb":[[2.44,12.68],[2.48,5],[2.56,2.5],[2.4,10]],"id":39614765},{"atl":[[5.9,1.76]],"id":39614765},{"atl":[[4.3,3.61]],"id":40642034},{"atl":[[2.86,1.9]],"id":40883678}],"con":true,"img":false}]}
{"op":"mcm","clk":"5323139755","pt":1646327903506,"mc":[{"id":"1.195532875","rc":[{"atb":[[2.36,0],[2.28,0],[2.2,0]],"id":37306244},{"atl":[[5.6,2.5]],"id":37306244},{"atb":[[4.1,0]],"id":41469398},{"atb":[[2.5,35.18]],"id":35985721},{"atl":[[5.6,0],[5.1,5.86],[5.5,32.7],[5.4,9.09]],"id":35985721},{"atb":[[2.5,15.59],[2.44,0],[2.56,6.25]],"id":39614765},{"atl":[[6.4,20.28],[6.6,0],[5.9,8.01]],"id":39614765},{"atl":[[4.5,31.43],[4.6,14.11],[4.2,9.13]],"id":40642034}],"con":true,"img":false}]}
{"op":"mcm","clk":"5323139763","pt":1646327903622,"mc":[{"id":"1.195532875","rc":[{"atb":[[2.54,0],[2.42,0],[2.52,0],[2.1,90.91]],"id":37306244},{"atl":[[5.6,11.2]],"id":37306244},{"atb":[[3.6,0],[4.3,5.47],[3.95,13.56],[3.15,46.51]],"id":41469398},{"atb":[[2.32,0],[2.4,0],[2.24,0],[2.46,9.26],[2.66,0],[2.7,7.85]],"id":35985721},{"atl":[[5.3,2.5],[5.2,11.23]],"id":35985721},{"atb":[[2.5,21.39],[2.56,2.5],[2.52,1.99]],"id":39614765},{"atl":[[6.2,10.19],[6,0]],"id":39614765},{"atb":[[1.78,0],[1.71,353.9]],"id":40642034},{"atl":[[4.6,3],[4.4,0]],"id":40642034},{"atl":[[2.92,0],[2.9,21.05]],"id":40883678}],"con":true,"img":false}]}
{"op":"mcm","clk":"5323139772","pt":1646327903716,"mc":[{"id":"1.195532875","rc":[{"atb":[[3.85,90.35]],"id":41469398},{"atb":[[2.52,0]],"id":39614765},{"atl":[[6.4,0],[6.2,39.19]],"id":39614765}],"con":true,"img":false}]}
{"op":"mcm","clk":"5323139781","pt":1646327903829,"mc":[{"id":"1.195532875","rc":[{"atb":[[2.04,40.96],[2.62,1.65]],"id":37306244},{"atb":[[2.72,1.65],[2.46,0]],"id":35985721},{"atb":[[2.58,3.64]],"id":39614765},{"atl":[[4.8,29.58]],"id":40642034}],"con":true,"img":false}]}
{"op":"mcm","clk":"5323139791","pt":1646327903931,"mc":[{"id":"1.195532875","rc":[{"atl":[[5.3,11.8],[5.4,0]],"id":35985721},{"atb":[[2.3,21.37]],"id":39614765},{"atl":[[6.2,10.19]],"id":39614765},{"atl":[[4.5,20],[4.4,11.76]],"id":40642034}],"con":true,"img":false}]}
{"op":"mcm","clk":"5323139808","pt":1646327904136,"mc":[{"id":"1.195532875","rc":[{"atb":[[2.5,15.59]],"id":39614765}],"con":true,"img":false}]}
{"op":"mcm","clk":"5323139826","pt":1646327904320,"mc":[{"id":"1.195532875","rc":[{"atl":[[5.5,19.65]],"id":37306244},{"atl":[[4.8,26.32]],"id":40642034}],"con":true,"img":false}]}
{"op":"mcm","clk":"5323139834","pt":1646327904407,"mc":[{"id":"1.195532875","rc":[{"atb":[[1.67,1.99]],"id":40883678}],"con":true,"img":false}]}
{"op":"mcm","clk":"5323139843","pt":1646327904511,"mc":[{"id":"1.195532875","rc":[{"atb":[[1.85,20.88],[1.86,96.56]],"id":40642034}],"con":true,"img":false}]}
{"op":"mcm","clk":"5323139851","pt":1646327904609,"mc":[{"id":"1.195532875","rc":[{"atb":[[2.04,79.52]],"id":37306244}],"con":true,"img":false}]}
{"op":"mcm","clk":"5323139860","pt":1646327904715,"mc":[{"id":"1.195532875","rc":[{"atl":[[5.5,14.8]],"id":37306244}],"con":true,"img":false}]}
{"op":"mcm","clk":"5323139888","pt":1646327905029,"mc":[{"id":"1.195532875","rc":[{"atl":[[5.4,6.15]],"id":37306244}],"con":true,"img":false}]}
{"op":"mcm","clk":"5323139954","pt":1646327905605,"mc":[{"id":"1.195532875","rc":[{"atl":[[2.86,22.95],[2.94,161.7]],"id":40883678}],"con":true,"img":false}]}
{"op":"mcm","clk":"5323139991","pt":1646327906014,"mc":[{"id":"1.195532875","rc":[{"atb":[[1.86,73.82]],"id":40642034}],"con":true,"img":false}]}
{"op":"mcm","clk":"5323140146","pt":1646327907638,"mc":[{"id":"1.195532875","rc":[{"atb":[[2.6,0],[2.16,2.15]],"id":37306244}],"con":true,"img":false}]}
{"op":"mcm","clk":"5323140163","pt":1646327907844,"mc":[{"id":"1.195532875","rc":[{"atb":[[2.16,15.16]],"id":37306244}],"con":true,"img":false}]}
{"op":"mcm","clk":"5323140173","pt":1646327907951,"mc":[{"id":"1.195532875","rc":[{"atb":[[4.3,0]],"id":41469398},{"atb":[[2.68,0]],"id":35985721},{"atb":[[2.28,0]],"id":39614765},{"atb":[[1.86,19.1]],"id":40642034}],"con":true,"img":false}]}
{"op":"mcm","clk":"5323140182","pt":1646327908008,"mc":[{"id":"1.195532875","rc":[{"atb":[[2.06,32.42]],"id":37306244}],"con":true,"img":false}]}
{"op":"mcm","clk":"5323140213","pt":1646327908424,"mc":[{"id":"1.195532875","rc":[{"atb":[[2.3,0]],"id":39614765}],"con":true,"img":false}]}
{"op":"mcm","clk":"5323140228","pt":1646327908637,"mc":[{"id":"1.195532875","rc":[{"atb":[[2.1,103.05]],"id":37306244}],"con":true,"img":false}]}
{"op":"mcm","clk":"5323140240","pt":1646327908842,"mc":[{"id":"1.195532875","rc":[{"atb":[[2.1,90.91]],"id":37306244}],"con":true,"img":false}]}
{"op":"mcm","clk":"5323140251","pt":1646327908939,"mc":[{"id":"1.195532875","rc":[{"atb":[[4,16.99],[3.15,0],[3.5,40]],"id":41469398}],"con":true,"img":false}]}
{"op":"mcm","clk":"5323140260","pt":1646327909033,"mc":[{"id":"1.195532875","rc":[{"atb":[[2.7,1.99]],"id":35985721}],"con":true,"img":false}]}
{"op":"mcm","clk":"5323140286","pt":1646327909323,"mc":[{"id":"1.195532875","rc":[{"atl":[[5.3,11.2]],"id":37306244}],"con":true,"img":false}]}
{"op":"mcm","clk":"5323140294","pt":1646327909424,"mc":[{"id":"1.195532875","rc":[{"atl":[[5.7,65.9]],"id":37306244}],"con":true,"img":false}]}
{"op":"mcm","clk":"5323140317","pt":1646327909733,"mc":[{"id":"1.195532875","rc":[{"atl":[[5.5,23.69]],"id":37306244}],"con":true,"img":false}]}
{"op":"mcm","clk":"5323140336","pt":1646327909934,"mc":[{"id":"1.195532875","rc":[{"atl":[[4.6,0]],"id":40642034}],"con":true,"img":false}]}
{"op":"mcm","clk":"5323140399","pt":1646327910535,"mc":[{"id":"1.195532875","rc":[{"atb":[[2.32,32.43],[2.1,0]],"id":37306244}],"con":true,"img":false}]}
{"op":"mcm","clk":"5323140431","pt":1646327910949,"mc":[{"id":"1.195532875","rc":[{"atb":[[2.12,16.82]],"id":37306244},{"atb":[[1.67,8.21]],"id":40883678}],"con":true,"img":false}]}
{"op":"mcm","clk":"5323140438","pt":1646327911047,"mc":[{"id":"1.195532875","rc":[{"atl":[[5.5,84.19],[5.7,8.51]],"id":37306244}],"con":true,"img":false}]}
{"op":"mcm","clk":"5323140460","pt":1646327911214,"mc":[{"id":"1.195532875","rc":[{"atl":[[5.4,2.15]],"id":37306244}],"con":true,"img":false}]}
{"op":"mcm","clk":"5323140470","pt":1646327911321,"mc":[{"id":"1.195532875","rc":[{"atb":[[2.32,52.21]],"id":37306244},{"atl":[[5.3,0],[5.4,24.55]],"id":37306244}],"con":true,"img":false}]}
{"op":"mcm","clk":"5323140490","pt":1646327911534,"mc":[{"id":"1.195532875","rc":[{"atb":[[2.16,2.15]],"id":37306244},{"atl":[[5.6,15.14],[5.5,88.65],[5.3,18.6],[5.4,2.15]],"id":37306244}],"con":true,"img":false}]}
{"op":"mcm","clk":"5323140501","pt":1646327911631,"mc":[{"id":"1.195532875","rc":[{"atb":[[2.62,0]],"id":37306244}],"con":true,"img":false}]}
{"op":"mcm","clk":"5323140512","pt":1646327911742,"mc":[{"id":"1.195532875","rc":[{"atb":[[2.34,1.65]],"id":37306244},{"atl":[[5.6,11.2],[5.5,73.85]],"id":37306244},{"atb":[[4.5,1.65]],"id":41469398}],"con":true,"img":false}]}
{"op":"mcm","clk":"5323140581","pt":1646327912542,"mc":[{"id":"1.195532875","rc":[{"atl":[[5.2,2]],"id":37306244}],"con":true,"img":false}]}
{"op":"mcm","clk":"5323140635","pt":1646327913227,"mc":[{"id":"1.195532875","rc":[{"atl":[[2.9,107.03],[2.94,51.55]],"id":40883678}],"con":true,"img":false}]}
{"op":"mcm","clk":"5323140645","pt":1646327913324,"mc":[{"id":"1.195532875","rc":[{"atl":[[4.5,23]],"id":40642034}],"con":true,"img":false}]}
{"op":"mcm","clk":"5323140650","pt":1646327913431,"mc":[{"id":"1.195532875","rc":[{"atl":[[2.8,32.24],[2.88,31.4]],"id":40883678}],"con":true,"img":false}]}
{"op":"mcm","clk":"5323140663","pt":1646327913544,"mc":[{"id":"1.195532875","rc":[{"atb":[[4.4,0]],"id":41469398},{"atb":[[1.87,22.12]],"id":40642034}],"con":true,"img":false}]}
{"op":"mcm","clk":"5323140674","pt":1646327913656,"mc":[{"id":"1.195532875","rc":[{"atl":[[5.4,11.24]],"id":37306244},{"atb":[[4,18.97]],"id":41469398},{"atl":[[2.84,21.74],[2.88,9.46],[2.86,1.9],[2.9,85.98],[2.78,31.4]],"id":40883678}],"con":true,"img":false}]}
{"op":"mcm","clk":"5323140683","pt":1646327913754,"mc":[{"id":"1.195532875","rc":[{"atl":[[2.88,0]],"id":40883678}],"con":true,"img":false}]}
{"op":"mcm","clk":"5323140699","pt":1646327913856,"mc":[{"id":"1.195532875","rc":[{"atb":[[1.02,0]],"id":37306244}],"con":true,"img":false}]}
{"op":"mcm","clk":"5323140705","pt":1646327913925,"mc":[{"id":"1.195532875","rc":[{"atb":[[2.18,1.99]],"id":37306244}],"con":true,"img":false}]}
{"op":"mcm","clk":"5323140725","pt":1646327914137,"mc":[{"id":"1.195532875","rc":[{"atl":[[6.6,17.86]],"id":39614765},{"atl":[[2.82,21.98],[2.84,0]],"id":40883678}],"con":true,"img":false}]}
{"op":"mcm","clk":"5323140764","pt":1646327914546,"mc":[{"id":"1.195532875","rc":[{"atl":[[5.5,54.92]],"id":35985721},{"atl":[[4.6,27.78]],"id":40642034}],"con":true,"img":false}]}
{"op":"mcm","clk":"5323140783","pt":1646327914716,"mc":[{"id":"1.195532875","rc":[{"atl":[[16.5,0]],"id":39614765}],"con":true,"img":false}]}
{"op":"mcm","clk":"5323140800","pt":1646327914941,"mc":[{"id":"1.195532875","rc":[{"atb":[[2.18,0]],"id":37306244}],"con":true,"img":false}]}
{"op":"mcm","clk":"5323140811","pt":1646327915029,"mc":[{"id":"1.195532875","rc":[{"atb":[[1.02,1.99]],"id":37306244}],"con":true,"img":false}]}
{"op":"mcm","clk":"5323140938","pt":1646327916337,"mc":[{"id":"1.195532875","rc":[{"atb":[[4.1,15.18]],"id":41469398},{"atb":[[2.62,10.03]],"id":35985721},{"atb":[[2.52,9.12]],"id":39614765},{"atb":[[1.87,75.9]],"id":40642034}],"con":true,"img":false}]}
{"op":"mcm","clk":"5323140959","pt":1646327916550,"mc":[{"id":"1.195532875","rc":[{"atb":[[2.6,25],[2.62,29.91]],"id":35985721}],"con":true,"img":false}]}
{"op":"mcm","clk":"5323141041","pt":1646327917446,"mc":[{"id":"1.195532875","rc":[{"atl":[[6.2,0]],"id":35985721},{"atl":[[5.2,0]],"id":40642034}],"con":true,"img":false}]}
{"op":"mcm","clk":"5323141072","pt":1646327917841,"mc":[{"id":"1.195532875","rc":[{"atl":[[5.5,13.35],[5.4,67.38]],"id":37306244}],"con":true,"img":false}]}
{"op":"mcm","clk":"5323141089","pt":1646327918031,"mc":[{"id":"1.195532875","rc":[{"atb":[[2.5,13.44],[2.58,5.8]],"id":39614765}],"con":true,"img":false}]}
{"op":"mcm","clk":"5323141098","pt":1646327918140,"mc":[{"id":"1.195532875","rc":[{"atl":[[4.4,42.32]],"id":40642034}],"con":true,"img":false}]}
{"op":"mcm","clk":"5323141107","pt":1646327918244,"mc":[{"id":"1.195532875","rc":[{"atl":[[5.3,45.98],[5.5,22.22]],"id":35985721},{"atb":[[2.5,0],[2.52,30.54]],"id":39614765},{"atl":[[4.5,5.5]],"id":40642034}],"con":true,"img":false}]}
{"op":"mcm","clk":"5323141113","pt":1646327918350,"mc":[{"id":"1.195532875","rc":[{"atl":[[5.5,0],[5.2,20.6]],"id":37306244},{"atl":[[5.3,50.38]],"id":35985721}],"con":true,"img":false}]}
{"op":"mcm","clk":"5323141119","pt":1646327918448,"mc":[{"id":"1.195532875","rc":[{"atb":[[2.12,0]],"id":37306244},{"atb":[[3.95,51.57]],"id":41469398},{"atl":[[6.6,52.14]],"id":39614765}],"con":true,"img":false}]}
{"op":"mcm","clk":"5323141125","pt":1646327918552,"mc":[{"id":"1.195532875","rc":[{"atb":[[3.85,35.09]],"id":41469398},{"atl":[[5.3,45.98]],"id":35985721}],"con":true,"img":false}]}
{"op":"mcm","clk":"5323141141","pt":1646327918761,"mc":[{"id":"1.195532875","rc":[{"atb":[[2.06,0]],"id":37306244}],"con":true,"img":false}]}
{"op":"mcm","clk":"5323141148","pt":1646327918856,"mc":[{"id":"1.195532875","rc":[{"atl":[[4.5,16.22]],"id":40642034},{"atl":[[2.82,76.93],[2.78,0]],"id":40883678}],"con":true,"img":false}]}
{"op":"mcm","clk":"5323141163","pt":1646327919027,"mc":[{"id":"1.195532875","rc":[{"atl":[[4.5,5.5]],"id":40642034}],"con":true,"img":false}]}
{"op":"mcm","clk":"5323141171","pt":1646327919129,"mc":[{"id":"1.195532875","rc":[{"atb":[[1.87,95],[1.86,0]],"id":40642034}],"con":true,"img":false}]}
{"op":"mcm","clk":"5323141189","pt":1646327919342,"mc":[{"id":"1.195532875","rc":[{"atl":[[2.84,21.74]],"id":40883678}],"con":true,"img":false}]}
{"op":"mcm","clk":"5323141198","pt":1646327919447,"mc":[{"id":"1.195532875","rc":[{"atl":[[2.82,54.95]],"id":40883678}],"con":true,"img":false}]}
{"op":"mcm","clk":"5323141211","pt":1646327919655,"mc":[{"id":"1.195532875","rc":[{"atb":[[4.5,0]],"id":41469398}],"con":true,"img":false}]}
{"op":"mcm","clk":"5323141221","pt":1646327919747,"mc":[{"id":"1.195532875","rc":[{"atb":[[4.2,1.65]],"id":41469398}],"con":true,"img":false}]}
{"op":"mcm","clk":"5323141390","pt":1646327921858,"mc":[{"id":"1.195532875","rc":[{"atl":[[5.2,18.6]],"id":37306244}],"con":true,"img":false}]}
{"op":"mcm","clk":"5323141419","pt":1646327922128,"mc":[{"id":"1.195532875","rc":[{"atl":[[5.1,3]],"id":37306244}],"con":true,"img":false}]}
{"op":"mcm","clk":"5323141432","pt":1646327922379,"mc":[{"id":"1.195532875","rc":[{"atl":[[5.3,27.9]],"id":37306244}],"con":true,"img":false}]}
{"op":"mcm","clk":"5323141472","pt":1646327922858,"mc":[{"id":"1.195532875","rc":[{"atl":[[5.1,0]],"id":37306244}],"con":true,"img":false}]}
{"op":"mcm","clk":"5323141501","pt":1646327923162,"mc":[{"id":"1.195532875","rc":[{"atl":[[5,3.44]],"id":37306244}],"con":true,"img":false}]}
{"op":"mcm","clk":"5323141508","pt":1646327923224,"mc":[{"id":"1.195532875","rc":[{"atb":[[2.06,34.51]],"id":37306244}],"con":true,"img":false}]}
{"op":"mcm","clk":"5323141518","pt":1646327923340,"mc":[{"id":"1.195532875","rc":[{"atb":[[2.06,92.63],[2.04,40.96]],"id":37306244},{"atl":[[5.3,18.6],[5.2,28.12]],"id":37306244}],"con":true,"img":false}]}
{"op":"mcm","clk":"5323141528","pt":1646327923448,"mc":[{"id":"1.195532875","rc":[{"atb":[[4.2,19.86]],"id":41469398}],"con":true,"img":false}]}
{"op":"mcm","clk":"5323141537","pt":1646327923543,"mc":[{"id":"1.195532875","rc":[{"atl":[[5,0]],"id":37306244}],"con":true,"img":false}]}
{"op":"mcm","clk":"5323141542","pt":1646327923644,"mc":[{"id":"1.195532875","rc":[{"atb":[[4,1.99]],"id":41469398}],"con":true,"img":false}]}
{"op":"mcm","clk":"5323141550","pt":1646327923749,"mc":[{"id":"1.195532875","rc":[{"atl":[[5.3,41.86],[5.2,0]],"id":37306244}],"con":true,"img":false}]}
{"op":"mcm","clk":"5323141575","pt":1646327923949,"mc":[{"id":"1.195532875","rc":[{"atl":[[2.82,0],[2.84,76.09]],"id":40883678}],"con":true,"img":false}]}
{"op":"mcm","clk":"5323141583","pt":1646327924054,"mc":[{"id":"1.195532875","rc":[{"atl":[[2.8,0]],"id":40883678}],"con":true,"img":false}]}
{"op":"mcm","clk":"5323141591","pt":1646327924159,"mc":[{"id":"1.195532875","rc":[{"atl":[[2.8,30.34]],"id":40883678}],"con":true,"img":false}]}
{"op":"mcm","clk":"5323141601","pt":1646327924262,"mc":[{"id":"1.195532875","rc":[{"atb":[[3.8,0]],"id":41469398},{"atl":[[2.84,54.35],[2.94,167.93],[2.88,21.28],[2.9,0]],"id":40883678}],"con":true,"img":false}]}
{"op":"mcm","clk":"5323141619","pt":1646327924435,"mc":[{"id":"1.195532875","rc":[{"atl":[[2.94,51.55]],"id":40883678}],"con":true,"img":false}]}
{"op":"mcm","clk":"5323141631","pt":1646327924539,"mc":[{"id":"1.195532875","rc":[{"atb":[[2.06,137.04]],"id":37306244},{"atl":[[7,30]],"id":39614765},{"atb":[[1.67,1.99]],"id":40883678}],"con":true,"img":false}]}
{"op":"mcm","clk":"5323141640","pt":1646327924638,"mc":[{"id":"1.195532875","rc":[{"atl":[[5.6,72.35]],"id":37306244}],"con":true,"img":false}]}
{"op":"mcm","clk":"5323141649","pt":1646327924767,"mc":[{"id":"1.195532875","rc":[{"atl":[[5.4,11.24]],"id":37306244}],"con":true,"img":false}]}
{"op":"mcm","clk":"5323141658","pt":1646327924857,"mc":[{"id":"1.195532875","rc":[{"atl":[[2.8,0]],"id":40883678}],"con":true,"img":false}]}
{"op":"mcm","clk":"5323141665","pt":1646327924959,"mc":[{"id":"1.195532875","rc":[{"atl":[[5.7,31.91]],"id":35985721},{"atl":[[4.8,39.47]],"id":40642034},{"atl":[[2.82,24.38]],"id":40883678}],"con":true,"img":false}]}
{"op":"mcm","clk":"5323141677","pt":1646327925051,"mc":[{"id":"1.195532875","rc":[{"atl":[[5.5,8.89]],"id":37306244}],"con":true,"img":false}]}
{"op":"mcm","clk":"5323141684","pt":1646327925153,"mc":[{"id":"1.195532875","rc":[{"atl":[[5.4,2.15]],"id":37306244}],"con":true,"img":false}]}
{"op":"mcm","clk":"5323141696","pt":1646327925355,"mc":[{"id":"1.195532875","rc":[{"atb":[[2.7,0]],"id":35985721}],"con":true,"img":false}]}
{"op":"mcm","clk":"5323141705","pt":1646327925461,"mc":[{"id":"1.195532875","rc":[{"atb":[[2.66,1.99]],"id":35985721}],"con":true,"img":false}]}
{"op":"mcm","clk":"5323141714","pt":1646327925564,"mc":[{"id":"1.195532875","rc":[{"atl":[[5.6,11.2],[5.5,71.27]],"id":37306244},{"atb":[[2.64,14.97],[2.6,70.29],[2.62,10.03]],"id":35985721}],"con":true,"img":false}]}
{"op":"mcm","clk":"5323141736","pt":1646327925740,"mc":[{"id":"1.195532875","rc":[{"atb":[[2.6,25]],"id":35985721}],"con":true,"img":false}]}
{"op":"mcm","clk":"5323141768","pt":1646327926054,"mc":[{"id":"1.195532875","rc":[{"atl":[[5.1,19.51]],"id":37306244}],"con":true,"img":false}]}
{"op":"mcm","clk":"5323141792","pt":1646327926281,"mc":[{"id":"1.195532875","rc":[{"atl":[[5.3,23.26]],"id":37306244}],"con":true,"img":false}]}
{"op":"mcm","clk":"5323141800","pt":1646327926389,"mc":[{"id":"1.195532875","rc":[{"atl":[[5.3,32.56]],"id":37306244}],"con":true,"img":false}]}
{"op":"mcm","clk":"5323141806","pt":1646327926458,"mc":[{"id":"1.195532875","rc":[{"atb":[[4,0]],"id":41469398}],"con":true,"img":false}]}
{"op":"mcm","clk":"5323141815","pt":1646327926550,"mc":[{"id":"1.195532875","rc":[{"atb":[[4.3,1.99]],"id":41469398}],"con":true,"img":false}]}
{"op":"mcm","clk":"5323141824","pt":1646327926653,"mc":[{"id":"1.195532875","rc":[{"atb":[[3.85,37.59]],"id":41469398}],"con":true,"img":false}]}
{"op":"mcm","clk":"5323141835","pt":1646327926755,"mc":[{"id":"1.195532875","rc":[{"atb":[[2.3,4.11]],"id":37306244}],"con":true,"img":false}]}
{"op":"mcm","clk":"5323141854","pt":1646327926954,"mc":[{"id":"1.195532875","rc":[{"atb":[[2.3,0]],"id":37306244}],"con":true,"img":false}]}
{"op":"mcm","clk":"5323141875","pt":1646327927165,"mc":[{"id":"1.195532875","rc":[{"atb":[[4.1,0]],"id":41469398}],"con":true,"img":false}]}
{"op":"mcm","clk":"5323141895","pt":1646327927373,"mc":[{"id":"1.195532875","rc":[{"atb":[[4,7.59],[3.85,111.9],[3.95,13.56]],"id":41469398}],"con":true,"img":false}]}
{"op":"mcm","clk":"5323141904","pt":1646327927480,"mc":[{"id":"1.195532875","rc":[{"atb":[[1.63,153.61]],"id":40883678}],"con":true,"img":false}]}
{"op":"mcm","clk":"5323141913","pt":1646327927543,"mc":[{"id":"1.195532875","rc":[{"atb":[[4,0]],"id":41469398},{"atl":[[4.5,2.5]],"id":40642034}],"con":true,"img":false}]}
{"op":"mcm","clk":"5323141921","pt":1646327927662,"mc":[{"id":"1.195532875","rc":[{"atb":[[4.2,18.21]],"id":41469398},{"atb":[[2.72,0]],"id":35985721}],"con":true,"img":false}]}
{"op":"mcm","clk":"5323141932","pt":1646327927796,"mc":[{"id":"1.195532875","rc":[{"atl":[[2.88,140.96]],"id":40883678}],"con":true,"img":false}]}
{"op":"mcm","clk":"5323141943","pt":1646327927856,"mc":[{"id":"1.195532875","rc":[{"atb":[[2.68,1.65]],"id":35985721}],"con":true,"img":false}]}
{"op":"mcm","clk":"5323141961","pt":1646327928065,"mc":[{"id":"1.195532875","rc":[{"atb":[[2.6,28.77]],"id":35985721}],"con":true,"img":false}]}
{"op":"mcm","clk":"5323141996","pt":1646327928365,"mc":[{"id":"1.195532875","rc":[{"atl":[[2.92,21.99]],"id":40883678}],"con":true,"img":false}]}
{"op":"mcm","clk":"5323142010","pt":1646327928572,"mc":[{"id":"1.195532875","rc":[{"atb":[[2.6,25]],"id":35985721},{"atl":[[2.92,0]],"id":40883678}],"con":true,"img":false}]}
{"op":"mcm","clk":"5323142033","pt":1646327928783,"mc":[{"id":"1.195532875","rc":[{"atb":[[2.32,19.78],[2.28,53.87]],"id":37306244},{"atb":[[4.2,0]],"id":41469398},{"atb":[[1.71,250],[1.76,131.58]],"id":40642034},{"atl":[[2.88,119.68],[2.86,23.41]],"id":40883678}],"con":true,"img":false}]}
{"op":"mcm","clk":"5323142052","pt":1646327928948,"mc":[{"id":"1.195532875","rc":[{"atb":[[4,16.99]],"id":41469398}],"con":true,"img":false}]}
{"op":"mcm","clk":"5323142063","pt":1646327929050,"mc":[{"id":"1.195532875","rc":[{"atl":[[5.1,0]],"id":37306244}],"con":true,"img":false}]}
{"op":"mcm","clk":"5323142074","pt":1646327929152,"mc":[{"id":"1.195532875","rc":[{"atl":[[5.2,19.05]],"id":37306244}],"con":true,"img":false}]}
{"op":"mcm","clk":"5323142085","pt":1646327929257,"mc":[{"id":"1.195532875","rc":[{"atl":[[5.3,9.3],[5.4,24.88]],"id":37306244}],"con":true,"img":false}]}
{"op":"mcm","clk":"5323142094","pt":1646327929360,"mc":[{"id":"1.195532875","rc":[{"atl":[[5.3,0],[5.4,33.97]],"id":37306244}],"con":true,"img":false}]}
{"op":"mcm","clk":"5323142101","pt":1646327929464,"mc":[{"id":"1.195532875","rc":[{"atb":[[4.3,0]],"id":41469398}],"con":true,"img":false}]}
{"op":"mcm","clk":"5323142112","pt":1646327929571,"mc":[{"id":"1.195532875","rc":[{"atb":[[4.1,1.99]],"id":41469398},{"atb":[[2.54,5.93]],"id":35985721}],"con":true,"img":false}]}
{"op":"mcm","clk":"5323142155","pt":1646327930046,"mc":[{"id":"1.195532875","rc":[{"atb":[[2.54,0]],"id":35985721}],"con":true,"img":false}]}
{"op":"mcm","clk":"5323142204","pt":1646327930563,"mc":[{"id":"1.195532875","rc":[{"atb":[[2.62,0]],"id":35985721},{"atb":[[1.67,8.21]],"id":40883678}],"con":true,"img":false}]}
{"op":"mcm","clk":"5323142213","pt":1646327930669,"mc":[{"id":"1.195532875","rc":[{"atl":[[5.1,2]],"id":37306244}],"con":true,"img":false}]}
{"op":"mcm","clk":"5323142227","pt":1646327930771,"mc":[{"id":"1.195532875","rc":[{"atb":[[1.63,63.49]],"id":40883678}],"con":true,"img":false}]}
{"op":"mcm","clk":"5323142239","pt":1646327930868,"mc":[{"id":"1.195532875","rc":[{"atl":[[5.1,21.05],[5.4,11.24]],"id":37306244}],"con":true,"img":false}]}
{"op":"mcm","clk":"5323142254","pt":1646327930971,"mc":[{"id":"1.195532875","rc":[{"atb":[[2.6,57.76]],"id":35985721}],"con":true,"img":false}]}
{"op":"mcm","clk":"5323142293","pt":1646327931464,"mc":[{"id":"1.195532875","rc":[{"atl":[[5.3,9.3],[5.4,2.15]],"id":37306244}],"con":true,"img":false}]}
{"op":"mcm","clk":"5323142376","pt":1646327932277,"mc":[{"id":"1.195532875","rc":[{"atb":[[2.06,102.52]],"id":37306244},{"atl":[[5.3,74.94],[5.5,8.89]],"id":37306244}],"con":true,"img":false}]}
{"op":"mcm","clk":"5323142429","pt":1646327932763,"mc":[{"id":"1.195532875","rc":[{"atl":[[5.5,35.68]],"id":35985721}],"con":true,"img":false}]}
{"op":"mcm","clk":"5323142468","pt":1646327933069,"mc":[{"id":"1.195532875","rc":[{"atl":[[5.5,22.22]],"id":35985721}],"con":true,"img":false}]}
{"op":"mcm","clk":"5323142532","pt":1646327933653,"mc":[{"id":"1.195532875","rc":[{"atb":[[2.06,58.12]],"id":37306244},{"atl":[[5.1,19.05]],"id":37306244},{"atb":[[4.1,17.17]],"id":41469398}],"con":true,"img":false}]}
{"op":"mcm","clk":"5323142557","pt":1646327933869,"mc":[{"id":"1.195532875","rc":[{"atb":[[3.85,37.59],[3.95,51.75]],"id":41469398}],"con":true,"img":false}]}
{"op":"mcm","clk":"5323142605","pt":1646327934472,"mc":[{"id":"1.195532875","rc":[{"atl":[[5,2.32]],"id":37306244}],"con":true,"img":false}]}
{"op":"mcm","clk":"5323142632","pt":1646327934855,"mc":[{"id":"1.195532875","rc":[{"atl":[[5,0]],"id":37306244},{"atl":[[7.4,39.06]],"id":39614765}],"con":true,"img":false}]}
{"op":"mcm","clk":"5323142666","pt":1646327935169,"mc":[{"id":"1.195532875","rc":[{"atl":[[4.8,4.32]],"id":37306244},{"atl":[[5.9,81.63]],"id":35985721}],"con":true,"img":false}]}
{"op":"mcm","clk":"5323142678","pt":1646327935267,"mc":[{"id":"1.195532875","rc":[{"atl":[[5.9,51.02]],"id":35985721},{"atl":[[5,62.5]],"id":40642034}],"con":true,"img":false}]}
{"op":"mcm","clk":"5323142696","pt":1646327935474,"mc":[{"id":"1.195532875","rc":[{"atb":[[2.28,0],[2.34,21.43]],"id":37306244}],"con":true,"img":false}]}
{"op":"mcm","clk":"5323142713","pt":1646327935673,"mc":[{"id":"1.195532875","rc":[{"atb":[[2.28,53.87],[2.34,30.23]],"id":37306244}],"con":true,"img":false}]}
{"op":"mcm","clk":"5323142737","pt":1646327935851,"mc":[{"id":"1.195532875","rc":[{"atb":[[2.32,0],[2.28,0],[2.34,50.01]],"id":37306244}],"con":true,"img":false}]}
{"op":"mcm","clk":"5323142743","pt":1646327935963,"mc":[{"id":"1.195532875","rc":[{"atb":[[2.4,2.15],[2.16,0]],"id":37306244}],"con":true,"img":false}]}
{"op":"mcm","clk":"5323142790","pt":1646327936468,"mc":[{"id":"1.195532875","rc":[{"atl":[[5,10],[5.3,65.64]],"id":37306244},{"atl":[[15.5,0]],"id":39614765}],"con":true,"img":false}]}
{"op":"mcm","clk":"5323142821","pt":1646327936774,"mc":[{"id":"1.195532875","rc":[{"atl":[[4.8,0]],"id":37306244},{"atb":[[2.68,7.13]],"id":35985721}],"con":true,"img":false}]}
{"op":"mcm","clk":"5323142839","pt":1646327936987,"mc":[{"id":"1.195532875","rc":[{"atl":[[5.1,0],[5,0],[5.2,52.38]],"id":37306244}],"con":true,"img":false}]}
{"op":"mcm","clk":"5323142880","pt":1646327937364,"mc":[{"id":"1.195532875","rc":[{"atl":[[5.2,42.86],[5.4,11.24]],"id":37306244}],"con":true,"img":false}]}
{"op":"mcm","clk":"5323142892","pt":1646327937565,"mc":[{"id":"1.195532875","rc":[{"atb":[[2.66,0]],"id":35985721}],"con":true,"img":false}]}
{"op":"mcm","clk":"5323142907","pt":1646327937677,"mc":[{"id":"1.195532875","rc":[{"atb":[[2.7,1.99]],"id":35985721}],"con":true,"img":false}]}
{"op":"mcm","clk":"5323142917","pt":1646327937778,"mc":[{"id":"1.195532875","rc":[{"atb":[[4.2,25]],"id":41469398}],"con":true,"img":false}]}
{"op":"mcm","clk":"5323142927","pt":1646327937881,"mc":[{"id":"1.195532875","rc":[{"atb":[[4,0]],"id":41469398}],"con":true,"img":false}]}
{"op":"mcm","clk":"5323142943","pt":1646327938082,"mc":[{"id":"1.195532875","rc":[{"atb":[[4.1,15.18]],"id":41469398}],"con":true,"img":false}]}
{"op":"mcm","clk":"5323142951","pt":1646327938144,"mc":[{"id":"1.195532875","rc":[{"atb":[[4.3,1.99]],"id":41469398}],"con":true,"img":false}]}
{"op":"mcm","clk":"5323142988","pt":1646327938560,"mc":[{"id":"1.195532875","rc":[{"atl":[[2.88,0],[2.86,118.99]],"id":40883678}],"con":true,"img":false}]}
{"op":"mcm","clk":"5323143007","pt":1646327938768,"mc":[{"id":"1.195532875","rc":[{"atl":[[2.86,172.75],[2.84,0]],"id":40883678}],"con":true,"img":false}]}
{"op":"mcm","clk":"5323143014","pt":1646327938868,"mc":[{"id":"1.195532875","rc":[{"atl":[[5.4,76.54]],"id":37306244}],"con":true,"img":false}]}
{"op":"mcm","clk":"5323143027","pt":1646327938973,"mc":[{"id":"1.195532875","rc":[{"atl":[[5.3,0]],"id":37306244},{"atl":[[2.9,52.63]],"id":40883678}],"con":true,"img":false}]}
{"op":"mcm","clk":"5323143035","pt":1646327939081,"mc":[{"id":"1.195532875","rc":[{"atb":[[2.08,33.87]],"id":37306244}],"con":true,"img":false}]}
{"op":"mcm","clk":"5323143049","pt":1646327939279,"mc":[{"id":"1.195532875","rc":[{"atb":[[2.06,0],[2.08,129.78]],"id":37306244}],"con":true,"img":false}]}
{"op":"mcm","clk":"5323143064","pt":1646327939446,"mc":[{"id":"1.195532875","rc":[{"atb":[[4.2,0]],"id":41469398},{"atb":[[2.5,0],[2.32,75.76],[2.6,25]],"id":35985721}],"con":true,"img":false}]}
{"op":"mcm","clk":"5323143072","pt":1646327939552,"mc":[{"id":"1.195532875","rc":[{"atb":[[4,8.69]],"id":41469398},{"atb":[[2.64,2.15]],"id":35985721},{"atb":[[2.54,18.86]],"id":39614765},{"atl":[[3.05,0]],"id":40883678}],"con":true,"img":false}]}
{"op":"mcm","clk":"5323143078","pt":1646327939655,"mc":[{"id":"1.195532875","rc":[{"atb":[[3.85,106.05],[3.95,13.56]],"id":41469398},{"atb":[[2.52,34.18]],"id":39614765}],"con":true,"img":false}]}
{"op":"mcm","clk":"5323143085","pt":1646327939768,"mc":[{"id":"1.195532875","rc":[{"atb":[[2.54,22.75],[2.52,12.76]],"id":39614765}],"con":true,"img":false}]}
{"op":"mcm","clk":"5323143098","pt":1646327939994,"mc":[{"id":"1.195532875","rc":[{"atb":[[2.08,173.36]],"id":37306244},{"atb":[[4.3,0]],"id":41469398}],"con":true,"img":false}]}
{"op":"mcm","clk":"5323143109","pt":1646327940077,"mc":[{"id":"1.195532875","rc":[{"atb":[[4.2,1.99]],"id":41469398}],"con":true,"img":false}]}
{"op":"mcm","clk":"5323143122","pt":1646327940189,"mc":[{"id":"1.195532875","rc":[{"atb":[[2.52,9.12]],"id":39614765}],"con":true,"img":false}]}
{"op":"mcm","clk":"5323143257","pt":1646327941589,"mc":[{"id":"1.195532875","rc":[{"atb":[[3.95,41.87]],"id":41469398}],"con":true,"img":false}]}
{"op":"mcm","clk":"5323143268","pt":1646327941656,"mc":[{"id":"1.195532875","rc":[{"spn":2.4,"spf":1.0,"id":37306244},{"atb":[[3.85,37.59]],"id":41469398},{"spn":4.2,"spf":1.0,"id":41469398},{"spn":2.68,"spf":1.0,"id":35985721},{"spn":2.56,"spf":1.0,"id":39614765},{"spn":3.26,"spf":"NaN","id":40642034},{"spn":2.24,"spf":"NaN","id":40883678}],"con":true,"img":false}]}
{"op":"mcm","clk":"5323143308","pt":1646327942178,"mc":[{"id":"1.195532875","rc":[{"atl":[[5.2,19.05],[5.4,99.27]],"id":37306244}],"con":true,"img":false}]}
{"op":"mcm","clk":"5323143315","pt":1646327942280,"mc":[{"id":"1.195532875","rc":[{"atl":[[5,2.5],[5.3,43.48],[5.4,5]],"id":35985721}],"con":true,"img":false}]}
{"op":"mcm","clk":"5323143323","pt":1646327942385,"mc":[{"id":"1.195532875","rc":[{"atl":[[5,8.52]],"id":35985721}],"con":true,"img":false}]}
{"op":"mcm","clk":"5323143332","pt":1646327942488,"mc":[{"id":"1.195532875","rc":[{"atb":[[2.36,50.02],[2.34,30.23]],"id":37306244},{"atl":[[5.3,9.3],[5.2,41.19]],"id":35985721}],"con":true,"img":false}]}
{"op":"mcm","clk":"5323143342","pt":1646327942599,"mc":[{"id":"1.195532875","rc":[{"atl":[[5.1,0]],"id":35985721}],"con":true,"img":false}]}
{"op":"mcm","clk":"5323143376","pt":1646327942852,"mc":[{"id":"1.195532875","rc":[{"atb":[[2.52,0]],"id":39614765},{"atb":[[1.67,1.99]],"id":40883678}],"con":true,"img":false}]}
{"op":"mcm","clk":"5323143392","pt":1646327943078,"mc":[{"id":"1.195532875","rc":[{"atb":[[1.63,188.93]],"id":40883678}],"con":true,"img":false}]}
{"op":"mcm","clk":"5323143402","pt":1646327943172,"mc":[{"id":"1.195532875","rc":[{"atb":[[4.1,28.52]],"id":41469398}],"con":true,"img":false}]}
{"op":"mcm","clk":"5323143410","pt":1646327943279,"mc":[{"id":"1.195532875","rc":[{"atb":[[4,0]],"id":41469398}],"con":true,"img":false}]}
{"op":"mcm","clk":"5323143449","pt":1646327943696,"mc":[{"id":"1.195532875","rc":[{"atb":[[2.34,28.58]],"id":37306244},{"atb":[[2.68,5.47]],"id":35985721}],"con":true,"img":false}]}
{"op":"mcm","clk":"5323143462","pt":1646327943853,"mc":[{"id":"1.195532875","rc":[{"atb":[[2.42,1.65]],"id":37306244},{"atb":[[2.72,1.65]],"id":35985721}],"con":true,"img":false}]}
{"op":"mcm","clk":"5323143567","pt":1646327945195,"mc":[{"id":"1.195532875","rc":[{"atl":[[2.86,77.17],[2.9,175.78]],"id":40883678}],"con":true,"img":false}]}
{"op":"mcm","clk":"5323143575","pt":1646327945298,"mc":[{"id":"1.195532875","rc":[{"atl":[[5.3,0],[5.2,50.71]],"id":35985721}],"con":true,"img":false}]}
{"op":"mcm","clk":"5323143586","pt":1646327945389,"mc":[{"id":"1.195532875","rc":[{"atl":[[5.3,23.26],[5.2,41.82]],"id":35985721}],"con":true,"img":false}]}
{"op":"mcm","clk":"5323143594","pt":1646327945455,"mc":[{"id":"1.195532875","rc":[{"atl":[[5.5,73.86]],"id":37306244}],"con":true,"img":false}]}
{"op":"mcm","clk":"5323143600","pt":1646327945559,"mc":[{"id":"1.195532875","rc":[{"atl":[[5.4,33.97]],"id":37306244}],"con":true,"img":false}]}
{"op":"mcm","clk":"5323143606","pt":1646327945663,"mc":[{"id":"1.195532875","rc":[{"atb":[[2.08,95.91]],"id":37306244},{"atb":[[2.68,0]],"id":35985721}],"con":true,"img":false}]}
{"op":"mcm","clk":"5323143655","pt":1646327946286,"mc":[{"id":"1.195532875","rc":[{"atb":[[3.85,122.73],[3.95,13.56]],"id":41469398}],"con":true,"img":false}]}
{"op":"mcm","clk":"5323143698","pt":1646327946656,"mc":[{"id":"1.195532875","rc":[{"atl":[[5.4,9.15]],"id":35985721}],"con":true,"img":false}]}
{"op":"mcm","clk":"5323143733","pt":1646327947074,"mc":[{"id":"1.195532875","rc":[{"atl":[[5.4,4.99]],"id":35985721}],"con":true,"img":false}]}
{"op":"mcm","clk":"5323143763","pt":1646327947378,"mc":[{"id":"1.195532875","rc":[{"atl":[[5.6,24.24]],"id":37306244}],"con":true,"img":false}]}
{"op":"mcm","clk":"5323143897","pt":1646327948773,"mc":[{"id":"1.195532875","rc":[{"atb":[[2.32,4.15],[2.3,1.99],[2.22,0],[2.24,5],[2.16,10]],"id":40642034}],"con":true,"img":false}]}
{"op":"mcm","clk":"5323143916","pt":1646327948987,"mc":[{"id":"1.195532875","rc":[{"atl":[[5.3,86.82],[5.2,11.86]],"id":35985721},{"atb":[[1.87,75.9],[2.2,3.56]],"id":40642034},{"atl":[[2.94,128.87]],"id":40883678}],"con":true,"img":false}]}
{"op":"mcm","clk":"5323143925","pt":1646327949078,"mc":[{"id":"1.195532875","rc":[{"atl":[[2.94,77.32]],"id":40883678}],"con":true,"img":false}]}
{"op":"mcm","clk":"5323143945","pt":1646327949297,"mc":[{"id":"1.195532875","rc":[{"atb":[[2.2,0]],"id":40642034}],"con":true,"img":false}]}
{"op":"mcm","clk":"5323143952","pt":1646327949404,"mc":[{"id":"1.195532875","rc":[{"atb":[[4.1,13.34]],"id":41469398},{"atb":[[2.6,8.7]],"id":39614765},{"atb":[[1.67,8.21]],"id":40883678}],"con":true,"img":false}]}
{"op":"mcm","clk":"5323143979","pt":1646327949683,"mc":[{"id":"1.195532875","rc":[{"atb":[[2.4,34.76]],"id":37306244},{"atb":[[2.54,0]],"id":39614765},{"atb":[[1.63,63.49]],"id":40883678}],"con":true,"img":false}]}
{"op":"mcm","clk":"5323143997","pt":1646327949882,"mc":[{"id":"1.195532875","rc":[{"atb":[[2.34,0]],"id":37306244},{"atl":[[2.88,7.88]],"id":40883678}],"con":true,"img":false}]}
{"op":"mcm","clk":"5323144025","pt":1646327950188,"mc":[{"id":"1.195532875","rc":[{"atl":[[2.8,24.44]],"id":40883678}],"con":true,"img":false}]}
{"op":"mcm","clk":"5323144039","pt":1646327950388,"mc":[{"id":"1.195532875","rc":[{"atl":[[2.88,0]],"id":40883678}],"con":true,"img":false}]}
{"op":"mcm","clk":"5323144047","pt":1646327950498,"mc":[{"id":"1.195532875","rc":[{"atl":[[2.82,0]],"id":40883678}],"con":true,"img":false}]}
{"op":"mcm","clk":"5323144146","pt":1646327951696,"mc":[{"id":"1.195532875","rc":[{"atb":[[2.58,4.14]],"id":39614765}],"con":true,"img":false}]}
{"op":"mcm","clk":"5323144234","pt":1646327952674,"mc":[{"id":"1.195532875","rc":[{"atb":[[1.87,53.78]],"id":40642034}],"con":true,"img":false}]}
{"op":"mcm","clk":"5323144246","pt":1646327952778,"mc":[{"id":"1.195532875","rc":[{"atb":[[2.1,33.25]],"id":37306244}],"con":true,"img":false}]}
{"op":"mcm","clk":"5323144268","pt":1646327952986,"mc":[{"id":"1.195532875","rc":[{"atb":[[2.42,7.38]],"id":37306244},{"atb":[[2.62,10.03]],"id":35985721},{"atb":[[1.87,0]],"id":40642034}],"con":true,"img":false}]}
{"op":"mcm","clk":"5323144288","pt":1646327953193,"mc":[{"id":"1.195532875","rc":[{"atb":[[2.36,135.95],[2.08,0]],"id":37306244}],"con":true,"img":false}]}
{"op":"mcm","clk":"5323144303","pt":1646327953405,"mc":[{"id":"1.195532875","rc":[{"atl":[[2.86,55.66],[2.84,21.74]],"id":40883678}],"con":true,"img":false}]}
{"op":"mcm","clk":"5323144320","pt":1646327953570,"mc":[{"id":"1.195532875","rc":[{"atl":[[2.86,148.02],[2.9,52.63]],"id":40883678}],"con":true,"img":false}]}
{"op":"mcm","clk":"5323144340","pt":1646327953774,"mc":[{"id":"1.195532875","rc":[{"atb":[[2.56,23.39]],"id":39614765}],"con":true,"img":false}]}
{"op":"mcm","clk":"5323144388","pt":1646327954296,"mc":[{"id":"1.195532875","rc":[{"atb":[[2.3,0]],"id":40642034}],"con":true,"img":false}]}
{"op":"mcm","clk":"5323144402","pt":1646327954402,"mc":[{"id":"1.195532875","rc":[{"atb":[[2.34,1.99]],"id":40642034}],"con":true,"img":false}]}
{"op":"mcm","clk":"5323144428","pt":1646327954668,"mc":[{"id":"1.195532875","rc":[{"atb":[[4.2,18.81]],"id":41469398},{"atb":[[2.7,0]],"id":35985721}],"con":true,"img":false}]}
{"op":"mcm","clk":"5323144438","pt":1646327954769,"mc":[{"id":"1.195532875","rc":[{"atb":[[2.38,7.82]],"id":37306244},{"atb":[[3.85,37.59],[3.95,47.18],[4.1,0]],"id":41469398},{"atb":[[2.66,1.99]],"id":35985721}],"con":true,"img":false}]}
{"op":"mcm","clk":"5323144458","pt":1646327954985,"mc":[{"id":"1.195532875","rc":[{"atb":[[2.38,0]],"id":37306244}],"con":true,"img":false}]}
{"op":"mcm","clk":"5323144495","pt":1646327955296,"mc":[{"id":"1.195532875","rc":[{"atb":[[2.18,6.23]],"id":40642034}],"con":true,"img":false}]}
{"op":"mcm","clk":"5323144576","pt":1646327956192,"mc":[{"id":"1.195532875","rc":[{"atb":[[4.2,33.51]],"id":41469398}],"con":true,"img":false}]}
{"op":"mcm","clk":"5323144633","pt":1646327956768,"mc":[{"id":"1.195532875","rc":[{"atb":[[2.6,22.87]],"id":39614765},{"atl":[[2.8,29.96]],"id":40883678}],"con":true,"img":false}]}
{"op":"mcm","clk":"5323144642","pt":1646327956874,"mc":[{"id":"1.195532875","rc":[{"atb":[[2.58,2.15]],"id":39614765},{"atl":[[2.86,94.26],[2.78,29.96]],"id":40883678}],"con":true,"img":false}]}
{"op":"mcm","clk":"5323144648","pt":1646327956985,"mc":[{"id":"1.195532875","rc":[{"atb":[[2.62,1.99]],"id":39614765}],"con":true,"img":false}]}
{"op":"mcm","clk":"5323144675","pt":1646327957289,"mc":[{"id":"1.195532875","rc":[{"atl":[[5.8,31.25]],"id":37306244},{"atl":[[2.8,24.44]],"id":40883678}],"con":true,"img":false}]}
{"op":"mcm","clk":"5323144699","pt":1646327957603,"mc":[{"id":"1.195532875","rc":[{"atl":[[5.5,64.97],[5.7,0]],"id":37306244}],"con":true,"img":false}]}
{"op":"mcm","clk":"5323144706","pt":1646327957709,"mc":[{"id":"1.195532875","rc":[{"atb":[[2.1,0]],"id":37306244}],"con":true,"img":false}]}
{"op":"mcm","clk":"5323144821","pt":1646327959030,"mc":[{"id":"1.195532875","rc":[{"atl":[[2.86,1.9],[2.84,114.1]],"id":40883678}],"con":true,"img":false}]}
{"op":"mcm","clk":"5323144833","pt":1646327959180,"mc":[{"id":"1.195532875","rc":[{"atb":[[4.2,16.69]],"id":41469398},{"atb":[[2.6,8.7]],"id":39614765}],"con":true,"img":false}]}
{"op":"mcm","clk":"5323144845","pt":1646327959293,"mc":[{"id":"1.195532875","rc":[{"atb":[[4,26.67]],"id":41469398}],"con":true,"img":false}]}
{"op":"mcm","clk":"5323144890","pt":1646327959708,"mc":[{"id":"1.195532875","rc":[{"atb":[[2.72,0]],"id":35985721},{"atb":[[2.32,2.5],[2.2,19.97]],"id":40642034},{"atb":[[1.67,1.99]],"id":40883678}],"con":true,"img":false}]}
{"op":"mcm","clk":"5323144906","pt":1646327959824,"mc":[{"id":"1.195532875","rc":[{"atb":[[2.36,85.93],[2.34,74.63]],"id":37306244},{"atb":[[2.68,1.65]],"id":35985721},{"atb":[[2.36,1.65]],"id":40642034},{"atb":[[1.63,160.59]],"id":40883678},{"atl":[[2.82,21.98],[2.84,92.36]],"id":40883678}],"con":true,"img":false}]}
{"op":"mcm","clk":"5323144952","pt":1646327960290,"mc":[{"id":"1.195532875","rc":[{"atb":[[2.3,2.15],[1.65,0]],"id":40642034}],"con":true,"img":false}]}
{"op":"mcm","clk":"5323145035","pt":1646327961177,"mc":[{"id":"1.195532875","rc":[{"atl":[[5.4,36.47]],"id":37306244}],"con":true,"img":false}]}
{"op":"mcm","clk":"5323145041","pt":1646327961292,"mc":[{"id":"1.195532875","rc":[{"atl":[[5.6,21.74],[6,0]],"id":37306244}],"con":true,"img":false}]}
{"op":"mcm","clk":"5323145051","pt":1646327961385,"mc":[{"id":"1.195532875","rc":[{"atb":[[2.1,36.36]],"id":37306244}],"con":true,"img":false}]}
{"op":"mcm","clk":"5323145057","pt":1646327961488,"mc":[{"id":"1.195532875","rc":[{"atb":[[2.04,7.26]],"id":37306244}],"con":true,"img":false}]}
{"op":"mcm","clk":"5323145070","pt":1646327961592,"mc":[{"id":"1.195532875","rc":[{"atb":[[2,0],[1.98,0],[1.96,0]],"id":37306244}],"con":true,"img":false}]}
{"op":"mcm","clk":"5323145079","pt":1646327961700,"mc":[{"id":"1.195532875","rc":[{"atb":[[2.14,35.09]],"id":37306244}],"con":true,"img":false}]}
{"op":"mcm","clk":"5323145086","pt":1646327961805,"mc":[{"id":"1.195532875","rc":[{"atb":[[2.1,0]],"id":37306244}],"con":true,"img":false}]}
{"op":"mcm","clk":"5323145096","pt":1646327961910,"mc":[{"id":"1.195532875","rc":[{"atb":[[2.04,2.5]],"id":37306244}],"con":true,"img":false}]}
{"op":"mcm","clk":"5323145110","pt":1646327962122,"mc":[{"id":"1.195532875","rc":[{"atl":[[2.82,76.38]],"id":40883678}],"con":true,"img":false}]}
{"op":"mcm","clk":"5323145120","pt":1646327962179,"mc":[{"id":"1.195532875","rc":[{"atl":[[2.78,0]],"id":40883678}],"con":true,"img":false}]}
{"op":"mcm","clk":"5323145138","pt":1646327962384,"mc":[{"id":"1.195532875","rc":[{"atb":[[2.2,33.33]],"id":37306244},{"atb":[[2.6,0]],"id":39614765},{"atl":[[2.84,114.1]],"id":40883678}],"con":true,"img":false}]}
{"op":"mcm","clk":"5323145147","pt":1646327962489,"mc":[{"id":"1.195532875","rc":[{"atb":[[2.44,5.16]],"id":37306244},{"atb":[[2.56,2.5],[2.48,27.75]],"id":39614765},{"atb":[[2.18,0]],"id":40642034},{"atl":[[2.82,54.4]],"id":40883678}],"con":true,"img":false}]}
{"op":"mcm","clk":"5323145165","pt":1646327962698,"mc":[{"id":"1.195532875","rc":[{"atb":[[2.04,0]],"id":37306244}],"con":true,"img":false}]}
{"op":"mcm","clk":"5323145185","pt":1646327962906,"mc":[{"id":"1.195532875","rc":[{"atb":[[2.56,7.91],[2.5,26.67],[2.6,0]],"id":35985721}],"con":true,"img":false}]}
{"op":"mcm","clk":"5323145224","pt":1646327963437,"mc":[{"id":"1.195532875","rc":[{"atb":[[2.44,33.72]],"id":37306244},{"atb":[[2.56,0]],"id":35985721}],"con":true,"img":false}]}
{"op":"mcm","clk":"5323145236","pt":1646327963592,"mc":[{"id":"1.195532875","rc":[{"atb":[[2.4,2.15]],"id":37306244}],"con":true,"img":false}]}
{"op":"mcm","clk":"5323145297","pt":1646327964284,"mc":[{"id":"1.195532875","rc":[{"atl":[[2.78,44.94]],"id":40883678}],"con":true,"img":false}]}
{"op":"mcm","clk":"5323145317","pt":1646327964498,"mc":[{"id":"1.195532875","rc":[{"atl":[[2.8,0]],"id":40883678}],"con":true,"img":false}]}
{"op":"mcm","clk":"5323145359","pt":1646327965013,"mc":[{"id":"1.195532875","rc":[{"atb":[[2.32,67.44],[2.34,0]],"id":37306244},{"atb":[[4,46.01],[3.2,45.45],[3.5,0]],"id":41469398},{"atb":[[2.52,0]],"id":35985721},{"atl":[[2.82,76.38],[2.84,92.36]],"id":40883678}],"con":true,"img":false}]}
{"op":"mcm","clk":"5323145376","pt":1646327965223,"mc":[{"id":"1.195532875","rc":[{"atb":[[4,26.67]],"id":41469398}],"con":true,"img":false}]}
{"op":"mcm","clk":"5323145410","pt":1646327965591,"mc":[{"id":"1.195532875","rc":[{"atb":[[2.26,4.37]],"id":40642034}],"con":true,"img":false}]}
{"op":"mcm","clk":"5323145418","pt":1646327965696,"mc":[{"id":"1.195532875","rc":[{"atb":[[2.2,0]],"id":40642034},{"atb":[[1.67,8.21]],"id":40883678}],"con":true,"img":false}]}
{"op":"mcm","clk":"5323145516","pt":1646327966897,"mc":[{"id":"1.195532875","rc":[{"atb":[[2.4,68.11],[2.36,0]],"id":37306244}],"con":true,"img":false}]}
{"op":"mcm","clk":"5323145550","pt":1646327967316,"mc":[{"id":"1.195532875","rc":[{"atl":[[2.82,21.98],[2.84,146.71]],"id":40883678}],"con":true,"img":false}]}
{"op":"mcm","clk":"5323145573","pt":1646327967692,"mc":[{"id":"1.195532875","rc":[{"atb":[[2.42,5.72]],"id":37306244}],"con":true,"img":false}]}
{"op":"mcm","clk":"5323145582","pt":1646327967788,"mc":[{"id":"1.195532875","rc":[{"atb":[[2.46,1.65]],"id":37306244}],"con":true,"img":false}]}
{"op":"mcm","clk":"5323145594","pt":1646327967998,"mc":[{"id":"1.195532875","rc":[{"atb":[[2.44,28.56]],"id":37306244}],"con":true,"img":false}]}
{"op":"mcm","clk":"5323145660","pt":1646327968891,"mc":[{"id":"1.195532875","rc":[{"atb":[[2.42,0]],"id":37306244},{"atb":[[2.62,0]],"id":35985721},{"atb":[[2.5,11.4]],"id":39614765}],"con":true,"img":false}]}
{"op":"mcm","clk":"5323145666","pt":1646327969001,"mc":[{"id":"1.195532875","rc":[{"atb":[[2.5,52.15]],"id":35985721},{"atb":[[2.5,34.15]],"id":39614765}],"con":true,"img":false}]}
{"op":"mcm","clk":"5323145674","pt":1646327969099,"mc":[{"id":"1.195532875","rc":[{"atb":[[2.48,5]],"id":39614765}],"con":true,"img":false}]}
{"op":"mcm","clk":"5323145809","pt":1646327970824,"mc":[{"id":"1.195532875","rc":[{"atb":[[2.4,65.96],[2.5,2.15]],"id":37306244}],"con":true,"img":false}]}
{"op":"mcm","clk":"5323145917","pt":1646327971920,"mc":[{"id":"1.195532875","rc":[{"atl":[[5.5,35.57]],"id":35985721}],"con":true,"img":false}]}
{"op":"mcm","clk":"5323145921","pt":1646327972025,"mc":[{"id":"1.195532875","rc":[{"atl":[[6,50]],"id":37306244},{"atb":[[2.28,9.12]],"id":40642034}],"con":true,"img":false}]}
{"op":"mcm","clk":"5323145962","pt":1646327972397,"mc":[{"id":"1.195532875","rc":[{"atl":[[5.5,22.22]],"id":35985721}],"con":true,"img":false}]}
{"op":"mcm","clk":"5323145969","pt":1646327972497,"mc":[{"id":"1.195532875","rc":[{"atb":[[2.46,68.49]],"id":35985721}],"con":true,"img":false}]}
{"op":"mcm","clk":"5323145977","pt":1646327972608,"mc":[{"id":"1.195532875","rc":[{"atb":[[2.34,27.3]],"id":37306244}],"con":true,"img":false}]}
{"op":"mcm","clk":"5323146038","pt":1646327973392,"mc":[{"id":"1.195532875","rc":[{"atb":[[1.64,131.36],[1.63,63.49]],"id":40883678}],"con":true,"img":false}]}
{"op":"mcm","clk":"5323146136","pt":1646327974618,"mc":[{"id":"1.195532875","rc":[{"atl":[[2.86,55.66]],"id":40883678}],"con":true,"img":false}]}
{"op":"mcm","clk":"5323146151","pt":1646327974829,"mc":[{"id":"1.195532875","rc":[{"atb":[[2.26,0]],"id":40642034}],"con":true,"img":false}]}
{"op":"mcm","clk":"5323146209","pt":1646327975511,"mc":[{"id":"1.195532875","rc":[{"atl":[[2.98,0]],"id":40883678}],"con":true,"img":false}]}
{"op":"mcm","clk":"5323146221","pt":1646327975623,"mc":[{"id":"1.195532875","rc":[{"atb":[[2.46,0]],"id":37306244},{"atb":[[2.58,10.03]],"id":39614765}],"con":true,"img":false}]}
{"op":"mcm","clk":"5323146231","pt":1646327975726,"mc":[{"id":"1.195532875","rc":[{"atb":[[2.48,5.72]],"id":37306244},{"atb":[[2.52,12.78]],"id":35985721}],"con":true,"img":false}]}
{"op":"mcm","clk":"5323146242","pt":1646327975828,"mc":[{"id":"1.195532875","rc":[{"atb":[[2.52,1.65]],"id":37306244},{"atb":[[4.3,1.65]],"id":41469398},{"atb":[[2.64,1.65]],"id":39614765}],"con":true,"img":false}]}
{"op":"mcm","clk":"5323146261","pt":1646327976035,"mc":[{"id":"1.195532875","rc":[{"atb":[[2.5,11.4],[2.56,25.06]],"id":39614765}],"con":true,"img":false}]}
{"op":"mcm","clk":"5323146294","pt":1646327976426,"mc":[{"id":"1.195532875","rc":[{"atb":[[2.56,29.31]],"id":39614765}],"con":true,"img":false}]}
{"op":"mcm","clk":"5323146313","pt":1646327976617,"mc":[{"id":"1.195532875","rc":[{"atb":[[2.56,25.06]],"id":39614765}],"con":true,"img":false}]}
{"op":"mcm","clk":"5323146336","pt":1646327976936,"mc":[{"id":"1.195532875","rc":[{"atb":[[2.5,20.73]],"id":37306244}],"con":true,"img":false}]}
{"op":"mcm","clk":"5323146356","pt":1646327977104,"mc":[{"id":"1.195532875","rc":[{"atb":[[2.44,0],[2.34,0]],"id":37306244}],"con":true,"img":false}]}
{"op":"mcm","clk":"5323146552","pt":1646327979722,"mc":[{"id":"1.195532875","rc":[{"atb":[[2.36,4.21]],"id":40642034}],"con":true,"img":false}]}
{"op":"mcm","clk":"5323146610","pt":1646327980405,"mc":[{"id":"1.195532875","rc":[{"atl":[[4.5,7.88]],"id":40642034}],"con":true,"img":false}]}
{"op":"mcm","clk":"5323146631","pt":1646327980625,"mc":[{"id":"1.195532875","rc":[{"atl":[[4.5,2.5]],"id":40642034}],"con":true,"img":false}]}
{"op":"mcm","clk":"5323146691","pt":1646327981359,"mc":[{"id":"1.195532875","rc":[{"atb":[[2.48,0]],"id":37306244},{"atb":[[2.5,0]],"id":39614765}],"con":true,"img":false}]}
{"op":"mcm","clk":"5323146709","pt":1646327981515,"mc":[{"id":"1.195532875","rc":[{"atb":[[2.4,0],[2.32,194.24]],"id":37306244}],"con":true,"img":false}]}
{"op":"mcm","clk":"5323146720","pt":1646327981614,"mc":[{"id":"1.195532875","rc":[{"atb":[[2.24,2.5],[2.38,9.25]],"id":37306244}],"con":true,"img":false}]}
{"op":"mcm","clk":"5323146735","pt":1646327981824,"mc":[{"id":"1.195532875","rc":[{"atb":[[2.38,0]],"id":37306244}],"con":true,"img":false}]}
{"op":"mcm","clk":"5323146744","pt":1646327981933,"mc":[{"id":"1.195532875","rc":[{"atb":[[2.42,105.63]],"id":35985721}],"con":true,"img":false}]}
{"op":"mcm","clk":"5323146781","pt":1646327982409,"mc":[{"id":"1.195532875","rc":[{"atb":[[2.5,26.67],[2.52,38.26]],"id":35985721}],"con":true,"img":false}]}
{"op":"mcm","clk":"5323146801","pt":1646327982620,"mc":[{"id":"1.195532875","rc":[{"atb":[[2.42,25.76]],"id":37306244}],"con":true,"img":false}]}
{"op":"mcm","clk":"5323146868","pt":1646327983518,"mc":[{"id":"1.195532875","rc":[{"atb":[[2.26,31.75]],"id":37306244},{"atb":[[2.4,28.57]],"id":35985721}],"con":true,"img":false}]}
{"op":"mcm","clk":"5323146874","pt":1646327983624,"mc":[{"id":"1.195532875","rc":[{"atb":[[2.5,0],[2.48,0]],"id":35985721}],"con":true,"img":false}]}
{"op":"mcm","clk":"5323146908","pt":1646327984045,"mc":[{"id":"1.195532875","rc":[{"atb":[[2.28,0]],"id":40642034},{"atl":[[2.9,78.95]],"id":40883678}],"con":true,"img":false}]}
{"op":"mcm","clk":"5323146938","pt":1646327984315,"mc":[{"id":"1.195532875","rc":[{"atb":[[3.85,35.09],[3.95,49.68]],"id":41469398}],"con":true,"img":false}]}
{"op":"mcm","clk":"5323146997","pt":1646327985141,"mc":[{"id":"1.195532875","rc":[{"atb":[[3.8,4.7]],"id":41469398}],"con":true,"img":false}]}
{"op":"mcm","clk":"5323147036","pt":1646327985510,"mc":[{"id":"1.195532875","rc":[{"atb":[[3.8,0]],"id":41469398}],"con":true,"img":false}]}
{"op":"mcm","clk":"5323147090","pt":1646327986028,"mc":[{"id":"1.195532875","rc":[{"atb":[[2.46,0]],"id":35985721}],"con":true,"img":false}]}
{"op":"mcm","clk":"5323147137","pt":1646327986498,"mc":[{"id":"1.195532875","rc":[{"atb":[[2.42,0]],"id":35985721}],"con":true,"img":false}]}
{"op":"mcm","clk":"5323147204","pt":1646327987332,"mc":[{"id":"1.195532875","rc":[{"atb":[[2.42,0]],"id":37306244},{"atb":[[2.36,1.65]],"id":40642034}],"con":true,"img":false}]}
{"op":"mcm","clk":"5323147233","pt":1646327987643,"mc":[{"id":"1.195532875","rc":[{"atb":[[2.34,35.12]],"id":37306244},{"atb":[[2.52,25.48]],"id":35985721},{"atb":[[2.64,7.13]],"id":39614765}],"con":true,"img":false}]}
{"op":"mcm","clk":"5323147245","pt":1646327987747,"mc":[{"id":"1.195532875","rc":[{"atb":[[2.32,67.44],[2.26,117.03]],"id":37306244}],"con":true,"img":false}]}
{"op":"mcm","clk":"5323147330","pt":1646327988742,"mc":[{"id":"1.195532875","rc":[{"atb":[[2.44,8.12]],"id":35985721}],"con":true,"img":false}]}
{"op":"mcm","clk":"5323147360","pt":1646327989006,"mc":[{"id":"1.195532875","rc":[{"atb":[[2.44,0]],"id":35985721}],"con":true,"img":false}]}
{"op":"mcm","clk":"5323147503","pt":1646327990629,"mc":[{"id":"1.195532875","rc":[{"atb":[[2.26,10.03]],"id":40642034}],"con":true,"img":false}]}
{"op":"mcm","clk":"5323147564","pt":1646327991314,"mc":[{"id":"1.195532875","rc":[{"atb":[[1.62,5.96]],"id":40883678}],"con":true,"img":false}]}
{"op":"mcm","clk":"5323147589","pt":1646327991619,"mc":[{"id":"1.195532875","rc":[{"atb":[[1.62,0]],"id":40883678}],"con":true,"img":false}]}
{"op":"mcm","clk":"5323147639","pt":1646327992350,"mc":[{"id":"1.195532875","rc":[{"atb":[[2.62,0]],"id":39614765}],"con":true,"img":false}]}
{"op":"mcm","clk":"5323147648","pt":1646327992453,"mc":[{"id":"1.195532875","rc":[{"atb":[[2.66,1.99]],"id":39614765}],"con":true,"img":false}]}
{"op":"mcm","clk":"5323147679","pt":1646327992821,"mc":[{"id":"1.195532875","rc":[{"atb":[[2.36,73.53]],"id":35985721}],"con":true,"img":false}]}
{"op":"mcm","clk":"5323147725","pt":1646327993352,"mc":[{"id":"1.195532875","rc":[{"atl":[[2.94,128.87]],"id":40883678}],"con":true,"img":false}]}
{"op":"mcm","clk":"5323147787","pt":1646327994121,"mc":[{"id":"1.195532875","rc":[{"atb":[[2.36,26.9]],"id":37306244},{"atb":[[2.28,4.01]],"id":40642034}],"con":true,"img":false}]}
{"op":"mcm","clk":"5323147824","pt":1646327994651,"mc":[{"id":"1.195532875","rc":[{"atb":[[2.26,31.75],[2.34,112.64]],"id":37306244}],"con":true,"img":false}]}
{"op":"mcm","clk":"5323147949","pt":1646327996018,"mc":[{"id":"1.195532875","rc":[{"atb":[[2.42,17.33]],"id":35985721}],"con":true,"img":false}]}
{"op":"mcm","clk":"5323148170","pt":1646327998958,"mc":[{"id":"1.195532875","rc":[{"atb":[[2.34,77.52]],"id":37306244},{"atb":[[2.26,0]],"id":40642034}],"con":true,"img":false}]}
{"op":"mcm","clk":"5323148241","pt":1646327999744,"mc":[{"id":"1.195532875","rc":[{"atb":[[2.64,5.47]],"id":39614765}],"con":true,"img":false}]}
{"op":"mcm","clk":"5323148249","pt":1646327999848,"mc":[{"id":"1.195532875","rc":[{"atb":[[2.68,1.65]],"id":39614765}],"con":true,"img":false}]}
{"op":"mcm","clk":"5323148267","pt":1646328000162,"mc":[{"id":"1.195532875","rc":[{"atb":[[2.58,32.59],[2.56,2.5]],"id":39614765}],"con":true,"img":false}]}
{"op":"mcm","clk":"5323148424","pt":1646328001958,"mc":[{"id":"1.195532875","rc":[{"spn":2.52,"spf":1.0,"id":37306244},{"spn":4.3,"spf":1.0,"id":41469398},{"atb":[[2.32,189.4]],"id":35985721},{"spn":2.6,"spf":1.0,"id":35985721},{"spn":2.64,"spf":1.0,"id":39614765},{"spn":3.28,"spf":"NaN","id":40642034},{"spn":2.22,"spf":"NaN","id":40883678}],"con":true,"img":false}]}
{"op":"mcm","clk":"5323148498","pt":1646328002693,"mc":[{"id":"1.195532875","rc":[{"atb":[[2.24,6.67]],"id":37306244},{"atb":[[4,39.53]],"id":41469398}],"con":true,"img":false}]}
{"op":"mcm","clk":"5323148531","pt":1646328002959,"mc":[{"id":"1.195532875","rc":[{"atb":[[4,26.67]],"id":41469398}],"con":true,"img":false}]}
{"op":"mcm","clk":"5323148558","pt":1646328003170,"mc":[{"id":"1.195532875","rc":[{"atb":[[2.24,2.5]],"id":37306244}],"con":true,"img":false}]}
{"op":"mcm","clk":"5323148755","pt":1646328005287,"mc":[{"id":"1.195532875","rc":[{"atb":[[2.38,34.1]],"id":37306244},{"atl":[[5,6.02],[5.3,91.82],[5.5,26.65],[4.9,2.5],[5.4,0]],"id":35985721},{"atb":[[2.64,0]],"id":39614765},{"atb":[[2.36,7.13]],"id":40642034}],"con":true,"img":false}]}
{"op":"mcm","clk":"5323148764","pt":1646328005394,"mc":[{"id":"1.195532875","rc":[{"atb":[[2.32,0],[2.36,9.63],[2.24,0],[2.16,0]],"id":40642034}],"con":true,"img":false}]}
{"op":"mcm","clk":"5323148775","pt":1646328005493,"mc":[{"id":"1.195532875","rc":[{"atb":[[2.34,0],[2.36,103.16]],"id":37306244},{"atl":[[5.1,17.04],[5.3,5],[4.9,5.61],[5.2,31.2],[5.4,5.82]],"id":35985721},{"atb":[[2.62,3.58]],"id":39614765},{"atb":[[2.34,0]],"id":40642034}],"con":true,"img":false}]}
{"op":"mcm","clk":"5323148783","pt":1646328005549,"mc":[{"id":"1.195532875","rc":[{"atl":[[5,0],[5.5,22.22]],"id":35985721},{"atb":[[2.3,5.48],[2.38,1.99]],"id":40642034}],"con":true,"img":false}]}
{"op":"mcm","clk":"5323148799","pt":1646328005773,"mc":[{"id":"1.195532875","rc":[{"atb":[[2.66,0]],"id":39614765}],"con":true,"img":false}]}
{"op":"mcm","clk":"5323148808","pt":1646328005875,"mc":[{"id":"1.195532875","rc":[{"atb":[[2.6,1.99]],"id":39614765}],"con":true,"img":false}]}
{"op":"mcm","clk":"5323148814","pt":1646328005970,"mc":[{"id":"1.195532875","rc":[{"atl":[[5.4,0]],"id":35985721},{"atb":[[2.3,2.15]],"id":40642034}],"con":true,"img":false}]}
{"op":"mcm","clk":"5323148823","pt":1646328006078,"mc":[{"id":"1.195532875","rc":[{"atb":[[2.62,0],[2.56,25.25]],"id":39614765}],"con":true,"img":false}]}
{"op":"mcm","clk":"5323148830","pt":1646328006183,"mc":[{"id":"1.195532875","rc":[{"atb":[[2.58,10.03]],"id":39614765}],"con":true,"img":false}]}
{"op":"mcm","clk":"5323148849","pt":1646328006394,"mc":[{"id":"1.195532875","rc":[{"atb":[[2.6,15.53]],"id":39614765}],"con":true,"img":false}]}
{"op":"mcm","clk":"5323148864","pt":1646328006551,"mc":[{"id":"1.195532875","rc":[{"atb":[[2.58,2.15]],"id":39614765}],"con":true,"img":false}]}
{"op":"mcm","clk":"5323148951","pt":1646328007453,"mc":[{"id":"1.195532875","rc":[{"atl":[[5.1,26.8],[5.2,21.68]],"id":35985721}],"con":true,"img":false}]}
{"op":"mcm","clk":"5323148977","pt":1646328007784,"mc":[{"id":"1.195532875","rc":[{"atb":[[2.68,0]],"id":39614765},{"atb":[[2.36,7.97]],"id":40642034}],"con":true,"img":false}]}
{"op":"mcm","clk":"5323149000","pt":1646328007980,"mc":[{"id":"1.195532875","rc":[{"atb":[[2.62,1.65]],"id":39614765},{"atb":[[2.4,1.65]],"id":40642034}],"con":true,"img":false}]}
{"op":"mcm","clk":"5323149019","pt":1646328008196,"mc":[{"id":"1.195532875","rc":[{"atb":[[2.5,2.15]],"id":37306244},{"atl":[[5.1,2.44]],"id":37306244},{"atl":[[4.8,2.8]],"id":35985721},{"atb":[[2.6,1.99]],"id":39614765},{"atl":[[4.1,2.67]],"id":40642034},{"atl":[[2.76,2.08]],"id":40883678}],"con":true,"img":false}]}
{"op":"mcm","clk":"5323149045","pt":1646328008360,"mc":[{"id":"1.195532875","rc":[{"atl":[[5.1,21.49],[5,16.12],[5.5,0],[5.4,88.23]],"id":37306244},{"atl":[[4.3,18.13],[4.4,11.76],[4,4.71]],"id":40642034},{"atl":[[2.82,82.36],[2.84,0],[2.76,24.06],[2.86,93.4],[2.74,22.64]],"id":40883678}],"con":true,"img":false}]}
{"op":"mcm","clk":"5323149055","pt":1646328008468,"mc":[{"id":"1.195532875","rc":[{"atl":[[5.2,0],[4.9,2.68]],"id":37306244},{"atl":[[4.5,7.88],[3.95,2.19],[4.2,3.61]],"id":40642034},{"atl":[[2.72,2.16],[2.78,0]],"id":40883678}],"con":true,"img":false}]}
{"op":"mcm","clk":"5323149065","pt":1646328008572,"mc":[{"id":"1.195532875","rc":[{"atl":[[5.6,25.98]],"id":37306244},{"atl":[[4.6,31.22],[3.95,4.86]],"id":40642034},{"atl":[[2.72,24.8],[2.76,2.08],[2.78,3.88]],"id":40883678}],"con":true,"img":false}]}
{"op":"mcm","clk":"5323149076","pt":1646328008675,"mc":[{"id":"1.195532875","rc":[{"atl":[[5.5,11.78]],"id":37306244},{"atl":[[4.2,0]],"id":40642034},{"atl":[[2.78,0]],"id":40883678}],"con":true,"img":false}]}
{"op":"mcm","clk":"5323149084","pt":1646328008781,"mc":[{"id":"1.195532875","rc":[{"atl":[[5.6,21.74]],"id":37306244},{"atl":[[4.6,27.78]],"id":40642034}],"con":true,"img":false}]}
{"op":"mcm","clk":"5323149100","pt":1646328008991,"mc":[{"id":"1.195532875","rc":[{"atl":[[5.1,31.25],[5.4,79.14]],"id":37306244},{"atl":[[5.1,17.04],[5,10]],"id":35985721},{"atl":[[4.4,0],[4.1,15.57]],"id":40642034}],"con":true,"img":false}]}
{"op":"mcm","clk":"5323149120","pt":1646328009199,"mc":[{"id":"1.195532875","rc":[{"atl":[[5.5,0]],"id":37306244},{"atl":[[4.5,2.5]],"id":40642034},{"atl":[[2.86,55.66]],"id":40883678}],"con":true,"img":false}]}
{"op":"mcm","clk":"5323149162","pt":1646328009567,"mc":[{"id":"1.195532875","rc":[{"atb":[[2.36,76.26]],"id":37306244},{"atb":[[2.28,0]],"id":40642034}],"con":true,"img":false}]}
{"op":"mcm","clk":"5323149278","pt":1646328011080,"mc":[{"id":"1.195532875","rc":[{"atb":[[2.42,0]],"id":35985721},{"atb":[[2.5,31.37]],"id":39614765}],"con":true,"img":false}]}
{"op":"mcm","clk":"5323149303","pt":1646328011398,"mc":[{"id":"1.195532875","rc":[{"atl":[[4.8,8.41],[5.1,0]],"id":35985721}],"con":true,"img":false}]}
{"op":"mcm","clk":"5323149316","pt":1646328011552,"mc":[{"id":"1.195532875","rc":[{"atl":[[2.82,60.38],[2.76,24.81]],"id":40883678}],"con":true,"img":false}]}
{"op":"mcm","clk":"5323149443","pt":1646328013193,"mc":[{"id":"1.195532875","rc":[{"atb":[[1.56,178.57],[1.51,0]],"id":40883678}],"con":true,"img":false}]}
{"op":"mcm","clk":"5323149493","pt":1646328013776,"mc":[{"id":"1.195532875","rc":[{"atb":[[2.36,2.5]],"id":40642034},{"atb":[[1.67,1.99]],"id":40883678}],"con":true,"img":false}]}
{"op":"mcm","clk":"5323149502","pt":1646328013882,"mc":[{"id":"1.195532875","rc":[{"atb":[[1.64,47.71],[1.63,125.5],[1.66,37.73]],"id":40883678}],"con":true,"img":false}]}
{"op":"mcm","clk":"5323149519","pt":1646328014091,"mc":[{"id":"1.195532875","rc":[{"atb":[[2.6,4.49],[2.48,0],[2.56,22.75],[2.4,0]],"id":39614765}],"con":true,"img":false}]}
{"op":"mcm","clk":"5323149528","pt":1646328014195,"mc":[{"id":"1.195532875","rc":[{"atl":[[4.9,18.8]],"id":37306244}],"con":true,"img":false}]}
{"op":"mcm","clk":"5323149539","pt":1646328014299,"mc":[{"id":"1.195532875","rc":[{"atl":[[5.1,12.2]],"id":37306244}],"con":true,"img":false}]}
{"op":"mcm","clk":"5323149550","pt":1646328014405,"mc":[{"id":"1.195532875","rc":[{"atb":[[2.4,4.96]],"id":37306244},{"atb":[[1.86,14.96]],"id":40642034}],"con":true,"img":false}]}
{"op":"mcm","clk":"5323149563","pt":1646328014563,"mc":[{"id":"1.195532875","rc":[{"atb":[[2.36,15.3],[2.38,69.5]],"id":37306244}],"con":true,"img":false}]}
{"op":"mcm","clk":"5323149586","pt":1646328014884,"mc":[{"id":"1.195532875","rc":[{"atb":[[2.36,0]],"id":37306244}],"con":true,"img":false}]}
{"op":"mcm","clk":"5323149773","pt":1646328016991,"mc":[{"id":"1.195532875","rc":[{"atb":[[2.42,17.33]],"id":35985721}],"con":true,"img":false}]}
{"op":"mcm","clk":"5323149783","pt":1646328017096,"mc":[{"id":"1.195532875","rc":[{"atl":[[5.1,14.7],[5.4,76.64]],"id":37306244}],"con":true,"img":false}]}
{"op":"mcm","clk":"5323149845","pt":1646328017779,"mc":[{"id":"1.195532875","rc":[{"atl":[[5.3,23.26]],"id":37306244},{"atb":[[2.28,195.31]],"id":35985721},{"atl":[[5.2,45.49]],"id":35985721},{"atl":[[4.3,48.43]],"id":40642034}],"con":true,"img":false}]}
{"op":"mcm","clk":"5323149871","pt":1646328018096,"mc":[{"id":"1.195532875","rc":[{"atl":[[5,38.04],[4.7,5.83]],"id":35985721}],"con":true,"img":false}]}
{"op":"mcm","clk":"5323149881","pt":1646328018201,"mc":[{"id":"1.195532875","rc":[{"atl":[[5.2,26.15]],"id":35985721}],"con":true,"img":false}]}
{"op":"mcm","clk":"5323149889","pt":1646328018303,"mc":[{"id":"1.195532875","rc":[{"atl":[[4.6,2.57],[4.9,2.5]],"id":35985721}],"con":true,"img":false}]}
{"op":"mcm","clk":"5323149904","pt":1646328018464,"mc":[{"id":"1.195532875","rc":[{"atl":[[4.8,2.8],[4.6,8.4]],"id":35985721}],"con":true,"img":false}]}
{"op":"mcm","clk":"5323149921","pt":1646328018673,"mc":[{"id":"1.195532875","rc":[{"atl":[[5.6,0],[5.8,0],[6,0]],"id":37306244},{"atl":[[4.8,13.33],[5,28.04],[5.5,0],[5.7,0],[5.9,0]],"id":35985721},{"atl":[[4.8,0],[4.6,0],[5,0]],"id":40642034}],"con":true,"img":false}]}
{"op":"mcm","clk":"5323150099","pt":1646328020376,"mc":[{"id":"1.195532875","rc":[{"atl":[[2.8,55.56]],"id":40883678}],"con":true,"img":false}]}
{"op":"mcm","clk":"5323150133","pt":1646328020781,"mc":[{"id":"1.195532875","rc":[{"atb":[[2.38,35.4]],"id":37306244},{"atb":[[1.87,35.58]],"id":40642034},{"atb":[[1.67,61.58]],"id":40883678}],"con":true,"img":false}]}
{"op":"mcm","clk":"5323150147","pt":1646328020992,"mc":[{"id":"1.195532875","rc":[{"atl":[[4.8,14.74],[5.1,76.34],[5.4,2.15]],"id":37306244},{"atl":[[4.3,33.91],[3.95,10.27],[4.1,32.29]],"id":40642034},{"atl":[[2.82,0],[2.76,149.91],[2.7,46.91]],"id":40883678}],"con":true,"img":false}]}
{"op":"mcm","clk":"5323150162","pt":1646328021095,"mc":[{"id":"1.195532875","rc":[{"atl":[[4.7,19.06]],"id":37306244},{"atl":[[2.72,2.16],[2.68,27.05]],"id":40883678}],"con":true,"img":false}]}
{"op":"mcm","clk":"5323150169","pt":1646328021209,"mc":[{"id":"1.195532875","rc":[{"atl":[[5,0],[4.9,2.68]],"id":37306244},{"atl":[[4,0]],"id":40642034},{"atl":[[2.72,60.3],[2.74,0],[2.68,2.25]],"id":40883678}],"con":true,"img":false}]}
{"op":"mcm","clk":"5323150177","pt":1646328021330,"mc":[{"id":"1.195532875","rc":[{"atl":[[4.8,30.86],[4.7,2.94]],"id":37306244},{"atb":[[1.65,4.25]],"id":40883678}],"con":true,"img":false}]}
{"op":"mcm","clk":"5323150185","pt":1646328021409,"mc":[{"id":"1.195532875","rc":[{"atb":[[2.3,0],[1.9,2.15]],"id":40642034},{"atb":[[1.7,2.15],[1.66,35.58]],"id":40883678}],"con":true,"img":false}]}
{"op":"mcm","clk":"5323150206","pt":1646328021571,"mc":[{"id":"1.195532875","rc":[{"atl":[[4.9,12.94]],"id":37306244},{"atb":[[1.9,19.55]],"id":40642034},{"atb":[[1.65,0]],"id":40883678}],"con":true,"img":false}]}
{"op":"mcm","clk":"5323150223","pt":1646328021778,"mc":[{"id":"1.195532875","rc":[{"atb":[[1.67,59.59]],"id":40883678}],"con":true,"img":false}]}
{"op":"mcm","clk":"5323150229","pt":1646328021896,"mc":[{"id":"1.195532875","rc":[{"atb":[[1.71,1.99]],"id":40883678}],"con":true,"img":false}]}
{"op":"mcm","clk":"5323150344","pt":1646328023607,"mc":[{"id":"1.195532875","rc":[{"atb":[[1.86,0]],"id":40642034},{"atb":[[1.64,0]],"id":40883678}],"con":true,"img":false}]}
{"op":"mcm","clk":"5323150361","pt":1646328023770,"mc":[{"id":"1.195532875","rc":[{"atb":[[1.62,3.46]],"id":40883678}],"con":true,"img":false}]}
{"op":"mcm","clk":"5323150380","pt":1646328023974,"mc":[{"id":"1.195532875","rc":[{"atb":[[1.62,0]],"id":40883678}],"con":true,"img":false}]}
{"op":"mcm","clk":"5323150449","pt":1646328024875,"mc":[{"id":"1.195532875","rc":[{"atl":[[2.72,83.56],[2.94,0],[2.76,127.18],[2.86,1.9],[2.9,0]],"id":40883678}],"con":true,"img":false}]}
{"op":"mcm","clk":"5323150568","pt":1646328026397,"mc":[{"id":"1.195532875","rc":[{"atb":[[1.63,63.49],[1.66,138.69]],"id":40883678}],"con":true,"img":false}]}
{"op":"mcm","clk":"5323150578","pt":1646328026499,"mc":[{"id":"1.195532875","rc":[{"atl":[[4.5,45.36]],"id":40642034}],"con":true,"img":false}]}
{"op":"mcm","clk":"5323150596","pt":1646328026710,"mc":[{"id":"1.195532875","rc":[{"atl":[[4.3,93.57],[4.1,15.57]],"id":40642034}],"con":true,"img":false}]}
{"op":"mcm","clk":"5323150611","pt":1646328026916,"mc":[{"id":"1.195532875","rc":[{"atb":[[2.42,10.49]],"id":37306244},{"atb":[[1.87,0]],"id":40642034},{"atb":[[1.67,0]],"id":40883678}],"con":true,"img":false}]}
{"op":"mcm","clk":"5323150618","pt":1646328027018,"mc":[{"id":"1.195532875","rc":[{"atl":[[2.72,25.42],[2.68,49.16]],"id":40883678}],"con":true,"img":false}]}
{"op":"mcm","clk":"5323150627","pt":1646328027072,"mc":[{"id":"1.195532875","rc":[{"atb":[[2.4,24.27],[2.38,0]],"id":37306244}],"con":true,"img":false}]}
{"op":"mcm","clk":"5323150649","pt":1646328027284,"mc":[{"id":"1.195532875","rc":[{"atl":[[5,53.04]],"id":35985721}],"con":true,"img":false}]}
{"op":"mcm","clk":"5323150750","pt":1646328028381,"mc":[{"id":"1.195532875","rc":[{"atb":[[1.91,13.13]],"id":40642034},{"atb":[[1.71,4.89]],"id":40883678}],"con":true,"img":false}]}
{"op":"mcm","clk":"5323150864","pt":1646328030175,"mc":[{"id":"1.195532875","rc":[{"atl":[[5.1,100.73]],"id":37306244}],"con":true,"img":false}]}
{"op":"mcm","clk":"5323150872","pt":1646328030279,"mc":[{"id":"1.195532875","rc":[{"atl":[[5.1,90.97]],"id":37306244}],"con":true,"img":false}]}
{"op":"mcm","clk":"5323150893","pt":1646328030488,"mc":[{"id":"1.195532875","rc":[{"atl":[[4.8,47.09],[4.5,5.99]],"id":35985721}],"con":true,"img":false}]}
{"op":"mcm","clk":"5323150899","pt":1646328030599,"mc":[{"id":"1.195532875","rc":[{"atl":[[4.8,41.79],[4.6,2.57],[5,25],[4.4,5.99],[4.7,0]],"id":35985721}],"con":true,"img":false}]}
{"op":"mcm","clk":"5323150908","pt":1646328030703,"mc":[{"id":"1.195532875","rc":[{"atl":[[4.4,8.26]],"id":35985721}],"con":true,"img":false}]}
{"op":"mcm","clk":"5323150916","pt":1646328030810,"mc":[{"id":"1.195532875","rc":[{"atb":[[2.4,19.31]],"id":37306244},{"atl":[[4.5,17.97],[4.4,2.27]],"id":35985721}],"con":true,"img":false}]}
{"op":"mcm","clk":"5323150925","pt":1646328030915,"mc":[{"id":"1.195532875","rc":[{"atl":[[4.1,1.55]],"id":35985721}],"con":true,"img":false}]}
{"op":"mcm","clk":"5323150945","pt":1646328031079,"mc":[{"id":"1.195532875","rc":[{"atl":[[4,2.11],[4.5,5.99],[5.2,23.81],[4.2,3.1]],"id":35985721}],"con":true,"img":false}]}
{"op":"mcm","clk":"5323150999","pt":1646328031813,"mc":[{"id":"1.195532875","rc":[{"atb":[[1.94,2.15],[1.9,17.4]],"id":40642034}],"con":true,"img":false}]}
{"op":"mcm","clk":"5323151014","pt":1646328032025,"mc":[{"id":"1.195532875","rc":[{"atl":[[4.2,7.56]],"id":40642034}],"con":true,"img":false}]}
{"op":"mcm","clk":"5323151050","pt":1646328032499,"mc":[{"id":"1.195532875","rc":[{"atl":[[4.2,0]],"id":40642034}],"con":true,"img":false}]}
{"op":"mcm","clk":"5323151058","pt":1646328032613,"mc":[{"id":"1.195532875","rc":[{"atl":[[2.7,61.79]],"id":40883678}],"con":true,"img":false}]}
{"op":"mcm","clk":"5323151083","pt":1646328032975,"mc":[{"id":"1.195532875","rc":[{"atl":[[5.1,3]],"id":35985721},{"atb":[[1.92,31.03]],"id":40642034},{"atb":[[1.64,17.1]],"id":40883678},{"atl":[[2.7,46.91]],"id":40883678}],"con":true,"img":false}]}
{"op":"mcm","clk":"5323151095","pt":1646328033184,"mc":[{"id":"1.195532875","rc":[{"atl":[[5.3,29.16]],"id":37306244}],"con":true,"img":false}]}
{"op":"mcm","clk":"5323151102","pt":1646328033293,"mc":[{"id":"1.195532875","rc":[{"atl":[[5.1,29.33],[4.6,10.07],[4.9,59.8]],"id":37306244},{"atl":[[5.1,0]],"id":35985721},{"atl":[[2.72,170.08],[2.66,48.19],[2.76,9.18]],"id":40883678}],"con":true,"img":false}]}
{"op":"mcm","clk":"5323151111","pt":1646328033400,"mc":[{"id":"1.195532875","rc":[{"atb":[[2.44,4.19]],"id":37306244},{"atl":[[4.8,14.74],[4.5,13.32]],"id":37306244},{"atl":[[2.64,50.52],[2.86,0],[2.68,2.25]],"id":40883678}],"con":true,"img":false}]}
{"op":"mcm","clk":"5323151120","pt":1646328033508,"mc":[{"id":"1.195532875","rc":[{"atl":[[4.8,0],[5.3,23.26],[4.9,65.06]],"id":37306244},{"atl":[[2.7,23.53],[2.76,2.08]],"id":40883678}],"con":true,"img":false}]}
{"op":"mcm","clk":"5323151125","pt":1646328033609,"mc":[{"id":"1.195532875","rc":[{"atb":[[2.4,0]],"id":37306244}],"con":true,"img":false}]}
{"op":"mcm","clk":"5323151133","pt":1646328033722,"mc":[{"id":"1.195532875","rc":[{"atl":[[4.9,59.8]],"id":37306244}],"con":true,"img":false}]}
{"op":"mcm","clk":"5323151152","pt":1646328033934,"mc":[{"id":"1.195532875","rc":[{"atb":[[1.94,19.55],[1.9,0]],"id":40642034}],"con":true,"img":false}]}
{"op":"mcm","clk":"5323151258","pt":1646328035104,"mc":[{"id":"1.195532875","rc":[{"atl":[[4.7,67.57]],"id":40642034}],"con":true,"img":false}]}
{"op":"mcm","clk":"5323151290","pt":1646328035521,"mc":[{"id":"1.195532875","rc":[{"atb":[[2.42,0]],"id":35985721}],"con":true,"img":false}]}
{"op":"mcm","clk":"5323151300","pt":1646328035630,"mc":[{"id":"1.195532875","rc":[{"atb":[[1.91,0]],"id":40642034},{"atb":[[1.71,1.99]],"id":40883678}],"con":true,"img":false}]}
{"op":"mcm","clk":"5323151317","pt":1646328035789,"mc":[{"id":"1.195532875","rc":[{"atb":[[1.64,98.72],[1.66,35.58]],"id":40883678}],"con":true,"img":false}]}
{"op":"mcm","clk":"5323151324","pt":1646328035897,"mc":[{"id":"1.195532875","rc":[{"atl":[[4.4,14.03]],"id":35985721}],"con":true,"img":false}]}
{"op":"mcm","clk":"5323151395","pt":1646328036691,"mc":[{"id":"1.195532875","rc":[{"atl":[[4.7,13.75]],"id":37306244},{"atl":[[2.68,26.06]],"id":40883678}],"con":true,"img":false}]}
{"op":"mcm","clk":"5323151559","pt":1646328038620,"mc":[{"id":"1.195532875","rc":[{"atb":[[2.42,0]],"id":37306244},{"atb":[[1.92,0]],"id":40642034}],"con":true,"img":false}]}
{"op":"mcm","clk":"5323151595","pt":1646328039092,"mc":[{"id":"1.195532875","rc":[{"atb":[[3.95,47.18],[4.1,2.5]],"id":41469398}],"con":true,"img":false}]}
{"op":"mcm","clk":"5323151603","pt":1646328039198,"mc":[{"id":"1.195532875","rc":[{"atb":[[4,60.98],[3.95,13.56]],"id":41469398}],"con":true,"img":false}]}
{"op":"mcm","clk":"5323151616","pt":1646328039411,"mc":[{"id":"1.195532875","rc":[{"atb":[[2.32,96.68]],"id":37306244},{"atb":[[3.95,24.77]],"id":41469398}],"con":true,"img":false}]}
{"op":"mcm","clk":"5323151712","pt":1646328040619,"mc":[{"id":"1.195532875","rc":[{"atb":[[1.95,11.67]],"id":40642034},{"atb":[[1.67,4.55]],"id":40883678}],"con":true,"img":false}]}
{"op":"mcm","clk":"5323151723","pt":1646328040725,"mc":[{"id":"1.195532875","rc":[{"atb":[[3.95,13.56]],"id":41469398},{"atb":[[1.66,112.63]],"id":40883678}],"con":true,"img":false}]}
{"op":"mcm","clk":"5323151734","pt":1646328040855,"mc":[{"id":"1.195532875","rc":[{"atb":[[1.64,17.1]],"id":40883678}],"con":true,"img":false}]}
{"op":"mcm","clk":"5323151805","pt":1646328041749,"mc":[{"id":"1.195532875","rc":[{"atb":[[2.42,17.33]],"id":35985721},{"atb":[[1.64,0]],"id":40883678}],"con":true,"img":false}]}
{"op":"mcm","clk":"5323151852","pt":1646328042435,"mc":[{"id":"1.195532875","rc":[{"atb":[[2.38,2.15]],"id":37306244}],"con":true,"img":false}]}
{"op":"mcm","clk":"5323151861","pt":1646328042543,"mc":[{"id":"1.195532875","rc":[{"atb":[[2.5,0]],"id":37306244}],"con":true,"img":false}]}
{"op":"mcm","clk":"5323151870","pt":1646328042646,"mc":[{"id":"1.195532875","rc":[{"atl":[[4.8,13.33],[4.4,30.63]],"id":35985721}],"con":true,"img":false}]}
{"op":"mcm","clk":"5323151896","pt":1646328042906,"mc":[{"id":"1.195532875","rc":[{"atb":[[2.44,0]],"id":37306244}],"con":true,"img":false}]}
{"op":"mcm","clk":"5323151904","pt":1646328043012,"mc":[{"id":"1.195532875","rc":[{"atb":[[2.38,19.69]],"id":37306244}],"con":true,"img":false}]}
{"op":"mcm","clk":"5323151914","pt":1646328043117,"mc":[{"id":"1.195532875","rc":[{"atb":[[2.24,8.85]],"id":37306244}],"con":true,"img":false}]}
{"op":"mcm","clk":"5323151923","pt":1646328043223,"mc":[{"id":"1.195532875","rc":[{"atb":[[2.42,3.47]],"id":37306244}],"con":true,"img":false}]}
{"op":"mcm","clk":"5323151934","pt":1646328043324,"mc":[{"id":"1.195532875","rc":[{"atb":[[2.24,6.74]],"id":37306244}],"con":true,"img":false}]}
{"op":"mcm","clk":"5323151941","pt":1646328043431,"mc":[{"id":"1.195532875","rc":[{"atb":[[2.42,0]],"id":37306244}],"con":true,"img":false}]}
{"op":"mcm","clk":"5323151952","pt":1646328043537,"mc":[{"id":"1.195532875","rc":[{"atb":[[2.24,2.5]],"id":37306244}],"con":true,"img":false}]}
{"op":"mcm","clk":"5323152031","pt":1646328044329,"mc":[{"id":"1.195532875","rc":[{"atl":[[4.6,30.35]],"id":35985721}],"con":true,"img":false}]}
{"op":"mcm","clk":"5323152092","pt":1646328044958,"mc":[{"id":"1.195532875","rc":[{"atb":[[2.26,75.64]],"id":37306244}],"con":true,"img":false}]}
{"op":"mcm","clk":"5323152101","pt":1646328045011,"mc":[{"id":"1.195532875","rc":[{"atb":[[2.32,67.44]],"id":37306244}],"con":true,"img":false}]}
{"op":"mcm","clk":"5323152110","pt":1646328045116,"mc":[{"id":"1.195532875","rc":[{"atl":[[4.9,75.18]],"id":37306244},{"atl":[[2.72,204.96]],"id":40883678}],"con":true,"img":false}]}
{"op":"mcm","clk":"5323152121","pt":1646328045220,"mc":[{"id":"1.195532875","rc":[{"atb":[[2.34,14.3]],"id":37306244},{"atl":[[5.2,0]],"id":35985721},{"atb":[[1.96,27.38]],"id":40642034}],"con":true,"img":false}]}
{"op":"mcm","clk":"5323152132","pt":1646328045329,"mc":[{"id":"1.195532875","rc":[{"atl":[[4.7,69.87]],"id":37306244}],"con":true,"img":false}]}
{"op":"mcm","clk":"5323152144","pt":1646328045433,"mc":[{"id":"1.195532875","rc":[{"atl":[[4.9,28.32],[4.4,20.3]],"id":37306244},{"atl":[[2.72,60.3],[2.62,22.96],[2.68,174.56]],"id":40883678}],"con":true,"img":false}]}
{"op":"mcm","clk":"5323152151","pt":1646328045540,"mc":[{"id":"1.195532875","rc":[{"atl":[[4.5,3.25],[4.3,16.93],[4.6,0],[5.4,0]],"id":37306244},{"atl":[[2.64,2.33],[2.6,50.63],[2.66,0]],"id":40883678}],"con":true,"img":false}]}
{"op":"mcm","clk":"5323152164","pt":1646328045643,"mc":[{"id":"1.195532875","rc":[{"atl":[[2.64,52.85]],"id":40883678}],"con":true,"img":false}]}
{"op":"mcm","clk":"5323152176","pt":1646328045750,"mc":[{"id":"1.195532875","rc":[{"atl":[[4.3,3.61],[4.4,33.62]],"id":37306244},{"atl":[[2.6,2.44]],"id":40883678}],"con":true,"img":false}]}
{"op":"mcm","clk":"5323152204","pt":1646328046075,"mc":[{"id":"1.195532875","rc":[{"atb":[[1.96,59.68],[1.94,2.15]],"id":40642034}],"con":true,"img":false}]}
{"op":"mcm","clk":"5323152286","pt":1646328047023,"mc":[{"id":"1.195532875","rc":[{"atl":[[4.5,14.68]],"id":37306244}],"con":true,"img":false}]}
{"op":"mcm","clk":"5323152292","pt":1646328047128,"mc":[{"id":"1.195532875","rc":[{"atl":[[4.5,43.25],[4.4,20.3],[4.7,59.06]],"id":37306244}],"con":true,"img":false}]}
{"op":"mcm","clk":"5323152298","pt":1646328047232,"mc":[{"id":"1.195532875","rc":[{"atl":[[4.5,14.68],[4.2,14.68]],"id":37306244}],"con":true,"img":false}]}
{"op":"mcm","clk":"5323152301","pt":1646328047337,"mc":[{"id":"1.195532875","rc":[{"atl":[[4.1,4.04]],"id":37306244}],"con":true,"img":false}]}
{"op":"mcm","clk":"5323152308","pt":1646328047442,"mc":[{"id":"1.195532875","rc":[{"atl":[[4,4.04],[4.2,0]],"id":37306244}],"con":true,"img":false}]}
{"op":"mcm","clk":"5323152319","pt":1646328047547,"mc":[{"id":"1.195532875","rc":[{"atl":[[3.95,2.19]],"id":37306244}],"con":true,"img":false}]}
{"op":"mcm","clk":"5323152328","pt":1646328047651,"mc":[{"id":"1.195532875","rc":[{"atb":[[2.52,0]],"id":37306244}],"con":true,"img":false}]}
{"op":"mcm","clk":"5323152341","pt":1646328047813,"mc":[{"id":"1.195532875","rc":[{"atb":[[2.4,1.65],[2.32,0],[2.26,115.04]],"id":37306244}],"con":true,"img":false}]}
{"op":"mcm","clk":"5323152353","pt":1646328048022,"mc":[{"id":"1.195532875","rc":[{"atb":[[2.4,16.6]],"id":37306244},{"atb":[[1.95,0]],"id":40642034}],"con":true,"img":false}]}
{"op":"mcm","clk":"5323152381","pt":1646328048448,"mc":[{"id":"1.195532875","rc":[{"atb":[[1.71,8.21]],"id":40883678}],"con":true,"img":false}]}
{"op":"mcm","clk":"5323152398","pt":1646328048654,"mc":[{"id":"1.195532875","rc":[{"atb":[[1.67,20.51],[1.66,35.58]],"id":40883678},{"atl":[[2.6,25.4],[2.64,2.33]],"id":40883678}],"con":true,"img":false}]}
{"op":"mcm","clk":"5323152554","pt":1646328050357,"mc":[{"id":"1.195532875","rc":[{"atl":[[4,5.19]],"id":35985721}],"con":true,"img":false}]}
{"op":"mcm","clk":"5323152576","pt":1646328050516,"mc":[{"id":"1.195532875","rc":[{"atl":[[4.5,0]],"id":35985721}],"con":true,"img":false}]}
{"op":"mcm","clk":"5323152606","pt":1646328050836,"mc":[{"id":"1.195532875","rc":[{"atl":[[4.5,3.25],[4.1,16.94]],"id":37306244},{"atb":[[2.6,13.87]],"id":39614765},{"atb":[[1.97,10.95]],"id":40642034},{"atl":[[2.64,26.72],[2.68,150.75]],"id":40883678}],"con":true,"img":false}]}
{"op":"mcm","clk":"5323152629","pt":1646328051048,"mc":[{"id":"1.195532875","rc":[{"atb":[[2.6,4.48]],"id":39614765}],"con":true,"img":false}]}
{"op":"mcm","clk":"5323152647","pt":1646328051260,"mc":[{"id":"1.195532875","rc":[{"atb":[[2.58,11.53]],"id":39614765}],"con":true,"img":false}]}
{"op":"mcm","clk":"5323152659","pt":1646328051367,"mc":[{"id":"1.195532875","rc":[{"atb":[[2.26,71.15],[2.34,52.94]],"id":37306244}],"con":true,"img":false}]}
