{"op":"mcm","clk":"5345904403","pt":1646079078744,"mc":[{"id":"1.195395452","marketDefinition":{"bspMarket":false,"turnInPlayEnabled":false,"persistenceEnabled":false,"marketBaseRate":5.0,"eventId":"31270459","eventTypeId":"4339","numberOfWinners":3,"bettingType":"ODDS","marketType":"PLACE","marketTime":"2022-03-01T01:25:00.000Z","suspendTime":"2022-03-01T01:25:00.000Z","bspReconciled":false,"complete":true,"inPlay":false,"crossMatching":false,"runnersVoidable":false,"numberOfActiveRunners":8,"betDelay":0,"status":"OPEN","runners":[{"status":"ACTIVE","sortPriority":1,"id":40251221,"name":"1. Elsa Blueblood"},{"status":"ACTIVE","sortPriority":2,"id":42492389,"name":"3. Emilys Perfect"},{"status":"ACTIVE","sortPriority":3,"id":43154431,"name":"4. Lonely Gemma"},{"status":"ACTIVE","sortPriority":4,"id":39979879,"name":"5. Goldstar Smiles"},{"status":"ACTIVE","sortPriority":5,"id":27151693,"name":"6. Hustle Ace"},{"status":"ACTIVE","sortPriority":6,"id":41921674,"name":"7. Sozins Queen"},{"status":"ACTIVE","sortPriority":7,"id":36899924,"name":"8. Horse Range Gold"},{"status":"ACTIVE","sortPriority":8,"id":39722911,"name":"9. Know Pops"}],"regulators":["MR_INT"],"venue":"Addington","countryCode":"NZ","discountAllowed":false,"timezone":"NZ","openDate":"2022-02-28T23:02:00.000Z","version":4380660699,"name":"To Be Placed","eventName":"Addington (NZL) 1st Mar"},"rc":[],"con":true,"img":false}]}
{"op":"mcm","clk":"5345904626","pt":1646079080740,"mc":[{"id":"1.195395452","marketDefinition":{"bspMarket":false,"turnInPlayEnabled":false,"persistenceEnabled":false,"marketBaseRate":5.0,"eventId":"31270459","eventTypeId":"4339","numberOfWinners":3,"bettingType":"ODDS","marketType":"PLACE","marketTime":"2022-03-01T01:25:00.000Z","suspendTime":"2022-03-01T01:25:00.000Z","bspReconciled":false,"complete":true,"inPlay":false,"crossMatching":false,"runnersVoidable":false,"numberOfActiveRunners":8,"betDelay":0,"status":"OPEN","runners":[{"status":"ACTIVE","sortPriority":1,"id":40251221,"name":"1. Elsa Blueblood"},{"status":"ACTIVE","sortPriority":2,"id":42492389,"name":"3. Emilys Perfect"},{"status":"ACTIVE","sortPriority":3,"id":43154431,"name":"4. Lonely Gemma"},{"status":"ACTIVE","sortPriority":4,"id":39979879,"name":"5. Goldstar Smiles"},{"status":"ACTIVE","sortPriority":5,"id":27151693,"name":"6. Hustle Ace"},{"status":"ACTIVE","sortPriority":6,"id":41921674,"name":"7. Sozins Queen"},{"status":"ACTIVE","sortPriority":7,"id":36899924,"name":"8. Horse Range Gold"},{"status":"ACTIVE","sortPriority":8,"id":39722911,"name":"9. Know Pops"}],"regulators":["MR_INT"],"venue":"Addington","countryCode":"NZ","discountAllowed":true,"timezone":"NZ","openDate":"2022-02-28T23:02:00.000Z","version":4380660699,"name":"To Be Placed","eventName":"Addington (NZL) 1st Mar"},"rc":[],"con":true,"img":false}]}
{"op":"mcm","clk":"5346140410","pt":1646081720446,"mc":[{"id":"1.195395452","rc":[{"atb":[[1.8,75.1],[1.7,171.66],[1.75,160.22]],"id":41921674},{"atl":[[3.6,4.62],[6.4,4.44],[5.2,5.72],[4.2,3.75],[8.4,6.49]],"id":41921674},{"atb":[[2.4,85.83],[2.5,40.05],[2.3,92.43]],"id":40251221},{"atl":[[8,1.71],[10,2.66],[20,2.52],[6,2.4],[15,1.71]],"id":40251221},{"atb":[[2,120.16],[2.2,50.07],[2.1,109.24]],"id":36899924},{"atl":[[17.5,2.91],[9,3],[5.5,2.66],[12.5,2.08],[7,2]],"id":36899924},{"atb":[[2,60.08],[1.9,133.52],[1.95,126.49]],"id":39979879},{"atl":[[5.1,2.92],[6.2,2.31],[10.5,2.52],[8.2,3.33],[15.5,3.31]],"id":39979879},{"atb":[[2.4,42.91],[2.3,92.43],[2.2,100.14]],"id":39722911},{"atl":[[9.6,2.79],[19,2.66],[5.8,2.5],[7.6,1.81],[14,1.85]],"id":39722911},{"atb":[[1.01,30042.22]],"id":42492389},{"atl":[[2.06,11.33],[2.46,16.46],[2.66,28.95],[2.26,19.07],[1.93,12.92]],"id":42492389},{"atb":[[2.4,42.91],[2.3,92.43],[2.2,100.14]],"id":43154431},{"atl":[[9.6,2.79],[19,2.66],[5.8,2.5],[7.6,1.81],[14,1.85]],"id":43154431},{"atb":[[2.4,85.83],[2.5,80.11],[2.6,37.55]],"id":27151693},{"atl":[[6.2,2.31],[10.5,2.52],[21,2.4],[8.2,1.66],[15.5,1.65]],"id":27151693}],"con":true,"img":false}]}
{"op":"mcm","clk":"5346143128","pt":1646081761493,"mc":[{"id":"1.195395452","rc":[{"atb":[[1.8,0],[1.7,0],[1.75,0]],"id":41921674},{"atl":[[3.6,0],[6.4,0],[5.2,0],[4.2,0],[8.4,0]],"id":41921674},{"atb":[[2.4,0],[2.5,0],[2.3,0]],"id":40251221},{"atl":[[8,0],[10,0],[20,0],[6,0],[15,0]],"id":40251221},{"atb":[[2,0],[2.2,0],[2.1,0]],"id":36899924},{"atl":[[17.5,0],[9,0],[5.5,0],[12.5,0],[7,0]],"id":36899924},{"atb":[[2,0],[1.9,0],[1.95,0]],"id":39979879},{"atl":[[5.1,0],[6.2,0],[10.5,0],[8.2,0],[15.5,0]],"id":39979879},{"atb":[[2.4,0],[2.3,0],[2.2,0]],"id":39722911},{"atl":[[9.6,0],[19,0],[5.8,0],[7.6,0],[14,0]],"id":39722911},{"atb":[[1.01,0]],"id":42492389},{"atl":[[2.06,0],[2.46,0],[2.66,0],[2.26,0],[1.93,0]],"id":42492389},{"atb":[[2.4,0],[2.3,0],[2.2,0]],"id":43154431},{"atl":[[9.6,0],[19,0],[5.8,0],[7.6,0],[14,0]],"id":43154431},{"atb":[[2.4,0],[2.5,0],[2.6,0]],"id":27151693},{"atl":[[6.2,0],[10.5,0],[21,0],[8.2,0],[15.5,0]],"id":27151693}],"con":true,"img":false}]}
{"op":"mcm","clk":"5346143339","pt":1646081763933,"mc":[{"id":"1.195395452","rc":[{"atb":[[1.8,75.1],[1.7,171.66],[1.75,160.22]],"id":41921674},{"atl":[[3.6,4.62],[6.4,4.44],[5.2,5.72],[4.2,3.75],[8.4,6.49]],"id":41921674},{"atb":[[2.4,85.83],[2.5,40.05],[2.3,92.43]],"id":40251221},{"atl":[[8,1.71],[10,2.66],[20,2.52],[6,2.4],[15,1.71]],"id":40251221},{"atb":[[2,120.16],[2.2,50.07],[2.1,109.24]],"id":36899924},{"atl":[[17.5,2.91],[9,3],[5.5,2.66],[12.5,2.08],[7,2]],"id":36899924},{"atb":[[2,60.08],[1.9,133.52],[1.95,126.49]],"id":39979879},{"atl":[[5.1,2.92],[6.2,2.31],[10.5,2.52],[8.2,3.33],[15.5,3.31]],"id":39979879},{"atb":[[2.4,42.91],[2.3,92.43],[2.2,100.14]],"id":39722911},{"atl":[[9.6,2.79],[19,2.66],[5.8,2.5],[7.6,1.81],[14,1.85]],"id":39722911},{"atb":[[1.01,30042.22]],"id":42492389},{"atl":[[2.06,11.33],[2.46,16.46],[2.66,28.95],[2.26,19.07],[1.93,12.92]],"id":42492389},{"atb":[[2.4,42.91],[2.3,92.43],[2.2,100.14]],"id":43154431},{"atl":[[9.6,2.79],[19,2.66],[5.8,2.5],[7.6,1.81],[14,1.85]],"id":43154431},{"atb":[[2.4,85.83],[2.5,80.11],[2.6,37.55]],"id":27151693},{"atl":[[6.2,2.31],[10.5,2.52],[21,2.4],[8.2,1.66],[15.5,1.65]],"id":27151693}],"con":true,"img":false}]}
{"op":"mcm","clk":"5346183401","pt":1646082292757,"mc":[{"id":"1.195395452","rc":[{"atb":[[1.8,0],[1.7,0],[1.75,0]],"id":41921674},{"atl":[[3.6,0],[6.4,0],[5.2,0],[4.2,0],[8.4,0]],"id":41921674},{"atb":[[2.4,0],[2.5,0],[2.3,0]],"id":40251221},{"atl":[[8,0],[10,0],[20,0],[6,0],[15,0]],"id":40251221},{"atb":[[2,0],[2.2,0],[2.1,0]],"id":36899924},{"atl":[[17.5,0],[9,0],[5.5,0],[12.5,0],[7,0]],"id":36899924},{"atb":[[2,0],[1.9,0],[1.95,0]],"id":39979879},{"atl":[[5.1,0],[6.2,0],[10.5,0],[8.2,0],[15.5,0]],"id":39979879},{"atb":[[2.4,0],[2.3,0],[2.2,0]],"id":39722911},{"atl":[[9.6,0],[19,0],[5.8,0],[7.6,0],[14,0]],"id":39722911},{"atb":[[1.01,0]],"id":42492389},{"atl":[[2.06,0],[2.46,0],[2.66,0],[2.26,0],[1.93,0]],"id":42492389},{"atb":[[2.4,0],[2.5,0],[2.6,0]],"id":27151693},{"atl":[[6.2,0],[10.5,0],[21,0],[8.2,0],[15.5,0]],"id":27151693},{"atb":[[2.4,0],[2.3,0],[2.2,0]],"id":43154431},{"atl":[[9.6,0],[19,0],[5.8,0],[7.6,0],[14,0]],"id":43154431}],"con":true,"img":false}]}
{"op":"mcm","clk":"5346184036","pt":1646082300481,"mc":[{"id":"1.195395452","rc":[{"atb":[[1.7,171.66],[1.75,80.11],[1.65,184.87]],"id":41921674},{"atl":[[4,4],[8,6.86],[5,6],[6,4.8],[3.5,4.8]],"id":41921674},{"atb":[[2.4,85.83],[2.5,40.05],[2.3,92.43]],"id":40251221},{"atl":[[8,1.71],[10,2.66],[20,2.52],[6,2.4],[15,1.71]],"id":40251221},{"atb":[[2.06,113.36],[2.26,47.68],[2.16,103.59]],"id":36899924},{"atl":[[5.6,2.61],[7.2,1.93],[18,2.82],[9.2,2.92],[13,2]],"id":36899924},{"atb":[[2,60.08],[1.9,133.52],[1.95,126.49]],"id":39979879},{"atl":[[5.1,2.92],[6.2,2.31],[10.5,2.52],[8.2,3.33],[15.5,3.31]],"id":39979879},{"atb":[[2.36,44.18],[2.26,95.37],[2.16,103.59]],"id":39722911},{"atl":[[18.5,2.74],[7.4,1.87],[5.7,2.55],[13.5,1.92],[9.4,2.86]],"id":39722911},{"atb":[[1.01,30042.22]],"id":42492389},{"atl":[[2.06,11.33],[2.46,16.46],[2.66,28.95],[2.26,19.07],[1.93,12.92]],"id":42492389},{"atb":[[2.4,42.91],[2.3,92.43],[2.2,100.14]],"id":43154431},{"atl":[[9.6,2.79],[19,2.66],[5.8,2.5],[7.6,1.81],[14,1.85]],"id":43154431},{"atb":[[2.8,33.38],[2.6,75.1],[2.7,70.68]],"id":27151693},{"atl":[[7.2,1.93],[18,1.41],[9.2,1.46],[13,2],[26,1.92]],"id":27151693}],"con":true,"img":false}]}
{"op":"mcm","clk":"5346201592","pt":1646082501025,"mc":[{"id":"1.195395452","rc":[{"atb":[[2.4,0],[2.5,0],[2.3,0]],"id":40251221},{"atl":[[8,0],[10,0],[20,0],[6,0],[15,0]],"id":40251221},{"atb":[[2.06,0],[2.26,0],[2.16,0]],"id":36899924},{"atl":[[5.6,0],[7.2,0],[18,0],[9.2,0],[13,0]],"id":36899924},{"atb":[[2,0],[1.9,0],[1.95,0]],"id":39979879},{"atl":[[5.1,0],[6.2,0],[10.5,0],[8.2,0],[15.5,0]],"id":39979879},{"atb":[[2.36,0],[2.26,0],[2.16,0]],"id":39722911},{"atl":[[18.5,0],[7.4,0],[5.7,0],[13.5,0],[9.4,0]],"id":39722911}],"con":true,"img":false}]}
{"op":"mcm","clk":"5346201915","pt":1646082504418,"mc":[{"id":"1.195395452","rc":[{"atb":[[2.3,46.21],[2.2,100.14],[2.1,109.24]],"id":40251221},{"atl":[[5.6,2.61],[7.2,1.93],[18,2.82],[9.2,2.92],[13,2]],"id":40251221},{"atb":[[2.4,42.91],[2.3,92.43],[2.2,100.14]],"id":36899924},{"atl":[[9.6,2.79],[19,2.66],[5.8,2.5],[7.6,1.81],[14,1.85]],"id":36899924},{"atb":[[2.06,113.36],[1.98,122.62],[2.16,51.79]],"id":39979879},{"atl":[[17,3],[6.8,2.07],[12,2.18],[8.8,3.08],[5.4,2.73]],"id":39979879},{"atb":[[2.4,42.91],[2.3,92.43],[2.2,100.14]],"id":39722911},{"atl":[[9.6,2.79],[19,2.66],[5.8,2.5],[7.6,1.81],[14,1.85]],"id":39722911}],"con":true,"img":false}]}
{"op":"mcm","clk":"5346223607","pt":1646082746065,"mc":[{"id":"1.195395452","rc":[{"atb":[[1.7,0],[1.75,0],[1.65,0]],"id":41921674},{"atl":[[4,0],[8,0],[5,0],[6,0],[3.5,0]],"id":41921674},{"atb":[[2.3,0],[2.2,0],[2.1,0]],"id":40251221},{"atl":[[5.6,0],[7.2,0],[18,0],[9.2,0],[13,0]],"id":40251221},{"atb":[[2.4,0],[2.3,0],[2.2,0]],"id":36899924},{"atl":[[9.6,0],[19,0],[5.8,0],[7.6,0],[14,0]],"id":36899924},{"atb":[[2.06,0],[1.98,0],[2.16,0]],"id":39979879},{"atl":[[17,0],[6.8,0],[12,0],[8.8,0],[5.4,0]],"id":39979879},{"atb":[[2.4,0],[2.3,0],[2.2,0]],"id":39722911},{"atl":[[9.6,0],[19,0],[5.8,0],[7.6,0],[14,0]],"id":39722911},{"atb":[[1.01,0]],"id":42492389},{"atl":[[2.06,0],[2.46,0],[2.66,0],[2.26,0],[1.93,0]],"id":42492389},{"atb":[[2.8,0],[2.6,0],[2.7,0]],"id":27151693},{"atl":[[7.2,0],[18,0],[9.2,0],[13,0],[26,0]],"id":27151693},{"atb":[[2.4,0],[2.3,0],[2.2,0]],"id":43154431},{"atl":[[9.6,0],[19,0],[5.8,0],[7.6,0],[14,0]],"id":43154431}],"con":true,"img":false}]}
{"op":"mcm","clk":"5346226108","pt":1646082775530,"mc":[{"id":"1.195395452","rc":[{"atb":[[1.7,171.66],[1.75,80.11],[1.65,184.87]],"id":41921674},{"atl":[[4,4],[8,6.86],[5,6],[6,4.8],[3.5,4.8]],"id":41921674},{"atb":[[2.06,113.36],[2.26,47.68],[2.16,103.59]],"id":40251221},{"atl":[[5.6,2.61],[7.2,1.93],[18,2.82],[9.2,2.92],[13,2]],"id":40251221},{"atb":[[2,120.16],[2.2,50.07],[2.1,109.24]],"id":36899924},{"atl":[[17.5,2.91],[9,3],[5.5,2.66],[12.5,2.08],[7,2]],"id":36899924},{"atb":[[2,60.08],[1.9,133.52],[1.95,126.49]],"id":39979879},{"atl":[[5.1,2.92],[6.2,2.31],[10.5,2.52],[8.2,3.33],[15.5,3.31]],"id":39979879},{"atb":[[2.4,42.91],[2.3,92.43],[2.2,100.14]],"id":39722911},{"atl":[[9.6,2.79],[19,2.66],[5.8,2.5],[7.6,1.81],[14,1.85]],"id":39722911},{"atb":[[1.01,30042.22]],"id":42492389},{"atl":[[2.06,11.33],[2.46,16.46],[2.66,28.95],[2.26,19.07],[1.93,12.92]],"id":42492389},{"atb":[[2.4,85.83],[2.5,80.11],[2.6,37.55]],"id":27151693},{"atl":[[6.2,2.31],[10.5,2.52],[21,2.4],[8.2,1.66],[15.5,1.65]],"id":27151693},{"atb":[[2.4,42.91],[2.3,92.43],[2.2,100.14]],"id":43154431},{"atl":[[9.6,2.79],[19,2.66],[5.8,2.5],[7.6,1.81],[14,1.85]],"id":43154431}],"con":true,"img":false}]}
{"op":"mcm","clk":"5346427235","pt":1646086102107,"mc":[{"id":"1.195395452","rc":[{"atb":[[1.7,0],[1.75,0],[1.65,0]],"id":41921674},{"atl":[[4,0],[8,0],[5,0],[6,0],[3.5,0]],"id":41921674},{"atb":[[2.06,0],[2.26,0],[2.16,0]],"id":40251221},{"atl":[[5.6,0],[7.2,0],[18,0],[9.2,0],[13,0]],"id":40251221},{"atb":[[2,0],[2.2,0],[2.1,0]],"id":36899924},{"atl":[[17.5,0],[9,0],[5.5,0],[12.5,0],[7,0]],"id":36899924},{"atb":[[2,0],[1.9,0],[1.95,0]],"id":39979879},{"atl":[[5.1,0],[6.2,0],[10.5,0],[8.2,0],[15.5,0]],"id":39979879},{"atb":[[2.4,42.91],[2.3,92.42],[2.2,100.12]],"id":39722911},{"atl":[[9.6,2.79],[19,2.66],[5.8,2.5],[7.6,1.81],[14,1.85]],"id":39722911},{"atb":[[1.01,30037.34]],"id":42492389},{"atl":[[2.06,11.33],[2.46,16.45],[2.66,28.94],[2.26,19.07],[1.93,12.91]],"id":42492389},{"atb":[[2.4,85.82],[2.5,80.09],[2.6,37.54]],"id":27151693},{"atl":[[6.2,2.31],[10.5,2.52],[21,2.4],[8.2,1.66],[15.5,1.65]],"id":27151693},{"atb":[[2.4,42.91],[2.3,92.42],[2.2,100.12]],"id":43154431},{"atl":[[9.6,2.79],[19,2.66],[5.8,2.5],[7.6,1.81],[14,1.85]],"id":43154431}],"con":true,"img":false}]}
{"op":"mcm","clk":"5346427444","pt":1646086108526,"mc":[{"id":"1.195395452","rc":[{"atb":[[1.8,150.18],[1.85,141.35],[1.9,66.74]],"id":41921674},{"atl":[[4,4],[8,3.43],[5,3],[10,5.34],[6,4.8]],"id":41921674},{"atb":[[2,60.07],[1.9,133.5],[1.95,126.47]],"id":40251221},{"atl":[[5.1,2.92],[6.2,2.31],[10.5,2.52],[8.2,3.33],[15.5,3.31]],"id":40251221},{"atb":[[2.3,46.2],[2.2,100.12],[2.1,109.22]],"id":36899924},{"atl":[[5.6,2.61],[7.2,1.93],[18,2.82],[9.2,2.92],[13,2]],"id":36899924},{"atb":[[2,120.14],[1.95,126.47],[2.1,54.61]],"id":39979879},{"atl":[[16.5,3.1],[8.6,3.16],[5.3,2.79],[11.5,2.28],[6.6,2.14]],"id":39979879}],"con":true,"img":false}]}
{"op":"mcm","clk":"5346492653","pt":1646088262065,"mc":[{"id":"1.195395452","rc":[{"atb":[[2.3,0],[2.2,0],[2.1,0]],"id":36899924},{"atl":[[5.6,0],[7.2,0],[18,0],[9.2,0],[13,0]],"id":36899924}],"con":true,"img":false}]}
{"op":"mcm","clk":"5346492782","pt":1646088266492,"mc":[{"id":"1.195395452","rc":[{"atb":[[2.4,42.91],[2.3,92.42],[2.2,100.12]],"id":36899924},{"atl":[[9.6,2.79],[19,2.66],[5.8,2.5],[7.6,1.81],[14,1.85]],"id":36899924}],"con":true,"img":false}]}
{"op":"mcm","clk":"5346622219","pt":1646092565645,"mc":[{"id":"1.195395452","rc":[{"atb":[[1.5,82.26],[1.77,40.59]],"id":41921674},{"atl":[[5.6,8.28],[5.9,8.39]],"id":41921674},{"atb":[[1.94,40.59],[1.61,60.03]],"id":40251221},{"atl":[[9.8,4.06],[6.6,7.24]],"id":40251221},{"atb":[[2.16,34.99],[1.76,51.62]],"id":36899924},{"atl":[[8,5.79],[12,3.56]],"id":36899924},{"atb":[[1.58,68.11],[1.9,40.59]],"id":39979879},{"atl":[[6.4,7.51],[9.4,4.7]],"id":39979879},{"atb":[[2.22,35.72],[2.46,27.8]],"id":39722911},{"atl":[[9.6,7.51],[14,5.09]],"id":39722911},{"atb":[[1.02,1916.79]],"id":42492389},{"atl":[[1.6,62.54],[1.37,40.59]],"id":42492389},{"atb":[[2.56,26.02],[2,40.49]],"id":27151693},{"atl":[[10.5,6.79],[15.5,4.44]],"id":27151693},{"atb":[[2.5,27.06],[2.22,34.09]],"id":43154431},{"atl":[[10,4.5],[14.5,3.24]],"id":43154431}],"con":true,"img":false}]}
{"op":"mcm","clk":"5346624132","pt":1646092624508,"mc":[{"id":"1.195395452","rc":[{"atb":[[1.77,0]],"id":41921674},{"atl":[[5.6,0]],"id":41921674},{"atb":[[1.94,0]],"id":40251221},{"atb":[[2.16,0]],"id":36899924},{"atb":[[1.9,0]],"id":39979879},{"atb":[[2.56,0]],"id":27151693}],"con":true,"img":false}]}
{"op":"mcm","clk":"5346624138","pt":1646092624612,"mc":[{"id":"1.195395452","rc":[{"atb":[[1.86,40.59]],"id":41921674},{"atl":[[4.9,8.28]],"id":41921674},{"atb":[[2.02,40.59]],"id":40251221},{"atb":[[2.32,34.99]],"id":36899924},{"atb":[[2.02,40.59]],"id":39979879},{"atb":[[2.62,26.02]],"id":27151693}],"con":true,"img":false}]}
{"op":"mcm","clk":"5346625215","pt":1646092658756,"mc":[{"id":"1.195395452","rc":[{"atb":[[1.91,40.24],[1.61,0]],"id":40251221},{"atb":[[2.22,0]],"id":39722911},{"atb":[[2,0],[2.52,26.64]],"id":27151693},{"atb":[[2.22,0]],"id":43154431}],"con":true,"img":false}]}
{"op":"mcm","clk":"5346625221","pt":1646092658856,"mc":[{"id":"1.195395452","rc":[{"atb":[[2.32,35.72]],"id":39722911},{"atb":[[2.32,34.09]],"id":43154431}],"con":true,"img":false}]}
{"op":"mcm","clk":"5346626802","pt":1646092713235,"mc":[{"id":"1.195395452","rc":[{"atl":[[4.9,0]],"id":41921674}],"con":true,"img":false}]}
{"op":"mcm","clk":"5346626805","pt":1646092713336,"mc":[{"id":"1.195395452","rc":[{"atl":[[4.8,8.28]],"id":41921674}],"con":true,"img":false}]}
{"op":"mcm","clk":"5346627902","pt":1646092745583,"mc":[{"id":"1.195395452","rc":[{"atl":[[4.8,0]],"id":41921674}],"con":true,"img":false}]}
{"op":"mcm","clk":"5346627905","pt":1646092745686,"mc":[{"id":"1.195395452","rc":[{"atl":[[4.9,8.28]],"id":41921674}],"con":true,"img":false}]}
{"op":"mcm","clk":"5346630779","pt":1646092831848,"mc":[{"id":"1.195395452","rc":[{"atb":[[1.8,150.08],[1.85,141.26],[1.9,66.7],[1.5,82.21],[1.86,40.56]],"id":41921674},{"atl":[[4,4],[8,3.42],[5,3],[10,5.33],[6,4.8],[4.9,0],[5.9,8.38]],"id":41921674},{"atb":[[2,60.03],[2.02,40.56],[1.91,40.21],[1.9,133.41],[1.95,126.38]],"id":40251221},{"atl":[[5.1,2.92],[6.2,2.3],[10.5,2.52],[8.2,3.33],[9.8,4.06],[6.6,7.24],[15.5,3.31]],"id":40251221},{"atb":[[2.4,42.88],[2.32,34.97],[2.3,92.36],[2.2,100.05],[1.76,51.59]],"id":36899924},{"atl":[[8,5.79],[9.6,2.79],[19,2.66],[5.8,2.5],[7.6,1.81],[12,3.56],[14,1.84]],"id":36899924},{"atb":[[2,120.07],[2.02,40.56],[1.58,68.07],[1.95,126.38],[2.1,54.57]],"id":39979879},{"atl":[[16.5,3.09],[8.6,3.15],[6.4,7.51],[5.3,2.79],[11.5,2.28],[6.6,2.14],[9.4,4.7]],"id":39979879},{"atb":[[2.4,42.88],[2.32,35.69],[2.3,92.36],[2.46,27.78],[2.2,100.05]],"id":39722911},{"atl":[[9.6,7.5],[19,2.66],[5.8,2.5],[7.6,1.81],[14,5.09]],"id":39722911},{"atb":[[1.01,30017.84],[1.02,1915.55]],"id":42492389},{"atl":[[1.6,62.5],[1.37,40.56],[2.06,11.32],[2.46,16.44],[2.66,28.93],[2.26,19.05],[1.93,12.91]],"id":42492389},{"atb":[[2.4,42.88],[2.5,27.04],[2.32,34.07],[2.3,92.36],[2.2,100.05]],"id":43154431},{"atl":[[9.6,2.79],[19,2.66],[5.8,2.5],[10,4.5],[7.6,1.81],[14,1.84],[14.5,3.24]],"id":43154431},{"atb":[[2.4,85.76],[2.5,80.04],[2.52,26.62],[2.6,37.52],[2.62,26]],"id":27151693},{"atl":[[6.2,2.3],[10.5,6.79],[21,2.4],[8.2,1.66],[15.5,4.44]],"id":27151693}],"con":true,"img":false}]}
{"op":"mcm","clk":"5346630785","pt":1646092831952,"mc":[{"id":"1.195395452","rc":[{"atl":[[4.8,8.28]],"id":41921674}],"con":true,"img":false}]}
{"op":"mcm","clk":"5346631850","pt":1646092862794,"mc":[{"id":"1.195395452","rc":[{"atl":[[4.8,0]],"id":41921674}],"con":true,"img":false}]}
{"op":"mcm","clk":"5346631853","pt":1646092862896,"mc":[{"id":"1.195395452","rc":[{"atl":[[4.9,8.28]],"id":41921674}],"con":true,"img":false}]}
{"op":"mcm","clk":"5346634201","pt":1646092923483,"mc":[{"id":"1.195395452","rc":[{"atl":[[4.9,0]],"id":41921674}],"con":true,"img":false}]}
{"op":"mcm","clk":"5346634207","pt":1646092923542,"mc":[{"id":"1.195395452","rc":[{"atl":[[4.8,8.28]],"id":41921674}],"con":true,"img":false}]}
{"op":"mcm","clk":"5346635408","pt":1646092953314,"mc":[{"id":"1.195395452","rc":[{"atl":[[4.8,0]],"id":41921674}],"con":true,"img":false}]}
{"op":"mcm","clk":"5346635411","pt":1646092953416,"mc":[{"id":"1.195395452","rc":[{"atl":[[4.9,8.28]],"id":41921674}],"con":true,"img":false}]}
{"op":"mcm","clk":"5346638814","pt":1646093040688,"mc":[{"id":"1.195395452","rc":[{"atl":[[4.9,0]],"id":41921674}],"con":true,"img":false}]}
{"op":"mcm","clk":"5346638820","pt":1646093040789,"mc":[{"id":"1.195395452","rc":[{"atl":[[4.8,8.28]],"id":41921674}],"con":true,"img":false}]}
{"op":"mcm","clk":"5346639836","pt":1646093069262,"mc":[{"id":"1.195395452","rc":[{"atl":[[4.8,0]],"id":41921674}],"con":true,"img":false}]}
{"op":"mcm","clk":"5346639841","pt":1646093069366,"mc":[{"id":"1.195395452","rc":[{"atl":[[4.9,8.28]],"id":41921674}],"con":true,"img":false}]}
{"op":"mcm","clk":"5346643128","pt":1646093152823,"mc":[{"id":"1.195395452","rc":[{"atl":[[4.9,0]],"id":41921674}],"con":true,"img":false}]}
{"op":"mcm","clk":"5346643131","pt":1646093152928,"mc":[{"id":"1.195395452","rc":[{"atl":[[4.8,8.28]],"id":41921674}],"con":true,"img":false}]}
{"op":"mcm","clk":"5346644053","pt":1646093180163,"mc":[{"id":"1.195395452","rc":[{"atl":[[4.8,0]],"id":41921674}],"con":true,"img":false}]}
{"op":"mcm","clk":"5346644055","pt":1646093180263,"mc":[{"id":"1.195395452","rc":[{"atl":[[4.9,8.28]],"id":41921674}],"con":true,"img":false}]}
{"op":"mcm","clk":"5346646886","pt":1646093260396,"mc":[{"id":"1.195395452","rc":[{"atl":[[4.9,0]],"id":41921674}],"con":true,"img":false}]}
{"op":"mcm","clk":"5346646891","pt":1646093260501,"mc":[{"id":"1.195395452","rc":[{"atl":[[4.8,8.28]],"id":41921674}],"con":true,"img":false}]}
{"op":"mcm","clk":"5346647914","pt":1646093286693,"mc":[{"id":"1.195395452","rc":[{"atl":[[4.8,0]],"id":41921674}],"con":true,"img":false}]}
{"op":"mcm","clk":"5346647919","pt":1646093286794,"mc":[{"id":"1.195395452","rc":[{"atl":[[4.9,8.28]],"id":41921674}],"con":true,"img":false}]}
{"op":"mcm","clk":"5346650611","pt":1646093363684,"mc":[{"id":"1.195395452","rc":[{"atl":[[4.9,0]],"id":41921674}],"con":true,"img":false}]}
{"op":"mcm","clk":"5346650613","pt":1646093363787,"mc":[{"id":"1.195395452","rc":[{"atl":[[4.8,8.28]],"id":41921674}],"con":true,"img":false}]}
{"op":"mcm","clk":"5346651530","pt":1646093388721,"mc":[{"id":"1.195395452","rc":[{"atl":[[4.8,0]],"id":41921674}],"con":true,"img":false}]}
{"op":"mcm","clk":"5346651532","pt":1646093388826,"mc":[{"id":"1.195395452","rc":[{"atl":[[4.9,8.28]],"id":41921674}],"con":true,"img":false}]}
{"op":"mcm","clk":"5346654183","pt":1646093462999,"mc":[{"id":"1.195395452","rc":[{"atl":[[4.9,0]],"id":41921674}],"con":true,"img":false}]}
{"op":"mcm","clk":"5346654184","pt":1646093463101,"mc":[{"id":"1.195395452","rc":[{"atl":[[4.8,8.28]],"id":41921674}],"con":true,"img":false}]}
{"op":"mcm","clk":"5346654804","pt":1646093487173,"mc":[{"id":"1.195395452","rc":[{"atl":[[4.8,0]],"id":41921674}],"con":true,"img":false}]}
{"op":"mcm","clk":"5346654808","pt":1646093487223,"mc":[{"id":"1.195395452","rc":[{"atl":[[4.9,8.28]],"id":41921674}],"con":true,"img":false}]}
{"op":"mcm","clk":"5346657004","pt":1646093558545,"mc":[{"id":"1.195395452","rc":[{"atl":[[4.9,0]],"id":41921674}],"con":true,"img":false}]}
{"op":"mcm","clk":"5346657007","pt":1646093558646,"mc":[{"id":"1.195395452","rc":[{"atl":[[4.8,8.28]],"id":41921674}],"con":true,"img":false}]}
{"op":"mcm","clk":"5346657660","pt":1646093581782,"mc":[{"id":"1.195395452","rc":[{"atl":[[4.8,0]],"id":41921674}],"con":true,"img":false}]}
{"op":"mcm","clk":"5346657665","pt":1646093581883,"mc":[{"id":"1.195395452","rc":[{"atl":[[4.9,8.28]],"id":41921674}],"con":true,"img":false}]}
{"op":"mcm","clk":"5346659791","pt":1646093650750,"mc":[{"id":"1.195395452","rc":[{"atl":[[4.9,0]],"id":41921674}],"con":true,"img":false}]}
{"op":"mcm","clk":"5346659795","pt":1646093650853,"mc":[{"id":"1.195395452","rc":[{"atl":[[4.8,8.28]],"id":41921674}],"con":true,"img":false}]}
{"op":"mcm","clk":"5346660542","pt":1646093673303,"mc":[{"id":"1.195395452","rc":[{"atl":[[4.8,0]],"id":41921674}],"con":true,"img":false}]}
{"op":"mcm","clk":"5346660544","pt":1646093673406,"mc":[{"id":"1.195395452","rc":[{"atl":[[4.9,8.28]],"id":41921674}],"con":true,"img":false}]}
{"op":"mcm","clk":"5346662950","pt":1646093739524,"mc":[{"id":"1.195395452","rc":[{"atl":[[4.9,0]],"id":41921674}],"con":true,"img":false}]}
{"op":"mcm","clk":"5346662954","pt":1646093739626,"mc":[{"id":"1.195395452","rc":[{"atl":[[4.8,8.28]],"id":41921674}],"con":true,"img":false}]}
{"op":"mcm","clk":"5346663614","pt":1646093761346,"mc":[{"id":"1.195395452","rc":[{"atl":[[4.8,0]],"id":41921674}],"con":true,"img":false}]}
{"op":"mcm","clk":"5346663617","pt":1646093761449,"mc":[{"id":"1.195395452","rc":[{"atl":[[4.9,8.28]],"id":41921674}],"con":true,"img":false}]}
{"op":"mcm","clk":"5346673283","pt":1646093825872,"mc":[{"id":"1.195395452","rc":[{"atl":[[4.9,0]],"id":41921674}],"con":true,"img":false}]}
{"op":"mcm","clk":"5346673289","pt":1646093825924,"mc":[{"id":"1.195395452","rc":[{"atl":[[4.8,8.28]],"id":41921674}],"con":true,"img":false}]}
{"op":"mcm","clk":"5346674094","pt":1646093846683,"mc":[{"id":"1.195395452","rc":[{"atl":[[4.8,0]],"id":41921674}],"con":true,"img":false}]}
{"op":"mcm","clk":"5346674100","pt":1646093846785,"mc":[{"id":"1.195395452","rc":[{"atl":[[4.9,8.28]],"id":41921674}],"con":true,"img":false}]}
{"op":"mcm","clk":"5346676238","pt":1646093908978,"mc":[{"id":"1.195395452","rc":[{"atl":[[4.9,0]],"id":41921674}],"con":true,"img":false}]}
{"op":"mcm","clk":"5346676243","pt":1646093909079,"mc":[{"id":"1.195395452","rc":[{"atl":[[4.8,8.28]],"id":41921674}],"con":true,"img":false}]}
{"op":"mcm","clk":"5346676998","pt":1646093929302,"mc":[{"id":"1.195395452","rc":[{"atl":[[4.8,0]],"id":41921674}],"con":true,"img":false}]}
{"op":"mcm","clk":"5346677003","pt":1646093929404,"mc":[{"id":"1.195395452","rc":[{"atl":[[4.9,8.28]],"id":41921674}],"con":true,"img":false}]}
{"op":"mcm","clk":"5346679185","pt":1646093990040,"mc":[{"id":"1.195395452","rc":[{"atl":[[4.9,0]],"id":41921674}],"con":true,"img":false}]}
{"op":"mcm","clk":"5346679188","pt":1646093990141,"mc":[{"id":"1.195395452","rc":[{"atl":[[4.8,8.28]],"id":41921674}],"con":true,"img":false}]}
{"op":"mcm","clk":"5346679941","pt":1646094010787,"mc":[{"id":"1.195395452","rc":[{"atl":[[4.8,0]],"id":41921674}],"con":true,"img":false}]}
{"op":"mcm","clk":"5346679946","pt":1646094010839,"mc":[{"id":"1.195395452","rc":[{"atl":[[4.9,8.28]],"id":41921674}],"con":true,"img":false}]}
{"op":"mcm","clk":"5346682141","pt":1646094071331,"mc":[{"id":"1.195395452","rc":[{"atl":[[4.9,0]],"id":41921674}],"con":true,"img":false}]}
{"op":"mcm","clk":"5346682146","pt":1646094071435,"mc":[{"id":"1.195395452","rc":[{"atl":[[4.8,8.28]],"id":41921674}],"con":true,"img":false}]}
{"op":"mcm","clk":"5346683573","pt":1646094105686,"mc":[{"id":"1.195395452","rc":[{"atl":[[4.8,0]],"id":41921674}],"con":true,"img":false}]}
{"op":"mcm","clk":"5346683579","pt":1646094105788,"mc":[{"id":"1.195395452","rc":[{"atl":[[4.9,8.28]],"id":41921674}],"con":true,"img":false}]}
{"op":"mcm","clk":"5346685987","pt":1646094164780,"mc":[{"id":"1.195395452","rc":[{"atl":[[4.9,0]],"id":41921674}],"con":true,"img":false}]}
{"op":"mcm","clk":"5346685989","pt":1646094164882,"mc":[{"id":"1.195395452","rc":[{"atl":[[4.8,8.28]],"id":41921674}],"con":true,"img":false}]}
{"op":"mcm","clk":"5346686772","pt":1646094184157,"mc":[{"id":"1.195395452","rc":[{"atl":[[4.8,0]],"id":41921674}],"con":true,"img":false}]}
{"op":"mcm","clk":"5346686773","pt":1646094184208,"mc":[{"id":"1.195395452","rc":[{"atl":[[4.9,8.28]],"id":41921674}],"con":true,"img":false}]}
{"op":"mcm","clk":"5346689302","pt":1646094255658,"mc":[{"id":"1.195395452","rc":[{"atl":[[4.9,0]],"id":41921674}],"con":true,"img":false}]}
{"op":"mcm","clk":"5346689304","pt":1646094255761,"mc":[{"id":"1.195395452","rc":[{"atl":[[4.8,8.28]],"id":41921674}],"con":true,"img":false}]}
{"op":"mcm","clk":"5346690176","pt":1646094288694,"mc":[{"id":"1.195395452","rc":[{"atl":[[4.8,0]],"id":41921674}],"con":true,"img":false}]}
{"op":"mcm","clk":"5346690179","pt":1646094288797,"mc":[{"id":"1.195395452","rc":[{"atl":[[4.9,8.28]],"id":41921674}],"con":true,"img":false}]}
{"op":"mcm","clk":"5346691115","pt":1646094315974,"mc":[{"id":"1.195395452","rc":[{"atb":[[1.3,164.42]],"id":41921674},{"atl":[[3.95,4]],"id":41921674},{"atb":[[1.53,120.08]],"id":40251221},{"atl":[[5.1,5.85]],"id":40251221},{"atb":[[2.06,94.34]],"id":36899924},{"atl":[[11,5.29]],"id":36899924},{"atb":[[2.12,54.58]],"id":39979879},{"atl":[[9,5.95]],"id":39979879},{"atb":[[2.48,35.7]],"id":39722911},{"atl":[[8,5.09]],"id":39722911},{"atb":[[2.06,85.76]],"id":43154431},{"atl":[[6.4,5]],"id":43154431},{"atb":[[2.64,26.63]],"id":27151693},{"atl":[[25,4.17]],"id":27151693}],"con":true,"img":false}]}
{"op":"mcm","clk":"5346691537","pt":1646094326367,"mc":[{"id":"1.195395452","rc":[{"atl":[[4.9,0]],"id":41921674}],"con":true,"img":false}]}
{"op":"mcm","clk":"5346691542","pt":1646094326470,"mc":[{"id":"1.195395452","rc":[{"atl":[[5.6,8.28]],"id":41921674}],"con":true,"img":false}]}
{"op":"mcm","clk":"5346692804","pt":1646094358456,"mc":[{"id":"1.195395452","rc":[{"atl":[[5,10.14],[6.6,0]],"id":40251221},{"atb":[[2.32,0],[1.74,58.95]],"id":39722911},{"atl":[[1.6,0],[2.04,36.05]],"id":42492389},{"atb":[[1.82,49.35],[2.52,0]],"id":27151693},{"atl":[[10,0],[6.2,7.79]],"id":43154431}],"con":true,"img":false}]}
{"op":"mcm","clk":"5346692809","pt":1646094358557,"mc":[{"id":"1.195395452","rc":[{"atl":[[8,0]],"id":36899924},{"atb":[[2.46,0]],"id":39722911},{"atl":[[9.6,2.79]],"id":39722911},{"atl":[[1.37,0]],"id":42492389},{"atb":[[2.5,0],[2.32,0]],"id":43154431},{"atl":[[10.5,2.52]],"id":27151693}],"con":true,"img":false}]}
{"op":"mcm","clk":"5346692812","pt":1646094358661,"mc":[{"id":"1.195395452","rc":[{"atl":[[5.1,2.92],[4.9,5.86]],"id":40251221},{"atl":[[7.4,5.79]],"id":36899924},{"atb":[[2.5,27.78]],"id":39722911},{"atl":[[7.8,4.71]],"id":39722911},{"atl":[[1.92,40.56]],"id":42492389},{"atb":[[2.42,27.04],[2.08,34.07]],"id":43154431},{"atl":[[8.4,4.26]],"id":27151693}],"con":true,"img":false}]}
{"op":"mcm","clk":"5346692817","pt":1646094358718,"mc":[{"id":"1.195395452","rc":[{"atb":[[2.42,70.42],[2.48,0]],"id":39722911}],"con":true,"img":false}]}
{"op":"mcm","clk":"5346692819","pt":1646094358816,"mc":[{"id":"1.195395452","rc":[{"atb":[[2.52,42.88]],"id":39722911}],"con":true,"img":false}]}
{"op":"mcm","clk":"5346692821","pt":1646094358922,"mc":[{"id":"1.195395452","rc":[{"atb":[[2.42,0]],"id":39722911}],"con":true,"img":false}]}
{"op":"mcm","clk":"5346693470","pt":1646094376944,"mc":[{"id":"1.195395452","rc":[{"atb":[[1.57,67.77],[1.91,0]],"id":40251221},{"atb":[[2.08,36.3],[1.76,0]],"id":36899924},{"atl":[[12,0],[9.4,4.66]],"id":36899924}],"con":true,"img":false}]}
{"op":"mcm","clk":"5346693474","pt":1646094377048,"mc":[{"id":"1.195395452","rc":[{"atl":[[9.4,0]],"id":39979879}],"con":true,"img":false}]}
{"op":"mcm","clk":"5346693477","pt":1646094377150,"mc":[{"id":"1.195395452","rc":[{"atl":[[8.8,4.7]],"id":39979879}],"con":true,"img":false}]}
{"op":"mcm","clk":"5346694649","pt":1646094409413,"mc":[{"id":"1.195395452","rc":[{"atl":[[5.6,0],[3.95,17.74]],"id":41921674},{"atl":[[5,0]],"id":40251221},{"atb":[[2.5,0]],"id":39722911},{"atl":[[7.8,11.2],[14,1.84]],"id":39722911},{"atl":[[14.5,0],[9.4,4.86]],"id":43154431},{"atl":[[10,4.49],[15.5,1.65]],"id":27151693}],"con":true,"img":false}]}
{"op":"mcm","clk":"5346694652","pt":1646094409514,"mc":[{"id":"1.195395452","rc":[{"atl":[[4.8,10.14],[5.1,14.64],[4.9,0]],"id":40251221},{"atb":[[2.54,27.78],[2.42,70.42],[2.52,0]],"id":39722911}],"con":true,"img":false}]}
{"op":"mcm","clk":"5346695384","pt":1646094427532,"mc":[{"id":"1.195395452","rc":[{"atl":[[3.95,4],[5.4,9.22]],"id":41921674}],"con":true,"img":false}]}
{"op":"mcm","clk":"5346695389","pt":1646094427635,"mc":[{"id":"1.195395452","rc":[{"atl":[[4.8,0]],"id":40251221},{"atb":[[2.54,0]],"id":39722911},{"atl":[[10,0],[12.5,3.52]],"id":27151693}],"con":true,"img":false}]}
{"op":"mcm","clk":"5346695395","pt":1646094427739,"mc":[{"id":"1.195395452","rc":[{"atl":[[5,10.14]],"id":40251221},{"atb":[[2.44,27.78]],"id":39722911}],"con":true,"img":false}]}
{"op":"mcm","clk":"5346696169","pt":1646094445558,"mc":[{"id":"1.195395452","rc":[{"atl":[[5.1,2.92],[4.9,10.14]],"id":40251221},{"atb":[[2.42,0],[2.46,42.88]],"id":39722911}],"con":true,"img":false}]}
{"op":"mcm","clk":"5346697990","pt":1646094495189,"mc":[{"id":"1.195395452","rc":[{"atl":[[5,0]],"id":40251221},{"atb":[[2.44,0]],"id":39722911},{"atl":[[10,4.49]],"id":27151693}],"con":true,"img":false}]}
{"op":"mcm","clk":"5346697994","pt":1646094495292,"mc":[{"id":"1.195395452","rc":[{"atl":[[4.8,10.14],[5.1,23.2],[4.9,0]],"id":40251221},{"atb":[[2.42,70.42],[2.46,0],[2.48,27.78]],"id":39722911},{"atl":[[12.5,0]],"id":27151693}],"con":true,"img":false}]}
{"op":"mcm","clk":"5346698480","pt":1646094508574,"mc":[{"id":"1.195395452","rc":[{"atl":[[4.8,0]],"id":40251221},{"atb":[[2.48,0]],"id":39722911}],"con":true,"img":false}]}
{"op":"mcm","clk":"5346698482","pt":1646094508676,"mc":[{"id":"1.195395452","rc":[{"atl":[[5,10.14]],"id":40251221},{"atb":[[2.44,27.78]],"id":39722911}],"con":true,"img":false}]}
{"op":"mcm","clk":"5346699244","pt":1646094530420,"mc":[{"id":"1.195395452","rc":[{"atl":[[5.1,2.92]],"id":40251221},{"atb":[[2.42,0],[2.46,42.88]],"id":39722911}],"con":true,"img":false}]}
{"op":"mcm","clk":"5346699248","pt":1646094530521,"mc":[{"id":"1.195395452","rc":[{"atl":[[4.9,10.14]],"id":40251221}],"con":true,"img":false}]}
{"op":"mcm","clk":"5346701788","pt":1646094603745,"mc":[{"id":"1.195395452","rc":[{"atl":[[5,0]],"id":40251221},{"atb":[[2.44,0]],"id":39722911}],"con":true,"img":false}]}
{"op":"mcm","clk":"5346701791","pt":1646094603850,"mc":[{"id":"1.195395452","rc":[{"atl":[[4.8,10.14],[5.1,23.2],[4.9,0]],"id":40251221},{"atb":[[2.42,70.42],[2.46,0],[2.48,27.78]],"id":39722911}],"con":true,"img":false}]}
{"op":"mcm","clk":"5346702511","pt":1646094621886,"mc":[{"id":"1.195395452","rc":[{"atl":[[4.8,0]],"id":40251221},{"atb":[[2.48,0]],"id":39722911}],"con":true,"img":false}]}
{"op":"mcm","clk":"5346702517","pt":1646094621989,"mc":[{"id":"1.195395452","rc":[{"atl":[[5,10.14]],"id":40251221},{"atb":[[2.44,27.78]],"id":39722911}],"con":true,"img":false}]}
{"op":"mcm","clk":"5346703160","pt":1646094638038,"mc":[{"id":"1.195395452","rc":[{"atl":[[5.1,2.92],[4.9,10.14]],"id":40251221},{"atb":[[2.42,0],[2.46,42.88]],"id":39722911}],"con":true,"img":false}]}
{"op":"mcm","clk":"5346705331","pt":1646094695879,"mc":[{"id":"1.195395452","rc":[{"atl":[[5,0]],"id":40251221},{"atb":[[2.44,0]],"id":39722911}],"con":true,"img":false}]}
{"op":"mcm","clk":"5346705335","pt":1646094695982,"mc":[{"id":"1.195395452","rc":[{"atl":[[4.8,10.14],[5.1,23.2],[4.9,0]],"id":40251221},{"atb":[[2.42,70.42],[2.46,0],[2.48,27.78]],"id":39722911}],"con":true,"img":false}]}
{"op":"mcm","clk":"5346705341","pt":1646094696085,"mc":[{"id":"1.195395452","rc":[{"atl":[[5.1,2.92],[4.7,10.14]],"id":40251221},{"atb":[[2.5,42.88],[2.42,0]],"id":39722911}],"con":true,"img":false}]}
{"op":"mcm","clk":"5346706869","pt":1646094740453,"mc":[{"id":"1.195395452","rc":[{"atl":[[4.8,0]],"id":40251221},{"atb":[[2.48,0]],"id":39722911}],"con":true,"img":false}]}
{"op":"mcm","clk":"5346706875","pt":1646094740555,"mc":[{"id":"1.195395452","rc":[{"atl":[[5.1,23.2],[4.6,10.14],[4.7,0]],"id":40251221},{"atb":[[2.5,0],[2.42,70.42],[2.52,27.78]],"id":39722911}],"con":true,"img":false}]}
{"op":"mcm","clk":"5346706878","pt":1646094740659,"mc":[{"id":"1.195395452","rc":[{"atl":[[5.1,2.92],[6,13.07]],"id":40251221},{"atb":[[2.54,42.88]],"id":39722911}],"con":true,"img":false}]}
{"op":"mcm","clk":"5346706883","pt":1646094740761,"mc":[{"id":"1.195395452","rc":[{"atl":[[4.5,10.14]],"id":40251221},{"atb":[[2.42,0]],"id":39722911}],"con":true,"img":false}]}
{"op":"mcm","clk":"5346706889","pt":1646094740863,"mc":[{"id":"1.195395452","rc":[{"atl":[[6,0]],"id":40251221}],"con":true,"img":false}]}
{"op":"mcm","clk":"5346708441","pt":1646094784713,"mc":[{"id":"1.195395452","rc":[{"atl":[[4.6,0]],"id":40251221},{"atb":[[2.52,0]],"id":39722911}],"con":true,"img":false}]}
{"op":"mcm","clk":"5346708447","pt":1646094784865,"mc":[{"id":"1.195395452","rc":[{"atl":[[4.5,0],[5.1,23.2],[4.4,10.14]],"id":40251221},{"atb":[[2.56,27.78],[2.54,0],[2.42,70.42]],"id":39722911}],"con":true,"img":false}]}
{"op":"mcm","clk":"5346708454","pt":1646094784917,"mc":[{"id":"1.195395452","rc":[{"atl":[[5.1,2.92],[6,13.07]],"id":40251221}],"con":true,"img":false}]}
{"op":"mcm","clk":"5346708458","pt":1646094785018,"mc":[{"id":"1.195395452","rc":[{"atb":[[2.42,0],[2.58,42.88]],"id":39722911}],"con":true,"img":false}]}
{"op":"mcm","clk":"5346708464","pt":1646094785123,"mc":[{"id":"1.195395452","rc":[{"atl":[[4.3,10.14],[6,0]],"id":40251221}],"con":true,"img":false}]}
{"op":"mcm","clk":"5346710383","pt":1646094828009,"mc":[{"id":"1.195395452","rc":[{"atl":[[4.4,0]],"id":40251221}],"con":true,"img":false}]}
{"op":"mcm","clk":"5346710386","pt":1646094828112,"mc":[{"id":"1.195395452","rc":[{"atl":[[4.3,0],[5.1,23.2],[5.5,10.14]],"id":40251221}],"con":true,"img":false}]}
{"op":"mcm","clk":"5346711442","pt":1646094856361,"mc":[{"id":"1.195395452","rc":[{"atl":[[5.5,0]],"id":40251221},{"atb":[[2.56,0]],"id":39722911}],"con":true,"img":false}]}
{"op":"mcm","clk":"5346711446","pt":1646094856465,"mc":[{"id":"1.195395452","rc":[{"atl":[[5,10.14]],"id":40251221},{"atb":[[2.42,70.42],[2.6,27.78],[2.58,0]],"id":39722911}],"con":true,"img":false}]}
{"op":"mcm","clk":"5346711563","pt":1646094859951,"mc":[{"id":"1.195395452","rc":[{"atl":[[5.1,2.92],[4.9,10.14]],"id":40251221}],"con":true,"img":false}]}
{"op":"mcm","clk":"5346712057","pt":1646094872673,"mc":[{"id":"1.195395452","rc":[{"atb":[[2.6,0]],"id":39722911}],"con":true,"img":false}]}
{"op":"mcm","clk":"5346712063","pt":1646094872776,"mc":[{"id":"1.195395452","rc":[{"atb":[[2.44,27.78]],"id":39722911}],"con":true,"img":false}]}
{"op":"mcm","clk":"5346712440","pt":1646094883196,"mc":[{"id":"1.195395452","rc":[{"atb":[[1.62,161.29],[1.53,0]],"id":40251221},{"atb":[[2.06,0],[2.16,86.21]],"id":36899924},{"atb":[[2.16,86.21]],"id":43154431},{"atl":[[5.8,7.5]],"id":43154431}],"con":true,"img":false}]}
{"op":"mcm","clk":"5346712446","pt":1646094883295,"mc":[{"id":"1.195395452","rc":[{"atb":[[2.06,0]],"id":43154431},{"atl":[[6.4,0]],"id":43154431}],"con":true,"img":false}]}
{"op":"mcm","clk":"5346712603","pt":1646094888018,"mc":[{"id":"1.195395452","rc":[{"atb":[[2.46,42.88]],"id":39722911}],"con":true,"img":false}]}
{"op":"mcm","clk":"5346712607","pt":1646094888120,"mc":[{"id":"1.195395452","rc":[{"atb":[[2.42,0]],"id":39722911}],"con":true,"img":false}]}
{"op":"mcm","clk":"5346712970","pt":1646094898444,"mc":[{"id":"1.195395452","rc":[{"atb":[[1.72,54.45],[2.08,0]],"id":36899924},{"atb":[[1.75,55.7],[2.08,0]],"id":43154431}],"con":true,"img":false}]}
{"op":"mcm","clk":"5346713918","pt":1646094926183,"mc":[{"id":"1.195395452","rc":[{"atl":[[5,0]],"id":40251221},{"atb":[[2.44,0]],"id":39722911},{"atl":[[6.2,0]],"id":43154431}],"con":true,"img":false}]}
{"op":"mcm","clk":"5346713924","pt":1646094926288,"mc":[{"id":"1.195395452","rc":[{"atl":[[4.8,10.14],[5.1,23.2]],"id":40251221},{"atb":[[2.42,70.42],[2.48,27.78]],"id":39722911},{"atl":[[5.7,7.79]],"id":43154431}],"con":true,"img":false}]}
{"op":"mcm","clk":"5346713928","pt":1646094926389,"mc":[{"id":"1.195395452","rc":[{"atl":[[4.9,0],[4.7,10.14]],"id":40251221},{"atb":[[2.46,0]],"id":39722911},{"atl":[[5.6,7.5],[5.8,2.5]],"id":43154431}],"con":true,"img":false}]}
{"op":"mcm","clk":"5346713933","pt":1646094926491,"mc":[{"id":"1.195395452","rc":[{"atb":[[2.5,42.88]],"id":39722911}],"con":true,"img":false}]}
{"op":"mcm","clk":"5346713938","pt":1646094926595,"mc":[{"id":"1.195395452","rc":[{"atl":[[5.1,2.92]],"id":40251221},{"atb":[[2.42,0]],"id":39722911}],"con":true,"img":false}]}
{"op":"mcm","clk":"5346714951","pt":1646094953364,"mc":[{"id":"1.195395452","rc":[{"atb":[[1.57,0]],"id":40251221}],"con":true,"img":false}]}
{"op":"mcm","clk":"5346714957","pt":1646094953467,"mc":[{"id":"1.195395452","rc":[{"atb":[[1.63,67.77]],"id":40251221}],"con":true,"img":false}]}
{"op":"mcm","clk":"5346716437","pt":1646094993939,"mc":[{"id":"1.195395452","rc":[{"atl":[[4.8,0]],"id":40251221},{"atb":[[2.48,0]],"id":39722911},{"atl":[[5.7,0]],"id":43154431}],"con":true,"img":false}]}
{"op":"mcm","clk":"5346716443","pt":1646094994042,"mc":[{"id":"1.195395452","rc":[{"atl":[[5.1,23.2],[4.6,10.14]],"id":40251221},{"atb":[[2.52,27.78]],"id":39722911},{"atl":[[5.6,0],[5.8,17.5],[5.5,7.79]],"id":43154431}],"con":true,"img":false}]}
{"op":"mcm","clk":"5346716448","pt":1646094994147,"mc":[{"id":"1.195395452","rc":[{"atl":[[4.7,0]],"id":40251221},{"atb":[[2.5,0],[2.42,70.42]],"id":39722911}],"con":true,"img":false}]}
{"op":"mcm","clk":"5346717376","pt":1646095020497,"mc":[{"id":"1.195395452","rc":[{"atl":[[7.6,6.23]],"id":41921674},{"atl":[[4.6,0]],"id":40251221},{"atb":[[2.52,0]],"id":39722911},{"atl":[[5.5,0],[9.4,0]],"id":43154431},{"atl":[[12,3.67]],"id":27151693}],"con":true,"img":false}]}
{"op":"mcm","clk":"5346717381","pt":1646095020602,"mc":[{"id":"1.195395452","rc":[{"atl":[[5.9,0]],"id":41921674},{"atl":[[5,10.14]],"id":40251221},{"atb":[[2.44,27.78]],"id":39722911},{"atl":[[10,0]],"id":27151693},{"atl":[[11,4.86],[5.7,7.79]],"id":43154431}],"con":true,"img":false}]}
{"op":"mcm","clk":"5346717513","pt":1646095024299,"mc":[{"id":"1.195395452","rc":[{"atl":[[5.1,2.92],[4.9,10.14]],"id":40251221},{"atl":[[5.6,7.8],[5.8,2.5]],"id":43154431}],"con":true,"img":false}]}
{"op":"mcm","clk":"5346717517","pt":1646095024404,"mc":[{"id":"1.195395452","rc":[{"atb":[[2.42,0],[2.46,42.88]],"id":39722911}],"con":true,"img":false}]}
{"op":"mcm","clk":"5346720174","pt":1646095098972,"mc":[{"id":"1.195395452","rc":[{"atl":[[7.6,0]],"id":41921674},{"atl":[[12,0]],"id":27151693}],"con":true,"img":false}]}
{"op":"mcm","clk":"5346720179","pt":1646095099023,"mc":[{"id":"1.195395452","rc":[{"atl":[[5.9,8.38]],"id":41921674},{"atl":[[5,0]],"id":40251221},{"atb":[[2.44,0]],"id":39722911},{"atl":[[10,4.49]],"id":27151693},{"atl":[[11,0],[5.7,0]],"id":43154431}],"con":true,"img":false}]}
{"op":"mcm","clk":"5346720184","pt":1646095099129,"mc":[{"id":"1.195395452","rc":[{"atl":[[4.8,10.14],[5.1,23.2],[4.9,0]],"id":40251221},{"atb":[[2.42,70.42],[2.46,0],[2.48,27.78]],"id":39722911},{"atl":[[5.6,0],[5.8,18.1],[5.5,7.79],[9.4,4.86]],"id":43154431}],"con":true,"img":false}]}
{"op":"mcm","clk":"5346721135","pt":1646095124406,"mc":[{"id":"1.195395452","rc":[{"atl":[[7.6,6.23],[5.9,0]],"id":41921674},{"atl":[[4.8,0]],"id":40251221},{"atb":[[2.48,0]],"id":39722911},{"atl":[[5.5,0],[9.4,0]],"id":43154431},{"atl":[[10,0],[12,3.67]],"id":27151693}],"con":true,"img":false}]}
{"op":"mcm","clk":"5346721139","pt":1646095124509,"mc":[{"id":"1.195395452","rc":[{"atl":[[5,10.14]],"id":40251221},{"atb":[[2.44,27.78]],"id":39722911},{"atl":[[11,4.86],[5.7,7.79]],"id":43154431}],"con":true,"img":false}]}
{"op":"mcm","clk":"5346721282","pt":1646095128307,"mc":[{"id":"1.195395452","rc":[{"atl":[[5.1,2.92],[4.9,10.14]],"id":40251221},{"atb":[[2.42,0],[2.46,42.88]],"id":39722911},{"atl":[[5.6,7.8],[5.8,2.5]],"id":43154431}],"con":true,"img":false}]}
{"op":"mcm","clk":"5346724414","pt":1646095199785,"mc":[{"id":"1.195395452","rc":[{"atl":[[7.6,0],[5.9,8.38]],"id":41921674},{"atl":[[5,0]],"id":40251221},{"atb":[[2.44,0]],"id":39722911},{"atl":[[11,0],[5.7,0]],"id":43154431},{"atl":[[10,4.49],[12,0]],"id":27151693}],"con":true,"img":false}]}
{"op":"mcm","clk":"5346724420","pt":1646095199886,"mc":[{"id":"1.195395452","rc":[{"atl":[[4.8,10.14],[5.1,23.2],[4.9,0]],"id":40251221},{"atb":[[2.42,70.42],[2.46,0],[2.48,27.78]],"id":39722911},{"atl":[[5.6,0],[5.8,18.1],[5.5,7.79],[9.4,4.86]],"id":43154431}],"con":true,"img":false}]}
{"op":"mcm","clk":"5346724448","pt":1646095200721,"mc":[{"id":"1.195395452","rc":[{"atl":[[7.4,0],[9.4,0]],"id":36899924},{"atl":[[10,0],[8.4,0]],"id":27151693}],"con":true,"img":false}]}
{"op":"mcm","clk":"5346724452","pt":1646095200830,"mc":[{"id":"1.195395452","rc":[{"atl":[[10.5,4.66],[8.2,5.79]],"id":36899924},{"atl":[[9.2,4.26],[11.5,4.49]],"id":27151693}],"con":true,"img":false}]}
{"op":"mcm","clk":"5346725497","pt":1646095224356,"mc":[{"id":"1.195395452","rc":[{"atl":[[7.6,6.23],[5.9,0]],"id":41921674},{"atl":[[4.8,0]],"id":40251221},{"atb":[[2.48,0]],"id":39722911},{"atl":[[5.5,0]],"id":43154431}],"con":true,"img":false}]}
{"op":"mcm","clk":"5346725500","pt":1646095224459,"mc":[{"id":"1.195395452","rc":[{"atl":[[5,10.14]],"id":40251221},{"atb":[[2.44,27.78]],"id":39722911},{"atl":[[5.7,7.79]],"id":43154431}],"con":true,"img":false}]}
{"op":"mcm","clk":"5346725660","pt":1646095228060,"mc":[{"id":"1.195395452","rc":[{"atl":[[5.1,2.92],[4.9,10.14]],"id":40251221},{"atb":[[2.42,0],[2.46,42.88]],"id":39722911},{"atl":[[5.6,7.8]],"id":43154431}],"con":true,"img":false}]}
{"op":"mcm","clk":"5346725663","pt":1646095228162,"mc":[{"id":"1.195395452","rc":[{"atl":[[5.8,2.5]],"id":43154431}],"con":true,"img":false}]}
{"op":"mcm","clk":"5346726378","pt":1646095249088,"mc":[{"id":"1.195395452","rc":[{"atl":[[8.2,0]],"id":36899924},{"atl":[[9.2,0]],"id":27151693}],"con":true,"img":false}]}
{"op":"mcm","clk":"5346726380","pt":1646095249185,"mc":[{"id":"1.195395452","rc":[{"atl":[[7.2,5.79]],"id":36899924},{"atl":[[8.2,5.93]],"id":27151693}],"con":true,"img":false}]}
{"op":"mcm","clk":"5346726554","pt":1646095254533,"mc":[{"id":"1.195395452","rc":[{"atl":[[7.2,5.58],[9,0]],"id":39979879},{"atl":[[8,0],[7.4,5.09]],"id":39722911}],"con":true,"img":false}]}
{"op":"mcm","clk":"5346727214","pt":1646095273140,"mc":[{"id":"1.195395452","rc":[{"atl":[[7.8,4.71]],"id":39722911}],"con":true,"img":false}]}
{"op":"mcm","clk":"5346727218","pt":1646095273243,"mc":[{"id":"1.195395452","rc":[{"atl":[[9.4,6.49]],"id":39722911}],"con":true,"img":false}]}
{"op":"mcm","clk":"5346727900","pt":1646095297013,"mc":[{"id":"1.195395452","rc":[{"atl":[[7.6,0],[5.9,8.38]],"id":41921674},{"atl":[[11.5,4.32],[9.4,0]],"id":39722911},{"atl":[[11.5,0],[15,2.89]],"id":27151693}],"con":true,"img":false}]}
{"op":"mcm","clk":"5346727903","pt":1646095297117,"mc":[{"id":"1.195395452","rc":[{"atl":[[5,0]],"id":40251221},{"atl":[[7.2,0]],"id":36899924},{"atb":[[2.44,0]],"id":39722911},{"atl":[[7.8,0]],"id":39722911},{"atl":[[8.2,1.66]],"id":27151693},{"atl":[[5.7,0]],"id":43154431}],"con":true,"img":false}]}
{"op":"mcm","clk":"5346727905","pt":1646095297167,"mc":[{"id":"1.195395452","rc":[{"atl":[[4.8,10.14]],"id":40251221},{"atl":[[8,5.79]],"id":36899924},{"atb":[[2.48,27.78]],"id":39722911},{"atl":[[7.2,4.71]],"id":39722911},{"atl":[[10,4.26]],"id":27151693},{"atl":[[5.5,7.79]],"id":43154431}],"con":true,"img":false}]}
{"op":"mcm","clk":"5346727906","pt":1646095297270,"mc":[{"id":"1.195395452","rc":[{"atl":[[5.1,23.2],[4.9,0]],"id":40251221},{"atb":[[2.42,70.42],[2.46,0]],"id":39722911},{"atl":[[5.6,0],[5.8,18.1]],"id":43154431}],"con":true,"img":false}]}
{"op":"mcm","clk":"5346728495","pt":1646095316201,"mc":[{"id":"1.195395452","rc":[{"atb":[[2.06,7.87]],"id":40251221}],"con":true,"img":false}]}
{"op":"mcm","clk":"5346728498","pt":1646095316357,"mc":[{"id":"1.195395452","rc":[{"atb":[[2.46,5.72]],"id":43154431}],"con":true,"img":false}]}
{"op":"mcm","clk":"5346728501","pt":1646095316407,"mc":[{"id":"1.195395452","rc":[{"atb":[[2.46,5.72]],"id":36899924}],"con":true,"img":false}]}
{"op":"mcm","clk":"5346728506","pt":1646095316666,"mc":[{"id":"1.195395452","rc":[{"atb":[[2.16,7.2]],"id":39979879}],"con":true,"img":false}]}
{"op":"mcm","clk":"5346728509","pt":1646095316715,"mc":[{"id":"1.195395452","rc":[{"atb":[[2.48,33.43]],"id":39722911}],"con":true,"img":false}]}
{"op":"mcm","clk":"5346728512","pt":1646095316820,"mc":[{"id":"1.195395452","rc":[{"atb":[[2.12,0],[2.18,54.58]],"id":39979879},{"atb":[[2.66,5.02]],"id":27151693}],"con":true,"img":false}]}
{"op":"mcm","clk":"5346728515","pt":1646095316922,"mc":[{"id":"1.195395452","rc":[{"atb":[[2.64,0],[2.68,26]],"id":27151693}],"con":true,"img":false}]}
{"op":"mcm","clk":"5346728524","pt":1646095317126,"mc":[{"id":"1.195395452","rc":[{"atb":[[1.94,8.88]],"id":41921674}],"con":true,"img":false}]}
{"op":"mcm","clk":"5346728647","pt":1646095320569,"mc":[{"id":"1.195395452","rc":[{"atl":[[5.4,0]],"id":41921674},{"atl":[[4.8,0]],"id":40251221},{"atl":[[8.8,0],[7,6.58]],"id":39979879},{"atb":[[2.48,5.64]],"id":39722911},{"atl":[[7.2,0]],"id":39722911},{"atl":[[1.92,0]],"id":42492389},{"atl":[[5.5,0]],"id":43154431}],"con":true,"img":false}]}
{"op":"mcm","clk":"5346728648","pt":1646095320620,"mc":[{"id":"1.195395452","rc":[{"atl":[[4.9,9.22]],"id":41921674},{"atl":[[5,10.14]],"id":40251221},{"atb":[[2.44,27.78]],"id":39722911},{"atl":[[8,4.71]],"id":39722911},{"atl":[[1.75,40.56]],"id":42492389},{"atl":[[5.7,7.79]],"id":43154431}],"con":true,"img":false}]}
{"op":"mcm","clk":"5346728790","pt":1646095324433,"mc":[{"id":"1.195395452","rc":[{"atl":[[5.1,2.92],[4.9,10.14]],"id":40251221},{"atb":[[2.5,27.78],[2.42,0]],"id":39722911},{"atl":[[5.6,7.8]],"id":43154431}],"con":true,"img":false}]}
{"op":"mcm","clk":"5346728796","pt":1646095324534,"mc":[{"id":"1.195395452","rc":[{"atl":[[5.8,2.5]],"id":43154431}],"con":true,"img":false}]}
{"op":"mcm","clk":"5346729161","pt":1646095334278,"mc":[{"id":"1.195395452","rc":[{"atb":[[2.16,0]],"id":39979879}],"con":true,"img":false}]}
{"op":"mcm","clk":"5346729171","pt":1646095334486,"mc":[{"id":"1.195395452","rc":[{"atb":[[2.12,89.29],[2.18,0]],"id":39979879}],"con":true,"img":false}]}
{"op":"mcm","clk":"5346729375","pt":1646095340196,"mc":[{"id":"1.195395452","rc":[{"atb":[[2.48,0]],"id":39722911}],"con":true,"img":false}]}
{"op":"mcm","clk":"5346729380","pt":1646095340300,"mc":[{"id":"1.195395452","rc":[{"atb":[[2.5,0],[2.46,55.56]],"id":39722911}],"con":true,"img":false}]}
{"op":"mcm","clk":"5346729531","pt":1646095344206,"mc":[{"id":"1.195395452","rc":[{"atb":[[2.22,35.69],[1.74,0]],"id":39722911},{"atl":[[2.04,0]],"id":42492389},{"atb":[[1.82,0],[2.42,28.5]],"id":27151693}],"con":true,"img":false}]}
{"op":"mcm","clk":"5346729534","pt":1646095344307,"mc":[{"id":"1.195395452","rc":[{"atl":[[1.92,36.05]],"id":42492389}],"con":true,"img":false}]}
{"op":"mcm","clk":"5346729701","pt":1646095348693,"mc":[{"id":"1.195395452","marketDefinition":{"bspMarket":false,"turnInPlayEnabled":false,"persistenceEnabled":false,"marketBaseRate":5.0,"eventId":"31270459","eventTypeId":"4339","numberOfWinners":3,"bettingType":"ODDS","marketType":"PLACE","marketTime":"2022-03-01T01:25:00.000Z","suspendTime":"2022-03-01T01:25:00.000Z","bspReconciled":false,"complete":true,"inPlay":false,"crossMatching":true,"runnersVoidable":false,"numberOfActiveRunners":8,"betDelay":0,"status":"OPEN","runners":[{"status":"ACTIVE","sortPriority":1,"id":40251221,"name":"1. Elsa Blueblood"},{"status":"ACTIVE","sortPriority":2,"id":42492389,"name":"3. Emilys Perfect"},{"status":"ACTIVE","sortPriority":3,"id":43154431,"name":"4. Lonely Gemma"},{"status":"ACTIVE","sortPriority":4,"id":39979879,"name":"5. Goldstar Smiles"},{"status":"ACTIVE","sortPriority":5,"id":27151693,"name":"6. Hustle Ace"},{"status":"ACTIVE","sortPriority":6,"id":41921674,"name":"7. Sozins Queen"},{"status":"ACTIVE","sortPriority":7,"id":36899924,"name":"8. Horse Range Gold"},{"status":"ACTIVE","sortPriority":8,"id":39722911,"name":"9. Know Pops"}],"regulators":["MR_INT"],"venue":"Addington","countryCode":"NZ","discountAllowed":true,"timezone":"NZ","openDate":"2022-02-28T23:02:00.000Z","version":4380660699,"name":"To Be Placed","eventName":"Addington (NZL) 1st Mar"},"rc":[],"con":true,"img":false}]}
{"op":"mcm","clk":"5346729837","pt":1646095352786,"mc":[{"id":"1.195395452","rc":[{"atb":[[2.16,7.2]],"id":39979879}],"con":true,"img":false}]}
{"op":"mcm","clk":"5346730037","pt":1646095359204,"mc":[{"id":"1.195395452","rc":[{"atb":[[2.52,5.49]],"id":39722911}],"con":true,"img":false}]}
{"op":"mcm","clk":"5346730040","pt":1646095359308,"mc":[{"id":"1.195395452","rc":[{"atb":[[2.54,27.78],[2.46,0]],"id":39722911}],"con":true,"img":false}]}
{"op":"mcm","clk":"5346730109","pt":1646095361311,"mc":[{"id":"1.195395452","rc":[{"atb":[[2.12,0],[2.18,54.58]],"id":39979879}],"con":true,"img":false}]}
{"op":"mcm","clk":"5346730114","pt":1646095361414,"mc":[{"id":"1.195395452","rc":[{"atl":[[11,0],[8.8,5]],"id":36899924},{"atl":[[7.2,0],[6.4,14.09]],"id":39979879},{"atl":[[7.4,0],[6.6,5]],"id":39722911}],"con":true,"img":false}]}
{"op":"mcm","clk":"5346730301","pt":1646095367266,"mc":[{"id":"1.195395452","rc":[{"atl":[[9.4,4.7]],"id":39979879}],"con":true,"img":false}]}
{"op":"mcm","clk":"5346730305","pt":1646095367319,"mc":[{"id":"1.195395452","rc":[{"atl":[[7,0]],"id":39979879},{"atb":[[2.44,0]],"id":39722911}],"con":true,"img":false}]}
{"op":"mcm","clk":"5346730311","pt":1646095367425,"mc":[{"id":"1.195395452","rc":[{"atb":[[2.42,27.78]],"id":39722911}],"con":true,"img":false}]}
{"op":"mcm","clk":"5346730424","pt":1646095370425,"mc":[{"id":"1.195395452","rc":[{"atb":[[2.22,0],[1.77,56.79]],"id":39722911}],"con":true,"img":false}]}
{"op":"mcm","clk":"5346730650","pt":1646095376542,"mc":[{"id":"1.195395452","rc":[{"atb":[[2.16,0]],"id":39979879},{"atb":[[2.52,0]],"id":39722911}],"con":true,"img":false}]}
{"op":"mcm","clk":"5346730655","pt":1646095376643,"mc":[{"id":"1.195395452","rc":[{"atb":[[2.12,89.29],[2.18,0]],"id":39979879},{"atb":[[2.54,0],[2.44,55.56]],"id":39722911}],"con":true,"img":false}]}
{"op":"mcm","clk":"5346731031","pt":1646095387969,"mc":[{"id":"1.195395452","rc":[{"atl":[[6.2,5],[6.6,0]],"id":39722911}],"con":true,"img":false}]}
{"op":"mcm","clk":"5346731100","pt":1646095390587,"mc":[{"id":"1.195395452","rc":[{"atl":[[5,0]],"id":40251221},{"atl":[[8,0],[6.4,7.51]],"id":39722911},{"atl":[[5.7,0]],"id":43154431}],"con":true,"img":false}]}
{"op":"mcm","clk":"5346731104","pt":1646095390691,"mc":[{"id":"1.195395452","rc":[{"atl":[[4.8,10.14],[5.1,23.2]],"id":40251221},{"atl":[[5.6,0],[5.8,18.1],[7,7.79]],"id":43154431}],"con":true,"img":false}]}
{"op":"mcm","clk":"5346731105","pt":1646095390791,"mc":[{"id":"1.195395452","rc":[{"atl":[[6,13.07],[4.9,0]],"id":40251221},{"atl":[[5.8,2.5],[7.4,10.3]],"id":43154431}],"con":true,"img":false}]}
{"op":"mcm","clk":"5346731109","pt":1646095390893,"mc":[{"id":"1.195395452","rc":[{"atl":[[5.1,2.92]],"id":40251221}],"con":true,"img":false}]}
{"op":"mcm","clk":"5346731111","pt":1646095390995,"mc":[{"id":"1.195395452","rc":[{"atl":[[6,0],[4.7,10.14]],"id":40251221},{"atl":[[5.8,10.3],[7.4,0]],"id":43154431}],"con":true,"img":false}]}
{"op":"mcm","clk":"5346731114","pt":1646095391097,"mc":[{"id":"1.195395452","rc":[{"atl":[[5.8,2.5],[6.8,7.8]],"id":43154431}],"con":true,"img":false}]}
{"op":"mcm","clk":"5346731118","pt":1646095391152,"mc":[{"id":"1.195395452","rc":[{"atl":[[5.8,10.3]],"id":43154431}],"con":true,"img":false}]}
{"op":"mcm","clk":"5346731121","pt":1646095391256,"mc":[{"id":"1.195395452","rc":[{"atl":[[6.8,0]],"id":43154431}],"con":true,"img":false}]}
{"op":"mcm","clk":"5346731223","pt":1646095394698,"mc":[{"id":"1.195395452","rc":[{"atb":[[2.16,7.2]],"id":39979879},{"atb":[[2.5,5.57]],"id":39722911}],"con":true,"img":false}]}
{"op":"mcm","clk":"5346731229","pt":1646095394901,"mc":[{"id":"1.195395452","rc":[{"atb":[[2.12,0],[2.18,54.58]],"id":39979879},{"atb":[[2.52,27.78],[2.44,0]],"id":39722911}],"con":true,"img":false}]}
{"op":"mcm","clk":"5346731549","pt":1646095404900,"mc":[{"id":"1.195395452","rc":[{"atl":[[6.4,15.01],[6.2,0]],"id":39722911}],"con":true,"img":false}]}
{"op":"mcm","clk":"5346731806","pt":1646095413016,"mc":[{"id":"1.195395452","rc":[{"atb":[[2.16,0]],"id":39979879},{"atb":[[2.5,0]],"id":39722911}],"con":true,"img":false}]}
{"op":"mcm","clk":"5346731808","pt":1646095413120,"mc":[{"id":"1.195395452","rc":[{"atb":[[2.12,89.29],[2.18,0]],"id":39979879},{"atb":[[2.52,0],[2.44,55.56]],"id":39722911}],"con":true,"img":false}]}
{"op":"mcm","clk":"5346731821","pt":1646095413529,"mc":[{"id":"1.195395452","rc":[{"atl":[[10.5,0]],"id":36899924}],"con":true,"img":false}]}
{"op":"mcm","clk":"5346731825","pt":1646095413631,"mc":[{"id":"1.195395452","rc":[{"atl":[[8.6,4.66]],"id":36899924}],"con":true,"img":false}]}
{"op":"mcm","clk":"5346732331","pt":1646095430947,"mc":[{"id":"1.195395452","rc":[{"atb":[[2.16,7.2]],"id":39979879},{"atb":[[2.5,5.57]],"id":39722911}],"con":true,"img":false}]}
{"op":"mcm","clk":"5346732333","pt":1646095431050,"mc":[{"id":"1.195395452","rc":[{"atb":[[2.12,0],[2.18,54.58]],"id":39979879},{"atb":[[2.52,27.78],[2.44,0]],"id":39722911}],"con":true,"img":false}]}
{"op":"mcm","clk":"5346732476","pt":1646095436093,"mc":[{"id":"1.195395452","rc":[{"atl":[[6.2,7.59],[9.4,0]],"id":39979879},{"atl":[[6.4,7.5],[11.5,0],[9.4,5.4]],"id":39722911},{"atl":[[7,0]],"id":43154431}],"con":true,"img":false}]}
{"op":"mcm","clk":"5346732481","pt":1646095436146,"mc":[{"id":"1.195395452","rc":[{"atl":[[6.2,7.51]],"id":39722911},{"atl":[[5.7,7.79]],"id":43154431}],"con":true,"img":false}]}
{"op":"mcm","clk":"5346732483","pt":1646095436250,"mc":[{"id":"1.195395452","rc":[{"atl":[[5.6,7.8],[5.8,2.5]],"id":43154431}],"con":true,"img":false}]}
{"op":"mcm","clk":"5346732909","pt":1646095448895,"mc":[{"id":"1.195395452","rc":[{"atb":[[2.16,0]],"id":39979879},{"atb":[[2.5,0]],"id":39722911}],"con":true,"img":false}]}
{"op":"mcm","clk":"5346732914","pt":1646095449001,"mc":[{"id":"1.195395452","rc":[{"atb":[[2.12,89.29],[2.18,0]],"id":39979879},{"atb":[[2.52,0],[2.44,55.56]],"id":39722911}],"con":true,"img":false}]}
{"op":"mcm","clk":"5346733268","pt":1646095458607,"mc":[{"id":"1.195395452","rc":[{"atl":[[4.8,0]],"id":40251221}],"con":true,"img":false}]}
{"op":"mcm","clk":"5346733269","pt":1646095458712,"mc":[{"id":"1.195395452","rc":[{"atl":[[5.1,23.2],[4.6,10.14]],"id":40251221}],"con":true,"img":false}]}
{"op":"mcm","clk":"5346733271","pt":1646095458818,"mc":[{"id":"1.195395452","rc":[{"atl":[[4.7,0]],"id":40251221}],"con":true,"img":false}]}
{"op":"mcm","clk":"5346733536","pt":1646095467403,"mc":[{"id":"1.195395452","rc":[{"atb":[[2.16,7.2]],"id":39979879}],"con":true,"img":false}]}
{"op":"mcm","clk":"5346733539","pt":1646095467505,"mc":[{"id":"1.195395452","rc":[{"atb":[[2.5,5.57]],"id":39722911}],"con":true,"img":false}]}
{"op":"mcm","clk":"5346733763","pt":1646095474606,"mc":[{"id":"1.195395452","rc":[{"atb":[[2.12,0],[2.18,54.58]],"id":39979879},{"atb":[[2.52,27.78],[2.44,0]],"id":39722911}],"con":true,"img":false}]}
{"op":"mcm","clk":"5346733972","pt":1646095481030,"mc":[{"id":"1.195395452","rc":[{"atl":[[4.6,0]],"id":40251221},{"atl":[[5.7,0]],"id":43154431}],"con":true,"img":false}]}
{"op":"mcm","clk":"5346733975","pt":1646095481133,"mc":[{"id":"1.195395452","rc":[{"atl":[[5,10.14]],"id":40251221},{"atl":[[5.6,0],[5.8,18.1],[7,7.79]],"id":43154431}],"con":true,"img":false}]}
{"op":"mcm","clk":"5346734092","pt":1646095484272,"mc":[{"id":"1.195395452","rc":[{"atl":[[5.1,2.92],[4.9,10.14]],"id":40251221}],"con":true,"img":false}]}
{"op":"mcm","clk":"5346734389","pt":1646095491179,"mc":[{"id":"1.195395452","rc":[{"atb":[[2.16,0]],"id":39979879},{"atb":[[2.5,0]],"id":39722911}],"con":true,"img":false}]}
{"op":"mcm","clk":"5346734400","pt":1646095491385,"mc":[{"id":"1.195395452","rc":[{"atb":[[2.12,89.29],[2.18,0]],"id":39979879},{"atb":[[2.52,0],[2.44,55.56]],"id":39722911}],"con":true,"img":false}]}
{"op":"mcm","clk":"5346734499","pt":1646095493657,"mc":[{"id":"1.195395452","rc":[{"atb":[[1.94,16.81]],"id":41921674},{"atb":[[2.06,14.9]],"id":40251221},{"atb":[[2.46,10.82]],"id":36899924},{"atb":[[2.46,10.82]],"id":43154431},{"atb":[[2.66,9.51]],"id":27151693}],"con":true,"img":false}]}
{"op":"mcm","clk":"5346734623","pt":1646095496765,"mc":[{"id":"1.195395452","rc":[{"atb":[[1.62,0],[1.71,120.08]],"id":40251221},{"atb":[[2.16,0],[2.48,34.97]],"id":36899924},{"atb":[[2.24,80.65],[2.44,0]],"id":39722911},{"atl":[[1.63,36.06]],"id":42492389},{"atb":[[2.68,0],[1.71,57]],"id":27151693}],"con":true,"img":false}]}
{"op":"mcm","clk":"5346734740","pt":1646095499748,"mc":[{"id":"1.195395452","rc":[{"atb":[[2.46,5.72]],"id":36899924},{"atb":[[2.16,6.42]],"id":39979879}],"con":true,"img":false}]}
{"op":"mcm","clk":"5346735007","pt":1646095505673,"mc":[{"id":"1.195395452","rc":[{"atb":[[2.54,4.83]],"id":36899924},{"atb":[[2.46,5.1]],"id":39722911}],"con":true,"img":false}]}
{"op":"mcm","clk":"5346735134","pt":1646095508862,"mc":[{"id":"1.195395452","rc":[{"atb":[[2.16,13.62]],"id":39979879}],"con":true,"img":false}]}
{"op":"mcm","clk":"5346735444","pt":1646095516628,"mc":[{"id":"1.195395452","rc":[{"atb":[[2.12,0],[2.18,54.58]],"id":39979879}],"con":true,"img":false}]}
{"op":"mcm","clk":"5346735512","pt":1646095517822,"mc":[{"id":"1.195395452","rc":[{"atb":[[2.16,7.2]],"id":39979879}],"con":true,"img":false}]}
{"op":"mcm","clk":"5346735551","pt":1646095518804,"mc":[{"id":"1.195395452","rc":[{"atb":[[2.46,0]],"id":36899924}],"con":true,"img":false}]}
{"op":"mcm","clk":"5346735556","pt":1646095518908,"mc":[{"id":"1.195395452","rc":[{"atb":[[2.46,10.82]],"id":39722911}],"con":true,"img":false}]}
{"op":"mcm","clk":"5346735692","pt":1646095521810,"mc":[{"id":"1.195395452","rc":[{"atl":[[7.4,6.42],[5.9,0]],"id":41921674},{"atl":[[1.92,0],[1.75,0]],"id":42492389},{"atb":[[2.42,0],[1.87,46.52]],"id":27151693},{"atl":[[7,0]],"id":43154431}],"con":true,"img":false}]}
{"op":"mcm","clk":"5346735696","pt":1646095521911,"mc":[{"id":"1.195395452","rc":[{"atb":[[2.56,34.97],[2.48,0]],"id":36899924},{"atl":[[2.04,36.05],[1.9,40.56]],"id":42492389},{"atl":[[5.7,7.79]],"id":43154431}],"con":true,"img":false}]}
{"op":"mcm","clk":"5346735701","pt":1646095522015,"mc":[{"id":"1.195395452","rc":[{"atl":[[5.6,7.8],[5.8,2.5]],"id":43154431}],"con":true,"img":false}]}
{"op":"mcm","clk":"5346735777","pt":1646095523719,"mc":[{"id":"1.195395452","rc":[{"atb":[[2.54,0]],"id":36899924},{"atb":[[2.24,6]],"id":39979879}],"con":true,"img":false}]}
{"op":"mcm","clk":"5346735815","pt":1646095524646,"mc":[{"id":"1.195395452","rc":[{"atl":[[5,0]],"id":40251221}],"con":true,"img":false}]}
{"op":"mcm","clk":"5346735819","pt":1646095524748,"mc":[{"id":"1.195395452","rc":[{"atl":[[4.8,10.14]],"id":40251221}],"con":true,"img":false}]}
{"op":"mcm","clk":"5346735822","pt":1646095524849,"mc":[{"id":"1.195395452","rc":[{"atl":[[5.1,23.2],[4.9,0]],"id":40251221}],"con":true,"img":false}]}
{"op":"mcm","clk":"5346735910","pt":1646095527110,"mc":[{"id":"1.195395452","rc":[{"atb":[[2.56,0],[2.42,69.94]],"id":36899924}],"con":true,"img":false}]}
{"op":"mcm","clk":"5346736073","pt":1646095530659,"mc":[{"id":"1.195395452","rc":[{"atb":[[2.16,0]],"id":39979879}],"con":true,"img":false}]}
{"op":"mcm","clk":"5346736288","pt":1646095535757,"mc":[{"id":"1.195395452","rc":[{"atb":[[2.48,5.03]],"id":36899924}],"con":true,"img":false}]}
{"op":"mcm","clk":"5346736337","pt":1646095536737,"mc":[{"id":"1.195395452","rc":[{"atb":[[2.24,12.73]],"id":39979879}],"con":true,"img":false}]}
{"op":"mcm","clk":"5346736534","pt":1646095541540,"mc":[{"id":"1.195395452","rc":[{"atb":[[2.26,54.58]],"id":39979879}],"con":true,"img":false}]}
{"op":"mcm","clk":"5346736538","pt":1646095541643,"mc":[{"id":"1.195395452","rc":[{"atb":[[2.18,0]],"id":39979879}],"con":true,"img":false}]}
{"op":"mcm","clk":"5346736581","pt":1646095542881,"mc":[{"id":"1.195395452","rc":[{"atb":[[2.48,10.68]],"id":36899924}],"con":true,"img":false}]}
{"op":"mcm","clk":"5346736690","pt":1646095545869,"mc":[{"id":"1.195395452","rc":[{"atb":[[2.24,6.73]],"id":39979879}],"con":true,"img":false}]}
{"op":"mcm","clk":"5346736726","pt":1646095546846,"mc":[{"id":"1.195395452","rc":[{"atl":[[4.8,0]],"id":40251221},{"atl":[[8,0]],"id":36899924},{"atl":[[6.4,6.58]],"id":39979879},{"atl":[[10,0]],"id":27151693}],"con":true,"img":false}]}
{"op":"mcm","clk":"5346736733","pt":1646095546950,"mc":[{"id":"1.195395452","rc":[{"atl":[[5,10.14]],"id":40251221},{"atl":[[7.2,5.79]],"id":36899924},{"atl":[[6.2,15.1]],"id":39979879},{"atl":[[8.2,5.93]],"id":27151693}],"con":true,"img":false}]}
{"op":"mcm","clk":"5346736824","pt":1646095549674,"mc":[{"id":"1.195395452","rc":[{"atl":[[5.1,2.92],[4.9,10.14]],"id":40251221}],"con":true,"img":false}]}
{"op":"mcm","clk":"5346736923","pt":1646095551989,"mc":[{"id":"1.195395452","rc":[{"atb":[[2.5,42.88],[2.42,0]],"id":36899924}],"con":true,"img":false}]}
{"op":"mcm","clk":"5346736984","pt":1646095553791,"mc":[{"id":"1.195395452","rc":[{"atb":[[2.48,5.64]],"id":36899924},{"atb":[[2.32,5.64]],"id":39979879}],"con":true,"img":false}]}
{"op":"mcm","clk":"5346737020","pt":1646095554873,"mc":[{"id":"1.195395452","rc":[{"atb":[[2.24,0]],"id":39979879}],"con":true,"img":false}]}
{"op":"mcm","clk":"5346737208","pt":1646095559813,"mc":[{"id":"1.195395452","rc":[{"atb":[[2.56,4.77]],"id":36899924}],"con":true,"img":false}]}
{"op":"mcm","clk":"5346737250","pt":1646095560889,"mc":[{"id":"1.195395452","rc":[{"atb":[[2.32,11.98]],"id":39979879}],"con":true,"img":false}]}
{"op":"mcm","clk":"5346737469","pt":1646095566288,"mc":[{"id":"1.195395452","rc":[{"atb":[[2.34,54.58]],"id":39979879}],"con":true,"img":false}]}
{"op":"mcm","clk":"5346737471","pt":1646095566395,"mc":[{"id":"1.195395452","rc":[{"atb":[[2.26,0]],"id":39979879}],"con":true,"img":false}]}
{"op":"mcm","clk":"5346737482","pt":1646095566598,"mc":[{"id":"1.195395452","rc":[{"atb":[[2.48,0]],"id":36899924}],"con":true,"img":false}]}
{"op":"mcm","clk":"5346737540","pt":1646095568032,"mc":[{"id":"1.195395452","rc":[{"atb":[[1.72,50.83],[1.63,0]],"id":40251221},{"atl":[[5.7,0]],"id":43154431}],"con":true,"img":false}]}
{"op":"mcm","clk":"5346737547","pt":1646095568085,"mc":[{"id":"1.195395452","rc":[{"atl":[[5.5,7.79]],"id":43154431}],"con":true,"img":false}]}
{"op":"mcm","clk":"5346737555","pt":1646095568240,"mc":[{"id":"1.195395452","rc":[{"atl":[[5.6,0],[5.8,18.1]],"id":43154431}],"con":true,"img":false}]}
{"op":"mcm","clk":"5346737605","pt":1646095568919,"mc":[{"id":"1.195395452","rc":[{"atb":[[2.32,6.33]],"id":39979879}],"con":true,"img":false}]}
{"op":"mcm","clk":"5346737771","pt":1646095572606,"mc":[{"id":"1.195395452","rc":[{"atb":[[2.56,10.13]],"id":36899924}],"con":true,"img":false}]}
{"op":"mcm","clk":"5346737857","pt":1646095574827,"mc":[{"id":"1.195395452","rc":[{"atb":[[2.4,5.31]],"id":39979879}],"con":true,"img":false}]}
{"op":"mcm","clk":"5346737940","pt":1646095576628,"mc":[{"id":"1.195395452","rc":[{"atb":[[2.5,0],[2.58,42.88]],"id":36899924}],"con":true,"img":false}]}
{"op":"mcm","clk":"5346737996","pt":1646095577916,"mc":[{"id":"1.195395452","rc":[{"atb":[[2.56,5.35]],"id":36899924}],"con":true,"img":false}]}
{"op":"mcm","clk":"5346738249","pt":1646095583838,"mc":[{"id":"1.195395452","rc":[{"atb":[[2.64,4.54]],"id":36899924}],"con":true,"img":false}]}
{"op":"mcm","clk":"5346738304","pt":1646095584869,"mc":[{"id":"1.195395452","rc":[{"atb":[[2.32,0]],"id":39979879}],"con":true,"img":false}]}
{"op":"mcm","clk":"5346738502","pt":1646095589569,"mc":[{"id":"1.195395452","rc":[{"atl":[[6.2,7.51],[9.4,4.7]],"id":39979879},{"atl":[[5.5,0]],"id":43154431}],"con":true,"img":false}]}
{"op":"mcm","clk":"5346738506","pt":1646095589671,"mc":[{"id":"1.195395452","rc":[{"atl":[[5.7,7.79]],"id":43154431}],"con":true,"img":false}]}
{"op":"mcm","clk":"5346738551","pt":1646095590751,"mc":[{"id":"1.195395452","rc":[{"atb":[[2.42,54.58],[2.34,0]],"id":39979879}],"con":true,"img":false}]}
{"op":"mcm","clk":"5346738554","pt":1646095590854,"mc":[{"id":"1.195395452","rc":[{"atb":[[2.56,0]],"id":36899924}],"con":true,"img":false}]}
{"op":"mcm","clk":"5346738561","pt":1646095591059,"mc":[{"id":"1.195395452","rc":[{"atb":[[2.4,11.28]],"id":39979879}],"con":true,"img":false}]}
{"op":"mcm","clk":"5346738631","pt":1646095592655,"mc":[{"id":"1.195395452","rc":[{"atl":[[5.6,7.8],[5.8,2.5]],"id":43154431}],"con":true,"img":false}]}
{"op":"mcm","clk":"5346738646","pt":1646095592964,"mc":[{"id":"1.195395452","rc":[{"atb":[[2.4,5.96]],"id":39979879}],"con":true,"img":false}]}
{"op":"mcm","clk":"5346738786","pt":1646095596667,"mc":[{"id":"1.195395452","rc":[{"atb":[[2.64,9.64]],"id":36899924}],"con":true,"img":false}]}
{"op":"mcm","clk":"5346738909","pt":1646095598876,"mc":[{"id":"1.195395452","rc":[{"atb":[[2.48,5.03]],"id":39979879}],"con":true,"img":false}]}
{"op":"mcm","clk":"5346738915","pt":1646095598980,"mc":[{"id":"1.195395452","rc":[{"atb":[[2.5,5.97],[2.42,0]],"id":39979879}],"con":true,"img":false}]}
{"op":"mcm","clk":"5346739007","pt":1646095601094,"mc":[{"id":"1.195395452","rc":[{"atb":[[2.6,42.88],[2.58,0]],"id":36899924}],"con":true,"img":false}]}
{"op":"mcm","clk":"5346739100","pt":1646095602898,"mc":[{"id":"1.195395452","rc":[{"atb":[[2.64,5.09]],"id":36899924},{"atb":[[2.48,0]],"id":39979879}],"con":true,"img":false}]}
{"op":"mcm","clk":"5346739113","pt":1646095603105,"mc":[{"id":"1.195395452","rc":[{"atb":[[2.5,0],[2.42,40.56]],"id":39979879}],"con":true,"img":false}]}
{"op":"mcm","clk":"5346739371","pt":1646095608816,"mc":[{"id":"1.195395452","rc":[{"atb":[[2.4,0]],"id":39979879}],"con":true,"img":false}]}
{"op":"mcm","clk":"5346739379","pt":1646095608970,"mc":[{"id":"1.195395452","rc":[{"atb":[[2.42,0],[2.12,81.12]],"id":39979879}],"con":true,"img":false}]}
{"op":"mcm","clk":"5346739399","pt":1646095609387,"mc":[{"id":"1.195395452","rc":[{"atl":[[6.4,0],[6.6,15]],"id":39722911}],"con":true,"img":false}]}
{"op":"mcm","clk":"5346739442","pt":1646095610389,"mc":[{"id":"1.195395452","rc":[{"atl":[[5,0]],"id":40251221},{"atl":[[6.2,0]],"id":39722911}],"con":true,"img":false}]}
{"op":"mcm","clk":"5346739445","pt":1646095610491,"mc":[{"id":"1.195395452","rc":[{"atl":[[4.8,10.14],[5.1,23.2],[4.9,0]],"id":40251221},{"atl":[[6.4,7.51]],"id":39722911}],"con":true,"img":false}]}
{"op":"mcm","clk":"5346739448","pt":1646095610596,"mc":[{"id":"1.195395452","rc":[{"atl":[[6,13.07]],"id":40251221}],"con":true,"img":false}]}
{"op":"mcm","clk":"5346739453","pt":1646095610699,"mc":[{"id":"1.195395452","rc":[{"atl":[[5.1,2.92],[6,0],[4.7,10.14]],"id":40251221}],"con":true,"img":false}]}
{"op":"mcm","clk":"5346739457","pt":1646095610801,"mc":[{"id":"1.195395452","rc":[{"atb":[[2.66,4.48]],"id":36899924}],"con":true,"img":false}]}
{"op":"mcm","clk":"5346739610","pt":1646095614704,"mc":[{"id":"1.195395452","rc":[{"atb":[[2.64,0]],"id":36899924}],"con":true,"img":false}]}
{"op":"mcm","clk":"5346739692","pt":1646095616912,"mc":[{"id":"1.195395452","rc":[{"atb":[[2.16,6.42]],"id":39979879}],"con":true,"img":false}]}
{"op":"mcm","clk":"5346739857","pt":1646095620717,"mc":[{"id":"1.195395452","rc":[{"atb":[[2.66,9.51]],"id":36899924}],"con":true,"img":false}]}
{"op":"mcm","clk":"5346740095","pt":1646095626735,"mc":[{"id":"1.195395452","rc":[{"atb":[[2.16,13.62]],"id":39979879}],"con":true,"img":false}]}
{"op":"mcm","clk":"5346740111","pt":1646095627201,"mc":[{"id":"1.195395452","rc":[{"atb":[[2.12,0],[2.18,54.58]],"id":39979879}],"con":true,"img":false}]}
{"op":"mcm","clk":"5346740171","pt":1646095628948,"mc":[{"id":"1.195395452","rc":[{"atb":[[2.16,7.2]],"id":39979879}],"con":true,"img":false}]}
{"op":"mcm","clk":"5346740420","pt":1646095634919,"mc":[{"id":"1.195395452","rc":[{"atb":[[2.24,6]],"id":39979879}],"con":true,"img":false}]}
{"op":"mcm","clk":"5346740792","pt":1646095644844,"mc":[{"id":"1.195395452","rc":[{"atb":[[2.16,0]],"id":39979879}],"con":true,"img":false}]}
{"op":"mcm","clk":"5346741007","pt":1646095650744,"mc":[{"id":"1.195395452","rc":[{"atb":[[2.24,12.73]],"id":39979879}],"con":true,"img":false}]}
{"op":"mcm","clk":"5346741019","pt":1646095651055,"mc":[{"id":"1.195395452","rc":[{"atb":[[2.18,0],[2.26,54.58]],"id":39979879}],"con":true,"img":false}]}
{"op":"mcm","clk":"5346741064","pt":1646095652486,"mc":[{"id":"1.195395452","rc":[{"atl":[[6.2,15.1],[9.4,0]],"id":39979879},{"atl":[[5.7,0]],"id":43154431}],"con":true,"img":false}]}
{"op":"mcm","clk":"5346741067","pt":1646095652589,"mc":[{"id":"1.195395452","rc":[{"atl":[[5.6,0],[5.8,18.1],[5.5,7.79]],"id":43154431}],"con":true,"img":false}]}
{"op":"mcm","clk":"5346741080","pt":1646095653002,"mc":[{"id":"1.195395452","rc":[{"atb":[[2.24,6.73]],"id":39979879}],"con":true,"img":false}]}
{"op":"mcm","clk":"5346741270","pt":1646095658960,"mc":[{"id":"1.195395452","rc":[{"atb":[[2.32,5.64]],"id":39979879}],"con":true,"img":false}]}
{"op":"mcm","clk":"5346741544","pt":1646095668805,"mc":[{"id":"1.195395452","rc":[{"atb":[[2.24,0]],"id":39979879}],"con":true,"img":false}]}
{"op":"mcm","clk":"5346741632","pt":1646095673229,"mc":[{"id":"1.195395452","rc":[{"atl":[[4.8,0]],"id":40251221},{"atl":[[5.5,0]],"id":43154431}],"con":true,"img":false}]}
{"op":"mcm","clk":"5346741634","pt":1646095673335,"mc":[{"id":"1.195395452","rc":[{"atl":[[4.6,10.14]],"id":40251221},{"atl":[[5.7,7.79]],"id":43154431}],"con":true,"img":false}]}
{"op":"mcm","clk":"5346741637","pt":1646095673389,"mc":[{"id":"1.195395452","rc":[{"atl":[[5.1,23.2],[4.7,0]],"id":40251221}],"con":true,"img":false}]}
{"op":"mcm","clk":"5346741662","pt":1646095674719,"mc":[{"id":"1.195395452","rc":[{"atb":[[2.32,11.98],[2.26,0],[2.34,54.58]],"id":39979879}],"con":true,"img":false}]}
{"op":"mcm","clk":"5346741690","pt":1646095676208,"mc":[{"id":"1.195395452","rc":[{"atl":[[5.6,7.8],[5.8,2.5]],"id":43154431}],"con":true,"img":false}]}
{"op":"mcm","clk":"5346741704","pt":1646095677027,"mc":[{"id":"1.195395452","rc":[{"atb":[[2.32,6.33]],"id":39979879}],"con":true,"img":false}]}
{"op":"mcm","clk":"5346741859","pt":1646095683010,"mc":[{"id":"1.195395452","rc":[{"atb":[[2.4,5.31]],"id":39979879}],"con":true,"img":false}]}
{"op":"mcm","clk":"5346742171","pt":1646095693159,"mc":[{"id":"1.195395452","rc":[{"atb":[[2.32,0]],"id":39979879}],"con":true,"img":false}]}
{"op":"mcm","clk":"5346742178","pt":1646095693469,"mc":[{"id":"1.195395452","rc":[{"atl":[[7.4,0],[5.9,8.38]],"id":41921674}],"con":true,"img":false}]}
{"op":"mcm","clk":"5346742183","pt":1646095693572,"mc":[{"id":"1.195395452","rc":[{"atl":[[4.6,0]],"id":40251221}],"con":true,"img":false}]}
{"op":"mcm","clk":"5346742186","pt":1646095693623,"mc":[{"id":"1.195395452","rc":[{"atl":[[5,10.14]],"id":40251221}],"con":true,"img":false}]}
{"op":"mcm","clk":"5346742272","pt":1646095696856,"mc":[{"id":"1.195395452","rc":[{"atl":[[4.9,10.14]],"id":40251221}],"con":true,"img":false}]}
{"op":"mcm","clk":"5346742276","pt":1646095696958,"mc":[{"id":"1.195395452","rc":[{"atl":[[5.1,2.92]],"id":40251221}],"con":true,"img":false}]}
{"op":"mcm","clk":"5346742311","pt":1646095698141,"mc":[{"id":"1.195395452","rc":[{"atb":[[2.42,54.58],[2.34,0]],"id":39979879}],"con":true,"img":false}]}
{"op":"mcm","clk":"5346742401","pt":1646095701369,"mc":[{"id":"1.195395452","rc":[{"atb":[[2.4,0]],"id":39979879}],"con":true,"img":false}]}
{"op":"mcm","clk":"5346742463","pt":1646095703271,"mc":[{"id":"1.195395452","rc":[{"atb":[[2.42,0],[2.12,89.29]],"id":39979879}],"con":true,"img":false}]}
{"op":"mcm","clk":"5346742641","pt":1646095709994,"mc":[{"id":"1.195395452","rc":[{"atb":[[2.16,6.42]],"id":39979879}],"con":true,"img":false}]}
{"op":"mcm","clk":"5346742744","pt":1646095713995,"mc":[{"id":"1.195395452","rc":[{"atl":[[7.4,6.42],[5.9,0]],"id":41921674}],"con":true,"img":false}]}
{"op":"mcm","clk":"5346742813","pt":1646095716765,"mc":[{"id":"1.195395452","rc":[{"atb":[[2.16,13.62]],"id":39979879}],"con":true,"img":false}]}
{"op":"mcm","clk":"5346743064","pt":1646095726387,"mc":[{"id":"1.195395452","rc":[{"atb":[[2.18,54.58]],"id":39979879}],"con":true,"img":false}]}
{"op":"mcm","clk":"5346743068","pt":1646095726488,"mc":[{"id":"1.195395452","rc":[{"atb":[[2.12,0]],"id":39979879}],"con":true,"img":false}]}
{"op":"mcm","clk":"5346743126","pt":1646095728081,"mc":[{"id":"1.195395452","rc":[{"atb":[[2.16,7.2]],"id":39979879}],"con":true,"img":false}]}
{"op":"mcm","clk":"5346743332","pt":1646095734001,"mc":[{"id":"1.195395452","rc":[{"atb":[[2.24,6]],"id":39979879}],"con":true,"img":false}]}
{"op":"mcm","clk":"5346743334","pt":1646095734102,"mc":[{"id":"1.195395452","rc":[{"atl":[[5.7,0]],"id":43154431}],"con":true,"img":false}]}
{"op":"mcm","clk":"5346743337","pt":1646095734204,"mc":[{"id":"1.195395452","rc":[{"atl":[[5.8,18.1],[5.5,7.79]],"id":43154431}],"con":true,"img":false}]}
{"op":"mcm","clk":"5346743340","pt":1646095734306,"mc":[{"id":"1.195395452","rc":[{"atl":[[5.6,0],[5.8,2.5],[5.4,7.8]],"id":43154431}],"con":true,"img":false}]}
{"op":"mcm","clk":"5346743416","pt":1646095737439,"mc":[{"id":"1.195395452","rc":[{"atl":[[10,7.46],[8.8,0]],"id":36899924}],"con":true,"img":false}]}
{"op":"mcm","clk":"5346743499","pt":1646095740932,"mc":[{"id":"1.195395452","rc":[{"atb":[[2.16,0]],"id":39979879}],"con":true,"img":false}]}
{"op":"mcm","clk":"5346743667","pt":1646095746946,"mc":[{"id":"1.195395452","rc":[{"atb":[[2.24,12.73]],"id":39979879}],"con":true,"img":false}]}
{"op":"mcm","clk":"5346743754","pt":1646095749250,"mc":[{"id":"1.195395452","rc":[{"atb":[[2.18,0],[2.26,54.58]],"id":39979879}],"con":true,"img":false}]}
{"op":"mcm","clk":"5346743854","pt":1646095752227,"mc":[{"id":"1.195395452","rc":[{"atb":[[2.24,6.73]],"id":39979879}],"con":true,"img":false}]}
{"op":"mcm","clk":"5346743911","pt":1646095754175,"mc":[{"id":"1.195395452","rc":[{"atl":[[5,0]],"id":40251221},{"atl":[[8.6,0]],"id":36899924}],"con":true,"img":false}]}
{"op":"mcm","clk":"5346743915","pt":1646095754277,"mc":[{"id":"1.195395452","rc":[{"atl":[[4.8,10.14]],"id":40251221},{"atl":[[9.4,4.66]],"id":36899924}],"con":true,"img":false}]}
{"op":"mcm","clk":"5346743917","pt":1646095754334,"mc":[{"id":"1.195395452","rc":[{"atl":[[5.1,23.2]],"id":40251221}],"con":true,"img":false}]}
{"op":"mcm","clk":"5346743920","pt":1646095754437,"mc":[{"id":"1.195395452","rc":[{"atl":[[4.9,0]],"id":40251221}],"con":true,"img":false}]}
{"op":"mcm","clk":"5346744017","pt":1646095758152,"mc":[{"id":"1.195395452","rc":[{"atb":[[2.32,5.64]],"id":39979879}],"con":true,"img":false}]}
{"op":"mcm","clk":"5346744233","pt":1646095765085,"mc":[{"id":"1.195395452","rc":[{"atb":[[2.24,0]],"id":39979879}],"con":true,"img":false}]}
{"op":"mcm","clk":"5346744381","pt":1646095771179,"mc":[{"id":"1.195395452","rc":[{"atb":[[2.32,11.98]],"id":39979879}],"con":true,"img":false}]}
{"op":"mcm","clk":"5346744395","pt":1646095771894,"mc":[{"id":"1.195395452","rc":[{"atb":[[2.34,54.58]],"id":39979879}],"con":true,"img":false}]}
{"op":"mcm","clk":"5346744399","pt":1646095771996,"mc":[{"id":"1.195395452","rc":[{"atb":[[2.26,0]],"id":39979879}],"con":true,"img":false}]}
{"op":"mcm","clk":"5346744441","pt":1646095773282,"mc":[{"id":"1.195395452","rc":[{"atb":[[2.32,6.33]],"id":39979879}],"con":true,"img":false}]}
{"op":"mcm","clk":"5346744462","pt":1646095773999,"mc":[{"id":"1.195395452","rc":[{"atl":[[4.8,0]],"id":40251221},{"atl":[[5.5,0]],"id":43154431}],"con":true,"img":false}]}
{"op":"mcm","clk":"5346744466","pt":1646095774112,"mc":[{"id":"1.195395452","rc":[{"atl":[[5,10.14]],"id":40251221},{"atl":[[5.8,18.1],[6.6,7.79]],"id":43154431}],"con":true,"img":false}]}
{"op":"mcm","clk":"5346744473","pt":1646095774212,"mc":[{"id":"1.195395452","rc":[{"atl":[[5.4,0]],"id":43154431}],"con":true,"img":false}]}
{"op":"mcm","clk":"5346744556","pt":1646095776891,"mc":[{"id":"1.195395452","rc":[{"atl":[[5.1,2.92],[4.9,10.14]],"id":40251221}],"con":true,"img":false}]}
{"op":"mcm","clk":"5346744627","pt":1646095779203,"mc":[{"id":"1.195395452","rc":[{"atb":[[2.4,5.31]],"id":39979879}],"con":true,"img":false}]}
{"op":"mcm","clk":"5346744908","pt":1646095789117,"mc":[{"id":"1.195395452","rc":[{"atb":[[2.32,0]],"id":39979879}],"con":true,"img":false}]}
{"op":"mcm","clk":"5346745047","pt":1646095794056,"mc":[{"id":"1.195395452","rc":[{"atl":[[9.4,4.7]],"id":39979879}],"con":true,"img":false}]}
{"op":"mcm","clk":"5346745050","pt":1646095794164,"mc":[{"id":"1.195395452","rc":[{"atl":[[6.2,7.51]],"id":39979879}],"con":true,"img":false}]}
{"op":"mcm","clk":"5346745054","pt":1646095794319,"mc":[{"id":"1.195395452","rc":[{"atb":[[2.42,54.58]],"id":39979879}],"con":true,"img":false}]}
{"op":"mcm","clk":"5346745058","pt":1646095794418,"mc":[{"id":"1.195395452","rc":[{"atb":[[2.34,0]],"id":39979879}],"con":true,"img":false}]}
{"op":"mcm","clk":"5346745143","pt":1646095797141,"mc":[{"id":"1.195395452","rc":[{"atb":[[2.4,0]],"id":39979879}],"con":true,"img":false}]}
{"op":"mcm","clk":"5346745150","pt":1646095797242,"mc":[{"id":"1.195395452","rc":[{"atb":[[2.42,0],[2.12,89.29]],"id":39979879}],"con":true,"img":false}]}
{"op":"mcm","clk":"5346745443","pt":1646095806147,"mc":[{"id":"1.195395452","rc":[{"atb":[[2.16,6.42]],"id":39979879}],"con":true,"img":false}]}
{"op":"mcm","clk":"5346745655","pt":1646095813381,"mc":[{"id":"1.195395452","rc":[{"atl":[[6.6,0]],"id":43154431}],"con":true,"img":false}]}
{"op":"mcm","clk":"5346745657","pt":1646095813483,"mc":[{"id":"1.195395452","rc":[{"atl":[[5.7,7.79]],"id":43154431}],"con":true,"img":false}]}
{"op":"mcm","clk":"5346745660","pt":1646095813587,"mc":[{"id":"1.195395452","rc":[{"atb":[[2.16,13.62]],"id":39979879},{"atl":[[5.6,7.8]],"id":43154431}],"con":true,"img":false}]}
{"op":"mcm","clk":"5346745663","pt":1646095813638,"mc":[{"id":"1.195395452","rc":[{"atl":[[5.8,2.5]],"id":43154431}],"con":true,"img":false}]}
{"op":"mcm","clk":"5346745854","pt":1646095819384,"mc":[{"id":"1.195395452","rc":[{"atb":[[2.12,0],[2.18,54.58]],"id":39979879}],"con":true,"img":false}]}
{"op":"mcm","clk":"5346745913","pt":1646095821279,"mc":[{"id":"1.195395452","rc":[{"atb":[[2.16,7.2]],"id":39979879}],"con":true,"img":false}]}
{"op":"mcm","clk":"5346746077","pt":1646095827224,"mc":[{"id":"1.195395452","rc":[{"atb":[[2.24,6]],"id":39979879}],"con":true,"img":false}]}
{"op":"mcm","clk":"5346746239","pt":1646095832500,"mc":[{"id":"1.195395452","rc":[{"atl":[[5,0]],"id":40251221}],"con":true,"img":false}]}
{"op":"mcm","clk":"5346746241","pt":1646095832604,"mc":[{"id":"1.195395452","rc":[{"atl":[[4.8,10.14],[5.1,23.2],[4.9,0]],"id":40251221}],"con":true,"img":false}]}
{"op":"mcm","clk":"5346746371","pt":1646095837212,"mc":[{"id":"1.195395452","rc":[{"atb":[[2.16,0]],"id":39979879}],"con":true,"img":false}]}
{"op":"mcm","clk":"5346746475","pt":1646095841326,"mc":[{"id":"1.195395452","rc":[{"atb":[[2.18,0],[2.26,54.58]],"id":39979879}],"con":true,"img":false}]}
{"op":"mcm","clk":"5346746504","pt":1646095842707,"mc":[{"id":"1.195395452","rc":[{"atb":[[2.24,0]],"id":39979879}],"con":true,"img":false}]}
{"op":"mcm","clk":"5346746601","pt":1646095846450,"mc":[{"id":"1.195395452","rc":[{"atb":[[2.12,89.29],[2.26,0]],"id":39979879}],"con":true,"img":false}]}
{"op":"mcm","clk":"5346746769","pt":1646095851716,"mc":[{"id":"1.195395452","rc":[{"atl":[[4.8,0]],"id":40251221},{"atl":[[9.4,0]],"id":36899924},{"atl":[[6.2,15.1],[9.4,0]],"id":39979879}],"con":true,"img":false}]}
{"op":"mcm","clk":"5346746771","pt":1646095851819,"mc":[{"id":"1.195395452","rc":[{"atl":[[5,10.14]],"id":40251221},{"atl":[[9.8,4.66]],"id":36899924}],"con":true,"img":false}]}
{"op":"mcm","clk":"5346746866","pt":1646095854438,"mc":[{"id":"1.195395452","rc":[{"atl":[[5.1,2.92],[4.9,10.14]],"id":40251221}],"con":true,"img":false}]}
{"op":"mcm","clk":"5346746871","pt":1646095854540,"mc":[{"id":"1.195395452","rc":[{"atb":[[2.16,6.42]],"id":39979879}],"con":true,"img":false}]}
{"op":"mcm","clk":"5346747053","pt":1646095861459,"mc":[{"id":"1.195395452","rc":[{"atb":[[2.16,13.62]],"id":39979879}],"con":true,"img":false}]}
{"op":"mcm","clk":"5346747098","pt":1646095863045,"mc":[{"id":"1.195395452","rc":[{"atb":[[2.18,54.58]],"id":39979879}],"con":true,"img":false}]}
{"op":"mcm","clk":"5346747100","pt":1646095863148,"mc":[{"id":"1.195395452","rc":[{"atb":[[2.12,0]],"id":39979879}],"con":true,"img":false}]}
{"op":"mcm","clk":"5346747131","pt":1646095864173,"mc":[{"id":"1.195395452","rc":[{"atb":[[2.16,7.2]],"id":39979879}],"con":true,"img":false}]}
{"op":"mcm","clk":"5346747326","pt":1646095870168,"mc":[{"id":"1.195395452","rc":[{"atb":[[2.24,6]],"id":39979879}],"con":true,"img":false}]}
{"op":"mcm","clk":"5346747358","pt":1646095871090,"mc":[{"id":"1.195395452","rc":[{"atl":[[5.7,0]],"id":43154431}],"con":true,"img":false}]}
{"op":"mcm","clk":"5346747362","pt":1646095871192,"mc":[{"id":"1.195395452","rc":[{"atl":[[5.8,18.1],[5.5,7.79]],"id":43154431}],"con":true,"img":false}]}
{"op":"mcm","clk":"5346747368","pt":1646095871294,"mc":[{"id":"1.195395452","rc":[{"atl":[[5.6,0],[5.8,2.5],[7.4,10.3]],"id":43154431}],"con":true,"img":false}]}
{"op":"mcm","clk":"5346747678","pt":1646095879299,"mc":[{"id":"1.195395452","rc":[{"atb":[[2.16,0]],"id":39979879}],"con":true,"img":false}]}
{"op":"mcm","clk":"5346747858","pt":1646095884617,"mc":[{"id":"1.195395452","rc":[{"atb":[[2.18,0],[2.26,54.58]],"id":39979879}],"con":true,"img":false}]}
{"op":"mcm","clk":"5346747890","pt":1646095885408,"mc":[{"id":"1.195395452","rc":[{"atb":[[2.24,0]],"id":39979879}],"con":true,"img":false}]}
{"op":"mcm","clk":"5346747893","pt":1646095885506,"mc":[{"id":"1.195395452","rc":[{"atb":[[2.12,89.29]],"id":39979879}],"con":true,"img":false}]}
{"op":"mcm","clk":"5346747897","pt":1646095885609,"mc":[{"id":"1.195395452","rc":[{"atb":[[2.26,0]],"id":39979879}],"con":true,"img":false}]}
{"op":"mcm","clk":"5346748056","pt":1646095890022,"mc":[{"id":"1.195395452","rc":[{"atl":[[5.5,0]],"id":43154431}],"con":true,"img":false}]}
{"op":"mcm","clk":"5346748061","pt":1646095890125,"mc":[{"id":"1.195395452","rc":[{"atl":[[7.2,7.79]],"id":43154431}],"con":true,"img":false}]}
{"op":"mcm","clk":"5346748156","pt":1646095892739,"mc":[{"id":"1.195395452","rc":[{"atl":[[5.8,10.3],[7.4,0]],"id":43154431}],"con":true,"img":false}]}
{"op":"mcm","clk":"5346748162","pt":1646095892844,"mc":[{"id":"1.195395452","rc":[{"atl":[[7,7.8]],"id":43154431}],"con":true,"img":false}]}
{"op":"mcm","clk":"5346748167","pt":1646095892897,"mc":[{"id":"1.195395452","rc":[{"atl":[[5.8,2.5]],"id":43154431}],"con":true,"img":false}]}
{"op":"mcm","clk":"5346748171","pt":1646095893002,"mc":[{"id":"1.195395452","rc":[{"atl":[[5.8,10.3]],"id":43154431}],"con":true,"img":false}]}
{"op":"mcm","clk":"5346748175","pt":1646095893103,"mc":[{"id":"1.195395452","rc":[{"atl":[[7,0]],"id":43154431}],"con":true,"img":false}]}
{"op":"mcm","clk":"5346748210","pt":1646095894227,"mc":[{"id":"1.195395452","rc":[{"atb":[[2.16,6.42]],"id":39979879}],"con":true,"img":false}]}
{"op":"mcm","clk":"5346748342","pt":1646095898122,"mc":[{"id":"1.195395452","rc":[{"atl":[[7,16.67]],"id":43154431}],"con":true,"img":false}]}
{"op":"mcm","clk":"5346748346","pt":1646095898220,"mc":[{"id":"1.195395452","rc":[{"atl":[[5.8,2.5]],"id":43154431}],"con":true,"img":false}]}
{"op":"mcm","clk":"5346748536","pt":1646095903650,"mc":[{"id":"1.195395452","rc":[{"atb":[[2.16,13.62]],"id":39979879}],"con":true,"img":false}]}
{"op":"mcm","clk":"5346748621","pt":1646095906724,"mc":[{"id":"1.195395452","rc":[{"atb":[[2.12,0],[2.18,54.58]],"id":39979879}],"con":true,"img":false}]}
{"op":"mcm","clk":"5346748684","pt":1646095908728,"mc":[{"id":"1.195395452","rc":[{"atl":[[5,0]],"id":40251221},{"atl":[[9.8,0]],"id":36899924}],"con":true,"img":false}]}
{"op":"mcm","clk":"5346748688","pt":1646095908881,"mc":[{"id":"1.195395452","rc":[{"atl":[[4.8,10.14],[5.1,23.2],[4.9,0]],"id":40251221},{"atl":[[9.4,4.66]],"id":36899924}],"con":true,"img":false}]}
{"op":"mcm","clk":"5346748703","pt":1646095909343,"mc":[{"id":"1.195395452","rc":[{"atb":[[2.16,7.2]],"id":39979879}],"con":true,"img":false}]}
{"op":"mcm","clk":"5346748879","pt":1646095915340,"mc":[{"id":"1.195395452","rc":[{"atb":[[2.24,6]],"id":39979879}],"con":true,"img":false}]}
{"op":"mcm","clk":"5346748994","pt":1646095919283,"mc":[{"id":"1.195395452","rc":[{"atl":[[5.8,10.3]],"id":43154431}],"con":true,"img":false}]}
{"op":"mcm","clk":"5346748998","pt":1646095919385,"mc":[{"id":"1.195395452","rc":[{"atl":[[7,0]],"id":43154431}],"con":true,"img":false}]}
{"op":"mcm","clk":"5346749060","pt":1646095921692,"mc":[{"id":"1.195395452","rc":[{"atb":[[2.16,0]],"id":39979879}],"con":true,"img":false}]}
{"op":"mcm","clk":"5346749226","pt":1646095927283,"mc":[{"id":"1.195395452","rc":[{"atl":[[4.8,0]],"id":40251221},{"atl":[[9.4,0]],"id":36899924},{"atb":[[2.24,12.73]],"id":39979879}],"con":true,"img":false}]}
{"op":"mcm","clk":"5346749231","pt":1646095927385,"mc":[{"id":"1.195395452","rc":[{"atl":[[5,10.14]],"id":40251221},{"atl":[[9.8,4.66]],"id":36899924}],"con":true,"img":false}]}
{"op":"mcm","clk":"5346749250","pt":1646095927797,"mc":[{"id":"1.195395452","rc":[{"atb":[[2.18,0],[2.26,54.58]],"id":39979879}],"con":true,"img":false}]}
{"op":"mcm","clk":"5346749314","pt":1646095929896,"mc":[{"id":"1.195395452","rc":[{"atl":[[4.9,10.14]],"id":40251221}],"con":true,"img":false}]}
{"op":"mcm","clk":"5346749318","pt":1646095929999,"mc":[{"id":"1.195395452","rc":[{"atl":[[5.1,2.92]],"id":40251221}],"con":true,"img":false}]}
{"op":"mcm","clk":"5346749330","pt":1646095930510,"mc":[{"id":"1.195395452","rc":[{"atb":[[2.24,6.73]],"id":39979879}],"con":true,"img":false}]}
{"op":"mcm","clk":"5346749507","pt":1646095936521,"mc":[{"id":"1.195395452","rc":[{"atb":[[2.32,5.64]],"id":39979879}],"con":true,"img":false}]}
{"op":"mcm","clk":"5346749744","pt":1646095945598,"mc":[{"id":"1.195395452","rc":[{"atb":[[2.24,0]],"id":39979879}],"con":true,"img":false}]}
{"op":"mcm","clk":"5346749763","pt":1646095946315,"mc":[{"id":"1.195395452","rc":[{"atl":[[7.2,0]],"id":43154431}],"con":true,"img":false}]}
{"op":"mcm","clk":"5346749767","pt":1646095946417,"mc":[{"id":"1.195395452","rc":[{"atl":[[5.7,7.79]],"id":43154431}],"con":true,"img":false}]}
{"op":"mcm","clk":"5346749770","pt":1646095946520,"mc":[{"id":"1.195395452","rc":[{"atl":[[5.6,7.8],[5.8,2.5]],"id":43154431}],"con":true,"img":false}]}
{"op":"mcm","clk":"5346749829","pt":1646095948621,"mc":[{"id":"1.195395452","rc":[{"atb":[[2.26,0],[2.34,54.58]],"id":39979879}],"con":true,"img":false}]}
{"op":"mcm","clk":"5346749940","pt":1646095951648,"mc":[{"id":"1.195395452","rc":[{"atb":[[2.32,0]],"id":39979879}],"con":true,"img":false}]}
{"op":"mcm","clk":"5346750006","pt":1646095953750,"mc":[{"id":"1.195395452","rc":[{"atb":[[2.12,89.29],[2.34,0]],"id":39979879}],"con":true,"img":false}]}
{"op":"mcm","clk":"5346750193","pt":1646095960528,"mc":[{"id":"1.195395452","rc":[{"atb":[[2.16,6.42]],"id":39979879}],"con":true,"img":false}]}
{"op":"mcm","clk":"5346750455","pt":1646095970051,"mc":[{"id":"1.195395452","rc":[{"atb":[[2.16,13.62]],"id":39979879}],"con":true,"img":false}]}
{"op":"mcm","clk":"5346750564","pt":1646095974358,"mc":[{"id":"1.195395452","rc":[{"atb":[[2.12,0],[2.18,54.58]],"id":39979879}],"con":true,"img":false}]}
{"op":"mcm","clk":"5346750594","pt":1646095975482,"mc":[{"id":"1.195395452","rc":[{"atb":[[2.16,7.2]],"id":39979879}],"con":true,"img":false}]}
{"op":"mcm","clk":"5346750753","pt":1646095981583,"mc":[{"id":"1.195395452","rc":[{"atb":[[2.24,6]],"id":39979879}],"con":true,"img":false}]}
{"op":"mcm","clk":"5346750814","pt":1646095983173,"mc":[{"id":"1.195395452","rc":[{"atl":[[5,0]],"id":40251221}],"con":true,"img":false}]}
{"op":"mcm","clk":"5346750817","pt":1646095983275,"mc":[{"id":"1.195395452","rc":[{"atl":[[4.8,10.14],[5.1,23.2]],"id":40251221}],"con":true,"img":false}]}
{"op":"mcm","clk":"5346750820","pt":1646095983378,"mc":[{"id":"1.195395452","rc":[{"atl":[[5.1,2.92],[4.9,0],[4.7,10.14]],"id":40251221}],"con":true,"img":false}]}
{"op":"mcm","clk":"5346750971","pt":1646095987995,"mc":[{"id":"1.195395452","rc":[{"atb":[[2.16,0]],"id":39979879}],"con":true,"img":false}]}
{"op":"mcm","clk":"5346751133","pt":1646095993703,"mc":[{"id":"1.195395452","rc":[{"atb":[[2.24,12.73]],"id":39979879}],"con":true,"img":false}]}
{"op":"mcm","clk":"5346751165","pt":1646095994831,"mc":[{"id":"1.195395452","rc":[{"atb":[[2.18,0],[2.26,54.58]],"id":39979879}],"con":true,"img":false}]}
{"op":"mcm","clk":"5346751219","pt":1646095996530,"mc":[{"id":"1.195395452","rc":[{"atb":[[2.24,6.73]],"id":39979879}],"con":true,"img":false}]}
{"op":"mcm","clk":"5346751373","pt":1646096001408,"mc":[{"id":"1.195395452","rc":[{"atl":[[9.8,0]],"id":36899924},{"atl":[[5.7,0]],"id":43154431}],"con":true,"img":false}]}
{"op":"mcm","clk":"5346751376","pt":1646096001512,"mc":[{"id":"1.195395452","rc":[{"atl":[[9.4,4.66]],"id":36899924},{"atl":[[5.8,18.1],[5.5,7.79]],"id":43154431}],"con":true,"img":false}]}
{"op":"mcm","clk":"5346751381","pt":1646096001614,"mc":[{"id":"1.195395452","rc":[{"atl":[[5.6,0],[5.8,2.5],[7.4,10.3]],"id":43154431}],"con":true,"img":false}]}
{"op":"mcm","clk":"5346751385","pt":1646096001716,"mc":[{"id":"1.195395452","rc":[{"atl":[[5.4,7.8]],"id":43154431}],"con":true,"img":false}]}
{"op":"mcm","clk":"5346751390","pt":1646096001820,"mc":[{"id":"1.195395452","rc":[{"atl":[[7.4,0]],"id":43154431}],"con":true,"img":false}]}
{"op":"mcm","clk":"5346751413","pt":1646096002404,"mc":[{"id":"1.195395452","rc":[{"atb":[[2.32,5.64]],"id":39979879}],"con":true,"img":false}]}
{"op":"mcm","clk":"5346751715","pt":1646096011960,"mc":[{"id":"1.195395452","rc":[{"atb":[[2.24,0]],"id":39979879}],"con":true,"img":false}]}
{"op":"mcm","clk":"5346751806","pt":1646096014934,"mc":[{"id":"1.195395452","rc":[{"atb":[[2.26,0],[2.34,54.58]],"id":39979879}],"con":true,"img":false}]}
{"op":"mcm","clk":"5346751889","pt":1646096018064,"mc":[{"id":"1.195395452","rc":[{"atb":[[2.32,0]],"id":39979879}],"con":true,"img":false}]}
{"op":"mcm","clk":"5346751892","pt":1646096018164,"mc":[{"id":"1.195395452","rc":[{"atb":[[2.12,89.29]],"id":39979879}],"con":true,"img":false}]}
{"op":"mcm","clk":"5346751896","pt":1646096018269,"mc":[{"id":"1.195395452","rc":[{"atb":[[2.34,0]],"id":39979879}],"con":true,"img":false}]}
{"op":"mcm","clk":"5346751971","pt":1646096020675,"mc":[{"id":"1.195395452","rc":[{"atb":[[1.3,0],[1.39,164.42]],"id":41921674},{"atl":[[10,0],[7.4,8.29]],"id":36899924},{"atl":[[6.4,0],[5.3,9.37]],"id":39979879},{"atl":[[5.8,10.01],[6.6,0]],"id":39722911},{"atb":[[2.4,114.31],[2.16,0]],"id":43154431}],"con":true,"img":false}]}
{"op":"mcm","clk":"5346751976","pt":1646096020779,"mc":[{"id":"1.195395452","rc":[{"atl":[[5.3,2.79],[6,6.58]],"id":39979879},{"atl":[[5.8,2.5],[6.2,7.51]],"id":39722911}],"con":true,"img":false}]}
{"op":"mcm","clk":"5346751979","pt":1646096020880,"mc":[{"id":"1.195395452","rc":[{"atl":[[5.3,12.16],[6,0]],"id":39979879}],"con":true,"img":false}]}
{"op":"mcm","clk":"5346751984","pt":1646096020980,"mc":[{"id":"1.195395452","rc":[{"atl":[[5.3,2.79],[6,6.58]],"id":39979879}],"con":true,"img":false}]}
{"op":"mcm","clk":"5346751986","pt":1646096021083,"mc":[{"id":"1.195395452","rc":[{"atl":[[5.3,14.95],[6,0]],"id":39979879}],"con":true,"img":false}]}
{"op":"mcm","clk":"5346751989","pt":1646096021137,"mc":[{"id":"1.195395452","rc":[{"atl":[[5.3,2.79],[6,6.58]],"id":39979879}],"con":true,"img":false}]}
{"op":"mcm","clk":"5346752140","pt":1646096026462,"mc":[{"id":"1.195395452","rc":[{"atb":[[2.16,6.42]],"id":39979879}],"con":true,"img":false}]}
{"op":"mcm","clk":"5346752143","pt":1646096026573,"mc":[{"id":"1.195395452","rc":[{"atb":[[2.12,0],[2.18,54.58]],"id":39979879},{"atl":[[5.3,9.37],[6,0]],"id":39979879}],"con":true,"img":false}]}
{"op":"mcm","clk":"5346752233","pt":1646096029795,"mc":[{"id":"1.195395452","rc":[{"atb":[[2.16,0]],"id":39979879}],"con":true,"img":false}]}
{"op":"mcm","clk":"5346752282","pt":1646096031698,"mc":[{"id":"1.195395452","rc":[{"atb":[[2.12,89.29],[2.18,0]],"id":39979879}],"con":true,"img":false}]}
{"op":"mcm","clk":"5346752321","pt":1646096033592,"mc":[{"id":"1.195395452","rc":[{"atl":[[1.63,0],[1.68,72.12]],"id":42492389},{"atb":[[2.4,42.88],[2.3,169.28]],"id":43154431}],"con":true,"img":false}]}
{"op":"mcm","clk":"5346752441","pt":1646096037294,"mc":[{"id":"1.195395452","rc":[{"atl":[[9,4.93]],"id":39979879}],"con":true,"img":false}]}
{"op":"mcm","clk":"5346752444","pt":1646096037409,"mc":[{"id":"1.195395452","rc":[{"atl":[[4.8,0]],"id":40251221},{"atl":[[9.4,0]],"id":36899924},{"atl":[[6.2,7.51]],"id":39979879},{"atl":[[5.5,0]],"id":43154431}],"con":true,"img":false}]}
{"op":"mcm","clk":"5346752447","pt":1646096037500,"mc":[{"id":"1.195395452","rc":[{"atl":[[4.6,10.14]],"id":40251221},{"atl":[[11,4.66]],"id":36899924},{"atl":[[6.6,7.79]],"id":43154431}],"con":true,"img":false}]}
{"op":"mcm","clk":"5346752452","pt":1646096037617,"mc":[{"id":"1.195395452","rc":[{"atl":[[5.1,23.2],[4.7,0]],"id":40251221},{"atl":[[5.8,18.1],[5.4,0]],"id":43154431}],"con":true,"img":false}]}
{"op":"mcm","clk":"5346752479","pt":1646096038592,"mc":[{"id":"1.195395452","rc":[{"atb":[[2.16,6.42]],"id":39979879}],"con":true,"img":false}]}
{"op":"mcm","clk":"5346752550","pt":1646096040685,"mc":[{"id":"1.195395452","rc":[{"atl":[[5.8,10.01],[6.2,0]],"id":39722911}],"con":true,"img":false}]}
{"op":"mcm","clk":"5346752783","pt":1646096047621,"mc":[{"id":"1.195395452","rc":[{"atb":[[2.16,13.62]],"id":39979879}],"con":true,"img":false}]}
{"op":"mcm","clk":"5346752812","pt":1646096048494,"mc":[{"id":"1.195395452","rc":[{"atb":[[1.53,120.08],[1.71,0]],"id":40251221},{"atb":[[2.6,0],[2.68,42.88]],"id":36899924},{"atl":[[5.3,2.79],[5.4,18.74]],"id":39979879},{"atb":[[1.98,102.04]],"id":39722911},{"atl":[[1.72,138.89]],"id":42492389},{"atb":[[1.98,75.06],[1.71,0]],"id":27151693}],"con":true,"img":false}]}
{"op":"mcm","clk":"5346752817","pt":1646096048599,"mc":[{"id":"1.195395452","rc":[{"atb":[[2.24,0]],"id":39722911},{"atl":[[1.68,0]],"id":42492389}],"con":true,"img":false}]}
{"op":"mcm","clk":"5346752878","pt":1646096050599,"mc":[{"id":"1.195395452","rc":[{"atb":[[2.66,5.02]],"id":36899924}],"con":true,"img":false}]}
{"op":"mcm","clk":"5346752910","pt":1646096051525,"mc":[{"id":"1.195395452","rc":[{"atb":[[2.12,0],[2.16,68.2]],"id":39979879}],"con":true,"img":false}]}
{"op":"mcm","clk":"5346752915","pt":1646096051625,"mc":[{"id":"1.195395452","rc":[{"atb":[[2.12,54.58],[2.16,13.62]],"id":39979879}],"con":true,"img":false}]}
{"op":"mcm","clk":"5346752918","pt":1646096051726,"mc":[{"id":"1.195395452","rc":[{"atb":[[2.12,0],[2.16,68.2]],"id":39979879}],"con":true,"img":false}]}
{"op":"mcm","clk":"5346753010","pt":1646096054616,"mc":[{"id":"1.195395452","rc":[{"atb":[[2.16,61.78]],"id":39979879}],"con":true,"img":false}]}
{"op":"mcm","clk":"5346753025","pt":1646096055029,"mc":[{"id":"1.195395452","rc":[{"atl":[[4.6,0]],"id":40251221},{"atl":[[6.4,0]],"id":39722911},{"atl":[[2.04,0]],"id":42492389}],"con":true,"img":false}]}
{"op":"mcm","clk":"5346753028","pt":1646096055129,"mc":[{"id":"1.195395452","rc":[{"atl":[[5,10.14]],"id":40251221},{"atl":[[7,7.51]],"id":39722911},{"atl":[[2.24,36.05]],"id":42492389}],"con":true,"img":false}]}
{"op":"mcm","clk":"5346753073","pt":1646096056720,"mc":[{"id":"1.195395452","rc":[{"atb":[[2.74,4.28]],"id":36899924}],"con":true,"img":false}]}
{"op":"mcm","clk":"5346753095","pt":1646096057336,"mc":[{"id":"1.195395452","rc":[{"atl":[[5.1,2.92],[4.9,10.14]],"id":40251221}],"con":true,"img":false}]}
{"op":"mcm","clk":"5346753185","pt":1646096059646,"mc":[{"id":"1.195395452","rc":[{"atb":[[2.2,6.2]],"id":39979879}],"con":true,"img":false}]}
{"op":"mcm","clk":"5346753430","pt":1646096066250,"mc":[{"id":"1.195395452","rc":[{"atb":[[2.66,0]],"id":36899924},{"atb":[[2.16,54.58]],"id":39979879}],"con":true,"img":false}]}
{"op":"mcm","clk":"5346753493","pt":1646096068145,"mc":[{"id":"1.195395452","rc":[{"atb":[[2.76,42.88]],"id":36899924}],"con":true,"img":false}]}
{"op":"mcm","clk":"5346753497","pt":1646096068248,"mc":[{"id":"1.195395452","rc":[{"atb":[[2.68,0]],"id":36899924}],"con":true,"img":false}]}
{"op":"mcm","clk":"5346753508","pt":1646096068656,"mc":[{"id":"1.195395452","rc":[{"atb":[[2.74,0]],"id":36899924}],"con":true,"img":false}]}
{"op":"mcm","clk":"5346753655","pt":1646096072357,"mc":[{"id":"1.195395452","rc":[{"atb":[[2.2,13.16]],"id":39979879}],"con":true,"img":false}]}
{"op":"mcm","clk":"5346753659","pt":1646096072460,"mc":[{"id":"1.195395452","rc":[{"atl":[[5,0]],"id":40251221},{"atl":[[6.2,0]],"id":39979879},{"atl":[[1.9,0]],"id":42492389},{"atl":[[6.6,0]],"id":43154431}],"con":true,"img":false}]}
{"op":"mcm","clk":"5346753661","pt":1646096072562,"mc":[{"id":"1.195395452","rc":[{"atl":[[5.6,10.14],[5.1,23.2],[4.9,0]],"id":40251221},{"atl":[[5.3,10.3]],"id":39979879},{"atl":[[1.71,40.56]],"id":42492389},{"atl":[[5.7,7.79]],"id":43154431}],"con":true,"img":false}]}
{"op":"mcm","clk":"5346753664","pt":1646096072665,"mc":[{"id":"1.195395452","rc":[{"atl":[[1.72,0],[1.7,40.56]],"id":42492389},{"atl":[[5.6,7.8],[5.8,2.5]],"id":43154431}],"con":true,"img":false}]}
{"op":"mcm","clk":"5346753683","pt":1646096073231,"mc":[{"id":"1.195395452","rc":[{"atb":[[2.42,70.42]],"id":36899924}],"con":true,"img":false}]}
{"op":"mcm","clk":"5346753689","pt":1646096073338,"mc":[{"id":"1.195395452","rc":[{"atb":[[2.76,0]],"id":36899924}],"con":true,"img":false}]}
{"op":"mcm","clk":"5346753927","pt":1646096080670,"mc":[{"id":"1.195395452","rc":[{"atb":[[2.48,5.03]],"id":36899924}],"con":true,"img":false}]}
{"op":"mcm","clk":"5346754207","pt":1646096087607,"mc":[{"id":"1.195395452","rc":[{"atb":[[2.5,42.88],[2.42,0]],"id":36899924}],"con":true,"img":false}]}
{"op":"mcm","clk":"5346754300","pt":1646096089716,"mc":[{"id":"1.195395452","rc":[{"atb":[[2.48,0]],"id":36899924}],"con":true,"img":false}]}
{"op":"mcm","clk":"5346754310","pt":1646096089872,"mc":[{"id":"1.195395452","rc":[{"atb":[[2.5,0],[2.42,70.42]],"id":36899924}],"con":true,"img":false}]}
{"op":"mcm","clk":"5346754331","pt":1646096090485,"mc":[{"id":"1.195395452","rc":[{"atl":[[5.7,0]],"id":43154431}],"con":true,"img":false}]}
{"op":"mcm","clk":"5346754334","pt":1646096090587,"mc":[{"id":"1.195395452","rc":[{"atl":[[5.6,0],[5.8,18.1],[7,7.79]],"id":43154431}],"con":true,"img":false}]}
{"op":"mcm","clk":"5346754341","pt":1646096090794,"mc":[{"id":"1.195395452","rc":[{"atb":[[2.48,5.64]],"id":36899924}],"con":true,"img":false}]}
{"op":"mcm","clk":"5346754620","pt":1646096098805,"mc":[{"id":"1.195395452","rc":[{"atb":[[2.48,10.68]],"id":36899924}],"con":true,"img":false}]}
{"op":"mcm","clk":"5346754682","pt":1646096100302,"mc":[{"id":"1.195395452","rc":[{"atl":[[7.2,12.11],[11,0]],"id":36899924},{"atb":[[1.99,44.35],[1.77,0]],"id":39722911},{"atl":[[1.71,0]],"id":42492389},{"atb":[[1.87,0]],"id":27151693}],"con":true,"img":false}]}
{"op":"mcm","clk":"5346754689","pt":1646096100403,"mc":[{"id":"1.195395452","rc":[{"atl":[[1.72,81.12],[1.7,0],[1.9,40.56]],"id":42492389},{"atb":[[1.99,46.52]],"id":27151693}],"con":true,"img":false}]}
{"op":"mcm","clk":"5346754811","pt":1646096103229,"mc":[{"id":"1.195395452","rc":[{"atb":[[1.72,69.44],[1.74,27.03],[1.7,107.14],[1.68,183.82],[1.76,26.32]],"id":41921674},{"atl":[[3.2,34.09],[3.1,23.81],[3,10],[3.3,54.35]],"id":41921674},{"atb":[[1.59,127.12],[1.63,31.75],[1.57,219.3],[1.61,81.97]],"id":40251221},{"atl":[[3.6,28.85],[3.7,46.3],[3.4,8.33],[3.5,20]],"id":40251221},{"atb":[[2.24,60.48],[2.32,50.12],[2.28,39.06],[2.2,204.22]],"id":36899924},{"atl":[[5.6,16.3],[5.8,28.54],[5.2,4.76],[5.4,11.36]],"id":36899924},{"atb":[[1.99,75.76],[2.02,89.58],[2.06,18.87],[1.97,128.87]],"id":39979879},{"atl":[[5.6,10.87],[5.8,15.62],[6,25],[5.4,23.29]],"id":39979879},{"atb":[[1.99,170.61],[2.02,73.53],[2.06,47.17],[2.1,18.18]],"id":39722911},{"atl":[[5.1,18.29],[5.3,29.07],[4.9,12.82],[4.7,5.41]],"id":39722911},{"atb":[[1.02,2165.55]],"id":42492389},{"atl":[[1.36,208.33],[1.32,62.5],[1.34,147.06],[1.38,250]],"id":42492389},{"atb":[[1.99,172.78],[2.02,73.53],[2.06,47.17],[2.1,18.18]],"id":27151693},{"atl":[[11,2],[12,4.55],[13,6.25],[14,9.62]],"id":27151693},{"atb":[[2.56,48.08],[2.52,82.24],[2.64,12.2],[2.6,31.25]],"id":43154431},{"atl":[[5.1,18.29],[5.3,29.07],[4.9,12.82],[4.7,5.41]],"id":43154431}],"con":true,"img":false}]}
{"op":"mcm","clk":"5346754818","pt":1646096103435,"mc":[{"id":"1.195395452","rc":[{"atb":[[1.76,0]],"id":41921674},{"atl":[[2.98,23.81],[3.95,0]],"id":41921674},{"atl":[[5.1,2.92],[4.4,29.41]],"id":40251221},{"atl":[[5.8,2.5],[5.3,52.33]],"id":39722911}],"con":true,"img":false}]}
{"op":"mcm","clk":"5346754867","pt":1646096104717,"mc":[{"id":"1.195395452","rc":[{"atb":[[2.46,5.72]],"id":43154431}],"con":true,"img":false}]}
{"op":"mcm","clk":"5346754880","pt":1646096105025,"mc":[{"id":"1.195395452","rc":[{"atb":[[2.2,67.74]],"id":39979879}],"con":true,"img":false}]}
{"op":"mcm","clk":"5346754887","pt":1646096105127,"mc":[{"id":"1.195395452","rc":[{"atb":[[2.16,0]],"id":39979879}],"con":true,"img":false}]}
{"op":"mcm","clk":"5346755001","pt":1646096107695,"mc":[{"id":"1.195395452","rc":[{"atb":[[2.2,61.53]],"id":39979879}],"con":true,"img":false}]}
{"op":"mcm","clk":"5346755042","pt":1646096108517,"mc":[{"id":"1.195395452","rc":[{"atl":[[3.1,57.9],[2.98,0]],"id":41921674}],"con":true,"img":false}]}
{"op":"mcm","clk":"5346755045","pt":1646096108620,"mc":[{"id":"1.195395452","rc":[{"atl":[[3.2,79.54]],"id":41921674}],"con":true,"img":false}]}
{"op":"mcm","clk":"5346755049","pt":1646096108721,"mc":[{"id":"1.195395452","rc":[{"atl":[[3.1,23.8]],"id":41921674}],"con":true,"img":false}]}
{"op":"mcm","clk":"5346755065","pt":1646096109133,"mc":[{"id":"1.195395452","rc":[{"atb":[[2.5,42.88],[2.42,0]],"id":36899924}],"con":true,"img":false}]}
{"op":"mcm","clk":"5346755090","pt":1646096109801,"mc":[{"id":"1.195395452","rc":[{"atl":[[5.1,36.58],[5.8,2.5]],"id":43154431}],"con":true,"img":false}]}
{"op":"mcm","clk":"5346755109","pt":1646096110314,"mc":[{"id":"1.195395452","rc":[{"atl":[[7.2,5.79],[10,4.35]],"id":36899924},{"atl":[[2.44,26.04],[2.24,0]],"id":42492389}],"con":true,"img":false}]}
{"op":"mcm","clk":"5346755114","pt":1646096110417,"mc":[{"id":"1.195395452","rc":[{"atl":[[5.3,2.79]],"id":39979879}],"con":true,"img":false}]}
{"op":"mcm","clk":"5346755119","pt":1646096110520,"mc":[{"id":"1.195395452","rc":[{"atl":[[5.9,7.51]],"id":39979879}],"con":true,"img":false}]}
{"op":"mcm","clk":"5346755127","pt":1646096110725,"mc":[{"id":"1.195395452","rc":[{"atb":[[2.66,4.48]],"id":43154431}],"con":true,"img":false}]}
{"op":"mcm","clk":"5346755132","pt":1646096110827,"mc":[{"id":"1.195395452","rc":[{"atb":[[2.48,5.64]],"id":36899924}],"con":true,"img":false}]}
{"op":"mcm","clk":"5346755240","pt":1646096113703,"mc":[{"id":"1.195395452","rc":[{"atb":[[2.26,5.91]],"id":39979879}],"con":true,"img":false}]}
{"op":"mcm","clk":"5346755337","pt":1646096116739,"mc":[{"id":"1.195395452","rc":[{"atb":[[2.56,4.77]],"id":36899924}],"con":true,"img":false}]}
{"op":"mcm","clk":"5346755342","pt":1646096116840,"mc":[{"id":"1.195395452","rc":[{"atb":[[2.5,0],[2.58,5.65]],"id":36899924}],"con":true,"img":false}]}
{"op":"mcm","clk":"5346755442","pt":1646096119561,"mc":[{"id":"1.195395452","rc":[{"atl":[[1.36,417.89],[1.72,0]],"id":42492389}],"con":true,"img":false}]}
{"op":"mcm","clk":"5346755450","pt":1646096119818,"mc":[{"id":"1.195395452","rc":[{"atb":[[2.56,0]],"id":36899924}],"con":true,"img":false}]}
{"op":"mcm","clk":"5346755472","pt":1646096120441,"mc":[{"id":"1.195395452","rc":[{"atb":[[1.72,0]],"id":40251221},{"atl":[[5.6,0]],"id":40251221},{"atl":[[5.9,0]],"id":39979879},{"atl":[[8.2,1.66]],"id":27151693}],"con":true,"img":false}]}
{"op":"mcm","clk":"5346755478","pt":1646096120542,"mc":[{"id":"1.195395452","rc":[{"atb":[[1.62,50.83]],"id":40251221},{"atl":[[4.3,10.14]],"id":40251221},{"atl":[[6.6,9.65]],"id":39979879},{"atl":[[9,4.26]],"id":27151693}],"con":true,"img":false}]}
{"op":"mcm","clk":"5346755523","pt":1646096121929,"mc":[{"id":"1.195395452","rc":[{"atb":[[2.5,42.88]],"id":36899924}],"con":true,"img":false}]}
{"op":"mcm","clk":"5346755526","pt":1646096122033,"mc":[{"id":"1.195395452","rc":[{"atb":[[2.58,0]],"id":36899924}],"con":true,"img":false}]}
{"op":"mcm","clk":"5346755538","pt":1646096122341,"mc":[{"id":"1.195395452","rc":[{"atb":[[2.48,0]],"id":36899924},{"atb":[[2.2,54.58]],"id":39979879},{"atb":[[2.46,0]],"id":43154431}],"con":true,"img":false}]}
{"op":"mcm","clk":"5346755542","pt":1646096122445,"mc":[{"id":"1.195395452","rc":[{"atb":[[2.5,0],[2.42,70.42]],"id":36899924}],"con":true,"img":false}]}
{"op":"mcm","clk":"5346755594","pt":1646096124037,"mc":[{"id":"1.195395452","rc":[{"atb":[[2.22,54.58],[2.2,0]],"id":39979879}],"con":true,"img":false}]}
{"op":"mcm","clk":"5346755653","pt":1646096125836,"mc":[{"id":"1.195395452","rc":[{"atb":[[2.26,0]],"id":39979879}],"con":true,"img":false}]}
{"op":"mcm","clk":"5346755659","pt":1646096125937,"mc":[{"id":"1.195395452","rc":[{"atb":[[2.12,89.29]],"id":39979879}],"con":true,"img":false}]}
{"op":"mcm","clk":"5346755662","pt":1646096126040,"mc":[{"id":"1.195395452","rc":[{"atb":[[2.22,0]],"id":39979879}],"con":true,"img":false}]}
{"op":"mcm","clk":"5346755752","pt":1646096128250,"mc":[{"id":"1.195395452","rc":[{"atb":[[2.66,9.51]],"id":43154431}],"con":true,"img":false}]}
{"op":"mcm","clk":"5346755774","pt":1646096128763,"mc":[{"id":"1.195395452","rc":[{"atb":[[2.48,5.03]],"id":36899924}],"con":true,"img":false}]}
{"op":"mcm","clk":"5346755835","pt":1646096130457,"mc":[{"id":"1.195395452","rc":[{"atl":[[4.9,0]],"id":41921674},{"atl":[[4.3,0]],"id":40251221},{"atl":[[7,0]],"id":39722911}],"con":true,"img":false}]}
{"op":"mcm","clk":"5346755841","pt":1646096130560,"mc":[{"id":"1.195395452","rc":[{"atl":[[4.7,9.22]],"id":41921674},{"atl":[[5.2,10.14]],"id":40251221},{"atl":[[6.8,7.51]],"id":39722911}],"con":true,"img":false}]}
{"op":"mcm","clk":"5346755994","pt":1646096134670,"mc":[{"id":"1.195395452","rc":[{"atb":[[2.16,6.42]],"id":39979879}],"con":true,"img":false}]}
{"op":"mcm","clk":"5346756000","pt":1646096134876,"mc":[{"id":"1.195395452","rc":[{"atb":[[2.12,0],[2.18,54.58]],"id":39979879}],"con":true,"img":false}]}
{"op":"mcm","clk":"5346756019","pt":1646096135749,"mc":[{"id":"1.195395452","rc":[{"atb":[[2.5,42.88],[2.42,0]],"id":36899924}],"con":true,"img":false}]}
{"op":"mcm","clk":"5346756092","pt":1646096137760,"mc":[{"id":"1.195395452","rc":[{"atb":[[2.48,0]],"id":36899924},{"atb":[[2.16,0]],"id":39979879}],"con":true,"img":false}]}
{"op":"mcm","clk":"5346756097","pt":1646096137863,"mc":[{"id":"1.195395452","rc":[{"atb":[[2.42,70.42]],"id":36899924},{"atb":[[2.12,89.29]],"id":39979879}],"con":true,"img":false}]}
{"op":"mcm","clk":"5346756102","pt":1646096137965,"mc":[{"id":"1.195395452","rc":[{"atb":[[2.5,0]],"id":36899924},{"atb":[[2.18,0]],"id":39979879}],"con":true,"img":false}]}
{"op":"mcm","clk":"5346756187","pt":1646096140278,"mc":[{"id":"1.195395452","rc":[{"atb":[[1.74,0],[1.75,26.67]],"id":41921674},{"atl":[[5.7,8.63]],"id":36899924}],"con":true,"img":false}]}
{"op":"mcm","clk":"5346756191","pt":1646096140380,"mc":[{"id":"1.195395452","rc":[{"atb":[[2.48,5.64]],"id":36899924},{"atl":[[7.2,0]],"id":36899924},{"atb":[[2.16,7.2]],"id":39979879},{"atl":[[1.9,0]],"id":42492389},{"atb":[[2.42,0]],"id":43154431},{"atl":[[15,0]],"id":27151693}],"con":true,"img":false}]}
{"op":"mcm","clk":"5346756194","pt":1646096140434,"mc":[{"id":"1.195395452","rc":[{"atl":[[1.69,40.56]],"id":42492389},{"atb":[[2.58,27.04]],"id":43154431},{"atl":[[13.5,2.89]],"id":27151693}],"con":true,"img":false}]}
{"op":"mcm","clk":"5346756405","pt":1646096146798,"mc":[{"id":"1.195395452","rc":[{"atb":[[2.48,10.68]],"id":36899924},{"atb":[[2.16,13.62]],"id":39979879}],"con":true,"img":false}]}
{"op":"mcm","clk":"5346756530","pt":1646096150295,"mc":[{"id":"1.195395452","rc":[{"atb":[[1.73,56.3],[1.74,27.03],[1.5,0],[1.75,0]],"id":41921674},{"atb":[[1.99,126.26]],"id":39722911},{"atb":[[1.99,126.26],[2.42,28.5]],"id":27151693}],"con":true,"img":false}]}
{"op":"mcm","clk":"5346756535","pt":1646096150398,"mc":[{"id":"1.195395452","rc":[{"atb":[[2.08,44.35]],"id":39722911}],"con":true,"img":false}]}
{"op":"mcm","clk":"5346756540","pt":1646096150500,"mc":[{"id":"1.195395452","rc":[{"atl":[[2.44,0]],"id":42492389}],"con":true,"img":false}]}
{"op":"mcm","clk":"5346756545","pt":1646096150602,"mc":[{"id":"1.195395452","rc":[{"atl":[[2.18,26.04]],"id":42492389}],"con":true,"img":false}]}
{"op":"mcm","clk":"5346756581","pt":1646096151884,"mc":[{"id":"1.195395452","rc":[{"atb":[[1.74,0],[1.75,26.67]],"id":41921674}],"con":true,"img":false}]}
{"op":"mcm","clk":"5346756603","pt":1646096152710,"mc":[{"id":"1.195395452","rc":[{"atb":[[1.74,27.03],[1.75,0]],"id":41921674}],"con":true,"img":false}]}
{"op":"mcm","clk":"5346756738","pt":1646096156616,"mc":[{"id":"1.195395452","rc":[{"atb":[[2.5,42.88],[2.42,0]],"id":36899924},{"atb":[[2.12,0],[2.18,54.58]],"id":39979879}],"con":true,"img":false}]}
{"op":"mcm","clk":"5346756830","pt":1646096158900,"mc":[{"id":"1.195395452","rc":[{"atb":[[2.48,5.64]],"id":36899924},{"atb":[[2.16,7.2]],"id":39979879}],"con":true,"img":false}]}
{"op":"mcm","clk":"5346756876","pt":1646096160393,"mc":[{"id":"1.195395452","rc":[{"atl":[[5.2,0]],"id":40251221}],"con":true,"img":false}]}
{"op":"mcm","clk":"5346756879","pt":1646096160496,"mc":[{"id":"1.195395452","rc":[{"atl":[[4.3,10.14]],"id":40251221}],"con":true,"img":false}]}
{"op":"mcm","clk":"5346756980","pt":1646096163681,"mc":[{"id":"1.195395452","rc":[{"atb":[[1.74,0],[1.75,26.67]],"id":41921674}],"con":true,"img":false}]}
{"op":"mcm","clk":"5346757017","pt":1646096164909,"mc":[{"id":"1.195395452","rc":[{"atb":[[1.74,27.03]],"id":41921674},{"atb":[[2.56,4.77]],"id":36899924},{"atb":[[2.24,6]],"id":39979879}],"con":true,"img":false}]}
{"op":"mcm","clk":"5346757020","pt":1646096165012,"mc":[{"id":"1.195395452","rc":[{"atb":[[1.75,0]],"id":41921674}],"con":true,"img":false}]}
{"op":"mcm","clk":"5346757038","pt":1646096165525,"mc":[{"id":"1.195395452","rc":[{"atl":[[3,0],[3.05,9.76]],"id":41921674},{"atl":[[3.35,8.51],[3.4,0]],"id":40251221}],"con":true,"img":false}]}
{"op":"mcm","clk":"5346757044","pt":1646096165627,"mc":[{"id":"1.195395452","rc":[{"atl":[[3.1,71.43]],"id":41921674}],"con":true,"img":false}]}
{"op":"mcm","clk":"5346757048","pt":1646096165729,"mc":[{"id":"1.195395452","rc":[{"atl":[[3.2,34.09]],"id":41921674}],"con":true,"img":false}]}
{"op":"mcm","clk":"5346757200","pt":1646096170609,"mc":[{"id":"1.195395452","rc":[{"atb":[[2.48,0]],"id":36899924},{"atb":[[2.16,0]],"id":39979879}],"con":true,"img":false}]}
{"op":"mcm","clk":"5346757203","pt":1646096170713,"mc":[{"id":"1.195395452","rc":[{"atl":[[3.2,79.54],[3.1,23.81]],"id":41921674}],"con":true,"img":false}]}
{"op":"mcm","clk":"5346757343","pt":1646096175109,"mc":[{"id":"1.195395452","rc":[{"atb":[[2.58,42.88]],"id":36899924},{"atb":[[2.22,54.58],[2.18,0]],"id":39979879}],"con":true,"img":false}]}
{"op":"mcm","clk":"5346757347","pt":1646096175212,"mc":[{"id":"1.195395452","rc":[{"atb":[[2.5,0]],"id":36899924}],"con":true,"img":false}]}
{"op":"mcm","clk":"5346757358","pt":1646096175519,"mc":[{"id":"1.195395452","rc":[{"atl":[[3.15,23.26]],"id":41921674}],"con":true,"img":false}]}
{"op":"mcm","clk":"5346757406","pt":1646096177017,"mc":[{"id":"1.195395452","rc":[{"atb":[[2.56,0]],"id":36899924},{"atb":[[2.24,0]],"id":39979879}],"con":true,"img":false}]}
{"op":"mcm","clk":"5346757415","pt":1646096177325,"mc":[{"id":"1.195395452","rc":[{"atl":[[3.2,45.45],[3.1,0],[3.3,0]],"id":41921674}],"con":true,"img":false}]}
{"op":"mcm","clk":"5346757511","pt":1646096180207,"mc":[{"id":"1.195395452","rc":[{"atb":[[2.42,70.42],[2.58,0]],"id":36899924},{"atb":[[2.22,0],[2.12,89.29]],"id":39979879}],"con":true,"img":false}]}
{"op":"mcm","clk":"5346757520","pt":1646096180414,"mc":[{"id":"1.195395452","rc":[{"atb":[[2.58,0]],"id":43154431}],"con":true,"img":false}]}
{"op":"mcm","clk":"5346757525","pt":1646096180517,"mc":[{"id":"1.195395452","rc":[{"atb":[[2.62,27.04]],"id":43154431}],"con":true,"img":false}]}
{"op":"mcm","clk":"5346757620","pt":1646096182831,"mc":[{"id":"1.195395452","rc":[{"atb":[[2.66,5.02]],"id":43154431}],"con":true,"img":false}]}
{"op":"mcm","clk":"5346757708","pt":1646096185549,"mc":[{"id":"1.195395452","rc":[{"atl":[[3.25,33.33]],"id":41921674}],"con":true,"img":false}]}
{"op":"mcm","clk":"5346757768","pt":1646096187454,"mc":[{"id":"1.195395452","rc":[{"atb":[[1.74,0],[1.75,26.67]],"id":41921674}],"con":true,"img":false}]}
{"op":"mcm","clk":"5346757823","pt":1646096188838,"mc":[{"id":"1.195395452","rc":[{"atb":[[2.48,5.03]],"id":36899924},{"atb":[[2.16,6.42]],"id":39979879},{"atb":[[2.68,4.43]],"id":43154431}],"con":true,"img":false}]}
{"op":"mcm","clk":"5346757847","pt":1646096189658,"mc":[{"id":"1.195395452","rc":[{"atb":[[1.74,27.03],[1.75,0]],"id":41921674}],"con":true,"img":false}]}
{"op":"mcm","clk":"5346757873","pt":1646096190326,"mc":[{"id":"1.195395452","rc":[{"atb":[[2.62,0]],"id":43154431}],"con":true,"img":false}]}
{"op":"mcm","clk":"5346757875","pt":1646096190432,"mc":[{"id":"1.195395452","rc":[{"atb":[[2.58,27.04]],"id":43154431}],"con":true,"img":false}]}
{"op":"mcm","clk":"5346757925","pt":1646096191865,"mc":[{"id":"1.195395452","rc":[{"atb":[[2.68,0]],"id":43154431}],"con":true,"img":false}]}
{"op":"mcm","clk":"5346757983","pt":1646096193454,"mc":[{"id":"1.195395452","rc":[{"atb":[[2.5,42.88]],"id":36899924}],"con":true,"img":false}]}
{"op":"mcm","clk":"5346757986","pt":1646096193556,"mc":[{"id":"1.195395452","rc":[{"atb":[[2.42,0]],"id":36899924}],"con":true,"img":false}]}
{"op":"mcm","clk":"5346758024","pt":1646096194636,"mc":[{"id":"1.195395452","rc":[{"atb":[[2.16,13.62]],"id":39979879}],"con":true,"img":false}]}
{"op":"mcm","clk":"5346758030","pt":1646096194838,"mc":[{"id":"1.195395452","rc":[{"atb":[[2.48,0]],"id":36899924}],"con":true,"img":false}]}
{"op":"mcm","clk":"5346758032","pt":1646096194941,"mc":[{"id":"1.195395452","rc":[{"atb":[[2.5,0],[2.42,70.42]],"id":36899924}],"con":true,"img":false}]}
{"op":"mcm","clk":"5346758134","pt":1646096197972,"mc":[{"id":"1.195395452","rc":[{"atb":[[2.66,9.51]],"id":43154431}],"con":true,"img":false}]}
{"op":"mcm","clk":"5346758153","pt":1646096198538,"mc":[{"id":"1.195395452","rc":[{"atb":[[2.18,54.58]],"id":39979879}],"con":true,"img":false}]}
{"op":"mcm","clk":"5346758158","pt":1646096198697,"mc":[{"id":"1.195395452","rc":[{"atb":[[2.12,0]],"id":39979879}],"con":true,"img":false}]}
{"op":"mcm","clk":"5346758194","pt":1646096199684,"mc":[{"id":"1.195395452","rc":[{"atb":[[1.74,0],[1.75,26.67]],"id":41921674},{"atl":[[3.35,53.19]],"id":41921674}],"con":true,"img":false}]}
{"op":"mcm","clk":"5346758237","pt":1646096200865,"mc":[{"id":"1.195395452","rc":[{"atb":[[1.74,27.03]],"id":41921674}],"con":true,"img":false}]}
{"op":"mcm","clk":"5346758243","pt":1646096200967,"mc":[{"id":"1.195395452","rc":[{"atb":[[1.75,0]],"id":41921674},{"atb":[[2.16,7.2]],"id":39979879}],"con":true,"img":false}]}
{"op":"mcm","clk":"5346758350","pt":1646096203903,"mc":[{"id":"1.195395452","rc":[{"atb":[[2.48,5.03]],"id":36899924}],"con":true,"img":false}]}
{"op":"mcm","clk":"5346758357","pt":1646096204060,"mc":[{"id":"1.195395452","rc":[{"atb":[[2.5,42.88],[2.42,0]],"id":36899924}],"con":true,"img":false}]}
{"op":"mcm","clk":"5346758473","pt":1646096206894,"mc":[{"id":"1.195395452","rc":[{"atb":[[2.48,0]],"id":36899924},{"atb":[[2.24,6]],"id":39979879}],"con":true,"img":false}]}
{"op":"mcm","clk":"5346758573","pt":1646096209206,"mc":[{"id":"1.195395452","rc":[{"atb":[[2.5,0],[2.42,70.42]],"id":36899924}],"con":true,"img":false}]}
{"op":"mcm","clk":"5346758623","pt":1646096210284,"mc":[{"id":"1.195395452","rc":[{"atl":[[6.6,2.14]],"id":39979879}],"con":true,"img":false}]}
{"op":"mcm","clk":"5346758627","pt":1646096210385,"mc":[{"id":"1.195395452","rc":[{"atl":[[5.9,7.51]],"id":39979879}],"con":true,"img":false}]}
{"op":"mcm","clk":"5346758682","pt":1646096211876,"mc":[{"id":"1.195395452","rc":[{"atb":[[1.74,0],[1.75,26.67]],"id":41921674}],"con":true,"img":false}]}
{"op":"mcm","clk":"5346758741","pt":1646096213272,"mc":[{"id":"1.195395452","rc":[{"atb":[[2.16,0]],"id":39979879}],"con":true,"img":false}]}
{"op":"mcm","clk":"5346758805","pt":1646096214608,"mc":[{"id":"1.195395452","rc":[{"atb":[[1.74,27.03],[1.75,0]],"id":41921674}],"con":true,"img":false}]}
{"op":"mcm","clk":"5346758867","pt":1646096215891,"mc":[{"id":"1.195395452","rc":[{"atb":[[2.48,5.03]],"id":36899924}],"con":true,"img":false}]}
{"op":"mcm","clk":"5346758907","pt":1646096216709,"mc":[{"id":"1.195395452","rc":[{"atb":[[2.22,54.58]],"id":39979879}],"con":true,"img":false}]}
{"op":"mcm","clk":"5346758912","pt":1646096216811,"mc":[{"id":"1.195395452","rc":[{"atb":[[2.18,0]],"id":39979879}],"con":true,"img":false}]}
{"op":"mcm","clk":"5346759008","pt":1646096219022,"mc":[{"id":"1.195395452","rc":[{"atb":[[2.24,0]],"id":39979879}],"con":true,"img":false}]}
{"op":"mcm","clk":"5346759075","pt":1646096220413,"mc":[{"id":"1.195395452","rc":[{"atb":[[2.42,0]],"id":27151693}],"con":true,"img":false}]}
{"op":"mcm","clk":"5346759080","pt":1646096220514,"mc":[{"id":"1.195395452","rc":[{"atb":[[2.52,28.5]],"id":27151693}],"con":true,"img":false}]}
{"op":"mcm","clk":"5346759146","pt":1646096221809,"mc":[{"id":"1.195395452","rc":[{"atb":[[2.12,89.29]],"id":39979879}],"con":true,"img":false}]}
{"op":"mcm","clk":"5346759154","pt":1646096221914,"mc":[{"id":"1.195395452","rc":[{"atb":[[2.22,0]],"id":39979879}],"con":true,"img":false}]}
{"op":"mcm","clk":"5346759170","pt":1646096222219,"mc":[{"id":"1.195395452","rc":[{"atb":[[2.5,42.88],[2.42,0]],"id":36899924}],"con":true,"img":false}]}
{"op":"mcm","clk":"5346759224","pt":1646096223411,"mc":[{"id":"1.195395452","rc":[{"atb":[[1.75,26.67]],"id":41921674}],"con":true,"img":false}]}
{"op":"mcm","clk":"5346759230","pt":1646096223513,"mc":[{"id":"1.195395452","rc":[{"atb":[[1.74,0]],"id":41921674}],"con":true,"img":false}]}
{"op":"mcm","clk":"5346759301","pt":1646096225009,"mc":[{"id":"1.195395452","rc":[{"atb":[[2.48,0]],"id":36899924}],"con":true,"img":false}]}
{"op":"mcm","clk":"5346759388","pt":1646096226724,"mc":[{"id":"1.195395452","rc":[{"atb":[[1.74,27.03],[1.75,0]],"id":41921674}],"con":true,"img":false}]}
{"op":"mcm","clk":"5346759425","pt":1646096227339,"mc":[{"id":"1.195395452","rc":[{"atb":[[2.5,0],[2.42,70.42]],"id":36899924}],"con":true,"img":false}]}
{"op":"mcm","clk":"5346759616","pt":1646096231037,"mc":[{"id":"1.195395452","rc":[{"atb":[[2.16,6.42]],"id":39979879}],"con":true,"img":false}]}
{"op":"mcm","clk":"5346759749","pt":1646096233820,"mc":[{"id":"1.195395452","rc":[{"atb":[[2.48,5.03]],"id":36899924}],"con":true,"img":false}]}
{"op":"mcm","clk":"5346759841","pt":1646096235719,"mc":[{"id":"1.195395452","rc":[{"atb":[[1.74,0],[1.75,26.67]],"id":41921674}],"con":true,"img":false}]}
{"op":"mcm","clk":"5346759882","pt":1646096236646,"mc":[{"id":"1.195395452","rc":[{"atb":[[2.16,13.62]],"id":39979879}],"con":true,"img":false}]}
{"op":"mcm","clk":"5346759939","pt":1646096238033,"mc":[{"id":"1.195395452","rc":[{"atb":[[1.74,27.03],[1.75,0]],"id":41921674}],"con":true,"img":false}]}
{"op":"mcm","clk":"5346760007","pt":1646096239733,"mc":[{"id":"1.195395452","rc":[{"atb":[[2.12,0],[2.18,54.58]],"id":39979879}],"con":true,"img":false}]}
{"op":"mcm","clk":"5346760023","pt":1646096240137,"mc":[{"id":"1.195395452","rc":[{"atb":[[2.5,42.88],[2.42,0]],"id":36899924}],"con":true,"img":false}]}
{"op":"mcm","clk":"5346760158","pt":1646096243229,"mc":[{"id":"1.195395452","rc":[{"atb":[[2.48,0]],"id":36899924},{"atb":[[2.16,7.2]],"id":39979879}],"con":true,"img":false}]}
{"op":"mcm","clk":"5346760251","pt":1646096245233,"mc":[{"id":"1.195395452","rc":[{"atb":[[2.5,0],[2.42,70.42]],"id":36899924}],"con":true,"img":false}]}
{"op":"mcm","clk":"5346760377","pt":1646096247750,"mc":[{"id":"1.195395452","rc":[{"atb":[[1.75,26.67]],"id":41921674}],"con":true,"img":false}]}
{"op":"mcm","clk":"5346760384","pt":1646096247849,"mc":[{"id":"1.195395452","rc":[{"atb":[[1.74,0]],"id":41921674}],"con":true,"img":false}]}
{"op":"mcm","clk":"5346760439","pt":1646096248934,"mc":[{"id":"1.195395452","rc":[{"atb":[[2.24,6]],"id":39979879}],"con":true,"img":false}]}
{"op":"mcm","clk":"5346760481","pt":1646096249957,"mc":[{"id":"1.195395452","rc":[{"atb":[[1.74,27.03],[1.75,0]],"id":41921674}],"con":true,"img":false}]}
{"op":"mcm","clk":"5346760563","pt":1646096251964,"mc":[{"id":"1.195395452","rc":[{"atb":[[2.48,5.03]],"id":36899924}],"con":true,"img":false}]}
{"op":"mcm","clk":"5346760684","pt":1646096254879,"mc":[{"id":"1.195395452","rc":[{"atb":[[2.16,0]],"id":39979879}],"con":true,"img":false}]}
{"op":"mcm","clk":"5346760797","pt":1646096257460,"mc":[{"id":"1.195395452","rc":[{"atb":[[2.22,54.58],[2.18,0]],"id":39979879}],"con":true,"img":false}]}
{"op":"mcm","clk":"5346760821","pt":1646096258072,"mc":[{"id":"1.195395452","rc":[{"atb":[[2.24,0]],"id":39979879}],"con":true,"img":false}]}
{"op":"mcm","clk":"5346760823","pt":1646096258177,"mc":[{"id":"1.195395452","rc":[{"atb":[[2.22,0],[2.12,89.29]],"id":39979879}],"con":true,"img":false}]}
{"op":"mcm","clk":"5346760875","pt":1646096259666,"mc":[{"id":"1.195395452","rc":[{"atb":[[1.74,0],[1.75,26.67]],"id":41921674}],"con":true,"img":false}]}
{"op":"mcm","clk":"5346760920","pt":1646096260489,"mc":[{"id":"1.195395452","rc":[{"atb":[[2.48,10.68]],"id":36899924}],"con":true,"img":false}]}
{"op":"mcm","clk":"5346761002","pt":1646096262284,"mc":[{"id":"1.195395452","rc":[{"atb":[[1.74,27.03],[1.75,0]],"id":41921674}],"con":true,"img":false}]}
{"op":"mcm","clk":"5346761028","pt":1646096262953,"mc":[{"id":"1.195395452","rc":[{"atb":[[2.5,42.88],[2.42,0]],"id":36899924}],"con":true,"img":false}]}
{"op":"mcm","clk":"5346761057","pt":1646096263978,"mc":[{"id":"1.195395452","rc":[{"atb":[[2.48,5.64]],"id":36899924}],"con":true,"img":false}]}
{"op":"mcm","clk":"5346761180","pt":1646096266965,"mc":[{"id":"1.195395452","rc":[{"atb":[[2.16,6.42]],"id":39979879}],"con":true,"img":false}]}
{"op":"mcm","clk":"5346761298","pt":1646096269992,"mc":[{"id":"1.195395452","rc":[{"atb":[[2.56,4.77]],"id":36899924}],"con":true,"img":false}]}
{"op":"mcm","clk":"5346761384","pt":1646096272099,"mc":[{"id":"1.195395452","rc":[{"atb":[[1.74,0],[1.75,26.67]],"id":41921674}],"con":true,"img":false}]}
{"op":"mcm","clk":"5346761416","pt":1646096272928,"mc":[{"id":"1.195395452","rc":[{"atb":[[2.16,13.62]],"id":39979879}],"con":true,"img":false}]}
{"op":"mcm","clk":"5346761478","pt":1646096274315,"mc":[{"id":"1.195395452","rc":[{"atb":[[1.74,27.03],[1.75,0]],"id":41921674}],"con":true,"img":false}]}
{"op":"mcm","clk":"5346761520","pt":1646096275702,"mc":[{"id":"1.195395452","rc":[{"atb":[[2.18,54.58]],"id":39979879}],"con":true,"img":false}]}
{"op":"mcm","clk":"5346761523","pt":1646096275805,"mc":[{"id":"1.195395452","rc":[{"atb":[[2.12,0]],"id":39979879}],"con":true,"img":false}]}
{"op":"mcm","clk":"5346761617","pt":1646096278685,"mc":[{"id":"1.195395452","rc":[{"atb":[[2.48,0]],"id":36899924}],"con":true,"img":false}]}
{"op":"mcm","clk":"5346761629","pt":1646096278991,"mc":[{"id":"1.195395452","rc":[{"atb":[[2.16,7.2]],"id":39979879}],"con":true,"img":false}]}
{"op":"mcm","clk":"5346761697","pt":1646096280539,"mc":[{"id":"1.195395452","rc":[{"atb":[[2.5,0],[2.58,42.88]],"id":36899924}],"con":true,"img":false}]}
{"op":"mcm","clk":"5346761763","pt":1646096282239,"mc":[{"id":"1.195395452","rc":[{"atb":[[2.56,0]],"id":36899924}],"con":true,"img":false}]}
{"op":"mcm","clk":"5346761771","pt":1646096282394,"mc":[{"id":"1.195395452","rc":[{"atb":[[2.42,70.42],[2.58,0]],"id":36899924}],"con":true,"img":false}]}
{"op":"mcm","clk":"5346761808","pt":1646096283419,"mc":[{"id":"1.195395452","rc":[{"atb":[[1.74,0],[1.75,26.67]],"id":41921674}],"con":true,"img":false}]}
{"op":"mcm","clk":"5346761862","pt":1646096285015,"mc":[{"id":"1.195395452","rc":[{"atb":[[2.24,6]],"id":39979879}],"con":true,"img":false}]}
{"op":"mcm","clk":"5346761929","pt":1646096286613,"mc":[{"id":"1.195395452","rc":[{"atb":[[1.74,27.03],[1.75,0]],"id":41921674}],"con":true,"img":false}]}
{"op":"mcm","clk":"5346762089","pt":1646096290411,"mc":[{"id":"1.195395452","rc":[{"atb":[[2.58,0]],"id":43154431}],"con":true,"img":false}]}
{"op":"mcm","clk":"5346762095","pt":1646096290514,"mc":[{"id":"1.195395452","rc":[{"atb":[[2.62,27.04]],"id":43154431}],"con":true,"img":false}]}
{"op":"mcm","clk":"5346762115","pt":1646096291029,"mc":[{"id":"1.195395452","rc":[{"atb":[[2.48,5.03]],"id":36899924}],"con":true,"img":false}]}
{"op":"mcm","clk":"5346762118","pt":1646096291133,"mc":[{"id":"1.195395452","rc":[{"atb":[[2.66,5.02]],"id":43154431}],"con":true,"img":false}]}
{"op":"mcm","clk":"5346762127","pt":1646096291444,"mc":[{"id":"1.195395452","rc":[{"atb":[[2.16,0]],"id":39979879}],"con":true,"img":false}]}
{"op":"mcm","clk":"5346762178","pt":1646096293041,"mc":[{"id":"1.195395452","rc":[{"atb":[[2.22,54.58],[2.18,0]],"id":39979879}],"con":true,"img":false}]}
{"op":"mcm","clk":"5346762208","pt":1646096294022,"mc":[{"id":"1.195395452","rc":[{"atb":[[2.24,0]],"id":39979879}],"con":true,"img":false}]}
{"op":"mcm","clk":"5346762212","pt":1646096294122,"mc":[{"id":"1.195395452","rc":[{"atb":[[2.12,89.29]],"id":39979879}],"con":true,"img":false}]}
{"op":"mcm","clk":"5346762214","pt":1646096294248,"mc":[{"id":"1.195395452","rc":[{"atb":[[2.22,0]],"id":39979879}],"con":true,"img":false}]}
{"op":"mcm","clk":"5346762266","pt":1646096295744,"mc":[{"id":"1.195395452","rc":[{"atb":[[1.74,0],[1.75,26.67]],"id":41921674}],"con":true,"img":false}]}
{"op":"mcm","clk":"5346762297","pt":1646096296620,"mc":[{"id":"1.195395452","rc":[{"atb":[[2.48,10.68]],"id":36899924}],"con":true,"img":false}]}
{"op":"mcm","clk":"5346762315","pt":1646096297031,"mc":[{"id":"1.195395452","rc":[{"atb":[[2.68,4.43]],"id":43154431}],"con":true,"img":false}]}
{"op":"mcm","clk":"5346762377","pt":1646096298628,"mc":[{"id":"1.195395452","rc":[{"atb":[[1.74,27.03],[1.75,0]],"id":41921674}],"con":true,"img":false}]}
{"op":"mcm","clk":"5346762415","pt":1646096299757,"mc":[{"id":"1.195395452","rc":[{"atb":[[2.5,42.88]],"id":36899924}],"con":true,"img":false}]}
{"op":"mcm","clk":"5346762418","pt":1646096299812,"mc":[{"id":"1.195395452","rc":[{"atb":[[2.42,0]],"id":36899924}],"con":true,"img":false}]}
{"op":"mcm","clk":"5346762427","pt":1646096300123,"mc":[{"id":"1.195395452","rc":[{"atb":[[2.48,5.64]],"id":36899924}],"con":true,"img":false}]}
{"op":"mcm","clk":"5346762533","pt":1646096302949,"mc":[{"id":"1.195395452","rc":[{"atb":[[2.16,6.42]],"id":39979879}],"con":true,"img":false}]}
{"op":"mcm","clk":"5346762537","pt":1646096303051,"mc":[{"id":"1.195395452","rc":[{"atb":[[2.12,0],[2.18,54.58]],"id":39979879}],"con":true,"img":false}]}
{"op":"mcm","clk":"5346762661","pt":1646096306038,"mc":[{"id":"1.195395452","rc":[{"atb":[[2.56,4.77]],"id":36899924},{"atb":[[2.16,0]],"id":39979879}],"con":true,"img":false}]}
{"op":"mcm","clk":"5346762665","pt":1646096306140,"mc":[{"id":"1.195395452","rc":[{"atb":[[2.5,0],[2.58,5.65]],"id":36899924},{"atb":[[2.12,89.29],[2.18,0]],"id":39979879}],"con":true,"img":false}]}
{"op":"mcm","clk":"5346762744","pt":1646096308577,"mc":[{"id":"1.195395452","rc":[{"atb":[[2.16,7.2]],"id":39979879}],"con":true,"img":false}]}
{"op":"mcm","clk":"5346762749","pt":1646096308678,"mc":[{"id":"1.195395452","rc":[{"atb":[[2.12,0],[2.18,54.58]],"id":39979879}],"con":true,"img":false}]}
{"op":"mcm","clk":"5346762765","pt":1646096309142,"mc":[{"id":"1.195395452","rc":[{"atb":[[2.56,0]],"id":36899924}],"con":true,"img":false}]}
{"op":"mcm","clk":"5346762770","pt":1646096309243,"mc":[{"id":"1.195395452","rc":[{"atb":[[2.5,42.88]],"id":36899924}],"con":true,"img":false}]}
{"op":"mcm","clk":"5346762775","pt":1646096309347,"mc":[{"id":"1.195395452","rc":[{"atb":[[2.58,0]],"id":36899924}],"con":true,"img":false}]}
{"op":"mcm","clk":"5346762844","pt":1646096311965,"mc":[{"id":"1.195395452","rc":[{"atb":[[2.24,6]],"id":39979879}],"con":true,"img":false}]}
{"op":"mcm","clk":"5346762914","pt":1646096314685,"mc":[{"id":"1.195395452","rc":[{"atb":[[2.48,0]],"id":36899924}],"con":true,"img":false}]}
{"op":"mcm","clk":"5346762921","pt":1646096314838,"mc":[{"id":"1.195395452","rc":[{"atb":[[2.5,0],[2.42,70.42]],"id":36899924}],"con":true,"img":false}]}
{"op":"mcm","clk":"5346763069","pt":1646096320380,"mc":[{"id":"1.195395452","rc":[{"atb":[[1.74,0],[1.75,26.67]],"id":41921674}],"con":true,"img":false}]}
{"op":"mcm","clk":"5346763150","pt":1646096323298,"mc":[{"id":"1.195395452","rc":[{"atb":[[1.74,27.03],[1.75,0]],"id":41921674}],"con":true,"img":false}]}
{"op":"mcm","clk":"5346763165","pt":1646096324071,"mc":[{"id":"1.195395452","rc":[{"atb":[[2.48,5.03]],"id":36899924}],"con":true,"img":false}]}
{"op":"mcm","clk":"5346763205","pt":1646096325710,"mc":[{"id":"1.195395452","rc":[{"atb":[[2.22,54.58],[2.18,0]],"id":39979879}],"con":true,"img":false}]}
{"op":"mcm","clk":"5346763236","pt":1646096326685,"mc":[{"id":"1.195395452","rc":[{"atb":[[2.16,0]],"id":39979879}],"con":true,"img":false}]}
{"op":"mcm","clk":"5346763245","pt":1646096327098,"mc":[{"id":"1.195395452","rc":[{"atb":[[2.24,0]],"id":39979879}],"con":true,"img":false}]}
{"op":"mcm","clk":"5346763249","pt":1646096327201,"mc":[{"id":"1.195395452","rc":[{"atb":[[2.12,89.29]],"id":39979879}],"con":true,"img":false}]}
{"op":"mcm","clk":"5346763253","pt":1646096327302,"mc":[{"id":"1.195395452","rc":[{"atb":[[2.22,0]],"id":39979879}],"con":true,"img":false}]}
{"op":"mcm","clk":"5346763326","pt":1646096330280,"mc":[{"id":"1.195395452","rc":[{"atb":[[2.62,0]],"id":43154431}],"con":true,"img":false}]}
{"op":"mcm","clk":"5346763331","pt":1646096330384,"mc":[{"id":"1.195395452","rc":[{"atb":[[2.58,27.04]],"id":43154431}],"con":true,"img":false}]}
{"op":"mcm","clk":"5346763367","pt":1646096331822,"mc":[{"id":"1.195395452","rc":[{"atb":[[2.5,42.88],[2.42,0]],"id":36899924}],"con":true,"img":false}]}
{"op":"mcm","clk":"5346763375","pt":1646096332082,"mc":[{"id":"1.195395452","rc":[{"atb":[[1.74,0],[1.75,26.67]],"id":41921674}],"con":true,"img":false}]}
{"op":"mcm","clk":"5346763394","pt":1646096333002,"mc":[{"id":"1.195395452","rc":[{"atb":[[2.48,0]],"id":36899924},{"atb":[[2.68,0]],"id":43154431}],"con":true,"img":false}]}
{"op":"mcm","clk":"5346763463","pt":1646096335002,"mc":[{"id":"1.195395452","rc":[{"atb":[[1.74,27.03]],"id":41921674}],"con":true,"img":false}]}
{"op":"mcm","clk":"5346763466","pt":1646096335104,"mc":[{"id":"1.195395452","rc":[{"atb":[[1.75,0]],"id":41921674}],"con":true,"img":false}]}
{"op":"mcm","clk":"5346763494","pt":1646096336083,"mc":[{"id":"1.195395452","rc":[{"atb":[[2.16,6.42]],"id":39979879}],"con":true,"img":false}]}
{"op":"mcm","clk":"5346763496","pt":1646096336187,"mc":[{"id":"1.195395452","rc":[{"atb":[[2.18,54.58]],"id":39979879}],"con":true,"img":false}]}
{"op":"mcm","clk":"5346763498","pt":1646096336287,"mc":[{"id":"1.195395452","rc":[{"atb":[[2.12,0]],"id":39979879}],"con":true,"img":false}]}
{"op":"mcm","clk":"5346763509","pt":1646096336902,"mc":[{"id":"1.195395452","rc":[{"atb":[[2.5,0],[2.42,70.42]],"id":36899924}],"con":true,"img":false}]}
{"op":"mcm","clk":"5346763558","pt":1646096339103,"mc":[{"id":"1.195395452","rc":[{"atb":[[2.16,0]],"id":39979879},{"atb":[[2.66,9.51]],"id":43154431}],"con":true,"img":false}]}
{"op":"mcm","clk":"5346763563","pt":1646096339207,"mc":[{"id":"1.195395452","rc":[{"atb":[[2.12,89.29],[2.18,0]],"id":39979879}],"con":true,"img":false}]}
{"op":"mcm","clk":"5346763660","pt":1646096343513,"mc":[{"id":"1.195395452","rc":[{"atb":[[1.75,26.67]],"id":41921674}],"con":true,"img":false}]}
{"op":"mcm","clk":"5346763663","pt":1646096343616,"mc":[{"id":"1.195395452","rc":[{"atb":[[1.74,0]],"id":41921674}],"con":true,"img":false}]}
{"op":"mcm","clk":"5346763702","pt":1646096345102,"mc":[{"id":"1.195395452","rc":[{"atb":[[2.48,5.03]],"id":36899924}],"con":true,"img":false}]}
{"op":"mcm","clk":"5346763739","pt":1646096346335,"mc":[{"id":"1.195395452","rc":[{"atb":[[1.75,0]],"id":41921674}],"con":true,"img":false}]}
{"op":"mcm","clk":"5346763741","pt":1646096346437,"mc":[{"id":"1.195395452","rc":[{"atb":[[1.74,27.03]],"id":41921674}],"con":true,"img":false}]}
{"op":"mcm","clk":"5346763790","pt":1646096348128,"mc":[{"id":"1.195395452","rc":[{"atb":[[2.16,6.42]],"id":39979879}],"con":true,"img":false}]}
{"op":"mcm","clk":"5346763794","pt":1646096348229,"mc":[{"id":"1.195395452","rc":[{"atb":[[2.18,54.58]],"id":39979879}],"con":true,"img":false}]}
{"op":"mcm","clk":"5346763797","pt":1646096348332,"mc":[{"id":"1.195395452","rc":[{"atb":[[2.12,0]],"id":39979879}],"con":true,"img":false}]}
{"op":"mcm","clk":"5346763870","pt":1646096351044,"mc":[{"id":"1.195395452","rc":[{"atb":[[2.48,10.68]],"id":36899924}],"con":true,"img":false}]}
{"op":"mcm","clk":"5346763876","pt":1646096351251,"mc":[{"id":"1.195395452","rc":[{"atb":[[2.16,0]],"id":39979879}],"con":true,"img":false}]}
{"op":"mcm","clk":"5346763930","pt":1646096353351,"mc":[{"id":"1.195395452","rc":[{"atb":[[2.12,89.29]],"id":39979879}],"con":true,"img":false}]}
{"op":"mcm","clk":"5346763933","pt":1646096353453,"mc":[{"id":"1.195395452","rc":[{"atb":[[2.18,0]],"id":39979879}],"con":true,"img":false}]}
{"op":"mcm","clk":"5346763940","pt":1646096353610,"mc":[{"id":"1.195395452","rc":[{"atb":[[2.5,42.88]],"id":36899924}],"con":true,"img":false}]}
{"op":"mcm","clk":"5346763943","pt":1646096353711,"mc":[{"id":"1.195395452","rc":[{"atb":[[2.42,0]],"id":36899924}],"con":true,"img":false}]}
{"op":"mcm","clk":"5346763954","pt":1646096354122,"mc":[{"id":"1.195395452","rc":[{"atb":[[2.48,5.64]],"id":36899924}],"con":true,"img":false}]}
{"op":"mcm","clk":"5346763995","pt":1646096355757,"mc":[{"id":"1.195395452","rc":[{"atb":[[1.74,0],[1.75,26.67]],"id":41921674}],"con":true,"img":false}]}
{"op":"mcm","clk":"5346764070","pt":1646096358020,"mc":[{"id":"1.195395452","rc":[{"atb":[[1.74,27.03],[1.75,0]],"id":41921674}],"con":true,"img":false}]}
{"op":"mcm","clk":"5346764151","pt":1646096360133,"mc":[{"id":"1.195395452","rc":[{"atb":[[2.56,4.77]],"id":36899924},{"atb":[[2.16,6.42]],"id":39979879}],"con":true,"img":false}]}
{"op":"mcm","clk":"5346764156","pt":1646096360236,"mc":[{"id":"1.195395452","rc":[{"atb":[[2.5,0],[2.58,5.65]],"id":36899924}],"con":true,"img":false}]}
{"op":"mcm","clk":"5346764251","pt":1646096363264,"mc":[{"id":"1.195395452","rc":[{"atb":[[2.56,0]],"id":36899924}],"con":true,"img":false}]}
{"op":"mcm","clk":"5346764257","pt":1646096363367,"mc":[{"id":"1.195395452","rc":[{"atb":[[2.58,0]],"id":36899924}],"con":true,"img":false}]}
{"op":"mcm","clk":"5346764260","pt":1646096363467,"mc":[{"id":"1.195395452","rc":[{"atb":[[2.5,42.88]],"id":36899924}],"con":true,"img":false}]}
{"op":"mcm","clk":"5346764401","pt":1646096367880,"mc":[{"id":"1.195395452","rc":[{"atb":[[1.74,0],[1.75,26.67]],"id":41921674}],"con":true,"img":false}]}
{"op":"mcm","clk":"5346764442","pt":1646096369272,"mc":[{"id":"1.195395452","rc":[{"atb":[[2.48,0]],"id":36899924}],"con":true,"img":false}]}
{"op":"mcm","clk":"5346764445","pt":1646096369370,"mc":[{"id":"1.195395452","rc":[{"atb":[[2.42,70.42]],"id":36899924}],"con":true,"img":false}]}
{"op":"mcm","clk":"5346764448","pt":1646096369473,"mc":[{"id":"1.195395452","rc":[{"atb":[[2.5,0]],"id":36899924},{"atb":[[2.16,13.62]],"id":39979879}],"con":true,"img":false}]}
{"op":"mcm","clk":"5346764456","pt":1646096369783,"mc":[{"id":"1.195395452","rc":[{"atb":[[1.74,27.03],[1.75,0]],"id":41921674}],"con":true,"img":false}]}
{"op":"mcm","clk":"5346764463","pt":1646096369988,"mc":[{"id":"1.195395452","rc":[{"atb":[[2.12,0],[2.18,54.58]],"id":39979879}],"con":true,"img":false}]}
{"op":"mcm","clk":"5346764526","pt":1646096372253,"mc":[{"id":"1.195395452","rc":[{"atb":[[2.16,7.2]],"id":39979879}],"con":true,"img":false}]}
{"op":"mcm","clk":"5346764702","pt":1646096378056,"mc":[{"id":"1.195395452","rc":[{"atb":[[2.24,6]],"id":39979879}],"con":true,"img":false}]}
{"op":"mcm","clk":"5346764708","pt":1646096378157,"mc":[{"id":"1.195395452","rc":[{"atb":[[2.48,5.03]],"id":36899924}],"con":true,"img":false}]}
{"op":"mcm","clk":"5346764757","pt":1646096379695,"mc":[{"id":"1.195395452","rc":[{"atb":[[1.75,26.67]],"id":41921674}],"con":true,"img":false}]}
{"op":"mcm","clk":"5346764759","pt":1646096379798,"mc":[{"id":"1.195395452","rc":[{"atb":[[1.74,0]],"id":41921674}],"con":true,"img":false}]}
{"op":"mcm","clk":"5346764762","pt":1646096379901,"mc":[{"id":"1.195395452","rc":[{"atb":[[2.5,42.88]],"id":36899924}],"con":true,"img":false}]}
{"op":"mcm","clk":"5346764765","pt":1646096380003,"mc":[{"id":"1.195395452","rc":[{"atb":[[2.42,0]],"id":36899924}],"con":true,"img":false}]}
{"op":"mcm","clk":"5346764793","pt":1646096381185,"mc":[{"id":"1.195395452","rc":[{"atb":[[2.48,0]],"id":36899924}],"con":true,"img":false}]}
{"op":"mcm","clk":"5346764795","pt":1646096381288,"mc":[{"id":"1.195395452","rc":[{"atb":[[2.5,0],[2.42,70.42]],"id":36899924}],"con":true,"img":false}]}
{"op":"mcm","clk":"5346764804","pt":1646096381698,"mc":[{"id":"1.195395452","rc":[{"atb":[[1.74,27.03],[1.75,0]],"id":41921674}],"con":true,"img":false}]}
{"op":"mcm","clk":"5346764936","pt":1646096386409,"mc":[{"id":"1.195395452","rc":[{"atb":[[2.22,54.58],[2.18,0]],"id":39979879}],"con":true,"img":false}]}
{"op":"mcm","clk":"5346764952","pt":1646096386876,"mc":[{"id":"1.195395452","rc":[{"atb":[[2.16,0]],"id":39979879}],"con":true,"img":false}]}
{"op":"mcm","clk":"5346764969","pt":1646096387287,"mc":[{"id":"1.195395452","rc":[{"atb":[[2.24,0]],"id":39979879}],"con":true,"img":false}]}
{"op":"mcm","clk":"5346765102","pt":1646096391494,"mc":[{"id":"1.195395452","rc":[{"atb":[[1.74,0],[1.75,26.67]],"id":41921674},{"atb":[[2.22,0],[2.12,89.29]],"id":39979879}],"con":true,"img":false}]}
{"op":"mcm","clk":"5346765142","pt":1646096393128,"mc":[{"id":"1.195395452","rc":[{"atb":[[2.48,5.03]],"id":36899924}],"con":true,"img":false}]}
{"op":"mcm","clk":"5346765147","pt":1646096393283,"mc":[{"id":"1.195395452","rc":[{"atb":[[2.5,42.88],[2.42,0]],"id":36899924}],"con":true,"img":false}]}
{"op":"mcm","clk":"5346765158","pt":1646096393696,"mc":[{"id":"1.195395452","rc":[{"atb":[[1.74,27.03],[1.75,0]],"id":41921674}],"con":true,"img":false}]}
{"op":"mcm","clk":"5346765232","pt":1646096396311,"mc":[{"id":"1.195395452","rc":[{"atb":[[2.48,0]],"id":36899924}],"con":true,"img":false}]}
{"op":"mcm","clk":"5346765299","pt":1646096398416,"mc":[{"id":"1.195395452","rc":[{"atb":[[2.5,0],[2.42,70.42]],"id":36899924}],"con":true,"img":false}]}
{"op":"mcm","clk":"5346765326","pt":1646096399232,"mc":[{"id":"1.195395452","rc":[{"atb":[[2.16,6.42]],"id":39979879}],"con":true,"img":false}]}
{"op":"mcm","clk":"5346765510","pt":1646096403829,"mc":[{"id":"1.195395452","rc":[{"atb":[[1.74,0],[1.75,26.67]],"id":41921674}],"con":true,"img":false}]}
{"op":"mcm","clk":"5346765581","pt":1646096405116,"mc":[{"id":"1.195395452","rc":[{"atb":[[2.16,13.62]],"id":39979879}],"con":true,"img":false}]}
{"op":"mcm","clk":"5346765588","pt":1646096405321,"mc":[{"id":"1.195395452","rc":[{"atb":[[2.48,5.03]],"id":36899924}],"con":true,"img":false}]}
{"op":"mcm","clk":"5346765593","pt":1646096405425,"mc":[{"id":"1.195395452","rc":[{"atb":[[1.74,27.03],[1.75,0]],"id":41921674}],"con":true,"img":false}]}
{"op":"mcm","clk":"5346765674","pt":1646096407733,"mc":[{"id":"1.195395452","rc":[{"atb":[[2.12,0],[2.18,54.58]],"id":39979879}],"con":true,"img":false}]}
{"op":"mcm","clk":"5346765699","pt":1646096408451,"mc":[{"id":"1.195395452","rc":[{"atb":[[2.16,7.2]],"id":39979879}],"con":true,"img":false}]}
{"op":"mcm","clk":"5346765731","pt":1646096409543,"mc":[{"id":"1.195395452","rc":[{"atb":[[2.5,42.88],[2.42,0]],"id":36899924}],"con":true,"img":false}]}
{"op":"mcm","clk":"5346765803","pt":1646096411236,"mc":[{"id":"1.195395452","rc":[{"atb":[[2.48,0]],"id":36899924}],"con":true,"img":false}]}
{"op":"mcm","clk":"5346765807","pt":1646096411333,"mc":[{"id":"1.195395452","rc":[{"atb":[[2.5,0],[2.42,70.42]],"id":36899924}],"con":true,"img":false}]}
{"op":"mcm","clk":"5346765893","pt":1646096414261,"mc":[{"id":"1.195395452","rc":[{"atb":[[2.24,6]],"id":39979879}],"con":true,"img":false}]}
{"op":"mcm","clk":"5346765900","pt":1646096414465,"mc":[{"id":"1.195395452","rc":[{"atb":[[2.22,54.58],[2.18,0]],"id":39979879}],"con":true,"img":false}]}
{"op":"mcm","clk":"5346765913","pt":1646096415034,"mc":[{"id":"1.195395452","rc":[{"atb":[[1.74,0],[1.75,26.67]],"id":41921674}],"con":true,"img":false}]}
{"op":"mcm","clk":"5346765976","pt":1646096417344,"mc":[{"id":"1.195395452","rc":[{"atb":[[2.24,0]],"id":39979879}],"con":true,"img":false}]}
{"op":"mcm","clk":"5346765988","pt":1646096417751,"mc":[{"id":"1.195395452","rc":[{"atb":[[1.74,27.03],[1.75,0]],"id":41921674}],"con":true,"img":false}]}
{"op":"mcm","clk":"5346766054","pt":1646096419660,"mc":[{"id":"1.195395452","rc":[{"atb":[[2.18,84.75]],"id":39979879}],"con":true,"img":false}]}
{"op":"mcm","clk":"5346766058","pt":1646096419765,"mc":[{"id":"1.195395452","rc":[{"atb":[[2.22,0]],"id":39979879}],"con":true,"img":false}]}
{"op":"mcm","clk":"5346766081","pt":1646096420433,"mc":[{"id":"1.195395452","rc":[{"atb":[[2.48,5.03]],"id":36899924}],"con":true,"img":false}]}
{"op":"mcm","clk":"5346766085","pt":1646096420538,"mc":[{"id":"1.195395452","rc":[{"atb":[[2.5,42.88],[2.42,0]],"id":36899924}],"con":true,"img":false}]}
{"op":"mcm","clk":"5346766185","pt":1646096423262,"mc":[{"id":"1.195395452","rc":[{"atb":[[2.48,0]],"id":36899924}],"con":true,"img":false}]}
{"op":"mcm","clk":"5346766270","pt":1646096425678,"mc":[{"id":"1.195395452","rc":[{"atb":[[2.5,0],[2.42,70.42]],"id":36899924}],"con":true,"img":false}]}
{"op":"mcm","clk":"5346766292","pt":1646096426145,"mc":[{"id":"1.195395452","rc":[{"atb":[[2.24,6]],"id":39979879}],"con":true,"img":false}]}
{"op":"mcm","clk":"5346766318","pt":1646096426863,"mc":[{"id":"1.195395452","rc":[{"atb":[[1.75,26.67]],"id":41921674}],"con":true,"img":false}]}
{"op":"mcm","clk":"5346766324","pt":1646096427066,"mc":[{"id":"1.195395452","rc":[{"atb":[[1.74,0]],"id":41921674},{"atb":[[2.16,0]],"id":39979879}],"con":true,"img":false}]}
{"op":"mcm","clk":"5346766394","pt":1646096429477,"mc":[{"id":"1.195395452","rc":[{"atb":[[1.74,27.03],[1.75,0]],"id":41921674}],"con":true,"img":false}]}
{"op":"mcm","clk":"5346766511","pt":1646096432255,"mc":[{"id":"1.195395452","rc":[{"atb":[[2.48,5.03]],"id":36899924}],"con":true,"img":false}]}
{"op":"mcm","clk":"5346766619","pt":1646096435490,"mc":[{"id":"1.195395452","rc":[{"atb":[[2.48,10.68]],"id":36899924}],"con":true,"img":false}]}
{"op":"mcm","clk":"5346766623","pt":1646096435596,"mc":[{"id":"1.195395452","rc":[{"atb":[[2.18,0],[2.2,54.58]],"id":39979879}],"con":true,"img":false}]}
{"op":"mcm","clk":"5346766627","pt":1646096435751,"mc":[{"id":"1.195395452","rc":[{"atb":[[2.24,12.73]],"id":39979879}],"con":true,"img":false}]}
{"op":"mcm","clk":"5346766749","pt":1646096438274,"mc":[{"id":"1.195395452","rc":[{"atb":[[2.24,6.73]],"id":39979879}],"con":true,"img":false}]}
{"op":"mcm","clk":"5346766786","pt":1646096439198,"mc":[{"id":"1.195395452","rc":[{"atb":[[1.74,0]],"id":41921674}],"con":true,"img":false}]}
{"op":"mcm","clk":"5346766789","pt":1646096439302,"mc":[{"id":"1.195395452","rc":[{"atb":[[1.76,26.32]],"id":41921674}],"con":true,"img":false}]}
{"op":"mcm","clk":"5346766865","pt":1646096441000,"mc":[{"id":"1.195395452","rc":[{"atb":[[1.74,27.03],[1.76,0]],"id":41921674}],"con":true,"img":false}]}
{"op":"mcm","clk":"5346766891","pt":1646096441571,"mc":[{"id":"1.195395452","rc":[{"atb":[[2.5,42.88]],"id":36899924}],"con":true,"img":false}]}
{"op":"mcm","clk":"5346766894","pt":1646096441673,"mc":[{"id":"1.195395452","rc":[{"atb":[[2.42,0]],"id":36899924}],"con":true,"img":false}]}
{"op":"mcm","clk":"5346766986","pt":1646096444394,"mc":[{"id":"1.195395452","rc":[{"atb":[[2.48,5.64]],"id":36899924},{"atb":[[2.26,5.91]],"id":39979879}],"con":true,"img":false}]}
{"op":"mcm","clk":"5346767156","pt":1646096449419,"mc":[{"id":"1.195395452","rc":[{"atb":[[2.56,4.77]],"id":36899924}],"con":true,"img":false}]}
{"op":"mcm","clk":"5346767163","pt":1646096449573,"mc":[{"id":"1.195395452","rc":[{"atb":[[2.5,0],[2.58,5.65]],"id":36899924}],"con":true,"img":false}]}
{"op":"mcm","clk":"5346767233","pt":1646096452087,"mc":[{"id":"1.195395452","rc":[{"atb":[[1.74,0],[1.76,26.32]],"id":41921674}],"con":true,"img":false}]}
{"op":"mcm","clk":"5346767242","pt":1646096452396,"mc":[{"id":"1.195395452","rc":[{"atb":[[2.56,0]],"id":36899924}],"con":true,"img":false}]}
{"op":"mcm","clk":"5346767245","pt":1646096452499,"mc":[{"id":"1.195395452","rc":[{"atb":[[2.5,42.88],[2.58,0]],"id":36899924}],"con":true,"img":false}]}
{"op":"mcm","clk":"5346767271","pt":1646096453319,"mc":[{"id":"1.195395452","rc":[{"atb":[[1.74,27.03],[1.76,0]],"id":41921674}],"con":true,"img":false}]}
{"op":"mcm","clk":"5346767281","pt":1646096453577,"mc":[{"id":"1.195395452","rc":[{"atb":[[2.24,0]],"id":39979879}],"con":true,"img":false}]}
{"op":"mcm","clk":"5346767522","pt":1646096459835,"mc":[{"id":"1.195395452","rc":[{"atb":[[2.26,12.54]],"id":39979879}],"con":true,"img":false}]}
{"op":"mcm","clk":"5346767532","pt":1646096460099,"mc":[{"id":"1.195395452","rc":[{"atb":[[2.48,0]],"id":36899924}],"con":true,"img":false}]}
{"op":"mcm","clk":"5346767535","pt":1646096460200,"mc":[{"id":"1.195395452","rc":[{"atb":[[2.5,0],[2.42,70.42]],"id":36899924}],"con":true,"img":false}]}
{"op":"mcm","clk":"5346767539","pt":1646096460301,"mc":[{"id":"1.195395452","rc":[{"atl":[[7.8,5.38],[9.8,0]],"id":40251221},{"atb":[[2.58,0]],"id":43154431}],"con":true,"img":false}]}
{"op":"mcm","clk":"5346767544","pt":1646096460404,"mc":[{"id":"1.195395452","rc":[{"atb":[[2.62,27.04]],"id":43154431}],"con":true,"img":false}]}
{"op":"mcm","clk":"5346767587","pt":1646096461736,"mc":[{"id":"1.195395452","rc":[{"atb":[[2.66,5.02]],"id":43154431}],"con":true,"img":false}]}
{"op":"mcm","clk":"5346767647","pt":1646096463126,"mc":[{"id":"1.195395452","rc":[{"atb":[[1.76,26.32]],"id":41921674}],"con":true,"img":false}]}
{"op":"mcm","clk":"5346767655","pt":1646096463233,"mc":[{"id":"1.195395452","rc":[{"atb":[[1.74,0]],"id":41921674}],"con":true,"img":false}]}
{"op":"mcm","clk":"5346767756","pt":1646096465699,"mc":[{"id":"1.195395452","rc":[{"atb":[[1.74,27.03],[1.76,0]],"id":41921674}],"con":true,"img":false}]}
{"op":"mcm","clk":"5346767818","pt":1646096467499,"mc":[{"id":"1.195395452","rc":[{"atb":[[2.48,5.03]],"id":36899924},{"atb":[[2.68,4.43]],"id":43154431}],"con":true,"img":false}]}
{"op":"mcm","clk":"5346768078","pt":1646096474534,"mc":[{"id":"1.195395452","rc":[{"atb":[[1.74,0],[1.76,26.32]],"id":41921674}],"con":true,"img":false}]}
{"op":"mcm","clk":"5346768118","pt":1646096475716,"mc":[{"id":"1.195395452","rc":[{"atb":[[2.5,42.88],[2.42,0]],"id":36899924}],"con":true,"img":false}]}
{"op":"mcm","clk":"5346768189","pt":1646096477441,"mc":[{"id":"1.195395452","rc":[{"atb":[[1.74,27.03],[1.76,0]],"id":41921674},{"atb":[[2.48,0]],"id":36899924}],"con":true,"img":false}]}
{"op":"mcm","clk":"5346768341","pt":1646096480925,"mc":[{"id":"1.195395452","rc":[{"atb":[[2.5,0],[2.42,70.42]],"id":36899924}],"con":true,"img":false}]}
{"op":"mcm","clk":"5346768551","pt":1646096486064,"mc":[{"id":"1.195395452","rc":[{"atb":[[1.76,26.32]],"id":41921674}],"con":true,"img":false}]}
{"op":"mcm","clk":"5346768559","pt":1646096486168,"mc":[{"id":"1.195395452","rc":[{"atb":[[1.74,0]],"id":41921674}],"con":true,"img":false}]}
{"op":"mcm","clk":"5346768685","pt":1646096488437,"mc":[{"id":"1.195395452","rc":[{"atb":[[2.48,5.03]],"id":36899924}],"con":true,"img":false}]}
{"op":"mcm","clk":"5346768724","pt":1646096489667,"mc":[{"id":"1.195395452","rc":[{"atb":[[1.74,27.03],[1.76,0]],"id":41921674}],"con":true,"img":false}]}
{"op":"mcm","clk":"5346768777","pt":1646096491159,"mc":[{"id":"1.195395452","rc":[{"atb":[[2.5,42.88],[2.42,0]],"id":36899924}],"con":true,"img":false}]}
{"op":"mcm","clk":"5346768792","pt":1646096491573,"mc":[{"id":"1.195395452","rc":[{"atb":[[2.48,0]],"id":36899924}],"con":true,"img":false}]}
{"op":"mcm","clk":"5346768968","pt":1646096496247,"mc":[{"id":"1.195395452","rc":[{"atb":[[2.5,0],[2.42,70.42]],"id":36899924}],"con":true,"img":false}]}
{"op":"mcm","clk":"5346769053","pt":1646096498046,"mc":[{"id":"1.195395452","rc":[{"atb":[[1.74,0],[1.76,26.32]],"id":41921674}],"con":true,"img":false}]}
{"op":"mcm","clk":"5346769172","pt":1646096501280,"mc":[{"id":"1.195395452","rc":[{"atb":[[1.74,27.03],[1.76,0]],"id":41921674}],"con":true,"img":false}]}
{"op":"mcm","clk":"5346769279","pt":1646096503790,"mc":[{"id":"1.195395452","rc":[{"atb":[[2.48,5.03]],"id":36899924}],"con":true,"img":false}]}
{"op":"mcm","clk":"5346769356","pt":1646096506404,"mc":[{"id":"1.195395452","rc":[{"atb":[[2.5,42.88],[2.42,0]],"id":36899924}],"con":true,"img":false}]}
{"op":"mcm","clk":"5346769470","pt":1646096509582,"mc":[{"id":"1.195395452","rc":[{"atb":[[2.48,0]],"id":36899924}],"con":true,"img":false}]}
{"op":"mcm","clk":"5346769480","pt":1646096509790,"mc":[{"id":"1.195395452","rc":[{"atb":[[1.74,0],[1.76,26.32]],"id":41921674}],"con":true,"img":false}]}
{"op":"mcm","clk":"5346769549","pt":1646096511483,"mc":[{"id":"1.195395452","rc":[{"atb":[[2.5,0],[2.42,70.42]],"id":36899924}],"con":true,"img":false}]}
{"op":"mcm","clk":"5346769616","pt":1646096513692,"mc":[{"id":"1.195395452","rc":[{"atb":[[1.74,27.03],[1.76,0]],"id":41921674}],"con":true,"img":false}]}
{"op":"mcm","clk":"5346769753","pt":1646096518476,"mc":[{"id":"1.195395452","rc":[{"atb":[[2.48,5.03]],"id":36899924}],"con":true,"img":false}]}
{"op":"mcm","clk":"5346769834","pt":1646096521423,"mc":[{"id":"1.195395452","rc":[{"atb":[[1.76,26.32]],"id":41921674}],"con":true,"img":false}]}
{"op":"mcm","clk":"5346769837","pt":1646096521476,"mc":[{"id":"1.195395452","rc":[{"atb":[[1.74,0]],"id":41921674},{"atb":[[2.5,42.88],[2.42,0]],"id":36899924}],"con":true,"img":false}]}
{"op":"mcm","clk":"5346769926","pt":1646096524598,"mc":[{"id":"1.195395452","rc":[{"atb":[[2.48,0]],"id":36899924}],"con":true,"img":false}]}
{"op":"mcm","clk":"5346769961","pt":1646096525727,"mc":[{"id":"1.195395452","rc":[{"atb":[[1.74,27.03]],"id":41921674}],"con":true,"img":false}]}
{"op":"mcm","clk":"5346769965","pt":1646096525828,"mc":[{"id":"1.195395452","rc":[{"atb":[[1.76,0]],"id":41921674}],"con":true,"img":false}]}
{"op":"mcm","clk":"5346769998","pt":1646096526601,"mc":[{"id":"1.195395452","rc":[{"atb":[[2.42,70.42]],"id":36899924}],"con":true,"img":false}]}
{"op":"mcm","clk":"5346770000","pt":1646096526703,"mc":[{"id":"1.195395452","rc":[{"atb":[[2.5,0]],"id":36899924}],"con":true,"img":false}]}
{"op":"mcm","clk":"5346770035","pt":1646096527727,"mc":[{"id":"1.195395452","rc":[{"atb":[[2.48,5.64]],"id":36899924}],"con":true,"img":false}]}
{"op":"mcm","clk":"5346770223","pt":1646096533534,"mc":[{"id":"1.195395452","rc":[{"atb":[[2.48,10.68]],"id":36899924}],"con":true,"img":false}]}
{"op":"mcm","clk":"5346770235","pt":1646096534150,"mc":[{"id":"1.195395452","rc":[{"atb":[[1.74,0],[1.76,26.32]],"id":41921674}],"con":true,"img":false}]}
{"op":"mcm","clk":"5346770313","pt":1646096536413,"mc":[{"id":"1.195395452","rc":[{"atb":[[2.5,42.88],[2.42,0]],"id":36899924}],"con":true,"img":false}]}
{"op":"mcm","clk":"5346770357","pt":1646096537446,"mc":[{"id":"1.195395452","rc":[{"atb":[[1.74,27.03],[1.76,0]],"id":41921674}],"con":true,"img":false}]}
{"op":"mcm","clk":"5346770441","pt":1646096539552,"mc":[{"id":"1.195395452","rc":[{"atb":[[2.48,5.64]],"id":36899924}],"con":true,"img":false}]}
{"op":"mcm","clk":"5346770660","pt":1646096545564,"mc":[{"id":"1.195395452","rc":[{"atb":[[2.56,4.77]],"id":36899924}],"con":true,"img":false}]}
{"op":"mcm","clk":"5346770669","pt":1646096545720,"mc":[{"id":"1.195395452","rc":[{"atb":[[1.74,0],[1.76,26.32]],"id":41921674}],"con":true,"img":false}]}
{"op":"mcm","clk":"5346770805","pt":1646096549443,"mc":[{"id":"1.195395452","rc":[{"atb":[[1.74,27.03]],"id":41921674}],"con":true,"img":false}]}
{"op":"mcm","clk":"5346770807","pt":1646096549546,"mc":[{"id":"1.195395452","rc":[{"atb":[[1.76,0]],"id":41921674}],"con":true,"img":false}]}
{"op":"mcm","clk":"5346770866","pt":1646096551139,"mc":[{"id":"1.195395452","rc":[{"atb":[[2.58,5.65]],"id":36899924}],"con":true,"img":false}]}
{"op":"mcm","clk":"5346770869","pt":1646096551242,"mc":[{"id":"1.195395452","rc":[{"atb":[[2.5,0]],"id":36899924}],"con":true,"img":false}]}
{"op":"mcm","clk":"5346770878","pt":1646096551654,"mc":[{"id":"1.195395452","rc":[{"atb":[[2.56,0]],"id":36899924}],"con":true,"img":false}]}
{"op":"mcm","clk":"5346770881","pt":1646096551758,"mc":[{"id":"1.195395452","rc":[{"atb":[[2.48,0]],"id":36899924}],"con":true,"img":false}]}
{"op":"mcm","clk":"5346771053","pt":1646096556237,"mc":[{"id":"1.195395452","rc":[{"atb":[[2.42,50.12]],"id":36899924}],"con":true,"img":false}]}
{"op":"mcm","clk":"5346771056","pt":1646096556339,"mc":[{"id":"1.195395452","rc":[{"atb":[[2.58,0]],"id":36899924}],"con":true,"img":false}]}
{"op":"mcm","clk":"5346771316","pt":1646096563646,"mc":[{"id":"1.195395452","rc":[{"atb":[[2.48,5.03]],"id":36899924}],"con":true,"img":false}]}
{"op":"mcm","clk":"5346771328","pt":1646096564055,"mc":[{"id":"1.195395452","rc":[{"atb":[[1.73,83.7],[1.74,0]],"id":41921674},{"atl":[[3.35,0],[3.4,8.33]],"id":40251221},{"atl":[[5.3,4.65],[5.2,0]],"id":36899924}],"con":true,"img":false}]}
{"op":"mcm","clk":"5346771530","pt":1646096569697,"mc":[{"id":"1.195395452","rc":[{"atb":[[1.73,56.3],[1.75,26.67]],"id":41921674},{"atl":[[11,0],[11.5,1.9]],"id":27151693}],"con":true,"img":false}]}
{"op":"mcm","clk":"5346771547","pt":1646096570057,"mc":[{"id":"1.195395452","rc":[{"atb":[[2.48,10.68]],"id":36899924}],"con":true,"img":false}]}
{"op":"mcm","clk":"5346771578","pt":1646096570778,"mc":[{"id":"1.195395452","rc":[{"atb":[[2.5,42.88],[2.42,0]],"id":36899924},{"atl":[[11.5,0]],"id":27151693}],"con":true,"img":false}]}
{"op":"mcm","clk":"5346771581","pt":1646096570878,"mc":[{"id":"1.195395452","rc":[{"atl":[[11,2]],"id":27151693}],"con":true,"img":false}]}
{"op":"mcm","clk":"5346771653","pt":1646096572578,"mc":[{"id":"1.195395452","rc":[{"atb":[[2.48,5.64]],"id":36899924}],"con":true,"img":false}]}
{"op":"mcm","clk":"5346771663","pt":1646096572885,"mc":[{"id":"1.195395452","rc":[{"atb":[[1.73,83.7],[1.75,0]],"id":41921674}],"con":true,"img":false}]}
{"op":"mcm","clk":"5346771716","pt":1646096574073,"mc":[{"id":"1.195395452","rc":[{"atl":[[5.5,11.11]],"id":36899924}],"con":true,"img":false}]}
{"op":"mcm","clk":"5346771891","pt":1646096578618,"mc":[{"id":"1.195395452","rc":[{"atb":[[2.56,4.77]],"id":36899924}],"con":true,"img":false}]}
{"op":"mcm","clk":"5346772002","pt":1646096581497,"mc":[{"id":"1.195395452","rc":[{"atb":[[1.73,56.3],[1.75,26.67]],"id":41921674}],"con":true,"img":false}]}
{"op":"mcm","clk":"5346772005","pt":1646096581598,"mc":[{"id":"1.195395452","rc":[{"atl":[[5.6,0],[5.8,2.5],[5.4,0]],"id":36899924},{"atb":[[2.18,67.13],[2.2,0]],"id":39979879},{"atl":[[11,0],[11.5,1.9]],"id":27151693}],"con":true,"img":false}]}
{"op":"mcm","clk":"5346772080","pt":1646096584111,"mc":[{"id":"1.195395452","rc":[{"atl":[[5.7,24.59]],"id":36899924}],"con":true,"img":false}]}
{"op":"mcm","clk":"5346772119","pt":1646096585188,"mc":[{"id":"1.195395452","rc":[{"atb":[[1.73,83.7],[1.75,0]],"id":41921674},{"atb":[[2.5,0],[2.58,5.65]],"id":36899924},{"atl":[[11,2],[11.5,0]],"id":27151693}],"con":true,"img":false}]}
{"op":"mcm","clk":"5346772143","pt":1646096585808,"mc":[{"id":"1.195395452","rc":[{"atb":[[2.56,0]],"id":36899924},{"atb":[[2.26,6.63]],"id":39979879}],"con":true,"img":false}]}
{"op":"mcm","clk":"5346772345","pt":1646096590317,"mc":[{"id":"1.195395452","rc":[{"atb":[[2.5,42.88]],"id":36899924},{"atl":[[5.7,15.96]],"id":36899924}],"con":true,"img":false}]}
{"op":"mcm","clk":"5346772350","pt":1646096590420,"mc":[{"id":"1.195395452","rc":[{"atb":[[2.58,0]],"id":36899924},{"atl":[[7.2,8.63]],"id":36899924}],"con":true,"img":false}]}
{"op":"mcm","clk":"5346772423","pt":1646096592008,"mc":[{"id":"1.195395452","rc":[{"atb":[[2.48,0]],"id":36899924}],"con":true,"img":false}]}
{"op":"mcm","clk":"5346772492","pt":1646096593703,"mc":[{"id":"1.195395452","rc":[{"atb":[[1.73,56.3],[1.75,26.67]],"id":41921674},{"atl":[[11,0],[11.5,1.9]],"id":27151693}],"con":true,"img":false}]}
{"op":"mcm","clk":"5346772505","pt":1646096594011,"mc":[{"id":"1.195395452","rc":[{"atb":[[2.24,6]],"id":39979879}],"con":true,"img":false}]}
{"op":"mcm","clk":"5346772508","pt":1646096594114,"mc":[{"id":"1.195395452","rc":[{"atl":[[5.9,25.51]],"id":36899924}],"con":true,"img":false}]}
{"op":"mcm","clk":"5346772579","pt":1646096595601,"mc":[{"id":"1.195395452","rc":[{"atb":[[2.5,0],[2.42,70.42]],"id":36899924}],"con":true,"img":false}]}
{"op":"mcm","clk":"5346772593","pt":1646096595910,"mc":[{"id":"1.195395452","rc":[{"atb":[[2.18,0],[2.2,54.58]],"id":39979879}],"con":true,"img":false}]}
{"op":"mcm","clk":"5346772634","pt":1646096596733,"mc":[{"id":"1.195395452","rc":[{"atb":[[2.24,0]],"id":39979879}],"con":true,"img":false}]}
{"op":"mcm","clk":"5346772663","pt":1646096597454,"mc":[{"id":"1.195395452","rc":[{"atb":[[1.73,83.7]],"id":41921674},{"atl":[[11,2],[11.5,0]],"id":27151693}],"con":true,"img":false}]}
{"op":"mcm","clk":"5346772674","pt":1646096597608,"mc":[{"id":"1.195395452","rc":[{"atb":[[1.75,0]],"id":41921674}],"con":true,"img":false}]}
{"op":"mcm","clk":"5346772886","pt":1646096602648,"mc":[{"id":"1.195395452","rc":[{"atb":[[2.48,5.03]],"id":36899924},{"atb":[[2.26,12.54]],"id":39979879}],"con":true,"img":false}]}
{"op":"mcm","clk":"5346772994","pt":1646096604710,"mc":[{"id":"1.195395452","rc":[{"atb":[[2.5,42.88],[2.42,0]],"id":36899924}],"con":true,"img":false}]}
{"op":"mcm","clk":"5346773037","pt":1646096605736,"mc":[{"id":"1.195395452","rc":[{"atb":[[2.48,0]],"id":36899924}],"con":true,"img":false}]}
{"op":"mcm","clk":"5346773042","pt":1646096605840,"mc":[{"id":"1.195395452","rc":[{"atb":[[2.5,0],[2.42,70.42]],"id":36899924}],"con":true,"img":false}]}
{"op":"mcm","clk":"5346773123","pt":1646096607532,"mc":[{"id":"1.195395452","rc":[{"atb":[[1.71,70.42]],"id":41921674}],"con":true,"img":false}]}
{"op":"mcm","clk":"5346773221","pt":1646096609739,"mc":[{"id":"1.195395452","rc":[{"atb":[[2.48,5.64]],"id":36899924}],"con":true,"img":false}]}
{"op":"mcm","clk":"5346773240","pt":1646096610250,"mc":[{"id":"1.195395452","rc":[{"atb":[[1.72,0],[1.7,0],[1.68,0]],"id":41921674}],"con":true,"img":false}]}
{"op":"mcm","clk":"5346773429","pt":1646096614782,"mc":[{"id":"1.195395452","rc":[{"atb":[[2.48,10.68]],"id":36899924}],"con":true,"img":false}]}
{"op":"mcm","clk":"5346773556","pt":1646096617554,"mc":[{"id":"1.195395452","rc":[{"atb":[[1.69,108.7]],"id":41921674}],"con":true,"img":false}]}
{"op":"mcm","clk":"5346773568","pt":1646096617762,"mc":[{"id":"1.195395452","rc":[{"atb":[[1.75,26.67]],"id":41921674},{"atl":[[11,0],[11.5,1.9]],"id":27151693}],"con":true,"img":false}]}
{"op":"mcm","clk":"5346773658","pt":1646096619973,"mc":[{"id":"1.195395452","rc":[{"atb":[[2.5,42.88]],"id":36899924}],"con":true,"img":false}]}
{"op":"mcm","clk":"5346773661","pt":1646096620076,"mc":[{"id":"1.195395452","rc":[{"atb":[[2.42,0]],"id":36899924}],"con":true,"img":false}]}
{"op":"mcm","clk":"5346773686","pt":1646096620800,"mc":[{"id":"1.195395452","rc":[{"atb":[[2.48,5.64]],"id":36899924}],"con":true,"img":false}]}
{"op":"mcm","clk":"5346773689","pt":1646096620850,"mc":[{"id":"1.195395452","rc":[{"atl":[[11,2],[11.5,0]],"id":27151693}],"con":true,"img":false}]}
{"op":"mcm","clk":"5346773757","pt":1646096622344,"mc":[{"id":"1.195395452","rc":[{"atb":[[1.75,0]],"id":41921674}],"con":true,"img":false}]}
{"op":"mcm","clk":"5346773930","pt":1646096626765,"mc":[{"id":"1.195395452","rc":[{"atb":[[2.56,4.77]],"id":36899924}],"con":true,"img":false}]}
{"op":"mcm","clk":"5346773932","pt":1646096626866,"mc":[{"id":"1.195395452","rc":[{"atb":[[2.58,5.65]],"id":36899924}],"con":true,"img":false}]}
{"op":"mcm","clk":"5346773935","pt":1646096626968,"mc":[{"id":"1.195395452","rc":[{"atb":[[2.5,0]],"id":36899924}],"con":true,"img":false}]}
{"op":"mcm","clk":"5346773957","pt":1646096627797,"mc":[{"id":"1.195395452","rc":[{"atb":[[1.67,186.57]],"id":41921674}],"con":true,"img":false}]}
{"op":"mcm","clk":"5346774021","pt":1646096629795,"mc":[{"id":"1.195395452","rc":[{"atb":[[2.56,0]],"id":36899924}],"con":true,"img":false}]}
{"op":"mcm","clk":"5346774030","pt":1646096630002,"mc":[{"id":"1.195395452","rc":[{"atb":[[2.5,42.88],[2.58,0]],"id":36899924}],"con":true,"img":false}]}
{"op":"mcm","clk":"5346774035","pt":1646096630056,"mc":[{"id":"1.195395452","rc":[{"atb":[[1.73,56.3],[1.75,26.67]],"id":41921674},{"atl":[[11,0],[11.5,1.9]],"id":27151693}],"con":true,"img":false}]}
{"op":"mcm","clk":"5346774044","pt":1646096630363,"mc":[{"id":"1.195395452","rc":[{"atb":[[1.73,0]],"id":41921674},{"atl":[[7.2,0]],"id":36899924}],"con":true,"img":false}]}
{"op":"mcm","clk":"5346774046","pt":1646096630461,"mc":[{"id":"1.195395452","rc":[{"atb":[[1.72,56.3]],"id":41921674},{"atl":[[5.8,11.13]],"id":36899924}],"con":true,"img":false}]}
{"op":"mcm","clk":"5346774153","pt":1646096633857,"mc":[{"id":"1.195395452","rc":[{"atb":[[2.48,0]],"id":36899924}],"con":true,"img":false}]}
{"op":"mcm","clk":"5346774163","pt":1646096634166,"mc":[{"id":"1.195395452","rc":[{"atl":[[3.3,8.7],[3.4,0]],"id":40251221},{"atl":[[5.3,0],[5.2,4.76]],"id":36899924},{"atl":[[11,2],[11.5,0]],"id":27151693}],"con":true,"img":false}]}
{"op":"mcm","clk":"5346774185","pt":1646096635089,"mc":[{"id":"1.195395452","rc":[{"atb":[[2.5,0],[2.42,70.42]],"id":36899924}],"con":true,"img":false}]}
{"op":"mcm","clk":"5346774354","pt":1646096640084,"mc":[{"id":"1.195395452","rc":[{"atb":[[1.73,68.49]],"id":41921674}],"con":true,"img":false}]}
{"op":"mcm","clk":"5346774387","pt":1646096641008,"mc":[{"id":"1.195395452","rc":[{"atb":[[1.67,0]],"id":41921674}],"con":true,"img":false}]}
{"op":"mcm","clk":"5346774401","pt":1646096641422,"mc":[{"id":"1.195395452","rc":[{"atb":[[1.44,164.42],[1.39,0],[1.77,25.97],[1.75,0]],"id":41921674},{"atb":[[2.18,67.13],[2.2,0]],"id":39979879}],"con":true,"img":false}]}
{"op":"mcm","clk":"5346774406","pt":1646096641474,"mc":[{"id":"1.195395452","rc":[{"atb":[[2.18,0],[2.2,54.58]],"id":39979879}],"con":true,"img":false}]}
{"op":"mcm","clk":"5346774417","pt":1646096641784,"mc":[{"id":"1.195395452","rc":[{"atb":[[2.48,5.03]],"id":36899924}],"con":true,"img":false}]}
{"op":"mcm","clk":"5346774504","pt":1646096644212,"mc":[{"id":"1.195395452","rc":[{"atl":[[3.4,20.83]],"id":40251221}],"con":true,"img":false}]}
{"op":"mcm","clk":"5346774616","pt":1646096647296,"mc":[{"id":"1.195395452","rc":[{"atb":[[1.77,0],[1.75,26.67]],"id":41921674},{"atb":[[1.59,0],[1.44,163.94],[1.53,0],[1.63,0],[1.54,37.04],[1.61,0]],"id":40251221},{"atl":[[3.7,0]],"id":40251221},{"atb":[[2.28,54.58],[2.2,0]],"id":39979879},{"atl":[[5.4,18.74],[4.7,5.41]],"id":39979879},{"atb":[[1.98,0],[2.1,0],[1.8,94.34],[1.99,0],[2.02,0],[2.06,0],[1.9,22.22]],"id":39722911},{"atl":[[5.3,29.07],[5.9,20.41]],"id":39722911},{"atb":[[1.98,0],[2.3,15.38],[2.1,0],[2.16,66.03]],"id":27151693}],"con":true,"img":false}]}
{"op":"mcm","clk":"5346774620","pt":1646096647400,"mc":[{"id":"1.195395452","rc":[{"atl":[[4.7,10.82],[5.4,0]],"id":39979879}],"con":true,"img":false}]}
{"op":"mcm","clk":"5346774632","pt":1646096647708,"mc":[{"id":"1.195395452","rc":[{"atb":[[2.26,6.63]],"id":39979879}],"con":true,"img":false}]}
{"op":"mcm","clk":"5346774675","pt":1646096648891,"mc":[{"id":"1.195395452","rc":[{"atb":[[2.5,42.88],[2.42,0]],"id":36899924}],"con":true,"img":false}]}
{"op":"mcm","clk":"5346774720","pt":1646096650281,"mc":[{"id":"1.195395452","rc":[{"atb":[[1.81,54.08]],"id":39722911}],"con":true,"img":false}]}
{"op":"mcm","clk":"5346774723","pt":1646096650384,"mc":[{"id":"1.195395452","rc":[{"atb":[[2.08,0]],"id":39722911}],"con":true,"img":false}]}
{"op":"mcm","clk":"5346774733","pt":1646096650794,"mc":[{"id":"1.195395452","rc":[{"atb":[[2.48,0]],"id":36899924}],"con":true,"img":false}]}
{"op":"mcm","clk":"5346774764","pt":1646096651829,"mc":[{"id":"1.195395452","rc":[{"atb":[[2.26,0]],"id":39979879}],"con":true,"img":false}]}
{"op":"mcm","clk":"5346774786","pt":1646096652392,"mc":[{"id":"1.195395452","rc":[{"atb":[[2.12,89.29]],"id":39979879}],"con":true,"img":false}]}
{"op":"mcm","clk":"5346774788","pt":1646096652496,"mc":[{"id":"1.195395452","rc":[{"atb":[[2.28,0]],"id":39979879},{"atl":[[5.3,24.43],[4.7,5.41]],"id":39979879}],"con":true,"img":false}]}
{"op":"mcm","clk":"5346774844","pt":1646096654032,"mc":[{"id":"1.195395452","rc":[{"atb":[[2.5,0],[2.42,70.42]],"id":36899924}],"con":true,"img":false}]}
{"op":"mcm","clk":"5346774848","pt":1646096654238,"mc":[{"id":"1.195395452","rc":[{"atb":[[1.77,25.97],[1.75,0]],"id":41921674},{"atb":[[1.57,0]],"id":40251221}],"con":true,"img":false}]}
{"op":"mcm","clk":"5346774950","pt":1646096657337,"mc":[{"id":"1.195395452","rc":[{"atb":[[1.52,96.15]],"id":40251221},{"atl":[[3.5,30]],"id":40251221},{"atl":[[4.9,12.82]],"id":39979879},{"atb":[[1.88,56.82]],"id":39722911},{"atb":[[2.26,39.68]],"id":27151693}],"con":true,"img":false}]}
{"op":"mcm","clk":"5346775023","pt":1646096659602,"mc":[{"id":"1.195395452","rc":[{"atb":[[1.77,0],[1.75,26.67]],"id":41921674},{"atb":[[1.99,0]],"id":27151693}],"con":true,"img":false}]}
{"op":"mcm","clk":"5346775025","pt":1646096659705,"mc":[{"id":"1.195395452","rc":[{"atl":[[5.6,0],[5.8,0],[6,0]],"id":39979879}],"con":true,"img":false}]}
{"op":"mcm","clk":"5346775034","pt":1646096660020,"mc":[{"id":"1.195395452","rc":[{"atb":[[2.16,6.42]],"id":39979879}],"con":true,"img":false}]}
{"op":"mcm","clk":"5346775045","pt":1646096660324,"mc":[{"id":"1.195395452","rc":[{"atb":[[2.62,0]],"id":43154431}],"con":true,"img":false}]}
{"op":"mcm","clk":"5346775051","pt":1646096660427,"mc":[{"id":"1.195395452","rc":[{"atb":[[2.58,27.04]],"id":43154431}],"con":true,"img":false}]}
{"op":"mcm","clk":"5346775158","pt":1646096662752,"mc":[{"id":"1.195395452","rc":[{"atb":[[2.48,5.03]],"id":36899924},{"atb":[[2.68,0]],"id":43154431}],"con":true,"img":false}]}
{"op":"mcm","clk":"5346775275","pt":1646096666040,"mc":[{"id":"1.195395452","rc":[{"atb":[[2.12,0],[2.18,54.58]],"id":39979879}],"con":true,"img":false}]}
{"op":"mcm","clk":"5346775299","pt":1646096666501,"mc":[{"id":"1.195395452","rc":[{"atb":[[1.77,25.97],[1.75,0]],"id":41921674}],"con":true,"img":false}]}
{"op":"mcm","clk":"5346775334","pt":1646096667325,"mc":[{"id":"1.195395452","rc":[{"atb":[[1.5,150]],"id":40251221},{"atl":[[3.6,48.08]],"id":40251221},{"atl":[[5.1,18.29]],"id":39979879},{"atb":[[1.86,87.21]],"id":39722911},{"atb":[[2.22,61.48]],"id":27151693}],"con":true,"img":false}]}
{"op":"mcm","clk":"5346775338","pt":1646096667429,"mc":[{"id":"1.195395452","rc":[{"atl":[[5.1,36.52],[5.3,2.79]],"id":39979879}],"con":true,"img":false}]}
{"op":"mcm","clk":"5346775347","pt":1646096667634,"mc":[{"id":"1.195395452","rc":[{"atb":[[2.5,42.88],[2.42,0]],"id":36899924}],"con":true,"img":false}]}
{"op":"mcm","clk":"5346775396","pt":1646096668819,"mc":[{"id":"1.195395452","rc":[{"atb":[[2.48,0]],"id":36899924},{"atb":[[2.16,0]],"id":39979879},{"atb":[[2.66,9.51]],"id":43154431}],"con":true,"img":false}]}
{"op":"mcm","clk":"5346775402","pt":1646096668922,"mc":[{"id":"1.195395452","rc":[{"atb":[[2.12,89.29],[2.18,0]],"id":39979879}],"con":true,"img":false}]}
{"op":"mcm","clk":"5346775456","pt":1646096669948,"mc":[{"id":"1.195395452","rc":[{"atb":[[2.16,7.2]],"id":39979879}],"con":true,"img":false}]}
{"op":"mcm","clk":"5346775461","pt":1646096670052,"mc":[{"id":"1.195395452","rc":[{"atb":[[2.18,54.58]],"id":39979879}],"con":true,"img":false}]}
{"op":"mcm","clk":"5346775465","pt":1646096670152,"mc":[{"id":"1.195395452","rc":[{"atb":[[2.12,0]],"id":39979879}],"con":true,"img":false}]}
{"op":"mcm","clk":"5346775473","pt":1646096670361,"mc":[{"id":"1.195395452","rc":[{"atb":[[1.72,0]],"id":41921674},{"atb":[[1.62,69.05]],"id":40251221}],"con":true,"img":false}]}
{"op":"mcm","clk":"5346775476","pt":1646096670412,"mc":[{"id":"1.195395452","rc":[{"atb":[[1.74,56.3]],"id":41921674}],"con":true,"img":false}]}
{"op":"mcm","clk":"5346775552","pt":1646096672268,"mc":[{"id":"1.195395452","rc":[{"atb":[[1.77,0],[1.75,26.67]],"id":41921674},{"atb":[[2.02,0]],"id":27151693}],"con":true,"img":false}]}
{"op":"mcm","clk":"5346775568","pt":1646096672722,"mc":[{"id":"1.195395452","rc":[{"atb":[[2.5,0],[2.42,70.42]],"id":36899924}],"con":true,"img":false}]}
{"op":"mcm","clk":"5346775646","pt":1646096674829,"mc":[{"id":"1.195395452","rc":[{"atb":[[2.24,6]],"id":39979879}],"con":true,"img":false}]}
{"op":"mcm","clk":"5346775741","pt":1646096677351,"mc":[{"id":"1.195395452","rc":[{"atb":[[1.48,250]],"id":40251221},{"atl":[[5.3,31.86]],"id":39979879},{"atb":[[1.84,148.81]],"id":39722911},{"atb":[[2.18,105.93]],"id":27151693}],"con":true,"img":false}]}
{"op":"mcm","clk":"5346775784","pt":1646096678633,"mc":[{"id":"1.195395452","rc":[{"atb":[[1.77,25.97],[1.75,0]],"id":41921674},{"atb":[[2.06,0]],"id":27151693}],"con":true,"img":false}]}
{"op":"mcm","clk":"5346775848","pt":1646096680641,"mc":[{"id":"1.195395452","rc":[{"atb":[[1.75,26.67]],"id":41921674}],"con":true,"img":false}]}
{"op":"mcm","clk":"5346775851","pt":1646096680744,"mc":[{"id":"1.195395452","rc":[{"atb":[[1.77,0]],"id":41921674}],"con":true,"img":false}]}
{"op":"mcm","clk":"5346775854","pt":1646096680845,"mc":[{"id":"1.195395452","rc":[{"atb":[[2.48,5.03]],"id":36899924}],"con":true,"img":false}]}
{"op":"mcm","clk":"5346775947","pt":1646096683464,"mc":[{"id":"1.195395452","rc":[{"atb":[[2.18,0],[2.26,7.2]],"id":39979879}],"con":true,"img":false}]}
{"op":"mcm","clk":"5346775959","pt":1646096683874,"mc":[{"id":"1.195395452","rc":[{"atb":[[2.24,0]],"id":39979879}],"con":true,"img":false}]}
{"op":"mcm","clk":"5346775967","pt":1646096684081,"mc":[{"id":"1.195395452","rc":[{"atb":[[1.77,25.97],[1.75,0]],"id":41921674},{"atb":[[2.18,18.87],[2.26,0]],"id":39979879}],"con":true,"img":false}]}
{"op":"mcm","clk":"5346776045","pt":1646096686192,"mc":[{"id":"1.195395452","rc":[{"atb":[[2.5,42.88],[2.42,0]],"id":36899924}],"con":true,"img":false}]}
{"op":"mcm","clk":"5346776074","pt":1646096686965,"mc":[{"id":"1.195395452","rc":[{"atb":[[2.48,0]],"id":36899924}],"con":true,"img":false}]}
{"op":"mcm","clk":"5346776077","pt":1646096687071,"mc":[{"id":"1.195395452","rc":[{"atb":[[2.5,0],[2.42,70.42]],"id":36899924}],"con":true,"img":false}]}
{"op":"mcm","clk":"5346776111","pt":1646096687943,"mc":[{"id":"1.195395452","rc":[{"atb":[[2.16,0]],"id":39979879}],"con":true,"img":false}]}
{"op":"mcm","clk":"5346776119","pt":1646096688151,"mc":[{"id":"1.195395452","rc":[{"atb":[[2.48,5.64]],"id":36899924}],"con":true,"img":false}]}
{"op":"mcm","clk":"5346776122","pt":1646096688252,"mc":[{"id":"1.195395452","rc":[{"atb":[[2.5,42.88],[2.42,0]],"id":36899924}],"con":true,"img":false}]}
{"op":"mcm","clk":"5346776160","pt":1646096689175,"mc":[{"id":"1.195395452","rc":[{"atb":[[2.12,54.58],[2.18,0]],"id":39979879}],"con":true,"img":false}]}
{"op":"mcm","clk":"5346776206","pt":1646096690353,"mc":[{"id":"1.195395452","rc":[{"atb":[[2.58,0]],"id":43154431}],"con":true,"img":false}]}
{"op":"mcm","clk":"5346776209","pt":1646096690456,"mc":[{"id":"1.195395452","rc":[{"atb":[[2.62,27.04]],"id":43154431}],"con":true,"img":false}]}
{"op":"mcm","clk":"5346776225","pt":1646096690869,"mc":[{"id":"1.195395452","rc":[{"atb":[[1.78,25.64],[1.77,0]],"id":41921674}],"con":true,"img":false}]}
{"op":"mcm","clk":"5346776301","pt":1646096692882,"mc":[{"id":"1.195395452","rc":[{"atb":[[2.56,4.77]],"id":36899924},{"atb":[[2.66,5.02]],"id":43154431}],"con":true,"img":false}]}
{"op":"mcm","clk":"5346776365","pt":1646096694373,"mc":[{"id":"1.195395452","rc":[{"atb":[[1.78,0],[1.77,25.97]],"id":41921674}],"con":true,"img":false}]}
{"op":"mcm","clk":"5346776410","pt":1646096695761,"mc":[{"id":"1.195395452","rc":[{"atb":[[2.16,6.42]],"id":39979879}],"con":true,"img":false}]}
{"op":"mcm","clk":"5346776517","pt":1646096698893,"mc":[{"id":"1.195395452","rc":[{"atb":[[2.68,4.43]],"id":43154431}],"con":true,"img":false}]}
{"op":"mcm","clk":"5346776568","pt":1646096700384,"mc":[{"id":"1.195395452","rc":[{"atl":[[5.9,0]],"id":39979879},{"atb":[[1.81,0]],"id":39722911},{"atb":[[2.22,34.07],[1.75,0]],"id":43154431}],"con":true,"img":false}]}
{"op":"mcm","clk":"5346776571","pt":1646096700488,"mc":[{"id":"1.195395452","rc":[{"atl":[[5.2,7.51]],"id":39979879},{"atb":[[1.89,54.08]],"id":39722911}],"con":true,"img":false}]}
{"op":"mcm","clk":"5346776601","pt":1646096701514,"mc":[{"id":"1.195395452","rc":[{"atb":[[2.5,0],[2.58,5.65]],"id":36899924}],"con":true,"img":false}]}
{"op":"mcm","clk":"5346776617","pt":1646096701981,"mc":[{"id":"1.195395452","rc":[{"atb":[[2.56,0]],"id":36899924}],"con":true,"img":false}]}
{"op":"mcm","clk":"5346776636","pt":1646096702393,"mc":[{"id":"1.195395452","rc":[{"atb":[[1.78,25.64],[1.77,0]],"id":41921674}],"con":true,"img":false}]}
{"op":"mcm","clk":"5346776638","pt":1646096702494,"mc":[{"id":"1.195395452","rc":[{"atb":[[2.12,0],[2.18,54.58]],"id":39979879}],"con":true,"img":false}]}
{"op":"mcm","clk":"5346776711","pt":1646096703580,"mc":[{"id":"1.195395452","rc":[{"atb":[[1.77,25.97]],"id":41921674},{"atb":[[2.36,14.71],[2.32,34.97]],"id":36899924}],"con":true,"img":false}]}
{"op":"mcm","clk":"5346776715","pt":1646096703678,"mc":[{"id":"1.195395452","rc":[{"atb":[[1.78,0]],"id":41921674}],"con":true,"img":false}]}
{"op":"mcm","clk":"5346776776","pt":1646096705014,"mc":[{"id":"1.195395452","rc":[{"atb":[[2.16,0]],"id":39979879}],"con":true,"img":false}]}
{"op":"mcm","clk":"5346776785","pt":1646096705219,"mc":[{"id":"1.195395452","rc":[{"atb":[[2.12,89.29],[2.18,0]],"id":39979879}],"con":true,"img":false}]}
{"op":"mcm","clk":"5346776827","pt":1646096706098,"mc":[{"id":"1.195395452","rc":[{"atb":[[2.48,0]],"id":36899924}],"con":true,"img":false}]}
{"op":"mcm","clk":"5346776839","pt":1646096706304,"mc":[{"id":"1.195395452","rc":[{"atb":[[2.16,7.2]],"id":39979879}],"con":true,"img":false}]}
{"op":"mcm","clk":"5346776843","pt":1646096706406,"mc":[{"id":"1.195395452","rc":[{"atb":[[2.18,54.58]],"id":39979879}],"con":true,"img":false}]}
{"op":"mcm","clk":"5346776847","pt":1646096706511,"mc":[{"id":"1.195395452","rc":[{"atb":[[2.12,0]],"id":39979879}],"con":true,"img":false}]}
{"op":"mcm","clk":"5346776851","pt":1646096706612,"mc":[{"id":"1.195395452","rc":[{"atb":[[2.42,34.97],[2.58,0]],"id":36899924}],"con":true,"img":false}]}
{"op":"mcm","clk":"5346777026","pt":1646096710887,"mc":[{"id":"1.195395452","rc":[{"atb":[[2.24,6]],"id":39979879}],"con":true,"img":false}]}
{"op":"mcm","clk":"5346777132","pt":1646096713608,"mc":[{"id":"1.195395452","rc":[{"atb":[[1.75,66.67]],"id":41921674},{"atb":[[2.32,72.85]],"id":36899924}],"con":true,"img":false}]}
{"op":"mcm","clk":"5346777138","pt":1646096713916,"mc":[{"id":"1.195395452","rc":[{"atb":[[2.48,5.03]],"id":36899924}],"con":true,"img":false}]}
{"op":"mcm","clk":"5346777154","pt":1646096714427,"mc":[{"id":"1.195395452","rc":[{"atb":[[1.78,25.64],[1.77,0]],"id":41921674},{"atb":[[2.2,100.05]],"id":36899924}],"con":true,"img":false}]}
{"op":"mcm","clk":"5346777157","pt":1646096714483,"mc":[{"id":"1.195395452","rc":[{"atb":[[1.69,0]],"id":41921674}],"con":true,"img":false}]}
{"op":"mcm","clk":"5346777324","pt":1646096719526,"mc":[{"id":"1.195395452","rc":[{"atb":[[2.18,0],[2.26,7.2]],"id":39979879}],"con":true,"img":false}]}
{"op":"mcm","clk":"5346777330","pt":1646096719731,"mc":[{"id":"1.195395452","rc":[{"atb":[[2.5,34.97],[2.42,0]],"id":36899924}],"con":true,"img":false}]}
{"op":"mcm","clk":"5346777336","pt":1646096719888,"mc":[{"id":"1.195395452","rc":[{"atb":[[2.24,0]],"id":39979879}],"con":true,"img":false}]}
{"op":"mcm","clk":"5346777338","pt":1646096719988,"mc":[{"id":"1.195395452","rc":[{"atb":[[2.18,18.87],[2.26,0]],"id":39979879}],"con":true,"img":false}]}
{"op":"mcm","clk":"5346777358","pt":1646096720507,"mc":[{"id":"1.195395452","rc":[{"atb":[[1.78,0],[1.77,25.97]],"id":41921674}],"con":true,"img":false}]}
{"op":"mcm","clk":"5346777456","pt":1646096722923,"mc":[{"id":"1.195395452","rc":[{"atb":[[2.48,0]],"id":36899924}],"con":true,"img":false}]}
{"op":"mcm","clk":"5346777460","pt":1646096723023,"mc":[{"id":"1.195395452","rc":[{"atb":[[2.42,69.94]],"id":36899924}],"con":true,"img":false}]}
{"op":"mcm","clk":"5346777465","pt":1646096723127,"mc":[{"id":"1.195395452","rc":[{"atb":[[2.5,0]],"id":36899924}],"con":true,"img":false}]}
{"op":"mcm","clk":"5346777485","pt":1646096723638,"mc":[{"id":"1.195395452","rc":[{"atb":[[2.28,58.59]],"id":36899924}],"con":true,"img":false}]}
{"op":"mcm","clk":"5346777497","pt":1646096724003,"mc":[{"id":"1.195395452","rc":[{"atb":[[2.16,0]],"id":39979879}],"con":true,"img":false}]}
{"op":"mcm","clk":"5346777499","pt":1646096724103,"mc":[{"id":"1.195395452","rc":[{"atb":[[2.12,54.58],[2.18,0]],"id":39979879}],"con":true,"img":false}]}
{"op":"mcm","clk":"5346777502","pt":1646096724207,"mc":[{"id":"1.195395452","rc":[{"atb":[[2.48,5.64]],"id":36899924}],"con":true,"img":false}]}
{"op":"mcm","clk":"5346777764","pt":1646096730528,"mc":[{"id":"1.195395452","rc":[{"atb":[[1.73,102.74]],"id":41921674}],"con":true,"img":false}]}
{"op":"mcm","clk":"5346777820","pt":1646096731918,"mc":[{"id":"1.195395452","rc":[{"atb":[[2.16,6.42]],"id":39979879}],"con":true,"img":false}]}
{"op":"mcm","clk":"5346777825","pt":1646096732021,"mc":[{"id":"1.195395452","rc":[{"atb":[[2.48,10.68]],"id":36899924},{"atb":[[2.12,0],[2.18,54.58]],"id":39979879}],"con":true,"img":false}]}
{"op":"mcm","clk":"5346777883","pt":1646096733611,"mc":[{"id":"1.195395452","rc":[{"atb":[[2.24,100.81]],"id":36899924}],"con":true,"img":false}]}
{"op":"mcm","clk":"5346777925","pt":1646096734945,"mc":[{"id":"1.195395452","rc":[{"atb":[[2.16,0]],"id":39979879}],"con":true,"img":false}]}
{"op":"mcm","clk":"5346777959","pt":1646096735926,"mc":[{"id":"1.195395452","rc":[{"atb":[[2.5,42.88],[2.42,0]],"id":36899924}],"con":true,"img":false}]}
{"op":"mcm","clk":"5346778002","pt":1646096737158,"mc":[{"id":"1.195395452","rc":[{"atb":[[2.12,89.29],[2.18,0]],"id":39979879}],"con":true,"img":false}]}
{"op":"mcm","clk":"5346778024","pt":1646096738033,"mc":[{"id":"1.195395452","rc":[{"atb":[[2.48,5.64]],"id":36899924}],"con":true,"img":false}]}
{"op":"mcm","clk":"5346778058","pt":1646096739268,"mc":[{"id":"1.195395452","rc":[{"atb":[[1.78,25.64],[1.77,0]],"id":41921674}],"con":true,"img":false}]}
{"op":"mcm","clk":"5346778097","pt":1646096740351,"mc":[{"id":"1.195395452","rc":[{"atl":[[5.2,0]],"id":39979879}],"con":true,"img":false}]}
{"op":"mcm","clk":"5346778101","pt":1646096740457,"mc":[{"id":"1.195395452","rc":[{"atl":[[5,7.51]],"id":39979879}],"con":true,"img":false}]}
{"op":"mcm","clk":"5346778105","pt":1646096740559,"mc":[{"id":"1.195395452","rc":[{"atl":[[5.1,18.29]],"id":39979879}],"con":true,"img":false}]}
{"op":"mcm","clk":"5346778110","pt":1646096740662,"mc":[{"id":"1.195395452","rc":[{"atl":[[4.9,25.64]],"id":39979879}],"con":true,"img":false}]}
{"op":"mcm","clk":"5346778115","pt":1646096740867,"mc":[{"id":"1.195395452","rc":[{"atb":[[1.78,0],[1.77,25.97]],"id":41921674}],"con":true,"img":false}]}
{"op":"mcm","clk":"5346778211","pt":1646096743951,"mc":[{"id":"1.195395452","rc":[{"atb":[[2.56,4.77]],"id":36899924},{"atb":[[2.16,6.42]],"id":39979879}],"con":true,"img":false}]}
{"op":"mcm","clk":"5346778213","pt":1646096744053,"mc":[{"id":"1.195395452","rc":[{"atb":[[2.58,5.65]],"id":36899924}],"con":true,"img":false}]}
{"op":"mcm","clk":"5346778218","pt":1646096744155,"mc":[{"id":"1.195395452","rc":[{"atb":[[2.5,0]],"id":36899924}],"con":true,"img":false}]}
{"op":"mcm","clk":"5346778243","pt":1646096744874,"mc":[{"id":"1.195395452","rc":[{"atb":[[2.18,54.58]],"id":39979879}],"con":true,"img":false}]}
{"op":"mcm","clk":"5346778246","pt":1646096744978,"mc":[{"id":"1.195395452","rc":[{"atb":[[2.12,0]],"id":39979879}],"con":true,"img":false}]}
{"op":"mcm","clk":"5346778304","pt":1646096747082,"mc":[{"id":"1.195395452","rc":[{"atb":[[2.56,0]],"id":36899924},{"atb":[[2.16,0]],"id":39979879}],"con":true,"img":false}]}
{"op":"mcm","clk":"5346778364","pt":1646096749189,"mc":[{"id":"1.195395452","rc":[{"atb":[[2.5,14.71],[2.58,0]],"id":36899924}],"con":true,"img":false}]}
{"op":"mcm","clk":"5346778395","pt":1646096749960,"mc":[{"id":"1.195395452","rc":[{"atb":[[2.12,89.29]],"id":39979879}],"con":true,"img":false}]}
{"op":"mcm","clk":"5346778400","pt":1646096750063,"mc":[{"id":"1.195395452","rc":[{"atb":[[2.18,0]],"id":39979879}],"con":true,"img":false}]}
{"op":"mcm","clk":"5346778424","pt":1646096750880,"mc":[{"id":"1.195395452","rc":[{"atb":[[1.71,246.48]],"id":41921674}],"con":true,"img":false}]}
{"op":"mcm","clk":"5346778426","pt":1646096750983,"mc":[{"id":"1.195395452","rc":[{"atb":[[1.71,176.06]],"id":41921674}],"con":true,"img":false}]}
{"op":"mcm","clk":"5346778448","pt":1646096751551,"mc":[{"id":"1.195395452","rc":[{"atb":[[1.78,25.64],[1.77,0]],"id":41921674}],"con":true,"img":false}]}
{"op":"mcm","clk":"5346778492","pt":1646096752982,"mc":[{"id":"1.195395452","rc":[{"atb":[[2.46,5.1]],"id":36899924}],"con":true,"img":false}]}
{"op":"mcm","clk":"5346778525","pt":1646096754162,"mc":[{"id":"1.195395452","rc":[{"atb":[[2.48,0]],"id":36899924}],"con":true,"img":false}]}
{"op":"mcm","clk":"5346778528","pt":1646096754263,"mc":[{"id":"1.195395452","rc":[{"atb":[[2.5,0],[2.48,29.42]],"id":36899924}],"con":true,"img":false}]}
{"op":"mcm","clk":"5346778580","pt":1646096755958,"mc":[{"id":"1.195395452","rc":[{"atb":[[2.16,6.42]],"id":39979879}],"con":true,"img":false}]}
{"op":"mcm","clk":"5346778584","pt":1646096756061,"mc":[{"id":"1.195395452","rc":[{"atb":[[2.46,0]],"id":36899924}],"con":true,"img":false}]}
{"op":"mcm","clk":"5346778588","pt":1646096756163,"mc":[{"id":"1.195395452","rc":[{"atb":[[2.42,58.84],[2.48,0]],"id":36899924}],"con":true,"img":false}]}
{"op":"mcm","clk":"5346778594","pt":1646096756469,"mc":[{"id":"1.195395452","rc":[{"atb":[[1.78,0],[1.77,25.97]],"id":41921674}],"con":true,"img":false}]}
{"op":"mcm","clk":"5346778622","pt":1646096757556,"mc":[{"id":"1.195395452","rc":[{"atb":[[2.12,0],[2.18,54.58]],"id":39979879}],"con":true,"img":false}]}
{"op":"mcm","clk":"5346778674","pt":1646096759296,"mc":[{"id":"1.195395452","rc":[{"atb":[[2.16,0]],"id":39979879}],"con":true,"img":false}]}
{"op":"mcm","clk":"5346778713","pt":1646096760376,"mc":[{"id":"1.195395452","rc":[{"atb":[[1.74,0]],"id":41921674},{"atl":[[5,0]],"id":39979879},{"atb":[[2.62,0]],"id":43154431}],"con":true,"img":false}]}
{"op":"mcm","clk":"5346778718","pt":1646096760477,"mc":[{"id":"1.195395452","rc":[{"atb":[[1.76,56.3]],"id":41921674},{"atl":[[5.2,7.51]],"id":39979879},{"atb":[[2.58,27.04]],"id":43154431}],"con":true,"img":false}]}
{"op":"mcm","clk":"5346778723","pt":1646096760579,"mc":[{"id":"1.195395452","rc":[{"atl":[[5.1,42.68],[4.9,12.82]],"id":39979879}],"con":true,"img":false}]}
{"op":"mcm","clk":"5346778770","pt":1646096762176,"mc":[{"id":"1.195395452","rc":[{"atb":[[2.68,0]],"id":43154431}],"con":true,"img":false}]}
{"op":"mcm","clk":"5346778791","pt":1646096762687,"mc":[{"id":"1.195395452","rc":[{"atb":[[2.12,89.29]],"id":39979879}],"con":true,"img":false}]}
{"op":"mcm","clk":"5346778796","pt":1646096762788,"mc":[{"id":"1.195395452","rc":[{"atb":[[2.18,0]],"id":39979879}],"con":true,"img":false}]}
{"op":"mcm","clk":"5346778814","pt":1646096763356,"mc":[{"id":"1.195395452","rc":[{"atb":[[1.78,25.64],[1.77,0]],"id":41921674}],"con":true,"img":false}]}
{"op":"mcm","clk":"5346778865","pt":1646096765301,"mc":[{"id":"1.195395452","rc":[{"atb":[[2.48,5.03]],"id":36899924}],"con":true,"img":false}]}
{"op":"mcm","clk":"5346778932","pt":1646096768281,"mc":[{"id":"1.195395452","rc":[{"atb":[[2.66,9.51]],"id":43154431}],"con":true,"img":false}]}
{"op":"mcm","clk":"5346778941","pt":1646096768692,"mc":[{"id":"1.195395452","rc":[{"atb":[[1.78,0],[1.77,25.97]],"id":41921674}],"con":true,"img":false}]}
{"op":"mcm","clk":"5346778944","pt":1646096768794,"mc":[{"id":"1.195395452","rc":[{"atb":[[2.5,42.88],[2.42,0]],"id":36899924}],"con":true,"img":false}]}
{"op":"mcm","clk":"5346779016","pt":1646096771310,"mc":[{"id":"1.195395452","rc":[{"atb":[[2.48,0]],"id":36899924},{"atb":[[2.16,6.42]],"id":39979879}],"con":true,"img":false}]}
{"op":"mcm","clk":"5346779021","pt":1646096771412,"mc":[{"id":"1.195395452","rc":[{"atb":[[2.42,70.42]],"id":36899924}],"con":true,"img":false}]}
{"op":"mcm","clk":"5346779024","pt":1646096771514,"mc":[{"id":"1.195395452","rc":[{"atb":[[2.5,0]],"id":36899924}],"con":true,"img":false}]}
{"op":"mcm","clk":"5346779050","pt":1646096772489,"mc":[{"id":"1.195395452","rc":[{"atb":[[2.48,5.64]],"id":36899924}],"con":true,"img":false}]}
{"op":"mcm","clk":"5346779054","pt":1646096772591,"mc":[{"id":"1.195395452","rc":[{"atb":[[2.5,42.88],[2.42,0]],"id":36899924}],"con":true,"img":false}]}
{"op":"mcm","clk":"5346779128","pt":1646096775205,"mc":[{"id":"1.195395452","rc":[{"atb":[[2.12,0],[2.18,54.58]],"id":39979879}],"con":true,"img":false}]}
{"op":"mcm","clk":"5346779147","pt":1646096775716,"mc":[{"id":"1.195395452","rc":[{"atb":[[1.78,25.64],[1.77,0]],"id":41921674}],"con":true,"img":false}]}
{"op":"mcm","clk":"5346779194","pt":1646096777207,"mc":[{"id":"1.195395452","rc":[{"atb":[[2.56,4.77]],"id":36899924},{"atb":[[2.16,0]],"id":39979879}],"con":true,"img":false}]}
{"op":"mcm","clk":"5346779279","pt":1646096780230,"mc":[{"id":"1.195395452","rc":[{"atb":[[1.78,0],[1.77,25.97]],"id":41921674},{"atl":[[5.1,4.88],[5.2,0]],"id":36899924}],"con":true,"img":false}]}
{"op":"mcm","clk":"5346779284","pt":1646096780435,"mc":[{"id":"1.195395452","rc":[{"atb":[[2.12,89.29],[2.18,0]],"id":39979879},{"atl":[[5.2,0]],"id":39979879}],"con":true,"img":false}]}
{"op":"mcm","clk":"5346779288","pt":1646096780537,"mc":[{"id":"1.195395452","rc":[{"atl":[[5,7.51]],"id":39979879}],"con":true,"img":false}]}
{"op":"mcm","clk":"5346779297","pt":1646096780745,"mc":[{"id":"1.195395452","rc":[{"atl":[[5.1,18.29],[4.9,25.64]],"id":39979879}],"con":true,"img":false}]}
{"op":"mcm","clk":"5346779399","pt":1646096785007,"mc":[{"id":"1.195395452","rc":[{"atb":[[2.58,5.65]],"id":36899924}],"con":true,"img":false}]}
{"op":"mcm","clk":"5346779402","pt":1646096785110,"mc":[{"id":"1.195395452","rc":[{"atb":[[2.5,0]],"id":36899924}],"con":true,"img":false}]}
{"op":"mcm","clk":"5346779445","pt":1646096786444,"mc":[{"id":"1.195395452","rc":[{"atb":[[2.56,0]],"id":36899924}],"con":true,"img":false}]}
{"op":"mcm","clk":"5346779451","pt":1646096786648,"mc":[{"id":"1.195395452","rc":[{"atb":[[2.5,14.71]],"id":36899924}],"con":true,"img":false}]}
{"op":"mcm","clk":"5346779455","pt":1646096786701,"mc":[{"id":"1.195395452","rc":[{"atb":[[2.58,0]],"id":36899924}],"con":true,"img":false}]}
{"op":"mcm","clk":"5346779489","pt":1646096788035,"mc":[{"id":"1.195395452","rc":[{"atb":[[1.78,25.64],[1.77,0]],"id":41921674}],"con":true,"img":false}]}
{"op":"mcm","clk":"5346779506","pt":1646096788549,"mc":[{"id":"1.195395452","rc":[{"atb":[[1.78,0],[1.77,25.97]],"id":41921674}],"con":true,"img":false}]}
{"op":"mcm","clk":"5346779530","pt":1646096789318,"mc":[{"id":"1.195395452","rc":[{"atb":[[2.16,6.42]],"id":39979879}],"con":true,"img":false}]}
{"op":"mcm","clk":"5346779546","pt":1646096790238,"mc":[{"id":"1.195395452","rc":[{"atl":[[5.3,11.63]],"id":36899924}],"con":true,"img":false}]}
{"op":"mcm","clk":"5346779548","pt":1646096790444,"mc":[{"id":"1.195395452","rc":[{"atb":[[2.48,0]],"id":36899924},{"atb":[[2.58,0]],"id":43154431}],"con":true,"img":false}]}
{"op":"mcm","clk":"5346779551","pt":1646096790547,"mc":[{"id":"1.195395452","rc":[{"atb":[[2.42,42.88]],"id":36899924},{"atb":[[2.62,27.04]],"id":43154431}],"con":true,"img":false}]}
{"op":"mcm","clk":"5346779555","pt":1646096790648,"mc":[{"id":"1.195395452","rc":[{"atb":[[2.5,0]],"id":36899924}],"con":true,"img":false}]}
{"op":"mcm","clk":"5346779594","pt":1646096792449,"mc":[{"id":"1.195395452","rc":[{"atb":[[2.66,5.02]],"id":43154431}],"con":true,"img":false}]}
{"op":"mcm","clk":"5346779596","pt":1646096792551,"mc":[{"id":"1.195395452","rc":[{"atl":[[5.9,0]],"id":36899924}],"con":true,"img":false}]}
{"op":"mcm","clk":"5346779603","pt":1646096792757,"mc":[{"id":"1.195395452","rc":[{"atb":[[2.12,0],[2.18,54.58]],"id":39979879}],"con":true,"img":false}]}
{"op":"mcm","clk":"5346779672","pt":1646096795630,"mc":[{"id":"1.195395452","rc":[{"atb":[[2.16,0]],"id":39979879}],"con":true,"img":false}]}
{"op":"mcm","clk":"5346779717","pt":1646096797837,"mc":[{"id":"1.195395452","rc":[{"atb":[[2.12,89.29]],"id":39979879}],"con":true,"img":false}]}
{"op":"mcm","clk":"5346779720","pt":1646096797939,"mc":[{"id":"1.195395452","rc":[{"atb":[[2.18,0]],"id":39979879}],"con":true,"img":false}]}
{"op":"mcm","clk":"5346779730","pt":1646096798349,"mc":[{"id":"1.195395452","rc":[{"atb":[[2.48,5.03]],"id":36899924},{"atb":[[2.68,4.43]],"id":43154431}],"con":true,"img":false}]}
{"op":"mcm","clk":"5346779766","pt":1646096799740,"mc":[{"id":"1.195395452","rc":[{"atb":[[1.78,25.64],[1.77,0]],"id":41921674}],"con":true,"img":false}]}
{"op":"mcm","clk":"5346779776","pt":1646096800253,"mc":[{"id":"1.195395452","rc":[{"atl":[[5.5,16.67]],"id":36899924}],"con":true,"img":false}]}
{"op":"mcm","clk":"5346779778","pt":1646096800457,"mc":[{"id":"1.195395452","rc":[{"atl":[[5.8,2.5]],"id":36899924},{"atl":[[5,0]],"id":39979879}],"con":true,"img":false}]}
{"op":"mcm","clk":"5346779781","pt":1646096800560,"mc":[{"id":"1.195395452","rc":[{"atl":[[7.2,8.63]],"id":36899924},{"atl":[[5.1,42.68],[5.2,7.51]],"id":39979879}],"con":true,"img":false}]}
{"op":"mcm","clk":"5346779785","pt":1646096800662,"mc":[{"id":"1.195395452","rc":[{"atl":[[4.9,12.82]],"id":39979879}],"con":true,"img":false}]}
{"op":"mcm","clk":"5346779833","pt":1646096802769,"mc":[{"id":"1.195395452","rc":[{"atb":[[2.5,42.88],[2.42,0]],"id":36899924}],"con":true,"img":false}]}
{"op":"mcm","clk":"5346779865","pt":1646096804358,"mc":[{"id":"1.195395452","rc":[{"atb":[[2.16,6.42]],"id":39979879}],"con":true,"img":false}]}
{"op":"mcm","clk":"5346779868","pt":1646096804461,"mc":[{"id":"1.195395452","rc":[{"atb":[[2.48,0]],"id":36899924}],"con":true,"img":false}]}
{"op":"mcm","clk":"5346779870","pt":1646096804564,"mc":[{"id":"1.195395452","rc":[{"atb":[[2.5,0],[2.42,70.42]],"id":36899924}],"con":true,"img":false}]}
{"op":"mcm","clk":"5346779873","pt":1646096804667,"mc":[{"id":"1.195395452","rc":[{"atb":[[1.78,0],[1.77,25.97]],"id":41921674}],"con":true,"img":false}]}
{"op":"mcm","clk":"5346779975","pt":1646096809073,"mc":[{"id":"1.195395452","rc":[{"atb":[[2.48,5.64]],"id":36899924}],"con":true,"img":false}]}
{"op":"mcm","clk":"5346779996","pt":1646096809949,"mc":[{"id":"1.195395452","rc":[{"atb":[[2.18,54.58]],"id":39979879}],"con":true,"img":false}]}
{"op":"mcm","clk":"5346780003","pt":1646096810151,"mc":[{"id":"1.195395452","rc":[{"atb":[[2.12,0]],"id":39979879}],"con":true,"img":false}]}
{"op":"mcm","clk":"5346780005","pt":1646096810253,"mc":[{"id":"1.195395452","rc":[{"atl":[[5.7,26.6]],"id":36899924}],"con":true,"img":false}]}
{"op":"mcm","clk":"5346780008","pt":1646096810355,"mc":[{"id":"1.195395452","rc":[{"atb":[[1.76,0]],"id":41921674},{"atb":[[2.16,0]],"id":39979879},{"atl":[[11,4.32],[9.4,0]],"id":39722911},{"atl":[[11.5,3.78],[9.4,0]],"id":43154431},{"atl":[[9,0]],"id":27151693}],"con":true,"img":false}]}
{"op":"mcm","clk":"5346780010","pt":1646096810458,"mc":[{"id":"1.195395452","rc":[{"atb":[[1.72,56.3]],"id":41921674},{"atb":[[2.12,89.29],[2.18,0]],"id":39979879},{"atl":[[11.5,4.26]],"id":27151693}],"con":true,"img":false}]}
{"op":"mcm","clk":"5346780042","pt":1646096812045,"mc":[{"id":"1.195395452","rc":[{"atb":[[1.78,25.64],[1.77,0]],"id":41921674}],"con":true,"img":false}]}
{"op":"mcm","clk":"5346780064","pt":1646096813275,"mc":[{"id":"1.195395452","rc":[{"atb":[[2.48,10.68]],"id":36899924}],"con":true,"img":false}]}
{"op":"mcm","clk":"5346780088","pt":1646096814452,"mc":[{"id":"1.195395452","rc":[{"atb":[[2.16,7.2]],"id":39979879}],"con":true,"img":false}]}
{"op":"mcm","clk":"5346780090","pt":1646096814557,"mc":[{"id":"1.195395452","rc":[{"atb":[[2.12,0],[2.18,54.58]],"id":39979879}],"con":true,"img":false}]}
{"op":"mcm","clk":"5346780147","pt":1646096816665,"mc":[{"id":"1.195395452","rc":[{"atb":[[1.78,0],[1.77,25.97]],"id":41921674},{"atb":[[2.5,42.88],[2.42,0]],"id":36899924}],"con":true,"img":false}]}
{"op":"mcm","clk":"5346780212","pt":1646096819383,"mc":[{"id":"1.195395452","rc":[{"atb":[[2.48,5.64]],"id":36899924}],"con":true,"img":false}]}
{"op":"mcm","clk":"5346780230","pt":1646096820361,"mc":[{"id":"1.195395452","rc":[{"atl":[[4.7,0]],"id":41921674}],"con":true,"img":false}]}
{"op":"mcm","clk":"5346780234","pt":1646096820463,"mc":[{"id":"1.195395452","rc":[{"atl":[[4.6,9.22]],"id":41921674}],"con":true,"img":false}]}
{"op":"mcm","clk":"5346780308","pt":1646096822416,"mc":[{"id":"1.195395452","rc":[{"atb":[[2.24,6]],"id":39979879}],"con":true,"img":false}]}
{"op":"mcm","clk":"5346780372","pt":1646096824312,"mc":[{"id":"1.195395452","rc":[{"atb":[[1.78,25.64],[1.77,0]],"id":41921674}],"con":true,"img":false}]}
{"op":"mcm","clk":"5346780411","pt":1646096825394,"mc":[{"id":"1.195395452","rc":[{"atb":[[2.56,4.77]],"id":36899924}],"con":true,"img":false}]}
{"op":"mcm","clk":"5346780414","pt":1646096825496,"mc":[{"id":"1.195395452","rc":[{"atb":[[2.58,5.65]],"id":36899924}],"con":true,"img":false}]}
{"op":"mcm","clk":"5346780419","pt":1646096825601,"mc":[{"id":"1.195395452","rc":[{"atb":[[2.5,0]],"id":36899924}],"con":true,"img":false}]}
{"op":"mcm","clk":"5346780450","pt":1646096826570,"mc":[{"id":"1.195395452","rc":[{"atb":[[2.18,0],[2.26,7.2]],"id":39979879}],"con":true,"img":false}]}
{"op":"mcm","clk":"5346780510","pt":1646096828520,"mc":[{"id":"1.195395452","rc":[{"atb":[[2.56,0]],"id":36899924},{"atb":[[2.24,0]],"id":39979879}],"con":true,"img":false}]}
{"op":"mcm","clk":"5346780522","pt":1646096828726,"mc":[{"id":"1.195395452","rc":[{"atb":[[1.78,0],[1.77,25.97]],"id":41921674},{"atb":[[2.5,14.71],[2.58,0]],"id":36899924},{"atb":[[2.18,18.87],[2.26,0]],"id":39979879}],"con":true,"img":false}]}
{"op":"mcm","clk":"5346780576","pt":1646096830421,"mc":[{"id":"1.195395452","rc":[{"atl":[[1.69,0]],"id":42492389}],"con":true,"img":false}]}
{"op":"mcm","clk":"5346780578","pt":1646096830523,"mc":[{"id":"1.195395452","rc":[{"atl":[[1.35,40.56]],"id":42492389}],"con":true,"img":false}]}
{"op":"mcm","clk":"5346780587","pt":1646096830732,"mc":[{"id":"1.195395452","rc":[{"atl":[[1.36,208.33],[1.34,294.12]],"id":42492389}],"con":true,"img":false}]}
{"op":"mcm","clk":"5346780641","pt":1646096832318,"mc":[{"id":"1.195395452","rc":[{"atb":[[2.48,0]],"id":36899924},{"atb":[[2.16,0]],"id":39979879}],"con":true,"img":false}]}
{"op":"mcm","clk":"5346780644","pt":1646096832423,"mc":[{"id":"1.195395452","rc":[{"atb":[[2.5,0],[2.42,42.88]],"id":36899924},{"atb":[[2.12,54.58]],"id":39979879}],"con":true,"img":false}]}
{"op":"mcm","clk":"5346780647","pt":1646096832525,"mc":[{"id":"1.195395452","rc":[{"atb":[[2.18,0]],"id":39979879}],"con":true,"img":false}]}
{"op":"mcm","clk":"5346780806","pt":1646096836734,"mc":[{"id":"1.195395452","rc":[{"atb":[[1.78,25.64],[1.77,0]],"id":41921674}],"con":true,"img":false}]}
{"op":"mcm","clk":"5346780921","pt":1646096840433,"mc":[{"id":"1.195395452","rc":[{"atb":[[2.62,0]],"id":43154431}],"con":true,"img":false}]}
{"op":"mcm","clk":"5346780924","pt":1646096840536,"mc":[{"id":"1.195395452","rc":[{"atb":[[2.58,27.04]],"id":43154431}],"con":true,"img":false}]}
{"op":"mcm","clk":"5346780928","pt":1646096840640,"mc":[{"id":"1.195395452","rc":[{"atb":[[1.78,0],[1.77,25.97]],"id":41921674}],"con":true,"img":false}]}
{"op":"mcm","clk":"5346780944","pt":1646096841103,"mc":[{"id":"1.195395452","rc":[{"atb":[[2.48,5.03]],"id":36899924},{"atb":[[2.16,6.42]],"id":39979879},{"atb":[[2.68,0]],"id":43154431}],"con":true,"img":false}]}
{"op":"mcm","clk":"5346781032","pt":1646096844244,"mc":[{"id":"1.195395452","rc":[{"atb":[[2.5,42.88],[2.42,0]],"id":36899924},{"atb":[[2.12,0],[2.18,54.58]],"id":39979879}],"con":true,"img":false}]}
{"op":"mcm","clk":"5346781058","pt":1646096844915,"mc":[{"id":"1.195395452","rc":[{"atb":[[2.48,0]],"id":36899924},{"atb":[[2.16,0]],"id":39979879}],"con":true,"img":false}]}
{"op":"mcm","clk":"5346781063","pt":1646096845019,"mc":[{"id":"1.195395452","rc":[{"atb":[[2.5,0],[2.42,70.42]],"id":36899924},{"atb":[[2.12,89.29],[2.18,0]],"id":39979879}],"con":true,"img":false}]}
{"op":"mcm","clk":"5346781132","pt":1646096846918,"mc":[{"id":"1.195395452","rc":[{"atb":[[2.66,9.51]],"id":43154431}],"con":true,"img":false}]}
{"op":"mcm","clk":"5346781188","pt":1646096848814,"mc":[{"id":"1.195395452","rc":[{"atb":[[1.78,25.64],[1.77,0]],"id":41921674}],"con":true,"img":false}]}
{"op":"mcm","clk":"5346781227","pt":1646096850252,"mc":[{"id":"1.195395452","rc":[{"atb":[[2.16,7.2]],"id":39979879}],"con":true,"img":false}]}
{"op":"mcm","clk":"5346781230","pt":1646096850355,"mc":[{"id":"1.195395452","rc":[{"atb":[[1.89,0],[2.22,35.69]],"id":39722911},{"atl":[[1.73,51.37],[2.18,0]],"id":42492389}],"con":true,"img":false}]}
{"op":"mcm","clk":"5346781241","pt":1646096850663,"mc":[{"id":"1.195395452","rc":[{"atb":[[2.48,5.64]],"id":36899924}],"con":true,"img":false}]}
{"op":"mcm","clk":"5346781297","pt":1646096852721,"mc":[{"id":"1.195395452","rc":[{"atb":[[1.78,0],[1.77,25.97]],"id":41921674}],"con":true,"img":false}]}
{"op":"mcm","clk":"5346781299","pt":1646096852828,"mc":[{"id":"1.195395452","rc":[{"atb":[[2.48,10.68]],"id":36899924},{"atb":[[2.16,13.62]],"id":39979879}],"con":true,"img":false}]}
{"op":"mcm","clk":"5346781423","pt":1646096856732,"mc":[{"id":"1.195395452","rc":[{"atb":[[2.5,42.88],[2.42,0]],"id":36899924},{"atb":[[2.12,0],[2.18,54.58]],"id":39979879}],"con":true,"img":false}]}
{"op":"mcm","clk":"5346781496","pt":1646096859038,"mc":[{"id":"1.195395452","rc":[{"atb":[[2.48,5.64]],"id":36899924},{"atb":[[2.16,7.2]],"id":39979879}],"con":true,"img":false}]}
{"op":"mcm","clk":"5346781546","pt":1646096860678,"mc":[{"id":"1.195395452","rc":[{"atb":[[1.78,25.64],[1.77,0]],"id":41921674}],"con":true,"img":false}]}
