{"op":"mcm","clk":"5352092077","pt":1646182318991,"mc":[{"id":"1.195503869","marketDefinition":{"bspMarket":false,"turnInPlayEnabled":false,"persistenceEnabled":false,"marketBaseRate":7.0,"eventId":"31272499","eventTypeId":"4339","numberOfWinners":1,"bettingType":"ODDS","marketType":"EXACTA","marketTime":"2022-03-02T11:39:00.000Z","suspendTime":"2022-03-02T11:39:00.000Z","bspReconciled":false,"complete":true,"inPlay":false,"crossMatching":false,"runnersVoidable":false,"numberOfActiveRunners":56,"betDelay":0,"status":"OPEN","runners":[{"status":"ACTIVE","sortPriority":1,"id":41419585,"name":"1 - 2"},{"status":"ACTIVE","sortPriority":2,"id":41419586,"name":"1 - 3"},{"status":"ACTIVE","sortPriority":3,"id":41419587,"name":"1 - 4"},{"status":"ACTIVE","sortPriority":4,"id":41419588,"name":"1 - 5"},{"status":"ACTIVE","sortPriority":5,"id":41419589,"name":"1 - 6"},{"status":"ACTIVE","sortPriority":6,"id":41419591,"name":"1 - 8"},{"status":"ACTIVE","sortPriority":7,"id":28546943,"name":"1 - 9"},{"status":"ACTIVE","sortPriority":8,"id":41419592,"name":"2 - 1"},{"status":"ACTIVE","sortPriority":9,"id":41419593,"name":"2 - 3"},{"status":"ACTIVE","sortPriority":10,"id":41419594,"name":"2 - 4"},{"status":"ACTIVE","sortPriority":11,"id":41419595,"name":"2 - 5"},{"status":"ACTIVE","sortPriority":12,"id":41419596,"name":"2 - 6"},{"status":"ACTIVE","sortPriority":13,"id":41419598,"name":"2 - 8"},{"status":"ACTIVE","sortPriority":14,"id":41419651,"name":"2 - 9"},{"status":"ACTIVE","sortPriority":15,"id":41419599,"name":"3 - 1"},{"status":"ACTIVE","sortPriority":16,"id":41419600,"name":"3 - 2"},{"status":"ACTIVE","sortPriority":17,"id":41419601,"name":"3 - 4"},{"status":"ACTIVE","sortPriority":18,"id":41419602,"name":"3 - 5"},{"status":"ACTIVE","sortPriority":19,"id":41419603,"name":"3 - 6"},{"status":"ACTIVE","sortPriority":20,"id":41419605,"name":"3 - 8"},{"status":"ACTIVE","sortPriority":21,"id":41419652,"name":"3 - 9"},{"status":"ACTIVE","sortPriority":22,"id":41419606,"name":"4 - 1"},{"status":"ACTIVE","sortPriority":23,"id":41419607,"name":"4 - 2"},{"status":"ACTIVE","sortPriority":24,"id":41419608,"name":"4 - 3"},{"status":"ACTIVE","sortPriority":25,"id":41419609,"name":"4 - 5"},{"status":"ACTIVE","sortPriority":26,"id":41419610,"name":"4 - 6"},{"status":"ACTIVE","sortPriority":27,"id":41419612,"name":"4 - 8"},{"status":"ACTIVE","sortPriority":28,"id":41435525,"name":"4 - 9"},{"status":"ACTIVE","sortPriority":29,"id":41419613,"name":"5 - 1"},{"status":"ACTIVE","sortPriority":30,"id":41419614,"name":"5 - 2"},{"status":"ACTIVE","sortPriority":31,"id":41419615,"name":"5 - 3"},{"status":"ACTIVE","sortPriority":32,"id":41419616,"name":"5 - 4"},{"status":"ACTIVE","sortPriority":33,"id":41419617,"name":"5 - 6"},{"status":"ACTIVE","sortPriority":34,"id":41419619,"name":"5 - 8"},{"status":"ACTIVE","sortPriority":35,"id":41419653,"name":"5 - 9"},{"status":"ACTIVE","sortPriority":36,"id":41419620,"name":"6 - 1"},{"status":"ACTIVE","sortPriority":37,"id":41419621,"name":"6 - 2"},{"status":"ACTIVE","sortPriority":38,"id":41419622,"name":"6 - 3"},{"status":"ACTIVE","sortPriority":39,"id":41419623,"name":"6 - 4"},{"status":"ACTIVE","sortPriority":40,"id":41419624,"name":"6 - 5"},{"status":"ACTIVE","sortPriority":41,"id":41419626,"name":"6 - 8"},{"status":"ACTIVE","sortPriority":42,"id":41435526,"name":"6 - 9"},{"status":"ACTIVE","sortPriority":43,"id":41419634,"name":"8 - 1"},{"status":"ACTIVE","sortPriority":44,"id":41419635,"name":"8 - 2"},{"status":"ACTIVE","sortPriority":45,"id":41419636,"name":"8 - 3"},{"status":"ACTIVE","sortPriority":46,"id":41419637,"name":"8 - 4"},{"status":"ACTIVE","sortPriority":47,"id":41419638,"name":"8 - 5"},{"status":"ACTIVE","sortPriority":48,"id":41419639,"name":"8 - 6"},{"status":"ACTIVE","sortPriority":49,"id":41419655,"name":"8 - 9"},{"status":"ACTIVE","sortPriority":50,"id":28546950,"name":"9 - 1"},{"status":"ACTIVE","sortPriority":51,"id":41419656,"name":"9 - 2"},{"status":"ACTIVE","sortPriority":52,"id":41419657,"name":"9 - 3"},{"status":"ACTIVE","sortPriority":53,"id":41435527,"name":"9 - 4"},{"status":"ACTIVE","sortPriority":54,"id":41419658,"name":"9 - 5"},{"status":"ACTIVE","sortPriority":55,"id":41435528,"name":"9 - 6"},{"status":"ACTIVE","sortPriority":56,"id":41419660,"name":"9 - 8"}],"regulators":["MR_INT"],"venue":"Rockhampton","countryCode":"AU","discountAllowed":true,"timezone":"Australia/Queensland","openDate":"2022-03-02T08:34:00.000Z","version":4382565138,"name":"Exacta","eventName":"Rockhampton (AUS) 2nd Mar"},"rc":[],"con":true,"img":false}]}
{"op":"mcm","clk":"5352095665","pt":1646182412891,"mc":[{"id":"1.195503869","rc":[{"atb":[[17.5,16.12],[50,4.07],[25,8.31]],"id":41419609},{"atb":[[17.5,16.12],[50,4.07],[25,8.31]],"id":41419607},{"atb":[[10.5,28.01],[26,7.98],[15.5,13.76]],"id":41419605},{"atb":[[16,17.74],[44,4.64],[22,9.5]],"id":41419603},{"atb":[[75,2.69],[20,14],[30,6.88]],"id":41419593},{"atb":[[3.95,90.2],[6.8,34.41],[4.9,51.17]],"id":41419591},{"atb":[[34,8.06],[170,1.18],[60,3.38]],"id":41435525},{"atb":[[8.6,26.26],[14,15.35],[6.6,47.52]],"id":41419589},{"atb":[[600,0.44],[700,0.28],[850,0.23]],"id":41419651},{"atb":[[3.7,98.56],[4.4,58.69],[5.9,40.73]],"id":41419587},{"atb":[[24,8.67],[9.8,30.24],[14.5,14.78]],"id":41419601},{"atb":[[9.6,23.2],[5.3,61.88],[6.6,35.63]],"id":41419599},{"atb":[[17.5,12.09],[12.5,23.13],[30,6.88]],"id":28546943},{"atb":[[310,0.64],[210,1.27],[460,0.43]],"id":41419595},{"atb":[[9.6,30.94],[23,9.07],[14,15.35]],"id":41419608},{"atb":[[5.7,42.46],[8.4,26.97],[4.7,71.92]],"id":41419606},{"atb":[[65,3.11],[19,14.78],[28,7.39]],"id":41419602},{"atb":[[18.5,11.4],[11,19.95],[8.4,35.95]],"id":41419585},{"atb":[[9.2,32.45],[21,9.97],[13,16.63]],"id":41419612},{"atb":[[40,5.11],[20,10.5],[15,19]],"id":41419610},{"atb":[[16,13.3],[11,26.61],[27,7.67]],"id":41419592},{"atb":[[95,2.12],[48,5.66],[240,0.83]],"id":41419652},{"atb":[[18.5,11.4],[11,19.95],[8.4,35.95]],"id":41419588},{"atb":[[7.4,31.18],[5.2,47.52],[4.2,83.16]],"id":41419586},{"atb":[[65,3.11],[19,14.78],[28,7.39]],"id":41419600},{"atb":[[65,3.11],[19,14.78],[28,7.39]],"id":41419598},{"atb":[[270,0.74],[120,1.67],[60,4.5]],"id":41419596},{"atb":[[18.5,15.2],[27,7.67],[60,3.38]],"id":41419594}],"con":true,"img":false}]}
{"op":"mcm","clk":"5352095669","pt":1646182412947,"mc":[{"id":"1.195503869","rc":[{"atb":[[18,15.65],[26,7.98],[55,3.69]],"id":41419638},{"atb":[[9,24.94],[5,66.52],[6,39.91]],"id":41419634},{"atb":[[270,0.74],[120,1.67],[60,4.5]],"id":41419617},{"atb":[[16,13.3],[11,26.61],[27,7.67]],"id":41419613},{"atb":[[80,2.52],[42,6.48],[210,0.95]],"id":41419655},{"atb":[[16.5,17.17],[46,4.43],[23,9.07]],"id":41419622},{"atb":[[85,2.37],[44,6.19],[220,0.9]],"id":41435527},{"atb":[[16,17.74],[44,4.64],[22,9.5]],"id":41419626},{"atb":[[42,4.86],[21,9.97],[15.5,18.35]],"id":41419639},{"atb":[[18,15.65],[26,7.98],[55,3.69]],"id":41419635},{"atb":[[310,0.64],[210,1.27],[460,0.43]],"id":41419614},{"atb":[[600,0.44],[700,0.28],[850,0.23]],"id":41419656},{"atb":[[42,4.86],[21,9.97],[15.5,18.35]],"id":41419623},{"atb":[[550,0.48],[650,0.3],[800,0.25]],"id":41435528},{"atb":[[65,3.11],[19,14.78],[28,7.39]],"id":41419619},{"atb":[[100,2.01],[50,5.43],[250,0.8]],"id":41419660},{"atb":[[16.5,17.17],[46,4.43],[23,9.07]],"id":28546950},{"atb":[[10.5,28.01],[26,7.98],[15.5,13.76]],"id":41419636},{"atb":[[75,2.69],[20,14],[30,6.88]],"id":41419615},{"atb":[[140,1.43],[70,3.85],[290,0.69]],"id":41419657},{"atb":[[260,0.77],[110,1.82],[55,4.92]],"id":41419624},{"atb":[[600,0.44],[700,0.28],[850,0.23]],"id":41419653},{"atb":[[19.5,10.79],[12,18.14],[8.8,34.11]],"id":41419620},{"atb":[[9.2,32.45],[21,9.97],[13,16.63]],"id":41419637},{"atb":[[18.5,15.2],[27,7.67],[60,3.38]],"id":41419616},{"atb":[[610,0.32],[760,0.26],[510,0.52]],"id":41435526},{"atb":[[260,0.77],[110,1.82],[55,4.92]],"id":41419621},{"atb":[[600,0.44],[700,0.28],[850,0.23]],"id":41419658}],"con":true,"img":false}]}
{"op":"mcm","clk":"5352146190","pt":1646183572646,"mc":[{"id":"1.195503869","marketDefinition":{"bspMarket":false,"turnInPlayEnabled":false,"persistenceEnabled":false,"marketBaseRate":7.0,"eventId":"31272499","eventTypeId":"4339","numberOfWinners":1,"bettingType":"ODDS","marketType":"EXACTA","marketTime":"2022-03-02T11:39:00.000Z","suspendTime":"2022-03-02T11:39:00.000Z","bspReconciled":false,"complete":true,"inPlay":false,"crossMatching":false,"runnersVoidable":false,"numberOfActiveRunners":56,"betDelay":0,"status":"OPEN","runners":[{"status":"ACTIVE","sortPriority":1,"id":41419585,"name":"1 - 2"},{"status":"ACTIVE","sortPriority":2,"id":41419586,"name":"1 - 3"},{"status":"ACTIVE","sortPriority":3,"id":41419587,"name":"1 - 4"},{"status":"ACTIVE","sortPriority":4,"id":41419588,"name":"1 - 5"},{"status":"ACTIVE","sortPriority":5,"id":41419589,"name":"1 - 6"},{"status":"ACTIVE","sortPriority":6,"id":41419591,"name":"1 - 8"},{"status":"ACTIVE","sortPriority":7,"id":28546943,"name":"1 - 9"},{"status":"ACTIVE","sortPriority":8,"id":41419592,"name":"2 - 1"},{"status":"ACTIVE","sortPriority":9,"id":41419593,"name":"2 - 3"},{"status":"ACTIVE","sortPriority":10,"id":41419594,"name":"2 - 4"},{"status":"ACTIVE","sortPriority":11,"id":41419595,"name":"2 - 5"},{"status":"ACTIVE","sortPriority":12,"id":41419596,"name":"2 - 6"},{"status":"ACTIVE","sortPriority":13,"id":41419598,"name":"2 - 8"},{"status":"ACTIVE","sortPriority":14,"id":41419651,"name":"2 - 9"},{"status":"ACTIVE","sortPriority":15,"id":41419599,"name":"3 - 1"},{"status":"ACTIVE","sortPriority":16,"id":41419600,"name":"3 - 2"},{"status":"ACTIVE","sortPriority":17,"id":41419601,"name":"3 - 4"},{"status":"ACTIVE","sortPriority":18,"id":41419602,"name":"3 - 5"},{"status":"ACTIVE","sortPriority":19,"id":41419603,"name":"3 - 6"},{"status":"ACTIVE","sortPriority":20,"id":41419605,"name":"3 - 8"},{"status":"ACTIVE","sortPriority":21,"id":41419652,"name":"3 - 9"},{"status":"ACTIVE","sortPriority":22,"id":41419606,"name":"4 - 1"},{"status":"ACTIVE","sortPriority":23,"id":41419607,"name":"4 - 2"},{"status":"ACTIVE","sortPriority":24,"id":41419608,"name":"4 - 3"},{"status":"ACTIVE","sortPriority":25,"id":41419609,"name":"4 - 5"},{"status":"ACTIVE","sortPriority":26,"id":41419610,"name":"4 - 6"},{"status":"ACTIVE","sortPriority":27,"id":41419612,"name":"4 - 8"},{"status":"ACTIVE","sortPriority":28,"id":41435525,"name":"4 - 9"},{"status":"ACTIVE","sortPriority":29,"id":41419613,"name":"5 - 1"},{"status":"ACTIVE","sortPriority":30,"id":41419614,"name":"5 - 2"},{"status":"ACTIVE","sortPriority":31,"id":41419615,"name":"5 - 3"},{"status":"ACTIVE","sortPriority":32,"id":41419616,"name":"5 - 4"},{"status":"ACTIVE","sortPriority":33,"id":41419617,"name":"5 - 6"},{"status":"ACTIVE","sortPriority":34,"id":41419619,"name":"5 - 8"},{"status":"ACTIVE","sortPriority":35,"id":41419653,"name":"5 - 9"},{"status":"ACTIVE","sortPriority":36,"id":41419620,"name":"6 - 1"},{"status":"ACTIVE","sortPriority":37,"id":41419621,"name":"6 - 2"},{"status":"ACTIVE","sortPriority":38,"id":41419622,"name":"6 - 3"},{"status":"ACTIVE","sortPriority":39,"id":41419623,"name":"6 - 4"},{"status":"ACTIVE","sortPriority":40,"id":41419624,"name":"6 - 5"},{"status":"ACTIVE","sortPriority":41,"id":41419626,"name":"6 - 8"},{"status":"ACTIVE","sortPriority":42,"id":41435526,"name":"6 - 9"},{"status":"ACTIVE","sortPriority":43,"id":41419634,"name":"8 - 1"},{"status":"ACTIVE","sortPriority":44,"id":41419635,"name":"8 - 2"},{"status":"ACTIVE","sortPriority":45,"id":41419636,"name":"8 - 3"},{"status":"ACTIVE","sortPriority":46,"id":41419637,"name":"8 - 4"},{"status":"ACTIVE","sortPriority":47,"id":41419638,"name":"8 - 5"},{"status":"ACTIVE","sortPriority":48,"id":41419639,"name":"8 - 6"},{"status":"ACTIVE","sortPriority":49,"id":41419655,"name":"8 - 9"},{"status":"ACTIVE","sortPriority":50,"id":28546950,"name":"9 - 1"},{"status":"ACTIVE","sortPriority":51,"id":41419656,"name":"9 - 2"},{"status":"ACTIVE","sortPriority":52,"id":41419657,"name":"9 - 3"},{"status":"ACTIVE","sortPriority":53,"id":41435527,"name":"9 - 4"},{"status":"ACTIVE","sortPriority":54,"id":41419658,"name":"9 - 5"},{"status":"ACTIVE","sortPriority":55,"id":41435528,"name":"9 - 6"},{"status":"ACTIVE","sortPriority":56,"id":41419660,"name":"9 - 8"}],"regulators":["MR_INT"],"venue":"Rockhampton","countryCode":"AU","discountAllowed":true,"timezone":"Australia/Queensland","openDate":"2022-03-02T08:28:00.000Z","version":4382597906,"name":"Exacta","eventName":"Rockhampton (AUS) 2nd Mar"},"rc":[],"con":true,"img":false}]}
{"op":"mcm","clk":"5352164601","pt":1646184066706,"mc":[{"id":"1.195503869","marketDefinition":{"bspMarket":false,"turnInPlayEnabled":false,"persistenceEnabled":false,"marketBaseRate":7.0,"eventId":"31272499","eventTypeId":"4339","numberOfWinners":1,"bettingType":"ODDS","marketType":"EXACTA","marketTime":"2022-03-02T11:29:00.000Z","suspendTime":"2022-03-02T11:29:00.000Z","bspReconciled":false,"complete":true,"inPlay":false,"crossMatching":false,"runnersVoidable":false,"numberOfActiveRunners":56,"betDelay":0,"status":"OPEN","runners":[{"status":"ACTIVE","sortPriority":1,"id":41419585,"name":"1 - 2"},{"status":"ACTIVE","sortPriority":2,"id":41419586,"name":"1 - 3"},{"status":"ACTIVE","sortPriority":3,"id":41419587,"name":"1 - 4"},{"status":"ACTIVE","sortPriority":4,"id":41419588,"name":"1 - 5"},{"status":"ACTIVE","sortPriority":5,"id":41419589,"name":"1 - 6"},{"status":"ACTIVE","sortPriority":6,"id":41419591,"name":"1 - 8"},{"status":"ACTIVE","sortPriority":7,"id":28546943,"name":"1 - 9"},{"status":"ACTIVE","sortPriority":8,"id":41419592,"name":"2 - 1"},{"status":"ACTIVE","sortPriority":9,"id":41419593,"name":"2 - 3"},{"status":"ACTIVE","sortPriority":10,"id":41419594,"name":"2 - 4"},{"status":"ACTIVE","sortPriority":11,"id":41419595,"name":"2 - 5"},{"status":"ACTIVE","sortPriority":12,"id":41419596,"name":"2 - 6"},{"status":"ACTIVE","sortPriority":13,"id":41419598,"name":"2 - 8"},{"status":"ACTIVE","sortPriority":14,"id":41419651,"name":"2 - 9"},{"status":"ACTIVE","sortPriority":15,"id":41419599,"name":"3 - 1"},{"status":"ACTIVE","sortPriority":16,"id":41419600,"name":"3 - 2"},{"status":"ACTIVE","sortPriority":17,"id":41419601,"name":"3 - 4"},{"status":"ACTIVE","sortPriority":18,"id":41419602,"name":"3 - 5"},{"status":"ACTIVE","sortPriority":19,"id":41419603,"name":"3 - 6"},{"status":"ACTIVE","sortPriority":20,"id":41419605,"name":"3 - 8"},{"status":"ACTIVE","sortPriority":21,"id":41419652,"name":"3 - 9"},{"status":"ACTIVE","sortPriority":22,"id":41419606,"name":"4 - 1"},{"status":"ACTIVE","sortPriority":23,"id":41419607,"name":"4 - 2"},{"status":"ACTIVE","sortPriority":24,"id":41419608,"name":"4 - 3"},{"status":"ACTIVE","sortPriority":25,"id":41419609,"name":"4 - 5"},{"status":"ACTIVE","sortPriority":26,"id":41419610,"name":"4 - 6"},{"status":"ACTIVE","sortPriority":27,"id":41419612,"name":"4 - 8"},{"status":"ACTIVE","sortPriority":28,"id":41435525,"name":"4 - 9"},{"status":"ACTIVE","sortPriority":29,"id":41419613,"name":"5 - 1"},{"status":"ACTIVE","sortPriority":30,"id":41419614,"name":"5 - 2"},{"status":"ACTIVE","sortPriority":31,"id":41419615,"name":"5 - 3"},{"status":"ACTIVE","sortPriority":32,"id":41419616,"name":"5 - 4"},{"status":"ACTIVE","sortPriority":33,"id":41419617,"name":"5 - 6"},{"status":"ACTIVE","sortPriority":34,"id":41419619,"name":"5 - 8"},{"status":"ACTIVE","sortPriority":35,"id":41419653,"name":"5 - 9"},{"status":"ACTIVE","sortPriority":36,"id":41419620,"name":"6 - 1"},{"status":"ACTIVE","sortPriority":37,"id":41419621,"name":"6 - 2"},{"status":"ACTIVE","sortPriority":38,"id":41419622,"name":"6 - 3"},{"status":"ACTIVE","sortPriority":39,"id":41419623,"name":"6 - 4"},{"status":"ACTIVE","sortPriority":40,"id":41419624,"name":"6 - 5"},{"status":"ACTIVE","sortPriority":41,"id":41419626,"name":"6 - 8"},{"status":"ACTIVE","sortPriority":42,"id":41435526,"name":"6 - 9"},{"status":"ACTIVE","sortPriority":43,"id":41419634,"name":"8 - 1"},{"status":"ACTIVE","sortPriority":44,"id":41419635,"name":"8 - 2"},{"status":"ACTIVE","sortPriority":45,"id":41419636,"name":"8 - 3"},{"status":"ACTIVE","sortPriority":46,"id":41419637,"name":"8 - 4"},{"status":"ACTIVE","sortPriority":47,"id":41419638,"name":"8 - 5"},{"status":"ACTIVE","sortPriority":48,"id":41419639,"name":"8 - 6"},{"status":"ACTIVE","sortPriority":49,"id":41419655,"name":"8 - 9"},{"status":"ACTIVE","sortPriority":50,"id":28546950,"name":"9 - 1"},{"status":"ACTIVE","sortPriority":51,"id":41419656,"name":"9 - 2"},{"status":"ACTIVE","sortPriority":52,"id":41419657,"name":"9 - 3"},{"status":"ACTIVE","sortPriority":53,"id":41435527,"name":"9 - 4"},{"status":"ACTIVE","sortPriority":54,"id":41419658,"name":"9 - 5"},{"status":"ACTIVE","sortPriority":55,"id":41435528,"name":"9 - 6"},{"status":"ACTIVE","sortPriority":56,"id":41419660,"name":"9 - 8"}],"regulators":["MR_INT"],"venue":"Rockhampton","countryCode":"AU","discountAllowed":true,"timezone":"Australia/Queensland","openDate":"2022-03-02T08:28:00.000Z","version":4382606040,"name":"Exacta","eventName":"Rockhampton (AUS) 2nd Mar"},"rc":[],"con":true,"img":false}]}
{"op":"mcm","clk":"5352239448","pt":1646185602749,"mc":[{"id":"1.195503869","marketDefinition":{"bspMarket":false,"turnInPlayEnabled":false,"persistenceEnabled":false,"marketBaseRate":7.0,"eventId":"31272499","eventTypeId":"4339","numberOfWinners":1,"bettingType":"ODDS","marketType":"EXACTA","marketTime":"2022-03-02T11:29:00.000Z","suspendTime":"2022-03-02T11:29:00.000Z","bspReconciled":false,"complete":true,"inPlay":false,"crossMatching":false,"runnersVoidable":false,"numberOfActiveRunners":56,"betDelay":0,"status":"OPEN","runners":[{"status":"ACTIVE","sortPriority":1,"id":41419585,"name":"1 - 2"},{"status":"ACTIVE","sortPriority":2,"id":41419586,"name":"1 - 3"},{"status":"ACTIVE","sortPriority":3,"id":41419587,"name":"1 - 4"},{"status":"ACTIVE","sortPriority":4,"id":41419588,"name":"1 - 5"},{"status":"ACTIVE","sortPriority":5,"id":41419589,"name":"1 - 6"},{"status":"ACTIVE","sortPriority":6,"id":41419591,"name":"1 - 8"},{"status":"ACTIVE","sortPriority":7,"id":28546943,"name":"1 - 9"},{"status":"ACTIVE","sortPriority":8,"id":41419592,"name":"2 - 1"},{"status":"ACTIVE","sortPriority":9,"id":41419593,"name":"2 - 3"},{"status":"ACTIVE","sortPriority":10,"id":41419594,"name":"2 - 4"},{"status":"ACTIVE","sortPriority":11,"id":41419595,"name":"2 - 5"},{"status":"ACTIVE","sortPriority":12,"id":41419596,"name":"2 - 6"},{"status":"ACTIVE","sortPriority":13,"id":41419598,"name":"2 - 8"},{"status":"ACTIVE","sortPriority":14,"id":41419651,"name":"2 - 9"},{"status":"ACTIVE","sortPriority":15,"id":41419599,"name":"3 - 1"},{"status":"ACTIVE","sortPriority":16,"id":41419600,"name":"3 - 2"},{"status":"ACTIVE","sortPriority":17,"id":41419601,"name":"3 - 4"},{"status":"ACTIVE","sortPriority":18,"id":41419602,"name":"3 - 5"},{"status":"ACTIVE","sortPriority":19,"id":41419603,"name":"3 - 6"},{"status":"ACTIVE","sortPriority":20,"id":41419605,"name":"3 - 8"},{"status":"ACTIVE","sortPriority":21,"id":41419652,"name":"3 - 9"},{"status":"ACTIVE","sortPriority":22,"id":41419606,"name":"4 - 1"},{"status":"ACTIVE","sortPriority":23,"id":41419607,"name":"4 - 2"},{"status":"ACTIVE","sortPriority":24,"id":41419608,"name":"4 - 3"},{"status":"ACTIVE","sortPriority":25,"id":41419609,"name":"4 - 5"},{"status":"ACTIVE","sortPriority":26,"id":41419610,"name":"4 - 6"},{"status":"ACTIVE","sortPriority":27,"id":41419612,"name":"4 - 8"},{"status":"ACTIVE","sortPriority":28,"id":41435525,"name":"4 - 9"},{"status":"ACTIVE","sortPriority":29,"id":41419613,"name":"5 - 1"},{"status":"ACTIVE","sortPriority":30,"id":41419614,"name":"5 - 2"},{"status":"ACTIVE","sortPriority":31,"id":41419615,"name":"5 - 3"},{"status":"ACTIVE","sortPriority":32,"id":41419616,"name":"5 - 4"},{"status":"ACTIVE","sortPriority":33,"id":41419617,"name":"5 - 6"},{"status":"ACTIVE","sortPriority":34,"id":41419619,"name":"5 - 8"},{"status":"ACTIVE","sortPriority":35,"id":41419653,"name":"5 - 9"},{"status":"ACTIVE","sortPriority":36,"id":41419620,"name":"6 - 1"},{"status":"ACTIVE","sortPriority":37,"id":41419621,"name":"6 - 2"},{"status":"ACTIVE","sortPriority":38,"id":41419622,"name":"6 - 3"},{"status":"ACTIVE","sortPriority":39,"id":41419623,"name":"6 - 4"},{"status":"ACTIVE","sortPriority":40,"id":41419624,"name":"6 - 5"},{"status":"ACTIVE","sortPriority":41,"id":41419626,"name":"6 - 8"},{"status":"ACTIVE","sortPriority":42,"id":41435526,"name":"6 - 9"},{"status":"ACTIVE","sortPriority":43,"id":41419634,"name":"8 - 1"},{"status":"ACTIVE","sortPriority":44,"id":41419635,"name":"8 - 2"},{"status":"ACTIVE","sortPriority":45,"id":41419636,"name":"8 - 3"},{"status":"ACTIVE","sortPriority":46,"id":41419637,"name":"8 - 4"},{"status":"ACTIVE","sortPriority":47,"id":41419638,"name":"8 - 5"},{"status":"ACTIVE","sortPriority":48,"id":41419639,"name":"8 - 6"},{"status":"ACTIVE","sortPriority":49,"id":41419655,"name":"8 - 9"},{"status":"ACTIVE","sortPriority":50,"id":28546950,"name":"9 - 1"},{"status":"ACTIVE","sortPriority":51,"id":41419656,"name":"9 - 2"},{"status":"ACTIVE","sortPriority":52,"id":41419657,"name":"9 - 3"},{"status":"ACTIVE","sortPriority":53,"id":41435527,"name":"9 - 4"},{"status":"ACTIVE","sortPriority":54,"id":41419658,"name":"9 - 5"},{"status":"ACTIVE","sortPriority":55,"id":41435528,"name":"9 - 6"},{"status":"ACTIVE","sortPriority":56,"id":41419660,"name":"9 - 8"}],"regulators":["MR_INT"],"venue":"Rockhampton","countryCode":"AU","discountAllowed":true,"timezone":"Australia/Queensland","openDate":"2022-03-02T08:28:00.000Z","version":4382606040,"name":"Exacta","eventName":"Rockhampton (AUS) 2nd Mar"},"rc":[{"atb":[[17.5,16.15],[50,4.07],[25,8.32]],"id":41419609},{"atb":[[18,15.67],[26,7.99],[55,3.7]],"id":41419638},{"atb":[[10.5,28.05],[26,7.99],[15.5,13.78]],"id":41419605},{"atb":[[9,24.98],[5,66.63],[6,39.98]],"id":41419634},{"atb":[[270,0.74],[120,1.67],[60,4.51]],"id":41419617},{"atb":[[16,13.32],[11,26.65],[27,7.68]],"id":41419613},{"atb":[[75,2.69],[20,14.03],[30,6.89]],"id":41419593},{"atb":[[80,2.53],[42,6.49],[210,0.95]],"id":41419655},{"atb":[[16.5,17.19],[46,4.44],[23,9.08]],"id":41419622},{"atb":[[8.6,26.3],[14,15.37],[6.6,47.59]],"id":41419589},{"atb":[[85,2.37],[44,6.19],[220,0.91]],"id":41435527},{"atb":[[600,0.44],[700,0.28],[850,0.23]],"id":41419651},{"atb":[[24,8.69],[9.8,30.29],[14.5,14.8]],"id":41419601},{"atb":[[17.5,12.11],[12.5,23.17],[30,6.89]],"id":28546943},{"atb":[[16,17.77],[44,4.65],[22,9.52]],"id":41419626},{"atb":[[42,4.87],[21,9.99],[15.5,18.38]],"id":41419639},{"atb":[[5.7,42.53],[8.4,27.01],[4.7,72.03]],"id":41419606},{"atb":[[18,15.67],[26,7.99],[55,3.7]],"id":41419635},{"atb":[[65,3.12],[19,14.8],[28,7.4]],"id":41419602},{"atb":[[18.5,11.42],[11,19.99],[8.4,36.01]],"id":41419585},{"atb":[[310,0.64],[210,1.27],[460,0.43]],"id":41419614},{"atb":[[40,5.12],[20,10.51],[15,19.03]],"id":41419610},{"atb":[[600,0.44],[700,0.28],[850,0.23]],"id":41419656},{"atb":[[42,4.87],[21,9.99],[15.5,18.38]],"id":41419623},{"atb":[[95,2.12],[48,5.67],[240,0.83]],"id":41419652},{"atb":[[550,0.48],[650,0.3],[800,0.25]],"id":41435528},{"atb":[[65,3.12],[19,14.8],[28,7.4]],"id":41419619},{"atb":[[7.4,31.23],[5.2,47.59],[4.2,83.29]],"id":41419586},{"atb":[[65,3.12],[19,14.8],[28,7.4]],"id":41419598},{"atb":[[100,2.01],[50,5.44],[250,0.8]],"id":41419660},{"atb":[[18.5,15.22],[27,7.68],[60,3.38]],"id":41419594},{"atb":[[17.5,16.15],[50,4.07],[25,8.32]],"id":41419607},{"atb":[[16.5,17.19],[46,4.44],[23,9.08]],"id":28546950},{"atb":[[10.5,28.05],[26,7.99],[15.5,13.78]],"id":41419636},{"atb":[[16,17.77],[44,4.65],[22,9.52]],"id":41419603},{"atb":[[75,2.69],[20,14.03],[30,6.89]],"id":41419615},{"atb":[[140,1.43],[70,3.86],[290,0.69]],"id":41419657},{"atb":[[260,0.77],[110,1.83],[55,4.93]],"id":41419624},{"atb":[[3.95,90.34],[6.8,34.46],[4.9,51.25]],"id":41419591},{"atb":[[34,8.07],[170,1.18],[60,3.38]],"id":41435525},{"atb":[[600,0.44],[700,0.28],[850,0.23]],"id":41419653},{"atb":[[19.5,10.8],[12,18.17],[8.8,34.17]],"id":41419620},{"atb":[[3.7,98.71],[4.4,58.79],[5.9,40.79]],"id":41419587},{"atb":[[9.6,23.24],[5.3,61.98],[6.6,35.69]],"id":41419599},{"atb":[[310,0.64],[210,1.27],[460,0.43]],"id":41419595},{"atb":[[9.6,30.99],[23,9.08],[14,15.37]],"id":41419608},{"atb":[[9.2,32.5],[21,9.99],[13,16.65]],"id":41419637},{"atb":[[18.5,15.22],[27,7.68],[60,3.38]],"id":41419616},{"atb":[[9.2,32.5],[21,9.99],[13,16.65]],"id":41419612},{"atb":[[16,13.32],[11,26.65],[27,7.68]],"id":41419592},{"atb":[[610,0.32],[760,0.26],[510,0.52]],"id":41435526},{"atb":[[260,0.77],[110,1.83],[55,4.93]],"id":41419621},{"atb":[[18.5,11.42],[11,19.99],[8.4,36.01]],"id":41419588},{"atb":[[65,3.12],[19,14.8],[28,7.4]],"id":41419600},{"atb":[[270,0.74],[120,1.67],[60,4.51]],"id":41419596},{"atb":[[600,0.44],[700,0.28],[850,0.23]],"id":41419658}],"con":true,"img":true}]}
{"op":"mcm","clk":"5352466735","pt":1646191002692,"mc":[{"id":"1.195503869","marketDefinition":{"bspMarket":false,"turnInPlayEnabled":false,"persistenceEnabled":false,"marketBaseRate":7.0,"eventId":"31272499","eventTypeId":"4339","numberOfWinners":1,"bettingType":"ODDS","marketType":"EXACTA","marketTime":"2022-03-02T11:29:00.000Z","suspendTime":"2022-03-02T11:29:00.000Z","bspReconciled":false,"complete":true,"inPlay":false,"crossMatching":false,"runnersVoidable":false,"numberOfActiveRunners":56,"betDelay":0,"status":"OPEN","runners":[{"status":"ACTIVE","sortPriority":1,"id":41419585,"name":"1 - 2"},{"status":"ACTIVE","sortPriority":2,"id":41419586,"name":"1 - 3"},{"status":"ACTIVE","sortPriority":3,"id":41419587,"name":"1 - 4"},{"status":"ACTIVE","sortPriority":4,"id":41419588,"name":"1 - 5"},{"status":"ACTIVE","sortPriority":5,"id":41419589,"name":"1 - 6"},{"status":"ACTIVE","sortPriority":6,"id":41419591,"name":"1 - 8"},{"status":"ACTIVE","sortPriority":7,"id":28546943,"name":"1 - 9"},{"status":"ACTIVE","sortPriority":8,"id":41419592,"name":"2 - 1"},{"status":"ACTIVE","sortPriority":9,"id":41419593,"name":"2 - 3"},{"status":"ACTIVE","sortPriority":10,"id":41419594,"name":"2 - 4"},{"status":"ACTIVE","sortPriority":11,"id":41419595,"name":"2 - 5"},{"status":"ACTIVE","sortPriority":12,"id":41419596,"name":"2 - 6"},{"status":"ACTIVE","sortPriority":13,"id":41419598,"name":"2 - 8"},{"status":"ACTIVE","sortPriority":14,"id":41419651,"name":"2 - 9"},{"status":"ACTIVE","sortPriority":15,"id":41419599,"name":"3 - 1"},{"status":"ACTIVE","sortPriority":16,"id":41419600,"name":"3 - 2"},{"status":"ACTIVE","sortPriority":17,"id":41419601,"name":"3 - 4"},{"status":"ACTIVE","sortPriority":18,"id":41419602,"name":"3 - 5"},{"status":"ACTIVE","sortPriority":19,"id":41419603,"name":"3 - 6"},{"status":"ACTIVE","sortPriority":20,"id":41419605,"name":"3 - 8"},{"status":"ACTIVE","sortPriority":21,"id":41419652,"name":"3 - 9"},{"status":"ACTIVE","sortPriority":22,"id":41419606,"name":"4 - 1"},{"status":"ACTIVE","sortPriority":23,"id":41419607,"name":"4 - 2"},{"status":"ACTIVE","sortPriority":24,"id":41419608,"name":"4 - 3"},{"status":"ACTIVE","sortPriority":25,"id":41419609,"name":"4 - 5"},{"status":"ACTIVE","sortPriority":26,"id":41419610,"name":"4 - 6"},{"status":"ACTIVE","sortPriority":27,"id":41419612,"name":"4 - 8"},{"status":"ACTIVE","sortPriority":28,"id":41435525,"name":"4 - 9"},{"status":"ACTIVE","sortPriority":29,"id":41419613,"name":"5 - 1"},{"status":"ACTIVE","sortPriority":30,"id":41419614,"name":"5 - 2"},{"status":"ACTIVE","sortPriority":31,"id":41419615,"name":"5 - 3"},{"status":"ACTIVE","sortPriority":32,"id":41419616,"name":"5 - 4"},{"status":"ACTIVE","sortPriority":33,"id":41419617,"name":"5 - 6"},{"status":"ACTIVE","sortPriority":34,"id":41419619,"name":"5 - 8"},{"status":"ACTIVE","sortPriority":35,"id":41419653,"name":"5 - 9"},{"status":"ACTIVE","sortPriority":36,"id":41419620,"name":"6 - 1"},{"status":"ACTIVE","sortPriority":37,"id":41419621,"name":"6 - 2"},{"status":"ACTIVE","sortPriority":38,"id":41419622,"name":"6 - 3"},{"status":"ACTIVE","sortPriority":39,"id":41419623,"name":"6 - 4"},{"status":"ACTIVE","sortPriority":40,"id":41419624,"name":"6 - 5"},{"status":"ACTIVE","sortPriority":41,"id":41419626,"name":"6 - 8"},{"status":"ACTIVE","sortPriority":42,"id":41435526,"name":"6 - 9"},{"status":"ACTIVE","sortPriority":43,"id":41419634,"name":"8 - 1"},{"status":"ACTIVE","sortPriority":44,"id":41419635,"name":"8 - 2"},{"status":"ACTIVE","sortPriority":45,"id":41419636,"name":"8 - 3"},{"status":"ACTIVE","sortPriority":46,"id":41419637,"name":"8 - 4"},{"status":"ACTIVE","sortPriority":47,"id":41419638,"name":"8 - 5"},{"status":"ACTIVE","sortPriority":48,"id":41419639,"name":"8 - 6"},{"status":"ACTIVE","sortPriority":49,"id":41419655,"name":"8 - 9"},{"status":"ACTIVE","sortPriority":50,"id":28546950,"name":"9 - 1"},{"status":"ACTIVE","sortPriority":51,"id":41419656,"name":"9 - 2"},{"status":"ACTIVE","sortPriority":52,"id":41419657,"name":"9 - 3"},{"status":"ACTIVE","sortPriority":53,"id":41435527,"name":"9 - 4"},{"status":"ACTIVE","sortPriority":54,"id":41419658,"name":"9 - 5"},{"status":"ACTIVE","sortPriority":55,"id":41435528,"name":"9 - 6"},{"status":"ACTIVE","sortPriority":56,"id":41419660,"name":"9 - 8"}],"regulators":["MR_INT"],"venue":"Rockhampton","countryCode":"AU","discountAllowed":true,"timezone":"Australia/Queensland","openDate":"2022-03-02T08:28:00.000Z","version":4382606040,"name":"Exacta","eventName":"Rockhampton (AUS) 2nd Mar"},"rc":[{"atb":[[17.5,16.17],[50,4.08],[25,8.34]],"id":41419609},{"atb":[[18,15.7],[26,8],[55,3.7]],"id":41419638},{"atb":[[10.5,28.1],[26,8],[15.5,13.8]],"id":41419605},{"atb":[[9,25.02],[5,66.74],[6,40.04]],"id":41419634},{"atb":[[270,0.74],[120,1.68],[60,4.52]],"id":41419617},{"atb":[[16,13.34],[11,26.69],[27,7.7]],"id":41419613},{"atb":[[75,2.7],[20,14.05],[30,6.9]],"id":41419593},{"atb":[[80,2.53],[42,6.51],[210,0.95]],"id":41419655},{"atb":[[16.5,17.22],[46,4.45],[23,9.09]],"id":41419622},{"atb":[[8.6,26.34],[14,15.4],[6.6,47.67]],"id":41419589},{"atb":[[85,2.38],[44,6.21],[220,0.91]],"id":41435527},{"atb":[[600,0.44],[700,0.28],[850,0.23]],"id":41419651},{"atb":[[24,8.7],[9.8,30.34],[14.5,14.83]],"id":41419601},{"atb":[[17.5,12.13],[12.5,23.21],[30,6.9]],"id":28546943},{"atb":[[16,17.8],[44,4.65],[22,9.53]],"id":41419626},{"atb":[[42,4.88],[21,10.01],[15.5,18.41]],"id":41419639},{"atb":[[5.7,42.6],[8.4,27.05],[4.7,72.15]],"id":41419606},{"atb":[[18,15.7],[26,8],[55,3.7]],"id":41419635},{"atb":[[65,3.12],[19,14.83],[28,7.41]],"id":41419602},{"atb":[[18.5,11.44],[11,20.02],[8.4,36.07]],"id":41419585},{"atb":[[310,0.64],[210,1.27],[460,0.43]],"id":41419614},{"atb":[[40,5.13],[20,10.53],[15,19.06]],"id":41419610},{"atb":[[600,0.44],[700,0.28],[850,0.23]],"id":41419656},{"atb":[[42,4.88],[21,10.01],[15.5,18.41]],"id":41419623},{"atb":[[95,2.13],[48,5.68],[240,0.83]],"id":41419652},{"atb":[[550,0.48],[650,0.3],[800,0.25]],"id":41435528},{"atb":[[65,3.12],[19,14.83],[28,7.41]],"id":41419619},{"atb":[[7.4,31.28],[5.2,47.67],[4.2,83.43]],"id":41419586},{"atb":[[65,3.12],[19,14.83],[28,7.41]],"id":41419598},{"atb":[[100,2.02],[50,5.45],[250,0.8]],"id":41419660},{"atb":[[18.5,15.25],[27,7.7],[60,3.39]],"id":41419594},{"atb":[[17.5,16.17],[50,4.08],[25,8.34]],"id":41419607},{"atb":[[16.5,17.22],[46,4.45],[23,9.09]],"id":28546950},{"atb":[[10.5,28.1],[26,8],[15.5,13.8]],"id":41419636},{"atb":[[16,17.8],[44,4.65],[22,9.53]],"id":41419603},{"atb":[[75,2.7],[20,14.05],[30,6.9]],"id":41419615},{"atb":[[140,1.44],[70,3.86],[290,0.69]],"id":41419657},{"atb":[[260,0.77],[110,1.83],[55,4.94]],"id":41419624},{"atb":[[3.95,90.5],[6.8,34.52],[4.9,51.34]],"id":41419591},{"atb":[[34,8.08],[170,1.18],[60,3.39]],"id":41435525},{"atb":[[600,0.44],[700,0.28],[850,0.23]],"id":41419653},{"atb":[[19.5,10.82],[12,18.2],[8.8,34.23]],"id":41419620},{"atb":[[3.7,98.88],[4.4,58.89],[5.9,40.86]],"id":41419587},{"atb":[[9.6,23.28],[5.3,62.08],[6.6,35.75]],"id":41419599},{"atb":[[310,0.64],[210,1.27],[460,0.43]],"id":41419595},{"atb":[[9.6,31.04],[23,9.09],[14,15.4]],"id":41419608},{"atb":[[9.2,32.55],[21,10.01],[13,16.68]],"id":41419637},{"atb":[[18.5,15.25],[27,7.7],[60,3.39]],"id":41419616},{"atb":[[9.2,32.55],[21,10.01],[13,16.68]],"id":41419612},{"atb":[[16,13.34],[11,26.69],[27,7.7]],"id":41419592},{"atb":[[610,0.32],[760,0.26],[510,0.52]],"id":41435526},{"atb":[[260,0.77],[110,1.83],[55,4.94]],"id":41419621},{"atb":[[18.5,11.44],[11,20.02],[8.4,36.07]],"id":41419588},{"atb":[[65,3.12],[19,14.83],[28,7.41]],"id":41419600},{"atb":[[270,0.74],[120,1.68],[60,4.52]],"id":41419596},{"atb":[[600,0.44],[700,0.28],[850,0.23]],"id":41419658}],"con":true,"img":true}]}
{"op":"mcm","clk":"5352732305","pt":1646198603770,"mc":[{"id":"1.195503869","rc":[{"atb":[[17.5,16.17],[50,4.08],[25,8.33]],"id":41419609},{"atb":[[18,15.69],[26,8],[55,3.7]],"id":41419638},{"atb":[[10.5,0],[26,0],[15.5,0]],"id":41419605},{"atb":[[9,25.01],[5,66.72],[6,40.03]],"id":41419634},{"atb":[[270,0.74],[120,1.68],[60,4.52]],"id":41419617},{"atb":[[16,13.34],[11,26.68],[27,7.69]],"id":41419613},{"atb":[[75,0],[20,0],[30,0]],"id":41419593},{"atb":[[80,2.53],[42,6.5],[210,0.95]],"id":41419655},{"atb":[[16.5,17.22],[46,4.44],[23,9.09]],"id":41419622},{"atb":[[8.6,0],[14,0],[6.6,0]],"id":41419589},{"atb":[[85,2.38],[44,6.2],[220,0.91]],"id":41435527},{"atb":[[600,0.44],[700,0.28],[850,0.23]],"id":41419651},{"atb":[[24,0],[9.8,0],[14.5,0]],"id":41419601},{"atb":[[17.5,0],[12.5,0],[30,0]],"id":28546943},{"atb":[[16,17.79],[44,4.65],[22,9.53]],"id":41419626},{"atb":[[42,4.88],[21,10],[15.5,18.4]],"id":41419639},{"atb":[[5.7,42.58],[8.4,27.04],[4.7,72.13]],"id":41419606},{"atb":[[18,15.69],[26,8],[55,3.7]],"id":41419635},{"atb":[[65,0],[19,0],[28,0]],"id":41419602},{"atb":[[18.5,0],[11,0],[8.4,0]],"id":41419585},{"atb":[[310,0.64],[210,1.27],[460,0.43]],"id":41419614},{"atb":[[40,5.13],[20,10.53],[15,19.06]],"id":41419610},{"atb":[[600,0.44],[700,0.28],[850,0.23]],"id":41419656},{"atb":[[42,4.88],[21,10],[15.5,18.4]],"id":41419623},{"atb":[[95,2.12],[48,5.67],[240,0.83]],"id":41419652},{"atb":[[550,0.48],[650,0.3],[800,0.25]],"id":41435528},{"atb":[[65,3.12],[19,14.82],[28,7.41]],"id":41419619},{"atb":[[7.4,0],[5.2,0],[4.2,0]],"id":41419586},{"atb":[[65,0],[19,0],[28,0]],"id":41419598},{"atb":[[100,2.02],[50,5.44],[250,0.8]],"id":41419660},{"atb":[[18.5,0],[27,0],[60,0]],"id":41419594},{"atb":[[17.5,16.17],[50,4.08],[25,8.33]],"id":41419607},{"atb":[[16.5,0],[46,0],[23,0]],"id":28546950},{"atb":[[10.5,28.09],[26,8],[15.5,13.8]],"id":41419636},{"atb":[[16,0],[44,0],[22,0]],"id":41419603},{"atb":[[75,2.7],[20,14.04],[30,6.9]],"id":41419615},{"atb":[[140,1.44],[70,3.86],[290,0.69]],"id":41419657},{"atb":[[260,0.77],[110,1.83],[55,4.94]],"id":41419624},{"atb":[[3.95,0],[6.8,0],[4.9,0]],"id":41419591},{"atb":[[34,8.08],[170,1.18],[60,3.39]],"id":41435525},{"atb":[[600,0.44],[700,0.28],[850,0.23]],"id":41419653},{"atb":[[19.5,10.82],[12,18.19],[8.8,34.21]],"id":41419620},{"atb":[[3.7,0],[4.4,0],[5.9,0]],"id":41419587},{"atb":[[9.6,0],[5.3,0],[6.6,0]],"id":41419599},{"atb":[[310,0],[210,0],[460,0]],"id":41419595},{"atb":[[9.6,31.03],[23,9.09],[14,15.39]],"id":41419608},{"atb":[[9.2,32.54],[21,10],[13,16.68]],"id":41419637},{"atb":[[18.5,15.24],[27,7.69],[60,3.39]],"id":41419616},{"atb":[[9.2,32.54],[21,10],[13,16.68]],"id":41419612},{"atb":[[16,0],[11,0],[27,0]],"id":41419592},{"atb":[[610,0.32],[760,0.26],[510,0.52]],"id":41435526},{"atb":[[260,0.77],[110,1.83],[55,4.94]],"id":41419621},{"atb":[[18.5,0],[11,0],[8.4,0]],"id":41419588},{"atb":[[65,0],[19,0],[28,0]],"id":41419600},{"atb":[[270,0],[120,0],[60,0]],"id":41419596},{"atb":[[600,0.44],[700,0.28],[850,0.23]],"id":41419658}],"con":true,"img":false}]}
{"op":"mcm","clk":"5352732313","pt":1646198603978,"mc":[{"id":"1.195503869","rc":[{"atb":[[17.5,0],[50,0],[25,0]],"id":41419609},{"atb":[[18,0],[26,0],[55,0]],"id":41419638},{"atb":[[9,0],[5,0],[6,0]],"id":41419634},{"atb":[[270,0],[120,0],[60,0]],"id":41419617},{"atb":[[16,0],[11,0],[27,0]],"id":41419613},{"atb":[[80,0],[42,0],[210,0]],"id":41419655},{"atb":[[16.5,0],[46,0],[23,0]],"id":41419622},{"atb":[[85,0],[44,0],[220,0]],"id":41435527},{"atb":[[600,0],[700,0],[850,0]],"id":41419651},{"atb":[[16,0],[44,0],[22,0]],"id":41419626},{"atb":[[42,0],[21,0],[15.5,0]],"id":41419639},{"atb":[[5.7,0],[8.4,0],[4.7,0]],"id":41419606},{"atb":[[18,0],[26,0],[55,0]],"id":41419635},{"atb":[[310,0],[210,0],[460,0]],"id":41419614},{"atb":[[40,0],[20,0],[15,0]],"id":41419610},{"atb":[[600,0],[700,0],[850,0]],"id":41419656},{"atb":[[42,0],[21,0],[15.5,0]],"id":41419623},{"atb":[[95,0],[48,0],[240,0]],"id":41419652},{"atb":[[550,0],[650,0],[800,0]],"id":41435528},{"atb":[[65,0],[19,0],[28,0]],"id":41419619},{"atb":[[100,0],[50,0],[250,0]],"id":41419660},{"atb":[[17.5,0],[50,0],[25,0]],"id":41419607},{"atb":[[10.5,0],[26,0],[15.5,0]],"id":41419636},{"atb":[[75,0],[20,0],[30,0]],"id":41419615},{"atb":[[140,0],[70,0],[290,0]],"id":41419657},{"atb":[[260,0],[110,0],[55,0]],"id":41419624},{"atb":[[34,0],[170,0],[60,0]],"id":41435525},{"atb":[[600,0],[700,0],[850,0]],"id":41419653},{"atb":[[19.5,0],[12,0],[8.8,0]],"id":41419620},{"atb":[[9.6,0],[23,0],[14,0]],"id":41419608},{"atb":[[9.2,0],[21,0],[13,0]],"id":41419637},{"atb":[[18.5,0],[27,0],[60,0]],"id":41419616},{"atb":[[9.2,0],[21,0],[13,0]],"id":41419612},{"atb":[[610,0],[760,0],[510,0]],"id":41435526},{"atb":[[260,0],[110,0],[55,0]],"id":41419621},{"atb":[[600,0],[700,0],[850,0]],"id":41419658}],"con":true,"img":false}]}
{"op":"mcm","clk":"5352732765","pt":1646198617584,"mc":[{"id":"1.195503869","rc":[{"atb":[[17.5,16.17],[50,4.08],[25,8.33]],"id":41419609},{"atb":[[18,15.69],[26,8],[55,3.7]],"id":41419638},{"atb":[[10.5,28.09],[26,8],[15.5,13.8]],"id":41419605},{"atb":[[9,25.01],[5,66.72],[6,40.03]],"id":41419634},{"atb":[[270,0.74],[120,1.68],[60,4.52]],"id":41419617},{"atb":[[16,13.34],[11,26.68],[27,7.69]],"id":41419613},{"atb":[[75,2.7],[20,14.04],[30,6.9]],"id":41419593},{"atb":[[80,2.53],[42,6.5],[210,0.95]],"id":41419655},{"atb":[[16.5,17.22],[46,4.44],[23,9.09]],"id":41419622},{"atb":[[8.6,26.33],[14,15.39],[6.6,47.66]],"id":41419589},{"atb":[[85,2.38],[44,6.2],[220,0.91]],"id":41435527},{"atb":[[600,0.44],[700,0.28],[850,0.23]],"id":41419651},{"atb":[[24,8.7],[9.8,30.33],[14.5,14.82]],"id":41419601},{"atb":[[17.5,12.13],[12.5,23.2],[30,6.9]],"id":28546943},{"atb":[[16,17.79],[44,4.65],[22,9.53]],"id":41419626},{"atb":[[42,4.88],[21,10],[15.5,18.4]],"id":41419639},{"atb":[[5.7,42.58],[8.4,27.04],[4.7,72.13]],"id":41419606},{"atb":[[18,15.69],[26,8],[55,3.7]],"id":41419635},{"atb":[[65,3.12],[19,14.82],[28,7.41]],"id":41419602},{"atb":[[18.5,11.43],[11,20.01],[8.4,36.06]],"id":41419585},{"atb":[[310,0.64],[210,1.27],[460,0.43]],"id":41419614},{"atb":[[40,5.13],[20,10.53],[15,19.06]],"id":41419610},{"atb":[[600,0.44],[700,0.28],[850,0.23]],"id":41419656},{"atb":[[42,4.88],[21,10],[15.5,18.4]],"id":41419623},{"atb":[[95,2.12],[48,5.67],[240,0.83]],"id":41419652},{"atb":[[550,0.48],[650,0.3],[800,0.25]],"id":41435528},{"atb":[[65,3.12],[19,14.82],[28,7.41]],"id":41419619},{"atb":[[7.4,31.27],[5.2,47.66],[4.2,83.4]],"id":41419586},{"atb":[[65,3.12],[19,14.82],[28,7.41]],"id":41419598},{"atb":[[100,2.02],[50,5.44],[250,0.8]],"id":41419660},{"atb":[[18.5,15.24],[27,7.69],[60,3.39]],"id":41419594},{"atb":[[17.5,16.17],[50,4.08],[25,8.33]],"id":41419607},{"atb":[[16.5,17.22],[46,4.44],[23,9.09]],"id":28546950},{"atb":[[10.5,28.09],[26,8],[15.5,13.8]],"id":41419636},{"atb":[[16,17.79],[44,4.65],[22,9.53]],"id":41419603},{"atb":[[75,2.7],[20,14.04],[30,6.9]],"id":41419615},{"atb":[[140,1.44],[70,3.86],[290,0.69]],"id":41419657},{"atb":[[260,0.77],[110,1.83],[55,4.94]],"id":41419624},{"atb":[[3.95,90.46],[6.8,34.51],[4.9,51.32]],"id":41419591},{"atb":[[34,8.08],[170,1.18],[60,3.39]],"id":41435525},{"atb":[[600,0.44],[700,0.28],[850,0.23]],"id":41419653},{"atb":[[19.5,10.82],[12,18.19],[8.8,34.21]],"id":41419620},{"atb":[[3.7,98.84],[4.4,58.86],[5.9,40.85]],"id":41419587},{"atb":[[9.6,23.27],[5.3,62.06],[6.6,35.74]],"id":41419599},{"atb":[[310,0.64],[210,1.27],[460,0.43]],"id":41419595},{"atb":[[9.6,31.03],[23,9.09],[14,15.39]],"id":41419608},{"atb":[[9.2,32.54],[21,10],[13,16.68]],"id":41419637},{"atb":[[18.5,15.24],[27,7.69],[60,3.39]],"id":41419616},{"atb":[[9.2,32.54],[21,10],[13,16.68]],"id":41419612},{"atb":[[16,13.34],[11,26.68],[27,7.69]],"id":41419592},{"atb":[[610,0.32],[760,0.26],[510,0.52]],"id":41435526},{"atb":[[260,0.77],[110,1.83],[55,4.94]],"id":41419621},{"atb":[[18.5,11.43],[11,20.01],[8.4,36.06]],"id":41419588},{"atb":[[65,3.12],[19,14.82],[28,7.41]],"id":41419600},{"atb":[[270,0.74],[120,1.68],[60,4.52]],"id":41419596},{"atb":[[600,0.44],[700,0.28],[850,0.23]],"id":41419658}],"con":true,"img":false}]}
{"op":"mcm","clk":"5353028908","pt":1646207202760,"mc":[{"id":"1.195503869","marketDefinition":{"bspMarket":false,"turnInPlayEnabled":false,"persistenceEnabled":false,"marketBaseRate":7.0,"eventId":"31272499","eventTypeId":"4339","numberOfWinners":1,"bettingType":"ODDS","marketType":"EXACTA","marketTime":"2022-03-02T11:29:00.000Z","suspendTime":"2022-03-02T11:29:00.000Z","bspReconciled":false,"complete":true,"inPlay":false,"crossMatching":false,"runnersVoidable":false,"numberOfActiveRunners":56,"betDelay":0,"status":"OPEN","runners":[{"status":"ACTIVE","sortPriority":1,"id":41419585,"name":"1 - 2"},{"status":"ACTIVE","sortPriority":2,"id":41419586,"name":"1 - 3"},{"status":"ACTIVE","sortPriority":3,"id":41419587,"name":"1 - 4"},{"status":"ACTIVE","sortPriority":4,"id":41419588,"name":"1 - 5"},{"status":"ACTIVE","sortPriority":5,"id":41419589,"name":"1 - 6"},{"status":"ACTIVE","sortPriority":6,"id":41419591,"name":"1 - 8"},{"status":"ACTIVE","sortPriority":7,"id":28546943,"name":"1 - 9"},{"status":"ACTIVE","sortPriority":8,"id":41419592,"name":"2 - 1"},{"status":"ACTIVE","sortPriority":9,"id":41419593,"name":"2 - 3"},{"status":"ACTIVE","sortPriority":10,"id":41419594,"name":"2 - 4"},{"status":"ACTIVE","sortPriority":11,"id":41419595,"name":"2 - 5"},{"status":"ACTIVE","sortPriority":12,"id":41419596,"name":"2 - 6"},{"status":"ACTIVE","sortPriority":13,"id":41419598,"name":"2 - 8"},{"status":"ACTIVE","sortPriority":14,"id":41419651,"name":"2 - 9"},{"status":"ACTIVE","sortPriority":15,"id":41419599,"name":"3 - 1"},{"status":"ACTIVE","sortPriority":16,"id":41419600,"name":"3 - 2"},{"status":"ACTIVE","sortPriority":17,"id":41419601,"name":"3 - 4"},{"status":"ACTIVE","sortPriority":18,"id":41419602,"name":"3 - 5"},{"status":"ACTIVE","sortPriority":19,"id":41419603,"name":"3 - 6"},{"status":"ACTIVE","sortPriority":20,"id":41419605,"name":"3 - 8"},{"status":"ACTIVE","sortPriority":21,"id":41419652,"name":"3 - 9"},{"status":"ACTIVE","sortPriority":22,"id":41419606,"name":"4 - 1"},{"status":"ACTIVE","sortPriority":23,"id":41419607,"name":"4 - 2"},{"status":"ACTIVE","sortPriority":24,"id":41419608,"name":"4 - 3"},{"status":"ACTIVE","sortPriority":25,"id":41419609,"name":"4 - 5"},{"status":"ACTIVE","sortPriority":26,"id":41419610,"name":"4 - 6"},{"status":"ACTIVE","sortPriority":27,"id":41419612,"name":"4 - 8"},{"status":"ACTIVE","sortPriority":28,"id":41435525,"name":"4 - 9"},{"status":"ACTIVE","sortPriority":29,"id":41419613,"name":"5 - 1"},{"status":"ACTIVE","sortPriority":30,"id":41419614,"name":"5 - 2"},{"status":"ACTIVE","sortPriority":31,"id":41419615,"name":"5 - 3"},{"status":"ACTIVE","sortPriority":32,"id":41419616,"name":"5 - 4"},{"status":"ACTIVE","sortPriority":33,"id":41419617,"name":"5 - 6"},{"status":"ACTIVE","sortPriority":34,"id":41419619,"name":"5 - 8"},{"status":"ACTIVE","sortPriority":35,"id":41419653,"name":"5 - 9"},{"status":"ACTIVE","sortPriority":36,"id":41419620,"name":"6 - 1"},{"status":"ACTIVE","sortPriority":37,"id":41419621,"name":"6 - 2"},{"status":"ACTIVE","sortPriority":38,"id":41419622,"name":"6 - 3"},{"status":"ACTIVE","sortPriority":39,"id":41419623,"name":"6 - 4"},{"status":"ACTIVE","sortPriority":40,"id":41419624,"name":"6 - 5"},{"status":"ACTIVE","sortPriority":41,"id":41419626,"name":"6 - 8"},{"status":"ACTIVE","sortPriority":42,"id":41435526,"name":"6 - 9"},{"status":"ACTIVE","sortPriority":43,"id":41419634,"name":"8 - 1"},{"status":"ACTIVE","sortPriority":44,"id":41419635,"name":"8 - 2"},{"status":"ACTIVE","sortPriority":45,"id":41419636,"name":"8 - 3"},{"status":"ACTIVE","sortPriority":46,"id":41419637,"name":"8 - 4"},{"status":"ACTIVE","sortPriority":47,"id":41419638,"name":"8 - 5"},{"status":"ACTIVE","sortPriority":48,"id":41419639,"name":"8 - 6"},{"status":"ACTIVE","sortPriority":49,"id":41419655,"name":"8 - 9"},{"status":"ACTIVE","sortPriority":50,"id":28546950,"name":"9 - 1"},{"status":"ACTIVE","sortPriority":51,"id":41419656,"name":"9 - 2"},{"status":"ACTIVE","sortPriority":52,"id":41419657,"name":"9 - 3"},{"status":"ACTIVE","sortPriority":53,"id":41435527,"name":"9 - 4"},{"status":"ACTIVE","sortPriority":54,"id":41419658,"name":"9 - 5"},{"status":"ACTIVE","sortPriority":55,"id":41435528,"name":"9 - 6"},{"status":"ACTIVE","sortPriority":56,"id":41419660,"name":"9 - 8"}],"regulators":["MR_INT"],"venue":"Rockhampton","countryCode":"AU","discountAllowed":true,"timezone":"Australia/Queensland","openDate":"2022-03-02T08:28:00.000Z","version":4382606040,"name":"Exacta","eventName":"Rockhampton (AUS) 2nd Mar"},"rc":[{"atb":[[17.5,16.16],[50,4.08],[25,8.33]],"id":41419609},{"atb":[[18,15.69],[26,8],[55,3.7]],"id":41419638},{"atb":[[10.5,28.08],[26,8],[15.5,13.79]],"id":41419605},{"atb":[[9,25.01],[5,66.7],[6,40.02]],"id":41419634},{"atb":[[270,0.74],[120,1.68],[60,4.51]],"id":41419617},{"atb":[[16,13.34],[11,26.68],[27,7.69]],"id":41419613},{"atb":[[75,2.7],[20,14.04],[30,6.89]],"id":41419593},{"atb":[[80,2.53],[42,6.5],[210,0.95]],"id":41419655},{"atb":[[16.5,17.21],[46,4.44],[23,9.09]],"id":41419622},{"atb":[[8.6,26.33],[14,15.39],[6.6,47.64]],"id":41419589},{"atb":[[85,2.37],[44,6.2],[220,0.91]],"id":41435527},{"atb":[[600,0.44],[700,0.28],[850,0.23]],"id":41419651},{"atb":[[24,8.7],[9.8,30.32],[14.5,14.82]],"id":41419601},{"atb":[[17.5,12.12],[12.5,23.19],[30,6.89]],"id":28546943},{"atb":[[16,17.78],[44,4.65],[22,9.53]],"id":41419626},{"atb":[[42,4.87],[21,10],[15.5,18.4]],"id":41419639},{"atb":[[5.7,42.57],[8.4,27.04],[4.7,72.11]],"id":41419606},{"atb":[[18,15.69],[26,8],[55,3.7]],"id":41419635},{"atb":[[65,3.12],[19,14.82],[28,7.41]],"id":41419602},{"atb":[[18.5,11.43],[11,20.01],[8.4,36.05]],"id":41419585},{"atb":[[310,0.64],[210,1.27],[460,0.43]],"id":41419614},{"atb":[[40,5.13],[20,10.52],[15,19.05]],"id":41419610},{"atb":[[600,0.44],[700,0.28],[850,0.23]],"id":41419656},{"atb":[[42,4.87],[21,10],[15.5,18.4]],"id":41419623},{"atb":[[95,2.12],[48,5.67],[240,0.83]],"id":41419652},{"atb":[[550,0.48],[650,0.3],[800,0.25]],"id":41435528},{"atb":[[65,3.12],[19,14.82],[28,7.41]],"id":41419619},{"atb":[[7.4,31.26],[5.2,47.64],[4.2,83.37]],"id":41419586},{"atb":[[65,3.12],[19,14.82],[28,7.41]],"id":41419598},{"atb":[[100,2.01],[50,5.44],[250,0.8]],"id":41419660},{"atb":[[18.5,15.24],[27,7.69],[60,3.38]],"id":41419594},{"atb":[[17.5,16.16],[50,4.08],[25,8.33]],"id":41419607},{"atb":[[16.5,17.21],[46,4.44],[23,9.09]],"id":28546950},{"atb":[[10.5,28.08],[26,8],[15.5,13.79]],"id":41419636},{"atb":[[16,17.78],[44,4.65],[22,9.53]],"id":41419603},{"atb":[[75,2.7],[20,14.04],[30,6.89]],"id":41419615},{"atb":[[140,1.44],[70,3.86],[290,0.69]],"id":41419657},{"atb":[[260,0.77],[110,1.83],[55,4.93]],"id":41419624},{"atb":[[3.95,90.44],[6.8,34.5],[4.9,51.31]],"id":41419591},{"atb":[[34,8.08],[170,1.18],[60,3.38]],"id":41435525},{"atb":[[600,0.44],[700,0.28],[850,0.23]],"id":41419653},{"atb":[[19.5,10.81],[12,18.19],[8.8,34.2]],"id":41419620},{"atb":[[3.7,98.82],[4.4,58.85],[5.9,40.84]],"id":41419587},{"atb":[[9.6,23.26],[5.3,62.04],[6.6,35.73]],"id":41419599},{"atb":[[310,0.64],[210,1.27],[460,0.43]],"id":41419595},{"atb":[[9.6,31.02],[23,9.09],[14,15.39]],"id":41419608},{"atb":[[9.2,32.53],[21,10],[13,16.67]],"id":41419637},{"atb":[[18.5,15.24],[27,7.69],[60,3.38]],"id":41419616},{"atb":[[9.2,32.53],[21,10],[13,16.67]],"id":41419612},{"atb":[[16,13.34],[11,26.68],[27,7.69]],"id":41419592},{"atb":[[610,0.32],[760,0.26],[510,0.52]],"id":41435526},{"atb":[[260,0.77],[110,1.83],[55,4.93]],"id":41419621},{"atb":[[18.5,11.43],[11,20.01],[8.4,36.05]],"id":41419588},{"atb":[[65,3.12],[19,14.82],[28,7.41]],"id":41419600},{"atb":[[270,0.74],[120,1.68],[60,4.51]],"id":41419596},{"atb":[[600,0.44],[700,0.28],[850,0.23]],"id":41419658}],"con":true,"img":true}]}
{"op":"mcm","clk":"5353300295","pt":1646212602763,"mc":[{"id":"1.195503869","marketDefinition":{"bspMarket":false,"turnInPlayEnabled":false,"persistenceEnabled":false,"marketBaseRate":7.0,"eventId":"31272499","eventTypeId":"4339","numberOfWinners":1,"bettingType":"ODDS","marketType":"EXACTA","marketTime":"2022-03-02T11:29:00.000Z","suspendTime":"2022-03-02T11:29:00.000Z","bspReconciled":false,"complete":true,"inPlay":false,"crossMatching":false,"runnersVoidable":false,"numberOfActiveRunners":56,"betDelay":0,"status":"OPEN","runners":[{"status":"ACTIVE","sortPriority":1,"id":41419585,"name":"1 - 2"},{"status":"ACTIVE","sortPriority":2,"id":41419586,"name":"1 - 3"},{"status":"ACTIVE","sortPriority":3,"id":41419587,"name":"1 - 4"},{"status":"ACTIVE","sortPriority":4,"id":41419588,"name":"1 - 5"},{"status":"ACTIVE","sortPriority":5,"id":41419589,"name":"1 - 6"},{"status":"ACTIVE","sortPriority":6,"id":41419591,"name":"1 - 8"},{"status":"ACTIVE","sortPriority":7,"id":28546943,"name":"1 - 9"},{"status":"ACTIVE","sortPriority":8,"id":41419592,"name":"2 - 1"},{"status":"ACTIVE","sortPriority":9,"id":41419593,"name":"2 - 3"},{"status":"ACTIVE","sortPriority":10,"id":41419594,"name":"2 - 4"},{"status":"ACTIVE","sortPriority":11,"id":41419595,"name":"2 - 5"},{"status":"ACTIVE","sortPriority":12,"id":41419596,"name":"2 - 6"},{"status":"ACTIVE","sortPriority":13,"id":41419598,"name":"2 - 8"},{"status":"ACTIVE","sortPriority":14,"id":41419651,"name":"2 - 9"},{"status":"ACTIVE","sortPriority":15,"id":41419599,"name":"3 - 1"},{"status":"ACTIVE","sortPriority":16,"id":41419600,"name":"3 - 2"},{"status":"ACTIVE","sortPriority":17,"id":41419601,"name":"3 - 4"},{"status":"ACTIVE","sortPriority":18,"id":41419602,"name":"3 - 5"},{"status":"ACTIVE","sortPriority":19,"id":41419603,"name":"3 - 6"},{"status":"ACTIVE","sortPriority":20,"id":41419605,"name":"3 - 8"},{"status":"ACTIVE","sortPriority":21,"id":41419652,"name":"3 - 9"},{"status":"ACTIVE","sortPriority":22,"id":41419606,"name":"4 - 1"},{"status":"ACTIVE","sortPriority":23,"id":41419607,"name":"4 - 2"},{"status":"ACTIVE","sortPriority":24,"id":41419608,"name":"4 - 3"},{"status":"ACTIVE","sortPriority":25,"id":41419609,"name":"4 - 5"},{"status":"ACTIVE","sortPriority":26,"id":41419610,"name":"4 - 6"},{"status":"ACTIVE","sortPriority":27,"id":41419612,"name":"4 - 8"},{"status":"ACTIVE","sortPriority":28,"id":41435525,"name":"4 - 9"},{"status":"ACTIVE","sortPriority":29,"id":41419613,"name":"5 - 1"},{"status":"ACTIVE","sortPriority":30,"id":41419614,"name":"5 - 2"},{"status":"ACTIVE","sortPriority":31,"id":41419615,"name":"5 - 3"},{"status":"ACTIVE","sortPriority":32,"id":41419616,"name":"5 - 4"},{"status":"ACTIVE","sortPriority":33,"id":41419617,"name":"5 - 6"},{"status":"ACTIVE","sortPriority":34,"id":41419619,"name":"5 - 8"},{"status":"ACTIVE","sortPriority":35,"id":41419653,"name":"5 - 9"},{"status":"ACTIVE","sortPriority":36,"id":41419620,"name":"6 - 1"},{"status":"ACTIVE","sortPriority":37,"id":41419621,"name":"6 - 2"},{"status":"ACTIVE","sortPriority":38,"id":41419622,"name":"6 - 3"},{"status":"ACTIVE","sortPriority":39,"id":41419623,"name":"6 - 4"},{"status":"ACTIVE","sortPriority":40,"id":41419624,"name":"6 - 5"},{"status":"ACTIVE","sortPriority":41,"id":41419626,"name":"6 - 8"},{"status":"ACTIVE","sortPriority":42,"id":41435526,"name":"6 - 9"},{"status":"ACTIVE","sortPriority":43,"id":41419634,"name":"8 - 1"},{"status":"ACTIVE","sortPriority":44,"id":41419635,"name":"8 - 2"},{"status":"ACTIVE","sortPriority":45,"id":41419636,"name":"8 - 3"},{"status":"ACTIVE","sortPriority":46,"id":41419637,"name":"8 - 4"},{"status":"ACTIVE","sortPriority":47,"id":41419638,"name":"8 - 5"},{"status":"ACTIVE","sortPriority":48,"id":41419639,"name":"8 - 6"},{"status":"ACTIVE","sortPriority":49,"id":41419655,"name":"8 - 9"},{"status":"ACTIVE","sortPriority":50,"id":28546950,"name":"9 - 1"},{"status":"ACTIVE","sortPriority":51,"id":41419656,"name":"9 - 2"},{"status":"ACTIVE","sortPriority":52,"id":41419657,"name":"9 - 3"},{"status":"ACTIVE","sortPriority":53,"id":41435527,"name":"9 - 4"},{"status":"ACTIVE","sortPriority":54,"id":41419658,"name":"9 - 5"},{"status":"ACTIVE","sortPriority":55,"id":41435528,"name":"9 - 6"},{"status":"ACTIVE","sortPriority":56,"id":41419660,"name":"9 - 8"}],"regulators":["MR_INT"],"venue":"Rockhampton","countryCode":"AU","discountAllowed":true,"timezone":"Australia/Queensland","openDate":"2022-03-02T08:28:00.000Z","version":4382606040,"name":"Exacta","eventName":"Rockhampton (AUS) 2nd Mar"},"rc":[{"atb":[[17.5,16.14],[50,4.07],[25,8.32]],"id":41419609},{"atb":[[18,15.66],[26,7.98],[55,3.7]],"id":41419638},{"atb":[[10.5,28.03],[26,7.98],[15.5,13.77]],"id":41419605},{"atb":[[9,24.97],[5,66.59],[6,39.95]],"id":41419634},{"atb":[[270,0.74],[120,1.67],[60,4.51]],"id":41419617},{"atb":[[16,13.31],[11,26.63],[27,7.68]],"id":41419613},{"atb":[[75,2.69],[20,14.02],[30,6.88]],"id":41419593},{"atb":[[80,2.52],[42,6.49],[210,0.95]],"id":41419655},{"atb":[[16.5,17.18],[46,4.44],[23,9.07]],"id":41419622},{"atb":[[8.6,26.29],[14,15.36],[6.6,47.57]],"id":41419589},{"atb":[[85,2.37],[44,6.19],[220,0.91]],"id":41435527},{"atb":[[600,0.44],[700,0.28],[850,0.23]],"id":41419651},{"atb":[[24,8.68],[9.8,30.27],[14.5,14.8]],"id":41419601},{"atb":[[17.5,12.1],[12.5,23.16],[30,6.88]],"id":28546943},{"atb":[[16,17.76],[44,4.64],[22,9.51]],"id":41419626},{"atb":[[42,4.87],[21,9.98],[15.5,18.37]],"id":41419639},{"atb":[[5.7,42.5],[8.4,26.99],[4.7,71.99]],"id":41419606},{"atb":[[18,15.66],[26,7.98],[55,3.7]],"id":41419635},{"atb":[[65,3.12],[19,14.8],[28,7.4]],"id":41419602},{"atb":[[18.5,11.41],[11,19.97],[8.4,35.99]],"id":41419585},{"atb":[[310,0.64],[210,1.27],[460,0.43]],"id":41419614},{"atb":[[40,5.12],[20,10.51],[15,19.02]],"id":41419610},{"atb":[[600,0.44],[700,0.28],[850,0.23]],"id":41419656},{"atb":[[42,4.87],[21,9.98],[15.5,18.37]],"id":41419623},{"atb":[[95,2.12],[48,5.66],[240,0.83]],"id":41419652},{"atb":[[550,0.48],[650,0.3],[800,0.25]],"id":41435528},{"atb":[[65,3.12],[19,14.8],[28,7.4]],"id":41419619},{"atb":[[7.4,31.21],[5.2,47.57],[4.2,83.24]],"id":41419586},{"atb":[[65,3.12],[19,14.8],[28,7.4]],"id":41419598},{"atb":[[100,2.01],[50,5.43],[250,0.8]],"id":41419660},{"atb":[[18.5,15.22],[27,7.68],[60,3.38]],"id":41419594},{"atb":[[17.5,16.14],[50,4.07],[25,8.32]],"id":41419607},{"atb":[[16.5,17.18],[46,4.44],[23,9.07]],"id":28546950},{"atb":[[10.5,28.03],[26,7.98],[15.5,13.77]],"id":41419636},{"atb":[[16,17.76],[44,4.64],[22,9.51]],"id":41419603},{"atb":[[75,2.69],[20,14.02],[30,6.88]],"id":41419615},{"atb":[[140,1.43],[70,3.85],[290,0.69]],"id":41419657},{"atb":[[260,0.77],[110,1.83],[55,4.93]],"id":41419624},{"atb":[[3.95,90.29],[6.8,34.44],[4.9,51.22]],"id":41419591},{"atb":[[34,8.07],[170,1.18],[60,3.38]],"id":41435525},{"atb":[[600,0.44],[700,0.28],[850,0.23]],"id":41419653},{"atb":[[19.5,10.8],[12,18.16],[8.8,34.15]],"id":41419620},{"atb":[[3.7,98.66],[4.4,58.76],[5.9,40.77]],"id":41419587},{"atb":[[9.6,23.23],[5.3,61.94],[6.6,35.67]],"id":41419599},{"atb":[[310,0.64],[210,1.27],[460,0.43]],"id":41419595},{"atb":[[9.6,30.97],[23,9.07],[14,15.36]],"id":41419608},{"atb":[[9.2,32.48],[21,9.98],[13,16.64]],"id":41419637},{"atb":[[18.5,15.22],[27,7.68],[60,3.38]],"id":41419616},{"atb":[[9.2,32.48],[21,9.98],[13,16.64]],"id":41419612},{"atb":[[16,13.31],[11,26.63],[27,7.68]],"id":41419592},{"atb":[[610,0.32],[760,0.26],[510,0.52]],"id":41435526},{"atb":[[260,0.77],[110,1.83],[55,4.93]],"id":41419621},{"atb":[[18.5,11.41],[11,19.97],[8.4,35.99]],"id":41419588},{"atb":[[65,3.12],[19,14.8],[28,7.4]],"id":41419600},{"atb":[[270,0.74],[120,1.67],[60,4.51]],"id":41419596},{"atb":[[600,0.44],[700,0.28],[850,0.23]],"id":41419658}],"con":true,"img":true}]}
{"op":"mcm","clk":"5353343050","pt":1646213340441,"mc":[{"id":"1.195503869","rc":[{"atb":[[17.5,16.14],[42,3.26],[50,4.07],[25,8.32],[55,2.72]],"id":41419609},{"atb":[[18,15.66],[40,3.26],[50,2.72],[26,7.98],[55,3.7]],"id":41419638},{"atb":[[32,2.72],[10.5,28.03],[26,11.25],[15.5,13.77]],"id":41419605},{"atb":[[9,24.97],[5,66.59],[11.5,3.26],[6,39.95],[14,2.72]],"id":41419634},{"atb":[[270,0.74],[80,3.26],[110,2.72],[120,1.67],[60,4.51]],"id":41419617},{"atb":[[16,13.31],[34,3.26],[11,26.63],[44,2.72],[27,7.68]],"id":41419613},{"atb":[[75,2.69],[20,14.02],[80,2.72],[55,3.26],[30,6.88]],"id":41419593},{"atb":[[65,2.72],[80,2.52],[42,6.49],[46,3.26],[210,0.95]],"id":41419655},{"atb":[[16.5,17.18],[42,3.26],[46,4.44],[23,9.07],[55,2.72]],"id":41419622},{"atb":[[9.6,3.26],[8.6,26.29],[11.5,2.72],[14,15.36],[6.6,47.57]],"id":41419589},{"atb":[[85,5.64],[44,6.19],[220,0.91],[120,2.72]],"id":41435527},{"atb":[[600,0.44],[700,0.28],[170,2.72],[850,0.23],[120,3.26]],"id":41419651},{"atb":[[34,2.72],[24,8.68],[9.8,30.27],[27,3.26],[14.5,14.8]],"id":41419601},{"atb":[[17.5,12.1],[19,3.26],[23,2.72],[12.5,23.16],[30,6.88]],"id":28546943},{"atb":[[16,17.76],[40,3.26],[44,4.64],[22,9.51],[50,2.72]],"id":41419626},{"atb":[[40,2.72],[42,4.87],[21,9.98],[30,3.26],[15.5,18.37]],"id":41419639},{"atb":[[12,3.26],[5.7,42.5],[8.4,26.99],[14.5,2.72],[4.7,71.99]],"id":41419606},{"atb":[[18,15.66],[40,3.26],[50,2.72],[26,7.98],[55,3.7]],"id":41419635},{"atb":[[65,3.12],[19,14.8],[44,3.26],[28,7.4],[60,2.72]],"id":41419602},{"atb":[[18.5,11.41],[11,23.24],[13.5,2.72],[8.4,35.99]],"id":41419585},{"atb":[[130,2.72],[310,0.64],[90,3.26],[210,1.27],[460,0.43]],"id":41419614},{"atb":[[32,3.26],[40,5.12],[20,10.51],[42,2.72],[15,19.02]],"id":41419610},{"atb":[[600,0.44],[150,3.26],[700,0.28],[200,2.72],[850,0.23]],"id":41419656},{"atb":[[42,8.14],[21,9.98],[55,2.72],[15.5,18.37]],"id":41419623},{"atb":[[75,2.72],[95,2.12],[48,5.66],[50,3.26],[240,0.83]],"id":41419652},{"atb":[[550,0.48],[650,0.3],[160,2.72],[800,0.25],[110,3.26]],"id":41435528},{"atb":[[65,3.12],[75,2.72],[19,14.8],[50,3.26],[28,7.4]],"id":41419619},{"atb":[[7.4,31.21],[6.8,3.26],[5.2,47.57],[7.8,2.72],[4.2,83.24]],"id":41419586},{"atb":[[65,3.12],[75,2.72],[19,14.8],[50,3.26],[28,7.4]],"id":41419598},{"atb":[[85,3.26],[100,2.01],[50,5.43],[120,2.72],[250,0.8]],"id":41419660},{"atb":[[18.5,15.22],[75,2.72],[50,3.26],[27,7.68],[60,3.38]],"id":41419594},{"atb":[[17.5,16.14],[42,3.26],[50,4.07],[25,8.32],[55,2.72]],"id":41419607},{"atb":[[16.5,17.18],[70,2.72],[46,4.44],[23,9.07],[48,3.26]],"id":28546950},{"atb":[[32,2.72],[10.5,28.03],[26,11.25],[15.5,13.77]],"id":41419636},{"atb":[[16,17.76],[36,3.26],[44,4.64],[22,9.51],[46,2.72]],"id":41419603},{"atb":[[75,2.69],[20,14.02],[80,2.72],[55,3.26],[30,6.88]],"id":41419615},{"atb":[[130,2.72],[140,1.43],[70,3.85],[290,0.69],[90,3.26]],"id":41419657},{"atb":[[260,0.77],[65,3.26],[90,2.72],[110,1.83],[55,4.93]],"id":41419624},{"atb":[[5.8,3.26],[3.95,90.29],[6.8,34.44],[4.9,51.22],[6.6,2.72]],"id":41419591},{"atb":[[34,8.07],[70,2.72],[170,1.18],[48,3.26],[60,3.38]],"id":41435525},{"atb":[[600,0.44],[700,0.28],[170,2.72],[850,0.23],[120,3.26]],"id":41419653},{"atb":[[19.5,10.8],[12,18.16],[25,3.26],[8.8,34.15],[30,2.72]],"id":41419620},{"atb":[[5.8,3.26],[3.7,98.66],[4.4,58.76],[6.6,2.72],[5.9,40.77]],"id":41419587},{"atb":[[9.6,23.23],[17,2.72],[5.3,61.94],[6.6,35.67],[14.5,3.26]],"id":41419599},{"atb":[[130,2.72],[310,0.64],[90,3.26],[210,1.27],[460,0.43]],"id":41419595},{"atb":[[9.6,30.97],[32,2.72],[23,9.07],[26,3.26],[14,15.36]],"id":41419608},{"atb":[[9.2,32.48],[21,9.98],[24,3.26],[13,16.64],[29,2.72]],"id":41419637},{"atb":[[18.5,15.22],[80,2.72],[27,7.68],[55,3.26],[60,3.38]],"id":41419616},{"atb":[[9.2,32.48],[21,9.98],[25,3.26],[13,16.64],[30,2.72]],"id":41419612},{"atb":[[16,13.31],[34,3.26],[11,26.63],[44,2.72],[27,7.68]],"id":41419592},{"atb":[[610,0.32],[85,3.26],[760,0.26],[120,2.72],[510,0.52]],"id":41435526},{"atb":[[260,0.77],[65,3.26],[90,2.72],[110,1.83],[55,4.93]],"id":41419621},{"atb":[[16,2.72],[18.5,11.41],[11,19.97],[13.5,3.26],[8.4,35.99]],"id":41419588},{"atb":[[65,3.12],[19,14.8],[44,3.26],[28,7.4],[60,2.72]],"id":41419600},{"atb":[[270,0.74],[75,3.26],[100,2.72],[120,1.67],[60,4.51]],"id":41419596},{"atb":[[600,0.44],[150,3.26],[700,0.28],[200,2.72],[850,0.23]],"id":41419658}],"con":true,"img":false}]}
{"op":"mcm","clk":"5353347391","pt":1646213424762,"mc":[{"id":"1.195503869","rc":[{"atb":[[10.5,0],[26,3.26],[15.5,0]],"id":41419605},{"atb":[[75,0],[20,0],[30,0]],"id":41419593},{"atb":[[8.6,0],[14,0],[6.6,0]],"id":41419589},{"atb":[[24,0],[9.8,0],[14.5,0]],"id":41419601},{"atb":[[17.5,0],[12.5,0],[30,0]],"id":28546943},{"atb":[[65,0],[19,0],[28,0]],"id":41419602},{"atb":[[18.5,0],[11,3.26],[8.4,0]],"id":41419585},{"atb":[[7.4,0],[5.2,0],[4.2,0]],"id":41419586},{"atb":[[65,0],[19,0],[28,0]],"id":41419598},{"atb":[[18.5,0],[27,0],[60,0]],"id":41419594},{"atb":[[16.5,0],[46,0],[23,0]],"id":28546950},{"atb":[[16,0],[44,0],[22,0]],"id":41419603},{"atb":[[3.95,0],[6.8,0],[4.9,0]],"id":41419591},{"atb":[[3.7,0],[4.4,0],[5.9,0]],"id":41419587},{"atb":[[9.6,0],[5.3,0],[6.6,0]],"id":41419599},{"atb":[[310,0],[210,0],[460,0]],"id":41419595},{"atb":[[16,0],[11,0],[27,0]],"id":41419592},{"atb":[[18.5,0],[11,0],[8.4,0]],"id":41419588},{"atb":[[65,0],[19,0],[28,0]],"id":41419600},{"atb":[[270,0],[120,0],[60,0]],"id":41419596}],"con":true,"img":false}]}
{"op":"mcm","clk":"5353347403","pt":1646213424929,"mc":[{"id":"1.195503869","rc":[{"atb":[[17.5,0],[50,0],[25,0]],"id":41419609},{"atb":[[9,0],[5,0],[6,0]],"id":41419634},{"atb":[[270,0],[120,0],[60,0]],"id":41419617},{"atb":[[16,0],[11,0],[27,0]],"id":41419613},{"atb":[[16.5,0],[46,0],[23,0]],"id":41419622},{"atb":[[16,0],[44,0],[22,0]],"id":41419626},{"atb":[[5.7,0],[8.4,0],[4.7,0]],"id":41419606},{"atb":[[18,0],[26,0],[55,0]],"id":41419635},{"atb":[[310,0],[210,0],[460,0]],"id":41419614},{"atb":[[40,0],[20,0],[15,0]],"id":41419610},{"atb":[[42,3.26],[21,0],[15.5,0]],"id":41419623},{"atb":[[65,0],[19,0],[28,0]],"id":41419619},{"atb":[[17.5,0],[50,0],[25,0]],"id":41419607},{"atb":[[75,0],[20,0],[30,0]],"id":41419615},{"atb":[[260,0],[110,0],[55,0]],"id":41419624},{"atb":[[19.5,0],[12,0],[8.8,0]],"id":41419620},{"atb":[[9.6,0],[23,0],[14,0]],"id":41419608},{"atb":[[18.5,0],[27,0],[60,0]],"id":41419616},{"atb":[[9.2,0],[21,0],[13,0]],"id":41419612},{"atb":[[260,0],[110,0],[55,0]],"id":41419621}],"con":true,"img":false}]}
{"op":"mcm","clk":"5353347409","pt":1646213425029,"mc":[{"id":"1.195503869","rc":[{"atb":[[18,0],[26,0],[55,0]],"id":41419638},{"atb":[[80,0],[42,0],[210,0]],"id":41419655},{"atb":[[85,3.26],[44,0],[220,0]],"id":41435527},{"atb":[[600,0],[700,0],[850,0]],"id":41419651},{"atb":[[42,0],[21,0],[15.5,0]],"id":41419639},{"atb":[[600,0],[700,0],[850,0]],"id":41419656},{"atb":[[95,0],[48,0],[240,0]],"id":41419652},{"atb":[[550,0],[650,0],[800,0]],"id":41435528},{"atb":[[100,0],[50,0],[250,0]],"id":41419660},{"atb":[[10.5,0],[26,3.26],[15.5,0]],"id":41419636},{"atb":[[140,0],[70,0],[290,0]],"id":41419657},{"atb":[[34,0],[170,0],[60,0]],"id":41435525},{"atb":[[600,0],[700,0],[850,0]],"id":41419653},{"atb":[[9.2,0],[21,0],[13,0]],"id":41419637},{"atb":[[610,0],[760,0],[510,0]],"id":41435526},{"atb":[[600,0],[700,0],[850,0]],"id":41419658}],"con":true,"img":false}]}
{"op":"mcm","clk":"5353348298","pt":1646213442874,"mc":[{"id":"1.195503869","rc":[{"atb":[[17.5,16.14],[50,4.07],[25,8.32]],"id":41419609},{"atb":[[10.5,28.03],[26,11.25],[15.5,13.77]],"id":41419605},{"atb":[[75,2.69],[20,14.02],[30,6.88]],"id":41419593},{"atb":[[8.6,26.29],[14,15.36],[6.6,47.57]],"id":41419589},{"atb":[[600,0.44],[700,0.28],[850,0.23]],"id":41419651},{"atb":[[24,8.68],[9.8,30.27],[14.5,14.8]],"id":41419601},{"atb":[[17.5,12.1],[12.5,23.16],[30,6.88]],"id":28546943},{"atb":[[5.7,42.5],[8.4,26.99],[4.7,71.99]],"id":41419606},{"atb":[[65,3.12],[19,14.8],[28,7.4]],"id":41419602},{"atb":[[18.5,11.41],[11,23.24],[8.4,35.99]],"id":41419585},{"atb":[[40,5.12],[20,10.51],[15,19.02]],"id":41419610},{"atb":[[95,2.12],[48,5.66],[240,0.83]],"id":41419652},{"atb":[[7.4,31.21],[5.2,47.57],[4.2,83.24]],"id":41419586},{"atb":[[65,3.12],[19,14.8],[28,7.4]],"id":41419598},{"atb":[[18.5,15.22],[27,7.68],[60,3.38]],"id":41419594},{"atb":[[17.5,16.14],[50,4.07],[25,8.32]],"id":41419607},{"atb":[[16,17.76],[44,4.64],[22,9.51]],"id":41419603},{"atb":[[3.95,90.29],[6.8,34.44],[4.9,51.22]],"id":41419591},{"atb":[[34,8.07],[170,1.18],[60,3.38]],"id":41435525},{"atb":[[3.7,98.66],[4.4,58.76],[5.9,40.77]],"id":41419587},{"atb":[[9.6,23.23],[5.3,61.94],[6.6,35.67]],"id":41419599},{"atb":[[310,0.64],[210,1.27],[460,0.43]],"id":41419595},{"atb":[[9.6,30.97],[23,9.07],[14,15.36]],"id":41419608},{"atb":[[9.2,32.48],[21,9.98],[13,16.64]],"id":41419612},{"atb":[[16,13.31],[11,26.63],[27,7.68]],"id":41419592},{"atb":[[18.5,11.41],[11,19.97],[8.4,35.99]],"id":41419588},{"atb":[[65,3.12],[19,14.8],[28,7.4]],"id":41419600},{"atb":[[270,0.74],[120,1.67],[60,4.51]],"id":41419596}],"con":true,"img":false}]}
{"op":"mcm","clk":"5353348302","pt":1646213442986,"mc":[{"id":"1.195503869","rc":[{"atb":[[18,15.66],[26,7.98],[55,3.7]],"id":41419638},{"atb":[[9,24.97],[5,66.59],[6,39.95]],"id":41419634},{"atb":[[270,0.74],[120,1.67],[60,4.51]],"id":41419617},{"atb":[[16,13.31],[11,26.63],[27,7.68]],"id":41419613},{"atb":[[80,2.52],[42,6.49],[210,0.95]],"id":41419655},{"atb":[[16.5,17.18],[46,4.44],[23,9.07]],"id":41419622},{"atb":[[85,5.64],[44,6.19],[220,0.91]],"id":41435527},{"atb":[[16,17.76],[44,4.64],[22,9.51]],"id":41419626},{"atb":[[42,4.87],[21,9.98],[15.5,18.37]],"id":41419639},{"atb":[[18,15.66],[26,7.98],[55,3.7]],"id":41419635},{"atb":[[310,0.64],[210,1.27],[460,0.43]],"id":41419614},{"atb":[[600,0.44],[700,0.28],[850,0.23]],"id":41419656},{"atb":[[42,8.14],[21,9.98],[15.5,18.37]],"id":41419623},{"atb":[[550,0.48],[650,0.3],[800,0.25]],"id":41435528},{"atb":[[65,3.12],[19,14.8],[28,7.4]],"id":41419619},{"atb":[[100,2.01],[50,5.43],[250,0.8]],"id":41419660},{"atb":[[16.5,17.18],[46,4.44],[23,9.07]],"id":28546950},{"atb":[[10.5,28.03],[26,11.25],[15.5,13.77]],"id":41419636},{"atb":[[75,2.69],[20,14.02],[30,6.88]],"id":41419615},{"atb":[[140,1.43],[70,3.85],[290,0.69]],"id":41419657},{"atb":[[260,0.77],[110,1.83],[55,4.93]],"id":41419624},{"atb":[[600,0.44],[700,0.28],[850,0.23]],"id":41419653},{"atb":[[19.5,10.8],[12,18.16],[8.8,34.15]],"id":41419620},{"atb":[[9.2,32.48],[21,9.98],[13,16.64]],"id":41419637},{"atb":[[18.5,15.22],[27,7.68],[60,3.38]],"id":41419616},{"atb":[[610,0.32],[760,0.26],[510,0.52]],"id":41435526},{"atb":[[260,0.77],[110,1.83],[55,4.93]],"id":41419621},{"atb":[[600,0.44],[700,0.28],[850,0.23]],"id":41419658}],"con":true,"img":false}]}
{"op":"mcm","clk":"5353349464","pt":1646213465475,"mc":[{"id":"1.195503869","rc":[{"atb":[[32,0],[26,7.98]],"id":41419605},{"atb":[[80,0],[55,0]],"id":41419593},{"atb":[[34,0],[27,0]],"id":41419601},{"atb":[[44,0],[60,0]],"id":41419602},{"atb":[[130,0],[90,0]],"id":41419614},{"atb":[[75,0],[50,0]],"id":41419652},{"atb":[[80,0],[55,0]],"id":41419615},{"atb":[[170,0],[120,0]],"id":41419653},{"atb":[[17,0],[14.5,0]],"id":41419599},{"atb":[[130,0],[90,0]],"id":41419595},{"atb":[[32,0],[26,0]],"id":41419608},{"atb":[[75,0],[100,0]],"id":41419596},{"atb":[[150,0],[200,0]],"id":41419658}],"con":true,"img":false}]}
{"op":"mcm","clk":"5353349469","pt":1646213465580,"mc":[{"id":"1.195503869","rc":[{"atb":[[42,0],[55,0]],"id":41419622},{"atb":[[6.8,0],[7.8,0]],"id":41419586},{"atb":[[36,0],[46,0]],"id":41419603}],"con":true,"img":false}]}
{"op":"mcm","clk":"5353349510","pt":1646213466197,"mc":[{"id":"1.195503869","rc":[{"atb":[[34,2.72],[27,3.26]],"id":41419605},{"atb":[[85,2.72],[60,3.26]],"id":41419593},{"atb":[[36,2.72],[28,3.26]],"id":41419601},{"atb":[[65,5.84],[46,3.26]],"id":41419602},{"atb":[[140,2.72],[95,3.26]],"id":41419614},{"atb":[[80,2.72],[55,3.26]],"id":41419652},{"atb":[[18,2.72],[15.5,3.26]],"id":41419599},{"atb":[[140,2.72],[95,3.26]],"id":41419595},{"atb":[[34,2.72],[27,3.26]],"id":41419608},{"atb":[[80,3.26],[110,2.72]],"id":41419596}],"con":true,"img":false}]}
{"op":"mcm","clk":"5353349516","pt":1646213466300,"mc":[{"id":"1.195503869","rc":[{"atb":[[85,2.72],[60,3.26]],"id":41419615},{"atb":[[130,3.26],[180,2.72]],"id":41419653},{"atb":[[160,3.26],[210,2.72]],"id":41419658}],"con":true,"img":false}]}
{"op":"mcm","clk":"5353349526","pt":1646213466354,"mc":[{"id":"1.195503869","rc":[{"atb":[[44,3.26],[60,2.72]],"id":41419622},{"atb":[[7.2,3.26],[8.2,2.72]],"id":41419586},{"atb":[[38,3.26],[48,2.72]],"id":41419603}],"con":true,"img":false}]}
{"op":"mcm","clk":"5353417232","pt":1646214555347,"mc":[{"id":"1.195503869","rc":[{"atb":[[11,19.97],[13.5,0]],"id":41419585},{"atb":[[5.8,0],[6.6,0]],"id":41419591},{"atb":[[5.8,0],[6.6,0]],"id":41419587}],"con":true,"img":false}]}
{"op":"mcm","clk":"5353417277","pt":1646214556069,"mc":[{"id":"1.195503869","rc":[{"atb":[[12,2.72],[9.8,3.26]],"id":41419585},{"atb":[[6.4,2.72],[5.7,3.26]],"id":41419591},{"atb":[[6.4,2.72],[5.7,3.26]],"id":41419587}],"con":true,"img":false}]}
{"op":"mcm","clk":"5353449199","pt":1646215160248,"mc":[{"id":"1.195503869","rc":[{"atb":[[12,0],[9.8,0]],"id":41419585},{"atb":[[6.4,0],[5.7,0]],"id":41419591},{"atb":[[6.4,0],[5.7,0]],"id":41419587}],"con":true,"img":false}]}
{"op":"mcm","clk":"5353449230","pt":1646215160972,"mc":[{"id":"1.195503869","rc":[{"atb":[[11,23.24],[13.5,2.72]],"id":41419585},{"atb":[[5.8,3.26],[6.6,2.72]],"id":41419591},{"atb":[[5.8,3.26],[6.6,2.72]],"id":41419587}],"con":true,"img":false}]}
{"op":"mcm","clk":"5353497272","pt":1646215755305,"mc":[{"id":"1.195503869","rc":[{"atb":[[11,19.97],[13.5,0]],"id":41419585},{"atb":[[5.8,0],[6.6,0]],"id":41419591},{"atb":[[5.8,0],[6.6,0]],"id":41419587}],"con":true,"img":false}]}
{"op":"mcm","clk":"5353497338","pt":1646215756029,"mc":[{"id":"1.195503869","rc":[{"atb":[[12,2.72],[9.8,3.26]],"id":41419585},{"atb":[[6.4,2.72],[5.7,3.26]],"id":41419587}],"con":true,"img":false}]}
{"op":"mcm","clk":"5353497345","pt":1646215756131,"mc":[{"id":"1.195503869","rc":[{"atb":[[6.4,2.72],[5.7,3.26]],"id":41419591}],"con":true,"img":false}]}
{"op":"mcm","clk":"5353498790","pt":1646215773340,"mc":[{"id":"1.195503869","rc":[{"atb":[[6.4,0],[5.7,0]],"id":41419587}],"con":true,"img":false}]}
{"op":"mcm","clk":"5353498860","pt":1646215774127,"mc":[{"id":"1.195503869","rc":[{"atb":[[5.8,3.26],[6.6,2.72]],"id":41419587}],"con":true,"img":false}]}
{"op":"mcm","clk":"5353555010","pt":1646216240263,"mc":[{"id":"1.195503869","rc":[{"atb":[[12,0],[9.8,0]],"id":41419585},{"atb":[[6.4,0],[5.7,0]],"id":41419591}],"con":true,"img":false}]}
{"op":"mcm","clk":"5353555116","pt":1646216241259,"mc":[{"id":"1.195503869","rc":[{"atb":[[11,23.24],[13.5,2.72]],"id":41419585},{"atb":[[5.8,3.26],[6.6,2.72]],"id":41419591}],"con":true,"img":false}]}
{"op":"mcm","clk":"5353631763","pt":1646216975295,"mc":[{"id":"1.195503869","rc":[{"atb":[[29,3.57]],"id":41419657},{"atb":[[28,3.7]],"id":41419596}],"con":true,"img":false}]}
{"op":"mcm","clk":"5353631775","pt":1646216975402,"mc":[{"id":"1.195503869","rc":[{"atb":[[25,12.49]],"id":41419609},{"atl":[[1000,2]],"id":41419609},{"atb":[[25,4.17]],"id":41419638},{"atl":[[1000,2]],"id":41419638},{"atb":[[14.5,7.41]],"id":41419605},{"atl":[[1000,2]],"id":41419605},{"atb":[[4.2,31.25]],"id":41419634},{"atl":[[480,2]],"id":41419634},{"atb":[[28,3.7]],"id":41419617},{"atb":[[9.6,11.63]],"id":41419613},{"atl":[[900,2]],"id":41419613},{"atb":[[27,3.85]],"id":41419593},{"atb":[[28,3.7]],"id":41419655},{"atb":[[12.5,8.7]],"id":41419622},{"atl":[[1000,2]],"id":41419622},{"atb":[[3.85,30.74]],"id":41419589},{"atl":[[410,2]],"id":41419589},{"atb":[[29,3.57]],"id":41435527},{"atb":[[29,2]],"id":41419651},{"atb":[[14,7.69]],"id":41419601},{"atl":[[1000,2]],"id":41419601},{"atb":[[12.5,31.86]],"id":28546943},{"atl":[[970,2]],"id":28546943},{"atb":[[12.5,8.7]],"id":41419626},{"atl":[[1000,2]],"id":41419626},{"atb":[[12.5,8.7]],"id":41419639},{"atl":[[990,2]],"id":41419639},{"atb":[[4.3,30.3]],"id":41419606},{"atl":[[490,2]],"id":41419606},{"atb":[[14.5,7.4]],"id":41419635},{"atl":[[1000,2]],"id":41419635},{"atb":[[27,3.85]],"id":41419602},{"atb":[[3.55,34.67]],"id":41419585},{"atl":[[410,2]],"id":41419585},{"atb":[[28,2.56]],"id":41419614},{"atb":[[12.5,8.7]],"id":41419610},{"atl":[[1000,2]],"id":41419610},{"atb":[[29,2]],"id":41419656},{"atb":[[12.5,8.7]],"id":41419623},{"atl":[[1000,2]],"id":41419623},{"atb":[[29,3.57]],"id":41419652},{"atb":[[29,2]],"id":41435528},{"atb":[[26,4]],"id":41419619},{"atb":[[3.05,48.78]],"id":41419586},{"atl":[[270,2]],"id":41419586},{"atb":[[26,4]],"id":41419598},{"atl":[[1000,2]],"id":41419598},{"atb":[[29,3.57]],"id":41419660},{"atb":[[26,4]],"id":41419594},{"atl":[[1000,2]],"id":41419594},{"atb":[[15.5,6.9]],"id":41419607},{"atl":[[1000,2]],"id":41419607},{"atb":[[12.5,8.7]],"id":28546950},{"atb":[[8.4,13.51]],"id":41419636},{"atl":[[850,2]],"id":41419636},{"atb":[[26,4]],"id":41419603},{"atb":[[27,3.85]],"id":41419615},{"atb":[[12.5,5.44]],"id":41419624},{"atb":[[2.84,54.35]],"id":41419591},{"atl":[[130,2]],"id":41419591},{"atb":[[29,3.57]],"id":41435525},{"atb":[[29,2]],"id":41419653},{"atb":[[7,16.67]],"id":41419620},{"atl":[[720,2]],"id":41419620},{"atb":[[2.7,58.82]],"id":41419587},{"atl":[[160,2]],"id":41419587},{"atb":[[6.2,19.23]],"id":41419599},{"atl":[[620,2]],"id":41419599},{"atb":[[28,2.56]],"id":41419595},{"atb":[[8.4,13.51]],"id":41419608},{"atl":[[860,2]],"id":41419608},{"atb":[[6.8,17.24]],"id":41419637},{"atl":[[710,2]],"id":41419637},{"atb":[[26,4]],"id":41419616},{"atb":[[7,16.67]],"id":41419612},{"atl":[[720,2]],"id":41419612},{"atb":[[8.6,13.16]],"id":41419592},{"atl":[[860,2]],"id":41419592},{"atb":[[12.5,2]],"id":41435526},{"atb":[[12.5,5.44]],"id":41419621},{"atb":[[4.4,22.84]],"id":41419588},{"atl":[[490,2]],"id":41419588},{"atb":[[26,4]],"id":41419600},{"atb":[[29,2]],"id":41419658}],"con":true,"img":false}]}
{"op":"mcm","clk":"5353631790","pt":1646216975609,"mc":[{"id":"1.195503869","rc":[{"atl":[[1000,0]],"id":41419622},{"atl":[[720,0],[710,2]],"id":41419620}],"con":true,"img":false}]}
{"op":"mcm","clk":"5353631797","pt":1646216975711,"mc":[{"id":"1.195503869","rc":[{"atb":[[5.8,0],[6.6,0]],"id":41419587}],"con":true,"img":false}]}
{"op":"mcm","clk":"5353631834","pt":1646216976081,"mc":[{"id":"1.195503869","rc":[{"atb":[[11,19.97],[13.5,0]],"id":41419585},{"atb":[[5.8,0],[6.6,0]],"id":41419591}],"con":true,"img":false}]}
{"op":"mcm","clk":"5353631879","pt":1646216976597,"mc":[{"id":"1.195503869","rc":[{"atb":[[6.4,2.72],[5.7,3.26]],"id":41419587}],"con":true,"img":false}]}
{"op":"mcm","clk":"5353631911","pt":1646216977013,"mc":[{"id":"1.195503869","rc":[{"atb":[[6.4,2.72],[5.7,3.26]],"id":41419591}],"con":true,"img":false}]}
{"op":"mcm","clk":"5353631941","pt":1646216977326,"mc":[{"id":"1.195503869","rc":[{"atb":[[12,2.72],[9.8,3.26]],"id":41419585}],"con":true,"img":false}]}
{"op":"mcm","clk":"5353634287","pt":1646217003060,"mc":[{"id":"1.195503869","rc":[{"atl":[[1000,2]],"id":41419622},{"atl":[[1000,2]],"id":41419619}],"con":true,"img":false}]}
{"op":"mcm","clk":"5353634311","pt":1646217003228,"mc":[{"id":"1.195503869","rc":[{"atb":[[6.4,0],[5.7,0]],"id":41419591}],"con":true,"img":false}]}
{"op":"mcm","clk":"5353634374","pt":1646217003954,"mc":[{"id":"1.195503869","rc":[{"atb":[[5.8,3.26],[6.6,2.72]],"id":41419591}],"con":true,"img":false}]}
{"op":"mcm","clk":"5353635232","pt":1646217012268,"mc":[{"id":"1.195503869","rc":[{"atl":[[960,2],[1000,0]],"id":41419605},{"atl":[[460,2],[480,0]],"id":41419634},{"atl":[[860,2],[900,0]],"id":41419613},{"atl":[[950,2],[1000,0]],"id":41419601},{"atl":[[920,2],[970,0]],"id":28546943},{"atl":[[940,2],[990,0]],"id":41419639},{"atl":[[470,2],[490,0]],"id":41419606},{"atl":[[970,2],[1000,0]],"id":41419635},{"atl":[[410,0],[400,2]],"id":41419585},{"atl":[[980,2],[1000,0]],"id":41419610},{"atl":[[270,0],[250,2]],"id":41419586},{"atl":[[980,2],[1000,0]],"id":41419607},{"atl":[[820,2],[850,0]],"id":41419636},{"atb":[[26,0],[29,3.57]],"id":41419603},{"atb":[[2.84,0],[2.98,50.51]],"id":41419591},{"atl":[[130,0],[110,2]],"id":41419591},{"atb":[[2.84,54.35],[2.7,0]],"id":41419587},{"atl":[[130,2],[160,0]],"id":41419587},{"atl":[[600,2],[620,0]],"id":41419599},{"atl":[[820,2],[860,0]],"id":41419608},{"atl":[[680,2],[710,0]],"id":41419637},{"atl":[[700,2],[720,0]],"id":41419612},{"atl":[[820,2],[860,0]],"id":41419592},{"atl":[[490,0],[480,2]],"id":41419588}],"con":true,"img":false}]}
{"op":"mcm","clk":"5353635245","pt":1646217012319,"mc":[{"id":"1.195503869","rc":[{"atl":[[700,2],[710,0]],"id":41419620}],"con":true,"img":false}]}
{"op":"mcm","clk":"5353645608","pt":1646217122992,"mc":[{"id":"1.195503869","rc":[{"atl":[[1000,0]],"id":41419619},{"atl":[[1000,0]],"id":41419598},{"atl":[[1000,0]],"id":41419594},{"atb":[[2.98,0],[2.84,54.35]],"id":41419591},{"atb":[[2.84,0],[2.7,58.82]],"id":41419587}],"con":true,"img":false}]}
{"op":"mcm","clk":"5353665580","pt":1646217338759,"mc":[{"id":"1.195503869","rc":[{"atb":[[6.4,0],[5.7,0]],"id":41419587}],"con":true,"img":false}]}
{"op":"mcm","clk":"5353665637","pt":1646217339341,"mc":[{"id":"1.195503869","rc":[{"atb":[[12,0]],"id":41419585}],"con":true,"img":false}]}
{"op":"mcm","clk":"5353665648","pt":1646217339440,"mc":[{"id":"1.195503869","rc":[{"atb":[[9.8,0]],"id":41419585}],"con":true,"img":false}]}
{"op":"mcm","clk":"5353665659","pt":1646217339548,"mc":[{"id":"1.195503869","rc":[{"atb":[[5.8,3.26],[6.6,2.72]],"id":41419587}],"con":true,"img":false}]}
{"op":"mcm","clk":"5353665720","pt":1646217340178,"mc":[{"id":"1.195503869","rc":[{"atb":[[11,23.24]],"id":41419585}],"con":true,"img":false}]}
{"op":"mcm","clk":"5353665741","pt":1646217340339,"mc":[{"id":"1.195503869","rc":[{"atb":[[13.5,2.72]],"id":41419585}],"con":true,"img":false}]}
{"op":"mcm","clk":"5353700593","pt":1646217663022,"mc":[{"id":"1.195503869","rc":[{"atb":[[7.2,0],[8.2,0]],"id":41419586}],"con":true,"img":false}]}
{"op":"mcm","clk":"5353700659","pt":1646217663717,"mc":[{"id":"1.195503869","rc":[{"atb":[[8,2.72],[7,3.26]],"id":41419586}],"con":true,"img":false}]}
{"op":"mcm","clk":"5353734121","pt":1646217963146,"mc":[{"id":"1.195503869","rc":[{"atb":[[8,0],[7,0]],"id":41419586}],"con":true,"img":false}]}
{"op":"mcm","clk":"5353734185","pt":1646217963829,"mc":[{"id":"1.195503869","rc":[{"atb":[[7.2,3.26],[8.2,2.72]],"id":41419586}],"con":true,"img":false}]}
{"op":"mcm","clk":"5353772791","pt":1646218306225,"mc":[{"id":"1.195503869","rc":[{"atb":[[23,13.62],[12.5,0]],"id":41419622},{"atb":[[23,4.55],[29,0]],"id":41435527},{"atb":[[23,2.45],[29,0]],"id":41419651},{"atb":[[18,5.88]],"id":41419626},{"atb":[[12.5,0],[15,26.16]],"id":41419610},{"atb":[[23,2.45],[29,0]],"id":41419656},{"atb":[[21,14.98],[12.5,0]],"id":41419623},{"atb":[[23,2.49],[29,0]],"id":41435528},{"atb":[[23,4.55],[29,0]],"id":41419660},{"atb":[[23,13.62],[12.5,0]],"id":28546950},{"atb":[[23,4.55],[12.5,0]],"id":41419624},{"atb":[[2.72,58.14],[2.84,0]],"id":41419591},{"atb":[[23,4.55],[29,0]],"id":41435525},{"atb":[[23,2.45],[29,0]],"id":41419653},{"atb":[[23,2],[12.5,0]],"id":41435526},{"atb":[[23,4.55],[12.5,0]],"id":41419621},{"atb":[[23,2.45],[29,0]],"id":41419658}],"con":true,"img":false}]}
{"op":"mcm","clk":"5353772803","pt":1646218306327,"mc":[{"id":"1.195503869","rc":[{"atb":[[12.5,0]],"id":41419626}],"con":true,"img":false}]}
{"op":"mcm","clk":"5353773068","pt":1646218310022,"mc":[{"id":"1.195503869","rc":[{"atb":[[18.5,5.71]],"id":41419605},{"atb":[[9.6,0],[13.5,8]],"id":41419613},{"atl":[[1000,0]],"id":41419622},{"atb":[[17.5,6.06]],"id":41419601},{"atb":[[12.5,0],[15,7.14]],"id":41419639},{"atl":[[940,2],[970,0]],"id":41419635},{"atb":[[3.85,34.67],[3.55,0]],"id":41419585},{"atl":[[340,2],[400,0]],"id":41419585},{"atl":[[1000,2]],"id":41419598},{"atl":[[1000,2]],"id":41419594},{"atl":[[950,2],[980,0]],"id":41419607},{"atb":[[10,11.11],[8.4,0]],"id":41419636},{"atb":[[2.8,55.56],[2.7,0]],"id":41419587},{"atb":[[10,11.11],[8.4,0]],"id":41419608},{"atl":[[760,2],[820,0]],"id":41419592},{"atb":[[5,22.84],[4.4,0]],"id":41419588}],"con":true,"img":false}]}
{"op":"mcm","clk":"5353773079","pt":1646218310122,"mc":[{"id":"1.195503869","rc":[{"atb":[[14.5,0]],"id":41419605},{"atb":[[14,0]],"id":41419601}],"con":true,"img":false}]}
{"op":"mcm","clk":"5353773092","pt":1646218310330,"mc":[{"id":"1.195503869","rc":[{"atb":[[5.8,0],[6.6,0]],"id":41419587}],"con":true,"img":false}]}
{"op":"mcm","clk":"5353773120","pt":1646218310644,"mc":[{"id":"1.195503869","rc":[{"atb":[[11,19.97],[13.5,0]],"id":41419585},{"atb":[[5.8,0],[6.6,0]],"id":41419591}],"con":true,"img":false}]}
{"op":"mcm","clk":"5353773155","pt":1646218311060,"mc":[{"id":"1.195503869","rc":[{"atb":[[6.4,2.72],[5.7,3.26]],"id":41419587}],"con":true,"img":false}]}
{"op":"mcm","clk":"5353773173","pt":1646218311322,"mc":[{"id":"1.195503869","rc":[{"atb":[[12,2.72],[9.8,3.26]],"id":41419585},{"atb":[[6.4,2.72],[5.7,3.26]],"id":41419591}],"con":true,"img":false}]}
{"op":"mcm","clk":"5353774073","pt":1646218322949,"mc":[{"id":"1.195503869","rc":[{"atb":[[18.5,0],[15.5,20.67]],"id":41419605},{"atb":[[10.5,10.53],[13.5,0]],"id":41419613},{"atl":[[1000,2]],"id":41419622},{"atl":[[940,0],[970,2]],"id":41419635},{"atl":[[1000,2]],"id":41419619},{"atl":[[950,0],[980,2]],"id":41419607},{"atb":[[7.2,16.13],[6.2,0]],"id":41419599},{"atl":[[600,0],[580,2]],"id":41419599},{"atl":[[760,0],[820,2]],"id":41419592}],"con":true,"img":false}]}
{"op":"mcm","clk":"5353774095","pt":1646218323261,"mc":[{"id":"1.195503869","rc":[{"atb":[[6.4,0],[5.7,0]],"id":41419587}],"con":true,"img":false}]}
{"op":"mcm","clk":"5353774146","pt":1646218323941,"mc":[{"id":"1.195503869","rc":[{"atb":[[5.8,3.26],[6.6,2.72]],"id":41419587}],"con":true,"img":false}]}
{"op":"mcm","clk":"5353774591","pt":1646218329747,"mc":[{"id":"1.195503869","rc":[{"atb":[[2.72,0],[2.84,54.35]],"id":41419591}],"con":true,"img":false}]}
{"op":"mcm","clk":"5353783999","pt":1646218442953,"mc":[{"id":"1.195503869","rc":[{"atb":[[17.5,0],[14,7.69]],"id":41419601},{"atl":[[1000,0]],"id":41419619},{"atl":[[1000,0]],"id":41419598},{"atb":[[10,0],[8.4,13.51]],"id":41419636},{"atb":[[2.72,58.14],[2.84,0]],"id":41419591},{"atb":[[8.4,13.51]],"id":41419608},{"atb":[[5,0],[4.4,29.41]],"id":41419588}],"con":true,"img":false}]}
{"op":"mcm","clk":"5353784011","pt":1646218443057,"mc":[{"id":"1.195503869","rc":[{"atl":[[1000,0]],"id":41419594},{"atb":[[10,0]],"id":41419608}],"con":true,"img":false}]}
{"op":"mcm","clk":"5353794804","pt":1646218539906,"mc":[{"id":"1.195503869","rc":[{"atb":[[12,0],[9.8,0]],"id":41419585},{"atb":[[6.4,0],[5.7,0]],"id":41419591}],"con":true,"img":false}]}
{"op":"mcm","clk":"5353794912","pt":1646218540691,"mc":[{"id":"1.195503869","rc":[{"atb":[[11,23.24],[13.5,2.72]],"id":41419585},{"atb":[[5.8,3.26],[6.6,2.72]],"id":41419591}],"con":true,"img":false}]}
{"op":"mcm","clk":"5353814610","pt":1646218743011,"mc":[{"id":"1.195503869","rc":[{"atb":[[17,6.25],[14,0]],"id":41419601},{"atl":[[930,2],[970,0]],"id":41419635},{"atl":[[1000,2]],"id":41419619},{"atl":[[1000,2]],"id":41419598},{"atl":[[1000,2]],"id":41419594},{"atl":[[940,2],[980,0]],"id":41419607},{"atb":[[9.6,11.63],[8.4,0]],"id":41419636},{"atb":[[2.72,0],[2.84,54.35]],"id":41419591},{"atb":[[9.8,11.36],[8.4,0]],"id":41419608},{"atl":[[750,2],[820,0]],"id":41419592}],"con":true,"img":false}]}
{"op":"mcm","clk":"5353814638","pt":1646218743287,"mc":[{"id":"1.195503869","rc":[{"atb":[[11,19.97],[13.5,0]],"id":41419585}],"con":true,"img":false}]}
{"op":"mcm","clk":"5353814704","pt":1646218743994,"mc":[{"id":"1.195503869","rc":[{"atb":[[12,2.72],[9.8,3.26]],"id":41419585}],"con":true,"img":false}]}
{"op":"mcm","clk":"5353826669","pt":1646218863039,"mc":[{"id":"1.195503869","rc":[{"atb":[[17.5,16.14],[42,3.27],[50,4.07],[25,12.49],[55,2.72]],"id":41419609},{"atb":[[18,15.66],[40,3.27],[50,2.72],[26,7.98],[55,3.7]],"id":41419638},{"atb":[[34,2.72],[10.5,28.04],[26,7.98],[27,3.27],[15.5,20.67]],"id":41419605},{"atb":[[9,24.97],[5,66.6],[11.5,3.27],[6,39.96],[14,2.72]],"id":41419634},{"atb":[[80,3.27],[110,2.72],[60,4.51]],"id":41419617},{"atb":[[16,13.32],[34,3.27],[44,2.72],[11,26.64],[27,7.68]],"id":41419613},{"atb":[[75,2.69],[20,14.02],[85,2.72],[60,3.27],[30,6.88]],"id":41419593},{"atb":[[65,2.72],[80,2.52],[42,6.49],[46,3.27]],"id":41419655},{"atb":[[16.5,17.18],[44,3.27],[46,4.44],[23,13.63],[60,2.72]],"id":41419622},{"atl":[[1000,0]],"id":41419622},{"atb":[[9.6,3.27],[8.6,26.29],[11.5,2.72],[14,15.36],[6.6,47.57]],"id":41419589},{"atb":[[85,5.64],[44,6.19],[120,2.72]],"id":41435527},{"atb":[[170,2.72],[120,3.27]],"id":41419651},{"atb":[[36,2.72],[24,8.68],[9.8,30.27],[28,3.27],[14.5,14.8]],"id":41419601},{"atb":[[17.5,12.11],[19,3.27],[23,2.72],[12.5,31.86],[30,6.88]],"id":28546943},{"atb":[[16,17.76],[40,3.27],[44,4.64],[22,9.51],[50,2.72]],"id":41419626},{"atb":[[40,2.72],[42,4.87],[21,9.99],[30,3.27],[15.5,18.37]],"id":41419639},{"atb":[[12,3.27],[5.7,42.51],[14.5,2.72],[8.4,27],[4.7,72]],"id":41419606},{"atb":[[18,15.66],[40,3.27],[50,2.72],[26,7.98],[55,3.7]],"id":41419635},{"atb":[[65,5.84],[19,14.8],[46,3.27],[28,7.4]],"id":41419602},{"atb":[[18.5,11.41],[11,19.98],[12,2.72],[9.8,3.27],[8.4,35.99]],"id":41419585},{"atb":[[140,2.72],[95,3.27]],"id":41419614},{"atb":[[32,3.27],[40,5.12],[20,10.51],[42,2.72],[15,26.16]],"id":41419610},{"atb":[[150,3.27],[200,2.72]],"id":41419656},{"atb":[[42,8.14],[21,14.99],[55,2.72],[15.5,18.37]],"id":41419623},{"atb":[[80,2.72],[95,2.12],[48,5.66],[55,3.27]],"id":41419652},{"atb":[[160,2.72],[110,3.27]],"id":41435528},{"atb":[[65,3.12],[75,2.72],[19,14.8],[50,3.27],[28,7.4]],"id":41419619},{"atl":[[1000,0]],"id":41419619},{"atb":[[7.2,3.27],[8.2,2.72],[7.4,31.21],[5.2,47.57],[4.2,83.25]],"id":41419586},{"atb":[[65,3.12],[75,2.72],[19,14.8],[50,3.27],[28,7.4]],"id":41419598},{"atb":[[85,3.27],[100,2.01],[50,5.43],[120,2.72]],"id":41419660},{"atb":[[75,2.72],[18.5,15.22],[50,3.27],[27,7.68],[60,3.38]],"id":41419594},{"atb":[[17.5,16.14],[42,3.27],[50,4.07],[25,8.32],[55,2.72]],"id":41419607},{"atb":[[16.5,17.18],[70,2.72],[46,4.44],[23,13.63],[48,3.27]],"id":28546950},{"atb":[[32,2.72],[10.5,28.04],[26,11.26],[15.5,13.77]],"id":41419636},{"atb":[[16,17.76],[38,3.27],[44,4.64],[22,9.51],[48,2.72]],"id":41419603},{"atb":[[75,2.69],[20,14.02],[85,2.72],[60,3.27],[30,6.88]],"id":41419615},{"atb":[[130,2.72],[70,3.85],[90,3.27]],"id":41419657},{"atb":[[65,3.27],[90,2.72],[55,4.93]],"id":41419624},{"atb":[[2.72,58.14],[5.8,3.27],[3.95,90.3],[6.8,34.45],[4.9,51.23],[2.84,0],[6.6,2.72]],"id":41419591},{"atb":[[70,2.72],[34,8.07],[48,3.27],[60,3.38]],"id":41435525},{"atb":[[130,3.27],[180,2.72]],"id":41419653},{"atb":[[19.5,10.8],[12,18.16],[25,3.27],[8.8,34.15],[30,2.72]],"id":41419620},{"atb":[[5.8,3.27],[3.7,98.67],[4.4,58.76],[6.6,2.72],[5.9,40.77]],"id":41419587},{"atb":[[9.6,23.23],[18,2.72],[5.3,61.95],[6.6,35.67],[15.5,3.27]],"id":41419599},{"atb":[[140,2.72],[95,3.27]],"id":41419595},{"atb":[[9.6,30.97],[34,2.72],[23,9.08],[27,3.27],[14,15.36]],"id":41419608},{"atb":[[9.2,32.48],[21,9.99],[24,3.27],[13,16.65],[29,2.72]],"id":41419637},{"atb":[[18.5,15.22],[80,2.72],[55,3.27],[27,7.68],[60,3.38]],"id":41419616},{"atb":[[9.2,32.48],[21,9.99],[25,3.27],[13,16.65],[30,2.72]],"id":41419612},{"atb":[[16,13.32],[34,3.27],[7.2,16.13],[8.6,0],[44,2.72],[11,26.64],[27,7.68]],"id":41419592},{"atb":[[85,3.27],[120,2.72]],"id":41435526},{"atb":[[65,3.27],[90,2.72],[55,4.93]],"id":41419621},{"atb":[[16,2.72],[18.5,11.41],[11,19.98],[13.5,3.27],[8.4,35.99]],"id":41419588},{"atb":[[65,3.12],[19,14.8],[44,3.27],[28,7.4],[60,2.72]],"id":41419600},{"atb":[[80,3.27],[110,2.72],[60,4.51]],"id":41419596},{"atb":[[160,3.27],[210,2.72]],"id":41419658}],"con":true,"img":false}]}
{"op":"mcm","clk":"5353900964","pt":1646219625212,"mc":[{"id":"1.195503869","rc":[{"atb":[[18.5,5.71],[15.5,13.77]],"id":41419605},{"atb":[[10.5,0],[13.5,8]],"id":41419613},{"atb":[[18,0],[21,5]],"id":41419626},{"atb":[[5,25],[4.4,0]],"id":41419588}],"con":true,"img":false}]}
{"op":"mcm","clk":"5353901023","pt":1646219625835,"mc":[{"id":"1.195503869","rc":[{"atb":[[5.8,0],[6.6,0]],"id":41419591},{"atb":[[5.8,0],[6.6,0]],"id":41419587}],"con":true,"img":false}]}
{"op":"mcm","clk":"5353901089","pt":1646219626520,"mc":[{"id":"1.195503869","rc":[{"atb":[[6.4,2.72],[5.7,3.27]],"id":41419587}],"con":true,"img":false}]}
{"op":"mcm","clk":"5353901109","pt":1646219626748,"mc":[{"id":"1.195503869","rc":[{"atb":[[6.4,2.72],[5.7,3.27]],"id":41419591}],"con":true,"img":false}]}
{"op":"mcm","clk":"5353901874","pt":1646219633951,"mc":[{"id":"1.195503869","rc":[{"atb":[[34,0],[44,0]],"id":41419613},{"atb":[[40,0],[50,0]],"id":41419626}],"con":true,"img":false}]}
{"op":"mcm","clk":"5353901957","pt":1646219634734,"mc":[{"id":"1.195503869","rc":[{"atb":[[36,3.27],[46,2.72]],"id":41419613}],"con":true,"img":false}]}
{"op":"mcm","clk":"5353901967","pt":1646219634837,"mc":[{"id":"1.195503869","rc":[{"atb":[[42,3.27],[55,2.72]],"id":41419626}],"con":true,"img":false}]}
{"op":"mcm","clk":"5353908373","pt":1646219697745,"mc":[{"id":"1.195503869","rc":[{"atb":[[6.4,0],[6.8,0]],"id":41419591},{"atl":[[6.4,187.08]],"id":41419591},{"trd":[[6.4,5.45],[6.8,68.9]],"ltp":6.4,"tv":74.35,"id":41419591}],"con":true,"img":false}]}
{"op":"mcm","clk":"5353908393","pt":1646219697953,"mc":[{"id":"1.195503869","rc":[{"atl":[[18,5.88],[110,0]],"id":41419591}],"con":true,"img":false}]}
{"op":"mcm","clk":"5353908424","pt":1646219698220,"mc":[{"id":"1.195503869","rc":[{"atb":[[5.7,0]],"id":41419591}],"con":true,"img":false}]}
{"op":"mcm","clk":"5353908443","pt":1646219698426,"mc":[{"id":"1.195503869","rc":[{"atl":[[8.8,3.64]],"id":41419591}],"con":true,"img":false}]}
{"op":"mcm","clk":"5353908461","pt":1646219698632,"mc":[{"id":"1.195503869","rc":[{"atb":[[5,1.5]],"id":41419591}],"con":true,"img":false}]}
{"op":"mcm","clk":"5353908469","pt":1646219698739,"mc":[{"id":"1.195503869","rc":[{"atl":[[8.8,0]],"id":41419591}],"con":true,"img":false}]}
{"op":"mcm","clk":"5353908491","pt":1646219698948,"mc":[{"id":"1.195503869","rc":[{"atb":[[3.7,3.27]],"id":41419591}],"con":true,"img":false}]}
{"op":"mcm","clk":"5353908942","pt":1646219703077,"mc":[{"id":"1.195503869","marketDefinition":{"bspMarket":false,"turnInPlayEnabled":false,"persistenceEnabled":false,"marketBaseRate":7.0,"eventId":"31272499","eventTypeId":"4339","numberOfWinners":1,"bettingType":"ODDS","marketType":"EXACTA","marketTime":"2022-03-02T11:29:00.000Z","suspendTime":"2022-03-02T11:29:00.000Z","bspReconciled":false,"complete":true,"inPlay":false,"crossMatching":true,"runnersVoidable":false,"numberOfActiveRunners":56,"betDelay":0,"status":"OPEN","runners":[{"status":"ACTIVE","sortPriority":1,"id":41419585,"name":"1 - 2"},{"status":"ACTIVE","sortPriority":2,"id":41419586,"name":"1 - 3"},{"status":"ACTIVE","sortPriority":3,"id":41419587,"name":"1 - 4"},{"status":"ACTIVE","sortPriority":4,"id":41419588,"name":"1 - 5"},{"status":"ACTIVE","sortPriority":5,"id":41419589,"name":"1 - 6"},{"status":"ACTIVE","sortPriority":6,"id":41419591,"name":"1 - 8"},{"status":"ACTIVE","sortPriority":7,"id":28546943,"name":"1 - 9"},{"status":"ACTIVE","sortPriority":8,"id":41419592,"name":"2 - 1"},{"status":"ACTIVE","sortPriority":9,"id":41419593,"name":"2 - 3"},{"status":"ACTIVE","sortPriority":10,"id":41419594,"name":"2 - 4"},{"status":"ACTIVE","sortPriority":11,"id":41419595,"name":"2 - 5"},{"status":"ACTIVE","sortPriority":12,"id":41419596,"name":"2 - 6"},{"status":"ACTIVE","sortPriority":13,"id":41419598,"name":"2 - 8"},{"status":"ACTIVE","sortPriority":14,"id":41419651,"name":"2 - 9"},{"status":"ACTIVE","sortPriority":15,"id":41419599,"name":"3 - 1"},{"status":"ACTIVE","sortPriority":16,"id":41419600,"name":"3 - 2"},{"status":"ACTIVE","sortPriority":17,"id":41419601,"name":"3 - 4"},{"status":"ACTIVE","sortPriority":18,"id":41419602,"name":"3 - 5"},{"status":"ACTIVE","sortPriority":19,"id":41419603,"name":"3 - 6"},{"status":"ACTIVE","sortPriority":20,"id":41419605,"name":"3 - 8"},{"status":"ACTIVE","sortPriority":21,"id":41419652,"name":"3 - 9"},{"status":"ACTIVE","sortPriority":22,"id":41419606,"name":"4 - 1"},{"status":"ACTIVE","sortPriority":23,"id":41419607,"name":"4 - 2"},{"status":"ACTIVE","sortPriority":24,"id":41419608,"name":"4 - 3"},{"status":"ACTIVE","sortPriority":25,"id":41419609,"name":"4 - 5"},{"status":"ACTIVE","sortPriority":26,"id":41419610,"name":"4 - 6"},{"status":"ACTIVE","sortPriority":27,"id":41419612,"name":"4 - 8"},{"status":"ACTIVE","sortPriority":28,"id":41435525,"name":"4 - 9"},{"status":"ACTIVE","sortPriority":29,"id":41419613,"name":"5 - 1"},{"status":"ACTIVE","sortPriority":30,"id":41419614,"name":"5 - 2"},{"status":"ACTIVE","sortPriority":31,"id":41419615,"name":"5 - 3"},{"status":"ACTIVE","sortPriority":32,"id":41419616,"name":"5 - 4"},{"status":"ACTIVE","sortPriority":33,"id":41419617,"name":"5 - 6"},{"status":"ACTIVE","sortPriority":34,"id":41419619,"name":"5 - 8"},{"status":"ACTIVE","sortPriority":35,"id":41419653,"name":"5 - 9"},{"status":"ACTIVE","sortPriority":36,"id":41419620,"name":"6 - 1"},{"status":"ACTIVE","sortPriority":37,"id":41419621,"name":"6 - 2"},{"status":"ACTIVE","sortPriority":38,"id":41419622,"name":"6 - 3"},{"status":"ACTIVE","sortPriority":39,"id":41419623,"name":"6 - 4"},{"status":"ACTIVE","sortPriority":40,"id":41419624,"name":"6 - 5"},{"status":"ACTIVE","sortPriority":41,"id":41419626,"name":"6 - 8"},{"status":"ACTIVE","sortPriority":42,"id":41435526,"name":"6 - 9"},{"status":"ACTIVE","sortPriority":43,"id":41419634,"name":"8 - 1"},{"status":"ACTIVE","sortPriority":44,"id":41419635,"name":"8 - 2"},{"status":"ACTIVE","sortPriority":45,"id":41419636,"name":"8 - 3"},{"status":"ACTIVE","sortPriority":46,"id":41419637,"name":"8 - 4"},{"status":"ACTIVE","sortPriority":47,"id":41419638,"name":"8 - 5"},{"status":"ACTIVE","sortPriority":48,"id":41419639,"name":"8 - 6"},{"status":"ACTIVE","sortPriority":49,"id":41419655,"name":"8 - 9"},{"status":"ACTIVE","sortPriority":50,"id":28546950,"name":"9 - 1"},{"status":"ACTIVE","sortPriority":51,"id":41419656,"name":"9 - 2"},{"status":"ACTIVE","sortPriority":52,"id":41419657,"name":"9 - 3"},{"status":"ACTIVE","sortPriority":53,"id":41435527,"name":"9 - 4"},{"status":"ACTIVE","sortPriority":54,"id":41419658,"name":"9 - 5"},{"status":"ACTIVE","sortPriority":55,"id":41435528,"name":"9 - 6"},{"status":"ACTIVE","sortPriority":56,"id":41419660,"name":"9 - 8"}],"regulators":["MR_INT"],"venue":"Rockhampton","countryCode":"AU","discountAllowed":true,"timezone":"Australia/Queensland","openDate":"2022-03-02T08:28:00.000Z","version":4382606040,"name":"Exacta","eventName":"Rockhampton (AUS) 2nd Mar"},"rc":[],"con":true,"img":false}]}
{"op":"mcm","clk":"5353909178","pt":1646219705364,"mc":[{"id":"1.195503869","rc":[{"atb":[[12,9.09]],"id":41419636},{"atb":[[38,2.7]],"id":41419615},{"atb":[[3.1,47.62]],"id":41419591},{"atb":[[2.8,0],[3.1,47.62]],"id":41419587},{"atb":[[9.6,11.63]],"id":41419592},{"atb":[[5,0]],"id":41419588}],"con":true,"img":false}]}
{"op":"mcm","clk":"5353909189","pt":1646219705469,"mc":[{"id":"1.195503869","rc":[{"atb":[[18.5,0],[22,4.76]],"id":41419605},{"atb":[[4.2,0],[5.4,22.73]],"id":41419634},{"atb":[[16.5,6.45],[13.5,0]],"id":41419613},{"atb":[[34,3.03],[27,0]],"id":41419593},{"atb":[[3.85,0],[4.4,29.41]],"id":41419589},{"atb":[[17,0],[21,5]],"id":41419601},{"atb":[[16,6.67],[12.5,23.16]],"id":28546943},{"atb":[[5.6,21.74],[4.3,0]],"id":41419606},{"atb":[[17.5,6.06],[14.5,0]],"id":41419635},{"atb":[[3.85,0],[4.4,29.41]],"id":41419585},{"atb":[[40,2.56],[29,0]],"id":41419652},{"atb":[[3.6,38.46],[3.05,0]],"id":41419586},{"atb":[[18,5.88],[15.5,0]],"id":41419607},{"atb":[[9.6,0]],"id":41419636},{"atb":[[36,2.86],[29,0]],"id":41419603},{"atb":[[27,0]],"id":41419615},{"atb":[[40,2.56],[29,0]],"id":41419657},{"atb":[[2.72,0]],"id":41419591},{"atb":[[9.2,12.2],[7,0]],"id":41419620},{"atb":[[7.2,0],[8.2,13.89]],"id":41419599},{"atb":[[12,9.09],[9.8,0]],"id":41419608},{"atb":[[9,12.5],[6.8,0]],"id":41419637},{"atb":[[9.2,44.68],[7,0]],"id":41419612},{"atb":[[7.2,0]],"id":41419592},{"atb":[[6,20]],"id":41419588},{"atb":[[34,3.03],[26,0]],"id":41419600}],"con":true,"img":false}]}
{"op":"mcm","clk":"5353909842","pt":1646219711972,"mc":[{"id":"1.195503869","rc":[{"atb":[[3.95,93.02]],"id":41419591}],"con":true,"img":false}]}
{"op":"mcm","clk":"5353910747","pt":1646219720675,"mc":[{"id":"1.195503869","rc":[{"atb":[[22,0],[11,10]],"id":41419605},{"atl":[[820,2],[960,0]],"id":41419605},{"atb":[[4.5,28.57],[5.4,0]],"id":41419634},{"atl":[[420,2],[460,0]],"id":41419634},{"atb":[[16.5,0],[10,11.11]],"id":41419613},{"atl":[[800,2],[860,0]],"id":41419613},{"atl":[[1000,2]],"id":41419593},{"atl":[[1000,2]],"id":41419622},{"atb":[[16,0]],"id":28546943},{"atl":[[920,0]],"id":28546943},{"atb":[[21,0],[15.5,6.9]],"id":41419626},{"atl":[[910,2],[1000,0]],"id":41419626},{"atb":[[15,0]],"id":41419639},{"atl":[[940,0]],"id":41419639},{"atb":[[6.4,18.52]],"id":41419606},{"atb":[[8.6,9.76]],"id":41419635},{"atl":[[650,2]],"id":41419635},{"atl":[[320,2],[340,0]],"id":41419585},{"atb":[[3.6,0],[4.2,114.5]],"id":41419586},{"atb":[[26,0],[14.5,7.27]],"id":41419598},{"atl":[[900,2],[1000,0]],"id":41419598},{"atl":[[990,2],[1000,0]],"id":41419594},{"atb":[[18,0]],"id":41419607},{"atl":[[940,0]],"id":41419607},{"atb":[[9.2,12.2],[12,0]],"id":41419636},{"atl":[[710,2],[820,0]],"id":41419636},{"atb":[[36,0],[20,5.26]],"id":41419603},{"atl":[[980,2]],"id":41419603},{"atb":[[3.55,39.22]],"id":41419591},{"atl":[[24,4.35]],"id":41419591},{"atl":[[580,2],[700,0]],"id":41419620},{"atb":[[3.1,0],[3.8,35.71]],"id":41419587},{"atl":[[530,2],[580,0]],"id":41419599},{"atb":[[17.5,6.06],[12,0]],"id":41419608},{"atl":[[1000,2]],"id":41419616},{"atb":[[9.6,0],[8.4,13.51]],"id":41419592},{"atl":[[560,2],[750,0]],"id":41419592},{"atl":[[1000,2]],"id":41419621},{"atb":[[34,0],[19,20.36]],"id":41419600},{"atl":[[960,2]],"id":41419600},{"atb":[[28,0]],"id":41419596},{"atl":[[1000,2]],"id":41419596}],"con":true,"img":false}]}
{"op":"mcm","clk":"5353910756","pt":1646219720783,"mc":[{"id":"1.195503869","rc":[{"atl":[[920,2],[1000,0]],"id":41419638},{"atb":[[34,0],[42,2.44]],"id":41419593},{"atb":[[4.4,0],[5.4,22.73]],"id":41419589},{"atl":[[410,0],[400,2]],"id":41419589},{"atb":[[21,0],[15,7.14]],"id":41419601},{"atl":[[900,2],[950,0]],"id":41419601},{"atb":[[12.5,31.86]],"id":28546943},{"atl":[[850,2]],"id":28546943},{"atb":[[9.6,11.63]],"id":41419639},{"atl":[[770,2]],"id":41419639},{"atb":[[5.6,0]],"id":41419606},{"atb":[[17.5,0]],"id":41419635},{"atl":[[930,0]],"id":41419635},{"atb":[[5.2,23.81],[4.4,0]],"id":41419585},{"atl":[[1000,2]],"id":41419614},{"atl":[[910,2],[980,0]],"id":41419610},{"atl":[[910,2],[1000,0]],"id":41419623},{"atb":[[40,0],[50,2.04]],"id":41419652},{"atl":[[1000,2]],"id":41419619},{"atb":[[14.5,7.41]],"id":41419607},{"atl":[[900,2]],"id":41419607},{"atl":[[1000,2]],"id":28546950},{"atb":[[38,0],[48,2.13]],"id":41419615},{"atb":[[40,0],[50,2.04]],"id":41419657},{"atb":[[3.1,0]],"id":41419591},{"atl":[[18,0]],"id":41419591},{"atb":[[9.2,0],[11,10]],"id":41419620},{"atb":[[9.6,34.86],[8.2,0]],"id":41419599},{"atb":[[9,0],[11,10]],"id":41419637},{"atl":[[670,2],[680,0]],"id":41419637},{"atb":[[9.2,32.48],[11,10]],"id":41419612},{"atb":[[6,0],[8.4,49.5]],"id":41419588}],"con":true,"img":false}]}
{"op":"mcm","clk":"5353910769","pt":1646219720881,"mc":[{"id":"1.195503869","rc":[{"atb":[[3.8,0],[4.4,88.17]],"id":41419587},{"atb":[[23,4.55]],"id":41419596}],"con":true,"img":false}]}
{"op":"mcm","clk":"5353910780","pt":1646219720989,"mc":[{"id":"1.195503869","rc":[{"atb":[[11.5,0],[14,0]],"id":41419634},{"atb":[[40,0],[50,0]],"id":41419635},{"atb":[[12,0],[9.8,0]],"id":41419585},{"atb":[[34,0],[44,0]],"id":41419592}],"con":true,"img":false}]}
{"op":"mcm","clk":"5353910863","pt":1646219721682,"mc":[{"id":"1.195503869","rc":[{"atb":[[11,3.27],[13.5,2.72]],"id":41419634},{"atb":[[38,3.27],[48,2.72]],"id":41419635},{"atb":[[11,22.7],[9.4,3.27]],"id":41419585},{"atb":[[36,2.72],[28,3.27]],"id":41419592}],"con":true,"img":false}]}
{"op":"mcm","clk":"5353911063","pt":1646219723607,"mc":[{"id":"1.195503869","rc":[{"atb":[[6.4,0],[5.7,0]],"id":41419587}],"con":true,"img":false}]}
{"op":"mcm","clk":"5353911178","pt":1646219724637,"mc":[{"id":"1.195503869","rc":[{"atb":[[7.2,2.72],[6.2,3.27],[6,1.48]],"id":41419587}],"con":true,"img":false}]}
{"op":"mcm","clk":"5353911374","pt":1646219726392,"mc":[{"id":"1.195503869","rc":[{"atb":[[38,0],[48,0]],"id":41419635}],"con":true,"img":false}]}
{"op":"mcm","clk":"5353911443","pt":1646219727089,"mc":[{"id":"1.195503869","rc":[{"atb":[[36,3.27],[46,2.72]],"id":41419635}],"con":true,"img":false}]}
{"op":"mcm","clk":"5353911698","pt":1646219729534,"mc":[{"id":"1.195503869","rc":[{"atb":[[17.5,0],[50,0],[25,4.17]],"id":41419609},{"atb":[[18,0],[26,0],[55,0]],"id":41419638},{"atb":[[10.5,0],[26,0],[15.5,0]],"id":41419605},{"atb":[[9,0],[5,0],[6,0]],"id":41419634},{"atb":[[270,0],[120,0],[60,0]],"id":41419617},{"atb":[[16,0],[11,0],[27,0]],"id":41419613},{"atb":[[75,0],[20,0],[30,0]],"id":41419593},{"atb":[[80,0],[42,0],[210,0]],"id":41419655},{"atb":[[16.5,0],[46,0],[23,4.55]],"id":41419622},{"atb":[[8.6,0],[14,0],[6.6,0]],"id":41419589},{"atb":[[85,3.27],[44,0],[220,0]],"id":41435527},{"atb":[[600,0],[700,0],[850,0]],"id":41419651},{"atb":[[24,0],[9.8,0],[14.5,0]],"id":41419601},{"atb":[[17.5,0],[12.5,8.7],[30,0]],"id":28546943},{"atb":[[16,0],[44,0],[22,0]],"id":41419626},{"atb":[[42,0],[21,0],[15.5,0]],"id":41419639},{"atb":[[5.7,0],[8.4,0],[4.7,0]],"id":41419606},{"atb":[[18,0],[26,0],[55,0]],"id":41419635},{"atb":[[65,2.72],[19,0],[28,0]],"id":41419602},{"atb":[[18.5,0],[11,2.72],[8.4,0]],"id":41419585},{"atb":[[310,0],[210,0],[460,0]],"id":41419614},{"atb":[[40,0],[20,0],[15,7.14]],"id":41419610},{"atb":[[600,0],[700,0],[850,0]],"id":41419656},{"atb":[[42,3.27],[21,5],[15.5,0]],"id":41419623},{"atb":[[95,0],[48,0],[240,0]],"id":41419652},{"atb":[[550,0],[650,0],[800,0]],"id":41435528},{"atb":[[65,0],[19,0],[28,0]],"id":41419619},{"atb":[[7.4,0],[5.2,0],[4.2,31.25]],"id":41419586},{"atb":[[65,0],[19,0],[28,0]],"id":41419598},{"atb":[[100,0],[50,0],[250,0]],"id":41419660},{"atb":[[18.5,0],[27,0],[60,0]],"id":41419594},{"atb":[[17.5,0],[50,0],[25,0]],"id":41419607},{"atb":[[16.5,0],[46,0],[23,4.55]],"id":28546950},{"atb":[[10.5,0],[26,3.27],[15.5,0]],"id":41419636},{"atb":[[16,0],[44,0],[22,0]],"id":41419603},{"atb":[[75,0],[20,0],[30,0]],"id":41419615},{"atb":[[140,0],[70,0],[290,0]],"id":41419657},{"atb":[[260,0],[110,0],[55,0]],"id":41419624},{"atb":[[3.95,2.72],[4.9,0]],"id":41419591},{"atb":[[34,0],[170,0],[60,0]],"id":41435525},{"atb":[[600,0],[700,0],[850,0]],"id":41419653},{"atb":[[19.5,0],[12,0],[8.8,0]],"id":41419620},{"atb":[[3.7,0],[4.4,29.41],[5.9,0]],"id":41419587},{"atb":[[9.6,11.63],[5.3,0],[6.6,0]],"id":41419599},{"atb":[[310,0],[210,0],[460,0]],"id":41419595},{"atb":[[9.6,0],[23,0],[14,0]],"id":41419608},{"atb":[[9.2,0],[21,0],[13,0]],"id":41419637},{"atb":[[18.5,0],[27,0],[60,0]],"id":41419616},{"atb":[[9.2,0],[21,0],[13,0]],"id":41419612},{"atb":[[16,0],[11,0],[27,0]],"id":41419592},{"atb":[[610,0],[760,0],[510,0]],"id":41435526},{"atb":[[260,0],[110,0],[55,0]],"id":41419621},{"atb":[[18.5,0],[11,0],[8.4,13.51]],"id":41419588},{"atb":[[65,0],[19,5.56],[28,0]],"id":41419600},{"atb":[[270,0],[120,0],[60,0]],"id":41419596},{"atb":[[600,0],[700,0],[850,0]],"id":41419658}],"con":true,"img":false}]}
{"op":"mcm","clk":"5353911769","pt":1646219730112,"mc":[{"id":"1.195503869","rc":[{"atl":[[750,2],[820,0]],"id":41419605},{"atl":[[400,2],[420,0]],"id":41419634},{"atl":[[730,2],[800,0]],"id":41419613},{"atl":[[980,2],[1000,0]],"id":41419593},{"atl":[[900,2],[1000,0]],"id":41419622},{"atl":[[810,2],[910,0]],"id":41419626},{"atl":[[610,2],[650,0]],"id":41419635},{"atl":[[290,2],[320,0]],"id":41419585},{"atl":[[810,2],[900,0]],"id":41419598},{"atl":[[890,2],[990,0]],"id":41419594},{"atl":[[660,2],[710,0]],"id":41419636},{"atl":[[880,2],[980,0]],"id":41419603},{"atb":[[4.1,3.27],[3.55,0]],"id":41419591},{"atl":[[540,2],[580,0]],"id":41419620},{"atl":[[530,0],[510,2]],"id":41419599},{"atl":[[530,2],[560,0]],"id":41419592},{"atl":[[890,2],[1000,0]],"id":41419621},{"atl":[[870,2],[960,0]],"id":41419600},{"atl":[[980,2],[1000,0]],"id":41419596}],"con":true,"img":false}]}
{"op":"mcm","clk":"5353911783","pt":1646219730218,"mc":[{"id":"1.195503869","rc":[{"atl":[[820,2],[900,0]],"id":41419601},{"atl":[[780,2],[850,0]],"id":28546943},{"atl":[[700,2],[770,0]],"id":41419639},{"atl":[[910,0],[900,2]],"id":41419610},{"atl":[[910,0],[900,2]],"id":41419623},{"atl":[[810,2],[900,0]],"id":41419607},{"atl":[[620,2],[670,0]],"id":41419637}],"con":true,"img":false}]}
{"op":"mcm","clk":"5353911795","pt":1646219730321,"mc":[{"id":"1.195503869","rc":[{"atb":[[5,0]],"id":41419591}],"con":true,"img":false}]}
{"op":"mcm","clk":"5353911810","pt":1646219730386,"mc":[{"id":"1.195503869","rc":[{"atb":[[1.01,1.5]],"id":41419591}],"con":true,"img":false}]}
{"op":"mcm","clk":"5353912125","pt":1646219733567,"mc":[{"id":"1.195503869","rc":[{"atb":[[9,35.02],[25,10],[12.5,24.36]],"id":41419609},{"atb":[[9.2,34.16],[26,5.6],[13,23.34]],"id":41419638},{"atb":[[6.2,53.88],[8.2,38.91],[15.5,9.66]],"id":41419605},{"atb":[[4,93.39],[6,28.01],[3.5,112.07]],"id":41419634},{"atb":[[34,8.49],[22,13.34],[120,1.17]],"id":41419617},{"atb":[[16,9.34],[6.4,51.88],[8.4,37.86]],"id":41419613},{"atb":[[10,31.13],[30,4.82],[15,20.01]],"id":41419593},{"atb":[[18,16.48],[80,1.77],[26,11.2]],"id":41419655},{"atb":[[8.6,36.86],[23,10.91],[11.5,26.68]],"id":41419622},{"atb":[[8.6,18.43],[4.3,84.9],[5.3,65.15]],"id":41419589},{"atb":[[18.5,16.01],[85,4.93],[27,10.77]],"id":41435527},{"atb":[[700,0.2],[400,0.7],[500,0.56]],"id":41419651},{"atb":[[7.8,41.2],[14.5,10.37],[5.9,57.18]],"id":41419601},{"atb":[[17.5,8.49],[9,35.02],[7,46.69]],"id":28546943},{"atb":[[22,6.67],[11,28.01],[8.4,37.86]],"id":41419626},{"atb":[[21,7],[10.5,29.49],[8.2,38.91]],"id":41419639},{"atb":[[3.85,98.31],[3.35,119.22],[5.7,29.8]],"id":41419606},{"atb":[[9.2,34.16],[26,5.6],[13,23.34]],"id":41419635},{"atb":[[9.6,32.58],[28,5.18],[14,21.55]],"id":41419602},{"atb":[[6.4,51.88],[11,16.73],[5.2,90.52]],"id":41419585},{"atb":[[310,0.45],[110,2.57],[55,5.18]],"id":41419614},{"atb":[[8,40.02],[20,7.37],[10,31.13]],"id":41419610},{"atb":[[700,0.2],[400,0.7],[500,0.56]],"id":41419656},{"atb":[[21,12],[10.5,29.49],[8.2,38.91]],"id":41419623},{"atb":[[19.5,15.14],[95,1.48],[29,10]],"id":41419652},{"atb":[[650,0.21],[350,0.8],[450,0.62]],"id":41435528},{"atb":[[9.6,32.58],[28,5.18],[14,21.55]],"id":41419619},{"atb":[[3.6,107.76],[3.1,133.42],[5.2,33.35]],"id":41419586},{"atb":[[9.6,32.58],[28,5.18],[14,21.55]],"id":41419598},{"atb":[[20,14.74],[100,1.41],[30,9.66]],"id":41419660},{"atb":[[27,5.39],[13.5,22.41],[9.4,33.35]],"id":41419594},{"atb":[[9,35.02],[25,5.83],[12.5,24.36]],"id":41419607},{"atb":[[8.6,36.86],[23,10.91],[11.5,26.68]],"id":28546950},{"atb":[[6.2,53.88],[8.2,38.91],[15.5,9.66]],"id":41419636},{"atb":[[22,6.67],[11,28.01],[8.4,37.86]],"id":41419603},{"atb":[[10,31.13],[30,4.82],[15,20.01]],"id":41419615},{"atb":[[140,1],[38,7.57],[24,12.18]],"id":41419657},{"atb":[[32,9.03],[21,14],[110,1.28]],"id":41419624},{"atb":[[3.45,76.11],[4.9,23.9],[2.98,94.17]],"id":41419591},{"atb":[[16,18.67],[22,13.34],[60,2.37]],"id":41435525},{"atb":[[700,0.2],[400,0.7],[500,0.56]],"id":41419653},{"atb":[[12,12.73],[6.8,48.31],[5.4,63.67]],"id":41419620},{"atb":[[3.2,127.35],[2.88,149.03],[4.4,70.61]],"id":41419587},{"atb":[[4.3,84.9],[6.6,25.01],[3.65,105.72]],"id":41419599},{"atb":[[310,0.45],[110,2.57],[55,5.18]],"id":41419595},{"atb":[[5.8,58.37],[7.6,42.45],[14,10.77]],"id":41419608},{"atb":[[5.6,60.91],[7.2,45.19],[13,11.67]],"id":41419637},{"atb":[[27,5.39],[13.5,22.41],[9.4,33.35]],"id":41419616},{"atb":[[5.6,60.91],[7.2,45.19],[13,11.67]],"id":41419612},{"atb":[[16,9.34],[6.4,51.88],[8.4,51.37]],"id":41419592},{"atb":[[610,0.22],[310,0.9],[410,0.68]],"id":41435526},{"atb":[[32,9.03],[21,14],[110,1.28]],"id":41419621},{"atb":[[6.4,51.88],[11,14],[5.2,66.71]],"id":41419588},{"atb":[[9.6,32.58],[28,5.18],[14,21.55]],"id":41419600},{"atb":[[34,8.49],[22,13.34],[120,1.17]],"id":41419596},{"atb":[[700,0.2],[400,0.7],[500,0.56]],"id":41419658}],"con":true,"img":false}]}
{"op":"mcm","clk":"5353912143","pt":1646219733722,"mc":[{"id":"1.195503869","rc":[{"atb":[[11,0],[14.5,7.41]],"id":41419605},{"atb":[[4.5,0],[5.4,22.73]],"id":41419634},{"atb":[[13,8.33]],"id":41419613},{"atb":[[16,6.67],[12.5,0]],"id":28546943},{"atb":[[19,5.56],[15.5,0]],"id":41419626},{"atb":[[9.6,0],[12,9.09]],"id":41419639},{"atb":[[8.6,0]],"id":41419635},{"atb":[[18.5,5.71],[14.5,0]],"id":41419607},{"atb":[[9.2,0],[11.5,9.52]],"id":41419636},{"atb":[[11,0],[13.5,8]],"id":41419612},{"atb":[[11,10],[8.4,37.86]],"id":41419592},{"atb":[[19,0],[25,4.17]],"id":41419600}],"con":true,"img":false}]}
{"op":"mcm","clk":"5353912152","pt":1646219733828,"mc":[{"id":"1.195503869","rc":[{"atb":[[10,0]],"id":41419613},{"atb":[[10.5,10.53]],"id":41419635},{"atb":[[5,25],[4.2,0]],"id":41419586},{"atb":[[18.5,5.71],[14.5,0]],"id":41419598}],"con":true,"img":false}]}
{"op":"mcm","clk":"5353912707","pt":1646219739301,"mc":[{"id":"1.195503869","rc":[{"atl":[[290,0]],"id":41419585}],"con":true,"img":false}]}
{"op":"mcm","clk":"5353912718","pt":1646219739408,"mc":[{"id":"1.195503869","rc":[{"atl":[[280,2]],"id":41419585}],"con":true,"img":false}]}
{"op":"mcm","clk":"5353912728","pt":1646219739514,"mc":[{"id":"1.195503869","rc":[{"atl":[[780,0],[770,2]],"id":28546943}],"con":true,"img":false}]}
{"op":"mcm","clk":"5353912970","pt":1646219741520,"mc":[{"id":"1.195503869","rc":[{"atl":[[970,2]],"id":41419596}],"con":true,"img":false}]}
{"op":"mcm","clk":"5353912983","pt":1646219741623,"mc":[{"id":"1.195503869","rc":[{"atl":[[770,0],[780,2]],"id":28546943},{"atl":[[980,0]],"id":41419596}],"con":true,"img":false}]}
{"op":"mcm","clk":"5353913460","pt":1646219745748,"mc":[{"id":"1.195503869","rc":[{"atb":[[42,0],[55,0]],"id":41419609},{"atb":[[85,1.66],[120,0]],"id":41435527},{"atb":[[170,0],[120,0]],"id":41419651},{"atb":[[150,0],[200,0]],"id":41419656},{"atb":[[75,0],[50,0]],"id":41419594},{"atb":[[42,0],[55,0]],"id":41419607},{"atb":[[70,0],[48,0]],"id":41435525},{"atb":[[25,0],[30,0]],"id":41419620},{"atb":[[34,0],[27,0]],"id":41419608},{"atb":[[25,0],[30,0]],"id":41419612}],"con":true,"img":false}]}
{"op":"mcm","clk":"5353913469","pt":1646219745808,"mc":[{"id":"1.195503869","rc":[{"atb":[[12,0],[14.5,0]],"id":41419606},{"atb":[[32,0],[42,0]],"id":41419610},{"atb":[[24,0],[29,0]],"id":41419637}],"con":true,"img":false}]}
{"op":"mcm","clk":"5353913483","pt":1646219745935,"mc":[{"id":"1.195503869","rc":[{"atb":[[23,4.55],[25,5.83]],"id":41419609},{"atb":[[23,4.55],[26,0]],"id":41419594}],"con":true,"img":false}]}
{"op":"mcm","clk":"5353913542","pt":1646219746434,"mc":[{"id":"1.195503869","rc":[{"atb":[[44,3.27],[60,2.72]],"id":41419609},{"atb":[[130,3.27],[180,2.72]],"id":41419651},{"atb":[[160,3.27],[210,2.72]],"id":41419656},{"atb":[[75,2.72],[50,3.27]],"id":41435525},{"atb":[[24,3.27],[29,2.72]],"id":41419620},{"atb":[[36,2.72],[28,3.27]],"id":41419608},{"atb":[[32,2.72],[26,3.27]],"id":41419612}],"con":true,"img":false}]}
{"op":"mcm","clk":"5353913557","pt":1646219746537,"mc":[{"id":"1.195503869","rc":[{"atb":[[130,2.72],[90,3.27]],"id":41435527},{"atb":[[16,2.72],[13.5,3.27]],"id":41419606},{"atb":[[34,3.27],[44,2.72]],"id":41419610},{"atb":[[80,2.72],[55,3.27]],"id":41419594},{"atb":[[44,3.27],[60,2.72]],"id":41419607},{"atb":[[25,3.27],[30,2.72]],"id":41419637}],"con":true,"img":false}]}
{"op":"mcm","clk":"5353913569","pt":1646219746645,"mc":[{"id":"1.195503869","rc":[{"atb":[[6.6,1.56]],"id":41419606},{"atb":[[17.5,0],[22,4.76]],"id":41419608}],"con":true,"img":false}]}
{"op":"mcm","clk":"5353913581","pt":1646219746710,"mc":[{"id":"1.195503869","rc":[{"atb":[[6.4,0],[8.4,13.51]],"id":41419606}],"con":true,"img":false}]}
{"op":"mcm","clk":"5353913991","pt":1646219750837,"mc":[{"id":"1.195503869","rc":[{"atl":[[780,0],[770,2]],"id":28546943}],"con":true,"img":false}]}
{"op":"mcm","clk":"5353915034","pt":1646219760340,"mc":[{"id":"1.195503869","rc":[{"atb":[[44,0],[60,0]],"id":41419600}],"con":true,"img":false}]}
{"op":"mcm","clk":"5353915121","pt":1646219761030,"mc":[{"id":"1.195503869","rc":[{"atb":[[65,2.72],[46,3.27]],"id":41419600}],"con":true,"img":false}]}
{"op":"mcm","clk":"5353919434","pt":1646219796196,"mc":[{"id":"1.195503869","rc":[{"atb":[[160,0],[110,0]],"id":41435528}],"con":true,"img":false}]}
{"op":"mcm","clk":"5353919639","pt":1646219797107,"mc":[{"id":"1.195503869","rc":[{"atb":[[170,2.72],[120,3.27]],"id":41435528}],"con":true,"img":false}]}
{"op":"mcm","clk":"5353920155","pt":1646219800491,"mc":[{"id":"1.195503869","rc":[{"atb":[[3.95,0]],"id":41419591}],"con":true,"img":false}]}
{"op":"mcm","clk":"5353920255","pt":1646219801248,"mc":[{"id":"1.195503869","rc":[{"atb":[[5.2,2.72]],"id":41419591}],"con":true,"img":false}]}
{"op":"mcm","clk":"5353920299","pt":1646219801502,"mc":[{"id":"1.195503869","rc":[{"atl":[[950,2],[1000,0]],"id":41419609},{"atl":[[460,2],[470,0]],"id":41419606},{"atl":[[880,2],[900,0]],"id":41419610},{"atl":[[790,2],[810,0]],"id":41419607}],"con":true,"img":false}]}
{"op":"mcm","clk":"5353920349","pt":1646219801921,"mc":[{"id":"1.195503869","rc":[{"atb":[[36,0],[46,0]],"id":41419635}],"con":true,"img":false}]}
{"op":"mcm","clk":"5353920440","pt":1646219802815,"mc":[{"id":"1.195503869","rc":[{"atb":[[38,3.27],[48,2.72]],"id":41419635}],"con":true,"img":false}]}
{"op":"mcm","clk":"5353920568","pt":1646219803612,"mc":[{"id":"1.195503869","rc":[{"atl":[[880,2],[920,0]],"id":41419638},{"atb":[[6.2,19.23],[5.4,0]],"id":41419634},{"atb":[[42,0]],"id":41419593},{"atl":[[920,2],[980,0]],"id":41419593},{"atl":[[750,2],[820,0]],"id":41419601},{"atb":[[16,0],[17.5,14.55]],"id":28546943},{"atl":[[1000,2]],"id":41419602},{"atl":[[850,2],[900,0]],"id":41419623},{"atl":[[840,2],[890,0]],"id":41419594},{"atb":[[18.5,0],[13,8.33]],"id":41419607},{"atb":[[4.3,26.64],[4.1,0]],"id":41419591},{"atb":[[22,0],[14.5,7.41]],"id":41419608},{"atl":[[750,2],[820,0]],"id":41419608},{"atl":[[580,2],[620,0]],"id":41419637},{"atl":[[650,2],[700,0]],"id":41419612},{"atb":[[19,5.56],[25,0]],"id":41419600},{"atl":[[810,2],[870,0]],"id":41419600}],"con":true,"img":false}]}
{"op":"mcm","clk":"5353920590","pt":1646219803860,"mc":[{"id":"1.195503869","rc":[{"atb":[[32,3.23]],"id":41419593}],"con":true,"img":false}]}
{"op":"mcm","clk":"5353920601","pt":1646219803896,"mc":[{"id":"1.195503869","rc":[{"atb":[[11,14],[9.4,0]],"id":41419585},{"atb":[[80,0],[55,0]],"id":41419594},{"atb":[[44,0],[60,0]],"id":41419607},{"atb":[[5.2,0]],"id":41419591}],"con":true,"img":false}]}
{"op":"mcm","clk":"5353920624","pt":1646219804111,"mc":[{"id":"1.195503869","rc":[{"atb":[[21,5],[23,0]],"id":41419594}],"con":true,"img":false}]}
{"op":"mcm","clk":"5353920681","pt":1646219804631,"mc":[{"id":"1.195503869","rc":[{"atb":[[75,2.72],[50,3.27]],"id":41419594},{"atb":[[42,3.27],[55,2.72]],"id":41419607},{"atb":[[5.6,2.72]],"id":41419591}],"con":true,"img":false}]}
{"op":"mcm","clk":"5353920731","pt":1646219805009,"mc":[{"id":"1.195503869","rc":[{"atb":[[9.6,3.27],[11.5,2.72]],"id":41419585}],"con":true,"img":false}]}
{"op":"mcm","clk":"5353920949","pt":1646219806931,"mc":[{"id":"1.195503869","rc":[{"atb":[[6.2,19.23],[5.4,0]],"id":41419589},{"atb":[[19,0],[23,4.55]],"id":41419626},{"atb":[[7.2,16.13],[8.4,0]],"id":41419606}],"con":true,"img":false}]}
{"op":"mcm","clk":"5353921361","pt":1646219809436,"mc":[{"id":"1.195503869","rc":[{"atb":[[36,0],[28,0]],"id":41419592}],"con":true,"img":false}]}
{"op":"mcm","clk":"5353921470","pt":1646219810046,"mc":[{"id":"1.195503869","rc":[{"atl":[[930,2]],"id":41419609},{"atl":[[460,0],[450,2]],"id":41419606},{"atl":[[810,2],[880,0]],"id":41419610},{"atl":[[710,2]],"id":41419607}],"con":true,"img":false}]}
{"op":"mcm","clk":"5353921486","pt":1646219810154,"mc":[{"id":"1.195503869","rc":[{"atl":[[950,0]],"id":41419609},{"atl":[[790,0]],"id":41419607}],"con":true,"img":false}]}
{"op":"mcm","clk":"5353921520","pt":1646219810270,"mc":[{"id":"1.195503869","rc":[{"atb":[[38,2.72],[29,3.27]],"id":41419592}],"con":true,"img":false}]}
{"op":"mcm","clk":"5353921777","pt":1646219811856,"mc":[{"id":"1.195503869","rc":[{"atb":[[7.2,0],[6.2,0]],"id":41419587}],"con":true,"img":false}]}
{"op":"mcm","clk":"5353921826","pt":1646219812128,"mc":[{"id":"1.195503869","rc":[{"atl":[[830,2],[840,0]],"id":41419594},{"atl":[[750,0],[740,2]],"id":41419608},{"atl":[[650,0],[640,2]],"id":41419612}],"con":true,"img":false}]}
{"op":"mcm","clk":"5353921897","pt":1646219812649,"mc":[{"id":"1.195503869","rc":[{"atb":[[7.4,2.72]],"id":41419587}],"con":true,"img":false}]}
{"op":"mcm","clk":"5353921911","pt":1646219812756,"mc":[{"id":"1.195503869","rc":[{"atb":[[6.4,3.27],[6,0]],"id":41419587}],"con":true,"img":false}]}
{"op":"mcm","clk":"5353921929","pt":1646219812812,"mc":[{"id":"1.195503869","rc":[{"atb":[[4.5,1.48]],"id":41419587}],"con":true,"img":false}]}
{"op":"mcm","clk":"5353922486","pt":1646219817144,"mc":[{"id":"1.195503869","rc":[{"atl":[[570,2],[580,0]],"id":41419637}],"con":true,"img":false}]}
{"op":"mcm","clk":"5353922838","pt":1646219820543,"mc":[{"id":"1.195503869","rc":[{"atl":[[630,2]],"id":41419612}],"con":true,"img":false}]}
{"op":"mcm","clk":"5353922854","pt":1646219820651,"mc":[{"id":"1.195503869","rc":[{"atl":[[640,0]],"id":41419612}],"con":true,"img":false}]}
{"op":"mcm","clk":"5353924455","pt":1646219835087,"mc":[{"id":"1.195503869","rc":[{"atl":[[570,0],[580,2]],"id":41419637}],"con":true,"img":false}]}
{"op":"mcm","clk":"5353925103","pt":1646219840997,"mc":[{"id":"1.195503869","rc":[{"atl":[[450,0],[460,2]],"id":41419606},{"atl":[[810,0],[830,2]],"id":41419610},{"atl":[[740,0],[750,2]],"id":41419608}],"con":true,"img":false}]}
{"op":"mcm","clk":"5353925551","pt":1646219845896,"mc":[{"id":"1.195503869","rc":[{"atb":[[11,0],[13.5,0]],"id":41419634},{"atb":[[24,0],[29,0]],"id":41419620},{"atb":[[18,0],[15.5,0]],"id":41419599}],"con":true,"img":false}]}
{"op":"mcm","clk":"5353925562","pt":1646219845994,"mc":[{"id":"1.195503869","rc":[{"atb":[[42,0],[55,0]],"id":41419607}],"con":true,"img":false}]}
{"op":"mcm","clk":"5353925576","pt":1646219846093,"mc":[{"id":"1.195503869","rc":[{"atb":[[5.6,21.74],[6.2,0]],"id":41419634},{"atb":[[11,0],[11.5,9.52]],"id":41419620}],"con":true,"img":false}]}
{"op":"mcm","clk":"5353925627","pt":1646219846572,"mc":[{"id":"1.195503869","rc":[{"atb":[[6.2,1.56]],"id":41419634}],"con":true,"img":false}]}
{"op":"mcm","clk":"5353925646","pt":1646219846677,"mc":[{"id":"1.195503869","rc":[{"atb":[[11.5,3.27],[14,2.72]],"id":41419634},{"atb":[[25,3.27],[30,2.72]],"id":41419620},{"atb":[[16,3.27],[18.5,2.72]],"id":41419599}],"con":true,"img":false}]}
{"op":"mcm","clk":"5353925657","pt":1646219846833,"mc":[{"id":"1.195503869","rc":[{"atb":[[40,3.27],[50,2.72]],"id":41419607}],"con":true,"img":false}]}
{"op":"mcm","clk":"5353926484","pt":1646219855529,"mc":[{"id":"1.195503869","rc":[{"atb":[[11.5,0],[14,0]],"id":41419634}],"con":true,"img":false}]}
{"op":"mcm","clk":"5353926552","pt":1646219856317,"mc":[{"id":"1.195503869","rc":[{"atb":[[11,3.27],[13.5,2.72]],"id":41419634}],"con":true,"img":false}]}
{"op":"mcm","clk":"5353929919","pt":1646219891276,"mc":[{"id":"1.195503869","rc":[{"atb":[[19,0],[23,0]],"id":28546943},{"atb":[[38,0],[48,0]],"id":41419635},{"atb":[[7.2,0],[8.2,0]],"id":41419586},{"atb":[[16,0],[13.5,0]],"id":41419588}],"con":true,"img":false}]}
{"op":"mcm","clk":"5353929929","pt":1646219891380,"mc":[{"id":"1.195503869","rc":[{"atb":[[75,0],[50,0]],"id":41419619},{"atb":[[65,0],[90,0]],"id":41419624}],"con":true,"img":false}]}
{"op":"mcm","clk":"5353929960","pt":1646219891595,"mc":[{"id":"1.195503869","rc":[{"atb":[[23,4.55],[26,0]],"id":41419619}],"con":true,"img":false}]}
{"op":"mcm","clk":"5353929997","pt":1646219891965,"mc":[{"id":"1.195503869","rc":[{"atb":[[19.5,3.27],[24,2.72]],"id":28546943},{"atb":[[40,3.27],[50,2.72]],"id":41419635},{"atb":[[7.4,3.27],[8.4,2.72]],"id":41419586},{"atb":[[16.5,2.72],[14,3.27]],"id":41419588}],"con":true,"img":false}]}
{"op":"mcm","clk":"5353930014","pt":1646219892066,"mc":[{"id":"1.195503869","rc":[{"atb":[[5.3,1.49]],"id":41419586}],"con":true,"img":false}]}
{"op":"mcm","clk":"5353930022","pt":1646219892171,"mc":[{"id":"1.195503869","rc":[{"atb":[[80,2.72],[55,3.27]],"id":41419619},{"atb":[[70,3.27],[95,2.72]],"id":41419624}],"con":true,"img":false}]}
{"op":"mcm","clk":"5353930891","pt":1646219900978,"mc":[{"id":"1.195503869","rc":[{"atl":[[750,0],[740,2]],"id":41419605},{"atl":[[750,0],[740,2]],"id":41419601},{"atl":[[810,0],[800,2]],"id":41419600}],"con":true,"img":false}]}
{"op":"mcm","clk":"5353931164","pt":1646219903913,"mc":[{"id":"1.195503869","rc":[{"atb":[[75,0],[50,0]],"id":41419598},{"atb":[[65,0],[90,0]],"id":41419621}],"con":true,"img":false}]}
{"op":"mcm","clk":"5353931181","pt":1646219904115,"mc":[{"id":"1.195503869","rc":[{"atb":[[18.5,0],[20,5.26]],"id":41419598},{"atb":[[6.4,0],[7.4,0]],"id":41419587}],"con":true,"img":false}]}
{"op":"mcm","clk":"5353931230","pt":1646219904595,"mc":[{"id":"1.195503869","rc":[{"atb":[[70,3.27],[95,2.72]],"id":41419621}],"con":true,"img":false}]}
{"op":"mcm","clk":"5353931241","pt":1646219904697,"mc":[{"id":"1.195503869","rc":[{"atb":[[80,2.72],[55,3.27]],"id":41419598}],"con":true,"img":false}]}
{"op":"mcm","clk":"5353931254","pt":1646219904807,"mc":[{"id":"1.195503869","rc":[{"atb":[[7.6,2.72],[6.6,3.27]],"id":41419587}],"con":true,"img":false}]}
{"op":"mcm","clk":"5353932922","pt":1646219921797,"mc":[{"id":"1.195503869","rc":[{"atb":[[50,0]],"id":41419607}],"con":true,"img":false}]}
{"op":"mcm","clk":"5353932944","pt":1646219922011,"mc":[{"id":"1.195503869","rc":[{"atb":[[40,0]],"id":41419607}],"con":true,"img":false}]}
{"op":"mcm","clk":"5353933005","pt":1646219922591,"mc":[{"id":"1.195503869","rc":[{"atb":[[55,2.72]],"id":41419607}],"con":true,"img":false}]}
{"op":"mcm","clk":"5353933023","pt":1646219922798,"mc":[{"id":"1.195503869","rc":[{"atb":[[42,3.27]],"id":41419607}],"con":true,"img":false}]}
{"op":"mcm","clk":"5353933819","pt":1646219930441,"mc":[{"id":"1.195503869","rc":[{"atb":[[11,0],[13.5,0]],"id":41419634}],"con":true,"img":false}]}
{"op":"mcm","clk":"5353933901","pt":1646219931231,"mc":[{"id":"1.195503869","rc":[{"atb":[[11.5,3.27],[14,2.72]],"id":41419634}],"con":true,"img":false}]}
{"op":"mcm","clk":"5353934622","pt":1646219938782,"mc":[{"id":"1.195503869","rc":[{"atl":[[6.4,0]],"id":41419591}],"con":true,"img":false}]}
{"op":"mcm","clk":"5353934641","pt":1646219938938,"mc":[{"id":"1.195503869","rc":[{"atl":[[6,187.09]],"id":41419591}],"con":true,"img":false}]}
{"op":"mcm","clk":"5353934916","pt":1646219941599,"mc":[{"id":"1.195503869","rc":[{"atb":[[65,2.47],[75,9.9],[95,4.95],[25,14.75]],"id":41419609},{"atl":[[180,4.95],[920,0.17],[950,1.29]],"id":41419609},{"atb":[[26,14.51],[55,2.93]],"id":41419638},{"atl":[[870,0.17],[900,1.36]],"id":41419638},{"atb":[[36,14.43],[44,4.95],[15.5,18.57]],"id":41419605},{"atl":[[90,4.95],[730,0.21],[760,1.61],[120,9.9]],"id":41419605},{"atb":[[10,9.9],[6,36.93],[12,4.95]],"id":41419634},{"atl":[[20,4.95],[24,9.9],[390,0.4],[420,2.93]],"id":41419634},{"atb":[[80,11.38]],"id":41419617},{"atb":[[65,9.9],[85,9.56]],"id":41419593},{"atl":[[220,4.95],[910,0.17]],"id":41419593},{"atb":[[160,4.95],[46,11.38],[120,9.9]],"id":41419655},{"atb":[[65,9.9],[85,4.95],[23,19.83]],"id":41419622},{"atl":[[160,4.95],[920,1.32]],"id":41419622},{"atb":[[8.6,27.34],[10,9.9],[12,4.95]],"id":41419589},{"atl":[[20,4.95],[24,9.9],[420,2.93]],"id":41419589},{"atb":[[140,1.13],[85,9.78]],"id":41435527},{"atl":[[1000,0.15]],"id":41435527},{"atb":[[32,9.9],[36,7.25],[40,4.95],[15,16.05]],"id":41419601},{"atl":[[90,4.95],[730,0.21],[760,1.61],[120,9.9]],"id":41419601},{"atb":[[17.5,23.46],[34,9.9],[42,4.95],[25,6.6]],"id":28546943},{"atl":[[760,0.2],[790,1.55],[110,4.95]],"id":28546943},{"atb":[[23,13.46]],"id":41419626},{"atl":[[830,1.47]],"id":41419626},{"atb":[[34,4.95],[40,6.79],[28,9.9]],"id":41419639},{"atl":[[690,0.22],[90,4.95],[120,9.9]],"id":41419639},{"atb":[[7.2,25.04]],"id":41419606},{"atl":[[480,2.56]],"id":41419606},{"atb":[[26,14.51]],"id":41419635},{"atl":[[630,1.95]],"id":41419635},{"atb":[[70,2.29],[85,9.9],[110,4.95],[28,14.1]],"id":41419602},{"atl":[[240,4.95],[990,0.15]],"id":41419602},{"atb":[[8.6,9.9],[9.4,4.95]],"id":41419585},{"atl":[[270,0.58],[300,4.1],[22,4.95],[26,9.9]],"id":41419585},{"atb":[[110,14.31]],"id":41419614},{"atl":[[990,0.15]],"id":41419614},{"atb":[[20,16.29]],"id":41419610},{"atl":[[850,1.44]],"id":41419610},{"atb":[[46,9.9],[55,5.66],[60,4.95]],"id":41419623},{"atl":[[140,4.95],[840,0.19]],"id":41419623},{"atb":[[160,4.95],[100,1.6],[55,11.38],[120,9.9]],"id":41419652},{"atl":[[1000,0.15]],"id":41419652},{"atb":[[85,1.88]],"id":41419619},{"atl":[[990,0.15]],"id":41419619},{"atb":[[10,4.95],[9.2,9.9],[5.2,42.27]],"id":41419586},{"atl":[[16.5,4.95],[270,4.56],[18.5,9.9]],"id":41419586},{"atb":[[160,4.95],[120,12.63]],"id":41419660},{"atb":[[44,9.9],[27,13.5],[55,4.95]],"id":41419594},{"atl":[[200,4.95],[820,0.19],[850,1.44]],"id":41419594},{"atb":[[38,4.95],[25,14.75],[30,9.9]],"id":41419607},{"atl":[[700,0.22],[730,1.68],[110,4.95]],"id":41419607},{"atb":[[75,2.14],[85,9.9],[23,19.83],[110,4.95]],"id":28546950},{"atl":[[990,0.15]],"id":28546950},{"atb":[[32,7.83],[34,4.95],[28,9.9]],"id":41419636},{"atl":[[70,4.95],[650,0.24],[90,9.9]],"id":41419636},{"atb":[[22,15.58],[50,3.23]],"id":41419603},{"atl":[[870,0.17],[900,1.36]],"id":41419603},{"atb":[[130,4.95],[90,1.78],[95,9.9]],"id":41419615},{"atl":[[1000,0.15]],"id":41419615},{"atb":[[150,1.06],[90,11.38]],"id":41419657},{"atl":[[1000,0.15]],"id":41419657},{"atb":[[130,4.95],[70,11.38],[95,12.63]],"id":41419624},{"atb":[[5.6,37.19],[4.3,97.72]],"id":41419591},{"atb":[[160,4.95],[50,11.38],[120,9.9]],"id":41435525},{"atb":[[12,21.65],[24,9.9],[28,4.95]],"id":41419620},{"atl":[[530,0.29],[560,2.19],[75,9.9],[55,4.95]],"id":41419620},{"atb":[[9.6,20.54],[18.5,11.64]],"id":41419599},{"atl":[[530,2.32],[500,0.31]],"id":41419599},{"atb":[[140,7.67],[100,9.9],[110,10.21]],"id":41419595},{"atl":[[1000,0.15]],"id":41419595},{"atb":[[38,4.28],[14.5,16.32]],"id":41419608},{"atl":[[740,0.21],[770,1.59]],"id":41419608},{"atb":[[13,20.59]],"id":41419637},{"atl":[[570,0.27],[600,2.04]],"id":41419637},{"atb":[[85,9.9],[110,4.95]],"id":41419616},{"atl":[[220,4.95]],"id":41419616},{"atb":[[34,4.95],[28,9.9]],"id":41419612},{"atl":[[70,4.95],[90,9.9]],"id":41419612},{"atb":[[16,18.25],[19.5,9.9],[23,4.95]],"id":41419592},{"atl":[[520,0.3],[550,2.23],[90,4.95],[120,9.9]],"id":41419592},{"atb":[[160,4.95],[120,12.63]],"id":41435526},{"atb":[[70,10.3]],"id":41419621},{"atl":[[880,0.17],[910,1.34]],"id":41419621},{"atb":[[44,9.9],[55,4.95]],"id":41419600},{"atl":[[130,4.95],[790,0.2]],"id":41419600},{"atb":[[80,10.3],[85,9.9],[110,7.67]],"id":41419596},{"atl":[[990,1.23]],"id":41419596}],"con":true,"img":false}]}
{"op":"mcm","clk":"5353934932","pt":1646219941700,"mc":[{"id":"1.195503869","rc":[{"atb":[[9,0],[25,8.91],[12.5,0]],"id":41419609},{"atb":[[70,4.95],[9.2,0],[50,12.63],[26,8.91],[13,0]],"id":41419638},{"atl":[[150,4.95]],"id":41419638},{"atb":[[6.2,0],[8.2,0],[15.5,8.91]],"id":41419605},{"atb":[[4,0],[6,8.91],[3.5,0]],"id":41419634},{"atb":[[130,1.23],[34,0],[22,0],[120,0]],"id":41419617},{"atl":[[1000,0.15]],"id":41419617},{"atb":[[16,8.91],[32,9.9],[6.4,0],[40,4.95],[8.4,0]],"id":41419613},{"atl":[[720,0.21],[750,1.63],[100,4.95]],"id":41419613},{"atb":[[32,12.08],[10,0],[30,0],[15,0]],"id":41419593},{"atl":[[940,1.3]],"id":41419593},{"atb":[[18,0],[80,0],[85,1.88],[26,0]],"id":41419655},{"atl":[[1000,0.15]],"id":41419655},{"atb":[[65,12.38],[8.6,0],[23,13.46],[11.5,0]],"id":41419622},{"atl":[[890,0.17]],"id":41419622},{"atb":[[8.6,8.91],[4.3,0],[5.3,0],[11.5,11.64]],"id":41419589},{"atl":[[390,0.4]],"id":41419589},{"atb":[[18.5,0],[160,4.95],[85,8.11],[27,0],[120,9.9]],"id":41435527},{"atb":[[700,0],[400,0],[500,0]],"id":41419651},{"atb":[[7.8,0],[14.5,0],[5.9,0]],"id":41419601},{"atb":[[17.5,14.97],[9,0],[7,0]],"id":28546943},{"atb":[[22,0],[11,0],[44,9.9],[55,10.61],[8.4,0]],"id":41419626},{"atl":[[130,4.95],[800,0.19]],"id":41419626},{"atb":[[21,8.91],[10.5,0],[8.2,0]],"id":41419639},{"atl":[[720,1.7]],"id":41419639},{"atb":[[16,11.64],[16.5,4.95],[3.85,0],[3.35,0],[5.7,0],[14.5,9.9]],"id":41419606},{"atl":[[34,9.9],[28,4.95],[450,0.35]],"id":41419606},{"atb":[[9.2,0],[23,9.9],[26,8.91],[13,0],[27,4.95]],"id":41419635},{"atl":[[110,4.95]],"id":41419635},{"atb":[[9.6,0],[28,8.91],[14,0]],"id":41419602},{"atb":[[6.4,0],[11,0],[5.2,23.81]],"id":41419585},{"atb":[[310,0],[110,11.74],[55,0]],"id":41419614},{"atb":[[8,0],[20,8.91],[10,0],[42,9.9],[46,3.52],[50,4.95]],"id":41419610},{"atl":[[130,4.95],[820,0.19]],"id":41419610},{"atb":[[700,0],[400,0],[500,0]],"id":41419656},{"atb":[[21,13.91],[10.5,0],[8.2,0]],"id":41419623},{"atl":[[870,1.41]],"id":41419623},{"atb":[[19.5,0],[95,0],[29,0]],"id":41419652},{"atb":[[650,0],[350,0],[450,0]],"id":41435528},{"atb":[[9.6,0],[80,12.63],[100,4.95],[28,8.91],[14,0]],"id":41419619},{"atl":[[220,4.95]],"id":41419619},{"atb":[[3.6,0],[3.1,0],[5.2,8.91],[8.4,9.75]],"id":41419586},{"atl":[[240,0.66]],"id":41419586},{"atb":[[9.6,0],[42,9.9],[50,4.95],[28,8.91],[14,0]],"id":41419598},{"atl":[[200,4.95],[800,0.19],[830,1.47]],"id":41419598},{"atb":[[20,0],[85,11.38],[100,0],[30,0]],"id":41419660},{"atb":[[27,8.11],[13.5,0],[9.4,0]],"id":41419594},{"atb":[[9,0],[25,8.91],[12.5,0]],"id":41419607},{"atb":[[8.6,0],[23,13.46],[11.5,0]],"id":28546950},{"atb":[[6.2,0],[8.2,0],[15.5,8.91]],"id":41419636},{"atl":[[680,1.8]],"id":41419636},{"atb":[[70,4.95],[22,8.91],[11,0],[50,13.14],[8.4,0]],"id":41419603},{"atl":[[150,4.95]],"id":41419603},{"atb":[[10,0],[48,10.24],[30,0],[15,0]],"id":41419615},{"atb":[[140,0],[38,0],[160,4.95],[24,0],[120,9.9]],"id":41419657},{"atb":[[32,0],[21,0],[110,0],[120,1.32]],"id":41419624},{"atl":[[1000,0.15]],"id":41419624},{"atb":[[3.45,0],[5.5,9.9],[4.9,0],[2.98,0],[5.9,4.95]],"id":41419591},{"atl":[[11.5,4.95],[13.5,9.9]],"id":41419591},{"atb":[[16,0],[80,2],[22,0],[60,0]],"id":41435525},{"atl":[[1000,0.15]],"id":41435525},{"atb":[[700,0],[400,0],[500,0]],"id":41419653},{"atb":[[12,8.91],[6.8,0],[5.4,0]],"id":41419620},{"atb":[[3.2,0],[2.88,0],[7.6,14.71],[6.8,9.9],[4.4,38.32]],"id":41419587},{"atl":[[150,8.22],[12.5,4.95],[14.5,9.9],[120,1.32]],"id":41419587},{"atb":[[4.3,0],[18,9.9],[20,4.95],[6.6,0],[3.65,0]],"id":41419599},{"atl":[[38,4.95],[46,9.9]],"id":41419599},{"atb":[[310,0],[110,7.64],[55,0]],"id":41419595},{"atb":[[36,12.63],[5.8,0],[44,4.95],[7.6,0],[14,0]],"id":41419608},{"atl":[[90,4.95],[120,9.9]],"id":41419608},{"atb":[[5.6,0],[7.2,0],[23,9.9],[13,8.91],[27,4.95]],"id":41419637},{"atl":[[70,9.9],[50,4.95]],"id":41419637},{"atb":[[85,11.79],[27,8.91],[13.5,0],[9.4,0]],"id":41419616},{"atl":[[990,0.15]],"id":41419616},{"atb":[[32,7.83],[5.6,0],[7.2,0],[13,0],[13.5,16.91]],"id":41419612},{"atl":[[620,0.25],[650,1.89]],"id":41419612},{"atb":[[16,8.91],[6.4,0],[8.4,0]],"id":41419592},{"atb":[[610,0],[310,0],[410,0]],"id":41435526},{"atb":[[32,0],[65,9.9],[21,0],[85,4.95],[110,0]],"id":41419621},{"atb":[[16.5,11.64],[17,9.9],[6.4,0],[19,4.95],[11,8.91],[5.2,0]],"id":41419588},{"atl":[[34,4.95],[42,9.9],[470,0.33],[500,2.45]],"id":41419588},{"atb":[[9.6,0],[28,8.91],[14,0]],"id":41419600},{"atl":[[820,1.49]],"id":41419600},{"atb":[[34,0],[22,0],[120,1.32]],"id":41419596},{"atl":[[960,0.16]],"id":41419596},{"atb":[[700,0],[400,0],[500,0]],"id":41419658}],"con":true,"img":false}]}
{"op":"mcm","clk":"5353934935","pt":1646219941755,"mc":[{"id":"1.195503869","rc":[{"atl":[[930,0]],"id":41419609},{"atl":[[340,2],[740,0]],"id":41419605},{"atl":[[520,2],[920,0]],"id":41419593},{"atl":[[400,0]],"id":41419589},{"atb":[[27,0]],"id":41419602},{"atl":[[1000,0]],"id":41419602},{"atl":[[32,3.23],[280,0]],"id":41419585},{"atl":[[40,2.56]],"id":41419586},{"atl":[[430,2]],"id":41419594},{"atl":[[330,2],[710,0]],"id":41419607},{"atl":[[660,0]],"id":41419636},{"atb":[[20,0]],"id":41419603},{"atl":[[880,0]],"id":41419603},{"atl":[[160,2]],"id":41419620},{"atl":[[630,0]],"id":41419612},{"atl":[[970,0]],"id":41419596}],"con":true,"img":false}]}
{"op":"mcm","clk":"5353934952","pt":1646219941879,"mc":[{"id":"1.195503869","rc":[{"atl":[[540,2]],"id":41419609},{"atl":[[880,0],[480,2]],"id":41419638},{"atl":[[400,0],[60,2]],"id":41419634},{"atl":[[730,0]],"id":41419613},{"atl":[[520,2],[900,0]],"id":41419622},{"atl":[[55,2]],"id":41419589},{"atl":[[340,2],[740,0]],"id":41419601},{"atl":[[770,0],[400,2]],"id":28546943},{"atl":[[810,0],[830,3.47]],"id":41419626},{"atl":[[330,2],[700,0]],"id":41419639},{"atl":[[80,2],[460,0]],"id":41419606},{"atl":[[610,0],[630,3.95]],"id":41419635},{"atb":[[44,2.33]],"id":41419602},{"atl":[[830,2]],"id":41419602},{"atl":[[830,0],[430,2]],"id":41419610},{"atl":[[850,0],[460,2]],"id":41419623},{"atl":[[650,2],[1000,0]],"id":41419619},{"atl":[[250,0]],"id":41419586},{"atl":[[810,0],[430,2]],"id":41419598},{"atb":[[130,1.23]],"id":41419660},{"atl":[[1000,0.15]],"id":41419660},{"atl":[[830,0]],"id":41419594},{"atl":[[260,2]],"id":41419636},{"atb":[[27,3.85]],"id":41419603},{"atl":[[890,2]],"id":41419603},{"atl":[[540,0]],"id":41419620},{"atl":[[130,0],[27,3.85]],"id":41419587},{"atl":[[110,2],[510,0]],"id":41419599},{"atl":[[350,2],[750,0]],"id":41419608},{"atl":[[580,0],[180,2]],"id":41419637},{"atl":[[630,2],[1000,0]],"id":41419616},{"atl":[[260,2]],"id":41419612},{"atl":[[530,0],[140,2]],"id":41419592},{"atl":[[890,0],[900,2]],"id":41419621},{"atl":[[95,2],[480,0]],"id":41419588},{"atl":[[800,0]],"id":41419600}],"con":true,"img":false}]}
{"op":"mcm","clk":"5353934958","pt":1646219941967,"mc":[{"id":"1.195503869","rc":[{"atl":[[340,2]],"id":41419613},{"atl":[[400,2]],"id":41419600}],"con":true,"img":false}]}
{"op":"mcm","clk":"5353934973","pt":1646219942084,"mc":[{"id":"1.195503869","rc":[{"atl":[[540,0],[920,2.17]],"id":41419609},{"atl":[[6,1.69]],"id":41419591},{"trd":[[6,370.78]],"ltp":6.0,"tv":370.78,"id":41419591}],"con":true,"img":false}]}
{"op":"mcm","clk":"5353934980","pt":1646219942175,"mc":[{"id":"1.195503869","rc":[{"atb":[[160,4.95],[23,10.56],[190,0.83],[120,9.9]],"id":41419651},{"atl":[[1000,0.02]],"id":41419651},{"atl":[[1000,1.22]],"id":41419602},{"atb":[[9.4,17.17]],"id":41419585},{"atb":[[160,8.22],[23,10.56],[220,0.72],[120,9.9]],"id":41419656},{"atb":[[160,4.95],[180,0.88],[23,10.6],[120,13.17]],"id":41435528},{"atl":[[1000,1.22]],"id":41419619},{"atb":[[160,4.95],[23,10.56],[190,0.83],[120,9.9]],"id":41419653},{"atb":[[150,1.06]],"id":41419595},{"atl":[[240,5.13]],"id":41419616},{"atb":[[85,17.8]],"id":41435526},{"atl":[[990,3.23]],"id":41419596},{"atb":[[160,8.22],[23,10.56],[220,0.72],[120,9.9]],"id":41419658}],"con":true,"img":false}]}
{"op":"mcm","clk":"5353934992","pt":1646219942280,"mc":[{"id":"1.195503869","rc":[{"atb":[[170,0.93]],"id":41435526},{"atl":[[1000,0.02]],"id":41435526}],"con":true,"img":false}]}
{"op":"mcm","clk":"5353935005","pt":1646219942337,"mc":[{"id":"1.195503869","rc":[{"atb":[[150,4.95],[110,12.63]],"id":41419617},{"atl":[[600,0.26]],"id":41419635},{"atl":[[13.5,39.36]],"id":41419591}],"con":true,"img":false}]}
{"op":"mcm","clk":"5353935019","pt":1646219942440,"mc":[{"id":"1.195503869","rc":[{"atl":[[220,0],[230,4.95]],"id":41419619},{"atl":[[200,0],[210,4.95]],"id":41419598},{"atl":[[220,0],[230,4.95]],"id":41419616}],"con":true,"img":false}]}
{"op":"mcm","clk":"5353935028","pt":1646219942545,"mc":[{"id":"1.195503869","rc":[{"atl":[[8.6,2],[11.5,20.05]],"id":41419591}],"con":true,"img":false}]}
{"op":"mcm","clk":"5353935036","pt":1646219942653,"mc":[{"id":"1.195503869","rc":[{"atb":[[4.3,71.08]],"id":41419591}],"con":true,"img":false}]}
{"op":"mcm","clk":"5353935052","pt":1646219942860,"mc":[{"id":"1.195503869","rc":[{"atb":[[5.6,34.46],[3.7,0]],"id":41419591}],"con":true,"img":false}]}
{"op":"mcm","clk":"5353935057","pt":1646219942963,"mc":[{"id":"1.195503869","rc":[{"atb":[[5.8,4.95],[5.5,0],[5.9,0]],"id":41419591},{"atl":[[6,0]],"id":41419591},{"trd":[[6,374.17]],"ltp":6.0,"tv":374.17,"id":41419591}],"con":true,"img":false}]}
{"op":"mcm","clk":"5353935069","pt":1646219943068,"mc":[{"id":"1.195503869","rc":[{"atb":[[34,9.9],[36,2.72],[42,4.95],[44,0]],"id":41419608}],"con":true,"img":false}]}
{"op":"mcm","clk":"5353935079","pt":1646219943173,"mc":[{"id":"1.195503869","rc":[{"atl":[[210,0]],"id":41419598}],"con":true,"img":false}]}
{"op":"mcm","clk":"5353935131","pt":1646219943651,"mc":[{"id":"1.195503869","rc":[{"atl":[[220,0],[240,4.95]],"id":41419593},{"atl":[[1000,0]],"id":41419651},{"atl":[[110,0],[120,4.95]],"id":41419635},{"atl":[[22,0],[26,0]],"id":41419585},{"atb":[[9,9.9],[10,0],[9.2,0],[9.8,4.95]],"id":41419586},{"atl":[[220,4.95]],"id":41419598},{"atl":[[200,0],[210,4.95]],"id":41419594},{"atl":[[90,0],[95,4.95],[120,0]],"id":41419592}],"con":true,"img":false}]}
{"op":"mcm","clk":"5353935141","pt":1646219943755,"mc":[{"id":"1.195503869","rc":[{"atl":[[23,4.95],[27,9.9]],"id":41419585}],"con":true,"img":false}]}
{"op":"mcm","clk":"5353935160","pt":1646219943966,"mc":[{"id":"1.195503869","rc":[{"atl":[[75,0],[80,9.9],[55,0],[60,4.95]],"id":41419620}],"con":true,"img":false}]}
{"op":"mcm","clk":"5353935197","pt":1646219944380,"mc":[{"id":"1.195503869","rc":[{"atl":[[230,4.95],[240,0]],"id":41419593},{"atb":[[12,0],[14.5,7.41]],"id":41419639},{"atb":[[7.2,8.91]],"id":41419606},{"atb":[[5.2,0]],"id":41419585},{"atl":[[8.6,0]],"id":41419591},{"atb":[[8.4,0],[9.4,11.9]],"id":41419588}],"con":true,"img":false}]}
{"op":"mcm","clk":"5353935210","pt":1646219944437,"mc":[{"id":"1.195503869","rc":[{"atb":[[8.2,13.89]],"id":41419606},{"atb":[[5.7,21.28]],"id":41419585},{"atl":[[990,2]],"id":41419591}],"con":true,"img":false}]}
{"op":"mcm","clk":"5353935247","pt":1646219944749,"mc":[{"id":"1.195503869","rc":[{"atl":[[11,27.01]],"id":41419591}],"con":true,"img":false}]}
{"op":"mcm","clk":"5353935254","pt":1646219944855,"mc":[{"id":"1.195503869","rc":[{"atl":[[11.5,4.95]],"id":41419591}],"con":true,"img":false}]}
{"op":"mcm","clk":"5353935402","pt":1646219946607,"mc":[{"id":"1.195503869","rc":[{"atb":[[9,35.02],[25,14.75],[12.5,24.36]],"id":41419609},{"atb":[[9.2,34.16],[26,14.51],[13,23.34]],"id":41419638},{"atb":[[6.2,53.88],[8.2,38.91],[15.5,18.57]],"id":41419605},{"atb":[[4,93.39],[6,36.93],[3.5,112.07]],"id":41419634},{"atb":[[34,8.49],[22,13.34],[120,1.17]],"id":41419617},{"atb":[[16,18.25],[6.4,51.88],[8.4,37.86]],"id":41419613},{"atb":[[10,31.13],[30,4.82],[15,20.01]],"id":41419593},{"atb":[[18,16.48],[80,1.77],[26,11.2]],"id":41419655},{"atb":[[8.6,36.86],[23,19.83],[11.5,26.68]],"id":41419622},{"atb":[[8.6,27.34],[4.3,84.9],[5.3,65.15]],"id":41419589},{"atb":[[18.5,16.01],[85,9.78],[27,10.77]],"id":41435527},{"atb":[[700,0.2],[400,0.7],[500,0.56]],"id":41419651},{"atb":[[7.8,41.2],[14.5,10.37],[5.9,57.18]],"id":41419601},{"atb":[[17.5,23.46],[9,35.02],[7,46.69]],"id":28546943},{"atb":[[22,6.67],[11,28.01],[8.4,37.86]],"id":41419626},{"atb":[[21,15.91],[10.5,29.49],[8.2,38.91]],"id":41419639},{"atb":[[3.85,98.31],[3.35,119.22],[5.7,29.8]],"id":41419606},{"atb":[[9.2,34.16],[26,14.51],[13,23.34]],"id":41419635},{"atb":[[9.6,32.58],[28,14.1],[14,21.55]],"id":41419602},{"atb":[[6.4,51.88],[11,14],[5.2,66.71]],"id":41419585},{"atb":[[310,0.45],[110,14.31],[55,5.18]],"id":41419614},{"atb":[[8,40.02],[20,16.29],[10,31.13]],"id":41419610},{"atb":[[700,0.2],[400,0.7],[500,0.56]],"id":41419656},{"atb":[[21,20.91],[10.5,29.49],[8.2,38.91]],"id":41419623},{"atb":[[19.5,15.14],[95,1.48],[29,10]],"id":41419652},{"atb":[[650,0.21],[350,0.8],[450,0.62]],"id":41435528},{"atb":[[9.6,32.58],[28,14.1],[14,21.55]],"id":41419619},{"atb":[[3.6,107.76],[3.1,133.42],[5.2,42.27]],"id":41419586},{"atb":[[9.6,32.58],[28,14.1],[14,21.55]],"id":41419598},{"atb":[[20,14.74],[100,1.41],[30,9.66]],"id":41419660},{"atb":[[27,13.5],[13.5,22.41],[9.4,33.35]],"id":41419594},{"atb":[[9,35.02],[25,14.75],[12.5,24.36]],"id":41419607},{"atb":[[8.6,36.86],[23,19.83],[11.5,26.68]],"id":28546950},{"atb":[[6.2,53.88],[8.2,38.91],[15.5,18.57]],"id":41419636},{"atb":[[22,15.58],[11,28.01],[8.4,37.86]],"id":41419603},{"atb":[[10,31.13],[30,4.82],[15,20.01]],"id":41419615},{"atb":[[140,1],[38,7.57],[24,12.18]],"id":41419657},{"atb":[[32,9.03],[21,14],[110,1.28]],"id":41419624},{"atb":[[3.45,76.11],[4.9,23.9],[2.98,94.17]],"id":41419591},{"atb":[[16,18.67],[22,13.34],[60,2.37]],"id":41435525},{"atb":[[700,0.2],[400,0.7],[500,0.56]],"id":41419653},{"atb":[[12,21.65],[6.8,48.31],[5.4,63.67]],"id":41419620},{"atb":[[3.2,127.35],[2.88,149.03],[4.4,79.52]],"id":41419587},{"atb":[[4.3,84.9],[6.6,25.01],[3.65,105.72]],"id":41419599},{"atb":[[310,0.45],[110,10.21],[55,5.18]],"id":41419595},{"atb":[[5.8,58.37],[7.6,42.45],[14,10.77]],"id":41419608},{"atb":[[5.6,60.91],[7.2,45.19],[13,20.59]],"id":41419637},{"atb":[[27,14.3],[13.5,22.41],[9.4,33.35]],"id":41419616},{"atb":[[5.6,60.91],[7.2,45.19],[13,11.67]],"id":41419612},{"atb":[[16,18.25],[6.4,51.88],[8.4,37.86]],"id":41419592},{"atb":[[610,0.22],[310,0.9],[410,0.68]],"id":41435526},{"atb":[[32,9.03],[21,14],[110,1.28]],"id":41419621},{"atb":[[6.4,51.88],[11,22.92],[5.2,66.71]],"id":41419588},{"atb":[[9.6,32.58],[28,14.1],[14,21.55]],"id":41419600},{"atb":[[34,8.49],[22,13.34],[120,2.5]],"id":41419596},{"atb":[[700,0.2],[400,0.7],[500,0.56]],"id":41419658}],"con":true,"img":false}]}
{"op":"mcm","clk":"5353935438","pt":1646219946963,"mc":[{"id":"1.195503869","rc":[{"atl":[[520,0],[910,2.17]],"id":41419593},{"atl":[[820,2.19],[430,0]],"id":41419594},{"atl":[[330,0],[700,2.22]],"id":41419607}],"con":true,"img":false}]}
{"op":"mcm","clk":"5353935447","pt":1646219947075,"mc":[{"id":"1.195503869","rc":[{"atl":[[870,2.17],[480,0]],"id":41419638},{"atl":[[340,0],[720,2.21]],"id":41419613},{"atl":[[520,0],[890,2.17]],"id":41419622},{"atb":[[23,2.45]],"id":41419651},{"atl":[[760,2.2],[400,0]],"id":28546943},{"atl":[[830,0],[990,2.15]],"id":41419602},{"atb":[[9.4,4.95]],"id":41419585},{"atl":[[820,2.19],[430,0]],"id":41419610},{"atb":[[23,2.45]],"id":41419656},{"atl":[[840,2.19],[460,0]],"id":41419623},{"atb":[[23,2.49]],"id":41435528},{"atl":[[650,0],[990,2.15]],"id":41419619},{"atl":[[800,2.19],[430,0]],"id":41419598},{"atb":[[23,2.45]],"id":41419653},{"atl":[[520,2.3],[140,0]],"id":41419592},{"atb":[[85,3.27]],"id":41435526},{"atl":[[1000,0]],"id":41435526},{"atl":[[900,0],[910,3.34]],"id":41419621},{"atl":[[790,2.2],[400,0]],"id":41419600},{"atb":[[23,2.45]],"id":41419658}],"con":true,"img":false}]}
{"op":"mcm","clk":"5353935505","pt":1646219947550,"mc":[{"id":"1.195503869","rc":[{"atb":[[1.01,0]],"id":41419591}],"con":true,"img":false}]}
{"op":"mcm","clk":"5353935516","pt":1646219947653,"mc":[{"id":"1.195503869","rc":[{"atb":[[5.8,6.46]],"id":41419591}],"con":true,"img":false}]}
{"op":"mcm","clk":"5353935726","pt":1646219949851,"mc":[{"id":"1.195503869","rc":[{"atl":[[630,3.98],[240,0]],"id":41419616}],"con":true,"img":false}]}
{"op":"mcm","clk":"5353936328","pt":1646219957275,"mc":[{"id":"1.195503869","rc":[{"atb":[[65,13.52],[95,6.63]],"id":41419609},{"atl":[[180,5.84]],"id":41419609},{"atb":[[70,7.25],[26,5.6]],"id":41419638},{"atb":[[34,17.44],[44,8.64],[15.5,9.66]],"id":41419605},{"atl":[[340,5.75],[90,6.73],[760,0]],"id":41419605},{"atb":[[11.5,15.48],[6,28.01]],"id":41419634},{"atl":[[420,0]],"id":41419634},{"atb":[[80,3.27],[120,4.75]],"id":41419617},{"atl":[[220,0.72]],"id":41419593},{"atb":[[85,12.05],[46,3.27]],"id":41419655},{"atb":[[23,10.91],[60,14.14]],"id":41419622},{"atb":[[8.6,18.43],[10,31.99]],"id":41419589},{"atl":[[420,0],[55,24.08]],"id":41419589},{"atb":[[170,0.93]],"id":41435527},{"atb":[[32,28.04],[40,9.02],[15,7.14]],"id":41419601},{"atl":[[340,5.75],[90,6.73],[760,0]],"id":41419601},{"atb":[[44,3.68]],"id":28546943},{"atl":[[110,6.4]],"id":28546943},{"atb":[[42,15.8],[23,4.55]],"id":41419626},{"atl":[[90,6.73]],"id":41419639},{"atb":[[7.2,0],[14.5,31.99]],"id":41419606},{"atl":[[480,0]],"id":41419606},{"atb":[[26,5.6],[27,15.68]],"id":41419635},{"atb":[[110,6.4],[28,5.18]],"id":41419602},{"atl":[[32,15.44],[300,0],[22,7.54]],"id":41419585},{"atb":[[20,7.37],[44,12.01]],"id":41419610},{"atb":[[60,7.64]],"id":41419623},{"atl":[[140,6.09]],"id":41419623},{"atb":[[170,0.93],[100,11.33],[55,3.27]],"id":41419652},{"atb":[[100,6.55]],"id":41419619},{"atl":[[230,5.64]],"id":41419619},{"atb":[[5.2,33.35],[8.4,31.62]],"id":41419586},{"atl":[[40,24.42]],"id":41419586},{"atb":[[50,12.18],[27,5.39]],"id":41419594},{"atl":[[200,0.79]],"id":41419594},{"atb":[[38,13.87],[25,5.83]],"id":41419607},{"atb":[[23,10.91],[110,6.4]],"id":28546950},{"atl":[[70,7.25]],"id":41419636},{"atb":[[70,7.25],[22,6.67],[48,14.14]],"id":41419603},{"atl":[[150,6.01],[890,3.42],[900,0]],"id":41419603},{"atb":[[130,6.18]],"id":41419615},{"atb":[[140,4.08],[170,0.93],[90,3.27]],"id":41419657},{"atb":[[4.9,40.92]],"id":41419591},{"atb":[[50,3.27]],"id":41435525},{"atb":[[12,12.73],[25,15.48]],"id":41419620},{"atl":[[560,0],[160,9.98],[60,7.64]],"id":41419620},{"atb":[[9.6,11.63],[18,31.99],[20,13.29]],"id":41419599},{"atl":[[530,0],[38,9.23],[110,13.61]],"id":41419599},{"atb":[[110,2.57]],"id":41419595},{"atb":[[36,16.44],[14.5,7.41]],"id":41419608},{"atl":[[350,5.64],[770,0]],"id":41419608},{"atb":[[25,15.48],[13,11.67]],"id":41419637},{"atl":[[600,0],[180,9.09]],"id":41419637},{"atb":[[16,9.34],[23,13.87]],"id":41419592},{"atl":[[90,1.78]],"id":41419592},{"atl":[[130,6.18]],"id":41419600},{"atb":[[80,3.27],[85,19.53]],"id":41419596},{"atl":[[990,2],[980,1.29]],"id":41419596}],"con":true,"img":false}]}
{"op":"mcm","clk":"5353936338","pt":1646219957378,"mc":[{"id":"1.195503869","rc":[{"atb":[[25,5.83]],"id":41419609},{"atl":[[150,6.01]],"id":41419638},{"atl":[[60,14.21]],"id":41419634},{"atb":[[150,6.01]],"id":41419617},{"atb":[[16,9.34],[36,12.18]],"id":41419613},{"atl":[[100,6.55]],"id":41419613},{"atb":[[32,3.23],[60,15.48]],"id":41419593},{"atb":[[170,0.93]],"id":41419655},{"atb":[[85,6.83]],"id":41419622},{"atl":[[160,5.95]],"id":41419622},{"atb":[[130,8.47],[85,1.66]],"id":41435527},{"atb":[[17.5,14.55],[25,21.32]],"id":28546943},{"atl":[[130,6.18]],"id":41419626},{"atb":[[21,7],[30,17.98]],"id":41419639},{"atl":[[330,5.86],[720,0]],"id":41419639},{"atb":[[16.5,15.18]],"id":41419606},{"atl":[[80,17.97],[28,10.82]],"id":41419606},{"atb":[[70,13.07]],"id":41419602},{"atl":[[240,5.61]],"id":41419602},{"atb":[[50,8.19]],"id":41419610},{"atl":[[130,6.18]],"id":41419610},{"atb":[[9.8,22.97]],"id":41419586},{"atl":[[16.5,15.18],[270,0]],"id":41419586},{"atb":[[50,13.87],[28,5.18]],"id":41419598},{"atl":[[210,0.75]],"id":41419598},{"atb":[[85,3.27],[120,21.81]],"id":41419660},{"atl":[[110,6.4]],"id":41419607},{"atb":[[75,8.5]],"id":28546950},{"atb":[[34,9.76]],"id":41419636},{"atl":[[260,6.91],[680,0]],"id":41419636},{"atb":[[90,11.78],[48,2.13]],"id":41419615},{"atb":[[70,3.27],[140,1.13],[110,5.18]],"id":41419624},{"atb":[[4.3,0]],"id":41419591},{"atb":[[80,12.35],[170,0.93]],"id":41435525},{"atb":[[4.4,70.61],[6.6,25.35]],"id":41419587},{"atl":[[150,0],[12.5,18.74],[27,25.93]],"id":41419587},{"atb":[[140,9.92]],"id":41419595},{"atb":[[42,8.82]],"id":41419608},{"atl":[[90,6.73]],"id":41419608},{"atb":[[80,16.01],[110,6.4],[27,5.39]],"id":41419616},{"atl":[[230,5.64]],"id":41419616},{"atb":[[34,9.76],[13.5,8],[28,28.91]],"id":41419612},{"atl":[[260,6.91],[70,7.25],[650,0]],"id":41419612},{"atb":[[70,3.27],[85,13.06]],"id":41419621},{"atl":[[910,2],[900,1.41]],"id":41419621},{"atb":[[16.5,33.73],[19,13.76],[11,14]],"id":41419588},{"atl":[[34,9.76],[500,0]],"id":41419588},{"atb":[[46,12.18],[28,5.18]],"id":41419600}],"con":true,"img":false}]}
{"op":"mcm","clk":"5353936348","pt":1646219957482,"mc":[{"id":"1.195503869","rc":[{"atb":[[12,19.36]],"id":41419589},{"atl":[[20,13.29]],"id":41419589},{"atb":[[21,12],[46,24.62]],"id":41419623},{"atb":[[80,23.2],[28,5.18]],"id":41419619},{"atb":[[28,28.91],[15.5,9.66]],"id":41419636},{"atl":[[630,2],[990,1.43]],"id":41419616},{"atl":[[520,0.3],[140,2]],"id":41419592}],"con":true,"img":false}]}
{"op":"mcm","clk":"5353936355","pt":1646219957584,"mc":[{"id":"1.195503869","rc":[{"atb":[[170,0.93]],"id":41419660},{"atl":[[630,0],[990,3.43]],"id":41419616},{"atl":[[95,15.46]],"id":41419588}],"con":true,"img":false}]}
{"op":"mcm","clk":"5353936363","pt":1646219957692,"mc":[{"id":"1.195503869","rc":[{"atb":[[50,24.36]],"id":41419638}],"con":true,"img":false}]}
{"op":"mcm","clk":"5353936376","pt":1646219957794,"mc":[{"id":"1.195503869","rc":[{"atl":[[910,3.56],[940,0]],"id":41419593},{"atl":[[820,3.74],[850,0]],"id":41419594},{"atl":[[550,0]],"id":41419592}],"con":true,"img":false}]}
{"op":"mcm","clk":"5353936385","pt":1646219957846,"mc":[{"id":"1.195503869","rc":[{"atl":[[800,3.78],[830,0]],"id":41419598},{"atl":[[520,2.75]],"id":41419592}],"con":true,"img":false}]}
{"op":"mcm","clk":"5353936396","pt":1646219957953,"mc":[{"id":"1.195503869","rc":[{"atb":[[65,11.04]],"id":41419609},{"atl":[[920,2]],"id":41419609},{"atb":[[55,0]],"id":41419638},{"atb":[[36,9.9]],"id":41419605},{"atl":[[730,0]],"id":41419605},{"atb":[[140,0]],"id":41435527},{"atb":[[36,2.72]],"id":41419601},{"atl":[[730,0]],"id":41419601},{"atb":[[25,14.71]],"id":28546943},{"atl":[[690,0]],"id":41419639},{"atl":[[840,2]],"id":41419623},{"atb":[[85,0]],"id":41419619},{"atl":[[650,0]],"id":41419636},{"atb":[[90,10]],"id":41419615},{"atb":[[150,0]],"id":41419657},{"atb":[[18.5,2.72]],"id":41419599},{"atl":[[790,2]],"id":41419600}],"con":true,"img":false}]}
{"op":"mcm","clk":"5353936402","pt":1646219958109,"mc":[{"id":"1.195503869","rc":[{"atl":[[870,2]],"id":41419638},{"atl":[[720,2]],"id":41419613},{"atl":[[910,3.39]],"id":41419593},{"atb":[[85,10.16]],"id":41419655},{"atb":[[65,9.9]],"id":41419622},{"atl":[[890,2]],"id":41419622},{"atb":[[12.5,1.51]],"id":41419589},{"atl":[[760,2]],"id":28546943},{"atb":[[16,2.72],[6.6,0]],"id":41419606},{"atl":[[28,4.95],[450,0]],"id":41419606},{"atl":[[110,1.45]],"id":41419635},{"atb":[[70,10.77]],"id":41419602},{"atl":[[990,2]],"id":41419602},{"atl":[[270,0]],"id":41419585},{"atb":[[46,0]],"id":41419610},{"atl":[[820,2]],"id":41419610},{"atb":[[55,2.72]],"id":41419623},{"atb":[[100,9.73]],"id":41419652},{"atl":[[990,2]],"id":41419619},{"atb":[[5.3,0],[8.4,24.59]],"id":41419586},{"atl":[[820,3.55]],"id":41419594},{"atb":[[75,6.36]],"id":28546950},{"atb":[[32,2.72]],"id":41419636},{"atb":[[50,9.9]],"id":41419603},{"atl":[[870,0]],"id":41419603},{"atb":[[120,0]],"id":41419624},{"atb":[[80,10.34]],"id":41435525},{"atl":[[530,0]],"id":41419620},{"atl":[[120,0]],"id":41419587},{"atb":[[20,14.78]],"id":41419599},{"atl":[[500,0]],"id":41419599},{"atb":[[38,0]],"id":41419608},{"atb":[[85,9.9]],"id":41419616},{"atl":[[620,0]],"id":41419612},{"atl":[[520,2.45]],"id":41419592},{"atl":[[470,0]],"id":41419588},{"atl":[[980,0]],"id":41419596}],"con":true,"img":false}]}
{"op":"mcm","clk":"5353936414","pt":1646219958162,"mc":[{"id":"1.195503869","rc":[{"atb":[[130,0]],"id":41419617},{"atb":[[11.5,2.72]],"id":41419589},{"atl":[[390,0]],"id":41419589},{"atl":[[800,0]],"id":41419626},{"atb":[[17,1.56]],"id":41419606},{"atb":[[10,1.49]],"id":41419586},{"atl":[[240,0]],"id":41419586},{"atl":[[800,3.59]],"id":41419598},{"atl":[[700,2]],"id":41419607},{"atl":[[740,0]],"id":41419608},{"atl":[[990,3.28]],"id":41419616},{"atb":[[32,2.72]],"id":41419612},{"atb":[[16.5,24.81]],"id":41419588}],"con":true,"img":false}]}
{"op":"mcm","clk":"5353936424","pt":1646219958268,"mc":[{"id":"1.195503869","rc":[{"atl":[[630,1.95],[230,2]],"id":41419635},{"atb":[[130,0]],"id":41419660}],"con":true,"img":false}]}
{"op":"mcm","clk":"5353936457","pt":1646219958585,"mc":[{"id":"1.195503869","rc":[{"atl":[[600,2.39],[630,0]],"id":41419635}],"con":true,"img":false}]}
{"op":"mcm","clk":"5353936467","pt":1646219958688,"mc":[{"id":"1.195503869","rc":[{"atl":[[830,2]],"id":41419626}],"con":true,"img":false}]}
{"op":"mcm","clk":"5353936475","pt":1646219958794,"mc":[{"id":"1.195503869","rc":[{"atb":[[12.5,0]],"id":41419589},{"atb":[[17,0]],"id":41419606},{"atb":[[20,13.29]],"id":41419599}],"con":true,"img":false}]}
{"op":"mcm","clk":"5353936484","pt":1646219958899,"mc":[{"id":"1.195503869","rc":[{"atb":[[1.01,1.51]],"id":41419589},{"atl":[[150,8.54]],"id":41419626},{"atb":[[1.01,1.56]],"id":41419606},{"atl":[[34,14.71]],"id":41419606},{"atl":[[600,2.13]],"id":41419635},{"atb":[[1.01,1.49]],"id":41419599}],"con":true,"img":false}]}
{"op":"mcm","clk":"5353936501","pt":1646219959054,"mc":[{"id":"1.195503869","rc":[{"atl":[[830,0],[450,2]],"id":41419626}],"con":true,"img":false}]}
{"op":"mcm","clk":"5353936527","pt":1646219959374,"mc":[{"id":"1.195503869","rc":[{"atl":[[21,4.95],[25,9.9]],"id":41419634}],"con":true,"img":false}]}
{"op":"mcm","clk":"5353936533","pt":1646219959472,"mc":[{"id":"1.195503869","rc":[{"atl":[[20,0],[24,0]],"id":41419634},{"atb":[[44,0]],"id":28546943}],"con":true,"img":false}]}
{"op":"mcm","clk":"5353936573","pt":1646219959992,"mc":[{"id":"1.195503869","rc":[{"atl":[[21,12.88]],"id":41419634}],"con":true,"img":false}]}
{"op":"mcm","clk":"5353936599","pt":1646219960256,"mc":[{"id":"1.195503869","rc":[{"atb":[[36,4.52]],"id":28546943}],"con":true,"img":false}]}
{"op":"mcm","clk":"5353936635","pt":1646219960678,"mc":[{"id":"1.195503869","rc":[{"atb":[[5.6,0],[6.8,17.24]],"id":41419634},{"atl":[[390,0]],"id":41419634}],"con":true,"img":false}]}
{"op":"mcm","clk":"5353937030","pt":1646219964873,"mc":[{"id":"1.195503869","rc":[{"atb":[[110,24.44],[120,1.17]],"id":41419617},{"atb":[[42,31.28],[44,2.72]],"id":41419610},{"atb":[[34,37.74],[36,2.72]],"id":41419608}],"con":true,"img":false}]}
{"op":"mcm","clk":"5353937039","pt":1646219964978,"mc":[{"id":"1.195503869","rc":[{"atb":[[80,12.63],[55,16.53]],"id":41419619},{"atl":[[900,0],[910,3.42]],"id":41419621}],"con":true,"img":false}]}
{"op":"mcm","clk":"5353937057","pt":1646219965187,"mc":[{"id":"1.195503869","rc":[{"atb":[[40,17.08],[50,12.63]],"id":41419638}],"con":true,"img":false}]}
{"op":"mcm","clk":"5353937077","pt":1646219965395,"mc":[{"id":"1.195503869","rc":[{"atl":[[990,2],[250,5.19]],"id":41419616}],"con":true,"img":false}]}
{"op":"mcm","clk":"5353937093","pt":1646219965607,"mc":[{"id":"1.195503869","rc":[{"atl":[[630,2],[990,0]],"id":41419616}],"con":true,"img":false}]}
{"op":"mcm","clk":"5353937150","pt":1646219966181,"mc":[{"id":"1.195503869","rc":[{"atl":[[250,0]],"id":41419616}],"con":true,"img":false}]}
{"op":"mcm","clk":"5353937168","pt":1646219966388,"mc":[{"id":"1.195503869","rc":[{"atl":[[150,0],[450,4.88]],"id":41419626}],"con":true,"img":false}]}
{"op":"mcm","clk":"5353937581","pt":1646219971007,"mc":[{"id":"1.195503869","rc":[{"atb":[[9.6,21.84]],"id":41419585}],"con":true,"img":false}]}
{"op":"mcm","clk":"5353937727","pt":1646219972581,"mc":[{"id":"1.195503869","rc":[{"atb":[[9,47.2]],"id":41419586}],"con":true,"img":false}]}
{"op":"mcm","clk":"5353937732","pt":1646219972688,"mc":[{"id":"1.195503869","rc":[{"atb":[[85,0],[120,18.66]],"id":41419655},{"atb":[[44,3.68]],"id":28546943},{"atl":[[32,3.23],[27,35.86]],"id":41419585},{"atb":[[100,0],[120,18.66]],"id":41419652},{"atb":[[8.4,2.72]],"id":41419586},{"atl":[[170,7.77],[890,2]],"id":41419603},{"atl":[[980,1.34]],"id":41419596}],"con":true,"img":false}]}
{"op":"mcm","clk":"5353937743","pt":1646219972794,"mc":[{"id":"1.195503869","rc":[{"atb":[[34,23.99],[25,0]],"id":28546943},{"atl":[[28,10.82]],"id":41419606},{"atb":[[10,19.1]],"id":41419586},{"atl":[[490,2]],"id":41419603},{"atb":[[80,0],[120,18.66]],"id":41435525},{"atl":[[250,5.28]],"id":41419616},{"atl":[[910,2],[900,1.46]],"id":41419621}],"con":true,"img":false}]}
{"op":"mcm","clk":"5353937753","pt":1646219972894,"mc":[{"id":"1.195503869","rc":[{"atl":[[890,0]],"id":41419603}],"con":true,"img":false}]}
{"op":"mcm","clk":"5353937774","pt":1646219973208,"mc":[{"id":"1.195503869","rc":[{"atl":[[520,0],[140,10.91]],"id":41419592}],"con":true,"img":false}]}
{"op":"mcm","clk":"5353937790","pt":1646219973417,"mc":[{"id":"1.195503869","rc":[{"atb":[[36,0]],"id":28546943},{"atl":[[170,0]],"id":41419603}],"con":true,"img":false}]}
{"op":"mcm","clk":"5353937798","pt":1646219973520,"mc":[{"id":"1.195503869","rc":[{"atl":[[34,9.9],[28,4.95]],"id":41419606},{"atl":[[900,0]],"id":41419621}],"con":true,"img":false}]}
{"op":"mcm","clk":"5353937806","pt":1646219973623,"mc":[{"id":"1.195503869","rc":[{"atb":[[9.8,4.95]],"id":41419586}],"con":true,"img":false}]}
{"op":"mcm","clk":"5353937836","pt":1646219973890,"mc":[{"id":"1.195503869","rc":[{"atl":[[600,0],[230,7.75]],"id":41419635}],"con":true,"img":false}]}
{"op":"mcm","clk":"5353937871","pt":1646219974207,"mc":[{"id":"1.195503869","rc":[{"atl":[[150,8.84],[450,2]],"id":41419626},{"atl":[[34,14.71]],"id":41419606}],"con":true,"img":false}]}
{"op":"mcm","clk":"5353937936","pt":1646219974883,"mc":[{"id":"1.195503869","rc":[{"atl":[[150,0]],"id":41419626}],"con":true,"img":false}]}
{"op":"mcm","clk":"5353938416","pt":1646219980106,"mc":[{"id":"1.195503869","rc":[{"atl":[[980,0],[990,3.34]],"id":41419596}],"con":true,"img":false}]}
{"op":"mcm","clk":"5353938429","pt":1646219980213,"mc":[{"id":"1.195503869","rc":[{"atl":[[630,4.12],[250,0]],"id":41419616},{"atl":[[900,1.48]],"id":41419621}],"con":true,"img":false}]}
{"op":"mcm","clk":"5353938487","pt":1646219980836,"mc":[{"id":"1.195503869","rc":[{"atl":[[990,2]],"id":41419596}],"con":true,"img":false}]}
{"op":"mcm","clk":"5353938506","pt":1646219981050,"mc":[{"id":"1.195503869","rc":[{"atb":[[20,5.26],[13,0]],"id":41419613},{"atb":[[17.5,8.49],[20,5.26]],"id":28546943},{"atl":[[32,0],[28,3.7]],"id":41419585},{"atl":[[1000,0]],"id":28546950},{"atl":[[18.5,5.71],[24,0]],"id":41419591},{"atl":[[160,7.98],[240,2]],"id":41419620},{"atb":[[9.6,0],[11.5,9.52]],"id":41419599},{"atl":[[140,8.91],[210,2]],"id":41419592}],"con":true,"img":false}]}
{"op":"mcm","clk":"5353938531","pt":1646219981318,"mc":[{"id":"1.195503869","rc":[{"atb":[[32,9.9],[36,0],[40,4.95],[44,0]],"id":41419605},{"atl":[[90,4.95]],"id":41419605},{"atb":[[14,14.92]],"id":41419634},{"atl":[[21,7.93],[24,4.95],[25,0],[28,9.9]],"id":41419634},{"atb":[[46,6.24]],"id":41419613},{"atl":[[100,1.6],[110,4.95]],"id":41419613},{"atl":[[160,0.99],[180,4.95]],"id":41419622},{"atl":[[32,4.95],[34,4.8],[40,9.9],[28,0]],"id":41419606},{"atl":[[260,4.95],[240,0.66]],"id":41419602},{"atb":[[9.6,0],[8.6,0],[11.5,0],[9.4,0]],"id":41419585},{"atb":[[30,8.19]],"id":41419620},{"atl":[[70,4.95],[80,0],[90,9.9],[60,2.68]],"id":41419620},{"atb":[[6.2,9.9],[7.6,2.72],[6.8,0],[7,4.95]],"id":41419587},{"atl":[[38,4.28],[60,9.9]],"id":41419599},{"atb":[[34,0],[26,13.17],[28,19.01],[30,4.95]],"id":41419612},{"atb":[[38,0],[29,0]],"id":41419592},{"atb":[[310,2.27]],"id":41435526}],"con":true,"img":false}]}
{"op":"mcm","clk":"5353938539","pt":1646219981420,"mc":[{"id":"1.195503869","rc":[{"atb":[[10,1.49]],"id":41419586}],"con":true,"img":false}]}
{"op":"mcm","clk":"5353938543","pt":1646219981518,"mc":[{"id":"1.195503869","rc":[{"atl":[[720,0],[400,2]],"id":41419613},{"atl":[[220,0]],"id":41419593},{"atl":[[540,2],[890,0]],"id":41419622},{"atl":[[940,2],[990,0]],"id":41419602},{"atl":[[22,0]],"id":41419585},{"atl":[[200,0]],"id":41419594},{"atl":[[110,0],[120,4.95]],"id":41419607},{"atl":[[230,0],[240,4.95]],"id":41419616},{"atl":[[90,0]],"id":41419592}],"con":true,"img":false}]}
{"op":"mcm","clk":"5353938552","pt":1646219981628,"mc":[{"id":"1.195503869","rc":[{"atl":[[250,4.95]],"id":41419593},{"atl":[[130,1.23],[140,4.95],[150,8.97]],"id":41419626},{"atl":[[24,4.95],[28,13.6]],"id":41419585},{"atl":[[230,0]],"id":41419619},{"atl":[[60,0]],"id":41419620},{"atb":[[34,27.83],[38,4.95],[42,0],[30,9.9]],"id":41419608},{"atl":[[630,2]],"id":41419616},{"atl":[[95,0]],"id":41419592},{"atl":[[130,0],[150,4.95]],"id":41419600}],"con":true,"img":false}]}
{"op":"mcm","clk":"5353938559","pt":1646219981738,"mc":[{"id":"1.195503869","rc":[{"atb":[[32,33.2],[34,2.72]],"id":41419605},{"atl":[[28,36.42],[60,2]],"id":41419634},{"atl":[[100,0]],"id":41419613},{"atl":[[230,0]],"id":41419593},{"atl":[[40,31.99],[80,2]],"id":41419606},{"atl":[[990,1.35],[1000,0]],"id":41419602},{"atb":[[5.7,73.73]],"id":41419585},{"atl":[[23,0],[27,25.95]],"id":41419585},{"atl":[[240,4.95]],"id":41419619},{"atl":[[320,2],[700,0]],"id":41419607},{"atl":[[110,2],[60,32.37]],"id":41419599},{"atb":[[16,36.48],[23,4.95]],"id":41419592},{"atl":[[100,4.95]],"id":41419592}],"con":true,"img":false}]}
{"op":"mcm","clk":"5353938566","pt":1646219981842,"mc":[{"id":"1.195503869","rc":[{"atl":[[720,1.86],[750,0]],"id":41419613},{"atl":[[530,2],[910,1.39]],"id":41419593},{"atl":[[890,1.5],[920,0]],"id":41419622},{"atl":[[990,0],[1000,3.22]],"id":41419619},{"atl":[[160,0],[90,24.88]],"id":41419620},{"atb":[[24,6.89]],"id":41419592},{"atl":[[790,0],[400,2]],"id":41419600}],"con":true,"img":false}]}
{"op":"mcm","clk":"5353938575","pt":1646219981942,"mc":[{"id":"1.195503869","rc":[{"atl":[[910,0]],"id":41419593},{"atl":[[27,0],[28,61.78]],"id":41419585},{"atl":[[820,2],[230,5.85]],"id":41419594},{"atl":[[140,0],[210,8.41]],"id":41419592}],"con":true,"img":false}]}
{"op":"mcm","clk":"5353938584","pt":1646219982049,"mc":[{"id":"1.195503869","rc":[{"atb":[[34,7.53]],"id":41419605},{"atl":[[110,0],[120,4.95]],"id":41419613},{"atb":[[16.5,4.95],[16,7.67],[14,9.9]],"id":41419606},{"atb":[[11,16.73],[9.4,3.27]],"id":41419585},{"atb":[[10,0]],"id":41419586},{"atb":[[7.2,22.08]],"id":41419587},{"atb":[[30,10.42]],"id":41419612},{"atb":[[36,3.27],[46,2.72]],"id":41419592}],"con":true,"img":false}]}
{"op":"mcm","clk":"5353938591","pt":1646219982099,"mc":[{"id":"1.195503869","rc":[{"atb":[[16.5,0],[14.5,22.08]],"id":41419606},{"atl":[[1000,2]],"id":41419619},{"atb":[[1.01,1.49],[9.8,22.97]],"id":41419586},{"atl":[[820,0],[440,2]],"id":41419594}],"con":true,"img":false}]}
{"op":"mcm","clk":"5353938602","pt":1646219982208,"mc":[{"id":"1.195503869","rc":[{"atl":[[90,6.73]],"id":41419605},{"atl":[[26,6.34]],"id":41419585},{"atl":[[210,5.71]],"id":41419594},{"atl":[[110,1.45]],"id":41419607},{"atl":[[620,0.25]],"id":41419616}],"con":true,"img":false}]}
{"op":"mcm","clk":"5353938614","pt":1646219982315,"mc":[{"id":"1.195503869","rc":[{"atl":[[260,4.95],[250,0]],"id":41419593},{"atb":[[8,9.9],[8.8,4.95]],"id":41419585},{"atl":[[260,5.18],[990,0.15]],"id":41419619},{"atl":[[70,7.25]],"id":41419620},{"atb":[[38,9.23]],"id":41419608},{"atl":[[130,1.23]],"id":41419592},{"atl":[[390,0.4]],"id":41419600}],"con":true,"img":false}]}
{"op":"mcm","clk":"5353938631","pt":1646219982519,"mc":[{"id":"1.195503869","rc":[{"atl":[[120,6.28]],"id":41419613},{"atl":[[520,0.3]],"id":41419593},{"atb":[[14,36.05]],"id":41419606},{"atl":[[240,0],[250,4.95]],"id":41419619},{"atb":[[9,9.9],[8.4,40.02]],"id":41419586},{"atb":[[7,47.54],[6.6,3.27]],"id":41419587},{"atl":[[100,0],[110,4.95]],"id":41419592}],"con":true,"img":false}]}
{"op":"mcm","clk":"5353938637","pt":1646219982627,"mc":[{"id":"1.195503869","rc":[{"atb":[[14.5,0]],"id":41419606},{"atl":[[230,0]],"id":41419594},{"atl":[[320,6.21],[730,0]],"id":41419607},{"atl":[[90,9.9]],"id":41419620},{"atl":[[210,2]],"id":41419592}],"con":true,"img":false}]}
{"op":"mcm","clk":"5353938651","pt":1646219982733,"mc":[{"id":"1.195503869","rc":[{"atl":[[910,1.47]],"id":41419593},{"atb":[[14.5,11.74]],"id":41419606},{"atb":[[1.01,0]],"id":41419586},{"atb":[[4.5,0]],"id":41419587}],"con":true,"img":false}]}
{"op":"mcm","clk":"5353938657","pt":1646219982833,"mc":[{"id":"1.195503869","rc":[{"atb":[[10,1.49]],"id":41419586},{"atb":[[7.6,4.2]],"id":41419587},{"atl":[[400,5.36],[820,0]],"id":41419600}],"con":true,"img":false}]}
{"op":"mcm","clk":"5353938927","pt":1646219986230,"mc":[{"id":"1.195503869","rc":[{"atb":[[5.7,21.28]],"id":41419585}],"con":true,"img":false}]}
{"op":"mcm","clk":"5353938939","pt":1646219986437,"mc":[{"id":"1.195503869","rc":[{"atb":[[8.8,21.73]],"id":41419585}],"con":true,"img":false}]}
{"op":"mcm","clk":"5353938956","pt":1646219986699,"mc":[{"id":"1.195503869","rc":[{"atl":[[720,3.86],[400,0]],"id":41419613}],"con":true,"img":false}]}
{"op":"mcm","clk":"5353939012","pt":1646219987533,"mc":[{"id":"1.195503869","rc":[{"atl":[[900,0]],"id":41419621}],"con":true,"img":false}]}
{"op":"mcm","clk":"5353939049","pt":1646219987852,"mc":[{"id":"1.195503869","rc":[{"atb":[[9,47.2],[8.4,2.72]],"id":41419586},{"atl":[[170,8.02]],"id":41419603},{"atl":[[910,3.48]],"id":41419621},{"atl":[[980,1.38]],"id":41419596}],"con":true,"img":false}]}
{"op":"mcm","clk":"5353939079","pt":1646219988104,"mc":[{"id":"1.195503869","rc":[{"atl":[[630,4.15]],"id":41419616}],"con":true,"img":false}]}
{"op":"mcm","clk":"5353939084","pt":1646219988206,"mc":[{"id":"1.195503869","rc":[{"atl":[[32,10.06]],"id":41419606},{"atb":[[10,19.1]],"id":41419586}],"con":true,"img":false}]}
{"op":"mcm","clk":"5353939112","pt":1646219988522,"mc":[{"id":"1.195503869","rc":[{"atl":[[620,2],[1000,0]],"id":41419619},{"atl":[[210,8.5]],"id":41419592}],"con":true,"img":false}]}
{"op":"mcm","clk":"5353939148","pt":1646219988952,"mc":[{"id":"1.195503869","rc":[{"atb":[[9.8,4.95]],"id":41419586}],"con":true,"img":false}]}
{"op":"mcm","clk":"5353939163","pt":1646219989144,"mc":[{"id":"1.195503869","rc":[{"atl":[[34,0]],"id":41419606}],"con":true,"img":false}]}
{"op":"mcm","clk":"5353939200","pt":1646219989668,"mc":[{"id":"1.195503869","rc":[{"atl":[[40,9.9],[80,19.12]],"id":41419606},{"atl":[[260,0]],"id":41419619}],"con":true,"img":false}]}
{"op":"mcm","clk":"5353939216","pt":1646219989821,"mc":[{"id":"1.195503869","rc":[{"atl":[[620,4.2]],"id":41419619}],"con":true,"img":false}]}
{"op":"mcm","clk":"5353939624","pt":1646219995041,"mc":[{"id":"1.195503869","rc":[{"atl":[[24,0],[25,4.95],[28,51.87],[29,9.9]],"id":41419585},{"atl":[[170,0],[490,4.81]],"id":41419603},{"atl":[[980,0],[990,3.38]],"id":41419596}],"con":true,"img":false}]}
{"op":"mcm","clk":"5353939644","pt":1646219995354,"mc":[{"id":"1.195503869","rc":[{"atl":[[910,2],[900,1.53]],"id":41419621}],"con":true,"img":false}]}
{"op":"mcm","clk":"5353939685","pt":1646219995829,"mc":[{"id":"1.195503869","rc":[{"atl":[[490,2]],"id":41419603}],"con":true,"img":false}]}
{"op":"mcm","clk":"5353939743","pt":1646219996661,"mc":[{"id":"1.195503869","rc":[{"atl":[[130,4.95],[140,9.92],[720,2],[120,0]],"id":41419613},{"atl":[[260,0]],"id":41419593},{"atl":[[540,4.56],[890,0]],"id":41419622},{"atl":[[940,3.47],[990,0]],"id":41419602},{"atl":[[240,7.78]],"id":41419620},{"atb":[[16,9.34]],"id":41419592}],"con":true,"img":false}]}
{"op":"mcm","clk":"5353939759","pt":1646219996766,"mc":[{"id":"1.195503869","rc":[{"atl":[[270,4.95]],"id":41419593},{"atl":[[160,0]],"id":41419622},{"atb":[[16,2.72],[13.5,13.17],[14,26.14],[15.5,4.95]],"id":41419606},{"atl":[[1000,0]],"id":41419657},{"atb":[[5.8,39.49]],"id":41419591},{"atl":[[240,0],[250,4.95]],"id":41419616},{"atb":[[24,19.11]],"id":41419592},{"atl":[[150,0],[160,4.95]],"id":41419600}],"con":true,"img":false}]}
{"op":"mcm","clk":"5353939768","pt":1646219996815,"mc":[{"id":"1.195503869","rc":[{"atl":[[720,0],[410,2]],"id":41419613}],"con":true,"img":false}]}
{"op":"mcm","clk":"5353939776","pt":1646219996919,"mc":[{"id":"1.195503869","rc":[{"atb":[[40,9.02]],"id":41419605},{"atl":[[25,0],[29,0]],"id":41419585},{"atl":[[260,4.95],[250,0]],"id":41419619},{"atl":[[210,0]],"id":41419598},{"atl":[[210,0],[220,4.95],[230,6.03]],"id":41419594},{"atb":[[26,3.27],[28,0],[29,4.95],[30,0]],"id":41419612}],"con":true,"img":false}]}
{"op":"mcm","clk":"5353939790","pt":1646219997022,"mc":[{"id":"1.195503869","rc":[{"atl":[[990,1.55]],"id":41419619}],"con":true,"img":false}]}
{"op":"mcm","clk":"5353939794","pt":1646219997126,"mc":[{"id":"1.195503869","rc":[{"atl":[[26,11.29]],"id":41419585},{"atl":[[620,2]],"id":41419619}],"con":true,"img":false}]}
{"op":"mcm","clk":"5353939800","pt":1646219997230,"mc":[{"id":"1.195503869","rc":[{"atl":[[110,6.4]],"id":41419592},{"atl":[[160,5.95]],"id":41419600}],"con":true,"img":false}]}
{"op":"mcm","clk":"5353939807","pt":1646219997334,"mc":[{"id":"1.195503869","rc":[{"atl":[[130,6.18]],"id":41419613},{"atl":[[540,2]],"id":41419622},{"atl":[[28,3.7],[29,34.29]],"id":41419585},{"atl":[[260,5.56]],"id":41419619},{"atl":[[800,2],[240,5.79]],"id":41419598},{"atb":[[26,20.9]],"id":41419612}],"con":true,"img":false}]}
{"op":"mcm","clk":"5353939812","pt":1646219997437,"mc":[{"id":"1.195503869","rc":[{"atl":[[510,0.31]],"id":41419593},{"atb":[[14,0],[14.5,41.44]],"id":41419606},{"atl":[[620,0],[980,2]],"id":41419619},{"atl":[[800,0],[410,2]],"id":41419598}],"con":true,"img":false}]}
{"op":"mcm","clk":"5353939820","pt":1646219997543,"mc":[{"id":"1.195503869","rc":[{"atl":[[270,0],[280,4.95]],"id":41419593},{"atl":[[180,5.84]],"id":41419622},{"atb":[[5.6,0]],"id":41419591},{"atl":[[260,4.95],[610,0.26],[250,0]],"id":41419616}],"con":true,"img":false}]}
{"op":"mcm","clk":"5353939832","pt":1646219997645,"mc":[{"id":"1.195503869","rc":[{"atl":[[530,4.62],[910,0]],"id":41419593},{"atb":[[15.5,15.88]],"id":41419606}],"con":true,"img":false}]}
{"op":"mcm","clk":"5353939843","pt":1646219997749,"mc":[{"id":"1.195503869","rc":[{"atb":[[34,2.72]],"id":41419605},{"atl":[[28,0],[29,37.86]],"id":41419585},{"atl":[[220,5.67]],"id":41419598},{"atl":[[220,5.67]],"id":41419594},{"atb":[[25,9.9]],"id":41419612}],"con":true,"img":false}]}
{"op":"mcm","clk":"5353939854","pt":1646219997962,"mc":[{"id":"1.195503869","rc":[{"atl":[[130,0]],"id":41419592}],"con":true,"img":false}]}
{"op":"mcm","clk":"5353939867","pt":1646219998166,"mc":[{"id":"1.195503869","rc":[{"atl":[[990,1.39]],"id":41419619},{"atl":[[390,0]],"id":41419600}],"con":true,"img":false}]}
{"op":"mcm","clk":"5353939874","pt":1646219998270,"mc":[{"id":"1.195503869","rc":[{"atb":[[1.01,0]],"id":41419606}],"con":true,"img":false}]}
{"op":"mcm","clk":"5353939884","pt":1646219998375,"mc":[{"id":"1.195503869","rc":[{"atl":[[520,0]],"id":41419593},{"atb":[[16,4.29],[14.5,29.69]],"id":41419606},{"atb":[[3.45,133.86],[4.9,23.9]],"id":41419591},{"atl":[[620,2.24],[630,2]],"id":41419616}],"con":true,"img":false}]}
{"op":"mcm","clk":"5353939894","pt":1646219998429,"mc":[{"id":"1.195503869","rc":[{"atl":[[130,10.72],[210,2]],"id":41419592}],"con":true,"img":false}]}
{"op":"mcm","clk":"5353939911","pt":1646219998637,"mc":[{"id":"1.195503869","rc":[{"atl":[[180,7.74],[400,2]],"id":41419600}],"con":true,"img":false}]}
{"op":"mcm","clk":"5353940124","pt":1646220001507,"mc":[{"id":"1.195503869","rc":[{"atb":[[70,2.29],[75,4.95],[50,2.72],[55,9.9]],"id":41419638},{"atl":[[85,4.95],[90,1.78],[110,9.9],[120,0]],"id":41419605},{"atb":[[10,0],[11.5,25.39],[12,0],[13.5,4.95]],"id":41419634},{"atb":[[150,1.06],[160,4.95],[110,14.54],[120,11.08]],"id":41419617},{"atb":[[32,0],[40,0],[42,9.9],[50,4.95]],"id":41419613},{"atb":[[65,0],[75,9.9],[85,4.61],[95,4.95]],"id":41419593},{"atb":[[65,0],[80,9.9],[85,1.88],[100,4.95]],"id":41419622},{"atb":[[34,14.08],[50,4.95]],"id":28546943},{"atb":[[34,0],[38,4.95],[28,0],[30,27.89]],"id":41419639},{"atl":[[32,5.11],[38,9.9],[40,0],[30,4.95]],"id":41419606},{"atl":[[140,9.9],[100,4.95],[120,0]],"id":41419635},{"atb":[[85,0],[90,9.9],[110,1.45],[120,4.95]],"id":41419602},{"atb":[[8,0],[9,4.95],[8.2,9.9],[8.8,16.78]],"id":41419585},{"atb":[[65,4.95],[46,14.71],[48,9.9],[60,2.68]],"id":41419623},{"atb":[[9,37.29],[10,24.06],[9.2,9.9],[9.8,0]],"id":41419586},{"atl":[[140,9.9],[100,4.95],[120,0]],"id":41419607},{"atb":[[140,4.95],[85,0],[100,9.9],[110,1.45]],"id":28546950},{"atb":[[70,2.29],[75,4.95],[50,0],[55,9.9]],"id":41419603},{"atb":[[130,1.23],[140,4.95],[95,0],[100,9.9]],"id":41419615},{"atb":[[140,6.09],[100,9.9]],"id":41419624},{"atl":[[9.8,4.95],[13.5,29.45]],"id":41419591},{"atb":[[32,4.95],[24,0],[27,9.9],[28,0]],"id":41419620},{"atb":[[18,22.08],[24,4.95]],"id":41419599},{"atb":[[140,4.97],[150,6.01],[100,0],[110,12.48]],"id":41419595},{"atl":[[65,9.9],[70,0],[48,4.95],[50,0]],"id":41419637},{"atl":[[70,2.29],[80,9.9],[90,0],[60,4.95]],"id":41419612},{"atb":[[19.5,0],[27,4.95]],"id":41419592},{"atb":[[17,0],[17.5,9.9],[19,8.8],[19.5,4.95]],"id":41419588},{"atb":[[85,9.63],[90,9.9],[110,2.72],[120,7.46]],"id":41419596}],"con":true,"img":false}]}
{"op":"mcm","clk":"5353940128","pt":1646220001556,"mc":[{"id":"1.195503869","rc":[{"atb":[[130,0],[95,2.72]],"id":41419624},{"atl":[[12.5,13.78],[14.5,0]],"id":41419587}],"con":true,"img":false}]}
{"op":"mcm","clk":"5353940134","pt":1646220001660,"mc":[{"id":"1.195503869","rc":[{"atl":[[9.6,25.9],[990,0]],"id":41419591},{"atl":[[260,4.91],[200,2]],"id":41419612}],"con":true,"img":false}]}
{"op":"mcm","clk":"5353940145","pt":1646220001765,"mc":[{"id":"1.195503869","rc":[{"atl":[[11,4.95],[13,9.9]],"id":41419587},{"atb":[[75,9.9],[95,7.67]],"id":41419621}],"con":true,"img":false}]}
{"op":"mcm","clk":"5353940168","pt":1646220001982,"mc":[{"id":"1.195503869","rc":[{"atb":[[40,3.27],[80,2],[55,20.68]],"id":41419638},{"atl":[[80,2],[340,2],[110,22.67]],"id":41419605},{"atb":[[170,0.93],[110,2.72],[120,20.01]],"id":41419617},{"atb":[[36,3.27],[42,28.4],[55,2.93]],"id":41419613},{"atb":[[75,24.13],[100,1.6],[60,3.27]],"id":41419593},{"atb":[[80,24.62],[100,6.55],[60,2.72]],"id":41419622},{"atb":[[34,0],[42,17.79],[55,2.93]],"id":28546943},{"atl":[[38,32.23],[80,2],[29,5.64]],"id":41419606},{"atl":[[140,19.94],[100,6.55],[230,2]],"id":41419635},{"atb":[[130,1.23],[70,0],[90,22.42]],"id":41419602},{"atb":[[9,38.54],[8.8,0]],"id":41419585},{"atb":[[70,2.29],[46,0],[55,10.78]],"id":41419623},{"atl":[[140,19.94],[320,2],[100,6.55]],"id":41419607},{"atb":[[75,0],[150,1.06],[100,19.43]],"id":28546950},{"atb":[[80,2],[48,2.72],[55,24.62]],"id":41419603},{"atb":[[150,1.06],[90,0],[100,19.09]],"id":41419615},{"atl":[[9.6,51.13],[11.5,80.65],[13.5,0]],"id":41419591},{"atb":[[34,4.8],[25,3.27],[27,33.66]],"id":41419620},{"atb":[[18.5,24.81],[18,0],[25,6.6]],"id":41419599},{"atl":[[260,0],[80,24.62]],"id":41419612},{"atb":[[16.5,2.72],[17.5,39.14],[20,8.34]],"id":41419588},{"atb":[[85,0],[90,19.98]],"id":41419596}],"con":true,"img":false}]}
{"op":"mcm","clk":"5353940176","pt":1646220002081,"mc":[{"id":"1.195503869","rc":[{"atl":[[120,4.95]],"id":41419610},{"atl":[[13.5,65.66]],"id":41419587},{"atb":[[65,0],[85,8.11]],"id":41419621}],"con":true,"img":false}]}
{"op":"mcm","clk":"5353940186","pt":1646220002185,"mc":[{"id":"1.195503869","rc":[{"atl":[[130,1.23]],"id":41419610},{"atb":[[100,23.95],[110,1.28]],"id":41419624},{"atb":[[7.6,28.23]],"id":41419587},{"atl":[[27,3.85]],"id":41419587}],"con":true,"img":false}]}
{"op":"mcm","clk":"5353940192","pt":1646220002236,"mc":[{"id":"1.195503869","rc":[{"atl":[[430,2]],"id":41419610},{"atl":[[16,4.95],[18,9.9]],"id":41419586},{"atl":[[10.5,16.68]],"id":41419587}],"con":true,"img":false}]}
{"op":"mcm","clk":"5353940200","pt":1646220002342,"mc":[{"id":"1.195503869","rc":[{"atl":[[820,0]],"id":41419610},{"atl":[[16.5,10.22],[18.5,0]],"id":41419586}],"con":true,"img":false}]}
{"op":"mcm","clk":"5353940216","pt":1646220002548,"mc":[{"id":"1.195503869","rc":[{"atl":[[820,1.7],[110,1.45]],"id":41419610},{"atl":[[170,6.83]],"id":41419603},{"atl":[[900,0],[910,3.53]],"id":41419621},{"atl":[[990,2],[980,1.42]],"id":41419596}],"con":true,"img":false}]}
{"op":"mcm","clk":"5353940228","pt":1646220002653,"mc":[{"id":"1.195503869","rc":[{"atb":[[85,0]],"id":41419622},{"atl":[[32,0]],"id":41419606},{"atl":[[110,0]],"id":41419635},{"atb":[[110,0]],"id":41419602},{"atl":[[850,0]],"id":41419610},{"atl":[[18,47.2],[15.5,10.93]],"id":41419586},{"atb":[[70,0]],"id":41419603},{"atl":[[11,0]],"id":41419591},{"atb":[[19,0]],"id":41419588}],"con":true,"img":false}]}
{"op":"mcm","clk":"5353940237","pt":1646220002758,"mc":[{"id":"1.195503869","rc":[{"atb":[[70,0]],"id":41419638},{"atl":[[90,0],[110,9.9]],"id":41419605},{"atb":[[150,0]],"id":41419617},{"atb":[[46,2.72]],"id":41419613},{"atb":[[85,2.72]],"id":41419593},{"atb":[[44,0]],"id":28546943},{"atl":[[38,9.9]],"id":41419606},{"atb":[[60,0]],"id":41419623},{"atl":[[40,2.56]],"id":41419586},{"atb":[[110,0]],"id":28546950},{"atb":[[130,0]],"id":41419615},{"atb":[[30,2.72]],"id":41419620},{"atb":[[20,4.95]],"id":41419599}],"con":true,"img":false}]}
{"op":"mcm","clk":"5353940247","pt":1646220002863,"mc":[{"id":"1.195503869","rc":[{"atb":[[7.2,0]],"id":41419587},{"atb":[[20,9.86]],"id":41419588}],"con":true,"img":false}]}
{"op":"mcm","clk":"5353940262","pt":1646220003076,"mc":[{"id":"1.195503869","rc":[{"atl":[[110,0]],"id":41419607},{"atl":[[12.5,0]],"id":41419587}],"con":true,"img":false}]}
{"op":"mcm","clk":"5353940279","pt":1646220003232,"mc":[{"id":"1.195503869","rc":[{"atl":[[910,2]],"id":41419621}],"con":true,"img":false}]}
{"op":"mcm","clk":"5353940289","pt":1646220003338,"mc":[{"id":"1.195503869","rc":[{"atl":[[130,0]],"id":41419610},{"atb":[[7,4.95],[6.6,48.57]],"id":41419587},{"atb":[[20,8.34]],"id":41419588}],"con":true,"img":false}]}
{"op":"mcm","clk":"5353940298","pt":1646220003444,"mc":[{"id":"1.195503869","rc":[{"atb":[[1.01,1.52]],"id":41419588}],"con":true,"img":false}]}
{"op":"mcm","clk":"5353940315","pt":1646220003652,"mc":[{"id":"1.195503869","rc":[{"atl":[[16.5,0]],"id":41419586}],"con":true,"img":false}]}
{"op":"mcm","clk":"5353940341","pt":1646220003963,"mc":[{"id":"1.195503869","rc":[{"atl":[[140,0],[410,5.43]],"id":41419613}],"con":true,"img":false}]}
{"op":"mcm","clk":"5353940378","pt":1646220004377,"mc":[{"id":"1.195503869","rc":[{"atl":[[38,33.03]],"id":41419606},{"atl":[[440,5.19],[230,0]],"id":41419594}],"con":true,"img":false}]}
{"op":"mcm","clk":"5353940405","pt":1646220004742,"mc":[{"id":"1.195503869","rc":[{"atl":[[410,5.43],[240,0]],"id":41419598}],"con":true,"img":false}]}
{"op":"mcm","clk":"5353940462","pt":1646220005575,"mc":[{"id":"1.195503869","rc":[{"atl":[[410,2]],"id":41419598}],"con":true,"img":false}]}
{"op":"mcm","clk":"5353940486","pt":1646220005783,"mc":[{"id":"1.195503869","rc":[{"atl":[[130,0],[210,8.73]],"id":41419592},{"atl":[[400,5.53]],"id":41419600}],"con":true,"img":false}]}
{"op":"mcm","clk":"5353940491","pt":1646220005835,"mc":[{"id":"1.195503869","rc":[{"atl":[[180,0]],"id":41419600}],"con":true,"img":false}]}
{"op":"mcm","clk":"5353940551","pt":1646220006574,"mc":[{"id":"1.195503869","rc":[{"atl":[[400,2]],"id":41419600}],"con":true,"img":false}]}
{"op":"mcm","clk":"5353940776","pt":1646220009078,"mc":[{"id":"1.195503869","rc":[{"atb":[[80,9.9]],"id":41419622}],"con":true,"img":false}]}
{"op":"mcm","clk":"5353940801","pt":1646220009389,"mc":[{"id":"1.195503869","rc":[{"atb":[[60,20.08]],"id":41419622},{"atl":[[140,9.9],[320,6.44]],"id":41419607}],"con":true,"img":false}]}
{"op":"mcm","clk":"5353940807","pt":1646220009441,"mc":[{"id":"1.195503869","rc":[{"atl":[[140,9.9],[230,8.19]],"id":41419635}],"con":true,"img":false}]}
{"op":"mcm","clk":"5353940824","pt":1646220009754,"mc":[{"id":"1.195503869","rc":[{"atl":[[170,0],[490,4.9]],"id":41419603},{"atl":[[980,0],[990,3.43]],"id":41419596}],"con":true,"img":false}]}
{"op":"mcm","clk":"5353940848","pt":1646220009966,"mc":[{"id":"1.195503869","rc":[{"atl":[[25,4.95],[29,47.77]],"id":41419585},{"atl":[[260,0.61],[250,4.95]],"id":41419619},{"atl":[[900,1.57]],"id":41419621},{"atl":[[160,0],[170,4.95]],"id":41419600}],"con":true,"img":false}]}
{"op":"mcm","clk":"5353940858","pt":1646220010069,"mc":[{"id":"1.195503869","rc":[{"atl":[[26,6.34],[28,3.7]],"id":41419585},{"atl":[[620,2],[980,0]],"id":41419619},{"atl":[[210,4.95],[220,0.72]],"id":41419598},{"atl":[[210,4.95],[220,0.72]],"id":41419594},{"atl":[[260,0]],"id":41419616}],"con":true,"img":false}]}
{"op":"mcm","clk":"5353940866","pt":1646220010172,"mc":[{"id":"1.195503869","rc":[{"atl":[[29,44.2]],"id":41419585},{"atl":[[250,4.95]],"id":41419616}],"con":true,"img":false}]}
{"op":"mcm","clk":"5353940874","pt":1646220010276,"mc":[{"id":"1.195503869","rc":[{"atl":[[280,0]],"id":41419593},{"atl":[[130,6.18],[140,0]],"id":41419626},{"atl":[[630,0],[660,2]],"id":41419616}],"con":true,"img":false}]}
{"op":"mcm","clk":"5353940890","pt":1646220010484,"mc":[{"id":"1.195503869","rc":[{"atl":[[25,11.55]],"id":41419585},{"atl":[[990,0],[980,1.44]],"id":41419619}],"con":true,"img":false}]}
{"op":"mcm","clk":"5353940908","pt":1646220010641,"mc":[{"id":"1.195503869","rc":[{"atl":[[490,2]],"id":41419603},{"atl":[[620,0],[630,2.26]],"id":41419616}],"con":true,"img":false}]}
{"op":"mcm","clk":"5353940914","pt":1646220010747,"mc":[{"id":"1.195503869","rc":[{"atl":[[150,0],[450,5.17]],"id":41419626},{"atl":[[25,6.6],[26,11.29],[29,34.29]],"id":41419585},{"atl":[[260,5.56],[250,0]],"id":41419619},{"atl":[[210,0],[220,5.67]],"id":41419598},{"atl":[[210,0],[220,5.67]],"id":41419594},{"atl":[[390,0.4]],"id":41419600}],"con":true,"img":false}]}
{"op":"mcm","clk":"5353940935","pt":1646220010956,"mc":[{"id":"1.195503869","rc":[{"atl":[[280,4.95]],"id":41419593},{"atl":[[160,4.95],[170,0]],"id":41419600}],"con":true,"img":false}]}
{"op":"mcm","clk":"5353940959","pt":1646220011167,"mc":[{"id":"1.195503869","rc":[{"atb":[[70,9.9],[90,4.95],[95,4.95]],"id":41419609}],"con":true,"img":false}]}
{"op":"mcm","clk":"5353940967","pt":1646220011274,"mc":[{"id":"1.195503869","rc":[{"atb":[[75,0],[95,0]],"id":41419609}],"con":true,"img":false}]}
{"op":"mcm","clk":"5353940978","pt":1646220011374,"mc":[{"id":"1.195503869","rc":[{"atl":[[150,9.53],[410,2]],"id":41419613},{"atl":[[200,7.15]],"id":41419622},{"atl":[[25,0],[26,4.95]],"id":41419585},{"atb":[[24,6.89],[27,19.66]],"id":41419592}],"con":true,"img":false}]}
{"op":"mcm","clk":"5353941012","pt":1646220011687,"mc":[{"id":"1.195503869","rc":[{"atb":[[65,0],[75,14.71]],"id":41419609},{"atl":[[440,2],[240,5.96]],"id":41419594}],"con":true,"img":false}]}
{"op":"mcm","clk":"5353941035","pt":1646220011895,"mc":[{"id":"1.195503869","rc":[{"atl":[[280,0]],"id":41419593},{"atl":[[130,1.23],[140,4.95]],"id":41419626},{"atl":[[610,0.26]],"id":41419619},{"atl":[[240,5.96]],"id":41419598},{"atl":[[160,0.99],[170,4.95]],"id":41419600}],"con":true,"img":false}]}
{"op":"mcm","clk":"5353941046","pt":1646220011948,"mc":[{"id":"1.195503869","rc":[{"atb":[[75,16.85]],"id":41419609}],"con":true,"img":false}]}
{"op":"mcm","clk":"5353941055","pt":1646220012052,"mc":[{"id":"1.195503869","rc":[{"atl":[[280,0.56]],"id":41419593}],"con":true,"img":false}]}
{"op":"mcm","clk":"5353941064","pt":1646220012157,"mc":[{"id":"1.195503869","rc":[{"atl":[[27,6.09]],"id":41419585},{"atl":[[250,5.59]],"id":41419616}],"con":true,"img":false}]}
{"op":"mcm","clk":"5353941090","pt":1646220012368,"mc":[{"id":"1.195503869","rc":[{"atb":[[75,2.14]],"id":41419609},{"atl":[[620,4.3],[980,0]],"id":41419619},{"atl":[[400,0.39]],"id":41419598}],"con":true,"img":false}]}
{"op":"mcm","clk":"5353941125","pt":1646220012683,"mc":[{"id":"1.195503869","rc":[{"atl":[[280,5.52]],"id":41419593},{"atl":[[28,20.12],[29,0]],"id":41419585},{"atl":[[170,0],[390,0]],"id":41419600}],"con":true,"img":false}]}
{"op":"mcm","clk":"5353941136","pt":1646220012784,"mc":[{"id":"1.195503869","rc":[{"atl":[[610,0]],"id":41419619}],"con":true,"img":false}]}
{"op":"mcm","clk":"5353941153","pt":1646220013096,"mc":[{"id":"1.195503869","rc":[{"atl":[[510,0]],"id":41419593},{"atl":[[610,0]],"id":41419616},{"atl":[[130,11.04]],"id":41419592}],"con":true,"img":false}]}
{"op":"mcm","clk":"5353941160","pt":1646220013149,"mc":[{"id":"1.195503869","rc":[{"atl":[[400,0]],"id":41419598},{"atl":[[210,2]],"id":41419592}],"con":true,"img":false}]}
{"op":"mcm","clk":"5353941180","pt":1646220013358,"mc":[{"id":"1.195503869","rc":[{"atl":[[160,5.95],[180,7.97]],"id":41419600}],"con":true,"img":false}]}
{"op":"mcm","clk":"5353941200","pt":1646220013670,"mc":[{"id":"1.195503869","rc":[{"atl":[[530,2],[300,4.78]],"id":41419593}],"con":true,"img":false}]}
{"op":"mcm","clk":"5353941232","pt":1646220014087,"mc":[{"id":"1.195503869","rc":[{"atl":[[130,0]],"id":41419592}],"con":true,"img":false}]}
{"op":"mcm","clk":"5353941256","pt":1646220014348,"mc":[{"id":"1.195503869","rc":[{"atl":[[300,0]],"id":41419593}],"con":true,"img":false}]}
{"op":"mcm","clk":"5353941350","pt":1646220015388,"mc":[{"id":"1.195503869","rc":[{"atl":[[9.6,25.23]],"id":41419591}],"con":true,"img":false}]}
{"op":"mcm","clk":"5353941357","pt":1646220015492,"mc":[{"id":"1.195503869","rc":[{"atl":[[990,2.09]],"id":41419591}],"con":true,"img":false}]}
{"op":"mcm","clk":"5353941376","pt":1646220015650,"mc":[{"id":"1.195503869","rc":[{"atl":[[60,7.64]],"id":41419612}],"con":true,"img":false}]}
{"op":"mcm","clk":"5353941455","pt":1646220016380,"mc":[{"id":"1.195503869","rc":[{"atl":[[70,0]],"id":41419612}],"con":true,"img":false}]}
{"op":"mcm","clk":"5353941465","pt":1646220016488,"mc":[{"id":"1.195503869","rc":[{"atl":[[110,23.05]],"id":41419605},{"atb":[[42,9.9],[46,14.45]],"id":41419613},{"atb":[[75,9.9]],"id":41419593},{"atb":[[27,9.9],[30,20.85]],"id":41419620},{"atb":[[18.5,2.72],[20,22.13]],"id":41419599}],"con":true,"img":false}]}
{"op":"mcm","clk":"5353941488","pt":1646220016695,"mc":[{"id":"1.195503869","rc":[{"atb":[[85,10.84]],"id":41419593},{"atl":[[13,49.44]],"id":41419587}],"con":true,"img":false}]}
{"op":"mcm","clk":"5353941497","pt":1646220016747,"mc":[{"id":"1.195503869","rc":[{"atl":[[13.5,0]],"id":41419587}],"con":true,"img":false}]}
{"op":"mcm","clk":"5353941521","pt":1646220016957,"mc":[{"id":"1.195503869","rc":[{"atl":[[820,0],[430,5.35]],"id":41419610},{"atl":[[170,8.51]],"id":41419603},{"atl":[[80,9.9],[200,9.22]],"id":41419612},{"atl":[[910,3.58]],"id":41419621},{"atl":[[980,1.46]],"id":41419596}],"con":true,"img":false}]}
{"op":"mcm","clk":"5353941532","pt":1646220017061,"mc":[{"id":"1.195503869","rc":[{"atl":[[900,0]],"id":41419621},{"atl":[[990,2]],"id":41419596}],"con":true,"img":false}]}
{"op":"mcm","clk":"5353941590","pt":1646220017794,"mc":[{"id":"1.195503869","rc":[{"atl":[[980,0]],"id":41419596}],"con":true,"img":false}]}
{"op":"mcm","clk":"5353941605","pt":1646220017951,"mc":[{"id":"1.195503869","rc":[{"atl":[[630,0],[660,4.18]],"id":41419616}],"con":true,"img":false}]}
{"op":"mcm","clk":"5353941613","pt":1646220018054,"mc":[{"id":"1.195503869","rc":[{"atl":[[910,2]],"id":41419621}],"con":true,"img":false}]}
{"op":"mcm","clk":"5353941656","pt":1646220018680,"mc":[{"id":"1.195503869","rc":[{"atl":[[150,0],[410,5.53]],"id":41419613},{"atl":[[540,4.68],[200,0]],"id":41419622},{"atl":[[440,5.29],[240,0]],"id":41419594}],"con":true,"img":false}]}
{"op":"mcm","clk":"5353941691","pt":1646220019096,"mc":[{"id":"1.195503869","rc":[{"atl":[[410,5.53],[240,0]],"id":41419598}],"con":true,"img":false}]}
{"op":"mcm","clk":"5353941720","pt":1646220019409,"mc":[{"id":"1.195503869","rc":[{"atl":[[540,2]],"id":41419622}],"con":true,"img":false}]}
{"op":"mcm","clk":"5353941769","pt":1646220019887,"mc":[{"id":"1.195503869","rc":[{"atl":[[160,0.99]],"id":41419600}],"con":true,"img":false}]}
{"op":"mcm","clk":"5353941798","pt":1646220020203,"mc":[{"id":"1.195503869","rc":[{"atl":[[130,1.23],[120,4.95]],"id":41419613},{"atl":[[280,0],[290,4.95]],"id":41419593},{"atl":[[130,9.72]],"id":41419592},{"atl":[[160,0],[170,4.95]],"id":41419600}],"con":true,"img":false}]}
{"op":"mcm","clk":"5353941821","pt":1646220020507,"mc":[{"id":"1.195503869","rc":[{"atl":[[180,0],[400,5.63]],"id":41419600}],"con":true,"img":false}]}
{"op":"mcm","clk":"5353941853","pt":1646220020767,"mc":[{"id":"1.195503869","rc":[{"atl":[[120,6.28]],"id":41419613}],"con":true,"img":false}]}
{"op":"mcm","clk":"5353941890","pt":1646220021207,"mc":[{"id":"1.195503869","rc":[{"atl":[[520,0.3]],"id":41419593},{"atl":[[170,5.89]],"id":41419600}],"con":true,"img":false}]}
{"op":"mcm","clk":"5353941921","pt":1646220021578,"mc":[{"id":"1.195503869","rc":[{"atl":[[130,0]],"id":41419613}],"con":true,"img":false}]}
{"op":"mcm","clk":"5353942107","pt":1646220023971,"mc":[{"id":"1.195503869","rc":[{"atl":[[170,0]],"id":41419603}],"con":true,"img":false}]}
{"op":"mcm","clk":"5353942135","pt":1646220024286,"mc":[{"id":"1.195503869","rc":[{"atl":[[490,4.98]],"id":41419603},{"atl":[[900,1.62]],"id":41419621},{"atl":[[980,1.48]],"id":41419596}],"con":true,"img":false}]}
{"op":"mcm","clk":"5353942169","pt":1646220024807,"mc":[{"id":"1.195503869","rc":[{"atl":[[620,2]],"id":41419619}],"con":true,"img":false}]}
{"op":"mcm","clk":"5353942197","pt":1646220025119,"mc":[{"id":"1.195503869","rc":[{"atl":[[26,11.29]],"id":41419585},{"atl":[[280,5.24]],"id":41419619},{"atl":[[270,5.43],[660,2]],"id":41419616}],"con":true,"img":false}]}
{"op":"mcm","clk":"5353942221","pt":1646220025376,"mc":[{"id":"1.195503869","rc":[{"atb":[[65,9.9],[70,0],[85,4.95],[90,0]],"id":41419609}],"con":true,"img":false}]}
{"op":"mcm","clk":"5353942255","pt":1646220025798,"mc":[{"id":"1.195503869","rc":[{"atl":[[140,10.51],[410,2]],"id":41419613},{"atl":[[200,7.35]],"id":41419622}],"con":true,"img":false}]}
{"op":"mcm","clk":"5353942286","pt":1646220026114,"mc":[{"id":"1.195503869","rc":[{"atb":[[65,20.44]],"id":41419609},{"atl":[[27,0]],"id":41419585},{"atl":[[440,2],[240,6.13]],"id":41419594}],"con":true,"img":false}]}
{"op":"mcm","clk":"5353942318","pt":1646220026469,"mc":[{"id":"1.195503869","rc":[{"atl":[[290,5.5]],"id":41419593},{"atl":[[410,2],[240,6.13]],"id":41419598}],"con":true,"img":false}]}
{"op":"mcm","clk":"5353942342","pt":1646220026783,"mc":[{"id":"1.195503869","rc":[{"atb":[[85,6.83]],"id":41419609}],"con":true,"img":false}]}
{"op":"mcm","clk":"5353942374","pt":1646220027201,"mc":[{"id":"1.195503869","rc":[{"atl":[[130,0],[210,9.02]],"id":41419592}],"con":true,"img":false}]}
{"op":"mcm","clk":"5353942406","pt":1646220027634,"mc":[{"id":"1.195503869","rc":[{"atb":[[75,0]],"id":41419609},{"atl":[[520,0]],"id":41419593},{"atl":[[240,0]],"id":41419598}],"con":true,"img":false}]}
{"op":"mcm","clk":"5353942434","pt":1646220027884,"mc":[{"id":"1.195503869","rc":[{"atl":[[190,7.77],[400,2]],"id":41419600}],"con":true,"img":false}]}
{"op":"mcm","clk":"5353942460","pt":1646220028198,"mc":[{"id":"1.195503869","rc":[{"atl":[[530,4.77]],"id":41419593}],"con":true,"img":false}]}
{"op":"mcm","clk":"5353942496","pt":1646220028617,"mc":[{"id":"1.195503869","rc":[{"atl":[[190,0]],"id":41419600}],"con":true,"img":false}]}
{"op":"mcm","clk":"5353942647","pt":1646220030402,"mc":[{"id":"1.195503869","rc":[{"atb":[[40,9.9],[42,12.84],[48,4.95],[50,0],[55,0]],"id":28546943},{"atb":[[16,14.85],[17.5,4.95],[13.5,3.27]],"id":41419606},{"atb":[[130,0]],"id":41419602},{"atl":[[140,0],[150,9.9],[100,0],[110,4.95]],"id":41419607},{"atl":[[1000,0.15]],"id":41419657},{"atb":[[25,0]],"id":41419599},{"atb":[[38,4.28],[30,0]],"id":41419608},{"atb":[[32,7.83],[25,0],[26,30.8],[29,0],[30,4.95]],"id":41419612},{"atl":[[90,4.95],[110,1.45],[120,9.9]],"id":41419592}],"con":true,"img":false}]}
{"op":"mcm","clk":"5353942655","pt":1646220030494,"mc":[{"id":"1.195503869","rc":[{"atb":[[65,10.54],[75,9.9],[85,1.88],[95,4.95]],"id":41419609},{"atb":[[34,37.74],[42,4.95]],"id":41419608}],"con":true,"img":false}]}
{"op":"mcm","clk":"5353942681","pt":1646220030808,"mc":[{"id":"1.195503869","rc":[{"atb":[[40,26.79],[42,0]],"id":28546943},{"atb":[[14.5,0],[15.5,46.37]],"id":41419606},{"atb":[[65,15.23],[90,9.9]],"id":41419602},{"atb":[[18.5,24.81],[20,4.95]],"id":41419599},{"atl":[[90,6.73]],"id":41419592}],"con":true,"img":false}]}
{"op":"mcm","clk":"5353942708","pt":1646220031127,"mc":[{"id":"1.195503869","rc":[{"atl":[[23,4.95],[24,0],[27,9.9],[28,26.51]],"id":41419634},{"atb":[[44,3.68]],"id":28546943},{"atb":[[15.5,35.44]],"id":41419606},{"atb":[[120,6.28]],"id":41419602},{"atl":[[110,6.4]],"id":41419607},{"atb":[[20,13.29]],"id":41419599},{"atb":[[34,9.9],[36,18.48],[44,3.68]],"id":41419608}],"con":true,"img":false}]}
{"op":"mcm","clk":"5353942731","pt":1646220031435,"mc":[{"id":"1.195503869","rc":[{"atl":[[170,8.74],[490,2]],"id":41419603},{"atl":[[900,0],[910,3.62]],"id":41419621},{"atl":[[980,0],[990,3.49]],"id":41419596}],"con":true,"img":false}]}
{"op":"mcm","clk":"5353942766","pt":1646220031706,"mc":[{"id":"1.195503869","rc":[{"atl":[[27,36.42],[28,0]],"id":41419634},{"atl":[[110,0]],"id":41419592}],"con":true,"img":false}]}
{"op":"mcm","clk":"5353942805","pt":1646220032121,"mc":[{"id":"1.195503869","rc":[{"atl":[[280,0],[620,4.39]],"id":41419619},{"atb":[[38,0]],"id":41419608},{"atl":[[270,0],[660,4.25]],"id":41419616}],"con":true,"img":false}]}
{"op":"mcm","clk":"5353942841","pt":1646220032489,"mc":[{"id":"1.195503869","rc":[{"atl":[[910,2]],"id":41419621}],"con":true,"img":false}]}
{"op":"mcm","clk":"5353942865","pt":1646220032701,"mc":[{"id":"1.195503869","rc":[{"atl":[[140,0],[410,5.62]],"id":41419613},{"atl":[[540,4.75],[200,0]],"id":41419622}],"con":true,"img":false}]}
{"op":"mcm","clk":"5353942907","pt":1646220033119,"mc":[{"id":"1.195503869","rc":[{"atl":[[440,5.38],[240,0]],"id":41419594},{"atl":[[660,2]],"id":41419616}],"con":true,"img":false}]}
{"op":"mcm","clk":"5353942935","pt":1646220033431,"mc":[{"id":"1.195503869","rc":[{"atl":[[540,2]],"id":41419622},{"atl":[[240,6.21]],"id":41419598}],"con":true,"img":false}]}
{"op":"mcm","clk":"5353942980","pt":1646220033912,"mc":[{"id":"1.195503869","rc":[{"atl":[[440,2]],"id":41419594}],"con":true,"img":false}]}
{"op":"mcm","clk":"5353943034","pt":1646220034639,"mc":[{"id":"1.195503869","rc":[{"atl":[[190,7.87]],"id":41419600}],"con":true,"img":false}]}
{"op":"mcm","clk":"5353943129","pt":1646220035839,"mc":[{"id":"1.195503869","rc":[{"atb":[[32,0],[44,2.33]],"id":41419593},{"atl":[[540,0],[760,2]],"id":41419622},{"atl":[[330,3.86],[400,2]],"id":41419639},{"atl":[[940,1.47]],"id":41419602},{"atb":[[46,2.22],[27,0]],"id":41419603},{"atl":[[610,2],[490,0]],"id":41419603},{"atl":[[310,2],[240,5.78]],"id":41419620},{"atb":[[17,6.25],[14.5,0]],"id":41419608},{"atb":[[19,0],[23,4.55]],"id":41419600}],"con":true,"img":false}]}
{"op":"mcm","clk":"5353943146","pt":1646220036001,"mc":[{"id":"1.195503869","rc":[{"atl":[[170,4.95],[180,0.88]],"id":41419609},{"atb":[[44,0],[55,5.66]],"id":41419626},{"atb":[[9,33.59],[8.6,4.95],[8.2,0]],"id":41419585},{"atl":[[150,1.06]],"id":41419603},{"atb":[[6.2,0],[7,0]],"id":41419587},{"atl":[[90,1.78],[120,0]],"id":41419608},{"atb":[[120,1.32]],"id":41419621},{"atb":[[65,5.2],[44,0],[55,0]],"id":41419600}],"con":true,"img":false}]}
{"op":"mcm","clk":"5353943156","pt":1646220036109,"mc":[{"id":"1.195503869","rc":[{"atl":[[540,2],[920,0]],"id":41419609},{"atb":[[32,23.29],[38,9.9],[40,4.06],[46,4.95]],"id":41419605},{"atl":[[130,9.9],[85,0],[95,4.95],[110,13.14]],"id":41419605},{"atl":[[180,0.88],[230,4.95]],"id":41419622},{"atb":[[10,22.08],[11,9.9],[12,14.41],[13,4.95]],"id":41419589},{"atl":[[20,8.34],[22,4.95],[24,0],[26,9.9]],"id":41419589},{"atb":[[32,18.13],[36,12.63],[40,4.06],[44,4.95]],"id":41419601},{"atb":[[65,4.95],[48,9.9]],"id":41419626},{"atl":[[150,9.9],[90,1.78],[110,4.95],[120,0]],"id":41419639},{"atl":[[260,0],[270,4.95]],"id":41419602},{"atb":[[9,0],[11,14],[9.4,0]],"id":41419585},{"atb":[[42,21.37],[50,3.23]],"id":41419610},{"atl":[[120,0]],"id":41419610},{"atl":[[140,1.13],[160,4.95]],"id":41419623},{"atb":[[34,4.8],[36,4.95],[28,19.01],[29,9.9]],"id":41419636},{"atl":[[70,2.29],[75,4.95],[90,0],[95,9.9]],"id":41419636},{"atl":[[210,4.95]],"id":41419603},{"atl":[[70,2.29],[80,4.95],[90,0],[100,9.9]],"id":41419620},{"atb":[[6.4,4.95],[7.6,4.2]],"id":41419587},{"atl":[[130,9.9],[95,4.95]],"id":41419608},{"atb":[[17.5,29.24],[18,4.95],[19.5,0],[20,0]],"id":41419588},{"atl":[[32,4.95],[34,4.8],[40,9.9],[42,0]],"id":41419588},{"atb":[[65,10.15],[48,9.9]],"id":41419600}],"con":true,"img":false}]}
{"op":"mcm","clk":"5353943173","pt":1646220036313,"mc":[{"id":"1.195503869","rc":[{"atb":[[65,4.95],[48,9.9]],"id":41419610},{"atl":[[150,4.95]],"id":41419610},{"atl":[[840,0],[510,2]],"id":41419623}],"con":true,"img":false}]}
{"op":"mcm","clk":"5353943180","pt":1646220036429,"mc":[{"id":"1.195503869","rc":[{"atl":[[160,1.09],[920,1.62],[950,0]],"id":41419609},{"atb":[[23,0],[27,10.73],[28,4.95]],"id":41419635},{"atb":[[4.4,184.78],[6.6,3.27]],"id":41419587},{"atb":[[46,3.27],[28,21.67]],"id":41419600}],"con":true,"img":false}]}
{"op":"mcm","clk":"5353943189","pt":1646220036523,"mc":[{"id":"1.195503869","rc":[{"atb":[[32,0]],"id":41419605},{"atb":[[10,0],[13.5,12.68]],"id":41419589},{"atl":[[55,2]],"id":41419589},{"atb":[[32,0],[46,3.52]],"id":41419601},{"atb":[[70,2.29],[23,19.59]],"id":41419626},{"atl":[[150,19.92],[330,0]],"id":41419639},{"atb":[[6.4,93.53]],"id":41419585},{"atl":[[430,2]],"id":41419610},{"atl":[[840,1.78],[870,0]],"id":41419623},{"atb":[[32,17.23],[38,4.28],[28,0]],"id":41419636},{"atl":[[260,2],[95,24.41]],"id":41419636},{"atl":[[100,24.62],[240,0]],"id":41419620},{"atl":[[130,21.46]],"id":41419608},{"atb":[[85,0],[95,11.63]],"id":41419621},{"atb":[[16.5,17.44],[17.5,0]],"id":41419588},{"atl":[[40,24.62],[95,2]],"id":41419588}],"con":true,"img":false}]}
{"op":"mcm","clk":"5353943199","pt":1646220036626,"mc":[{"id":"1.195503869","rc":[{"atb":[[11.5,22.48]],"id":41419589},{"atl":[[26,29.66]],"id":41419589},{"atb":[[36,31.21]],"id":41419601},{"atb":[[42,3.27]],"id":41419626}],"con":true,"img":false}]}
{"op":"mcm","clk":"5353943207","pt":1646220036737,"mc":[{"id":"1.195503869","rc":[{"atb":[[38,24.62],[46,8.47]],"id":41419605},{"atb":[[7.6,2.72]],"id":41419587},{"atl":[[350,2]],"id":41419608}],"con":true,"img":false}]}
{"op":"mcm","clk":"5353943219","pt":1646220036840,"mc":[{"id":"1.195503869","rc":[{"atb":[[70,2.29],[42,0],[48,24.62]],"id":41419610},{"atl":[[75,0],[80,4.95],[95,14.5],[100,9.9]],"id":41419636},{"atb":[[6.6,31.58]],"id":41419587}],"con":true,"img":false}]}
{"op":"mcm","clk":"5353943231","pt":1646220036896,"mc":[{"id":"1.195503869","rc":[{"atb":[[1.01,1.48]],"id":41419587}],"con":true,"img":false}]}
{"op":"mcm","clk":"5353943239","pt":1646220037010,"mc":[{"id":"1.195503869","rc":[{"atb":[[27,0],[28,22.06]],"id":41419635},{"atb":[[17.5,9.6]],"id":41419588},{"atl":[[32,10.06]],"id":41419588}],"con":true,"img":false}]}
{"op":"mcm","clk":"5353943250","pt":1646220037102,"mc":[{"id":"1.195503869","rc":[{"atl":[[300,4.95]],"id":41419621}],"con":true,"img":false}]}
{"op":"mcm","clk":"5353943259","pt":1646220037210,"mc":[{"id":"1.195503869","rc":[{"atl":[[180,0]],"id":41419609},{"atl":[[650,2]],"id":41419621},{"atb":[[28,5.18]],"id":41419600}],"con":true,"img":false}]}
{"op":"mcm","clk":"5353943271","pt":1646220037313,"mc":[{"id":"1.195503869","rc":[{"atb":[[9.2,3.27],[10.5,2.72]],"id":41419585},{"atl":[[910,0]],"id":41419621}],"con":true,"img":false}]}
{"op":"mcm","clk":"5353943281","pt":1646220037425,"mc":[{"id":"1.195503869","rc":[{"atb":[[12,0]],"id":41419589},{"atb":[[40,0]],"id":41419601},{"atb":[[23,4.55],[55,2.72]],"id":41419626},{"atl":[[430,5.49]],"id":41419610},{"atb":[[34,0]],"id":41419636}],"con":true,"img":false}]}
{"op":"mcm","clk":"5353943290","pt":1646220037528,"mc":[{"id":"1.195503869","rc":[{"atb":[[40,0]],"id":41419605},{"atl":[[650,0],[880,2.17]],"id":41419621}],"con":true,"img":false}]}
{"op":"mcm","clk":"5353943304","pt":1646220037738,"mc":[{"id":"1.195503869","rc":[{"atl":[[300,5.48]],"id":41419621}],"con":true,"img":false}]}
{"op":"mcm","clk":"5353943316","pt":1646220037837,"mc":[{"id":"1.195503869","rc":[{"atb":[[6.4,51.88]],"id":41419585},{"atb":[[50,0]],"id":41419610},{"atl":[[34,0]],"id":41419588}],"con":true,"img":false}]}
{"op":"mcm","clk":"5353943350","pt":1646220038232,"mc":[{"id":"1.195503869","rc":[{"atl":[[170,0]],"id":41419603}],"con":true,"img":false}]}
{"op":"mcm","clk":"5353943375","pt":1646220038519,"mc":[{"id":"1.195503869","rc":[{"atl":[[210,12.12]],"id":41419603},{"atl":[[880,2]],"id":41419621},{"atl":[[990,2],[980,1.53]],"id":41419596}],"con":true,"img":false}]}
{"op":"mcm","clk":"5353943437","pt":1646220039158,"mc":[{"id":"1.195503869","rc":[{"atl":[[620,2]],"id":41419619}],"con":true,"img":false}]}
{"op":"mcm","clk":"5353943468","pt":1646220039421,"mc":[{"id":"1.195503869","rc":[{"atl":[[280,5.38]],"id":41419619}],"con":true,"img":false}]}
