{"op":"mcm","clk":"5346195394","pt":1646178339823,"mc":[{"id":"1.195453759","marketDefinition":{"bspMarket":false,"turnInPlayEnabled":false,"persistenceEnabled":false,"marketBaseRate":7.0,"eventId":"31272494","eventTypeId":"4339","numberOfWinners":1,"bettingType":"ODDS","marketType":"QUINELLA","marketTime":"2022-03-02T11:49:00.000Z","suspendTime":"2022-03-02T11:49:00.000Z","bspReconciled":false,"complete":true,"inPlay":false,"crossMatching":false,"runnersVoidable":false,"numberOfActiveRunners":15,"betDelay":0,"status":"OPEN","runners":[{"status":"ACTIVE","sortPriority":1,"id":522741,"name":"1 - 2 / 2 - 1"},{"status":"ACTIVE","sortPriority":2,"id":522742,"name":"1 - 3 / 3 - 1"},{"status":"ACTIVE","sortPriority":3,"id":522743,"name":"1 - 4 / 4 - 1"},{"status":"ACTIVE","sortPriority":4,"id":522745,"name":"1 - 6 / 6 - 1"},{"status":"ACTIVE","sortPriority":5,"id":3805730,"name":"1 - 7 / 7 - 1"},{"status":"ACTIVE","sortPriority":6,"id":522746,"name":"2 - 3 / 3 - 2"},{"status":"ACTIVE","sortPriority":7,"id":522747,"name":"2 - 4 / 4 - 2"},{"status":"ACTIVE","sortPriority":8,"id":522749,"name":"2 - 6 / 6 - 2"},{"status":"ACTIVE","sortPriority":9,"id":3805736,"name":"2 - 7 / 7 - 2"},{"status":"ACTIVE","sortPriority":10,"id":522750,"name":"3 - 4 / 4 - 3"},{"status":"ACTIVE","sortPriority":11,"id":522752,"name":"3 - 6 / 6 - 3"},{"status":"ACTIVE","sortPriority":12,"id":3805746,"name":"3 - 7 / 7 - 3"},{"status":"ACTIVE","sortPriority":13,"id":522753,"name":"4 - 6 / 6 - 4"},{"status":"ACTIVE","sortPriority":14,"id":3805755,"name":"4 - 7 / 7 - 4"},{"status":"ACTIVE","sortPriority":15,"id":3805783,"name":"6 - 7 / 7 - 6"}],"regulators":["MR_INT"],"venue":"Traralgon","countryCode":"AU","discountAllowed":true,"timezone":"Australia/Sydney","openDate":"2022-03-02T08:31:00.000Z","version":4382480609,"name":"Quinella","eventName":"Traralgon (AUS) 2nd Mar"},"rc":[],"con":true,"img":false}]}
{"op":"mcm","clk":"5346200440","pt":1646178438338,"mc":[{"id":"1.195453759","rc":[{"atb":[[4.3,60.47],[3.4,83.15],[2.96,135.75]],"id":522746},{"atb":[[4.8,70.02],[8.6,26.26],[5.8,41.57]],"id":522747},{"atb":[[12,18.14],[7.8,29.34],[5.9,54.3]],"id":3805730},{"atb":[[3.7,98.55],[4.4,58.69],[5.9,40.72]],"id":522741},{"atb":[[9,24.94],[5,66.52],[6,39.91]],"id":522742},{"atb":[[19.5,10.78],[12,18.14],[8.8,34.11]],"id":522743},{"atb":[[18.5,11.4],[11,19.95],[8.4,35.95]],"id":522745}],"con":true,"img":false}]}
{"op":"mcm","clk":"5346200445","pt":1646178438495,"mc":[{"id":"1.195453759","rc":[{"atb":[[17,12.47],[9.8,22.67],[7.8,39.12]],"id":3805783},{"atb":[[5.6,43.38],[4.6,73.91],[8.2,27.71]],"id":3805746},{"atb":[[18,11.73],[10.5,21],[8.2,36.95]],"id":3805755},{"atb":[[5.3,46.41],[3.4,110.87],[3.9,68.81]],"id":3805736},{"atb":[[5.6,43.38],[4.6,73.91],[8.2,27.71]],"id":522749},{"atb":[[6.8,45.87],[8.8,25.58],[14.5,14.78]],"id":522750},{"atb":[[8.6,26.26],[14,15.35],[6.6,47.51]],"id":522752},{"atb":[[10.5,28],[26,7.98],[15.5,13.76]],"id":522753}],"con":true,"img":false}]}
{"op":"mcm","clk":"5346322377","pt":1646180813699,"mc":[{"id":"1.195453759","rc":[{"atb":[[17,0],[9.8,0],[7.8,0]],"id":3805783},{"atb":[[5.6,0],[4.6,0],[8.2,0]],"id":3805746},{"atb":[[18,0],[10.5,0],[8.2,0]],"id":3805755},{"atb":[[4.3,0],[3.4,0],[2.96,0]],"id":522746},{"atb":[[5.3,0],[3.4,0],[3.9,0]],"id":3805736},{"atb":[[4.8,0],[8.6,0],[5.8,0]],"id":522747},{"atb":[[5.6,0],[4.6,0],[8.2,0]],"id":522749},{"atb":[[6.8,0],[8.8,0],[14.5,0]],"id":522750},{"atb":[[8.6,0],[14,0],[6.6,0]],"id":522752},{"atb":[[12,0],[7.8,0],[5.9,0]],"id":3805730},{"atb":[[10.5,0],[26,0],[15.5,0]],"id":522753},{"atb":[[3.7,0],[4.4,0],[5.9,0]],"id":522741},{"atb":[[9,0],[5,0],[6,0]],"id":522742},{"atb":[[19.5,0],[12,0],[8.8,0]],"id":522743},{"atb":[[18.5,0],[11,0],[8.4,0]],"id":522745}],"con":true,"img":false}]}
{"op":"mcm","clk":"5346323000","pt":1646180826367,"mc":[{"id":"1.195453759","rc":[{"atb":[[8,38.01],[17.5,12.09],[10,22.17]],"id":3805783},{"atb":[[8,28.51],[4.5,76.03],[5.5,44.35]],"id":3805746},{"atb":[[18.5,11.4],[11,19.95],[8.4,35.95]],"id":3805755},{"atb":[[3.35,84.93],[4.2,62.36],[2.94,137.17]],"id":522746},{"atb":[[5,49.89],[3.25,118.27],[3.75,72.57]],"id":3805736},{"atb":[[5.1,64.9],[9.2,24.34],[6.2,38.38]],"id":522747},{"atb":[[4.8,70.02],[8.6,26.26],[5.8,41.58]],"id":522749},{"atb":[[16,13.3],[7.4,41.58],[9.4,23.75]],"id":522750},{"atb":[[6.8,45.88],[8.8,25.58],[14.5,14.78]],"id":522752},{"atb":[[11,19.95],[7.4,31.18],[5.7,56.62]],"id":3805730},{"atb":[[16.5,12.87],[11.5,25.34],[28,7.39]],"id":522753},{"atb":[[4.3,60.48],[5.8,41.58],[3.65,100.41]],"id":522741},{"atb":[[9,24.94],[5,66.52],[6,39.91]],"id":522742},{"atb":[[9,33.26],[20,10.5],[12.5,17.35]],"id":522743},{"atb":[[8.6,35.01],[19,11.08],[11.5,19]],"id":522745}],"con":true,"img":false}]}
{"op":"mcm","clk":"5346767655","pt":1646187402719,"mc":[{"id":"1.195453759","marketDefinition":{"bspMarket":false,"turnInPlayEnabled":false,"persistenceEnabled":false,"marketBaseRate":7.0,"eventId":"31272494","eventTypeId":"4339","numberOfWinners":1,"bettingType":"ODDS","marketType":"QUINELLA","marketTime":"2022-03-02T11:49:00.000Z","suspendTime":"2022-03-02T11:49:00.000Z","bspReconciled":false,"complete":true,"inPlay":false,"crossMatching":false,"runnersVoidable":false,"numberOfActiveRunners":15,"betDelay":0,"status":"OPEN","runners":[{"status":"ACTIVE","sortPriority":1,"id":522741,"name":"1 - 2 / 2 - 1"},{"status":"ACTIVE","sortPriority":2,"id":522742,"name":"1 - 3 / 3 - 1"},{"status":"ACTIVE","sortPriority":3,"id":522743,"name":"1 - 4 / 4 - 1"},{"status":"ACTIVE","sortPriority":4,"id":522745,"name":"1 - 6 / 6 - 1"},{"status":"ACTIVE","sortPriority":5,"id":3805730,"name":"1 - 7 / 7 - 1"},{"status":"ACTIVE","sortPriority":6,"id":522746,"name":"2 - 3 / 3 - 2"},{"status":"ACTIVE","sortPriority":7,"id":522747,"name":"2 - 4 / 4 - 2"},{"status":"ACTIVE","sortPriority":8,"id":522749,"name":"2 - 6 / 6 - 2"},{"status":"ACTIVE","sortPriority":9,"id":3805736,"name":"2 - 7 / 7 - 2"},{"status":"ACTIVE","sortPriority":10,"id":522750,"name":"3 - 4 / 4 - 3"},{"status":"ACTIVE","sortPriority":11,"id":522752,"name":"3 - 6 / 6 - 3"},{"status":"ACTIVE","sortPriority":12,"id":3805746,"name":"3 - 7 / 7 - 3"},{"status":"ACTIVE","sortPriority":13,"id":522753,"name":"4 - 6 / 6 - 4"},{"status":"ACTIVE","sortPriority":14,"id":3805755,"name":"4 - 7 / 7 - 4"},{"status":"ACTIVE","sortPriority":15,"id":3805783,"name":"6 - 7 / 7 - 6"}],"regulators":["MR_INT"],"venue":"Traralgon","countryCode":"AU","discountAllowed":true,"timezone":"Australia/Sydney","openDate":"2022-03-02T08:31:00.000Z","version":4382480609,"name":"Quinella","eventName":"Traralgon (AUS) 2nd Mar"},"rc":[{"atb":[[8,38.07],[17.5,12.11],[10,22.2]],"id":3805783},{"atb":[[8,28.55],[4.5,76.15],[5.5,44.42]],"id":3805746},{"atb":[[18.5,11.42],[11,19.99],[8.4,36.01]],"id":3805755},{"atb":[[3.35,85.06],[4.2,62.46],[2.94,137.39]],"id":522746},{"atb":[[5,49.97],[3.25,118.45],[3.75,72.69]],"id":3805736},{"atb":[[5.1,65],[9.2,24.37],[6.2,38.44]],"id":522747},{"atb":[[4.8,70.14],[8.6,26.3],[5.8,41.64]],"id":522749},{"atb":[[16,13.32],[7.4,41.64],[9.4,23.79]],"id":522750},{"atb":[[6.8,45.95],[8.8,25.62],[14.5,14.8]],"id":522752},{"atb":[[11,19.99],[7.4,31.23],[5.7,56.7]],"id":3805730},{"atb":[[16.5,12.89],[11.5,25.38],[28,7.4]],"id":522753},{"atb":[[4.3,60.57],[5.8,41.64],[3.65,100.57]],"id":522741},{"atb":[[9,24.98],[5,66.63],[6,39.98]],"id":522742},{"atb":[[9,33.31],[20,10.51],[12.5,17.38]],"id":522743},{"atb":[[8.6,35.07],[19,11.1],[11.5,19.03]],"id":522745}],"con":true,"img":true}]}
{"op":"mcm","clk":"5347092219","pt":1646192802701,"mc":[{"id":"1.195453759","marketDefinition":{"bspMarket":false,"turnInPlayEnabled":false,"persistenceEnabled":false,"marketBaseRate":7.0,"eventId":"31272494","eventTypeId":"4339","numberOfWinners":1,"bettingType":"ODDS","marketType":"QUINELLA","marketTime":"2022-03-02T11:49:00.000Z","suspendTime":"2022-03-02T11:49:00.000Z","bspReconciled":false,"complete":true,"inPlay":false,"crossMatching":false,"runnersVoidable":false,"numberOfActiveRunners":15,"betDelay":0,"status":"OPEN","runners":[{"status":"ACTIVE","sortPriority":1,"id":522741,"name":"1 - 2 / 2 - 1"},{"status":"ACTIVE","sortPriority":2,"id":522742,"name":"1 - 3 / 3 - 1"},{"status":"ACTIVE","sortPriority":3,"id":522743,"name":"1 - 4 / 4 - 1"},{"status":"ACTIVE","sortPriority":4,"id":522745,"name":"1 - 6 / 6 - 1"},{"status":"ACTIVE","sortPriority":5,"id":3805730,"name":"1 - 7 / 7 - 1"},{"status":"ACTIVE","sortPriority":6,"id":522746,"name":"2 - 3 / 3 - 2"},{"status":"ACTIVE","sortPriority":7,"id":522747,"name":"2 - 4 / 4 - 2"},{"status":"ACTIVE","sortPriority":8,"id":522749,"name":"2 - 6 / 6 - 2"},{"status":"ACTIVE","sortPriority":9,"id":3805736,"name":"2 - 7 / 7 - 2"},{"status":"ACTIVE","sortPriority":10,"id":522750,"name":"3 - 4 / 4 - 3"},{"status":"ACTIVE","sortPriority":11,"id":522752,"name":"3 - 6 / 6 - 3"},{"status":"ACTIVE","sortPriority":12,"id":3805746,"name":"3 - 7 / 7 - 3"},{"status":"ACTIVE","sortPriority":13,"id":522753,"name":"4 - 6 / 6 - 4"},{"status":"ACTIVE","sortPriority":14,"id":3805755,"name":"4 - 7 / 7 - 4"},{"status":"ACTIVE","sortPriority":15,"id":3805783,"name":"6 - 7 / 7 - 6"}],"regulators":["MR_INT"],"venue":"Traralgon","countryCode":"AU","discountAllowed":true,"timezone":"Australia/Sydney","openDate":"2022-03-02T08:31:00.000Z","version":4382480609,"name":"Quinella","eventName":"Traralgon (AUS) 2nd Mar"},"rc":[{"atb":[[8,38.14],[17.5,12.13],[10,22.24]],"id":3805783},{"atb":[[8,28.6],[4.5,76.28],[5.5,44.49]],"id":3805746},{"atb":[[18.5,11.44],[11,20.02],[8.4,36.07]],"id":3805755},{"atb":[[3.35,85.2],[4.2,62.57],[2.94,137.62]],"id":522746},{"atb":[[5,50.06],[3.25,118.65],[3.75,72.81]],"id":3805736},{"atb":[[5.1,65.11],[9.2,24.42],[6.2,38.5]],"id":522747},{"atb":[[4.8,70.25],[8.6,26.34],[5.8,41.71]],"id":522749},{"atb":[[16,13.34],[7.4,41.71],[9.4,23.83]],"id":522750},{"atb":[[6.8,46.03],[8.8,25.67],[14.5,14.83]],"id":522752},{"atb":[[11,20.02],[7.4,31.28],[5.7,56.8]],"id":3805730},{"atb":[[16.5,12.91],[11.5,25.42],[28,7.41]],"id":522753},{"atb":[[4.3,60.67],[5.8,41.71],[3.65,100.74]],"id":522741},{"atb":[[9,25.02],[5,66.74],[6,40.04]],"id":522742},{"atb":[[9,33.37],[20,10.53],[12.5,17.41]],"id":522743},{"atb":[[8.6,35.13],[19,11.12],[11.5,19.06]],"id":522745}],"con":true,"img":true}]}
{"op":"mcm","clk":"5347381092","pt":1646198202719,"mc":[{"id":"1.195453759","marketDefinition":{"bspMarket":false,"turnInPlayEnabled":false,"persistenceEnabled":false,"marketBaseRate":7.0,"eventId":"31272494","eventTypeId":"4339","numberOfWinners":1,"bettingType":"ODDS","marketType":"QUINELLA","marketTime":"2022-03-02T11:49:00.000Z","suspendTime":"2022-03-02T11:49:00.000Z","bspReconciled":false,"complete":true,"inPlay":false,"crossMatching":false,"runnersVoidable":false,"numberOfActiveRunners":15,"betDelay":0,"status":"OPEN","runners":[{"status":"ACTIVE","sortPriority":1,"id":522741,"name":"1 - 2 / 2 - 1"},{"status":"ACTIVE","sortPriority":2,"id":522742,"name":"1 - 3 / 3 - 1"},{"status":"ACTIVE","sortPriority":3,"id":522743,"name":"1 - 4 / 4 - 1"},{"status":"ACTIVE","sortPriority":4,"id":522745,"name":"1 - 6 / 6 - 1"},{"status":"ACTIVE","sortPriority":5,"id":3805730,"name":"1 - 7 / 7 - 1"},{"status":"ACTIVE","sortPriority":6,"id":522746,"name":"2 - 3 / 3 - 2"},{"status":"ACTIVE","sortPriority":7,"id":522747,"name":"2 - 4 / 4 - 2"},{"status":"ACTIVE","sortPriority":8,"id":522749,"name":"2 - 6 / 6 - 2"},{"status":"ACTIVE","sortPriority":9,"id":3805736,"name":"2 - 7 / 7 - 2"},{"status":"ACTIVE","sortPriority":10,"id":522750,"name":"3 - 4 / 4 - 3"},{"status":"ACTIVE","sortPriority":11,"id":522752,"name":"3 - 6 / 6 - 3"},{"status":"ACTIVE","sortPriority":12,"id":3805746,"name":"3 - 7 / 7 - 3"},{"status":"ACTIVE","sortPriority":13,"id":522753,"name":"4 - 6 / 6 - 4"},{"status":"ACTIVE","sortPriority":14,"id":3805755,"name":"4 - 7 / 7 - 4"},{"status":"ACTIVE","sortPriority":15,"id":3805783,"name":"6 - 7 / 7 - 6"}],"regulators":["MR_INT"],"venue":"Traralgon","countryCode":"AU","discountAllowed":true,"timezone":"Australia/Sydney","openDate":"2022-03-02T08:31:00.000Z","version":4382480609,"name":"Quinella","eventName":"Traralgon (AUS) 2nd Mar"},"rc":[{"atb":[[8,38.12],[17.5,12.13],[10,22.23]],"id":3805783},{"atb":[[8,28.59],[4.5,76.25],[5.5,44.48]],"id":3805746},{"atb":[[18.5,11.43],[11,20.01],[8.4,36.06]],"id":3805755},{"atb":[[3.35,85.17],[4.2,62.54],[2.94,137.57]],"id":522746},{"atb":[[5,50.04],[3.25,118.61],[3.75,72.78]],"id":3805736},{"atb":[[5.1,65.09],[9.2,24.41],[6.2,38.49]],"id":522747},{"atb":[[4.8,70.23],[8.6,26.33],[5.8,41.7]],"id":522749},{"atb":[[16,13.34],[7.4,41.7],[9.4,23.82]],"id":522750},{"atb":[[6.8,46.01],[8.8,25.66],[14.5,14.82]],"id":522752},{"atb":[[11,20.01],[7.4,31.27],[5.7,56.78]],"id":3805730},{"atb":[[16.5,12.91],[11.5,25.41],[28,7.41]],"id":522753},{"atb":[[4.3,60.65],[5.8,41.7],[3.65,100.7]],"id":522741},{"atb":[[9,25.01],[5,66.72],[6,40.03]],"id":522742},{"atb":[[9,33.36],[20,10.53],[12.5,17.4]],"id":522743},{"atb":[[8.6,35.11],[19,11.12],[11.5,19.06]],"id":522745}],"con":true,"img":true}]}
{"op":"mcm","clk":"5347430697","pt":1646199232267,"mc":[{"id":"1.195453759","rc":[{"atb":[[8,0],[17.5,0],[10,0]],"id":3805783},{"atb":[[8,0],[4.5,0],[5.5,0]],"id":3805746},{"atb":[[18.5,0],[11,0],[8.4,0]],"id":3805755},{"atb":[[3.35,0],[4.2,0],[2.94,0]],"id":522746},{"atb":[[5,0],[3.25,0],[3.75,0]],"id":3805736},{"atb":[[5.1,0],[9.2,0],[6.2,0]],"id":522747},{"atb":[[4.8,0],[8.6,0],[5.8,0]],"id":522749},{"atb":[[16,0],[7.4,0],[9.4,0]],"id":522750},{"atb":[[6.8,0],[8.8,0],[14.5,0]],"id":522752},{"atb":[[11,0],[7.4,0],[5.7,0]],"id":3805730},{"atb":[[16.5,0],[11.5,0],[28,0]],"id":522753},{"atb":[[4.3,0],[5.8,0],[3.65,0]],"id":522741},{"atb":[[9,0],[5,0],[6,0]],"id":522742},{"atb":[[9,0],[20,0],[12.5,0]],"id":522743},{"atb":[[8.6,0],[19,0],[11.5,0]],"id":522745}],"con":true,"img":false}]}
{"op":"mcm","clk":"5347431195","pt":1646199243202,"mc":[{"id":"1.195453759","rc":[{"atb":[[17,12.5],[9.8,22.74],[7.8,39.24]],"id":3805783},{"atb":[[8,28.59],[4.5,76.25],[5.5,44.48]],"id":3805746},{"atb":[[18,11.77],[10.5,21.07],[8.2,37.06]],"id":3805755},{"atb":[[3.45,81.69],[2.98,134.79],[4.4,58.86]],"id":522746},{"atb":[[5,50.04],[3.25,118.61],[3.75,72.78]],"id":3805736},{"atb":[[9,25.01],[5,66.72],[6,40.03]],"id":522747},{"atb":[[5.7,42.58],[8.4,27.04],[4.7,72.13]],"id":522749},{"atb":[[16.5,12.91],[9.6,23.27],[7.6,40.43]],"id":522750},{"atb":[[9,25.01],[7,44.48],[15,14.29]],"id":522752},{"atb":[[5.6,58.01],[7.2,32.28],[10.5,21.07]],"id":3805730},{"atb":[[16.5,12.91],[11.5,25.41],[28,7.41]],"id":522753},{"atb":[[3.6,102.64],[5.7,42.58],[4.2,62.54]],"id":522741},{"atb":[[5.1,65.09],[9.2,24.41],[6.2,38.49]],"id":522742},{"atb":[[9,33.36],[20,10.53],[12.5,17.4]],"id":522743},{"atb":[[8.6,35.11],[19,11.12],[11.5,19.06]],"id":522745}],"con":true,"img":false}]}
{"op":"mcm","clk":"5347848777","pt":1646209002723,"mc":[{"id":"1.195453759","marketDefinition":{"bspMarket":false,"turnInPlayEnabled":false,"persistenceEnabled":false,"marketBaseRate":7.0,"eventId":"31272494","eventTypeId":"4339","numberOfWinners":1,"bettingType":"ODDS","marketType":"QUINELLA","marketTime":"2022-03-02T11:49:00.000Z","suspendTime":"2022-03-02T11:49:00.000Z","bspReconciled":false,"complete":true,"inPlay":false,"crossMatching":false,"runnersVoidable":false,"numberOfActiveRunners":15,"betDelay":0,"status":"OPEN","runners":[{"status":"ACTIVE","sortPriority":1,"id":522741,"name":"1 - 2 / 2 - 1"},{"status":"ACTIVE","sortPriority":2,"id":522742,"name":"1 - 3 / 3 - 1"},{"status":"ACTIVE","sortPriority":3,"id":522743,"name":"1 - 4 / 4 - 1"},{"status":"ACTIVE","sortPriority":4,"id":522745,"name":"1 - 6 / 6 - 1"},{"status":"ACTIVE","sortPriority":5,"id":3805730,"name":"1 - 7 / 7 - 1"},{"status":"ACTIVE","sortPriority":6,"id":522746,"name":"2 - 3 / 3 - 2"},{"status":"ACTIVE","sortPriority":7,"id":522747,"name":"2 - 4 / 4 - 2"},{"status":"ACTIVE","sortPriority":8,"id":522749,"name":"2 - 6 / 6 - 2"},{"status":"ACTIVE","sortPriority":9,"id":3805736,"name":"2 - 7 / 7 - 2"},{"status":"ACTIVE","sortPriority":10,"id":522750,"name":"3 - 4 / 4 - 3"},{"status":"ACTIVE","sortPriority":11,"id":522752,"name":"3 - 6 / 6 - 3"},{"status":"ACTIVE","sortPriority":12,"id":3805746,"name":"3 - 7 / 7 - 3"},{"status":"ACTIVE","sortPriority":13,"id":522753,"name":"4 - 6 / 6 - 4"},{"status":"ACTIVE","sortPriority":14,"id":3805755,"name":"4 - 7 / 7 - 4"},{"status":"ACTIVE","sortPriority":15,"id":3805783,"name":"6 - 7 / 7 - 6"}],"regulators":["MR_INT"],"venue":"Traralgon","countryCode":"AU","discountAllowed":true,"timezone":"Australia/Sydney","openDate":"2022-03-02T08:31:00.000Z","version":4382480609,"name":"Quinella","eventName":"Traralgon (AUS) 2nd Mar"},"rc":[{"atb":[[17,12.5],[9.8,22.74],[7.8,39.23]],"id":3805783},{"atb":[[8,28.58],[4.5,76.23],[5.5,44.47]],"id":3805746},{"atb":[[18,11.76],[10.5,21.06],[8.2,37.05]],"id":3805755},{"atb":[[3.45,81.67],[2.98,134.75],[4.4,58.85]],"id":522746},{"atb":[[5,50.02],[3.25,118.58],[3.75,72.76]],"id":3805736},{"atb":[[9,25.01],[5,66.7],[6,40.02]],"id":522747},{"atb":[[5.7,42.57],[8.4,27.04],[4.7,72.11]],"id":522749},{"atb":[[16.5,12.9],[9.6,23.26],[7.6,40.42]],"id":522750},{"atb":[[9,25.01],[7,44.47],[15,14.29]],"id":522752},{"atb":[[5.6,58],[7.2,32.27],[10.5,21.06]],"id":3805730},{"atb":[[16.5,12.9],[11.5,25.4],[28,7.41]],"id":522753},{"atb":[[3.6,102.62],[5.7,42.57],[4.2,62.53]],"id":522741},{"atb":[[5.1,65.07],[9.2,24.4],[6.2,38.48]],"id":522742},{"atb":[[9,33.35],[20,10.52],[12.5,17.4]],"id":522743},{"atb":[[8.6,35.1],[19,11.11],[11.5,19.05]],"id":522745}],"con":true,"img":true}]}
{"op":"mcm","clk":"5348132960","pt":1646214402730,"mc":[{"id":"1.195453759","marketDefinition":{"bspMarket":false,"turnInPlayEnabled":false,"persistenceEnabled":false,"marketBaseRate":7.0,"eventId":"31272494","eventTypeId":"4339","numberOfWinners":1,"bettingType":"ODDS","marketType":"QUINELLA","marketTime":"2022-03-02T11:49:00.000Z","suspendTime":"2022-03-02T11:49:00.000Z","bspReconciled":false,"complete":true,"inPlay":false,"crossMatching":false,"runnersVoidable":false,"numberOfActiveRunners":15,"betDelay":0,"status":"OPEN","runners":[{"status":"ACTIVE","sortPriority":1,"id":522741,"name":"1 - 2 / 2 - 1"},{"status":"ACTIVE","sortPriority":2,"id":522742,"name":"1 - 3 / 3 - 1"},{"status":"ACTIVE","sortPriority":3,"id":522743,"name":"1 - 4 / 4 - 1"},{"status":"ACTIVE","sortPriority":4,"id":522745,"name":"1 - 6 / 6 - 1"},{"status":"ACTIVE","sortPriority":5,"id":3805730,"name":"1 - 7 / 7 - 1"},{"status":"ACTIVE","sortPriority":6,"id":522746,"name":"2 - 3 / 3 - 2"},{"status":"ACTIVE","sortPriority":7,"id":522747,"name":"2 - 4 / 4 - 2"},{"status":"ACTIVE","sortPriority":8,"id":522749,"name":"2 - 6 / 6 - 2"},{"status":"ACTIVE","sortPriority":9,"id":3805736,"name":"2 - 7 / 7 - 2"},{"status":"ACTIVE","sortPriority":10,"id":522750,"name":"3 - 4 / 4 - 3"},{"status":"ACTIVE","sortPriority":11,"id":522752,"name":"3 - 6 / 6 - 3"},{"status":"ACTIVE","sortPriority":12,"id":3805746,"name":"3 - 7 / 7 - 3"},{"status":"ACTIVE","sortPriority":13,"id":522753,"name":"4 - 6 / 6 - 4"},{"status":"ACTIVE","sortPriority":14,"id":3805755,"name":"4 - 7 / 7 - 4"},{"status":"ACTIVE","sortPriority":15,"id":3805783,"name":"6 - 7 / 7 - 6"}],"regulators":["MR_INT"],"venue":"Traralgon","countryCode":"AU","discountAllowed":true,"timezone":"Australia/Sydney","openDate":"2022-03-02T08:31:00.000Z","version":4382480609,"name":"Quinella","eventName":"Traralgon (AUS) 2nd Mar"},"rc":[{"atb":[[17,12.48],[9.8,22.7],[7.8,39.17]],"id":3805783},{"atb":[[8,28.54],[4.5,76.11],[5.5,44.4]],"id":3805746},{"atb":[[18,11.74],[10.5,21.03],[8.2,36.99]],"id":3805755},{"atb":[[3.45,81.54],[2.98,134.54],[4.4,58.76]],"id":522746},{"atb":[[5,49.94],[3.25,118.39],[3.75,72.65]],"id":3805736},{"atb":[[9,24.97],[5,66.59],[6,39.95]],"id":522747},{"atb":[[5.7,42.5],[8.4,26.99],[4.7,71.99]],"id":522749},{"atb":[[16.5,12.88],[9.6,23.23],[7.6,40.36]],"id":522750},{"atb":[[9,24.97],[7,44.4],[15,14.27]],"id":522752},{"atb":[[5.6,57.91],[7.2,32.22],[10.5,21.03]],"id":3805730},{"atb":[[16.5,12.88],[11.5,25.36],[28,7.4]],"id":522753},{"atb":[[3.6,102.45],[5.7,42.5],[4.2,62.43]],"id":522741},{"atb":[[5.1,64.97],[9.2,24.36],[6.2,38.42]],"id":522742},{"atb":[[9,33.29],[20,10.51],[12.5,17.37]],"id":522743},{"atb":[[8.6,35.05],[19,11.1],[11.5,19.02]],"id":522745}],"con":true,"img":true}]}
{"op":"mcm","clk":"5348145048","pt":1646214540437,"mc":[{"id":"1.195453759","rc":[{"atb":[[17,12.48],[11,3.26],[9.8,22.7],[13.5,2.72],[7.8,39.17]],"id":3805783},{"atb":[[8,28.54],[4.5,76.11],[5.5,44.4],[4.2,3.26],[4.7,2.72]],"id":3805746},{"atb":[[18,11.74],[10.5,21.03],[8.2,36.99],[12,3.26],[14.5,2.72]],"id":3805755},{"atb":[[3.45,81.54],[5.1,2.72],[4.6,3.26],[2.98,134.54],[4.4,58.76]],"id":522746},{"atb":[[5,49.94],[4.9,3.26],[3.25,118.39],[3.75,72.65],[5.4,2.72]],"id":3805736},{"atb":[[9,24.97],[5,66.59],[9.2,3.26],[10.5,2.72],[6,39.95]],"id":522747},{"atb":[[9.2,2.72],[8.2,3.26],[5.7,42.5],[8.4,26.99],[4.7,71.99]],"id":522749},{"atb":[[16.5,12.88],[9.6,23.23],[11.5,3.26],[7.6,40.36],[14,2.72]],"id":522750},{"atb":[[9.6,3.26],[9,24.97],[11.5,2.72],[7,44.4],[15,14.27]],"id":522752},{"atb":[[5.6,57.91],[7.2,32.22],[10.5,21.03],[11,2.72],[9.4,3.26]],"id":3805730},{"atb":[[16.5,12.88],[18.5,3.26],[22,2.72],[11.5,25.36],[28,7.4]],"id":522753},{"atb":[[3.6,102.45],[6.8,2.72],[5.7,42.5],[4.2,62.43],[5.9,3.26]],"id":522741},{"atb":[[5.1,64.97],[9.2,27.63],[6.2,38.42],[10.5,2.72]],"id":522742},{"atb":[[17,2.72],[9,33.29],[20,10.51],[12.5,17.37],[14.5,3.26]],"id":522743},{"atb":[[16,2.72],[8.6,35.05],[19,11.1],[11.5,19.02],[13.5,3.26]],"id":522745}],"con":true,"img":false}]}
{"op":"mcm","clk":"5348145455","pt":1646214546140,"mc":[{"id":"1.195453759","rc":[{"atb":[[11,0],[13.5,0]],"id":3805783}],"con":true,"img":false}]}
{"op":"mcm","clk":"5348145500","pt":1646214546868,"mc":[{"id":"1.195453759","rc":[{"atb":[[10.5,3.26],[13,2.72]],"id":3805783}],"con":true,"img":false}]}
{"op":"mcm","clk":"5348233809","pt":1646215755250,"mc":[{"id":"1.195453759","rc":[{"atb":[[10.5,0],[13,0]],"id":3805783}],"con":true,"img":false}]}
{"op":"mcm","clk":"5348233864","pt":1646215755926,"mc":[{"id":"1.195453759","rc":[{"atb":[[11,3.26],[13.5,2.72]],"id":3805783}],"con":true,"img":false}]}
{"op":"mcm","clk":"5348235539","pt":1646215773757,"mc":[{"id":"1.195453759","rc":[{"atb":[[11,0],[13.5,0]],"id":3805783}],"con":true,"img":false}]}
{"op":"mcm","clk":"5348235589","pt":1646215774480,"mc":[{"id":"1.195453759","rc":[{"atb":[[10.5,3.26],[13,2.72]],"id":3805783}],"con":true,"img":false}]}
{"op":"mcm","clk":"5348396157","pt":1646217255182,"mc":[{"id":"1.195453759","rc":[{"atb":[[10.5,0],[13,0]],"id":3805783}],"con":true,"img":false}]}
{"op":"mcm","clk":"5348396213","pt":1646217255857,"mc":[{"id":"1.195453759","rc":[{"atb":[[11,3.26],[13.5,2.72]],"id":3805783}],"con":true,"img":false}]}
{"op":"mcm","clk":"5348403604","pt":1646217333575,"mc":[{"id":"1.195453759","rc":[{"atb":[[11,0],[13.5,0]],"id":3805783}],"con":true,"img":false}]}
{"op":"mcm","clk":"5348403681","pt":1646217334507,"mc":[{"id":"1.195453759","rc":[{"atb":[[10.5,3.26],[13,2.72]],"id":3805783}],"con":true,"img":false}]}
{"op":"mcm","clk":"5348404866","pt":1646217347810,"mc":[{"id":"1.195453759","rc":[{"atb":[[9.2,0],[8.2,0]],"id":522749}],"con":true,"img":false}]}
{"op":"mcm","clk":"5348404930","pt":1646217348500,"mc":[{"id":"1.195453759","rc":[{"atb":[[8.4,30.26],[9.4,2.72]],"id":522749}],"con":true,"img":false}]}
{"op":"mcm","clk":"5348495163","pt":1646218197802,"mc":[{"id":"1.195453759","rc":[{"atb":[[3.5,24.98]],"id":3805783},{"atl":[[410,2]],"id":3805783},{"atb":[[2.32,57.08]],"id":3805746},{"atl":[[320,2]],"id":3805746},{"atb":[[6.2,19.23]],"id":3805755},{"atl":[[570,2]],"id":3805755},{"atb":[[2.66,60.24]],"id":522746},{"atl":[[140,2]],"id":522746},{"atb":[[2.94,51.55]],"id":3805736},{"atl":[[240,2]],"id":3805736},{"atb":[[6.8,17.24]],"id":522747},{"atl":[[630,2]],"id":522747},{"atb":[[3.85,35.09]],"id":522749},{"atl":[[480,2]],"id":522749},{"atb":[[5.5,22.22]],"id":522750},{"atl":[[540,2]],"id":522750},{"atb":[[3.35,28.54]],"id":522752},{"atl":[[360,2]],"id":522752},{"atb":[[1.98,42.06]],"id":3805730},{"atl":[[470,2]],"id":3805730},{"atb":[[10,11.11]],"id":522753},{"atl":[[910,2]],"id":522753},{"atb":[[4,33.33]],"id":522741},{"atl":[[510,2]],"id":522741},{"atb":[[3.6,38.46]],"id":522742},{"atl":[[420,2]],"id":522742},{"atb":[[12.5,26.07]],"id":522743},{"atl":[[980,2]],"id":522743},{"atb":[[4,22.2]],"id":522745},{"atl":[[670,2]],"id":522745}],"con":true,"img":false}]}
{"op":"mcm","clk":"5348495212","pt":1646218198195,"mc":[{"id":"1.195453759","rc":[{"atb":[[11,0],[9.4,0]],"id":3805730}],"con":true,"img":false}]}
{"op":"mcm","clk":"5348495296","pt":1646218198901,"mc":[{"id":"1.195453759","rc":[{"atb":[[9.2,3.26],[10.5,23.75]],"id":3805730}],"con":true,"img":false}]}
{"op":"mcm","clk":"5348504440","pt":1646218266208,"mc":[{"id":"1.195453759","rc":[{"atb":[[4.9,0],[5.4,0]],"id":3805736},{"atb":[[18.5,0],[22,0]],"id":522753},{"atb":[[17,0],[14.5,0]],"id":522743}],"con":true,"img":false}]}
{"op":"mcm","clk":"5348504449","pt":1646218266260,"mc":[{"id":"1.195453759","rc":[{"atb":[[12,0],[14.5,0]],"id":3805755}],"con":true,"img":false}]}
{"op":"mcm","clk":"5348504523","pt":1646218266887,"mc":[{"id":"1.195453759","rc":[{"atb":[[5,53.21],[5.5,2.72]],"id":3805736},{"atb":[[19,3.26],[23,2.72]],"id":522753},{"atb":[[17.5,2.72],[15,3.26]],"id":522743}],"con":true,"img":false}]}
{"op":"mcm","clk":"5348504565","pt":1646218267096,"mc":[{"id":"1.195453759","rc":[{"atb":[[12.5,3.26],[15,2.72]],"id":3805755}],"con":true,"img":false}]}
{"op":"mcm","clk":"5348507066","pt":1646218288035,"mc":[{"id":"1.195453759","rc":[{"atl":[[390,2],[410,0]],"id":3805783}],"con":true,"img":false}]}
{"op":"mcm","clk":"5348511591","pt":1646218327090,"mc":[{"id":"1.195453759","rc":[{"atb":[[16,0],[13.5,0]],"id":522745}],"con":true,"img":false}]}
{"op":"mcm","clk":"5348511708","pt":1646218328077,"mc":[{"id":"1.195453759","rc":[{"atb":[[16.5,2.72],[14,3.26]],"id":522745}],"con":true,"img":false}]}
{"op":"mcm","clk":"5348515430","pt":1646218360417,"mc":[{"id":"1.195453759","rc":[{"atb":[[6.8,0],[5.9,0]],"id":522741},{"atb":[[9.2,24.36],[10.5,0]],"id":522742}],"con":true,"img":false}]}
{"op":"mcm","clk":"5348515515","pt":1646218361146,"mc":[{"id":"1.195453759","rc":[{"atb":[[7.2,2.72],[6.2,3.26]],"id":522741},{"atb":[[11,2.72],[9.4,3.26]],"id":522742}],"con":true,"img":false}]}
{"op":"mcm","clk":"5348519312","pt":1646218397387,"mc":[{"id":"1.195453759","rc":[{"atb":[[11.5,0],[14,0]],"id":522750}],"con":true,"img":false}]}
{"op":"mcm","clk":"5348519377","pt":1646218398059,"mc":[{"id":"1.195453759","rc":[{"atb":[[12,3.26],[14.5,2.72]],"id":522750}],"con":true,"img":false}]}
{"op":"mcm","clk":"5348535917","pt":1646218558910,"mc":[{"id":"1.195453759","rc":[{"atb":[[9.2,0],[10.5,21.03]],"id":3805730}],"con":true,"img":false}]}
{"op":"mcm","clk":"5348536010","pt":1646218559839,"mc":[{"id":"1.195453759","rc":[{"atb":[[9.6,3.26],[11.5,2.72]],"id":3805730}],"con":true,"img":false}]}
{"op":"mcm","clk":"5348541310","pt":1646218619922,"mc":[{"id":"1.195453759","rc":[{"atb":[[17.5,0],[15,0]],"id":522743}],"con":true,"img":false}]}
{"op":"mcm","clk":"5348541389","pt":1646218620593,"mc":[{"id":"1.195453759","rc":[{"atb":[[16,3.26]],"id":522743}],"con":true,"img":false}]}
{"op":"mcm","clk":"5348541406","pt":1646218620802,"mc":[{"id":"1.195453759","rc":[{"atb":[[18.5,2.72]],"id":522743}],"con":true,"img":false}]}
{"op":"mcm","clk":"5348546052","pt":1646218675261,"mc":[{"id":"1.195453759","rc":[{"atb":[[16.5,0],[14,0]],"id":522745}],"con":true,"img":false}]}
{"op":"mcm","clk":"5348546097","pt":1646218675982,"mc":[{"id":"1.195453759","rc":[{"atb":[[17.5,2.72]],"id":522745}],"con":true,"img":false}]}
{"op":"mcm","clk":"5348546104","pt":1646218676095,"mc":[{"id":"1.195453759","rc":[{"atb":[[15,3.26]],"id":522745}],"con":true,"img":false}]}
{"op":"mcm","clk":"5348552813","pt":1646218754912,"mc":[{"id":"1.195453759","rc":[{"atb":[[4,24.98],[3.5,0]],"id":3805783},{"atl":[[380,2],[390,0]],"id":3805783},{"atl":[[570,0],[560,2]],"id":3805755},{"atb":[[2.66,0],[2.78,56.18]],"id":522746},{"atl":[[140,0],[120,2]],"id":522746},{"atb":[[3.1,47.62],[2.94,0]],"id":3805736},{"atl":[[630,0],[620,2]],"id":522747},{"atl":[[470,2],[480,0]],"id":522749},{"atb":[[5.5,0],[6,20]],"id":522750},{"atl":[[540,0],[530,2]],"id":522750},{"atl":[[350,2],[360,0]],"id":522752},{"atl":[[450,2],[470,0]],"id":3805730},{"atl":[[880,2],[910,0]],"id":522753},{"atl":[[490,2],[510,0]],"id":522741},{"atl":[[410,2],[420,0]],"id":522742},{"atl":[[920,2]],"id":522743},{"atl":[[670,0],[640,2]],"id":522745}],"con":true,"img":false}]}
{"op":"mcm","clk":"5348552825","pt":1646218754956,"mc":[{"id":"1.195453759","rc":[{"atl":[[980,0]],"id":522743}],"con":true,"img":false}]}
{"op":"mcm","clk":"5348552858","pt":1646218755277,"mc":[{"id":"1.195453759","rc":[{"atb":[[10.5,0],[13,0]],"id":3805783}],"con":true,"img":false}]}
{"op":"mcm","clk":"5348552913","pt":1646218756005,"mc":[{"id":"1.195453759","rc":[{"atb":[[11,3.26],[13.5,2.72]],"id":3805783}],"con":true,"img":false}]}
{"op":"mcm","clk":"5348556721","pt":1646218803062,"mc":[{"id":"1.195453759","rc":[{"atb":[[17,12.48],[11,3.27],[9.8,22.7],[13.5,2.72],[7.8,39.17]],"id":3805783},{"atl":[[380,0],[370,2]],"id":3805783},{"atb":[[8,28.54],[4.5,76.11],[2.32,0],[2.42,57.08],[5.5,44.4],[4.2,3.27],[4.7,2.72]],"id":3805746},{"atb":[[18,11.75],[10.5,21.03],[8.2,37],[12.5,3.27],[15,2.72]],"id":3805755},{"atb":[[3.45,81.55],[5.1,2.72],[4.6,3.27],[2.98,134.54],[4.4,58.76]],"id":522746},{"atb":[[5,53.22],[5.5,2.72],[3.25,118.39],[3.75,72.65]],"id":3805736},{"atl":[[230,2],[240,0]],"id":3805736},{"atb":[[9,24.97],[9.2,3.27],[5,66.6],[10.5,2.72],[6,39.96]],"id":522747},{"atl":[[610,2]],"id":522747},{"atb":[[5.7,42.51],[8.4,30.27],[9.4,2.72],[4.7,72]],"id":522749},{"atl":[[460,2],[470,0]],"id":522749},{"atb":[[16.5,12.88],[9.6,23.23],[12,3.27],[7.6,40.36],[14.5,2.72]],"id":522750},{"atb":[[9.6,3.27],[9,24.97],[11.5,2.72],[7,44.4],[15,14.27]],"id":522752},{"atb":[[9.6,3.27],[5.6,57.91],[7.2,32.22],[10.5,21.03],[11.5,2.72]],"id":3805730},{"atb":[[16.5,12.88],[19,3.27],[23,2.72],[11.5,25.37],[28,7.4]],"id":522753},{"atl":[[880,0],[870,2]],"id":522753},{"atb":[[7.2,2.72],[3.6,102.46],[6.2,3.27],[5.7,42.51],[4.2,62.43]],"id":522741},{"atb":[[3.6,0],[5.1,64.97],[3.85,35.09],[9.2,24.36],[6.2,38.42],[11,2.72],[9.4,3.27]],"id":522742},{"atb":[[16,3.27],[18.5,2.72],[9,33.3],[20,10.51],[12.5,26.07]],"id":522743},{"atb":[[17.5,2.72],[8.6,35.05],[19,11.1],[11.5,19.02],[15,3.27]],"id":522745}],"con":true,"img":false}]}
{"op":"mcm","clk":"5348556731","pt":1646218803124,"mc":[{"id":"1.195453759","rc":[{"atl":[[620,0]],"id":522747}],"con":true,"img":false}]}
{"op":"mcm","clk":"5348556769","pt":1646218803541,"mc":[{"id":"1.195453759","rc":[{"atb":[[11,0],[13.5,0]],"id":3805783}],"con":true,"img":false}]}
{"op":"mcm","clk":"5348556870","pt":1646218804542,"mc":[{"id":"1.195453759","rc":[{"atb":[[10.5,3.27],[13,2.72]],"id":3805783}],"con":true,"img":false}]}
{"op":"mcm","clk":"5348568683","pt":1646218923101,"mc":[{"id":"1.195453759","rc":[{"atb":[[4,0],[3.7,35.2]],"id":3805783},{"atb":[[2.66,60.24],[2.78,0]],"id":522746},{"atl":[[610,0],[620,2]],"id":522747}],"con":true,"img":false}]}
{"op":"mcm","clk":"5348568715","pt":1646218923417,"mc":[{"id":"1.195453759","rc":[{"atl":[[350,2],[370,0]],"id":3805783},{"atb":[[2.8,55.56],[2.42,0]],"id":3805746},{"atb":[[6.2,0],[4.2,30.98]],"id":3805755},{"atl":[[560,0],[480,2]],"id":3805755},{"atb":[[2.66,0],[3.5,40]],"id":522746},{"atb":[[3.1,0],[3.35,42.55]],"id":3805736},{"atb":[[8.2,13.89],[6.8,0]],"id":522747},{"atb":[[3.85,0],[4.9,25.64]],"id":522749},{"atb":[[6,0],[4.2,31.25]],"id":522750},{"atl":[[530,0],[480,2]],"id":522750},{"atb":[[3.35,0],[3.8,28.54]],"id":522752},{"atl":[[320,2],[450,0]],"id":3805730},{"atb":[[10,0],[7.8,14.71]],"id":522753},{"atl":[[630,2],[870,0]],"id":522753},{"atb":[[4,0],[4.7,27.03]],"id":522741},{"atl":[[450,2],[490,0]],"id":522741},{"atb":[[3.85,0],[3.5,40]],"id":522742},{"atl":[[340,2],[410,0]],"id":522742},{"atb":[[12.5,17.37],[7,16.67]],"id":522743},{"atl":[[570,2],[920,0]],"id":522743},{"atl":[[520,2],[640,0]],"id":522745}],"con":true,"img":false}]}
{"op":"mcm","clk":"5348568754","pt":1646218923728,"mc":[{"id":"1.195453759","rc":[{"atb":[[4.2,0],[4.7,0]],"id":3805746},{"atb":[[9.6,0],[11.5,0]],"id":522752},{"atb":[[9.6,0],[11.5,0]],"id":3805730}],"con":true,"img":false}]}
{"op":"mcm","clk":"5348568867","pt":1646218924424,"mc":[{"id":"1.195453759","rc":[{"atb":[[6.4,2.72],[5.7,3.27]],"id":3805746},{"atb":[[11,3.27],[13.5,2.72]],"id":522752},{"atb":[[9.2,3.27],[10.5,23.75]],"id":3805730}],"con":true,"img":false}]}
{"op":"mcm","clk":"5348571761","pt":1646218952419,"mc":[{"id":"1.195453759","rc":[{"atb":[[3.7,0],[4.7,27.03]],"id":3805783},{"atl":[[520,2],[620,0]],"id":522747}],"con":true,"img":false}]}
{"op":"mcm","clk":"5348571786","pt":1646218952760,"mc":[{"id":"1.195453759","rc":[{"atb":[[4.9,25.64],[4.2,0]],"id":3805755},{"atl":[[450,2],[480,0]],"id":3805755},{"atb":[[4,33.33],[3.5,0]],"id":522746},{"atb":[[3.35,0]],"id":3805736},{"atl":[[290,2],[320,0]],"id":3805730},{"atl":[[420,2],[450,0]],"id":522741},{"atb":[[8.6,13.16],[7,0]],"id":522743},{"atl":[[540,2],[570,0]],"id":522743},{"atl":[[520,0],[500,2]],"id":522745}],"con":true,"img":false}]}
{"op":"mcm","clk":"5348571795","pt":1646218952866,"mc":[{"id":"1.195453759","rc":[{"atb":[[2.8,0],[3.1,47.62]],"id":3805746},{"atb":[[3.8,35.71]],"id":3805736},{"atb":[[4.9,0],[5.9,20.41]],"id":522749},{"atb":[[5,25],[4.2,0]],"id":522750},{"atl":[[450,2],[480,0]],"id":522750},{"atb":[[4.3,28.54],[3.8,0]],"id":522752},{"atb":[[9.6,11.63],[7.8,0]],"id":522753},{"atl":[[590,2],[630,0]],"id":522753},{"atb":[[4,33.33],[3.5,0]],"id":522742},{"atl":[[320,2],[340,0]],"id":522742}],"con":true,"img":false}]}
{"op":"mcm","clk":"5348585991","pt":1646219087190,"mc":[{"id":"1.195453759","rc":[{"atb":[[5.1,0],[4.6,0]],"id":522746}],"con":true,"img":false}]}
{"op":"mcm","clk":"5348586074","pt":1646219087968,"mc":[{"id":"1.195453759","rc":[{"atb":[[5.2,2.72],[4.7,3.27]],"id":522746}],"con":true,"img":false}]}
{"op":"mcm","clk":"5348601682","pt":1646219215272,"mc":[{"id":"1.195453759","rc":[{"atl":[[350,0],[340,2]],"id":3805783},{"atl":[[460,0],[450,2]],"id":522749},{"atl":[[280,2],[290,0]],"id":3805730},{"atl":[[590,0],[580,2]],"id":522753}],"con":true,"img":false}]}
{"op":"mcm","clk":"5348601717","pt":1646219215580,"mc":[{"id":"1.195453759","rc":[{"atb":[[9.2,0],[10.5,21.03]],"id":3805730}],"con":true,"img":false}]}
{"op":"mcm","clk":"5348601808","pt":1646219216360,"mc":[{"id":"1.195453759","rc":[{"atb":[[9,3.27],[10,2.72]],"id":3805730}],"con":true,"img":false}]}
{"op":"mcm","clk":"5348616277","pt":1646219335276,"mc":[{"id":"1.195453759","rc":[{"atb":[[3.8,0],[3.5,40]],"id":3805736},{"atb":[[5.3,23.26]],"id":522749},{"atb":[[9.6,0],[8.4,13.51]],"id":522753}],"con":true,"img":false}]}
{"op":"mcm","clk":"5348616288","pt":1646219335341,"mc":[{"id":"1.195453759","rc":[{"atb":[[5.9,0]],"id":522749}],"con":true,"img":false}]}
{"op":"mcm","clk":"5348618116","pt":1646219349872,"mc":[{"id":"1.195453759","rc":[{"atl":[[410,2],[420,0]],"id":522741},{"atb":[[4,0],[4.6,22.2]],"id":522745}],"con":true,"img":false}]}
{"op":"mcm","clk":"5348618153","pt":1646219350181,"mc":[{"id":"1.195453759","rc":[{"atb":[[6.4,0],[5.7,0]],"id":3805746}],"con":true,"img":false}]}
{"op":"mcm","clk":"5348618247","pt":1646219350980,"mc":[{"id":"1.195453759","rc":[{"atb":[[5.8,3.27],[6.6,2.72]],"id":3805746}],"con":true,"img":false}]}
{"op":"mcm","clk":"5348619331","pt":1646219360508,"mc":[{"id":"1.195453759","rc":[{"atb":[[3.5,0],[3.75,109.01]],"id":3805736},{"atb":[[9.6,11.63],[8.4,0]],"id":522753}],"con":true,"img":false}]}
{"op":"mcm","clk":"5348694919","pt":1646219920760,"mc":[{"id":"1.195453759","rc":[{"atl":[[490,2],[500,0]],"id":522745}],"con":true,"img":false}]}
{"op":"mcm","clk":"5348694957","pt":1646219921025,"mc":[{"id":"1.195453759","rc":[{"atb":[[5.8,0],[6.6,0]],"id":3805746},{"atb":[[9,0],[10,0]],"id":3805730}],"con":true,"img":false}]}
{"op":"mcm","clk":"5348695054","pt":1646219921746,"mc":[{"id":"1.195453759","rc":[{"atb":[[5.8,3.27],[6.6,2.72]],"id":3805746},{"atb":[[9.2,3.27],[10.5,23.75]],"id":3805730}],"con":true,"img":false}]}
{"op":"mcm","clk":"5348699472","pt":1646219956606,"mc":[{"id":"1.195453759","rc":[{"atb":[[1.98,0],[2.16,55.99]],"id":3805730},{"atb":[[5.1,22.2],[4.6,0]],"id":522745}],"con":true,"img":false}]}
{"op":"mcm","clk":"5348701299","pt":1646219970846,"mc":[{"id":"1.195453759","rc":[{"atl":[[310,2]],"id":522742}],"con":true,"img":false}]}
{"op":"mcm","clk":"5348701312","pt":1646219970949,"mc":[{"id":"1.195453759","rc":[{"atl":[[320,0]],"id":522742}],"con":true,"img":false}]}
{"op":"mcm","clk":"5348718893","pt":1646220109042,"mc":[{"id":"1.195453759","rc":[{"atb":[[5.2,0],[4.7,0]],"id":522746},{"atb":[[8.4,27],[9.4,0]],"id":522749},{"atb":[[7.2,0],[6.2,0]],"id":522741},{"atb":[[11,0],[9.4,0]],"id":522742}],"con":true,"img":false}]}
{"op":"mcm","clk":"5348718931","pt":1646220109357,"mc":[{"id":"1.195453759","rc":[{"atb":[[5.8,0],[6.6,0]],"id":3805746}],"con":true,"img":false}]}
{"op":"mcm","clk":"5348718980","pt":1646220109774,"mc":[{"id":"1.195453759","rc":[{"atb":[[4.8,3.27],[5.3,2.72]],"id":522746}],"con":true,"img":false}]}
{"op":"mcm","clk":"5348718993","pt":1646220109875,"mc":[{"id":"1.195453759","rc":[{"atb":[[9.6,2.72],[8.6,3.27]],"id":522749},{"atb":[[6.8,2.72],[5.9,3.27]],"id":522741},{"atb":[[9.2,27.63],[10.5,2.72]],"id":522742}],"con":true,"img":false}]}
{"op":"mcm","clk":"5348719034","pt":1646220110127,"mc":[{"id":"1.195453759","rc":[{"atb":[[6.8,2.72],[5.9,3.27]],"id":3805746}],"con":true,"img":false}]}
{"op":"mcm","clk":"5348719187","pt":1646220111447,"mc":[{"id":"1.195453759","rc":[{"atb":[[5.3,0],[4.7,99.03]],"id":522749},{"atb":[[9.6,0],[8.4,13.51]],"id":522753},{"atb":[[8.6,0],[7,16.67]],"id":522743}],"con":true,"img":false}]}
{"op":"mcm","clk":"5348721451","pt":1646220128875,"mc":[{"id":"1.195453759","rc":[{"atb":[[5.2,23.81],[4.7,72]],"id":522749},{"atb":[[8.4,0],[9.4,11.9]],"id":522753}],"con":true,"img":false}]}
{"op":"mcm","clk":"5348726642","pt":1646220170125,"mc":[{"id":"1.195453759","rc":[{"atb":[[5,49.95],[5.5,0]],"id":3805736}],"con":true,"img":false}]}
{"op":"mcm","clk":"5348726728","pt":1646220170849,"mc":[{"id":"1.195453759","rc":[{"atb":[[5.6,2.72],[5.1,3.27]],"id":3805736}],"con":true,"img":false}]}
{"op":"mcm","clk":"5348736810","pt":1646220255162,"mc":[{"id":"1.195453759","rc":[{"atb":[[9.2,0],[10.5,21.03]],"id":3805730}],"con":true,"img":false}]}
{"op":"mcm","clk":"5348736910","pt":1646220256096,"mc":[{"id":"1.195453759","rc":[{"atb":[[9,3.27],[10,2.72]],"id":3805730}],"con":true,"img":false}]}
{"op":"mcm","clk":"5348748192","pt":1646220363241,"mc":[{"id":"1.195453759","rc":[{"atb":[[9,0],[10,0]],"id":3805730}],"con":true,"img":false}]}
{"op":"mcm","clk":"5348748282","pt":1646220363924,"mc":[{"id":"1.195453759","rc":[{"atb":[[9.2,3.27],[10.5,23.75]],"id":3805730}],"con":true,"img":false}]}
{"op":"mcm","clk":"5348771301","pt":1646220546423,"mc":[{"id":"1.195453759","rc":[{"atb":[[1.8,64.46],[2.16,0]],"id":3805730},{"atb":[[5.1,0],[5.8,20.83]],"id":522745}],"con":true,"img":false}]}
{"op":"mcm","clk":"5348775367","pt":1646220591142,"mc":[{"id":"1.195453759","rc":[{"atb":[[12.5,0],[15,0]],"id":3805755},{"atb":[[6.8,0],[5.9,0]],"id":522741},{"atb":[[9.2,24.36],[10.5,0]],"id":522742},{"atb":[[16,0],[18.5,0]],"id":522743}],"con":true,"img":false}]}
{"op":"mcm","clk":"5348775378","pt":1646220591198,"mc":[{"id":"1.195453759","rc":[{"atb":[[19,0],[23,0]],"id":522753}],"con":true,"img":false}]}
{"op":"mcm","clk":"5348775441","pt":1646220591791,"mc":[{"id":"1.195453759","rc":[{"atb":[[13,3.27],[15.5,2.72]],"id":3805755},{"atb":[[6.4,3.27],[7.4,2.72]],"id":522741},{"atb":[[11,2.72],[9.4,3.27]],"id":522742},{"atb":[[16.5,3.27],[19,2.72]],"id":522743}],"con":true,"img":false}]}
{"op":"mcm","clk":"5348775449","pt":1646220591884,"mc":[{"id":"1.195453759","rc":[{"atb":[[19.5,3.27],[24,2.72]],"id":522753}],"con":true,"img":false}]}
{"op":"mcm","clk":"5348805038","pt":1646220841544,"mc":[{"id":"1.195453759","rc":[{"atb":[[9.2,0],[10.5,21.03]],"id":3805730}],"con":true,"img":false}]}
{"op":"mcm","clk":"5348805136","pt":1646220842238,"mc":[{"id":"1.195453759","rc":[{"atb":[[9,3.27],[10,2.72]],"id":3805730}],"con":true,"img":false}]}
{"op":"mcm","clk":"5348805403","pt":1646220844548,"mc":[{"id":"1.195453759","rc":[{"atb":[[6.8,0],[5.9,0]],"id":3805746}],"con":true,"img":false}]}
{"op":"mcm","clk":"5348805473","pt":1646220845242,"mc":[{"id":"1.195453759","rc":[{"atb":[[6,3.27],[7,2.72]],"id":3805746}],"con":true,"img":false}]}
{"op":"mcm","clk":"5348806230","pt":1646220851163,"mc":[{"id":"1.195453759","rc":[{"atb":[[6,0],[7,0]],"id":3805746}],"con":true,"img":false}]}
{"op":"mcm","clk":"5348806314","pt":1646220851851,"mc":[{"id":"1.195453759","rc":[{"atb":[[6.8,2.72],[5.9,3.27]],"id":3805746}],"con":true,"img":false}]}
{"op":"mcm","clk":"5348807113","pt":1646220858372,"mc":[{"id":"1.195453759","rc":[{"atl":[[570,2],[580,0]],"id":522753},{"atl":[[490,0],[480,2]],"id":522745}],"con":true,"img":false}]}
{"op":"mcm","clk":"5348807313","pt":1646220860458,"mc":[{"id":"1.195453759","rc":[{"atl":[[300,2],[310,0]],"id":522742}],"con":true,"img":false}]}
{"op":"mcm","clk":"5348811106","pt":1646220891518,"mc":[{"id":"1.195453759","rc":[{"atb":[[4.8,0],[5.3,0]],"id":522746},{"atb":[[5.6,0],[5.1,0]],"id":3805736},{"atb":[[9.2,0],[10.5,0]],"id":522747},{"atb":[[6.4,0],[7.4,0]],"id":522741}],"con":true,"img":false}]}
{"op":"mcm","clk":"5348811121","pt":1646220891682,"mc":[{"id":"1.195453759","rc":[{"atb":[[4,0],[4.1,32.26]],"id":522746},{"atb":[[9.6,0],[8.6,0]],"id":522749}],"con":true,"img":false}]}
{"op":"mcm","clk":"5348811186","pt":1646220892214,"mc":[{"id":"1.195453759","rc":[{"atb":[[5.8,2.72],[5.3,3.27]],"id":3805736},{"atb":[[7.6,2.72],[6.6,3.27]],"id":522741}],"con":true,"img":false}]}
{"op":"mcm","clk":"5348811201","pt":1646220892309,"mc":[{"id":"1.195453759","rc":[{"atb":[[4.9,3.27],[5.4,2.72]],"id":522746},{"atb":[[11,2.72],[9.4,3.27]],"id":522747}],"con":true,"img":false}]}
{"op":"mcm","clk":"5348811227","pt":1646220892520,"mc":[{"id":"1.195453759","rc":[{"atb":[[9,3.27],[10,2.72]],"id":522749}],"con":true,"img":false}]}
{"op":"mcm","clk":"5348811461","pt":1646220894430,"mc":[{"id":"1.195453759","rc":[{"atb":[[17,0],[9.8,0],[7.8,0]],"id":3805783},{"atb":[[8,0],[4.5,0],[5.5,0]],"id":3805746},{"atb":[[18,0],[10.5,0],[8.2,0]],"id":3805755},{"atb":[[3.45,0],[2.98,0],[4.4,0]],"id":522746},{"atb":[[5,0],[3.25,0],[3.75,36.36]],"id":3805736},{"atb":[[9,0],[5,0],[6,0]],"id":522747},{"atb":[[5.7,0],[8.4,0],[4.7,0]],"id":522749},{"atb":[[16.5,0],[9.6,0],[7.6,0]],"id":522750},{"atb":[[9,0],[7,0],[15,0]],"id":522752},{"atb":[[5.6,0],[7.2,0],[10.5,0]],"id":3805730},{"atb":[[16.5,0],[11.5,0],[28,0]],"id":522753},{"atb":[[3.6,0],[5.7,0],[4.2,0]],"id":522741},{"atb":[[5.1,0],[9.2,0],[6.2,0]],"id":522742},{"atb":[[9,0],[20,0],[12.5,0]],"id":522743},{"atb":[[8.6,0],[19,0],[11.5,0]],"id":522745}],"con":true,"img":false}]}
{"op":"mcm","clk":"5348811723","pt":1646220896599,"mc":[{"id":"1.195453759","rc":[{"atb":[[11,0],[13.5,0]],"id":522752}],"con":true,"img":false}]}
{"op":"mcm","clk":"5348811811","pt":1646220897300,"mc":[{"id":"1.195453759","rc":[{"atb":[[10.5,3.27],[13,2.72]],"id":522752}],"con":true,"img":false}]}
{"op":"mcm","clk":"5348812740","pt":1646220905102,"mc":[{"id":"1.195453759","rc":[{"atl":[[270,2],[280,0]],"id":3805730}],"con":true,"img":false}]}
{"op":"mcm","clk":"5348813076","pt":1646220908527,"mc":[{"id":"1.195453759","rc":[{"atb":[[5.7,56.68],[4.7,99.03],[9.4,15.86]],"id":3805783},{"atb":[[5.6,28.95],[3.8,95.14],[3.3,115.82]],"id":3805746},{"atb":[[10,14.8],[5,66.6],[6,53.28]],"id":3805755},{"atb":[[2.86,143.23],[2.66,160.48],[3.65,50.26]],"id":522746},{"atb":[[2.9,140.21],[3.75,84.79],[2.7,156.7]],"id":3805736},{"atb":[[3.6,102.46],[6.4,24.66],[4.2,83.25]],"id":522747},{"atb":[[5.8,27.75],[3.4,111],[3.9,91.86]],"id":522749},{"atb":[[9.8,15.13],[4.9,68.3],[5.9,54.37]],"id":522750},{"atb":[[5.6,57.91],[9.2,16.24],[4.6,74]],"id":522752},{"atb":[[6.2,25.61],[4.1,85.93],[3.55,104.47]],"id":3805730},{"atb":[[16,8.87],[6.4,49.33],[8.4,35.99]],"id":522753},{"atb":[[4,44.4],[2.8,148],[3,133.2]],"id":522741},{"atb":[[4,122.12],[6,26.64],[3.5,106.56]],"id":522742},{"atb":[[5.3,61.95],[11.5,12.68],[6.6,47.57]],"id":522743},{"atb":[[5.1,64.97],[10.5,14.02],[6.2,51.23]],"id":522745}],"con":true,"img":false}]}
{"op":"mcm","clk":"5348813095","pt":1646220908736,"mc":[{"id":"1.195453759","rc":[{"atb":[[1.89,64.46]],"id":3805730}],"con":true,"img":false}]}
{"op":"mcm","clk":"5348813104","pt":1646220908836,"mc":[{"id":"1.195453759","rc":[{"atb":[[1.8,0]],"id":3805730}],"con":true,"img":false}]}
{"op":"mcm","clk":"5348813891","pt":1646220915723,"mc":[{"id":"1.195453759","rc":[{"atb":[[11,0],[9.4,0]],"id":522742}],"con":true,"img":false}]}
{"op":"mcm","clk":"5348813961","pt":1646220916414,"mc":[{"id":"1.195453759","rc":[{"atb":[[9.2,3.27],[10.5,2.72]],"id":522742}],"con":true,"img":false}]}
{"op":"mcm","clk":"5348814422","pt":1646220920426,"mc":[{"id":"1.195453759","rc":[{"atl":[[300,0],[290,2]],"id":522742}],"con":true,"img":false}]}
{"op":"mcm","clk":"5348814454","pt":1646220920739,"mc":[{"id":"1.195453759","rc":[{"atb":[[6.8,0],[5.9,0]],"id":3805746}],"con":true,"img":false}]}
{"op":"mcm","clk":"5348814553","pt":1646220921420,"mc":[{"id":"1.195453759","rc":[{"atb":[[5.8,3.27],[6.6,2.72]],"id":3805746}],"con":true,"img":false}]}
{"op":"mcm","clk":"5348816526","pt":1646220937757,"mc":[{"id":"1.195453759","rc":[{"atb":[[9,0],[10,0]],"id":3805730}],"con":true,"img":false}]}
{"op":"mcm","clk":"5348816653","pt":1646220938453,"mc":[{"id":"1.195453759","rc":[{"atb":[[10.5,2.72]],"id":3805730}],"con":true,"img":false}]}
{"op":"mcm","clk":"5348816679","pt":1646220938660,"mc":[{"id":"1.195453759","rc":[{"atb":[[9.2,3.27]],"id":3805730}],"con":true,"img":false}]}
{"op":"mcm","clk":"5348816699","pt":1646220938768,"mc":[{"id":"1.195453759","rc":[{"atl":[[280,2],[290,0]],"id":522742}],"con":true,"img":false}]}
{"op":"mcm","clk":"5348818153","pt":1646220949973,"mc":[{"id":"1.195453759","rc":[{"atb":[[9.2,0],[10.5,0]],"id":522742}],"con":true,"img":false}]}
{"op":"mcm","clk":"5348818233","pt":1646220950695,"mc":[{"id":"1.195453759","rc":[{"atb":[[9,3.27],[10,2.72]],"id":522742}],"con":true,"img":false}]}
{"op":"mcm","clk":"5348821954","pt":1646220982736,"mc":[{"id":"1.195453759","rc":[{"atb":[[6.6,0]],"id":522741}],"con":true,"img":false}]}
{"op":"mcm","clk":"5348821973","pt":1646220982903,"mc":[{"id":"1.195453759","rc":[{"atb":[[5.3,0]],"id":3805736},{"atb":[[7.6,0]],"id":522741}],"con":true,"img":false}]}
{"op":"mcm","clk":"5348821983","pt":1646220983005,"mc":[{"id":"1.195453759","rc":[{"atb":[[5.8,0]],"id":3805736}],"con":true,"img":false}]}
{"op":"mcm","clk":"5348821994","pt":1646220983108,"mc":[{"id":"1.195453759","rc":[{"atb":[[4.6,27.78],[4.7,0]],"id":522741}],"con":true,"img":false}]}
{"op":"mcm","clk":"5348822037","pt":1646220983427,"mc":[{"id":"1.195453759","rc":[{"atb":[[6.8,3.27]],"id":522741}],"con":true,"img":false}]}
{"op":"mcm","clk":"5348822070","pt":1646220983694,"mc":[{"id":"1.195453759","rc":[{"atb":[[5.6,3.27],[6.2,2.72]],"id":3805736},{"atb":[[7.8,2.72]],"id":522741}],"con":true,"img":false}]}
{"op":"mcm","clk":"5348823270","pt":1646220994734,"mc":[{"id":"1.195453759","rc":[{"atb":[[4.9,0],[5.4,0]],"id":522746}],"con":true,"img":false}]}
{"op":"mcm","clk":"5348823297","pt":1646220994939,"mc":[{"id":"1.195453759","rc":[{"atb":[[4,33.33],[4.1,0]],"id":522746}],"con":true,"img":false}]}
{"op":"mcm","clk":"5348823355","pt":1646220995416,"mc":[{"id":"1.195453759","rc":[{"atb":[[5,3.27],[5.5,2.72]],"id":522746}],"con":true,"img":false}]}
{"op":"mcm","clk":"5348823624","pt":1646220997529,"mc":[{"id":"1.195453759","rc":[{"atb":[[5.8,0],[6.6,0]],"id":3805746},{"atb":[[9.2,0],[10.5,0]],"id":3805730}],"con":true,"img":false}]}
{"op":"mcm","clk":"5348823727","pt":1646220998226,"mc":[{"id":"1.195453759","rc":[{"atb":[[6.4,2.72],[5.7,3.27]],"id":3805746},{"atb":[[9,3.27],[10,2.72]],"id":3805730}],"con":true,"img":false}]}
{"op":"mcm","clk":"5348825597","pt":1646221013152,"mc":[{"id":"1.195453759","rc":[{"atb":[[5.7,0],[9.4,0],[4.7,27.03]],"id":3805783},{"atb":[[5.6,0],[3.8,0],[3.3,0]],"id":3805746},{"atb":[[10,0],[5,0],[6,0]],"id":3805755},{"atb":[[2.86,0],[2.66,0],[3.65,0]],"id":522746},{"atb":[[2.9,0],[3.75,36.36],[2.7,0]],"id":3805736},{"atb":[[3.6,0],[6.4,0],[4.2,0]],"id":522747},{"atb":[[5.8,0],[3.4,0],[3.9,0]],"id":522749},{"atb":[[9.8,0],[4.9,0],[5.9,0]],"id":522750},{"atb":[[5.6,0],[9.2,0],[4.6,0]],"id":522752},{"atb":[[6.2,0],[4.1,0],[3.55,0]],"id":3805730},{"atb":[[16,0],[6.4,0],[8.4,0]],"id":522753},{"atb":[[4,0],[2.8,0],[3,0]],"id":522741},{"atb":[[4,33.33],[6,0],[3.5,0]],"id":522742},{"atb":[[5.3,0],[11.5,0],[6.6,0]],"id":522743},{"atb":[[5.1,0],[10.5,0],[6.2,0]],"id":522745}],"con":true,"img":false}]}
{"op":"mcm","clk":"5348826313","pt":1646221019097,"mc":[{"id":"1.195453759","rc":[{"atb":[[9.8,15.13],[4.9,68.3],[5.9,54.37]],"id":3805783},{"atb":[[5.3,30.97],[3.15,123.9],[3.65,100.52]],"id":3805746},{"atb":[[5.7,56.68],[9.4,15.86],[4.7,72]],"id":3805755},{"atb":[[2.88,141.7],[3.7,49.33],[2.68,158.57]],"id":522746},{"atb":[[2.88,141.7],[3.7,49.33],[2.68,158.57]],"id":3805736},{"atb":[[3.6,102.46],[6.4,24.66],[4.2,83.25]],"id":522747},{"atb":[[4.5,76.11],[7,22.19],[3.75,96.87]],"id":522749},{"atb":[[5.7,56.68],[9.4,15.86],[4.7,72]],"id":522750},{"atb":[[9.8,15.13],[4.9,68.3],[5.9,54.37]],"id":522752},{"atb":[[5.8,27.75],[3.4,111],[3.9,91.86]],"id":3805730},{"atb":[[17,8.32],[6.8,45.93],[8.8,34.15]],"id":522753},{"atb":[[2.82,146.37],[4.1,42.96],[3.05,129.95]],"id":522741},{"atb":[[5.8,27.75],[3.4,111],[3.9,91.86]],"id":522742},{"atb":[[6.4,49.33],[11,13.32],[5.2,63.42]],"id":522743},{"atb":[[5.3,61.95],[11.5,12.68],[6.6,47.57]],"id":522745}],"con":true,"img":false}]}
{"op":"mcm","clk":"5348826876","pt":1646221023973,"mc":[{"id":"1.195453759","rc":[{"atb":[[11,0],[9.4,0]],"id":522747},{"atb":[[9,0],[10,0]],"id":522749}],"con":true,"img":false}]}
{"op":"mcm","clk":"5348826900","pt":1646221024177,"mc":[{"id":"1.195453759","rc":[{"atb":[[5.5,22.22],[5.2,0]],"id":522749}],"con":true,"img":false}]}
{"op":"mcm","clk":"5348827001","pt":1646221024966,"mc":[{"id":"1.195453759","rc":[{"atb":[[4.9,0],[5.7,77.96]],"id":3805755},{"atb":[[9.6,3.27],[8.2,0],[11.5,2.72],[7.4,15.62]],"id":522747},{"atb":[[9.2,3.27],[10.5,2.72]],"id":522749},{"atb":[[1.89,0],[2.52,64.46]],"id":3805730},{"atl":[[410,0],[400,2]],"id":522741},{"atb":[[3.85,29.99],[7,0]],"id":522743}],"con":true,"img":false}]}
{"op":"mcm","clk":"5348829612","pt":1646221046400,"mc":[{"id":"1.195453759","rc":[{"atb":[[9,0],[10,0]],"id":522742}],"con":true,"img":false}]}
{"op":"mcm","clk":"5348829702","pt":1646221047094,"mc":[{"id":"1.195453759","rc":[{"atb":[[9.2,3.27],[10.5,2.72]],"id":522742}],"con":true,"img":false}]}
{"op":"mcm","clk":"5348831607","pt":1646221063391,"mc":[{"id":"1.195453759","rc":[{"atb":[[9.2,0],[10.5,0]],"id":522742}],"con":true,"img":false}]}
{"op":"mcm","clk":"5348831719","pt":1646221064385,"mc":[{"id":"1.195453759","rc":[{"atb":[[9,3.27],[10,2.72]],"id":522742}],"con":true,"img":false}]}
{"op":"mcm","clk":"5348831769","pt":1646221064803,"mc":[{"id":"1.195453759","rc":[{"atb":[[6.8,0]],"id":522741}],"con":true,"img":false}]}
{"op":"mcm","clk":"5348831808","pt":1646221065069,"mc":[{"id":"1.195453759","rc":[{"atb":[[7.8,0]],"id":522741}],"con":true,"img":false}]}
{"op":"mcm","clk":"5348831821","pt":1646221065173,"mc":[{"id":"1.195453759","rc":[{"atb":[[4.6,0],[4.2,31.25]],"id":522741}],"con":true,"img":false}]}
{"op":"mcm","clk":"5348831849","pt":1646221065491,"mc":[{"id":"1.195453759","rc":[{"atb":[[7,3.27]],"id":522741}],"con":true,"img":false}]}
{"op":"mcm","clk":"5348831891","pt":1646221065907,"mc":[{"id":"1.195453759","rc":[{"atb":[[8,2.72]],"id":522741}],"con":true,"img":false}]}
{"op":"mcm","clk":"5348832603","pt":1646221072224,"mc":[{"id":"1.195453759","rc":[{"atb":[[9.8,0],[4.9,0],[5.9,0]],"id":3805783},{"atb":[[5.3,0],[3.15,0],[3.65,0]],"id":3805746},{"atb":[[5.7,21.28],[9.4,0],[4.7,0]],"id":3805755},{"atb":[[2.88,0],[3.7,0],[2.68,0]],"id":522746},{"atb":[[2.88,0],[3.7,0],[2.68,0]],"id":3805736},{"atb":[[3.6,0],[6.4,0],[4.2,0]],"id":522747},{"atb":[[4.5,0],[7,0],[3.75,0]],"id":522749},{"atb":[[5.7,0],[9.4,0],[4.7,0]],"id":522750},{"atb":[[9.8,0],[4.9,0],[5.9,0]],"id":522752},{"atb":[[5.8,0],[3.4,0],[3.9,0]],"id":3805730},{"atb":[[17,0],[6.8,0],[8.8,0]],"id":522753},{"atb":[[2.82,0],[4.1,0],[3.05,0]],"id":522741},{"atb":[[5.8,0],[3.4,0],[3.9,0]],"id":522742},{"atb":[[6.4,0],[11,0],[5.2,0]],"id":522743},{"atb":[[5.3,0],[11.5,0],[6.6,0]],"id":522745}],"con":true,"img":false}]}
{"op":"mcm","clk":"5348833036","pt":1646221075597,"mc":[{"id":"1.195453759","rc":[{"atb":[[5,0]],"id":522746}],"con":true,"img":false}]}
{"op":"mcm","clk":"5348833068","pt":1646221075915,"mc":[{"id":"1.195453759","rc":[{"atb":[[5.5,0]],"id":522746}],"con":true,"img":false}]}
{"op":"mcm","clk":"5348833094","pt":1646221076117,"mc":[{"id":"1.195453759","rc":[{"atb":[[4,0],[3.9,34.48]],"id":522746}],"con":true,"img":false}]}
{"op":"mcm","clk":"5348833135","pt":1646221076396,"mc":[{"id":"1.195453759","rc":[{"atb":[[5.1,3.27]],"id":522746}],"con":true,"img":false}]}
{"op":"mcm","clk":"5348833185","pt":1646221076813,"mc":[{"id":"1.195453759","rc":[{"atb":[[5.6,2.72]],"id":522746}],"con":true,"img":false}]}
{"op":"mcm","clk":"5348833382","pt":1646221078391,"mc":[{"id":"1.195453759","rc":[{"atb":[[6.4,0],[5.7,0]],"id":3805746}],"con":true,"img":false}]}
{"op":"mcm","clk":"5348833520","pt":1646221079503,"mc":[{"id":"1.195453759","rc":[{"atb":[[5.8,3.27],[6.6,2.72]],"id":3805746}],"con":true,"img":false}]}
{"op":"mcm","clk":"5348833898","pt":1646221082619,"mc":[{"id":"1.195453759","rc":[{"atb":[[9.8,15.13],[4.9,68.3],[5.9,54.37]],"id":3805783},{"atb":[[5.3,30.97],[3.15,123.9],[3.65,100.52]],"id":3805746},{"atb":[[5.7,77.96],[9.4,15.86],[4.7,72]],"id":3805755},{"atb":[[2.88,141.7],[3.7,49.33],[2.68,158.57]],"id":522746},{"atb":[[2.88,141.7],[3.7,49.33],[2.68,158.57]],"id":3805736},{"atb":[[3.6,102.46],[6.4,24.66],[4.2,83.25]],"id":522747},{"atb":[[4.5,76.11],[7,22.19],[3.75,96.87]],"id":522749},{"atb":[[5.7,56.68],[9.4,15.86],[4.7,72]],"id":522750},{"atb":[[9.8,15.13],[4.9,68.3],[5.9,54.37]],"id":522752},{"atb":[[5.8,27.75],[3.4,111],[3.9,91.86]],"id":3805730},{"atb":[[17,8.32],[6.8,45.93],[8.8,34.15]],"id":522753},{"atb":[[2.82,146.37],[4.1,42.96],[3.05,129.95]],"id":522741},{"atb":[[5.8,27.75],[3.4,111],[3.9,91.86]],"id":522742},{"atb":[[6.4,49.33],[11,13.32],[5.2,63.42]],"id":522743},{"atb":[[5.3,61.95],[11.5,12.68],[6.6,47.57]],"id":522745}],"con":true,"img":false}]}
{"op":"mcm","clk":"5348834206","pt":1646221085286,"mc":[{"id":"1.195453759","rc":[{"atb":[[5.8,0]],"id":3805746}],"con":true,"img":false}]}
{"op":"mcm","clk":"5348834238","pt":1646221085597,"mc":[{"id":"1.195453759","rc":[{"atb":[[6.6,0]],"id":3805746}],"con":true,"img":false}]}
{"op":"mcm","clk":"5348834329","pt":1646221086332,"mc":[{"id":"1.195453759","rc":[{"atb":[[5.7,3.27]],"id":3805746}],"con":true,"img":false}]}
{"op":"mcm","clk":"5348834353","pt":1646221086595,"mc":[{"id":"1.195453759","rc":[{"atb":[[6.4,2.72]],"id":3805746}],"con":true,"img":false}]}
{"op":"mcm","clk":"5348834776","pt":1646221090006,"mc":[{"id":"1.195453759","rc":[{"atb":[[10.5,0],[13,0]],"id":522752}],"con":true,"img":false}]}
{"op":"mcm","clk":"5348834879","pt":1646221090825,"mc":[{"id":"1.195453759","rc":[{"atb":[[11,3.27],[13.5,2.72]],"id":522752}],"con":true,"img":false}]}
{"op":"mcm","clk":"5348840908","pt":1646221140675,"mc":[{"id":"1.195453759","rc":[{"atb":[[5.3,39.89]],"id":3805746},{"atl":[[340,3.61]],"id":3805746},{"atb":[[9.4,24.77]],"id":3805755},{"atl":[[470,2.61]],"id":3805755},{"atb":[[20,9.9],[24,4.95]],"id":522743},{"atl":[[46,4.95],[60,9.9]],"id":522743}],"con":true,"img":false}]}
{"op":"mcm","clk":"5348840930","pt":1646221140784,"mc":[{"id":"1.195453759","rc":[{"atb":[[10.5,8.22],[9.8,24.05],[9.4,9.9]],"id":3805783},{"atl":[[330,0.47],[360,3.41],[23,4.95],[27,9.9]],"id":3805783},{"atb":[[5.3,44.84],[4.9,9.9]],"id":3805746},{"atl":[[310,0.51],[12.5,4.95],[14.5,9.9]],"id":3805746},{"atb":[[12,9.9],[14,4.95],[15.5,11.64]],"id":3805755},{"atl":[[32,9.9],[27,4.95],[440,0.35]],"id":3805755},{"atb":[[5.6,11.64],[6.2,9.9],[3.9,43.39],[7,4.95]],"id":522746},{"atl":[[140,8.79],[11.5,4.95],[13.5,9.9],[110,1.45]],"id":522746},{"atb":[[8,4.95],[7.2,9.9],[6.2,11.64],[3.75,45.27]],"id":3805736},{"atl":[[13,4.95],[220,0.72],[15,9.9],[250,4.92]],"id":3805736},{"atb":[[16,9.9],[18,4.95],[7.4,24.53],[12,8.91]],"id":522747},{"atl":[[540,2.27],[42,4.95],[50,9.9],[510,0.31]],"id":522747},{"atb":[[13,9.9],[7,31.11],[15,4.95]],"id":522749},{"atl":[[38,9.9],[470,2.61],[30,4.95]],"id":522749},{"atb":[[11,9.9],[13,4.95],[14.5,11.64],[9.4,24.77]],"id":522750},{"atl":[[26,4.95],[440,0.35],[470,2.61],[30,9.9]],"id":522750},{"atb":[[9,9.9],[9.8,29]],"id":522752},{"atl":[[340,0.46],[22,4.95],[370,3.31],[26,9.9]],"id":522752},{"atb":[[5.8,36.66],[8.2,4.95],[7.4,9.9]],"id":3805730},{"atl":[[260,0.61],[290,4.24],[13,4.95],[15,9.9]],"id":3805730},{"atb":[[17,17.24],[25,6.6],[26,9.9],[30,4.95]],"id":522753},{"atl":[[560,0.28],[590,2.07],[80,9.9],[60,4.95]],"id":522753},{"atb":[[8.2,8.91],[4.2,40.16]],"id":522741},{"atl":[[390,0.4],[420,2.92]],"id":522741},{"atb":[[5.8,36.66],[7.8,4.95],[7,9.9]],"id":522742},{"atl":[[270,0.58],[300,4.09],[13,4.95],[15,9.9]],"id":522742},{"atb":[[19,11.53],[11,22.23]],"id":522743},{"atl":[[530,0.29],[560,2.19]],"id":522743},{"atb":[[16,9.9],[17.5,11.64],[18,4.95],[11.5,21.6]],"id":522745},{"atl":[[34,4.95],[42,9.9],[470,0.33],[500,2.45]],"id":522745}],"con":true,"img":false}]}
{"op":"mcm","clk":"5348840940","pt":1646221140890,"mc":[{"id":"1.195453759","rc":[{"atl":[[320,0],[330,2]],"id":3805746},{"atl":[[540,0],[150,2]],"id":522743}],"con":true,"img":false}]}
{"op":"mcm","clk":"5348840954","pt":1646221140994,"mc":[{"id":"1.195453759","rc":[{"atl":[[340,0],[42,2.44]],"id":3805783},{"atl":[[75,2],[450,0]],"id":3805755},{"atl":[[21,5],[120,0]],"id":522746},{"atl":[[230,0]],"id":3805736},{"atl":[[520,0],[150,2]],"id":522747},{"atb":[[11,8.91]],"id":522749},{"atl":[[90,2],[440,0.35],[450,0]],"id":522749},{"atl":[[80,2],[450,0]],"id":522750},{"atl":[[70,2],[350,0]],"id":522752},{"atl":[[270,0],[28,3.7]],"id":3805730},{"atl":[[570,0],[220,2]],"id":522753},{"atb":[[5,25],[8.2,13.87],[7.4,9.9],[4.2,8.91]],"id":522741},{"atl":[[21,4.95],[25,9.9]],"id":522741},{"atl":[[280,0],[34,3.03]],"id":522742},{"atl":[[100,2],[480,0]],"id":522745}],"con":true,"img":false}]}
{"op":"mcm","clk":"5348840968","pt":1646221141097,"mc":[{"id":"1.195453759","rc":[{"atl":[[28,3.7]],"id":3805736}],"con":true,"img":false}]}
{"op":"mcm","clk":"5348840982","pt":1646221141199,"mc":[{"id":"1.195453759","rc":[{"atl":[[400,0],[50,2.04]],"id":522741}],"con":true,"img":false}]}
{"op":"mcm","clk":"5348841018","pt":1646221141468,"mc":[{"id":"1.195453759","rc":[{"atl":[[23,4.95],[27,9.9]],"id":522752}],"con":true,"img":false}]}
{"op":"mcm","clk":"5348841030","pt":1646221141572,"mc":[{"id":"1.195453759","rc":[{"atl":[[22,0],[26,0]],"id":522752}],"con":true,"img":false}]}
{"op":"mcm","clk":"5348841055","pt":1646221141781,"mc":[{"id":"1.195453759","rc":[{"atb":[[6.2,19.23],[4.7,0]],"id":3805783},{"atb":[[3.1,0],[3.7,37.04]],"id":3805746},{"atb":[[5.7,56.68],[7.8,14.71]],"id":3805755},{"atb":[[4.9,25.64],[3.9,8.91]],"id":522746},{"atb":[[4.8,26.32],[3.75,8.91]],"id":3805736},{"atb":[[10,11.11],[7.4,8.91]],"id":522747},{"atb":[[7.2,16.13],[5.5,0]],"id":522749},{"atb":[[5,0],[6.6,17.86]],"id":522750},{"atb":[[4.3,0],[5.5,22.22]],"id":522752},{"atb":[[11.5,9.52],[9.4,0]],"id":522753},{"atb":[[4,0],[4.8,26.32]],"id":522742},{"atb":[[5.8,0],[6.6,65.43]],"id":522745}],"con":true,"img":false}]}
{"op":"mcm","clk":"5348841139","pt":1646221142467,"mc":[{"id":"1.195453759","rc":[{"atl":[[32,9.9],[26,0],[27,4.95],[30,0]],"id":522750}],"con":true,"img":false}]}
{"op":"mcm","clk":"5348841744","pt":1646221148116,"mc":[{"id":"1.195453759","rc":[{"atb":[[6.6,17.86]],"id":522741}],"con":true,"img":false}]}
{"op":"mcm","clk":"5348841748","pt":1646221148178,"mc":[{"id":"1.195453759","rc":[{"atb":[[5,0]],"id":522741}],"con":true,"img":false}]}
{"op":"mcm","clk":"5348841780","pt":1646221148516,"mc":[{"id":"1.195453759","rc":[{"atb":[[5.1,0]],"id":522746}],"con":true,"img":false}]}
{"op":"mcm","clk":"5348841818","pt":1646221148896,"mc":[{"id":"1.195453759","rc":[{"atb":[[5.6,8.91]],"id":522746}],"con":true,"img":false}]}
{"op":"mcm","clk":"5348841847","pt":1646221149219,"mc":[{"id":"1.195453759","rc":[{"atb":[[5.2,3.27]],"id":522746}],"con":true,"img":false}]}
{"op":"mcm","clk":"5348841885","pt":1646221149583,"mc":[{"id":"1.195453759","rc":[{"atb":[[5.7,2.72]],"id":522746}],"con":true,"img":false}]}
{"op":"mcm","clk":"5348842007","pt":1646221150899,"mc":[{"id":"1.195453759","rc":[{"atb":[[8.2,4.95]],"id":522741}],"con":true,"img":false}]}
{"op":"mcm","clk":"5348842056","pt":1646221151303,"mc":[{"id":"1.195453759","rc":[{"atb":[[8,7.67],[7.2,9.9],[8.2,0],[7.4,0]],"id":522741}],"con":true,"img":false}]}
{"op":"mcm","clk":"5348842087","pt":1646221151610,"mc":[{"id":"1.195453759","rc":[{"atb":[[8,22.39]],"id":522741}],"con":true,"img":false}]}
{"op":"mcm","clk":"5348842236","pt":1646221152907,"mc":[{"id":"1.195453759","rc":[{"atb":[[16,0],[17.5,4.95],[18,0],[15.5,9.9]],"id":522747}],"con":true,"img":false}]}
{"op":"mcm","clk":"5348842353","pt":1646221153888,"mc":[{"id":"1.195453759","rc":[{"atb":[[17.5,0],[15.5,0]],"id":522747}],"con":true,"img":false}]}
{"op":"mcm","clk":"5348842381","pt":1646221154203,"mc":[{"id":"1.195453759","rc":[{"atl":[[23,0],[24,4.95],[27,0],[28,9.9]],"id":3805783},{"atl":[[32,0],[34,9.9],[27,0],[28,4.95]],"id":3805755}],"con":true,"img":false}]}
{"op":"mcm","clk":"5348842400","pt":1646221154407,"mc":[{"id":"1.195453759","rc":[{"atl":[[34,3.03],[42,0]],"id":3805783}],"con":true,"img":false}]}
{"op":"mcm","clk":"5348842439","pt":1646221154818,"mc":[{"id":"1.195453759","rc":[{"atb":[[16,9.9],[18,4.95]],"id":522747}],"con":true,"img":false}]}
{"op":"mcm","clk":"5348842471","pt":1646221155093,"mc":[{"id":"1.195453759","rc":[{"atl":[[24,0],[28,0]],"id":3805783}],"con":true,"img":false}]}
{"op":"mcm","clk":"5348842548","pt":1646221155814,"mc":[{"id":"1.195453759","rc":[{"atl":[[23,4.95],[27,9.9]],"id":3805783},{"atb":[[9,0],[10,0]],"id":522742}],"con":true,"img":false}]}
{"op":"mcm","clk":"5348842576","pt":1646221156022,"mc":[{"id":"1.195453759","rc":[{"atl":[[12.5,0],[13,4.95],[14.5,0],[15,9.9]],"id":3805746},{"atb":[[16,0],[18,0]],"id":522747},{"atl":[[32,0],[34,9.9],[27,0],[28,4.95]],"id":522750},{"atl":[[23,0],[24,4.95],[27,0],[28,9.9]],"id":522752},{"atb":[[19.5,9.9],[20,0],[23,4.95],[24,0]],"id":522743}],"con":true,"img":false}]}
{"op":"mcm","clk":"5348842586","pt":1646221156089,"mc":[{"id":"1.195453759","rc":[{"atb":[[17.5,4.95],[15.5,9.9]],"id":522747}],"con":true,"img":false}]}
{"op":"mcm","clk":"5348842599","pt":1646221156192,"mc":[{"id":"1.195453759","rc":[{"atl":[[70,2],[330,0]],"id":3805746}],"con":true,"img":false}]}
{"op":"mcm","clk":"5348842612","pt":1646221156295,"mc":[{"id":"1.195453759","rc":[{"atb":[[7.8,16.81]],"id":522742}],"con":true,"img":false}]}
{"op":"mcm","clk":"5348842624","pt":1646221156402,"mc":[{"id":"1.195453759","rc":[{"atl":[[310,4.62],[340,0]],"id":3805746},{"atb":[[13,17.98],[9.4,15.86]],"id":3805755},{"atl":[[75,16.71],[470,0]],"id":3805755}],"con":true,"img":false}]}
{"op":"mcm","clk":"5348842640","pt":1646221156505,"mc":[{"id":"1.195453759","rc":[{"atl":[[34,22.6],[360,0]],"id":3805783},{"atl":[[70,2.29]],"id":3805755},{"atb":[[3.9,0]],"id":522746},{"atl":[[140,0],[21,19.79],[11.5,19.74]],"id":522746},{"atl":[[13,18.16],[28,25.78],[250,0]],"id":3805736},{"atb":[[9.4,15.86]],"id":522750},{"atl":[[24,11.84]],"id":522752},{"atb":[[5.8,27.75]],"id":3805730},{"atl":[[290,0],[28,16.55]],"id":3805730},{"atb":[[17,8.32],[25,23.79],[30,10.42]],"id":522753},{"atl":[[590,0],[220,7.79]],"id":522753},{"atl":[[50,24.12]],"id":522741},{"atl":[[34,25.11],[300,0]],"id":522742}],"con":true,"img":false}]}
{"op":"mcm","clk":"5348842653","pt":1646221156653,"mc":[{"id":"1.195453759","rc":[{"atl":[[22,7.54]],"id":3805783},{"atl":[[13,13.87]],"id":3805746},{"atb":[[5.7,17.51],[7,19.74]],"id":522746},{"atb":[[8,27.04],[3.75,0]],"id":3805736},{"atb":[[17.5,14.56],[7.4,0],[12,29.53]],"id":522747},{"atl":[[540,0],[150,10.5],[42,8.82]],"id":522747},{"atb":[[11,29.53],[7,22.19]],"id":522749},{"atl":[[90,16.18],[470,0]],"id":522749},{"atb":[[12,17.98]],"id":522750},{"atl":[[80,16.71],[28,10.82],[470,0]],"id":522750},{"atl":[[70,14.21],[370,0]],"id":522752},{"atb":[[8.2,17.81]],"id":3805730},{"atl":[[13,17.81]],"id":3805730},{"atl":[[60,7.64]],"id":522753},{"atb":[[7,25.35],[4.2,0]],"id":522741},{"atl":[[21,12.88],[420,0]],"id":522741},{"atb":[[9.2,3.27],[10.5,2.72]],"id":522742},{"atl":[[13,16.81]],"id":522742},{"atb":[[19,33.62],[11,13.32],[23,12.15]],"id":522743},{"atl":[[560,0],[150,10.5],[46,8.47]],"id":522743},{"atb":[[16,31.99],[18,14.27],[11.5,12.68]],"id":522745},{"atl":[[34,9.76],[100,14.76],[500,0]],"id":522745}],"con":true,"img":false}]}
{"op":"mcm","clk":"5348842667","pt":1646221156714,"mc":[{"id":"1.195453759","rc":[{"atl":[[13,8.91],[15,0]],"id":3805746},{"atl":[[17,6.25],[21,14.79]],"id":522746},{"atb":[[15,16.27]],"id":522749},{"atl":[[30,10.42]],"id":522749},{"atl":[[34,0],[28,5.86]],"id":522750},{"atl":[[24,6.89],[28,0]],"id":522752},{"atb":[[19.5,0],[23,7.2]],"id":522743}],"con":true,"img":false}]}
{"op":"mcm","clk":"5348842674","pt":1646221156808,"mc":[{"id":"1.195453759","rc":[{"atl":[[23,0],[24,4.95],[27,0],[28,9.9]],"id":3805783},{"atb":[[6.2,33.73]],"id":3805736},{"atl":[[23,4.55],[28,12.85]],"id":3805730},{"atl":[[40,2.56],[50,22.08]],"id":522741}],"con":true,"img":false}]}
{"op":"mcm","clk":"5348842704","pt":1646221157120,"mc":[{"id":"1.195453759","rc":[{"atb":[[5.8,27.75],[7.8,56.52]],"id":522742}],"con":true,"img":false}]}
{"op":"mcm","clk":"5348842717","pt":1646221157289,"mc":[{"id":"1.195453759","rc":[{"atl":[[440,0]],"id":3805755},{"atl":[[110,0]],"id":522746},{"atl":[[220,0]],"id":3805736}],"con":true,"img":false}]}
{"op":"mcm","clk":"5348842729","pt":1646221157394,"mc":[{"id":"1.195453759","rc":[{"atl":[[330,0]],"id":3805783},{"atb":[[5.7,0]],"id":3805746},{"atl":[[310,4.1],[13,13.87],[15,9.9]],"id":3805746},{"atb":[[5.6,0]],"id":522746},{"atb":[[6.2,24.81]],"id":3805736},{"atb":[[12,20.61]],"id":522747},{"atl":[[510,0]],"id":522747},{"atb":[[11,20.61]],"id":522749},{"atl":[[440,0]],"id":522749},{"atl":[[34,9.9],[80,2],[440,0],[28,10.82]],"id":522750},{"atl":[[70,2],[340,0],[24,11.84],[28,9.9]],"id":522752},{"atl":[[260,0]],"id":3805730},{"atb":[[25,17.18]],"id":522753},{"atl":[[560,0]],"id":522753},{"atl":[[390,0]],"id":522741},{"atl":[[270,0]],"id":522742},{"atb":[[19,24.81],[19.5,9.9],[23,12.15]],"id":522743},{"atl":[[530,0]],"id":522743},{"atb":[[17.5,2.72]],"id":522745},{"atl":[[470,0]],"id":522745}],"con":true,"img":false}]}
{"op":"mcm","clk":"5348842763","pt":1646221157711,"mc":[{"id":"1.195453759","rc":[{"atb":[[6.4,0]],"id":3805746}],"con":true,"img":false}]}
{"op":"mcm","clk":"5348842779","pt":1646221157912,"mc":[{"id":"1.195453759","rc":[{"atb":[[5.3,35.93],[4.9,39.36]],"id":3805746},{"atl":[[28,4.95]],"id":522750}],"con":true,"img":false}]}
{"op":"mcm","clk":"5348842814","pt":1646221158224,"mc":[{"id":"1.195453759","rc":[{"atb":[[5.8,3.27],[5.4,29.45]],"id":3805746}],"con":true,"img":false}]}
{"op":"mcm","clk":"5348842856","pt":1646221158604,"mc":[{"id":"1.195453759","rc":[{"atb":[[6.6,2.72]],"id":3805746}],"con":true,"img":false}]}
{"op":"mcm","clk":"5348842881","pt":1646221158909,"mc":[{"id":"1.195453759","rc":[{"atl":[[22,0]],"id":3805783},{"atl":[[32,5.11]],"id":522750}],"con":true,"img":false}]}
{"op":"mcm","clk":"5348842960","pt":1646221159599,"mc":[{"id":"1.195453759","rc":[{"atl":[[27,6.09]],"id":3805783}],"con":true,"img":false}]}
{"op":"mcm","clk":"5348843598","pt":1646221165321,"mc":[{"id":"1.195453759","rc":[{"atl":[[13,0],[13.5,4.95],[15,0],[15.5,9.9]],"id":3805746},{"atb":[[17.5,0],[17,4.95],[15,9.9],[15.5,0]],"id":522747},{"atl":[[24,0],[25,4.95],[28,0],[29,9.9]],"id":522752},{"atb":[[8,2.72],[7.2,0],[7,35.26],[7.8,4.95]],"id":522741}],"con":true,"img":false}]}
{"op":"mcm","clk":"5348843685","pt":1646221166216,"mc":[{"id":"1.195453759","rc":[{"atl":[[15,8.91]],"id":3805746},{"atb":[[15.5,10.93]],"id":522747},{"atl":[[65,2.47]],"id":522752},{"atb":[[7.8,16.37]],"id":522741}],"con":true,"img":false}]}
{"op":"mcm","clk":"5348843767","pt":1646221167100,"mc":[{"id":"1.195453759","rc":[{"atb":[[8,25.37]],"id":522741}],"con":true,"img":false}]}
{"op":"mcm","clk":"5348843846","pt":1646221167889,"mc":[{"id":"1.195453759","rc":[{"atb":[[8,2.72],[7.8,4.95]],"id":522741}],"con":true,"img":false}]}
{"op":"mcm","clk":"5348843905","pt":1646221168611,"mc":[{"id":"1.195453759","rc":[{"atb":[[7.2,22.08]],"id":522741}],"con":true,"img":false}]}
{"op":"mcm","clk":"5348843916","pt":1646221168725,"mc":[{"id":"1.195453759","rc":[{"atb":[[19.5,0],[19,34.72],[22,4.95],[23,0]],"id":522743}],"con":true,"img":false}]}
{"op":"mcm","clk":"5348843944","pt":1646221169026,"mc":[{"id":"1.195453759","rc":[{"atb":[[16,4.95],[17,0],[14,9.9],[15,0]],"id":522747}],"con":true,"img":false}]}
{"op":"mcm","clk":"5348843978","pt":1646221169298,"mc":[{"id":"1.195453759","rc":[{"atb":[[16.5,30.6],[19,12.63]],"id":522743}],"con":true,"img":false}]}
{"op":"mcm","clk":"5348843990","pt":1646221169408,"mc":[{"id":"1.195453759","rc":[{"atb":[[19,21.44]],"id":522743}],"con":true,"img":false}]}
{"op":"mcm","clk":"5348844258","pt":1646221171814,"mc":[{"id":"1.195453759","rc":[{"atl":[[310,0],[15.5,30.52]],"id":3805746}],"con":true,"img":false}]}
{"op":"mcm","clk":"5348844274","pt":1646221171915,"mc":[{"id":"1.195453759","rc":[{"atl":[[34,3.03],[28,31.19]],"id":3805783},{"atl":[[70,21.15],[75,2],[28,10.82]],"id":3805755},{"atl":[[24,6.89]],"id":522752},{"atl":[[23,26.04],[28,0]],"id":3805730},{"atl":[[40,24.64],[50,0]],"id":522741}],"con":true,"img":false}]}
{"op":"mcm","clk":"5348844284","pt":1646221172028,"mc":[{"id":"1.195453759","rc":[{"atl":[[24,11.84]],"id":3805783},{"atl":[[13,13.21]],"id":3805746},{"atl":[[17,47.02],[21,0]],"id":522746},{"atb":[[16,15.52],[12,0],[14,39.36]],"id":522747},{"atl":[[34,32.23]],"id":522750},{"atl":[[65,14.69]],"id":522752},{"atb":[[7.2,44.17]],"id":522741},{"atb":[[22,12.5]],"id":522743}],"con":true,"img":false}]}
{"op":"mcm","clk":"5348844299","pt":1646221172118,"mc":[{"id":"1.195453759","rc":[{"atl":[[28,10.82]],"id":522750},{"atb":[[7,13.17]],"id":522741}],"con":true,"img":false}]}
{"op":"mcm","clk":"5348844345","pt":1646221172638,"mc":[{"id":"1.195453759","rc":[{"atl":[[70,18.85],[28,4.95]],"id":3805755},{"atl":[[65,12.21]],"id":522752}],"con":true,"img":false}]}
{"op":"mcm","clk":"5348844362","pt":1646221172819,"mc":[{"id":"1.195453759","rc":[{"atl":[[27,0]],"id":3805783},{"atb":[[15.5,0]],"id":522747},{"atb":[[19,12.63]],"id":522743}],"con":true,"img":false}]}
{"op":"mcm","clk":"5348844371","pt":1646221172910,"mc":[{"id":"1.195453759","rc":[{"atl":[[15,0]],"id":3805746},{"atl":[[32,0],[28,4.95]],"id":522750}],"con":true,"img":false}]}
{"op":"mcm","clk":"5348844415","pt":1646221173329,"mc":[{"id":"1.195453759","rc":[{"atb":[[4.9,9.9],[5.4,50.07]],"id":3805746},{"atl":[[32,5.11]],"id":3805755}],"con":true,"img":false}]}
{"op":"mcm","clk":"5348844442","pt":1646221173633,"mc":[{"id":"1.195453759","rc":[{"atl":[[32,5.11]],"id":522750}],"con":true,"img":false}]}
{"op":"mcm","clk":"5348844737","pt":1646221176814,"mc":[{"id":"1.195453759","rc":[{"atl":[[24,0],[25,4.95],[28,21.28],[29,9.9]],"id":3805783},{"atb":[[5.8,0],[6.6,0]],"id":3805746},{"atb":[[9.2,0],[10.5,0]],"id":522742}],"con":true,"img":false}]}
{"op":"mcm","clk":"5348844771","pt":1646221177236,"mc":[{"id":"1.195453759","rc":[{"atb":[[7.8,16.81]],"id":522742}],"con":true,"img":false}]}
{"op":"mcm","clk":"5348844798","pt":1646221177542,"mc":[{"id":"1.195453759","rc":[{"atl":[[27,6.09]],"id":3805783},{"atb":[[6.4,2.72],[5.7,3.27]],"id":3805746},{"atb":[[9,3.27],[5.8,90.07],[10,2.72]],"id":522742}],"con":true,"img":false}]}
{"op":"mcm","clk":"5348845004","pt":1646221179532,"mc":[{"id":"1.195453759","rc":[{"atb":[[11.5,33.07],[14,9.9]],"id":522747}],"con":true,"img":false}]}
{"op":"mcm","clk":"5348845010","pt":1646221179629,"mc":[{"id":"1.195453759","rc":[{"atl":[[32,3.23],[34,0]],"id":3805783},{"atb":[[6.8,17.24],[6.6,0]],"id":522741}],"con":true,"img":false}]}
{"op":"mcm","clk":"5348845034","pt":1646221179939,"mc":[{"id":"1.195453759","rc":[{"atb":[[15.5,2.72]],"id":3805755}],"con":true,"img":false}]}
{"op":"mcm","clk":"5348845044","pt":1646221180040,"mc":[{"id":"1.195453759","rc":[{"atl":[[34,0],[38,9.9],[28,0],[30,4.95]],"id":3805755},{"atl":[[65,4.95],[80,0],[85,9.9],[60,2.68]],"id":522753}],"con":true,"img":false}]}
{"op":"mcm","clk":"5348845063","pt":1646221180250,"mc":[{"id":"1.195453759","rc":[{"atl":[[75,0],[55,2]],"id":3805755},{"atl":[[32,0],[34,9.9],[42,9.9],[28,0]],"id":522750},{"atl":[[160,2],[220,5.79]],"id":522753}],"con":true,"img":false}]}
{"op":"mcm","clk":"5348845073","pt":1646221180353,"mc":[{"id":"1.195453759","rc":[{"atl":[[28,5.86]],"id":522750}],"con":true,"img":false}]}
{"op":"mcm","clk":"5348845095","pt":1646221180518,"mc":[{"id":"1.195453759","rc":[{"atl":[[85,25.72],[220,0]],"id":522753}],"con":true,"img":false}]}
{"op":"mcm","clk":"5348845106","pt":1646221180618,"mc":[{"id":"1.195453759","rc":[{"atb":[[14,17.15]],"id":3805755},{"atl":[[42,3.86],[44,4.95],[50,0],[55,9.9]],"id":522747},{"atl":[[70,2],[80,0]],"id":522750},{"atb":[[9,0],[10,0]],"id":3805730}],"con":true,"img":false}]}
{"op":"mcm","clk":"5348845116","pt":1646221180723,"mc":[{"id":"1.195453759","rc":[{"atl":[[80,16.8]],"id":522750}],"con":true,"img":false}]}
{"op":"mcm","clk":"5348845153","pt":1646221181035,"mc":[{"id":"1.195453759","rc":[{"atl":[[24,0]],"id":522752},{"atb":[[8.2,4.95]],"id":3805730}],"con":true,"img":false}]}
{"op":"mcm","clk":"5348845171","pt":1646221181239,"mc":[{"id":"1.195453759","rc":[{"atl":[[150,2],[55,34.38]],"id":522747},{"atb":[[5.8,80.7],[8.2,26.97]],"id":3805730}],"con":true,"img":false}]}
{"op":"mcm","clk":"5348845180","pt":1646221181346,"mc":[{"id":"1.195453759","rc":[{"atb":[[9.2,3.27],[10.5,2.72]],"id":3805730}],"con":true,"img":false}]}
{"op":"mcm","clk":"5348845194","pt":1646221181547,"mc":[{"id":"1.195453759","rc":[{"atb":[[8,25.37]],"id":522741}],"con":true,"img":false}]}
{"op":"mcm","clk":"5348845219","pt":1646221181815,"mc":[{"id":"1.195453759","rc":[{"atl":[[44,0],[55,24.47]],"id":522747},{"atl":[[28,5.86]],"id":522752}],"con":true,"img":false}]}
{"op":"mcm","clk":"5348845228","pt":1646221181916,"mc":[{"id":"1.195453759","rc":[{"atl":[[65,9.9],[48,4.95]],"id":522747}],"con":true,"img":false}]}
{"op":"mcm","clk":"5348845261","pt":1646221182232,"mc":[{"id":"1.195453759","rc":[{"atb":[[7.2,22.08]],"id":522741}],"con":true,"img":false}]}
{"op":"mcm","clk":"5348845381","pt":1646221183322,"mc":[{"id":"1.195453759","rc":[{"atb":[[6.4,0],[5.7,0]],"id":3805746}],"con":true,"img":false}]}
{"op":"mcm","clk":"5348845399","pt":1646221183528,"mc":[{"id":"1.195453759","rc":[{"atl":[[32,9.9],[25,0],[27,4.95],[29,0]],"id":522752}],"con":true,"img":false}]}
{"op":"mcm","clk":"5348845425","pt":1646221183840,"mc":[{"id":"1.195453759","rc":[{"atb":[[4.9,74.92],[5.4,29.45]],"id":3805746}],"con":true,"img":false}]}
{"op":"mcm","clk":"5348845449","pt":1646221184146,"mc":[{"id":"1.195453759","rc":[{"atb":[[5.6,3.27],[6.2,2.72]],"id":3805746}],"con":true,"img":false}]}
{"op":"mcm","clk":"5348845512","pt":1646221184832,"mc":[{"id":"1.195453759","rc":[{"atb":[[16,0],[14,0]],"id":522747},{"atb":[[18,9.9],[19,2.72],[20,4.95],[22,0]],"id":522743}],"con":true,"img":false}]}
{"op":"mcm","clk":"5348845528","pt":1646221185038,"mc":[{"id":"1.195453759","rc":[{"atb":[[10,0],[10.5,10.53],[13,9.9],[15,4.95]],"id":522747}],"con":true,"img":false}]}
{"op":"mcm","clk":"5348845558","pt":1646221185348,"mc":[{"id":"1.195453759","rc":[{"atl":[[25,0],[26,4.95],[29,0]],"id":3805783},{"atb":[[16.5,3.27],[18,37.24]],"id":522743}],"con":true,"img":false}]}
{"op":"mcm","clk":"5348845586","pt":1646221185658,"mc":[{"id":"1.195453759","rc":[{"atb":[[12,13.1]],"id":522747},{"atb":[[19.5,8.56]],"id":522743}],"con":true,"img":false}]}
{"op":"mcm","clk":"5348845632","pt":1646221186139,"mc":[{"id":"1.195453759","rc":[{"atl":[[30,9.9]],"id":3805783}],"con":true,"img":false}]}
{"op":"mcm","clk":"5348845718","pt":1646221186959,"mc":[{"id":"1.195453759","rc":[{"atl":[[70,0]],"id":3805755}],"con":true,"img":false}]}
{"op":"mcm","clk":"5348845731","pt":1646221187065,"mc":[{"id":"1.195453759","rc":[{"atl":[[26,11.29]],"id":3805783},{"atl":[[38,32.23],[30,10.42]],"id":3805755},{"atb":[[11.5,2.72],[15.5,10.93]],"id":522747},{"atl":[[80,0],[42,39.36]],"id":522750},{"atl":[[27,11.05]],"id":522752},{"atb":[[9.2,0],[10.5,0]],"id":3805730},{"atb":[[20,13.29]],"id":522743}],"con":true,"img":false}]}
{"op":"mcm","clk":"5348845754","pt":1646221187229,"mc":[{"id":"1.195453759","rc":[{"atl":[[26,6.34],[27,11.05],[30,0]],"id":3805783},{"atb":[[12,35.19]],"id":522747},{"atl":[[32,25.99],[65,0]],"id":522752}],"con":true,"img":false}]}
{"op":"mcm","clk":"5348845802","pt":1646221187750,"mc":[{"id":"1.195453759","rc":[{"atl":[[26,0],[27,4.95]],"id":3805783},{"atb":[[19.5,0]],"id":522743}],"con":true,"img":false}]}
{"op":"mcm","clk":"5348845810","pt":1646221187858,"mc":[{"id":"1.195453759","rc":[{"atl":[[32,0]],"id":3805755},{"atb":[[12,22.08],[15.5,0]],"id":522747},{"atl":[[28,0]],"id":522752},{"atb":[[9,3.27],[10,2.72]],"id":3805730}],"con":true,"img":false}]}
{"op":"mcm","clk":"5348845828","pt":1646221188060,"mc":[{"id":"1.195453759","rc":[{"atl":[[32,13.13]],"id":3805783}],"con":true,"img":false}]}
{"op":"mcm","clk":"5348845864","pt":1646221188329,"mc":[{"id":"1.195453759","rc":[{"atl":[[32,32.71],[28,0]],"id":3805783}],"con":true,"img":false}]}
{"op":"mcm","clk":"5348845890","pt":1646221188640,"mc":[{"id":"1.195453759","rc":[{"atl":[[27,11.05]],"id":3805783},{"atb":[[4.9,9.9],[5.4,56.45]],"id":3805746},{"atb":[[13.5,12.68]],"id":522747}],"con":true,"img":false}]}
{"op":"mcm","clk":"5348846036","pt":1646221190177,"mc":[{"id":"1.195453759","rc":[{"atl":[[32,22.8],[34,9.9],[27,0],[28,4.95]],"id":3805783}],"con":true,"img":false}]}
{"op":"mcm","clk":"5348846121","pt":1646221190941,"mc":[{"id":"1.195453759","rc":[{"atl":[[30,5.46]],"id":3805783}],"con":true,"img":false}]}
{"op":"mcm","clk":"5348846290","pt":1646221192651,"mc":[{"id":"1.195453759","rc":[{"atl":[[34,0],[28,5.86],[29,4.95]],"id":3805783},{"atb":[[5.8,27.75],[7.8,56.52]],"id":522742}],"con":true,"img":false}]}
{"op":"mcm","clk":"5348846380","pt":1646221193642,"mc":[{"id":"1.195453759","rc":[{"atl":[[28,0],[30,0]],"id":3805783}],"con":true,"img":false}]}
{"op":"mcm","clk":"5348846453","pt":1646221194370,"mc":[{"id":"1.195453759","rc":[{"atl":[[29,0],[30,4.95]],"id":3805783},{"atl":[[38,9.9],[55,27.15]],"id":3805755}],"con":true,"img":false}]}
{"op":"mcm","clk":"5348846484","pt":1646221194682,"mc":[{"id":"1.195453759","rc":[{"atl":[[30,10.42]],"id":3805783},{"atb":[[12,0],[13,31.99]],"id":522747},{"atl":[[32,9.9],[70,21.77]],"id":522752}],"con":true,"img":false}]}
{"op":"mcm","clk":"5348846580","pt":1646221195467,"mc":[{"id":"1.195453759","rc":[{"atl":[[30,5.46]],"id":3805783}],"con":true,"img":false}]}
{"op":"mcm","clk":"5348846603","pt":1646221195673,"mc":[{"id":"1.195453759","rc":[{"atl":[[32,3.23],[34,30.97]],"id":3805783},{"atb":[[15.5,13.65]],"id":3805755}],"con":true,"img":false}]}
{"op":"mcm","clk":"5348846640","pt":1646221196049,"mc":[{"id":"1.195453759","rc":[{"atl":[[32,0],[34,34]],"id":3805783}],"con":true,"img":false}]}
{"op":"mcm","clk":"5348846661","pt":1646221196254,"mc":[{"id":"1.195453759","rc":[{"atl":[[36,9.9],[29,4.95]],"id":3805783},{"atb":[[5.8,27.75],[8.2,68.17]],"id":3805730}],"con":true,"img":false}]}
{"op":"mcm","clk":"5348846689","pt":1646221196563,"mc":[{"id":"1.195453759","rc":[{"atb":[[14,4.95]],"id":3805755}],"con":true,"img":false}]}
{"op":"mcm","clk":"5348846781","pt":1646221197663,"mc":[{"id":"1.195453759","rc":[{"atl":[[36,0],[29,0],[30,10.42]],"id":3805783}],"con":true,"img":false}]}
{"op":"mcm","clk":"5348846806","pt":1646221197966,"mc":[{"id":"1.195453759","rc":[{"atb":[[12.5,9.9],[13,22.08],[14.5,4.95],[15,0]],"id":522747}],"con":true,"img":false}]}
{"op":"mcm","clk":"5348846867","pt":1646221198544,"mc":[{"id":"1.195453759","rc":[{"atl":[[38,9.9]],"id":3805783}],"con":true,"img":false}]}
{"op":"mcm","clk":"5348846909","pt":1646221198969,"mc":[{"id":"1.195453759","rc":[{"atb":[[12.5,0],[14.5,0]],"id":522747}],"con":true,"img":false}]}
{"op":"mcm","clk":"5348846994","pt":1646221199753,"mc":[{"id":"1.195453759","rc":[{"atb":[[16.5,9.9],[18.5,4.95]],"id":522747},{"atl":[[60,0]],"id":522753}],"con":true,"img":false}]}
{"op":"mcm","clk":"5348847069","pt":1646221200483,"mc":[{"id":"1.195453759","rc":[{"atb":[[18.5,14.01]],"id":522747},{"atl":[[65,7.43],[160,10.74],[85,9.9]],"id":522753}],"con":true,"img":false}]}
{"op":"mcm","clk":"5348847089","pt":1646221200652,"mc":[{"id":"1.195453759","rc":[{"atl":[[11.5,4.95]],"id":3805746},{"atb":[[12,0],[14,0]],"id":3805755},{"atb":[[11,0],[13,0]],"id":522750},{"atl":[[32,0],[27,6.09]],"id":522752},{"atb":[[7.8,0],[7,3.27]],"id":522741},{"atl":[[13,11.85],[15,0]],"id":522742},{"atb":[[18,27.33],[24,4.95]],"id":522743}],"con":true,"img":false}]}
{"op":"mcm","clk":"5348847098","pt":1646221200758,"mc":[{"id":"1.195453759","rc":[{"atl":[[34,43.91],[38,0],[28,4.95],[30,5.46]],"id":3805783},{"atl":[[15.5,20.61]],"id":3805746},{"atb":[[13,27.89],[15,4.95]],"id":3805755},{"atb":[[13,0],[13.5,9.9],[15,11.32],[15.5,4.95]],"id":522749},{"atb":[[12,27.89],[14,4.95]],"id":522750},{"atl":[[24,4.95],[28,9.9]],"id":522752},{"atb":[[32,4.95],[26,0],[27,9.9],[30,5.46]],"id":522753},{"atb":[[8,30.33],[7.2,31.99]],"id":522741},{"atl":[[12.5,4.95],[14.5,9.9]],"id":522742}],"con":true,"img":false}]}
{"op":"mcm","clk":"5348847128","pt":1646221201068,"mc":[{"id":"1.195453759","rc":[{"atb":[[13,13.17]],"id":3805755}],"con":true,"img":false}]}
{"op":"mcm","clk":"5348847139","pt":1646221201178,"mc":[{"id":"1.195453759","rc":[{"atl":[[11.5,19.66],[13.5,19.66],[15.5,0]],"id":3805746},{"atb":[[9.4,59.73]],"id":3805755},{"atb":[[12,13.17],[9.4,56.73]],"id":522750},{"atb":[[7.2,9.9],[7,55.24]],"id":522741},{"atl":[[34,3.03],[14,35.25]],"id":522742},{"atb":[[18,0],[19,30.05],[24,11.84]],"id":522743}],"con":true,"img":false}]}
{"op":"mcm","clk":"5348847146","pt":1646221201275,"mc":[{"id":"1.195453759","rc":[{"atb":[[13.5,0]],"id":522747},{"atl":[[24,11.84]],"id":522752},{"atb":[[25,0],[27,35.68]],"id":522753},{"atl":[[12,14.41]],"id":522742}],"con":true,"img":false}]}
{"op":"mcm","clk":"5348847155","pt":1646221201379,"mc":[{"id":"1.195453759","rc":[{"atb":[[16,10.56],[11,0],[13.5,40.12]],"id":522749},{"atb":[[34,4.8]],"id":522753}],"con":true,"img":false}]}
{"op":"mcm","clk":"5348847165","pt":1646221201445,"mc":[{"id":"1.195453759","rc":[{"atl":[[36,9.9],[38,0],[29,4.95],[30,5.46]],"id":3805755},{"atb":[[16.5,0],[17,9.9],[18.5,9.05],[19,4.95]],"id":522747},{"atl":[[42,29.45],[28,10.82]],"id":522750},{"atl":[[65,2.47],[70,4.95],[85,0],[90,9.9]],"id":522753}],"con":true,"img":false}]}
{"op":"mcm","clk":"5348847209","pt":1646221201860,"mc":[{"id":"1.195453759","rc":[{"atl":[[27,6.09]],"id":3805783},{"atl":[[36,32.77],[55,2],[28,5.86]],"id":3805755},{"atb":[[19,13.76]],"id":522747},{"atb":[[9.4,15.86]],"id":522750},{"atl":[[28,4.95]],"id":522750}],"con":true,"img":false}]}
{"op":"mcm","clk":"5348847220","pt":1646221201962,"mc":[{"id":"1.195453759","rc":[{"atl":[[27,0]],"id":522752},{"atb":[[20,4.95]],"id":522743}],"con":true,"img":false}]}
{"op":"mcm","clk":"5348847228","pt":1646221202069,"mc":[{"id":"1.195453759","rc":[{"atl":[[13,0]],"id":3805746},{"atb":[[17,30.73],[13,0]],"id":522747},{"atb":[[15,0]],"id":522749},{"atl":[[70,2],[28,33.7]],"id":522752},{"atl":[[13,0]],"id":522742}],"con":true,"img":false}]}
{"op":"mcm","clk":"5348847239","pt":1646221202175,"mc":[{"id":"1.195453759","rc":[{"atb":[[30,0]],"id":522753}],"con":true,"img":false}]}
{"op":"mcm","clk":"5348847280","pt":1646221202543,"mc":[{"id":"1.195453759","rc":[{"atb":[[16,22.08],[16.5,9.9],[18,9.32],[18.5,4.95]],"id":522745}],"con":true,"img":false}]}
{"op":"mcm","clk":"5348847291","pt":1646221202650,"mc":[{"id":"1.195453759","rc":[{"atl":[[30,0]],"id":3805783},{"atl":[[28,0],[30,0]],"id":3805755},{"atb":[[18.5,0]],"id":522747},{"atl":[[32,5.11]],"id":522750}],"con":true,"img":false}]}
{"op":"mcm","clk":"5348847304","pt":1646221202755,"mc":[{"id":"1.195453759","rc":[{"atl":[[27,0]],"id":3805783},{"atl":[[28,9.9]],"id":522752}],"con":true,"img":false}]}
{"op":"mcm","clk":"5348847333","pt":1646221203063,"mc":[{"id":"1.195453759","rc":[{"atb":[[16,0],[17.5,31.09],[19,8.8]],"id":522745}],"con":true,"img":false}]}
{"op":"mcm","clk":"5348847341","pt":1646221203166,"mc":[{"id":"1.195453759","rc":[{"atl":[[34,12.93],[30,17.19]],"id":3805783},{"atl":[[42,0]],"id":522750}],"con":true,"img":false}]}
{"op":"mcm","clk":"5348847353","pt":1646221203270,"mc":[{"id":"1.195453759","rc":[{"atl":[[34,32.23]],"id":522750}],"con":true,"img":false}]}
{"op":"mcm","clk":"5348847372","pt":1646221203472,"mc":[{"id":"1.195453759","rc":[{"atl":[[34,4.8]],"id":3805755}],"con":true,"img":false}]}
{"op":"mcm","clk":"5348847385","pt":1646221203588,"mc":[{"id":"1.195453759","rc":[{"atl":[[32,5.11]],"id":3805783}],"con":true,"img":false}]}
{"op":"mcm","clk":"5348847412","pt":1646221203861,"mc":[{"id":"1.195453759","rc":[{"atb":[[18,0]],"id":522745}],"con":true,"img":false}]}
{"op":"mcm","clk":"5348847422","pt":1646221203952,"mc":[{"id":"1.195453759","rc":[{"atl":[[30,0]],"id":3805783}],"con":true,"img":false}]}
{"op":"mcm","clk":"5348847619","pt":1646221205885,"mc":[{"id":"1.195453759","rc":[{"atl":[[28,10.82]],"id":3805783}],"con":true,"img":false}]}
{"op":"mcm","clk":"5348847706","pt":1646221206777,"mc":[{"id":"1.195453759","rc":[{"atl":[[32,0],[28,4.95]],"id":3805783}],"con":true,"img":false}]}
{"op":"mcm","clk":"5348847721","pt":1646221206947,"mc":[{"id":"1.195453759","rc":[{"atl":[[36,22.86],[38,9.9],[29,0],[30,4.95]],"id":3805755}],"con":true,"img":false}]}
{"op":"mcm","clk":"5348847787","pt":1646221207674,"mc":[{"id":"1.195453759","rc":[{"atl":[[32,5.11]],"id":3805783}],"con":true,"img":false}]}
{"op":"mcm","clk":"5348847806","pt":1646221207877,"mc":[{"id":"1.195453759","rc":[{"atl":[[65,0]],"id":522753}],"con":true,"img":false}]}
{"op":"mcm","clk":"5348847834","pt":1646221208149,"mc":[{"id":"1.195453759","rc":[{"atl":[[70,0],[75,4.95],[90,0],[95,9.9]],"id":522753}],"con":true,"img":false}]}
{"op":"mcm","clk":"5348847847","pt":1646221208249,"mc":[{"id":"1.195453759","rc":[{"atl":[[70,22.32],[13.5,4.95]],"id":3805746}],"con":true,"img":false}]}
{"op":"mcm","clk":"5348847880","pt":1646221208565,"mc":[{"id":"1.195453759","rc":[{"atl":[[70,2.29]],"id":522753}],"con":true,"img":false}]}
{"op":"mcm","clk":"5348847939","pt":1646221209163,"mc":[{"id":"1.195453759","rc":[{"atb":[[17,9.9]],"id":522747}],"con":true,"img":false}]}
{"op":"mcm","clk":"5348847971","pt":1646221209472,"mc":[{"id":"1.195453759","rc":[{"atl":[[27,6.09]],"id":3805783},{"atb":[[11.5,30.53]],"id":522747},{"atl":[[70,21.59]],"id":522752}],"con":true,"img":false}]}
{"op":"mcm","clk":"5348848062","pt":1646221210465,"mc":[{"id":"1.195453759","rc":[{"atl":[[32,16.66]],"id":3805783}],"con":true,"img":false}]}
{"op":"mcm","clk":"5348848142","pt":1646221211184,"mc":[{"id":"1.195453759","rc":[{"atl":[[32,4.95],[38,0],[30,0]],"id":3805755},{"atb":[[8,2.72],[7.2,0],[7,65.15],[7.8,4.95]],"id":522741}],"con":true,"img":false}]}
{"op":"mcm","clk":"5348848155","pt":1646221211288,"mc":[{"id":"1.195453759","rc":[{"atl":[[27,0]],"id":3805783}],"con":true,"img":false}]}
{"op":"mcm","clk":"5348848220","pt":1646221211873,"mc":[{"id":"1.195453759","rc":[{"atb":[[7.8,27.04]],"id":522741}],"con":true,"img":false}]}
{"op":"mcm","clk":"5348848229","pt":1646221211986,"mc":[{"id":"1.195453759","rc":[{"atb":[[9.2,0],[10.5,0]],"id":522749},{"atb":[[12,9.9],[14.5,8.91]],"id":522750},{"atb":[[19.5,0],[24,0]],"id":522753}],"con":true,"img":false}]}
{"op":"mcm","clk":"5348848253","pt":1646221212181,"mc":[{"id":"1.195453759","rc":[{"atl":[[30,5.46]],"id":3805783}],"con":true,"img":false}]}
{"op":"mcm","clk":"5348848277","pt":1646221212392,"mc":[{"id":"1.195453759","rc":[{"atl":[[32,0],[34,9.76],[42,9.9]],"id":3805755}],"con":true,"img":false}]}
{"op":"mcm","clk":"5348848308","pt":1646221212668,"mc":[{"id":"1.195453759","rc":[{"atb":[[11,2.72],[9.4,3.27]],"id":522749},{"atb":[[12.5,3.27],[15,2.72]],"id":522750},{"atb":[[20,3.27],[25,2.72]],"id":522753}],"con":true,"img":false}]}
{"op":"mcm","clk":"5348848337","pt":1646221212972,"mc":[{"id":"1.195453759","rc":[{"atl":[[36,0],[42,44.1]],"id":3805755}],"con":true,"img":false}]}
{"op":"mcm","clk":"5348848356","pt":1646221213179,"mc":[{"id":"1.195453759","rc":[{"atb":[[15.5,10.93]],"id":522750}],"con":true,"img":false}]}
{"op":"mcm","clk":"5348848463","pt":1646221214170,"mc":[{"id":"1.195453759","rc":[{"atb":[[17,0],[18,9.9],[19,8.8],[20,4.95]],"id":522747},{"atb":[[14.5,0]],"id":522750}],"con":true,"img":false}]}
{"op":"mcm","clk":"5348848500","pt":1646221214484,"mc":[{"id":"1.195453759","rc":[{"atl":[[70,7.25],[75,0],[90,9.9],[95,0]],"id":522753}],"con":true,"img":false}]}
{"op":"mcm","clk":"5348848518","pt":1646221214690,"mc":[{"id":"1.195453759","rc":[{"atl":[[11.5,0],[13.5,0]],"id":3805746},{"atl":[[34,0],[36,4.95],[42,34.19],[44,9.9]],"id":3805755},{"atb":[[21,7.93]],"id":522747},{"atb":[[6.8,27.14],[7.6,4.95],[7.8,0],[7,55.24]],"id":522741}],"con":true,"img":false}]}
{"op":"mcm","clk":"5348848527","pt":1646221214786,"mc":[{"id":"1.195453759","rc":[{"atl":[[12,4.95],[14,9.9]],"id":3805746}],"con":true,"img":false}]}
{"op":"mcm","clk":"5348848543","pt":1646221215001,"mc":[{"id":"1.195453759","rc":[{"atl":[[34,3.03],[28,0],[29,4.95]],"id":3805783},{"atl":[[34,22.32],[36,9.9],[28,0],[29,4.95]],"id":522750},{"atl":[[70,4.95]],"id":522753}],"con":true,"img":false}]}
{"op":"mcm","clk":"5348848583","pt":1646221215265,"mc":[{"id":"1.195453759","rc":[{"atl":[[70,0],[75,4.95],[90,0],[95,9.9]],"id":522753}],"con":true,"img":false}]}
{"op":"mcm","clk":"5348848601","pt":1646221215367,"mc":[{"id":"1.195453759","rc":[{"atl":[[13.5,8.91]],"id":3805746},{"atl":[[36,0],[38,4.95],[40,4.06],[44,0],[46,9.9]],"id":3805755},{"atb":[[19,0],[21,0]],"id":522747}],"con":true,"img":false}]}
{"op":"mcm","clk":"5348848614","pt":1646221215471,"mc":[{"id":"1.195453759","rc":[{"atb":[[18,0],[19.5,4.95],[20,0]],"id":522747},{"atb":[[16,0]],"id":522749},{"atb":[[7.2,4.95],[7.6,0],[6.8,17.24]],"id":522741}],"con":true,"img":false}]}
{"op":"mcm","clk":"5348848625","pt":1646221215576,"mc":[{"id":"1.195453759","rc":[{"atl":[[12,0],[14,0]],"id":3805746}],"con":true,"img":false}]}
{"op":"mcm","clk":"5348848635","pt":1646221215676,"mc":[{"id":"1.195453759","rc":[{"atl":[[34,12.93],[28,4.95]],"id":3805783},{"atl":[[12.5,4.95],[14.5,9.9]],"id":3805746},{"atb":[[13,47.49],[9.4,15.86]],"id":3805755},{"atb":[[14,19.9]],"id":522750},{"atl":[[70,2.29]],"id":522753}],"con":true,"img":false}]}
{"op":"mcm","clk":"5348848647","pt":1646221215778,"mc":[{"id":"1.195453759","rc":[{"atl":[[29,0]],"id":3805783}],"con":true,"img":false}]}
{"op":"mcm","clk":"5348848663","pt":1646221215982,"mc":[{"id":"1.195453759","rc":[{"atl":[[70,2],[14,20.61]],"id":3805746},{"atb":[[11,32.94]],"id":522749}],"con":true,"img":false}]}
{"op":"mcm","clk":"5348848671","pt":1646221216090,"mc":[{"id":"1.195453759","rc":[{"atb":[[12,13.1]],"id":522747},{"atb":[[13.5,9.9]],"id":522749}],"con":true,"img":false}]}
{"op":"mcm","clk":"5348848680","pt":1646221216190,"mc":[{"id":"1.195453759","rc":[{"atl":[[160,2],[95,24.62]],"id":522753}],"con":true,"img":false}]}
{"op":"mcm","clk":"5348848686","pt":1646221216296,"mc":[{"id":"1.195453759","rc":[{"atb":[[17.5,9.9]],"id":522747},{"atb":[[13.5,22.59]],"id":522749},{"atb":[[7.2,0],[7.4,4.95]],"id":522741}],"con":true,"img":false}]}
{"op":"mcm","clk":"5348848699","pt":1646221216355,"mc":[{"id":"1.195453759","rc":[{"atl":[[28,10.82]],"id":3805783},{"atl":[[38,9.23]],"id":3805755}],"con":true,"img":false}]}
{"op":"mcm","clk":"5348848707","pt":1646221216459,"mc":[{"id":"1.195453759","rc":[{"atb":[[10.5,33.54],[11.5,2.72]],"id":522747}],"con":true,"img":false}]}
{"op":"mcm","clk":"5348848716","pt":1646221216568,"mc":[{"id":"1.195453759","rc":[{"atl":[[12,4.95],[12.5,0],[14,30.52],[14.5,0]],"id":3805746},{"atl":[[23,4.95],[24,6.89],[27,9.9],[28,0]],"id":522752},{"atb":[[20,0],[21,9.9],[24,6.89],[25,4.95]],"id":522743}],"con":true,"img":false}]}
{"op":"mcm","clk":"5348848737","pt":1646221216979,"mc":[{"id":"1.195453759","rc":[{"atl":[[70,2],[23,12.15],[27,27.5]],"id":522752},{"atb":[[19,2.72],[21,37.24],[26,6.34]],"id":522743}],"con":true,"img":false}]}
{"op":"mcm","clk":"5348848770","pt":1646221217286,"mc":[{"id":"1.195453759","rc":[{"atl":[[28,4.95],[30,0]],"id":3805783},{"atl":[[40,0]],"id":3805755},{"atl":[[29,10.61]],"id":522750}],"con":true,"img":false}]}
{"op":"mcm","clk":"5348848808","pt":1646221217670,"mc":[{"id":"1.195453759","rc":[{"atl":[[65,0],[48,0]],"id":522747},{"atl":[[24,0]],"id":522752},{"atb":[[24,0]],"id":522743}],"con":true,"img":false}]}
{"op":"mcm","clk":"5348848834","pt":1646221217981,"mc":[{"id":"1.195453759","rc":[{"atl":[[32,0],[34,44.39]],"id":3805783},{"atl":[[46,4.95],[60,9.9]],"id":522747},{"atl":[[70,0]],"id":522753}],"con":true,"img":false}]}
{"op":"mcm","clk":"5348848863","pt":1646221218288,"mc":[{"id":"1.195453759","rc":[{"atl":[[32,4.95],[34,34.48],[40,9.9],[28,0],[30,5.46]],"id":3805783},{"atl":[[38,0],[40,4.95],[46,0],[48,9.9]],"id":3805755},{"atb":[[6.4,4.95],[5.8,9.9],[6.2,0],[7,0]],"id":522746},{"atl":[[150,11.66],[55,0]],"id":522747},{"atl":[[32,0],[34,32.23],[36,0],[28,4.95],[29,5.66]],"id":522750},{"atl":[[13,0],[13.5,4.95],[15,0],[15.5,9.9]],"id":3805730},{"atl":[[75,0],[80,4.95],[95,14.71],[100,9.9]],"id":522753}],"con":true,"img":false}]}
{"op":"mcm","clk":"5348848887","pt":1646221218494,"mc":[{"id":"1.195453759","rc":[{"atl":[[32,8.18],[34,31.45]],"id":3805783}],"con":true,"img":false}]}
{"op":"mcm","clk":"5348848913","pt":1646221218705,"mc":[{"id":"1.195453759","rc":[{"atl":[[34,0]],"id":3805783},{"atl":[[75,2.14]],"id":522753}],"con":true,"img":false}]}
{"op":"mcm","clk":"5348848952","pt":1646221218977,"mc":[{"id":"1.195453759","rc":[{"atl":[[32,3.23],[40,0]],"id":3805783},{"atl":[[40,9.02]],"id":3805755},{"atb":[[6.4,0],[5.8,22.08]],"id":522746},{"atl":[[34,22.32],[36,9.9],[28,0],[29,10.61]],"id":522750},{"atl":[[13,4.95],[13.5,0],[15,9.9],[15.5,8.91]],"id":3805730},{"atl":[[80,0],[100,0]],"id":522753}],"con":true,"img":false}]}
{"op":"mcm","clk":"5348848962","pt":1646221219083,"mc":[{"id":"1.195453759","rc":[{"atb":[[6.2,9.9],[7,4.95]],"id":522746}],"con":true,"img":false}]}
{"op":"mcm","clk":"5348848996","pt":1646221219396,"mc":[{"id":"1.195453759","rc":[{"atb":[[5.2,58.67]],"id":522746}],"con":true,"img":false}]}
{"op":"mcm","clk":"5348849006","pt":1646221219496,"mc":[{"id":"1.195453759","rc":[{"atb":[[5.7,2.72]],"id":522746},{"atl":[[34,0],[36,41.93]],"id":522750},{"atl":[[23,4.55]],"id":3805730}],"con":true,"img":false}]}
{"op":"mcm","clk":"5348849019","pt":1646221219604,"mc":[{"id":"1.195453759","rc":[{"atl":[[15.5,29.53]],"id":3805730}],"con":true,"img":false}]}
{"op":"mcm","clk":"5348849030","pt":1646221219664,"mc":[{"id":"1.195453759","rc":[{"atl":[[34,9.9],[28,4.95]],"id":3805783},{"atl":[[75,7.09],[95,24.62]],"id":522753}],"con":true,"img":false}]}
{"op":"mcm","clk":"5348849067","pt":1646221220079,"mc":[{"id":"1.195453759","rc":[{"atl":[[42,0],[48,40.24]],"id":3805755},{"atb":[[5.2,3.27]],"id":522746}],"con":true,"img":false}]}
{"op":"mcm","clk":"5348849090","pt":1646221220283,"mc":[{"id":"1.195453759","rc":[{"atl":[[28,10.82]],"id":3805783}],"con":true,"img":false}]}
{"op":"mcm","clk":"5348849118","pt":1646221220596,"mc":[{"id":"1.195453759","rc":[{"atl":[[34,0],[28,5.86],[29,4.95]],"id":3805783},{"atb":[[6.2,0],[6.8,4.95],[6,9.9],[7,0]],"id":522746}],"con":true,"img":false}]}
{"op":"mcm","clk":"5348849174","pt":1646221221181,"mc":[{"id":"1.195453759","rc":[{"atl":[[28,0],[30,0]],"id":3805783}],"con":true,"img":false}]}
{"op":"mcm","clk":"5348849286","pt":1646221222066,"mc":[{"id":"1.195453759","rc":[{"atl":[[1000,0.15]],"id":3805783}],"con":true,"img":false}]}
{"op":"mcm","clk":"5348849388","pt":1646221222998,"mc":[{"id":"1.195453759","rc":[{"atl":[[65,9.9],[46,0],[48,4.95],[60,0]],"id":522747}],"con":true,"img":false}]}
{"op":"mcm","clk":"5348849397","pt":1646221223102,"mc":[{"id":"1.195453759","rc":[{"atl":[[11.5,14.79],[13.5,0]],"id":522746},{"atb":[[8.2,63.22],[7.4,0],[7.6,9.9],[8.4,4.95]],"id":3805730}],"con":true,"img":false}]}
{"op":"mcm","clk":"5348849407","pt":1646221223171,"mc":[{"id":"1.195453759","rc":[{"atl":[[11,4.95],[13,9.9]],"id":522746}],"con":true,"img":false}]}
{"op":"mcm","clk":"5348849415","pt":1646221223272,"mc":[{"id":"1.195453759","rc":[{"atl":[[160,11.15],[95,9.9]],"id":522753}],"con":true,"img":false}]}
{"op":"mcm","clk":"5348849451","pt":1646221223580,"mc":[{"id":"1.195453759","rc":[{"atl":[[320,2]],"id":3805783},{"atl":[[17,6.25],[12.5,43.96]],"id":522746},{"atb":[[8.4,19.66]],"id":3805730}],"con":true,"img":false}]}
{"op":"mcm","clk":"5348849462","pt":1646221223685,"mc":[{"id":"1.195453759","rc":[{"atl":[[32,0]],"id":3805783},{"atb":[[8.2,22.01]],"id":3805730}],"con":true,"img":false}]}
{"op":"mcm","clk":"5348849477","pt":1646221223789,"mc":[{"id":"1.195453759","rc":[{"atl":[[38,9.9],[29,0],[30,4.95]],"id":3805783},{"atl":[[10.5,16.68]],"id":522746}],"con":true,"img":false}]}
{"op":"mcm","clk":"5348849488","pt":1646221223887,"mc":[{"id":"1.195453759","rc":[{"atb":[[10.5,10.53],[12,35.19]],"id":522747}],"con":true,"img":false}]}
{"op":"mcm","clk":"5348849498","pt":1646221223992,"mc":[{"id":"1.195453759","rc":[{"atl":[[70,22.96],[27,9.9]],"id":522752}],"con":true,"img":false}]}
{"op":"mcm","clk":"5348849527","pt":1646221224265,"mc":[{"id":"1.195453759","rc":[{"atl":[[30,10.42]],"id":3805783}],"con":true,"img":false}]}
{"op":"mcm","clk":"5348849533","pt":1646221224400,"mc":[{"id":"1.195453759","rc":[{"atl":[[75,0],[80,4.95],[95,0],[100,9.9]],"id":522753}],"con":true,"img":false}]}
{"op":"mcm","clk":"5348849550","pt":1646221224579,"mc":[{"id":"1.195453759","rc":[{"atb":[[6.8,0],[6,0],[6.6,4.95],[5.9,9.9]],"id":522746},{"atl":[[11.5,0]],"id":522746},{"atb":[[17.5,0],[17,9.9],[19.5,0],[19,4.95]],"id":522747},{"atl":[[13,0],[13.5,4.95],[15,0],[15.5,39.44]],"id":3805730}],"con":true,"img":false}]}
{"op":"mcm","clk":"5348849561","pt":1646221224682,"mc":[{"id":"1.195453759","rc":[{"atl":[[34,4.95],[38,0],[42,9.9],[30,5.46]],"id":3805783}],"con":true,"img":false}]}
{"op":"mcm","clk":"5348849581","pt":1646221224892,"mc":[{"id":"1.195453759","rc":[{"atl":[[320,6.58]],"id":3805783}],"con":true,"img":false}]}
{"op":"mcm","clk":"5348849596","pt":1646221224997,"mc":[{"id":"1.195453759","rc":[{"atl":[[30,0],[1000,0]],"id":3805783}],"con":true,"img":false}]}
{"op":"mcm","clk":"5348849620","pt":1646221225207,"mc":[{"id":"1.195453759","rc":[{"atl":[[80,2],[100,0]],"id":522753}],"con":true,"img":false}]}
{"op":"mcm","clk":"5348849664","pt":1646221225574,"mc":[{"id":"1.195453759","rc":[{"atl":[[160,9.15],[200,2]],"id":522753}],"con":true,"img":false}]}
{"op":"mcm","clk":"5348849695","pt":1646221225890,"mc":[{"id":"1.195453759","rc":[{"atl":[[40,4.06]],"id":3805783},{"atl":[[75,4.95],[95,9.9]],"id":522753}],"con":true,"img":false}]}
{"op":"mcm","clk":"5348849765","pt":1646221226474,"mc":[{"id":"1.195453759","rc":[{"atb":[[16.5,9.9],[17,0],[18.5,4.95],[19,0]],"id":522747},{"atl":[[70,23.06],[36,9.9]],"id":522750},{"atb":[[7.4,0]],"id":522741}],"con":true,"img":false}]}
{"op":"mcm","clk":"5348849777","pt":1646221226568,"mc":[{"id":"1.195453759","rc":[{"atl":[[12,0],[12.5,4.95],[14,20.61],[14.5,9.9]],"id":3805746},{"atl":[[23,18.67],[15.5,18.82]],"id":3805730},{"atb":[[7.2,4.95]],"id":522741}],"con":true,"img":false}]}
{"op":"mcm","clk":"5348849791","pt":1646221226716,"mc":[{"id":"1.195453759","rc":[{"atb":[[6.4,4.95],[5.8,31.99],[6.6,0],[5.9,0]],"id":522746},{"atl":[[16,9.9],[13.5,0],[14,4.95],[15.5,8.91]],"id":3805730}],"con":true,"img":false}]}
{"op":"mcm","clk":"5348849832","pt":1646221226993,"mc":[{"id":"1.195453759","rc":[{"atl":[[48,9.9],[55,28.84]],"id":3805755},{"atb":[[6.8,62.01],[7,3.27]],"id":522741}],"con":true,"img":false}]}
{"op":"mcm","clk":"5348849892","pt":1646221227396,"mc":[{"id":"1.195453759","rc":[{"atl":[[34,0],[42,0]],"id":3805783},{"atb":[[16.5,0],[18.5,0]],"id":522747},{"atl":[[75,0],[80,6.95],[95,0],[100,9.9]],"id":522753}],"con":true,"img":false}]}
{"op":"mcm","clk":"5348849926","pt":1646221227703,"mc":[{"id":"1.195453759","rc":[{"atl":[[36,4.95],[44,9.9]],"id":3805783}],"con":true,"img":false}]}
{"op":"mcm","clk":"5348849979","pt":1646221228175,"mc":[{"id":"1.195453759","rc":[{"atb":[[17,9.9],[19,4.95]],"id":522747}],"con":true,"img":false}]}
{"op":"mcm","clk":"5348850058","pt":1646221228969,"mc":[{"id":"1.195453759","rc":[{"atb":[[19,13.76]],"id":522747}],"con":true,"img":false}]}
{"op":"mcm","clk":"5348850128","pt":1646221229696,"mc":[{"id":"1.195453759","rc":[{"atl":[[13,12.21]],"id":3805746}],"con":true,"img":false}]}
{"op":"mcm","clk":"5348850145","pt":1646221229902,"mc":[{"id":"1.195453759","rc":[{"atl":[[44,12.23]],"id":3805783},{"atb":[[12,22.08]],"id":522747},{"atl":[[150,1.06]],"id":522753}],"con":true,"img":false}]}
{"op":"mcm","clk":"5348850153","pt":1646221230002,"mc":[{"id":"1.195453759","rc":[{"atl":[[320,4.58]],"id":3805783}],"con":true,"img":false}]}
{"op":"mcm","clk":"5348850162","pt":1646221230068,"mc":[{"id":"1.195453759","rc":[{"atb":[[16.5,9.9],[17,0],[18.5,4.95],[19,0]],"id":522747}],"con":true,"img":false}]}
{"op":"mcm","clk":"5348850191","pt":1646221230382,"mc":[{"id":"1.195453759","rc":[{"atl":[[13.5,29.53],[14,0]],"id":3805746}],"con":true,"img":false}]}
{"op":"mcm","clk":"5348850200","pt":1646221230491,"mc":[{"id":"1.195453759","rc":[{"atl":[[13.5,20.61]],"id":3805746},{"atb":[[15.5,15.88]],"id":522749},{"atl":[[150,10.96],[160,0]],"id":522753}],"con":true,"img":false}]}
{"op":"mcm","clk":"5348850219","pt":1646221230694,"mc":[{"id":"1.195453759","rc":[{"atl":[[34,4.8]],"id":3805783},{"atl":[[150,9.89]],"id":522753}],"con":true,"img":false}]}
{"op":"mcm","clk":"5348850232","pt":1646221230899,"mc":[{"id":"1.195453759","rc":[{"atl":[[34,7.83],[44,9.9]],"id":3805783}],"con":true,"img":false}]}
{"op":"mcm","clk":"5348850242","pt":1646221231005,"mc":[{"id":"1.195453759","rc":[{"atb":[[12,35.19]],"id":522747}],"con":true,"img":false}]}
{"op":"mcm","clk":"5348850251","pt":1646221231071,"mc":[{"id":"1.195453759","rc":[{"atl":[[34,4.8],[40,6.62]],"id":3805783}],"con":true,"img":false}]}
{"op":"mcm","clk":"5348850280","pt":1646221231390,"mc":[{"id":"1.195453759","rc":[{"atb":[[13.5,9.9]],"id":522749}],"con":true,"img":false}]}
{"op":"mcm","clk":"5348850311","pt":1646221231696,"mc":[{"id":"1.195453759","rc":[{"atl":[[40,2.56]],"id":3805783}],"con":true,"img":false}]}
{"op":"mcm","clk":"5348850357","pt":1646221232216,"mc":[{"id":"1.195453759","rc":[{"atl":[[320,0]],"id":3805783}],"con":true,"img":false}]}
{"op":"mcm","clk":"5348850368","pt":1646221232285,"mc":[{"id":"1.195453759","rc":[{"atl":[[40,19.77]],"id":3805783}],"con":true,"img":false}]}
{"op":"mcm","clk":"5348850387","pt":1646221232479,"mc":[{"id":"1.195453759","rc":[{"atl":[[65,31.99],[150,2]],"id":522747}],"con":true,"img":false}]}
{"op":"mcm","clk":"5348850476","pt":1646221233514,"mc":[{"id":"1.195453759","rc":[{"atb":[[5.7,34.89]],"id":522746},{"atb":[[9,0],[10,0]],"id":522742}],"con":true,"img":false}]}
{"op":"mcm","clk":"5348850500","pt":1646221233780,"mc":[{"id":"1.195453759","rc":[{"atl":[[16,30.52],[23,4.55]],"id":3805730}],"con":true,"img":false}]}
{"op":"mcm","clk":"5348850518","pt":1646221234009,"mc":[{"id":"1.195453759","rc":[{"atb":[[6.4,34.31]],"id":522746}],"con":true,"img":false}]}
{"op":"mcm","clk":"5348850527","pt":1646221234082,"mc":[{"id":"1.195453759","rc":[{"atl":[[34,0]],"id":3805783},{"atl":[[40,0],[42,4.95],[48,0],[50,9.9]],"id":3805755},{"atb":[[5.8,90.43],[7.8,16.81]],"id":522742}],"con":true,"img":false}]}
{"op":"mcm","clk":"5348850536","pt":1646221234193,"mc":[{"id":"1.195453759","rc":[{"atl":[[14,17.15]],"id":3805730},{"atb":[[9.8,2.72],[8.8,3.27]],"id":522742}],"con":true,"img":false}]}
{"op":"mcm","clk":"5348850597","pt":1646221234880,"mc":[{"id":"1.195453759","rc":[{"atl":[[38,4.28]],"id":3805783},{"atl":[[50,13.14]],"id":3805755},{"atb":[[5.8,9.9]],"id":522746}],"con":true,"img":false}]}
{"op":"mcm","clk":"5348850608","pt":1646221234976,"mc":[{"id":"1.195453759","rc":[{"atb":[[6.4,0],[5.8,0],[6.2,4.95],[5.7,44.8]],"id":522746}],"con":true,"img":false}]}
{"op":"mcm","clk":"5348850620","pt":1646221235105,"mc":[{"id":"1.195453759","rc":[{"atl":[[15.5,0]],"id":3805730}],"con":true,"img":false}]}
{"op":"mcm","clk":"5348850692","pt":1646221235709,"mc":[{"id":"1.195453759","rc":[{"atl":[[16,20.61],[14,0]],"id":3805730},{"atl":[[80,0],[85,4.95],[100,0],[110,9.9]],"id":522753}],"con":true,"img":false}]}
{"op":"mcm","clk":"5348850726","pt":1646221235995,"mc":[{"id":"1.195453759","rc":[{"atl":[[42,0],[44,4.95],[50,3.23],[55,38.75]],"id":3805755},{"atb":[[5.2,17.98]],"id":522746},{"atl":[[16.5,9.9],[14.5,4.95]],"id":3805730}],"con":true,"img":false}]}
{"op":"mcm","clk":"5348850744","pt":1646221236192,"mc":[{"id":"1.195453759","rc":[{"atl":[[65,2],[55,36.75]],"id":3805755}],"con":true,"img":false}]}
{"op":"mcm","clk":"5348850757","pt":1646221236292,"mc":[{"id":"1.195453759","rc":[{"atl":[[36,9.48]],"id":3805783}],"con":true,"img":false}]}
{"op":"mcm","clk":"5348850806","pt":1646221236610,"mc":[{"id":"1.195453759","rc":[{"atl":[[22,7.54]],"id":3805730},{"atl":[[85,6.83]],"id":522753}],"con":true,"img":false}]}
{"op":"mcm","clk":"5348850879","pt":1646221237308,"mc":[{"id":"1.195453759","rc":[{"atl":[[38,0]],"id":3805783}],"con":true,"img":false}]}
{"op":"mcm","clk":"5348850940","pt":1646221237832,"mc":[{"id":"1.195453759","rc":[{"atb":[[11,0],[13.5,0]],"id":522752},{"atl":[[21,7.93],[25,0]],"id":522741}],"con":true,"img":false}]}
{"op":"mcm","clk":"5348850960","pt":1646221238037,"mc":[{"id":"1.195453759","rc":[{"atl":[[20,4.95],[24,9.9]],"id":522741},{"atl":[[44,4.95],[46,3.52],[55,9.9],[60,0]],"id":522743}],"con":true,"img":false}]}
{"op":"mcm","clk":"5348850991","pt":1646221238297,"mc":[{"id":"1.195453759","rc":[{"atb":[[9.8,38.1],[5.9,106.57]],"id":522752},{"atl":[[40,2.56],[23,14.71]],"id":522741}],"con":true,"img":false}]}
{"op":"mcm","clk":"5348850999","pt":1646221238402,"mc":[{"id":"1.195453759","rc":[{"atl":[[36,0],[40,24.72],[44,0],[48,9.9]],"id":3805783},{"atl":[[12.5,0],[13,17.17],[14.5,0]],"id":3805746},{"atl":[[44,0],[46,4.95],[55,26.84],[60,9.9]],"id":3805755},{"atb":[[5.6,9.9],[6.2,0],[6,4.95],[5.7,34.89]],"id":522746},{"atl":[[16.5,0],[17.5,9.9],[14.5,0],[15.5,4.95]],"id":3805730}],"con":true,"img":false}]}
{"op":"mcm","clk":"5348851022","pt":1646221238506,"mc":[{"id":"1.195453759","rc":[{"atl":[[20,13.29]],"id":522741},{"atl":[[150,2],[42,3.86],[55,26.68]],"id":522743}],"con":true,"img":false}]}
{"op":"mcm","clk":"5348851032","pt":1646221238611,"mc":[{"id":"1.195453759","rc":[{"atl":[[40,22.16],[44,2.33]],"id":3805783},{"atb":[[10.5,3.27],[13,2.72]],"id":522752}],"con":true,"img":false}]}
{"op":"mcm","clk":"5348851060","pt":1646221238881,"mc":[{"id":"1.195453759","rc":[{"atl":[[70,23.56],[13.5,0]],"id":3805746}],"con":true,"img":false}]}
{"op":"mcm","clk":"5348851082","pt":1646221239082,"mc":[{"id":"1.195453759","rc":[{"atl":[[40,9.02],[48,36.85]],"id":3805783},{"atl":[[15,9.9]],"id":3805746}],"con":true,"img":false}]}
{"op":"mcm","clk":"5348851092","pt":1646221239185,"mc":[{"id":"1.195453759","rc":[{"atb":[[7.2,0],[7,8.22]],"id":522741},{"atl":[[21,0]],"id":522741}],"con":true,"img":false}]}
{"op":"mcm","clk":"5348851106","pt":1646221239291,"mc":[{"id":"1.195453759","rc":[{"atl":[[46,0],[55,9.9]],"id":522743}],"con":true,"img":false}]}
{"op":"mcm","clk":"5348851179","pt":1646221240116,"mc":[{"id":"1.195453759","rc":[{"atb":[[6.2,9.9]],"id":522741}],"con":true,"img":false}]}
{"op":"mcm","clk":"5348851210","pt":1646221240381,"mc":[{"id":"1.195453759","rc":[{"atb":[[5.6,49.44]],"id":522746}],"con":true,"img":false}]}
{"op":"mcm","clk":"5348851224","pt":1646221240524,"mc":[{"id":"1.195453759","rc":[{"atb":[[5.7,2.72]],"id":522746}],"con":true,"img":false}]}
{"op":"mcm","clk":"5348851247","pt":1646221240695,"mc":[{"id":"1.195453759","rc":[{"atl":[[16,0]],"id":3805730}],"con":true,"img":false}]}
{"op":"mcm","clk":"5348851256","pt":1646221240795,"mc":[{"id":"1.195453759","rc":[{"atl":[[17.5,31.99]],"id":3805730}],"con":true,"img":false}]}
{"op":"mcm","clk":"5348851437","pt":1646221242426,"mc":[{"id":"1.195453759","rc":[{"atl":[[65,0],[60,11.9]],"id":3805755}],"con":true,"img":false}]}
{"op":"mcm","clk":"5348851499","pt":1646221242900,"mc":[{"id":"1.195453759","rc":[{"atb":[[18.5,14.01]],"id":522747}],"con":true,"img":false}]}
{"op":"mcm","clk":"5348851555","pt":1646221243419,"mc":[{"id":"1.195453759","rc":[{"atb":[[10.5,3.27],[9.4,0]],"id":3805783}],"con":true,"img":false}]}
{"op":"mcm","clk":"5348851588","pt":1646221243683,"mc":[{"id":"1.195453759","rc":[{"atl":[[44,0],[48,38.98]],"id":3805783}],"con":true,"img":false}]}
{"op":"mcm","clk":"5348851600","pt":1646221243791,"mc":[{"id":"1.195453759","rc":[{"atb":[[9.6,9.9],[11,4.95]],"id":3805783},{"atb":[[12,22.08]],"id":522747}],"con":true,"img":false}]}
{"op":"mcm","clk":"5348851648","pt":1646221244312,"mc":[{"id":"1.195453759","rc":[{"atb":[[10.5,17.98],[9.8,15.13]],"id":3805783}],"con":true,"img":false}]}
{"op":"mcm","clk":"5348851751","pt":1646221245308,"mc":[{"id":"1.195453759","rc":[{"atl":[[23,0],[24,44.4]],"id":522741}],"con":true,"img":false}]}
{"op":"mcm","clk":"5348851789","pt":1646221245677,"mc":[{"id":"1.195453759","rc":[{"atb":[[5.6,0],[6.2,0]],"id":3805746}],"con":true,"img":false}]}
{"op":"mcm","clk":"5348851857","pt":1646221246312,"mc":[{"id":"1.195453759","rc":[{"atb":[[4.9,70.46],[5.4,29.45]],"id":3805746}],"con":true,"img":false}]}
{"op":"mcm","clk":"5348851871","pt":1646221246416,"mc":[{"id":"1.195453759","rc":[{"atl":[[44,26.81],[48,12.03]],"id":3805783}],"con":true,"img":false}]}
{"op":"mcm","clk":"5348851891","pt":1646221246627,"mc":[{"id":"1.195453759","rc":[{"atl":[[42,2.44]],"id":3805783}],"con":true,"img":false}]}
{"op":"mcm","clk":"5348851903","pt":1646221246735,"mc":[{"id":"1.195453759","rc":[{"atl":[[48,9.9]],"id":3805783},{"atb":[[6.4,2.72],[5.7,3.27]],"id":3805746}],"con":true,"img":false}]}
{"op":"mcm","clk":"5348851982","pt":1646221247531,"mc":[{"id":"1.195453759","rc":[{"atl":[[17.5,9.9]],"id":3805730}],"con":true,"img":false}]}
{"op":"mcm","clk":"5348852013","pt":1646221247782,"mc":[{"id":"1.195453759","rc":[{"atl":[[22,26.12]],"id":3805730}],"con":true,"img":false}]}
{"op":"mcm","clk":"5348852025","pt":1646221247892,"mc":[{"id":"1.195453759","rc":[{"atb":[[6,36.66]],"id":522746}],"con":true,"img":false}]}
{"op":"mcm","clk":"5348852051","pt":1646221248117,"mc":[{"id":"1.195453759","rc":[{"atb":[[5.8,27.75]],"id":522742}],"con":true,"img":false}]}
{"op":"mcm","clk":"5348852065","pt":1646221248217,"mc":[{"id":"1.195453759","rc":[{"atl":[[15.5,15.88]],"id":3805730},{"atb":[[7.8,45.6]],"id":522742}],"con":true,"img":false}]}
{"op":"mcm","clk":"5348852132","pt":1646221248828,"mc":[{"id":"1.195453759","rc":[{"atl":[[44,3.68]],"id":3805755},{"atb":[[5.2,3.27]],"id":522746}],"con":true,"img":false}]}
{"op":"mcm","clk":"5348852167","pt":1646221249094,"mc":[{"id":"1.195453759","rc":[{"atl":[[22,18.57]],"id":3805730}],"con":true,"img":false}]}
{"op":"mcm","clk":"5348852200","pt":1646221249407,"mc":[{"id":"1.195453759","rc":[{"atl":[[50,17.95],[55,0]],"id":3805755}],"con":true,"img":false}]}
{"op":"mcm","clk":"5348852230","pt":1646221249724,"mc":[{"id":"1.195453759","rc":[{"atl":[[50,14.71]],"id":3805755}],"con":true,"img":false}]}
{"op":"mcm","clk":"5348852353","pt":1646221250917,"mc":[{"id":"1.195453759","rc":[{"atl":[[44,0]],"id":3805755}],"con":true,"img":false}]}
{"op":"mcm","clk":"5348852459","pt":1646221251816,"mc":[{"id":"1.195453759","rc":[{"atl":[[42,0],[44,29.14]],"id":3805783}],"con":true,"img":false}]}
{"op":"mcm","clk":"5348852475","pt":1646221251917,"mc":[{"id":"1.195453759","rc":[{"atl":[[48,3.37]],"id":3805755}],"con":true,"img":false}]}
{"op":"mcm","clk":"5348852484","pt":1646221252024,"mc":[{"id":"1.195453759","rc":[{"atl":[[44,26.81],[48,12.03]],"id":3805783}],"con":true,"img":false}]}
{"op":"mcm","clk":"5348852506","pt":1646221252186,"mc":[{"id":"1.195453759","rc":[{"atb":[[9.8,70.91],[5.9,54.37]],"id":522752},{"atl":[[40,34.54],[24,9.9]],"id":522741},{"atl":[[55,26.68]],"id":522743}],"con":true,"img":false}]}
{"op":"mcm","clk":"5348852594","pt":1646221253035,"mc":[{"id":"1.195453759","rc":[{"atb":[[9.8,0],[4.9,0],[5.9,0]],"id":3805783},{"atb":[[5.3,4.95],[3.15,0],[3.65,0]],"id":3805746},{"atb":[[5.7,0],[9.4,0],[4.7,0]],"id":3805755},{"atb":[[2.88,0],[3.7,0],[2.68,0]],"id":522746},{"atb":[[2.88,0],[3.7,0],[2.68,0]],"id":3805736},{"atb":[[3.6,0],[6.4,0],[4.2,0]],"id":522747},{"atb":[[4.5,0],[7,0],[3.75,0]],"id":522749},{"atb":[[5.7,0],[9.4,0],[4.7,0]],"id":522750},{"atb":[[9.8,55.77],[4.9,0],[5.9,0]],"id":522752},{"atb":[[5.8,0],[3.4,0],[3.9,0]],"id":3805730},{"atb":[[17,0],[6.8,0],[8.8,0]],"id":522753},{"atb":[[2.82,0],[4.1,0],[3.05,0]],"id":522741},{"atb":[[5.8,0],[3.4,0],[3.9,0]],"id":522742},{"atb":[[6.4,0],[11,0],[5.2,0]],"id":522743},{"atb":[[5.3,0],[11.5,0],[6.6,17.86]],"id":522745}],"con":true,"img":false}]}
{"op":"mcm","clk":"5348852624","pt":1646221253328,"mc":[{"id":"1.195453759","rc":[{"atl":[[44,0],[48,43.34]],"id":3805783}],"con":true,"img":false}]}
{"op":"mcm","clk":"5348852743","pt":1646221254433,"mc":[{"id":"1.195453759","rc":[{"atl":[[48,12.03]],"id":3805783}],"con":true,"img":false}]}
{"op":"mcm","clk":"5348852778","pt":1646221254694,"mc":[{"id":"1.195453759","rc":[{"atl":[[38,4.95],[40,4.06],[46,9.9],[48,2.13]],"id":3805783}],"con":true,"img":false}]}
{"op":"mcm","clk":"5348852841","pt":1646221255326,"mc":[{"id":"1.195453759","rc":[{"atl":[[38,9.23]],"id":3805783}],"con":true,"img":false}]}
{"op":"mcm","clk":"5348852915","pt":1646221256102,"mc":[{"id":"1.195453759","rc":[{"atl":[[40,0]],"id":3805783}],"con":true,"img":false}]}
{"op":"mcm","clk":"5348852986","pt":1646221256737,"mc":[{"id":"1.195453759","rc":[{"atb":[[16.5,0],[18.5,9.05]],"id":522747}],"con":true,"img":false}]}
{"op":"mcm","clk":"5348853020","pt":1646221257050,"mc":[{"id":"1.195453759","rc":[{"atb":[[17,9.9],[19,4.95]],"id":522747}],"con":true,"img":false}]}
{"op":"mcm","clk":"5348853032","pt":1646221257143,"mc":[{"id":"1.195453759","rc":[{"atb":[[10,11.11],[10.5,0]],"id":522747}],"con":true,"img":false}]}
{"op":"mcm","clk":"5348853069","pt":1646221257426,"mc":[{"id":"1.195453759","rc":[{"atb":[[11.5,23.55],[12,0]],"id":522747}],"con":true,"img":false}]}
{"op":"mcm","clk":"5348853102","pt":1646221257745,"mc":[{"id":"1.195453759","rc":[{"atl":[[12.5,4.95],[13,12.21],[14.5,9.9],[15,0]],"id":3805746},{"atb":[[19,13.76]],"id":522747},{"atl":[[21,4.95],[23,7.2],[25,9.9],[27,0]],"id":522752},{"atb":[[7.2,4.95],[6.4,9.9],[6.2,0],[7,3.27]],"id":522741},{"atl":[[12,19.36],[12.5,0],[14,45.16],[14.5,0]],"id":522742}],"con":true,"img":false}]}
{"op":"mcm","clk":"5348853159","pt":1646221258258,"mc":[{"id":"1.195453759","rc":[{"atl":[[70,2],[14.5,31.99]],"id":3805746},{"atb":[[6.8,17.24],[7,25.35]],"id":522741},{"atl":[[34,36.68],[14,9.9]],"id":522742}],"con":true,"img":false}]}
{"op":"mcm","clk":"5348853170","pt":1646221258319,"mc":[{"id":"1.195453759","rc":[{"atl":[[12.5,18.74]],"id":3805746},{"atl":[[70,2],[21,12.88],[25,27.98]],"id":522752}],"con":true,"img":false}]}
{"op":"mcm","clk":"5348853189","pt":1646221258418,"mc":[{"id":"1.195453759","rc":[{"atl":[[46,0],[60,2]],"id":3805755},{"atb":[[18.5,0]],"id":522747},{"atl":[[36,0],[26,4.95],[29,5.66],[30,9.9]],"id":522750}],"con":true,"img":false}]}
{"op":"mcm","clk":"5348853233","pt":1646221258536,"mc":[{"id":"1.195453759","rc":[{"atl":[[44,4.95],[55,9.9]],"id":3805755}],"con":true,"img":false}]}
{"op":"mcm","clk":"5348853271","pt":1646221258946,"mc":[{"id":"1.195453759","rc":[{"atl":[[50,0],[60,28.1]],"id":3805755},{"atl":[[70,2],[25,6.6],[30,33.04]],"id":522750}],"con":true,"img":false}]}
{"op":"mcm","clk":"5348853297","pt":1646221259219,"mc":[{"id":"1.195453759","rc":[{"atl":[[13,0]],"id":3805746},{"atl":[[23,0]],"id":522752}],"con":true,"img":false}]}
{"op":"mcm","clk":"5348853356","pt":1646221259844,"mc":[{"id":"1.195453759","rc":[{"atl":[[29,0]],"id":522750}],"con":true,"img":false}]}
{"op":"mcm","clk":"5348853405","pt":1646221260258,"mc":[{"id":"1.195453759","rc":[{"atl":[[48,23.22]],"id":3805783},{"atb":[[4.9,9.9],[5.4,62.17]],"id":3805746}],"con":true,"img":false}]}
{"op":"mcm","clk":"5348853470","pt":1646221260735,"mc":[{"id":"1.195453759","rc":[{"atl":[[150,0],[100,2]],"id":522747},{"atb":[[2.52,0],[2.7,58.82]],"id":3805730},{"atb":[[6.6,0],[7.8,14.71]],"id":522745}],"con":true,"img":false}]}
{"op":"mcm","clk":"5348853636","pt":1646221262457,"mc":[{"id":"1.195453759","rc":[{"atl":[[44,8.64]],"id":3805755}],"con":true,"img":false}]}
{"op":"mcm","clk":"5348853651","pt":1646221262672,"mc":[{"id":"1.195453759","rc":[{"atb":[[9.8,15.13],[4.9,68.3],[5.9,54.37]],"id":3805783},{"atb":[[5.3,35.93],[3.15,123.9],[3.65,100.52]],"id":3805746},{"atb":[[5.7,56.68],[9.4,15.86],[4.7,72]],"id":3805755},{"atb":[[2.88,141.7],[3.7,49.33],[2.68,158.57]],"id":522746},{"atb":[[2.88,141.7],[3.7,49.33],[2.68,158.57]],"id":3805736},{"atb":[[3.6,102.46],[6.4,24.66],[4.2,83.25]],"id":522747},{"atb":[[4.5,76.11],[7,22.19],[3.75,96.87]],"id":522749},{"atb":[[5.7,56.68],[9.4,15.86],[4.7,72]],"id":522750},{"atb":[[9.8,70.91],[4.9,68.3],[5.9,54.37]],"id":522752},{"atb":[[5.8,27.75],[3.4,111],[3.9,91.86]],"id":3805730},{"atb":[[17,8.32],[6.8,45.93],[8.8,34.15]],"id":522753},{"atb":[[2.82,146.37],[4.1,42.96],[3.05,129.95]],"id":522741},{"atb":[[5.8,27.75],[3.4,111],[3.9,91.86]],"id":522742},{"atb":[[6.4,49.33],[11,13.32],[5.2,63.42]],"id":522743},{"atb":[[5.3,61.95],[11.5,12.68],[6.6,47.57]],"id":522745}],"con":true,"img":false}]}
{"op":"mcm","clk":"5348853696","pt":1646221263147,"mc":[{"id":"1.195453759","rc":[{"atl":[[55,31.99]],"id":3805755}],"con":true,"img":false}]}
{"op":"mcm","clk":"5348853725","pt":1646221263463,"mc":[{"id":"1.195453759","rc":[{"atl":[[48,0],[60,2]],"id":3805755}],"con":true,"img":false}]}
{"op":"mcm","clk":"5348853808","pt":1646221264256,"mc":[{"id":"1.195453759","rc":[{"atl":[[55,9.9]],"id":3805755}],"con":true,"img":false}]}
{"op":"mcm","clk":"5348853868","pt":1646221264834,"mc":[{"id":"1.195453759","rc":[{"atl":[[70,24.61]],"id":3805746},{"atl":[[70,24.61],[25,9.9]],"id":522752}],"con":true,"img":false}]}
{"op":"mcm","clk":"5348853877","pt":1646221264929,"mc":[{"id":"1.195453759","rc":[{"atl":[[14.5,9.9]],"id":3805746}],"con":true,"img":false}]}
{"op":"mcm","clk":"5348854474","pt":1646221270766,"mc":[{"id":"1.195453759","rc":[{"atl":[[85,1.88],[110,0]],"id":522753}],"con":true,"img":false}]}
{"op":"mcm","clk":"5348854483","pt":1646221270856,"mc":[{"id":"1.195453759","rc":[{"atl":[[80,4.95],[100,9.9]],"id":522753}],"con":true,"img":false}]}
{"op":"mcm","clk":"5348854491","pt":1646221270958,"mc":[{"id":"1.195453759","rc":[{"atb":[[17,0],[17.5,9.9],[19,8.8],[19.5,4.95]],"id":522747}],"con":true,"img":false}]}
{"op":"mcm","clk":"5348854526","pt":1646221271230,"mc":[{"id":"1.195453759","rc":[{"atl":[[150,0],[200,10]],"id":522753}],"con":true,"img":false}]}
{"op":"mcm","clk":"5348854548","pt":1646221271439,"mc":[{"id":"1.195453759","rc":[{"atb":[[17.5,30.36],[19.5,13.52],[11.5,2.72]],"id":522747},{"atl":[[80,6.95]],"id":522753}],"con":true,"img":false}]}
{"op":"mcm","clk":"5348854603","pt":1646221272060,"mc":[{"id":"1.195453759","rc":[{"atl":[[200,2]],"id":522753}],"con":true,"img":false}]}
{"op":"mcm","clk":"5348854632","pt":1646221272340,"mc":[{"id":"1.195453759","rc":[{"atl":[[60,28.73]],"id":3805755},{"atb":[[19,0]],"id":522747},{"atl":[[85,0]],"id":522753}],"con":true,"img":false}]}
{"op":"mcm","clk":"5348854803","pt":1646221273856,"mc":[{"id":"1.195453759","rc":[{"atl":[[65,22.08],[48,0]],"id":522747}],"con":true,"img":false}]}
{"op":"mcm","clk":"5348854845","pt":1646221274160,"mc":[{"id":"1.195453759","rc":[{"atl":[[44,4.95],[55,9.9]],"id":522747}],"con":true,"img":false}]}
{"op":"mcm","clk":"5348854878","pt":1646221274471,"mc":[{"id":"1.195453759","rc":[{"atl":[[65,0]],"id":522747}],"con":true,"img":false}]}
{"op":"mcm","clk":"5348854890","pt":1646221274533,"mc":[{"id":"1.195453759","rc":[{"atl":[[100,18.09]],"id":522747}],"con":true,"img":false}]}
{"op":"mcm","clk":"5348854952","pt":1646221275062,"mc":[{"id":"1.195453759","rc":[{"atb":[[6.2,4.95],[5.7,12.63]],"id":522746},{"atl":[[16.5,9.9],[17.5,0],[14.5,4.95],[15.5,10.93]],"id":3805730}],"con":true,"img":false}]}
{"op":"mcm","clk":"5348854962","pt":1646221275158,"mc":[{"id":"1.195453759","rc":[{"atb":[[5.6,39.54],[6,31.7]],"id":522746}],"con":true,"img":false}]}
{"op":"mcm","clk":"5348854982","pt":1646221275365,"mc":[{"id":"1.195453759","rc":[{"atb":[[7.2,0],[8.6,13.16]],"id":522749}],"con":true,"img":false}]}
{"op":"mcm","clk":"5348855001","pt":1646221275565,"mc":[{"id":"1.195453759","rc":[{"atb":[[5.6,0]],"id":522746}],"con":true,"img":false}]}
{"op":"mcm","clk":"5348855021","pt":1646221275732,"mc":[{"id":"1.195453759","rc":[{"atb":[[6.2,35.44],[5.7,56.21]],"id":522746},{"atl":[[16.5,31.99],[22,0],[14.5,16.69]],"id":3805730}],"con":true,"img":false}]}
{"op":"mcm","clk":"5348855053","pt":1646221276056,"mc":[{"id":"1.195453759","rc":[{"atl":[[12,4.95],[12.5,13.78],[14,9.9],[14.5,0]],"id":3805746}],"con":true,"img":false}]}
{"op":"mcm","clk":"5348855129","pt":1646221276776,"mc":[{"id":"1.195453759","rc":[{"atl":[[70,2],[12,19.36],[14,31.99]],"id":3805746},{"atb":[[6,0]],"id":522746},{"atl":[[15.5,0]],"id":3805730}],"con":true,"img":false}]}
{"op":"mcm","clk":"5348855230","pt":1646221277837,"mc":[{"id":"1.195453759","rc":[{"atl":[[12.5,0]],"id":3805746}],"con":true,"img":false}]}
{"op":"mcm","clk":"5348855258","pt":1646221278152,"mc":[{"id":"1.195453759","rc":[{"atb":[[17.5,9.9],[11.5,24.81]],"id":522747}],"con":true,"img":false}]}
{"op":"mcm","clk":"5348855506","pt":1646221280755,"mc":[{"id":"1.195453759","rc":[{"atb":[[13.5,0],[15.5,10.93]],"id":522749}],"con":true,"img":false}]}
{"op":"mcm","clk":"5348855544","pt":1646221281171,"mc":[{"id":"1.195453759","rc":[{"atb":[[16,4.95],[14,9.9]],"id":522749}],"con":true,"img":false}]}
{"op":"mcm","clk":"5348855578","pt":1646221281446,"mc":[{"id":"1.195453759","rc":[{"atb":[[11,2.72],[9.4,35]],"id":522749}],"con":true,"img":false}]}
{"op":"mcm","clk":"5348855613","pt":1646221281863,"mc":[{"id":"1.195453759","rc":[{"atb":[[16.5,10.22]],"id":522749}],"con":true,"img":false}]}
{"op":"mcm","clk":"5348855631","pt":1646221282069,"mc":[{"id":"1.195453759","rc":[{"atb":[[5.2,80.75],[5.7,12.63]],"id":522746}],"con":true,"img":false}]}
{"op":"mcm","clk":"5348855640","pt":1646221282173,"mc":[{"id":"1.195453759","rc":[{"atb":[[9.4,3.27]],"id":522749},{"atl":[[16.5,9.9],[23,36.13]],"id":3805730}],"con":true,"img":false}]}
{"op":"mcm","clk":"5348855679","pt":1646221282592,"mc":[{"id":"1.195453759","rc":[{"atb":[[15.5,0]],"id":522749}],"con":true,"img":false}]}
{"op":"mcm","clk":"5348855739","pt":1646221283082,"mc":[{"id":"1.195453759","rc":[{"atl":[[14,9.9]],"id":3805746}],"con":true,"img":false}]}
{"op":"mcm","clk":"5348855776","pt":1646221283443,"mc":[{"id":"1.195453759","rc":[{"atl":[[70,25.35]],"id":3805746}],"con":true,"img":false}]}
{"op":"mcm","clk":"5348855800","pt":1646221283655,"mc":[{"id":"1.195453759","rc":[{"atl":[[60,26.73]],"id":3805755},{"atb":[[8.6,0],[7.4,15.62]],"id":522749}],"con":true,"img":false}]}
{"op":"mcm","clk":"5348855813","pt":1646221283761,"mc":[{"id":"1.195453759","rc":[{"atl":[[75,2]],"id":3805755}],"con":true,"img":false}]}
{"op":"mcm","clk":"5348855834","pt":1646221283967,"mc":[{"id":"1.195453759","rc":[{"atb":[[5.3,30.97],[4.9,0],[5.4,67.12]],"id":3805746},{"atb":[[13,34.31],[13.5,9.9],[15,0],[15.5,15.88]],"id":3805755},{"atb":[[8,22.08],[5.6,0],[7.2,0],[6.2,22.08],[8.2,4.95],[7.4,9.9]],"id":3805736},{"atb":[[9.8,0],[8.8,0]],"id":522742}],"con":true,"img":false}]}
{"op":"mcm","clk":"5348855860","pt":1646221284173,"mc":[{"id":"1.195453759","rc":[{"atl":[[32,4.95],[34,4.8],[40,9.9],[42,0]],"id":522745}],"con":true,"img":false}]}
{"op":"mcm","clk":"5348855892","pt":1646221284449,"mc":[{"id":"1.195453759","rc":[{"atb":[[6.2,0],[7.4,51.64],[8.4,21.42]],"id":3805736},{"atl":[[200,10.18]],"id":522753},{"atb":[[5.8,97.79],[7.8,16.81]],"id":522742}],"con":true,"img":false}]}
{"op":"mcm","clk":"5348855917","pt":1646221284656,"mc":[{"id":"1.195453759","rc":[{"atb":[[16,2.72],[13.5,13.17]],"id":3805755},{"atb":[[6.4,2.72],[5.7,3.27]],"id":3805736},{"atb":[[8.4,3.27],[9.4,2.72]],"id":522742},{"atl":[[32,10.06],[40,30.36],[100,2]],"id":522745}],"con":true,"img":false}]}
{"op":"mcm","clk":"5348855977","pt":1646221285175,"mc":[{"id":"1.195453759","rc":[{"atb":[[16.5,10.22],[13,0],[13.5,47.49]],"id":3805755}],"con":true,"img":false}]}
{"op":"mcm","clk":"5348855994","pt":1646221285282,"mc":[{"id":"1.195453759","rc":[{"atb":[[8,0]],"id":3805736},{"atb":[[5.8,27.75]],"id":522742}],"con":true,"img":false}]}
{"op":"mcm","clk":"5348856024","pt":1646221285448,"mc":[{"id":"1.195453759","rc":[{"atl":[[34,0]],"id":522745}],"con":true,"img":false}]}
{"op":"mcm","clk":"5348856079","pt":1646221285963,"mc":[{"id":"1.195453759","rc":[{"atb":[[15.5,4.95]],"id":3805755}],"con":true,"img":false}]}
{"op":"mcm","clk":"5348856235","pt":1646221287576,"mc":[{"id":"1.195453759","rc":[{"atl":[[100,2]],"id":522747}],"con":true,"img":false}]}
{"op":"mcm","clk":"5348856281","pt":1646221287950,"mc":[{"id":"1.195453759","rc":[{"atl":[[55,39.36]],"id":522747}],"con":true,"img":false}]}
{"op":"mcm","clk":"5348856625","pt":1646221291071,"mc":[{"id":"1.195453759","rc":[{"atl":[[40,9.9],[100,18.56]],"id":522745}],"con":true,"img":false}]}
{"op":"mcm","clk":"5348856838","pt":1646221292966,"mc":[{"id":"1.195453759","rc":[{"atl":[[19,4.95],[20,8.34],[22,9.9],[24,0]],"id":522741}],"con":true,"img":false}]}
{"op":"mcm","clk":"5348856914","pt":1646221293584,"mc":[{"id":"1.195453759","rc":[{"atl":[[18.5,9.05],[40,2.56],[22,29.66]],"id":522741}],"con":true,"img":false}]}
{"op":"mcm","clk":"5348857011","pt":1646221294277,"mc":[{"id":"1.195453759","rc":[{"atl":[[20,0]],"id":522741}],"con":true,"img":false}]}
{"op":"mcm","clk":"5348857045","pt":1646221294591,"mc":[{"id":"1.195453759","rc":[{"atb":[[14,39.84]],"id":522749},{"atb":[[10.5,0],[13,0]],"id":522752}],"con":true,"img":false}]}
{"op":"mcm","clk":"5348857122","pt":1646221295274,"mc":[{"id":"1.195453759","rc":[{"atb":[[11,3.27],[9.8,38.1],[13.5,2.72],[5.9,110.11]],"id":522752}],"con":true,"img":false}]}
{"op":"mcm","clk":"5348857272","pt":1646221296691,"mc":[{"id":"1.195453759","rc":[{"atb":[[8.6,13.16],[7.4,0]],"id":522749}],"con":true,"img":false}]}
{"op":"mcm","clk":"5348857293","pt":1646221296861,"mc":[{"id":"1.195453759","rc":[{"atl":[[44,0],[46,4.95],[55,29.45],[60,9.9]],"id":522747}],"con":true,"img":false}]}
{"op":"mcm","clk":"5348857338","pt":1646221297278,"mc":[{"id":"1.195453759","rc":[{"atb":[[7.8,56.52]],"id":522742}],"con":true,"img":false}]}
{"op":"mcm","clk":"5348857373","pt":1646221297588,"mc":[{"id":"1.195453759","rc":[{"atl":[[21,0],[22,4.95],[25,0],[26,9.9]],"id":522752}],"con":true,"img":false}]}
{"op":"mcm","clk":"5348857454","pt":1646221298177,"mc":[{"id":"1.195453759","rc":[{"atb":[[13.5,13.17],[15.5,32.52]],"id":3805755}],"con":true,"img":false}]}
{"op":"mcm","clk":"5348857465","pt":1646221298281,"mc":[{"id":"1.195453759","rc":[{"atl":[[25,6.6]],"id":522752}],"con":true,"img":false}]}
{"op":"mcm","clk":"5348857474","pt":1646221298382,"mc":[{"id":"1.195453759","rc":[{"atl":[[21,4.95],[22,0],[25,16.51],[26,0]],"id":522752}],"con":true,"img":false}]}
{"op":"mcm","clk":"5348857515","pt":1646221298792,"mc":[{"id":"1.195453759","rc":[{"atb":[[8.6,0],[7.4,15.62]],"id":522749},{"atl":[[70,2],[26,17.18]],"id":522752}],"con":true,"img":false}]}
{"op":"mcm","clk":"5348857782","pt":1646221301397,"mc":[{"id":"1.195453759","rc":[{"atl":[[70,0]],"id":522752},{"atb":[[2.88,53.19],[2.7,0]],"id":3805730},{"atb":[[6.8,0],[5.7,21.28]],"id":522741},{"atb":[[4.5,28.57],[3.85,0]],"id":522743}],"con":true,"img":false}]}
{"op":"mcm","clk":"5348857791","pt":1646221301461,"mc":[{"id":"1.195453759","rc":[{"atl":[[36,2.86]],"id":522752}],"con":true,"img":false}]}
{"op":"mcm","clk":"5348857828","pt":1646221301875,"mc":[{"id":"1.195453759","rc":[{"atb":[[6.4,0],[5.7,0]],"id":3805746}],"con":true,"img":false}]}
{"op":"mcm","clk":"5348857838","pt":1646221301980,"mc":[{"id":"1.195453759","rc":[{"atb":[[9,0],[10,4.95],[9.2,9.9],[9.8,33.15]],"id":522752},{"atb":[[19.5,9.9],[21,27.33],[23,4.95],[25,0]],"id":522743},{"atb":[[16.5,0],[17.5,36.05],[18.5,0]],"id":522745}],"con":true,"img":false}]}
{"op":"mcm","clk":"5348857861","pt":1646221302191,"mc":[{"id":"1.195453759","rc":[{"atl":[[36,4.95],[38,4.28],[44,9.9],[46,0]],"id":3805783},{"atb":[[17.5,0],[18,9.9],[19.5,8.56],[20,4.95]],"id":522747},{"atl":[[36,9.9],[29,4.95]],"id":522749}],"con":true,"img":false}]}
{"op":"mcm","clk":"5348857872","pt":1646221302294,"mc":[{"id":"1.195453759","rc":[{"atl":[[38,0],[30,5.46]],"id":522749},{"atl":[[80,0],[85,4.95],[100,0],[110,9.9]],"id":522753}],"con":true,"img":false}]}
{"op":"mcm","clk":"5348857883","pt":1646221302398,"mc":[{"id":"1.195453759","rc":[{"atl":[[36,7.81],[48,21.09]],"id":3805783},{"atb":[[3.7,120.77]],"id":3805746}],"con":true,"img":false}]}
{"op":"mcm","clk":"5348857896","pt":1646221302495,"mc":[{"id":"1.195453759","rc":[{"atb":[[5.4,34.41]],"id":3805746},{"atb":[[17.5,7.67],[15,32.96]],"id":522745}],"con":true,"img":false}]}
{"op":"mcm","clk":"5348857906","pt":1646221302600,"mc":[{"id":"1.195453759","rc":[{"atb":[[6.8,2.72],[5.9,3.27]],"id":3805746}],"con":true,"img":false}]}
{"op":"mcm","clk":"5348857916","pt":1646221302704,"mc":[{"id":"1.195453759","rc":[{"atl":[[34,4.8],[44,24.62],[48,0]],"id":3805783},{"atb":[[18,30],[20,13.29],[11.5,2.72]],"id":522747},{"atl":[[36,39.84],[90,2],[29,10.61]],"id":522749},{"atl":[[25,0]],"id":522750},{"atl":[[21,0],[22,4.95],[25,6.6],[26,27.09]],"id":522752}],"con":true,"img":false}]}
{"op":"mcm","clk":"5348857930","pt":1646221302774,"mc":[{"id":"1.195453759","rc":[{"atb":[[15.5,9.9]],"id":522745}],"con":true,"img":false}]}
{"op":"mcm","clk":"5348857967","pt":1646221303075,"mc":[{"id":"1.195453759","rc":[{"atl":[[190,0.83]],"id":522753}],"con":true,"img":false}]}
{"op":"mcm","clk":"5348857974","pt":1646221303182,"mc":[{"id":"1.195453759","rc":[{"atb":[[3.7,37.04]],"id":3805746},{"atl":[[70,25.6],[30,9.9]],"id":522750}],"con":true,"img":false}]}
{"op":"mcm","clk":"5348857988","pt":1646221303285,"mc":[{"id":"1.195453759","rc":[{"atl":[[80,4.95],[85,0],[100,9.9],[110,0]],"id":522753},{"atb":[[8,23.55]],"id":522741}],"con":true,"img":false}]}
{"op":"mcm","clk":"5348857997","pt":1646221303391,"mc":[{"id":"1.195453759","rc":[{"atl":[[38,0]],"id":3805783},{"atb":[[19.5,0]],"id":522747},{"atl":[[30,15.37]],"id":522750}],"con":true,"img":false}]}
{"op":"mcm","clk":"5348858018","pt":1646221303598,"mc":[{"id":"1.195453759","rc":[{"atl":[[30,0]],"id":522749},{"atl":[[190,9.73],[200,2]],"id":522753}],"con":true,"img":false}]}
{"op":"mcm","clk":"5348858068","pt":1646221303970,"mc":[{"id":"1.195453759","rc":[{"atl":[[80,0],[100,0]],"id":522753}],"con":true,"img":false}]}
{"op":"mcm","clk":"5348858080","pt":1646221304076,"mc":[{"id":"1.195453759","rc":[{"atl":[[85,4.95],[110,9.9]],"id":522753}],"con":true,"img":false}]}
{"op":"mcm","clk":"5348858459","pt":1646221307395,"mc":[{"id":"1.195453759","rc":[{"atb":[[26,0]],"id":522743},{"atl":[[42,0]],"id":522743}],"con":true,"img":false}]}
{"op":"mcm","clk":"5348858477","pt":1646221307602,"mc":[{"id":"1.195453759","rc":[{"atl":[[36,4.95],[38,2.7]],"id":3805783}],"con":true,"img":false}]}
{"op":"mcm","clk":"5348858506","pt":1646221307914,"mc":[{"id":"1.195453759","rc":[{"atb":[[5.9,54.37]],"id":522752},{"atb":[[19.5,31.99],[21,0]],"id":522743},{"atl":[[150,13.36],[55,9.9]],"id":522743}],"con":true,"img":false}]}
{"op":"mcm","clk":"5348858527","pt":1646221308082,"mc":[{"id":"1.195453759","rc":[{"atb":[[10,19.66]],"id":522752}],"con":true,"img":false}]}
{"op":"mcm","clk":"5348858537","pt":1646221308185,"mc":[{"id":"1.195453759","rc":[{"atb":[[21,7.93]],"id":522743},{"atl":[[50,3.23]],"id":522743}],"con":true,"img":false}]}
{"op":"mcm","clk":"5348858594","pt":1646221308794,"mc":[{"id":"1.195453759","rc":[{"atl":[[36,9.9]],"id":522749}],"con":true,"img":false}]}
{"op":"mcm","clk":"5348858625","pt":1646221309106,"mc":[{"id":"1.195453759","rc":[{"atl":[[32,4.95],[36,0],[40,9.9],[44,14.71]],"id":3805783},{"atb":[[8.4,0]],"id":3805736},{"atb":[[18,9.9],[11.5,29.85]],"id":522747},{"atl":[[90,20.97]],"id":522749},{"atl":[[32,9.9],[26,0],[27,4.95],[30,5.46]],"id":522750},{"atl":[[22,0],[23,4.95],[26,17.18],[27,9.9]],"id":522752}],"con":true,"img":false}]}
{"op":"mcm","clk":"5348858678","pt":1646221309680,"mc":[{"id":"1.195453759","rc":[{"atb":[[6.4,44.46]],"id":3805736}],"con":true,"img":false}]}
{"op":"mcm","clk":"5348858689","pt":1646221309780,"mc":[{"id":"1.195453759","rc":[{"atb":[[7.4,9.9]],"id":3805736}],"con":true,"img":false}]}
{"op":"mcm","clk":"5348858725","pt":1646221310102,"mc":[{"id":"1.195453759","rc":[{"atb":[[7.4,34.67]],"id":3805736},{"atb":[[9.6,0],[11.5,27.12]],"id":522747}],"con":true,"img":false}]}
{"op":"mcm","clk":"5348858793","pt":1646221310780,"mc":[{"id":"1.195453759","rc":[{"atb":[[12,2.72],[9.8,3.27]],"id":522747},{"atl":[[24,6.89]],"id":522752}],"con":true,"img":false}]}
{"op":"mcm","clk":"5348858815","pt":1646221310993,"mc":[{"id":"1.195453759","rc":[{"atb":[[18,0],[19.5,9.9],[20,8.34],[23,4.95]],"id":522747}],"con":true,"img":false}]}
{"op":"mcm","clk":"5348858858","pt":1646221311410,"mc":[{"id":"1.195453759","rc":[{"atl":[[25,23.79],[26,0]],"id":522752}],"con":true,"img":false}]}
{"op":"mcm","clk":"5348858873","pt":1646221311512,"mc":[{"id":"1.195453759","rc":[{"atl":[[25,17.18]],"id":522752}],"con":true,"img":false}]}
{"op":"mcm","clk":"5348858902","pt":1646221311781,"mc":[{"id":"1.195453759","rc":[{"atl":[[9.6,9.9],[12,14.41],[8.8,4.95],[14,0]],"id":3805746},{"atl":[[22,4.95],[23,0],[26,9.9],[27,0]],"id":522752}],"con":true,"img":false}]}
{"op":"mcm","clk":"5348858909","pt":1646221311879,"mc":[{"id":"1.195453759","rc":[{"atb":[[7.2,0],[6.4,0],[9.2,4.95],[8.4,9.9]],"id":522741}],"con":true,"img":false}]}
{"op":"mcm","clk":"5348858924","pt":1646221312092,"mc":[{"id":"1.195453759","rc":[{"atb":[[6.8,0],[5.9,0]],"id":3805746},{"atb":[[9,0],[10,0],[7.6,0],[8.4,14.71]],"id":3805730},{"atb":[[19.5,22.08],[20,9.9],[23,0],[24,4.95]],"id":522743}],"con":true,"img":false}]}
{"op":"mcm","clk":"5348858931","pt":1646221312195,"mc":[{"id":"1.195453759","rc":[{"atl":[[70,2],[12,36.5],[8.8,25.28]],"id":3805746}],"con":true,"img":false}]}
{"op":"mcm","clk":"5348858949","pt":1646221312403,"mc":[{"id":"1.195453759","rc":[{"atb":[[8,51.74],[7,3.27]],"id":522741}],"con":true,"img":false}]}
{"op":"mcm","clk":"5348858960","pt":1646221312508,"mc":[{"id":"1.195453759","rc":[{"atb":[[8.4,0]],"id":3805730}],"con":true,"img":false}]}
{"op":"mcm","clk":"5348858969","pt":1646221312614,"mc":[{"id":"1.195453759","rc":[{"atl":[[44,3.68],[55,0]],"id":3805755},{"atb":[[8,4.95],[7.2,9.9],[5.8,85.3],[8.4,21.42]],"id":3805730}],"con":true,"img":false}]}
{"op":"mcm","clk":"5348858982","pt":1646221312718,"mc":[{"id":"1.195453759","rc":[{"atl":[[36,9.9],[29,4.95]],"id":3805755}],"con":true,"img":false}]}
{"op":"mcm","clk":"5348858992","pt":1646221312777,"mc":[{"id":"1.195453759","rc":[{"atb":[[5.8,3.27],[6.6,2.72]],"id":3805746}],"con":true,"img":false}]}
{"op":"mcm","clk":"5348859003","pt":1646221312888,"mc":[{"id":"1.195453759","rc":[{"atb":[[9.8,2.72],[8.8,3.27]],"id":3805730}],"con":true,"img":false}]}
{"op":"mcm","clk":"5348859016","pt":1646221312989,"mc":[{"id":"1.195453759","rc":[{"atl":[[12,22.08]],"id":3805746}],"con":true,"img":false}]}
{"op":"mcm","clk":"5348859027","pt":1646221313087,"mc":[{"id":"1.195453759","rc":[{"atl":[[75,22.68],[60,0]],"id":3805755}],"con":true,"img":false}]}
{"op":"mcm","clk":"5348859040","pt":1646221313192,"mc":[{"id":"1.195453759","rc":[{"atb":[[9.8,0],[4.9,0],[5.9,0]],"id":3805783},{"atb":[[5.3,0],[3.15,0],[3.65,0]],"id":3805746},{"atb":[[5.7,0],[9.4,0],[4.7,0]],"id":3805755},{"atb":[[2.88,0],[3.7,0],[2.68,0]],"id":522746},{"atb":[[2.88,0],[3.7,0],[2.68,0]],"id":3805736},{"atb":[[3.6,0],[6.4,0],[4.2,0]],"id":522747},{"atb":[[4.5,0],[7,0],[3.75,0]],"id":522749},{"atb":[[5.7,0],[9.4,0],[4.7,0]],"id":522750},{"atb":[[9.8,18.01],[4.9,0],[5.9,0]],"id":522752},{"atb":[[5.8,57.55],[3.4,0],[3.9,0]],"id":3805730},{"atb":[[17,0],[6.8,0],[8.8,0]],"id":522753},{"atb":[[2.82,0],[4.1,0],[3.05,0]],"id":522741},{"atb":[[5.8,0],[3.4,0],[3.9,0]],"id":522742},{"atb":[[6.4,0],[11,0],[5.2,0]],"id":522743},{"atb":[[5.3,0],[11.5,0],[6.6,0]],"id":522745}],"con":true,"img":false}]}
{"op":"mcm","clk":"5348859053","pt":1646221313352,"mc":[{"id":"1.195453759","rc":[{"atl":[[29,10.61]],"id":3805755}],"con":true,"img":false}]}
{"op":"mcm","clk":"5348859061","pt":1646221313412,"mc":[{"id":"1.195453759","rc":[{"atb":[[8.2,0]],"id":3805730}],"con":true,"img":false}]}
{"op":"mcm","clk":"5348859113","pt":1646221313930,"mc":[{"id":"1.195453759","rc":[{"atl":[[75,2]],"id":3805755}],"con":true,"img":false}]}
{"op":"mcm","clk":"5348859130","pt":1646221314098,"mc":[{"id":"1.195453759","rc":[{"atl":[[44,0]],"id":3805755}],"con":true,"img":false}]}
{"op":"mcm","clk":"5348859217","pt":1646221314772,"mc":[{"id":"1.195453759","rc":[{"atb":[[5.4,81.97]],"id":3805746}],"con":true,"img":false}]}
{"op":"mcm","clk":"5348859230","pt":1646221314920,"mc":[{"id":"1.195453759","rc":[{"atb":[[15.5,39.36]],"id":522745}],"con":true,"img":false}]}
{"op":"mcm","clk":"5348859247","pt":1646221314981,"mc":[{"id":"1.195453759","rc":[{"atb":[[15,3.27]],"id":522745}],"con":true,"img":false}]}
{"op":"mcm","clk":"5348859273","pt":1646221315190,"mc":[{"id":"1.195453759","rc":[{"atl":[[30,5.46]],"id":3805783},{"atb":[[19.5,29.66],[23,12.15],[11.5,0]],"id":522747}],"con":true,"img":false}]}
{"op":"mcm","clk":"5348859289","pt":1646221315305,"mc":[{"id":"1.195453759","rc":[{"atl":[[38,17.2],[44,0]],"id":3805783}],"con":true,"img":false}]}
{"op":"mcm","clk":"5348859302","pt":1646221315397,"mc":[{"id":"1.195453759","rc":[{"atl":[[36,2.86],[38,14.5]],"id":3805783}],"con":true,"img":false}]}
{"op":"mcm","clk":"5348859326","pt":1646221315604,"mc":[{"id":"1.195453759","rc":[{"atl":[[32,32.77],[70,2]],"id":522750},{"atl":[[85,6.83]],"id":522753}],"con":true,"img":false}]}
{"op":"mcm","clk":"5348859362","pt":1646221315919,"mc":[{"id":"1.195453759","rc":[{"atl":[[27,11.05]],"id":522750},{"atb":[[9.2,24.29]],"id":522741}],"con":true,"img":false}]}
{"op":"mcm","clk":"5348859372","pt":1646221315981,"mc":[{"id":"1.195453759","rc":[{"atl":[[34,0]],"id":3805783},{"atb":[[20,0]],"id":522747}],"con":true,"img":false}]}
{"op":"mcm","clk":"5348859416","pt":1646221316394,"mc":[{"id":"1.195453759","rc":[{"atl":[[190,8.9]],"id":522753}],"con":true,"img":false}]}
{"op":"mcm","clk":"5348859450","pt":1646221316715,"mc":[{"id":"1.195453759","rc":[{"atl":[[30,0]],"id":522750},{"atb":[[8,30.92]],"id":522741}],"con":true,"img":false}]}
{"op":"mcm","clk":"5348859508","pt":1646221317293,"mc":[{"id":"1.195453759","rc":[{"atb":[[16,9.9],[17.5,2.72],[18,4.95],[15.5,29.45]],"id":522745}],"con":true,"img":false}]}
{"op":"mcm","clk":"5348859672","pt":1646221319115,"mc":[{"id":"1.195453759","rc":[{"atb":[[20,0],[25,0]],"id":522753}],"con":true,"img":false}]}
{"op":"mcm","clk":"5348859749","pt":1646221319906,"mc":[{"id":"1.195453759","rc":[{"atb":[[21,3.27],[26,2.72]],"id":522753}],"con":true,"img":false}]}
{"op":"mcm","clk":"5348859779","pt":1646221320213,"mc":[{"id":"1.195453759","rc":[{"atb":[[19.5,0],[20,29.05]],"id":522743},{"atl":[[150,2],[55,29.05]],"id":522743}],"con":true,"img":false}]}
{"op":"mcm","clk":"5348859830","pt":1646221320641,"mc":[{"id":"1.195453759","rc":[{"atb":[[24,11.84]],"id":522743},{"atl":[[44,8.64]],"id":522743}],"con":true,"img":false}]}
{"op":"mcm","clk":"5348859847","pt":1646221320803,"mc":[{"id":"1.195453759","rc":[{"atl":[[36,0],[38,9.9],[29,0],[30,4.95]],"id":3805755}],"con":true,"img":false}]}
{"op":"mcm","clk":"5348859883","pt":1646221321217,"mc":[{"id":"1.195453759","rc":[{"atb":[[19.5,9.9]],"id":522747}],"con":true,"img":false}]}
{"op":"mcm","clk":"5348859895","pt":1646221321322,"mc":[{"id":"1.195453759","rc":[{"atb":[[12,28.15]],"id":522747}],"con":true,"img":false}]}
{"op":"mcm","clk":"5348859905","pt":1646221321427,"mc":[{"id":"1.195453759","rc":[{"atb":[[21,0]],"id":522743},{"atl":[[50,0]],"id":522743}],"con":true,"img":false}]}
{"op":"mcm","clk":"5348859942","pt":1646221321706,"mc":[{"id":"1.195453759","rc":[{"atl":[[70,2.29]],"id":3805755},{"atl":[[32,9.9],[70,26.91]],"id":522750}],"con":true,"img":false}]}
{"op":"mcm","clk":"5348860052","pt":1646221322698,"mc":[{"id":"1.195453759","rc":[{"atb":[[8.2,26.97]],"id":3805736}],"con":true,"img":false}]}
{"op":"mcm","clk":"5348860110","pt":1646221323320,"mc":[{"id":"1.195453759","rc":[{"atl":[[21,7.93]],"id":522752}],"con":true,"img":false}]}
{"op":"mcm","clk":"5348860142","pt":1646221323589,"mc":[{"id":"1.195453759","rc":[{"atb":[[7.4,9.9]],"id":3805736}],"con":true,"img":false}]}
{"op":"mcm","clk":"5348860180","pt":1646221324001,"mc":[{"id":"1.195453759","rc":[{"atl":[[24,24.49],[25,0]],"id":522752}],"con":true,"img":false}]}
{"op":"mcm","clk":"5348860187","pt":1646221324105,"mc":[{"id":"1.195453759","rc":[{"atl":[[38,0],[30,0]],"id":3805755},{"atl":[[21,0],[24,17.59]],"id":522752},{"atb":[[9,4.95],[9.2,19.33],[8.2,9.9],[8.4,0]],"id":522741}],"con":true,"img":false}]}
{"op":"mcm","clk":"5348860194","pt":1646221324213,"mc":[{"id":"1.195453759","rc":[{"atl":[[32,4.95],[40,9.9]],"id":3805755}],"con":true,"img":false}]}
{"op":"mcm","clk":"5348860203","pt":1646221324318,"mc":[{"id":"1.195453759","rc":[{"atl":[[9.6,0],[9,4.95],[9.8,9.9],[8.8,0]],"id":3805746},{"atb":[[9.2,0]],"id":522741}],"con":true,"img":false}]}
{"op":"mcm","clk":"5348860212","pt":1646221324422,"mc":[{"id":"1.195453759","rc":[{"atb":[[19.5,0],[20,9.9],[23,7.2],[24,4.95]],"id":522747}],"con":true,"img":false}]}
{"op":"mcm","clk":"5348860236","pt":1646221324635,"mc":[{"id":"1.195453759","rc":[{"atb":[[5.6,57.91],[9.2,16.24],[4.6,74]],"id":3805783},{"atb":[[5.3,30.97],[3.15,123.9],[3.65,100.52]],"id":3805746},{"atb":[[9.8,15.13],[4.9,68.3],[5.9,54.37]],"id":3805755},{"atb":[[2.9,140.21],[3.75,48.43],[2.7,156.7]],"id":522746},{"atb":[[2.9,140.21],[3.75,48.43],[2.7,156.7]],"id":3805736},{"atb":[[4.5,76.11],[7,22.19],[3.75,96.87]],"id":522747},{"atb":[[3.6,102.46],[6.4,24.66],[4.2,83.25]],"id":522749},{"atb":[[9.8,15.13],[4.9,68.3],[5.9,54.37]],"id":522750},{"atb":[[5.6,57.91],[9.2,26.14],[4.6,74]],"id":522752},{"atb":[[3.85,93.47],[3.35,113.36],[5.7,28.34]],"id":3805730},{"atb":[[17,8.32],[6.8,45.93],[8.8,34.15]],"id":522753},{"atb":[[2.82,146.37],[4.1,42.96],[3.05,129.95]],"id":522741},{"atb":[[3.85,93.47],[3.35,113.36],[5.7,28.34]],"id":522742},{"atb":[[6.4,49.33],[11,13.32],[5.2,63.42]],"id":522743},{"atb":[[5.1,64.97],[10.5,14.02],[6.2,51.23]],"id":522745}],"con":true,"img":false}]}
{"op":"mcm","clk":"5348860248","pt":1646221324701,"mc":[{"id":"1.195453759","rc":[{"atb":[[8,2.72],[8.2,38.1]],"id":522741}],"con":true,"img":false}]}
{"op":"mcm","clk":"5348860258","pt":1646221324794,"mc":[{"id":"1.195453759","rc":[{"atb":[[8.4,60.97]],"id":3805730}],"con":true,"img":false}]}
{"op":"mcm","clk":"5348860266","pt":1646221324899,"mc":[{"id":"1.195453759","rc":[{"atb":[[5.8,0]],"id":3805730}],"con":true,"img":false}]}
{"op":"mcm","clk":"5348860279","pt":1646221325004,"mc":[{"id":"1.195453759","rc":[{"atl":[[11.5,8.91]],"id":3805746},{"atl":[[23,7.2],[24,0]],"id":522752},{"atb":[[8,17.44]],"id":522741}],"con":true,"img":false}]}
{"op":"mcm","clk":"5348860291","pt":1646221325107,"mc":[{"id":"1.195453759","rc":[{"atl":[[32,0],[34,4.95],[40,0],[42,9.9]],"id":3805755}],"con":true,"img":false}]}
{"op":"mcm","clk":"5348860312","pt":1646221325319,"mc":[{"id":"1.195453759","rc":[{"atl":[[85,0],[90,4.95],[110,0],[120,9.9]],"id":522753}],"con":true,"img":false}]}
{"op":"mcm","clk":"5348860327","pt":1646221325423,"mc":[{"id":"1.195453759","rc":[{"atl":[[70,24.38]],"id":3805755}],"con":true,"img":false}]}
{"op":"mcm","clk":"5348860338","pt":1646221325523,"mc":[{"id":"1.195453759","rc":[{"atl":[[11.5,29.53],[12,0]],"id":3805746},{"atb":[[8.2,9.9]],"id":522741}],"con":true,"img":false}]}
{"op":"mcm","clk":"5348860354","pt":1646221325628,"mc":[{"id":"1.195453759","rc":[{"atl":[[34,9.76]],"id":3805755}],"con":true,"img":false}]}
{"op":"mcm","clk":"5348860413","pt":1646221326107,"mc":[{"id":"1.195453759","rc":[{"atl":[[90,6.73]],"id":522753}],"con":true,"img":false}]}
{"op":"mcm","clk":"5348860420","pt":1646221326206,"mc":[{"id":"1.195453759","rc":[{"atb":[[19,33.18]],"id":522743},{"atl":[[55,9.9]],"id":522743}],"con":true,"img":false}]}
{"op":"mcm","clk":"5348860439","pt":1646221326414,"mc":[{"id":"1.195453759","rc":[{"atl":[[70,22.08]],"id":3805755},{"atb":[[20,9.9]],"id":522743},{"atl":[[150,13.7]],"id":522743}],"con":true,"img":false}]}
{"op":"mcm","clk":"5348860518","pt":1646221327118,"mc":[{"id":"1.195453759","rc":[{"atb":[[15.5,0]],"id":522745}],"con":true,"img":false}]}
{"op":"mcm","clk":"5348860552","pt":1646221327409,"mc":[{"id":"1.195453759","rc":[{"atb":[[20,27.98],[24,11.84],[12,2.72]],"id":522747},{"atl":[[44,4.95],[46,0],[55,39.36],[60,0]],"id":522747},{"atl":[[90,1.78],[120,0]],"id":522753},{"atb":[[17.5,30.54]],"id":522745}],"con":true,"img":false}]}
{"op":"mcm","clk":"5348860580","pt":1646221327726,"mc":[{"id":"1.195453759","rc":[{"atl":[[36,17.57],[38,0]],"id":3805783},{"atl":[[85,4.95],[110,9.9]],"id":522753}],"con":true,"img":false}]}
{"op":"mcm","clk":"5348860610","pt":1646221328041,"mc":[{"id":"1.195453759","rc":[{"atl":[[190,0],[200,10.8]],"id":522753}],"con":true,"img":false}]}
{"op":"mcm","clk":"5348860644","pt":1646221328358,"mc":[{"id":"1.195453759","rc":[{"atl":[[85,6.83]],"id":522753}],"con":true,"img":false}]}
{"op":"mcm","clk":"5348860655","pt":1646221328422,"mc":[{"id":"1.195453759","rc":[{"atb":[[5.7,2.72],[7,4.95]],"id":522746},{"atb":[[23,0]],"id":522747},{"atb":[[9,24.77]],"id":522741}],"con":true,"img":false}]}
{"op":"mcm","clk":"5348860679","pt":1646221328619,"mc":[{"id":"1.195453759","rc":[{"atl":[[16.5,0]],"id":3805730}],"con":true,"img":false}]}
{"op":"mcm","clk":"5348860686","pt":1646221328734,"mc":[{"id":"1.195453759","rc":[{"atl":[[12.5,4.95]],"id":3805730}],"con":true,"img":false}]}
{"op":"mcm","clk":"5348860698","pt":1646221328830,"mc":[{"id":"1.195453759","rc":[{"atb":[[7.2,25.57],[5.2,3.27],[5.7,34.89]],"id":522746}],"con":true,"img":false}]}
{"op":"mcm","clk":"5348860707","pt":1646221328946,"mc":[{"id":"1.195453759","rc":[{"atl":[[200,2]],"id":522753}],"con":true,"img":false}]}
{"op":"mcm","clk":"5348860718","pt":1646221329041,"mc":[{"id":"1.195453759","rc":[{"atl":[[90,0]],"id":522753}],"con":true,"img":false}]}
{"op":"mcm","clk":"5348860730","pt":1646221329163,"mc":[{"id":"1.195453759","rc":[{"atl":[[23,4.55],[15.5,49.64]],"id":3805730},{"atb":[[8,2.72]],"id":522741}],"con":true,"img":false}]}
{"op":"mcm","clk":"5348860757","pt":1646221329330,"mc":[{"id":"1.195453759","rc":[{"atl":[[12,12.21]],"id":3805730}],"con":true,"img":false}]}
{"op":"mcm","clk":"5348860771","pt":1646221329427,"mc":[{"id":"1.195453759","rc":[{"atl":[[9.6,9.9],[9,0],[9.8,0],[8.8,4.95]],"id":3805746}],"con":true,"img":false}]}
{"op":"mcm","clk":"5348860811","pt":1646221329738,"mc":[{"id":"1.195453759","rc":[{"atb":[[6.2,4.95]],"id":522746}],"con":true,"img":false}]}
{"op":"mcm","clk":"5348860842","pt":1646221330053,"mc":[{"id":"1.195453759","rc":[{"atl":[[14.5,4.95]],"id":3805730}],"con":true,"img":false}]}
{"op":"mcm","clk":"5348860932","pt":1646221330830,"mc":[{"id":"1.195453759","rc":[{"atl":[[85,0],[90,4.95],[110,0],[120,9.9]],"id":522753}],"con":true,"img":false}]}
{"op":"mcm","clk":"5348861032","pt":1646221331821,"mc":[{"id":"1.195453759","rc":[{"atl":[[190,0.83]],"id":522753}],"con":true,"img":false}]}
{"op":"mcm","clk":"5348861222","pt":1646221333502,"mc":[{"id":"1.195453759","rc":[{"atb":[[20,9.9],[12,27.69]],"id":522747}],"con":true,"img":false}]}
{"op":"mcm","clk":"5348861459","pt":1646221335436,"mc":[{"id":"1.195453759","rc":[{"atl":[[22,12.5]],"id":522752}],"con":true,"img":false}]}
{"op":"mcm","clk":"5348861526","pt":1646221336013,"mc":[{"id":"1.195453759","rc":[{"atb":[[8.4,0]],"id":522742}],"con":true,"img":false}]}
{"op":"mcm","clk":"5348861538","pt":1646221336116,"mc":[{"id":"1.195453759","rc":[{"atb":[[9.4,0]],"id":522742}],"con":true,"img":false}]}
{"op":"mcm","clk":"5348861571","pt":1646221336426,"mc":[{"id":"1.195453759","rc":[{"atl":[[23,0],[26,35.35]],"id":522752}],"con":true,"img":false}]}
{"op":"mcm","clk":"5348861603","pt":1646221336740,"mc":[{"id":"1.195453759","rc":[{"atb":[[8,30.92]],"id":522741},{"atb":[[8.6,3.27],[7.8,16.81],[7,53.42]],"id":522742}],"con":true,"img":false}]}
{"op":"mcm","clk":"5348861635","pt":1646221337007,"mc":[{"id":"1.195453759","rc":[{"atb":[[9.6,2.72]],"id":522742}],"con":true,"img":false}]}
{"op":"mcm","clk":"5348861642","pt":1646221337106,"mc":[{"id":"1.195453759","rc":[{"atl":[[8.8,17.17]],"id":3805746}],"con":true,"img":false}]}
{"op":"mcm","clk":"5348861708","pt":1646221337838,"mc":[{"id":"1.195453759","rc":[{"atl":[[11.5,20.61]],"id":3805746}],"con":true,"img":false}]}
{"op":"mcm","clk":"5348861738","pt":1646221338113,"mc":[{"id":"1.195453759","rc":[{"atl":[[90,6.73]],"id":522753}],"con":true,"img":false}]}
{"op":"mcm","clk":"5348861816","pt":1646221338845,"mc":[{"id":"1.195453759","rc":[{"atl":[[190,0]],"id":522753}],"con":true,"img":false}]}
{"op":"mcm","clk":"5348861919","pt":1646221339908,"mc":[{"id":"1.195453759","rc":[{"atl":[[200,10.97]],"id":522753}],"con":true,"img":false}]}
{"op":"mcm","clk":"5348862043","pt":1646221340950,"mc":[{"id":"1.195453759","rc":[{"atb":[[6.2,37.12]],"id":522746}],"con":true,"img":false}]}
{"op":"mcm","clk":"5348862055","pt":1646221341010,"mc":[{"id":"1.195453759","rc":[{"atb":[[5.7,2.72]],"id":522746}],"con":true,"img":false}]}
{"op":"mcm","clk":"5348862093","pt":1646221341322,"mc":[{"id":"1.195453759","rc":[{"atl":[[14.5,19.66],[15.5,0]],"id":3805730}],"con":true,"img":false}]}
{"op":"mcm","clk":"5348862209","pt":1646221342320,"mc":[{"id":"1.195453759","rc":[{"atl":[[36,26.3],[26,9.9]],"id":522752}],"con":true,"img":false}]}
{"op":"mcm","clk":"5348862570","pt":1646221345307,"mc":[{"id":"1.195453759","rc":[{"atl":[[19,0],[22,19.75]],"id":522741}],"con":true,"img":false}]}
{"op":"mcm","clk":"5348862614","pt":1646221345620,"mc":[{"id":"1.195453759","rc":[{"atl":[[18.5,14.01],[21,9.9]],"id":522741}],"con":true,"img":false}]}
{"op":"mcm","clk":"5348862651","pt":1646221345930,"mc":[{"id":"1.195453759","rc":[{"atl":[[40,46.66],[22,0]],"id":522741}],"con":true,"img":false}]}
{"op":"mcm","clk":"5348862981","pt":1646221348856,"mc":[{"id":"1.195453759","rc":[{"atb":[[7.8,56.52],[7,9.9]],"id":522742}],"con":true,"img":false}]}
{"op":"mcm","clk":"5348863052","pt":1646221349599,"mc":[{"id":"1.195453759","rc":[{"atl":[[22,0],[23,4.95],[26,0],[27,9.9]],"id":522752}],"con":true,"img":false}]}
{"op":"mcm","clk":"5348863153","pt":1646221350430,"mc":[{"id":"1.195453759","rc":[{"atl":[[34,4.8]],"id":522752}],"con":true,"img":false}]}
{"op":"mcm","clk":"5348863197","pt":1646221350849,"mc":[{"id":"1.195453759","rc":[{"atl":[[34,19.31]],"id":522752}],"con":true,"img":false}]}
{"op":"mcm","clk":"5348863210","pt":1646221350955,"mc":[{"id":"1.195453759","rc":[{"atl":[[36,2.86]],"id":522752}],"con":true,"img":false}]}
{"op":"mcm","clk":"5348863536","pt":1646221354145,"mc":[{"id":"1.195453759","rc":[{"atl":[[32,0],[40,0],[25,4.95],[29,9.9]],"id":3805783}],"con":true,"img":false}]}
{"op":"mcm","clk":"5348863583","pt":1646221354564,"mc":[{"id":"1.195453759","rc":[{"atl":[[30,20.95]],"id":3805783}],"con":true,"img":false}]}
{"op":"mcm","clk":"5348863594","pt":1646221354667,"mc":[{"id":"1.195453759","rc":[{"atl":[[36,2.86],[25,11.55]],"id":3805783}],"con":true,"img":false}]}
{"op":"mcm","clk":"5348863680","pt":1646221355561,"mc":[{"id":"1.195453759","rc":[{"atl":[[30,15.48]],"id":3805783}],"con":true,"img":false}]}
{"op":"mcm","clk":"5348864071","pt":1646221359331,"mc":[{"id":"1.195453759","rc":[{"atb":[[5.8,0],[6.6,0]],"id":3805746}],"con":true,"img":false}]}
{"op":"mcm","clk":"5348864120","pt":1646221359850,"mc":[{"id":"1.195453759","rc":[{"atb":[[3.7,113.74],[5.4,34.41]],"id":3805746}],"con":true,"img":false}]}
{"op":"mcm","clk":"5348864145","pt":1646221360058,"mc":[{"id":"1.195453759","rc":[{"atb":[[6.4,2.72],[5.7,3.27]],"id":3805746}],"con":true,"img":false}]}
{"op":"mcm","clk":"5348864187","pt":1646221360481,"mc":[{"id":"1.195453759","rc":[{"atl":[[22,4.95],[23,0],[26,9.9],[27,0]],"id":522752}],"con":true,"img":false}]}
{"op":"mcm","clk":"5348864220","pt":1646221360746,"mc":[{"id":"1.195453759","rc":[{"atl":[[32,3.23],[36,0]],"id":3805783},{"atb":[[3.7,37.04]],"id":3805746}],"con":true,"img":false}]}
{"op":"mcm","clk":"5348864260","pt":1646221361059,"mc":[{"id":"1.195453759","rc":[{"atb":[[12,0],[12.5,13.17],[14,14.95],[14.5,4.95]],"id":522750},{"atl":[[32,0],[36,9.9],[27,6.09],[29,4.95]],"id":522750}],"con":true,"img":false}]}
{"op":"mcm","clk":"5348864281","pt":1646221361272,"mc":[{"id":"1.195453759","rc":[{"atl":[[22,0],[23,4.95],[26,0],[27,9.9]],"id":522752}],"con":true,"img":false}]}
{"op":"mcm","clk":"5348864306","pt":1646221361538,"mc":[{"id":"1.195453759","rc":[{"atb":[[14,0],[14.5,21.38]],"id":522750},{"atl":[[70,2],[36,26.33]],"id":522750}],"con":true,"img":false}]}
{"op":"mcm","clk":"5348864364","pt":1646221362060,"mc":[{"id":"1.195453759","rc":[{"atl":[[23,12.15]],"id":522752}],"con":true,"img":false}]}
{"op":"mcm","clk":"5348864455","pt":1646221362844,"mc":[{"id":"1.195453759","rc":[{"atl":[[34,14.5]],"id":522752}],"con":true,"img":false}]}
{"op":"mcm","clk":"5348864497","pt":1646221363263,"mc":[{"id":"1.195453759","rc":[{"atb":[[9,19.81],[9.2,4.95],[8.2,0],[8.4,9.9]],"id":522741}],"con":true,"img":false}]}
{"op":"mcm","clk":"5348864518","pt":1646221363474,"mc":[{"id":"1.195453759","rc":[{"atl":[[9.6,0],[8.8,12.21]],"id":3805746}],"con":true,"img":false}]}
{"op":"mcm","clk":"5348864524","pt":1646221363578,"mc":[{"id":"1.195453759","rc":[{"atl":[[8.6,4.95],[9.4,9.9]],"id":3805746}],"con":true,"img":false}]}
{"op":"mcm","clk":"5348864553","pt":1646221363839,"mc":[{"id":"1.195453759","rc":[{"atl":[[11.5,0]],"id":3805746},{"atb":[[8,2.72],[9.2,24.29],[8.4,45.46]],"id":522741}],"con":true,"img":false}]}
{"op":"mcm","clk":"5348864564","pt":1646221363947,"mc":[{"id":"1.195453759","rc":[{"atl":[[70,25.02]],"id":3805746}],"con":true,"img":false}]}
{"op":"mcm","clk":"5348864585","pt":1646221364149,"mc":[{"id":"1.195453759","rc":[{"atl":[[8.6,25.81]],"id":3805746},{"atl":[[34,4.8],[36,9.9],[42,0],[29,4.95]],"id":3805755}],"con":true,"img":false}]}
{"op":"mcm","clk":"5348864626","pt":1646221364563,"mc":[{"id":"1.195453759","rc":[{"atb":[[9,0]],"id":522741}],"con":true,"img":false}]}
{"op":"mcm","clk":"5348864652","pt":1646221364877,"mc":[{"id":"1.195453759","rc":[{"atl":[[8.8,0]],"id":3805746},{"atl":[[70,0],[36,31.99],[29,10.61]],"id":3805755}],"con":true,"img":false}]}
{"op":"mcm","clk":"5348864791","pt":1646221365767,"mc":[{"id":"1.195453759","rc":[{"atl":[[34,0]],"id":3805755}],"con":true,"img":false}]}
{"op":"mcm","clk":"5348865144","pt":1646221369441,"mc":[{"id":"1.195453759","rc":[{"atb":[[8,59.65],[8.4,9.9]],"id":522741}],"con":true,"img":false}]}
{"op":"mcm","clk":"5348865227","pt":1646221370379,"mc":[{"id":"1.195453759","rc":[{"atl":[[36,9.9],[75,27.09]],"id":3805755}],"con":true,"img":false}]}
{"op":"mcm","clk":"5348865324","pt":1646221371176,"mc":[{"id":"1.195453759","rc":[{"atb":[[5.4,86.34]],"id":3805746}],"con":true,"img":false}]}
{"op":"mcm","clk":"5348866081","pt":1646221378792,"mc":[{"id":"1.195453759","rc":[{"atl":[[36,0],[38,9.9],[29,0],[30,4.95]],"id":3805755},{"atl":[[27,0]],"id":522750},{"atl":[[130,9.9],[90,0],[95,4.95],[120,0]],"id":522753}],"con":true,"img":false}]}
{"op":"mcm","clk":"5348866134","pt":1646221379265,"mc":[{"id":"1.195453759","rc":[{"atl":[[70,25.6],[36,9.9]],"id":522750}],"con":true,"img":false}]}
{"op":"mcm","clk":"5348866153","pt":1646221379475,"mc":[{"id":"1.195453759","rc":[{"atl":[[34,4.8]],"id":522750},{"atb":[[9,4.95],[9.2,0],[8.2,9.9],[8.4,0]],"id":522741}],"con":true,"img":false}]}
{"op":"mcm","clk":"5348866164","pt":1646221379579,"mc":[{"id":"1.195453759","rc":[{"atl":[[36,4.52]],"id":3805755}],"con":true,"img":false}]}
{"op":"mcm","clk":"5348866173","pt":1646221379689,"mc":[{"id":"1.195453759","rc":[{"atl":[[190,0.83]],"id":522753}],"con":true,"img":false}]}
{"op":"mcm","clk":"5348866201","pt":1646221379957,"mc":[{"id":"1.195453759","rc":[{"atl":[[70,2]],"id":522750}],"con":true,"img":false}]}
{"op":"mcm","clk":"5348866224","pt":1646221380168,"mc":[{"id":"1.195453759","rc":[{"atl":[[75,2],[38,31.99]],"id":3805755}],"con":true,"img":false}]}
{"op":"mcm","clk":"5348866230","pt":1646221380266,"mc":[{"id":"1.195453759","rc":[{"atl":[[200,2]],"id":522753},{"atb":[[8,81.74]],"id":522741}],"con":true,"img":false}]}
{"op":"mcm","clk":"5348866240","pt":1646221380375,"mc":[{"id":"1.195453759","rc":[{"atl":[[190,10.88]],"id":522753}],"con":true,"img":false}]}
{"op":"mcm","clk":"5348866314","pt":1646221381166,"mc":[{"id":"1.195453759","rc":[{"atl":[[8.6,20.86],[9.2,9.9],[8.4,4.95],[9.4,0]],"id":3805746}],"con":true,"img":false}]}
{"op":"mcm","clk":"5348866351","pt":1646221381575,"mc":[{"id":"1.195453759","rc":[{"atl":[[38,22.08],[30,0]],"id":3805755}],"con":true,"img":false}]}
{"op":"mcm","clk":"5348866361","pt":1646221381678,"mc":[{"id":"1.195453759","rc":[{"atl":[[70,2],[9.2,31.99]],"id":3805746}],"con":true,"img":false}]}
{"op":"mcm","clk":"5348866369","pt":1646221381782,"mc":[{"id":"1.195453759","rc":[{"atl":[[65,2],[75,0]],"id":3805755}],"con":true,"img":false}]}
{"op":"mcm","clk":"5348866381","pt":1646221381889,"mc":[{"id":"1.195453759","rc":[{"atl":[[32,4.95],[40,9.9]],"id":3805755}],"con":true,"img":false}]}
{"op":"mcm","clk":"5348866401","pt":1646221382100,"mc":[{"id":"1.195453759","rc":[{"atl":[[8.6,25.81],[9.2,22.08],[8.4,0],[9.4,9.9]],"id":3805746}],"con":true,"img":false}]}
{"op":"mcm","clk":"5348866412","pt":1646221382206,"mc":[{"id":"1.195453759","rc":[{"atl":[[8.4,21.42]],"id":3805746}],"con":true,"img":false}]}
{"op":"mcm","clk":"5348866479","pt":1646221382882,"mc":[{"id":"1.195453759","rc":[{"atl":[[8.6,4.95],[8.4,0]],"id":3805746}],"con":true,"img":false}]}
{"op":"mcm","clk":"5348866543","pt":1646221383563,"mc":[{"id":"1.195453759","rc":[{"atl":[[9.2,34.3]],"id":3805746}],"con":true,"img":false}]}
{"op":"mcm","clk":"5348866562","pt":1646221383771,"mc":[{"id":"1.195453759","rc":[{"atl":[[24,4.95],[25,6.6],[28,9.9],[29,0]],"id":3805783}],"con":true,"img":false}]}
{"op":"mcm","clk":"5348866607","pt":1646221384298,"mc":[{"id":"1.195453759","rc":[{"atl":[[24,11.84],[28,27.09],[30,0]],"id":3805783}],"con":true,"img":false}]}
{"op":"mcm","clk":"5348866629","pt":1646221384458,"mc":[{"id":"1.195453759","rc":[{"atl":[[24,6.89],[25,11.55],[28,17.18],[29,9.9]],"id":3805783}],"con":true,"img":false}]}
{"op":"mcm","clk":"5348866696","pt":1646221385189,"mc":[{"id":"1.195453759","rc":[{"atl":[[24,0],[25,4.95]],"id":3805783}],"con":true,"img":false}]}
{"op":"mcm","clk":"5348866766","pt":1646221385865,"mc":[{"id":"1.195453759","rc":[{"atl":[[27,6.09]],"id":3805783}],"con":true,"img":false}]}
{"op":"mcm","clk":"5348866774","pt":1646221385970,"mc":[{"id":"1.195453759","rc":[{"atl":[[32,0],[34,3.03]],"id":3805783},{"atl":[[17,0],[15.5,6.9]],"id":522746}],"con":true,"img":false}]}
{"op":"mcm","clk":"5348866801","pt":1646221386287,"mc":[{"id":"1.195453759","rc":[{"atb":[[16.5,15.18],[13.5,3.27],[14.5,9.9],[15.5,27.57]],"id":3805755},{"atb":[[20,0],[21,9.9],[24,6.89],[25,4.95]],"id":522747},{"atl":[[44,0],[46,4.95],[55,29.45],[60,9.9]],"id":522747},{"atb":[[8,0],[7.2,0],[8.2,4.95],[9.8,0],[8.8,0]],"id":3805730},{"atb":[[32,0],[34,9.76],[27,25.77],[28,9.9]],"id":522753},{"atb":[[9.6,0],[8.6,0]],"id":522742},{"atl":[[11.5,4.95],[12,14.41],[13.5,9.9],[14,0]],"id":522742},{"atb":[[20,0],[21,9.9],[24,6.89],[25,4.95]],"id":522743},{"atl":[[65,9.9],[44,3.68],[48,4.95],[55,0]],"id":522743}],"con":true,"img":false}]}
{"op":"mcm","clk":"5348866837","pt":1646221386656,"mc":[{"id":"1.195453759","rc":[{"atb":[[7.8,16.81]],"id":522742},{"atl":[[34,3.03]],"id":522742},{"atb":[[21,27.5],[26,6.34]],"id":522743},{"atl":[[65,27.5]],"id":522743}],"con":true,"img":false}]}
{"op":"mcm","clk":"5348866847","pt":1646221386762,"mc":[{"id":"1.195453759","rc":[{"atb":[[26,6.34]],"id":522747},{"atb":[[5.7,64.5]],"id":522742},{"atl":[[13.5,46.07]],"id":522742},{"atb":[[19,2.72]],"id":522743},{"atl":[[150,2]],"id":522743}],"con":true,"img":false}]}
{"op":"mcm","clk":"5348866854","pt":1646221386866,"mc":[{"id":"1.195453759","rc":[{"atb":[[21,27.5],[12,2.72]],"id":522747},{"atb":[[5.7,75.74],[8.4,21.42]],"id":3805730},{"atl":[[11,15.85]],"id":522742}],"con":true,"img":false}]}
{"op":"mcm","clk":"5348866862","pt":1646221386969,"mc":[{"id":"1.195453759","rc":[{"atl":[[9.2,12.21],[9.4,31.99]],"id":3805746},{"atb":[[9,3.27],[10,2.72]],"id":3805730},{"atb":[[8.4,3.27],[9.4,2.72]],"id":522742}],"con":true,"img":false}]}
{"op":"mcm","clk":"5348866902","pt":1646221387391,"mc":[{"id":"1.195453759","rc":[{"atb":[[24,0]],"id":522743}],"con":true,"img":false}]}
{"op":"mcm","clk":"5348866912","pt":1646221387497,"mc":[{"id":"1.195453759","rc":[{"atb":[[24,0]],"id":522747},{"atl":[[130,0],[140,9.9],[95,0],[100,4.95]],"id":522753}],"con":true,"img":false}]}
{"op":"mcm","clk":"5348866936","pt":1646221387652,"mc":[{"id":"1.195453759","rc":[{"atl":[[12,0]],"id":522742}],"con":true,"img":false}]}
{"op":"mcm","clk":"5348866997","pt":1646221388203,"mc":[{"id":"1.195453759","rc":[{"atl":[[140,0],[100,0]],"id":522753}],"con":true,"img":false}]}
{"op":"mcm","clk":"5348867009","pt":1646221388364,"mc":[{"id":"1.195453759","rc":[{"atl":[[130,9.9],[95,4.95]],"id":522753}],"con":true,"img":false}]}
{"op":"mcm","clk":"5348867067","pt":1646221388878,"mc":[{"id":"1.195453759","rc":[{"atl":[[190,0.83],[210,9.19]],"id":522753}],"con":true,"img":false}]}
{"op":"mcm","clk":"5348867075","pt":1646221388986,"mc":[{"id":"1.195453759","rc":[{"atl":[[8.6,0],[9.2,17.17],[10,9.9],[9.4,22.08]],"id":3805746},{"atl":[[32,0],[38,27.04],[40,0]],"id":3805755},{"atb":[[7.2,0]],"id":522746},{"atb":[[8.2,4.95]],"id":3805736},{"atb":[[26,0]],"id":522747},{"atl":[[25,4.95],[29,9.9]],"id":522752}],"con":true,"img":false}]}
{"op":"mcm","clk":"5348867084","pt":1646221389086,"mc":[{"id":"1.195453759","rc":[{"atl":[[25,0],[27,0],[28,22.13],[29,0]],"id":3805783},{"atl":[[36,0]],"id":3805755},{"atb":[[6.2,32.16],[6.8,4.95],[6,9.9],[7,0]],"id":522746},{"atb":[[8.2,0],[7.4,0],[7.6,4.95],[6.8,9.9]],"id":3805736},{"atb":[[20,9.9],[21,17.59],[24,4.95],[25,0]],"id":522747},{"atl":[[32,4.95],[36,0],[40,9.9],[29,0]],"id":522750},{"atl":[[23,0],[27,0]],"id":522752},{"atl":[[130,0],[140,9.9],[95,0],[100,4.95]],"id":522753},{"atb":[[8,86.69],[7.2,9.9],[9,0],[8.2,0]],"id":522741}],"con":true,"img":false}]}
{"op":"mcm","clk":"5348867089","pt":1646221389188,"mc":[{"id":"1.195453759","rc":[{"atl":[[32,3.23],[36,0]],"id":522752}],"con":true,"img":false}]}
{"op":"mcm","clk":"5348867099","pt":1646221389295,"mc":[{"id":"1.195453759","rc":[{"atl":[[25,6.6]],"id":3805783}],"con":true,"img":false}]}
{"op":"mcm","clk":"5348867115","pt":1646221389450,"mc":[{"id":"1.195453759","rc":[{"atl":[[65,31.29],[38,4.95]],"id":3805755},{"atb":[[6.2,0],[5.7,34.89]],"id":522746},{"atl":[[34,0],[27,22.08]],"id":522752}],"con":true,"img":false}]}
{"op":"mcm","clk":"5348867128","pt":1646221389553,"mc":[{"id":"1.195453759","rc":[{"atb":[[8,29.76],[7,38.82]],"id":522741}],"con":true,"img":false}]}
{"op":"mcm","clk":"5348867134","pt":1646221389660,"mc":[{"id":"1.195453759","rc":[{"atl":[[28,4.95],[30,14.71]],"id":3805783},{"atl":[[34,4.95],[38,0],[42,9.9]],"id":3805755},{"atb":[[6.2,14.71]],"id":522746},{"atb":[[6.8,31.99]],"id":3805736},{"atb":[[21,25.52]],"id":522747},{"atl":[[25,0],[29,0]],"id":522752}],"con":true,"img":false}]}
{"op":"mcm","clk":"5348867145","pt":1646221389762,"mc":[{"id":"1.195453759","rc":[{"atl":[[36,4.52]],"id":3805755},{"atb":[[8,4.95],[7.2,9.9],[7.6,0],[6.8,22.08]],"id":3805736},{"atb":[[20,0],[24,0]],"id":522747},{"atl":[[32,0],[38,9.9],[40,0],[30,4.95]],"id":522750},{"atl":[[32,0],[34,3.03],[23,4.95],[27,31.99],[28,5.86]],"id":522752},{"atl":[[150,9.9],[110,4.95]],"id":522753},{"atb":[[8,24.81],[7.2,0]],"id":522741}],"con":true,"img":false}]}
{"op":"mcm","clk":"5348867152","pt":1646221389867,"mc":[{"id":"1.195453759","rc":[{"atl":[[140,0],[100,0]],"id":522753}],"con":true,"img":false}]}
{"op":"mcm","clk":"5348867170","pt":1646221390215,"mc":[{"id":"1.195453759","rc":[{"atb":[[6.4,2.72],[6.8,63.82]],"id":3805736},{"atl":[[40,22.08]],"id":522750},{"atl":[[27,9.9]],"id":522752}],"con":true,"img":false}]}
{"op":"mcm","clk":"5348867191","pt":1646221390484,"mc":[{"id":"1.195453759","rc":[{"atb":[[8,0],[7.2,0],[7.8,4.95],[7,9.9]],"id":3805736},{"atb":[[21,35.43],[25,4.95]],"id":522747},{"atl":[[32,4.95],[38,0],[40,31.99],[30,0]],"id":522750},{"atb":[[8,34.72],[8.8,4.95]],"id":522741}],"con":true,"img":false}]}
{"op":"mcm","clk":"5348867213","pt":1646221390693,"mc":[{"id":"1.195453759","rc":[{"atl":[[34,4.8],[36,9.48],[42,0],[44,9.9]],"id":3805755},{"atl":[[180,0.88]],"id":522753}],"con":true,"img":false}]}
{"op":"mcm","clk":"5348867230","pt":1646221390903,"mc":[{"id":"1.195453759","rc":[{"atl":[[32,10.06]],"id":522750}],"con":true,"img":false}]}
{"op":"mcm","clk":"5348867246","pt":1646221391113,"mc":[{"id":"1.195453759","rc":[{"atl":[[42,22.08]],"id":3805755}],"con":true,"img":false}]}
{"op":"mcm","clk":"5348867252","pt":1646221391164,"mc":[{"id":"1.195453759","rc":[{"atl":[[65,2]],"id":3805755},{"atl":[[180,11.66]],"id":522753},{"atb":[[8.8,25.28]],"id":522741}],"con":true,"img":false}]}
{"op":"mcm","clk":"5348867264","pt":1646221391269,"mc":[{"id":"1.195453759","rc":[{"atl":[[210,0]],"id":522753}],"con":true,"img":false}]}
{"op":"mcm","clk":"5348867270","pt":1646221391372,"mc":[{"id":"1.195453759","rc":[{"atl":[[25,0]],"id":3805783},{"atl":[[34,0],[36,0],[38,4.95],[44,0],[46,9.9]],"id":3805755},{"atb":[[6.8,73.73],[7.6,4.95],[7.8,0],[7,0]],"id":3805736},{"atl":[[32,5.11],[34,9.76],[40,22.08],[42,9.9]],"id":522750},{"atl":[[23,0],[24,4.95],[27,0],[28,15.77]],"id":522752},{"atl":[[190,0]],"id":522753},{"atb":[[8,24.81],[7.6,9.9],[8.8,20.32],[8.4,4.95]],"id":522741}],"con":true,"img":false}]}
{"op":"mcm","clk":"5348867290","pt":1646221391582,"mc":[{"id":"1.195453759","rc":[{"atl":[[28,0],[30,19.66]],"id":3805783},{"atl":[[9.2,0],[10,0],[11.5,9.9],[9.8,4.95]],"id":3805746},{"atb":[[5.8,4.95],[6.2,0],[6.8,0],[6,0],[5.7,2.72]],"id":522746},{"atb":[[19,9.9],[21,25.52],[22,4.95],[25,0]],"id":522747},{"atl":[[12,0],[12.5,0],[13.5,4.95],[14.5,14.71],[15.5,9.9]],"id":3805730},{"atl":[[130,4.95],[150,0],[170,9.9],[110,0]],"id":522753},{"atl":[[11,0]],"id":522742},{"atl":[[65,17.59],[75,9.9],[44,0],[48,0],[55,4.95]],"id":522743},{"atl":[[32,0],[38,4.95],[40,0],[46,9.9]],"id":522745}],"con":true,"img":false}]}
{"op":"mcm","clk":"5348867298","pt":1646221391684,"mc":[{"id":"1.195453759","rc":[{"atl":[[32,0],[34,4.95]],"id":522750},{"atl":[[120,2]],"id":522743}],"con":true,"img":false}]}
{"op":"mcm","clk":"5348867306","pt":1646221391789,"mc":[{"id":"1.195453759","rc":[{"atl":[[150,0]],"id":522743},{"atl":[[75,2],[100,16.56]],"id":522745}],"con":true,"img":false}]}
{"op":"mcm","clk":"5348867314","pt":1646221391893,"mc":[{"id":"1.195453759","rc":[{"atl":[[42,0]],"id":3805755},{"atb":[[8,2.72]],"id":522741}],"con":true,"img":false}]}
{"op":"mcm","clk":"5348867323","pt":1646221392009,"mc":[{"id":"1.195453759","rc":[{"atl":[[34,0],[36,2.86]],"id":3805783},{"atb":[[5.8,12.31]],"id":522746},{"atl":[[15.5,31.99]],"id":3805730},{"atl":[[34,15.24],[13.5,9.9]],"id":522742},{"atl":[[75,34.06]],"id":522743}],"con":true,"img":false}]}
{"op":"mcm","clk":"5348867330","pt":1646221392101,"mc":[{"id":"1.195453759","rc":[{"atl":[[40,4.06]],"id":3805755},{"atb":[[6.2,9.9],[7.6,0],[6.8,63.82]],"id":3805736},{"atl":[[24,0],[28,5.86]],"id":522752},{"atl":[[14.5,0]],"id":3805730},{"atl":[[65,0]],"id":522743}],"con":true,"img":false}]}
{"op":"mcm","clk":"5348867336","pt":1646221392152,"mc":[{"id":"1.195453759","rc":[{"atl":[[29,5.66]],"id":3805783},{"atb":[[19,31.99],[21,7.93]],"id":522747},{"atl":[[75,22.45],[100,0]],"id":522745}],"con":true,"img":false}]}
{"op":"mcm","clk":"5348867347","pt":1646221392309,"mc":[{"id":"1.195453759","rc":[{"atl":[[9.6,12.21],[11.5,31.99],[9.4,0]],"id":3805746},{"atb":[[5.8,7.35],[6.6,4.95],[5.9,9.9]],"id":522746},{"atb":[[19,22.08],[22,0]],"id":522747},{"atl":[[13,4.95],[13.5,0],[14.5,8.91],[15,9.9],[15.5,22.08]],"id":3805730},{"atl":[[130,0],[170,0]],"id":522753},{"atl":[[70,9.9],[75,24.15],[50,4.95],[55,0],[60,2.68]],"id":522743},{"atl":[[34,4.95],[38,0],[42,9.9],[46,0]],"id":522745}],"con":true,"img":false}]}
{"op":"mcm","clk":"5348867355","pt":1646221392360,"mc":[{"id":"1.195453759","rc":[{"atl":[[13.5,22.12]],"id":522742},{"atl":[[70,2.29]],"id":522745}],"con":true,"img":false}]}
{"op":"mcm","clk":"5348867361","pt":1646221392464,"mc":[{"id":"1.195453759","rc":[{"atl":[[38,4.28]],"id":522750},{"atl":[[200,0],[220,2]],"id":522753}],"con":true,"img":false}]}
{"op":"mcm","clk":"5348867396","pt":1646221392775,"mc":[{"id":"1.195453759","rc":[{"atb":[[7.2,4.95],[6.4,12.63],[6.2,0]],"id":3805736},{"atl":[[23,4.95],[27,9.9]],"id":522752}],"con":true,"img":false}]}
{"op":"mcm","clk":"5348867413","pt":1646221392996,"mc":[{"id":"1.195453759","rc":[{"atb":[[21,17.83],[25,4.95]],"id":522747},{"atl":[[150,9.9],[110,4.95]],"id":522753}],"con":true,"img":false}]}
{"op":"mcm","clk":"5348867424","pt":1646221393087,"mc":[{"id":"1.195453759","rc":[{"atl":[[9.8,17.17]],"id":3805746}],"con":true,"img":false}]}
{"op":"mcm","clk":"5348867466","pt":1646221393560,"mc":[{"id":"1.195453759","rc":[{"atb":[[8.8,0]],"id":522741}],"con":true,"img":false}]}
{"op":"mcm","clk":"5348867493","pt":1646221393975,"mc":[{"id":"1.195453759","rc":[{"atl":[[9.8,4.95]],"id":3805746}],"con":true,"img":false}]}
{"op":"mcm","clk":"5348867539","pt":1646221394396,"mc":[{"id":"1.195453759","rc":[{"atb":[[6.2,4.95],[5.7,12.63],[6.6,0],[5.9,0]],"id":522746},{"atb":[[7.2,0],[6.4,2.72],[6.2,9.9],[7,4.95]],"id":3805736},{"atl":[[34,0],[36,4.95],[42,0]],"id":522750},{"atl":[[150,0],[160,9.9],[110,0],[120,4.95]],"id":522753},{"atb":[[8,24.81]],"id":522741},{"atl":[[34,0],[36,4.95],[42,0],[44,9.9]],"id":522745}],"con":true,"img":false}]}
{"op":"mcm","clk":"5348867550","pt":1646221394498,"mc":[{"id":"1.195453759","rc":[{"atl":[[38,0],[40,9.02],[46,0],[48,9.9]],"id":3805755},{"atl":[[44,4.95],[46,0],[55,39.36],[60,0]],"id":522747},{"atl":[[34,9.9],[36,0],[28,4.95],[29,5.66]],"id":522749}],"con":true,"img":false}]}
{"op":"mcm","clk":"5348867593","pt":1646221394866,"mc":[{"id":"1.195453759","rc":[{"atl":[[36,18.63],[30,4.95]],"id":3805783}],"con":true,"img":false}]}
{"op":"mcm","clk":"5348867601","pt":1646221394969,"mc":[{"id":"1.195453759","rc":[{"atl":[[34,33.04],[90,2],[28,10.82]],"id":522749}],"con":true,"img":false}]}
{"op":"mcm","clk":"5348867610","pt":1646221395072,"mc":[{"id":"1.195453759","rc":[{"atl":[[10.5,21.64],[11,0],[12.5,53.87],[13,0]],"id":522746},{"atb":[[6.2,0],[6.8,68.78],[7,0]],"id":3805736},{"atl":[[44,9.9]],"id":522750},{"atb":[[16,0],[16.5,9.9],[18,0],[18.5,4.95]],"id":522745}],"con":true,"img":false}]}
{"op":"mcm","clk":"5348867629","pt":1646221395381,"mc":[{"id":"1.195453759","rc":[{"atb":[[6.4,44.46],[6.8,27.04]],"id":3805736}],"con":true,"img":false}]}
{"op":"mcm","clk":"5348867649","pt":1646221395589,"mc":[{"id":"1.195453759","rc":[{"atl":[[12.5,9.9],[15.5,36.61]],"id":522746}],"con":true,"img":false}]}
{"op":"mcm","clk":"5348867658","pt":1646221395694,"mc":[{"id":"1.195453759","rc":[{"atl":[[29,0]],"id":522749}],"con":true,"img":false}]}
{"op":"mcm","clk":"5348867678","pt":1646221395901,"mc":[{"id":"1.195453759","rc":[{"atl":[[34,4.95],[36,0],[42,9.9],[44,0]],"id":522745}],"con":true,"img":false}]}
{"op":"mcm","clk":"5348867720","pt":1646221396263,"mc":[{"id":"1.195453759","rc":[{"atl":[[23,0],[24,4.95],[27,0],[28,15.77]],"id":522752}],"con":true,"img":false}]}
{"op":"mcm","clk":"5348867749","pt":1646221396575,"mc":[{"id":"1.195453759","rc":[{"atl":[[34,0],[36,4.95],[42,0],[44,9.9]],"id":522745}],"con":true,"img":false}]}
{"op":"mcm","clk":"5348867783","pt":1646221396886,"mc":[{"id":"1.195453759","rc":[{"atb":[[20,9.9],[21,7.93],[24,4.95],[25,0]],"id":522747}],"con":true,"img":false}]}
{"op":"mcm","clk":"5348867846","pt":1646221397457,"mc":[{"id":"1.195453759","rc":[{"atb":[[24,11.84]],"id":522747},{"atb":[[5.7,28.34],[7.8,46.83]],"id":522742},{"atl":[[70,26.68],[75,0]],"id":522743}],"con":true,"img":false}]}
{"op":"mcm","clk":"5348867859","pt":1646221397665,"mc":[{"id":"1.195453759","rc":[{"atb":[[5.6,9.9],[6.2,0],[6,4.95],[5.7,2.72]],"id":522746},{"atb":[[19,0],[20,29.05]],"id":522747},{"atb":[[5.7,28.34],[8.4,42.04]],"id":3805730},{"atl":[[11.5,20.05]],"id":522742}],"con":true,"img":false}]}
{"op":"mcm","clk":"5348867913","pt":1646221398293,"mc":[{"id":"1.195453759","rc":[{"atb":[[21,0]],"id":522747}],"con":true,"img":false}]}
{"op":"mcm","clk":"5348867922","pt":1646221398397,"mc":[{"id":"1.195453759","rc":[{"atl":[[13.5,9.9]],"id":522742}],"con":true,"img":false}]}
{"op":"mcm","clk":"5348868025","pt":1646221399598,"mc":[{"id":"1.195453759","rc":[{"atl":[[18.5,9.05],[18,4.95],[20,9.9],[21,0]],"id":522741}],"con":true,"img":false}]}
{"op":"mcm","clk":"5348868031","pt":1646221399702,"mc":[{"id":"1.195453759","rc":[{"atb":[[12,0],[9.8,0]],"id":522747}],"con":true,"img":false}]}
{"op":"mcm","clk":"5348868037","pt":1646221399806,"mc":[{"id":"1.195453759","rc":[{"atb":[[16,0],[13.5,0]],"id":3805755},{"atb":[[11,0],[13.5,0]],"id":522752},{"atb":[[8.4,0],[9.4,0]],"id":522742}],"con":true,"img":false}]}
{"op":"mcm","clk":"5348868051","pt":1646221399965,"mc":[{"id":"1.195453759","rc":[{"atl":[[17.5,9.6],[20,38.1],[40,2.56]],"id":522741}],"con":true,"img":false}]}
{"op":"mcm","clk":"5348868057","pt":1646221400068,"mc":[{"id":"1.195453759","rc":[{"atl":[[34,9.9]],"id":522749}],"con":true,"img":false}]}
{"op":"mcm","clk":"5348868066","pt":1646221400172,"mc":[{"id":"1.195453759","rc":[{"atl":[[65,30.13]],"id":3805755},{"atb":[[5.7,28.39]],"id":522746},{"atl":[[90,23.84]],"id":522749},{"atl":[[34,15.24]],"id":522752}],"con":true,"img":false}]}
{"op":"mcm","clk":"5348868073","pt":1646221400280,"mc":[{"id":"1.195453759","rc":[{"atb":[[14.5,39.36],[15.5,0]],"id":3805755},{"atb":[[10,16.81],[9.2,76.38]],"id":522752},{"atb":[[8.2,4.95],[7.4,9.9],[7.6,28.19],[7,3.27],[8.4,0]],"id":522741}],"con":true,"img":false}]}
{"op":"mcm","clk":"5348868082","pt":1646221400379,"mc":[{"id":"1.195453759","rc":[{"atb":[[10,14.38],[12.5,2.72]],"id":522747}],"con":true,"img":false}]}
{"op":"mcm","clk":"5348868090","pt":1646221400484,"mc":[{"id":"1.195453759","rc":[{"atb":[[16.5,17.9],[14,3.27]],"id":3805755},{"atl":[[28,4.95]],"id":522749},{"atb":[[10.5,3.27],[13,2.72]],"id":522752},{"atb":[[9.2,2.72],[8.2,3.27]],"id":522742}],"con":true,"img":false}]}
{"op":"mcm","clk":"5348868098","pt":1646221400588,"mc":[{"id":"1.195453759","rc":[{"atb":[[6.4,2.72],[5.7,68.61]],"id":3805736}],"con":true,"img":false}]}
{"op":"mcm","clk":"5348868107","pt":1646221400692,"mc":[{"id":"1.195453759","rc":[{"atb":[[6,36.66]],"id":522746},{"atl":[[23,7.2]],"id":522752}],"con":true,"img":false}]}
{"op":"mcm","clk":"5348868135","pt":1646221401128,"mc":[{"id":"1.195453759","rc":[{"atb":[[9.8,0]],"id":522752},{"atl":[[18.5,0]],"id":522741}],"con":true,"img":false}]}
{"op":"mcm","clk":"5348868143","pt":1646221401214,"mc":[{"id":"1.195453759","rc":[{"atl":[[32,5.11]],"id":522749}],"con":true,"img":false}]}
{"op":"mcm","clk":"5348868164","pt":1646221401474,"mc":[{"id":"1.195453759","rc":[{"atb":[[5.8,0]],"id":522746},{"atl":[[28,9.9]],"id":522752},{"atl":[[170,0.93]],"id":522753}],"con":true,"img":false}]}
{"op":"mcm","clk":"5348868173","pt":1646221401578,"mc":[{"id":"1.195453759","rc":[{"atl":[[36,9.48]],"id":522750}],"con":true,"img":false}]}
{"op":"mcm","clk":"5348868189","pt":1646221401787,"mc":[{"id":"1.195453759","rc":[{"atl":[[40,0],[42,4.95],[48,0],[50,9.9]],"id":3805755}],"con":true,"img":false}]}
{"op":"mcm","clk":"5348868200","pt":1646221401998,"mc":[{"id":"1.195453759","rc":[{"atb":[[5.6,0],[9.2,0],[4.6,0]],"id":3805783},{"atb":[[5.3,0],[3.15,0],[3.65,0]],"id":3805746},{"atb":[[9.8,0],[4.9,0],[5.9,0]],"id":3805755},{"atl":[[65,28.13],[80,2]],"id":3805755},{"atb":[[2.9,0],[3.75,0],[2.7,0]],"id":522746},{"atb":[[2.9,0],[3.75,0],[2.7,0]],"id":3805736},{"atb":[[4.5,0],[7,0],[3.75,0]],"id":522747},{"atb":[[3.6,0],[6.4,0],[4.2,0]],"id":522749},{"atb":[[9.8,0],[4.9,0],[5.9,0]],"id":522750},{"atb":[[5.6,0],[9.2,60.14],[4.6,0]],"id":522752},{"atb":[[3.85,0],[3.35,0],[5.7,0]],"id":3805730},{"atb":[[17,0],[6.8,0],[8.8,0]],"id":522753},{"atl":[[170,12.52],[180,0.88]],"id":522753},{"atb":[[2.82,0],[8.2,26.59],[4.1,0],[3.05,0]],"id":522741},{"atb":[[3.85,0],[3.35,0],[5.7,0]],"id":522742},{"atb":[[6.4,0],[11,0],[5.2,0]],"id":522743},{"atb":[[5.1,0],[10.5,0],[6.2,0]],"id":522745}],"con":true,"img":false}]}
{"op":"mcm","clk":"5348868206","pt":1646221402100,"mc":[{"id":"1.195453759","rc":[{"atb":[[5.6,0],[5.5,9.9],[6,0],[5.9,4.95]],"id":522746},{"atl":[[13,0],[13.5,4.95],[15,0],[15.5,31.99]],"id":3805730}],"con":true,"img":false}]}
{"op":"mcm","clk":"5348868217","pt":1646221402311,"mc":[{"id":"1.195453759","rc":[{"atl":[[38,0]],"id":522750},{"atl":[[180,0]],"id":522753}],"con":true,"img":false}]}
{"op":"mcm","clk":"5348868243","pt":1646221402572,"mc":[{"id":"1.195453759","rc":[{"atl":[[60,2.68]],"id":3805755}],"con":true,"img":false}]}
{"op":"mcm","clk":"5348868259","pt":1646221402780,"mc":[{"id":"1.195453759","rc":[{"atb":[[5.8,4.95],[5.5,0],[5.7,62.13],[5.9,0],[5.4,9.9]],"id":522746},{"atb":[[20,9.9],[12.5,27.69]],"id":522747},{"atl":[[40,0],[44,40.88]],"id":522750},{"atb":[[8,2.72]],"id":522741}],"con":true,"img":false}]}
{"op":"mcm","clk":"5348868267","pt":1646221402884,"mc":[{"id":"1.195453759","rc":[{"atl":[[42,0],[44,4.95],[50,0],[55,9.9]],"id":3805755},{"atl":[[70,22.75],[75,2]],"id":522745}],"con":true,"img":false}]}
{"op":"mcm","clk":"5348868276","pt":1646221402987,"mc":[{"id":"1.195453759","rc":[{"atl":[[65,0],[60,24.77]],"id":3805755},{"atl":[[50,8.19]],"id":522743},{"atl":[[36,9.48]],"id":522745}],"con":true,"img":false}]}
{"op":"mcm","clk":"5348868296","pt":1646221403298,"mc":[{"id":"1.195453759","rc":[{"atl":[[29,0]],"id":3805783}],"con":true,"img":false}]}
{"op":"mcm","clk":"5348868341","pt":1646221403820,"mc":[{"id":"1.195453759","rc":[{"atl":[[34,14.71],[36,2.86]],"id":3805783},{"atb":[[6.4,0],[5.7,0]],"id":3805746},{"atl":[[60,0]],"id":522743},{"atl":[[70,20.45]],"id":522745}],"con":true,"img":false}]}
{"op":"mcm","clk":"5348868360","pt":1646221403975,"mc":[{"id":"1.195453759","rc":[{"atl":[[34,19.52]],"id":3805783}],"con":true,"img":false}]}
{"op":"mcm","clk":"5348868389","pt":1646221404288,"mc":[{"id":"1.195453759","rc":[{"atl":[[36,0],[38,2.7]],"id":3805783}],"con":true,"img":false}]}
{"op":"mcm","clk":"5348868399","pt":1646221404390,"mc":[{"id":"1.195453759","rc":[{"atb":[[5.2,95.13],[5.4,34.41]],"id":3805746},{"atl":[[70,9.9],[120,18.48]],"id":522743}],"con":true,"img":false}]}
{"op":"mcm","clk":"5348868411","pt":1646221404496,"mc":[{"id":"1.195453759","rc":[{"atl":[[32,4.95],[40,9.9],[30,0]],"id":3805783}],"con":true,"img":false}]}
{"op":"mcm","clk":"5348868420","pt":1646221404598,"mc":[{"id":"1.195453759","rc":[{"atb":[[13,15.93]],"id":3805783}],"con":true,"img":false}]}
{"op":"mcm","clk":"5348868430","pt":1646221404701,"mc":[{"id":"1.195453759","rc":[{"atb":[[5.8,3.27],[6.6,2.72]],"id":3805746},{"atb":[[5.8,0],[5.3,9.9],[5.7,67.08],[5.4,0]],"id":522746}],"con":true,"img":false}]}
{"op":"mcm","clk":"5348868474","pt":1646221405276,"mc":[{"id":"1.195453759","rc":[{"atb":[[5.2,50.16],[5.7,41.41]],"id":522746}],"con":true,"img":false}]}
{"op":"mcm","clk":"5348868490","pt":1646221405483,"mc":[{"id":"1.195453759","rc":[{"atb":[[14,44.62],[14.5,9.9]],"id":3805755}],"con":true,"img":false}]}
{"op":"mcm","clk":"5348868498","pt":1646221405588,"mc":[{"id":"1.195453759","rc":[{"atl":[[34,32.23],[90,2],[28,10.82]],"id":522749}],"con":true,"img":false}]}
{"op":"mcm","clk":"5348868507","pt":1646221405694,"mc":[{"id":"1.195453759","rc":[{"atl":[[32,0],[34,24.47],[40,0]],"id":3805783},{"atb":[[4.6,27.78],[4.9,0]],"id":522746}],"con":true,"img":false}]}
{"op":"mcm","clk":"5348868557","pt":1646221406370,"mc":[{"id":"1.195453759","rc":[{"atl":[[32,0],[28,4.95]],"id":522749}],"con":true,"img":false}]}
{"op":"mcm","clk":"5348868577","pt":1646221406686,"mc":[{"id":"1.195453759","rc":[{"atl":[[44,0],[46,4.95],[55,0],[60,34.68]],"id":3805755}],"con":true,"img":false}]}
{"op":"mcm","clk":"5348868612","pt":1646221407098,"mc":[{"id":"1.195453759","rc":[{"atl":[[60,12.59]],"id":3805755}],"con":true,"img":false}]}
{"op":"mcm","clk":"5348868643","pt":1646221407513,"mc":[{"id":"1.195453759","rc":[{"atl":[[80,26.82]],"id":3805755},{"atl":[[34,37.03]],"id":522749},{"atl":[[16,9.9],[13.5,0],[14,4.95],[15.5,22.08]],"id":3805730}],"con":true,"img":false}]}
{"op":"mcm","clk":"5348868694","pt":1646221408199,"mc":[{"id":"1.195453759","rc":[{"atl":[[70,30.4],[44,9.9]],"id":522750},{"atl":[[14,17.15]],"id":3805730}],"con":true,"img":false}]}
{"op":"mcm","clk":"5348868780","pt":1646221409189,"mc":[{"id":"1.195453759","rc":[{"atl":[[34,9.76],[40,31.04]],"id":3805783},{"atl":[[14.5,0]],"id":3805730}],"con":true,"img":false}]}
{"op":"mcm","clk":"5348868802","pt":1646221409390,"mc":[{"id":"1.195453759","rc":[{"atl":[[22,4.95],[24,0],[26,9.9],[28,0]],"id":522752}],"con":true,"img":false}]}
{"op":"mcm","clk":"5348868811","pt":1646221409499,"mc":[{"id":"1.195453759","rc":[{"atl":[[130,4.95],[160,0],[170,22.43],[120,0]],"id":522753}],"con":true,"img":false}]}
{"op":"mcm","clk":"5348868821","pt":1646221409596,"mc":[{"id":"1.195453759","rc":[{"atl":[[40,33.6]],"id":3805783}],"con":true,"img":false}]}
{"op":"mcm","clk":"5348868833","pt":1646221409708,"mc":[{"id":"1.195453759","rc":[{"atl":[[38,0]],"id":3805783},{"atl":[[16,50.13],[15.5,0]],"id":3805730}],"con":true,"img":false}]}
{"op":"mcm","clk":"5348868857","pt":1646221410018,"mc":[{"id":"1.195453759","rc":[{"atl":[[170,10.84],[220,11.05]],"id":522753}],"con":true,"img":false}]}
{"op":"mcm","clk":"5348868895","pt":1646221410481,"mc":[{"id":"1.195453759","rc":[{"atb":[[6.6,0]],"id":3805746}],"con":true,"img":false}]}
{"op":"mcm","clk":"5348868902","pt":1646221410584,"mc":[{"id":"1.195453759","rc":[{"atb":[[5.8,0]],"id":3805746}],"con":true,"img":false}]}
{"op":"mcm","clk":"5348868914","pt":1646221410691,"mc":[{"id":"1.195453759","rc":[{"atl":[[34,14.71],[90,24.17]],"id":522749},{"atl":[[34,3.03],[26,27.98]],"id":522752}],"con":true,"img":false}]}
{"op":"mcm","clk":"5348868934","pt":1646221410899,"mc":[{"id":"1.195453759","rc":[{"atb":[[10,34.88],[9.2,9.9]],"id":522752}],"con":true,"img":false}]}
{"op":"mcm","clk":"5348868939","pt":1646221411001,"mc":[{"id":"1.195453759","rc":[{"atb":[[5.8,25.52]],"id":3805746}],"con":true,"img":false}]}
{"op":"mcm","clk":"5348868948","pt":1646221411106,"mc":[{"id":"1.195453759","rc":[{"atb":[[3.7,135.75],[5.2,0]],"id":3805746}],"con":true,"img":false}]}
{"op":"mcm","clk":"5348868955","pt":1646221411215,"mc":[{"id":"1.195453759","rc":[{"atb":[[5.1,64.97],[10.5,32],[6.2,70.46]],"id":3805783},{"atb":[[5.1,32.48],[6.4,2.72],[3.55,104.47],[3.05,129.95]],"id":3805746},{"atb":[[5.3,61.95],[11.5,12.68],[6.6,47.57]],"id":3805755},{"atb":[[2.56,170.77],[3.4,55.49],[2.76,151.36]],"id":522746},{"atb":[[2.92,138.75],[2.72,154.88],[3.8,47.57]],"id":3805736},{"atb":[[4.8,70.1],[7.6,20.18],[3.9,91.86]],"id":522747},{"atb":[[4.3,80.72],[6.6,23.78],[3.65,100.52]],"id":522749},{"atb":[[9.6,15.48],[4.8,70.1],[5.8,55.49]],"id":522750},{"atb":[[9,16.65],[4.5,76.11],[5.5,81.41]],"id":522752},{"atl":[[22,12.5]],"id":522752},{"atb":[[6.2,25.61],[4.1,85.93],[3.55,104.47]],"id":3805730},{"atb":[[18.5,7.61],[7.4,41.62],[9.4,31.71]],"id":522753},{"atb":[[3.1,126.85],[2.84,144.78],[4.2,41.62]],"id":522741},{"atb":[[5.5,29.59],[3.25,118.39],[3.75,96.87]],"id":522742},{"atb":[[5.6,57.91],[7.2,42.96],[13,11.1]],"id":522743},{"atb":[[5.3,61.95],[11.5,12.68],[6.6,47.57]],"id":522745}],"con":true,"img":false}]}
{"op":"mcm","clk":"5348868961","pt":1646221411320,"mc":[{"id":"1.195453759","rc":[{"atb":[[5.7,3.27]],"id":3805746}],"con":true,"img":false}]}
{"op":"mcm","clk":"5348868994","pt":1646221411690,"mc":[{"id":"1.195453759","rc":[{"atl":[[28,10.82]],"id":522749}],"con":true,"img":false}]}
{"op":"mcm","clk":"5348869002","pt":1646221411797,"mc":[{"id":"1.195453759","rc":[{"atb":[[5.4,4.95]],"id":3805746}],"con":true,"img":false}]}
{"op":"mcm","clk":"5348869009","pt":1646221411898,"mc":[{"id":"1.195453759","rc":[{"atb":[[3.7,37.04]],"id":3805746}],"con":true,"img":false}]}
{"op":"mcm","clk":"5348869018","pt":1646221412002,"mc":[{"id":"1.195453759","rc":[{"atl":[[23,0]],"id":522752},{"atl":[[120,1.32]],"id":522753}],"con":true,"img":false}]}
{"op":"mcm","clk":"5348869023","pt":1646221412107,"mc":[{"id":"1.195453759","rc":[{"atb":[[8.2,21.64],[7.4,0],[7.6,38.1],[8.4,4.95]],"id":522741}],"con":true,"img":false}]}
{"op":"mcm","clk":"5348869028","pt":1646221412215,"mc":[{"id":"1.195453759","rc":[{"atl":[[9,4.95],[11.5,22.08]],"id":3805746}],"con":true,"img":false}]}
{"op":"mcm","clk":"5348869045","pt":1646221412422,"mc":[{"id":"1.195453759","rc":[{"atl":[[34,9.9],[28,4.95]],"id":522749}],"con":true,"img":false}]}
{"op":"mcm","clk":"5348869052","pt":1646221412525,"mc":[{"id":"1.195453759","rc":[{"atl":[[170,22.61]],"id":522753}],"con":true,"img":false}]}
{"op":"mcm","clk":"5348869059","pt":1646221412586,"mc":[{"id":"1.195453759","rc":[{"atl":[[220,2]],"id":522753},{"atb":[[8,24.36],[7.6,9.9],[8.4,26.37]],"id":522741}],"con":true,"img":false}]}
{"op":"mcm","clk":"5348869067","pt":1646221412684,"mc":[{"id":"1.195453759","rc":[{"atl":[[9,19.66],[11.5,0],[9.8,19.66]],"id":3805746},{"atb":[[21,0],[26,0]],"id":522753},{"atl":[[170,21.67]],"id":522753}],"con":true,"img":false}]}
{"op":"mcm","clk":"5348869077","pt":1646221412890,"mc":[{"id":"1.195453759","rc":[{"atl":[[44,4.95],[46,0],[55,9.9],[60,2.68]],"id":3805755}],"con":true,"img":false}]}
{"op":"mcm","clk":"5348869083","pt":1646221412996,"mc":[{"id":"1.195453759","rc":[{"atl":[[9,14.71],[9.2,4.95],[10,9.9],[9.8,14.71]],"id":3805746}],"con":true,"img":false}]}
{"op":"mcm","clk":"5348869089","pt":1646221413100,"mc":[{"id":"1.195453759","rc":[{"atl":[[44,8.64]],"id":3805755},{"atl":[[34,14.71]],"id":522749}],"con":true,"img":false}]}
{"op":"mcm","clk":"5348869104","pt":1646221413308,"mc":[{"id":"1.195453759","rc":[{"atl":[[80,2],[60,32.14]],"id":3805755},{"atb":[[8.2,0]],"id":522741}],"con":true,"img":false}]}
{"op":"mcm","clk":"5348869111","pt":1646221413412,"mc":[{"id":"1.195453759","rc":[{"atl":[[9.6,0],[9,0]],"id":3805746},{"atb":[[22,3.27],[27,28.49]],"id":522753}],"con":true,"img":false}]}
{"op":"mcm","clk":"5348869145","pt":1646221413826,"mc":[{"id":"1.195453759","rc":[{"atl":[[60,29.45]],"id":3805755}],"con":true,"img":false}]}
{"op":"mcm","clk":"5348869169","pt":1646221414087,"mc":[{"id":"1.195453759","rc":[{"atl":[[9.8,23.63]],"id":3805746}],"con":true,"img":false}]}
{"op":"mcm","clk":"5348869184","pt":1646221414295,"mc":[{"id":"1.195453759","rc":[{"atl":[[38,47.38],[40,2.56]],"id":3805783}],"con":true,"img":false}]}
{"op":"mcm","clk":"5348869229","pt":1646221414918,"mc":[{"id":"1.195453759","rc":[{"atb":[[5.7,25.35]],"id":3805746},{"atl":[[23,36.8]],"id":3805730}],"con":true,"img":false}]}
{"op":"mcm","clk":"5348869236","pt":1646221415022,"mc":[{"id":"1.195453759","rc":[{"atl":[[16,9.9]],"id":3805730}],"con":true,"img":false}]}
{"op":"mcm","clk":"5348869293","pt":1646221415798,"mc":[{"id":"1.195453759","rc":[{"atl":[[34,26.47],[26,9.9]],"id":522752}],"con":true,"img":false}]}
{"op":"mcm","clk":"5348869310","pt":1646221416008,"mc":[{"id":"1.195453759","rc":[{"atl":[[28,10.82]],"id":522749}],"con":true,"img":false}]}
{"op":"mcm","clk":"5348869410","pt":1646221417099,"mc":[{"id":"1.195453759","rc":[{"atl":[[44,0],[46,4.95],[55,29.45],[60,9.9]],"id":522747},{"atl":[[34,9.9],[28,4.95]],"id":522749}],"con":true,"img":false}]}
{"op":"mcm","clk":"5348869455","pt":1646221417615,"mc":[{"id":"1.195453759","rc":[{"atb":[[8,2.72]],"id":522741}],"con":true,"img":false}]}
{"op":"mcm","clk":"5348869463","pt":1646221417720,"mc":[{"id":"1.195453759","rc":[{"atl":[[10,59.76],[9.8,8.91]],"id":3805746},{"atb":[[7.6,60.86]],"id":522741}],"con":true,"img":false}]}
{"op":"mcm","clk":"5348869483","pt":1646221417926,"mc":[{"id":"1.195453759","rc":[{"atl":[[34,14.71]],"id":522749}],"con":true,"img":false}]}
{"op":"mcm","clk":"5348869618","pt":1646221419449,"mc":[{"id":"1.195453759","rc":[{"atl":[[38,0],[40,40.76]],"id":3805783}],"con":true,"img":false}]}
{"op":"mcm","clk":"5348869664","pt":1646221419918,"mc":[{"id":"1.195453759","rc":[{"atb":[[10,3.27],[12.5,36.39]],"id":522747}],"con":true,"img":false}]}
{"op":"mcm","clk":"5348869686","pt":1646221420129,"mc":[{"id":"1.195453759","rc":[{"atb":[[19.5,9.9],[20,0],[23,4.95],[24,0]],"id":522747}],"con":true,"img":false}]}
{"op":"mcm","clk":"5348869693","pt":1646221420236,"mc":[{"id":"1.195453759","rc":[{"atb":[[9.6,0],[11,0],[11.5,4.95],[9.8,9.9]],"id":3805783},{"atb":[[6.4,0],[5.8,0],[5.7,22.08]],"id":3805746}],"con":true,"img":false}]}
{"op":"mcm","clk":"5348869699","pt":1646221420341,"mc":[{"id":"1.195453759","rc":[{"atb":[[5.6,4.95],[5.3,0],[5.2,60.07],[5.7,2.72]],"id":522746},{"atl":[[36,0],[38,4.95],[44,0],[46,9.9]],"id":522745}],"con":true,"img":false}]}
{"op":"mcm","clk":"5348869714","pt":1646221420501,"mc":[{"id":"1.195453759","rc":[{"atb":[[5.7,0]],"id":3805746},{"atl":[[16,0],[16.5,9.9],[14,0],[14.5,4.95]],"id":3805730}],"con":true,"img":false}]}
{"op":"mcm","clk":"5348869746","pt":1646221420924,"mc":[{"id":"1.195453759","rc":[{"atl":[[32,4.95],[34,4.8],[40,50.66]],"id":3805783},{"atb":[[5.6,3.27],[6.2,2.72],[5.2,7.35]],"id":3805746},{"atb":[[13,13.1]],"id":522747}],"con":true,"img":false}]}
{"op":"mcm","clk":"5348869755","pt":1646221421031,"mc":[{"id":"1.195453759","rc":[{"atb":[[5.1,78.58]],"id":3805746}],"con":true,"img":false}]}
{"op":"mcm","clk":"5348869761","pt":1646221421138,"mc":[{"id":"1.195453759","rc":[{"atb":[[5.6,27.04]],"id":522746},{"atl":[[65,2.47]],"id":522745}],"con":true,"img":false}]}
{"op":"mcm","clk":"5348869769","pt":1646221421238,"mc":[{"id":"1.195453759","rc":[{"atl":[[14.5,13.87]],"id":3805730}],"con":true,"img":false}]}
{"op":"mcm","clk":"5348869776","pt":1646221421291,"mc":[{"id":"1.195453759","rc":[{"atl":[[16.5,0],[14.5,8.91]],"id":3805730}],"con":true,"img":false}]}
{"op":"mcm","clk":"5348869785","pt":1646221421397,"mc":[{"id":"1.195453759","rc":[{"atl":[[32,10.06]],"id":3805783}],"con":true,"img":false}]}
{"op":"mcm","clk":"5348869794","pt":1646221421501,"mc":[{"id":"1.195453759","rc":[{"atb":[[13,35.19]],"id":522747}],"con":true,"img":false}]}
{"op":"mcm","clk":"5348869809","pt":1646221421709,"mc":[{"id":"1.195453759","rc":[{"atl":[[23,0],[25,4.17],[15.5,26.51]],"id":3805730},{"atl":[[65,22.93],[70,0]],"id":522745}],"con":true,"img":false}]}
{"op":"mcm","clk":"5348869816","pt":1646221421816,"mc":[{"id":"1.195453759","rc":[{"atb":[[12.5,11.42]],"id":522747}],"con":true,"img":false}]}
{"op":"mcm","clk":"5348869830","pt":1646221422022,"mc":[{"id":"1.195453759","rc":[{"atl":[[28,10.82]],"id":522749},{"atl":[[16,9.9],[14,4.95]],"id":3805730}],"con":true,"img":false}]}
{"op":"mcm","clk":"5348869852","pt":1646221422337,"mc":[{"id":"1.195453759","rc":[{"atl":[[34,0]],"id":3805783}],"con":true,"img":false}]}
{"op":"mcm","clk":"5348869910","pt":1646221422905,"mc":[{"id":"1.195453759","rc":[{"atl":[[34,9.9],[28,4.95]],"id":522749}],"con":true,"img":false}]}
{"op":"mcm","clk":"5348869918","pt":1646221423009,"mc":[{"id":"1.195453759","rc":[{"atl":[[9.2,19.66]],"id":3805746}],"con":true,"img":false}]}
{"op":"mcm","clk":"5348869981","pt":1646221423693,"mc":[{"id":"1.195453759","rc":[{"atl":[[34,14.71]],"id":522749}],"con":true,"img":false}]}
{"op":"mcm","clk":"5348869998","pt":1646221423901,"mc":[{"id":"1.195453759","rc":[{"atl":[[9.8,0]],"id":3805746}],"con":true,"img":false}]}
{"op":"mcm","clk":"5348870028","pt":1646221424423,"mc":[{"id":"1.195453759","rc":[{"atl":[[70,14.21],[10,9.9]],"id":3805746}],"con":true,"img":false}]}
{"op":"mcm","clk":"5348870046","pt":1646221424632,"mc":[{"id":"1.195453759","rc":[{"atl":[[36,47.38],[40,12.46]],"id":3805783}],"con":true,"img":false}]}
{"op":"mcm","clk":"5348870075","pt":1646221425100,"mc":[{"id":"1.195453759","rc":[{"atb":[[5.1,32.48],[5.4,27.04]],"id":3805746}],"con":true,"img":false}]}
{"op":"mcm","clk":"5348870092","pt":1646221425411,"mc":[{"id":"1.195453759","rc":[{"atl":[[36,0]],"id":3805783}],"con":true,"img":false}]}
{"op":"mcm","clk":"5348870154","pt":1646221426037,"mc":[{"id":"1.195453759","rc":[{"atb":[[9.2,0],[8.2,0]],"id":522742}],"con":true,"img":false}]}
{"op":"mcm","clk":"5348870182","pt":1646221426348,"mc":[{"id":"1.195453759","rc":[{"atl":[[28,10.82]],"id":522749}],"con":true,"img":false}]}
{"op":"mcm","clk":"5348870214","pt":1646221426612,"mc":[{"id":"1.195453759","rc":[{"atb":[[5.6,0]],"id":3805746},{"atb":[[5.5,82.08],[7.8,16.81]],"id":522742}],"con":true,"img":false}]}
{"op":"mcm","clk":"5348870225","pt":1646221426714,"mc":[{"id":"1.195453759","rc":[{"atb":[[6.2,0]],"id":3805746}],"con":true,"img":false}]}
{"op":"mcm","clk":"5348870243","pt":1646221426923,"mc":[{"id":"1.195453759","rc":[{"atb":[[8,3.27],[9,2.72]],"id":522742}],"con":true,"img":false}]}
{"op":"mcm","clk":"5348870253","pt":1646221427032,"mc":[{"id":"1.195453759","rc":[{"atb":[[5.2,43.22],[5.4,4.95]],"id":3805746},{"atl":[[34,9.9],[28,4.95]],"id":522749}],"con":true,"img":false}]}
{"op":"mcm","clk":"5348870292","pt":1646221427459,"mc":[{"id":"1.195453759","rc":[{"atb":[[5.5,3.27]],"id":3805746}],"con":true,"img":false}]}
{"op":"mcm","clk":"5348870304","pt":1646221427509,"mc":[{"id":"1.195453759","rc":[{"atb":[[6,2.72]],"id":3805746}],"con":true,"img":false}]}
{"op":"mcm","clk":"5348870328","pt":1646221427812,"mc":[{"id":"1.195453759","rc":[{"atl":[[34,14.71]],"id":522749}],"con":true,"img":false}]}
{"op":"mcm","clk":"5348870345","pt":1646221428020,"mc":[{"id":"1.195453759","rc":[{"atb":[[10,0]],"id":3805730}],"con":true,"img":false}]}
{"op":"mcm","clk":"5348870354","pt":1646221428127,"mc":[{"id":"1.195453759","rc":[{"atb":[[9,0]],"id":3805730}],"con":true,"img":false}]}
{"op":"mcm","clk":"5348870397","pt":1646221428544,"mc":[{"id":"1.195453759","rc":[{"atb":[[9,19.81],[8.2,25.57],[8.4,21.42]],"id":3805730}],"con":true,"img":false}]}
{"op":"mcm","clk":"5348870420","pt":1646221428701,"mc":[{"id":"1.195453759","rc":[{"atb":[[11,2.72]],"id":3805730}],"con":true,"img":false}]}
{"op":"mcm","clk":"5348870429","pt":1646221428803,"mc":[{"id":"1.195453759","rc":[{"atl":[[9.6,9.9],[9.2,14.71],[10,0],[8.8,4.95]],"id":3805746},{"atb":[[9.4,3.27]],"id":3805730}],"con":true,"img":false}]}
{"op":"mcm","clk":"5348870483","pt":1646221429424,"mc":[{"id":"1.195453759","rc":[{"atl":[[9.6,24.62],[70,2],[8.8,19.66]],"id":3805746},{"atb":[[8.4,0]],"id":3805730}],"con":true,"img":false}]}
{"op":"mcm","clk":"5348870506","pt":1646221429735,"mc":[{"id":"1.195453759","rc":[{"atl":[[36,37.07]],"id":3805783}],"con":true,"img":false}]}
{"op":"mcm","clk":"5348870580","pt":1646221430414,"mc":[{"id":"1.195453759","rc":[{"atl":[[9.2,0]],"id":3805746}],"con":true,"img":false}]}
{"op":"mcm","clk":"5348870641","pt":1646221431037,"mc":[{"id":"1.195453759","rc":[{"atb":[[23,12.15]],"id":522747}],"con":true,"img":false}]}
{"op":"mcm","clk":"5348870662","pt":1646221431245,"mc":[{"id":"1.195453759","rc":[{"atb":[[5.2,7.35],[5.4,17.17]],"id":3805746},{"atb":[[5.7,36.46]],"id":522746},{"atl":[[38,9.23]],"id":522745}],"con":true,"img":false}]}
{"op":"mcm","clk":"5348870677","pt":1646221431405,"mc":[{"id":"1.195453759","rc":[{"atl":[[14,17.15]],"id":3805730}],"con":true,"img":false}]}
{"op":"mcm","clk":"5348870712","pt":1646221431719,"mc":[{"id":"1.195453759","rc":[{"atl":[[32,5.11],[38,9.9],[40,2.56],[30,4.95]],"id":3805783}],"con":true,"img":false}]}
{"op":"mcm","clk":"5348870722","pt":1646221431824,"mc":[{"id":"1.195453759","rc":[{"atb":[[13,22.08]],"id":522747}],"con":true,"img":false}]}
{"op":"mcm","clk":"5348870728","pt":1646221431927,"mc":[{"id":"1.195453759","rc":[{"atl":[[65,20.45]],"id":522745}],"con":true,"img":false}]}
{"op":"mcm","clk":"5348870740","pt":1646221432135,"mc":[{"id":"1.195453759","rc":[{"atb":[[5.6,4.95]],"id":522746},{"atl":[[28,10.82]],"id":522749}],"con":true,"img":false}]}
{"op":"mcm","clk":"5348870752","pt":1646221432239,"mc":[{"id":"1.195453759","rc":[{"atl":[[30,10.42]],"id":3805783},{"atl":[[14.5,0]],"id":3805730}],"con":true,"img":false}]}
{"op":"mcm","clk":"5348870770","pt":1646221432449,"mc":[{"id":"1.195453759","rc":[{"atb":[[5.1,0],[10.5,17.98],[6.2,19.23]],"id":3805783},{"atb":[[5.1,0],[3.55,0],[3.05,0]],"id":3805746},{"atb":[[5.3,0],[11.5,0],[6.6,0]],"id":3805755},{"atb":[[2.56,0],[3.4,0],[2.76,0]],"id":522746},{"atb":[[2.92,0],[2.72,0],[3.8,0]],"id":3805736},{"atb":[[4.8,0],[7.6,0],[3.9,0]],"id":522747},{"atb":[[4.3,0],[6.6,0],[3.65,0]],"id":522749},{"atb":[[9.6,0],[4.8,0],[5.8,0]],"id":522750},{"atb":[[9,0],[4.5,0],[5.5,22.22]],"id":522752},{"atb":[[6.2,0],[4.1,0],[3.55,0]],"id":3805730},{"atb":[[18.5,0],[7.4,0],[9.4,0]],"id":522753},{"atb":[[3.1,0],[2.84,0],[4.2,0]],"id":522741},{"atb":[[5.5,52.48],[3.25,0],[3.75,0]],"id":522742},{"atb":[[5.6,0],[7.2,0],[13,0]],"id":522743},{"atb":[[5.3,0],[11.5,0],[6.6,0]],"id":522745}],"con":true,"img":false}]}
{"op":"mcm","clk":"5348870809","pt":1646221432814,"mc":[{"id":"1.195453759","rc":[{"atl":[[34,9.9],[28,4.95]],"id":522749},{"atl":[[16,50.13],[15.5,0]],"id":3805730}],"con":true,"img":false}]}
{"op":"mcm","clk":"5348870835","pt":1646221433126,"mc":[{"id":"1.195453759","rc":[{"atl":[[32,0]],"id":3805783}],"con":true,"img":false}]}
{"op":"mcm","clk":"5348870903","pt":1646221433852,"mc":[{"id":"1.195453759","rc":[{"atl":[[34,14.71]],"id":522749}],"con":true,"img":false}]}
{"op":"mcm","clk":"5348870912","pt":1646221433956,"mc":[{"id":"1.195453759","rc":[{"atb":[[17.5,4.95],[15.5,9.9]],"id":3805755},{"atb":[[8.6,4.95],[8.2,20.61]],"id":3805730},{"atb":[[36,4.95],[29,9.9]],"id":522753},{"atb":[[23,9.9],[27,4.95]],"id":522743}],"con":true,"img":false}]}
{"op":"mcm","clk":"5348870921","pt":1646221434060,"mc":[{"id":"1.195453759","rc":[{"atb":[[16.5,12.95],[14.5,0]],"id":3805755},{"atb":[[34,4.8],[28,0]],"id":522753},{"atb":[[21,17.59],[25,0]],"id":522743}],"con":true,"img":false}]}
{"op":"mcm","clk":"5348870929","pt":1646221434111,"mc":[{"id":"1.195453759","rc":[{"atb":[[19.5,0],[21,9.9],[23,7.2],[25,4.95]],"id":522747}],"con":true,"img":false}]}
{"op":"mcm","clk":"5348870940","pt":1646221434216,"mc":[{"id":"1.195453759","rc":[{"atl":[[70,31.46]],"id":3805746}],"con":true,"img":false}]}
{"op":"mcm","clk":"5348870953","pt":1646221434321,"mc":[{"id":"1.195453759","rc":[{"atl":[[9.6,9.9]],"id":3805746},{"atb":[[18,9.32],[15.5,39.36]],"id":3805755},{"atb":[[27,2.72],[29,31.77]],"id":522753},{"atb":[[21,0],[25,21.59],[28,5.86]],"id":522743}],"con":true,"img":false}]}
