{"op":"mcm","clk":"5346195478","pt":1646178340818,"mc":[{"id":"1.195453755","marketDefinition":{"bspMarket":false,"turnInPlayEnabled":false,"persistenceEnabled":false,"marketBaseRate":7.0,"eventId":"31272494","eventTypeId":"4339","numberOfWinners":1,"bettingType":"ODDS","marketType":"QUINELLA","marketTime":"2022-03-02T10:27:00.000Z","suspendTime":"2022-03-02T10:27:00.000Z","bspReconciled":false,"complete":true,"inPlay":false,"crossMatching":false,"runnersVoidable":false,"numberOfActiveRunners":21,"betDelay":0,"status":"OPEN","runners":[{"status":"ACTIVE","sortPriority":1,"id":522741,"name":"1 - 2 / 2 - 1"},{"status":"ACTIVE","sortPriority":2,"id":522742,"name":"1 - 3 / 3 - 1"},{"status":"ACTIVE","sortPriority":3,"id":522743,"name":"1 - 4 / 4 - 1"},{"status":"ACTIVE","sortPriority":4,"id":522745,"name":"1 - 6 / 6 - 1"},{"status":"ACTIVE","sortPriority":5,"id":3805730,"name":"1 - 7 / 7 - 1"},{"status":"ACTIVE","sortPriority":6,"id":3805731,"name":"1 - 8 / 8 - 1"},{"status":"ACTIVE","sortPriority":7,"id":522746,"name":"2 - 3 / 3 - 2"},{"status":"ACTIVE","sortPriority":8,"id":522747,"name":"2 - 4 / 4 - 2"},{"status":"ACTIVE","sortPriority":9,"id":522749,"name":"2 - 6 / 6 - 2"},{"status":"ACTIVE","sortPriority":10,"id":3805736,"name":"2 - 7 / 7 - 2"},{"status":"ACTIVE","sortPriority":11,"id":3805740,"name":"2 - 8 / 8 - 2"},{"status":"ACTIVE","sortPriority":12,"id":522750,"name":"3 - 4 / 4 - 3"},{"status":"ACTIVE","sortPriority":13,"id":522752,"name":"3 - 6 / 6 - 3"},{"status":"ACTIVE","sortPriority":14,"id":3805746,"name":"3 - 7 / 7 - 3"},{"status":"ACTIVE","sortPriority":15,"id":3805747,"name":"3 - 8 / 8 - 3"},{"status":"ACTIVE","sortPriority":16,"id":522753,"name":"4 - 6 / 6 - 4"},{"status":"ACTIVE","sortPriority":17,"id":3805755,"name":"4 - 7 / 7 - 4"},{"status":"ACTIVE","sortPriority":18,"id":3805762,"name":"4 - 8 / 8 - 4"},{"status":"ACTIVE","sortPriority":19,"id":3805783,"name":"6 - 7 / 7 - 6"},{"status":"ACTIVE","sortPriority":20,"id":3805784,"name":"6 - 8 / 8 - 6"},{"status":"ACTIVE","sortPriority":21,"id":3805793,"name":"7 - 8 / 8 - 7"}],"regulators":["MR_INT"],"venue":"Traralgon","countryCode":"AU","discountAllowed":true,"timezone":"Australia/Sydney","openDate":"2022-03-02T08:31:00.000Z","version":4382480633,"name":"Quinella","eventName":"Traralgon (AUS) 2nd Mar"},"rc":[],"con":true,"img":false}]}
{"op":"mcm","clk":"5346200445","pt":1646178438495,"mc":[{"id":"1.195453755","rc":[{"atb":[[18,11.73],[10.5,21],[8.2,36.95]],"id":3805784},{"atb":[[16,13.3],[7.4,41.57],[9.4,23.75]],"id":3805783},{"atb":[[5.7,42.46],[8.4,26.96],[4.7,71.91]],"id":3805747},{"atb":[[4.3,80.63],[5.3,46.41],[7.6,30.23]],"id":3805746},{"atb":[[2.4,142.54],[2.2,221.73],[2.7,117.39]],"id":3805793},{"atb":[[16,13.3],[7.4,41.57],[9.4,23.75]],"id":3805755},{"atb":[[10.5,28],[26,7.98],[15.5,13.76]],"id":522746},{"atb":[[4.3,80.63],[5.3,46.41],[7.6,30.23]],"id":3805736},{"atb":[[16,17.74],[44,4.64],[22,9.5]],"id":522747},{"atb":[[16,17.74],[44,4.64],[22,9.5]],"id":522749},{"atb":[[16,17.74],[44,4.64],[22,9.5]],"id":522750},{"atb":[[6.2,51.17],[8.2,27.71],[13,16.63]],"id":3805731},{"atb":[[16,17.74],[44,4.64],[22,9.5]],"id":522752},{"atb":[[18,11.73],[10.5,21],[8.2,36.95]],"id":3805762},{"atb":[[10,22.17],[5.5,59.12],[7,33.26]],"id":3805730},{"atb":[[130,1.54],[46,4.43],[28,9.85]],"id":522753},{"atb":[[32,6.43],[18,11.73],[13,22.17]],"id":522741},{"atb":[[32,6.43],[18,11.73],[13,22.17]],"id":522742},{"atb":[[70,2.89],[19.5,14.38],[29,7.12]],"id":522743},{"atb":[[5.7,42.46],[8.4,26.96],[4.7,71.91]],"id":3805740},{"atb":[[70,2.89],[19.5,14.38],[29,7.12]],"id":522745}],"con":true,"img":false}]}
{"op":"mcm","clk":"5346401297","pt":1646182002775,"mc":[{"id":"1.195453755","marketDefinition":{"bspMarket":false,"turnInPlayEnabled":false,"persistenceEnabled":false,"marketBaseRate":7.0,"eventId":"31272494","eventTypeId":"4339","numberOfWinners":1,"bettingType":"ODDS","marketType":"QUINELLA","marketTime":"2022-03-02T10:27:00.000Z","suspendTime":"2022-03-02T10:27:00.000Z","bspReconciled":false,"complete":true,"inPlay":false,"crossMatching":false,"runnersVoidable":false,"numberOfActiveRunners":21,"betDelay":0,"status":"OPEN","runners":[{"status":"ACTIVE","sortPriority":1,"id":522741,"name":"1 - 2 / 2 - 1"},{"status":"ACTIVE","sortPriority":2,"id":522742,"name":"1 - 3 / 3 - 1"},{"status":"ACTIVE","sortPriority":3,"id":522743,"name":"1 - 4 / 4 - 1"},{"status":"ACTIVE","sortPriority":4,"id":522745,"name":"1 - 6 / 6 - 1"},{"status":"ACTIVE","sortPriority":5,"id":3805730,"name":"1 - 7 / 7 - 1"},{"status":"ACTIVE","sortPriority":6,"id":3805731,"name":"1 - 8 / 8 - 1"},{"status":"ACTIVE","sortPriority":7,"id":522746,"name":"2 - 3 / 3 - 2"},{"status":"ACTIVE","sortPriority":8,"id":522747,"name":"2 - 4 / 4 - 2"},{"status":"ACTIVE","sortPriority":9,"id":522749,"name":"2 - 6 / 6 - 2"},{"status":"ACTIVE","sortPriority":10,"id":3805736,"name":"2 - 7 / 7 - 2"},{"status":"ACTIVE","sortPriority":11,"id":3805740,"name":"2 - 8 / 8 - 2"},{"status":"ACTIVE","sortPriority":12,"id":522750,"name":"3 - 4 / 4 - 3"},{"status":"ACTIVE","sortPriority":13,"id":522752,"name":"3 - 6 / 6 - 3"},{"status":"ACTIVE","sortPriority":14,"id":3805746,"name":"3 - 7 / 7 - 3"},{"status":"ACTIVE","sortPriority":15,"id":3805747,"name":"3 - 8 / 8 - 3"},{"status":"ACTIVE","sortPriority":16,"id":522753,"name":"4 - 6 / 6 - 4"},{"status":"ACTIVE","sortPriority":17,"id":3805755,"name":"4 - 7 / 7 - 4"},{"status":"ACTIVE","sortPriority":18,"id":3805762,"name":"4 - 8 / 8 - 4"},{"status":"ACTIVE","sortPriority":19,"id":3805783,"name":"6 - 7 / 7 - 6"},{"status":"ACTIVE","sortPriority":20,"id":3805784,"name":"6 - 8 / 8 - 6"},{"status":"ACTIVE","sortPriority":21,"id":3805793,"name":"7 - 8 / 8 - 7"}],"regulators":["MR_INT"],"venue":"Traralgon","countryCode":"AU","discountAllowed":true,"timezone":"Australia/Sydney","openDate":"2022-03-02T08:31:00.000Z","version":4382480633,"name":"Quinella","eventName":"Traralgon (AUS) 2nd Mar"},"rc":[{"atb":[[18,11.73],[10.5,21],[8.2,36.96]],"id":3805784},{"atb":[[16,13.3],[7.4,41.58],[9.4,23.75]],"id":3805783},{"atb":[[5.7,42.46],[8.4,26.97],[4.7,71.92]],"id":3805747},{"atb":[[4.3,80.64],[5.3,46.41],[7.6,30.24]],"id":3805746},{"atb":[[2.4,142.56],[2.2,221.76],[2.7,117.4]],"id":3805793},{"atb":[[16,13.3],[7.4,41.58],[9.4,23.75]],"id":3805755},{"atb":[[10.5,28.01],[26,7.98],[15.5,13.76]],"id":522746},{"atb":[[4.3,80.64],[5.3,46.41],[7.6,30.24]],"id":3805736},{"atb":[[16,17.74],[44,4.64],[22,9.5]],"id":522747},{"atb":[[16,17.74],[44,4.64],[22,9.5]],"id":522749},{"atb":[[16,17.74],[44,4.64],[22,9.5]],"id":522750},{"atb":[[6.2,51.17],[8.2,27.72],[13,16.63]],"id":3805731},{"atb":[[16,17.74],[44,4.64],[22,9.5]],"id":522752},{"atb":[[18,11.73],[10.5,21],[8.2,36.96]],"id":3805762},{"atb":[[10,22.17],[5.5,59.13],[7,33.26]],"id":3805730},{"atb":[[130,1.54],[46,4.43],[28,9.85]],"id":522753},{"atb":[[32,6.44],[18,11.73],[13,22.17]],"id":522741},{"atb":[[32,6.44],[18,11.73],[13,22.17]],"id":522742},{"atb":[[70,2.89],[19.5,14.38],[29,7.12]],"id":522743},{"atb":[[5.7,42.46],[8.4,26.97],[4.7,71.92]],"id":3805740},{"atb":[[70,2.89],[19.5,14.38],[29,7.12]],"id":522745}],"con":true,"img":true}]}
{"op":"mcm","clk":"5346767658","pt":1646187402719,"mc":[{"id":"1.195453755","marketDefinition":{"bspMarket":false,"turnInPlayEnabled":false,"persistenceEnabled":false,"marketBaseRate":7.0,"eventId":"31272494","eventTypeId":"4339","numberOfWinners":1,"bettingType":"ODDS","marketType":"QUINELLA","marketTime":"2022-03-02T10:27:00.000Z","suspendTime":"2022-03-02T10:27:00.000Z","bspReconciled":false,"complete":true,"inPlay":false,"crossMatching":false,"runnersVoidable":false,"numberOfActiveRunners":21,"betDelay":0,"status":"OPEN","runners":[{"status":"ACTIVE","sortPriority":1,"id":522741,"name":"1 - 2 / 2 - 1"},{"status":"ACTIVE","sortPriority":2,"id":522742,"name":"1 - 3 / 3 - 1"},{"status":"ACTIVE","sortPriority":3,"id":522743,"name":"1 - 4 / 4 - 1"},{"status":"ACTIVE","sortPriority":4,"id":522745,"name":"1 - 6 / 6 - 1"},{"status":"ACTIVE","sortPriority":5,"id":3805730,"name":"1 - 7 / 7 - 1"},{"status":"ACTIVE","sortPriority":6,"id":3805731,"name":"1 - 8 / 8 - 1"},{"status":"ACTIVE","sortPriority":7,"id":522746,"name":"2 - 3 / 3 - 2"},{"status":"ACTIVE","sortPriority":8,"id":522747,"name":"2 - 4 / 4 - 2"},{"status":"ACTIVE","sortPriority":9,"id":522749,"name":"2 - 6 / 6 - 2"},{"status":"ACTIVE","sortPriority":10,"id":3805736,"name":"2 - 7 / 7 - 2"},{"status":"ACTIVE","sortPriority":11,"id":3805740,"name":"2 - 8 / 8 - 2"},{"status":"ACTIVE","sortPriority":12,"id":522750,"name":"3 - 4 / 4 - 3"},{"status":"ACTIVE","sortPriority":13,"id":522752,"name":"3 - 6 / 6 - 3"},{"status":"ACTIVE","sortPriority":14,"id":3805746,"name":"3 - 7 / 7 - 3"},{"status":"ACTIVE","sortPriority":15,"id":3805747,"name":"3 - 8 / 8 - 3"},{"status":"ACTIVE","sortPriority":16,"id":522753,"name":"4 - 6 / 6 - 4"},{"status":"ACTIVE","sortPriority":17,"id":3805755,"name":"4 - 7 / 7 - 4"},{"status":"ACTIVE","sortPriority":18,"id":3805762,"name":"4 - 8 / 8 - 4"},{"status":"ACTIVE","sortPriority":19,"id":3805783,"name":"6 - 7 / 7 - 6"},{"status":"ACTIVE","sortPriority":20,"id":3805784,"name":"6 - 8 / 8 - 6"},{"status":"ACTIVE","sortPriority":21,"id":3805793,"name":"7 - 8 / 8 - 7"}],"regulators":["MR_INT"],"venue":"Traralgon","countryCode":"AU","discountAllowed":true,"timezone":"Australia/Sydney","openDate":"2022-03-02T08:31:00.000Z","version":4382480633,"name":"Quinella","eventName":"Traralgon (AUS) 2nd Mar"},"rc":[{"atb":[[18,11.75],[10.5,21.04],[8.2,37.01]],"id":3805784},{"atb":[[16,13.32],[7.4,41.64],[9.4,23.79]],"id":3805783},{"atb":[[5.7,42.53],[8.4,27.01],[4.7,72.03]],"id":3805747},{"atb":[[4.3,80.76],[5.3,46.49],[7.6,30.29]],"id":3805746},{"atb":[[2.4,142.78],[2.2,222.11],[2.7,117.59]],"id":3805793},{"atb":[[16,13.32],[7.4,41.64],[9.4,23.79]],"id":3805755},{"atb":[[10.5,28.05],[26,7.99],[15.5,13.78]],"id":522746},{"atb":[[4.3,80.76],[5.3,46.49],[7.6,30.29]],"id":3805736},{"atb":[[16,17.77],[44,4.65],[22,9.52]],"id":522747},{"atb":[[16,17.77],[44,4.65],[22,9.52]],"id":522749},{"atb":[[16,17.77],[44,4.65],[22,9.52]],"id":522750},{"atb":[[6.2,51.25],[8.2,27.76],[13,16.65]],"id":3805731},{"atb":[[16,17.77],[44,4.65],[22,9.52]],"id":522752},{"atb":[[18,11.75],[10.5,21.04],[8.2,37.01]],"id":3805762},{"atb":[[10,22.2],[5.5,59.22],[7,33.31]],"id":3805730},{"atb":[[130,1.54],[46,4.44],[28,9.86]],"id":522753},{"atb":[[32,6.45],[18,11.75],[13,22.2]],"id":522741},{"atb":[[32,6.45],[18,11.75],[13,22.2]],"id":522742},{"atb":[[70,2.89],[19.5,14.4],[29,7.13]],"id":522743},{"atb":[[5.7,42.53],[8.4,27.01],[4.7,72.03]],"id":3805740},{"atb":[[70,2.89],[19.5,14.4],[29,7.13]],"id":522745}],"con":true,"img":true}]}
{"op":"mcm","clk":"5347092222","pt":1646192802701,"mc":[{"id":"1.195453755","marketDefinition":{"bspMarket":false,"turnInPlayEnabled":false,"persistenceEnabled":false,"marketBaseRate":7.0,"eventId":"31272494","eventTypeId":"4339","numberOfWinners":1,"bettingType":"ODDS","marketType":"QUINELLA","marketTime":"2022-03-02T10:27:00.000Z","suspendTime":"2022-03-02T10:27:00.000Z","bspReconciled":false,"complete":true,"inPlay":false,"crossMatching":false,"runnersVoidable":false,"numberOfActiveRunners":21,"betDelay":0,"status":"OPEN","runners":[{"status":"ACTIVE","sortPriority":1,"id":522741,"name":"1 - 2 / 2 - 1"},{"status":"ACTIVE","sortPriority":2,"id":522742,"name":"1 - 3 / 3 - 1"},{"status":"ACTIVE","sortPriority":3,"id":522743,"name":"1 - 4 / 4 - 1"},{"status":"ACTIVE","sortPriority":4,"id":522745,"name":"1 - 6 / 6 - 1"},{"status":"ACTIVE","sortPriority":5,"id":3805730,"name":"1 - 7 / 7 - 1"},{"status":"ACTIVE","sortPriority":6,"id":3805731,"name":"1 - 8 / 8 - 1"},{"status":"ACTIVE","sortPriority":7,"id":522746,"name":"2 - 3 / 3 - 2"},{"status":"ACTIVE","sortPriority":8,"id":522747,"name":"2 - 4 / 4 - 2"},{"status":"ACTIVE","sortPriority":9,"id":522749,"name":"2 - 6 / 6 - 2"},{"status":"ACTIVE","sortPriority":10,"id":3805736,"name":"2 - 7 / 7 - 2"},{"status":"ACTIVE","sortPriority":11,"id":3805740,"name":"2 - 8 / 8 - 2"},{"status":"ACTIVE","sortPriority":12,"id":522750,"name":"3 - 4 / 4 - 3"},{"status":"ACTIVE","sortPriority":13,"id":522752,"name":"3 - 6 / 6 - 3"},{"status":"ACTIVE","sortPriority":14,"id":3805746,"name":"3 - 7 / 7 - 3"},{"status":"ACTIVE","sortPriority":15,"id":3805747,"name":"3 - 8 / 8 - 3"},{"status":"ACTIVE","sortPriority":16,"id":522753,"name":"4 - 6 / 6 - 4"},{"status":"ACTIVE","sortPriority":17,"id":3805755,"name":"4 - 7 / 7 - 4"},{"status":"ACTIVE","sortPriority":18,"id":3805762,"name":"4 - 8 / 8 - 4"},{"status":"ACTIVE","sortPriority":19,"id":3805783,"name":"6 - 7 / 7 - 6"},{"status":"ACTIVE","sortPriority":20,"id":3805784,"name":"6 - 8 / 8 - 6"},{"status":"ACTIVE","sortPriority":21,"id":3805793,"name":"7 - 8 / 8 - 7"}],"regulators":["MR_INT"],"venue":"Traralgon","countryCode":"AU","discountAllowed":true,"timezone":"Australia/Sydney","openDate":"2022-03-02T08:31:00.000Z","version":4382480633,"name":"Quinella","eventName":"Traralgon (AUS) 2nd Mar"},"rc":[{"atb":[[18,11.77],[10.5,21.07],[8.2,37.08]],"id":3805784},{"atb":[[16,13.34],[7.4,41.71],[9.4,23.83]],"id":3805783},{"atb":[[5.7,42.6],[8.4,27.05],[4.7,72.15]],"id":3805747},{"atb":[[4.3,80.9],[5.3,46.56],[7.6,30.34]],"id":3805746},{"atb":[[2.4,143.03],[2.2,222.48],[2.7,117.79]],"id":3805793},{"atb":[[16,13.34],[7.4,41.71],[9.4,23.83]],"id":3805755},{"atb":[[10.5,28.1],[26,8],[15.5,13.8]],"id":522746},{"atb":[[4.3,80.9],[5.3,46.56],[7.6,30.34]],"id":3805736},{"atb":[[16,17.8],[44,4.65],[22,9.53]],"id":522747},{"atb":[[16,17.8],[44,4.65],[22,9.53]],"id":522749},{"atb":[[16,17.8],[44,4.65],[22,9.53]],"id":522750},{"atb":[[6.2,51.34],[8.2,27.81],[13,16.68]],"id":3805731},{"atb":[[16,17.8],[44,4.65],[22,9.53]],"id":522752},{"atb":[[18,11.77],[10.5,21.07],[8.2,37.08]],"id":3805762},{"atb":[[10,22.24],[5.5,59.32],[7,33.37]],"id":3805730},{"atb":[[130,1.55],[46,4.45],[28,9.88]],"id":522753},{"atb":[[32,6.46],[18,11.77],[13,22.24]],"id":522741},{"atb":[[32,6.46],[18,11.77],[13,22.24]],"id":522742},{"atb":[[70,2.9],[19.5,14.43],[29,7.14]],"id":522743},{"atb":[[5.7,42.6],[8.4,27.05],[4.7,72.15]],"id":3805740},{"atb":[[70,2.9],[19.5,14.43],[29,7.14]],"id":522745}],"con":true,"img":true}]}
{"op":"mcm","clk":"5347381095","pt":1646198202719,"mc":[{"id":"1.195453755","marketDefinition":{"bspMarket":false,"turnInPlayEnabled":false,"persistenceEnabled":false,"marketBaseRate":7.0,"eventId":"31272494","eventTypeId":"4339","numberOfWinners":1,"bettingType":"ODDS","marketType":"QUINELLA","marketTime":"2022-03-02T10:27:00.000Z","suspendTime":"2022-03-02T10:27:00.000Z","bspReconciled":false,"complete":true,"inPlay":false,"crossMatching":false,"runnersVoidable":false,"numberOfActiveRunners":21,"betDelay":0,"status":"OPEN","runners":[{"status":"ACTIVE","sortPriority":1,"id":522741,"name":"1 - 2 / 2 - 1"},{"status":"ACTIVE","sortPriority":2,"id":522742,"name":"1 - 3 / 3 - 1"},{"status":"ACTIVE","sortPriority":3,"id":522743,"name":"1 - 4 / 4 - 1"},{"status":"ACTIVE","sortPriority":4,"id":522745,"name":"1 - 6 / 6 - 1"},{"status":"ACTIVE","sortPriority":5,"id":3805730,"name":"1 - 7 / 7 - 1"},{"status":"ACTIVE","sortPriority":6,"id":3805731,"name":"1 - 8 / 8 - 1"},{"status":"ACTIVE","sortPriority":7,"id":522746,"name":"2 - 3 / 3 - 2"},{"status":"ACTIVE","sortPriority":8,"id":522747,"name":"2 - 4 / 4 - 2"},{"status":"ACTIVE","sortPriority":9,"id":522749,"name":"2 - 6 / 6 - 2"},{"status":"ACTIVE","sortPriority":10,"id":3805736,"name":"2 - 7 / 7 - 2"},{"status":"ACTIVE","sortPriority":11,"id":3805740,"name":"2 - 8 / 8 - 2"},{"status":"ACTIVE","sortPriority":12,"id":522750,"name":"3 - 4 / 4 - 3"},{"status":"ACTIVE","sortPriority":13,"id":522752,"name":"3 - 6 / 6 - 3"},{"status":"ACTIVE","sortPriority":14,"id":3805746,"name":"3 - 7 / 7 - 3"},{"status":"ACTIVE","sortPriority":15,"id":3805747,"name":"3 - 8 / 8 - 3"},{"status":"ACTIVE","sortPriority":16,"id":522753,"name":"4 - 6 / 6 - 4"},{"status":"ACTIVE","sortPriority":17,"id":3805755,"name":"4 - 7 / 7 - 4"},{"status":"ACTIVE","sortPriority":18,"id":3805762,"name":"4 - 8 / 8 - 4"},{"status":"ACTIVE","sortPriority":19,"id":3805783,"name":"6 - 7 / 7 - 6"},{"status":"ACTIVE","sortPriority":20,"id":3805784,"name":"6 - 8 / 8 - 6"},{"status":"ACTIVE","sortPriority":21,"id":3805793,"name":"7 - 8 / 8 - 7"}],"regulators":["MR_INT"],"venue":"Traralgon","countryCode":"AU","discountAllowed":true,"timezone":"Australia/Sydney","openDate":"2022-03-02T08:31:00.000Z","version":4382480633,"name":"Quinella","eventName":"Traralgon (AUS) 2nd Mar"},"rc":[{"atb":[[18,11.77],[10.5,21.07],[8.2,37.06]],"id":3805784},{"atb":[[16,13.34],[7.4,41.7],[9.4,23.82]],"id":3805783},{"atb":[[5.7,42.58],[8.4,27.04],[4.7,72.13]],"id":3805747},{"atb":[[4.3,80.87],[5.3,46.55],[7.6,30.33]],"id":3805746},{"atb":[[2.4,142.97],[2.2,222.4],[2.7,117.74]],"id":3805793},{"atb":[[16,13.34],[7.4,41.7],[9.4,23.82]],"id":3805755},{"atb":[[10.5,28.09],[26,8],[15.5,13.8]],"id":522746},{"atb":[[4.3,80.87],[5.3,46.55],[7.6,30.33]],"id":3805736},{"atb":[[16,17.79],[44,4.65],[22,9.53]],"id":522747},{"atb":[[16,17.79],[44,4.65],[22,9.53]],"id":522749},{"atb":[[16,17.79],[44,4.65],[22,9.53]],"id":522750},{"atb":[[6.2,51.32],[8.2,27.8],[13,16.68]],"id":3805731},{"atb":[[16,17.79],[44,4.65],[22,9.53]],"id":522752},{"atb":[[18,11.77],[10.5,21.07],[8.2,37.06]],"id":3805762},{"atb":[[10,22.23],[5.5,59.3],[7,33.36]],"id":3805730},{"atb":[[130,1.55],[46,4.44],[28,9.88]],"id":522753},{"atb":[[32,6.45],[18,11.77],[13,22.23]],"id":522741},{"atb":[[32,6.45],[18,11.77],[13,22.23]],"id":522742},{"atb":[[70,2.89],[19.5,14.42],[29,7.14]],"id":522743},{"atb":[[5.7,42.58],[8.4,27.04],[4.7,72.13]],"id":3805740},{"atb":[[70,2.89],[19.5,14.42],[29,7.14]],"id":522745}],"con":true,"img":true}]}
{"op":"mcm","clk":"5347848780","pt":1646209002723,"mc":[{"id":"1.195453755","marketDefinition":{"bspMarket":false,"turnInPlayEnabled":false,"persistenceEnabled":false,"marketBaseRate":7.0,"eventId":"31272494","eventTypeId":"4339","numberOfWinners":1,"bettingType":"ODDS","marketType":"QUINELLA","marketTime":"2022-03-02T10:27:00.000Z","suspendTime":"2022-03-02T10:27:00.000Z","bspReconciled":false,"complete":true,"inPlay":false,"crossMatching":false,"runnersVoidable":false,"numberOfActiveRunners":21,"betDelay":0,"status":"OPEN","runners":[{"status":"ACTIVE","sortPriority":1,"id":522741,"name":"1 - 2 / 2 - 1"},{"status":"ACTIVE","sortPriority":2,"id":522742,"name":"1 - 3 / 3 - 1"},{"status":"ACTIVE","sortPriority":3,"id":522743,"name":"1 - 4 / 4 - 1"},{"status":"ACTIVE","sortPriority":4,"id":522745,"name":"1 - 6 / 6 - 1"},{"status":"ACTIVE","sortPriority":5,"id":3805730,"name":"1 - 7 / 7 - 1"},{"status":"ACTIVE","sortPriority":6,"id":3805731,"name":"1 - 8 / 8 - 1"},{"status":"ACTIVE","sortPriority":7,"id":522746,"name":"2 - 3 / 3 - 2"},{"status":"ACTIVE","sortPriority":8,"id":522747,"name":"2 - 4 / 4 - 2"},{"status":"ACTIVE","sortPriority":9,"id":522749,"name":"2 - 6 / 6 - 2"},{"status":"ACTIVE","sortPriority":10,"id":3805736,"name":"2 - 7 / 7 - 2"},{"status":"ACTIVE","sortPriority":11,"id":3805740,"name":"2 - 8 / 8 - 2"},{"status":"ACTIVE","sortPriority":12,"id":522750,"name":"3 - 4 / 4 - 3"},{"status":"ACTIVE","sortPriority":13,"id":522752,"name":"3 - 6 / 6 - 3"},{"status":"ACTIVE","sortPriority":14,"id":3805746,"name":"3 - 7 / 7 - 3"},{"status":"ACTIVE","sortPriority":15,"id":3805747,"name":"3 - 8 / 8 - 3"},{"status":"ACTIVE","sortPriority":16,"id":522753,"name":"4 - 6 / 6 - 4"},{"status":"ACTIVE","sortPriority":17,"id":3805755,"name":"4 - 7 / 7 - 4"},{"status":"ACTIVE","sortPriority":18,"id":3805762,"name":"4 - 8 / 8 - 4"},{"status":"ACTIVE","sortPriority":19,"id":3805783,"name":"6 - 7 / 7 - 6"},{"status":"ACTIVE","sortPriority":20,"id":3805784,"name":"6 - 8 / 8 - 6"},{"status":"ACTIVE","sortPriority":21,"id":3805793,"name":"7 - 8 / 8 - 7"}],"regulators":["MR_INT"],"venue":"Traralgon","countryCode":"AU","discountAllowed":true,"timezone":"Australia/Sydney","openDate":"2022-03-02T08:31:00.000Z","version":4382480633,"name":"Quinella","eventName":"Traralgon (AUS) 2nd Mar"},"rc":[{"atb":[[18,11.76],[10.5,21.06],[8.2,37.05]],"id":3805784},{"atb":[[16,13.34],[7.4,41.69],[9.4,23.82]],"id":3805783},{"atb":[[5.7,42.57],[8.4,27.04],[4.7,72.11]],"id":3805747},{"atb":[[4.3,80.85],[5.3,46.53],[7.6,30.32]],"id":3805746},{"atb":[[2.4,142.93],[2.2,222.34],[2.7,117.71]],"id":3805793},{"atb":[[16,13.34],[7.4,41.69],[9.4,23.82]],"id":3805755},{"atb":[[10.5,28.08],[26,8],[15.5,13.79]],"id":522746},{"atb":[[4.3,80.85],[5.3,46.53],[7.6,30.32]],"id":3805736},{"atb":[[16,17.78],[44,4.65],[22,9.53]],"id":522747},{"atb":[[16,17.78],[44,4.65],[22,9.53]],"id":522749},{"atb":[[16,17.78],[44,4.65],[22,9.53]],"id":522750},{"atb":[[6.2,51.31],[8.2,27.79],[13,16.67]],"id":3805731},{"atb":[[16,17.78],[44,4.65],[22,9.53]],"id":522752},{"atb":[[18,11.76],[10.5,21.06],[8.2,37.05]],"id":3805762},{"atb":[[10,22.23],[5.5,59.29],[7,33.35]],"id":3805730},{"atb":[[130,1.55],[46,4.44],[28,9.87]],"id":522753},{"atb":[[32,6.45],[18,11.76],[13,22.23]],"id":522741},{"atb":[[32,6.45],[18,11.76],[13,22.23]],"id":522742},{"atb":[[70,2.89],[19.5,14.42],[29,7.14]],"id":522743},{"atb":[[5.7,42.57],[8.4,27.04],[4.7,72.11]],"id":3805740},{"atb":[[70,2.89],[19.5,14.42],[29,7.14]],"id":522745}],"con":true,"img":true}]}
{"op":"mcm","clk":"5347883108","pt":1646209620446,"mc":[{"id":"1.195453755","rc":[{"atb":[[16,2.72],[18,11.76],[10.5,21.06],[8.2,37.05],[13.5,3.27]],"id":3805784},{"atb":[[16,13.34],[7.4,41.69],[12,3.27],[14.5,2.72],[9.4,23.82]],"id":3805783},{"atb":[[9.6,2.72],[8.6,3.27],[5.7,42.57],[8.4,27.04],[4.7,72.11]],"id":3805747},{"atb":[[4.3,80.85],[8.6,2.72],[5.3,46.53],[7.6,33.59]],"id":3805746},{"atb":[[2.4,142.93],[1.97,3.27],[2.04,2.72],[2.2,222.34],[2.7,117.71]],"id":3805793},{"atb":[[16,13.34],[7.4,41.69],[12,3.27],[14.5,2.72],[9.4,23.82]],"id":3805755},{"atb":[[18.5,3.27],[10.5,28.08],[22,2.72],[26,8],[15.5,13.79]],"id":522746},{"atb":[[7.2,3.27],[4.3,80.85],[5.3,46.53],[8.2,2.72],[7.6,30.32]],"id":3805736},{"atb":[[16,17.78],[36,2.72],[44,4.65],[22,9.53],[28,3.27]],"id":522747},{"atb":[[16,17.78],[38,2.72],[44,4.65],[22,9.53],[29,3.27]],"id":522749},{"atb":[[16,17.78],[38,2.72],[44,4.65],[22,9.53],[29,3.27]],"id":522750},{"atb":[[6.2,51.31],[8.2,27.79],[12,2.72],[9.8,3.27],[13,16.67]],"id":3805731},{"atb":[[16,17.78],[38,2.72],[44,4.65],[22,9.53],[29,3.27]],"id":522752},{"atb":[[18,11.76],[10.5,21.06],[8.2,37.05],[13,3.27],[15.5,2.72]],"id":3805762},{"atb":[[10,22.23],[5.5,59.29],[11,2.72],[7,33.35],[9.4,3.27]],"id":3805730},{"atb":[[130,1.55],[65,2.72],[46,7.72],[28,9.87]],"id":522753},{"atb":[[32,6.45],[18,11.76],[22,3.27],[13,22.23],[27,2.72]],"id":522741},{"atb":[[32,6.45],[18,11.76],[23,3.27],[13,22.23],[28,2.72]],"id":522742},{"atb":[[70,2.89],[36,3.27],[19.5,14.42],[46,2.72],[29,7.14]],"id":522743},{"atb":[[9.2,2.72],[8.2,3.27],[5.7,42.57],[8.4,27.04],[4.7,72.11]],"id":3805740},{"atb":[[70,2.89],[19.5,14.42],[38,3.27],[48,2.72],[29,7.14]],"id":522745}],"con":true,"img":false}]}
{"op":"mcm","clk":"5347905597","pt":1646210117125,"mc":[{"id":"1.195453755","rc":[{"atb":[[9.6,0],[8.6,0]],"id":3805747},{"atb":[[8.6,0],[7.6,30.32]],"id":3805746}],"con":true,"img":false}]}
{"op":"mcm","clk":"5347905632","pt":1646210118006,"mc":[{"id":"1.195453755","rc":[{"atb":[[8.4,30.31],[9.4,2.72]],"id":3805747},{"atb":[[7.4,3.27],[8.4,2.72]],"id":3805746}],"con":true,"img":false}]}
{"op":"mcm","clk":"5347915210","pt":1646210346276,"mc":[{"id":"1.195453755","rc":[{"atb":[[1.97,0],[2.04,0]],"id":3805793}],"con":true,"img":false}]}
{"op":"mcm","clk":"5347915241","pt":1646210346997,"mc":[{"id":"1.195453755","rc":[{"atb":[[2,3.27]],"id":3805793}],"con":true,"img":false}]}
{"op":"mcm","clk":"5347915247","pt":1646210347157,"mc":[{"id":"1.195453755","rc":[{"atb":[[2.1,2.72]],"id":3805793}],"con":true,"img":false}]}
{"op":"mcm","clk":"5347966368","pt":1646211459430,"mc":[{"id":"1.195453755","rc":[{"atb":[[2,0],[2.1,0]],"id":3805793}],"con":true,"img":false}]}
{"op":"mcm","clk":"5347966414","pt":1646211460253,"mc":[{"id":"1.195453755","rc":[{"atb":[[1.97,3.27],[2.04,2.72]],"id":3805793}],"con":true,"img":false}]}
{"op":"mcm","clk":"5347971040","pt":1646211575820,"mc":[{"id":"1.195453755","rc":[{"atb":[[1.97,0],[2.04,0]],"id":3805793}],"con":true,"img":false}]}
{"op":"mcm","clk":"5347971071","pt":1646211576548,"mc":[{"id":"1.195453755","rc":[{"atb":[[2,2.72],[1.95,3.27]],"id":3805793}],"con":true,"img":false}]}
{"op":"mcm","clk":"5347997229","pt":1646212106715,"mc":[{"id":"1.195453755","rc":[{"atb":[[16,2.72],[18,11.74],[10.5,21.03],[8.2,36.99],[13.5,3.26]],"id":3805784},{"atb":[[16,13.31],[7.4,41.62],[12,3.26],[14.5,2.72],[9.4,23.78]],"id":3805783},{"atb":[[5.7,42.5],[8.4,30.26],[9.4,2.72],[4.7,71.99]],"id":3805747},{"atb":[[4.3,80.72],[5.3,46.46],[7.4,3.26],[7.6,30.27],[8.4,2.72]],"id":3805746},{"atb":[[2.4,142.71],[2,0],[2.2,221.99],[1.95,0],[2.7,117.52]],"id":3805793},{"atb":[[16,13.31],[7.4,41.62],[12,3.26],[14.5,2.72],[9.4,23.78]],"id":3805755},{"atb":[[18.5,3.26],[10.5,28.03],[22,2.72],[26,7.98],[15.5,13.77]],"id":522746},{"atb":[[16,17.76],[36,2.72],[44,4.64],[22,9.51],[28,3.26]],"id":522747},{"atb":[[7.2,3.26],[4.3,80.72],[8.2,2.72],[5.3,46.46],[7.6,30.27]],"id":3805736},{"atb":[[16,17.76],[38,2.72],[44,4.64],[22,9.51],[29,3.26]],"id":522749},{"atb":[[16,17.76],[38,2.72],[44,4.64],[22,9.51],[29,3.26]],"id":522750},{"atb":[[6.2,51.22],[8.2,27.75],[12,2.72],[9.8,3.26],[13,16.64]],"id":3805731},{"atb":[[16,17.76],[38,2.72],[44,4.64],[22,9.51],[29,3.26]],"id":522752},{"atb":[[10,22.19],[11,2.72],[5.5,59.19],[7,33.29],[9.4,3.26]],"id":3805730},{"atb":[[18,11.74],[10.5,21.03],[8.2,36.99],[13,3.26],[15.5,2.72]],"id":3805762},{"atb":[[130,1.54],[65,2.72],[46,7.71],[28,9.86]],"id":522753},{"atb":[[32,6.44],[18,11.74],[22,3.26],[13,22.19],[27,2.72]],"id":522741},{"atb":[[32,6.44],[18,11.74],[23,3.26],[13,22.19],[28,2.72]],"id":522742},{"atb":[[9.2,2.72],[8.2,3.26],[5.7,42.5],[8.4,26.99],[4.7,71.99]],"id":3805740},{"atb":[[70,2.89],[36,3.26],[19.5,14.39],[46,2.72],[29,7.13]],"id":522743},{"atb":[[70,2.89],[38,3.26],[19.5,14.39],[48,2.72],[29,7.13]],"id":522745}],"con":true,"img":false}]}
{"op":"mcm","clk":"5347997270","pt":1646212107387,"mc":[{"id":"1.195453755","rc":[{"atb":[[2.06,2.72],[1.98,3.26]],"id":3805793}],"con":true,"img":false}]}
{"op":"mcm","clk":"5348030721","pt":1646212755503,"mc":[{"id":"1.195453755","rc":[{"atb":[[2.06,0],[1.98,0]],"id":3805793}],"con":true,"img":false}]}
{"op":"mcm","clk":"5348030746","pt":1646212756330,"mc":[{"id":"1.195453755","rc":[{"atb":[[2,2.72],[1.95,3.26]],"id":3805793}],"con":true,"img":false}]}
{"op":"mcm","clk":"5348053683","pt":1646213168421,"mc":[{"id":"1.195453755","rc":[{"atb":[[2,0]],"id":3805793}],"con":true,"img":false}]}
{"op":"mcm","clk":"5348053687","pt":1646213168528,"mc":[{"id":"1.195453755","rc":[{"atb":[[1.95,0]],"id":3805793}],"con":true,"img":false}]}
{"op":"mcm","clk":"5348053725","pt":1646213169248,"mc":[{"id":"1.195453755","rc":[{"atb":[[2.02,2.72],[1.96,3.26]],"id":3805793}],"con":true,"img":false}]}
{"op":"mcm","clk":"5348057200","pt":1646213233598,"mc":[{"id":"1.195453755","rc":[{"atb":[[16,0],[13,3.26],[13.5,0],[15.5,2.72]],"id":3805784}],"con":true,"img":false}]}
{"op":"mcm","clk":"5348057207","pt":1646213233806,"mc":[{"id":"1.195453755","rc":[{"atb":[[38,0],[29,0]],"id":522750},{"atb":[[12,0],[9.8,0]],"id":3805731}],"con":true,"img":false}]}
{"op":"mcm","clk":"5348057218","pt":1646213233911,"mc":[{"id":"1.195453755","rc":[{"atb":[[2.02,0],[1.96,0]],"id":3805793},{"atb":[[18.5,0],[22,0]],"id":522746},{"atb":[[23,0],[28,0]],"id":522742},{"atb":[[36,0],[46,0]],"id":522743}],"con":true,"img":false}]}
{"op":"mcm","clk":"5348057221","pt":1646213234011,"mc":[{"id":"1.195453755","rc":[{"atb":[[12,0],[14.5,0]],"id":3805783},{"atb":[[13,0],[15.5,0]],"id":3805762},{"atb":[[22,0],[27,0]],"id":522741},{"atb":[[8,3.26],[9,2.72],[9.2,0],[8.2,0]],"id":3805740}],"con":true,"img":false}]}
{"op":"mcm","clk":"5348057227","pt":1646213234115,"mc":[{"id":"1.195453755","rc":[{"atb":[[8.4,26.99],[9.4,0]],"id":3805747},{"atb":[[36,3.26],[38,0],[46,2.72],[48,0]],"id":522745}],"con":true,"img":false}]}
{"op":"mcm","clk":"5348057234","pt":1646213234216,"mc":[{"id":"1.195453755","rc":[{"atb":[[7.4,0],[8.4,0]],"id":3805746},{"atb":[[8,2.72],[7.2,0],[8.2,0],[7,3.26]],"id":3805736}],"con":true,"img":false}]}
{"op":"mcm","clk":"5348057248","pt":1646213234425,"mc":[{"id":"1.195453755","rc":[{"atb":[[11.5,3.26],[12,0],[14,2.72],[14.5,0]],"id":3805755},{"atb":[[36,2.72],[38,0],[28,3.26],[29,0]],"id":522749}],"con":true,"img":false}]}
{"op":"mcm","clk":"5348057255","pt":1646213234528,"mc":[{"id":"1.195453755","rc":[{"atb":[[12,2.72],[9.8,3.26]],"id":3805731}],"con":true,"img":false}]}
{"op":"mcm","clk":"5348057263","pt":1646213234630,"mc":[{"id":"1.195453755","rc":[{"atb":[[18.5,3.26],[22,2.72]],"id":522746},{"atb":[[38,2.72],[29,3.26]],"id":522750},{"atb":[[23,3.26],[28,2.72]],"id":522742},{"atb":[[36,3.26],[46,2.72]],"id":522743}],"con":true,"img":false}]}
{"op":"mcm","clk":"5348057269","pt":1646213234734,"mc":[{"id":"1.195453755","rc":[{"atb":[[2.02,2.72],[1.96,3.26]],"id":3805793},{"atb":[[13,3.26],[15.5,2.72]],"id":3805762},{"atb":[[22,3.26],[27,2.72]],"id":522741}],"con":true,"img":false}]}
{"op":"mcm","clk":"5348057275","pt":1646213234836,"mc":[{"id":"1.195453755","rc":[{"atb":[[12,3.26],[14.5,2.72]],"id":3805783},{"atb":[[8.4,30.26],[9.4,2.72]],"id":3805747}],"con":true,"img":false}]}
{"op":"mcm","clk":"5348057289","pt":1646213234992,"mc":[{"id":"1.195453755","rc":[{"atb":[[7.4,3.26],[8.4,2.72]],"id":3805746}],"con":true,"img":false}]}
{"op":"mcm","clk":"5348058869","pt":1646213267040,"mc":[{"id":"1.195453755","rc":[{"atb":[[3.95,26.64]],"id":3805783},{"atl":[[500,2]],"id":3805783},{"atb":[[3.35,42.55]],"id":3805747},{"atl":[[410,2]],"id":3805747},{"atb":[[3.05,48.78]],"id":3805746},{"atl":[[410,2]],"id":3805746},{"atb":[[1.36,235.06]],"id":3805793},{"atl":[[12.5,2]],"id":3805793},{"atb":[[5,25]],"id":3805755},{"atl":[[520,2]],"id":3805755},{"atb":[[16.5,6.45]],"id":522746},{"atl":[[1000,2]],"id":522746},{"atb":[[5.6,21.74]],"id":3805736},{"atl":[[540,2]],"id":3805736},{"atb":[[28,6.96]],"id":522747},{"atb":[[28,6.96]],"id":522749},{"atb":[[25,4.17]],"id":522750},{"atl":[[1000,2]],"id":522750},{"atb":[[6.8,17.24]],"id":3805731},{"atl":[[610,2]],"id":3805731},{"atb":[[22,14.27]],"id":522752},{"atl":[[1000,2]],"id":522752},{"atb":[[6,20]],"id":3805762},{"atl":[[560,2]],"id":3805762},{"atb":[[5.9,20.41]],"id":3805730},{"atl":[[550,2]],"id":3805730},{"atb":[[28,13.56]],"id":522753},{"atb":[[28,3.7]],"id":522741},{"atb":[[26,4]],"id":522742},{"atl":[[1000,2]],"id":522742},{"atb":[[28,3.7]],"id":522743},{"atb":[[6.6,17.86]],"id":3805740},{"atl":[[590,2]],"id":3805740},{"atb":[[6.8,6.54]],"id":522745}],"con":true,"img":false}]}
{"op":"mcm","clk":"5348058874","pt":1646213267143,"mc":[{"id":"1.195453755","rc":[{"atb":[[5,23.5]],"id":3805784},{"atl":[[520,2]],"id":3805784}],"con":true,"img":false}]}
{"op":"mcm","clk":"5348063370","pt":1646213353705,"mc":[{"id":"1.195453755","rc":[{"atl":[[1000,0]],"id":522742}],"con":true,"img":false}]}
{"op":"mcm","clk":"5348063376","pt":1646213353762,"mc":[{"id":"1.195453755","rc":[{"atb":[[26,4],[28,0]],"id":522741}],"con":true,"img":false}]}
{"op":"mcm","clk":"5348063412","pt":1646213354385,"mc":[{"id":"1.195453755","rc":[{"atb":[[2.9,52.63],[3.05,0]],"id":3805746}],"con":true,"img":false}]}
{"op":"mcm","clk":"5348063591","pt":1646213358007,"mc":[{"id":"1.195453755","rc":[{"atb":[[16.5,0],[12,9.09]],"id":522746}],"con":true,"img":false}]}
{"op":"mcm","clk":"5348098634","pt":1646213955256,"mc":[{"id":"1.195453755","rc":[{"atb":[[2.9,0],[3,50]],"id":3805746},{"atl":[[1000,0]],"id":522750},{"atl":[[600,2],[610,0]],"id":3805731},{"atb":[[26,0],[28,3.7]],"id":522741},{"atl":[[1000,2]],"id":522742}],"con":true,"img":false}]}
{"op":"mcm","clk":"5348098653","pt":1646213955563,"mc":[{"id":"1.195453755","rc":[{"atb":[[2.02,0],[1.96,0]],"id":3805793}],"con":true,"img":false}]}
{"op":"mcm","clk":"5348098707","pt":1646213956284,"mc":[{"id":"1.195453755","rc":[{"atb":[[1.98,2.72],[1.93,3.26]],"id":3805793}],"con":true,"img":false}]}
{"op":"mcm","clk":"5348105706","pt":1646214075193,"mc":[{"id":"1.195453755","rc":[{"atb":[[5,0],[5.7,21.28]],"id":3805784},{"atl":[[540,2],[550,0]],"id":3805730}],"con":true,"img":false}]}
{"op":"mcm","clk":"5348105733","pt":1646214075661,"mc":[{"id":"1.195453755","rc":[{"atb":[[1.98,0],[1.93,0]],"id":3805793}],"con":true,"img":false}]}
{"op":"mcm","clk":"5348105784","pt":1646214076427,"mc":[{"id":"1.195453755","rc":[{"atb":[[1.91,3.26],[1.96,2.72]],"id":3805793}],"con":true,"img":false}]}
{"op":"mcm","clk":"5348106976","pt":1646214093235,"mc":[{"id":"1.195453755","rc":[{"atl":[[1000,2]],"id":522750},{"atl":[[600,0],[610,2]],"id":3805731}],"con":true,"img":false}]}
{"op":"mcm","clk":"5348113867","pt":1646214213316,"mc":[{"id":"1.195453755","rc":[{"atb":[[5,25],[5.7,0]],"id":3805784},{"atb":[[5.3,23.26],[5.9,0]],"id":3805730},{"atb":[[26,4],[28,0]],"id":522741},{"atl":[[1000,0]],"id":522742}],"con":true,"img":false}]}
{"op":"mcm","clk":"5348116449","pt":1646214255416,"mc":[{"id":"1.195453755","rc":[{"atb":[[26,0],[28,3.7]],"id":522741},{"atl":[[1000,2]],"id":522742}],"con":true,"img":false}]}
{"op":"mcm","clk":"5348123426","pt":1646214356496,"mc":[{"id":"1.195453755","rc":[{"atb":[[1.91,0],[1.96,0]],"id":3805793}],"con":true,"img":false}]}
{"op":"mcm","clk":"5348123461","pt":1646214357181,"mc":[{"id":"1.195453755","rc":[{"atb":[[2,2.72],[1.95,3.26]],"id":3805793}],"con":true,"img":false}]}
{"op":"mcm","clk":"5348124696","pt":1646214375420,"mc":[{"id":"1.195453755","rc":[{"atl":[[1000,0]],"id":522750},{"atb":[[26,4],[28,0]],"id":522741},{"atl":[[1000,0]],"id":522742}],"con":true,"img":false}]}
{"op":"mcm","clk":"5348137082","pt":1646214431158,"mc":[{"id":"1.195453755","rc":[{"atb":[[7.4,0],[8.4,0]],"id":3805746},{"atb":[[11.5,0],[14,0]],"id":3805755},{"atb":[[18.5,0],[22,0]],"id":522746},{"atb":[[8,0],[7,0]],"id":3805736},{"atb":[[36,0],[28,3.7]],"id":522747},{"atb":[[36,0],[28,3.7]],"id":522749},{"atb":[[38,0],[29,0]],"id":522750},{"atb":[[38,0],[29,0]],"id":522752},{"atb":[[11,0],[9.4,0]],"id":3805730},{"atb":[[22,0],[27,0]],"id":522741},{"atb":[[23,0],[28,0]],"id":522742},{"atb":[[8,0],[9,0]],"id":3805740},{"atb":[[36,0],[46,0]],"id":522743},{"atb":[[36,0],[46,0]],"id":522745}],"con":true,"img":false}]}
{"op":"mcm","clk":"5348137121","pt":1646214431837,"mc":[{"id":"1.195453755","rc":[{"atb":[[8.6,2.72],[7.6,33.54]],"id":3805746},{"atb":[[12,3.26],[14.5,2.72]],"id":3805755},{"atb":[[19.5,3.26],[24,2.72]],"id":522746},{"atb":[[7.4,3.26],[8.4,2.72]],"id":3805736},{"atb":[[38,2.72],[29,3.26]],"id":522747},{"atb":[[38,2.72],[29,3.26]],"id":522749},{"atb":[[40,2.72],[30,3.26]],"id":522750},{"atb":[[40,2.72],[30,3.26]],"id":522752},{"atb":[[9.6,3.26],[11.5,2.72]],"id":3805730},{"atb":[[24,3.26],[29,2.72]],"id":522741},{"atb":[[9.2,2.72],[8.2,3.26]],"id":3805740},{"atb":[[40,3.26],[50,2.72]],"id":522743},{"atb":[[40,3.26],[50,2.72]],"id":522745}],"con":true,"img":false}]}
{"op":"mcm","clk":"5348137126","pt":1646214431937,"mc":[{"id":"1.195453755","rc":[{"atb":[[8.4,26.99],[9.4,0]],"id":3805747},{"atb":[[25,3.26],[30,2.72]],"id":522742}],"con":true,"img":false}]}
{"op":"mcm","clk":"5348137171","pt":1646214432658,"mc":[{"id":"1.195453755","rc":[{"atb":[[9.6,2.72],[8.6,3.26]],"id":3805747}],"con":true,"img":false}]}
{"op":"mcm","clk":"5348137382","pt":1646214435531,"mc":[{"id":"1.195453755","rc":[{"atl":[[1000,2]],"id":522750},{"atb":[[26,0],[28,3.7]],"id":522741},{"atl":[[1000,2]],"id":522742}],"con":true,"img":false}]}
{"op":"mcm","clk":"5348137399","pt":1646214435849,"mc":[{"id":"1.195453755","rc":[{"atb":[[2,0],[1.95,0]],"id":3805793}],"con":true,"img":false}]}
{"op":"mcm","clk":"5348137441","pt":1646214436532,"mc":[{"id":"1.195453755","rc":[{"atb":[[1.99,2.72],[1.94,3.26]],"id":3805793}],"con":true,"img":false}]}
{"op":"mcm","clk":"5348139704","pt":1646214468652,"mc":[{"id":"1.195453755","rc":[{"atb":[[5,0],[5.5,22.22]],"id":3805784},{"atl":[[1000,0]],"id":522750},{"atb":[[5.8,20.83],[5.3,0]],"id":3805730},{"atl":[[1000,0]],"id":522742}],"con":true,"img":false}]}
{"op":"mcm","clk":"5348139737","pt":1646214469064,"mc":[{"id":"1.195453755","rc":[{"atb":[[1.99,0],[1.94,0]],"id":3805793}],"con":true,"img":false}]}
{"op":"mcm","clk":"5348139799","pt":1646214469743,"mc":[{"id":"1.195453755","rc":[{"atb":[[1.92,3.26],[1.97,2.72]],"id":3805793}],"con":true,"img":false}]}
{"op":"mcm","clk":"5348143094","pt":1646214514002,"mc":[{"id":"1.195453755","rc":[{"atl":[[1000,2]],"id":522750}],"con":true,"img":false}]}
{"op":"mcm","clk":"5348145394","pt":1646214545255,"mc":[{"id":"1.195453755","rc":[{"atl":[[1000,0]],"id":522750}],"con":true,"img":false}]}
{"op":"mcm","clk":"5348146705","pt":1646214562587,"mc":[{"id":"1.195453755","rc":[{"atb":[[1.92,0],[1.97,0]],"id":3805793}],"con":true,"img":false}]}
{"op":"mcm","clk":"5348146773","pt":1646214563412,"mc":[{"id":"1.195453755","rc":[{"atb":[[1.91,3.26],[1.96,2.72]],"id":3805793}],"con":true,"img":false}]}
{"op":"mcm","clk":"5348151183","pt":1646214626058,"mc":[{"id":"1.195453755","rc":[{"atb":[[1.91,0],[1.96,0]],"id":3805793}],"con":true,"img":false}]}
{"op":"mcm","clk":"5348151241","pt":1646214626785,"mc":[{"id":"1.195453755","rc":[{"atb":[[1.9,3.26],[1.95,2.72]],"id":3805793}],"con":true,"img":false}]}
{"op":"mcm","clk":"5348152383","pt":1646214641941,"mc":[{"id":"1.195453755","rc":[{"atl":[[470,2]],"id":3805783},{"atb":[[3,0]],"id":3805746},{"atb":[[1.36,0]],"id":3805793},{"atb":[[3.9,34.48]],"id":3805755},{"atl":[[480,2]],"id":3805755},{"atb":[[9,12.5],[12,0]],"id":522746},{"atl":[[880,2],[1000,0]],"id":522746},{"atb":[[11.5,8.82],[25,0]],"id":522750},{"atl":[[950,2]],"id":522750},{"atb":[[6.8,0]],"id":3805731},{"atl":[[610,0]],"id":3805731},{"atb":[[3.8,35.71]],"id":3805730},{"atl":[[460,2]],"id":3805730},{"atb":[[26,0]],"id":522742}],"con":true,"img":false}]}
{"op":"mcm","clk":"5348152389","pt":1646214642046,"mc":[{"id":"1.195453755","rc":[{"atb":[[5.5,0],[6.8,17.24]],"id":3805784},{"atl":[[520,0],[490,2]],"id":3805784},{"atb":[[3.95,0],[4.7,26.64]],"id":3805783},{"atl":[[500,0]],"id":3805783},{"atb":[[4,33.33],[3.35,0]],"id":3805747},{"atb":[[2.84,54.35]],"id":3805746},{"atb":[[1.62,161.29]],"id":3805793},{"atb":[[5,0]],"id":3805755},{"atl":[[520,0]],"id":3805755},{"atb":[[34,3.03],[28,0]],"id":522747},{"atl":[[1000,2]],"id":522747},{"atb":[[5.6,0],[3.8,35.71]],"id":3805736},{"atl":[[540,0],[460,2]],"id":3805736},{"atb":[[28,0],[30,3.45]],"id":522749},{"atl":[[1000,2]],"id":522749},{"atb":[[4.9,25.64]],"id":3805731},{"atl":[[540,2]],"id":3805731},{"atb":[[22,9.51],[11,9.3]],"id":522752},{"atl":[[870,2],[1000,0]],"id":522752},{"atb":[[5.8,0]],"id":3805730},{"atl":[[540,0]],"id":3805730},{"atb":[[7.2,16.13],[6,0]],"id":3805762},{"atl":[[540,2],[560,0]],"id":3805762},{"atb":[[26,4],[28,0]],"id":522741},{"atl":[[1000,2]],"id":522741},{"atb":[[10.5,10.45]],"id":522742},{"atl":[[860,2]],"id":522742},{"atb":[[5.3,23.26],[6.6,0]],"id":3805740},{"atl":[[530,2],[590,0]],"id":3805740},{"atl":[[1000,2]],"id":522745}],"con":true,"img":false}]}
{"op":"mcm","clk":"5348152395","pt":1646214642102,"mc":[{"id":"1.195453755","rc":[{"atl":[[430,2],[470,0]],"id":3805783},{"atb":[[4.8,26.32],[3.9,0]],"id":3805755},{"atl":[[440,2],[480,0]],"id":3805755},{"atb":[[9,0],[11.5,9.52]],"id":522746},{"atl":[[760,2],[880,0]],"id":522746},{"atb":[[11.5,0],[15,7.14]],"id":522750},{"atl":[[820,2],[950,0]],"id":522750}],"con":true,"img":false}]}
{"op":"mcm","clk":"5348152403","pt":1646214642206,"mc":[{"id":"1.195453755","rc":[{"atb":[[8.6,0],[7.6,30.27],[2.84,0],[3.3,43.48]],"id":3805746},{"atb":[[3.8,0],[4.7,27.03]],"id":3805736},{"atl":[[420,2],[460,0]],"id":3805736},{"atb":[[6.2,70.45],[4.9,0]],"id":3805731},{"atl":[[540,0],[510,2]],"id":3805731},{"atb":[[11,0],[15,7.14]],"id":522752},{"atl":[[750,2],[870,0]],"id":522752},{"atl":[[540,0],[510,2]],"id":3805762},{"atb":[[26,0],[30,3.45]],"id":522741},{"atb":[[10.5,0],[14.5,7.41]],"id":522742},{"atl":[[740,2],[860,0]],"id":522742},{"atb":[[5.3,0],[6.8,17.24]],"id":3805740},{"atl":[[530,0],[490,2]],"id":3805740}],"con":true,"img":false}]}
{"op":"mcm","clk":"5348152477","pt":1646214643186,"mc":[{"id":"1.195453755","rc":[{"atb":[[7.2,2.72],[6.2,3.26]],"id":3805746}],"con":true,"img":false}]}
{"op":"mcm","clk":"5348153875","pt":1646214664936,"mc":[{"id":"1.195453755","rc":[{"atb":[[3.8,0],[4.7,27.03]],"id":3805730},{"atl":[[430,2],[460,0]],"id":3805730}],"con":true,"img":false}]}
{"op":"mcm","clk":"5348161969","pt":1646214788429,"mc":[{"id":"1.195453755","rc":[{"atl":[[430,0],[440,2]],"id":3805783},{"atl":[[440,0],[460,2]],"id":3805755},{"atl":[[760,0],[800,2]],"id":522746},{"atl":[[420,0],[430,2]],"id":3805736},{"atb":[[32,3.23],[34,0]],"id":522747},{"atl":[[1000,0]],"id":522747},{"atl":[[820,0],[860,2]],"id":522750},{"atl":[[520,2],[510,0]],"id":3805731},{"atl":[[750,0],[790,2]],"id":522752},{"atl":[[430,0],[440,2]],"id":3805730},{"atl":[[520,2],[510,0]],"id":3805762},{"atl":[[740,0],[780,2]],"id":522742},{"atl":[[490,0],[510,2]],"id":3805740},{"atl":[[1000,0]],"id":522745}],"con":true,"img":false}]}
{"op":"mcm","clk":"5348166362","pt":1646214851831,"mc":[{"id":"1.195453755","rc":[{"atb":[[1.95,0]],"id":3805793}],"con":true,"img":false}]}
{"op":"mcm","clk":"5348166383","pt":1646214852239,"mc":[{"id":"1.195453755","rc":[{"atb":[[1.9,0]],"id":3805793}],"con":true,"img":false}]}
{"op":"mcm","clk":"5348166416","pt":1646214852859,"mc":[{"id":"1.195453755","rc":[{"atb":[[2.82,2.72]],"id":3805793}],"con":true,"img":false}]}
{"op":"mcm","clk":"5348166446","pt":1646214853266,"mc":[{"id":"1.195453755","rc":[{"atb":[[2.72,3.26]],"id":3805793}],"con":true,"img":false}]}
{"op":"mcm","clk":"5348173868","pt":1646214966004,"mc":[{"id":"1.195453755","rc":[{"atl":[[430,2],[440,0]],"id":3805783},{"atl":[[440,2],[460,0]],"id":3805755},{"atl":[[760,2],[800,0]],"id":522746},{"atb":[[32,0],[34,3.03]],"id":522747},{"atl":[[1000,2]],"id":522747},{"atl":[[430,0],[420,2]],"id":3805736},{"atl":[[820,2],[860,0]],"id":522750},{"atl":[[520,0],[510,2]],"id":3805731},{"atl":[[750,2],[790,0]],"id":522752},{"atl":[[430,2],[440,0]],"id":3805730},{"atl":[[520,0],[510,2]],"id":3805762},{"atl":[[740,2],[780,0]],"id":522742},{"atl":[[490,2],[510,0]],"id":3805740},{"atl":[[1000,2]],"id":522745}],"con":true,"img":false}]}
{"op":"mcm","clk":"5348173899","pt":1646214966624,"mc":[{"id":"1.195453755","rc":[{"atb":[[7.2,0],[6.2,0]],"id":3805746}],"con":true,"img":false}]}
{"op":"mcm","clk":"5348173943","pt":1646214967408,"mc":[{"id":"1.195453755","rc":[{"atb":[[6.4,3.26],[7.4,2.72]],"id":3805746}],"con":true,"img":false}]}
{"op":"mcm","clk":"5348176008","pt":1646215000578,"mc":[{"id":"1.195453755","rc":[{"atl":[[1000,2]],"id":522743}],"con":true,"img":false}]}
{"op":"mcm","clk":"5348176040","pt":1646215000990,"mc":[{"id":"1.195453755","rc":[{"atb":[[6.4,0],[7.4,0]],"id":3805746}],"con":true,"img":false}]}
{"op":"mcm","clk":"5348176091","pt":1646215001662,"mc":[{"id":"1.195453755","rc":[{"atb":[[7.2,2.72],[6.2,3.26]],"id":3805746}],"con":true,"img":false}]}
{"op":"mcm","clk":"5348177486","pt":1646215021328,"mc":[{"id":"1.195453755","rc":[{"atl":[[510,0],[500,2]],"id":3805731}],"con":true,"img":false}]}
{"op":"mcm","clk":"5348179565","pt":1646215053173,"mc":[{"id":"1.195453755","rc":[{"atl":[[510,0],[500,2]],"id":3805762}],"con":true,"img":false}]}
{"op":"mcm","clk":"5348187971","pt":1646215189447,"mc":[{"id":"1.195453755","rc":[{"atb":[[7.2,0],[6.2,0]],"id":3805746}],"con":true,"img":false}]}
{"op":"mcm","clk":"5348187995","pt":1646215190174,"mc":[{"id":"1.195453755","rc":[{"atb":[[7.4,2.72]],"id":3805746}],"con":true,"img":false}]}
{"op":"mcm","clk":"5348187998","pt":1646215190272,"mc":[{"id":"1.195453755","rc":[{"atb":[[6.4,3.26]],"id":3805746}],"con":true,"img":false}]}
{"op":"mcm","clk":"5348207816","pt":1646215455150,"mc":[{"id":"1.195453755","rc":[{"atb":[[34,0],[36,2.86]],"id":522747},{"atl":[[1000,0]],"id":522747},{"atb":[[17.5,6.06],[15,0]],"id":522750},{"atl":[[490,2],[500,0]],"id":3805731},{"atl":[[430,0],[420,2]],"id":3805730},{"atb":[[36,2.86],[28,9.86]],"id":522753},{"atl":[[730,2],[740,0]],"id":522742},{"atl":[[1000,0]],"id":522743}],"con":true,"img":false}]}
{"op":"mcm","clk":"5348207842","pt":1646215455415,"mc":[{"id":"1.195453755","rc":[{"atb":[[6.4,0],[7.4,0]],"id":3805746}],"con":true,"img":false}]}
{"op":"mcm","clk":"5348207895","pt":1646215456144,"mc":[{"id":"1.195453755","rc":[{"atb":[[7.2,2.72],[6.2,3.26]],"id":3805746}],"con":true,"img":false}]}
{"op":"mcm","clk":"5348210090","pt":1646215482167,"mc":[{"id":"1.195453755","rc":[{"atl":[[1000,0]],"id":522749}],"con":true,"img":false}]}
{"op":"mcm","clk":"5348211050","pt":1646215494077,"mc":[{"id":"1.195453755","rc":[{"atl":[[1000,2]],"id":522749}],"con":true,"img":false}]}
{"op":"mcm","clk":"5348212813","pt":1646215516104,"mc":[{"id":"1.195453755","rc":[{"atl":[[1000,0]],"id":522749}],"con":true,"img":false}]}
{"op":"mcm","clk":"5348214158","pt":1646215533235,"mc":[{"id":"1.195453755","rc":[{"atb":[[34,3.03],[36,0]],"id":522747},{"atl":[[1000,2]],"id":522747},{"atl":[[1000,2]],"id":522749},{"atl":[[1000,2]],"id":522743}],"con":true,"img":false}]}
{"op":"mcm","clk":"5348219423","pt":1646215591186,"mc":[{"id":"1.195453755","rc":[{"atl":[[1000,0]],"id":522747}],"con":true,"img":false}]}
{"op":"mcm","clk":"5348220046","pt":1646215598195,"mc":[{"id":"1.195453755","rc":[{"atb":[[7.2,0],[6.2,0]],"id":3805746}],"con":true,"img":false}]}
{"op":"mcm","clk":"5348220069","pt":1646215598502,"mc":[{"id":"1.195453755","rc":[{"atl":[[1000,2]],"id":522747}],"con":true,"img":false}]}
{"op":"mcm","clk":"5348220118","pt":1646215598879,"mc":[{"id":"1.195453755","rc":[{"atb":[[7.4,2.72]],"id":3805746}],"con":true,"img":false}]}
{"op":"mcm","clk":"5348220127","pt":1646215598985,"mc":[{"id":"1.195453755","rc":[{"atb":[[6.4,3.26]],"id":3805746}],"con":true,"img":false}]}
{"op":"mcm","clk":"5348220430","pt":1646215602572,"mc":[{"id":"1.195453755","rc":[{"atb":[[17.5,0],[14.5,7.41]],"id":522750},{"atl":[[820,0],[810,2]],"id":522750}],"con":true,"img":false}]}
{"op":"mcm","clk":"5348220574","pt":1646215604503,"mc":[{"id":"1.195453755","rc":[{"atl":[[420,2]],"id":3805755},{"atl":[[730,2],[810,0]],"id":522750},{"atl":[[480,2],[500,0]],"id":3805762},{"atl":[[1000,2]],"id":522753}],"con":true,"img":false}]}
{"op":"mcm","clk":"5348220584","pt":1646215604607,"mc":[{"id":"1.195453755","rc":[{"atl":[[440,0]],"id":3805755}],"con":true,"img":false}]}
{"op":"mcm","clk":"5348222511","pt":1646215627925,"mc":[{"id":"1.195453755","rc":[{"atb":[[34,0],[22,14.27]],"id":522747}],"con":true,"img":false}]}
{"op":"mcm","clk":"5348225992","pt":1646215668667,"mc":[{"id":"1.195453755","rc":[{"atl":[[730,0],[720,2]],"id":522750}],"con":true,"img":false}]}
{"op":"mcm","clk":"5348230633","pt":1646215720325,"mc":[{"id":"1.195453755","rc":[{"atl":[[490,0],[480,2]],"id":3805784},{"atl":[[750,0],[740,2]],"id":522752},{"atl":[[470,2],[480,0]],"id":3805762},{"atb":[[7.2,16.13],[6.8,0]],"id":3805740}],"con":true,"img":false}]}
{"op":"mcm","clk":"5348232376","pt":1646215739435,"mc":[{"id":"1.195453755","rc":[{"atl":[[720,0],[710,2]],"id":522750}],"con":true,"img":false}]}
{"op":"mcm","clk":"5348249574","pt":1646215923887,"mc":[{"id":"1.195453755","rc":[{"atb":[[6.4,0],[7.4,0]],"id":3805746}],"con":true,"img":false}]}
{"op":"mcm","clk":"5348249656","pt":1646215924923,"mc":[{"id":"1.195453755","rc":[{"atb":[[7.6,32.99],[6.6,3.26]],"id":3805746}],"con":true,"img":false}]}
{"op":"mcm","clk":"5348254767","pt":1646215977636,"mc":[{"id":"1.195453755","rc":[{"atb":[[18,0],[10.5,0],[8.2,0]],"id":3805784},{"atb":[[16,0],[7.4,0],[9.4,0]],"id":3805783},{"atb":[[5.7,0],[8.4,0],[4.7,0]],"id":3805747},{"atb":[[4.3,0],[5.3,0],[7.6,2.72]],"id":3805746},{"atb":[[2.4,0],[2.2,0],[2.7,0]],"id":3805793},{"atb":[[16,0],[7.4,0],[9.4,0]],"id":3805755},{"atb":[[10.5,0],[26,0],[15.5,0]],"id":522746},{"atb":[[16,0],[44,0],[22,4.76]],"id":522747},{"atb":[[4.3,0],[5.3,0],[7.6,0]],"id":3805736},{"atb":[[16,0],[44,0],[22,0]],"id":522749},{"atb":[[16,0],[44,0],[22,0]],"id":522750},{"atb":[[6.2,19.23],[8.2,0],[13,0]],"id":3805731},{"atb":[[16,0],[44,0],[22,0]],"id":522752},{"atb":[[18,0],[10.5,0],[8.2,0]],"id":3805762},{"atb":[[10,0],[5.5,0],[7,0]],"id":3805730},{"atb":[[130,0],[46,3.26],[28,0]],"id":522753},{"atb":[[32,0],[18,0],[13,0]],"id":522741},{"atb":[[32,0],[18,0],[13,0]],"id":522742},{"atb":[[5.7,0],[8.4,0],[4.7,0]],"id":3805740},{"atb":[[70,0],[19.5,0],[29,0]],"id":522743},{"atb":[[70,0],[19.5,0],[29,0]],"id":522745}],"con":true,"img":false}]}
{"op":"mcm","clk":"5348254795","pt":1646215977800,"mc":[{"id":"1.195453755","rc":[{"atb":[[29,6.83],[30,0]],"id":522749},{"atb":[[24,7.61],[30,0]],"id":522741}],"con":true,"img":false}]}
{"op":"mcm","clk":"5348255001","pt":1646215978876,"mc":[{"id":"1.195453755","rc":[{"atb":[[5.6,6.54],[7.2,0]],"id":3805762}],"con":true,"img":false}]}
{"op":"mcm","clk":"5348255266","pt":1646215981301,"mc":[{"id":"1.195453755","rc":[{"atb":[[5.1,64.97],[10.5,14.02],[6.2,51.22]],"id":3805784},{"atb":[[5.7,56.67],[4.7,98.63],[9.4,15.85]],"id":3805783},{"atb":[[3.85,93.47],[3.35,113.35],[5.7,28.33]],"id":3805747},{"atb":[[5.3,30.97],[3.15,123.9],[3.65,100.52]],"id":3805746},{"atb":[[2.4,95.13],[2,266.39],[1.9,295.98]],"id":3805793},{"atb":[[5.7,56.67],[9.4,15.85],[4.7,71.99]],"id":3805755},{"atb":[[6.2,51.22],[8.2,36.99],[15.5,9.18]],"id":522746},{"atb":[[22,11.1],[11,26.63],[8.4,35.99]],"id":522747},{"atb":[[5.3,30.97],[3.15,123.9],[3.65,100.52]],"id":3805736},{"atb":[[22,6.34],[11,26.63],[8.4,35.99]],"id":522749},{"atb":[[22,6.34],[11,26.63],[8.4,35.99]],"id":522750},{"atb":[[5.1,64.97],[8.2,18.49],[4.1,85.93]],"id":3805731},{"atb":[[22,6.34],[11,26.63],[8.4,35.99]],"id":522752},{"atb":[[5.1,64.97],[10.5,14.02],[6.2,51.22]],"id":3805762},{"atb":[[4.5,76.11],[7,22.19],[3.75,96.87]],"id":3805730},{"atb":[[19,14.8],[46,6.22],[14,20.49]],"id":522753},{"atb":[[7.2,42.96],[18,7.83],[9.2,32.48]],"id":522741},{"atb":[[7.2,42.96],[18,7.83],[9.2,32.48]],"id":522742},{"atb":[[3.85,93.47],[3.35,113.35],[5.7,28.33]],"id":3805740},{"atb":[[9.8,30.27],[29,4.75],[14.5,19.73]],"id":522743},{"atb":[[9.8,30.27],[29,4.75],[14.5,19.73]],"id":522745}],"con":true,"img":false}]}
{"op":"mcm","clk":"5348255290","pt":1646215981511,"mc":[{"id":"1.195453755","rc":[{"atb":[[28,0],[30,3.45]],"id":522743}],"con":true,"img":false}]}
{"op":"mcm","clk":"5348255472","pt":1646215982982,"mc":[{"id":"1.195453755","rc":[{"atb":[[23,4.55],[29,3.26]],"id":522749},{"atb":[[18.5,5.71],[24,3.26]],"id":522741}],"con":true,"img":false}]}
{"op":"mcm","clk":"5348266407","pt":1646216079541,"mc":[{"id":"1.195453755","rc":[{"atl":[[470,2],[480,0]],"id":3805784}],"con":true,"img":false}]}
{"op":"mcm","clk":"5348266832","pt":1646216081948,"mc":[{"id":"1.195453755","rc":[{"atl":[[430,0],[420,2]],"id":3805783},{"atl":[[410,2],[420,0]],"id":3805755},{"atb":[[11,36.63]],"id":522750},{"atl":[[680,2]],"id":522750},{"atl":[[720,2],[740,0]],"id":522752},{"atl":[[960,2],[1000,0]],"id":522753}],"con":true,"img":false}]}
{"op":"mcm","clk":"5348266860","pt":1646216082008,"mc":[{"id":"1.195453755","rc":[{"atb":[[14.5,0]],"id":522750},{"atl":[[710,0]],"id":522750}],"con":true,"img":false}]}
{"op":"mcm","clk":"5348268924","pt":1646216088144,"mc":[{"id":"1.195453755","rc":[{"atl":[[460,2],[470,0]],"id":3805784}],"con":true,"img":false}]}
{"op":"mcm","clk":"5348273989","pt":1646216107885,"mc":[{"id":"1.195453755","rc":[{"atb":[[1.62,0],[1.35,256.43]],"id":3805793},{"atb":[[6.8,0],[8.8,9.52]],"id":522745}],"con":true,"img":false}]}
{"op":"mcm","clk":"5348292176","pt":1646216221403,"mc":[{"id":"1.195453755","rc":[{"atb":[[17,4.95],[10.5,22.92],[15,9.9]],"id":3805784},{"atl":[[36,9.9],[29,4.95],[480,2.56]],"id":3805784},{"atb":[[10,9.9],[12,8.22],[9.4,24.76]],"id":3805783},{"atl":[[25,4.95],[440,2.79],[29,9.9]],"id":3805783},{"atb":[[8.6,8.22],[7.8,9.9]],"id":3805747},{"atl":[[400,0.39],[13.5,4.95],[15.5,9.9]],"id":3805747},{"atb":[[6.2,4.95],[5.3,39.88],[5.7,9.9]],"id":3805746},{"atl":[[12,4.95],[400,0.39],[430,2.86],[14,9.9]],"id":3805746},{"atb":[[2.82,11.63],[2.4,104.04],[2.8,9.9],[2.88,4.95]],"id":3805793},{"atl":[[3.85,4.95],[4.1,9.9],[12,8.9],[13.5,8.9]],"id":3805793},{"atb":[[9.6,9.9],[11,4.95],[9.4,24.76]],"id":3805755},{"atl":[[24,4.95],[400,0.39],[430,2.86],[28,9.9]],"id":3805755},{"atb":[[38,4.95],[25,6.6],[30,9.9],[15.5,18.09]],"id":522746},{"atl":[[95,4.95],[750,0.21],[780,1.57]],"id":522746},{"atb":[[80,9.9],[40,4.06],[22,20],[100,4.95]],"id":522747},{"atl":[[200,4.95],[990,0.15]],"id":522747},{"atb":[[8.6,8.9],[10.5,9.9],[5.3,39.88],[12.5,4.95]],"id":3805736},{"atl":[[23,4.95],[410,0.38],[27,9.9],[440,2.79]],"id":3805736},{"atb":[[90,9.9],[23,13.45],[120,4.95]],"id":522749},{"atl":[[240,4.95]],"id":522749},{"atb":[[32,4.95],[40,6.79],[22,15.24],[27,9.9]],"id":522750},{"atl":[[670,0.23],[700,1.75],[110,4.95]],"id":522750},{"atb":[[8.2,27.4],[12.5,18.81],[14.5,4.95]],"id":3805731},{"atl":[[36,4.95],[44,9.9],[480,0.33],[510,2.4]],"id":3805731},{"atb":[[36,9.9],[40,6.79],[22,15.24],[44,4.95]],"id":522752},{"atl":[[710,0.22],[740,1.65],[110,4.95]],"id":522752},{"atb":[[10.5,22.92],[12.5,9.9],[14.5,4.95]],"id":3805762},{"atl":[[36,9.9],[29,4.95],[490,2.5]],"id":3805762},{"atb":[[11.5,11.63],[7,31.1]],"id":3805730},{"atl":[[410,0.38],[440,2.79]],"id":3805730},{"atb":[[70,2.29],[36,11.15],[85,9.9],[110,4.95]],"id":522753},{"atl":[[950,0.16],[980,1.24]],"id":522753},{"atb":[[80,9.9],[100,4.95],[30,5.46]],"id":522741},{"atl":[[990,0.15]],"id":522741},{"atb":[[32,5.11],[18,16.74],[42,9.9],[50,4.95]],"id":522742},{"atl":[[720,0.21],[750,1.63],[110,4.95]],"id":522742},{"atb":[[85,9.9],[110,4.95],[55,2.93],[30,12.35]],"id":522743},{"atl":[[220,4.95],[990,0.15]],"id":522743},{"atb":[[9.4,8.9]],"id":3805740},{"atl":[[480,0.33]],"id":3805740},{"atb":[[85,9.9],[110,4.95],[29,13.66]],"id":522745},{"atl":[[240,4.95]],"id":522745}],"con":true,"img":false}]}
{"op":"mcm","clk":"5348292188","pt":1646216221506,"mc":[{"id":"1.195453755","rc":[{"atb":[[5.7,37.24]],"id":3805747},{"atl":[[430,2.86]],"id":3805747},{"atb":[[16,4.95],[7.2,25.03],[14,9.9]],"id":3805740},{"atl":[[36,4.95],[44,9.9],[510,2.4]],"id":3805740}],"con":true,"img":false}]}
{"op":"mcm","clk":"5348292199","pt":1646216221614,"mc":[{"id":"1.195453755","rc":[{"atl":[[85,2],[460,0]],"id":3805784},{"atl":[[65,2],[420,0]],"id":3805783},{"atl":[[70,2],[410,0]],"id":3805747},{"atl":[[70,2],[410,0]],"id":3805746},{"atl":[[5,14.86],[12.5,0]],"id":3805793},{"atl":[[410,0],[55,2]],"id":3805755},{"atl":[[760,0],[370,2]],"id":522746},{"atl":[[70,2],[420,0]],"id":3805736},{"atb":[[22,15.24],[27,3.85]],"id":522747},{"atl":[[630,2],[1000,0]],"id":522747},{"atb":[[34,3.03],[23,8.9]],"id":522749},{"atl":[[790,2],[1000,0]],"id":522749},{"atl":[[280,2],[680,0]],"id":522750},{"atl":[[490,0],[120,2]],"id":3805731},{"atl":[[320,2],[720,0]],"id":522752},{"atl":[[85,2],[470,0]],"id":3805762},{"atl":[[420,0],[430,2]],"id":3805730},{"atl":[[960,0],[970,2]],"id":522753},{"atb":[[18.5,0],[27,3.85]],"id":522741},{"atl":[[730,0],[360,2]],"id":522742},{"atl":[[710,2],[1000,0]],"id":522743},{"atl":[[830,2],[1000,0]],"id":522745}],"con":true,"img":false}]}
{"op":"mcm","clk":"5348292213","pt":1646216221672,"mc":[{"id":"1.195453755","rc":[{"atl":[[100,2],[490,0]],"id":3805740}],"con":true,"img":false}]}
{"op":"mcm","clk":"5348292265","pt":1646216222093,"mc":[{"id":"1.195453755","rc":[{"atb":[[15.5,11.63]],"id":3805784},{"atl":[[450,0.35]],"id":3805784},{"atl":[[410,0.38]],"id":3805783},{"atl":[[1000,1.22]],"id":522747},{"atl":[[260,4.74]],"id":522749},{"atl":[[1000,1.22]],"id":522743}],"con":true,"img":false}]}
{"op":"mcm","clk":"5348292280","pt":1646216222209,"mc":[{"id":"1.195453755","rc":[{"atb":[[40,4.06]],"id":522749},{"atl":[[990,0.15]],"id":522749},{"atb":[[15.5,11.63]],"id":3805762},{"atl":[[460,0.34]],"id":3805762},{"atb":[[12.5,9.9],[14.5,4.95]],"id":3805730},{"atl":[[25,4.95],[29,9.9]],"id":3805730},{"atb":[[18.5,8.9]],"id":522741},{"atb":[[55,2.93]],"id":522745},{"atl":[[990,0.15]],"id":522745}],"con":true,"img":false}]}
{"op":"mcm","clk":"5348292295","pt":1646216222301,"mc":[{"id":"1.195453755","rc":[{"atb":[[6.8,0],[8.4,13.51]],"id":3805784},{"atb":[[6,20],[4.7,71.99]],"id":3805783},{"atb":[[4,0],[4.9,25.64]],"id":3805747},{"atb":[[4,33.33],[3.3,0]],"id":3805746},{"atb":[[4.8,0],[5.8,20.83]],"id":3805755},{"atb":[[11.5,0],[15,7.14]],"id":522746},{"atb":[[6.2,19.23],[4.7,0]],"id":3805736},{"atl":[[630,2],[790,0]],"id":522749},{"atb":[[16,6.67],[11,26.63]],"id":522750},{"atb":[[6.2,0],[8.8,12.82]],"id":3805731},{"atb":[[19,5.56],[15,0]],"id":522752},{"atb":[[6.6,17.86],[4.7,0]],"id":3805730},{"atb":[[5.6,0],[7,16.67]],"id":3805762},{"atb":[[23,4.55],[14.5,0]],"id":522742},{"atb":[[7.2,8.9],[9.4,20.8]],"id":3805740}],"con":true,"img":false}]}
{"op":"mcm","clk":"5348292344","pt":1646216222711,"mc":[{"id":"1.195453755","rc":[{"atl":[[990,1.4]],"id":522745}],"con":true,"img":false}]}
{"op":"mcm","clk":"5348292786","pt":1646216226131,"mc":[{"id":"1.195453755","rc":[{"atl":[[250,4.95]],"id":522753}],"con":true,"img":false}]}
{"op":"mcm","clk":"5348292880","pt":1646216226814,"mc":[{"id":"1.195453755","rc":[{"atl":[[690,2],[370,0]],"id":522746},{"atl":[[630,0],[900,2]],"id":522747},{"atl":[[280,0],[610,2]],"id":522750},{"atl":[[320,0],[640,2]],"id":522752},{"atl":[[670,2],[360,0]],"id":522742},{"atl":[[710,0],[960,2]],"id":522743},{"atl":[[830,0],[990,3.4]],"id":522745}],"con":true,"img":false}]}
{"op":"mcm","clk":"5348292961","pt":1646216227501,"mc":[{"id":"1.195453755","rc":[{"atl":[[26,4.95],[30,9.9]],"id":3805783},{"atl":[[990,2.15]],"id":522745}],"con":true,"img":false}]}
{"op":"mcm","clk":"5348292978","pt":1646216227605,"mc":[{"id":"1.195453755","rc":[{"atl":[[25,0],[29,0]],"id":3805783}],"con":true,"img":false}]}
{"op":"mcm","clk":"5348293032","pt":1646216227918,"mc":[{"id":"1.195453755","rc":[{"atl":[[24,0],[25,4.95],[28,0],[29,9.9]],"id":3805755}],"con":true,"img":false}]}
{"op":"mcm","clk":"5348293068","pt":1646216228184,"mc":[{"id":"1.195453755","rc":[{"atl":[[26,0],[30,0]],"id":3805783},{"atl":[[250,0]],"id":522753}],"con":true,"img":false}]}
{"op":"mcm","clk":"5348293155","pt":1646216228801,"mc":[{"id":"1.195453755","rc":[{"atl":[[850,2],[970,0]],"id":522753}],"con":true,"img":false}]}
{"op":"mcm","clk":"5348293196","pt":1646216229114,"mc":[{"id":"1.195453755","rc":[{"atl":[[25,4.95],[29,9.9]],"id":3805783}],"con":true,"img":false}]}
{"op":"mcm","clk":"5348293295","pt":1646216229905,"mc":[{"id":"1.195453755","rc":[{"atl":[[260,0],[630,3.98]],"id":522749}],"con":true,"img":false}]}
{"op":"mcm","clk":"5348294251","pt":1646216236123,"mc":[{"id":"1.195453755","rc":[{"atl":[[25,0],[26,4.95],[29,0],[30,9.9]],"id":3805783},{"atl":[[240,4.95]],"id":522753}],"con":true,"img":false}]}
{"op":"mcm","clk":"5348294283","pt":1646216236336,"mc":[{"id":"1.195453755","rc":[{"atl":[[850,0],[450,2]],"id":522753}],"con":true,"img":false}]}
{"op":"mcm","clk":"5348294390","pt":1646216237123,"mc":[{"id":"1.195453755","rc":[{"atb":[[10.5,14.02],[15,31.99]],"id":3805784},{"atl":[[480,0]],"id":3805784},{"atl":[[65,21.57],[440,0]],"id":3805783},{"atb":[[6.2,17.17],[5.3,30.97]],"id":3805746},{"atl":[[70,14.21],[12,17.17],[430,0]],"id":3805746},{"atb":[[2.8,39.36],[2.4,95.13],[2.88,34.41]],"id":3805793},{"atl":[[3.85,34.41],[13.5,0]],"id":3805793},{"atl":[[50,3.23]],"id":3805755},{"atb":[[40,4.06]],"id":522746},{"atl":[[95,6.63]],"id":522746},{"atb":[[40,17.47],[22,6.34],[100,6.55]],"id":522747},{"atl":[[200,5.74]],"id":522747},{"atb":[[12.5,18.74]],"id":3805736},{"atb":[[40,17.47],[23,0]],"id":522749},{"atb":[[22,6.34]],"id":522750},{"atl":[[100,1.6]],"id":522750},{"atb":[[8.2,18.49],[15,11.32]],"id":3805731},{"atl":[[36,9.48]],"id":3805731},{"atb":[[11.5,33.71]],"id":3805730},{"atl":[[410,3.49],[440,0]],"id":3805730},{"atb":[[110,6.4]],"id":522753},{"atb":[[100,6.55]],"id":522741},{"atb":[[16,15.52]],"id":3805740},{"atl":[[36,9.48]],"id":3805740}],"con":true,"img":false}]}
{"op":"mcm","clk":"5348294404","pt":1646216237233,"mc":[{"id":"1.195453755","rc":[{"atl":[[85,17.03]],"id":3805784},{"atb":[[10,29.48],[9.4,15.85]],"id":3805783},{"atl":[[430,0],[13.5,17.63]],"id":3805747},{"atl":[[5,44.31]],"id":3805793},{"atb":[[11,17.17],[9.4,15.85]],"id":3805755},{"atl":[[430,0],[55,14.21]],"id":3805755},{"atb":[[25,21.31],[15.5,9.18]],"id":522746},{"atl":[[750,1.9],[780,0]],"id":522746},{"atb":[[8.6,29.5],[5.3,30.97]],"id":3805736},{"atl":[[70,20.25],[23,12.15],[440,0]],"id":3805736},{"atb":[[30,15.48]],"id":522750},{"atl":[[670,2.13],[700,0]],"id":522750},{"atb":[[12,17.43]],"id":3805731},{"atl":[[120,12.64],[510,0]],"id":3805731},{"atb":[[36,24.62],[44,8.64],[22,6.34]],"id":522752},{"atl":[[710,2.01],[740,0],[110,6.4]],"id":522752},{"atb":[[7,22.19],[14.5,16.69]],"id":3805730},{"atl":[[25,11.55]],"id":3805730},{"atb":[[10.5,14.02],[13,17.98]],"id":3805762},{"atl":[[85,16.71]],"id":3805762},{"atb":[[70,13.07],[36,2.86]],"id":522753},{"atl":[[230,0.69],[950,1.5]],"id":522753},{"atb":[[32,19.82],[18,7.83],[50,8.19]],"id":522742},{"atl":[[720,1.98],[750,0],[110,6.4]],"id":522742},{"atb":[[110,6.4],[55,14.66],[30,3.45]],"id":522743},{"atl":[[220,5.67]],"id":522743},{"atb":[[55,17.65],[29,4.75]],"id":522745}],"con":true,"img":false}]}
{"op":"mcm","clk":"5348294416","pt":1646216237331,"mc":[{"id":"1.195453755","rc":[{"atb":[[5.7,28.33]],"id":3805747},{"atl":[[70,20.26]],"id":3805747},{"atl":[[4.5,28.57],[5,29.45]],"id":3805793},{"atl":[[630,1.98],[990,2.15]],"id":522749},{"atl":[[610,0],[210,2]],"id":522750},{"atb":[[9.4,42.89]],"id":3805740},{"atl":[[100,14.77],[510,0]],"id":3805740}],"con":true,"img":false}]}
{"op":"mcm","clk":"5348294430","pt":1646216237397,"mc":[{"id":"1.195453755","rc":[{"atl":[[65,2],[430,0]],"id":3805730}],"con":true,"img":false}]}
{"op":"mcm","clk":"5348294454","pt":1646216237602,"mc":[{"id":"1.195453755","rc":[{"atl":[[630,0],[990,3.43]],"id":522749}],"con":true,"img":false}]}
{"op":"mcm","clk":"5348294484","pt":1646216237816,"mc":[{"id":"1.195453755","rc":[{"atb":[[17,14.86]],"id":3805784},{"atl":[[29,10.61]],"id":3805784},{"atl":[[26,11.29]],"id":3805783},{"atl":[[12,0]],"id":3805793},{"atb":[[40,13.4]],"id":522747},{"atl":[[990,1.28],[1000,0]],"id":522747},{"atl":[[670,1.89]],"id":522750},{"atl":[[480,0]],"id":3805731},{"atb":[[9.4,33.98]],"id":3805740},{"atl":[[480,0]],"id":3805740},{"atl":[[990,1.44],[1000,0]],"id":522743}],"con":true,"img":false}]}
{"op":"mcm","clk":"5348294495","pt":1646216237914,"mc":[{"id":"1.195453755","rc":[{"atl":[[400,0]],"id":3805746},{"atb":[[2.82,2.72]],"id":3805793},{"atl":[[400,0]],"id":3805755},{"atb":[[25,14.71]],"id":522746},{"atl":[[750,1.69]],"id":522746},{"atb":[[8.6,20.6]],"id":3805736},{"atb":[[120,6.28]],"id":522749},{"atl":[[240,5.61]],"id":522749},{"atl":[[100,0]],"id":522750},{"atb":[[12.5,9.9],[15,0]],"id":3805731},{"atl":[[710,1.79]],"id":522752},{"atl":[[490,0]],"id":3805762},{"atb":[[70,10.77]],"id":522753},{"atl":[[240,0],[980,0],[250,4.95]],"id":522753},{"atb":[[18.5,0],[30,16.26]],"id":522741},{"atb":[[110,6.4]],"id":522745},{"atl":[[240,5.61]],"id":522745}],"con":true,"img":false}]}
{"op":"mcm","clk":"5348294510","pt":1646216238018,"mc":[{"id":"1.195453755","rc":[{"atl":[[400,0]],"id":3805747},{"atl":[[410,0]],"id":3805736},{"atb":[[40,2.72]],"id":522752},{"atl":[[29,10.61]],"id":3805762},{"atb":[[11.5,24.81]],"id":3805730},{"atl":[[410,3.1]],"id":3805730},{"atl":[[230,0],[950,1.33]],"id":522753},{"atb":[[32,14.71]],"id":522742},{"atb":[[55,11.72]],"id":522743},{"atl":[[990,1.28]],"id":522743}],"con":true,"img":false}]}
{"op":"mcm","clk":"5348294521","pt":1646216238119,"mc":[{"id":"1.195453755","rc":[{"atb":[[7.8,29.48]],"id":3805747},{"atl":[[720,1.76]],"id":522742},{"atb":[[7.2,0]],"id":3805740}],"con":true,"img":false}]}
{"op":"mcm","clk":"5348294596","pt":1646216238605,"mc":[{"id":"1.195453755","rc":[{"atb":[[15.5,2.72]],"id":3805784},{"atl":[[450,0]],"id":3805784},{"atl":[[410,0]],"id":3805783},{"atb":[[40,13.4]],"id":522749},{"atl":[[990,3.28]],"id":522749},{"atl":[[110,6.4]],"id":522750},{"atb":[[55,14.71]],"id":522745}],"con":true,"img":false}]}
{"op":"mcm","clk":"5348294611","pt":1646216238713,"mc":[{"id":"1.195453755","rc":[{"atb":[[13,13.21]],"id":3805731},{"atl":[[990,2]],"id":522745}],"con":true,"img":false}]}
{"op":"mcm","clk":"5348294628","pt":1646216238815,"mc":[{"id":"1.195453755","rc":[{"atl":[[440,0.35]],"id":522753}],"con":true,"img":false}]}
{"op":"mcm","clk":"5348294646","pt":1646216238911,"mc":[{"id":"1.195453755","rc":[{"atl":[[460,0]],"id":3805762}],"con":true,"img":false}]}
{"op":"mcm","clk":"5348295135","pt":1646216242423,"mc":[{"id":"1.195453755","rc":[{"atl":[[610,2],[210,0]],"id":522750}],"con":true,"img":false}]}
{"op":"mcm","clk":"5348295550","pt":1646216245603,"mc":[{"id":"1.195453755","rc":[{"atl":[[260,4.99],[990,2]],"id":522749}],"con":true,"img":false}]}
{"op":"mcm","clk":"5348295577","pt":1646216245822,"mc":[{"id":"1.195453755","rc":[{"atl":[[620,2],[990,0]],"id":522749}],"con":true,"img":false}]}
{"op":"mcm","clk":"5348295693","pt":1646216246715,"mc":[{"id":"1.195453755","rc":[{"atl":[[900,0],[990,3.28]],"id":522747},{"atb":[[16,0],[19,5.56]],"id":522750},{"atb":[[36,0],[46,8.44]],"id":522753},{"atl":[[560,2],[450,0]],"id":522753}],"con":true,"img":false}]}
{"op":"mcm","clk":"5348295716","pt":1646216246924,"mc":[{"id":"1.195453755","rc":[{"atb":[[7.6,0],[6.6,0]],"id":3805746},{"atb":[[2.84,4.95],[2.76,9.9]],"id":3805793},{"atl":[[200,0.79],[230,4.95]],"id":522747},{"atl":[[32,4.95],[36,0],[40,9.9],[29,5.66]],"id":3805762},{"atl":[[220,0.72],[250,4.95]],"id":522743},{"atl":[[260,5.01]],"id":522745}],"con":true,"img":false}]}
{"op":"mcm","clk":"5348295730","pt":1646216247025,"mc":[{"id":"1.195453755","rc":[{"atb":[[2.8,29.45],[2.88,0]],"id":3805793}],"con":true,"img":false}]}
{"op":"mcm","clk":"5348295747","pt":1646216247131,"mc":[{"id":"1.195453755","rc":[{"atl":[[700,2],[960,0]],"id":522743},{"atl":[[640,2],[990,0]],"id":522745}],"con":true,"img":false}]}
{"op":"mcm","clk":"5348295774","pt":1646216247336,"mc":[{"id":"1.195453755","rc":[{"atl":[[990,2]],"id":522747}],"con":true,"img":false}]}
{"op":"mcm","clk":"5348295787","pt":1646216247439,"mc":[{"id":"1.195453755","rc":[{"atb":[[6.2,35.44],[5.3,77.63]],"id":3805746}],"con":true,"img":false}]}
{"op":"mcm","clk":"5348295830","pt":1646216247718,"mc":[{"id":"1.195453755","rc":[{"atb":[[6.4,3.26],[7.4,2.72]],"id":3805746},{"atb":[[2.82,24.81]],"id":3805793}],"con":true,"img":false}]}
{"op":"mcm","clk":"5348296401","pt":1646216252526,"mc":[{"id":"1.195453755","rc":[{"atb":[[6.2,71.3],[5.3,30.97]],"id":3805746},{"atb":[[2.84,46.07]],"id":3805793},{"atl":[[25,11.55]],"id":3805755},{"atb":[[15,11.32]],"id":3805731},{"atl":[[65,22.33],[410,0]],"id":3805730}],"con":true,"img":false}]}
{"op":"mcm","clk":"5348296415","pt":1646216252631,"mc":[{"id":"1.195453755","rc":[{"atl":[[4.5,107.9],[5,0]],"id":3805793},{"atl":[[50,15.45],[55,2]],"id":3805755},{"atb":[[25,0],[30,23.31]],"id":522746},{"atb":[[12,2.72],[12.5,39.36]],"id":3805731},{"atl":[[40,33.04],[85,2]],"id":3805762},{"atl":[[560,4.35],[950,0],[250,5.59]],"id":522753}],"con":true,"img":false}]}
{"op":"mcm","clk":"5348296480","pt":1646216253237,"mc":[{"id":"1.195453755","rc":[{"atl":[[990,3.32]],"id":522747},{"atl":[[260,0],[620,4.12]],"id":522749},{"atl":[[700,3.88],[990,0]],"id":522743}],"con":true,"img":false}]}
{"op":"mcm","clk":"5348296489","pt":1646216253341,"mc":[{"id":"1.195453755","rc":[{"atb":[[2.82,2.72]],"id":3805793},{"atl":[[50,12.21]],"id":3805755},{"atb":[[13,0]],"id":3805731}],"con":true,"img":false}]}
{"op":"mcm","clk":"5348296504","pt":1646216253449,"mc":[{"id":"1.195453755","rc":[{"atl":[[440,0]],"id":522753}],"con":true,"img":false}]}
{"op":"mcm","clk":"5348296643","pt":1646216254612,"mc":[{"id":"1.195453755","rc":[{"atl":[[260,0],[640,4.06]],"id":522745}],"con":true,"img":false}]}
{"op":"mcm","clk":"5348297050","pt":1646216258139,"mc":[{"id":"1.195453755","rc":[{"atl":[[270,4.95]],"id":522741}],"con":true,"img":false}]}
{"op":"mcm","clk":"5348297073","pt":1646216258351,"mc":[{"id":"1.195453755","rc":[{"atl":[[760,2],[1000,0]],"id":522741}],"con":true,"img":false}]}
{"op":"mcm","clk":"5348297101","pt":1646216258516,"mc":[{"id":"1.195453755","rc":[{"atl":[[760,0],[990,2.15]],"id":522741}],"con":true,"img":false}]}
{"op":"mcm","clk":"5348297116","pt":1646216258627,"mc":[{"id":"1.195453755","rc":[{"atl":[[260,0.61],[1000,1.32]],"id":522741}],"con":true,"img":false}]}
{"op":"mcm","clk":"5348297217","pt":1646216259448,"mc":[{"id":"1.195453755","rc":[{"atl":[[990,2]],"id":522741}],"con":true,"img":false}]}
{"op":"mcm","clk":"5348297248","pt":1646216259622,"mc":[{"id":"1.195453755","rc":[{"atb":[[2.82,7.67],[2.84,41.12],[2.76,0]],"id":3805793}],"con":true,"img":false}]}
{"op":"mcm","clk":"5348297320","pt":1646216260139,"mc":[{"id":"1.195453755","rc":[{"atl":[[700,1.88],[820,2]],"id":522743}],"con":true,"img":false}]}
{"op":"mcm","clk":"5348297345","pt":1646216260355,"mc":[{"id":"1.195453755","rc":[{"atb":[[17,4.95]],"id":3805784},{"atl":[[25,6.6],[29,0]],"id":3805730}],"con":true,"img":false}]}
{"op":"mcm","clk":"5348297362","pt":1646216260464,"mc":[{"id":"1.195453755","rc":[{"atb":[[16,4.95],[17,0],[14,9.9],[15,22.08]],"id":3805784},{"atl":[[26,4.95],[30,9.9]],"id":3805730},{"atl":[[250,0]],"id":522743},{"atl":[[640,2]],"id":522745}],"con":true,"img":false}]}
{"op":"mcm","clk":"5348297380","pt":1646216260559,"mc":[{"id":"1.195453755","rc":[{"atb":[[2.84,0]],"id":3805793}],"con":true,"img":false}]}
{"op":"mcm","clk":"5348297429","pt":1646216260831,"mc":[{"id":"1.195453755","rc":[{"atl":[[65,2]],"id":3805730}],"con":true,"img":false}]}
{"op":"mcm","clk":"5348297444","pt":1646216260933,"mc":[{"id":"1.195453755","rc":[{"atl":[[260,5.16],[620,2]],"id":522749},{"atl":[[700,0],[820,3.62]],"id":522743}],"con":true,"img":false}]}
{"op":"mcm","clk":"5348297459","pt":1646216261044,"mc":[{"id":"1.195453755","rc":[{"atb":[[15.5,13.65]],"id":3805784},{"atb":[[2.8,0],[2.72,61.78]],"id":3805793}],"con":true,"img":false}]}
{"op":"mcm","clk":"5348297490","pt":1646216261262,"mc":[{"id":"1.195453755","rc":[{"atb":[[2.8,44.49]],"id":3805793}],"con":true,"img":false}]}
{"op":"mcm","clk":"5348297549","pt":1646216261628,"mc":[{"id":"1.195453755","rc":[{"atl":[[820,2]],"id":522743}],"con":true,"img":false}]}
{"op":"mcm","clk":"5348297762","pt":1646216263046,"mc":[{"id":"1.195453755","rc":[{"atb":[[2.82,47.85]],"id":3805793}],"con":true,"img":false}]}
{"op":"mcm","clk":"5348297911","pt":1646216263968,"mc":[{"id":"1.195453755","rc":[{"atb":[[2.8,0]],"id":3805793}],"con":true,"img":false}]}
{"op":"mcm","clk":"5348298449","pt":1646216267748,"mc":[{"id":"1.195453755","rc":[{"atl":[[30,39.36]],"id":3805730},{"atl":[[270,5.04],[560,2]],"id":522753}],"con":true,"img":false}]}
{"op":"mcm","clk":"5348298533","pt":1646216268434,"mc":[{"id":"1.195453755","rc":[{"atb":[[2.4,258.11],[2.72,3.26]],"id":3805793},{"atl":[[260,0],[620,4.19]],"id":522749}],"con":true,"img":false}]}
{"op":"mcm","clk":"5348298675","pt":1646216269450,"mc":[{"id":"1.195453755","rc":[{"atl":[[12,0],[13.5,4.95],[14,0],[15.5,9.9]],"id":3805746},{"atb":[[15,0]],"id":3805731},{"atl":[[110,0],[120,4.95]],"id":522752},{"atb":[[75,9.9],[80,0],[95,4.95],[100,0]],"id":522741},{"atb":[[16,0],[13.5,9.9],[14,0],[15.5,4.95]],"id":3805740}],"con":true,"img":false}]}
{"op":"mcm","clk":"5348298704","pt":1646216269655,"mc":[{"id":"1.195453755","rc":[{"atl":[[640,0],[230,2]],"id":522752}],"con":true,"img":false}]}
{"op":"mcm","clk":"5348298767","pt":1646216270068,"mc":[{"id":"1.195453755","rc":[{"atb":[[12,31.54],[12.5,9.9]],"id":3805731}],"con":true,"img":false}]}
{"op":"mcm","clk":"5348298784","pt":1646216270173,"mc":[{"id":"1.195453755","rc":[{"atl":[[65,2.47]],"id":3805746},{"atb":[[13,13.21]],"id":3805731},{"atl":[[220,0.72]],"id":522752}],"con":true,"img":false}]}
{"op":"mcm","clk":"5348298794","pt":1646216270277,"mc":[{"id":"1.195453755","rc":[{"atb":[[32,3.88]],"id":522741},{"atb":[[9.6,18.43]],"id":3805740}],"con":true,"img":false}]}
{"op":"mcm","clk":"5348298861","pt":1646216270738,"mc":[{"id":"1.195453755","rc":[{"atl":[[65,14.69],[70,2]],"id":3805746},{"atl":[[710,0],[230,7.96]],"id":522752},{"atb":[[32,17],[30,0]],"id":522741},{"atb":[[9.6,47.89],[9.4,11.9]],"id":3805740}],"con":true,"img":false}]}
{"op":"mcm","clk":"5348298874","pt":1646216270854,"mc":[{"id":"1.195453755","rc":[{"atb":[[12,2.72]],"id":3805731}],"con":true,"img":false}]}
{"op":"mcm","clk":"5348299285","pt":1646216273760,"mc":[{"id":"1.195453755","rc":[{"atl":[[990,3.38],[1000,0]],"id":522741}],"con":true,"img":false}]}
{"op":"mcm","clk":"5348299392","pt":1646216274552,"mc":[{"id":"1.195453755","rc":[{"atl":[[110,0],[120,4.95]],"id":522750}],"con":true,"img":false}]}
{"op":"mcm","clk":"5348299407","pt":1646216274660,"mc":[{"id":"1.195453755","rc":[{"atl":[[16,9.9],[13.5,0],[14,4.95],[15.5,0]],"id":3805746}],"con":true,"img":false}]}
{"op":"mcm","clk":"5348299426","pt":1646216274768,"mc":[{"id":"1.195453755","rc":[{"atl":[[610,0],[250,2]],"id":522750}],"con":true,"img":false}]}
{"op":"mcm","clk":"5348299445","pt":1646216274976,"mc":[{"id":"1.195453755","rc":[{"atl":[[270,0],[560,4.46]],"id":522753}],"con":true,"img":false}]}
{"op":"mcm","clk":"5348299497","pt":1646216275351,"mc":[{"id":"1.195453755","rc":[{"atl":[[120,6.28]],"id":522750}],"con":true,"img":false}]}
{"op":"mcm","clk":"5348299522","pt":1646216275555,"mc":[{"id":"1.195453755","rc":[{"atl":[[650,2],[250,0]],"id":522750}],"con":true,"img":false}]}
{"op":"mcm","clk":"5348299542","pt":1646216275763,"mc":[{"id":"1.195453755","rc":[{"atl":[[280,4.95]],"id":522743}],"con":true,"img":false}]}
{"op":"mcm","clk":"5348299572","pt":1646216275971,"mc":[{"id":"1.195453755","rc":[{"atb":[[16,15.52]],"id":3805784},{"atl":[[260,5.32],[620,2]],"id":522749}],"con":true,"img":false}]}
{"op":"mcm","clk":"5348299592","pt":1646216276130,"mc":[{"id":"1.195453755","rc":[{"atl":[[570,2],[620,0]],"id":522749}],"con":true,"img":false}]}
{"op":"mcm","clk":"5348299604","pt":1646216276236,"mc":[{"id":"1.195453755","rc":[{"atl":[[820,3.68]],"id":522743}],"con":true,"img":false}]}
{"op":"mcm","clk":"5348299654","pt":1646216276758,"mc":[{"id":"1.195453755","rc":[{"atb":[[15.5,2.72]],"id":3805784},{"atl":[[260,0]],"id":522749}],"con":true,"img":false}]}
{"op":"mcm","clk":"5348300059","pt":1646216280020,"mc":[{"id":"1.195453755","rc":[{"atl":[[130,4.95],[120,0]],"id":522750},{"atb":[[70,9.9],[75,0],[90,4.95],[95,0]],"id":522741}],"con":true,"img":false}]}
{"op":"mcm","clk":"5348300076","pt":1646216280185,"mc":[{"id":"1.195453755","rc":[{"atl":[[650,0],[250,2]],"id":522750}],"con":true,"img":false}]}
{"op":"mcm","clk":"5348300154","pt":1646216280774,"mc":[{"id":"1.195453755","rc":[{"atl":[[240,0.66]],"id":522750}],"con":true,"img":false}]}
{"op":"mcm","clk":"5348300182","pt":1646216280985,"mc":[{"id":"1.195453755","rc":[{"atb":[[13,9.9],[13.5,0],[15,4.95],[15.5,0]],"id":3805740}],"con":true,"img":false}]}
{"op":"mcm","clk":"5348300212","pt":1646216281145,"mc":[{"id":"1.195453755","rc":[{"atb":[[2.82,2.72],[2.72,8.22],[2.64,9.9]],"id":3805793},{"atl":[[95,0],[110,4.95]],"id":522746},{"atl":[[200,0]],"id":522747},{"atl":[[130,0],[160,4.95]],"id":522750},{"atl":[[150,4.95],[120,0]],"id":522752},{"atl":[[560,2],[250,0]],"id":522753}],"con":true,"img":false}]}
{"op":"mcm","clk":"5348300228","pt":1646216281250,"mc":[{"id":"1.195453755","rc":[{"atl":[[670,0],[250,7.6]],"id":522750}],"con":true,"img":false}]}
{"op":"mcm","clk":"5348300245","pt":1646216281358,"mc":[{"id":"1.195453755","rc":[{"atl":[[32,9.9],[36,0],[27,4.95],[29,5.66]],"id":3805784},{"atl":[[23,4.95],[26,6.34],[27,9.9],[30,0]],"id":3805783},{"atl":[[16,0],[12,4.95]],"id":3805746},{"atb":[[9.6,0],[10,9.9],[11,12.21],[12,8.22]],"id":3805755},{"atl":[[280,2],[690,0]],"id":522746},{"atb":[[80,0],[85,9.9],[100,1.6],[110,4.95]],"id":522747},{"atl":[[220,4.95],[240,0.66]],"id":522749},{"atb":[[17,4.95],[12.5,0],[14.5,0],[15,9.9]],"id":3805731},{"atb":[[12.5,0],[13,9.9],[14.5,11.74],[15,4.95]],"id":3805730},{"atb":[[16.5,4.95]],"id":3805762},{"atb":[[85,0],[90,9.9],[110,1.45],[120,4.95]],"id":522753},{"atb":[[130,4.95],[70,0],[90,0],[95,9.9]],"id":522741},{"atb":[[42,0],[44,9.9],[50,3.23],[55,4.95]],"id":522742},{"atb":[[130,4.95],[85,0],[95,9.9],[110,1.45]],"id":522743}],"con":true,"img":false}]}
{"op":"mcm","clk":"5348300272","pt":1646216281576,"mc":[{"id":"1.195453755","rc":[{"atl":[[85,15.03],[60,2]],"id":3805784},{"atl":[[65,19.57],[46,2.22]],"id":3805783},{"atb":[[2.4,95.13],[2.64,39.36]],"id":3805793},{"atl":[[250,5.6]],"id":522747}],"con":true,"img":false}]}
{"op":"mcm","clk":"5348300285","pt":1646216281676,"mc":[{"id":"1.195453755","rc":[{"atl":[[990,2]],"id":522747},{"atb":[[16,4.95],[13,0],[14,9.9],[15,0]],"id":3805740},{"atl":[[34,4.95],[36,4.52],[42,9.9],[44,0]],"id":3805740}],"con":true,"img":false}]}
{"op":"mcm","clk":"5348300329","pt":1646216281890,"mc":[{"id":"1.195453755","rc":[{"atl":[[32,33.04],[85,0],[26,6.32]],"id":3805784},{"atl":[[65,0],[22,7.54],[27,31.54]],"id":3805783},{"atb":[[2.72,37.68]],"id":3805793},{"atl":[[3.85,29.45],[3.95,9.9],[4.1,0],[3.75,4.95]],"id":3805793},{"atl":[[130,9.9],[95,4.95],[110,1.45]],"id":522746},{"atb":[[40,0],[85,24.62],[120,1.32]],"id":522747},{"atl":[[230,5.64]],"id":522747},{"atl":[[210,0.75]],"id":522749},{"atb":[[40,11.74],[27,0]],"id":522750},{"atl":[[140,4.95],[160,0]],"id":522750},{"atl":[[130,4.95],[150,0]],"id":522752},{"atb":[[11.5,2.72],[13,34.45],[15.5,10.93]],"id":3805730},{"atb":[[17,9.9],[13,3.26],[14.5,20.72]],"id":3805762},{"atb":[[70,0],[90,20.23],[120,6.28]],"id":522753},{"atl":[[1000,0.15]],"id":522753},{"atb":[[32,0],[44,22.08],[60,2.68]],"id":522742},{"atb":[[140,1.13],[95,22.73],[55,0]],"id":522743}],"con":true,"img":false}]}
{"op":"mcm","clk":"5348300336","pt":1646216281936,"mc":[{"id":"1.195453755","rc":[{"atl":[[630,2],[990,0]],"id":522747}],"con":true,"img":false}]}
{"op":"mcm","clk":"5348300353","pt":1646216282044,"mc":[{"id":"1.195453755","rc":[{"atl":[[12,0],[13.5,4.95],[14,0],[15.5,9.9]],"id":3805746},{"atl":[[24,4.95],[28,9.9]],"id":3805755},{"atl":[[630,0],[990,2]],"id":522747},{"atb":[[12.5,0]],"id":3805762},{"atl":[[560,0],[240,4.95],[960,2]],"id":522753},{"atb":[[130,0],[80,9.9],[95,0],[100,4.95]],"id":522741},{"atl":[[75,2],[100,12.77]],"id":3805740}],"con":true,"img":false}]}
{"op":"mcm","clk":"5348300371","pt":1646216282150,"mc":[{"id":"1.195453755","rc":[{"atl":[[25,6.6],[29,0]],"id":3805755},{"atb":[[17,0],[13,23.11]],"id":3805731}],"con":true,"img":false}]}
{"op":"mcm","clk":"5348300391","pt":1646216282259,"mc":[{"id":"1.195453755","rc":[{"atl":[[630,2],[990,0]],"id":522747},{"atl":[[560,2],[960,0]],"id":522753}],"con":true,"img":false}]}
{"op":"mcm","clk":"5348300399","pt":1646216282361,"mc":[{"id":"1.195453755","rc":[{"atl":[[4.5,28.57],[3.95,68.42],[3.7,58.51]],"id":3805793},{"atl":[[130,20.72],[750,0]],"id":522746},{"atl":[[250,0]],"id":522747},{"atl":[[32,5.11],[42,31.99],[100,0]],"id":3805740}],"con":true,"img":false}]}
{"op":"mcm","clk":"5348300413","pt":1646216282465,"mc":[{"id":"1.195453755","rc":[{"atl":[[24,11.84],[50,0],[28,36.85]],"id":3805755},{"atl":[[580,2.41]],"id":522753}],"con":true,"img":false}]}
{"op":"mcm","clk":"5348300433","pt":1646216282575,"mc":[{"id":"1.195453755","rc":[{"atl":[[26,0]],"id":3805783},{"atl":[[240,0]],"id":522749},{"atb":[[15.5,2.72]],"id":3805762},{"atb":[[14.5,0]],"id":3805730},{"atb":[[110,0]],"id":522753},{"atb":[[50,0]],"id":522742},{"atb":[[110,0]],"id":522743}],"con":true,"img":false}]}
{"op":"mcm","clk":"5348300449","pt":1646216282680,"mc":[{"id":"1.195453755","rc":[{"atl":[[29,0]],"id":3805784},{"atb":[[2.8,4.95],[2.64,29.45]],"id":3805793},{"atb":[[100,0]],"id":522747}],"con":true,"img":false}]}
{"op":"mcm","clk":"5348300529","pt":1646216283157,"mc":[{"id":"1.195453755","rc":[{"atl":[[3.85,0]],"id":3805793},{"atl":[[36,0]],"id":3805740}],"con":true,"img":false}]}
{"op":"mcm","clk":"5348300541","pt":1646216283253,"mc":[{"id":"1.195453755","rc":[{"atb":[[2.72,88.82],[2.64,0]],"id":3805793},{"atl":[[25,0]],"id":3805755},{"atl":[[570,4.46]],"id":522749}],"con":true,"img":false}]}
{"op":"mcm","clk":"5348300736","pt":1646216284468,"mc":[{"id":"1.195453755","rc":[{"atl":[[640,0],[700,2]],"id":522745}],"con":true,"img":false}]}
{"op":"mcm","clk":"5348300778","pt":1646216284764,"mc":[{"id":"1.195453755","rc":[{"atl":[[22,4.95],[23,7.2],[26,9.9],[27,0]],"id":3805736},{"atl":[[36,4.52],[38,4.95],[44,0],[46,9.9]],"id":3805731},{"atl":[[270,0]],"id":522741},{"atl":[[110,1.45],[120,4.95]],"id":522742}],"con":true,"img":false}]}
{"op":"mcm","clk":"5348300792","pt":1646216284868,"mc":[{"id":"1.195453755","rc":[{"atb":[[12,32.18]],"id":3805731}],"con":true,"img":false}]}
{"op":"mcm","clk":"5348300800","pt":1646216284974,"mc":[{"id":"1.195453755","rc":[{"atl":[[22,0]],"id":3805783},{"atl":[[15,8.9]],"id":3805746},{"atb":[[15,21.23]],"id":3805731},{"atl":[[130,6.18]],"id":522752},{"atb":[[34,4.8]],"id":522741},{"atl":[[290,2],[670,0]],"id":522742},{"atb":[[16,0],[13.5,9.9],[14,0],[15.5,4.95]],"id":3805740},{"atl":[[700,4.01]],"id":522745}],"con":true,"img":false}]}
{"op":"mcm","clk":"5348300831","pt":1646216285281,"mc":[{"id":"1.195453755","rc":[{"atl":[[70,2],[21,6.97],[26,39.36]],"id":3805736},{"atl":[[46,31.99],[120,2]],"id":3805731},{"atl":[[990,2]],"id":522741},{"atl":[[670,2.1],[720,0]],"id":522742}],"con":true,"img":false}]}
{"op":"mcm","clk":"5348300870","pt":1646216285552,"mc":[{"id":"1.195453755","rc":[{"atl":[[65,2.47],[15.5,30.5]],"id":3805746},{"atl":[[240,0],[250,4.95]],"id":522753},{"atb":[[32,3.88],[34,19.1]],"id":522741},{"atb":[[15.5,15.88]],"id":3805740}],"con":true,"img":false}]}
{"op":"mcm","clk":"5348300883","pt":1646216285654,"mc":[{"id":"1.195453755","rc":[{"atl":[[65,0]],"id":3805746},{"atb":[[13,9.9]],"id":3805731},{"atl":[[220,0]],"id":522752},{"atb":[[13.5,0],[15.5,10.93]],"id":3805740},{"atl":[[700,2]],"id":522745}],"con":true,"img":false}]}
{"op":"mcm","clk":"5348300895","pt":1646216285757,"mc":[{"id":"1.195453755","rc":[{"atl":[[26,6.34]],"id":3805783}],"con":true,"img":false}]}
{"op":"mcm","clk":"5348300913","pt":1646216285871,"mc":[{"id":"1.195453755","rc":[{"atb":[[32,0]],"id":522741}],"con":true,"img":false}]}
{"op":"mcm","clk":"5348300933","pt":1646216286074,"mc":[{"id":"1.195453755","rc":[{"atl":[[23,0],[26,9.9]],"id":3805736}],"con":true,"img":false}]}
{"op":"mcm","clk":"5348300944","pt":1646216286180,"mc":[{"id":"1.195453755","rc":[{"atb":[[9.6,18.43],[9.4,45.83]],"id":3805740}],"con":true,"img":false}]}
{"op":"mcm","clk":"5348300963","pt":1646216286343,"mc":[{"id":"1.195453755","rc":[{"atl":[[150,9.43],[230,2]],"id":522752},{"atb":[[9.6,0]],"id":3805740}],"con":true,"img":false}]}
{"op":"mcm","clk":"5348300978","pt":1646216286446,"mc":[{"id":"1.195453755","rc":[{"atb":[[13.5,9.9],[15.5,15.88]],"id":3805740}],"con":true,"img":false}]}
{"op":"mcm","clk":"5348301258","pt":1646216288973,"mc":[{"id":"1.195453755","rc":[{"atb":[[65,14.12],[90,9.9]],"id":522753}],"con":true,"img":false}]}
{"op":"mcm","clk":"5348301342","pt":1646216289692,"mc":[{"id":"1.195453755","rc":[{"atl":[[55,27.94],[28,9.9]],"id":3805755}],"con":true,"img":false}]}
{"op":"mcm","clk":"5348301360","pt":1646216289896,"mc":[{"id":"1.195453755","rc":[{"atl":[[22,4.95],[23,0],[26,16.25],[27,21.64]],"id":3805783},{"atl":[[16,9.9],[13.5,0],[14,4.95],[15.5,20.6]],"id":3805746},{"atl":[[130,10.81],[140,9.9],[95,0],[100,4.95]],"id":522746},{"atl":[[130,0],[140,4.95]],"id":522752},{"atl":[[240,4.95],[250,0]],"id":522753}],"con":true,"img":false}]}
{"op":"mcm","clk":"5348301407","pt":1646216290166,"mc":[{"id":"1.195453755","rc":[{"atl":[[140,6.09]],"id":522750}],"con":true,"img":false}]}
{"op":"mcm","clk":"5348301462","pt":1646216290589,"mc":[{"id":"1.195453755","rc":[{"atl":[[130,4.95],[140,6.09]],"id":522752}],"con":true,"img":false}]}
{"op":"mcm","clk":"5348301477","pt":1646216290697,"mc":[{"id":"1.195453755","rc":[{"atl":[[140,1.13]],"id":522752}],"con":true,"img":false}]}
{"op":"mcm","clk":"5348301498","pt":1646216290847,"mc":[{"id":"1.195453755","rc":[{"atl":[[22,0],[23,4.95],[26,6.34],[27,31.54]],"id":3805783},{"atl":[[240,0]],"id":522750},{"atl":[[240,0],[250,4.95]],"id":522753}],"con":true,"img":false}]}
{"op":"mcm","clk":"5348301567","pt":1646216291376,"mc":[{"id":"1.195453755","rc":[{"atl":[[130,0]],"id":522752}],"con":true,"img":false}]}
{"op":"mcm","clk":"5348301578","pt":1646216291479,"mc":[{"id":"1.195453755","rc":[{"atl":[[140,6.09]],"id":522752}],"con":true,"img":false}]}
{"op":"mcm","clk":"5348301822","pt":1646216293579,"mc":[{"id":"1.195453755","rc":[{"atl":[[150,0],[230,8.24]],"id":522752}],"con":true,"img":false}]}
{"op":"mcm","clk":"5348302032","pt":1646216295252,"mc":[{"id":"1.195453755","rc":[{"atl":[[290,4.95]],"id":522741}],"con":true,"img":false}]}
{"op":"mcm","clk":"5348302056","pt":1646216295463,"mc":[{"id":"1.195453755","rc":[{"atl":[[850,2],[990,0]],"id":522741}],"con":true,"img":false}]}
{"op":"mcm","clk":"5348302107","pt":1646216295883,"mc":[{"id":"1.195453755","rc":[{"atl":[[160,9.01],[250,2]],"id":522750},{"atl":[[990,1.44]],"id":522741}],"con":true,"img":false}]}
{"op":"mcm","clk":"5348302157","pt":1646216296355,"mc":[{"id":"1.195453755","rc":[{"atb":[[14.5,4.95],[15.5,18.49]],"id":3805762},{"atl":[[550,0.28]],"id":522753}],"con":true,"img":false}]}
{"op":"mcm","clk":"5348302199","pt":1646216296774,"mc":[{"id":"1.195453755","rc":[{"atl":[[160,0]],"id":522750},{"atl":[[560,4.57]],"id":522753}],"con":true,"img":false}]}
{"op":"mcm","clk":"5348302206","pt":1646216296879,"mc":[{"id":"1.195453755","rc":[{"atl":[[580,0]],"id":522753}],"con":true,"img":false}]}
{"op":"mcm","clk":"5348302231","pt":1646216297036,"mc":[{"id":"1.195453755","rc":[{"atl":[[1000,0]],"id":522753}],"con":true,"img":false}]}
{"op":"mcm","clk":"5348302490","pt":1646216299342,"mc":[{"id":"1.195453755","rc":[{"atl":[[14.5,11.74]],"id":3805746}],"con":true,"img":false}]}
{"op":"mcm","clk":"5348302498","pt":1646216299446,"mc":[{"id":"1.195453755","rc":[{"atb":[[100,6.55]],"id":522741}],"con":true,"img":false}]}
{"op":"mcm","clk":"5348302530","pt":1646216299762,"mc":[{"id":"1.195453755","rc":[{"atl":[[26,39.36]],"id":3805736},{"atl":[[290,7],[670,0]],"id":522742}],"con":true,"img":false}]}
{"op":"mcm","clk":"5348302557","pt":1646216299965,"mc":[{"id":"1.195453755","rc":[{"atl":[[15,29.5],[15.5,0]],"id":3805746}],"con":true,"img":false}]}
{"op":"mcm","clk":"5348302584","pt":1646216300175,"mc":[{"id":"1.195453755","rc":[{"atl":[[15,20.6]],"id":3805746}],"con":true,"img":false}]}
{"op":"mcm","clk":"5348302603","pt":1646216300384,"mc":[{"id":"1.195453755","rc":[{"atb":[[34,14.3]],"id":522741}],"con":true,"img":false}]}
{"op":"mcm","clk":"5348302676","pt":1646216300861,"mc":[{"id":"1.195453755","rc":[{"atl":[[160,9.1],[230,2]],"id":522752}],"con":true,"img":false}]}
{"op":"mcm","clk":"5348302782","pt":1646216301694,"mc":[{"id":"1.195453755","rc":[{"atl":[[250,0]],"id":522753}],"con":true,"img":false}]}
{"op":"mcm","clk":"5348302804","pt":1646216301850,"mc":[{"id":"1.195453755","rc":[{"atl":[[560,2.57],[580,2]],"id":522753}],"con":true,"img":false}]}
{"op":"mcm","clk":"5348302813","pt":1646216301955,"mc":[{"id":"1.195453755","rc":[{"atl":[[260,4.95]],"id":522753}],"con":true,"img":false}]}
{"op":"mcm","clk":"5348303518","pt":1646216307791,"mc":[{"id":"1.195453755","rc":[{"atl":[[160,0],[230,8.41]],"id":522752}],"con":true,"img":false}]}
{"op":"mcm","clk":"5348303623","pt":1646216308574,"mc":[{"id":"1.195453755","rc":[{"atl":[[230,2]],"id":522752}],"con":true,"img":false}]}
{"op":"mcm","clk":"5348303805","pt":1646216310087,"mc":[{"id":"1.195453755","rc":[{"atl":[[160,9.27]],"id":522750}],"con":true,"img":false}]}
{"op":"mcm","clk":"5348303837","pt":1646216310353,"mc":[{"id":"1.195453755","rc":[{"atl":[[850,3.73],[990,0]],"id":522741}],"con":true,"img":false}]}
{"op":"mcm","clk":"5348303877","pt":1646216310775,"mc":[{"id":"1.195453755","rc":[{"atl":[[260,5.56]],"id":522753}],"con":true,"img":false}]}
{"op":"mcm","clk":"5348303912","pt":1646216311089,"mc":[{"id":"1.195453755","rc":[{"atb":[[2.82,17.43]],"id":3805793}],"con":true,"img":false}]}
{"op":"mcm","clk":"5348303994","pt":1646216311782,"mc":[{"id":"1.195453755","rc":[{"atl":[[550,0]],"id":522753}],"con":true,"img":false}]}
{"op":"mcm","clk":"5348304041","pt":1646216312200,"mc":[{"id":"1.195453755","rc":[{"atb":[[2.72,59.37]],"id":3805793}],"con":true,"img":false}]}
{"op":"mcm","clk":"5348304065","pt":1646216312352,"mc":[{"id":"1.195453755","rc":[{"atl":[[560,0],[580,4.56]],"id":522753}],"con":true,"img":false}]}
{"op":"mcm","clk":"5348304202","pt":1646216313455,"mc":[{"id":"1.195453755","rc":[{"atl":[[13.5,12.68]],"id":3805746}],"con":true,"img":false}]}
{"op":"mcm","clk":"5348304290","pt":1646216314200,"mc":[{"id":"1.195453755","rc":[{"atl":[[14.5,36.55],[15,0]],"id":3805746}],"con":true,"img":false}]}
{"op":"mcm","clk":"5348304323","pt":1646216314459,"mc":[{"id":"1.195453755","rc":[{"atl":[[14.5,24.8]],"id":3805746}],"con":true,"img":false}]}
{"op":"mcm","clk":"5348304386","pt":1646216314987,"mc":[{"id":"1.195453755","rc":[{"atl":[[160,9.36]],"id":522752}],"con":true,"img":false}]}
{"op":"mcm","clk":"5348304586","pt":1646216316970,"mc":[{"id":"1.195453755","rc":[{"atl":[[160,0],[250,8.01]],"id":522750}],"con":true,"img":false}]}
{"op":"mcm","clk":"5348304650","pt":1646216317595,"mc":[{"id":"1.195453755","rc":[{"atb":[[16,10.56],[16.5,4.95],[14,0],[14.5,9.9]],"id":3805784},{"atl":[[32,23.14],[34,9.9],[27,0],[28,4.95]],"id":3805784},{"atb":[[6.4,0],[7.4,0]],"id":3805746},{"atb":[[2.82,2.72],[2.8,0],[2.72,54.41],[2.78,4.95],[2.7,9.9]],"id":3805793},{"atb":[[32,9.9],[38,0],[40,9.01],[30,13.4]],"id":522746},{"atl":[[36,9.48],[38,0],[44,9.9],[46,22.08]],"id":3805731},{"atl":[[25,11.55],[26,0],[29,9.9],[30,29.45]],"id":3805730}],"con":true,"img":false}]}
{"op":"mcm","clk":"5348304693","pt":1646216317970,"mc":[{"id":"1.195453755","rc":[{"atl":[[140,0],[150,4.95]],"id":522750},{"atl":[[260,0],[270,4.95],[580,2]],"id":522753}],"con":true,"img":false}]}
{"op":"mcm","clk":"5348304711","pt":1646216318068,"mc":[{"id":"1.195453755","rc":[{"atb":[[17,9.9],[15,0],[15.5,19.47]],"id":3805784},{"atb":[[6.2,35.44],[5.3,86.7]],"id":3805746},{"atl":[[100,6.55]],"id":522746}],"con":true,"img":false}]}
{"op":"mcm","clk":"5348304738","pt":1646216318275,"mc":[{"id":"1.195453755","rc":[{"atb":[[7.6,2.72],[6.6,3.26]],"id":3805746},{"atb":[[2.72,69.13]],"id":3805793}],"con":true,"img":false}]}
{"op":"mcm","clk":"5348304784","pt":1646216318695,"mc":[{"id":"1.195453755","rc":[{"atl":[[240,0.66]],"id":522750},{"atl":[[1000,0.15]],"id":522753}],"con":true,"img":false}]}
{"op":"mcm","clk":"5348304804","pt":1646216318852,"mc":[{"id":"1.195453755","rc":[{"atl":[[580,0],[1000,2.15]],"id":522753}],"con":true,"img":false}]}
{"op":"mcm","clk":"5348304813","pt":1646216318958,"mc":[{"id":"1.195453755","rc":[{"atb":[[16,0]],"id":3805784},{"atl":[[110,0]],"id":522746}],"con":true,"img":false}]}
{"op":"mcm","clk":"5348304870","pt":1646216319483,"mc":[{"id":"1.195453755","rc":[{"atl":[[130,0],[140,20.69]],"id":522746}],"con":true,"img":false}]}
{"op":"mcm","clk":"5348305151","pt":1646216321881,"mc":[{"id":"1.195453755","rc":[{"atl":[[160,0],[230,8.59]],"id":522752}],"con":true,"img":false}]}
{"op":"mcm","clk":"5348305233","pt":1646216322767,"mc":[{"id":"1.195453755","rc":[{"atl":[[230,2]],"id":522752}],"con":true,"img":false}]}
{"op":"mcm","clk":"5348305295","pt":1646216323392,"mc":[{"id":"1.195453755","rc":[{"atl":[[270,0],[260,4.95]],"id":522753}],"con":true,"img":false}]}
{"op":"mcm","clk":"5348305313","pt":1646216323603,"mc":[{"id":"1.195453755","rc":[{"atl":[[610,2],[1000,0.15]],"id":522753}],"con":true,"img":false}]}
{"op":"mcm","clk":"5348305351","pt":1646216323969,"mc":[{"id":"1.195453755","rc":[{"atl":[[140,4.95],[150,0]],"id":522750}],"con":true,"img":false}]}
{"op":"mcm","clk":"5348305426","pt":1646216324806,"mc":[{"id":"1.195453755","rc":[{"atl":[[140,0],[150,4.95]],"id":522750},{"atl":[[260,5.56]],"id":522753}],"con":true,"img":false}]}
{"op":"mcm","clk":"5348305443","pt":1646216324965,"mc":[{"id":"1.195453755","rc":[{"atl":[[610,0],[1000,2.15]],"id":522753}],"con":true,"img":false}]}
{"op":"mcm","clk":"5348305524","pt":1646216325799,"mc":[{"id":"1.195453755","rc":[{"atl":[[1000,2]],"id":522753}],"con":true,"img":false}]}
{"op":"mcm","clk":"5348305565","pt":1646216326164,"mc":[{"id":"1.195453755","rc":[{"atl":[[140,9.9],[280,7.46]],"id":522746},{"atl":[[280,5.46]],"id":522753}],"con":true,"img":false}]}
{"op":"mcm","clk":"5348305575","pt":1646216326268,"mc":[{"id":"1.195453755","rc":[{"atl":[[610,2],[1000,0]],"id":522753}],"con":true,"img":false}]}
{"op":"mcm","clk":"5348305857","pt":1646216328994,"mc":[{"id":"1.195453755","rc":[{"atl":[[160,9.6]],"id":522752}],"con":true,"img":false}]}
{"op":"mcm","clk":"5348306153","pt":1646216332080,"mc":[{"id":"1.195453755","rc":[{"atb":[[6.2,61.64],[5.3,30.97]],"id":3805746}],"con":true,"img":false}]}
{"op":"mcm","clk":"5348306214","pt":1646216332805,"mc":[{"id":"1.195453755","rc":[{"atl":[[230,0.69]],"id":522750}],"con":true,"img":false}]}
{"op":"mcm","clk":"5348306238","pt":1646216333071,"mc":[{"id":"1.195453755","rc":[{"atl":[[280,0],[610,4.52]],"id":522753}],"con":true,"img":false}]}
{"op":"mcm","clk":"5348306274","pt":1646216333383,"mc":[{"id":"1.195453755","rc":[{"atl":[[250,2]],"id":522750}],"con":true,"img":false}]}
{"op":"mcm","clk":"5348306283","pt":1646216333487,"mc":[{"id":"1.195453755","rc":[{"atl":[[240,7.11]],"id":522750}],"con":true,"img":false}]}
{"op":"mcm","clk":"5348306295","pt":1646216333592,"mc":[{"id":"1.195453755","rc":[{"atl":[[240,6.45]],"id":522750}],"con":true,"img":false}]}
{"op":"mcm","clk":"5348306514","pt":1646216335606,"mc":[{"id":"1.195453755","rc":[{"atl":[[160,0],[230,8.76]],"id":522752}],"con":true,"img":false}]}
{"op":"mcm","clk":"5348306776","pt":1646216338320,"mc":[{"id":"1.195453755","rc":[{"atl":[[16,0],[13.5,17.63],[14,0],[15.5,9.9]],"id":3805746},{"atb":[[13,0],[13.5,9.9],[15,11.32],[15.5,4.95]],"id":3805731},{"atb":[[16.5,0],[17,14.86],[14.5,0],[15,9.9]],"id":3805762}],"con":true,"img":false}]}
{"op":"mcm","clk":"5348306818","pt":1646216338787,"mc":[{"id":"1.195453755","rc":[{"atl":[[14.5,0],[15.5,50.85]],"id":3805746},{"atb":[[32,0],[34,9.9],[40,6.79],[42,4.95]],"id":522750},{"atb":[[12,2.72],[13.5,39.36],[15.5,15.88]],"id":3805731},{"atb":[[15,46.72],[15.5,2.72]],"id":3805762}],"con":true,"img":false}]}
{"op":"mcm","clk":"5348306829","pt":1646216338894,"mc":[{"id":"1.195453755","rc":[{"atl":[[3.95,58.51],[3.7,63.46],[3.9,9.9],[3.75,0]],"id":3805793}],"con":true,"img":false}]}
{"op":"mcm","clk":"5348306839","pt":1646216338997,"mc":[{"id":"1.195453755","rc":[{"atl":[[24,6.89],[28,0]],"id":3805755}],"con":true,"img":false}]}
{"op":"mcm","clk":"5348306851","pt":1646216339101,"mc":[{"id":"1.195453755","rc":[{"atl":[[23,4.95],[27,9.9]],"id":3805755}],"con":true,"img":false}]}
{"op":"mcm","clk":"5348306870","pt":1646216339308,"mc":[{"id":"1.195453755","rc":[{"atb":[[34,26.85],[44,3.68],[30,3.26]],"id":522750}],"con":true,"img":false}]}
{"op":"mcm","clk":"5348306905","pt":1646216339630,"mc":[{"id":"1.195453755","rc":[{"atl":[[23,12.15],[26,24.43],[55,2]],"id":3805755},{"atb":[[15,0]],"id":3805731}],"con":true,"img":false}]}
{"op":"mcm","clk":"5348306927","pt":1646216339820,"mc":[{"id":"1.195453755","rc":[{"atl":[[280,5.59],[610,2]],"id":522753}],"con":true,"img":false}]}
{"op":"mcm","clk":"5348306961","pt":1646216340088,"mc":[{"id":"1.195453755","rc":[{"atb":[[40,2.72]],"id":522750}],"con":true,"img":false}]}
{"op":"mcm","clk":"5348306984","pt":1646216340303,"mc":[{"id":"1.195453755","rc":[{"atl":[[24,0]],"id":3805755}],"con":true,"img":false}]}
{"op":"mcm","clk":"5348307262","pt":1646216342501,"mc":[{"id":"1.195453755","rc":[{"atl":[[160,9.84],[230,2]],"id":522752}],"con":true,"img":false}]}
{"op":"mcm","clk":"5348307610","pt":1646216345424,"mc":[{"id":"1.195453755","rc":[{"atl":[[70,24.63],[15.5,9.9]],"id":3805746},{"atb":[[12,41.07],[13.5,9.9]],"id":3805731}],"con":true,"img":false}]}
{"op":"mcm","clk":"5348307631","pt":1646216345586,"mc":[{"id":"1.195453755","rc":[{"atb":[[1.71,140.85],[1.35,0]],"id":3805793},{"atb":[[5.5,22.22],[8.8,0]],"id":3805731},{"atb":[[23,4.55],[30,0]],"id":522743},{"atb":[[9.8,41.63],[8.8,0]],"id":522745}],"con":true,"img":false}]}
{"op":"mcm","clk":"5348307681","pt":1646216346110,"mc":[{"id":"1.195453755","rc":[{"atl":[[26,0],[27,42.71]],"id":3805755}],"con":true,"img":false}]}
{"op":"mcm","clk":"5348307704","pt":1646216346319,"mc":[{"id":"1.195453755","rc":[{"atl":[[140,1.13]],"id":522750},{"atl":[[280,0],[610,4.59]],"id":522753}],"con":true,"img":false}]}
{"op":"mcm","clk":"5348307780","pt":1646216346999,"mc":[{"id":"1.195453755","rc":[{"atl":[[230,7.59]],"id":522750},{"atl":[[610,2]],"id":522753}],"con":true,"img":false}]}
{"op":"mcm","clk":"5348307794","pt":1646216347103,"mc":[{"id":"1.195453755","rc":[{"atl":[[230,6.89],[240,0]],"id":522750}],"con":true,"img":false}]}
{"op":"mcm","clk":"5348308031","pt":1646216349251,"mc":[{"id":"1.195453755","rc":[{"atl":[[160,0],[230,8.92]],"id":522752}],"con":true,"img":false}]}
{"op":"mcm","clk":"5348308110","pt":1646216349826,"mc":[{"id":"1.195453755","rc":[{"atb":[[13,9.9],[13.5,0],[15,4.95],[15.5,0]],"id":3805731}],"con":true,"img":false}]}
{"op":"mcm","clk":"5348308233","pt":1646216350818,"mc":[{"id":"1.195453755","rc":[{"atb":[[13.5,12.68]],"id":3805731},{"atl":[[260,0.61],[250,4.95]],"id":522753}],"con":true,"img":false}]}
{"op":"mcm","clk":"5348308296","pt":1646216351340,"mc":[{"id":"1.195453755","rc":[{"atl":[[250,5.59]],"id":522753}],"con":true,"img":false}]}
{"op":"mcm","clk":"5348308403","pt":1646216352135,"mc":[{"id":"1.195453755","rc":[{"atl":[[260,0]],"id":522753}],"con":true,"img":false}]}
{"op":"mcm","clk":"5348308421","pt":1646216352351,"mc":[{"id":"1.195453755","rc":[{"atb":[[12,2.72],[13,39.36],[15,16.27]],"id":3805731}],"con":true,"img":false}]}
{"op":"mcm","clk":"5348308456","pt":1646216352607,"mc":[{"id":"1.195453755","rc":[{"atl":[[27,9.9],[55,31.18]],"id":3805755},{"atb":[[34,9.9],[40,15.56]],"id":522750}],"con":true,"img":false}]}
{"op":"mcm","clk":"5348308520","pt":1646216353232,"mc":[{"id":"1.195453755","rc":[{"atb":[[13.5,0]],"id":3805731},{"atl":[[270,5.94]],"id":522753}],"con":true,"img":false}]}
{"op":"mcm","clk":"5348308813","pt":1646216355907,"mc":[{"id":"1.195453755","rc":[{"atl":[[160,10.08],[230,2]],"id":522752}],"con":true,"img":false}]}
{"op":"mcm","clk":"5348308857","pt":1646216356326,"mc":[{"id":"1.195453755","rc":[{"atl":[[260,4.95],[250,0]],"id":522753}],"con":true,"img":false}]}
{"op":"mcm","clk":"5348308956","pt":1646216357326,"mc":[{"id":"1.195453755","rc":[{"atl":[[270,6.52]],"id":522753}],"con":true,"img":false}]}
{"op":"mcm","clk":"5348309106","pt":1646216358833,"mc":[{"id":"1.195453755","rc":[{"atb":[[12,41.65]],"id":3805731}],"con":true,"img":false}]}
{"op":"mcm","clk":"5348309118","pt":1646216358934,"mc":[{"id":"1.195453755","rc":[{"atb":[[13,9.9]],"id":3805731}],"con":true,"img":false}]}
{"op":"mcm","clk":"5348309197","pt":1646216359823,"mc":[{"id":"1.195453755","rc":[{"atl":[[270,0.58],[610,4.65]],"id":522753}],"con":true,"img":false}]}
{"op":"mcm","clk":"5348309407","pt":1646216362325,"mc":[{"id":"1.195453755","rc":[{"atl":[[160,0]],"id":522752}],"con":true,"img":false}]}
{"op":"mcm","clk":"5348309419","pt":1646216362442,"mc":[{"id":"1.195453755","rc":[{"atl":[[230,9.09]],"id":522752}],"con":true,"img":false}]}
{"op":"mcm","clk":"5348309647","pt":1646216364524,"mc":[{"id":"1.195453755","rc":[{"atl":[[260,5.56]],"id":522753}],"con":true,"img":false}]}
{"op":"mcm","clk":"5348309739","pt":1646216365459,"mc":[{"id":"1.195453755","rc":[{"atl":[[270,0]],"id":522753}],"con":true,"img":false}]}
{"op":"mcm","clk":"5348309776","pt":1646216365828,"mc":[{"id":"1.195453755","rc":[{"atb":[[18,5.88],[15,0]],"id":522746},{"atl":[[630,0],[770,2]],"id":522747},{"atl":[[570,2.46],[720,2]],"id":522749},{"atb":[[19,0],[24,4.35]],"id":522750},{"atb":[[8.2,13.89],[7,0]],"id":3805762},{"atl":[[610,2.65],[780,2]],"id":522753},{"atl":[[820,1.68],[930,2]],"id":522743},{"atl":[[700,0],[790,2]],"id":522745}],"con":true,"img":false}]}
{"op":"mcm","clk":"5348309797","pt":1646216366038,"mc":[{"id":"1.195453755","rc":[{"atl":[[34,0],[28,0]],"id":3805784},{"atb":[[7.6,0],[6.6,0]],"id":3805746},{"atb":[[10,0],[10.5,9.9],[12,3.26],[12.5,4.95]],"id":3805755},{"atb":[[85,14.71],[110,0]],"id":522747},{"atl":[[230,0.69]],"id":522747},{"atb":[[15.5,0]],"id":3805730},{"atb":[[140,4.95],[90,0],[100,9.9],[120,1.32]],"id":522753},{"atl":[[610,0]],"id":522753},{"atl":[[240,0.66]],"id":522745}],"con":true,"img":false}]}
{"op":"mcm","clk":"5348309807","pt":1646216366144,"mc":[{"id":"1.195453755","rc":[{"atl":[[29,4.95]],"id":3805784},{"atl":[[27,37.64]],"id":3805783},{"atb":[[2.78,0],[2.7,0]],"id":3805793},{"atb":[[14.5,14.46]],"id":3805755},{"atb":[[90,9.9],[120,6.28]],"id":522747},{"atl":[[260,4.95]],"id":522747},{"atb":[[130,4.95],[90,0],[95,9.9],[120,1.32]],"id":522749},{"atl":[[260,4.95],[220,0]],"id":522749},{"atb":[[36,14.71],[42,9.9],[44,3.68],[50,4.95]],"id":522752},{"atb":[[12,9.9],[13,24.55],[14,4.95],[15,0]],"id":3805730},{"atl":[[280,0],[310,4.95],[220,0]],"id":522743},{"atl":[[270,4.95]],"id":522745}],"con":true,"img":false}]}
{"op":"mcm","clk":"5348309827","pt":1646216366356,"mc":[{"id":"1.195453755","rc":[{"atb":[[34,0],[46,2.22]],"id":522749},{"atl":[[780,4.09]],"id":522753},{"atl":[[790,4.07]],"id":522745}],"con":true,"img":false}]}
{"op":"mcm","clk":"5348309835","pt":1646216366457,"mc":[{"id":"1.195453755","rc":[{"atl":[[32,0]],"id":3805784},{"atb":[[6.2,35.44]],"id":3805746},{"atb":[[13,0]],"id":3805730},{"atb":[[65,2.72],[150,1.06],[100,24.62]],"id":522753}],"con":true,"img":false}]}
{"op":"mcm","clk":"5348309845","pt":1646216366556,"mc":[{"id":"1.195453755","rc":[{"atl":[[60,26.12]],"id":3805784},{"atb":[[5.3,93.81]],"id":3805746},{"atb":[[11,0],[12,25.35]],"id":3805755},{"atb":[[38,8.67],[85,0]],"id":522747},{"atb":[[36,0],[55,2.93]],"id":522752},{"atb":[[11.5,34.63]],"id":3805730}],"con":true,"img":false}]}
{"op":"mcm","clk":"5348309855","pt":1646216366622,"mc":[{"id":"1.195453755","rc":[{"atb":[[2.4,276.45],[2.72,17.98],[2.6,9.9],[2.68,4.95]],"id":3805793},{"atl":[[770,4.12]],"id":522747},{"atb":[[140,1.13],[95,20.92]],"id":522749},{"atb":[[42,28.01]],"id":522752},{"atl":[[820,0],[930,3.76]],"id":522743}],"con":true,"img":false}]}
{"op":"mcm","clk":"5348309872","pt":1646216366728,"mc":[{"id":"1.195453755","rc":[{"atb":[[6.4,3.26],[7.4,2.72]],"id":3805746},{"atb":[[13,13.21]],"id":3805730}],"con":true,"img":false}]}
{"op":"mcm","clk":"5348309890","pt":1646216366931,"mc":[{"id":"1.195453755","rc":[{"atl":[[27,31.54]],"id":3805783},{"atb":[[40,0]],"id":522749},{"atl":[[310,5.46]],"id":522743}],"con":true,"img":false}]}
{"op":"mcm","clk":"5348309920","pt":1646216367243,"mc":[{"id":"1.195453755","rc":[{"atb":[[120,0]],"id":522753},{"atl":[[780,2]],"id":522753}],"con":true,"img":false}]}
{"op":"mcm","clk":"5348309939","pt":1646216367451,"mc":[{"id":"1.195453755","rc":[{"atb":[[120,0]],"id":522749},{"atb":[[44,0]],"id":522752},{"atl":[[930,2]],"id":522743}],"con":true,"img":false}]}
{"op":"mcm","clk":"5348310095","pt":1646216369017,"mc":[{"id":"1.195453755","rc":[{"atl":[[160,10.31],[230,2]],"id":522752}],"con":true,"img":false}]}
{"op":"mcm","clk":"5348310118","pt":1646216369226,"mc":[{"id":"1.195453755","rc":[{"atl":[[23,0],[24,4.95],[27,21.64],[28,9.9]],"id":3805783},{"atl":[[23,0],[24,4.95],[27,0],[28,9.9]],"id":3805755},{"atl":[[140,0]],"id":522750},{"atl":[[140,4.95]],"id":522752},{"atl":[[260,4.95],[280,4.95]],"id":522753},{"atb":[[80,0],[85,9.9],[100,1.6],[110,4.95]],"id":522741}],"con":true,"img":false}]}
{"op":"mcm","clk":"5348310127","pt":1646216369330,"mc":[{"id":"1.195453755","rc":[{"atl":[[150,4.95]],"id":522752},{"atl":[[260,0]],"id":522753}],"con":true,"img":false}]}
{"op":"mcm","clk":"5348310166","pt":1646216369640,"mc":[{"id":"1.195453755","rc":[{"atl":[[230,0],[250,8.6]],"id":522750},{"atl":[[140,0]],"id":522752},{"atb":[[34,0],[85,22.82]],"id":522741}],"con":true,"img":false}]}
{"op":"mcm","clk":"5348310180","pt":1646216369740,"mc":[{"id":"1.195453755","rc":[{"atb":[[110,6.4]],"id":522741}],"con":true,"img":false}]}
{"op":"mcm","clk":"5348310209","pt":1646216369952,"mc":[{"id":"1.195453755","rc":[{"atl":[[50,3.23]],"id":3805755},{"atl":[[150,6.01]],"id":522750},{"atl":[[280,5.52]],"id":522753}],"con":true,"img":false}]}
{"op":"mcm","clk":"5348310235","pt":1646216370212,"mc":[{"id":"1.195453755","rc":[{"atl":[[150,6.01]],"id":522752}],"con":true,"img":false}]}
{"op":"mcm","clk":"5348310258","pt":1646216370426,"mc":[{"id":"1.195453755","rc":[{"atl":[[50,25.32],[55,2]],"id":3805755}],"con":true,"img":false}]}
{"op":"mcm","clk":"5348310276","pt":1646216370632,"mc":[{"id":"1.195453755","rc":[{"atb":[[13,0],[15.5,16.75]],"id":3805784},{"atb":[[2.82,0],[2.72,14.71]],"id":3805793},{"atb":[[40,0],[30,0]],"id":522752},{"atb":[[100,0]],"id":522741}],"con":true,"img":false}]}
{"op":"mcm","clk":"5348310283","pt":1646216370731,"mc":[{"id":"1.195453755","rc":[{"atb":[[38,0],[29,0]],"id":522749},{"atb":[[65,0],[46,5.17]],"id":522753},{"atb":[[40,0],[50,0]],"id":522745}],"con":true,"img":false}]}
{"op":"mcm","clk":"5348310305","pt":1646216370949,"mc":[{"id":"1.195453755","rc":[{"atl":[[23,4.95],[24,0],[27,31.54],[28,0]],"id":3805783}],"con":true,"img":false}]}
{"op":"mcm","clk":"5348310321","pt":1646216371046,"mc":[{"id":"1.195453755","rc":[{"atl":[[140,4.95],[150,1.06]],"id":522752}],"con":true,"img":false}]}
{"op":"mcm","clk":"5348310352","pt":1646216371317,"mc":[{"id":"1.195453755","rc":[{"atb":[[16,2.72],[13.5,3.26]],"id":3805784},{"atb":[[2.8,2.72],[2.7,3.26]],"id":3805793},{"atb":[[32,3.26],[42,30.73]],"id":522752}],"con":true,"img":false}]}
{"op":"mcm","clk":"5348310374","pt":1646216371527,"mc":[{"id":"1.195453755","rc":[{"atb":[[40,2.72],[30,3.26]],"id":522749},{"atb":[[70,2.72],[48,3.26]],"id":522753},{"atb":[[42,3.26],[55,17.43]],"id":522745}],"con":true,"img":false}]}
{"op":"mcm","clk":"5348310421","pt":1646216371944,"mc":[{"id":"1.195453755","rc":[{"atb":[[16,19.47],[15.5,0]],"id":3805784}],"con":true,"img":false}]}
{"op":"mcm","clk":"5348310477","pt":1646216372314,"mc":[{"id":"1.195453755","rc":[{"atl":[[23,0],[24,4.95],[27,21.64],[28,9.9]],"id":3805783},{"atl":[[140,0],[150,6.01]],"id":522752}],"con":true,"img":false}]}
{"op":"mcm","clk":"5348310524","pt":1646216372732,"mc":[{"id":"1.195453755","rc":[{"atb":[[16.5,0],[17.5,4.95],[14.5,0],[15.5,9.9]],"id":3805784},{"atb":[[32,0],[34,9.9],[40,4.06],[42,4.95]],"id":522746},{"atl":[[34,4.95],[36,4.52],[42,9.9],[44,0]],"id":3805731},{"atl":[[24,4.95],[25,6.6],[28,9.9],[29,0]],"id":3805730},{"atl":[[300,5.53]],"id":522753}],"con":true,"img":false}]}
{"op":"mcm","clk":"5348310576","pt":1646216373147,"mc":[{"id":"1.195453755","rc":[{"atb":[[18,9.32]],"id":3805784},{"atb":[[34,30.74],[44,3.68],[30,0]],"id":522746},{"atl":[[32,4.51],[42,39.36],[46,0]],"id":3805731},{"atl":[[23,7.2],[28,34.45],[30,0]],"id":3805730}],"con":true,"img":false}]}
{"op":"mcm","clk":"5348310681","pt":1646216374041,"mc":[{"id":"1.195453755","rc":[{"atb":[[17,0]],"id":3805784},{"atb":[[40,0]],"id":522746},{"atl":[[36,0],[42,9.9]],"id":3805731},{"atl":[[25,0]],"id":3805730}],"con":true,"img":false}]}
{"op":"mcm","clk":"5348310843","pt":1646216375558,"mc":[{"id":"1.195453755","rc":[{"atl":[[230,9.24]],"id":522752}],"con":true,"img":false}]}
{"op":"mcm","clk":"5348310862","pt":1646216375670,"mc":[{"id":"1.195453755","rc":[{"atl":[[160,0]],"id":522752}],"con":true,"img":false}]}
{"op":"mcm","clk":"5348310900","pt":1646216375924,"mc":[{"id":"1.195453755","rc":[{"atb":[[85,9.9],[29,15.64]],"id":522741}],"con":true,"img":false}]}
{"op":"mcm","clk":"5348311187","pt":1646216378834,"mc":[{"id":"1.195453755","rc":[{"atl":[[80,2],[120,0]],"id":3805731}],"con":true,"img":false}]}
{"op":"mcm","clk":"5348311228","pt":1646216379149,"mc":[{"id":"1.195453755","rc":[{"atl":[[22,0],[23,4.95],[26,29.45],[27,9.9]],"id":3805736},{"atl":[[32,0],[36,4.95],[40,23.14],[44,9.9]],"id":3805762},{"atl":[[300,0],[780,4.14]],"id":522753},{"atl":[[300,4.95],[310,0.51]],"id":522743}],"con":true,"img":false}]}
{"op":"mcm","clk":"5348311239","pt":1646216379247,"mc":[{"id":"1.195453755","rc":[{"atb":[[5.3,30.97]],"id":3805746},{"atb":[[12,35.33]],"id":3805730}],"con":true,"img":false}]}
{"op":"mcm","clk":"5348311254","pt":1646216379352,"mc":[{"id":"1.195453755","rc":[{"atb":[[11.5,2.72]],"id":3805730}],"con":true,"img":false}]}
{"op":"mcm","clk":"5348311272","pt":1646216379463,"mc":[{"id":"1.195453755","rc":[{"atb":[[6.2,76.39]],"id":3805746},{"atb":[[2.7,39.86]],"id":3805793},{"atl":[[330,5.08]],"id":522743}],"con":true,"img":false}]}
{"op":"mcm","clk":"5348311290","pt":1646216379569,"mc":[{"id":"1.195453755","rc":[{"atb":[[14,17.15]],"id":3805730}],"con":true,"img":false}]}
{"op":"mcm","clk":"5348311314","pt":1646216379728,"mc":[{"id":"1.195453755","rc":[{"atl":[[290,0.55]],"id":522743}],"con":true,"img":false}]}
{"op":"mcm","clk":"5348311327","pt":1646216379851,"mc":[{"id":"1.195453755","rc":[{"atl":[[780,2]],"id":522753}],"con":true,"img":false}]}
{"op":"mcm","clk":"5348311353","pt":1646216380038,"mc":[{"id":"1.195453755","rc":[{"atl":[[280,0.56],[290,4.95]],"id":522753}],"con":true,"img":false}]}
{"op":"mcm","clk":"5348311375","pt":1646216380245,"mc":[{"id":"1.195453755","rc":[{"atb":[[2.4,95.13]],"id":3805793},{"atl":[[330,0]],"id":522743}],"con":true,"img":false}]}
{"op":"mcm","clk":"5348311389","pt":1646216380354,"mc":[{"id":"1.195453755","rc":[{"atb":[[13,0]],"id":3805730}],"con":true,"img":false}]}
{"op":"mcm","clk":"5348311408","pt":1646216380563,"mc":[{"id":"1.195453755","rc":[{"atl":[[310,0]],"id":522743}],"con":true,"img":false}]}
{"op":"mcm","clk":"5348311494","pt":1646216381246,"mc":[{"id":"1.195453755","rc":[{"atl":[[280,5.52]],"id":522753}],"con":true,"img":false}]}
{"op":"mcm","clk":"5348311501","pt":1646216381346,"mc":[{"id":"1.195453755","rc":[{"atl":[[290,0]],"id":522753}],"con":true,"img":false}]}
{"op":"mcm","clk":"5348311521","pt":1646216381553,"mc":[{"id":"1.195453755","rc":[{"atl":[[70,22.63],[110,2]],"id":3805746},{"atb":[[1.71,0],[1.35,79.74]],"id":3805793},{"atb":[[5.5,0],[6.8,17.24]],"id":3805731},{"atb":[[23,0],[29,8.32]],"id":522743},{"atb":[[9.8,30.27],[12.5,8.7]],"id":522745}],"con":true,"img":false}]}
{"op":"mcm","clk":"5348311558","pt":1646216381867,"mc":[{"id":"1.195453755","rc":[{"atl":[[230,2]],"id":522752}],"con":true,"img":false}]}
{"op":"mcm","clk":"5348311597","pt":1646216382128,"mc":[{"id":"1.195453755","rc":[{"atl":[[170,9.92]],"id":522752}],"con":true,"img":false}]}
{"op":"mcm","clk":"5348311625","pt":1646216382440,"mc":[{"id":"1.195453755","rc":[{"atl":[[170,9.92],[250,2]],"id":522750}],"con":true,"img":false}]}
{"op":"mcm","clk":"5348311655","pt":1646216382652,"mc":[{"id":"1.195453755","rc":[{"atl":[[24,11.84]],"id":3805755}],"con":true,"img":false}]}
{"op":"mcm","clk":"5348311868","pt":1646216384434,"mc":[{"id":"1.195453755","rc":[{"atl":[[50,22.08]],"id":3805755}],"con":true,"img":false}]}
{"op":"mcm","clk":"5348311956","pt":1646216385325,"mc":[{"id":"1.195453755","rc":[{"atb":[[11.5,38.91]],"id":3805730}],"con":true,"img":false}]}
{"op":"mcm","clk":"5348311966","pt":1646216385426,"mc":[{"id":"1.195453755","rc":[{"atb":[[12,9.9]],"id":3805730}],"con":true,"img":false}]}
{"op":"mcm","clk":"5348311975","pt":1646216385530,"mc":[{"id":"1.195453755","rc":[{"atl":[[300,5.65]],"id":522753}],"con":true,"img":false}]}
{"op":"mcm","clk":"5348312014","pt":1646216385847,"mc":[{"id":"1.195453755","rc":[{"atl":[[42,39.36]],"id":3805731}],"con":true,"img":false}]}
{"op":"mcm","clk":"5348312294","pt":1646216388568,"mc":[{"id":"1.195453755","rc":[{"atl":[[170,0],[230,9.41]],"id":522752}],"con":true,"img":false}]}
{"op":"mcm","clk":"5348312311","pt":1646216388665,"mc":[{"id":"1.195453755","rc":[{"atl":[[170,0],[250,8.81]],"id":522750}],"con":true,"img":false}]}
{"op":"mcm","clk":"5348312458","pt":1646216389942,"mc":[{"id":"1.195453755","rc":[{"atb":[[2.72,0]],"id":3805793}],"con":true,"img":false}]}
{"op":"mcm","clk":"5348312510","pt":1646216390468,"mc":[{"id":"1.195453755","rc":[{"atb":[[2.68,78.94],[2.7,3.26]],"id":3805793}],"con":true,"img":false}]}
{"op":"mcm","clk":"5348312640","pt":1646216391674,"mc":[{"id":"1.195453755","rc":[{"atl":[[780,4.19]],"id":522753}],"con":true,"img":false}]}
{"op":"mcm","clk":"5348312648","pt":1646216391778,"mc":[{"id":"1.195453755","rc":[{"atl":[[300,0]],"id":522753}],"con":true,"img":false}]}
{"op":"mcm","clk":"5348312660","pt":1646216391885,"mc":[{"id":"1.195453755","rc":[{"atl":[[150,9.9],[110,4.95]],"id":522746},{"atl":[[280,0.56]],"id":522753}],"con":true,"img":false}]}
{"op":"mcm","clk":"5348312667","pt":1646216391937,"mc":[{"id":"1.195453755","rc":[{"atl":[[140,0],[100,1.6]],"id":522746},{"atl":[[290,4.95]],"id":522753}],"con":true,"img":false}]}
{"op":"mcm","clk":"5348312694","pt":1646216392147,"mc":[{"id":"1.195453755","rc":[{"atl":[[930,3.83]],"id":522743}],"con":true,"img":false}]}
{"op":"mcm","clk":"5348312716","pt":1646216392357,"mc":[{"id":"1.195453755","rc":[{"atl":[[280,2],[140,12.26]],"id":522746},{"atb":[[17,9.9],[17.5,4.95],[15,36.81],[15.5,12.63]],"id":3805762},{"atl":[[780,2]],"id":522753}],"con":true,"img":false}]}
{"op":"mcm","clk":"5348312739","pt":1646216392567,"mc":[{"id":"1.195453755","rc":[{"atb":[[13,0],[13.5,9.9],[15,11.32],[15.5,4.95]],"id":3805731}],"con":true,"img":false}]}
{"op":"mcm","clk":"5348312777","pt":1646216392885,"mc":[{"id":"1.195453755","rc":[{"atl":[[3.7,58.51],[3.55,4.95],[3.9,0],[3.75,9.9]],"id":3805793},{"atb":[[18,9.32],[15,0],[15.5,35.77]],"id":3805762}],"con":true,"img":false}]}
{"op":"mcm","clk":"5348312785","pt":1646216392938,"mc":[{"id":"1.195453755","rc":[{"atb":[[34,0],[42,0]],"id":522750}],"con":true,"img":false}]}
{"op":"mcm","clk":"5348312801","pt":1646216393051,"mc":[{"id":"1.195453755","rc":[{"atb":[[40,25.47],[48,4.95]],"id":522750},{"atb":[[12,2.72],[13.5,31.99],[15.5,15.88]],"id":3805731}],"con":true,"img":false}]}
{"op":"mcm","clk":"5348312843","pt":1646216393420,"mc":[{"id":"1.195453755","rc":[{"atl":[[3.95,0],[3.5,22.08],[3.75,31.99]],"id":3805793}],"con":true,"img":false}]}
{"op":"mcm","clk":"5348312847","pt":1646216393467,"mc":[{"id":"1.195453755","rc":[{"atb":[[40,12.63],[30,21.16]],"id":522750}],"con":true,"img":false}]}
{"op":"mcm","clk":"5348312860","pt":1646216393576,"mc":[{"id":"1.195453755","rc":[{"atb":[[50,3.23]],"id":522750},{"atb":[[17,0]],"id":3805762}],"con":true,"img":false}]}
{"op":"mcm","clk":"5348312886","pt":1646216393842,"mc":[{"id":"1.195453755","rc":[{"atb":[[15,0]],"id":3805731}],"con":true,"img":false}]}
{"op":"mcm","clk":"5348312925","pt":1646216394267,"mc":[{"id":"1.195453755","rc":[{"atl":[[3.7,0]],"id":3805793}],"con":true,"img":false}]}
{"op":"mcm","clk":"5348312939","pt":1646216394377,"mc":[{"id":"1.195453755","rc":[{"atb":[[44,0]],"id":522750}],"con":true,"img":false}]}
{"op":"mcm","clk":"5348312979","pt":1646216394747,"mc":[{"id":"1.195453755","rc":[{"atl":[[170,10.13],[230,2]],"id":522752}],"con":true,"img":false}]}
{"op":"mcm","clk":"5348313004","pt":1646216395058,"mc":[{"id":"1.195453755","rc":[{"atl":[[170,10.14],[250,2]],"id":522750}],"con":true,"img":false}]}
{"op":"mcm","clk":"5348313159","pt":1646216396576,"mc":[{"id":"1.195453755","rc":[{"atb":[[5.8,0],[6.6,17.86]],"id":3805755},{"atb":[[19,0]],"id":522752},{"atb":[[29,3.57]],"id":522742}],"con":true,"img":false}]}
{"op":"mcm","clk":"5348313171","pt":1646216396683,"mc":[{"id":"1.195453755","rc":[{"atb":[[25,4.17]],"id":522752},{"atb":[[23,0]],"id":522742}],"con":true,"img":false}]}
{"op":"mcm","clk":"5348313332","pt":1646216397951,"mc":[{"id":"1.195453755","rc":[{"atl":[[780,4.21]],"id":522753}],"con":true,"img":false}]}
{"op":"mcm","clk":"5348313457","pt":1646216399061,"mc":[{"id":"1.195453755","rc":[{"atb":[[12,33.7],[13.5,9.9]],"id":3805731}],"con":true,"img":false}]}
{"op":"mcm","clk":"5348313629","pt":1646216400654,"mc":[{"id":"1.195453755","rc":[{"atl":[[170,0]],"id":522752}],"con":true,"img":false}]}
{"op":"mcm","clk":"5348313662","pt":1646216400973,"mc":[{"id":"1.195453755","rc":[{"atl":[[170,0],[250,8.95]],"id":522750},{"atl":[[230,9.56]],"id":522752}],"con":true,"img":false}]}
{"op":"mcm","clk":"5348314006","pt":1646216404397,"mc":[{"id":"1.195453755","rc":[{"atl":[[280,5.52],[290,0]],"id":522753}],"con":true,"img":false}]}
{"op":"mcm","clk":"5348314065","pt":1646216404871,"mc":[{"id":"1.195453755","rc":[{"atl":[[300,5.83],[780,2]],"id":522753}],"con":true,"img":false}]}
{"op":"mcm","clk":"5348314086","pt":1646216405084,"mc":[{"id":"1.195453755","rc":[{"atl":[[280,0.56],[290,4.95]],"id":522753}],"con":true,"img":false}]}
{"op":"mcm","clk":"5348314142","pt":1646216405605,"mc":[{"id":"1.195453755","rc":[{"atl":[[300,0]],"id":522753}],"con":true,"img":false}]}
{"op":"mcm","clk":"5348314151","pt":1646216405659,"mc":[{"id":"1.195453755","rc":[{"atb":[[40,30.53],[30,3.26]],"id":522750}],"con":true,"img":false}]}
{"op":"mcm","clk":"5348314168","pt":1646216405867,"mc":[{"id":"1.195453755","rc":[{"atl":[[24,0],[25,4.95],[28,0],[29,9.9]],"id":3805755}],"con":true,"img":false}]}
{"op":"mcm","clk":"5348314233","pt":1646216406561,"mc":[{"id":"1.195453755","rc":[{"atl":[[48,3.37]],"id":3805755}],"con":true,"img":false}]}
{"op":"mcm","clk":"5348314271","pt":1646216406980,"mc":[{"id":"1.195453755","rc":[{"atl":[[48,25.46],[50,0]],"id":3805755},{"atl":[[170,10.34],[230,2]],"id":522752}],"con":true,"img":false}]}
{"op":"mcm","clk":"5348314301","pt":1646216407292,"mc":[{"id":"1.195453755","rc":[{"atl":[[170,10.34],[250,2]],"id":522750}],"con":true,"img":false}]}
{"op":"mcm","clk":"5348314396","pt":1646216408191,"mc":[{"id":"1.195453755","rc":[{"atl":[[170,0]],"id":522750}],"con":true,"img":false}]}
{"op":"mcm","clk":"5348314589","pt":1646216410170,"mc":[{"id":"1.195453755","rc":[{"atl":[[780,4.25]],"id":522753}],"con":true,"img":false}]}
{"op":"mcm","clk":"5348314918","pt":1646216413123,"mc":[{"id":"1.195453755","rc":[{"atl":[[170,10.44]],"id":522750},{"atl":[[170,0],[230,9.71]],"id":522752}],"con":true,"img":false}]}
{"op":"mcm","clk":"5348315084","pt":1646216414596,"mc":[{"id":"1.195453755","rc":[{"atl":[[24,4.95],[25,0],[28,9.9],[29,0]],"id":3805755}],"con":true,"img":false}]}
{"op":"mcm","clk":"5348315369","pt":1646216417587,"mc":[{"id":"1.195453755","rc":[{"atb":[[16,4.95],[13.5,0],[14,9.9],[15.5,10.93]],"id":3805740}],"con":true,"img":false}]}
{"op":"mcm","clk":"5348315390","pt":1646216417796,"mc":[{"id":"1.195453755","rc":[{"atb":[[6.4,0],[7.4,0]],"id":3805746}],"con":true,"img":false}]}
{"op":"mcm","clk":"5348315418","pt":1646216418005,"mc":[{"id":"1.195453755","rc":[{"atb":[[16,15.52],[9.4,11.9]],"id":3805740}],"con":true,"img":false}]}
{"op":"mcm","clk":"5348315434","pt":1646216418109,"mc":[{"id":"1.195453755","rc":[{"atb":[[14,32.23]],"id":3805740}],"con":true,"img":false}]}
{"op":"mcm","clk":"5348315450","pt":1646216418316,"mc":[{"id":"1.195453755","rc":[{"atb":[[5.3,90.84]],"id":3805746}],"con":true,"img":false}]}
{"op":"mcm","clk":"5348315460","pt":1646216418418,"mc":[{"id":"1.195453755","rc":[{"atb":[[6.2,35.44]],"id":3805746}],"con":true,"img":false}]}
{"op":"mcm","clk":"5348315477","pt":1646216418579,"mc":[{"id":"1.195453755","rc":[{"atb":[[7.6,2.72],[6.6,3.26]],"id":3805746},{"atl":[[24,11.84]],"id":3805755}],"con":true,"img":false}]}
{"op":"mcm","clk":"5348315497","pt":1646216418785,"mc":[{"id":"1.195453755","rc":[{"atb":[[15.5,0]],"id":3805740}],"con":true,"img":false}]}
{"op":"mcm","clk":"5348315521","pt":1646216419098,"mc":[{"id":"1.195453755","rc":[{"atb":[[5.3,30.97]],"id":3805746},{"atl":[[170,0],[250,9.16]],"id":522750},{"atl":[[170,10.54],[230,2]],"id":522752}],"con":true,"img":false}]}
{"op":"mcm","clk":"5348315556","pt":1646216419511,"mc":[{"id":"1.195453755","rc":[{"atl":[[48,22.08]],"id":3805755}],"con":true,"img":false}]}
{"op":"mcm","clk":"5348315618","pt":1646216420083,"mc":[{"id":"1.195453755","rc":[{"atl":[[170,0]],"id":522752}],"con":true,"img":false}]}
{"op":"mcm","clk":"5348315785","pt":1646216421806,"mc":[{"id":"1.195453755","rc":[{"atb":[[85,0],[110,1.45]],"id":522741}],"con":true,"img":false}]}
{"op":"mcm","clk":"5348315803","pt":1646216422015,"mc":[{"id":"1.195453755","rc":[{"atb":[[90,9.9],[120,4.95]],"id":522741}],"con":true,"img":false}]}
{"op":"mcm","clk":"5348315837","pt":1646216422278,"mc":[{"id":"1.195453755","rc":[{"atb":[[27,15.13],[29,2.72]],"id":522741}],"con":true,"img":false}]}
{"op":"mcm","clk":"5348315865","pt":1646216422590,"mc":[{"id":"1.195453755","rc":[{"atb":[[120,6.28]],"id":522741}],"con":true,"img":false}]}
{"op":"mcm","clk":"5348315929","pt":1646216423319,"mc":[{"id":"1.195453755","rc":[{"atb":[[27,3.85]],"id":522741}],"con":true,"img":false}]}
{"op":"mcm","clk":"5348315941","pt":1646216423423,"mc":[{"id":"1.195453755","rc":[{"atl":[[140,4.95],[180,9.9]],"id":522752}],"con":true,"img":false}]}
{"op":"mcm","clk":"5348315951","pt":1646216423478,"mc":[{"id":"1.195453755","rc":[{"atl":[[23,4.95],[24,0],[27,31.54],[28,0]],"id":3805783},{"atl":[[150,1.06]],"id":522752},{"atb":[[110,0]],"id":522741}],"con":true,"img":false}]}
{"op":"mcm","clk":"5348315982","pt":1646216423790,"mc":[{"id":"1.195453755","rc":[{"atb":[[14,9.9]],"id":3805740}],"con":true,"img":false}]}
{"op":"mcm","clk":"5348315990","pt":1646216423893,"mc":[{"id":"1.195453755","rc":[{"atl":[[23,12.15]],"id":3805783},{"atl":[[140,6.09]],"id":522752},{"atb":[[9.4,52.65]],"id":3805740}],"con":true,"img":false}]}
{"op":"mcm","clk":"5348316063","pt":1646216424685,"mc":[{"id":"1.195453755","rc":[{"atl":[[150,0]],"id":522752}],"con":true,"img":false}]}
{"op":"mcm","clk":"5348316074","pt":1646216424790,"mc":[{"id":"1.195453755","rc":[{"atl":[[26,0]],"id":3805783}],"con":true,"img":false}]}
{"op":"mcm","clk":"5348316092","pt":1646216425012,"mc":[{"id":"1.195453755","rc":[{"atl":[[170,10.64],[250,2]],"id":522750},{"atl":[[180,19.95]],"id":522752}],"con":true,"img":false}]}
{"op":"mcm","clk":"5348316102","pt":1646216425105,"mc":[{"id":"1.195453755","rc":[{"atb":[[34,20.84],[36,9.9],[42,0],[44,8.64]],"id":522746},{"atl":[[32,9.46],[34,0],[40,9.9],[42,29.45]],"id":3805731}],"con":true,"img":false}]}
{"op":"mcm","clk":"5348316127","pt":1646216425317,"mc":[{"id":"1.195453755","rc":[{"atl":[[46,32.51],[27,9.9]],"id":3805783}],"con":true,"img":false}]}
{"op":"mcm","clk":"5348316226","pt":1646216426316,"mc":[{"id":"1.195453755","rc":[{"atb":[[85,9.9],[90,0],[110,4.95],[120,0]],"id":522741},{"atb":[[16,0],[13.5,9.9],[14,0],[15.5,4.95]],"id":3805740}],"con":true,"img":false}]}
{"op":"mcm","clk":"5348316239","pt":1646216426422,"mc":[{"id":"1.195453755","rc":[{"atl":[[24,0],[25,4.95],[28,0],[29,9.9]],"id":3805755}],"con":true,"img":false}]}
{"op":"mcm","clk":"5348316313","pt":1646216427160,"mc":[{"id":"1.195453755","rc":[{"atb":[[110,6.4]],"id":522741},{"atb":[[14,12.19]],"id":3805740}],"con":true,"img":false}]}
{"op":"mcm","clk":"5348316337","pt":1646216427317,"mc":[{"id":"1.195453755","rc":[{"atl":[[46,3.52]],"id":3805755}],"con":true,"img":false}]}
{"op":"mcm","clk":"5348316403","pt":1646216427792,"mc":[{"id":"1.195453755","rc":[{"atl":[[46,25.6],[48,0]],"id":3805755},{"atb":[[13.5,0],[15.5,0]],"id":3805731}],"con":true,"img":false}]}
{"op":"mcm","clk":"5348316425","pt":1646216428014,"mc":[{"id":"1.195453755","rc":[{"atb":[[13,9.9],[15,4.95]],"id":3805731}],"con":true,"img":false}]}
{"op":"mcm","clk":"5348316456","pt":1646216428317,"mc":[{"id":"1.195453755","rc":[{"atb":[[8.2,60.72],[12,2.72]],"id":3805731}],"con":true,"img":false}]}
{"op":"mcm","clk":"5348316486","pt":1646216428583,"mc":[{"id":"1.195453755","rc":[{"atb":[[13.5,12.68]],"id":3805731}],"con":true,"img":false}]}
{"op":"mcm","clk":"5348316546","pt":1646216429103,"mc":[{"id":"1.195453755","rc":[{"atb":[[8.2,18.49]],"id":3805731}],"con":true,"img":false}]}
{"op":"mcm","clk":"5348316621","pt":1646216429887,"mc":[{"id":"1.195453755","rc":[{"atb":[[13.5,32.23],[15.5,15.88],[9.4,11.9]],"id":3805740}],"con":true,"img":false}]}
{"op":"mcm","clk":"5348316631","pt":1646216429993,"mc":[{"id":"1.195453755","rc":[{"atb":[[6.2,76.39]],"id":3805746}],"con":true,"img":false}]}
{"op":"mcm","clk":"5348316694","pt":1646216430619,"mc":[{"id":"1.195453755","rc":[{"atl":[[25,11.55]],"id":3805755}],"con":true,"img":false}]}
{"op":"mcm","clk":"5348316704","pt":1646216430723,"mc":[{"id":"1.195453755","rc":[{"atl":[[170,0],[250,9.29]],"id":522750},{"atl":[[180,9.9],[230,9.93]],"id":522752},{"atb":[[14,0]],"id":3805740}],"con":true,"img":false}]}
{"op":"mcm","clk":"5348316808","pt":1646216431766,"mc":[{"id":"1.195453755","rc":[{"atl":[[46,22.08]],"id":3805755}],"con":true,"img":false}]}
{"op":"mcm","clk":"5348316966","pt":1646216433230,"mc":[{"id":"1.195453755","rc":[{"atl":[[270,4.95]],"id":522753}],"con":true,"img":false}]}
{"op":"mcm","clk":"5348316978","pt":1646216433285,"mc":[{"id":"1.195453755","rc":[{"atl":[[290,0]],"id":522753}],"con":true,"img":false}]}
{"op":"mcm","clk":"5348317021","pt":1646216433703,"mc":[{"id":"1.195453755","rc":[{"atl":[[260,0.61],[290,6.31],[780,2]],"id":522753}],"con":true,"img":false}]}
{"op":"mcm","clk":"5348317051","pt":1646216434016,"mc":[{"id":"1.195453755","rc":[{"atb":[[29,15.64]],"id":522741}],"con":true,"img":false}]}
{"op":"mcm","clk":"5348317099","pt":1646216434491,"mc":[{"id":"1.195453755","rc":[{"atl":[[280,0],[290,0]],"id":522753}],"con":true,"img":false}]}
{"op":"mcm","clk":"5348317178","pt":1646216435321,"mc":[{"id":"1.195453755","rc":[{"atb":[[17,4.95]],"id":3805784}],"con":true,"img":false}]}
{"op":"mcm","clk":"5348317186","pt":1646216435425,"mc":[{"id":"1.195453755","rc":[{"atb":[[17.5,0],[15.5,0]],"id":3805784}],"con":true,"img":false}]}
{"op":"mcm","clk":"5348317209","pt":1646216435636,"mc":[{"id":"1.195453755","rc":[{"atb":[[13.5,9.9],[9.4,53.2]],"id":3805740}],"con":true,"img":false}]}
{"op":"mcm","clk":"5348317242","pt":1646216435900,"mc":[{"id":"1.195453755","rc":[{"atb":[[16,2.72],[17,21.7]],"id":3805784}],"con":true,"img":false}]}
{"op":"mcm","clk":"5348317267","pt":1646216436211,"mc":[{"id":"1.195453755","rc":[{"atb":[[15,9.9]],"id":3805784}],"con":true,"img":false}]}
{"op":"mcm","clk":"5348317313","pt":1646216436630,"mc":[{"id":"1.195453755","rc":[{"atl":[[170,10.83],[250,2]],"id":522750},{"atb":[[13,9.9],[13.5,0],[15,4.95],[15.5,0]],"id":3805740}],"con":true,"img":false}]}
{"op":"mcm","clk":"5348317391","pt":1646216437308,"mc":[{"id":"1.195453755","rc":[{"atb":[[9.6,14.71]],"id":3805740}],"con":true,"img":false}]}
{"op":"mcm","clk":"5348317400","pt":1646216437413,"mc":[{"id":"1.195453755","rc":[{"atl":[[170,0]],"id":522750}],"con":true,"img":false}]}
{"op":"mcm","clk":"5348317566","pt":1646216438729,"mc":[{"id":"1.195453755","rc":[{"atl":[[16,9.9],[14,4.95]],"id":3805746},{"atb":[[15,16.27]],"id":3805740}],"con":true,"img":false}]}
{"op":"mcm","clk":"5348317577","pt":1646216438835,"mc":[{"id":"1.195453755","rc":[{"atl":[[13.5,0],[15.5,0]],"id":3805746},{"atb":[[140,0]],"id":522749}],"con":true,"img":false}]}
{"op":"mcm","clk":"5348317644","pt":1646216439209,"mc":[{"id":"1.195453755","rc":[{"atl":[[15.5,22.08]],"id":3805746}],"con":true,"img":false}]}
{"op":"mcm","clk":"5348317659","pt":1646216439311,"mc":[{"id":"1.195453755","rc":[{"atl":[[70,0]],"id":3805746},{"atb":[[95,9.9],[46,13.23]],"id":522749}],"con":true,"img":false}]}
{"op":"mcm","clk":"5348317690","pt":1646216439527,"mc":[{"id":"1.195453755","rc":[{"atb":[[130,6.18]],"id":522749}],"con":true,"img":false}]}
{"op":"mcm","clk":"5348317705","pt":1646216439632,"mc":[{"id":"1.195453755","rc":[{"atl":[[65,2.47]],"id":3805746},{"atb":[[9.6,0]],"id":3805740}],"con":true,"img":false}]}
{"op":"mcm","clk":"5348317718","pt":1646216439742,"mc":[{"id":"1.195453755","rc":[{"atb":[[8,14.29],[9.4,41.3]],"id":3805740}],"con":true,"img":false}]}
{"op":"mcm","clk":"5348317747","pt":1646216439949,"mc":[{"id":"1.195453755","rc":[{"atb":[[13,39.36]],"id":3805731}],"con":true,"img":false}]}
{"op":"mcm","clk":"5348317759","pt":1646216440056,"mc":[{"id":"1.195453755","rc":[{"atl":[[15.5,0]],"id":3805746},{"atb":[[2.6,0],[2.62,9.9],[2.68,73.98],[2.7,8.22]],"id":3805793},{"atl":[[140,22.17],[150,0],[100,6.55],[110,0]],"id":522746},{"atl":[[22,4.95],[23,0],[26,39.36],[27,0]],"id":3805736},{"atl":[[280,4.95],[290,0]],"id":522741}],"con":true,"img":false}]}
{"op":"mcm","clk":"5348317782","pt":1646216440215,"mc":[{"id":"1.195453755","rc":[{"atb":[[15,16.27]],"id":3805731},{"atl":[[800,2],[850,1.73]],"id":522741}],"con":true,"img":false}]}
{"op":"mcm","clk":"5348317813","pt":1646216440527,"mc":[{"id":"1.195453755","rc":[{"atl":[[140,9.9],[280,8.61]],"id":522746}],"con":true,"img":false}]}
{"op":"mcm","clk":"5348317853","pt":1646216440838,"mc":[{"id":"1.195453755","rc":[{"atl":[[800,4.31],[850,0]],"id":522741}],"con":true,"img":false}]}
{"op":"mcm","clk":"5348317862","pt":1646216440944,"mc":[{"id":"1.195453755","rc":[{"atb":[[13.5,0]],"id":3805731}],"con":true,"img":false}]}
{"op":"mcm","clk":"5348317924","pt":1646216441465,"mc":[{"id":"1.195453755","rc":[{"atb":[[17,4.95]],"id":3805784}],"con":true,"img":false}]}
{"op":"mcm","clk":"5348317935","pt":1646216441534,"mc":[{"id":"1.195453755","rc":[{"atb":[[16,25.96]],"id":3805784}],"con":true,"img":false}]}
{"op":"mcm","clk":"5348318015","pt":1646216442306,"mc":[{"id":"1.195453755","rc":[{"atl":[[170,10.92]],"id":522750}],"con":true,"img":false}]}
{"op":"mcm","clk":"5348318163","pt":1646216443819,"mc":[{"id":"1.195453755","rc":[{"atb":[[17.5,0],[15.5,25.86]],"id":3805762}],"con":true,"img":false}]}
{"op":"mcm","clk":"5348318191","pt":1646216444026,"mc":[{"id":"1.195453755","rc":[{"atb":[[16,4.95],[13,29.45],[14,9.9],[15,11.32]],"id":3805731},{"atb":[[16,9.9],[18,14.27]],"id":3805762}],"con":true,"img":false}]}
{"op":"mcm","clk":"5348318221","pt":1646216444340,"mc":[{"id":"1.195453755","rc":[{"atb":[[13,25.53],[15.5,2.72]],"id":3805762}],"con":true,"img":false}]}
{"op":"mcm","clk":"5348318322","pt":1646216445329,"mc":[{"id":"1.195453755","rc":[{"atl":[[780,4.38]],"id":522753}],"con":true,"img":false}]}
{"op":"mcm","clk":"5348318379","pt":1646216446016,"mc":[{"id":"1.195453755","rc":[{"atl":[[650,2],[720,0]],"id":522749}],"con":true,"img":false}]}
{"op":"mcm","clk":"5348318530","pt":1646216447811,"mc":[{"id":"1.195453755","rc":[{"atl":[[250,9.49]],"id":522750}],"con":true,"img":false}]}
{"op":"mcm","clk":"5348318538","pt":1646216447918,"mc":[{"id":"1.195453755","rc":[{"atl":[[170,0]],"id":522750}],"con":true,"img":false}]}
{"op":"mcm","clk":"5348318596","pt":1646216448638,"mc":[{"id":"1.195453755","rc":[{"atl":[[250,2]],"id":522750}],"con":true,"img":false}]}
{"op":"mcm","clk":"5348318770","pt":1646216450626,"mc":[{"id":"1.195453755","rc":[{"atl":[[65,14.69]],"id":3805746}],"con":true,"img":false}]}
{"op":"mcm","clk":"5348318804","pt":1646216451035,"mc":[{"id":"1.195453755","rc":[{"atl":[[14,17.15]],"id":3805746}],"con":true,"img":false}]}
{"op":"mcm","clk":"5348318827","pt":1646216451345,"mc":[{"id":"1.195453755","rc":[{"atb":[[13,0],[14,39.36]],"id":3805731}],"con":true,"img":false}]}
{"op":"mcm","clk":"5348318841","pt":1646216451552,"mc":[{"id":"1.195453755","rc":[{"atb":[[16,15.52]],"id":3805731}],"con":true,"img":false}]}
{"op":"mcm","clk":"5348318868","pt":1646216451863,"mc":[{"id":"1.195453755","rc":[{"atl":[[65,12.21]],"id":3805746}],"con":true,"img":false}]}
{"op":"mcm","clk":"5348318914","pt":1646216452439,"mc":[{"id":"1.195453755","rc":[{"atb":[[15,0]],"id":3805731}],"con":true,"img":false}]}
{"op":"mcm","clk":"5348318996","pt":1646216453631,"mc":[{"id":"1.195453755","rc":[{"atl":[[170,11.11]],"id":522750}],"con":true,"img":false}]}
{"op":"mcm","clk":"5348319131","pt":1646216455553,"mc":[{"id":"1.195453755","rc":[{"atb":[[15.5,25.86]],"id":3805762}],"con":true,"img":false}]}
{"op":"mcm","clk":"5348319137","pt":1646216455659,"mc":[{"id":"1.195453755","rc":[{"atb":[[13,3.26]],"id":3805762}],"con":true,"img":false}]}
{"op":"mcm","clk":"5348319236","pt":1646216456853,"mc":[{"id":"1.195453755","rc":[{"atb":[[12,40.51],[14,9.9]],"id":3805731}],"con":true,"img":false}]}
{"op":"mcm","clk":"5348319419","pt":1646216459050,"mc":[{"id":"1.195453755","rc":[{"atl":[[170,0],[250,9.61]],"id":522750}],"con":true,"img":false}]}
{"op":"mcm","clk":"5348320013","pt":1646216464843,"mc":[{"id":"1.195453755","rc":[{"atl":[[170,11.3],[250,2]],"id":522750}],"con":true,"img":false}]}
{"op":"mcm","clk":"5348320594","pt":1646216470146,"mc":[{"id":"1.195453755","rc":[{"atl":[[170,0],[250,9.74]],"id":522750}],"con":true,"img":false}]}
{"op":"mcm","clk":"5348320678","pt":1646216471039,"mc":[{"id":"1.195453755","rc":[{"atl":[[250,2]],"id":522750}],"con":true,"img":false}]}
{"op":"mcm","clk":"5348320907","pt":1646216473340,"mc":[{"id":"1.195453755","rc":[{"atl":[[130,4.95],[140,1.13],[170,9.9],[180,0]],"id":522752}],"con":true,"img":false}]}
{"op":"mcm","clk":"5348320927","pt":1646216473544,"mc":[{"id":"1.195453755","rc":[{"atb":[[14.5,14.46]],"id":3805783}],"con":true,"img":false}]}
{"op":"mcm","clk":"5348320956","pt":1646216473856,"mc":[{"id":"1.195453755","rc":[{"atl":[[130,6.18],[170,21.36],[230,2]],"id":522752}],"con":true,"img":false}]}
{"op":"mcm","clk":"5348321036","pt":1646216474744,"mc":[{"id":"1.195453755","rc":[{"atl":[[140,0]],"id":522752}],"con":true,"img":false}]}
{"op":"mcm","clk":"5348321140","pt":1646216475785,"mc":[{"id":"1.195453755","rc":[{"atl":[[170,11.48]],"id":522750}],"con":true,"img":false}]}
{"op":"mcm","clk":"5348321454","pt":1646216479077,"mc":[{"id":"1.195453755","rc":[{"atl":[[170,9.9],[230,10.52]],"id":522752}],"con":true,"img":false}]}
{"op":"mcm","clk":"5348321638","pt":1646216480958,"mc":[{"id":"1.195453755","rc":[{"atl":[[250,9.86]],"id":522750}],"con":true,"img":false}]}
{"op":"mcm","clk":"5348321647","pt":1646216481065,"mc":[{"id":"1.195453755","rc":[{"atl":[[170,0]],"id":522750}],"con":true,"img":false}]}
{"op":"mcm","clk":"5348321726","pt":1646216481848,"mc":[{"id":"1.195453755","rc":[{"atl":[[250,2]],"id":522750}],"con":true,"img":false}]}
{"op":"mcm","clk":"5348321958","pt":1646216484088,"mc":[{"id":"1.195453755","rc":[{"atl":[[16,0],[13.5,4.95],[14,12.19],[15.5,9.9]],"id":3805746}],"con":true,"img":false}]}
{"op":"mcm","clk":"5348322000","pt":1646216484561,"mc":[{"id":"1.195453755","rc":[{"atl":[[65,0],[13.5,17.63],[15.5,31.99]],"id":3805746},{"atl":[[24,4.95],[28,9.9]],"id":3805755}],"con":true,"img":false}]}
{"op":"mcm","clk":"5348322008","pt":1646216484660,"mc":[{"id":"1.195453755","rc":[{"atl":[[25,6.6],[29,0]],"id":3805755}],"con":true,"img":false}]}
{"op":"mcm","clk":"5348322017","pt":1646216484766,"mc":[{"id":"1.195453755","rc":[{"atb":[[8.4,0],[9.4,11.9]],"id":3805784}],"con":true,"img":false}]}
{"op":"mcm","clk":"5348322047","pt":1646216485081,"mc":[{"id":"1.195453755","rc":[{"atl":[[46,0],[24,11.84],[28,41.81]],"id":3805755}],"con":true,"img":false}]}
{"op":"mcm","clk":"5348322073","pt":1646216485349,"mc":[{"id":"1.195453755","rc":[{"atl":[[14,0]],"id":3805746}],"con":true,"img":false}]}
{"op":"mcm","clk":"5348322136","pt":1646216485976,"mc":[{"id":"1.195453755","rc":[{"atl":[[25,0]],"id":3805755}],"con":true,"img":false}]}
{"op":"mcm","clk":"5348322180","pt":1646216486442,"mc":[{"id":"1.195453755","rc":[{"atl":[[170,11.66]],"id":522750}],"con":true,"img":false}]}
{"op":"mcm","clk":"5348322199","pt":1646216486668,"mc":[{"id":"1.195453755","rc":[{"atl":[[24,4.95],[25,4.95],[29,9.9]],"id":3805755}],"con":true,"img":false}]}
{"op":"mcm","clk":"5348322207","pt":1646216486757,"mc":[{"id":"1.195453755","rc":[{"atl":[[24,0],[28,31.9]],"id":3805755}],"con":true,"img":false}]}
{"op":"mcm","clk":"5348322258","pt":1646216487403,"mc":[{"id":"1.195453755","rc":[{"atl":[[28,37.77]],"id":3805755}],"con":true,"img":false}]}
{"op":"mcm","clk":"5348322300","pt":1646216487944,"mc":[{"id":"1.195453755","rc":[{"atl":[[16,9.9],[13.5,0],[14,4.95],[15.5,22.08]],"id":3805746},{"atl":[[25,0],[26,4.95],[29,0],[30,9.9]],"id":3805755},{"atl":[[150,0],[160,4.95],[200,9.9]],"id":522750},{"atb":[[85,0],[90,9.9],[110,1.45],[120,4.95]],"id":522741},{"atb":[[12.5,9.9],[13,0],[14.5,4.95],[15,0]],"id":3805740}],"con":true,"img":false}]}
{"op":"mcm","clk":"5348322351","pt":1646216488387,"mc":[{"id":"1.195453755","rc":[{"atb":[[90,23.66],[29,2.72],[120,6.28]],"id":522741}],"con":true,"img":false}]}
{"op":"mcm","clk":"5348322366","pt":1646216488594,"mc":[{"id":"1.195453755","rc":[{"atl":[[15,11.32]],"id":3805746},{"atl":[[160,5.95]],"id":522750},{"atb":[[13,13.21]],"id":3805740}],"con":true,"img":false}]}
{"op":"mcm","clk":"5348322404","pt":1646216489068,"mc":[{"id":"1.195453755","rc":[{"atb":[[12.5,32.23]],"id":3805740}],"con":true,"img":false}]}
{"op":"mcm","clk":"5348322411","pt":1646216489169,"mc":[{"id":"1.195453755","rc":[{"atb":[[110,0]],"id":522741},{"atb":[[9.4,0]],"id":3805740}],"con":true,"img":false}]}
{"op":"mcm","clk":"5348322422","pt":1646216489276,"mc":[{"id":"1.195453755","rc":[{"atb":[[85,9.9],[90,13.76],[110,4.95],[120,0]],"id":522741},{"atb":[[12.5,22.32],[13,23.11],[14.5,0],[15,4.95]],"id":3805740}],"con":true,"img":false}]}
{"op":"mcm","clk":"5348322428","pt":1646216489382,"mc":[{"id":"1.195453755","rc":[{"atl":[[150,4.95],[160,0.99],[190,9.9],[200,0]],"id":522750}],"con":true,"img":false}]}
{"op":"mcm","clk":"5348322487","pt":1646216489973,"mc":[{"id":"1.195453755","rc":[{"atb":[[90,15.54]],"id":522741}],"con":true,"img":false}]}
{"op":"mcm","clk":"5348322506","pt":1646216490180,"mc":[{"id":"1.195453755","rc":[{"atl":[[28,5.86],[30,46.14]],"id":3805755}],"con":true,"img":false}]}
{"op":"mcm","clk":"5348322714","pt":1646216492492,"mc":[{"id":"1.195453755","rc":[{"atl":[[150,0],[160,5.95],[190,0]],"id":522750}],"con":true,"img":false}]}
{"op":"mcm","clk":"5348322765","pt":1646216492968,"mc":[{"id":"1.195453755","rc":[{"atl":[[170,0],[250,10]],"id":522750}],"con":true,"img":false}]}
{"op":"mcm","clk":"5348322776","pt":1646216493072,"mc":[{"id":"1.195453755","rc":[{"atb":[[12.5,32.23],[13,13.21],[14.5,4.95],[15,0]],"id":3805740}],"con":true,"img":false}]}
{"op":"mcm","clk":"5348322788","pt":1646216493175,"mc":[{"id":"1.195453755","rc":[{"atl":[[200,9.9]],"id":522750}],"con":true,"img":false}]}
{"op":"mcm","clk":"5348322802","pt":1646216493382,"mc":[{"id":"1.195453755","rc":[{"atb":[[85,24.62],[90,1.78]],"id":522741}],"con":true,"img":false}]}
{"op":"mcm","clk":"5348322959","pt":1646216495107,"mc":[{"id":"1.195453755","rc":[{"atl":[[14,17.15]],"id":3805746}],"con":true,"img":false}]}
{"op":"mcm","clk":"5348323017","pt":1646216495586,"mc":[{"id":"1.195453755","rc":[{"atl":[[26,11.29]],"id":3805755}],"con":true,"img":false}]}
{"op":"mcm","clk":"5348323051","pt":1646216495903,"mc":[{"id":"1.195453755","rc":[{"atl":[[15,0]],"id":3805746}],"con":true,"img":false}]}
{"op":"mcm","clk":"5348323099","pt":1646216496371,"mc":[{"id":"1.195453755","rc":[{"atl":[[16,50.12],[15.5,0]],"id":3805746},{"atl":[[28,0]],"id":3805755}],"con":true,"img":false}]}
{"op":"mcm","clk":"5348323110","pt":1646216496476,"mc":[{"id":"1.195453755","rc":[{"atl":[[650,0],[710,2]],"id":522749}],"con":true,"img":false}]}
{"op":"mcm","clk":"5348323135","pt":1646216496791,"mc":[{"id":"1.195453755","rc":[{"atb":[[9.6,21.16],[8,9.9],[8.6,3.26],[8.8,4.95],[7.8,19.57]],"id":3805747},{"atb":[[7.6,0],[6.6,0]],"id":3805746},{"atb":[[2.66,4.95],[2.62,0],[2.7,3.26]],"id":3805793},{"atl":[[3.7,9.9],[3.55,0],[3.5,27.04],[3.75,22.08]],"id":3805793},{"atb":[[40,20.62],[42,9.9],[48,0],[50,8.19]],"id":522750},{"atb":[[44,12.17],[46,9.9],[55,0],[60,7.64]],"id":522742},{"atb":[[85,0],[90,9.9],[110,1.45],[120,4.95]],"id":522745}],"con":true,"img":false}]}
{"op":"mcm","clk":"5348323154","pt":1646216497007,"mc":[{"id":"1.195453755","rc":[{"atl":[[55,38.6],[30,9.9]],"id":3805755}],"con":true,"img":false}]}
{"op":"mcm","clk":"5348323176","pt":1646216497165,"mc":[{"id":"1.195453755","rc":[{"atb":[[6.2,35.44],[5.3,102.51]],"id":3805746},{"atb":[[130,1.23]],"id":522745}],"con":true,"img":false}]}
{"op":"mcm","clk":"5348323185","pt":1646216497271,"mc":[{"id":"1.195453755","rc":[{"atb":[[8.6,44.22]],"id":3805747},{"atb":[[90,23.31],[55,2.72]],"id":522745}],"con":true,"img":false}]}
{"op":"mcm","clk":"5348323195","pt":1646216497374,"mc":[{"id":"1.195453755","rc":[{"atb":[[7.8,0]],"id":3805747}],"con":true,"img":false}]}
{"op":"mcm","clk":"5348323219","pt":1646216497583,"mc":[{"id":"1.195453755","rc":[{"atb":[[6.8,3.26],[7.8,2.72]],"id":3805746}],"con":true,"img":false}]}
{"op":"mcm","clk":"5348323253","pt":1646216497998,"mc":[{"id":"1.195453755","rc":[{"atb":[[110,0]],"id":522745}],"con":true,"img":false}]}
{"op":"mcm","clk":"5348323345","pt":1646216498886,"mc":[{"id":"1.195453755","rc":[{"atb":[[120,1.32]],"id":522741}],"con":true,"img":false}]}
{"op":"mcm","clk":"5348323408","pt":1646216499405,"mc":[{"id":"1.195453755","rc":[{"atb":[[85,9.9],[90,10.83]],"id":522741}],"con":true,"img":false}]}
{"op":"mcm","clk":"5348323443","pt":1646216499672,"mc":[{"id":"1.195453755","rc":[{"atb":[[90,9.05]],"id":522741}],"con":true,"img":false}]}
{"op":"mcm","clk":"5348323459","pt":1646216499878,"mc":[{"id":"1.195453755","rc":[{"atb":[[14.5,2.72]],"id":3805783},{"atl":[[22,4.95],[23,7.2],[26,9.9],[27,0]],"id":3805783},{"atb":[[2.66,0],[2.68,78.94]],"id":3805793},{"atb":[[10.5,0],[11,9.9],[12.5,0],[13,4.95]],"id":3805755},{"atl":[[23,12.15],[24,0],[27,9.9],[28,24.55]],"id":3805730},{"atb":[[130,0],[140,6.09],[95,12.82],[100,9.9]],"id":522743}],"con":true,"img":false}]}
{"op":"mcm","clk":"5348323471","pt":1646216499981,"mc":[{"id":"1.195453755","rc":[{"atb":[[17.5,4.95],[15.5,9.9]],"id":3805784},{"atl":[[270,0],[290,4.95]],"id":522753}],"con":true,"img":false}]}
{"op":"mcm","clk":"5348323480","pt":1646216500085,"mc":[{"id":"1.195453755","rc":[{"atb":[[17,0],[15,0]],"id":3805784},{"atl":[[270,0],[290,4.95]],"id":522745}],"con":true,"img":false}]}
{"op":"mcm","clk":"5348323506","pt":1646216500407,"mc":[{"id":"1.195453755","rc":[{"atl":[[22,12.5],[46,2.22],[26,32.82]],"id":3805783}],"con":true,"img":false}]}
{"op":"mcm","clk":"5348323516","pt":1646216500515,"mc":[{"id":"1.195453755","rc":[{"atb":[[16,2.72],[17,16.75]],"id":3805784}],"con":true,"img":false}]}
{"op":"mcm","clk":"5348323526","pt":1646216500574,"mc":[{"id":"1.195453755","rc":[{"atb":[[12,22.63]],"id":3805783},{"atb":[[2.56,9.9],[2.64,4.95],[2.68,73.98]],"id":3805793},{"atl":[[780,2.38],[850,2]],"id":522753}],"con":true,"img":false}]}
{"op":"mcm","clk":"5348323555","pt":1646216500890,"mc":[{"id":"1.195453755","rc":[{"atl":[[38,9.9],[29,0],[30,4.95]],"id":3805784},{"atl":[[270,4.95]],"id":522747},{"atb":[[44,9.9],[55,7.89]],"id":522752},{"atb":[[16,0],[18,9.32]],"id":3805762},{"atb":[[150,6.01],[110,9.9]],"id":522753},{"atl":[[300,0],[330,4.95]],"id":522743}],"con":true,"img":false}]}
{"op":"mcm","clk":"5348323565","pt":1646216500994,"mc":[{"id":"1.195453755","rc":[{"atl":[[260,0]],"id":522747},{"atb":[[42,20.82],[50,0]],"id":522752},{"atb":[[16.5,9.9],[18.5,4.95]],"id":3805762},{"atb":[[140,0],[100,14.71]],"id":522753}],"con":true,"img":false}]}
{"op":"mcm","clk":"5348323587","pt":1646216501205,"mc":[{"id":"1.195453755","rc":[{"atl":[[23,0]],"id":3805783}],"con":true,"img":false}]}
{"op":"mcm","clk":"5348323599","pt":1646216501308,"mc":[{"id":"1.195453755","rc":[{"atl":[[60,2]],"id":3805784},{"atl":[[16,9.9]],"id":3805746},{"atb":[[15.5,2.72]],"id":3805762}],"con":true,"img":false}]}
{"op":"mcm","clk":"5348323608","pt":1646216501370,"mc":[{"id":"1.195453755","rc":[{"atl":[[38,33.15]],"id":3805784},{"atl":[[110,20.41]],"id":3805746},{"atb":[[42,2.72],[44,36.36]],"id":522752},{"atb":[[13,25.53]],"id":3805762},{"atb":[[100,0],[110,24.62]],"id":522753}],"con":true,"img":false}]}
{"op":"mcm","clk":"5348323622","pt":1646216501471,"mc":[{"id":"1.195453755","rc":[{"atl":[[770,2]],"id":522747},{"atb":[[19,8.8]],"id":3805762}],"con":true,"img":false}]}
{"op":"mcm","clk":"5348323731","pt":1646216502308,"mc":[{"id":"1.195453755","rc":[{"atl":[[770,4.62]],"id":522747},{"atb":[[18,0]],"id":3805762}],"con":true,"img":false}]}
{"op":"mcm","clk":"5348323864","pt":1646216503412,"mc":[{"id":"1.195453755","rc":[{"atb":[[6.8,0],[7.8,0]],"id":3805746}],"con":true,"img":false}]}
{"op":"mcm","clk":"5348323877","pt":1646216503527,"mc":[{"id":"1.195453755","rc":[{"atl":[[790,2.07],[850,2]],"id":522745}],"con":true,"img":false}]}
{"op":"mcm","clk":"5348323890","pt":1646216503579,"mc":[{"id":"1.195453755","rc":[{"atl":[[22,0],[23,4.95],[26,22.91],[27,9.9]],"id":3805783},{"atl":[[16,0],[16.5,9.9],[14,0],[14.5,4.95]],"id":3805746},{"atl":[[32,9.9],[26,0],[27,4.95],[30,0]],"id":3805755},{"atb":[[130,0],[90,9.9],[95,0],[120,4.95]],"id":522749},{"atb":[[16,10.56],[16.5,4.95],[14,0],[14.5,9.9]],"id":3805731},{"atb":[[85,0],[100,4.95],[110,0],[120,0]],"id":522741},{"atb":[[10.5,9.9],[13,0],[14.5,0]],"id":3805740}],"con":true,"img":false}]}
{"op":"mcm","clk":"5348323915","pt":1646216503784,"mc":[{"id":"1.195453755","rc":[{"atl":[[270,0],[260,4.95]],"id":522747},{"atl":[[130,0],[140,4.95],[170,0],[180,9.9]],"id":522752}],"con":true,"img":false}]}
{"op":"mcm","clk":"5348323930","pt":1646216503898,"mc":[{"id":"1.195453755","rc":[{"atb":[[2.8,0],[2.7,0]],"id":3805793}],"con":true,"img":false}]}
{"op":"mcm","clk":"5348323942","pt":1646216504004,"mc":[{"id":"1.195453755","rc":[{"atl":[[700,2],[770,2.62]],"id":522747},{"atb":[[16.5,15.18],[12,2.72],[14.5,39.36]],"id":3805731}],"con":true,"img":false}]}
{"op":"mcm","clk":"5348323952","pt":1646216504101,"mc":[{"id":"1.195453755","rc":[{"atb":[[6.4,3.26]],"id":3805746},{"atb":[[9.2,25.04],[12.5,9.9]],"id":3805740}],"con":true,"img":false}]}
{"op":"mcm","clk":"5348323964","pt":1646216504207,"mc":[{"id":"1.195453755","rc":[{"atb":[[7.4,2.72]],"id":3805746}],"con":true,"img":false}]}
{"op":"mcm","clk":"5348323975","pt":1646216504312,"mc":[{"id":"1.195453755","rc":[{"atl":[[26,29.26]],"id":3805783},{"atl":[[100,0.16]],"id":3805746},{"atb":[[2.56,57.46],[2.68,0]],"id":3805793},{"atl":[[30,5.46]],"id":3805755},{"atb":[[90,0],[120,0]],"id":522749},{"atb":[[80,9.9],[90,0],[100,6.55],[29,16.48]],"id":522741},{"atb":[[12.5,23.69]],"id":3805740}],"con":true,"img":false}]}
{"op":"mcm","clk":"5348323984","pt":1646216504366,"mc":[{"id":"1.195453755","rc":[{"atb":[[2.68,47.38]],"id":3805793},{"atb":[[85,9.9],[48,3.37],[110,4.95]],"id":522749}],"con":true,"img":false}]}
{"op":"mcm","clk":"5348324004","pt":1646216504580,"mc":[{"id":"1.195453755","rc":[{"atb":[[6.6,28.31]],"id":3805746},{"atb":[[2.82,2.72],[2.72,3.26]],"id":3805793},{"atl":[[220,0.72]],"id":522752}],"con":true,"img":false}]}
{"op":"mcm","clk":"5348324021","pt":1646216504681,"mc":[{"id":"1.195453755","rc":[{"atb":[[16,0]],"id":3805731}],"con":true,"img":false}]}
{"op":"mcm","clk":"5348324028","pt":1646216504782,"mc":[{"id":"1.195453755","rc":[{"atl":[[32,32.77],[55,2]],"id":3805755},{"atb":[[46,2.22],[30,12.17]],"id":522749}],"con":true,"img":false}]}
{"op":"mcm","clk":"5348324064","pt":1646216505097,"mc":[{"id":"1.195453755","rc":[{"atl":[[220,9.97],[230,2]],"id":522752}],"con":true,"img":false}]}
{"op":"mcm","clk":"5348324081","pt":1646216505306,"mc":[{"id":"1.195453755","rc":[{"atl":[[26,6.34],[27,58.28]],"id":3805783},{"atl":[[14.5,16.69]],"id":3805746}],"con":true,"img":false}]}
{"op":"mcm","clk":"5348324095","pt":1646216505411,"mc":[{"id":"1.195453755","rc":[{"atb":[[6.2,4.95]],"id":3805746}],"con":true,"img":false}]}
{"op":"mcm","clk":"5348324145","pt":1646216505844,"mc":[{"id":"1.195453755","rc":[{"atb":[[130,4.95],[95,9.9]],"id":522749},{"atb":[[16.5,0],[16,4.95],[14,9.9],[14.5,29.45]],"id":3805731}],"con":true,"img":false}]}
{"op":"mcm","clk":"5348324157","pt":1646216505906,"mc":[{"id":"1.195453755","rc":[{"atb":[[85,0],[110,0]],"id":522749}],"con":true,"img":false}]}
{"op":"mcm","clk":"5348324170","pt":1646216506002,"mc":[{"id":"1.195453755","rc":[{"atl":[[100,0]],"id":3805746},{"atl":[[27,11.05]],"id":3805755}],"con":true,"img":false}]}
{"op":"mcm","clk":"5348324223","pt":1646216506332,"mc":[{"id":"1.195453755","rc":[{"atb":[[46,0]],"id":522749}],"con":true,"img":false}]}
{"op":"mcm","clk":"5348324275","pt":1646216506445,"mc":[{"id":"1.195453755","rc":[{"atb":[[48,5.5]],"id":522749},{"atb":[[42,21.81],[44,9.9]],"id":522752},{"atb":[[70,14.12],[110,9.9]],"id":522753}],"con":true,"img":false}]}
{"op":"mcm","clk":"5348324312","pt":1646216506505,"mc":[{"id":"1.195453755","rc":[{"atl":[[110,2]],"id":3805746}],"con":true,"img":false}]}
{"op":"mcm","clk":"5348324338","pt":1646216506612,"mc":[{"id":"1.195453755","rc":[{"atb":[[14.5,41.2]],"id":3805731}],"con":true,"img":false}]}
{"op":"mcm","clk":"5348324389","pt":1646216506720,"mc":[{"id":"1.195453755","rc":[{"atl":[[100,12.21]],"id":3805746}],"con":true,"img":false}]}
{"op":"mcm","clk":"5348324436","pt":1646216506869,"mc":[{"id":"1.195453755","rc":[{"atl":[[30,0]],"id":3805755},{"atl":[[290,2],[230,0]],"id":522752},{"atl":[[850,0],[910,2]],"id":522753},{"atl":[[930,1.83]],"id":522743}],"con":true,"img":false}]}
{"op":"mcm","clk":"5348324682","pt":1646216507536,"mc":[{"id":"1.195453755","rc":[{"atb":[[6.4,15.48],[5.3,30.97]],"id":3805746}],"con":true,"img":false}]}
{"op":"mcm","clk":"5348324770","pt":1646216507827,"mc":[{"id":"1.195453755","rc":[{"atl":[[850,0],[910,2]],"id":522745}],"con":true,"img":false}]}
{"op":"mcm","clk":"5348324793","pt":1646216507891,"mc":[{"id":"1.195453755","rc":[{"atb":[[38,5.94],[29,0]],"id":522747},{"atb":[[40,17.89],[30,0]],"id":522750},{"atb":[[13,22.26],[15.5,0]],"id":3805762},{"atb":[[40,0],[50,0]],"id":522743}],"con":true,"img":false}]}
{"op":"mcm","clk":"5348324880","pt":1646216508307,"mc":[{"id":"1.195453755","rc":[{"atl":[[700,0],[760,2]],"id":522747}],"con":true,"img":false}]}
{"op":"mcm","clk":"5348324948","pt":1646216508630,"mc":[{"id":"1.195453755","rc":[{"atb":[[40,2.72],[30,3.26]],"id":522747},{"atb":[[32,3.26],[42,12.63]],"id":522750}],"con":true,"img":false}]}
{"op":"mcm","clk":"5348324976","pt":1646216508789,"mc":[{"id":"1.195453755","rc":[{"atb":[[16,2.72],[13.5,3.26]],"id":3805762}],"con":true,"img":false}]}
{"op":"mcm","clk":"5348324989","pt":1646216508894,"mc":[{"id":"1.195453755","rc":[{"atb":[[12,40.01],[14.5,11.74]],"id":3805731},{"atb":[[42,3.26],[55,2.72]],"id":522743}],"con":true,"img":false}]}
{"op":"mcm","clk":"5348325163","pt":1646216510516,"mc":[{"id":"1.195453755","rc":[{"atl":[[23,12.15]],"id":3805783},{"atb":[[2.82,0],[2.72,0]],"id":3805793}],"con":true,"img":false}]}
{"op":"mcm","clk":"5348325190","pt":1646216510793,"mc":[{"id":"1.195453755","rc":[{"atb":[[14.5,14.46]],"id":3805783}],"con":true,"img":false}]}
{"op":"mcm","clk":"5348325243","pt":1646216511297,"mc":[{"id":"1.195453755","rc":[{"atl":[[26,0]],"id":3805783},{"atb":[[2.8,2.72],[2.7,3.26]],"id":3805793}],"con":true,"img":false}]}
{"op":"mcm","clk":"5348325272","pt":1646216511621,"mc":[{"id":"1.195453755","rc":[{"atb":[[12,8.22]],"id":3805783},{"atb":[[16.5,31.41],[13,0]],"id":3805762}],"con":true,"img":false}]}
{"op":"mcm","clk":"5348325358","pt":1646216512398,"mc":[{"id":"1.195453755","rc":[{"atl":[[700,2.93],[770,0]],"id":522747}],"con":true,"img":false}]}
{"op":"mcm","clk":"5348325382","pt":1646216512710,"mc":[{"id":"1.195453755","rc":[{"atb":[[19.5,0],[24,0]],"id":522746}],"con":true,"img":false}]}
{"op":"mcm","clk":"5348325395","pt":1646216512818,"mc":[{"id":"1.195453755","rc":[{"atb":[[9.6,18.43],[8.6,40.95]],"id":3805747},{"atb":[[12,22.08],[14.5,11.74]],"id":3805755},{"atb":[[40,0],[30,0]],"id":522747},{"atb":[[7.4,0],[8.4,0]],"id":3805736},{"atb":[[40,0],[30,8.9]],"id":522749},{"atb":[[32,0],[42,9.9]],"id":522750},{"atb":[[24,0],[29,13.76]],"id":522741},{"atb":[[25,0],[30,0]],"id":522742},{"atb":[[9.2,22.32],[8.2,0]],"id":3805740}],"con":true,"img":false}]}
{"op":"mcm","clk":"5348325452","pt":1646216513499,"mc":[{"id":"1.195453755","rc":[{"atb":[[9,3.26],[10,2.72]],"id":3805747},{"atb":[[12.5,3.26],[15,2.72]],"id":3805755},{"atb":[[22,3.26],[27,2.72]],"id":522746},{"atb":[[8,3.26],[9,2.72]],"id":3805736},{"atb":[[34,3.26],[44,2.72]],"id":522747},{"atb":[[32,3.26],[42,2.72]],"id":522749},{"atb":[[32,2.72],[26,3.26]],"id":522741},{"atb":[[32,2.72],[26,3.26]],"id":522742},{"atb":[[9,3.26],[10,2.72]],"id":3805740}],"con":true,"img":false}]}
{"op":"mcm","clk":"5348325464","pt":1646216513603,"mc":[{"id":"1.195453755","rc":[{"atb":[[34,3.26],[44,2.72]],"id":522750}],"con":true,"img":false}]}
{"op":"mcm","clk":"5348325516","pt":1646216514189,"mc":[{"id":"1.195453755","rc":[{"atb":[[12.5,13.78]],"id":3805731}],"con":true,"img":false}]}
{"op":"mcm","clk":"5348325545","pt":1646216514505,"mc":[{"id":"1.195453755","rc":[{"atb":[[2.56,9.9],[2.68,94.94]],"id":3805793},{"atb":[[50,3.23]],"id":522749}],"con":true,"img":false}]}
{"op":"mcm","clk":"5348325561","pt":1646216514710,"mc":[{"id":"1.195453755","rc":[{"atl":[[140,6.09]],"id":522752}],"con":true,"img":false}]}
{"op":"mcm","clk":"5348325569","pt":1646216514815,"mc":[{"id":"1.195453755","rc":[{"atb":[[48,17.86]],"id":522749}],"con":true,"img":false}]}
{"op":"mcm","clk":"5348325587","pt":1646216514920,"mc":[{"id":"1.195453755","rc":[{"atb":[[30,0]],"id":522749}],"con":true,"img":false}]}
{"op":"mcm","clk":"5348325599","pt":1646216514985,"mc":[{"id":"1.195453755","rc":[{"atb":[[12.5,0]],"id":3805731}],"con":true,"img":false}]}
{"op":"mcm","clk":"5348325627","pt":1646216515398,"mc":[{"id":"1.195453755","rc":[{"atb":[[48,14.49]],"id":522749}],"con":true,"img":false}]}
{"op":"mcm","clk":"5348325659","pt":1646216515710,"mc":[{"id":"1.195453755","rc":[{"atl":[[220,9.24]],"id":522752}],"con":true,"img":false}]}
{"op":"mcm","clk":"5348325768","pt":1646216516685,"mc":[{"id":"1.195453755","rc":[{"atb":[[10,17.61]],"id":3805731}],"con":true,"img":false}]}
{"op":"mcm","clk":"5348325817","pt":1646216517110,"mc":[{"id":"1.195453755","rc":[{"atb":[[2.8,0]],"id":3805793}],"con":true,"img":false}]}
{"op":"mcm","clk":"5348325837","pt":1646216517327,"mc":[{"id":"1.195453755","rc":[{"atb":[[2.7,0]],"id":3805793}],"con":true,"img":false}]}
{"op":"mcm","clk":"5348325847","pt":1646216517427,"mc":[{"id":"1.195453755","rc":[{"atb":[[10,0]],"id":3805731}],"con":true,"img":false}]}
{"op":"mcm","clk":"5348325889","pt":1646216517794,"mc":[{"id":"1.195453755","rc":[{"atb":[[2.74,2.72]],"id":3805793}],"con":true,"img":false}]}
{"op":"mcm","clk":"5348325907","pt":1646216518006,"mc":[{"id":"1.195453755","rc":[{"atb":[[2.64,8.22]],"id":3805793}],"con":true,"img":false}]}
{"op":"mcm","clk":"5348326234","pt":1646216521059,"mc":[{"id":"1.195453755","rc":[{"atl":[[130,4.95],[140,1.13],[170,9.9],[180,0]],"id":522752}],"con":true,"img":false}]}
{"op":"mcm","clk":"5348326255","pt":1646216521227,"mc":[{"id":"1.195453755","rc":[{"atl":[[46,41.8],[27,9.9]],"id":3805783},{"atb":[[9,44.22],[8.6,0]],"id":3805747},{"atb":[[2.64,55.78],[2.68,47.38]],"id":3805793},{"atb":[[12,0],[13,28.73],[15,14.04]],"id":3805755},{"atl":[[32,9.9],[55,25.78]],"id":3805755},{"atb":[[38,0],[44,14.43]],"id":522747},{"atb":[[9,27.81],[8.6,0]],"id":3805736},{"atb":[[40,0],[42,36.8]],"id":522750},{"atb":[[12,2.72],[14,39.36]],"id":3805731},{"atb":[[32,16.48]],"id":522741},{"atb":[[10,25.04],[9.2,0]],"id":3805740}],"con":true,"img":false}]}
{"op":"mcm","clk":"5348326271","pt":1646216521337,"mc":[{"id":"1.195453755","rc":[{"atb":[[29,0]],"id":522741}],"con":true,"img":false}]}
{"op":"mcm","clk":"5348326277","pt":1646216521445,"mc":[{"id":"1.195453755","rc":[{"atb":[[7.8,14.71],[9.4,0]],"id":3805784},{"atl":[[130,2],[70,18.26]],"id":3805747},{"atb":[[1.8,125],[1.35,0]],"id":3805793},{"atl":[[70,0],[110,2]],"id":3805736},{"atb":[[44,16.76],[27,0]],"id":522747},{"atl":[[340,2],[250,8]],"id":522750},{"atb":[[4.8,26.32],[6.8,0]],"id":3805731},{"atb":[[8,0],[9.4,11.9]],"id":3805740},{"atb":[[29,4.75],[8.4,13.51]],"id":522743},{"atb":[[20,5.26],[12.5,0]],"id":522745}],"con":true,"img":false}]}
{"op":"mcm","clk":"5348326290","pt":1646216521505,"mc":[{"id":"1.195453755","rc":[{"atl":[[170,22.13],[220,0]],"id":522752}],"con":true,"img":false}]}
{"op":"mcm","clk":"5348326336","pt":1646216521925,"mc":[{"id":"1.195453755","rc":[{"atb":[[14.5,0]],"id":3805755}],"con":true,"img":false}]}
{"op":"mcm","clk":"5348326577","pt":1646216524147,"mc":[{"id":"1.195453755","rc":[{"atb":[[16,15.52]],"id":3805731}],"con":true,"img":false}]}
{"op":"mcm","clk":"5348326601","pt":1646216524313,"mc":[{"id":"1.195453755","rc":[{"atb":[[130,6.18]],"id":522749}],"con":true,"img":false}]}
{"op":"mcm","clk":"5348326639","pt":1646216524540,"mc":[{"id":"1.195453755","rc":[{"atl":[[130,6.18]],"id":522752}],"con":true,"img":false}]}
{"op":"mcm","clk":"5348326654","pt":1646216524651,"mc":[{"id":"1.195453755","rc":[{"atb":[[48,2.13],[50,15.41]],"id":522749}],"con":true,"img":false}]}
{"op":"mcm","clk":"5348326685","pt":1646216524822,"mc":[{"id":"1.195453755","rc":[{"atb":[[14.5,0]],"id":3805731}],"con":true,"img":false}]}
{"op":"mcm","clk":"5348326728","pt":1646216525136,"mc":[{"id":"1.195453755","rc":[{"atb":[[50,12.17]],"id":522749}],"con":true,"img":false}]}
{"op":"mcm","clk":"5348326764","pt":1646216525313,"mc":[{"id":"1.195453755","rc":[{"atl":[[140,0]],"id":522752}],"con":true,"img":false}]}
{"op":"mcm","clk":"5348326825","pt":1646216525628,"mc":[{"id":"1.195453755","rc":[{"atb":[[32,0],[42,0]],"id":522749},{"atb":[[32,0],[42,19.08]],"id":522752},{"atb":[[70,11.4],[48,0]],"id":522753}],"con":true,"img":false}]}
{"op":"mcm","clk":"5348326840","pt":1646216525740,"mc":[{"id":"1.195453755","rc":[{"atb":[[9,40.95],[10,0]],"id":3805747}],"con":true,"img":false}]}
{"op":"mcm","clk":"5348326892","pt":1646216526025,"mc":[{"id":"1.195453755","rc":[{"atb":[[12.5,40.57],[13,4.95]],"id":3805755},{"atb":[[12,40.51],[14,9.9]],"id":3805731}],"con":true,"img":false}]}
{"op":"mcm","clk":"5348326927","pt":1646216526233,"mc":[{"id":"1.195453755","rc":[{"atb":[[9,0],[8.8,58.31]],"id":3805747}],"con":true,"img":false}]}
{"op":"mcm","clk":"5348326946","pt":1646216526342,"mc":[{"id":"1.195453755","rc":[{"atb":[[34,3.26],[44,2.72]],"id":522749},{"atb":[[34,3.26],[44,12.63]],"id":522752},{"atl":[[290,9.16],[170,9.9]],"id":522752},{"atb":[[75,2.72],[50,3.26]],"id":522753}],"con":true,"img":false}]}
{"op":"mcm","clk":"5348326959","pt":1646216526410,"mc":[{"id":"1.195453755","rc":[{"atb":[[9.8,2.72],[8.8,61.58]],"id":3805747}],"con":true,"img":false}]}
{"op":"mcm","clk":"5348327043","pt":1646216526844,"mc":[{"id":"1.195453755","rc":[{"atb":[[70,0],[75,14.12]],"id":522753}],"con":true,"img":false}]}
{"op":"mcm","clk":"5348327097","pt":1646216527219,"mc":[{"id":"1.195453755","rc":[{"atb":[[9.8,20.74]],"id":3805747}],"con":true,"img":false}]}
{"op":"mcm","clk":"5348327184","pt":1646216527968,"mc":[{"id":"1.195453755","rc":[{"atb":[[9.6,0]],"id":3805747}],"con":true,"img":false}]}
{"op":"mcm","clk":"5348327500","pt":1646216529708,"mc":[{"id":"1.195453755","rc":[{"atb":[[12,4.95],[14.5,11.74]],"id":3805783}],"con":true,"img":false}]}
{"op":"mcm","clk":"5348327645","pt":1646216530504,"mc":[{"id":"1.195453755","rc":[{"atb":[[11.5,3.26],[14,2.72]],"id":3805783}],"con":true,"img":false}]}
{"op":"mcm","clk":"5348327692","pt":1646216530810,"mc":[{"id":"1.195453755","rc":[{"atl":[[16.5,0],[16,9.9],[14,4.95],[14.5,11.74]],"id":3805746}],"con":true,"img":false}]}
{"op":"mcm","clk":"5348327707","pt":1646216530914,"mc":[{"id":"1.195453755","rc":[{"atb":[[10,9.9],[12,37.13]],"id":3805783},{"atb":[[8,63.26],[8.8,8.22]],"id":3805747}],"con":true,"img":false}]}
{"op":"mcm","clk":"5348327721","pt":1646216531017,"mc":[{"id":"1.195453755","rc":[{"atl":[[110,0],[29,3.57]],"id":3805746}],"con":true,"img":false}]}
{"op":"mcm","clk":"5348327766","pt":1646216531327,"mc":[{"id":"1.195453755","rc":[{"atl":[[16,42.08],[100,0],[14,17.15]],"id":3805746}],"con":true,"img":false}]}
{"op":"mcm","clk":"5348327776","pt":1646216531432,"mc":[{"id":"1.195453755","rc":[{"atl":[[32,0],[26,4.95],[27,6.09],[30,9.9]],"id":3805755}],"con":true,"img":false}]}
{"op":"mcm","clk":"5348327847","pt":1646216531853,"mc":[{"id":"1.195453755","rc":[{"atl":[[55,2],[30,33.7]],"id":3805755}],"con":true,"img":false}]}
{"op":"mcm","clk":"5348327862","pt":1646216531908,"mc":[{"id":"1.195453755","rc":[{"atl":[[26,11.29]],"id":3805755}],"con":true,"img":false}]}
{"op":"mcm","clk":"5348327897","pt":1646216532181,"mc":[{"id":"1.195453755","rc":[{"atl":[[14.5,0]],"id":3805746}],"con":true,"img":false}]}
{"op":"mcm","clk":"5348327934","pt":1646216532329,"mc":[{"id":"1.195453755","rc":[{"atl":[[16.5,9.9],[14,4.95],[14.5,4.95]],"id":3805746},{"atb":[[130,0],[90,9.9],[95,0],[120,4.95]],"id":522749}],"con":true,"img":false}]}
{"op":"mcm","clk":"5348327950","pt":1646216532430,"mc":[{"id":"1.195453755","rc":[{"atl":[[16,32.18],[14,0]],"id":3805746}],"con":true,"img":false}]}
{"op":"mcm","clk":"5348327985","pt":1646216532640,"mc":[{"id":"1.195453755","rc":[{"atl":[[27,0]],"id":3805755}],"con":true,"img":false}]}
{"op":"mcm","clk":"5348328060","pt":1646216533019,"mc":[{"id":"1.195453755","rc":[{"atl":[[15.5,10.93]],"id":3805746},{"atb":[[120,6.28]],"id":522749}],"con":true,"img":false}]}
{"op":"mcm","clk":"5348328354","pt":1646216534644,"mc":[{"id":"1.195453755","rc":[{"atb":[[80,0],[85,9.9],[100,1.6],[110,4.95]],"id":522741}],"con":true,"img":false}]}
{"op":"mcm","clk":"5348328444","pt":1646216535118,"mc":[{"id":"1.195453755","rc":[{"atb":[[110,6.4]],"id":522741}],"con":true,"img":false}]}
{"op":"mcm","clk":"5348328464","pt":1646216535226,"mc":[{"id":"1.195453755","rc":[{"atb":[[32,2.72],[85,23.66]],"id":522741}],"con":true,"img":false}]}
{"op":"mcm","clk":"5348328583","pt":1646216535822,"mc":[{"id":"1.195453755","rc":[{"atb":[[100,0]],"id":522741},{"atb":[[10.5,0],[12,9.9],[12.5,13.78],[14,4.95]],"id":3805740}],"con":true,"img":false}]}
{"op":"mcm","clk":"5348328679","pt":1646216536341,"mc":[{"id":"1.195453755","rc":[{"atb":[[10,2.72],[12,32.23],[14,17.15]],"id":3805740}],"con":true,"img":false}]}
{"op":"mcm","clk":"5348328701","pt":1646216536442,"mc":[{"id":"1.195453755","rc":[{"atl":[[30,9.9]],"id":3805755}],"con":true,"img":false}]}
{"op":"mcm","clk":"5348328721","pt":1646216536547,"mc":[{"id":"1.195453755","rc":[{"atl":[[55,39.68]],"id":3805755}],"con":true,"img":false}]}
{"op":"mcm","clk":"5348328827","pt":1646216537128,"mc":[{"id":"1.195453755","rc":[{"atb":[[12.5,0]],"id":3805740}],"con":true,"img":false}]}
{"op":"mcm","clk":"5348329290","pt":1646216539828,"mc":[{"id":"1.195453755","rc":[{"atb":[[32,16.48],[85,9.9]],"id":522741}],"con":true,"img":false}]}
{"op":"mcm","clk":"5348329469","pt":1646216540821,"mc":[{"id":"1.195453755","rc":[{"atl":[[14.5,16.69]],"id":3805746},{"atb":[[10,35.81],[12,9.9]],"id":3805740}],"con":true,"img":false}]}
{"op":"mcm","clk":"5348329585","pt":1646216541549,"mc":[{"id":"1.195453755","rc":[{"atl":[[15.5,0]],"id":3805746}],"con":true,"img":false}]}
{"op":"mcm","clk":"5348329699","pt":1646216542141,"mc":[{"id":"1.195453755","rc":[{"atl":[[16,0],[16.5,57.75]],"id":3805746}],"con":true,"img":false}]}
{"op":"mcm","clk":"5348329743","pt":1646216542457,"mc":[{"id":"1.195453755","rc":[{"atb":[[5.1,0],[10.5,0],[6.2,0]],"id":3805784},{"atb":[[5.7,0],[9.4,0],[4.7,0]],"id":3805783},{"atb":[[3.85,0],[3.35,0],[5.7,0]],"id":3805747},{"atb":[[5.3,0],[3.15,0],[3.65,0]],"id":3805746},{"atb":[[2.4,0],[2,0],[1.9,0]],"id":3805793},{"atb":[[5.7,0],[9.4,0],[4.7,0]],"id":3805755},{"atb":[[6.2,0],[8.2,0],[15.5,0]],"id":522746},{"atb":[[22,0],[11,0],[8.4,0]],"id":522747},{"atb":[[5.3,0],[3.15,0],[3.65,0]],"id":3805736},{"atb":[[22,0],[11,0],[8.4,0]],"id":522749},{"atb":[[22,0],[11,0],[8.4,0]],"id":522750},{"atb":[[5.1,0],[8.2,0],[4.1,0]],"id":3805731},{"atb":[[22,0],[11,0],[8.4,0]],"id":522752},{"atb":[[5.1,0],[10.5,0],[6.2,0]],"id":3805762},{"atb":[[4.5,0],[7,0],[3.75,0]],"id":3805730},{"atb":[[19,0],[46,2.22],[14,0]],"id":522753},{"atb":[[7.2,0],[18,0],[9.2,0]],"id":522741},{"atb":[[7.2,0],[18,0],[9.2,0]],"id":522742},{"atb":[[3.85,0],[3.35,0],[5.7,0]],"id":3805740},{"atb":[[9.8,0],[29,0],[14.5,0]],"id":522743},{"atb":[[9.8,0],[29,0],[14.5,0]],"id":522745}],"con":true,"img":false}]}
{"op":"mcm","clk":"5348330021","pt":1646216544144,"mc":[{"id":"1.195453755","rc":[{"atl":[[150,4.95],[160,0.99],[190,9.9],[200,0]],"id":522750}],"con":true,"img":false}]}
{"op":"mcm","clk":"5348330075","pt":1646216544558,"mc":[{"id":"1.195453755","rc":[{"atl":[[150,6.01],[190,20.85],[250,0]],"id":522750}],"con":true,"img":false}]}
{"op":"mcm","clk":"5348330190","pt":1646216545238,"mc":[{"id":"1.195453755","rc":[{"atl":[[160,0]],"id":522750}],"con":true,"img":false}]}
{"op":"mcm","clk":"5348330333","pt":1646216546231,"mc":[{"id":"1.195453755","rc":[{"atb":[[16,12.63],[17.5,0],[18,14.27],[15.5,0]],"id":3805784}],"con":true,"img":false}]}
{"op":"mcm","clk":"5348330386","pt":1646216546750,"mc":[{"id":"1.195453755","rc":[{"atb":[[16,52.62],[17,0]],"id":3805784},{"atl":[[16.5,9.9],[29,51.41]],"id":3805746}],"con":true,"img":false}]}
{"op":"mcm","clk":"5348330523","pt":1646216547853,"mc":[{"id":"1.195453755","rc":[{"atl":[[150,0],[160,4.95],[190,10.94],[200,9.9]],"id":522750}],"con":true,"img":false}]}
{"op":"mcm","clk":"5348330620","pt":1646216548640,"mc":[{"id":"1.195453755","rc":[{"atl":[[190,11.78]],"id":522750}],"con":true,"img":false}]}
{"op":"mcm","clk":"5348330657","pt":1646216548953,"mc":[{"id":"1.195453755","rc":[{"atl":[[190,0.83],[200,20.3]],"id":522750}],"con":true,"img":false}]}
{"op":"mcm","clk":"5348330702","pt":1646216549428,"mc":[{"id":"1.195453755","rc":[{"atb":[[16,10.56],[16.5,4.95],[14,0],[14.5,9.9]],"id":3805731}],"con":true,"img":false}]}
{"op":"mcm","clk":"5348330757","pt":1646216549951,"mc":[{"id":"1.195453755","rc":[{"atb":[[16.5,15.18],[14.5,39.36]],"id":3805731}],"con":true,"img":false}]}
{"op":"mcm","clk":"5348330771","pt":1646216550045,"mc":[{"id":"1.195453755","rc":[{"atb":[[12,2.72]],"id":3805731}],"con":true,"img":false}]}
{"op":"mcm","clk":"5348330835","pt":1646216550624,"mc":[{"id":"1.195453755","rc":[{"atb":[[16,0]],"id":3805731}],"con":true,"img":false}]}
{"op":"mcm","clk":"5348330883","pt":1646216551043,"mc":[{"id":"1.195453755","rc":[{"atb":[[6.4,49.33],[11,13.31],[5.2,63.42]],"id":3805784},{"atb":[[9.6,15.48],[4.8,70.1],[5.8,55.49]],"id":3805783},{"atb":[[5.8,27.75],[3.4,110.99],[3.9,91.85]],"id":3805747},{"atb":[[3.2,121.08],[3.7,98.66],[5.4,30.27]],"id":3805746},{"atb":[[1.77,345.96],[1.87,306.19],[2.14,116.84]],"id":3805793},{"atb":[[9.6,15.48],[4.8,70.1],[5.8,55.49]],"id":3805755},{"atb":[[16.5,8.59],[8.6,35.05],[6.6,47.57]],"id":522746},{"atb":[[3.2,121.08],[3.7,98.66],[5.4,30.27]],"id":3805736},{"atb":[[9,33.29],[25,5.54],[12.5,23.16]],"id":522747},{"atb":[[9,33.29],[25,5.54],[12.5,23.16]],"id":522749},{"atb":[[9,33.29],[25,5.54],[12.5,23.16]],"id":522750},{"atb":[[5.1,64.97],[8.2,18.49],[4.1,85.93]],"id":3805731},{"atb":[[9,33.29],[25,9.71],[12.5,23.16]],"id":522752},{"atb":[[4.5,76.11],[7,22.19],[3.75,96.87]],"id":3805730},{"atb":[[6.4,49.33],[11,13.31],[5.2,63.42]],"id":3805762},{"atb":[[18,15.66],[80,1.68],[26,10.65]],"id":522753},{"atb":[[9.6,30.97],[19,7.4],[7.6,40.36]],"id":522741},{"atb":[[9.6,30.97],[19,7.4],[7.6,40.36]],"id":522742},{"atb":[[16,17.76],[34,4.03],[11,26.63]],"id":522743},{"atb":[[5.8,27.75],[3.4,110.99],[3.9,91.85]],"id":3805740},{"atb":[[16,17.76],[34,4.03],[11,26.63]],"id":522745}],"con":true,"img":false}]}
{"op":"mcm","clk":"5348330894","pt":1646216551137,"mc":[{"id":"1.195453755","rc":[{"atb":[[16,12.63],[13.5,33.88]],"id":3805784}],"con":true,"img":false}]}
{"op":"mcm","clk":"5348330944","pt":1646216551560,"mc":[{"id":"1.195453755","rc":[{"atb":[[130,4.95],[90,0],[95,9.9],[120,1.32]],"id":522749},{"atb":[[75,2.72],[80,12.59]],"id":522753}],"con":true,"img":false}]}
{"op":"mcm","clk":"5348330991","pt":1646216551930,"mc":[{"id":"1.195453755","rc":[{"atb":[[95,20.92],[50,0]],"id":522749}],"con":true,"img":false}]}
{"op":"mcm","clk":"5348331004","pt":1646216552033,"mc":[{"id":"1.195453755","rc":[{"atb":[[130,6.18]],"id":522749}],"con":true,"img":false}]}
{"op":"mcm","clk":"5348331066","pt":1646216552753,"mc":[{"id":"1.195453755","rc":[{"atb":[[120,0]],"id":522749}],"con":true,"img":false}]}
{"op":"mcm","clk":"5348331159","pt":1646216553749,"mc":[{"id":"1.195453755","rc":[{"atl":[[160,5.95]],"id":522750}],"con":true,"img":false}]}
{"op":"mcm","clk":"5348331336","pt":1646216555157,"mc":[{"id":"1.195453755","rc":[{"atl":[[190,0]],"id":522750},{"atb":[[12,40.01],[14.5,9.9]],"id":3805731}],"con":true,"img":false}]}
{"op":"mcm","clk":"5348331374","pt":1646216555434,"mc":[{"id":"1.195453755","rc":[{"atb":[[2.64,52.51]],"id":3805793}],"con":true,"img":false}]}
{"op":"mcm","clk":"5348331484","pt":1646216556462,"mc":[{"id":"1.195453755","rc":[{"atb":[[2.66,3.26]],"id":3805793},{"atb":[[95,9.9],[48,13.14]],"id":522749},{"atl":[[340,8.1],[200,9.9]],"id":522750}],"con":true,"img":false}]}
{"op":"mcm","clk":"5348331537","pt":1646216556985,"mc":[{"id":"1.195453755","rc":[{"atb":[[2.66,50.83],[2.64,4.95]],"id":3805793}],"con":true,"img":false}]}
{"op":"mcm","clk":"5348331649","pt":1646216557870,"mc":[{"id":"1.195453755","rc":[{"atl":[[710,0],[770,2]],"id":522749},{"atl":[[910,0],[980,2]],"id":522753}],"con":true,"img":false}]}
{"op":"mcm","clk":"5348331672","pt":1646216558034,"mc":[{"id":"1.195453755","rc":[{"atl":[[38,23.24],[30,0]],"id":3805784},{"atb":[[12.5,4.95]],"id":3805783},{"atl":[[290,0],[310,4.95]],"id":522753},{"atb":[[65,4.95],[48,9.9]],"id":522742}],"con":true,"img":false}]}
{"op":"mcm","clk":"5348331680","pt":1646216558140,"mc":[{"id":"1.195453755","rc":[{"atl":[[32,4.95],[40,9.9]],"id":3805784},{"atb":[[10,0],[12,32.18]],"id":3805783},{"atb":[[2.56,0],[2.64,0]],"id":3805793},{"atb":[[46,0],[60,2.68]],"id":522742},{"atl":[[290,0],[310,4.95]],"id":522745}],"con":true,"img":false}]}
{"op":"mcm","clk":"5348331711","pt":1646216558446,"mc":[{"id":"1.195453755","rc":[{"atl":[[38,0],[60,36.67]],"id":3805784},{"atb":[[70,2.29]],"id":522742}],"con":true,"img":false}]}
{"op":"mcm","clk":"5348331721","pt":1646216558549,"mc":[{"id":"1.195453755","rc":[{"atb":[[12,0],[12.5,37.13]],"id":3805783},{"atb":[[2.54,9.9],[2.62,4.95]],"id":3805793},{"atb":[[44,0],[48,27.68]],"id":522742}],"con":true,"img":false}]}
{"op":"mcm","clk":"5348331789","pt":1646216559233,"mc":[{"id":"1.195453755","rc":[{"atb":[[60,0]],"id":522742}],"con":true,"img":false}]}
{"op":"mcm","clk":"5348331809","pt":1646216559438,"mc":[{"id":"1.195453755","rc":[{"atl":[[290,7.16],[350,2]],"id":522752},{"atl":[[980,0]],"id":522753},{"atl":[[970,2]],"id":522743},{"atl":[[910,0],[1000,2]],"id":522745}],"con":true,"img":false}]}
{"op":"mcm","clk":"5348331826","pt":1646216559645,"mc":[{"id":"1.195453755","rc":[{"atb":[[6.4,12.21],[7.4,0]],"id":3805746},{"atb":[[2.54,0],[2.64,4.95],[2.62,0]],"id":3805793},{"atl":[[260,0],[270,4.95]],"id":522747},{"atl":[[260,0],[290,4.95]],"id":522749},{"atb":[[44,2.72],[46,9.9],[55,2.93],[60,4.95]],"id":522752},{"atl":[[130,4.95],[170,9.9],[120,0]],"id":522742},{"atl":[[330,0],[320,4.95]],"id":522743},{"atb":[[130,6.18],[95,9.9]],"id":522745}],"con":true,"img":false}]}
{"op":"mcm","clk":"5348331837","pt":1646216559748,"mc":[{"id":"1.195453755","rc":[{"atb":[[6.6,0]],"id":3805746},{"atl":[[1000,2]],"id":522753},{"atb":[[90,13.4],[120,0]],"id":522745}],"con":true,"img":false}]}
{"op":"mcm","clk":"5348331872","pt":1646216560064,"mc":[{"id":"1.195453755","rc":[{"atb":[[65,2.47],[42,0],[46,29.76]],"id":522752},{"atl":[[290,2],[170,22.13]],"id":522742}],"con":true,"img":false}]}
{"op":"mcm","clk":"5348331882","pt":1646216560168,"mc":[{"id":"1.195453755","rc":[{"atb":[[6.4,0],[6.2,47.93]],"id":3805746},{"atb":[[95,24.62]],"id":522745}],"con":true,"img":false}]}
{"op":"mcm","clk":"5348331895","pt":1646216560274,"mc":[{"id":"1.195453755","rc":[{"atb":[[90,0]],"id":522745}],"con":true,"img":false}]}
{"op":"mcm","clk":"5348331908","pt":1646216560332,"mc":[{"id":"1.195453755","rc":[{"atb":[[7.2,2.72],[6.2,51.2]],"id":3805746}],"con":true,"img":false}]}
{"op":"mcm","clk":"5348331923","pt":1646216560484,"mc":[{"id":"1.195453755","rc":[{"atb":[[6.2,81.69]],"id":3805746},{"atl":[[970,0]],"id":522743}],"con":true,"img":false}]}
{"op":"mcm","clk":"5348331948","pt":1646216560646,"mc":[{"id":"1.195453755","rc":[{"atb":[[130,0],[90,9.9],[95,0],[120,4.95]],"id":522749}],"con":true,"img":false}]}
{"op":"mcm","clk":"5348331962","pt":1646216560752,"mc":[{"id":"1.195453755","rc":[{"atb":[[8,53.35],[9,4.95],[8.2,9.9],[8.8,3.26]],"id":3805747},{"atl":[[140,0],[150,9.9],[100,0],[110,4.95]],"id":522746},{"atb":[[42,26.9],[44,12.63],[50,3.23],[55,4.95]],"id":522750},{"atl":[[160,4.95]],"id":522750},{"atb":[[55,0]],"id":522752},{"atl":[[130,1.23],[140,4.95],[170,0],[180,9.9]],"id":522752},{"atl":[[110,0]],"id":522742}],"con":true,"img":false}]}
{"op":"mcm","clk":"5348331971","pt":1646216560853,"mc":[{"id":"1.195453755","rc":[{"atl":[[130,0]],"id":522752},{"atb":[[95,9.9]],"id":522745}],"con":true,"img":false}]}
{"op":"mcm","clk":"5348332003","pt":1646216561163,"mc":[{"id":"1.195453755","rc":[{"atb":[[8,0],[8.8,44.22]],"id":3805747},{"atb":[[42,0],[44,32.04]],"id":522750}],"con":true,"img":false}]}
{"op":"mcm","clk":"5348332030","pt":1646216561372,"mc":[{"id":"1.195453755","rc":[{"atb":[[90,0],[120,1.32]],"id":522749},{"atl":[[280,4.95],[290,0]],"id":522749},{"atb":[[60,2.68]],"id":522750},{"atl":[[290,0],[180,21.45]],"id":522752}],"con":true,"img":false}]}
{"op":"mcm","clk":"5348332041","pt":1646216561476,"mc":[{"id":"1.195453755","rc":[{"atb":[[9.8,18.01],[8.8,40.95]],"id":3805747},{"atl":[[270,0.58],[140,9.9],[100,4.95]],"id":522746},{"atl":[[150,1.06]],"id":522750},{"atl":[[130,6.18]],"id":522742}],"con":true,"img":false}]}
{"op":"mcm","clk":"5348332067","pt":1646216561643,"mc":[{"id":"1.195453755","rc":[{"atl":[[280,0.56]],"id":522752}],"con":true,"img":false}]}
{"op":"mcm","clk":"5348332088","pt":1646216561848,"mc":[{"id":"1.195453755","rc":[{"atl":[[150,0],[110,0]],"id":522746},{"atb":[[44,10.42],[48,2.13]],"id":522749}],"con":true,"img":false}]}
{"op":"mcm","clk":"5348332100","pt":1646216561950,"mc":[{"id":"1.195453755","rc":[{"atl":[[140,24.75],[280,2]],"id":522746},{"atl":[[340,2],[200,20.3]],"id":522750}],"con":true,"img":false}]}
{"op":"mcm","clk":"5348332110","pt":1646216562057,"mc":[{"id":"1.195453755","rc":[{"atb":[[130,4.95],[95,9.9]],"id":522749},{"atb":[[50,0]],"id":522750},{"atl":[[180,9.9]],"id":522752}],"con":true,"img":false}]}
{"op":"mcm","clk":"5348332121","pt":1646216562163,"mc":[{"id":"1.195453755","rc":[{"atb":[[9,8.22],[10,2.72]],"id":3805747}],"con":true,"img":false}]}
{"op":"mcm","clk":"5348332363","pt":1646216564346,"mc":[{"id":"1.195453755","rc":[{"atl":[[290,9.16]],"id":522742}],"con":true,"img":false}]}
{"op":"mcm","clk":"5348332379","pt":1646216564449,"mc":[{"id":"1.195453755","rc":[{"atl":[[170,9.9]],"id":522742}],"con":true,"img":false}]}
{"op":"mcm","clk":"5348332389","pt":1646216564551,"mc":[{"id":"1.195453755","rc":[{"atb":[[6.2,38.71],[5.7,49.45]],"id":3805746}],"con":true,"img":false}]}
{"op":"mcm","clk":"5348332431","pt":1646216564968,"mc":[{"id":"1.195453755","rc":[{"atl":[[930,2],[1000,0]],"id":522753},{"atl":[[940,2]],"id":522743},{"atl":[[940,2],[1000,0]],"id":522745}],"con":true,"img":false}]}
{"op":"mcm","clk":"5348332455","pt":1646216565179,"mc":[{"id":"1.195453755","rc":[{"atb":[[11.5,0],[14,0]],"id":3805783}],"con":true,"img":false}]}
{"op":"mcm","clk":"5348332489","pt":1646216565449,"mc":[{"id":"1.195453755","rc":[{"atb":[[44,2.72],[95,20.92]],"id":522749}],"con":true,"img":false}]}
{"op":"mcm","clk":"5348332513","pt":1646216565650,"mc":[{"id":"1.195453755","rc":[{"atb":[[9.6,56.58],[12.5,4.95]],"id":3805783}],"con":true,"img":false}]}
{"op":"mcm","clk":"5348332535","pt":1646216565859,"mc":[{"id":"1.195453755","rc":[{"atb":[[12,3.26],[14.5,14.46]],"id":3805783}],"con":true,"img":false}]}
{"op":"mcm","clk":"5348332591","pt":1646216566342,"mc":[{"id":"1.195453755","rc":[{"atl":[[270,8.28],[140,9.9]],"id":522746}],"con":true,"img":false}]}
{"op":"mcm","clk":"5348332621","pt":1646216566655,"mc":[{"id":"1.195453755","rc":[{"atb":[[2.74,0],[2.66,47.56]],"id":3805793}],"con":true,"img":false}]}
{"op":"mcm","clk":"5348332633","pt":1646216566758,"mc":[{"id":"1.195453755","rc":[{"atl":[[130,4.95],[140,0],[170,9.9],[180,0]],"id":522752}],"con":true,"img":false}]}
{"op":"mcm","clk":"5348332662","pt":1646216567077,"mc":[{"id":"1.195453755","rc":[{"atb":[[2.66,0],[2.64,77.97]],"id":3805793}],"con":true,"img":false}]}
{"op":"mcm","clk":"5348332689","pt":1646216567346,"mc":[{"id":"1.195453755","rc":[{"atb":[[2.56,3.26],[2.66,2.72]],"id":3805793}],"con":true,"img":false}]}
{"op":"mcm","clk":"5348332696","pt":1646216567456,"mc":[{"id":"1.195453755","rc":[{"atl":[[40,43.4],[60,2]],"id":3805784},{"atb":[[9.6,15.48],[12,36.07]],"id":3805783},{"atl":[[130,0],[140,4.95],[170,0],[180,9.9]],"id":522752}],"con":true,"img":false}]}
{"op":"mcm","clk":"5348332739","pt":1646216567966,"mc":[{"id":"1.195453755","rc":[{"atb":[[9,4.95]],"id":3805747}],"con":true,"img":false}]}
{"op":"mcm","clk":"5348332748","pt":1646216568075,"mc":[{"id":"1.195453755","rc":[{"atb":[[10,0]],"id":3805747}],"con":true,"img":false}]}
{"op":"mcm","clk":"5348332801","pt":1646216568648,"mc":[{"id":"1.195453755","rc":[{"atb":[[8.6,3.26]],"id":3805747}],"con":true,"img":false}]}
{"op":"mcm","clk":"5348332833","pt":1646216568958,"mc":[{"id":"1.195453755","rc":[{"atb":[[9.6,2.72]],"id":3805747}],"con":true,"img":false}]}
{"op":"mcm","clk":"5348332855","pt":1646216569167,"mc":[{"id":"1.195453755","rc":[{"atb":[[55,14.12]],"id":522745}],"con":true,"img":false}]}
{"op":"mcm","clk":"5348332879","pt":1646216569374,"mc":[{"id":"1.195453755","rc":[{"atl":[[930,0],[990,2]],"id":522753},{"atl":[[940,0]],"id":522743},{"atl":[[940,0]],"id":522745}],"con":true,"img":false}]}
{"op":"mcm","clk":"5348332973","pt":1646216570063,"mc":[{"id":"1.195453755","rc":[{"atb":[[9,45.9],[8.8,0]],"id":3805747}],"con":true,"img":false}]}
{"op":"mcm","clk":"5348333006","pt":1646216570269,"mc":[{"id":"1.195453755","rc":[{"atb":[[130,6.18]],"id":522749},{"atl":[[280,7.98]],"id":522752}],"con":true,"img":false}]}
{"op":"mcm","clk":"5348333017","pt":1646216570366,"mc":[{"id":"1.195453755","rc":[{"atb":[[2.64,73.02],[2.62,4.95]],"id":3805793},{"atl":[[100,6.55]],"id":522746}],"con":true,"img":false}]}
{"op":"mcm","clk":"5348333043","pt":1646216570574,"mc":[{"id":"1.195453755","rc":[{"atl":[[270,0.58]],"id":522752}],"con":true,"img":false}]}
{"op":"mcm","clk":"5348333090","pt":1646216571054,"mc":[{"id":"1.195453755","rc":[{"atl":[[270,7.69]],"id":522746},{"atb":[[120,0]],"id":522749}],"con":true,"img":false}]}
{"op":"mcm","clk":"5348333126","pt":1646216571468,"mc":[{"id":"1.195453755","rc":[{"atl":[[760,0],[850,2]],"id":522747},{"atl":[[770,0],[960,2]],"id":522749},{"atb":[[24,0],[30,3.45]],"id":522750},{"atb":[[32,3.23],[25,5.54]],"id":522752},{"atl":[[990,0]],"id":522753},{"atl":[[800,2.31]],"id":522741},{"atb":[[36,2.86],[29,0]],"id":522742},{"atl":[[290,7.16],[350,2]],"id":522742}],"con":true,"img":false}]}
{"op":"mcm","clk":"5348333204","pt":1646216572202,"mc":[{"id":"1.195453755","rc":[{"atl":[[4.5,0],[4.1,32.26]],"id":3805793}],"con":true,"img":false}]}
{"op":"mcm","clk":"5348333442","pt":1646216574324,"mc":[{"id":"1.195453755","rc":[{"atl":[[280,7.42]],"id":522752}],"con":true,"img":false}]}
{"op":"mcm","clk":"5348333486","pt":1646216574665,"mc":[{"id":"1.195453755","rc":[{"atb":[[95,9.9]],"id":522749}],"con":true,"img":false}]}
{"op":"mcm","clk":"5348333517","pt":1646216574977,"mc":[{"id":"1.195453755","rc":[{"atl":[[270,0],[280,4.95]],"id":522747},{"atb":[[48,13.14]],"id":522749},{"atl":[[32,4.51],[34,4.95],[40,0],[42,39.36]],"id":3805731},{"atb":[[150,1.06],[110,0]],"id":522753},{"atl":[[310,0]],"id":522753}],"con":true,"img":false}]}
{"op":"mcm","clk":"5348333533","pt":1646216575186,"mc":[{"id":"1.195453755","rc":[{"atb":[[160,4.95],[120,9.9]],"id":522753},{"atl":[[340,4.95]],"id":522753}],"con":true,"img":false}]}
{"op":"mcm","clk":"5348333545","pt":1646216575292,"mc":[{"id":"1.195453755","rc":[{"atb":[[2.64,0]],"id":3805793},{"atb":[[36,0],[40,9.9],[44,3.68],[48,4.95]],"id":522746},{"atl":[[140,0],[150,9.9],[100,1.6],[110,4.95]],"id":522746},{"atl":[[280,0],[320,4.95],[210,0]],"id":522749},{"atb":[[12,0],[13,9.9],[14,12.19],[15,4.95]],"id":3805730},{"atl":[[23,7.2],[26,4.95],[27,0],[30,9.9]],"id":3805730},{"atl":[[320,0],[350,4.95]],"id":522743}],"con":true,"img":false}]}
{"op":"mcm","clk":"5348333567","pt":1646216575461,"mc":[{"id":"1.195453755","rc":[{"atb":[[9.8,0]],"id":3805747},{"atl":[[36,0],[44,0]],"id":3805762}],"con":true,"img":false}]}
{"op":"mcm","clk":"5348333579","pt":1646216575568,"mc":[{"id":"1.195453755","rc":[{"atl":[[23,7.2],[26,4.95],[27,0],[30,9.9]],"id":3805783},{"atb":[[2.62,0],[2.68,0]],"id":3805793},{"atl":[[3.7,0],[3.35,4.95],[3.55,9.9],[3.5,22.08]],"id":3805793},{"atl":[[22,0],[23,4.95],[26,29.45],[27,9.9]],"id":3805736},{"atl":[[34,4.95],[42,9.9]],"id":3805762},{"atl":[[280,0],[330,4.95]],"id":522741},{"atl":[[130,1.23],[150,4.95],[170,0],[190,9.9]],"id":522742},{"atl":[[310,0],[380,4.95],[240,0]],"id":522745}],"con":true,"img":false}]}
{"op":"mcm","clk":"5348333657","pt":1646216576397,"mc":[{"id":"1.195453755","rc":[{"atb":[[75,9.83],[80,1.68],[170,0.93]],"id":522753},{"atl":[[780,0]],"id":522753}],"con":true,"img":false}]}
{"op":"mcm","clk":"5348333665","pt":1646216576453,"mc":[{"id":"1.195453755","rc":[{"atb":[[34,0],[40,24.62],[50,3.23]],"id":522746},{"atl":[[270,0],[150,23.77]],"id":522746},{"atl":[[570,0],[960,4.15]],"id":522749},{"atb":[[11.5,2.72],[13,35.33],[15.5,10.93]],"id":3805730}],"con":true,"img":false}]}
{"op":"mcm","clk":"5348333676","pt":1646216576605,"mc":[{"id":"1.195453755","rc":[{"atl":[[16,9.9],[13.5,0],[14,4.95],[15.5,0]],"id":3805747},{"atl":[[150,0]],"id":522750}],"con":true,"img":false}]}
{"op":"mcm","clk":"5348333692","pt":1646216576698,"mc":[{"id":"1.195453755","rc":[{"atl":[[16.5,0],[17,9.9],[14.5,0],[15,4.95]],"id":3805746},{"atl":[[24,4.95],[26,6.34],[28,9.9],[30,0]],"id":3805755},{"atl":[[140,0],[150,4.95],[180,0],[190,9.9]],"id":522752},{"atl":[[85,23.5]],"id":3805762}],"con":true,"img":false}]}
{"op":"mcm","clk":"5348333701","pt":1646216576766,"mc":[{"id":"1.195453755","rc":[{"atl":[[46,2.22],[30,35.33]],"id":3805783},{"atb":[[9,24.76],[8.6,44.22]],"id":3805747},{"atb":[[2.52,4.95],[2.44,9.9],[2.14,138.92],[2.16,11.4]],"id":3805793},{"atl":[[3.55,31.99],[3.3,11.4],[3.75,0]],"id":3805793},{"atl":[[320,5.44]],"id":522749},{"atl":[[40,0]],"id":3805762},{"atl":[[290,0],[190,20.85]],"id":522742},{"atl":[[790,0],[780,0.2]],"id":522745}],"con":true,"img":false}]}
{"op":"mcm","clk":"5348333741","pt":1646216577077,"mc":[{"id":"1.195453755","rc":[{"atb":[[8.8,12.82],[7.8,0]],"id":3805784},{"atb":[[18,0],[22,8.02]],"id":522746},{"atl":[[340,8.1],[200,9.9]],"id":522750},{"atb":[[32,0],[36,2.86]],"id":522752},{"atb":[[36,0],[40,2.56]],"id":522742},{"atb":[[10,46.92],[9.4,0]],"id":3805740}],"con":true,"img":false}]}
{"op":"mcm","clk":"5348333751","pt":1646216577188,"mc":[{"id":"1.195453755","rc":[{"atl":[[24,11.84],[55,2],[28,34.06]],"id":3805755},{"atb":[[44,0]],"id":522746},{"atb":[[150,0],[75,2.72]],"id":522753},{"atl":[[780,2.65]],"id":522753}],"con":true,"img":false}]}
{"op":"mcm","clk":"5348333767","pt":1646216577295,"mc":[{"id":"1.195453755","rc":[{"atl":[[65,2.47]],"id":3805747},{"atl":[[960,2]],"id":522749},{"atl":[[160,5.95]],"id":522750},{"atb":[[14,0]],"id":3805730}],"con":true,"img":false}]}
{"op":"mcm","clk":"5348333781","pt":1646216577393,"mc":[{"id":"1.195453755","rc":[{"atl":[[16.5,10.22]],"id":3805746}],"con":true,"img":false}]}
{"op":"mcm","clk":"5348333790","pt":1646216577497,"mc":[{"id":"1.195453755","rc":[{"atl":[[16.5,20.13],[17,0],[14.5,4.95],[15,0]],"id":3805746},{"atl":[[3.5,0]],"id":3805793},{"atl":[[790,2.62]],"id":522745}],"con":true,"img":false}]}
{"op":"mcm","clk":"5348333828","pt":1646216577812,"mc":[{"id":"1.195453755","rc":[{"atl":[[65,24.56],[70,0]],"id":3805747}],"con":true,"img":false}]}
{"op":"mcm","clk":"5348333848","pt":1646216577976,"mc":[{"id":"1.195453755","rc":[{"atl":[[26,0]],"id":3805755}],"con":true,"img":false}]}
{"op":"mcm","clk":"5348333891","pt":1646216578400,"mc":[{"id":"1.195453755","rc":[{"atl":[[16,0],[16.5,9.9],[14,0],[14.5,4.95]],"id":3805747},{"atl":[[16.5,10.22],[17.5,9.9],[14.5,0],[15.5,4.95]],"id":3805746}],"con":true,"img":false}]}
{"op":"mcm","clk":"5348334073","pt":1646216580180,"mc":[{"id":"1.195453755","rc":[{"atb":[[34,6.29],[30,0]],"id":522750},{"atl":[[1000,2]],"id":522741},{"atb":[[10,35.81]],"id":3805740}],"con":true,"img":false}]}
{"op":"mcm","clk":"5348334083","pt":1646216580285,"mc":[{"id":"1.195453755","rc":[{"atb":[[8.4,13.51]],"id":3805740}],"con":true,"img":false}]}
{"op":"mcm","clk":"5348334245","pt":1646216581791,"mc":[{"id":"1.195453755","rc":[{"atl":[[130,0],[80,2]],"id":3805747},{"atb":[[1.89,112.36]],"id":3805793},{"atl":[[350,0]],"id":522742}],"con":true,"img":false}]}
{"op":"mcm","clk":"5348334259","pt":1646216581869,"mc":[{"id":"1.195453755","rc":[{"atl":[[70,2],[46,0]],"id":3805783},{"atb":[[1.8,0]],"id":3805793},{"atl":[[410,2]],"id":522742}],"con":true,"img":false}]}
{"op":"mcm","clk":"5348334306","pt":1646216582280,"mc":[{"id":"1.195453755","rc":[{"atb":[[10,11.11],[8.8,0]],"id":3805784}],"con":true,"img":false}]}
{"op":"mcm","clk":"5348334328","pt":1646216582496,"mc":[{"id":"1.195453755","rc":[{"atl":[[17.5,39.84]],"id":3805746},{"atb":[[85,0],[90,9.9],[110,1.45],[120,4.95]],"id":522741}],"con":true,"img":false}]}
{"op":"mcm","clk":"5348334371","pt":1646216582765,"mc":[{"id":"1.195453755","rc":[{"atl":[[29,3.57]],"id":3805746}],"con":true,"img":false}]}
{"op":"mcm","clk":"5348334397","pt":1646216582969,"mc":[{"id":"1.195453755","rc":[{"atl":[[16.5,0],[14.5,0]],"id":3805747},{"atl":[[270,8.28],[280,0]],"id":522752}],"con":true,"img":false}]}
{"op":"mcm","clk":"5348334411","pt":1646216583076,"mc":[{"id":"1.195453755","rc":[{"atl":[[16,9.9],[14,4.95]],"id":3805747},{"atl":[[17.5,29.93],[15.5,0]],"id":3805746},{"atl":[[150,6.01]],"id":522752},{"atb":[[12,0],[12.5,9.9],[14,12.19],[14.5,4.95]],"id":3805740}],"con":true,"img":false}]}
{"op":"mcm","clk":"5348334447","pt":1646216583381,"mc":[{"id":"1.195453755","rc":[{"atb":[[9.6,0],[8.6,40.95]],"id":3805747},{"atb":[[2.56,0],[2.66,0]],"id":3805793},{"atb":[[12,37.29],[9.8,0]],"id":3805731},{"atb":[[9.6,0],[11.5,0]],"id":3805730},{"atb":[[32,13.76],[26,0]],"id":522741},{"atb":[[32,0],[26,0]],"id":522742},{"atb":[[42,0],[55,0]],"id":522743},{"atb":[[42,0],[55,11.4]],"id":522745}],"con":true,"img":false}]}
{"op":"mcm","clk":"5348334486","pt":1646216583696,"mc":[{"id":"1.195453755","rc":[{"atb":[[2.5,4.95],[2.52,0],[2.44,0]],"id":3805793},{"atl":[[25,4.95],[26,0],[29,9.9],[30,0]],"id":3805730},{"atb":[[18.5,0]],"id":3805762}],"con":true,"img":false}]}
{"op":"mcm","clk":"5348334522","pt":1646216584011,"mc":[{"id":"1.195453755","rc":[{"atl":[[55,39.82],[28,9.9]],"id":3805755},{"atb":[[32,0],[90,20.69]],"id":522741}],"con":true,"img":false}]}
{"op":"mcm","clk":"5348334537","pt":1646216584072,"mc":[{"id":"1.195453755","rc":[{"atb":[[120,6.28]],"id":522741}],"con":true,"img":false}]}
{"op":"mcm","clk":"5348334549","pt":1646216584172,"mc":[{"id":"1.195453755","rc":[{"atl":[[65,2.47],[75,27.73]],"id":3805747}],"con":true,"img":false}]}
{"op":"mcm","clk":"5348334565","pt":1646216584280,"mc":[{"id":"1.195453755","rc":[{"atb":[[8.6,0],[8.2,61.15]],"id":3805747},{"atl":[[17.5,0]],"id":3805746},{"atb":[[16.5,9.9],[16,24.23],[14.5,9.9]],"id":3805762},{"atb":[[10,2.72],[12.5,32.23]],"id":3805740}],"con":true,"img":false}]}
{"op":"mcm","clk":"5348334598","pt":1646216584488,"mc":[{"id":"1.195453755","rc":[{"atb":[[14.5,16.69]],"id":3805740}],"con":true,"img":false}]}
{"op":"mcm","clk":"5348334610","pt":1646216584591,"mc":[{"id":"1.195453755","rc":[{"atl":[[16.5,20.13],[14.5,4.95]],"id":3805746},{"atl":[[270,7.69]],"id":522752},{"atb":[[40,0]],"id":522742}],"con":true,"img":false}]}
{"op":"mcm","clk":"5348334623","pt":1646216584696,"mc":[{"id":"1.195453755","rc":[{"atb":[[34,2.72],[27,3.26]],"id":522742},{"atb":[[44,3.26],[60,2.72]],"id":522745}],"con":true,"img":false}]}
{"op":"mcm","clk":"5348334632","pt":1646216584803,"mc":[{"id":"1.195453755","rc":[{"atb":[[8.4,3.26],[9.4,2.72]],"id":3805747},{"atb":[[2.52,3.26],[2.62,2.72]],"id":3805793},{"atb":[[10,3.26],[12.5,2.72]],"id":3805731},{"atb":[[34,2.72],[27,7.11]],"id":522741},{"atb":[[32,3.23]],"id":522742},{"atb":[[44,3.26],[60,2.72]],"id":522743}],"con":true,"img":false}]}
{"op":"mcm","clk":"5348334673","pt":1646216585079,"mc":[{"id":"1.195453755","rc":[{"atb":[[2.42,9.9]],"id":3805793},{"atl":[[100,0]],"id":522746},{"atl":[[340,6.1]],"id":522749},{"atb":[[12,2.72],[9.8,3.26]],"id":3805730},{"atb":[[120,21.21]],"id":522753},{"atb":[[55,0]],"id":522745}],"con":true,"img":false}]}
{"op":"mcm","clk":"5348334686","pt":1646216585186,"mc":[{"id":"1.195453755","rc":[{"atb":[[60,14.12]],"id":522745}],"con":true,"img":false}]}
{"op":"mcm","clk":"5348334699","pt":1646216585279,"mc":[{"id":"1.195453755","rc":[{"atl":[[280,0],[340,2]],"id":522746},{"atb":[[12,0]],"id":3805731}],"con":true,"img":false}]}
{"op":"mcm","clk":"5348334715","pt":1646216585384,"mc":[{"id":"1.195453755","rc":[{"atb":[[9.6,12.21]],"id":3805747},{"atb":[[2.5,19.66],[2.14,116.84]],"id":3805793},{"atb":[[12.5,24.81]],"id":3805731},{"atl":[[42,37.72],[85,2]],"id":3805762},{"atl":[[380,5.37]],"id":522745}],"con":true,"img":false}]}
{"op":"mcm","clk":"5348334729","pt":1646216585486,"mc":[{"id":"1.195453755","rc":[{"atl":[[280,7.42]],"id":522746},{"atb":[[110,0]],"id":522741},{"atb":[[10,13.83],[8.4,0]],"id":3805740}],"con":true,"img":false}]}
{"op":"mcm","clk":"5348334738","pt":1646216585591,"mc":[{"id":"1.195453755","rc":[{"atl":[[150,9.9]],"id":522746}],"con":true,"img":false}]}
{"op":"mcm","clk":"5348334768","pt":1646216585765,"mc":[{"id":"1.195453755","rc":[{"atb":[[14,0]],"id":3805740}],"con":true,"img":false}]}
{"op":"mcm","clk":"5348334792","pt":1646216585972,"mc":[{"id":"1.195453755","rc":[{"atl":[[14,17.15]],"id":3805747},{"atl":[[14.5,16.69]],"id":3805746}],"con":true,"img":false}]}
{"op":"mcm","clk":"5348334802","pt":1646216586076,"mc":[{"id":"1.195453755","rc":[{"atl":[[110,6.4]],"id":522746}],"con":true,"img":false}]}
{"op":"mcm","clk":"5348334821","pt":1646216586284,"mc":[{"id":"1.195453755","rc":[{"atb":[[9,4.95]],"id":3805747}],"con":true,"img":false}]}
{"op":"mcm","clk":"5348334836","pt":1646216586490,"mc":[{"id":"1.195453755","rc":[{"atl":[[75,0]],"id":3805747}],"con":true,"img":false}]}
{"op":"mcm","clk":"5348334848","pt":1646216586596,"mc":[{"id":"1.195453755","rc":[{"atl":[[780,0]],"id":522745}],"con":true,"img":false}]}
{"op":"mcm","clk":"5348334858","pt":1646216586699,"mc":[{"id":"1.195453755","rc":[{"atl":[[65,0]],"id":3805747}],"con":true,"img":false}]}
{"op":"mcm","clk":"5348334867","pt":1646216586761,"mc":[{"id":"1.195453755","rc":[{"atl":[[16.5,9.9]],"id":3805746}],"con":true,"img":false}]}
{"op":"mcm","clk":"5348334920","pt":1646216587184,"mc":[{"id":"1.195453755","rc":[{"atl":[[65,22.08]],"id":3805747}],"con":true,"img":false}]}
{"op":"mcm","clk":"5348334949","pt":1646216587384,"mc":[{"id":"1.195453755","rc":[{"atl":[[790,0]],"id":522745}],"con":true,"img":false}]}
{"op":"mcm","clk":"5348335138","pt":1646216588904,"mc":[{"id":"1.195453755","rc":[{"atb":[[34,14.12],[90,9.9]],"id":522741}],"con":true,"img":false}]}
{"op":"mcm","clk":"5348335161","pt":1646216589068,"mc":[{"id":"1.195453755","rc":[{"atb":[[10,59.21],[12.5,9.9]],"id":3805740}],"con":true,"img":false}]}
{"op":"mcm","clk":"5348335195","pt":1646216589379,"mc":[{"id":"1.195453755","rc":[{"atl":[[340,0],[960,4.15]],"id":522749}],"con":true,"img":false}]}
{"op":"mcm","clk":"5348335248","pt":1646216589798,"mc":[{"id":"1.195453755","rc":[{"atb":[[16,2.72],[17,9.9],[18,9.32],[19,4.95]],"id":3805784}],"con":true,"img":false}]}
{"op":"mcm","clk":"5348335303","pt":1646216590271,"mc":[{"id":"1.195453755","rc":[{"atb":[[17,33.15],[19.5,8.56],[13.5,3.26]],"id":3805784}],"con":true,"img":false}]}
{"op":"mcm","clk":"5348335397","pt":1646216591133,"mc":[{"id":"1.195453755","rc":[{"atb":[[18,0]],"id":3805784},{"atl":[[29,43.11]],"id":3805746}],"con":true,"img":false}]}
{"op":"mcm","clk":"5348335507","pt":1646216591994,"mc":[{"id":"1.195453755","rc":[{"atb":[[6.2,35.44]],"id":3805746}],"con":true,"img":false}]}
{"op":"mcm","clk":"5348335511","pt":1646216592102,"mc":[{"id":"1.195453755","rc":[{"atb":[[7.2,0]],"id":3805746}],"con":true,"img":false}]}
{"op":"mcm","clk":"5348335550","pt":1646216592576,"mc":[{"id":"1.195453755","rc":[{"atb":[[5.7,9.9],[5.4,127.94]],"id":3805746}],"con":true,"img":false}]}
{"op":"mcm","clk":"5348335575","pt":1646216592789,"mc":[{"id":"1.195453755","rc":[{"atb":[[7.6,2.72],[6.6,3.26]],"id":3805746}],"con":true,"img":false}]}
{"op":"mcm","clk":"5348335586","pt":1646216592890,"mc":[{"id":"1.195453755","rc":[{"atl":[[150,0],[160,9.9],[110,1.45],[120,4.95]],"id":522746}],"con":true,"img":false}]}
{"op":"mcm","clk":"5348335612","pt":1646216593095,"mc":[{"id":"1.195453755","rc":[{"atb":[[16.5,10.22],[17,4.95],[14.5,0],[15,9.9]],"id":3805731}],"con":true,"img":false}]}
{"op":"mcm","clk":"5348335642","pt":1646216593413,"mc":[{"id":"1.195453755","rc":[{"atb":[[9,37.84],[8.2,9.9]],"id":3805747}],"con":true,"img":false}]}
{"op":"mcm","clk":"5348335658","pt":1646216593574,"mc":[{"id":"1.195453755","rc":[{"atb":[[17,14.86]],"id":3805731}],"con":true,"img":false}]}
{"op":"mcm","clk":"5348335683","pt":1646216593781,"mc":[{"id":"1.195453755","rc":[{"atl":[[340,6.1],[960,2]],"id":522749}],"con":true,"img":false}]}
{"op":"mcm","clk":"5348335694","pt":1646216593887,"mc":[{"id":"1.195453755","rc":[{"atl":[[280,0],[160,22.9]],"id":522746},{"atb":[[15,31.99]],"id":3805731}],"con":true,"img":false}]}
{"op":"mcm","clk":"5348335706","pt":1646216593990,"mc":[{"id":"1.195453755","rc":[{"atb":[[12.5,2.72]],"id":3805731}],"con":true,"img":false}]}
{"op":"mcm","clk":"5348335739","pt":1646216594301,"mc":[{"id":"1.195453755","rc":[{"atl":[[790,2],[850,0]],"id":522747},{"atl":[[930,2],[1000,0]],"id":522741}],"con":true,"img":false}]}
{"op":"mcm","clk":"5348335750","pt":1646216594405,"mc":[{"id":"1.195453755","rc":[{"atb":[[16.5,0]],"id":3805731}],"con":true,"img":false}]}
{"op":"mcm","clk":"5348335760","pt":1646216594511,"mc":[{"id":"1.195453755","rc":[{"atl":[[16.5,0],[17,9.9],[14.5,0],[15,4.95]],"id":3805746}],"con":true,"img":false}]}
{"op":"mcm","clk":"5348335828","pt":1646216594984,"mc":[{"id":"1.195453755","rc":[{"atb":[[130,1.23],[150,4.95],[95,0],[110,9.9]],"id":522749}],"con":true,"img":false}]}
{"op":"mcm","clk":"5348335870","pt":1646216595304,"mc":[{"id":"1.195453755","rc":[{"atl":[[28,5.86]],"id":3805746}],"con":true,"img":false}]}
{"op":"mcm","clk":"5348335893","pt":1646216595505,"mc":[{"id":"1.195453755","rc":[{"atb":[[150,6.01],[48,2.13],[110,25.36]],"id":522749}],"con":true,"img":false}]}
{"op":"mcm","clk":"5348335903","pt":1646216595608,"mc":[{"id":"1.195453755","rc":[{"atl":[[32,10.06],[34,0],[40,9.9],[42,22.08]],"id":3805740}],"con":true,"img":false}]}
{"op":"mcm","clk":"5348335978","pt":1646216596189,"mc":[{"id":"1.195453755","rc":[{"atb":[[130,0]],"id":522749}],"con":true,"img":false}]}
{"op":"mcm","clk":"5348336015","pt":1646216596611,"mc":[{"id":"1.195453755","rc":[{"atl":[[160,4.95],[170,4.95],[210,9.9]],"id":522750}],"con":true,"img":false}]}
{"op":"mcm","clk":"5348336089","pt":1646216597094,"mc":[{"id":"1.195453755","rc":[{"atl":[[340,2],[200,20.3]],"id":522750}],"con":true,"img":false}]}
{"op":"mcm","clk":"5348336131","pt":1646216597405,"mc":[{"id":"1.195453755","rc":[{"atl":[[160,0],[200,10.39]],"id":522750}],"con":true,"img":false}]}
{"op":"mcm","clk":"5348336190","pt":1646216597876,"mc":[{"id":"1.195453755","rc":[{"atl":[[340,0],[960,4.15]],"id":522749},{"atl":[[170,5.89]],"id":522750},{"atb":[[12.5,32.17],[15,9.9]],"id":3805731}],"con":true,"img":false}]}
{"op":"mcm","clk":"5348336281","pt":1646216598710,"mc":[{"id":"1.195453755","rc":[{"atl":[[960,2]],"id":522749}],"con":true,"img":false}]}
{"op":"mcm","clk":"5348336305","pt":1646216598920,"mc":[{"id":"1.195453755","rc":[{"atl":[[150,0],[160,4.95],[190,0],[200,9.9]],"id":522752}],"con":true,"img":false}]}
{"op":"mcm","clk":"5348336338","pt":1646216599184,"mc":[{"id":"1.195453755","rc":[{"atb":[[22,4.76],[27,0]],"id":522746}],"con":true,"img":false}]}
{"op":"mcm","clk":"5348336350","pt":1646216599288,"mc":[{"id":"1.195453755","rc":[{"atb":[[8,0],[9,25.09]],"id":3805736},{"atb":[[34,0],[27,0]],"id":522742}],"con":true,"img":false}]}
{"op":"mcm","clk":"5348336372","pt":1646216599497,"mc":[{"id":"1.195453755","rc":[{"atl":[[28,21.95],[29,3.57]],"id":3805746},{"atb":[[48,18.33],[110,9.9]],"id":522749}],"con":true,"img":false}]}
{"op":"mcm","clk":"5348336392","pt":1646216599706,"mc":[{"id":"1.195453755","rc":[{"atl":[[160,4.95],[170,0.93],[200,20.3],[210,0]],"id":522750},{"atl":[[260,0.61]],"id":522752}],"con":true,"img":false}]}
{"op":"mcm","clk":"5348336408","pt":1646216599913,"mc":[{"id":"1.195453755","rc":[{"atb":[[23,3.26],[28,2.72]],"id":522746}],"con":true,"img":false}]}
{"op":"mcm","clk":"5348336415","pt":1646216600019,"mc":[{"id":"1.195453755","rc":[{"atb":[[9.2,2.72],[8.2,3.26]],"id":3805736},{"atb":[[36,2.72],[28,3.26]],"id":522742}],"con":true,"img":false}]}
{"op":"mcm","clk":"5348336431","pt":1646216600180,"mc":[{"id":"1.195453755","rc":[{"atl":[[260,8.6],[270,0]],"id":522752}],"con":true,"img":false}]}
{"op":"mcm","clk":"5348336459","pt":1646216600490,"mc":[{"id":"1.195453755","rc":[{"atb":[[9,0],[9.2,27.81]],"id":3805736}],"con":true,"img":false}]}
{"op":"mcm","clk":"5348336472","pt":1646216600596,"mc":[{"id":"1.195453755","rc":[{"atl":[[34,0],[42,29.45]],"id":3805731}],"con":true,"img":false}]}
{"op":"mcm","clk":"5348336482","pt":1646216600698,"mc":[{"id":"1.195453755","rc":[{"atl":[[32,9.46],[40,9.9]],"id":3805731}],"con":true,"img":false}]}
{"op":"mcm","clk":"5348336509","pt":1646216600905,"mc":[{"id":"1.195453755","rc":[{"atb":[[6.2,57.52],[5.4,30.27]],"id":3805746}],"con":true,"img":false}]}
{"op":"mcm","clk":"5348336520","pt":1646216601009,"mc":[{"id":"1.195453755","rc":[{"atl":[[80,28],[42,0]],"id":3805731}],"con":true,"img":false}]}
{"op":"mcm","clk":"5348336547","pt":1646216601325,"mc":[{"id":"1.195453755","rc":[{"atb":[[11,9.9],[12.5,0],[13,4.95]],"id":3805783},{"atb":[[65,0],[80,4.95],[48,17.77],[60,9.9]],"id":522742}],"con":true,"img":false}]}
{"op":"mcm","clk":"5348336592","pt":1646216601794,"mc":[{"id":"1.195453755","rc":[{"atb":[[85,1.88],[48,0],[60,24.62]],"id":522742}],"con":true,"img":false}]}
{"op":"mcm","clk":"5348336627","pt":1646216602210,"mc":[{"id":"1.195453755","rc":[{"atl":[[340,6.1]],"id":522749}],"con":true,"img":false}]}
{"op":"mcm","clk":"5348336649","pt":1646216602422,"mc":[{"id":"1.195453755","rc":[{"atl":[[890,2],[960,0]],"id":522749}],"con":true,"img":false}]}
{"op":"mcm","clk":"5348336670","pt":1646216602628,"mc":[{"id":"1.195453755","rc":[{"atb":[[70,0]],"id":522742}],"con":true,"img":false}]}
{"op":"mcm","clk":"5348336682","pt":1646216602735,"mc":[{"id":"1.195453755","rc":[{"atb":[[75,4.95],[46,19.85],[55,9.9],[60,0]],"id":522752},{"atb":[[130,1.23],[140,4.95],[95,0],[100,9.9]],"id":522745}],"con":true,"img":false}]}
{"op":"mcm","clk":"5348336707","pt":1646216602894,"mc":[{"id":"1.195453755","rc":[{"atb":[[19.5,0]],"id":3805784},{"atl":[[790,0],[930,2]],"id":522747},{"atb":[[34,3.26],[38,2.7]],"id":522750},{"atl":[[930,0]],"id":522741},{"atl":[[350,0],[340,4.95]],"id":522743}],"con":true,"img":false}]}
