{"op":"mcm","clk":"5345985303","pt":1646174444265,"mc":[{"id":"1.195453630","marketDefinition":{"bspMarket":true,"turnInPlayEnabled":false,"persistenceEnabled":false,"marketBaseRate":7.0,"eventId":"31272494","eventTypeId":"4339","numberOfWinners":2,"bettingType":"ODDS","marketType":"PLACE","marketTime":"2022-03-02T11:49:00.000Z","suspendTime":"2022-03-02T11:49:00.000Z","bspReconciled":false,"complete":true,"inPlay":false,"crossMatching":false,"runnersVoidable":false,"numberOfActiveRunners":6,"betDelay":0,"status":"OPEN","runners":[{"status":"ACTIVE","sortPriority":1,"id":40717352,"name":"1. Elswyk Shadow"},{"status":"ACTIVE","sortPriority":2,"id":39860456,"name":"2. Jax"},{"status":"ACTIVE","sortPriority":3,"id":37406513,"name":"3. Fab Rocket"},{"status":"ACTIVE","sortPriority":4,"id":41946970,"name":"4. Dashing Mini"},{"status":"ACTIVE","sortPriority":5,"id":39267517,"name":"6. Bull Montana"},{"status":"ACTIVE","sortPriority":6,"id":39931665,"name":"7. Elswyk Jordy"}],"regulators":["MR_INT"],"venue":"Traralgon","countryCode":"AU","discountAllowed":true,"timezone":"Australia/Sydney","openDate":"2022-03-02T08:31:00.000Z","version":4382425389,"name":"To Be Placed","eventName":"Traralgon (AUS) 2nd Mar"},"rc":[],"con":true,"img":false}]}
{"op":"mcm","clk":"5346059623","pt":1646175788371,"mc":[{"id":"1.195453630","rc":[{"atb":[[2.36,73.3],[2.26,79.12],[2.16,85.94]],"id":40717352},{"atl":[[7.4,11.32],[5.7,7.71],[9.4,8.63]],"id":40717352},{"spn":4.03,"spf":"NaN","id":40717352},{"atb":[[2.4,71.21],[2.5,66.46],[2.6,62.31]],"id":41946970},{"atl":[[6.2,6.97],[10.5,7.63],[8.2,10.07]],"id":41946970},{"spn":4.4,"spf":"NaN","id":41946970},{"atb":[[2.3,76.69],[2.2,83.08],[2.1,90.63]],"id":39931665},{"atl":[[5.6,7.88],[7.2,11.69],[9.2,8.84]],"id":39931665},{"spn":3.95,"spf":"NaN","id":39931665},{"atb":[[2.06,94.05],[1.98,101.73],[2.16,85.94]],"id":39267517},{"atl":[[6.8,12.5],[8.8,9.29],[5.4,8.24]],"id":39267517},{"spn":3.78,"spf":"NaN","id":39267517},{"atb":[[1.8,124.62],[1.85,117.29],[1.9,110.77]],"id":37406513},{"atl":[[4,12.08],[5,18.12],[6,14.5]],"id":37406513},{"spn":2.95,"spf":"NaN","id":37406513},{"atb":[[1.2,498.5],[1.25,398.8],[1.3,332.33]],"id":39860456},{"atl":[[2.54,23.54],[2.74,41.67],[2.94,37.37]],"id":39860456},{"spn":1.92,"spf":"NaN","id":39860456}],"con":true,"img":false}]}
{"op":"mcm","clk":"5346061998","pt":1646175839944,"mc":[{"id":"1.195453630","rc":[{"atb":[[2.36,0],[2.26,0],[2.16,0]],"id":40717352},{"atl":[[7.4,0],[5.7,0],[9.4,0]],"id":40717352},{"atb":[[2.4,0],[2.5,0],[2.6,0]],"id":41946970},{"atl":[[6.2,0],[10.5,0],[8.2,0]],"id":41946970},{"atb":[[2.3,0],[2.2,0],[2.1,0]],"id":39931665},{"atl":[[5.6,0],[7.2,0],[9.2,0]],"id":39931665},{"atb":[[2.06,0],[1.98,0],[2.16,0]],"id":39267517},{"atl":[[6.8,0],[8.8,0],[5.4,0]],"id":39267517},{"atb":[[1.8,0],[1.85,0],[1.9,0]],"id":37406513},{"atl":[[4,0],[5,0],[6,0]],"id":37406513},{"atb":[[1.2,0],[1.25,0],[1.3,0]],"id":39860456},{"atl":[[2.54,0],[2.74,0],[2.94,0]],"id":39860456}],"con":true,"img":false}]}
{"op":"mcm","clk":"5346062228","pt":1646175844782,"mc":[{"id":"1.195453630","rc":[{"atb":[[2.36,73.3],[2.26,79.12],[2.16,85.94]],"id":40717352},{"atl":[[7.4,11.32],[5.7,7.71],[9.4,8.63]],"id":40717352},{"atb":[[2.4,71.21],[2.5,66.46],[2.6,62.31]],"id":41946970},{"atl":[[6.2,6.97],[10.5,7.63],[8.2,10.07]],"id":41946970},{"atb":[[2.3,76.69],[2.2,83.08],[2.1,90.63]],"id":39931665},{"atl":[[5.6,7.88],[7.2,11.69],[9.2,8.84]],"id":39931665},{"atb":[[2.06,94.05],[1.98,101.73],[2.16,85.94]],"id":39267517},{"atl":[[6.8,12.5],[8.8,9.29],[5.4,8.24]],"id":39267517},{"atb":[[1.8,124.62],[1.85,117.29],[1.9,110.77]],"id":37406513},{"atl":[[4,12.08],[5,18.12],[6,14.5]],"id":37406513},{"atb":[[1.2,498.5],[1.25,398.8],[1.3,332.33]],"id":39860456},{"atl":[[2.54,23.54],[2.74,41.67],[2.94,37.37]],"id":39860456}],"con":true,"img":false}]}
{"op":"mcm","clk":"5346105185","pt":1646176602707,"mc":[{"id":"1.195453630","marketDefinition":{"bspMarket":true,"turnInPlayEnabled":false,"persistenceEnabled":false,"marketBaseRate":7.0,"eventId":"31272494","eventTypeId":"4339","numberOfWinners":2,"bettingType":"ODDS","marketType":"PLACE","marketTime":"2022-03-02T11:49:00.000Z","suspendTime":"2022-03-02T11:49:00.000Z","bspReconciled":false,"complete":true,"inPlay":false,"crossMatching":false,"runnersVoidable":false,"numberOfActiveRunners":6,"betDelay":0,"status":"OPEN","runners":[{"status":"ACTIVE","sortPriority":1,"id":40717352,"name":"1. Elswyk Shadow"},{"status":"ACTIVE","sortPriority":2,"id":39860456,"name":"2. Jax"},{"status":"ACTIVE","sortPriority":3,"id":37406513,"name":"3. Fab Rocket"},{"status":"ACTIVE","sortPriority":4,"id":41946970,"name":"4. Dashing Mini"},{"status":"ACTIVE","sortPriority":5,"id":39267517,"name":"6. Bull Montana"},{"status":"ACTIVE","sortPriority":6,"id":39931665,"name":"7. Elswyk Jordy"}],"regulators":["MR_INT"],"venue":"Traralgon","countryCode":"AU","discountAllowed":true,"timezone":"Australia/Sydney","openDate":"2022-03-02T08:31:00.000Z","version":4382425389,"name":"To Be Placed","eventName":"Traralgon (AUS) 2nd Mar"},"rc":[{"atb":[[2.36,73.3],[2.26,79.12],[2.16,85.94]],"id":40717352},{"atl":[[7.4,11.32],[5.7,7.71],[9.4,8.63]],"id":40717352},{"spn":4.03,"spf":"NaN","id":40717352},{"atb":[[2.4,71.21],[2.5,66.46],[2.6,62.31]],"id":41946970},{"atl":[[6.2,6.97],[10.5,7.63],[8.2,10.07]],"id":41946970},{"spn":4.4,"spf":"NaN","id":41946970},{"atb":[[2.3,76.69],[2.2,83.08],[2.1,90.63]],"id":39931665},{"atl":[[5.6,7.88],[7.2,11.69],[9.2,8.84]],"id":39931665},{"spn":3.95,"spf":"NaN","id":39931665},{"atb":[[2.06,94.05],[1.98,101.73],[2.16,85.94]],"id":39267517},{"atl":[[6.8,12.5],[8.8,9.29],[5.4,8.24]],"id":39267517},{"spn":3.78,"spf":"NaN","id":39267517},{"atb":[[1.8,124.62],[1.85,117.29],[1.9,110.77]],"id":37406513},{"atl":[[4,12.08],[5,18.12],[6,14.5]],"id":37406513},{"spn":2.95,"spf":"NaN","id":37406513},{"atb":[[1.2,498.5],[1.25,398.8],[1.3,332.33]],"id":39860456},{"atl":[[2.54,23.54],[2.74,41.67],[2.94,37.37]],"id":39860456},{"spn":1.92,"spf":"NaN","id":39860456}],"con":true,"img":true}]}
{"op":"mcm","clk":"5346136720","pt":1646177155076,"mc":[{"id":"1.195453630","rc":[{"atb":[[2.36,0],[2.26,0],[2.16,0]],"id":40717352},{"atl":[[7.4,0],[5.7,0],[9.4,0]],"id":40717352},{"spn":"NaN","spf":"NaN","id":40717352},{"atb":[[2.4,0],[2.5,0],[2.6,0]],"id":41946970},{"atl":[[6.2,0],[10.5,0],[8.2,0]],"id":41946970},{"spn":"NaN","spf":"NaN","id":41946970},{"atb":[[2.3,0],[2.2,0],[2.1,0]],"id":39931665},{"atl":[[5.6,0],[7.2,0],[9.2,0]],"id":39931665},{"spn":"NaN","spf":"NaN","id":39931665},{"atb":[[2.06,0],[1.98,0],[2.16,0]],"id":39267517},{"atl":[[6.8,0],[8.8,0],[5.4,0]],"id":39267517},{"spn":"NaN","spf":"NaN","id":39267517},{"atb":[[1.8,0],[1.85,0],[1.9,0]],"id":37406513},{"atl":[[4,0],[5,0],[6,0]],"id":37406513},{"spn":"NaN","spf":"NaN","id":37406513},{"atb":[[1.2,0],[1.25,0],[1.3,0]],"id":39860456},{"atl":[[2.54,0],[2.74,0],[2.94,0]],"id":39860456},{"spn":"NaN","spf":"NaN","id":39860456}],"con":true,"img":false}]}
{"op":"mcm","clk":"5346137122","pt":1646177162517,"mc":[{"id":"1.195453630","rc":[{"atb":[[2.36,73.3],[2.26,79.12],[2.16,85.94]],"id":40717352},{"atl":[[7.4,11.32],[5.7,7.71],[9.4,8.63]],"id":40717352},{"atb":[[2.86,53.6],[3.15,46.37],[2.96,50.86]],"id":41946970},{"atl":[[16,4.83],[11,7.25],[8.4,4.89]],"id":41946970},{"atb":[[2.06,94.05],[1.98,101.73],[2.16,85.94]],"id":39931665},{"atl":[[6.8,12.5],[8.8,9.29],[5.4,8.24]],"id":39931665},{"atb":[[2.8,55.38],[2.6,62.31],[2.7,58.64]],"id":39267517},{"atl":[[7.2,5.84],[9.2,8.84],[13,6.04]],"id":39267517},{"atb":[[1.8,124.62],[1.85,117.29],[1.9,110.77]],"id":37406513},{"atl":[[4,12.08],[5,18.12],[6,14.5]],"id":37406513},{"atb":[[1.2,498.5],[1.25,398.8],[1.3,332.33]],"id":39860456},{"atl":[[2.54,23.54],[2.74,41.67],[2.94,37.37]],"id":39860456}],"con":true,"img":false}]}
{"op":"mcm","clk":"5346162718","pt":1646177695576,"mc":[{"id":"1.195453630","rc":[{"atb":[[2.36,0],[2.26,0],[2.16,0]],"id":40717352},{"atl":[[7.4,0],[5.7,0],[9.4,0]],"id":40717352},{"spn":5.77,"spf":"NaN","id":41946970},{"spn":3.78,"spf":"NaN","id":39931665},{"atb":[[2.8,0],[2.6,0],[2.7,0]],"id":39267517},{"atl":[[7.2,0],[9.2,0],[13,0]],"id":39267517},{"spn":2.95,"spf":"NaN","id":37406513},{"atb":[[1.2,0],[1.25,0],[1.3,0]],"id":39860456},{"atl":[[2.54,0],[2.74,0],[2.94,0]],"id":39860456}],"con":true,"img":false}]}
{"op":"mcm","clk":"5346162904","pt":1646177698359,"mc":[{"id":"1.195453630","rc":[{"atb":[[2.06,94.05],[2.26,79.12],[2.16,85.94]],"id":40717352},{"atl":[[5.6,7.88],[7.2,11.69],[9.2,8.84]],"id":40717352},{"atb":[[2.82,54.77],[2.92,51.92],[3.05,48.63]],"id":39267517},{"atl":[[10.5,7.63],[8.2,5.03],[15.5,5]],"id":39267517},{"atb":[[1.2,498.5],[1.25,398.8],[1.3,332.33]],"id":39860456},{"atl":[[2.54,23.54],[2.74,41.67],[2.94,37.37]],"id":39860456}],"con":true,"img":false}]}
{"op":"mcm","clk":"5346322365","pt":1646180813493,"mc":[{"id":"1.195453630","rc":[{"atb":[[2.06,0],[2.26,0],[2.16,0]],"id":40717352},{"atl":[[5.6,0],[7.2,0],[9.2,0]],"id":40717352},{"atb":[[2.86,0],[3.15,0],[2.96,0]],"id":41946970},{"atl":[[16,0],[11,0],[8.4,0]],"id":41946970},{"spn":"NaN","spf":"NaN","id":41946970},{"atb":[[2.06,0],[1.98,0],[2.16,0]],"id":39931665},{"atl":[[6.8,0],[8.8,0],[5.4,0]],"id":39931665},{"spn":"NaN","spf":"NaN","id":39931665},{"atb":[[2.82,0],[2.92,0],[3.05,0]],"id":39267517},{"atl":[[10.5,0],[8.2,0],[15.5,0]],"id":39267517},{"atb":[[1.8,124.64],[1.85,117.3],[1.9,110.79]],"id":37406513},{"atl":[[4,12.08],[5,18.12],[6,14.5]],"id":37406513},{"atb":[[1.2,498.55],[1.25,398.84],[1.3,332.37]],"id":39860456},{"atl":[[2.54,23.54],[2.74,41.67],[2.94,37.38]],"id":39860456},{"spn":1.92,"spf":"NaN","id":39860456}],"con":true,"img":false}]}
{"op":"mcm","clk":"5346323000","pt":1646180826367,"mc":[{"id":"1.195453630","rc":[{"atb":[[2.06,94.06],[2.26,79.13],[2.16,85.95]],"id":40717352},{"atl":[[5.6,7.88],[7.2,11.69],[9.2,8.84]],"id":40717352},{"atb":[[3.45,40.7],[3.2,45.32],[2.98,50.35]],"id":41946970},{"atl":[[18.5,4.14],[13.5,5.8],[9.4,4.31]],"id":41946970},{"atb":[[2.06,94.06],[1.98,101.74],[1.93,107.21]],"id":39931665},{"atl":[[6.4,13.43],[5.2,8.63],[8.4,9.79]],"id":39931665},{"atb":[[2.86,53.6],[3.15,46.37],[2.96,50.87]],"id":39267517},{"atl":[[16,4.83],[11,7.25],[8.4,4.89]],"id":39267517}],"con":true,"img":false}]}
{"op":"mcm","clk":"5346401641","pt":1646182002790,"mc":[{"id":"1.195453630","marketDefinition":{"bspMarket":true,"turnInPlayEnabled":false,"persistenceEnabled":false,"marketBaseRate":7.0,"eventId":"31272494","eventTypeId":"4339","numberOfWinners":2,"bettingType":"ODDS","marketType":"PLACE","marketTime":"2022-03-02T11:49:00.000Z","suspendTime":"2022-03-02T11:49:00.000Z","bspReconciled":false,"complete":true,"inPlay":false,"crossMatching":false,"runnersVoidable":false,"numberOfActiveRunners":6,"betDelay":0,"status":"OPEN","runners":[{"status":"ACTIVE","sortPriority":1,"id":40717352,"name":"1. Elswyk Shadow"},{"status":"ACTIVE","sortPriority":2,"id":39860456,"name":"2. Jax"},{"status":"ACTIVE","sortPriority":3,"id":37406513,"name":"3. Fab Rocket"},{"status":"ACTIVE","sortPriority":4,"id":41946970,"name":"4. Dashing Mini"},{"status":"ACTIVE","sortPriority":5,"id":39267517,"name":"6. Bull Montana"},{"status":"ACTIVE","sortPriority":6,"id":39931665,"name":"7. Elswyk Jordy"}],"regulators":["MR_INT"],"venue":"Traralgon","countryCode":"AU","discountAllowed":true,"timezone":"Australia/Sydney","openDate":"2022-03-02T08:31:00.000Z","version":4382425389,"name":"To Be Placed","eventName":"Traralgon (AUS) 2nd Mar"},"rc":[{"atb":[[2.06,94.06],[2.26,79.13],[2.16,85.95]],"id":40717352},{"atl":[[5.6,7.88],[7.2,11.69],[9.2,8.84]],"id":40717352},{"spn":3.93,"spf":"NaN","id":40717352},{"atb":[[3.45,40.7],[3.2,45.32],[2.98,50.35]],"id":41946970},{"atl":[[18.5,4.14],[13.5,5.8],[9.4,4.31]],"id":41946970},{"spn":6.42,"spf":"NaN","id":41946970},{"atb":[[2.06,94.06],[1.98,101.74],[1.93,107.21]],"id":39931665},{"atl":[[6.4,13.43],[5.2,8.63],[8.4,9.79]],"id":39931665},{"spn":3.63,"spf":"NaN","id":39931665},{"atb":[[2.86,53.6],[3.15,46.37],[2.96,50.87]],"id":39267517},{"atl":[[16,4.83],[11,7.25],[8.4,4.89]],"id":39267517},{"spn":5.77,"spf":"NaN","id":39267517},{"atb":[[1.8,124.64],[1.85,117.3],[1.9,110.79]],"id":37406513},{"atl":[[4,12.08],[5,18.12],[6,14.5]],"id":37406513},{"spn":2.95,"spf":"NaN","id":37406513},{"atb":[[1.2,498.55],[1.25,398.84],[1.3,332.37]],"id":39860456},{"atl":[[2.54,23.54],[2.74,41.67],[2.94,37.38]],"id":39860456},{"spn":1.92,"spf":"NaN","id":39860456}],"con":true,"img":true}]}
{"op":"mcm","clk":"5346767995","pt":1646187402735,"mc":[{"id":"1.195453630","marketDefinition":{"bspMarket":true,"turnInPlayEnabled":false,"persistenceEnabled":false,"marketBaseRate":7.0,"eventId":"31272494","eventTypeId":"4339","numberOfWinners":2,"bettingType":"ODDS","marketType":"PLACE","marketTime":"2022-03-02T11:49:00.000Z","suspendTime":"2022-03-02T11:49:00.000Z","bspReconciled":false,"complete":true,"inPlay":false,"crossMatching":false,"runnersVoidable":false,"numberOfActiveRunners":6,"betDelay":0,"status":"OPEN","runners":[{"status":"ACTIVE","sortPriority":1,"id":40717352,"name":"1. Elswyk Shadow"},{"status":"ACTIVE","sortPriority":2,"id":39860456,"name":"2. Jax"},{"status":"ACTIVE","sortPriority":3,"id":37406513,"name":"3. Fab Rocket"},{"status":"ACTIVE","sortPriority":4,"id":41946970,"name":"4. Dashing Mini"},{"status":"ACTIVE","sortPriority":5,"id":39267517,"name":"6. Bull Montana"},{"status":"ACTIVE","sortPriority":6,"id":39931665,"name":"7. Elswyk Jordy"}],"regulators":["MR_INT"],"venue":"Traralgon","countryCode":"AU","discountAllowed":true,"timezone":"Australia/Sydney","openDate":"2022-03-02T08:31:00.000Z","version":4382425389,"name":"To Be Placed","eventName":"Traralgon (AUS) 2nd Mar"},"rc":[{"atb":[[2.06,94.21],[2.26,79.26],[2.16,86.09]],"id":40717352},{"atl":[[5.6,7.89],[7.2,11.71],[9.2,8.85]],"id":40717352},{"spn":3.93,"spf":"NaN","id":40717352},{"atb":[[3.45,40.76],[3.2,45.39],[2.98,50.43]],"id":41946970},{"atl":[[18.5,4.14],[13.5,5.81],[9.4,4.32]],"id":41946970},{"spn":6.42,"spf":"NaN","id":41946970},{"atb":[[2.06,94.21],[1.98,101.9],[1.93,107.38]],"id":39931665},{"atl":[[6.4,13.45],[5.2,8.64],[8.4,9.81]],"id":39931665},{"spn":3.63,"spf":"NaN","id":39931665},{"atb":[[2.86,53.69],[3.15,46.45],[2.96,50.95]],"id":39267517},{"atl":[[16,4.84],[11,7.26],[8.4,4.9]],"id":39267517},{"spn":5.77,"spf":"NaN","id":39267517},{"atb":[[1.8,124.83],[1.85,117.49],[1.9,110.96]],"id":37406513},{"atl":[[4,12.1],[5,18.15],[6,14.52]],"id":37406513},{"spn":2.95,"spf":"NaN","id":37406513},{"atb":[[1.2,499.34],[1.25,399.47],[1.3,332.89]],"id":39860456},{"atl":[[2.54,23.58],[2.74,41.74],[2.94,37.43]],"id":39860456},{"spn":1.92,"spf":"NaN","id":39860456}],"con":true,"img":true}]}
{"op":"mcm","clk":"5347092546","pt":1646192802714,"mc":[{"id":"1.195453630","marketDefinition":{"bspMarket":true,"turnInPlayEnabled":false,"persistenceEnabled":false,"marketBaseRate":7.0,"eventId":"31272494","eventTypeId":"4339","numberOfWinners":2,"bettingType":"ODDS","marketType":"PLACE","marketTime":"2022-03-02T11:49:00.000Z","suspendTime":"2022-03-02T11:49:00.000Z","bspReconciled":false,"complete":true,"inPlay":false,"crossMatching":false,"runnersVoidable":false,"numberOfActiveRunners":6,"betDelay":0,"status":"OPEN","runners":[{"status":"ACTIVE","sortPriority":1,"id":40717352,"name":"1. Elswyk Shadow"},{"status":"ACTIVE","sortPriority":2,"id":39860456,"name":"2. Jax"},{"status":"ACTIVE","sortPriority":3,"id":37406513,"name":"3. Fab Rocket"},{"status":"ACTIVE","sortPriority":4,"id":41946970,"name":"4. Dashing Mini"},{"status":"ACTIVE","sortPriority":5,"id":39267517,"name":"6. Bull Montana"},{"status":"ACTIVE","sortPriority":6,"id":39931665,"name":"7. Elswyk Jordy"}],"regulators":["MR_INT"],"venue":"Traralgon","countryCode":"AU","discountAllowed":true,"timezone":"Australia/Sydney","openDate":"2022-03-02T08:31:00.000Z","version":4382425389,"name":"To Be Placed","eventName":"Traralgon (AUS) 2nd Mar"},"rc":[{"atb":[[2.06,94.37],[2.26,79.39],[2.16,86.24]],"id":40717352},{"atl":[[5.6,7.9],[7.2,11.73],[9.2,8.87]],"id":40717352},{"spn":3.93,"spf":"NaN","id":40717352},{"atb":[[3.45,40.83],[3.2,45.47],[2.98,50.52]],"id":41946970},{"atl":[[18.5,4.15],[13.5,5.82],[9.4,4.33]],"id":41946970},{"spn":6.42,"spf":"NaN","id":41946970},{"atb":[[2.06,94.37],[1.98,102.08],[1.93,107.57]],"id":39931665},{"atl":[[6.4,13.47],[5.2,8.66],[8.4,9.83]],"id":39931665},{"spn":3.63,"spf":"NaN","id":39931665},{"atb":[[2.86,53.78],[3.15,46.53],[2.96,51.03]],"id":39267517},{"atl":[[16,4.85],[11,7.27],[8.4,4.91]],"id":39267517},{"spn":5.77,"spf":"NaN","id":39267517},{"atb":[[1.8,125.04],[1.85,117.69],[1.9,111.15]],"id":37406513},{"atl":[[4,12.12],[5,18.18],[6,14.55]],"id":37406513},{"spn":2.95,"spf":"NaN","id":37406513},{"atb":[[1.2,500.19],[1.25,400.15],[1.3,333.46]],"id":39860456},{"atl":[[2.54,23.62],[2.74,41.81],[2.94,37.5]],"id":39860456},{"spn":1.92,"spf":"NaN","id":39860456}],"con":true,"img":true}]}
{"op":"mcm","clk":"5347381400","pt":1646198202731,"mc":[{"id":"1.195453630","marketDefinition":{"bspMarket":true,"turnInPlayEnabled":false,"persistenceEnabled":false,"marketBaseRate":7.0,"eventId":"31272494","eventTypeId":"4339","numberOfWinners":2,"bettingType":"ODDS","marketType":"PLACE","marketTime":"2022-03-02T11:49:00.000Z","suspendTime":"2022-03-02T11:49:00.000Z","bspReconciled":false,"complete":true,"inPlay":false,"crossMatching":false,"runnersVoidable":false,"numberOfActiveRunners":6,"betDelay":0,"status":"OPEN","runners":[{"status":"ACTIVE","sortPriority":1,"id":40717352,"name":"1. Elswyk Shadow"},{"status":"ACTIVE","sortPriority":2,"id":39860456,"name":"2. Jax"},{"status":"ACTIVE","sortPriority":3,"id":37406513,"name":"3. Fab Rocket"},{"status":"ACTIVE","sortPriority":4,"id":41946970,"name":"4. Dashing Mini"},{"status":"ACTIVE","sortPriority":5,"id":39267517,"name":"6. Bull Montana"},{"status":"ACTIVE","sortPriority":6,"id":39931665,"name":"7. Elswyk Jordy"}],"regulators":["MR_INT"],"venue":"Traralgon","countryCode":"AU","discountAllowed":true,"timezone":"Australia/Sydney","openDate":"2022-03-02T08:31:00.000Z","version":4382425389,"name":"To Be Placed","eventName":"Traralgon (AUS) 2nd Mar"},"rc":[{"atb":[[2.06,94.33],[2.26,79.36],[2.16,86.2]],"id":40717352},{"atl":[[5.6,7.9],[7.2,11.72],[9.2,8.86]],"id":40717352},{"spn":3.93,"spf":"NaN","id":40717352},{"atb":[[3.45,40.81],[3.2,45.45],[2.98,50.5]],"id":41946970},{"atl":[[18.5,4.15],[13.5,5.82],[9.4,4.32]],"id":41946970},{"spn":6.42,"spf":"NaN","id":41946970},{"atb":[[2.06,94.33],[1.98,102.04],[1.93,107.52]],"id":39931665},{"atl":[[6.4,13.46],[5.2,8.65],[8.4,9.82]],"id":39931665},{"spn":3.63,"spf":"NaN","id":39931665},{"atb":[[2.86,53.76],[3.15,46.51],[2.96,51.01]],"id":39267517},{"atl":[[16,4.84],[11,7.27],[8.4,4.91]],"id":39267517},{"spn":5.77,"spf":"NaN","id":39267517},{"atb":[[1.8,125],[1.85,117.64],[1.9,111.11]],"id":37406513},{"atl":[[4,12.12],[5,18.18],[6,14.54]],"id":37406513},{"spn":2.95,"spf":"NaN","id":37406513},{"atb":[[1.2,500],[1.25,400],[1.3,333.33]],"id":39860456},{"atl":[[2.54,23.61],[2.74,41.79],[2.94,37.48]],"id":39860456},{"spn":1.92,"spf":"NaN","id":39860456}],"con":true,"img":true}]}
{"op":"mcm","clk":"5347430686","pt":1646199232063,"mc":[{"id":"1.195453630","rc":[{"atb":[[2.06,94.33],[2.26,79.36],[2.16,86.2]],"id":40717352},{"atl":[[5.6,7.9],[7.2,11.72],[9.2,8.86]],"id":40717352},{"spn":3.93,"spf":"NaN","id":40717352},{"atb":[[3.45,40.81],[3.2,45.45],[2.98,50.5]],"id":41946970},{"atl":[[18.5,4.15],[13.5,5.82],[9.4,4.32]],"id":41946970},{"spn":6.42,"spf":"NaN","id":41946970},{"atb":[[2.06,94.33],[1.98,102.04],[1.93,107.52]],"id":39931665},{"atl":[[6.4,13.46],[5.2,8.65],[8.4,9.82]],"id":39931665},{"spn":3.63,"spf":"NaN","id":39931665},{"atb":[[2.86,53.76],[3.15,46.51],[2.96,51.01]],"id":39267517},{"atl":[[16,4.84],[11,7.27],[8.4,4.91]],"id":39267517},{"spn":5.77,"spf":"NaN","id":39267517},{"atb":[[1.8,0],[1.85,0],[1.9,0]],"id":37406513},{"atl":[[4,0],[5,0],[6,0]],"id":37406513},{"spn":"NaN","spf":"NaN","id":37406513},{"atb":[[1.2,500],[1.25,400],[1.3,333.33]],"id":39860456},{"atl":[[2.54,23.61],[2.74,41.79],[2.94,37.48]],"id":39860456}],"con":true,"img":false}]}
{"op":"mcm","clk":"5347431115","pt":1646199241453,"mc":[{"id":"1.195453630","rc":[{"atb":[[1.85,117.64],[1.9,111.11],[1.95,105.26]],"id":37406513},{"atl":[[5.6,15.81],[7.2,11.72],[4.6,10.1]],"id":37406513}],"con":true,"img":false}]}
{"op":"mcm","clk":"5347624546","pt":1646203602735,"mc":[{"id":"1.195453630","marketDefinition":{"bspMarket":true,"turnInPlayEnabled":false,"persistenceEnabled":false,"marketBaseRate":7.0,"eventId":"31272494","eventTypeId":"4339","numberOfWinners":2,"bettingType":"ODDS","marketType":"PLACE","marketTime":"2022-03-02T11:49:00.000Z","suspendTime":"2022-03-02T11:49:00.000Z","bspReconciled":false,"complete":true,"inPlay":false,"crossMatching":false,"runnersVoidable":false,"numberOfActiveRunners":6,"betDelay":0,"status":"OPEN","runners":[{"status":"ACTIVE","sortPriority":1,"id":40717352,"name":"1. Elswyk Shadow"},{"status":"ACTIVE","sortPriority":2,"id":39860456,"name":"2. Jax"},{"status":"ACTIVE","sortPriority":3,"id":37406513,"name":"3. Fab Rocket"},{"status":"ACTIVE","sortPriority":4,"id":41946970,"name":"4. Dashing Mini"},{"status":"ACTIVE","sortPriority":5,"id":39267517,"name":"6. Bull Montana"},{"status":"ACTIVE","sortPriority":6,"id":39931665,"name":"7. Elswyk Jordy"}],"regulators":["MR_INT"],"venue":"Traralgon","countryCode":"AU","discountAllowed":true,"timezone":"Australia/Sydney","openDate":"2022-03-02T08:31:00.000Z","version":4382425389,"name":"To Be Placed","eventName":"Traralgon (AUS) 2nd Mar"},"rc":[{"atb":[[2.06,94.33],[2.26,79.36],[2.16,86.2]],"id":40717352},{"atl":[[5.6,7.9],[7.2,11.72],[9.2,8.86]],"id":40717352},{"spn":3.93,"spf":"NaN","id":40717352},{"atb":[[3.45,40.81],[3.2,45.45],[2.98,50.5]],"id":41946970},{"atl":[[18.5,4.15],[13.5,5.82],[9.4,4.32]],"id":41946970},{"spn":6.42,"spf":"NaN","id":41946970},{"atb":[[2.06,94.33],[1.98,102.04],[1.93,107.52]],"id":39931665},{"atl":[[6.4,13.46],[5.2,8.65],[8.4,9.82]],"id":39931665},{"spn":3.63,"spf":"NaN","id":39931665},{"atb":[[2.86,53.76],[3.15,46.51],[2.96,51.01]],"id":39267517},{"atl":[[16,4.84],[11,7.27],[8.4,4.91]],"id":39267517},{"spn":5.77,"spf":"NaN","id":39267517},{"atb":[[1.85,117.64],[1.9,111.11],[1.95,105.26]],"id":37406513},{"atl":[[5.6,15.81],[7.2,11.72],[4.6,10.1]],"id":37406513},{"spn":3.27,"spf":"NaN","id":37406513},{"atb":[[1.2,500],[1.25,400],[1.3,333.33]],"id":39860456},{"atl":[[2.54,23.61],[2.74,41.79],[2.94,37.48]],"id":39860456},{"spn":1.92,"spf":"NaN","id":39860456}],"con":true,"img":true}]}
{"op":"mcm","clk":"5347849097","pt":1646209002736,"mc":[{"id":"1.195453630","marketDefinition":{"bspMarket":true,"turnInPlayEnabled":false,"persistenceEnabled":false,"marketBaseRate":7.0,"eventId":"31272494","eventTypeId":"4339","numberOfWinners":2,"bettingType":"ODDS","marketType":"PLACE","marketTime":"2022-03-02T11:49:00.000Z","suspendTime":"2022-03-02T11:49:00.000Z","bspReconciled":false,"complete":true,"inPlay":false,"crossMatching":false,"runnersVoidable":false,"numberOfActiveRunners":6,"betDelay":0,"status":"OPEN","runners":[{"status":"ACTIVE","sortPriority":1,"id":40717352,"name":"1. Elswyk Shadow"},{"status":"ACTIVE","sortPriority":2,"id":39860456,"name":"2. Jax"},{"status":"ACTIVE","sortPriority":3,"id":37406513,"name":"3. Fab Rocket"},{"status":"ACTIVE","sortPriority":4,"id":41946970,"name":"4. Dashing Mini"},{"status":"ACTIVE","sortPriority":5,"id":39267517,"name":"6. Bull Montana"},{"status":"ACTIVE","sortPriority":6,"id":39931665,"name":"7. Elswyk Jordy"}],"regulators":["MR_INT"],"venue":"Traralgon","countryCode":"AU","discountAllowed":true,"timezone":"Australia/Sydney","openDate":"2022-03-02T08:31:00.000Z","version":4382425389,"name":"To Be Placed","eventName":"Traralgon (AUS) 2nd Mar"},"rc":[{"atb":[[2.06,94.31],[2.26,79.34],[2.16,86.18]],"id":40717352},{"atl":[[5.6,7.9],[7.2,11.72],[9.2,8.86]],"id":40717352},{"spn":3.93,"spf":"NaN","id":40717352},{"atb":[[3.45,40.8],[3.2,45.44],[2.98,50.49]],"id":41946970},{"atl":[[18.5,4.15],[13.5,5.81],[9.4,4.32]],"id":41946970},{"spn":6.42,"spf":"NaN","id":41946970},{"atb":[[2.06,94.31],[1.98,102.01],[1.93,107.5]],"id":39931665},{"atl":[[6.4,13.46],[5.2,8.65],[8.4,9.82]],"id":39931665},{"spn":3.63,"spf":"NaN","id":39931665},{"atb":[[2.86,53.75],[3.15,46.5],[2.96,51]],"id":39267517},{"atl":[[16,4.84],[11,7.27],[8.4,4.91]],"id":39267517},{"spn":5.77,"spf":"NaN","id":39267517},{"atb":[[1.85,117.61],[1.9,111.08],[1.95,105.23]],"id":37406513},{"atl":[[5.6,15.8],[7.2,11.72],[4.6,10.09]],"id":37406513},{"spn":3.27,"spf":"NaN","id":37406513},{"atb":[[1.2,499.86],[1.25,399.89],[1.3,333.24]],"id":39860456},{"atl":[[2.54,23.6],[2.74,41.78],[2.94,37.47]],"id":39860456},{"spn":1.92,"spf":"NaN","id":39860456}],"con":true,"img":true}]}
{"op":"mcm","clk":"5348133280","pt":1646214402747,"mc":[{"id":"1.195453630","marketDefinition":{"bspMarket":true,"turnInPlayEnabled":false,"persistenceEnabled":false,"marketBaseRate":7.0,"eventId":"31272494","eventTypeId":"4339","numberOfWinners":2,"bettingType":"ODDS","marketType":"PLACE","marketTime":"2022-03-02T11:49:00.000Z","suspendTime":"2022-03-02T11:49:00.000Z","bspReconciled":false,"complete":true,"inPlay":false,"crossMatching":false,"runnersVoidable":false,"numberOfActiveRunners":6,"betDelay":0,"status":"OPEN","runners":[{"status":"ACTIVE","sortPriority":1,"id":40717352,"name":"1. Elswyk Shadow"},{"status":"ACTIVE","sortPriority":2,"id":39860456,"name":"2. Jax"},{"status":"ACTIVE","sortPriority":3,"id":37406513,"name":"3. Fab Rocket"},{"status":"ACTIVE","sortPriority":4,"id":41946970,"name":"4. Dashing Mini"},{"status":"ACTIVE","sortPriority":5,"id":39267517,"name":"6. Bull Montana"},{"status":"ACTIVE","sortPriority":6,"id":39931665,"name":"7. Elswyk Jordy"}],"regulators":["MR_INT"],"venue":"Traralgon","countryCode":"AU","discountAllowed":true,"timezone":"Australia/Sydney","openDate":"2022-03-02T08:31:00.000Z","version":4382425389,"name":"To Be Placed","eventName":"Traralgon (AUS) 2nd Mar"},"rc":[{"atb":[[2.06,94.16],[2.26,79.21],[2.16,86.04]],"id":40717352},{"atl":[[5.6,7.89],[7.2,11.7],[9.2,8.85]],"id":40717352},{"spn":3.93,"spf":"NaN","id":40717352},{"atb":[[3.45,40.74],[3.2,45.37],[2.98,50.41]],"id":41946970},{"atl":[[18.5,4.14],[13.5,5.8],[9.4,4.32]],"id":41946970},{"spn":6.42,"spf":"NaN","id":41946970},{"atb":[[2.06,94.16],[1.98,101.85],[1.93,107.33]],"id":39931665},{"atl":[[6.4,13.44],[5.2,8.64],[8.4,9.8]],"id":39931665},{"spn":3.63,"spf":"NaN","id":39931665},{"atb":[[2.86,53.66],[3.15,46.42],[2.96,50.92]],"id":39267517},{"atl":[[16,4.83],[11,7.25],[8.4,4.9]],"id":39267517},{"spn":5.77,"spf":"NaN","id":39267517},{"atb":[[1.85,117.42],[1.9,110.9],[1.95,105.06]],"id":37406513},{"atl":[[5.6,15.78],[7.2,11.7],[4.6,10.08]],"id":37406513},{"spn":3.27,"spf":"NaN","id":37406513},{"atb":[[1.2,499.07],[1.25,399.25],[1.3,332.71]],"id":39860456},{"atl":[[2.54,23.57],[2.74,41.71],[2.94,37.41]],"id":39860456},{"spn":1.92,"spf":"NaN","id":39860456}],"con":true,"img":true}]}
{"op":"mcm","clk":"5348231673","pt":1646215731624,"mc":[{"id":"1.195453630","rc":[{"atb":[[2.06,94.16],[2.26,79.21],[2.16,86.04]],"id":40717352},{"atl":[[5.6,7.89],[7.2,11.7],[9.2,8.85]],"id":40717352},{"atb":[[3.45,40.74],[3.2,45.37],[2.98,50.41]],"id":41946970},{"atl":[[18.5,4.14],[13.5,5.8],[9.4,4.32]],"id":41946970},{"atb":[[2.06,94.16],[1.98,101.85],[1.93,107.33]],"id":39931665},{"atl":[[6.4,13.44],[5.2,8.64],[8.4,9.8]],"id":39931665},{"atb":[[2.86,53.66],[3.15,46.42],[2.96,50.92]],"id":39267517},{"atl":[[16,4.83],[11,7.25],[8.4,4.9]],"id":39267517},{"atb":[[1.85,117.42],[1.9,110.9],[1.95,105.06]],"id":37406513},{"atl":[[5.6,15.78],[7.2,11.7],[4.6,10.08]],"id":37406513},{"spn":3.27,"spf":"NaN","id":37406513},{"atb":[[1.2,499.07],[1.25,399.25],[1.3,332.71]],"id":39860456},{"spl":[[1.01,5.17]],"id":39860456},{"atl":[[2.54,23.57],[2.74,41.71],[2.94,37.41]],"id":39860456},{"spn":1.3,"spf":1.0,"id":39860456}],"con":true,"img":false}]}
{"op":"mcm","clk":"5348316022","pt":1646216424319,"mc":[{"id":"1.195453630","rc":[{"atb":[[2.18,55.04],[2.34,34.06]],"id":40717352},{"atl":[[9,13.62]],"id":40717352},{"spn":3.97,"spf":"NaN","id":40717352},{"atb":[[2.88,33.24],[3.25,19.37]],"id":41946970},{"atl":[[14.5,3.23],[15.5,4.35]],"id":41946970},{"atb":[[1.79,55.19],[1.66,83.19]],"id":39931665},{"atl":[[5.6,9.47],[6,10.56]],"id":39931665},{"atb":[[2.6,39.23],[2.98,22.01]],"id":39267517},{"atl":[[13.5,3.48],[14,4.9]],"id":39267517},{"atb":[[1.63,86.93],[1.74,58.91]],"id":37406513},{"atl":[[5.3,9.68],[5.5,12.16]],"id":37406513},{"atb":[[1.36,121.1],[1.31,193.82]],"id":39860456},{"atl":[[2.72,25.34],[3.4,25.03]],"id":39860456},{"spn":1.36,"spf":1.0,"id":39860456}],"con":true,"img":false}]}
{"op":"mcm","clk":"5348325088","pt":1646216509680,"mc":[{"id":"1.195453630","rc":[{"atb":[[2.18,0]],"id":40717352},{"atl":[[9,8.17]],"id":40717352},{"atb":[[2.88,0]],"id":41946970},{"atl":[[2.72,0]],"id":39860456}],"con":true,"img":false}]}
{"op":"mcm","clk":"5348325097","pt":1646216509782,"mc":[{"id":"1.195453630","rc":[{"atb":[[2.28,55.04]],"id":40717352},{"atl":[[7,5.44]],"id":40717352},{"atb":[[3,33.24]],"id":41946970},{"atl":[[2.52,25.34]],"id":39860456}],"con":true,"img":false}]}
{"op":"mcm","clk":"5348495163","pt":1646218197802,"mc":[{"id":"1.195453630","rc":[{"atb":[[2.36,55.04]],"id":40717352},{"atl":[[11.5,9.52]],"id":40717352},{"spn":3.98,"spf":"NaN","id":40717352},{"atb":[[3.5,40]],"id":41946970},{"atl":[[30,3.45]],"id":41946970},{"spn":6.45,"spf":"NaN","id":41946970},{"atb":[[1.39,188.32]],"id":39931665},{"atl":[[6.8,17.24]],"id":39931665},{"atb":[[2.4,71.43]],"id":39267517},{"atl":[[8.2,4.9]],"id":39267517},{"spn":5.67,"spf":"NaN","id":39267517},{"atb":[[1.3,210.14]],"id":37406513},{"atl":[[11.5,9.52]],"id":37406513},{"atl":[[4.2,31.25]],"id":39860456}],"con":true,"img":false}]}
{"op":"mcm","clk":"5348497307","pt":1646218215230,"mc":[{"id":"1.195453630","rc":[{"atb":[[3.25,0]],"id":41946970},{"atb":[[1.79,0]],"id":39931665},{"atb":[[1.74,0]],"id":37406513}],"con":true,"img":false}]}
{"op":"mcm","clk":"5348497324","pt":1646218215336,"mc":[{"id":"1.195453630","rc":[{"atb":[[3.5,59.37]],"id":41946970},{"atb":[[1.94,55.19]],"id":39931665},{"atb":[[1.86,58.91]],"id":37406513}],"con":true,"img":false}]}
{"op":"mcm","clk":"5348499250","pt":1646218226702,"mc":[{"id":"1.195453630","rc":[{"atb":[[2.34,0]],"id":40717352}],"con":true,"img":false}]}
{"op":"mcm","clk":"5348499264","pt":1646218226804,"mc":[{"id":"1.195453630","rc":[{"atb":[[2.38,34.06]],"id":40717352}],"con":true,"img":false}]}
{"op":"mcm","clk":"5348500275","pt":1646218233644,"mc":[{"id":"1.195453630","rc":[{"atl":[[13.5,0]],"id":39267517}],"con":true,"img":false}]}
{"op":"mcm","clk":"5348500293","pt":1646218233789,"mc":[{"id":"1.195453630","rc":[{"atl":[[10.5,3.48]],"id":39267517}],"con":true,"img":false}]}
{"op":"mcm","clk":"5348500389","pt":1646218234353,"mc":[{"id":"1.195453630","rc":[{"atb":[[2.36,0],[2.4,55.04]],"id":40717352}],"con":true,"img":false}]}
{"op":"mcm","clk":"5348501695","pt":1646218244477,"mc":[{"id":"1.195453630","rc":[{"atb":[[2.6,0]],"id":39267517}],"con":true,"img":false}]}
{"op":"mcm","clk":"5348501708","pt":1646218244580,"mc":[{"id":"1.195453630","rc":[{"atb":[[2.88,39.23]],"id":39267517}],"con":true,"img":false}]}
{"op":"mcm","clk":"5348504336","pt":1646218265261,"mc":[{"id":"1.195453630","rc":[{"atb":[[2.38,0]],"id":40717352},{"spn":4.0,"spf":"NaN","id":40717352}],"con":true,"img":false}]}
{"op":"mcm","clk":"5348504354","pt":1646218265427,"mc":[{"id":"1.195453630","rc":[{"atb":[[2.4,0],[2.42,34.06]],"id":40717352}],"con":true,"img":false}]}
{"op":"mcm","clk":"5348504358","pt":1646218265468,"mc":[{"id":"1.195453630","rc":[{"atb":[[2.3,76.92]],"id":40717352}],"con":true,"img":false}]}
{"op":"mcm","clk":"5348505859","pt":1646218278489,"mc":[{"id":"1.195453630","rc":[{"atb":[[2.42,0],[2.28,0]],"id":40717352},{"atl":[[7,0]],"id":40717352}],"con":true,"img":false}]}
{"op":"mcm","clk":"5348505869","pt":1646218278593,"mc":[{"id":"1.195453630","rc":[{"atb":[[1.81,80.65],[1.93,34.06]],"id":40717352},{"atl":[[8.2,5.44]],"id":40717352}],"con":true,"img":false}]}
{"op":"mcm","clk":"5348505881","pt":1646218278698,"mc":[{"id":"1.195453630","rc":[{"atb":[[2.3,0],[2.28,78.13]],"id":40717352}],"con":true,"img":false}]}
{"op":"mcm","clk":"5348508627","pt":1646218302630,"mc":[{"id":"1.195453630","rc":[{"atb":[[3.5,40]],"id":41946970}],"con":true,"img":false}]}
{"op":"mcm","clk":"5348508640","pt":1646218302734,"mc":[{"id":"1.195453630","rc":[{"atb":[[3.55,19.37]],"id":41946970}],"con":true,"img":false}]}
{"op":"mcm","clk":"5348516510","pt":1646218369825,"mc":[{"id":"1.195453630","rc":[{"atb":[[1.93,0]],"id":40717352},{"atl":[[8.2,0]],"id":40717352},{"spn":3.94,"spf":"NaN","id":40717352},{"spn":6.47,"spf":"NaN","id":41946970}],"con":true,"img":false}]}
{"op":"mcm","clk":"5348516525","pt":1646218369927,"mc":[{"id":"1.195453630","rc":[{"atb":[[2.3,34.06]],"id":40717352},{"atl":[[7,5.44]],"id":40717352}],"con":true,"img":false}]}
{"op":"mcm","clk":"5348516547","pt":1646218370138,"mc":[{"id":"1.195453630","rc":[{"atb":[[2.32,75.76],[2.28,0]],"id":40717352}],"con":true,"img":false}]}
{"op":"mcm","clk":"5348519672","pt":1646218401787,"mc":[{"id":"1.195453630","rc":[{"atb":[[1.81,0],[2.08,60.49]],"id":40717352},{"atl":[[9,0]],"id":40717352}],"con":true,"img":false}]}
{"op":"mcm","clk":"5348519681","pt":1646218401892,"mc":[{"id":"1.195453630","rc":[{"atl":[[8.2,8.17]],"id":40717352}],"con":true,"img":false}]}
{"op":"mcm","clk":"5348520361","pt":1646218409064,"mc":[{"id":"1.195453630","rc":[{"atb":[[2.3,0]],"id":40717352}],"con":true,"img":false}]}
{"op":"mcm","clk":"5348520371","pt":1646218409169,"mc":[{"id":"1.195453630","rc":[{"atb":[[2.28,78.13],[2.34,34.06]],"id":40717352}],"con":true,"img":false}]}
{"op":"mcm","clk":"5348520381","pt":1646218409271,"mc":[{"id":"1.195453630","rc":[{"atb":[[2.32,0]],"id":40717352}],"con":true,"img":false}]}
{"op":"mcm","clk":"5348521402","pt":1646218420586,"mc":[{"id":"1.195453630","rc":[{"atb":[[2.34,0]],"id":40717352}],"con":true,"img":false}]}
{"op":"mcm","clk":"5348521414","pt":1646218420691,"mc":[{"id":"1.195453630","rc":[{"atb":[[2.3,34.06]],"id":40717352}],"con":true,"img":false}]}
{"op":"mcm","clk":"5348523538","pt":1646218443629,"mc":[{"id":"1.195453630","rc":[{"atb":[[2.32,75.76],[2.28,0]],"id":40717352},{"spn":3.96,"spf":"NaN","id":40717352}],"con":true,"img":false}]}
{"op":"mcm","clk":"5348526841","pt":1646218476386,"mc":[{"id":"1.195453630","rc":[{"atb":[[2.3,0]],"id":40717352}],"con":true,"img":false}]}
{"op":"mcm","clk":"5348526850","pt":1646218476490,"mc":[{"id":"1.195453630","rc":[{"atb":[[2.34,34.06]],"id":40717352}],"con":true,"img":false}]}
{"op":"mcm","clk":"5348526862","pt":1646218476592,"mc":[{"id":"1.195453630","rc":[{"atb":[[2.32,0],[2.28,78.13]],"id":40717352}],"con":true,"img":false}]}
{"op":"mcm","clk":"5348528454","pt":1646218487710,"mc":[{"id":"1.195453630","rc":[{"atb":[[2.34,0]],"id":40717352}],"con":true,"img":false}]}
{"op":"mcm","clk":"5348528462","pt":1646218487814,"mc":[{"id":"1.195453630","rc":[{"atb":[[2.3,34.06]],"id":40717352}],"con":true,"img":false}]}
{"op":"mcm","clk":"5348530514","pt":1646218510421,"mc":[{"id":"1.195453630","rc":[{"atb":[[2.32,75.76],[2.28,0]],"id":40717352}],"con":true,"img":false}]}
{"op":"mcm","clk":"5348531010","pt":1646218514835,"mc":[{"id":"1.195453630","rc":[{"atb":[[3.55,0]],"id":41946970},{"atb":[[1.94,0]],"id":39931665},{"atb":[[1.86,0]],"id":37406513}],"con":true,"img":false}]}
{"op":"mcm","clk":"5348531025","pt":1646218514932,"mc":[{"id":"1.195453630","rc":[{"atb":[[3.5,59.37]],"id":41946970},{"atb":[[1.82,55.19]],"id":39931665},{"atb":[[1.77,58.91]],"id":37406513}],"con":true,"img":false}]}
{"op":"mcm","clk":"5348533843","pt":1646218538866,"mc":[{"id":"1.195453630","rc":[{"atb":[[2.3,0]],"id":40717352}],"con":true,"img":false}]}
{"op":"mcm","clk":"5348533855","pt":1646218538964,"mc":[{"id":"1.195453630","rc":[{"atb":[[2.32,0],[2.28,78.13],[2.34,34.06]],"id":40717352}],"con":true,"img":false}]}
{"op":"mcm","clk":"5348535014","pt":1646218550025,"mc":[{"id":"1.195453630","rc":[{"atb":[[2.34,0]],"id":40717352}],"con":true,"img":false}]}
{"op":"mcm","clk":"5348535020","pt":1646218550076,"mc":[{"id":"1.195453630","rc":[{"atb":[[2.3,34.06]],"id":40717352}],"con":true,"img":false}]}
{"op":"mcm","clk":"5348537239","pt":1646218572133,"mc":[{"id":"1.195453630","rc":[{"atb":[[2.32,75.76],[2.28,0]],"id":40717352},{"spn":6.45,"spf":"NaN","id":41946970}],"con":true,"img":false}]}
{"op":"mcm","clk":"5348539961","pt":1646218603975,"mc":[{"id":"1.195453630","rc":[{"atb":[[2.3,0]],"id":40717352}],"con":true,"img":false}]}
{"op":"mcm","clk":"5348539967","pt":1646218604080,"mc":[{"id":"1.195453630","rc":[{"atb":[[2.34,34.06]],"id":40717352}],"con":true,"img":false}]}
{"op":"mcm","clk":"5348539977","pt":1646218604185,"mc":[{"id":"1.195453630","rc":[{"atb":[[2.32,0],[2.28,78.13]],"id":40717352}],"con":true,"img":false}]}
{"op":"mcm","clk":"5348541090","pt":1646218617144,"mc":[{"id":"1.195453630","rc":[{"atb":[[2.34,0]],"id":40717352}],"con":true,"img":false}]}
{"op":"mcm","clk":"5348541102","pt":1646218617300,"mc":[{"id":"1.195453630","rc":[{"atb":[[2.3,34.06]],"id":40717352}],"con":true,"img":false}]}
{"op":"mcm","clk":"5348542876","pt":1646218636713,"mc":[{"id":"1.195453630","rc":[{"atb":[[2.32,75.76],[2.28,0]],"id":40717352}],"con":true,"img":false}]}
{"op":"mcm","clk":"5348545222","pt":1646218664588,"mc":[{"id":"1.195453630","rc":[{"atb":[[2.3,0]],"id":40717352}],"con":true,"img":false}]}
{"op":"mcm","clk":"5348545230","pt":1646218664693,"mc":[{"id":"1.195453630","rc":[{"atb":[[2.34,34.06]],"id":40717352}],"con":true,"img":false}]}
{"op":"mcm","clk":"5348545238","pt":1646218664755,"mc":[{"id":"1.195453630","rc":[{"atb":[[2.28,78.13]],"id":40717352}],"con":true,"img":false}]}
{"op":"mcm","clk":"5348545252","pt":1646218664868,"mc":[{"id":"1.195453630","rc":[{"atb":[[2.32,0]],"id":40717352}],"con":true,"img":false}]}
{"op":"mcm","clk":"5348546478","pt":1646218680574,"mc":[{"id":"1.195453630","rc":[{"atb":[[2.34,0]],"id":40717352}],"con":true,"img":false}]}
{"op":"mcm","clk":"5348546488","pt":1646218680679,"mc":[{"id":"1.195453630","rc":[{"atb":[[2.3,34.06]],"id":40717352}],"con":true,"img":false}]}
{"op":"mcm","clk":"5348547867","pt":1646218696618,"mc":[{"id":"1.195453630","rc":[{"atb":[[2.32,75.76],[2.28,0]],"id":40717352}],"con":true,"img":false}]}
{"op":"mcm","clk":"5348550394","pt":1646218725533,"mc":[{"id":"1.195453630","rc":[{"atb":[[2.3,0]],"id":40717352}],"con":true,"img":false}]}
{"op":"mcm","clk":"5348550405","pt":1646218725638,"mc":[{"id":"1.195453630","rc":[{"atb":[[2.34,34.06]],"id":40717352}],"con":true,"img":false}]}
{"op":"mcm","clk":"5348550413","pt":1646218725740,"mc":[{"id":"1.195453630","rc":[{"atb":[[2.32,0],[2.28,78.13]],"id":40717352}],"con":true,"img":false}]}
{"op":"mcm","clk":"5348551302","pt":1646218736679,"mc":[{"id":"1.195453630","rc":[{"atb":[[2.34,0]],"id":40717352}],"con":true,"img":false}]}
{"op":"mcm","clk":"5348551321","pt":1646218736888,"mc":[{"id":"1.195453630","rc":[{"atb":[[2.3,34.06]],"id":40717352}],"con":true,"img":false}]}
{"op":"mcm","clk":"5348552813","pt":1646218754912,"mc":[{"id":"1.195453630","rc":[{"atb":[[1.44,188.32],[1.39,0]],"id":39931665},{"atb":[[2.4,0],[2.52,65.79]],"id":39267517}],"con":true,"img":false}]}
{"op":"mcm","clk":"5348552998","pt":1646218757091,"mc":[{"id":"1.195453630","rc":[{"atb":[[2.32,75.76],[2.28,0]],"id":40717352}],"con":true,"img":false}]}
{"op":"mcm","clk":"5348558483","pt":1646218821645,"mc":[{"id":"1.195453630","rc":[{"atb":[[2.3,0],[2.06,94.16],[2.26,79.22],[2.16,86.05],[2.08,60.49]],"id":40717352},{"atl":[[5.6,7.89],[7.2,11.7],[9.2,8.85],[8.2,8.17],[7,5.45]],"id":40717352},{"atb":[[3.45,40.74],[3.2,45.37],[3,33.24],[2.98,50.41],[3.5,59.38]],"id":41946970},{"atl":[[18.5,4.14],[13.5,5.8],[14.5,3.23],[9.4,4.32],[15.5,4.36]],"id":41946970},{"atb":[[1.82,55.19],[2.06,94.16],[1.98,101.85],[1.93,107.33],[1.66,83.19]],"id":39931665},{"atl":[[5.6,9.47],[6.4,13.44],[6,10.56],[5.2,8.64],[8.4,9.81]],"id":39931665},{"atb":[[2.88,39.24],[2.86,53.66],[3.15,46.43],[2.98,22.01],[2.96,50.92]],"id":39267517},{"atl":[[16,4.83],[10.5,3.48],[11,7.25],[14,4.9],[8.4,4.9]],"id":39267517},{"atb":[[1.63,86.94],[1.85,117.43],[1.9,110.91],[1.77,58.92],[1.95,105.07]],"id":37406513},{"atl":[[5.6,15.78],[7.2,11.7],[4.6,10.08],[5.3,9.69],[5.5,12.17]],"id":37406513},{"atb":[[1.2,499.1],[1.36,121.11],[1.25,399.28],[1.3,332.73],[1.31,193.83]],"id":39860456},{"spl":[[1.01,5.17]],"id":39860456},{"atl":[[2.54,23.57],[2.74,41.72],[2.52,25.34],[3.4,25.03],[2.94,37.42]],"id":39860456}],"con":true,"img":false}]}
{"op":"mcm","clk":"5348558492","pt":1646218821747,"mc":[{"id":"1.195453630","rc":[{"atb":[[2.32,0],[2.28,78.13],[2.34,34.06]],"id":40717352}],"con":true,"img":false}]}
{"op":"mcm","clk":"5348559713","pt":1646218835669,"mc":[{"id":"1.195453630","rc":[{"atb":[[2.34,0]],"id":40717352}],"con":true,"img":false}]}
{"op":"mcm","clk":"5348559721","pt":1646218835776,"mc":[{"id":"1.195453630","rc":[{"atb":[[2.3,34.06]],"id":40717352}],"con":true,"img":false}]}
{"op":"mcm","clk":"5348561075","pt":1646218852118,"mc":[{"id":"1.195453630","rc":[{"atb":[[2.32,75.76],[2.28,0]],"id":40717352}],"con":true,"img":false}]}
{"op":"mcm","clk":"5348563828","pt":1646218881643,"mc":[{"id":"1.195453630","rc":[{"atb":[[2.3,0]],"id":40717352}],"con":true,"img":false}]}
{"op":"mcm","clk":"5348563840","pt":1646218881744,"mc":[{"id":"1.195453630","rc":[{"atb":[[2.34,34.06]],"id":40717352},{"spn":3.97,"spf":"NaN","id":40717352}],"con":true,"img":false}]}
{"op":"mcm","clk":"5348563852","pt":1646218881848,"mc":[{"id":"1.195453630","rc":[{"atb":[[2.32,0],[2.28,78.13]],"id":40717352}],"con":true,"img":false}]}
{"op":"mcm","clk":"5348564935","pt":1646218894546,"mc":[{"id":"1.195453630","rc":[{"atb":[[2.34,0]],"id":40717352}],"con":true,"img":false}]}
{"op":"mcm","clk":"5348564948","pt":1646218894652,"mc":[{"id":"1.195453630","rc":[{"atb":[[2.3,34.06]],"id":40717352}],"con":true,"img":false}]}
{"op":"mcm","clk":"5348567073","pt":1646218911570,"mc":[{"id":"1.195453630","rc":[{"atb":[[2.32,75.76],[2.28,0]],"id":40717352}],"con":true,"img":false}]}
{"op":"mcm","clk":"5348568683","pt":1646218923101,"mc":[{"id":"1.195453630","rc":[{"atb":[[2.4,71.43],[2.52,0]],"id":39267517}],"con":true,"img":false}]}
{"op":"mcm","clk":"5348568715","pt":1646218923417,"mc":[{"id":"1.195453630","rc":[{"atb":[[2.32,0],[2.22,81.97]],"id":40717352},{"atl":[[11.5,0],[7.6,15.15]],"id":40717352},{"atb":[[3.1,47.62],[3.5,19.38]],"id":41946970},{"atl":[[16.5,6.45],[30,0]],"id":41946970},{"atb":[[1.44,0],[1.49,188.34]],"id":39931665},{"atb":[[1.3,0],[1.17,215.98]],"id":37406513},{"atl":[[5.2,23.81],[4.2,0]],"id":39860456}],"con":true,"img":false}]}
{"op":"mcm","clk":"5348569636","pt":1646218931113,"mc":[{"id":"1.195453630","rc":[{"atb":[[2.3,0]],"id":40717352}],"con":true,"img":false}]}
{"op":"mcm","clk":"5348569647","pt":1646218931218,"mc":[{"id":"1.195453630","rc":[{"atb":[[2.28,34.06]],"id":40717352}],"con":true,"img":false}]}
{"op":"mcm","clk":"5348571761","pt":1646218952419,"mc":[{"id":"1.195453630","rc":[{"spn":3.94,"spf":"NaN","id":40717352},{"atb":[[2.4,0],[2.52,65.79]],"id":39267517}],"con":true,"img":false}]}
{"op":"mcm","clk":"5348571786","pt":1646218952760,"mc":[{"id":"1.195453630","rc":[{"atb":[[2.3,76.92],[2.22,0]],"id":40717352},{"atl":[[7.6,0],[7,21.23]],"id":40717352},{"atb":[[1.26,215.98],[1.17,0]],"id":37406513}],"con":true,"img":false}]}
{"op":"mcm","clk":"5348571795","pt":1646218952866,"mc":[{"id":"1.195453630","rc":[{"atb":[[3.1,0],[3.55,39.22]],"id":41946970},{"atl":[[5.2,0],[4.7,27.03]],"id":39860456}],"con":true,"img":false}]}
{"op":"mcm","clk":"5348572091","pt":1646218955838,"mc":[{"id":"1.195453630","rc":[{"atl":[[14.5,0]],"id":41946970}],"con":true,"img":false}]}
{"op":"mcm","clk":"5348572103","pt":1646218955931,"mc":[{"id":"1.195453630","rc":[{"atl":[[13,3.23]],"id":41946970}],"con":true,"img":false}]}
{"op":"mcm","clk":"5348574449","pt":1646218980155,"mc":[{"id":"1.195453630","rc":[{"atb":[[2.28,0]],"id":40717352},{"atb":[[1.31,0]],"id":39860456}],"con":true,"img":false}]}
{"op":"mcm","clk":"5348574460","pt":1646218980258,"mc":[{"id":"1.195453630","rc":[{"atb":[[2.32,34.06],[2.28,78.13]],"id":40717352},{"atb":[[1.33,193.83]],"id":39860456}],"con":true,"img":false}]}
{"op":"mcm","clk":"5348574467","pt":1646218980361,"mc":[{"id":"1.195453630","rc":[{"atb":[[2.3,0]],"id":40717352}],"con":true,"img":false}]}
{"op":"mcm","clk":"5348574631","pt":1646218981781,"mc":[{"id":"1.195453630","rc":[{"atb":[[2.28,0],[2.34,74.63]],"id":40717352}],"con":true,"img":false}]}
{"op":"mcm","clk":"5348574786","pt":1646218983150,"mc":[{"id":"1.195453630","rc":[{"atb":[[2.88,0]],"id":39267517}],"con":true,"img":false}]}
{"op":"mcm","clk":"5348574799","pt":1646218983254,"mc":[{"id":"1.195453630","rc":[{"atb":[[2.6,39.24]],"id":39267517}],"con":true,"img":false}]}
{"op":"mcm","clk":"5348576022","pt":1646218994756,"mc":[{"id":"1.195453630","rc":[{"atb":[[3.5,0]],"id":41946970}],"con":true,"img":false}]}
{"op":"mcm","clk":"5348576036","pt":1646218994857,"mc":[{"id":"1.195453630","rc":[{"atb":[[3.25,19.38],[3.5,40]],"id":41946970}],"con":true,"img":false}]}
{"op":"mcm","clk":"5348576047","pt":1646218994964,"mc":[{"id":"1.195453630","rc":[{"atb":[[3.55,0]],"id":41946970}],"con":true,"img":false}]}
{"op":"mcm","clk":"5348577815","pt":1646219012422,"mc":[{"id":"1.195453630","rc":[{"atb":[[2.32,0]],"id":40717352}],"con":true,"img":false}]}
{"op":"mcm","clk":"5348577826","pt":1646219012519,"mc":[{"id":"1.195453630","rc":[{"atb":[[2.36,34.06]],"id":40717352},{"spn":3.98,"spf":"NaN","id":40717352}],"con":true,"img":false}]}
{"op":"mcm","clk":"5348577831","pt":1646219012622,"mc":[{"id":"1.195453630","rc":[{"atb":[[2.28,78.13],[2.34,0]],"id":40717352}],"con":true,"img":false}]}
{"op":"mcm","clk":"5348577841","pt":1646219012726,"mc":[{"id":"1.195453630","rc":[{"atb":[[2.38,72.46],[2.28,0]],"id":40717352}],"con":true,"img":false}]}
{"op":"mcm","clk":"5348582174","pt":1646219055132,"mc":[{"id":"1.195453630","rc":[{"atb":[[2.36,0]],"id":40717352}],"con":true,"img":false}]}
{"op":"mcm","clk":"5348582183","pt":1646219055236,"mc":[{"id":"1.195453630","rc":[{"atb":[[2.4,34.06],[2.38,0],[2.28,78.13]],"id":40717352}],"con":true,"img":false}]}
{"op":"mcm","clk":"5348583371","pt":1646219067544,"mc":[{"id":"1.195453630","rc":[{"atb":[[2.4,0]],"id":40717352}],"con":true,"img":false}]}
{"op":"mcm","clk":"5348583383","pt":1646219067648,"mc":[{"id":"1.195453630","rc":[{"atb":[[2.3,34.06]],"id":40717352}],"con":true,"img":false}]}
{"op":"mcm","clk":"5348583945","pt":1646219073170,"mc":[{"id":"1.195453630","rc":[{"atb":[[2.32,1.66]],"id":40717352},{"spn":3.96,"spf":"NaN","id":40717352},{"atb":[[3.55,1.66]],"id":41946970},{"spn":6.47,"spf":"NaN","id":41946970},{"atb":[[2.08,1.66]],"id":39931665},{"spn":3.64,"spf":"NaN","id":39931665},{"atb":[[3.2,1.66]],"id":39267517},{"spn":5.7,"spf":"NaN","id":39267517}],"con":true,"img":false}]}
{"op":"mcm","clk":"5348585565","pt":1646219083171,"mc":[{"id":"1.195453630","rc":[{"atb":[[2.32,35.72],[2.28,0]],"id":40717352}],"con":true,"img":false}]}
{"op":"mcm","clk":"5348586835","pt":1646219095902,"mc":[{"id":"1.195453630","rc":[{"atb":[[2.3,0]],"id":40717352}],"con":true,"img":false}]}
{"op":"mcm","clk":"5348586844","pt":1646219096008,"mc":[{"id":"1.195453630","rc":[{"atb":[[2.28,34.06]],"id":40717352}],"con":true,"img":false}]}
{"op":"mcm","clk":"5348587399","pt":1646219101655,"mc":[{"id":"1.195453630","marketDefinition":{"bspMarket":true,"turnInPlayEnabled":false,"persistenceEnabled":false,"marketBaseRate":7.0,"eventId":"31272494","eventTypeId":"4339","numberOfWinners":2,"bettingType":"ODDS","marketType":"PLACE","marketTime":"2022-03-02T11:49:00.000Z","suspendTime":"2022-03-02T11:49:00.000Z","bspReconciled":false,"complete":true,"inPlay":false,"crossMatching":true,"runnersVoidable":false,"numberOfActiveRunners":6,"betDelay":0,"status":"OPEN","runners":[{"status":"ACTIVE","sortPriority":1,"id":40717352,"name":"1. Elswyk Shadow"},{"status":"ACTIVE","sortPriority":2,"id":39860456,"name":"2. Jax"},{"status":"ACTIVE","sortPriority":3,"id":37406513,"name":"3. Fab Rocket"},{"status":"ACTIVE","sortPriority":4,"id":41946970,"name":"4. Dashing Mini"},{"status":"ACTIVE","sortPriority":5,"id":39267517,"name":"6. Bull Montana"},{"status":"ACTIVE","sortPriority":6,"id":39931665,"name":"7. Elswyk Jordy"}],"regulators":["MR_INT"],"venue":"Traralgon","countryCode":"AU","discountAllowed":true,"timezone":"Australia/Sydney","openDate":"2022-03-02T08:31:00.000Z","version":4382425389,"name":"To Be Placed","eventName":"Traralgon (AUS) 2nd Mar"},"rc":[],"con":true,"img":false}]}
{"op":"mcm","clk":"5348607649","pt":1646219265443,"mc":[{"id":"1.195453630","rc":[{"atb":[[2.1,6.82]],"id":39931665},{"spn":3.65,"spf":"NaN","id":39931665},{"atb":[[3.2,5.08]],"id":39267517},{"atb":[[1.99,7.58]],"id":37406513},{"spn":3.29,"spf":"NaN","id":37406513}],"con":true,"img":false}]}
{"op":"mcm","clk":"5348607661","pt":1646219265563,"mc":[{"id":"1.195453630","rc":[{"atb":[[2.38,5.44]],"id":40717352},{"atb":[[3.6,2.89]],"id":41946970},{"atb":[[1.39,19.24]],"id":39860456}],"con":true,"img":false}]}
{"op":"mcm","clk":"5348607685","pt":1646219265772,"mc":[{"id":"1.195453630","rc":[{"atb":[[2.4,34.06],[2.32,1.66]],"id":40717352},{"atb":[[3.55,40.88],[3.5,0]],"id":41946970}],"con":true,"img":false}]}
{"op":"mcm","clk":"5348607968","pt":1646219268174,"mc":[{"id":"1.195453630","rc":[{"atb":[[2.38,0]],"id":40717352},{"atb":[[3.6,0]],"id":41946970}],"con":true,"img":false}]}
{"op":"mcm","clk":"5348607992","pt":1646219268348,"mc":[{"id":"1.195453630","rc":[{"atb":[[2.32,69.78]],"id":40717352}],"con":true,"img":false}]}
{"op":"mcm","clk":"5348608005","pt":1646219268445,"mc":[{"id":"1.195453630","rc":[{"atb":[[2.4,0]],"id":40717352}],"con":true,"img":false}]}
{"op":"mcm","clk":"5348608018","pt":1646219268564,"mc":[{"id":"1.195453630","rc":[{"atb":[[2.32,1.66],[2.3,76.92]],"id":40717352}],"con":true,"img":false}]}
{"op":"mcm","clk":"5348608029","pt":1646219268642,"mc":[{"id":"1.195453630","rc":[{"atb":[[2.32,0]],"id":40717352},{"atb":[[2.08,0]],"id":39931665}],"con":true,"img":false}]}
{"op":"mcm","clk":"5348608040","pt":1646219268747,"mc":[{"id":"1.195453630","rc":[{"atb":[[2.42,1.66]],"id":40717352},{"atb":[[2.12,1.66]],"id":39931665}],"con":true,"img":false}]}
{"op":"mcm","clk":"5348609095","pt":1646219277269,"mc":[{"id":"1.195453630","rc":[{"atb":[[2.36,5.51]],"id":40717352},{"atb":[[3.65,2.83]],"id":41946970}],"con":true,"img":false}]}
{"op":"mcm","clk":"5348609722","pt":1646219282367,"mc":[{"id":"1.195453630","rc":[{"atl":[[6.4,15.78],[7,5.45]],"id":40717352},{"atl":[[16.5,0],[13,11.56]],"id":41946970},{"atl":[[4.2,31.25],[4.7,0]],"id":39860456}],"con":true,"img":false}]}
{"op":"mcm","clk":"5348610036","pt":1646219284760,"mc":[{"id":"1.195453630","rc":[{"atl":[[10.5,0]],"id":39267517}],"con":true,"img":false}]}
{"op":"mcm","clk":"5348610047","pt":1646219284865,"mc":[{"id":"1.195453630","rc":[{"atl":[[13.5,3.48]],"id":39267517}],"con":true,"img":false}]}
{"op":"mcm","clk":"5348610344","pt":1646219286873,"mc":[{"id":"1.195453630","rc":[{"atb":[[1.86,75.75],[2.08,0]],"id":40717352},{"atb":[[2.5,41.96],[3,0]],"id":41946970},{"atl":[[20,3.27],[13.5,0],[14,0]],"id":39267517},{"atl":[[6.4,9.12],[5.5,0]],"id":37406513}],"con":true,"img":false}]}
{"op":"mcm","clk":"5348610359","pt":1646219286964,"mc":[{"id":"1.195453630","rc":[{"atl":[[18.5,3.48]],"id":39267517}],"con":true,"img":false}]}
{"op":"mcm","clk":"5348610703","pt":1646219289698,"mc":[{"id":"1.195453630","rc":[{"atb":[[2.42,0]],"id":40717352},{"atb":[[3.55,39.22]],"id":41946970}],"con":true,"img":false}]}
{"op":"mcm","clk":"5348610729","pt":1646219289862,"mc":[{"id":"1.195453630","rc":[{"atb":[[2.38,1.66]],"id":40717352},{"atb":[[3.7,1.66]],"id":41946970}],"con":true,"img":false}]}
{"op":"mcm","clk":"5348611289","pt":1646219294422,"mc":[{"id":"1.195453630","rc":[{"atb":[[2.3,0],[2.38,7.18]],"id":40717352}],"con":true,"img":false}]}
{"op":"mcm","clk":"5348611430","pt":1646219295497,"mc":[{"id":"1.195453630","rc":[{"atb":[[2.36,0]],"id":40717352}],"con":true,"img":false}]}
{"op":"mcm","clk":"5348611617","pt":1646219297013,"mc":[{"id":"1.195453630","rc":[{"atl":[[5.3,0]],"id":37406513}],"con":true,"img":false}]}
{"op":"mcm","clk":"5348611630","pt":1646219297073,"mc":[{"id":"1.195453630","rc":[{"atl":[[5.5,9.69]],"id":37406513}],"con":true,"img":false}]}
{"op":"mcm","clk":"5348612120","pt":1646219301412,"mc":[{"id":"1.195453630","rc":[{"atb":[[2.34,5.6]],"id":40717352}],"con":true,"img":false}]}
{"op":"mcm","clk":"5348613544","pt":1646219312834,"mc":[{"id":"1.195453630","rc":[{"atl":[[6.2,8.38],[7,0]],"id":40717352},{"atl":[[13,8.33]],"id":41946970}],"con":true,"img":false}]}
{"op":"mcm","clk":"5348613560","pt":1646219312898,"mc":[{"id":"1.195453630","rc":[{"atl":[[11.5,3.23]],"id":41946970}],"con":true,"img":false}]}
{"op":"mcm","clk":"5348616277","pt":1646219335276,"mc":[{"id":"1.195453630","rc":[{"spn":3.99,"spf":"NaN","id":40717352},{"atb":[[3.55,0],[3.3,43.48]],"id":41946970},{"spn":6.55,"spf":"NaN","id":41946970},{"spn":3.66,"spf":"NaN","id":39931665},{"atb":[[1.26,0]],"id":37406513},{"spn":1.39,"spf":1.0,"id":39860456}],"con":true,"img":false}]}
{"op":"mcm","clk":"5348616288","pt":1646219335341,"mc":[{"id":"1.195453630","rc":[{"atb":[[2.3,76.92],[2.38,1.66]],"id":40717352},{"atb":[[1.2,210.14]],"id":37406513}],"con":true,"img":false}]}
{"op":"mcm","clk":"5348616540","pt":1646219337376,"mc":[{"id":"1.195453630","rc":[{"atb":[[2.34,0]],"id":40717352},{"atb":[[3.65,0]],"id":41946970}],"con":true,"img":false}]}
{"op":"mcm","clk":"5348617072","pt":1646219341455,"mc":[{"id":"1.195453630","rc":[{"atl":[[8.2,0],[7,10.9]],"id":40717352},{"atl":[[12,5.45],[15.5,0]],"id":41946970}],"con":true,"img":false}]}
{"op":"mcm","clk":"5348617666","pt":1646219346459,"mc":[{"id":"1.195453630","rc":[{"atb":[[2.36,5.51]],"id":40717352},{"atb":[[3.55,2.94]],"id":41946970}],"con":true,"img":false}]}
{"op":"mcm","clk":"5348617709","pt":1646219346767,"mc":[{"id":"1.195453630","rc":[{"atb":[[2.38,0]],"id":40717352},{"atb":[[3.7,0]],"id":41946970}],"con":true,"img":false}]}
{"op":"mcm","clk":"5348617737","pt":1646219347018,"mc":[{"id":"1.195453630","rc":[{"atb":[[2.32,1.66]],"id":40717352},{"atb":[[3.5,1.66]],"id":41946970}],"con":true,"img":false}]}
{"op":"mcm","clk":"5348617938","pt":1646219348461,"mc":[{"id":"1.195453630","rc":[{"atl":[[7.2,27.83],[6.4,0]],"id":40717352},{"atl":[[4.9,25.64],[4.2,0]],"id":39860456}],"con":true,"img":false}]}
{"op":"mcm","clk":"5348619032","pt":1646219357987,"mc":[{"id":"1.195453630","rc":[{"atl":[[15.5,4.36]],"id":39267517}],"con":true,"img":false}]}
{"op":"mcm","clk":"5348619041","pt":1646219358087,"mc":[{"id":"1.195453630","rc":[{"atl":[[20,0]],"id":39267517}],"con":true,"img":false}]}
{"op":"mcm","clk":"5348619331","pt":1646219360508,"mc":[{"id":"1.195453630","rc":[{"atb":[[3.55,5.88],[3.3,0]],"id":41946970}],"con":true,"img":false}]}
{"op":"mcm","clk":"5348619337","pt":1646219360608,"mc":[{"id":"1.195453630","rc":[{"atb":[[2.3,0],[2.38,5.52]],"id":40717352},{"atb":[[1.2,0],[1.25,210.14]],"id":37406513}],"con":true,"img":false}]}
{"op":"mcm","clk":"5348619431","pt":1646219361411,"mc":[{"id":"1.195453630","rc":[{"atb":[[2.36,0]],"id":40717352}],"con":true,"img":false}]}
{"op":"mcm","clk":"5348619921","pt":1646219365682,"mc":[{"id":"1.195453630","rc":[{"atb":[[2.32,34.06],[2.38,0]],"id":40717352},{"atb":[[3.5,0]],"id":41946970}],"con":true,"img":false}]}
{"op":"mcm","clk":"5348619943","pt":1646219365897,"mc":[{"id":"1.195453630","rc":[{"atb":[[2.4,1.66]],"id":40717352},{"atb":[[3.6,1.66]],"id":41946970}],"con":true,"img":false}]}
{"op":"mcm","clk":"5348620884","pt":1646219373533,"mc":[{"id":"1.195453630","rc":[{"atb":[[2.38,5.44]],"id":40717352},{"atl":[[7.2,11.7],[6.8,16.27]],"id":40717352}],"con":true,"img":false}]}
{"op":"mcm","clk":"5348621100","pt":1646219375614,"mc":[{"id":"1.195453630","rc":[{"atl":[[15.5,0]],"id":39267517}],"con":true,"img":false}]}
{"op":"mcm","clk":"5348621110","pt":1646219375720,"mc":[{"id":"1.195453630","rc":[{"atl":[[18,4.36]],"id":39267517}],"con":true,"img":false}]}
{"op":"mcm","clk":"5348622853","pt":1646219390633,"mc":[{"id":"1.195453630","rc":[{"atb":[[2.4,7.1],[2.32,0]],"id":40717352},{"atl":[[18.5,0]],"id":39267517}],"con":true,"img":false}]}
{"op":"mcm","clk":"5348622870","pt":1646219390737,"mc":[{"id":"1.195453630","rc":[{"atl":[[10.5,3.48]],"id":39267517}],"con":true,"img":false}]}
{"op":"mcm","clk":"5348623422","pt":1646219394519,"mc":[{"id":"1.195453630","rc":[{"atb":[[2.38,0]],"id":40717352}],"con":true,"img":false}]}
{"op":"mcm","clk":"5348623781","pt":1646219397967,"mc":[{"id":"1.195453630","rc":[{"spn":4.0,"spf":"NaN","id":40717352},{"spn":6.5,"spf":"NaN","id":41946970},{"atb":[[3.2,8.87]],"id":39267517}],"con":true,"img":false}]}
{"op":"mcm","clk":"5348623790","pt":1646219398027,"mc":[{"id":"1.195453630","rc":[{"atb":[[2.1,14.39]],"id":39931665}],"con":true,"img":false}]}
{"op":"mcm","clk":"5348623876","pt":1646219398852,"mc":[{"id":"1.195453630","rc":[{"atb":[[3.55,9.14]],"id":41946970},{"atb":[[1.39,40.6]],"id":39860456}],"con":true,"img":false}]}
{"op":"mcm","clk":"5348623911","pt":1646219399163,"mc":[{"id":"1.195453630","rc":[{"atb":[[2.32,6.31]],"id":40717352},{"atb":[[1.99,15.99]],"id":37406513}],"con":true,"img":false}]}
{"op":"mcm","clk":"5348624087","pt":1646219400635,"mc":[{"id":"1.195453630","rc":[{"atb":[[2.34,5.6]],"id":40717352}],"con":true,"img":false}]}
{"op":"mcm","clk":"5348626916","pt":1646219424180,"mc":[{"id":"1.195453630","rc":[{"atl":[[7,0]],"id":40717352}],"con":true,"img":false}]}
{"op":"mcm","clk":"5348626928","pt":1646219424285,"mc":[{"id":"1.195453630","rc":[{"atl":[[6.6,10.9]],"id":40717352}],"con":true,"img":false}]}
{"op":"mcm","clk":"5348628625","pt":1646219438439,"mc":[{"id":"1.195453630","rc":[{"atl":[[18,0]],"id":39267517}],"con":true,"img":false}]}
{"op":"mcm","clk":"5348628632","pt":1646219438498,"mc":[{"id":"1.195453630","rc":[{"atl":[[15.5,4.36]],"id":39267517}],"con":true,"img":false}]}
{"op":"mcm","clk":"5348643138","pt":1646219554912,"mc":[{"id":"1.195453630","rc":[{"atb":[[2.4,1.66],[2.3,76.92]],"id":40717352},{"atb":[[3.55,6.2],[3.3,43.48]],"id":41946970}],"con":true,"img":false}]}
{"op":"mcm","clk":"5348643419","pt":1646219557387,"mc":[{"id":"1.195453630","rc":[{"atb":[[2.34,0]],"id":40717352}],"con":true,"img":false}]}
{"op":"mcm","clk":"5348644383","pt":1646219565891,"mc":[{"id":"1.195453630","rc":[{"atb":[[2.4,0]],"id":40717352}],"con":true,"img":false}]}
{"op":"mcm","clk":"5348644400","pt":1646219566095,"mc":[{"id":"1.195453630","rc":[{"atb":[[2.34,1.66]],"id":40717352}],"con":true,"img":false}]}
{"op":"mcm","clk":"5348645842","pt":1646219579433,"mc":[{"id":"1.195453630","rc":[{"atl":[[15.5,0]],"id":39267517}],"con":true,"img":false}]}
{"op":"mcm","clk":"5348645852","pt":1646219579538,"mc":[{"id":"1.195453630","rc":[{"atl":[[18,4.36]],"id":39267517}],"con":true,"img":false}]}
{"op":"mcm","clk":"5348646062","pt":1646219581231,"mc":[{"id":"1.195453630","rc":[{"atb":[[3.25,0]],"id":41946970}],"con":true,"img":false}]}
{"op":"mcm","clk":"5348646093","pt":1646219581533,"mc":[{"id":"1.195453630","rc":[{"atb":[[3.35,19.38]],"id":41946970}],"con":true,"img":false}]}
{"op":"mcm","clk":"5348646273","pt":1646219583116,"mc":[{"id":"1.195453630","rc":[{"atb":[[2.28,0]],"id":40717352}],"con":true,"img":false}]}
{"op":"mcm","clk":"5348646290","pt":1646219583218,"mc":[{"id":"1.195453630","rc":[{"atb":[[2.32,40.37]],"id":40717352}],"con":true,"img":false}]}
{"op":"mcm","clk":"5348646734","pt":1646219587832,"mc":[{"id":"1.195453630","rc":[{"atb":[[2.32,34.06]],"id":40717352}],"con":true,"img":false}]}
{"op":"mcm","clk":"5348648387","pt":1646219604891,"mc":[{"id":"1.195453630","rc":[{"atb":[[2.36,6.12]],"id":40717352}],"con":true,"img":false}]}
{"op":"mcm","clk":"5348650276","pt":1646219624006,"mc":[{"id":"1.195453630","rc":[{"atb":[[2.34,0]],"id":40717352},{"spn":3.98,"spf":"NaN","id":40717352}],"con":true,"img":false}]}
{"op":"mcm","clk":"5348650297","pt":1646219624214,"mc":[{"id":"1.195453630","rc":[{"atb":[[2.38,1.66]],"id":40717352}],"con":true,"img":false}]}
{"op":"mcm","clk":"5348651936","pt":1646219638700,"mc":[{"id":"1.195453630","rc":[{"atl":[[18,0]],"id":39267517}],"con":true,"img":false}]}
{"op":"mcm","clk":"5348651953","pt":1646219638807,"mc":[{"id":"1.195453630","rc":[{"atl":[[15.5,4.36]],"id":39267517}],"con":true,"img":false}]}
{"op":"mcm","clk":"5348653121","pt":1646219648934,"mc":[{"id":"1.195453630","rc":[{"atb":[[2.3,0],[2.38,7.78]],"id":40717352},{"atb":[[3.55,25.58],[3.3,0]],"id":41946970}],"con":true,"img":false}]}
{"op":"mcm","clk":"5348653293","pt":1646219650451,"mc":[{"id":"1.195453630","rc":[{"atb":[[3.55,22.64]],"id":41946970}],"con":true,"img":false}]}
{"op":"mcm","clk":"5348654661","pt":1646219663155,"mc":[{"id":"1.195453630","rc":[{"atb":[[2.32,0]],"id":40717352},{"atb":[[3.35,0]],"id":41946970}],"con":true,"img":false}]}
{"op":"mcm","clk":"5348654674","pt":1646219663266,"mc":[{"id":"1.195453630","rc":[{"atb":[[2.28,34.06]],"id":40717352},{"atb":[[3.25,19.38]],"id":41946970}],"con":true,"img":false}]}
{"op":"mcm","clk":"5348655408","pt":1646219669586,"mc":[{"id":"1.195453630","rc":[{"atb":[[2.36,0]],"id":40717352}],"con":true,"img":false}]}
{"op":"mcm","clk":"5348657129","pt":1646219685100,"mc":[{"id":"1.195453630","rc":[{"atb":[[2.32,6.31]],"id":40717352},{"spn":3.99,"spf":"NaN","id":40717352}],"con":true,"img":false}]}
{"op":"mcm","clk":"5348658979","pt":1646219702626,"mc":[{"id":"1.195453630","rc":[{"atb":[[2.34,5.6]],"id":40717352}],"con":true,"img":false}]}
{"op":"mcm","clk":"5348658992","pt":1646219702735,"mc":[{"id":"1.195453630","rc":[{"atb":[[3.65,2.83]],"id":41946970}],"con":true,"img":false}]}
{"op":"mcm","clk":"5348659104","pt":1646219703849,"mc":[{"id":"1.195453630","rc":[{"atb":[[3.6,0]],"id":41946970}],"con":true,"img":false}]}
{"op":"mcm","clk":"5348659123","pt":1646219704053,"mc":[{"id":"1.195453630","rc":[{"atb":[[3.7,1.66]],"id":41946970}],"con":true,"img":false}]}
{"op":"mcm","clk":"5348659154","pt":1646219704368,"mc":[{"id":"1.195453630","rc":[{"atl":[[6.4,16.27],[6.8,0]],"id":40717352},{"atl":[[4.1,32.26],[4.9,0]],"id":39860456}],"con":true,"img":false}]}
{"op":"mcm","clk":"5348659202","pt":1646219704735,"mc":[{"id":"1.195453630","rc":[{"atl":[[6.6,0]],"id":40717352}],"con":true,"img":false}]}
{"op":"mcm","clk":"5348659213","pt":1646219704837,"mc":[{"id":"1.195453630","rc":[{"atl":[[7,10.9]],"id":40717352}],"con":true,"img":false}]}
{"op":"mcm","clk":"5348659597","pt":1646219708153,"mc":[{"id":"1.195453630","rc":[{"atl":[[10.5,0]],"id":39267517}],"con":true,"img":false}]}
{"op":"mcm","clk":"5348659611","pt":1646219708288,"mc":[{"id":"1.195453630","rc":[{"atl":[[16.5,3.48]],"id":39267517}],"con":true,"img":false}]}
{"op":"mcm","clk":"5348677975","pt":1646219802716,"mc":[{"id":"1.195453630","marketDefinition":{"bspMarket":true,"turnInPlayEnabled":false,"persistenceEnabled":false,"marketBaseRate":7.0,"eventId":"31272494","eventTypeId":"4339","numberOfWinners":2,"bettingType":"ODDS","marketType":"PLACE","marketTime":"2022-03-02T11:49:00.000Z","suspendTime":"2022-03-02T11:49:00.000Z","bspReconciled":false,"complete":true,"inPlay":false,"crossMatching":true,"runnersVoidable":false,"numberOfActiveRunners":6,"betDelay":0,"status":"OPEN","runners":[{"status":"ACTIVE","sortPriority":1,"id":40717352,"name":"1. Elswyk Shadow"},{"status":"ACTIVE","sortPriority":2,"id":39860456,"name":"2. Jax"},{"status":"ACTIVE","sortPriority":3,"id":37406513,"name":"3. Fab Rocket"},{"status":"ACTIVE","sortPriority":4,"id":41946970,"name":"4. Dashing Mini"},{"status":"ACTIVE","sortPriority":5,"id":39267517,"name":"6. Bull Montana"},{"status":"ACTIVE","sortPriority":6,"id":39931665,"name":"7. Elswyk Jordy"}],"regulators":["MR_INT"],"venue":"Traralgon","countryCode":"AU","discountAllowed":true,"timezone":"Australia/Sydney","openDate":"2022-03-02T08:31:00.000Z","version":4382425389,"name":"To Be Placed","eventName":"Traralgon (AUS) 2nd Mar"},"rc":[{"atb":[[2.32,6.31],[2.06,94.16],[2.38,7.78],[2.28,34.06],[1.86,75.75],[2.26,79.22],[2.16,86.05],[2.34,5.6]],"id":40717352},{"atl":[[5.6,7.89],[7.2,11.7],[6.4,16.27],[9.2,8.85],[6.2,8.38],[7,10.9]],"id":40717352},{"spn":3.99,"spf":"NaN","id":40717352},{"atb":[[3.45,40.74],[3.2,45.37],[2.5,41.96],[3.7,1.66],[3.55,22.64],[3.25,19.38],[2.98,50.41],[3.65,2.83]],"id":41946970},{"atl":[[18.5,4.14],[11.5,3.23],[12,5.45],[13,8.33],[13.5,5.8],[9.4,4.32]],"id":41946970},{"spn":6.55,"spf":"NaN","id":41946970},{"atb":[[1.82,55.19],[2.06,94.16],[1.98,101.85],[2.12,1.66],[1.49,188.34],[1.93,107.33],[1.66,83.19],[2.1,14.39]],"id":39931665},{"atl":[[5.6,9.47],[6.4,13.44],[6,10.56],[6.8,17.24],[5.2,8.64],[8.4,9.81]],"id":39931665},{"spn":3.66,"spf":"NaN","id":39931665},{"atb":[[3.2,8.87],[2.86,53.66],[2.52,65.79],[2.6,39.24],[3.15,46.43],[2.98,22.01],[2.96,50.92]],"id":39267517},{"atl":[[16,4.83],[16.5,3.48],[8.2,4.9],[11,7.25],[8.4,4.9],[15.5,4.36]],"id":39267517},{"spn":5.7,"spf":"NaN","id":39267517},{"atb":[[1.99,15.99],[1.63,86.94],[1.25,210.14],[1.85,117.43],[1.9,110.91],[1.77,58.92],[1.95,105.07]],"id":37406513},{"atl":[[5.6,15.78],[7.2,11.7],[6.4,9.12],[4.6,10.08],[5.5,9.69],[11.5,9.52]],"id":37406513},{"spn":3.29,"spf":"NaN","id":37406513},{"atb":[[1.2,499.1],[1.36,121.11],[1.25,399.28],[1.33,193.83],[1.3,332.73],[1.39,40.6]],"id":39860456},{"spl":[[1.01,5.17]],"id":39860456},{"atl":[[2.54,23.57],[2.74,41.72],[4.1,32.26],[2.52,25.34],[3.4,25.03],[2.94,37.42]],"id":39860456},{"spn":1.39,"spf":1.0,"id":39860456}],"con":true,"img":true}]}
{"op":"mcm","clk":"5348684687","pt":1646219839789,"mc":[{"id":"1.195453630","rc":[{"spn":6.55,"spf":"NaN","id":41946970},{"atl":[[15.5,0]],"id":39267517}],"con":true,"img":false}]}
{"op":"mcm","clk":"5348684701","pt":1646219839893,"mc":[{"id":"1.195453630","rc":[{"atl":[[18,4.36]],"id":39267517}],"con":true,"img":false}]}
{"op":"mcm","clk":"5348689645","pt":1646219880160,"mc":[{"id":"1.195453630","rc":[{"atb":[[2.3,76.92],[2.38,1.66]],"id":40717352},{"atb":[[3.55,3.26],[3.3,43.48]],"id":41946970}],"con":true,"img":false}]}
{"op":"mcm","clk":"5348690086","pt":1646219883276,"mc":[{"id":"1.195453630","rc":[{"atb":[[2.34,0]],"id":40717352},{"atb":[[3.65,0]],"id":41946970}],"con":true,"img":false}]}
{"op":"mcm","clk":"5348691352","pt":1646219892184,"mc":[{"id":"1.195453630","rc":[{"atb":[[2.36,5.51]],"id":40717352},{"atb":[[3.55,6.2]],"id":41946970}],"con":true,"img":false}]}
{"op":"mcm","clk":"5348692302","pt":1646219899392,"mc":[{"id":"1.195453630","rc":[{"atb":[[2.32,0]],"id":40717352},{"atb":[[3.7,0]],"id":41946970}],"con":true,"img":false}]}
{"op":"mcm","clk":"5348692324","pt":1646219899597,"mc":[{"id":"1.195453630","rc":[{"atb":[[3.6,1.66]],"id":41946970}],"con":true,"img":false}]}
{"op":"mcm","clk":"5348693095","pt":1646219905586,"mc":[{"id":"1.195453630","rc":[{"atl":[[18,0]],"id":39267517}],"con":true,"img":false}]}
{"op":"mcm","clk":"5348693105","pt":1646219905687,"mc":[{"id":"1.195453630","rc":[{"atl":[[15.5,4.36]],"id":39267517}],"con":true,"img":false}]}
{"op":"mcm","clk":"5348693512","pt":1646219909315,"mc":[{"id":"1.195453630","rc":[{"atb":[[2.28,0]],"id":40717352},{"atb":[[3.25,0]],"id":41946970}],"con":true,"img":false}]}
{"op":"mcm","clk":"5348693524","pt":1646219909408,"mc":[{"id":"1.195453630","rc":[{"atb":[[2.32,34.06]],"id":40717352},{"atb":[[3.35,19.38]],"id":41946970}],"con":true,"img":false}]}
{"op":"mcm","clk":"5348693635","pt":1646219910407,"mc":[{"id":"1.195453630","rc":[{"atb":[[2.36,0]],"id":40717352}],"con":true,"img":false}]}
{"op":"mcm","clk":"5348694083","pt":1646219914011,"mc":[{"id":"1.195453630","rc":[{"atb":[[2.36,6.12]],"id":40717352}],"con":true,"img":false}]}
{"op":"mcm","clk":"5348694363","pt":1646219916207,"mc":[{"id":"1.195453630","rc":[{"atb":[[2.38,7.1]],"id":40717352}],"con":true,"img":false}]}
{"op":"mcm","clk":"5348694919","pt":1646219920760,"mc":[{"id":"1.195453630","rc":[{"atb":[[2.4,7.11],[2.3,0]],"id":40717352},{"atl":[[7.2,27.83],[6.4,0]],"id":40717352},{"atb":[[3.55,25.58],[3.3,0]],"id":41946970},{"atl":[[4.8,26.32],[4.1,0]],"id":39860456}],"con":true,"img":false}]}
{"op":"mcm","clk":"5348695140","pt":1646219922436,"mc":[{"id":"1.195453630","rc":[{"atb":[[3.55,22.64]],"id":41946970}],"con":true,"img":false}]}
{"op":"mcm","clk":"5348695406","pt":1646219924323,"mc":[{"id":"1.195453630","rc":[{"atl":[[5.8,18.12]],"id":39931665},{"atb":[[2.52,0],[2.78,56.18]],"id":39267517},{"atl":[[11.5,0]],"id":37406513}],"con":true,"img":false}]}
{"op":"mcm","clk":"5348695416","pt":1646219924427,"mc":[{"id":"1.195453630","rc":[{"atl":[[6.8,0]],"id":39931665},{"atl":[[5,20.16]],"id":37406513}],"con":true,"img":false}]}
{"op":"mcm","clk":"5348695650","pt":1646219925967,"mc":[{"id":"1.195453630","rc":[{"atb":[[2.4,0],[2.28,78.13]],"id":40717352}],"con":true,"img":false}]}
{"op":"mcm","clk":"5348695963","pt":1646219928252,"mc":[{"id":"1.195453630","rc":[{"atb":[[3.65,2.83]],"id":41946970}],"con":true,"img":false}]}
{"op":"mcm","clk":"5348696232","pt":1646219930349,"mc":[{"id":"1.195453630","rc":[{"atl":[[15.5,0]],"id":39267517}],"con":true,"img":false}]}
{"op":"mcm","clk":"5348697136","pt":1646219937473,"mc":[{"id":"1.195453630","rc":[{"atb":[[3.6,0]],"id":41946970}],"con":true,"img":false}]}
{"op":"mcm","clk":"5348697162","pt":1646219937685,"mc":[{"id":"1.195453630","rc":[{"atb":[[3.7,1.66]],"id":41946970}],"con":true,"img":false}]}
{"op":"mcm","clk":"5348697585","pt":1646219940860,"mc":[{"id":"1.195453630","rc":[{"atb":[[2.32,0]],"id":40717352},{"atb":[[3.35,0]],"id":41946970}],"con":true,"img":false}]}
{"op":"mcm","clk":"5348697600","pt":1646219940962,"mc":[{"id":"1.195453630","rc":[{"atb":[[2.3,34.06]],"id":40717352},{"atb":[[3.25,19.38]],"id":41946970}],"con":true,"img":false}]}
{"op":"mcm","clk":"5348697685","pt":1646219941778,"mc":[{"id":"1.195453630","rc":[{"atl":[[4.1,32.26]],"id":39860456}],"con":true,"img":false}]}
{"op":"mcm","clk":"5348697699","pt":1646219941883,"mc":[{"id":"1.195453630","rc":[{"atl":[[7.2,11.7],[6.6,16.27]],"id":40717352},{"atl":[[4.8,0]],"id":39860456}],"con":true,"img":false}]}
{"op":"mcm","clk":"5348697820","pt":1646219942977,"mc":[{"id":"1.195453630","rc":[{"atb":[[2.36,20.83],[2.24,100.81],[2.32,37.88],[2.28,136.72]],"id":40717352},{"atl":[[5.1,4.88],[5.3,11.63],[5.5,16.67],[5.7,26.6]],"id":40717352},{"atb":[[3.2,102.19],[3.4,20.83],[3.5,8],[3.3,32.61]],"id":41946970},{"atl":[[8,17.86],[7.2,8.06],[6.8,3.45],[7.6,11.36]],"id":41946970},{"atb":[[1.92,81.52],[1.9,138.89],[1.96,20.83],[1.94,53.19]],"id":39931665},{"atl":[[6.4,27.33],[5.8,22.29],[6,20.56],[6.8,21.55]],"id":39931665},{"atb":[[2.92,65.1],[3.1,9.52],[3,25],[2.96,89.19]],"id":39267517},{"atl":[[7.2,12.1],[6.4,3.7],[6.8,8.62],[7.6,18.94]],"id":39267517},{"atb":[[1.82,91.46],[1.8,156.25],[1.84,59.52],[1.86,23.26]],"id":37406513},{"atl":[[5.6,42.95],[5,25.16],[5.2,11.9],[5.4,17.05]],"id":37406513},{"atb":[[1.41,121.95],[1.43,46.51],[1.37,250],[1.39,232.91]],"id":39860456},{"atl":[[3.45,20.41],[3.35,8.51],[3.55,29.41],[3.65,47.17]],"id":39860456}],"con":true,"img":false}]}
{"op":"mcm","clk":"5348697836","pt":1646219943184,"mc":[{"id":"1.195453630","rc":[{"atl":[[6.2,8.62],[8.2,0]],"id":39267517}],"con":true,"img":false}]}
{"op":"mcm","clk":"5348697877","pt":1646219943610,"mc":[{"id":"1.195453630","rc":[{"atb":[[2.36,14.71],[2.38,1.66]],"id":40717352}],"con":true,"img":false}]}
{"op":"mcm","clk":"5348698009","pt":1646219944808,"mc":[{"id":"1.195453630","rc":[{"atb":[[2.6,0]],"id":39267517}],"con":true,"img":false}]}
{"op":"mcm","clk":"5348698024","pt":1646219944902,"mc":[{"id":"1.195453630","rc":[{"atb":[[2.42,39.24]],"id":39267517}],"con":true,"img":false}]}
{"op":"mcm","clk":"5348698216","pt":1646219946391,"mc":[{"id":"1.195453630","rc":[{"atb":[[1.39,213.66]],"id":39860456}],"con":true,"img":false}]}
{"op":"mcm","clk":"5348698331","pt":1646219947404,"mc":[{"id":"1.195453630","rc":[{"atl":[[5.5,0]],"id":37406513}],"con":true,"img":false}]}
{"op":"mcm","clk":"5348698345","pt":1646219947511,"mc":[{"id":"1.195453630","rc":[{"atl":[[4.9,9.69]],"id":37406513}],"con":true,"img":false}]}
{"op":"mcm","clk":"5348698442","pt":1646219948291,"mc":[{"id":"1.195453630","rc":[{"atl":[[6.2,0],[6.8,20.94]],"id":39267517}],"con":true,"img":false}]}
{"op":"mcm","clk":"5348698494","pt":1646219948706,"mc":[{"id":"1.195453630","rc":[{"atl":[[10,6.54]],"id":39267517}],"con":true,"img":false}]}
{"op":"mcm","clk":"5348698522","pt":1646219948910,"mc":[{"id":"1.195453630","rc":[{"atb":[[3.55,3.26]],"id":41946970}],"con":true,"img":false}]}
{"op":"mcm","clk":"5348698535","pt":1646219949017,"mc":[{"id":"1.195453630","rc":[{"atb":[[2.28,58.59],[2.34,37.88]],"id":40717352},{"atb":[[3.7,4.49]],"id":41946970},{"atb":[[2.86,107.33],[2.78,0]],"id":39267517}],"con":true,"img":false}]}
{"op":"mcm","clk":"5348698570","pt":1646219949296,"mc":[{"id":"1.195453630","rc":[{"atb":[[3.65,0]],"id":41946970}],"con":true,"img":false}]}
{"op":"mcm","clk":"5348698653","pt":1646219950007,"mc":[{"id":"1.195453630","rc":[{"atl":[[2.52,0]],"id":39860456}],"con":true,"img":false}]}
{"op":"mcm","clk":"5348698671","pt":1646219950118,"mc":[{"id":"1.195453630","rc":[{"atl":[[2.72,25.34]],"id":39860456}],"con":true,"img":false}]}
{"op":"mcm","clk":"5348698931","pt":1646219952219,"mc":[{"id":"1.195453630","rc":[{"atb":[[1.44,17.06]],"id":39860456}],"con":true,"img":false}]}
{"op":"mcm","clk":"5348699085","pt":1646219953418,"mc":[{"id":"1.195453630","rc":[{"atl":[[7.2,28.23]],"id":39267517}],"con":true,"img":false}]}
{"op":"mcm","clk":"5348699096","pt":1646219953515,"mc":[{"id":"1.195453630","rc":[{"atl":[[6.8,8.62]],"id":39267517}],"con":true,"img":false}]}
{"op":"mcm","clk":"5348699327","pt":1646219955397,"mc":[{"id":"1.195453630","rc":[{"atb":[[3.55,6.2]],"id":41946970}],"con":true,"img":false}]}
{"op":"mcm","clk":"5348699679","pt":1646219958329,"mc":[{"id":"1.195453630","rc":[{"atb":[[2.4,5.36]],"id":40717352}],"con":true,"img":false}]}
{"op":"mcm","clk":"5348700270","pt":1646219963214,"mc":[{"id":"1.195453630","rc":[{"atb":[[3.25,0]],"id":41946970},{"atb":[[1.82,0]],"id":39931665},{"atb":[[1.77,0]],"id":37406513}],"con":true,"img":false}]}
{"op":"mcm","clk":"5348700282","pt":1646219963317,"mc":[{"id":"1.195453630","rc":[{"atb":[[3.35,19.38]],"id":41946970},{"atb":[[1.91,55.19]],"id":39931665},{"atb":[[1.85,176.35]],"id":37406513}],"con":true,"img":false}]}
{"op":"mcm","clk":"5348700428","pt":1646219964520,"mc":[{"id":"1.195453630","rc":[{"atb":[[1.36,0]],"id":39860456}],"con":true,"img":false}]}
{"op":"mcm","clk":"5348700620","pt":1646219965920,"mc":[{"id":"1.195453630","rc":[{"atl":[[6.2,0]],"id":40717352},{"atl":[[11.5,0],[7.4,6.81]],"id":41946970},{"atl":[[16.5,0],[7,7.26]],"id":39267517}],"con":true,"img":false}]}
{"op":"mcm","clk":"5348700634","pt":1646219966026,"mc":[{"id":"1.195453630","rc":[{"atl":[[5.4,8.38]],"id":40717352}],"con":true,"img":false}]}
{"op":"mcm","clk":"5348700819","pt":1646219967341,"mc":[{"id":"1.195453630","rc":[{"atl":[[7.2,12.1],[6.8,17.24]],"id":39267517}],"con":true,"img":false}]}
{"op":"mcm","clk":"5348700991","pt":1646219968541,"mc":[{"id":"1.195453630","rc":[{"atl":[[6.4,0],[5.3,12.73]],"id":37406513}],"con":true,"img":false}]}
{"op":"mcm","clk":"5348701537","pt":1646219972742,"mc":[{"id":"1.195453630","rc":[{"atb":[[1.39,192.31]],"id":39860456}],"con":true,"img":false}]}
{"op":"mcm","clk":"5348701566","pt":1646219972949,"mc":[{"id":"1.195453630","rc":[{"atb":[[2.4,11.3]],"id":40717352}],"con":true,"img":false}]}
{"op":"mcm","clk":"5348702057","pt":1646219976451,"mc":[{"id":"1.195453630","rc":[{"atb":[[2.38,0]],"id":40717352}],"con":true,"img":false}]}
{"op":"mcm","clk":"5348702079","pt":1646219976616,"mc":[{"id":"1.195453630","rc":[{"atb":[[2.42,1.66]],"id":40717352}],"con":true,"img":false}]}
{"op":"mcm","clk":"5348702925","pt":1646219982952,"mc":[{"id":"1.195453630","rc":[{"atb":[[1.43,126.81]],"id":39860456}],"con":true,"img":false}]}
{"op":"mcm","clk":"5348702941","pt":1646219983061,"mc":[{"id":"1.195453630","rc":[{"atb":[[1.42,143.06]],"id":39860456}],"con":true,"img":false}]}
{"op":"mcm","clk":"5348702954","pt":1646219983159,"mc":[{"id":"1.195453630","rc":[{"atb":[[1.33,0]],"id":39860456}],"con":true,"img":false}]}
{"op":"mcm","clk":"5348703109","pt":1646219984355,"mc":[{"id":"1.195453630","rc":[{"atl":[[7,0]],"id":40717352}],"con":true,"img":false}]}
{"op":"mcm","clk":"5348703124","pt":1646219984458,"mc":[{"id":"1.195453630","rc":[{"atl":[[6.4,10.9]],"id":40717352}],"con":true,"img":false}]}
{"op":"mcm","clk":"5348703242","pt":1646219985349,"mc":[{"id":"1.195453630","rc":[{"atb":[[1.44,0]],"id":39860456}],"con":true,"img":false}]}
{"op":"mcm","clk":"5348703429","pt":1646219986969,"mc":[{"id":"1.195453630","rc":[{"atb":[[2.08,60.49],[1.86,0]],"id":40717352}],"con":true,"img":false}]}
{"op":"mcm","clk":"5348703951","pt":1646219990979,"mc":[{"id":"1.195453630","rc":[{"atl":[[7,0]],"id":39267517}],"con":true,"img":false}]}
{"op":"mcm","clk":"5348703966","pt":1646219991078,"mc":[{"id":"1.195453630","rc":[{"atl":[[6.6,7.26]],"id":39267517}],"con":true,"img":false}]}
{"op":"mcm","clk":"5348703976","pt":1646219991182,"mc":[{"id":"1.195453630","rc":[{"atl":[[7.2,28.23],[6.8,8.62]],"id":39267517}],"con":true,"img":false}]}
{"op":"mcm","clk":"5348704004","pt":1646219991350,"mc":[{"id":"1.195453630","rc":[{"atl":[[7.2,12.1],[6.4,10.97]],"id":39267517}],"con":true,"img":false}]}
{"op":"mcm","clk":"5348704038","pt":1646219991660,"mc":[{"id":"1.195453630","rc":[{"atb":[[1.46,16.32]],"id":39860456}],"con":true,"img":false}]}
{"op":"mcm","clk":"5348705466","pt":1646220002880,"mc":[{"id":"1.195453630","rc":[{"spn":3.76,"spf":"NaN","id":40717352},{"spn":5.25,"spf":"NaN","id":41946970},{"spn":4.8,"spf":"NaN","id":39267517},{"atb":[[1.46,34.42]],"id":39860456},{"spn":1.46,"spf":1.0,"id":39860456}],"con":true,"img":false}]}
{"op":"mcm","clk":"5348705634","pt":1646220004075,"mc":[{"id":"1.195453630","rc":[{"atl":[[6,10]],"id":39931665}],"con":true,"img":false}]}
{"op":"mcm","clk":"5348705648","pt":1646220004181,"mc":[{"id":"1.195453630","rc":[{"atl":[[5.7,10.56]],"id":39931665}],"con":true,"img":false}]}
{"op":"mcm","clk":"5348707018","pt":1646220014666,"mc":[{"id":"1.195453630","rc":[{"atl":[[6.6,0]],"id":39267517}],"con":true,"img":false}]}
{"op":"mcm","clk":"5348707031","pt":1646220014769,"mc":[{"id":"1.195453630","rc":[{"atl":[[7.2,28.23],[6.4,3.7],[6.2,7.26]],"id":39267517}],"con":true,"img":false}]}
{"op":"mcm","clk":"5348708111","pt":1646220022623,"mc":[{"id":"1.195453630","rc":[{"atl":[[6.2,0]],"id":39267517}],"con":true,"img":false}]}
{"op":"mcm","clk":"5348708129","pt":1646220022726,"mc":[{"id":"1.195453630","rc":[{"atl":[[7,7.26]],"id":39267517}],"con":true,"img":false}]}
{"op":"mcm","clk":"5348709446","pt":1646220033220,"mc":[{"id":"1.195453630","rc":[{"atl":[[7.2,12.1],[6.8,17.24]],"id":39267517}],"con":true,"img":false}]}
{"op":"mcm","clk":"5348712380","pt":1646220056862,"mc":[{"id":"1.195453630","rc":[{"atl":[[7,0]],"id":39267517}],"con":true,"img":false}]}
{"op":"mcm","clk":"5348712393","pt":1646220056964,"mc":[{"id":"1.195453630","rc":[{"atl":[[6.6,7.26]],"id":39267517}],"con":true,"img":false}]}
{"op":"mcm","clk":"5348712406","pt":1646220057068,"mc":[{"id":"1.195453630","rc":[{"atl":[[7.2,28.23],[6.8,8.62]],"id":39267517}],"con":true,"img":false}]}
{"op":"mcm","clk":"5348713349","pt":1646220064788,"mc":[{"id":"1.195453630","rc":[{"atl":[[6.6,0]],"id":39267517}],"con":true,"img":false}]}
{"op":"mcm","clk":"5348713361","pt":1646220064894,"mc":[{"id":"1.195453630","rc":[{"atl":[[7,7.26]],"id":39267517}],"con":true,"img":false}]}
{"op":"mcm","clk":"5348714480","pt":1646220075087,"mc":[{"id":"1.195453630","rc":[{"atl":[[7.2,12.1],[6.8,17.24]],"id":39267517}],"con":true,"img":false}]}
{"op":"mcm","clk":"5348717393","pt":1646220097735,"mc":[{"id":"1.195453630","rc":[{"atl":[[7,0]],"id":39267517}],"con":true,"img":false}]}
{"op":"mcm","clk":"5348717404","pt":1646220097826,"mc":[{"id":"1.195453630","rc":[{"atl":[[6.6,7.26]],"id":39267517}],"con":true,"img":false}]}
{"op":"mcm","clk":"5348717417","pt":1646220097922,"mc":[{"id":"1.195453630","rc":[{"atl":[[7.2,28.23],[6.8,8.62]],"id":39267517}],"con":true,"img":false}]}
{"op":"mcm","clk":"5348717580","pt":1646220099036,"mc":[{"id":"1.195453630","rc":[{"atb":[[1.91,0]],"id":39931665}],"con":true,"img":false}]}
{"op":"mcm","clk":"5348717597","pt":1646220099137,"mc":[{"id":"1.195453630","rc":[{"atb":[[1.95,55.19]],"id":39931665}],"con":true,"img":false}]}
{"op":"mcm","clk":"5348718438","pt":1646220105677,"mc":[{"id":"1.195453630","rc":[{"atl":[[6.6,0]],"id":39267517}],"con":true,"img":false}]}
{"op":"mcm","clk":"5348718452","pt":1646220105762,"mc":[{"id":"1.195453630","rc":[{"atl":[[7,7.26]],"id":39267517}],"con":true,"img":false}]}
{"op":"mcm","clk":"5348719187","pt":1646220111447,"mc":[{"id":"1.195453630","rc":[{"atb":[[2.22,81.97],[2.34,0]],"id":40717352},{"atb":[[3.7,1.66],[3.4,41.66]],"id":41946970},{"atb":[[2.86,53.66],[2.7,58.82]],"id":39267517}],"con":true,"img":false}]}
{"op":"mcm","clk":"5348719251","pt":1646220111968,"mc":[{"id":"1.195453630","rc":[{"atb":[[2.4,5.94]],"id":40717352}],"con":true,"img":false}]}
{"op":"mcm","clk":"5348719710","pt":1646220115467,"mc":[{"id":"1.195453630","rc":[{"atb":[[3.7,0]],"id":41946970}],"con":true,"img":false}]}
{"op":"mcm","clk":"5348719724","pt":1646220115569,"mc":[{"id":"1.195453630","rc":[{"atl":[[7.2,12.1],[6.8,17.24]],"id":39267517}],"con":true,"img":false}]}
{"op":"mcm","clk":"5348719735","pt":1646220115668,"mc":[{"id":"1.195453630","rc":[{"atb":[[3.6,1.66]],"id":41946970}],"con":true,"img":false}]}
{"op":"mcm","clk":"5348720042","pt":1646220118072,"mc":[{"id":"1.195453630","rc":[{"atb":[[2.38,5.44]],"id":40717352}],"con":true,"img":false}]}
{"op":"mcm","clk":"5348720078","pt":1646220118370,"mc":[{"id":"1.195453630","rc":[{"atb":[[2.08,0]],"id":40717352},{"atl":[[6.4,0]],"id":40717352},{"atl":[[5.7,0]],"id":39931665}],"con":true,"img":false}]}
{"op":"mcm","clk":"5348720094","pt":1646220118479,"mc":[{"id":"1.195453630","rc":[{"atb":[[1.94,60.49]],"id":40717352},{"atl":[[7,10.9]],"id":40717352},{"atl":[[6.2,10.56]],"id":39931665}],"con":true,"img":false}]}
{"op":"mcm","clk":"5348720162","pt":1646220118972,"mc":[{"id":"1.195453630","rc":[{"atb":[[1.66,0]],"id":39931665}],"con":true,"img":false}]}
{"op":"mcm","clk":"5348720177","pt":1646220119078,"mc":[{"id":"1.195453630","rc":[{"atb":[[1.73,83.19]],"id":39931665}],"con":true,"img":false}]}
{"op":"mcm","clk":"5348721451","pt":1646220128875,"mc":[{"id":"1.195453630","rc":[{"atb":[[2.22,0],[2.34,37.88]],"id":40717352},{"atb":[[3.6,7.87],[3.4,20.83]],"id":41946970},{"spn":5.2,"spf":"NaN","id":41946970},{"atb":[[2.86,107.33],[2.7,0]],"id":39267517}],"con":true,"img":false}]}
{"op":"mcm","clk":"5348721514","pt":1646220129341,"mc":[{"id":"1.195453630","rc":[{"atb":[[3.35,0]],"id":41946970}],"con":true,"img":false}]}
{"op":"mcm","clk":"5348721530","pt":1646220129444,"mc":[{"id":"1.195453630","rc":[{"atb":[[3.5,27.38]],"id":41946970}],"con":true,"img":false}]}
{"op":"mcm","clk":"5348721599","pt":1646220130071,"mc":[{"id":"1.195453630","rc":[{"atb":[[2.38,0]],"id":40717352},{"atb":[[3.55,3.26]],"id":41946970}],"con":true,"img":false}]}
{"op":"mcm","clk":"5348722317","pt":1646220135905,"mc":[{"id":"1.195453630","rc":[{"atb":[[2.4,11.3]],"id":40717352},{"atb":[[3.6,10.76]],"id":41946970}],"con":true,"img":false}]}
{"op":"mcm","clk":"5348722659","pt":1646220138578,"mc":[{"id":"1.195453630","rc":[{"atb":[[3.55,0]],"id":41946970}],"con":true,"img":false}]}
{"op":"mcm","clk":"5348722673","pt":1646220138679,"mc":[{"id":"1.195453630","rc":[{"atl":[[7,0]],"id":39267517}],"con":true,"img":false}]}
{"op":"mcm","clk":"5348722687","pt":1646220138780,"mc":[{"id":"1.195453630","rc":[{"atl":[[6.6,7.26]],"id":39267517}],"con":true,"img":false}]}
{"op":"mcm","clk":"5348722703","pt":1646220138887,"mc":[{"id":"1.195453630","rc":[{"atl":[[7.2,28.23],[6.8,8.62]],"id":39267517}],"con":true,"img":false}]}
{"op":"mcm","clk":"5348723672","pt":1646220146643,"mc":[{"id":"1.195453630","rc":[{"atl":[[6.6,0]],"id":39267517}],"con":true,"img":false}]}
{"op":"mcm","clk":"5348723680","pt":1646220146687,"mc":[{"id":"1.195453630","rc":[{"atl":[[7,7.26]],"id":39267517}],"con":true,"img":false}]}
{"op":"mcm","clk":"5348724877","pt":1646220156032,"mc":[{"id":"1.195453630","rc":[{"atl":[[7.2,12.1],[6.8,17.24]],"id":39267517}],"con":true,"img":false}]}
{"op":"mcm","clk":"5348725067","pt":1646220157537,"mc":[{"id":"1.195453630","rc":[{"atb":[[3.6,13.97]],"id":41946970}],"con":true,"img":false}]}
{"op":"mcm","clk":"5348727814","pt":1646220179578,"mc":[{"id":"1.195453630","rc":[{"atl":[[7,0]],"id":39267517}],"con":true,"img":false}]}
{"op":"mcm","clk":"5348727825","pt":1646220179675,"mc":[{"id":"1.195453630","rc":[{"atl":[[6.6,7.26]],"id":39267517}],"con":true,"img":false}]}
{"op":"mcm","clk":"5348727835","pt":1646220179736,"mc":[{"id":"1.195453630","rc":[{"atl":[[7.2,28.23],[6.8,8.62]],"id":39267517}],"con":true,"img":false}]}
{"op":"mcm","clk":"5348728750","pt":1646220187487,"mc":[{"id":"1.195453630","rc":[{"atl":[[6.6,0]],"id":39267517}],"con":true,"img":false}]}
{"op":"mcm","clk":"5348728762","pt":1646220187590,"mc":[{"id":"1.195453630","rc":[{"atl":[[7,7.26]],"id":39267517}],"con":true,"img":false}]}
{"op":"mcm","clk":"5348729847","pt":1646220196462,"mc":[{"id":"1.195453630","rc":[{"atl":[[7.2,12.1],[6.8,17.24]],"id":39267517}],"con":true,"img":false}]}
{"op":"mcm","clk":"5348732555","pt":1646220219135,"mc":[{"id":"1.195453630","rc":[{"atl":[[7,0]],"id":39267517}],"con":true,"img":false}]}
{"op":"mcm","clk":"5348732568","pt":1646220219240,"mc":[{"id":"1.195453630","rc":[{"atl":[[6.6,7.26]],"id":39267517}],"con":true,"img":false}]}
{"op":"mcm","clk":"5348732584","pt":1646220219339,"mc":[{"id":"1.195453630","rc":[{"atl":[[7.2,28.23],[6.8,8.62]],"id":39267517}],"con":true,"img":false}]}
{"op":"mcm","clk":"5348733525","pt":1646220227031,"mc":[{"id":"1.195453630","rc":[{"atl":[[6.6,0]],"id":39267517}],"con":true,"img":false}]}
{"op":"mcm","clk":"5348733538","pt":1646220227137,"mc":[{"id":"1.195453630","rc":[{"atl":[[7,7.26]],"id":39267517}],"con":true,"img":false}]}
{"op":"mcm","clk":"5348734083","pt":1646220231749,"mc":[{"id":"1.195453630","rc":[{"atb":[[2.22,81.97],[2.34,0]],"id":40717352},{"atb":[[3.6,7.76],[3.4,62.5]],"id":41946970},{"atb":[[2.86,53.66],[2.7,58.82]],"id":39267517}],"con":true,"img":false}]}
{"op":"mcm","clk":"5348734140","pt":1646220232229,"mc":[{"id":"1.195453630","rc":[{"atb":[[2.4,5.94]],"id":40717352}],"con":true,"img":false}]}
{"op":"mcm","clk":"5348734304","pt":1646220233748,"mc":[{"id":"1.195453630","rc":[{"atl":[[7,0]],"id":40717352},{"atl":[[6.2,0]],"id":39931665}],"con":true,"img":false}]}
{"op":"mcm","clk":"5348734316","pt":1646220233843,"mc":[{"id":"1.195453630","rc":[{"atl":[[6.4,10.9]],"id":40717352},{"atl":[[5.7,10.56]],"id":39931665}],"con":true,"img":false}]}
{"op":"mcm","clk":"5348734430","pt":1646220234934,"mc":[{"id":"1.195453630","rc":[{"atb":[[1.94,0]],"id":40717352}],"con":true,"img":false}]}
{"op":"mcm","clk":"5348734441","pt":1646220235045,"mc":[{"id":"1.195453630","rc":[{"atb":[[2.08,60.49]],"id":40717352}],"con":true,"img":false}]}
{"op":"mcm","clk":"5348734518","pt":1646220235729,"mc":[{"id":"1.195453630","rc":[{"atl":[[7.2,12.1],[6.8,17.24]],"id":39267517}],"con":true,"img":false}]}
{"op":"mcm","clk":"5348734933","pt":1646220239350,"mc":[{"id":"1.195453630","rc":[{"atb":[[2.38,5.44]],"id":40717352}],"con":true,"img":false}]}
{"op":"mcm","clk":"5348735306","pt":1646220242334,"mc":[{"id":"1.195453630","rc":[{"atb":[[2.4,0]],"id":40717352}],"con":true,"img":false}]}
{"op":"mcm","clk":"5348736753","pt":1646220254780,"mc":[{"id":"1.195453630","rc":[{"atb":[[2.3,92.65]],"id":40717352},{"atb":[[3.65,27.38]],"id":41946970},{"atb":[[2.88,53.19],[2.7,0]],"id":39267517},{"atl":[[3.4,33.36]],"id":39860456}],"con":true,"img":false}]}
{"op":"mcm","clk":"5348736766","pt":1646220254889,"mc":[{"id":"1.195453630","rc":[{"atb":[[2.22,0]],"id":40717352},{"atb":[[3.4,20.83]],"id":41946970},{"atl":[[3.35,0]],"id":39860456}],"con":true,"img":false}]}
{"op":"mcm","clk":"5348736946","pt":1646220256359,"mc":[{"id":"1.195453630","rc":[{"atb":[[3.6,4.87]],"id":41946970}],"con":true,"img":false}]}
{"op":"mcm","clk":"5348736979","pt":1646220256670,"mc":[{"id":"1.195453630","rc":[{"atb":[[2.38,11.48]],"id":40717352},{"spn":5.22,"spf":"NaN","id":41946970}],"con":true,"img":false}]}
{"op":"mcm","clk":"5348737080","pt":1646220257502,"mc":[{"id":"1.195453630","rc":[{"atb":[[2.42,0]],"id":40717352},{"atb":[[3.6,3.2]],"id":41946970}],"con":true,"img":false}]}
{"op":"mcm","clk":"5348737106","pt":1646220257662,"mc":[{"id":"1.195453630","rc":[{"atb":[[2.4,1.66]],"id":40717352},{"atb":[[3.7,1.66]],"id":41946970}],"con":true,"img":false}]}
{"op":"mcm","clk":"5348737225","pt":1646220258657,"mc":[{"id":"1.195453630","rc":[{"atl":[[7,0]],"id":39267517}],"con":true,"img":false}]}
{"op":"mcm","clk":"5348737238","pt":1646220258759,"mc":[{"id":"1.195453630","rc":[{"atl":[[7.2,28.23],[6.8,8.62],[6.6,7.26]],"id":39267517}],"con":true,"img":false}]}
{"op":"mcm","clk":"5348737248","pt":1646220258862,"mc":[{"id":"1.195453630","rc":[{"atl":[[7.2,12.1],[6.4,10.97]],"id":39267517}],"con":true,"img":false}]}
{"op":"mcm","clk":"5348737672","pt":1646220262462,"mc":[{"id":"1.195453630","rc":[{"atb":[[3.75,2.73]],"id":41946970}],"con":true,"img":false}]}
{"op":"mcm","clk":"5348737926","pt":1646220264813,"mc":[{"id":"1.195453630","rc":[{"atl":[[3.5,20]],"id":39860456}],"con":true,"img":false}]}
{"op":"mcm","clk":"5348738562","pt":1646220270787,"mc":[{"id":"1.195453630","rc":[{"atb":[[3.7,7.12],[3.65,0]],"id":41946970}],"con":true,"img":false}]}
{"op":"mcm","clk":"5348738625","pt":1646220271417,"mc":[{"id":"1.195453630","rc":[{"atb":[[3.6,0]],"id":41946970}],"con":true,"img":false}]}
{"op":"mcm","clk":"5348738955","pt":1646220274637,"mc":[{"id":"1.195453630","rc":[{"atb":[[3.75,0]],"id":41946970}],"con":true,"img":false}]}
{"op":"mcm","clk":"5348738995","pt":1646220274896,"mc":[{"id":"1.195453630","rc":[{"atl":[[3.45,0],[3.6,28.85],[3.55,0],[3.65,0]],"id":39860456}],"con":true,"img":false}]}
{"op":"mcm","clk":"5348739702","pt":1646220281500,"mc":[{"id":"1.195453630","rc":[{"atb":[[3.6,2.89]],"id":41946970}],"con":true,"img":false}]}
{"op":"mcm","clk":"5348739826","pt":1646220282490,"mc":[{"id":"1.195453630","rc":[{"atl":[[6.6,0]],"id":39267517}],"con":true,"img":false}]}
{"op":"mcm","clk":"5348739838","pt":1646220282596,"mc":[{"id":"1.195453630","rc":[{"atl":[[6.2,7.26]],"id":39267517}],"con":true,"img":false}]}
{"op":"mcm","clk":"5348739846","pt":1646220282712,"mc":[{"id":"1.195453630","rc":[{"atl":[[7.2,28.23],[6.4,3.7]],"id":39267517}],"con":true,"img":false}]}
{"op":"mcm","clk":"5348740109","pt":1646220284908,"mc":[{"id":"1.195453630","rc":[{"atl":[[3.7,46.3]],"id":39860456}],"con":true,"img":false}]}
{"op":"mcm","clk":"5348740734","pt":1646220290334,"mc":[{"id":"1.195453630","rc":[{"atl":[[6.2,0]],"id":39267517}],"con":true,"img":false}]}
{"op":"mcm","clk":"5348740747","pt":1646220290439,"mc":[{"id":"1.195453630","rc":[{"atl":[[7,7.26]],"id":39267517}],"con":true,"img":false}]}
{"op":"mcm","clk":"5348741609","pt":1646220298447,"mc":[{"id":"1.195453630","rc":[{"atl":[[7.2,12.1],[6.8,17.24]],"id":39267517}],"con":true,"img":false}]}
{"op":"mcm","clk":"5348742488","pt":1646220307249,"mc":[{"id":"1.195453630","rc":[{"atb":[[3.6,6.09]],"id":41946970}],"con":true,"img":false}]}
{"op":"mcm","clk":"5348743959","pt":1646220322011,"mc":[{"id":"1.195453630","rc":[{"spn":3.75,"spf":"NaN","id":40717352},{"spn":5.25,"spf":"NaN","id":41946970},{"atl":[[7,0]],"id":39267517}],"con":true,"img":false}]}
{"op":"mcm","clk":"5348743969","pt":1646220322059,"mc":[{"id":"1.195453630","rc":[{"atl":[[6.6,7.26]],"id":39267517}],"con":true,"img":false}]}
{"op":"mcm","clk":"5348743980","pt":1646220322162,"mc":[{"id":"1.195453630","rc":[{"atl":[[7.2,28.23],[6.8,8.62]],"id":39267517}],"con":true,"img":false}]}
{"op":"mcm","clk":"5348743999","pt":1646220322366,"mc":[{"id":"1.195453630","rc":[{"atl":[[7.2,12.1],[6.4,10.97]],"id":39267517}],"con":true,"img":false}]}
{"op":"mcm","clk":"5348746431","pt":1646220345724,"mc":[{"id":"1.195453630","rc":[{"atl":[[6.6,0]],"id":39267517}],"con":true,"img":false}]}
{"op":"mcm","clk":"5348746441","pt":1646220345827,"mc":[{"id":"1.195453630","rc":[{"atl":[[6.2,7.26]],"id":39267517}],"con":true,"img":false}]}
{"op":"mcm","clk":"5348746451","pt":1646220345930,"mc":[{"id":"1.195453630","rc":[{"atl":[[7.2,28.23],[6.4,3.7]],"id":39267517}],"con":true,"img":false}]}
{"op":"mcm","clk":"5348747187","pt":1646220353710,"mc":[{"id":"1.195453630","rc":[{"atl":[[6.2,0]],"id":39267517}],"con":true,"img":false}]}
{"op":"mcm","clk":"5348747202","pt":1646220353813,"mc":[{"id":"1.195453630","rc":[{"atl":[[7,7.26]],"id":39267517}],"con":true,"img":false}]}
{"op":"mcm","clk":"5348747861","pt":1646220361019,"mc":[{"id":"1.195453630","rc":[{"atl":[[7.2,12.1],[6.8,17.24]],"id":39267517}],"con":true,"img":false}]}
{"op":"mcm","clk":"5348748159","pt":1646220363028,"mc":[{"id":"1.195453630","rc":[{"atb":[[2.3,34.06],[2.34,58.59]],"id":40717352},{"atl":[[3.35,8.51],[3.4,25.03]],"id":39860456}],"con":true,"img":false}]}
{"op":"mcm","clk":"5348748545","pt":1646220365937,"mc":[{"id":"1.195453630","rc":[{"atb":[[2.38,6.03]],"id":40717352}],"con":true,"img":false}]}
{"op":"mcm","clk":"5348749332","pt":1646220372829,"mc":[{"id":"1.195453630","rc":[{"atb":[[2.4,7.02]],"id":40717352}],"con":true,"img":false}]}
{"op":"mcm","clk":"5348749879","pt":1646220377557,"mc":[{"id":"1.195453630","rc":[{"atb":[[2.38,0]],"id":40717352}],"con":true,"img":false}]}
{"op":"mcm","clk":"5348750537","pt":1646220383969,"mc":[{"id":"1.195453630","rc":[{"atl":[[7,0]],"id":39267517}],"con":true,"img":false}]}
{"op":"mcm","clk":"5348750549","pt":1646220384073,"mc":[{"id":"1.195453630","rc":[{"atl":[[6.6,7.26]],"id":39267517}],"con":true,"img":false}]}
{"op":"mcm","clk":"5348750562","pt":1646220384167,"mc":[{"id":"1.195453630","rc":[{"atl":[[7.2,28.23],[6.8,8.62]],"id":39267517}],"con":true,"img":false}]}
{"op":"mcm","clk":"5348750815","pt":1646220386570,"mc":[{"id":"1.195453630","rc":[{"atb":[[2.3,0]],"id":40717352}],"con":true,"img":false}]}
{"op":"mcm","clk":"5348750829","pt":1646220386702,"mc":[{"id":"1.195453630","rc":[{"atb":[[2.36,48.77]],"id":40717352}],"con":true,"img":false}]}
{"op":"mcm","clk":"5348751303","pt":1646220390805,"mc":[{"id":"1.195453630","rc":[{"atb":[[2.4,1.66]],"id":40717352}],"con":true,"img":false}]}
{"op":"mcm","clk":"5348751433","pt":1646220391898,"mc":[{"id":"1.195453630","rc":[{"atl":[[6.6,0]],"id":39267517}],"con":true,"img":false}]}
{"op":"mcm","clk":"5348751444","pt":1646220392001,"mc":[{"id":"1.195453630","rc":[{"atl":[[7,7.26]],"id":39267517}],"con":true,"img":false}]}
{"op":"mcm","clk":"5348752145","pt":1646220398721,"mc":[{"id":"1.195453630","rc":[{"atb":[[2.42,5.28]],"id":40717352}],"con":true,"img":false}]}
{"op":"mcm","clk":"5348752164","pt":1646220398882,"mc":[{"id":"1.195453630","rc":[{"atl":[[7.2,12.1],[6.8,17.24]],"id":39267517}],"con":true,"img":false}]}
{"op":"mcm","clk":"5348753337","pt":1646220408522,"mc":[{"id":"1.195453630","rc":[{"atb":[[2.4,0]],"id":40717352}],"con":true,"img":false}]}
{"op":"mcm","clk":"5348753344","pt":1646220408627,"mc":[{"id":"1.195453630","rc":[{"atb":[[2.44,1.66]],"id":40717352}],"con":true,"img":false}]}
{"op":"mcm","clk":"5348754410","pt":1646220417633,"mc":[{"id":"1.195453630","rc":[{"atb":[[2.42,11.14]],"id":40717352}],"con":true,"img":false}]}
{"op":"mcm","clk":"5348755201","pt":1646220422258,"mc":[{"id":"1.195453630","rc":[{"atl":[[7,0]],"id":39267517}],"con":true,"img":false}]}
{"op":"mcm","clk":"5348755222","pt":1646220422374,"mc":[{"id":"1.195453630","rc":[{"atl":[[6.6,7.26]],"id":39267517}],"con":true,"img":false}]}
{"op":"mcm","clk":"5348755235","pt":1646220422477,"mc":[{"id":"1.195453630","rc":[{"atl":[[7.2,28.23],[6.8,8.62]],"id":39267517}],"con":true,"img":false}]}
{"op":"mcm","clk":"5348755285","pt":1646220422710,"mc":[{"id":"1.195453630","rc":[{"atl":[[7.2,12.1],[6.4,10.97]],"id":39267517}],"con":true,"img":false}]}
{"op":"mcm","clk":"5348759983","pt":1646220445966,"mc":[{"id":"1.195453630","rc":[{"spn":3.77,"spf":"NaN","id":40717352},{"atl":[[6.6,0]],"id":39267517}],"con":true,"img":false}]}
{"op":"mcm","clk":"5348760004","pt":1646220446117,"mc":[{"id":"1.195453630","rc":[{"atl":[[6.2,7.26]],"id":39267517}],"con":true,"img":false}]}
{"op":"mcm","clk":"5348760042","pt":1646220446223,"mc":[{"id":"1.195453630","rc":[{"atl":[[7.2,28.23],[6.4,3.7]],"id":39267517}],"con":true,"img":false}]}
{"op":"mcm","clk":"5348761841","pt":1646220453899,"mc":[{"id":"1.195453630","rc":[{"atl":[[6.2,0]],"id":39267517}],"con":true,"img":false}]}
{"op":"mcm","clk":"5348761859","pt":1646220454007,"mc":[{"id":"1.195453630","rc":[{"atl":[[7,7.26]],"id":39267517}],"con":true,"img":false}]}
{"op":"mcm","clk":"5348762669","pt":1646220460282,"mc":[{"id":"1.195453630","rc":[{"atl":[[7.2,12.1],[6.8,17.24]],"id":39267517}],"con":true,"img":false}]}
{"op":"mcm","clk":"5348764657","pt":1646220478416,"mc":[{"id":"1.195453630","rc":[{"atb":[[2.08,0]],"id":40717352},{"atl":[[6.4,0]],"id":40717352},{"atl":[[5.7,0]],"id":39931665}],"con":true,"img":false}]}
{"op":"mcm","clk":"5348764666","pt":1646220478526,"mc":[{"id":"1.195453630","rc":[{"atb":[[1.94,60.49]],"id":40717352},{"atl":[[7,10.9]],"id":40717352},{"atl":[[6.2,10.56]],"id":39931665}],"con":true,"img":false}]}
{"op":"mcm","clk":"5348765158","pt":1646220482932,"mc":[{"id":"1.195453630","rc":[{"atl":[[7,0]],"id":39267517}],"con":true,"img":false}]}
{"op":"mcm","clk":"5348765173","pt":1646220483032,"mc":[{"id":"1.195453630","rc":[{"atl":[[6.6,7.26]],"id":39267517}],"con":true,"img":false}]}
{"op":"mcm","clk":"5348765182","pt":1646220483138,"mc":[{"id":"1.195453630","rc":[{"atl":[[7.2,28.23],[6.8,8.62]],"id":39267517}],"con":true,"img":false}]}
{"op":"mcm","clk":"5348765195","pt":1646220483245,"mc":[{"id":"1.195453630","rc":[{"atl":[[6.4,10.97]],"id":39267517}],"con":true,"img":false}]}
{"op":"mcm","clk":"5348765207","pt":1646220483346,"mc":[{"id":"1.195453630","rc":[{"atl":[[7.2,12.1]],"id":39267517}],"con":true,"img":false}]}
{"op":"mcm","clk":"5348767418","pt":1646220506656,"mc":[{"id":"1.195453630","rc":[{"atl":[[6.6,0]],"id":39267517}],"con":true,"img":false}]}
{"op":"mcm","clk":"5348767431","pt":1646220506764,"mc":[{"id":"1.195453630","rc":[{"atl":[[6.2,7.26]],"id":39267517}],"con":true,"img":false}]}
{"op":"mcm","clk":"5348767443","pt":1646220506863,"mc":[{"id":"1.195453630","rc":[{"atl":[[7.2,28.23],[6.4,3.7]],"id":39267517}],"con":true,"img":false}]}
{"op":"mcm","clk":"5348767463","pt":1646220507030,"mc":[{"id":"1.195453630","rc":[{"atl":[[7.2,12.1],[6.2,15.88]],"id":39267517}],"con":true,"img":false}]}
{"op":"mcm","clk":"5348768226","pt":1646220514536,"mc":[{"id":"1.195453630","rc":[{"atl":[[6.2,8.62]],"id":39267517}],"con":true,"img":false}]}
{"op":"mcm","clk":"5348768235","pt":1646220514641,"mc":[{"id":"1.195453630","rc":[{"atl":[[7,7.26]],"id":39267517}],"con":true,"img":false}]}
{"op":"mcm","clk":"5348768243","pt":1646220514744,"mc":[{"id":"1.195453630","rc":[{"atl":[[6.2,0],[6.8,20.94]],"id":39267517}],"con":true,"img":false}]}
{"op":"mcm","clk":"5348769079","pt":1646220523293,"mc":[{"id":"1.195453630","rc":[{"atb":[[2.32,97.8],[2.34,0]],"id":40717352}],"con":true,"img":false}]}
{"op":"mcm","clk":"5348769767","pt":1646220530419,"mc":[{"id":"1.195453630","rc":[{"atb":[[2.36,14.71]],"id":40717352}],"con":true,"img":false}]}
{"op":"mcm","clk":"5348769775","pt":1646220530525,"mc":[{"id":"1.195453630","rc":[{"atb":[[2.34,34.06]],"id":40717352}],"con":true,"img":false}]}
{"op":"mcm","clk":"5348769842","pt":1646220531522,"mc":[{"id":"1.195453630","rc":[{"atb":[[2.32,0],[1.62,121],[2.36,0],[2.24,0],[1.72,27.78],[2.28,0]],"id":40717352},{"atl":[[5.1,0],[3.9,6.9]],"id":40717352},{"atb":[[3.7,1.66],[3.4,55.34]],"id":41946970},{"atl":[[8,0],[9.6,2.33],[7.2,0],[6.8,0],[7.6,0]],"id":41946970},{"atb":[[1.58,172.41],[1.49,0]],"id":39931665},{"atl":[[5.1,9.48],[5.8,0],[3.1,9.52]],"id":39931665},{"atb":[[3.1,0],[3.4,8.33]],"id":39267517},{"atl":[[5,0],[5.2,0],[5.7,25.54]],"id":37406513},{"atb":[[1.41,0],[1.43,80.3],[1.37,0],[1.09,222.22],[1.39,0]],"id":39860456}],"con":true,"img":false}]}
{"op":"mcm","clk":"5348769859","pt":1646220531722,"mc":[{"id":"1.195453630","rc":[{"atl":[[10.5,4.58]],"id":41946970}],"con":true,"img":false}]}
{"op":"mcm","clk":"5348769869","pt":1646220531824,"mc":[{"id":"1.195453630","rc":[{"atl":[[7.4,0]],"id":41946970},{"atb":[[1.42,0]],"id":39860456}],"con":true,"img":false}]}
{"op":"mcm","clk":"5348769880","pt":1646220531891,"mc":[{"id":"1.195453630","rc":[{"atb":[[1.37,143.06]],"id":39860456}],"con":true,"img":false}]}
{"op":"mcm","clk":"5348769939","pt":1646220532634,"mc":[{"id":"1.195453630","rc":[{"atb":[[2.42,5.86]],"id":40717352}],"con":true,"img":false}]}
{"op":"mcm","clk":"5348770020","pt":1646220533308,"mc":[{"id":"1.195453630","rc":[{"atl":[[5.4,0]],"id":37406513}],"con":true,"img":false}]}
{"op":"mcm","clk":"5348770148","pt":1646220534405,"mc":[{"id":"1.195453630","rc":[{"atl":[[5.3,0]],"id":37406513}],"con":true,"img":false}]}
{"op":"mcm","clk":"5348770159","pt":1646220534507,"mc":[{"id":"1.195453630","rc":[{"atl":[[5.5,12.73]],"id":37406513}],"con":true,"img":false}]}
{"op":"mcm","clk":"5348770200","pt":1646220534938,"mc":[{"id":"1.195453630","rc":[{"atb":[[3.7,0]],"id":41946970},{"atb":[[3.2,7.2]],"id":39267517}],"con":true,"img":false}]}
{"op":"mcm","clk":"5348770215","pt":1646220535087,"mc":[{"id":"1.195453630","rc":[{"atb":[[3.65,1.66]],"id":41946970},{"atb":[[3.45,1.66]],"id":39267517}],"con":true,"img":false}]}
{"op":"mcm","clk":"5348770518","pt":1646220538340,"mc":[{"id":"1.195453630","rc":[{"atb":[[2.34,0]],"id":40717352},{"atl":[[7,0]],"id":39267517},{"atl":[[4.9,0]],"id":37406513}],"con":true,"img":false}]}
{"op":"mcm","clk":"5348770529","pt":1646220538435,"mc":[{"id":"1.195453630","rc":[{"atb":[[2.28,34.06]],"id":40717352},{"atl":[[6.6,7.26]],"id":39267517},{"atl":[[5.5,22.42]],"id":37406513}],"con":true,"img":false}]}
{"op":"mcm","clk":"5348770539","pt":1646220538501,"mc":[{"id":"1.195453630","rc":[{"atl":[[7.2,28.23],[6.8,8.62]],"id":39267517}],"con":true,"img":false}]}
{"op":"mcm","clk":"5348770856","pt":1646220541415,"mc":[{"id":"1.195453630","rc":[{"atl":[[10,5.56]],"id":41946970},{"atl":[[5.9,10.2]],"id":37406513},{"atb":[[1.07,250]],"id":39860456}],"con":true,"img":false}]}
{"op":"mcm","clk":"5348770862","pt":1646220541517,"mc":[{"id":"1.195453630","rc":[{"atb":[[1.7,71.43]],"id":40717352},{"atl":[[4,16.67]],"id":40717352},{"atl":[[3.2,22.73]],"id":39931665},{"atb":[[3.3,21.74]],"id":39267517},{"atl":[[5.6,15.78]],"id":37406513}],"con":true,"img":false}]}
{"op":"mcm","clk":"5348770947","pt":1646220542442,"mc":[{"id":"1.195453630","rc":[{"atl":[[5.3,0],[5.5,0],[5.7,0]],"id":40717352},{"atl":[[6.8,0]],"id":39931665},{"atb":[[2.92,0]],"id":39267517}],"con":true,"img":false}]}
{"op":"mcm","clk":"5348771154","pt":1646220544643,"mc":[{"id":"1.195453630","rc":[{"atb":[[3.2,3.78]],"id":39267517}],"con":true,"img":false}]}
{"op":"mcm","clk":"5348771287","pt":1646220546215,"mc":[{"id":"1.195453630","rc":[{"atl":[[6.6,0]],"id":39267517}],"con":true,"img":false}]}
{"op":"mcm","clk":"5348771295","pt":1646220546322,"mc":[{"id":"1.195453630","rc":[{"atl":[[7,7.26]],"id":39267517}],"con":true,"img":false}]}
{"op":"mcm","clk":"5348771702","pt":1646220551529,"mc":[{"id":"1.195453630","rc":[{"atb":[[1.68,110.29]],"id":40717352},{"atl":[[4.2,23.44]],"id":40717352},{"atl":[[11,7.5]],"id":41946970},{"atl":[[3.3,32.61]],"id":39931665},{"atb":[[3.2,37.87]],"id":39267517},{"atl":[[6.2,14.42]],"id":37406513},{"atb":[[1.05,250]],"id":39860456}],"con":true,"img":false}]}
{"op":"mcm","clk":"5348771716","pt":1646220551632,"mc":[{"id":"1.195453630","rc":[{"atl":[[3.3,64.86]],"id":39931665}],"con":true,"img":false}]}
{"op":"mcm","clk":"5348771727","pt":1646220551732,"mc":[{"id":"1.195453630","rc":[{"atl":[[5.1,0]],"id":39931665},{"atl":[[7.2,12.1],[6.8,17.24]],"id":39267517}],"con":true,"img":false}]}
{"op":"mcm","clk":"5348771800","pt":1646220552557,"mc":[{"id":"1.195453630","rc":[{"atl":[[6.4,13.44]],"id":39931665},{"atb":[[2.96,50.92]],"id":39267517}],"con":true,"img":false}]}
{"op":"mcm","clk":"5348772091","pt":1646220555234,"mc":[{"id":"1.195453630","rc":[{"atb":[[2.42,0]],"id":40717352}],"con":true,"img":false}]}
{"op":"mcm","clk":"5348772144","pt":1646220555853,"mc":[{"id":"1.195453630","rc":[{"atb":[[2.44,0]],"id":40717352}],"con":true,"img":false}]}
{"op":"mcm","clk":"5348772167","pt":1646220556063,"mc":[{"id":"1.195453630","rc":[{"atb":[[2.3,1.66]],"id":40717352}],"con":true,"img":false}]}
{"op":"mcm","clk":"5348772682","pt":1646220561566,"mc":[{"id":"1.195453630","rc":[{"atb":[[1.66,189.39]],"id":40717352},{"atl":[[4.4,36.76]],"id":40717352},{"atl":[[12,16.81]],"id":41946970},{"atl":[[3.4,52.08]],"id":39931665},{"atb":[[3.1,59.52]],"id":39267517},{"atl":[[6.6,22.32]],"id":37406513},{"atb":[[1.03,250]],"id":39860456}],"con":true,"img":false}]}
{"op":"mcm","clk":"5348772719","pt":1646220562073,"mc":[{"id":"1.195453630","rc":[{"atb":[[1.43,0]],"id":39860456}],"con":true,"img":false}]}
{"op":"mcm","clk":"5348772727","pt":1646220562180,"mc":[{"id":"1.195453630","rc":[{"atb":[[1.45,80.3]],"id":39860456}],"con":true,"img":false}]}
{"op":"mcm","clk":"5348772768","pt":1646220562667,"mc":[{"id":"1.195453630","rc":[{"atb":[[1.46,18.1]],"id":39860456}],"con":true,"img":false}]}
{"op":"mcm","clk":"5348772839","pt":1646220563454,"mc":[{"id":"1.195453630","rc":[{"atl":[[5.5,12.73]],"id":37406513}],"con":true,"img":false}]}
{"op":"mcm","clk":"5348772848","pt":1646220563551,"mc":[{"id":"1.195453630","rc":[{"atl":[[5.1,9.69]],"id":37406513}],"con":true,"img":false}]}
{"op":"mcm","clk":"5348772938","pt":1646220564661,"mc":[{"id":"1.195453630","rc":[{"atl":[[4.1,14.06]],"id":40717352},{"atl":[[3.25,19.38]],"id":39931665}],"con":true,"img":false}]}
{"op":"mcm","clk":"5348772945","pt":1646220564752,"mc":[{"id":"1.195453630","rc":[{"atl":[[5.4,0]],"id":40717352},{"atl":[[5.6,0]],"id":39931665}],"con":true,"img":false}]}
{"op":"mcm","clk":"5348772954","pt":1646220564859,"mc":[{"id":"1.195453630","rc":[{"atl":[[3.2,45.46],[3.3,32.61]],"id":39931665}],"con":true,"img":false}]}
{"op":"mcm","clk":"5348773293","pt":1646220568579,"mc":[{"id":"1.195453630","rc":[{"spn":3.1,"spf":"NaN","id":40717352},{"spn":6.52,"spf":"NaN","id":41946970},{"atl":[[6,0]],"id":39931665},{"spn":2.61,"spf":"NaN","id":39931665},{"atb":[[3,0]],"id":39267517},{"spn":4.92,"spf":"NaN","id":39267517}],"con":true,"img":false}]}
{"op":"mcm","clk":"5348773448","pt":1646220570470,"mc":[{"id":"1.195453630","rc":[{"atb":[[3.2,34.09]],"id":39267517}],"con":true,"img":false}]}
{"op":"mcm","clk":"5348773461","pt":1646220570571,"mc":[{"id":"1.195453630","rc":[{"atb":[[2.32,6.31]],"id":40717352}],"con":true,"img":false}]}
{"op":"mcm","clk":"5348773862","pt":1646220575179,"mc":[{"id":"1.195453630","rc":[{"atl":[[7,0]],"id":39267517}],"con":true,"img":false}]}
{"op":"mcm","clk":"5348773871","pt":1646220575282,"mc":[{"id":"1.195453630","rc":[{"atl":[[6.6,7.26]],"id":39267517}],"con":true,"img":false}]}
{"op":"mcm","clk":"5348773881","pt":1646220575374,"mc":[{"id":"1.195453630","rc":[{"atl":[[7.2,28.23],[6.8,8.62]],"id":39267517}],"con":true,"img":false}]}
{"op":"mcm","clk":"5348774050","pt":1646220576975,"mc":[{"id":"1.195453630","rc":[{"atb":[[2.3,0]],"id":40717352}],"con":true,"img":false}]}
{"op":"mcm","clk":"5348774070","pt":1646220577183,"mc":[{"id":"1.195453630","rc":[{"atb":[[2.34,1.66]],"id":40717352}],"con":true,"img":false}]}
{"op":"mcm","clk":"5348774611","pt":1646220583184,"mc":[{"id":"1.195453630","rc":[{"atl":[[7,0]],"id":40717352},{"atl":[[6.6,0]],"id":39267517}],"con":true,"img":false}]}
{"op":"mcm","clk":"5348774621","pt":1646220583291,"mc":[{"id":"1.195453630","rc":[{"atl":[[6.2,10.9]],"id":40717352},{"atl":[[7,7.26]],"id":39267517}],"con":true,"img":false}]}
{"op":"mcm","clk":"5348774751","pt":1646220584479,"mc":[{"id":"1.195453630","rc":[{"atl":[[12,11.36],[9.8,7.08]],"id":41946970},{"atl":[[5.1,13.39],[6.2,0]],"id":39931665},{"atb":[[2.42,0]],"id":39267517}],"con":true,"img":false}]}
{"op":"mcm","clk":"5348774760","pt":1646220584582,"mc":[{"id":"1.195453630","rc":[{"atb":[[2.56,39.24]],"id":39267517}],"con":true,"img":false}]}
{"op":"mcm","clk":"5348774773","pt":1646220584686,"mc":[{"id":"1.195453630","rc":[{"atb":[[2.5,0]],"id":41946970}],"con":true,"img":false}]}
{"op":"mcm","clk":"5348774777","pt":1646220584786,"mc":[{"id":"1.195453630","rc":[{"atb":[[2.74,41.96]],"id":41946970}],"con":true,"img":false}]}
{"op":"mcm","clk":"5348774871","pt":1646220585780,"mc":[{"id":"1.195453630","rc":[{"atl":[[9.8,0]],"id":41946970}],"con":true,"img":false}]}
{"op":"mcm","clk":"5348774876","pt":1646220585883,"mc":[{"id":"1.195453630","rc":[{"atl":[[10.5,11.67]],"id":41946970}],"con":true,"img":false}]}
{"op":"mcm","clk":"5348775088","pt":1646220588175,"mc":[{"id":"1.195453630","rc":[{"atl":[[7.2,12.1],[6.8,17.24]],"id":39267517}],"con":true,"img":false}]}
{"op":"mcm","clk":"5348775154","pt":1646220588793,"mc":[{"id":"1.195453630","rc":[{"atb":[[1.46,0]],"id":39860456}],"con":true,"img":false}]}
{"op":"mcm","clk":"5348775162","pt":1646220588903,"mc":[{"id":"1.195453630","rc":[{"atb":[[3.25,3.69]],"id":39267517}],"con":true,"img":false}]}
{"op":"mcm","clk":"5348776251","pt":1646220600101,"mc":[{"id":"1.195453630","rc":[{"atb":[[1.48,17.34]],"id":39860456}],"con":true,"img":false}]}
{"op":"mcm","clk":"5348776479","pt":1646220601903,"mc":[{"id":"1.195453630","rc":[{"atb":[[2.34,7.26]],"id":40717352},{"atb":[[1.48,32.98]],"id":39860456}],"con":true,"img":false}]}
{"op":"mcm","clk":"5348776491","pt":1646220602003,"mc":[{"id":"1.195453630","rc":[{"atb":[[3.4,11.46]],"id":39267517}],"con":true,"img":false}]}
{"op":"mcm","clk":"5348777512","pt":1646220610813,"mc":[{"id":"1.195453630","rc":[{"atl":[[7,0]],"id":39267517}],"con":true,"img":false}]}
{"op":"mcm","clk":"5348777520","pt":1646220610916,"mc":[{"id":"1.195453630","rc":[{"atl":[[6.6,7.26]],"id":39267517}],"con":true,"img":false}]}
{"op":"mcm","clk":"5348777531","pt":1646220611019,"mc":[{"id":"1.195453630","rc":[{"atl":[[7.2,28.23],[6.8,8.62]],"id":39267517}],"con":true,"img":false}]}
{"op":"mcm","clk":"5348778328","pt":1646220618823,"mc":[{"id":"1.195453630","rc":[{"atl":[[6.6,0]],"id":39267517}],"con":true,"img":false}]}
{"op":"mcm","clk":"5348778337","pt":1646220618937,"mc":[{"id":"1.195453630","rc":[{"atl":[[7,7.26]],"id":39267517}],"con":true,"img":false}]}
{"op":"mcm","clk":"5348778844","pt":1646220623406,"mc":[{"id":"1.195453630","rc":[{"atl":[[7.2,12.1],[6.8,17.24]],"id":39267517}],"con":true,"img":false}]}
{"op":"mcm","clk":"5348779659","pt":1646220630631,"mc":[{"id":"1.195453630","rc":[{"spn":3.12,"spf":"NaN","id":40717352},{"atb":[[3,31.61]],"id":41946970},{"spn":1.48,"spf":1.0,"id":39860456}],"con":true,"img":false}]}
{"op":"mcm","clk":"5348779669","pt":1646220630719,"mc":[{"id":"1.195453630","rc":[{"atb":[[2.74,0]],"id":41946970}],"con":true,"img":false}]}
{"op":"mcm","clk":"5348780758","pt":1646220640237,"mc":[{"id":"1.195453630","rc":[{"atl":[[3.35,0],[3.3,8.7]],"id":39860456}],"con":true,"img":false}]}
{"op":"mcm","clk":"5348781323","pt":1646220646438,"mc":[{"id":"1.195453630","rc":[{"atl":[[7,0]],"id":39267517}],"con":true,"img":false}]}
{"op":"mcm","clk":"5348781328","pt":1646220646542,"mc":[{"id":"1.195453630","rc":[{"atl":[[6.6,7.26]],"id":39267517}],"con":true,"img":false}]}
{"op":"mcm","clk":"5348781336","pt":1646220646648,"mc":[{"id":"1.195453630","rc":[{"atl":[[7.2,28.23],[6.8,8.62]],"id":39267517}],"con":true,"img":false}]}
{"op":"mcm","clk":"5348781655","pt":1646220650244,"mc":[{"id":"1.195453630","rc":[{"atl":[[3.4,45.86]],"id":39860456}],"con":true,"img":false}]}
{"op":"mcm","clk":"5348782002","pt":1646220654365,"mc":[{"id":"1.195453630","rc":[{"atl":[[6.6,0]],"id":39267517}],"con":true,"img":false}]}
{"op":"mcm","clk":"5348782009","pt":1646220654433,"mc":[{"id":"1.195453630","rc":[{"atl":[[7,7.26]],"id":39267517}],"con":true,"img":false}]}
{"op":"mcm","clk":"5348782387","pt":1646220658769,"mc":[{"id":"1.195453630","rc":[{"atl":[[7.2,12.1],[6.8,17.24]],"id":39267517}],"con":true,"img":false}]}
{"op":"mcm","clk":"5348782511","pt":1646220660031,"mc":[{"id":"1.195453630","rc":[{"atl":[[3.7,0]],"id":39860456}],"con":true,"img":false}]}
{"op":"mcm","clk":"5348782535","pt":1646220660244,"mc":[{"id":"1.195453630","rc":[{"atl":[[3.5,50]],"id":39860456}],"con":true,"img":false}]}
{"op":"mcm","clk":"5348782542","pt":1646220660345,"mc":[{"id":"1.195453630","rc":[{"atl":[[3.5,30]],"id":39860456}],"con":true,"img":false}]}
{"op":"mcm","clk":"5348782671","pt":1646220661760,"mc":[{"id":"1.195453630","rc":[{"atb":[[2.38,2.16]],"id":40717352},{"atb":[[2.16,2.16]],"id":39931665},{"atb":[[2.04,2.16]],"id":37406513}],"con":true,"img":false}]}
{"op":"mcm","clk":"5348783518","pt":1646220670248,"mc":[{"id":"1.195453630","rc":[{"atl":[[3.6,0]],"id":39860456}],"con":true,"img":false}]}
{"op":"mcm","clk":"5348783534","pt":1646220670357,"mc":[{"id":"1.195453630","rc":[{"atl":[[3.6,48.08]],"id":39860456}],"con":true,"img":false}]}
{"op":"mcm","clk":"5348784339","pt":1646220677070,"mc":[{"id":"1.195453630","rc":[{"atb":[[2.34,5.6]],"id":40717352},{"atb":[[2.12,0]],"id":39931665}],"con":true,"img":false}]}
{"op":"mcm","clk":"5348784374","pt":1646220677276,"mc":[{"id":"1.195453630","rc":[{"atb":[[2.4,1.66]],"id":40717352},{"atb":[[2.18,1.66]],"id":39931665},{"atb":[[2.06,1.66]],"id":37406513}],"con":true,"img":false}]}
{"op":"mcm","clk":"5348785080","pt":1646220682054,"mc":[{"id":"1.195453630","rc":[{"atl":[[7,0]],"id":39267517}],"con":true,"img":false}]}
{"op":"mcm","clk":"5348785098","pt":1646220682160,"mc":[{"id":"1.195453630","rc":[{"atl":[[6.6,7.26]],"id":39267517}],"con":true,"img":false}]}
{"op":"mcm","clk":"5348785115","pt":1646220682266,"mc":[{"id":"1.195453630","rc":[{"atl":[[7.2,28.23],[6.8,8.62]],"id":39267517}],"con":true,"img":false}]}
{"op":"mcm","clk":"5348785259","pt":1646220683375,"mc":[{"id":"1.195453630","rc":[{"atb":[[2.4,9.32]],"id":40717352},{"atb":[[3.65,17.19]],"id":41946970},{"atb":[[2.12,10.52]],"id":39931665},{"atb":[[3.45,20.93]],"id":39267517},{"atb":[[1.96,14.35]],"id":37406513},{"atb":[[1.38,124.18]],"id":39860456}],"con":true,"img":false}]}
{"op":"mcm","clk":"5348785412","pt":1646220684476,"mc":[{"id":"1.195453630","rc":[{"atb":[[1.51,2.16]],"id":39860456}],"con":true,"img":false}]}
{"op":"mcm","clk":"5348785598","pt":1646220685651,"mc":[{"id":"1.195453630","rc":[{"atb":[[3.4,8.33]],"id":39267517}],"con":true,"img":false}]}
{"op":"mcm","clk":"5348786218","pt":1646220690016,"mc":[{"id":"1.195453630","rc":[{"atl":[[6.6,0]],"id":39267517}],"con":true,"img":false}]}
{"op":"mcm","clk":"5348786229","pt":1646220690067,"mc":[{"id":"1.195453630","rc":[{"atl":[[7,7.26]],"id":39267517}],"con":true,"img":false}]}
{"op":"mcm","clk":"5348786489","pt":1646220691776,"mc":[{"id":"1.195453630","rc":[{"spn":3.15,"spf":"NaN","id":40717352},{"spn":2.64,"spf":"NaN","id":39931665},{"atb":[[3.55,2.94]],"id":39267517},{"spn":4.97,"spf":"NaN","id":39267517},{"spn":3.33,"spf":"NaN","id":37406513},{"spn":1.49,"spf":1.0,"id":39860456}],"con":true,"img":false}]}
{"op":"mcm","clk":"5348786796","pt":1646220693781,"mc":[{"id":"1.195453630","rc":[{"atb":[[3.45,1.66]],"id":39267517}],"con":true,"img":false}]}
{"op":"mcm","clk":"5348786822","pt":1646220693996,"mc":[{"id":"1.195453630","rc":[{"atl":[[6.8,17.24]],"id":39267517}],"con":true,"img":false}]}
{"op":"mcm","clk":"5348786835","pt":1646220694099,"mc":[{"id":"1.195453630","rc":[{"atl":[[7.2,12.1]],"id":39267517}],"con":true,"img":false}]}
{"op":"mcm","clk":"5348787050","pt":1646220695792,"mc":[{"id":"1.195453630","rc":[{"atb":[[3.55,0]],"id":39267517}],"con":true,"img":false}]}
{"op":"mcm","clk":"5348787482","pt":1646220698793,"mc":[{"id":"1.195453630","rc":[{"atb":[[3.45,20.92]],"id":39267517}],"con":true,"img":false}]}
{"op":"mcm","clk":"5348788528","pt":1646220706404,"mc":[{"id":"1.195453630","rc":[{"atb":[[2.4,0]],"id":40717352},{"trd":[[2.4,18.64]],"ltp":2.4,"tv":18.64,"id":40717352}],"con":true,"img":false}]}
{"op":"mcm","clk":"5348788723","pt":1646220707820,"mc":[{"id":"1.195453630","rc":[{"atb":[[3.55,2.94]],"id":39267517}],"con":true,"img":false}]}
{"op":"mcm","clk":"5348789431","pt":1646220712989,"mc":[{"id":"1.195453630","rc":[{"atb":[[3.45,1.66]],"id":39267517}],"con":true,"img":false}]}
{"op":"mcm","clk":"5348789820","pt":1646220715997,"mc":[{"id":"1.195453630","rc":[{"atb":[[3.55,0]],"id":39267517}],"con":true,"img":false}]}
{"op":"mcm","clk":"5348789926","pt":1646220717006,"mc":[{"id":"1.195453630","rc":[{"atb":[[2.4,1.66]],"id":40717352}],"con":true,"img":false}]}
{"op":"mcm","clk":"5348790003","pt":1646220717691,"mc":[{"id":"1.195453630","rc":[{"atl":[[7,0]],"id":39267517}],"con":true,"img":false}]}
{"op":"mcm","clk":"5348790015","pt":1646220717795,"mc":[{"id":"1.195453630","rc":[{"atl":[[6.6,7.26]],"id":39267517}],"con":true,"img":false}]}
{"op":"mcm","clk":"5348790028","pt":1646220717900,"mc":[{"id":"1.195453630","rc":[{"atl":[[7.2,28.23],[6.8,8.62]],"id":39267517}],"con":true,"img":false}]}
{"op":"mcm","clk":"5348790195","pt":1646220719312,"mc":[{"id":"1.195453630","rc":[{"atb":[[3.45,20.92]],"id":39267517}],"con":true,"img":false}]}
{"op":"mcm","clk":"5348790685","pt":1646220723004,"mc":[{"id":"1.195453630","rc":[{"atb":[[1.37,0]],"id":39860456}],"con":true,"img":false}]}
{"op":"mcm","clk":"5348790693","pt":1646220723102,"mc":[{"id":"1.195453630","rc":[{"atb":[[1.39,143.06]],"id":39860456}],"con":true,"img":false}]}
{"op":"mcm","clk":"5348791020","pt":1646220725622,"mc":[{"id":"1.195453630","rc":[{"atl":[[6.6,0]],"id":39267517}],"con":true,"img":false}]}
{"op":"mcm","clk":"5348791032","pt":1646220725729,"mc":[{"id":"1.195453630","rc":[{"atl":[[7,7.26]],"id":39267517}],"con":true,"img":false}]}
{"op":"mcm","clk":"5348791319","pt":1646220727813,"mc":[{"id":"1.195453630","rc":[{"atb":[[3.55,2.94]],"id":39267517}],"con":true,"img":false}]}
{"op":"mcm","clk":"5348791364","pt":1646220728233,"mc":[{"id":"1.195453630","rc":[{"atl":[[4.1,0]],"id":40717352}],"con":true,"img":false}]}
{"op":"mcm","clk":"5348791375","pt":1646220728294,"mc":[{"id":"1.195453630","rc":[{"atl":[[3.95,14.06]],"id":40717352}],"con":true,"img":false}]}
{"op":"mcm","clk":"5348791437","pt":1646220728814,"mc":[{"id":"1.195453630","rc":[{"atb":[[1.38,0]],"id":39860456}],"con":true,"img":false}]}
{"op":"mcm","clk":"5348791498","pt":1646220729344,"mc":[{"id":"1.195453630","rc":[{"atl":[[7.2,12.1],[6.8,17.24]],"id":39267517}],"con":true,"img":false}]}
{"op":"mcm","clk":"5348791882","pt":1646220731931,"mc":[{"id":"1.195453630","rc":[{"atb":[[3.45,1.66]],"id":39267517}],"con":true,"img":false}]}
{"op":"mcm","clk":"5348792121","pt":1646220733818,"mc":[{"id":"1.195453630","rc":[{"atb":[[3.55,0]],"id":39267517}],"con":true,"img":false}]}
{"op":"mcm","clk":"5348792348","pt":1646220735626,"mc":[{"id":"1.195453630","rc":[{"atb":[[1.4,117.96]],"id":39860456}],"con":true,"img":false}]}
{"op":"mcm","clk":"5348792720","pt":1646220738612,"mc":[{"id":"1.195453630","rc":[{"atb":[[3.45,20.92]],"id":39267517}],"con":true,"img":false}]}
{"op":"mcm","clk":"5348793711","pt":1646220746836,"mc":[{"id":"1.195453630","rc":[{"atb":[[3.55,2.94]],"id":39267517}],"con":true,"img":false}]}
{"op":"mcm","clk":"5348794068","pt":1646220750022,"mc":[{"id":"1.195453630","rc":[{"atb":[[3.45,1.66]],"id":39267517}],"con":true,"img":false}]}
{"op":"mcm","clk":"5348794319","pt":1646220751925,"mc":[{"id":"1.195453630","rc":[{"atb":[[3.55,0]],"id":39267517},{"atl":[[7,0]],"id":39267517},{"spn":4.92,"spf":"NaN","id":39267517}],"con":true,"img":false}]}
{"op":"mcm","clk":"5348794347","pt":1646220752164,"mc":[{"id":"1.195453630","rc":[{"atl":[[7.2,28.23],[6.8,8.62],[6.6,7.26]],"id":39267517}],"con":true,"img":false}]}
{"op":"mcm","clk":"5348794830","pt":1646220755925,"mc":[{"id":"1.195453630","rc":[{"atb":[[3.45,20.92]],"id":39267517}],"con":true,"img":false}]}
{"op":"mcm","clk":"5348795320","pt":1646220759959,"mc":[{"id":"1.195453630","rc":[{"atl":[[6.6,0]],"id":39267517}],"con":true,"img":false}]}
{"op":"mcm","clk":"5348795332","pt":1646220760061,"mc":[{"id":"1.195453630","rc":[{"atl":[[7,7.26]],"id":39267517}],"con":true,"img":false}]}
{"op":"mcm","clk":"5348795687","pt":1646220763165,"mc":[{"id":"1.195453630","rc":[{"atl":[[6.8,17.24]],"id":39267517}],"con":true,"img":false}]}
{"op":"mcm","clk":"5348795699","pt":1646220763267,"mc":[{"id":"1.195453630","rc":[{"atl":[[7.2,12.1]],"id":39267517}],"con":true,"img":false}]}
{"op":"mcm","clk":"5348796153","pt":1646220766955,"mc":[{"id":"1.195453630","rc":[{"atb":[[3.55,2.94]],"id":39267517}],"con":true,"img":false}]}
{"op":"mcm","clk":"5348796645","pt":1646220771180,"mc":[{"id":"1.195453630","rc":[{"atb":[[3.45,1.66]],"id":39267517}],"con":true,"img":false}]}
{"op":"mcm","clk":"5348796844","pt":1646220772972,"mc":[{"id":"1.195453630","rc":[{"atb":[[3.55,0]],"id":39267517}],"con":true,"img":false}]}
{"op":"mcm","clk":"5348796999","pt":1646220774386,"mc":[{"id":"1.195453630","rc":[{"atb":[[1.39,0]],"id":39860456}],"con":true,"img":false}]}
{"op":"mcm","clk":"5348797013","pt":1646220774459,"mc":[{"id":"1.195453630","rc":[{"atb":[[1.41,143.06]],"id":39860456}],"con":true,"img":false}]}
{"op":"mcm","clk":"5348797356","pt":1646220777382,"mc":[{"id":"1.195453630","rc":[{"atb":[[3.45,20.92]],"id":39267517}],"con":true,"img":false}]}
{"op":"mcm","clk":"5348797684","pt":1646220780176,"mc":[{"id":"1.195453630","rc":[{"atb":[[1.7,0],[1.68,0],[1.72,0],[1.66,30.3]],"id":40717352},{"atl":[[3.2,22.73],[3.1,0],[3.25,28.27]],"id":39931665},{"atb":[[3.4,0],[3.3,8.7]],"id":39267517}],"con":true,"img":false}]}
{"op":"mcm","clk":"5348797737","pt":1646220780588,"mc":[{"id":"1.195453630","rc":[{"atb":[[1.4,0]],"id":39860456}],"con":true,"img":false}]}
{"op":"mcm","clk":"5348798328","pt":1646220785095,"mc":[{"id":"1.195453630","rc":[{"atb":[[3.55,2.94]],"id":39267517}],"con":true,"img":false}]}
{"op":"mcm","clk":"5348798497","pt":1646220786368,"mc":[{"id":"1.195453630","rc":[{"atl":[[7,0]],"id":39267517}],"con":true,"img":false}]}
{"op":"mcm","clk":"5348798513","pt":1646220786468,"mc":[{"id":"1.195453630","rc":[{"atl":[[6.6,7.26]],"id":39267517}],"con":true,"img":false}]}
{"op":"mcm","clk":"5348798525","pt":1646220786576,"mc":[{"id":"1.195453630","rc":[{"atl":[[7.2,28.23],[6.8,8.62]],"id":39267517}],"con":true,"img":false}]}
{"op":"mcm","clk":"5348798548","pt":1646220786781,"mc":[{"id":"1.195453630","rc":[{"atl":[[7.2,12.1],[6.4,10.97]],"id":39267517}],"con":true,"img":false}]}
{"op":"mcm","clk":"5348798614","pt":1646220787397,"mc":[{"id":"1.195453630","rc":[{"atb":[[1.42,112.34]],"id":39860456}],"con":true,"img":false}]}
{"op":"mcm","clk":"5348798951","pt":1646220790186,"mc":[{"id":"1.195453630","rc":[{"atb":[[1.64,78.13]],"id":40717352},{"atl":[[3.35,21.28]],"id":39931665},{"atb":[[3.2,22.73]],"id":39267517}],"con":true,"img":false}]}
{"op":"mcm","clk":"5348798998","pt":1646220790493,"mc":[{"id":"1.195453630","rc":[{"atb":[[3.45,1.66]],"id":39267517}],"con":true,"img":false}]}
{"op":"mcm","clk":"5348799076","pt":1646220791071,"mc":[{"id":"1.195453630","rc":[{"atb":[[3.55,0]],"id":39267517}],"con":true,"img":false}]}
{"op":"mcm","clk":"5348799444","pt":1646220794306,"mc":[{"id":"1.195453630","rc":[{"atl":[[6.6,0]],"id":39267517}],"con":true,"img":false}]}
{"op":"mcm","clk":"5348799462","pt":1646220794406,"mc":[{"id":"1.195453630","rc":[{"atl":[[7,7.26]],"id":39267517}],"con":true,"img":false}]}
{"op":"mcm","clk":"5348799474","pt":1646220794512,"mc":[{"id":"1.195453630","rc":[{"atl":[[7.2,28.23],[6.4,3.7]],"id":39267517}],"con":true,"img":false}]}
{"op":"mcm","clk":"5348799768","pt":1646220796990,"mc":[{"id":"1.195453630","rc":[{"atb":[[3.25,7.03]],"id":39267517}],"con":true,"img":false}]}
{"op":"mcm","clk":"5348799783","pt":1646220797109,"mc":[{"id":"1.195453630","rc":[{"atb":[[3.45,0]],"id":39267517}],"con":true,"img":false}]}
{"op":"mcm","clk":"5348799813","pt":1646220797299,"mc":[{"id":"1.195453630","rc":[{"atb":[[3.35,21.74]],"id":39267517}],"con":true,"img":false}]}
{"op":"mcm","clk":"5348800095","pt":1646220800024,"mc":[{"id":"1.195453630","rc":[{"atb":[[3.25,3.69]],"id":39267517}],"con":true,"img":false}]}
{"op":"mcm","clk":"5348800126","pt":1646220800236,"mc":[{"id":"1.195453630","rc":[{"atb":[[1.62,241.97]],"id":40717352},{"atl":[[3.45,30.61]],"id":39931665},{"atb":[[3.1,35.71]],"id":39267517}],"con":true,"img":false}]}
{"op":"mcm","clk":"5348800160","pt":1646220800506,"mc":[{"id":"1.195453630","rc":[{"atl":[[3.4,0],[3.3,0]],"id":39931665}],"con":true,"img":false}]}
{"op":"mcm","clk":"5348800626","pt":1646220805116,"mc":[{"id":"1.195453630","rc":[{"atl":[[7.2,12.1],[6.8,17.24]],"id":39267517}],"con":true,"img":false}]}
{"op":"mcm","clk":"5348800740","pt":1646220806123,"mc":[{"id":"1.195453630","rc":[{"atb":[[3.45,3.06]],"id":39267517}],"con":true,"img":false}]}
{"op":"mcm","clk":"5348800913","pt":1646220807395,"mc":[{"id":"1.195453630","rc":[{"atl":[[3.25,8.89]],"id":39931665}],"con":true,"img":false}]}
{"op":"mcm","clk":"5348800929","pt":1646220807530,"mc":[{"id":"1.195453630","rc":[{"atl":[[3.3,19.38]],"id":39931665}],"con":true,"img":false}]}
{"op":"mcm","clk":"5348800942","pt":1646220807627,"mc":[{"id":"1.195453630","rc":[{"atl":[[3.2,0],[3.35,52.9]],"id":39931665}],"con":true,"img":false}]}
{"op":"mcm","clk":"5348801206","pt":1646220809732,"mc":[{"id":"1.195453630","rc":[{"atb":[[3.35,1.66]],"id":39267517}],"con":true,"img":false}]}
{"op":"mcm","clk":"5348801264","pt":1646220810204,"mc":[{"id":"1.195453630","rc":[{"atb":[[1.6,208.33]],"id":40717352},{"atl":[[3.55,49.02]],"id":39931665},{"atb":[[3,62.5]],"id":39267517}],"con":true,"img":false}]}
{"op":"mcm","clk":"5348801478","pt":1646220812119,"mc":[{"id":"1.195453630","rc":[{"spn":2.71,"spf":"NaN","id":39931665},{"atb":[[3.45,0]],"id":39267517},{"spn":4.87,"spf":"NaN","id":39267517}],"con":true,"img":false}]}
{"op":"mcm","clk":"5348801861","pt":1646220815317,"mc":[{"id":"1.195453630","rc":[{"atb":[[3.25,0]],"id":39267517}],"con":true,"img":false}]}
{"op":"mcm","clk":"5348801933","pt":1646220815845,"mc":[{"id":"1.195453630","rc":[{"atb":[[3.35,21.74]],"id":39267517}],"con":true,"img":false}]}
{"op":"mcm","clk":"5348802249","pt":1646220818107,"mc":[{"id":"1.195453630","rc":[{"atl":[[3.35,21.28],[3.25,28.27]],"id":39931665}],"con":true,"img":false}]}
{"op":"mcm","clk":"5348802990","pt":1646220823994,"mc":[{"id":"1.195453630","rc":[{"atb":[[3.45,3.06]],"id":39267517}],"con":true,"img":false}]}
{"op":"mcm","clk":"5348803222","pt":1646220825823,"mc":[{"id":"1.195453630","rc":[{"atb":[[1.41,0]],"id":39860456}],"con":true,"img":false}]}
{"op":"mcm","clk":"5348803234","pt":1646220825928,"mc":[{"id":"1.195453630","rc":[{"atb":[[1.43,143.06]],"id":39860456}],"con":true,"img":false}]}
{"op":"mcm","clk":"5348803511","pt":1646220828172,"mc":[{"id":"1.195453630","rc":[{"atb":[[3.35,1.66]],"id":39267517}],"con":true,"img":false}]}
{"op":"mcm","clk":"5348803528","pt":1646220828331,"mc":[{"id":"1.195453630","rc":[{"atb":[[3.2,26.51]],"id":39267517}],"con":true,"img":false}]}
{"op":"mcm","clk":"5348803542","pt":1646220828539,"mc":[{"id":"1.195453630","rc":[{"atl":[[7,0]],"id":39267517}],"con":true,"img":false}]}
{"op":"mcm","clk":"5348803552","pt":1646220828645,"mc":[{"id":"1.195453630","rc":[{"atl":[[6.6,7.26]],"id":39267517}],"con":true,"img":false}]}
{"op":"mcm","clk":"5348803564","pt":1646220828749,"mc":[{"id":"1.195453630","rc":[{"atl":[[7.2,28.23],[6.8,8.62]],"id":39267517}],"con":true,"img":false}]}
{"op":"mcm","clk":"5348803639","pt":1646220829323,"mc":[{"id":"1.195453630","rc":[{"atb":[[1.72,27.78],[1.66,0]],"id":40717352},{"atl":[[3.1,9.52],[3.25,19.38]],"id":39931665},{"atb":[[3.3,0],[3.4,8.33]],"id":39267517}],"con":true,"img":false}]}
{"op":"mcm","clk":"5348803718","pt":1646220830000,"mc":[{"id":"1.195453630","rc":[{"atb":[[2.98,0]],"id":39267517}],"con":true,"img":false}]}
{"op":"mcm","clk":"5348803737","pt":1646220830160,"mc":[{"id":"1.195453630","rc":[{"atb":[[3.45,0],[3.05,22.01]],"id":39267517}],"con":true,"img":false}]}
{"op":"mcm","clk":"5348803806","pt":1646220830846,"mc":[{"id":"1.195453630","rc":[{"atb":[[1.42,0]],"id":39860456}],"con":true,"img":false}]}
{"op":"mcm","clk":"5348803844","pt":1646220831214,"mc":[{"id":"1.195453630","rc":[{"atb":[[1.43,0]],"id":39860456}],"con":true,"img":false}]}
{"op":"mcm","clk":"5348803853","pt":1646220831317,"mc":[{"id":"1.195453630","rc":[{"atb":[[1.39,143.06]],"id":39860456}],"con":true,"img":false}]}
{"op":"mcm","clk":"5348803860","pt":1646220831424,"mc":[{"id":"1.195453630","rc":[{"atb":[[1.08,250]],"id":39860456}],"con":true,"img":false}]}
{"op":"mcm","clk":"5348803873","pt":1646220831537,"mc":[{"id":"1.195453630","rc":[{"atb":[[1.72,0],[1.66,30.3]],"id":40717352},{"atb":[[1.96,0],[1.94,0],[1.92,21.74]],"id":39931665},{"atl":[[6.4,0],[6.8,3.45]],"id":39267517},{"atb":[[1.83,24.1],[1.84,0],[1.86,0]],"id":37406513},{"atb":[[1.09,0]],"id":39860456}],"con":true,"img":false}]}
{"op":"mcm","clk":"5348804149","pt":1646220833931,"mc":[{"id":"1.195453630","rc":[{"atb":[[3.25,20.96]],"id":39267517}],"con":true,"img":false}]}
{"op":"mcm","clk":"5348804379","pt":1646220836130,"mc":[{"id":"1.195453630","rc":[{"atb":[[3.25,24.3]],"id":39267517}],"con":true,"img":false}]}
{"op":"mcm","clk":"5348804416","pt":1646220836446,"mc":[{"id":"1.195453630","rc":[{"atl":[[6.6,0]],"id":39267517}],"con":true,"img":false}]}
{"op":"mcm","clk":"5348804426","pt":1646220836552,"mc":[{"id":"1.195453630","rc":[{"atl":[[7,7.26]],"id":39267517}],"con":true,"img":false}]}
{"op":"mcm","clk":"5348804444","pt":1646220836609,"mc":[{"id":"1.195453630","rc":[{"atl":[[7.2,12.1],[7.6,34.09]],"id":39267517}],"con":true,"img":false}]}
{"op":"mcm","clk":"5348804466","pt":1646220836832,"mc":[{"id":"1.195453630","rc":[{"atb":[[1.62,120.97],[1.71,78.13],[1.66,0],[1.75,26.67]],"id":40717352},{"atl":[[9.6,0],[9.8,2.27]],"id":41946970},{"atl":[[5.7,21.28],[5.9,4.08]],"id":37406513}],"con":true,"img":false}]}
{"op":"mcm","clk":"5348804479","pt":1646220836956,"mc":[{"id":"1.195453630","rc":[{"atb":[[1.4,117.96]],"id":39860456}],"con":true,"img":false}]}
{"op":"mcm","clk":"5348804488","pt":1646220837029,"mc":[{"id":"1.195453630","rc":[{"atb":[[3.35,0]],"id":39267517}],"con":true,"img":false}]}
{"op":"mcm","clk":"5348804499","pt":1646220837147,"mc":[{"id":"1.195453630","rc":[{"atb":[[3.45,1.66]],"id":39267517}],"con":true,"img":false}]}
{"op":"mcm","clk":"5348804553","pt":1646220837660,"mc":[{"id":"1.195453630","rc":[{"atb":[[1.96,20.83]],"id":39931665},{"atl":[[3.1,0],[3.35,0],[3.4,8.33]],"id":39931665},{"atb":[[3.3,8.7],[3.4,0]],"id":39267517},{"atl":[[6.4,3.7]],"id":39267517},{"atb":[[1.86,23.26]],"id":37406513},{"atb":[[1.09,222.22],[1.08,0]],"id":39860456}],"con":true,"img":false}]}
{"op":"mcm","clk":"5348804716","pt":1646220839032,"mc":[{"id":"1.195453630","rc":[{"atb":[[1.94,0],[1.87,75.21]],"id":40717352},{"atb":[[1.95,0]],"id":39931665},{"atb":[[1.85,117.43]],"id":37406513}],"con":true,"img":false}]}
{"op":"mcm","clk":"5348804729","pt":1646220839134,"mc":[{"id":"1.195453630","rc":[{"atb":[[1.94,55.19]],"id":39931665},{"atb":[[1.83,83.02]],"id":37406513}],"con":true,"img":false}]}
{"op":"mcm","clk":"5348805019","pt":1646220841347,"mc":[{"id":"1.195453630","rc":[{"atl":[[2.84,2]],"id":40717352},{"atb":[[2.6,2]],"id":39931665},{"atl":[[4.8,4]],"id":39267517},{"atl":[[3.35,8.51],[3.3,0]],"id":39860456}],"con":true,"img":false}]}
{"op":"mcm","clk":"5348805038","pt":1646220841544,"mc":[{"id":"1.195453630","rc":[{"atb":[[2.62,4]],"id":39931665},{"atl":[[4.1,2]],"id":39267517}],"con":true,"img":false}]}
{"op":"mcm","clk":"5348805056","pt":1646220841660,"mc":[{"id":"1.195453630","rc":[{"atl":[[2.86,4]],"id":40717352},{"atl":[[4.8,0]],"id":39267517}],"con":true,"img":false}]}
{"op":"mcm","clk":"5348805193","pt":1646220842754,"mc":[{"id":"1.195453630","rc":[{"atl":[[2.82,4],[2.86,0]],"id":40717352},{"atb":[[2.64,2]],"id":39931665},{"atl":[[4,3]],"id":39267517}],"con":true,"img":false}]}
{"op":"mcm","clk":"5348805318","pt":1646220843713,"mc":[{"id":"1.195453630","rc":[{"atl":[[2.86,4]],"id":40717352},{"atb":[[2.66,2]],"id":39931665},{"atl":[[3.95,3]],"id":39267517}],"con":true,"img":false}]}
{"op":"mcm","clk":"5348805366","pt":1646220844135,"mc":[{"id":"1.195453630","rc":[{"atl":[[2.8,4]],"id":40717352},{"atb":[[3.4,20.83],[3.5,67.38]],"id":41946970},{"atb":[[2.98,50.51],[3.3,0],[2.88,0],[3.4,8.33]],"id":39267517},{"atl":[[4,0],[3.95,0],[4.1,0],[3.9,3]],"id":39267517},{"atb":[[1.25,0],[1.31,210.14]],"id":37406513},{"atl":[[3.35,0],[3.3,8.7]],"id":39860456}],"con":true,"img":false}]}
{"op":"mcm","clk":"5348805381","pt":1646220844341,"mc":[{"id":"1.195453630","rc":[{"atl":[[2.84,0],[2.86,0],[2.78,3]],"id":40717352},{"atl":[[3.9,0]],"id":39267517}],"con":true,"img":false}]}
{"op":"mcm","clk":"5348805492","pt":1646220845445,"mc":[{"id":"1.195453630","rc":[{"atl":[[2.82,0],[2.76,3]],"id":40717352},{"atb":[[2.1,7.57]],"id":39931665}],"con":true,"img":false}]}
{"op":"mcm","clk":"5348805519","pt":1646220845659,"mc":[{"id":"1.195453630","rc":[{"atl":[[3.3,0]],"id":39931665}],"con":true,"img":false}]}
{"op":"mcm","clk":"5348805539","pt":1646220845758,"mc":[{"id":"1.195453630","rc":[{"atl":[[3.4,27.71]],"id":39931665}],"con":true,"img":false}]}
{"op":"mcm","clk":"5348805555","pt":1646220845863,"mc":[{"id":"1.195453630","rc":[{"atl":[[3.45,61.22],[3.25,0]],"id":39931665}],"con":true,"img":false}]}
{"op":"mcm","clk":"5348805604","pt":1646220846239,"mc":[{"id":"1.195453630","rc":[{"atb":[[2.12,0]],"id":39931665}],"con":true,"img":false}]}
{"op":"mcm","clk":"5348805684","pt":1646220846821,"mc":[{"id":"1.195453630","rc":[{"atb":[[1.73,68.49]],"id":40717352},{"atl":[[10.5,16.93]],"id":41946970},{"atl":[[6.8,10.85],[7.6,18.94]],"id":39267517}],"con":true,"img":false}]}
{"op":"mcm","clk":"5348805773","pt":1646220847654,"mc":[{"id":"1.195453630","rc":[{"atb":[[1.94,108.38]],"id":39931665},{"atl":[[3.5,20]],"id":39931665},{"atl":[[6.2,9.62]],"id":37406513}],"con":true,"img":false}]}
{"op":"mcm","clk":"5348805804","pt":1646220847881,"mc":[{"id":"1.195453630","rc":[{"atb":[[1.64,0],[1.6,0],[1.62,0]],"id":40717352},{"atl":[[2.8,0],[2.94,3],[2.76,0],[2.78,0]],"id":40717352},{"atl":[[10,0],[11,0],[12,0]],"id":41946970},{"atb":[[2.64,0],[2.6,0],[1.96,0],[1.94,55.19],[2.62,0],[2.66,0]],"id":39931665},{"atl":[[3.2,3],[3.1,9.52],[3.4,19.38]],"id":39931665},{"atb":[[3.8,4]],"id":39267517},{"atl":[[6.4,0]],"id":39267517},{"atb":[[1.86,0]],"id":37406513},{"atl":[[5.6,19.78]],"id":37406513},{"atb":[[1.09,0],[1.08,250]],"id":39860456},{"atl":[[1.98,2]],"id":39860456}],"con":true,"img":false}]}
{"op":"mcm","clk":"5348805826","pt":1646220848030,"mc":[{"id":"1.195453630","rc":[{"atl":[[2.92,2]],"id":40717352},{"atl":[[3.2,0],[2.86,4]],"id":39931665},{"atb":[[3.85,3]],"id":39267517},{"atl":[[5.5,14.73]],"id":37406513},{"atl":[[1.97,4]],"id":39860456}],"con":true,"img":false}]}
{"op":"mcm","clk":"5348805860","pt":1646220848235,"mc":[{"id":"1.195453630","rc":[{"atl":[[2.92,4.52]],"id":40717352}],"con":true,"img":false}]}
{"op":"mcm","clk":"5348805875","pt":1646220848385,"mc":[{"id":"1.195453630","rc":[{"atl":[[2.94,0],[2.9,3]],"id":40717352},{"atl":[[2.84,2]],"id":39931665},{"atb":[[3.9,4]],"id":39267517},{"atl":[[5.4,4]],"id":37406513},{"atl":[[1.96,2]],"id":39860456}],"con":true,"img":false}]}
{"op":"mcm","clk":"5348805934","pt":1646220848848,"mc":[{"id":"1.195453630","rc":[{"atl":[[2.82,4]],"id":39931665},{"atb":[[3.95,4]],"id":39267517},{"atl":[[5.3,3]],"id":37406513},{"atl":[[1.95,2]],"id":39860456}],"con":true,"img":false}]}
{"op":"mcm","clk":"5348805973","pt":1646220849267,"mc":[{"id":"1.195453630","rc":[{"atl":[[2.74,3]],"id":40717352}],"con":true,"img":false}]}
{"op":"mcm","clk":"5348805988","pt":1646220849365,"mc":[{"id":"1.195453630","rc":[{"atb":[[3.4,62.5],[3.5,27.38]],"id":41946970}],"con":true,"img":false}]}
{"op":"mcm","clk":"5348805996","pt":1646220849418,"mc":[{"id":"1.195453630","rc":[{"atl":[[2.88,3]],"id":40717352},{"atl":[[2.8,3]],"id":39931665},{"atl":[[3.35,8.51],[3.3,0]],"id":39860456}],"con":true,"img":false}]}
{"op":"mcm","clk":"5348806213","pt":1646220850961,"mc":[{"id":"1.195453630","rc":[{"atl":[[2.92,2.52],[2.88,0],[2.9,0],[2.86,2]],"id":40717352},{"atb":[[2.6,2],[1.96,20.83]],"id":39931665},{"atl":[[2.8,0],[2.82,0],[3.1,0],[2.84,0],[2.86,0],[3.4,27.71]],"id":39931665},{"atb":[[3.85,0],[3.8,0],[3.3,8.7],[3.95,0],[3.4,0],[3.9,0]],"id":39267517},{"atl":[[4.8,3],[6.4,3.7]],"id":39267517},{"atb":[[1.86,23.26]],"id":37406513},{"atl":[[5.6,15.78],[5.3,0],[5.5,12.73],[5.4,0]],"id":37406513},{"atb":[[1.09,222.22],[1.08,0]],"id":39860456},{"atl":[[1.98,0],[1.96,0],[1.95,0],[1.97,0]],"id":39860456}],"con":true,"img":false}]}
{"op":"mcm","clk":"5348806277","pt":1646220851532,"mc":[{"id":"1.195453630","rc":[{"atl":[[2.74,6],[2.86,0]],"id":40717352},{"atb":[[2.62,3]],"id":39931665},{"atl":[[4.7,2]],"id":39267517}],"con":true,"img":false}]}
{"op":"mcm","clk":"5348806304","pt":1646220851747,"mc":[{"id":"1.195453630","rc":[{"atb":[[2.64,3]],"id":39931665},{"atl":[[4.6,2]],"id":39267517}],"con":true,"img":false}]}
{"op":"mcm","clk":"5348806349","pt":1646220852116,"mc":[{"id":"1.195453630","rc":[{"atb":[[2.12,10.52]],"id":39931665},{"atb":[[3.25,3.33]],"id":39267517},{"atb":[[1.4,0]],"id":39860456}],"con":true,"img":false}]}
{"op":"mcm","clk":"5348806360","pt":1646220852221,"mc":[{"id":"1.195453630","rc":[{"atl":[[10.5,9.84],[12,5.45]],"id":41946970}],"con":true,"img":false}]}
{"op":"mcm","clk":"5348806457","pt":1646220852967,"mc":[{"id":"1.195453630","rc":[{"atl":[[2.74,3],[2.66,4]],"id":40717352},{"atb":[[2.66,3]],"id":39931665},{"atl":[[4.9,3]],"id":39267517}],"con":true,"img":false}]}
{"op":"mcm","clk":"5348806746","pt":1646220855230,"mc":[{"id":"1.195453630","rc":[{"atl":[[2.64,3]],"id":40717352},{"atl":[[4.1,2]],"id":39267517}],"con":true,"img":false}]}
{"op":"mcm","clk":"5348806752","pt":1646220855330,"mc":[{"id":"1.195453630","rc":[{"atl":[[4.8,0],[4.9,0],[4.6,0],[4.7,0]],"id":39267517}],"con":true,"img":false}]}
{"op":"mcm","clk":"5348806801","pt":1646220855748,"mc":[{"id":"1.195453630","rc":[{"atl":[[2.62,3]],"id":40717352},{"atl":[[4,4]],"id":39267517}],"con":true,"img":false}]}
{"op":"mcm","clk":"5348806824","pt":1646220855957,"mc":[{"id":"1.195453630","rc":[{"atl":[[3.45,30.61],[3.35,27.71]],"id":39931665}],"con":true,"img":false}]}
{"op":"mcm","clk":"5348806835","pt":1646220856062,"mc":[{"id":"1.195453630","rc":[{"atb":[[2.4,0]],"id":40717352},{"atb":[[2.18,0]],"id":39931665},{"atb":[[3.45,0]],"id":39267517}],"con":true,"img":false}]}
{"op":"mcm","clk":"5348806947","pt":1646220856858,"mc":[{"id":"1.195453630","rc":[{"atb":[[1.71,183.76]],"id":40717352},{"atl":[[11.5,7.14]],"id":41946970}],"con":true,"img":false}]}
{"op":"mcm","clk":"5348806995","pt":1646220857373,"mc":[{"id":"1.195453630","rc":[{"atl":[[2.92,0]],"id":40717352}],"con":true,"img":false}]}
{"op":"mcm","clk":"5348807089","pt":1646220858161,"mc":[{"id":"1.195453630","rc":[{"atl":[[2.74,0]],"id":40717352},{"atb":[[2.12,0]],"id":39931665},{"atb":[[1.4,117.96]],"id":39860456}],"con":true,"img":false}]}
{"op":"mcm","clk":"5348807104","pt":1646220858269,"mc":[{"id":"1.195453630","rc":[{"atb":[[3.25,12.22],[3.3,0]],"id":39267517},{"atl":[[3.95,3]],"id":39267517}],"con":true,"img":false}]}
{"op":"mcm","clk":"5348807113","pt":1646220858372,"mc":[{"id":"1.195453630","rc":[{"atl":[[2.6,2]],"id":40717352},{"atb":[[1.58,0],[2.6,0],[1.63,158.73],[2.68,2]],"id":39931665},{"atb":[[2.9,52.63],[2.98,0]],"id":39267517},{"atl":[[6.4,0],[6.2,3.85]],"id":39267517},{"atl":[[3.45,8.16],[3.35,0]],"id":39860456}],"con":true,"img":false}]}
{"op":"mcm","clk":"5348807132","pt":1646220858532,"mc":[{"id":"1.195453630","rc":[{"atl":[[3.9,3]],"id":39267517}],"con":true,"img":false}]}
{"op":"mcm","clk":"5348807202","pt":1646220859259,"mc":[{"id":"1.195453630","rc":[{"atb":[[1.81,24.69]],"id":40717352},{"atl":[[2.6,0],[2.64,0],[2.62,0],[2.66,0]],"id":40717352},{"atb":[[2.64,0],[2.62,0],[2.66,0],[2.68,0]],"id":39931665},{"atl":[[3.1,9.52],[3.4,19.38]],"id":39931665},{"atb":[[3.25,3.33],[3.3,8.7]],"id":39267517},{"atl":[[4,0],[3.95,0],[4.1,0],[3.9,0]],"id":39267517},{"atl":[[3.4,25.03]],"id":39860456}],"con":true,"img":false}]}
{"op":"mcm","clk":"5348807218","pt":1646220859366,"mc":[{"id":"1.195453630","rc":[{"atb":[[3.4,20.83],[3.55,39.22]],"id":41946970},{"atl":[[6.8,3.45],[6,7.27]],"id":39267517}],"con":true,"img":false}]}
{"op":"mcm","clk":"5348807237","pt":1646220859571,"mc":[{"id":"1.195453630","rc":[{"atb":[[3.4,50],[3.55,0],[3.5,19.38]],"id":41946970},{"atb":[[2.9,0]],"id":39267517}],"con":true,"img":false}]}
{"op":"mcm","clk":"5348807246","pt":1646220859677,"mc":[{"id":"1.195453630","rc":[{"atb":[[2.68,59.52]],"id":39267517},{"atl":[[6.4,3.7],[6.2,0]],"id":39267517}],"con":true,"img":false}]}
{"op":"mcm","clk":"5348807295","pt":1646220860253,"mc":[{"id":"1.195453630","rc":[{"atb":[[3.6,3.2]],"id":41946970}],"con":true,"img":false}]}
{"op":"mcm","clk":"5348807355","pt":1646220860885,"mc":[{"id":"1.195453630","rc":[{"atb":[[3.35,17.4]],"id":39267517}],"con":true,"img":false}]}
{"op":"mcm","clk":"5348807362","pt":1646220860982,"mc":[{"id":"1.195453630","rc":[{"atl":[[6.6,13.39]],"id":37406513}],"con":true,"img":false}]}
{"op":"mcm","clk":"5348807748","pt":1646220864087,"mc":[{"id":"1.195453630","rc":[{"atb":[[1.99,36.51]],"id":39931665}],"con":true,"img":false}]}
{"op":"mcm","clk":"5348807806","pt":1646220864454,"mc":[{"id":"1.195453630","rc":[{"atl":[[6,0],[6.8,14.42]],"id":39267517}],"con":true,"img":false}]}
{"op":"mcm","clk":"5348808035","pt":1646220866392,"mc":[{"id":"1.195453630","rc":[{"atb":[[3.55,2.94]],"id":41946970},{"atb":[[2.1,14.39]],"id":39931665}],"con":true,"img":false}]}
{"op":"mcm","clk":"5348808281","pt":1646220868389,"mc":[{"id":"1.195453630","rc":[{"atl":[[3.55,19.61]],"id":39860456}],"con":true,"img":false}]}
{"op":"mcm","clk":"5348808371","pt":1646220869275,"mc":[{"id":"1.195453630","rc":[{"atb":[[1.79,63.29]],"id":40717352},{"atb":[[1.94,108.38]],"id":39931665},{"atl":[[3.2,22.73]],"id":39931665}],"con":true,"img":false}]}
{"op":"mcm","clk":"5348808403","pt":1646220869489,"mc":[{"id":"1.195453630","rc":[{"atl":[[3.35,0],[3.15,22.73]],"id":39931665}],"con":true,"img":false}]}
{"op":"mcm","clk":"5348808418","pt":1646220869596,"mc":[{"id":"1.195453630","rc":[{"atb":[[3.3,54.35]],"id":41946970},{"atl":[[12.5,10.87]],"id":41946970}],"con":true,"img":false}]}
{"op":"mcm","clk":"5348808433","pt":1646220869701,"mc":[{"id":"1.195453630","rc":[{"atb":[[3.3,21.74]],"id":41946970},{"atl":[[3.35,32.25],[3.15,0]],"id":39931665},{"atl":[[6.8,19.59]],"id":39267517}],"con":true,"img":false}]}
{"op":"mcm","clk":"5348808462","pt":1646220869865,"mc":[{"id":"1.195453630","rc":[{"atl":[[3.2,54.98],[3.35,0]],"id":39931665}],"con":true,"img":false}]}
{"op":"mcm","clk":"5348808608","pt":1646220870973,"mc":[{"id":"1.195453630","rc":[{"atl":[[7,20.83]],"id":37406513}],"con":true,"img":false}]}
{"op":"mcm","clk":"5348808766","pt":1646220872066,"mc":[{"id":"1.195453630","rc":[{"atb":[[1.71,78.13]],"id":40717352},{"atl":[[3.45,0],[3.55,0]],"id":39931665}],"con":true,"img":false}]}
{"op":"mcm","clk":"5348808863","pt":1646220872970,"mc":[{"id":"1.195453630","rc":[{"spn":3.14,"spf":"NaN","id":40717352},{"atb":[[1.99,0]],"id":39931665},{"spn":2.63,"spf":"NaN","id":39931665}],"con":true,"img":false}]}
{"op":"mcm","clk":"5348808987","pt":1646220874173,"mc":[{"id":"1.195453630","rc":[{"atl":[[3.1,0],[3.15,9.3]],"id":39931665},{"atb":[[3.25,12.22],[3.3,0]],"id":39267517},{"atl":[[6.4,0],[6.2,3.85]],"id":39267517}],"con":true,"img":false}]}
{"op":"mcm","clk":"5348809085","pt":1646220874998,"mc":[{"id":"1.195453630","rc":[{"atb":[[2.4,1.66]],"id":40717352},{"atb":[[2.18,1.66]],"id":39931665},{"atb":[[3.4,1.66]],"id":39267517}],"con":true,"img":false}]}
{"op":"mcm","clk":"5348809109","pt":1646220875152,"mc":[{"id":"1.195453630","rc":[{"atl":[[3.35,42.55]],"id":39931665}],"con":true,"img":false}]}
{"op":"mcm","clk":"5348809126","pt":1646220875257,"mc":[{"id":"1.195453630","rc":[{"atl":[[3.2,22.73]],"id":39931665}],"con":true,"img":false}]}
{"op":"mcm","clk":"5348809527","pt":1646220878399,"mc":[{"id":"1.195453630","rc":[{"atl":[[3.65,28.3]],"id":39860456}],"con":true,"img":false}]}
{"op":"mcm","clk":"5348809606","pt":1646220878979,"mc":[{"id":"1.195453630","rc":[{"atb":[[2.12,10.52]],"id":39931665}],"con":true,"img":false}]}
{"op":"mcm","clk":"5348809637","pt":1646220879288,"mc":[{"id":"1.195453630","rc":[{"atb":[[1.77,97.4]],"id":40717352}],"con":true,"img":false}]}
{"op":"mcm","clk":"5348809667","pt":1646220879606,"mc":[{"id":"1.195453630","rc":[{"atb":[[3.2,79.46]],"id":41946970}],"con":true,"img":false}]}
{"op":"mcm","clk":"5348809686","pt":1646220879807,"mc":[{"id":"1.195453630","rc":[{"atb":[[2.32,47.96],[2.56,0]],"id":39267517}],"con":true,"img":false}]}
{"op":"mcm","clk":"5348809979","pt":1646220882396,"mc":[{"id":"1.195453630","rc":[{"atb":[[3.6,0]],"id":41946970}],"con":true,"img":false}]}
{"op":"mcm","clk":"5348810192","pt":1646220884176,"mc":[{"id":"1.195453630","rc":[{"atb":[[1.92,81.52]],"id":39931665},{"atl":[[3.25,22.22]],"id":39931665},{"atb":[[3.15,69.69]],"id":39267517}],"con":true,"img":false}]}
{"op":"mcm","clk":"5348810246","pt":1646220884594,"mc":[{"id":"1.195453630","rc":[{"atb":[[1.73,0]],"id":40717352},{"atl":[[3.6,0],[3.5,0]],"id":39860456}],"con":true,"img":false}]}
{"op":"mcm","clk":"5348810257","pt":1646220884700,"mc":[{"id":"1.195453630","rc":[{"atb":[[3.2,3.78],[3.1,0],[3,0]],"id":39267517}],"con":true,"img":false}]}
{"op":"mcm","clk":"5348810298","pt":1646220885018,"mc":[{"id":"1.195453630","rc":[{"atl":[[3.35,0],[3.25,54.25]],"id":39931665}],"con":true,"img":false}]}
{"op":"mcm","clk":"5348810335","pt":1646220885230,"mc":[{"id":"1.195453630","rc":[{"atl":[[3.4,0]],"id":39931665}],"con":true,"img":false}]}
{"op":"mcm","clk":"5348810358","pt":1646220885393,"mc":[{"id":"1.195453630","rc":[{"atl":[[3.3,19.38]],"id":39931665}],"con":true,"img":false}]}
{"op":"mcm","clk":"5348810449","pt":1646220886190,"mc":[{"id":"1.195453630","rc":[{"atb":[[2.32,1.89],[2.34,0],[2.4,0],[2.38,0]],"id":40717352},{"trd":[[2.32,8.84],[2.4,21.98],[2.38,4.32],[2.34,11.2]],"ltp":2.32,"tv":46.34,"id":40717352}],"con":true,"img":false}]}
{"op":"mcm","clk":"5348810482","pt":1646220886501,"mc":[{"id":"1.195453630","rc":[{"atb":[[3.05,0]],"id":39267517}],"con":true,"img":false}]}
{"op":"mcm","clk":"5348810495","pt":1646220886615,"mc":[{"id":"1.195453630","rc":[{"atb":[[2.7,22.01]],"id":39267517}],"con":true,"img":false}]}
{"op":"mcm","clk":"5348810577","pt":1646220887202,"mc":[{"id":"1.195453630","rc":[{"atl":[[3,4.36]],"id":40717352}],"con":true,"img":false}]}
{"op":"mcm","clk":"5348810591","pt":1646220887306,"mc":[{"id":"1.195453630","rc":[{"atl":[[1000,1.66]],"id":40717352},{"atb":[[3.25,8.89]],"id":39267517}],"con":true,"img":false}]}
{"op":"mcm","clk":"5348810615","pt":1646220887513,"mc":[{"id":"1.195453630","rc":[{"atl":[[1000,1.34]],"id":40717352}],"con":true,"img":false}]}
{"op":"mcm","clk":"5348810628","pt":1646220887618,"mc":[{"id":"1.195453630","rc":[{"atl":[[1000,0]],"id":40717352}],"con":true,"img":false}]}
{"op":"mcm","clk":"5348810639","pt":1646220887685,"mc":[{"id":"1.195453630","rc":[{"atl":[[3.8,1.34]],"id":40717352}],"con":true,"img":false}]}
{"op":"mcm","clk":"5348810651","pt":1646220887785,"mc":[{"id":"1.195453630","rc":[{"atl":[[7,0]],"id":39267517}],"con":true,"img":false}]}
{"op":"mcm","clk":"5348810669","pt":1646220887896,"mc":[{"id":"1.195453630","rc":[{"atl":[[6.6,7.26]],"id":39267517}],"con":true,"img":false}]}
{"op":"mcm","clk":"5348810682","pt":1646220887997,"mc":[{"id":"1.195453630","rc":[{"atl":[[7.2,28.23],[6.8,8.62]],"id":39267517}],"con":true,"img":false}]}
{"op":"mcm","clk":"5348810721","pt":1646220888413,"mc":[{"id":"1.195453630","rc":[{"atl":[[3.75,45.45]],"id":39860456}],"con":true,"img":false}]}
{"op":"mcm","clk":"5348810840","pt":1646220889318,"mc":[{"id":"1.195453630","rc":[{"atb":[[1.75,166.67]],"id":40717352}],"con":true,"img":false}]}
{"op":"mcm","clk":"5348810874","pt":1646220889580,"mc":[{"id":"1.195453630","rc":[{"atb":[[3.1,59.52]],"id":41946970}],"con":true,"img":false}]}
{"op":"mcm","clk":"5348810904","pt":1646220889783,"mc":[{"id":"1.195453630","rc":[{"atb":[[1.87,0]],"id":40717352}],"con":true,"img":false}]}
{"op":"mcm","clk":"5348810913","pt":1646220889893,"mc":[{"id":"1.195453630","rc":[{"atb":[[1.8,75.21]],"id":40717352}],"con":true,"img":false}]}
{"op":"mcm","clk":"5348811076","pt":1646220891309,"mc":[{"id":"1.195453630","rc":[{"atl":[[3.95,20.84],[3.9,0]],"id":40717352},{"atb":[[3.25,0],[3.15,55.73]],"id":39267517},{"atl":[[6.2,0],[5.9,4.08]],"id":39267517}],"con":true,"img":false}]}
{"op":"mcm","clk":"5348811093","pt":1646220891419,"mc":[{"id":"1.195453630","rc":[{"atb":[[2.18,30.9]],"id":40717352}],"con":true,"img":false}]}
{"op":"mcm","clk":"5348811259","pt":1646220892692,"mc":[{"id":"1.195453630","rc":[{"atl":[[3.3,0]],"id":39931665}],"con":true,"img":false}]}
{"op":"mcm","clk":"5348811270","pt":1646220892789,"mc":[{"id":"1.195453630","rc":[{"atl":[[3.45,19.38]],"id":39931665}],"con":true,"img":false}]}
{"op":"mcm","clk":"5348811328","pt":1646220893309,"mc":[{"id":"1.195453630","rc":[{"atb":[[3.2,7.2]],"id":39267517}],"con":true,"img":false}]}
{"op":"mcm","clk":"5348811413","pt":1646220894010,"mc":[{"id":"1.195453630","rc":[{"atb":[[2.06,0],[2.26,0],[2.16,0]],"id":40717352},{"atl":[[5.6,0],[7.2,0],[9.2,0]],"id":40717352},{"atb":[[3.45,0],[3.2,34.09],[2.98,0]],"id":41946970},{"atl":[[18.5,0],[13.5,0],[9.4,0]],"id":41946970},{"atb":[[1.98,0],[1.93,0],[2.06,0]],"id":39931665},{"atl":[[6.4,0],[5.2,0],[8.4,0]],"id":39931665},{"atb":[[2.86,0],[3.15,9.3],[2.96,0]],"id":39267517},{"atl":[[16,0],[11,0],[8.4,0]],"id":39267517},{"atb":[[1.2,0],[1.25,0],[1.3,0]],"id":39860456},{"atl":[[2.54,0],[2.74,0],[2.94,0]],"id":39860456}],"con":true,"img":false}]}
{"op":"mcm","clk":"5348811440","pt":1646220894232,"mc":[{"id":"1.195453630","rc":[{"atl":[[3.35,31.91]],"id":39931665}],"con":true,"img":false}]}
{"op":"mcm","clk":"5348811475","pt":1646220894533,"mc":[{"id":"1.195453630","rc":[{"atb":[[3,0]],"id":41946970},{"atl":[[2.72,0]],"id":39860456}],"con":true,"img":false}]}
{"op":"mcm","clk":"5348811485","pt":1646220894600,"mc":[{"id":"1.195453630","rc":[{"atb":[[2.82,31.61]],"id":41946970},{"atl":[[3.1,25.34]],"id":39860456}],"con":true,"img":false}]}
{"op":"mcm","clk":"5348811540","pt":1646220895021,"mc":[{"id":"1.195453630","rc":[{"atl":[[3.2,0],[3.5,0]],"id":39931665}],"con":true,"img":false}]}
{"op":"mcm","clk":"5348811564","pt":1646220895182,"mc":[{"id":"1.195453630","rc":[{"atl":[[3.35,74.46],[3.25,22.22]],"id":39931665}],"con":true,"img":false}]}
{"op":"mcm","clk":"5348811584","pt":1646220895390,"mc":[{"id":"1.195453630","rc":[{"atl":[[6.6,0]],"id":39267517}],"con":true,"img":false}]}
{"op":"mcm","clk":"5348811595","pt":1646220895490,"mc":[{"id":"1.195453630","rc":[{"atl":[[7,7.26]],"id":39267517}],"con":true,"img":false}]}
{"op":"mcm","clk":"5348811693","pt":1646220896384,"mc":[{"id":"1.195453630","rc":[{"atb":[[3.55,0]],"id":41946970},{"atb":[[2.1,7.57]],"id":39931665},{"atb":[[3.2,3.78]],"id":39267517}],"con":true,"img":false}]}
{"op":"mcm","clk":"5348811741","pt":1646220896806,"mc":[{"id":"1.195453630","rc":[{"atb":[[1.82,54.5],[2.28,0]],"id":40717352},{"atl":[[3.95,6.78]],"id":40717352},{"atl":[[12,0]],"id":41946970},{"atb":[[1.39,0]],"id":39860456}],"con":true,"img":false}]}
{"op":"mcm","clk":"5348811760","pt":1646220896918,"mc":[{"id":"1.195453630","rc":[{"atl":[[4.1,14.06]],"id":40717352},{"atl":[[11,5.45]],"id":41946970},{"atb":[[1.41,143.06]],"id":39860456}],"con":true,"img":false}]}
{"op":"mcm","clk":"5348811839","pt":1646220897505,"mc":[{"id":"1.195453630","rc":[{"atb":[[2.3,1.41]],"id":40717352},{"atb":[[3.7,1.49]],"id":41946970},{"atb":[[2.16,3.73]],"id":39931665},{"atb":[[3.4,3.24]],"id":39267517},{"atb":[[2.04,3.73]],"id":37406513},{"atb":[[1.51,3.59]],"id":39860456}],"con":true,"img":false}]}
{"op":"mcm","clk":"5348811861","pt":1646220897713,"mc":[{"id":"1.195453630","rc":[{"atl":[[7.2,12.1],[6.8,17.24]],"id":39267517}],"con":true,"img":false}]}
{"op":"mcm","clk":"5348811903","pt":1646220897987,"mc":[{"id":"1.195453630","rc":[{"atb":[[2.18,0]],"id":40717352},{"atb":[[3.35,0]],"id":39267517},{"atb":[[1.4,0]],"id":39860456}],"con":true,"img":false}]}
{"op":"mcm","clk":"5348811945","pt":1646220898396,"mc":[{"id":"1.195453630","rc":[{"atb":[[2.3,0]],"id":40717352},{"atb":[[3.4,1.66]],"id":39267517}],"con":true,"img":false}]}
{"op":"mcm","clk":"5348811962","pt":1646220898504,"mc":[{"id":"1.195453630","rc":[{"atb":[[1.83,1.41]],"id":40717352},{"atb":[[3.25,1.58]],"id":39267517}],"con":true,"img":false}]}
{"op":"mcm","clk":"5348812102","pt":1646220899825,"mc":[{"id":"1.195453630","rc":[{"atb":[[1.83,24.1]],"id":37406513}],"con":true,"img":false}]}
{"op":"mcm","clk":"5348812109","pt":1646220899929,"mc":[{"id":"1.195453630","rc":[{"atb":[[2.1,0]],"id":39931665},{"atb":[[1.91,58.92]],"id":37406513}],"con":true,"img":false}]}
{"op":"mcm","clk":"5348812243","pt":1646220901026,"mc":[{"id":"1.195453630","rc":[{"atb":[[3.65,1.66]],"id":41946970}],"con":true,"img":false}]}
{"op":"mcm","clk":"5348812284","pt":1646220901304,"mc":[{"id":"1.195453630","rc":[{"atl":[[4.1,30.19]],"id":40717352},{"atb":[[3.05,24.39]],"id":39267517},{"atl":[[6.2,9.62]],"id":39267517}],"con":true,"img":false}]}
{"op":"mcm","clk":"5348812351","pt":1646220901925,"mc":[{"id":"1.195453630","rc":[{"atb":[[3.7,0]],"id":41946970}],"con":true,"img":false}]}
{"op":"mcm","clk":"5348812369","pt":1646220902033,"mc":[{"id":"1.195453630","rc":[{"atb":[[3.55,1.49]],"id":41946970}],"con":true,"img":false}]}
{"op":"mcm","clk":"5348812450","pt":1646220902630,"mc":[{"id":"1.195453630","rc":[{"atb":[[3.5,22.38]],"id":41946970},{"atb":[[1.98,7.65]],"id":39931665}],"con":true,"img":false}]}
{"op":"mcm","clk":"5348812533","pt":1646220903306,"mc":[{"id":"1.195453630","rc":[{"atl":[[4,0],[4.4,0],[4.2,0]],"id":40717352},{"atl":[[7.2,0],[6.8,8.62],[7.6,0]],"id":39267517}],"con":true,"img":false}]}
{"op":"mcm","clk":"5348812565","pt":1646220903622,"mc":[{"id":"1.195453630","rc":[{"atl":[[4.1,16.13]],"id":40717352}],"con":true,"img":false}]}
{"op":"mcm","clk":"5348812577","pt":1646220903724,"mc":[{"id":"1.195453630","rc":[{"atl":[[5.7,9.27]],"id":40717352}],"con":true,"img":false}]}
{"op":"mcm","clk":"5348812623","pt":1646220904206,"mc":[{"id":"1.195453630","rc":[{"atb":[[1.84,6.6]],"id":40717352},{"atb":[[2.12,0]],"id":39931665},{"atl":[[3.45,70.4]],"id":39931665},{"atb":[[3.3,6.5]],"id":39267517},{"atb":[[1.46,12.58]],"id":39860456}],"con":true,"img":false}]}
{"op":"mcm","clk":"5348812676","pt":1646220904627,"mc":[{"id":"1.195453630","rc":[{"atb":[[1.83,0]],"id":40717352},{"atb":[[2.16,2.16]],"id":39931665},{"atb":[[3.25,0]],"id":39267517}],"con":true,"img":false}]}
{"op":"mcm","clk":"5348812688","pt":1646220904723,"mc":[{"id":"1.195453630","rc":[{"atb":[[1.85,1.41]],"id":40717352},{"atb":[[1.01,1.57]],"id":39931665},{"atb":[[3.35,1.58]],"id":39267517}],"con":true,"img":false}]}
{"op":"mcm","clk":"5348812732","pt":1646220905001,"mc":[{"id":"1.195453630","rc":[{"atb":[[3.5,3]],"id":41946970},{"atl":[[7,0]],"id":39267517}],"con":true,"img":false}]}
{"op":"mcm","clk":"5348812740","pt":1646220905102,"mc":[{"id":"1.195453630","rc":[{"atb":[[3.45,19.38]],"id":41946970},{"atl":[[9,7.26]],"id":39267517}],"con":true,"img":false}]}
{"op":"mcm","clk":"5348812758","pt":1646220905316,"mc":[{"id":"1.195453630","rc":[{"atb":[[2.02,2.16],[2.16,0]],"id":39931665}],"con":true,"img":false}]}
{"op":"mcm","clk":"5348812765","pt":1646220905419,"mc":[{"id":"1.195453630","rc":[{"atb":[[1.85,0],[1.95,0],[1.9,0]],"id":37406513},{"atl":[[5.6,0],[7.2,0],[4.6,0]],"id":37406513}],"con":true,"img":false}]}
{"op":"mcm","clk":"5348812853","pt":1646220906313,"mc":[{"id":"1.195453630","rc":[{"atl":[[5.5,0]],"id":37406513}],"con":true,"img":false}]}
{"op":"mcm","clk":"5348812860","pt":1646220906422,"mc":[{"id":"1.195453630","rc":[{"atb":[[1.01,0]],"id":39931665},{"atl":[[5.6,12.73]],"id":37406513}],"con":true,"img":false}]}
{"op":"mcm","clk":"5348812869","pt":1646220906523,"mc":[{"id":"1.195453630","rc":[{"atb":[[2.02,3.73]],"id":39931665}],"con":true,"img":false}]}
{"op":"mcm","clk":"5348812938","pt":1646220907211,"mc":[{"id":"1.195453630","rc":[{"atb":[[3.6,6.3]],"id":41946970}],"con":true,"img":false}]}
{"op":"mcm","clk":"5348813047","pt":1646220908217,"mc":[{"id":"1.195453630","rc":[{"atb":[[3.55,0]],"id":41946970}],"con":true,"img":false}]}
{"op":"mcm","clk":"5348813058","pt":1646220908317,"mc":[{"id":"1.195453630","rc":[{"atb":[[3.65,3.15]],"id":41946970},{"atb":[[3.1,3.57]],"id":39267517},{"atb":[[1.99,8.41]],"id":37406513}],"con":true,"img":false}]}
{"op":"mcm","clk":"5348813076","pt":1646220908527,"mc":[{"id":"1.195453630","rc":[{"atb":[[2.26,79.22],[2.06,94.16],[2.16,86.05]],"id":40717352},{"atl":[[5.6,7.89],[7.2,11.7],[9.2,8.85]],"id":40717352},{"atb":[[3.1,107.05],[3.35,42.47],[2.94,51.45]],"id":41946970},{"atl":[[17,4.54],[12,6.6],[8.8,4.65]],"id":41946970},{"atb":[[2,99.82],[1.9,249.8],[1.95,105.07]],"id":39931665},{"atl":[[5.1,22.24],[6.2,13.96],[8.2,10.08]],"id":39931665},{"atb":[[2.98,50.41],[2.88,53.09],[2.78,56.07]],"id":39267517},{"atl":[[10.5,7.64],[8.2,5.04],[15.5,5]],"id":39267517},{"atb":[[1.85,117.43],[1.95,105.07],[1.9,110.91]],"id":37406513},{"atl":[[5.6,28.52],[7.2,11.7],[4.6,10.08]],"id":37406513},{"atb":[[1.4,249.55],[1.45,302.13],[1.5,199.64]],"id":39860456},{"atl":[[3.45,37.79],[2.98,36.66],[2.78,20.39]],"id":39860456}],"con":true,"img":false}]}
{"op":"mcm","clk":"5348813132","pt":1646220909117,"mc":[{"id":"1.195453630","rc":[{"atb":[[1.85,0]],"id":40717352}],"con":true,"img":false}]}
{"op":"mcm","clk":"5348813140","pt":1646220909223,"mc":[{"id":"1.195453630","rc":[{"atb":[[2.28,1.41]],"id":40717352}],"con":true,"img":false}]}
{"op":"mcm","clk":"5348813287","pt":1646220910536,"mc":[{"id":"1.195453630","rc":[{"atb":[[1.84,0]],"id":40717352},{"atb":[[1.99,14.86]],"id":39931665},{"atb":[[3.3,0]],"id":39267517},{"atb":[[1.96,0]],"id":37406513}],"con":true,"img":false}]}
{"op":"mcm","clk":"5348813337","pt":1646220910926,"mc":[{"id":"1.195453630","rc":[{"atb":[[3.35,0]],"id":39267517}],"con":true,"img":false}]}
{"op":"mcm","clk":"5348813347","pt":1646220911020,"mc":[{"id":"1.195453630","rc":[{"atb":[[3.25,1.58]],"id":39267517}],"con":true,"img":false}]}
{"op":"mcm","clk":"5348813382","pt":1646220911340,"mc":[{"id":"1.195453630","rc":[{"atl":[[4.3,22.73]],"id":40717352},{"atb":[[2.98,88.29]],"id":39267517},{"atl":[[6.6,13.39]],"id":39267517}],"con":true,"img":false}]}
{"op":"mcm","clk":"5348813405","pt":1646220911510,"mc":[{"id":"1.195453630","rc":[{"atb":[[1.98,0]],"id":39931665},{"atb":[[1.48,17.34]],"id":39860456}],"con":true,"img":false}]}
{"op":"mcm","clk":"5348813456","pt":1646220912027,"mc":[{"id":"1.195453630","rc":[{"atb":[[2.18,0]],"id":39931665},{"atb":[[3.4,0]],"id":39267517}],"con":true,"img":false}]}
{"op":"mcm","clk":"5348813481","pt":1646220912238,"mc":[{"id":"1.195453630","rc":[{"atb":[[2.04,1.66]],"id":39931665},{"atb":[[3.25,3.24]],"id":39267517}],"con":true,"img":false}]}
{"op":"mcm","clk":"5348813586","pt":1646220913038,"mc":[{"id":"1.195453630","rc":[{"atl":[[3.45,51.02]],"id":39931665}],"con":true,"img":false}]}
{"op":"mcm","clk":"5348813599","pt":1646220913139,"mc":[{"id":"1.195453630","rc":[{"atl":[[3.3,19.38]],"id":39931665}],"con":true,"img":false}]}
{"op":"mcm","clk":"5348813628","pt":1646220913310,"mc":[{"id":"1.195453630","rc":[{"atl":[[3.35,31.91],[3.25,44.44]],"id":39931665}],"con":true,"img":false}]}
{"op":"mcm","clk":"5348813642","pt":1646220913413,"mc":[{"id":"1.195453630","rc":[{"atb":[[3.5,6.33]],"id":41946970},{"atb":[[3.2,0]],"id":39267517}],"con":true,"img":false}]}
{"op":"mcm","clk":"5348813670","pt":1646220913629,"mc":[{"id":"1.195453630","rc":[{"atb":[[3.6,0]],"id":41946970},{"atb":[[1.46,0]],"id":39860456}],"con":true,"img":false}]}
{"op":"mcm","clk":"5348813759","pt":1646220914510,"mc":[{"id":"1.195453630","rc":[{"atb":[[3.65,1.66]],"id":41946970},{"atb":[[3.25,1.66]],"id":39267517}],"con":true,"img":false}]}
{"op":"mcm","clk":"5348813769","pt":1646220914620,"mc":[{"id":"1.195453630","rc":[{"atb":[[3.55,1.49]],"id":41946970},{"atb":[[3.2,1.58]],"id":39267517}],"con":true,"img":false}]}
{"op":"mcm","clk":"5348814024","pt":1646220917136,"mc":[{"id":"1.195453630","rc":[{"atb":[[2.18,11.56]],"id":40717352},{"atb":[[1.99,0]],"id":39931665},{"atb":[[3.3,6.5]],"id":39267517},{"atb":[[1.96,20.24]],"id":37406513}],"con":true,"img":false}]}
{"op":"mcm","clk":"5348814044","pt":1646220917350,"mc":[{"id":"1.195453630","rc":[{"atb":[[2.04,8.88]],"id":39931665},{"atb":[[1.99,15.99]],"id":37406513},{"atb":[[1.53,14.16]],"id":39860456}],"con":true,"img":false}]}
{"op":"mcm","clk":"5348814131","pt":1646220918046,"mc":[{"id":"1.195453630","rc":[{"atb":[[1.56,2.16],[1.51,1.43]],"id":39860456}],"con":true,"img":false}]}
{"op":"mcm","clk":"5348814142","pt":1646220918143,"mc":[{"id":"1.195453630","rc":[{"atb":[[2.02,2.16]],"id":39931665},{"atb":[[3.2,0]],"id":39267517},{"atb":[[1.51,0]],"id":39860456}],"con":true,"img":false}]}
{"op":"mcm","clk":"5348814155","pt":1646220918246,"mc":[{"id":"1.195453630","rc":[{"atb":[[2.06,1.57]],"id":39931665},{"atb":[[3.35,1.58]],"id":39267517},{"atb":[[1.54,1.43]],"id":39860456}],"con":true,"img":false}]}
{"op":"mcm","clk":"5348814256","pt":1646220919144,"mc":[{"id":"1.195453630","rc":[{"atb":[[1.54,0]],"id":39860456}],"con":true,"img":false}]}
{"op":"mcm","clk":"5348814268","pt":1646220919247,"mc":[{"id":"1.195453630","rc":[{"atb":[[1.56,3.59]],"id":39860456}],"con":true,"img":false}]}
{"op":"mcm","clk":"5348814309","pt":1646220919521,"mc":[{"id":"1.195453630","rc":[{"atb":[[1.94,53.19]],"id":39931665},{"atb":[[1.63,0]],"id":37406513}],"con":true,"img":false}]}
{"op":"mcm","clk":"5348814323","pt":1646220919634,"mc":[{"id":"1.195453630","rc":[{"atb":[[2.02,57.35]],"id":39931665},{"atb":[[1.7,86.94]],"id":37406513}],"con":true,"img":false}]}
{"op":"mcm","clk":"5348814422","pt":1646220920426,"mc":[{"id":"1.195453630","rc":[{"atb":[[3.45,60.2],[3.4,8.33]],"id":41946970},{"atb":[[2.04,1.66]],"id":39931665},{"atl":[[3.45,29.63],[3.5,8]],"id":39860456}],"con":true,"img":false}]}
{"op":"mcm","clk":"5348814467","pt":1646220920836,"mc":[{"id":"1.195453630","rc":[{"atb":[[3.6,6.3]],"id":41946970},{"atb":[[2.06,0]],"id":39931665},{"atb":[[1.52,7.19]],"id":39860456}],"con":true,"img":false}]}
{"op":"mcm","clk":"5348814477","pt":1646220920940,"mc":[{"id":"1.195453630","rc":[{"atb":[[2.04,3.24]],"id":39931665}],"con":true,"img":false}]}
{"op":"mcm","clk":"5348814539","pt":1646220921356,"mc":[{"id":"1.195453630","rc":[{"atl":[[4.5,35.71]],"id":40717352},{"atb":[[2.94,64.43]],"id":39267517},{"atl":[[7,20.83]],"id":39267517}],"con":true,"img":false}]}
{"op":"mcm","clk":"5348814781","pt":1646220923521,"mc":[{"id":"1.195453630","rc":[{"atb":[[3.5,3.33]],"id":41946970}],"con":true,"img":false}]}
{"op":"mcm","clk":"5348814858","pt":1646220924249,"mc":[{"id":"1.195453630","rc":[{"atb":[[2.06,6.48]],"id":39931665}],"con":true,"img":false}]}
{"op":"mcm","clk":"5348814988","pt":1646220925344,"mc":[{"id":"1.195453630","rc":[{"atb":[[2.04,1.66]],"id":39931665}],"con":true,"img":false}]}
{"op":"mcm","clk":"5348815000","pt":1646220925455,"mc":[{"id":"1.195453630","rc":[{"atb":[[2.08,1.57]],"id":39931665}],"con":true,"img":false}]}
{"op":"mcm","clk":"5348815181","pt":1646220927054,"mc":[{"id":"1.195453630","rc":[{"atb":[[1.52,0]],"id":39860456}],"con":true,"img":false}]}
{"op":"mcm","clk":"5348815216","pt":1646220927356,"mc":[{"id":"1.195453630","rc":[{"atb":[[2.06,13.56]],"id":39931665}],"con":true,"img":false}]}
{"op":"mcm","clk":"5348815229","pt":1646220927425,"mc":[{"id":"1.195453630","rc":[{"atb":[[2.7,0]],"id":39267517},{"atb":[[1.45,221.82]],"id":39860456}],"con":true,"img":false}]}
{"op":"mcm","clk":"5348815242","pt":1646220927527,"mc":[{"id":"1.195453630","rc":[{"atb":[[3,22.01]],"id":39267517},{"atb":[[1.51,80.3]],"id":39860456}],"con":true,"img":false}]}
{"op":"mcm","clk":"5348815348","pt":1646220928430,"mc":[{"id":"1.195453630","rc":[{"atb":[[2.12,2.16],[2.02,55.19]],"id":39931665}],"con":true,"img":false}]}
{"op":"mcm","clk":"5348815546","pt":1646220929948,"mc":[{"id":"1.195453630","rc":[{"atb":[[3.05,28.45]],"id":39267517}],"con":true,"img":false}]}
{"op":"mcm","clk":"5348815557","pt":1646220930050,"mc":[{"id":"1.195453630","rc":[{"atb":[[2.04,0]],"id":39931665},{"atb":[[3.25,0]],"id":39267517}],"con":true,"img":false}]}
{"op":"mcm","clk":"5348815571","pt":1646220930150,"mc":[{"id":"1.195453630","rc":[{"atb":[[1.48,0]],"id":39860456}],"con":true,"img":false}]}
{"op":"mcm","clk":"5348815584","pt":1646220930250,"mc":[{"id":"1.195453630","rc":[{"atb":[[2.14,1.66]],"id":39931665},{"atb":[[3.35,3.24]],"id":39267517}],"con":true,"img":false}]}
{"op":"mcm","clk":"5348815603","pt":1646220930455,"mc":[{"id":"1.195453630","rc":[{"atl":[[3.6,19.23]],"id":39860456}],"con":true,"img":false}]}
{"op":"mcm","clk":"5348815714","pt":1646220931453,"mc":[{"id":"1.195453630","rc":[{"atb":[[2.32,0]],"id":39267517},{"atl":[[3.1,0]],"id":39860456}],"con":true,"img":false}]}
{"op":"mcm","clk":"5348815728","pt":1646220931556,"mc":[{"id":"1.195453630","rc":[{"atb":[[2.46,47.96]],"id":39267517},{"atl":[[2.96,25.34]],"id":39860456}],"con":true,"img":false}]}
{"op":"mcm","clk":"5348815810","pt":1646220932249,"mc":[{"id":"1.195453630","rc":[{"atl":[[3.55,0],[3.65,0],[3.75,0]],"id":39860456}],"con":true,"img":false}]}
{"op":"mcm","clk":"5348815843","pt":1646220932555,"mc":[{"id":"1.195453630","rc":[{"atb":[[3.55,4.43]],"id":41946970},{"atb":[[1.53,0]],"id":39860456}],"con":true,"img":false}]}
{"op":"mcm","clk":"5348815914","pt":1646220933245,"mc":[{"id":"1.195453630","rc":[{"spn":2.66,"spf":"NaN","id":40717352},{"spn":6.22,"spf":"NaN","id":41946970},{"atb":[[2.06,7.07]],"id":39931665},{"spn":2.64,"spf":"NaN","id":39931665},{"spn":4.62,"spf":"NaN","id":39267517},{"spn":1.54,"spf":1.0,"id":39860456}],"con":true,"img":false}]}
{"op":"mcm","clk":"5348815929","pt":1646220933347,"mc":[{"id":"1.195453630","rc":[{"atb":[[1.54,9.88]],"id":39860456}],"con":true,"img":false}]}
{"op":"mcm","clk":"5348815941","pt":1646220933452,"mc":[{"id":"1.195453630","rc":[{"atb":[[1.56,2.16]],"id":39860456}],"con":true,"img":false}]}
{"op":"mcm","clk":"5348815949","pt":1646220933551,"mc":[{"id":"1.195453630","rc":[{"atb":[[1.01,1.43]],"id":39860456}],"con":true,"img":false}]}
{"op":"mcm","clk":"5348815993","pt":1646220934031,"mc":[{"id":"1.195453630","rc":[{"atb":[[1.82,0]],"id":40717352},{"atl":[[3.3,0]],"id":39931665}],"con":true,"img":false}]}
{"op":"mcm","clk":"5348816004","pt":1646220934136,"mc":[{"id":"1.195453630","rc":[{"atb":[[1.84,54.5]],"id":40717352},{"atl":[[3.2,19.38]],"id":39931665}],"con":true,"img":false}]}
{"op":"mcm","clk":"5348816015","pt":1646220934250,"mc":[{"id":"1.195453630","rc":[{"atl":[[3.35,74.46],[3.25,22.22]],"id":39931665}],"con":true,"img":false}]}
{"op":"mcm","clk":"5348816036","pt":1646220934448,"mc":[{"id":"1.195453630","rc":[{"atb":[[1.01,0]],"id":39860456}],"con":true,"img":false}]}
{"op":"mcm","clk":"5348816053","pt":1646220934556,"mc":[{"id":"1.195453630","rc":[{"atb":[[1.56,3.59]],"id":39860456}],"con":true,"img":false}]}
{"op":"mcm","clk":"5348816284","pt":1646220936023,"mc":[{"id":"1.195453630","rc":[{"atb":[[3.3,0]],"id":39267517}],"con":true,"img":false}]}
{"op":"mcm","clk":"5348816312","pt":1646220936230,"mc":[{"id":"1.195453630","rc":[{"atb":[[3.35,1.66]],"id":39267517}],"con":true,"img":false}]}
{"op":"mcm","clk":"5348816326","pt":1646220936334,"mc":[{"id":"1.195453630","rc":[{"atb":[[3.2,1.58]],"id":39267517}],"con":true,"img":false}]}
{"op":"mcm","clk":"5348816388","pt":1646220936753,"mc":[{"id":"1.195453630","rc":[{"atl":[[9,0]],"id":39267517}],"con":true,"img":false}]}
{"op":"mcm","clk":"5348816402","pt":1646220936860,"mc":[{"id":"1.195453630","rc":[{"atl":[[6.4,7.26]],"id":39267517}],"con":true,"img":false}]}
{"op":"mcm","clk":"5348816427","pt":1646220937058,"mc":[{"id":"1.195453630","rc":[{"atl":[[6.2,19.24],[6.8,0]],"id":39267517}],"con":true,"img":false}]}
{"op":"mcm","clk":"5348816638","pt":1646220938343,"mc":[{"id":"1.195453630","rc":[{"atb":[[1.54,23.79]],"id":39860456}],"con":true,"img":false}]}
{"op":"mcm","clk":"5348816740","pt":1646220939042,"mc":[{"id":"1.195453630","rc":[{"atb":[[2.08,12.09]],"id":39931665}],"con":true,"img":false}]}
{"op":"mcm","clk":"5348816922","pt":1646220940463,"mc":[{"id":"1.195453630","rc":[{"atl":[[3.7,27.78]],"id":39860456}],"con":true,"img":false}]}
{"op":"mcm","clk":"5348817117","pt":1646220941964,"mc":[{"id":"1.195453630","rc":[{"atl":[[4,14.53],[5.7,0]],"id":40717352}],"con":true,"img":false}]}
{"op":"mcm","clk":"5348817125","pt":1646220942057,"mc":[{"id":"1.195453630","rc":[{"atb":[[3.25,6.5]],"id":39267517}],"con":true,"img":false}]}
{"op":"mcm","clk":"5348817302","pt":1646220943483,"mc":[{"id":"1.195453630","rc":[{"atl":[[3.35,31.91],[3.15,28.68]],"id":39931665}],"con":true,"img":false}]}
{"op":"mcm","clk":"5348817501","pt":1646220944972,"mc":[{"id":"1.195453630","rc":[{"atb":[[3.5,0]],"id":41946970}],"con":true,"img":false}]}
{"op":"mcm","clk":"5348817537","pt":1646220945281,"mc":[{"id":"1.195453630","rc":[{"atb":[[2.06,14.93]],"id":39931665}],"con":true,"img":false}]}
{"op":"mcm","clk":"5348817559","pt":1646220945487,"mc":[{"id":"1.195453630","rc":[{"atb":[[1.54,39.21]],"id":39860456}],"con":true,"img":false}]}
{"op":"mcm","clk":"5348817915","pt":1646220948075,"mc":[{"id":"1.195453630","rc":[{"atb":[[3.35,0]],"id":39267517}],"con":true,"img":false}]}
{"op":"mcm","clk":"5348817937","pt":1646220948286,"mc":[{"id":"1.195453630","rc":[{"atb":[[3.3,1.66]],"id":39267517}],"con":true,"img":false}]}
{"op":"mcm","clk":"5348818122","pt":1646220949767,"mc":[{"id":"1.195453630","rc":[{"atb":[[1.41,0]],"id":39860456}],"con":true,"img":false}]}
{"op":"mcm","clk":"5348818137","pt":1646220949865,"mc":[{"id":"1.195453630","rc":[{"atb":[[1.46,143.06]],"id":39860456}],"con":true,"img":false}]}
{"op":"mcm","clk":"5348818211","pt":1646220950486,"mc":[{"id":"1.195453630","rc":[{"atl":[[3.8,44.64]],"id":39860456}],"con":true,"img":false}]}
{"op":"mcm","clk":"5348818282","pt":1646220951171,"mc":[{"id":"1.195453630","rc":[{"atb":[[2.82,0]],"id":41946970}],"con":true,"img":false}]}
{"op":"mcm","clk":"5348818294","pt":1646220951277,"mc":[{"id":"1.195453630","rc":[{"atb":[[2.96,31.61]],"id":41946970}],"con":true,"img":false}]}
{"op":"mcm","clk":"5348819283","pt":1646220960390,"mc":[{"id":"1.195453630","rc":[{"atl":[[6.4,0]],"id":39267517}],"con":true,"img":false}]}
{"op":"mcm","clk":"5348819293","pt":1646220960494,"mc":[{"id":"1.195453630","rc":[{"atl":[[6,7.26]],"id":39267517}],"con":true,"img":false}]}
{"op":"mcm","clk":"5348819306","pt":1646220960598,"mc":[{"id":"1.195453630","rc":[{"atl":[[6.2,9.62],[6.6,31.25]],"id":39267517}],"con":true,"img":false}]}
{"op":"mcm","clk":"5348819318","pt":1646220960703,"mc":[{"id":"1.195453630","rc":[{"atb":[[3.55,7.69]],"id":41946970},{"atl":[[5.9,11.35]],"id":39267517}],"con":true,"img":false}]}
{"op":"mcm","clk":"5348819331","pt":1646220960810,"mc":[{"id":"1.195453630","rc":[{"atl":[[6.6,13.39]],"id":39267517}],"con":true,"img":false}]}
{"op":"mcm","clk":"5348820191","pt":1646220968315,"mc":[{"id":"1.195453630","rc":[{"atl":[[6,0]],"id":39267517}],"con":true,"img":false}]}
{"op":"mcm","clk":"5348820209","pt":1646220968419,"mc":[{"id":"1.195453630","rc":[{"atl":[[6.4,7.26]],"id":39267517}],"con":true,"img":false}]}
{"op":"mcm","clk":"5348820224","pt":1646220968503,"mc":[{"id":"1.195453630","rc":[{"atl":[[6.6,31.25],[5.9,4.08]],"id":39267517}],"con":true,"img":false}]}
{"op":"mcm","clk":"5348821355","pt":1646220977434,"mc":[{"id":"1.195453630","rc":[{"atl":[[6.2,19.24],[6.6,13.39]],"id":39267517}],"con":true,"img":false}]}
{"op":"mcm","clk":"5348821371","pt":1646220977491,"mc":[{"id":"1.195453630","rc":[{"atb":[[1.73,0]],"id":39931665}],"con":true,"img":false}]}
{"op":"mcm","clk":"5348821385","pt":1646220977605,"mc":[{"id":"1.195453630","rc":[{"atb":[[1.67,83.19]],"id":39931665}],"con":true,"img":false}]}
{"op":"mcm","clk":"5348821397","pt":1646220977698,"mc":[{"id":"1.195453630","rc":[{"atb":[[2.08,10.52]],"id":39931665},{"atb":[[3.2,0]],"id":39267517}],"con":true,"img":false}]}
{"op":"mcm","clk":"5348821414","pt":1646220977799,"mc":[{"id":"1.195453630","rc":[{"atb":[[2.12,3.73]],"id":39931665},{"atb":[[3.3,3.24]],"id":39267517}],"con":true,"img":false}]}
{"op":"mcm","clk":"5348822096","pt":1646220983909,"mc":[{"id":"1.195453630","rc":[{"atb":[[3.25,0]],"id":39267517}],"con":true,"img":false}]}
{"op":"mcm","clk":"5348822214","pt":1646220984901,"mc":[{"id":"1.195453630","rc":[{"atb":[[3.3,1.66]],"id":39267517}],"con":true,"img":false}]}
{"op":"mcm","clk":"5348822228","pt":1646220985021,"mc":[{"id":"1.195453630","rc":[{"atb":[[3.2,1.58]],"id":39267517}],"con":true,"img":false}]}
{"op":"mcm","clk":"5348822759","pt":1646220989818,"mc":[{"id":"1.195453630","rc":[{"atb":[[3.25,6.5]],"id":39267517}],"con":true,"img":false}]}
{"op":"mcm","clk":"5348823381","pt":1646220995623,"mc":[{"id":"1.195453630","rc":[{"atl":[[3.95,0],[3.9,6.9]],"id":40717352},{"atl":[[3.1,9.52],[3.15,19.38]],"id":39931665},{"spn":2.62,"spf":"NaN","id":39931665},{"atl":[[5.8,4.17],[5.9,0]],"id":39267517},{"spn":4.55,"spf":"NaN","id":39267517},{"spn":1.55,"spf":1.0,"id":39860456}],"con":true,"img":false}]}
{"op":"mcm","clk":"5348823587","pt":1646220997264,"mc":[{"id":"1.195453630","rc":[{"atb":[[1.63,0],[1.54,110.38]],"id":39931665},{"atb":[[2.56,50.47],[2.68,0]],"id":39267517}],"con":true,"img":false}]}
{"op":"mcm","clk":"5348823610","pt":1646220997424,"mc":[{"id":"1.195453630","rc":[{"atb":[[2.56,0],[2.88,106.28]],"id":39267517}],"con":true,"img":false}]}
{"op":"mcm","clk":"5348823813","pt":1646220998848,"mc":[{"id":"1.195453630","rc":[{"atb":[[2.18,0]],"id":40717352}],"con":true,"img":false}]}
{"op":"mcm","clk":"5348823876","pt":1646220999330,"mc":[{"id":"1.195453630","rc":[{"atl":[[3.45,37.79],[3.5,0]],"id":39860456}],"con":true,"img":false}]}
{"op":"mcm","clk":"5348823944","pt":1646220999840,"mc":[{"id":"1.195453630","rc":[{"atl":[[3.85,7.02],[3.9,0]],"id":40717352},{"atb":[[3.25,15.39],[3.15,0]],"id":39267517},{"atl":[[6,4]],"id":39267517}],"con":true,"img":false}]}
{"op":"mcm","clk":"5348823957","pt":1646220999943,"mc":[{"id":"1.195453630","rc":[{"atl":[[5.8,0]],"id":39267517}],"con":true,"img":false}]}
{"op":"mcm","clk":"5348823979","pt":1646221000158,"mc":[{"id":"1.195453630","rc":[{"atl":[[6.2,9.62],[6.6,0],[7,0]],"id":39267517}],"con":true,"img":false}]}
{"op":"mcm","clk":"5348824129","pt":1646221001355,"mc":[{"id":"1.195453630","rc":[{"atl":[[6.4,0]],"id":39267517}],"con":true,"img":false}]}
{"op":"mcm","clk":"5348824142","pt":1646221001464,"mc":[{"id":"1.195453630","rc":[{"atl":[[8.6,7.26]],"id":39267517}],"con":true,"img":false}]}
{"op":"mcm","clk":"5348824157","pt":1646221001520,"mc":[{"id":"1.195453630","rc":[{"atl":[[8,13.62],[6.2,0]],"id":39267517}],"con":true,"img":false}]}
{"op":"mcm","clk":"5348824172","pt":1646221001625,"mc":[{"id":"1.195453630","rc":[{"atl":[[10.5,6.69],[9.8,0]],"id":41946970},{"atl":[[3.2,57.37],[3.1,0],[3.15,0]],"id":39931665},{"atl":[[4.3,6.06],[4.5,10.08],[5.9,0]],"id":37406513}],"con":true,"img":false}]}
{"op":"mcm","clk":"5348824187","pt":1646221001736,"mc":[{"id":"1.195453630","rc":[{"atl":[[5.7,0]],"id":37406513}],"con":true,"img":false}]}
{"op":"mcm","clk":"5348824298","pt":1646221002650,"mc":[{"id":"1.195453630","rc":[{"atl":[[4.7,5.41]],"id":37406513}],"con":true,"img":false}]}
{"op":"mcm","clk":"5348824312","pt":1646221002755,"mc":[{"id":"1.195453630","rc":[{"atb":[[1.79,0],[1.81,0],[1.77,0],[1.75,26.67]],"id":40717352},{"atl":[[2.74,2]],"id":40717352},{"atb":[[2.46,3]],"id":39931665},{"atl":[[3.45,0],[3.2,48.28],[3.35,0],[3.25,0],[3.5,8]],"id":39931665},{"atb":[[3.25,6.5],[3.15,9.3]],"id":39267517},{"atl":[[4.7,2]],"id":39267517},{"atb":[[2.44,4]],"id":37406513},{"atl":[[4.3,0]],"id":37406513}],"con":true,"img":false}]}
{"op":"mcm","clk":"5348824340","pt":1646221002922,"mc":[{"id":"1.195453630","rc":[{"atl":[[2.74,0],[2.68,3]],"id":40717352},{"atb":[[2.48,4]],"id":39931665},{"atl":[[4.1,2],[4.7,0]],"id":39267517},{"atb":[[2.46,2]],"id":37406513}],"con":true,"img":false}]}
{"op":"mcm","clk":"5348824353","pt":1646221003027,"mc":[{"id":"1.195453630","rc":[{"atb":[[2.14,0]],"id":39931665},{"atb":[[2.06,0]],"id":37406513},{"atl":[[3.45,29.63],[3.4,33.36]],"id":39860456}],"con":true,"img":false}]}
{"op":"mcm","clk":"5348824373","pt":1646221003235,"mc":[{"id":"1.195453630","rc":[{"atl":[[2.66,2],[2.68,0]],"id":40717352},{"atb":[[2.5,2]],"id":39931665},{"atl":[[4,4]],"id":39267517},{"atb":[[2.48,3]],"id":37406513}],"con":true,"img":false}]}
{"op":"mcm","clk":"5348824414","pt":1646221003644,"mc":[{"id":"1.195453630","rc":[{"atb":[[2.28,0]],"id":40717352},{"atl":[[2.8,2],[2.66,0]],"id":40717352},{"atb":[[2.5,0],[2.12,2.16],[1.96,0],[1.94,0],[2.48,0],[1.92,21.74],[2.46,0]],"id":39931665},{"atl":[[3.2,57.37],[3.05,2]],"id":39931665},{"atb":[[3.25,15.39],[3.15,0]],"id":39267517},{"atl":[[4,0],[4.1,0]],"id":39267517},{"atb":[[2.5,3],[2.04,2.16]],"id":37406513},{"atb":[[1.09,0],[1.08,250]],"id":39860456},{"atl":[[2.04,3]],"id":39860456}],"con":true,"img":false}]}
{"op":"mcm","clk":"5348824429","pt":1646221003745,"mc":[{"id":"1.195453630","rc":[{"atb":[[1.01,1.41]],"id":40717352},{"atb":[[2.5,1.57]],"id":39931665},{"atb":[[2.5,4.56]],"id":37406513}],"con":true,"img":false}]}
{"op":"mcm","clk":"5348824448","pt":1646221003854,"mc":[{"id":"1.195453630","rc":[{"atl":[[2.8,0],[2.78,4]],"id":40717352},{"atb":[[3.45,19.38]],"id":41946970},{"atl":[[3,2],[3.05,0]],"id":39931665},{"atb":[[3.85,3]],"id":39267517},{"atl":[[6.2,3.85],[6,0]],"id":39267517},{"atb":[[2.5,1.56],[2.32,4],[2.44,0],[2.48,0],[2.46,0]],"id":37406513},{"atl":[[2.02,2],[2.04,0]],"id":39860456}],"con":true,"img":false}]}
{"op":"mcm","clk":"5348824467","pt":1646221003953,"mc":[{"id":"1.195453630","rc":[{"atb":[[1.8,0],[1.72,90.47]],"id":40717352},{"atb":[[3.6,14]],"id":41946970}],"con":true,"img":false}]}
{"op":"mcm","clk":"5348824478","pt":1646221004058,"mc":[{"id":"1.195453630","rc":[{"atl":[[2.76,2],[2.78,0]],"id":40717352},{"atl":[[3,0],[2.96,4]],"id":39931665},{"atb":[[3.9,2]],"id":39267517},{"atb":[[2.34,4]],"id":37406513},{"atl":[[2,2]],"id":39860456}],"con":true,"img":false}]}
{"op":"mcm","clk":"5348824538","pt":1646221004565,"mc":[{"id":"1.195453630","rc":[{"atb":[[3.55,4.75]],"id":41946970},{"atb":[[1.99,8.41]],"id":37406513}],"con":true,"img":false}]}
{"op":"mcm","clk":"5348824547","pt":1646221004637,"mc":[{"id":"1.195453630","rc":[{"atb":[[1.01,0]],"id":40717352},{"atl":[[2.74,3]],"id":40717352},{"atb":[[2.5,0]],"id":39931665},{"atl":[[2.94,2]],"id":39931665},{"atb":[[3.95,4]],"id":39267517},{"atb":[[2.5,0],[2.36,4]],"id":37406513},{"atl":[[1.99,4]],"id":39860456}],"con":true,"img":false}]}
{"op":"mcm","clk":"5348824569","pt":1646221004848,"mc":[{"id":"1.195453630","rc":[{"atb":[[2.28,1.41]],"id":40717352},{"atb":[[2.12,3.73]],"id":39931665},{"atl":[[2.92,3]],"id":39931665},{"atb":[[4,3]],"id":39267517},{"atb":[[2.36,5.56],[2.38,4]],"id":37406513},{"atl":[[1.98,3]],"id":39860456}],"con":true,"img":false}]}
{"op":"mcm","clk":"5348824581","pt":1646221004953,"mc":[{"id":"1.195453630","rc":[{"atl":[[2.72,2]],"id":40717352},{"atb":[[3.25,8.89]],"id":39267517},{"atb":[[1.96,0]],"id":37406513}],"con":true,"img":false}]}
{"op":"mcm","clk":"5348824596","pt":1646221005055,"mc":[{"id":"1.195453630","rc":[{"atb":[[2.18,11.56]],"id":40717352},{"atl":[[2.9,3]],"id":39931665}],"con":true,"img":false}]}
{"op":"mcm","clk":"5348824618","pt":1646221005227,"mc":[{"id":"1.195453630","rc":[{"atl":[[2.7,3]],"id":40717352}],"con":true,"img":false}]}
{"op":"mcm","clk":"5348824630","pt":1646221005329,"mc":[{"id":"1.195453630","rc":[{"atl":[[1.98,0],[2.04,2]],"id":39860456}],"con":true,"img":false}]}
{"op":"mcm","clk":"5348824655","pt":1646221005538,"mc":[{"id":"1.195453630","rc":[{"atb":[[2.28,0]],"id":40717352},{"atb":[[2.36,4]],"id":37406513},{"atb":[[1.56,2.16]],"id":39860456}],"con":true,"img":false}]}
{"op":"mcm","clk":"5348824665","pt":1646221005634,"mc":[{"id":"1.195453630","rc":[{"atb":[[1.01,1.41]],"id":40717352},{"atb":[[2.4,1.56]],"id":37406513},{"atb":[[1.01,1.43]],"id":39860456}],"con":true,"img":false}]}
{"op":"mcm","clk":"5348824707","pt":1646221006052,"mc":[{"id":"1.195453630","rc":[{"atb":[[2.98,138.8],[2.88,53.09]],"id":39267517}],"con":true,"img":false}]}
{"op":"mcm","clk":"5348824792","pt":1646221006636,"mc":[{"id":"1.195453630","rc":[{"atl":[[2.9,4.25]],"id":39931665},{"atl":[[4.4,1.27]],"id":37406513}],"con":true,"img":false}]}
{"op":"mcm","clk":"5348824893","pt":1646221007356,"mc":[{"id":"1.195453630","rc":[{"atl":[[3,0]],"id":40717352}],"con":true,"img":false}]}
{"op":"mcm","clk":"5348824944","pt":1646221007731,"mc":[{"id":"1.195453630","rc":[{"atl":[[2.68,7.88]],"id":40717352},{"atb":[[1.54,29.32]],"id":39860456}],"con":true,"img":false}]}
{"op":"mcm","clk":"5348824958","pt":1646221007838,"mc":[{"id":"1.195453630","rc":[{"atl":[[2.76,0]],"id":40717352}],"con":true,"img":false}]}
{"op":"mcm","clk":"5348825265","pt":1646221010442,"mc":[{"id":"1.195453630","rc":[{"atl":[[2.62,3]],"id":40717352}],"con":true,"img":false}]}
{"op":"mcm","clk":"5348825276","pt":1646221010547,"mc":[{"id":"1.195453630","rc":[{"atl":[[2.68,3]],"id":40717352},{"atb":[[3.45,22.44]],"id":41946970}],"con":true,"img":false}]}
{"op":"mcm","clk":"5348825297","pt":1646221010747,"mc":[{"id":"1.195453630","rc":[{"atl":[[2.64,4.96]],"id":40717352}],"con":true,"img":false}]}
{"op":"mcm","clk":"5348825411","pt":1646221011639,"mc":[{"id":"1.195453630","rc":[{"atl":[[11.5,4.76]],"id":41946970}],"con":true,"img":false}]}
{"op":"mcm","clk":"5348825435","pt":1646221011852,"mc":[{"id":"1.195453630","rc":[{"atb":[[3.45,3.06]],"id":41946970}],"con":true,"img":false}]}
{"op":"mcm","clk":"5348825444","pt":1646221011951,"mc":[{"id":"1.195453630","rc":[{"atl":[[2.66,4]],"id":40717352},{"atb":[[3.4,27.71]],"id":41946970},{"atl":[[1.99,0],[2.06,2]],"id":39860456}],"con":true,"img":false}]}
{"op":"mcm","clk":"5348825455","pt":1646221012053,"mc":[{"id":"1.195453630","rc":[{"atl":[[2.72,0],[2.74,0],[2.7,0]],"id":40717352}],"con":true,"img":false}]}
{"op":"mcm","clk":"5348825526","pt":1646221012636,"mc":[{"id":"1.195453630","rc":[{"atb":[[1.73,68.49]],"id":40717352},{"atl":[[3.95,16.95]],"id":40717352},{"atl":[[4.9,12.82]],"id":37406513}],"con":true,"img":false}]}
{"op":"mcm","clk":"5348825553","pt":1646221012844,"mc":[{"id":"1.195453630","rc":[{"atb":[[2.06,0],[2.26,0],[2.16,0]],"id":40717352},{"atl":[[9.2,0],[5.6,0],[7.2,0]],"id":40717352},{"atb":[[2,0],[1.9,138.89],[1.95,0]],"id":39931665},{"atl":[[5.1,13.39],[6.2,0],[8.2,0]],"id":39931665},{"atb":[[2.98,88.39],[2.88,0],[2.78,0]],"id":39267517},{"atl":[[10.5,0],[8.2,0],[15.5,0]],"id":39267517},{"atb":[[1.4,0],[1.45,0],[1.5,0]],"id":39860456},{"atl":[[2.98,0],[3.45,0],[2.78,0]],"id":39860456}],"con":true,"img":false}]}
{"op":"mcm","clk":"5348825597","pt":1646221013152,"mc":[{"id":"1.195453630","rc":[{"atl":[[2.96,0]],"id":39860456}],"con":true,"img":false}]}
{"op":"mcm","clk":"5348825611","pt":1646221013255,"mc":[{"id":"1.195453630","rc":[{"atl":[[3.25,25.34]],"id":39860456}],"con":true,"img":false}]}
{"op":"mcm","clk":"5348825644","pt":1646221013569,"mc":[{"id":"1.195453630","rc":[{"atl":[[2.64,4],[4.5,0]],"id":40717352},{"atb":[[3.45,0]],"id":41946970},{"atb":[[1.99,15.99]],"id":37406513},{"atl":[[7,0]],"id":37406513}],"con":true,"img":false}]}
{"op":"mcm","clk":"5348825657","pt":1646221013673,"mc":[{"id":"1.195453630","rc":[{"atb":[[1.9,55.56]],"id":39931665},{"atl":[[3.3,21.74]],"id":39931665},{"atb":[[2.4,12.69]],"id":37406513},{"atb":[[1.06,250]],"id":39860456},{"atl":[[3.5,20]],"id":39860456}],"con":true,"img":false}]}
{"op":"mcm","clk":"5348825672","pt":1646221013738,"mc":[{"id":"1.195453630","rc":[{"atl":[[2.6,5.03]],"id":40717352}],"con":true,"img":false}]}
{"op":"mcm","clk":"5348825685","pt":1646221013843,"mc":[{"id":"1.195453630","rc":[{"atb":[[3.15,23.26]],"id":39267517},{"atl":[[6.6,8.93]],"id":39267517}],"con":true,"img":false}]}
{"op":"mcm","clk":"5348825829","pt":1646221015039,"mc":[{"id":"1.195453630","rc":[{"atb":[[3.2,0]],"id":39267517}],"con":true,"img":false}]}
{"op":"mcm","clk":"5348825841","pt":1646221015141,"mc":[{"id":"1.195453630","rc":[{"atb":[[4.1,1.58]],"id":39267517}],"con":true,"img":false}]}
{"op":"mcm","clk":"5348826016","pt":1646221016648,"mc":[{"id":"1.195453630","rc":[{"atl":[[2.6,0]],"id":40717352},{"atb":[[3.1,0]],"id":39267517}],"con":true,"img":false}]}
{"op":"mcm","clk":"5348826031","pt":1646221016756,"mc":[{"id":"1.195453630","rc":[{"atl":[[2.58,5.07]],"id":40717352}],"con":true,"img":false}]}
{"op":"mcm","clk":"5348826054","pt":1646221016956,"mc":[{"id":"1.195453630","rc":[{"atb":[[2.18,0]],"id":40717352},{"atb":[[3.6,7.7]],"id":41946970}],"con":true,"img":false}]}
{"op":"mcm","clk":"5348826064","pt":1646221017073,"mc":[{"id":"1.195453630","rc":[{"atl":[[2.62,0]],"id":40717352},{"atb":[[1.47,100.39]],"id":39860456}],"con":true,"img":false}]}
{"op":"mcm","clk":"5348826088","pt":1646221017267,"mc":[{"id":"1.195453630","rc":[{"atb":[[3.4,19.38],[3.5,8]],"id":41946970},{"atb":[[3.25,0],[3.15,9.3]],"id":39267517}],"con":true,"img":false}]}
{"op":"mcm","clk":"5348826101","pt":1646221017372,"mc":[{"id":"1.195453630","rc":[{"atl":[[2.62,3]],"id":40717352},{"atl":[[6,4]],"id":39267517},{"atb":[[1.03,0],[1.07,0],[1.05,0]],"id":39860456},{"atl":[[3.8,0]],"id":39860456}],"con":true,"img":false}]}
{"op":"mcm","clk":"5348826122","pt":1646221017580,"mc":[{"id":"1.195453630","rc":[{"atl":[[8,0],[6.6,17.86]],"id":39267517}],"con":true,"img":false}]}
{"op":"mcm","clk":"5348826161","pt":1646221017855,"mc":[{"id":"1.195453630","rc":[{"atb":[[1.01,0]],"id":40717352},{"atb":[[4.1,0]],"id":39267517}],"con":true,"img":false}]}
{"op":"mcm","clk":"5348826173","pt":1646221017955,"mc":[{"id":"1.195453630","rc":[{"atb":[[1.85,1.41]],"id":40717352},{"atb":[[1.01,1.58]],"id":39267517}],"con":true,"img":false}]}
{"op":"mcm","clk":"5348826215","pt":1646221018265,"mc":[{"id":"1.195453630","rc":[{"atl":[[5.9,1.32]],"id":39267517}],"con":true,"img":false}]}
{"op":"mcm","clk":"5348826237","pt":1646221018468,"mc":[{"id":"1.195453630","rc":[{"atl":[[6.6,8.93],[5.9,5.17]],"id":39267517}],"con":true,"img":false}]}
{"op":"mcm","clk":"5348826256","pt":1646221018673,"mc":[{"id":"1.195453630","rc":[{"atl":[[6.2,11.12],[5.9,1.32]],"id":39267517}],"con":true,"img":false}]}
{"op":"mcm","clk":"5348826313","pt":1646221019097,"mc":[{"id":"1.195453630","rc":[{"atb":[[2.06,94.16],[2.26,79.22],[2.16,86.05]],"id":40717352},{"atl":[[9.2,8.85],[5.6,7.89],[7.2,11.7]],"id":40717352},{"atb":[[1.85,117.43],[1.9,166.47],[1.95,105.07]],"id":39931665},{"atl":[[5.6,15.78],[7.2,11.7],[4.6,10.08]],"id":39931665},{"atb":[[2.98,138.8],[3.45,40.74],[3.2,45.37]],"id":39267517},{"atl":[[18.5,4.14],[13.5,5.8],[9.4,4.32]],"id":39267517},{"atb":[[1.4,249.55],[1.45,221.82],[1.5,199.64]],"id":39860456},{"atl":[[2.98,36.66],[3.45,29.63],[2.78,20.39]],"id":39860456}],"con":true,"img":false}]}
{"op":"mcm","clk":"5348826333","pt":1646221019260,"mc":[{"id":"1.195453630","rc":[{"atl":[[1.99,4],[2.06,0]],"id":39860456}],"con":true,"img":false}]}
{"op":"mcm","clk":"5348826395","pt":1646221019739,"mc":[{"id":"1.195453630","rc":[{"atb":[[1.01,0]],"id":39267517}],"con":true,"img":false}]}
{"op":"mcm","clk":"5348826408","pt":1646221019882,"mc":[{"id":"1.195453630","rc":[{"atb":[[4.1,1.58]],"id":39267517}],"con":true,"img":false}]}
{"op":"mcm","clk":"5348826484","pt":1646221020570,"mc":[{"id":"1.195453630","rc":[{"atb":[[1.76,47.98]],"id":40717352},{"atb":[[3.65,19.47]],"id":41946970}],"con":true,"img":false}]}
{"op":"mcm","clk":"5348826510","pt":1646221020779,"mc":[{"id":"1.195453630","rc":[{"atb":[[2.22,2.5],[2.26,86.03],[2.14,5],[2.06,213.59]],"id":40717352},{"atb":[[3.55,27.98],[3.65,28.58],[3.75,2.5]],"id":41946970},{"atl":[[9,2.5],[11,23.68],[11.5,14.76],[9.8,5],[8.8,13.76]],"id":41946970}],"con":true,"img":false}]}
{"op":"mcm","clk":"5348826535","pt":1646221020948,"mc":[{"id":"1.195453630","rc":[{"atl":[[11,5.45]],"id":41946970},{"atl":[[4.6,15.08],[4.4,11.83],[4.2,2.5],[4.7,28.65]],"id":37406513},{"atb":[[1.7,5],[1.51,89.55],[1.56,6.79],[1.74,2.5],[1.66,10]],"id":39860456}],"con":true,"img":false}]}
{"op":"mcm","clk":"5348826547","pt":1646221021056,"mc":[{"id":"1.195453630","rc":[{"atl":[[8.6,1.31]],"id":41946970}],"con":true,"img":false}]}
{"op":"mcm","clk":"5348826614","pt":1646221021668,"mc":[{"id":"1.195453630","rc":[{"atb":[[3.55,26.49]],"id":41946970}],"con":true,"img":false}]}
{"op":"mcm","clk":"5348826630","pt":1646221021771,"mc":[{"id":"1.195453630","rc":[{"atb":[[3.75,3.99]],"id":41946970}],"con":true,"img":false}]}
{"op":"mcm","clk":"5348826667","pt":1646221022046,"mc":[{"id":"1.195453630","rc":[{"atb":[[3.65,26.91]],"id":41946970},{"atb":[[3.3,0]],"id":39267517},{"atl":[[4.4,10.56]],"id":37406513}],"con":true,"img":false}]}
{"op":"mcm","clk":"5348826678","pt":1646221022149,"mc":[{"id":"1.195453630","rc":[{"atl":[[4.2,3.77]],"id":37406513}],"con":true,"img":false}]}
{"op":"mcm","clk":"5348826690","pt":1646221022294,"mc":[{"id":"1.195453630","rc":[{"atb":[[3.8,1.66]],"id":41946970},{"atb":[[2.14,1.66]],"id":39931665},{"atb":[[4.1,3.24]],"id":39267517},{"atl":[[6,9.25],[6.6,23.78]],"id":39267517}],"con":true,"img":false}]}
{"op":"mcm","clk":"5348826701","pt":1646221022358,"mc":[{"id":"1.195453630","rc":[{"atb":[[2.02,0]],"id":39931665},{"atl":[[4.5,0],[4.3,10.56]],"id":37406513}],"con":true,"img":false}]}
{"op":"mcm","clk":"5348826714","pt":1646221022458,"mc":[{"id":"1.195453630","rc":[{"atl":[[2.9,9.31],[2.94,16.5]],"id":39931665}],"con":true,"img":false}]}
{"op":"mcm","clk":"5348826737","pt":1646221022664,"mc":[{"id":"1.195453630","rc":[{"atb":[[1.71,183.76]],"id":40717352},{"atl":[[4.1,24.19]],"id":40717352},{"atb":[[1.96,55.19]],"id":39931665},{"atl":[[5.1,27.98]],"id":37406513}],"con":true,"img":false}]}
{"op":"mcm","clk":"5348826818","pt":1646221023459,"mc":[{"id":"1.195453630","rc":[{"atl":[[5.7,12.1],[6.6,0]],"id":40717352}],"con":true,"img":false}]}
{"op":"mcm","clk":"5348826839","pt":1646221023661,"mc":[{"id":"1.195453630","rc":[{"atb":[[1.88,85.23]],"id":39931665},{"atl":[[3.4,31.25]],"id":39931665},{"atb":[[1.04,250]],"id":39860456},{"atl":[[3.6,28.85]],"id":39860456}],"con":true,"img":false}]}
{"op":"mcm","clk":"5348826853","pt":1646221023767,"mc":[{"id":"1.195453630","rc":[{"atl":[[2.5,5.07]],"id":40717352},{"atl":[[6.6,0]],"id":37406513},{"atb":[[1.47,0]],"id":39860456}],"con":true,"img":false}]}
{"op":"mcm","clk":"5348826876","pt":1646221023973,"mc":[{"id":"1.195453630","rc":[{"atl":[[2.5,0]],"id":40717352},{"trd":[[2.5,10.15]],"ltp":2.5,"tv":10.15,"id":40717352}],"con":true,"img":false}]}
{"op":"mcm","clk":"5348826921","pt":1646221024344,"mc":[{"id":"1.195453630","rc":[{"atb":[[2.34,2.52]],"id":40717352}],"con":true,"img":false}]}
{"op":"mcm","clk":"5348826987","pt":1646221024862,"mc":[{"id":"1.195453630","rc":[{"atl":[[1.99,0],[2.06,4]],"id":39860456}],"con":true,"img":false}]}
{"op":"mcm","clk":"5348827021","pt":1646221025173,"mc":[{"id":"1.195453630","rc":[{"atl":[[2.08,2]],"id":39860456}],"con":true,"img":false}]}
{"op":"mcm","clk":"5348827033","pt":1646221025271,"mc":[{"id":"1.195453630","rc":[{"atb":[[2.06,7.85]],"id":39931665},{"atl":[[2,0]],"id":39860456}],"con":true,"img":false}]}
{"op":"mcm","clk":"5348827044","pt":1646221025377,"mc":[{"id":"1.195453630","rc":[{"atb":[[3.55,2.94]],"id":39267517}],"con":true,"img":false}]}
{"op":"mcm","clk":"5348827158","pt":1646221026578,"mc":[{"id":"1.195453630","rc":[{"atb":[[1.76,0]],"id":40717352},{"atb":[[3.65,9.11]],"id":41946970}],"con":true,"img":false}]}
{"op":"mcm","clk":"5348827208","pt":1646221026958,"mc":[{"id":"1.195453630","rc":[{"atl":[[5.9,10.57]],"id":39267517}],"con":true,"img":false}]}
{"op":"mcm","clk":"5348827218","pt":1646221027058,"mc":[{"id":"1.195453630","rc":[{"atl":[[6.2,3.85]],"id":39267517}],"con":true,"img":false}]}
{"op":"mcm","clk":"5348827241","pt":1646221027271,"mc":[{"id":"1.195453630","rc":[{"atl":[[12.5,0]],"id":41946970},{"atl":[[5.1,18.29]],"id":37406513}],"con":true,"img":false}]}
{"op":"mcm","clk":"5348827251","pt":1646221027369,"mc":[{"id":"1.195453630","rc":[{"atb":[[3.4,40.21]],"id":41946970},{"atl":[[12.5,6.52]],"id":41946970},{"atl":[[6.4,9.26]],"id":39267517},{"atl":[[4.5,9.69]],"id":37406513}],"con":true,"img":false}]}
{"op":"mcm","clk":"5348827378","pt":1646221028572,"mc":[{"id":"1.195453630","rc":[{"atb":[[3,0]],"id":39267517}],"con":true,"img":false}]}
{"op":"mcm","clk":"5348827393","pt":1646221028683,"mc":[{"id":"1.195453630","rc":[{"atb":[[2.96,22.01]],"id":39267517}],"con":true,"img":false}]}
{"op":"mcm","clk":"5348827444","pt":1646221029059,"mc":[{"id":"1.195453630","rc":[{"atb":[[3.1,47.53]],"id":41946970},{"atl":[[3.45,37.79],[3.4,25.03]],"id":39860456}],"con":true,"img":false}]}
{"op":"mcm","clk":"5348827490","pt":1646221029496,"mc":[{"id":"1.195453630","rc":[{"atl":[[3.85,0],[2.5,2.27],[3.9,6.9]],"id":40717352},{"atb":[[1.92,0],[1.88,22.73],[1.9,110.91]],"id":39931665},{"atb":[[3.25,8.89],[3.15,0]],"id":39267517},{"atl":[[6.4,3.7],[6.2,0],[6,5.25]],"id":39267517}],"con":true,"img":false}]}
{"op":"mcm","clk":"5348827518","pt":1646221029684,"mc":[{"id":"1.195453630","rc":[{"atl":[[2.5,0],[2.58,0]],"id":40717352},{"trd":[[2.58,10.15],[2.5,14.69]],"ltp":2.58,"tv":24.84,"id":40717352}],"con":true,"img":false}]}
{"op":"mcm","clk":"5348827532","pt":1646221029787,"mc":[{"id":"1.195453630","rc":[{"atl":[[2.6,2.4]],"id":40717352}],"con":true,"img":false}]}
{"op":"mcm","clk":"5348827545","pt":1646221029890,"mc":[{"id":"1.195453630","rc":[{"atl":[[2.6,0]],"id":40717352}],"con":true,"img":false}]}
{"op":"mcm","clk":"5348827558","pt":1646221029998,"mc":[{"id":"1.195453630","rc":[{"atl":[[3.75,5.2]],"id":40717352}],"con":true,"img":false}]}
{"op":"mcm","clk":"5348827598","pt":1646221030270,"mc":[{"id":"1.195453630","rc":[{"atl":[[10.5,2.11]],"id":41946970},{"atl":[[8.6,0]],"id":39267517}],"con":true,"img":false}]}
{"op":"mcm","clk":"5348827607","pt":1646221030373,"mc":[{"id":"1.195453630","rc":[{"atl":[[8.6,5.9]],"id":41946970},{"atl":[[6.4,10.96]],"id":39267517}],"con":true,"img":false}]}
{"op":"mcm","clk":"5348827641","pt":1646221030683,"mc":[{"id":"1.195453630","rc":[{"atb":[[1.75,24.49]],"id":40717352}],"con":true,"img":false}]}
{"op":"mcm","clk":"5348827654","pt":1646221030782,"mc":[{"id":"1.195453630","rc":[{"atb":[[1.81,22.68]],"id":40717352},{"atl":[[2.64,0],[2.62,0],[2.66,0],[2.68,0]],"id":40717352},{"atb":[[1.91,21.98]],"id":39931665},{"atl":[[6,9.25]],"id":39267517},{"atb":[[2.32,0],[2.34,0],[2.36,0],[2.38,0]],"id":37406513},{"atl":[[4.3,16.62],[4.7,23.24]],"id":37406513},{"atb":[[1.09,222.22]],"id":39860456}],"con":true,"img":false}]}
{"op":"mcm","clk":"5348827669","pt":1646221030886,"mc":[{"id":"1.195453630","rc":[{"atl":[[2.92,0],[2.9,6.31],[2.96,0],[2.94,14.5]],"id":39931665},{"atb":[[3.85,0],[4,0],[3.95,0],[3.9,0]],"id":39267517},{"atl":[[2.04,0],[2.08,0],[2.02,0],[2.06,0]],"id":39860456}],"con":true,"img":false}]}
{"op":"mcm","clk":"5348827680","pt":1646221030987,"mc":[{"id":"1.195453630","rc":[{"atl":[[3.75,10.45],[3.7,3.86]],"id":40717352}],"con":true,"img":false}]}
{"op":"mcm","clk":"5348827695","pt":1646221031093,"mc":[{"id":"1.195453630","rc":[{"atl":[[3.2,84.94],[2.94,0]],"id":39931665},{"atb":[[3.45,70.47]],"id":39267517},{"atl":[[3.25,70.92],[2.78,22.39]],"id":39860456}],"con":true,"img":false}]}
{"op":"mcm","clk":"5348827710","pt":1646221031165,"mc":[{"id":"1.195453630","rc":[{"atb":[[4.1,1.66]],"id":39267517},{"atb":[[1.01,0]],"id":39860456}],"con":true,"img":false}]}
{"op":"mcm","clk":"5348827722","pt":1646221031268,"mc":[{"id":"1.195453630","rc":[{"atb":[[2.34,8.12]],"id":40717352},{"atb":[[3.6,1.58]],"id":39267517},{"atb":[[1.74,3.93]],"id":39860456}],"con":true,"img":false}]}
{"op":"mcm","clk":"5348827753","pt":1646221031414,"mc":[{"id":"1.195453630","rc":[{"atb":[[3.6,0],[3.45,40.21]],"id":41946970},{"atb":[[2.86,53.76],[3.55,17.8]],"id":39267517}],"con":true,"img":false}]}
{"op":"mcm","clk":"5348827786","pt":1646221031477,"mc":[{"id":"1.195453630","rc":[{"atb":[[2,7.5]],"id":39931665},{"atb":[[2.98,88.29]],"id":39267517}],"con":true,"img":false}]}
{"op":"mcm","clk":"5348827838","pt":1646221031583,"mc":[{"id":"1.195453630","rc":[{"atl":[[3.8,0],[1000,1.66],[4,0]],"id":40717352}],"con":true,"img":false}]}
{"op":"mcm","clk":"5348827850","pt":1646221031679,"mc":[{"id":"1.195453630","rc":[{"atl":[[3.85,14.53]],"id":40717352}],"con":true,"img":false}]}
{"op":"mcm","clk":"5348827864","pt":1646221031785,"mc":[{"id":"1.195453630","rc":[{"atl":[[1000,1.43]],"id":40717352}],"con":true,"img":false}]}
{"op":"mcm","clk":"5348827895","pt":1646221031996,"mc":[{"id":"1.195453630","rc":[{"atl":[[1000,0]],"id":40717352}],"con":true,"img":false}]}
{"op":"mcm","clk":"5348827909","pt":1646221032059,"mc":[{"id":"1.195453630","rc":[{"atl":[[3.6,1.43]],"id":40717352}],"con":true,"img":false}]}
{"op":"mcm","clk":"5348827918","pt":1646221032166,"mc":[{"id":"1.195453630","rc":[{"atb":[[1.85,0]],"id":40717352}],"con":true,"img":false}]}
{"op":"mcm","clk":"5348827937","pt":1646221032276,"mc":[{"id":"1.195453630","rc":[{"atb":[[2.36,1.41]],"id":40717352}],"con":true,"img":false}]}
{"op":"mcm","clk":"5348827991","pt":1646221032673,"mc":[{"id":"1.195453630","rc":[{"atb":[[3.8,12.97]],"id":41946970}],"con":true,"img":false}]}
{"op":"mcm","clk":"5348828012","pt":1646221032884,"mc":[{"id":"1.195453630","rc":[{"atb":[[2.34,5.6],[1.81,0]],"id":40717352},{"atl":[[2.68,3]],"id":40717352},{"atb":[[1.91,0]],"id":39931665},{"atl":[[2.96,3]],"id":39931665},{"atb":[[3.85,4]],"id":39267517},{"atl":[[6,5.25]],"id":39267517},{"atb":[[2.32,2]],"id":37406513},{"atl":[[4.3,10.56],[4.7,28.65]],"id":37406513},{"atb":[[1.09,0]],"id":39860456},{"atl":[[2.08,3]],"id":39860456}],"con":true,"img":false}]}
{"op":"mcm","clk":"5348828035","pt":1646221033083,"mc":[{"id":"1.195453630","rc":[{"atl":[[2.66,4]],"id":40717352},{"atl":[[2.94,4]],"id":39931665},{"atb":[[3.9,2]],"id":39267517},{"atb":[[2.34,2]],"id":37406513},{"atl":[[2.06,3],[3.25,25.34]],"id":39860456}],"con":true,"img":false}]}
{"op":"mcm","clk":"5348828048","pt":1646221033189,"mc":[{"id":"1.195453630","rc":[{"atb":[[3.75,2.5]],"id":41946970}],"con":true,"img":false}]}
{"op":"mcm","clk":"5348828061","pt":1646221033294,"mc":[{"id":"1.195453630","rc":[{"atb":[[3.85,1.49]],"id":41946970}],"con":true,"img":false}]}
{"op":"mcm","clk":"5348828165","pt":1646221034085,"mc":[{"id":"1.195453630","rc":[{"atb":[[2.36,0]],"id":40717352},{"atb":[[1.74,2.5]],"id":39860456}],"con":true,"img":false}]}
{"op":"mcm","clk":"5348828179","pt":1646221034191,"mc":[{"id":"1.195453630","rc":[{"atb":[[1.01,1.41]],"id":40717352},{"atb":[[1.01,1.43]],"id":39860456}],"con":true,"img":false}]}
{"op":"mcm","clk":"5348828196","pt":1646221034297,"mc":[{"id":"1.195453630","rc":[{"atl":[[2.72,2]],"id":40717352},{"atb":[[3.65,11.94]],"id":41946970},{"atl":[[2.92,3]],"id":39931665},{"atb":[[3.95,3]],"id":39267517},{"atb":[[2.36,3]],"id":37406513},{"atl":[[2.04,4]],"id":39860456}],"con":true,"img":false}]}
{"op":"mcm","clk":"5348828218","pt":1646221034468,"mc":[{"id":"1.195453630","rc":[{"atl":[[3.75,5.25]],"id":40717352},{"atb":[[3.45,40.74]],"id":39267517}],"con":true,"img":false}]}
{"op":"mcm","clk":"5348828239","pt":1646221034679,"mc":[{"id":"1.195453630","rc":[{"atl":[[2.7,3]],"id":40717352},{"atl":[[2.9,9.31]],"id":39931665},{"atb":[[4,2]],"id":39267517},{"atb":[[2.38,3]],"id":37406513},{"atl":[[2.02,2]],"id":39860456}],"con":true,"img":false}]}
{"op":"mcm","clk":"5348828252","pt":1646221034775,"mc":[{"id":"1.195453630","rc":[{"atb":[[1.01,3.93]],"id":40717352}],"con":true,"img":false}]}
{"op":"mcm","clk":"5348828276","pt":1646221034981,"mc":[{"id":"1.195453630","rc":[{"atb":[[1.01,3.51]],"id":40717352}],"con":true,"img":false}]}
