{"op":"mcm","clk":"5345985315","pt":1646174444272,"mc":[{"id":"1.195453626","marketDefinition":{"bspMarket":true,"turnInPlayEnabled":false,"persistenceEnabled":false,"marketBaseRate":7.0,"eventId":"31272494","eventTypeId":"4339","numberOfWinners":2,"bettingType":"ODDS","marketType":"PLACE","marketTime":"2022-03-02T11:12:00.000Z","suspendTime":"2022-03-02T11:12:00.000Z","bspReconciled":false,"complete":true,"inPlay":false,"crossMatching":false,"runnersVoidable":false,"numberOfActiveRunners":7,"betDelay":0,"status":"OPEN","runners":[{"status":"ACTIVE","sortPriority":1,"id":42099020,"name":"1. Charlize"},{"status":"ACTIVE","sortPriority":2,"id":40559875,"name":"2. Hot Shaynna"},{"status":"ACTIVE","sortPriority":3,"id":38981227,"name":"3. Mac Rooster"},{"status":"ACTIVE","sortPriority":4,"id":36592903,"name":"4. Why Not Opal"},{"status":"ACTIVE","sortPriority":5,"id":37429121,"name":"6. Papi Go Fast"},{"status":"ACTIVE","sortPriority":6,"id":39360156,"name":"7. Beans Multi"},{"status":"ACTIVE","sortPriority":7,"id":36986045,"name":"8. Throw Caution"}],"regulators":["MR_INT"],"venue":"Traralgon","countryCode":"AU","discountAllowed":true,"timezone":"Australia/Sydney","openDate":"2022-03-02T08:31:00.000Z","version":4382425397,"name":"To Be Placed","eventName":"Traralgon (AUS) 2nd Mar"},"rc":[],"con":true,"img":false}]}
{"op":"mcm","clk":"5346059623","pt":1646175788371,"mc":[{"id":"1.195453626","rc":[{"atb":[[2.06,94.05],[2.26,79.12],[2.16,85.94]],"id":38981227},{"atl":[[5.6,7.88],[7.2,11.69],[9.2,8.84]],"id":38981227},{"spn":3.93,"spf":"NaN","id":38981227},{"atb":[[2.5,66.46],[2.6,62.31],[2.7,58.64]],"id":36986045},{"atl":[[8.6,9.54],[11.5,6.9],[6.6,6.47]],"id":36986045},{"spn":4.65,"spf":"NaN","id":36986045},{"atb":[[1.8,124.62],[1.85,117.29],[1.75,132.93]],"id":36592903},{"atl":[[4.5,20.71],[5.5,16.11],[3.75,13.18]],"id":36592903},{"spn":2.8,"spf":"NaN","id":36592903},{"atb":[[1.2,498.5],[1.25,398.8],[1.15,664.67]],"id":37429121},{"atl":[[2.44,25.17],[2.64,44.21],[2.84,39.4]],"id":37429121},{"spn":1.84,"spf":"NaN","id":37429121},{"atb":[[2.88,53.03],[2.98,50.35],[2.78,56]],"id":42099020},{"atl":[[10.5,7.63],[8.2,5.03],[15.5,5]],"id":42099020},{"spn":5.59,"spf":"NaN","id":42099020},{"atb":[[2.4,71.21],[2.3,76.69],[2.2,83.08]],"id":40559875},{"atl":[[9.6,8.43],[5.8,7.55],[7.6,10.98]],"id":40559875},{"spn":4.1,"spf":"NaN","id":40559875},{"atb":[[4.5,28.48],[5,24.92],[5.5,22.15]],"id":39360156},{"atl":[[18.5,2.07],[44,1.68],[27,2.78]],"id":39360156},{"spn":12.0,"spf":"NaN","id":39360156}],"con":true,"img":false}]}
{"op":"mcm","clk":"5346061998","pt":1646175839944,"mc":[{"id":"1.195453626","rc":[{"atb":[[2.06,0],[2.26,0],[2.16,0]],"id":38981227},{"atl":[[5.6,0],[7.2,0],[9.2,0]],"id":38981227},{"atb":[[2.5,0],[2.6,0],[2.7,0]],"id":36986045},{"atl":[[8.6,0],[11.5,0],[6.6,0]],"id":36986045},{"atb":[[1.8,0],[1.85,0],[1.75,0]],"id":36592903},{"atl":[[4.5,0],[5.5,0],[3.75,0]],"id":36592903},{"atb":[[1.2,0],[1.25,0],[1.15,0]],"id":37429121},{"atl":[[2.44,0],[2.64,0],[2.84,0]],"id":37429121},{"atb":[[2.88,0],[2.98,0],[2.78,0]],"id":42099020},{"atl":[[10.5,0],[8.2,0],[15.5,0]],"id":42099020},{"atb":[[2.4,0],[2.3,0],[2.2,0]],"id":40559875},{"atl":[[9.6,0],[5.8,0],[7.6,0]],"id":40559875},{"atb":[[4.5,0],[5,0],[5.5,0]],"id":39360156},{"atl":[[18.5,0],[44,0],[27,0]],"id":39360156}],"con":true,"img":false}]}
{"op":"mcm","clk":"5346062228","pt":1646175844782,"mc":[{"id":"1.195453626","rc":[{"atb":[[2.06,94.05],[2.26,79.12],[2.16,85.94]],"id":38981227},{"atl":[[5.6,7.88],[7.2,11.69],[9.2,8.84]],"id":38981227},{"atb":[[2.5,66.46],[2.6,62.31],[2.7,58.64]],"id":36986045},{"atl":[[8.6,9.54],[11.5,6.9],[6.6,6.47]],"id":36986045},{"atb":[[1.8,124.62],[1.85,117.29],[1.75,132.93]],"id":36592903},{"atl":[[4.5,20.71],[5.5,16.11],[3.75,13.18]],"id":36592903},{"atb":[[1.2,498.5],[1.25,398.8],[1.15,664.67]],"id":37429121},{"atl":[[2.44,25.17],[2.64,44.21],[2.84,39.4]],"id":37429121},{"atb":[[2.88,53.03],[2.98,50.35],[2.78,56]],"id":42099020},{"atl":[[10.5,7.63],[8.2,5.03],[15.5,5]],"id":42099020},{"atb":[[2.4,71.21],[2.3,76.69],[2.2,83.08]],"id":40559875},{"atl":[[9.6,8.43],[5.8,7.55],[7.6,10.98]],"id":40559875},{"atb":[[4.5,28.48],[5,24.92],[5.5,22.15]],"id":39360156},{"atl":[[18.5,2.07],[44,1.68],[27,2.78]],"id":39360156}],"con":true,"img":false}]}
{"op":"mcm","clk":"5346105172","pt":1646176602702,"mc":[{"id":"1.195453626","marketDefinition":{"bspMarket":true,"turnInPlayEnabled":false,"persistenceEnabled":false,"marketBaseRate":7.0,"eventId":"31272494","eventTypeId":"4339","numberOfWinners":2,"bettingType":"ODDS","marketType":"PLACE","marketTime":"2022-03-02T11:12:00.000Z","suspendTime":"2022-03-02T11:12:00.000Z","bspReconciled":false,"complete":true,"inPlay":false,"crossMatching":false,"runnersVoidable":false,"numberOfActiveRunners":7,"betDelay":0,"status":"OPEN","runners":[{"status":"ACTIVE","sortPriority":1,"id":42099020,"name":"1. Charlize"},{"status":"ACTIVE","sortPriority":2,"id":40559875,"name":"2. Hot Shaynna"},{"status":"ACTIVE","sortPriority":3,"id":38981227,"name":"3. Mac Rooster"},{"status":"ACTIVE","sortPriority":4,"id":36592903,"name":"4. Why Not Opal"},{"status":"ACTIVE","sortPriority":5,"id":37429121,"name":"6. Papi Go Fast"},{"status":"ACTIVE","sortPriority":6,"id":39360156,"name":"7. Beans Multi"},{"status":"ACTIVE","sortPriority":7,"id":36986045,"name":"8. Throw Caution"}],"regulators":["MR_INT"],"venue":"Traralgon","countryCode":"AU","discountAllowed":true,"timezone":"Australia/Sydney","openDate":"2022-03-02T08:31:00.000Z","version":4382425397,"name":"To Be Placed","eventName":"Traralgon (AUS) 2nd Mar"},"rc":[{"atb":[[2.06,94.05],[2.26,79.12],[2.16,85.94]],"id":38981227},{"atl":[[5.6,7.88],[7.2,11.69],[9.2,8.84]],"id":38981227},{"spn":3.93,"spf":"NaN","id":38981227},{"atb":[[2.5,66.46],[2.6,62.31],[2.7,58.64]],"id":36986045},{"atl":[[8.6,9.54],[11.5,6.9],[6.6,6.47]],"id":36986045},{"spn":4.65,"spf":"NaN","id":36986045},{"atb":[[1.8,124.62],[1.85,117.29],[1.75,132.93]],"id":36592903},{"atl":[[4.5,20.71],[5.5,16.11],[3.75,13.18]],"id":36592903},{"spn":2.8,"spf":"NaN","id":36592903},{"atb":[[1.2,498.5],[1.25,398.8],[1.15,664.67]],"id":37429121},{"atl":[[2.44,25.17],[2.64,44.21],[2.84,39.4]],"id":37429121},{"spn":1.84,"spf":"NaN","id":37429121},{"atb":[[2.88,53.03],[2.98,50.35],[2.78,56]],"id":42099020},{"atl":[[10.5,7.63],[8.2,5.03],[15.5,5]],"id":42099020},{"spn":5.59,"spf":"NaN","id":42099020},{"atb":[[2.4,71.21],[2.3,76.69],[2.2,83.08]],"id":40559875},{"atl":[[9.6,8.43],[5.8,7.55],[7.6,10.98]],"id":40559875},{"spn":4.1,"spf":"NaN","id":40559875},{"atb":[[4.5,28.48],[5,24.92],[5.5,22.15]],"id":39360156},{"atl":[[18.5,2.07],[44,1.68],[27,2.78]],"id":39360156},{"spn":12.0,"spf":"NaN","id":39360156}],"con":true,"img":true}]}
{"op":"mcm","clk":"5346285833","pt":1646180120965,"mc":[{"id":"1.195453626","rc":[{"atb":[[2.06,94.06],[2.26,79.13],[2.16,85.95]],"id":38981227},{"atl":[[5.6,7.88],[7.2,11.69],[9.2,8.84]],"id":38981227},{"atb":[[2.5,66.47],[2.6,62.32],[2.7,58.65]],"id":36986045},{"atl":[[8.6,9.54],[11.5,6.9],[6.6,6.47]],"id":36986045},{"atb":[[1.8,124.64],[1.85,117.3],[1.75,132.94]],"id":36592903},{"spl":[[1.01,2.72]],"id":36592903},{"atl":[[4.5,20.72],[5.5,16.11],[3.75,13.18]],"id":36592903},{"spn":1.85,"spf":1.0,"id":36592903},{"atb":[[1.2,498.55],[1.25,398.84],[1.15,664.74]],"id":37429121},{"atl":[[2.44,25.17],[2.64,44.21],[2.84,39.41]],"id":37429121},{"atb":[[2.88,53.03],[2.98,50.35],[2.78,56.01]],"id":42099020},{"atl":[[10.5,7.63],[8.2,5.03],[15.5,5]],"id":42099020},{"atb":[[2.4,71.22],[2.3,76.69],[2.2,83.09]],"id":40559875},{"atl":[[9.6,8.43],[5.8,7.55],[7.6,10.98]],"id":40559875},{"atb":[[4.5,28.48],[5,24.92],[5.5,22.15]],"id":39360156},{"atl":[[18.5,2.07],[44,1.68],[27,2.78]],"id":39360156}],"con":true,"img":false}]}
{"op":"mcm","clk":"5346767984","pt":1646187402734,"mc":[{"id":"1.195453626","marketDefinition":{"bspMarket":true,"turnInPlayEnabled":false,"persistenceEnabled":false,"marketBaseRate":7.0,"eventId":"31272494","eventTypeId":"4339","numberOfWinners":2,"bettingType":"ODDS","marketType":"PLACE","marketTime":"2022-03-02T11:12:00.000Z","suspendTime":"2022-03-02T11:12:00.000Z","bspReconciled":false,"complete":true,"inPlay":false,"crossMatching":false,"runnersVoidable":false,"numberOfActiveRunners":7,"betDelay":0,"status":"OPEN","runners":[{"status":"ACTIVE","sortPriority":1,"id":42099020,"name":"1. Charlize"},{"status":"ACTIVE","sortPriority":2,"id":40559875,"name":"2. Hot Shaynna"},{"status":"ACTIVE","sortPriority":3,"id":38981227,"name":"3. Mac Rooster"},{"status":"ACTIVE","sortPriority":4,"id":36592903,"name":"4. Why Not Opal"},{"status":"ACTIVE","sortPriority":5,"id":37429121,"name":"6. Papi Go Fast"},{"status":"ACTIVE","sortPriority":6,"id":39360156,"name":"7. Beans Multi"},{"status":"ACTIVE","sortPriority":7,"id":36986045,"name":"8. Throw Caution"}],"regulators":["MR_INT"],"venue":"Traralgon","countryCode":"AU","discountAllowed":true,"timezone":"Australia/Sydney","openDate":"2022-03-02T08:31:00.000Z","version":4382425397,"name":"To Be Placed","eventName":"Traralgon (AUS) 2nd Mar"},"rc":[{"atb":[[2.06,94.21],[2.26,79.26],[2.16,86.09]],"id":38981227},{"atl":[[5.6,7.89],[7.2,11.71],[9.2,8.85]],"id":38981227},{"spn":3.93,"spf":"NaN","id":38981227},{"atb":[[2.5,66.57],[2.6,62.41],[2.7,58.74]],"id":36986045},{"atl":[[8.6,9.55],[11.5,6.91],[6.6,6.48]],"id":36986045},{"spn":4.65,"spf":"NaN","id":36986045},{"atb":[[1.8,124.83],[1.85,117.49],[1.75,133.15]],"id":36592903},{"spl":[[1.01,2.72]],"id":36592903},{"atl":[[4.5,20.75],[5.5,16.14],[3.75,13.2]],"id":36592903},{"spn":1.85,"spf":1.0,"id":36592903},{"atb":[[1.2,499.34],[1.25,399.47],[1.15,665.79]],"id":37429121},{"atl":[[2.44,25.21],[2.64,44.28],[2.84,39.47]],"id":37429121},{"spn":1.84,"spf":"NaN","id":37429121},{"atb":[[2.88,53.12],[2.98,50.43],[2.78,56.1]],"id":42099020},{"atl":[[10.5,7.64],[8.2,5.04],[15.5,5.01]],"id":42099020},{"spn":5.59,"spf":"NaN","id":42099020},{"atb":[[2.4,71.33],[2.3,76.81],[2.2,83.22]],"id":40559875},{"atl":[[9.6,8.44],[5.8,7.56],[7.6,11]],"id":40559875},{"spn":4.1,"spf":"NaN","id":40559875},{"atb":[[4.5,28.53],[5,24.96],[5.5,22.19]],"id":39360156},{"atl":[[18.5,2.07],[44,1.69],[27,2.79]],"id":39360156},{"spn":12.0,"spf":"NaN","id":39360156}],"con":true,"img":true}]}
{"op":"mcm","clk":"5347092535","pt":1646192802713,"mc":[{"id":"1.195453626","marketDefinition":{"bspMarket":true,"turnInPlayEnabled":false,"persistenceEnabled":false,"marketBaseRate":7.0,"eventId":"31272494","eventTypeId":"4339","numberOfWinners":2,"bettingType":"ODDS","marketType":"PLACE","marketTime":"2022-03-02T11:12:00.000Z","suspendTime":"2022-03-02T11:12:00.000Z","bspReconciled":false,"complete":true,"inPlay":false,"crossMatching":false,"runnersVoidable":false,"numberOfActiveRunners":7,"betDelay":0,"status":"OPEN","runners":[{"status":"ACTIVE","sortPriority":1,"id":42099020,"name":"1. Charlize"},{"status":"ACTIVE","sortPriority":2,"id":40559875,"name":"2. Hot Shaynna"},{"status":"ACTIVE","sortPriority":3,"id":38981227,"name":"3. Mac Rooster"},{"status":"ACTIVE","sortPriority":4,"id":36592903,"name":"4. Why Not Opal"},{"status":"ACTIVE","sortPriority":5,"id":37429121,"name":"6. Papi Go Fast"},{"status":"ACTIVE","sortPriority":6,"id":39360156,"name":"7. Beans Multi"},{"status":"ACTIVE","sortPriority":7,"id":36986045,"name":"8. Throw Caution"}],"regulators":["MR_INT"],"venue":"Traralgon","countryCode":"AU","discountAllowed":true,"timezone":"Australia/Sydney","openDate":"2022-03-02T08:31:00.000Z","version":4382425397,"name":"To Be Placed","eventName":"Traralgon (AUS) 2nd Mar"},"rc":[{"atb":[[2.06,94.37],[2.26,79.39],[2.16,86.24]],"id":38981227},{"atl":[[5.6,7.9],[7.2,11.73],[9.2,8.87]],"id":38981227},{"spn":3.93,"spf":"NaN","id":38981227},{"atb":[[2.5,66.69],[2.6,62.52],[2.7,58.84]],"id":36986045},{"atl":[[8.6,9.57],[11.5,6.93],[6.6,6.49]],"id":36986045},{"spn":4.65,"spf":"NaN","id":36986045},{"atb":[[1.8,125.04],[1.85,117.69],[1.75,133.38]],"id":36592903},{"spl":[[1.01,2.73]],"id":36592903},{"atl":[[4.5,20.78],[5.5,16.16],[3.75,13.22]],"id":36592903},{"spn":1.85,"spf":1.0,"id":36592903},{"atb":[[1.2,500.19],[1.25,400.15],[1.15,666.92]],"id":37429121},{"atl":[[2.44,25.26],[2.64,44.36],[2.84,39.54]],"id":37429121},{"spn":1.84,"spf":"NaN","id":37429121},{"atb":[[2.88,53.21],[2.98,50.52],[2.78,56.19]],"id":42099020},{"atl":[[10.5,7.65],[8.2,5.05],[15.5,5.01]],"id":42099020},{"spn":5.59,"spf":"NaN","id":42099020},{"atb":[[2.4,71.45],[2.3,76.94],[2.2,83.36]],"id":40559875},{"atl":[[9.6,8.46],[5.8,7.58],[7.6,11.02]],"id":40559875},{"spn":4.1,"spf":"NaN","id":40559875},{"atb":[[4.5,28.58],[5,25.01],[5.5,22.23]],"id":39360156},{"atl":[[18.5,2.08],[44,1.69],[27,2.79]],"id":39360156},{"spn":12.0,"spf":"NaN","id":39360156}],"con":true,"img":true}]}
{"op":"mcm","clk":"5347381391","pt":1646198202731,"mc":[{"id":"1.195453626","marketDefinition":{"bspMarket":true,"turnInPlayEnabled":false,"persistenceEnabled":false,"marketBaseRate":7.0,"eventId":"31272494","eventTypeId":"4339","numberOfWinners":2,"bettingType":"ODDS","marketType":"PLACE","marketTime":"2022-03-02T11:12:00.000Z","suspendTime":"2022-03-02T11:12:00.000Z","bspReconciled":false,"complete":true,"inPlay":false,"crossMatching":false,"runnersVoidable":false,"numberOfActiveRunners":7,"betDelay":0,"status":"OPEN","runners":[{"status":"ACTIVE","sortPriority":1,"id":42099020,"name":"1. Charlize"},{"status":"ACTIVE","sortPriority":2,"id":40559875,"name":"2. Hot Shaynna"},{"status":"ACTIVE","sortPriority":3,"id":38981227,"name":"3. Mac Rooster"},{"status":"ACTIVE","sortPriority":4,"id":36592903,"name":"4. Why Not Opal"},{"status":"ACTIVE","sortPriority":5,"id":37429121,"name":"6. Papi Go Fast"},{"status":"ACTIVE","sortPriority":6,"id":39360156,"name":"7. Beans Multi"},{"status":"ACTIVE","sortPriority":7,"id":36986045,"name":"8. Throw Caution"}],"regulators":["MR_INT"],"venue":"Traralgon","countryCode":"AU","discountAllowed":true,"timezone":"Australia/Sydney","openDate":"2022-03-02T08:31:00.000Z","version":4382425397,"name":"To Be Placed","eventName":"Traralgon (AUS) 2nd Mar"},"rc":[{"atb":[[2.06,94.33],[2.26,79.36],[2.16,86.2]],"id":38981227},{"atl":[[5.6,7.9],[7.2,11.72],[9.2,8.86]],"id":38981227},{"spn":3.93,"spf":"NaN","id":38981227},{"atb":[[2.5,66.66],[2.6,62.5],[2.7,58.82]],"id":36986045},{"atl":[[8.6,9.57],[11.5,6.92],[6.6,6.49]],"id":36986045},{"spn":4.65,"spf":"NaN","id":36986045},{"atb":[[1.8,125],[1.85,117.64],[1.75,133.33]],"id":36592903},{"spl":[[1.01,2.73]],"id":36592903},{"atl":[[4.5,20.78],[5.5,16.16],[3.75,13.22]],"id":36592903},{"spn":1.85,"spf":1.0,"id":36592903},{"atb":[[1.2,500],[1.25,400],[1.15,666.66]],"id":37429121},{"atl":[[2.44,25.25],[2.64,44.34],[2.84,39.52]],"id":37429121},{"spn":1.84,"spf":"NaN","id":37429121},{"atb":[[2.88,53.19],[2.98,50.5],[2.78,56.17]],"id":42099020},{"atl":[[10.5,7.65],[8.2,5.05],[15.5,5.01]],"id":42099020},{"spn":5.59,"spf":"NaN","id":42099020},{"atb":[[2.4,71.42],[2.3,76.92],[2.2,83.33]],"id":40559875},{"atl":[[9.6,8.45],[5.8,7.57],[7.6,11.01]],"id":40559875},{"spn":4.1,"spf":"NaN","id":40559875},{"atb":[[4.5,28.57],[5,25],[5.5,22.22]],"id":39360156},{"atl":[[18.5,2.08],[44,1.69],[27,2.79]],"id":39360156},{"spn":12.0,"spf":"NaN","id":39360156}],"con":true,"img":true}]}
{"op":"mcm","clk":"5347572813","pt":1646202475324,"mc":[{"id":"1.195453626","rc":[{"atb":[[2.06,0],[2.26,0],[2.16,0]],"id":38981227},{"atl":[[5.6,0],[7.2,0],[9.2,0]],"id":38981227},{"spn":"NaN","spf":"NaN","id":38981227},{"atb":[[2.5,0],[2.6,0],[2.7,0]],"id":36986045},{"atl":[[8.6,0],[11.5,0],[6.6,0]],"id":36986045},{"spn":"NaN","spf":"NaN","id":36986045},{"atb":[[1.8,125],[1.85,117.64],[1.75,133.33]],"id":36592903},{"spl":[[1.01,2.73]],"id":36592903},{"atl":[[4.5,20.78],[5.5,16.16],[3.75,13.22]],"id":36592903},{"atb":[[1.2,500],[1.25,400],[1.15,666.66]],"id":37429121},{"atl":[[2.44,25.25],[2.64,44.34],[2.84,39.52]],"id":37429121},{"atb":[[2.88,0],[2.98,0],[2.78,0]],"id":42099020},{"atl":[[10.5,0],[8.2,0],[15.5,0]],"id":42099020},{"spn":"NaN","spf":"NaN","id":42099020},{"atb":[[2.4,71.42],[2.3,76.92],[2.2,83.33]],"id":40559875},{"atl":[[9.6,8.45],[5.8,7.57],[7.6,11.01]],"id":40559875},{"atb":[[4.5,0],[5,0],[5.5,0]],"id":39360156},{"atl":[[18.5,0],[44,0],[27,0]],"id":39360156},{"spn":"NaN","spf":"NaN","id":39360156}],"con":true,"img":false}]}
{"op":"mcm","clk":"5347573695","pt":1646202497536,"mc":[{"id":"1.195453626","rc":[{"atb":[[2.4,71.42],[2.5,66.66],[2.3,76.92]],"id":38981227},{"atl":[[8,10.39],[10,8.08],[6,7.27]],"id":38981227},{"atb":[[2.86,53.76],[3.15,46.51],[2.96,51.01]],"id":36986045},{"atl":[[16,4.84],[11,7.27],[8.4,4.91]],"id":36986045},{"atb":[[2.88,53.19],[2.98,50.5],[2.78,56.17]],"id":42099020},{"atl":[[10.5,7.65],[8.2,5.05],[15.5,5.01]],"id":42099020},{"atb":[[4.5,28.57],[5,25],[5.5,22.22]],"id":39360156},{"atl":[[18.5,2.08],[44,1.69],[27,2.79]],"id":39360156}],"con":true,"img":false}]}
{"op":"mcm","clk":"5347624537","pt":1646203602734,"mc":[{"id":"1.195453626","marketDefinition":{"bspMarket":true,"turnInPlayEnabled":false,"persistenceEnabled":false,"marketBaseRate":7.0,"eventId":"31272494","eventTypeId":"4339","numberOfWinners":2,"bettingType":"ODDS","marketType":"PLACE","marketTime":"2022-03-02T11:12:00.000Z","suspendTime":"2022-03-02T11:12:00.000Z","bspReconciled":false,"complete":true,"inPlay":false,"crossMatching":false,"runnersVoidable":false,"numberOfActiveRunners":7,"betDelay":0,"status":"OPEN","runners":[{"status":"ACTIVE","sortPriority":1,"id":42099020,"name":"1. Charlize"},{"status":"ACTIVE","sortPriority":2,"id":40559875,"name":"2. Hot Shaynna"},{"status":"ACTIVE","sortPriority":3,"id":38981227,"name":"3. Mac Rooster"},{"status":"ACTIVE","sortPriority":4,"id":36592903,"name":"4. Why Not Opal"},{"status":"ACTIVE","sortPriority":5,"id":37429121,"name":"6. Papi Go Fast"},{"status":"ACTIVE","sortPriority":6,"id":39360156,"name":"7. Beans Multi"},{"status":"ACTIVE","sortPriority":7,"id":36986045,"name":"8. Throw Caution"}],"regulators":["MR_INT"],"venue":"Traralgon","countryCode":"AU","discountAllowed":true,"timezone":"Australia/Sydney","openDate":"2022-03-02T08:31:00.000Z","version":4382425397,"name":"To Be Placed","eventName":"Traralgon (AUS) 2nd Mar"},"rc":[{"atb":[[2.4,71.42],[2.5,66.66],[2.3,76.92]],"id":38981227},{"atl":[[8,10.39],[10,8.08],[6,7.27]],"id":38981227},{"spn":4.25,"spf":"NaN","id":38981227},{"atb":[[2.86,53.76],[3.15,46.51],[2.96,51.01]],"id":36986045},{"atl":[[16,4.84],[11,7.27],[8.4,4.91]],"id":36986045},{"spn":5.77,"spf":"NaN","id":36986045},{"atb":[[1.8,125],[1.85,117.64],[1.75,133.33]],"id":36592903},{"spl":[[1.01,2.73]],"id":36592903},{"atl":[[4.5,20.78],[5.5,16.16],[3.75,13.22]],"id":36592903},{"spn":1.85,"spf":1.0,"id":36592903},{"atb":[[1.2,500],[1.25,400],[1.15,666.66]],"id":37429121},{"atl":[[2.44,25.25],[2.64,44.34],[2.84,39.52]],"id":37429121},{"spn":1.84,"spf":"NaN","id":37429121},{"atb":[[2.88,53.19],[2.98,50.5],[2.78,56.17]],"id":42099020},{"atl":[[10.5,7.65],[8.2,5.05],[15.5,5.01]],"id":42099020},{"spn":5.59,"spf":"NaN","id":42099020},{"atb":[[2.4,71.42],[2.3,76.92],[2.2,83.33]],"id":40559875},{"atl":[[9.6,8.45],[5.8,7.57],[7.6,11.01]],"id":40559875},{"spn":4.1,"spf":"NaN","id":40559875},{"atb":[[4.5,28.57],[5,25],[5.5,22.22]],"id":39360156},{"atl":[[18.5,2.08],[44,1.69],[27,2.79]],"id":39360156},{"spn":12.0,"spf":"NaN","id":39360156}],"con":true,"img":true}]}
{"op":"mcm","clk":"5347849088","pt":1646209002735,"mc":[{"id":"1.195453626","marketDefinition":{"bspMarket":true,"turnInPlayEnabled":false,"persistenceEnabled":false,"marketBaseRate":7.0,"eventId":"31272494","eventTypeId":"4339","numberOfWinners":2,"bettingType":"ODDS","marketType":"PLACE","marketTime":"2022-03-02T11:12:00.000Z","suspendTime":"2022-03-02T11:12:00.000Z","bspReconciled":false,"complete":true,"inPlay":false,"crossMatching":false,"runnersVoidable":false,"numberOfActiveRunners":7,"betDelay":0,"status":"OPEN","runners":[{"status":"ACTIVE","sortPriority":1,"id":42099020,"name":"1. Charlize"},{"status":"ACTIVE","sortPriority":2,"id":40559875,"name":"2. Hot Shaynna"},{"status":"ACTIVE","sortPriority":3,"id":38981227,"name":"3. Mac Rooster"},{"status":"ACTIVE","sortPriority":4,"id":36592903,"name":"4. Why Not Opal"},{"status":"ACTIVE","sortPriority":5,"id":37429121,"name":"6. Papi Go Fast"},{"status":"ACTIVE","sortPriority":6,"id":39360156,"name":"7. Beans Multi"},{"status":"ACTIVE","sortPriority":7,"id":36986045,"name":"8. Throw Caution"}],"regulators":["MR_INT"],"venue":"Traralgon","countryCode":"AU","discountAllowed":true,"timezone":"Australia/Sydney","openDate":"2022-03-02T08:31:00.000Z","version":4382425397,"name":"To Be Placed","eventName":"Traralgon (AUS) 2nd Mar"},"rc":[{"atb":[[2.4,71.4],[2.5,66.64],[2.3,76.89]],"id":38981227},{"atl":[[8,10.38],[10,8.07],[6,7.27]],"id":38981227},{"spn":4.25,"spf":"NaN","id":38981227},{"atb":[[2.86,53.75],[3.15,46.5],[2.96,51]],"id":36986045},{"atl":[[16,4.84],[11,7.27],[8.4,4.91]],"id":36986045},{"spn":5.77,"spf":"NaN","id":36986045},{"atb":[[1.8,124.96],[1.85,117.61],[1.75,133.29]],"id":36592903},{"spl":[[1.01,2.72]],"id":36592903},{"atl":[[4.5,20.77],[5.5,16.15],[3.75,13.22]],"id":36592903},{"spn":1.85,"spf":1.0,"id":36592903},{"atb":[[1.2,499.86],[1.25,399.89],[1.15,666.48]],"id":37429121},{"atl":[[2.44,25.24],[2.64,44.33],[2.84,39.51]],"id":37429121},{"spn":1.84,"spf":"NaN","id":37429121},{"atb":[[2.88,53.17],[2.98,50.49],[2.78,56.16]],"id":42099020},{"atl":[[10.5,7.65],[8.2,5.04],[15.5,5.01]],"id":42099020},{"spn":5.59,"spf":"NaN","id":42099020},{"atb":[[2.4,71.4],[2.3,76.89],[2.2,83.31]],"id":40559875},{"atl":[[9.6,8.45],[5.8,7.57],[7.6,11.01]],"id":40559875},{"spn":4.1,"spf":"NaN","id":40559875},{"atb":[[4.5,28.56],[5,24.99],[5.5,22.21]],"id":39360156},{"atl":[[18.5,2.07],[44,1.69],[27,2.79]],"id":39360156},{"spn":12.0,"spf":"NaN","id":39360156}],"con":true,"img":true}]}
{"op":"mcm","clk":"5348113557","pt":1646214208820,"mc":[{"id":"1.195453626","rc":[{"atb":[[2.4,71.29],[1.82,53.16],[2.5,66.54],[2.3,76.77],[1.66,89.79]],"id":38981227},{"atl":[[8,10.37],[10,8.06],[6,7.25],[7.8,15.12]],"id":38981227},{"spn":4.25,"spf":"NaN","id":38981227},{"atb":[[3.2,19.81],[2.88,33.04],[2.86,53.66],[3.15,46.42],[2.96,50.92]],"id":36986045},{"atl":[[16,4.83],[11,7.25],[8.4,4.9],[14.5,3.23],[15.5,4.28]],"id":36986045},{"spn":5.8,"spf":"NaN","id":36986045},{"atb":[[1.8,124.76],[1.85,117.42],[1.86,50.69],[1.75,133.08],[1.76,86.1]],"id":36592903},{"spl":[[1.01,2.72]],"id":36592903},{"atl":[[4.5,20.74],[6.4,11.98],[5.5,16.13],[4.4,12.82],[3.75,13.19]],"id":36592903},{"spn":1.86,"spf":1.0,"id":36592903},{"atb":[[1.2,499.07],[1.25,399.25],[1.15,665.43],[1.21,266.65],[1.23,189.56]],"id":37429121},{"atl":[[2.44,55.48],[2.64,44.26],[2.84,39.45],[2.62,34.56]],"id":37429121},{"atb":[[3.45,17.79],[2.88,53.09],[3,28.47],[2.98,50.41],[2.78,56.07]],"id":42099020},{"atl":[[16.5,2.81],[19,3],[10.5,7.64],[8.2,5.04],[15.5,5]],"id":42099020},{"spn":5.82,"spf":"NaN","id":42099020},{"atb":[[2.4,71.29],[2.3,76.77],[2.42,30.7],[2.22,53.95],[2.2,83.18]],"id":40559875},{"atl":[[9.6,8.44],[5.8,7.56],[9.2,5.31],[7.6,10.99],[9.4,7.62]],"id":40559875},{"spn":4.11,"spf":"NaN","id":40559875},{"atb":[[9.6,5.06],[8,7.94],[4.5,28.51],[5,24.95],[5.5,22.18]],"id":39360156},{"atl":[[18.5,2.07],[75,2.72],[80,2.72],[44,1.68],[27,2.79]],"id":39360156},{"spn":14.05,"spf":"NaN","id":39360156}],"con":true,"img":false}]}
{"op":"mcm","clk":"5348119072","pt":1646214294587,"mc":[{"id":"1.195453626","rc":[{"atb":[[2.88,0]],"id":36986045},{"atl":[[2.44,25.2],[2.62,0]],"id":37429121}],"con":true,"img":false}]}
{"op":"mcm","clk":"5348119077","pt":1646214294694,"mc":[{"id":"1.195453626","rc":[{"atb":[[2.98,33.04]],"id":36986045},{"atl":[[2.42,64.84]],"id":37429121}],"con":true,"img":false}]}
{"op":"mcm","clk":"5348133271","pt":1646214402746,"mc":[{"id":"1.195453626","marketDefinition":{"bspMarket":true,"turnInPlayEnabled":false,"persistenceEnabled":false,"marketBaseRate":7.0,"eventId":"31272494","eventTypeId":"4339","numberOfWinners":2,"bettingType":"ODDS","marketType":"PLACE","marketTime":"2022-03-02T11:12:00.000Z","suspendTime":"2022-03-02T11:12:00.000Z","bspReconciled":false,"complete":true,"inPlay":false,"crossMatching":false,"runnersVoidable":false,"numberOfActiveRunners":7,"betDelay":0,"status":"OPEN","runners":[{"status":"ACTIVE","sortPriority":1,"id":42099020,"name":"1. Charlize"},{"status":"ACTIVE","sortPriority":2,"id":40559875,"name":"2. Hot Shaynna"},{"status":"ACTIVE","sortPriority":3,"id":38981227,"name":"3. Mac Rooster"},{"status":"ACTIVE","sortPriority":4,"id":36592903,"name":"4. Why Not Opal"},{"status":"ACTIVE","sortPriority":5,"id":37429121,"name":"6. Papi Go Fast"},{"status":"ACTIVE","sortPriority":6,"id":39360156,"name":"7. Beans Multi"},{"status":"ACTIVE","sortPriority":7,"id":36986045,"name":"8. Throw Caution"}],"regulators":["MR_INT"],"venue":"Traralgon","countryCode":"AU","discountAllowed":true,"timezone":"Australia/Sydney","openDate":"2022-03-02T08:31:00.000Z","version":4382425397,"name":"To Be Placed","eventName":"Traralgon (AUS) 2nd Mar"},"rc":[{"atb":[[2.4,71.29],[1.82,53.16],[2.5,66.54],[2.3,76.77],[1.66,89.79]],"id":38981227},{"atl":[[8,10.37],[10,8.06],[6,7.25],[7.8,15.12]],"id":38981227},{"spn":4.25,"spf":"NaN","id":38981227},{"atb":[[3.2,19.81],[2.86,53.66],[3.15,46.42],[2.98,33.04],[2.96,50.92]],"id":36986045},{"atl":[[16,4.83],[11,7.25],[8.4,4.9],[14.5,3.23],[15.5,4.28]],"id":36986045},{"spn":5.8,"spf":"NaN","id":36986045},{"atb":[[1.8,124.76],[1.85,117.42],[1.86,50.69],[1.75,133.08],[1.76,86.1]],"id":36592903},{"spl":[[1.01,2.72]],"id":36592903},{"atl":[[4.5,20.74],[6.4,11.98],[5.5,16.13],[4.4,12.82],[3.75,13.19]],"id":36592903},{"spn":1.86,"spf":1.0,"id":36592903},{"atb":[[1.2,499.07],[1.25,399.25],[1.15,665.43],[1.21,266.65],[1.23,189.56]],"id":37429121},{"atl":[[2.42,64.84],[2.44,25.2],[2.64,44.26],[2.84,39.45]],"id":37429121},{"spn":1.83,"spf":"NaN","id":37429121},{"atb":[[3.45,17.79],[2.88,53.09],[3,28.47],[2.98,50.41],[2.78,56.07]],"id":42099020},{"atl":[[16.5,2.81],[19,3],[10.5,7.64],[8.2,5.04],[15.5,5]],"id":42099020},{"spn":5.82,"spf":"NaN","id":42099020},{"atb":[[2.4,71.29],[2.3,76.77],[2.42,30.7],[2.22,53.95],[2.2,83.18]],"id":40559875},{"atl":[[9.6,8.44],[5.8,7.56],[9.2,5.31],[7.6,10.99],[9.4,7.62]],"id":40559875},{"spn":4.11,"spf":"NaN","id":40559875},{"atb":[[9.6,5.06],[8,7.94],[4.5,28.51],[5,24.95],[5.5,22.18]],"id":39360156},{"atl":[[18.5,2.07],[75,2.72],[80,2.72],[44,1.68],[27,2.79]],"id":39360156},{"spn":14.05,"spf":"NaN","id":39360156}],"con":true,"img":true}]}
{"op":"mcm","clk":"5348177122","pt":1646215015787,"mc":[{"id":"1.195453626","rc":[{"atl":[[2.8,45]],"id":36592903},{"spn":1.83,"spf":"NaN","id":37429121}],"con":true,"img":false}]}
{"op":"mcm","clk":"5348177615","pt":1646215022778,"mc":[{"id":"1.195453626","rc":[{"atl":[[2.42,30.27]],"id":37429121}],"con":true,"img":false}]}
{"op":"mcm","clk":"5348177626","pt":1646215022937,"mc":[{"id":"1.195453626","rc":[{"atl":[[2.62,34.56]],"id":37429121}],"con":true,"img":false}]}
{"op":"mcm","clk":"5348250998","pt":1646215939734,"mc":[{"id":"1.195453626","rc":[{"atb":[[1.44,142.6]],"id":38981227},{"atl":[[11,10]],"id":38981227},{"atb":[[2.44,69.44]],"id":36986045},{"atl":[[9.6,9.8]],"id":36986045},{"atb":[[1.45,222.22]],"id":36592903},{"atl":[[12.5,8.7]],"id":36592903},{"atl":[[3.8,35.71]],"id":37429121},{"atb":[[3.5,28.47]],"id":42099020},{"atl":[[23,4.55]],"id":42099020},{"spn":5.85,"spf":"NaN","id":42099020},{"atb":[[2,100]],"id":40559875},{"atl":[[5.7,7.56]],"id":40559875},{"spn":4.06,"spf":"NaN","id":40559875},{"atb":[[3.45,40.82]],"id":39360156},{"atl":[[38,2.7]],"id":39360156}],"con":true,"img":false}]}
{"op":"mcm","clk":"5348252297","pt":1646215953024,"mc":[{"id":"1.195453626","marketDefinition":{"bspMarket":true,"turnInPlayEnabled":false,"persistenceEnabled":false,"marketBaseRate":7.0,"eventId":"31272494","eventTypeId":"4339","numberOfWinners":2,"bettingType":"ODDS","marketType":"PLACE","marketTime":"2022-03-02T11:12:00.000Z","suspendTime":"2022-03-02T11:12:00.000Z","bspReconciled":false,"complete":true,"inPlay":false,"crossMatching":true,"runnersVoidable":false,"numberOfActiveRunners":7,"betDelay":0,"status":"OPEN","runners":[{"status":"ACTIVE","sortPriority":1,"id":42099020,"name":"1. Charlize"},{"status":"ACTIVE","sortPriority":2,"id":40559875,"name":"2. Hot Shaynna"},{"status":"ACTIVE","sortPriority":3,"id":38981227,"name":"3. Mac Rooster"},{"status":"ACTIVE","sortPriority":4,"id":36592903,"name":"4. Why Not Opal"},{"status":"ACTIVE","sortPriority":5,"id":37429121,"name":"6. Papi Go Fast"},{"status":"ACTIVE","sortPriority":6,"id":39360156,"name":"7. Beans Multi"},{"status":"ACTIVE","sortPriority":7,"id":36986045,"name":"8. Throw Caution"}],"regulators":["MR_INT"],"venue":"Traralgon","countryCode":"AU","discountAllowed":true,"timezone":"Australia/Sydney","openDate":"2022-03-02T08:31:00.000Z","version":4382425397,"name":"To Be Placed","eventName":"Traralgon (AUS) 2nd Mar"},"rc":[],"con":true,"img":false}]}
{"op":"mcm","clk":"5348252329","pt":1646215953236,"mc":[{"id":"1.195453626","rc":[{"atb":[[3.35,42.55],[3.5,0]],"id":42099020}],"con":true,"img":false}]}
{"op":"mcm","clk":"5348252438","pt":1646215954432,"mc":[{"id":"1.195453626","rc":[{"atl":[[7.8,6.4]],"id":38981227},{"atb":[[2.98,0]],"id":36986045},{"atb":[[1.76,0]],"id":36592903},{"atl":[[2.42,0]],"id":37429121},{"atb":[[3.45,0]],"id":42099020},{"atl":[[9.2,0],[9.4,0]],"id":40559875},{"atb":[[9.6,0],[8,0]],"id":39360156}],"con":true,"img":false}]}
{"op":"mcm","clk":"5348252447","pt":1646215954536,"mc":[{"id":"1.195453626","rc":[{"atl":[[2.62,64.84]],"id":37429121},{"atb":[[3.4,17.79]],"id":42099020}],"con":true,"img":false}]}
{"op":"mcm","clk":"5348254416","pt":1646215974681,"mc":[{"id":"1.195453626","rc":[{"atl":[[10.5,4.58],[14.5,0]],"id":36986045}],"con":true,"img":false}]}
{"op":"mcm","clk":"5348254426","pt":1646215974789,"mc":[{"id":"1.195453626","rc":[{"atl":[[16.5,0]],"id":42099020},{"atl":[[75,0]],"id":39360156}],"con":true,"img":false}]}
{"op":"mcm","clk":"5348254437","pt":1646215974909,"mc":[{"id":"1.195453626","rc":[{"atl":[[14,2.81]],"id":42099020},{"atl":[[36,2.72]],"id":39360156}],"con":true,"img":false}]}
{"op":"mcm","clk":"5348254590","pt":1646215976669,"mc":[{"id":"1.195453626","rc":[{"atb":[[1.44,0],[1.62,142.6]],"id":38981227},{"atb":[[3.45,0],[3.7,37.04]],"id":39360156},{"atl":[[38,0],[28,3.7]],"id":39360156}],"con":true,"img":false}]}
{"op":"mcm","clk":"5348254601","pt":1646215976796,"mc":[{"id":"1.195453626","rc":[{"atl":[[2.62,30.27]],"id":37429121}],"con":true,"img":false}]}
{"op":"mcm","clk":"5348254617","pt":1646215976889,"mc":[{"id":"1.195453626","rc":[{"atl":[[2.82,34.56]],"id":37429121}],"con":true,"img":false}]}
{"op":"mcm","clk":"5348256163","pt":1646215990007,"mc":[{"id":"1.195453626","rc":[{"atl":[[7.8,15.12]],"id":38981227},{"atb":[[2.46,42.55]],"id":36986045},{"atb":[[1.5,142.24]],"id":36592903},{"atl":[[12.5,3.79],[13.5,5.44]],"id":40559875},{"atb":[[5.5,34.53],[6.6,7.78]],"id":39360156}],"con":true,"img":false}]}
{"op":"mcm","clk":"5348256953","pt":1646215999203,"mc":[{"id":"1.195453626","rc":[{"atl":[[7.8,6.4]],"id":38981227},{"atl":[[15.5,0]],"id":36986045},{"atl":[[6.4,0]],"id":36592903},{"atb":[[1.23,0]],"id":37429121},{"atl":[[19,0]],"id":42099020}],"con":true,"img":false}]}
{"op":"mcm","clk":"5348256964","pt":1646215999310,"mc":[{"id":"1.195453626","rc":[{"atb":[[1.82,0]],"id":38981227},{"atl":[[9.4,6.73]],"id":38981227},{"atl":[[10.5,11.12]],"id":36986045},{"atl":[[4.4,31.89]],"id":36592903},{"atb":[[1.32,85.42]],"id":37429121},{"atl":[[15,3.86]],"id":42099020},{"atl":[[80,0]],"id":39360156}],"con":true,"img":false}]}
{"op":"mcm","clk":"5348256978","pt":1646215999424,"mc":[{"id":"1.195453626","rc":[{"atb":[[1.88,53.16]],"id":38981227},{"atb":[[5.5,22.18]],"id":39360156},{"atl":[[36,5.44]],"id":39360156}],"con":true,"img":false}]}
{"op":"mcm","clk":"5348256986","pt":1646215999519,"mc":[{"id":"1.195453626","rc":[{"atb":[[5.1,12.35]],"id":39360156}],"con":true,"img":false}]}
{"op":"mcm","clk":"5348259506","pt":1646216022535,"mc":[{"id":"1.195453626","rc":[{"spn":1.88,"spf":"NaN","id":37429121},{"spn":5.8,"spf":"NaN","id":42099020},{"atl":[[36,2.72]],"id":39360156},{"spn":12.55,"spf":"NaN","id":39360156}],"con":true,"img":false}]}
{"op":"mcm","clk":"5348259515","pt":1646216022637,"mc":[{"id":"1.195453626","rc":[{"atl":[[30,2.72]],"id":39360156}],"con":true,"img":false}]}
{"op":"mcm","clk":"5348260953","pt":1646216036553,"mc":[{"id":"1.195453626","rc":[{"atb":[[1.26,215.37]],"id":37429121},{"atb":[[6.6,0]],"id":39360156}],"con":true,"img":false}]}
{"op":"mcm","clk":"5348260966","pt":1646216036646,"mc":[{"id":"1.195453626","rc":[{"atb":[[1.21,0]],"id":37429121},{"atb":[[5.9,7.78]],"id":39360156}],"con":true,"img":false}]}
{"op":"mcm","clk":"5348263909","pt":1646216065268,"mc":[{"id":"1.195453626","rc":[{"atl":[[7.8,15.12]],"id":38981227}],"con":true,"img":false}]}
{"op":"mcm","clk":"5348265217","pt":1646216072330,"mc":[{"id":"1.195453626","rc":[{"atl":[[10.5,6.53]],"id":36986045},{"atl":[[4.4,19.07]],"id":36592903},{"atb":[[5.1,0]],"id":39360156},{"atl":[[30,0]],"id":39360156}],"con":true,"img":false}]}
{"op":"mcm","clk":"5348265233","pt":1646216072434,"mc":[{"id":"1.195453626","rc":[{"atl":[[9.4,0]],"id":38981227},{"atl":[[9.4,4.58]],"id":36986045},{"atl":[[4.1,12.82]],"id":36592903},{"atb":[[5.6,12.35]],"id":39360156},{"atl":[[27,5.51]],"id":39360156}],"con":true,"img":false}]}
{"op":"mcm","clk":"5348272982","pt":1646216105078,"mc":[{"id":"1.195453626","rc":[{"atl":[[27,2.79]],"id":39360156},{"spn":12.2,"spf":"NaN","id":39360156}],"con":true,"img":false}]}
{"op":"mcm","clk":"5348273039","pt":1646216105322,"mc":[{"id":"1.195453626","rc":[{"atl":[[26,2.72]],"id":39360156}],"con":true,"img":false}]}
{"op":"mcm","clk":"5348294827","pt":1646216240112,"mc":[{"id":"1.195453626","rc":[{"atl":[[13.5,0]],"id":40559875}],"con":true,"img":false}]}
{"op":"mcm","clk":"5348294842","pt":1646216240216,"mc":[{"id":"1.195453626","rc":[{"atl":[[14.5,5.44]],"id":40559875}],"con":true,"img":false}]}
{"op":"mcm","clk":"5348352254","pt":1646216771574,"mc":[{"id":"1.195453626","rc":[{"atl":[[2.8,62.06]],"id":36592903}],"con":true,"img":false}]}
{"op":"mcm","clk":"5348353988","pt":1646216789777,"mc":[{"id":"1.195453626","rc":[{"atl":[[26,0]],"id":39360156}],"con":true,"img":false}]}
{"op":"mcm","clk":"5348353997","pt":1646216789880,"mc":[{"id":"1.195453626","rc":[{"atl":[[27,5.51]],"id":39360156}],"con":true,"img":false}]}
{"op":"mcm","clk":"5348358721","pt":1646216837939,"mc":[{"id":"1.195453626","rc":[{"atb":[[2.52,1.66]],"id":38981227},{"spn":4.26,"spf":"NaN","id":38981227},{"atb":[[3.25,1.66]],"id":36986045},{"spn":5.82,"spf":"NaN","id":36986045},{"atb":[[3.45,1.66]],"id":42099020},{"spn":5.82,"spf":"NaN","id":42099020},{"atb":[[2.44,1.66]],"id":40559875},{"spn":4.07,"spf":"NaN","id":40559875},{"atb":[[6,1.66]],"id":39360156},{"spn":12.25,"spf":"NaN","id":39360156}],"con":true,"img":false}]}
{"op":"mcm","clk":"5348361308","pt":1646216866286,"mc":[{"id":"1.195453626","rc":[{"atb":[[2.56,4.81]],"id":38981227},{"atb":[[3.2,23.23]],"id":36986045},{"atb":[[1.9,8.35]],"id":36592903},{"atb":[[1.35,21.48]],"id":37429121},{"atb":[[3.45,4.73]],"id":42099020},{"atb":[[2.48,5.08]],"id":40559875}],"con":true,"img":false}]}
{"op":"mcm","clk":"5348361982","pt":1646216873885,"mc":[{"id":"1.195453626","rc":[{"atb":[[2.52,0]],"id":38981227},{"atb":[[2.44,0]],"id":40559875}],"con":true,"img":false}]}
{"op":"mcm","clk":"5348362004","pt":1646216874096,"mc":[{"id":"1.195453626","rc":[{"atb":[[2.58,1.66]],"id":38981227},{"atb":[[2.5,1.66]],"id":40559875}],"con":true,"img":false}]}
{"op":"mcm","clk":"5348366591","pt":1646216925952,"mc":[{"id":"1.195453626","rc":[{"spn":4.29,"spf":"NaN","id":38981227},{"spn":1.9,"spf":1.0,"id":36592903},{"spn":1.89,"spf":"NaN","id":37429121},{"atb":[[2.46,5.71]],"id":40559875},{"spn":4.1,"spf":"NaN","id":40559875}],"con":true,"img":false}]}
{"op":"mcm","clk":"5348366611","pt":1646216926160,"mc":[{"id":"1.195453626","rc":[{"atb":[[3.45,8.13]],"id":42099020}],"con":true,"img":false}]}
{"op":"mcm","clk":"5348366620","pt":1646216926266,"mc":[{"id":"1.195453626","rc":[{"atb":[[2.56,10.16]],"id":38981227}],"con":true,"img":false}]}
{"op":"mcm","clk":"5348366639","pt":1646216926474,"mc":[{"id":"1.195453626","rc":[{"atb":[[1.9,17.61]],"id":36592903}],"con":true,"img":false}]}
{"op":"mcm","clk":"5348366704","pt":1646216927158,"mc":[{"id":"1.195453626","rc":[{"atb":[[1.35,45.29]],"id":37429121}],"con":true,"img":false}]}
{"op":"mcm","clk":"5348366825","pt":1646216928493,"mc":[{"id":"1.195453626","rc":[{"atb":[[3.2,27.02]],"id":36986045}],"con":true,"img":false}]}
{"op":"mcm","clk":"5348367108","pt":1646216931659,"mc":[{"id":"1.195453626","rc":[{"atb":[[3.2,23.6]],"id":36986045}],"con":true,"img":false}]}
{"op":"mcm","clk":"5348367724","pt":1646216937965,"mc":[{"id":"1.195453626","rc":[{"atb":[[3.25,5]],"id":36986045}],"con":true,"img":false}]}
{"op":"mcm","clk":"5348370386","pt":1646216969124,"mc":[{"id":"1.195453626","rc":[{"atb":[[1.32,0]],"id":37429121}],"con":true,"img":false}]}
{"op":"mcm","clk":"5348370391","pt":1646216969227,"mc":[{"id":"1.195453626","rc":[{"atb":[[1.36,85.42]],"id":37429121}],"con":true,"img":false}]}
{"op":"mcm","clk":"5348370563","pt":1646216970807,"mc":[{"id":"1.195453626","rc":[{"atb":[[1.35,23.81]],"id":37429121}],"con":true,"img":false}]}
{"op":"mcm","clk":"5348371121","pt":1646216977016,"mc":[{"id":"1.195453626","rc":[{"atb":[[1.39,19.27]],"id":37429121}],"con":true,"img":false}]}
{"op":"mcm","clk":"5348371219","pt":1646216978055,"mc":[{"id":"1.195453626","rc":[{"atb":[[1.36,0]],"id":37429121}],"con":true,"img":false}]}
{"op":"mcm","clk":"5348371231","pt":1646216978109,"mc":[{"id":"1.195453626","rc":[{"atb":[[1.31,85.42]],"id":37429121}],"con":true,"img":false}]}
{"op":"mcm","clk":"5348371479","pt":1646216980736,"mc":[{"id":"1.195453626","rc":[{"atb":[[1.39,0]],"id":37429121}],"con":true,"img":false}]}
{"op":"mcm","clk":"5348371908","pt":1646216985754,"mc":[{"id":"1.195453626","rc":[{"atb":[[1.34,22.11]],"id":37429121}],"con":true,"img":false}]}
{"op":"mcm","clk":"5348372927","pt":1646216997694,"mc":[{"id":"1.195453626","rc":[{"atl":[[11,0],[8.8,12.82]],"id":38981227},{"atb":[[2.72,58.14],[2.44,0]],"id":36986045},{"atl":[[9.6,0],[10.5,16.33]],"id":36986045},{"atb":[[3.35,0],[3.5,17.79]],"id":42099020},{"spn":5.85,"spf":"NaN","id":42099020},{"atb":[[2,0],[1.73,107.9]],"id":40559875},{"atb":[[4.3,30.3],[3.7,0]],"id":39360156}],"con":true,"img":false}]}
{"op":"mcm","clk":"5348372963","pt":1646216998062,"mc":[{"id":"1.195453626","rc":[{"atb":[[1.35,0]],"id":37429121}],"con":true,"img":false}]}
{"op":"mcm","clk":"5348373194","pt":1646217000763,"mc":[{"id":"1.195453626","rc":[{"atb":[[3.45,5.06]],"id":42099020}],"con":true,"img":false}]}
{"op":"mcm","clk":"5348373303","pt":1646217002104,"mc":[{"id":"1.195453626","rc":[{"atb":[[3.45,3.4]],"id":42099020}],"con":true,"img":false}]}
{"op":"mcm","clk":"5348373322","pt":1646217002271,"mc":[{"id":"1.195453626","rc":[{"atb":[[3.55,1.66]],"id":42099020}],"con":true,"img":false}]}
{"op":"mcm","clk":"5348373787","pt":1646217006880,"mc":[{"id":"1.195453626","rc":[{"atb":[[3.05,3.66]],"id":42099020}],"con":true,"img":false}]}
{"op":"mcm","clk":"5348374361","pt":1646217012589,"mc":[{"id":"1.195453626","rc":[{"atb":[[1.34,46.62]],"id":37429121}],"con":true,"img":false}]}
{"op":"mcm","clk":"5348374809","pt":1646217018100,"mc":[{"id":"1.195453626","rc":[{"atl":[[9.4,0]],"id":36986045}],"con":true,"img":false}]}
{"op":"mcm","clk":"5348374816","pt":1646217018211,"mc":[{"id":"1.195453626","rc":[{"atl":[[10,4.58]],"id":36986045}],"con":true,"img":false}]}
{"op":"mcm","clk":"5348375371","pt":1646217024110,"mc":[{"id":"1.195453626","rc":[{"atb":[[1.73,0],[1.95,105.26]],"id":40559875}],"con":true,"img":false}]}
{"op":"mcm","clk":"5348375970","pt":1646217030515,"mc":[{"id":"1.195453626","rc":[{"atl":[[27,2.79]],"id":39360156}],"con":true,"img":false}]}
{"op":"mcm","clk":"5348375979","pt":1646217030619,"mc":[{"id":"1.195453626","rc":[{"atl":[[26,2.72]],"id":39360156}],"con":true,"img":false}]}
{"op":"mcm","clk":"5348376274","pt":1646217033721,"mc":[{"id":"1.195453626","rc":[{"atb":[[3.45,0]],"id":42099020}],"con":true,"img":false}]}
{"op":"mcm","clk":"5348376479","pt":1646217035924,"mc":[{"id":"1.195453626","rc":[{"atb":[[3.4,0]],"id":42099020}],"con":true,"img":false}]}
{"op":"mcm","clk":"5348376487","pt":1646217036026,"mc":[{"id":"1.195453626","rc":[{"atb":[[3.55,19.46]],"id":42099020}],"con":true,"img":false}]}
{"op":"mcm","clk":"5348376505","pt":1646217036236,"mc":[{"id":"1.195453626","rc":[{"atb":[[3.6,17.79],[3.5,0]],"id":42099020}],"con":true,"img":false}]}
{"op":"mcm","clk":"5348376943","pt":1646217041017,"mc":[{"id":"1.195453626","rc":[{"atb":[[3.55,17.79]],"id":42099020}],"con":true,"img":false}]}
{"op":"mcm","clk":"5348376959","pt":1646217041233,"mc":[{"id":"1.195453626","rc":[{"atb":[[3.65,1.66]],"id":42099020}],"con":true,"img":false}]}
{"op":"mcm","clk":"5348377539","pt":1646217047419,"mc":[{"id":"1.195453626","rc":[{"atb":[[1.31,0]],"id":37429121}],"con":true,"img":false}]}
{"op":"mcm","clk":"5348377553","pt":1646217047522,"mc":[{"id":"1.195453626","rc":[{"atb":[[1.35,85.42]],"id":37429121}],"con":true,"img":false}]}
{"op":"mcm","clk":"5348377701","pt":1646217048930,"mc":[{"id":"1.195453626","rc":[{"atb":[[1.34,24.51]],"id":37429121}],"con":true,"img":false}]}
{"op":"mcm","clk":"5348377793","pt":1646217049823,"mc":[{"id":"1.195453626","rc":[{"atb":[[3.05,7.73]],"id":42099020}],"con":true,"img":false}]}
{"op":"mcm","clk":"5348378295","pt":1646217054870,"mc":[{"id":"1.195453626","rc":[{"atb":[[1.38,19.78]],"id":37429121}],"con":true,"img":false}]}
{"op":"mcm","clk":"5348379230","pt":1646217064657,"mc":[{"id":"1.195453626","rc":[{"atb":[[1.34,0]],"id":37429121},{"spn":1.91,"spf":"NaN","id":37429121},{"spn":5.92,"spf":"NaN","id":42099020}],"con":true,"img":false}]}
{"op":"mcm","clk":"5348379904","pt":1646217071862,"mc":[{"id":"1.195453626","rc":[{"atb":[[3.55,0]],"id":42099020}],"con":true,"img":false}]}
{"op":"mcm","clk":"5348379918","pt":1646217071967,"mc":[{"id":"1.195453626","rc":[{"atb":[[3.65,19.46]],"id":42099020}],"con":true,"img":false}]}
{"op":"mcm","clk":"5348379939","pt":1646217072169,"mc":[{"id":"1.195453626","rc":[{"atb":[[3.6,0],[3.65,37.25]],"id":42099020}],"con":true,"img":false}]}
{"op":"mcm","clk":"5348380021","pt":1646217073059,"mc":[{"id":"1.195453626","rc":[{"atb":[[3.05,4.06]],"id":42099020}],"con":true,"img":false}]}
{"op":"mcm","clk":"5348380496","pt":1646217078878,"mc":[{"id":"1.195453626","rc":[{"atb":[[3.75,2.73]],"id":42099020}],"con":true,"img":false}]}
{"op":"mcm","clk":"5348380504","pt":1646217078975,"mc":[{"id":"1.195453626","rc":[{"atb":[[1.38,41.73]],"id":37429121}],"con":true,"img":false}]}
{"op":"mcm","clk":"5348380600","pt":1646217080083,"mc":[{"id":"1.195453626","rc":[{"atb":[[3.65,35.58]],"id":42099020}],"con":true,"img":false}]}
{"op":"mcm","clk":"5348380621","pt":1646217080286,"mc":[{"id":"1.195453626","rc":[{"atb":[[3.8,1.66]],"id":42099020}],"con":true,"img":false}]}
{"op":"mcm","clk":"5348381499","pt":1646217089678,"mc":[{"id":"1.195453626","rc":[{"atb":[[3.05,0]],"id":42099020}],"con":true,"img":false}]}
{"op":"mcm","clk":"5348381815","pt":1646217093096,"mc":[{"id":"1.195453626","rc":[{"atl":[[10.5,10.53],[8.8,0]],"id":38981227},{"atb":[[2.56,64.1]],"id":36986045},{"atl":[[9.6,9.8]],"id":36986045},{"atb":[[3.6,38.46],[3.65,17.79]],"id":42099020},{"atb":[[1.81,107.9],[1.95,0]],"id":40559875}],"con":true,"img":false}]}
{"op":"mcm","clk":"5348381824","pt":1646217093197,"mc":[{"id":"1.195453626","rc":[{"atb":[[2.72,0]],"id":36986045},{"atl":[[10.5,6.53]],"id":36986045}],"con":true,"img":false}]}
{"op":"mcm","clk":"5348382167","pt":1646217097003,"mc":[{"id":"1.195453626","rc":[{"atb":[[3.75,0]],"id":42099020}],"con":true,"img":false}]}
{"op":"mcm","clk":"5348382556","pt":1646217101512,"mc":[{"id":"1.195453626","rc":[{"atl":[[26,0]],"id":39360156}],"con":true,"img":false}]}
{"op":"mcm","clk":"5348382565","pt":1646217101609,"mc":[{"id":"1.195453626","rc":[{"atl":[[27,5.51]],"id":39360156}],"con":true,"img":false}]}
{"op":"mcm","clk":"5348382693","pt":1646217103014,"mc":[{"id":"1.195453626","rc":[{"atb":[[3.7,2.78]],"id":42099020}],"con":true,"img":false}]}
{"op":"mcm","clk":"5348383147","pt":1646217108026,"mc":[{"id":"1.195453626","rc":[{"atb":[[3.8,0]],"id":42099020}],"con":true,"img":false}]}
{"op":"mcm","clk":"5348383170","pt":1646217108190,"mc":[{"id":"1.195453626","rc":[{"atb":[[3.75,1.66]],"id":42099020}],"con":true,"img":false}]}
{"op":"mcm","clk":"5348383831","pt":1646217116218,"mc":[{"id":"1.195453626","rc":[{"atb":[[3.7,5.86]],"id":42099020}],"con":true,"img":false}]}
{"op":"mcm","clk":"5348384046","pt":1646217118525,"mc":[{"id":"1.195453626","rc":[{"atl":[[9.6,0],[9,9.8]],"id":36986045},{"atb":[[1.81,0],[2.08,92.59]],"id":40559875}],"con":true,"img":false}]}
{"op":"mcm","clk":"5348384225","pt":1646217120196,"mc":[{"id":"1.195453626","rc":[{"atl":[[10,0]],"id":36986045}],"con":true,"img":false}]}
{"op":"mcm","clk":"5348384234","pt":1646217120298,"mc":[{"id":"1.195453626","rc":[{"atl":[[9.4,4.58]],"id":36986045}],"con":true,"img":false}]}
{"op":"mcm","clk":"5348386594","pt":1646217147473,"mc":[{"id":"1.195453626","rc":[{"atb":[[2.46,0]],"id":36986045},{"atl":[[9.4,0]],"id":36986045},{"spn":5.97,"spf":"NaN","id":42099020}],"con":true,"img":false}]}
{"op":"mcm","clk":"5348386602","pt":1646217147576,"mc":[{"id":"1.195453626","rc":[{"atb":[[2.58,42.55]],"id":36986045},{"atl":[[8.8,4.58]],"id":36986045}],"con":true,"img":false}]}
{"op":"mcm","clk":"5348392292","pt":1646217213134,"mc":[{"id":"1.195453626","rc":[{"atb":[[2.56,0],[2.44,69.44]],"id":36986045},{"atl":[[9.6,9.8],[9,0]],"id":36986045},{"atb":[[3.6,0],[3.35,42.55]],"id":42099020},{"atb":[[4.3,0],[3.7,37.04]],"id":39360156}],"con":true,"img":false}]}
{"op":"mcm","clk":"5348392390","pt":1646217214333,"mc":[{"id":"1.195453626","rc":[{"atb":[[3.7,3.08]],"id":42099020}],"con":true,"img":false}]}
{"op":"mcm","clk":"5348392732","pt":1646217218061,"mc":[{"id":"1.195453626","rc":[{"atb":[[2.58,0]],"id":36986045}],"con":true,"img":false}]}
{"op":"mcm","clk":"5348392744","pt":1646217218168,"mc":[{"id":"1.195453626","rc":[{"atb":[[2.46,42.55]],"id":36986045}],"con":true,"img":false}]}
{"op":"mcm","clk":"5348392956","pt":1646217220416,"mc":[{"id":"1.195453626","rc":[{"atb":[[3.45,3.06]],"id":42099020}],"con":true,"img":false}]}
{"op":"mcm","clk":"5348393670","pt":1646217227836,"mc":[{"id":"1.195453626","rc":[{"atl":[[8.8,0]],"id":36986045},{"atb":[[3.65,0]],"id":42099020}],"con":true,"img":false}]}
{"op":"mcm","clk":"5348393679","pt":1646217227941,"mc":[{"id":"1.195453626","rc":[{"atl":[[9.4,4.58]],"id":36986045},{"atb":[[3.4,17.79]],"id":42099020}],"con":true,"img":false}]}
{"op":"mcm","clk":"5348394583","pt":1646217237968,"mc":[{"id":"1.195453626","rc":[{"atb":[[3.7,0]],"id":42099020}],"con":true,"img":false}]}
{"op":"mcm","clk":"5348395527","pt":1646217248076,"mc":[{"id":"1.195453626","rc":[{"atb":[[3.75,0]],"id":42099020}],"con":true,"img":false}]}
{"op":"mcm","clk":"5348395544","pt":1646217248284,"mc":[{"id":"1.195453626","rc":[{"atb":[[3.5,1.66]],"id":42099020}],"con":true,"img":false}]}
{"op":"mcm","clk":"5348396090","pt":1646217254498,"mc":[{"id":"1.195453626","rc":[{"atb":[[3.45,6.46]],"id":42099020}],"con":true,"img":false}]}
{"op":"mcm","clk":"5348438628","pt":1646217711536,"mc":[{"id":"1.195453626","rc":[{"atb":[[1.62,0],[1.71,119.71]],"id":38981227},{"atl":[[6.2,19.23],[12.5,0]],"id":36592903},{"atb":[[3.35,0],[3.5,8.13]],"id":42099020},{"spn":5.85,"spf":"NaN","id":42099020}],"con":true,"img":false}]}
{"op":"mcm","clk":"5348438838","pt":1646217713849,"mc":[{"id":"1.195453626","rc":[{"atb":[[3.45,3.4]],"id":42099020}],"con":true,"img":false}]}
{"op":"mcm","clk":"5348439404","pt":1646217719842,"mc":[{"id":"1.195453626","rc":[{"atb":[[3.05,3.66]],"id":42099020}],"con":true,"img":false}]}
{"op":"mcm","clk":"5348439704","pt":1646217722774,"mc":[{"id":"1.195453626","rc":[{"atb":[[1.79,63.29],[1.81,24.69],[1.77,97.4],[1.75,166.67]],"id":38981227},{"atl":[[6.2,24.04],[5.5,4.44],[5.7,10.64],[5.9,15.31]],"id":38981227},{"atb":[[3.15,55.72],[2.98,37.88],[2.94,64.43],[3.05,24.39]],"id":36986045},{"atl":[[8.6,2.63],[9,6.25],[9.8,14.2],[9.4,13.51]],"id":36986045},{"atb":[[1.8,281.01],[1.82,91.46],[1.84,59.52],[1.86,73.95]],"id":36592903},{"atl":[[6.2,23.08],[7.4,19.53],[6.6,8.93],[7,12.5]],"id":36592903},{"atb":[[1.01,250],[1.03,250]],"id":37429121},{"atl":[[2.3,15.38],[2.42,88.03],[2.38,54.35],[2.34,37.31]],"id":37429121},{"atb":[[3.2,56.82],[3.4,38.62],[3.5,16.13],[3.3,32.61]],"id":42099020},{"atl":[[11,2],[12,4.55],[13,6.25],[14,12.43]],"id":42099020},{"atb":[[2.32,37.88],[2.36,14.71],[2.24,100.81],[2.28,58.59]],"id":40559875},{"atl":[[4,6.67],[4.6,34.72],[4.4,22.06],[4.2,15.62]],"id":40559875},{"atb":[[6.2,14.42],[7,3.33],[6.6,8.93],[5.9,33.29]],"id":39360156},{"atl":[[32,1.61],[36,4.86],[40,3.21],[29,1]],"id":39360156}],"con":true,"img":false}]}
{"op":"mcm","clk":"5348439732","pt":1646217722937,"mc":[{"id":"1.195453626","rc":[{"atl":[[5,7.56],[5.7,0]],"id":40559875}],"con":true,"img":false}]}
{"op":"mcm","clk":"5348439796","pt":1646217723525,"mc":[{"id":"1.195453626","rc":[{"atl":[[9,6.73],[7.8,6.4]],"id":38981227},{"atl":[[10.5,0]],"id":36986045}],"con":true,"img":false}]}
{"op":"mcm","clk":"5348439802","pt":1646217723632,"mc":[{"id":"1.195453626","rc":[{"atl":[[11.5,6.53]],"id":36986045}],"con":true,"img":false}]}
{"op":"mcm","clk":"5348439970","pt":1646217725586,"mc":[{"id":"1.195453626","rc":[{"atb":[[2.22,0]],"id":40559875},{"atl":[[36,2.14]],"id":39360156}],"con":true,"img":false}]}
{"op":"mcm","clk":"5348439981","pt":1646217725643,"mc":[{"id":"1.195453626","rc":[{"atb":[[2.1,53.95]],"id":40559875},{"atl":[[38,2.72]],"id":39360156}],"con":true,"img":false}]}
{"op":"mcm","clk":"5348439991","pt":1646217725744,"mc":[{"id":"1.195453626","rc":[{"atb":[[3.05,0]],"id":42099020}],"con":true,"img":false}]}
{"op":"mcm","clk":"5348440648","pt":1646217731781,"mc":[{"id":"1.195453626","rc":[{"atb":[[3.5,19.14]],"id":42099020}],"con":true,"img":false}]}
{"op":"mcm","clk":"5348440700","pt":1646217732257,"mc":[{"id":"1.195453626","rc":[{"atb":[[6,0]],"id":39360156}],"con":true,"img":false}]}
{"op":"mcm","clk":"5348440711","pt":1646217732374,"mc":[{"id":"1.195453626","rc":[{"atb":[[7.2,1.66]],"id":39360156}],"con":true,"img":false}]}
{"op":"mcm","clk":"5348441599","pt":1646217740005,"mc":[{"id":"1.195453626","rc":[{"atb":[[3.45,0]],"id":42099020}],"con":true,"img":false}]}
{"op":"mcm","clk":"5348442164","pt":1646217745498,"mc":[{"id":"1.195453626","rc":[{"atl":[[7.8,0]],"id":38981227},{"atl":[[14,9.62]],"id":42099020}],"con":true,"img":false}]}
{"op":"mcm","clk":"5348442176","pt":1646217745600,"mc":[{"id":"1.195453626","rc":[{"atl":[[5.8,9.08]],"id":38981227},{"atl":[[4.1,0]],"id":36592903},{"atl":[[11.5,4.15]],"id":42099020}],"con":true,"img":false}]}
{"op":"mcm","clk":"5348442184","pt":1646217745704,"mc":[{"id":"1.195453626","rc":[{"atl":[[3.75,26.02]],"id":36592903}],"con":true,"img":false}]}
{"op":"mcm","clk":"5348442371","pt":1646217747489,"mc":[{"id":"1.195453626","rc":[{"atl":[[4.3,13.21]],"id":40559875}],"con":true,"img":false}]}
{"op":"mcm","clk":"5348442382","pt":1646217747593,"mc":[{"id":"1.195453626","rc":[{"atl":[[2.62,0]],"id":37429121},{"atl":[[12.5,0]],"id":40559875},{"atb":[[5.9,25.51]],"id":39360156}],"con":true,"img":false}]}
{"op":"mcm","clk":"5348442392","pt":1646217747698,"mc":[{"id":"1.195453626","rc":[{"atl":[[2.32,30.27]],"id":37429121},{"atb":[[8.2,7.78]],"id":39360156}],"con":true,"img":false}]}
{"op":"mcm","clk":"5348442573","pt":1646217749495,"mc":[{"id":"1.195453626","rc":[{"atb":[[1.88,0],[2.52,28.68]],"id":38981227}],"con":true,"img":false}]}
{"op":"mcm","clk":"5348442610","pt":1646217749821,"mc":[{"id":"1.195453626","rc":[{"atl":[[9.2,12.2],[10.5,0]],"id":38981227},{"atb":[[1.92,93.47],[2.44,0]],"id":36986045},{"atl":[[9.6,0],[12,9.09]],"id":36986045},{"atb":[[1.45,0],[1.57,175.44]],"id":36592903},{"atl":[[2.3,0],[3.8,0],[3.3,43.48],[2.08,18.52]],"id":37429121},{"atb":[[3.2,102.27],[3.5,12.67]],"id":42099020},{"atl":[[17.5,6.06],[23,0]],"id":42099020},{"atb":[[2.08,0],[2.24,181.46]],"id":40559875},{"atl":[[4.5,28.57],[5,0]],"id":40559875},{"atb":[[3.7,0],[3.35,28.84]],"id":39360156}],"con":true,"img":false}]}
{"op":"mcm","clk":"5348442806","pt":1646217751591,"mc":[{"id":"1.195453626","rc":[{"atb":[[2.1,0],[1.91,72.48]],"id":40559875}],"con":true,"img":false}]}
{"op":"mcm","clk":"5348442944","pt":1646217753112,"mc":[{"id":"1.195453626","rc":[{"atl":[[5.5,0],[5.4,4.55]],"id":38981227}],"con":true,"img":false}]}
{"op":"mcm","clk":"5348443046","pt":1646217754211,"mc":[{"id":"1.195453626","rc":[{"atb":[[2.56,5.34]],"id":38981227}],"con":true,"img":false}]}
{"op":"mcm","clk":"5348443186","pt":1646217755530,"mc":[{"id":"1.195453626","rc":[{"atb":[[2.04,56.98],[1.66,0]],"id":38981227}],"con":true,"img":false}]}
{"op":"mcm","clk":"5348443228","pt":1646217755896,"mc":[{"id":"1.195453626","rc":[{"atb":[[3.5,16]],"id":42099020}],"con":true,"img":false}]}
{"op":"mcm","clk":"5348443623","pt":1646217759726,"mc":[{"id":"1.195453626","rc":[{"atl":[[2.12,44.64]],"id":37429121}],"con":true,"img":false}]}
{"op":"mcm","clk":"5348443843","pt":1646217762094,"mc":[{"id":"1.195453626","rc":[{"atb":[[2.58,6.42]],"id":38981227}],"con":true,"img":false}]}
{"op":"mcm","clk":"5348443854","pt":1646217762202,"mc":[{"id":"1.195453626","rc":[{"atb":[[7.2,0]],"id":39360156}],"con":true,"img":false}]}
{"op":"mcm","clk":"5348443878","pt":1646217762398,"mc":[{"id":"1.195453626","rc":[{"atb":[[8.4,1.66]],"id":39360156}],"con":true,"img":false}]}
{"op":"mcm","clk":"5348443996","pt":1646217763495,"mc":[{"id":"1.195453626","rc":[{"atl":[[12.5,4.7],[15,0]],"id":42099020}],"con":true,"img":false}]}
{"op":"mcm","clk":"5348444190","pt":1646217765542,"mc":[{"id":"1.195453626","rc":[{"atl":[[9,0],[7.6,8.71]],"id":38981227},{"atl":[[11.5,0]],"id":36986045},{"atb":[[1.58,112.81],[1.5,0]],"id":36592903},{"atl":[[2.82,0]],"id":37429121}],"con":true,"img":false}]}
{"op":"mcm","clk":"5348444200","pt":1646217765599,"mc":[{"id":"1.195453626","rc":[{"atl":[[9.6,6.53]],"id":36986045},{"atl":[[2.4,34.56]],"id":37429121}],"con":true,"img":false}]}
{"op":"mcm","clk":"5348444386","pt":1646217767523,"mc":[{"id":"1.195453626","rc":[{"atb":[[3,0]],"id":42099020},{"atl":[[6.6,11.98],[14.5,0]],"id":40559875}],"con":true,"img":false}]}
{"op":"mcm","clk":"5348444399","pt":1646217767626,"mc":[{"id":"1.195453626","rc":[{"atb":[[3.25,28.47]],"id":42099020}],"con":true,"img":false}]}
{"op":"mcm","clk":"5348444500","pt":1646217768739,"mc":[{"id":"1.195453626","rc":[{"atb":[[1.92,0],[2.48,67.57]],"id":36986045},{"atl":[[3.3,0],[3.05,48.78]],"id":37429121},{"atb":[[3.2,56.82],[3.55,32.61]],"id":42099020},{"atl":[[4.5,0],[4.4,50.63]],"id":40559875},{"atb":[[3.35,0],[4.2,28.84]],"id":39360156}],"con":true,"img":false}]}
{"op":"mcm","clk":"5348444582","pt":1646217769517,"mc":[{"id":"1.195453626","rc":[{"atb":[[2.46,0],[3,31.06]],"id":36986045}],"con":true,"img":false}]}
{"op":"mcm","clk":"5348444606","pt":1646217769731,"mc":[{"id":"1.195453626","rc":[{"atl":[[2.42,0],[2.38,0],[2.16,64.66],[2.34,0]],"id":37429121}],"con":true,"img":false}]}
{"op":"mcm","clk":"5348444732","pt":1646217771043,"mc":[{"id":"1.195453626","rc":[{"atb":[[3.5,13]],"id":42099020}],"con":true,"img":false}]}
{"op":"mcm","clk":"5348444784","pt":1646217771512,"mc":[{"id":"1.195453626","rc":[{"atl":[[2.4,0]],"id":37429121},{"atb":[[7,12.59]],"id":39360156}],"con":true,"img":false}]}
{"op":"mcm","clk":"5348444794","pt":1646217771616,"mc":[{"id":"1.195453626","rc":[{"spn":3.99,"spf":"NaN","id":38981227},{"atl":[[2.62,34.56]],"id":37429121},{"spn":1.73,"spf":"NaN","id":37429121},{"spn":5.87,"spf":"NaN","id":42099020},{"spn":3.25,"spf":"NaN","id":40559875},{"atb":[[5.6,0]],"id":39360156},{"spn":13.45,"spf":"NaN","id":39360156}],"con":true,"img":false}]}
{"op":"mcm","clk":"5348445295","pt":1646217777035,"mc":[{"id":"1.195453626","rc":[{"atb":[[3.65,2.83]],"id":42099020}],"con":true,"img":false}]}
{"op":"mcm","clk":"5348445324","pt":1646217777347,"mc":[{"id":"1.195453626","rc":[{"atb":[[3.5,11.33]],"id":42099020}],"con":true,"img":false}]}
{"op":"mcm","clk":"5348445343","pt":1646217777520,"mc":[{"id":"1.195453626","rc":[{"atb":[[3.6,1.66]],"id":42099020},{"atl":[[11.5,0]],"id":42099020}],"con":true,"img":false}]}
{"op":"mcm","clk":"5348445353","pt":1646217777619,"mc":[{"id":"1.195453626","rc":[{"atl":[[10,4.15]],"id":42099020}],"con":true,"img":false}]}
{"op":"mcm","clk":"5348445545","pt":1646217779759,"mc":[{"id":"1.195453626","rc":[{"atl":[[2.2,104.17]],"id":37429121}],"con":true,"img":false}]}
{"op":"mcm","clk":"5348445731","pt":1646217781535,"mc":[{"id":"1.195453626","rc":[{"atl":[[10,0]],"id":42099020}],"con":true,"img":false}]}
{"op":"mcm","clk":"5348445745","pt":1646217781643,"mc":[{"id":"1.195453626","rc":[{"atl":[[11,6.15]],"id":42099020}],"con":true,"img":false}]}
{"op":"mcm","clk":"5348446106","pt":1646217784952,"mc":[{"id":"1.195453626","rc":[{"atb":[[3.5,8]],"id":42099020}],"con":true,"img":false}]}
{"op":"mcm","clk":"5348446180","pt":1646217785531,"mc":[{"id":"1.195453626","rc":[{"atl":[[2.32,0]],"id":37429121}],"con":true,"img":false}]}
{"op":"mcm","clk":"5348446191","pt":1646217785633,"mc":[{"id":"1.195453626","rc":[{"atl":[[2.1,30.27]],"id":37429121}],"con":true,"img":false}]}
{"op":"mcm","clk":"5348446367","pt":1646217787461,"mc":[{"id":"1.195453626","rc":[{"atb":[[3.55,0],[3.65,5.66]],"id":42099020}],"con":true,"img":false}]}
{"op":"mcm","clk":"5348446377","pt":1646217787567,"mc":[{"id":"1.195453626","rc":[{"atb":[[3.6,9.66]],"id":42099020}],"con":true,"img":false}]}
{"op":"mcm","clk":"5348446393","pt":1646217787637,"mc":[{"id":"1.195453626","rc":[{"atb":[[3.65,2.83]],"id":42099020}],"con":true,"img":false}]}
{"op":"mcm","clk":"5348446542","pt":1646217789141,"mc":[{"id":"1.195453626","rc":[{"atb":[[3.65,0]],"id":42099020}],"con":true,"img":false}]}
{"op":"mcm","clk":"5348447145","pt":1646217794847,"mc":[{"id":"1.195453626","rc":[{"atb":[[3.5,11]],"id":42099020}],"con":true,"img":false}]}
{"op":"mcm","clk":"5348449151","pt":1646217813672,"mc":[{"id":"1.195453626","rc":[{"atb":[[3.5,14.34]],"id":42099020}],"con":true,"img":false}]}
{"op":"mcm","clk":"5348508383","pt":1646218300397,"mc":[{"id":"1.195453626","rc":[{"atl":[[5.3,4.65],[5.4,0]],"id":38981227},{"spn":3.94,"spf":"NaN","id":38981227},{"atb":[[2.72,58.14],[2.48,0]],"id":36986045},{"atl":[[11,17.25],[12,0]],"id":36986045},{"atl":[[2.1,48.45],[2.08,0]],"id":37429121},{"spn":1.74,"spf":"NaN","id":37429121},{"spn":5.9,"spf":"NaN","id":42099020}],"con":true,"img":false}]}
{"op":"mcm","clk":"5348508486","pt":1646218301440,"mc":[{"id":"1.195453626","rc":[{"atl":[[2.1,30.27],[2.08,18.52]],"id":37429121},{"atb":[[2.1,75.76],[2.24,100.81]],"id":40559875},{"atl":[[4.6,62.5],[4.4,22.06]],"id":40559875}],"con":true,"img":false}]}
{"op":"mcm","clk":"5348509162","pt":1646218307419,"mc":[{"id":"1.195453626","rc":[{"atb":[[1.71,0],[1.8,97.4],[1.81,0],[1.9,22.22]],"id":38981227},{"atl":[[8.6,0],[6.6,3.57]],"id":36986045},{"atl":[[6.2,19.23],[6.6,3.57]],"id":36592903},{"atb":[[1.09,222.22]],"id":37429121},{"atl":[[2.88,53.19],[3.05,0]],"id":37429121},{"atl":[[11,4.15],[11.5,1.9]],"id":42099020},{"atb":[[6.2,3.85],[7,9.26],[6.6,0]],"id":39360156}],"con":true,"img":false}]}
{"op":"mcm","clk":"5348509175","pt":1646218307522,"mc":[{"id":"1.195453626","rc":[{"atb":[[1.8,171.48],[2.04,0]],"id":38981227}],"con":true,"img":false}]}
{"op":"mcm","clk":"5348509955","pt":1646218313993,"mc":[{"id":"1.195453626","rc":[{"atl":[[5.1,4.88],[9.2,0],[5.3,0],[8.2,13.89]],"id":38981227},{"atb":[[2.72,0],[2.96,101.94]],"id":36986045},{"atl":[[2.88,0],[2.12,17.86],[2.08,0],[3.05,48.78]],"id":37429121},{"atb":[[4.2,0]],"id":39360156}],"con":true,"img":false}]}
{"op":"mcm","clk":"5348509968","pt":1646218314039,"mc":[{"id":"1.195453626","rc":[{"atb":[[3.7,37.04]],"id":39360156}],"con":true,"img":false}]}
{"op":"mcm","clk":"5348509992","pt":1646218314248,"mc":[{"id":"1.195453626","rc":[{"atb":[[3.7,0],[5.4,22.73]],"id":39360156}],"con":true,"img":false}]}
{"op":"mcm","clk":"5348510053","pt":1646218314767,"mc":[{"id":"1.195453626","rc":[{"atl":[[4.6,34.72],[4.4,48.48]],"id":40559875}],"con":true,"img":false}]}
{"op":"mcm","clk":"5348510402","pt":1646218317456,"mc":[{"id":"1.195453626","rc":[{"atl":[[7,8.33]],"id":36986045},{"atl":[[7,8.33]],"id":36592903},{"atl":[[12.5,9.05]],"id":42099020},{"atb":[[5.9,10.2]],"id":39360156}],"con":true,"img":false}]}
{"op":"mcm","clk":"5348510848","pt":1646218321271,"mc":[{"id":"1.195453626","rc":[{"atl":[[9.8,0]],"id":36986045},{"atl":[[12,0],[13,0],[14,0]],"id":42099020}],"con":true,"img":false}]}
{"op":"mcm","clk":"5348510882","pt":1646218321586,"mc":[{"id":"1.195453626","rc":[{"atb":[[1.88,49.54]],"id":38981227},{"atl":[[2.1,0]],"id":37429121}],"con":true,"img":false}]}
{"op":"mcm","clk":"5348510893","pt":1646218321696,"mc":[{"id":"1.195453626","rc":[{"atb":[[2.52,0]],"id":38981227},{"atl":[[2.14,30.27]],"id":37429121}],"con":true,"img":false}]}
{"op":"mcm","clk":"5348511073","pt":1646218323162,"mc":[{"id":"1.195453626","rc":[{"atl":[[5.1,0],[5.3,4.65]],"id":38981227},{"atb":[[2.8,55.56],[2.96,50.92]],"id":36986045},{"atl":[[2.92,52.08],[3.05,0],[2.08,18.52]],"id":37429121},{"atb":[[2.1,0],[2.2,158.94]],"id":40559875},{"atl":[[4.6,62.5],[4.4,22.06]],"id":40559875},{"atb":[[3.7,20.4],[5.4,0]],"id":39360156}],"con":true,"img":false}]}
{"op":"mcm","clk":"5348511110","pt":1646218323479,"mc":[{"id":"1.195453626","rc":[{"atb":[[2.58,1.66]],"id":38981227}],"con":true,"img":false}]}
{"op":"mcm","clk":"5348511632","pt":1646218327398,"mc":[{"id":"1.195453626","rc":[{"atl":[[7.4,11.72]],"id":36986045},{"atl":[[7.4,11.72]],"id":36592903},{"atl":[[13.5,6]],"id":42099020},{"atb":[[5.7,15.96]],"id":39360156}],"con":true,"img":false}]}
{"op":"mcm","clk":"5348511850","pt":1646218329380,"mc":[{"id":"1.195453626","rc":[{"atb":[[2.56,10.16]],"id":38981227}],"con":true,"img":false}]}
{"op":"mcm","clk":"5348511886","pt":1646218329705,"mc":[{"id":"1.195453626","rc":[{"atl":[[9.4,4.58]],"id":36986045}],"con":true,"img":false}]}
{"op":"mcm","clk":"5348512109","pt":1646218331572,"mc":[{"id":"1.195453626","rc":[{"atb":[[3,0]],"id":36986045}],"con":true,"img":false}]}
{"op":"mcm","clk":"5348512119","pt":1646218331678,"mc":[{"id":"1.195453626","rc":[{"atb":[[2.88,31.06]],"id":36986045}],"con":true,"img":false}]}
{"op":"mcm","clk":"5348512293","pt":1646218333087,"mc":[{"id":"1.195453626","rc":[{"atb":[[1.88,106.36]],"id":38981227},{"atl":[[5.5,11.11]],"id":38981227}],"con":true,"img":false}]}
{"op":"mcm","clk":"5348512306","pt":1646218333192,"mc":[{"id":"1.195453626","rc":[{"atb":[[1.07,250]],"id":37429121},{"atl":[[2.12,44.64]],"id":37429121}],"con":true,"img":false}]}
{"op":"mcm","clk":"5348512661","pt":1646218336316,"mc":[{"id":"1.195453626","rc":[{"atb":[[4.5,52.97],[3.7,0]],"id":39360156}],"con":true,"img":false}]}
{"op":"mcm","clk":"5348512798","pt":1646218337450,"mc":[{"id":"1.195453626","rc":[{"atl":[[7.8,18.38]],"id":36986045},{"atl":[[14.5,9.26]],"id":42099020},{"atb":[[5.5,49.96]],"id":39360156}],"con":true,"img":false}]}
{"op":"mcm","clk":"5348512813","pt":1646218337463,"mc":[{"id":"1.195453626","rc":[{"atl":[[7.8,18.38]],"id":36592903}],"con":true,"img":false}]}
{"op":"mcm","clk":"5348513058","pt":1646218339598,"mc":[{"id":"1.195453626","rc":[{"atb":[[8.2,0]],"id":39360156}],"con":true,"img":false}]}
{"op":"mcm","clk":"5348513072","pt":1646218339703,"mc":[{"id":"1.195453626","rc":[{"atb":[[8.6,7.78]],"id":39360156}],"con":true,"img":false}]}
{"op":"mcm","clk":"5348513484","pt":1646218343198,"mc":[{"id":"1.195453626","rc":[{"atb":[[1.79,0],[1.86,87.21],[1.77,0],[1.75,0]],"id":38981227},{"atl":[[6.2,0],[5.7,15.96]],"id":38981227},{"atb":[[1.05,250]],"id":37429121}],"con":true,"img":false}]}
{"op":"mcm","clk":"5348513627","pt":1646218344290,"mc":[{"id":"1.195453626","rc":[{"atl":[[9,0]],"id":36986045},{"atb":[[8.4,0]],"id":39360156}],"con":true,"img":false}]}
{"op":"mcm","clk":"5348513948","pt":1646218347111,"mc":[{"id":"1.195453626","rc":[{"atb":[[1.01,0]],"id":37429121}],"con":true,"img":false}]}
{"op":"mcm","clk":"5348513996","pt":1646218347475,"mc":[{"id":"1.195453626","rc":[{"atb":[[1.8,97.4]],"id":38981227},{"atb":[[3.35,23.01],[3.25,0]],"id":42099020}],"con":true,"img":false}]}
{"op":"mcm","clk":"5348514006","pt":1646218347577,"mc":[{"id":"1.195453626","rc":[{"atb":[[1.81,74.08]],"id":38981227}],"con":true,"img":false}]}
{"op":"mcm","clk":"5348514197","pt":1646218349212,"mc":[{"id":"1.195453626","rc":[{"atb":[[2.8,0],[2.88,84.25]],"id":36986045},{"atl":[[2.1,18.18],[2.08,0]],"id":37429121}],"con":true,"img":false}]}
{"op":"mcm","clk":"5348514449","pt":1646218351513,"mc":[{"id":"1.195453626","rc":[{"atl":[[7.6,6.6],[9.4,0]],"id":36986045}],"con":true,"img":false}]}
{"op":"mcm","clk":"5348514636","pt":1646218353234,"mc":[{"id":"1.195453626","rc":[{"atb":[[1.84,148.81]],"id":38981227},{"atl":[[5.9,25.51]],"id":38981227}],"con":true,"img":false}]}
{"op":"mcm","clk":"5348514669","pt":1646218353497,"mc":[{"id":"1.195453626","rc":[{"atl":[[2.14,0]],"id":37429121}],"con":true,"img":false}]}
{"op":"mcm","clk":"5348514681","pt":1646218353598,"mc":[{"id":"1.195453626","rc":[{"atl":[[2.1,48.45]],"id":37429121}],"con":true,"img":false}]}
{"op":"mcm","clk":"5348514716","pt":1646218353914,"mc":[{"id":"1.195453626","rc":[{"atb":[[2.72,58.14],[2.88,31.06]],"id":36986045}],"con":true,"img":false}]}
{"op":"mcm","clk":"5348514847","pt":1646218355108,"mc":[{"id":"1.195453626","rc":[{"atl":[[2.08,18.52]],"id":37429121}],"con":true,"img":false}]}
{"op":"mcm","clk":"5348514860","pt":1646218355210,"mc":[{"id":"1.195453626","rc":[{"atl":[[2.1,30.27]],"id":37429121}],"con":true,"img":false}]}
{"op":"mcm","clk":"5348515805","pt":1646218363606,"mc":[{"id":"1.195453626","rc":[{"atl":[[5.8,0]],"id":38981227},{"spn":4.92,"spf":"NaN","id":36986045},{"spn":1.73,"spf":"NaN","id":37429121},{"spn":13.55,"spf":"NaN","id":39360156}],"con":true,"img":false}]}
{"op":"mcm","clk":"5348515815","pt":1646218363709,"mc":[{"id":"1.195453626","rc":[{"atl":[[5.6,9.08]],"id":38981227}],"con":true,"img":false}]}
{"op":"mcm","clk":"5348515868","pt":1646218364240,"mc":[{"id":"1.195453626","rc":[{"atb":[[2.72,0],[2.86,107.42]],"id":36986045}],"con":true,"img":false}]}
{"op":"mcm","clk":"5348516915","pt":1646218373513,"mc":[{"id":"1.195453626","rc":[{"atl":[[7.6,0]],"id":36986045}],"con":true,"img":false}]}
{"op":"mcm","clk":"5348516927","pt":1646218373624,"mc":[{"id":"1.195453626","rc":[{"atl":[[7.2,6.6]],"id":36986045}],"con":true,"img":false}]}
{"op":"mcm","clk":"5348517453","pt":1646218378331,"mc":[{"id":"1.195453626","rc":[{"atb":[[8.8,1.66]],"id":39360156}],"con":true,"img":false}]}
{"op":"mcm","clk":"5348518865","pt":1646218392564,"mc":[{"id":"1.195453626","rc":[{"atl":[[1.69,21.79]],"id":37429121}],"con":true,"img":false}]}
{"op":"mcm","clk":"5348518954","pt":1646218393552,"mc":[{"id":"1.195453626","rc":[{"atb":[[1.81,0]],"id":38981227}],"con":true,"img":false}]}
{"op":"mcm","clk":"5348518966","pt":1646218393657,"mc":[{"id":"1.195453626","rc":[{"atb":[[1.85,74.08]],"id":38981227}],"con":true,"img":false}]}
{"op":"mcm","clk":"5348521071","pt":1646218416802,"mc":[{"id":"1.195453626","rc":[{"atl":[[5.3,0],[4.7,5.41]],"id":38981227},{"atb":[[2.86,53.66],[2.74,57.47]],"id":36986045},{"atl":[[6.8,3.45],[6.6,0]],"id":36986045},{"atl":[[3.1,47.62],[2.14,17.54],[2.08,0],[2.92,0]],"id":37429121},{"atl":[[4.6,34.72],[4.9,25.64]],"id":40559875}],"con":true,"img":false}]}
{"op":"mcm","clk":"5348521969","pt":1646218426787,"mc":[{"id":"1.195453626","rc":[{"atl":[[4.9,12.82]],"id":38981227},{"spn":3.64,"spf":"NaN","id":38981227},{"atl":[[7.2,14.66]],"id":36986045},{"spn":5.02,"spf":"NaN","id":36986045},{"atl":[[2.18,42.37]],"id":37429121},{"spn":1.53,"spf":"NaN","id":37429121},{"spn":13.65,"spf":"NaN","id":39360156}],"con":true,"img":false}]}
{"op":"mcm","clk":"5348521983","pt":1646218426895,"mc":[{"id":"1.195453626","rc":[{"atl":[[2.12,0]],"id":37429121}],"con":true,"img":false}]}
{"op":"mcm","clk":"5348522114","pt":1646218428399,"mc":[{"id":"1.195453626","rc":[{"atl":[[1.69,0]],"id":37429121},{"trd":[[1.69,43.58]],"ltp":1.69,"tv":43.58,"id":37429121}],"con":true,"img":false}]}
{"op":"mcm","clk":"5348522571","pt":1646218433523,"mc":[{"id":"1.195453626","rc":[{"atl":[[2.1,0]],"id":37429121}],"con":true,"img":false}]}
{"op":"mcm","clk":"5348522581","pt":1646218433627,"mc":[{"id":"1.195453626","rc":[{"atl":[[2.14,47.81]],"id":37429121}],"con":true,"img":false}]}
{"op":"mcm","clk":"5348522783","pt":1646218435722,"mc":[{"id":"1.195453626","rc":[{"atl":[[27,2.79]],"id":39360156}],"con":true,"img":false}]}
{"op":"mcm","clk":"5348522793","pt":1646218435821,"mc":[{"id":"1.195453626","rc":[{"atl":[[34,2.72]],"id":39360156}],"con":true,"img":false}]}
{"op":"mcm","clk":"5348522882","pt":1646218436820,"mc":[{"id":"1.195453626","rc":[{"atl":[[5.1,18.29],[5.9,0]],"id":38981227},{"atl":[[7.4,0],[7.6,11.36],[7,0],[7.8,0]],"id":36986045},{"atl":[[2.22,61.48]],"id":37429121}],"con":true,"img":false}]}
{"op":"mcm","clk":"5348522968","pt":1646218437613,"mc":[{"id":"1.195453626","rc":[{"atl":[[9.6,0],[7.2,8.06]],"id":36986045}],"con":true,"img":false}]}
{"op":"mcm","clk":"5348522981","pt":1646218437721,"mc":[{"id":"1.195453626","rc":[{"atl":[[9,6.6],[10,6.53]],"id":36986045}],"con":true,"img":false}]}
{"op":"mcm","clk":"5348523352","pt":1646218441756,"mc":[{"id":"1.195453626","rc":[{"atb":[[2.62,2.16]],"id":38981227},{"atb":[[1.93,2.16]],"id":36592903},{"atb":[[2.52,2.16]],"id":40559875}],"con":true,"img":false}]}
{"op":"mcm","clk":"5348523447","pt":1646218442741,"mc":[{"id":"1.195453626","rc":[{"atl":[[5.7,0]],"id":38981227}],"con":true,"img":false}]}
{"op":"mcm","clk":"5348523461","pt":1646218442851,"mc":[{"id":"1.195453626","rc":[{"atl":[[2.2,0],[2.16,0]],"id":37429121}],"con":true,"img":false}]}
{"op":"mcm","clk":"5348523527","pt":1646218443525,"mc":[{"id":"1.195453626","rc":[{"atb":[[3.2,3.79]],"id":36986045},{"atb":[[2.42,0]],"id":40559875},{"atl":[[4.3,0]],"id":40559875}],"con":true,"img":false}]}
{"op":"mcm","clk":"5348523538","pt":1646218443629,"mc":[{"id":"1.195453626","rc":[{"atb":[[3,19.81]],"id":36986045},{"atb":[[2.34,30.7]],"id":40559875},{"atl":[[4.5,13.21]],"id":40559875}],"con":true,"img":false}]}
{"op":"mcm","clk":"5348523578","pt":1646218444148,"mc":[{"id":"1.195453626","rc":[{"atl":[[4.6,1.4]],"id":38981227},{"atl":[[6.6,1.35]],"id":36986045},{"atl":[[2.78,1.3]],"id":36592903},{"atl":[[2.12,1.25]],"id":37429121},{"atl":[[3.95,1.25]],"id":40559875}],"con":true,"img":false}]}
{"op":"mcm","clk":"5348523856","pt":1646218446530,"mc":[{"id":"1.195453626","rc":[{"atb":[[2.58,0]],"id":38981227},{"atb":[[2.5,0]],"id":40559875}],"con":true,"img":false}]}
{"op":"mcm","clk":"5348523885","pt":1646218446743,"mc":[{"id":"1.195453626","rc":[{"atb":[[2.64,1.66]],"id":38981227},{"atb":[[2.54,1.66]],"id":40559875}],"con":true,"img":false}]}
{"op":"mcm","clk":"5348523896","pt":1646218446849,"mc":[{"id":"1.195453626","rc":[{"atl":[[5.3,29.07]],"id":38981227},{"atb":[[3.25,1.66]],"id":36986045},{"atl":[[8,17.86]],"id":36986045},{"atl":[[2.26,99.21]],"id":37429121},{"atb":[[2.48,0]],"id":40559875}],"con":true,"img":false}]}
{"op":"mcm","clk":"5348524108","pt":1646218449364,"mc":[{"id":"1.195453626","rc":[{"atl":[[5.5,0]],"id":38981227}],"con":true,"img":false}]}
{"op":"mcm","clk":"5348524127","pt":1646218449526,"mc":[{"id":"1.195453626","rc":[{"atl":[[2.14,17.54]],"id":37429121}],"con":true,"img":false}]}
{"op":"mcm","clk":"5348524135","pt":1646218449629,"mc":[{"id":"1.195453626","rc":[{"atl":[[2.16,30.27]],"id":37429121}],"con":true,"img":false}]}
{"op":"mcm","clk":"5348524204","pt":1646218450354,"mc":[{"id":"1.195453626","rc":[{"atb":[[2.58,1.34]],"id":38981227},{"atb":[[3.2,5.15]],"id":36986045},{"atb":[[1.91,1.4]],"id":36592903},{"atb":[[1.39,1.48]],"id":37429121},{"atb":[[3.65,1.45]],"id":42099020},{"atb":[[2.46,7.1]],"id":40559875},{"atb":[[8.8,3.13]],"id":39360156}],"con":true,"img":false}]}
{"op":"mcm","clk":"5348524434","pt":1646218452754,"mc":[{"id":"1.195453626","rc":[{"atb":[[3.2,8.57]],"id":36986045},{"atb":[[2.46,12.25]],"id":40559875}],"con":true,"img":false}]}
{"op":"mcm","clk":"5348524917","pt":1646218457572,"mc":[{"id":"1.195453626","rc":[{"atl":[[3.75,13.19]],"id":36592903}],"con":true,"img":false}]}
{"op":"mcm","clk":"5348524931","pt":1646218457681,"mc":[{"id":"1.195453626","rc":[{"atl":[[3.6,12.82]],"id":36592903}],"con":true,"img":false}]}
{"op":"mcm","clk":"5348525125","pt":1646218459541,"mc":[{"id":"1.195453626","rc":[{"atb":[[2.42,30.7],[1.88,56.82]],"id":38981227}],"con":true,"img":false}]}
{"op":"mcm","clk":"5348525328","pt":1646218461563,"mc":[{"id":"1.195453626","rc":[{"atl":[[5.6,0]],"id":38981227}],"con":true,"img":false}]}
{"op":"mcm","clk":"5348525337","pt":1646218461664,"mc":[{"id":"1.195453626","rc":[{"atl":[[5,9.08]],"id":38981227}],"con":true,"img":false}]}
{"op":"mcm","clk":"5348525531","pt":1646218463554,"mc":[{"id":"1.195453626","rc":[{"atl":[[4.5,0]],"id":40559875}],"con":true,"img":false}]}
{"op":"mcm","clk":"5348525542","pt":1646218463661,"mc":[{"id":"1.195453626","rc":[{"atl":[[4.3,13.21]],"id":40559875}],"con":true,"img":false}]}
{"op":"mcm","clk":"5348526182","pt":1646218469582,"mc":[{"id":"1.195453626","rc":[{"atl":[[11,0]],"id":42099020}],"con":true,"img":false}]}
{"op":"mcm","clk":"5348526191","pt":1646218469685,"mc":[{"id":"1.195453626","rc":[{"atl":[[10,4.15]],"id":42099020}],"con":true,"img":false}]}
{"op":"mcm","clk":"5348526544","pt":1646218473593,"mc":[{"id":"1.195453626","rc":[{"atl":[[9,0]],"id":36986045}],"con":true,"img":false}]}
{"op":"mcm","clk":"5348526556","pt":1646218473689,"mc":[{"id":"1.195453626","rc":[{"atl":[[7.4,6.6]],"id":36986045}],"con":true,"img":false}]}
{"op":"mcm","clk":"5348527109","pt":1646218479481,"mc":[{"id":"1.195453626","rc":[{"atb":[[1.85,0]],"id":38981227},{"atb":[[3,0]],"id":36986045}],"con":true,"img":false}]}
{"op":"mcm","clk":"5348527116","pt":1646218479584,"mc":[{"id":"1.195453626","rc":[{"atb":[[2.02,58.1]],"id":38981227},{"atb":[[3.1,19.81]],"id":36986045}],"con":true,"img":false}]}
{"op":"mcm","clk":"5348528146","pt":1646218485499,"mc":[{"id":"1.195453626","rc":[{"atl":[[34,0]],"id":39360156}],"con":true,"img":false}]}
{"op":"mcm","clk":"5348528167","pt":1646218485604,"mc":[{"id":"1.195453626","rc":[{"atl":[[26,2.72]],"id":39360156}],"con":true,"img":false}]}
{"op":"mcm","clk":"5348528443","pt":1646218487609,"mc":[{"id":"1.195453626","rc":[{"atl":[[7.6,0]],"id":38981227},{"spn":3.62,"spf":"NaN","id":38981227},{"spn":4.92,"spf":"NaN","id":36986045},{"spn":1.92,"spf":1.0,"id":36592903},{"spn":1.75,"spf":"NaN","id":37429121},{"atb":[[3.35,0]],"id":42099020},{"spn":5.92,"spf":"NaN","id":42099020},{"spn":3.24,"spf":"NaN","id":40559875}],"con":true,"img":false}]}
{"op":"mcm","clk":"5348528454","pt":1646218487710,"mc":[{"id":"1.195453626","rc":[{"atl":[[6.8,8.71]],"id":38981227},{"atb":[[3.45,23.01]],"id":42099020}],"con":true,"img":false}]}
{"op":"mcm","clk":"5348528588","pt":1646218489012,"mc":[{"id":"1.195453626","rc":[{"atb":[[3.5,11.33]],"id":42099020}],"con":true,"img":false}]}
{"op":"mcm","clk":"5348529198","pt":1646218495004,"mc":[{"id":"1.195453626","rc":[{"atb":[[3.55,2.94]],"id":42099020}],"con":true,"img":false}]}
{"op":"mcm","clk":"5348529868","pt":1646218503550,"mc":[{"id":"1.195453626","rc":[{"atl":[[38,0]],"id":39360156}],"con":true,"img":false}]}
{"op":"mcm","clk":"5348529883","pt":1646218503607,"mc":[{"id":"1.195453626","rc":[{"atl":[[34,2.72]],"id":39360156}],"con":true,"img":false}]}
{"op":"mcm","clk":"5348531502","pt":1646218518774,"mc":[{"id":"1.195453626","rc":[{"atb":[[3.5,8]],"id":42099020}],"con":true,"img":false}]}
{"op":"mcm","clk":"5348533050","pt":1646218531885,"mc":[{"id":"1.195453626","rc":[{"atb":[[3.55,6.21]],"id":42099020}],"con":true,"img":false}]}
{"op":"mcm","clk":"5348539605","pt":1646218600310,"mc":[{"id":"1.195453626","rc":[{"atl":[[4.8,5.26],[4.7,0]],"id":38981227},{"atl":[[2.92,52.08],[3.1,0],[2.12,19.11],[2.14,0]],"id":37429121}],"con":true,"img":false}]}
{"op":"mcm","clk":"5348539634","pt":1646218600581,"mc":[{"id":"1.195453626","rc":[{"atb":[[1.83,24.1],[1.84,0],[1.88,0],[1.9,0],[1.86,0]],"id":38981227},{"atl":[[7.2,3.23],[6.6,0],[7,0]],"id":36592903}],"con":true,"img":false}]}
{"op":"mcm","clk":"5348539669","pt":1646218600986,"mc":[{"id":"1.195453626","rc":[{"atl":[[4.6,0]],"id":38981227}],"con":true,"img":false}]}
{"op":"mcm","clk":"5348539676","pt":1646218601086,"mc":[{"id":"1.195453626","rc":[{"atl":[[4.7,1.4]],"id":38981227}],"con":true,"img":false}]}
{"op":"mcm","clk":"5348539714","pt":1646218601506,"mc":[{"id":"1.195453626","rc":[{"atb":[[1.8,0],[2.42,44.78],[2.34,58.11]],"id":38981227},{"atl":[[6.4,3.7]],"id":36592903},{"atb":[[1.18,111.11],[1.09,0],[1.08,437.59]],"id":37429121},{"atb":[[3.6,1.66],[3.5,0],[3.3,0],[3.2,0],[2.06,65.22],[3.4,17.79],[2.2,16.67]],"id":42099020},{"atl":[[8.2,7.82],[11.5,0]],"id":42099020},{"atl":[[4,0],[4.4,0],[4.2,0],[4.7,5.41]],"id":40559875},{"atb":[[6.2,0],[5.9,4.08]],"id":39360156}],"con":true,"img":false}]}
{"op":"mcm","clk":"5348539741","pt":1646218601773,"mc":[{"id":"1.195453626","rc":[{"atl":[[8,1.33]],"id":42099020},{"atl":[[3.95,0]],"id":40559875}],"con":true,"img":false}]}
{"op":"mcm","clk":"5348539751","pt":1646218601879,"mc":[{"id":"1.195453626","rc":[{"atb":[[2.46,13.7]],"id":38981227},{"atl":[[5.1,4.88],[4.6,0],[4.2,1.25],[4.7,0]],"id":40559875}],"con":true,"img":false}]}
{"op":"mcm","clk":"5348539862","pt":1646218602972,"mc":[{"id":"1.195453626","rc":[{"atl":[[6.4,0],[5.9,4.08]],"id":36592903},{"atl":[[4.7,5.41]],"id":40559875}],"con":true,"img":false}]}
{"op":"mcm","clk":"5348539915","pt":1646218603594,"mc":[{"id":"1.195453626","rc":[{"atb":[[3.45,0]],"id":42099020}],"con":true,"img":false}]}
{"op":"mcm","clk":"5348539926","pt":1646218603702,"mc":[{"id":"1.195453626","rc":[{"atb":[[3.05,23.01]],"id":42099020}],"con":true,"img":false}]}
{"op":"mcm","clk":"5348540156","pt":1646218606194,"mc":[{"id":"1.195453626","rc":[{"atb":[[3.55,3.26]],"id":42099020}],"con":true,"img":false}]}
{"op":"mcm","clk":"5348540239","pt":1646218607215,"mc":[{"id":"1.195453626","rc":[{"atb":[[3.65,0]],"id":42099020}],"con":true,"img":false}]}
{"op":"mcm","clk":"5348540250","pt":1646218607322,"mc":[{"id":"1.195453626","rc":[{"atb":[[3.45,1.45]],"id":42099020}],"con":true,"img":false}]}
{"op":"mcm","clk":"5348540279","pt":1646218607593,"mc":[{"id":"1.195453626","rc":[{"atl":[[4.8,0],[8.2,0],[7.2,16.13],[4.6,5.56]],"id":38981227},{"atl":[[2.12,1.25],[2.14,17.54]],"id":37429121}],"con":true,"img":false}]}
{"op":"mcm","clk":"5348540359","pt":1646218608521,"mc":[{"id":"1.195453626","rc":[{"atl":[[4.7,0]],"id":38981227}],"con":true,"img":false}]}
{"op":"mcm","clk":"5348540369","pt":1646218608590,"mc":[{"id":"1.195453626","rc":[{"atl":[[4.5,1.4]],"id":38981227}],"con":true,"img":false}]}
{"op":"mcm","clk":"5348540440","pt":1646218609313,"mc":[{"id":"1.195453626","rc":[{"atl":[[4.3,0]],"id":40559875}],"con":true,"img":false}]}
{"op":"mcm","clk":"5348540450","pt":1646218609417,"mc":[{"id":"1.195453626","rc":[{"atl":[[4.8,13.21]],"id":40559875}],"con":true,"img":false}]}
{"op":"mcm","clk":"5348540532","pt":1646218610199,"mc":[{"id":"1.195453626","rc":[{"atl":[[4.2,0]],"id":40559875}],"con":true,"img":false}]}
{"op":"mcm","clk":"5348540543","pt":1646218610311,"mc":[{"id":"1.195453626","rc":[{"atl":[[4.6,1.25]],"id":40559875}],"con":true,"img":false}]}
{"op":"mcm","clk":"5348540639","pt":1646218611504,"mc":[{"id":"1.195453626","rc":[{"atb":[[2.16,43.1]],"id":42099020},{"atl":[[8.6,6.58]],"id":42099020},{"atb":[[5.7,10.64]],"id":39360156}],"con":true,"img":false}]}
{"op":"mcm","clk":"5348540675","pt":1646218611980,"mc":[{"id":"1.195453626","rc":[{"atb":[[3.05,26.68]],"id":42099020}],"con":true,"img":false}]}
{"op":"mcm","clk":"5348540769","pt":1646218613020,"mc":[{"id":"1.195453626","rc":[{"atl":[[6.2,28.85]],"id":36592903},{"atl":[[4.9,38.46]],"id":40559875}],"con":true,"img":false}]}
{"op":"mcm","clk":"5348541124","pt":1646218617614,"mc":[{"id":"1.195453626","rc":[{"atb":[[2.42,65.91]],"id":38981227},{"atb":[[1.16,250]],"id":37429121}],"con":true,"img":false}]}
{"op":"mcm","clk":"5348541485","pt":1646218621544,"mc":[{"id":"1.195453626","rc":[{"atb":[[2.12,66.96]],"id":42099020},{"atl":[[9,9.38],[14.5,0]],"id":42099020},{"atb":[[5.5,38.85]],"id":39360156}],"con":true,"img":false}]}
{"op":"mcm","clk":"5348541579","pt":1646218622435,"mc":[{"id":"1.195453626","rc":[{"atl":[[7.2,0]],"id":36592903},{"atb":[[1.03,0],[1.07,0],[1.05,0]],"id":37429121}],"con":true,"img":false}]}
{"op":"mcm","clk":"5348541586","pt":1646218622538,"mc":[{"id":"1.195453626","rc":[{"atl":[[13.5,0]],"id":42099020}],"con":true,"img":false}]}
{"op":"mcm","clk":"5348541631","pt":1646218623013,"mc":[{"id":"1.195453626","rc":[{"atl":[[6.6,13.39]],"id":36592903},{"atl":[[5.1,18.29]],"id":40559875}],"con":true,"img":false}]}
{"op":"mcm","clk":"5348541878","pt":1646218625308,"mc":[{"id":"1.195453626","rc":[{"atl":[[7.8,0]],"id":36592903}],"con":true,"img":false}]}
{"op":"mcm","clk":"5348542093","pt":1646218627598,"mc":[{"id":"1.195453626","rc":[{"atb":[[2.38,54.35]],"id":38981227},{"atb":[[1.14,250]],"id":37429121}],"con":true,"img":false}]}
{"op":"mcm","clk":"5348542424","pt":1646218631499,"mc":[{"id":"1.195453626","rc":[{"atb":[[2.08,115.74]],"id":42099020},{"atl":[[9.4,14.88]],"id":42099020},{"atb":[[5.3,29.07]],"id":39360156}],"con":true,"img":false}]}
{"op":"mcm","clk":"5348542550","pt":1646218633013,"mc":[{"id":"1.195453626","rc":[{"atl":[[7,20.83]],"id":36592903},{"atl":[[5.3,29.07]],"id":40559875}],"con":true,"img":false}]}
{"op":"mcm","clk":"5348542577","pt":1646218633327,"mc":[{"id":"1.195453626","rc":[{"atl":[[7.4,0]],"id":36592903},{"atl":[[12.5,4.7]],"id":42099020}],"con":true,"img":false}]}
{"op":"mcm","clk":"5348542594","pt":1646218633535,"mc":[{"id":"1.195453626","rc":[{"atl":[[34,0]],"id":39360156}],"con":true,"img":false}]}
{"op":"mcm","clk":"5348542607","pt":1646218633640,"mc":[{"id":"1.195453626","rc":[{"atl":[[38,2.72]],"id":39360156}],"con":true,"img":false}]}
{"op":"mcm","clk":"5348542691","pt":1646218634633,"mc":[{"id":"1.195453626","rc":[{"atb":[[3.55,0]],"id":42099020}],"con":true,"img":false}]}
{"op":"mcm","clk":"5348542947","pt":1646218637655,"mc":[{"id":"1.195453626","rc":[{"atb":[[2.34,151.39]],"id":38981227},{"atb":[[1.12,250]],"id":37429121}],"con":true,"img":false}]}
{"op":"mcm","clk":"5348543049","pt":1646218638630,"mc":[{"id":"1.195453626","rc":[{"atb":[[3.6,0]],"id":42099020}],"con":true,"img":false}]}
{"op":"mcm","clk":"5348543074","pt":1646218638853,"mc":[{"id":"1.195453626","rc":[{"atb":[[3.45,3.11]],"id":42099020}],"con":true,"img":false}]}
{"op":"mcm","clk":"5348543138","pt":1646218639513,"mc":[{"id":"1.195453626","rc":[{"atl":[[26,0]],"id":39360156}],"con":true,"img":false}]}
{"op":"mcm","clk":"5348543144","pt":1646218639623,"mc":[{"id":"1.195453626","rc":[{"atl":[[27,5.51]],"id":39360156}],"con":true,"img":false}]}
{"op":"mcm","clk":"5348543854","pt":1646218647556,"mc":[{"id":"1.195453626","rc":[{"atl":[[10,0]],"id":42099020}],"con":true,"img":false}]}
{"op":"mcm","clk":"5348543864","pt":1646218647660,"mc":[{"id":"1.195453626","rc":[{"atb":[[1.83,0]],"id":38981227},{"atl":[[8.8,4.15]],"id":42099020}],"con":true,"img":false}]}
{"op":"mcm","clk":"5348544121","pt":1646218650483,"mc":[{"id":"1.195453626","rc":[{"atb":[[3.1,3.96]],"id":42099020}],"con":true,"img":false}]}
{"op":"mcm","clk":"5348544366","pt":1646218653583,"mc":[{"id":"1.195453626","rc":[{"atb":[[1.26,0]],"id":37429121}],"con":true,"img":false}]}
{"op":"mcm","clk":"5348544381","pt":1646218653641,"mc":[{"id":"1.195453626","rc":[{"atb":[[1.29,215.37]],"id":37429121}],"con":true,"img":false}]}
{"op":"mcm","clk":"5348544404","pt":1646218653943,"mc":[{"id":"1.195453626","rc":[{"atb":[[1.41,2.16]],"id":37429121}],"con":true,"img":false}]}
{"op":"mcm","clk":"5348544536","pt":1646218655568,"mc":[{"id":"1.195453626","rc":[{"atl":[[10,6.01],[12.5,0]],"id":42099020}],"con":true,"img":false}]}
{"op":"mcm","clk":"5348546323","pt":1646218678696,"mc":[{"id":"1.195453626","rc":[{"spn":3.57,"spf":"NaN","id":38981227},{"atb":[[1.35,0],[1.29,0]],"id":37429121},{"spn":1.76,"spf":"NaN","id":37429121},{"spn":5.72,"spf":"NaN","id":42099020},{"spn":3.57,"spf":"NaN","id":40559875}],"con":true,"img":false}]}
{"op":"mcm","clk":"5348546331","pt":1646218678799,"mc":[{"id":"1.195453626","rc":[{"atb":[[1.28,85.42],[1.26,215.37]],"id":37429121}],"con":true,"img":false}]}
{"op":"mcm","clk":"5348546405","pt":1646218679592,"mc":[{"id":"1.195453626","rc":[{"atb":[[2.4,0],[2.5,0],[2.3,0]],"id":38981227},{"atl":[[8,0],[10,0],[6,0]],"id":38981227},{"atb":[[2.86,0],[3.15,9.3],[2.96,0]],"id":36986045},{"atl":[[16,0],[11,10],[8.4,0]],"id":36986045},{"atb":[[1.8,156.25],[1.85,0],[1.75,0]],"id":36592903},{"atl":[[4.5,0],[5.5,0],[3.75,0]],"id":36592903},{"atb":[[1.2,0],[1.25,0],[1.15,0]],"id":37429121},{"atl":[[2.44,0],[2.64,0],[2.84,0]],"id":37429121},{"atb":[[2.88,0],[2.98,0],[2.78,0]],"id":42099020},{"atl":[[10.5,0],[8.2,2.78],[15.5,0]],"id":42099020},{"atb":[[2.4,0],[2.3,0],[2.2,75.76]],"id":40559875},{"atl":[[9.6,0],[5.8,0],[7.6,0]],"id":40559875},{"atb":[[4.5,24.46],[5,0],[5.5,16.67]],"id":39360156},{"atl":[[18.5,0],[44,0],[27,2.72]],"id":39360156}],"con":true,"img":false}]}
{"op":"mcm","clk":"5348546545","pt":1646218681305,"mc":[{"id":"1.195453626","rc":[{"atb":[[2.56,5.34]],"id":38981227},{"atb":[[3.2,5.15]],"id":36986045},{"atb":[[1.38,21.94]],"id":37429121},{"atb":[[3.05,23.01]],"id":42099020},{"atb":[[2.46,7.1]],"id":40559875}],"con":true,"img":false}]}
{"op":"mcm","clk":"5348546567","pt":1646218681518,"mc":[{"id":"1.195453626","rc":[{"atb":[[2.88,0]],"id":36986045},{"atb":[[1.26,0]],"id":37429121},{"atl":[[10,0]],"id":42099020}],"con":true,"img":false}]}
{"op":"mcm","clk":"5348546576","pt":1646218681568,"mc":[{"id":"1.195453626","rc":[{"atb":[[2.76,31.06]],"id":36986045},{"atb":[[1.23,215.37]],"id":37429121},{"atl":[[11.5,6.01]],"id":42099020}],"con":true,"img":false}]}
{"op":"mcm","clk":"5348546701","pt":1646218682772,"mc":[{"id":"1.195453626","rc":[{"atl":[[2.1,2.52]],"id":37429121}],"con":true,"img":false}]}
{"op":"mcm","clk":"5348546809","pt":1646218684015,"mc":[{"id":"1.195453626","rc":[{"atb":[[2.4,71.29],[2.5,66.54],[2.3,76.77]],"id":38981227},{"atl":[[8,10.37],[10,8.06],[6,7.25]],"id":38981227},{"atb":[[2.86,53.66],[3.15,55.72],[2.96,50.92]],"id":36986045},{"atl":[[16,4.83],[11,17.25],[8.4,4.9]],"id":36986045},{"atb":[[1.8,281.01],[1.85,117.42],[1.75,133.08]],"id":36592903},{"atl":[[4.5,20.74],[5.5,16.13],[3.75,13.19]],"id":36592903},{"atb":[[1.2,499.07],[1.25,399.25],[1.15,665.43]],"id":37429121},{"atl":[[2.44,25.2],[2.64,44.26],[2.84,39.45]],"id":37429121},{"atb":[[2.88,53.09],[2.98,50.41],[2.78,56.07]],"id":42099020},{"atl":[[10.5,7.64],[8.2,7.82],[15.5,5]],"id":42099020},{"atb":[[2.4,71.29],[2.3,76.77],[2.2,158.94]],"id":40559875},{"atl":[[9.6,8.44],[5.8,7.56],[7.6,10.99]],"id":40559875},{"atb":[[4.5,52.97],[5,24.95],[5.5,38.85]],"id":39360156},{"atl":[[18.5,2.07],[44,1.68],[27,5.51]],"id":39360156}],"con":true,"img":false}]}
{"op":"mcm","clk":"5348547013","pt":1646218686712,"mc":[{"id":"1.195453626","rc":[{"atl":[[2.12,0]],"id":37429121}],"con":true,"img":false}]}
{"op":"mcm","clk":"5348547020","pt":1646218686818,"mc":[{"id":"1.195453626","rc":[{"atl":[[2.1,3.78]],"id":37429121}],"con":true,"img":false}]}
{"op":"mcm","clk":"5348547273","pt":1646218689674,"mc":[{"id":"1.195453626","rc":[{"atb":[[3.05,0]],"id":42099020},{"atl":[[38,0]],"id":39360156}],"con":true,"img":false}]}
{"op":"mcm","clk":"5348547283","pt":1646218689777,"mc":[{"id":"1.195453626","rc":[{"atb":[[3,23.01]],"id":42099020},{"atl":[[34,2.72]],"id":39360156}],"con":true,"img":false}]}
{"op":"mcm","clk":"5348547336","pt":1646218690397,"mc":[{"id":"1.195453626","rc":[{"atb":[[2.56,10.16]],"id":38981227},{"atb":[[3.2,8.57]],"id":36986045},{"atb":[[1.31,24.25]],"id":37429121},{"atb":[[3.05,3.66]],"id":42099020},{"atb":[[2.46,12.25]],"id":40559875}],"con":true,"img":false}]}
{"op":"mcm","clk":"5348547429","pt":1646218691384,"mc":[{"id":"1.195453626","rc":[{"atl":[[2.1,1.25]],"id":37429121}],"con":true,"img":false}]}
{"op":"mcm","clk":"5348547462","pt":1646218691694,"mc":[{"id":"1.195453626","rc":[{"atl":[[2.08,2.52]],"id":37429121}],"con":true,"img":false}]}
{"op":"mcm","clk":"5348547487","pt":1646218692003,"mc":[{"id":"1.195453626","rc":[{"atl":[[2.1,0]],"id":37429121}],"con":true,"img":false}]}
{"op":"mcm","clk":"5348547496","pt":1646218692109,"mc":[{"id":"1.195453626","rc":[{"atl":[[2.08,3.78]],"id":37429121}],"con":true,"img":false}]}
{"op":"mcm","clk":"5348547853","pt":1646218696409,"mc":[{"id":"1.195453626","rc":[{"atb":[[1.38,0]],"id":37429121}],"con":true,"img":false}]}
{"op":"mcm","clk":"5348547913","pt":1646218697188,"mc":[{"id":"1.195453626","rc":[{"atb":[[1.39,0]],"id":37429121}],"con":true,"img":false}]}
{"op":"mcm","clk":"5348547922","pt":1646218697291,"mc":[{"id":"1.195453626","rc":[{"atb":[[1.32,1.48]],"id":37429121}],"con":true,"img":false}]}
{"op":"mcm","clk":"5348548122","pt":1646218699651,"mc":[{"id":"1.195453626","rc":[{"atl":[[2.08,1.25]],"id":37429121}],"con":true,"img":false}]}
{"op":"mcm","clk":"5348548143","pt":1646218699881,"mc":[{"id":"1.195453626","rc":[{"atl":[[2.06,2.52]],"id":37429121}],"con":true,"img":false}]}
{"op":"mcm","clk":"5348548525","pt":1646218704621,"mc":[{"id":"1.195453626","rc":[{"atl":[[5,18.62],[4.9,12.82]],"id":40559875}],"con":true,"img":false}]}
{"op":"mcm","clk":"5348548654","pt":1646218706125,"mc":[{"id":"1.195453626","rc":[{"atl":[[2.08,0]],"id":37429121}],"con":true,"img":false}]}
{"op":"mcm","clk":"5348548668","pt":1646218706228,"mc":[{"id":"1.195453626","rc":[{"atl":[[2.06,3.78]],"id":37429121}],"con":true,"img":false}]}
{"op":"mcm","clk":"5348548941","pt":1646218709320,"mc":[{"id":"1.195453626","rc":[{"atl":[[2.06,1.25]],"id":37429121}],"con":true,"img":false}]}
{"op":"mcm","clk":"5348548981","pt":1646218709710,"mc":[{"id":"1.195453626","rc":[{"atl":[[2.04,2.52]],"id":37429121}],"con":true,"img":false}]}
{"op":"mcm","clk":"5348549017","pt":1646218710121,"mc":[{"id":"1.195453626","rc":[{"atl":[[2.06,0]],"id":37429121}],"con":true,"img":false}]}
{"op":"mcm","clk":"5348549024","pt":1646218710224,"mc":[{"id":"1.195453626","rc":[{"atb":[[1.31,51.14]],"id":37429121},{"atl":[[2.04,3.78]],"id":37429121},{"atb":[[3.1,0]],"id":42099020}],"con":true,"img":false}]}
{"op":"mcm","clk":"5348549128","pt":1646218711631,"mc":[{"id":"1.195453626","rc":[{"atl":[[4.8,0]],"id":40559875}],"con":true,"img":false}]}
{"op":"mcm","clk":"5348549138","pt":1646218711734,"mc":[{"id":"1.195453626","rc":[{"atl":[[4.9,26.03]],"id":40559875}],"con":true,"img":false}]}
{"op":"mcm","clk":"5348549420","pt":1646218715011,"mc":[{"id":"1.195453626","rc":[{"atl":[[2.12,17.86],[2.14,0]],"id":37429121},{"atl":[[8.2,5.04],[8.4,2.7]],"id":42099020}],"con":true,"img":false}]}
{"op":"mcm","clk":"5348549761","pt":1646218718442,"mc":[{"id":"1.195453626","rc":[{"atl":[[2.04,1.25]],"id":37429121}],"con":true,"img":false}]}
{"op":"mcm","clk":"5348549844","pt":1646218719224,"mc":[{"id":"1.195453626","rc":[{"atl":[[2.04,0]],"id":37429121}],"con":true,"img":false}]}
{"op":"mcm","clk":"5348549855","pt":1646218719327,"mc":[{"id":"1.195453626","rc":[{"atl":[[2.1,1.25]],"id":37429121}],"con":true,"img":false}]}
{"op":"mcm","clk":"5348550001","pt":1646218721153,"mc":[{"id":"1.195453626","rc":[{"atl":[[4.9,44.65]],"id":40559875}],"con":true,"img":false}]}
{"op":"mcm","clk":"5348550011","pt":1646218721255,"mc":[{"id":"1.195453626","rc":[{"atl":[[5,0]],"id":40559875}],"con":true,"img":false}]}
{"op":"mcm","clk":"5348550238","pt":1646218723658,"mc":[{"id":"1.195453626","rc":[{"atb":[[1.23,0]],"id":37429121}],"con":true,"img":false}]}
{"op":"mcm","clk":"5348550247","pt":1646218723758,"mc":[{"id":"1.195453626","rc":[{"atb":[[1.26,215.37]],"id":37429121}],"con":true,"img":false}]}
{"op":"mcm","clk":"5348550362","pt":1646218725064,"mc":[{"id":"1.195453626","rc":[{"atl":[[8.8,10.56]],"id":42099020}],"con":true,"img":false}]}
{"op":"mcm","clk":"5348550394","pt":1646218725533,"mc":[{"id":"1.195453626","rc":[{"atb":[[2.76,0]],"id":36986045},{"atl":[[11.5,0]],"id":42099020}],"con":true,"img":false}]}
{"op":"mcm","clk":"5348550405","pt":1646218725638,"mc":[{"id":"1.195453626","rc":[{"atb":[[2.88,31.06]],"id":36986045},{"atl":[[10,6.01]],"id":42099020}],"con":true,"img":false}]}
{"op":"mcm","clk":"5348550445","pt":1646218726160,"mc":[{"id":"1.195453626","rc":[{"atb":[[3.05,7.73]],"id":42099020}],"con":true,"img":false}]}
{"op":"mcm","clk":"5348550599","pt":1646218727729,"mc":[{"id":"1.195453626","rc":[{"atl":[[8.6,0],[9,0],[9.4,0]],"id":42099020}],"con":true,"img":false}]}
{"op":"mcm","clk":"5348551162","pt":1646218735054,"mc":[{"id":"1.195453626","rc":[{"atl":[[9.2,9.15]],"id":42099020}],"con":true,"img":false}]}
{"op":"mcm","clk":"5348551210","pt":1646218735636,"mc":[{"id":"1.195453626","rc":[{"atl":[[8.8,6.41]],"id":42099020}],"con":true,"img":false}]}
{"op":"mcm","clk":"5348551221","pt":1646218735740,"mc":[{"id":"1.195453626","rc":[{"atl":[[10,10.16]],"id":42099020}],"con":true,"img":false}]}
{"op":"mcm","clk":"5348551985","pt":1646218745034,"mc":[{"id":"1.195453626","rc":[{"spn":1.75,"spf":"NaN","id":37429121},{"atl":[[9.6,14.53]],"id":42099020}],"con":true,"img":false}]}
{"op":"mcm","clk":"5348553206","pt":1646218759570,"mc":[{"id":"1.195453626","rc":[{"atl":[[10,6.01]],"id":42099020}],"con":true,"img":false}]}
{"op":"mcm","clk":"5348553213","pt":1646218759673,"mc":[{"id":"1.195453626","rc":[{"atl":[[9,4.15]],"id":42099020}],"con":true,"img":false}]}
{"op":"mcm","clk":"5348553268","pt":1646218760463,"mc":[{"id":"1.195453626","rc":[{"atb":[[2.66,3.33]],"id":38981227},{"atb":[[3.3,3.33]],"id":36986045},{"atb":[[1.94,4.33]],"id":36592903},{"atb":[[1.33,9.2]],"id":37429121},{"atb":[[3.5,6.24]],"id":42099020},{"atb":[[2.48,5]],"id":40559875}],"con":true,"img":false}]}
{"op":"mcm","clk":"5348553383","pt":1646218762102,"mc":[{"id":"1.195453626","rc":[{"atl":[[2.08,2.52]],"id":37429121}],"con":true,"img":false}]}
{"op":"mcm","clk":"5348553453","pt":1646218762994,"mc":[{"id":"1.195453626","rc":[{"atb":[[1.91,0]],"id":36592903},{"atb":[[1.32,0]],"id":37429121},{"atl":[[2.92,0],[2.64,104.82],[2.1,0]],"id":37429121},{"atb":[[3.45,1.66]],"id":42099020},{"atb":[[2.46,10.86]],"id":40559875},{"atl":[[4.7,23.7]],"id":40559875}],"con":true,"img":false}]}
{"op":"mcm","clk":"5348553464","pt":1646218763100,"mc":[{"id":"1.195453626","rc":[{"atb":[[1.94,5.73]],"id":36592903},{"atb":[[1.34,1.48]],"id":37429121},{"atl":[[2.08,3.78]],"id":37429121},{"atb":[[3.55,1.45]],"id":42099020},{"atb":[[2.48,6.39]],"id":40559875},{"atl":[[4.9,26.03]],"id":40559875}],"con":true,"img":false}]}
{"op":"mcm","clk":"5348553508","pt":1646218763673,"mc":[{"id":"1.195453626","rc":[{"atb":[[2.64,0]],"id":38981227},{"atb":[[3.25,0]],"id":36986045},{"atb":[[3.45,0]],"id":42099020}],"con":true,"img":false}]}
{"op":"mcm","clk":"5348553516","pt":1646218763781,"mc":[{"id":"1.195453626","rc":[{"atb":[[2.68,1.66]],"id":38981227},{"atb":[[3.35,1.66]],"id":36986045},{"atb":[[3.55,3.11]],"id":42099020}],"con":true,"img":false}]}
{"op":"mcm","clk":"5348553706","pt":1646218766124,"mc":[{"id":"1.195453626","rc":[{"atb":[[2.66,0]],"id":38981227},{"atb":[[3.3,0]],"id":36986045},{"atb":[[1.94,1.4]],"id":36592903},{"atb":[[1.33,0]],"id":37429121},{"atb":[[3.5,0]],"id":42099020}],"con":true,"img":false}]}
{"op":"mcm","clk":"5348553760","pt":1646218767008,"mc":[{"id":"1.195453626","rc":[{"atb":[[1.94,0]],"id":36592903},{"atb":[[1.34,0]],"id":37429121},{"atb":[[3.55,1.66]],"id":42099020}],"con":true,"img":false}]}
{"op":"mcm","clk":"5348553772","pt":1646218767114,"mc":[{"id":"1.195453626","rc":[{"atb":[[1.91,1.4]],"id":36592903},{"atb":[[1.32,1.48]],"id":37429121},{"atb":[[3.45,1.45]],"id":42099020}],"con":true,"img":false}]}
{"op":"mcm","clk":"5348553930","pt":1646218769209,"mc":[{"id":"1.195453626","rc":[{"atl":[[2.08,1.25]],"id":37429121}],"con":true,"img":false}]}
{"op":"mcm","clk":"5348553958","pt":1646218769575,"mc":[{"id":"1.195453626","rc":[{"atl":[[2.08,0]],"id":37429121}],"con":true,"img":false}]}
{"op":"mcm","clk":"5348553969","pt":1646218769690,"mc":[{"id":"1.195453626","rc":[{"atl":[[2.1,1.25]],"id":37429121}],"con":true,"img":false}]}
{"op":"mcm","clk":"5348554002","pt":1646218769992,"mc":[{"id":"1.195453626","rc":[{"atb":[[2.64,4.59]],"id":38981227},{"atb":[[3.25,4.59]],"id":36986045},{"atb":[[1.94,4.33]],"id":36592903},{"atb":[[1.33,9.2]],"id":37429121},{"atb":[[3.6,3.33]],"id":42099020}],"con":true,"img":false}]}
{"op":"mcm","clk":"5348554087","pt":1646218770983,"mc":[{"id":"1.195453626","rc":[{"atb":[[3.2,7.21]],"id":36986045},{"atb":[[1.91,0]],"id":36592903},{"atl":[[2.08,2.52]],"id":37429121}],"con":true,"img":false}]}
{"op":"mcm","clk":"5348554096","pt":1646218771086,"mc":[{"id":"1.195453626","rc":[{"atb":[[3.25,5.95]],"id":36986045},{"atb":[[1.94,5.73]],"id":36592903}],"con":true,"img":false}]}
{"op":"mcm","clk":"5348554876","pt":1646218781412,"mc":[{"id":"1.195453626","rc":[{"atl":[[2.12,0],[2.14,17.54]],"id":37429121}],"con":true,"img":false}]}
{"op":"mcm","clk":"5348554908","pt":1646218781727,"mc":[{"id":"1.195453626","rc":[{"atb":[[2.68,0]],"id":38981227},{"atb":[[3.35,0]],"id":36986045},{"atb":[[3.55,0]],"id":42099020}],"con":true,"img":false}]}
{"op":"mcm","clk":"5348554927","pt":1646218781937,"mc":[{"id":"1.195453626","rc":[{"atb":[[2.66,1.66]],"id":38981227},{"atb":[[3.3,1.66]],"id":36986045},{"atb":[[3.65,1.66]],"id":42099020}],"con":true,"img":false}]}
{"op":"mcm","clk":"5348555067","pt":1646218783497,"mc":[{"id":"1.195453626","rc":[{"atl":[[4.9,12.82]],"id":40559875}],"con":true,"img":false}]}
{"op":"mcm","clk":"5348555077","pt":1646218783601,"mc":[{"id":"1.195453626","rc":[{"atl":[[4.6,14.46]],"id":40559875}],"con":true,"img":false}]}
{"op":"mcm","clk":"5348555132","pt":1646218784119,"mc":[{"id":"1.195453626","rc":[{"atb":[[2.42,44.78],[2.46,0]],"id":38981227},{"atl":[[3.3,4]],"id":38981227},{"atb":[[2.5,4]],"id":36592903},{"atl":[[6.4,3.7],[6.2,19.23],[5.9,0]],"id":36592903},{"atb":[[2.34,45.63],[2.36,0]],"id":40559875},{"atl":[[4.5,3]],"id":40559875}],"con":true,"img":false}]}
{"op":"mcm","clk":"5348555155","pt":1646218784328,"mc":[{"id":"1.195453626","rc":[{"atl":[[3.25,3],[3.3,0]],"id":38981227},{"atb":[[2.52,4]],"id":36592903},{"atb":[[2.34,30.7]],"id":40559875},{"atl":[[4.5,0],[4.4,4]],"id":40559875}],"con":true,"img":false}]}
{"op":"mcm","clk":"5348555164","pt":1646218784431,"mc":[{"id":"1.195453626","rc":[{"atl":[[2.78,0]],"id":36592903},{"atb":[[2.36,14.71]],"id":40559875},{"atl":[[4.6,13.21]],"id":40559875}],"con":true,"img":false}]}
{"op":"mcm","clk":"5348555172","pt":1646218784534,"mc":[{"id":"1.195453626","rc":[{"atb":[[2.54,4]],"id":36592903},{"atl":[[1000,1.3]],"id":36592903},{"atl":[[4.5,1.25]],"id":40559875}],"con":true,"img":false}]}
{"op":"mcm","clk":"5348555180","pt":1646218784639,"mc":[{"id":"1.195453626","rc":[{"atl":[[3.25,0]],"id":38981227},{"atl":[[4.4,0]],"id":40559875}],"con":true,"img":false}]}
{"op":"mcm","clk":"5348555188","pt":1646218784743,"mc":[{"id":"1.195453626","rc":[{"atb":[[2.46,13.7]],"id":38981227},{"atb":[[2.54,0],[2.5,0],[2.52,0],[2.38,2]],"id":36592903},{"atb":[[3.15,4]],"id":40559875},{"atl":[[5.1,4.88],[4.9,0],[4.7,18.29]],"id":40559875}],"con":true,"img":false}]}
{"op":"mcm","clk":"5348555196","pt":1646218784799,"mc":[{"id":"1.195453626","rc":[{"atl":[[6.4,0],[6.8,3.45],[6.6,0]],"id":36592903},{"atb":[[1.27,74.07]],"id":37429121},{"atb":[[2.1,18.18]],"id":42099020},{"atl":[[5.3,0],[4.9,25.64]],"id":40559875}],"con":true,"img":false}]}
{"op":"mcm","clk":"5348555205","pt":1646218784900,"mc":[{"id":"1.195453626","rc":[{"atb":[[2.34,93.28],[2.52,65.79]],"id":38981227},{"atb":[[2.4,2]],"id":36592903},{"atb":[[1.18,0],[1.08,0],[1.17,250]],"id":37429121},{"atb":[[2.2,0],[2.16,0]],"id":42099020},{"atl":[[5.3,4.65],[4.7,0]],"id":40559875},{"atb":[[6.2,3.85],[5.9,0]],"id":39360156}],"con":true,"img":false}]}
{"op":"mcm","clk":"5348555213","pt":1646218785003,"mc":[{"id":"1.195453626","rc":[{"atb":[[3.3,4],[3.15,0]],"id":40559875},{"atl":[[5.1,0]],"id":40559875}],"con":true,"img":false}]}
{"op":"mcm","clk":"5348555237","pt":1646218785213,"mc":[{"id":"1.195453626","rc":[{"atb":[[3.6,0]],"id":42099020}],"con":true,"img":false}]}
{"op":"mcm","clk":"5348555254","pt":1646218785424,"mc":[{"id":"1.195453626","rc":[{"atb":[[2.42,4]],"id":36592903},{"atb":[[2.12,0]],"id":42099020},{"atb":[[3.35,3]],"id":40559875}],"con":true,"img":false}]}
{"op":"mcm","clk":"5348555289","pt":1646218785842,"mc":[{"id":"1.195453626","rc":[{"atb":[[1.93,0],[1.97,2.16]],"id":36592903}],"con":true,"img":false}]}
{"op":"mcm","clk":"5348555348","pt":1646218786519,"mc":[{"id":"1.195453626","rc":[{"atb":[[2.56,5.34]],"id":38981227},{"atb":[[1.9,9.26]],"id":36592903},{"atl":[[6.2,23.08]],"id":36592903},{"atb":[[3.35,0],[3.3,0],[2.46,5.71]],"id":40559875},{"atl":[[4.9,30.77]],"id":40559875}],"con":true,"img":false}]}
{"op":"mcm","clk":"5348555354","pt":1646218786622,"mc":[{"id":"1.195453626","rc":[{"atb":[[2.4,0],[2.42,0],[2.38,0]],"id":36592903}],"con":true,"img":false}]}
{"op":"mcm","clk":"5348555376","pt":1646218786934,"mc":[{"id":"1.195453626","rc":[{"atl":[[1000,0]],"id":36592903}],"con":true,"img":false}]}
{"op":"mcm","clk":"5348555390","pt":1646218787039,"mc":[{"id":"1.195453626","rc":[{"atl":[[2.78,1.3]],"id":36592903}],"con":true,"img":false}]}
{"op":"mcm","clk":"5348555405","pt":1646218787242,"mc":[{"id":"1.195453626","rc":[{"atb":[[1.94,1.4]],"id":36592903},{"atb":[[2.48,1.39]],"id":40559875}],"con":true,"img":false}]}
{"op":"mcm","clk":"5348555450","pt":1646218787814,"mc":[{"id":"1.195453626","rc":[{"atb":[[1.94,0]],"id":36592903}],"con":true,"img":false}]}
{"op":"mcm","clk":"5348555458","pt":1646218787918,"mc":[{"id":"1.195453626","rc":[{"atb":[[1.91,1.4]],"id":36592903}],"con":true,"img":false}]}
{"op":"mcm","clk":"5348555562","pt":1646218789118,"mc":[{"id":"1.195453626","rc":[{"atb":[[3.5,5]],"id":42099020}],"con":true,"img":false}]}
{"op":"mcm","clk":"5348555590","pt":1646218789434,"mc":[{"id":"1.195453626","rc":[{"atb":[[3.45,0]],"id":42099020}],"con":true,"img":false}]}
{"op":"mcm","clk":"5348555596","pt":1646218789534,"mc":[{"id":"1.195453626","rc":[{"atb":[[3.5,6.45]],"id":42099020}],"con":true,"img":false}]}
{"op":"mcm","clk":"5348555641","pt":1646218790106,"mc":[{"id":"1.195453626","rc":[{"atl":[[2.12,17.86],[2.14,0]],"id":37429121}],"con":true,"img":false}]}
{"op":"mcm","clk":"5348555723","pt":1646218791297,"mc":[{"id":"1.195453626","rc":[{"atb":[[1.92,7.57]],"id":36592903},{"atb":[[2.56,3.33]],"id":40559875}],"con":true,"img":false}]}
{"op":"mcm","clk":"5348555741","pt":1646218791507,"mc":[{"id":"1.195453626","rc":[{"atl":[[4.6,0]],"id":40559875}],"con":true,"img":false}]}
{"op":"mcm","clk":"5348555751","pt":1646218791611,"mc":[{"id":"1.195453626","rc":[{"atl":[[4.8,13.21]],"id":40559875}],"con":true,"img":false}]}
{"op":"mcm","clk":"5348555765","pt":1646218791819,"mc":[{"id":"1.195453626","rc":[{"atl":[[4.5,0]],"id":40559875}],"con":true,"img":false}]}
{"op":"mcm","clk":"5348555773","pt":1646218791923,"mc":[{"id":"1.195453626","rc":[{"atb":[[1.91,0]],"id":36592903},{"atl":[[4.8,14.46]],"id":40559875}],"con":true,"img":false}]}
{"op":"mcm","clk":"5348555780","pt":1646218792026,"mc":[{"id":"1.195453626","rc":[{"atb":[[1.93,1.4]],"id":36592903}],"con":true,"img":false}]}
{"op":"mcm","clk":"5348555883","pt":1646218793330,"mc":[{"id":"1.195453626","rc":[{"atb":[[2.58,6.1]],"id":38981227}],"con":true,"img":false}]}
{"op":"mcm","clk":"5348555954","pt":1646218794313,"mc":[{"id":"1.195453626","rc":[{"atb":[[2.58,4.75]],"id":38981227}],"con":true,"img":false}]}
{"op":"mcm","clk":"5348555961","pt":1646218794417,"mc":[{"id":"1.195453626","rc":[{"atb":[[2.64,5.93]],"id":38981227}],"con":true,"img":false}]}
{"op":"mcm","clk":"5348555986","pt":1646218794730,"mc":[{"id":"1.195453626","rc":[{"atb":[[2.42,65.91]],"id":38981227}],"con":true,"img":false}]}
{"op":"mcm","clk":"5348555992","pt":1646218794831,"mc":[{"id":"1.195453626","rc":[{"atb":[[2.06,112.39]],"id":42099020},{"atb":[[5.9,10.2]],"id":39360156}],"con":true,"img":false}]}
{"op":"mcm","clk":"5348556033","pt":1646218795353,"mc":[{"id":"1.195453626","rc":[{"atb":[[1.92,0]],"id":36592903}],"con":true,"img":false}]}
{"op":"mcm","clk":"5348556068","pt":1646218795830,"mc":[{"id":"1.195453626","rc":[{"atb":[[1.93,0]],"id":36592903}],"con":true,"img":false}]}
{"op":"mcm","clk":"5348556079","pt":1646218795925,"mc":[{"id":"1.195453626","rc":[{"atb":[[1.91,1.4]],"id":36592903}],"con":true,"img":false}]}
{"op":"mcm","clk":"5348556099","pt":1646218796239,"mc":[{"id":"1.195453626","rc":[{"atb":[[1.97,0],[1.93,2.16]],"id":36592903}],"con":true,"img":false}]}
{"op":"mcm","clk":"5348556119","pt":1646218796550,"mc":[{"id":"1.195453626","rc":[{"atl":[[5.1,12.2]],"id":40559875}],"con":true,"img":false}]}
{"op":"mcm","clk":"5348556144","pt":1646218796914,"mc":[{"id":"1.195453626","rc":[{"atb":[[5.3,0]],"id":39360156}],"con":true,"img":false}]}
{"op":"mcm","clk":"5348556271","pt":1646218798530,"mc":[{"id":"1.195453626","rc":[{"atb":[[1.9,17.61]],"id":36592903},{"atb":[[2.46,10.86]],"id":40559875}],"con":true,"img":false}]}
{"op":"mcm","clk":"5348556316","pt":1646218799047,"mc":[{"id":"1.195453626","rc":[{"atb":[[1.94,4.33]],"id":36592903}],"con":true,"img":false}]}
{"op":"mcm","clk":"5348556362","pt":1646218799724,"mc":[{"id":"1.195453626","rc":[{"atb":[[3.65,0]],"id":42099020},{"atb":[[2.54,0]],"id":40559875}],"con":true,"img":false}]}
{"op":"mcm","clk":"5348556371","pt":1646218799826,"mc":[{"id":"1.195453626","rc":[{"atb":[[3.55,1.66]],"id":42099020},{"atb":[[2.58,1.66]],"id":40559875}],"con":true,"img":false}]}
{"op":"mcm","clk":"5348556394","pt":1646218800139,"mc":[{"id":"1.195453626","rc":[{"atb":[[1.41,5.68],[1.25,599.25],[1.31,93.62]],"id":37429121},{"atl":[[2.16,72.75],[2.08,6.04]],"id":37429121}],"con":true,"img":false}]}
{"op":"mcm","clk":"5348556418","pt":1646218800352,"mc":[{"id":"1.195453626","rc":[{"atb":[[1.44,2.5],[1.4,5],[1.36,10]],"id":37429121}],"con":true,"img":false}]}
{"op":"mcm","clk":"5348556446","pt":1646218800564,"mc":[{"id":"1.195453626","rc":[{"atb":[[3.25,13],[3.3,11.66],[3.5,5],[3.7,2.5],[3.15,77.96]],"id":36986045},{"atl":[[7.4,28.84],[6.8,10.5]],"id":36986045},{"atb":[[3.85,5],[3.55,7.46],[3.05,28.95],[4.1,2.5],[3.65,10]],"id":42099020},{"atl":[[8.2,10.84]],"id":42099020},{"atb":[[2.5,5],[2.58,4.16],[2.46,47.53]],"id":40559875},{"atl":[[5.1,48.87],[4.7,11.66]],"id":40559875},{"atb":[[6.2,6.35]],"id":39360156},{"atl":[[18,4.71],[19,2.5],[22,5],[28,11.74]],"id":39360156}],"con":true,"img":false}]}
{"op":"mcm","clk":"5348556483","pt":1646218800864,"mc":[{"id":"1.195453626","rc":[{"atl":[[2.1,0]],"id":37429121},{"atl":[[4.8,13.21]],"id":40559875}],"con":true,"img":false}]}
{"op":"mcm","clk":"5348556492","pt":1646218800918,"mc":[{"id":"1.195453626","rc":[{"atb":[[2.56,0]],"id":38981227},{"atl":[[2.06,1.25]],"id":37429121},{"atl":[[4.6,1.25]],"id":40559875}],"con":true,"img":false}]}
{"op":"mcm","clk":"5348556506","pt":1646218801020,"mc":[{"id":"1.195453626","rc":[{"atb":[[2.64,11.73]],"id":38981227},{"atl":[[4.6,11.36]],"id":38981227},{"atl":[[34,0]],"id":39360156}],"con":true,"img":false}]}
{"op":"mcm","clk":"5348556521","pt":1646218801129,"mc":[{"id":"1.195453626","rc":[{"atb":[[2.58,26.62]],"id":38981227},{"atl":[[5,30.95]],"id":38981227},{"atl":[[38,2.72]],"id":39360156}],"con":true,"img":false}]}
{"op":"mcm","clk":"5348556566","pt":1646218801548,"mc":[{"id":"1.195453626","rc":[{"atb":[[3.25,11.64]],"id":36986045},{"atb":[[1.32,0],[1.31,69.37]],"id":37429121},{"atb":[[3.5,5],[3.05,25.28]],"id":42099020},{"atb":[[2.48,0],[2.46,42.38]],"id":40559875},{"atb":[[8.6,0]],"id":39360156}],"con":true,"img":false}]}
{"op":"mcm","clk":"5348556576","pt":1646218801650,"mc":[{"id":"1.195453626","rc":[{"atb":[[3.5,6.35]],"id":36986045},{"atb":[[1.41,7.17]],"id":37429121},{"atb":[[3.85,6.45]],"id":42099020},{"atb":[[2.5,6.39]],"id":40559875},{"atb":[[7.6,7.78]],"id":39360156}],"con":true,"img":false}]}
{"op":"mcm","clk":"5348556592","pt":1646218801757,"mc":[{"id":"1.195453626","rc":[{"atb":[[6.2,18.11]],"id":39360156}],"con":true,"img":false}]}
{"op":"mcm","clk":"5348556617","pt":1646218801968,"mc":[{"id":"1.195453626","rc":[{"atb":[[6.2,6.35]],"id":39360156}],"con":true,"img":false}]}
{"op":"mcm","clk":"5348556629","pt":1646218802025,"mc":[{"id":"1.195453626","rc":[{"atl":[[2.08,3.52]],"id":37429121}],"con":true,"img":false}]}
{"op":"mcm","clk":"5348556657","pt":1646218802332,"mc":[{"id":"1.195453626","rc":[{"atb":[[8.8,1.66]],"id":39360156}],"con":true,"img":false}]}
{"op":"mcm","clk":"5348556663","pt":1646218802435,"mc":[{"id":"1.195453626","rc":[{"atb":[[7.8,1.46]],"id":39360156}],"con":true,"img":false}]}
{"op":"mcm","clk":"5348556751","pt":1646218803334,"mc":[{"id":"1.195453626","rc":[{"atb":[[2.5,66.54],[2.3,76.78],[2.64,11.72],[2.58,26.62],[2.62,2.16],[2.4,71.29],[2.02,58.1],[2.42,65.91],[2.66,1.66]],"id":38981227},{"atl":[[8,10.37],[4.5,1.4],[5,30.95],[10,8.06],[6,7.25],[6.8,8.71]],"id":38981227},{"atb":[[3.1,19.81],[3.25,7.05],[3.5,6.35],[3.3,11.66],[3.2,7.2],[2.88,31.06],[2.86,53.66],[3.15,77.97],[2.96,50.92]],"id":36986045},{"atl":[[16,4.83],[10,6.54],[11,17.25],[7.4,28.84],[6.6,1.35],[8.4,4.9]],"id":36986045},{"atb":[[1.8,281.02],[1.58,112.81],[1.85,117.43],[1.91,1.4],[1.9,17.59],[1.86,73.95],[1.94,4.32],[1.93,2.16],[1.75,133.09]],"id":36592903},{"spl":[[1.01,2.72]],"id":36592903},{"atl":[[3.6,12.82],[4.5,20.74],[5.5,16.13],[4.4,19.07],[2.78,1.3],[3.75,13.2]],"id":36592903},{"atb":[[1.28,85.42],[1.2,499.1],[1.26,215.38],[1.33,0],[1.41,7.16],[1.25,599.28],[1.15,665.46],[1.31,69.34]],"id":37429121},{"atl":[[2.06,1.25],[2.44,25.2],[2.64,104.82],[2.84,39.45],[2.62,34.57],[2.16,72.76]],"id":37429121},{"trd":[[1.69,43.59]],"ltp":1.69,"tv":43.59,"id":37429121},{"atb":[[3.85,6.44],[3,23.01],[3.55,7.46],[2.98,50.41],[3.5,0],[3.05,25.28],[2.88,53.09],[3.4,17.79],[2.78,56.07]],"id":42099020},{"atl":[[8,1.33],[9,4.15],[10,6.01],[10.5,7.64],[8.2,10.84],[15.5,5]],"id":42099020},{"atb":[[2.5,6.39],[2.3,76.78],[2.58,4.16],[2.34,30.7],[2.56,0],[2.4,71.29],[2.52,2.16],[2.46,42.37],[1.91,72.48],[2.2,158.94]],"id":40559875},{"atl":[[4.8,13.21],[9.6,8.44],[4.6,1.25],[5.8,7.56],[7.6,10.99],[6.6,11.99]],"id":40559875},{"atb":[[4.5,52.98],[5,24.95],[5.5,38.85],[7.6,7.78],[8.8,1.66],[7.8,1.46],[7,9.26]],"id":39360156},{"atl":[[18.5,2.07],[38,2.72],[27,5.51]],"id":39360156}],"con":true,"img":false}]}
{"op":"mcm","clk":"5348556769","pt":1646218803541,"mc":[{"id":"1.195453626","rc":[{"atb":[[1.9,56.62]],"id":36592903},{"atl":[[3.75,52.23]],"id":36592903}],"con":true,"img":false}]}
{"op":"mcm","clk":"5348556818","pt":1646218804126,"mc":[{"id":"1.195453626","rc":[{"atb":[[1.12,0],[1.14,0],[1.16,0]],"id":37429121}],"con":true,"img":false}]}
{"op":"mcm","clk":"5348556913","pt":1646218804960,"mc":[{"id":"1.195453626","rc":[{"atb":[[2.02,73.53]],"id":42099020},{"atb":[[5.7,15.96]],"id":39360156}],"con":true,"img":false}]}
{"op":"mcm","clk":"5348557059","pt":1646218806532,"mc":[{"id":"1.195453626","rc":[{"spn":3.58,"spf":"NaN","id":38981227},{"spn":5.15,"spf":"NaN","id":36986045},{"spn":1.94,"spf":1.0,"id":36592903},{"spn":1.75,"spf":"NaN","id":37429121},{"spn":6.05,"spf":"NaN","id":42099020},{"atl":[[5.3,17.44]],"id":40559875},{"spn":3.59,"spf":"NaN","id":40559875},{"spn":13.4,"spf":"NaN","id":39360156}],"con":true,"img":false}]}
{"op":"mcm","clk":"5348557120","pt":1646218807352,"mc":[{"id":"1.195453626","rc":[{"atb":[[1.9,48.28]],"id":36592903},{"atb":[[1.34,22.07]],"id":37429121},{"atb":[[3.1,3.57]],"id":42099020},{"atb":[[2.52,7.1]],"id":40559875}],"con":true,"img":false}]}
{"op":"mcm","clk":"5348557150","pt":1646218807622,"mc":[{"id":"1.195453626","rc":[{"atb":[[1.45,5]],"id":37429121},{"atb":[[2.6,8.33]],"id":40559875}],"con":true,"img":false}]}
{"op":"mcm","clk":"5348557266","pt":1646218808920,"mc":[{"id":"1.195453626","rc":[{"atb":[[2.64,2.16],[2.52,4.93]],"id":40559875}],"con":true,"img":false}]}
{"op":"mcm","clk":"5348557286","pt":1646218809123,"mc":[{"id":"1.195453626","rc":[{"atb":[[3.3,10]],"id":36986045},{"atb":[[3.55,5.8]],"id":42099020},{"atb":[[2.58,2.5],[2.46,5.7]],"id":40559875},{"atb":[[8.8,0]],"id":39360156}],"con":true,"img":false}]}
{"op":"mcm","clk":"5348557299","pt":1646218809286,"mc":[{"id":"1.195453626","rc":[{"atb":[[3.75,1.66]],"id":36986045},{"atb":[[4.2,1.66]],"id":42099020},{"atb":[[2.62,1.66]],"id":40559875},{"atb":[[7.8,3.13]],"id":39360156}],"con":true,"img":false}]}
{"op":"mcm","clk":"5348557386","pt":1646218810167,"mc":[{"id":"1.195453626","rc":[{"atb":[[1.23,250]],"id":37429121}],"con":true,"img":false}]}
{"op":"mcm","clk":"5348557394","pt":1646218810218,"mc":[{"id":"1.195453626","rc":[{"atb":[[1.46,1.68]],"id":37429121}],"con":true,"img":false}]}
{"op":"mcm","clk":"5348557450","pt":1646218810749,"mc":[{"id":"1.195453626","rc":[{"atb":[[2.52,0]],"id":40559875}],"con":true,"img":false}]}
{"op":"mcm","clk":"5348557506","pt":1646218811320,"mc":[{"id":"1.195453626","rc":[{"atb":[[2.6,0]],"id":40559875}],"con":true,"img":false}]}
{"op":"mcm","clk":"5348557678","pt":1646218813356,"mc":[{"id":"1.195453626","rc":[{"atb":[[1.45,0]],"id":37429121}],"con":true,"img":false}]}
{"op":"mcm","clk":"5348557686","pt":1646218813461,"mc":[{"id":"1.195453626","rc":[{"atb":[[1.94,12.31]],"id":36592903}],"con":true,"img":false}]}
{"op":"mcm","clk":"5348557817","pt":1646218814870,"mc":[{"id":"1.195453626","rc":[{"atb":[[2.58,29.12]],"id":38981227},{"atb":[[1.99,126.26]],"id":42099020},{"atb":[[5.5,49.96]],"id":39360156}],"con":true,"img":false}]}
{"op":"mcm","clk":"5348557871","pt":1646218815337,"mc":[{"id":"1.195453626","rc":[{"atb":[[2.66,4.32]],"id":40559875}],"con":true,"img":false}]}
{"op":"mcm","clk":"5348557974","pt":1646218816425,"mc":[{"id":"1.195453626","rc":[{"atb":[[2.46,10.84]],"id":40559875}],"con":true,"img":false}]}
{"op":"mcm","clk":"5348557986","pt":1646218816526,"mc":[{"id":"1.195453626","rc":[{"atl":[[5.5,27.78]],"id":40559875}],"con":true,"img":false}]}
{"op":"mcm","clk":"5348558016","pt":1646218816847,"mc":[{"id":"1.195453626","rc":[{"atb":[[2.08,0]],"id":42099020}],"con":true,"img":false}]}
{"op":"mcm","clk":"5348558043","pt":1646218817147,"mc":[{"id":"1.195453626","rc":[{"atb":[[1.42,5.46]],"id":37429121}],"con":true,"img":false}]}
{"op":"mcm","clk":"5348558060","pt":1646218817355,"mc":[{"id":"1.195453626","rc":[{"atb":[[2.58,34.39]],"id":38981227}],"con":true,"img":false}]}
{"op":"mcm","clk":"5348558086","pt":1646218817666,"mc":[{"id":"1.195453626","rc":[{"atb":[[1.44,7.01]],"id":37429121}],"con":true,"img":false}]}
{"op":"mcm","clk":"5348558097","pt":1646218817768,"mc":[{"id":"1.195453626","rc":[{"atb":[[1.41,26.12],[1.31,26.86]],"id":37429121}],"con":true,"img":false}]}
{"op":"mcm","clk":"5348558109","pt":1646218817876,"mc":[{"id":"1.195453626","rc":[{"atb":[[1.41,22.6]],"id":37429121}],"con":true,"img":false}]}
{"op":"mcm","clk":"5348558129","pt":1646218818032,"mc":[{"id":"1.195453626","rc":[{"atb":[[3.3,37.09],[3.7,9.14],[3.15,55.73]],"id":36986045},{"atb":[[3.05,4.06],[4.1,6.4],[3.65,29.29]],"id":42099020},{"atl":[[5.1,12.2],[4.9,56.63]],"id":40559875},{"atl":[[19,14.26],[28,3.7]],"id":39360156}],"con":true,"img":false}]}
{"op":"mcm","clk":"5348558151","pt":1646218818240,"mc":[{"id":"1.195453626","rc":[{"atb":[[3.25,0]],"id":36986045}],"con":true,"img":false}]}
{"op":"mcm","clk":"5348558164","pt":1646218818344,"mc":[{"id":"1.195453626","rc":[{"atb":[[3.55,0]],"id":42099020}],"con":true,"img":false}]}
{"op":"mcm","clk":"5348558224","pt":1646218819073,"mc":[{"id":"1.195453626","rc":[{"atl":[[10,0]],"id":42099020}],"con":true,"img":false}]}
{"op":"mcm","clk":"5348558236","pt":1646218819174,"mc":[{"id":"1.195453626","rc":[{"atl":[[11.5,6.01]],"id":42099020}],"con":true,"img":false}]}
{"op":"mcm","clk":"5348558250","pt":1646218819381,"mc":[{"id":"1.195453626","rc":[{"atb":[[1.97,2.16]],"id":36592903},{"atb":[[1.45,2.16]],"id":37429121}],"con":true,"img":false}]}
{"op":"mcm","clk":"5348558260","pt":1646218819433,"mc":[{"id":"1.195453626","rc":[{"atb":[[1.93,0]],"id":36592903},{"atb":[[1.41,20.44]],"id":37429121}],"con":true,"img":false}]}
{"op":"mcm","clk":"5348558273","pt":1646218819538,"mc":[{"id":"1.195453626","rc":[{"atb":[[1.9,9.25]],"id":36592903}],"con":true,"img":false}]}
{"op":"mcm","clk":"5348558318","pt":1646218819954,"mc":[{"id":"1.195453626","rc":[{"atb":[[2.58,29.64]],"id":38981227},{"atb":[[3.2,3.78]],"id":36986045},{"atb":[[1.34,0]],"id":37429121},{"atb":[[3.1,0]],"id":42099020}],"con":true,"img":false}]}
{"op":"mcm","clk":"5348558341","pt":1646218820164,"mc":[{"id":"1.195453626","rc":[{"atb":[[1.21,250]],"id":37429121}],"con":true,"img":false}]}
{"op":"mcm","clk":"5348558431","pt":1646218821057,"mc":[{"id":"1.195453626","rc":[{"atb":[[1.9,46.95]],"id":36592903}],"con":true,"img":false}]}
{"op":"mcm","clk":"5348558556","pt":1646218822480,"mc":[{"id":"1.195453626","rc":[{"atb":[[1.94,7.98]],"id":36592903},{"atb":[[1.42,0]],"id":37429121}],"con":true,"img":false}]}
{"op":"mcm","clk":"5348558614","pt":1646218823054,"mc":[{"id":"1.195453626","rc":[{"atb":[[1.26,0]],"id":37429121}],"con":true,"img":false}]}
{"op":"mcm","clk":"5348558622","pt":1646218823155,"mc":[{"id":"1.195453626","rc":[{"atb":[[1.28,300.81]],"id":37429121}],"con":true,"img":false}]}
{"op":"mcm","clk":"5348558691","pt":1646218824101,"mc":[{"id":"1.195453626","rc":[{"atl":[[8,7.56],[9,0]],"id":42099020}],"con":true,"img":false}]}
{"op":"mcm","clk":"5348558709","pt":1646218824241,"mc":[{"id":"1.195453626","rc":[{"atl":[[8,15.55]],"id":42099020}],"con":true,"img":false}]}
{"op":"mcm","clk":"5348558727","pt":1646218824452,"mc":[{"id":"1.195453626","rc":[{"atl":[[8.2,5.04]],"id":42099020}],"con":true,"img":false}]}
{"op":"mcm","clk":"5348558838","pt":1646218825442,"mc":[{"id":"1.195453626","rc":[{"atb":[[2.64,16.3]],"id":38981227},{"atb":[[3.4,3.13]],"id":36986045},{"atb":[[1.31,51.08]],"id":37429121},{"atb":[[3.75,2.73]],"id":42099020}],"con":true,"img":false}]}
{"op":"mcm","clk":"5348558887","pt":1646218826063,"mc":[{"id":"1.195453626","rc":[{"atb":[[1.92,7.56]],"id":36592903},{"atb":[[1.47,3.36]],"id":37429121}],"con":true,"img":false}]}
{"op":"mcm","clk":"5348558895","pt":1646218826167,"mc":[{"id":"1.195453626","rc":[{"atb":[[2.62,0]],"id":40559875}],"con":true,"img":false}]}
{"op":"mcm","clk":"5348558917","pt":1646218826375,"mc":[{"id":"1.195453626","rc":[{"atb":[[2.68,1.66]],"id":40559875}],"con":true,"img":false}]}
{"op":"mcm","clk":"5348559200","pt":1646218829675,"mc":[{"id":"1.195453626","rc":[{"atb":[[2.66,0]],"id":40559875}],"con":true,"img":false}]}
{"op":"mcm","clk":"5348559221","pt":1646218829883,"mc":[{"id":"1.195453626","rc":[{"atb":[[2.5,35.35]],"id":40559875}],"con":true,"img":false}]}
{"op":"mcm","clk":"5348559300","pt":1646218830876,"mc":[{"id":"1.195453626","rc":[{"atb":[[2.64,0],[2.56,2.16]],"id":40559875}],"con":true,"img":false}]}
{"op":"mcm","clk":"5348559368","pt":1646218831553,"mc":[{"id":"1.195453626","rc":[{"atb":[[2.46,5.14]],"id":40559875}],"con":true,"img":false}]}
{"op":"mcm","clk":"5348559399","pt":1646218831967,"mc":[{"id":"1.195453626","rc":[{"atl":[[8,9.32]],"id":42099020}],"con":true,"img":false}]}
{"op":"mcm","clk":"5348559409","pt":1646218832074,"mc":[{"id":"1.195453626","rc":[{"atl":[[9.4,6.22]],"id":42099020}],"con":true,"img":false}]}
{"op":"mcm","clk":"5348559416","pt":1646218832177,"mc":[{"id":"1.195453626","rc":[{"atl":[[2.8,73.73]],"id":36592903}],"con":true,"img":false}]}
{"op":"mcm","clk":"5348559475","pt":1646218832959,"mc":[{"id":"1.195453626","rc":[{"atl":[[17.5,1.24]],"id":39360156}],"con":true,"img":false}]}
{"op":"mcm","clk":"5348559486","pt":1646218833064,"mc":[{"id":"1.195453626","rc":[{"atl":[[17,5]],"id":39360156}],"con":true,"img":false}]}
{"op":"mcm","clk":"5348559493","pt":1646218833167,"mc":[{"id":"1.195453626","rc":[{"atb":[[1.9,9.25]],"id":36592903},{"atl":[[2.12,0],[2.14,17.54]],"id":37429121},{"atl":[[18,0]],"id":39360156}],"con":true,"img":false}]}
{"op":"mcm","clk":"5348559540","pt":1646218833792,"mc":[{"id":"1.195453626","rc":[{"atb":[[2.6,5.42]],"id":40559875}],"con":true,"img":false}]}
{"op":"mcm","clk":"5348559558","pt":1646218834001,"mc":[{"id":"1.195453626","rc":[{"atb":[[2.5,6.39]],"id":40559875},{"atb":[[7,0]],"id":39360156}],"con":true,"img":false}]}
{"op":"mcm","clk":"5348559570","pt":1646218834060,"mc":[{"id":"1.195453626","rc":[{"atb":[[6.2,15.61]],"id":39360156}],"con":true,"img":false}]}
{"op":"mcm","clk":"5348559579","pt":1646218834161,"mc":[{"id":"1.195453626","rc":[{"atb":[[6.2,27.8]],"id":39360156}],"con":true,"img":false}]}
{"op":"mcm","clk":"5348559591","pt":1646218834269,"mc":[{"id":"1.195453626","rc":[{"atb":[[1.94,0]],"id":36592903},{"atb":[[2.46,0]],"id":40559875}],"con":true,"img":false}]}
{"op":"mcm","clk":"5348559638","pt":1646218834888,"mc":[{"id":"1.195453626","rc":[{"atb":[[1.44,24.69],[1.47,7.51]],"id":37429121}],"con":true,"img":false}]}
{"op":"mcm","clk":"5348559647","pt":1646218834996,"mc":[{"id":"1.195453626","rc":[{"atb":[[1.41,1.48]],"id":37429121}],"con":true,"img":false}]}
{"op":"mcm","clk":"5348559656","pt":1646218835095,"mc":[{"id":"1.195453626","rc":[{"atb":[[1.44,20.18]],"id":37429121}],"con":true,"img":false}]}
{"op":"mcm","clk":"5348559680","pt":1646218835308,"mc":[{"id":"1.195453626","rc":[{"atb":[[3.3,10],[3.4,31.43]],"id":36986045},{"atb":[[3.75,19.97],[3.65,10]],"id":42099020},{"atl":[[18.5,14.26],[19,2.5]],"id":39360156}],"con":true,"img":false}]}
{"op":"mcm","clk":"5348559915","pt":1646218838186,"mc":[{"id":"1.195453626","rc":[{"atb":[[1.9,44.47]],"id":36592903}],"con":true,"img":false}]}
{"op":"mcm","clk":"5348559972","pt":1646218838866,"mc":[{"id":"1.195453626","rc":[{"atl":[[17.5,0]],"id":39360156}],"con":true,"img":false}]}
{"op":"mcm","clk":"5348559982","pt":1646218838969,"mc":[{"id":"1.195453626","rc":[{"atl":[[16.5,1.24],[17,0]],"id":39360156}],"con":true,"img":false}]}
{"op":"mcm","clk":"5348559989","pt":1646218839073,"mc":[{"id":"1.195453626","rc":[{"atl":[[16,5.33]],"id":39360156}],"con":true,"img":false}]}
{"op":"mcm","clk":"5348560105","pt":1646218840479,"mc":[{"id":"1.195453626","rc":[{"atb":[[3.4,28.3]],"id":36986045},{"atb":[[3.75,17.24]],"id":42099020}],"con":true,"img":false}]}
{"op":"mcm","clk":"5348560328","pt":1646218843099,"mc":[{"id":"1.195453626","rc":[{"atb":[[2.68,0]],"id":40559875},{"atl":[[38,0]],"id":39360156}],"con":true,"img":false}]}
{"op":"mcm","clk":"5348560337","pt":1646218843195,"mc":[{"id":"1.195453626","rc":[{"atl":[[27,8.24]],"id":39360156}],"con":true,"img":false}]}
{"op":"mcm","clk":"5348560340","pt":1646218843297,"mc":[{"id":"1.195453626","rc":[{"atb":[[2.62,1.66]],"id":40559875}],"con":true,"img":false}]}
{"op":"mcm","clk":"5348560479","pt":1646218845006,"mc":[{"id":"1.195453626","rc":[{"atl":[[3.7,24.52],[4.4,0]],"id":36592903},{"atb":[[3.4,0]],"id":42099020}],"con":true,"img":false}]}
{"op":"mcm","clk":"5348560488","pt":1646218845063,"mc":[{"id":"1.195453626","rc":[{"atb":[[3.8,17.79]],"id":42099020}],"con":true,"img":false}]}
{"op":"mcm","clk":"5348560498","pt":1646218845220,"mc":[{"id":"1.195453626","rc":[{"atl":[[3.7,80.55],[3.75,13.2]],"id":36592903}],"con":true,"img":false}]}
{"op":"mcm","clk":"5348560533","pt":1646218845581,"mc":[{"id":"1.195453626","rc":[{"atl":[[3.7,56.03],[4.2,19.07]],"id":36592903}],"con":true,"img":false}]}
{"op":"mcm","clk":"5348560603","pt":1646218846370,"mc":[{"id":"1.195453626","rc":[{"atb":[[3.5,9.36]],"id":36986045},{"atb":[[1.94,7.98]],"id":36592903},{"atb":[[3.05,7.72]],"id":42099020},{"atb":[[2.46,5.14]],"id":40559875}],"con":true,"img":false}]}
{"op":"mcm","clk":"5348560618","pt":1646218846579,"mc":[{"id":"1.195453626","rc":[{"atb":[[1.9,9.25]],"id":36592903}],"con":true,"img":false}]}
{"op":"mcm","clk":"5348560645","pt":1646218846791,"mc":[{"id":"1.195453626","rc":[{"atb":[[2.56,32.17]],"id":40559875}],"con":true,"img":false}]}
{"op":"mcm","clk":"5348560727","pt":1646218847566,"mc":[{"id":"1.195453626","rc":[{"atb":[[3.2,0]],"id":36986045}],"con":true,"img":false}]}
{"op":"mcm","clk":"5348560884","pt":1646218849471,"mc":[{"id":"1.195453626","rc":[{"atb":[[1.94,0]],"id":36592903},{"atb":[[2.46,0]],"id":40559875}],"con":true,"img":false}]}
{"op":"mcm","clk":"5348561075","pt":1646218852118,"mc":[{"id":"1.195453626","rc":[{"atb":[[3.8,39.57],[3.75,0]],"id":42099020}],"con":true,"img":false}]}
{"op":"mcm","clk":"5348561214","pt":1646218853520,"mc":[{"id":"1.195453626","rc":[{"atl":[[27,5.51]],"id":39360156}],"con":true,"img":false}]}
{"op":"mcm","clk":"5348561223","pt":1646218853617,"mc":[{"id":"1.195453626","rc":[{"atl":[[26,2.72]],"id":39360156}],"con":true,"img":false}]}
{"op":"mcm","clk":"5348561374","pt":1646218855018,"mc":[{"id":"1.195453626","rc":[{"atb":[[1.9,44.47]],"id":36592903}],"con":true,"img":false}]}
{"op":"mcm","clk":"5348561413","pt":1646218855386,"mc":[{"id":"1.195453626","rc":[{"atb":[[1.9,52.81]],"id":36592903},{"atb":[[3.05,4.06]],"id":42099020},{"atb":[[2.62,6.29]],"id":40559875}],"con":true,"img":false}]}
{"op":"mcm","clk":"5348561432","pt":1646218855588,"mc":[{"id":"1.195453626","rc":[{"atb":[[2.56,2.16]],"id":40559875}],"con":true,"img":false}]}
{"op":"mcm","clk":"5348561605","pt":1646218858295,"mc":[{"id":"1.195453626","rc":[{"atl":[[16.5,0]],"id":39360156}],"con":true,"img":false}]}
{"op":"mcm","clk":"5348561612","pt":1646218858398,"mc":[{"id":"1.195453626","rc":[{"atl":[[15.5,1.24]],"id":39360156}],"con":true,"img":false}]}
{"op":"mcm","clk":"5348561620","pt":1646218858513,"mc":[{"id":"1.195453626","rc":[{"atl":[[16,0],[18.5,2.07],[19,16.52]],"id":39360156}],"con":true,"img":false}]}
{"op":"mcm","clk":"5348561631","pt":1646218858609,"mc":[{"id":"1.195453626","rc":[{"atl":[[15.5,6.76]],"id":39360156}],"con":true,"img":false}]}
{"op":"mcm","clk":"5348561672","pt":1646218859082,"mc":[{"id":"1.195453626","rc":[{"atl":[[15.5,5.52]],"id":39360156}],"con":true,"img":false}]}
{"op":"mcm","clk":"5348561676","pt":1646218859189,"mc":[{"id":"1.195453626","rc":[{"atl":[[1000,1.24]],"id":39360156}],"con":true,"img":false}]}
{"op":"mcm","clk":"5348561685","pt":1646218859298,"mc":[{"id":"1.195453626","rc":[{"atb":[[1.9,44.47]],"id":36592903},{"atb":[[2.62,1.66]],"id":40559875},{"atl":[[15.5,0]],"id":39360156}],"con":true,"img":false}]}
{"op":"mcm","clk":"5348561696","pt":1646218859498,"mc":[{"id":"1.195453626","rc":[{"atl":[[18,4.71]],"id":39360156}],"con":true,"img":false}]}
{"op":"mcm","clk":"5348561872","pt":1646218861526,"mc":[{"id":"1.195453626","rc":[{"atl":[[2.24,45.16],[2.62,0]],"id":37429121}],"con":true,"img":false}]}
{"op":"mcm","clk":"5348562015","pt":1646218863196,"mc":[{"id":"1.195453626","rc":[{"atb":[[3.5,12.69]],"id":36986045}],"con":true,"img":false}]}
{"op":"mcm","clk":"5348562035","pt":1646218863413,"mc":[{"id":"1.195453626","rc":[{"atb":[[2.56,32.17]],"id":40559875}],"con":true,"img":false}]}
{"op":"mcm","clk":"5348562046","pt":1646218863503,"mc":[{"id":"1.195453626","rc":[{"atb":[[3.05,0]],"id":42099020}],"con":true,"img":false}]}
{"op":"mcm","clk":"5348562054","pt":1646218863610,"mc":[{"id":"1.195453626","rc":[{"atb":[[2.46,5.7]],"id":40559875}],"con":true,"img":false}]}
{"op":"mcm","clk":"5348562339","pt":1646218866532,"mc":[{"id":"1.195453626","rc":[{"atb":[[3.85,2.5],[3.5,7.69],[3.3,0],[3.45,10],[3.7,6.64],[3.65,5]],"id":36986045},{"spn":5.22,"spf":"NaN","id":36986045},{"spn":1.95,"spf":1.0,"id":36592903},{"spn":1.76,"spf":"NaN","id":37429121},{"spn":6.1,"spf":"NaN","id":42099020},{"spn":3.61,"spf":"NaN","id":40559875},{"spn":12.9,"spf":"NaN","id":39360156}],"con":true,"img":false}]}
{"op":"mcm","clk":"5348562357","pt":1646218866699,"mc":[{"id":"1.195453626","rc":[{"atb":[[3.85,9.36],[3.4,0],[3.65,29.55]],"id":36986045}],"con":true,"img":false}]}
{"op":"mcm","clk":"5348562375","pt":1646218866899,"mc":[{"id":"1.195453626","rc":[{"atb":[[3.7,0]],"id":36986045}],"con":true,"img":false}]}
{"op":"mcm","clk":"5348562412","pt":1646218867319,"mc":[{"id":"1.195453626","rc":[{"atb":[[3.5,4.68]],"id":36986045},{"atb":[[1.94,7.98]],"id":36592903}],"con":true,"img":false}]}
{"op":"mcm","clk":"5348562500","pt":1646218868309,"mc":[{"id":"1.195453626","rc":[{"atb":[[3.85,1.44],[4.1,3.9],[3.9,5],[4.2,4.16],[3.65,0]],"id":42099020}],"con":true,"img":false}]}
{"op":"mcm","clk":"5348562517","pt":1646218868509,"mc":[{"id":"1.195453626","rc":[{"atb":[[4.2,11.04]],"id":42099020}],"con":true,"img":false}]}
{"op":"mcm","clk":"5348562527","pt":1646218868614,"mc":[{"id":"1.195453626","rc":[{"atb":[[3.8,17.79],[3.9,18.76]],"id":42099020}],"con":true,"img":false}]}
{"op":"mcm","clk":"5348562540","pt":1646218868717,"mc":[{"id":"1.195453626","rc":[{"atb":[[4.1,0]],"id":42099020},{"atl":[[1000,0]],"id":39360156}],"con":true,"img":false}]}
{"op":"mcm","clk":"5348562547","pt":1646218868820,"mc":[{"id":"1.195453626","rc":[{"atl":[[17.5,1.24]],"id":39360156}],"con":true,"img":false}]}
{"op":"mcm","clk":"5348562725","pt":1646218870696,"mc":[{"id":"1.195453626","rc":[{"atb":[[2.62,6.29]],"id":40559875}],"con":true,"img":false}]}
{"op":"mcm","clk":"5348562747","pt":1646218870909,"mc":[{"id":"1.195453626","rc":[{"atb":[[2.56,2.16]],"id":40559875}],"con":true,"img":false}]}
{"op":"mcm","clk":"5348562793","pt":1646218871423,"mc":[{"id":"1.195453626","rc":[{"atb":[[1.92,38.78]],"id":36592903}],"con":true,"img":false}]}
{"op":"mcm","clk":"5348562801","pt":1646218871525,"mc":[{"id":"1.195453626","rc":[{"atb":[[1.9,9.25]],"id":36592903}],"con":true,"img":false}]}
{"op":"mcm","clk":"5348563045","pt":1646218874435,"mc":[{"id":"1.195453626","rc":[{"atb":[[3.5,36.51],[3.65,5]],"id":36986045}],"con":true,"img":false}]}
{"op":"mcm","clk":"5348563103","pt":1646218874909,"mc":[{"id":"1.195453626","rc":[{"atl":[[18.5,13.83],[19,2.5]],"id":39360156}],"con":true,"img":false}]}
{"op":"mcm","clk":"5348563131","pt":1646218875022,"mc":[{"id":"1.195453626","rc":[{"atb":[[6.2,18.54]],"id":39360156},{"atl":[[17,5]],"id":39360156}],"con":true,"img":false}]}
{"op":"mcm","clk":"5348563178","pt":1646218875122,"mc":[{"id":"1.195453626","rc":[{"atb":[[6.4,9.26]],"id":39360156}],"con":true,"img":false}]}
{"op":"mcm","clk":"5348563191","pt":1646218875233,"mc":[{"id":"1.195453626","rc":[{"atl":[[18,0]],"id":39360156}],"con":true,"img":false}]}
{"op":"mcm","clk":"5348563198","pt":1646218875327,"mc":[{"id":"1.195453626","rc":[{"atb":[[6.4,23.83],[6.2,6.35]],"id":39360156}],"con":true,"img":false}]}
{"op":"mcm","clk":"5348563308","pt":1646218876321,"mc":[{"id":"1.195453626","rc":[{"atb":[[1.94,0]],"id":36592903},{"atb":[[3.8,48.35],[3.9,5]],"id":42099020},{"atb":[[2.62,1.66]],"id":40559875}],"con":true,"img":false}]}
{"op":"mcm","clk":"5348563382","pt":1646218877114,"mc":[{"id":"1.195453626","rc":[{"atb":[[3.75,0]],"id":36986045}],"con":true,"img":false}]}
{"op":"mcm","clk":"5348563398","pt":1646218877322,"mc":[{"id":"1.195453626","rc":[{"atb":[[3.9,1.66]],"id":36986045}],"con":true,"img":false}]}
{"op":"mcm","clk":"5348563550","pt":1646218879026,"mc":[{"id":"1.195453626","rc":[{"atb":[[1.9,86.66]],"id":36592903}],"con":true,"img":false}]}
{"op":"mcm","clk":"5348563566","pt":1646218879233,"mc":[{"id":"1.195453626","rc":[{"atb":[[1.92,7.56]],"id":36592903}],"con":true,"img":false}]}
{"op":"mcm","clk":"5348563618","pt":1646218879755,"mc":[{"id":"1.195453626","rc":[{"atb":[[2.56,32.17]],"id":40559875}],"con":true,"img":false}]}
{"op":"mcm","clk":"5348564141","pt":1646218885235,"mc":[{"id":"1.195453626","rc":[{"atb":[[3.6,2.89]],"id":36986045}],"con":true,"img":false}]}
{"op":"mcm","clk":"5348564161","pt":1646218885441,"mc":[{"id":"1.195453626","rc":[{"atb":[[3.6,31.53],[3.5,4.68]],"id":36986045}],"con":true,"img":false}]}
{"op":"mcm","clk":"5348564361","pt":1646218888141,"mc":[{"id":"1.195453626","rc":[{"atb":[[3.6,28.64]],"id":36986045},{"atb":[[1.94,7.98]],"id":36592903},{"atb":[[2.62,6.29]],"id":40559875}],"con":true,"img":false}]}
{"op":"mcm","clk":"5348564376","pt":1646218888343,"mc":[{"id":"1.195453626","rc":[{"atb":[[1.92,38.78],[1.9,9.25]],"id":36592903},{"atb":[[2.56,2.16]],"id":40559875}],"con":true,"img":false}]}
{"op":"mcm","clk":"5348564661","pt":1646218891358,"mc":[{"id":"1.195453626","rc":[{"atb":[[1.94,0]],"id":36592903},{"atb":[[2.62,1.66]],"id":40559875}],"con":true,"img":false}]}
{"op":"mcm","clk":"5348564682","pt":1646218891569,"mc":[{"id":"1.195453626","rc":[{"atb":[[3.5,3.33]],"id":36986045},{"atb":[[1.41,0]],"id":37429121},{"atb":[[3.85,0]],"id":42099020},{"atb":[[2.5,5]],"id":40559875}],"con":true,"img":false}]}
{"op":"mcm","clk":"5348564690","pt":1646218891670,"mc":[{"id":"1.195453626","rc":[{"atb":[[3.5,0],[3.9,3.02]],"id":36986045},{"atb":[[1.48,1.48]],"id":37429121},{"atb":[[4.3,1.44]],"id":42099020},{"atb":[[2.6,6.81]],"id":40559875}],"con":true,"img":false}]}
{"op":"mcm","clk":"5348564709","pt":1646218891833,"mc":[{"id":"1.195453626","rc":[{"atb":[[3.6,0],[3.9,12.82],[3.65,31.13]],"id":36986045}],"con":true,"img":false}]}
{"op":"mcm","clk":"5348564724","pt":1646218892045,"mc":[{"id":"1.195453626","rc":[{"atb":[[3.85,2.5]],"id":36986045}],"con":true,"img":false}]}
{"op":"mcm","clk":"5348564741","pt":1646218892255,"mc":[{"id":"1.195453626","rc":[{"atl":[[17.5,0]],"id":39360156}],"con":true,"img":false}]}
{"op":"mcm","clk":"5348564749","pt":1646218892355,"mc":[{"id":"1.195453626","rc":[{"atl":[[16.5,1.24]],"id":39360156}],"con":true,"img":false}]}
{"op":"mcm","clk":"5348564755","pt":1646218892459,"mc":[{"id":"1.195453626","rc":[{"atl":[[19,17.8]],"id":39360156}],"con":true,"img":false}]}
{"op":"mcm","clk":"5348564761","pt":1646218892563,"mc":[{"id":"1.195453626","rc":[{"atl":[[16,5.33],[17,0],[18.5,2.07]],"id":39360156}],"con":true,"img":false}]}
{"op":"mcm","clk":"5348564770","pt":1646218892668,"mc":[{"id":"1.195453626","rc":[{"atl":[[19,2.5]],"id":39360156}],"con":true,"img":false}]}
{"op":"mcm","clk":"5348564790","pt":1646218892929,"mc":[{"id":"1.195453626","rc":[{"atb":[[2.64,2.16],[2.56,0]],"id":40559875}],"con":true,"img":false}]}
{"op":"mcm","clk":"5348564831","pt":1646218893449,"mc":[{"id":"1.195453626","rc":[{"atl":[[16.5,0]],"id":39360156}],"con":true,"img":false}]}
{"op":"mcm","clk":"5348564841","pt":1646218893551,"mc":[{"id":"1.195453626","rc":[{"atl":[[1000,1.24]],"id":39360156}],"con":true,"img":false}]}
{"op":"mcm","clk":"5348564851","pt":1646218893654,"mc":[{"id":"1.195453626","rc":[{"atl":[[16,0]],"id":39360156}],"con":true,"img":false}]}
{"op":"mcm","clk":"5348564871","pt":1646218893865,"mc":[{"id":"1.195453626","rc":[{"atl":[[18.5,6.29]],"id":39360156}],"con":true,"img":false}]}
{"op":"mcm","clk":"5348564887","pt":1646218894074,"mc":[{"id":"1.195453626","rc":[{"atl":[[27,2.79]],"id":39360156}],"con":true,"img":false}]}
{"op":"mcm","clk":"5348564897","pt":1646218894172,"mc":[{"id":"1.195453626","rc":[{"atl":[[34,2.72]],"id":39360156}],"con":true,"img":false}]}
{"op":"mcm","clk":"5348564983","pt":1646218894963,"mc":[{"id":"1.195453626","rc":[{"atb":[[1.47,4.15]],"id":37429121},{"atb":[[2.6,1.39]],"id":40559875}],"con":true,"img":false}]}
{"op":"mcm","clk":"5348565012","pt":1646218895170,"mc":[{"id":"1.195453626","rc":[{"atb":[[2.62,0]],"id":40559875}],"con":true,"img":false}]}
{"op":"mcm","clk":"5348565033","pt":1646218895372,"mc":[{"id":"1.195453626","rc":[{"atb":[[2.66,1.66]],"id":40559875}],"con":true,"img":false}]}
{"op":"mcm","clk":"5348565063","pt":1646218895687,"mc":[{"id":"1.195453626","rc":[{"atb":[[1.48,0]],"id":37429121},{"atb":[[2.5,31.88],[2.6,0]],"id":40559875}],"con":true,"img":false}]}
{"op":"mcm","clk":"5348565076","pt":1646218895745,"mc":[{"id":"1.195453626","rc":[{"atb":[[1.9,86.66]],"id":36592903},{"atb":[[1.45,3.64]],"id":37429121},{"atb":[[2.5,33.27]],"id":40559875}],"con":true,"img":false}]}
{"op":"mcm","clk":"5348565084","pt":1646218895855,"mc":[{"id":"1.195453626","rc":[{"atb":[[1.92,7.56]],"id":36592903}],"con":true,"img":false}]}
{"op":"mcm","clk":"5348565305","pt":1646218898848,"mc":[{"id":"1.195453626","rc":[{"atb":[[1.48,8.3]],"id":37429121},{"atb":[[2.6,5]],"id":40559875}],"con":true,"img":false}]}
{"op":"mcm","clk":"5348565336","pt":1646218899069,"mc":[{"id":"1.195453626","rc":[{"atb":[[1.44,2.5],[1.45,24.08],[1.48,14.05]],"id":37429121},{"atb":[[2.5,6.39]],"id":40559875}],"con":true,"img":false}]}
{"op":"mcm","clk":"5348565363","pt":1646218899242,"mc":[{"id":"1.195453626","rc":[{"atb":[[1.47,0]],"id":37429121}],"con":true,"img":false}]}
{"op":"mcm","clk":"5348565430","pt":1646218899781,"mc":[{"id":"1.195453626","rc":[{"atb":[[1.45,22.6]],"id":37429121}],"con":true,"img":false}]}
{"op":"mcm","clk":"5348565440","pt":1646218899836,"mc":[{"id":"1.195453626","rc":[{"atb":[[1.49,1.48]],"id":37429121}],"con":true,"img":false}]}
{"op":"mcm","clk":"5348565485","pt":1646218900197,"mc":[{"id":"1.195453626","rc":[{"atb":[[3.75,2.73]],"id":36986045}],"con":true,"img":false}]}
{"op":"mcm","clk":"5348565623","pt":1646218901256,"mc":[{"id":"1.195453626","rc":[{"atb":[[3.75,32.61],[3.65,5]],"id":36986045}],"con":true,"img":false}]}
{"op":"mcm","clk":"5348565807","pt":1646218902566,"mc":[{"id":"1.195453626","rc":[{"atb":[[1.48,5.75]],"id":37429121}],"con":true,"img":false}]}
{"op":"mcm","clk":"5348565930","pt":1646218903369,"mc":[{"id":"1.195453626","rc":[{"atb":[[3.75,29.88]],"id":36986045},{"atb":[[1.94,7.98]],"id":36592903}],"con":true,"img":false}]}
{"op":"mcm","clk":"5348566057","pt":1646218904200,"mc":[{"id":"1.195453626","rc":[{"atb":[[1.92,38.78],[1.9,9.25]],"id":36592903}],"con":true,"img":false}]}
{"op":"mcm","clk":"5348566288","pt":1646218905800,"mc":[{"id":"1.195453626","rc":[{"atb":[[1.5,2.95]],"id":37429121}],"con":true,"img":false}]}
{"op":"mcm","clk":"5348566355","pt":1646218906288,"mc":[{"id":"1.195453626","rc":[{"atb":[[1.94,0]],"id":36592903},{"atb":[[1.68,80],[2.88,55.09],[2.02,75.53],[2.52,2],[1.77,2],[2.96,15],[2.16,2],[2.7,2],[2.3,41],[1.85,2],[2.84,21],[1.94,57],[2.62,29],[2.76,2],[2.4,2],[2.92,2]],"id":42099020},{"atb":[[2.46,10.84]],"id":40559875}],"con":true,"img":false}]}
{"op":"mcm","clk":"5348566382","pt":1646218906501,"mc":[{"id":"1.195453626","rc":[{"atl":[[40,14],[60,1],[95,1],[160,20],[11,5],[12,1],[13,1],[14,7],[250,1],[16,1],[17.5,7.06],[19.5,10],[330,1],[24,1],[420,28],[30,1]],"id":42099020}],"con":true,"img":false}]}
{"op":"mcm","clk":"5348566407","pt":1646218906692,"mc":[{"id":"1.195453626","rc":[{"atb":[[2,15],[1.2,80],[1.46,57],[1.78,2],[1.96,2],[1.53,2],[1.67,41],[1.9,2],[1.83,29],[1.6,2],[1.98,2],[1.37,2],[1.94,21],[1.87,2],[1.72,2],[1.29,2]],"id":40559875},{"atl":[[9.2,2],[44,20],[7.4,2],[8.6,2],[80,1],[7,2],[140,1],[10,10],[12.5,1],[7.8,7],[230,28],[15.5,1],[18,14],[23,1],[6.6,16.99],[30,1]],"id":40559875}],"con":true,"img":false}]}
{"op":"mcm","clk":"5348566502","pt":1646218907485,"mc":[{"id":"1.195453626","rc":[{"atb":[[2,2],[1.71,41],[2.08,15],[1.41,2],[1.91,2],[1.24,80],[1.64,2],[1.98,21],[2.04,2],[1.33,2],[1.94,2],[1.87,29],[1.76,2],[1.82,2],[1.57,2],[1.5,57]],"id":38981227}],"con":true,"img":false}]}
{"op":"mcm","clk":"5348566530","pt":1646218907685,"mc":[{"id":"1.195453626","rc":[{"atl":[[36,20],[9.2,10],[5.9,5],[60,1],[6.2,2],[100,1],[7,7],[10.5,1],[190,28],[13.5,1],[7.8,2],[8.4,2],[16,14],[19.5,1],[26,1],[6.6,2]],"id":38981227}],"con":true,"img":false}]}
{"op":"mcm","clk":"5348566614","pt":1646218908172,"mc":[{"id":"1.195453626","rc":[{"atb":[[1.18,2],[1.45,2],[1.03,2],[1.56,2],[1.41,29],[1.36,2],[1.11,2],[1.02,2],[1.52,21],[1.01,80],[1.58,127.81],[1.48,2],[1.25,41],[1.54,2],[1.3,2],[1.04,57]],"id":36592903},{"atl":[[22,18.72]],"id":39360156}],"con":true,"img":false}]}
{"op":"mcm","clk":"5348566643","pt":1646218908384,"mc":[{"id":"1.195453626","rc":[{"atl":[[34,1],[9.2,2],[48,1],[9.6,7],[80,20],[150,1],[11,1],[12.5,1],[230,1],[8.4,5],[14.5,10],[17,1],[20,1],[320,28],[25,14],[8.8,2]],"id":36592903}],"con":true,"img":false}]}
{"op":"mcm","clk":"5348566670","pt":1646218908608,"mc":[{"id":"1.195453626","rc":[{"atb":[[1.01,21],[1.03,2],[1.02,2],[1.04,15]],"id":37429121},{"atl":[[3.85,2],[3.1,2],[4.9,2],[2.78,5],[4.2,14],[2.82,2],[10,1],[2.98,2],[3.55,2],[3.3,10],[8.4,2],[14.5,28],[5.6,2],[2.86,2],[2.9,7],[6.6,20]],"id":37429121}],"con":true,"img":false}]}
{"op":"mcm","clk":"5348566778","pt":1646218909395,"mc":[{"id":"1.195453626","rc":[{"atb":[[3.6,2],[9,2],[6.4,52.83],[3.25,57],[2.58,80],[7.8,5.13],[9.4,2],[2.76,2],[7.2,2],[2.92,2],[8.6,21],[5.1,2],[4.6,41],[3.95,2],[9.8,15],[5.7,17.96]],"id":39360156}],"con":true,"img":false}]}
{"op":"mcm","clk":"5348566804","pt":1646218909603,"mc":[{"id":"1.195453626","rc":[{"atl":[[2.8,62.06]],"id":36592903},{"atb":[[6.4,38.26]],"id":39360156}],"con":true,"img":false}]}
{"op":"mcm","clk":"5348566822","pt":1646218909657,"mc":[{"id":"1.195453626","rc":[{"atb":[[7.8,3.66]],"id":39360156}],"con":true,"img":false}]}
{"op":"mcm","clk":"5348566834","pt":1646218909765,"mc":[{"id":"1.195453626","rc":[{"atb":[[10,1.46]],"id":39360156}],"con":true,"img":false}]}
{"op":"mcm","clk":"5348566874","pt":1646218909998,"mc":[{"id":"1.195453626","rc":[{"atb":[[2,2],[2.6,2],[1.93,2],[2.14,41],[2.24,2],[2.46,29],[1.86,57],[1.77,2],[2.68,21],[2.8,15],[2.72,2],[2.54,2],[1.6,80],[2.76,2],[1.69,2],[2.36,2]],"id":36986045}],"con":true,"img":false}]}
{"op":"mcm","clk":"5348566894","pt":1646218910185,"mc":[{"id":"1.195453626","rc":[{"atl":[[40,1],[60,1],[95,20],[9,5],[10.5,7],[180,1],[12.5,1],[14,1],[9.4,2],[16,14.83],[260,1],[18.5,1],[350,28],[23,1],[9.8,2],[28,14]],"id":36986045}],"con":true,"img":false}]}
{"op":"mcm","clk":"5348567058","pt":1646218911464,"mc":[{"id":"1.195453626","rc":[{"atb":[[1.92,7.56],[1.9,86.66]],"id":36592903}],"con":true,"img":false}]}
{"op":"mcm","clk":"5348567276","pt":1646218913160,"mc":[{"id":"1.195453626","rc":[{"atb":[[7.8,2]],"id":39360156}],"con":true,"img":false}]}
{"op":"mcm","clk":"5348567304","pt":1646218913370,"mc":[{"id":"1.195453626","rc":[{"atb":[[10,3.13]],"id":39360156}],"con":true,"img":false}]}
{"op":"mcm","clk":"5348567464","pt":1646218914710,"mc":[{"id":"1.195453626","rc":[{"atb":[[1.5,7.81]],"id":37429121}],"con":true,"img":false}]}
{"op":"mcm","clk":"5348567495","pt":1646218914888,"mc":[{"id":"1.195453626","rc":[{"atb":[[1.48,0]],"id":37429121}],"con":true,"img":false}]}
{"op":"mcm","clk":"5348567604","pt":1646218915613,"mc":[{"id":"1.195453626","rc":[{"atb":[[6.4,29]],"id":39360156}],"con":true,"img":false}]}
{"op":"mcm","clk":"5348567632","pt":1646218915787,"mc":[{"id":"1.195453626","rc":[{"atb":[[1.49,0]],"id":37429121}],"con":true,"img":false}]}
{"op":"mcm","clk":"5348567644","pt":1646218915937,"mc":[{"id":"1.195453626","rc":[{"atb":[[1.51,1.48]],"id":37429121},{"atb":[[6.6,9.26]],"id":39360156}],"con":true,"img":false}]}
{"op":"mcm","clk":"5348567670","pt":1646218915988,"mc":[{"id":"1.195453626","rc":[{"atb":[[1.44,40.54],[1.45,2.16]],"id":37429121}],"con":true,"img":false}]}
{"op":"mcm","clk":"5348567802","pt":1646218917013,"mc":[{"id":"1.195453626","rc":[{"atl":[[2.6,34.57],[2.24,0]],"id":37429121}],"con":true,"img":false}]}
{"op":"mcm","clk":"5348568002","pt":1646218918308,"mc":[{"id":"1.195453626","rc":[{"atb":[[1.94,7.98]],"id":36592903}],"con":true,"img":false}]}
{"op":"mcm","clk":"5348568016","pt":1646218918361,"mc":[{"id":"1.195453626","rc":[{"atb":[[1.5,4.86]],"id":37429121}],"con":true,"img":false}]}
{"op":"mcm","clk":"5348568067","pt":1646218918788,"mc":[{"id":"1.195453626","rc":[{"atb":[[1.91,0]],"id":36592903}],"con":true,"img":false}]}
{"op":"mcm","clk":"5348568079","pt":1646218918903,"mc":[{"id":"1.195453626","rc":[{"atb":[[1.95,1.4]],"id":36592903}],"con":true,"img":false}]}
{"op":"mcm","clk":"5348568205","pt":1646218919705,"mc":[{"id":"1.195453626","rc":[{"atb":[[1.92,40.89],[1.9,9.25]],"id":36592903}],"con":true,"img":false}]}
{"op":"mcm","clk":"5348568445","pt":1646218921342,"mc":[{"id":"1.195453626","rc":[{"atb":[[1.94,0]],"id":36592903}],"con":true,"img":false}]}
{"op":"mcm","clk":"5348568529","pt":1646218921823,"mc":[{"id":"1.195453626","rc":[{"atb":[[1.95,0]],"id":36592903}],"con":true,"img":false}]}
{"op":"mcm","clk":"5348568545","pt":1646218921886,"mc":[{"id":"1.195453626","rc":[{"atb":[[1.93,1.4],[1.92,33.33]],"id":36592903},{"atb":[[1.47,4.8]],"id":37429121}],"con":true,"img":false}]}
{"op":"mcm","clk":"5348568824","pt":1646218924210,"mc":[{"id":"1.195453626","rc":[{"atb":[[2.6,17.97]],"id":38981227},{"atb":[[1.96,2.5]],"id":36592903},{"atb":[[1.46,9.29]],"id":37429121}],"con":true,"img":false}]}
{"op":"mcm","clk":"5348568867","pt":1646218924424,"mc":[{"id":"1.195453626","rc":[{"atb":[[2.6,64.15],[2.58,7.77]],"id":38981227}],"con":true,"img":false}]}
{"op":"mcm","clk":"5348568878","pt":1646218924517,"mc":[{"id":"1.195453626","rc":[{"atb":[[2.02,0]],"id":38981227},{"atl":[[6.8,0],[7.8,21.94]],"id":38981227},{"atb":[[2.88,0]],"id":36986045},{"atl":[[10,0],[15,14.86]],"id":36986045},{"atl":[[4.2,0]],"id":36592903},{"atb":[[1.28,85.42],[1.5,7.02],[1.24,81.64]],"id":37429121},{"atl":[[2.6,0],[2.62,52.51]],"id":37429121},{"atl":[[11.5,0],[15.5,15.8]],"id":42099020},{"atl":[[7.4,19.95],[6.6,5]],"id":40559875},{"atl":[[34,0],[110,3.83]],"id":39360156}],"con":true,"img":false}]}
{"op":"mcm","clk":"5348568896","pt":1646218924578,"mc":[{"id":"1.195453626","rc":[{"atb":[[1.88,58.1]],"id":38981227},{"atl":[[7.8,2]],"id":38981227},{"atb":[[2.76,33.06]],"id":36986045},{"atl":[[4.4,19.07]],"id":36592903},{"atb":[[1.45,0]],"id":37429121},{"atl":[[15.5,5]],"id":42099020}],"con":true,"img":false}]}
{"op":"mcm","clk":"5348568912","pt":1646218924690,"mc":[{"id":"1.195453626","rc":[{"atl":[[8.2,19.94]],"id":38981227},{"atl":[[17,10.79]],"id":42099020}],"con":true,"img":false}]}
{"op":"mcm","clk":"5348569002","pt":1646218925414,"mc":[{"id":"1.195453626","rc":[{"atb":[[1.94,6.48]],"id":36592903}],"con":true,"img":false}]}
{"op":"mcm","clk":"5348569028","pt":1646218925580,"mc":[{"id":"1.195453626","rc":[{"atb":[[1.92,0]],"id":36592903}],"con":true,"img":false}]}
{"op":"mcm","clk":"5348569228","pt":1646218927409,"mc":[{"id":"1.195453626","rc":[{"atb":[[2.64,11.72]],"id":38981227},{"spn":5.25,"spf":"NaN","id":36986045},{"spn":1.96,"spf":1.0,"id":36592903},{"spn":1.78,"spf":"NaN","id":37429121},{"spn":6.15,"spf":"NaN","id":42099020},{"spn":3.63,"spf":"NaN","id":40559875},{"spn":14.25,"spf":"NaN","id":39360156}],"con":true,"img":false}]}
{"op":"mcm","clk":"5348569392","pt":1646218928817,"mc":[{"id":"1.195453626","rc":[{"atb":[[1.93,0]],"id":36592903}],"con":true,"img":false}]}
{"op":"mcm","clk":"5348569399","pt":1646218928918,"mc":[{"id":"1.195453626","rc":[{"atb":[[1.95,1.4]],"id":36592903}],"con":true,"img":false}]}
{"op":"mcm","clk":"5348569456","pt":1646218929404,"mc":[{"id":"1.195453626","rc":[{"atb":[[1.94,0]],"id":36592903}],"con":true,"img":false}]}
{"op":"mcm","clk":"5348569466","pt":1646218929511,"mc":[{"id":"1.195453626","rc":[{"atb":[[1.58,92.54]],"id":36592903}],"con":true,"img":false}]}
{"op":"mcm","clk":"5348569485","pt":1646218929711,"mc":[{"id":"1.195453626","rc":[{"atb":[[1.9,44.47]],"id":36592903}],"con":true,"img":false}]}
{"op":"mcm","clk":"5348569500","pt":1646218929925,"mc":[{"id":"1.195453626","rc":[{"atb":[[1.95,0]],"id":36592903}],"con":true,"img":false}]}
{"op":"mcm","clk":"5348569511","pt":1646218930056,"mc":[{"id":"1.195453626","rc":[{"atb":[[1.91,1.4]],"id":36592903}],"con":true,"img":false}]}
{"op":"mcm","clk":"5348569550","pt":1646218930415,"mc":[{"id":"1.195453626","rc":[{"atb":[[3.85,0],[3.45,0],[3.7,5],[3.9,15.32],[3.65,0]],"id":36986045}],"con":true,"img":false}]}
{"op":"mcm","clk":"5348569571","pt":1646218930624,"mc":[{"id":"1.195453626","rc":[{"atb":[[3.75,0],[3.7,45.77]],"id":36986045}],"con":true,"img":false}]}
{"op":"mcm","clk":"5348569647","pt":1646218931218,"mc":[{"id":"1.195453626","rc":[{"atb":[[1.46,36.01],[1.44,2.5]],"id":37429121}],"con":true,"img":false}]}
{"op":"mcm","clk":"5348569832","pt":1646218932832,"mc":[{"id":"1.195453626","rc":[{"atb":[[1.92,7.56]],"id":36592903}],"con":true,"img":false}]}
{"op":"mcm","clk":"5348569884","pt":1646218933310,"mc":[{"id":"1.195453626","rc":[{"atb":[[2.66,6.18]],"id":38981227}],"con":true,"img":false}]}
{"op":"mcm","clk":"5348569904","pt":1646218933514,"mc":[{"id":"1.195453626","rc":[{"atb":[[2.66,19.34]],"id":38981227}],"con":true,"img":false}]}
{"op":"mcm","clk":"5348569937","pt":1646218933831,"mc":[{"id":"1.195453626","rc":[{"atb":[[2.64,5.92]],"id":38981227},{"atl":[[11,7.25],[9.4,13.9]],"id":36986045}],"con":true,"img":false}]}
{"op":"mcm","clk":"5348569950","pt":1646218933932,"mc":[{"id":"1.195453626","rc":[{"atb":[[2.64,4.58]],"id":38981227},{"atb":[[1.91,0]],"id":36592903}],"con":true,"img":false}]}
{"op":"mcm","clk":"5348569965","pt":1646218933991,"mc":[{"id":"1.195453626","rc":[{"atb":[[2.68,1.34]],"id":38981227},{"atb":[[1.93,1.4]],"id":36592903}],"con":true,"img":false}]}
{"op":"mcm","clk":"5348570048","pt":1646218934927,"mc":[{"id":"1.195453626","rc":[{"atb":[[1.92,40.26],[1.9,9.25]],"id":36592903}],"con":true,"img":false}]}
{"op":"mcm","clk":"5348570174","pt":1646218936219,"mc":[{"id":"1.195453626","rc":[{"atb":[[2.64,0]],"id":38981227},{"atb":[[1.92,32.7]],"id":36592903}],"con":true,"img":false}]}
{"op":"mcm","clk":"5348570317","pt":1646218937736,"mc":[{"id":"1.195453626","rc":[{"atb":[[3.7,4.99],[3.15,121.99]],"id":36986045}],"con":true,"img":false}]}
{"op":"mcm","clk":"5348570358","pt":1646218938117,"mc":[{"id":"1.195453626","rc":[{"atl":[[1000,0]],"id":39360156}],"con":true,"img":false}]}
{"op":"mcm","clk":"5348570371","pt":1646218938217,"mc":[{"id":"1.195453626","rc":[{"atl":[[18,1.24]],"id":39360156}],"con":true,"img":false}]}
{"op":"mcm","clk":"5348570393","pt":1646218938417,"mc":[{"id":"1.195453626","rc":[{"atb":[[2.6,46.18]],"id":38981227},{"atb":[[1.46,28.4]],"id":37429121},{"atl":[[17.5,4.22],[19,10.94],[22,5]],"id":39360156}],"con":true,"img":false}]}
{"op":"mcm","clk":"5348570407","pt":1646218938524,"mc":[{"id":"1.195453626","rc":[{"atl":[[2.62,34.57]],"id":37429121},{"atb":[[7.6,0]],"id":39360156}],"con":true,"img":false}]}
{"op":"mcm","clk":"5348570415","pt":1646218938623,"mc":[{"id":"1.195453626","rc":[{"atb":[[8.8,7.78]],"id":39360156},{"atl":[[18.5,2.07]],"id":39360156}],"con":true,"img":false}]}
{"op":"mcm","clk":"5348570591","pt":1646218940405,"mc":[{"id":"1.195453626","rc":[{"atb":[[2.7,2.68]],"id":38981227},{"atb":[[1.94,6.48]],"id":36592903}],"con":true,"img":false}]}
{"op":"mcm","clk":"5348570601","pt":1646218940604,"mc":[{"id":"1.195453626","rc":[{"atb":[[2.6,0],[2.62,40.54]],"id":38981227},{"atb":[[1.92,0]],"id":36592903}],"con":true,"img":false}]}
{"op":"mcm","clk":"5348570773","pt":1646218942326,"mc":[{"id":"1.195453626","rc":[{"atb":[[2.66,14.82]],"id":38981227}],"con":true,"img":false}]}
{"op":"mcm","clk":"5348570961","pt":1646218944208,"mc":[{"id":"1.195453626","rc":[{"atb":[[1.96,0]],"id":36592903},{"atb":[[1.51,7.43]],"id":37429121},{"atb":[[2.66,4.34]],"id":40559875}],"con":true,"img":false}]}
{"op":"mcm","clk":"5348570981","pt":1646218944416,"mc":[{"id":"1.195453626","rc":[{"atb":[[1.51,16.3]],"id":37429121}],"con":true,"img":false}]}
{"op":"mcm","clk":"5348571010","pt":1646218944624,"mc":[{"id":"1.195453626","rc":[{"atb":[[1.5,2.16]],"id":37429121}],"con":true,"img":false}]}
{"op":"mcm","clk":"5348571023","pt":1646218944733,"mc":[{"id":"1.195453626","rc":[{"atb":[[1.9,44.47]],"id":36592903},{"atb":[[1.54,2.16]],"id":37429121},{"atl":[[18,0]],"id":39360156}],"con":true,"img":false}]}
{"op":"mcm","clk":"5348571034","pt":1646218944829,"mc":[{"id":"1.195453626","rc":[{"atb":[[1.5,0]],"id":37429121},{"atb":[[2.5,5]],"id":40559875},{"atl":[[17,1.24]],"id":39360156}],"con":true,"img":false}]}
{"op":"mcm","clk":"5348571043","pt":1646218944939,"mc":[{"id":"1.195453626","rc":[{"atb":[[2.66,5.73]],"id":40559875},{"atl":[[17.5,0]],"id":39360156}],"con":true,"img":false}]}
{"op":"mcm","clk":"5348571059","pt":1646218945044,"mc":[{"id":"1.195453626","rc":[{"atl":[[16.5,3.91]],"id":39360156}],"con":true,"img":false}]}
{"op":"mcm","clk":"5348571093","pt":1646218945301,"mc":[{"id":"1.195453626","rc":[{"atl":[[17,0]],"id":39360156}],"con":true,"img":false}]}
{"op":"mcm","clk":"5348571099","pt":1646218945403,"mc":[{"id":"1.195453626","rc":[{"atb":[[3.2,3.41]],"id":36986045},{"atl":[[18.5,3.32]],"id":39360156}],"con":true,"img":false}]}
{"op":"mcm","clk":"5348571107","pt":1646218945505,"mc":[{"id":"1.195453626","rc":[{"atl":[[16.5,0]],"id":39360156}],"con":true,"img":false}]}
{"op":"mcm","clk":"5348571118","pt":1646218945617,"mc":[{"id":"1.195453626","rc":[{"atb":[[3.2,33.29],[3.15,55.73]],"id":36986045}],"con":true,"img":false}]}
{"op":"mcm","clk":"5348571128","pt":1646218945722,"mc":[{"id":"1.195453626","rc":[{"atl":[[18.5,7.89],[19,2.5],[22,17.5]],"id":39360156}],"con":true,"img":false}]}
{"op":"mcm","clk":"5348571165","pt":1646218946132,"mc":[{"id":"1.195453626","rc":[{"atb":[[1.46,1.68],[1.47,36.46]],"id":37429121}],"con":true,"img":false}]}
{"op":"mcm","clk":"5348571204","pt":1646218946498,"mc":[{"id":"1.195453626","rc":[{"atb":[[1.91,0]],"id":40559875}],"con":true,"img":false}]}
{"op":"mcm","clk":"5348571217","pt":1646218946602,"mc":[{"id":"1.195453626","rc":[{"atb":[[1.99,72.48]],"id":40559875}],"con":true,"img":false}]}
{"op":"mcm","clk":"5348571241","pt":1646218946811,"mc":[{"id":"1.195453626","rc":[{"atb":[[1.55,2.52]],"id":37429121}],"con":true,"img":false}]}
{"op":"mcm","clk":"5348571288","pt":1646218947327,"mc":[{"id":"1.195453626","rc":[{"atb":[[1.47,31.66]],"id":37429121}],"con":true,"img":false}]}
{"op":"mcm","clk":"5348571316","pt":1646218947639,"mc":[{"id":"1.195453626","rc":[{"atl":[[2.8,68.56]],"id":36592903}],"con":true,"img":false}]}
{"op":"mcm","clk":"5348571326","pt":1646218947749,"mc":[{"id":"1.195453626","rc":[{"atl":[[2.8,62.06]],"id":36592903}],"con":true,"img":false}]}
{"op":"mcm","clk":"5348571357","pt":1646218948101,"mc":[{"id":"1.195453626","rc":[{"atl":[[7.2,0],[6.2,21.23]],"id":38981227},{"atl":[[15,7.14],[17.5,1]],"id":42099020}],"con":true,"img":false}]}
{"op":"mcm","clk":"5348571388","pt":1646218948427,"mc":[{"id":"1.195453626","rc":[{"atb":[[2.7,13.22]],"id":38981227}],"con":true,"img":false}]}
{"op":"mcm","clk":"5348571402","pt":1646218948631,"mc":[{"id":"1.195453626","rc":[{"atb":[[2.66,1.66],[2.68,5.8]],"id":38981227},{"atb":[[3.2,29.88]],"id":36986045}],"con":true,"img":false}]}
{"op":"mcm","clk":"5348571436","pt":1646218948940,"mc":[{"id":"1.195453626","rc":[{"atb":[[2.68,4.46]],"id":38981227}],"con":true,"img":false}]}
{"op":"mcm","clk":"5348571447","pt":1646218949044,"mc":[{"id":"1.195453626","rc":[{"atb":[[2.72,1.34]],"id":38981227},{"atb":[[1.58,127.81]],"id":36592903}],"con":true,"img":false}]}
{"op":"mcm","clk":"5348571453","pt":1646218949091,"mc":[{"id":"1.195453626","rc":[{"atb":[[2.66,0]],"id":38981227}],"con":true,"img":false}]}
{"op":"mcm","clk":"5348571468","pt":1646218949306,"mc":[{"id":"1.195453626","rc":[{"atb":[[2.72,3]],"id":38981227}],"con":true,"img":false}]}
{"op":"mcm","clk":"5348571520","pt":1646218949823,"mc":[{"id":"1.195453626","rc":[{"atb":[[1.9,9.25]],"id":36592903},{"atb":[[2.5,0],[2.6,7.5],[2.58,0],[2.08,45.42],[2.2,83.18]],"id":40559875}],"con":true,"img":false}]}
{"op":"mcm","clk":"5348571528","pt":1646218949929,"mc":[{"id":"1.195453626","rc":[{"atb":[[1.87,12.97]],"id":36592903},{"atl":[[2.8,68.56]],"id":36592903}],"con":true,"img":false}]}
{"op":"mcm","clk":"5348571605","pt":1646218950856,"mc":[{"id":"1.195453626","rc":[{"atb":[[1.52,7.56]],"id":37429121}],"con":true,"img":false}]}
{"op":"mcm","clk":"5348571648","pt":1646218951217,"mc":[{"id":"1.195453626","rc":[{"atl":[[2.8,62.06]],"id":36592903}],"con":true,"img":false}]}
{"op":"mcm","clk":"5348571715","pt":1646218951837,"mc":[{"id":"1.195453626","rc":[{"atb":[[1.51,14.82]],"id":37429121}],"con":true,"img":false}]}
{"op":"mcm","clk":"5348571721","pt":1646218951939,"mc":[{"id":"1.195453626","rc":[{"atb":[[1.53,1.48]],"id":37429121}],"con":true,"img":false}]}
{"op":"mcm","clk":"5348571752","pt":1646218952306,"mc":[{"id":"1.195453626","rc":[{"atl":[[2.8,68.56]],"id":36592903}],"con":true,"img":false}]}
{"op":"mcm","clk":"5348571778","pt":1646218952605,"mc":[{"id":"1.195453626","rc":[{"atb":[[1.51,8.87]],"id":37429121},{"atb":[[2.66,3.05]],"id":40559875}],"con":true,"img":false}]}
{"op":"mcm","clk":"5348571786","pt":1646218952760,"mc":[{"id":"1.195453626","rc":[{"atb":[[2.7,10.54]],"id":38981227}],"con":true,"img":false}]}
{"op":"mcm","clk":"5348571795","pt":1646218952866,"mc":[{"id":"1.195453626","rc":[{"atb":[[2.66,1.66]],"id":40559875}],"con":true,"img":false}]}
{"op":"mcm","clk":"5348571812","pt":1646218953032,"mc":[{"id":"1.195453626","rc":[{"atb":[[2.46,46.5],[2.62,1.39]],"id":40559875}],"con":true,"img":false}]}
{"op":"mcm","clk":"5348571883","pt":1646218953753,"mc":[{"id":"1.195453626","rc":[{"atl":[[2.8,62.06]],"id":36592903}],"con":true,"img":false}]}
{"op":"mcm","clk":"5348571971","pt":1646218954636,"mc":[{"id":"1.195453626","rc":[{"atb":[[3.25,3.33]],"id":36986045},{"atb":[[2.46,41.36]],"id":40559875}],"con":true,"img":false}]}
{"op":"mcm","clk":"5348571980","pt":1646218954739,"mc":[{"id":"1.195453626","rc":[{"atb":[[1.52,0]],"id":37429121}],"con":true,"img":false}]}
{"op":"mcm","clk":"5348571991","pt":1646218954842,"mc":[{"id":"1.195453626","rc":[{"atb":[[3.25,33.21],[3.2,0]],"id":36986045}],"con":true,"img":false}]}
{"op":"mcm","clk":"5348572005","pt":1646218955049,"mc":[{"id":"1.195453626","rc":[{"atl":[[2.8,68.56]],"id":36592903}],"con":true,"img":false}]}
{"op":"mcm","clk":"5348572020","pt":1646218955154,"mc":[{"id":"1.195453626","rc":[{"atl":[[2.14,0],[2.16,90]],"id":37429121},{"atb":[[6.2,3.85]],"id":39360156}],"con":true,"img":false}]}
{"op":"mcm","clk":"5348572028","pt":1646218955212,"mc":[{"id":"1.195453626","rc":[{"atl":[[2.8,62.06]],"id":36592903}],"con":true,"img":false}]}
{"op":"mcm","clk":"5348572038","pt":1646218955309,"mc":[{"id":"1.195453626","rc":[{"atb":[[2.68,39.42],[2.62,2.16]],"id":38981227},{"atl":[[2.18,65.07],[2.16,47.52]],"id":37429121}],"con":true,"img":false}]}
{"op":"mcm","clk":"5348572091","pt":1646218955838,"mc":[{"id":"1.195453626","rc":[{"atb":[[1.53,0]],"id":37429121}],"con":true,"img":false}]}
{"op":"mcm","clk":"5348572103","pt":1646218955931,"mc":[{"id":"1.195453626","rc":[{"atb":[[1.52,1.48]],"id":37429121}],"con":true,"img":false}]}
{"op":"mcm","clk":"5348572176","pt":1646218956610,"mc":[{"id":"1.195453626","rc":[{"atb":[[2.74,6.02]],"id":38981227},{"atb":[[2.6,2.5]],"id":40559875}],"con":true,"img":false}]}
{"op":"mcm","clk":"5348572191","pt":1646218956825,"mc":[{"id":"1.195453626","rc":[{"atb":[[2.72,1.66]],"id":38981227},{"atb":[[2.62,0]],"id":40559875}],"con":true,"img":false}]}
{"op":"mcm","clk":"5348572198","pt":1646218956919,"mc":[{"id":"1.195453626","rc":[{"atb":[[2.76,1.34]],"id":38981227},{"atb":[[2.48,1.39]],"id":40559875}],"con":true,"img":false}]}
{"op":"mcm","clk":"5348572231","pt":1646218957234,"mc":[{"id":"1.195453626","rc":[{"atl":[[2.8,68.56]],"id":36592903}],"con":true,"img":false}]}
{"op":"mcm","clk":"5348572258","pt":1646218957542,"mc":[{"id":"1.195453626","rc":[{"atb":[[2.68,34.96]],"id":38981227},{"atb":[[3.25,29.88]],"id":36986045},{"atb":[[2.64,0],[2.52,2.16]],"id":40559875}],"con":true,"img":false}]}
{"op":"mcm","clk":"5348572342","pt":1646218958634,"mc":[{"id":"1.195453626","rc":[{"atb":[[1.2,501.35]],"id":37429121}],"con":true,"img":false}]}
{"op":"mcm","clk":"5348572356","pt":1646218958845,"mc":[{"id":"1.195453626","rc":[{"atl":[[2.8,62.06]],"id":36592903},{"atb":[[1.56,5.04]],"id":37429121}],"con":true,"img":false}]}
{"op":"mcm","clk":"5348572367","pt":1646218959054,"mc":[{"id":"1.195453626","rc":[{"atb":[[1.2,500.86]],"id":37429121}],"con":true,"img":false}]}
{"op":"mcm","clk":"5348572378","pt":1646218959165,"mc":[{"id":"1.195453626","rc":[{"atb":[[1.56,9.57]],"id":37429121}],"con":true,"img":false}]}
{"op":"mcm","clk":"5348572391","pt":1646218959315,"mc":[{"id":"1.195453626","rc":[{"atb":[[1.2,499.1],[1.51,0]],"id":37429121}],"con":true,"img":false}]}
{"op":"mcm","clk":"5348572398","pt":1646218959416,"mc":[{"id":"1.195453626","rc":[{"atb":[[1.56,11.33]],"id":37429121}],"con":true,"img":false}]}
{"op":"mcm","clk":"5348572403","pt":1646218959520,"mc":[{"id":"1.195453626","rc":[{"atl":[[2.8,68.56]],"id":36592903}],"con":true,"img":false}]}
{"op":"mcm","clk":"5348572418","pt":1646218959728,"mc":[{"id":"1.195453626","rc":[{"atl":[[2.8,62.06]],"id":36592903},{"atb":[[1.55,0]],"id":37429121},{"atb":[[2.66,4.34]],"id":40559875}],"con":true,"img":false}]}
{"op":"mcm","clk":"5348572426","pt":1646218959831,"mc":[{"id":"1.195453626","rc":[{"atb":[[2.6,62.5],[2.52,0]],"id":38981227},{"atl":[[6.2,3.85],[5.5,42.79]],"id":36592903},{"atb":[[2.1,0],[2.16,32],[2.3,56.38],[2.06,47.17]],"id":42099020},{"atb":[[1.96,77.76],[2.08,0]],"id":40559875},{"atl":[[4.9,25.86],[5.1,29.27]],"id":40559875},{"atb":[[3.35,17.06],[5.9,0],[4.5,28.52],[5,29.95],[6.2,0],[5.5,22.18],[5.7,2]],"id":39360156}],"con":true,"img":false}]}
{"op":"mcm","clk":"5348572441","pt":1646218960040,"mc":[{"id":"1.195453626","rc":[{"atb":[[2.46,0],[2.42,44.78]],"id":38981227},{"atl":[[3.3,2]],"id":38981227},{"atb":[[2.5,3],[1.9,44.47]],"id":36592903},{"atl":[[5.5,38.35],[6,4]],"id":36592903},{"atl":[[2.14,17.54],[1.67,4],[2.16,30.28]],"id":37429121},{"atb":[[2.34,45.63],[2.36,0]],"id":40559875},{"atl":[[4.9,28.86]],"id":40559875}],"con":true,"img":false}]}
{"op":"mcm","clk":"5348572450","pt":1646218960149,"mc":[{"id":"1.195453626","rc":[{"atb":[[1.27,0],[1.25,399.28],[1.24,164.97]],"id":37429121}],"con":true,"img":false}]}
{"op":"mcm","clk":"5348572459","pt":1646218960246,"mc":[{"id":"1.195453626","rc":[{"atl":[[4.9,50.29],[5,9.08],[3.3,0],[3.05,2]],"id":38981227},{"trd":[[3.3,4]],"ltp":3.3,"tv":4.0,"id":38981227},{"atb":[[2.52,4],[1.9,9.25]],"id":36592903},{"atl":[[6,0]],"id":36592903},{"atl":[[1.67,0],[1.66,2]],"id":37429121},{"trd":[[1.67,8]],"ltp":1.67,"tv":8.0,"id":37429121},{"atl":[[4.8,15.21]],"id":40559875}],"con":true,"img":false}]}
{"op":"mcm","clk":"5348572473","pt":1646218960354,"mc":[{"id":"1.195453626","rc":[{"atb":[[2.78,2]],"id":38981227},{"atl":[[4.6,5.56]],"id":38981227},{"atl":[[9.4,2],[8.8,12.82]],"id":36986045},{"atb":[[1.57,2.84]],"id":37429121},{"atl":[[2.5,50.42],[2.64,44.26],[2.08,0],[1.66,0]],"id":37429121},{"atb":[[2.34,30.7],[2.36,14.71]],"id":40559875},{"atl":[[4.9,25.86]],"id":40559875}],"con":true,"img":false}]}
{"op":"mcm","clk":"5348572482","pt":1646218960454,"mc":[{"id":"1.195453626","rc":[{"atl":[[3.05,0]],"id":38981227},{"atb":[[2.52,7.1]],"id":40559875}],"con":true,"img":false}]}
{"op":"mcm","clk":"5348572492","pt":1646218960567,"mc":[{"id":"1.195453626","rc":[{"atb":[[2.46,13.7]],"id":38981227},{"atb":[[2.54,4]],"id":36592903},{"atl":[[6,4]],"id":36592903},{"atl":[[2.14,28.18]],"id":37429121},{"atb":[[3.1,4]],"id":40559875},{"atl":[[5.5,0],[4.8,13.21],[5.3,0],[5.6,4.35],[5.1,24.39]],"id":40559875}],"con":true,"img":false}]}
{"op":"mcm","clk":"5348572501","pt":1646218960611,"mc":[{"id":"1.195453626","rc":[{"atb":[[2.74,0]],"id":38981227},{"atb":[[2.54,6.24]],"id":40559875}],"con":true,"img":false}]}
{"op":"mcm","clk":"5348572511","pt":1646218960715,"mc":[{"id":"1.195453626","rc":[{"atb":[[2.56,2]],"id":36592903},{"atl":[[6,0]],"id":36592903},{"atb":[[1.54,47.37],[1.47,0]],"id":37429121},{"atb":[[3.1,0],[2.46,5.7],[3.15,4]],"id":40559875}],"con":true,"img":false}]}
{"op":"mcm","clk":"5348572523","pt":1646218960822,"mc":[{"id":"1.195453626","rc":[{"atb":[[2.76,0]],"id":38981227}],"con":true,"img":false}]}
{"op":"mcm","clk":"5348572535","pt":1646218960925,"mc":[{"id":"1.195453626","rc":[{"atb":[[2.72,3]],"id":38981227},{"atl":[[6,4]],"id":36592903},{"atb":[[3.2,2]],"id":40559875}],"con":true,"img":false}]}
{"op":"mcm","clk":"5348572543","pt":1646218961028,"mc":[{"id":"1.195453626","rc":[{"atb":[[2.78,0]],"id":38981227},{"atl":[[8.2,0]],"id":38981227},{"atb":[[2.76,2]],"id":36986045},{"atl":[[17,0]],"id":42099020}],"con":true,"img":false}]}
{"op":"mcm","clk":"5348572554","pt":1646218961147,"mc":[{"id":"1.195453626","rc":[{"atl":[[7.8,21.94]],"id":38981227},{"atb":[[2.88,31.06]],"id":36986045},{"atl":[[6,0]],"id":36592903},{"atl":[[15.5,15.8]],"id":42099020},{"atb":[[3.25,2]],"id":40559875}],"con":true,"img":false}]}
{"op":"mcm","clk":"5348572564","pt":1646218961242,"mc":[{"id":"1.195453626","rc":[{"atb":[[2.74,2]],"id":38981227}],"con":true,"img":false}]}
{"op":"mcm","clk":"5348572575","pt":1646218961363,"mc":[{"id":"1.195453626","rc":[{"atl":[[1000,2.52]],"id":38981227},{"atl":[[6,4]],"id":36592903},{"atb":[[3.3,3]],"id":40559875}],"con":true,"img":false}]}
{"op":"mcm","clk":"5348572585","pt":1646218961470,"mc":[{"id":"1.195453626","rc":[{"atl":[[2.78,0]],"id":36592903},{"atl":[[2.06,0]],"id":37429121}],"con":true,"img":false}]}
{"op":"mcm","clk":"5348572592","pt":1646218961567,"mc":[{"id":"1.195453626","rc":[{"atl":[[1000,2.1]],"id":38981227},{"atl":[[1000,1.3]],"id":36592903},{"atl":[[2.12,1.25]],"id":37429121}],"con":true,"img":false}]}
{"op":"mcm","clk":"5348572611","pt":1646218961719,"mc":[{"id":"1.195453626","rc":[{"atl":[[1000,0]],"id":38981227}],"con":true,"img":false}]}
{"op":"mcm","clk":"5348572620","pt":1646218961831,"mc":[{"id":"1.195453626","rc":[{"atl":[[4.4,2.1]],"id":38981227}],"con":true,"img":false}]}
{"op":"mcm","clk":"5348572632","pt":1646218961928,"mc":[{"id":"1.195453626","rc":[{"atl":[[2.16,32.5]],"id":37429121}],"con":true,"img":false}]}
{"op":"mcm","clk":"5348572645","pt":1646218962039,"mc":[{"id":"1.195453626","rc":[{"atl":[[15.5,5]],"id":42099020}],"con":true,"img":false}]}
{"op":"mcm","clk":"5348572658","pt":1646218962135,"mc":[{"id":"1.195453626","rc":[{"atl":[[4.5,0]],"id":38981227},{"atl":[[17,10.79]],"id":42099020}],"con":true,"img":false}]}
{"op":"mcm","clk":"5348572670","pt":1646218962258,"mc":[{"id":"1.195453626","rc":[{"atl":[[4.4,3.51]],"id":38981227},{"atb":[[1.94,0]],"id":36592903},{"atb":[[1.56,6.29]],"id":37429121}],"con":true,"img":false}]}
{"op":"mcm","clk":"5348572711","pt":1646218962651,"mc":[{"id":"1.195453626","rc":[{"atl":[[6,0]],"id":36592903},{"atl":[[18.5,10.39],[21,5],[25,10]],"id":39360156}],"con":true,"img":false}]}
{"op":"mcm","clk":"5348572717","pt":1646218962753,"mc":[{"id":"1.195453626","rc":[{"atl":[[19,0],[22,12.5]],"id":39360156}],"con":true,"img":false}]}
{"op":"mcm","clk":"5348572729","pt":1646218962863,"mc":[{"id":"1.195453626","rc":[{"atl":[[21,17.19],[22,0]],"id":39360156}],"con":true,"img":false}]}
{"op":"mcm","clk":"5348572736","pt":1646218962911,"mc":[{"id":"1.195453626","rc":[{"atb":[[1.93,0]],"id":36592903},{"atb":[[1.52,0]],"id":37429121}],"con":true,"img":false}]}
{"op":"mcm","clk":"5348572753","pt":1646218963022,"mc":[{"id":"1.195453626","rc":[{"atb":[[2.74,8.8],[1.88,0]],"id":38981227},{"atb":[[1.91,1.4]],"id":36592903},{"atb":[[1.57,4.32]],"id":37429121},{"atl":[[21,5]],"id":39360156}],"con":true,"img":false}]}
{"op":"mcm","clk":"5348572767","pt":1646218963131,"mc":[{"id":"1.195453626","rc":[{"atb":[[1.99,58.1]],"id":38981227}],"con":true,"img":false}]}
{"op":"mcm","clk":"5348572773","pt":1646218963229,"mc":[{"id":"1.195453626","rc":[{"atb":[[2.7,0]],"id":38981227}],"con":true,"img":false}]}
{"op":"mcm","clk":"5348572784","pt":1646218963342,"mc":[{"id":"1.195453626","rc":[{"atb":[[1.31,26.86]],"id":37429121},{"atb":[[2.52,2.16]],"id":40559875},{"atl":[[18.5,9.14]],"id":39360156}],"con":true,"img":false}]}
{"op":"mcm","clk":"5348572789","pt":1646218963444,"mc":[{"id":"1.195453626","rc":[{"atl":[[1000,1.24]],"id":39360156}],"con":true,"img":false}]}
{"op":"mcm","clk":"5348572807","pt":1646218963549,"mc":[{"id":"1.195453626","rc":[{"atb":[[1.99,0]],"id":38981227},{"atb":[[1.87,0]],"id":36592903}],"con":true,"img":false}]}
{"op":"mcm","clk":"5348572813","pt":1646218963653,"mc":[{"id":"1.195453626","rc":[{"atb":[[1.95,58.1]],"id":38981227}],"con":true,"img":false}]}
{"op":"mcm","clk":"5348572835","pt":1646218963870,"mc":[{"id":"1.195453626","rc":[{"atb":[[2.5,0],[2.52,0],[2.54,0],[2.56,0]],"id":36592903},{"atl":[[6,4]],"id":36592903}],"con":true,"img":false}]}
{"op":"mcm","clk":"5348572854","pt":1646218964032,"mc":[{"id":"1.195453626","rc":[{"atb":[[2.76,3.99]],"id":38981227},{"atb":[[2.54,0]],"id":40559875}],"con":true,"img":false}]}
{"op":"mcm","clk":"5348572881","pt":1646218964338,"mc":[{"id":"1.195453626","rc":[{"atl":[[6,0]],"id":36592903}],"con":true,"img":false}]}
{"op":"mcm","clk":"5348572910","pt":1646218964660,"mc":[{"id":"1.195453626","rc":[{"atl":[[6,4]],"id":36592903}],"con":true,"img":false}]}
{"op":"mcm","clk":"5348572929","pt":1646218964871,"mc":[{"id":"1.195453626","rc":[{"atl":[[2.16,30.28]],"id":37429121}],"con":true,"img":false}]}
{"op":"mcm","clk":"5348572956","pt":1646218965137,"mc":[{"id":"1.195453626","rc":[{"atl":[[2.16,32.18]],"id":37429121}],"con":true,"img":false}]}
{"op":"mcm","clk":"5348572983","pt":1646218965441,"mc":[{"id":"1.195453626","rc":[{"atl":[[6,0]],"id":36592903}],"con":true,"img":false}]}
{"op":"mcm","clk":"5348573036","pt":1646218965964,"mc":[{"id":"1.195453626","rc":[{"atb":[[1.92,7.56]],"id":36592903},{"atb":[[1.58,8.64]],"id":37429121}],"con":true,"img":false}]}
{"op":"mcm","clk":"5348573043","pt":1646218966076,"mc":[{"id":"1.195453626","rc":[{"atb":[[1.58,92.54]],"id":36592903}],"con":true,"img":false}]}
{"op":"mcm","clk":"5348573066","pt":1646218966228,"mc":[{"id":"1.195453626","rc":[{"atb":[[1.56,4.53]],"id":37429121},{"atb":[[2.66,1.66]],"id":40559875}],"con":true,"img":false}]}
{"op":"mcm","clk":"5348573077","pt":1646218966334,"mc":[{"id":"1.195453626","rc":[{"atl":[[6,4]],"id":36592903}],"con":true,"img":false}]}
{"op":"mcm","clk":"5348573110","pt":1646218966649,"mc":[{"id":"1.195453626","rc":[{"atl":[[6,0]],"id":36592903}],"con":true,"img":false}]}
{"op":"mcm","clk":"5348573138","pt":1646218966960,"mc":[{"id":"1.195453626","rc":[{"atb":[[2.48,0]],"id":40559875}],"con":true,"img":false}]}
{"op":"mcm","clk":"5348573153","pt":1646218967063,"mc":[{"id":"1.195453626","rc":[{"atb":[[2.72,1.34]],"id":38981227},{"atb":[[2.66,0],[1.01,1.39]],"id":40559875}],"con":true,"img":false}]}
{"op":"mcm","clk":"5348573169","pt":1646218967225,"mc":[{"id":"1.195453626","rc":[{"atb":[[2.78,1.66]],"id":38981227},{"atl":[[6,4],[2.8,77.35]],"id":36592903}],"con":true,"img":false}]}
{"op":"mcm","clk":"5348573190","pt":1646218967434,"mc":[{"id":"1.195453626","rc":[{"atl":[[6,0]],"id":36592903}],"con":true,"img":false}]}
{"op":"mcm","clk":"5348573196","pt":1646218967540,"mc":[{"id":"1.195453626","rc":[{"atl":[[2.16,30.28]],"id":37429121}],"con":true,"img":false}]}
{"op":"mcm","clk":"5348573224","pt":1646218967852,"mc":[{"id":"1.195453626","rc":[{"atl":[[2.14,30.37]],"id":37429121}],"con":true,"img":false}]}
{"op":"mcm","clk":"5348573242","pt":1646218967963,"mc":[{"id":"1.195453626","rc":[{"atb":[[1.57,2.84]],"id":37429121},{"atb":[[1.01,0]],"id":40559875}],"con":true,"img":false}]}
{"op":"mcm","clk":"5348573252","pt":1646218968061,"mc":[{"id":"1.195453626","rc":[{"atl":[[6,4],[2.8,62.06]],"id":36592903},{"atb":[[1.59,1.48]],"id":37429121},{"atb":[[2.46,7.09]],"id":40559875}],"con":true,"img":false}]}
{"op":"mcm","clk":"5348573345","pt":1646218968947,"mc":[{"id":"1.195453626","rc":[{"atl":[[2.1,2.52]],"id":37429121}],"con":true,"img":false}]}
{"op":"mcm","clk":"5348573355","pt":1646218969056,"mc":[{"id":"1.195453626","rc":[{"atl":[[4.4,1.4]],"id":38981227}],"con":true,"img":false}]}
{"op":"mcm","clk":"5348573370","pt":1646218969268,"mc":[{"id":"1.195453626","rc":[{"atb":[[2.76,0]],"id":38981227},{"atl":[[4.9,12.82],[5,35.92]],"id":38981227},{"atb":[[1.87,12.65]],"id":36592903}],"con":true,"img":false}]}
{"op":"mcm","clk":"5348573376","pt":1646218969363,"mc":[{"id":"1.195453626","rc":[{"atl":[[4.4,0]],"id":38981227}],"con":true,"img":false}]}
{"op":"mcm","clk":"5348573387","pt":1646218969469,"mc":[{"id":"1.195453626","rc":[{"atb":[[2.68,0],[2.62,37.1]],"id":38981227},{"atl":[[4.5,1.4]],"id":38981227}],"con":true,"img":false}]}
{"op":"mcm","clk":"5348573394","pt":1646218969522,"mc":[{"id":"1.195453626","rc":[{"atl":[[1000,2.52]],"id":38981227}],"con":true,"img":false}]}
{"op":"mcm","clk":"5348573401","pt":1646218969628,"mc":[{"id":"1.195453626","rc":[{"atl":[[6,0],[2.8,77.35]],"id":36592903}],"con":true,"img":false}]}
{"op":"mcm","clk":"5348573408","pt":1646218969735,"mc":[{"id":"1.195453626","rc":[{"atl":[[1000,2.1]],"id":38981227},{"atl":[[2.18,42.37],[2.16,52.27]],"id":37429121}],"con":true,"img":false}]}
{"op":"mcm","clk":"5348573419","pt":1646218969897,"mc":[{"id":"1.195453626","rc":[{"atl":[[2.8,62.06]],"id":36592903}],"con":true,"img":false}]}
{"op":"mcm","clk":"5348573431","pt":1646218969951,"mc":[{"id":"1.195453626","rc":[{"atl":[[1000,0]],"id":38981227}],"con":true,"img":false}]}
{"op":"mcm","clk":"5348573439","pt":1646218970046,"mc":[{"id":"1.195453626","rc":[{"atl":[[4.3,2.1]],"id":38981227}],"con":true,"img":false}]}
{"op":"mcm","clk":"5348573449","pt":1646218970155,"mc":[{"id":"1.195453626","rc":[{"atb":[[2.26,39.68]],"id":42099020},{"atb":[[4.8,13.16]],"id":39360156}],"con":true,"img":false}]}
{"op":"mcm","clk":"5348573476","pt":1646218970469,"mc":[{"id":"1.195453626","rc":[{"atb":[[1.22,227.27]],"id":37429121},{"atl":[[2.22,60.41]],"id":37429121}],"con":true,"img":false}]}
{"op":"mcm","clk":"5348573482","pt":1646218970572,"mc":[{"id":"1.195453626","rc":[{"atl":[[6,4]],"id":36592903},{"atb":[[1.99,0]],"id":42099020}],"con":true,"img":false}]}
{"op":"mcm","clk":"5348573501","pt":1646218970730,"mc":[{"id":"1.195453626","rc":[{"atl":[[6,0]],"id":36592903}],"con":true,"img":false}]}
{"op":"mcm","clk":"5348573508","pt":1646218970832,"mc":[{"id":"1.195453626","rc":[{"atb":[[2.42,65.91]],"id":38981227},{"atb":[[1.58,0]],"id":37429121},{"atl":[[5.8,17.98]],"id":40559875}],"con":true,"img":false}]}
{"op":"mcm","clk":"5348573542","pt":1646218971144,"mc":[{"id":"1.195453626","rc":[{"atl":[[6,4]],"id":36592903}],"con":true,"img":false}]}
{"op":"mcm","clk":"5348573592","pt":1646218971568,"mc":[{"id":"1.195453626","rc":[{"atl":[[6,0]],"id":36592903}],"con":true,"img":false}]}
{"op":"mcm","clk":"5348573627","pt":1646218971878,"mc":[{"id":"1.195453626","rc":[{"atl":[[6,4]],"id":36592903},{"atb":[[1.59,0]],"id":37429121}],"con":true,"img":false}]}
{"op":"mcm","clk":"5348573634","pt":1646218971934,"mc":[{"id":"1.195453626","rc":[{"atb":[[1.56,6.01]],"id":37429121}],"con":true,"img":false}]}
{"op":"mcm","clk":"5348573647","pt":1646218972039,"mc":[{"id":"1.195453626","rc":[{"atb":[[2.58,5.27]],"id":38981227},{"atl":[[6,0],[2.8,77.35]],"id":36592903}],"con":true,"img":false}]}
{"op":"mcm","clk":"5348573662","pt":1646218972245,"mc":[{"id":"1.195453626","rc":[{"atb":[[1.2,48],[1.46,2],[1.7,2],[1.68,17],[1.41,63],[1.27,2],[1.74,12],[1.61,2],[1.52,23],[1.64,2],[1.01,147],[1.14,2],[1.34,2],[1.72,2],[1.57,199.44],[1.07,2]],"id":36592903}],"con":true,"img":false}]}
{"op":"mcm","clk":"5348573676","pt":1646218972453,"mc":[{"id":"1.195453626","rc":[{"atb":[[2.8,3.33]],"id":38981227}],"con":true,"img":false}]}
{"op":"mcm","clk":"5348573684","pt":1646218972557,"mc":[{"id":"1.195453626","rc":[{"atb":[[3.3,3.26]],"id":36986045},{"atb":[[1.9,17.59]],"id":36592903},{"atb":[[1.58,12.94]],"id":37429121}],"con":true,"img":false}]}
{"op":"mcm","clk":"5348573706","pt":1646218972760,"mc":[{"id":"1.195453626","rc":[{"atb":[[3.25,0],[3.3,33.14]],"id":36986045}],"con":true,"img":false}]}
{"op":"mcm","clk":"5348573727","pt":1646218972867,"mc":[{"id":"1.195453626","rc":[{"atb":[[2.78,5.62]],"id":38981227},{"atb":[[1.59,7.08]],"id":37429121}],"con":true,"img":false}]}
{"op":"mcm","clk":"5348573760","pt":1646218973071,"mc":[{"id":"1.195453626","rc":[{"atb":[[2.74,27.7],[2.62,2.16],[2.42,35.21]],"id":38981227},{"atb":[[3.1,0],[2.88,0]],"id":36986045},{"atb":[[1.28,0]],"id":37429121},{"atb":[[2.34,0]],"id":40559875},{"atb":[[10,7.97],[8.8,0]],"id":39360156}],"con":true,"img":false}]}
{"op":"mcm","clk":"5348573765","pt":1646218973121,"mc":[{"id":"1.195453626","rc":[{"atb":[[2.64,30.7]],"id":38981227},{"atb":[[3.95,19.81],[2.76,33.06]],"id":36986045},{"atb":[[1.55,85.42]],"id":37429121},{"atb":[[2.42,30.7]],"id":40559875}],"con":true,"img":false}]}
{"op":"mcm","clk":"5348573776","pt":1646218973228,"mc":[{"id":"1.195453626","rc":[{"atb":[[3.95,33.73]],"id":36986045},{"atl":[[6,4]],"id":36592903}],"con":true,"img":false}]}
{"op":"mcm","clk":"5348573799","pt":1646218973438,"mc":[{"id":"1.195453626","rc":[{"atb":[[3.9,5.52]],"id":36986045},{"atb":[[1.59,14.53]],"id":37429121}],"con":true,"img":false}]}
{"op":"mcm","clk":"5348573812","pt":1646218973549,"mc":[{"id":"1.195453626","rc":[{"atl":[[2.62,52.4]],"id":37429121}],"con":true,"img":false}]}
{"op":"mcm","clk":"5348573833","pt":1646218973746,"mc":[{"id":"1.195453626","rc":[{"atl":[[6,0]],"id":36592903},{"atb":[[1.56,1.48]],"id":37429121}],"con":true,"img":false}]}
{"op":"mcm","clk":"5348573855","pt":1646218973957,"mc":[{"id":"1.195453626","rc":[{"atb":[[2.72,0]],"id":38981227},{"atb":[[3.9,4.16]],"id":36986045}],"con":true,"img":false}]}
{"op":"mcm","clk":"5348573863","pt":1646218974056,"mc":[{"id":"1.195453626","rc":[{"atb":[[2.78,6.97]],"id":38981227},{"atb":[[4,1.35]],"id":36986045}],"con":true,"img":false}]}
{"op":"mcm","clk":"5348573891","pt":1646218974268,"mc":[{"id":"1.195453626","rc":[{"atb":[[1.58,18.61]],"id":37429121}],"con":true,"img":false}]}
{"op":"mcm","clk":"5348573896","pt":1646218974367,"mc":[{"id":"1.195453626","rc":[{"atb":[[1.9,65.32]],"id":36592903}],"con":true,"img":false}]}
{"op":"mcm","clk":"5348573904","pt":1646218974470,"mc":[{"id":"1.195453626","rc":[{"atb":[[1.62,2.16]],"id":37429121}],"con":true,"img":false}]}
{"op":"mcm","clk":"5348573915","pt":1646218974526,"mc":[{"id":"1.195453626","rc":[{"atl":[[4.9,33.73]],"id":38981227},{"atb":[[1.54,45.21]],"id":37429121}],"con":true,"img":false}]}
{"op":"mcm","clk":"5348573924","pt":1646218974630,"mc":[{"id":"1.195453626","rc":[{"atb":[[2.82,2]],"id":38981227},{"atl":[[5,9.08]],"id":38981227},{"atb":[[1.63,4]],"id":37429121}],"con":true,"img":false}]}
{"op":"mcm","clk":"5348573938","pt":1646218974836,"mc":[{"id":"1.195453626","rc":[{"atb":[[2.74,25.7]],"id":38981227},{"atb":[[1.57,0]],"id":37429121}],"con":true,"img":false}]}
{"op":"mcm","clk":"5348573964","pt":1646218975045,"mc":[{"id":"1.195453626","rc":[{"atb":[[1.59,42.34],[1.54,0]],"id":37429121}],"con":true,"img":false}]}
{"op":"mcm","clk":"5348574002","pt":1646218975467,"mc":[{"id":"1.195453626","rc":[{"atb":[[1.87,0]],"id":36592903}],"con":true,"img":false}]}
{"op":"mcm","clk":"5348574034","pt":1646218975777,"mc":[{"id":"1.195453626","rc":[{"atl":[[4.7,5.31],[4.6,0]],"id":38981227},{"atl":[[6,4]],"id":36592903}],"con":true,"img":false}]}
{"op":"mcm","clk":"5348574107","pt":1646218976471,"mc":[{"id":"1.195453626","rc":[{"atl":[[5,0]],"id":38981227}],"con":true,"img":false}]}
{"op":"mcm","clk":"5348574113","pt":1646218976561,"mc":[{"id":"1.195453626","rc":[{"atl":[[4.8,9.08]],"id":38981227}],"con":true,"img":false}]}
{"op":"mcm","clk":"5348574133","pt":1646218976770,"mc":[{"id":"1.195453626","rc":[{"atl":[[4.9,12.82]],"id":38981227}],"con":true,"img":false}]}
{"op":"mcm","clk":"5348574174","pt":1646218977135,"mc":[{"id":"1.195453626","rc":[{"atl":[[25,24.05]],"id":39360156}],"con":true,"img":false}]}
{"op":"mcm","clk":"5348574194","pt":1646218977339,"mc":[{"id":"1.195453626","rc":[{"atb":[[2.82,6.07]],"id":38981227},{"atl":[[4.3,0]],"id":38981227}],"con":true,"img":false}]}
{"op":"mcm","clk":"5348574219","pt":1646218977654,"mc":[{"id":"1.195453626","rc":[{"atb":[[2.74,18.9],[2.8,0]],"id":38981227},{"atb":[[1.58,12.94]],"id":37429121}],"con":true,"img":false}]}
{"op":"mcm","clk":"5348574258","pt":1646218978069,"mc":[{"id":"1.195453626","rc":[{"atl":[[26,0]],"id":39360156}],"con":true,"img":false}]}
{"op":"mcm","clk":"5348574265","pt":1646218978172,"mc":[{"id":"1.195453626","rc":[{"atl":[[24,2.72]],"id":39360156}],"con":true,"img":false}]}
{"op":"mcm","clk":"5348574292","pt":1646218978435,"mc":[{"id":"1.195453626","rc":[{"atb":[[2.64,33.2],[2.78,3]],"id":38981227},{"atl":[[6,0]],"id":36592903},{"atb":[[1.59,35.26]],"id":37429121}],"con":true,"img":false}]}
{"op":"mcm","clk":"5348574319","pt":1646218978746,"mc":[{"id":"1.195453626","rc":[{"atb":[[3.3,29.88]],"id":36986045},{"atb":[[1.9,56.98]],"id":36592903},{"atb":[[1.58,0]],"id":37429121}],"con":true,"img":false}]}
{"op":"mcm","clk":"5348574358","pt":1646218979161,"mc":[{"id":"1.195453626","rc":[{"atl":[[4.5,0]],"id":38981227},{"atl":[[6,4]],"id":36592903}],"con":true,"img":false}]}
{"op":"mcm","clk":"5348574365","pt":1646218979264,"mc":[{"id":"1.195453626","rc":[{"atl":[[4.6,1.4]],"id":38981227}],"con":true,"img":false}]}
{"op":"mcm","clk":"5348574375","pt":1646218979368,"mc":[{"id":"1.195453626","rc":[{"atb":[[1.01,2.52]],"id":38981227}],"con":true,"img":false}]}
{"op":"mcm","clk":"5348574393","pt":1646218979576,"mc":[{"id":"1.195453626","rc":[{"atb":[[1.01,2.1]],"id":38981227}],"con":true,"img":false}]}
{"op":"mcm","clk":"5348574411","pt":1646218979735,"mc":[{"id":"1.195453626","rc":[{"atb":[[1.01,0]],"id":38981227}],"con":true,"img":false}]}
{"op":"mcm","clk":"5348574419","pt":1646218979838,"mc":[{"id":"1.195453626","rc":[{"atb":[[2.84,2.1]],"id":38981227}],"con":true,"img":false}]}
{"op":"mcm","clk":"5348574439","pt":1646218980048,"mc":[{"id":"1.195453626","rc":[{"atb":[[2.86,2]],"id":38981227}],"con":true,"img":false}]}
{"op":"mcm","clk":"5348574460","pt":1646218980258,"mc":[{"id":"1.195453626","rc":[{"atb":[[2.82,4.07]],"id":38981227}],"con":true,"img":false}]}
{"op":"mcm","clk":"5348574467","pt":1646218980361,"mc":[{"id":"1.195453626","rc":[{"atb":[[2.22,61.48]],"id":42099020},{"atb":[[4.6,61.83]],"id":39360156}],"con":true,"img":false}]}
{"op":"mcm","clk":"5348574494","pt":1646218980576,"mc":[{"id":"1.195453626","rc":[{"atb":[[1.2,749.1]],"id":37429121},{"atl":[[2.26,97.49]],"id":37429121}],"con":true,"img":false}]}
{"op":"mcm","clk":"5348574510","pt":1646218980780,"mc":[{"id":"1.195453626","rc":[{"atb":[[2.6,64.5],[2.74,0]],"id":36986045},{"atb":[[1.9,9.25]],"id":36592903},{"atl":[[6,0]],"id":36592903},{"atb":[[1.21,0],[1.23,0]],"id":37429121},{"atb":[[2.02,2]],"id":42099020}],"con":true,"img":false}]}
{"op":"mcm","clk":"5348574536","pt":1646218980950,"mc":[{"id":"1.195453626","rc":[{"atb":[[2.78,1.66]],"id":38981227}],"con":true,"img":false}]}
{"op":"mcm","clk":"5348574550","pt":1646218981050,"mc":[{"id":"1.195453626","rc":[{"atb":[[2.76,1.34]],"id":38981227},{"atl":[[6,15]],"id":40559875}],"con":true,"img":false}]}
{"op":"mcm","clk":"5348574603","pt":1646218981570,"mc":[{"id":"1.195453626","rc":[{"atb":[[2.84,14.25]],"id":38981227},{"atb":[[1.87,12.65]],"id":36592903},{"atb":[[1.6,12]],"id":37429121}],"con":true,"img":false}]}
{"op":"mcm","clk":"5348574669","pt":1646218982052,"mc":[{"id":"1.195453626","rc":[{"atb":[[1.55,0]],"id":37429121}],"con":true,"img":false}]}
{"op":"mcm","clk":"5348574680","pt":1646218982152,"mc":[{"id":"1.195453626","rc":[{"atb":[[1.36,95.42]],"id":37429121}],"con":true,"img":false}]}
{"op":"mcm","clk":"5348574696","pt":1646218982263,"mc":[{"id":"1.195453626","rc":[{"atl":[[6,4]],"id":36592903}],"con":true,"img":false}]}
{"op":"mcm","clk":"5348574806","pt":1646218983357,"mc":[{"id":"1.195453626","rc":[{"atl":[[4.9,36.53]],"id":38981227}],"con":true,"img":false}]}
{"op":"mcm","clk":"5348574836","pt":1646218983671,"mc":[{"id":"1.195453626","rc":[{"atb":[[2.74,0],[2.82,27.78]],"id":38981227}],"con":true,"img":false}]}
{"op":"mcm","clk":"5348574916","pt":1646218984345,"mc":[{"id":"1.195453626","rc":[{"atl":[[6,0]],"id":36592903}],"con":true,"img":false}]}
{"op":"mcm","clk":"5348574965","pt":1646218984868,"mc":[{"id":"1.195453626","rc":[{"atb":[[2.84,2.1]],"id":38981227}],"con":true,"img":false}]}
{"op":"mcm","clk":"5348574989","pt":1646218985077,"mc":[{"id":"1.195453626","rc":[{"atb":[[2.86,4.87]],"id":38981227},{"atb":[[1.56,7.48]],"id":37429121}],"con":true,"img":false}]}
{"op":"mcm","clk":"5348575003","pt":1646218985183,"mc":[{"id":"1.195453626","rc":[{"atb":[[2.78,0]],"id":38981227},{"atb":[[3.9,2.49]],"id":36986045}],"con":true,"img":false}]}
{"op":"mcm","clk":"5348575023","pt":1646218985391,"mc":[{"id":"1.195453626","rc":[{"atb":[[2.88,1.66]],"id":38981227},{"atb":[[4,3.02]],"id":36986045}],"con":true,"img":false}]}
{"op":"mcm","clk":"5348575094","pt":1646218985860,"mc":[{"id":"1.195453626","rc":[{"atl":[[6,4]],"id":36592903}],"con":true,"img":false}]}
{"op":"mcm","clk":"5348575199","pt":1646218986844,"mc":[{"id":"1.195453626","rc":[{"atb":[[2.84,0]],"id":38981227},{"atb":[[3.3,0],[3.9,32.38]],"id":36986045}],"con":true,"img":false}]}
{"op":"mcm","clk":"5348575252","pt":1646218987362,"mc":[{"id":"1.195453626","rc":[{"atb":[[4,16.94]],"id":36986045}],"con":true,"img":false}]}
{"op":"mcm","clk":"5348575266","pt":1646218987482,"mc":[{"id":"1.195453626","rc":[{"spn":3.74,"spf":"NaN","id":38981227},{"atb":[[3.95,19.81]],"id":36986045},{"spn":5.3,"spf":"NaN","id":36986045},{"spn":1.95,"spf":1.0,"id":36592903},{"spn":1.86,"spf":"NaN","id":37429121},{"spn":3.95,"spf":"NaN","id":40559875}],"con":true,"img":false}]}
{"op":"mcm","clk":"5348575276","pt":1646218987582,"mc":[{"id":"1.195453626","rc":[{"atb":[[1.63,8.89]],"id":37429121}],"con":true,"img":false}]}
{"op":"mcm","clk":"5348575292","pt":1646218987784,"mc":[{"id":"1.195453626","rc":[{"atb":[[1.59,27.81]],"id":37429121}],"con":true,"img":false}]}
{"op":"mcm","clk":"5348575374","pt":1646218988666,"mc":[{"id":"1.195453626","rc":[{"atb":[[2.9,2]],"id":38981227}],"con":true,"img":false}]}
{"op":"mcm","clk":"5348575392","pt":1646218988875,"mc":[{"id":"1.195453626","rc":[{"atb":[[2.86,2.87]],"id":38981227},{"atl":[[6,0]],"id":36592903}],"con":true,"img":false}]}
{"op":"mcm","clk":"5348575414","pt":1646218989083,"mc":[{"id":"1.195453626","rc":[{"atb":[[1.59,0],[1.6,43.34]],"id":37429121}],"con":true,"img":false}]}
{"op":"mcm","clk":"5348575490","pt":1646218989862,"mc":[{"id":"1.195453626","rc":[{"atb":[[3.75,5],[3.95,22.31],[3.7,0],[3.9,29.88]],"id":36986045}],"con":true,"img":false}]}
{"op":"mcm","clk":"5348575497","pt":1646218989964,"mc":[{"id":"1.195453626","rc":[{"atb":[[4.1,14.06]],"id":36986045}],"con":true,"img":false}]}
{"op":"mcm","clk":"5348575511","pt":1646218990071,"mc":[{"id":"1.195453626","rc":[{"atb":[[3.95,2.5]],"id":36986045},{"atl":[[6,4]],"id":36592903},{"atb":[[3.95,5],[4.2,8.54],[4.3,3.94],[3.9,0]],"id":42099020}],"con":true,"img":false}]}
{"op":"mcm","clk":"5348575520","pt":1646218990176,"mc":[{"id":"1.195453626","rc":[{"atb":[[3.95,20.06]],"id":42099020}],"con":true,"img":false}]}
{"op":"mcm","clk":"5348575535","pt":1646218990282,"mc":[{"id":"1.195453626","rc":[{"atb":[[4.3,11.47],[3.8,17.79]],"id":42099020}],"con":true,"img":false}]}
{"op":"mcm","clk":"5348575547","pt":1646218990383,"mc":[{"id":"1.195453626","rc":[{"atb":[[1.56,1.48]],"id":37429121},{"atb":[[2.18,105.93],[4.2,1.66]],"id":42099020},{"atb":[[4.4,36.76]],"id":39360156}],"con":true,"img":false}]}
{"op":"mcm","clk":"5348575565","pt":1646218990591,"mc":[{"id":"1.195453626","rc":[{"atb":[[1.18,250]],"id":37429121}],"con":true,"img":false}]}
{"op":"mcm","clk":"5348575599","pt":1646218990851,"mc":[{"id":"1.195453626","rc":[{"atb":[[4,15.58]],"id":36986045}],"con":true,"img":false}]}
{"op":"mcm","clk":"5348575612","pt":1646218990957,"mc":[{"id":"1.195453626","rc":[{"atb":[[4.2,1.35]],"id":36986045},{"atl":[[6,0]],"id":36592903},{"atb":[[2.06,0]],"id":42099020},{"atl":[[8.4,0]],"id":42099020}],"con":true,"img":false}]}
{"op":"mcm","clk":"5348575624","pt":1646218991063,"mc":[{"id":"1.195453626","rc":[{"atl":[[8.6,2.63]],"id":42099020},{"atl":[[6.4,23.15]],"id":40559875}],"con":true,"img":false}]}
{"op":"mcm","clk":"5348575634","pt":1646218991167,"mc":[{"id":"1.195453626","rc":[{"atl":[[24,17.77],[25,10]],"id":39360156}],"con":true,"img":false}]}
{"op":"mcm","clk":"5348575663","pt":1646218991374,"mc":[{"id":"1.195453626","rc":[{"atb":[[2.64,2.5]],"id":38981227}],"con":true,"img":false}]}
{"op":"mcm","clk":"5348575672","pt":1646218991475,"mc":[{"id":"1.195453626","rc":[{"atb":[[2.84,30.7],[2.9,5.66]],"id":38981227},{"atl":[[6,4]],"id":36592903}],"con":true,"img":false}]}
{"op":"mcm","clk":"5348575696","pt":1646218991686,"mc":[{"id":"1.195453626","rc":[{"atb":[[2.82,0],[2.84,54.41]],"id":38981227}],"con":true,"img":false}]}
{"op":"mcm","clk":"5348575826","pt":1646218992882,"mc":[{"id":"1.195453626","rc":[{"atb":[[2.86,0]],"id":38981227}],"con":true,"img":false}]}
{"op":"mcm","clk":"5348575847","pt":1646218993099,"mc":[{"id":"1.195453626","rc":[{"atl":[[17,0]],"id":42099020}],"con":true,"img":false}]}
{"op":"mcm","clk":"5348575858","pt":1646218993195,"mc":[{"id":"1.195453626","rc":[{"atl":[[15.5,15.8]],"id":42099020}],"con":true,"img":false}]}
{"op":"mcm","clk":"5348575991","pt":1646218994499,"mc":[{"id":"1.195453626","rc":[{"atb":[[3,31.45]],"id":42099020},{"atb":[[6.6,16.37]],"id":39360156}],"con":true,"img":false}]}
{"op":"mcm","clk":"5348575999","pt":1646218994549,"mc":[{"id":"1.195453626","rc":[{"atb":[[1.01,2.52]],"id":38981227}],"con":true,"img":false}]}
{"op":"mcm","clk":"5348576022","pt":1646218994756,"mc":[{"id":"1.195453626","rc":[{"atb":[[1.01,2.1]],"id":38981227}],"con":true,"img":false}]}
{"op":"mcm","clk":"5348576036","pt":1646218994857,"mc":[{"id":"1.195453626","rc":[{"atb":[[1.01,0]],"id":38981227}],"con":true,"img":false}]}
{"op":"mcm","clk":"5348576047","pt":1646218994964,"mc":[{"id":"1.195453626","rc":[{"atb":[[2.92,2.1]],"id":38981227}],"con":true,"img":false}]}
{"op":"mcm","clk":"5348576064","pt":1646218995069,"mc":[{"id":"1.195453626","rc":[{"atb":[[2.94,2]],"id":38981227}],"con":true,"img":false}]}
{"op":"mcm","clk":"5348576085","pt":1646218995278,"mc":[{"id":"1.195453626","rc":[{"atb":[[2.9,3.66]],"id":38981227}],"con":true,"img":false}]}
{"op":"mcm","clk":"5348576145","pt":1646218995902,"mc":[{"id":"1.195453626","rc":[{"atb":[[1.47,21.33]],"id":37429121}],"con":true,"img":false}]}
{"op":"mcm","clk":"5348576163","pt":1646218996059,"mc":[{"id":"1.195453626","rc":[{"atl":[[6,0]],"id":36592903}],"con":true,"img":false}]}
{"op":"mcm","clk":"5348576215","pt":1646218996579,"mc":[{"id":"1.195453626","rc":[{"atb":[[3.95,5],[3.8,48.99]],"id":42099020}],"con":true,"img":false}]}
{"op":"mcm","clk":"5348576247","pt":1646218996992,"mc":[{"id":"1.195453626","rc":[{"atl":[[3.4,18.16]],"id":36592903}],"con":true,"img":false}]}
{"op":"mcm","clk":"5348576257","pt":1646218997101,"mc":[{"id":"1.195453626","rc":[{"atl":[[3.6,0]],"id":36592903}],"con":true,"img":false}]}
{"op":"mcm","clk":"5348576265","pt":1646218997160,"mc":[{"id":"1.195453626","rc":[{"atl":[[3.6,35.22],[3.7,0]],"id":36592903}],"con":true,"img":false}]}
{"op":"mcm","clk":"5348576311","pt":1646218997575,"mc":[{"id":"1.195453626","rc":[{"atb":[[2.84,30.7],[2.9,19.23]],"id":38981227}],"con":true,"img":false}]}
{"op":"mcm","clk":"5348576349","pt":1646218998102,"mc":[{"id":"1.195453626","rc":[{"atl":[[6,4]],"id":36592903}],"con":true,"img":false}]}
{"op":"mcm","clk":"5348576453","pt":1646218999202,"mc":[{"id":"1.195453626","rc":[{"atb":[[2.94,4.87]],"id":38981227},{"atl":[[6,0]],"id":36592903}],"con":true,"img":false}]}
{"op":"mcm","clk":"5348576574","pt":1646219000466,"mc":[{"id":"1.195453626","rc":[{"atl":[[6,4]],"id":36592903}],"con":true,"img":false}]}
{"op":"mcm","clk":"5348576596","pt":1646219000670,"mc":[{"id":"1.195453626","rc":[{"atb":[[3.95,43.44]],"id":36986045}],"con":true,"img":false}]}
{"op":"mcm","clk":"5348576607","pt":1646219000775,"mc":[{"id":"1.195453626","rc":[{"atb":[[3.9,0]],"id":36986045}],"con":true,"img":false}]}
{"op":"mcm","clk":"5348576613","pt":1646219000880,"mc":[{"id":"1.195453626","rc":[{"atl":[[9,6.25]],"id":42099020}],"con":true,"img":false}]}
{"op":"mcm","clk":"5348576660","pt":1646219001401,"mc":[{"id":"1.195453626","rc":[{"atl":[[6,0]],"id":36592903},{"atl":[[9.2,0],[9.6,0],[8.8,0]],"id":42099020}],"con":true,"img":false}]}
{"op":"mcm","clk":"5348576716","pt":1646219001973,"mc":[{"id":"1.195453626","rc":[{"atb":[[1.87,0]],"id":36592903},{"atb":[[1.47,0]],"id":37429121}],"con":true,"img":false}]}
{"op":"mcm","clk":"5348576723","pt":1646219002076,"mc":[{"id":"1.195453626","rc":[{"atb":[[2.92,0]],"id":38981227}],"con":true,"img":false}]}
{"op":"mcm","clk":"5348576732","pt":1646219002181,"mc":[{"id":"1.195453626","rc":[{"atl":[[6,4]],"id":36592903}],"con":true,"img":false}]}
{"op":"mcm","clk":"5348576744","pt":1646219002286,"mc":[{"id":"1.195453626","rc":[{"atb":[[2.84,73.18],[2.9,3.66]],"id":38981227}],"con":true,"img":false}]}
{"op":"mcm","clk":"5348576775","pt":1646219002598,"mc":[{"id":"1.195453626","rc":[{"atb":[[1.01,2.52]],"id":38981227}],"con":true,"img":false}]}
{"op":"mcm","clk":"5348576794","pt":1646219002809,"mc":[{"id":"1.195453626","rc":[{"atb":[[1.01,2.1]],"id":38981227}],"con":true,"img":false}]}
{"op":"mcm","clk":"5348576802","pt":1646219002910,"mc":[{"id":"1.195453626","rc":[{"atb":[[1.01,0]],"id":38981227}],"con":true,"img":false}]}
{"op":"mcm","clk":"5348576812","pt":1646219002963,"mc":[{"id":"1.195453626","rc":[{"atb":[[2.96,2.1]],"id":38981227}],"con":true,"img":false}]}
{"op":"mcm","clk":"5348576822","pt":1646219003068,"mc":[{"id":"1.195453626","rc":[{"atb":[[2.88,0],[2.98,2]],"id":38981227},{"atb":[[4,13.92]],"id":36986045},{"atb":[[4.2,0]],"id":42099020}],"con":true,"img":false}]}
{"op":"mcm","clk":"5348576841","pt":1646219003275,"mc":[{"id":"1.195453626","rc":[{"atb":[[2.94,2.87],[2.96,3.76]],"id":38981227},{"atb":[[4.2,3.02]],"id":36986045},{"atb":[[4.4,1.66]],"id":42099020}],"con":true,"img":false}]}
{"op":"mcm","clk":"5348576884","pt":1646219003698,"mc":[{"id":"1.195453626","rc":[{"atl":[[6,0]],"id":36592903},{"atb":[[1.63,4]],"id":37429121}],"con":true,"img":false}]}
{"op":"mcm","clk":"5348576905","pt":1646219003906,"mc":[{"id":"1.195453626","rc":[{"atl":[[6,4]],"id":36592903},{"atb":[[1.6,12]],"id":37429121}],"con":true,"img":false}]}
{"op":"mcm","clk":"5348576927","pt":1646219004113,"mc":[{"id":"1.195453626","rc":[{"atl":[[6,0]],"id":36592903}],"con":true,"img":false}]}
{"op":"mcm","clk":"5348576956","pt":1646219004378,"mc":[{"id":"1.195453626","rc":[{"atl":[[2.14,28.18]],"id":37429121}],"con":true,"img":false}]}
{"op":"mcm","clk":"5348576977","pt":1646219004478,"mc":[{"id":"1.195453626","rc":[{"atb":[[2.76,2]],"id":36986045}],"con":true,"img":false}]}
{"op":"mcm","clk":"5348577002","pt":1646219004583,"mc":[{"id":"1.195453626","rc":[{"atb":[[2.88,31.06]],"id":36986045}],"con":true,"img":false}]}
{"op":"mcm","clk":"5348577011","pt":1646219004694,"mc":[{"id":"1.195453626","rc":[{"atl":[[2.1,4.6]],"id":37429121}],"con":true,"img":false}]}
{"op":"mcm","clk":"5348577060","pt":1646219005213,"mc":[{"id":"1.195453626","rc":[{"atb":[[2.98,6.99]],"id":38981227}],"con":true,"img":false}]}
{"op":"mcm","clk":"5348577077","pt":1646219005366,"mc":[{"id":"1.195453626","rc":[{"atb":[[2.94,18.61],[2.84,30.7],[2.9,0]],"id":38981227}],"con":true,"img":false}]}
{"op":"mcm","clk":"5348577174","pt":1646219006408,"mc":[{"id":"1.195453626","rc":[{"atb":[[1.9,52.49]],"id":36592903}],"con":true,"img":false}]}
{"op":"mcm","clk":"5348577189","pt":1646219006467,"mc":[{"id":"1.195453626","rc":[{"atl":[[6,4]],"id":36592903},{"atl":[[2.14,10.64],[2.12,18.8]],"id":37429121},{"atb":[[1.96,2],[1.9,38]],"id":40559875}],"con":true,"img":false}]}
{"op":"mcm","clk":"5348577199","pt":1646219006566,"mc":[{"id":"1.195453626","rc":[{"atl":[[2.14,33.5],[2.16,30.28]],"id":37429121}],"con":true,"img":false}]}
{"op":"mcm","clk":"5348577218","pt":1646219006675,"mc":[{"id":"1.195453626","rc":[{"atl":[[6,0]],"id":36592903}],"con":true,"img":false}]}
{"op":"mcm","clk":"5348577229","pt":1646219006778,"mc":[{"id":"1.195453626","rc":[{"atl":[[2.1,2.52]],"id":37429121}],"con":true,"img":false}]}
{"op":"mcm","clk":"5348577254","pt":1646219006996,"mc":[{"id":"1.195453626","rc":[{"atl":[[6,4]],"id":36592903}],"con":true,"img":false}]}
{"op":"mcm","clk":"5348577301","pt":1646219007405,"mc":[{"id":"1.195453626","rc":[{"atl":[[2.16,33.04]],"id":37429121}],"con":true,"img":false}]}
{"op":"mcm","clk":"5348577335","pt":1646219007772,"mc":[{"id":"1.195453626","rc":[{"atl":[[2.16,30.28]],"id":37429121}],"con":true,"img":false}]}
{"op":"mcm","clk":"5348577357","pt":1646219008083,"mc":[{"id":"1.195453626","rc":[{"atl":[[2.14,35.62]],"id":37429121}],"con":true,"img":false}]}
{"op":"mcm","clk":"5348577386","pt":1646219008397,"mc":[{"id":"1.195453626","rc":[{"atb":[[2.94,15.74]],"id":38981227},{"atb":[[1.87,12.65]],"id":36592903},{"atb":[[1.47,9.6]],"id":37429121},{"atl":[[2.14,33.5]],"id":37429121}],"con":true,"img":false}]}
{"op":"mcm","clk":"5348577400","pt":1646219008500,"mc":[{"id":"1.195453626","rc":[{"atl":[[6,0]],"id":36592903}],"con":true,"img":false}]}
{"op":"mcm","clk":"5348577417","pt":1646219008709,"mc":[{"id":"1.195453626","rc":[{"atl":[[2.16,31.52]],"id":37429121}],"con":true,"img":false}]}
{"op":"mcm","clk":"5348577461","pt":1646219009122,"mc":[{"id":"1.195453626","rc":[{"atl":[[2.16,30.28]],"id":37429121}],"con":true,"img":false}]}
{"op":"mcm","clk":"5348577494","pt":1646219009383,"mc":[{"id":"1.195453626","rc":[{"atl":[[2.14,40.9]],"id":37429121}],"con":true,"img":false}]}
{"op":"mcm","clk":"5348577529","pt":1646219009697,"mc":[{"id":"1.195453626","rc":[{"atl":[[6,4]],"id":36592903}],"con":true,"img":false}]}
{"op":"mcm","clk":"5348577615","pt":1646219010480,"mc":[{"id":"1.195453626","rc":[{"atl":[[9.4,15.15]],"id":42099020}],"con":true,"img":false}]}
{"op":"mcm","clk":"5348577667","pt":1646219011004,"mc":[{"id":"1.195453626","rc":[{"atb":[[2.96,1.66],[2.84,0]],"id":38981227},{"atb":[[3.2,19.81],[4.1,0]],"id":36986045},{"atb":[[1.36,10]],"id":37429121},{"atb":[[2.42,0]],"id":40559875},{"atb":[[10,3.13]],"id":39360156}],"con":true,"img":false}]}
{"op":"mcm","clk":"5348577681","pt":1646219011110,"mc":[{"id":"1.195453626","rc":[{"atb":[[2.42,65.91]],"id":38981227},{"atb":[[1.28,85.42]],"id":37429121},{"atb":[[2.34,30.7]],"id":40559875},{"atb":[[8.8,4.84]],"id":39360156}],"con":true,"img":false}]}
{"op":"mcm","clk":"5348577691","pt":1646219011213,"mc":[{"id":"1.195453626","rc":[{"atb":[[2.64,26.62],[2.94,0]],"id":38981227}],"con":true,"img":false}]}
{"op":"mcm","clk":"5348577704","pt":1646219011316,"mc":[{"id":"1.195453626","rc":[{"atb":[[1.01,2.52]],"id":38981227}],"con":true,"img":false}]}
{"op":"mcm","clk":"5348577713","pt":1646219011367,"mc":[{"id":"1.195453626","rc":[{"atb":[[1.01,2.1]],"id":38981227},{"atb":[[4.2,1.66]],"id":36986045}],"con":true,"img":false}]}
{"op":"mcm","clk":"5348577725","pt":1646219011474,"mc":[{"id":"1.195453626","rc":[{"atb":[[3.75,46.18],[4.1,1.35]],"id":36986045},{"atl":[[6,0]],"id":36592903}],"con":true,"img":false}]}
{"op":"mcm","clk":"5348577736","pt":1646219011575,"mc":[{"id":"1.195453626","rc":[{"atb":[[3.95,2.5]],"id":36986045}],"con":true,"img":false}]}
{"op":"mcm","clk":"5348577750","pt":1646219011689,"mc":[{"id":"1.195453626","rc":[{"atb":[[1.01,0]],"id":38981227},{"atb":[[3.75,5]],"id":36986045}],"con":true,"img":false}]}
{"op":"mcm","clk":"5348577761","pt":1646219011792,"mc":[{"id":"1.195453626","rc":[{"atb":[[3,2.1]],"id":38981227}],"con":true,"img":false}]}
{"op":"mcm","clk":"5348577767","pt":1646219011897,"mc":[{"id":"1.195453626","rc":[{"atb":[[4,11.83]],"id":42099020}],"con":true,"img":false}]}
{"op":"mcm","clk":"5348577778","pt":1646219012004,"mc":[{"id":"1.195453626","rc":[{"atb":[[3.05,2]],"id":38981227}],"con":true,"img":false}]}
{"op":"mcm","clk":"5348577785","pt":1646219012105,"mc":[{"id":"1.195453626","rc":[{"atb":[[3.95,26.54],[3.8,17.79]],"id":42099020}],"con":true,"img":false}]}
{"op":"mcm","clk":"5348577794","pt":1646219012211,"mc":[{"id":"1.195453626","rc":[{"atb":[[2.98,4.99]],"id":38981227}],"con":true,"img":false}]}
{"op":"mcm","clk":"5348577870","pt":1646219012998,"mc":[{"id":"1.195453626","rc":[{"atb":[[6.6,9.92]],"id":39360156}],"con":true,"img":false}]}
{"op":"mcm","clk":"5348577986","pt":1646219014190,"mc":[{"id":"1.195453626","rc":[{"atb":[[3.95,32.38]],"id":36986045}],"con":true,"img":false}]}
{"op":"mcm","clk":"5348578159","pt":1646219015810,"mc":[{"id":"1.195453626","rc":[{"atb":[[2.64,2.5],[2.98,22.56]],"id":38981227}],"con":true,"img":false}]}
{"op":"mcm","clk":"5348578222","pt":1646219016383,"mc":[{"id":"1.195453626","rc":[{"atl":[[3.45,2.5],[5.5,42.79],[3.65,5]],"id":36592903},{"atb":[[1.6,36]],"id":37429121},{"atb":[[3.35,4],[3.25,0],[3.2,0],[3.15,0]],"id":40559875}],"con":true,"img":false}]}
