{"op":"mcm","clk":"5352134785","pt":1646183310062,"mc":[{"id":"1.195503857","marketDefinition":{"bspMarket":false,"turnInPlayEnabled":false,"persistenceEnabled":false,"marketBaseRate":7.0,"eventId":"31272499","eventTypeId":"4339","numberOfWinners":1,"bettingType":"ODDS","marketType":"MATCH_BET","marketTime":"2022-03-02T11:39:00.000Z","suspendTime":"2022-03-02T11:39:00.000Z","bspReconciled":false,"complete":true,"inPlay":false,"crossMatching":true,"runnersVoidable":false,"numberOfActiveRunners":2,"betDelay":0,"status":"OPEN","runners":[{"status":"ACTIVE","sortPriority":1,"id":38247349,"name":"3. Hearts Thunder"},{"status":"ACTIVE","sortPriority":2,"id":41120152,"name":"8. Rosas Memory"}],"regulators":["MR_INT"],"venue":"Rockhampton","countryCode":"AU","discountAllowed":true,"timezone":"Australia/Queensland","openDate":"2022-03-02T08:34:00.000Z","version":4382585396,"name":"Hearts Thunder v Rosas Memory","eventName":"Rockhampton (AUS) 2nd Mar"},"rc":[],"con":true,"img":false}]}
{"op":"mcm","clk":"5352139712","pt":1646183422125,"mc":[{"id":"1.195503857","rc":[{"atb":[[1.72,7.49],[1.32,16.87],[1.52,10.38]],"id":41120152},{"atb":[[1.45,11.99],[1.85,6.35],[1.65,8.3]],"id":38247349}],"con":true,"img":false}]}
{"op":"mcm","clk":"5352146171","pt":1646183572635,"mc":[{"id":"1.195503857","marketDefinition":{"bspMarket":false,"turnInPlayEnabled":false,"persistenceEnabled":false,"marketBaseRate":7.0,"eventId":"31272499","eventTypeId":"4339","numberOfWinners":1,"bettingType":"ODDS","marketType":"MATCH_BET","marketTime":"2022-03-02T11:39:00.000Z","suspendTime":"2022-03-02T11:39:00.000Z","bspReconciled":false,"complete":true,"inPlay":false,"crossMatching":true,"runnersVoidable":false,"numberOfActiveRunners":2,"betDelay":0,"status":"OPEN","runners":[{"status":"ACTIVE","sortPriority":1,"id":38247349,"name":"3. Hearts Thunder"},{"status":"ACTIVE","sortPriority":2,"id":41120152,"name":"8. Rosas Memory"}],"regulators":["MR_INT"],"venue":"Rockhampton","countryCode":"AU","discountAllowed":true,"timezone":"Australia/Queensland","openDate":"2022-03-02T08:28:00.000Z","version":4382597882,"name":"Hearts Thunder v Rosas Memory","eventName":"Rockhampton (AUS) 2nd Mar"},"rc":[],"con":true,"img":false}]}
{"op":"mcm","clk":"5352164844","pt":1646184074719,"mc":[{"id":"1.195503857","marketDefinition":{"bspMarket":false,"turnInPlayEnabled":false,"persistenceEnabled":false,"marketBaseRate":7.0,"eventId":"31272499","eventTypeId":"4339","numberOfWinners":1,"bettingType":"ODDS","marketType":"MATCH_BET","marketTime":"2022-03-02T11:29:00.000Z","suspendTime":"2022-03-02T11:29:00.000Z","bspReconciled":false,"complete":true,"inPlay":false,"crossMatching":true,"runnersVoidable":false,"numberOfActiveRunners":2,"betDelay":0,"status":"OPEN","runners":[{"status":"ACTIVE","sortPriority":1,"id":38247349,"name":"3. Hearts Thunder"},{"status":"ACTIVE","sortPriority":2,"id":41120152,"name":"8. Rosas Memory"}],"regulators":["MR_INT"],"venue":"Rockhampton","countryCode":"AU","discountAllowed":true,"timezone":"Australia/Queensland","openDate":"2022-03-02T08:28:00.000Z","version":4382606089,"name":"Hearts Thunder v Rosas Memory","eventName":"Rockhampton (AUS) 2nd Mar"},"rc":[],"con":true,"img":false}]}
{"op":"mcm","clk":"5352466711","pt":1646191002691,"mc":[{"id":"1.195503857","marketDefinition":{"bspMarket":false,"turnInPlayEnabled":false,"persistenceEnabled":false,"marketBaseRate":7.0,"eventId":"31272499","eventTypeId":"4339","numberOfWinners":1,"bettingType":"ODDS","marketType":"MATCH_BET","marketTime":"2022-03-02T11:29:00.000Z","suspendTime":"2022-03-02T11:29:00.000Z","bspReconciled":false,"complete":true,"inPlay":false,"crossMatching":true,"runnersVoidable":false,"numberOfActiveRunners":2,"betDelay":0,"status":"OPEN","runners":[{"status":"ACTIVE","sortPriority":1,"id":38247349,"name":"3. Hearts Thunder"},{"status":"ACTIVE","sortPriority":2,"id":41120152,"name":"8. Rosas Memory"}],"regulators":["MR_INT"],"venue":"Rockhampton","countryCode":"AU","discountAllowed":true,"timezone":"Australia/Queensland","openDate":"2022-03-02T08:28:00.000Z","version":4382606089,"name":"Hearts Thunder v Rosas Memory","eventName":"Rockhampton (AUS) 2nd Mar"},"rc":[{"atb":[[1.72,7.51],[1.32,16.89],[1.52,10.39]],"id":41120152},{"atb":[[1.45,12.01],[1.85,6.36],[1.65,8.31]],"id":38247349}],"con":true,"img":true}]}
{"op":"mcm","clk":"5352732298","pt":1646198603668,"mc":[{"id":"1.195503857","rc":[{"atb":[[1.72,0],[1.32,0],[1.52,0]],"id":41120152},{"atb":[[1.45,0],[1.85,0],[1.65,0]],"id":38247349}],"con":true,"img":false}]}
{"op":"mcm","clk":"5352732760","pt":1646198617476,"mc":[{"id":"1.195503857","rc":[{"atb":[[1.72,7.5],[1.32,16.89],[1.52,10.39]],"id":41120152},{"atb":[[1.45,12.01],[1.85,6.36],[1.65,8.31]],"id":38247349}],"con":true,"img":false}]}
{"op":"mcm","clk":"5353028887","pt":1646207202758,"mc":[{"id":"1.195503857","marketDefinition":{"bspMarket":false,"turnInPlayEnabled":false,"persistenceEnabled":false,"marketBaseRate":7.0,"eventId":"31272499","eventTypeId":"4339","numberOfWinners":1,"bettingType":"ODDS","marketType":"MATCH_BET","marketTime":"2022-03-02T11:29:00.000Z","suspendTime":"2022-03-02T11:29:00.000Z","bspReconciled":false,"complete":true,"inPlay":false,"crossMatching":true,"runnersVoidable":false,"numberOfActiveRunners":2,"betDelay":0,"status":"OPEN","runners":[{"status":"ACTIVE","sortPriority":1,"id":38247349,"name":"3. Hearts Thunder"},{"status":"ACTIVE","sortPriority":2,"id":41120152,"name":"8. Rosas Memory"}],"regulators":["MR_INT"],"venue":"Rockhampton","countryCode":"AU","discountAllowed":true,"timezone":"Australia/Queensland","openDate":"2022-03-02T08:28:00.000Z","version":4382606089,"name":"Hearts Thunder v Rosas Memory","eventName":"Rockhampton (AUS) 2nd Mar"},"rc":[{"atb":[[1.72,7.5],[1.32,16.88],[1.52,10.39]],"id":41120152},{"atb":[[1.45,12],[1.85,6.35],[1.65,8.31]],"id":38247349}],"con":true,"img":true}]}
{"op":"mcm","clk":"5353300274","pt":1646212602762,"mc":[{"id":"1.195503857","marketDefinition":{"bspMarket":false,"turnInPlayEnabled":false,"persistenceEnabled":false,"marketBaseRate":7.0,"eventId":"31272499","eventTypeId":"4339","numberOfWinners":1,"bettingType":"ODDS","marketType":"MATCH_BET","marketTime":"2022-03-02T11:29:00.000Z","suspendTime":"2022-03-02T11:29:00.000Z","bspReconciled":false,"complete":true,"inPlay":false,"crossMatching":true,"runnersVoidable":false,"numberOfActiveRunners":2,"betDelay":0,"status":"OPEN","runners":[{"status":"ACTIVE","sortPriority":1,"id":38247349,"name":"3. Hearts Thunder"},{"status":"ACTIVE","sortPriority":2,"id":41120152,"name":"8. Rosas Memory"}],"regulators":["MR_INT"],"venue":"Rockhampton","countryCode":"AU","discountAllowed":true,"timezone":"Australia/Queensland","openDate":"2022-03-02T08:28:00.000Z","version":4382606089,"name":"Hearts Thunder v Rosas Memory","eventName":"Rockhampton (AUS) 2nd Mar"},"rc":[{"atb":[[1.72,7.49],[1.32,16.86],[1.52,10.37]],"id":41120152},{"atb":[[1.45,11.98],[1.85,6.34],[1.65,8.3]],"id":38247349}],"con":true,"img":true}]}
{"op":"mcm","clk":"5353900964","pt":1646219625212,"mc":[{"id":"1.195503857","rc":[{"atb":[[1.72,7.49],[1.32,16.86],[1.61,20.76],[1.52,10.37]],"id":41120152},{"atl":[[2.16,20.76]],"id":41120152},{"atb":[[1.45,11.99],[1.85,6.34],[1.65,8.3],[1.87,16.6]],"id":38247349},{"atl":[[2.54,16.6]],"id":38247349}],"con":true,"img":false}]}
{"op":"mcm","clk":"5353901469","pt":1646219630436,"mc":[{"id":"1.195503857","rc":[{"atl":[[2.16,0],[2.14,20.76]],"id":41120152}],"con":true,"img":false}]}
{"op":"mcm","clk":"5353907091","pt":1646219685247,"mc":[{"id":"1.195503857","rc":[{"atb":[[1.61,0]],"id":41120152},{"atl":[[2.14,0]],"id":41120152},{"atb":[[1.87,0]],"id":38247349},{"atl":[[2.54,0]],"id":38247349}],"con":true,"img":false}]}
{"op":"mcm","clk":"5353910756","pt":1646219720783,"mc":[{"id":"1.195503857","rc":[{"atb":[[1.61,2]],"id":41120152},{"atl":[[2.16,2]],"id":41120152},{"atb":[[1.87,2]],"id":38247349},{"atl":[[2.56,2]],"id":38247349}],"con":true,"img":false}]}
{"op":"mcm","clk":"5353911333","pt":1646219725978,"mc":[{"id":"1.195503857","rc":[{"atb":[[1.86,16.6],[1.87,0]],"id":38247349},{"atl":[[2.56,0],[2.54,16.6]],"id":38247349}],"con":true,"img":false}]}
{"op":"mcm","clk":"5353911698","pt":1646219729534,"mc":[{"id":"1.195503857","rc":[{"atb":[[1.72,0],[1.32,0],[1.52,0]],"id":41120152},{"atb":[[1.45,0],[1.85,0],[1.65,0]],"id":38247349}],"con":true,"img":false}]}
{"op":"mcm","clk":"5353912116","pt":1646219733405,"mc":[{"id":"1.195503857","rc":[{"atb":[[1.72,7.49],[1.32,16.86],[1.52,10.37]],"id":41120152},{"atb":[[1.45,11.99],[1.85,6.34],[1.65,8.3]],"id":38247349}],"con":true,"img":false}]}
{"op":"mcm","clk":"5353920568","pt":1646219803612,"mc":[{"id":"1.195503857","rc":[{"atl":[[2.56,16.6],[2.54,0]],"id":38247349}],"con":true,"img":false}]}
{"op":"mcm","clk":"5353934932","pt":1646219941700,"mc":[{"id":"1.195503857","rc":[{"atb":[[1.72,0],[1.32,0],[1.52,0]],"id":41120152},{"atb":[[1.45,0],[1.85,0],[1.65,0]],"id":38247349}],"con":true,"img":false}]}
{"op":"mcm","clk":"5353934952","pt":1646219941879,"mc":[{"id":"1.195503857","rc":[{"atb":[[1.6,2],[1.61,0]],"id":41120152}],"con":true,"img":false}]}
{"op":"mcm","clk":"5353935385","pt":1646219946481,"mc":[{"id":"1.195503857","rc":[{"atb":[[1.72,7.49],[1.32,16.86],[1.52,10.37]],"id":41120152},{"atb":[[1.45,11.99],[1.85,6.34],[1.65,8.3]],"id":38247349}],"con":true,"img":false}]}
{"op":"mcm","clk":"5353938438","pt":1646219980317,"mc":[{"id":"1.195503857","rc":[{"atl":[[2.16,0],[2.14,2]],"id":41120152},{"atb":[[1.88,16.6],[1.86,0]],"id":38247349}],"con":true,"img":false}]}
{"op":"mcm","clk":"5353938461","pt":1646219980525,"mc":[{"id":"1.195503857","rc":[{"atb":[[1.88,0],[1.86,16.6]],"id":38247349}],"con":true,"img":false}]}
{"op":"mcm","clk":"5353938506","pt":1646219981050,"mc":[{"id":"1.195503857","rc":[{"atl":[[2.56,0],[2.54,16.6]],"id":38247349}],"con":true,"img":false}]}
{"op":"mcm","clk":"5353938522","pt":1646219981203,"mc":[{"id":"1.195503857","rc":[{"atl":[[2.14,0],[2.08,2]],"id":41120152},{"atb":[[1.88,2],[1.86,0]],"id":38247349}],"con":true,"img":false}]}
{"op":"mcm","clk":"5353938939","pt":1646219986437,"mc":[{"id":"1.195503857","rc":[{"atl":[[2.02,2],[2.08,0]],"id":41120152},{"atb":[[2,2],[1.88,0]],"id":38247349}],"con":true,"img":false}]}
{"op":"mcm","clk":"5353939733","pt":1646219996454,"mc":[{"id":"1.195503857","rc":[{"atb":[[2,0],[1.95,2]],"id":38247349}],"con":true,"img":false}]}
{"op":"mcm","clk":"5353939743","pt":1646219996661,"mc":[{"id":"1.195503857","rc":[{"atb":[[1.96,2],[1.95,0]],"id":38247349}],"con":true,"img":false}]}
{"op":"mcm","clk":"5353940145","pt":1646220001765,"mc":[{"id":"1.195503857","rc":[{"atb":[[1.97,2],[1.96,0]],"id":38247349}],"con":true,"img":false}]}
{"op":"mcm","clk":"5353940598","pt":1646220006934,"mc":[{"id":"1.195503857","rc":[{"atb":[[1.98,2],[1.97,0]],"id":38247349}],"con":true,"img":false}]}
{"op":"mcm","clk":"5353940880","pt":1646220010381,"mc":[{"id":"1.195503857","rc":[{"atb":[[1.99,2],[1.98,0]],"id":38247349}],"con":true,"img":false}]}
{"op":"mcm","clk":"5353942560","pt":1646220029295,"mc":[{"id":"1.195503857","rc":[{"atb":[[1.99,0],[1.98,2]],"id":38247349}],"con":true,"img":false}]}
{"op":"mcm","clk":"5353942582","pt":1646220029602,"mc":[{"id":"1.195503857","rc":[{"atb":[[2,2],[1.98,0]],"id":38247349}],"con":true,"img":false}]}
{"op":"mcm","clk":"5353942640","pt":1646220030284,"mc":[{"id":"1.195503857","rc":[{"atb":[[2,0],[1.99,2]],"id":38247349}],"con":true,"img":false}]}
{"op":"mcm","clk":"5353943094","pt":1646220035435,"mc":[{"id":"1.195503857","rc":[{"atb":[[1.98,2]],"id":38247349}],"con":true,"img":false}]}
{"op":"mcm","clk":"5353943104","pt":1646220035520,"mc":[{"id":"1.195503857","rc":[{"atb":[[1.99,0]],"id":38247349}],"con":true,"img":false}]}
{"op":"mcm","clk":"5353943129","pt":1646220035839,"mc":[{"id":"1.195503857","rc":[{"atl":[[2.56,2],[2.54,0]],"id":38247349}],"con":true,"img":false}]}
{"op":"mcm","clk":"5353943161","pt":1646220036212,"mc":[{"id":"1.195503857","rc":[{"atb":[[2.02,2],[1.98,0]],"id":38247349}],"con":true,"img":false}]}
{"op":"mcm","clk":"5353943481","pt":1646220039528,"mc":[{"id":"1.195503857","rc":[{"atl":[[2,2],[2.02,0]],"id":41120152}],"con":true,"img":false}]}
{"op":"mcm","clk":"5353943659","pt":1646220041356,"mc":[{"id":"1.195503857","rc":[{"atb":[[2.02,0],[2.06,2]],"id":38247349}],"con":true,"img":false}]}
{"op":"mcm","clk":"5353943983","pt":1646220044662,"mc":[{"id":"1.195503857","rc":[{"atl":[[2,0],[1.98,2]],"id":41120152}],"con":true,"img":false}]}
{"op":"mcm","clk":"5353944150","pt":1646220046434,"mc":[{"id":"1.195503857","rc":[{"atb":[[2.06,0],[2.04,2]],"id":38247349}],"con":true,"img":false}]}
{"op":"mcm","clk":"5353944581","pt":1646220051534,"mc":[{"id":"1.195503857","rc":[{"atb":[[2.06,2],[2.04,0]],"id":38247349}],"con":true,"img":false}]}
{"op":"mcm","clk":"5353945609","pt":1646220062888,"mc":[{"id":"1.195503857","rc":[{"atb":[[2,2]],"id":38247349}],"con":true,"img":false}]}
{"op":"mcm","clk":"5353945621","pt":1646220062997,"mc":[{"id":"1.195503857","rc":[{"atb":[[2.06,0]],"id":38247349}],"con":true,"img":false}]}
{"op":"mcm","clk":"5353946120","pt":1646220068090,"mc":[{"id":"1.195503857","rc":[{"atb":[[2,0],[1.99,2]],"id":38247349}],"con":true,"img":false}]}
{"op":"mcm","clk":"5353946339","pt":1646220070299,"mc":[{"id":"1.195503857","rc":[{"atl":[[1.97,2]],"id":41120152}],"con":true,"img":false}]}
{"op":"mcm","clk":"5353946348","pt":1646220070389,"mc":[{"id":"1.195503857","rc":[{"atl":[[1.98,0]],"id":41120152}],"con":true,"img":false}]}
{"op":"mcm","clk":"5353946587","pt":1646220073267,"mc":[{"id":"1.195503857","rc":[{"atb":[[1.99,0],[2.08,2]],"id":38247349}],"con":true,"img":false}]}
{"op":"mcm","clk":"5353946848","pt":1646220076173,"mc":[{"id":"1.195503857","rc":[{"atl":[[1.97,0],[1.96,2]],"id":41120152}],"con":true,"img":false}]}
{"op":"mcm","clk":"5353947812","pt":1646220086911,"mc":[{"id":"1.195503857","rc":[{"atb":[[2.1,2],[2.08,0]],"id":38247349}],"con":true,"img":false}]}
{"op":"mcm","clk":"5353947898","pt":1646220088007,"mc":[{"id":"1.195503857","rc":[{"atb":[[2.1,0],[2.08,2]],"id":38247349}],"con":true,"img":false}]}
{"op":"mcm","clk":"5353947954","pt":1646220088629,"mc":[{"id":"1.195503857","rc":[{"atl":[[1.96,0],[1.95,2]],"id":41120152},{"atb":[[2.1,2]],"id":38247349}],"con":true,"img":false}]}
{"op":"mcm","clk":"5353947969","pt":1646220088693,"mc":[{"id":"1.195503857","rc":[{"atb":[[2.08,0]],"id":38247349}],"con":true,"img":false}]}
{"op":"mcm","clk":"5353948815","pt":1646220098621,"mc":[{"id":"1.195503857","rc":[{"atl":[[2.56,0],[2.58,2]],"id":38247349}],"con":true,"img":false}]}
{"op":"mcm","clk":"5353949662","pt":1646220107162,"mc":[{"id":"1.195503857","rc":[{"atl":[[1.94,2],[1.95,0]],"id":41120152},{"atb":[[2.12,2],[2.1,0]],"id":38247349}],"con":true,"img":false}]}
{"op":"mcm","clk":"5353950225","pt":1646220113140,"mc":[{"id":"1.195503857","rc":[{"atl":[[1.9,2],[1.94,0]],"id":41120152},{"atb":[[2.12,0],[2.18,2]],"id":38247349}],"con":true,"img":false}]}
{"op":"mcm","clk":"5353950239","pt":1646220113349,"mc":[{"id":"1.195503857","rc":[{"atb":[[1.72,0],[1.32,0],[1.52,0]],"id":41120152},{"atb":[[1.45,0],[1.85,0],[1.65,0]],"id":38247349}],"con":true,"img":false}]}
{"op":"mcm","clk":"5353950712","pt":1646220118376,"mc":[{"id":"1.195503857","rc":[{"atl":[[1.89,2],[1.9,0]],"id":41120152},{"atb":[[2.18,0],[2.2,2]],"id":38247349}],"con":true,"img":false}]}
{"op":"mcm","clk":"5353951322","pt":1646220124796,"mc":[{"id":"1.195503857","rc":[{"atb":[[1.46,11.72],[1.26,20.75],[1.66,8.17]],"id":41120152},{"atb":[[1.89,6.06],[1.49,11],[1.69,7.82]],"id":38247349}],"con":true,"img":false}]}
{"op":"mcm","clk":"5353951336","pt":1646220124997,"mc":[{"id":"1.195503857","rc":[{"atb":[[1.6,0],[1.61,2]],"id":41120152},{"atb":[[2.12,2],[2.2,0]],"id":38247349}],"con":true,"img":false}]}
{"op":"mcm","clk":"5353952399","pt":1646220136272,"mc":[{"id":"1.195503857","rc":[{"atb":[[2.12,0],[2.14,2]],"id":38247349}],"con":true,"img":false}]}
{"op":"mcm","clk":"5353952880","pt":1646220141496,"mc":[{"id":"1.195503857","rc":[{"atb":[[2.12,2],[2.14,0]],"id":38247349}],"con":true,"img":false}]}
{"op":"mcm","clk":"5353954375","pt":1646220157651,"mc":[{"id":"1.195503857","rc":[{"atb":[[1.6,2],[1.61,0]],"id":41120152}],"con":true,"img":false}]}
{"op":"mcm","clk":"5353955314","pt":1646220167771,"mc":[{"id":"1.195503857","rc":[{"atb":[[2.06,2],[2.12,0]],"id":38247349}],"con":true,"img":false}]}
{"op":"mcm","clk":"5353955829","pt":1646220172943,"mc":[{"id":"1.195503857","rc":[{"atb":[[2.12,2]],"id":38247349}],"con":true,"img":false}]}
{"op":"mcm","clk":"5353955836","pt":1646220173047,"mc":[{"id":"1.195503857","rc":[{"atb":[[2.06,0]],"id":38247349}],"con":true,"img":false}]}
{"op":"mcm","clk":"5353956068","pt":1646220175456,"mc":[{"id":"1.195503857","rc":[{"atb":[[2.12,0],[2.14,2]],"id":38247349}],"con":true,"img":false}]}
{"op":"mcm","clk":"5353956538","pt":1646220180625,"mc":[{"id":"1.195503857","rc":[{"atb":[[2.12,2],[2.14,0]],"id":38247349}],"con":true,"img":false}]}
{"op":"mcm","clk":"5353957204","pt":1646220188671,"mc":[{"id":"1.195503857","rc":[{"atb":[[2.12,0],[2.14,2]],"id":38247349}],"con":true,"img":false}]}
{"op":"mcm","clk":"5353959046","pt":1646220208995,"mc":[{"id":"1.195503857","rc":[{"atb":[[2.14,0],[2.16,2]],"id":38247349}],"con":true,"img":false}]}
{"op":"mcm","clk":"5353959529","pt":1646220214425,"mc":[{"id":"1.195503857","rc":[{"atb":[[2.18,2],[2.16,0]],"id":38247349}],"con":true,"img":false}]}
{"op":"mcm","clk":"5353959689","pt":1646220216210,"mc":[{"id":"1.195503857","rc":[{"atl":[[2.6,2],[2.58,0]],"id":38247349}],"con":true,"img":false}]}
{"op":"mcm","clk":"5353959964","pt":1646220219509,"mc":[{"id":"1.195503857","rc":[{"atb":[[2.16,2]],"id":38247349}],"con":true,"img":false}]}
{"op":"mcm","clk":"5353959975","pt":1646220219614,"mc":[{"id":"1.195503857","rc":[{"atb":[[2.18,0]],"id":38247349}],"con":true,"img":false}]}
{"op":"mcm","clk":"5353960102","pt":1646220221122,"mc":[{"id":"1.195503857","rc":[{"atb":[[2.02,2],[2.16,0]],"id":38247349}],"con":true,"img":false}]}
{"op":"mcm","clk":"5353960132","pt":1646220221571,"mc":[{"id":"1.195503857","rc":[{"atb":[[2,2],[2.02,0]],"id":38247349}],"con":true,"img":false}]}
{"op":"mcm","clk":"5353960620","pt":1646220226613,"mc":[{"id":"1.195503857","rc":[{"atb":[[2.08,2]],"id":38247349}],"con":true,"img":false}]}
{"op":"mcm","clk":"5353960627","pt":1646220226732,"mc":[{"id":"1.195503857","rc":[{"atb":[[2,0]],"id":38247349}],"con":true,"img":false}]}
{"op":"mcm","clk":"5353960685","pt":1646220227450,"mc":[{"id":"1.195503857","rc":[{"atb":[[2.12,2],[2.08,0]],"id":38247349}],"con":true,"img":false}]}
{"op":"mcm","clk":"5353961155","pt":1646220232643,"mc":[{"id":"1.195503857","rc":[{"atb":[[2.12,0],[2.16,2]],"id":38247349}],"con":true,"img":false}]}
{"op":"mcm","clk":"5353961905","pt":1646220241065,"mc":[{"id":"1.195503857","rc":[{"atb":[[2.18,2],[2.16,0]],"id":38247349}],"con":true,"img":false}]}
{"op":"mcm","clk":"5353962047","pt":1646220242867,"mc":[{"id":"1.195503857","rc":[{"atl":[[29,1.42]],"id":41120152},{"atl":[[30,1.42]],"id":38247349}],"con":true,"img":false}]}
{"op":"mcm","clk":"5353962063","pt":1646220243065,"mc":[{"id":"1.195503857","rc":[{"atl":[[1.89,0],[1.9,2]],"id":41120152},{"atl":[[3.7,2],[2.6,0]],"id":38247349}],"con":true,"img":false}]}
{"op":"mcm","clk":"5353962352","pt":1646220246249,"mc":[{"id":"1.195503857","rc":[{"atb":[[2.18,0],[2.2,2]],"id":38247349}],"con":true,"img":false}]}
{"op":"mcm","clk":"5353962431","pt":1646220247078,"mc":[{"id":"1.195503857","rc":[{"atl":[[32,1.42]],"id":41120152},{"atl":[[32,1.42]],"id":38247349}],"con":true,"img":false}]}
{"op":"mcm","clk":"5353962534","pt":1646220248250,"mc":[{"id":"1.195503857","rc":[{"atl":[[1.9,0],[1.96,2]],"id":41120152},{"atl":[[3.7,0],[2.76,2]],"id":38247349}],"con":true,"img":false}]}
{"op":"mcm","clk":"5353962540","pt":1646220248355,"mc":[{"id":"1.195503857","rc":[{"atl":[[32,2.84]],"id":41120152},{"atl":[[32,2.84]],"id":38247349}],"con":true,"img":false}]}
{"op":"mcm","clk":"5353962602","pt":1646220248975,"mc":[{"id":"1.195503857","rc":[{"atl":[[2.8,2],[2.76,0]],"id":38247349}],"con":true,"img":false}]}
{"op":"mcm","clk":"5353962610","pt":1646220249079,"mc":[{"id":"1.195503857","rc":[{"atl":[[2.02,2],[1.96,0]],"id":41120152}],"con":true,"img":false}]}
{"op":"mcm","clk":"5353962647","pt":1646220249461,"mc":[{"id":"1.195503857","rc":[{"atl":[[2.8,0],[2.82,2]],"id":38247349}],"con":true,"img":false}]}
{"op":"mcm","clk":"5353962693","pt":1646220250075,"mc":[{"id":"1.195503857","rc":[{"atl":[[34,1.42]],"id":41120152},{"atl":[[34,1.42]],"id":38247349}],"con":true,"img":false}]}
{"op":"mcm","clk":"5353962735","pt":1646220250550,"mc":[{"id":"1.195503857","rc":[{"atl":[[29,0]],"id":41120152}],"con":true,"img":false}]}
{"op":"mcm","clk":"5353962817","pt":1646220251382,"mc":[{"id":"1.195503857","rc":[{"atl":[[34,2.84]],"id":41120152},{"atb":[[2,2]],"id":38247349},{"atl":[[34,2.84]],"id":38247349}],"con":true,"img":false}]}
{"op":"mcm","clk":"5353962823","pt":1646220251487,"mc":[{"id":"1.195503857","rc":[{"atb":[[2.2,0]],"id":38247349}],"con":true,"img":false}]}
{"op":"mcm","clk":"5353962958","pt":1646220252743,"mc":[{"id":"1.195503857","rc":[{"atl":[[30,1.42]],"id":41120152},{"atl":[[29,1.42]],"id":38247349}],"con":true,"img":false}]}
{"op":"mcm","clk":"5353963090","pt":1646220254264,"mc":[{"id":"1.195503857","rc":[{"atl":[[28,1.42]],"id":41120152},{"atl":[[27,1.42]],"id":38247349}],"con":true,"img":false}]}
{"op":"mcm","clk":"5353963128","pt":1646220254675,"mc":[{"id":"1.195503857","rc":[{"atl":[[2.82,0],[2.78,2]],"id":38247349}],"con":true,"img":false}]}
{"op":"mcm","clk":"5353963279","pt":1646220256255,"mc":[{"id":"1.195503857","rc":[{"atl":[[26,1.42]],"id":41120152},{"atl":[[26,1.42]],"id":38247349}],"con":true,"img":false}]}
{"op":"mcm","clk":"5353963490","pt":1646220258290,"mc":[{"id":"1.195503857","rc":[{"atl":[[25,1.42]],"id":41120152},{"atl":[[25,1.42]],"id":38247349}],"con":true,"img":false}]}
{"op":"mcm","clk":"5353963624","pt":1646220259701,"mc":[{"id":"1.195503857","rc":[{"atl":[[24,1.42]],"id":41120152},{"atl":[[24,1.42]],"id":38247349}],"con":true,"img":false}]}
{"op":"mcm","clk":"5353963748","pt":1646220260731,"mc":[{"id":"1.195503857","rc":[{"atl":[[2.02,0],[2.04,2]],"id":41120152}],"con":true,"img":false}]}
{"op":"mcm","clk":"5353963783","pt":1646220261208,"mc":[{"id":"1.195503857","rc":[{"atl":[[23,1.42]],"id":41120152},{"atl":[[22,1.42]],"id":38247349}],"con":true,"img":false}]}
{"op":"mcm","clk":"5353963966","pt":1646220263082,"mc":[{"id":"1.195503857","rc":[{"atl":[[22,1.42]],"id":41120152},{"atl":[[23,1.42]],"id":38247349}],"con":true,"img":false}]}
{"op":"mcm","clk":"5353964122","pt":1646220264699,"mc":[{"id":"1.195503857","rc":[{"atl":[[21,1.42]],"id":41120152},{"atl":[[21,1.42]],"id":38247349}],"con":true,"img":false}]}
{"op":"mcm","clk":"5353964151","pt":1646220264968,"mc":[{"id":"1.195503857","rc":[{"atl":[[2.8,2],[2.78,0]],"id":38247349}],"con":true,"img":false}]}
{"op":"mcm","clk":"5353964274","pt":1646220266081,"mc":[{"id":"1.195503857","rc":[{"atl":[[19.5,1.42]],"id":41120152},{"atl":[[19.5,1.42]],"id":38247349}],"con":true,"img":false}]}
{"op":"mcm","clk":"5353964333","pt":1646220266708,"mc":[{"id":"1.195503857","rc":[{"atl":[[2.8,0],[2.82,2]],"id":38247349}],"con":true,"img":false}]}
{"op":"mcm","clk":"5353964402","pt":1646220267400,"mc":[{"id":"1.195503857","rc":[{"atl":[[19,1.42]],"id":41120152},{"atl":[[18.5,1.42]],"id":38247349}],"con":true,"img":false}]}
{"op":"mcm","clk":"5353964567","pt":1646220269119,"mc":[{"id":"1.195503857","rc":[{"atl":[[18,1.42]],"id":41120152},{"atl":[[18,1.42]],"id":38247349}],"con":true,"img":false}]}
{"op":"mcm","clk":"5353964645","pt":1646220269901,"mc":[{"id":"1.195503857","rc":[{"atl":[[2.04,0],[2.02,2]],"id":41120152}],"con":true,"img":false}]}
{"op":"mcm","clk":"5353964715","pt":1646220270680,"mc":[{"id":"1.195503857","rc":[{"atl":[[18,2.84]],"id":41120152},{"atl":[[18,2.84]],"id":38247349}],"con":true,"img":false}]}
{"op":"mcm","clk":"5353964873","pt":1646220272307,"mc":[{"id":"1.195503857","rc":[{"atl":[[2.86,2]],"id":38247349}],"con":true,"img":false}]}
{"op":"mcm","clk":"5353964881","pt":1646220272413,"mc":[{"id":"1.195503857","rc":[{"atl":[[2.82,0]],"id":38247349}],"con":true,"img":false}]}
{"op":"mcm","clk":"5353964894","pt":1646220272514,"mc":[{"id":"1.195503857","rc":[{"atl":[[18.5,1.42]],"id":41120152},{"atl":[[19,1.42]],"id":38247349}],"con":true,"img":false}]}
{"op":"mcm","clk":"5353965010","pt":1646220273922,"mc":[{"id":"1.195503857","rc":[{"atl":[[18.5,2.84]],"id":41120152},{"atl":[[19,2.84],[2.88,2],[2.86,0]],"id":38247349}],"con":true,"img":false}]}
{"op":"mcm","clk":"5353965071","pt":1646220274639,"mc":[{"id":"1.195503857","rc":[{"atb":[[2.02,2]],"id":38247349}],"con":true,"img":false}]}
{"op":"mcm","clk":"5353965079","pt":1646220274691,"mc":[{"id":"1.195503857","rc":[{"atb":[[2,0]],"id":38247349}],"con":true,"img":false}]}
{"op":"mcm","clk":"5353965248","pt":1646220276725,"mc":[{"id":"1.195503857","rc":[{"atl":[[20,1.42]],"id":41120152},{"atl":[[20,1.42]],"id":38247349}],"con":true,"img":false}]}
{"op":"mcm","clk":"5353965435","pt":1646220279136,"mc":[{"id":"1.195503857","rc":[{"atl":[[20,2.84]],"id":41120152},{"atl":[[20,2.84]],"id":38247349}],"con":true,"img":false}]}
{"op":"mcm","clk":"5353965610","pt":1646220280814,"mc":[{"id":"1.195503857","rc":[{"atl":[[18,0]],"id":38247349}],"con":true,"img":false}]}
{"op":"mcm","clk":"5353965618","pt":1646220280921,"mc":[{"id":"1.195503857","rc":[{"atl":[[2.04,2],[2.02,0]],"id":41120152},{"atb":[[2,2],[2.02,0]],"id":38247349}],"con":true,"img":false}]}
{"op":"mcm","clk":"5353965759","pt":1646220282434,"mc":[{"id":"1.195503857","rc":[{"atl":[[18,0]],"id":41120152}],"con":true,"img":false}]}
{"op":"mcm","clk":"5353965855","pt":1646220283335,"mc":[{"id":"1.195503857","rc":[{"atl":[[2.88,0],[2.9,2]],"id":38247349}],"con":true,"img":false}]}
{"op":"mcm","clk":"5353966114","pt":1646220286009,"mc":[{"id":"1.195503857","rc":[{"atl":[[1.98,2],[2.04,0]],"id":41120152},{"atb":[[2,0],[2.06,2]],"id":38247349}],"con":true,"img":false}]}
{"op":"mcm","clk":"5353966343","pt":1646220288452,"mc":[{"id":"1.195503857","rc":[{"atl":[[3,2],[2.9,0]],"id":38247349}],"con":true,"img":false}]}
{"op":"mcm","clk":"5353966571","pt":1646220291014,"mc":[{"id":"1.195503857","rc":[{"atl":[[18.5,0]],"id":38247349}],"con":true,"img":false}]}
{"op":"mcm","clk":"5353966718","pt":1646220292529,"mc":[{"id":"1.195503857","rc":[{"atl":[[18.5,0]],"id":41120152}],"con":true,"img":false}]}
{"op":"mcm","clk":"5353966756","pt":1646220292938,"mc":[{"id":"1.195503857","rc":[{"atl":[[1.98,0],[2.02,2]],"id":41120152},{"atb":[[2.02,2],[2.06,0]],"id":38247349}],"con":true,"img":false}]}
{"op":"mcm","clk":"5353966775","pt":1646220293145,"mc":[{"id":"1.195503857","rc":[{"atl":[[27,1.42]],"id":41120152}],"con":true,"img":false}]}
{"op":"mcm","clk":"5353966991","pt":1646220295128,"mc":[{"id":"1.195503857","rc":[{"atl":[[27,2.84]],"id":41120152}],"con":true,"img":false}]}
{"op":"mcm","clk":"5353967034","pt":1646220295648,"mc":[{"id":"1.195503857","rc":[{"atl":[[3,0],[3.05,2]],"id":38247349}],"con":true,"img":false}]}
{"op":"mcm","clk":"5353967278","pt":1646220298140,"mc":[{"id":"1.195503857","rc":[{"atl":[[1.98,2],[2.02,0]],"id":41120152},{"atb":[[2.02,0],[2.06,2]],"id":38247349}],"con":true,"img":false}]}
{"op":"mcm","clk":"5353967302","pt":1646220298453,"mc":[{"id":"1.195503857","rc":[{"atl":[[1.98,0],[1.99,2]],"id":41120152}],"con":true,"img":false}]}
{"op":"mcm","clk":"5353967356","pt":1646220298930,"mc":[{"id":"1.195503857","rc":[{"atb":[[2.06,0],[2.04,2]],"id":38247349}],"con":true,"img":false}]}
{"op":"mcm","clk":"5353967557","pt":1646220300756,"mc":[{"id":"1.195503857","rc":[{"atl":[[3.35,2],[3.05,0],[19,0]],"id":38247349}],"con":true,"img":false}]}
{"op":"mcm","clk":"5353967658","pt":1646220301534,"mc":[{"id":"1.195503857","rc":[{"atl":[[28,1.42]],"id":38247349}],"con":true,"img":false}]}
{"op":"mcm","clk":"5353967801","pt":1646220302794,"mc":[{"id":"1.195503857","rc":[{"atl":[[19,0]],"id":41120152}],"con":true,"img":false}]}
{"op":"mcm","clk":"5353968000","pt":1646220304349,"mc":[{"id":"1.195503857","rc":[{"atl":[[1.99,0],[2.02,2]],"id":41120152},{"atb":[[2.02,2],[2.04,0]],"id":38247349}],"con":true,"img":false}]}
{"op":"mcm","clk":"5353968366","pt":1646220307880,"mc":[{"id":"1.195503857","rc":[{"atl":[[3.35,0],[3.3,2]],"id":38247349}],"con":true,"img":false}]}
{"op":"mcm","clk":"5353968546","pt":1646220309451,"mc":[{"id":"1.195503857","rc":[{"atl":[[1.98,2]],"id":41120152}],"con":true,"img":false}]}
{"op":"mcm","clk":"5353968555","pt":1646220309557,"mc":[{"id":"1.195503857","rc":[{"atl":[[2.02,0]],"id":41120152},{"atb":[[2.02,0],[2.06,2]],"id":38247349}],"con":true,"img":false}]}
{"op":"mcm","clk":"5353968592","pt":1646220309867,"mc":[{"id":"1.195503857","rc":[{"atl":[[1.98,0],[1.97,2]],"id":41120152}],"con":true,"img":false}]}
{"op":"mcm","clk":"5353968677","pt":1646220310650,"mc":[{"id":"1.195503857","rc":[{"atl":[[19,1.42]],"id":41120152},{"atl":[[19,1.42]],"id":38247349}],"con":true,"img":false}]}
{"op":"mcm","clk":"5353968851","pt":1646220312378,"mc":[{"id":"1.195503857","rc":[{"atl":[[19,2.84]],"id":41120152},{"atl":[[19,2.84]],"id":38247349}],"con":true,"img":false}]}
{"op":"mcm","clk":"5353968911","pt":1646220313007,"mc":[{"id":"1.195503857","rc":[{"atl":[[3.6,2]],"id":38247349}],"con":true,"img":false}]}
{"op":"mcm","clk":"5353968922","pt":1646220313061,"mc":[{"id":"1.195503857","rc":[{"atl":[[3.3,0]],"id":38247349}],"con":true,"img":false}]}
{"op":"mcm","clk":"5353968947","pt":1646220313271,"mc":[{"id":"1.195503857","rc":[{"atl":[[19,1.42]],"id":38247349}],"con":true,"img":false}]}
{"op":"mcm","clk":"5353969095","pt":1646220314691,"mc":[{"id":"1.195503857","rc":[{"atb":[[2.06,0],[2.1,2]],"id":38247349}],"con":true,"img":false}]}
{"op":"mcm","clk":"5353969104","pt":1646220314794,"mc":[{"id":"1.195503857","rc":[{"atl":[[19,0]],"id":41120152},{"atl":[[19,0]],"id":38247349}],"con":true,"img":false}]}
{"op":"mcm","clk":"5353969258","pt":1646220316203,"mc":[{"id":"1.195503857","rc":[{"atl":[[1.98,2],[1.97,0]],"id":41120152}],"con":true,"img":false}]}
{"op":"mcm","clk":"5353969279","pt":1646220316360,"mc":[{"id":"1.195503857","rc":[{"atl":[[1.98,0],[1.97,2]],"id":41120152}],"con":true,"img":false}]}
{"op":"mcm","clk":"5353969307","pt":1646220316676,"mc":[{"id":"1.195503857","rc":[{"atl":[[19.5,0]],"id":38247349}],"con":true,"img":false}]}
{"op":"mcm","clk":"5353969348","pt":1646220317099,"mc":[{"id":"1.195503857","rc":[{"atl":[[1.99,2],[1.97,0]],"id":41120152}],"con":true,"img":false}]}
{"op":"mcm","clk":"5353969464","pt":1646220318197,"mc":[{"id":"1.195503857","rc":[{"atl":[[3.6,0],[3.7,2]],"id":38247349}],"con":true,"img":false}]}
{"op":"mcm","clk":"5353969512","pt":1646220318562,"mc":[{"id":"1.195503857","rc":[{"atl":[[19.5,0]],"id":41120152}],"con":true,"img":false}]}
{"op":"mcm","clk":"5353969568","pt":1646220319182,"mc":[{"id":"1.195503857","rc":[{"atl":[[29,1.42]],"id":41120152}],"con":true,"img":false}]}
{"op":"mcm","clk":"5353969628","pt":1646220319762,"mc":[{"id":"1.195503857","rc":[{"atb":[[2,2],[2.1,0]],"id":38247349}],"con":true,"img":false}]}
{"op":"mcm","clk":"5353969696","pt":1646220320484,"mc":[{"id":"1.195503857","rc":[{"atl":[[20,0]],"id":41120152},{"atl":[[20,0]],"id":38247349}],"con":true,"img":false}]}
{"op":"mcm","clk":"5353969806","pt":1646220321480,"mc":[{"id":"1.195503857","rc":[{"atb":[[1.46,0],[1.26,0],[1.66,0]],"id":41120152},{"atb":[[1.89,0],[1.49,0],[1.69,0]],"id":38247349}],"con":true,"img":false}]}
{"op":"mcm","clk":"5353969816","pt":1646220321584,"mc":[{"id":"1.195503857","rc":[{"atb":[[1.58,2]],"id":41120152}],"con":true,"img":false}]}
{"op":"mcm","clk":"5353969826","pt":1646220321694,"mc":[{"id":"1.195503857","rc":[{"atb":[[1.6,0]],"id":41120152}],"con":true,"img":false}]}
{"op":"mcm","clk":"5353969924","pt":1646220322578,"mc":[{"id":"1.195503857","rc":[{"atl":[[1.98,2],[1.99,0]],"id":41120152}],"con":true,"img":false}]}
{"op":"mcm","clk":"5353969980","pt":1646220323259,"mc":[{"id":"1.195503857","rc":[{"atl":[[3.7,0],[3.65,2]],"id":38247349}],"con":true,"img":false}]}
{"op":"mcm","clk":"5353970123","pt":1646220324985,"mc":[{"id":"1.195503857","rc":[{"atb":[[2,0],[2.02,2]],"id":38247349}],"con":true,"img":false}]}
{"op":"mcm","clk":"5353970299","pt":1646220326869,"mc":[{"id":"1.195503857","rc":[{"atl":[[20,1.42]],"id":41120152},{"atl":[[19.5,1.42]],"id":38247349}],"con":true,"img":false}]}
{"op":"mcm","clk":"5353970326","pt":1646220327289,"mc":[{"id":"1.195503857","rc":[{"atb":[[1.58,0],[1.57,2]],"id":41120152}],"con":true,"img":false}]}
{"op":"mcm","clk":"5353970371","pt":1646220327706,"mc":[{"id":"1.195503857","rc":[{"atl":[[1.98,0],[1.99,2]],"id":41120152}],"con":true,"img":false}]}
{"op":"mcm","clk":"5353970419","pt":1646220328074,"mc":[{"id":"1.195503857","rc":[{"atl":[[19,1.42]],"id":41120152},{"atl":[[19,1.42]],"id":38247349}],"con":true,"img":false}]}
{"op":"mcm","clk":"5353970456","pt":1646220328390,"mc":[{"id":"1.195503857","rc":[{"atl":[[3.7,2],[3.65,0]],"id":38247349}],"con":true,"img":false}]}
{"op":"mcm","clk":"5353970521","pt":1646220329072,"mc":[{"id":"1.195503857","rc":[{"atb":[[1.15,35.97],[1.55,9.81],[1.35,15.41]],"id":41120152},{"atb":[[1.97,5.56],[1.57,9.46],[1.77,7]],"id":38247349}],"con":true,"img":false}]}
{"op":"mcm","clk":"5353970570","pt":1646220329492,"mc":[{"id":"1.195503857","rc":[{"atl":[[18.5,1.42]],"id":41120152},{"atl":[[18.5,1.42]],"id":38247349}],"con":true,"img":false}]}
{"op":"mcm","clk":"5353970629","pt":1646220330074,"mc":[{"id":"1.195503857","rc":[{"atb":[[2.02,0],[2.08,2]],"id":38247349}],"con":true,"img":false}]}
{"op":"mcm","clk":"5353970745","pt":1646220331015,"mc":[{"id":"1.195503857","rc":[{"atl":[[18,1.42]],"id":41120152},{"atl":[[17,1.42]],"id":38247349}],"con":true,"img":false}]}
{"op":"mcm","clk":"5353970926","pt":1646220332510,"mc":[{"id":"1.195503857","rc":[{"atb":[[1.56,2],[1.57,0]],"id":41120152},{"atl":[[17,1.42]],"id":41120152},{"atl":[[17,2.84]],"id":38247349}],"con":true,"img":false}]}
{"op":"mcm","clk":"5353970952","pt":1646220332819,"mc":[{"id":"1.195503857","rc":[{"atl":[[1.95,2],[1.99,0]],"id":41120152}],"con":true,"img":false}]}
{"op":"mcm","clk":"5353971036","pt":1646220333604,"mc":[{"id":"1.195503857","rc":[{"atl":[[3.7,0],[3.65,2]],"id":38247349}],"con":true,"img":false}]}
{"op":"mcm","clk":"5353971152","pt":1646220334809,"mc":[{"id":"1.195503857","rc":[{"atl":[[16.5,1.42]],"id":41120152},{"atl":[[16.5,1.42]],"id":38247349}],"con":true,"img":false}]}
{"op":"mcm","clk":"5353971191","pt":1646220335224,"mc":[{"id":"1.195503857","rc":[{"atb":[[2.1,2]],"id":38247349}],"con":true,"img":false}]}
{"op":"mcm","clk":"5353971201","pt":1646220335282,"mc":[{"id":"1.195503857","rc":[{"atl":[[1.94,2],[1.95,0]],"id":41120152},{"atb":[[2.12,2],[2.08,0]],"id":38247349}],"con":true,"img":false}]}
{"op":"mcm","clk":"5353971209","pt":1646220335384,"mc":[{"id":"1.195503857","rc":[{"atb":[[2.1,0]],"id":38247349}],"con":true,"img":false}]}
{"op":"mcm","clk":"5353971342","pt":1646220336230,"mc":[{"id":"1.195503857","rc":[{"atl":[[15.5,1.42]],"id":41120152},{"atl":[[15,1.42]],"id":38247349}],"con":true,"img":false}]}
{"op":"mcm","clk":"5353971500","pt":1646220337525,"mc":[{"id":"1.195503857","rc":[{"atl":[[15.5,2.84]],"id":41120152},{"atl":[[15,2.84]],"id":38247349}],"con":true,"img":false}]}
{"op":"mcm","clk":"5353971698","pt":1646220339408,"mc":[{"id":"1.195503857","rc":[{"atl":[[15,1.42]],"id":41120152},{"atl":[[14,1.42]],"id":38247349}],"con":true,"img":false}]}
{"op":"mcm","clk":"5353971808","pt":1646220340405,"mc":[{"id":"1.195503857","rc":[{"atl":[[1.93,2]],"id":41120152},{"atb":[[2.14,2]],"id":38247349}],"con":true,"img":false}]}
{"op":"mcm","clk":"5353971817","pt":1646220340512,"mc":[{"id":"1.195503857","rc":[{"atl":[[1.94,0]],"id":41120152},{"atb":[[2.12,0]],"id":38247349}],"con":true,"img":false}]}
{"op":"mcm","clk":"5353972005","pt":1646220342013,"mc":[{"id":"1.195503857","rc":[{"atl":[[16,1.42]],"id":41120152},{"atl":[[14.5,1.42]],"id":38247349}],"con":true,"img":false}]}
{"op":"mcm","clk":"5353972032","pt":1646220342321,"mc":[{"id":"1.195503857","rc":[{"atl":[[15,0]],"id":41120152},{"atl":[[14,0]],"id":38247349}],"con":true,"img":false}]}
{"op":"mcm","clk":"5353972162","pt":1646220343425,"mc":[{"id":"1.195503857","rc":[{"atl":[[16,2.84]],"id":41120152},{"atl":[[14.5,2.84]],"id":38247349}],"con":true,"img":false}]}
{"op":"mcm","clk":"5353972173","pt":1646220343530,"mc":[{"id":"1.195503857","rc":[{"atl":[[3.85,2],[3.65,0]],"id":38247349}],"con":true,"img":false}]}
{"op":"mcm","clk":"5353972207","pt":1646220343799,"mc":[{"id":"1.195503857","rc":[{"atl":[[3.85,0],[4,2]],"id":38247349}],"con":true,"img":false}]}
{"op":"mcm","clk":"5353972337","pt":1646220345210,"mc":[{"id":"1.195503857","rc":[{"atl":[[17.5,1.42]],"id":41120152},{"atl":[[15.5,1.42],[4,0],[4.1,2]],"id":38247349}],"con":true,"img":false}]}
{"op":"mcm","clk":"5353972368","pt":1646220345519,"mc":[{"id":"1.195503857","rc":[{"atl":[[1.93,0],[1.87,2]],"id":41120152},{"atb":[[2.24,2]],"id":38247349}],"con":true,"img":false}]}
{"op":"mcm","clk":"5353972380","pt":1646220345622,"mc":[{"id":"1.195503857","rc":[{"atb":[[2.14,0]],"id":38247349}],"con":true,"img":false}]}
{"op":"mcm","clk":"5353972420","pt":1646220346039,"mc":[{"id":"1.195503857","rc":[{"atl":[[15.5,0]],"id":41120152},{"atl":[[14.5,0]],"id":38247349}],"con":true,"img":false}]}
{"op":"mcm","clk":"5353972462","pt":1646220346401,"mc":[{"id":"1.195503857","rc":[{"atb":[[2.24,0],[2.26,2]],"id":38247349}],"con":true,"img":false}]}
{"op":"mcm","clk":"5353972620","pt":1646220347922,"mc":[{"id":"1.195503857","rc":[{"atl":[[19.5,1.42]],"id":41120152},{"atl":[[16,1.42]],"id":38247349}],"con":true,"img":false}]}
{"op":"mcm","clk":"5353972630","pt":1646220348029,"mc":[{"id":"1.195503857","rc":[{"atl":[[16,0]],"id":41120152},{"atl":[[15,0]],"id":38247349}],"con":true,"img":false}]}
{"op":"mcm","clk":"5353972738","pt":1646220349232,"mc":[{"id":"1.195503857","rc":[{"atl":[[19.5,2.84]],"id":41120152},{"atl":[[16,2.84]],"id":38247349}],"con":true,"img":false}]}
{"op":"mcm","clk":"5353972857","pt":1646220350339,"mc":[{"id":"1.195503857","rc":[{"atl":[[4.3,2],[4.1,0]],"id":38247349}],"con":true,"img":false}]}
{"op":"mcm","clk":"5353972896","pt":1646220350700,"mc":[{"id":"1.195503857","rc":[{"atl":[[1.87,0],[1.88,2]],"id":41120152}],"con":true,"img":false}]}
{"op":"mcm","clk":"5353972905","pt":1646220350818,"mc":[{"id":"1.195503857","rc":[{"atl":[[16.5,0]],"id":41120152},{"atl":[[15.5,0]],"id":38247349}],"con":true,"img":false}]}
{"op":"mcm","clk":"5353972943","pt":1646220351220,"mc":[{"id":"1.195503857","rc":[{"atl":[[1.88,0],[1.86,2]],"id":41120152}],"con":true,"img":false}]}
{"op":"mcm","clk":"5353973028","pt":1646220351982,"mc":[{"id":"1.195503857","rc":[{"atl":[[17.5,1.42]],"id":38247349}],"con":true,"img":false}]}
{"op":"mcm","clk":"5353973078","pt":1646220352359,"mc":[{"id":"1.195503857","rc":[{"atb":[[1.15,0],[1.55,0],[1.35,0]],"id":41120152},{"atb":[[1.97,0],[1.57,0],[1.77,0]],"id":38247349}],"con":true,"img":false}]}
{"op":"mcm","clk":"5353973134","pt":1646220352931,"mc":[{"id":"1.195503857","rc":[{"atl":[[17,0]],"id":41120152},{"atl":[[16,0]],"id":38247349}],"con":true,"img":false}]}
{"op":"mcm","clk":"5353973304","pt":1646220354541,"mc":[{"id":"1.195503857","rc":[{"atl":[[18,1.42]],"id":38247349}],"con":true,"img":false}]}
{"op":"mcm","clk":"5353973362","pt":1646220355017,"mc":[{"id":"1.195503857","rc":[{"atl":[[1.87,2],[1.86,0]],"id":41120152}],"con":true,"img":false}]}
{"op":"mcm","clk":"5353973378","pt":1646220355232,"mc":[{"id":"1.195503857","rc":[{"atl":[[17.5,0]],"id":41120152},{"atl":[[16.5,0],[17,0],[17.5,0]],"id":38247349}],"con":true,"img":false}]}
{"op":"mcm","clk":"5353973387","pt":1646220355335,"mc":[{"id":"1.195503857","rc":[{"atb":[[1.56,0],[1.53,2]],"id":41120152}],"con":true,"img":false}]}
{"op":"mcm","clk":"5353973441","pt":1646220355848,"mc":[{"id":"1.195503857","rc":[{"atl":[[4.3,0],[4.5,2]],"id":38247349}],"con":true,"img":false}]}
{"op":"mcm","clk":"5353973553","pt":1646220357036,"mc":[{"id":"1.195503857","rc":[{"atl":[[17,1.42]],"id":38247349}],"con":true,"img":false}]}
{"op":"mcm","clk":"5353973625","pt":1646220357814,"mc":[{"id":"1.195503857","rc":[{"atl":[[18,0],[18.5,0]],"id":41120152}],"con":true,"img":false}]}
{"op":"mcm","clk":"5353973642","pt":1646220358021,"mc":[{"id":"1.195503857","rc":[{"atl":[[4.4,2],[4.5,0]],"id":38247349}],"con":true,"img":false}]}
{"op":"mcm","clk":"5353973751","pt":1646220359053,"mc":[{"id":"1.195503857","rc":[{"atb":[[1.09,59.95],[1.49,11],[1.29,18.6]],"id":41120152},{"atb":[[1.83,6.5],[1.63,8.56],[2.06,5.09]],"id":38247349}],"con":true,"img":false}]}
{"op":"mcm","clk":"5353973769","pt":1646220359217,"mc":[{"id":"1.195503857","rc":[{"atb":[[2.24,2],[2.26,0]],"id":38247349}],"con":true,"img":false}]}
{"op":"mcm","clk":"5353973778","pt":1646220359319,"mc":[{"id":"1.195503857","rc":[{"atl":[[17.5,1.42]],"id":38247349}],"con":true,"img":false}]}
{"op":"mcm","clk":"5353973801","pt":1646220359526,"mc":[{"id":"1.195503857","rc":[{"atl":[[19,0]],"id":41120152}],"con":true,"img":false}]}
{"op":"mcm","clk":"5353973909","pt":1646220360578,"mc":[{"id":"1.195503857","rc":[{"atb":[[1.5,2],[1.53,0]],"id":41120152}],"con":true,"img":false}]}
{"op":"mcm","clk":"5353974284","pt":1646220363038,"mc":[{"id":"1.195503857","rc":[{"atl":[[19,1.42]],"id":41120152},{"atl":[[14.5,1.42]],"id":38247349}],"con":true,"img":false}]}
{"op":"mcm","clk":"5353974301","pt":1646220363189,"mc":[{"id":"1.195503857","rc":[{"atl":[[4.4,0],[4.5,2]],"id":38247349}],"con":true,"img":false}]}
{"op":"mcm","clk":"5353974527","pt":1646220364979,"mc":[{"id":"1.195503857","rc":[{"atl":[[19,2.84]],"id":41120152},{"atl":[[14.5,2.84]],"id":38247349}],"con":true,"img":false}]}
{"op":"mcm","clk":"5353974784","pt":1646220366831,"mc":[{"id":"1.195503857","rc":[{"atl":[[15,1.42]],"id":38247349}],"con":true,"img":false}]}
{"op":"mcm","clk":"5353975032","pt":1646220368668,"mc":[{"id":"1.195503857","rc":[{"atl":[[15,2.84]],"id":38247349}],"con":true,"img":false}]}
{"op":"mcm","clk":"5353975322","pt":1646220370841,"mc":[{"id":"1.195503857","rc":[{"atl":[[18.5,1.42]],"id":41120152},{"atl":[[14,1.42]],"id":38247349}],"con":true,"img":false}]}
{"op":"mcm","clk":"5353975542","pt":1646220372681,"mc":[{"id":"1.195503857","rc":[{"atl":[[18,1.42]],"id":41120152},{"atl":[[13.5,1.42]],"id":38247349}],"con":true,"img":false}]}
{"op":"mcm","clk":"5353975929","pt":1646220375977,"mc":[{"id":"1.195503857","rc":[{"atb":[[2.3,2]],"id":38247349},{"atl":[[4.9,2],[4.5,0]],"id":38247349}],"con":true,"img":false}]}
{"op":"mcm","clk":"5353975941","pt":1646220376078,"mc":[{"id":"1.195503857","rc":[{"atl":[[1.87,0],[1.82,2],[17.5,1.42]],"id":41120152},{"atb":[[2.24,0]],"id":38247349},{"atl":[[13.5,2.84]],"id":38247349}],"con":true,"img":false}]}
{"op":"mcm","clk":"5353975953","pt":1646220376183,"mc":[{"id":"1.195503857","rc":[{"atb":[[2.3,0],[2.32,2]],"id":38247349}],"con":true,"img":false}]}
{"op":"mcm","clk":"5353976007","pt":1646220376550,"mc":[{"id":"1.195503857","rc":[{"atb":[[2.32,0],[2.3,2]],"id":38247349}],"con":true,"img":false}]}
{"op":"mcm","clk":"5353976325","pt":1646220379191,"mc":[{"id":"1.195503857","rc":[{"atl":[[17,1.42]],"id":41120152},{"atl":[[13,1.42]],"id":38247349}],"con":true,"img":false}]}
{"op":"mcm","clk":"5353976450","pt":1646220380288,"mc":[{"id":"1.195503857","rc":[{"atl":[[13.5,0]],"id":38247349}],"con":true,"img":false}]}
{"op":"mcm","clk":"5353976491","pt":1646220380665,"mc":[{"id":"1.195503857","rc":[{"atb":[[2.3,0],[2.32,2]],"id":38247349}],"con":true,"img":false}]}
{"op":"mcm","clk":"5353976554","pt":1646220381284,"mc":[{"id":"1.195503857","rc":[{"atl":[[1.82,0],[1.81,2]],"id":41120152},{"atb":[[2.32,0],[2.34,2]],"id":38247349}],"con":true,"img":false}]}
{"op":"mcm","clk":"5353976563","pt":1646220381384,"mc":[{"id":"1.195503857","rc":[{"atl":[[4.9,0],[5,2]],"id":38247349}],"con":true,"img":false}]}
{"op":"mcm","clk":"5353976673","pt":1646220382376,"mc":[{"id":"1.195503857","rc":[{"atl":[[5.1,2]],"id":38247349}],"con":true,"img":false}]}
{"op":"mcm","clk":"5353976682","pt":1646220382483,"mc":[{"id":"1.195503857","rc":[{"atl":[[5,0]],"id":38247349}],"con":true,"img":false}]}
{"op":"mcm","clk":"5353976727","pt":1646220382859,"mc":[{"id":"1.195503857","rc":[{"atb":[[1.09,0],[1.49,0],[1.29,0]],"id":41120152},{"atb":[[1.83,0],[1.63,0],[2.06,0]],"id":38247349}],"con":true,"img":false}]}
{"op":"mcm","clk":"5353976771","pt":1646220383279,"mc":[{"id":"1.195503857","rc":[{"atl":[[13,0],[14,0],[14.5,0]],"id":38247349}],"con":true,"img":false}]}
{"op":"mcm","clk":"5353976973","pt":1646220385056,"mc":[{"id":"1.195503857","rc":[{"atb":[[1.5,6]],"id":41120152},{"atl":[[1.81,6]],"id":41120152},{"atb":[[2.34,6]],"id":38247349},{"atl":[[5.1,6]],"id":38247349}],"con":true,"img":false}]}
{"op":"mcm","clk":"5353977139","pt":1646220386363,"mc":[{"id":"1.195503857","rc":[{"atl":[[1.8,2],[1.81,4]],"id":41120152}],"con":true,"img":false}]}
{"op":"mcm","clk":"5353977179","pt":1646220386705,"mc":[{"id":"1.195503857","rc":[{"atl":[[1.81,0]],"id":41120152}],"con":true,"img":false}]}
{"op":"mcm","clk":"5353977191","pt":1646220386762,"mc":[{"id":"1.195503857","rc":[{"atl":[[1.8,6]],"id":41120152}],"con":true,"img":false}]}
{"op":"mcm","clk":"5353977326","pt":1646220387972,"mc":[{"id":"1.195503857","rc":[{"atl":[[15.5,1.42]],"id":38247349}],"con":true,"img":false}]}
{"op":"mcm","clk":"5353977442","pt":1646220389070,"mc":[{"id":"1.195503857","rc":[{"atl":[[4.9,2],[5.1,4]],"id":38247349}],"con":true,"img":false}]}
{"op":"mcm","clk":"5353977450","pt":1646220389178,"mc":[{"id":"1.195503857","rc":[{"atl":[[17,0]],"id":41120152}],"con":true,"img":false}]}
{"op":"mcm","clk":"5353977491","pt":1646220389595,"mc":[{"id":"1.195503857","rc":[{"atl":[[4.9,0],[4.7,2]],"id":38247349}],"con":true,"img":false}]}
{"op":"mcm","clk":"5353977692","pt":1646220391268,"mc":[{"id":"1.195503857","rc":[{"atl":[[16,1.42]],"id":38247349}],"con":true,"img":false}]}
{"op":"mcm","clk":"5353977739","pt":1646220391689,"mc":[{"id":"1.195503857","rc":[{"atl":[[15,0]],"id":38247349}],"con":true,"img":false}]}
{"op":"mcm","clk":"5353977983","pt":1646220394092,"mc":[{"id":"1.195503857","rc":[{"atl":[[1.73,22]],"id":41120152}],"con":true,"img":false}]}
{"op":"mcm","clk":"5353977994","pt":1646220394200,"mc":[{"id":"1.195503857","rc":[{"atl":[[1.8,4],[1.74,2]],"id":41120152}],"con":true,"img":false}]}
{"op":"mcm","clk":"5353978017","pt":1646220394407,"mc":[{"id":"1.195503857","rc":[{"atl":[[17.5,0]],"id":41120152}],"con":true,"img":false}]}
{"op":"mcm","clk":"5353978092","pt":1646220395095,"mc":[{"id":"1.195503857","rc":[{"atb":[[1.44,12.26],[1.24,22.48],[1.04,134.89]],"id":41120152},{"atb":[[1.89,6.06],[2.18,4.57],[1.69,7.82]],"id":38247349}],"con":true,"img":false}]}
{"op":"mcm","clk":"5353978232","pt":1646220396511,"mc":[{"id":"1.195503857","rc":[{"atl":[[4.9,2],[4.7,0]],"id":38247349}],"con":true,"img":false}]}
{"op":"mcm","clk":"5353978242","pt":1646220396621,"mc":[{"id":"1.195503857","rc":[{"atl":[[5.1,0]],"id":38247349}],"con":true,"img":false}]}
{"op":"mcm","clk":"5353978255","pt":1646220396739,"mc":[{"id":"1.195503857","rc":[{"atl":[[4.7,4]],"id":38247349}],"con":true,"img":false}]}
{"op":"mcm","clk":"5353978262","pt":1646220396843,"mc":[{"id":"1.195503857","rc":[{"atl":[[16.5,1.42]],"id":38247349}],"con":true,"img":false}]}
{"op":"mcm","clk":"5353978294","pt":1646220397098,"mc":[{"id":"1.195503857","rc":[{"atl":[[4.7,0]],"id":38247349}],"con":true,"img":false}]}
{"op":"mcm","clk":"5353978323","pt":1646220397425,"mc":[{"id":"1.195503857","rc":[{"atl":[[4.9,6]],"id":38247349}],"con":true,"img":false}]}
{"op":"mcm","clk":"5353978411","pt":1646220398195,"mc":[{"id":"1.195503857","rc":[{"atl":[[17,1.42]],"id":41120152},{"atl":[[15,1.42]],"id":38247349}],"con":true,"img":false}]}
{"op":"mcm","clk":"5353978670","pt":1646220400508,"mc":[{"id":"1.195503857","rc":[{"atl":[[17,2.84]],"id":41120152},{"atl":[[20,1.42]],"id":38247349}],"con":true,"img":false}]}
{"op":"mcm","clk":"5353978685","pt":1646220400609,"mc":[{"id":"1.195503857","rc":[{"atb":[[1.5,2]],"id":41120152},{"atl":[[1.8,0]],"id":41120152},{"atb":[[2.34,2]],"id":38247349},{"atl":[[4.9,2]],"id":38247349}],"con":true,"img":false}]}
{"op":"mcm","clk":"5353978698","pt":1646220400718,"mc":[{"id":"1.195503857","rc":[{"atb":[[2.34,0]],"id":38247349}],"con":true,"img":false}]}
{"op":"mcm","clk":"5353978712","pt":1646220400820,"mc":[{"id":"1.195503857","rc":[{"atb":[[1.45,2],[1.5,0]],"id":41120152},{"atb":[[2.28,2]],"id":38247349}],"con":true,"img":false}]}
{"op":"mcm","clk":"5353978773","pt":1646220401394,"mc":[{"id":"1.195503857","rc":[{"atb":[[1.45,6]],"id":41120152},{"atl":[[1.73,30.56]],"id":41120152},{"atb":[[2.28,6]],"id":38247349},{"atl":[[4.9,6]],"id":38247349}],"con":true,"img":false}]}
{"op":"mcm","clk":"5353978787","pt":1646220401606,"mc":[{"id":"1.195503857","rc":[{"atl":[[4.9,4],[4.7,2]],"id":38247349}],"con":true,"img":false}]}
{"op":"mcm","clk":"5353978816","pt":1646220401917,"mc":[{"id":"1.195503857","rc":[{"atl":[[17,1.42]],"id":41120152},{"atl":[[15,0]],"id":38247349}],"con":true,"img":false}]}
{"op":"mcm","clk":"5353978920","pt":1646220402697,"mc":[{"id":"1.195503857","rc":[{"atl":[[1.73,22]],"id":41120152}],"con":true,"img":false}]}
{"op":"mcm","clk":"5353979155","pt":1646220404422,"mc":[{"id":"1.195503857","rc":[{"atl":[[1.73,30.16],[17.5,1.42]],"id":41120152}],"con":true,"img":false}]}
{"op":"mcm","clk":"5353979176","pt":1646220404637,"mc":[{"id":"1.195503857","rc":[{"atl":[[17,0]],"id":41120152}],"con":true,"img":false}]}
{"op":"mcm","clk":"5353979347","pt":1646220406006,"mc":[{"id":"1.195503857","rc":[{"atb":[[2.3,2],[2.28,4]],"id":38247349}],"con":true,"img":false}]}
{"op":"mcm","clk":"5353979375","pt":1646220406317,"mc":[{"id":"1.195503857","rc":[{"atl":[[17.5,2.84]],"id":41120152},{"atb":[[2.28,0]],"id":38247349}],"con":true,"img":false}]}
{"op":"mcm","clk":"5353979389","pt":1646220406421,"mc":[{"id":"1.195503857","rc":[{"atb":[[2.3,6]],"id":38247349}],"con":true,"img":false}]}
{"op":"mcm","clk":"5353979420","pt":1646220406688,"mc":[{"id":"1.195503857","rc":[{"atb":[[2.3,2]],"id":38247349}],"con":true,"img":false}]}
{"op":"mcm","clk":"5353979449","pt":1646220406997,"mc":[{"id":"1.195503857","rc":[{"atb":[[2.3,6]],"id":38247349}],"con":true,"img":false}]}
{"op":"mcm","clk":"5353979715","pt":1646220409306,"mc":[{"id":"1.195503857","rc":[{"atl":[[4.9,0]],"id":38247349}],"con":true,"img":false}]}
{"op":"mcm","clk":"5353979728","pt":1646220409415,"mc":[{"id":"1.195503857","rc":[{"atl":[[4.7,6]],"id":38247349}],"con":true,"img":false}]}
{"op":"mcm","clk":"5353980083","pt":1646220412402,"mc":[{"id":"1.195503857","rc":[{"atl":[[15.5,0],[16,0],[16.5,0]],"id":38247349}],"con":true,"img":false}]}
{"op":"mcm","clk":"5353980136","pt":1646220412829,"mc":[{"id":"1.195503857","rc":[{"atb":[[1.44,0],[1.24,0],[1.04,0]],"id":41120152},{"atb":[[1.89,0],[2.18,0],[1.69,0]],"id":38247349}],"con":true,"img":false}]}
{"op":"mcm","clk":"5353980443","pt":1646220415501,"mc":[{"id":"1.195503857","rc":[{"atl":[[17,0],[17.5,0]],"id":38247349}],"con":true,"img":false}]}
{"op":"mcm","clk":"5353980719","pt":1646220416731,"mc":[{"id":"1.195503857","rc":[{"atl":[[1.73,22]],"id":41120152}],"con":true,"img":false}]}
{"op":"mcm","clk":"5353980739","pt":1646220416840,"mc":[{"id":"1.195503857","rc":[{"atb":[[1.45,2]],"id":41120152},{"atb":[[2.3,2]],"id":38247349},{"atl":[[4.7,2]],"id":38247349}],"con":true,"img":false}]}
{"op":"mcm","clk":"5353980814","pt":1646220417234,"mc":[{"id":"1.195503857","rc":[{"atl":[[17,1.42]],"id":41120152}],"con":true,"img":false}]}
{"op":"mcm","clk":"5353980858","pt":1646220417463,"mc":[{"id":"1.195503857","rc":[{"atb":[[1.45,6]],"id":41120152},{"atb":[[2.3,6]],"id":38247349},{"atl":[[4.7,6]],"id":38247349}],"con":true,"img":false}]}
{"op":"mcm","clk":"5353981040","pt":1646220418461,"mc":[{"id":"1.195503857","rc":[{"atl":[[1.73,32.88]],"id":41120152}],"con":true,"img":false}]}
{"op":"mcm","clk":"5353981339","pt":1646220419930,"mc":[{"id":"1.195503857","rc":[{"atl":[[16.5,1.42]],"id":41120152},{"atl":[[17.5,1.42]],"id":38247349}],"con":true,"img":false}]}
{"op":"mcm","clk":"5353981550","pt":1646220420945,"mc":[{"id":"1.195503857","rc":[{"atb":[[1.01,539.56],[1.15,35.97],[1.35,15.41]],"id":41120152},{"atb":[[2.02,5.29],[1.81,6.66],[2.42,3.79]],"id":38247349}],"con":true,"img":false}]}
{"op":"mcm","clk":"5353981598","pt":1646220421125,"mc":[{"id":"1.195503857","rc":[{"atb":[[2.3,4],[2.38,2]],"id":38247349}],"con":true,"img":false}]}
{"op":"mcm","clk":"5353981663","pt":1646220421543,"mc":[{"id":"1.195503857","rc":[{"atl":[[4.5,2],[4.7,4]],"id":38247349}],"con":true,"img":false}]}
{"op":"mcm","clk":"5353981762","pt":1646220422043,"mc":[{"id":"1.195503857","rc":[{"atl":[[1.73,22]],"id":41120152}],"con":true,"img":false}]}
{"op":"mcm","clk":"5353981889","pt":1646220422761,"mc":[{"id":"1.195503857","rc":[{"atb":[[1.45,2]],"id":41120152},{"atb":[[2.3,0]],"id":38247349},{"atl":[[4.7,0]],"id":38247349}],"con":true,"img":false}]}
{"op":"mcm","clk":"5353981924","pt":1646220422927,"mc":[{"id":"1.195503857","rc":[{"atb":[[1.36,2],[1.45,0]],"id":41120152}],"con":true,"img":false}]}
{"op":"mcm","clk":"5353982025","pt":1646220423539,"mc":[{"id":"1.195503857","rc":[{"atl":[[16.5,2.84]],"id":41120152},{"atl":[[17,1.42]],"id":38247349}],"con":true,"img":false}]}
{"op":"mcm","clk":"5353982374","pt":1646220425230,"mc":[{"id":"1.195503857","rc":[{"atl":[[16,1.42]],"id":41120152},{"atl":[[16,1.42]],"id":38247349}],"con":true,"img":false}]}
{"op":"mcm","clk":"5353982671","pt":1646220426728,"mc":[{"id":"1.195503857","rc":[{"atl":[[4.5,0],[4.6,2]],"id":38247349}],"con":true,"img":false}]}
{"op":"mcm","clk":"5353982862","pt":1646220427740,"mc":[{"id":"1.195503857","rc":[{"atl":[[15.5,1.42]],"id":41120152},{"atl":[[15,1.42]],"id":38247349}],"con":true,"img":false}]}
{"op":"mcm","clk":"5353983249","pt":1646220429593,"mc":[{"id":"1.195503857","rc":[{"atl":[[15,1.42]],"id":41120152},{"atl":[[14.5,1.42]],"id":38247349}],"con":true,"img":false}]}
{"op":"mcm","clk":"5353983924","pt":1646220431566,"mc":[{"id":"1.195503857","rc":[{"atb":[[1.36,6]],"id":41120152},{"atl":[[1.73,30.64]],"id":41120152},{"atl":[[4.6,6]],"id":38247349}],"con":true,"img":false}]}
{"op":"mcm","clk":"5353984183","pt":1646220432610,"mc":[{"id":"1.195503857","rc":[{"atl":[[14.5,1.42]],"id":41120152},{"atl":[[14,1.42]],"id":38247349}],"con":true,"img":false}]}
{"op":"mcm","clk":"5353984386","pt":1646220433344,"mc":[{"id":"1.195503857","rc":[{"atl":[[4.5,2]],"id":38247349}],"con":true,"img":false}]}
{"op":"mcm","clk":"5353984407","pt":1646220433450,"mc":[{"id":"1.195503857","rc":[{"atl":[[4.6,4]],"id":38247349}],"con":true,"img":false}]}
{"op":"mcm","clk":"5353984490","pt":1646220433781,"mc":[{"id":"1.195503857","rc":[{"atl":[[4.6,0]],"id":38247349}],"con":true,"img":false}]}
{"op":"mcm","clk":"5353984532","pt":1646220433845,"mc":[{"id":"1.195503857","rc":[{"atl":[[4.5,6]],"id":38247349}],"con":true,"img":false}]}
{"op":"mcm","clk":"5353984614","pt":1646220434167,"mc":[{"id":"1.195503857","rc":[{"atb":[[2.42,9.4]],"id":38247349}],"con":true,"img":false}]}
{"op":"mcm","clk":"5353984814","pt":1646220434894,"mc":[{"id":"1.195503857","rc":[{"atl":[[14,1.42]],"id":41120152},{"atl":[[13.5,1.42]],"id":38247349}],"con":true,"img":false}]}
{"op":"mcm","clk":"5353985453","pt":1646220437488,"mc":[{"id":"1.195503857","rc":[{"atl":[[4.4,2],[4.5,4]],"id":38247349}],"con":true,"img":false}]}
{"op":"mcm","clk":"5353985480","pt":1646220437552,"mc":[{"id":"1.195503857","rc":[{"atb":[[1.39,1.42]],"id":41120152},{"atl":[[13.5,1.42]],"id":41120152},{"atl":[[15.5,1.42]],"id":38247349}],"con":true,"img":false}]}
{"op":"mcm","clk":"5353985530","pt":1646220437762,"mc":[{"id":"1.195503857","rc":[{"atb":[[1.36,4],[1.39,3.42]],"id":41120152}],"con":true,"img":false}]}
{"op":"mcm","clk":"5353985548","pt":1646220437867,"mc":[{"id":"1.195503857","rc":[{"atb":[[1.37,2],[1.39,1.42]],"id":41120152},{"atl":[[4.5,0]],"id":38247349}],"con":true,"img":false}]}
{"op":"mcm","clk":"5353985568","pt":1646220437971,"mc":[{"id":"1.195503857","rc":[{"atb":[[1.37,0],[1.39,3.42]],"id":41120152},{"atl":[[4.4,6]],"id":38247349}],"con":true,"img":false}]}
{"op":"mcm","clk":"5353985582","pt":1646220438075,"mc":[{"id":"1.195503857","rc":[{"atb":[[1.37,2],[1.39,1.42]],"id":41120152}],"con":true,"img":false}]}
{"op":"mcm","clk":"5353985615","pt":1646220438240,"mc":[{"id":"1.195503857","rc":[{"atb":[[1.37,0],[1.39,3.42]],"id":41120152}],"con":true,"img":false}]}
{"op":"mcm","clk":"5353985739","pt":1646220439081,"mc":[{"id":"1.195503857","rc":[{"atb":[[1.4,1.42]],"id":41120152},{"atl":[[13.5,2.84]],"id":41120152},{"atl":[[13,1.42]],"id":38247349}],"con":true,"img":false}]}
{"op":"mcm","clk":"5353985996","pt":1646220440277,"mc":[{"id":"1.195503857","rc":[{"atb":[[1.36,0]],"id":41120152},{"atl":[[1.73,22]],"id":41120152},{"atb":[[2.42,3.79]],"id":38247349},{"atl":[[4.4,2]],"id":38247349}],"con":true,"img":false}]}
{"op":"mcm","clk":"5353986143","pt":1646220440882,"mc":[{"id":"1.195503857","rc":[{"atb":[[1.4,4.26],[1.41,1.42]],"id":41120152},{"atl":[[1.73,35.74],[13,1.42]],"id":41120152},{"atb":[[2.42,11.39],[2.46,1.42]],"id":38247349},{"atl":[[4.4,6],[12.5,1.42]],"id":38247349}],"con":true,"img":false}]}
{"op":"mcm","clk":"5353986220","pt":1646220441177,"mc":[{"id":"1.195503857","rc":[{"atb":[[1.4,1.42]],"id":41120152}],"con":true,"img":false}]}
{"op":"mcm","clk":"5353986240","pt":1646220441282,"mc":[{"id":"1.195503857","rc":[{"atb":[[1.41,4.26]],"id":41120152}],"con":true,"img":false}]}
{"op":"mcm","clk":"5353986509","pt":1646220442376,"mc":[{"id":"1.195503857","rc":[{"atb":[[1.4,0]],"id":41120152}],"con":true,"img":false}]}
{"op":"mcm","clk":"5353986765","pt":1646220443357,"mc":[{"id":"1.195503857","rc":[{"atb":[[1.42,2],[1.39,1.42]],"id":41120152}],"con":true,"img":false}]}
{"op":"mcm","clk":"5353986854","pt":1646220443781,"mc":[{"id":"1.195503857","rc":[{"atb":[[1.41,1.42]],"id":41120152}],"con":true,"img":false}]}
{"op":"mcm","clk":"5353986901","pt":1646220443957,"mc":[{"id":"1.195503857","rc":[{"atb":[[1.41,3.42],[1.42,0]],"id":41120152}],"con":true,"img":false}]}
{"op":"mcm","clk":"5353986926","pt":1646220444060,"mc":[{"id":"1.195503857","rc":[{"atb":[[1.42,4]],"id":41120152}],"con":true,"img":false}]}
{"op":"mcm","clk":"5353986966","pt":1646220444277,"mc":[{"id":"1.195503857","rc":[{"atb":[[1.38,1.42]],"id":41120152},{"atl":[[13,2.84]],"id":41120152},{"atb":[[2.46,2.84]],"id":38247349},{"atl":[[12.5,2.84]],"id":38247349}],"con":true,"img":false}]}
{"op":"mcm","clk":"5353986985","pt":1646220444386,"mc":[{"id":"1.195503857","rc":[{"atb":[[1.42,0]],"id":41120152}],"con":true,"img":false}]}
{"op":"mcm","clk":"5353987046","pt":1646220444662,"mc":[{"id":"1.195503857","rc":[{"atb":[[1.41,10.26]],"id":41120152}],"con":true,"img":false}]}
{"op":"mcm","clk":"5353987277","pt":1646220445859,"mc":[{"id":"1.195503857","rc":[{"atl":[[4.4,4],[4.2,2]],"id":38247349}],"con":true,"img":false}]}
{"op":"mcm","clk":"5353987717","pt":1646220447487,"mc":[{"id":"1.195503857","rc":[{"atb":[[1.37,1.42]],"id":41120152},{"atb":[[2.54,1.42]],"id":38247349},{"atl":[[16.5,1.42]],"id":38247349}],"con":true,"img":false}]}
{"op":"mcm","clk":"5353988541","pt":1646220450996,"mc":[{"id":"1.195503857","rc":[{"atb":[[1.37,0],[1.39,0]],"id":41120152},{"atb":[[2.54,0]],"id":38247349},{"atl":[[12.5,0]],"id":38247349}],"con":true,"img":false}]}
{"op":"mcm","clk":"5353988554","pt":1646220451108,"mc":[{"id":"1.195503857","rc":[{"atl":[[4.2,0],[4.3,2]],"id":38247349}],"con":true,"img":false}]}
{"op":"mcm","clk":"5353988624","pt":1646220451490,"mc":[{"id":"1.195503857","rc":[{"atl":[[4.4,0]],"id":38247349}],"con":true,"img":false}]}
{"op":"mcm","clk":"5353988654","pt":1646220451600,"mc":[{"id":"1.195503857","rc":[{"atl":[[4.3,6]],"id":38247349}],"con":true,"img":false}]}
{"op":"mcm","clk":"5353988790","pt":1646220451990,"mc":[{"id":"1.195503857","rc":[{"atb":[[1.41,3.42]],"id":41120152},{"atl":[[1.73,22]],"id":41120152},{"atb":[[2.42,3.79]],"id":38247349},{"atl":[[4.3,2]],"id":38247349}],"con":true,"img":false}]}
{"op":"mcm","clk":"5353989009","pt":1646220452703,"mc":[{"id":"1.195503857","rc":[{"atb":[[1.41,10.26]],"id":41120152},{"atl":[[1.73,30.16]],"id":41120152},{"atl":[[4.3,6]],"id":38247349}],"con":true,"img":false}]}
{"op":"mcm","clk":"5353989173","pt":1646220453200,"mc":[{"id":"1.195503857","rc":[{"atl":[[1.73,22]],"id":41120152}],"con":true,"img":false}]}
{"op":"mcm","clk":"5353989328","pt":1646220453693,"mc":[{"id":"1.195503857","rc":[{"atl":[[1.74,0],[1.72,2]],"id":41120152},{"atb":[[2.36,2],[2.38,0]],"id":38247349}],"con":true,"img":false}]}
{"op":"mcm","clk":"5353989448","pt":1646220454377,"mc":[{"id":"1.195503857","rc":[{"atb":[[1.38,0]],"id":41120152},{"atl":[[13,0]],"id":41120152}],"con":true,"img":false}]}
{"op":"mcm","clk":"5353989895","pt":1646220457167,"mc":[{"id":"1.195503857","rc":[{"atl":[[13.5,0]],"id":41120152},{"atl":[[13,0]],"id":38247349}],"con":true,"img":false}]}
{"op":"mcm","clk":"5353990088","pt":1646220458171,"mc":[{"id":"1.195503857","rc":[{"atb":[[1.41,3.42]],"id":41120152},{"atl":[[4.3,2]],"id":38247349}],"con":true,"img":false}]}
{"op":"mcm","clk":"5353990126","pt":1646220458377,"mc":[{"id":"1.195503857","rc":[{"atl":[[4.3,0],[4.6,2]],"id":38247349}],"con":true,"img":false}]}
{"op":"mcm","clk":"5353990188","pt":1646220458797,"mc":[{"id":"1.195503857","rc":[{"atl":[[4.9,2],[4.6,0]],"id":38247349}],"con":true,"img":false}]}
{"op":"mcm","clk":"5353990201","pt":1646220458901,"mc":[{"id":"1.195503857","rc":[{"atb":[[2.36,0],[2.46,4.84]],"id":38247349}],"con":true,"img":false}]}
{"op":"mcm","clk":"5353990219","pt":1646220458964,"mc":[{"id":"1.195503857","rc":[{"atb":[[1.41,10.26]],"id":41120152},{"atl":[[4.6,4]],"id":38247349}],"con":true,"img":false}]}
{"op":"mcm","clk":"5353990238","pt":1646220459073,"mc":[{"id":"1.195503857","rc":[{"atb":[[2.46,2.84],[2.44,2]],"id":38247349},{"atl":[[4.9,0],[5,2]],"id":38247349}],"con":true,"img":false}]}
{"op":"mcm","clk":"5353990269","pt":1646220459280,"mc":[{"id":"1.195503857","rc":[{"atb":[[1.42,1.42]],"id":41120152},{"atl":[[4.5,2],[5,0],[4.6,0]],"id":38247349}],"con":true,"img":false}]}
{"op":"mcm","clk":"5353990315","pt":1646220459590,"mc":[{"id":"1.195503857","rc":[{"atb":[[1.41,3.42]],"id":41120152},{"atl":[[4.5,6]],"id":38247349}],"con":true,"img":false}]}
{"op":"mcm","clk":"5353990334","pt":1646220459696,"mc":[{"id":"1.195503857","rc":[{"atb":[[1.42,8.26]],"id":41120152}],"con":true,"img":false}]}
{"op":"mcm","clk":"5353990371","pt":1646220459857,"mc":[{"id":"1.195503857","rc":[{"atb":[[1.41,1.42],[1.43,2]],"id":41120152}],"con":true,"img":false}]}
{"op":"mcm","clk":"5353990426","pt":1646220460171,"mc":[{"id":"1.195503857","rc":[{"atb":[[1.42,4.26]],"id":41120152},{"atl":[[13.5,0]],"id":38247349}],"con":true,"img":false}]}
{"op":"mcm","clk":"5353990484","pt":1646220460491,"mc":[{"id":"1.195503857","rc":[{"atb":[[1.42,1.42]],"id":41120152}],"con":true,"img":false}]}
{"op":"mcm","clk":"5353990520","pt":1646220460698,"mc":[{"id":"1.195503857","rc":[{"atb":[[1.43,0],[1.42,3.42]],"id":41120152}],"con":true,"img":false}]}
{"op":"mcm","clk":"5353990559","pt":1646220460912,"mc":[{"id":"1.195503857","rc":[{"atb":[[1.43,4]],"id":41120152}],"con":true,"img":false}]}
{"op":"mcm","clk":"5353990619","pt":1646220461285,"mc":[{"id":"1.195503857","rc":[{"atb":[[1.43,0]],"id":41120152}],"con":true,"img":false}]}
{"op":"mcm","clk":"5353990690","pt":1646220461699,"mc":[{"id":"1.195503857","rc":[{"atb":[[1.42,10.26]],"id":41120152}],"con":true,"img":false}]}
{"op":"mcm","clk":"5353990739","pt":1646220461964,"mc":[{"id":"1.195503857","rc":[{"atl":[[1.72,6]],"id":41120152}],"con":true,"img":false}]}
{"op":"mcm","clk":"5353990884","pt":1646220462972,"mc":[{"id":"1.195503857","rc":[{"atb":[[1.41,0],[1.42,8.84]],"id":41120152},{"atl":[[14,0]],"id":41120152},{"atl":[[14,0]],"id":38247349}],"con":true,"img":false}]}
{"op":"mcm","clk":"5353991076","pt":1646220464389,"mc":[{"id":"1.195503857","rc":[{"atl":[[3.95,2]],"id":38247349}],"con":true,"img":false}]}
{"op":"mcm","clk":"5353991087","pt":1646220464495,"mc":[{"id":"1.195503857","rc":[{"atl":[[4.5,4]],"id":38247349}],"con":true,"img":false}]}
{"op":"mcm","clk":"5353991224","pt":1646220465503,"mc":[{"id":"1.195503857","rc":[{"atb":[[2.46,8.52]],"id":38247349}],"con":true,"img":false}]}
{"op":"mcm","clk":"5353991249","pt":1646220465711,"mc":[{"id":"1.195503857","rc":[{"atl":[[14.5,0]],"id":41120152},{"atb":[[2.44,0],[2.48,2]],"id":38247349}],"con":true,"img":false}]}
{"op":"mcm","clk":"5353991304","pt":1646220466082,"mc":[{"id":"1.195503857","rc":[{"atb":[[2.46,2.84]],"id":38247349}],"con":true,"img":false}]}
{"op":"mcm","clk":"5353991314","pt":1646220466187,"mc":[{"id":"1.195503857","rc":[{"atb":[[2.48,7.68]],"id":38247349}],"con":true,"img":false}]}
{"op":"mcm","clk":"5353991566","pt":1646220468071,"mc":[{"id":"1.195503857","rc":[{"atb":[[2.46,0]],"id":38247349},{"atl":[[14.5,0]],"id":38247349}],"con":true,"img":false}]}
{"op":"mcm","clk":"5353991747","pt":1646220469486,"mc":[{"id":"1.195503857","rc":[{"atl":[[3.95,0],[4.2,2]],"id":38247349}],"con":true,"img":false}]}
{"op":"mcm","clk":"5353991957","pt":1646220471113,"mc":[{"id":"1.195503857","rc":[{"atl":[[15,0]],"id":41120152},{"atl":[[15,0]],"id":38247349}],"con":true,"img":false}]}
{"op":"mcm","clk":"5353992258","pt":1646220473526,"mc":[{"id":"1.195503857","rc":[{"atl":[[4.5,0]],"id":38247349}],"con":true,"img":false}]}
{"op":"mcm","clk":"5353992275","pt":1646220473632,"mc":[{"id":"1.195503857","rc":[{"atl":[[4.2,6]],"id":38247349}],"con":true,"img":false}]}
{"op":"mcm","clk":"5353992290","pt":1646220473738,"mc":[{"id":"1.195503857","rc":[{"atb":[[1.01,0],[1.15,0],[1.35,0]],"id":41120152},{"atb":[[2.02,0],[1.81,0],[2.42,0]],"id":38247349}],"con":true,"img":false}]}
{"op":"mcm","clk":"5353992416","pt":1646220474687,"mc":[{"id":"1.195503857","rc":[{"atl":[[4,2],[4.2,4]],"id":38247349}],"con":true,"img":false}]}
{"op":"mcm","clk":"5353992480","pt":1646220475104,"mc":[{"id":"1.195503857","rc":[{"atb":[[1.42,2]],"id":41120152},{"atl":[[1.72,2]],"id":41120152},{"atb":[[2.48,2]],"id":38247349},{"atl":[[4.2,0]],"id":38247349}],"con":true,"img":false}]}
{"op":"mcm","clk":"5353992583","pt":1646220475899,"mc":[{"id":"1.195503857","rc":[{"atb":[[1.42,6]],"id":41120152},{"atl":[[1.72,6]],"id":41120152},{"atb":[[2.48,6]],"id":38247349},{"atl":[[4,6]],"id":38247349}],"con":true,"img":false}]}
{"op":"mcm","clk":"5353993070","pt":1646220479823,"mc":[{"id":"1.195503857","rc":[{"atl":[[4,4],[3.9,2]],"id":38247349}],"con":true,"img":false}]}
{"op":"mcm","clk":"5353993125","pt":1646220480192,"mc":[{"id":"1.195503857","rc":[{"atl":[[4,0]],"id":38247349}],"con":true,"img":false}]}
{"op":"mcm","clk":"5353993145","pt":1646220480295,"mc":[{"id":"1.195503857","rc":[{"atl":[[3.9,6]],"id":38247349}],"con":true,"img":false}]}
{"op":"mcm","clk":"5353993443","pt":1646220482510,"mc":[{"id":"1.195503857","rc":[{"atl":[[15.5,0]],"id":38247349}],"con":true,"img":false}]}
{"op":"mcm","clk":"5353993479","pt":1646220482822,"mc":[{"id":"1.195503857","rc":[{"atl":[[100,1.63]],"id":41120152}],"con":true,"img":false}]}
{"op":"mcm","clk":"5353993540","pt":1646220483297,"mc":[{"id":"1.195503857","rc":[{"atl":[[100,0.04]],"id":41120152}],"con":true,"img":false}]}
{"op":"mcm","clk":"5353993611","pt":1646220483823,"mc":[{"id":"1.195503857","rc":[{"atl":[[100,0]],"id":41120152}],"con":true,"img":false}]}
{"op":"mcm","clk":"5353993624","pt":1646220483928,"mc":[{"id":"1.195503857","rc":[{"atb":[[1.42,5.96]],"id":41120152},{"trd":[[1.42,0.08]],"ltp":1.42,"tv":0.08,"id":41120152}],"con":true,"img":false}]}
{"op":"mcm","clk":"5353993645","pt":1646220484138,"mc":[{"id":"1.195503857","rc":[{"atb":[[1.42,4]],"id":41120152}],"con":true,"img":false}]}
{"op":"mcm","clk":"5353993699","pt":1646220484505,"mc":[{"id":"1.195503857","rc":[{"atb":[[1.42,0]],"id":41120152}],"con":true,"img":false}]}
{"op":"mcm","clk":"5353993723","pt":1646220484716,"mc":[{"id":"1.195503857","rc":[{"atb":[[2.48,2]],"id":38247349}],"con":true,"img":false}]}
{"op":"mcm","clk":"5353993757","pt":1646220485028,"mc":[{"id":"1.195503857","rc":[{"atl":[[15.5,0]],"id":41120152}],"con":true,"img":false}]}
{"op":"mcm","clk":"5353993801","pt":1646220485453,"mc":[{"id":"1.195503857","rc":[{"atb":[[1.01,539.56],[1.3,17.98],[1.1,53.95]],"id":41120152},{"atb":[[1.9,5.99],[2.6,3.37],[2.2,4.49]],"id":38247349}],"con":true,"img":false}]}
{"op":"mcm","clk":"5353993825","pt":1646220485610,"mc":[{"id":"1.195503857","rc":[{"atb":[[2.52,2],[2.48,0]],"id":38247349}],"con":true,"img":false}]}
{"op":"mcm","clk":"5353993840","pt":1646220485715,"mc":[{"id":"1.195503857","rc":[{"atb":[[1.3,53.96]],"id":41120152}],"con":true,"img":false}]}
{"op":"mcm","clk":"5353994247","pt":1646220489318,"mc":[{"id":"1.195503857","rc":[{"atb":[[1.36,1.42]],"id":41120152},{"atl":[[15.5,1.42]],"id":41120152},{"atl":[[15.5,1.42]],"id":38247349}],"con":true,"img":false}]}
{"op":"mcm","clk":"5353994329","pt":1646220490153,"mc":[{"id":"1.195503857","rc":[{"atb":[[1.3,17.98]],"id":41120152},{"atl":[[1.72,2]],"id":41120152},{"atl":[[3.9,2]],"id":38247349}],"con":true,"img":false}]}
{"op":"mcm","clk":"5353994356","pt":1646220490311,"mc":[{"id":"1.195503857","rc":[{"atl":[[4.4,2],[3.9,0]],"id":38247349}],"con":true,"img":false}]}
{"op":"mcm","clk":"5353994391","pt":1646220490631,"mc":[{"id":"1.195503857","rc":[{"atb":[[1.36,4.26]],"id":41120152},{"atl":[[1.72,6]],"id":41120152},{"atl":[[4.4,6]],"id":38247349}],"con":true,"img":false}]}
{"op":"mcm","clk":"5353994418","pt":1646220490838,"mc":[{"id":"1.195503857","rc":[{"atb":[[1.36,1.42]],"id":41120152},{"atl":[[1.72,2]],"id":41120152},{"atl":[[4.4,2]],"id":38247349}],"con":true,"img":false}]}
{"op":"mcm","clk":"5353994461","pt":1646220491253,"mc":[{"id":"1.195503857","rc":[{"atb":[[1.36,4.26]],"id":41120152},{"atl":[[1.72,6]],"id":41120152},{"atl":[[4.4,6]],"id":38247349}],"con":true,"img":false}]}
{"op":"mcm","clk":"5353994488","pt":1646220491419,"mc":[{"id":"1.195503857","rc":[{"atb":[[1.35,1.42]],"id":41120152}],"con":true,"img":false}]}
{"op":"mcm","clk":"5353994679","pt":1646220493140,"mc":[{"id":"1.195503857","rc":[{"atb":[[1.37,1.42]],"id":41120152},{"atl":[[15,1.42]],"id":41120152},{"atl":[[15,1.42]],"id":38247349}],"con":true,"img":false}]}
{"op":"mcm","clk":"5353994716","pt":1646220493555,"mc":[{"id":"1.195503857","rc":[{"atb":[[1.36,1.42]],"id":41120152}],"con":true,"img":false}]}
{"op":"mcm","clk":"5353994728","pt":1646220493611,"mc":[{"id":"1.195503857","rc":[{"atb":[[1.37,4.26]],"id":41120152}],"con":true,"img":false}]}
{"op":"mcm","clk":"5353994870","pt":1646220494989,"mc":[{"id":"1.195503857","rc":[{"atb":[[1.31,1.42]],"id":41120152},{"atl":[[15,2.84]],"id":41120152},{"atl":[[15,2.84]],"id":38247349}],"con":true,"img":false}]}
{"op":"mcm","clk":"5353994922","pt":1646220495458,"mc":[{"id":"1.195503857","rc":[{"atl":[[4.3,2]],"id":38247349}],"con":true,"img":false}]}
{"op":"mcm","clk":"5353994932","pt":1646220495561,"mc":[{"id":"1.195503857","rc":[{"atl":[[4.4,4]],"id":38247349}],"con":true,"img":false}]}
{"op":"mcm","clk":"5353994954","pt":1646220495719,"mc":[{"id":"1.195503857","rc":[{"atb":[[1.36,0],[1.35,0]],"id":41120152}],"con":true,"img":false}]}
{"op":"mcm","clk":"5353994966","pt":1646220495825,"mc":[{"id":"1.195503857","rc":[{"atl":[[4.4,0]],"id":38247349}],"con":true,"img":false}]}
{"op":"mcm","clk":"5353994976","pt":1646220495928,"mc":[{"id":"1.195503857","rc":[{"atl":[[4.3,6]],"id":38247349}],"con":true,"img":false}]}
{"op":"mcm","clk":"5353995204","pt":1646220497646,"mc":[{"id":"1.195503857","rc":[{"atb":[[1.32,1.42]],"id":41120152}],"con":true,"img":false}]}
{"op":"mcm","clk":"5353995355","pt":1646220498943,"mc":[{"id":"1.195503857","rc":[{"atb":[[1.32,2.84]],"id":41120152}],"con":true,"img":false}]}
{"op":"mcm","clk":"5353995654","pt":1646220501368,"mc":[{"id":"1.195503857","rc":[{"atb":[[1.01,0],[1.3,0],[1.1,0]],"id":41120152},{"atb":[[1.9,0],[2.6,0],[2.2,0]],"id":38247349}],"con":true,"img":false}]}
{"op":"mcm","clk":"5353995691","pt":1646220501683,"mc":[{"id":"1.195503857","rc":[{"atb":[[2.52,6]],"id":38247349}],"con":true,"img":false}]}
{"op":"mcm","clk":"5353995823","pt":1646220502575,"mc":[{"id":"1.195503857","rc":[{"atl":[[14.5,1.42]],"id":41120152},{"atl":[[14.5,1.42]],"id":38247349}],"con":true,"img":false}]}
{"op":"mcm","clk":"5353995878","pt":1646220502941,"mc":[{"id":"1.195503857","rc":[{"atb":[[1.37,1.42]],"id":41120152},{"atl":[[1.72,2]],"id":41120152},{"atb":[[2.52,2]],"id":38247349},{"atl":[[4.3,2]],"id":38247349}],"con":true,"img":false}]}
{"op":"mcm","clk":"5353995892","pt":1646220503044,"mc":[{"id":"1.195503857","rc":[{"atl":[[4.5,2],[4.3,0]],"id":38247349}],"con":true,"img":false}]}
{"op":"mcm","clk":"5353995949","pt":1646220503474,"mc":[{"id":"1.195503857","rc":[{"atb":[[1.32,0],[1.31,0]],"id":41120152}],"con":true,"img":false}]}
{"op":"mcm","clk":"5353995982","pt":1646220503684,"mc":[{"id":"1.195503857","rc":[{"atb":[[1.37,4.26]],"id":41120152},{"atl":[[1.72,6]],"id":41120152},{"atb":[[2.52,6]],"id":38247349},{"atl":[[4.5,6]],"id":38247349}],"con":true,"img":false}]}
{"op":"mcm","clk":"5353996074","pt":1646220504462,"mc":[{"id":"1.195503857","rc":[{"atl":[[14.5,2.84]],"id":41120152},{"atl":[[14.5,2.84]],"id":38247349}],"con":true,"img":false}]}
{"op":"mcm","clk":"5353996113","pt":1646220504777,"mc":[{"id":"1.195503857","rc":[{"atb":[[1.37,1.42]],"id":41120152},{"atl":[[1.72,2]],"id":41120152},{"atb":[[2.52,2]],"id":38247349},{"atl":[[4.5,2]],"id":38247349}],"con":true,"img":false}]}
{"op":"mcm","clk":"5353996171","pt":1646220505251,"mc":[{"id":"1.195503857","rc":[{"atl":[[4.5,0],[4.6,2]],"id":38247349}],"con":true,"img":false}]}
{"op":"mcm","clk":"5353996183","pt":1646220505353,"mc":[{"id":"1.195503857","rc":[{"atb":[[1.37,4.26]],"id":41120152},{"atl":[[1.72,6]],"id":41120152},{"atb":[[2.52,6]],"id":38247349},{"atl":[[4.5,4]],"id":38247349}],"con":true,"img":false}]}
{"op":"mcm","clk":"5353996220","pt":1646220505668,"mc":[{"id":"1.195503857","rc":[{"atl":[[4.5,0]],"id":38247349}],"con":true,"img":false}]}
{"op":"mcm","clk":"5353996267","pt":1646220505982,"mc":[{"id":"1.195503857","rc":[{"atl":[[4.5,8]],"id":38247349}],"con":true,"img":false}]}
{"op":"mcm","clk":"5353996310","pt":1646220506245,"mc":[{"id":"1.195503857","rc":[{"atl":[[4.5,0]],"id":38247349}],"con":true,"img":false}]}
{"op":"mcm","clk":"5353996320","pt":1646220506350,"mc":[{"id":"1.195503857","rc":[{"atl":[[4.6,10]],"id":38247349}],"con":true,"img":false}]}
{"op":"mcm","clk":"5353996423","pt":1646220507181,"mc":[{"id":"1.195503857","rc":[{"atb":[[1.3,1.42]],"id":41120152}],"con":true,"img":false}]}
{"op":"mcm","clk":"5353996509","pt":1646220507758,"mc":[{"id":"1.195503857","rc":[{"atb":[[1.37,1.42]],"id":41120152},{"atl":[[1.72,2]],"id":41120152},{"atb":[[2.52,2]],"id":38247349},{"atl":[[4.6,2]],"id":38247349}],"con":true,"img":false}]}
{"op":"mcm","clk":"5353996586","pt":1646220508491,"mc":[{"id":"1.195503857","rc":[{"atb":[[1.37,4.26]],"id":41120152},{"atl":[[1.72,6]],"id":41120152},{"atb":[[2.52,6]],"id":38247349},{"atl":[[4.6,6]],"id":38247349}],"con":true,"img":false}]}
{"op":"mcm","clk":"5353996609","pt":1646220508653,"mc":[{"id":"1.195503857","rc":[{"atb":[[1.3,2.84]],"id":41120152}],"con":true,"img":false}]}
{"op":"mcm","clk":"5353996634","pt":1646220508862,"mc":[{"id":"1.195503857","rc":[{"atb":[[1.01,539.56],[1.02,269.78],[1.22,24.52]],"id":41120152},{"atb":[[2.36,3.96],[1.98,5.5],[2.76,3.06]],"id":38247349}],"con":true,"img":false}]}
{"op":"mcm","clk":"5353996707","pt":1646220509486,"mc":[{"id":"1.195503857","rc":[{"atb":[[1.37,2.84],[1.3,1.42]],"id":41120152},{"atl":[[14.5,0],[15,0]],"id":41120152}],"con":true,"img":false}]}
{"op":"mcm","clk":"5353996763","pt":1646220509859,"mc":[{"id":"1.195503857","rc":[{"atb":[[1.37,0]],"id":41120152}],"con":true,"img":false}]}
{"op":"mcm","clk":"5353996832","pt":1646220510382,"mc":[{"id":"1.195503857","rc":[{"atb":[[1.3,4.26]],"id":41120152}],"con":true,"img":false}]}
{"op":"mcm","clk":"5353997028","pt":1646220511460,"mc":[{"id":"1.195503857","rc":[{"atl":[[14,1.42]],"id":38247349}],"con":true,"img":false}]}
{"op":"mcm","clk":"5353997094","pt":1646220511779,"mc":[{"id":"1.195503857","rc":[{"atb":[[1.3,2.84]],"id":41120152}],"con":true,"img":false}]}
{"op":"mcm","clk":"5353997140","pt":1646220512149,"mc":[{"id":"1.195503857","rc":[{"atb":[[1.3,0]],"id":41120152}],"con":true,"img":false}]}
{"op":"mcm","clk":"5353997198","pt":1646220512567,"mc":[{"id":"1.195503857","rc":[{"atb":[[1.22,73.58]],"id":41120152}],"con":true,"img":false}]}
{"op":"mcm","clk":"5353997363","pt":1646220513761,"mc":[{"id":"1.195503857","rc":[{"atb":[[1.31,1.42]],"id":41120152},{"atl":[[14.5,1.42]],"id":41120152},{"atl":[[13.5,1.42]],"id":38247349}],"con":true,"img":false}]}
{"op":"mcm","clk":"5353997407","pt":1646220514176,"mc":[{"id":"1.195503857","rc":[{"atb":[[1.22,24.52]],"id":41120152},{"atl":[[1.72,2]],"id":41120152},{"atb":[[2.52,2]],"id":38247349},{"atl":[[4.6,2]],"id":38247349}],"con":true,"img":false}]}
{"op":"mcm","clk":"5353997438","pt":1646220514389,"mc":[{"id":"1.195503857","rc":[{"atl":[[4.7,2],[4.6,0]],"id":38247349}],"con":true,"img":false}]}
{"op":"mcm","clk":"5353997498","pt":1646220514856,"mc":[{"id":"1.195503857","rc":[{"atb":[[1.31,4.26]],"id":41120152},{"atl":[[1.72,6]],"id":41120152},{"atl":[[4.7,6]],"id":38247349}],"con":true,"img":false}]}
{"op":"mcm","clk":"5353997541","pt":1646220515273,"mc":[{"id":"1.195503857","rc":[{"atb":[[1.33,1.42]],"id":41120152},{"atl":[[14,1.42]],"id":41120152},{"atl":[[13.5,2.84]],"id":38247349}],"con":true,"img":false}]}
{"op":"mcm","clk":"5353997637","pt":1646220516066,"mc":[{"id":"1.195503857","rc":[{"atb":[[1.31,2.84]],"id":41120152}],"con":true,"img":false}]}
{"op":"mcm","clk":"5353997795","pt":1646220517364,"mc":[{"id":"1.195503857","rc":[{"atl":[[4.7,4],[4.6,2]],"id":38247349}],"con":true,"img":false}]}
{"op":"mcm","clk":"5353997840","pt":1646220517676,"mc":[{"id":"1.195503857","rc":[{"atl":[[4.7,0]],"id":38247349}],"con":true,"img":false}]}
{"op":"mcm","clk":"5353997855","pt":1646220517783,"mc":[{"id":"1.195503857","rc":[{"atb":[[1.28,1.42]],"id":41120152},{"atl":[[15,1.42]],"id":41120152},{"atl":[[13,1.42],[4.6,6]],"id":38247349}],"con":true,"img":false}]}
{"op":"mcm","clk":"5353998033","pt":1646220518983,"mc":[{"id":"1.195503857","rc":[{"atb":[[1.28,2.84]],"id":41120152},{"atl":[[15,2.84]],"id":41120152},{"atl":[[13,2.84]],"id":38247349}],"con":true,"img":false}]}
{"op":"mcm","clk":"5353998085","pt":1646220519351,"mc":[{"id":"1.195503857","rc":[{"atb":[[1.31,0]],"id":41120152},{"atl":[[1.72,2]],"id":41120152},{"atl":[[4.6,2]],"id":38247349}],"con":true,"img":false}]}
{"op":"mcm","clk":"5353998217","pt":1646220520409,"mc":[{"id":"1.195503857","rc":[{"atb":[[1.33,4.26]],"id":41120152},{"atl":[[1.72,6]],"id":41120152},{"atl":[[4.6,6]],"id":38247349}],"con":true,"img":false}]}
{"op":"mcm","clk":"5353998279","pt":1646220520887,"mc":[{"id":"1.195503857","rc":[{"atb":[[1.29,1.42]],"id":41120152},{"atl":[[12.5,1.42]],"id":38247349}],"con":true,"img":false}]}
{"op":"mcm","clk":"5353998316","pt":1646220521202,"mc":[{"id":"1.195503857","rc":[{"atb":[[1.33,2.84]],"id":41120152}],"con":true,"img":false}]}
{"op":"mcm","clk":"5353998329","pt":1646220521252,"mc":[{"id":"1.195503857","rc":[{"atl":[[4.5,2],[4.6,4]],"id":38247349}],"con":true,"img":false}]}
{"op":"mcm","clk":"5353998352","pt":1646220521468,"mc":[{"id":"1.195503857","rc":[{"atb":[[1.33,0]],"id":41120152},{"atl":[[4.6,0]],"id":38247349}],"con":true,"img":false}]}
{"op":"mcm","clk":"5353998363","pt":1646220521571,"mc":[{"id":"1.195503857","rc":[{"atl":[[4.5,6]],"id":38247349}],"con":true,"img":false}]}
{"op":"mcm","clk":"5353998398","pt":1646220521884,"mc":[{"id":"1.195503857","rc":[{"atb":[[1.29,4.26]],"id":41120152}],"con":true,"img":false}]}
{"op":"mcm","clk":"5353998412","pt":1646220521995,"mc":[{"id":"1.195503857","rc":[{"atb":[[1.29,1.42]],"id":41120152},{"atl":[[1.72,2]],"id":41120152},{"atl":[[4.5,2]],"id":38247349}],"con":true,"img":false}]}
{"op":"mcm","clk":"5353998436","pt":1646220522203,"mc":[{"id":"1.195503857","rc":[{"atb":[[1.23,1.42]],"id":41120152},{"atl":[[12.5,2.84]],"id":38247349}],"con":true,"img":false}]}
{"op":"mcm","clk":"5353998493","pt":1646220522722,"mc":[{"id":"1.195503857","rc":[{"atl":[[1.72,6]],"id":41120152},{"atl":[[4.5,6]],"id":38247349}],"con":true,"img":false}]}
{"op":"mcm","clk":"5353998671","pt":1646220523978,"mc":[{"id":"1.195503857","rc":[{"atl":[[4.5,4],[4.1,2]],"id":38247349}],"con":true,"img":false}]}
{"op":"mcm","clk":"5353998716","pt":1646220524397,"mc":[{"id":"1.195503857","rc":[{"atl":[[1.71,2],[1.72,4]],"id":41120152}],"con":true,"img":false}]}
{"op":"mcm","clk":"5353998726","pt":1646220524499,"mc":[{"id":"1.195503857","rc":[{"atl":[[1.72,0]],"id":41120152},{"atl":[[4.5,0]],"id":38247349}],"con":true,"img":false}]}
{"op":"mcm","clk":"5353998775","pt":1646220525019,"mc":[{"id":"1.195503857","rc":[{"atb":[[1.29,0]],"id":41120152}],"con":true,"img":false}]}
{"op":"mcm","clk":"5353998797","pt":1646220525178,"mc":[{"id":"1.195503857","rc":[{"atl":[[1.71,6]],"id":41120152},{"atl":[[4.1,6]],"id":38247349}],"con":true,"img":false}]}
{"op":"mcm","clk":"5353998942","pt":1646220526713,"mc":[{"id":"1.195503857","rc":[{"atb":[[1.32,1.42]],"id":41120152}],"con":true,"img":false}]}
{"op":"mcm","clk":"5353999039","pt":1646220527607,"mc":[{"id":"1.195503857","rc":[{"atb":[[1.32,4.26]],"id":41120152}],"con":true,"img":false}]}
{"op":"mcm","clk":"5353999059","pt":1646220527810,"mc":[{"id":"1.195503857","rc":[{"atb":[[1.32,1.42]],"id":41120152},{"atl":[[1.71,2]],"id":41120152},{"atl":[[4.1,2]],"id":38247349}],"con":true,"img":false}]}
{"op":"mcm","clk":"5353999081","pt":1646220528027,"mc":[{"id":"1.195503857","rc":[{"atb":[[1.28,0]],"id":41120152}],"con":true,"img":false}]}
{"op":"mcm","clk":"5353999151","pt":1646220528606,"mc":[{"id":"1.195503857","rc":[{"atl":[[1.71,6]],"id":41120152},{"atl":[[4.1,6]],"id":38247349}],"con":true,"img":false}]}
{"op":"mcm","clk":"5353999300","pt":1646220529793,"mc":[{"id":"1.195503857","rc":[{"atb":[[1.34,1.42]],"id":41120152}],"con":true,"img":false}]}
{"op":"mcm","clk":"5353999324","pt":1646220530009,"mc":[{"id":"1.195503857","rc":[{"atl":[[4,2],[4.1,4]],"id":38247349}],"con":true,"img":false}]}
{"op":"mcm","clk":"5353999360","pt":1646220530316,"mc":[{"id":"1.195503857","rc":[{"atl":[[4.1,0]],"id":38247349}],"con":true,"img":false}]}
{"op":"mcm","clk":"5353999372","pt":1646220530426,"mc":[{"id":"1.195503857","rc":[{"atl":[[4,6]],"id":38247349}],"con":true,"img":false}]}
{"op":"mcm","clk":"5353999392","pt":1646220530623,"mc":[{"id":"1.195503857","rc":[{"atl":[[12.5,0]],"id":38247349}],"con":true,"img":false}]}
{"op":"mcm","clk":"5353999641","pt":1646220532519,"mc":[{"id":"1.195503857","rc":[{"atb":[[1.35,1.42]],"id":41120152}],"con":true,"img":false}]}
{"op":"mcm","clk":"5353999670","pt":1646220532728,"mc":[{"id":"1.195503857","rc":[{"atb":[[1.32,0],[1.34,4.26]],"id":41120152},{"atl":[[14,0]],"id":41120152}],"con":true,"img":false}]}
{"op":"mcm","clk":"5353999682","pt":1646220532829,"mc":[{"id":"1.195503857","rc":[{"atb":[[1.4,5.63]],"id":41120152}],"con":true,"img":false}]}
{"op":"mcm","clk":"5353999715","pt":1646220533115,"mc":[{"id":"1.195503857","rc":[{"atb":[[1.34,1.42]],"id":41120152}],"con":true,"img":false}]}
{"op":"mcm","clk":"5353999729","pt":1646220533205,"mc":[{"id":"1.195503857","rc":[{"atb":[[1.35,4.26]],"id":41120152}],"con":true,"img":false}]}
{"op":"mcm","clk":"5353999863","pt":1646220534307,"mc":[{"id":"1.195503857","rc":[{"atb":[[1.35,1.42]],"id":41120152},{"atl":[[1.71,2]],"id":41120152},{"atl":[[4,2]],"id":38247349}],"con":true,"img":false}]}
{"op":"mcm","clk":"5353999889","pt":1646220534513,"mc":[{"id":"1.195503857","rc":[{"atl":[[1.71,0],[1.72,2]],"id":41120152}],"con":true,"img":false}]}
{"op":"mcm","clk":"5353999966","pt":1646220535136,"mc":[{"id":"1.195503857","rc":[{"atb":[[1.23,0],[1.34,0],[1.35,0]],"id":41120152},{"atl":[[14.5,0]],"id":41120152},{"atl":[[3.85,2],[4,0],[13,0]],"id":38247349}],"con":true,"img":false}]}
{"op":"mcm","clk":"5354000008","pt":1646220535408,"mc":[{"id":"1.195503857","rc":[{"atl":[[3.85,0]],"id":38247349}],"con":true,"img":false}]}
{"op":"mcm","clk":"5354000020","pt":1646220535514,"mc":[{"id":"1.195503857","rc":[{"atl":[[3.75,2]],"id":38247349}],"con":true,"img":false}]}
{"op":"mcm","clk":"5354000028","pt":1646220535616,"mc":[{"id":"1.195503857","rc":[{"atl":[[3.75,0]],"id":38247349}],"con":true,"img":false}]}
{"op":"mcm","clk":"5354000051","pt":1646220535724,"mc":[{"id":"1.195503857","rc":[{"atl":[[3.9,2]],"id":38247349}],"con":true,"img":false}]}
{"op":"mcm","clk":"5354000064","pt":1646220535830,"mc":[{"id":"1.195503857","rc":[{"atb":[[1.4,16.89]],"id":41120152},{"atl":[[1.72,6]],"id":41120152},{"atl":[[3.75,4]],"id":38247349}],"con":true,"img":false}]}
{"op":"mcm","clk":"5354000075","pt":1646220535928,"mc":[{"id":"1.195503857","rc":[{"atl":[[3.85,2],[3.9,0]],"id":38247349}],"con":true,"img":false}]}
{"op":"mcm","clk":"5354000107","pt":1646220536136,"mc":[{"id":"1.195503857","rc":[{"atl":[[3.75,0]],"id":38247349}],"con":true,"img":false}]}
{"op":"mcm","clk":"5354000131","pt":1646220536401,"mc":[{"id":"1.195503857","rc":[{"atl":[[3.85,6]],"id":38247349}],"con":true,"img":false}]}
{"op":"mcm","clk":"5354000141","pt":1646220536508,"mc":[{"id":"1.195503857","rc":[{"atb":[[2.52,0],[2.76,0]],"id":38247349},{"atl":[[2.4,430.94]],"id":38247349},{"trd":[[2.52,4],[2.76,6.13]],"ltp":2.52,"tv":10.12,"id":38247349}],"con":true,"img":false}]}
{"op":"mcm","clk":"5354000153","pt":1646220536617,"mc":[{"id":"1.195503857","rc":[{"atl":[[2.4,326.78]],"id":38247349},{"trd":[[2.4,208.31]],"ltp":2.4,"tv":208.31,"id":38247349}],"con":true,"img":false}]}
{"op":"mcm","clk":"5354000179","pt":1646220536821,"mc":[{"id":"1.195503857","rc":[{"atb":[[2.38,2]],"id":38247349},{"atl":[[2.4,222.62]],"id":38247349},{"trd":[[2.4,416.63]],"ltp":2.4,"tv":416.63,"id":38247349}],"con":true,"img":false}]}
{"op":"mcm","clk":"5354000196","pt":1646220536926,"mc":[{"id":"1.195503857","rc":[{"atb":[[1.67,43.51]],"id":41120152},{"atb":[[2.36,11.9],[2.28,22.77]],"id":38247349}],"con":true,"img":false}]}
{"op":"mcm","clk":"5354000218","pt":1646220537138,"mc":[{"id":"1.195503857","rc":[{"atl":[[15,0]],"id":41120152},{"atl":[[13.5,0],[14,0]],"id":38247349}],"con":true,"img":false}]}
{"op":"mcm","clk":"5354000255","pt":1646220537401,"mc":[{"id":"1.195503857","rc":[{"atb":[[2.36,3.96]],"id":38247349}],"con":true,"img":false}]}
{"op":"mcm","clk":"5354000268","pt":1646220537508,"mc":[{"id":"1.195503857","rc":[{"atl":[[1.73,0]],"id":41120152},{"atb":[[2.38,9.94]],"id":38247349}],"con":true,"img":false}]}
{"op":"mcm","clk":"5354000317","pt":1646220537915,"mc":[{"id":"1.195503857","rc":[{"atl":[[1.72,0]],"id":41120152},{"trd":[[1.73,0],[1.72,11.99]],"ltp":1.73,"tv":11.99,"id":41120152},{"atb":[[1.99,29.44],[2.38,9.93],[2.28,0]],"id":38247349},{"trd":[[2.38,0.01]],"ltp":2.38,"tv":0.01,"id":38247349}],"con":true,"img":false}]}
{"op":"mcm","clk":"5354000342","pt":1646220538132,"mc":[{"id":"1.195503857","rc":[{"atb":[[1.51,2]],"id":41120152}],"con":true,"img":false}]}
{"op":"mcm","clk":"5354000370","pt":1646220538336,"mc":[{"id":"1.195503857","rc":[{"atb":[[1.67,0]],"id":41120152},{"atb":[[1.99,0]],"id":38247349}],"con":true,"img":false}]}
{"op":"mcm","clk":"5354000388","pt":1646220538494,"mc":[{"id":"1.195503857","rc":[{"atb":[[1.41,2],[1.51,0]],"id":41120152}],"con":true,"img":false}]}
{"op":"mcm","clk":"5354000435","pt":1646220538908,"mc":[{"id":"1.195503857","rc":[{"atb":[[1.4,5.63]],"id":41120152}],"con":true,"img":false}]}
{"op":"mcm","clk":"5354000452","pt":1646220539020,"mc":[{"id":"1.195503857","rc":[{"atb":[[1.41,13.26]],"id":41120152},{"atl":[[15.5,0],[16,0],[16.5,0]],"id":41120152},{"atl":[[32,0],[34,0],[14.5,0],[15,0],[15.5,0],[16,0],[16.5,0],[17,0],[17.5,0],[18,0],[18.5,0],[19,0],[19.5,0],[20,0],[21,0],[22,0],[23,0],[24,0],[25,0],[26,0],[27,0],[28,0],[29,0],[30,0]],"id":38247349}],"con":true,"img":false}]}
{"op":"mcm","clk":"5354000479","pt":1646220539226,"mc":[{"id":"1.195503857","rc":[{"atl":[[15.5,2.84]],"id":41120152}],"con":true,"img":false}]}
{"op":"mcm","clk":"5354000501","pt":1646220539431,"mc":[{"id":"1.195503857","rc":[{"atb":[[1.41,2]],"id":41120152},{"atl":[[15.5,0]],"id":41120152},{"atb":[[2.38,1.99]],"id":38247349},{"atl":[[3.85,2]],"id":38247349}],"con":true,"img":false}]}
{"op":"mcm","clk":"5354000566","pt":1646220539917,"mc":[{"id":"1.195503857","rc":[{"atb":[[1.7,1.42]],"id":41120152},{"atb":[[2.38,0]],"id":38247349},{"atl":[[2.42,1.42]],"id":38247349},{"trd":[[2.38,3.99]],"ltp":2.38,"tv":3.99,"id":38247349}],"con":true,"img":false}]}
{"op":"mcm","clk":"5354000579","pt":1646220540047,"mc":[{"id":"1.195503857","rc":[{"atb":[[1.41,6]],"id":41120152},{"atb":[[2.38,3.98]],"id":38247349}],"con":true,"img":false}]}
{"op":"mcm","clk":"5354000597","pt":1646220540204,"mc":[{"id":"1.195503857","rc":[{"atl":[[2.4,124.04]],"id":38247349},{"trd":[[2.4,613.81]],"ltp":2.4,"tv":613.81,"id":38247349}],"con":true,"img":false}]}
{"op":"mcm","clk":"5354000634","pt":1646220540530,"mc":[{"id":"1.195503857","rc":[{"atb":[[1.67,11.98],[1.68,11.9]],"id":41120152},{"atb":[[2.38,0]],"id":38247349}],"con":true,"img":false}]}
{"op":"mcm","clk":"5354000671","pt":1646220540835,"mc":[{"id":"1.195503857","rc":[{"atl":[[17,0],[17.5,0],[18,0],[18.5,0],[19,0],[19.5,0],[20,0]],"id":41120152}],"con":true,"img":false}]}
{"op":"mcm","clk":"5354000698","pt":1646220541043,"mc":[{"id":"1.195503857","rc":[{"atb":[[2.36,11.9]],"id":38247349},{"atl":[[2.84,2]],"id":38247349}],"con":true,"img":false}]}
{"op":"mcm","clk":"5354000713","pt":1646220541100,"mc":[{"id":"1.195503857","rc":[{"atl":[[3.85,0]],"id":38247349}],"con":true,"img":false}]}
{"op":"mcm","clk":"5354000800","pt":1646220541829,"mc":[{"id":"1.195503857","rc":[{"atb":[[2.36,0]],"id":38247349},{"trd":[[2.36,23.81]],"ltp":2.36,"tv":23.81,"id":38247349}],"con":true,"img":false}]}
{"op":"mcm","clk":"5354000840","pt":1646220542039,"mc":[{"id":"1.195503857","rc":[{"atb":[[2.38,2]],"id":38247349}],"con":true,"img":false}]}
{"op":"mcm","clk":"5354000862","pt":1646220542189,"mc":[{"id":"1.195503857","rc":[{"atb":[[1.7,0]],"id":41120152},{"atb":[[2.38,0]],"id":38247349},{"atl":[[2.42,0]],"id":38247349},{"trd":[[2.38,7.98]],"ltp":2.38,"tv":7.98,"id":38247349}],"con":true,"img":false}]}
{"op":"mcm","clk":"5354000962","pt":1646220542918,"mc":[{"id":"1.195503857","rc":[{"atb":[[2.1,2.56]],"id":38247349}],"con":true,"img":false}]}
{"op":"mcm","clk":"5354001013","pt":1646220543330,"mc":[{"id":"1.195503857","rc":[{"atb":[[2.1,7.68]],"id":38247349}],"con":true,"img":false}]}
{"op":"mcm","clk":"5354001067","pt":1646220543706,"mc":[{"id":"1.195503857","rc":[{"atb":[[1.41,4],[1.51,2]],"id":41120152}],"con":true,"img":false}]}
{"op":"mcm","clk":"5354001144","pt":1646220544366,"mc":[{"id":"1.195503857","rc":[{"atl":[[32,0],[34,0],[21,0],[22,0],[23,0],[24,0],[25,0],[26,0],[27,0],[28,0],[29,0],[30,0]],"id":41120152}],"con":true,"img":false}]}
{"op":"mcm","clk":"5354001156","pt":1646220544439,"mc":[{"id":"1.195503857","rc":[{"atl":[[21,2.84]],"id":41120152}],"con":true,"img":false}]}
{"op":"mcm","clk":"5354001211","pt":1646220544807,"mc":[{"id":"1.195503857","rc":[{"atl":[[21,0]],"id":41120152}],"con":true,"img":false}]}
{"op":"mcm","clk":"5354001479","pt":1646220547042,"mc":[{"id":"1.195503857","rc":[{"atb":[[1.41,0]],"id":41120152},{"atb":[[2.1,2.56]],"id":38247349}],"con":true,"img":false}]}
{"op":"mcm","clk":"5354001571","pt":1646220547736,"mc":[{"id":"1.195503857","rc":[{"atb":[[2.1,7.68]],"id":38247349}],"con":true,"img":false}]}
{"op":"mcm","clk":"5354001618","pt":1646220548151,"mc":[{"id":"1.195503857","rc":[{"atb":[[2.1,2.56]],"id":38247349}],"con":true,"img":false}]}
{"op":"mcm","clk":"5354001711","pt":1646220548836,"mc":[{"id":"1.195503857","rc":[{"atb":[[2.1,7.68]],"id":38247349}],"con":true,"img":false}]}
{"op":"mcm","clk":"5354001955","pt":1646220550743,"mc":[{"id":"1.195503857","rc":[{"atb":[[1.03,2.87]],"id":41120152}],"con":true,"img":false}]}
{"op":"mcm","clk":"5354001981","pt":1646220550947,"mc":[{"id":"1.195503857","rc":[{"atb":[[1.03,0.14]],"id":41120152}],"con":true,"img":false}]}
{"op":"mcm","clk":"5354001994","pt":1646220551055,"mc":[{"id":"1.195503857","rc":[{"atb":[[1.4,0]],"id":41120152}],"con":true,"img":false}]}
{"op":"mcm","clk":"5354002005","pt":1646220551156,"mc":[{"id":"1.195503857","rc":[{"atb":[[1.03,0],[1.42,5.63]],"id":41120152}],"con":true,"img":false}]}
{"op":"mcm","clk":"5354002017","pt":1646220551218,"mc":[{"id":"1.195503857","rc":[{"trd":[[1.91,0.14]],"ltp":1.91,"tv":0.14,"id":41120152},{"atb":[[2.1,7.54]],"id":38247349},{"trd":[[2.1,0.13]],"ltp":2.1,"tv":0.13,"id":38247349}],"con":true,"img":false}]}
{"op":"mcm","clk":"5354002047","pt":1646220551425,"mc":[{"id":"1.195503857","rc":[{"atl":[[1.8,2]],"id":41120152}],"con":true,"img":false}]}
{"op":"mcm","clk":"5354002085","pt":1646220551730,"mc":[{"id":"1.195503857","rc":[{"atl":[[1.8,6]],"id":41120152}],"con":true,"img":false}]}
{"op":"mcm","clk":"5354002095","pt":1646220551838,"mc":[{"id":"1.195503857","rc":[{"atb":[[2.4,125.96]],"id":38247349},{"atl":[[2.4,0]],"id":38247349},{"trd":[[2.4,861.89]],"ltp":2.4,"tv":861.89,"id":38247349}],"con":true,"img":false}]}
{"op":"mcm","clk":"5354002120","pt":1646220552041,"mc":[{"id":"1.195503857","rc":[{"atb":[[1.68,0]],"id":41120152},{"trd":[[1.68,11.9]],"ltp":1.68,"tv":11.9,"id":41120152},{"atb":[[2.32,2]],"id":38247349},{"atl":[[2.86,2],[2.84,0]],"id":38247349},{"trd":[[2.48,8.06]],"ltp":2.48,"tv":8.06,"id":38247349}],"con":true,"img":false}]}
{"op":"mcm","clk":"5354002131","pt":1646220552145,"mc":[{"id":"1.195503857","rc":[{"atb":[[2.32,11.48],[2.34,9.4]],"id":38247349}],"con":true,"img":false}]}
{"op":"mcm","clk":"5354002156","pt":1646220552361,"mc":[{"id":"1.195503857","rc":[{"atb":[[2.36,2],[2.32,9.48]],"id":38247349}],"con":true,"img":false}]}
{"op":"mcm","clk":"5354002169","pt":1646220552411,"mc":[{"id":"1.195503857","rc":[{"atl":[[2.86,6]],"id":38247349}],"con":true,"img":false}]}
{"op":"mcm","clk":"5354002224","pt":1646220552826,"mc":[{"id":"1.195503857","rc":[{"atl":[[2.84,5.13]],"id":38247349}],"con":true,"img":false}]}
{"op":"mcm","clk":"5354002346","pt":1646220553765,"mc":[{"id":"1.195503857","rc":[{"atb":[[1.03,2.87]],"id":38247349}],"con":true,"img":false}]}
{"op":"mcm","clk":"5354002375","pt":1646220553924,"mc":[{"id":"1.195503857","rc":[{"atb":[[1.03,0.14]],"id":38247349}],"con":true,"img":false}]}
{"op":"mcm","clk":"5354002394","pt":1646220554128,"mc":[{"id":"1.195503857","rc":[{"atb":[[1.03,0]],"id":38247349}],"con":true,"img":false}]}
{"op":"mcm","clk":"5354002400","pt":1646220554242,"mc":[{"id":"1.195503857","rc":[{"atb":[[1.67,11.76]],"id":41120152},{"trd":[[1.67,0.22]],"ltp":1.67,"tv":0.22,"id":41120152},{"trd":[[2.5,0.14]],"ltp":2.5,"tv":0.14,"id":38247349}],"con":true,"img":false}]}
{"op":"mcm","clk":"5354002411","pt":1646220554345,"mc":[{"id":"1.195503857","rc":[{"atl":[[2.86,2]],"id":38247349}],"con":true,"img":false}]}
{"op":"mcm","clk":"5354002442","pt":1646220554647,"mc":[{"id":"1.195503857","rc":[{"atb":[[1.27,2.03]],"id":38247349}],"con":true,"img":false}]}
{"op":"mcm","clk":"5354002467","pt":1646220554861,"mc":[{"id":"1.195503857","rc":[{"atl":[[2.84,9.64]],"id":38247349}],"con":true,"img":false}]}
{"op":"mcm","clk":"5354002484","pt":1646220554971,"mc":[{"id":"1.195503857","rc":[{"atb":[[1.27,0.02]],"id":38247349}],"con":true,"img":false}]}
{"op":"mcm","clk":"5354002506","pt":1646220555140,"mc":[{"id":"1.195503857","rc":[{"atb":[[1.27,0]],"id":38247349}],"con":true,"img":false}]}
{"op":"mcm","clk":"5354002518","pt":1646220555229,"mc":[{"id":"1.195503857","rc":[{"atb":[[1.67,11.72]],"id":41120152},{"trd":[[1.67,0.26]],"ltp":1.67,"tv":0.26,"id":41120152},{"trd":[[2.5,0.17]],"ltp":2.5,"tv":0.17,"id":38247349}],"con":true,"img":false}]}
{"op":"mcm","clk":"5354002532","pt":1646220555338,"mc":[{"id":"1.195503857","rc":[{"atb":[[1.67,0]],"id":41120152}],"con":true,"img":false}]}
{"op":"mcm","clk":"5354002558","pt":1646220555548,"mc":[{"id":"1.195503857","rc":[{"atb":[[1.43,2],[1.42,0],[1.51,0]],"id":41120152},{"atb":[[2.1,5.12]],"id":38247349}],"con":true,"img":false}]}
{"op":"mcm","clk":"5354002568","pt":1646220555642,"mc":[{"id":"1.195503857","rc":[{"atb":[[1.44,5.63]],"id":41120152},{"atb":[[2.06,2.42]],"id":38247349}],"con":true,"img":false}]}
{"op":"mcm","clk":"5354002578","pt":1646220555750,"mc":[{"id":"1.195503857","rc":[{"atb":[[1.51,4]],"id":41120152}],"con":true,"img":false}]}
{"op":"mcm","clk":"5354002628","pt":1646220556123,"mc":[{"id":"1.195503857","rc":[{"atb":[[1.51,0]],"id":41120152},{"atl":[[2.84,5.13]],"id":38247349}],"con":true,"img":false}]}
{"op":"mcm","clk":"5354002684","pt":1646220556639,"mc":[{"id":"1.195503857","rc":[{"atb":[[1.44,16.89]],"id":41120152}],"con":true,"img":false}]}
{"op":"mcm","clk":"5354002846","pt":1646220557857,"mc":[{"id":"1.195503857","rc":[{"atl":[[2.84,0]],"id":38247349}],"con":true,"img":false}]}
{"op":"mcm","clk":"5354003123","pt":1646220559721,"mc":[{"id":"1.195503857","rc":[{"atl":[[2.86,6]],"id":38247349}],"con":true,"img":false}]}
{"op":"mcm","clk":"5354003211","pt":1646220560349,"mc":[{"id":"1.195503857","rc":[{"atb":[[1.44,5.63]],"id":41120152},{"atl":[[1.8,2]],"id":41120152},{"atb":[[2.1,0]],"id":38247349},{"atl":[[2.86,2]],"id":38247349}],"con":true,"img":false}]}
{"op":"mcm","clk":"5354003275","pt":1646220560716,"mc":[{"id":"1.195503857","rc":[{"atb":[[1.43,0],[1.45,2]],"id":41120152}],"con":true,"img":false}]}
{"op":"mcm","clk":"5354003339","pt":1646220561140,"mc":[{"id":"1.195503857","rc":[{"atb":[[1.45,6]],"id":41120152},{"atl":[[1.8,6]],"id":41120152},{"atb":[[2.4,134.36]],"id":38247349},{"atl":[[2.86,6]],"id":38247349}],"con":true,"img":false}]}
{"op":"mcm","clk":"5354003367","pt":1646220561349,"mc":[{"id":"1.195503857","rc":[{"atb":[[2.36,0],[2.42,2]],"id":38247349}],"con":true,"img":false}]}
{"op":"mcm","clk":"5354003432","pt":1646220561820,"mc":[{"id":"1.195503857","rc":[{"atb":[[2.4,125.96]],"id":38247349}],"con":true,"img":false}]}
{"op":"mcm","clk":"5354003445","pt":1646220561922,"mc":[{"id":"1.195503857","rc":[{"atb":[[2.42,10.4]],"id":38247349}],"con":true,"img":false}]}
{"op":"mcm","clk":"5354003512","pt":1646220562446,"mc":[{"id":"1.195503857","rc":[{"atb":[[2.42,6]],"id":38247349}],"con":true,"img":false}]}
{"op":"mcm","clk":"5354003573","pt":1646220562921,"mc":[{"id":"1.195503857","rc":[{"atl":[[2.84,5.13]],"id":38247349}],"con":true,"img":false}]}
{"op":"mcm","clk":"5354003610","pt":1646220563127,"mc":[{"id":"1.195503857","rc":[{"atb":[[2.42,2]],"id":38247349}],"con":true,"img":false}]}
{"op":"mcm","clk":"5354003628","pt":1646220563238,"mc":[{"id":"1.195503857","rc":[{"atb":[[1.44,0]],"id":41120152},{"atl":[[2.86,2]],"id":38247349}],"con":true,"img":false}]}
{"op":"mcm","clk":"5354003637","pt":1646220563337,"mc":[{"id":"1.195503857","rc":[{"atb":[[1.47,5.63]],"id":41120152}],"con":true,"img":false}]}
{"op":"mcm","clk":"5354003683","pt":1646220563660,"mc":[{"id":"1.195503857","rc":[{"atb":[[1.45,2]],"id":41120152},{"atl":[[2.84,12.76]],"id":38247349}],"con":true,"img":false}]}
{"op":"mcm","clk":"5354003749","pt":1646220564125,"mc":[{"id":"1.195503857","rc":[{"atb":[[1.47,16.89]],"id":41120152}],"con":true,"img":false}]}
{"op":"mcm","clk":"5354003761","pt":1646220564230,"mc":[{"id":"1.195503857","rc":[{"atb":[[1.47,5.63]],"id":41120152},{"atl":[[1.8,2]],"id":41120152},{"atl":[[2.84,5.13]],"id":38247349}],"con":true,"img":false}]}
{"op":"mcm","clk":"5354003855","pt":1646220564960,"mc":[{"id":"1.195503857","rc":[{"atl":[[1.8,6]],"id":41120152},{"atb":[[2.42,6]],"id":38247349},{"atl":[[2.84,11.86]],"id":38247349}],"con":true,"img":false}]}
{"op":"mcm","clk":"5354003863","pt":1646220565062,"mc":[{"id":"1.195503857","rc":[{"atl":[[2.84,6.73]],"id":38247349}],"con":true,"img":false}]}
{"op":"mcm","clk":"5354003907","pt":1646220565433,"mc":[{"id":"1.195503857","rc":[{"atl":[[2.84,0]],"id":38247349}],"con":true,"img":false}]}
{"op":"mcm","clk":"5354003956","pt":1646220565854,"mc":[{"id":"1.195503857","rc":[{"atb":[[1.45,0],[1.48,2]],"id":41120152}],"con":true,"img":false}]}
{"op":"mcm","clk":"5354003967","pt":1646220565955,"mc":[{"id":"1.195503857","rc":[{"atl":[[2.86,6]],"id":38247349}],"con":true,"img":false}]}
{"op":"mcm","clk":"5354004023","pt":1646220566425,"mc":[{"id":"1.195503857","rc":[{"atl":[[1.8,2]],"id":41120152},{"atb":[[2.42,2]],"id":38247349},{"atl":[[2.86,2]],"id":38247349}],"con":true,"img":false}]}
{"op":"mcm","clk":"5354004050","pt":1646220566646,"mc":[{"id":"1.195503857","rc":[{"atb":[[2.36,2],[2.42,0]],"id":38247349},{"atl":[[2.88,2],[2.86,0]],"id":38247349}],"con":true,"img":false}]}
{"op":"mcm","clk":"5354004123","pt":1646220567268,"mc":[{"id":"1.195503857","rc":[{"atl":[[1.8,6]],"id":41120152},{"atb":[[2.4,134.82]],"id":38247349},{"atl":[[2.88,6]],"id":38247349}],"con":true,"img":false}]}
{"op":"mcm","clk":"5354004129","pt":1646220567320,"mc":[{"id":"1.195503857","rc":[{"atb":[[1.47,0]],"id":41120152}],"con":true,"img":false}]}
{"op":"mcm","clk":"5354004147","pt":1646220567431,"mc":[{"id":"1.195503857","rc":[{"atb":[[1.44,5.63],[1.48,0]],"id":41120152}],"con":true,"img":false}]}
{"op":"mcm","clk":"5354004160","pt":1646220567531,"mc":[{"id":"1.195503857","rc":[{"atb":[[1.33,2]],"id":41120152}],"con":true,"img":false}]}
{"op":"mcm","clk":"5354004173","pt":1646220567641,"mc":[{"id":"1.195503857","rc":[{"atb":[[1.45,2],[1.33,0]],"id":41120152}],"con":true,"img":false}]}
{"op":"mcm","clk":"5354004229","pt":1646220568054,"mc":[{"id":"1.195503857","rc":[{"atl":[[2.86,5.09]],"id":38247349}],"con":true,"img":false}]}
{"op":"mcm","clk":"5354004284","pt":1646220568434,"mc":[{"id":"1.195503857","rc":[{"atb":[[2.4,125.96]],"id":38247349},{"atl":[[2.88,2]],"id":38247349}],"con":true,"img":false}]}
{"op":"mcm","clk":"5354004363","pt":1646220569062,"mc":[{"id":"1.195503857","rc":[{"atl":[[2.86,15.27]],"id":38247349}],"con":true,"img":false}]}
{"op":"mcm","clk":"5354004509","pt":1646220570050,"mc":[{"id":"1.195503857","rc":[{"atb":[[1.45,6]],"id":41120152}],"con":true,"img":false}]}
{"op":"mcm","clk":"5354004748","pt":1646220571833,"mc":[{"id":"1.195503857","rc":[{"atl":[[2.88,0],[2.9,2]],"id":38247349}],"con":true,"img":false}]}
{"op":"mcm","clk":"5354004976","pt":1646220573460,"mc":[{"id":"1.195503857","rc":[{"atb":[[1.44,0]],"id":41120152},{"atb":[[2.06,0]],"id":38247349}],"con":true,"img":false}]}
{"op":"mcm","clk":"5354005484","pt":1646220577064,"mc":[{"id":"1.195503857","rc":[{"atl":[[2.9,0],[2.94,2]],"id":38247349}],"con":true,"img":false}]}
{"op":"mcm","clk":"5354005562","pt":1646220577544,"mc":[{"id":"1.195503857","marketDefinition":{"bspMarket":false,"turnInPlayEnabled":false,"persistenceEnabled":false,"marketBaseRate":7.0,"eventId":"31272499","eventTypeId":"4339","numberOfWinners":1,"bettingType":"ODDS","marketType":"MATCH_BET","marketTime":"2022-03-02T11:29:00.000Z","suspendTime":"2022-03-02T11:29:00.000Z","bspReconciled":false,"complete":true,"inPlay":false,"crossMatching":true,"runnersVoidable":false,"numberOfActiveRunners":2,"betDelay":0,"status":"SUSPENDED","runners":[{"status":"ACTIVE","sortPriority":1,"id":38247349,"name":"3. Hearts Thunder"},{"status":"ACTIVE","sortPriority":2,"id":41120152,"name":"8. Rosas Memory"}],"regulators":["MR_INT"],"venue":"Rockhampton","countryCode":"AU","discountAllowed":true,"timezone":"Australia/Queensland","openDate":"2022-03-02T08:28:00.000Z","version":4383007165,"name":"Hearts Thunder v Rosas Memory","eventName":"Rockhampton (AUS) 2nd Mar"},"rc":[],"con":true,"img":false}]}
{"op":"mcm","clk":"5354005562","pt":1646220577544,"mc":[{"id":"1.195503857","rc":[{"atb":[[1.01,0],[1.45,0],[1.02,0],[1.22,0]],"id":41120152},{"atl":[[1.8,0]],"id":41120152},{"atb":[[2.4,0],[2.36,0],[2.32,0],[1.98,0],[2.34,0]],"id":38247349},{"atl":[[2.86,0],[2.94,0]],"id":38247349}],"con":true,"img":false}]}
{"op":"mcm","clk":"5354015050","pt":1646220651349,"mc":[{"id":"1.195503857","rc":[{"trd":[[1.73,0],[1.72,0],[1.67,0],[1.68,0],[1.91,0],[1.42,0]],"ltp":1.73,"tv":0.0,"id":41120152},{"trd":[[2.36,0],[2.4,0],[2.5,0],[2.38,0],[2.52,0],[2.1,0],[2.48,0],[2.76,0]],"ltp":2.36,"tv":0.0,"id":38247349}],"con":true,"img":false}]}
{"op":"mcm","clk":"5354015149","pt":1646220652069,"mc":[{"id":"1.195503857","marketDefinition":{"bspMarket":false,"turnInPlayEnabled":false,"persistenceEnabled":false,"marketBaseRate":7.0,"eventId":"31272499","eventTypeId":"4339","numberOfWinners":1,"bettingType":"ODDS","marketType":"MATCH_BET","marketTime":"2022-03-02T11:29:00.000Z","suspendTime":"2022-03-02T11:29:00.000Z","bspReconciled":false,"complete":true,"inPlay":false,"crossMatching":false,"runnersVoidable":false,"numberOfActiveRunners":0,"betDelay":0,"status":"CLOSED","settledTime":"2022-03-02T11:30:50.000Z","runners":[{"status":"LOSER","sortPriority":1,"id":38247349,"name":"3. Hearts Thunder"},{"status":"WINNER","sortPriority":2,"id":41120152,"name":"8. Rosas Memory"}],"regulators":["MR_INT"],"venue":"Rockhampton","countryCode":"AU","discountAllowed":true,"timezone":"Australia/Queensland","openDate":"2022-03-02T08:28:00.000Z","version":4383011281,"name":"Hearts Thunder v Rosas Memory","eventName":"Rockhampton (AUS) 2nd Mar"},"rc":[],"con":true,"img":false}]}
