{"op":"mcm","clk":"5345904396","pt":1646079078742,"mc":[{"id":"1.195395449","marketDefinition":{"bspMarket":true,"turnInPlayEnabled":false,"persistenceEnabled":false,"marketBaseRate":5.0,"eventId":"31270459","eventTypeId":"4339","numberOfWinners":1,"bettingType":"ODDS","marketType":"WIN","marketTime":"2022-03-01T01:05:00.000Z","suspendTime":"2022-03-01T01:05:00.000Z","bspReconciled":false,"complete":true,"inPlay":false,"crossMatching":false,"runnersVoidable":false,"numberOfActiveRunners":8,"betDelay":0,"status":"OPEN","runners":[{"status":"ACTIVE","sortPriority":1,"id":43066393,"name":"1. Naya Bale"},{"status":"ACTIVE","sortPriority":2,"id":25760990,"name":"2. Darla Bale"},{"status":"ACTIVE","sortPriority":3,"id":37495442,"name":"3. Know Ego"},{"status":"ACTIVE","sortPriority":4,"id":40908100,"name":"4. Not So Simple"},{"status":"ACTIVE","sortPriority":5,"id":40494151,"name":"5. Money Bags"},{"status":"ACTIVE","sortPriority":6,"id":41962160,"name":"6. Opawa Nut"},{"status":"ACTIVE","sortPriority":7,"id":41360966,"name":"7. Sugar Time"},{"status":"ACTIVE","sortPriority":8,"id":40995914,"name":"8. Goldstar Butters"}],"regulators":["MR_INT"],"venue":"Addington","countryCode":"NZ","discountAllowed":false,"timezone":"NZ","openDate":"2022-02-28T23:02:00.000Z","version":4380660685,"name":"R8 520m C2","eventName":"Addington (NZL) 1st Mar"},"rc":[],"con":true,"img":false}]}
{"op":"mcm","clk":"5345904629","pt":1646079080740,"mc":[{"id":"1.195395449","marketDefinition":{"bspMarket":true,"turnInPlayEnabled":false,"persistenceEnabled":false,"marketBaseRate":5.0,"eventId":"31270459","eventTypeId":"4339","numberOfWinners":1,"bettingType":"ODDS","marketType":"WIN","marketTime":"2022-03-01T01:05:00.000Z","suspendTime":"2022-03-01T01:05:00.000Z","bspReconciled":false,"complete":true,"inPlay":false,"crossMatching":false,"runnersVoidable":false,"numberOfActiveRunners":8,"betDelay":0,"status":"OPEN","runners":[{"status":"ACTIVE","sortPriority":1,"id":43066393,"name":"1. Naya Bale"},{"status":"ACTIVE","sortPriority":2,"id":25760990,"name":"2. Darla Bale"},{"status":"ACTIVE","sortPriority":3,"id":37495442,"name":"3. Know Ego"},{"status":"ACTIVE","sortPriority":4,"id":40908100,"name":"4. Not So Simple"},{"status":"ACTIVE","sortPriority":5,"id":40494151,"name":"5. Money Bags"},{"status":"ACTIVE","sortPriority":6,"id":41962160,"name":"6. Opawa Nut"},{"status":"ACTIVE","sortPriority":7,"id":41360966,"name":"7. Sugar Time"},{"status":"ACTIVE","sortPriority":8,"id":40995914,"name":"8. Goldstar Butters"}],"regulators":["MR_INT"],"venue":"Addington","countryCode":"NZ","discountAllowed":true,"timezone":"NZ","openDate":"2022-02-28T23:02:00.000Z","version":4380660685,"name":"R8 520m C2","eventName":"Addington (NZL) 1st Mar"},"rc":[],"con":true,"img":false}]}
{"op":"mcm","clk":"5346131645","pt":1646081590850,"mc":[{"id":"1.195395449","rc":[{"atb":[[18,4.77],[21,2.02],[10.5,17.09],[15.5,8.4]],"id":37495442},{"atl":[[150,0.88],[300,0.66],[200,0.66],[250,0.79]],"id":37495442},{"spn":85.5,"spf":"NaN","id":37495442},{"atb":[[18,4.77],[21,2.02],[10.5,17.09],[15.5,8.4]],"id":40995914},{"atl":[[150,0.88],[300,0.66],[200,0.66],[250,0.79]],"id":40995914},{"spn":85.5,"spf":"NaN","id":40995914},{"atb":[[17.5,4.92],[20,2.13],[10,18.04],[15,8.69]],"id":41360966},{"atl":[[150,0.88],[300,0.66],[200,0.66],[250,0.79]],"id":41360966},{"spn":85.0,"spf":"NaN","id":41360966},{"atb":[[6.4,30.07],[11,4.05],[8.4,16.46],[9.4,9.66]],"id":41962160},{"atl":[[80,1.67],[160,1.25],[55,2.45],[110,1.81]],"id":41962160},{"spn":33.0,"spf":"NaN","id":41962160},{"atb":[[6.4,30.07],[11,4.05],[8.4,16.46],[9.4,9.66]],"id":40494151},{"atl":[[80,1.67],[160,1.25],[55,2.45],[110,1.81]],"id":40494151},{"spn":33.0,"spf":"NaN","id":40494151},{"atb":[[18,4.77],[21,2.02],[10.5,17.09],[15.5,8.4]],"id":25760990},{"atl":[[150,0.88],[300,0.66],[200,0.66],[250,0.79]],"id":25760990},{"spn":85.5,"spf":"NaN","id":25760990},{"atb":[[1.4,202.98],[1.45,90.21],[1.25,649.56],[1.35,347.98]],"id":43066393},{"atl":[[2.86,106.69],[2.66,79.69],[2.96,101.24],[2.76,75.16]],"id":43066393},{"spn":2.05,"spf":"NaN","id":43066393},{"atb":[[3.6,46.84],[3.85,28.48],[3.1,77.33],[4.2,12.68]],"id":40908100},{"atl":[[17.5,12.02],[20,10.44],[12.5,11.5],[15,9.45]],"id":40908100},{"spn":8.35,"spf":"NaN","id":40908100}],"con":true,"img":false}]}
{"op":"mcm","clk":"5346132698","pt":1646081605530,"mc":[{"id":"1.195395449","rc":[{"atb":[[18,0],[21,0],[10.5,0],[15.5,0]],"id":37495442},{"atl":[[150,0],[300,0],[200,0],[250,0]],"id":37495442},{"atb":[[18,0],[21,0],[10.5,0],[15.5,0]],"id":40995914},{"atl":[[150,0],[300,0],[200,0],[250,0]],"id":40995914},{"atb":[[17.5,0],[20,0],[10,0],[15,0]],"id":41360966},{"atl":[[150,0],[300,0],[200,0],[250,0]],"id":41360966},{"atb":[[6.4,0],[11,0],[8.4,0],[9.4,0]],"id":41962160},{"atl":[[80,0],[160,0],[55,0],[110,0]],"id":41962160},{"atb":[[6.4,0],[11,0],[8.4,0],[9.4,0]],"id":40494151},{"atl":[[80,0],[160,0],[55,0],[110,0]],"id":40494151},{"atb":[[18,0],[21,0],[10.5,0],[15.5,0]],"id":25760990},{"atl":[[150,0],[300,0],[200,0],[250,0]],"id":25760990},{"atb":[[1.4,0],[1.45,0],[1.25,0],[1.35,0]],"id":43066393},{"atl":[[2.86,0],[2.66,0],[2.96,0],[2.76,0]],"id":43066393},{"atb":[[3.6,0],[3.85,0],[3.1,0],[4.2,0]],"id":40908100},{"atl":[[17.5,0],[20,0],[12.5,0],[15,0]],"id":40908100}],"con":true,"img":false}]}
{"op":"mcm","clk":"5346133741","pt":1646081621322,"mc":[{"id":"1.195395449","rc":[{"atb":[[18,4.77],[21,2.02],[10.5,17.09],[15.5,8.4]],"id":37495442},{"atl":[[150,0.88],[300,0.66],[200,0.66],[250,0.79]],"id":37495442},{"atb":[[18,4.77],[21,2.02],[10.5,17.09],[15.5,8.4]],"id":40995914},{"atl":[[150,0.88],[300,0.66],[200,0.66],[250,0.79]],"id":40995914},{"atb":[[17.5,4.92],[20,2.13],[10,18.04],[15,8.69]],"id":41360966},{"atl":[[150,0.88],[300,0.66],[200,0.66],[250,0.79]],"id":41360966},{"atb":[[6.4,30.07],[11,4.05],[8.4,16.46],[9.4,9.66]],"id":41962160},{"atl":[[80,1.67],[160,1.25],[55,2.45],[110,1.81]],"id":41962160},{"atb":[[6.4,30.07],[11,4.05],[8.4,16.46],[9.4,9.66]],"id":40494151},{"atl":[[80,1.67],[160,1.25],[55,2.45],[110,1.81]],"id":40494151},{"atb":[[18,4.77],[21,2.02],[10.5,17.09],[15.5,8.4]],"id":25760990},{"atl":[[150,0.88],[300,0.66],[200,0.66],[250,0.79]],"id":25760990},{"atb":[[3.6,46.84],[3.85,28.48],[3.1,77.33],[4.2,12.68]],"id":40908100},{"atl":[[17.5,12.02],[20,10.44],[12.5,11.5],[15,9.45]],"id":40908100},{"atb":[[1.4,202.98],[1.45,90.21],[1.25,649.56],[1.35,347.98]],"id":43066393},{"atl":[[2.86,106.69],[2.66,79.69],[2.96,101.24],[2.76,75.16]],"id":43066393}],"con":true,"img":false}]}
{"op":"mcm","clk":"5346134796","pt":1646081637702,"mc":[{"id":"1.195395449","rc":[{"atb":[[18,0],[21,0],[10.5,0],[15.5,0]],"id":37495442},{"atl":[[150,0],[300,0],[200,0],[250,0]],"id":37495442},{"atb":[[18,0],[21,0],[10.5,0],[15.5,0]],"id":40995914},{"atl":[[150,0],[300,0],[200,0],[250,0]],"id":40995914},{"atb":[[17.5,0],[20,0],[10,0],[15,0]],"id":41360966},{"atl":[[150,0],[300,0],[200,0],[250,0]],"id":41360966},{"atb":[[6.4,0],[11,0],[8.4,0],[9.4,0]],"id":41962160},{"atl":[[80,0],[160,0],[55,0],[110,0]],"id":41962160},{"atb":[[6.4,0],[11,0],[8.4,0],[9.4,0]],"id":40494151},{"atl":[[80,0],[160,0],[55,0],[110,0]],"id":40494151},{"atb":[[18,0],[21,0],[10.5,0],[15.5,0]],"id":25760990},{"atl":[[150,0],[300,0],[200,0],[250,0]],"id":25760990},{"atb":[[3.6,0],[3.85,0],[3.1,0],[4.2,0]],"id":40908100},{"atl":[[17.5,0],[20,0],[12.5,0],[15,0]],"id":40908100},{"atb":[[1.4,0],[1.45,0],[1.25,0],[1.35,0]],"id":43066393},{"atl":[[2.86,0],[2.66,0],[2.96,0],[2.76,0]],"id":43066393}],"con":true,"img":false}]}
{"op":"mcm","clk":"5346135981","pt":1646081656756,"mc":[{"id":"1.195395449","rc":[{"atb":[[18,4.77],[21,2.02],[10.5,17.09],[15.5,8.4]],"id":40995914},{"atl":[[150,0.88],[300,0.66],[200,0.66],[250,0.79]],"id":40995914},{"atb":[[18,4.77],[21,2.02],[10.5,17.09],[15.5,8.4]],"id":37495442},{"atl":[[150,0.88],[300,0.66],[200,0.66],[250,0.79]],"id":37495442},{"atb":[[17.5,4.92],[20,2.13],[10,18.04],[15,8.69]],"id":41360966},{"atl":[[150,0.88],[300,0.66],[200,0.66],[250,0.79]],"id":41360966},{"atb":[[6.4,30.07],[11,4.05],[8.4,16.46],[9.4,9.66]],"id":41962160},{"atl":[[80,1.67],[160,1.25],[55,2.45],[110,1.81]],"id":41962160},{"atb":[[6.4,30.07],[11,4.05],[8.4,16.46],[9.4,9.66]],"id":40494151},{"atl":[[80,1.67],[160,1.25],[55,2.45],[110,1.81]],"id":40494151},{"atb":[[18,4.77],[21,2.02],[10.5,17.09],[15.5,8.4]],"id":25760990},{"atl":[[150,0.88],[300,0.66],[200,0.66],[250,0.79]],"id":25760990},{"atb":[[1.4,202.98],[1.45,90.21],[1.25,649.56],[1.35,347.98]],"id":43066393},{"atl":[[2.86,106.69],[2.66,79.69],[2.96,101.24],[2.76,75.16]],"id":43066393},{"atb":[[3.6,46.84],[3.85,28.48],[3.1,77.33],[4.2,12.68]],"id":40908100},{"atl":[[17.5,12.02],[20,10.44],[12.5,11.5],[15,9.45]],"id":40908100}],"con":true,"img":false}]}
{"op":"mcm","clk":"5346138703","pt":1646081695695,"mc":[{"id":"1.195395449","rc":[{"atb":[[18,0],[21,0],[10.5,0],[15.5,0]],"id":37495442},{"atl":[[150,0],[300,0],[200,0],[250,0]],"id":37495442},{"atb":[[18,0],[21,0],[10.5,0]],"id":40995914},{"atl":[[300,0]],"id":40995914},{"atb":[[17.5,0],[20,0],[10,0],[15,0]],"id":41360966},{"atl":[[150,0],[300,0],[200,0],[250,0]],"id":41360966},{"atb":[[6.4,0],[11,0],[8.4,0],[9.4,0]],"id":41962160},{"atl":[[80,0],[160,0],[55,0],[110,0]],"id":41962160},{"atb":[[6.4,0],[11,0],[8.4,0],[9.4,0]],"id":40494151},{"atl":[[80,0],[160,0],[55,0],[110,0]],"id":40494151},{"atb":[[18,0],[21,0],[10.5,0],[15.5,0]],"id":25760990},{"atl":[[150,0],[300,0],[200,0],[250,0]],"id":25760990},{"atb":[[1.4,0],[1.45,0],[1.25,0],[1.35,0]],"id":43066393},{"atl":[[2.86,0],[2.66,0],[2.96,0],[2.76,0]],"id":43066393},{"atb":[[3.6,0],[3.85,0],[3.1,0],[4.2,0]],"id":40908100},{"atl":[[17.5,0],[20,0],[12.5,0],[15,0]],"id":40908100}],"con":true,"img":false}]}
{"op":"mcm","clk":"5346138712","pt":1646081695747,"mc":[{"id":"1.195395449","rc":[{"atb":[[15.5,0]],"id":40995914},{"atl":[[150,0],[200,0],[250,0]],"id":40995914}],"con":true,"img":false}]}
{"op":"mcm","clk":"5346140304","pt":1646081718873,"mc":[{"id":"1.195395449","rc":[{"atb":[[18,4.77],[21,2.02],[10.5,17.09],[15.5,8.4]],"id":40995914},{"atl":[[150,0.88],[300,0.66],[200,0.66],[250,0.79]],"id":40995914},{"atb":[[18,4.77],[21,2.02],[10.5,17.09],[15.5,8.4]],"id":37495442},{"atl":[[150,0.88],[300,0.66],[200,0.66],[250,0.79]],"id":37495442},{"atb":[[17.5,4.92],[20,2.13],[10,18.04],[15,8.69]],"id":41360966},{"atl":[[150,0.88],[300,0.66],[200,0.66],[250,0.79]],"id":41360966},{"atb":[[6.4,30.07],[11,4.05],[8.4,16.46],[9.4,9.66]],"id":41962160},{"atl":[[80,1.67],[160,1.25],[55,2.45],[110,1.81]],"id":41962160},{"atb":[[6.4,30.07],[11,4.05],[8.4,16.46],[9.4,9.66]],"id":40494151},{"atl":[[80,1.67],[160,1.25],[55,2.45],[110,1.81]],"id":40494151},{"atb":[[18,4.77],[21,2.02],[10.5,17.09],[15.5,8.4]],"id":25760990},{"atl":[[150,0.88],[300,0.66],[200,0.66],[250,0.79]],"id":25760990},{"atb":[[1.4,202.98],[1.45,90.21],[1.25,649.56],[1.35,347.98]],"id":43066393},{"atl":[[2.86,106.69],[2.66,79.69],[2.96,101.24],[2.76,75.16]],"id":43066393},{"atb":[[3.6,46.84],[3.85,28.48],[3.1,77.33],[4.2,12.68]],"id":40908100},{"atl":[[17.5,12.02],[20,10.44],[12.5,11.5],[15,9.45]],"id":40908100}],"con":true,"img":false}]}
{"op":"mcm","clk":"5346223570","pt":1646082745662,"mc":[{"id":"1.195395449","rc":[{"atb":[[18,0],[21,0],[10.5,0],[15.5,0]],"id":37495442},{"atl":[[150,0],[300,0],[200,0],[250,0]],"id":37495442},{"spn":"NaN","spf":"NaN","id":37495442},{"atb":[[18,0],[21,0],[10.5,0],[15.5,0]],"id":40995914},{"atl":[[150,0],[300,0],[200,0],[250,0]],"id":40995914},{"spn":"NaN","spf":"NaN","id":40995914},{"atb":[[17.5,0],[20,0],[10,0],[15,0]],"id":41360966},{"atl":[[150,0],[300,0],[200,0],[250,0]],"id":41360966},{"spn":"NaN","spf":"NaN","id":41360966},{"atb":[[6.4,0],[11,0],[8.4,0],[9.4,0]],"id":41962160},{"atl":[[80,0],[160,0],[55,0],[110,0]],"id":41962160},{"spn":"NaN","spf":"NaN","id":41962160},{"atb":[[6.4,0],[11,0],[8.4,0],[9.4,0]],"id":40494151},{"atl":[[80,0],[160,0],[55,0],[110,0]],"id":40494151},{"spn":"NaN","spf":"NaN","id":40494151},{"atb":[[18,0],[21,0],[10.5,0],[15.5,0]],"id":25760990},{"atl":[[150,0],[300,0],[200,0],[250,0]],"id":25760990},{"spn":"NaN","spf":"NaN","id":25760990},{"atb":[[1.4,0],[1.45,0],[1.25,0],[1.35,0]],"id":43066393},{"atl":[[2.86,0],[2.66,0],[2.96,0],[2.76,0]],"id":43066393},{"spn":"NaN","spf":"NaN","id":43066393},{"atb":[[3.6,0],[3.85,0],[3.1,0],[4.2,0]],"id":40908100},{"atl":[[17.5,0],[20,0],[12.5,0],[15,0]],"id":40908100},{"spn":"NaN","spf":"NaN","id":40908100}],"con":true,"img":false}]}
{"op":"mcm","clk":"5346225933","pt":1646082773230,"mc":[{"id":"1.195395449","rc":[{"atb":[[18,4.77],[21,2.02],[10.5,17.09],[15.5,8.4]],"id":37495442},{"atl":[[150,0.88],[300,0.66],[200,0.66],[250,0.79]],"id":37495442},{"atb":[[18,4.77],[21,2.02],[10.5,17.09],[15.5,8.4]],"id":40995914},{"atl":[[150,0.88],[300,0.66],[200,0.66],[250,0.79]],"id":40995914},{"atb":[[17.5,4.92],[20,2.13],[10,18.04],[15,8.69]],"id":41360966},{"atl":[[150,0.88],[300,0.66],[200,0.66],[250,0.79]],"id":41360966},{"atb":[[6.4,30.07],[11,4.05],[8.4,16.46],[9.4,9.66]],"id":41962160},{"atl":[[80,1.67],[160,1.25],[55,2.45],[110,1.81]],"id":41962160},{"atb":[[6.4,30.07],[11,4.05],[8.4,16.46],[9.4,9.66]],"id":40494151},{"atl":[[80,1.67],[160,1.25],[55,2.45],[110,1.81]],"id":40494151},{"atb":[[18,4.77],[21,2.02],[10.5,17.09],[15.5,8.4]],"id":25760990},{"atl":[[150,0.88],[300,0.66],[200,0.66],[250,0.79]],"id":25760990},{"atb":[[1.4,202.98],[1.45,90.21],[1.25,649.56],[1.35,347.98]],"id":43066393},{"atl":[[2.86,106.69],[2.66,79.69],[2.96,101.24],[2.76,75.16]],"id":43066393},{"atb":[[3.6,46.84],[3.85,28.48],[3.1,77.33],[4.2,12.68]],"id":40908100},{"atl":[[17.5,12.02],[20,10.44],[12.5,11.5],[15,9.45]],"id":40908100}],"con":true,"img":false}]}
{"op":"mcm","clk":"5346253005","pt":1646083002681,"mc":[{"id":"1.195395449","marketDefinition":{"bspMarket":true,"turnInPlayEnabled":false,"persistenceEnabled":false,"marketBaseRate":5.0,"eventId":"31270459","eventTypeId":"4339","numberOfWinners":1,"bettingType":"ODDS","marketType":"WIN","marketTime":"2022-03-01T01:05:00.000Z","suspendTime":"2022-03-01T01:05:00.000Z","bspReconciled":false,"complete":true,"inPlay":false,"crossMatching":false,"runnersVoidable":false,"numberOfActiveRunners":8,"betDelay":0,"status":"OPEN","runners":[{"status":"ACTIVE","sortPriority":1,"id":43066393,"name":"1. Naya Bale"},{"status":"ACTIVE","sortPriority":2,"id":25760990,"name":"2. Darla Bale"},{"status":"ACTIVE","sortPriority":3,"id":37495442,"name":"3. Know Ego"},{"status":"ACTIVE","sortPriority":4,"id":40908100,"name":"4. Not So Simple"},{"status":"ACTIVE","sortPriority":5,"id":40494151,"name":"5. Money Bags"},{"status":"ACTIVE","sortPriority":6,"id":41962160,"name":"6. Opawa Nut"},{"status":"ACTIVE","sortPriority":7,"id":41360966,"name":"7. Sugar Time"},{"status":"ACTIVE","sortPriority":8,"id":40995914,"name":"8. Goldstar Butters"}],"regulators":["MR_INT"],"venue":"Addington","countryCode":"NZ","discountAllowed":true,"timezone":"NZ","openDate":"2022-02-28T23:02:00.000Z","version":4380660685,"name":"R8 520m C2","eventName":"Addington (NZL) 1st Mar"},"rc":[{"atb":[[18,4.77],[21,2.02],[10.5,17.09],[15.5,8.4]],"id":40995914},{"atl":[[150,0.88],[300,0.66],[200,0.66],[250,0.79]],"id":40995914},{"spn":85.5,"spf":"NaN","id":40995914},{"atb":[[18,4.77],[21,2.02],[10.5,17.09],[15.5,8.4]],"id":37495442},{"atl":[[150,0.88],[300,0.66],[200,0.66],[250,0.79]],"id":37495442},{"spn":85.5,"spf":"NaN","id":37495442},{"atb":[[17.5,4.92],[20,2.13],[10,18.04],[15,8.69]],"id":41360966},{"atl":[[150,0.88],[300,0.66],[200,0.66],[250,0.79]],"id":41360966},{"spn":85.0,"spf":"NaN","id":41360966},{"atb":[[6.4,30.07],[11,4.05],[8.4,16.46],[9.4,9.66]],"id":41962160},{"atl":[[80,1.67],[160,1.25],[55,2.45],[110,1.81]],"id":41962160},{"spn":33.0,"spf":"NaN","id":41962160},{"atb":[[6.4,30.07],[11,4.05],[8.4,16.46],[9.4,9.66]],"id":40494151},{"atl":[[80,1.67],[160,1.25],[55,2.45],[110,1.81]],"id":40494151},{"spn":33.0,"spf":"NaN","id":40494151},{"atb":[[18,4.77],[21,2.02],[10.5,17.09],[15.5,8.4]],"id":25760990},{"atl":[[150,0.88],[300,0.66],[200,0.66],[250,0.79]],"id":25760990},{"spn":85.5,"spf":"NaN","id":25760990},{"atb":[[3.6,46.84],[3.85,28.48],[3.1,77.33],[4.2,12.68]],"id":40908100},{"atl":[[17.5,12.02],[20,10.44],[12.5,11.5],[15,9.45]],"id":40908100},{"spn":8.35,"spf":"NaN","id":40908100},{"atb":[[1.4,202.98],[1.45,90.21],[1.25,649.56],[1.35,347.98]],"id":43066393},{"atl":[[2.86,106.69],[2.66,79.69],[2.96,101.24],[2.76,75.16]],"id":43066393},{"spn":2.05,"spf":"NaN","id":43066393}],"con":true,"img":true}]}
{"op":"mcm","clk":"5346418745","pt":1646085864996,"mc":[{"id":"1.195395449","rc":[{"atb":[[18,4.77],[21,2.02],[10.5,17.09],[15.5,8.39]],"id":40995914},{"atl":[[150,0.88],[300,0.66],[200,0.66],[250,0.79]],"id":40995914},{"spn":85.5,"spf":"NaN","id":40995914},{"atb":[[18,4.77],[21,2.02],[10.5,17.09],[15.5,8.39]],"id":37495442},{"atl":[[150,0.88],[300,0.66],[200,0.66],[250,0.79]],"id":37495442},{"spn":85.5,"spf":"NaN","id":37495442},{"atb":[[17.5,4.91],[20,2.13],[10,18.03],[15,8.69]],"id":41360966},{"atl":[[150,0.88],[300,0.66],[200,0.66],[250,0.79]],"id":41360966},{"spn":85.0,"spf":"NaN","id":41360966},{"atb":[[6.4,30.06],[11,4.05],[8.4,16.45],[9.4,9.66]],"id":41962160},{"atl":[[80,1.67],[160,1.25],[55,2.45],[110,1.81]],"id":41962160},{"spn":33.0,"spf":"NaN","id":41962160},{"atb":[[6.4,30.06],[11,4.05],[8.4,16.45],[9.4,9.66]],"id":40494151},{"atl":[[80,1.67],[160,1.25],[55,2.45],[110,1.81]],"id":40494151},{"spn":33.0,"spf":"NaN","id":40494151},{"atb":[[18,4.77],[21,2.02],[10.5,17.09],[15.5,8.39]],"id":25760990},{"atl":[[150,0.88],[300,0.66],[200,0.66],[250,0.79]],"id":25760990},{"spn":85.5,"spf":"NaN","id":25760990},{"atb":[[3.6,46.83],[3.85,28.48],[3.1,77.31],[4.2,12.68]],"id":40908100},{"atl":[[17.5,12.02],[20,10.44],[12.5,11.5],[15,9.44]],"id":40908100},{"spn":8.35,"spf":"NaN","id":40908100},{"atb":[[1.4,202.95],[1.45,90.2],[1.25,649.45],[1.35,347.92]],"id":43066393},{"atl":[[2.86,106.67],[2.38,10.82],[2.66,79.68],[2.96,101.22],[2.76,75.15]],"id":43066393},{"spn":1.91,"spf":"NaN","id":43066393}],"con":true,"img":false}]}
{"op":"mcm","clk":"5346426188","pt":1646086073665,"mc":[{"id":"1.195395449","rc":[{"atb":[[18,0],[21,0],[10.5,0],[15.5,0]],"id":40995914},{"atl":[[150,0],[300,0],[200,0],[250,0]],"id":40995914},{"spn":"NaN","spf":"NaN","id":40995914},{"atb":[[18,0],[21,0],[10.5,0],[15.5,0]],"id":37495442},{"atl":[[150,0],[300,0],[200,0],[250,0]],"id":37495442},{"spn":"NaN","spf":"NaN","id":37495442},{"atb":[[17.5,0],[20,0],[10,0],[15,0]],"id":41360966},{"atl":[[150,0],[300,0],[200,0],[250,0]],"id":41360966},{"spn":"NaN","spf":"NaN","id":41360966},{"atb":[[6.4,0],[11,0],[8.4,0],[9.4,0]],"id":41962160},{"atl":[[80,0],[160,0],[55,0],[110,0]],"id":41962160},{"spn":"NaN","spf":"NaN","id":41962160},{"atb":[[6.4,0],[11,0],[8.4,0],[9.4,0]],"id":40494151},{"atl":[[80,0],[160,0],[55,0],[110,0]],"id":40494151},{"spn":"NaN","spf":"NaN","id":40494151},{"atb":[[18,0],[21,0],[10.5,0],[15.5,0]],"id":25760990},{"atl":[[150,0],[300,0],[200,0],[250,0]],"id":25760990},{"spn":"NaN","spf":"NaN","id":25760990},{"atb":[[1.4,0],[1.45,0],[1.25,0],[1.35,0]],"id":43066393},{"atl":[[2.86,0],[2.66,0],[2.96,0],[2.76,0]],"id":43066393},{"spn":1.0,"spf":"NaN","id":43066393},{"atb":[[3.6,0],[3.85,0],[3.1,0],[4.2,0]],"id":40908100},{"atl":[[17.5,0],[20,0],[12.5,0],[15,0]],"id":40908100},{"spn":"NaN","spf":"NaN","id":40908100}],"con":true,"img":false}]}
{"op":"mcm","clk":"5346426617","pt":1646086084569,"mc":[{"id":"1.195395449","rc":[{"atb":[[16.5,7.85],[19,4.5],[23,1.84],[11.5,15.46]],"id":37495442},{"atl":[[260,0.76],[310,0.64],[160,0.83],[210,0.63]],"id":37495442},{"atb":[[18,4.77],[21,2.02],[10.5,17.09],[15.5,8.39]],"id":40995914},{"atl":[[150,0.88],[300,0.66],[200,0.66],[250,0.79]],"id":40995914},{"atb":[[16.5,7.85],[19,4.5],[23,1.84],[11.5,15.46]],"id":41360966},{"atl":[[260,0.76],[310,0.64],[160,0.83],[210,0.63]],"id":41360966},{"atb":[[12,3.69],[6.8,27.99],[9.8,9.22],[8.8,15.61]],"id":41962160},{"atl":[[70,1.91],[140,1.42],[95,1.4],[190,1.04]],"id":41962160},{"atb":[[12,3.69],[6.8,27.99],[9.8,9.22],[8.8,15.61]],"id":40494151},{"atl":[[70,1.91],[140,1.42],[95,1.4],[190,1.04]],"id":40494151},{"atb":[[16.5,7.85],[19,4.5],[23,1.84],[11.5,15.46]],"id":25760990},{"atl":[[260,0.76],[310,0.64],[160,0.83],[210,0.63]],"id":25760990},{"atb":[[3.6,46.83],[3.85,28.48],[3.1,77.31],[4.2,12.68]],"id":40908100},{"atl":[[17.5,12.02],[20,10.44],[12.5,11.5],[15,9.44]],"id":40908100},{"atb":[[1.25,487.09],[1.15,1082.42],[1.3,270.6],[1.35,115.97]],"id":43066393},{"atl":[[2.54,85.89],[2.74,114.02],[2.64,80.65],[2.84,107.83]],"id":43066393}],"con":true,"img":false}]}
{"op":"mcm","clk":"5346429419","pt":1646086162100,"mc":[{"id":"1.195395449","rc":[{"spn":85.5,"spf":"NaN","id":40995914},{"spn":91.5,"spf":"NaN","id":37495442},{"atb":[[16.5,0],[19,0],[23,0],[11.5,0]],"id":41360966},{"atl":[[260,0],[310,0],[160,0],[210,0]],"id":41360966},{"atb":[[12,0],[6.8,0],[9.8,0],[8.8,0]],"id":41962160},{"atl":[[70,0],[140,0],[95,0],[190,0]],"id":41962160},{"spn":41.0,"spf":"NaN","id":40494151},{"spn":91.5,"spf":"NaN","id":25760990},{"atb":[[1.25,0],[1.15,0],[1.3,0],[1.35,0]],"id":43066393},{"atl":[[2.54,0],[2.74,0],[2.64,0],[2.84,0]],"id":43066393},{"spn":8.35,"spf":"NaN","id":40908100}],"con":true,"img":false}]}
{"op":"mcm","clk":"5346429715","pt":1646086168572,"mc":[{"id":"1.195395449","rc":[{"atb":[[18,4.77],[21,2.02],[10.5,17.09],[15.5,8.39]],"id":41360966},{"atl":[[150,0.88],[300,0.66],[200,0.66],[250,0.79]],"id":41360966},{"atb":[[12,3.69],[6.8,27.99],[9.8,9.22],[8.8,15.61]],"id":41962160},{"atl":[[70,1.91],[140,1.42],[95,1.4],[190,1.04]],"id":41962160},{"atb":[[1.25,487.09],[1.15,1082.42],[1.3,270.6],[1.35,115.97]],"id":43066393},{"atl":[[2.54,85.89],[2.74,114.02],[2.64,80.65],[2.84,107.83]],"id":43066393}],"con":true,"img":false}]}
{"op":"mcm","clk":"5346431801","pt":1646086222846,"mc":[{"id":"1.195395449","rc":[{"atb":[[16.5,0],[19,0],[23,0],[11.5,0]],"id":37495442},{"atl":[[260,0],[310,0],[160,0],[210,0]],"id":37495442},{"spn":"NaN","spf":"NaN","id":37495442},{"spn":85.5,"spf":"NaN","id":41360966},{"spn":41.0,"spf":"NaN","id":41962160},{"spn":1.86,"spf":"NaN","id":43066393}],"con":true,"img":false}]}
{"op":"mcm","clk":"5346432170","pt":1646086230379,"mc":[{"id":"1.195395449","rc":[{"atb":[[16.5,7.85],[19,4.5],[23,1.84],[11.5,15.46]],"id":37495442},{"atl":[[260,0.76],[310,0.64],[160,0.83],[210,0.63]],"id":37495442}],"con":true,"img":false}]}
{"op":"mcm","clk":"5346433294","pt":1646086253622,"mc":[{"id":"1.195395449","rc":[{"atb":[[16.5,0],[19,0],[23,0],[11.5,0]],"id":37495442},{"atl":[[260,0],[310,0],[160,0],[210,0]],"id":37495442}],"con":true,"img":false}]}
{"op":"mcm","clk":"5346433716","pt":1646086264498,"mc":[{"id":"1.195395449","rc":[{"atb":[[16.5,7.85],[19,4.5],[23,1.84],[11.5,15.46]],"id":37495442},{"atl":[[260,0.76],[310,0.64],[160,0.83],[210,0.63]],"id":37495442}],"con":true,"img":false}]}
{"op":"mcm","clk":"5346483784","pt":1646087923220,"mc":[{"id":"1.195395449","rc":[{"spn":91.5,"spf":"NaN","id":37495442},{"atb":[[1.37,20.14]],"id":43066393},{"spn":1.87,"spf":"NaN","id":43066393},{"atb":[[3.9,2.57]],"id":40908100}],"con":true,"img":false}]}
{"op":"mcm","clk":"5346484765","pt":1646087962597,"mc":[{"id":"1.195395449","rc":[{"atb":[[1.37,42.74]],"id":43066393}],"con":true,"img":false}]}
{"op":"mcm","clk":"5346484768","pt":1646087962702,"mc":[{"id":"1.195395449","rc":[{"atb":[[3.9,5.45]],"id":40908100}],"con":true,"img":false}]}
{"op":"mcm","clk":"5346484883","pt":1646087966607,"mc":[{"id":"1.195395449","marketDefinition":{"bspMarket":true,"turnInPlayEnabled":false,"persistenceEnabled":false,"marketBaseRate":5.0,"eventId":"31270459","eventTypeId":"4339","numberOfWinners":1,"bettingType":"ODDS","marketType":"WIN","marketTime":"2022-03-01T01:05:00.000Z","suspendTime":"2022-03-01T01:05:00.000Z","bspReconciled":false,"complete":true,"inPlay":false,"crossMatching":true,"runnersVoidable":false,"numberOfActiveRunners":8,"betDelay":0,"status":"OPEN","runners":[{"status":"ACTIVE","sortPriority":1,"id":43066393,"name":"1. Naya Bale"},{"status":"ACTIVE","sortPriority":2,"id":25760990,"name":"2. Darla Bale"},{"status":"ACTIVE","sortPriority":3,"id":37495442,"name":"3. Know Ego"},{"status":"ACTIVE","sortPriority":4,"id":40908100,"name":"4. Not So Simple"},{"status":"ACTIVE","sortPriority":5,"id":40494151,"name":"5. Money Bags"},{"status":"ACTIVE","sortPriority":6,"id":41962160,"name":"6. Opawa Nut"},{"status":"ACTIVE","sortPriority":7,"id":41360966,"name":"7. Sugar Time"},{"status":"ACTIVE","sortPriority":8,"id":40995914,"name":"8. Goldstar Butters"}],"regulators":["MR_INT"],"venue":"Addington","countryCode":"NZ","discountAllowed":true,"timezone":"NZ","openDate":"2022-02-28T23:02:00.000Z","version":4380660685,"name":"R8 520m C2","eventName":"Addington (NZL) 1st Mar"},"rc":[],"con":true,"img":false}]}
{"op":"mcm","clk":"5346527252","pt":1646089202297,"mc":[{"id":"1.195395449","rc":[{"atl":[[2.04,4.05]],"id":43066393},{"spn":1.7,"spf":"NaN","id":43066393}],"con":true,"img":false}]}
{"op":"mcm","clk":"5346528074","pt":1646089226838,"mc":[{"id":"1.195395449","rc":[{"spl":[[100,2]],"id":37495442},{"spl":[[100,2]],"id":40995914},{"spl":[[100,2]],"id":41360966},{"spl":[[100,2]],"id":41962160},{"spl":[[100,2]],"id":40494151},{"spl":[[100,2]],"id":25760990},{"spl":[[100,2]],"id":43066393},{"spl":[[100,2]],"id":40908100}],"con":true,"img":false}]}
{"op":"mcm","clk":"5346534810","pt":1646089500164,"mc":[{"id":"1.195395449","rc":[{"atb":[[18.5,0.58]],"id":40995914},{"spn":60.5,"spf":1.0,"id":40995914},{"atb":[[22,0.49]],"id":37495442},{"spn":61.5,"spf":1.0,"id":37495442},{"atb":[[22,0.49]],"id":41360966},{"spn":61.0,"spf":1.0,"id":41360966},{"atb":[[10.5,1.06]],"id":41962160},{"spn":41.0,"spf":1.0,"id":41962160},{"atb":[[15.5,0.7]],"id":40494151},{"spn":42.75,"spf":1.0,"id":40494151},{"atb":[[21,0.51]],"id":25760990},{"spn":61.5,"spf":1.0,"id":25760990},{"atb":[[4.1,2]],"id":40908100},{"spn":8.35,"spf":1.0,"id":40908100},{"atb":[[1.25,489.09]],"id":43066393},{"spn":1.7,"spf":1.0,"id":43066393}],"con":true,"img":false}]}
{"op":"mcm","clk":"5346564422","pt":1646090719118,"mc":[{"id":"1.195395449","rc":[{"atb":[[10.5,0]],"id":41962160},{"atb":[[4.1,0]],"id":40908100}],"con":true,"img":false}]}
{"op":"mcm","clk":"5346564424","pt":1646090719219,"mc":[{"id":"1.195395449","rc":[{"atb":[[11,1.01]],"id":41962160},{"atb":[[4.2,14.68]],"id":40908100}],"con":true,"img":false}]}
{"op":"mcm","clk":"5346570099","pt":1646090916091,"mc":[{"id":"1.195395449","rc":[{"atl":[[2.5,6.55]],"id":43066393}],"con":true,"img":false}]}
{"op":"mcm","clk":"5346572452","pt":1646090993793,"mc":[{"id":"1.195395449","rc":[{"atl":[[2.5,13.91]],"id":43066393}],"con":true,"img":false}]}
{"op":"mcm","clk":"5346573662","pt":1646091033239,"mc":[{"id":"1.195395449","rc":[{"atl":[[2.5,7.35]],"id":43066393}],"con":true,"img":false}]}
{"op":"mcm","clk":"5346573744","pt":1646091036220,"mc":[{"id":"1.195395449","rc":[{"atl":[[2.5,13.91]],"id":43066393}],"con":true,"img":false}]}
{"op":"mcm","clk":"5346576055","pt":1646091111114,"mc":[{"id":"1.195395449","rc":[{"atl":[[2.5,6.55]],"id":43066393}],"con":true,"img":false}]}
{"op":"mcm","clk":"5346576257","pt":1646091116921,"mc":[{"id":"1.195395449","rc":[{"atl":[[2.5,13.91]],"id":43066393}],"con":true,"img":false}]}
{"op":"mcm","clk":"5346577604","pt":1646091153449,"mc":[{"id":"1.195395449","rc":[{"atl":[[2.5,7.35]],"id":43066393}],"con":true,"img":false}]}
{"op":"mcm","clk":"5346577721","pt":1646091156371,"mc":[{"id":"1.195395449","rc":[{"atl":[[2.5,13.91]],"id":43066393}],"con":true,"img":false}]}
{"op":"mcm","clk":"5346580304","pt":1646091237149,"mc":[{"id":"1.195395449","rc":[{"atl":[[2.5,6.55]],"id":43066393}],"con":true,"img":false}]}
{"op":"mcm","clk":"5346580480","pt":1646091243165,"mc":[{"id":"1.195395449","rc":[{"atl":[[2.5,13.91]],"id":43066393}],"con":true,"img":false}]}
{"op":"mcm","clk":"5346581370","pt":1646091273616,"mc":[{"id":"1.195395449","rc":[{"atl":[[2.5,7.35]],"id":43066393}],"con":true,"img":false}]}
{"op":"mcm","clk":"5346581449","pt":1646091276589,"mc":[{"id":"1.195395449","rc":[{"atl":[[2.5,13.91]],"id":43066393}],"con":true,"img":false}]}
{"op":"mcm","clk":"5346582402","pt":1646091305136,"mc":[{"id":"1.195395449","rc":[{"atb":[[11,7.2]],"id":41360966},{"atb":[[6.4,13.33]],"id":41962160},{"atb":[[6.4,13.33]],"id":40494151},{"atb":[[2.6,45]],"id":40908100},{"atl":[[23,8.2]],"id":40908100}],"con":true,"img":false}]}
{"op":"mcm","clk":"5346582405","pt":1646091305238,"mc":[{"id":"1.195395449","rc":[{"atb":[[2.62,46.3],[4.2,26.56]],"id":37495442},{"atb":[[2.62,46.3],[4.2,26.56]],"id":40995914},{"atb":[[2.62,46.3],[4.2,26.56]],"id":41360966},{"atb":[[2.62,46.3]],"id":41962160},{"atb":[[2.62,46.3],[4.2,26.56]],"id":40494151},{"atb":[[2.62,46.3],[4.2,26.56]],"id":25760990}],"con":true,"img":false}]}
{"op":"mcm","clk":"5346582406","pt":1646091305340,"mc":[{"id":"1.195395449","rc":[{"atb":[[4.2,26.56]],"id":41962160},{"atl":[[17,8.5],[34,13.5]],"id":43066393}],"con":true,"img":false}]}
{"op":"mcm","clk":"5346582408","pt":1646091305443,"mc":[{"id":"1.195395449","rc":[{"atl":[[34,13.5]],"id":40908100}],"con":true,"img":false}]}
{"op":"mcm","clk":"5346584024","pt":1646091363490,"mc":[{"id":"1.195395449","rc":[{"atl":[[2.5,6.55]],"id":43066393}],"con":true,"img":false}]}
{"op":"mcm","clk":"5346584082","pt":1646091366306,"mc":[{"id":"1.195395449","rc":[{"atb":[[18,7.57],[21,2.7]],"id":37495442},{"atl":[[150,2.7],[120,0.36]],"id":37495442},{"atb":[[16.5,2.79],[16,7.88]],"id":40995914},{"atl":[[95,0.46],[120,2.7]],"id":40995914},{"spn":58.0,"spf":1.0,"id":40995914},{"atb":[[17,7.57],[20,2.7]],"id":41360966},{"atl":[[140,2.7],[110,0.39]],"id":41360966},{"atb":[[9.2,16.23],[10.5,4.55]],"id":41962160},{"atl":[[65,2.7],[55,0.8]],"id":41962160},{"spn":33.5,"spf":1.0,"id":41962160},{"atb":[[12,14.16],[14,3.32]],"id":40494151},{"atl":[[80,0.54],[90,2.7]],"id":40494151},{"atb":[[18,2.7],[15.5,7.78]],"id":25760990},{"atl":[[130,2.7],[100,0.43]],"id":25760990},{"atb":[[1.2,588.56],[1.26,43.29]],"id":43066393},{"atl":[[2.52,77.44],[2.46,28.48]],"id":43066393},{"atb":[[4.3,13.11],[3.2,57.9]],"id":40908100},{"atl":[[12,3.93],[14.5,9.2]],"id":40908100},{"spn":8.15,"spf":1.0,"id":40908100}],"con":true,"img":false}]}
{"op":"mcm","clk":"5346584163","pt":1646091369431,"mc":[{"id":"1.195395449","rc":[{"atl":[[2.48,7.41]],"id":43066393}],"con":true,"img":false}]}
{"op":"mcm","clk":"5346584337","pt":1646091375603,"mc":[{"id":"1.195395449","rc":[{"atb":[[11.5,22.32]],"id":37495442}],"con":true,"img":false}]}
{"op":"mcm","clk":"5346584789","pt":1646091393836,"mc":[{"id":"1.195395449","rc":[{"atl":[[2.5,0]],"id":43066393}],"con":true,"img":false}]}
{"op":"mcm","clk":"5346584869","pt":1646091396825,"mc":[{"id":"1.195395449","rc":[{"atl":[[2.48,14.02]],"id":43066393}],"con":true,"img":false}]}
{"op":"mcm","clk":"5346586425","pt":1646091449902,"mc":[{"id":"1.195395449","rc":[{"atb":[[16.5,0]],"id":40995914},{"atb":[[9.2,0]],"id":41962160},{"atb":[[18,0],[15.5,0]],"id":25760990},{"atl":[[2.52,0],[2.46,0]],"id":43066393}],"con":true,"img":false}]}
{"op":"mcm","clk":"5346586427","pt":1646091450001,"mc":[{"id":"1.195395449","rc":[{"atb":[[18.5,3.37]],"id":40995914},{"atb":[[10,16.23]],"id":41962160},{"atb":[[17,7.78],[19.5,2.7]],"id":25760990},{"atl":[[2.36,28.48],[2.46,77.44]],"id":43066393}],"con":true,"img":false}]}
{"op":"mcm","clk":"5346586847","pt":1646091464355,"mc":[{"id":"1.195395449","rc":[{"atb":[[11,7.2]],"id":25760990}],"con":true,"img":false}]}
{"op":"mcm","clk":"5346587466","pt":1646091489701,"mc":[{"id":"1.195395449","rc":[{"atl":[[2.48,6.6]],"id":43066393}],"con":true,"img":false}]}
{"op":"mcm","clk":"5346587667","pt":1646091495657,"mc":[{"id":"1.195395449","rc":[{"atl":[[2.42,7.59]],"id":43066393}],"con":true,"img":false}]}
{"op":"mcm","clk":"5346588231","pt":1646091514110,"mc":[{"id":"1.195395449","rc":[{"atl":[[2.48,0]],"id":43066393}],"con":true,"img":false}]}
{"op":"mcm","clk":"5346588319","pt":1646091516984,"mc":[{"id":"1.195395449","rc":[{"atl":[[2.42,14.37]],"id":43066393}],"con":true,"img":false}]}
{"op":"mcm","clk":"5346588935","pt":1646091538229,"mc":[{"id":"1.195395449","rc":[{"atl":[[2.46,0]],"id":43066393}],"con":true,"img":false}]}
{"op":"mcm","clk":"5346588938","pt":1646091538332,"mc":[{"id":"1.195395449","rc":[{"atl":[[2.52,77.44]],"id":43066393}],"con":true,"img":false}]}
{"op":"mcm","clk":"5346591146","pt":1646091616012,"mc":[{"id":"1.195395449","rc":[{"atl":[[2.42,6.77]],"id":43066393}],"con":true,"img":false}]}
{"op":"mcm","clk":"5346591284","pt":1646091621924,"mc":[{"id":"1.195395449","rc":[{"atl":[[2.48,7.41]],"id":43066393}],"con":true,"img":false}]}
{"op":"mcm","clk":"5346591567","pt":1646091634247,"mc":[{"id":"1.195395449","rc":[{"atl":[[2.42,0]],"id":43066393}],"con":true,"img":false}]}
{"op":"mcm","clk":"5346591631","pt":1646091637265,"mc":[{"id":"1.195395449","rc":[{"atl":[[2.48,14.02]],"id":43066393}],"con":true,"img":false}]}
{"op":"mcm","clk":"5346592648","pt":1646091677594,"mc":[{"id":"1.195395449","rc":[{"atl":[[2.52,0]],"id":43066393}],"con":true,"img":false}]}
{"op":"mcm","clk":"5346592651","pt":1646091677694,"mc":[{"id":"1.195395449","rc":[{"atl":[[2.46,77.44]],"id":43066393}],"con":true,"img":false}]}
{"op":"mcm","clk":"5346594331","pt":1646091742162,"mc":[{"id":"1.195395449","rc":[{"atl":[[2.48,6.6]],"id":43066393}],"con":true,"img":false}]}
{"op":"mcm","clk":"5346594463","pt":1646091748153,"mc":[{"id":"1.195395449","rc":[{"atl":[[2.42,7.59]],"id":43066393}],"con":true,"img":false}]}
{"op":"mcm","clk":"5346594596","pt":1646091754471,"mc":[{"id":"1.195395449","rc":[{"atl":[[2.48,0]],"id":43066393}],"con":true,"img":false}]}
{"op":"mcm","clk":"5346594681","pt":1646091757390,"mc":[{"id":"1.195395449","rc":[{"atl":[[2.42,14.37]],"id":43066393}],"con":true,"img":false}]}
{"op":"mcm","clk":"5346594779","pt":1646091761094,"mc":[{"id":"1.195395449","rc":[{"atl":[[2.46,0]],"id":43066393}],"con":true,"img":false}]}
{"op":"mcm","clk":"5346594781","pt":1646091761195,"mc":[{"id":"1.195395449","rc":[{"atl":[[2.52,77.44]],"id":43066393}],"con":true,"img":false}]}
{"op":"mcm","clk":"5346595082","pt":1646091773717,"mc":[{"id":"1.195395449","rc":[{"atb":[[18,0],[21,0],[10.5,0],[15.5,0]],"id":40995914},{"atl":[[150,0],[300,0],[200,0],[250,0]],"id":40995914},{"atb":[[16.5,0],[19,0],[23,0],[11.5,6.86]],"id":37495442},{"atl":[[260,0],[310,0],[160,0],[210,0]],"id":37495442},{"atb":[[18,0],[21,0],[10.5,0],[15.5,0]],"id":41360966},{"atl":[[150,0],[300,0],[200,0],[250,0]],"id":41360966},{"atb":[[12,10.47],[6.8,0],[9.8,0],[8.8,0]],"id":40494151},{"atl":[[70,0],[140,0],[95,0],[190,0]],"id":40494151},{"atb":[[16.5,0],[19,0],[23,0],[11.5,0]],"id":25760990},{"atl":[[260,0],[310,0],[160,0],[210,0]],"id":25760990},{"atb":[[1.25,2],[1.15,0],[1.3,0],[1.35,0]],"id":43066393},{"atl":[[2.54,0],[2.74,0],[2.64,0],[2.84,0]],"id":43066393}],"con":true,"img":false}]}
{"op":"mcm","clk":"5346595185","pt":1646091778531,"mc":[{"id":"1.195395449","rc":[{"atb":[[16.5,7.85],[19,4.5],[11.5,22.32],[23,1.84]],"id":37495442},{"atl":[[260,0.76],[310,0.64],[160,0.83],[210,0.63]],"id":37495442},{"atb":[[18,4.77],[21,2.02],[10.5,17.09],[15.5,8.39]],"id":40995914},{"atl":[[150,0.88],[300,0.66],[200,0.66],[250,0.79]],"id":40995914},{"atb":[[18,4.77],[21,2.02],[10.5,17.09],[15.5,8.39]],"id":41360966},{"atl":[[150,0.88],[300,0.66],[200,0.66],[250,0.79]],"id":41360966},{"atb":[[12,14.16],[6.8,27.99],[9.8,9.22],[8.8,15.61]],"id":40494151},{"atl":[[70,1.91],[140,1.42],[95,1.4],[190,1.04]],"id":40494151},{"atb":[[16.5,7.85],[19,4.5],[23,1.84],[11.5,15.46]],"id":25760990},{"atl":[[260,0.76],[310,0.64],[160,0.83],[210,0.63]],"id":25760990},{"atb":[[1.25,489.09],[1.15,1082.42],[1.3,270.6],[1.35,115.97]],"id":43066393},{"atl":[[2.54,85.89],[2.74,114.02],[2.64,80.65],[2.84,107.83]],"id":43066393}],"con":true,"img":false}]}
{"op":"mcm","clk":"5346597709","pt":1646091865407,"mc":[{"id":"1.195395449","rc":[{"atl":[[2.42,6.77]],"id":43066393}],"con":true,"img":false}]}
{"op":"mcm","clk":"5346597985","pt":1646091874634,"mc":[{"id":"1.195395449","rc":[{"atl":[[2.42,0]],"id":43066393}],"con":true,"img":false}]}
{"op":"mcm","clk":"5346598093","pt":1646091877453,"mc":[{"id":"1.195395449","rc":[{"atl":[[2.48,7.41]],"id":43066393}],"con":true,"img":false}]}
{"op":"mcm","clk":"5346598098","pt":1646091877555,"mc":[{"id":"1.195395449","rc":[{"atl":[[2.48,14.02]],"id":43066393}],"con":true,"img":false}]}
{"op":"mcm","clk":"5346600671","pt":1646091946002,"mc":[{"id":"1.195395449","rc":[{"atl":[[2.52,0]],"id":43066393}],"con":true,"img":false}]}
{"op":"mcm","clk":"5346600675","pt":1646091946102,"mc":[{"id":"1.195395449","rc":[{"atl":[[2.46,77.44]],"id":43066393}],"con":true,"img":false}]}
{"op":"mcm","clk":"5346602161","pt":1646091994689,"mc":[{"id":"1.195395449","rc":[{"atl":[[2.48,6.6]],"id":43066393}],"con":true,"img":false}]}
{"op":"mcm","clk":"5346602169","pt":1646091994896,"mc":[{"id":"1.195395449","rc":[{"atl":[[2.48,0]],"id":43066393}],"con":true,"img":false}]}
{"op":"mcm","clk":"5346602266","pt":1646091997875,"mc":[{"id":"1.195395449","rc":[{"atl":[[2.42,6.77]],"id":43066393}],"con":true,"img":false}]}
{"op":"mcm","clk":"5346602322","pt":1646091999672,"mc":[{"id":"1.195395449","rc":[{"atl":[[2.46,0]],"id":43066393}],"con":true,"img":false}]}
{"op":"mcm","clk":"5346602326","pt":1646091999772,"mc":[{"id":"1.195395449","rc":[{"atl":[[2.52,77.44]],"id":43066393}],"con":true,"img":false}]}
{"op":"mcm","clk":"5346602358","pt":1646092000811,"mc":[{"id":"1.195395449","rc":[{"atl":[[2.48,7.41]],"id":43066393}],"con":true,"img":false}]}
{"op":"mcm","clk":"5346604595","pt":1646092075683,"mc":[{"id":"1.195395449","rc":[{"atl":[[2.52,0]],"id":43066393}],"con":true,"img":false}]}
{"op":"mcm","clk":"5346604597","pt":1646092075782,"mc":[{"id":"1.195395449","rc":[{"atl":[[2.46,77.44]],"id":43066393}],"con":true,"img":false}]}
{"op":"mcm","clk":"5346605866","pt":1646092115022,"mc":[{"id":"1.195395449","rc":[{"atl":[[2.42,0]],"id":43066393}],"con":true,"img":false}]}
{"op":"mcm","clk":"5346605957","pt":1646092118048,"mc":[{"id":"1.195395449","rc":[{"atl":[[2.42,6.77]],"id":43066393}],"con":true,"img":false}]}
{"op":"mcm","clk":"5346606060","pt":1646092121021,"mc":[{"id":"1.195395449","rc":[{"atl":[[2.48,0]],"id":43066393}],"con":true,"img":false}]}
{"op":"mcm","clk":"5346606264","pt":1646092126964,"mc":[{"id":"1.195395449","rc":[{"atl":[[2.42,14.37]],"id":43066393}],"con":true,"img":false}]}
{"op":"mcm","clk":"5346606295","pt":1646092127740,"mc":[{"id":"1.195395449","rc":[{"atl":[[2.46,0]],"id":43066393}],"con":true,"img":false}]}
{"op":"mcm","clk":"5346606297","pt":1646092127843,"mc":[{"id":"1.195395449","rc":[{"atl":[[2.52,77.44]],"id":43066393}],"con":true,"img":false}]}
{"op":"mcm","clk":"5346610491","pt":1646092235219,"mc":[{"id":"1.195395449","rc":[{"atl":[[2.42,7.59]],"id":43066393}],"con":true,"img":false}]}
{"op":"mcm","clk":"5346610613","pt":1646092238196,"mc":[{"id":"1.195395449","rc":[{"atl":[[2.48,6.6]],"id":43066393}],"con":true,"img":false}]}
{"op":"mcm","clk":"5346612620","pt":1646092289357,"mc":[{"id":"1.195395449","rc":[{"atl":[[2.42,0]],"id":43066393}],"con":true,"img":false}]}
{"op":"mcm","clk":"5346612864","pt":1646092295260,"mc":[{"id":"1.195395449","rc":[{"atl":[[2.48,14.02]],"id":43066393}],"con":true,"img":false}]}
{"op":"mcm","clk":"5346613145","pt":1646092303171,"mc":[{"id":"1.195395449","rc":[{"atl":[[2.52,0]],"id":43066393}],"con":true,"img":false}]}
{"op":"mcm","clk":"5346613149","pt":1646092303275,"mc":[{"id":"1.195395449","rc":[{"atl":[[2.46,77.44]],"id":43066393}],"con":true,"img":false}]}
{"op":"mcm","clk":"5346614958","pt":1646092355458,"mc":[{"id":"1.195395449","rc":[{"atl":[[2.48,7.41]],"id":43066393}],"con":true,"img":false}]}
{"op":"mcm","clk":"5346615061","pt":1646092358431,"mc":[{"id":"1.195395449","rc":[{"atl":[[2.42,6.77]],"id":43066393}],"con":true,"img":false}]}
{"op":"mcm","clk":"5346619377","pt":1646092475701,"mc":[{"id":"1.195395449","rc":[{"atl":[[2.42,0]],"id":43066393}],"con":true,"img":false}]}
{"op":"mcm","clk":"5346619467","pt":1646092478728,"mc":[{"id":"1.195395449","rc":[{"atl":[[2.42,6.77]],"id":43066393}],"con":true,"img":false}]}
{"op":"mcm","clk":"5346622119","pt":1646092562724,"mc":[{"id":"1.195395449","rc":[{"atl":[[2.48,0]],"id":43066393}],"con":true,"img":false}]}
{"op":"mcm","clk":"5346622351","pt":1646092568936,"mc":[{"id":"1.195395449","rc":[{"atl":[[2.42,14.37]],"id":43066393}],"con":true,"img":false}]}
{"op":"mcm","clk":"5346622621","pt":1646092577725,"mc":[{"id":"1.195395449","rc":[{"atl":[[2.46,0]],"id":43066393}],"con":true,"img":false}]}
{"op":"mcm","clk":"5346622624","pt":1646092577827,"mc":[{"id":"1.195395449","rc":[{"atl":[[2.52,77.44]],"id":43066393}],"con":true,"img":false}]}
{"op":"mcm","clk":"5346623161","pt":1646092595987,"mc":[{"id":"1.195395449","rc":[{"atl":[[2.42,7.59]],"id":43066393}],"con":true,"img":false}]}
{"op":"mcm","clk":"5346623264","pt":1646092598959,"mc":[{"id":"1.195395449","rc":[{"atl":[[2.48,6.6]],"id":43066393}],"con":true,"img":false}]}
{"op":"mcm","clk":"5346624834","pt":1646092645026,"mc":[{"id":"1.195395449","rc":[{"atl":[[2.52,0]],"id":43066393}],"con":true,"img":false}]}
{"op":"mcm","clk":"5346624837","pt":1646092645130,"mc":[{"id":"1.195395449","rc":[{"atl":[[2.46,77.44]],"id":43066393}],"con":true,"img":false}]}
{"op":"mcm","clk":"5346626093","pt":1646092688774,"mc":[{"id":"1.195395449","rc":[{"atl":[[2.42,0]],"id":43066393}],"con":true,"img":false}]}
{"op":"mcm","clk":"5346626253","pt":1646092694777,"mc":[{"id":"1.195395449","rc":[{"atl":[[2.42,7.59]],"id":43066393}],"con":true,"img":false}]}
{"op":"mcm","clk":"5346626913","pt":1646092716310,"mc":[{"id":"1.195395449","rc":[{"atl":[[2.48,0]],"id":43066393}],"con":true,"img":false}]}
{"op":"mcm","clk":"5346626994","pt":1646092719227,"mc":[{"id":"1.195395449","rc":[{"atl":[[2.42,14.37]],"id":43066393}],"con":true,"img":false}]}
{"op":"mcm","clk":"5346627157","pt":1646092724152,"mc":[{"id":"1.195395449","rc":[{"atl":[[2.46,0]],"id":43066393}],"con":true,"img":false}]}
{"op":"mcm","clk":"5346627160","pt":1646092724204,"mc":[{"id":"1.195395449","rc":[{"atl":[[2.52,77.44]],"id":43066393}],"con":true,"img":false}]}
{"op":"mcm","clk":"5346630132","pt":1646092815043,"mc":[{"id":"1.195395449","rc":[{"atb":[[16.5,7.85],[18,7.57],[19,4.5],[21,2.7],[23,1.84],[11.5,22.31]],"id":37495442},{"atl":[[260,0.76],[150,2.7],[310,0.64],[160,0.83],[210,0.63],[120,0.36]],"id":37495442},{"atb":[[16,7.88],[18.5,3.37],[18,4.77],[21,2.02],[10.5,17.08],[15.5,8.39]],"id":40995914},{"atl":[[150,0.88],[300,0.66],[95,0.45],[200,0.66],[120,2.7],[250,0.79]],"id":40995914},{"atb":[[17,7.57],[18,4.77],[20,2.7],[21,2.02],[10.5,17.08],[15.5,8.39]],"id":41360966},{"atl":[[140,2.7],[150,0.88],[300,0.66],[200,0.66],[110,0.39],[250,0.79]],"id":41360966},{"atb":[[10,16.22],[10.5,4.55],[12,3.68],[6.8,27.97],[9.8,9.22],[8.8,15.6]],"id":41962160},{"atl":[[65,2.7],[70,1.91],[140,1.42],[95,1.4],[190,1.04],[55,0.8]],"id":41962160},{"atb":[[12,14.15],[6.8,27.97],[9.8,9.22],[8.8,15.6],[14,3.32]],"id":40494151},{"atl":[[70,1.91],[140,1.42],[80,0.54],[90,2.7],[95,1.4],[190,1.04]],"id":40494151},{"atb":[[16.5,7.85],[17,7.77],[19.5,2.7],[19,4.5],[23,1.84],[11.5,15.45]],"id":25760990},{"atl":[[130,2.7],[260,0.76],[310,0.64],[160,0.83],[100,0.43],[210,0.63]],"id":25760990},{"atb":[[1.2,588.18],[1.37,42.72],[1.25,488.77],[1.15,1081.72],[1.26,43.26],[1.3,270.43],[1.35,115.9]],"id":43066393},{"atl":[[2.36,28.46],[2.54,85.83],[2.74,113.95],[2.42,6.77],[2.04,4.05],[2.38,10.81],[2.52,77.39],[2.64,80.59],[2.84,107.76]],"id":43066393},{"atb":[[3.6,46.8],[4.3,13.11],[3.85,28.46],[3.2,57.87],[3.1,77.26],[3.9,5.45],[4.2,14.67]],"id":40908100},{"atl":[[17.5,12.01],[20,10.43],[12,3.93],[12.5,11.49],[14.5,9.19],[15,9.44]],"id":40908100}],"con":true,"img":false}]}
{"op":"mcm","clk":"5346630345","pt":1646092821033,"mc":[{"id":"1.195395449","rc":[{"atl":[[2.48,7.41]],"id":43066393}],"con":true,"img":false}]}
{"op":"mcm","clk":"5346630957","pt":1646092836572,"mc":[{"id":"1.195395449","rc":[{"atl":[[2.42,0]],"id":43066393}],"con":true,"img":false}]}
{"op":"mcm","clk":"5346631062","pt":1646092839757,"mc":[{"id":"1.195395449","rc":[{"atl":[[2.48,14.01]],"id":43066393}],"con":true,"img":false}]}
{"op":"mcm","clk":"5346633101","pt":1646092896329,"mc":[{"id":"1.195395449","rc":[{"atl":[[2.52,0]],"id":43066393}],"con":true,"img":false}]}
{"op":"mcm","clk":"5346633105","pt":1646092896433,"mc":[{"id":"1.195395449","rc":[{"atl":[[2.46,77.39]],"id":43066393}],"con":true,"img":false}]}
{"op":"mcm","clk":"5346634989","pt":1646092941596,"mc":[{"id":"1.195395449","rc":[{"atl":[[2.48,6.6]],"id":43066393}],"con":true,"img":false}]}
{"op":"mcm","clk":"5346635209","pt":1646092947611,"mc":[{"id":"1.195395449","rc":[{"atl":[[2.42,7.59]],"id":43066393}],"con":true,"img":false}]}
{"op":"mcm","clk":"5346635533","pt":1646092956705,"mc":[{"id":"1.195395449","rc":[{"atl":[[2.48,0]],"id":43066393}],"con":true,"img":false}]}
{"op":"mcm","clk":"5346635664","pt":1646092959697,"mc":[{"id":"1.195395449","rc":[{"atl":[[2.42,14.36]],"id":43066393}],"con":true,"img":false}]}
{"op":"mcm","clk":"5346635914","pt":1646092966520,"mc":[{"id":"1.195395449","rc":[{"atl":[[2.46,0]],"id":43066393}],"con":true,"img":false}]}
{"op":"mcm","clk":"5346635918","pt":1646092966625,"mc":[{"id":"1.195395449","rc":[{"atl":[[2.52,77.39]],"id":43066393}],"con":true,"img":false}]}
{"op":"mcm","clk":"5346639791","pt":1646093067830,"mc":[{"id":"1.195395449","rc":[{"atl":[[2.42,6.77]],"id":43066393}],"con":true,"img":false}]}
{"op":"mcm","clk":"5346639991","pt":1646093073723,"mc":[{"id":"1.195395449","rc":[{"atl":[[2.48,7.41]],"id":43066393}],"con":true,"img":false}]}
{"op":"mcm","clk":"5346640110","pt":1646093077070,"mc":[{"id":"1.195395449","rc":[{"atl":[[2.42,0]],"id":43066393}],"con":true,"img":false}]}
{"op":"mcm","clk":"5346640225","pt":1646093079943,"mc":[{"id":"1.195395449","rc":[{"atl":[[2.48,14.01]],"id":43066393}],"con":true,"img":false}]}
{"op":"mcm","clk":"5346641887","pt":1646093122704,"mc":[{"id":"1.195395449","rc":[{"atl":[[2.52,0]],"id":43066393}],"con":true,"img":false}]}
{"op":"mcm","clk":"5346641897","pt":1646093122815,"mc":[{"id":"1.195395449","rc":[{"atb":[[1.19,526.32]],"id":43066393},{"atl":[[2.02,10.82],[2.46,77.39]],"id":43066393}],"con":true,"img":false}]}
{"op":"mcm","clk":"5346641906","pt":1646093123026,"mc":[{"id":"1.195395449","rc":[{"atb":[[9.4,11.9]],"id":37495442},{"atl":[[740,2]],"id":37495442},{"atb":[[10.5,27.61]],"id":40995914},{"atl":[[280,2]],"id":40995914},{"atb":[[10.5,27.61]],"id":41360966},{"atl":[[290,2]],"id":41360966},{"atb":[[5,25]],"id":41962160},{"atl":[[65,4.7]],"id":41962160},{"atb":[[8.8,28.42]],"id":40494151},{"atl":[[160,2]],"id":40494151},{"atb":[[9,12.5]],"id":25760990},{"atl":[[170,2]],"id":25760990},{"atb":[[3.85,63.55]],"id":40908100},{"atl":[[16,6.67]],"id":40908100}],"con":true,"img":false}]}
{"op":"mcm","clk":"5346643377","pt":1646093159960,"mc":[{"id":"1.195395449","rc":[{"atl":[[660,2],[740,0]],"id":37495442},{"spn":1.69,"spf":1.0,"id":43066393}],"con":true,"img":false}]}
{"op":"mcm","clk":"5346644270","pt":1646093186593,"mc":[{"id":"1.195395449","rc":[{"atb":[[21,0]],"id":37495442},{"atb":[[20,0]],"id":41360966},{"atb":[[10.5,0]],"id":41962160},{"atb":[[14,0]],"id":40494151},{"atl":[[2.36,0]],"id":43066393}],"con":true,"img":false}]}
{"op":"mcm","clk":"5346644272","pt":1646093186696,"mc":[{"id":"1.195395449","rc":[{"atb":[[22,3.19]],"id":37495442},{"atb":[[22,3.19]],"id":41360966},{"atb":[[11,5.56]],"id":41962160},{"atb":[[15.5,4.02]],"id":40494151},{"atl":[[2.24,28.46]],"id":43066393}],"con":true,"img":false}]}
{"op":"mcm","clk":"5346644571","pt":1646093194007,"mc":[{"id":"1.195395449","rc":[{"atl":[[2.48,6.6]],"id":43066393}],"con":true,"img":false}]}
{"op":"mcm","clk":"5346644675","pt":1646093197196,"mc":[{"id":"1.195395449","rc":[{"atl":[[2.48,0]],"id":43066393}],"con":true,"img":false}]}
{"op":"mcm","clk":"5346644752","pt":1646093200014,"mc":[{"id":"1.195395449","rc":[{"atl":[[2.42,7.59]],"id":43066393}],"con":true,"img":false}]}
{"op":"mcm","clk":"5346644758","pt":1646093200170,"mc":[{"id":"1.195395449","rc":[{"atl":[[2.42,14.36]],"id":43066393}],"con":true,"img":false}]}
{"op":"mcm","clk":"5346644882","pt":1646093203821,"mc":[{"id":"1.195395449","rc":[{"atb":[[3.65,47.05]],"id":40908100}],"con":true,"img":false}]}
{"op":"mcm","clk":"5346644888","pt":1646093204027,"mc":[{"id":"1.195395449","rc":[{"atb":[[18,0]],"id":37495442},{"atb":[[17,0]],"id":41360966},{"atb":[[12,3.68]],"id":40494151},{"atb":[[19.5,0]],"id":25760990},{"atb":[[3.2,0]],"id":40908100},{"atl":[[2.46,0]],"id":43066393}],"con":true,"img":false}]}
{"op":"mcm","clk":"5346644890","pt":1646093204081,"mc":[{"id":"1.195395449","rc":[{"atb":[[19.5,7.57]],"id":37495442},{"atb":[[19,7.57]],"id":41360966},{"atb":[[13,10.47]],"id":40494151},{"atb":[[18,2.7]],"id":25760990},{"atl":[[2.34,77.39]],"id":43066393}],"con":true,"img":false}]}
{"op":"mcm","clk":"5346644987","pt":1646093207515,"mc":[{"id":"1.195395449","rc":[{"atl":[[2.34,0]],"id":43066393}],"con":true,"img":false}]}
{"op":"mcm","clk":"5346644990","pt":1646093207620,"mc":[{"id":"1.195395449","rc":[{"atl":[[2.36,77.39]],"id":43066393}],"con":true,"img":false}]}
{"op":"mcm","clk":"5346646456","pt":1646093248867,"mc":[{"id":"1.195395449","rc":[{"atb":[[18,0]],"id":25760990}],"con":true,"img":false}]}
{"op":"mcm","clk":"5346646460","pt":1646093248970,"mc":[{"id":"1.195395449","rc":[{"atb":[[19.5,2.7]],"id":25760990}],"con":true,"img":false}]}
{"op":"mcm","clk":"5346649154","pt":1646093317455,"mc":[{"id":"1.195395449","rc":[{"atl":[[2.42,7.59]],"id":43066393}],"con":true,"img":false}]}
{"op":"mcm","clk":"5346649226","pt":1646093320230,"mc":[{"id":"1.195395449","rc":[{"atl":[[2.42,0]],"id":43066393}],"con":true,"img":false}]}
{"op":"mcm","clk":"5346649234","pt":1646093320432,"mc":[{"id":"1.195395449","rc":[{"atl":[[2.32,7.06]],"id":43066393}],"con":true,"img":false}]}
{"op":"mcm","clk":"5346649423","pt":1646093326133,"mc":[{"id":"1.195395449","rc":[{"atl":[[2.32,14.98]],"id":43066393}],"con":true,"img":false}]}
{"op":"mcm","clk":"5346650824","pt":1646093368882,"mc":[{"id":"1.195395449","rc":[{"atl":[[2.36,0]],"id":43066393}],"con":true,"img":false}]}
{"op":"mcm","clk":"5346650828","pt":1646093368989,"mc":[{"id":"1.195395449","rc":[{"atl":[[2.3,77.39]],"id":43066393}],"con":true,"img":false}]}
{"op":"mcm","clk":"5346651049","pt":1646093376133,"mc":[{"id":"1.195395449","rc":[{"atl":[[1.49,16.22]],"id":43066393}],"con":true,"img":false}]}
{"op":"mcm","clk":"5346651056","pt":1646093376338,"mc":[{"id":"1.195395449","rc":[{"atl":[[1.76,32.46],[2.02,0]],"id":43066393}],"con":true,"img":false}]}
{"op":"mcm","clk":"5346651061","pt":1646093376391,"mc":[{"id":"1.195395449","rc":[{"atb":[[5.6,21.74],[5,0]],"id":41962160},{"atb":[[10,11.11],[8.8,15.6]],"id":40494151},{"atb":[[9,0],[10,11.11]],"id":25760990},{"atb":[[3.85,28.46],[4.1,32.26]],"id":40908100}],"con":true,"img":false}]}
{"op":"mcm","clk":"5346651313","pt":1646093383537,"mc":[{"id":"1.195395449","rc":[{"atb":[[3.9,2.88]],"id":40908100},{"spn":1.43,"spf":1.0,"id":43066393}],"con":true,"img":false}]}
{"op":"mcm","clk":"5346651641","pt":1646093392213,"mc":[{"id":"1.195395449","rc":[{"atb":[[3.9,0]],"id":40908100}],"con":true,"img":false}]}
{"op":"mcm","clk":"5346651653","pt":1646093392521,"mc":[{"id":"1.195395449","rc":[{"atb":[[4.2,17.23]],"id":40908100}],"con":true,"img":false}]}
{"op":"mcm","clk":"5346651672","pt":1646093393446,"mc":[{"id":"1.195395449","rc":[{"atl":[[1.59,16.22]],"id":43066393}],"con":true,"img":false}]}
{"op":"mcm","clk":"5346651840","pt":1646093398558,"mc":[{"id":"1.195395449","rc":[{"atb":[[4.2,20.09]],"id":40908100}],"con":true,"img":false}]}
{"op":"mcm","clk":"5346652126","pt":1646093407438,"mc":[{"id":"1.195395449","rc":[{"atl":[[150,0],[120,0]],"id":37495442},{"atl":[[95,0],[120,0]],"id":40995914},{"atl":[[140,0],[110,0]],"id":41360966},{"atl":[[65,2],[55,0]],"id":41962160},{"atl":[[80,0],[90,0]],"id":40494151},{"atl":[[130,0],[100,0]],"id":25760990},{"atl":[[12,0],[14.5,0]],"id":40908100}],"con":true,"img":false}]}
{"op":"mcm","clk":"5346652129","pt":1646093407541,"mc":[{"id":"1.195395449","rc":[{"atl":[[140,2.7]],"id":40995914},{"atl":[[150,0.36],[200,2.7]],"id":37495442},{"atl":[[140,0.39],[190,2.7]],"id":41360966},{"atl":[[65,0],[70,3.91],[90,2.7],[60,0.8]],"id":41962160},{"atl":[[130,2.7],[90,0.54]],"id":40494151},{"atl":[[150,2.7],[170,0],[210,2.63]],"id":25760990},{"atb":[[4.2,17.54]],"id":40908100},{"atl":[[16,0],[14.5,3.93],[15.5,6.9]],"id":40908100}],"con":true,"img":false}]}
{"op":"mcm","clk":"5346652475","pt":1646093416551,"mc":[{"id":"1.195395449","rc":[{"atb":[[4.3,15.59]],"id":40908100}],"con":true,"img":false}]}
{"op":"mcm","clk":"5346652816","pt":1646093426471,"mc":[{"id":"1.195395449","rc":[{"atl":[[150,0],[180,0.24]],"id":37495442},{"atl":[[140,0],[170,0.25]],"id":41360966},{"atl":[[60,0]],"id":41962160},{"atb":[[15.5,0.7]],"id":40494151},{"atl":[[90,0]],"id":40494151},{"atl":[[2.24,0],[1.92,43.26]],"id":43066393}],"con":true,"img":false}]}
{"op":"mcm","clk":"5346652818","pt":1646093426574,"mc":[{"id":"1.195395449","rc":[{"atl":[[65,0.8]],"id":41962160},{"atb":[[18,3.32]],"id":40494151},{"atl":[[110,0.54]],"id":40494151}],"con":true,"img":false}]}
{"op":"mcm","clk":"5346653326","pt":1646093437606,"mc":[{"id":"1.195395449","rc":[{"atl":[[2.32,7.92]],"id":43066393}],"con":true,"img":false}]}
{"op":"mcm","clk":"5346653331","pt":1646093437761,"mc":[{"id":"1.195395449","rc":[{"atl":[[2.04,0]],"id":43066393}],"con":true,"img":false}]}
{"op":"mcm","clk":"5346653585","pt":1646093441564,"mc":[{"id":"1.195395449","rc":[{"atl":[[180,2],[210,0.63]],"id":25760990}],"con":true,"img":false}]}
{"op":"mcm","clk":"5346653695","pt":1646093445419,"mc":[{"id":"1.195395449","rc":[{"atl":[[130,0.33]],"id":40995914},{"spn":60.5,"spf":1.0,"id":40995914},{"spn":38.5,"spf":1.0,"id":41962160},{"spn":44.0,"spf":1.0,"id":40494151},{"atl":[[150,2.99]],"id":25760990},{"atl":[[17,7.57]],"id":40908100},{"spn":8.4,"spf":1.0,"id":40908100}],"con":true,"img":false}]}
{"op":"mcm","clk":"5346653698","pt":1646093445471,"mc":[{"id":"1.195395449","rc":[{"atb":[[3.65,0]],"id":40908100}],"con":true,"img":false}]}
{"op":"mcm","clk":"5346653703","pt":1646093445574,"mc":[{"id":"1.195395449","rc":[{"atb":[[3.9,47.05]],"id":40908100}],"con":true,"img":false}]}
{"op":"mcm","clk":"5346653722","pt":1646093446506,"mc":[{"id":"1.195395449","rc":[{"atl":[[2.32,0]],"id":43066393}],"con":true,"img":false}]}
{"op":"mcm","clk":"5346653979","pt":1646093455296,"mc":[{"id":"1.195395449","rc":[{"atb":[[4.2,15.54]],"id":40908100}],"con":true,"img":false}]}
{"op":"mcm","clk":"5346653982","pt":1646093455399,"mc":[{"id":"1.195395449","rc":[{"atb":[[4.3,17.59]],"id":40908100}],"con":true,"img":false}]}
{"op":"mcm","clk":"5346654152","pt":1646093461616,"mc":[{"id":"1.195395449","rc":[{"atb":[[4.3,15.11]],"id":40908100}],"con":true,"img":false}]}
{"op":"mcm","clk":"5346654210","pt":1646093464231,"mc":[{"id":"1.195395449","rc":[{"atb":[[13,0],[15.5,8.64]],"id":40494151}],"con":true,"img":false}]}
{"op":"mcm","clk":"5346654381","pt":1646093470744,"mc":[{"id":"1.195395449","rc":[{"atb":[[4.2,18.09]],"id":40908100}],"con":true,"img":false}]}
{"op":"mcm","clk":"5346654883","pt":1646093489630,"mc":[{"id":"1.195395449","rc":[{"atb":[[12.5,9.97]],"id":40995914},{"atb":[[3.65,25.17]],"id":40908100},{"atl":[[19.5,12.44]],"id":40908100},{"atb":[[1.16,107.76]],"id":43066393}],"con":true,"img":false}]}
{"op":"mcm","clk":"5346654885","pt":1646093489734,"mc":[{"id":"1.195395449","rc":[{"atb":[[16,0]],"id":40995914},{"atl":[[140,0]],"id":40995914},{"atb":[[19.5,0]],"id":37495442},{"atl":[[200,0]],"id":37495442},{"atl":[[190,0]],"id":41360966},{"atb":[[10,10.45]],"id":41962160},{"atl":[[130,0]],"id":40494151},{"atb":[[17,0]],"id":25760990},{"atl":[[150,0.29]],"id":25760990},{"atb":[[3.9,0]],"id":40908100},{"atl":[[17,0]],"id":40908100},{"atb":[[1.2,0],[1.26,0]],"id":43066393}],"con":true,"img":false}]}
{"op":"mcm","clk":"5346654889","pt":1646093489840,"mc":[{"id":"1.195395449","rc":[{"atl":[[240,2.7]],"id":40995914},{"atb":[[17,7.57]],"id":37495442},{"atl":[[520,2.7]],"id":37495442},{"atl":[[430,2.7]],"id":41360966},{"atl":[[360,2.7]],"id":40494151},{"atb":[[19.5,0],[14,7.77]],"id":25760990},{"atl":[[300,2.7]],"id":25760990},{"atb":[[1.22,43.26]],"id":43066393}],"con":true,"img":false}]}
{"op":"mcm","clk":"5346654892","pt":1646093489939,"mc":[{"id":"1.195395449","rc":[{"atb":[[18,2.7]],"id":25760990}],"con":true,"img":false}]}
{"op":"mcm","clk":"5346655266","pt":1646093501480,"mc":[{"id":"1.195395449","rc":[{"atb":[[18.5,0.58]],"id":40995914},{"atl":[[1.92,0]],"id":43066393}],"con":true,"img":false}]}
{"op":"mcm","clk":"5346655269","pt":1646093501583,"mc":[{"id":"1.195395449","rc":[{"atb":[[16.5,2.79]],"id":40995914},{"atl":[[1.75,43.26]],"id":43066393}],"con":true,"img":false}]}
{"op":"mcm","clk":"5346655333","pt":1646093503787,"mc":[{"id":"1.195395449","rc":[{"atl":[[180,0],[190,2]],"id":25760990},{"atl":[[15,16.58],[15.5,0]],"id":40908100}],"con":true,"img":false}]}
{"op":"mcm","clk":"5346656327","pt":1646093534600,"mc":[{"id":"1.195395449","rc":[{"atb":[[16.5,0]],"id":40995914}],"con":true,"img":false}]}
{"op":"mcm","clk":"5346656330","pt":1646093534747,"mc":[{"id":"1.195395449","rc":[{"atb":[[18.5,3.37]],"id":40995914}],"con":true,"img":false}]}
{"op":"mcm","clk":"5346660726","pt":1646093679841,"mc":[{"id":"1.195395449","rc":[{"atl":[[660,0],[750,2]],"id":37495442},{"atb":[[8.6,13.16],[10,0]],"id":40494151},{"atl":[[190,0],[210,2.63]],"id":25760990},{"atb":[[4.1,0],[3.75,36.36]],"id":40908100},{"atl":[[16.5,6.45],[15,9.44]],"id":40908100},{"atl":[[1.84,77.39],[1.76,0]],"id":43066393}],"con":true,"img":false}]}
{"op":"mcm","clk":"5346660988","pt":1646093687234,"mc":[{"id":"1.195395449","rc":[{"atb":[[4.2,15.54]],"id":40908100}],"con":true,"img":false}]}
{"op":"mcm","clk":"5346661008","pt":1646093687643,"mc":[{"id":"1.195395449","rc":[{"atb":[[16,6.67]],"id":37495442}],"con":true,"img":false}]}
{"op":"mcm","clk":"5346661012","pt":1646093687745,"mc":[{"id":"1.195395449","rc":[{"atb":[[9.4,0]],"id":37495442},{"atb":[[10.5,17.08],[14,7.69]],"id":41360966},{"atl":[[260,2],[290,0]],"id":41360966},{"atb":[[1.19,0]],"id":43066393}],"con":true,"img":false}]}
{"op":"mcm","clk":"5346661098","pt":1646093689647,"mc":[{"id":"1.195395449","rc":[{"atb":[[14,0]],"id":41360966},{"atl":[[130,2],[160,0]],"id":40494151}],"con":true,"img":false}]}
{"op":"mcm","clk":"5346661103","pt":1646093689749,"mc":[{"id":"1.195395449","rc":[{"atb":[[10,11.11]],"id":41360966}],"con":true,"img":false}]}
{"op":"mcm","clk":"5346661227","pt":1646093693034,"mc":[{"id":"1.195395449","rc":[{"atb":[[4.2,12.67]],"id":40908100}],"con":true,"img":false}]}
{"op":"mcm","clk":"5346661361","pt":1646093696130,"mc":[{"id":"1.195395449","rc":[{"atb":[[3.9,3.1]],"id":40908100},{"atl":[[1.75,0]],"id":43066393}],"con":true,"img":false}]}
{"op":"mcm","clk":"5346661367","pt":1646093696235,"mc":[{"id":"1.195395449","rc":[{"atl":[[1.83,43.26]],"id":43066393}],"con":true,"img":false}]}
{"op":"mcm","clk":"5346661459","pt":1646093698949,"mc":[{"id":"1.195395449","rc":[{"atb":[[3.9,6.28]],"id":40908100}],"con":true,"img":false}]}
{"op":"mcm","clk":"5346661937","pt":1646093711170,"mc":[{"id":"1.195395449","rc":[{"atl":[[640,2],[750,0]],"id":37495442},{"atb":[[8.6,0],[11,10]],"id":40494151}],"con":true,"img":false}]}
{"op":"mcm","clk":"5346662216","pt":1646093718957,"mc":[{"id":"1.195395449","rc":[{"atl":[[260,0],[200,2.66]],"id":41360966}],"con":true,"img":false}]}
{"op":"mcm","clk":"5346662610","pt":1646093729915,"mc":[{"id":"1.195395449","rc":[{"atl":[[110,0]],"id":40494151}],"con":true,"img":false}]}
{"op":"mcm","clk":"5346662614","pt":1646093730017,"mc":[{"id":"1.195395449","rc":[{"atl":[[100,0.54]],"id":40494151}],"con":true,"img":false}]}
{"op":"mcm","clk":"5346663196","pt":1646093746849,"mc":[{"id":"1.195395449","rc":[{"atl":[[100,0]],"id":40494151},{"atb":[[18,0]],"id":25760990}],"con":true,"img":false}]}
{"op":"mcm","clk":"5346663200","pt":1646093746901,"mc":[{"id":"1.195395449","rc":[{"atl":[[110,0.54]],"id":40494151},{"atb":[[19.5,2.7]],"id":25760990}],"con":true,"img":false}]}
{"op":"mcm","clk":"5346663665","pt":1646093763347,"mc":[{"id":"1.195395449","rc":[{"atl":[[170,0]],"id":41360966}],"con":true,"img":false}]}
{"op":"mcm","clk":"5346663669","pt":1646093763450,"mc":[{"id":"1.195395449","rc":[{"atl":[[160,0.25],[250,2.79]],"id":41360966}],"con":true,"img":false}]}
{"op":"mcm","clk":"5346663673","pt":1646093763552,"mc":[{"id":"1.195395449","rc":[{"atl":[[200,0.66]],"id":41360966}],"con":true,"img":false}]}
{"op":"mcm","clk":"5346663677","pt":1646093763653,"mc":[{"id":"1.195395449","rc":[{"atl":[[200,2.66],[250,0.79]],"id":41360966}],"con":true,"img":false}]}
{"op":"mcm","clk":"5346664732","pt":1646093796085,"mc":[{"id":"1.195395449","rc":[{"atl":[[110,0]],"id":40494151}],"con":true,"img":false}]}
{"op":"mcm","clk":"5346664736","pt":1646093796189,"mc":[{"id":"1.195395449","rc":[{"atl":[[100,0.54]],"id":40494151}],"con":true,"img":false}]}
{"op":"mcm","clk":"5346672773","pt":1646093812508,"mc":[{"id":"1.195395449","rc":[{"atl":[[100,0]],"id":40494151}],"con":true,"img":false}]}
{"op":"mcm","clk":"5346672779","pt":1646093812610,"mc":[{"id":"1.195395449","rc":[{"atl":[[110,0.54]],"id":40494151}],"con":true,"img":false}]}
{"op":"mcm","clk":"5346674016","pt":1646093844482,"mc":[{"id":"1.195395449","rc":[{"atl":[[110,0]],"id":40494151}],"con":true,"img":false}]}
{"op":"mcm","clk":"5346674021","pt":1646093844583,"mc":[{"id":"1.195395449","rc":[{"atl":[[100,0.54]],"id":40494151}],"con":true,"img":false}]}
{"op":"mcm","clk":"5346674563","pt":1646093860497,"mc":[{"id":"1.195395449","rc":[{"atl":[[100,0]],"id":40494151}],"con":true,"img":false}]}
{"op":"mcm","clk":"5346674568","pt":1646093860598,"mc":[{"id":"1.195395449","rc":[{"atl":[[110,0.54]],"id":40494151}],"con":true,"img":false}]}
{"op":"mcm","clk":"5346676212","pt":1646093908006,"mc":[{"id":"1.195395449","rc":[{"atl":[[110,0]],"id":40494151}],"con":true,"img":false}]}
{"op":"mcm","clk":"5346676216","pt":1646093908057,"mc":[{"id":"1.195395449","rc":[{"atl":[[100,0.54]],"id":40494151}],"con":true,"img":false}]}
{"op":"mcm","clk":"5346676809","pt":1646093924219,"mc":[{"id":"1.195395449","rc":[{"atl":[[100,0]],"id":40494151}],"con":true,"img":false}]}
{"op":"mcm","clk":"5346676813","pt":1646093924322,"mc":[{"id":"1.195395449","rc":[{"atl":[[110,0.54]],"id":40494151}],"con":true,"img":false}]}
{"op":"mcm","clk":"5346678449","pt":1646093971381,"mc":[{"id":"1.195395449","rc":[{"atl":[[110,0]],"id":40494151}],"con":true,"img":false}]}
{"op":"mcm","clk":"5346678453","pt":1646093971484,"mc":[{"id":"1.195395449","rc":[{"atl":[[100,0.54]],"id":40494151}],"con":true,"img":false}]}
{"op":"mcm","clk":"5346679554","pt":1646093999446,"mc":[{"id":"1.195395449","rc":[{"atl":[[100,0]],"id":40494151}],"con":true,"img":false}]}
{"op":"mcm","clk":"5346679558","pt":1646093999550,"mc":[{"id":"1.195395449","rc":[{"atl":[[110,0.54]],"id":40494151}],"con":true,"img":false}]}
{"op":"mcm","clk":"5346681644","pt":1646094058849,"mc":[{"id":"1.195395449","rc":[{"atl":[[110,0]],"id":40494151}],"con":true,"img":false}]}
{"op":"mcm","clk":"5346681650","pt":1646094058951,"mc":[{"id":"1.195395449","rc":[{"atl":[[100,0.54]],"id":40494151}],"con":true,"img":false}]}
{"op":"mcm","clk":"5346682277","pt":1646094074456,"mc":[{"id":"1.195395449","rc":[{"atl":[[100,0]],"id":40494151}],"con":true,"img":false}]}
{"op":"mcm","clk":"5346682282","pt":1646094074558,"mc":[{"id":"1.195395449","rc":[{"atl":[[110,0.54]],"id":40494151}],"con":true,"img":false}]}
{"op":"mcm","clk":"5346684040","pt":1646094116425,"mc":[{"id":"1.195395449","rc":[{"atl":[[110,0]],"id":40494151}],"con":true,"img":false}]}
{"op":"mcm","clk":"5346684046","pt":1646094116526,"mc":[{"id":"1.195395449","rc":[{"atl":[[100,0.54]],"id":40494151}],"con":true,"img":false}]}
{"op":"mcm","clk":"5346684657","pt":1646094131719,"mc":[{"id":"1.195395449","rc":[{"atl":[[100,0]],"id":40494151}],"con":true,"img":false}]}
{"op":"mcm","clk":"5346684660","pt":1646094131821,"mc":[{"id":"1.195395449","rc":[{"atl":[[110,0.54]],"id":40494151}],"con":true,"img":false}]}
{"op":"mcm","clk":"5346686351","pt":1646094172997,"mc":[{"id":"1.195395449","rc":[{"atl":[[110,0]],"id":40494151}],"con":true,"img":false}]}
{"op":"mcm","clk":"5346686355","pt":1646094173100,"mc":[{"id":"1.195395449","rc":[{"atl":[[100,0.54]],"id":40494151}],"con":true,"img":false}]}
{"op":"mcm","clk":"5346686915","pt":1646094188037,"mc":[{"id":"1.195395449","rc":[{"atl":[[100,0]],"id":40494151}],"con":true,"img":false}]}
{"op":"mcm","clk":"5346686918","pt":1646094188139,"mc":[{"id":"1.195395449","rc":[{"atl":[[110,0.54]],"id":40494151}],"con":true,"img":false}]}
{"op":"mcm","clk":"5346688455","pt":1646094228410,"mc":[{"id":"1.195395449","rc":[{"atl":[[110,0]],"id":40494151}],"con":true,"img":false}]}
{"op":"mcm","clk":"5346688457","pt":1646094228512,"mc":[{"id":"1.195395449","rc":[{"atl":[[100,0.54]],"id":40494151}],"con":true,"img":false}]}
{"op":"mcm","clk":"5346688897","pt":1646094242850,"mc":[{"id":"1.195395449","rc":[{"atl":[[100,0]],"id":40494151}],"con":true,"img":false}]}
{"op":"mcm","clk":"5346688900","pt":1646094242953,"mc":[{"id":"1.195395449","rc":[{"atl":[[110,0.54]],"id":40494151}],"con":true,"img":false}]}
{"op":"mcm","clk":"5346690037","pt":1646094282391,"mc":[{"id":"1.195395449","rc":[{"atl":[[110,0]],"id":40494151}],"con":true,"img":false}]}
{"op":"mcm","clk":"5346690039","pt":1646094282494,"mc":[{"id":"1.195395449","rc":[{"atl":[[100,0.54]],"id":40494151}],"con":true,"img":false}]}
{"op":"mcm","clk":"5346690446","pt":1646094297411,"mc":[{"id":"1.195395449","rc":[{"atb":[[16,0],[23,5.03]],"id":37495442},{"atl":[[100,0]],"id":40494151}],"con":true,"img":false}]}
{"op":"mcm","clk":"5346690449","pt":1646094297511,"mc":[{"id":"1.195395449","rc":[{"atl":[[110,0.54]],"id":40494151}],"con":true,"img":false}]}
{"op":"mcm","clk":"5346692935","pt":1646094361225,"mc":[{"id":"1.195395449","rc":[{"atb":[[22,0.49]],"id":37495442},{"atl":[[110,0]],"id":40494151}],"con":true,"img":false}]}
{"op":"mcm","clk":"5346692939","pt":1646094361325,"mc":[{"id":"1.195395449","rc":[{"atb":[[24,2.7]],"id":37495442},{"atl":[[100,0.54]],"id":40494151}],"con":true,"img":false}]}
{"op":"mcm","clk":"5346693417","pt":1646094375145,"mc":[{"id":"1.195395449","rc":[{"atl":[[100,0]],"id":40494151}],"con":true,"img":false}]}
{"op":"mcm","clk":"5346693420","pt":1646094375248,"mc":[{"id":"1.195395449","rc":[{"atl":[[110,0.54]],"id":40494151}],"con":true,"img":false}]}
{"op":"mcm","clk":"5346695837","pt":1646094437641,"mc":[{"id":"1.195395449","rc":[{"spn":62.0,"spf":1.0,"id":37495442},{"atl":[[110,0]],"id":40494151}],"con":true,"img":false}]}
{"op":"mcm","clk":"5346695841","pt":1646094437744,"mc":[{"id":"1.195395449","rc":[{"atl":[[100,0.54]],"id":40494151}],"con":true,"img":false}]}
{"op":"mcm","clk":"5346696402","pt":1646094451778,"mc":[{"id":"1.195395449","rc":[{"atl":[[100,0]],"id":40494151}],"con":true,"img":false}]}
{"op":"mcm","clk":"5346696403","pt":1646094451881,"mc":[{"id":"1.195395449","rc":[{"atl":[[110,0.54]],"id":40494151}],"con":true,"img":false}]}
{"op":"mcm","clk":"5346698561","pt":1646094511293,"mc":[{"id":"1.195395449","rc":[{"atl":[[110,0]],"id":40494151}],"con":true,"img":false}]}
{"op":"mcm","clk":"5346698562","pt":1646094511395,"mc":[{"id":"1.195395449","rc":[{"atl":[[100,0.54]],"id":40494151}],"con":true,"img":false}]}
{"op":"mcm","clk":"5346699064","pt":1646094525333,"mc":[{"id":"1.195395449","rc":[{"atl":[[100,0]],"id":40494151}],"con":true,"img":false}]}
{"op":"mcm","clk":"5346699069","pt":1646094525438,"mc":[{"id":"1.195395449","rc":[{"atl":[[110,0.54]],"id":40494151}],"con":true,"img":false}]}
{"op":"mcm","clk":"5346701030","pt":1646094583406,"mc":[{"id":"1.195395449","rc":[{"atl":[[110,0]],"id":40494151}],"con":true,"img":false}]}
{"op":"mcm","clk":"5346701031","pt":1646094583510,"mc":[{"id":"1.195395449","rc":[{"atl":[[100,0.54]],"id":40494151}],"con":true,"img":false}]}
{"op":"mcm","clk":"5346701533","pt":1646094597040,"mc":[{"id":"1.195395449","rc":[{"atl":[[100,0]],"id":40494151}],"con":true,"img":false}]}
{"op":"mcm","clk":"5346701536","pt":1646094597146,"mc":[{"id":"1.195395449","rc":[{"atl":[[110,0.54]],"id":40494151}],"con":true,"img":false}]}
{"op":"mcm","clk":"5346701561","pt":1646094597916,"mc":[{"id":"1.195395449","rc":[{"atl":[[640,0],[730,2]],"id":37495442},{"atb":[[8,14.29],[10,0]],"id":41360966},{"atb":[[5.6,0],[4.6,27.78]],"id":41962160},{"atb":[[8.6,13.16],[11,0]],"id":40494151},{"atl":[[1.84,0],[1.91,77.39]],"id":43066393}],"con":true,"img":false}]}
{"op":"mcm","clk":"5346702390","pt":1646094618576,"mc":[{"id":"1.195395449","rc":[{"atl":[[1.83,0]],"id":43066393}],"con":true,"img":false}]}
{"op":"mcm","clk":"5346702394","pt":1646094618678,"mc":[{"id":"1.195395449","rc":[{"atl":[[1.9,43.26]],"id":43066393}],"con":true,"img":false}]}
{"op":"mcm","clk":"5346703725","pt":1646094653129,"mc":[{"id":"1.195395449","rc":[{"atl":[[110,0]],"id":40494151}],"con":true,"img":false}]}
{"op":"mcm","clk":"5346703732","pt":1646094653232,"mc":[{"id":"1.195395449","rc":[{"atl":[[100,0.54]],"id":40494151}],"con":true,"img":false}]}
{"op":"mcm","clk":"5346704595","pt":1646094675873,"mc":[{"id":"1.195395449","rc":[{"atl":[[100,0]],"id":40494151}],"con":true,"img":false}]}
{"op":"mcm","clk":"5346704599","pt":1646094675976,"mc":[{"id":"1.195395449","rc":[{"atl":[[110,0.54]],"id":40494151}],"con":true,"img":false}]}
{"op":"mcm","clk":"5346706587","pt":1646094732048,"mc":[{"id":"1.195395449","rc":[{"atl":[[110,0]],"id":40494151}],"con":true,"img":false}]}
{"op":"mcm","clk":"5346706590","pt":1646094732152,"mc":[{"id":"1.195395449","rc":[{"atl":[[100,0.54]],"id":40494151}],"con":true,"img":false}]}
{"op":"mcm","clk":"5346707372","pt":1646094754204,"mc":[{"id":"1.195395449","rc":[{"atl":[[100,0]],"id":40494151}],"con":true,"img":false}]}
{"op":"mcm","clk":"5346707376","pt":1646094754306,"mc":[{"id":"1.195395449","rc":[{"atl":[[110,0.54]],"id":40494151}],"con":true,"img":false}]}
{"op":"mcm","clk":"5346708550","pt":1646094787127,"mc":[{"id":"1.195395449","rc":[{"atl":[[110,0]],"id":40494151}],"con":true,"img":false}]}
{"op":"mcm","clk":"5346708554","pt":1646094787229,"mc":[{"id":"1.195395449","rc":[{"atl":[[100,0.54]],"id":40494151}],"con":true,"img":false}]}
{"op":"mcm","clk":"5346709572","pt":1646094808906,"mc":[{"id":"1.195395449","rc":[{"atl":[[100,0]],"id":40494151}],"con":true,"img":false}]}
{"op":"mcm","clk":"5346709578","pt":1646094808958,"mc":[{"id":"1.195395449","rc":[{"atl":[[110,0.54]],"id":40494151}],"con":true,"img":false}]}
{"op":"mcm","clk":"5346711249","pt":1646094851380,"mc":[{"id":"1.195395449","rc":[{"atl":[[110,0]],"id":40494151}],"con":true,"img":false}]}
{"op":"mcm","clk":"5346711253","pt":1646094851437,"mc":[{"id":"1.195395449","rc":[{"atl":[[100,0.54]],"id":40494151}],"con":true,"img":false}]}
{"op":"mcm","clk":"5346712046","pt":1646094872415,"mc":[{"id":"1.195395449","rc":[{"atl":[[100,0]],"id":40494151}],"con":true,"img":false}]}
{"op":"mcm","clk":"5346712052","pt":1646094872471,"mc":[{"id":"1.195395449","rc":[{"atl":[[110,0.54]],"id":40494151}],"con":true,"img":false}]}
{"op":"mcm","clk":"5346713138","pt":1646094903371,"mc":[{"id":"1.195395449","rc":[{"atb":[[16.5,12.69],[17.5,3.03],[18.5,1.14],[15.5,8.62]],"id":37495442},{"atl":[[820,1],[840,1],[860,1],[880,1]],"id":37495442},{"atb":[[11.5,11.9],[12.5,16.49],[13.5,4],[14.5,1.48]],"id":40995914},{"atl":[[290,1],[310,1],[330,1],[350,1]],"id":40995914},{"atb":[[15.5,17.01],[16.5,4.84],[17.5,3.03],[18.5,1.14]],"id":41360966},{"atl":[[330,1],[350,1],[370,1],[390,1]],"id":41360966},{"atb":[[9.6,5.81],[10,12.67],[9.2,9.15],[8.8,31.63]],"id":41962160},{"atl":[[34,1],[38,1.35],[42,1.83],[46,2.78]],"id":41962160},{"atb":[[10.5,7.89],[11.5,4.76],[12.5,1.74],[9.8,23.42]],"id":40494151},{"atl":[[190,2.04],[210,1],[230,1],[250,1]],"id":40494151},{"atb":[[12,11.36],[13,6.25],[14,11.62],[15,1.43]],"id":25760990},{"atl":[[270,1],[290,1],[310,1.64],[250,1]],"id":25760990},{"atb":[[1.2,250],[1.26,76.92],[1.22,293.26],[1.24,208.33]],"id":43066393},{"atl":[[1.68,73.53],[1.7,107.14],[1.72,173.61],[1.66,30.3]],"id":43066393},{"atb":[[3.85,46],[3.95,6.78],[3.75,63.63],[3.65,72.34]],"id":40908100},{"atl":[[18,1.18],[19,2.78],[20,14.38],[22,5.95]],"id":40908100}],"con":true,"img":false}]}
{"op":"mcm","clk":"5346713141","pt":1646094903475,"mc":[{"id":"1.195395449","rc":[{"atl":[[46,5]],"id":41962160}],"con":true,"img":false}]}
{"op":"mcm","clk":"5346713147","pt":1646094903532,"mc":[{"id":"1.195395449","rc":[{"atl":[[70,1.91]],"id":41962160}],"con":true,"img":false}]}
{"op":"mcm","clk":"5346713349","pt":1646094909846,"mc":[{"id":"1.195395449","rc":[{"atb":[[18.5,0.58]],"id":40995914},{"atl":[[110,0]],"id":40494151},{"atb":[[19.5,0]],"id":25760990},{"atb":[[1.22,250]],"id":43066393}],"con":true,"img":false}]}
{"op":"mcm","clk":"5346713351","pt":1646094909950,"mc":[{"id":"1.195395449","rc":[{"atb":[[16.5,2.79]],"id":40995914},{"atl":[[100,0.54]],"id":40494151},{"atb":[[18,2.7]],"id":25760990},{"atb":[[1.25,532.04]],"id":43066393}],"con":true,"img":false}]}
{"op":"mcm","clk":"5346713668","pt":1646094919855,"mc":[{"id":"1.195395449","rc":[{"atl":[[100,0],[120,0.36]],"id":40494151}],"con":true,"img":false}]}
{"op":"mcm","clk":"5346713672","pt":1646094920007,"mc":[{"id":"1.195395449","rc":[{"atl":[[160,0]],"id":41360966}],"con":true,"img":false}]}
{"op":"mcm","clk":"5346713677","pt":1646094920059,"mc":[{"id":"1.195395449","rc":[{"atl":[[180,0.25]],"id":41360966}],"con":true,"img":false}]}
{"op":"mcm","clk":"5346713681","pt":1646094920162,"mc":[{"id":"1.195395449","rc":[{"atl":[[250,2.79]],"id":41360966}],"con":true,"img":false}]}
{"op":"mcm","clk":"5346713684","pt":1646094920265,"mc":[{"id":"1.195395449","rc":[{"atl":[[200,0.66]],"id":41360966}],"con":true,"img":false}]}
{"op":"mcm","clk":"5346713811","pt":1646094923407,"mc":[{"id":"1.195395449","rc":[{"atb":[[11,4.55]],"id":41962160}],"con":true,"img":false}]}
{"op":"mcm","clk":"5346713817","pt":1646094923510,"mc":[{"id":"1.195395449","rc":[{"atb":[[11.5,0.96]],"id":41962160}],"con":true,"img":false}]}
{"op":"mcm","clk":"5346714057","pt":1646094929885,"mc":[{"id":"1.195395449","rc":[{"atb":[[17,0]],"id":37495442},{"atl":[[430,0]],"id":41360966},{"atl":[[65,0]],"id":41962160},{"atb":[[14,3.85]],"id":25760990},{"atl":[[300,0]],"id":25760990},{"atl":[[19.5,0]],"id":40908100}],"con":true,"img":false}]}
{"op":"mcm","clk":"5346714061","pt":1646094929987,"mc":[{"id":"1.195395449","rc":[{"atb":[[18,7.57]],"id":37495442},{"atl":[[320,2.7]],"id":41360966},{"atl":[[60,0.8]],"id":41962160},{"atb":[[15.5,7.77]],"id":25760990},{"atl":[[260,3.47]],"id":25760990},{"atl":[[18.5,12.44]],"id":40908100}],"con":true,"img":false}]}
{"op":"mcm","clk":"5346714387","pt":1646094939099,"mc":[{"id":"1.195395449","rc":[{"atl":[[200,2.66],[250,0.79]],"id":41360966},{"spn":23.0,"spf":1.0,"id":41962160}],"con":true,"img":false}]}
{"op":"mcm","clk":"5346714411","pt":1646094939825,"mc":[{"id":"1.195395449","rc":[{"atl":[[120,0]],"id":40494151}],"con":true,"img":false}]}
{"op":"mcm","clk":"5346714416","pt":1646094939930,"mc":[{"id":"1.195395449","rc":[{"atl":[[110,0.36]],"id":40494151}],"con":true,"img":false}]}
{"op":"mcm","clk":"5346715117","pt":1646094958039,"mc":[{"id":"1.195395449","rc":[{"atl":[[180,0]],"id":41360966}],"con":true,"img":false}]}
{"op":"mcm","clk":"5346715120","pt":1646094958144,"mc":[{"id":"1.195395449","rc":[{"atl":[[170,0.25],[200,0.66],[250,2.79]],"id":41360966}],"con":true,"img":false}]}
{"op":"mcm","clk":"5346715207","pt":1646094960562,"mc":[{"id":"1.195395449","rc":[{"atb":[[15.5,7.94]],"id":40494151}],"con":true,"img":false}]}
{"op":"mcm","clk":"5346715212","pt":1646094960665,"mc":[{"id":"1.195395449","rc":[{"atb":[[16.5,0.66]],"id":40494151}],"con":true,"img":false}]}
{"op":"mcm","clk":"5346715412","pt":1646094966165,"mc":[{"id":"1.195395449","rc":[{"atl":[[320,3.7],[330,0]],"id":41360966},{"atb":[[12.5,0],[13,1.67]],"id":40494151},{"atl":[[190,1.04],[200,1]],"id":40494151}],"con":true,"img":false}]}
{"op":"mcm","clk":"5346715556","pt":1646094969861,"mc":[{"id":"1.195395449","rc":[{"atl":[[110,0]],"id":40494151}],"con":true,"img":false}]}
{"op":"mcm","clk":"5346715563","pt":1646094969962,"mc":[{"id":"1.195395449","rc":[{"atl":[[100,0.36]],"id":40494151}],"con":true,"img":false}]}
{"op":"mcm","clk":"5346715641","pt":1646094971656,"mc":[{"id":"1.195395449","rc":[{"atl":[[70,0.25]],"id":40494151},{"trd":[[70,3.31]],"ltp":70.0,"tv":3.31,"id":40494151}],"con":true,"img":false}]}
{"op":"mcm","clk":"5346715796","pt":1646094976183,"mc":[{"id":"1.195395449","rc":[{"atl":[[220,1]],"id":40494151}],"con":true,"img":false}]}
{"op":"mcm","clk":"5346715813","pt":1646094976698,"mc":[{"id":"1.195395449","rc":[{"atl":[[200,2.66],[250,0.79]],"id":41360966},{"atl":[[210,0],[230,0],[250,0]],"id":40494151}],"con":true,"img":false}]}
{"op":"mcm","clk":"5346716149","pt":1646094986228,"mc":[{"id":"1.195395449","rc":[{"atl":[[240,1]],"id":40494151}],"con":true,"img":false}]}
{"op":"mcm","clk":"5346716525","pt":1646094996250,"mc":[{"id":"1.195395449","rc":[{"atl":[[260,1]],"id":40494151}],"con":true,"img":false}]}
{"op":"mcm","clk":"5346716643","pt":1646094999956,"mc":[{"id":"1.195395449","rc":[{"atl":[[170,0]],"id":41360966},{"atl":[[100,0]],"id":40494151}],"con":true,"img":false}]}
{"op":"mcm","clk":"5346716645","pt":1646095000059,"mc":[{"id":"1.195395449","rc":[{"atl":[[160,0.25],[200,0.66],[250,2.79]],"id":41360966},{"atl":[[90,0.36]],"id":40494151}],"con":true,"img":false}]}
{"op":"mcm","clk":"5346717017","pt":1646095009953,"mc":[{"id":"1.195395449","rc":[{"atl":[[160,0]],"id":41360966}],"con":true,"img":false}]}
{"op":"mcm","clk":"5346717021","pt":1646095010105,"mc":[{"id":"1.195395449","rc":[{"atl":[[180,0.25]],"id":41360966}],"con":true,"img":false}]}
{"op":"mcm","clk":"5346717310","pt":1646095018179,"mc":[{"id":"1.195395449","rc":[{"atl":[[200,2.66],[250,0.79]],"id":41360966}],"con":true,"img":false}]}
{"op":"mcm","clk":"5346718023","pt":1646095039939,"mc":[{"id":"1.195395449","rc":[{"atl":[[180,0]],"id":41360966}],"con":true,"img":false}]}
{"op":"mcm","clk":"5346718026","pt":1646095040043,"mc":[{"id":"1.195395449","rc":[{"atl":[[170,0.25],[200,0.66],[250,2.79]],"id":41360966}],"con":true,"img":false}]}
{"op":"mcm","clk":"5346718372","pt":1646095049339,"mc":[{"id":"1.195395449","rc":[{"atl":[[90,0]],"id":40494151}],"con":true,"img":false}]}
{"op":"mcm","clk":"5346718375","pt":1646095049441,"mc":[{"id":"1.195395449","rc":[{"atl":[[120,0.36]],"id":40494151}],"con":true,"img":false}]}
{"op":"mcm","clk":"5346718659","pt":1646095057766,"mc":[{"id":"1.195395449","rc":[{"atl":[[200,2.66],[250,0.79]],"id":41360966}],"con":true,"img":false}]}
{"op":"mcm","clk":"5346719116","pt":1646095069927,"mc":[{"id":"1.195395449","rc":[{"atl":[[120,0]],"id":40494151}],"con":true,"img":false}]}
{"op":"mcm","clk":"5346719120","pt":1646095069977,"mc":[{"id":"1.195395449","rc":[{"atl":[[90,0.36]],"id":40494151}],"con":true,"img":false}]}
{"op":"mcm","clk":"5346719413","pt":1646095079923,"mc":[{"id":"1.195395449","rc":[{"atl":[[170,0]],"id":41360966}],"con":true,"img":false}]}
{"op":"mcm","clk":"5346719415","pt":1646095080027,"mc":[{"id":"1.195395449","rc":[{"atl":[[160,0.25],[250,2.79]],"id":41360966}],"con":true,"img":false}]}
{"op":"mcm","clk":"5346719420","pt":1646095080129,"mc":[{"id":"1.195395449","rc":[{"atl":[[200,0.66]],"id":41360966}],"con":true,"img":false}]}
{"op":"mcm","clk":"5346719430","pt":1646095080284,"mc":[{"id":"1.195395449","rc":[{"atl":[[200,2.66],[250,0.79]],"id":41360966}],"con":true,"img":false}]}
{"op":"mcm","clk":"5346719828","pt":1646095089862,"mc":[{"id":"1.195395449","rc":[{"atl":[[160,0]],"id":41360966}],"con":true,"img":false}]}
{"op":"mcm","clk":"5346719833","pt":1646095089912,"mc":[{"id":"1.195395449","rc":[{"atl":[[180,0.25]],"id":41360966}],"con":true,"img":false}]}
{"op":"mcm","clk":"5346719839","pt":1646095090013,"mc":[{"id":"1.195395449","rc":[{"atl":[[200,0.66],[250,2.79]],"id":41360966}],"con":true,"img":false}]}
{"op":"mcm","clk":"5346720491","pt":1646095107261,"mc":[{"id":"1.195395449","rc":[{"atl":[[200,2.66]],"id":41360966}],"con":true,"img":false}]}
{"op":"mcm","clk":"5346720495","pt":1646095107364,"mc":[{"id":"1.195395449","rc":[{"atl":[[250,0.79]],"id":41360966}],"con":true,"img":false}]}
{"op":"mcm","clk":"5346721350","pt":1646095129901,"mc":[{"id":"1.195395449","rc":[{"atl":[[180,0]],"id":41360966}],"con":true,"img":false}]}
{"op":"mcm","clk":"5346721355","pt":1646095130004,"mc":[{"id":"1.195395449","rc":[{"atl":[[170,0.25]],"id":41360966}],"con":true,"img":false}]}
{"op":"mcm","clk":"5346721358","pt":1646095130106,"mc":[{"id":"1.195395449","rc":[{"atl":[[200,0.66],[250,2.79]],"id":41360966}],"con":true,"img":false}]}
{"op":"mcm","clk":"5346721364","pt":1646095130209,"mc":[{"id":"1.195395449","rc":[{"atl":[[200,2.66]],"id":41360966}],"con":true,"img":false}]}
{"op":"mcm","clk":"5346721371","pt":1646095130312,"mc":[{"id":"1.195395449","rc":[{"atl":[[250,0.79]],"id":41360966}],"con":true,"img":false}]}
{"op":"mcm","clk":"5346721734","pt":1646095139431,"mc":[{"id":"1.195395449","rc":[{"atl":[[90,0]],"id":40494151}],"con":true,"img":false}]}
{"op":"mcm","clk":"5346721740","pt":1646095139533,"mc":[{"id":"1.195395449","rc":[{"atl":[[120,0.36]],"id":40494151}],"con":true,"img":false}]}
{"op":"mcm","clk":"5346722676","pt":1646095159961,"mc":[{"id":"1.195395449","rc":[{"atl":[[170,0]],"id":41360966},{"atl":[[120,0]],"id":40494151}],"con":true,"img":false}]}
{"op":"mcm","clk":"5346722680","pt":1646095160064,"mc":[{"id":"1.195395449","rc":[{"atl":[[160,0.25],[250,2.79]],"id":41360966},{"atl":[[90,0.36]],"id":40494151}],"con":true,"img":false}]}
{"op":"mcm","clk":"5346722684","pt":1646095160167,"mc":[{"id":"1.195395449","rc":[{"atl":[[200,0.66]],"id":41360966}],"con":true,"img":false}]}
{"op":"mcm","clk":"5346722688","pt":1646095160270,"mc":[{"id":"1.195395449","rc":[{"atl":[[200,2.66]],"id":41360966}],"con":true,"img":false}]}
{"op":"mcm","clk":"5346722693","pt":1646095160374,"mc":[{"id":"1.195395449","rc":[{"atl":[[250,0.79]],"id":41360966}],"con":true,"img":false}]}
{"op":"mcm","clk":"5346726554","pt":1646095254533,"mc":[{"id":"1.195395449","rc":[{"atl":[[820,0],[930,1]],"id":37495442},{"atl":[[280,0],[290,0],[200,2.66],[250,1.79]],"id":40995914},{"atb":[[8,0],[12.5,8.7]],"id":41360966},{"atb":[[5.3,23.26],[4.6,0]],"id":41962160},{"atb":[[8.6,0],[9.8,34.78]],"id":40494151},{"atb":[[10,0],[13,14.58]],"id":25760990},{"atl":[[260,4.47],[250,0]],"id":25760990},{"atl":[[1.64,31.25],[1.81,103.83],[1.91,0],[1.66,0]],"id":43066393}],"con":true,"img":false}]}
{"op":"mcm","clk":"5346726588","pt":1646095255608,"mc":[{"id":"1.195395449","rc":[{"atl":[[840,0]],"id":37495442}],"con":true,"img":false}]}
{"op":"mcm","clk":"5346726592","pt":1646095255812,"mc":[{"id":"1.195395449","rc":[{"atl":[[860,0]],"id":37495442}],"con":true,"img":false}]}
{"op":"mcm","clk":"5346726689","pt":1646095258834,"mc":[{"id":"1.195395449","rc":[{"atl":[[880,0]],"id":37495442}],"con":true,"img":false}]}
{"op":"mcm","clk":"5346726933","pt":1646095264510,"mc":[{"id":"1.195395449","rc":[{"atl":[[950,1]],"id":37495442},{"atl":[[270,1]],"id":40995914},{"atl":[[280,1]],"id":25760990},{"atl":[[1.66,75.76]],"id":43066393}],"con":true,"img":false}]}
{"op":"mcm","clk":"5346727067","pt":1646095268317,"mc":[{"id":"1.195395449","rc":[{"atl":[[350,0]],"id":40995914},{"atl":[[270,0],[290,0],[310,0.64]],"id":25760990},{"atl":[[1.72,0]],"id":43066393}],"con":true,"img":false}]}
{"op":"mcm","clk":"5346727117","pt":1646095269959,"mc":[{"id":"1.195395449","rc":[{"atl":[[260,1.76]],"id":25760990},{"atl":[[1.9,0]],"id":43066393}],"con":true,"img":false}]}
{"op":"mcm","clk":"5346727121","pt":1646095270061,"mc":[{"id":"1.195395449","rc":[{"atl":[[270,2.7]],"id":25760990},{"atl":[[1.8,43.26]],"id":43066393}],"con":true,"img":false}]}
{"op":"mcm","clk":"5346727262","pt":1646095274541,"mc":[{"id":"1.195395449","rc":[{"atl":[[290,1]],"id":40995914},{"atl":[[970,1]],"id":37495442},{"atl":[[300,1]],"id":25760990},{"atl":[[1.68,110.29]],"id":43066393}],"con":true,"img":false}]}
{"op":"mcm","clk":"5346727456","pt":1646095280543,"mc":[{"id":"1.195395449","rc":[{"atl":[[330,0]],"id":40995914}],"con":true,"img":false}]}
{"op":"mcm","clk":"5346727580","pt":1646095284552,"mc":[{"id":"1.195395449","rc":[{"atl":[[320,1]],"id":25760990},{"atl":[[1.7,178.57]],"id":43066393}],"con":true,"img":false}]}
{"op":"mcm","clk":"5346728913","pt":1646095327779,"mc":[{"id":"1.195395449","rc":[{"atl":[[730,0],[790,2]],"id":37495442}],"con":true,"img":false}]}
{"op":"mcm","clk":"5346730186","pt":1646095363828,"mc":[{"id":"1.195395449","rc":[{"atl":[[920,1]],"id":37495442},{"atl":[[260,0.76],[250,1]],"id":25760990}],"con":true,"img":false}]}
{"op":"mcm","clk":"5346730548","pt":1646095373760,"mc":[{"id":"1.195395449","rc":[{"atl":[[940,1]],"id":37495442}],"con":true,"img":false}]}
{"op":"mcm","clk":"5346730613","pt":1646095375463,"mc":[{"id":"1.195395449","rc":[{"atl":[[930,0],[950,0],[970,0]],"id":37495442}],"con":true,"img":false}]}
{"op":"mcm","clk":"5346730839","pt":1646095381583,"mc":[{"id":"1.195395449","rc":[{"atb":[[21,1.92]],"id":40995914},{"trd":[[21,0.2]],"ltp":21.0,"tv":0.2,"id":40995914}],"con":true,"img":false}]}
{"op":"mcm","clk":"5346730892","pt":1646095383383,"mc":[{"id":"1.195395449","rc":[{"atb":[[9.6,8.37]],"id":40995914}],"con":true,"img":false}]}
{"op":"mcm","clk":"5346730904","pt":1646095383746,"mc":[{"id":"1.195395449","rc":[{"atl":[[960,1]],"id":37495442}],"con":true,"img":false}]}
{"op":"mcm","clk":"5346732290","pt":1646095429355,"mc":[{"id":"1.195395449","rc":[{"atl":[[660,2],[790,0],[830,1]],"id":37495442},{"atl":[[260,1],[200,0.66]],"id":40995914},{"atl":[[260,1.76],[250,0]],"id":25760990},{"atl":[[1.64,0],[1.62,32.26]],"id":43066393}],"con":true,"img":false}]}
{"op":"mcm","clk":"5346732293","pt":1646095429456,"mc":[{"id":"1.195395449","rc":[{"atl":[[240,4.7],[250,0.79]],"id":40995914}],"con":true,"img":false}]}
{"op":"mcm","clk":"5346732567","pt":1646095439382,"mc":[{"id":"1.195395449","rc":[{"atl":[[280,1]],"id":40995914},{"atl":[[850,1]],"id":37495442},{"atl":[[1.64,78.13]],"id":43066393}],"con":true,"img":false}]}
{"op":"mcm","clk":"5346732675","pt":1646095442412,"mc":[{"id":"1.195395449","rc":[{"atl":[[270,0],[290,0],[310,0]],"id":40995914},{"atl":[[920,0],[940,0],[960,0]],"id":37495442},{"atl":[[1.7,0]],"id":43066393}],"con":true,"img":false}]}
{"op":"mcm","clk":"5346732928","pt":1646095449409,"mc":[{"id":"1.195395449","rc":[{"atl":[[870,1]],"id":37495442},{"atl":[[300,1.66]],"id":40995914},{"atl":[[1.66,113.64]],"id":43066393}],"con":true,"img":false}]}
{"op":"mcm","clk":"5346733147","pt":1646095455419,"mc":[{"id":"1.195395449","rc":[{"atb":[[17,1.25],[18.5,0],[19.5,5.4],[23,1.84]],"id":37495442},{"atb":[[1.2,0],[1.26,0],[1.22,0],[1.09,222.22],[1.24,0]],"id":43066393}],"con":true,"img":false}]}
{"op":"mcm","clk":"5346733290","pt":1646095459429,"mc":[{"id":"1.195395449","rc":[{"atl":[[320,1]],"id":40995914}],"con":true,"img":false}]}
{"op":"mcm","clk":"5346733304","pt":1646095459792,"mc":[{"id":"1.195395449","rc":[{"atb":[[17.5,0]],"id":37495442}],"con":true,"img":false}]}
{"op":"mcm","clk":"5346733308","pt":1646095459895,"mc":[{"id":"1.195395449","rc":[{"atb":[[24,0]],"id":37495442},{"atb":[[1.25,488.77]],"id":43066393}],"con":true,"img":false}]}
{"op":"mcm","clk":"5346733313","pt":1646095459996,"mc":[{"id":"1.195395449","rc":[{"atb":[[22,3.19]],"id":37495442},{"atb":[[1.22,43.26]],"id":43066393}],"con":true,"img":false}]}
{"op":"mcm","clk":"5346733471","pt":1646095465397,"mc":[{"id":"1.195395449","rc":[{"atb":[[16,3.33]],"id":37495442},{"atl":[[890,1]],"id":37495442},{"atb":[[1.07,250]],"id":43066393},{"atl":[[1.68,183.82]],"id":43066393}],"con":true,"img":false}]}
{"op":"mcm","clk":"5346733490","pt":1646095466014,"mc":[{"id":"1.195395449","rc":[{"atb":[[19.5,4.99]],"id":41360966},{"atb":[[12.5,2.76]],"id":41962160},{"atb":[[16,6.16]],"id":40494151},{"atb":[[17,5.78]],"id":25760990},{"atb":[[4.4,11.33]],"id":40908100}],"con":true,"img":false}]}
{"op":"mcm","clk":"5346733556","pt":1646095468021,"mc":[{"id":"1.195395449","rc":[{"atb":[[14,1.54]],"id":40995914},{"atl":[[320,2.7],[340,1]],"id":41360966},{"atb":[[16.5,0]],"id":40494151},{"atl":[[200,0],[210,1]],"id":40494151}],"con":true,"img":false}]}
{"op":"mcm","clk":"5346733559","pt":1646095468124,"mc":[{"id":"1.195395449","rc":[{"atb":[[14.5,0]],"id":40995914},{"atb":[[17,0.64]],"id":40494151}],"con":true,"img":false}]}
{"op":"mcm","clk":"5346733614","pt":1646095469927,"mc":[{"id":"1.195395449","rc":[{"atl":[[320,0]],"id":41360966}],"con":true,"img":false}]}
{"op":"mcm","clk":"5346733617","pt":1646095470031,"mc":[{"id":"1.195395449","rc":[{"atl":[[330,2.7]],"id":41360966}],"con":true,"img":false}]}
{"op":"mcm","clk":"5346733785","pt":1646095475425,"mc":[{"id":"1.195395449","rc":[{"atb":[[15,5.36]],"id":37495442},{"atb":[[1.05,250]],"id":43066393}],"con":true,"img":false}]}
{"op":"mcm","clk":"5346733873","pt":1646095478043,"mc":[{"id":"1.195395449","rc":[{"atb":[[13,4.17]],"id":40995914},{"atl":[[360,1]],"id":41360966},{"atl":[[230,1]],"id":40494151}],"con":true,"img":false}]}
{"op":"mcm","clk":"5346733932","pt":1646095479740,"mc":[{"id":"1.195395449","rc":[{"atb":[[11.5,0],[12.5,9.97],[13.5,0]],"id":40995914},{"atb":[[15.5,0],[16.5,7.85]],"id":37495442},{"atl":[[350,0],[370,0],[390,0]],"id":41360966},{"atl":[[260,0],[220,0],[240,0]],"id":40494151}],"con":true,"img":false}]}
{"op":"mcm","clk":"5346733935","pt":1646095479845,"mc":[{"id":"1.195395449","rc":[{"atb":[[16.5,0]],"id":40995914}],"con":true,"img":false}]}
{"op":"mcm","clk":"5346733938","pt":1646095479948,"mc":[{"id":"1.195395449","rc":[{"atb":[[18.5,3.37]],"id":40995914}],"con":true,"img":false}]}
{"op":"mcm","clk":"5346733961","pt":1646095480724,"mc":[{"id":"1.195395449","rc":[{"atl":[[830,0],[840,1]],"id":37495442},{"atl":[[1.62,0],[1.76,110.39],[1.81,0],[1.61,32.79]],"id":43066393}],"con":true,"img":false}]}
{"op":"mcm","clk":"5346734104","pt":1646095484529,"mc":[{"id":"1.195395449","rc":[{"atl":[[260,0],[270,1]],"id":40995914}],"con":true,"img":false}]}
{"op":"mcm","clk":"5346734256","pt":1646095488034,"mc":[{"id":"1.195395449","rc":[{"atl":[[380,1]],"id":41360966},{"atl":[[250,1]],"id":40494151}],"con":true,"img":false}]}
{"op":"mcm","clk":"5346734330","pt":1646095489898,"mc":[{"id":"1.195395449","rc":[{"atb":[[18,0],[19.5,11.67]],"id":37495442},{"spn":61.5,"spf":1.0,"id":37495442},{"atl":[[44,2.7],[60,0]],"id":41962160},{"spn":23.25,"spf":1.0,"id":41962160},{"atl":[[90,0]],"id":40494151},{"spn":8.45,"spf":1.0,"id":40908100}],"con":true,"img":false}]}
{"op":"mcm","clk":"5346734335","pt":1646095489941,"mc":[{"id":"1.195395449","rc":[{"atl":[[120,0.36]],"id":40494151}],"con":true,"img":false}]}
{"op":"mcm","clk":"5346734339","pt":1646095490044,"mc":[{"id":"1.195395449","rc":[{"atb":[[19.5,5.4]],"id":37495442}],"con":true,"img":false}]}
{"op":"mcm","clk":"5346734345","pt":1646095490148,"mc":[{"id":"1.195395449","rc":[{"atb":[[18.5,6.27]],"id":37495442}],"con":true,"img":false}]}
{"op":"mcm","clk":"5346734368","pt":1646095490770,"mc":[{"id":"1.195395449","rc":[{"atb":[[14,9.62]],"id":37495442},{"atl":[[860,1]],"id":37495442},{"atb":[[1.03,250]],"id":43066393}],"con":true,"img":false}]}
{"op":"mcm","clk":"5346734400","pt":1646095491385,"mc":[{"id":"1.195395449","rc":[{"atl":[[850,0],[870,0],[890,0]],"id":37495442},{"atl":[[270,0],[260,1]],"id":40995914}],"con":true,"img":false}]}
{"op":"mcm","clk":"5346734519","pt":1646095494172,"mc":[{"id":"1.195395449","rc":[{"atl":[[260,0]],"id":40995914},{"atl":[[840,0]],"id":37495442},{"atl":[[200,0.66],[240,2]],"id":41360966},{"atl":[[46,2.78],[55,2]],"id":41962160},{"atl":[[260,0.76]],"id":25760990},{"atl":[[1.6,33.33],[1.61,0]],"id":43066393}],"con":true,"img":false}]}
{"op":"mcm","clk":"5346734549","pt":1646095494793,"mc":[{"id":"1.195395449","rc":[{"atl":[[1.8,0]],"id":43066393}],"con":true,"img":false}]}
{"op":"mcm","clk":"5346734552","pt":1646095494843,"mc":[{"id":"1.195395449","rc":[{"atl":[[1.75,43.26]],"id":43066393}],"con":true,"img":false}]}
{"op":"mcm","clk":"5346734660","pt":1646095497539,"mc":[{"id":"1.195395449","rc":[{"atl":[[860,0],[870,1]],"id":37495442}],"con":true,"img":false}]}
{"op":"mcm","clk":"5346734680","pt":1646095498052,"mc":[{"id":"1.195395449","rc":[{"atl":[[400,1]],"id":41360966},{"atl":[[270,1]],"id":40494151}],"con":true,"img":false}]}
{"op":"mcm","clk":"5346734822","pt":1646095501397,"mc":[{"id":"1.195395449","rc":[{"atb":[[12,6.82]],"id":40995914},{"atl":[[340,1]],"id":40995914},{"atl":[[340,1]],"id":25760990}],"con":true,"img":false}]}
{"op":"mcm","clk":"5346734934","pt":1646095503862,"mc":[{"id":"1.195395449","rc":[{"atl":[[860,1]],"id":37495442}],"con":true,"img":false}]}
{"op":"mcm","clk":"5346734941","pt":1646095504069,"mc":[{"id":"1.195395449","rc":[{"atl":[[1.62,80.65]],"id":43066393}],"con":true,"img":false}]}
{"op":"mcm","clk":"5346735156","pt":1646095509686,"mc":[{"id":"1.195395449","rc":[{"atl":[[120,0]],"id":40494151}],"con":true,"img":false}]}
{"op":"mcm","clk":"5346735161","pt":1646095509790,"mc":[{"id":"1.195395449","rc":[{"atl":[[110,0.36]],"id":40494151}],"con":true,"img":false}]}
{"op":"mcm","clk":"5346735185","pt":1646095510304,"mc":[{"id":"1.195395449","rc":[{"atl":[[860,0]],"id":37495442},{"atl":[[1.68,0]],"id":43066393}],"con":true,"img":false}]}
{"op":"mcm","clk":"5346735226","pt":1646095511379,"mc":[{"id":"1.195395449","rc":[{"atb":[[11,12.5]],"id":40995914}],"con":true,"img":false}]}
{"op":"mcm","clk":"5346735340","pt":1646095513905,"mc":[{"id":"1.195395449","rc":[{"atl":[[860,1]],"id":37495442}],"con":true,"img":false}]}
{"op":"mcm","clk":"5346735351","pt":1646095514109,"mc":[{"id":"1.195395449","rc":[{"atl":[[1.64,117.19]],"id":43066393}],"con":true,"img":false}]}
{"op":"mcm","clk":"5346735726","pt":1646095522529,"mc":[{"id":"1.195395449","rc":[{"atl":[[860,0]],"id":37495442}],"con":true,"img":false}]}
{"op":"mcm","clk":"5346735787","pt":1646095523923,"mc":[{"id":"1.195395449","rc":[{"atl":[[860,1]],"id":37495442}],"con":true,"img":false}]}
{"op":"mcm","clk":"5346735797","pt":1646095524129,"mc":[{"id":"1.195395449","rc":[{"atl":[[1.66,189.39]],"id":43066393}],"con":true,"img":false}]}
{"op":"mcm","clk":"5346736037","pt":1646095529837,"mc":[{"id":"1.195395449","rc":[{"atb":[[18.5,0]],"id":37495442}],"con":true,"img":false}]}
{"op":"mcm","clk":"5346736041","pt":1646095529940,"mc":[{"id":"1.195395449","rc":[{"atb":[[19.5,11.67]],"id":37495442}],"con":true,"img":false}]}
{"op":"mcm","clk":"5346736212","pt":1646095533957,"mc":[{"id":"1.195395449","rc":[{"atl":[[880,1]],"id":37495442}],"con":true,"img":false}]}
{"op":"mcm","clk":"5346736272","pt":1646095535243,"mc":[{"id":"1.195395449","rc":[{"atl":[[860,0]],"id":37495442}],"con":true,"img":false}]}
{"op":"mcm","clk":"5346736467","pt":1646095539838,"mc":[{"id":"1.195395449","rc":[{"atl":[[110,0]],"id":40494151}],"con":true,"img":false}]}
{"op":"mcm","clk":"5346736471","pt":1646095539939,"mc":[{"id":"1.195395449","rc":[{"atl":[[100,0.36]],"id":40494151}],"con":true,"img":false}]}
{"op":"mcm","clk":"5346736488","pt":1646095540355,"mc":[{"id":"1.195395449","rc":[{"atl":[[860,1]],"id":37495442}],"con":true,"img":false}]}
{"op":"mcm","clk":"5346736761","pt":1646095547773,"mc":[{"id":"1.195395449","rc":[{"atl":[[860,0]],"id":37495442}],"con":true,"img":false}]}
{"op":"mcm","clk":"5346736834","pt":1646095549877,"mc":[{"id":"1.195395449","rc":[{"atl":[[100,0]],"id":40494151}],"con":true,"img":false}]}
{"op":"mcm","clk":"5346736839","pt":1646095549980,"mc":[{"id":"1.195395449","rc":[{"atl":[[120,0.36]],"id":40494151}],"con":true,"img":false}]}
{"op":"mcm","clk":"5346736855","pt":1646095550391,"mc":[{"id":"1.195395449","rc":[{"atl":[[860,1]],"id":37495442}],"con":true,"img":false}]}
{"op":"mcm","clk":"5346737228","pt":1646095560376,"mc":[{"id":"1.195395449","rc":[{"atl":[[900,1]],"id":37495442}],"con":true,"img":false}]}
{"op":"mcm","clk":"5346737683","pt":1646095570397,"mc":[{"id":"1.195395449","rc":[{"atl":[[920,1]],"id":37495442}],"con":true,"img":false}]}
{"op":"mcm","clk":"5346737766","pt":1646095572504,"mc":[{"id":"1.195395449","rc":[{"atl":[[860,0],[870,0],[880,0],[900,0],[920,0]],"id":37495442}],"con":true,"img":false}]}
{"op":"mcm","clk":"5346737958","pt":1646095577036,"mc":[{"id":"1.195395449","rc":[{"atl":[[860,1],[880,1],[900,1],[920,1]],"id":37495442}],"con":true,"img":false}]}
{"op":"mcm","clk":"5346738088","pt":1646095579826,"mc":[{"id":"1.195395449","rc":[{"atl":[[120,0]],"id":40494151}],"con":true,"img":false}]}
{"op":"mcm","clk":"5346738094","pt":1646095579928,"mc":[{"id":"1.195395449","rc":[{"atl":[[110,0.36]],"id":40494151}],"con":true,"img":false}]}
{"op":"mcm","clk":"5346738294","pt":1646095584661,"mc":[{"id":"1.195395449","rc":[{"atl":[[870,1]],"id":37495442}],"con":true,"img":false}]}
{"op":"mcm","clk":"5346738300","pt":1646095584766,"mc":[{"id":"1.195395449","rc":[{"atl":[[860,0]],"id":37495442}],"con":true,"img":false}]}
{"op":"mcm","clk":"5346738457","pt":1646095588546,"mc":[{"id":"1.195395449","rc":[{"atl":[[860,1],[870,0]],"id":37495442}],"con":true,"img":false}]}
{"op":"mcm","clk":"5346738797","pt":1646095596875,"mc":[{"id":"1.195395449","rc":[{"atl":[[860,0],[870,1]],"id":37495442}],"con":true,"img":false}]}
{"op":"mcm","clk":"5346738989","pt":1646095600682,"mc":[{"id":"1.195395449","rc":[{"atl":[[860,1],[870,0]],"id":37495442}],"con":true,"img":false}]}
{"op":"mcm","clk":"5346739348","pt":1646095608400,"mc":[{"id":"1.195395449","rc":[{"atl":[[860,0],[870,1]],"id":37495442}],"con":true,"img":false}]}
{"op":"mcm","clk":"5346739394","pt":1646095609279,"mc":[{"id":"1.195395449","rc":[{"atl":[[660,0],[730,2],[870,0]],"id":37495442},{"atl":[[280,2],[290,1],[210,0.63]],"id":25760990},{"atl":[[1.59,50.12],[1.6,0]],"id":43066393}],"con":true,"img":false}]}
{"op":"mcm","clk":"5346739421","pt":1646095609900,"mc":[{"id":"1.195395449","rc":[{"atl":[[110,0]],"id":40494151}],"con":true,"img":false}]}
{"op":"mcm","clk":"5346739425","pt":1646095610002,"mc":[{"id":"1.195395449","rc":[{"atl":[[100,0.36]],"id":40494151}],"con":true,"img":false}]}
{"op":"mcm","clk":"5346739762","pt":1646095618405,"mc":[{"id":"1.195395449","rc":[{"atl":[[940,1]],"id":37495442}],"con":true,"img":false}]}
{"op":"mcm","clk":"5346739798","pt":1646095619326,"mc":[{"id":"1.195395449","rc":[{"atl":[[310,1.64]],"id":25760990}],"con":true,"img":false}]}
{"op":"mcm","clk":"5346739822","pt":1646095619895,"mc":[{"id":"1.195395449","rc":[{"atl":[[100,0]],"id":40494151}],"con":true,"img":false}]}
{"op":"mcm","clk":"5346739825","pt":1646095619996,"mc":[{"id":"1.195395449","rc":[{"atl":[[120,0.36]],"id":40494151}],"con":true,"img":false}]}
{"op":"mcm","clk":"5346739863","pt":1646095620922,"mc":[{"id":"1.195395449","rc":[{"atl":[[880,0],[890,1]],"id":37495442},{"atl":[[300,0],[320,0],[340,0]],"id":25760990}],"con":true,"img":false}]}
{"op":"mcm","clk":"5346740005","pt":1646095624421,"mc":[{"id":"1.195395449","rc":[{"atl":[[890,0],[880,1]],"id":37495442}],"con":true,"img":false}]}
{"op":"mcm","clk":"5346740194","pt":1646095629309,"mc":[{"id":"1.195395449","rc":[{"atl":[[330,1]],"id":25760990}],"con":true,"img":false}]}
{"op":"mcm","clk":"5346740314","pt":1646095632449,"mc":[{"id":"1.195395449","rc":[{"atl":[[880,0],[890,1]],"id":37495442}],"con":true,"img":false}]}
{"op":"mcm","clk":"5346740521","pt":1646095637348,"mc":[{"id":"1.195395449","rc":[{"atl":[[890,0],[880,1]],"id":37495442}],"con":true,"img":false}]}
{"op":"mcm","clk":"5346740600","pt":1646095639349,"mc":[{"id":"1.195395449","rc":[{"atl":[[350,1]],"id":25760990}],"con":true,"img":false}]}
{"op":"mcm","clk":"5346740804","pt":1646095645254,"mc":[{"id":"1.195395449","rc":[{"atl":[[880,0],[890,1]],"id":37495442}],"con":true,"img":false}]}
{"op":"mcm","clk":"5346740947","pt":1646095649356,"mc":[{"id":"1.195395449","rc":[{"atl":[[890,0],[880,1]],"id":37495442}],"con":true,"img":false}]}
{"op":"mcm","clk":"5346740966","pt":1646095649871,"mc":[{"id":"1.195395449","rc":[{"atl":[[120,0]],"id":40494151}],"con":true,"img":false}]}
{"op":"mcm","clk":"5346740971","pt":1646095649974,"mc":[{"id":"1.195395449","rc":[{"atl":[[110,0.36]],"id":40494151}],"con":true,"img":false}]}
{"op":"mcm","clk":"5346741225","pt":1646095657676,"mc":[{"id":"1.195395449","rc":[{"atl":[[880,0],[890,1]],"id":37495442}],"con":true,"img":false}]}
{"op":"mcm","clk":"5346741374","pt":1646095662323,"mc":[{"id":"1.195395449","rc":[{"atl":[[880,1]],"id":37495442}],"con":true,"img":false}]}
{"op":"mcm","clk":"5346741377","pt":1646095662396,"mc":[{"id":"1.195395449","rc":[{"atl":[[890,0]],"id":37495442}],"con":true,"img":false}]}
{"op":"mcm","clk":"5346741560","pt":1646095669523,"mc":[{"id":"1.195395449","rc":[{"atl":[[880,0],[890,1]],"id":37495442}],"con":true,"img":false}]}
{"op":"mcm","clk":"5346741658","pt":1646095674618,"mc":[{"id":"1.195395449","rc":[{"atl":[[890,0],[880,1]],"id":37495442}],"con":true,"img":false}]}
{"op":"mcm","clk":"5346741724","pt":1646095678015,"mc":[{"id":"1.195395449","rc":[{"atb":[[4.4,14.19]],"id":40908100}],"con":true,"img":false}]}
{"op":"mcm","clk":"5346741769","pt":1646095679919,"mc":[{"id":"1.195395449","rc":[{"atl":[[110,0]],"id":40494151}],"con":true,"img":false}]}
{"op":"mcm","clk":"5346741774","pt":1646095680020,"mc":[{"id":"1.195395449","rc":[{"atl":[[100,0.36]],"id":40494151}],"con":true,"img":false}]}
{"op":"mcm","clk":"5346741827","pt":1646095681925,"mc":[{"id":"1.195395449","rc":[{"atl":[[880,0],[890,1]],"id":37495442}],"con":true,"img":false}]}
{"op":"mcm","clk":"5346741986","pt":1646095686427,"mc":[{"id":"1.195395449","rc":[{"atl":[[890,0],[880,1]],"id":37495442}],"con":true,"img":false}]}
{"op":"mcm","clk":"5346742092","pt":1646095689931,"mc":[{"id":"1.195395449","rc":[{"atl":[[100,0]],"id":40494151}],"con":true,"img":false}]}
{"op":"mcm","clk":"5346742095","pt":1646095690032,"mc":[{"id":"1.195395449","rc":[{"atl":[[120,0.36]],"id":40494151}],"con":true,"img":false}]}
{"op":"mcm","clk":"5346742207","pt":1646095694445,"mc":[{"id":"1.195395449","rc":[{"atl":[[880,0],[890,1]],"id":37495442}],"con":true,"img":false}]}
{"op":"mcm","clk":"5346742352","pt":1646095699474,"mc":[{"id":"1.195395449","rc":[{"atl":[[890,0],[880,1]],"id":37495442}],"con":true,"img":false}]}
{"op":"mcm","clk":"5346742392","pt":1646095701074,"mc":[{"id":"1.195395449","rc":[{"atl":[[880,0]],"id":37495442}],"con":true,"img":false}]}
{"op":"mcm","clk":"5346742550","pt":1646095706758,"mc":[{"id":"1.195395449","rc":[{"atl":[[900,0],[910,1]],"id":37495442}],"con":true,"img":false}]}
{"op":"mcm","clk":"5346742573","pt":1646095707688,"mc":[{"id":"1.195395449","rc":[{"atl":[[900,1]],"id":37495442}],"con":true,"img":false}]}
{"op":"mcm","clk":"5346742827","pt":1646095717684,"mc":[{"id":"1.195395449","rc":[{"atl":[[960,1]],"id":37495442}],"con":true,"img":false}]}
{"op":"mcm","clk":"5346742855","pt":1646095718974,"mc":[{"id":"1.195395449","rc":[{"atl":[[900,0],[920,0],[940,0],[960,0]],"id":37495442}],"con":true,"img":false}]}
{"op":"mcm","clk":"5346742859","pt":1646095719067,"mc":[{"id":"1.195395449","rc":[{"atl":[[910,0]],"id":37495442}],"con":true,"img":false}]}
{"op":"mcm","clk":"5346742881","pt":1646095719895,"mc":[{"id":"1.195395449","rc":[{"atl":[[120,0]],"id":40494151}],"con":true,"img":false}]}
{"op":"mcm","clk":"5346742884","pt":1646095719988,"mc":[{"id":"1.195395449","rc":[{"atl":[[110,0.36]],"id":40494151}],"con":true,"img":false}]}
{"op":"mcm","clk":"5346743004","pt":1646095724380,"mc":[{"id":"1.195395449","rc":[{"atl":[[900,1],[920,1],[940,1],[960,1]],"id":37495442}],"con":true,"img":false}]}
{"op":"mcm","clk":"5346743216","pt":1646095730700,"mc":[{"id":"1.195395449","rc":[{"atl":[[900,0],[910,1]],"id":37495442}],"con":true,"img":false}]}
{"op":"mcm","clk":"5346743404","pt":1646095736926,"mc":[{"id":"1.195395449","rc":[{"atl":[[900,1]],"id":37495442}],"con":true,"img":false}]}
{"op":"mcm","clk":"5346743408","pt":1646095737027,"mc":[{"id":"1.195395449","rc":[{"atl":[[910,0]],"id":37495442}],"con":true,"img":false}]}
{"op":"mcm","clk":"5346743481","pt":1646095740110,"mc":[{"id":"1.195395449","rc":[{"atb":[[1.09,0],[1.08,250]],"id":43066393}],"con":true,"img":false}]}
{"op":"mcm","clk":"5346743545","pt":1646095742624,"mc":[{"id":"1.195395449","rc":[{"atl":[[910,1]],"id":37495442}],"con":true,"img":false}]}
{"op":"mcm","clk":"5346743547","pt":1646095742727,"mc":[{"id":"1.195395449","rc":[{"atl":[[900,0]],"id":37495442}],"con":true,"img":false}]}
{"op":"mcm","clk":"5346743710","pt":1646095748330,"mc":[{"id":"1.195395449","rc":[{"atl":[[900,1]],"id":37495442}],"con":true,"img":false}]}
{"op":"mcm","clk":"5346743715","pt":1646095748434,"mc":[{"id":"1.195395449","rc":[{"atl":[[910,0]],"id":37495442}],"con":true,"img":false}]}
{"op":"mcm","clk":"5346743774","pt":1646095749863,"mc":[{"id":"1.195395449","rc":[{"atl":[[110,0]],"id":40494151}],"con":true,"img":false}]}
{"op":"mcm","clk":"5346743779","pt":1646095749967,"mc":[{"id":"1.195395449","rc":[{"atl":[[100,0.36]],"id":40494151}],"con":true,"img":false}]}
{"op":"mcm","clk":"5346743786","pt":1646095750121,"mc":[{"id":"1.195395449","rc":[{"atb":[[1.06,250]],"id":43066393}],"con":true,"img":false}]}
{"op":"mcm","clk":"5346743927","pt":1646095754745,"mc":[{"id":"1.195395449","rc":[{"atl":[[900,0],[910,1]],"id":37495442},{"atb":[[1.03,0],[1.07,0],[1.05,0]],"id":43066393}],"con":true,"img":false}]}
{"op":"mcm","clk":"5346744022","pt":1646095758355,"mc":[{"id":"1.195395449","rc":[{"atl":[[610,1]],"id":37495442},{"atl":[[230,1]],"id":40995914}],"con":true,"img":false}]}
{"op":"mcm","clk":"5346744026","pt":1646095758459,"mc":[{"id":"1.195395449","rc":[{"atl":[[730,0],[910,0],[480,2]],"id":37495442},{"atl":[[280,0],[200,2.66],[240,2.7]],"id":40995914},{"atl":[[200,2.66],[240,0]],"id":41360966},{"atl":[[34,0],[36,1],[44,5.03]],"id":41962160},{"atb":[[8,14.29],[9.8,23.42]],"id":40494151},{"atl":[[130,0],[110,2]],"id":40494151},{"atl":[[260,1.76],[280,0],[290,0],[210,2.63]],"id":25760990},{"atl":[[1.59,16.22],[1.61,32.79]],"id":43066393},{"atb":[[4.2,41.97],[3.75,27.27]],"id":40908100},{"atl":[[16.5,0],[23,12.75]],"id":40908100}],"con":true,"img":false}]}
{"op":"mcm","clk":"5346744029","pt":1646095758560,"mc":[{"id":"1.195395449","rc":[{"atl":[[55,0]],"id":41962160}],"con":true,"img":false}]}
{"op":"mcm","clk":"5346744081","pt":1646095759845,"mc":[{"id":"1.195395449","rc":[{"atl":[[270,0]],"id":25760990}],"con":true,"img":false}]}
{"op":"mcm","clk":"5346744084","pt":1646095759946,"mc":[{"id":"1.195395449","rc":[{"atl":[[300,2.7]],"id":25760990}],"con":true,"img":false}]}
{"op":"mcm","clk":"5346744119","pt":1646095761387,"mc":[{"id":"1.195395449","rc":[{"atb":[[1.2,2.23]],"id":41962160}],"con":true,"img":false}]}
{"op":"mcm","clk":"5346744129","pt":1646095761694,"mc":[{"id":"1.195395449","rc":[{"atb":[[1.2,1.88]],"id":41962160}],"con":true,"img":false}]}
{"op":"mcm","clk":"5346744135","pt":1646095762002,"mc":[{"id":"1.195395449","rc":[{"atb":[[1.2,0]],"id":41962160}],"con":true,"img":false}]}
{"op":"mcm","clk":"5346744137","pt":1646095762106,"mc":[{"id":"1.195395449","rc":[{"atb":[[13,1.88]],"id":41962160}],"con":true,"img":false}]}
{"op":"mcm","clk":"5346744147","pt":1646095762366,"mc":[{"id":"1.195395449","rc":[{"atb":[[4.5,6.45]],"id":40908100}],"con":true,"img":false}]}
{"op":"mcm","clk":"5346744216","pt":1646095764677,"mc":[{"id":"1.195395449","rc":[{"atb":[[4.4,2.86]],"id":40908100}],"con":true,"img":false}]}
{"op":"mcm","clk":"5346744239","pt":1646095765392,"mc":[{"id":"1.195395449","rc":[{"atb":[[4.4,0]],"id":40908100}],"con":true,"img":false}]}
{"op":"mcm","clk":"5346744280","pt":1646095767088,"mc":[{"id":"1.195395449","rc":[{"atb":[[3.9,3.17]],"id":40908100}],"con":true,"img":false}]}
{"op":"mcm","clk":"5346744304","pt":1646095768377,"mc":[{"id":"1.195395449","rc":[{"atl":[[250,1.79]],"id":40995914},{"atl":[[630,1]],"id":37495442},{"atl":[[40,1.28]],"id":41962160},{"atl":[[280,1]],"id":25760990},{"atb":[[1.04,250]],"id":43066393},{"atl":[[1.63,79.37]],"id":43066393}],"con":true,"img":false}]}
{"op":"mcm","clk":"5346744308","pt":1646095768606,"mc":[{"id":"1.195395449","rc":[{"atb":[[4.6,4.84]],"id":40908100}],"con":true,"img":false}]}
{"op":"mcm","clk":"5346744381","pt":1646095771179,"mc":[{"id":"1.195395449","rc":[{"atb":[[4.5,0]],"id":40908100}],"con":true,"img":false}]}
{"op":"mcm","clk":"5346744458","pt":1646095773796,"mc":[{"id":"1.195395449","rc":[{"atl":[[920,0],[940,0],[960,0]],"id":37495442},{"atl":[[300,0.66],[320,0],[340,0]],"id":40995914},{"atl":[[38,0],[42,0],[46,0]],"id":41962160},{"atl":[[310,0.64],[330,0],[350,0]],"id":25760990},{"atl":[[1.64,0],[1.62,0],[1.66,0]],"id":43066393}],"con":true,"img":false}]}
{"op":"mcm","clk":"5346744479","pt":1646095774410,"mc":[{"id":"1.195395449","rc":[{"atb":[[4.6,0]],"id":40908100}],"con":true,"img":false}]}
{"op":"mcm","clk":"5346744526","pt":1646095776005,"mc":[{"id":"1.195395449","rc":[{"atb":[[4.3,17.84]],"id":40908100}],"con":true,"img":false}]}
{"op":"mcm","clk":"5346744533","pt":1646095776210,"mc":[{"id":"1.195395449","rc":[{"atb":[[4.4,4.84]],"id":40908100}],"con":true,"img":false}]}
{"op":"mcm","clk":"5346744544","pt":1646095776521,"mc":[{"id":"1.195395449","rc":[{"atb":[[3.9,0]],"id":40908100}],"con":true,"img":false}]}
{"op":"mcm","clk":"5346744554","pt":1646095776786,"mc":[{"id":"1.195395449","rc":[{"atb":[[21,11.33]],"id":40494151}],"con":true,"img":false}]}
{"op":"mcm","clk":"5346744579","pt":1646095777710,"mc":[{"id":"1.195395449","rc":[{"atl":[[610,0],[620,1]],"id":37495442},{"atl":[[1.6,33.33]],"id":43066393}],"con":true,"img":false}]}
{"op":"mcm","clk":"5346744597","pt":1646095778386,"mc":[{"id":"1.195395449","rc":[{"atl":[[270,1]],"id":40995914},{"atl":[[44,6.77]],"id":41962160},{"atl":[[300,3.7]],"id":25760990},{"atb":[[4.5,3.63]],"id":40908100}],"con":true,"img":false}]}
{"op":"mcm","clk":"5346744606","pt":1646095778589,"mc":[{"id":"1.195395449","rc":[{"atl":[[610,1]],"id":37495442},{"atl":[[1.6,0],[1.62,32.26]],"id":43066393}],"con":true,"img":false}]}
{"op":"mcm","clk":"5346744641","pt":1646095779921,"mc":[{"id":"1.195395449","rc":[{"atl":[[520,0]],"id":37495442},{"atl":[[240,0]],"id":40995914},{"atl":[[100,0]],"id":40494151}],"con":true,"img":false}]}
{"op":"mcm","clk":"5346744643","pt":1646095780025,"mc":[{"id":"1.195395449","rc":[{"atl":[[470,2.7]],"id":37495442},{"atl":[[220,2.7]],"id":40995914},{"atl":[[90,0.36]],"id":40494151}],"con":true,"img":false}]}
{"op":"mcm","clk":"5346744653","pt":1646095780386,"mc":[{"id":"1.195395449","rc":[{"atb":[[16,0]],"id":40494151}],"con":true,"img":false}]}
{"op":"mcm","clk":"5346744658","pt":1646095780593,"mc":[{"id":"1.195395449","rc":[{"atl":[[610,0]],"id":37495442},{"atb":[[11.5,0]],"id":41962160},{"atl":[[1.61,0]],"id":43066393}],"con":true,"img":false}]}
{"op":"mcm","clk":"5346744662","pt":1646095780695,"mc":[{"id":"1.195395449","rc":[{"atb":[[11,5.56]],"id":41962160}],"con":true,"img":false}]}
{"op":"mcm","clk":"5346744711","pt":1646095782287,"mc":[{"id":"1.195395449","rc":[{"atb":[[4.3,20.62]],"id":40908100}],"con":true,"img":false}]}
{"op":"mcm","clk":"5346744749","pt":1646095784290,"mc":[{"id":"1.195395449","rc":[{"atb":[[18.5,5.28]],"id":40494151}],"con":true,"img":false}]}
{"op":"mcm","clk":"5346744881","pt":1646095788400,"mc":[{"id":"1.195395449","rc":[{"atl":[[290,1]],"id":40995914},{"atl":[[48,2.66]],"id":41962160},{"atl":[[320,1]],"id":25760990}],"con":true,"img":false}]}
{"op":"mcm","clk":"5346744889","pt":1646095788605,"mc":[{"id":"1.195395449","rc":[{"atl":[[640,1]],"id":37495442},{"atb":[[1.02,250]],"id":43066393},{"atl":[[1.64,78.13]],"id":43066393}],"con":true,"img":false}]}
{"op":"mcm","clk":"5346744918","pt":1646095789425,"mc":[{"id":"1.195395449","rc":[{"atl":[[1.61,32.79]],"id":43066393},{"atb":[[4.3,41.25],[4.2,12.67]],"id":40908100}],"con":true,"img":false}]}
{"op":"mcm","clk":"5346744931","pt":1646095789938,"mc":[{"id":"1.195395449","rc":[{"atl":[[90,0]],"id":40494151},{"atl":[[300,1]],"id":25760990}],"con":true,"img":false}]}
{"op":"mcm","clk":"5346744936","pt":1646095790043,"mc":[{"id":"1.195395449","rc":[{"atl":[[100,0.36]],"id":40494151},{"atl":[[270,2.7]],"id":25760990}],"con":true,"img":false}]}
{"op":"mcm","clk":"5346744974","pt":1646095791121,"mc":[{"id":"1.195395449","rc":[{"atb":[[4.3,38.52]],"id":40908100}],"con":true,"img":false}]}
{"op":"mcm","clk":"5346745123","pt":1646095796525,"mc":[{"id":"1.195395449","rc":[{"atb":[[18,0]],"id":40494151}],"con":true,"img":false}]}
{"op":"mcm","clk":"5346745129","pt":1646095796626,"mc":[{"id":"1.195395449","rc":[{"atb":[[19,3.32]],"id":40494151}],"con":true,"img":false}]}
{"op":"mcm","clk":"5346745184","pt":1646095798627,"mc":[{"id":"1.195395449","rc":[{"atl":[[660,1]],"id":37495442},{"spn":24.5,"spf":1.0,"id":41962160},{"spn":45.5,"spf":1.0,"id":40494151},{"spn":8.5,"spf":1.0,"id":40908100}],"con":true,"img":false}]}
{"op":"mcm","clk":"5346745188","pt":1646095798856,"mc":[{"id":"1.195395449","rc":[{"atb":[[19.5,6.27]],"id":37495442}],"con":true,"img":false}]}
{"op":"mcm","clk":"5346745192","pt":1646095798960,"mc":[{"id":"1.195395449","rc":[{"atb":[[19,10.06]],"id":37495442}],"con":true,"img":false}]}
{"op":"mcm","clk":"5346745213","pt":1646095799425,"mc":[{"id":"1.195395449","rc":[{"atl":[[1.65,115.38]],"id":43066393}],"con":true,"img":false}]}
{"op":"mcm","clk":"5346745225","pt":1646095799735,"mc":[{"id":"1.195395449","rc":[{"atb":[[18.5,0]],"id":40494151}],"con":true,"img":false}]}
{"op":"mcm","clk":"5346745236","pt":1646095800037,"mc":[{"id":"1.195395449","rc":[{"atb":[[4.4,7.49]],"id":40908100}],"con":true,"img":false}]}
{"op":"mcm","clk":"5346745299","pt":1646095801735,"mc":[{"id":"1.195395449","rc":[{"atl":[[1.64,0],[1.62,0]],"id":43066393}],"con":true,"img":false}]}
{"op":"mcm","clk":"5346745353","pt":1646095803628,"mc":[{"id":"1.195395449","rc":[{"atb":[[19.5,4.99]],"id":40494151}],"con":true,"img":false}]}
{"op":"mcm","clk":"5346745455","pt":1646095806557,"mc":[{"id":"1.195395449","rc":[{"atb":[[4.3,35.74]],"id":40908100}],"con":true,"img":false}]}
{"op":"mcm","clk":"5346745520","pt":1646095808663,"mc":[{"id":"1.195395449","rc":[{"atl":[[680,1]],"id":37495442}],"con":true,"img":false}]}
{"op":"mcm","clk":"5346745553","pt":1646095809487,"mc":[{"id":"1.195395449","rc":[{"atl":[[1.67,186.57]],"id":43066393}],"con":true,"img":false}]}
{"op":"mcm","clk":"5346745573","pt":1646095810050,"mc":[{"id":"1.195395449","rc":[{"atl":[[630,0]],"id":37495442}],"con":true,"img":false}]}
{"op":"mcm","clk":"5346745641","pt":1646095812767,"mc":[{"id":"1.195395449","rc":[{"atb":[[4.4,10.19]],"id":40908100}],"con":true,"img":false}]}
{"op":"mcm","clk":"5346745720","pt":1646095815482,"mc":[{"id":"1.195395449","rc":[{"atl":[[220,3.7],[230,0]],"id":40995914},{"atb":[[4,6.67],[3.95,0]],"id":40908100}],"con":true,"img":false}]}
{"op":"mcm","clk":"5346745871","pt":1646095819898,"mc":[{"id":"1.195395449","rc":[{"atb":[[19,0]],"id":40494151}],"con":true,"img":false}]}
{"op":"mcm","clk":"5346745877","pt":1646095819949,"mc":[{"id":"1.195395449","rc":[{"atb":[[20,3.32]],"id":40494151}],"con":true,"img":false}]}
{"op":"mcm","clk":"5346745960","pt":1646095822968,"mc":[{"id":"1.195395449","rc":[{"atb":[[19.5,0]],"id":40494151}],"con":true,"img":false}]}
{"op":"mcm","clk":"5346746315","pt":1646095835010,"mc":[{"id":"1.195395449","rc":[{"atl":[[1000,1.67]],"id":41962160},{"atl":[[1000,1.67]],"id":40908100}],"con":true,"img":false}]}
{"op":"mcm","clk":"5346746321","pt":1646095835217,"mc":[{"id":"1.195395449","rc":[{"atl":[[1000,0.24]],"id":41962160},{"atl":[[1000,0.69]],"id":40908100}],"con":true,"img":false}]}
{"op":"mcm","clk":"5346746329","pt":1646095835524,"mc":[{"id":"1.195395449","rc":[{"atl":[[1000,0]],"id":40908100}],"con":true,"img":false}]}
{"op":"mcm","clk":"5346746332","pt":1646095835626,"mc":[{"id":"1.195395449","rc":[{"atl":[[12,0.69]],"id":40908100}],"con":true,"img":false}]}
{"op":"mcm","clk":"5346746342","pt":1646095835831,"mc":[{"id":"1.195395449","rc":[{"atl":[[1000,0]],"id":41962160}],"con":true,"img":false}]}
{"op":"mcm","clk":"5346746345","pt":1646095835933,"mc":[{"id":"1.195395449","rc":[{"atl":[[34,0.24]],"id":41962160}],"con":true,"img":false}]}
{"op":"mcm","clk":"5346746348","pt":1646095836086,"mc":[{"id":"1.195395449","rc":[{"atl":[[42,2.44],[44,4.44]],"id":41962160}],"con":true,"img":false}]}
{"op":"mcm","clk":"5346746442","pt":1646095839941,"mc":[{"id":"1.195395449","rc":[{"atb":[[20,0]],"id":40494151}],"con":true,"img":false}]}
{"op":"mcm","clk":"5346746445","pt":1646095840044,"mc":[{"id":"1.195395449","rc":[{"atb":[[19,3.32]],"id":40494151}],"con":true,"img":false}]}
{"op":"mcm","clk":"5346746536","pt":1646095843735,"mc":[{"id":"1.195395449","rc":[{"atb":[[19.5,4.99]],"id":40494151}],"con":true,"img":false}]}
{"op":"mcm","clk":"5346746560","pt":1646095844510,"mc":[{"id":"1.195395449","rc":[{"atl":[[330,3.7],[340,0]],"id":41360966},{"atl":[[210,0],[220,1]],"id":40494151},{"atl":[[260,0.76],[250,1]],"id":25760990}],"con":true,"img":false}]}
{"op":"mcm","clk":"5346746562","pt":1646095844609,"mc":[{"id":"1.195395449","rc":[{"atb":[[17,0]],"id":40494151}],"con":true,"img":false}]}
{"op":"mcm","clk":"5346746565","pt":1646095844711,"mc":[{"id":"1.195395449","rc":[{"atb":[[18,0.6]],"id":40494151}],"con":true,"img":false}]}
{"op":"mcm","clk":"5346746700","pt":1646095849925,"mc":[{"id":"1.195395449","rc":[{"atl":[[44,1.74]],"id":41962160}],"con":true,"img":false}]}
{"op":"mcm","clk":"5346746704","pt":1646095850026,"mc":[{"id":"1.195395449","rc":[{"atl":[[46,2.7]],"id":41962160}],"con":true,"img":false}]}
{"op":"mcm","clk":"5346746871","pt":1646095854540,"mc":[{"id":"1.195395449","rc":[{"atl":[[240,1]],"id":40494151}],"con":true,"img":false}]}
{"op":"mcm","clk":"5346746920","pt":1646095856743,"mc":[{"id":"1.195395449","rc":[{"atl":[[270,0],[230,0],[250,0]],"id":40494151}],"con":true,"img":false}]}
{"op":"mcm","clk":"5346747002","pt":1646095860025,"mc":[{"id":"1.195395449","rc":[{"atl":[[180,0]],"id":37495442},{"atl":[[160,0]],"id":41360966},{"spn":23.5,"spf":1.0,"id":41962160},{"spn":8.25,"spf":1.0,"id":40908100}],"con":true,"img":false}]}
{"op":"mcm","clk":"5346747005","pt":1646095860127,"mc":[{"id":"1.195395449","rc":[{"atl":[[150,0.24]],"id":37495442},{"atl":[[140,0.25],[200,0.66],[250,2.79]],"id":41360966}],"con":true,"img":false}]}
{"op":"mcm","clk":"5346747009","pt":1646095860229,"mc":[{"id":"1.195395449","rc":[{"atl":[[200,2.66],[250,0.79]],"id":41360966}],"con":true,"img":false}]}
{"op":"mcm","clk":"5346747144","pt":1646095864480,"mc":[{"id":"1.195395449","rc":[{"atb":[[19,0]],"id":40494151},{"atl":[[260,1]],"id":40494151}],"con":true,"img":false}]}
{"op":"mcm","clk":"5346747148","pt":1646095864581,"mc":[{"id":"1.195395449","rc":[{"atb":[[20,3.32]],"id":40494151}],"con":true,"img":false}]}
{"op":"mcm","clk":"5346747162","pt":1646095865042,"mc":[{"id":"1.195395449","rc":[{"atb":[[1.03,1.67]],"id":41962160},{"atb":[[4.6,1.81]],"id":40908100}],"con":true,"img":false}]}
{"op":"mcm","clk":"5346747167","pt":1646095865144,"mc":[{"id":"1.195395449","rc":[{"atb":[[1.03,0.61]],"id":41962160},{"atb":[[1.02,1.67]],"id":40494151}],"con":true,"img":false}]}
{"op":"mcm","clk":"5346747172","pt":1646095865348,"mc":[{"id":"1.195395449","rc":[{"atb":[[1.03,0]],"id":41962160}],"con":true,"img":false}]}
{"op":"mcm","clk":"5346747176","pt":1646095865451,"mc":[{"id":"1.195395449","rc":[{"atb":[[13.5,0.61]],"id":41962160}],"con":true,"img":false}]}
{"op":"mcm","clk":"5346747181","pt":1646095865654,"mc":[{"id":"1.195395449","rc":[{"atb":[[1.02,0.37]],"id":40494151}],"con":true,"img":false}]}
{"op":"mcm","clk":"5346747190","pt":1646095865860,"mc":[{"id":"1.195395449","rc":[{"atb":[[1.02,0]],"id":40494151}],"con":true,"img":false}]}
{"op":"mcm","clk":"5346747193","pt":1646095865962,"mc":[{"id":"1.195395449","rc":[{"atb":[[22,0.37]],"id":40494151}],"con":true,"img":false}]}
{"op":"mcm","clk":"5346747227","pt":1646095866941,"mc":[{"id":"1.195395449","rc":[{"atb":[[19.5,0]],"id":40494151}],"con":true,"img":false}]}
{"op":"mcm","clk":"5346747490","pt":1646095874479,"mc":[{"id":"1.195395449","rc":[{"atl":[[280,1]],"id":40494151}],"con":true,"img":false}]}
{"op":"mcm","clk":"5346747495","pt":1646095874682,"mc":[{"id":"1.195395449","rc":[{"atl":[[620,0],[710,1]],"id":37495442},{"atb":[[8,0],[9.6,11.63]],"id":40494151},{"atl":[[140,3.42],[110,0]],"id":40494151},{"atb":[[4.3,15.11],[3.75,63.63]],"id":40908100},{"atl":[[18,7.06],[23,8.2]],"id":40908100},{"atl":[[1.66,30.3],[1.61,0]],"id":43066393}],"con":true,"img":false}]}
{"op":"mcm","clk":"5346747506","pt":1646095874990,"mc":[{"id":"1.195395449","rc":[{"atb":[[1.07,2.77]],"id":40995914},{"atb":[[1.05,2.8]],"id":41962160},{"atb":[[1.02,2.92]],"id":40908100},{"atb":[[1.02,253.4]],"id":43066393}],"con":true,"img":false}]}
{"op":"mcm","clk":"5346747521","pt":1646095875503,"mc":[{"id":"1.195395449","rc":[{"atb":[[1.07,0.07]],"id":40995914},{"atb":[[1.05,0.09]],"id":41962160},{"atb":[[1.02,0.22]],"id":40908100},{"atb":[[1.02,250.69]],"id":43066393}],"con":true,"img":false}]}
{"op":"mcm","clk":"5346747534","pt":1646095875864,"mc":[{"id":"1.195395449","rc":[{"atb":[[20,0]],"id":40494151}],"con":true,"img":false}]}
{"op":"mcm","clk":"5346747540","pt":1646095875967,"mc":[{"id":"1.195395449","rc":[{"atb":[[1.07,0]],"id":40995914},{"atb":[[19,3.32]],"id":40494151},{"atb":[[1.02,0]],"id":40908100},{"atb":[[1.02,250]],"id":43066393}],"con":true,"img":false}]}
{"op":"mcm","clk":"5346747545","pt":1646095876072,"mc":[{"id":"1.195395449","rc":[{"atb":[[15.5,8.46]],"id":40995914},{"atb":[[1.05,0]],"id":41962160},{"atb":[[4.8,0.22]],"id":40908100},{"atl":[[1.49,15.52]],"id":43066393},{"trd":[[1.49,1.39]],"ltp":1.49,"tv":1.39,"id":43066393}],"con":true,"img":false}]}
{"op":"mcm","clk":"5346747547","pt":1646095876170,"mc":[{"id":"1.195395449","rc":[{"atb":[[11,5.66]],"id":41962160},{"atb":[[1.25,486.77]],"id":43066393},{"atb":[[4.3,13.11]],"id":40908100}],"con":true,"img":false}]}
{"op":"mcm","clk":"5346747552","pt":1646095876275,"mc":[{"id":"1.195395449","rc":[{"atb":[[4.4,12.19]],"id":40908100}],"con":true,"img":false}]}
{"op":"mcm","clk":"5346747575","pt":1646095876789,"mc":[{"id":"1.195395449","rc":[{"atb":[[1.38,4.22]],"id":43066393}],"con":true,"img":false}]}
{"op":"mcm","clk":"5346747614","pt":1646095877814,"mc":[{"id":"1.195395449","rc":[{"atb":[[11,4.65]],"id":41962160}],"con":true,"img":false}]}
{"op":"mcm","clk":"5346747621","pt":1646095877866,"mc":[{"id":"1.195395449","rc":[{"atb":[[11.5,0.96]],"id":41962160}],"con":true,"img":false}]}
{"op":"mcm","clk":"5346747643","pt":1646095878377,"mc":[{"id":"1.195395449","rc":[{"atb":[[19.5,4.99]],"id":40494151}],"con":true,"img":false}]}
{"op":"mcm","clk":"5346747658","pt":1646095878787,"mc":[{"id":"1.195395449","rc":[{"atl":[[640,0]],"id":37495442},{"atl":[[1.63,0]],"id":43066393}],"con":true,"img":false}]}
{"op":"mcm","clk":"5346747735","pt":1646095881301,"mc":[{"id":"1.195395449","rc":[{"atb":[[4.4,9.54]],"id":40908100}],"con":true,"img":false}]}
{"op":"mcm","clk":"5346747742","pt":1646095881505,"mc":[{"id":"1.195395449","rc":[{"atl":[[660,0]],"id":37495442},{"atl":[[1.76,0],[1.82,86.54],[1.67,29.85],[1.65,0]],"id":43066393}],"con":true,"img":false}]}
{"op":"mcm","clk":"5346747751","pt":1646095881709,"mc":[{"id":"1.195395449","rc":[{"atl":[[1.48,4]],"id":43066393}],"con":true,"img":false}]}
{"op":"mcm","clk":"5346747756","pt":1646095881813,"mc":[{"id":"1.195395449","rc":[{"atb":[[16.5,0],[19,5.56],[23,0],[11.5,6.86]],"id":37495442},{"atl":[[260,0],[310,0],[160,0],[210,0]],"id":37495442},{"atb":[[12,0],[6.8,0],[9.8,14.2],[8.8,0]],"id":40494151},{"atl":[[70,0],[140,2],[95,0],[190,0]],"id":40494151},{"atb":[[11.5,0],[16.5,0],[19,0],[23,0]],"id":25760990},{"atl":[[260,0],[310,0],[160,0],[210,2]],"id":25760990},{"atb":[[1.25,0],[1.15,0],[1.3,0],[1.35,0]],"id":43066393},{"atl":[[2.54,0],[2.64,0],[2.84,0],[2.74,0]],"id":43066393}],"con":true,"img":false}]}
{"op":"mcm","clk":"5346747767","pt":1646095882023,"mc":[{"id":"1.195395449","rc":[{"atl":[[140,0],[220,3]],"id":40494151},{"atl":[[210,0],[250,3]],"id":25760990}],"con":true,"img":false}]}
{"op":"mcm","clk":"5346747796","pt":1646095882693,"mc":[{"id":"1.195395449","rc":[{"atl":[[680,0]],"id":37495442},{"atb":[[23,3]],"id":41962160},{"atl":[[1.47,4]],"id":43066393}],"con":true,"img":false}]}
{"op":"mcm","clk":"5346747800","pt":1646095882796,"mc":[{"id":"1.195395449","rc":[{"atl":[[1.66,0]],"id":43066393}],"con":true,"img":false}]}
{"op":"mcm","clk":"5346747846","pt":1646095884281,"mc":[{"id":"1.195395449","rc":[{"atb":[[17,0]],"id":25760990},{"atb":[[1.37,22.58]],"id":43066393}],"con":true,"img":false}]}
{"op":"mcm","clk":"5346747849","pt":1646095884381,"mc":[{"id":"1.195395449","rc":[{"atl":[[100,0]],"id":40494151}],"con":true,"img":false}]}
{"op":"mcm","clk":"5346747853","pt":1646095884484,"mc":[{"id":"1.195395449","rc":[{"atl":[[120,0.36]],"id":40494151}],"con":true,"img":false}]}
{"op":"mcm","clk":"5346747858","pt":1646095884617,"mc":[{"id":"1.195395449","rc":[{"atb":[[1.37,0]],"id":43066393}],"con":true,"img":false}]}
{"op":"mcm","clk":"5346747862","pt":1646095884689,"mc":[{"id":"1.195395449","rc":[{"atl":[[730,1]],"id":37495442}],"con":true,"img":false}]}
{"op":"mcm","clk":"5346747871","pt":1646095884893,"mc":[{"id":"1.195395449","rc":[{"atb":[[23,0]],"id":41962160},{"trd":[[23,6]],"ltp":23.0,"tv":6.0,"id":41962160}],"con":true,"img":false}]}
{"op":"mcm","clk":"5346747874","pt":1646095884995,"mc":[{"id":"1.195395449","rc":[{"atb":[[11.5,0]],"id":41962160}],"con":true,"img":false}]}
{"op":"mcm","clk":"5346747903","pt":1646095885818,"mc":[{"id":"1.195395449","rc":[{"atb":[[1.38,0]],"id":43066393}],"con":true,"img":false}]}
{"op":"mcm","clk":"5346747910","pt":1646095886020,"mc":[{"id":"1.195395449","rc":[{"atb":[[1.02,1.67]],"id":37495442},{"atb":[[1.02,1.67]],"id":41360966}],"con":true,"img":false}]}
{"op":"mcm","clk":"5346747914","pt":1646095886126,"mc":[{"id":"1.195395449","rc":[{"atb":[[12.5,0],[13,0]],"id":41962160}],"con":true,"img":false}]}
{"op":"mcm","clk":"5346747919","pt":1646095886224,"mc":[{"id":"1.195395449","rc":[{"atb":[[1.02,0.35]],"id":37495442},{"atb":[[1.02,0.35]],"id":41360966}],"con":true,"img":false}]}
{"op":"mcm","clk":"5346747923","pt":1646095886277,"mc":[{"id":"1.195395449","rc":[{"atb":[[1.23,4.22]],"id":43066393}],"con":true,"img":false}]}
{"op":"mcm","clk":"5346747928","pt":1646095886382,"mc":[{"id":"1.195395449","rc":[{"atb":[[1.02,0]],"id":41360966}],"con":true,"img":false}]}
{"op":"mcm","clk":"5346747931","pt":1646095886483,"mc":[{"id":"1.195395449","rc":[{"atb":[[23,0.35]],"id":41360966}],"con":true,"img":false}]}
{"op":"mcm","clk":"5346747935","pt":1646095886584,"mc":[{"id":"1.195395449","rc":[{"atb":[[11.5,22.25],[16.5,7.82],[19,10.04],[23,1.83]],"id":37495442},{"atl":[[260,0.76],[310,0.64],[160,0.83],[210,0.63]],"id":37495442},{"atb":[[14,11.99],[9.6,35.81],[16.5,6.7],[19,6.21]],"id":40494151},{"atl":[[140,0.78],[290,0.56],[190,0.57],[240,1.68]],"id":40494151},{"atb":[[11.5,15.39],[16.5,7.82],[19,4.48],[23,1.83]],"id":25760990},{"atl":[[260,0.76],[310,0.64],[160,0.83],[210,0.63]],"id":25760990},{"atb":[[1.25,484.91],[1.15,1077.58],[1.3,269.39],[1.35,115.45]],"id":43066393},{"atl":[[2.54,86.03],[2.64,80.78],[2.84,108.01],[2.74,114.21]],"id":43066393}],"con":true,"img":false}]}
{"op":"mcm","clk":"5346747940","pt":1646095886688,"mc":[{"id":"1.195395449","rc":[{"atb":[[1.02,0]],"id":37495442},{"atl":[[620,1]],"id":37495442},{"atb":[[9.6,6.98]],"id":41962160},{"atb":[[1.35,112.45]],"id":43066393},{"atl":[[1.48,0],[1.47,0],[1.61,32.79]],"id":43066393},{"trd":[[1.35,6]],"ltp":1.35,"tv":6.0,"id":43066393},{"atb":[[4.3,25.79],[3.75,27.27]],"id":40908100},{"atl":[[18,1.18],[24,4.35]],"id":40908100}],"con":true,"img":false}]}
{"op":"mcm","clk":"5346747944","pt":1646095886791,"mc":[{"id":"1.195395449","rc":[{"atb":[[24,0.35]],"id":37495442}],"con":true,"img":false}]}
{"op":"mcm","clk":"5346747995","pt":1646095888124,"mc":[{"id":"1.195395449","rc":[{"atb":[[16,6.16]],"id":25760990}],"con":true,"img":false}]}
{"op":"mcm","clk":"5346748050","pt":1646095889917,"mc":[{"id":"1.195395449","rc":[{"atl":[[120,0]],"id":40494151}],"con":true,"img":false}]}
{"op":"mcm","clk":"5346748056","pt":1646095890022,"mc":[{"id":"1.195395449","rc":[{"atl":[[130,0.36]],"id":40494151}],"con":true,"img":false}]}
{"op":"mcm","clk":"5346748061","pt":1646095890125,"mc":[{"id":"1.195395449","rc":[{"atb":[[12.5,3.23]],"id":41962160}],"con":true,"img":false}]}
{"op":"mcm","clk":"5346748077","pt":1646095890535,"mc":[{"id":"1.195395449","rc":[{"atb":[[1.34,27.99],[1.35,84.43]],"id":43066393},{"trd":[[1.35,62.03]],"ltp":1.35,"tv":62.03,"id":43066393}],"con":true,"img":false}]}
{"op":"mcm","clk":"5346748089","pt":1646095890796,"mc":[{"id":"1.195395449","rc":[{"atl":[[1.82,0],[1.72,77.39]],"id":43066393},{"atl":[[1000,2.23]],"id":40908100}],"con":true,"img":false}]}
{"op":"mcm","clk":"5346748097","pt":1646095890999,"mc":[{"id":"1.195395449","rc":[{"atb":[[1.2,2.23]],"id":41962160}],"con":true,"img":false}]}
{"op":"mcm","clk":"5346748108","pt":1646095891305,"mc":[{"id":"1.195395449","rc":[{"atb":[[1.2,1.96]],"id":41962160},{"atl":[[190,2.57],[220,1]],"id":40494151},{"atl":[[210,2.63],[250,1]],"id":25760990}],"con":true,"img":false}]}
{"op":"mcm","clk":"5346748117","pt":1646095891513,"mc":[{"id":"1.195395449","rc":[{"atb":[[1.2,0],[9.6,5.94]],"id":41962160},{"atl":[[1.75,0]],"id":43066393}],"con":true,"img":false}]}
{"op":"mcm","clk":"5346748120","pt":1646095891613,"mc":[{"id":"1.195395449","rc":[{"atb":[[12.5,5.2]],"id":41962160},{"atl":[[1.81,43.26]],"id":43066393}],"con":true,"img":false}]}
{"op":"mcm","clk":"5346748122","pt":1646095891715,"mc":[{"id":"1.195395449","rc":[{"atl":[[720,1]],"id":37495442},{"atb":[[19,2.88]],"id":40494151},{"atb":[[1.34,0]],"id":43066393},{"atl":[[1.66,29.98],[1.61,0]],"id":43066393},{"atb":[[4.3,13.11],[3.8,35.71]],"id":40908100},{"atl":[[18,7.06],[24,0]],"id":40908100}],"con":true,"img":false}]}
{"op":"mcm","clk":"5346748128","pt":1646095891818,"mc":[{"id":"1.195395449","rc":[{"atl":[[620,0]],"id":37495442},{"atb":[[20,3.32]],"id":40494151}],"con":true,"img":false}]}
{"op":"mcm","clk":"5346748143","pt":1646095892126,"mc":[{"id":"1.195395449","rc":[{"atb":[[16,0]],"id":25760990},{"atl":[[1000,0.14]],"id":40908100}],"con":true,"img":false}]}
{"op":"mcm","clk":"5346748171","pt":1646095893002,"mc":[{"id":"1.195395449","rc":[{"atl":[[1000,0]],"id":40908100}],"con":true,"img":false}]}
{"op":"mcm","clk":"5346748175","pt":1646095893103,"mc":[{"id":"1.195395449","rc":[{"atl":[[12,0.84]],"id":40908100}],"con":true,"img":false}]}
{"op":"mcm","clk":"5346748181","pt":1646095893309,"mc":[{"id":"1.195395449","rc":[{"atb":[[18,0]],"id":25760990}],"con":true,"img":false}]}
{"op":"mcm","clk":"5346748186","pt":1646095893415,"mc":[{"id":"1.195395449","rc":[{"atb":[[19.5,2.7]],"id":25760990}],"con":true,"img":false}]}
{"op":"mcm","clk":"5346748202","pt":1646095893922,"mc":[{"id":"1.195395449","rc":[{"atb":[[1.23,0]],"id":43066393}],"con":true,"img":false}]}
{"op":"mcm","clk":"5346748205","pt":1646095894024,"mc":[{"id":"1.195395449","rc":[{"atb":[[19.5,0]],"id":40494151}],"con":true,"img":false}]}
{"op":"mcm","clk":"5346748230","pt":1646095894841,"mc":[{"id":"1.195395449","rc":[{"atl":[[710,0]],"id":37495442}],"con":true,"img":false}]}
{"op":"mcm","clk":"5346748240","pt":1646095895202,"mc":[{"id":"1.195395449","rc":[{"atb":[[1.03,1.67],[13.5,0]],"id":41962160}],"con":true,"img":false}]}
{"op":"mcm","clk":"5346748245","pt":1646095895303,"mc":[{"id":"1.195395449","rc":[{"atb":[[1.03,0.61]],"id":41962160},{"atb":[[4.9,1.7],[4.6,0]],"id":40908100}],"con":true,"img":false}]}
{"op":"mcm","clk":"5346748254","pt":1646095895510,"mc":[{"id":"1.195395449","rc":[{"atb":[[1.03,0]],"id":41962160}],"con":true,"img":false}]}
{"op":"mcm","clk":"5346748258","pt":1646095895611,"mc":[{"id":"1.195395449","rc":[{"atb":[[23,3.42]],"id":37495442},{"atb":[[19,1.55]],"id":40995914},{"atb":[[23,1.94]],"id":41360966},{"atb":[[13,2.12]],"id":41962160},{"atb":[[22,1.88]],"id":40494151},{"atb":[[19.5,4.35]],"id":25760990},{"atb":[[4.6,1.52]],"id":40908100}],"con":true,"img":false}]}
{"op":"mcm","clk":"5346748264","pt":1646095895814,"mc":[{"id":"1.195395449","rc":[{"atb":[[4.9,0],[4.6,3.22]],"id":40908100}],"con":true,"img":false}]}
{"op":"mcm","clk":"5346748269","pt":1646095895918,"mc":[{"id":"1.195395449","rc":[{"atb":[[20,3.79]],"id":25760990}],"con":true,"img":false}]}
{"op":"mcm","clk":"5346748272","pt":1646095896020,"mc":[{"id":"1.195395449","rc":[{"atl":[[42,3.82]],"id":41962160},{"atb":[[4.9,1.7],[4.6,1.52]],"id":40908100},{"atl":[[12,2.14]],"id":40908100},{"atl":[[1.72,0],[1.81,102.96]],"id":43066393}],"con":true,"img":false}]}
{"op":"mcm","clk":"5346748281","pt":1646095896328,"mc":[{"id":"1.195395449","rc":[{"atb":[[19.5,2.7]],"id":25760990}],"con":true,"img":false}]}
{"op":"mcm","clk":"5346748284","pt":1646095896427,"mc":[{"id":"1.195395449","rc":[{"atb":[[21,2.16]],"id":25760990}],"con":true,"img":false}]}
{"op":"mcm","clk":"5346748310","pt":1646095897143,"mc":[{"id":"1.195395449","rc":[{"atb":[[4.4,6.84]],"id":40908100}],"con":true,"img":false}]}
{"op":"mcm","clk":"5346748335","pt":1646095897916,"mc":[{"id":"1.195395449","rc":[{"atb":[[4.5,0]],"id":40908100}],"con":true,"img":false}]}
{"op":"mcm","clk":"5346748362","pt":1646095898733,"mc":[{"id":"1.195395449","rc":[{"atl":[[690,1]],"id":37495442},{"atb":[[12.5,0]],"id":41360966},{"atb":[[10,10.45],[9.8,11.09]],"id":41962160},{"atb":[[4.6,0]],"id":40908100},{"atl":[[1.94,77.39],[1.81,43.26],[1.74,26.74],[1.66,0]],"id":43066393}],"con":true,"img":false}]}
{"op":"mcm","clk":"5346748367","pt":1646095898836,"mc":[{"id":"1.195395449","rc":[{"atb":[[10.5,27.61]],"id":41360966},{"atb":[[4.5,1.52]],"id":40908100}],"con":true,"img":false}]}
{"op":"mcm","clk":"5346748404","pt":1646095899808,"mc":[{"id":"1.195395449","rc":[{"atb":[[20,0]],"id":25760990}],"con":true,"img":false}]}
{"op":"mcm","clk":"5346748409","pt":1646095899912,"mc":[{"id":"1.195395449","rc":[{"atl":[[18.5,0]],"id":40908100}],"con":true,"img":false}]}
{"op":"mcm","clk":"5346748412","pt":1646095900015,"mc":[{"id":"1.195395449","rc":[{"atl":[[19.5,12.44]],"id":40908100}],"con":true,"img":false}]}
{"op":"mcm","clk":"5346748423","pt":1646095900323,"mc":[{"id":"1.195395449","rc":[{"atl":[[690,0],[700,1]],"id":37495442},{"atl":[[1.67,0]],"id":43066393}],"con":true,"img":false}]}
{"op":"mcm","clk":"5346748433","pt":1646095900527,"mc":[{"id":"1.195395449","rc":[{"atb":[[21,0.51]],"id":25760990}],"con":true,"img":false}]}
{"op":"mcm","clk":"5346748436","pt":1646095900631,"mc":[{"id":"1.195395449","rc":[{"atb":[[19.5,4.35]],"id":25760990}],"con":true,"img":false}]}
{"op":"mcm","clk":"5346748465","pt":1646095901754,"mc":[{"id":"1.195395449","rc":[{"atb":[[4.6,2.58]],"id":40908100}],"con":true,"img":false}]}
{"op":"mcm","clk":"5346748491","pt":1646095902321,"mc":[{"id":"1.195395449","rc":[{"atb":[[4.5,0]],"id":40908100}],"con":true,"img":false}]}
{"op":"mcm","clk":"5346748496","pt":1646095902421,"mc":[{"id":"1.195395449","rc":[{"atb":[[4.6,4.1]],"id":40908100}],"con":true,"img":false}]}
{"op":"mcm","clk":"5346748536","pt":1646095903650,"mc":[{"id":"1.195395449","rc":[{"atb":[[20,4.87]],"id":25760990}],"con":true,"img":false}]}
{"op":"mcm","clk":"5346748553","pt":1646095904163,"mc":[{"id":"1.195395449","rc":[{"atb":[[20,0]],"id":40494151},{"atb":[[19.5,2.7]],"id":25760990},{"atl":[[1.81,0]],"id":43066393}],"con":true,"img":false}]}
{"op":"mcm","clk":"5346748558","pt":1646095904218,"mc":[{"id":"1.195395449","rc":[{"atb":[[19,6.21]],"id":40494151},{"atb":[[21,2.16]],"id":25760990},{"atl":[[1.93,43.26]],"id":43066393}],"con":true,"img":false}]}
{"op":"mcm","clk":"5346748621","pt":1646095906724,"mc":[{"id":"1.195395449","rc":[{"atl":[[700,0],[710,1]],"id":37495442}],"con":true,"img":false}]}
{"op":"mcm","clk":"5346748624","pt":1646095906829,"mc":[{"id":"1.195395449","rc":[{"atb":[[4.9,0],[4.7,1.7]],"id":40908100}],"con":true,"img":false}]}
{"op":"mcm","clk":"5346748627","pt":1646095906930,"mc":[{"id":"1.195395449","rc":[{"atb":[[4.9,1.7]],"id":40908100}],"con":true,"img":false}]}
{"op":"mcm","clk":"5346748630","pt":1646095907033,"mc":[{"id":"1.195395449","rc":[{"atb":[[4.7,0]],"id":40908100}],"con":true,"img":false}]}
{"op":"mcm","clk":"5346748648","pt":1646095907646,"mc":[{"id":"1.195395449","rc":[{"atb":[[19.5,4.99]],"id":40494151},{"atb":[[20,0]],"id":25760990}],"con":true,"img":false}]}
{"op":"mcm","clk":"5346748668","pt":1646095908161,"mc":[{"id":"1.195395449","rc":[{"atb":[[19,0],[20,5.8]],"id":41360966}],"con":true,"img":false}]}
{"op":"mcm","clk":"5346748673","pt":1646095908262,"mc":[{"id":"1.195395449","rc":[{"atb":[[21,0.51]],"id":25760990},{"atb":[[3.9,3.1]],"id":40908100}],"con":true,"img":false}]}
{"op":"mcm","clk":"5346748676","pt":1646095908366,"mc":[{"id":"1.195395449","rc":[{"atb":[[19.5,4.35]],"id":25760990}],"con":true,"img":false}]}
{"op":"mcm","clk":"5346748684","pt":1646095908728,"mc":[{"id":"1.195395449","rc":[{"atb":[[9.4,4.89]],"id":41962160},{"atl":[[1.76,65.1]],"id":43066393}],"con":true,"img":false}]}
{"op":"mcm","clk":"5346748688","pt":1646095908881,"mc":[{"id":"1.195395449","rc":[{"atb":[[3.9,6.28]],"id":40908100}],"con":true,"img":false}]}
{"op":"mcm","clk":"5346748709","pt":1646095909447,"mc":[{"id":"1.195395449","rc":[{"atl":[[700,1]],"id":37495442},{"atb":[[9.2,0],[9.6,1.17],[8.8,15.6]],"id":41962160}],"con":true,"img":false}]}
{"op":"mcm","clk":"5346748765","pt":1646095911549,"mc":[{"id":"1.195395449","rc":[{"atb":[[19.5,0]],"id":41360966},{"atb":[[20,4.87]],"id":25760990}],"con":true,"img":false}]}
{"op":"mcm","clk":"5346748778","pt":1646095912164,"mc":[{"id":"1.195395449","rc":[{"atb":[[20,0]],"id":41360966}],"con":true,"img":false}]}
{"op":"mcm","clk":"5346748782","pt":1646095912267,"mc":[{"id":"1.195395449","rc":[{"atb":[[18.5,6.94]],"id":41360966}],"con":true,"img":false}]}
{"op":"mcm","clk":"5346748866","pt":1646095914775,"mc":[{"id":"1.195395449","rc":[{"atl":[[700,0]],"id":37495442}],"con":true,"img":false}]}
{"op":"mcm","clk":"5346748883","pt":1646095915441,"mc":[{"id":"1.195395449","rc":[{"atb":[[19,5.14]],"id":41360966}],"con":true,"img":false}]}
{"op":"mcm","clk":"5346748931","pt":1646095917383,"mc":[{"id":"1.195395449","rc":[{"atl":[[700,1]],"id":37495442}],"con":true,"img":false}]}
{"op":"mcm","clk":"5346748937","pt":1646095917588,"mc":[{"id":"1.195395449","rc":[{"atb":[[4.7,1.7]],"id":40908100}],"con":true,"img":false}]}
{"op":"mcm","clk":"5346748941","pt":1646095917644,"mc":[{"id":"1.195395449","rc":[{"atb":[[4.9,0]],"id":40908100}],"con":true,"img":false}]}
{"op":"mcm","clk":"5346748945","pt":1646095917744,"mc":[{"id":"1.195395449","rc":[{"atb":[[5,1.67]],"id":40908100}],"con":true,"img":false}]}
{"op":"mcm","clk":"5346748951","pt":1646095917848,"mc":[{"id":"1.195395449","rc":[{"atb":[[4.7,0]],"id":40908100}],"con":true,"img":false}]}
{"op":"mcm","clk":"5346748982","pt":1646095918779,"mc":[{"id":"1.195395449","rc":[{"atb":[[9,7.7]],"id":41962160},{"atl":[[1.78,95.14]],"id":43066393}],"con":true,"img":false}]}
{"op":"mcm","clk":"5346749013","pt":1646095920075,"mc":[{"id":"1.195395449","rc":[{"spn":62.0,"spf":1.0,"id":37495442},{"spn":61.5,"spf":1.0,"id":41360966},{"spn":61.0,"spf":1.0,"id":40494151},{"spn":1.42,"spf":1.0,"id":43066393},{"atb":[[4.4,2]],"id":40908100},{"spn":8.5,"spf":1.0,"id":40908100}],"con":true,"img":false}]}
{"op":"mcm","clk":"5346749015","pt":1646095920156,"mc":[{"id":"1.195395449","rc":[{"atb":[[15.5,0]],"id":40494151}],"con":true,"img":false}]}
{"op":"mcm","clk":"5346749017","pt":1646095920262,"mc":[{"id":"1.195395449","rc":[{"atb":[[17,7.94]],"id":40494151}],"con":true,"img":false}]}
{"op":"mcm","clk":"5346749075","pt":1646095922256,"mc":[{"id":"1.195395449","rc":[{"atb":[[11,0.09]],"id":41962160}],"con":true,"img":false}]}
{"op":"mcm","clk":"5346749078","pt":1646095922412,"mc":[{"id":"1.195395449","rc":[{"atb":[[11.5,4.55]],"id":41962160}],"con":true,"img":false}]}
{"op":"mcm","clk":"5346749085","pt":1646095922569,"mc":[{"id":"1.195395449","rc":[{"atl":[[700,0]],"id":37495442}],"con":true,"img":false}]}
{"op":"mcm","clk":"5346749099","pt":1646095923080,"mc":[{"id":"1.195395449","rc":[{"atb":[[4.6,1.52]],"id":40908100}],"con":true,"img":false}]}
{"op":"mcm","clk":"5346749105","pt":1646095923387,"mc":[{"id":"1.195395449","rc":[{"atb":[[4.6,0]],"id":40908100}],"con":true,"img":false}]}
{"op":"mcm","clk":"5346749108","pt":1646095923489,"mc":[{"id":"1.195395449","rc":[{"atb":[[4.4,3.52]],"id":40908100}],"con":true,"img":false}]}
{"op":"mcm","clk":"5346749123","pt":1646095924103,"mc":[{"id":"1.195395449","rc":[{"atb":[[22,0.49]],"id":37495442},{"atb":[[19,2.88]],"id":40494151},{"atl":[[1.93,0]],"id":43066393}],"con":true,"img":false}]}
{"op":"mcm","clk":"5346749127","pt":1646095924207,"mc":[{"id":"1.195395449","rc":[{"atb":[[24,3.05]],"id":37495442},{"atb":[[20,3.32]],"id":40494151},{"atl":[[1.75,43.26]],"id":43066393}],"con":true,"img":false}]}
{"op":"mcm","clk":"5346749138","pt":1646095924565,"mc":[{"id":"1.195395449","rc":[{"atb":[[23,1.83]],"id":37495442}],"con":true,"img":false}]}
{"op":"mcm","clk":"5346749142","pt":1646095924670,"mc":[{"id":"1.195395449","rc":[{"atb":[[1.01,1.58]],"id":37495442}],"con":true,"img":false}]}
{"op":"mcm","clk":"5346749148","pt":1646095924873,"mc":[{"id":"1.195395449","rc":[{"atb":[[4.4,9.51]],"id":40908100}],"con":true,"img":false}]}
{"op":"mcm","clk":"5346749151","pt":1646095924976,"mc":[{"id":"1.195395449","rc":[{"atl":[[700,1]],"id":37495442}],"con":true,"img":false}]}
{"op":"mcm","clk":"5346749187","pt":1646095926206,"mc":[{"id":"1.195395449","rc":[{"atb":[[24,0.35]],"id":37495442}],"con":true,"img":false}]}
{"op":"mcm","clk":"5346749193","pt":1646095926311,"mc":[{"id":"1.195395449","rc":[{"atb":[[22,3.19]],"id":37495442}],"con":true,"img":false}]}
{"op":"mcm","clk":"5346749211","pt":1646095926873,"mc":[{"id":"1.195395449","rc":[{"atb":[[1.01,0]],"id":37495442}],"con":true,"img":false}]}
{"op":"mcm","clk":"5346749216","pt":1646095926975,"mc":[{"id":"1.195395449","rc":[{"atb":[[23,3.42]],"id":37495442}],"con":true,"img":false}]}
{"op":"mcm","clk":"5346749219","pt":1646095927077,"mc":[{"id":"1.195395449","rc":[{"atb":[[19.5,0]],"id":40494151},{"atb":[[4.5,8.55]],"id":40908100}],"con":true,"img":false}]}
{"op":"mcm","clk":"5346749243","pt":1646095927591,"mc":[{"id":"1.195395449","rc":[{"atb":[[4.4,7.99]],"id":40908100}],"con":true,"img":false}]}
{"op":"mcm","clk":"5346749246","pt":1646095927695,"mc":[{"id":"1.195395449","rc":[{"atb":[[5,0],[4.6,3.19]],"id":40908100}],"con":true,"img":false}]}
{"op":"mcm","clk":"5346749250","pt":1646095927797,"mc":[{"id":"1.195395449","rc":[{"atb":[[1.01,1.67]],"id":40908100}],"con":true,"img":false}]}
{"op":"mcm","clk":"5346749258","pt":1646095928001,"mc":[{"id":"1.195395449","rc":[{"atb":[[1.01,1.63],[4.6,1.52]],"id":40908100}],"con":true,"img":false}]}
{"op":"mcm","clk":"5346749265","pt":1646095928206,"mc":[{"id":"1.195395449","rc":[{"atb":[[1.01,0]],"id":40908100}],"con":true,"img":false}]}
{"op":"mcm","clk":"5346749269","pt":1646095928308,"mc":[{"id":"1.195395449","rc":[{"atb":[[5.1,1.63]],"id":40908100}],"con":true,"img":false}]}
{"op":"mcm","clk":"5346749283","pt":1646095928821,"mc":[{"id":"1.195395449","rc":[{"atb":[[8.6,13.51]],"id":41962160},{"atl":[[1.8,154.61]],"id":43066393}],"con":true,"img":false}]}
{"op":"mcm","clk":"5346749348","pt":1646095930972,"mc":[{"id":"1.195395449","rc":[{"atb":[[4.5,0]],"id":40908100}],"con":true,"img":false}]}
{"op":"mcm","clk":"5346749372","pt":1646095931791,"mc":[{"id":"1.195395449","rc":[{"atb":[[4.6,0]],"id":40908100}],"con":true,"img":false}]}
{"op":"mcm","clk":"5346749374","pt":1646095931895,"mc":[{"id":"1.195395449","rc":[{"atb":[[4.5,1.52]],"id":40908100}],"con":true,"img":false}]}
{"op":"mcm","clk":"5346749382","pt":1646095932203,"mc":[{"id":"1.195395449","rc":[{"atb":[[12.5,0]],"id":40995914},{"atb":[[20,0]],"id":40494151}],"con":true,"img":false}]}
{"op":"mcm","clk":"5346749387","pt":1646095932309,"mc":[{"id":"1.195395449","rc":[{"atb":[[13.5,9.97]],"id":40995914},{"atb":[[19,6.21]],"id":40494151}],"con":true,"img":false}]}
{"op":"mcm","clk":"5346749398","pt":1646095932618,"mc":[{"id":"1.195395449","rc":[{"atb":[[4.4,2]],"id":40908100}],"con":true,"img":false}]}
{"op":"mcm","clk":"5346749401","pt":1646095932720,"mc":[{"id":"1.195395449","rc":[{"atb":[[17,0],[18.5,1.14],[19,4.48],[22,7.95]],"id":37495442},{"atb":[[9,12.5],[15,1.43],[18.5,5.8]],"id":41360966},{"atb":[[9.2,2.44],[10.5,0],[11.5,0],[13,0]],"id":40494151},{"atb":[[10,11.11],[13,6.25]],"id":25760990},{"atl":[[13,1.67],[14.5,11.34],[18,0]],"id":40908100},{"atb":[[1.16,232.76],[1.08,377.16]],"id":43066393}],"con":true,"img":false}]}
{"op":"mcm","clk":"5346749405","pt":1646095932825,"mc":[{"id":"1.195395449","rc":[{"atb":[[10.5,17.08]],"id":41360966}],"con":true,"img":false}]}
{"op":"mcm","clk":"5346749455","pt":1646095934829,"mc":[{"id":"1.195395449","rc":[{"atb":[[19.5,4.99]],"id":40494151},{"atb":[[4.6,2.53]],"id":40908100}],"con":true,"img":false}]}
{"op":"mcm","clk":"5346749472","pt":1646095935289,"mc":[{"id":"1.195395449","rc":[{"atb":[[4.5,0]],"id":40908100}],"con":true,"img":false}]}
{"op":"mcm","clk":"5346749477","pt":1646095935391,"mc":[{"id":"1.195395449","rc":[{"atb":[[4.6,4.05]],"id":40908100}],"con":true,"img":false}]}
{"op":"mcm","clk":"5346749532","pt":1646095937806,"mc":[{"id":"1.195395449","rc":[{"atb":[[4.7,3.07]],"id":40908100}],"con":true,"img":false}]}
{"op":"mcm","clk":"5346749540","pt":1646095938004,"mc":[{"id":"1.195395449","rc":[{"atb":[[1.01,1.67]],"id":40908100}],"con":true,"img":false}]}
{"op":"mcm","clk":"5346749542","pt":1646095938107,"mc":[{"id":"1.195395449","rc":[{"atb":[[5.1,0]],"id":40908100}],"con":true,"img":false}]}
{"op":"mcm","clk":"5346749545","pt":1646095938212,"mc":[{"id":"1.195395449","rc":[{"atb":[[17.5,0]],"id":41360966},{"atb":[[9.8,0]],"id":40494151},{"atb":[[1.01,1.63]],"id":40908100}],"con":true,"img":false}]}
{"op":"mcm","clk":"5346749551","pt":1646095938417,"mc":[{"id":"1.195395449","rc":[{"atb":[[1.01,0],[4.6,2.53]],"id":40908100}],"con":true,"img":false}]}
{"op":"mcm","clk":"5346749555","pt":1646095938518,"mc":[{"id":"1.195395449","rc":[{"atb":[[4.8,1.85],[4.7,4.59]],"id":40908100}],"con":true,"img":false}]}
{"op":"mcm","clk":"5346749607","pt":1646095940111,"mc":[{"id":"1.195395449","rc":[{"atb":[[3.65,47.17]],"id":40908100}],"con":true,"img":false}]}
{"op":"mcm","clk":"5346749611","pt":1646095940213,"mc":[{"id":"1.195395449","rc":[{"atb":[[3.85,71.17]],"id":40908100}],"con":true,"img":false}]}
{"op":"mcm","clk":"5346749617","pt":1646095940419,"mc":[{"id":"1.195395449","rc":[{"atb":[[16.5,0]],"id":41360966}],"con":true,"img":false}]}
{"op":"mcm","clk":"5346749628","pt":1646095940828,"mc":[{"id":"1.195395449","rc":[{"atb":[[4.6,0]],"id":40908100}],"con":true,"img":false}]}
{"op":"mcm","clk":"5346749641","pt":1646095941401,"mc":[{"id":"1.195395449","rc":[{"atb":[[4.7,3.07]],"id":40908100}],"con":true,"img":false}]}
{"op":"mcm","clk":"5346749644","pt":1646095941499,"mc":[{"id":"1.195395449","rc":[{"atb":[[1.01,1.52]],"id":40908100}],"con":true,"img":false}]}
{"op":"mcm","clk":"5346749667","pt":1646095942728,"mc":[{"id":"1.195395449","rc":[{"atb":[[17.5,3.03]],"id":37495442},{"atl":[[740,1]],"id":37495442},{"atb":[[14,3.85],[15.5,8.39]],"id":41360966},{"atb":[[8.8,6.41]],"id":40494151},{"atl":[[14,3.85]],"id":40908100},{"atb":[[1.14,250]],"id":43066393}],"con":true,"img":false}]}
{"op":"mcm","clk":"5346749714","pt":1646095944723,"mc":[{"id":"1.195395449","rc":[{"atb":[[4.4,10.64]],"id":40908100}],"con":true,"img":false}]}
{"op":"mcm","clk":"5346749719","pt":1646095944930,"mc":[{"id":"1.195395449","rc":[{"atb":[[14,0],[15,0],[16,0]],"id":37495442},{"atl":[[710,0],[730,0]],"id":37495442},{"atl":[[14,11.54],[14.5,3.93],[22,0]],"id":40908100},{"atb":[[1.02,0]],"id":43066393}],"con":true,"img":false}]}
{"op":"mcm","clk":"5346749744","pt":1646095945598,"mc":[{"id":"1.195395449","rc":[{"atl":[[700,0],[710,1]],"id":37495442},{"atb":[[4.7,0]],"id":40908100}],"con":true,"img":false}]}
{"op":"mcm","clk":"5346749758","pt":1646095946212,"mc":[{"id":"1.195395449","rc":[{"atb":[[19.5,0]],"id":37495442}],"con":true,"img":false}]}
{"op":"mcm","clk":"5346749763","pt":1646095946315,"mc":[{"id":"1.195395449","rc":[{"atb":[[19,10.76]],"id":37495442}],"con":true,"img":false}]}
{"op":"mcm","clk":"5346749806","pt":1646095948007,"mc":[{"id":"1.195395449","rc":[{"atl":[[700,1]],"id":37495442}],"con":true,"img":false}]}
{"op":"mcm","clk":"5346749814","pt":1646095948211,"mc":[{"id":"1.195395449","rc":[{"atb":[[18.5,0]],"id":41360966},{"atb":[[4.8,0.22],[1.01,3.19]],"id":40908100}],"con":true,"img":false}]}
{"op":"mcm","clk":"5346749818","pt":1646095948313,"mc":[{"id":"1.195395449","rc":[{"atb":[[19.5,5.8]],"id":41360966}],"con":true,"img":false}]}
{"op":"mcm","clk":"5346749823","pt":1646095948414,"mc":[{"id":"1.195395449","rc":[{"atb":[[1.01,3.15]],"id":40908100}],"con":true,"img":false}]}
{"op":"mcm","clk":"5346749829","pt":1646095948621,"mc":[{"id":"1.195395449","rc":[{"atb":[[1.01,1.52]],"id":40908100}],"con":true,"img":false}]}
{"op":"mcm","clk":"5346749834","pt":1646095948720,"mc":[{"id":"1.195395449","rc":[{"atb":[[4.5,1.63]],"id":40908100}],"con":true,"img":false}]}
{"op":"mcm","clk":"5346749890","pt":1646095950261,"mc":[{"id":"1.195395449","rc":[{"atb":[[19,2.88]],"id":40494151}],"con":true,"img":false}]}
{"op":"mcm","clk":"5346749893","pt":1646095950363,"mc":[{"id":"1.195395449","rc":[{"atb":[[20,3.32]],"id":40494151},{"atb":[[4.5,8.09]],"id":40908100}],"con":true,"img":false}]}
{"op":"mcm","clk":"5346749901","pt":1646095950675,"mc":[{"id":"1.195395449","rc":[{"atb":[[19,0]],"id":41360966}],"con":true,"img":false}]}
{"op":"mcm","clk":"5346749957","pt":1646095952213,"mc":[{"id":"1.195395449","rc":[{"atb":[[22,5.25]],"id":37495442},{"atb":[[19.5,0]],"id":41360966}],"con":true,"img":false}]}
{"op":"mcm","clk":"5346749961","pt":1646095952317,"mc":[{"id":"1.195395449","rc":[{"atb":[[24,3.05]],"id":37495442},{"atb":[[18.5,5.8]],"id":41360966}],"con":true,"img":false}]}
{"op":"mcm","clk":"5346749969","pt":1646095952520,"mc":[{"id":"1.195395449","rc":[{"atb":[[19.5,0]],"id":40494151}],"con":true,"img":false}]}
{"op":"mcm","clk":"5346749974","pt":1646095952725,"mc":[{"id":"1.195395449","rc":[{"atb":[[13,6.25]],"id":41360966},{"atb":[[8.4,10.14]],"id":40494151},{"atl":[[15,14.8]],"id":40908100},{"atb":[[1.12,250]],"id":43066393}],"con":true,"img":false}]}
{"op":"mcm","clk":"5346749993","pt":1646095953340,"mc":[{"id":"1.195395449","rc":[{"atb":[[23,1.83]],"id":37495442},{"atl":[[700,0]],"id":37495442},{"atb":[[1.04,0]],"id":43066393}],"con":true,"img":false}]}
{"op":"mcm","clk":"5346749998","pt":1646095953440,"mc":[{"id":"1.195395449","rc":[{"atb":[[24,4.64]],"id":37495442},{"atl":[[20,10.43]],"id":40908100}],"con":true,"img":false}]}
{"op":"mcm","clk":"5346750026","pt":1646095954517,"mc":[{"id":"1.195395449","rc":[{"atb":[[19,5.14]],"id":41360966}],"con":true,"img":false}]}
{"op":"mcm","clk":"5346750062","pt":1646095955746,"mc":[{"id":"1.195395449","rc":[{"atl":[[700,1]],"id":37495442}],"con":true,"img":false}]}
{"op":"mcm","clk":"5346750131","pt":1646095958169,"mc":[{"id":"1.195395449","rc":[{"atb":[[24,1.93]],"id":37495442},{"atb":[[20,0]],"id":40494151},{"atl":[[14.5,0]],"id":40908100}],"con":true,"img":false}]}
{"op":"mcm","clk":"5346750134","pt":1646095958272,"mc":[{"id":"1.195395449","rc":[{"atb":[[23,4.54]],"id":37495442},{"atb":[[19,6.21]],"id":40494151},{"atl":[[13.5,3.93]],"id":40908100}],"con":true,"img":false}]}
{"op":"mcm","clk":"5346750184","pt":1646095960271,"mc":[{"id":"1.195395449","rc":[{"atl":[[130,0]],"id":40494151}],"con":true,"img":false}]}
{"op":"mcm","clk":"5346750187","pt":1646095960328,"mc":[{"id":"1.195395449","rc":[{"atl":[[150,0.36]],"id":40494151}],"con":true,"img":false}]}
{"op":"mcm","clk":"5346750191","pt":1646095960428,"mc":[{"id":"1.195395449","rc":[{"atb":[[19.5,4.99]],"id":40494151},{"atl":[[190,0.57],[220,3]],"id":40494151}],"con":true,"img":false}]}
{"op":"mcm","clk":"5346750193","pt":1646095960528,"mc":[{"id":"1.195395449","rc":[{"atl":[[190,2.57]],"id":40494151},{"atb":[[1.01,0]],"id":40908100}],"con":true,"img":false}]}
{"op":"mcm","clk":"5346750195","pt":1646095960630,"mc":[{"id":"1.195395449","rc":[{"atl":[[220,1]],"id":40494151},{"atb":[[4.6,1.52]],"id":40908100}],"con":true,"img":false}]}
{"op":"mcm","clk":"5346750206","pt":1646095961141,"mc":[{"id":"1.195395449","rc":[{"atl":[[700,0]],"id":37495442},{"atl":[[14.5,7.41]],"id":40908100},{"atl":[[1.73,27.11],[1.74,0]],"id":43066393}],"con":true,"img":false}]}
{"op":"mcm","clk":"5346750209","pt":1646095961243,"mc":[{"id":"1.195395449","rc":[{"atl":[[14,3.85]],"id":40908100}],"con":true,"img":false}]}
{"op":"mcm","clk":"5346750212","pt":1646095961449,"mc":[{"id":"1.195395449","rc":[{"atl":[[710,0]],"id":37495442}],"con":true,"img":false}]}
{"op":"mcm","clk":"5346750228","pt":1646095962165,"mc":[{"id":"1.195395449","rc":[{"atl":[[710,1]],"id":37495442}],"con":true,"img":false}]}
{"op":"mcm","clk":"5346750242","pt":1646095962782,"mc":[{"id":"1.195395449","rc":[{"atb":[[12,11.36]],"id":41360966},{"atb":[[8,17.86]],"id":40494151},{"atl":[[16,8.33]],"id":40908100}],"con":true,"img":false}]}
{"op":"mcm","clk":"5346750253","pt":1646095963139,"mc":[{"id":"1.195395449","rc":[{"atl":[[19,0]],"id":40908100}],"con":true,"img":false}]}
{"op":"mcm","clk":"5346750282","pt":1646095964163,"mc":[{"id":"1.195395449","rc":[{"atb":[[4.3,0]],"id":40908100}],"con":true,"img":false}]}
{"op":"mcm","clk":"5346750285","pt":1646095964265,"mc":[{"id":"1.195395449","rc":[{"atb":[[4.5,21.2]],"id":40908100}],"con":true,"img":false}]}
{"op":"mcm","clk":"5346750344","pt":1646095966258,"mc":[{"id":"1.195395449","rc":[{"atb":[[4.4,2]],"id":40908100}],"con":true,"img":false}]}
{"op":"mcm","clk":"5346750457","pt":1646095970153,"mc":[{"id":"1.195395449","rc":[{"atb":[[4.5,14.74]],"id":40908100}],"con":true,"img":false}]}
{"op":"mcm","clk":"5346750461","pt":1646095970256,"mc":[{"id":"1.195395449","rc":[{"atb":[[4.3,28.04]],"id":40908100}],"con":true,"img":false}]}
{"op":"mcm","clk":"5346750480","pt":1646095971176,"mc":[{"id":"1.195395449","rc":[{"atb":[[1.1,250]],"id":43066393}],"con":true,"img":false}]}
{"op":"mcm","clk":"5346750488","pt":1646095971484,"mc":[{"id":"1.195395449","rc":[{"atb":[[3.9,3.17]],"id":40908100}],"con":true,"img":false}]}
{"op":"mcm","clk":"5346750503","pt":1646095972050,"mc":[{"id":"1.195395449","rc":[{"atb":[[4.5,1.63]],"id":40908100}],"con":true,"img":false}]}
{"op":"mcm","clk":"5346750506","pt":1646095972151,"mc":[{"id":"1.195395449","rc":[{"atb":[[16.5,12.66]],"id":37495442},{"atl":[[730,1]],"id":37495442},{"atb":[[4.4,15.11]],"id":40908100}],"con":true,"img":false}]}
{"op":"mcm","clk":"5346750514","pt":1646095972459,"mc":[{"id":"1.195395449","rc":[{"atb":[[4.6,0]],"id":40908100}],"con":true,"img":false}]}
{"op":"mcm","clk":"5346750519","pt":1646095972562,"mc":[{"id":"1.195395449","rc":[{"atb":[[4.5,3.15]],"id":40908100}],"con":true,"img":false}]}
{"op":"mcm","clk":"5346750597","pt":1646095975586,"mc":[{"id":"1.195395449","rc":[{"atb":[[4.6,2.36]],"id":40908100}],"con":true,"img":false}]}
{"op":"mcm","clk":"5346750609","pt":1646095976095,"mc":[{"id":"1.195395449","rc":[{"atb":[[19,2.88]],"id":40494151},{"atb":[[4.5,1.63]],"id":40908100}],"con":true,"img":false}]}
{"op":"mcm","clk":"5346750612","pt":1646095976197,"mc":[{"id":"1.195395449","rc":[{"atb":[[20,3.32]],"id":40494151},{"atb":[[4.3,0],[4.6,3.88]],"id":40908100}],"con":true,"img":false}]}
{"op":"mcm","clk":"5346750642","pt":1646095977476,"mc":[{"id":"1.195395449","rc":[{"atb":[[1.06,0]],"id":43066393}],"con":true,"img":false}]}
{"op":"mcm","clk":"5346750658","pt":1646095978090,"mc":[{"id":"1.195395449","rc":[{"atb":[[19.5,0]],"id":40494151}],"con":true,"img":false}]}
{"op":"mcm","clk":"5346750706","pt":1646095980094,"mc":[{"id":"1.195395449","rc":[{"atb":[[4.7,3.08]],"id":40908100},{"spn":8.4,"spf":1.0,"id":40908100}],"con":true,"img":false}]}
{"op":"mcm","clk":"5346750717","pt":1646095980402,"mc":[{"id":"1.195395449","rc":[{"atb":[[4.6,2.36]],"id":40908100}],"con":true,"img":false}]}
{"op":"mcm","clk":"5346750720","pt":1646095980505,"mc":[{"id":"1.195395449","rc":[{"atb":[[4.7,4.6]],"id":40908100}],"con":true,"img":false}]}
{"op":"mcm","clk":"5346750772","pt":1646095982097,"mc":[{"id":"1.195395449","rc":[{"atb":[[15.5,8.62]],"id":37495442},{"atl":[[750,1]],"id":37495442},{"atb":[[4.4,2]],"id":40908100}],"con":true,"img":false}]}
{"op":"mcm","clk":"5346750779","pt":1646095982198,"mc":[{"id":"1.195395449","rc":[{"atb":[[4.3,13.11]],"id":40908100}],"con":true,"img":false}]}
{"op":"mcm","clk":"5346750817","pt":1646095983275,"mc":[{"id":"1.195395449","rc":[{"atb":[[4.6,0]],"id":40908100}],"con":true,"img":false}]}
{"op":"mcm","clk":"5346750836","pt":1646095983891,"mc":[{"id":"1.195395449","rc":[{"atb":[[4.7,3.08]],"id":40908100}],"con":true,"img":false}]}
{"op":"mcm","clk":"5346750843","pt":1646095983995,"mc":[{"id":"1.195395449","rc":[{"atb":[[1.01,1.52]],"id":40908100}],"con":true,"img":false}]}
{"op":"mcm","clk":"5346750848","pt":1646095984202,"mc":[{"id":"1.195395449","rc":[{"atb":[[20,0]],"id":40494151}],"con":true,"img":false}]}
{"op":"mcm","clk":"5346750851","pt":1646095984304,"mc":[{"id":"1.195395449","rc":[{"atb":[[19,6.21]],"id":40494151}],"con":true,"img":false}]}
{"op":"mcm","clk":"5346750882","pt":1646095985381,"mc":[{"id":"1.195395449","rc":[{"atb":[[4.9,1.7],[4.5,0]],"id":40908100}],"con":true,"img":false}]}
{"op":"mcm","clk":"5346750890","pt":1646095985586,"mc":[{"id":"1.195395449","rc":[{"atl":[[720,0],[740,0]],"id":37495442}],"con":true,"img":false}]}
{"op":"mcm","clk":"5346750894","pt":1646095985688,"mc":[{"id":"1.195395449","rc":[{"atb":[[4.8,1.92]],"id":40908100}],"con":true,"img":false}]}
{"op":"mcm","clk":"5346750898","pt":1646095985791,"mc":[{"id":"1.195395449","rc":[{"atb":[[4.8,0.22],[4.9,0],[5,1.67]],"id":40908100}],"con":true,"img":false}]}
{"op":"mcm","clk":"5346750906","pt":1646095985995,"mc":[{"id":"1.195395449","rc":[{"atb":[[4.7,0]],"id":40908100}],"con":true,"img":false}]}
{"op":"mcm","clk":"5346750911","pt":1646095986202,"mc":[{"id":"1.195395449","rc":[{"atb":[[18.5,0]],"id":41360966}],"con":true,"img":false}]}
{"op":"mcm","clk":"5346750914","pt":1646095986304,"mc":[{"id":"1.195395449","rc":[{"atb":[[19.5,5.8]],"id":41360966}],"con":true,"img":false}]}
{"op":"mcm","clk":"5346750966","pt":1646095987892,"mc":[{"id":"1.195395449","rc":[{"atb":[[19.5,4.99]],"id":40494151}],"con":true,"img":false}]}
{"op":"mcm","clk":"5346750989","pt":1646095988511,"mc":[{"id":"1.195395449","rc":[{"atb":[[4.4,7.51]],"id":40908100}],"con":true,"img":false}]}
{"op":"mcm","clk":"5346751029","pt":1646095989999,"mc":[{"id":"1.195395449","rc":[{"atb":[[19,0]],"id":41360966},{"atb":[[4.5,2.92]],"id":40908100}],"con":true,"img":false}]}
{"op":"mcm","clk":"5346751094","pt":1646095992111,"mc":[{"id":"1.195395449","rc":[{"atl":[[770,1]],"id":37495442},{"atb":[[19.5,0]],"id":41360966}],"con":true,"img":false}]}
{"op":"mcm","clk":"5346751098","pt":1646095992211,"mc":[{"id":"1.195395449","rc":[{"atb":[[18.5,5.8]],"id":41360966}],"con":true,"img":false}]}
{"op":"mcm","clk":"5346751101","pt":1646095992315,"mc":[{"id":"1.195395449","rc":[{"atl":[[700,1]],"id":37495442}],"con":true,"img":false}]}
{"op":"mcm","clk":"5346751104","pt":1646095992418,"mc":[{"id":"1.195395449","rc":[{"atl":[[710,0]],"id":37495442},{"atb":[[23,0.35]],"id":41360966},{"atb":[[1.01,0],[3.9,6.28]],"id":40908100}],"con":true,"img":false}]}
{"op":"mcm","clk":"5346751107","pt":1646095992519,"mc":[{"id":"1.195395449","rc":[{"atb":[[1.01,1.58]],"id":41360966},{"atb":[[4.5,4.44]],"id":40908100}],"con":true,"img":false}]}
{"op":"mcm","clk":"5346751115","pt":1646095992931,"mc":[{"id":"1.195395449","rc":[{"atb":[[1.01,0]],"id":41360966}],"con":true,"img":false}]}
{"op":"mcm","clk":"5346751118","pt":1646095993031,"mc":[{"id":"1.195395449","rc":[{"atb":[[23,1.94]],"id":41360966}],"con":true,"img":false}]}
{"op":"mcm","clk":"5346751133","pt":1646095993703,"mc":[{"id":"1.195395449","rc":[{"atl":[[700,0],[710,1]],"id":37495442},{"atl":[[14.5,0],[15,21.94]],"id":40908100}],"con":true,"img":false}]}
{"op":"mcm","clk":"5346751159","pt":1646095994626,"mc":[{"id":"1.195395449","rc":[{"atb":[[1.37,30]],"id":43066393}],"con":true,"img":false}]}
{"op":"mcm","clk":"5346751182","pt":1646095995398,"mc":[{"id":"1.195395449","rc":[{"atl":[[700,1]],"id":37495442}],"con":true,"img":false}]}
{"op":"mcm","clk":"5346751186","pt":1646095995554,"mc":[{"id":"1.195395449","rc":[{"atl":[[710,0]],"id":37495442}],"con":true,"img":false}]}
{"op":"mcm","clk":"5346751197","pt":1646095995914,"mc":[{"id":"1.195395449","rc":[{"atb":[[19,5.14]],"id":41360966}],"con":true,"img":false}]}
{"op":"mcm","clk":"5346751202","pt":1646095996016,"mc":[{"id":"1.195395449","rc":[{"atb":[[4.6,1.67]],"id":40908100}],"con":true,"img":false}]}
{"op":"mcm","clk":"5346751206","pt":1646095996118,"mc":[{"id":"1.195395449","rc":[{"atb":[[5,0]],"id":40908100}],"con":true,"img":false}]}
{"op":"mcm","clk":"5346751209","pt":1646095996227,"mc":[{"id":"1.195395449","rc":[{"atb":[[4.9,1.7]],"id":40908100}],"con":true,"img":false}]}
{"op":"mcm","clk":"5346751212","pt":1646095996325,"mc":[{"id":"1.195395449","rc":[{"atb":[[4.6,0]],"id":40908100}],"con":true,"img":false}]}
{"op":"mcm","clk":"5346751376","pt":1646096001512,"mc":[{"id":"1.195395449","rc":[{"atl":[[700,0],[710,1]],"id":37495442}],"con":true,"img":false}]}
{"op":"mcm","clk":"5346751385","pt":1646096001716,"mc":[{"id":"1.195395449","rc":[{"atl":[[700,1],[710,0]],"id":37495442}],"con":true,"img":false}]}
{"op":"mcm","clk":"5346751393","pt":1646096001941,"mc":[{"id":"1.195395449","rc":[{"atl":[[14.5,7.41],[15,14.8]],"id":40908100}],"con":true,"img":false}]}
{"op":"mcm","clk":"5346751407","pt":1646096002250,"mc":[{"id":"1.195395449","rc":[{"atb":[[19,2.88]],"id":40494151}],"con":true,"img":false}]}
{"op":"mcm","clk":"5346751410","pt":1646096002301,"mc":[{"id":"1.195395449","rc":[{"atb":[[20,3.32]],"id":40494151}],"con":true,"img":false}]}
{"op":"mcm","clk":"5346751507","pt":1646096005743,"mc":[{"id":"1.195395449","rc":[{"atb":[[19.5,0]],"id":40494151}],"con":true,"img":false}]}
{"op":"mcm","clk":"5346751601","pt":1646096008155,"mc":[{"id":"1.195395449","rc":[{"atb":[[4.3,0]],"id":40908100}],"con":true,"img":false}]}
{"op":"mcm","clk":"5346751605","pt":1646096008257,"mc":[{"id":"1.195395449","rc":[{"atb":[[4.5,17.55]],"id":40908100}],"con":true,"img":false}]}
{"op":"mcm","clk":"5346751609","pt":1646096008359,"mc":[{"id":"1.195395449","rc":[{"atb":[[4.9,0],[4.6,1.7]],"id":40908100}],"con":true,"img":false}]}
{"op":"mcm","clk":"5346751616","pt":1646096008514,"mc":[{"id":"1.195395449","rc":[{"atb":[[4.9,1.7],[4.6,0]],"id":40908100}],"con":true,"img":false}]}
{"op":"mcm","clk":"5346751661","pt":1646096010161,"mc":[{"id":"1.195395449","rc":[{"atb":[[20,0]],"id":40494151}],"con":true,"img":false}]}
{"op":"mcm","clk":"5346751664","pt":1646096010274,"mc":[{"id":"1.195395449","rc":[{"atb":[[19,6.21]],"id":40494151}],"con":true,"img":false}]}
{"op":"mcm","clk":"5346751750","pt":1646096013037,"mc":[{"id":"1.195395449","rc":[{"atb":[[4.4,2]],"id":40908100}],"con":true,"img":false}]}
{"op":"mcm","clk":"5346751761","pt":1646096013340,"mc":[{"id":"1.195395449","rc":[{"atb":[[19.5,4.99]],"id":40494151}],"con":true,"img":false}]}
{"op":"mcm","clk":"5346751821","pt":1646096015344,"mc":[{"id":"1.195395449","rc":[{"atb":[[4.5,14.63]],"id":40908100}],"con":true,"img":false}]}
{"op":"mcm","clk":"5346751892","pt":1646096018164,"mc":[{"id":"1.195395449","rc":[{"atb":[[4.3,6.85],[4.5,1.52]],"id":40908100}],"con":true,"img":false}]}
{"op":"mcm","clk":"5346751896","pt":1646096018269,"mc":[{"id":"1.195395449","rc":[{"atb":[[4.3,19.96]],"id":40908100}],"con":true,"img":false}]}
{"op":"mcm","clk":"5346751899","pt":1646096018372,"mc":[{"id":"1.195395449","rc":[{"atb":[[4.9,0],[4.6,1.7]],"id":40908100}],"con":true,"img":false}]}
{"op":"mcm","clk":"5346751906","pt":1646096018472,"mc":[{"id":"1.195395449","rc":[{"atb":[[5,1.67]],"id":40908100}],"con":true,"img":false}]}
{"op":"mcm","clk":"5346751911","pt":1646096018676,"mc":[{"id":"1.195395449","rc":[{"atl":[[670,1],[700,0]],"id":37495442},{"atb":[[5.3,0],[9.6,0],[8.6,2.16],[4.5,28.57],[9.8,9.22]],"id":41962160},{"atb":[[4.6,0]],"id":40908100},{"atl":[[14.5,0],[15,21.94]],"id":40908100},{"atl":[[1.73,0],[2,100],[1.94,0],[1.77,25.7]],"id":43066393}],"con":true,"img":false}]}
{"op":"mcm","clk":"5346751933","pt":1646096019341,"mc":[{"id":"1.195395449","rc":[{"atb":[[4.3,44.79]],"id":40908100}],"con":true,"img":false}]}
{"op":"mcm","clk":"5346751941","pt":1646096019650,"mc":[{"id":"1.195395449","rc":[{"atb":[[3.9,3.17]],"id":40908100}],"con":true,"img":false}]}
{"op":"mcm","clk":"5346751948","pt":1646096019956,"mc":[{"id":"1.195395449","rc":[{"atl":[[670,0],[690,1]],"id":37495442},{"atl":[[1.78,25.37],[1.76,0]],"id":43066393}],"con":true,"img":false}]}
{"op":"mcm","clk":"5346751951","pt":1646096020061,"mc":[{"id":"1.195395449","rc":[{"atb":[[9.4,0]],"id":41962160}],"con":true,"img":false}]}
{"op":"mcm","clk":"5346752037","pt":1646096022978,"mc":[{"id":"1.195395449","rc":[{"atb":[[9,0]],"id":41962160},{"atl":[[1.77,0]],"id":43066393}],"con":true,"img":false}]}
{"op":"mcm","clk":"5346752046","pt":1646096023289,"mc":[{"id":"1.195395449","rc":[{"atb":[[3.9,0]],"id":40908100}],"con":true,"img":false}]}
{"op":"mcm","clk":"5346752109","pt":1646096025388,"mc":[{"id":"1.195395449","rc":[{"atl":[[700,1]],"id":37495442}],"con":true,"img":false}]}
{"op":"mcm","clk":"5346752113","pt":1646096025491,"mc":[{"id":"1.195395449","rc":[{"atl":[[690,0]],"id":37495442}],"con":true,"img":false}]}
{"op":"mcm","clk":"5346752116","pt":1646096025591,"mc":[{"id":"1.195395449","rc":[{"atl":[[700,0],[690,1]],"id":37495442}],"con":true,"img":false}]}
{"op":"mcm","clk":"5346752131","pt":1646096026156,"mc":[{"id":"1.195395449","rc":[{"atl":[[1.75,0]],"id":43066393}],"con":true,"img":false}]}
{"op":"mcm","clk":"5346752134","pt":1646096026258,"mc":[{"id":"1.195395449","rc":[{"atl":[[1.77,43.26]],"id":43066393}],"con":true,"img":false}]}
{"op":"mcm","clk":"5346752185","pt":1646096028199,"mc":[{"id":"1.195395449","rc":[{"atb":[[18.5,0]],"id":41360966},{"atb":[[19,2.88]],"id":40494151}],"con":true,"img":false}]}
{"op":"mcm","clk":"5346752188","pt":1646096028253,"mc":[{"id":"1.195395449","rc":[{"atb":[[19.5,5.8]],"id":41360966},{"atb":[[20,3.32]],"id":40494151}],"con":true,"img":false}]}
{"op":"mcm","clk":"5346752191","pt":1646096028355,"mc":[{"id":"1.195395449","rc":[{"atb":[[5,0],[4.6,1.67]],"id":40908100}],"con":true,"img":false}]}
{"op":"mcm","clk":"5346752197","pt":1646096028460,"mc":[{"id":"1.195395449","rc":[{"atb":[[4.6,0],[5,1.67]],"id":40908100}],"con":true,"img":false}]}
{"op":"mcm","clk":"5346752203","pt":1646096028661,"mc":[{"id":"1.195395449","rc":[{"atb":[[8.2,5.7]],"id":41962160}],"con":true,"img":false}]}
{"op":"mcm","clk":"5346752238","pt":1646096030001,"mc":[{"id":"1.195395449","rc":[{"atl":[[1.8,61.84]],"id":43066393}],"con":true,"img":false}]}
{"op":"mcm","clk":"5346752258","pt":1646096030989,"mc":[{"id":"1.195395449","rc":[{"atb":[[19,0]],"id":41360966},{"atb":[[19.5,0]],"id":40494151}],"con":true,"img":false}]}
{"op":"mcm","clk":"5346752289","pt":1646096032106,"mc":[{"id":"1.195395449","rc":[{"atb":[[17,8.05],[19.5,0]],"id":41360966}],"con":true,"img":false}]}
{"op":"mcm","clk":"5346752354","pt":1646096034679,"mc":[{"id":"1.195395449","rc":[{"atb":[[4.4,4.65]],"id":40908100}],"con":true,"img":false}]}
{"op":"mcm","clk":"5346752358","pt":1646096034786,"mc":[{"id":"1.195395449","rc":[{"atb":[[18.5,5.28]],"id":41360966}],"con":true,"img":false}]}
{"op":"mcm","clk":"5346752366","pt":1646096035093,"mc":[{"id":"1.195395449","rc":[{"atb":[[18.5,0],[18,1.18],[20,5.26],[22,0.49]],"id":37495442},{"atb":[[12,1.82],[14,0],[15,0]],"id":41360966},{"atb":[[9.2,0],[9.4,2.38]],"id":40494151},{"atb":[[3.8,0],[4,40]],"id":40908100},{"atl":[[13,0],[13.5,8.23],[8.4,2.7],[15,14.8]],"id":40908100},{"atb":[[1.16,107.76],[1.23,86.96],[1.22,397.1],[1.08,0]],"id":43066393}],"con":true,"img":false}]}
{"op":"mcm","clk":"5346752374","pt":1646096035300,"mc":[{"id":"1.195395449","rc":[{"atb":[[4.4,7.35]],"id":40908100}],"con":true,"img":false}]}
{"op":"mcm","clk":"5346752387","pt":1646096035710,"mc":[{"id":"1.195395449","rc":[{"atb":[[24,0.35]],"id":37495442}],"con":true,"img":false}]}
{"op":"mcm","clk":"5346752391","pt":1646096035799,"mc":[{"id":"1.195395449","rc":[{"atb":[[1.01,1.58]],"id":37495442}],"con":true,"img":false}]}
{"op":"mcm","clk":"5346752405","pt":1646096036213,"mc":[{"id":"1.195395449","rc":[{"atb":[[20,0]],"id":40494151},{"atb":[[3.85,46]],"id":40908100}],"con":true,"img":false}]}
{"op":"mcm","clk":"5346752408","pt":1646096036315,"mc":[{"id":"1.195395449","rc":[{"atb":[[19,6.21]],"id":40494151},{"atb":[[3.8,25.17]],"id":40908100}],"con":true,"img":false}]}
{"op":"mcm","clk":"5346752424","pt":1646096036784,"mc":[{"id":"1.195395449","rc":[{"atb":[[4.3,19.96]],"id":40908100}],"con":true,"img":false}]}
{"op":"mcm","clk":"5346752444","pt":1646096037409,"mc":[{"id":"1.195395449","rc":[{"atb":[[4.3,13.11]],"id":40908100}],"con":true,"img":false}]}
{"op":"mcm","clk":"5346752452","pt":1646096037617,"mc":[{"id":"1.195395449","rc":[{"atl":[[690,0],[700,1]],"id":37495442},{"atb":[[13,0]],"id":41360966},{"atb":[[8.8,17.71]],"id":41962160},{"atl":[[8.2,2.78],[8.4,0]],"id":40908100}],"con":true,"img":false}]}
{"op":"mcm","clk":"5346752469","pt":1646096038169,"mc":[{"id":"1.195395449","rc":[{"atb":[[4.3,0]],"id":40908100}],"con":true,"img":false}]}
{"op":"mcm","clk":"5346752471","pt":1646096038283,"mc":[{"id":"1.195395449","rc":[{"atb":[[4.4,20.46]],"id":40908100}],"con":true,"img":false}]}
{"op":"mcm","clk":"5346752475","pt":1646096038386,"mc":[{"id":"1.195395449","rc":[{"atb":[[4.6,1.67]],"id":40908100}],"con":true,"img":false}]}
{"op":"mcm","clk":"5346752476","pt":1646096038477,"mc":[{"id":"1.195395449","rc":[{"atb":[[5,0]],"id":40908100}],"con":true,"img":false}]}
{"op":"mcm","clk":"5346752479","pt":1646096038592,"mc":[{"id":"1.195395449","rc":[{"atb":[[4.6,0],[5,1.67]],"id":40908100}],"con":true,"img":false}]}
{"op":"mcm","clk":"5346752484","pt":1646096038693,"mc":[{"id":"1.195395449","rc":[{"atb":[[19.5,4.99]],"id":40494151}],"con":true,"img":false}]}
{"op":"mcm","clk":"5346752550","pt":1646096040685,"mc":[{"id":"1.195395449","rc":[{"atb":[[4.6,2.55]],"id":40908100},{"spn":6.6,"spf":1.0,"id":40908100},{"spn":1.43,"spf":1.0,"id":43066393}],"con":true,"img":false}]}
{"op":"mcm","clk":"5346752568","pt":1646096041094,"mc":[{"id":"1.195395449","rc":[{"atb":[[4.5,0]],"id":40908100}],"con":true,"img":false}]}
{"op":"mcm","clk":"5346752573","pt":1646096041202,"mc":[{"id":"1.195395449","rc":[{"atb":[[4.6,4.07]],"id":40908100}],"con":true,"img":false}]}
{"op":"mcm","clk":"5346752600","pt":1646096042119,"mc":[{"id":"1.195395449","rc":[{"atb":[[4.6,6.46]],"id":40908100}],"con":true,"img":false}]}
{"op":"mcm","clk":"5346752685","pt":1646096045129,"mc":[{"id":"1.195395449","rc":[{"atb":[[11,12.2]],"id":41360966},{"atb":[[1.21,238.1]],"id":43066393},{"atl":[[1.82,90.5]],"id":43066393}],"con":true,"img":false}]}
{"op":"mcm","clk":"5346752691","pt":1646096045286,"mc":[{"id":"1.195395449","rc":[{"atl":[[700,0],[710,1]],"id":37495442}],"con":true,"img":false}]}
{"op":"mcm","clk":"5346752695","pt":1646096045390,"mc":[{"id":"1.195395449","rc":[{"atb":[[1.12,0],[1.14,0],[1.1,0]],"id":43066393}],"con":true,"img":false}]}
{"op":"mcm","clk":"5346752740","pt":1646096046625,"mc":[{"id":"1.195395449","rc":[{"atb":[[4.4,17.8]],"id":40908100}],"con":true,"img":false}]}
{"op":"mcm","clk":"5346752783","pt":1646096047621,"mc":[{"id":"1.195395449","rc":[{"atb":[[8.4,5.55]],"id":41962160},{"atl":[[8.6,6.58]],"id":40908100}],"con":true,"img":false}]}
{"op":"mcm","clk":"5346752859","pt":1646096050238,"mc":[{"id":"1.195395449","rc":[{"atb":[[4.4,4.69]],"id":40908100},{"atl":[[14,0],[15,9.44],[16,0]],"id":40908100},{"atb":[[1.22,353.84]],"id":43066393}],"con":true,"img":false}]}
{"op":"mcm","clk":"5346752863","pt":1646096050339,"mc":[{"id":"1.195395449","rc":[{"atb":[[4.3,13.11]],"id":40908100},{"atb":[[1.24,43.26]],"id":43066393}],"con":true,"img":false}]}
{"op":"mcm","clk":"5346752867","pt":1646096050442,"mc":[{"id":"1.195395449","rc":[{"atb":[[4.9,1.67],[5,0]],"id":40908100}],"con":true,"img":false}]}
{"op":"mcm","clk":"5346752873","pt":1646096050497,"mc":[{"id":"1.195395449","rc":[{"atb":[[4.6,3.91]],"id":40908100}],"con":true,"img":false}]}
{"op":"mcm","clk":"5346752878","pt":1646096050599,"mc":[{"id":"1.195395449","rc":[{"atb":[[1.01,1.67],[4.9,0]],"id":40908100}],"con":true,"img":false}]}
{"op":"mcm","clk":"5346752885","pt":1646096050804,"mc":[{"id":"1.195395449","rc":[{"atb":[[1.01,1.63]],"id":40908100}],"con":true,"img":false}]}
{"op":"mcm","clk":"5346752889","pt":1646096050907,"mc":[{"id":"1.195395449","rc":[{"atb":[[1.01,0]],"id":40908100}],"con":true,"img":false}]}
{"op":"mcm","clk":"5346752892","pt":1646096051010,"mc":[{"id":"1.195395449","rc":[{"atb":[[5.1,1.63]],"id":40908100}],"con":true,"img":false}]}
{"op":"mcm","clk":"5346752906","pt":1646096051422,"mc":[{"id":"1.195395449","rc":[{"atb":[[4.6,1.52]],"id":40908100}],"con":true,"img":false}]}
{"op":"mcm","clk":"5346752924","pt":1646096051831,"mc":[{"id":"1.195395449","rc":[{"atb":[[4.6,0]],"id":40908100}],"con":true,"img":false}]}
{"op":"mcm","clk":"5346752928","pt":1646096051931,"mc":[{"id":"1.195395449","rc":[{"atb":[[4.5,1.52]],"id":40908100}],"con":true,"img":false}]}
{"op":"mcm","clk":"5346752967","pt":1646096053117,"mc":[{"id":"1.195395449","rc":[{"atb":[[4.4,2]],"id":40908100}],"con":true,"img":false}]}
{"op":"mcm","clk":"5346752998","pt":1646096054250,"mc":[{"id":"1.195395449","rc":[{"atb":[[3.8,0]],"id":40908100}],"con":true,"img":false}]}
{"op":"mcm","clk":"5346753002","pt":1646096054304,"mc":[{"id":"1.195395449","rc":[{"atb":[[3.7,25.17]],"id":40908100}],"con":true,"img":false}]}
{"op":"mcm","clk":"5346753006","pt":1646096054510,"mc":[{"id":"1.195395449","rc":[{"atb":[[4.6,2.53]],"id":40908100}],"con":true,"img":false}]}
{"op":"mcm","clk":"5346753028","pt":1646096055129,"mc":[{"id":"1.195395449","rc":[{"atb":[[10,8.33]],"id":41360966},{"atb":[[1.19,250]],"id":43066393},{"atl":[[1.84,147.25]],"id":43066393}],"con":true,"img":false}]}
{"op":"mcm","clk":"5346753031","pt":1646096055233,"mc":[{"id":"1.195395449","rc":[{"atl":[[1.47,4]],"id":43066393}],"con":true,"img":false}]}
{"op":"mcm","clk":"5346753035","pt":1646096055336,"mc":[{"id":"1.195395449","rc":[{"atb":[[17,3.12]],"id":37495442}],"con":true,"img":false}]}
{"op":"mcm","clk":"5346753041","pt":1646096055539,"mc":[{"id":"1.195395449","rc":[{"atb":[[15.5,0],[16.5,7.82],[17.5,0]],"id":37495442},{"atb":[[18,2]],"id":41962160},{"atl":[[1.46,4]],"id":43066393}],"con":true,"img":false}]}
{"op":"mcm","clk":"5346753058","pt":1646096056154,"mc":[{"id":"1.195395449","rc":[{"atb":[[19,2.88]],"id":40494151}],"con":true,"img":false}]}
{"op":"mcm","clk":"5346753062","pt":1646096056209,"mc":[{"id":"1.195395449","rc":[{"atb":[[20,3.32]],"id":40494151}],"con":true,"img":false}]}
{"op":"mcm","clk":"5346753095","pt":1646096057336,"mc":[{"id":"1.195395449","rc":[{"atb":[[18,0]],"id":41962160},{"trd":[[18,4]],"ltp":18.0,"tv":4.0,"id":41962160}],"con":true,"img":false}]}
{"op":"mcm","clk":"5346753106","pt":1646096057641,"mc":[{"id":"1.195395449","rc":[{"atb":[[8,7.8]],"id":41962160},{"atl":[[9,9.38]],"id":40908100}],"con":true,"img":false}]}
{"op":"mcm","clk":"5346753113","pt":1646096057847,"mc":[{"id":"1.195395449","rc":[{"atb":[[1.01,2.53]],"id":41962160}],"con":true,"img":false}]}
{"op":"mcm","clk":"5346753120","pt":1646096058050,"mc":[{"id":"1.195395449","rc":[{"atb":[[1.01,1.26]],"id":41962160}],"con":true,"img":false}]}
{"op":"mcm","clk":"5346753130","pt":1646096058210,"mc":[{"id":"1.195395449","rc":[{"atb":[[1.01,0],[10,0]],"id":41962160}],"con":true,"img":false}]}
{"op":"mcm","clk":"5346753137","pt":1646096058311,"mc":[{"id":"1.195395449","rc":[{"atb":[[9,10.45],[12.5,3.23],[13.5,1.26]],"id":41962160},{"atl":[[1.45,3]],"id":43066393}],"con":true,"img":false}]}
{"op":"mcm","clk":"5346753141","pt":1646096058415,"mc":[{"id":"1.195395449","rc":[{"atb":[[8.2,0],[8.6,0]],"id":41962160},{"atl":[[12,0.84]],"id":40908100}],"con":true,"img":false}]}
{"op":"mcm","clk":"5346753147","pt":1646096058517,"mc":[{"id":"1.195395449","rc":[{"atl":[[8.2,4.08]],"id":40908100}],"con":true,"img":false}]}
{"op":"mcm","clk":"5346753154","pt":1646096058724,"mc":[{"id":"1.195395449","rc":[{"atb":[[12.5,0]],"id":41962160},{"atb":[[19.5,0]],"id":40494151}],"con":true,"img":false}]}
{"op":"mcm","clk":"5346753164","pt":1646096059031,"mc":[{"id":"1.195395449","rc":[{"atb":[[13,0.61]],"id":41962160},{"atb":[[4.1,2.96]],"id":40908100},{"atl":[[12,0.69]],"id":40908100}],"con":true,"img":false}]}
{"op":"mcm","clk":"5346753168","pt":1646096059135,"mc":[{"id":"1.195395449","rc":[{"atb":[[12.5,1.5]],"id":41962160},{"atl":[[8.2,4.23]],"id":40908100}],"con":true,"img":false}]}
{"op":"mcm","clk":"5346753221","pt":1646096060576,"mc":[{"id":"1.195395449","rc":[{"atb":[[4.6,0]],"id":40908100}],"con":true,"img":false}]}
{"op":"mcm","clk":"5346753227","pt":1646096060729,"mc":[{"id":"1.195395449","rc":[{"atb":[[1.01,1.67],[5.1,0]],"id":40908100}],"con":true,"img":false}]}
{"op":"mcm","clk":"5346753233","pt":1646096060940,"mc":[{"id":"1.195395449","rc":[{"atl":[[710,0],[720,1]],"id":37495442},{"atb":[[1.01,1.63]],"id":40908100},{"atl":[[1.44,3],[1.78,0],[1.77,68.96]],"id":43066393}],"con":true,"img":false}]}
{"op":"mcm","clk":"5346753240","pt":1646096061144,"mc":[{"id":"1.195395449","rc":[{"atb":[[1.01,0]],"id":40908100}],"con":true,"img":false}]}
{"op":"mcm","clk":"5346753243","pt":1646096061249,"mc":[{"id":"1.195395449","rc":[{"atb":[[4.6,1.63]],"id":40908100}],"con":true,"img":false}]}
{"op":"mcm","clk":"5346753347","pt":1646096063531,"mc":[{"id":"1.195395449","rc":[{"atb":[[1.2,2.23]],"id":41962160}],"con":true,"img":false}]}
{"op":"mcm","clk":"5346753353","pt":1646096063843,"mc":[{"id":"1.195395449","rc":[{"atb":[[1.2,1.88]],"id":41962160}],"con":true,"img":false}]}
{"op":"mcm","clk":"5346753362","pt":1646096064148,"mc":[{"id":"1.195395449","rc":[{"atb":[[1.2,0]],"id":41962160}],"con":true,"img":false}]}
{"op":"mcm","clk":"5346753367","pt":1646096064249,"mc":[{"id":"1.195395449","rc":[{"atb":[[13,2.5]],"id":41962160},{"atb":[[20,0]],"id":40494151},{"atl":[[13.5,4.3]],"id":40908100}],"con":true,"img":false}]}
{"op":"mcm","clk":"5346753372","pt":1646096064352,"mc":[{"id":"1.195395449","rc":[{"atb":[[19,6.21]],"id":40494151},{"atl":[[12,4.62]],"id":40908100}],"con":true,"img":false}]}
{"op":"mcm","clk":"5346753395","pt":1646096065125,"mc":[{"id":"1.195395449","rc":[{"atb":[[9.6,14.53]],"id":41360966}],"con":true,"img":false}]}
{"op":"mcm","clk":"5346753421","pt":1646096066046,"mc":[{"id":"1.195395449","rc":[{"atb":[[1.11,1.67]],"id":37495442},{"atb":[[1.09,1.67]],"id":40995914},{"atb":[[1.11,1.67]],"id":41360966},{"atb":[[1.06,1.67]],"id":41962160},{"atb":[[1.11,1.67]],"id":40494151},{"atb":[[1.11,1.67]],"id":25760990},{"atb":[[1.02,1.67]],"id":40908100},{"atb":[[1.02,1.67]],"id":43066393}],"con":true,"img":false}]}
{"op":"mcm","clk":"5346753426","pt":1646096066149,"mc":[{"id":"1.195395449","rc":[{"atl":[[46,0],[60,0.73]],"id":41962160}],"con":true,"img":false}]}
{"op":"mcm","clk":"5346753430","pt":1646096066250,"mc":[{"id":"1.195395449","rc":[{"atb":[[1.09,0.07]],"id":40995914},{"atb":[[1.11,0.06]],"id":37495442},{"atb":[[1.11,0.06]],"id":41360966},{"atb":[[1.06,0.11]],"id":41962160},{"atb":[[1.11,0.06]],"id":40494151},{"atb":[[1.11,0.06]],"id":25760990},{"atb":[[1.02,0.35]],"id":40908100},{"atb":[[1.02,1.21]],"id":43066393}],"con":true,"img":false}]}
{"op":"mcm","clk":"5346753434","pt":1646096066351,"mc":[{"id":"1.195395449","rc":[{"atb":[[18.5,5.28]],"id":40494151}],"con":true,"img":false}]}
{"op":"mcm","clk":"5346753437","pt":1646096066455,"mc":[{"id":"1.195395449","rc":[{"atb":[[1.11,0]],"id":37495442},{"atb":[[1.09,0]],"id":40995914},{"atb":[[1.11,0]],"id":41360966},{"atb":[[1.06,0]],"id":41962160},{"atb":[[1.11,0]],"id":40494151},{"atb":[[1.11,0]],"id":25760990},{"atb":[[1.02,0]],"id":43066393},{"atb":[[1.02,0]],"id":40908100}],"con":true,"img":false}]}
{"op":"mcm","clk":"5346753441","pt":1646096066556,"mc":[{"id":"1.195395449","rc":[{"atb":[[24,0.41]],"id":37495442},{"atb":[[22,0.07]],"id":40995914},{"atb":[[24,0.06]],"id":41360966},{"atb":[[14,0.11]],"id":41962160},{"atb":[[23,0.06]],"id":40494151},{"atb":[[24,0.06]],"id":25760990},{"atb":[[4.7,0.35]],"id":40908100},{"atb":[[1.37,31.21]],"id":43066393}],"con":true,"img":false}]}
{"op":"mcm","clk":"5346753450","pt":1646096066863,"mc":[{"id":"1.195395449","rc":[{"atl":[[42,2.44]],"id":41962160}],"con":true,"img":false}]}
{"op":"mcm","clk":"5346753454","pt":1646096066966,"mc":[{"id":"1.195395449","rc":[{"atl":[[1000,1.38]],"id":41962160}],"con":true,"img":false}]}
{"op":"mcm","clk":"5346753475","pt":1646096067635,"mc":[{"id":"1.195395449","rc":[{"atb":[[7.6,13.78]],"id":41962160},{"atl":[[9.4,14.88]],"id":40908100}],"con":true,"img":false}]}
{"op":"mcm","clk":"5346753552","pt":1646096070075,"mc":[{"id":"1.195395449","rc":[{"atb":[[18.5,0]],"id":40494151}],"con":true,"img":false}]}
{"op":"mcm","clk":"5346753558","pt":1646096070150,"mc":[{"id":"1.195395449","rc":[{"atb":[[17,0],[19,6.28]],"id":41360966}],"con":true,"img":false}]}
{"op":"mcm","clk":"5346753583","pt":1646096070766,"mc":[{"id":"1.195395449","rc":[{"atb":[[4.1,5.87]],"id":40908100}],"con":true,"img":false}]}
{"op":"mcm","clk":"5346753593","pt":1646096070969,"mc":[{"id":"1.195395449","rc":[{"atb":[[16,5]],"id":37495442},{"atl":[[740,1]],"id":37495442},{"atb":[[1.17,250]],"id":43066393}],"con":true,"img":false}]}
{"op":"mcm","clk":"5346753708","pt":1646096074053,"mc":[{"id":"1.195395449","rc":[{"atb":[[18.5,0]],"id":41360966},{"atb":[[19.5,4.99]],"id":40494151}],"con":true,"img":false}]}
{"op":"mcm","clk":"5346753714","pt":1646096074255,"mc":[{"id":"1.195395449","rc":[{"atl":[[730,0],[750,0],[770,0]],"id":37495442},{"atl":[[75,1.4]],"id":41962160}],"con":true,"img":false}]}
{"op":"mcm","clk":"5346753758","pt":1646096075692,"mc":[{"id":"1.195395449","rc":[{"atb":[[22,1.51],[1.02,1.67]],"id":40494151}],"con":true,"img":false}]}
{"op":"mcm","clk":"5346753767","pt":1646096075952,"mc":[{"id":"1.195395449","rc":[{"atb":[[1.02,0.35]],"id":40494151}],"con":true,"img":false}]}
{"op":"mcm","clk":"5346753774","pt":1646096076161,"mc":[{"id":"1.195395449","rc":[{"atb":[[11.5,0]],"id":41962160},{"atb":[[1.02,0]],"id":40494151}],"con":true,"img":false}]}
{"op":"mcm","clk":"5346753780","pt":1646096076258,"mc":[{"id":"1.195395449","rc":[{"atb":[[12.5,6.05]],"id":41962160},{"atb":[[24,0.35]],"id":40494151}],"con":true,"img":false}]}
{"op":"mcm","clk":"5346753847","pt":1646096077859,"mc":[{"id":"1.195395449","rc":[{"atb":[[19.5,4.99]],"id":41360966}],"con":true,"img":false}]}
{"op":"mcm","clk":"5346753917","pt":1646096080265,"mc":[{"id":"1.195395449","rc":[{"atl":[[19.5,0]],"id":40908100}],"con":true,"img":false}]}
{"op":"mcm","clk":"5346753921","pt":1646096080364,"mc":[{"id":"1.195395449","rc":[{"atl":[[17,12.44]],"id":40908100}],"con":true,"img":false}]}
{"op":"mcm","clk":"5346753941","pt":1646096080979,"mc":[{"id":"1.195395449","rc":[{"atb":[[15,8.93]],"id":37495442},{"atl":[[760,1]],"id":37495442}],"con":true,"img":false}]}
{"op":"mcm","clk":"5346753995","pt":1646096082165,"mc":[{"id":"1.195395449","rc":[{"atb":[[19,4.48]],"id":37495442},{"atl":[[46,2.7],[60,0]],"id":41962160}],"con":true,"img":false}]}
{"op":"mcm","clk":"5346754001","pt":1646096082268,"mc":[{"id":"1.195395449","rc":[{"atb":[[19.5,6.27]],"id":37495442}],"con":true,"img":false}]}
{"op":"mcm","clk":"5346754007","pt":1646096082370,"mc":[{"id":"1.195395449","rc":[{"atl":[[1000,0]],"id":41962160},{"atb":[[19,2.88]],"id":40494151}],"con":true,"img":false}]}
{"op":"mcm","clk":"5346754015","pt":1646096082473,"mc":[{"id":"1.195395449","rc":[{"atl":[[42,3.82]],"id":41962160},{"atb":[[20,3.32]],"id":40494151}],"con":true,"img":false}]}
{"op":"mcm","clk":"5346754034","pt":1646096082983,"mc":[{"id":"1.195395449","rc":[{"atl":[[75,0]],"id":41962160}],"con":true,"img":false}]}
{"op":"mcm","clk":"5346754109","pt":1646096084790,"mc":[{"id":"1.195395449","rc":[{"atb":[[1.2,56.27],[1.16,0]],"id":43066393}],"con":true,"img":false}]}
{"op":"mcm","clk":"5346754139","pt":1646096085564,"mc":[{"id":"1.195395449","rc":[{"atb":[[19.5,0]],"id":40494151}],"con":true,"img":false}]}
{"op":"mcm","clk":"5346754347","pt":1646096090996,"mc":[{"id":"1.195395449","rc":[{"atl":[[780,1]],"id":37495442}],"con":true,"img":false}]}
{"op":"mcm","clk":"5346754384","pt":1646096092078,"mc":[{"id":"1.195395449","rc":[{"atl":[[60,0.73]],"id":41962160},{"atb":[[20,0]],"id":40494151}],"con":true,"img":false}]}
{"op":"mcm","clk":"5346754388","pt":1646096092180,"mc":[{"id":"1.195395449","rc":[{"atl":[[46,0]],"id":41962160},{"atb":[[19.5,3.32]],"id":40494151}],"con":true,"img":false}]}
{"op":"mcm","clk":"5346754402","pt":1646096092589,"mc":[{"id":"1.195395449","rc":[{"atl":[[42,2.44]],"id":41962160}],"con":true,"img":false}]}
{"op":"mcm","clk":"5346754408","pt":1646096092692,"mc":[{"id":"1.195395449","rc":[{"atl":[[1000,1.38]],"id":41962160}],"con":true,"img":false}]}
{"op":"mcm","clk":"5346754493","pt":1646096095418,"mc":[{"id":"1.195395449","rc":[{"atb":[[11.5,6.86],[16.5,0],[19,0],[23,2.7]],"id":37495442},{"atl":[[260,0],[310,0],[160,0],[210,0]],"id":37495442},{"atb":[[10.5,10.53],[15.5,0.07],[18,0],[21,0]],"id":40995914},{"atl":[[150,0],[300,0],[200,2],[250,1]],"id":40995914},{"atb":[[10.5,0],[15.5,0],[18,0],[21,0]],"id":41360966},{"atl":[[150,0],[300,0],[200,2],[250,0]],"id":41360966},{"atb":[[12,0],[6.8,0],[9.8,0],[8.8,2.11]],"id":41962160},{"atl":[[140,0],[190,0],[70,0],[95,0]],"id":41962160},{"atb":[[14,0],[16.5,0],[9.6,11.63],[19,0]],"id":40494151},{"atl":[[140,0],[290,0],[190,2],[240,1]],"id":40494151},{"atb":[[11.5,0],[16.5,0],[19,0],[23,0]],"id":25760990},{"atl":[[260,0],[310,0],[160,0],[210,2]],"id":25760990},{"atb":[[1.25,0],[1.15,0],[1.3,0],[1.35,0]],"id":43066393},{"atl":[[2.54,0],[2.64,0],[2.84,0],[2.74,0]],"id":43066393},{"atb":[[3.6,0],[3.85,17.54],[3.1,0],[4.2,0]],"id":40908100},{"atl":[[12.5,0],[15,0],[17.5,0],[20,0]],"id":40908100}],"con":true,"img":false}]}
{"op":"mcm","clk":"5346754499","pt":1646096095624,"mc":[{"id":"1.195395449","rc":[{"atl":[[320,2],[200,0]],"id":41360966},{"atl":[[190,0],[220,3]],"id":40494151},{"atl":[[210,0],[250,3]],"id":25760990}],"con":true,"img":false}]}
{"op":"mcm","clk":"5346754503","pt":1646096095678,"mc":[{"id":"1.195395449","rc":[{"atb":[[19,0]],"id":40995914},{"atb":[[23,0.35]],"id":41360966}],"con":true,"img":false}]}
{"op":"mcm","clk":"5346754506","pt":1646096095779,"mc":[{"id":"1.195395449","rc":[{"atb":[[1.01,1.55]],"id":40995914},{"atb":[[1.01,1.58]],"id":41360966}],"con":true,"img":false}]}
{"op":"mcm","clk":"5346754520","pt":1646096096087,"mc":[{"id":"1.195395449","rc":[{"atl":[[90,0],[120,3.53]],"id":41962160}],"con":true,"img":false}]}
{"op":"mcm","clk":"5346754524","pt":1646096096189,"mc":[{"id":"1.195395449","rc":[{"atb":[[18.5,0.58]],"id":40995914},{"atb":[[19.5,0]],"id":37495442},{"atl":[[150,0]],"id":37495442},{"atl":[[140,0]],"id":41360966},{"atb":[[17,0]],"id":40494151},{"atl":[[17,0]],"id":40908100}],"con":true,"img":false}]}
{"op":"mcm","clk":"5346754527","pt":1646096096290,"mc":[{"id":"1.195395449","rc":[{"atb":[[17.5,6.27]],"id":37495442},{"atl":[[190,0.24],[480,0],[500,2]],"id":37495442},{"atb":[[16.5,2.79]],"id":40995914},{"atl":[[320,0],[330,5.7],[180,0.25]],"id":41360966},{"atb":[[14,7.94]],"id":40494151},{"atl":[[22,12.44]],"id":40908100}],"con":true,"img":false}]}
{"op":"mcm","clk":"5346754567","pt":1646096097418,"mc":[{"id":"1.195395449","rc":[{"atb":[[11.5,23.43],[16.5,8.42],[19,4.83],[23,4.68]],"id":37495442},{"atl":[[260,0.73],[310,0.61],[160,0.79],[210,0.6]],"id":37495442},{"atb":[[10.5,28.75],[15.5,9.02],[18,5.09],[21,2.16]],"id":40995914},{"atl":[[150,0.84],[300,0.63],[200,2.63],[250,1.76]],"id":40995914},{"atb":[[10.5,18.31],[15.5,8.99],[18,5.11],[21,2.17]],"id":41360966},{"atl":[[150,0.84],[300,0.63],[200,0.63],[250,0.76]],"id":41360966},{"atb":[[12,3.95],[6.8,30],[9.8,9.88],[8.8,18.84]],"id":41962160},{"atl":[[140,1.36],[190,1],[70,1.82],[95,1.34]],"id":41962160},{"atb":[[14,20.66],[9.6,37.25],[16.5,7.1],[19,3.06]],"id":40494151},{"atl":[[140,0.74],[290,0.53],[190,0.54],[240,1.64]],"id":40494151},{"atb":[[11.5,16.57],[16.5,8.42],[19,4.83],[23,1.97]],"id":25760990},{"atl":[[260,0.73],[310,0.61],[160,0.79],[210,0.6]],"id":25760990},{"atb":[[3.6,50.2],[3.85,48.07],[3.1,82.87],[4.2,13.59]],"id":40908100},{"atl":[[12.5,10.97],[15,9.02],[17.5,11.48],[20,9.96]],"id":40908100},{"atb":[[1.25,471.88],[1.15,1048.63],[1.3,262.16],[1.35,112.35]],"id":43066393},{"atl":[[2.54,87.44],[2.64,82.11],[2.84,109.78],[2.74,116.09]],"id":43066393}],"con":true,"img":false}]}
{"op":"mcm","clk":"5346754575","pt":1646096097623,"mc":[{"id":"1.195395449","rc":[{"atl":[[190,2.54],[220,1]],"id":40494151},{"atl":[[210,2.6],[250,1]],"id":25760990}],"con":true,"img":false}]}
{"op":"mcm","clk":"5346754610","pt":1646096098498,"mc":[{"id":"1.195395449","rc":[{"atb":[[20,0]],"id":25760990}],"con":true,"img":false}]}
{"op":"mcm","clk":"5346754644","pt":1646096099526,"mc":[{"id":"1.195395449","rc":[{"atb":[[1.2,2.23]],"id":40995914},{"atb":[[13,0.61]],"id":41962160}],"con":true,"img":false}]}
{"op":"mcm","clk":"5346754654","pt":1646096099784,"mc":[{"id":"1.195395449","rc":[{"atb":[[1.2,1.73]],"id":40995914}],"con":true,"img":false}]}
{"op":"mcm","clk":"5346754667","pt":1646096100093,"mc":[{"id":"1.195395449","rc":[{"atb":[[1.2,0]],"id":40995914}],"con":true,"img":false}]}
{"op":"mcm","clk":"5346754673","pt":1646096100198,"mc":[{"id":"1.195395449","rc":[{"atb":[[14,3.27]],"id":40995914},{"atl":[[1.45,6.5]],"id":43066393}],"con":true,"img":false}]}
{"op":"mcm","clk":"5346754689","pt":1646096100403,"mc":[{"id":"1.195395449","rc":[{"atb":[[13,2.45]],"id":41962160},{"atl":[[38,0.62]],"id":41962160}],"con":true,"img":false}]}
{"op":"mcm","clk":"5346754698","pt":1646096100608,"mc":[{"id":"1.195395449","rc":[{"atl":[[34,0],[38,2.62],[42,0],[1000,3.05]],"id":41962160}],"con":true,"img":false}]}
{"op":"mcm","clk":"5346754703","pt":1646096100712,"mc":[{"id":"1.195395449","rc":[{"spn":61.0,"spf":1.0,"id":40995914},{"spn":62.0,"spf":1.0,"id":41360966},{"atl":[[1000,1.62]],"id":41962160},{"spn":25.0,"spf":1.0,"id":41962160},{"spn":62.0,"spf":1.0,"id":40494151},{"spn":62.0,"spf":1.0,"id":25760990},{"spn":1.4,"spf":1.0,"id":43066393},{"spn":6.5,"spf":1.0,"id":40908100}],"con":true,"img":false}]}
{"op":"mcm","clk":"5346754707","pt":1646096100812,"mc":[{"id":"1.195395449","rc":[{"atl":[[1000,1.38]],"id":41962160}],"con":true,"img":false}]}
{"op":"mcm","clk":"5346754711","pt":1646096100914,"mc":[{"id":"1.195395449","rc":[{"atl":[[38,2.86]],"id":41962160}],"con":true,"img":false}]}
{"op":"mcm","clk":"5346754722","pt":1646096101121,"mc":[{"id":"1.195395449","rc":[{"atb":[[13.5,0]],"id":41962160}],"con":true,"img":false}]}
{"op":"mcm","clk":"5346754752","pt":1646096101894,"mc":[{"id":"1.195395449","rc":[{"atb":[[1.01,2.53]],"id":41962160}],"con":true,"img":false}]}
{"op":"mcm","clk":"5346754757","pt":1646096101996,"mc":[{"id":"1.195395449","rc":[{"atl":[[65,1.62]],"id":41962160}],"con":true,"img":false}]}
{"op":"mcm","clk":"5346754767","pt":1646096102205,"mc":[{"id":"1.195395449","rc":[{"atb":[[1.01,1.26]],"id":41962160}],"con":true,"img":false}]}
{"op":"mcm","clk":"5346754772","pt":1646096102304,"mc":[{"id":"1.195395449","rc":[{"atb":[[1.01,0]],"id":41962160},{"atb":[[20,4.87]],"id":25760990}],"con":true,"img":false}]}
{"op":"mcm","clk":"5346754777","pt":1646096102406,"mc":[{"id":"1.195395449","rc":[{"atb":[[13.5,1.26]],"id":41962160}],"con":true,"img":false}]}
{"op":"mcm","clk":"5346754780","pt":1646096102508,"mc":[{"id":"1.195395449","rc":[{"atb":[[1.2,2.23]],"id":41962160}],"con":true,"img":false}]}
{"op":"mcm","clk":"5346754791","pt":1646096102817,"mc":[{"id":"1.195395449","rc":[{"atb":[[1.2,1.88]],"id":41962160}],"con":true,"img":false}]}
{"op":"mcm","clk":"5346754803","pt":1646096103125,"mc":[{"id":"1.195395449","rc":[{"atb":[[1.2,0]],"id":41962160}],"con":true,"img":false}]}
{"op":"mcm","clk":"5346754811","pt":1646096103229,"mc":[{"id":"1.195395449","rc":[{"atb":[[13,4.33]],"id":41962160}],"con":true,"img":false}]}
{"op":"mcm","clk":"5346754818","pt":1646096103435,"mc":[{"id":"1.195395449","rc":[{"atl":[[200,2.63]],"id":41360966},{"atb":[[9,12.27],[8.8,16.73]],"id":41962160}],"con":true,"img":false}]}
{"op":"mcm","clk":"5346754821","pt":1646096103486,"mc":[{"id":"1.195395449","rc":[{"atl":[[330,3.7]],"id":41360966}],"con":true,"img":false}]}
{"op":"mcm","clk":"5346754887","pt":1646096105127,"mc":[{"id":"1.195395449","rc":[{"atb":[[14,1.54]],"id":40995914}],"con":true,"img":false}]}
{"op":"mcm","clk":"5346754904","pt":1646096105434,"mc":[{"id":"1.195395449","rc":[{"atb":[[16,16.22]],"id":40995914},{"atb":[[22,16.71]],"id":37495442},{"atb":[[22,19.42]],"id":41360966},{"atb":[[9,10.45],[11,16.32],[8.8,18.6]],"id":41962160},{"atb":[[16,16.22]],"id":40494151},{"atb":[[18,16.22]],"id":25760990},{"atb":[[1.19,266.22]],"id":43066393},{"atb":[[4,56.22]],"id":40908100}],"con":true,"img":false}]}
{"op":"mcm","clk":"5346754919","pt":1646096105692,"mc":[{"id":"1.195395449","rc":[{"atl":[[38,0.86],[40,3.84]],"id":41962160},{"atb":[[4.9,1.7],[4.6,0]],"id":40908100}],"con":true,"img":false}]}
{"op":"mcm","clk":"5346754924","pt":1646096105793,"mc":[{"id":"1.195395449","rc":[{"atb":[[1.01,0]],"id":37495442},{"atb":[[1.03,1.67],[12.5,4.55]],"id":41962160}],"con":true,"img":false}]}
{"op":"mcm","clk":"5346754927","pt":1646096105897,"mc":[{"id":"1.195395449","rc":[{"atb":[[24,2]],"id":37495442},{"atb":[[13.5,2.77]],"id":41962160}],"con":true,"img":false}]}
{"op":"mcm","clk":"5346754932","pt":1646096106000,"mc":[{"id":"1.195395449","rc":[{"atb":[[13,3.71]],"id":41962160},{"atb":[[4.9,0]],"id":40908100}],"con":true,"img":false}]}
{"op":"mcm","clk":"5346754937","pt":1646096106103,"mc":[{"id":"1.195395449","rc":[{"atl":[[130,0]],"id":40995914},{"atb":[[4.6,1.7]],"id":40908100}],"con":true,"img":false}]}
{"op":"mcm","clk":"5346754939","pt":1646096106205,"mc":[{"id":"1.195395449","rc":[{"atl":[[150,1.18],[200,0.63],[210,2]],"id":40995914},{"atb":[[1.03,0.57]],"id":41962160}],"con":true,"img":false}]}
{"op":"mcm","clk":"5346754946","pt":1646096106307,"mc":[{"id":"1.195395449","rc":[{"atl":[[150,3.18]],"id":40995914},{"atb":[[4.9,1.7]],"id":40908100}],"con":true,"img":false}]}
{"op":"mcm","clk":"5346754953","pt":1646096106410,"mc":[{"id":"1.195395449","rc":[{"atl":[[210,1.42]],"id":40995914},{"atb":[[1.03,0],[13,1.88]],"id":41962160},{"atl":[[1000,0]],"id":41962160},{"atb":[[4.6,0]],"id":40908100}],"con":true,"img":false}]}
{"op":"mcm","clk":"5346754956","pt":1646096106514,"mc":[{"id":"1.195395449","rc":[{"atb":[[14.5,0.57]],"id":41962160},{"atl":[[38,2.25]],"id":41962160}],"con":true,"img":false}]}
{"op":"mcm","clk":"5346754979","pt":1646096107130,"mc":[{"id":"1.195395449","rc":[{"atl":[[38,0.86]],"id":41962160}],"con":true,"img":false}]}
{"op":"mcm","clk":"5346754984","pt":1646096107231,"mc":[{"id":"1.195395449","rc":[{"atl":[[1000,1.38]],"id":41962160}],"con":true,"img":false}]}
{"op":"mcm","clk":"5346754986","pt":1646096107333,"mc":[{"id":"1.195395449","rc":[{"atl":[[710,1]],"id":37495442},{"atb":[[9,12.27]],"id":41962160}],"con":true,"img":false}]}
{"op":"mcm","clk":"5346754990","pt":1646096107435,"mc":[{"id":"1.195395449","rc":[{"atl":[[720,0]],"id":37495442},{"atb":[[8.8,16.73]],"id":41962160}],"con":true,"img":false}]}
{"op":"mcm","clk":"5346755079","pt":1646096109494,"mc":[{"id":"1.195395449","rc":[{"atl":[[710,0],[720,1]],"id":37495442}],"con":true,"img":false}]}
{"op":"mcm","clk":"5346755090","pt":1646096109801,"mc":[{"id":"1.195395449","rc":[{"atb":[[13,0]],"id":41962160}],"con":true,"img":false}]}
{"op":"mcm","clk":"5346755105","pt":1646096110212,"mc":[{"id":"1.195395449","rc":[{"atb":[[19,0]],"id":41360966}],"con":true,"img":false}]}
{"op":"mcm","clk":"5346755109","pt":1646096110314,"mc":[{"id":"1.195395449","rc":[{"atb":[[20,6.28]],"id":41360966}],"con":true,"img":false}]}
{"op":"mcm","clk":"5346755114","pt":1646096110417,"mc":[{"id":"1.195395449","rc":[{"atb":[[11,29.84]],"id":41962160},{"atb":[[4,72.45]],"id":40908100},{"atb":[[1.19,282.45]],"id":43066393}],"con":true,"img":false}]}
{"op":"mcm","clk":"5346755137","pt":1646096110930,"mc":[{"id":"1.195395449","rc":[{"atb":[[13.5,1.5]],"id":41962160}],"con":true,"img":false}]}
{"op":"mcm","clk":"5346755143","pt":1646096111033,"mc":[{"id":"1.195395449","rc":[{"atl":[[720,0],[710,1]],"id":37495442}],"con":true,"img":false}]}
{"op":"mcm","clk":"5346755153","pt":1646096111238,"mc":[{"id":"1.195395449","rc":[{"atb":[[1.01,2.53],[13,1.83]],"id":41962160}],"con":true,"img":false}]}
{"op":"mcm","clk":"5346755157","pt":1646096111343,"mc":[{"id":"1.195395449","rc":[{"atb":[[13.5,0]],"id":41962160}],"con":true,"img":false}]}
{"op":"mcm","clk":"5346755161","pt":1646096111400,"mc":[{"id":"1.195395449","rc":[{"atb":[[1.01,1.26],[13,3.33]],"id":41962160}],"con":true,"img":false}]}
{"op":"mcm","clk":"5346755167","pt":1646096111603,"mc":[{"id":"1.195395449","rc":[{"atb":[[1.01,0]],"id":41962160}],"con":true,"img":false}]}
{"op":"mcm","clk":"5346755171","pt":1646096111705,"mc":[{"id":"1.195395449","rc":[{"atb":[[14,1.38]],"id":41962160}],"con":true,"img":false}]}
{"op":"mcm","clk":"5346755177","pt":1646096111910,"mc":[{"id":"1.195395449","rc":[{"atb":[[22,0.49]],"id":37495442},{"atb":[[16,0]],"id":40995914},{"atb":[[22,3.19]],"id":41360966},{"atb":[[11,0.09]],"id":41962160},{"atb":[[16,0]],"id":40494151},{"atb":[[4,40]],"id":40908100}],"con":true,"img":false}]}
{"op":"mcm","clk":"5346755204","pt":1646096112423,"mc":[{"id":"1.195395449","rc":[{"atb":[[24,0.41]],"id":37495442}],"con":true,"img":false}]}
{"op":"mcm","clk":"5346755208","pt":1646096112526,"mc":[{"id":"1.195395449","rc":[{"atb":[[1.01,1.58]],"id":37495442}],"con":true,"img":false}]}
{"op":"mcm","clk":"5346755233","pt":1646096113397,"mc":[{"id":"1.195395449","rc":[{"atb":[[19.5,0]],"id":41360966}],"con":true,"img":false}]}
{"op":"mcm","clk":"5346755257","pt":1646096114115,"mc":[{"id":"1.195395449","rc":[{"atb":[[20,0]],"id":41360966}],"con":true,"img":false}]}
{"op":"mcm","clk":"5346755260","pt":1646096114216,"mc":[{"id":"1.195395449","rc":[{"atb":[[18.5,6.28]],"id":41360966}],"con":true,"img":false}]}
{"op":"mcm","clk":"5346755270","pt":1646096114632,"mc":[{"id":"1.195395449","rc":[{"atb":[[1.2,2.23]],"id":41962160}],"con":true,"img":false}]}
{"op":"mcm","clk":"5346755282","pt":1646096115045,"mc":[{"id":"1.195395449","rc":[{"atb":[[1.2,1.81]],"id":41962160}],"con":true,"img":false}]}
{"op":"mcm","clk":"5346755291","pt":1646096115300,"mc":[{"id":"1.195395449","rc":[{"atb":[[1.2,0]],"id":41962160}],"con":true,"img":false}]}
{"op":"mcm","clk":"5346755294","pt":1646096115404,"mc":[{"id":"1.195395449","rc":[{"atb":[[13.5,1.81]],"id":41962160}],"con":true,"img":false}]}
{"op":"mcm","clk":"5346755313","pt":1646096116019,"mc":[{"id":"1.195395449","rc":[{"atb":[[13,1.5]],"id":41962160}],"con":true,"img":false}]}
{"op":"mcm","clk":"5346755317","pt":1646096116121,"mc":[{"id":"1.195395449","rc":[{"atb":[[4.9,0],[4.6,1.7]],"id":40908100}],"con":true,"img":false}]}
{"op":"mcm","clk":"5346755321","pt":1646096116224,"mc":[{"id":"1.195395449","rc":[{"atb":[[4.9,1.7],[4.6,0]],"id":40908100}],"con":true,"img":false}]}
{"op":"mcm","clk":"5346755325","pt":1646096116326,"mc":[{"id":"1.195395449","rc":[{"atl":[[710,0],[720,1]],"id":37495442}],"con":true,"img":false}]}
{"op":"mcm","clk":"5346755346","pt":1646096116942,"mc":[{"id":"1.195395449","rc":[{"atl":[[720,0],[710,1]],"id":37495442}],"con":true,"img":false}]}
{"op":"mcm","clk":"5346755353","pt":1646096117148,"mc":[{"id":"1.195395449","rc":[{"atb":[[19,5.14]],"id":41360966}],"con":true,"img":false}]}
{"op":"mcm","clk":"5346755394","pt":1646096118223,"mc":[{"id":"1.195395449","rc":[{"atl":[[180,0]],"id":41360966}],"con":true,"img":false}]}
