{"op":"mcm","clk":"5351767857","pt":1646175389022,"mc":[{"id":"1.195453771","marketDefinition":{"bspMarket":true,"turnInPlayEnabled":false,"persistenceEnabled":false,"marketBaseRate":7.0,"eventId":"31272499","eventTypeId":"4339","numberOfWinners":3,"bettingType":"ODDS","marketType":"PLACE","marketTime":"2022-03-02T09:54:00.000Z","suspendTime":"2022-03-02T09:54:00.000Z","bspReconciled":false,"complete":true,"inPlay":false,"crossMatching":false,"runnersVoidable":false,"numberOfActiveRunners":8,"betDelay":0,"status":"OPEN","runners":[{"status":"ACTIVE","sortPriority":1,"id":36074638,"name":"1. Just Law"},{"status":"ACTIVE","sortPriority":2,"id":39784543,"name":"2. Surreal"},{"status":"ACTIVE","sortPriority":3,"id":36500377,"name":"3. Mystery Train"},{"status":"ACTIVE","sortPriority":4,"id":42189401,"name":"4. Daisy Cousins"},{"status":"ACTIVE","sortPriority":5,"id":35801684,"name":"5. Zeke The Freak"},{"status":"ACTIVE","sortPriority":6,"id":37127725,"name":"6. Exit Plan"},{"status":"ACTIVE","sortPriority":7,"id":26051221,"name":"7. Farmor Crownies"},{"status":"ACTIVE","sortPriority":8,"id":28338255,"name":"8. Until Late"}],"regulators":["MR_INT"],"venue":"Rockhampton","countryCode":"AU","discountAllowed":true,"timezone":"Australia/Queensland","openDate":"2022-03-02T08:34:00.000Z","version":4382437857,"name":"To Be Placed","eventName":"Rockhampton (AUS) 2nd Mar"},"rc":[],"con":true,"img":false}]}
{"op":"mcm","clk":"5351829775","pt":1646176640937,"mc":[{"id":"1.195453771","rc":[{"atb":[[2.74,69.45],[2.84,65.67],[2.94,31.14]],"id":39784543},{"atl":[[8,1.72],[10,1.34],[20,1.27],[15,1.72],[30,1.66]],"id":39784543},{"spn":5.47,"spf":"NaN","id":39784543},{"atb":[[2.5,80.56],[2.6,75.53],[2.7,35.54]],"id":36500377},{"atl":[[16.5,1.55],[8.6,1.58],[11.5,2.3],[23,2.19],[6.6,2.15]],"id":36500377},{"spn":4.65,"spf":"NaN","id":36500377},{"atb":[[2.5,80.56],[2.6,75.53],[2.7,35.54]],"id":35801684},{"atl":[[16.5,1.55],[8.6,1.58],[11.5,2.3],[23,2.19],[6.6,2.15]],"id":35801684},{"spn":4.65,"spf":"NaN","id":35801684},{"atb":[[2.8,67.13],[2.9,31.8],[2.7,71.08]],"id":36074638},{"atl":[[19.5,1.3],[9.8,1.37],[7.8,1.77],[14.5,1.79],[29,1.72]],"id":36074638},{"spn":5.35,"spf":"NaN","id":36074638},{"atb":[[1.19,318.02],[1.14,863.2],[1.09,1342.77]],"id":42189401},{"atl":[[2.88,12.85],[3.2,21.97],[2.28,9.43],[2.68,14.38],[2.48,8.16]],"id":42189401},{"spn":1.73,"spf":"NaN","id":42189401},{"atb":[[2.4,86.32],[2.5,80.56],[2.6,37.76]],"id":28338255},{"atl":[[6.2,2.32],[10.5,2.54],[21,2.41],[8.2,1.67],[15.5,1.66]],"id":28338255},{"spn":4.4,"spf":"NaN","id":28338255},{"atb":[[1.2,604.24],[1.25,241.69],[1.15,805.66]],"id":37127725},{"atl":[[3.6,18.59],[3.1,11.5],[2.44,8.39],[2.64,7.37],[2.84,13.13]],"id":37127725},{"spn":1.84,"spf":"NaN","id":37127725},{"atb":[[1.2,604.24],[1.25,241.69],[1.15,805.66]],"id":26051221},{"atl":[[3.6,18.59],[3.1,11.5],[2.44,8.39],[2.64,7.37],[2.84,13.13]],"id":26051221},{"spn":1.84,"spf":"NaN","id":26051221}],"con":true,"img":false}]}
{"op":"mcm","clk":"5351831316","pt":1646176678441,"mc":[{"id":"1.195453771","rc":[{"atb":[[2.74,0],[2.84,0],[2.94,0]],"id":39784543},{"atl":[[8,0],[10,0],[20,0],[15,0],[30,0]],"id":39784543},{"atb":[[2.5,0],[2.6,0],[2.7,0]],"id":36500377},{"atl":[[16.5,0],[8.6,0],[11.5,0],[23,0],[6.6,0]],"id":36500377},{"atb":[[2.5,0],[2.6,0],[2.7,0]],"id":35801684},{"atl":[[16.5,0],[8.6,0],[11.5,0],[23,0],[6.6,0]],"id":35801684},{"atb":[[2.8,0],[2.9,0],[2.7,0]],"id":36074638},{"atl":[[19.5,0],[9.8,0],[7.8,0],[14.5,0],[29,0]],"id":36074638},{"atb":[[1.19,0],[1.14,0],[1.09,0]],"id":42189401},{"atl":[[2.88,0],[3.2,0],[2.28,0],[2.68,0],[2.48,0]],"id":42189401},{"atb":[[2.4,0],[2.5,0],[2.6,0]],"id":28338255},{"atl":[[6.2,0],[10.5,0],[21,0],[8.2,0],[15.5,0]],"id":28338255},{"atb":[[1.2,0],[1.25,0],[1.15,0]],"id":37127725},{"atl":[[3.6,0],[3.1,0],[2.44,0],[2.64,0],[2.84,0]],"id":37127725},{"atb":[[1.2,0],[1.25,0],[1.15,0]],"id":26051221},{"atl":[[3.6,0],[3.1,0],[2.44,0],[2.64,0],[2.84,0]],"id":26051221}],"con":true,"img":false}]}
{"op":"mcm","clk":"5351832829","pt":1646176717820,"mc":[{"id":"1.195453771","rc":[{"atb":[[2.74,69.45],[2.84,65.67],[2.94,31.14]],"id":39784543},{"atl":[[8,1.72],[10,1.34],[20,1.27],[15,1.72],[30,1.66]],"id":39784543},{"atb":[[2.5,80.56],[2.6,75.53],[2.7,35.54]],"id":36500377},{"atl":[[16.5,1.55],[8.6,1.58],[11.5,2.3],[23,2.19],[6.6,2.15]],"id":36500377},{"atb":[[2.5,80.56],[2.6,75.53],[2.7,35.54]],"id":35801684},{"atl":[[16.5,1.55],[8.6,1.58],[11.5,2.3],[23,2.19],[6.6,2.15]],"id":35801684},{"atb":[[2.8,67.13],[2.9,31.8],[2.7,71.08]],"id":36074638},{"atl":[[19.5,1.3],[9.8,1.37],[7.8,1.77],[14.5,1.79],[29,1.72]],"id":36074638},{"atb":[[1.19,318.02],[1.14,863.2],[1.09,1342.77]],"id":42189401},{"atl":[[2.88,12.85],[3.2,21.97],[2.28,9.43],[2.68,14.38],[2.48,8.16]],"id":42189401},{"atb":[[1.2,604.24],[1.25,241.69],[1.15,805.66]],"id":37127725},{"atl":[[3.6,18.59],[3.1,11.5],[2.44,8.39],[2.64,7.37],[2.84,13.13]],"id":37127725},{"atb":[[1.6,201.41],[1.7,86.32],[1.65,185.92]],"id":28338255},{"atl":[[3.2,5.49],[3.7,4.47],[6.8,8.33],[4.4,7.1],[5.4,5.49]],"id":28338255},{"spn":2.45,"spf":"NaN","id":28338255},{"atb":[[1.2,604.24],[1.25,483.39],[1.3,201.41]],"id":26051221},{"atl":[[2.54,7.84],[3.85,16.96],[2.74,6.94],[3.35,10.28],[2.94,12.46]],"id":26051221},{"spn":1.92,"spf":"NaN","id":26051221}],"con":true,"img":false}]}
{"op":"mcm","clk":"5351835009","pt":1646176768084,"mc":[{"id":"1.195453771","rc":[{"atb":[[2.74,0],[2.84,0],[2.94,0]],"id":39784543},{"atl":[[8,0],[10,0],[20,0],[15,0],[30,0]],"id":39784543},{"atb":[[2.5,0],[2.6,0],[2.7,0]],"id":36500377},{"atl":[[16.5,0],[8.6,0],[11.5,0],[23,0],[6.6,0]],"id":36500377},{"atb":[[2.5,0],[2.6,0],[2.7,0]],"id":35801684},{"atl":[[16.5,0],[8.6,0],[11.5,0],[23,0],[6.6,0]],"id":35801684},{"atb":[[2.8,0],[2.9,0],[2.7,0]],"id":36074638},{"atl":[[19.5,0],[9.8,0],[7.8,0],[14.5,0],[29,0]],"id":36074638},{"atb":[[1.19,0],[1.14,0],[1.09,0]],"id":42189401},{"atl":[[2.88,0],[3.2,0],[2.28,0],[2.68,0],[2.48,0]],"id":42189401},{"atb":[[1.2,0],[1.25,0],[1.15,0]],"id":37127725},{"atl":[[3.6,0],[3.1,0],[2.44,0],[2.64,0],[2.84,0]],"id":37127725},{"atb":[[1.2,0],[1.25,0],[1.3,0]],"id":26051221},{"atl":[[2.54,0],[3.85,0],[2.74,0],[3.35,0],[2.94,0]],"id":26051221},{"atb":[[1.6,0],[1.7,0],[1.65,0]],"id":28338255},{"atl":[[3.2,0],[3.7,0],[6.8,0],[4.4,0],[5.4,0]],"id":28338255}],"con":true,"img":false}]}
{"op":"mcm","clk":"5351835810","pt":1646176785738,"mc":[{"id":"1.195453771","rc":[{"atb":[[2.74,69.45],[2.84,65.67],[2.94,31.14]],"id":39784543},{"atl":[[8,1.72],[10,1.34],[20,1.27],[15,1.72],[30,1.66]],"id":39784543},{"atb":[[2.5,80.56],[2.6,75.53],[2.7,35.54]],"id":36500377},{"atl":[[16.5,1.55],[8.6,1.58],[11.5,2.3],[23,2.19],[6.6,2.15]],"id":36500377},{"atb":[[2.5,80.56],[2.6,75.53],[2.7,35.54]],"id":35801684},{"atl":[[16.5,1.55],[8.6,1.58],[11.5,2.3],[23,2.19],[6.6,2.15]],"id":35801684},{"atb":[[2.8,67.13],[2.9,31.8],[2.7,71.08]],"id":36074638},{"atl":[[19.5,1.3],[9.8,1.37],[7.8,1.77],[14.5,1.79],[29,1.72]],"id":36074638},{"atb":[[1.19,318.02],[1.14,863.2],[1.09,1342.77]],"id":42189401},{"atl":[[2.88,12.85],[3.2,21.97],[2.28,9.43],[2.68,14.38],[2.48,8.16]],"id":42189401},{"atb":[[1.2,604.24],[1.25,483.39],[1.3,201.41]],"id":26051221},{"atl":[[2.54,7.84],[3.85,16.96],[2.74,6.94],[3.35,10.28],[2.94,12.46]],"id":26051221},{"atb":[[1.6,201.41],[1.7,86.32],[1.65,185.92]],"id":28338255},{"atl":[[3.2,5.49],[3.7,4.47],[6.8,8.33],[4.4,7.1],[5.4,5.49]],"id":28338255},{"atb":[[1.2,604.24],[1.25,241.69],[1.15,805.66]],"id":37127725},{"atl":[[3.6,18.59],[3.1,11.5],[2.44,8.39],[2.64,7.37],[2.84,13.13]],"id":37127725}],"con":true,"img":false}]}
{"op":"mcm","clk":"5352003876","pt":1646180202623,"mc":[{"id":"1.195453771","marketDefinition":{"bspMarket":true,"turnInPlayEnabled":false,"persistenceEnabled":false,"marketBaseRate":7.0,"eventId":"31272499","eventTypeId":"4339","numberOfWinners":3,"bettingType":"ODDS","marketType":"PLACE","marketTime":"2022-03-02T09:54:00.000Z","suspendTime":"2022-03-02T09:54:00.000Z","bspReconciled":false,"complete":true,"inPlay":false,"crossMatching":false,"runnersVoidable":false,"numberOfActiveRunners":8,"betDelay":0,"status":"OPEN","runners":[{"status":"ACTIVE","sortPriority":1,"id":36074638,"name":"1. Just Law"},{"status":"ACTIVE","sortPriority":2,"id":39784543,"name":"2. Surreal"},{"status":"ACTIVE","sortPriority":3,"id":36500377,"name":"3. Mystery Train"},{"status":"ACTIVE","sortPriority":4,"id":42189401,"name":"4. Daisy Cousins"},{"status":"ACTIVE","sortPriority":5,"id":35801684,"name":"5. Zeke The Freak"},{"status":"ACTIVE","sortPriority":6,"id":37127725,"name":"6. Exit Plan"},{"status":"ACTIVE","sortPriority":7,"id":26051221,"name":"7. Farmor Crownies"},{"status":"ACTIVE","sortPriority":8,"id":28338255,"name":"8. Until Late"}],"regulators":["MR_INT"],"venue":"Rockhampton","countryCode":"AU","discountAllowed":true,"timezone":"Australia/Queensland","openDate":"2022-03-02T08:34:00.000Z","version":4382437857,"name":"To Be Placed","eventName":"Rockhampton (AUS) 2nd Mar"},"rc":[{"atb":[[2.74,69.46],[2.84,65.68],[2.94,31.15]],"id":39784543},{"atl":[[8,1.72],[10,1.34],[20,1.27],[15,1.72],[30,1.66]],"id":39784543},{"spn":5.47,"spf":"NaN","id":39784543},{"atb":[[2.5,80.57],[2.6,75.53],[2.7,35.54]],"id":36500377},{"atl":[[16.5,1.55],[8.6,1.58],[11.5,2.3],[23,2.19],[6.6,2.15]],"id":36500377},{"spn":4.65,"spf":"NaN","id":36500377},{"atb":[[2.5,80.57],[2.6,75.53],[2.7,35.54]],"id":35801684},{"atl":[[16.5,1.55],[8.6,1.58],[11.5,2.3],[23,2.19],[6.6,2.15]],"id":35801684},{"spn":4.65,"spf":"NaN","id":35801684},{"atb":[[2.8,67.14],[2.9,31.8],[2.7,71.09]],"id":36074638},{"atl":[[19.5,1.3],[9.8,1.37],[7.8,1.77],[14.5,1.79],[29,1.72]],"id":36074638},{"spn":5.35,"spf":"NaN","id":36074638},{"atb":[[1.19,318.05],[1.14,863.3],[1.09,1342.91]],"id":42189401},{"atl":[[2.88,12.85],[3.2,21.97],[2.28,9.44],[2.68,14.38],[2.48,8.16]],"id":42189401},{"spn":1.73,"spf":"NaN","id":42189401},{"atb":[[1.6,201.43],[1.7,86.32],[1.65,185.94]],"id":28338255},{"atl":[[3.2,5.49],[3.7,4.47],[6.8,8.33],[4.4,7.11],[5.4,5.49]],"id":28338255},{"spn":2.45,"spf":"NaN","id":28338255},{"atb":[[1.2,604.31],[1.25,241.72],[1.15,805.74]],"id":37127725},{"atl":[[3.6,18.59],[3.1,11.5],[2.44,8.39],[2.64,7.37],[2.84,13.13]],"id":37127725},{"spn":1.84,"spf":"NaN","id":37127725},{"atb":[[1.2,604.31],[1.25,483.44],[1.3,201.43]],"id":26051221},{"atl":[[2.54,7.85],[3.85,16.96],[2.74,6.94],[3.35,10.28],[2.94,12.46]],"id":26051221},{"spn":1.92,"spf":"NaN","id":26051221}],"con":true,"img":true}]}
{"op":"mcm","clk":"5352146205","pt":1646183572661,"mc":[{"id":"1.195453771","marketDefinition":{"bspMarket":true,"turnInPlayEnabled":false,"persistenceEnabled":false,"marketBaseRate":7.0,"eventId":"31272499","eventTypeId":"4339","numberOfWinners":3,"bettingType":"ODDS","marketType":"PLACE","marketTime":"2022-03-02T09:54:00.000Z","suspendTime":"2022-03-02T09:54:00.000Z","bspReconciled":false,"complete":true,"inPlay":false,"crossMatching":false,"runnersVoidable":false,"numberOfActiveRunners":8,"betDelay":0,"status":"OPEN","runners":[{"status":"ACTIVE","sortPriority":1,"id":36074638,"name":"1. Just Law"},{"status":"ACTIVE","sortPriority":2,"id":39784543,"name":"2. Surreal"},{"status":"ACTIVE","sortPriority":3,"id":36500377,"name":"3. Mystery Train"},{"status":"ACTIVE","sortPriority":4,"id":42189401,"name":"4. Daisy Cousins"},{"status":"ACTIVE","sortPriority":5,"id":35801684,"name":"5. Zeke The Freak"},{"status":"ACTIVE","sortPriority":6,"id":37127725,"name":"6. Exit Plan"},{"status":"ACTIVE","sortPriority":7,"id":26051221,"name":"7. Farmor Crownies"},{"status":"ACTIVE","sortPriority":8,"id":28338255,"name":"8. Until Late"}],"regulators":["MR_INT"],"venue":"Rockhampton","countryCode":"AU","discountAllowed":true,"timezone":"Australia/Queensland","openDate":"2022-03-02T08:28:00.000Z","version":4382597834,"name":"To Be Placed","eventName":"Rockhampton (AUS) 2nd Mar"},"rc":[],"con":true,"img":false}]}
{"op":"mcm","clk":"5352157265","pt":1646183869273,"mc":[{"id":"1.195453771","marketDefinition":{"bspMarket":true,"turnInPlayEnabled":false,"persistenceEnabled":false,"marketBaseRate":7.0,"eventId":"31272499","eventTypeId":"4339","numberOfWinners":3,"bettingType":"ODDS","marketType":"PLACE","marketTime":"2022-03-02T09:47:00.000Z","suspendTime":"2022-03-02T09:47:00.000Z","bspReconciled":false,"complete":true,"inPlay":false,"crossMatching":false,"runnersVoidable":false,"numberOfActiveRunners":8,"betDelay":0,"status":"OPEN","runners":[{"status":"ACTIVE","sortPriority":1,"id":36074638,"name":"1. Just Law"},{"status":"ACTIVE","sortPriority":2,"id":39784543,"name":"2. Surreal"},{"status":"ACTIVE","sortPriority":3,"id":36500377,"name":"3. Mystery Train"},{"status":"ACTIVE","sortPriority":4,"id":42189401,"name":"4. Daisy Cousins"},{"status":"ACTIVE","sortPriority":5,"id":35801684,"name":"5. Zeke The Freak"},{"status":"ACTIVE","sortPriority":6,"id":37127725,"name":"6. Exit Plan"},{"status":"ACTIVE","sortPriority":7,"id":26051221,"name":"7. Farmor Crownies"},{"status":"ACTIVE","sortPriority":8,"id":28338255,"name":"8. Until Late"}],"regulators":["MR_INT"],"venue":"Rockhampton","countryCode":"AU","discountAllowed":true,"timezone":"Australia/Queensland","openDate":"2022-03-02T08:28:00.000Z","version":4382602050,"name":"To Be Placed","eventName":"Rockhampton (AUS) 2nd Mar"},"rc":[],"con":true,"img":false}]}
{"op":"mcm","clk":"5352237996","pt":1646185602657,"mc":[{"id":"1.195453771","marketDefinition":{"bspMarket":true,"turnInPlayEnabled":false,"persistenceEnabled":false,"marketBaseRate":7.0,"eventId":"31272499","eventTypeId":"4339","numberOfWinners":3,"bettingType":"ODDS","marketType":"PLACE","marketTime":"2022-03-02T09:47:00.000Z","suspendTime":"2022-03-02T09:47:00.000Z","bspReconciled":false,"complete":true,"inPlay":false,"crossMatching":false,"runnersVoidable":false,"numberOfActiveRunners":8,"betDelay":0,"status":"OPEN","runners":[{"status":"ACTIVE","sortPriority":1,"id":36074638,"name":"1. Just Law"},{"status":"ACTIVE","sortPriority":2,"id":39784543,"name":"2. Surreal"},{"status":"ACTIVE","sortPriority":3,"id":36500377,"name":"3. Mystery Train"},{"status":"ACTIVE","sortPriority":4,"id":42189401,"name":"4. Daisy Cousins"},{"status":"ACTIVE","sortPriority":5,"id":35801684,"name":"5. Zeke The Freak"},{"status":"ACTIVE","sortPriority":6,"id":37127725,"name":"6. Exit Plan"},{"status":"ACTIVE","sortPriority":7,"id":26051221,"name":"7. Farmor Crownies"},{"status":"ACTIVE","sortPriority":8,"id":28338255,"name":"8. Until Late"}],"regulators":["MR_INT"],"venue":"Rockhampton","countryCode":"AU","discountAllowed":true,"timezone":"Australia/Queensland","openDate":"2022-03-02T08:28:00.000Z","version":4382602050,"name":"To Be Placed","eventName":"Rockhampton (AUS) 2nd Mar"},"rc":[{"atb":[[2.74,69.57],[2.84,65.78],[2.94,31.2]],"id":39784543},{"atl":[[8,1.72],[10,1.34],[20,1.27],[15,1.72],[30,1.66]],"id":39784543},{"spn":5.47,"spf":"NaN","id":39784543},{"atb":[[2.5,80.7],[2.6,75.65],[2.7,35.6]],"id":36500377},{"atl":[[16.5,1.55],[8.6,1.59],[11.5,2.3],[23,2.2],[6.6,2.15]],"id":36500377},{"spn":4.65,"spf":"NaN","id":36500377},{"atb":[[2.5,80.7],[2.6,75.65],[2.7,35.6]],"id":35801684},{"atl":[[16.5,1.55],[8.6,1.59],[11.5,2.3],[23,2.2],[6.6,2.15]],"id":35801684},{"spn":4.65,"spf":"NaN","id":35801684},{"atb":[[2.8,67.25],[2.9,31.85],[2.7,71.2]],"id":36074638},{"atl":[[19.5,1.3],[9.8,1.37],[7.8,1.77],[14.5,1.79],[29,1.72]],"id":36074638},{"spn":5.35,"spf":"NaN","id":36074638},{"atb":[[1.19,318.56],[1.14,864.66],[1.09,1345.04]],"id":42189401},{"atl":[[2.88,12.87],[3.2,22],[2.28,9.45],[2.68,14.41],[2.48,8.17]],"id":42189401},{"spn":1.73,"spf":"NaN","id":42189401},{"atb":[[1.6,201.75],[1.7,86.46],[1.65,186.23]],"id":28338255},{"atl":[[3.2,5.5],[3.7,4.48],[6.8,8.34],[4.4,7.12],[5.4,5.5]],"id":28338255},{"spn":2.45,"spf":"NaN","id":28338255},{"atb":[[1.2,605.26],[1.25,242.1],[1.15,807.02]],"id":37127725},{"atl":[[3.6,18.62],[3.1,11.52],[2.44,8.4],[2.64,7.38],[2.84,13.15]],"id":37127725},{"spn":1.84,"spf":"NaN","id":37127725},{"atb":[[1.2,605.26],[1.25,484.21],[1.3,201.75]],"id":26051221},{"atl":[[2.54,7.86],[3.85,16.99],[2.74,6.95],[3.35,10.3],[2.94,12.48]],"id":26051221},{"spn":1.92,"spf":"NaN","id":26051221}],"con":true,"img":true}]}
{"op":"mcm","clk":"5352465293","pt":1646191002606,"mc":[{"id":"1.195453771","marketDefinition":{"bspMarket":true,"turnInPlayEnabled":false,"persistenceEnabled":false,"marketBaseRate":7.0,"eventId":"31272499","eventTypeId":"4339","numberOfWinners":3,"bettingType":"ODDS","marketType":"PLACE","marketTime":"2022-03-02T09:47:00.000Z","suspendTime":"2022-03-02T09:47:00.000Z","bspReconciled":false,"complete":true,"inPlay":false,"crossMatching":false,"runnersVoidable":false,"numberOfActiveRunners":8,"betDelay":0,"status":"OPEN","runners":[{"status":"ACTIVE","sortPriority":1,"id":36074638,"name":"1. Just Law"},{"status":"ACTIVE","sortPriority":2,"id":39784543,"name":"2. Surreal"},{"status":"ACTIVE","sortPriority":3,"id":36500377,"name":"3. Mystery Train"},{"status":"ACTIVE","sortPriority":4,"id":42189401,"name":"4. Daisy Cousins"},{"status":"ACTIVE","sortPriority":5,"id":35801684,"name":"5. Zeke The Freak"},{"status":"ACTIVE","sortPriority":6,"id":37127725,"name":"6. Exit Plan"},{"status":"ACTIVE","sortPriority":7,"id":26051221,"name":"7. Farmor Crownies"},{"status":"ACTIVE","sortPriority":8,"id":28338255,"name":"8. Until Late"}],"regulators":["MR_INT"],"venue":"Rockhampton","countryCode":"AU","discountAllowed":true,"timezone":"Australia/Queensland","openDate":"2022-03-02T08:28:00.000Z","version":4382602050,"name":"To Be Placed","eventName":"Rockhampton (AUS) 2nd Mar"},"rc":[{"atb":[[2.74,69.69],[2.84,65.9],[2.94,31.25]],"id":39784543},{"atl":[[8,1.73],[10,1.34],[20,1.27],[15,1.73],[30,1.67]],"id":39784543},{"spn":5.47,"spf":"NaN","id":39784543},{"atb":[[2.5,80.83],[2.6,75.78],[2.7,35.66]],"id":36500377},{"atl":[[16.5,1.56],[8.6,1.59],[11.5,2.31],[23,2.2],[6.6,2.16]],"id":36500377},{"spn":4.65,"spf":"NaN","id":36500377},{"atb":[[2.5,80.83],[2.6,75.78],[2.7,35.66]],"id":35801684},{"atl":[[16.5,1.56],[8.6,1.59],[11.5,2.31],[23,2.2],[6.6,2.16]],"id":35801684},{"spn":4.65,"spf":"NaN","id":35801684},{"atb":[[2.8,67.36],[2.9,31.9],[2.7,71.32]],"id":36074638},{"atl":[[19.5,1.31],[9.8,1.37],[7.8,1.78],[14.5,1.79],[29,1.73]],"id":36074638},{"spn":5.35,"spf":"NaN","id":36074638},{"atb":[[1.19,319.1],[1.14,866.12],[1.09,1347.31]],"id":42189401},{"atl":[[2.88,12.9],[3.2,22.04],[2.28,9.47],[2.68,14.43],[2.48,8.19]],"id":42189401},{"spn":1.73,"spf":"NaN","id":42189401},{"atb":[[1.6,202.09],[1.7,86.61],[1.65,186.55]],"id":28338255},{"atl":[[3.2,5.51],[3.7,4.48],[6.8,8.36],[4.4,7.13],[5.4,5.51]],"id":28338255},{"spn":2.45,"spf":"NaN","id":28338255},{"atb":[[1.2,606.29],[1.25,242.51],[1.15,808.38]],"id":37127725},{"atl":[[3.6,18.65],[3.1,11.54],[2.44,8.42],[2.64,7.39],[2.84,13.18]],"id":37127725},{"spn":1.84,"spf":"NaN","id":37127725},{"atb":[[1.2,606.29],[1.25,485.03],[1.3,202.09]],"id":26051221},{"atl":[[2.54,7.87],[3.85,17.01],[2.74,6.96],[3.35,10.31],[2.94,12.5]],"id":26051221},{"spn":1.92,"spf":"NaN","id":26051221}],"con":true,"img":true}]}
{"op":"mcm","clk":"5352822087","pt":1646201802638,"mc":[{"id":"1.195453771","marketDefinition":{"bspMarket":true,"turnInPlayEnabled":false,"persistenceEnabled":false,"marketBaseRate":7.0,"eventId":"31272499","eventTypeId":"4339","numberOfWinners":3,"bettingType":"ODDS","marketType":"PLACE","marketTime":"2022-03-02T09:47:00.000Z","suspendTime":"2022-03-02T09:47:00.000Z","bspReconciled":false,"complete":true,"inPlay":false,"crossMatching":false,"runnersVoidable":false,"numberOfActiveRunners":8,"betDelay":0,"status":"OPEN","runners":[{"status":"ACTIVE","sortPriority":1,"id":36074638,"name":"1. Just Law"},{"status":"ACTIVE","sortPriority":2,"id":39784543,"name":"2. Surreal"},{"status":"ACTIVE","sortPriority":3,"id":36500377,"name":"3. Mystery Train"},{"status":"ACTIVE","sortPriority":4,"id":42189401,"name":"4. Daisy Cousins"},{"status":"ACTIVE","sortPriority":5,"id":35801684,"name":"5. Zeke The Freak"},{"status":"ACTIVE","sortPriority":6,"id":37127725,"name":"6. Exit Plan"},{"status":"ACTIVE","sortPriority":7,"id":26051221,"name":"7. Farmor Crownies"},{"status":"ACTIVE","sortPriority":8,"id":28338255,"name":"8. Until Late"}],"regulators":["MR_INT"],"venue":"Rockhampton","countryCode":"AU","discountAllowed":true,"timezone":"Australia/Queensland","openDate":"2022-03-02T08:28:00.000Z","version":4382602050,"name":"To Be Placed","eventName":"Rockhampton (AUS) 2nd Mar"},"rc":[{"atb":[[2.74,69.66],[2.84,65.87],[2.94,31.24]],"id":39784543},{"atl":[[8,1.73],[10,1.34],[20,1.27],[15,1.73],[30,1.67]],"id":39784543},{"spn":5.47,"spf":"NaN","id":39784543},{"atb":[[2.5,80.8],[2.6,75.75],[2.7,35.64]],"id":36500377},{"atl":[[16.5,1.56],[8.6,1.59],[11.5,2.3],[23,2.2],[6.6,2.16]],"id":36500377},{"spn":4.65,"spf":"NaN","id":36500377},{"atb":[[2.5,80.8],[2.6,75.75],[2.7,35.64]],"id":35801684},{"atl":[[16.5,1.56],[8.6,1.59],[11.5,2.3],[23,2.2],[6.6,2.16]],"id":35801684},{"spn":4.65,"spf":"NaN","id":35801684},{"atb":[[2.8,67.33],[2.9,31.89],[2.7,71.3]],"id":36074638},{"atl":[[19.5,1.31],[9.8,1.37],[7.8,1.77],[14.5,1.79],[29,1.73]],"id":36074638},{"spn":5.35,"spf":"NaN","id":36074638},{"atb":[[1.19,318.97],[1.14,865.79],[1.09,1346.8]],"id":42189401},{"atl":[[2.88,12.89],[3.2,22.03],[2.28,9.46],[2.68,14.43],[2.48,8.19]],"id":42189401},{"spn":1.73,"spf":"NaN","id":42189401},{"atb":[[1.6,202.02],[1.7,86.57],[1.65,186.48]],"id":28338255},{"atl":[[3.2,5.5],[3.7,4.48],[6.8,8.35],[4.4,7.13],[5.4,5.5]],"id":28338255},{"spn":2.45,"spf":"NaN","id":28338255},{"atb":[[1.2,606.06],[1.25,242.42],[1.15,808.08]],"id":37127725},{"atl":[[3.6,18.64],[3.1,11.54],[2.44,8.41],[2.64,7.39],[2.84,13.17]],"id":37127725},{"spn":1.84,"spf":"NaN","id":37127725},{"atb":[[1.2,606.06],[1.25,484.84],[1.3,202.02]],"id":26051221},{"atl":[[2.54,7.87],[3.85,17.01],[2.74,6.96],[3.35,10.31],[2.94,12.49]],"id":26051221},{"spn":1.92,"spf":"NaN","id":26051221}],"con":true,"img":true}]}
{"op":"mcm","clk":"5353027462","pt":1646207202675,"mc":[{"id":"1.195453771","marketDefinition":{"bspMarket":true,"turnInPlayEnabled":false,"persistenceEnabled":false,"marketBaseRate":7.0,"eventId":"31272499","eventTypeId":"4339","numberOfWinners":3,"bettingType":"ODDS","marketType":"PLACE","marketTime":"2022-03-02T09:47:00.000Z","suspendTime":"2022-03-02T09:47:00.000Z","bspReconciled":false,"complete":true,"inPlay":false,"crossMatching":false,"runnersVoidable":false,"numberOfActiveRunners":8,"betDelay":0,"status":"OPEN","runners":[{"status":"ACTIVE","sortPriority":1,"id":36074638,"name":"1. Just Law"},{"status":"ACTIVE","sortPriority":2,"id":39784543,"name":"2. Surreal"},{"status":"ACTIVE","sortPriority":3,"id":36500377,"name":"3. Mystery Train"},{"status":"ACTIVE","sortPriority":4,"id":42189401,"name":"4. Daisy Cousins"},{"status":"ACTIVE","sortPriority":5,"id":35801684,"name":"5. Zeke The Freak"},{"status":"ACTIVE","sortPriority":6,"id":37127725,"name":"6. Exit Plan"},{"status":"ACTIVE","sortPriority":7,"id":26051221,"name":"7. Farmor Crownies"},{"status":"ACTIVE","sortPriority":8,"id":28338255,"name":"8. Until Late"}],"regulators":["MR_INT"],"venue":"Rockhampton","countryCode":"AU","discountAllowed":true,"timezone":"Australia/Queensland","openDate":"2022-03-02T08:28:00.000Z","version":4382602050,"name":"To Be Placed","eventName":"Rockhampton (AUS) 2nd Mar"},"rc":[{"atb":[[2.74,69.64],[2.84,65.85],[2.94,31.23]],"id":39784543},{"atl":[[8,1.73],[10,1.34],[20,1.27],[15,1.73],[30,1.67]],"id":39784543},{"spn":5.47,"spf":"NaN","id":39784543},{"atb":[[2.5,80.78],[2.6,75.73],[2.7,35.63]],"id":36500377},{"atl":[[16.5,1.56],[8.6,1.59],[11.5,2.3],[23,2.2],[6.6,2.16]],"id":36500377},{"spn":4.65,"spf":"NaN","id":36500377},{"atb":[[2.5,80.78],[2.6,75.73],[2.7,35.63]],"id":35801684},{"atl":[[16.5,1.56],[8.6,1.59],[11.5,2.3],[23,2.2],[6.6,2.16]],"id":35801684},{"spn":4.65,"spf":"NaN","id":35801684},{"atb":[[2.8,67.31],[2.9,31.88],[2.7,71.28]],"id":36074638},{"atl":[[19.5,1.31],[9.8,1.37],[7.8,1.77],[14.5,1.79],[29,1.73]],"id":36074638},{"spn":5.35,"spf":"NaN","id":36074638},{"atb":[[1.19,318.89],[1.14,865.56],[1.09,1346.43]],"id":42189401},{"atl":[[2.88,12.89],[3.2,22.03],[2.28,9.46],[2.68,14.42],[2.48,8.18]],"id":42189401},{"spn":1.73,"spf":"NaN","id":42189401},{"atb":[[1.6,201.96],[1.7,86.55],[1.65,186.43]],"id":28338255},{"atl":[[3.2,5.5],[3.7,4.48],[6.8,8.35],[4.4,7.12],[5.4,5.5]],"id":28338255},{"spn":2.45,"spf":"NaN","id":28338255},{"atb":[[1.2,605.89],[1.25,242.35],[1.15,807.86]],"id":37127725},{"atl":[[3.6,18.64],[3.1,11.53],[2.44,8.41],[2.64,7.39],[2.84,13.17]],"id":37127725},{"spn":1.84,"spf":"NaN","id":37127725},{"atb":[[1.2,605.89],[1.25,484.71],[1.3,201.96]],"id":26051221},{"atl":[[2.54,7.87],[3.85,17],[2.74,6.96],[3.35,10.31],[2.94,12.49]],"id":26051221},{"spn":1.92,"spf":"NaN","id":26051221}],"con":true,"img":true}]}
{"op":"mcm","clk":"5353112201","pt":1646209104643,"mc":[{"id":"1.195453771","rc":[{"atb":[[3.2,19.84],[2.74,69.64],[2.86,22.37],[2.84,65.85],[2.94,31.23]],"id":39784543},{"atl":[[8,1.73],[16,2.72],[10,1.34],[20,1.27],[14.5,3.23],[15,1.73],[30,1.67]],"id":39784543},{"spn":5.6,"spf":"NaN","id":39784543},{"atb":[[2.5,80.78],[2.6,75.73],[2.84,23.73],[2.62,26.74],[2.7,35.63]],"id":36500377},{"atl":[[16.5,1.56],[8.6,1.59],[11.5,2.3],[23,2.2],[12,3.96],[13.5,3.27],[6.6,2.16]],"id":36500377},{"spn":4.72,"spf":"NaN","id":36500377},{"atb":[[2.5,80.78],[2.6,75.73],[2.84,23.73],[2.62,26.74],[2.7,35.63]],"id":35801684},{"atl":[[16.5,1.56],[8.6,1.59],[11.5,2.3],[23,2.2],[12,3.96],[13.5,3.27],[6.6,2.16]],"id":35801684},{"spn":4.72,"spf":"NaN","id":35801684},{"atb":[[2.8,67.31],[2.82,21.24],[2.9,31.88],[3,21.83],[2.7,71.28]],"id":36074638},{"atl":[[19.5,1.31],[9.8,1.37],[13.5,3.49],[7.8,1.77],[14.5,1.79],[29,1.73],[15,2.76]],"id":36074638},{"spn":5.4,"spf":"NaN","id":36074638},{"atb":[[1.2,202.87],[1.19,318.89],[1.14,865.56],[1.09,1346.43],[1.22,92.57]],"id":42189401},{"atl":[[2.88,12.89],[3.2,22.03],[2.32,33.08],[2.28,9.46],[2.46,27.78],[2.68,14.42],[2.48,8.18]],"id":42189401},{"spn":1.75,"spf":"NaN","id":42189401},{"atb":[[1.6,201.96],[1.7,86.55],[1.65,186.43],[1.93,46.95],[1.75,54.46]],"id":28338255},{"atl":[[3.2,5.5],[6.4,7.8],[3.7,4.48],[6.8,8.35],[4.4,7.12],[6.6,7.29],[5.4,5.5]],"id":28338255},{"spn":2.56,"spf":"NaN","id":28338255},{"atb":[[1.2,605.89],[1.25,242.35],[1.15,807.86],[1.26,164.3],[1.29,87.54]],"id":37127725},{"atl":[[2.82,23.47],[3.6,18.64],[3.1,11.53],[2.44,8.41],[2.64,7.39],[2.84,13.17],[2.62,23.99]],"id":37127725},{"spn":1.86,"spf":"NaN","id":37127725},{"atb":[[1.2,605.89],[1.25,484.71],[1.3,201.96],[1.31,257.45]],"id":26051221},{"atl":[[2.92,20.7],[2.54,7.87],[3.85,17],[2.74,6.96],[3.35,10.31],[2.78,24.53],[2.94,12.49]],"id":26051221},{"spn":1.92,"spf":"NaN","id":26051221}],"con":true,"img":false}]}
{"op":"mcm","clk":"5353113891","pt":1646209144867,"mc":[{"id":"1.195453771","rc":[{"atl":[[4.3,13.23],[6.4,0]],"id":28338255}],"con":true,"img":false}]}
{"op":"mcm","clk":"5353200755","pt":1646210821555,"mc":[{"id":"1.195453771","rc":[{"atb":[[2.68,59.52]],"id":39784543},{"atl":[[14,3.08]],"id":39784543},{"atb":[[1.71,71.28]],"id":36500377},{"atl":[[6.6,4.32]],"id":36500377},{"atb":[[2.56,64.1]],"id":35801684},{"atl":[[50,2.04]],"id":35801684},{"atb":[[2.06,63.78]],"id":36074638},{"atl":[[7.8,3.77]],"id":36074638},{"atl":[[2.58,37.26]],"id":42189401},{"atb":[[1.94,54.47]],"id":28338255},{"atl":[[6,11.02]],"id":28338255},{"spn":2.57,"spf":"NaN","id":28338255},{"atl":[[3.6,22.8]],"id":26051221},{"atb":[[1.3,164.3]],"id":37127725},{"atl":[[2.92,26.34]],"id":37127725},{"spn":1.87,"spf":"NaN","id":37127725}],"con":true,"img":false}]}
{"op":"mcm","clk":"5353200965","pt":1646210825977,"mc":[{"id":"1.195453771","rc":[{"atl":[[4.3,0],[5.9,8.91]],"id":28338255}],"con":true,"img":false}]}
{"op":"mcm","clk":"5353201419","pt":1646210836071,"mc":[{"id":"1.195453771","rc":[{"atl":[[2.46,0]],"id":42189401}],"con":true,"img":false}]}
{"op":"mcm","clk":"5353201425","pt":1646210836174,"mc":[{"id":"1.195453771","rc":[{"atl":[[2.56,27.78]],"id":42189401}],"con":true,"img":false}]}
{"op":"mcm","clk":"5353202532","pt":1646210858714,"mc":[{"id":"1.195453771","rc":[{"atb":[[2.84,120.2],[2.68,0]],"id":39784543},{"atb":[[2.56,0],[2.72,47.46]],"id":35801684},{"atb":[[2.06,0],[2.2,63.78]],"id":36074638},{"atl":[[2.4,42.55],[2.58,0]],"id":42189401},{"atl":[[2.92,0],[2.74,23.47]],"id":37127725}],"con":true,"img":false}]}
{"op":"mcm","clk":"5353202721","pt":1646210862328,"mc":[{"id":"1.195453771","rc":[{"atl":[[14.5,0]],"id":39784543},{"atb":[[1.29,0]],"id":37127725},{"atb":[[1.93,0]],"id":28338255}],"con":true,"img":false}]}
{"op":"mcm","clk":"5353202726","pt":1646210862430,"mc":[{"id":"1.195453771","rc":[{"atl":[[13.5,3.23]],"id":39784543},{"atb":[[1.95,46.95]],"id":28338255},{"atb":[[1.31,87.54]],"id":37127725}],"con":true,"img":false}]}
{"op":"mcm","clk":"5353202736","pt":1646210862533,"mc":[{"id":"1.195453771","rc":[{"atb":[[1.94,0],[1.76,108.94]],"id":28338255},{"atb":[[1.27,328.6],[1.3,0]],"id":37127725}],"con":true,"img":false}]}
{"op":"mcm","clk":"5353203652","pt":1646210881742,"mc":[{"id":"1.195453771","rc":[{"spn":2.57,"spf":"NaN","id":28338255},{"atb":[[1.31,0]],"id":37127725},{"spn":1.85,"spf":"NaN","id":37127725}],"con":true,"img":false}]}
{"op":"mcm","clk":"5353203659","pt":1646210881845,"mc":[{"id":"1.195453771","rc":[{"atb":[[1.28,87.54]],"id":37127725}],"con":true,"img":false}]}
{"op":"mcm","clk":"5353203729","pt":1646210883294,"mc":[{"id":"1.195453771","rc":[{"atb":[[2.72,0],[2.66,60.24]],"id":35801684},{"atl":[[2.4,0],[2.46,66.16]],"id":42189401}],"con":true,"img":false}]}
{"op":"mcm","clk":"5353204433","pt":1646210899215,"mc":[{"id":"1.195453771","rc":[{"atb":[[1.27,0],[1.29,164.3]],"id":37127725},{"atb":[[1.96,54.47],[1.76,0]],"id":28338255}],"con":true,"img":false}]}
{"op":"mcm","clk":"5353204764","pt":1646210906744,"mc":[{"id":"1.195453771","rc":[{"atb":[[2.62,0]],"id":35801684},{"atl":[[2.56,0]],"id":42189401},{"atl":[[2.82,0]],"id":37127725}],"con":true,"img":false}]}
{"op":"mcm","clk":"5353204769","pt":1646210906902,"mc":[{"id":"1.195453771","rc":[{"atb":[[2.68,26.74]],"id":35801684},{"atl":[[2.44,27.78]],"id":42189401},{"atl":[[2.72,23.47]],"id":37127725}],"con":true,"img":false}]}
{"op":"mcm","clk":"5353205083","pt":1646210913355,"mc":[{"id":"1.195453771","rc":[{"atl":[[2.92,0]],"id":26051221}],"con":true,"img":false}]}
{"op":"mcm","clk":"5353205087","pt":1646210913458,"mc":[{"id":"1.195453771","rc":[{"atl":[[3.2,20.7]],"id":26051221}],"con":true,"img":false}]}
{"op":"mcm","clk":"5353205340","pt":1646210919847,"mc":[{"id":"1.195453771","rc":[{"atb":[[2.72,47.46],[2.66,0]],"id":35801684}],"con":true,"img":false}]}
{"op":"mcm","clk":"5353205931","pt":1646210935721,"mc":[{"id":"1.195453771","rc":[{"atb":[[1.22,0]],"id":42189401},{"atb":[[1.28,0]],"id":37127725},{"atb":[[1.95,0]],"id":28338255}],"con":true,"img":false}]}
{"op":"mcm","clk":"5353205936","pt":1646210935773,"mc":[{"id":"1.195453771","rc":[{"atb":[[1.23,92.57]],"id":42189401},{"atb":[[1.3,87.54]],"id":37127725},{"atb":[[1.97,46.95]],"id":28338255}],"con":true,"img":false}]}
{"op":"mcm","clk":"5353205940","pt":1646210935875,"mc":[{"id":"1.195453771","rc":[{"atb":[[1.27,328.6],[1.29,0]],"id":37127725},{"atb":[[1.96,0],[1.76,108.94]],"id":28338255}],"con":true,"img":false}]}
{"op":"mcm","clk":"5353206375","pt":1646210949117,"mc":[{"id":"1.195453771","rc":[{"spn":1.75,"spf":"NaN","id":42189401},{"spn":2.58,"spf":"NaN","id":28338255},{"atb":[[1.3,0]],"id":37127725}],"con":true,"img":false}]}
{"op":"mcm","clk":"5353206377","pt":1646210949219,"mc":[{"id":"1.195453771","rc":[{"atb":[[1.28,87.54]],"id":37127725}],"con":true,"img":false}]}
{"op":"mcm","clk":"5353207125","pt":1646210971830,"mc":[{"id":"1.195453771","rc":[{"atb":[[1.29,164.3]],"id":37127725},{"atb":[[1.98,54.47]],"id":28338255},{"atl":[[3.2,0]],"id":26051221}],"con":true,"img":false}]}
{"op":"mcm","clk":"5353207130","pt":1646210971932,"mc":[{"id":"1.195453771","rc":[{"atl":[[2.92,20.7]],"id":26051221},{"atb":[[1.27,0]],"id":37127725},{"atb":[[1.76,0]],"id":28338255}],"con":true,"img":false}]}
{"op":"mcm","clk":"5353207502","pt":1646210982176,"mc":[{"id":"1.195453771","rc":[{"atb":[[2.68,0]],"id":35801684}],"con":true,"img":false}]}
{"op":"mcm","clk":"5353207506","pt":1646210982279,"mc":[{"id":"1.195453771","rc":[{"atb":[[2.74,26.74]],"id":35801684}],"con":true,"img":false}]}
{"op":"mcm","clk":"5353208237","pt":1646211003108,"mc":[{"id":"1.195453771","rc":[{"atb":[[2.84,65.85],[2.68,59.52]],"id":39784543},{"atb":[[2.56,64.1],[2.72,0]],"id":35801684},{"atb":[[2.06,94.34],[2.2,0]],"id":36074638},{"atl":[[2.46,0],[2.58,55.58]],"id":42189401},{"atl":[[2.92,36.64],[2.74,0]],"id":37127725}],"con":true,"img":false}]}
{"op":"mcm","clk":"5353208556","pt":1646211011827,"mc":[{"id":"1.195453771","rc":[{"atb":[[2.74,0]],"id":35801684},{"atl":[[2.44,0]],"id":42189401},{"atb":[[1.28,0]],"id":37127725},{"atl":[[2.72,0]],"id":37127725},{"spn":1.86,"spf":"NaN","id":37127725},{"atb":[[1.97,0]],"id":28338255},{"spn":2.59,"spf":"NaN","id":28338255}],"con":true,"img":false}]}
{"op":"mcm","clk":"5353208564","pt":1646211011930,"mc":[{"id":"1.195453771","rc":[{"atb":[[2.62,26.74]],"id":35801684},{"atl":[[2.56,27.78]],"id":42189401},{"atb":[[1.3,87.54]],"id":37127725},{"atl":[[2.82,23.47]],"id":37127725},{"atb":[[1.99,46.95]],"id":28338255}],"con":true,"img":false}]}
{"op":"mcm","clk":"5353208569","pt":1646211012033,"mc":[{"id":"1.195453771","rc":[{"atb":[[1.27,328.6],[1.29,0]],"id":37127725},{"atb":[[1.98,0],[1.76,108.94]],"id":28338255}],"con":true,"img":false}]}
{"op":"mcm","clk":"5353209862","pt":1646211047265,"mc":[{"id":"1.195453771","rc":[{"atb":[[2,54.47],[1.76,0]],"id":28338255},{"atb":[[1.27,0],[1.31,164.3]],"id":37127725}],"con":true,"img":false}]}
{"op":"mcm","clk":"5353211595","pt":1646211088920,"mc":[{"id":"1.195453771","rc":[{"atb":[[1.3,0]],"id":37127725},{"spn":1.87,"spf":"NaN","id":37127725},{"atb":[[1.99,0]],"id":28338255},{"spn":2.6,"spf":"NaN","id":28338255}],"con":true,"img":false}]}
{"op":"mcm","clk":"5353211599","pt":1646211089023,"mc":[{"id":"1.195453771","rc":[{"atb":[[2,0],[2.02,46.95],[1.76,108.94]],"id":28338255},{"atb":[[1.27,328.6],[1.32,87.54],[1.31,0]],"id":37127725}],"con":true,"img":false}]}
{"op":"mcm","clk":"5353212387","pt":1646211110753,"mc":[{"id":"1.195453771","rc":[{"atb":[[1.32,0]],"id":37127725}],"con":true,"img":false}]}
{"op":"mcm","clk":"5353212392","pt":1646211110856,"mc":[{"id":"1.195453771","rc":[{"atb":[[1.28,87.54]],"id":37127725}],"con":true,"img":false}]}
{"op":"mcm","clk":"5353212834","pt":1646211123474,"mc":[{"id":"1.195453771","rc":[{"atb":[[1.29,164.3]],"id":37127725},{"atb":[[2,93.9]],"id":28338255}],"con":true,"img":false}]}
{"op":"mcm","clk":"5353212835","pt":1646211123576,"mc":[{"id":"1.195453771","rc":[{"atb":[[1.27,0]],"id":37127725},{"atb":[[1.76,0]],"id":28338255}],"con":true,"img":false}]}
{"op":"mcm","clk":"5353214296","pt":1646211163929,"mc":[{"id":"1.195453771","rc":[{"atb":[[1.28,0]],"id":37127725},{"spn":1.86,"spf":"NaN","id":37127725},{"spn":2.61,"spf":"NaN","id":28338255}],"con":true,"img":false}]}
{"op":"mcm","clk":"5353214299","pt":1646211164031,"mc":[{"id":"1.195453771","rc":[{"atb":[[1.27,328.6],[1.3,87.54],[1.29,0]],"id":37127725}],"con":true,"img":false}]}
{"op":"mcm","clk":"5353214302","pt":1646211164134,"mc":[{"id":"1.195453771","rc":[{"atb":[[1.27,0],[1.31,164.3]],"id":37127725}],"con":true,"img":false}]}
{"op":"mcm","clk":"5353216183","pt":1646211210824,"mc":[{"id":"1.195453771","rc":[{"atb":[[1.3,0]],"id":37127725}],"con":true,"img":false}]}
{"op":"mcm","clk":"5353216188","pt":1646211210925,"mc":[{"id":"1.195453771","rc":[{"atb":[[1.27,328.6],[1.32,87.54],[1.31,0]],"id":37127725}],"con":true,"img":false}]}
{"op":"mcm","clk":"5353216736","pt":1646211222665,"mc":[{"id":"1.195453771","rc":[{"atb":[[1.32,0]],"id":37127725}],"con":true,"img":false}]}
{"op":"mcm","clk":"5353216740","pt":1646211222763,"mc":[{"id":"1.195453771","rc":[{"atb":[[1.28,87.54]],"id":37127725}],"con":true,"img":false}]}
{"op":"mcm","clk":"5353217585","pt":1646211244217,"mc":[{"id":"1.195453771","rc":[{"atb":[[1.27,0],[1.29,164.3]],"id":37127725}],"con":true,"img":false}]}
{"op":"mcm","clk":"5353219162","pt":1646211281639,"mc":[{"id":"1.195453771","rc":[{"atb":[[1.28,0]],"id":37127725}],"con":true,"img":false}]}
{"op":"mcm","clk":"5353219169","pt":1646211281741,"mc":[{"id":"1.195453771","rc":[{"atb":[[1.27,328.6],[1.3,87.54],[1.29,0]],"id":37127725}],"con":true,"img":false}]}
{"op":"mcm","clk":"5353220546","pt":1646211314296,"mc":[{"id":"1.195453771","rc":[{"atb":[[1.31,164.3]],"id":37127725},{"spn":1.87,"spf":"NaN","id":37127725}],"con":true,"img":false}]}
{"op":"mcm","clk":"5353220551","pt":1646211314401,"mc":[{"id":"1.195453771","rc":[{"atb":[[1.27,0]],"id":37127725}],"con":true,"img":false}]}
{"op":"mcm","clk":"5353222659","pt":1646211361571,"mc":[{"id":"1.195453771","rc":[{"atb":[[1.3,0]],"id":37127725}],"con":true,"img":false}]}
{"op":"mcm","clk":"5353222662","pt":1646211361672,"mc":[{"id":"1.195453771","rc":[{"atb":[[1.27,328.6],[1.32,87.54],[1.31,0]],"id":37127725}],"con":true,"img":false}]}
{"op":"mcm","clk":"5353223659","pt":1646211384444,"mc":[{"id":"1.195453771","rc":[{"atb":[[1.32,0]],"id":37127725},{"spn":1.85,"spf":"NaN","id":37127725}],"con":true,"img":false}]}
{"op":"mcm","clk":"5353223668","pt":1646211384548,"mc":[{"id":"1.195453771","rc":[{"atb":[[1.28,87.54]],"id":37127725}],"con":true,"img":false}]}
{"op":"mcm","clk":"5353224089","pt":1646211393423,"mc":[{"id":"1.195453771","rc":[{"atb":[[1.27,0],[1.29,164.3]],"id":37127725}],"con":true,"img":false}]}
{"op":"mcm","clk":"5353224186","pt":1646211395231,"mc":[{"id":"1.195453771","rc":[{"atb":[[2.82,54.95],[2.68,0]],"id":39784543},{"atb":[[2.56,0],[2.86,26.75]],"id":35801684},{"atb":[[2,0],[2.04,54.47]],"id":28338255}],"con":true,"img":false}]}
{"op":"mcm","clk":"5353226190","pt":1646211438195,"mc":[{"id":"1.195453771","rc":[{"atb":[[2.02,0]],"id":28338255},{"atb":[[1.28,0]],"id":37127725}],"con":true,"img":false}]}
{"op":"mcm","clk":"5353226196","pt":1646211438297,"mc":[{"id":"1.195453771","rc":[{"atb":[[2.06,46.95],[2.04,0],[1.76,108.94]],"id":28338255},{"atb":[[1.27,328.6],[1.3,87.54],[1.29,0]],"id":37127725}],"con":true,"img":false}]}
{"op":"mcm","clk":"5353226202","pt":1646211438501,"mc":[{"id":"1.195453771","rc":[{"atb":[[2.06,101.42],[1.76,0]],"id":28338255}],"con":true,"img":false}]}
{"op":"mcm","clk":"5353226208","pt":1646211438605,"mc":[{"id":"1.195453771","rc":[{"atb":[[2.06,46.95],[1.76,93.9]],"id":28338255}],"con":true,"img":false}]}
{"op":"mcm","clk":"5353226212","pt":1646211438710,"mc":[{"id":"1.195453771","rc":[{"atb":[[2.06,133.51],[1.76,0]],"id":28338255}],"con":true,"img":false}]}
{"op":"mcm","clk":"5353226215","pt":1646211438813,"mc":[{"id":"1.195453771","rc":[{"atb":[[2.06,46.95],[1.76,93.9]],"id":28338255}],"con":true,"img":false}]}
{"op":"mcm","clk":"5353226629","pt":1646211448503,"mc":[{"id":"1.195453771","rc":[{"spn":4.73,"spf":"NaN","id":35801684},{"atb":[[2.06,0]],"id":28338255},{"spn":2.48,"spf":"NaN","id":28338255},{"spn":1.87,"spf":"NaN","id":37127725}],"con":true,"img":false}]}
{"op":"mcm","clk":"5353226637","pt":1646211448607,"mc":[{"id":"1.195453771","rc":[{"atb":[[1.92,46.95]],"id":28338255}],"con":true,"img":false}]}
{"op":"mcm","clk":"5353227587","pt":1646211469241,"mc":[{"id":"1.195453771","rc":[{"atb":[[1.31,164.3]],"id":37127725}],"con":true,"img":false}]}
{"op":"mcm","clk":"5353227592","pt":1646211469346,"mc":[{"id":"1.195453771","rc":[{"atb":[[1.27,0]],"id":37127725}],"con":true,"img":false}]}
{"op":"mcm","clk":"5353227607","pt":1646211469757,"mc":[{"id":"1.195453771","rc":[{"atb":[[1.93,54.47],[1.76,0]],"id":28338255}],"con":true,"img":false}]}
{"op":"mcm","clk":"5353229654","pt":1646211512561,"mc":[{"id":"1.195453771","rc":[{"atb":[[1.92,0]],"id":28338255},{"spn":2.56,"spf":"NaN","id":28338255},{"atb":[[1.3,0]],"id":37127725},{"spn":1.87,"spf":"NaN","id":37127725}],"con":true,"img":false}]}
{"op":"mcm","clk":"5353229658","pt":1646211512620,"mc":[{"id":"1.195453771","rc":[{"atb":[[1.94,46.95]],"id":28338255},{"atb":[[1.32,87.54]],"id":37127725}],"con":true,"img":false}]}
{"op":"mcm","clk":"5353229664","pt":1646211512719,"mc":[{"id":"1.195453771","rc":[{"atb":[[1.93,0],[1.76,108.94]],"id":28338255},{"atb":[[1.27,328.6],[1.31,0]],"id":37127725}],"con":true,"img":false}]}
{"op":"mcm","clk":"5353230216","pt":1646211523367,"mc":[{"id":"1.195453771","rc":[{"atb":[[1.32,0]],"id":37127725}],"con":true,"img":false}]}
{"op":"mcm","clk":"5353230221","pt":1646211523469,"mc":[{"id":"1.195453771","rc":[{"atb":[[1.28,87.54]],"id":37127725}],"con":true,"img":false}]}
{"op":"mcm","clk":"5353231253","pt":1646211542971,"mc":[{"id":"1.195453771","rc":[{"atb":[[1.27,0],[1.29,164.3]],"id":37127725},{"atb":[[1.95,54.47],[1.76,0]],"id":28338255}],"con":true,"img":false}]}
{"op":"mcm","clk":"5353233624","pt":1646211588364,"mc":[{"id":"1.195453771","rc":[{"atb":[[1.94,0]],"id":28338255},{"spn":2.57,"spf":"NaN","id":28338255},{"atb":[[1.28,0]],"id":37127725},{"spn":1.86,"spf":"NaN","id":37127725}],"con":true,"img":false}]}
{"op":"mcm","clk":"5353233631","pt":1646211588467,"mc":[{"id":"1.195453771","rc":[{"atb":[[1.27,328.6],[1.3,87.54],[1.29,0]],"id":37127725},{"atb":[[1.96,46.95],[1.95,0],[1.76,108.94]],"id":28338255}],"con":true,"img":false}]}
{"op":"mcm","clk":"5353235624","pt":1646211617936,"mc":[{"id":"1.195453771","rc":[{"atb":[[3.2,19.81],[2.86,22.34],[2.74,69.53],[2.84,65.75],[2.94,31.18]],"id":39784543},{"atl":[[8,1.72],[16,2.72],[10,1.34],[20,1.27],[13.5,3.23],[15,1.72],[30,1.66]],"id":39784543},{"atb":[[2.5,80.65],[2.6,75.61],[2.84,23.69],[2.62,26.7],[2.7,35.58]],"id":36500377},{"atl":[[16.5,1.55],[8.6,1.59],[11.5,2.3],[23,2.2],[12,3.96],[13.5,3.26],[6.6,4.31]],"id":36500377},{"atb":[[2.5,80.65],[2.6,75.61],[2.84,23.69],[2.62,26.7],[2.7,35.58]],"id":35801684},{"atl":[[16.5,1.55],[8.6,1.59],[11.5,2.3],[23,2.2],[12,3.96],[13.5,3.26],[6.6,2.15]],"id":35801684},{"atb":[[2.82,21.21],[2.8,67.21],[2.9,31.83],[3,21.79],[2.7,71.17]],"id":36074638},{"atl":[[19.5,1.3],[9.8,1.37],[13.5,3.48],[7.8,3.77],[14.5,1.79],[29,1.72],[15,2.75]],"id":36074638},{"atb":[[1.2,202.55],[1.19,318.38],[1.23,92.42],[1.14,864.19],[1.09,1344.3]],"id":42189401},{"atl":[[2.56,27.74],[2.88,12.87],[3.2,21.99],[2.32,33.03],[2.28,9.45],[2.68,14.4],[2.48,8.17]],"id":42189401},{"atb":[[1.2,604.93],[1.27,0],[1.25,241.97],[1.15,806.58],[1.26,164.04],[1.3,87.4],[1.31,164.3]],"id":37127725},{"atl":[[2.82,23.43],[3.6,18.61],[3.1,11.52],[2.44,8.4],[2.64,7.37],[2.84,13.15],[2.62,23.95]],"id":37127725},{"atb":[[1.6,201.64],[1.97,54.47],[1.7,86.41],[1.96,46.87],[1.75,54.37],[1.65,186.13],[1.76,0]],"id":28338255},{"atl":[[3.2,5.49],[3.7,4.47],[6.8,8.34],[4.4,7.11],[6.6,7.28],[5.9,8.89],[5.4,5.49]],"id":28338255},{"atb":[[1.2,604.93],[1.25,483.95],[1.3,201.64],[1.31,257.04]],"id":26051221},{"atl":[[2.92,20.67],[2.54,7.85],[3.85,16.98],[2.74,6.95],[3.35,10.29],[2.78,24.49],[2.94,12.47]],"id":26051221}],"con":true,"img":false}]}
{"op":"mcm","clk":"5353237987","pt":1646211658067,"mc":[{"id":"1.195453771","rc":[{"atb":[[1.96,0]],"id":28338255},{"spn":2.58,"spf":"NaN","id":28338255},{"atb":[[1.3,0]],"id":37127725},{"spn":1.87,"spf":"NaN","id":37127725}],"con":true,"img":false}]}
{"op":"mcm","clk":"5353237993","pt":1646211658172,"mc":[{"id":"1.195453771","rc":[{"atb":[[1.98,46.87],[1.76,108.94]],"id":28338255},{"atb":[[1.27,328.6],[1.32,87.4],[1.31,0]],"id":37127725}],"con":true,"img":false}]}
{"op":"mcm","clk":"5353237999","pt":1646211658274,"mc":[{"id":"1.195453771","rc":[{"atb":[[1.27,0],[1.31,241.98]],"id":37127725},{"atb":[[1.99,54.47],[1.97,0]],"id":28338255}],"con":true,"img":false}]}
{"op":"mcm","clk":"5353238005","pt":1646211658377,"mc":[{"id":"1.195453771","rc":[{"atb":[[1.76,0]],"id":28338255}],"con":true,"img":false}]}
{"op":"mcm","clk":"5353240375","pt":1646211700150,"mc":[{"id":"1.195453771","rc":[{"atb":[[1.98,0]],"id":28338255}],"con":true,"img":false}]}
{"op":"mcm","clk":"5353240380","pt":1646211700253,"mc":[{"id":"1.195453771","rc":[{"atb":[[2,46.87],[1.99,0],[1.76,108.94]],"id":28338255}],"con":true,"img":false}]}
{"op":"mcm","clk":"5353242135","pt":1646211728608,"mc":[{"id":"1.195453771","rc":[{"atb":[[2.02,54.38],[1.76,0]],"id":28338255},{"spn":2.61,"spf":"NaN","id":28338255},{"spn":1.88,"spf":"NaN","id":37127725}],"con":true,"img":false}]}
{"op":"mcm","clk":"5353242469","pt":1646211733597,"mc":[{"id":"1.195453771","rc":[{"atb":[[3.25,1.66]],"id":39784543},{"atb":[[2.86,1.66]],"id":36500377},{"atb":[[2.88,1.66]],"id":35801684},{"atb":[[3.05,1.66]],"id":36074638},{"atb":[[2.04,1.66]],"id":28338255}],"con":true,"img":false}]}
{"op":"mcm","clk":"5353243431","pt":1646211750214,"mc":[{"id":"1.195453771","marketDefinition":{"bspMarket":true,"turnInPlayEnabled":false,"persistenceEnabled":false,"marketBaseRate":7.0,"eventId":"31272499","eventTypeId":"4339","numberOfWinners":3,"bettingType":"ODDS","marketType":"PLACE","marketTime":"2022-03-02T09:47:00.000Z","suspendTime":"2022-03-02T09:47:00.000Z","bspReconciled":false,"complete":true,"inPlay":false,"crossMatching":true,"runnersVoidable":false,"numberOfActiveRunners":8,"betDelay":0,"status":"OPEN","runners":[{"status":"ACTIVE","sortPriority":1,"id":36074638,"name":"1. Just Law"},{"status":"ACTIVE","sortPriority":2,"id":39784543,"name":"2. Surreal"},{"status":"ACTIVE","sortPriority":3,"id":36500377,"name":"3. Mystery Train"},{"status":"ACTIVE","sortPriority":4,"id":42189401,"name":"4. Daisy Cousins"},{"status":"ACTIVE","sortPriority":5,"id":35801684,"name":"5. Zeke The Freak"},{"status":"ACTIVE","sortPriority":6,"id":37127725,"name":"6. Exit Plan"},{"status":"ACTIVE","sortPriority":7,"id":26051221,"name":"7. Farmor Crownies"},{"status":"ACTIVE","sortPriority":8,"id":28338255,"name":"8. Until Late"}],"regulators":["MR_INT"],"venue":"Rockhampton","countryCode":"AU","discountAllowed":true,"timezone":"Australia/Queensland","openDate":"2022-03-02T08:28:00.000Z","version":4382602050,"name":"To Be Placed","eventName":"Rockhampton (AUS) 2nd Mar"},"rc":[],"con":true,"img":false}]}
{"op":"mcm","clk":"5353244148","pt":1646211763341,"mc":[{"id":"1.195453771","rc":[{"atb":[[2,0]],"id":28338255}],"con":true,"img":false}]}
{"op":"mcm","clk":"5353244154","pt":1646211763441,"mc":[{"id":"1.195453771","rc":[{"atb":[[2.04,48.54]],"id":28338255}],"con":true,"img":false}]}
{"op":"mcm","clk":"5353244159","pt":1646211763547,"mc":[{"id":"1.195453771","rc":[{"atb":[[2.02,0],[2.06,54.38]],"id":28338255}],"con":true,"img":false}]}
{"op":"mcm","clk":"5353244485","pt":1646211768558,"mc":[{"id":"1.195453771","rc":[{"atb":[[2.04,46.87]],"id":28338255}],"con":true,"img":false}]}
{"op":"mcm","clk":"5353244500","pt":1646211768762,"mc":[{"id":"1.195453771","rc":[{"atb":[[2.08,1.66]],"id":28338255}],"con":true,"img":false}]}
{"op":"mcm","clk":"5353244746","pt":1646211772381,"mc":[{"id":"1.195453771","rc":[{"atb":[[2.84,0]],"id":35801684}],"con":true,"img":false}]}
{"op":"mcm","clk":"5353244752","pt":1646211772484,"mc":[{"id":"1.195453771","rc":[{"atb":[[2.88,25.36]],"id":35801684}],"con":true,"img":false}]}
{"op":"mcm","clk":"5353245012","pt":1646211776676,"mc":[{"id":"1.195453771","rc":[{"atb":[[3,3.75]],"id":39784543},{"atb":[[2.76,4.27]],"id":36500377},{"atb":[[2.96,3.83]],"id":36074638},{"atb":[[2.1,6.83]],"id":28338255}],"con":true,"img":false}]}
{"op":"mcm","clk":"5353245195","pt":1646211779778,"mc":[{"id":"1.195453771","rc":[{"atb":[[2.94,3.87]],"id":35801684}],"con":true,"img":false}]}
{"op":"mcm","clk":"5353245386","pt":1646211782514,"mc":[{"id":"1.195453771","rc":[{"atb":[[2.88,23.69]],"id":35801684},{"atb":[[2.08,0]],"id":28338255}],"con":true,"img":false}]}
{"op":"mcm","clk":"5353245404","pt":1646211782683,"mc":[{"id":"1.195453771","rc":[{"atb":[[2.96,1.66]],"id":35801684},{"atb":[[2.12,1.66]],"id":28338255}],"con":true,"img":false}]}
{"op":"mcm","clk":"5353245431","pt":1646211783086,"mc":[{"id":"1.195453771","rc":[{"atb":[[2.94,0]],"id":35801684}],"con":true,"img":false}]}
{"op":"mcm","clk":"5353245751","pt":1646211788883,"mc":[{"id":"1.195453771","rc":[{"spn":5.62,"spf":"NaN","id":39784543},{"spn":4.73,"spf":"NaN","id":36500377},{"atb":[[2.92,3.91]],"id":35801684},{"spn":4.78,"spf":"NaN","id":35801684},{"spn":5.42,"spf":"NaN","id":36074638},{"spn":2.66,"spf":"NaN","id":28338255}],"con":true,"img":false}]}
{"op":"mcm","clk":"5353245799","pt":1646211789507,"mc":[{"id":"1.195453771","rc":[{"atb":[[2.96,0]],"id":35801684}],"con":true,"img":false}]}
{"op":"mcm","clk":"5353245806","pt":1646211789609,"mc":[{"id":"1.195453771","rc":[{"atb":[[2.62,0]],"id":36500377},{"atb":[[2.62,0],[2.94,1.66]],"id":35801684}],"con":true,"img":false}]}
{"op":"mcm","clk":"5353245813","pt":1646211789712,"mc":[{"id":"1.195453771","rc":[{"atb":[[2.72,26.7]],"id":36500377},{"atb":[[2.72,26.7]],"id":35801684}],"con":true,"img":false}]}
{"op":"mcm","clk":"5353245957","pt":1646211791782,"mc":[{"id":"1.195453771","rc":[{"atb":[[2.76,0]],"id":36500377}],"con":true,"img":false}]}
{"op":"mcm","clk":"5353246362","pt":1646211797835,"mc":[{"id":"1.195453771","rc":[{"atb":[[2.78,4.22]],"id":36500377}],"con":true,"img":false}]}
{"op":"mcm","clk":"5353246481","pt":1646211799652,"mc":[{"id":"1.195453771","rc":[{"atb":[[2.04,0]],"id":28338255}],"con":true,"img":false}]}
{"op":"mcm","clk":"5353246487","pt":1646211799753,"mc":[{"id":"1.195453771","rc":[{"atb":[[2.08,46.87]],"id":28338255}],"con":true,"img":false}]}
{"op":"mcm","clk":"5353246546","pt":1646211800836,"mc":[{"id":"1.195453771","rc":[{"atb":[[2.1,0]],"id":28338255}],"con":true,"img":false}]}
{"op":"mcm","clk":"5353246725","pt":1646211803620,"mc":[{"id":"1.195453771","rc":[{"atb":[[2.12,0]],"id":28338255}],"con":true,"img":false}]}
{"op":"mcm","clk":"5353246728","pt":1646211803724,"mc":[{"id":"1.195453771","rc":[{"atb":[[2.1,1.66]],"id":28338255}],"con":true,"img":false}]}
{"op":"mcm","clk":"5353246881","pt":1646211806818,"mc":[{"id":"1.195453771","rc":[{"atb":[[2.12,6.71]],"id":28338255}],"con":true,"img":false}]}
{"op":"mcm","clk":"5353247082","pt":1646211810553,"mc":[{"id":"1.195453771","rc":[{"atb":[[2.1,0]],"id":28338255}],"con":true,"img":false}]}
{"op":"mcm","clk":"5353247087","pt":1646211810653,"mc":[{"id":"1.195453771","rc":[{"atb":[[2.14,1.66]],"id":28338255}],"con":true,"img":false}]}
{"op":"mcm","clk":"5353248125","pt":1646211828662,"mc":[{"id":"1.195453771","rc":[{"atb":[[2.86,0]],"id":39784543},{"atb":[[2.82,0]],"id":36074638}],"con":true,"img":false}]}
{"op":"mcm","clk":"5353248132","pt":1646211828768,"mc":[{"id":"1.195453771","rc":[{"atb":[[2.96,22.34]],"id":39784543},{"atb":[[2.92,21.21]],"id":36074638}],"con":true,"img":false}]}
{"op":"mcm","clk":"5353252683","pt":1646211910503,"mc":[{"id":"1.195453771","rc":[{"atb":[[1.89,71.28],[1.71,0]],"id":36500377},{"spn":4.77,"spf":"NaN","id":35801684},{"atb":[[2.06,0],[1.98,86.42]],"id":28338255},{"spn":2.67,"spf":"NaN","id":28338255}],"con":true,"img":false}]}
{"op":"mcm","clk":"5353252708","pt":1646211910913,"mc":[{"id":"1.195453771","rc":[{"atb":[[2.12,14.15]],"id":28338255}],"con":true,"img":false}]}
{"op":"mcm","clk":"5353252712","pt":1646211911018,"mc":[{"id":"1.195453771","rc":[{"atb":[[3,7.92]],"id":39784543}],"con":true,"img":false}]}
{"op":"mcm","clk":"5353252724","pt":1646211911226,"mc":[{"id":"1.195453771","rc":[{"atb":[[2.76,4.73]],"id":35801684},{"atb":[[2.96,8.08]],"id":36074638}],"con":true,"img":false}]}
{"op":"mcm","clk":"5353252737","pt":1646211911534,"mc":[{"id":"1.195453771","rc":[{"atb":[[2.76,4.73]],"id":36500377}],"con":true,"img":false}]}
{"op":"mcm","clk":"5353253283","pt":1646211921330,"mc":[{"id":"1.195453771","rc":[{"atb":[[2.08,0]],"id":28338255}],"con":true,"img":false}]}
{"op":"mcm","clk":"5353253290","pt":1646211921428,"mc":[{"id":"1.195453771","rc":[{"atb":[[1.99,46.87]],"id":28338255}],"con":true,"img":false}]}
{"op":"mcm","clk":"5353253433","pt":1646211924052,"mc":[{"id":"1.195453771","rc":[{"atb":[[2.12,7.44]],"id":28338255}],"con":true,"img":false}]}
{"op":"mcm","clk":"5353253832","pt":1646211930051,"mc":[{"id":"1.195453771","rc":[{"atb":[[2.04,7.23]],"id":28338255}],"con":true,"img":false}]}
{"op":"mcm","clk":"5353254736","pt":1646211944554,"mc":[{"id":"1.195453771","rc":[{"atb":[[2.12,0]],"id":28338255}],"con":true,"img":false}]}
{"op":"mcm","clk":"5353254961","pt":1646211948571,"mc":[{"id":"1.195453771","rc":[{"atb":[[2.14,0]],"id":28338255}],"con":true,"img":false}]}
{"op":"mcm","clk":"5353254970","pt":1646211948778,"mc":[{"id":"1.195453771","rc":[{"atb":[[2.06,1.66]],"id":28338255}],"con":true,"img":false}]}
{"op":"mcm","clk":"5353255676","pt":1646211959312,"mc":[{"id":"1.195453771","rc":[{"atb":[[2.04,15.25]],"id":28338255}],"con":true,"img":false}]}
{"op":"mcm","clk":"5353266655","pt":1646212137936,"mc":[{"id":"1.195453771","rc":[{"atb":[[3.2,0],[2.96,0]],"id":39784543},{"atl":[[16,0],[13.5,0]],"id":39784543},{"atb":[[2.72,0],[2.84,0]],"id":36500377},{"atl":[[12,0],[13.5,0]],"id":36500377},{"atb":[[2.72,0],[2.88,0]],"id":35801684},{"atl":[[12,0],[13.5,0]],"id":35801684},{"atb":[[2.92,0],[3,0]],"id":36074638},{"atl":[[13.5,0],[15,0]],"id":36074638},{"atb":[[1.2,0],[1.23,0]],"id":42189401},{"atl":[[2.56,0],[2.32,0]],"id":42189401},{"spn":1.73,"spf":"NaN","id":42189401},{"atb":[[1.99,0],[1.75,0]],"id":28338255},{"atl":[[6.6,0],[5.9,0]],"id":28338255},{"spn":2.63,"spf":"NaN","id":28338255},{"atb":[[1.26,0],[1.32,0]],"id":37127725},{"atl":[[2.82,0],[2.62,0]],"id":37127725},{"spn":1.87,"spf":"NaN","id":37127725},{"atb":[[1.31,0]],"id":26051221},{"atl":[[2.92,0],[2.78,0]],"id":26051221},{"spn":1.92,"spf":"NaN","id":26051221}],"con":true,"img":false}]}
{"op":"mcm","clk":"5353266667","pt":1646212138141,"mc":[{"id":"1.195453771","rc":[{"atb":[[3.2,19.81],[2.86,22.34]],"id":39784543},{"atl":[[14.5,3.26],[15,4.83]],"id":39784543},{"atb":[[2.84,23.69],[2.62,26.7]],"id":36500377},{"atl":[[12.5,3.79],[13.5,3.26]],"id":36500377},{"atb":[[2.84,23.69],[2.62,26.7]],"id":35801684},{"atl":[[12.5,3.79],[13.5,3.26]],"id":35801684},{"atb":[[2.82,21.21],[3,21.79]],"id":36074638},{"atl":[[14,3.35],[15.5,2.72]],"id":36074638},{"atb":[[1.2,202.55],[1.23,91.67]],"id":42189401},{"atl":[[2.56,25.96],[2.38,31.59]],"id":42189401},{"atb":[[1.26,548.66],[1.32,85.42],[1.31,0]],"id":37127725},{"atl":[[2.82,23.43],[2.66,26.26]],"id":37127725},{"atb":[[1.31,218.74]],"id":26051221},{"atl":[[3.2,17.25],[2.86,23.43]],"id":26051221},{"atb":[[1.99,44.04],[1.75,57.44]],"id":28338255},{"atl":[[6.6,7.28],[5.9,8.89]],"id":28338255}],"con":true,"img":false}]}
{"op":"mcm","clk":"5353266674","pt":1646212138340,"mc":[{"id":"1.195453771","rc":[{"atl":[[14.5,0]],"id":39784543},{"atb":[[1.26,164.04],[1.31,322.58]],"id":37127725}],"con":true,"img":false}]}
{"op":"mcm","clk":"5353266680","pt":1646212138449,"mc":[{"id":"1.195453771","rc":[{"atl":[[16.5,3.26]],"id":39784543},{"atb":[[2.78,0]],"id":36500377},{"atb":[[2.04,8.01]],"id":28338255}],"con":true,"img":false}]}
{"op":"mcm","clk":"5353267131","pt":1646212147382,"mc":[{"id":"1.195453771","rc":[{"atb":[[2.76,9]],"id":36500377},{"atb":[[2.04,15.25]],"id":28338255}],"con":true,"img":false}]}
{"op":"mcm","clk":"5353267564","pt":1646212154764,"mc":[{"id":"1.195453771","rc":[{"atb":[[2.82,0],[2.96,31.18]],"id":39784543},{"atb":[[2.86,0],[2.94,5.58]],"id":35801684},{"atb":[[2.06,0]],"id":36074638},{"atl":[[2.4,41.04],[2.58,0]],"id":42189401},{"atb":[[1.32,249.46]],"id":37127725},{"atl":[[2.74,23.43]],"id":37127725}],"con":true,"img":false}]}
{"op":"mcm","clk":"5353267572","pt":1646212154866,"mc":[{"id":"1.195453771","rc":[{"atb":[[2.3,76.92]],"id":36074638},{"atb":[[1.31,0]],"id":37127725},{"atl":[[2.92,0]],"id":37127725}],"con":true,"img":false}]}
{"op":"mcm","clk":"5353267668","pt":1646212156460,"mc":[{"id":"1.195453771","rc":[{"atb":[[3,4.16]],"id":39784543},{"atb":[[2.92,0]],"id":35801684}],"con":true,"img":false}]}
{"op":"mcm","clk":"5353267984","pt":1646212162385,"mc":[{"id":"1.195453771","rc":[{"atb":[[3.05,3.66]],"id":39784543},{"atb":[[2.76,9]],"id":35801684}],"con":true,"img":false}]}
{"op":"mcm","clk":"5353268540","pt":1646212173099,"mc":[{"id":"1.195453771","rc":[{"atl":[[2.4,0],[2.46,63.18]],"id":42189401},{"atb":[[1.32,85.42],[1.31,322.58]],"id":37127725}],"con":true,"img":false}]}
{"op":"mcm","clk":"5353268807","pt":1646212177632,"mc":[{"id":"1.195453771","rc":[{"atb":[[3,0]],"id":39784543}],"con":true,"img":false}]}
{"op":"mcm","clk":"5353268882","pt":1646212178609,"mc":[{"id":"1.195453771","rc":[{"atb":[[2.98,31.18],[2.96,0]],"id":39784543}],"con":true,"img":false}]}
{"op":"mcm","clk":"5353269255","pt":1646212185017,"mc":[{"id":"1.195453771","rc":[{"atl":[[15,1.72]],"id":39784543}],"con":true,"img":false}]}
{"op":"mcm","clk":"5353269265","pt":1646212185119,"mc":[{"id":"1.195453771","rc":[{"atl":[[13.5,3.11]],"id":39784543}],"con":true,"img":false}]}
{"op":"mcm","clk":"5353269919","pt":1646212196722,"mc":[{"id":"1.195453771","rc":[{"atb":[[1.33,164.04],[1.31,0]],"id":37127725}],"con":true,"img":false}]}
{"op":"mcm","clk":"5353270445","pt":1646212206268,"mc":[{"id":"1.195453771","rc":[{"atb":[[2.86,0]],"id":39784543},{"atb":[[2.62,0]],"id":36500377},{"atb":[[2.62,0]],"id":35801684},{"atb":[[2.82,0]],"id":36074638},{"atl":[[2.56,0]],"id":42189401},{"spn":1.75,"spf":"NaN","id":42189401},{"atl":[[2.82,0]],"id":37127725},{"spn":1.88,"spf":"NaN","id":37127725},{"spn":1.92,"spf":"NaN","id":26051221}],"con":true,"img":false}]}
{"op":"mcm","clk":"5353270452","pt":1646212206371,"mc":[{"id":"1.195453771","rc":[{"atb":[[3,22.34]],"id":39784543},{"atb":[[2.72,26.7]],"id":36500377},{"atb":[[2.72,26.7]],"id":35801684},{"atb":[[2.92,21.21]],"id":36074638},{"atl":[[2.44,25.96]],"id":42189401},{"atl":[[2.72,23.43]],"id":37127725}],"con":true,"img":false}]}
{"op":"mcm","clk":"5353270500","pt":1646212207189,"mc":[{"id":"1.195453771","rc":[{"atb":[[2.76,4.73]],"id":36500377},{"atb":[[2.76,4.73]],"id":35801684}],"con":true,"img":false}]}
{"op":"mcm","clk":"5353270560","pt":1646212208480,"mc":[{"id":"1.195453771","rc":[{"atb":[[3.05,7.73]],"id":39784543}],"con":true,"img":false}]}
{"op":"mcm","clk":"5353270812","pt":1646212213282,"mc":[{"id":"1.195453771","rc":[{"atb":[[2.78,4.22]],"id":36500377},{"atb":[[2.78,4.22]],"id":35801684}],"con":true,"img":false}]}
{"op":"mcm","clk":"5353272665","pt":1646212247254,"mc":[{"id":"1.195453771","rc":[{"atb":[[1.32,0]],"id":37127725}],"con":true,"img":false}]}
{"op":"mcm","clk":"5353272672","pt":1646212247360,"mc":[{"id":"1.195453771","rc":[{"atb":[[1.29,85.42]],"id":37127725}],"con":true,"img":false}]}
{"op":"mcm","clk":"5353272678","pt":1646212247408,"mc":[{"id":"1.195453771","rc":[{"atb":[[1.27,328.08]],"id":37127725}],"con":true,"img":false}]}
{"op":"mcm","clk":"5353272683","pt":1646212247513,"mc":[{"id":"1.195453771","rc":[{"atb":[[1.33,0]],"id":37127725}],"con":true,"img":false}]}
{"op":"mcm","clk":"5353273903","pt":1646212269196,"mc":[{"id":"1.195453771","rc":[{"spn":1.86,"spf":"NaN","id":37127725},{"atl":[[3.2,0]],"id":26051221}],"con":true,"img":false}]}
{"op":"mcm","clk":"5353273907","pt":1646212269298,"mc":[{"id":"1.195453771","rc":[{"atl":[[2.92,17.25]],"id":26051221}],"con":true,"img":false}]}
{"op":"mcm","clk":"5353273961","pt":1646212270283,"mc":[{"id":"1.195453771","rc":[{"atb":[[1.27,0],[1.3,164.04]],"id":37127725}],"con":true,"img":false}]}
{"op":"mcm","clk":"5353275245","pt":1646212293096,"mc":[{"id":"1.195453771","rc":[{"atb":[[2.82,54.95],[2.98,0]],"id":39784543},{"atb":[[2.86,11.18],[2.94,1.66]],"id":35801684},{"atb":[[2.3,0],[2.12,53.64]],"id":36074638},{"atl":[[2.46,0],[2.58,51.94]],"id":42189401},{"atl":[[2.74,0],[2.9,36.58]],"id":37127725}],"con":true,"img":false}]}
{"op":"mcm","clk":"5353275417","pt":1646212295526,"mc":[{"id":"1.195453771","rc":[{"atb":[[3.05,4.06]],"id":39784543}],"con":true,"img":false}]}
{"op":"mcm","clk":"5353275627","pt":1646212298923,"mc":[{"id":"1.195453771","rc":[{"atb":[[2.94,0]],"id":35801684}],"con":true,"img":false}]}
{"op":"mcm","clk":"5353275634","pt":1646212299026,"mc":[{"id":"1.195453771","rc":[{"atb":[[2.88,1.66]],"id":35801684}],"con":true,"img":false}]}
{"op":"mcm","clk":"5353276387","pt":1646212310837,"mc":[{"id":"1.195453771","rc":[{"atl":[[2.44,0]],"id":42189401},{"atb":[[1.29,0]],"id":37127725},{"atl":[[2.72,0]],"id":37127725}],"con":true,"img":false}]}
{"op":"mcm","clk":"5353276395","pt":1646212310939,"mc":[{"id":"1.195453771","rc":[{"atl":[[2.56,25.96]],"id":42189401},{"atb":[[1.31,85.42]],"id":37127725},{"atl":[[2.82,23.43]],"id":37127725}],"con":true,"img":false}]}
{"op":"mcm","clk":"5353276412","pt":1646212311248,"mc":[{"id":"1.195453771","rc":[{"atb":[[1.27,328.08],[1.3,0]],"id":37127725}],"con":true,"img":false}]}
{"op":"mcm","clk":"5353276532","pt":1646212313514,"mc":[{"id":"1.195453771","rc":[{"atb":[[3.05,0]],"id":39784543}],"con":true,"img":false}]}
{"op":"mcm","clk":"5353277642","pt":1646212333504,"mc":[{"id":"1.195453771","rc":[{"spn":4.74,"spf":"NaN","id":35801684},{"atb":[[1.27,0],[1.31,249.46]],"id":37127725},{"spn":1.87,"spf":"NaN","id":37127725}],"con":true,"img":false}]}
{"op":"mcm","clk":"5353277700","pt":1646212334589,"mc":[{"id":"1.195453771","rc":[{"atb":[[1.31,164.04]],"id":37127725}],"con":true,"img":false}]}
{"op":"mcm","clk":"5353277704","pt":1646212334690,"mc":[{"id":"1.195453771","rc":[{"atb":[[1.28,85.42]],"id":37127725}],"con":true,"img":false}]}
{"op":"mcm","clk":"5353277908","pt":1646212338597,"mc":[{"id":"1.195453771","rc":[{"atb":[[1.29,328.08],[1.31,0]],"id":37127725}],"con":true,"img":false}]}
{"op":"mcm","clk":"5353279882","pt":1646212369933,"mc":[{"id":"1.195453771","rc":[{"atb":[[1.28,0]],"id":37127725}],"con":true,"img":false}]}
{"op":"mcm","clk":"5353279894","pt":1646212370034,"mc":[{"id":"1.195453771","rc":[{"atb":[[1.27,370.37],[1.3,85.42],[1.29,0]],"id":37127725}],"con":true,"img":false}]}
{"op":"mcm","clk":"5353281174","pt":1646212391684,"mc":[{"id":"1.195453771","rc":[{"atb":[[1.31,164.04]],"id":37127725}],"con":true,"img":false}]}
{"op":"mcm","clk":"5353281182","pt":1646212391789,"mc":[{"id":"1.195453771","rc":[{"atb":[[1.27,0]],"id":37127725}],"con":true,"img":false}]}
{"op":"mcm","clk":"5353283260","pt":1646212427341,"mc":[{"id":"1.195453771","rc":[{"atb":[[1.3,0]],"id":37127725}],"con":true,"img":false}]}
{"op":"mcm","clk":"5353283267","pt":1646212427434,"mc":[{"id":"1.195453771","rc":[{"atb":[[1.27,328.08],[1.32,85.42],[1.31,0]],"id":37127725}],"con":true,"img":false}]}
{"op":"mcm","clk":"5353283281","pt":1646212427646,"mc":[{"id":"1.195453771","rc":[{"atb":[[1.27,0],[1.31,241.98]],"id":37127725}],"con":true,"img":false}]}
{"op":"mcm","clk":"5353298815","pt":1646212602693,"mc":[{"id":"1.195453771","marketDefinition":{"bspMarket":true,"turnInPlayEnabled":false,"persistenceEnabled":false,"marketBaseRate":7.0,"eventId":"31272499","eventTypeId":"4339","numberOfWinners":3,"bettingType":"ODDS","marketType":"PLACE","marketTime":"2022-03-02T09:47:00.000Z","suspendTime":"2022-03-02T09:47:00.000Z","bspReconciled":false,"complete":true,"inPlay":false,"crossMatching":true,"runnersVoidable":false,"numberOfActiveRunners":8,"betDelay":0,"status":"OPEN","runners":[{"status":"ACTIVE","sortPriority":1,"id":36074638,"name":"1. Just Law"},{"status":"ACTIVE","sortPriority":2,"id":39784543,"name":"2. Surreal"},{"status":"ACTIVE","sortPriority":3,"id":36500377,"name":"3. Mystery Train"},{"status":"ACTIVE","sortPriority":4,"id":42189401,"name":"4. Daisy Cousins"},{"status":"ACTIVE","sortPriority":5,"id":35801684,"name":"5. Zeke The Freak"},{"status":"ACTIVE","sortPriority":6,"id":37127725,"name":"6. Exit Plan"},{"status":"ACTIVE","sortPriority":7,"id":26051221,"name":"7. Farmor Crownies"},{"status":"ACTIVE","sortPriority":8,"id":28338255,"name":"8. Until Late"}],"regulators":["MR_INT"],"venue":"Rockhampton","countryCode":"AU","discountAllowed":true,"timezone":"Australia/Queensland","openDate":"2022-03-02T08:28:00.000Z","version":4382602050,"name":"To Be Placed","eventName":"Rockhampton (AUS) 2nd Mar"},"rc":[{"atb":[[2.82,54.95],[3.2,19.81],[2.74,69.53],[3,22.34],[3.25,1.66],[2.84,65.75],[2.94,31.18]],"id":39784543},{"atl":[[8,1.72],[16.5,3.26],[10,1.34],[20,1.27],[13.5,3.11],[14,3.08],[15,1.72],[30,1.66]],"id":39784543},{"spn":5.62,"spf":"NaN","id":39784543},{"atb":[[2.72,26.7],[2.86,1.66],[2.5,80.65],[1.89,71.28],[2.6,75.61],[2.84,23.69],[2.78,4.22],[2.76,4.73],[2.7,35.58]],"id":36500377},{"atl":[[16.5,1.55],[8.6,1.59],[11.5,2.3],[23,2.2],[12.5,3.79],[13.5,3.26],[6.6,4.31]],"id":36500377},{"spn":4.73,"spf":"NaN","id":36500377},{"atb":[[2.72,26.7],[2.88,1.66],[2.86,11.18],[2.5,80.65],[2.6,75.61],[2.84,23.69],[2.78,4.22],[2.76,4.73],[2.7,35.58]],"id":35801684},{"atl":[[16.5,1.55],[8.6,1.59],[11.5,2.3],[23,2.2],[12.5,3.79],[50,2.04],[13.5,3.26],[6.6,2.15]],"id":35801684},{"spn":4.74,"spf":"NaN","id":35801684},{"atb":[[2.8,67.21],[2.92,21.21],[2.9,31.83],[3,21.79],[2.12,53.64],[2.96,8.08],[3.05,1.66],[2.7,71.17]],"id":36074638},{"atl":[[19.5,1.3],[9.8,1.37],[7.8,3.77],[14,3.35],[14.5,1.79],[29,1.72],[15.5,2.72]],"id":36074638},{"spn":5.42,"spf":"NaN","id":36074638},{"atb":[[1.2,202.55],[1.19,318.38],[1.23,91.67],[1.14,864.19],[1.09,1344.3]],"id":42189401},{"atl":[[2.56,25.96],[2.88,12.87],[3.2,21.99],[2.38,31.59],[2.28,9.45],[2.58,51.94],[2.68,14.4],[2.48,8.17]],"id":42189401},{"spn":1.75,"spf":"NaN","id":42189401},{"atb":[[1.2,604.93],[1.25,241.97],[1.15,806.58],[1.26,164.04],[1.32,85.42],[1.31,241.98]],"id":37127725},{"atl":[[2.82,23.43],[3.6,18.61],[2.9,36.58],[3.1,11.52],[2.44,8.4],[2.64,7.37],[2.66,26.26],[2.84,13.15]],"id":37127725},{"spn":1.88,"spf":"NaN","id":37127725},{"atb":[[1.2,604.93],[1.25,483.95],[1.3,201.64],[1.31,218.74]],"id":26051221},{"atl":[[2.92,17.25],[3.6,22.8],[2.54,7.85],[3.85,16.98],[2.74,6.95],[2.86,23.43],[3.35,10.29],[2.94,12.47]],"id":26051221},{"spn":1.92,"spf":"NaN","id":26051221},{"atb":[[1.99,44.04],[1.6,201.64],[2.06,1.66],[1.98,86.42],[2.04,15.25],[1.7,86.41],[1.75,57.44],[1.65,186.13]],"id":28338255},{"atl":[[3.2,5.49],[3.7,4.47],[6,11.02],[6.8,8.34],[4.4,7.11],[6.6,7.28],[5.9,8.89],[5.4,5.49]],"id":28338255},{"spn":2.63,"spf":"NaN","id":28338255}],"con":true,"img":true}]}
{"op":"mcm","clk":"5353302532","pt":1646212622993,"mc":[{"id":"1.195453771","rc":[{"atb":[[2,20],[1.98,51.02],[1.96,78.12],[1.94,132.98]],"id":36500377},{"atl":[[6.2,9.62],[6.6,17.7],[7,20.83],[5.9,4.08]],"id":36500377},{"atb":[[2.82,22.36],[2.86,0]],"id":35801684},{"atb":[[2.92,47.25],[2.88,39.89],[2.84,67.93],[2.96,18.28]],"id":36074638},{"atl":[[6.2,3.85],[7.4,19.53],[6.6,8.93],[7,12.5]],"id":36074638},{"atb":[[1.3,327.4],[1.31,0]],"id":37127725},{"spn":1.88,"spf":"NaN","id":37127725}],"con":true,"img":false}]}
{"op":"mcm","clk":"5353302538","pt":1646212623147,"mc":[{"id":"1.195453771","rc":[{"atb":[[2.82,0],[3.2,53.9],[3.1,59.52],[3.4,8.33],[3.3,21.74],[2.96,51.02]],"id":39784543},{"atl":[[11,2],[12,4.55],[13,6.25],[14,12.7]],"id":39784543},{"atl":[[6.6,15.54],[5.9,13.7]],"id":36500377},{"atb":[[2.98,37.88],[2.94,64.43],[3.05,24.39],[3.15,9.3]],"id":35801684},{"atl":[[260,1],[280,1],[220,1],[240,1]],"id":35801684},{"atl":[[6,8.93],[7.8,1.77]],"id":36074638},{"atb":[[1.03,250],[1.09,1566.52],[1.07,250],[1.05,250]],"id":42189401},{"atl":[[1.84,23.81],[2.58,0],[1.88,85.23],[1.9,138.89],[2.46,41.04],[1.86,58.14]],"id":42189401},{"atb":[[1.28,178.57],[1.26,414.04],[1.3,394.07],[1.24,250]],"id":37127725},{"atl":[[2.36,36.76],[2.4,53.57],[2.9,0],[2.32,15.15],[2.44,95.21],[2.76,23.43]],"id":37127725},{"atb":[[1.33,151.52],[1.29,250],[1.31,460.68],[1.35,57.14]],"id":26051221},{"atl":[[2.24,40.32],[2.32,94.7],[2.28,58.59],[2.2,16.67]],"id":26051221},{"atb":[[1.99,119.8],[2.02,49.02],[2.06,20.53],[1.97,128.87]],"id":28338255},{"atl":[[4.3,37.88],[3.85,7.02],[3.95,16.95],[4.1,24.19]],"id":28338255}],"con":true,"img":false}]}
{"op":"mcm","clk":"5353302548","pt":1646212623301,"mc":[{"id":"1.195453771","rc":[{"atl":[[6,0],[6.6,21.71]],"id":36074638}],"con":true,"img":false}]}
{"op":"mcm","clk":"5353302552","pt":1646212623404,"mc":[{"id":"1.195453771","rc":[{"atl":[[6.6,8.93],[7,29.17]],"id":36074638}],"con":true,"img":false}]}
{"op":"mcm","clk":"5353302593","pt":1646212624534,"mc":[{"id":"1.195453771","rc":[{"atb":[[2.78,0]],"id":35801684},{"atb":[[2.96,14.45]],"id":36074638},{"atb":[[2.04,8.01]],"id":28338255}],"con":true,"img":false}]}
{"op":"mcm","clk":"5353302673","pt":1646212625931,"mc":[{"id":"1.195453771","rc":[{"atb":[[3.25,0]],"id":39784543},{"atb":[[2.88,0]],"id":35801684},{"atl":[[6.6,0]],"id":28338255},{"atl":[[2.92,0]],"id":26051221}],"con":true,"img":false}]}
{"op":"mcm","clk":"5353302684","pt":1646212626034,"mc":[{"id":"1.195453771","rc":[{"atl":[[3.2,17.25]],"id":26051221},{"atl":[[7.2,7.28]],"id":28338255}],"con":true,"img":false}]}
{"op":"mcm","clk":"5353302694","pt":1646212626137,"mc":[{"id":"1.195453771","rc":[{"atb":[[3.45,1.66]],"id":39784543},{"atb":[[3.2,1.66]],"id":35801684}],"con":true,"img":false}]}
{"op":"mcm","clk":"5353302815","pt":1646212628309,"mc":[{"id":"1.195453771","rc":[{"atl":[[6.6,33.4],[5.9,4.08]],"id":36500377}],"con":true,"img":false}]}
{"op":"mcm","clk":"5353302930","pt":1646212630528,"mc":[{"id":"1.195453771","rc":[{"atb":[[3.4,11.46]],"id":39784543},{"atb":[[3.1,3.57]],"id":35801684},{"atb":[[2.98,3.79]],"id":36074638},{"atb":[[1.38,19.78]],"id":26051221},{"atb":[[2.06,27.62]],"id":28338255}],"con":true,"img":false}]}
{"op":"mcm","clk":"5353302947","pt":1646212630838,"mc":[{"id":"1.195453771","rc":[{"atb":[[2.72,0]],"id":36500377},{"atl":[[12.5,0],[13.5,0]],"id":35801684},{"atb":[[2.36,28.38],[2.92,26.04]],"id":36074638},{"atb":[[1.32,0]],"id":37127725}],"con":true,"img":false}]}
{"op":"mcm","clk":"5353302953","pt":1646212630941,"mc":[{"id":"1.195453771","rc":[{"atb":[[2.52,26.7]],"id":36500377},{"atl":[[18,3.79],[20,3.26]],"id":35801684},{"atb":[[1.27,370.37],[1.3,66.67],[1.31,85.42]],"id":37127725}],"con":true,"img":false}]}
{"op":"mcm","clk":"5353303125","pt":1646212633627,"mc":[{"id":"1.195453771","rc":[{"atb":[[2.78,0]],"id":36500377}],"con":true,"img":false}]}
{"op":"mcm","clk":"5353303270","pt":1646212635840,"mc":[{"id":"1.195453771","rc":[{"atb":[[2.84,0]],"id":36500377},{"atb":[[3,0]],"id":36074638}],"con":true,"img":false}]}
{"op":"mcm","clk":"5353303274","pt":1646212635943,"mc":[{"id":"1.195453771","rc":[{"atb":[[2.72,23.69]],"id":36500377},{"atb":[[2.92,47.83]],"id":36074638}],"con":true,"img":false}]}
{"op":"mcm","clk":"5353303381","pt":1646212637958,"mc":[{"id":"1.195453771","rc":[{"atb":[[2.86,0]],"id":36500377},{"atb":[[3.05,0]],"id":36074638}],"con":true,"img":false}]}
{"op":"mcm","clk":"5353303390","pt":1646212638163,"mc":[{"id":"1.195453771","rc":[{"atb":[[2.78,1.66]],"id":36500377},{"atb":[[3,1.66]],"id":36074638}],"con":true,"img":false}]}
{"op":"mcm","clk":"5353303466","pt":1646212639561,"mc":[{"id":"1.195453771","rc":[{"atb":[[2.76,9]],"id":36500377}],"con":true,"img":false}]}
{"op":"mcm","clk":"5353303594","pt":1646212642145,"mc":[{"id":"1.195453771","rc":[{"atb":[[2.82,0],[3,37.88]],"id":35801684}],"con":true,"img":false}]}
{"op":"mcm","clk":"5353303767","pt":1646212645795,"mc":[{"id":"1.195453771","rc":[{"atb":[[2.72,0]],"id":35801684},{"atb":[[1.31,369.98]],"id":26051221},{"atb":[[1.99,75.76]],"id":28338255}],"con":true,"img":false}]}
{"op":"mcm","clk":"5353303771","pt":1646212645846,"mc":[{"id":"1.195453771","rc":[{"atb":[[2.62,26.7]],"id":35801684},{"atb":[[1.34,90.7]],"id":26051221},{"atb":[[2.04,52.05]],"id":28338255}],"con":true,"img":false}]}
{"op":"mcm","clk":"5353303904","pt":1646212648481,"mc":[{"id":"1.195453771","rc":[{"atb":[[2.06,20.53]],"id":28338255}],"con":true,"img":false}]}
{"op":"mcm","clk":"5353303983","pt":1646212649981,"mc":[{"id":"1.195453771","rc":[{"atb":[[1.27,0],[1.32,85.42]],"id":37127725}],"con":true,"img":false}]}
{"op":"mcm","clk":"5353304026","pt":1646212650757,"mc":[{"id":"1.195453771","rc":[{"atl":[[13.5,0]],"id":39784543},{"atl":[[6.4,8.07],[12.5,0]],"id":36500377},{"atl":[[6.8,7.51],[14,0]],"id":36074638},{"atl":[[2.38,0]],"id":42189401},{"atl":[[2.66,0]],"id":37127725},{"atl":[[5.9,0],[4.2,13.62]],"id":28338255},{"atl":[[2.26,34.6],[2.86,0]],"id":26051221}],"con":true,"img":false}]}
{"op":"mcm","clk":"5353304030","pt":1646212650857,"mc":[{"id":"1.195453771","rc":[{"atb":[[3.25,3.7]],"id":39784543},{"atl":[[12,7.66]],"id":39784543},{"atl":[[6.2,19.24],[6.6,15.54]],"id":36500377},{"atl":[[6.6,17.86]],"id":36074638},{"atl":[[1.85,31.59]],"id":42189401},{"atl":[[2.38,26.26]],"id":37127725}],"con":true,"img":false}]}
{"op":"mcm","clk":"5353304035","pt":1646212650961,"mc":[{"id":"1.195453771","rc":[{"atl":[[7,12.49]],"id":36074638}],"con":true,"img":false}]}
{"op":"mcm","clk":"5353304043","pt":1646212651167,"mc":[{"id":"1.195453771","rc":[{"atb":[[2.76,0]],"id":35801684},{"atb":[[2.04,44.04]],"id":28338255}],"con":true,"img":false}]}
{"op":"mcm","clk":"5353304213","pt":1646212654491,"mc":[{"id":"1.195453771","rc":[{"atb":[[2.08,6.96]],"id":28338255}],"con":true,"img":false}]}
{"op":"mcm","clk":"5353304292","pt":1646212655780,"mc":[{"id":"1.195453771","rc":[{"atb":[[2.84,0]],"id":35801684}],"con":true,"img":false}]}
{"op":"mcm","clk":"5353304297","pt":1646212655882,"mc":[{"id":"1.195453771","rc":[{"atb":[[3.05,48.08]],"id":35801684}],"con":true,"img":false}]}
{"op":"mcm","clk":"5353304306","pt":1646212656088,"mc":[{"id":"1.195453771","rc":[{"atb":[[2.06,18.87]],"id":28338255}],"con":true,"img":false}]}
{"op":"mcm","clk":"5353304312","pt":1646212656189,"mc":[{"id":"1.195453771","rc":[{"atb":[[2.1,1.66]],"id":28338255}],"con":true,"img":false}]}
{"op":"mcm","clk":"5353304574","pt":1646212660781,"mc":[{"id":"1.195453771","rc":[{"atb":[[2.24,34.33],[2.52,0]],"id":36500377}],"con":true,"img":false}]}
{"op":"mcm","clk":"5353304580","pt":1646212660884,"mc":[{"id":"1.195453771","rc":[{"atl":[[2.56,0]],"id":42189401}],"con":true,"img":false}]}
{"op":"mcm","clk":"5353304585","pt":1646212660986,"mc":[{"id":"1.195453771","rc":[{"atl":[[2.3,25.96]],"id":42189401}],"con":true,"img":false}]}
{"op":"mcm","clk":"5353304783","pt":1646212664490,"mc":[{"id":"1.195453771","rc":[{"spn":5.72,"spf":"NaN","id":39784543},{"spn":4.34,"spf":"NaN","id":36500377},{"spn":4.9,"spf":"NaN","id":35801684},{"atb":[[2.96,10.2]],"id":36074638},{"spn":4.6,"spf":"NaN","id":36074638},{"spn":1.53,"spf":"NaN","id":42189401},{"spn":2.65,"spf":"NaN","id":28338255},{"spn":1.82,"spf":"NaN","id":37127725},{"spn":1.79,"spf":"NaN","id":26051221}],"con":true,"img":false}]}
{"op":"mcm","clk":"5353304788","pt":1646212664594,"mc":[{"id":"1.195453771","rc":[{"atb":[[2.08,14.68]],"id":28338255}],"con":true,"img":false}]}
{"op":"mcm","clk":"5353304844","pt":1646212665891,"mc":[{"id":"1.195453771","rc":[{"atb":[[3,0]],"id":39784543},{"atb":[[1.26,250]],"id":37127725}],"con":true,"img":false}]}
{"op":"mcm","clk":"5353304847","pt":1646212665994,"mc":[{"id":"1.195453771","rc":[{"atb":[[3.15,22.34]],"id":39784543},{"atb":[[1.29,164.04]],"id":37127725}],"con":true,"img":false}]}
{"op":"mcm","clk":"5353305126","pt":1646212670780,"mc":[{"id":"1.195453771","rc":[{"atl":[[16.5,0]],"id":39784543},{"atl":[[9.2,5.44],[13.5,0]],"id":36500377},{"atb":[[2.92,26.04]],"id":36074638},{"atl":[[10,4.28],[15.5,0]],"id":36074638},{"atb":[[1.31,0]],"id":37127725},{"atl":[[7.2,0]],"id":28338255},{"atb":[[1.34,0]],"id":26051221},{"atl":[[2.84,21.57],[3.2,0]],"id":26051221}],"con":true,"img":false}]}
{"op":"mcm","clk":"5353305132","pt":1646212670882,"mc":[{"id":"1.195453771","rc":[{"atl":[[12.5,3.26]],"id":39784543},{"atb":[[2.94,21.79]],"id":36074638},{"atb":[[1.36,90.7]],"id":26051221},{"atb":[[1.32,0],[1.3,237.51],[1.33,85.42]],"id":37127725},{"atl":[[5.5,7.28]],"id":28338255}],"con":true,"img":false}]}
{"op":"mcm","clk":"5353305137","pt":1646212670986,"mc":[{"id":"1.195453771","rc":[{"atb":[[1.33,249.46],[1.3,66.67]],"id":37127725}],"con":true,"img":false}]}
{"op":"mcm","clk":"5353305141","pt":1646212671090,"mc":[{"id":"1.195453771","rc":[{"atb":[[1.33,85.42],[1.3,245.24]],"id":37127725}],"con":true,"img":false}]}
{"op":"mcm","clk":"5353305146","pt":1646212671190,"mc":[{"id":"1.195453771","rc":[{"atb":[[1.33,249.46]],"id":37127725}],"con":true,"img":false}]}
{"op":"mcm","clk":"5353305151","pt":1646212671294,"mc":[{"id":"1.195453771","rc":[{"atb":[[1.3,66.67]],"id":37127725}],"con":true,"img":false}]}
{"op":"mcm","clk":"5353305219","pt":1646212672684,"mc":[{"id":"1.195453771","rc":[{"atb":[[1.38,0]],"id":26051221}],"con":true,"img":false}]}
{"op":"mcm","clk":"5353305261","pt":1646212673410,"mc":[{"id":"1.195453771","rc":[{"atb":[[3.4,3.13],[3.5,8]],"id":39784543},{"atl":[[6,4],[5.9,0]],"id":36500377},{"atb":[[1.33,0],[1.3,268.31],[1.35,0]],"id":26051221}],"con":true,"img":false}]}
{"op":"mcm","clk":"5353305291","pt":1646212673989,"mc":[{"id":"1.195453771","rc":[{"atb":[[3.45,0]],"id":39784543}],"con":true,"img":false}]}
{"op":"mcm","clk":"5353305312","pt":1646212674195,"mc":[{"id":"1.195453771","rc":[{"atb":[[3.55,1.66]],"id":39784543}],"con":true,"img":false}]}
{"op":"mcm","clk":"5353305403","pt":1646212675901,"mc":[{"id":"1.195453771","rc":[{"atl":[[6.4,0]],"id":36500377},{"atl":[[6.8,0]],"id":36074638},{"atl":[[2.26,0]],"id":26051221},{"atl":[[2.38,0]],"id":37127725},{"atl":[[4.2,0]],"id":28338255}],"con":true,"img":false}]}
{"op":"mcm","clk":"5353305408","pt":1646212676004,"mc":[{"id":"1.195453771","rc":[{"atl":[[6.4,18.52],[6.2,9.62],[6,12.07]],"id":36500377},{"atl":[[6.4,7.51],[7,29.17]],"id":36074638},{"atl":[[4,13.62]],"id":28338255},{"atl":[[2.22,34.6]],"id":26051221},{"atl":[[2.34,26.26]],"id":37127725}],"con":true,"img":false}]}
{"op":"mcm","clk":"5353305415","pt":1646212676110,"mc":[{"id":"1.195453771","rc":[{"atl":[[6.4,0],[5.9,12.07]],"id":36500377},{"atl":[[6.2,11.37],[6.6,8.93],[7,12.49]],"id":36074638}],"con":true,"img":false}]}
{"op":"mcm","clk":"5353305447","pt":1646212676775,"mc":[{"id":"1.195453771","rc":[{"atb":[[3.1,7.54]],"id":35801684}],"con":true,"img":false}]}
{"op":"mcm","clk":"5353305509","pt":1646212678381,"mc":[{"id":"1.195453771","rc":[{"atb":[[1.39,19.27]],"id":26051221}],"con":true,"img":false}]}
{"op":"mcm","clk":"5353305766","pt":1646212683033,"mc":[{"id":"1.195453771","rc":[{"atl":[[2.24,80.65],[2.46,0]],"id":42189401},{"atl":[[3.6,0],[3.1,43.14]],"id":26051221},{"atl":[[2.52,65.79],[2.76,0]],"id":37127725},{"atl":[[6,0],[5.2,20.74]],"id":28338255}],"con":true,"img":false}]}
{"op":"mcm","clk":"5353305794","pt":1646212683395,"mc":[{"id":"1.195453771","rc":[{"atb":[[3.4,23.96]],"id":39784543},{"atl":[[6.4,9.26]],"id":36500377},{"atb":[[1.28,178.57],[1.31,128.04]],"id":26051221}],"con":true,"img":false}]}
{"op":"mcm","clk":"5353305934","pt":1646212685822,"mc":[{"id":"1.195453771","rc":[{"atl":[[6,4]],"id":36500377},{"atl":[[6.4,0]],"id":36074638},{"atb":[[1.33,164.04]],"id":37127725}],"con":true,"img":false}]}
{"op":"mcm","clk":"5353305939","pt":1646212685924,"mc":[{"id":"1.195453771","rc":[{"atl":[[6.4,17.33]],"id":36500377},{"atl":[[7.2,7.51]],"id":36074638},{"atb":[[1.31,85.42]],"id":37127725}],"con":true,"img":false}]}
{"op":"mcm","clk":"5353305944","pt":1646212686027,"mc":[{"id":"1.195453771","rc":[{"atl":[[6.2,25.69],[5.9,0]],"id":36500377},{"atl":[[6.2,3.85],[7,29.17]],"id":36074638},{"atb":[[1.33,0],[1.3,394.75]],"id":37127725}],"con":true,"img":false}]}
{"op":"mcm","clk":"5353306052","pt":1646212688104,"mc":[{"id":"1.195453771","rc":[{"atl":[[2.46,68.49]],"id":42189401},{"atl":[[2.76,56.82]],"id":37127725}],"con":true,"img":false}]}
{"op":"mcm","clk":"5353306062","pt":1646212688207,"mc":[{"id":"1.195453771","rc":[{"atl":[[2.24,0]],"id":42189401},{"atl":[[2.52,0]],"id":37127725},{"atl":[[3.1,0],[3.4,41.67]],"id":26051221},{"atl":[[5.8,14.56],[5.2,0]],"id":28338255}],"con":true,"img":false}]}
{"op":"mcm","clk":"5353306080","pt":1646212688519,"mc":[{"id":"1.195453771","rc":[{"atb":[[1.39,40.65]],"id":26051221}],"con":true,"img":false}]}
{"op":"mcm","clk":"5353306104","pt":1646212689137,"mc":[{"id":"1.195453771","rc":[{"atb":[[2.96,14.45]],"id":36074638}],"con":true,"img":false}]}
{"op":"mcm","clk":"5353306353","pt":1646212693411,"mc":[{"id":"1.195453771","rc":[{"atb":[[3.1,0],[3.3,32.61]],"id":39784543},{"atl":[[6.2,16.07],[6.8,12.93],[6.6,2.15],[7,0]],"id":36500377},{"atb":[[1.26,250]],"id":26051221}],"con":true,"img":false}]}
{"op":"mcm","clk":"5353306476","pt":1646212695829,"mc":[{"id":"1.195453771","rc":[{"atb":[[3.15,0]],"id":39784543},{"atl":[[2.34,0]],"id":37127725}],"con":true,"img":false}]}
{"op":"mcm","clk":"5353306481","pt":1646212695930,"mc":[{"id":"1.195453771","rc":[{"atb":[[2.98,22.34]],"id":39784543},{"atl":[[2.38,26.26]],"id":37127725}],"con":true,"img":false}]}
{"op":"mcm","clk":"5353306674","pt":1646212699332,"mc":[{"id":"1.195453771","rc":[{"atb":[[1.36,0]],"id":26051221}],"con":true,"img":false}]}
{"op":"mcm","clk":"5353306678","pt":1646212699430,"mc":[{"id":"1.195453771","rc":[{"atb":[[1.32,90.7]],"id":26051221}],"con":true,"img":false}]}
{"op":"mcm","clk":"5353306704","pt":1646212699739,"mc":[{"id":"1.195453771","rc":[{"atb":[[1.39,21.37]],"id":26051221}],"con":true,"img":false}]}
{"op":"mcm","clk":"5353306775","pt":1646212700824,"mc":[{"id":"1.195453771","rc":[{"atb":[[3.25,0]],"id":39784543}],"con":true,"img":false}]}
{"op":"mcm","clk":"5353306936","pt":1646212703463,"mc":[{"id":"1.195453771","rc":[{"atb":[[3.2,76.63]],"id":39784543},{"atl":[[7.2,20.16]],"id":36500377},{"atb":[[1.24,250]],"id":26051221}],"con":true,"img":false}]}
{"op":"mcm","clk":"5353306998","pt":1646212704544,"mc":[{"id":"1.195453771","rc":[{"atb":[[1.3,66.67],[1.32,164.04]],"id":37127725}],"con":true,"img":false}]}
{"op":"mcm","clk":"5353307014","pt":1646212704750,"mc":[{"id":"1.195453771","rc":[{"atb":[[3.2,56.82]],"id":39784543},{"atl":[[2.22,0]],"id":26051221}],"con":true,"img":false}]}
{"op":"mcm","clk":"5353307021","pt":1646212704853,"mc":[{"id":"1.195453771","rc":[{"atb":[[3.45,19.81]],"id":39784543},{"atl":[[2.26,34.6]],"id":26051221}],"con":true,"img":false}]}
{"op":"mcm","clk":"5353307192","pt":1646212707844,"mc":[{"id":"1.195453771","rc":[{"atb":[[1.29,0]],"id":26051221}],"con":true,"img":false}]}
{"op":"mcm","clk":"5353307380","pt":1646212710832,"mc":[{"id":"1.195453771","rc":[{"atl":[[6.4,9.26]],"id":36500377},{"atl":[[7.2,0]],"id":36074638}],"con":true,"img":false}]}
{"op":"mcm","clk":"5353307387","pt":1646212710937,"mc":[{"id":"1.195453771","rc":[{"atl":[[6.4,27.78],[6.2,0],[6,12.07]],"id":36500377},{"atl":[[6.8,7.51]],"id":36074638}],"con":true,"img":false}]}
{"op":"mcm","clk":"5353307400","pt":1646212711348,"mc":[{"id":"1.195453771","rc":[{"atl":[[6.6,17.86],[7,12.49]],"id":36074638}],"con":true,"img":false}]}
{"op":"mcm","clk":"5353307502","pt":1646212713358,"mc":[{"id":"1.195453771","rc":[{"atb":[[1.39,0]],"id":26051221}],"con":true,"img":false}]}
{"op":"mcm","clk":"5353307516","pt":1646212713567,"mc":[{"id":"1.195453771","rc":[{"atb":[[3.5,11.33]],"id":39784543}],"con":true,"img":false}]}
{"op":"mcm","clk":"5353307628","pt":1646212715883,"mc":[{"id":"1.195453771","rc":[{"atl":[[2.38,0]],"id":37127725}],"con":true,"img":false}]}
{"op":"mcm","clk":"5353307633","pt":1646212715937,"mc":[{"id":"1.195453771","rc":[{"atl":[[2.34,26.26]],"id":37127725}],"con":true,"img":false}]}
{"op":"mcm","clk":"5353307923","pt":1646212720791,"mc":[{"id":"1.195453771","rc":[{"atl":[[6,4]],"id":36500377},{"atb":[[2.94,0]],"id":36074638}],"con":true,"img":false}]}
{"op":"mcm","clk":"5353307928","pt":1646212720843,"mc":[{"id":"1.195453771","rc":[{"atl":[[6.2,8.07]],"id":36500377},{"atb":[[2.92,47.83]],"id":36074638}],"con":true,"img":false}]}
{"op":"mcm","clk":"5353308225","pt":1646212725753,"mc":[{"id":"1.195453771","rc":[{"spn":5.77,"spf":"NaN","id":39784543},{"spn":4.39,"spf":"NaN","id":36500377},{"atb":[[1.31,0]],"id":37127725},{"atl":[[2.82,0]],"id":37127725},{"spn":1.76,"spf":"NaN","id":26051221}],"con":true,"img":false}]}
{"op":"mcm","clk":"5353308231","pt":1646212725855,"mc":[{"id":"1.195453771","rc":[{"atb":[[1.3,394.75],[1.33,85.42]],"id":37127725},{"atl":[[2.74,23.43]],"id":37127725}],"con":true,"img":false}]}
{"op":"mcm","clk":"5353308236","pt":1646212725956,"mc":[{"id":"1.195453771","rc":[{"atb":[[1.32,0]],"id":37127725}],"con":true,"img":false}]}
{"op":"mcm","clk":"5353308417","pt":1646212729150,"mc":[{"id":"1.195453771","rc":[{"atl":[[6,12.07]],"id":36500377}],"con":true,"img":false}]}
{"op":"mcm","clk":"5353308424","pt":1646212729254,"mc":[{"id":"1.195453771","rc":[{"atl":[[6.4,9.26]],"id":36500377}],"con":true,"img":false}]}
{"op":"mcm","clk":"5353308821","pt":1646212735798,"mc":[{"id":"1.195453771","rc":[{"atl":[[6.2,0]],"id":36500377},{"atl":[[6.8,0]],"id":36074638},{"atb":[[1.33,0]],"id":37127725}],"con":true,"img":false}]}
{"op":"mcm","clk":"5353308829","pt":1646212735898,"mc":[{"id":"1.195453771","rc":[{"atl":[[6.6,10.22]],"id":36500377},{"atl":[[6.4,7.51]],"id":36074638},{"atb":[[1.31,85.42]],"id":37127725}],"con":true,"img":false}]}
{"op":"mcm","clk":"5353308835","pt":1646212736000,"mc":[{"id":"1.195453771","rc":[{"atl":[[6.4,27.78],[6,4]],"id":36500377},{"atl":[[6.6,8.93],[7,29.17]],"id":36074638}],"con":true,"img":false}]}
{"op":"mcm","clk":"5353309036","pt":1646212739563,"mc":[{"id":"1.195453771","rc":[{"atb":[[2.96,10.2]],"id":36074638}],"con":true,"img":false}]}
{"op":"mcm","clk":"5353309119","pt":1646212740803,"mc":[{"id":"1.195453771","rc":[{"atb":[[2.98,0],[3.25,18.52]],"id":39784543}],"con":true,"img":false}]}
{"op":"mcm","clk":"5353309240","pt":1646212743100,"mc":[{"id":"1.195453771","rc":[{"atb":[[2.82,54.95],[2.96,0]],"id":39784543},{"atb":[[3,0],[2.84,54.35]],"id":35801684},{"atl":[[2.9,52.52],[2.76,0]],"id":37127725}],"con":true,"img":false}]}
{"op":"mcm","clk":"5353309369","pt":1646212745781,"mc":[{"id":"1.195453771","rc":[{"atl":[[6.4,0]],"id":36074638},{"atl":[[2.26,0]],"id":26051221}],"con":true,"img":false}]}
{"op":"mcm","clk":"5353309374","pt":1646212745884,"mc":[{"id":"1.195453771","rc":[{"atl":[[6.8,7.51]],"id":36074638},{"atl":[[2.22,34.6]],"id":26051221}],"con":true,"img":false}]}
{"op":"mcm","clk":"5353309644","pt":1646212750797,"mc":[{"id":"1.195453771","rc":[{"atb":[[3.05,24.39]],"id":35801684}],"con":true,"img":false}]}
{"op":"mcm","clk":"5353309650","pt":1646212750900,"mc":[{"id":"1.195453771","rc":[{"atb":[[3,23.69]],"id":35801684}],"con":true,"img":false}]}
{"op":"mcm","clk":"5353309702","pt":1646212751983,"mc":[{"id":"1.195453771","rc":[{"atb":[[2.98,8]],"id":36074638}],"con":true,"img":false}]}
{"op":"mcm","clk":"5353309809","pt":1646212753994,"mc":[{"id":"1.195453771","rc":[{"atl":[[6.6,17.86],[7,12.49]],"id":36074638}],"con":true,"img":false}]}
{"op":"mcm","clk":"5353309907","pt":1646212755814,"mc":[{"id":"1.195453771","rc":[{"atb":[[2.24,0],[2.52,28.33]],"id":36500377}],"con":true,"img":false}]}
{"op":"mcm","clk":"5353310348","pt":1646212764020,"mc":[{"id":"1.195453771","rc":[{"atb":[[3.1,3.57]],"id":35801684}],"con":true,"img":false}]}
{"op":"mcm","clk":"5353310445","pt":1646212765725,"mc":[{"id":"1.195453771","rc":[{"atl":[[6.6,2.15]],"id":36500377}],"con":true,"img":false}]}
{"op":"mcm","clk":"5353310450","pt":1646212765831,"mc":[{"id":"1.195453771","rc":[{"atl":[[6.2,8.07]],"id":36500377}],"con":true,"img":false}]}
{"op":"mcm","clk":"5353310459","pt":1646212766037,"mc":[{"id":"1.195453771","rc":[{"atl":[[6.4,9.26],[6.2,16.14]],"id":36500377}],"con":true,"img":false}]}
{"op":"mcm","clk":"5353310472","pt":1646212766232,"mc":[{"id":"1.195453771","rc":[{"atl":[[6.4,22.19],[6.2,8.07]],"id":36500377}],"con":true,"img":false}]}
{"op":"mcm","clk":"5353310916","pt":1646212775741,"mc":[{"id":"1.195453771","rc":[{"atb":[[3.05,28.45]],"id":35801684}],"con":true,"img":false}]}
{"op":"mcm","clk":"5353311147","pt":1646212780752,"mc":[{"id":"1.195453771","rc":[{"atl":[[6.8,0]],"id":36074638}],"con":true,"img":false}]}
{"op":"mcm","clk":"5353311151","pt":1646212780857,"mc":[{"id":"1.195453771","rc":[{"atl":[[6.4,7.51]],"id":36074638}],"con":true,"img":false}]}
{"op":"mcm","clk":"5353311157","pt":1646212780965,"mc":[{"id":"1.195453771","rc":[{"atl":[[6.6,8.93],[7,29.17]],"id":36074638}],"con":true,"img":false}]}
{"op":"mcm","clk":"5353311308","pt":1646212783826,"mc":[{"id":"1.195453771","rc":[{"atl":[[6.2,16.14]],"id":36500377}],"con":true,"img":false}]}
{"op":"mcm","clk":"5353311312","pt":1646212783926,"mc":[{"id":"1.195453771","rc":[{"atl":[[6.4,9.26]],"id":36500377}],"con":true,"img":false}]}
{"op":"mcm","clk":"5353311678","pt":1646212790764,"mc":[{"id":"1.195453771","rc":[{"atl":[[6.2,8.07]],"id":36500377},{"atl":[[6.4,0]],"id":36074638},{"spn":1.81,"spf":"NaN","id":37127725}],"con":true,"img":false}]}
{"op":"mcm","clk":"5353311679","pt":1646212790850,"mc":[{"id":"1.195453771","rc":[{"atl":[[6.6,10.22]],"id":36500377},{"atl":[[6.8,7.51]],"id":36074638}],"con":true,"img":false}]}
{"op":"mcm","clk":"5353311685","pt":1646212790958,"mc":[{"id":"1.195453771","rc":[{"atl":[[6.4,21.33],[6.2,0]],"id":36500377}],"con":true,"img":false}]}
{"op":"mcm","clk":"5353312055","pt":1646212798473,"mc":[{"id":"1.195453771","rc":[{"atl":[[6.6,17.86],[7,12.49]],"id":36074638}],"con":true,"img":false}]}
{"op":"mcm","clk":"5353313043","pt":1646212815890,"mc":[{"id":"1.195453771","rc":[{"atl":[[6.6,2.15]],"id":36500377}],"con":true,"img":false}]}
{"op":"mcm","clk":"5353313047","pt":1646212815990,"mc":[{"id":"1.195453771","rc":[{"atl":[[6.2,8.07]],"id":36500377}],"con":true,"img":false}]}
{"op":"mcm","clk":"5353313055","pt":1646212816093,"mc":[{"id":"1.195453771","rc":[{"atl":[[6.4,9.26],[6.2,16.14]],"id":36500377}],"con":true,"img":false}]}
{"op":"mcm","clk":"5353313321","pt":1646212820907,"mc":[{"id":"1.195453771","rc":[{"atl":[[6.8,0]],"id":36074638}],"con":true,"img":false}]}
{"op":"mcm","clk":"5353313326","pt":1646212820962,"mc":[{"id":"1.195453771","rc":[{"atl":[[6.4,7.51]],"id":36074638}],"con":true,"img":false}]}
{"op":"mcm","clk":"5353313328","pt":1646212821066,"mc":[{"id":"1.195453771","rc":[{"atl":[[6.6,8.93],[7,29.17]],"id":36074638}],"con":true,"img":false}]}
{"op":"mcm","clk":"5353313334","pt":1646212821171,"mc":[{"id":"1.195453771","rc":[{"atl":[[6.2,11.37]],"id":36074638}],"con":true,"img":false}]}
{"op":"mcm","clk":"5353313338","pt":1646212821276,"mc":[{"id":"1.195453771","rc":[{"atl":[[7,12.49]],"id":36074638}],"con":true,"img":false}]}
{"op":"mcm","clk":"5353313617","pt":1646212825903,"mc":[{"id":"1.195453771","rc":[{"atl":[[6.2,8.07]],"id":36500377}],"con":true,"img":false}]}
{"op":"mcm","clk":"5353313623","pt":1646212826007,"mc":[{"id":"1.195453771","rc":[{"atl":[[6.4,21.33],[6.2,0],[6.6,10.22]],"id":36500377}],"con":true,"img":false}]}
{"op":"mcm","clk":"5353313897","pt":1646212830825,"mc":[{"id":"1.195453771","rc":[{"atl":[[6.4,0]],"id":36074638}],"con":true,"img":false}]}
{"op":"mcm","clk":"5353313905","pt":1646212830927,"mc":[{"id":"1.195453771","rc":[{"atl":[[6.8,7.51]],"id":36074638}],"con":true,"img":false}]}
{"op":"mcm","clk":"5353313909","pt":1646212831027,"mc":[{"id":"1.195453771","rc":[{"atl":[[6.2,3.85],[7,29.17]],"id":36074638}],"con":true,"img":false}]}
{"op":"mcm","clk":"5353314920","pt":1646212848016,"mc":[{"id":"1.195453771","rc":[{"atl":[[6.6,17.86],[7,12.49]],"id":36074638}],"con":true,"img":false}]}
{"op":"mcm","clk":"5353315105","pt":1646212850860,"mc":[{"id":"1.195453771","rc":[{"atl":[[6.6,2.15]],"id":36500377}],"con":true,"img":false}]}
{"op":"mcm","clk":"5353315108","pt":1646212850900,"mc":[{"id":"1.195453771","rc":[{"atl":[[6.2,8.07]],"id":36500377}],"con":true,"img":false}]}
{"op":"mcm","clk":"5353315117","pt":1646212851014,"mc":[{"id":"1.195453771","rc":[{"atl":[[6.4,9.26],[6.2,16.14]],"id":36500377}],"con":true,"img":false}]}
{"op":"mcm","clk":"5353315730","pt":1646212860838,"mc":[{"id":"1.195453771","rc":[{"atl":[[6.2,8.07]],"id":36500377}],"con":true,"img":false}]}
{"op":"mcm","clk":"5353315738","pt":1646212860943,"mc":[{"id":"1.195453771","rc":[{"atl":[[6.4,21.33],[6.2,0],[6.6,10.22]],"id":36500377}],"con":true,"img":false}]}
{"op":"mcm","clk":"5353316428","pt":1646212870756,"mc":[{"id":"1.195453771","rc":[{"atl":[[6.8,0]],"id":36074638}],"con":true,"img":false}]}
{"op":"mcm","clk":"5353316432","pt":1646212870858,"mc":[{"id":"1.195453771","rc":[{"atl":[[6.4,7.51]],"id":36074638}],"con":true,"img":false}]}
{"op":"mcm","clk":"5353316438","pt":1646212870962,"mc":[{"id":"1.195453771","rc":[{"atl":[[6.6,8.93],[7,29.17]],"id":36074638}],"con":true,"img":false}]}
{"op":"mcm","clk":"5353317054","pt":1646212880899,"mc":[{"id":"1.195453771","rc":[{"atl":[[6.4,0]],"id":36074638}],"con":true,"img":false}]}
{"op":"mcm","clk":"5353317056","pt":1646212880967,"mc":[{"id":"1.195453771","rc":[{"atl":[[6.8,7.51]],"id":36074638}],"con":true,"img":false}]}
{"op":"mcm","clk":"5353317312","pt":1646212885784,"mc":[{"id":"1.195453771","rc":[{"atl":[[6.6,2.15]],"id":36500377}],"con":true,"img":false}]}
{"op":"mcm","clk":"5353317318","pt":1646212885881,"mc":[{"id":"1.195453771","rc":[{"atl":[[6.2,8.07]],"id":36500377}],"con":true,"img":false}]}
{"op":"mcm","clk":"5353317333","pt":1646212886085,"mc":[{"id":"1.195453771","rc":[{"atl":[[6.4,9.26],[6.2,16.14]],"id":36500377}],"con":true,"img":false}]}
{"op":"mcm","clk":"5353317336","pt":1646212886190,"mc":[{"id":"1.195453771","rc":[{"atl":[[6.4,22.19]],"id":36500377}],"con":true,"img":false}]}
{"op":"mcm","clk":"5353317342","pt":1646212886298,"mc":[{"id":"1.195453771","rc":[{"atl":[[6.2,8.07]],"id":36500377}],"con":true,"img":false}]}
{"op":"mcm","clk":"5353317345","pt":1646212886393,"mc":[{"id":"1.195453771","rc":[{"atl":[[6.2,24.21]],"id":36500377}],"con":true,"img":false}]}
{"op":"mcm","clk":"5353317352","pt":1646212886554,"mc":[{"id":"1.195453771","rc":[{"atl":[[6.4,9.26]],"id":36500377}],"con":true,"img":false}]}
{"op":"mcm","clk":"5353317399","pt":1646212887580,"mc":[{"id":"1.195453771","rc":[{"atl":[[6.6,17.86]],"id":36074638}],"con":true,"img":false}]}
{"op":"mcm","clk":"5353317403","pt":1646212887683,"mc":[{"id":"1.195453771","rc":[{"atl":[[7,12.49]],"id":36074638}],"con":true,"img":false}]}
{"op":"mcm","clk":"5353317872","pt":1646212895803,"mc":[{"id":"1.195453771","rc":[{"atb":[[2.24,34.33],[2.52,0]],"id":36500377}],"con":true,"img":false}]}
{"op":"mcm","clk":"5353317916","pt":1646212896478,"mc":[{"id":"1.195453771","rc":[{"atb":[[2.84,0],[2.88,47.4]],"id":35801684},{"atb":[[1.3,66.67],[1.29,508.87]],"id":37127725}],"con":true,"img":false}]}
{"op":"mcm","clk":"5353318726","pt":1646212910807,"mc":[{"id":"1.195453771","rc":[{"atl":[[6.2,16.14]],"id":36500377},{"atl":[[6.8,0]],"id":36074638}],"con":true,"img":false}]}
{"op":"mcm","clk":"5353318732","pt":1646212910909,"mc":[{"id":"1.195453771","rc":[{"atl":[[6,12.07]],"id":36500377},{"atl":[[6.4,7.51],[6.6,8.93],[7,29.17]],"id":36074638}],"con":true,"img":false}]}
{"op":"mcm","clk":"5353318738","pt":1646212911014,"mc":[{"id":"1.195453771","rc":[{"atl":[[6.4,27.78],[6.2,0]],"id":36500377}],"con":true,"img":false}]}
{"op":"mcm","clk":"5353319281","pt":1646212920807,"mc":[{"id":"1.195453771","rc":[{"atl":[[6,4]],"id":36500377},{"atl":[[6.4,0]],"id":36074638}],"con":true,"img":false}]}
{"op":"mcm","clk":"5353319288","pt":1646212920910,"mc":[{"id":"1.195453771","rc":[{"atl":[[6.2,8.07]],"id":36500377},{"atl":[[6.8,7.51]],"id":36074638}],"con":true,"img":false}]}
{"op":"mcm","clk":"5353319622","pt":1646212927138,"mc":[{"id":"1.195453771","rc":[{"atl":[[6.6,17.86],[7,12.49]],"id":36074638}],"con":true,"img":false}]}
{"op":"mcm","clk":"5353319628","pt":1646212927241,"mc":[{"id":"1.195453771","rc":[{"atl":[[6.4,9.26],[6.2,16.14]],"id":36500377}],"con":true,"img":false}]}
{"op":"mcm","clk":"5353319632","pt":1646212927345,"mc":[{"id":"1.195453771","rc":[{"atl":[[6.4,22.19]],"id":36500377}],"con":true,"img":false}]}
{"op":"mcm","clk":"5353319636","pt":1646212927446,"mc":[{"id":"1.195453771","rc":[{"atl":[[6.2,8.07]],"id":36500377}],"con":true,"img":false}]}
{"op":"mcm","clk":"5353319638","pt":1646212927550,"mc":[{"id":"1.195453771","rc":[{"atl":[[6.4,9.26],[6.2,24.21]],"id":36500377}],"con":true,"img":false}]}
{"op":"mcm","clk":"5353320910","pt":1646212950751,"mc":[{"id":"1.195453771","rc":[{"atl":[[6.8,0]],"id":36074638}],"con":true,"img":false}]}
{"op":"mcm","clk":"5353320914","pt":1646212950853,"mc":[{"id":"1.195453771","rc":[{"atl":[[6.4,7.51],[6.6,8.93],[7,29.17]],"id":36074638}],"con":true,"img":false}]}
{"op":"mcm","clk":"5353321395","pt":1646212960794,"mc":[{"id":"1.195453771","rc":[{"atl":[[6.4,0]],"id":36074638}],"con":true,"img":false}]}
{"op":"mcm","clk":"5353321401","pt":1646212960896,"mc":[{"id":"1.195453771","rc":[{"atl":[[6.8,7.51]],"id":36074638}],"con":true,"img":false}]}
{"op":"mcm","clk":"5353321760","pt":1646212966676,"mc":[{"id":"1.195453771","rc":[{"atl":[[6.6,17.86],[7,12.49]],"id":36074638}],"con":true,"img":false}]}
{"op":"mcm","clk":"5353323231","pt":1646212990811,"mc":[{"id":"1.195453771","rc":[{"atl":[[6.8,0]],"id":36074638}],"con":true,"img":false}]}
{"op":"mcm","clk":"5353323238","pt":1646212990912,"mc":[{"id":"1.195453771","rc":[{"atl":[[6.4,7.51]],"id":36074638}],"con":true,"img":false}]}
{"op":"mcm","clk":"5353323244","pt":1646212991017,"mc":[{"id":"1.195453771","rc":[{"atl":[[6.6,8.93],[7,29.17]],"id":36074638}],"con":true,"img":false}]}
{"op":"mcm","clk":"5353323864","pt":1646213000704,"mc":[{"id":"1.195453771","rc":[{"atl":[[6.4,0]],"id":36074638}],"con":true,"img":false}]}
{"op":"mcm","clk":"5353323870","pt":1646213000808,"mc":[{"id":"1.195453771","rc":[{"atl":[[6.8,7.51]],"id":36074638}],"con":true,"img":false}]}
{"op":"mcm","clk":"5353324234","pt":1646213006448,"mc":[{"id":"1.195453771","rc":[{"atl":[[6.6,17.86],[7,12.49]],"id":36074638}],"con":true,"img":false}]}
{"op":"mcm","clk":"5353325812","pt":1646213030774,"mc":[{"id":"1.195453771","rc":[{"atl":[[6.8,0]],"id":36074638}],"con":true,"img":false}]}
{"op":"mcm","clk":"5353325817","pt":1646213030877,"mc":[{"id":"1.195453771","rc":[{"atl":[[6.4,7.51],[6.6,8.93],[7,29.17]],"id":36074638}],"con":true,"img":false}]}
{"op":"mcm","clk":"5353326393","pt":1646213040779,"mc":[{"id":"1.195453771","rc":[{"atl":[[6.4,0]],"id":36074638}],"con":true,"img":false}]}
{"op":"mcm","clk":"5353326397","pt":1646213040880,"mc":[{"id":"1.195453771","rc":[{"atl":[[6.8,7.51]],"id":36074638}],"con":true,"img":false}]}
{"op":"mcm","clk":"5353326707","pt":1646213045894,"mc":[{"id":"1.195453771","rc":[{"atl":[[6.6,17.86],[7,12.49]],"id":36074638}],"con":true,"img":false}]}
{"op":"mcm","clk":"5353328299","pt":1646213070799,"mc":[{"id":"1.195453771","rc":[{"atl":[[6.8,0]],"id":36074638}],"con":true,"img":false}]}
{"op":"mcm","clk":"5353328307","pt":1646213070903,"mc":[{"id":"1.195453771","rc":[{"atl":[[6.4,7.51],[6.6,8.93],[7,29.17]],"id":36074638}],"con":true,"img":false}]}
{"op":"mcm","clk":"5353328894","pt":1646213080833,"mc":[{"id":"1.195453771","rc":[{"atl":[[6.4,0]],"id":36074638}],"con":true,"img":false}]}
{"op":"mcm","clk":"5353328902","pt":1646213080932,"mc":[{"id":"1.195453771","rc":[{"atl":[[6.8,7.51]],"id":36074638}],"con":true,"img":false}]}
{"op":"mcm","clk":"5353329233","pt":1646213085531,"mc":[{"id":"1.195453771","rc":[{"atl":[[6.6,17.86],[7,12.49]],"id":36074638}],"con":true,"img":false}]}
{"op":"mcm","clk":"5353330379","pt":1646213105760,"mc":[{"id":"1.195453771","rc":[{"atl":[[6.8,0]],"id":36074638}],"con":true,"img":false}]}
{"op":"mcm","clk":"5353330385","pt":1646213105863,"mc":[{"id":"1.195453771","rc":[{"atl":[[6.4,7.51]],"id":36074638}],"con":true,"img":false}]}
{"op":"mcm","clk":"5353330391","pt":1646213105960,"mc":[{"id":"1.195453771","rc":[{"atl":[[7,29.17]],"id":36074638}],"con":true,"img":false}]}
{"op":"mcm","clk":"5353330401","pt":1646213106070,"mc":[{"id":"1.195453771","rc":[{"atl":[[6.2,11.37],[6.6,8.93],[7,12.49]],"id":36074638}],"con":true,"img":false}]}
{"op":"mcm","clk":"5353330996","pt":1646213115766,"mc":[{"id":"1.195453771","rc":[{"atl":[[6.4,0]],"id":36074638}],"con":true,"img":false}]}
{"op":"mcm","clk":"5353331002","pt":1646213115870,"mc":[{"id":"1.195453771","rc":[{"atl":[[6.8,7.51],[7,29.17]],"id":36074638}],"con":true,"img":false}]}
{"op":"mcm","clk":"5353331007","pt":1646213115973,"mc":[{"id":"1.195453771","rc":[{"atl":[[6.2,3.85]],"id":36074638}],"con":true,"img":false}]}
{"op":"mcm","clk":"5353331851","pt":1646213130040,"mc":[{"id":"1.195453771","rc":[{"atl":[[6.6,17.86],[7,12.49]],"id":36074638}],"con":true,"img":false}]}
{"op":"mcm","clk":"5353333079","pt":1646213150795,"mc":[{"id":"1.195453771","rc":[{"atl":[[6.8,0]],"id":36074638}],"con":true,"img":false}]}
{"op":"mcm","clk":"5353333083","pt":1646213150898,"mc":[{"id":"1.195453771","rc":[{"atl":[[6.4,7.51]],"id":36074638}],"con":true,"img":false}]}
{"op":"mcm","clk":"5353333087","pt":1646213151002,"mc":[{"id":"1.195453771","rc":[{"atl":[[6.6,8.93],[7,29.17]],"id":36074638}],"con":true,"img":false}]}
{"op":"mcm","clk":"5353333093","pt":1646213151105,"mc":[{"id":"1.195453771","rc":[{"atl":[[6.2,11.37],[7,12.49]],"id":36074638}],"con":true,"img":false}]}
{"op":"mcm","clk":"5353333683","pt":1646213160820,"mc":[{"id":"1.195453771","rc":[{"atl":[[6.4,0]],"id":36074638}],"con":true,"img":false}]}
{"op":"mcm","clk":"5353333688","pt":1646213160924,"mc":[{"id":"1.195453771","rc":[{"atl":[[6.8,7.51]],"id":36074638}],"con":true,"img":false}]}
{"op":"mcm","clk":"5353333698","pt":1646213160978,"mc":[{"id":"1.195453771","rc":[{"atl":[[6.2,3.85],[7,29.17]],"id":36074638}],"con":true,"img":false}]}
{"op":"mcm","clk":"5353334476","pt":1646213174714,"mc":[{"id":"1.195453771","rc":[{"atl":[[6.6,17.86]],"id":36074638}],"con":true,"img":false}]}
{"op":"mcm","clk":"5353334482","pt":1646213174817,"mc":[{"id":"1.195453771","rc":[{"atl":[[7,12.49]],"id":36074638}],"con":true,"img":false}]}
{"op":"mcm","clk":"5353335547","pt":1646213195822,"mc":[{"id":"1.195453771","rc":[{"atl":[[6.8,0]],"id":36074638}],"con":true,"img":false}]}
{"op":"mcm","clk":"5353335556","pt":1646213195927,"mc":[{"id":"1.195453771","rc":[{"atl":[[6.4,7.51]],"id":36074638}],"con":true,"img":false}]}
{"op":"mcm","clk":"5353337184","pt":1646213224468,"mc":[{"id":"1.195453771","rc":[{"atb":[[1.28,0],[1.26,0],[1.3,0],[1.29,164.04],[1.24,0]],"id":37127725},{"atl":[[2.36,0],[2.4,0],[2.32,0],[2.9,0],[2.44,8.4]],"id":37127725},{"spn":1.82,"spf":"NaN","id":37127725}],"con":true,"img":false}]}
{"op":"mcm","clk":"5353337189","pt":1646213224574,"mc":[{"id":"1.195453771","rc":[{"atb":[[2.82,0],[3.2,0],[3.4,3.13],[3.5,3.33],[3.3,0]],"id":39784543},{"atl":[[11,0],[12,3.11],[13,0],[14,0]],"id":39784543},{"atb":[[2,0],[1.98,0],[1.89,0],[1.96,0],[1.94,0]],"id":36500377},{"atl":[[7.2,0],[6.4,0],[6.2,8.07],[6,0],[6.8,0]],"id":36500377},{"atb":[[1.03,0],[1.09,1344.3],[1.07,0],[1.05,0]],"id":42189401},{"atl":[[1.84,0],[1.88,0],[1.9,0],[2.46,0],[1.86,0]],"id":42189401},{"atb":[[1.28,0],[1.26,0],[1.3,201.64],[1.24,0]],"id":26051221},{"atl":[[2.24,0],[2.32,0],[2.28,0],[3.4,0],[2.2,0]],"id":26051221}],"con":true,"img":false}]}
{"op":"mcm","clk":"5353337194","pt":1646213224678,"mc":[{"id":"1.195453771","rc":[{"atb":[[2.88,0],[3.15,0],[2.98,0],[2.94,0],[3.05,4.06]],"id":35801684},{"atl":[[260,0],[280,0],[50,0],[220,0],[240,0]],"id":35801684},{"atb":[[2.92,21.79],[2.88,0],[2.12,0],[2.84,0],[2.96,0]],"id":36074638},{"atl":[[6.2,0],[7.4,0],[6.6,0],[7,0]],"id":36074638},{"atb":[[1.99,0],[2.02,0],[2.06,0],[1.98,0],[1.97,0]],"id":28338255},{"atl":[[4.3,0],[3.85,0],[5.8,0],[3.95,0],[4.1,0]],"id":28338255}],"con":true,"img":false}]}
{"op":"mcm","clk":"5353337258","pt":1646213225769,"mc":[{"id":"1.195453771","rc":[{"atb":[[3.25,0]],"id":39784543},{"atl":[[12.5,0]],"id":39784543},{"atl":[[6.2,0]],"id":36500377},{"atb":[[3,0]],"id":35801684},{"atl":[[6.4,0]],"id":36074638},{"atl":[[1.85,0]],"id":42189401},{"atb":[[2.04,0]],"id":28338255},{"atl":[[4,0]],"id":28338255},{"atl":[[2.22,0]],"id":26051221},{"atb":[[1.29,0],[1.31,0]],"id":37127725},{"atl":[[2.34,0]],"id":37127725}],"con":true,"img":false}]}
{"op":"mcm","clk":"5353337262","pt":1646213225871,"mc":[{"id":"1.195453771","rc":[{"atb":[[2.96,18.52]],"id":39784543},{"atl":[[14,3.26]],"id":39784543},{"atl":[[8.2,8.07]],"id":36500377},{"atb":[[2.84,23.69]],"id":35801684},{"atl":[[8.8,7.51]],"id":36074638},{"atl":[[2.1,31.59]],"id":42189401},{"atb":[[1.83,44.04]],"id":28338255},{"atl":[[4.9,13.62]],"id":28338255},{"atb":[[1.26,164.04],[1.29,85.42]],"id":37127725},{"atl":[[2.5,26.26]],"id":37127725},{"atl":[[2.48,34.6]],"id":26051221}],"con":true,"img":false}]}
{"op":"mcm","clk":"5353337315","pt":1646213226905,"mc":[{"id":"1.195453771","rc":[{"atb":[[3.4,0]],"id":39784543},{"atb":[[3.1,0]],"id":35801684},{"atb":[[2.98,4.2]],"id":36074638},{"atb":[[2.08,7.71]],"id":28338255}],"con":true,"img":false}]}
{"op":"mcm","clk":"5353337474","pt":1646213229980,"mc":[{"id":"1.195453771","rc":[{"atb":[[3.2,0]],"id":35801684}],"con":true,"img":false}]}
{"op":"mcm","clk":"5353337481","pt":1646213230186,"mc":[{"id":"1.195453771","rc":[{"atb":[[3.1,1.66]],"id":35801684}],"con":true,"img":false}]}
{"op":"mcm","clk":"5353337737","pt":1646213234888,"mc":[{"id":"1.195453771","rc":[{"atb":[[3,3.75]],"id":39784543},{"atb":[[2.76,4.27]],"id":35801684},{"atb":[[2.96,3.83]],"id":36074638},{"atb":[[1.87,8.63]],"id":28338255}],"con":true,"img":false}]}
{"op":"mcm","clk":"5353338035","pt":1646213239390,"mc":[{"id":"1.195453771","rc":[{"atb":[[3.5,0]],"id":39784543},{"atb":[[3.05,0]],"id":35801684},{"atb":[[2.98,0]],"id":36074638},{"atb":[[2.08,0]],"id":28338255}],"con":true,"img":false}]}
{"op":"mcm","clk":"5353338326","pt":1646213243911,"mc":[{"id":"1.195453771","rc":[{"atb":[[3.55,0]],"id":39784543},{"atb":[[3.1,0]],"id":35801684},{"atb":[[3,0]],"id":36074638},{"atb":[[2.1,0]],"id":28338255}],"con":true,"img":false}]}
{"op":"mcm","clk":"5353338335","pt":1646213244017,"mc":[{"id":"1.195453771","rc":[{"atb":[[3.5,1.66]],"id":39784543},{"atb":[[2.86,1.66]],"id":35801684},{"atb":[[2.98,1.66]],"id":36074638}],"con":true,"img":false}]}
{"op":"mcm","clk":"5353339249","pt":1646213260828,"mc":[{"id":"1.195453771","rc":[{"atl":[[9.2,0]],"id":36500377},{"atl":[[10,0]],"id":36074638},{"atl":[[2.3,0]],"id":42189401},{"atl":[[4.9,0]],"id":28338255},{"atl":[[2.74,0]],"id":37127725}],"con":true,"img":false}]}
{"op":"mcm","clk":"5353339255","pt":1646213260931,"mc":[{"id":"1.195453771","rc":[{"atl":[[10,5.44]],"id":36500377},{"atl":[[11,4.28]],"id":36074638},{"atl":[[2.44,25.96]],"id":42189401},{"atl":[[2.82,23.43]],"id":37127725},{"atl":[[4.3,13.62]],"id":28338255}],"con":true,"img":false}]}
{"op":"mcm","clk":"5353339544","pt":1646213265850,"mc":[{"id":"1.195453771","rc":[{"atb":[[2.62,0]],"id":35801684},{"atl":[[5.5,0],[5.3,9.48]],"id":28338255}],"con":true,"img":false}]}
{"op":"mcm","clk":"5353339551","pt":1646213265954,"mc":[{"id":"1.195453771","rc":[{"atb":[[2.72,26.7]],"id":35801684}],"con":true,"img":false}]}
{"op":"mcm","clk":"5353339676","pt":1646213267917,"mc":[{"id":"1.195453771","rc":[{"atb":[[2.76,0]],"id":35801684}],"con":true,"img":false}]}
{"op":"mcm","clk":"5353340022","pt":1646213275740,"mc":[{"id":"1.195453771","rc":[{"atl":[[9.2,5.31]],"id":36500377},{"atl":[[10,4.84]],"id":36074638},{"atl":[[2.1,0]],"id":42189401}],"con":true,"img":false}]}
{"op":"mcm","clk":"5353340029","pt":1646213275843,"mc":[{"id":"1.195453771","rc":[{"atl":[[8.2,0]],"id":36500377},{"atl":[[8.8,0]],"id":36074638},{"atl":[[2.26,31.59]],"id":42189401}],"con":true,"img":false}]}
{"op":"mcm","clk":"5353340032","pt":1646213275946,"mc":[{"id":"1.195453771","rc":[{"atl":[[6.2,7.28],[5.5,9.68]],"id":28338255}],"con":true,"img":false}]}
{"op":"mcm","clk":"5353340040","pt":1646213276049,"mc":[{"id":"1.195453771","rc":[{"atl":[[4.3,0],[5.3,0]],"id":28338255}],"con":true,"img":false}]}
{"op":"mcm","clk":"5353340296","pt":1646213280837,"mc":[{"id":"1.195453771","rc":[{"atl":[[14,0]],"id":39784543},{"atl":[[2.48,0]],"id":26051221}],"con":true,"img":false}]}
{"op":"mcm","clk":"5353340303","pt":1646213280943,"mc":[{"id":"1.195453771","rc":[{"atl":[[15,4.99]],"id":39784543},{"atl":[[2.68,34.6]],"id":26051221}],"con":true,"img":false}]}
{"op":"mcm","clk":"5353340534","pt":1646213285842,"mc":[{"id":"1.195453771","rc":[{"atl":[[12,0]],"id":39784543},{"spn":5.75,"spf":"NaN","id":39784543},{"spn":4.69,"spf":"NaN","id":36500377},{"spn":4.73,"spf":"NaN","id":35801684},{"spn":5.39,"spf":"NaN","id":36074638},{"spn":1.74,"spf":"NaN","id":42189401},{"atl":[[2.84,0]],"id":26051221},{"spn":1.93,"spf":"NaN","id":26051221},{"spn":2.53,"spf":"NaN","id":28338255},{"spn":1.86,"spf":"NaN","id":37127725}],"con":true,"img":false}]}
{"op":"mcm","clk":"5353340541","pt":1646213285945,"mc":[{"id":"1.195453771","rc":[{"atl":[[13.5,3.11]],"id":39784543},{"atb":[[1.33,151.52],[1.29,250],[1.31,369.98],[1.35,57.14]],"id":26051221},{"atl":[[2.24,40.32],[2.92,21.57],[2.32,94.7],[2.28,58.59],[2.2,16.67]],"id":26051221}],"con":true,"img":false}]}
{"op":"mcm","clk":"5353340621","pt":1646213287953,"mc":[{"id":"1.195453771","rc":[{"atb":[[2.92,47.83],[2.88,39.89],[2.84,67.93],[2.96,14.03]],"id":36074638},{"atl":[[6.2,3.85],[7.4,19.53],[6.6,8.93],[7,12.5]],"id":36074638}],"con":true,"img":false}]}
{"op":"mcm","clk":"5353340673","pt":1646213288985,"mc":[{"id":"1.195453771","rc":[{"atb":[[2.96,10.2]],"id":36074638}],"con":true,"img":false}]}
{"op":"mcm","clk":"5353340780","pt":1646213290747,"mc":[{"id":"1.195453771","rc":[{"atb":[[2.24,0],[2.52,28.33]],"id":36500377},{"atl":[[10,0],[10.5,4.35]],"id":36500377},{"atb":[[2.72,0]],"id":35801684}],"con":true,"img":false}]}
{"op":"mcm","clk":"5353340785","pt":1646213290848,"mc":[{"id":"1.195453771","rc":[{"atb":[[2.62,26.7]],"id":35801684}],"con":true,"img":false}]}
{"op":"mcm","clk":"5353341050","pt":1646213295859,"mc":[{"id":"1.195453771","rc":[{"atb":[[1.31,241.94]],"id":26051221}],"con":true,"img":false}]}
{"op":"mcm","clk":"5353341054","pt":1646213295962,"mc":[{"id":"1.195453771","rc":[{"atb":[[1.3,329.69]],"id":26051221}],"con":true,"img":false}]}
{"op":"mcm","clk":"5353341243","pt":1646213299388,"mc":[{"id":"1.195453771","rc":[{"atb":[[3.45,0]],"id":39784543},{"atb":[[2.36,0]],"id":36074638}],"con":true,"img":false}]}
{"op":"mcm","clk":"5353341250","pt":1646213299492,"mc":[{"id":"1.195453771","rc":[{"atb":[[3.2,19.81]],"id":39784543},{"atb":[[2.22,28.38]],"id":36074638}],"con":true,"img":false}]}
{"op":"mcm","clk":"5353341286","pt":1646213300163,"mc":[{"id":"1.195453771","rc":[{"atb":[[3.5,0]],"id":39784543}],"con":true,"img":false}]}
{"op":"mcm","clk":"5353341296","pt":1646213300368,"mc":[{"id":"1.195453771","rc":[{"atb":[[3.25,1.66]],"id":39784543}],"con":true,"img":false}]}
{"op":"mcm","clk":"5353341799","pt":1646213310461,"mc":[{"id":"1.195453771","rc":[{"atb":[[3.15,9.3],[2.98,37.88],[2.94,64.43],[3.05,24.39]],"id":35801684},{"atl":[[8,17.86],[7.2,8.06],[6.8,3.45],[7.6,11.36]],"id":35801684}],"con":true,"img":false}]}
{"op":"mcm","clk":"5353341820","pt":1646213310873,"mc":[{"id":"1.195453771","rc":[{"atb":[[1.32,0]],"id":26051221}],"con":true,"img":false}]}
{"op":"mcm","clk":"5353341824","pt":1646213310975,"mc":[{"id":"1.195453771","rc":[{"atb":[[1.36,90.7]],"id":26051221}],"con":true,"img":false}]}
{"op":"mcm","clk":"5353341885","pt":1646213312475,"mc":[{"id":"1.195453771","rc":[{"atb":[[2.9,65.79],[2.98,25.25],[2.94,38.66],[3.05,9.76]],"id":36500377},{"atl":[[6.2,9.62],[6.6,15.54],[7,20.83],[5.9,4.08]],"id":36500377}],"con":true,"img":false}]}
{"op":"mcm","clk":"5353341921","pt":1646213313401,"mc":[{"id":"1.195453771","rc":[{"atb":[[2.76,4.73]],"id":36500377}],"con":true,"img":false}]}
{"op":"mcm","clk":"5353341952","pt":1646213314074,"mc":[{"id":"1.195453771","rc":[{"atb":[[2.78,0]],"id":36500377},{"atb":[[2.86,0]],"id":35801684}],"con":true,"img":false}]}
{"op":"mcm","clk":"5353341958","pt":1646213314175,"mc":[{"id":"1.195453771","rc":[{"atb":[[3.1,1.66]],"id":36500377},{"atb":[[3.2,1.66]],"id":35801684}],"con":true,"img":false}]}
{"op":"mcm","clk":"5353342030","pt":1646213315777,"mc":[{"id":"1.195453771","rc":[{"atl":[[15,1.72]],"id":39784543},{"atl":[[10.5,0]],"id":36500377},{"atb":[[2.62,0]],"id":35801684},{"atl":[[10,0],[6.8,7.51]],"id":36074638},{"atl":[[2.44,0]],"id":42189401},{"atl":[[2.68,0]],"id":26051221},{"atl":[[6.2,0]],"id":28338255},{"atl":[[2.82,0],[2.5,0]],"id":37127725}],"con":true,"img":false}]}
{"op":"mcm","clk":"5353342035","pt":1646213315879,"mc":[{"id":"1.195453771","rc":[{"atl":[[16.5,3.26]],"id":39784543},{"atl":[[11.5,6.66]],"id":36500377},{"atb":[[2.52,26.7]],"id":35801684},{"atl":[[2.62,25.96]],"id":42189401},{"atl":[[3.05,23.43],[2.76,26.26]],"id":37127725},{"atl":[[6.8,15.62]],"id":28338255},{"atl":[[2.22,34.6]],"id":26051221}],"con":true,"img":false}]}
{"op":"mcm","clk":"5353342242","pt":1646213320292,"mc":[{"id":"1.195453771","rc":[{"atb":[[3.05,13.42]],"id":36500377},{"atb":[[3.1,3.57]],"id":35801684},{"atb":[[2.98,5.46]],"id":36074638},{"atb":[[1.39,19.27]],"id":26051221}],"con":true,"img":false}]}
{"op":"mcm","clk":"5353342258","pt":1646213320706,"mc":[{"id":"1.195453771","rc":[{"atb":[[3.2,53.9],[3.1,59.52],[3.4,8.33],[3.3,21.74]],"id":39784543},{"atl":[[7.4,11.72],[6.6,3.57],[7,8.33],[7.8,18.38]],"id":39784543}],"con":true,"img":false}]}
{"op":"mcm","clk":"5353342262","pt":1646213320808,"mc":[{"id":"1.195453771","rc":[{"atb":[[2.22,34.87]],"id":36500377}],"con":true,"img":false}]}
{"op":"mcm","clk":"5353342267","pt":1646213320914,"mc":[{"id":"1.195453771","rc":[{"atb":[[2.52,0]],"id":36500377}],"con":true,"img":false}]}
{"op":"mcm","clk":"5353342277","pt":1646213321222,"mc":[{"id":"1.195453771","rc":[{"atb":[[3.25,0]],"id":39784543}],"con":true,"img":false}]}
{"op":"mcm","clk":"5353342279","pt":1646213321276,"mc":[{"id":"1.195453771","rc":[{"atb":[[3.45,1.66]],"id":39784543}],"con":true,"img":false}]}
{"op":"mcm","clk":"5353342370","pt":1646213323502,"mc":[{"id":"1.195453771","rc":[{"atb":[[3,0]],"id":39784543}],"con":true,"img":false}]}
{"op":"mcm","clk":"5353342456","pt":1646213325819,"mc":[{"id":"1.195453771","rc":[{"atl":[[5.5,0]],"id":28338255}],"con":true,"img":false}]}
{"op":"mcm","clk":"5353342462","pt":1646213325921,"mc":[{"id":"1.195453771","rc":[{"atl":[[6.2,9.68]],"id":28338255}],"con":true,"img":false}]}
{"op":"mcm","clk":"5353342625","pt":1646213330826,"mc":[{"id":"1.195453771","rc":[{"atb":[[2.96,0],[2.76,23.43]],"id":39784543}],"con":true,"img":false}]}
{"op":"mcm","clk":"5353342651","pt":1646213331293,"mc":[{"id":"1.195453771","rc":[{"atb":[[3.4,11.46]],"id":39784543}],"con":true,"img":false}]}
{"op":"mcm","clk":"5353342656","pt":1646213331398,"mc":[{"id":"1.195453771","rc":[{"atb":[[2.98,9.67]],"id":36074638}],"con":true,"img":false}]}
{"op":"mcm","clk":"5353342666","pt":1646213331601,"mc":[{"id":"1.195453771","rc":[{"atb":[[3.05,28.45]],"id":35801684}],"con":true,"img":false}]}
{"op":"mcm","clk":"5353342683","pt":1646213332015,"mc":[{"id":"1.195453771","rc":[{"atb":[[2.76,0]],"id":36500377}],"con":true,"img":false}]}
{"op":"mcm","clk":"5353342736","pt":1646213332995,"mc":[{"id":"1.195453771","rc":[{"atb":[[1.39,40.65]],"id":26051221}],"con":true,"img":false}]}
{"op":"mcm","clk":"5353342742","pt":1646213333098,"mc":[{"id":"1.195453771","rc":[{"atb":[[1.87,18.21]],"id":28338255}],"con":true,"img":false}]}
{"op":"mcm","clk":"5353342849","pt":1646213335843,"mc":[{"id":"1.195453771","rc":[{"atb":[[2.84,0]],"id":35801684},{"atl":[[7.4,6.81]],"id":35801684},{"atb":[[1.83,0]],"id":28338255}],"con":true,"img":false}]}
{"op":"mcm","clk":"5353342855","pt":1646213335898,"mc":[{"id":"1.195453771","rc":[{"atb":[[3,23.69]],"id":35801684},{"atl":[[18,0]],"id":35801684},{"atb":[[2.06,44.04]],"id":28338255}],"con":true,"img":false}]}
{"op":"mcm","clk":"5353342870","pt":1646213336310,"mc":[{"id":"1.195453771","rc":[{"atb":[[1.2,452.55],[1.26,76.92],[1.22,250],[1.24,208.33]],"id":42189401},{"atl":[[1.84,23.81],[1.88,85.23],[1.9,138.89],[1.86,58.14]],"id":42189401}],"con":true,"img":false}]}
{"op":"mcm","clk":"5353342912","pt":1646213337445,"mc":[{"id":"1.195453771","rc":[{"atb":[[1.87,9.57]],"id":28338255}],"con":true,"img":false}]}
{"op":"mcm","clk":"5353343068","pt":1646213340807,"mc":[{"id":"1.195453771","rc":[{"atb":[[2.44,28.88],[2.76,0]],"id":39784543},{"atb":[[2.72,0]],"id":36500377}],"con":true,"img":false}]}
{"op":"mcm","clk":"5353343071","pt":1646213340909,"mc":[{"id":"1.195453771","rc":[{"atb":[[3,23.69]],"id":36500377}],"con":true,"img":false}]}
{"op":"mcm","clk":"5353343121","pt":1646213342152,"mc":[{"id":"1.195453771","rc":[{"atb":[[2.08,1.66]],"id":28338255}],"con":true,"img":false}]}
{"op":"mcm","clk":"5353343161","pt":1646213343035,"mc":[{"id":"1.195453771","rc":[{"atb":[[1.99,75.76],[2.02,49.02],[2.06,62.91],[1.97,128.87]],"id":28338255},{"atl":[[4.3,37.88],[3.85,7.02],[3.95,16.95],[4.1,24.19]],"id":28338255}],"con":true,"img":false}]}
{"op":"mcm","clk":"5353343178","pt":1646213343456,"mc":[{"id":"1.195453771","rc":[{"atb":[[2.1,6.83]],"id":28338255}],"con":true,"img":false}]}
{"op":"mcm","clk":"5353343222","pt":1646213344441,"mc":[{"id":"1.195453771","rc":[{"atb":[[1.28,178.57],[1.26,414.04],[1.3,66.67],[1.24,250]],"id":37127725},{"atl":[[1.99,20.2],[2.02,49.02],[2.06,70.75],[2.1,113.64]],"id":37127725}],"con":true,"img":false}]}
{"op":"mcm","clk":"5353343281","pt":1646213345739,"mc":[{"id":"1.195453771","rc":[{"atl":[[6.4,8.07],[9.2,0]],"id":36500377}],"con":true,"img":false}]}
{"op":"mcm","clk":"5353343316","pt":1646213346621,"mc":[{"id":"1.195453771","rc":[{"atb":[[3.25,3.7]],"id":39784543},{"spn":5.02,"spf":"NaN","id":39784543},{"spn":4.5,"spf":"NaN","id":36500377},{"spn":4.9,"spf":"NaN","id":35801684},{"spn":4.59,"spf":"NaN","id":36074638},{"spn":1.55,"spf":"NaN","id":42189401},{"spn":1.64,"spf":"NaN","id":37127725},{"spn":2.65,"spf":"NaN","id":28338255},{"spn":1.79,"spf":"NaN","id":26051221}],"con":true,"img":false}]}
{"op":"mcm","clk":"5353343324","pt":1646213346825,"mc":[{"id":"1.195453771","rc":[{"atb":[[3,27.86]],"id":36500377}],"con":true,"img":false}]}
{"op":"mcm","clk":"5353343449","pt":1646213349150,"mc":[{"id":"1.195453771","rc":[{"atb":[[2.08,0]],"id":28338255}],"con":true,"img":false}]}
{"op":"mcm","clk":"5353343473","pt":1646213349356,"mc":[{"id":"1.195453771","rc":[{"atb":[[2.12,1.66]],"id":28338255}],"con":true,"img":false}]}
{"op":"mcm","clk":"5353343551","pt":1646213350751,"mc":[{"id":"1.195453771","rc":[{"atl":[[7.6,6.6]],"id":39784543},{"atb":[[3,4.16]],"id":36500377},{"atl":[[7.4,0]],"id":35801684},{"atl":[[6.8,0]],"id":36074638},{"atb":[[2.06,18.87]],"id":28338255},{"atb":[[1.3,201.64]],"id":26051221}],"con":true,"img":false}]}
{"op":"mcm","clk":"5353343554","pt":1646213350855,"mc":[{"id":"1.195453771","rc":[{"atl":[[13.5,0]],"id":39784543},{"atb":[[2.96,23.69]],"id":36500377},{"atl":[[7.8,6.81]],"id":35801684},{"atl":[[7.2,7.51]],"id":36074638},{"atb":[[2.04,44.04]],"id":28338255},{"atb":[[1.34,128.04]],"id":26051221}],"con":true,"img":false}]}
{"op":"mcm","clk":"5353343642","pt":1646213352458,"mc":[{"id":"1.195453771","rc":[{"atb":[[2.1,0]],"id":28338255}],"con":true,"img":false}]}
{"op":"mcm","clk":"5353343721","pt":1646213353662,"mc":[{"id":"1.195453771","rc":[{"atb":[[3.4,3.13],[3.5,8]],"id":39784543},{"atl":[[6.6,0],[7,3.33]],"id":39784543},{"atl":[[6,4],[5.9,0]],"id":36500377},{"atb":[[1.33,0],[1.3,268.31],[1.35,0]],"id":26051221}],"con":true,"img":false}]}
{"op":"mcm","clk":"5353343772","pt":1646213354856,"mc":[{"id":"1.195453771","rc":[{"atb":[[3,14.16],[3.05,3.66]],"id":36500377},{"atb":[[3.1,9.52],[2.96,0]],"id":36074638},{"atl":[[1.82,24.39],[1.84,0]],"id":42189401},{"atb":[[1.31,0]],"id":26051221},{"atl":[[2.24,16.13],[2.2,0]],"id":26051221},{"atl":[[3.85,0],[3.75,7.27]],"id":28338255},{"atl":[[1.99,0],[1.97,20.62]],"id":37127725}],"con":true,"img":false}]}
{"op":"mcm","clk":"5353343788","pt":1646213355156,"mc":[{"id":"1.195453771","rc":[{"atb":[[2.84,0]],"id":36074638}],"con":true,"img":false}]}
{"op":"mcm","clk":"5353343826","pt":1646213355731,"mc":[{"id":"1.195453771","rc":[{"atl":[[20,0],[9.8,4.9]],"id":35801684}],"con":true,"img":false}]}
{"op":"mcm","clk":"5353343855","pt":1646213356244,"mc":[{"id":"1.195453771","rc":[{"atb":[[3.45,0]],"id":39784543},{"atb":[[2.98,8]],"id":36074638},{"atb":[[2.12,0]],"id":28338255}],"con":true,"img":false}]}
{"op":"mcm","clk":"5353343867","pt":1646213356452,"mc":[{"id":"1.195453771","rc":[{"atb":[[3.55,1.66]],"id":39784543},{"atb":[[3.15,1.66]],"id":36074638},{"atb":[[2.08,1.66]],"id":28338255}],"con":true,"img":false}]}
{"op":"mcm","clk":"5353343952","pt":1646213358362,"mc":[{"id":"1.195453771","rc":[{"atb":[[2.08,8.62]],"id":28338255}],"con":true,"img":false}]}
{"op":"mcm","clk":"5353344009","pt":1646213359553,"mc":[{"id":"1.195453771","rc":[{"atb":[[1.87,0]],"id":28338255}],"con":true,"img":false}]}
{"op":"mcm","clk":"5353344081","pt":1646213360740,"mc":[{"id":"1.195453771","rc":[{"atl":[[9.2,5.44],[11.5,2.3]],"id":36500377}],"con":true,"img":false}]}
{"op":"mcm","clk":"5353344086","pt":1646213360842,"mc":[{"id":"1.195453771","rc":[{"atb":[[1.23,0]],"id":42189401},{"atl":[[2.22,0]],"id":26051221}],"con":true,"img":false}]}
{"op":"mcm","clk":"5353344090","pt":1646213360945,"mc":[{"id":"1.195453771","rc":[{"atb":[[1.25,91.67]],"id":42189401},{"atl":[[2.26,34.6]],"id":26051221}],"con":true,"img":false}]}
{"op":"mcm","clk":"5353344214","pt":1646213363646,"mc":[{"id":"1.195453771","rc":[{"atb":[[3.4,23.96]],"id":39784543},{"atl":[[7.4,7.81]],"id":39784543}],"con":true,"img":false}]}
{"op":"mcm","clk":"5353344276","pt":1646213364885,"mc":[{"id":"1.195453771","rc":[{"atb":[[2.96,49.2]],"id":36500377},{"atl":[[6.4,17.33]],"id":36500377},{"atb":[[3,25]],"id":36074638},{"atl":[[1.84,59.52]],"id":42189401},{"atb":[[1.28,178.57]],"id":26051221},{"atl":[[2.28,39.06]],"id":26051221},{"atl":[[3.85,17.54]],"id":28338255},{"atl":[[1.99,50.51]],"id":37127725}],"con":true,"img":false}]}
{"op":"mcm","clk":"5353344304","pt":1646213365865,"mc":[{"id":"1.195453771","rc":[{"atl":[[2.26,0]],"id":42189401},{"atb":[[1.29,0]],"id":37127725}],"con":true,"img":false}]}
{"op":"mcm","clk":"5353344308","pt":1646213365966,"mc":[{"id":"1.195453771","rc":[{"atl":[[1.85,31.59]],"id":42189401},{"atb":[[1.31,85.42]],"id":37127725}],"con":true,"img":false}]}
{"op":"mcm","clk":"5353344386","pt":1646213367568,"mc":[{"id":"1.195453771","rc":[{"atb":[[2.98,4.2]],"id":36074638}],"con":true,"img":false}]}
{"op":"mcm","clk":"5353344551","pt":1646213370771,"mc":[{"id":"1.195453771","rc":[{"atl":[[16.5,0],[10.5,4.35]],"id":39784543},{"atb":[[2.72,25.06],[2.22,0],[2.96,25.51]],"id":36500377},{"atb":[[2.52,0]],"id":35801684},{"atl":[[1.98,43.59],[2.76,0]],"id":37127725},{"atl":[[4,14.53],[6.2,0]],"id":28338255}],"con":true,"img":false}]}
{"op":"mcm","clk":"5353344556","pt":1646213370876,"mc":[{"id":"1.195453771","rc":[{"atb":[[3,37.86]],"id":36500377},{"atb":[[2.72,26.7]],"id":35801684}],"con":true,"img":false}]}
{"op":"mcm","clk":"5353344649","pt":1646213373102,"mc":[{"id":"1.195453771","rc":[{"atb":[[3.1,0]],"id":39784543},{"atb":[[3,27.86],[3.05,13.42]],"id":36500377},{"atl":[[6.2,0],[6.6,2.15],[7,0]],"id":36500377},{"atb":[[3.1,0],[2.96,10.2]],"id":36074638},{"atl":[[1.82,0],[1.84,23.81],[1.9,0]],"id":42189401},{"atl":[[4.3,0],[3.85,7.02],[3.75,0]],"id":28338255},{"atl":[[1.99,20.2],[1.97,0],[2.1,0]],"id":37127725},{"atl":[[2.2,16.67]],"id":26051221}],"con":true,"img":false}]}
{"op":"mcm","clk":"5353344667","pt":1646213373363,"mc":[{"id":"1.195453771","rc":[{"atb":[[2.96,0]],"id":36500377},{"atb":[[3,0],[3.05,3.66]],"id":36074638}],"con":true,"img":false}]}
{"op":"mcm","clk":"5353344683","pt":1646213373675,"mc":[{"id":"1.195453771","rc":[{"atb":[[3.3,32.61]],"id":39784543},{"atl":[[7.8,11.03]],"id":39784543}],"con":true,"img":false}]}
{"op":"mcm","clk":"5353344703","pt":1646213373987,"mc":[{"id":"1.195453771","rc":[{"atb":[[2.08,16.34]],"id":28338255}],"con":true,"img":false}]}
{"op":"mcm","clk":"5353344723","pt":1646213374399,"mc":[{"id":"1.195453771","rc":[{"atb":[[2.92,67.94]],"id":36074638}],"con":true,"img":false}]}
{"op":"mcm","clk":"5353344726","pt":1646213374503,"mc":[{"id":"1.195453771","rc":[{"atb":[[2.22,0]],"id":36074638},{"atb":[[1.36,0],[1.34,0]],"id":26051221}],"con":true,"img":false}]}
{"op":"mcm","clk":"5353344731","pt":1646213374557,"mc":[{"id":"1.195453771","rc":[{"atb":[[1.32,90.7],[1.31,128.04]],"id":26051221}],"con":true,"img":false}]}
{"op":"mcm","clk":"5353344789","pt":1646213375796,"mc":[{"id":"1.195453771","rc":[{"atl":[[6.4,9.26]],"id":36500377},{"atl":[[7.8,0]],"id":35801684},{"atb":[[1.2,250]],"id":42189401}],"con":true,"img":false}]}
{"op":"mcm","clk":"5353344795","pt":1646213375900,"mc":[{"id":"1.195453771","rc":[{"atl":[[7.8,8.07]],"id":36500377},{"atl":[[7.4,6.81]],"id":35801684},{"atb":[[1.23,202.55]],"id":42189401}],"con":true,"img":false}]}
{"op":"mcm","clk":"5353344820","pt":1646213376467,"mc":[{"id":"1.195453771","rc":[{"atb":[[3.05,0]],"id":36074638},{"atb":[[1.39,21.37]],"id":26051221}],"con":true,"img":false}]}
{"op":"mcm","clk":"5353344847","pt":1646213377193,"mc":[{"id":"1.195453771","rc":[{"atb":[[3.15,0]],"id":36074638}],"con":true,"img":false}]}
{"op":"mcm","clk":"5353344860","pt":1646213377402,"mc":[{"id":"1.195453771","rc":[{"atb":[[3,1.66]],"id":36074638}],"con":true,"img":false}]}
{"op":"mcm","clk":"5353345032","pt":1646213380872,"mc":[{"id":"1.195453771","rc":[{"atb":[[3.2,34.09]],"id":39784543},{"atl":[[7.2,0]],"id":36074638},{"atb":[[1.26,250]],"id":37127725}],"con":true,"img":false}]}
{"op":"mcm","clk":"5353345037","pt":1646213380975,"mc":[{"id":"1.195453771","rc":[{"atb":[[3.45,19.81]],"id":39784543},{"atl":[[6.8,7.51]],"id":36074638},{"atb":[[1.29,164.04]],"id":37127725}],"con":true,"img":false}]}
{"op":"mcm","clk":"5353345107","pt":1646213382479,"mc":[{"id":"1.195453771","rc":[{"atb":[[2.98,8]],"id":36074638}],"con":true,"img":false}]}
{"op":"mcm","clk":"5353345136","pt":1646213383078,"mc":[{"id":"1.195453771","rc":[{"atl":[[6.8,12.93]],"id":36500377},{"atb":[[2.84,67.93]],"id":36074638},{"atl":[[1.9,138.89]],"id":42189401},{"atl":[[2.1,113.64]],"id":37127725},{"atb":[[1.26,250]],"id":26051221},{"atl":[[2.24,40.32]],"id":26051221},{"atl":[[4.3,37.88]],"id":28338255}],"con":true,"img":false}]}
{"op":"mcm","clk":"5353345163","pt":1646213383699,"mc":[{"id":"1.195453771","rc":[{"atb":[[3.2,56.82]],"id":39784543},{"atl":[[8.2,17.36]],"id":39784543}],"con":true,"img":false}]}
{"op":"mcm","clk":"5353345266","pt":1646213385771,"mc":[{"id":"1.195453771","rc":[{"atb":[[2.96,21.25]],"id":39784543},{"atl":[[2.62,0]],"id":42189401},{"atl":[[1.98,0]],"id":37127725}],"con":true,"img":false}]}
{"op":"mcm","clk":"5353345269","pt":1646213385875,"mc":[{"id":"1.195453771","rc":[{"atb":[[2.44,0]],"id":39784543},{"atl":[[2.3,25.96]],"id":42189401},{"atl":[[2,43.59]],"id":37127725}],"con":true,"img":false}]}
{"op":"mcm","clk":"5353345452","pt":1646213389591,"mc":[{"id":"1.195453771","rc":[{"atb":[[3.25,0]],"id":39784543}],"con":true,"img":false}]}
{"op":"mcm","clk":"5353345500","pt":1646213390784,"mc":[{"id":"1.195453771","rc":[{"atl":[[2.44,37.83],[3.05,0]],"id":37127725},{"atl":[[2.26,0]],"id":26051221},{"atl":[[5.3,9.48],[6.8,8.34]],"id":28338255}],"con":true,"img":false}]}
{"op":"mcm","clk":"5353345507","pt":1646213390887,"mc":[{"id":"1.195453771","rc":[{"atl":[[2.3,34.6]],"id":26051221}],"con":true,"img":false}]}
{"op":"mcm","clk":"5353345597","pt":1646213393119,"mc":[{"id":"1.195453771","rc":[{"atl":[[7.2,20.16]],"id":36500377},{"atb":[[1.24,250]],"id":26051221},{"atl":[[2.28,58.59]],"id":26051221}],"con":true,"img":false}]}
{"op":"mcm","clk":"5353346068","pt":1646213401999,"mc":[{"id":"1.195453771","rc":[{"atb":[[3.5,11.33]],"id":39784543}],"con":true,"img":false}]}
{"op":"mcm","clk":"5353346076","pt":1646213402104,"mc":[{"id":"1.195453771","rc":[{"atb":[[1.39,0]],"id":26051221}],"con":true,"img":false}]}
{"op":"mcm","clk":"5353346086","pt":1646213402305,"mc":[{"id":"1.195453771","rc":[{"atb":[[1.29,0]],"id":26051221}],"con":true,"img":false}]}
{"op":"mcm","clk":"5353346365","pt":1646213405803,"mc":[{"id":"1.195453771","rc":[{"atb":[[2.96,0]],"id":39784543},{"atb":[[2.72,0]],"id":36500377},{"atb":[[2.72,0]],"id":35801684}],"con":true,"img":false}]}
{"op":"mcm","clk":"5353346372","pt":1646213405906,"mc":[{"id":"1.195453771","rc":[{"atb":[[2.86,21.25]],"id":39784543},{"atb":[[2.62,25.06]],"id":36500377},{"atb":[[2.62,26.7]],"id":35801684}],"con":true,"img":false}]}
{"op":"mcm","clk":"5353346478","pt":1646213407513,"mc":[{"id":"1.195453771","rc":[{"spn":5.27,"spf":"NaN","id":39784543},{"atb":[[3,37.86],[3.05,3.66]],"id":36500377},{"spn":4.55,"spf":"NaN","id":36500377},{"atl":[[6.2,3.85],[6.8,0]],"id":35801684},{"spn":4.7,"spf":"NaN","id":35801684},{"atb":[[2.88,10.64],[2.96,0]],"id":36074638},{"spn":4.6,"spf":"NaN","id":36074638},{"atl":[[2.06,18.87],[1.84,0]],"id":42189401},{"spn":1.55,"spf":"NaN","id":42189401},{"atl":[[2.24,16.13],[2.2,0]],"id":26051221},{"spn":1.78,"spf":"NaN","id":26051221},{"atl":[[3.85,0],[3.55,7.84]],"id":28338255},{"spn":2.64,"spf":"NaN","id":28338255},{"atl":[[1.99,0],[2.1,18.18]],"id":37127725},{"spn":1.65,"spf":"NaN","id":37127725}],"con":true,"img":false}]}
{"op":"mcm","clk":"5353346486","pt":1646213407718,"mc":[{"id":"1.195453771","rc":[{"atb":[[2.92,41.9]],"id":36074638},{"atl":[[2.02,0]],"id":37127725}],"con":true,"img":false}]}
{"op":"mcm","clk":"5353346523","pt":1646213408336,"mc":[{"id":"1.195453771","rc":[{"atl":[[1.86,0]],"id":42189401},{"atl":[[2.06,0]],"id":37127725}],"con":true,"img":false}]}
{"op":"mcm","clk":"5353346630","pt":1646213410817,"mc":[{"id":"1.195453771","rc":[{"atb":[[3,14.16]],"id":36500377},{"atb":[[2.92,21.79]],"id":36074638},{"atl":[[2,0],[2.52,28.68],[2.44,8.4],[2.84,36.58]],"id":37127725}],"con":true,"img":false}]}
{"op":"mcm","clk":"5353346635","pt":1646213410921,"mc":[{"id":"1.195453771","rc":[{"atb":[[2.96,23.69]],"id":36500377},{"atb":[[2.82,20.1]],"id":36074638}],"con":true,"img":false}]}
{"op":"mcm","clk":"5353346718","pt":1646213412637,"mc":[{"id":"1.195453771","rc":[{"atl":[[1.88,0]],"id":42189401},{"atl":[[2.12,17.86]],"id":37127725}],"con":true,"img":false}]}
{"op":"mcm","clk":"5353346721","pt":1646213412736,"mc":[{"id":"1.195453771","rc":[{"atl":[[2.1,0]],"id":37127725}],"con":true,"img":false}]}
{"op":"mcm","clk":"5353346779","pt":1646213413823,"mc":[{"id":"1.195453771","rc":[{"atb":[[2.98,4.2]],"id":36074638}],"con":true,"img":false}]}
{"op":"mcm","clk":"5353346910","pt":1646213415841,"mc":[{"id":"1.195453771","rc":[{"atl":[[7.8,0]],"id":36500377},{"atl":[[1.85,0]],"id":42189401},{"atl":[[2.3,0]],"id":26051221}],"con":true,"img":false}]}
{"op":"mcm","clk":"5353346915","pt":1646213415945,"mc":[{"id":"1.195453771","rc":[{"atl":[[6.6,10.22]],"id":36500377},{"atl":[[1.89,31.59]],"id":42189401},{"atl":[[2.26,34.6]],"id":26051221}],"con":true,"img":false}]}
{"op":"mcm","clk":"5353346994","pt":1646213417555,"mc":[{"id":"1.195453771","rc":[{"atb":[[2.96,49.2]],"id":36500377},{"atl":[[6.6,11.08]],"id":35801684},{"atb":[[2.84,27.17]],"id":36074638},{"atl":[[1.9,0],[2.1,45.45]],"id":42189401},{"atl":[[2.28,39.06]],"id":26051221},{"atl":[[3.65,18.87]],"id":28338255}],"con":true,"img":false}]}
{"op":"mcm","clk":"5353347012","pt":1646213417844,"mc":[{"id":"1.195453771","rc":[{"atb":[[2.9,0],[2.98,0],[2.94,0]],"id":36500377},{"atl":[[8,0],[7.2,0],[7.6,0]],"id":35801684},{"atl":[[4.3,0]],"id":28338255}],"con":true,"img":false}]}
{"op":"mcm","clk":"5353347172","pt":1646213420860,"mc":[{"id":"1.195453771","rc":[{"atl":[[10.5,0]],"id":39784543},{"atb":[[2.82,0]],"id":36074638},{"atl":[[2.3,0]],"id":42189401}],"con":true,"img":false}]}
{"op":"mcm","clk":"5353347178","pt":1646213420918,"mc":[{"id":"1.195453771","rc":[{"atl":[[11.5,4.35]],"id":39784543},{"atb":[[2.72,20.1]],"id":36074638},{"atl":[[2.58,25.96]],"id":42189401}],"con":true,"img":false}]}
{"op":"mcm","clk":"5353347216","pt":1646213421643,"mc":[{"id":"1.195453771","rc":[{"atb":[[2.96,3.83]],"id":36074638}],"con":true,"img":false}]}
{"op":"mcm","clk":"5353347273","pt":1646213422629,"mc":[{"id":"1.195453771","rc":[{"atl":[[2.16,43.1]],"id":37127725}],"con":true,"img":false}]}
{"op":"mcm","clk":"5353347295","pt":1646213423048,"mc":[{"id":"1.195453771","rc":[{"atb":[[3,10]],"id":36500377}],"con":true,"img":false}]}
{"op":"mcm","clk":"5353347455","pt":1646213425864,"mc":[{"id":"1.195453771","rc":[{"atl":[[1.89,0]],"id":42189401}],"con":true,"img":false}]}
{"op":"mcm","clk":"5353347459","pt":1646213425958,"mc":[{"id":"1.195453771","rc":[{"atl":[[2.08,31.59]],"id":42189401}],"con":true,"img":false}]}
{"op":"mcm","clk":"5353347531","pt":1646213427567,"mc":[{"id":"1.195453771","rc":[{"atb":[[2.92,39.06]],"id":36500377},{"atl":[[7,12.5]],"id":35801684},{"atb":[[2.8,108.88]],"id":36074638},{"atl":[[2.14,65.79]],"id":42189401},{"atl":[[3.75,27.27]],"id":28338255},{"atl":[[2.32,56.82]],"id":26051221}],"con":true,"img":false}]}
{"op":"mcm","clk":"5353347805","pt":1646213432762,"mc":[{"id":"1.195453771","rc":[{"atl":[[2.2,62.5]],"id":37127725}],"con":true,"img":false}]}
{"op":"mcm","clk":"5353347977","pt":1646213435773,"mc":[{"id":"1.195453771","rc":[{"atl":[[4,0]],"id":28338255}],"con":true,"img":false}]}
{"op":"mcm","clk":"5353347987","pt":1646213435875,"mc":[{"id":"1.195453771","rc":[{"atl":[[3.6,14.53]],"id":28338255}],"con":true,"img":false}]}
{"op":"mcm","clk":"5353347996","pt":1646213435930,"mc":[{"id":"1.195453771","rc":[{"atb":[[3.05,7.73]],"id":36500377}],"con":true,"img":false}]}
{"op":"mcm","clk":"5353348011","pt":1646213436237,"mc":[{"id":"1.195453771","rc":[{"atb":[[2.98,0]],"id":36074638}],"con":true,"img":false}]}
{"op":"mcm","clk":"5353348066","pt":1646213437537,"mc":[{"id":"1.195453771","rc":[{"atb":[[2.88,66.49]],"id":36500377},{"atl":[[7.4,26.34]],"id":35801684},{"atb":[[2.76,71.02]],"id":36074638},{"atl":[[2.18,105.93]],"id":42189401},{"atl":[[3.85,43.86],[4.1,0]],"id":28338255},{"atl":[[2.36,91.91]],"id":26051221}],"con":true,"img":false}]}
{"op":"mcm","clk":"5353348159","pt":1646213440066,"mc":[{"id":"1.195453771","rc":[{"atb":[[3,0]],"id":36074638}],"con":true,"img":false}]}
{"op":"mcm","clk":"5353348165","pt":1646213440170,"mc":[{"id":"1.195453771","rc":[{"atb":[[2.98,1.66]],"id":36074638}],"con":true,"img":false}]}
{"op":"mcm","clk":"5353348277","pt":1646213442658,"mc":[{"id":"1.195453771","rc":[{"atl":[[2.24,100.81]],"id":37127725}],"con":true,"img":false}]}
{"op":"mcm","clk":"5353348460","pt":1646213445844,"mc":[{"id":"1.195453771","rc":[{"atb":[[2.96,25.51]],"id":36500377},{"atl":[[7.4,19.53]],"id":35801684},{"atl":[[3.6,0]],"id":28338255}],"con":true,"img":false}]}
{"op":"mcm","clk":"5353348464","pt":1646213445945,"mc":[{"id":"1.195453771","rc":[{"atb":[[2.94,23.69]],"id":36500377},{"atl":[[6.8,6.81]],"id":35801684},{"atl":[[3.7,19.01]],"id":28338255}],"con":true,"img":false}]}
{"op":"mcm","clk":"5353348541","pt":1646213447549,"mc":[{"id":"1.195453771","rc":[{"atb":[[2.96,8.08]],"id":36074638},{"atl":[[3.95,0]],"id":28338255}],"con":true,"img":false}]}
{"op":"mcm","clk":"5353348694","pt":1646213450864,"mc":[{"id":"1.195453771","rc":[{"atl":[[2.52,0]],"id":37127725}],"con":true,"img":false}]}
{"op":"mcm","clk":"5353348706","pt":1646213451024,"mc":[{"id":"1.195453771","rc":[{"atl":[[2.14,28.68]],"id":37127725}],"con":true,"img":false}]}
{"op":"mcm","clk":"5353349120","pt":1646213458684,"mc":[{"id":"1.195453771","rc":[{"atb":[[3.05,3.66]],"id":36500377}],"con":true,"img":false}]}
{"op":"mcm","clk":"5353349182","pt":1646213460190,"mc":[{"id":"1.195453771","rc":[{"atb":[[1.26,0],[1.24,83.33]],"id":42189401},{"atb":[[1.3,0],[1.29,233.01]],"id":37127725},{"atb":[[2.02,19.61],[2.06,0]],"id":28338255}],"con":true,"img":false}]}
{"op":"mcm","clk":"5353349306","pt":1646213462270,"mc":[{"id":"1.195453771","rc":[{"atl":[[2.12,0],[2.1,18.18]],"id":37127725}],"con":true,"img":false}]}
{"op":"mcm","clk":"5353349481","pt":1646213465784,"mc":[{"id":"1.195453771","rc":[{"atb":[[2.72,0]],"id":36074638},{"atb":[[1.31,0]],"id":37127725},{"atb":[[2.04,0]],"id":28338255}],"con":true,"img":false}]}
{"op":"mcm","clk":"5353349488","pt":1646213465887,"mc":[{"id":"1.195453771","rc":[{"atb":[[2.86,20.1]],"id":36074638},{"atb":[[1.3,85.42]],"id":37127725},{"atb":[[2,44.04]],"id":28338255}],"con":true,"img":false}]}
{"op":"mcm","clk":"5353349651","pt":1646213469092,"mc":[{"id":"1.195453771","rc":[{"spn":4.59,"spf":"NaN","id":36074638},{"spn":1.65,"spf":"NaN","id":42189401},{"atb":[[2.08,9.38]],"id":28338255},{"spn":1.7,"spf":"NaN","id":37127725}],"con":true,"img":false}]}
{"op":"mcm","clk":"5353349704","pt":1646213470182,"mc":[{"id":"1.195453771","rc":[{"atb":[[1.22,227.27]],"id":42189401},{"atb":[[1.99,50.51]],"id":28338255}],"con":true,"img":false}]}
{"op":"mcm","clk":"5353349739","pt":1646213470802,"mc":[{"id":"1.195453771","rc":[{"atb":[[2.94,0]],"id":36500377},{"atl":[[2.84,13.15]],"id":37127725}],"con":true,"img":false}]}
{"op":"mcm","clk":"5353349745","pt":1646213470902,"mc":[{"id":"1.195453771","rc":[{"atb":[[2.98,23.69]],"id":36500377},{"atl":[[2.58,23.43]],"id":37127725}],"con":true,"img":false}]}
{"op":"mcm","clk":"5353349794","pt":1646213471789,"mc":[{"id":"1.195453771","rc":[{"atb":[[2.98,27.9]],"id":36500377}],"con":true,"img":false}]}
{"op":"mcm","clk":"5353349814","pt":1646213472302,"mc":[{"id":"1.195453771","rc":[{"atb":[[1.27,185.19]],"id":37127725}],"con":true,"img":false}]}
{"op":"mcm","clk":"5353349929","pt":1646213474898,"mc":[{"id":"1.195453771","rc":[{"atb":[[2.04,7.23]],"id":28338255}],"con":true,"img":false}]}
{"op":"mcm","clk":"5353350183","pt":1646213480221,"mc":[{"id":"1.195453771","rc":[{"atb":[[1.18,250]],"id":42189401}],"con":true,"img":false}]}
{"op":"mcm","clk":"5353350190","pt":1646213480278,"mc":[{"id":"1.195453771","rc":[{"atb":[[1.97,206.19]],"id":28338255}],"con":true,"img":false}]}
{"op":"mcm","clk":"5353350194","pt":1646213480381,"mc":[{"id":"1.195453771","rc":[{"atb":[[1.97,77.32]],"id":28338255}],"con":true,"img":false}]}
{"op":"mcm","clk":"5353350289","pt":1646213482293,"mc":[{"id":"1.195453771","rc":[{"atb":[[1.28,0],[1.25,491.97],[1.26,0],[1.24,0]],"id":37127725}],"con":true,"img":false}]}
{"op":"mcm","clk":"5353350460","pt":1646213485823,"mc":[{"id":"1.195453771","rc":[{"atb":[[1.29,68.97]],"id":37127725}],"con":true,"img":false}]}
{"op":"mcm","clk":"5353350466","pt":1646213485925,"mc":[{"id":"1.195453771","rc":[{"atb":[[1.28,164.04]],"id":37127725}],"con":true,"img":false}]}
{"op":"mcm","clk":"5353350470","pt":1646213486028,"mc":[{"id":"1.195453771","rc":[{"atb":[[2.08,1.66]],"id":28338255}],"con":true,"img":false}]}
{"op":"mcm","clk":"5353350485","pt":1646213486289,"mc":[{"id":"1.195453771","rc":[{"atb":[[2.06,18.87]],"id":28338255}],"con":true,"img":false}]}
{"op":"mcm","clk":"5353350763","pt":1646213492334,"mc":[{"id":"1.195453771","rc":[{"atb":[[1.23,250]],"id":37127725}],"con":true,"img":false}]}
{"op":"mcm","clk":"5353350772","pt":1646213492493,"mc":[{"id":"1.195453771","rc":[{"atb":[[2.06,0]],"id":28338255}],"con":true,"img":false}]}
{"op":"mcm","clk":"5353350958","pt":1646213496244,"mc":[{"id":"1.195453771","rc":[{"atb":[[2.08,0]],"id":28338255}],"con":true,"img":false}]}
{"op":"mcm","clk":"5353350967","pt":1646213496318,"mc":[{"id":"1.195453771","rc":[{"atb":[[2.06,1.66],[1.95,131.58]],"id":28338255}],"con":true,"img":false}]}
{"op":"mcm","clk":"5353351168","pt":1646213500442,"mc":[{"id":"1.195453771","rc":[{"atb":[[2.04,15.25]],"id":28338255}],"con":true,"img":false}]}
{"op":"mcm","clk":"5353351354","pt":1646213504232,"mc":[{"id":"1.195453771","rc":[{"atb":[[1.26,76.92],[1.24,0]],"id":42189401},{"atb":[[1.3,201.64],[1.29,68.97]],"id":26051221}],"con":true,"img":false}]}
{"op":"mcm","clk":"5353351437","pt":1646213505710,"mc":[{"id":"1.195453771","rc":[{"atb":[[1.26,0],[1.24,83.33]],"id":42189401},{"atb":[[1.3,268.31],[1.29,0]],"id":26051221},{"atb":[[1.3,152.09]],"id":37127725}],"con":true,"img":false}]}
{"op":"mcm","clk":"5353351440","pt":1646213505805,"mc":[{"id":"1.195453771","rc":[{"atb":[[1.29,0]],"id":37127725}],"con":true,"img":false}]}
{"op":"mcm","clk":"5353351521","pt":1646213507642,"mc":[{"id":"1.195453771","rc":[{"atb":[[1.26,76.92],[1.24,0]],"id":42189401},{"atb":[[1.3,201.64],[1.29,68.97]],"id":26051221}],"con":true,"img":false}]}
{"op":"mcm","clk":"5353351529","pt":1646213507742,"mc":[{"id":"1.195453771","rc":[{"atb":[[3,0],[2.98,38]],"id":36500377},{"atl":[[6.4,3.7]],"id":35801684},{"atb":[[2.88,0],[2.86,30.85]],"id":36074638},{"atl":[[3.5,8]],"id":28338255}],"con":true,"img":false}]}
{"op":"mcm","clk":"5353351536","pt":1646213507844,"mc":[{"id":"1.195453771","rc":[{"atl":[[6.2,0]],"id":35801684},{"atl":[[3.55,0]],"id":28338255}],"con":true,"img":false}]}
{"op":"mcm","clk":"5353351628","pt":1646213509859,"mc":[{"id":"1.195453771","rc":[{"atb":[[2.92,52.08]],"id":39784543},{"atl":[[8.2,2.78],[7.4,0],[9.8,11.36],[7,0]],"id":39784543},{"atb":[[2.92,0],[2.88,0],[2.06,73.59],[2.98,27.9],[2.2,16.67],[2.96,0]],"id":36500377},{"atl":[[6.4,19.49]],"id":36500377},{"atb":[[3.2,5.24]],"id":35801684},{"atl":[[11,10]],"id":35801684},{"atb":[[2.26,61.7]],"id":36074638},{"atl":[[6.6,17.86]],"id":36074638},{"atb":[[1.2,0],[1.18,111.11],[1.26,0],[1.22,0],[1.08,500]],"id":42189401},{"atl":[[2.64,57.56]],"id":42189401},{"atb":[[2.06,16.91]],"id":28338255},{"atl":[[4.8,26.32]],"id":28338255},{"atb":[[1.28,0],[1.26,0],[1.29,0],[1.08,250],[1.24,0]],"id":26051221},{"atl":[[3.15,43.14]],"id":26051221},{"atb":[[1.31,164.04]],"id":37127725},{"atl":[[2.72,52.11],[2.54,12.99],[2.1,0],[2.24,0],[2.2,0],[2.16,0]],"id":37127725}],"con":true,"img":false}]}
{"op":"mcm","clk":"5353351671","pt":1646213510823,"mc":[{"id":"1.195453771","rc":[{"atb":[[2.86,10.75]],"id":36074638},{"atb":[[1.25,0],[1.23,0]],"id":42189401},{"atl":[[2.58,0],[2.14,0]],"id":37127725}],"con":true,"img":false}]}
{"op":"mcm","clk":"5353351676","pt":1646213510928,"mc":[{"id":"1.195453771","rc":[{"atb":[[2.82,20.1]],"id":36074638},{"atb":[[1.2,202.55],[1.23,91.67]],"id":42189401},{"atl":[[2.46,28.68],[2.62,23.43]],"id":37127725}],"con":true,"img":false}]}
{"op":"mcm","clk":"5353351944","pt":1646213515847,"mc":[{"id":"1.195453771","rc":[{"atb":[[2.98,4.2]],"id":36500377},{"atb":[[2.82,0]],"id":36074638},{"atl":[[2.62,0]],"id":37127725}],"con":true,"img":false}]}
{"op":"mcm","clk":"5353351948","pt":1646213515948,"mc":[{"id":"1.195453771","rc":[{"atb":[[2.72,23.69]],"id":36500377},{"atb":[[2.78,20.1]],"id":36074638},{"atl":[[2.7,23.43]],"id":37127725}],"con":true,"img":false}]}
{"op":"mcm","clk":"5353352009","pt":1646213517184,"mc":[{"id":"1.195453771","rc":[{"atb":[[3.05,0]],"id":36500377}],"con":true,"img":false}]}
{"op":"mcm","clk":"5353352042","pt":1646213517768,"mc":[{"id":"1.195453771","rc":[{"atl":[[6.8,15.43]],"id":35801684},{"atb":[[2.82,27.47]],"id":36074638}],"con":true,"img":false}]}
{"op":"mcm","clk":"5353352145","pt":1646213519841,"mc":[{"id":"1.195453771","rc":[{"atl":[[8.6,6.58],[7.8,0]],"id":39784543},{"atb":[[2.16,43.1]],"id":36500377},{"atb":[[1.16,250]],"id":42189401},{"atl":[[2.58,31.65]],"id":37127725},{"atb":[[1.06,250]],"id":26051221}],"con":true,"img":false}]}
{"op":"mcm","clk":"5353352192","pt":1646213520827,"mc":[{"id":"1.195453771","rc":[{"atb":[[2.78,0]],"id":36074638}],"con":true,"img":false}]}
{"op":"mcm","clk":"5353352200","pt":1646213520929,"mc":[{"id":"1.195453771","rc":[{"atb":[[2.72,20.1]],"id":36074638}],"con":true,"img":false}]}
{"op":"mcm","clk":"5353352301","pt":1646213522957,"mc":[{"id":"1.195453771","rc":[{"atl":[[7.4,0],[6.6,2.15],[7,0]],"id":35801684},{"atb":[[2.8,67.21],[2.84,0],[2.76,0]],"id":36074638},{"atb":[[1.18,0],[1.16,125]],"id":42189401},{"atl":[[1.44,2]],"id":42189401},{"atb":[[1.12,2],[1.09,222.22]],"id":26051221},{"atl":[[2.84,2]],"id":28338255}],"con":true,"img":false}]}
{"op":"mcm","clk":"5353352315","pt":1646213523163,"mc":[{"id":"1.195453771","rc":[{"atb":[[3.1,0],[2.76,4.27]],"id":36500377},{"atl":[[1.45,2]],"id":42189401},{"atb":[[1.13,2]],"id":26051221},{"atl":[[2.84,0],[2.74,4]],"id":28338255}],"con":true,"img":false}]}
{"op":"mcm","clk":"5353352326","pt":1646213523263,"mc":[{"id":"1.195453771","rc":[{"atb":[[2.92,0],[3,43.79]],"id":39784543}],"con":true,"img":false}]}
{"op":"mcm","clk":"5353352336","pt":1646213523365,"mc":[{"id":"1.195453771","rc":[{"atb":[[3,1.66]],"id":36500377}],"con":true,"img":false}]}
{"op":"mcm","clk":"5353352342","pt":1646213523468,"mc":[{"id":"1.195453771","rc":[{"atl":[[1.45,0],[1.43,2]],"id":42189401},{"atl":[[2.72,3],[2.74,0]],"id":28338255},{"atb":[[1.14,3]],"id":26051221}],"con":true,"img":false}]}
{"op":"mcm","clk":"5353352373","pt":1646213524041,"mc":[{"id":"1.195453771","rc":[{"atb":[[1.15,4]],"id":26051221},{"atl":[[2.72,0],[2.68,2]],"id":28338255}],"con":true,"img":false}]}
{"op":"mcm","clk":"5353352434","pt":1646213525126,"mc":[{"id":"1.195453771","rc":[{"atb":[[2.98,0]],"id":36500377}],"con":true,"img":false}]}
{"op":"mcm","clk":"5353352474","pt":1646213525855,"mc":[{"id":"1.195453771","rc":[{"atl":[[7.6,0]],"id":39784543},{"atl":[[6.8,8.62]],"id":35801684}],"con":true,"img":false}]}
{"op":"mcm","clk":"5353352480","pt":1646213525956,"mc":[{"id":"1.195453771","rc":[{"atl":[[9.6,6.6]],"id":39784543},{"atl":[[8.4,6.81]],"id":35801684}],"con":true,"img":false}]}
{"op":"mcm","clk":"5353352582","pt":1646213527769,"mc":[{"id":"1.195453771","rc":[{"atl":[[7.2,12.1]],"id":35801684},{"atb":[[2.78,42.13]],"id":36074638}],"con":true,"img":false}]}
{"op":"mcm","clk":"5353352663","pt":1646213529176,"mc":[{"id":"1.195453771","rc":[{"spn":5.77,"spf":"NaN","id":39784543},{"atb":[[3,0]],"id":36500377},{"spn":4.38,"spf":"NaN","id":36500377},{"spn":4.8,"spf":"NaN","id":35801684},{"spn":1.33,"spf":"NaN","id":42189401},{"spn":2.37,"spf":"NaN","id":28338255},{"spn":1.87,"spf":"NaN","id":37127725}],"con":true,"img":false}]}
{"op":"mcm","clk":"5353352674","pt":1646213529334,"mc":[{"id":"1.195453771","rc":[{"atb":[[2.78,1.66]],"id":36500377}],"con":true,"img":false}]}
{"op":"mcm","clk":"5353352704","pt":1646213529859,"mc":[{"id":"1.195453771","rc":[{"atl":[[9,9.38]],"id":39784543},{"atb":[[2.12,66.96]],"id":36500377},{"atl":[[2.62,46.3]],"id":37127725}],"con":true,"img":false}]}
{"op":"mcm","clk":"5353352753","pt":1646213530877,"mc":[{"id":"1.195453771","rc":[{"atl":[[6.6,2.15]],"id":36500377},{"atl":[[6.8,0]],"id":36074638},{"atb":[[1.3,66.67]],"id":37127725}],"con":true,"img":false}]}
{"op":"mcm","clk":"5353352759","pt":1646213530981,"mc":[{"id":"1.195453771","rc":[{"atl":[[6.2,8.07]],"id":36500377},{"atl":[[6.4,7.51]],"id":36074638},{"atb":[[1.32,85.42]],"id":37127725}],"con":true,"img":false}]}
{"op":"mcm","clk":"5353352765","pt":1646213531040,"mc":[{"id":"1.195453771","rc":[{"atl":[[6.6,8.93],[7,29.17]],"id":36074638},{"atb":[[1.29,230.71]],"id":37127725}],"con":true,"img":false}]}
{"op":"mcm","clk":"5353352770","pt":1646213531139,"mc":[{"id":"1.195453771","rc":[{"atl":[[6.4,9.26],[6,12.07]],"id":36500377},{"atb":[[1.31,0]],"id":37127725}],"con":true,"img":false}]}
{"op":"mcm","clk":"5353352816","pt":1646213532175,"mc":[{"id":"1.195453771","rc":[{"atl":[[1.42,3]],"id":42189401},{"atl":[[2.66,3]],"id":28338255}],"con":true,"img":false}]}
{"op":"mcm","clk":"5353352829","pt":1646213532380,"mc":[{"id":"1.195453771","rc":[{"atl":[[1.41,3]],"id":42189401},{"atl":[[2.7,2]],"id":28338255}],"con":true,"img":false}]}
{"op":"mcm","clk":"5353352874","pt":1646213532949,"mc":[{"id":"1.195453771","rc":[{"atb":[[1.14,1114.19]],"id":42189401},{"atb":[[1.07,250]],"id":26051221}],"con":true,"img":false}]}
{"op":"mcm","clk":"5353353025","pt":1646213535849,"mc":[{"id":"1.195453771","rc":[{"atl":[[3.7,4.47]],"id":28338255}],"con":true,"img":false}]}
{"op":"mcm","clk":"5353353033","pt":1646213535959,"mc":[{"id":"1.195453771","rc":[{"atl":[[3.6,14.53]],"id":28338255}],"con":true,"img":false}]}
{"op":"mcm","clk":"5353353104","pt":1646213537141,"mc":[{"id":"1.195453771","rc":[{"atb":[[2.76,9]],"id":36500377}],"con":true,"img":false}]}
{"op":"mcm","clk":"5353353136","pt":1646213537760,"mc":[{"id":"1.195453771","rc":[{"atl":[[7.6,18.94]],"id":35801684},{"atb":[[2.74,71.84]],"id":36074638}],"con":true,"img":false}]}
{"op":"mcm","clk":"5353353141","pt":1646213537866,"mc":[{"id":"1.195453771","rc":[{"atl":[[2.64,2]],"id":28338255}],"con":true,"img":false}]}
{"op":"mcm","clk":"5353353156","pt":1646213538076,"mc":[{"id":"1.195453771","rc":[{"atl":[[1.4,4]],"id":42189401},{"atl":[[2.62,3]],"id":28338255}],"con":true,"img":false}]}
{"op":"mcm","clk":"5353353163","pt":1646213538180,"mc":[{"id":"1.195453771","rc":[{"atl":[[1.44,0]],"id":42189401},{"atl":[[2.68,0],[2.7,0]],"id":28338255}],"con":true,"img":false}]}
{"op":"mcm","clk":"5353353252","pt":1646213539882,"mc":[{"id":"1.195453771","rc":[{"atl":[[9.4,14.88]],"id":39784543},{"atb":[[2.08,115.74]],"id":36500377},{"atl":[[2.66,75.3]],"id":37127725}],"con":true,"img":false}]}
{"op":"mcm","clk":"5353353309","pt":1646213540867,"mc":[{"id":"1.195453771","rc":[{"atb":[[1.32,0]],"id":37127725}],"con":true,"img":false}]}
{"op":"mcm","clk":"5353353317","pt":1646213540973,"mc":[{"id":"1.195453771","rc":[{"atb":[[1.31,85.42]],"id":37127725}],"con":true,"img":false}]}
{"op":"mcm","clk":"5353353325","pt":1646213541080,"mc":[{"id":"1.195453771","rc":[{"atb":[[1.32,85.42]],"id":37127725}],"con":true,"img":false}]}
{"op":"mcm","clk":"5353353332","pt":1646213541182,"mc":[{"id":"1.195453771","rc":[{"atl":[[6.2,11.37],[7,12.49]],"id":36074638},{"atb":[[1.29,0]],"id":37127725}],"con":true,"img":false}]}
{"op":"mcm","clk":"5353353395","pt":1646213542374,"mc":[{"id":"1.195453771","rc":[{"atl":[[2.6,3]],"id":28338255}],"con":true,"img":false}]}
{"op":"mcm","clk":"5353353420","pt":1646213542990,"mc":[{"id":"1.195453771","rc":[{"atb":[[1.12,250]],"id":42189401},{"atb":[[1.05,250]],"id":26051221}],"con":true,"img":false}]}
{"op":"mcm","clk":"5353353434","pt":1646213543253,"mc":[{"id":"1.195453771","rc":[{"atb":[[1.08,0],[1.06,0]],"id":26051221}],"con":true,"img":false}]}
{"op":"mcm","clk":"5353353561","pt":1646213545894,"mc":[{"id":"1.195453771","rc":[{"atl":[[6.4,0]],"id":36074638}],"con":true,"img":false}]}
{"op":"mcm","clk":"5353353566","pt":1646213545989,"mc":[{"id":"1.195453771","rc":[{"atl":[[6.8,7.51]],"id":36074638}],"con":true,"img":false}]}
{"op":"mcm","clk":"5353353584","pt":1646213546251,"mc":[{"id":"1.195453771","rc":[{"atl":[[6.2,3.85],[6.6,26.79]],"id":36074638}],"con":true,"img":false}]}
{"op":"mcm","clk":"5353353832","pt":1646213550899,"mc":[{"id":"1.195453771","rc":[{"atb":[[2.86,0]],"id":39784543},{"atl":[[5.3,0]],"id":28338255}],"con":true,"img":false}]}
{"op":"mcm","clk":"5353353836","pt":1646213550959,"mc":[{"id":"1.195453771","rc":[{"atb":[[3.05,21.25]],"id":39784543},{"atl":[[4.7,9.48]],"id":28338255}],"con":true,"img":false}]}
{"op":"mcm","clk":"5353353955","pt":1646213552974,"mc":[{"id":"1.195453771","rc":[{"atb":[[1.1,250]],"id":42189401},{"atb":[[1.03,250]],"id":26051221}],"con":true,"img":false}]}
{"op":"mcm","clk":"5353354104","pt":1646213555770,"mc":[{"id":"1.195453771","rc":[{"atl":[[9.6,0]],"id":39784543},{"atl":[[6.2,0]],"id":36500377},{"atl":[[8.4,0]],"id":35801684},{"atl":[[2.7,0]],"id":37127725}],"con":true,"img":false}]}
{"op":"mcm","clk":"5353354112","pt":1646213555879,"mc":[{"id":"1.195453771","rc":[{"atl":[[8.8,6.6]],"id":39784543},{"atl":[[6.4,27.78],[5.9,8.07]],"id":36500377},{"atl":[[7,6.81]],"id":35801684},{"atl":[[2.56,23.43]],"id":37127725}],"con":true,"img":false}]}
{"op":"mcm","clk":"5353354120","pt":1646213555978,"mc":[{"id":"1.195453771","rc":[{"atl":[[6,4]],"id":36500377}],"con":true,"img":false}]}
{"op":"mcm","clk":"5353354231","pt":1646213557903,"mc":[{"id":"1.195453771","rc":[{"atl":[[2.68,4]],"id":28338255}],"con":true,"img":false}]}
{"op":"mcm","clk":"5353354236","pt":1646213558007,"mc":[{"id":"1.195453771","rc":[{"atl":[[1.43,0],[1.4,0],[1.41,0],[1.42,0]],"id":42189401},{"atl":[[2.6,0],[2.64,0],[2.62,0],[2.66,0]],"id":28338255}],"con":true,"img":false}]}
{"op":"mcm","clk":"5353354245","pt":1646213558213,"mc":[{"id":"1.195453771","rc":[{"atl":[[2.68,0]],"id":28338255}],"con":true,"img":false}]}
{"op":"mcm","clk":"5353354672","pt":1646213565698,"mc":[{"id":"1.195453771","rc":[{"atl":[[6.4,9.26],[5.8,8.07]],"id":36500377}],"con":true,"img":false}]}
{"op":"mcm","clk":"5353354681","pt":1646213565802,"mc":[{"id":"1.195453771","rc":[{"atl":[[5.9,0]],"id":36500377},{"atb":[[2.62,0]],"id":35801684},{"atl":[[6.8,0]],"id":36074638},{"atb":[[1.31,0]],"id":37127725}],"con":true,"img":false}]}
{"op":"mcm","clk":"5353354689","pt":1646213565903,"mc":[{"id":"1.195453771","rc":[{"atl":[[6.2,8.07]],"id":36500377},{"atb":[[2.72,26.7]],"id":35801684},{"atl":[[6.4,7.51]],"id":36074638},{"atb":[[1.33,85.42]],"id":37127725}],"con":true,"img":false}]}
{"op":"mcm","clk":"5353354697","pt":1646213566004,"mc":[{"id":"1.195453771","rc":[{"atl":[[6.6,8.93],[7,29.17]],"id":36074638},{"atb":[[1.32,0],[1.29,185.19]],"id":37127725}],"con":true,"img":false}]}
{"op":"mcm","clk":"5353354993","pt":1646213570926,"mc":[{"id":"1.195453771","rc":[{"atl":[[5.8,0],[6,20.14]],"id":36500377}],"con":true,"img":false}]}
{"op":"mcm","clk":"5353355071","pt":1646213572532,"mc":[{"id":"1.195453771","rc":[{"atb":[[2.72,0]],"id":36074638},{"atb":[[1.23,0]],"id":42189401}],"con":true,"img":false}]}
{"op":"mcm","clk":"5353355076","pt":1646213572585,"mc":[{"id":"1.195453771","rc":[{"atb":[[2.8,87.31]],"id":36074638},{"atb":[[1.21,91.67]],"id":42189401}],"con":true,"img":false}]}
{"op":"mcm","clk":"5353355235","pt":1646213575622,"mc":[{"id":"1.195453771","rc":[{"atl":[[6.2,11.37],[7,12.49]],"id":36074638}],"con":true,"img":false}]}
{"op":"mcm","clk":"5353355240","pt":1646213575727,"mc":[{"id":"1.195453771","rc":[{"atb":[[1.29,0],[1.34,85.42]],"id":37127725}],"con":true,"img":false}]}
{"op":"mcm","clk":"5353355247","pt":1646213575830,"mc":[{"id":"1.195453771","rc":[{"atl":[[6.2,0]],"id":36500377},{"atl":[[6.4,0]],"id":36074638},{"atb":[[1.33,0]],"id":37127725}],"con":true,"img":false}]}
{"op":"mcm","clk":"5353355255","pt":1646213575935,"mc":[{"id":"1.195453771","rc":[{"atl":[[6.6,10.22]],"id":36500377},{"atl":[[6.8,7.51]],"id":36074638},{"atb":[[1.31,85.42]],"id":37127725}],"con":true,"img":false}]}
{"op":"mcm","clk":"5353355261","pt":1646213576037,"mc":[{"id":"1.195453771","rc":[{"atl":[[6.4,27.78]],"id":36500377},{"atl":[[6.2,3.85],[7,29.17]],"id":36074638},{"atb":[[1.29,185.19],[1.34,0]],"id":37127725}],"con":true,"img":false}]}
{"op":"mcm","clk":"5353355267","pt":1646213576092,"mc":[{"id":"1.195453771","rc":[{"atl":[[6,4]],"id":36500377},{"atl":[[6.6,26.79],[7,12.49]],"id":36074638},{"atb":[[1.32,170.84],[1.29,0]],"id":37127725}],"con":true,"img":false}]}
{"op":"mcm","clk":"5353355339","pt":1646213577456,"mc":[{"id":"1.195453771","rc":[{"atb":[[2.74,0],[2.84,0],[2.94,0]],"id":39784543},{"atl":[[8,0],[10,0],[20,0],[15,0],[30,0]],"id":39784543},{"atb":[[2.5,0],[2.6,0],[2.7,0]],"id":36500377},{"atl":[[16.5,0],[8.6,0],[11.5,0],[23,0],[6.6,8.07]],"id":36500377},{"atb":[[2.5,0],[2.6,0],[2.7,0]],"id":35801684},{"atl":[[16.5,0],[8.6,0],[11.5,0],[23,0],[6.6,0]],"id":35801684},{"atb":[[2.8,20.1],[2.9,0],[2.7,0]],"id":36074638},{"atl":[[19.5,0],[9.8,0],[7.8,0],[14.5,0],[29,0]],"id":36074638},{"atb":[[1.19,0],[1.14,250],[1.09,0]],"id":42189401},{"atl":[[2.88,0],[3.2,0],[2.28,0],[2.68,0],[2.48,0]],"id":42189401},{"atb":[[1.2,0],[1.25,250],[1.15,0]],"id":37127725},{"atl":[[3.6,0],[3.1,0],[2.44,0],[2.64,0],[2.84,0]],"id":37127725},{"atb":[[1.6,0],[1.7,0],[1.65,0]],"id":28338255},{"atl":[[3.2,0],[3.7,0],[6.8,0],[4.4,0],[5.4,0]],"id":28338255},{"atb":[[1.2,0],[1.25,0],[1.3,0]],"id":26051221},{"atl":[[2.54,0],[3.85,0],[2.74,0],[3.35,0],[2.94,0]],"id":26051221}],"con":true,"img":false}]}
{"op":"mcm","clk":"5353355490","pt":1646213580416,"mc":[{"id":"1.195453771","rc":[{"atb":[[2.76,4.73]],"id":36500377},{"atb":[[2.96,4.25]],"id":36074638}],"con":true,"img":false}]}
{"op":"mcm","clk":"5353355510","pt":1646213580726,"mc":[{"id":"1.195453771","rc":[{"atb":[[2.36,31.6]],"id":36500377},{"atb":[[2.44,26.8]],"id":36074638}],"con":true,"img":false}]}
{"op":"mcm","clk":"5353355520","pt":1646213580831,"mc":[{"id":"1.195453771","rc":[{"atb":[[2.62,0]],"id":36500377},{"atb":[[2.72,0]],"id":35801684},{"atb":[[2.8,0]],"id":36074638},{"atb":[[1.2,0]],"id":42189401},{"atb":[[1.31,0]],"id":26051221}],"con":true,"img":false}]}
{"op":"mcm","clk":"5353355525","pt":1646213580937,"mc":[{"id":"1.195453771","rc":[{"atb":[[2.46,26.7]],"id":35801684},{"atb":[[1.17,202.55]],"id":42189401},{"atb":[[1.26,128.04]],"id":26051221}],"con":true,"img":false}]}
{"op":"mcm","clk":"5353355541","pt":1646213581150,"mc":[{"id":"1.195453771","rc":[{"atb":[[2.74,69.53],[2.84,65.75],[2.94,31.18]],"id":39784543},{"atl":[[8,1.72],[10,1.34],[20,1.27],[15,1.72],[30,1.66]],"id":39784543},{"atb":[[2.5,80.65],[2.6,75.61],[2.7,35.58]],"id":36500377},{"atl":[[16.5,1.55],[8.6,1.59],[11.5,2.3],[23,2.2],[6.6,10.22]],"id":36500377},{"atb":[[2.5,80.65],[2.6,75.61],[2.7,35.58]],"id":35801684},{"atl":[[16.5,1.55],[8.6,1.59],[11.5,2.3],[23,2.2],[6.6,2.15]],"id":35801684},{"atb":[[2.8,67.21],[2.9,31.83],[2.7,71.17]],"id":36074638},{"atl":[[19.5,1.3],[9.8,1.37],[7.8,1.77],[14.5,1.79],[29,1.72]],"id":36074638},{"atb":[[1.19,318.38],[1.14,1114.19],[1.09,1344.3]],"id":42189401},{"atl":[[2.88,12.87],[3.2,21.99],[2.28,9.45],[2.68,14.4],[2.48,8.17]],"id":42189401},{"atb":[[1.2,604.93],[1.25,483.95],[1.3,201.64]],"id":26051221},{"atl":[[2.54,7.85],[3.85,16.98],[2.74,6.95],[3.35,10.29],[2.94,12.47]],"id":26051221},{"atb":[[1.6,201.64],[1.7,86.41],[1.65,186.13]],"id":28338255},{"atl":[[3.2,5.49],[3.7,4.47],[6.8,8.34],[4.4,7.11],[5.4,5.49]],"id":28338255},{"atb":[[1.2,604.93],[1.25,491.97],[1.15,806.58]],"id":37127725},{"atl":[[3.6,18.61],[3.1,11.52],[2.44,8.4],[2.64,7.37],[2.84,13.15]],"id":37127725}],"con":true,"img":false}]}
{"op":"mcm","clk":"5353355770","pt":1646213585842,"mc":[{"id":"1.195453771","rc":[{"atl":[[8.8,0]],"id":39784543},{"atb":[[2.92,0]],"id":36074638},{"atl":[[3.6,0]],"id":28338255}],"con":true,"img":false}]}
{"op":"mcm","clk":"5353355777","pt":1646213585945,"mc":[{"id":"1.195453771","rc":[{"atl":[[9.2,6.6]],"id":39784543},{"atb":[[2.84,21.79]],"id":36074638},{"atl":[[3.7,19.01]],"id":28338255}],"con":true,"img":false}]}
{"op":"mcm","clk":"5353355928","pt":1646213589354,"mc":[{"id":"1.195453771","rc":[{"atb":[[2.76,9]],"id":36500377},{"spn":4.39,"spf":"NaN","id":36500377},{"atb":[[2.96,8.08]],"id":36074638},{"spn":1.63,"spf":"NaN","id":42189401},{"spn":2.63,"spf":"NaN","id":28338255},{"spn":1.88,"spf":"NaN","id":37127725}],"con":true,"img":false}]}
{"op":"mcm","clk":"5353356199","pt":1646213595834,"mc":[{"id":"1.195453771","rc":[{"atl":[[6.6,2.15]],"id":36500377},{"atl":[[6.8,0]],"id":36074638}],"con":true,"img":false}]}
{"op":"mcm","clk":"5353356206","pt":1646213595938,"mc":[{"id":"1.195453771","rc":[{"atl":[[6.2,8.07]],"id":36500377},{"atl":[[6.4,7.51],[6.6,8.93],[7,29.17]],"id":36074638}],"con":true,"img":false}]}
{"op":"mcm","clk":"5353356211","pt":1646213596041,"mc":[{"id":"1.195453771","rc":[{"atl":[[6.4,9.26],[6,12.07]],"id":36500377},{"atl":[[6.2,11.37]],"id":36074638}],"con":true,"img":false}]}
{"op":"mcm","clk":"5353356218","pt":1646213596145,"mc":[{"id":"1.195453771","rc":[{"atl":[[7,12.49]],"id":36074638}],"con":true,"img":false}]}
{"op":"mcm","clk":"5353356424","pt":1646213600762,"mc":[{"id":"1.195453771","rc":[{"atb":[[1.31,0]],"id":37127725}],"con":true,"img":false}]}
{"op":"mcm","clk":"5353356431","pt":1646213600868,"mc":[{"id":"1.195453771","rc":[{"atb":[[1.33,85.42]],"id":37127725}],"con":true,"img":false}]}
{"op":"mcm","clk":"5353356438","pt":1646213600969,"mc":[{"id":"1.195453771","rc":[{"atb":[[1.32,0],[1.29,237.51]],"id":37127725}],"con":true,"img":false}]}
{"op":"mcm","clk":"5353356444","pt":1646213601075,"mc":[{"id":"1.195453771","rc":[{"atb":[[1.29,0],[1.34,85.42]],"id":37127725}],"con":true,"img":false}]}
{"op":"mcm","clk":"5353356697","pt":1646213605847,"mc":[{"id":"1.195453771","rc":[{"atl":[[9.2,0]],"id":39784543},{"atb":[[2.84,0]],"id":36074638},{"atl":[[6.4,0]],"id":36074638}],"con":true,"img":false}]}
{"op":"mcm","clk":"5353356704","pt":1646213605951,"mc":[{"id":"1.195453771","rc":[{"atl":[[8.8,6.6]],"id":39784543},{"atb":[[2.92,21.79]],"id":36074638},{"atl":[[6.2,3.85],[6.8,7.51],[7,29.17]],"id":36074638}],"con":true,"img":false}]}
{"op":"mcm","clk":"5353356784","pt":1646213607666,"mc":[{"id":"1.195453771","rc":[{"atl":[[2.56,0]],"id":37127725}],"con":true,"img":false}]}
{"op":"mcm","clk":"5353356790","pt":1646213607769,"mc":[{"id":"1.195453771","rc":[{"atl":[[2.6,23.43]],"id":37127725}],"con":true,"img":false}]}
{"op":"mcm","clk":"5353356919","pt":1646213610878,"mc":[{"id":"1.195453771","rc":[{"atl":[[6.2,0]],"id":36500377}],"con":true,"img":false}]}
{"op":"mcm","clk":"5353356926","pt":1646213610981,"mc":[{"id":"1.195453771","rc":[{"atl":[[6.4,27.78],[6.6,10.22]],"id":36500377}],"con":true,"img":false}]}
{"op":"mcm","clk":"5353356936","pt":1646213611188,"mc":[{"id":"1.195453771","rc":[{"atl":[[6,4]],"id":36500377}],"con":true,"img":false}]}
{"op":"mcm","clk":"5353357128","pt":1646213615280,"mc":[{"id":"1.195453771","rc":[{"atl":[[6.6,17.86],[7,12.49]],"id":36074638}],"con":true,"img":false}]}
{"op":"mcm","clk":"5353357154","pt":1646213615902,"mc":[{"id":"1.195453771","rc":[{"atb":[[1.33,0]],"id":37127725},{"atl":[[2.46,0]],"id":37127725}],"con":true,"img":false}]}
{"op":"mcm","clk":"5353357160","pt":1646213616004,"mc":[{"id":"1.195453771","rc":[{"atb":[[1.31,85.42]],"id":37127725},{"atl":[[2.56,28.68]],"id":37127725}],"con":true,"img":false}]}
{"op":"mcm","clk":"5353357167","pt":1646213616057,"mc":[{"id":"1.195453771","rc":[{"atb":[[1.29,185.19]],"id":37127725}],"con":true,"img":false}]}
{"op":"mcm","clk":"5353357174","pt":1646213616161,"mc":[{"id":"1.195453771","rc":[{"atb":[[1.34,0]],"id":37127725}],"con":true,"img":false}]}
{"op":"mcm","clk":"5353357434","pt":1646213620791,"mc":[{"id":"1.195453771","rc":[{"atb":[[1.17,0]],"id":42189401}],"con":true,"img":false}]}
{"op":"mcm","clk":"5353357446","pt":1646213620905,"mc":[{"id":"1.195453771","rc":[{"atb":[[1.2,202.55]],"id":42189401}],"con":true,"img":false}]}
{"op":"mcm","clk":"5353357689","pt":1646213625321,"mc":[{"id":"1.195453771","rc":[{"atb":[[1.32,85.42],[1.29,0]],"id":37127725}],"con":true,"img":false}]}
{"op":"mcm","clk":"5353357717","pt":1646213625792,"mc":[{"id":"1.195453771","rc":[{"atb":[[2.36,0]],"id":36500377},{"atb":[[2.46,0]],"id":35801684},{"atb":[[2.44,0]],"id":36074638},{"atb":[[1.21,0]],"id":42189401},{"atb":[[1.26,0]],"id":26051221}],"con":true,"img":false}]}
{"op":"mcm","clk":"5353357724","pt":1646213625895,"mc":[{"id":"1.195453771","rc":[{"atb":[[2.62,31.6]],"id":36500377},{"atb":[[2.72,26.7]],"id":35801684},{"atb":[[2.72,26.8]],"id":36074638},{"atb":[[1.23,91.67]],"id":42189401},{"atb":[[1.31,128.04]],"id":26051221}],"con":true,"img":false}]}
{"op":"mcm","clk":"5353357967","pt":1646213630829,"mc":[{"id":"1.195453771","rc":[{"atl":[[6.6,2.15]],"id":36500377}],"con":true,"img":false}]}
{"op":"mcm","clk":"5353357976","pt":1646213630931,"mc":[{"id":"1.195453771","rc":[{"atl":[[6.2,8.07]],"id":36500377}],"con":true,"img":false}]}
{"op":"mcm","clk":"5353357984","pt":1646213631086,"mc":[{"id":"1.195453771","rc":[{"atl":[[6,12.07]],"id":36500377}],"con":true,"img":false}]}
{"op":"mcm","clk":"5353357993","pt":1646213631192,"mc":[{"id":"1.195453771","rc":[{"atl":[[6.4,9.26]],"id":36500377}],"con":true,"img":false}]}
{"op":"mcm","clk":"5353358277","pt":1646213635913,"mc":[{"id":"1.195453771","rc":[{"atl":[[6.8,0]],"id":36074638}],"con":true,"img":false}]}
{"op":"mcm","clk":"5353358281","pt":1646213636018,"mc":[{"id":"1.195453771","rc":[{"atl":[[6.4,7.51]],"id":36074638}],"con":true,"img":false}]}
{"op":"mcm","clk":"5353358287","pt":1646213636119,"mc":[{"id":"1.195453771","rc":[{"atl":[[6.6,8.93],[7,29.17]],"id":36074638}],"con":true,"img":false}]}
{"op":"mcm","clk":"5353358294","pt":1646213636229,"mc":[{"id":"1.195453771","rc":[{"atl":[[6.2,11.37],[7,12.49]],"id":36074638}],"con":true,"img":false}]}
{"op":"mcm","clk":"5353358815","pt":1646213645823,"mc":[{"id":"1.195453771","rc":[{"atl":[[6.4,0]],"id":36074638},{"atb":[[1.31,0]],"id":37127725}],"con":true,"img":false}]}
{"op":"mcm","clk":"5353358821","pt":1646213645926,"mc":[{"id":"1.195453771","rc":[{"atl":[[6.8,7.51]],"id":36074638},{"atb":[[1.33,85.42]],"id":37127725}],"con":true,"img":false}]}
{"op":"mcm","clk":"5353358825","pt":1646213646028,"mc":[{"id":"1.195453771","rc":[{"atl":[[6.2,3.85],[7,29.17]],"id":36074638},{"atb":[[1.32,0],[1.29,185.19]],"id":37127725}],"con":true,"img":false}]}
{"op":"mcm","clk":"5353359277","pt":1646213654948,"mc":[{"id":"1.195453771","rc":[{"atl":[[6.6,17.86]],"id":36074638},{"spn":1.64,"spf":"NaN","id":42189401},{"atb":[[1.34,85.42]],"id":37127725},{"spn":1.89,"spf":"NaN","id":37127725}],"con":true,"img":false}]}
{"op":"mcm","clk":"5353359285","pt":1646213655095,"mc":[{"id":"1.195453771","rc":[{"atl":[[7,12.49]],"id":36074638},{"atb":[[1.29,0]],"id":37127725}],"con":true,"img":false}]}
{"op":"mcm","clk":"5353359330","pt":1646213655802,"mc":[{"id":"1.195453771","rc":[{"atl":[[6.2,0]],"id":36500377},{"atb":[[1.33,0]],"id":37127725},{"atl":[[2.6,0]],"id":37127725}],"con":true,"img":false}]}
{"op":"mcm","clk":"5353359336","pt":1646213655870,"mc":[{"id":"1.195453771","rc":[{"atl":[[5.9,8.07]],"id":36500377},{"atb":[[1.31,85.42]],"id":37127725},{"atl":[[2.56,52.11]],"id":37127725}],"con":true,"img":false}]}
{"op":"mcm","clk":"5353359342","pt":1646213655968,"mc":[{"id":"1.195453771","rc":[{"atl":[[6.4,27.78]],"id":36500377}],"con":true,"img":false}]}
{"op":"mcm","clk":"5353359350","pt":1646213656075,"mc":[{"id":"1.195453771","rc":[{"atl":[[6,4]],"id":36500377}],"con":true,"img":false}]}
{"op":"mcm","clk":"5353359570","pt":1646213660052,"mc":[{"id":"1.195453771","rc":[{"atb":[[1.32,170.84],[1.34,0]],"id":37127725}],"con":true,"img":false}]}
{"op":"mcm","clk":"5353359619","pt":1646213660879,"mc":[{"id":"1.195453771","rc":[{"atl":[[2.56,28.68]],"id":37127725}],"con":true,"img":false}]}
{"op":"mcm","clk":"5353359626","pt":1646213660980,"mc":[{"id":"1.195453771","rc":[{"atl":[[2.6,23.43]],"id":37127725}],"con":true,"img":false}]}
{"op":"mcm","clk":"5353359814","pt":1646213664755,"mc":[{"id":"1.195453771","rc":[{"atl":[[6.4,9.26],[5.8,8.07]],"id":36500377}],"con":true,"img":false}]}
{"op":"mcm","clk":"5353359872","pt":1646213665888,"mc":[{"id":"1.195453771","rc":[{"atl":[[5.9,0]],"id":36500377}],"con":true,"img":false}]}
{"op":"mcm","clk":"5353359878","pt":1646213665943,"mc":[{"id":"1.195453771","rc":[{"atl":[[6.6,10.22]],"id":36500377}],"con":true,"img":false}]}
{"op":"mcm","clk":"5353360125","pt":1646213669978,"mc":[{"id":"1.195453771","rc":[{"atl":[[6.4,21.33],[5.8,0]],"id":36500377}],"con":true,"img":false}]}
{"op":"mcm","clk":"5353360504","pt":1646213675906,"mc":[{"id":"1.195453771","rc":[{"atl":[[6.8,0]],"id":36074638},{"atb":[[1.31,0]],"id":37127725}],"con":true,"img":false}]}
{"op":"mcm","clk":"5353360512","pt":1646213676002,"mc":[{"id":"1.195453771","rc":[{"atl":[[6.4,7.51]],"id":36074638},{"atb":[[1.33,85.42]],"id":37127725}],"con":true,"img":false}]}
{"op":"mcm","clk":"5353360519","pt":1646213676106,"mc":[{"id":"1.195453771","rc":[{"atl":[[6.6,8.93],[7,29.17]],"id":36074638},{"atb":[[1.32,0],[1.29,237.51]],"id":37127725}],"con":true,"img":false}]}
{"op":"mcm","clk":"5353360871","pt":1646213682008,"mc":[{"id":"1.195453771","rc":[{"atl":[[9,0],[10.5,2.11],[8.2,0],[9.4,0],[8.6,0]],"id":39784543},{"atb":[[2.44,63.22],[2.06,0],[2.2,0],[2.78,12.9]],"id":36500377},{"atb":[[1.16,0],[1.08,0],[1.24,83.33]],"id":42189401},{"atl":[[2.64,0],[2.78,56.18]],"id":42189401},{"atl":[[2.72,0],[2.54,0],[2.58,0],[2.62,0],[3.2,54.54],[2.66,0]],"id":37127725},{"atb":[[1.12,0],[1.44,2],[1.26,384.62],[1.14,0],[1.09,0],[1.15,0],[1.3,268.31],[1.13,0]],"id":26051221},{"atb":[[1.26,114.88],[1.33,60.61],[1.95,0],[1.99,0],[2.02,0],[2.06,1.66],[1.97,0]],"id":28338255}],"con":true,"img":false}]}
{"op":"mcm","clk":"5353360894","pt":1646213682319,"mc":[{"id":"1.195453771","rc":[{"atl":[[9.2,12.2],[11,0]],"id":35801684},{"atl":[[2.64,60.98],[3.15,0]],"id":26051221}],"con":true,"img":false}]}
{"op":"mcm","clk":"5353360979","pt":1646213683507,"mc":[{"id":"1.195453771","rc":[{"atb":[[1.26,76.92],[1.24,0]],"id":42189401},{"atb":[[1.44,0],[1.3,201.64],[1.29,68.97]],"id":26051221},{"atl":[[1.77,2]],"id":26051221}],"con":true,"img":false}]}
{"op":"mcm","clk":"5353360990","pt":1646213683616,"mc":[{"id":"1.195453771","rc":[{"atb":[[2.88,53.19],[3,0]],"id":39784543},{"atl":[[3.6,7.69],[3.5,0]],"id":28338255}],"con":true,"img":false}]}
{"op":"mcm","clk":"5353360993","pt":1646213683711,"mc":[{"id":"1.195453771","rc":[{"atl":[[1.76,2],[1.77,0]],"id":26051221}],"con":true,"img":false}]}
{"op":"mcm","clk":"5353361004","pt":1646213683818,"mc":[{"id":"1.195453771","rc":[{"atl":[[2.64,0]],"id":26051221}],"con":true,"img":false}]}
{"op":"mcm","clk":"5353361011","pt":1646213683914,"mc":[{"id":"1.195453771","rc":[{"atl":[[2.98,43.14]],"id":26051221}],"con":true,"img":false}]}
{"op":"mcm","clk":"5353361021","pt":1646213684021,"mc":[{"id":"1.195453771","rc":[{"atl":[[1.71,3],[1.76,0]],"id":26051221}],"con":true,"img":false}]}
{"op":"mcm","clk":"5353361049","pt":1646213684329,"mc":[{"id":"1.195453771","rc":[{"atb":[[2.88,0],[2.98,50.51]],"id":39784543}],"con":true,"img":false}]}
{"op":"mcm","clk":"5353361081","pt":1646213684704,"mc":[{"id":"1.195453771","rc":[{"atl":[[6.2,11.37],[7,12.49]],"id":36074638},{"atb":[[1.33,170.84],[1.29,0]],"id":37127725}],"con":true,"img":false}]}
{"op":"mcm","clk":"5353361104","pt":1646213685016,"mc":[{"id":"1.195453771","rc":[{"atb":[[2.84,10.87],[2.86,0]],"id":36074638},{"atl":[[1.7,2]],"id":26051221},{"atl":[[3.6,0],[3.55,7.84]],"id":28338255}],"con":true,"img":false}]}
{"op":"mcm","clk":"5353361120","pt":1646213685220,"mc":[{"id":"1.195453771","rc":[{"atl":[[1.69,3]],"id":26051221}],"con":true,"img":false}]}
{"op":"mcm","clk":"5353361131","pt":1646213685326,"mc":[{"id":"1.195453771","rc":[{"atl":[[1.7,0],[1.71,0]],"id":26051221}],"con":true,"img":false}]}
{"op":"mcm","clk":"5353361161","pt":1646213685797,"mc":[{"id":"1.195453771","rc":[{"atb":[[3.05,0]],"id":39784543},{"atl":[[6.4,0]],"id":36074638},{"atb":[[2,0]],"id":28338255},{"atb":[[1.33,85.42]],"id":37127725},{"atl":[[2.6,0]],"id":37127725}],"con":true,"img":false}]}
{"op":"mcm","clk":"5353361173","pt":1646213685936,"mc":[{"id":"1.195453771","rc":[{"atb":[[3,21.25]],"id":39784543},{"atl":[[6.8,7.51]],"id":36074638},{"atb":[[1.84,44.04]],"id":28338255},{"atb":[[1.31,85.42]],"id":37127725},{"atl":[[2.9,23.43]],"id":37127725}],"con":true,"img":false}]}
{"op":"mcm","clk":"5353361290","pt":1646213687443,"mc":[{"id":"1.195453771","rc":[{"atl":[[9.2,0],[11,10]],"id":35801684}],"con":true,"img":false}]}
{"op":"mcm","clk":"5353361386","pt":1646213688836,"mc":[{"id":"1.195453771","rc":[{"atb":[[2.04,8.01]],"id":28338255}],"con":true,"img":false}]}
{"op":"mcm","clk":"5353361451","pt":1646213689823,"mc":[{"id":"1.195453771","rc":[{"atl":[[6.6,26.79]],"id":36074638},{"atb":[[1.33,0],[1.32,170.84]],"id":37127725}],"con":true,"img":false}]}
{"op":"mcm","clk":"5353361459","pt":1646213689925,"mc":[{"id":"1.195453771","rc":[{"atl":[[6.2,3.85]],"id":36074638}],"con":true,"img":false}]}
{"op":"mcm","clk":"5353361527","pt":1646213690809,"mc":[{"id":"1.195453771","rc":[{"atl":[[8.8,0]],"id":39784543},{"atl":[[6.6,2.15]],"id":36500377}],"con":true,"img":false}]}
{"op":"mcm","clk":"5353361537","pt":1646213690920,"mc":[{"id":"1.195453771","rc":[{"atl":[[9.6,6.6]],"id":39784543},{"atl":[[6.2,8.07]],"id":36500377}],"con":true,"img":false}]}
{"op":"mcm","clk":"5353361552","pt":1646213691131,"mc":[{"id":"1.195453771","rc":[{"atl":[[6.4,9.26],[6,12.07]],"id":36500377}],"con":true,"img":false}]}
{"op":"mcm","clk":"5353361610","pt":1646213692046,"mc":[{"id":"1.195453771","rc":[{"atl":[[11.5,9.11]],"id":39784543},{"atb":[[2.74,28.74]],"id":36500377},{"atl":[[3.3,21.74]],"id":37127725}],"con":true,"img":false}]}
{"op":"mcm","clk":"5353361632","pt":1646213692311,"mc":[{"id":"1.195453771","rc":[{"atb":[[2.12,0],[2.16,0],[2.08,0]],"id":36500377},{"atl":[[1.68,4]],"id":26051221}],"con":true,"img":false}]}
{"op":"mcm","clk":"5353361644","pt":1646213692517,"mc":[{"id":"1.195453771","rc":[{"atl":[[1.69,0],[1.67,3]],"id":26051221}],"con":true,"img":false}]}
{"op":"mcm","clk":"5353361722","pt":1646213693550,"mc":[{"id":"1.195453771","rc":[{"atb":[[1.24,208.33]],"id":42189401},{"atb":[[1.27,185.19]],"id":26051221}],"con":true,"img":false}]}
{"op":"mcm","clk":"5353361796","pt":1646213694637,"mc":[{"id":"1.195453771","rc":[{"atb":[[1.88,8.54]],"id":28338255}],"con":true,"img":false}]}
{"op":"mcm","clk":"5353361804","pt":1646213694739,"mc":[{"id":"1.195453771","rc":[{"atb":[[2.76,4.73]],"id":36500377}],"con":true,"img":false}]}
{"op":"mcm","clk":"5353361830","pt":1646213695005,"mc":[{"id":"1.195453771","rc":[{"atb":[[2.8,94.99]],"id":36074638},{"atb":[[1.31,161.29]],"id":28338255}],"con":true,"img":false}]}
{"op":"mcm","clk":"5353362192","pt":1646213700654,"mc":[{"id":"1.195453771","rc":[{"atb":[[2.8,4.18]],"id":36500377}],"con":true,"img":false}]}
{"op":"mcm","clk":"5353362204","pt":1646213700815,"mc":[{"id":"1.195453771","rc":[{"atb":[[3.4,60.5],[3.5,24.79]],"id":39784543},{"atl":[[9,2.5],[9.8,39.36],[7.8,11.76]],"id":39784543},{"atb":[[2.8,17.18],[2.76,30.72]],"id":36500377},{"atl":[[6.4,35.25],[5.9,13]],"id":36500377},{"atb":[[3.1,16.99],[3.35,10],[3.55,5],[3.75,2.5],[3.2,11.95]],"id":35801684},{"atl":[[6.4,10.41],[6.8,22.04]],"id":35801684},{"atb":[[1.27,5],[1.26,168.7],[1.23,284.98],[1.31,2.5]],"id":42189401},{"atl":[[2.06,89.08],[2.1,152.81]],"id":42189401},{"atb":[[2.32,10],[1.84,71.38],[2.04,19.91],[2.48,2.5],[2.4,5]],"id":28338255},{"atl":[[3.2,16.61],[3.65,46.21]],"id":28338255},{"atb":[[1.44,2.5],[1.4,5],[1.36,10],[1.32,170.82],[1.3,361.88]],"id":26051221},{"atl":[[2.24,116.78]],"id":26051221},{"atb":[[1.41,5],[1.45,2.5],[1.37,10],[1.32,242.35],[1.3,209.69]],"id":37127725},{"atl":[[2.44,63.96],[2.64,92.77]],"id":37127725}],"con":true,"img":false}]}
{"op":"mcm","clk":"5353362210","pt":1646213700944,"mc":[{"id":"1.195453771","rc":[{"atl":[[5.8,12.07],[6,4]],"id":36500377}],"con":true,"img":false}]}
{"op":"mcm","clk":"5353362220","pt":1646213701043,"mc":[{"id":"1.195453771","rc":[{"atb":[[3.2,8.37],[3.7,10]],"id":35801684}],"con":true,"img":false}]}
{"op":"mcm","clk":"5353362225","pt":1646213701146,"mc":[{"id":"1.195453771","rc":[{"atb":[[2.78,11.24]],"id":36500377},{"atb":[[3.2,6.71]],"id":35801684},{"atb":[[2.06,0]],"id":28338255}],"con":true,"img":false}]}
{"op":"mcm","clk":"5353362237","pt":1646213701253,"mc":[{"id":"1.195453771","rc":[{"atb":[[2.82,1.66]],"id":36500377},{"atb":[[3.8,1.66]],"id":35801684},{"atb":[[2.5,1.66]],"id":28338255}],"con":true,"img":false}]}
{"op":"mcm","clk":"5353362284","pt":1646213701927,"mc":[{"id":"1.195453771","rc":[{"atl":[[12.5,6.52]],"id":39784543},{"atl":[[3.4,31.25]],"id":37127725}],"con":true,"img":false}]}
{"op":"mcm","clk":"5353362288","pt":1646213702029,"mc":[{"id":"1.195453771","rc":[{"atb":[[2.7,79.7]],"id":36500377}],"con":true,"img":false}]}
{"op":"mcm","clk":"5353362315","pt":1646213702447,"mc":[{"id":"1.195453771","rc":[{"atl":[[9.2,12.2],[11,0]],"id":35801684},{"atb":[[2.82,0],[2.74,0],[2.78,0]],"id":36074638},{"atl":[[6.8,40.83],[6,11.71]],"id":36074638},{"atb":[[1.1,0]],"id":42189401},{"atl":[[2.5,66.67],[2.78,0]],"id":42189401},{"atb":[[1.03,0]],"id":26051221},{"atl":[[1.68,0],[2.64,60.98],[2.98,0],[1.66,2]],"id":26051221}],"con":true,"img":false}]}
{"op":"mcm","clk":"5353362350","pt":1646213703124,"mc":[{"id":"1.195453771","rc":[{"atl":[[1.76,3],[1.67,0],[1.66,0]],"id":26051221}],"con":true,"img":false}]}
{"op":"mcm","clk":"5353362360","pt":1646213703227,"mc":[{"id":"1.195453771","rc":[{"atl":[[1.76,5]],"id":26051221}],"con":true,"img":false}]}
{"op":"mcm","clk":"5353362369","pt":1646213703330,"mc":[{"id":"1.195453771","rc":[{"atl":[[1.76,2]],"id":26051221}],"con":true,"img":false}]}
{"op":"mcm","clk":"5353362373","pt":1646213703430,"mc":[{"id":"1.195453771","rc":[{"atl":[[1.76,0]],"id":26051221}],"con":true,"img":false}]}
{"op":"mcm","clk":"5353362380","pt":1646213703534,"mc":[{"id":"1.195453771","rc":[{"atb":[[1.22,250]],"id":42189401},{"atb":[[1.25,733.95]],"id":26051221},{"atl":[[2.24,128.03]],"id":26051221}],"con":true,"img":false}]}
{"op":"mcm","clk":"5353362390","pt":1646213703638,"mc":[{"id":"1.195453771","rc":[{"atb":[[3.4,57.37]],"id":39784543},{"atb":[[2.8,13]],"id":36500377},{"atb":[[1.88,0]],"id":28338255}],"con":true,"img":false}]}
{"op":"mcm","clk":"5353362439","pt":1646213704355,"mc":[{"id":"1.195453771","rc":[{"atb":[[1.05,0]],"id":26051221}],"con":true,"img":false}]}
{"op":"mcm","clk":"5353362492","pt":1646213705034,"mc":[{"id":"1.195453771","rc":[{"atb":[[2.76,42.61]],"id":36074638},{"atb":[[1.29,250]],"id":28338255}],"con":true,"img":false}]}
{"op":"mcm","clk":"5353362539","pt":1646213705749,"mc":[{"id":"1.195453771","rc":[{"atl":[[6.8,33.32]],"id":36074638},{"atb":[[1.23,193.31]],"id":42189401},{"atl":[[3.7,4.47]],"id":28338255},{"atb":[[1.31,0]],"id":37127725}],"con":true,"img":false}]}
{"op":"mcm","clk":"5353362547","pt":1646213705857,"mc":[{"id":"1.195453771","rc":[{"atl":[[6.4,7.51]],"id":36074638},{"atb":[[1.25,91.67]],"id":42189401},{"atl":[[3.6,14.53]],"id":28338255},{"atb":[[1.33,85.42]],"id":37127725}],"con":true,"img":false}]}
{"op":"mcm","clk":"5353362564","pt":1646213706058,"mc":[{"id":"1.195453771","rc":[{"atl":[[5.8,0],[6,24]],"id":36500377},{"atl":[[6.2,23.08],[6.6,8.93]],"id":36074638}],"con":true,"img":false}]}
{"op":"mcm","clk":"5353362572","pt":1646213706162,"mc":[{"id":"1.195453771","rc":[{"atb":[[3.55,11.71]],"id":35801684}],"con":true,"img":false}]}
{"op":"mcm","clk":"5353362580","pt":1646213706265,"mc":[{"id":"1.195453771","rc":[{"atb":[[3.7,0]],"id":35801684}],"con":true,"img":false}]}
{"op":"mcm","clk":"5353362669","pt":1646213707465,"mc":[{"id":"1.195453771","rc":[{"atb":[[3.55,5],[3.5,9.3]],"id":35801684},{"atb":[[1.12,0]],"id":42189401},{"atl":[[2.04,19.23],[2.06,70.21]],"id":42189401},{"atl":[[2.24,111.9],[2.28,15.63]],"id":26051221}],"con":true,"img":false}]}
{"op":"mcm","clk":"5353362777","pt":1646213709269,"mc":[{"id":"1.195453771","rc":[{"atl":[[2.24,11.25],[2.28,54.08]],"id":26051221}],"con":true,"img":false}]}
{"op":"mcm","clk":"5353362798","pt":1646213709537,"mc":[{"id":"1.195453771","rc":[{"atb":[[3.6,2.89]],"id":39784543},{"atb":[[2.82,5.79]],"id":36500377}],"con":true,"img":false}]}
{"op":"mcm","clk":"5353362918","pt":1646213711963,"mc":[{"id":"1.195453771","rc":[{"atl":[[13.5,10]],"id":39784543},{"atb":[[2.66,75.3]],"id":36500377},{"atl":[[3.5,50]],"id":37127725}],"con":true,"img":false}]}
{"op":"mcm","clk":"5353363102","pt":1646213715063,"mc":[{"id":"1.195453771","rc":[{"spn":5.7,"spf":"NaN","id":39784543},{"spn":4.36,"spf":"NaN","id":36500377},{"spn":5.1,"spf":"NaN","id":35801684},{"atb":[[2.72,99.47]],"id":36074638},{"spn":4.49,"spf":"NaN","id":36074638},{"spn":1.67,"spf":"NaN","id":42189401},{"spn":1.94,"spf":"NaN","id":37127725},{"spn":1.84,"spf":"NaN","id":26051221},{"atb":[[1.27,250]],"id":28338255},{"spn":2.85,"spf":"NaN","id":28338255}],"con":true,"img":false}]}
{"op":"mcm","clk":"5353363106","pt":1646213715169,"mc":[{"id":"1.195453771","rc":[{"atb":[[3.55,0]],"id":39784543}],"con":true,"img":false}]}
{"op":"mcm","clk":"5353363114","pt":1646213715271,"mc":[{"id":"1.195453771","rc":[{"atb":[[3.65,1.66]],"id":39784543}],"con":true,"img":false}]}
{"op":"mcm","clk":"5353363171","pt":1646213716455,"mc":[{"id":"1.195453771","rc":[{"atb":[[2.72,0]],"id":36500377}],"con":true,"img":false}]}
{"op":"mcm","clk":"5353363180","pt":1646213716562,"mc":[{"id":"1.195453771","rc":[{"atb":[[2.78,34.93]],"id":36500377}],"con":true,"img":false}]}
{"op":"mcm","clk":"5353363242","pt":1646213717494,"mc":[{"id":"1.195453771","rc":[{"atb":[[1.2,452.55]],"id":42189401},{"atb":[[1.23,250]],"id":26051221},{"atl":[[2.32,37.88]],"id":26051221}],"con":true,"img":false}]}
{"op":"mcm","clk":"5353363292","pt":1646213718385,"mc":[{"id":"1.195453771","rc":[{"atb":[[3.1,3.57]],"id":35801684},{"atb":[[1.26,244.93],[1.31,40.62]],"id":42189401},{"atl":[[2.1,45.45]],"id":42189401},{"atb":[[1.36,41.88]],"id":26051221},{"atb":[[1.84,44.04]],"id":28338255},{"atb":[[1.45,31.51]],"id":37127725}],"con":true,"img":false}]}
{"op":"mcm","clk":"5353363298","pt":1646213718486,"mc":[{"id":"1.195453771","rc":[{"atb":[[3.6,6.93],[3.45,44.29],[3.4,20.83]],"id":39784543},{"atl":[[9,26.98],[9.8,16.36]],"id":39784543},{"atb":[[2.82,25.29],[2.78,73.93],[2.76,4.73]],"id":36500377},{"atl":[[6.4,9.26],[6.2,46.46]],"id":36500377},{"atb":[[3.5,30.75],[3.75,8.12]],"id":35801684},{"atb":[[1.23,10]],"id":42189401},{"atl":[[2.04,57.35],[2.08,107.82]],"id":42189401},{"atb":[[1.44,18.44],[1.3,201.64]],"id":26051221},{"atb":[[1.37,68.02],[1.3,66.66]],"id":37127725},{"atb":[[2.32,36.76],[2.48,12.13]],"id":28338255},{"atl":[[3.6,41.29],[3.65,18.87]],"id":28338255}],"con":true,"img":false}]}
{"op":"mcm","clk":"5353363306","pt":1646213718589,"mc":[{"id":"1.195453771","rc":[{"atb":[[2.8,0]],"id":36500377},{"atl":[[6.2,65.69],[6,4]],"id":36500377},{"atb":[[3.2,0]],"id":35801684},{"atb":[[1.26,153.15]],"id":42189401},{"atb":[[1.32,90.7]],"id":26051221},{"atb":[[1.32,170.84]],"id":37127725}],"con":true,"img":false}]}
{"op":"mcm","clk":"5353363317","pt":1646213718653,"mc":[{"id":"1.195453771","rc":[{"atb":[[3.5,11.33]],"id":39784543},{"atb":[[2.82,21.16]],"id":36500377},{"atl":[[2.06,0]],"id":42189401},{"atb":[[2.04,8.01]],"id":28338255}],"con":true,"img":false}]}
{"op":"mcm","clk":"5353363385","pt":1646213719983,"mc":[{"id":"1.195453771","rc":[{"atl":[[6.4,44.87]],"id":36074638}],"con":true,"img":false}]}
{"op":"mcm","clk":"5353363391","pt":1646213720091,"mc":[{"id":"1.195453771","rc":[{"atl":[[6.4,63.39],[6.8,0],[6.2,3.85]],"id":36074638}],"con":true,"img":false}]}
{"op":"mcm","clk":"5353363407","pt":1646213720352,"mc":[{"id":"1.195453771","rc":[{"atb":[[1.14,864.19]],"id":42189401},{"atb":[[1.07,0]],"id":26051221}],"con":true,"img":false}]}
{"op":"mcm","clk":"5353363482","pt":1646213721791,"mc":[{"id":"1.195453771","rc":[{"atb":[[3.6,4.04]],"id":39784543},{"atb":[[3.1,0]],"id":35801684}],"con":true,"img":false}]}
{"op":"mcm","clk":"5353363643","pt":1646213724588,"mc":[{"id":"1.195453771","rc":[{"atb":[[2.84,4.08]],"id":36500377}],"con":true,"img":false}]}
{"op":"mcm","clk":"5353363753","pt":1646213726474,"mc":[{"id":"1.195453771","rc":[{"atl":[[7,0]],"id":35801684},{"atl":[[2.08,76.23]],"id":42189401},{"atl":[[3.6,26.76]],"id":28338255}],"con":true,"img":false}]}
{"op":"mcm","clk":"5353363758","pt":1646213726577,"mc":[{"id":"1.195453771","rc":[{"atl":[[6.6,8.97]],"id":35801684},{"atl":[[2.02,31.59]],"id":42189401},{"atl":[[3.7,19.01]],"id":28338255}],"con":true,"img":false}]}
{"op":"mcm","clk":"5353363767","pt":1646213726680,"mc":[{"id":"1.195453771","rc":[{"atl":[[2.1,161.6]],"id":42189401}],"con":true,"img":false}]}
{"op":"mcm","clk":"5353363771","pt":1646213726784,"mc":[{"id":"1.195453771","rc":[{"atl":[[2.1,45.45],[2.08,0]],"id":42189401}],"con":true,"img":false}]}
{"op":"mcm","clk":"5353363807","pt":1646213727466,"mc":[{"id":"1.195453771","rc":[{"atl":[[2.36,55.15]],"id":26051221}],"con":true,"img":false}]}
{"op":"mcm","clk":"5353363824","pt":1646213727676,"mc":[{"id":"1.195453771","rc":[{"atb":[[3.55,2.94]],"id":39784543},{"atb":[[3.6,2.89]],"id":35801684},{"atb":[[2.38,5.45]],"id":28338255},{"atb":[[1.4,18.79]],"id":37127725}],"con":true,"img":false}]}
{"op":"mcm","clk":"5353363867","pt":1646213728506,"mc":[{"id":"1.195453771","rc":[{"atl":[[2.56,0]],"id":37127725}],"con":true,"img":false}]}
{"op":"mcm","clk":"5353363874","pt":1646213728563,"mc":[{"id":"1.195453771","rc":[{"atl":[[2.42,28.68]],"id":37127725}],"con":true,"img":false}]}
{"op":"mcm","clk":"5353363880","pt":1646213728671,"mc":[{"id":"1.195453771","rc":[{"atl":[[2.86,2.5],[2.64,7.37],[2.84,88.61]],"id":37127725}],"con":true,"img":false}]}
{"op":"mcm","clk":"5353363889","pt":1646213728877,"mc":[{"id":"1.195453771","rc":[{"atl":[[2.42,64.29]],"id":37127725}],"con":true,"img":false}]}
{"op":"mcm","clk":"5353363902","pt":1646213729084,"mc":[{"id":"1.195453771","rc":[{"atl":[[2.44,8.4]],"id":37127725}],"con":true,"img":false}]}
{"op":"mcm","clk":"5353363909","pt":1646213729191,"mc":[{"id":"1.195453771","rc":[{"atb":[[2.82,19.5]],"id":36500377}],"con":true,"img":false}]}
{"op":"mcm","clk":"5353363921","pt":1646213729395,"mc":[{"id":"1.195453771","rc":[{"atb":[[2.86,1.66]],"id":36500377}],"con":true,"img":false}]}
{"op":"mcm","clk":"5353363985","pt":1646213730385,"mc":[{"id":"1.195453771","rc":[{"atl":[[2.42,35.61]],"id":37127725}],"con":true,"img":false}]}
{"op":"mcm","clk":"5353363993","pt":1646213730490,"mc":[{"id":"1.195453771","rc":[{"atl":[[2.54,28.68]],"id":37127725}],"con":true,"img":false}]}
{"op":"mcm","clk":"5353364305","pt":1646213735595,"mc":[{"id":"1.195453771","rc":[{"atb":[[2.84,16.89]],"id":36500377}],"con":true,"img":false}]}
{"op":"mcm","clk":"5353364314","pt":1646213735699,"mc":[{"id":"1.195453771","rc":[{"atb":[[3.5,36.89],[3.45,19.81]],"id":39784543},{"atb":[[3.55,33.14],[3.5,9.3]],"id":35801684},{"atl":[[2.02,96.14],[2.1,164.67]],"id":42189401},{"atb":[[1.37,10],[1.4,90.01]],"id":37127725},{"atb":[[2.32,10],[2.38,37.91]],"id":28338255}],"con":true,"img":false}]}
{"op":"mcm","clk":"5353364323","pt":1646213735800,"mc":[{"id":"1.195453771","rc":[{"atb":[[2.82,0]],"id":36500377},{"atl":[[2.94,2]],"id":28338255}],"con":true,"img":false}]}
{"op":"mcm","clk":"5353364332","pt":1646213735908,"mc":[{"id":"1.195453771","rc":[{"atl":[[2.04,19.23]],"id":42189401}],"con":true,"img":false}]}
{"op":"mcm","clk":"5353364340","pt":1646213736009,"mc":[{"id":"1.195453771","rc":[{"atb":[[2.78,34.93],[2.76,52.07]],"id":36500377},{"atl":[[3.6,0],[3.55,40.3],[2.94,4]],"id":28338255}],"con":true,"img":false}]}
{"op":"mcm","clk":"5353364346","pt":1646213736114,"mc":[{"id":"1.195453771","rc":[{"atb":[[1.31,0]],"id":26051221}],"con":true,"img":false}]}
{"op":"mcm","clk":"5353364356","pt":1646213736175,"mc":[{"id":"1.195453771","rc":[{"atb":[[1.28,128.04]],"id":26051221},{"atb":[[2.5,0]],"id":28338255},{"atl":[[3.2,5.49],[2.94,2]],"id":28338255}],"con":true,"img":false}]}
{"op":"mcm","clk":"5353364361","pt":1646213736274,"mc":[{"id":"1.195453771","rc":[{"atl":[[2.94,4]],"id":28338255}],"con":true,"img":false}]}
{"op":"mcm","clk":"5353364373","pt":1646213736482,"mc":[{"id":"1.195453771","rc":[{"atb":[[3,0]],"id":39784543},{"atl":[[11.5,4.76]],"id":39784543},{"atb":[[2.62,0]],"id":36500377},{"atl":[[9.2,0]],"id":36500377},{"atl":[[9.8,0]],"id":35801684},{"atl":[[11,0]],"id":36074638},{"atb":[[1.2,250]],"id":42189401},{"atl":[[2.58,0]],"id":42189401},{"atl":[[2.94,2],[4.7,0]],"id":28338255},{"atb":[[1.28,0]],"id":26051221},{"atl":[[2.92,0]],"id":26051221},{"atb":[[1.28,0]],"id":37127725},{"atl":[[2.9,0]],"id":37127725}],"con":true,"img":false}]}
{"op":"mcm","clk":"5353364383","pt":1646213736595,"mc":[{"id":"1.195453771","rc":[{"atb":[[1.15,202.55]],"id":42189401},{"atb":[[1.21,128.04]],"id":26051221},{"atl":[[2.94,4]],"id":28338255}],"con":true,"img":false}]}
{"op":"mcm","clk":"5353364394","pt":1646213736790,"mc":[{"id":"1.195453771","rc":[{"atb":[[3.55,0]],"id":39784543},{"atb":[[3.6,0]],"id":35801684},{"atb":[[2.38,32.46]],"id":28338255},{"atl":[[2.94,2]],"id":28338255},{"atb":[[1.4,71.22]],"id":37127725}],"con":true,"img":false}]}
{"op":"mcm","clk":"5353364405","pt":1646213736996,"mc":[{"id":"1.195453771","rc":[{"atl":[[3.2,17.9]],"id":28338255}],"con":true,"img":false}]}
{"op":"mcm","clk":"5353364430","pt":1646213737474,"mc":[{"id":"1.195453771","rc":[{"atl":[[2.4,89.29]],"id":26051221}],"con":true,"img":false}]}
{"op":"mcm","clk":"5353364493","pt":1646213738498,"mc":[{"id":"1.195453771","rc":[{"atl":[[9.6,0]],"id":39784543},{"atb":[[1.32,0]],"id":26051221},{"atb":[[1.84,0]],"id":28338255}],"con":true,"img":false}]}
{"op":"mcm","clk":"5353364504","pt":1646213738601,"mc":[{"id":"1.195453771","rc":[{"atl":[[8.8,6.6]],"id":39784543},{"atb":[[1.31,90.7]],"id":26051221},{"atb":[[2.1,44.04]],"id":28338255}],"con":true,"img":false}]}
{"op":"mcm","clk":"5353364516","pt":1646213738807,"mc":[{"id":"1.195453771","rc":[{"atl":[[9,2.5],[8.8,34.16]],"id":39784543}],"con":true,"img":false}]}
{"op":"mcm","clk":"5353364746","pt":1646213742672,"mc":[{"id":"1.195453771","rc":[{"atb":[[3.6,6.93]],"id":39784543},{"atb":[[3.65,2.83]],"id":35801684},{"atb":[[1.43,17.48]],"id":37127725}],"con":true,"img":false}]}
{"op":"mcm","clk":"5353364764","pt":1646213743082,"mc":[{"id":"1.195453771","rc":[{"atl":[[2.94,0],[2.68,3]],"id":28338255}],"con":true,"img":false}]}
{"op":"mcm","clk":"5353364821","pt":1646213743707,"mc":[{"id":"1.195453771","rc":[{"atb":[[3.45,67.18],[3.5,11.33]],"id":39784543}],"con":true,"img":false}]}
{"op":"mcm","clk":"5353364857","pt":1646213744182,"mc":[{"id":"1.195453771","rc":[{"atl":[[2.66,2]],"id":28338255}],"con":true,"img":false}]}
{"op":"mcm","clk":"5353364871","pt":1646213744394,"mc":[{"id":"1.195453771","rc":[{"atl":[[3.55,7.84]],"id":28338255}],"con":true,"img":false}]}
{"op":"mcm","clk":"5353364936","pt":1646213745286,"mc":[{"id":"1.195453771","rc":[{"atl":[[2.66,0],[2.68,0]],"id":28338255}],"con":true,"img":false}]}
{"op":"mcm","clk":"5353364960","pt":1646213745697,"mc":[{"id":"1.195453771","rc":[{"atl":[[2.54,97.94],[2.84,13.15]],"id":37127725}],"con":true,"img":false}]}
{"op":"mcm","clk":"5353364964","pt":1646213745800,"mc":[{"id":"1.195453771","rc":[{"atb":[[3.6,4.04]],"id":39784543}],"con":true,"img":false}]}
{"op":"mcm","clk":"5353365162","pt":1646213749114,"mc":[{"id":"1.195453771","rc":[{"atl":[[3.55,0],[3.5,8]],"id":28338255}],"con":true,"img":false}]}
{"op":"mcm","clk":"5353365221","pt":1646213750096,"mc":[{"id":"1.195453771","rc":[{"atb":[[2.5,1.66]],"id":28338255}],"con":true,"img":false}]}
{"op":"mcm","clk":"5353365247","pt":1646213750513,"mc":[{"id":"1.195453771","rc":[{"atb":[[2.86,36.03]],"id":39784543},{"atl":[[22,13.09]],"id":39784543},{"atb":[[2.62,34.43]],"id":36500377},{"atl":[[15,16.02]],"id":36500377},{"atl":[[15,16.02]],"id":35801684},{"atl":[[17,14.7]],"id":36074638},{"atl":[[2.48,61.39]],"id":42189401},{"atl":[[3.7,4.47],[7.4,27.64]],"id":28338255},{"atb":[[1.21,128.01]],"id":37127725},{"atl":[[3.15,54.79]],"id":37127725},{"atl":[[3.3,54.43]],"id":26051221}],"con":true,"img":false}]}
{"op":"mcm","clk":"5353365254","pt":1646213750617,"mc":[{"id":"1.195453771","rc":[{"atl":[[3.8,14.53]],"id":28338255}],"con":true,"img":false}]}
{"op":"mcm","clk":"5353365333","pt":1646213751707,"mc":[{"id":"1.195453771","rc":[{"atb":[[3.55,2.94]],"id":39784543},{"atb":[[2.44,5.21]],"id":28338255}],"con":true,"img":false}]}
{"op":"mcm","clk":"5353365388","pt":1646213752494,"mc":[{"id":"1.195453771","rc":[{"atb":[[3.5,36.89],[3.45,19.81]],"id":39784543},{"atb":[[2.4,37.7]],"id":28338255},{"atb":[[1.41,78.5],[1.4,0]],"id":37127725}],"con":true,"img":false}]}
{"op":"mcm","clk":"5353365402","pt":1646213752599,"mc":[{"id":"1.195453771","rc":[{"atb":[[2.38,0]],"id":28338255}],"con":true,"img":false}]}
{"op":"mcm","clk":"5353365418","pt":1646213752803,"mc":[{"id":"1.195453771","rc":[{"atl":[[3.65,66.43]],"id":28338255}],"con":true,"img":false}]}
{"op":"mcm","clk":"5353365551","pt":1646213754723,"mc":[{"id":"1.195453771","rc":[{"atb":[[3.55,0]],"id":39784543},{"atb":[[2.44,0]],"id":28338255},{"atb":[[1.43,0]],"id":37127725}],"con":true,"img":false}]}
{"op":"mcm","clk":"5353365647","pt":1646213756292,"mc":[{"id":"1.195453771","rc":[{"atb":[[3.5,33.56]],"id":39784543},{"atb":[[2.76,47.34]],"id":36500377},{"atb":[[3.05,24.39]],"id":35801684},{"atb":[[2.04,0]],"id":28338255}],"con":true,"img":false}]}
{"op":"mcm","clk":"5353365661","pt":1646213756499,"mc":[{"id":"1.195453771","rc":[{"atl":[[8.8,27.56]],"id":39784543}],"con":true,"img":false}]}
{"op":"mcm","clk":"5353365668","pt":1646213756604,"mc":[{"id":"1.195453771","rc":[{"atl":[[8.6,6.6]],"id":39784543}],"con":true,"img":false}]}
{"op":"mcm","clk":"5353365672","pt":1646213756704,"mc":[{"id":"1.195453771","rc":[{"atl":[[8.6,34.16],[8.8,0]],"id":39784543}],"con":true,"img":false}]}
{"op":"mcm","clk":"5353365901","pt":1646213760301,"mc":[{"id":"1.195453771","rc":[{"atb":[[3.45,67.18],[3.5,8]],"id":39784543},{"atb":[[2.32,57.56],[2.4,5]],"id":28338255},{"atb":[[1.41,5],[1.37,110.68]],"id":37127725}],"con":true,"img":false}]}
{"op":"mcm","clk":"5353366258","pt":1646213766736,"mc":[{"id":"1.195453771","rc":[{"atb":[[1.4,18.79]],"id":37127725},{"atb":[[2.38,5.45]],"id":28338255}],"con":true,"img":false}]}
{"op":"mcm","clk":"5353366267","pt":1646213766840,"mc":[{"id":"1.195453771","rc":[{"atb":[[3.55,2.94]],"id":39784543},{"atl":[[9,0],[9.8,11.36],[8.8,2.5]],"id":39784543},{"atb":[[1.46,5],[1.44,15.94],[1.4,0],[1.36,31.88],[1.5,2.5],[1.42,10]],"id":26051221}],"con":true,"img":false}]}
{"op":"mcm","clk":"5353366282","pt":1646213767043,"mc":[{"id":"1.195453771","rc":[{"atb":[[1.44,56.72],[1.36,0],[1.5,22.89]],"id":26051221}],"con":true,"img":false}]}
{"op":"mcm","clk":"5353366300","pt":1646213767309,"mc":[{"id":"1.195453771","rc":[{"atb":[[1.44,40.78]],"id":26051221}],"con":true,"img":false}]}
{"op":"mcm","clk":"5353366374","pt":1646213768444,"mc":[{"id":"1.195453771","rc":[{"atb":[[2.62,0]],"id":36500377}],"con":true,"img":false}]}
{"op":"mcm","clk":"5353366384","pt":1646213768545,"mc":[{"id":"1.195453771","rc":[{"atb":[[2.52,34.43]],"id":36500377}],"con":true,"img":false}]}
{"op":"mcm","clk":"5353366420","pt":1646213769019,"mc":[{"id":"1.195453771","rc":[{"atb":[[3.5,28.56],[3.45,19.81]],"id":39784543},{"atb":[[2.32,10],[2.38,38.15]],"id":28338255},{"atb":[[1.37,10],[1.4,94.25]],"id":37127725}],"con":true,"img":false}]}
{"op":"mcm","clk":"5353366467","pt":1646213769744,"mc":[{"id":"1.195453771","rc":[{"atb":[[3.55,0]],"id":39784543},{"atb":[[2.84,21.41]],"id":36500377},{"atb":[[3.65,5.97]],"id":35801684},{"atb":[[2.38,32.7]],"id":28338255},{"atb":[[1.4,75.46]],"id":37127725}],"con":true,"img":false}]}
{"op":"mcm","clk":"5353366753","pt":1646213774454,"mc":[{"id":"1.195453771","rc":[{"atl":[[8.6,27.56]],"id":39784543}],"con":true,"img":false}]}
{"op":"mcm","clk":"5353366758","pt":1646213774555,"mc":[{"id":"1.195453771","rc":[{"atl":[[8.4,6.6]],"id":39784543}],"con":true,"img":false}]}
{"op":"mcm","clk":"5353366765","pt":1646213774660,"mc":[{"id":"1.195453771","rc":[{"atl":[[8.4,34.16],[8.6,0]],"id":39784543}],"con":true,"img":false}]}
{"op":"mcm","clk":"5353366853","pt":1646213776017,"mc":[{"id":"1.195453771","rc":[{"atb":[[3.6,6.93]],"id":39784543},{"spn":5.72,"spf":"NaN","id":39784543},{"spn":4.38,"spf":"NaN","id":36500377},{"spn":1.66,"spf":"NaN","id":42189401},{"atb":[[1.43,17.48]],"id":37127725},{"spn":1.93,"spf":"NaN","id":37127725},{"atb":[[2.44,5.21]],"id":28338255},{"spn":1.87,"spf":"NaN","id":26051221}],"con":true,"img":false}]}
{"op":"mcm","clk":"5353366876","pt":1646213776429,"mc":[{"id":"1.195453771","rc":[{"atl":[[3.8,0]],"id":28338255},{"atb":[[1.21,0]],"id":26051221}],"con":true,"img":false}]}
{"op":"mcm","clk":"5353366882","pt":1646213776528,"mc":[{"id":"1.195453771","rc":[{"atl":[[3.7,19.01]],"id":28338255},{"atb":[[1.24,128.04]],"id":26051221}],"con":true,"img":false}]}
{"op":"mcm","clk":"5353366889","pt":1646213776632,"mc":[{"id":"1.195453771","rc":[{"atb":[[2.4,37.7],[2.38,0]],"id":28338255},{"atb":[[1.41,78.5],[1.4,0]],"id":37127725}],"con":true,"img":false}]}
{"op":"mcm","clk":"5353366895","pt":1646213776733,"mc":[{"id":"1.195453771","rc":[{"atb":[[3.45,67.18],[3.5,8]],"id":39784543}],"con":true,"img":false}]}
{"op":"mcm","clk":"5353367030","pt":1646213778955,"mc":[{"id":"1.195453771","rc":[{"atb":[[3.6,4.04]],"id":39784543},{"atb":[[2.44,0]],"id":28338255},{"atb":[[1.43,0]],"id":37127725}],"con":true,"img":false}]}
{"op":"mcm","clk":"5353367203","pt":1646213782762,"mc":[{"id":"1.195453771","rc":[{"atb":[[3.55,3.26]],"id":39784543}],"con":true,"img":false}]}
{"op":"mcm","clk":"5353367300","pt":1646213784773,"mc":[{"id":"1.195453771","rc":[{"atb":[[3.55,6.21]],"id":39784543},{"atb":[[1.44,17.09]],"id":37127725}],"con":true,"img":false}]}
{"op":"mcm","clk":"5353367304","pt":1646213784826,"mc":[{"id":"1.195453771","rc":[{"atb":[[2.46,5.15]],"id":28338255}],"con":true,"img":false}]}
{"op":"mcm","clk":"5353367385","pt":1646213786429,"mc":[{"id":"1.195453771","rc":[{"atb":[[2.78,11.24]],"id":36500377},{"atb":[[1.31,0]],"id":26051221}],"con":true,"img":false}]}
{"op":"mcm","clk":"5353367393","pt":1646213786532,"mc":[{"id":"1.195453771","rc":[{"atb":[[2.86,25.36]],"id":36500377},{"atb":[[1.33,90.7]],"id":26051221}],"con":true,"img":false}]}
{"op":"mcm","clk":"5353367465","pt":1646213787764,"mc":[{"id":"1.195453771","rc":[{"atb":[[2.84,17.33]],"id":36500377}],"con":true,"img":false}]}
{"op":"mcm","clk":"5353367681","pt":1646213792459,"mc":[{"id":"1.195453771","rc":[{"atl":[[8.4,27.56]],"id":39784543},{"atb":[[2.86,1.66]],"id":36500377}],"con":true,"img":false}]}
{"op":"mcm","clk":"5353367689","pt":1646213792561,"mc":[{"id":"1.195453771","rc":[{"atl":[[8.2,6.6]],"id":39784543},{"atb":[[2.78,34.93]],"id":36500377}],"con":true,"img":false}]}
{"op":"mcm","clk":"5353367780","pt":1646213794462,"mc":[{"id":"1.195453771","rc":[{"atb":[[2.1,0],[2.46,10.86]],"id":28338255}],"con":true,"img":false}]}
{"op":"mcm","clk":"5353367785","pt":1646213794564,"mc":[{"id":"1.195453771","rc":[{"atb":[[2.14,44.04]],"id":28338255}],"con":true,"img":false}]}
{"op":"mcm","clk":"5353367790","pt":1646213794665,"mc":[{"id":"1.195453771","rc":[{"atb":[[1.44,36.03]],"id":37127725}],"con":true,"img":false}]}
{"op":"mcm","clk":"5353367851","pt":1646213795654,"mc":[{"id":"1.195453771","rc":[{"atb":[[3.5,0],[3.3,0],[3.2,0],[3.4,0]],"id":39784543},{"atl":[[10.5,0],[11.5,0],[12.5,0],[13.5,0]],"id":39784543},{"atb":[[2.74,0],[2.66,0],[2.78,23.69],[2.7,35.58]],"id":36500377},{"atl":[[7.2,0],[6.4,0],[6,0],[6.8,0]],"id":36500377},{"atb":[[2.98,0],[2.94,0],[3.05,0],[3.15,0]],"id":35801684},{"atl":[[7.2,0],[6.4,6.71],[6.8,13.42],[7.6,0]],"id":35801684},{"atb":[[2.8,67.21],[2.72,26.8],[2.84,0],[2.76,0]],"id":36074638},{"atl":[[6.2,0],[7.4,0],[6.6,0],[7,0]],"id":36074638},{"atb":[[1.33,0],[1.27,0],[1.29,0],[1.31,0]],"id":28338255},{"atl":[[3.85,0],[3.5,0],[3.65,47.56],[3.75,0]],"id":28338255},{"atb":[[1.23,0],[1.27,0],[1.25,483.95],[1.29,0]],"id":26051221},{"atl":[[2.32,0],[2.36,0],[2.4,0],[2.28,38.45]],"id":26051221}],"con":true,"img":false}]}
{"op":"mcm","clk":"5353367873","pt":1646213796061,"mc":[{"id":"1.195453771","rc":[{"atb":[[1.2,0],[1.26,76.23],[1.22,0],[1.24,0]],"id":42189401},{"atl":[[2.04,0],[2.18,0],[2.1,119.22],[2.14,0]],"id":42189401},{"atb":[[1.23,0],[1.27,0],[1.25,241.97],[1.3,0]],"id":37127725},{"atl":[[3.3,0],[3.5,0],[3.2,45.45],[3.4,0]],"id":37127725}],"con":true,"img":false}]}
{"op":"mcm","clk":"5353367910","pt":1646213796472,"mc":[{"id":"1.195453771","rc":[{"atl":[[6.6,2.15]],"id":35801684},{"atb":[[1.24,0]],"id":26051221}],"con":true,"img":false}]}
{"op":"mcm","clk":"5353367923","pt":1646213796574,"mc":[{"id":"1.195453771","rc":[{"atl":[[8.4,6.81]],"id":35801684},{"atb":[[1.21,128.04]],"id":26051221}],"con":true,"img":false}]}
{"op":"mcm","clk":"5353368040","pt":1646213798483,"mc":[{"id":"1.195453771","rc":[{"atl":[[2.26,0]],"id":26051221}],"con":true,"img":false}]}
{"op":"mcm","clk":"5353368048","pt":1646213798614,"mc":[{"id":"1.195453771","rc":[{"atl":[[2.52,34.6]],"id":26051221}],"con":true,"img":false}]}
{"op":"mcm","clk":"5353368074","pt":1646213799055,"mc":[{"id":"1.195453771","rc":[{"atl":[[8.2,25.84],[8.4,0]],"id":39784543},{"atl":[[6.2,27.3],[6.8,2.5],[7.6,5],[6.6,46.94],[5.9,0],[8.4,10]],"id":36500377},{"atl":[[8.2,2.5]],"id":35801684},{"atl":[[8.6,10],[6.4,26.03],[6,0],[7.8,44.67],[7,2.5]],"id":36074638},{"atl":[[2.28,139.13],[2.1,0]],"id":42189401},{"atl":[[2.24,0],[2.54,59.06]],"id":26051221},{"atl":[[3.7,74.39],[3.65,0]],"id":28338255}],"con":true,"img":false}]}
{"op":"mcm","clk":"5353368080","pt":1646213799158,"mc":[{"id":"1.195453771","rc":[{"atl":[[2.28,0]],"id":26051221}],"con":true,"img":false}]}
