{"op":"mcm","clk":"5305619429","pt":1646080581432,"mc":[{"id":"1.195395429","marketDefinition":{"bspMarket":true,"turnInPlayEnabled":false,"persistenceEnabled":false,"marketBaseRate":7.0,"eventId":"31270458","eventTypeId":"4339","numberOfWinners":1,"bettingType":"ODDS","marketType":"WIN","marketTime":"2022-03-01T03:42:00.000Z","suspendTime":"2022-03-01T03:42:00.000Z","bspReconciled":false,"complete":true,"inPlay":false,"crossMatching":false,"runnersVoidable":false,"numberOfActiveRunners":8,"betDelay":0,"status":"OPEN","runners":[{"status":"ACTIVE","sortPriority":1,"id":40494181,"name":"1. Loch And Loaded"},{"status":"ACTIVE","sortPriority":2,"id":38206580,"name":"2. Buckle Up Wilder"},{"status":"ACTIVE","sortPriority":3,"id":38206560,"name":"3. Hiccup Amisha"},{"status":"ACTIVE","sortPriority":4,"id":36104895,"name":"4. Langley Roo"},{"status":"ACTIVE","sortPriority":5,"id":39520250,"name":"5. Rip On Bye"},{"status":"ACTIVE","sortPriority":6,"id":41762283,"name":"6. Gracies Joy"},{"status":"ACTIVE","sortPriority":7,"id":37401228,"name":"7. Just Mercy"},{"status":"ACTIVE","sortPriority":8,"id":27701417,"name":"8. Jalla General"}],"regulators":["MR_INT"],"venue":"Devonport","countryCode":"AU","discountAllowed":true,"timezone":"Australia/Sydney","openDate":"2022-03-01T02:00:00.000Z","version":4380714802,"name":"R6 452m Gr4","eventName":"Devonport (AUS) 1st Mar"},"rc":[],"con":true,"img":false}]}
{"op":"mcm","clk":"5305743101","pt":1646082026907,"mc":[{"id":"1.195395429","rc":[{"atb":[[16.5,6.54],[20,5.34],[11.5,9.66],[14,7.8]],"id":39520250},{"atl":[[260,0.76],[310,0.64],[160,0.83],[210,0.63]],"id":39520250},{"spn":90.0,"spf":"NaN","id":39520250},{"atb":[[9.6,11.8],[17.5,6.14],[11.5,9.66],[14,7.8]],"id":36104895},{"atl":[[140,0.95],[290,0.68],[190,0.69],[240,0.82]],"id":36104895},{"spn":78.75,"spf":"NaN","id":36104895},{"atb":[[4.8,26.7],[4.3,30.75],[5.3,23.6],[6,20.29]],"id":38206580},{"atl":[[36,5.66],[19,7.34],[23,6],[28,7.34]],"id":38206580},{"spn":12.5,"spf":"NaN","id":38206580},{"atb":[[18,5.97],[21,5.07],[28,3.75],[15.5,6.99]],"id":27701417},{"atl":[[290,0.45],[340,0.58],[390,0.5],[240,0.55]],"id":27701417},{"spn":134.0,"spf":"NaN","id":27701417},{"atb":[[9.6,11.8],[8.6,13.35],[7.6,15.37],[12.5,8.82]],"id":38206560},{"atl":[[130,1.02],[90,1.48],[180,1.1],[230,0.86]],"id":38206560},{"spn":51.25,"spf":"NaN","id":38206560},{"atb":[[4.5,28.99],[6.4,18.79],[5,25.37],[5.5,22.55]],"id":41762283},{"atl":[[19.5,7.14],[38,5.35],[24,5.74],[29,7.08]],"id":41762283},{"spn":12.95,"spf":"NaN","id":41762283},{"atb":[[5,25.37],[5.5,22.55],[7.4,15.86],[6,20.29]],"id":37401228},{"atl":[[70,2.87],[38,3.57],[48,4.21],[29,4.72]],"id":37401228},{"spn":18.2,"spf":"NaN","id":37401228},{"atb":[[1.18,563.85],[1.23,441.27],[1.3,338.31],[1.13,780.72]],"id":40494181},{"atl":[[2.8,110.15],[2.5,88.12],[2.6,82.61],[2.7,116.63]],"id":40494181},{"spn":1.9,"spf":"NaN","id":40494181}],"con":true,"img":false}]}
{"op":"mcm","clk":"5305747397","pt":1646082083779,"mc":[{"id":"1.195395429","rc":[{"atb":[[16.5,0],[20,0],[11.5,0],[14,0]],"id":39520250},{"atl":[[260,0],[310,0],[160,0],[210,0]],"id":39520250},{"atb":[[9.6,0],[17.5,0],[11.5,0],[14,0]],"id":36104895},{"atl":[[140,0],[290,0],[190,0],[240,0]],"id":36104895},{"atb":[[4.8,0],[4.3,0],[5.3,0],[6,0]],"id":38206580},{"atl":[[36,0],[19,0],[23,0],[28,0]],"id":38206580},{"atb":[[18,0],[21,0],[28,0],[15.5,0]],"id":27701417},{"atl":[[290,0],[340,0],[390,0],[240,0]],"id":27701417},{"atb":[[9.6,0],[8.6,0],[7.6,0],[12.5,0]],"id":38206560},{"atl":[[130,0],[90,0],[180,0],[230,0]],"id":38206560},{"atb":[[4.5,0],[6.4,0],[5,0],[5.5,0]],"id":41762283},{"atl":[[19.5,0],[38,0],[24,0],[29,0]],"id":41762283},{"atb":[[5,0],[5.5,0],[7.4,0],[6,0]],"id":37401228},{"atl":[[70,0],[38,0],[48,0],[29,0]],"id":37401228},{"atb":[[1.18,0],[1.23,0],[1.3,0],[1.13,0]],"id":40494181},{"atl":[[2.8,0],[2.5,0],[2.6,0],[2.7,0]],"id":40494181}],"con":true,"img":false}]}
{"op":"mcm","clk":"5305747684","pt":1646082087094,"mc":[{"id":"1.195395429","rc":[{"atb":[[16.5,6.54],[20,5.34],[11.5,9.66],[14,7.8]],"id":39520250},{"atl":[[260,0.76],[310,0.64],[160,0.83],[210,0.63]],"id":39520250},{"atb":[[9.6,11.8],[17.5,6.14],[11.5,9.66],[14,7.8]],"id":36104895},{"atl":[[140,0.95],[290,0.68],[190,0.69],[240,0.82]],"id":36104895},{"atb":[[4.8,26.7],[4.3,30.75],[5.3,23.6],[6,20.29]],"id":38206580},{"atl":[[36,5.66],[19,7.34],[23,6],[28,7.34]],"id":38206580},{"atb":[[18,5.97],[21,5.07],[28,3.75],[15.5,6.99]],"id":27701417},{"atl":[[290,0.45],[340,0.58],[390,0.5],[240,0.55]],"id":27701417},{"atb":[[9.6,11.8],[8.6,13.35],[7.6,15.37],[12.5,8.82]],"id":38206560},{"atl":[[130,1.02],[90,1.48],[180,1.1],[230,0.86]],"id":38206560},{"atb":[[4.5,28.99],[6.4,18.79],[5,25.37],[5.5,22.55]],"id":41762283},{"atl":[[19.5,7.14],[38,5.35],[24,5.74],[29,7.08]],"id":41762283},{"atb":[[5,25.37],[5.5,22.55],[7.4,15.86],[6,20.29]],"id":37401228},{"atl":[[70,2.87],[38,3.57],[48,4.21],[29,4.72]],"id":37401228},{"atb":[[1.18,563.85],[1.23,441.27],[1.3,338.31],[1.13,780.72]],"id":40494181},{"atl":[[2.8,110.15],[2.5,88.12],[2.6,82.61],[2.7,116.63]],"id":40494181}],"con":true,"img":false}]}
{"op":"mcm","clk":"5305888880","pt":1646084024455,"mc":[{"id":"1.195395429","rc":[{"spl":[[1.3,54.13]],"id":40494181},{"spn":1.3,"spf":1.0,"id":40494181}],"con":true,"img":false}]}
{"op":"mcm","clk":"5305980431","pt":1646086479392,"mc":[{"id":"1.195395429","rc":[{"atb":[[16.5,6.54],[20,5.34],[11.5,9.66],[14,7.8]],"id":39520250},{"atl":[[260,0.76],[310,0.64],[160,0.83],[210,0.63]],"id":39520250},{"atb":[[9.6,11.79],[17.5,6.14],[11.5,9.66],[14,7.8]],"id":36104895},{"atl":[[140,0.95],[290,0.68],[190,0.69],[240,0.82]],"id":36104895},{"atb":[[4.8,26.7],[4.3,30.75],[5.3,23.59],[6,20.29]],"id":38206580},{"atl":[[36,5.66],[19,7.34],[23,6],[28,7.34]],"id":38206580},{"atb":[[18,5.96],[21,5.07],[28,3.75],[15.5,6.99]],"id":27701417},{"atb":[[9.6,11.79],[8.6,13.35],[7.6,15.37],[12.5,8.82]],"id":38206560},{"atl":[[130,1.02],[90,1.48],[180,1.1],[230,0.86]],"id":38206560},{"atb":[[4.5,28.99],[6.4,18.79],[5,25.37],[5.5,22.55]],"id":41762283},{"atl":[[19.5,7.14],[38,5.35],[24,5.74],[29,7.07]],"id":41762283},{"atb":[[5,25.37],[5.5,22.55],[7.4,15.85],[6,20.29]],"id":37401228},{"atl":[[70,2.87],[38,3.57],[48,4.21],[29,4.71]],"id":37401228},{"atb":[[1.18,563.76],[1.23,441.2],[1.3,338.25],[1.13,780.59]],"id":40494181},{"spl":[[1.3,54.12]],"id":40494181},{"atl":[[2.8,110.13],[2.5,88.1],[2.38,21.64],[2.6,82.6],[2.7,116.61]],"id":40494181}],"con":true,"img":false}]}
{"op":"mcm","clk":"5305990539","pt":1646086602700,"mc":[{"id":"1.195395429","marketDefinition":{"bspMarket":true,"turnInPlayEnabled":false,"persistenceEnabled":false,"marketBaseRate":7.0,"eventId":"31270458","eventTypeId":"4339","numberOfWinners":1,"bettingType":"ODDS","marketType":"WIN","marketTime":"2022-03-01T03:42:00.000Z","suspendTime":"2022-03-01T03:42:00.000Z","bspReconciled":false,"complete":true,"inPlay":false,"crossMatching":false,"runnersVoidable":false,"numberOfActiveRunners":8,"betDelay":0,"status":"OPEN","runners":[{"status":"ACTIVE","sortPriority":1,"id":40494181,"name":"1. Loch And Loaded"},{"status":"ACTIVE","sortPriority":2,"id":38206580,"name":"2. Buckle Up Wilder"},{"status":"ACTIVE","sortPriority":3,"id":38206560,"name":"3. Hiccup Amisha"},{"status":"ACTIVE","sortPriority":4,"id":36104895,"name":"4. Langley Roo"},{"status":"ACTIVE","sortPriority":5,"id":39520250,"name":"5. Rip On Bye"},{"status":"ACTIVE","sortPriority":6,"id":41762283,"name":"6. Gracies Joy"},{"status":"ACTIVE","sortPriority":7,"id":37401228,"name":"7. Just Mercy"},{"status":"ACTIVE","sortPriority":8,"id":27701417,"name":"8. Jalla General"}],"regulators":["MR_INT"],"venue":"Devonport","countryCode":"AU","discountAllowed":true,"timezone":"Australia/Sydney","openDate":"2022-03-01T02:00:00.000Z","version":4380714802,"name":"R6 452m Gr4","eventName":"Devonport (AUS) 1st Mar"},"rc":[{"atb":[[16.5,6.54],[20,5.34],[11.5,9.66],[14,7.8]],"id":39520250},{"atl":[[260,0.76],[310,0.64],[160,0.83],[210,0.63]],"id":39520250},{"spn":90.0,"spf":"NaN","id":39520250},{"atb":[[9.6,11.79],[17.5,6.14],[11.5,9.66],[14,7.8]],"id":36104895},{"atl":[[140,0.95],[290,0.68],[190,0.69],[240,0.82]],"id":36104895},{"spn":78.75,"spf":"NaN","id":36104895},{"atb":[[4.8,26.7],[4.3,30.75],[5.3,23.59],[6,20.29]],"id":38206580},{"atl":[[36,5.66],[19,7.34],[23,6],[28,7.34]],"id":38206580},{"spn":12.5,"spf":"NaN","id":38206580},{"atb":[[18,5.96],[21,5.07],[28,3.75],[15.5,6.99]],"id":27701417},{"atl":[[290,0.45],[340,0.58],[390,0.5],[240,0.55]],"id":27701417},{"spn":134.0,"spf":"NaN","id":27701417},{"atb":[[9.6,11.79],[8.6,13.35],[7.6,15.37],[12.5,8.82]],"id":38206560},{"atl":[[130,1.02],[90,1.48],[180,1.1],[230,0.86]],"id":38206560},{"spn":51.25,"spf":"NaN","id":38206560},{"atb":[[4.5,28.99],[6.4,18.79],[5,25.37],[5.5,22.55]],"id":41762283},{"atl":[[19.5,7.14],[38,5.35],[24,5.74],[29,7.07]],"id":41762283},{"spn":12.95,"spf":"NaN","id":41762283},{"atb":[[5,25.37],[5.5,22.55],[7.4,15.85],[6,20.29]],"id":37401228},{"atl":[[70,2.87],[38,3.57],[48,4.21],[29,4.71]],"id":37401228},{"spn":18.2,"spf":"NaN","id":37401228},{"atb":[[1.18,563.76],[1.23,441.2],[1.3,338.25],[1.13,780.59]],"id":40494181},{"spl":[[1.3,54.12]],"id":40494181},{"atl":[[2.8,110.13],[2.5,88.1],[2.38,21.64],[2.6,82.6],[2.7,116.61]],"id":40494181},{"spn":1.3,"spf":1.0,"id":40494181}],"con":true,"img":true}]}
{"op":"mcm","clk":"5306064315","pt":1646088413503,"mc":[{"id":"1.195395429","rc":[{"atb":[[16.5,0],[20,0],[11.5,0],[14,0]],"id":39520250},{"atl":[[260,0],[310,0],[160,0],[210,0]],"id":39520250},{"spn":"NaN","spf":"NaN","id":39520250},{"atb":[[4.8,0],[4.3,0],[5.3,0],[6,0]],"id":38206580},{"atl":[[36,0],[19,0],[23,0],[28,0]],"id":38206580},{"spn":"NaN","spf":"NaN","id":38206580},{"atb":[[18,0],[21,0],[28,0],[15.5,0]],"id":27701417},{"atl":[[290,0],[340,0],[390,0],[240,0]],"id":27701417},{"spn":"NaN","spf":"NaN","id":27701417},{"atb":[[4.5,0],[6.4,0],[5,0],[5.5,0]],"id":41762283},{"atl":[[19.5,0],[38,0],[24,0],[29,0]],"id":41762283},{"spn":"NaN","spf":"NaN","id":41762283},{"atb":[[5,0],[5.5,0],[7.4,0],[6,0]],"id":37401228},{"atl":[[70,0],[38,0],[48,0],[29,0]],"id":37401228},{"spn":"NaN","spf":"NaN","id":37401228},{"atb":[[1.18,0],[1.23,0],[1.3,0],[1.13,0]],"id":40494181},{"atl":[[2.8,0],[2.5,0],[2.6,0],[2.7,0]],"id":40494181},{"spn":1.0,"spf":1.0,"id":40494181}],"con":true,"img":false}]}
{"op":"mcm","clk":"5306064604","pt":1646088420529,"mc":[{"id":"1.195395429","rc":[{"atb":[[16.5,6.54],[20,5.34],[11.5,9.66],[14,7.8]],"id":39520250},{"atl":[[260,0.76],[310,0.64],[160,0.83],[210,0.63]],"id":39520250},{"atb":[[4.8,26.7],[4.3,30.75],[5.3,23.59],[6,20.29]],"id":38206580},{"atl":[[36,5.66],[19,7.34],[23,6],[28,7.34]],"id":38206580},{"atb":[[18,5.96],[21,5.07],[28,3.75],[15.5,6.99]],"id":27701417},{"atl":[[290,0.45],[340,0.58],[390,0.5],[240,0.55]],"id":27701417},{"atb":[[4.5,28.99],[6.4,18.79],[5,25.37],[5.5,22.55]],"id":41762283},{"atl":[[19.5,7.14],[38,5.35],[24,5.74],[29,7.07]],"id":41762283},{"atb":[[5,25.37],[5.5,22.55],[7.4,15.85],[6,20.29]],"id":37401228},{"atl":[[70,2.87],[38,3.57],[48,4.21],[29,4.71]],"id":37401228},{"atb":[[1.2,507.38],[1.25,405.91],[1.15,676.51],[1.32,317.11]],"id":40494181},{"atl":[[2.54,85.82],[2.74,113.93],[2.64,80.58],[2.84,107.74]],"id":40494181}],"con":true,"img":false}]}
{"op":"mcm","clk":"5306086901","pt":1646088981482,"mc":[{"id":"1.195395429","rc":[{"spn":90.0,"spf":"NaN","id":39520250},{"spn":12.5,"spf":"NaN","id":38206580},{"spn":134.0,"spf":"NaN","id":27701417},{"atb":[[9.6,0],[8.6,0],[7.6,0],[12.5,0]],"id":38206560},{"atl":[[130,0],[90,0],[180,0],[230,0]],"id":38206560},{"spn":"NaN","spf":"NaN","id":38206560},{"spn":12.95,"spf":"NaN","id":41762283},{"spn":18.2,"spf":"NaN","id":37401228},{"atb":[[1.2,0],[1.25,0],[1.15,0],[1.32,0]],"id":40494181},{"atl":[[2.54,0],[2.74,0],[2.64,0],[2.84,0]],"id":40494181}],"con":true,"img":false}]}
{"op":"mcm","clk":"5306087014","pt":1646088984565,"mc":[{"id":"1.195395429","rc":[{"atb":[[8,14.49],[9,12.68],[10,11.27],[13.5,8.11]],"id":38206560},{"atl":[[150,0.88],[100,1.33],[200,0.99],[250,0.79]],"id":38206560},{"atb":[[1.18,563.76],[1.23,441.2],[1.3,338.25],[1.13,780.59]],"id":40494181},{"atl":[[2.8,110.13],[2.5,88.1],[2.6,82.6],[2.7,116.61]],"id":40494181}],"con":true,"img":false}]}
{"op":"mcm","clk":"5306089056","pt":1646089041275,"mc":[{"id":"1.195395429","rc":[{"atb":[[8,0],[9,0],[10,0],[13.5,0]],"id":38206560},{"atl":[[150,0],[100,0],[200,0],[250,0]],"id":38206560}],"con":true,"img":false}]}
{"op":"mcm","clk":"5306089193","pt":1646089044467,"mc":[{"id":"1.195395429","rc":[{"atb":[[8,14.49],[9,12.68],[10,11.27],[13.5,8.11]],"id":38206560},{"atl":[[150,0.88],[100,1.33],[200,0.99],[250,0.79]],"id":38206560},{"spn":56.75,"spf":"NaN","id":38206560},{"spn":1.3,"spf":1.0,"id":40494181}],"con":true,"img":false}]}
{"op":"mcm","clk":"5306090270","pt":1646089072441,"mc":[{"id":"1.195395429","rc":[{"atb":[[9.6,0],[17.5,0],[11.5,0],[14,0]],"id":36104895},{"atl":[[140,0],[290,0],[190,0],[240,0]],"id":36104895},{"atb":[[4.8,0],[4.3,0],[5.3,0],[6,0]],"id":38206580},{"atl":[[36,0],[19,0],[23,0],[28,0]],"id":38206580},{"atb":[[8,0],[9,0],[10,0],[13.5,0]],"id":38206560},{"atl":[[150,0],[100,0],[200,0],[250,0]],"id":38206560},{"atb":[[5,0],[5.5,0],[7.4,0],[6,0]],"id":37401228},{"atl":[[70,0],[38,0],[48,0],[29,0]],"id":37401228}],"con":true,"img":false}]}
{"op":"mcm","clk":"5306090450","pt":1646089076413,"mc":[{"id":"1.195395429","rc":[{"atb":[[19,5.63],[10.5,10.68],[13,8.45],[15.5,6.99]],"id":36104895},{"atl":[[150,0.88],[300,0.66],[200,0.66],[250,0.79]],"id":36104895},{"atb":[[4.8,26.7],[4.3,30.75],[5.3,23.59],[6,20.29]],"id":38206580},{"atl":[[36,5.66],[19,7.34],[23,6],[28,7.34]],"id":38206580},{"atb":[[8,14.49],[9,12.68],[10,11.27],[13.5,8.11]],"id":38206560},{"atl":[[150,0.88],[100,1.33],[200,0.99],[250,0.79]],"id":38206560},{"atb":[[5,25.37],[5.5,22.55],[7.4,15.85],[6,20.29]],"id":37401228},{"atl":[[70,2.87],[38,3.57],[48,4.21],[29,4.71]],"id":37401228}],"con":true,"img":false}]}
{"op":"mcm","clk":"5306112322","pt":1646089707549,"mc":[{"id":"1.195395429","rc":[{"spl":[[100,2]],"id":39520250},{"spn":60.0,"spf":1.0,"id":39520250},{"spl":[[100,2]],"id":36104895},{"spn":59.5,"spf":1.0,"id":36104895},{"spl":[[100,2]],"id":38206580},{"spn":12.5,"spf":1.0,"id":38206580},{"spl":[[100,2]],"id":27701417},{"spn":64.0,"spf":1.0,"id":27701417},{"spl":[[100,2]],"id":38206560},{"spn":56.75,"spf":1.0,"id":38206560},{"spl":[[100,2]],"id":41762283},{"spn":12.95,"spf":1.0,"id":41762283},{"spl":[[100,2]],"id":37401228},{"spn":18.2,"spf":1.0,"id":37401228},{"spl":[[100,2]],"id":40494181}],"con":true,"img":false}]}
{"op":"mcm","clk":"5306331392","pt":1646095692643,"mc":[{"id":"1.195395429","rc":[{"atb":[[16.5,6.54],[20,5.33],[11.5,9.65],[14,7.79]],"id":39520250},{"atl":[[260,0.76],[310,0.64],[160,0.83],[210,0.63]],"id":39520250},{"atb":[[19,5.63],[10.5,10.67],[13,8.45],[15.5,6.99]],"id":36104895},{"atl":[[150,0.88],[300,0.66],[200,0.66],[250,0.79]],"id":36104895},{"atb":[[4.8,26.68],[4.3,30.73],[5.3,23.58],[6,20.28]],"id":38206580},{"atl":[[36,5.66],[19,7.33],[23,6],[28,7.33]],"id":38206580},{"atb":[[18,5.96],[21,5.07],[28,3.75],[15.5,6.99]],"id":27701417},{"atl":[[290,0.45],[340,0.58],[390,0.5],[240,0.55]],"id":27701417},{"atb":[[8,14.48],[9,12.67],[10,11.26],[13.5,8.11]],"id":38206560},{"atl":[[150,0.88],[100,1.33],[200,0.99],[250,0.79]],"id":38206560},{"atb":[[4.5,28.97],[6.4,18.77],[5,25.35],[5.5,22.53]],"id":41762283},{"atl":[[19.5,7.13],[38,5.35],[24,5.74],[29,7.07]],"id":41762283},{"atb":[[5,25.35],[5.5,22.53],[7.4,15.84],[6,20.28]],"id":37401228},{"spl":[[8.6,2.7]],"id":37401228},{"atl":[[70,2.87],[38,3.56],[48,4.21],[29,4.71]],"id":37401228},{"spn":8.0,"spf":1.0,"id":37401228},{"atb":[[1.18,563.39],[1.23,440.92],[1.3,338.03],[1.13,780.09]],"id":40494181},{"spl":[[1.3,54.08]],"id":40494181},{"atl":[[2.8,110.06],[2.5,88.05],[2.38,21.63],[2.6,82.55],[2.7,116.53]],"id":40494181}],"con":true,"img":false}]}
{"op":"mcm","clk":"5306352568","pt":1646096212700,"mc":[{"id":"1.195395429","rc":[{"atb":[[16.5,0],[20,0],[11.5,0],[14,0]],"id":39520250},{"atl":[[260,0],[310,0],[160,0],[210,0]],"id":39520250},{"spn":1.0,"spf":1.0,"id":39520250},{"atb":[[19,0],[10.5,0],[13,0],[15.5,0]],"id":36104895},{"atl":[[150,0],[300,0],[200,0],[250,0]],"id":36104895},{"spn":1.0,"spf":1.0,"id":36104895},{"atb":[[18,0],[21,0],[28,0],[15.5,0]],"id":27701417},{"atl":[[290,0],[340,0],[390,0],[240,0]],"id":27701417},{"spn":1.0,"spf":1.0,"id":27701417},{"atb":[[8,0],[9,0],[10,0],[13.5,0]],"id":38206560},{"atl":[[150,0],[100,0],[200,0],[250,0]],"id":38206560},{"spn":1.0,"spf":1.0,"id":38206560},{"atb":[[4.5,0],[6.4,0],[5,0],[5.5,0]],"id":41762283},{"atl":[[19.5,0],[38,0],[24,0],[29,0]],"id":41762283},{"spn":1.0,"spf":1.0,"id":41762283},{"atb":[[5,0],[5.5,0],[7.4,0],[6,0]],"id":37401228},{"atl":[[70,0],[38,0],[48,0],[29,0]],"id":37401228},{"spn":1.0,"spf":1.0,"id":37401228}],"con":true,"img":false}]}
{"op":"mcm","clk":"5306353027","pt":1646096223872,"mc":[{"id":"1.195395429","rc":[{"atb":[[16.5,6.54],[20,5.33],[11.5,9.65],[14,7.79]],"id":39520250},{"atl":[[260,0.76],[310,0.64],[160,0.83],[210,0.63]],"id":39520250},{"atb":[[19,5.63],[10.5,10.67],[13,8.45],[15.5,6.99]],"id":36104895},{"atl":[[150,0.88],[300,0.66],[200,0.66],[250,0.79]],"id":36104895},{"atb":[[18,5.96],[21,5.07],[28,3.75],[15.5,6.99]],"id":27701417},{"atl":[[290,0.45],[340,0.58],[390,0.5],[240,0.55]],"id":27701417},{"atb":[[8,14.48],[9,12.67],[10,11.26],[13.5,8.11]],"id":38206560},{"atl":[[150,0.88],[100,1.33],[200,0.99],[250,0.79]],"id":38206560},{"atb":[[4.5,28.97],[6.4,18.77],[5,25.35],[5.5,22.53]],"id":41762283},{"atl":[[19.5,7.13],[38,5.35],[24,5.74],[29,7.07]],"id":41762283},{"atb":[[5,25.35],[5.5,22.53],[7.4,15.84],[6,20.28]],"id":37401228},{"atl":[[70,2.87],[38,3.56],[48,4.21],[29,4.71]],"id":37401228}],"con":true,"img":false}]}
{"op":"mcm","clk":"5306354785","pt":1646096272772,"mc":[{"id":"1.195395429","rc":[{"atb":[[16.5,0],[20,0],[11.5,0],[14,0]],"id":39520250},{"atl":[[260,0],[310,0],[160,0],[210,0]],"id":39520250},{"atb":[[19,0],[10.5,0],[13,0],[15.5,0]],"id":36104895},{"atl":[[150,0],[300,0],[200,0],[250,0]],"id":36104895},{"atb":[[4.8,0],[4.3,0],[5.3,0],[6,0]],"id":38206580},{"atl":[[36,0],[19,0],[23,0],[28,0]],"id":38206580},{"spn":1.0,"spf":1.0,"id":38206580},{"atb":[[18,0],[21,0],[28,0],[15.5,0]],"id":27701417},{"atl":[[290,0],[340,0],[390,0],[240,0]],"id":27701417},{"atb":[[8,0],[9,0],[10,0],[13.5,0]],"id":38206560},{"atl":[[150,0],[100,0],[200,0],[250,0]],"id":38206560},{"atb":[[4.5,0],[6.4,0],[5,0],[5.5,0]],"id":41762283},{"atl":[[19.5,0],[38,0],[24,0],[29,0]],"id":41762283},{"atb":[[5,0],[5.5,0],[7.4,0],[6,0]],"id":37401228},{"atl":[[70,0],[38,0],[48,0],[29,0]],"id":37401228},{"atb":[[1.18,0],[1.23,0],[1.3,0],[1.13,0]],"id":40494181},{"atl":[[2.8,0],[2.5,0],[2.6,0],[2.7,0]],"id":40494181},{"spn":1.0,"spf":1.0,"id":40494181}],"con":true,"img":false}]}
{"op":"mcm","clk":"5306355053","pt":1646096280487,"mc":[{"id":"1.195395429","rc":[{"atb":[[11,10.14],[14.5,7.51],[8.4,13.7],[9.4,12.07]],"id":39520250},{"atl":[[260,0.76],[160,0.83],[210,0.94],[110,1.21]],"id":39520250},{"atb":[[16.5,6.54],[20,5.33],[11.5,9.65],[14,7.79]],"id":36104895},{"atl":[[260,0.76],[310,0.64],[160,0.83],[210,0.63]],"id":36104895},{"atb":[[4.5,28.97],[6.4,18.77],[5,25.35],[5.5,22.53]],"id":38206580},{"atl":[[19.5,7.13],[38,5.35],[24,5.74],[29,7.07]],"id":38206580},{"atb":[[18,5.96],[21,5.07],[28,3.75],[15.5,6.99]],"id":27701417},{"atl":[[290,0.45],[340,0.58],[390,0.5],[240,0.55]],"id":27701417},{"atb":[[12,9.22],[9.8,11.52],[8.8,13],[15.5,6.99]],"id":38206560},{"atl":[[270,0.73],[170,0.77],[220,0.9],[120,1.1]],"id":38206560},{"atb":[[4.5,28.97],[6.4,18.77],[5,25.35],[5.5,22.53]],"id":41762283},{"atl":[[19.5,7.13],[38,5.35],[24,5.74],[29,7.07]],"id":41762283},{"atb":[[8,14.48],[5.8,21.12],[5.3,23.58],[6.6,18.1]],"id":37401228},{"atl":[[65,3.09],[36,3.77],[90,2.22],[46,2.93]],"id":37401228},{"atb":[[1.2,507.05],[1.25,405.64],[1.15,676.07],[1.32,316.91]],"id":40494181},{"atl":[[2.54,85.76],[2.74,113.86],[2.64,80.53],[2.84,107.67]],"id":40494181}],"con":true,"img":false}]}
{"op":"mcm","clk":"5306358257","pt":1646096361770,"mc":[{"id":"1.195395429","rc":[{"atb":[[11,0],[14.5,0],[8.4,0],[9.4,0]],"id":39520250},{"atl":[[260,0],[160,0],[210,0],[110,0]],"id":39520250},{"atb":[[16.5,0],[20,0],[11.5,0],[14,0]],"id":36104895},{"atl":[[260,0],[310,0],[160,0],[210,0]],"id":36104895},{"spn":12.95,"spf":1.0,"id":38206580},{"spn":64.0,"spf":1.0,"id":27701417},{"spn":57.75,"spf":1.0,"id":38206560},{"spn":12.95,"spf":1.0,"id":41762283},{"atb":[[8,0],[5.8,0],[5.3,0],[6.6,0]],"id":37401228},{"atl":[[65,0],[36,0],[90,0],[46,0]],"id":37401228},{"spn":1.32,"spf":1.0,"id":40494181}],"con":true,"img":false}]}
{"op":"mcm","clk":"5306358450","pt":1646096366444,"mc":[{"id":"1.195395429","rc":[{"atb":[[7.2,16.35],[9.2,12.36],[8.2,14.08],[11.5,9.65]],"id":39520250},{"atl":[[80,1.67],[160,1.24],[210,0.94],[110,1.21]],"id":39520250},{"atb":[[18,5.96],[23,4.6],[13,8.45],[15.5,6.99]],"id":36104895},{"atl":[[300,0.66],[350,0.56],[200,0.66],[250,0.53]],"id":36104895},{"atb":[[5,25.35],[5.5,22.53],[7.4,15.84],[6,20.28]],"id":37401228},{"atl":[[70,2.87],[38,3.56],[48,4.21],[29,4.71]],"id":37401228}],"con":true,"img":false}]}
{"op":"mcm","clk":"5306387136","pt":1646097082158,"mc":[{"id":"1.195395429","rc":[{"atb":[[7.2,0],[9.2,0],[8.2,0],[11.5,0]],"id":39520250},{"atl":[[80,0],[160,0],[210,0],[110,0]],"id":39520250},{"spn":61.5,"spf":1.0,"id":36104895},{"spn":8.0,"spf":1.0,"id":37401228}],"con":true,"img":false}]}
{"op":"mcm","clk":"5306387345","pt":1646097088437,"mc":[{"id":"1.195395429","rc":[{"atb":[[7.2,16.35],[9.2,12.36],[8.2,14.08],[11.5,9.65]],"id":39520250},{"atl":[[80,1.67],[160,1.24],[210,0.94],[110,1.21]],"id":39520250}],"con":true,"img":false}]}
{"op":"mcm","clk":"5306392226","pt":1646097227980,"mc":[{"id":"1.195395429","rc":[{"spn":45.75,"spf":1.0,"id":39520250},{"atb":[[1.01,2.23]],"id":38206580},{"atb":[[1.01,2.23]],"id":41762283}],"con":true,"img":false}]}
{"op":"mcm","clk":"5306392235","pt":1646097228180,"mc":[{"id":"1.195395429","rc":[{"atb":[[1.01,1.61]],"id":38206580},{"atb":[[1.01,1.61]],"id":41762283}],"con":true,"img":false}]}
{"op":"mcm","clk":"5306392239","pt":1646097228383,"mc":[{"id":"1.195395429","rc":[{"atb":[[1.01,0]],"id":38206580}],"con":true,"img":false}]}
{"op":"mcm","clk":"5306392244","pt":1646097228486,"mc":[{"id":"1.195395429","rc":[{"atb":[[6.6,1.61]],"id":38206580}],"con":true,"img":false}]}
{"op":"mcm","clk":"5306392250","pt":1646097228691,"mc":[{"id":"1.195395429","rc":[{"atb":[[1.01,0]],"id":41762283}],"con":true,"img":false}]}
{"op":"mcm","clk":"5306392255","pt":1646097228795,"mc":[{"id":"1.195395429","rc":[{"atb":[[6.6,1.61]],"id":41762283}],"con":true,"img":false}]}
{"op":"mcm","clk":"5306404708","pt":1646097402655,"mc":[{"id":"1.195395429","marketDefinition":{"bspMarket":true,"turnInPlayEnabled":false,"persistenceEnabled":false,"marketBaseRate":7.0,"eventId":"31270458","eventTypeId":"4339","numberOfWinners":1,"bettingType":"ODDS","marketType":"WIN","marketTime":"2022-03-01T03:42:00.000Z","suspendTime":"2022-03-01T03:42:00.000Z","bspReconciled":false,"complete":true,"inPlay":false,"crossMatching":false,"runnersVoidable":false,"numberOfActiveRunners":8,"betDelay":0,"status":"OPEN","runners":[{"status":"ACTIVE","sortPriority":1,"id":40494181,"name":"1. Loch And Loaded"},{"status":"ACTIVE","sortPriority":2,"id":38206580,"name":"2. Buckle Up Wilder"},{"status":"ACTIVE","sortPriority":3,"id":38206560,"name":"3. Hiccup Amisha"},{"status":"ACTIVE","sortPriority":4,"id":36104895,"name":"4. Langley Roo"},{"status":"ACTIVE","sortPriority":5,"id":39520250,"name":"5. Rip On Bye"},{"status":"ACTIVE","sortPriority":6,"id":41762283,"name":"6. Gracies Joy"},{"status":"ACTIVE","sortPriority":7,"id":37401228,"name":"7. Just Mercy"},{"status":"ACTIVE","sortPriority":8,"id":27701417,"name":"8. Jalla General"}],"regulators":["MR_INT"],"venue":"Devonport","countryCode":"AU","discountAllowed":true,"timezone":"Australia/Sydney","openDate":"2022-03-01T02:00:00.000Z","version":4380714802,"name":"R6 452m Gr4","eventName":"Devonport (AUS) 1st Mar"},"rc":[{"atb":[[7.2,16.35],[9.2,12.36],[8.2,14.08],[11.5,9.65]],"id":39520250},{"spl":[[100,2]],"id":39520250},{"atl":[[80,1.67],[160,1.24],[210,0.94],[110,1.21]],"id":39520250},{"spn":45.75,"spf":1.0,"id":39520250},{"atb":[[18,5.96],[23,4.6],[13,8.45],[15.5,6.99]],"id":36104895},{"spl":[[100,2]],"id":36104895},{"atl":[[300,0.66],[350,0.56],[200,0.66],[250,0.53]],"id":36104895},{"spn":61.5,"spf":1.0,"id":36104895},{"atb":[[4.5,28.97],[6.4,18.77],[5,25.35],[5.5,22.53],[6.6,1.61]],"id":38206580},{"spl":[[100,2]],"id":38206580},{"atl":[[19.5,7.13],[38,5.35],[24,5.74],[29,7.07]],"id":38206580},{"spn":13.05,"spf":1.0,"id":38206580},{"atb":[[18,5.96],[21,5.07],[28,3.75],[15.5,6.99]],"id":27701417},{"spl":[[100,2]],"id":27701417},{"atl":[[290,0.45],[340,0.58],[390,0.5],[240,0.55]],"id":27701417},{"spn":64.0,"spf":1.0,"id":27701417},{"atb":[[12,9.22],[9.8,11.52],[8.8,13],[15.5,6.99]],"id":38206560},{"spl":[[100,2]],"id":38206560},{"atl":[[270,0.73],[170,0.77],[220,0.9],[120,1.1]],"id":38206560},{"spn":57.75,"spf":1.0,"id":38206560},{"atb":[[4.5,28.97],[6.4,18.77],[5,25.35],[5.5,22.53],[6.6,1.61]],"id":41762283},{"spl":[[100,2]],"id":41762283},{"atl":[[19.5,7.13],[38,5.35],[24,5.74],[29,7.07]],"id":41762283},{"spn":13.05,"spf":1.0,"id":41762283},{"atb":[[5,25.35],[5.5,22.53],[7.4,15.84],[6,20.28]],"id":37401228},{"spl":[[8.6,2.7],[100,2]],"id":37401228},{"atl":[[70,2.87],[38,3.56],[48,4.21],[29,4.71]],"id":37401228},{"spn":8.0,"spf":1.0,"id":37401228},{"atb":[[1.2,507.05],[1.25,405.64],[1.15,676.07],[1.32,316.91]],"id":40494181},{"spl":[[1.3,54.08],[100,2]],"id":40494181},{"atl":[[2.54,85.76],[2.74,113.86],[2.38,21.63],[2.64,80.53],[2.84,107.67]],"id":40494181},{"spn":1.32,"spf":1.0,"id":40494181}],"con":true,"img":true}]}
{"op":"mcm","clk":"5306416604","pt":1646097670363,"mc":[{"id":"1.195395429","rc":[{"spn":13.05,"spf":1.0,"id":38206580},{"spn":13.05,"spf":1.0,"id":41762283},{"atl":[[2.38,0]],"id":40494181}],"con":true,"img":false}]}
{"op":"mcm","clk":"5306421706","pt":1646097787482,"mc":[{"id":"1.195395429","rc":[{"atb":[[1.01,1.67]],"id":38206580}],"con":true,"img":false}]}
{"op":"mcm","clk":"5306421723","pt":1646097787790,"mc":[{"id":"1.195395429","rc":[{"atb":[[1.01,1.67]],"id":41762283}],"con":true,"img":false}]}
{"op":"mcm","clk":"5306421740","pt":1646097788052,"mc":[{"id":"1.195395429","rc":[{"atb":[[1.01,1.64]],"id":38206580}],"con":true,"img":false}]}
{"op":"mcm","clk":"5306421757","pt":1646097788358,"mc":[{"id":"1.195395429","rc":[{"atb":[[1.01,1.64]],"id":41762283}],"con":true,"img":false}]}
{"op":"mcm","clk":"5306421768","pt":1646097788665,"mc":[{"id":"1.195395429","rc":[{"atb":[[1.01,0]],"id":38206580}],"con":true,"img":false}]}
{"op":"mcm","clk":"5306421774","pt":1646097788768,"mc":[{"id":"1.195395429","rc":[{"atb":[[6.6,3.26]],"id":38206580}],"con":true,"img":false}]}
{"op":"mcm","clk":"5306421789","pt":1646097789078,"mc":[{"id":"1.195395429","rc":[{"atb":[[1.01,0]],"id":41762283}],"con":true,"img":false}]}
{"op":"mcm","clk":"5306421794","pt":1646097789181,"mc":[{"id":"1.195395429","rc":[{"atb":[[6.6,3.26]],"id":41762283}],"con":true,"img":false}]}
{"op":"mcm","clk":"5306467615","pt":1646098920203,"mc":[{"id":"1.195395429","rc":[{"atb":[[12.5,0.88]],"id":39520250},{"spn":46.25,"spf":1.0,"id":39520250},{"atb":[[22,0.49]],"id":36104895},{"atb":[[7.2,1.62]],"id":38206580},{"spn":13.35,"spf":1.0,"id":38206580},{"atb":[[36,0.3]],"id":27701417},{"spn":68.0,"spf":1.0,"id":27701417},{"atb":[[15.5,7.69]],"id":38206560},{"atb":[[7.2,1.62]],"id":41762283},{"spn":13.35,"spf":1.0,"id":41762283},{"atb":[[7.2,1.62]],"id":37401228},{"atb":[[1.36,2]],"id":40494181},{"spn":1.32,"spf":1.0,"id":40494181}],"con":true,"img":false}]}
{"op":"mcm","clk":"5306468702","pt":1646098947369,"mc":[{"id":"1.195395429","marketDefinition":{"bspMarket":true,"turnInPlayEnabled":false,"persistenceEnabled":false,"marketBaseRate":7.0,"eventId":"31270458","eventTypeId":"4339","numberOfWinners":1,"bettingType":"ODDS","marketType":"WIN","marketTime":"2022-03-01T03:42:00.000Z","suspendTime":"2022-03-01T03:42:00.000Z","bspReconciled":false,"complete":true,"inPlay":false,"crossMatching":true,"runnersVoidable":false,"numberOfActiveRunners":8,"betDelay":0,"status":"OPEN","runners":[{"status":"ACTIVE","sortPriority":1,"id":40494181,"name":"1. Loch And Loaded"},{"status":"ACTIVE","sortPriority":2,"id":38206580,"name":"2. Buckle Up Wilder"},{"status":"ACTIVE","sortPriority":3,"id":38206560,"name":"3. Hiccup Amisha"},{"status":"ACTIVE","sortPriority":4,"id":36104895,"name":"4. Langley Roo"},{"status":"ACTIVE","sortPriority":5,"id":39520250,"name":"5. Rip On Bye"},{"status":"ACTIVE","sortPriority":6,"id":41762283,"name":"6. Gracies Joy"},{"status":"ACTIVE","sortPriority":7,"id":37401228,"name":"7. Just Mercy"},{"status":"ACTIVE","sortPriority":8,"id":27701417,"name":"8. Jalla General"}],"regulators":["MR_INT"],"venue":"Devonport","countryCode":"AU","discountAllowed":true,"timezone":"Australia/Sydney","openDate":"2022-03-01T02:00:00.000Z","version":4380714802,"name":"R6 452m Gr4","eventName":"Devonport (AUS) 1st Mar"},"rc":[],"con":true,"img":false}]}
{"op":"mcm","clk":"5306551218","pt":1646100731432,"mc":[{"id":"1.195395429","rc":[{"atb":[[7.2,16.36],[9.2,12.37],[8.2,14.09],[11.5,9.66]],"id":39520250},{"atl":[[80,1.67],[160,1.24],[210,0.94],[110,1.21]],"id":39520250},{"atb":[[18,5.96],[23,4.61],[13,8.45],[15.5,6.99]],"id":36104895},{"atl":[[300,0.66],[350,0.56],[200,0.66],[250,0.53]],"id":36104895},{"atb":[[4.5,28.98],[6.4,18.78],[5,25.36],[5.5,22.54],[3.8,25.71],[6.6,3.26]],"id":38206580},{"atl":[[19.5,7.14],[38,5.35],[24,5.74],[29,7.07]],"id":38206580},{"atb":[[18,5.96],[21,5.07],[28,3.75],[15.5,6.99]],"id":27701417},{"atl":[[290,0.45],[340,0.58],[390,0.5],[240,0.55]],"id":27701417},{"atb":[[12,9.22],[9.8,11.53],[8.8,13],[15.5,7.69]],"id":38206560},{"atl":[[270,0.73],[170,0.77],[220,0.9],[120,1.1]],"id":38206560},{"atb":[[4.5,28.98],[6.4,18.78],[5,25.36],[5.5,22.54],[6.6,3.26]],"id":41762283},{"atl":[[19.5,7.14],[38,5.35],[24,5.74],[29,7.07]],"id":41762283},{"atb":[[5,25.36],[5.5,22.54],[7.4,15.85],[6,20.29]],"id":37401228},{"spl":[[8.6,2.7]],"id":37401228},{"atl":[[70,2.87],[38,3.57],[48,4.21],[29,4.71]],"id":37401228},{"atb":[[1.2,507.27],[1.25,405.82],[1.15,676.37],[1.32,317.04]],"id":40494181},{"spl":[[1.3,54.1]],"id":40494181},{"atl":[[2.54,85.8],[2.74,113.91],[2.64,80.56],[2.84,107.72]],"id":40494181}],"con":true,"img":false}]}
{"op":"mcm","clk":"5306551224","pt":1646100731488,"mc":[{"id":"1.195395429","rc":[{"atb":[[6.2,13.85]],"id":39520250},{"atb":[[12,6.55]],"id":36104895},{"atb":[[8.2,10]],"id":38206560}],"con":true,"img":false}]}
{"op":"mcm","clk":"5306551229","pt":1646100731589,"mc":[{"id":"1.195395429","rc":[{"atl":[[48,8.2]],"id":38206580},{"atb":[[11,7.2]],"id":27701417},{"atb":[[3.8,25.71]],"id":41762283},{"atb":[[4.2,22.5]],"id":37401228}],"con":true,"img":false}]}
{"op":"mcm","clk":"5306551232","pt":1646100731688,"mc":[{"id":"1.195395429","rc":[{"atb":[[2.62,46.3]],"id":38206580},{"atb":[[2.62,46.3]],"id":38206560},{"atl":[[48,8.2]],"id":41762283},{"atl":[[70,11.07]],"id":37401228}],"con":true,"img":false}]}
{"op":"mcm","clk":"5306551239","pt":1646100731793,"mc":[{"id":"1.195395429","rc":[{"atb":[[2.62,46.3]],"id":39520250},{"atb":[[2.62,46.3],[4.2,26.56]],"id":36104895},{"atb":[[2.62,46.3],[4.2,26.56]],"id":27701417},{"atb":[[4.2,26.56]],"id":38206560},{"atb":[[2.62,46.3]],"id":41762283},{"atb":[[2.62,46.3]],"id":37401228},{"atl":[[17,8.5],[34,13.5]],"id":40494181}],"con":true,"img":false}]}
{"op":"mcm","clk":"5306551997","pt":1646100747309,"mc":[{"id":"1.195395429","rc":[{"atb":[[9.6,13.04],[12,5.27]],"id":39520250},{"atl":[[36,2.7],[50,2.7]],"id":39520250},{"atb":[[18.5,7.03],[20,3.05]],"id":36104895},{"atl":[[80,2.7],[110,2.7]],"id":36104895},{"atb":[[6.6,26.52],[7,9.67]],"id":38206580},{"atl":[[17.5,3.51],[23,5.95]],"id":38206580},{"atb":[[22,6.49],[29,2.7]],"id":27701417},{"atl":[[180,0.32],[240,3.25]],"id":27701417},{"atb":[[12.5,11.36],[14,4.46]],"id":38206560},{"atl":[[44,2.7],[60,2.7]],"id":38206560},{"atb":[[5.6,24.28],[6.6,13.62]],"id":41762283},{"atl":[[17,3.62],[23,5.08]],"id":41762283},{"atb":[[6.2,22.63],[6.8,10]],"id":37401228},{"atl":[[16.5,3.74],[23,5.35]],"id":37401228},{"atb":[[1.33,323.01],[1.34,87.96]],"id":40494181},{"atl":[[2.52,70.13],[2.14,50.9]],"id":40494181}],"con":true,"img":false}]}
{"op":"mcm","clk":"5306552405","pt":1646100756016,"mc":[{"id":"1.195395429","rc":[{"atb":[[6.6,24.91]],"id":38206580},{"atb":[[6.6,12]],"id":41762283}],"con":true,"img":false}]}
{"op":"mcm","clk":"5306552489","pt":1646100757921,"mc":[{"id":"1.195395429","rc":[{"atb":[[4.2,26.56]],"id":39520250}],"con":true,"img":false}]}
{"op":"mcm","clk":"5306552764","pt":1646100765063,"mc":[{"id":"1.195395429","rc":[{"atb":[[1.01,2.23]],"id":38206580},{"atb":[[1.01,2.23]],"id":41762283},{"atb":[[1.36,27.05]],"id":40494181}],"con":true,"img":false}]}
{"op":"mcm","clk":"5306552772","pt":1646100765265,"mc":[{"id":"1.195395429","rc":[{"atb":[[1.01,1.55]],"id":38206580},{"atb":[[1.01,1.55]],"id":41762283}],"con":true,"img":false}]}
{"op":"mcm","clk":"5306552781","pt":1646100765424,"mc":[{"id":"1.195395429","rc":[{"atb":[[1.01,0]],"id":38206580}],"con":true,"img":false}]}
{"op":"mcm","clk":"5306552785","pt":1646100765525,"mc":[{"id":"1.195395429","rc":[{"atb":[[6.8,1.55]],"id":38206580}],"con":true,"img":false}]}
{"op":"mcm","clk":"5306552793","pt":1646100765729,"mc":[{"id":"1.195395429","rc":[{"atb":[[1.01,0]],"id":41762283}],"con":true,"img":false}]}
{"op":"mcm","clk":"5306552799","pt":1646100765832,"mc":[{"id":"1.195395429","rc":[{"atb":[[6.6,23.26]],"id":38206580},{"atb":[[6.8,1.55]],"id":41762283}],"con":true,"img":false}]}
{"op":"mcm","clk":"5306552804","pt":1646100765936,"mc":[{"id":"1.195395429","rc":[{"atb":[[1.36,55.11]],"id":40494181}],"con":true,"img":false}]}
{"op":"mcm","clk":"5306553052","pt":1646100771827,"mc":[{"id":"1.195395429","rc":[{"atb":[[6.8,3.28]],"id":38206580}],"con":true,"img":false}]}
{"op":"mcm","clk":"5306554997","pt":1646100811321,"mc":[{"id":"1.195395429","rc":[{"spn":24.25,"spf":1.0,"id":39520250},{"spn":51.5,"spf":1.0,"id":36104895},{"atl":[[23,0]],"id":38206580},{"spn":12.35,"spf":1.0,"id":38206580},{"atl":[[240,0.55]],"id":27701417},{"spn":29.75,"spf":1.0,"id":38206560},{"atl":[[19,6.2],[23,0]],"id":41762283},{"spn":12.1,"spf":1.0,"id":41762283},{"spn":1.36,"spf":1.0,"id":40494181}],"con":true,"img":false}]}
{"op":"mcm","clk":"5306555000","pt":1646100811423,"mc":[{"id":"1.195395429","rc":[{"atl":[[19,5.95]],"id":38206580},{"atl":[[230,2.7]],"id":27701417}],"con":true,"img":false}]}
{"op":"mcm","clk":"5306556260","pt":1646100837431,"mc":[{"id":"1.195395429","rc":[{"atb":[[1.34,0]],"id":40494181}],"con":true,"img":false}]}
{"op":"mcm","clk":"5306556266","pt":1646100837536,"mc":[{"id":"1.195395429","rc":[{"atb":[[1.37,87.96]],"id":40494181}],"con":true,"img":false}]}
{"op":"mcm","clk":"5306556664","pt":1646100846214,"mc":[{"id":"1.195395429","rc":[{"atb":[[1.36,30.06]],"id":40494181}],"con":true,"img":false}]}
{"op":"mcm","clk":"5306556855","pt":1646100850161,"mc":[{"id":"1.195395429","rc":[{"atb":[[1.36,2]],"id":40494181}],"con":true,"img":false}]}
{"op":"mcm","clk":"5306557097","pt":1646100855148,"mc":[{"id":"1.195395429","rc":[{"atb":[[1.39,23.11]],"id":40494181}],"con":true,"img":false}]}
{"op":"mcm","clk":"5306557143","pt":1646100856027,"mc":[{"id":"1.195395429","rc":[{"atb":[[1.39,49.01]],"id":40494181}],"con":true,"img":false}]}
{"op":"mcm","clk":"5306558852","pt":1646100889681,"mc":[{"id":"1.195395429","rc":[{"atb":[[1.37,0]],"id":40494181},{"spn":1.38,"spf":1.0,"id":40494181}],"con":true,"img":false}]}
{"op":"mcm","clk":"5306558857","pt":1646100889786,"mc":[{"id":"1.195395429","rc":[{"atb":[[1.35,87.96]],"id":40494181}],"con":true,"img":false}]}
{"op":"mcm","clk":"5306559267","pt":1646100897293,"mc":[{"id":"1.195395429","rc":[{"atb":[[1.39,25.89]],"id":40494181}],"con":true,"img":false}]}
{"op":"mcm","clk":"5306559621","pt":1646100904292,"mc":[{"id":"1.195395429","rc":[{"atb":[[1.39,0]],"id":40494181}],"con":true,"img":false}]}
{"op":"mcm","clk":"5306559720","pt":1646100906194,"mc":[{"id":"1.195395429","rc":[{"atb":[[1.37,24.37]],"id":40494181}],"con":true,"img":false}]}
{"op":"mcm","clk":"5306559937","pt":1646100910300,"mc":[{"id":"1.195395429","rc":[{"atb":[[1.37,51.69]],"id":40494181}],"con":true,"img":false}]}
{"op":"mcm","clk":"5306561828","pt":1646100951449,"mc":[{"id":"1.195395429","rc":[{"atb":[[1.35,0]],"id":40494181},{"spn":1.36,"spf":1.0,"id":40494181}],"con":true,"img":false}]}
{"op":"mcm","clk":"5306561837","pt":1646100951552,"mc":[{"id":"1.195395429","rc":[{"atb":[[1.38,87.96]],"id":40494181}],"con":true,"img":false}]}
{"op":"mcm","clk":"5306562268","pt":1646100960394,"mc":[{"id":"1.195395429","rc":[{"atb":[[1.37,27.31]],"id":40494181}],"con":true,"img":false}]}
{"op":"mcm","clk":"5306562457","pt":1646100964282,"mc":[{"id":"1.195395429","rc":[{"atb":[[1.37,0]],"id":40494181}],"con":true,"img":false}]}
{"op":"mcm","clk":"5306562728","pt":1646100969406,"mc":[{"id":"1.195395429","rc":[{"atb":[[1.4,22.54]],"id":40494181}],"con":true,"img":false}]}
{"op":"mcm","clk":"5306562772","pt":1646100970379,"mc":[{"id":"1.195395429","rc":[{"atb":[[1.4,47.8]],"id":40494181}],"con":true,"img":false}]}
{"op":"mcm","clk":"5306564770","pt":1646101013188,"mc":[{"id":"1.195395429","rc":[{"atb":[[1.38,0]],"id":40494181},{"spn":1.39,"spf":1.0,"id":40494181}],"con":true,"img":false}]}
{"op":"mcm","clk":"5306564772","pt":1646101013287,"mc":[{"id":"1.195395429","rc":[{"atb":[[1.35,87.96]],"id":40494181}],"con":true,"img":false}]}
{"op":"mcm","clk":"5306565055","pt":1646101020466,"mc":[{"id":"1.195395429","rc":[{"atb":[[1.4,25.25]],"id":40494181}],"con":true,"img":false}]}
{"op":"mcm","clk":"5306565476","pt":1646101030497,"mc":[{"id":"1.195395429","rc":[{"atb":[[1.4,0]],"id":40494181}],"con":true,"img":false}]}
{"op":"mcm","clk":"5306565549","pt":1646101032500,"mc":[{"id":"1.195395429","rc":[{"atb":[[1.37,24.37]],"id":40494181}],"con":true,"img":false}]}
{"op":"mcm","clk":"5306565730","pt":1646101036500,"mc":[{"id":"1.195395429","rc":[{"atb":[[1.37,51.69]],"id":40494181}],"con":true,"img":false}]}
{"op":"mcm","clk":"5306567368","pt":1646101074259,"mc":[{"id":"1.195395429","rc":[{"atb":[[1.35,0]],"id":40494181},{"spn":1.36,"spf":1.0,"id":40494181}],"con":true,"img":false}]}
{"op":"mcm","clk":"5306567374","pt":1646101074361,"mc":[{"id":"1.195395429","rc":[{"atb":[[1.38,87.96]],"id":40494181}],"con":true,"img":false}]}
{"op":"mcm","clk":"5306567653","pt":1646101080733,"mc":[{"id":"1.195395429","rc":[{"atb":[[1.37,27.31]],"id":40494181}],"con":true,"img":false}]}
{"op":"mcm","clk":"5306568141","pt":1646101090743,"mc":[{"id":"1.195395429","rc":[{"atb":[[1.37,0]],"id":40494181}],"con":true,"img":false}]}
{"op":"mcm","clk":"5306568242","pt":1646101092649,"mc":[{"id":"1.195395429","rc":[{"atb":[[1.4,22.54]],"id":40494181}],"con":true,"img":false}]}
{"op":"mcm","clk":"5306568426","pt":1646101096752,"mc":[{"id":"1.195395429","rc":[{"atb":[[1.4,47.8]],"id":40494181}],"con":true,"img":false}]}
{"op":"mcm","clk":"5306569654","pt":1646101124105,"mc":[{"id":"1.195395429","rc":[{"atb":[[1.38,0]],"id":40494181}],"con":true,"img":false}]}
{"op":"mcm","clk":"5306569657","pt":1646101124202,"mc":[{"id":"1.195395429","rc":[{"atb":[[1.35,87.96]],"id":40494181}],"con":true,"img":false}]}
{"op":"mcm","clk":"5306570014","pt":1646101131323,"mc":[{"id":"1.195395429","marketDefinition":{"bspMarket":true,"turnInPlayEnabled":false,"persistenceEnabled":false,"marketBaseRate":7.0,"eventId":"31270458","eventTypeId":"4339","numberOfWinners":1,"bettingType":"ODDS","marketType":"WIN","marketTime":"2022-03-01T03:57:00.000Z","suspendTime":"2022-03-01T03:57:00.000Z","bspReconciled":false,"complete":true,"inPlay":false,"crossMatching":true,"runnersVoidable":false,"numberOfActiveRunners":8,"betDelay":0,"status":"OPEN","runners":[{"status":"ACTIVE","sortPriority":1,"id":40494181,"name":"1. Loch And Loaded"},{"status":"ACTIVE","sortPriority":2,"id":38206580,"name":"2. Buckle Up Wilder"},{"status":"ACTIVE","sortPriority":3,"id":38206560,"name":"3. Hiccup Amisha"},{"status":"ACTIVE","sortPriority":4,"id":36104895,"name":"4. Langley Roo"},{"status":"ACTIVE","sortPriority":5,"id":39520250,"name":"5. Rip On Bye"},{"status":"ACTIVE","sortPriority":6,"id":41762283,"name":"6. Gracies Joy"},{"status":"ACTIVE","sortPriority":7,"id":37401228,"name":"7. Just Mercy"},{"status":"ACTIVE","sortPriority":8,"id":27701417,"name":"8. Jalla General"}],"regulators":["MR_INT"],"venue":"Devonport","countryCode":"AU","discountAllowed":true,"timezone":"Australia/Sydney","openDate":"2022-03-01T02:00:00.000Z","version":4381058423,"name":"R6 452m Gr4","eventName":"Devonport (AUS) 1st Mar"},"rc":[],"con":true,"img":false}]}
{"op":"mcm","clk":"5306570030","pt":1646101131694,"mc":[{"id":"1.195395429","rc":[{"atb":[[1.4,25.25]],"id":40494181}],"con":true,"img":false}]}
{"op":"mcm","clk":"5306570382","pt":1646101138833,"mc":[{"id":"1.195395429","rc":[{"atb":[[1.4,0]],"id":40494181},{"spn":1.35,"spf":1.0,"id":40494181}],"con":true,"img":false}]}
{"op":"mcm","clk":"5306570477","pt":1646101140731,"mc":[{"id":"1.195395429","rc":[{"atb":[[1.37,24.37]],"id":40494181}],"con":true,"img":false}]}
{"op":"mcm","clk":"5306570670","pt":1646101144844,"mc":[{"id":"1.195395429","rc":[{"atb":[[1.37,51.69]],"id":40494181}],"con":true,"img":false}]}
{"op":"mcm","clk":"5306571233","pt":1646101157721,"mc":[{"id":"1.195395429","rc":[{"atb":[[1.35,0]],"id":40494181}],"con":true,"img":false}]}
{"op":"mcm","clk":"5306571239","pt":1646101157825,"mc":[{"id":"1.195395429","rc":[{"atb":[[1.38,87.96]],"id":40494181}],"con":true,"img":false}]}
{"op":"mcm","clk":"5306571553","pt":1646101164853,"mc":[{"id":"1.195395429","rc":[{"atb":[[1.37,27.31]],"id":40494181}],"con":true,"img":false}]}
{"op":"mcm","clk":"5306571885","pt":1646101173764,"mc":[{"id":"1.195395429","rc":[{"atb":[[1.4,22.54]],"id":40494181}],"con":true,"img":false}]}
{"op":"mcm","clk":"5306571923","pt":1646101174841,"mc":[{"id":"1.195395429","rc":[{"atb":[[1.37,0]],"id":40494181}],"con":true,"img":false}]}
{"op":"mcm","clk":"5306572209","pt":1646101180890,"mc":[{"id":"1.195395429","rc":[{"atb":[[1.4,47.8]],"id":40494181}],"con":true,"img":false}]}
{"op":"mcm","clk":"5306573914","pt":1646101215915,"mc":[{"id":"1.195395429","rc":[{"atb":[[1.38,0]],"id":40494181},{"spn":1.39,"spf":1.0,"id":40494181}],"con":true,"img":false}]}
{"op":"mcm","clk":"5306573921","pt":1646101216019,"mc":[{"id":"1.195395429","rc":[{"atb":[[1.35,87.96]],"id":40494181}],"con":true,"img":false}]}
{"op":"mcm","clk":"5306574358","pt":1646101224940,"mc":[{"id":"1.195395429","rc":[{"atb":[[1.4,25.25]],"id":40494181}],"con":true,"img":false}]}
{"op":"mcm","clk":"5306574580","pt":1646101229150,"mc":[{"id":"1.195395429","rc":[{"atb":[[1.4,0]],"id":40494181}],"con":true,"img":false}]}
{"op":"mcm","clk":"5306574818","pt":1646101233927,"mc":[{"id":"1.195395429","rc":[{"atb":[[1.37,24.37]],"id":40494181}],"con":true,"img":false}]}
{"op":"mcm","clk":"5306574870","pt":1646101235055,"mc":[{"id":"1.195395429","rc":[{"atb":[[1.37,51.69]],"id":40494181}],"con":true,"img":false}]}
{"op":"mcm","clk":"5306575572","pt":1646101250032,"mc":[{"id":"1.195395429","rc":[{"atb":[[1.35,0]],"id":40494181}],"con":true,"img":false}]}
{"op":"mcm","clk":"5306575579","pt":1646101250136,"mc":[{"id":"1.195395429","rc":[{"atb":[[1.38,87.96]],"id":40494181}],"con":true,"img":false}]}
{"op":"mcm","clk":"5306575944","pt":1646101258046,"mc":[{"id":"1.195395429","rc":[{"atb":[[1.37,27.31]],"id":40494181}],"con":true,"img":false}]}
{"op":"mcm","clk":"5306576314","pt":1646101265245,"mc":[{"id":"1.195395429","rc":[{"atb":[[1.37,0]],"id":40494181}],"con":true,"img":false}]}
{"op":"mcm","clk":"5306576383","pt":1646101266985,"mc":[{"id":"1.195395429","rc":[{"atb":[[1.4,22.54]],"id":40494181}],"con":true,"img":false}]}
{"op":"mcm","clk":"5306576557","pt":1646101271257,"mc":[{"id":"1.195395429","rc":[{"atb":[[1.4,47.8]],"id":40494181}],"con":true,"img":false}]}
{"op":"mcm","clk":"5306578052","pt":1646101306213,"mc":[{"id":"1.195395429","rc":[{"atb":[[1.38,0]],"id":40494181}],"con":true,"img":false}]}
{"op":"mcm","clk":"5306578059","pt":1646101306316,"mc":[{"id":"1.195395429","rc":[{"atb":[[1.35,87.96]],"id":40494181}],"con":true,"img":false}]}
{"op":"mcm","clk":"5306578435","pt":1646101315052,"mc":[{"id":"1.195395429","rc":[{"atb":[[1.4,25.25]],"id":40494181}],"con":true,"img":false}]}
{"op":"mcm","clk":"5306578616","pt":1646101319827,"mc":[{"id":"1.195395429","rc":[{"atb":[[1.4,0]],"id":40494181}],"con":true,"img":false}]}
{"op":"mcm","clk":"5306578814","pt":1646101324040,"mc":[{"id":"1.195395429","rc":[{"atb":[[1.37,24.37]],"id":40494181}],"con":true,"img":false}]}
{"op":"mcm","clk":"5306578870","pt":1646101325478,"mc":[{"id":"1.195395429","rc":[{"atb":[[1.37,51.69]],"id":40494181}],"con":true,"img":false}]}
{"op":"mcm","clk":"5306579445","pt":1646101339853,"mc":[{"id":"1.195395429","rc":[{"atb":[[1.35,0]],"id":40494181}],"con":true,"img":false}]}
{"op":"mcm","clk":"5306579451","pt":1646101339957,"mc":[{"id":"1.195395429","rc":[{"atb":[[1.38,87.96]],"id":40494181}],"con":true,"img":false}]}
{"op":"mcm","clk":"5306579851","pt":1646101348270,"mc":[{"id":"1.195395429","rc":[{"atb":[[1.37,27.31]],"id":40494181}],"con":true,"img":false}]}
{"op":"mcm","clk":"5306580186","pt":1646101355401,"mc":[{"id":"1.195395429","rc":[{"atb":[[1.37,0]],"id":40494181}],"con":true,"img":false}]}
{"op":"mcm","clk":"5306580279","pt":1646101357201,"mc":[{"id":"1.195395429","rc":[{"atb":[[1.4,22.54]],"id":40494181}],"con":true,"img":false}]}
{"op":"mcm","clk":"5306580473","pt":1646101361365,"mc":[{"id":"1.195395429","rc":[{"atb":[[1.4,47.8]],"id":40494181}],"con":true,"img":false}]}
{"op":"mcm","clk":"5306582321","pt":1646101405254,"mc":[{"id":"1.195395429","rc":[{"atb":[[1.38,0]],"id":40494181}],"con":true,"img":false}]}
{"op":"mcm","clk":"5306582324","pt":1646101405356,"mc":[{"id":"1.195395429","rc":[{"atb":[[1.35,87.96]],"id":40494181}],"con":true,"img":false}]}
{"op":"mcm","clk":"5306582699","pt":1646101414382,"mc":[{"id":"1.195395429","rc":[{"atb":[[1.4,25.25]],"id":40494181}],"con":true,"img":false}]}
{"op":"mcm","clk":"5306583008","pt":1646101421570,"mc":[{"id":"1.195395429","rc":[{"atb":[[1.4,0]],"id":40494181}],"con":true,"img":false}]}
{"op":"mcm","clk":"5306583082","pt":1646101423265,"mc":[{"id":"1.195395429","rc":[{"atb":[[1.37,24.37]],"id":40494181}],"con":true,"img":false}]}
{"op":"mcm","clk":"5306583244","pt":1646101427468,"mc":[{"id":"1.195395429","rc":[{"atb":[[1.37,51.69]],"id":40494181}],"con":true,"img":false}]}
{"op":"mcm","clk":"5306584616","pt":1646101458450,"mc":[{"id":"1.195395429","rc":[{"atb":[[1.35,0]],"id":40494181}],"con":true,"img":false}]}
{"op":"mcm","clk":"5306584621","pt":1646101458505,"mc":[{"id":"1.195395429","rc":[{"atb":[[1.38,87.96]],"id":40494181}],"con":true,"img":false}]}
{"op":"mcm","clk":"5306584909","pt":1646101465436,"mc":[{"id":"1.195395429","rc":[{"atb":[[1.37,27.31]],"id":40494181},{"spn":1.38,"spf":1.0,"id":40494181}],"con":true,"img":false}]}
{"op":"mcm","clk":"5306585352","pt":1646101474429,"mc":[{"id":"1.195395429","rc":[{"atb":[[1.4,22.54]],"id":40494181}],"con":true,"img":false}]}
{"op":"mcm","clk":"5306585406","pt":1646101475662,"mc":[{"id":"1.195395429","rc":[{"atb":[[1.37,0]],"id":40494181}],"con":true,"img":false}]}
{"op":"mcm","clk":"5306585661","pt":1646101481568,"mc":[{"id":"1.195395429","rc":[{"atb":[[1.4,47.8]],"id":40494181}],"con":true,"img":false}]}
{"op":"mcm","clk":"5306587075","pt":1646101511303,"mc":[{"id":"1.195395429","rc":[{"atb":[[1.38,0]],"id":40494181}],"con":true,"img":false}]}
{"op":"mcm","clk":"5306587080","pt":1646101511357,"mc":[{"id":"1.195395429","rc":[{"atb":[[1.35,87.96]],"id":40494181}],"con":true,"img":false}]}
{"op":"mcm","clk":"5306587522","pt":1646101519668,"mc":[{"id":"1.195395429","rc":[{"atb":[[1.4,25.25]],"id":40494181}],"con":true,"img":false}]}
{"op":"mcm","clk":"5306587909","pt":1646101528488,"mc":[{"id":"1.195395429","rc":[{"atb":[[1.37,24.37]],"id":40494181},{"spn":1.38,"spf":1.0,"id":40494181}],"con":true,"img":false}]}
{"op":"mcm","clk":"5306587963","pt":1646101529715,"mc":[{"id":"1.195395429","rc":[{"atb":[[1.4,0]],"id":40494181}],"con":true,"img":false}]}
{"op":"mcm","clk":"5306588186","pt":1646101535612,"mc":[{"id":"1.195395429","rc":[{"atb":[[1.37,51.69]],"id":40494181}],"con":true,"img":false}]}
{"op":"mcm","clk":"5306588467","pt":1646101542937,"mc":[{"id":"1.195395429","rc":[{"atb":[[1.35,0]],"id":40494181}],"con":true,"img":false}]}
{"op":"mcm","clk":"5306588474","pt":1646101543039,"mc":[{"id":"1.195395429","rc":[{"atb":[[1.38,87.96]],"id":40494181}],"con":true,"img":false}]}
{"op":"mcm","clk":"5306588721","pt":1646101549645,"mc":[{"id":"1.195395429","rc":[{"atb":[[1.37,27.31]],"id":40494181}],"con":true,"img":false}]}
{"op":"mcm","clk":"5306589083","pt":1646101558662,"mc":[{"id":"1.195395429","rc":[{"atb":[[1.4,22.54]],"id":40494181}],"con":true,"img":false}]}
{"op":"mcm","clk":"5306589135","pt":1646101559946,"mc":[{"id":"1.195395429","rc":[{"atb":[[1.37,0]],"id":40494181}],"con":true,"img":false}]}
{"op":"mcm","clk":"5306589405","pt":1646101565855,"mc":[{"id":"1.195395429","rc":[{"atb":[[1.4,47.8]],"id":40494181}],"con":true,"img":false}]}
{"op":"mcm","clk":"5306591291","pt":1646101604703,"mc":[{"id":"1.195395429","rc":[{"atb":[[1.38,0]],"id":40494181},{"spn":1.39,"spf":1.0,"id":40494181}],"con":true,"img":false}]}
{"op":"mcm","clk":"5306591297","pt":1646101604804,"mc":[{"id":"1.195395429","rc":[{"atb":[[1.35,87.96]],"id":40494181}],"con":true,"img":false}]}
{"op":"mcm","clk":"5306591683","pt":1646101612699,"mc":[{"id":"1.195395429","rc":[{"atb":[[1.4,25.25]],"id":40494181}],"con":true,"img":false}]}
{"op":"mcm","clk":"5306592031","pt":1646101619748,"mc":[{"id":"1.195395429","rc":[{"atb":[[1.4,0]],"id":40494181}],"con":true,"img":false}]}
{"op":"mcm","clk":"5306592156","pt":1646101621856,"mc":[{"id":"1.195395429","rc":[{"atb":[[1.37,24.37]],"id":40494181}],"con":true,"img":false}]}
{"op":"mcm","clk":"5306592348","pt":1646101625919,"mc":[{"id":"1.195395429","rc":[{"atb":[[1.37,51.69]],"id":40494181}],"con":true,"img":false}]}
{"op":"mcm","clk":"5306593951","pt":1646101667195,"mc":[{"id":"1.195395429","rc":[{"atb":[[1.35,0]],"id":40494181},{"spn":1.36,"spf":1.0,"id":40494181}],"con":true,"img":false}]}
{"op":"mcm","clk":"5306593962","pt":1646101667296,"mc":[{"id":"1.195395429","rc":[{"atb":[[1.38,87.96]],"id":40494181}],"con":true,"img":false}]}
{"op":"mcm","clk":"5306594184","pt":1646101672936,"mc":[{"id":"1.195395429","rc":[{"atl":[[130,8.2]],"id":39520250}],"con":true,"img":false}]}
{"op":"mcm","clk":"5306594301","pt":1646101675913,"mc":[{"id":"1.195395429","rc":[{"atb":[[1.37,27.31]],"id":40494181}],"con":true,"img":false}]}
{"op":"mcm","clk":"5306594470","pt":1646101680012,"mc":[{"id":"1.195395429","rc":[{"atb":[[1.37,0]],"id":40494181}],"con":true,"img":false}]}
{"op":"mcm","clk":"5306594688","pt":1646101684827,"mc":[{"id":"1.195395429","rc":[{"atb":[[1.4,22.54]],"id":40494181}],"con":true,"img":false}]}
{"op":"mcm","clk":"5306594740","pt":1646101685904,"mc":[{"id":"1.195395429","rc":[{"atb":[[1.4,47.8]],"id":40494181}],"con":true,"img":false}]}
{"op":"mcm","clk":"5306596339","pt":1646101728565,"mc":[{"id":"1.195395429","rc":[{"atb":[[1.38,0]],"id":40494181},{"spn":1.39,"spf":1.0,"id":40494181}],"con":true,"img":false}]}
{"op":"mcm","clk":"5306596341","pt":1646101728668,"mc":[{"id":"1.195395429","rc":[{"atb":[[1.35,87.96]],"id":40494181}],"con":true,"img":false}]}
{"op":"mcm","clk":"5306596597","pt":1646101736099,"mc":[{"id":"1.195395429","rc":[{"atb":[[1.4,25.25]],"id":40494181}],"con":true,"img":false}]}
{"op":"mcm","clk":"5306596959","pt":1646101745025,"mc":[{"id":"1.195395429","rc":[{"atb":[[1.37,24.37]],"id":40494181}],"con":true,"img":false}]}
{"op":"mcm","clk":"5306596999","pt":1646101746105,"mc":[{"id":"1.195395429","rc":[{"atb":[[1.4,0]],"id":40494181}],"con":true,"img":false}]}
{"op":"mcm","clk":"5306597248","pt":1646101752041,"mc":[{"id":"1.195395429","rc":[{"atb":[[1.37,51.69]],"id":40494181}],"con":true,"img":false}]}
{"op":"mcm","clk":"5306598798","pt":1646101789065,"mc":[{"id":"1.195395429","rc":[{"atb":[[1.35,0]],"id":40494181},{"spn":1.36,"spf":1.0,"id":40494181}],"con":true,"img":false}]}
{"op":"mcm","clk":"5306598805","pt":1646101789169,"mc":[{"id":"1.195395429","rc":[{"atb":[[1.38,87.96]],"id":40494181}],"con":true,"img":false}]}
{"op":"mcm","clk":"5306599089","pt":1646101796095,"mc":[{"id":"1.195395429","rc":[{"atb":[[1.37,27.31]],"id":40494181}],"con":true,"img":false}]}
{"op":"mcm","clk":"5306599506","pt":1646101805064,"mc":[{"id":"1.195395429","rc":[{"atb":[[1.4,22.54]],"id":40494181}],"con":true,"img":false}]}
{"op":"mcm","clk":"5306599577","pt":1646101806299,"mc":[{"id":"1.195395429","rc":[{"atb":[[1.37,0]],"id":40494181}],"con":true,"img":false}]}
{"op":"mcm","clk":"5306599866","pt":1646101812202,"mc":[{"id":"1.195395429","rc":[{"atb":[[1.4,47.8]],"id":40494181}],"con":true,"img":false}]}
{"op":"mcm","clk":"5306601605","pt":1646101848710,"mc":[{"id":"1.195395429","rc":[{"atb":[[1.38,0]],"id":40494181}],"con":true,"img":false}]}
{"op":"mcm","clk":"5306601609","pt":1646101848813,"mc":[{"id":"1.195395429","rc":[{"atb":[[1.35,87.96]],"id":40494181}],"con":true,"img":false}]}
{"op":"mcm","clk":"5306601921","pt":1646101856251,"mc":[{"id":"1.195395429","rc":[{"atb":[[1.4,25.25]],"id":40494181},{"spn":1.37,"spf":1.0,"id":40494181}],"con":true,"img":false}]}
{"op":"mcm","clk":"5306602344","pt":1646101866349,"mc":[{"id":"1.195395429","rc":[{"atb":[[1.4,0]],"id":40494181}],"con":true,"img":false}]}
{"op":"mcm","clk":"5306602450","pt":1646101868253,"mc":[{"id":"1.195395429","rc":[{"atb":[[1.37,24.37]],"id":40494181}],"con":true,"img":false}]}
{"op":"mcm","clk":"5306602639","pt":1646101872356,"mc":[{"id":"1.195395429","rc":[{"atb":[[1.37,51.69]],"id":40494181}],"con":true,"img":false}]}
{"op":"mcm","clk":"5306603105","pt":1646101883667,"mc":[{"id":"1.195395429","rc":[{"atb":[[1.35,0]],"id":40494181}],"con":true,"img":false}]}
{"op":"mcm","clk":"5306603110","pt":1646101883773,"mc":[{"id":"1.195395429","rc":[{"atb":[[1.38,87.96]],"id":40494181}],"con":true,"img":false}]}
{"op":"mcm","clk":"5306603451","pt":1646101892267,"mc":[{"id":"1.195395429","rc":[{"atb":[[1.37,27.31]],"id":40494181}],"con":true,"img":false}]}
{"op":"mcm","clk":"5306603632","pt":1646101896407,"mc":[{"id":"1.195395429","rc":[{"atb":[[1.37,0]],"id":40494181}],"con":true,"img":false}]}
{"op":"mcm","clk":"5306603833","pt":1646101901220,"mc":[{"id":"1.195395429","rc":[{"atb":[[1.4,22.54]],"id":40494181}],"con":true,"img":false}]}
{"op":"mcm","clk":"5306603893","pt":1646101902304,"mc":[{"id":"1.195395429","rc":[{"atb":[[1.4,47.8]],"id":40494181}],"con":true,"img":false}]}
{"op":"mcm","clk":"5306606171","pt":1646101952467,"mc":[{"id":"1.195395429","rc":[{"atb":[[1.38,0]],"id":40494181},{"spn":1.39,"spf":1.0,"id":40494181}],"con":true,"img":false}]}
{"op":"mcm","clk":"5306606173","pt":1646101952568,"mc":[{"id":"1.195395429","rc":[{"atb":[[1.35,87.96]],"id":40494181}],"con":true,"img":false}]}
{"op":"mcm","clk":"5306606665","pt":1646101961487,"mc":[{"id":"1.195395429","rc":[{"atb":[[1.4,25.25]],"id":40494181}],"con":true,"img":false}]}
{"op":"mcm","clk":"5306607014","pt":1646101968609,"mc":[{"id":"1.195395429","rc":[{"atb":[[1.4,0]],"id":40494181}],"con":true,"img":false}]}
{"op":"mcm","clk":"5306607096","pt":1646101970405,"mc":[{"id":"1.195395429","rc":[{"atb":[[1.37,24.37]],"id":40494181}],"con":true,"img":false}]}
{"op":"mcm","clk":"5306611493","pt":1646102059676,"mc":[{"id":"1.195395429","rc":[{"atb":[[1.37,51.69]],"id":40494181},{"spn":1.36,"spf":1.0,"id":40494181}],"con":true,"img":false}]}
{"op":"mcm","clk":"5306614440","pt":1646102118558,"mc":[{"id":"1.195395429","rc":[{"atb":[[1.35,0]],"id":40494181}],"con":true,"img":false}]}
{"op":"mcm","clk":"5306614444","pt":1646102118661,"mc":[{"id":"1.195395429","rc":[{"atb":[[1.38,87.96]],"id":40494181}],"con":true,"img":false}]}
{"op":"mcm","clk":"5306614878","pt":1646102126763,"mc":[{"id":"1.195395429","rc":[{"atb":[[1.37,27.31]],"id":40494181},{"spn":1.38,"spf":1.0,"id":40494181}],"con":true,"img":false}]}
{"op":"mcm","clk":"5306615359","pt":1646102135672,"mc":[{"id":"1.195395429","rc":[{"atb":[[1.4,22.54]],"id":40494181}],"con":true,"img":false}]}
{"op":"mcm","clk":"5306616139","pt":1646102150684,"mc":[{"id":"1.195395429","rc":[{"atb":[[1.38,0]],"id":40494181}],"con":true,"img":false}]}
{"op":"mcm","clk":"5306616146","pt":1646102150785,"mc":[{"id":"1.195395429","rc":[{"atb":[[1.34,87.96]],"id":40494181}],"con":true,"img":false}]}
{"op":"mcm","clk":"5306616618","pt":1646102159840,"mc":[{"id":"1.195395429","rc":[{"atb":[[1.4,0]],"id":40494181}],"con":true,"img":false}]}
{"op":"mcm","clk":"5306617095","pt":1646102168849,"mc":[{"id":"1.195395429","rc":[{"atb":[[1.36,27.05]],"id":40494181}],"con":true,"img":false}]}
{"op":"mcm","clk":"5306624447","pt":1646102305328,"mc":[{"id":"1.195395429","rc":[{"atb":[[1.37,0]],"id":40494181},{"spn":1.34,"spf":1.0,"id":40494181}],"con":true,"img":false}]}
{"op":"mcm","clk":"5306624957","pt":1646102314331,"mc":[{"id":"1.195395429","rc":[{"atb":[[1.36,55.11]],"id":40494181}],"con":true,"img":false}]}
{"op":"mcm","clk":"5306627677","pt":1646102366803,"mc":[{"id":"1.195395429","rc":[{"atb":[[1.34,0]],"id":40494181},{"spn":1.36,"spf":1.0,"id":40494181}],"con":true,"img":false}]}
{"op":"mcm","clk":"5306627681","pt":1646102366905,"mc":[{"id":"1.195395429","rc":[{"atb":[[1.37,87.96]],"id":40494181}],"con":true,"img":false}]}
{"op":"mcm","clk":"5306627982","pt":1646102373182,"mc":[{"id":"1.195395429","rc":[{"atb":[[1.36,30.06]],"id":40494181}],"con":true,"img":false}]}
{"op":"mcm","clk":"5306628284","pt":1646102380191,"mc":[{"id":"1.195395429","rc":[{"atb":[[1.36,2]],"id":40494181}],"con":true,"img":false}]}
{"op":"mcm","clk":"5306628496","pt":1646102385102,"mc":[{"id":"1.195395429","rc":[{"atb":[[1.39,23.11]],"id":40494181}],"con":true,"img":false}]}
{"op":"mcm","clk":"5306628538","pt":1646102386122,"mc":[{"id":"1.195395429","rc":[{"atb":[[1.39,49.01]],"id":40494181}],"con":true,"img":false}]}
{"op":"mcm","clk":"5306630469","pt":1646102426255,"mc":[{"id":"1.195395429","rc":[{"atb":[[1.37,0]],"id":40494181}],"con":true,"img":false}]}
{"op":"mcm","clk":"5306630475","pt":1646102426358,"mc":[{"id":"1.195395429","rc":[{"atb":[[1.35,87.96]],"id":40494181}],"con":true,"img":false}]}
{"op":"mcm","clk":"5306630865","pt":1646102433286,"mc":[{"id":"1.195395429","rc":[{"atb":[[1.39,25.89]],"id":40494181},{"spn":1.36,"spf":1.0,"id":40494181}],"con":true,"img":false}]}
{"op":"mcm","clk":"5306631279","pt":1646102440400,"mc":[{"id":"1.195395429","rc":[{"atb":[[1.39,0]],"id":40494181}],"con":true,"img":false}]}
{"op":"mcm","clk":"5306631365","pt":1646102442196,"mc":[{"id":"1.195395429","rc":[{"atb":[[1.37,24.37]],"id":40494181}],"con":true,"img":false}]}
{"op":"mcm","clk":"5306631591","pt":1646102446296,"mc":[{"id":"1.195395429","rc":[{"atb":[[1.37,51.69]],"id":40494181}],"con":true,"img":false}]}
{"op":"mcm","clk":"5306633370","pt":1646102484269,"mc":[{"id":"1.195395429","rc":[{"atb":[[1.35,0]],"id":40494181}],"con":true,"img":false}]}
{"op":"mcm","clk":"5306633376","pt":1646102484361,"mc":[{"id":"1.195395429","rc":[{"atb":[[1.38,87.96]],"id":40494181}],"con":true,"img":false}]}
{"op":"mcm","clk":"5306633774","pt":1646102493384,"mc":[{"id":"1.195395429","rc":[{"atb":[[1.37,27.31]],"id":40494181},{"spn":1.38,"spf":1.0,"id":40494181}],"con":true,"img":false}]}
{"op":"mcm","clk":"5306634074","pt":1646102500475,"mc":[{"id":"1.195395429","rc":[{"atb":[[1.37,0]],"id":40494181}],"con":true,"img":false}]}
{"op":"mcm","clk":"5306634142","pt":1646102502366,"mc":[{"id":"1.195395429","rc":[{"atb":[[1.4,22.54]],"id":40494181}],"con":true,"img":false}]}
{"op":"mcm","clk":"5306634319","pt":1646102506364,"mc":[{"id":"1.195395429","rc":[{"atb":[[1.4,47.8]],"id":40494181}],"con":true,"img":false}]}
{"op":"mcm","clk":"5306635752","pt":1646102541549,"mc":[{"id":"1.195395429","rc":[{"atb":[[1.38,0]],"id":40494181}],"con":true,"img":false}]}
{"op":"mcm","clk":"5306635756","pt":1646102541652,"mc":[{"id":"1.195395429","rc":[{"atb":[[1.35,87.96]],"id":40494181}],"con":true,"img":false}]}
{"op":"mcm","clk":"5306636187","pt":1646102550550,"mc":[{"id":"1.195395429","rc":[{"atb":[[1.4,25.25]],"id":40494181}],"con":true,"img":false}]}
{"op":"mcm","clk":"5306636387","pt":1646102554856,"mc":[{"id":"1.195395429","rc":[{"atb":[[1.4,0]],"id":40494181},{"spn":1.35,"spf":1.0,"id":40494181}],"con":true,"img":false}]}
{"op":"mcm","clk":"5306636590","pt":1646102559464,"mc":[{"id":"1.195395429","rc":[{"atb":[[1.37,24.37]],"id":40494181}],"con":true,"img":false}]}
{"op":"mcm","clk":"5306636655","pt":1646102560848,"mc":[{"id":"1.195395429","rc":[{"atb":[[1.37,51.69]],"id":40494181}],"con":true,"img":false}]}
{"op":"mcm","clk":"5306637577","pt":1646102580586,"mc":[{"id":"1.195395429","rc":[{"atb":[[18.5,0]],"id":36104895},{"atb":[[10,14.6]],"id":38206560},{"atb":[[1.35,0]],"id":40494181}],"con":true,"img":false}]}
{"op":"mcm","clk":"5306637582","pt":1646102580690,"mc":[{"id":"1.195395429","rc":[{"atb":[[16,7.03]],"id":36104895},{"atb":[[12.5,0]],"id":38206560},{"atb":[[1.38,87.96]],"id":40494181}],"con":true,"img":false}]}
{"op":"mcm","clk":"5306638004","pt":1646102589600,"mc":[{"id":"1.195395429","rc":[{"atb":[[1.37,27.31]],"id":40494181}],"con":true,"img":false}]}
{"op":"mcm","clk":"5306638333","pt":1646102596882,"mc":[{"id":"1.195395429","rc":[{"atb":[[1.37,0]],"id":40494181}],"con":true,"img":false}]}
{"op":"mcm","clk":"5306638353","pt":1646102597701,"mc":[{"id":"1.195395429","rc":[{"atb":[[20,0]],"id":36104895},{"atb":[[14,0]],"id":38206560},{"atb":[[1.38,0]],"id":40494181}],"con":true,"img":false}]}
{"op":"mcm","clk":"5306638355","pt":1646102597805,"mc":[{"id":"1.195395429","rc":[{"atb":[[18.5,3.05]],"id":36104895},{"atb":[[12.5,4.46]],"id":38206560},{"atb":[[1.36,89.96]],"id":40494181}],"con":true,"img":false}]}
{"op":"mcm","clk":"5306639039","pt":1646102613630,"mc":[{"id":"1.195395429","rc":[{"atb":[[1.38,23.73]],"id":40494181}],"con":true,"img":false}]}
{"op":"mcm","clk":"5306639106","pt":1646102614808,"mc":[{"id":"1.195395429","rc":[{"atb":[[1.38,50.33]],"id":40494181}],"con":true,"img":false}]}
{"op":"mcm","clk":"5306639533","pt":1646102624944,"mc":[{"id":"1.195395429","rc":[{"atl":[[36,0]],"id":39520250},{"spn":31.25,"spf":1.0,"id":39520250},{"atl":[[80,0]],"id":36104895},{"spn":61.5,"spf":1.0,"id":36104895},{"spn":1.37,"spf":1.0,"id":40494181}],"con":true,"img":false}]}
{"op":"mcm","clk":"5306639537","pt":1646102625044,"mc":[{"id":"1.195395429","rc":[{"atl":[[34,2.7]],"id":39520250},{"atl":[[75,2.7]],"id":36104895}],"con":true,"img":false}]}
{"op":"mcm","clk":"5306642310","pt":1646102679281,"mc":[{"id":"1.195395429","rc":[{"atb":[[12.5,0]],"id":38206560},{"atb":[[1.36,2]],"id":40494181}],"con":true,"img":false}]}
{"op":"mcm","clk":"5306642316","pt":1646102679384,"mc":[{"id":"1.195395429","rc":[{"atb":[[13,4.46]],"id":38206560},{"atb":[[1.39,87.96]],"id":40494181}],"con":true,"img":false}]}
{"op":"mcm","clk":"5306642523","pt":1646102685813,"mc":[{"id":"1.195395429","rc":[{"spn":23.25,"spf":1.0,"id":39520250},{"spn":49.0,"spf":1.0,"id":36104895},{"atb":[[1.38,26.59]],"id":40494181},{"spn":1.39,"spf":1.0,"id":40494181}],"con":true,"img":false}]}
{"op":"mcm","clk":"5306642765","pt":1646102693135,"mc":[{"id":"1.195395429","rc":[{"atb":[[1.38,0]],"id":40494181}],"con":true,"img":false}]}
{"op":"mcm","clk":"5306642837","pt":1646102694707,"mc":[{"id":"1.195395429","rc":[{"atb":[[1.41,21.99]],"id":40494181}],"con":true,"img":false}]}
{"op":"mcm","clk":"5306642969","pt":1646102699103,"mc":[{"id":"1.195395429","rc":[{"atb":[[1.41,46.63]],"id":40494181}],"con":true,"img":false}]}
{"op":"mcm","clk":"5306643280","pt":1646102706330,"mc":[{"id":"1.195395429","rc":[{"atb":[[10,0],[12.5,11.36]],"id":38206560}],"con":true,"img":false}]}
{"op":"mcm","clk":"5306644276","pt":1646102733293,"mc":[{"id":"1.195395429","rc":[{"atb":[[1.39,0]],"id":40494181}],"con":true,"img":false}]}
{"op":"mcm","clk":"5306644284","pt":1646102733393,"mc":[{"id":"1.195395429","rc":[{"atb":[[1.37,87.96]],"id":40494181}],"con":true,"img":false}]}
{"op":"mcm","clk":"5306644514","pt":1646102739993,"mc":[{"id":"1.195395429","rc":[{"atb":[[1.41,24.63]],"id":40494181}],"con":true,"img":false}]}
{"op":"mcm","clk":"5306644763","pt":1646102747300,"mc":[{"id":"1.195395429","rc":[{"atb":[[1.41,0]],"id":40494181},{"spn":1.37,"spf":1.0,"id":40494181}],"con":true,"img":false}]}
{"op":"mcm","clk":"5306644808","pt":1646102748885,"mc":[{"id":"1.195395429","rc":[{"atb":[[1.39,19.11]],"id":40494181}],"con":true,"img":false}]}
{"op":"mcm","clk":"5306644948","pt":1646102753240,"mc":[{"id":"1.195395429","rc":[{"atb":[[1.39,45]],"id":40494181}],"con":true,"img":false}]}
{"op":"mcm","clk":"5306646185","pt":1646102785622,"mc":[{"id":"1.195395429","rc":[{"atb":[[1.37,0]],"id":40494181}],"con":true,"img":false}]}
{"op":"mcm","clk":"5306646188","pt":1646102785724,"mc":[{"id":"1.195395429","rc":[{"atb":[[1.4,87.96]],"id":40494181}],"con":true,"img":false}]}
{"op":"mcm","clk":"5306646487","pt":1646102794068,"mc":[{"id":"1.195395429","rc":[{"atb":[[1.39,25.89]],"id":40494181}],"con":true,"img":false}]}
{"op":"mcm","clk":"5306646710","pt":1646102801359,"mc":[{"id":"1.195395429","rc":[{"atb":[[1.39,0]],"id":40494181}],"con":true,"img":false}]}
{"op":"mcm","clk":"5306654517","pt":1646102803005,"mc":[{"id":"1.195395429","rc":[{"atb":[[1.42,17.74]],"id":40494181}],"con":true,"img":false}]}
{"op":"mcm","clk":"5306654759","pt":1646102807459,"mc":[{"id":"1.195395429","rc":[{"atb":[[1.42,41.8]],"id":40494181},{"spn":1.41,"spf":1.0,"id":40494181}],"con":true,"img":false}]}
{"op":"mcm","clk":"5306655913","pt":1646102837244,"mc":[{"id":"1.195395429","rc":[{"atb":[[1.4,0]],"id":40494181}],"con":true,"img":false}]}
{"op":"mcm","clk":"5306655918","pt":1646102837345,"mc":[{"id":"1.195395429","rc":[{"atb":[[1.37,87.96]],"id":40494181}],"con":true,"img":false}]}
{"op":"mcm","clk":"5306656248","pt":1646102845080,"mc":[{"id":"1.195395429","rc":[{"atb":[[1.42,24.05]],"id":40494181}],"con":true,"img":false}]}
{"op":"mcm","clk":"5306656578","pt":1646102854082,"mc":[{"id":"1.195395429","rc":[{"atb":[[1.39,19.11]],"id":40494181}],"con":true,"img":false}]}
{"op":"mcm","clk":"5306656638","pt":1646102855770,"mc":[{"id":"1.195395429","rc":[{"atb":[[1.42,0]],"id":40494181}],"con":true,"img":false}]}
{"op":"mcm","clk":"5306656871","pt":1646102861694,"mc":[{"id":"1.195395429","rc":[{"atb":[[1.39,45]],"id":40494181}],"con":true,"img":false}]}
{"op":"mcm","clk":"5306657871","pt":1646102888333,"mc":[{"id":"1.195395429","rc":[{"atb":[[1.37,0]],"id":40494181},{"spn":1.38,"spf":1.0,"id":40494181}],"con":true,"img":false}]}
{"op":"mcm","clk":"5306657873","pt":1646102888436,"mc":[{"id":"1.195395429","rc":[{"atb":[[1.4,87.96]],"id":40494181}],"con":true,"img":false}]}
{"op":"mcm","clk":"5306658224","pt":1646102896219,"mc":[{"id":"1.195395429","rc":[{"atb":[[1.39,25.89]],"id":40494181}],"con":true,"img":false}]}
{"op":"mcm","clk":"5306658552","pt":1646102903754,"mc":[{"id":"1.195395429","rc":[{"atb":[[1.39,0]],"id":40494181}],"con":true,"img":false}]}
{"op":"mcm","clk":"5306658623","pt":1646102905240,"mc":[{"id":"1.195395429","rc":[{"atb":[[1.42,17.74]],"id":40494181}],"con":true,"img":false}]}
{"op":"mcm","clk":"5306658837","pt":1646102910173,"mc":[{"id":"1.195395429","rc":[{"atb":[[1.42,41.8]],"id":40494181}],"con":true,"img":false}]}
{"op":"mcm","clk":"5306660005","pt":1646102938990,"mc":[{"id":"1.195395429","rc":[{"atb":[[1.4,0]],"id":40494181}],"con":true,"img":false}]}
{"op":"mcm","clk":"5306660008","pt":1646102939091,"mc":[{"id":"1.195395429","rc":[{"atb":[[1.37,87.96]],"id":40494181}],"con":true,"img":false}]}
{"op":"mcm","clk":"5306660321","pt":1646102947400,"mc":[{"id":"1.195395429","rc":[{"atb":[[1.42,24.05]],"id":40494181}],"con":true,"img":false}]}
{"op":"mcm","clk":"5306660488","pt":1646102951907,"mc":[{"id":"1.195395429","rc":[{"atb":[[1.42,0]],"id":40494181},{"spn":1.37,"spf":1.0,"id":40494181}],"con":true,"img":false}]}
{"op":"mcm","clk":"5306660677","pt":1646102956366,"mc":[{"id":"1.195395429","rc":[{"atb":[[1.39,19.11]],"id":40494181}],"con":true,"img":false}]}
{"op":"mcm","clk":"5306660759","pt":1646102957957,"mc":[{"id":"1.195395429","rc":[{"atb":[[1.39,45]],"id":40494181}],"con":true,"img":false}]}
{"op":"mcm","clk":"5306662045","pt":1646102988480,"mc":[{"id":"1.195395429","rc":[{"atb":[[1.37,0]],"id":40494181}],"con":true,"img":false}]}
{"op":"mcm","clk":"5306662051","pt":1646102988581,"mc":[{"id":"1.195395429","rc":[{"atb":[[1.4,87.96]],"id":40494181}],"con":true,"img":false}]}
{"op":"mcm","clk":"5306662421","pt":1646102995478,"mc":[{"id":"1.195395429","rc":[{"atb":[[1.39,25.89]],"id":40494181}],"con":true,"img":false}]}
{"op":"mcm","clk":"5306662723","pt":1646103003079,"mc":[{"id":"1.195395429","rc":[{"atb":[[1.39,0]],"id":40494181}],"con":true,"img":false}]}
{"op":"mcm","clk":"5306662788","pt":1646103004412,"mc":[{"id":"1.195395429","rc":[{"atb":[[1.42,17.74]],"id":40494181}],"con":true,"img":false}]}
{"op":"mcm","clk":"5306663005","pt":1646103009077,"mc":[{"id":"1.195395429","rc":[{"atb":[[1.42,41.8]],"id":40494181}],"con":true,"img":false}]}
{"op":"mcm","clk":"5306664125","pt":1646103036557,"mc":[{"id":"1.195395429","rc":[{"atb":[[1.4,0]],"id":40494181},{"spn":1.4,"spf":1.0,"id":40494181}],"con":true,"img":false}]}
{"op":"mcm","clk":"5306664129","pt":1646103036657,"mc":[{"id":"1.195395429","rc":[{"atb":[[1.37,87.96]],"id":40494181}],"con":true,"img":false}]}
{"op":"mcm","clk":"5306664448","pt":1646103043561,"mc":[{"id":"1.195395429","rc":[{"atb":[[1.42,24.05]],"id":40494181}],"con":true,"img":false}]}
{"op":"mcm","clk":"5306664774","pt":1646103051250,"mc":[{"id":"1.195395429","rc":[{"atb":[[1.42,0]],"id":40494181}],"con":true,"img":false}]}
{"op":"mcm","clk":"5306664827","pt":1646103052478,"mc":[{"id":"1.195395429","rc":[{"atb":[[1.39,19.11]],"id":40494181}],"con":true,"img":false}]}
{"op":"mcm","clk":"5306665023","pt":1646103057281,"mc":[{"id":"1.195395429","rc":[{"atb":[[1.39,45]],"id":40494181}],"con":true,"img":false}]}
{"op":"mcm","clk":"5306666132","pt":1646103084608,"mc":[{"id":"1.195395429","rc":[{"atb":[[1.37,0]],"id":40494181}],"con":true,"img":false}]}
{"op":"mcm","clk":"5306666134","pt":1646103084710,"mc":[{"id":"1.195395429","rc":[{"atb":[[1.4,87.96]],"id":40494181}],"con":true,"img":false}]}
{"op":"mcm","clk":"5306666431","pt":1646103091610,"mc":[{"id":"1.195395429","rc":[{"atb":[[1.39,25.89]],"id":40494181}],"con":true,"img":false}]}
{"op":"mcm","clk":"5306666757","pt":1646103099255,"mc":[{"id":"1.195395429","rc":[{"atb":[[1.39,0]],"id":40494181},{"spn":1.4,"spf":1.0,"id":40494181}],"con":true,"img":false}]}
{"op":"mcm","clk":"5306666939","pt":1646103103560,"mc":[{"id":"1.195395429","rc":[{"atb":[[1.42,17.74]],"id":40494181}],"con":true,"img":false}]}
{"op":"mcm","clk":"5306667007","pt":1646103105249,"mc":[{"id":"1.195395429","rc":[{"atb":[[1.42,41.8]],"id":40494181}],"con":true,"img":false}]}
{"op":"mcm","clk":"5306668128","pt":1646103131796,"mc":[{"id":"1.195395429","rc":[{"atb":[[1.4,0]],"id":40494181}],"con":true,"img":false}]}
{"op":"mcm","clk":"5306668132","pt":1646103131848,"mc":[{"id":"1.195395429","rc":[{"atb":[[1.37,87.96]],"id":40494181}],"con":true,"img":false}]}
{"op":"mcm","clk":"5306668444","pt":1646103139574,"mc":[{"id":"1.195395429","rc":[{"atb":[[1.42,24.05]],"id":40494181}],"con":true,"img":false}]}
{"op":"mcm","clk":"5306668807","pt":1646103147918,"mc":[{"id":"1.195395429","rc":[{"atb":[[1.42,0]],"id":40494181}],"con":true,"img":false}]}
{"op":"mcm","clk":"5306668838","pt":1646103148583,"mc":[{"id":"1.195395429","rc":[{"atb":[[1.39,19.11]],"id":40494181}],"con":true,"img":false}]}
{"op":"mcm","clk":"5306669059","pt":1646103153293,"mc":[{"id":"1.195395429","rc":[{"atb":[[1.39,45]],"id":40494181}],"con":true,"img":false}]}
{"op":"mcm","clk":"5306670117","pt":1646103178844,"mc":[{"id":"1.195395429","rc":[{"atb":[[1.37,0]],"id":40494181},{"spn":1.38,"spf":1.0,"id":40494181}],"con":true,"img":false}]}
{"op":"mcm","clk":"5306670122","pt":1646103178945,"mc":[{"id":"1.195395429","rc":[{"atb":[[1.4,87.96]],"id":40494181}],"con":true,"img":false}]}
{"op":"mcm","clk":"5306670458","pt":1646103187748,"mc":[{"id":"1.195395429","rc":[{"atb":[[1.39,25.89]],"id":40494181}],"con":true,"img":false}]}
{"op":"mcm","clk":"5306670759","pt":1646103195685,"mc":[{"id":"1.195395429","rc":[{"atb":[[1.39,0]],"id":40494181}],"con":true,"img":false}]}
{"op":"mcm","clk":"5306670792","pt":1646103196659,"mc":[{"id":"1.195395429","rc":[{"atb":[[1.42,17.74]],"id":40494181}],"con":true,"img":false}]}
{"op":"mcm","clk":"5306671015","pt":1646103201474,"mc":[{"id":"1.195395429","rc":[{"atb":[[1.42,41.8]],"id":40494181}],"con":true,"img":false}]}
{"op":"mcm","clk":"5306671020","pt":1646103201679,"mc":[{"id":"1.195395429","rc":[{"atb":[[1.4,0]],"id":40494181}],"con":true,"img":false}]}
{"op":"mcm","clk":"5306671024","pt":1646103201783,"mc":[{"id":"1.195395429","rc":[{"atb":[[1.36,89.96]],"id":40494181}],"con":true,"img":false}]}
{"op":"mcm","clk":"5306671297","pt":1646103208788,"mc":[{"id":"1.195395429","rc":[{"atb":[[1.42,24.05]],"id":40494181}],"con":true,"img":false}]}
{"op":"mcm","clk":"5306671649","pt":1646103217700,"mc":[{"id":"1.195395429","rc":[{"atb":[[1.38,19.61]],"id":40494181}],"con":true,"img":false}]}
{"op":"mcm","clk":"5306671725","pt":1646103219598,"mc":[{"id":"1.195395429","rc":[{"atb":[[1.42,0]],"id":40494181}],"con":true,"img":false}]}
{"op":"mcm","clk":"5306671957","pt":1646103225538,"mc":[{"id":"1.195395429","rc":[{"atb":[[1.38,46.2]],"id":40494181}],"con":true,"img":false}]}
{"op":"mcm","clk":"5306674500","pt":1646103291606,"mc":[{"id":"1.195395429","rc":[{"atb":[[1.36,2]],"id":40494181},{"spn":1.37,"spf":1.0,"id":40494181}],"con":true,"img":false}]}
{"op":"mcm","clk":"5306674506","pt":1646103291707,"mc":[{"id":"1.195395429","rc":[{"atb":[[1.39,87.96]],"id":40494181}],"con":true,"img":false}]}
{"op":"mcm","clk":"5306674777","pt":1646103298942,"mc":[{"id":"1.195395429","rc":[{"atb":[[1.38,26.59]],"id":40494181}],"con":true,"img":false}]}
{"op":"mcm","clk":"5306675254","pt":1646103307827,"mc":[{"id":"1.195395429","rc":[{"atb":[[1.41,18.17]],"id":40494181}],"con":true,"img":false}]}
{"op":"mcm","clk":"5306675332","pt":1646103309731,"mc":[{"id":"1.195395429","rc":[{"atb":[[1.38,0]],"id":40494181}],"con":true,"img":false}]}
{"op":"mcm","clk":"5306675502","pt":1646103314135,"mc":[{"id":"1.195395429","rc":[{"atb":[[1.39,0]],"id":40494181}],"con":true,"img":false}]}
{"op":"mcm","clk":"5306675505","pt":1646103314239,"mc":[{"id":"1.195395429","rc":[{"atb":[[1.36,89.96]],"id":40494181}],"con":true,"img":false}]}
{"op":"mcm","clk":"5306675856","pt":1646103323044,"mc":[{"id":"1.195395429","rc":[{"atb":[[1.41,0]],"id":40494181}],"con":true,"img":false}]}
{"op":"mcm","clk":"5306676041","pt":1646103327750,"mc":[{"id":"1.195395429","rc":[{"atb":[[1.38,26.59]],"id":40494181}],"con":true,"img":false}]}
{"op":"mcm","clk":"5306676250","pt":1646103331956,"mc":[{"id":"1.195395429","rc":[{"atb":[[1.38,46.2]],"id":40494181}],"con":true,"img":false}]}
{"op":"mcm","clk":"5306677880","pt":1646103368365,"mc":[{"id":"1.195395429","marketDefinition":{"bspMarket":true,"turnInPlayEnabled":false,"persistenceEnabled":false,"marketBaseRate":7.0,"eventId":"31270458","eventTypeId":"4339","numberOfWinners":1,"bettingType":"ODDS","marketType":"WIN","marketTime":"2022-03-01T04:42:00.000Z","suspendTime":"2022-03-01T04:42:00.000Z","bspReconciled":false,"complete":true,"inPlay":false,"crossMatching":true,"runnersVoidable":false,"numberOfActiveRunners":8,"betDelay":0,"status":"OPEN","runners":[{"status":"ACTIVE","sortPriority":1,"id":40494181,"name":"1. Loch And Loaded"},{"status":"ACTIVE","sortPriority":2,"id":38206580,"name":"2. Buckle Up Wilder"},{"status":"ACTIVE","sortPriority":3,"id":38206560,"name":"3. Hiccup Amisha"},{"status":"ACTIVE","sortPriority":4,"id":36104895,"name":"4. Langley Roo"},{"status":"ACTIVE","sortPriority":5,"id":39520250,"name":"5. Rip On Bye"},{"status":"ACTIVE","sortPriority":6,"id":41762283,"name":"6. Gracies Joy"},{"status":"ACTIVE","sortPriority":7,"id":37401228,"name":"7. Just Mercy"},{"status":"ACTIVE","sortPriority":8,"id":27701417,"name":"8. Jalla General"}],"regulators":["MR_INT"],"venue":"Devonport","countryCode":"AU","discountAllowed":true,"timezone":"Australia/Sydney","openDate":"2022-03-01T02:00:00.000Z","version":4381084011,"name":"R6 452m Gr4","eventName":"Devonport (AUS) 1st Mar"},"rc":[],"con":true,"img":false}]}
{"op":"mcm","clk":"5306678039","pt":1646103372230,"mc":[{"id":"1.195395429","rc":[{"atb":[[7.2,0]],"id":41762283},{"trd":[[7.2,3.23]],"ltp":7.2,"tv":3.23,"id":41762283},{"spn":11.9,"spf":1.0,"id":41762283},{"spn":1.37,"spf":1.0,"id":40494181}],"con":true,"img":false}]}
{"op":"mcm","clk":"5306678305","pt":1646103378858,"mc":[{"id":"1.195395429","rc":[{"atb":[[1.36,2]],"id":40494181}],"con":true,"img":false}]}
{"op":"mcm","clk":"5306678310","pt":1646103378960,"mc":[{"id":"1.195395429","rc":[{"atb":[[1.39,87.96]],"id":40494181}],"con":true,"img":false}]}
{"op":"mcm","clk":"5306678347","pt":1646103379729,"mc":[{"id":"1.195395429","rc":[{"atb":[[6.8,0]],"id":41762283},{"trd":[[6.8,3.1]],"ltp":6.8,"tv":3.1,"id":41762283}],"con":true,"img":false}]}
{"op":"mcm","clk":"5306678363","pt":1646103380039,"mc":[{"id":"1.195395429","rc":[{"atl":[[1000,2.23]],"id":41762283}],"con":true,"img":false}]}
{"op":"mcm","clk":"5306678379","pt":1646103380247,"mc":[{"id":"1.195395429","rc":[{"atl":[[1000,1.28]],"id":41762283}],"con":true,"img":false}]}
{"op":"mcm","clk":"5306678396","pt":1646103380452,"mc":[{"id":"1.195395429","rc":[{"atl":[[1000,0]],"id":41762283}],"con":true,"img":false}]}
{"op":"mcm","clk":"5306678401","pt":1646103380554,"mc":[{"id":"1.195395429","rc":[{"atl":[[8.2,1.28]],"id":41762283}],"con":true,"img":false}]}
{"op":"mcm","clk":"5306678635","pt":1646103386051,"mc":[{"id":"1.195395429","rc":[{"atb":[[1.38,26.59]],"id":40494181}],"con":true,"img":false}]}
{"op":"mcm","clk":"5306678962","pt":1646103393972,"mc":[{"id":"1.195395429","rc":[{"atb":[[1.38,0]],"id":40494181}],"con":true,"img":false}]}
{"op":"mcm","clk":"5306679013","pt":1646103395040,"mc":[{"id":"1.195395429","rc":[{"atb":[[1.41,18.17]],"id":40494181}],"con":true,"img":false}]}
{"op":"mcm","clk":"5306679255","pt":1646103400378,"mc":[{"id":"1.195395429","rc":[{"atb":[[1.39,0]],"id":40494181}],"con":true,"img":false}]}
{"op":"mcm","clk":"5306679260","pt":1646103400480,"mc":[{"id":"1.195395429","rc":[{"atb":[[1.36,89.96]],"id":40494181}],"con":true,"img":false}]}
{"op":"mcm","clk":"5306679515","pt":1646103407091,"mc":[{"id":"1.195395429","rc":[{"atb":[[1.41,0]],"id":40494181}],"con":true,"img":false}]}
{"op":"mcm","clk":"5306679829","pt":1646103416061,"mc":[{"id":"1.195395429","rc":[{"atb":[[1.38,19.61]],"id":40494181}],"con":true,"img":false}]}
{"op":"mcm","clk":"5306679897","pt":1646103418110,"mc":[{"id":"1.195395429","rc":[{"atb":[[1.38,46.2]],"id":40494181}],"con":true,"img":false}]}
{"op":"mcm","clk":"5306681452","pt":1646103464245,"mc":[{"id":"1.195395429","rc":[{"spn":7.4,"spf":1.0,"id":41762283},{"atb":[[1.36,2]],"id":40494181},{"spn":1.37,"spf":1.0,"id":40494181}],"con":true,"img":false}]}
{"op":"mcm","clk":"5306681455","pt":1646103464349,"mc":[{"id":"1.195395429","rc":[{"atb":[[1.39,87.96]],"id":40494181}],"con":true,"img":false}]}
{"op":"mcm","clk":"5306681780","pt":1646103473262,"mc":[{"id":"1.195395429","rc":[{"atb":[[1.38,26.59]],"id":40494181}],"con":true,"img":false}]}
{"op":"mcm","clk":"5306681904","pt":1646103478072,"mc":[{"id":"1.195395429","rc":[{"atb":[[1.38,0]],"id":40494181}],"con":true,"img":false}]}
{"op":"mcm","clk":"5306682040","pt":1646103482173,"mc":[{"id":"1.195395429","rc":[{"atb":[[1.41,18.17]],"id":40494181}],"con":true,"img":false}]}
{"op":"mcm","clk":"5306682093","pt":1646103483962,"mc":[{"id":"1.195395429","rc":[{"atb":[[1.41,42.81]],"id":40494181}],"con":true,"img":false}]}
{"op":"mcm","clk":"5306682412","pt":1646103494189,"mc":[{"id":"1.195395429","rc":[{"atl":[[8.2,0]],"id":41762283}],"con":true,"img":false}]}
{"op":"mcm","clk":"5306682417","pt":1646103494293,"mc":[{"id":"1.195395429","rc":[{"atl":[[1000,2.23]],"id":41762283}],"con":true,"img":false}]}
{"op":"mcm","clk":"5306682424","pt":1646103494497,"mc":[{"id":"1.195395429","rc":[{"atl":[[1000,0.6]],"id":41762283}],"con":true,"img":false}]}
{"op":"mcm","clk":"5306682429","pt":1646103494701,"mc":[{"id":"1.195395429","rc":[{"atl":[[1000,0]],"id":41762283}],"con":true,"img":false}]}
{"op":"mcm","clk":"5306682434","pt":1646103494803,"mc":[{"id":"1.195395429","rc":[{"atl":[[17.5,0.6]],"id":41762283}],"con":true,"img":false}]}
{"op":"mcm","clk":"5306682498","pt":1646103497306,"mc":[{"id":"1.195395429","rc":[{"atl":[[17.5,0]],"id":41762283}],"con":true,"img":false}]}
{"op":"mcm","clk":"5306682501","pt":1646103497408,"mc":[{"id":"1.195395429","rc":[{"atl":[[1000,2.23]],"id":41762283}],"con":true,"img":false}]}
{"op":"mcm","clk":"5306682510","pt":1646103497713,"mc":[{"id":"1.195395429","rc":[{"atl":[[1000,0.64]],"id":41762283}],"con":true,"img":false}]}
{"op":"mcm","clk":"5306682516","pt":1646103497919,"mc":[{"id":"1.195395429","rc":[{"atl":[[1000,0]],"id":41762283}],"con":true,"img":false}]}
{"op":"mcm","clk":"5306682519","pt":1646103498020,"mc":[{"id":"1.195395429","rc":[{"atl":[[16.5,0.64]],"id":41762283}],"con":true,"img":false}]}
{"op":"mcm","clk":"5306682748","pt":1646103505995,"mc":[{"id":"1.195395429","rc":[{"atb":[[1.39,0]],"id":40494181}],"con":true,"img":false}]}
{"op":"mcm","clk":"5306682751","pt":1646103506097,"mc":[{"id":"1.195395429","rc":[{"atb":[[1.37,87.96]],"id":40494181}],"con":true,"img":false}]}
{"op":"mcm","clk":"5306682982","pt":1646103515354,"mc":[{"id":"1.195395429","rc":[{"atb":[[1.41,24.63]],"id":40494181}],"con":true,"img":false}]}
{"op":"mcm","clk":"5306683125","pt":1646103520222,"mc":[{"id":"1.195395429","rc":[{"atb":[[1.41,0]],"id":40494181}],"con":true,"img":false}]}
{"op":"mcm","clk":"5306683249","pt":1646103524221,"mc":[{"id":"1.195395429","rc":[{"atb":[[1.39,19.11]],"id":40494181}],"con":true,"img":false}]}
{"op":"mcm","clk":"5306683289","pt":1646103526166,"mc":[{"id":"1.195395429","rc":[{"spn":11.55,"spf":1.0,"id":41762283},{"atb":[[1.39,45]],"id":40494181},{"spn":1.38,"spf":1.0,"id":40494181}],"con":true,"img":false}]}
{"op":"mcm","clk":"5306683828","pt":1646103547200,"mc":[{"id":"1.195395429","rc":[{"atb":[[1.37,0]],"id":40494181}],"con":true,"img":false}]}
{"op":"mcm","clk":"5306683829","pt":1646103547301,"mc":[{"id":"1.195395429","rc":[{"atb":[[1.4,87.96]],"id":40494181}],"con":true,"img":false}]}
{"op":"mcm","clk":"5306684078","pt":1646103554371,"mc":[{"id":"1.195395429","rc":[{"atb":[[1.39,25.89]],"id":40494181}],"con":true,"img":false}]}
{"op":"mcm","clk":"5306684353","pt":1646103562303,"mc":[{"id":"1.195395429","rc":[{"atb":[[1.39,0]],"id":40494181}],"con":true,"img":false}]}
{"op":"mcm","clk":"5306684385","pt":1646103563279,"mc":[{"id":"1.195395429","rc":[{"atb":[[1.42,17.74]],"id":40494181}],"con":true,"img":false}]}
{"op":"mcm","clk":"5306684509","pt":1646103568202,"mc":[{"id":"1.195395429","rc":[{"atb":[[1.42,41.8]],"id":40494181}],"con":true,"img":false}]}
{"op":"mcm","clk":"5306685105","pt":1646103585847,"mc":[{"id":"1.195395429","rc":[{"atb":[[1.4,0]],"id":40494181}],"con":true,"img":false}]}
{"op":"mcm","clk":"5306685109","pt":1646103585951,"mc":[{"id":"1.195395429","rc":[{"atb":[[1.38,87.96]],"id":40494181}],"con":true,"img":false}]}
{"op":"mcm","clk":"5306685382","pt":1646103593535,"mc":[{"id":"1.195395429","rc":[{"atb":[[1.42,24.05]],"id":40494181},{"spn":1.39,"spf":1.0,"id":40494181}],"con":true,"img":false}]}
{"op":"mcm","clk":"5306685749","pt":1646103602434,"mc":[{"id":"1.195395429","rc":[{"atb":[[1.4,18.63]],"id":40494181}],"con":true,"img":false}]}
{"op":"mcm","clk":"5306685848","pt":1646103604340,"mc":[{"id":"1.195395429","rc":[{"atb":[[1.42,0]],"id":40494181}],"con":true,"img":false}]}
{"op":"mcm","clk":"5306686065","pt":1646103610247,"mc":[{"id":"1.195395429","rc":[{"atb":[[1.4,43.88]],"id":40494181}],"con":true,"img":false}]}
{"op":"mcm","clk":"5306686223","pt":1646103615172,"mc":[{"id":"1.195395429","rc":[{"atl":[[16.5,0]],"id":37401228}],"con":true,"img":false}]}
{"op":"mcm","clk":"5306686226","pt":1646103615286,"mc":[{"id":"1.195395429","rc":[{"atl":[[16,3.74]],"id":37401228}],"con":true,"img":false}]}
{"op":"mcm","clk":"5306687439","pt":1646103654733,"mc":[{"id":"1.195395429","rc":[{"atb":[[1.38,0]],"id":40494181},{"spn":1.38,"spf":1.0,"id":40494181}],"con":true,"img":false}]}
{"op":"mcm","clk":"5306687445","pt":1646103654833,"mc":[{"id":"1.195395429","rc":[{"atb":[[1.41,87.96]],"id":40494181}],"con":true,"img":false}]}
{"op":"mcm","clk":"5306687707","pt":1646103662522,"mc":[{"id":"1.195395429","rc":[{"atb":[[1.4,25.25]],"id":40494181}],"con":true,"img":false}]}
{"op":"mcm","clk":"5306687880","pt":1646103667608,"mc":[{"id":"1.195395429","rc":[{"atb":[[1.4,0]],"id":40494181}],"con":true,"img":false}]}
{"op":"mcm","clk":"5306688008","pt":1646103671550,"mc":[{"id":"1.195395429","rc":[{"atb":[[1.43,17.33]],"id":40494181}],"con":true,"img":false}]}
{"op":"mcm","clk":"5306688096","pt":1646103673548,"mc":[{"id":"1.195395429","rc":[{"atb":[[1.41,0]],"id":40494181}],"con":true,"img":false}]}
{"op":"mcm","clk":"5306688102","pt":1646103673649,"mc":[{"id":"1.195395429","rc":[{"atb":[[1.37,87.96]],"id":40494181}],"con":true,"img":false}]}
{"op":"mcm","clk":"5306688110","pt":1646103673757,"mc":[{"id":"1.195395429","rc":[{"atb":[[1.43,36.75]],"id":40494181}],"con":true,"img":false}]}
{"op":"mcm","clk":"5306688421","pt":1646103680627,"mc":[{"id":"1.195395429","rc":[{"atb":[[1.43,19.42]],"id":40494181}],"con":true,"img":false}]}
{"op":"mcm","clk":"5306688873","pt":1646103691558,"mc":[{"id":"1.195395429","rc":[{"atb":[[1.43,0]],"id":40494181}],"con":true,"img":false}]}
{"op":"mcm","clk":"5306688914","pt":1646103692479,"mc":[{"id":"1.195395429","rc":[{"atb":[[1.39,19.11]],"id":40494181}],"con":true,"img":false}]}
{"op":"mcm","clk":"5306689114","pt":1646103697496,"mc":[{"id":"1.195395429","rc":[{"atb":[[1.39,40.51]],"id":40494181}],"con":true,"img":false}]}
{"op":"mcm","clk":"5306691057","pt":1646103752151,"mc":[{"id":"1.195395429","rc":[{"atb":[[1.37,0]],"id":40494181},{"spn":1.37,"spf":1.0,"id":40494181}],"con":true,"img":false}]}
{"op":"mcm","clk":"5306691062","pt":1646103752254,"mc":[{"id":"1.195395429","rc":[{"atb":[[1.4,87.96]],"id":40494181}],"con":true,"img":false}]}
{"op":"mcm","clk":"5306691337","pt":1646103758768,"mc":[{"id":"1.195395429","rc":[{"atb":[[1.39,21.4]],"id":40494181}],"con":true,"img":false}]}
{"op":"mcm","clk":"5306691606","pt":1646103767687,"mc":[{"id":"1.195395429","rc":[{"atb":[[1.42,17.74]],"id":40494181}],"con":true,"img":false}]}
{"op":"mcm","clk":"5306691672","pt":1646103769683,"mc":[{"id":"1.195395429","rc":[{"atb":[[1.39,0]],"id":40494181}],"con":true,"img":false}]}
{"op":"mcm","clk":"5306691703","pt":1646103770603,"mc":[{"id":"1.195395429","rc":[{"atb":[[1.4,0]],"id":40494181}],"con":true,"img":false}]}
{"op":"mcm","clk":"5306691705","pt":1646103770705,"mc":[{"id":"1.195395429","rc":[{"atb":[[1.37,87.96]],"id":40494181}],"con":true,"img":false}]}
{"op":"mcm","clk":"5306691983","pt":1646103779797,"mc":[{"id":"1.195395429","rc":[{"atb":[[1.42,0]],"id":40494181}],"con":true,"img":false}]}
{"op":"mcm","clk":"5306692239","pt":1646103787590,"mc":[{"id":"1.195395429","rc":[{"atb":[[1.39,21.4]],"id":40494181}],"con":true,"img":false}]}
{"op":"mcm","clk":"5306692278","pt":1646103788719,"mc":[{"id":"1.195395429","rc":[{"atb":[[1.39,40.51]],"id":40494181}],"con":true,"img":false}]}
{"op":"mcm","clk":"5306693650","pt":1646103826996,"mc":[{"id":"1.195395429","rc":[{"atb":[[1.37,0]],"id":40494181}],"con":true,"img":false}]}
{"op":"mcm","clk":"5306693655","pt":1646103827098,"mc":[{"id":"1.195395429","rc":[{"atb":[[1.4,87.96]],"id":40494181}],"con":true,"img":false}]}
{"op":"mcm","clk":"5306693917","pt":1646103833894,"mc":[{"id":"1.195395429","rc":[{"atb":[[1.39,21.4]],"id":40494181}],"con":true,"img":false}]}
{"op":"mcm","clk":"5306694199","pt":1646103841724,"mc":[{"id":"1.195395429","rc":[{"atb":[[1.39,0]],"id":40494181}],"con":true,"img":false}]}
{"op":"mcm","clk":"5306694243","pt":1646103842801,"mc":[{"id":"1.195395429","rc":[{"atb":[[1.42,17.74]],"id":40494181}],"con":true,"img":false}]}
{"op":"mcm","clk":"5306694381","pt":1646103846227,"mc":[{"id":"1.195395429","rc":[{"atb":[[1.4,0]],"id":40494181}],"con":true,"img":false}]}
{"op":"mcm","clk":"5306694389","pt":1646103846331,"mc":[{"id":"1.195395429","rc":[{"atb":[[1.37,87.96]],"id":40494181}],"con":true,"img":false}]}
{"op":"mcm","clk":"5306694716","pt":1646103854817,"mc":[{"id":"1.195395429","rc":[{"atb":[[1.42,0]],"id":40494181}],"con":true,"img":false}]}
{"op":"mcm","clk":"5306694931","pt":1646103859726,"mc":[{"id":"1.195395429","rc":[{"atb":[[1.39,21.4]],"id":40494181}],"con":true,"img":false}]}
{"op":"mcm","clk":"5306695105","pt":1646103863826,"mc":[{"id":"1.195395429","rc":[{"atb":[[1.39,40.51]],"id":40494181}],"con":true,"img":false}]}
{"op":"mcm","clk":"5306696555","pt":1646103900805,"mc":[{"id":"1.195395429","rc":[{"atb":[[1.37,0]],"id":40494181}],"con":true,"img":false}]}
{"op":"mcm","clk":"5306696561","pt":1646103900907,"mc":[{"id":"1.195395429","rc":[{"atb":[[1.4,87.96]],"id":40494181}],"con":true,"img":false}]}
{"op":"mcm","clk":"5306696870","pt":1646103908991,"mc":[{"id":"1.195395429","rc":[{"atb":[[1.39,21.4]],"id":40494181}],"con":true,"img":false}]}
{"op":"mcm","clk":"5306697030","pt":1646103913902,"mc":[{"id":"1.195395429","rc":[{"atb":[[1.39,0]],"id":40494181}],"con":true,"img":false}]}
{"op":"mcm","clk":"5306697154","pt":1646103917896,"mc":[{"id":"1.195395429","rc":[{"atb":[[1.42,17.74]],"id":40494181}],"con":true,"img":false}]}
{"op":"mcm","clk":"5306697201","pt":1646103919226,"mc":[{"id":"1.195395429","rc":[{"atb":[[1.4,0]],"id":40494181}],"con":true,"img":false}]}
{"op":"mcm","clk":"5306697205","pt":1646103919328,"mc":[{"id":"1.195395429","rc":[{"atb":[[1.37,87.96]],"id":40494181}],"con":true,"img":false}]}
{"op":"mcm","clk":"5306697521","pt":1646103926912,"mc":[{"id":"1.195395429","rc":[{"atb":[[1.42,0]],"id":40494181}],"con":true,"img":false}]}
{"op":"mcm","clk":"5306697878","pt":1646103935923,"mc":[{"id":"1.195395429","rc":[{"atb":[[1.39,19.11]],"id":40494181}],"con":true,"img":false}]}
{"op":"mcm","clk":"5306697941","pt":1646103937860,"mc":[{"id":"1.195395429","rc":[{"atb":[[1.39,40.51]],"id":40494181}],"con":true,"img":false}]}
{"op":"mcm","clk":"5306700036","pt":1646103990912,"mc":[{"id":"1.195395429","rc":[{"atb":[[1.37,0]],"id":40494181}],"con":true,"img":false}]}
{"op":"mcm","clk":"5306700042","pt":1646103991016,"mc":[{"id":"1.195395429","rc":[{"atb":[[1.4,87.96]],"id":40494181}],"con":true,"img":false}]}
{"op":"mcm","clk":"5306700395","pt":1646103999152,"mc":[{"id":"1.195395429","rc":[{"atb":[[1.39,21.4]],"id":40494181}],"con":true,"img":false}]}
{"op":"mcm","clk":"5306700574","pt":1646104004166,"mc":[{"id":"1.195395429","rc":[{"atb":[[1.39,0]],"id":40494181}],"con":true,"img":false}]}
{"op":"mcm","clk":"5306700763","pt":1646104008060,"mc":[{"id":"1.195395429","rc":[{"atb":[[1.42,17.74]],"id":40494181}],"con":true,"img":false}]}
{"op":"mcm","clk":"5306700785","pt":1646104008472,"mc":[{"id":"1.195395429","rc":[{"atb":[[1.4,0]],"id":40494181}],"con":true,"img":false}]}
{"op":"mcm","clk":"5306700789","pt":1646104008523,"mc":[{"id":"1.195395429","rc":[{"atb":[[1.37,87.96]],"id":40494181}],"con":true,"img":false}]}
{"op":"mcm","clk":"5306701201","pt":1646104017184,"mc":[{"id":"1.195395429","rc":[{"atb":[[1.42,0]],"id":40494181}],"con":true,"img":false}]}
{"op":"mcm","clk":"5306701420","pt":1646104021950,"mc":[{"id":"1.195395429","rc":[{"atb":[[1.39,21.4]],"id":40494181}],"con":true,"img":false}]}
{"op":"mcm","clk":"5306701626","pt":1646104026093,"mc":[{"id":"1.195395429","rc":[{"atb":[[1.39,40.51]],"id":40494181}],"con":true,"img":false}]}
{"op":"mcm","clk":"5306703888","pt":1646104077947,"mc":[{"id":"1.195395429","rc":[{"atb":[[1.37,0]],"id":40494181}],"con":true,"img":false}]}
{"op":"mcm","clk":"5306703892","pt":1646104078049,"mc":[{"id":"1.195395429","rc":[{"atb":[[1.4,87.96]],"id":40494181}],"con":true,"img":false}]}
{"op":"mcm","clk":"5306704172","pt":1646104086231,"mc":[{"id":"1.195395429","rc":[{"atb":[[1.39,21.4]],"id":40494181}],"con":true,"img":false}]}
{"op":"mcm","clk":"5306704449","pt":1646104094348,"mc":[{"id":"1.195395429","rc":[{"atb":[[1.39,0]],"id":40494181}],"con":true,"img":false}]}
{"op":"mcm","clk":"5306704484","pt":1646104095266,"mc":[{"id":"1.195395429","rc":[{"atb":[[1.42,17.74]],"id":40494181}],"con":true,"img":false}]}
{"op":"mcm","clk":"5306704510","pt":1646104095880,"mc":[{"id":"1.195395429","rc":[{"atb":[[1.4,0]],"id":40494181}],"con":true,"img":false}]}
{"op":"mcm","clk":"5306704515","pt":1646104095982,"mc":[{"id":"1.195395429","rc":[{"atb":[[1.37,87.96]],"id":40494181}],"con":true,"img":false}]}
{"op":"mcm","clk":"5306704773","pt":1646104104365,"mc":[{"id":"1.195395429","rc":[{"atb":[[1.42,0]],"id":40494181}],"con":true,"img":false}]}
{"op":"mcm","clk":"5306704982","pt":1646104112165,"mc":[{"id":"1.195395429","rc":[{"atb":[[1.39,21.4]],"id":40494181}],"con":true,"img":false}]}
{"op":"mcm","clk":"5306705029","pt":1646104113289,"mc":[{"id":"1.195395429","rc":[{"atb":[[1.39,40.51]],"id":40494181}],"con":true,"img":false}]}
{"op":"mcm","clk":"5306706789","pt":1646104162773,"mc":[{"id":"1.195395429","rc":[{"atb":[[1.37,0]],"id":40494181}],"con":true,"img":false}]}
{"op":"mcm","clk":"5306706792","pt":1646104162873,"mc":[{"id":"1.195395429","rc":[{"atb":[[1.4,87.96]],"id":40494181}],"con":true,"img":false}]}
{"op":"mcm","clk":"5306707041","pt":1646104170481,"mc":[{"id":"1.195395429","rc":[{"atb":[[1.39,21.4]],"id":40494181}],"con":true,"img":false}]}
{"op":"mcm","clk":"5306707286","pt":1646104178499,"mc":[{"id":"1.195395429","rc":[{"atb":[[1.39,0]],"id":40494181}],"con":true,"img":false}]}
{"op":"mcm","clk":"5306707315","pt":1646104179373,"mc":[{"id":"1.195395429","rc":[{"atb":[[1.42,17.74]],"id":40494181}],"con":true,"img":false}]}
{"op":"mcm","clk":"5306707323","pt":1646104179678,"mc":[{"id":"1.195395429","rc":[{"atb":[[1.4,0]],"id":40494181}],"con":true,"img":false}]}
{"op":"mcm","clk":"5306707324","pt":1646104179780,"mc":[{"id":"1.195395429","rc":[{"atb":[[1.37,87.96]],"id":40494181}],"con":true,"img":false}]}
{"op":"mcm","clk":"5306707609","pt":1646104188414,"mc":[{"id":"1.195395429","rc":[{"atb":[[1.42,0]],"id":40494181}],"con":true,"img":false}]}
{"op":"mcm","clk":"5306707852","pt":1646104196380,"mc":[{"id":"1.195395429","rc":[{"atb":[[1.39,21.4]],"id":40494181}],"con":true,"img":false}]}
{"op":"mcm","clk":"5306707886","pt":1646104197398,"mc":[{"id":"1.195395429","rc":[{"atb":[[1.39,40.51]],"id":40494181}],"con":true,"img":false}]}
{"op":"mcm","clk":"5306709748","pt":1646104245563,"mc":[{"id":"1.195395429","rc":[{"atb":[[1.37,0]],"id":40494181}],"con":true,"img":false}]}
{"op":"mcm","clk":"5306709753","pt":1646104245664,"mc":[{"id":"1.195395429","rc":[{"atb":[[1.4,87.96]],"id":40494181}],"con":true,"img":false}]}
{"op":"mcm","clk":"5306710163","pt":1646104254567,"mc":[{"id":"1.195395429","rc":[{"atb":[[1.39,21.4]],"id":40494181}],"con":true,"img":false}]}
{"op":"mcm","clk":"5306710430","pt":1646104261483,"mc":[{"id":"1.195395429","rc":[{"atb":[[1.4,0]],"id":40494181}],"con":true,"img":false}]}
{"op":"mcm","clk":"5306710435","pt":1646104261585,"mc":[{"id":"1.195395429","rc":[{"atb":[[1.37,87.96]],"id":40494181}],"con":true,"img":false}]}
{"op":"mcm","clk":"5306711134","pt":1646104278615,"mc":[{"id":"1.195395429","rc":[{"atb":[[1.39,40.51]],"id":40494181}],"con":true,"img":false}]}
{"op":"mcm","clk":"5306713042","pt":1646104321387,"mc":[{"id":"1.195395429","rc":[{"atb":[[22,0]],"id":36104895},{"atb":[[7.2,0]],"id":37401228},{"spn":1.38,"spf":1.0,"id":40494181}],"con":true,"img":false}]}
{"op":"mcm","clk":"5306713048","pt":1646104321439,"mc":[{"id":"1.195395429","rc":[{"atb":[[23,5.07]],"id":36104895},{"atb":[[7.4,17.42]],"id":37401228}],"con":true,"img":false}]}
{"op":"mcm","clk":"5306713120","pt":1646104323177,"mc":[{"id":"1.195395429","rc":[{"atb":[[4.6,2]],"id":41762283}],"con":true,"img":false}]}
{"op":"mcm","clk":"5306713689","pt":1646104336604,"mc":[{"id":"1.195395429","rc":[{"atb":[[1.37,0]],"id":40494181}],"con":true,"img":false}]}
{"op":"mcm","clk":"5306713695","pt":1646104336707,"mc":[{"id":"1.195395429","rc":[{"atb":[[1.4,87.96]],"id":40494181}],"con":true,"img":false}]}
{"op":"mcm","clk":"5306714147","pt":1646104344808,"mc":[{"id":"1.195395429","rc":[{"atb":[[1.39,21.4]],"id":40494181}],"con":true,"img":false}]}
{"op":"mcm","clk":"5306714603","pt":1646104353723,"mc":[{"id":"1.195395429","rc":[{"atb":[[1.42,17.74]],"id":40494181}],"con":true,"img":false}]}
{"op":"mcm","clk":"5306715336","pt":1646104367602,"mc":[{"id":"1.195395429","rc":[{"atb":[[1.4,0]],"id":40494181}],"con":true,"img":false}]}
{"op":"mcm","clk":"5306715341","pt":1646104367705,"mc":[{"id":"1.195395429","rc":[{"atb":[[1.37,87.96]],"id":40494181}],"con":true,"img":false}]}
{"op":"mcm","clk":"5306715723","pt":1646104374854,"mc":[{"id":"1.195395429","rc":[{"atb":[[1.42,0]],"id":40494181}],"con":true,"img":false}]}
{"op":"mcm","clk":"5306716212","pt":1646104383755,"mc":[{"id":"1.195395429","rc":[{"atb":[[1.39,40.51]],"id":40494181}],"con":true,"img":false}]}
{"op":"mcm","clk":"5306718805","pt":1646104429605,"mc":[{"id":"1.195395429","rc":[{"atb":[[1.37,0]],"id":40494181}],"con":true,"img":false}]}
{"op":"mcm","clk":"5306718807","pt":1646104429708,"mc":[{"id":"1.195395429","rc":[{"atb":[[1.4,87.96]],"id":40494181}],"con":true,"img":false}]}
{"op":"mcm","clk":"5306718996","pt":1646104434017,"mc":[{"id":"1.195395429","rc":[{"atb":[[1.39,19.11]],"id":40494181}],"con":true,"img":false}]}
{"op":"mcm","clk":"5306719152","pt":1646104437852,"mc":[{"id":"1.195395429","rc":[{"atb":[[1.39,0]],"id":40494181}],"con":true,"img":false}]}
{"op":"mcm","clk":"5306719489","pt":1646104445837,"mc":[{"id":"1.195395429","rc":[{"atb":[[1.42,19.87]],"id":40494181},{"spn":1.4,"spf":1.0,"id":40494181}],"con":true,"img":false}]}
{"op":"mcm","clk":"5306719532","pt":1646104446861,"mc":[{"id":"1.195395429","rc":[{"atb":[[1.42,37.62]],"id":40494181}],"con":true,"img":false}]}
{"op":"mcm","clk":"5306721511","pt":1646104490316,"mc":[{"id":"1.195395429","rc":[{"atb":[[1.4,0]],"id":40494181}],"con":true,"img":false}]}
{"op":"mcm","clk":"5306721515","pt":1646104490417,"mc":[{"id":"1.195395429","rc":[{"atb":[[1.38,87.96]],"id":40494181}],"con":true,"img":false}]}
{"op":"mcm","clk":"5306721837","pt":1646104498036,"mc":[{"id":"1.195395429","rc":[{"atb":[[1.42,19.87]],"id":40494181}],"con":true,"img":false}]}
{"op":"mcm","clk":"5306722241","pt":1646104506957,"mc":[{"id":"1.195395429","rc":[{"atb":[[1.4,18.63]],"id":40494181},{"spn":1.4,"spf":1.0,"id":40494181}],"con":true,"img":false}]}
{"op":"mcm","clk":"5306730026","pt":1646104665480,"mc":[{"id":"1.195395429","rc":[{"atb":[[12.5,5.5]],"id":39520250},{"atb":[[7.2,10.08]],"id":38206580},{"atb":[[13.5,7.41]],"id":38206560},{"atb":[[7,15.45]],"id":37401228},{"atb":[[1.43,14.9]],"id":40494181},{"spn":1.41,"spf":1.0,"id":40494181}],"con":true,"img":false}]}
{"op":"mcm","clk":"5306730394","pt":1646104672285,"mc":[{"id":"1.195395429","rc":[{"atb":[[6.8,1.73]],"id":38206580}],"con":true,"img":false}]}
{"op":"mcm","clk":"5306731443","pt":1646104692448,"mc":[{"id":"1.195395429","rc":[{"atb":[[1.42,0]],"id":40494181}],"con":true,"img":false}]}
{"op":"mcm","clk":"5306731647","pt":1646104695735,"mc":[{"id":"1.195395429","rc":[{"atb":[[13,0]],"id":38206560},{"atb":[[6.8,0]],"id":37401228}],"con":true,"img":false}]}
{"op":"mcm","clk":"5306731652","pt":1646104695837,"mc":[{"id":"1.195395429","rc":[{"atb":[[14,4.46]],"id":38206560},{"atb":[[7.2,10]],"id":37401228}],"con":true,"img":false}]}
{"op":"mcm","clk":"5306731678","pt":1646104696245,"mc":[{"id":"1.195395429","rc":[{"atb":[[1.43,0]],"id":40494181}],"con":true,"img":false}]}
{"op":"mcm","clk":"5306731782","pt":1646104698445,"mc":[{"id":"1.195395429","rc":[{"atb":[[1.4,39.5]],"id":40494181}],"con":true,"img":false}]}
{"op":"mcm","clk":"5306731787","pt":1646104698548,"mc":[{"id":"1.195395429","rc":[{"atb":[[13.5,0]],"id":38206560},{"atb":[[7,0]],"id":37401228}],"con":true,"img":false}]}
{"op":"mcm","clk":"5306731893","pt":1646104700750,"mc":[{"id":"1.195395429","rc":[{"atb":[[1.34,46.58]],"id":40494181}],"con":true,"img":false}]}
{"op":"mcm","clk":"5306732012","pt":1646104703362,"mc":[{"id":"1.195395429","rc":[{"atb":[[14.5,6.87]],"id":38206560},{"atb":[[7.6,13.06]],"id":37401228}],"con":true,"img":false}]}
{"op":"mcm","clk":"5306733066","pt":1646104723516,"mc":[{"id":"1.195395429","rc":[{"atb":[[7,0]],"id":38206580},{"atb":[[14,0]],"id":38206560},{"atb":[[7.2,0]],"id":37401228}],"con":true,"img":false}]}
{"op":"mcm","clk":"5306733072","pt":1646104723617,"mc":[{"id":"1.195395429","rc":[{"atb":[[7.4,9.67]],"id":38206580},{"atb":[[13,4.46]],"id":38206560},{"atb":[[6.6,10]],"id":37401228}],"con":true,"img":false}]}
{"op":"mcm","clk":"5306733315","pt":1646104727712,"mc":[{"id":"1.195395429","rc":[{"atb":[[7.2,1.62]],"id":38206580},{"spn":12.45,"spf":1.0,"id":38206580},{"atb":[[14.5,0]],"id":38206560},{"atb":[[7.6,0]],"id":37401228},{"spn":1.39,"spf":1.0,"id":40494181}],"con":true,"img":false}]}
{"op":"mcm","clk":"5306733620","pt":1646104732619,"mc":[{"id":"1.195395429","rc":[{"atb":[[7,14.51]],"id":38206580},{"atb":[[13.5,7.41]],"id":38206560},{"atb":[[6.8,15.98]],"id":37401228}],"con":true,"img":false}]}
{"op":"mcm","clk":"5306734409","pt":1646104746536,"mc":[{"id":"1.195395429","rc":[{"atb":[[6.8,0]],"id":38206580}],"con":true,"img":false}]}
{"op":"mcm","clk":"5306734687","pt":1646104751653,"mc":[{"id":"1.195395429","rc":[{"atb":[[7.4,0]],"id":38206580}],"con":true,"img":false}]}
{"op":"mcm","clk":"5306734694","pt":1646104751756,"mc":[{"id":"1.195395429","rc":[{"atb":[[7.2,11.29]],"id":38206580}],"con":true,"img":false}]}
{"op":"mcm","clk":"5306734848","pt":1646104754725,"mc":[{"id":"1.195395429","rc":[{"atb":[[7,0]],"id":38206580}],"con":true,"img":false}]}
{"op":"mcm","clk":"5306735074","pt":1646104759332,"mc":[{"id":"1.195395429","rc":[{"atb":[[6.8,15.98]],"id":38206580}],"con":true,"img":false}]}
{"op":"mcm","clk":"5306735948","pt":1646104779663,"mc":[{"id":"1.195395429","rc":[{"atb":[[13,0]],"id":38206560},{"atb":[[6.6,0]],"id":37401228},{"atb":[[1.33,0],[1.38,0]],"id":40494181}],"con":true,"img":false}]}
{"op":"mcm","clk":"5306735954","pt":1646104779765,"mc":[{"id":"1.195395429","rc":[{"atb":[[14,4.46]],"id":38206560},{"atb":[[7,10]],"id":37401228},{"atb":[[1.41,87.96],[1.35,323.01]],"id":40494181}],"con":true,"img":false}]}
{"op":"mcm","clk":"5306736137","pt":1646104783606,"mc":[{"id":"1.195395429","rc":[{"atb":[[13.5,0]],"id":38206560},{"atb":[[6.8,0]],"id":37401228},{"atb":[[1.34,0]],"id":40494181}],"con":true,"img":false}]}
{"op":"mcm","clk":"5306736257","pt":1646104786517,"mc":[{"id":"1.195395429","rc":[{"atb":[[1.4,20.87]],"id":40494181}],"con":true,"img":false}]}
{"op":"mcm","clk":"5306736344","pt":1646104788511,"mc":[{"id":"1.195395429","rc":[{"spn":12.35,"spf":1.0,"id":38206580},{"atb":[[14.5,6.87]],"id":38206560},{"atb":[[7.6,13.06]],"id":37401228},{"spn":8.1,"spf":1.0,"id":37401228},{"atb":[[1.36,199.92]],"id":40494181},{"spn":1.41,"spf":1.0,"id":40494181}],"con":true,"img":false}]}
{"op":"mcm","clk":"5306736658","pt":1646104794673,"mc":[{"id":"1.195395429","rc":[{"atb":[[1.4,0]],"id":40494181}],"con":true,"img":false}]}
{"op":"mcm","clk":"5306736689","pt":1646104795491,"mc":[{"id":"1.195395429","rc":[{"atb":[[1.43,17.33]],"id":40494181}],"con":true,"img":false}]}
{"op":"mcm","clk":"5306736849","pt":1646104799384,"mc":[{"id":"1.195395429","rc":[{"atb":[[1.36,2]],"id":40494181}],"con":true,"img":false}]}
{"op":"mcm","clk":"5306736906","pt":1646104800614,"mc":[{"id":"1.195395429","rc":[{"atb":[[1.43,36.75]],"id":40494181}],"con":true,"img":false}]}
{"op":"mcm","clk":"5306737105","pt":1646104803899,"mc":[{"id":"1.195395429","rc":[{"atb":[[1.36,103.08]],"id":40494181}],"con":true,"img":false}]}
{"op":"mcm","clk":"5306737228","pt":1646104806717,"mc":[{"id":"1.195395429","rc":[{"atb":[[14,0]],"id":38206560},{"atb":[[7,0]],"id":37401228}],"con":true,"img":false}]}
{"op":"mcm","clk":"5306737232","pt":1646104806819,"mc":[{"id":"1.195395429","rc":[{"atb":[[13,4.46]],"id":38206560},{"atb":[[6.6,10]],"id":37401228}],"con":true,"img":false}]}
{"op":"mcm","clk":"5306737400","pt":1646104810505,"mc":[{"id":"1.195395429","rc":[{"atb":[[14.5,0]],"id":38206560},{"atb":[[7.6,0]],"id":37401228}],"con":true,"img":false}]}
{"op":"mcm","clk":"5306737627","pt":1646104815120,"mc":[{"id":"1.195395429","rc":[{"atb":[[13.5,7.41]],"id":38206560},{"atb":[[6.8,15.98]],"id":37401228}],"con":true,"img":false}]}
{"op":"mcm","clk":"5306738476","pt":1646104834049,"mc":[{"id":"1.195395429","rc":[{"atb":[[6.6,0]],"id":38206580},{"atb":[[1.41,0]],"id":40494181}],"con":true,"img":false}]}
{"op":"mcm","clk":"5306738482","pt":1646104834152,"mc":[{"id":"1.195395429","rc":[{"atb":[[7,23.26]],"id":38206580},{"atb":[[1.38,87.96]],"id":40494181}],"con":true,"img":false}]}
{"op":"mcm","clk":"5306738591","pt":1646104836968,"mc":[{"id":"1.195395429","rc":[{"atb":[[6.8,0]],"id":38206580},{"atb":[[1.36,2]],"id":40494181}],"con":true,"img":false}]}
{"op":"mcm","clk":"5306738757","pt":1646104840653,"mc":[{"id":"1.195395429","rc":[{"atb":[[1.43,19.42]],"id":40494181}],"con":true,"img":false}]}
{"op":"mcm","clk":"5306738795","pt":1646104841778,"mc":[{"id":"1.195395429","rc":[{"atb":[[7.4,8.46]],"id":38206580},{"atb":[[1.36,103.08]],"id":40494181}],"con":true,"img":false}]}
{"op":"mcm","clk":"5306739087","pt":1646104848791,"mc":[{"id":"1.195395429","rc":[{"spn":12.45,"spf":1.0,"id":38206580},{"spn":8.0,"spf":1.0,"id":37401228},{"atb":[[1.43,0]],"id":40494181},{"spn":1.38,"spf":1.0,"id":40494181}],"con":true,"img":false}]}
{"op":"mcm","clk":"5306739122","pt":1646104849562,"mc":[{"id":"1.195395429","rc":[{"atb":[[1.4,18.63]],"id":40494181}],"con":true,"img":false}]}
{"op":"mcm","clk":"5306739245","pt":1646104852680,"mc":[{"id":"1.195395429","rc":[{"atb":[[1.36,2]],"id":40494181}],"con":true,"img":false}]}
{"op":"mcm","clk":"5306739323","pt":1646104854673,"mc":[{"id":"1.195395429","rc":[{"atb":[[1.4,39.5]],"id":40494181}],"con":true,"img":false}]}
{"op":"mcm","clk":"5306739445","pt":1646104857182,"mc":[{"id":"1.195395429","rc":[{"atb":[[1.36,81.01]],"id":40494181}],"con":true,"img":false}]}
{"op":"mcm","clk":"5306739621","pt":1646104860578,"mc":[{"id":"1.195395429","rc":[{"atb":[[7,0]],"id":38206580},{"atb":[[13,0]],"id":38206560},{"atb":[[6.6,0]],"id":37401228},{"atb":[[1.35,0]],"id":40494181}],"con":true,"img":false}]}
{"op":"mcm","clk":"5306739627","pt":1646104860682,"mc":[{"id":"1.195395429","rc":[{"atb":[[6.6,23.26]],"id":38206580},{"atb":[[14,4.46]],"id":38206560},{"atb":[[7,10]],"id":37401228},{"atb":[[1.37,323.01]],"id":40494181}],"con":true,"img":false}]}
{"op":"mcm","clk":"5306739743","pt":1646104864013,"mc":[{"id":"1.195395429","rc":[{"atb":[[7.4,0]],"id":38206580},{"atb":[[13.5,0]],"id":38206560},{"atb":[[6.8,0]],"id":37401228},{"atb":[[1.36,2]],"id":40494181}],"con":true,"img":false}]}
{"op":"mcm","clk":"5306739946","pt":1646104869106,"mc":[{"id":"1.195395429","rc":[{"atb":[[6.8,15.98]],"id":38206580},{"atb":[[14.5,6.87]],"id":38206560},{"atb":[[7.6,13.06]],"id":37401228},{"atb":[[1.41,29.63]],"id":40494181}],"con":true,"img":false}]}
{"op":"mcm","clk":"5306740630","pt":1646104887662,"mc":[{"id":"1.195395429","rc":[{"atb":[[14,0]],"id":38206560},{"atb":[[7,0]],"id":37401228},{"atb":[[1.37,0],[1.38,0]],"id":40494181}],"con":true,"img":false}]}
{"op":"mcm","clk":"5306740634","pt":1646104887763,"mc":[{"id":"1.195395429","rc":[{"atb":[[13,4.46]],"id":38206560},{"atb":[[6.6,10]],"id":37401228},{"atb":[[1.41,117.6],[1.33,323.01]],"id":40494181}],"con":true,"img":false}]}
{"op":"mcm","clk":"5306740734","pt":1646104890841,"mc":[{"id":"1.195395429","rc":[{"atb":[[14.5,0]],"id":38206560},{"atb":[[7.6,0]],"id":37401228},{"atb":[[1.41,87.96]],"id":40494181}],"con":true,"img":false}]}
{"op":"mcm","clk":"5306740890","pt":1646104894761,"mc":[{"id":"1.195395429","rc":[{"atb":[[1.4,20.87]],"id":40494181}],"con":true,"img":false}]}
{"op":"mcm","clk":"5306740928","pt":1646104895633,"mc":[{"id":"1.195395429","rc":[{"atb":[[13.5,7.41]],"id":38206560},{"atb":[[6.8,15.98]],"id":37401228},{"atb":[[1.34,241.89]],"id":40494181}],"con":true,"img":false}]}
{"op":"mcm","clk":"5306741252","pt":1646104902892,"mc":[{"id":"1.195395429","rc":[{"atb":[[1.4,0]],"id":40494181}],"con":true,"img":false}]}
{"op":"mcm","clk":"5306741295","pt":1646104903686,"mc":[{"id":"1.195395429","rc":[{"atb":[[1.43,17.33]],"id":40494181}],"con":true,"img":false}]}
{"op":"mcm","clk":"5306741428","pt":1646104906656,"mc":[{"id":"1.195395429","rc":[{"atb":[[1.34,0]],"id":40494181}],"con":true,"img":false}]}
{"op":"mcm","clk":"5306741518","pt":1646104908755,"mc":[{"id":"1.195395429","rc":[{"atb":[[1.43,36.75]],"id":40494181}],"con":true,"img":false}]}
{"op":"mcm","clk":"5306741634","pt":1646104911167,"mc":[{"id":"1.195395429","rc":[{"spn":12.35,"spf":1.0,"id":38206580},{"atb":[[1.34,56.34]],"id":40494181},{"spn":1.42,"spf":1.0,"id":40494181}],"con":true,"img":false}]}
{"op":"mcm","clk":"5306742987","pt":1646104940840,"mc":[{"id":"1.195395429","rc":[{"atb":[[6.6,0]],"id":38206580},{"atb":[[13,0]],"id":38206560},{"atb":[[6.6,0]],"id":37401228},{"atb":[[1.41,0]],"id":40494181}],"con":true,"img":false}]}
{"op":"mcm","clk":"5306742991","pt":1646104940943,"mc":[{"id":"1.195395429","rc":[{"atb":[[7,23.26]],"id":38206580},{"atb":[[14,4.46]],"id":38206560},{"atb":[[7,10]],"id":37401228},{"atb":[[1.38,87.96]],"id":40494181}],"con":true,"img":false}]}
{"op":"mcm","clk":"5306743116","pt":1646104944335,"mc":[{"id":"1.195395429","rc":[{"atb":[[6.8,0]],"id":38206580},{"atb":[[13.5,0]],"id":38206560},{"atb":[[6.8,0]],"id":37401228},{"atb":[[1.34,0]],"id":40494181}],"con":true,"img":false}]}
{"op":"mcm","clk":"5306743295","pt":1646104948843,"mc":[{"id":"1.195395429","rc":[{"atb":[[1.43,19.42]],"id":40494181}],"con":true,"img":false}]}
{"op":"mcm","clk":"5306743312","pt":1646104949355,"mc":[{"id":"1.195395429","rc":[{"atb":[[7.4,8.46]],"id":38206580},{"atb":[[14.5,6.87]],"id":38206560},{"atb":[[7.6,13.06]],"id":37401228},{"atb":[[1.34,119.46]],"id":40494181}],"con":true,"img":false}]}
{"op":"mcm","clk":"5306743577","pt":1646104956936,"mc":[{"id":"1.195395429","rc":[{"atb":[[1.43,0]],"id":40494181}],"con":true,"img":false}]}
{"op":"mcm","clk":"5306743600","pt":1646104957753,"mc":[{"id":"1.195395429","rc":[{"atb":[[1.4,18.63]],"id":40494181}],"con":true,"img":false}]}
{"op":"mcm","clk":"5306743697","pt":1646104960361,"mc":[{"id":"1.195395429","rc":[{"atb":[[1.34,0]],"id":40494181}],"con":true,"img":false}]}
{"op":"mcm","clk":"5306743786","pt":1646104962870,"mc":[{"id":"1.195395429","rc":[{"atb":[[1.4,39.5]],"id":40494181}],"con":true,"img":false}]}
{"op":"mcm","clk":"5306743863","pt":1646104964763,"mc":[{"id":"1.195395429","rc":[{"atb":[[1.34,46.58]],"id":40494181}],"con":true,"img":false}]}
{"op":"mcm","clk":"5306743926","pt":1646104966247,"mc":[{"id":"1.195395429","rc":[{"atb":[[7,0]],"id":38206580},{"atb":[[14,0]],"id":38206560},{"atb":[[7,0]],"id":37401228},{"atb":[[1.33,0]],"id":40494181}],"con":true,"img":false}]}
{"op":"mcm","clk":"5306743932","pt":1646104966349,"mc":[{"id":"1.195395429","rc":[{"atb":[[6.6,23.26]],"id":38206580},{"atb":[[13,4.46]],"id":38206560},{"atb":[[6.6,10]],"id":37401228},{"atb":[[1.35,323.01]],"id":40494181}],"con":true,"img":false}]}
{"op":"mcm","clk":"5306744035","pt":1646104969269,"mc":[{"id":"1.195395429","rc":[{"atb":[[7.4,0]],"id":38206580},{"atb":[[14.5,0]],"id":38206560},{"atb":[[7.6,0]],"id":37401228},{"atb":[[1.34,0]],"id":40494181}],"con":true,"img":false}]}
{"op":"mcm","clk":"5306744226","pt":1646104974382,"mc":[{"id":"1.195395429","rc":[{"atb":[[6.8,15.98]],"id":38206580},{"atb":[[13.5,7.41]],"id":38206560},{"atb":[[6.8,15.98]],"id":37401228},{"atb":[[1.36,81.01]],"id":40494181},{"spn":1.39,"spf":1.0,"id":40494181}],"con":true,"img":false}]}
{"op":"mcm","clk":"5306744994","pt":1646104993014,"mc":[{"id":"1.195395429","rc":[{"atb":[[1.38,0]],"id":40494181}],"con":true,"img":false}]}
{"op":"mcm","clk":"5306745000","pt":1646104993115,"mc":[{"id":"1.195395429","rc":[{"atb":[[1.41,87.96]],"id":40494181}],"con":true,"img":false}]}
{"op":"mcm","clk":"5306745115","pt":1646104996079,"mc":[{"id":"1.195395429","rc":[{"atb":[[1.36,2]],"id":40494181}],"con":true,"img":false}]}
{"op":"mcm","clk":"5306745263","pt":1646104999921,"mc":[{"id":"1.195395429","rc":[{"atb":[[1.4,20.87]],"id":40494181}],"con":true,"img":false}]}
{"op":"mcm","clk":"5306745292","pt":1646105000686,"mc":[{"id":"1.195395429","rc":[{"atb":[[1.36,199.92]],"id":40494181}],"con":true,"img":false}]}
{"op":"mcm","clk":"5306745644","pt":1646105008836,"mc":[{"id":"1.195395429","rc":[{"atb":[[1.43,17.33]],"id":40494181}],"con":true,"img":false}]}
{"op":"mcm","clk":"5306745718","pt":1646105010933,"mc":[{"id":"1.195395429","rc":[{"atb":[[1.4,0]],"id":40494181}],"con":true,"img":false}]}
{"op":"mcm","clk":"5306745747","pt":1646105011699,"mc":[{"id":"1.195395429","rc":[{"atb":[[1.36,2]],"id":40494181}],"con":true,"img":false}]}
{"op":"mcm","clk":"5306745912","pt":1646105016203,"mc":[{"id":"1.195395429","rc":[{"atb":[[1.36,49.67]],"id":40494181}],"con":true,"img":false}]}
{"op":"mcm","clk":"5306745942","pt":1646105017022,"mc":[{"id":"1.195395429","rc":[{"atb":[[1.43,36.75]],"id":40494181}],"con":true,"img":false}]}
{"op":"mcm","clk":"5306746005","pt":1646105018556,"mc":[{"id":"1.195395429","rc":[{"atb":[[13,0]],"id":38206560},{"atb":[[6.6,0]],"id":37401228}],"con":true,"img":false}]}
{"op":"mcm","clk":"5306746010","pt":1646105018607,"mc":[{"id":"1.195395429","rc":[{"atb":[[14,4.46]],"id":38206560},{"atb":[[7,10]],"id":37401228}],"con":true,"img":false}]}
{"op":"mcm","clk":"5306746164","pt":1646105022951,"mc":[{"id":"1.195395429","rc":[{"atb":[[13.5,0]],"id":38206560},{"atb":[[6.8,0]],"id":37401228}],"con":true,"img":false}]}
{"op":"mcm","clk":"5306746356","pt":1646105027557,"mc":[{"id":"1.195395429","rc":[{"atb":[[14.5,6.87]],"id":38206560},{"atb":[[7.6,13.06]],"id":37401228}],"con":true,"img":false}]}
{"op":"mcm","clk":"5306746917","pt":1646105043570,"mc":[{"id":"1.195395429","rc":[{"atb":[[6.6,0]],"id":38206580},{"atb":[[14,0]],"id":38206560},{"atb":[[7,0]],"id":37401228},{"spn":8.1,"spf":1.0,"id":37401228},{"atb":[[1.41,0],[1.35,0]],"id":40494181},{"spn":1.4,"spf":1.0,"id":40494181}],"con":true,"img":false}]}
{"op":"mcm","clk":"5306746922","pt":1646105043672,"mc":[{"id":"1.195395429","rc":[{"atb":[[7,23.26]],"id":38206580},{"atb":[[13,4.46]],"id":38206560},{"atb":[[6.6,10]],"id":37401228},{"atb":[[1.37,323.01],[1.38,87.96]],"id":40494181}],"con":true,"img":false}]}
{"op":"mcm","clk":"5306747069","pt":1646105047359,"mc":[{"id":"1.195395429","rc":[{"atb":[[6.8,0]],"id":38206580},{"atb":[[14.5,0]],"id":38206560},{"atb":[[7.6,0]],"id":37401228},{"atb":[[1.36,2]],"id":40494181}],"con":true,"img":false}]}
{"op":"mcm","clk":"5306747217","pt":1646105050991,"mc":[{"id":"1.195395429","rc":[{"atb":[[1.43,19.42]],"id":40494181}],"con":true,"img":false}]}
{"op":"mcm","clk":"5306747290","pt":1646105052374,"mc":[{"id":"1.195395429","rc":[{"atb":[[7.4,8.46]],"id":38206580},{"atb":[[13.5,7.41]],"id":38206560},{"atb":[[6.8,15.98]],"id":37401228},{"atb":[[1.39,73.51]],"id":40494181}],"con":true,"img":false}]}
{"op":"mcm","clk":"5306747585","pt":1646105059084,"mc":[{"id":"1.195395429","rc":[{"atb":[[1.43,0]],"id":40494181}],"con":true,"img":false}]}
{"op":"mcm","clk":"5306747826","pt":1646105065097,"mc":[{"id":"1.195395429","rc":[{"atb":[[1.41,20.36]],"id":40494181}],"con":true,"img":false}]}
{"op":"mcm","clk":"5306748032","pt":1646105069608,"mc":[{"id":"1.195395429","rc":[{"atb":[[7,0]],"id":38206580},{"atb":[[1.37,0]],"id":40494181}],"con":true,"img":false}]}
{"op":"mcm","clk":"5306748038","pt":1646105069711,"mc":[{"id":"1.195395429","rc":[{"atb":[[6.6,23.26]],"id":38206580},{"atb":[[1.33,323.01]],"id":40494181}],"con":true,"img":false}]}
{"op":"mcm","clk":"5306748146","pt":1646105071926,"mc":[{"id":"1.195395429","rc":[{"atb":[[1.41,38.54]],"id":40494181}],"con":true,"img":false}]}
{"op":"mcm","clk":"5306748158","pt":1646105072236,"mc":[{"id":"1.195395429","rc":[{"atb":[[7.4,0]],"id":38206580}],"con":true,"img":false}]}
{"op":"mcm","clk":"5306748323","pt":1646105076693,"mc":[{"id":"1.195395429","rc":[{"atb":[[6.8,15.98]],"id":38206580}],"con":true,"img":false}]}
{"op":"mcm","clk":"5306749195","pt":1646105094631,"mc":[{"id":"1.195395429","rc":[{"atb":[[13,0]],"id":38206560},{"atb":[[6.6,0]],"id":37401228},{"atb":[[1.38,0]],"id":40494181}],"con":true,"img":false}]}
{"op":"mcm","clk":"5306749198","pt":1646105094733,"mc":[{"id":"1.195395429","rc":[{"atb":[[14,4.46]],"id":38206560},{"atb":[[7,10]],"id":37401228},{"atb":[[1.4,87.96]],"id":40494181}],"con":true,"img":false}]}
{"op":"mcm","clk":"5306749371","pt":1646105098939,"mc":[{"id":"1.195395429","rc":[{"atb":[[13.5,0]],"id":38206560},{"atb":[[6.8,0]],"id":37401228},{"atb":[[1.39,0]],"id":40494181}],"con":true,"img":false}]}
{"op":"mcm","clk":"5306749544","pt":1646105102032,"mc":[{"id":"1.195395429","rc":[{"atb":[[1.41,20.36]],"id":40494181}],"con":true,"img":false}]}
{"op":"mcm","clk":"5306749654","pt":1646105103988,"mc":[{"id":"1.195395429","rc":[{"atb":[[14.5,6.87]],"id":38206560},{"atb":[[7.6,13.06]],"id":37401228},{"atb":[[1.34,105.98]],"id":40494181},{"spn":1.4,"spf":1.0,"id":40494181}],"con":true,"img":false}]}
{"op":"mcm","clk":"5306750126","pt":1646105113281,"mc":[{"id":"1.195395429","rc":[{"atb":[[1.41,0]],"id":40494181}],"con":true,"img":false}]}
{"op":"mcm","clk":"5306750150","pt":1646105113947,"mc":[{"id":"1.195395429","rc":[{"atb":[[1.42,17.74]],"id":40494181}],"con":true,"img":false}]}
{"op":"mcm","clk":"5306750278","pt":1646105117177,"mc":[{"id":"1.195395429","rc":[{"atb":[[1.34,0]],"id":40494181}],"con":true,"img":false}]}
{"op":"mcm","clk":"5306750372","pt":1646105119179,"mc":[{"id":"1.195395429","rc":[{"atb":[[1.42,37.62]],"id":40494181}],"con":true,"img":false}]}
{"op":"mcm","clk":"5306750399","pt":1646105119693,"mc":[{"id":"1.195395429","rc":[{"atb":[[14,0]],"id":38206560},{"atb":[[7,0]],"id":37401228},{"atb":[[1.4,0]],"id":40494181}],"con":true,"img":false}]}
{"op":"mcm","clk":"5306750404","pt":1646105119746,"mc":[{"id":"1.195395429","rc":[{"atb":[[13,4.46]],"id":38206560},{"atb":[[6.6,10]],"id":37401228},{"atb":[[1.38,87.96]],"id":40494181}],"con":true,"img":false}]}
{"op":"mcm","clk":"5306750499","pt":1646105121691,"mc":[{"id":"1.195395429","rc":[{"atb":[[1.34,112.87]],"id":40494181}],"con":true,"img":false}]}
{"op":"mcm","clk":"5306750625","pt":1646105123999,"mc":[{"id":"1.195395429","rc":[{"atb":[[14.5,0]],"id":38206560},{"atb":[[7.6,0]],"id":37401228}],"con":true,"img":false}]}
{"op":"mcm","clk":"5306750745","pt":1646105126158,"mc":[{"id":"1.195395429","rc":[{"atb":[[1.42,19.87]],"id":40494181}],"con":true,"img":false}]}
{"op":"mcm","clk":"5306750898","pt":1646105128673,"mc":[{"id":"1.195395429","rc":[{"atb":[[13.5,7.41]],"id":38206560},{"atb":[[6.8,15.98]],"id":37401228}],"con":true,"img":false}]}
{"op":"mcm","clk":"5306751175","pt":1646105135093,"mc":[{"id":"1.195395429","rc":[{"atb":[[1.4,18.63]],"id":40494181}],"con":true,"img":false}]}
{"op":"mcm","clk":"5306751269","pt":1646105137303,"mc":[{"id":"1.195395429","rc":[{"atb":[[1.42,0]],"id":40494181}],"con":true,"img":false}]}
{"op":"mcm","clk":"5306751279","pt":1646105137509,"mc":[{"id":"1.195395429","rc":[{"atb":[[1.34,0]],"id":40494181}],"con":true,"img":false}]}
{"op":"mcm","clk":"5306751476","pt":1646105142114,"mc":[{"id":"1.195395429","rc":[{"atb":[[1.34,46.58]],"id":40494181}],"con":true,"img":false}]}
{"op":"mcm","clk":"5306751523","pt":1646105143188,"mc":[{"id":"1.195395429","rc":[{"atb":[[1.4,39.5]],"id":40494181}],"con":true,"img":false}]}
{"op":"mcm","clk":"5306751561","pt":1646105144005,"mc":[{"id":"1.195395429","rc":[{"atb":[[6.6,0]],"id":38206580}],"con":true,"img":false}]}
{"op":"mcm","clk":"5306751566","pt":1646105144108,"mc":[{"id":"1.195395429","rc":[{"atb":[[7,23.26]],"id":38206580}],"con":true,"img":false}]}
{"op":"mcm","clk":"5306751662","pt":1646105146515,"mc":[{"id":"1.195395429","rc":[{"atb":[[6.8,0]],"id":38206580}],"con":true,"img":false}]}
{"op":"mcm","clk":"5306751843","pt":1646105151011,"mc":[{"id":"1.195395429","rc":[{"atb":[[7.4,8.46]],"id":38206580}],"con":true,"img":false}]}
{"op":"mcm","clk":"5306752586","pt":1646105168855,"mc":[{"id":"1.195395429","rc":[{"atb":[[7,0]],"id":38206580},{"spn":12.45,"spf":1.0,"id":38206580},{"atb":[[13,0]],"id":38206560},{"atb":[[6.6,0]],"id":37401228},{"spn":8.0,"spf":1.0,"id":37401228},{"atb":[[1.38,0]],"id":40494181},{"spn":1.38,"spf":1.0,"id":40494181}],"con":true,"img":false}]}
{"op":"mcm","clk":"5306752591","pt":1646105168957,"mc":[{"id":"1.195395429","rc":[{"atb":[[6.6,23.26]],"id":38206580},{"atb":[[14,4.46]],"id":38206560},{"atb":[[7,10]],"id":37401228},{"atb":[[1.41,87.96]],"id":40494181}],"con":true,"img":false}]}
{"op":"mcm","clk":"5306752777","pt":1646105173146,"mc":[{"id":"1.195395429","rc":[{"atb":[[7.4,0]],"id":38206580},{"atb":[[13.5,0]],"id":38206560},{"atb":[[6.8,0]],"id":37401228},{"atb":[[1.34,0]],"id":40494181}],"con":true,"img":false}]}
{"op":"mcm","clk":"5306752939","pt":1646105177245,"mc":[{"id":"1.195395429","rc":[{"atb":[[1.4,20.87]],"id":40494181}],"con":true,"img":false}]}
{"op":"mcm","clk":"5306752971","pt":1646105178140,"mc":[{"id":"1.195395429","rc":[{"atb":[[6.8,15.98]],"id":38206580},{"atb":[[14.5,6.87]],"id":38206560},{"atb":[[7.6,13.06]],"id":37401228},{"atb":[[1.34,241.89]],"id":40494181}],"con":true,"img":false}]}
{"op":"mcm","clk":"5306753241","pt":1646105185367,"mc":[{"id":"1.195395429","rc":[{"atb":[[1.4,0]],"id":40494181}],"con":true,"img":false}]}
{"op":"mcm","clk":"5306753278","pt":1646105186139,"mc":[{"id":"1.195395429","rc":[{"atb":[[1.43,17.33]],"id":40494181}],"con":true,"img":false}]}
{"op":"mcm","clk":"5306753394","pt":1646105189159,"mc":[{"id":"1.195395429","rc":[{"atb":[[1.34,0]],"id":40494181}],"con":true,"img":false}]}
{"op":"mcm","clk":"5306753473","pt":1646105191262,"mc":[{"id":"1.195395429","rc":[{"atb":[[1.43,36.75]],"id":40494181}],"con":true,"img":false}]}
{"op":"mcm","clk":"5306753516","pt":1646105192446,"mc":[{"id":"1.195395429","rc":[{"atb":[[14,0]],"id":38206560},{"atb":[[7,0]],"id":37401228}],"con":true,"img":false}]}
{"op":"mcm","clk":"5306753520","pt":1646105192547,"mc":[{"id":"1.195395429","rc":[{"atb":[[13,4.46]],"id":38206560},{"atb":[[6.6,10]],"id":37401228}],"con":true,"img":false}]}
{"op":"mcm","clk":"5306753574","pt":1646105193673,"mc":[{"id":"1.195395429","rc":[{"atb":[[1.34,56.34]],"id":40494181}],"con":true,"img":false}]}
{"op":"mcm","clk":"5306753666","pt":1646105195981,"mc":[{"id":"1.195395429","rc":[{"atb":[[14.5,0]],"id":38206560},{"atb":[[7.6,0]],"id":37401228}],"con":true,"img":false}]}
{"op":"mcm","clk":"5306753859","pt":1646105200660,"mc":[{"id":"1.195395429","rc":[{"atb":[[13.5,7.41]],"id":38206560},{"atb":[[6.8,15.98]],"id":37401228}],"con":true,"img":false}]}
{"op":"mcm","clk":"5306754501","pt":1646105217107,"mc":[{"id":"1.195395429","rc":[{"atb":[[1.41,0]],"id":40494181}],"con":true,"img":false}]}
{"op":"mcm","clk":"5306754504","pt":1646105217210,"mc":[{"id":"1.195395429","rc":[{"atb":[[1.38,87.96]],"id":40494181}],"con":true,"img":false}]}
{"op":"mcm","clk":"5306754604","pt":1646105220485,"mc":[{"id":"1.195395429","rc":[{"atb":[[1.34,0]],"id":40494181}],"con":true,"img":false}]}
{"op":"mcm","clk":"5306754763","pt":1646105224996,"mc":[{"id":"1.195395429","rc":[{"atb":[[1.34,119.46]],"id":40494181}],"con":true,"img":false}]}
{"op":"mcm","clk":"5306754771","pt":1646105225308,"mc":[{"id":"1.195395429","rc":[{"atb":[[1.43,19.42]],"id":40494181}],"con":true,"img":false}]}
{"op":"mcm","clk":"5306755021","pt":1646105233408,"mc":[{"id":"1.195395429","rc":[{"spn":12.35,"spf":1.0,"id":38206580},{"atb":[[1.43,0]],"id":40494181},{"spn":1.38,"spf":1.0,"id":40494181}],"con":true,"img":false}]}
{"op":"mcm","clk":"5306755053","pt":1646105234322,"mc":[{"id":"1.195395429","rc":[{"atb":[[1.4,18.63]],"id":40494181}],"con":true,"img":false}]}
{"op":"mcm","clk":"5306755166","pt":1646105238317,"mc":[{"id":"1.195395429","rc":[{"atb":[[1.34,0]],"id":40494181}],"con":true,"img":false}]}
{"op":"mcm","clk":"5306755203","pt":1646105239446,"mc":[{"id":"1.195395429","rc":[{"atb":[[1.4,39.5]],"id":40494181}],"con":true,"img":false}]}
{"op":"mcm","clk":"5306755262","pt":1646105241136,"mc":[{"id":"1.195395429","rc":[{"atb":[[6.6,0]],"id":38206580},{"atb":[[13,0]],"id":38206560},{"atb":[[6.6,0]],"id":37401228}],"con":true,"img":false}]}
{"op":"mcm","clk":"5306755264","pt":1646105241238,"mc":[{"id":"1.195395429","rc":[{"atb":[[7,23.26]],"id":38206580},{"atb":[[14,4.46]],"id":38206560},{"atb":[[7,10]],"id":37401228}],"con":true,"img":false}]}
{"op":"mcm","clk":"5306755294","pt":1646105242721,"mc":[{"id":"1.195395429","rc":[{"atb":[[1.34,98.77]],"id":40494181}],"con":true,"img":false}]}
{"op":"mcm","clk":"5306755345","pt":1646105245026,"mc":[{"id":"1.195395429","rc":[{"atb":[[6.8,0]],"id":38206580},{"atb":[[13.5,0]],"id":38206560},{"atb":[[6.8,0]],"id":37401228}],"con":true,"img":false}]}
{"op":"mcm","clk":"5306755469","pt":1646105249931,"mc":[{"id":"1.195395429","rc":[{"atb":[[7.4,8.46]],"id":38206580},{"atb":[[14.5,6.87]],"id":38206560},{"atb":[[7.6,13.06]],"id":37401228}],"con":true,"img":false}]}
{"op":"mcm","clk":"5306755880","pt":1646105265168,"mc":[{"id":"1.195395429","rc":[{"atb":[[7,0]],"id":38206580},{"atb":[[14,0]],"id":38206560},{"atb":[[7,0]],"id":37401228},{"atb":[[1.38,0]],"id":40494181}],"con":true,"img":false}]}
{"op":"mcm","clk":"5306755882","pt":1646105265272,"mc":[{"id":"1.195395429","rc":[{"atb":[[6.6,23.26]],"id":38206580},{"atb":[[13,4.46]],"id":38206560},{"atb":[[6.6,10]],"id":37401228},{"atb":[[1.41,87.96]],"id":40494181}],"con":true,"img":false}]}
{"op":"mcm","clk":"5306756030","pt":1646105269782,"mc":[{"id":"1.195395429","rc":[{"atb":[[7.4,0]],"id":38206580},{"atb":[[14.5,0]],"id":38206560},{"atb":[[7.6,0]],"id":37401228},{"atb":[[1.34,0]],"id":40494181}],"con":true,"img":false}]}
{"op":"mcm","clk":"5306756146","pt":1646105273473,"mc":[{"id":"1.195395429","rc":[{"atb":[[1.4,20.87]],"id":40494181}],"con":true,"img":false}]}
{"op":"mcm","clk":"5306756189","pt":1646105274755,"mc":[{"id":"1.195395429","rc":[{"atb":[[6.8,15.98]],"id":38206580},{"atb":[[13.5,7.41]],"id":38206560},{"atb":[[6.8,15.98]],"id":37401228},{"atb":[[1.34,241.89]],"id":40494181}],"con":true,"img":false}]}
{"op":"mcm","clk":"5306756383","pt":1646105281563,"mc":[{"id":"1.195395429","rc":[{"atb":[[1.4,0]],"id":40494181}],"con":true,"img":false}]}
{"op":"mcm","clk":"5306756419","pt":1646105282483,"mc":[{"id":"1.195395429","rc":[{"atb":[[1.43,17.33]],"id":40494181}],"con":true,"img":false}]}
{"op":"mcm","clk":"5306756517","pt":1646105285871,"mc":[{"id":"1.195395429","rc":[{"atb":[[1.34,0]],"id":40494181}],"con":true,"img":false}]}
{"op":"mcm","clk":"5306756568","pt":1646105287503,"mc":[{"id":"1.195395429","rc":[{"atb":[[1.43,36.75]],"id":40494181}],"con":true,"img":false}]}
{"op":"mcm","clk":"5306756673","pt":1646105290485,"mc":[{"id":"1.195395429","rc":[{"atb":[[1.34,119.46]],"id":40494181}],"con":true,"img":false}]}
{"op":"mcm","clk":"5306757358","pt":1646105311893,"mc":[{"id":"1.195395429","rc":[{"atb":[[13,0]],"id":38206560},{"atb":[[6.6,0]],"id":37401228},{"atb":[[1.41,0]],"id":40494181},{"spn":1.4,"spf":1.0,"id":40494181}],"con":true,"img":false}]}
{"op":"mcm","clk":"5306757362","pt":1646105311996,"mc":[{"id":"1.195395429","rc":[{"atb":[[14,4.46]],"id":38206560},{"atb":[[7,10]],"id":37401228},{"atb":[[1.38,87.96]],"id":40494181}],"con":true,"img":false}]}
{"op":"mcm","clk":"5306757445","pt":1646105314605,"mc":[{"id":"1.195395429","rc":[{"atb":[[13.5,0]],"id":38206560},{"atb":[[6.8,0]],"id":37401228},{"atb":[[1.34,0]],"id":40494181}],"con":true,"img":false}]}
{"op":"mcm","clk":"5306757553","pt":1646105318510,"mc":[{"id":"1.195395429","rc":[{"atb":[[1.43,19.42]],"id":40494181}],"con":true,"img":false}]}
{"op":"mcm","clk":"5306757581","pt":1646105319544,"mc":[{"id":"1.195395429","rc":[{"atb":[[14.5,6.87]],"id":38206560},{"atb":[[7.6,13.06]],"id":37401228},{"atb":[[1.34,119.46]],"id":40494181}],"con":true,"img":false}]}
{"op":"mcm","clk":"5306757842","pt":1646105327538,"mc":[{"id":"1.195395429","rc":[{"atb":[[1.4,18.63]],"id":40494181}],"con":true,"img":false}]}
{"op":"mcm","clk":"5306757923","pt":1646105330048,"mc":[{"id":"1.195395429","rc":[{"atb":[[1.43,0]],"id":40494181}],"con":true,"img":false}]}
{"op":"mcm","clk":"5306757937","pt":1646105330457,"mc":[{"id":"1.195395429","rc":[{"atb":[[1.34,0]],"id":40494181}],"con":true,"img":false}]}
{"op":"mcm","clk":"5306758069","pt":1646105334869,"mc":[{"id":"1.195395429","rc":[{"atb":[[1.34,46.58]],"id":40494181}],"con":true,"img":false}]}
{"op":"mcm","clk":"5306758087","pt":1646105335335,"mc":[{"id":"1.195395429","rc":[{"atb":[[6.6,0]],"id":38206580},{"atb":[[14,0]],"id":38206560},{"atb":[[7,0]],"id":37401228}],"con":true,"img":false}]}
{"op":"mcm","clk":"5306758092","pt":1646105335437,"mc":[{"id":"1.195395429","rc":[{"atb":[[7,23.26]],"id":38206580},{"atb":[[13,4.46]],"id":38206560},{"atb":[[6.6,10]],"id":37401228}],"con":true,"img":false}]}
{"op":"mcm","clk":"5306758095","pt":1646105335542,"mc":[{"id":"1.195395429","rc":[{"atb":[[1.4,39.5]],"id":40494181}],"con":true,"img":false}]}
{"op":"mcm","clk":"5306758215","pt":1646105339445,"mc":[{"id":"1.195395429","rc":[{"atb":[[6.8,0]],"id":38206580},{"atb":[[14.5,0]],"id":38206560},{"atb":[[7.6,0]],"id":37401228}],"con":true,"img":false}]}
{"op":"mcm","clk":"5306758402","pt":1646105344373,"mc":[{"id":"1.195395429","rc":[{"atb":[[7.4,8.46]],"id":38206580},{"atb":[[13.5,7.41]],"id":38206560},{"atb":[[6.8,15.98]],"id":37401228}],"con":true,"img":false}]}
{"op":"mcm","clk":"5306758864","pt":1646105358879,"mc":[{"id":"1.195395429","rc":[{"atb":[[7,0]],"id":38206580},{"atb":[[1.33,0]],"id":40494181}],"con":true,"img":false}]}
{"op":"mcm","clk":"5306758868","pt":1646105358981,"mc":[{"id":"1.195395429","rc":[{"atb":[[6.6,23.26]],"id":38206580},{"atb":[[1.35,323.01]],"id":40494181}],"con":true,"img":false}]}
{"op":"mcm","clk":"5306758988","pt":1646105362670,"mc":[{"id":"1.195395429","rc":[{"atb":[[7.4,0]],"id":38206580},{"atb":[[1.34,0]],"id":40494181}],"con":true,"img":false}]}
{"op":"mcm","clk":"5306759122","pt":1646105367591,"mc":[{"id":"1.195395429","rc":[{"atb":[[6.8,15.99]],"id":38206580},{"atb":[[1.36,81.01]],"id":40494181}],"con":true,"img":false}]}
{"op":"mcm","clk":"5306759576","pt":1646105381487,"mc":[{"id":"1.195395429","rc":[{"atb":[[13,0]],"id":38206560},{"atb":[[6.6,0]],"id":37401228},{"spn":1.39,"spf":1.0,"id":40494181}],"con":true,"img":false}]}
{"op":"mcm","clk":"5306759578","pt":1646105381587,"mc":[{"id":"1.195395429","rc":[{"atb":[[14,4.46]],"id":38206560},{"atb":[[7,10]],"id":37401228}],"con":true,"img":false}]}
{"op":"mcm","clk":"5306759713","pt":1646105385395,"mc":[{"id":"1.195395429","rc":[{"atb":[[13.5,0]],"id":38206560},{"atb":[[6.8,0]],"id":37401228}],"con":true,"img":false}]}
{"op":"mcm","clk":"5306759901","pt":1646105390217,"mc":[{"id":"1.195395429","rc":[{"atb":[[14.5,6.87]],"id":38206560},{"atb":[[7.6,13.06]],"id":37401228}],"con":true,"img":false}]}
{"op":"mcm","clk":"5306760403","pt":1646105403654,"mc":[{"id":"1.195395429","rc":[{"atb":[[14,0]],"id":38206560},{"atb":[[7,0]],"id":37401228},{"atb":[[1.38,0]],"id":40494181}],"con":true,"img":false}]}
{"op":"mcm","clk":"5306760407","pt":1646105403761,"mc":[{"id":"1.195395429","rc":[{"atb":[[13,4.46]],"id":38206560},{"atb":[[6.6,10]],"id":37401228},{"atb":[[1.41,87.96]],"id":40494181}],"con":true,"img":false}]}
{"op":"mcm","clk":"5306760546","pt":1646105408126,"mc":[{"id":"1.195395429","rc":[{"atb":[[14.5,0]],"id":38206560},{"atb":[[7.6,0]],"id":37401228},{"atb":[[1.36,2]],"id":40494181}],"con":true,"img":false}]}
{"op":"mcm","clk":"5306760647","pt":1646105411768,"mc":[{"id":"1.195395429","rc":[{"atb":[[1.4,20.87]],"id":40494181}],"con":true,"img":false}]}
{"op":"mcm","clk":"5306760691","pt":1646105413455,"mc":[{"id":"1.195395429","rc":[{"atb":[[13.5,7.42]],"id":38206560},{"atb":[[6.8,15.99]],"id":37401228},{"atb":[[1.36,199.92]],"id":40494181}],"con":true,"img":false}]}
{"op":"mcm","clk":"5306760856","pt":1646105419868,"mc":[{"id":"1.195395429","rc":[{"atb":[[1.4,0]],"id":40494181}],"con":true,"img":false}]}
{"op":"mcm","clk":"5306760882","pt":1646105420686,"mc":[{"id":"1.195395429","rc":[{"atb":[[1.43,17.33]],"id":40494181}],"con":true,"img":false}]}
{"op":"mcm","clk":"5306761071","pt":1646105425255,"mc":[{"id":"1.195395429","rc":[{"atb":[[1.36,2]],"id":40494181}],"con":true,"img":false}]}
{"op":"mcm","clk":"5306761090","pt":1646105425767,"mc":[{"id":"1.195395429","rc":[{"atb":[[1.43,36.75]],"id":40494181}],"con":true,"img":false}]}
{"op":"mcm","clk":"5306761120","pt":1646105426484,"mc":[{"id":"1.195395429","rc":[{"atb":[[6.6,0]],"id":38206580},{"atb":[[1.35,0]],"id":40494181}],"con":true,"img":false}]}
{"op":"mcm","clk":"5306761124","pt":1646105426588,"mc":[{"id":"1.195395429","rc":[{"atb":[[7,23.26]],"id":38206580},{"atb":[[1.33,323.01]],"id":40494181}],"con":true,"img":false}]}
{"op":"mcm","clk":"5306761289","pt":1646105430381,"mc":[{"id":"1.195395429","rc":[{"atb":[[6.8,0]],"id":38206580},{"atb":[[1.34,119.46]],"id":40494181}],"con":true,"img":false}]}
{"op":"mcm","clk":"5306761486","pt":1646105435604,"mc":[{"id":"1.195395429","rc":[{"atb":[[7.4,8.46]],"id":38206580}],"con":true,"img":false}]}
{"op":"mcm","clk":"5306761950","pt":1646105449126,"mc":[{"id":"1.195395429","rc":[{"atb":[[7,0]],"id":38206580},{"spn":12.45,"spf":1.0,"id":38206580},{"atb":[[13,0]],"id":38206560},{"atb":[[6.6,0]],"id":37401228},{"atb":[[1.41,0]],"id":40494181},{"spn":1.4,"spf":1.0,"id":40494181}],"con":true,"img":false}]}
{"op":"mcm","clk":"5306761954","pt":1646105449226,"mc":[{"id":"1.195395429","rc":[{"atb":[[6.6,23.26]],"id":38206580},{"atb":[[14,4.46]],"id":38206560},{"atb":[[7,10]],"id":37401228},{"atb":[[1.38,87.96]],"id":40494181}],"con":true,"img":false}]}
{"op":"mcm","clk":"5306762039","pt":1646105451682,"mc":[{"id":"1.195395429","rc":[{"atb":[[7.4,0]],"id":38206580},{"atb":[[13.5,0]],"id":38206560},{"atb":[[6.8,0]],"id":37401228}],"con":true,"img":false}]}
{"op":"mcm","clk":"5306762100","pt":1646105453929,"mc":[{"id":"1.195395429","rc":[{"atb":[[1.34,0]],"id":40494181}],"con":true,"img":false}]}
{"op":"mcm","clk":"5306762201","pt":1646105456799,"mc":[{"id":"1.195395429","rc":[{"atb":[[1.43,19.42]],"id":40494181}],"con":true,"img":false}]}
{"op":"mcm","clk":"5306762205","pt":1646105456903,"mc":[{"id":"1.195395429","rc":[{"atb":[[6.8,15.99]],"id":38206580},{"atb":[[14.5,6.87]],"id":38206560},{"atb":[[7.6,13.06]],"id":37401228}],"con":true,"img":false}]}
{"op":"mcm","clk":"5306762278","pt":1646105459208,"mc":[{"id":"1.195395429","rc":[{"atb":[[1.34,63.12]],"id":40494181}],"con":true,"img":false}]}
{"op":"mcm","clk":"5306762376","pt":1646105461924,"mc":[{"id":"1.195395429","rc":[{"atb":[[1.43,0]],"id":40494181}],"con":true,"img":false}]}
{"op":"mcm","clk":"5306762540","pt":1646105465820,"mc":[{"id":"1.195395429","rc":[{"atb":[[1.4,18.63]],"id":40494181}],"con":true,"img":false}]}
{"op":"mcm","clk":"5306762606","pt":1646105467812,"mc":[{"id":"1.195395429","rc":[{"atb":[[1.4,39.5]],"id":40494181}],"con":true,"img":false}]}
{"op":"mcm","clk":"5306762617","pt":1646105468218,"mc":[{"id":"1.195395429","rc":[{"atb":[[1.34,0]],"id":40494181}],"con":true,"img":false}]}
{"op":"mcm","clk":"5306762722","pt":1646105471851,"mc":[{"id":"1.195395429","rc":[{"atb":[[14,0]],"id":38206560},{"atb":[[7,0]],"id":37401228}],"con":true,"img":false}]}
{"op":"mcm","clk":"5306762726","pt":1646105471953,"mc":[{"id":"1.195395429","rc":[{"atb":[[13,4.46]],"id":38206560},{"atb":[[6.6,10]],"id":37401228}],"con":true,"img":false}]}
{"op":"mcm","clk":"5306762755","pt":1646105472813,"mc":[{"id":"1.195395429","rc":[{"atb":[[1.34,98.77]],"id":40494181}],"con":true,"img":false}]}
{"op":"mcm","clk":"5306762826","pt":1646105474316,"mc":[{"id":"1.195395429","rc":[{"atb":[[12.5,0.88]],"id":39520250},{"atb":[[6.8,0]],"id":38206580},{"atb":[[14.5,0]],"id":38206560},{"atb":[[7.6,0]],"id":37401228},{"atb":[[1.34,0]],"id":40494181}],"con":true,"img":false}]}
{"op":"mcm","clk":"5306763347","pt":1646105493642,"mc":[{"id":"1.195395429","rc":[{"atb":[[1.38,0]],"id":40494181}],"con":true,"img":false}]}
{"op":"mcm","clk":"5306763349","pt":1646105493742,"mc":[{"id":"1.195395429","rc":[{"atb":[[1.41,87.96]],"id":40494181}],"con":true,"img":false}]}
{"op":"mcm","clk":"5306763588","pt":1646105501969,"mc":[{"id":"1.195395429","rc":[{"atb":[[1.4,20.87]],"id":40494181}],"con":true,"img":false}]}
{"op":"mcm","clk":"5306763771","pt":1646105509989,"mc":[{"id":"1.195395429","rc":[{"spn":12.35,"spf":1.0,"id":38206580},{"atb":[[1.4,0]],"id":40494181},{"spn":1.41,"spf":1.0,"id":40494181}],"con":true,"img":false}]}
{"op":"mcm","clk":"5306763839","pt":1646105513872,"mc":[{"id":"1.195395429","rc":[{"atb":[[1.43,17.33]],"id":40494181}],"con":true,"img":false}]}
{"op":"mcm","clk":"5306763889","pt":1646105515416,"mc":[{"id":"1.195395429","rc":[{"atb":[[1.41,0]],"id":40494181}],"con":true,"img":false}]}
{"op":"mcm","clk":"5306763892","pt":1646105515468,"mc":[{"id":"1.195395429","rc":[{"atb":[[1.37,87.96]],"id":40494181}],"con":true,"img":false}]}
{"op":"mcm","clk":"5306763900","pt":1646105515877,"mc":[{"id":"1.195395429","rc":[{"atb":[[1.43,36.75]],"id":40494181}],"con":true,"img":false}]}
{"op":"mcm","clk":"5306764038","pt":1646105523024,"mc":[{"id":"1.195395429","rc":[{"atb":[[1.43,19.42]],"id":40494181}],"con":true,"img":false}]}
{"op":"mcm","clk":"5306764184","pt":1646105529525,"mc":[{"id":"1.195395429","rc":[{"atb":[[7.2,0],[9.2,0],[8.2,0],[11.5,0]],"id":39520250},{"atl":[[80,0],[160,0],[210,0],[110,0]],"id":39520250},{"atb":[[18,0],[23,0.46],[13,0],[15.5,0]],"id":36104895},{"atl":[[300,0],[350,0],[200,0],[250,0]],"id":36104895},{"atb":[[4.5,0],[6.4,0],[5,0],[5.5,0]],"id":38206580},{"atl":[[19.5,0],[38,0],[24,0],[29,0]],"id":38206580},{"atb":[[18,0],[21,0],[28,0],[15.5,0]],"id":27701417},{"atl":[[290,0],[340,0],[390,0],[240,0]],"id":27701417},{"atb":[[12,0],[9.8,0],[8.8,0],[15.5,0.7]],"id":38206560},{"atl":[[270,0],[170,0],[220,0],[120,0]],"id":38206560},{"atb":[[4.5,0],[6.4,0],[5,0],[5.5,0]],"id":41762283},{"atl":[[19.5,0],[38,0],[24,0],[29,0]],"id":41762283},{"atb":[[5,0],[5.5,0],[7.4,1.57],[6,0]],"id":37401228},{"atl":[[70,8.2],[38,0],[48,0],[29,0]],"id":37401228},{"atb":[[1.2,0],[1.25,0],[1.15,0],[1.32,0]],"id":40494181},{"atl":[[2.54,0],[2.74,0],[2.64,0],[2.84,0]],"id":40494181}],"con":true,"img":false}]}
{"op":"mcm","clk":"5306764232","pt":1646105531924,"mc":[{"id":"1.195395429","rc":[{"atb":[[1.39,19.11]],"id":40494181}],"con":true,"img":false}]}
{"op":"mcm","clk":"5306764243","pt":1646105532643,"mc":[{"id":"1.195395429","rc":[{"atb":[[7.2,16.36],[9.2,12.37],[8.2,14.09],[11.5,9.66]],"id":39520250},{"atl":[[80,1.67],[160,1.24],[210,0.94],[110,1.21]],"id":39520250},{"atb":[[18,5.96],[23,5.07],[13,8.45],[15.5,6.99]],"id":36104895},{"atl":[[300,0.66],[350,0.56],[200,0.66],[250,0.53]],"id":36104895},{"atb":[[4.5,28.98],[6.4,18.78],[5,25.36],[5.5,22.54]],"id":38206580},{"atl":[[19.5,7.14],[38,5.35],[24,5.74],[29,7.07]],"id":38206580},{"atb":[[18,5.96],[21,5.07],[28,3.75],[15.5,6.99]],"id":27701417},{"atl":[[290,0.45],[340,0.58],[390,0.5],[240,0.55]],"id":27701417},{"atb":[[12,9.22],[9.8,11.53],[8.8,13],[15.5,7.69]],"id":38206560},{"atl":[[270,0.73],[170,0.77],[220,0.9],[120,1.1]],"id":38206560},{"atb":[[4.5,28.98],[6.4,18.78],[5,25.36],[5.5,22.54]],"id":41762283},{"atl":[[19.5,7.14],[38,5.35],[24,5.74],[29,7.07]],"id":41762283},{"atb":[[5,25.36],[5.5,22.54],[7.4,17.42],[6,20.29]],"id":37401228},{"atl":[[70,11.07],[38,3.57],[48,4.21],[29,4.71]],"id":37401228},{"atb":[[1.2,507.27],[1.25,405.82],[1.15,676.37],[1.32,317.04]],"id":40494181},{"atl":[[2.54,85.8],[2.74,113.91],[2.64,80.56],[2.84,107.72]],"id":40494181}],"con":true,"img":false}]}
{"op":"mcm","clk":"5306764283","pt":1646105534025,"mc":[{"id":"1.195395429","rc":[{"atb":[[1.43,0]],"id":40494181}],"con":true,"img":false}]}
{"op":"mcm","clk":"5306764437","pt":1646105539906,"mc":[{"id":"1.195395429","rc":[{"atb":[[1.39,40.51]],"id":40494181}],"con":true,"img":false}]}
{"op":"mcm","clk":"5306764632","pt":1646105547233,"mc":[{"id":"1.195395429","rc":[{"atb":[[4.6,0]],"id":41762283}],"con":true,"img":false}]}
{"op":"mcm","clk":"5306764635","pt":1646105547335,"mc":[{"id":"1.195395429","rc":[{"atb":[[4.7,2]],"id":41762283}],"con":true,"img":false}]}
{"op":"mcm","clk":"5306765811","pt":1646105601921,"mc":[{"id":"1.195395429","rc":[{"atb":[[1.37,0]],"id":40494181},{"spn":1.37,"spf":1.0,"id":40494181}],"con":true,"img":false}]}
{"op":"mcm","clk":"5306765815","pt":1646105602023,"mc":[{"id":"1.195395429","rc":[{"atb":[[1.4,87.96]],"id":40494181}],"con":true,"img":false}]}
{"op":"mcm","clk":"5306765971","pt":1646105610092,"mc":[{"id":"1.195395429","rc":[{"atb":[[1.39,21.4]],"id":40494181}],"con":true,"img":false}]}
{"op":"mcm","clk":"5306766153","pt":1646105618116,"mc":[{"id":"1.195395429","rc":[{"atb":[[1.39,0]],"id":40494181}],"con":true,"img":false}]}
{"op":"mcm","clk":"5306766182","pt":1646105619138,"mc":[{"id":"1.195395429","rc":[{"atb":[[1.42,17.74]],"id":40494181}],"con":true,"img":false}]}
{"op":"mcm","clk":"5306766282","pt":1646105623533,"mc":[{"id":"1.195395429","rc":[{"atb":[[1.4,0]],"id":40494181}],"con":true,"img":false}]}
{"op":"mcm","clk":"5306766283","pt":1646105623634,"mc":[{"id":"1.195395429","rc":[{"atb":[[1.37,87.96]],"id":40494181}],"con":true,"img":false}]}
{"op":"mcm","clk":"5306766465","pt":1646105631142,"mc":[{"id":"1.195395429","rc":[{"atb":[[1.42,0]],"id":40494181}],"con":true,"img":false}]}
{"op":"mcm","clk":"5306766628","pt":1646105640042,"mc":[{"id":"1.195395429","rc":[{"atb":[[1.39,19.11]],"id":40494181}],"con":true,"img":false}]}
{"op":"mcm","clk":"5306766674","pt":1646105642136,"mc":[{"id":"1.195395429","rc":[{"atb":[[1.39,40.51]],"id":40494181}],"con":true,"img":false}]}
{"op":"mcm","clk":"5306766781","pt":1646105645771,"mc":[{"id":"1.195395429","rc":[{"atb":[[6.2,0],[2.62,0],[4.2,0]],"id":39520250},{"atl":[[130,0]],"id":39520250},{"atb":[[12,0],[2.62,0],[4.2,0]],"id":36104895},{"atb":[[3.8,0],[2.62,0]],"id":38206580},{"atl":[[48,0]],"id":38206580},{"atb":[[11,0],[2.62,0],[4.2,0]],"id":27701417},{"atb":[[8.2,0],[2.62,0],[4.2,0]],"id":38206560},{"atb":[[3.8,0],[2.62,0]],"id":41762283},{"atl":[[48,0]],"id":41762283},{"atb":[[2.62,0],[4.2,0]],"id":37401228},{"atl":[[70,2.87]],"id":37401228},{"atl":[[17,0],[34,0]],"id":40494181}],"con":true,"img":false}]}
{"op":"mcm","clk":"5306767736","pt":1646105686500,"mc":[{"id":"1.195395429","rc":[{"atb":[[1.37,0]],"id":40494181}],"con":true,"img":false}]}
{"op":"mcm","clk":"5306767738","pt":1646105686602,"mc":[{"id":"1.195395429","rc":[{"atb":[[1.4,87.96]],"id":40494181}],"con":true,"img":false}]}
{"op":"mcm","clk":"5306767908","pt":1646105694324,"mc":[{"id":"1.195395429","rc":[{"atb":[[1.39,21.4]],"id":40494181}],"con":true,"img":false}]}
{"op":"mcm","clk":"5306768102","pt":1646105702354,"mc":[{"id":"1.195395429","rc":[{"atb":[[1.39,0]],"id":40494181}],"con":true,"img":false}]}
{"op":"mcm","clk":"5306768131","pt":1646105703239,"mc":[{"id":"1.195395429","rc":[{"atb":[[1.42,17.74]],"id":40494181}],"con":true,"img":false}]}
{"op":"mcm","clk":"5306768262","pt":1646105707131,"mc":[{"id":"1.195395429","rc":[{"atb":[[1.4,0]],"id":40494181}],"con":true,"img":false}]}
{"op":"mcm","clk":"5306768264","pt":1646105707224,"mc":[{"id":"1.195395429","rc":[{"atb":[[1.37,87.96]],"id":40494181}],"con":true,"img":false}]}
{"op":"mcm","clk":"5306768477","pt":1646105715332,"mc":[{"id":"1.195395429","rc":[{"atb":[[1.42,0]],"id":40494181}],"con":true,"img":false}]}
{"op":"mcm","clk":"5306768608","pt":1646105720244,"mc":[{"id":"1.195395429","rc":[{"atb":[[1.39,21.4]],"id":40494181}],"con":true,"img":false}]}
{"op":"mcm","clk":"5306768751","pt":1646105724238,"mc":[{"id":"1.195395429","rc":[{"atb":[[1.39,40.51]],"id":40494181}],"con":true,"img":false}]}
{"op":"mcm","clk":"5306770271","pt":1646105768593,"mc":[{"id":"1.195395429","rc":[{"atb":[[1.37,0]],"id":40494181}],"con":true,"img":false}]}
{"op":"mcm","clk":"5306770277","pt":1646105768695,"mc":[{"id":"1.195395429","rc":[{"atb":[[1.4,87.96]],"id":40494181}],"con":true,"img":false}]}
{"op":"mcm","clk":"5306770579","pt":1646105775415,"mc":[{"id":"1.195395429","rc":[{"atb":[[1.39,21.4]],"id":40494181}],"con":true,"img":false}]}
{"op":"mcm","clk":"5306770970","pt":1646105784436,"mc":[{"id":"1.195395429","rc":[{"atb":[[1.42,17.74]],"id":40494181}],"con":true,"img":false}]}
{"op":"mcm","clk":"5306771052","pt":1646105786442,"mc":[{"id":"1.195395429","rc":[{"atb":[[1.39,0]],"id":40494181}],"con":true,"img":false}]}
{"op":"mcm","clk":"5306771158","pt":1646105789157,"mc":[{"id":"1.195395429","rc":[{"atb":[[1.4,0]],"id":40494181}],"con":true,"img":false}]}
{"op":"mcm","clk":"5306771161","pt":1646105789208,"mc":[{"id":"1.195395429","rc":[{"atb":[[1.37,87.96]],"id":40494181}],"con":true,"img":false}]}
{"op":"mcm","clk":"5306771422","pt":1646105796432,"mc":[{"id":"1.195395429","rc":[{"atb":[[1.42,0]],"id":40494181}],"con":true,"img":false}]}
{"op":"mcm","clk":"5306771708","pt":1646105804475,"mc":[{"id":"1.195395429","rc":[{"atb":[[1.39,21.4]],"id":40494181}],"con":true,"img":false}]}
{"op":"mcm","clk":"5306771879","pt":1646105809338,"mc":[{"id":"1.195395429","rc":[{"atb":[[1.39,40.51]],"id":40494181}],"con":true,"img":false}]}
{"op":"mcm","clk":"5306772987","pt":1646105840791,"mc":[{"id":"1.195395429","rc":[{"atl":[[2.14,61.72]],"id":40494181},{"spn":1.38,"spf":1.0,"id":40494181}],"con":true,"img":false}]}
{"op":"mcm","clk":"5306773013","pt":1646105841919,"mc":[{"id":"1.195395429","rc":[{"atb":[[1.39,51.33]],"id":40494181}],"con":true,"img":false}]}
{"op":"mcm","clk":"5306773063","pt":1646105843300,"mc":[{"id":"1.195395429","rc":[{"atb":[[7.2,22.11]],"id":38206580}],"con":true,"img":false}]}
{"op":"mcm","clk":"5306773072","pt":1646105843813,"mc":[{"id":"1.195395429","rc":[{"atl":[[44,13.52]],"id":38206560}],"con":true,"img":false}]}
{"op":"mcm","clk":"5306773114","pt":1646105845091,"mc":[{"id":"1.195395429","rc":[{"atb":[[12.5,11.7]],"id":39520250}],"con":true,"img":false}]}
{"op":"mcm","clk":"5306773137","pt":1646105845603,"mc":[{"id":"1.195395429","rc":[{"atl":[[16.5,11.46]],"id":41762283}],"con":true,"img":false}]}
{"op":"mcm","clk":"5306773154","pt":1646105846118,"mc":[{"id":"1.195395429","rc":[{"atl":[[16,14.56]],"id":37401228}],"con":true,"img":false}]}
{"op":"mcm","clk":"5306773190","pt":1646105847088,"mc":[{"id":"1.195395429","rc":[{"atb":[[7.4,28.24]],"id":37401228}],"con":true,"img":false}]}
{"op":"mcm","clk":"5306773207","pt":1646105847498,"mc":[{"id":"1.195395429","rc":[{"atl":[[16.5,10.82]],"id":41762283}],"con":true,"img":false}]}
{"op":"mcm","clk":"5306773210","pt":1646105847601,"mc":[{"id":"1.195395429","rc":[{"atl":[[1000,2.23]],"id":41762283}],"con":true,"img":false}]}
{"op":"mcm","clk":"5306773219","pt":1646105847908,"mc":[{"id":"1.195395429","rc":[{"atl":[[1000,0.66]],"id":41762283}],"con":true,"img":false}]}
{"op":"mcm","clk":"5306773231","pt":1646105848214,"mc":[{"id":"1.195395429","rc":[{"atl":[[1000,0]],"id":41762283}],"con":true,"img":false}]}
{"op":"mcm","clk":"5306773233","pt":1646105848316,"mc":[{"id":"1.195395429","rc":[{"atl":[[16,0.66]],"id":41762283}],"con":true,"img":false}]}
{"op":"mcm","clk":"5306773989","pt":1646105875233,"mc":[{"id":"1.195395429","rc":[{"atb":[[1.37,0]],"id":40494181}],"con":true,"img":false}]}
{"op":"mcm","clk":"5306773993","pt":1646105875360,"mc":[{"id":"1.195395429","rc":[{"atb":[[1.4,87.96]],"id":40494181}],"con":true,"img":false}]}
{"op":"mcm","clk":"5306774238","pt":1646105883555,"mc":[{"id":"1.195395429","rc":[{"atb":[[1.39,32.22]],"id":40494181}],"con":true,"img":false}]}
{"op":"mcm","clk":"5306774380","pt":1646105888682,"mc":[{"id":"1.195395429","rc":[{"atb":[[1.39,10.82]],"id":40494181}],"con":true,"img":false}]}
{"op":"mcm","clk":"5306774494","pt":1646105892595,"mc":[{"id":"1.195395429","rc":[{"atb":[[1.42,17.74]],"id":40494181}],"con":true,"img":false}]}
{"op":"mcm","clk":"5306774555","pt":1646105894594,"mc":[{"id":"1.195395429","rc":[{"atb":[[1.42,37.62]],"id":40494181}],"con":true,"img":false}]}
{"op":"mcm","clk":"5306774562","pt":1646105894798,"mc":[{"id":"1.195395429","rc":[{"atl":[[44,10.82]],"id":38206560},{"atl":[[17,0]],"id":41762283}],"con":true,"img":false}]}
{"op":"mcm","clk":"5306774565","pt":1646105894902,"mc":[{"id":"1.195395429","rc":[{"atl":[[42,2.7]],"id":38206560},{"atl":[[16,4.28]],"id":41762283}],"con":true,"img":false}]}
{"op":"mcm","clk":"5306774589","pt":1646105895574,"mc":[{"id":"1.195395429","rc":[{"atl":[[16,3.62]],"id":41762283}],"con":true,"img":false}]}
{"op":"mcm","clk":"5306774591","pt":1646105895678,"mc":[{"id":"1.195395429","rc":[{"atl":[[1000,2.23]],"id":41762283}],"con":true,"img":false}]}
{"op":"mcm","clk":"5306774597","pt":1646105895879,"mc":[{"id":"1.195395429","rc":[{"atl":[[1000,0.68]],"id":41762283}],"con":true,"img":false}]}
{"op":"mcm","clk":"5306774605","pt":1646105896085,"mc":[{"id":"1.195395429","rc":[{"atl":[[1000,0]],"id":41762283}],"con":true,"img":false}]}
{"op":"mcm","clk":"5306774607","pt":1646105896185,"mc":[{"id":"1.195395429","rc":[{"atl":[[15.5,0.68]],"id":41762283}],"con":true,"img":false}]}
{"op":"mcm","clk":"5306774757","pt":1646105900866,"mc":[{"id":"1.195395429","rc":[{"spn":28.75,"spf":1.0,"id":38206560},{"spn":11.05,"spf":1.0,"id":41762283},{"atl":[[2.14,72.55]],"id":40494181},{"spn":1.41,"spf":1.0,"id":40494181}],"con":true,"img":false}]}
{"op":"mcm","clk":"5306774781","pt":1646105901992,"mc":[{"id":"1.195395429","rc":[{"atb":[[1.42,48.44]],"id":40494181}],"con":true,"img":false}]}
{"op":"mcm","clk":"5306774821","pt":1646105903020,"mc":[{"id":"1.195395429","rc":[{"atb":[[7.2,32.93]],"id":38206580}],"con":true,"img":false}]}
{"op":"mcm","clk":"5306774843","pt":1646105903487,"mc":[{"id":"1.195395429","rc":[{"atl":[[42,13.52]],"id":38206560}],"con":true,"img":false}]}
{"op":"mcm","clk":"5306774872","pt":1646105904509,"mc":[{"id":"1.195395429","rc":[{"atb":[[12.5,22.52]],"id":39520250}],"con":true,"img":false}]}
{"op":"mcm","clk":"5306774888","pt":1646105905074,"mc":[{"id":"1.195395429","rc":[{"atl":[[15.5,11.5]],"id":41762283}],"con":true,"img":false}]}
{"op":"mcm","clk":"5306774900","pt":1646105905583,"mc":[{"id":"1.195395429","rc":[{"atl":[[16,25.38]],"id":37401228}],"con":true,"img":false}]}
{"op":"mcm","clk":"5306774930","pt":1646105906504,"mc":[{"id":"1.195395429","rc":[{"atb":[[7.4,39.06]],"id":37401228}],"con":true,"img":false}]}
{"op":"mcm","clk":"5306774966","pt":1646105907574,"mc":[{"id":"1.195395429","rc":[{"atl":[[15.5,10.82]],"id":41762283}],"con":true,"img":false}]}
{"op":"mcm","clk":"5306774968","pt":1646105907675,"mc":[{"id":"1.195395429","rc":[{"atl":[[1000,2.23]],"id":41762283}],"con":true,"img":false}]}
{"op":"mcm","clk":"5306774976","pt":1646105907880,"mc":[{"id":"1.195395429","rc":[{"atl":[[1000,0.7]],"id":41762283}],"con":true,"img":false}]}
{"op":"mcm","clk":"5306774979","pt":1646105908084,"mc":[{"id":"1.195395429","rc":[{"atl":[[1000,0]],"id":41762283}],"con":true,"img":false}]}
{"op":"mcm","clk":"5306774981","pt":1646105908189,"mc":[{"id":"1.195395429","rc":[{"atl":[[15,0.7]],"id":41762283}],"con":true,"img":false}]}
{"op":"mcm","clk":"5306775305","pt":1646105920005,"mc":[{"id":"1.195395429","rc":[{"atb":[[1.4,0]],"id":40494181}],"con":true,"img":false}]}
{"op":"mcm","clk":"5306775308","pt":1646105920107,"mc":[{"id":"1.195395429","rc":[{"atb":[[1.38,87.96]],"id":40494181}],"con":true,"img":false}]}
{"op":"mcm","clk":"5306775539","pt":1646105928510,"mc":[{"id":"1.195395429","rc":[{"atb":[[1.42,30.7]],"id":40494181}],"con":true,"img":false}]}
{"op":"mcm","clk":"5306775765","pt":1646105936633,"mc":[{"id":"1.195395429","rc":[{"atb":[[1.42,10.82]],"id":40494181}],"con":true,"img":false}]}
{"op":"mcm","clk":"5306775877","pt":1646105940510,"mc":[{"id":"1.195395429","rc":[{"atb":[[1.4,18.63]],"id":40494181}],"con":true,"img":false}]}
{"op":"mcm","clk":"5306775942","pt":1646105942761,"mc":[{"id":"1.195395429","rc":[{"atb":[[1.4,39.5]],"id":40494181}],"con":true,"img":false}]}
{"op":"mcm","clk":"5306776552","pt":1646105964454,"mc":[{"id":"1.195395429","rc":[{"atl":[[42,10.82]],"id":38206560},{"atl":[[16,0]],"id":41762283},{"spn":10.8,"spf":1.0,"id":41762283},{"spn":1.4,"spf":1.0,"id":40494181}],"con":true,"img":false}]}
{"op":"mcm","clk":"5306776553","pt":1646105964556,"mc":[{"id":"1.195395429","rc":[{"atl":[[40,2.7]],"id":38206560},{"atl":[[15,4.33]],"id":41762283}],"con":true,"img":false}]}
{"op":"mcm","clk":"5306776618","pt":1646105967679,"mc":[{"id":"1.195395429","rc":[{"atl":[[15,3.62]],"id":41762283}],"con":true,"img":false}]}
{"op":"mcm","clk":"5306776621","pt":1646105967782,"mc":[{"id":"1.195395429","rc":[{"atl":[[1000,2.23]],"id":41762283}],"con":true,"img":false}]}
{"op":"mcm","clk":"5306776625","pt":1646105967885,"mc":[{"id":"1.195395429","rc":[{"atl":[[1000,0.73]],"id":41762283}],"con":true,"img":false}]}
{"op":"mcm","clk":"5306776630","pt":1646105968088,"mc":[{"id":"1.195395429","rc":[{"atl":[[1000,0]],"id":41762283}],"con":true,"img":false}]}
{"op":"mcm","clk":"5306776632","pt":1646105968191,"mc":[{"id":"1.195395429","rc":[{"atl":[[14.5,0.73]],"id":41762283}],"con":true,"img":false}]}
{"op":"mcm","clk":"5306777550","pt":1646106000621,"mc":[{"id":"1.195395429","rc":[{"atb":[[1.32,379.54]],"id":40494181}],"con":true,"img":false}]}
{"op":"mcm","clk":"5306777776","pt":1646106007638,"mc":[{"id":"1.195395429","rc":[{"atb":[[1.19,105.79]],"id":40494181}],"con":true,"img":false}]}
{"op":"mcm","clk":"5306777834","pt":1646106009125,"mc":[{"id":"1.195395429","rc":[{"atb":[[1.38,0]],"id":40494181}],"con":true,"img":false}]}
{"op":"mcm","clk":"5306777839","pt":1646106009226,"mc":[{"id":"1.195395429","rc":[{"atb":[[1.41,87.96]],"id":40494181}],"con":true,"img":false}]}
{"op":"mcm","clk":"5306778077","pt":1646106015725,"mc":[{"id":"1.195395429","rc":[{"atb":[[1.4,20.87]],"id":40494181}],"con":true,"img":false}]}
{"op":"mcm","clk":"5306778456","pt":1646106024647,"mc":[{"id":"1.195395429","rc":[{"spn":27.75,"spf":1.0,"id":38206560},{"spn":10.55,"spf":1.0,"id":41762283},{"atb":[[1.43,17.33]],"id":40494181},{"spn":1.41,"spf":1.0,"id":40494181}],"con":true,"img":false}]}
{"op":"mcm","clk":"5306778542","pt":1646106026853,"mc":[{"id":"1.195395429","rc":[{"atb":[[1.4,0]],"id":40494181}],"con":true,"img":false}]}
{"op":"mcm","clk":"5306778758","pt":1646106032753,"mc":[{"id":"1.195395429","rc":[{"atb":[[1.43,36.75]],"id":40494181}],"con":true,"img":false}]}
{"op":"mcm","clk":"5306778812","pt":1646106033984,"mc":[{"id":"1.195395429","rc":[{"atb":[[1.41,0]],"id":40494181}],"con":true,"img":false}]}
{"op":"mcm","clk":"5306778816","pt":1646106034086,"mc":[{"id":"1.195395429","rc":[{"atb":[[1.37,87.96]],"id":40494181}],"con":true,"img":false}]}
{"op":"mcm","clk":"5306779132","pt":1646106042786,"mc":[{"id":"1.195395429","rc":[{"atb":[[1.43,19.42]],"id":40494181}],"con":true,"img":false}]}
{"op":"mcm","clk":"5306779469","pt":1646106050871,"mc":[{"id":"1.195395429","rc":[{"atb":[[1.43,0]],"id":40494181}],"con":true,"img":false}]}
{"op":"mcm","clk":"5306779496","pt":1646106051690,"mc":[{"id":"1.195395429","rc":[{"atb":[[1.39,29.93]],"id":40494181}],"con":true,"img":false}]}
{"op":"mcm","clk":"5306779684","pt":1646106056915,"mc":[{"id":"1.195395429","rc":[{"atb":[[1.39,51.33]],"id":40494181}],"con":true,"img":false}]}
{"op":"mcm","clk":"5306779974","pt":1646106063980,"mc":[{"id":"1.195395429","rc":[{"spl":[[18,5.41]],"id":39520250},{"spl":[[18,5.41]],"id":37401228}],"con":true,"img":false}]}
{"op":"mcm","clk":"5306779980","pt":1646106064185,"mc":[{"id":"1.195395429","rc":[{"spl":[[18,5.41]],"id":38206580},{"spl":[[18,5.41]],"id":38206560}],"con":true,"img":false}]}
{"op":"mcm","clk":"5306779986","pt":1646106064390,"mc":[{"id":"1.195395429","rc":[{"spl":[[18,10.82]],"id":39520250},{"spl":[[18,10.82]],"id":37401228}],"con":true,"img":false}]}
{"op":"mcm","clk":"5306779996","pt":1646106064595,"mc":[{"id":"1.195395429","rc":[{"spl":[[18,10.82]],"id":38206580}],"con":true,"img":false}]}
{"op":"mcm","clk":"5306779999","pt":1646106064702,"mc":[{"id":"1.195395429","rc":[{"spl":[[18,10.82]],"id":38206560}],"con":true,"img":false}]}
{"op":"mcm","clk":"5306780904","pt":1646106089438,"mc":[{"id":"1.195395429","rc":[{"atb":[[7.2,0],[9.2,0],[8.2,0],[11.5,0]],"id":39520250},{"atl":[[80,0],[160,0],[210,0],[110,0]],"id":39520250},{"spn":15.25,"spf":1.0,"id":39520250},{"atb":[[18,0],[23,0.46],[13,0],[15.5,0]],"id":36104895},{"atl":[[300,0],[350,0],[200,0],[250,0]],"id":36104895},{"atb":[[4.5,0],[6.4,0],[5,0],[5.5,0]],"id":38206580},{"atl":[[19.5,0],[38,0],[24,0],[29,0]],"id":38206580},{"atb":[[18,0],[21,0],[28,0],[15.5,0]],"id":27701417},{"atl":[[290,0],[340,0],[390,0],[240,0]],"id":27701417},{"atb":[[12,0],[9.8,0],[8.8,0],[15.5,0.7]],"id":38206560},{"atl":[[270,0],[170,0],[220,0],[120,0]],"id":38206560},{"spn":16.75,"spf":1.0,"id":38206560},{"atb":[[4.5,0],[6.4,0],[5,0],[5.5,0]],"id":41762283},{"atl":[[19.5,0],[38,0],[24,0],[29,0]],"id":41762283},{"atb":[[5,0],[5.5,0],[7.4,23.21],[6,0]],"id":37401228},{"atl":[[70,0],[38,0],[48,0],[29,0]],"id":37401228},{"atb":[[1.2,0],[1.25,0],[1.15,0],[1.32,62.5]],"id":40494181},{"atl":[[2.54,0],[2.74,0],[2.64,0],[2.84,0]],"id":40494181},{"spn":1.39,"spf":1.0,"id":40494181}],"con":true,"img":false}]}
{"op":"mcm","clk":"5306780976","pt":1646106092152,"mc":[{"id":"1.195395429","rc":[{"atb":[[9.2,26.36],[10.5,22.75],[13,9]],"id":39520250},{"atl":[[80,1.36],[160,1.35],[110,1.98]],"id":39520250},{"atb":[[18,12.72],[21,10.81],[26,4.32]],"id":36104895},{"atl":[[300,0.72],[200,0.54],[250,0.86]],"id":36104895},{"atb":[[5.5,48.04],[6,43.24],[7,18.01]],"id":38206580},{"atl":[[19.5,5.84],[24,9.39],[29,7.72]],"id":38206580},{"atb":[[32,3.49],[21,10.81],[26,8.64]],"id":27701417},{"atl":[[290,0.74],[340,0.63],[240,0.45]],"id":27701417},{"atb":[[17,6.75],[12,19.65],[14.5,16.01]],"id":38206560},{"atl":[[170,1.27],[220,0.98],[120,0.9]],"id":38206560},{"atb":[[5.5,48.04],[6,43.24],[7,18.01]],"id":41762283},{"atl":[[19.5,5.84],[24,9.39],[29,7.72]],"id":41762283},{"atb":[[8,15.44],[6,43.24],[7,36.03]],"id":37401228},{"atl":[[38,5.84],[48,4.59],[29,3.86]],"id":37401228},{"atb":[[1.25,864.88],[1.3,720.74],[1.35,308.89]],"id":40494181},{"atl":[[2.54,70.2],[2.74,124.26],[2.64,131.84]],"id":40494181}],"con":true,"img":false}]}
{"op":"mcm","clk":"5306781000","pt":1646106092920,"mc":[{"id":"1.195395429","rc":[{"atl":[[2.1,7.94]],"id":40494181}],"con":true,"img":false}]}
{"op":"mcm","clk":"5306781022","pt":1646106093741,"mc":[{"id":"1.195395429","rc":[{"atl":[[2.1,15.04]],"id":40494181}],"con":true,"img":false}]}
{"op":"mcm","clk":"5306781097","pt":1646106095842,"mc":[{"id":"1.195395429","rc":[{"atb":[[12,0]],"id":39520250},{"atb":[[6.6,0]],"id":38206580}],"con":true,"img":false}]}
{"op":"mcm","clk":"5306781102","pt":1646106095944,"mc":[{"id":"1.195395429","rc":[{"atb":[[11.5,5.27]],"id":39520250},{"atb":[[6.2,23.26]],"id":38206580}],"con":true,"img":false}]}
{"op":"mcm","clk":"5306781285","pt":1646106101420,"mc":[{"id":"1.195395429","rc":[{"atb":[[7,6.8]],"id":41762283},{"trd":[[7,22.43]],"ltp":7.0,"tv":22.43,"id":41762283}],"con":true,"img":false}]}
{"op":"mcm","clk":"5306781347","pt":1646106104947,"mc":[{"id":"1.195395429","rc":[{"atb":[[6.6,10.36]],"id":41762283}],"con":true,"img":false}]}
{"op":"mcm","clk":"5306781451","pt":1646106107965,"mc":[{"id":"1.195395429","rc":[{"atb":[[1.01,3.36]],"id":39520250},{"atb":[[1.01,3.36]],"id":36104895},{"atb":[[6,48.22]],"id":38206580},{"atb":[[1.01,2492.16]],"id":40494181}],"con":true,"img":false}]}
{"op":"mcm","clk":"5306781453","pt":1646106108067,"mc":[{"id":"1.195395429","rc":[{"atl":[[90,3.7]],"id":39520250},{"atl":[[190,3.7]],"id":36104895},{"atl":[[23,3.7]],"id":38206580},{"atb":[[1.01,3.36]],"id":27701417},{"atl":[[320,3.7]],"id":27701417},{"atb":[[1.01,3.36]],"id":38206560},{"atl":[[70,3.7]],"id":38206560},{"atb":[[5.9,5.08]],"id":41762283},{"atl":[[19,9.91]],"id":41762283},{"atb":[[6.8,4.29]],"id":37401228},{"atl":[[20,3.7]],"id":37401228}],"con":true,"img":false}]}
{"op":"mcm","clk":"5306781456","pt":1646106108170,"mc":[{"id":"1.195395429","rc":[{"atb":[[1.01,2.76]],"id":39520250},{"atb":[[1.01,1.31]],"id":36104895}],"con":true,"img":false}]}
{"op":"mcm","clk":"5306781460","pt":1646106108273,"mc":[{"id":"1.195395429","rc":[{"atb":[[1.01,1.03]],"id":27701417},{"atb":[[1.01,1.91]],"id":38206560}],"con":true,"img":false}]}
{"op":"mcm","clk":"5306781464","pt":1646106108374,"mc":[{"id":"1.195395429","rc":[{"atb":[[1.01,0]],"id":39520250},{"atb":[[1.01,0]],"id":36104895}],"con":true,"img":false}]}
{"op":"mcm","clk":"5306781467","pt":1646106108475,"mc":[{"id":"1.195395429","rc":[{"atb":[[10,2.76]],"id":39520250},{"atb":[[20,1.31]],"id":36104895},{"atb":[[1.01,0]],"id":27701417},{"atb":[[1.01,0]],"id":38206560}],"con":true,"img":false}]}
{"op":"mcm","clk":"5306781468","pt":1646106108578,"mc":[{"id":"1.195395429","rc":[{"atb":[[25,1.03]],"id":27701417},{"atb":[[14,1.91]],"id":38206560}],"con":true,"img":false}]}
{"op":"mcm","clk":"5306781479","pt":1646106108936,"mc":[{"id":"1.195395429","rc":[{"atl":[[1000,2.7]],"id":41762283},{"atl":[[1000,2.7]],"id":40494181}],"con":true,"img":false}]}
{"op":"mcm","clk":"5306781484","pt":1646106109142,"mc":[{"id":"1.195395429","rc":[{"atl":[[1000,2.7]],"id":38206580},{"atl":[[1000,2.7]],"id":37401228}],"con":true,"img":false}]}
{"op":"mcm","clk":"5306781495","pt":1646106109449,"mc":[{"id":"1.195395429","rc":[{"atl":[[1000,2.7]],"id":39520250},{"atl":[[1000,2.73]],"id":41762283}],"con":true,"img":false}]}
{"op":"mcm","clk":"5306781503","pt":1646106109653,"mc":[{"id":"1.195395429","rc":[{"atl":[[1000,2.72]],"id":38206580},{"atl":[[1000,2.7]],"id":38206560}],"con":true,"img":false}]}
{"op":"mcm","clk":"5306781508","pt":1646106109859,"mc":[{"id":"1.195395429","rc":[{"atl":[[1000,2.71]],"id":38206560}],"con":true,"img":false}]}
{"op":"mcm","clk":"5306781510","pt":1646106109962,"mc":[{"id":"1.195395429","rc":[{"atl":[[1000,0.02]],"id":38206580}],"con":true,"img":false}]}
{"op":"mcm","clk":"5306781512","pt":1646106110064,"mc":[{"id":"1.195395429","rc":[{"atl":[[1000,5.43]],"id":41762283}],"con":true,"img":false}]}
{"op":"mcm","clk":"5306781517","pt":1646106110271,"mc":[{"id":"1.195395429","rc":[{"atl":[[1000,2.71]],"id":39520250},{"atl":[[1000,0.01]],"id":38206560}],"con":true,"img":false}]}
{"op":"mcm","clk":"5306781525","pt":1646106110475,"mc":[{"id":"1.195395429","rc":[{"atl":[[1000,0.01]],"id":39520250},{"atl":[[1000,0]],"id":38206560}],"con":true,"img":false}]}
{"op":"mcm","clk":"5306781528","pt":1646106110577,"mc":[{"id":"1.195395429","rc":[{"atb":[[17,6.74]],"id":38206560},{"trd":[[17,0.02]],"ltp":17.0,"tv":0.02,"id":38206560}],"con":true,"img":false}]}
{"op":"mcm","clk":"5306781532","pt":1646106110680,"mc":[{"id":"1.195395429","rc":[{"atl":[[1000,0]],"id":39520250}],"con":true,"img":false}]}
{"op":"mcm","clk":"5306781534","pt":1646106110782,"mc":[{"id":"1.195395429","rc":[{"atb":[[13,8.99]],"id":39520250},{"trd":[[13,0.02]],"ltp":13.0,"tv":0.02,"id":39520250},{"atb":[[15.5,0]],"id":38206560},{"atl":[[1000,5.48]],"id":41762283}],"con":true,"img":false}]}
{"op":"mcm","clk":"5306781544","pt":1646106111039,"mc":[{"id":"1.195395429","rc":[{"atl":[[1000,0.07]],"id":41762283}],"con":true,"img":false}]}
{"op":"mcm","clk":"5306781552","pt":1646106111347,"mc":[{"id":"1.195395429","rc":[{"atl":[[1000,0]],"id":41762283}],"con":true,"img":false}]}
{"op":"mcm","clk":"5306781555","pt":1646106111449,"mc":[{"id":"1.195395429","rc":[{"atb":[[7,6.72]],"id":41762283},{"trd":[[7,22.58]],"ltp":7.0,"tv":22.58,"id":41762283}],"con":true,"img":false}]}
{"op":"mcm","clk":"5306781562","pt":1646106111653,"mc":[{"id":"1.195395429","rc":[{"atl":[[1000,5.41]],"id":37401228},{"atl":[[1000,2.84]],"id":40494181}],"con":true,"img":false}]}
{"op":"mcm","clk":"5306781569","pt":1646106111860,"mc":[{"id":"1.195395429","rc":[{"atl":[[1000,5.43]],"id":37401228},{"atl":[[1000,0.13]],"id":40494181}],"con":true,"img":false}]}
{"op":"mcm","clk":"5306781577","pt":1646106112067,"mc":[{"id":"1.195395429","rc":[{"atl":[[1000,2.7]],"id":40494181}],"con":true,"img":false}]}
{"op":"mcm","clk":"5306781580","pt":1646106112169,"mc":[{"id":"1.195395429","rc":[{"atb":[[1.42,10.68]],"id":40494181},{"trd":[[1.42,0.27]],"ltp":1.42,"tv":0.27,"id":40494181}],"con":true,"img":false}]}
{"op":"mcm","clk":"5306781582","pt":1646106112272,"mc":[{"id":"1.195395429","rc":[{"atb":[[1.36,0]],"id":40494181},{"atl":[[1000,2.95]],"id":40494181}],"con":true,"img":false}]}
{"op":"mcm","clk":"5306781584","pt":1646106112374,"mc":[{"id":"1.195395429","rc":[{"atl":[[1000,0]],"id":38206580}],"con":true,"img":false}]}
{"op":"mcm","clk":"5306781586","pt":1646106112476,"mc":[{"id":"1.195395429","rc":[{"atb":[[7.2,32.91]],"id":38206580},{"trd":[[7.2,0.04]],"ltp":7.2,"tv":0.04,"id":38206580},{"atl":[[1000,5.47]],"id":37401228}],"con":true,"img":false}]}
{"op":"mcm","clk":"5306781597","pt":1646106112734,"mc":[{"id":"1.195395429","rc":[{"atl":[[1000,0.06]],"id":37401228}],"con":true,"img":false}]}
{"op":"mcm","clk":"5306781603","pt":1646106112940,"mc":[{"id":"1.195395429","rc":[{"atb":[[1.04,2.23]],"id":38206560},{"atl":[[1000,2.23]],"id":38206560},{"atl":[[1000,0.02]],"id":37401228},{"atl":[[1000,0.25]],"id":40494181}],"con":true,"img":false}]}
{"op":"mcm","clk":"5306781605","pt":1646106113044,"mc":[{"id":"1.195395429","rc":[{"atb":[[8,15.39]],"id":37401228},{"trd":[[8,0.08]],"ltp":8.0,"tv":0.08,"id":37401228}],"con":true,"img":false}]}
{"op":"mcm","clk":"5306781607","pt":1646106113146,"mc":[{"id":"1.195395429","rc":[{"atl":[[1000,0]],"id":40494181}],"con":true,"img":false}]}
{"op":"mcm","clk":"5306781610","pt":1646106113251,"mc":[{"id":"1.195395429","rc":[{"atb":[[1.42,10.43]],"id":40494181},{"trd":[[1.42,0.77]],"ltp":1.42,"tv":0.77,"id":40494181}],"con":true,"img":false}]}
{"op":"mcm","clk":"5306781612","pt":1646106113351,"mc":[{"id":"1.195395429","rc":[{"atb":[[1.04,0.29]],"id":38206560},{"atl":[[1000,0.47]],"id":38206560},{"atl":[[1000,0]],"id":37401228}],"con":true,"img":false}]}
{"op":"mcm","clk":"5306781614","pt":1646106113453,"mc":[{"id":"1.195395429","rc":[{"atb":[[8,15.37]],"id":37401228},{"trd":[[8,0.12]],"ltp":8.0,"tv":0.12,"id":37401228}],"con":true,"img":false}]}
{"op":"mcm","clk":"5306781618","pt":1646106113760,"mc":[{"id":"1.195395429","rc":[{"atb":[[1.04,0]],"id":38206560},{"atl":[[1000,0]],"id":38206560}],"con":true,"img":false}]}
{"op":"mcm","clk":"5306781622","pt":1646106113863,"mc":[{"id":"1.195395429","rc":[{"atl":[[38,0.47],[40,2.4]],"id":38206560},{"trd":[[40,0.59]],"ltp":40.0,"tv":0.59,"id":38206560}],"con":true,"img":false}]}
{"op":"mcm","clk":"5306781731","pt":1646106116944,"mc":[{"id":"1.195395429","rc":[{"atb":[[1.01,1.66]],"id":41762283}],"con":true,"img":false}]}
{"op":"mcm","clk":"5306781740","pt":1646106117252,"mc":[{"id":"1.195395429","rc":[{"atb":[[1.01,1.6]],"id":41762283}],"con":true,"img":false}]}
{"op":"mcm","clk":"5306781745","pt":1646106117557,"mc":[{"id":"1.195395429","rc":[{"atb":[[1.01,0]],"id":41762283}],"con":true,"img":false}]}
{"op":"mcm","clk":"5306781747","pt":1646106117661,"mc":[{"id":"1.195395429","rc":[{"atb":[[6.2,1.6]],"id":41762283}],"con":true,"img":false}]}
{"op":"mcm","clk":"5306781797","pt":1646106119249,"mc":[{"id":"1.195395429","rc":[{"atb":[[9.6,0],[11.5,0]],"id":39520250},{"atb":[[16,0],[12,11.18]],"id":36104895},{"atl":[[40,0]],"id":38206560},{"atb":[[6.6,0]],"id":41762283},{"atb":[[6.6,0]],"id":37401228},{"atb":[[1.37,0],[1.33,0]],"id":40494181}],"con":true,"img":false}]}
{"op":"mcm","clk":"5306781801","pt":1646106119351,"mc":[{"id":"1.195395429","rc":[{"atb":[[11,5.27],[9.4,13.04]],"id":39520250},{"atl":[[42,13.22]],"id":38206560},{"atb":[[6.2,11.96]],"id":41762283},{"atb":[[6.4,10]],"id":37401228},{"atb":[[1.36,87.96],[1.31,323.01]],"id":40494181}],"con":true,"img":false}]}
{"op":"mcm","clk":"5306781910","pt":1646106121558,"mc":[{"id":"1.195395429","rc":[{"spl":[[1.01,15.25]],"id":38206580}],"con":true,"img":false}]}
{"op":"mcm","clk":"5306781916","pt":1646106121661,"mc":[{"id":"1.195395429","rc":[{"spl":[[1.01,11.95]],"id":39520250}],"con":true,"img":false}]}
{"op":"mcm","clk":"5306782097","pt":1646106126592,"mc":[{"id":"1.195395429","rc":[{"atl":[[2.1,25.86]],"id":40494181}],"con":true,"img":false}]}
{"op":"mcm","clk":"5306782103","pt":1646106126797,"mc":[{"id":"1.195395429","rc":[{"atb":[[1.39,32.22]],"id":40494181}],"con":true,"img":false}]}
{"op":"mcm","clk":"5306782161","pt":1646106128176,"mc":[{"id":"1.195395429","rc":[{"atb":[[1.42,21.25]],"id":40494181}],"con":true,"img":false}]}
{"op":"mcm","clk":"5306782204","pt":1646106129454,"mc":[{"id":"1.195395429","rc":[{"atb":[[7.2,43.74]],"id":38206580}],"con":true,"img":false}]}
{"op":"mcm","clk":"5306782223","pt":1646106129967,"mc":[{"id":"1.195395429","rc":[{"atl":[[40,10.82]],"id":38206560}],"con":true,"img":false}]}
{"op":"mcm","clk":"5306782272","pt":1646106130989,"mc":[{"id":"1.195395429","rc":[{"atl":[[42,13.52]],"id":38206560}],"con":true,"img":false}]}
{"op":"mcm","clk":"5306782279","pt":1646106131092,"mc":[{"id":"1.195395429","rc":[{"atl":[[34,0]],"id":39520250},{"atl":[[17.5,0]],"id":38206580},{"atb":[[29,0]],"id":27701417},{"atl":[[180,0]],"id":27701417},{"atl":[[16,21.64]],"id":37401228},{"atl":[[2.14,21.64]],"id":40494181}],"con":true,"img":false}]}
{"op":"mcm","clk":"5306782283","pt":1646106131192,"mc":[{"id":"1.195395429","rc":[{"atl":[[32,2.7]],"id":39520250},{"atl":[[14.5,3.51]],"id":38206580},{"atb":[[34,2.7]],"id":27701417},{"atl":[[160,0.32]],"id":27701417},{"atl":[[14.5,3.74]],"id":37401228},{"atl":[[1.99,50.9]],"id":40494181}],"con":true,"img":false}]}
{"op":"mcm","clk":"5306782287","pt":1646106131295,"mc":[{"id":"1.195395429","rc":[{"atb":[[13,19.82]],"id":39520250}],"con":true,"img":false}]}
{"op":"mcm","clk":"5306782304","pt":1646106131808,"mc":[{"id":"1.195395429","rc":[{"atl":[[14.5,11.55]],"id":41762283}],"con":true,"img":false}]}
{"op":"mcm","clk":"5306782324","pt":1646106132269,"mc":[{"id":"1.195395429","rc":[{"atl":[[16,32.46]],"id":37401228}],"con":true,"img":false}]}
{"op":"mcm","clk":"5306782348","pt":1646106132784,"mc":[{"id":"1.195395429","rc":[{"atl":[[14.5,10.82]],"id":41762283}],"con":true,"img":false}]}
{"op":"mcm","clk":"5306782359","pt":1646106132988,"mc":[{"id":"1.195395429","rc":[{"atl":[[1000,2.23]],"id":41762283}],"con":true,"img":false}]}
{"op":"mcm","clk":"5306782364","pt":1646106133090,"mc":[{"id":"1.195395429","rc":[{"atl":[[1000,0.76]],"id":41762283}],"con":true,"img":false}]}
{"op":"mcm","clk":"5306782372","pt":1646106133295,"mc":[{"id":"1.195395429","rc":[{"atl":[[1000,0]],"id":41762283}],"con":true,"img":false}]}
{"op":"mcm","clk":"5306782376","pt":1646106133398,"mc":[{"id":"1.195395429","rc":[{"atl":[[14,0.76]],"id":41762283}],"con":true,"img":false}]}
{"op":"mcm","clk":"5306782380","pt":1646106133500,"mc":[{"id":"1.195395429","rc":[{"atb":[[8,26.19]],"id":37401228}],"con":true,"img":false}]}
{"op":"mcm","clk":"5306782447","pt":1646106134988,"mc":[{"id":"1.195395429","rc":[{"atb":[[1.39,10.82]],"id":40494181}],"con":true,"img":false}]}
{"op":"mcm","clk":"5306782658","pt":1646106140978,"mc":[{"id":"1.195395429","rc":[{"atb":[[1.38,21.97]],"id":40494181}],"con":true,"img":false}]}
{"op":"mcm","clk":"5306782737","pt":1646106143180,"mc":[{"id":"1.195395429","rc":[{"atl":[[32,0]],"id":39520250},{"atb":[[5.6,0]],"id":41762283}],"con":true,"img":false}]}
{"op":"mcm","clk":"5306782741","pt":1646106143282,"mc":[{"id":"1.195395429","rc":[{"atl":[[34,2.7]],"id":39520250},{"atb":[[6.2,36.25]],"id":41762283}],"con":true,"img":false}]}
{"op":"mcm","clk":"5306782751","pt":1646106143587,"mc":[{"id":"1.195395429","rc":[{"atb":[[15,11.71]],"id":37401228},{"atl":[[14.5,0]],"id":37401228},{"trd":[[14.5,7.48]],"ltp":14.5,"tv":7.48,"id":37401228},{"atb":[[2,165.53]],"id":40494181},{"atl":[[1.99,0]],"id":40494181},{"trd":[[1.99,101.81]],"ltp":1.99,"tv":101.81,"id":40494181}],"con":true,"img":false}]}
{"op":"mcm","clk":"5306782755","pt":1646106143689,"mc":[{"id":"1.195395429","rc":[{"atb":[[2,128.06]],"id":40494181},{"trd":[[2,74.96]],"ltp":2.0,"tv":74.96,"id":40494181}],"con":true,"img":false}]}
{"op":"mcm","clk":"5306782787","pt":1646106144508,"mc":[{"id":"1.195395429","rc":[{"atb":[[1.04,1.44]],"id":40494181}],"con":true,"img":false}]}
{"op":"mcm","clk":"5306782801","pt":1646106144814,"mc":[{"id":"1.195395429","rc":[{"atl":[[14,0]],"id":41762283}],"con":true,"img":false}]}
{"op":"mcm","clk":"5306782806","pt":1646106144915,"mc":[{"id":"1.195395429","rc":[{"atb":[[1.04,0.84]],"id":40494181}],"con":true,"img":false}]}
{"op":"mcm","clk":"5306782808","pt":1646106145017,"mc":[{"id":"1.195395429","rc":[{"atl":[[1000,2.23]],"id":41762283}],"con":true,"img":false}]}
{"op":"mcm","clk":"5306782812","pt":1646106145120,"mc":[{"id":"1.195395429","rc":[{"atl":[[1000,0.96]],"id":41762283}],"con":true,"img":false}]}
{"op":"mcm","clk":"5306782815","pt":1646106145222,"mc":[{"id":"1.195395429","rc":[{"atl":[[1000,0]],"id":41762283},{"atb":[[1.04,0]],"id":40494181}],"con":true,"img":false}]}
{"op":"mcm","clk":"5306782818","pt":1646106145325,"mc":[{"id":"1.195395429","rc":[{"atl":[[11,0.96]],"id":41762283},{"atl":[[2.1,25.02]],"id":40494181},{"trd":[[2.1,1.68]],"ltp":2.1,"tv":1.68,"id":40494181}],"con":true,"img":false}]}
{"op":"mcm","clk":"5306782848","pt":1646106146398,"mc":[{"id":"1.195395429","rc":[{"atb":[[1.95,3.2]],"id":40494181}],"con":true,"img":false}]}
{"op":"mcm","clk":"5306782873","pt":1646106147115,"mc":[{"id":"1.195395429","rc":[{"atb":[[13,15.13]],"id":39520250},{"trd":[[13,4.7]],"ltp":13.0,"tv":4.7,"id":39520250},{"atb":[[26,1.97]],"id":36104895},{"trd":[[26,2.34]],"ltp":26.0,"tv":2.34,"id":36104895},{"atl":[[14.5,0]],"id":38206580},{"trd":[[15,0.92],[11.5,0.93],[12,3.02],[14.5,7.03]],"ltp":15.0,"tv":11.9,"id":38206580},{"atb":[[34,1.23],[36,0]],"id":27701417},{"trd":[[34,1.47],[36,0.3]],"ltp":34.0,"tv":1.77,"id":27701417},{"atb":[[17,3.16]],"id":38206560},{"trd":[[17,3.6]],"ltp":17.0,"tv":3.6,"id":38206560},{"atb":[[6.2,34.01],[7,0]],"id":41762283},{"trd":[[6.2,2.24],[7,29.31]],"ltp":6.2,"tv":31.54,"id":41762283},{"atb":[[15,7.65]],"id":37401228},{"trd":[[15,4.06]],"ltp":15.0,"tv":4.06,"id":37401228},{"atb":[[2,97.58]],"id":40494181},{"trd":[[2,105.44]],"ltp":2.0,"tv":105.44,"id":40494181}],"con":true,"img":false}]}
{"op":"mcm","clk":"5306782876","pt":1646106147217,"mc":[{"id":"1.195395429","rc":[{"atb":[[1.38,0]],"id":40494181},{"atl":[[2.1,17.91]],"id":40494181}],"con":true,"img":false}]}
{"op":"mcm","clk":"5306783139","pt":1646106154938,"mc":[{"id":"1.195395429","rc":[{"spn":13.0,"spf":1.0,"id":39520250},{"spn":50.5,"spf":1.0,"id":36104895},{"atb":[[5.6,17.65]],"id":38206580},{"spn":7.2,"spf":1.0,"id":38206580},{"atl":[[220,0.14]],"id":27701417},{"spn":67.0,"spf":1.0,"id":27701417},{"atb":[[12.5,13.38]],"id":38206560},{"spn":17.5,"spf":1.0,"id":38206560},{"atl":[[23,4.68]],"id":41762283},{"spn":8.6,"spf":1.0,"id":41762283},{"atl":[[26,7.63]],"id":37401228},{"spn":15.0,"spf":1.0,"id":37401228},{"atl":[[3.25,56.17]],"id":40494181},{"spn":2.0,"spf":1.0,"id":40494181}],"con":true,"img":false}]}
{"op":"mcm","clk":"5306783142","pt":1646106155040,"mc":[{"id":"1.195395429","rc":[{"atb":[[11,1.13],[9.4,9.53]],"id":39520250},{"atb":[[18.5,0.64]],"id":36104895},{"atl":[[75,0.54],[110,0]],"id":36104895},{"atb":[[7.2,39.24],[6.2,0]],"id":38206580},{"atl":[[19,0]],"id":38206580},{"atb":[[34,0]],"id":27701417},{"atl":[[160,0],[230,0]],"id":27701417},{"atb":[[12.5,2.01],[13,0]],"id":38206560},{"atl":[[60,0]],"id":38206560},{"atb":[[6.2,0.76]],"id":41762283},{"atl":[[19,3.7]],"id":41762283},{"atb":[[6.2,0]],"id":37401228},{"atl":[[23,0]],"id":37401228},{"atb":[[1.36,27.41],[1.31,142.86]],"id":40494181},{"atl":[[2.52,0]],"id":40494181}],"con":true,"img":false}]}
{"op":"mcm","clk":"5306783146","pt":1646106155094,"mc":[{"id":"1.195395429","rc":[{"atl":[[180,2.7]],"id":36104895},{"atl":[[22,5.95]],"id":38206580},{"atl":[[310,2.7]],"id":27701417},{"atb":[[8.8,11.36]],"id":38206560},{"atl":[[65,2.7]],"id":38206560},{"atb":[[4.7,26.28]],"id":41762283},{"atb":[[4.8,22.63]],"id":37401228}],"con":true,"img":false}]}
{"op":"mcm","clk":"5306783152","pt":1646106155197,"mc":[{"id":"1.195395429","rc":[{"atb":[[11.5,0.96]],"id":38206560}],"con":true,"img":false}]}
{"op":"mcm","clk":"5306783313","pt":1646106159032,"mc":[{"id":"1.195395429","rc":[{"atl":[[1000,1.66]],"id":41762283},{"atb":[[1.01,2493.83]],"id":40494181}],"con":true,"img":false}]}
{"op":"mcm","clk":"5306783329","pt":1646106159340,"mc":[{"id":"1.195395429","rc":[{"atl":[[1000,0.94]],"id":41762283},{"atb":[[1.01,2493.04]],"id":40494181}],"con":true,"img":false}]}
{"op":"mcm","clk":"5306783348","pt":1646106159599,"mc":[{"id":"1.195395429","rc":[{"atl":[[1000,0]],"id":41762283},{"atb":[[1.01,2492.16]],"id":40494181}],"con":true,"img":false}]}
{"op":"mcm","clk":"5306783353","pt":1646106159701,"mc":[{"id":"1.195395429","rc":[{"atl":[[10.5,0.94]],"id":41762283},{"atb":[[2.02,0.87]],"id":40494181}],"con":true,"img":false}]}
{"op":"mcm","clk":"5306783426","pt":1646106161909,"mc":[{"id":"1.195395429","rc":[{"atl":[[38,3.18]],"id":38206560}],"con":true,"img":false}]}
{"op":"mcm","clk":"5306783430","pt":1646106162012,"mc":[{"id":"1.195395429","rc":[{"atl":[[42,10.82]],"id":38206560}],"con":true,"img":false}]}
{"op":"mcm","clk":"5306783471","pt":1646106163141,"mc":[{"id":"1.195395429","rc":[{"atb":[[6.2,1.4]],"id":41762283},{"atb":[[6.4,0],[12.5,2.59]],"id":37401228}],"con":true,"img":false}]}
{"op":"mcm","clk":"5306783584","pt":1646106166417,"mc":[{"id":"1.195395429","rc":[{"atl":[[16.5,2.79]],"id":38206580},{"atl":[[19.5,2.7]],"id":37401228},{"atl":[[2.48,15.32]],"id":40494181}],"con":true,"img":false}]}
{"op":"mcm","clk":"5306783644","pt":1646106167640,"mc":[{"id":"1.195395429","rc":[{"atb":[[12.5,0]],"id":37401228}],"con":true,"img":false}]}
{"op":"mcm","clk":"5306783649","pt":1646106167742,"mc":[{"id":"1.195395429","rc":[{"atb":[[12,2.59]],"id":37401228}],"con":true,"img":false}]}
{"op":"mcm","clk":"5306783652","pt":1646106167845,"mc":[{"id":"1.195395429","rc":[{"atl":[[170,1.33]],"id":36104895},{"atl":[[16,1.31]],"id":38206580},{"atl":[[300,1.34]],"id":27701417},{"atl":[[36,1.21]],"id":38206560},{"atl":[[14,1.23]],"id":41762283}],"con":true,"img":false}]}
{"op":"mcm","clk":"5306783917","pt":1646106175215,"mc":[{"id":"1.195395429","rc":[{"atb":[[1.98,20.22]],"id":40494181}],"con":true,"img":false}]}
{"op":"mcm","clk":"5306783921","pt":1646106175318,"mc":[{"id":"1.195395429","rc":[{"atb":[[1.36,0]],"id":40494181}],"con":true,"img":false}]}
{"op":"mcm","clk":"5306784147","pt":1646106181529,"mc":[{"id":"1.195395429","rc":[{"atl":[[75,0]],"id":36104895},{"atl":[[65,0]],"id":38206560}],"con":true,"img":false}]}
{"op":"mcm","clk":"5306784150","pt":1646106181630,"mc":[{"id":"1.195395429","rc":[{"atl":[[85,0.54]],"id":36104895},{"atl":[[90,2.7]],"id":38206560}],"con":true,"img":false}]}
{"op":"mcm","clk":"5306784309","pt":1646106187049,"mc":[{"id":"1.195395429","rc":[{"atl":[[38,0.47]],"id":38206560}],"con":true,"img":false}]}
{"op":"mcm","clk":"5306784314","pt":1646106187151,"mc":[{"id":"1.195395429","rc":[{"atl":[[40,13.52]],"id":38206560}],"con":true,"img":false}]}
{"op":"mcm","clk":"5306784330","pt":1646106187765,"mc":[{"id":"1.195395429","rc":[{"atl":[[36,0]],"id":38206560}],"con":true,"img":false}]}
{"op":"mcm","clk":"5306784334","pt":1646106187867,"mc":[{"id":"1.195395429","rc":[{"atl":[[38,1.68]],"id":38206560}],"con":true,"img":false}]}
{"op":"mcm","clk":"5306784415","pt":1646106190272,"mc":[{"id":"1.195395429","rc":[{"atl":[[19.5,0]],"id":37401228},{"atb":[[1.98,0]],"id":40494181}],"con":true,"img":false}]}
{"op":"mcm","clk":"5306784418","pt":1646106190374,"mc":[{"id":"1.195395429","rc":[{"atl":[[19,2.7]],"id":37401228},{"atb":[[1.99,20.22]],"id":40494181}],"con":true,"img":false}]}
{"op":"mcm","clk":"5306784432","pt":1646106190732,"mc":[{"id":"1.195395429","rc":[{"atb":[[1.19,0],[1.32,0]],"id":40494181}],"con":true,"img":false}]}
{"op":"mcm","clk":"5306784813","pt":1646106202962,"mc":[{"id":"1.195395429","rc":[{"atl":[[180,0]],"id":36104895}],"con":true,"img":false}]}
{"op":"mcm","clk":"5306784819","pt":1646106203063,"mc":[{"id":"1.195395429","rc":[{"atl":[[160,2.7]],"id":36104895}],"con":true,"img":false}]}
{"op":"mcm","clk":"5306784832","pt":1646106203472,"mc":[{"id":"1.195395429","rc":[{"atl":[[170,0]],"id":36104895}],"con":true,"img":false}]}
{"op":"mcm","clk":"5306784835","pt":1646106203574,"mc":[{"id":"1.195395429","rc":[{"atl":[[150,1.33]],"id":36104895}],"con":true,"img":false}]}
{"op":"mcm","clk":"5306784840","pt":1646106203676,"mc":[{"id":"1.195395429","rc":[{"atl":[[10.5,0.9]],"id":41762283},{"trd":[[10.5,0.08]],"ltp":10.5,"tv":0.08,"id":41762283},{"atl":[[16,32.43]],"id":37401228},{"trd":[[16,0.06]],"ltp":16.0,"tv":0.06,"id":37401228},{"atl":[[2.1,17.65]],"id":40494181},{"trd":[[2.1,2.2]],"ltp":2.1,"tv":2.2,"id":40494181}],"con":true,"img":false}]}
{"op":"mcm","clk":"5306784993","pt":1646106208999,"mc":[{"id":"1.195395429","rc":[{"atb":[[17,0.64]],"id":27701417}],"con":true,"img":false}]}
{"op":"mcm","clk":"5306785019","pt":1646106209569,"mc":[{"id":"1.195395429","rc":[{"atb":[[2,65.99],[2.02,0]],"id":40494181},{"trd":[[2,168.62],[2.02,1.75]],"ltp":2.0,"tv":170.37,"id":40494181}],"con":true,"img":false}]}
{"op":"mcm","clk":"5306785040","pt":1646106210178,"mc":[{"id":"1.195395429","rc":[{"atl":[[1000,2.23]],"id":38206580},{"atl":[[1000,2.23]],"id":38206560},{"atl":[[1000,2.23]],"id":41762283}],"con":true,"img":false}]}
{"op":"mcm","clk":"5306785072","pt":1646106211100,"mc":[{"id":"1.195395429","rc":[{"atl":[[2.1,10.82]],"id":40494181}],"con":true,"img":false}]}
{"op":"mcm","clk":"5306785086","pt":1646106211463,"mc":[{"id":"1.195395429","rc":[{"atl":[[1000,0.14]],"id":38206580},{"atl":[[1000,0.14]],"id":38206560},{"atl":[[1000,0.14]],"id":41762283}],"con":true,"img":false}]}
{"op":"mcm","clk":"5306785106","pt":1646106212076,"mc":[{"id":"1.195395429","rc":[{"atl":[[1000,0]],"id":38206580},{"atl":[[1000,0]],"id":38206560},{"atl":[[1000,0]],"id":41762283}],"con":true,"img":false}]}
{"op":"mcm","clk":"5306785109","pt":1646106212177,"mc":[{"id":"1.195395429","rc":[{"atl":[[19.5,5.99]],"id":38206580},{"atl":[[38,1.83]],"id":38206560},{"atl":[[14.5,10.97]],"id":41762283}],"con":true,"img":false}]}
{"op":"mcm","clk":"5306785157","pt":1646106213971,"mc":[{"id":"1.195395429","rc":[{"atb":[[1.03,2.23]],"id":40494181}],"con":true,"img":false}]}
{"op":"mcm","clk":"5306785161","pt":1646106214174,"mc":[{"id":"1.195395429","rc":[{"atb":[[1.03,0.27]],"id":40494181}],"con":true,"img":false}]}
{"op":"mcm","clk":"5306785171","pt":1646106214380,"mc":[{"id":"1.195395429","rc":[{"atb":[[1.03,0]],"id":40494181}],"con":true,"img":false}]}
{"op":"mcm","clk":"5306785175","pt":1646106214478,"mc":[{"id":"1.195395429","rc":[{"atb":[[1.99,20.5]],"id":40494181}],"con":true,"img":false}]}
{"op":"mcm","clk":"5306785468","pt":1646106224511,"mc":[{"id":"1.195395429","rc":[{"spn":55.5,"spf":1.0,"id":36104895},{"spn":66.0,"spf":1.0,"id":27701417},{"spn":8.35,"spf":1.0,"id":41762283},{"atb":[[2,82.23],[1.99,0.27]],"id":40494181}],"con":true,"img":false}]}
{"op":"mcm","clk":"5306785949","pt":1646106239398,"mc":[{"id":"1.195395429","rc":[{"atl":[[160,0]],"id":36104895}],"con":true,"img":false}]}
{"op":"mcm","clk":"5306785953","pt":1646106239501,"mc":[{"id":"1.195395429","rc":[{"atl":[[140,2.7]],"id":36104895}],"con":true,"img":false}]}
{"op":"mcm","clk":"5306785968","pt":1646106240013,"mc":[{"id":"1.195395429","rc":[{"atl":[[150,0]],"id":36104895}],"con":true,"img":false}]}
{"op":"mcm","clk":"5306785970","pt":1646106240116,"mc":[{"id":"1.195395429","rc":[{"atl":[[1000,1.33]],"id":36104895}],"con":true,"img":false}]}
{"op":"mcm","clk":"5306785983","pt":1646106240521,"mc":[{"id":"1.195395429","rc":[{"atl":[[140,0]],"id":36104895}],"con":true,"img":false}]}
{"op":"mcm","clk":"5306785986","pt":1646106240624,"mc":[{"id":"1.195395429","rc":[{"atl":[[180,2.7]],"id":36104895}],"con":true,"img":false}]}
{"op":"mcm","clk":"5306786009","pt":1646106241241,"mc":[{"id":"1.195395429","rc":[{"atl":[[1000,0]],"id":36104895}],"con":true,"img":false}]}
{"op":"mcm","clk":"5306786013","pt":1646106241345,"mc":[{"id":"1.195395429","rc":[{"atl":[[170,1.33]],"id":36104895}],"con":true,"img":false}]}
{"op":"mcm","clk":"5306786019","pt":1646106241502,"mc":[{"id":"1.195395429","rc":[{"atb":[[6.8,16.66],[9.4,0]],"id":39520250},{"atb":[[8.8,0],[7.8,14.79]],"id":38206560}],"con":true,"img":false}]}
{"op":"mcm","clk":"5306786044","pt":1646106242319,"mc":[{"id":"1.195395429","rc":[{"atb":[[13.5,1.4]],"id":39520250},{"atb":[[22,1.48]],"id":36104895},{"atb":[[7.4,1.52]],"id":38206580},{"atb":[[6.2,2.84]],"id":41762283}],"con":true,"img":false}]}
{"op":"mcm","clk":"5306786079","pt":1646106243242,"mc":[{"id":"1.195395429","rc":[{"atb":[[5.6,11.71],[4.7,2]],"id":41762283}],"con":true,"img":false}]}
{"op":"mcm","clk":"5306786205","pt":1646106247133,"mc":[{"id":"1.195395429","rc":[{"atb":[[11,0]],"id":39520250},{"atb":[[12.5,0]],"id":38206560}],"con":true,"img":false}]}
{"op":"mcm","clk":"5306786209","pt":1646106247234,"mc":[{"id":"1.195395429","rc":[{"atb":[[9.4,1.13]],"id":39520250},{"atb":[[10,2.01]],"id":38206560}],"con":true,"img":false}]}
{"op":"mcm","clk":"5306786368","pt":1646106252251,"mc":[{"id":"1.195395429","rc":[{"atb":[[13.5,2.73]],"id":39520250},{"atb":[[7.4,2.77]],"id":38206580},{"atb":[[6.2,4.14]],"id":41762283}],"con":true,"img":false}]}
{"op":"mcm","clk":"5306786404","pt":1646106253127,"mc":[{"id":"1.195395429","rc":[{"atl":[[11,0]],"id":41762283}],"con":true,"img":false}]}
{"op":"mcm","clk":"5306786409","pt":1646106253329,"mc":[{"id":"1.195395429","rc":[{"atl":[[1000,2.23]],"id":41762283}],"con":true,"img":false}]}
{"op":"mcm","clk":"5306786413","pt":1646106253430,"mc":[{"id":"1.195395429","rc":[{"atl":[[1000,1.06]],"id":41762283}],"con":true,"img":false}]}
{"op":"mcm","clk":"5306786418","pt":1646106253532,"mc":[{"id":"1.195395429","rc":[{"atl":[[1000,0]],"id":41762283}],"con":true,"img":false}]}
{"op":"mcm","clk":"5306786420","pt":1646106253633,"mc":[{"id":"1.195395429","rc":[{"atl":[[10,1.06]],"id":41762283}],"con":true,"img":false}]}
{"op":"mcm","clk":"5306786464","pt":1646106255330,"mc":[{"id":"1.195395429","rc":[{"atl":[[10.5,0],[1000,1.66]],"id":41762283}],"con":true,"img":false}]}
{"op":"mcm","clk":"5306786474","pt":1646106255634,"mc":[{"id":"1.195395429","rc":[{"atl":[[1000,0.96]],"id":41762283}],"con":true,"img":false}]}
{"op":"mcm","clk":"5306786486","pt":1646106255942,"mc":[{"id":"1.195395429","rc":[{"atl":[[1000,0]],"id":41762283}],"con":true,"img":false}]}
{"op":"mcm","clk":"5306786489","pt":1646106256045,"mc":[{"id":"1.195395429","rc":[{"atl":[[9.8,0.96]],"id":41762283}],"con":true,"img":false}]}
{"op":"mcm","clk":"5306786582","pt":1646106258665,"mc":[{"id":"1.195395429","rc":[{"atl":[[34,0]],"id":39520250},{"atb":[[7.2,34.06],[7.4,7.16]],"id":38206580},{"atl":[[40,10.82]],"id":38206560}],"con":true,"img":false}]}
{"op":"mcm","clk":"5306786585","pt":1646106258722,"mc":[{"id":"1.195395429","rc":[{"atl":[[32,2.7]],"id":39520250},{"atl":[[38,4.54]],"id":38206560}],"con":true,"img":false}]}
{"op":"mcm","clk":"5306786638","pt":1646106260529,"mc":[{"id":"1.195395429","rc":[{"atl":[[1000,2.23]],"id":38206560}],"con":true,"img":false}]}
{"op":"mcm","clk":"5306786646","pt":1646106260735,"mc":[{"id":"1.195395429","rc":[{"atl":[[1000,0.1]],"id":38206560}],"con":true,"img":false}]}
{"op":"mcm","clk":"5306786652","pt":1646106260943,"mc":[{"id":"1.195395429","rc":[{"atl":[[1000,0]],"id":38206560}],"con":true,"img":false}]}
{"op":"mcm","clk":"5306786656","pt":1646106261046,"mc":[{"id":"1.195395429","rc":[{"atl":[[36,0.1]],"id":38206560}],"con":true,"img":false}]}
{"op":"mcm","clk":"5306786807","pt":1646106265550,"mc":[{"id":"1.195395429","rc":[{"atb":[[13.5,1.93]],"id":39520250},{"trd":[[13.5,0.79]],"ltp":13.5,"tv":0.79,"id":39520250},{"atb":[[26,1.56]],"id":36104895},{"trd":[[26,2.75]],"ltp":26.0,"tv":2.75,"id":36104895},{"trd":[[14.5,7.77]],"ltp":14.5,"tv":7.77,"id":38206580},{"atb":[[32,3.15]],"id":27701417},{"trd":[[32,0.33]],"ltp":32.0,"tv":0.33,"id":27701417},{"atb":[[17,2.53]],"id":38206560},{"trd":[[17,4.23]],"ltp":17.0,"tv":4.23,"id":38206560},{"atb":[[6.2,2.42]],"id":41762283},{"trd":[[6.2,3.96]],"ltp":6.2,"tv":3.96,"id":41762283},{"atb":[[15,6.94]],"id":37401228},{"trd":[[15,4.77]],"ltp":15.0,"tv":4.77,"id":37401228},{"atb":[[2,76.89]],"id":40494181},{"trd":[[2,173.95]],"ltp":2.0,"tv":173.95,"id":40494181}],"con":true,"img":false}]}
{"op":"mcm","clk":"5306786814","pt":1646106265755,"mc":[{"id":"1.195395429","rc":[{"atb":[[5.6,0],[4.7,22.1]],"id":41762283}],"con":true,"img":false}]}
{"op":"mcm","clk":"5306786836","pt":1646106266366,"mc":[{"id":"1.195395429","rc":[{"atb":[[13.5,1.32]],"id":39520250},{"atl":[[32,3.54]],"id":39520250}],"con":true,"img":false}]}
{"op":"mcm","clk":"5306786855","pt":1646106267141,"mc":[{"id":"1.195395429","rc":[{"atl":[[32,3.39]],"id":39520250}],"con":true,"img":false}]}
{"op":"mcm","clk":"5306787100","pt":1646106275738,"mc":[{"id":"1.195395429","rc":[{"atl":[[180,0]],"id":36104895}],"con":true,"img":false}]}
{"op":"mcm","clk":"5306787103","pt":1646106275841,"mc":[{"id":"1.195395429","rc":[{"atl":[[160,2.7]],"id":36104895}],"con":true,"img":false}]}
{"op":"mcm","clk":"5306787111","pt":1646106276046,"mc":[{"id":"1.195395429","rc":[{"atl":[[170,0]],"id":36104895}],"con":true,"img":false}]}
{"op":"mcm","clk":"5306787114","pt":1646106276148,"mc":[{"id":"1.195395429","rc":[{"atl":[[1000,1.33]],"id":36104895}],"con":true,"img":false}]}
{"op":"mcm","clk":"5306787129","pt":1646106276659,"mc":[{"id":"1.195395429","rc":[{"atl":[[1000,0]],"id":36104895}],"con":true,"img":false}]}
{"op":"mcm","clk":"5306787132","pt":1646106276762,"mc":[{"id":"1.195395429","rc":[{"atl":[[150,1.33]],"id":36104895}],"con":true,"img":false}]}
{"op":"mcm","clk":"5306787169","pt":1646106278044,"mc":[{"id":"1.195395429","rc":[{"atl":[[90,0]],"id":38206560}],"con":true,"img":false}]}
{"op":"mcm","clk":"5306787172","pt":1646106278145,"mc":[{"id":"1.195395429","rc":[{"atl":[[65,2.7]],"id":38206560}],"con":true,"img":false}]}
{"op":"mcm","clk":"5306787209","pt":1646106279580,"mc":[{"id":"1.195395429","rc":[{"atl":[[2.48,0]],"id":40494181}],"con":true,"img":false}]}
{"op":"mcm","clk":"5306787212","pt":1646106279679,"mc":[{"id":"1.195395429","rc":[{"atl":[[2.44,15.32]],"id":40494181}],"con":true,"img":false}]}
{"op":"mcm","clk":"5306788286","pt":1646106313213,"mc":[{"id":"1.195395429","rc":[{"atb":[[9.4,0]],"id":39520250},{"spn":13.05,"spf":1.0,"id":39520250},{"atl":[[160,0]],"id":36104895},{"spn":7.29,"spf":1.0,"id":38206580},{"spn":8.0,"spf":1.0,"id":41762283}],"con":true,"img":false}]}
{"op":"mcm","clk":"5306788290","pt":1646106313315,"mc":[{"id":"1.195395429","rc":[{"atb":[[9.8,1.13]],"id":39520250},{"atl":[[140,2.7]],"id":36104895}],"con":true,"img":false}]}
{"op":"mcm","clk":"5306788307","pt":1646106313924,"mc":[{"id":"1.195395429","rc":[{"atl":[[150,0]],"id":36104895}],"con":true,"img":false}]}
{"op":"mcm","clk":"5306788311","pt":1646106314027,"mc":[{"id":"1.195395429","rc":[{"atl":[[1000,1.33]],"id":36104895}],"con":true,"img":false}]}
{"op":"mcm","clk":"5306788329","pt":1646106314436,"mc":[{"id":"1.195395429","rc":[{"atl":[[140,0]],"id":36104895},{"atb":[[10,0]],"id":38206560}],"con":true,"img":false}]}
{"op":"mcm","clk":"5306788334","pt":1646106314539,"mc":[{"id":"1.195395429","rc":[{"atl":[[180,2.7]],"id":36104895},{"atb":[[11,2.01]],"id":38206560}],"con":true,"img":false}]}
{"op":"mcm","clk":"5306788350","pt":1646106315105,"mc":[{"id":"1.195395429","rc":[{"atl":[[1000,0]],"id":36104895}],"con":true,"img":false}]}
{"op":"mcm","clk":"5306788353","pt":1646106315207,"mc":[{"id":"1.195395429","rc":[{"atl":[[170,1.33]],"id":36104895}],"con":true,"img":false}]}
{"op":"mcm","clk":"5306788493","pt":1646106320637,"mc":[{"id":"1.195395429","rc":[{"atb":[[1.03,2.23]],"id":38206580}],"con":true,"img":false}]}
{"op":"mcm","clk":"5306788500","pt":1646106320738,"mc":[{"id":"1.195395429","rc":[{"atl":[[1000,2.23]],"id":39520250}],"con":true,"img":false}]}
{"op":"mcm","clk":"5306788508","pt":1646106321047,"mc":[{"id":"1.195395429","rc":[{"atl":[[1000,0.12]],"id":39520250}],"con":true,"img":false}]}
{"op":"mcm","clk":"5306788515","pt":1646106321254,"mc":[{"id":"1.195395429","rc":[{"atl":[[1000,0]],"id":39520250},{"atb":[[1.03,0.49]],"id":38206580}],"con":true,"img":false}]}
{"op":"mcm","clk":"5306788519","pt":1646106321356,"mc":[{"id":"1.195395429","rc":[{"atl":[[30,0.12]],"id":39520250}],"con":true,"img":false}]}
{"op":"mcm","clk":"5306788531","pt":1646106321820,"mc":[{"id":"1.195395429","rc":[{"atb":[[1.03,0]],"id":38206580}],"con":true,"img":false}]}
{"op":"mcm","clk":"5306788536","pt":1646106321921,"mc":[{"id":"1.195395429","rc":[{"atb":[[7.6,0.49]],"id":38206580}],"con":true,"img":false}]}
{"op":"mcm","clk":"5306788848","pt":1646106333370,"mc":[{"id":"1.195395429","rc":[{"atb":[[6.8,0]],"id":39520250}],"con":true,"img":false}]}
{"op":"mcm","clk":"5306788851","pt":1646106333473,"mc":[{"id":"1.195395429","rc":[{"atb":[[7.4,16.66]],"id":39520250}],"con":true,"img":false}]}
{"op":"mcm","clk":"5306789414","pt":1646106350666,"mc":[{"id":"1.195395429","rc":[{"atl":[[180,0]],"id":36104895}],"con":true,"img":false}]}
{"op":"mcm","clk":"5306789420","pt":1646106350769,"mc":[{"id":"1.195395429","rc":[{"atl":[[160,2.7]],"id":36104895}],"con":true,"img":false}]}
{"op":"mcm","clk":"5306789434","pt":1646106351175,"mc":[{"id":"1.195395429","rc":[{"atl":[[170,0]],"id":36104895}],"con":true,"img":false}]}
{"op":"mcm","clk":"5306789435","pt":1646106351278,"mc":[{"id":"1.195395429","rc":[{"atl":[[150,1.33]],"id":36104895}],"con":true,"img":false}]}
{"op":"mcm","clk":"5306789957","pt":1646106367409,"mc":[{"id":"1.195395429","rc":[{"atl":[[10,0]],"id":41762283}],"con":true,"img":false}]}
{"op":"mcm","clk":"5306789963","pt":1646106367817,"mc":[{"id":"1.195395429","rc":[{"atl":[[1000,2.23]],"id":41762283}],"con":true,"img":false}]}
{"op":"mcm","clk":"5306789975","pt":1646106368122,"mc":[{"id":"1.195395429","rc":[{"atl":[[1000,0.79]],"id":41762283}],"con":true,"img":false}]}
{"op":"mcm","clk":"5306789979","pt":1646106368379,"mc":[{"id":"1.195395429","rc":[{"atl":[[1000,0]],"id":41762283}],"con":true,"img":false}]}
{"op":"mcm","clk":"5306789981","pt":1646106368482,"mc":[{"id":"1.195395429","rc":[{"atl":[[13.5,0.79]],"id":41762283}],"con":true,"img":false}]}
{"op":"mcm","clk":"5306790222","pt":1646106375493,"mc":[{"id":"1.195395429","rc":[{"spn":7.3,"spf":1.0,"id":38206580},{"atl":[[9.8,0]],"id":41762283},{"spn":9.85,"spf":1.0,"id":41762283}],"con":true,"img":false}]}
{"op":"mcm","clk":"5306790226","pt":1646106375596,"mc":[{"id":"1.195395429","rc":[{"atl":[[1000,1.66]],"id":41762283}],"con":true,"img":false}]}
{"op":"mcm","clk":"5306790240","pt":1646106375900,"mc":[{"id":"1.195395429","rc":[{"atl":[[1000,0.95]],"id":41762283}],"con":true,"img":false}]}
{"op":"mcm","clk":"5306790246","pt":1646106376108,"mc":[{"id":"1.195395429","rc":[{"atl":[[1000,0]],"id":41762283}],"con":true,"img":false}]}
{"op":"mcm","clk":"5306790249","pt":1646106376208,"mc":[{"id":"1.195395429","rc":[{"atl":[[10,0.95]],"id":41762283}],"con":true,"img":false}]}
{"op":"mcm","clk":"5306790584","pt":1646106387139,"mc":[{"id":"1.195395429","rc":[{"atl":[[160,0]],"id":36104895}],"con":true,"img":false}]}
{"op":"mcm","clk":"5306790587","pt":1646106387241,"mc":[{"id":"1.195395429","rc":[{"atl":[[140,2.7]],"id":36104895}],"con":true,"img":false}]}
{"op":"mcm","clk":"5306790616","pt":1646106387808,"mc":[{"id":"1.195395429","rc":[{"atl":[[150,0]],"id":36104895}],"con":true,"img":false}]}
{"op":"mcm","clk":"5306790619","pt":1646106387911,"mc":[{"id":"1.195395429","rc":[{"atl":[[1000,1.33]],"id":36104895}],"con":true,"img":false}]}
{"op":"mcm","clk":"5306790654","pt":1646106388931,"mc":[{"id":"1.195395429","rc":[{"atl":[[140,0]],"id":36104895}],"con":true,"img":false}]}
{"op":"mcm","clk":"5306790658","pt":1646106389036,"mc":[{"id":"1.195395429","rc":[{"atl":[[180,2.7]],"id":36104895}],"con":true,"img":false}]}
{"op":"mcm","clk":"5306790681","pt":1646106389550,"mc":[{"id":"1.195395429","rc":[{"atl":[[1000,0]],"id":36104895}],"con":true,"img":false}]}
{"op":"mcm","clk":"5306790686","pt":1646106389599,"mc":[{"id":"1.195395429","rc":[{"atl":[[170,1.33]],"id":36104895}],"con":true,"img":false}]}
{"op":"mcm","clk":"5306791665","pt":1646106424160,"mc":[{"id":"1.195395429","rc":[{"atl":[[180,0]],"id":36104895}],"con":true,"img":false}]}
{"op":"mcm","clk":"5306791670","pt":1646106424262,"mc":[{"id":"1.195395429","rc":[{"atl":[[160,2.7]],"id":36104895}],"con":true,"img":false}]}
{"op":"mcm","clk":"5306791679","pt":1646106424671,"mc":[{"id":"1.195395429","rc":[{"atl":[[170,0]],"id":36104895}],"con":true,"img":false}]}
{"op":"mcm","clk":"5306791681","pt":1646106424773,"mc":[{"id":"1.195395429","rc":[{"atl":[[150,1.33]],"id":36104895}],"con":true,"img":false}]}
{"op":"mcm","clk":"5306792691","pt":1646106459920,"mc":[{"id":"1.195395429","rc":[{"atl":[[160,0]],"id":36104895},{"spn":8.1,"spf":1.0,"id":41762283}],"con":true,"img":false}]}
{"op":"mcm","clk":"5306792694","pt":1646106460020,"mc":[{"id":"1.195395429","rc":[{"atl":[[140,2.7]],"id":36104895}],"con":true,"img":false}]}
{"op":"mcm","clk":"5306792719","pt":1646106460731,"mc":[{"id":"1.195395429","rc":[{"atl":[[150,0]],"id":36104895}],"con":true,"img":false}]}
{"op":"mcm","clk":"5306792722","pt":1646106460834,"mc":[{"id":"1.195395429","rc":[{"atl":[[1000,1.33]],"id":36104895}],"con":true,"img":false}]}
{"op":"mcm","clk":"5306792727","pt":1646106460939,"mc":[{"id":"1.195395429","rc":[{"atl":[[140,0]],"id":36104895}],"con":true,"img":false}]}
{"op":"mcm","clk":"5306792732","pt":1646106460991,"mc":[{"id":"1.195395429","rc":[{"atl":[[180,2.7]],"id":36104895}],"con":true,"img":false}]}
{"op":"mcm","clk":"5306792741","pt":1646106461199,"mc":[{"id":"1.195395429","rc":[{"atl":[[1000,0]],"id":36104895}],"con":true,"img":false}]}
{"op":"mcm","clk":"5306792745","pt":1646106461299,"mc":[{"id":"1.195395429","rc":[{"atl":[[170,1.33]],"id":36104895}],"con":true,"img":false}]}
{"op":"mcm","clk":"5306793983","pt":1646106496366,"mc":[{"id":"1.195395429","rc":[{"atl":[[180,0]],"id":36104895}],"con":true,"img":false}]}
{"op":"mcm","clk":"5306793987","pt":1646106496467,"mc":[{"id":"1.195395429","rc":[{"atl":[[160,2.7]],"id":36104895}],"con":true,"img":false}]}
{"op":"mcm","clk":"5306793994","pt":1646106496772,"mc":[{"id":"1.195395429","rc":[{"atl":[[170,0]],"id":36104895}],"con":true,"img":false}]}
{"op":"mcm","clk":"5306793998","pt":1646106496874,"mc":[{"id":"1.195395429","rc":[{"atl":[[150,1.33]],"id":36104895}],"con":true,"img":false}]}
{"op":"mcm","clk":"5306794871","pt":1646106519128,"mc":[{"id":"1.195395429","rc":[{"spl":[[1.01,3.78]],"id":41762283}],"con":true,"img":false}]}
{"op":"mcm","clk":"5306795312","pt":1646106531720,"mc":[{"id":"1.195395429","rc":[{"atl":[[160,0]],"id":36104895},{"spn":6.12,"spf":1.0,"id":41762283}],"con":true,"img":false}]}
{"op":"mcm","clk":"5306795314","pt":1646106531825,"mc":[{"id":"1.195395429","rc":[{"atl":[[140,2.7]],"id":36104895}],"con":true,"img":false}]}
{"op":"mcm","clk":"5306795323","pt":1646106532130,"mc":[{"id":"1.195395429","rc":[{"atl":[[150,0]],"id":36104895}],"con":true,"img":false}]}
{"op":"mcm","clk":"5306795326","pt":1646106532233,"mc":[{"id":"1.195395429","rc":[{"atl":[[1000,1.33]],"id":36104895}],"con":true,"img":false}]}
{"op":"mcm","clk":"5306795379","pt":1646106533617,"mc":[{"id":"1.195395429","rc":[{"atl":[[140,0]],"id":36104895}],"con":true,"img":false}]}
